{
  "name": "multi_thering_1_base1",
  "refpalette": "deceasedcraft:multi_thering_1/multi_thering_1_base1_palette",
  "xsize": 16,
  "zsize": 16,
  "slices": [
    [
      "vaaaaaaaaaaaaaaa",
      "va              ",
      "va              ",
      "va              ",
      "va              ",
      "va              ",
      "va              ",
      "va              ",
      "va              ",
      "va              ",
      "va              ",
      "va              ",
      "va              ",
      "va              ",
      "vaaaaaaabbbbbbaa",
      "va    a        c"
    ],
    [
      "vaaaaaaaaaaaaaaa",
      "va              ",
      "va             d",
      "va              ",
      "va             e",
      "va             e",
      "va             e",
      "va             e",
      "va             e",
      "va             e",
      "va             e",
      "va              ",
      "va             d",
      "va              ",
      "vaaaaaaaffffffaa",
      "va    a        c"
    ],
    [
      "vaaaaaaaaaaaaaaa",
      "va             g",
      "va             h",
      "va             i",
      "va             e",
      "va             e",
      "va             e",
      "va             e",
      "va             e",
      "va             e",
      "va             e",
      "va             g",
      "va             h",
      "va             i",
      "vaaaaaaaaaaaaaaa",
      "vajkk a        c"
    ],
    [
      "vaaaaaaaaaaaaaaa",
      "va             l",
      "va             m",
      "va             n",
      "va             e",
      "va             e",
      "va             e",
      "va             e",
      "va             e",
      "va             e",
      "va             e",
      "va             l",
      "va             h",
      "va             n",
      "vaaaaaaaaaaaaaaa",
      "vaopppa        c"
    ],
    [
      "vaaaaaaaaaaaaaaa",
      "va              ",
      "va              ",
      "va              ",
      "va              ",
      "va              ",
      "va              ",
      "va    q         ",
      "va              ",
      "va              ",
      "va              ",
      "va              ",
      "va              ",
      "va              ",
      "vaaaaaaaaaaaaaaa",
      "vars sa        c"
    ],
    [
      "vaaaaaaaaaaaaaaa",
      "vapppppppppppppt",
      "vapppppppppppppt",
      "vapppppppppppppt",
      "vapppppppppppppt",
      "vapppppppppppppt",
      "vapppppppppppppt",
      "vapppp!ppppppppt",
      "vapppppppppppppt",
      "vapppppppppppppt",
      "vapppppppppppppt",
      "vapppppppppppppt",
      "vapppppppppppppt",
      "vapppppppppppppt",
      "vaaaaaaaaaaaaaaa",
      "vauuuuappppppppc"
    ]
  ]
}