{
  "name": "multi_thering_1_base2",
  "refpalette": "deceasedcraft:multi_thering_1/multi_thering_1_base2_palette",
  "xsize": 16,
  "zsize": 16,
  "slices": [
    [
      "vaaaaaaaaaaaaaaa",
      "vaaaaaaaaaaaaaaa",
      "vaaaaaaaaaaaaaaa",
      "vaaaaaaaaaaaaaaa",
      "vaaaaaaaaaaaaaaa",
      "vaaaaaaaaaaaaaaa",
      "vaaaaaaaaaaaaaaa",
      "vaaaaaaaaaaaaaaa",
      "vaaaaaaaaaaaaaaa",
      "vaaaaaaaaaaaaaaa",
      "vaaaaaaaaaaaaaaa",
      "vaaaaaaaaaaaaaaa",
      "vaaaaaaaaaaaaaaa",
      "vaaaaaaaaaaaaaaa",
      "vaaaaaaaaaaaaaaa",
      "vaaaaaaaaaaaaaab"
    ],
    [
      "vaaaaaaaaaaaaaaa",
      "vaaaaaaaaaaaaaaa",
      "vaaaaaaaaaaaaaaa",
      "vaaaaaaaaaaaaaaa",
      "vaaaaaaaaaaaaaaa",
      "vaaaaaaaaaaaaaaa",
      "vaaaaaaaaaaaaaaa",
      "vaaaaaaaaaaaaaaa",
      "vaaaaaaaaaaaaaaa",
      "vaaaaaaaaaaaaaaa",
      "vaaaaaaaaaaaaaaa",
      "vaaaaaaaaaaaaaaa",
      "vaaaaaaaaaaaaaaa",
      "vaaaaaaaaaaaaaaa",
      "vaaaaaaaaaaaaaaa",
      "vaaaaaaaaaaaaaab"
    ],
    [
      "vccccccccccccccc",
      "vccccccccccccccc",
      "vccccccccccccccc",
      "vccccccccccccccc",
      "vccccccccccccccc",
      "vccccccccccccccc",
      "vccccccccccccccc",
      "vccccccccccccccc",
      "vccccccccccccccc",
      "vccccccccccccccc",
      "vccccccccccccccc",
      "vccccccccccccccc",
      "vccccccccccccccc",
      "vccccccccccccccc",
      "vccccccccccccccc",
      "vccccccccccccccb"
    ],
    [
      "vddddddddddddddd",
      "vdeeeeeeeeeeee!f",
      "vdeeeeeeeeeeeeff",
      "vdeeeeeeeeeeeeff",
      "vdeeeeeeeeeeeeff",
      "vdeeeeeeeeeeeeff",
      "vdeeeeeeeeeeeeff",
      "vdeeeeeeeeeeeeff",
      "vdeeeeeeeeeeeeff",
      "vdeeeeeeeeeeeeff",
      "vdeeeeeeeeeeeeff",
      "vdeeeeeeeeeeeeff",
      "vdeeeeeeeeeeeeff",
      "vdeeeeeeeeeeeeff",
      "vdddddddggggggdd",
      "vdhhhhdffffffffd"
    ],
    [
      "vddddddddddddddd",
      "vd            ij",
      "vd           kjj",
      "vdl l l l    kjj",
      "vdl l l lmn  kjj",
      "vdl l l l    kjj",
      "vdl l l lmn  kjj",
      "vd           kjj",
      "vdl l l lmn  kjj",
      "vdl l l l    kjj",
      "vdl l l lmn  kjj",
      "vdl l l l    kjj",
      "vd           kjj",
      "vd            ij",
      "vdddddddoopqoodd",
      "vd    d        r"
    ],
    [
      "vddddddddddddddd",
      "vd              ",
      "vd              ",
      "vd              ",
      "vd              ",
      "vd              ",
      "vd              ",
      "vd              ",
      "vd              ",
      "vd            s ",
      "vd              ",
      "vd              ",
      "vd              ",
      "vd              ",
      "vdddddddootuoodd",
      "vd    d        r"
    ]
  ]
}