{
  "name": "multi_thering_1_floor7",
  "refpalette": "deceasedcraft:multi_thering_1/multi_thering_1_floor7_palette",
  "xsize": 16,
  "zsize": 16,
  "slices": [
    [
      "           aabcc",
      "           abccc",
      "          abcccc",
      "         abbcccb",
      "         abccccb",
      "        abccccbb",
      "       aabcccbb ",
      "       abccccb  ",
      "      aabcccbb  ",
      "      abcccbb   ",
      "      abcccb    ",
      "     abccccb    ",
      "     abcccbb    ",
      "     abcccb     ",
      "    abcccbb     ",
      "    abcccb     d"
    ],
    [
      "             efg",
      "            efgh",
      "           efghh",
      "          eefih ",
      "          efghh ",
      "         efihh  ",
      "         efgh   ",
      "        efghh   ",
      "        efhh    ",
      "       efgh     ",
      "       efgh     ",
      "      efghh     ",
      "      ef h      ",
      "      efhh      ",
      "     efgh       ",
      "     efgh      d"
    ],
    [
      "              f ",
      "             f  ",
      "            f   ",
      "            f   ",
      "           f    ",
      "          f     ",
      "          f     ",
      "         f      ",
      "         f      ",
      "        f       ",
      "        f       ",
      "       f        ",
      "       f        ",
      "       f        ",
      "      f         ",
      "      f        d"
    ],
    [
      "                ",
      "                ",
      "                ",
      "                ",
      "                ",
      "                ",
      "                ",
      "                ",
      "                ",
      "                ",
      "                ",
      "                ",
      "                ",
      "                ",
      "                ",
      "               d"
    ],
    [
      "                ",
      "                ",
      "                ",
      "                ",
      "                ",
      "                ",
      "                ",
      "                ",
      "                ",
      "                ",
      "                ",
      "                ",
      "                ",
      "                ",
      "                ",
      "               d"
    ],
    [
      "                ",
      "                ",
      "                ",
      "                ",
      "                ",
      "                ",
      "                ",
      "                ",
      "                ",
      "                ",
      "                ",
      "                ",
      "                ",
      "                ",
      "                ",
      "               d"
    ]
  ]
}