{
  "name": "multi_terraceplaza_20_base2",
  "refpalette": "deceasedcraft:multi_terraceplaza_20/multi_terraceplaza_20_base2_palette",
  "xsize": 16,
  "zsize": 16,
  "slices": [
    [
      "abbbbbbbbbbbbbba",
      "abbbbbbbbbbbbbba",
      "abbbbbbbbbbbbbba",
      "abbbbbbbbbbbbbba",
      "abbbbbbbbbbbbbba",
      "abbbbbbbbbbbbbba",
      "abbbbbbbbbbbbbba",
      "abbbbbbbbbbbbbba",
      "abbbbbbbbbbbbbba",
      "abbbbbbbbbbbbbba",
      "acbbbbbbbbbbbbca",
      "abbbbbbbbbbbbbba",
      "abbbbbbbbbbbbbba",
      "dddddddddddddddd",
      "eeeeeeeeeeeeeeee",
      "vvvvvvvvvvvvvvvv"
    ],
    [
      "fg            hi",
      "jg            hk",
      "hg   lm  lm   hn",
      "ho   lp  qm   hk",
      "ho   rp  qs   ht",
      "ho   rp  qs   hk",
      "ho   lp  qm   hu",
      "hg   lm  lm   hk",
      "w             ht",
      "fg            hi",
      "fc  x       y cA",
      "f  BCDE FIJF   K",
      "fCCCEEELLIIJJJJf",
      "dddddddddddddddd",
      "eeeeeeeeeeeeeeee",
      "vvvvvvvvvvvvvvvv"
    ],
    [
      "fM             i",
      " N            OP",
      "Q     R  S     P",
      " T   UV  WX   SP",
      " Y    Z  W     P",
      "0U    1       2P",
      "3    UX  4U   SP",
      " U   5    X    P",
      "               P",
      "fU             i",
      "fc            cA",
      "f     x   Z    6",
      "fCC BEEL7I 7JFJf",
      "dddddddddddddddd",
      "eeeeeeeeeeeeeeee",
      "vvvvvvvvvvvvvvvv"
    ],
    [
      "f              i",
      "                ",
      "                ",
      "                ",
      "                ",
      "                ",
      "                ",
      "                ",
      "                ",
      "f              i",
      "fc            cf",
      "f              f",
      "f 8    D    F  f",
      "dddddddddddddddd",
      "eeeeeeeeeeeeeeee",
      "vvvvvvvvvvvvvvvv"
    ],
    [
      "f              i",
      "                ",
      "                ",
      "                ",
      "                ",
      "                ",
      "                ",
      "                ",
      "                ",
      "f              i",
      "fc            cf",
      "f              f",
      "f9             f",
      "dddddddddddddddd",
      "eeeeeeeeeeeeeeee",
      "vvvvvvvvvvvvvvvv"
    ],
    [
      "f#            $i",
      "%#            $ ",
      "^#            $ ",
      "%#            $ ",
      "^#            $ ",
      "%#            $ ",
      "^#            $ ",
      "%#            $ ",
      "^#            $ ",
      "f#            $i",
      "fc&&&&&&&&&&&&cf",
      "f99 99         f",
      "f99  9 9       f",
      "dddddddddddddddd",
      "eeeeeeeeeeeeeeee",
      "vvvvvvvvvvvvvvvv"
    ]
  ]
}