{
  "name": "multi_terraceplaza_20_base1",
  "refpalette": "deceasedcraft:multi_terraceplaza_20/multi_terraceplaza_20_base1_palette",
  "xsize": 16,
  "zsize": 16,
  "slices": [
    [
      "ab            cd",
      "eb            ce",
      "eb            ce",
      "eb            ce",
      "eb            ce",
      "eb            ce",
      "eb            ce",
      "eb            ce",
      "eb            ce",
      "ab            cd",
      "afggggggggggggfa",
      "aeeeeeeeeeeeeeea",
      "aeeeeeeeeeeeeeea",
      "hhhhhhhhhhhhhhhh",
      "iiiiiiiiiiiiiiii",
      "vvvvvvvvvvvvvvvv"
    ],
    [
      "ab            cd",
      " b            c ",
      " b            c ",
      " b            c ",
      " b            c ",
      " b            c ",
      " b            c ",
      " b            c ",
      " b            c ",
      "ab            cd",
      "afggggggggggggfa",
      "a              a",
      "a    !    j    a",
      "hhhhhhhhhhhhhhhh",
      "iiiiiiiiiiiiiiii",
      "vvvvvvvvvvvvvvvv"
    ],
    [
      "ab            cd",
      " b            c ",
      "jb            cj",
      " b            c ",
      " b            c ",
      " b            c ",
      " b            c ",
      "jb            cj",
      " b            c ",
      "ab            cd",
      "afggggggggggggfa",
      "a              a",
      "kkkkkkkkkkkkkkkk",
      "hhhhhhhhhhhhhhhh",
      "iiiiiiiiiiiiiiii",
      "vvvvvvvvvvvvvvvv"
    ],
    [
      "kb            ck",
      "kb            ck",
      "kb            ck",
      "kb            ck",
      "kb            ck",
      "kb            ck",
      "kb            ck",
      "kb            ck",
      "kb            ck",
      "ab            cd",
      "afggggggggggggfa",
      "aiiiiiiiiiiiiiia",
      "iiiiiiiiiiiiiiii",
      "hhhhhhhhhhhhhhhh",
      "iiiiiiiiiiiiiiii",
      "vvvvvvvvvvvvvvvv"
    ],
    [
      "kllllllllllllllk",
      "illmllnllmllnlli",
      "illnjlnllmljnlli",
      "illnllnllmllnlli",
      "illlllllllllllli",
      "illlllllllllllli",
      "illnllnllnllmlli",
      "illnjlnllmljnlli",
      "ollnllnllmllnllo",
      "ollllllllllllllo",
      "ofllllllllllllfo",
      "ollllllllllllllo",
      "ollllllllllllllo",
      "hhhhhhhhhhhhhhhh",
      "iiiiiiiiiiiiiiii",
      "vvvvvvvvvvvvvvvv"
    ],
    [
      "ipkkkkkkkkkkkkpi",
      "ipqqkqq q qkqqpi",
      "ip rkqr  rqkrqpi",
      "ip  kq     kq pi",
      "ipq k    q k  pi",
      "ip qk     qk qpi",
      "ip  kq  q qk  pi",
      "ip rk r  rqkrqpi",
      "opq  q  q  q qpo",
      "opqq qq  qq qqpo",
      "sfllllllllllllfs",
      "tpllllllllllllpt",
      "opllllllllllllpo",
      "pphhhhhhhhhhhhpp",
      "iiiiiiiiiiiiiiii",
      "vvvvvvvvvvvvvvvv"
    ]
  ]
}