{
  "name": "multi_terraceplaza_20_ground",
  "refpalette": "deceasedcraft:multi_terraceplaza_20/multi_terraceplaza_20_ground_palette",
  "xsize": 16,
  "zsize": 16,
  "slices": [
    [
      "aaaaaaaaaaaaaaaa",
      "aaabbaabbaabbaaa",
      "aaabbaabbaabbaaa",
      "aaaaabbaabbaaaaa",
      "aaaaabbaabbaaaaa",
      "caabbaabbaabbaac",
      "caabbaabbaabbaac",
      "ccaaabbaabbaaacc",
      " caaabbaabbaaac ",
      " cabbaabbaabbac ",
      " dabbaabbaabbad ",
      "ecaaabbaabbaaace",
      "fcaaabbaabbaaacf",
      "ccabbaabbaabbacc",
      "aaabbaabbaabbaaa",
      "aaaaaaaaaaaaaaaa"
    ],
    [
      "                ",
      "                ",
      "                ",
      "                ",
      "                ",
      "g              g",
      "g              g",
      "gg            gg",
      " g            g ",
      " g            g ",
      " h            h ",
      "ig            gi",
      " g            g ",
      "gg            gg",
      "                ",
      "                "
    ],
    [
      "                ",
      "                ",
      "                ",
      "                ",
      "                ",
      "                ",
      "                ",
      "                ",
      "                ",
      "                ",
      "                ",
      "i              i",
      "                ",
      "                ",
      "                ",
      "                "
    ],
    [
      "                ",
      "                ",
      "                ",
      "                ",
      "                ",
      "                ",
      "                ",
      "                ",
      "                ",
      "                ",
      "                ",
      "                ",
      "                ",
      "                ",
      "                ",
      "                "
    ],
    [
      "                ",
      "                ",
      "                ",
      "                ",
      "                ",
      "                ",
      "                ",
      "                ",
      "                ",
      "                ",
      "                ",
      "                ",
      "                ",
      "                ",
      "                ",
      "                "
    ],
    [
      "jkllllllllllllmn",
      "jonppppppppppjon",
      "jqnppppppppppjqn",
      "prpppppppppppprp",
      "                ",
      "                ",
      "                ",
      "                ",
      "                ",
      "                ",
      "                ",
      "                ",
      "                ",
      "                ",
      "                ",
      "                "
    ]
  ]
}