{
  "name": "multi_oasiscondo_1_top",
  "refpalette": "deceasedcraft:multi_oasiscondo_1/multi_oasiscondo_1_top_palette",
  "xsize": 16,
  "zsize": 16,
  "slices": [
    [
      "         abbbbbb",
      "         abbbbbb",
      "         acbbbbb",
      "         abbbbbb",
      "         abbbbbb",
      "         abbbbbb",
      "         abbbbbb",
      "         abbbbbb",
      "         abbbbbb",
      "         abbbbbb",
      "         abbbbbb",
      "         acbbbbb",
      "         abbbbbb",
      "         abbbbbb",
      "         abbbbbb",
      "         abbbbbb"
    ],
    [
      "       defghi   ",
      "       defj j   ",
      "       de c     ",
      "       defk k   ",
      "       defghi lm",
      "       defj j  m",
      "       dee    n ",
      "       dee      ",
      "       defk k lm",
      "       defghi lm",
      "       defj j   ",
      "       de c     ",
      "       defk k   ",
      "       defghi lm",
      "       defj j lm",
      "       dee      "
    ],
    [
      "       o pq r   ",
      "       o p      ",
      "       o sc     ",
      "       o p      ",
      "       o p     t",
      "       o p     !",
      "       o        ",
      "       o        ",
      "       o p      ",
      "       o pquq   ",
      "       o p      ",
      "       o sc     ",
      "       o p      ",
      "       o pw x   ",
      "       o p     y",
      "       o        "
    ],
    [
      "                ",
      "                ",
      "          c     ",
      "                ",
      "                ",
      "                ",
      "                ",
      "                ",
      "                ",
      "                ",
      "                ",
      "          c     ",
      "                ",
      "                ",
      "                ",
      "                "
    ],
    [
      "                ",
      "                ",
      "          c     ",
      "                ",
      "                ",
      "                ",
      "                ",
      "                ",
      "                ",
      "                ",
      "                ",
      "          c     ",
      "                ",
      "                ",
      "                ",
      "                "
    ],
    [
      "                ",
      "                ",
      "         Ac     ",
      "                ",
      "                ",
      "                ",
      "                ",
      "                ",
      "                ",
      "                ",
      "                ",
      "          c     ",
      "                ",
      "                ",
      "                ",
      "                "
    ],
    [
      "                ",
      "                ",
      "         Bc     ",
      "                ",
      "                ",
      "                ",
      "                ",
      "                ",
      "                ",
      "                ",
      "                ",
      "         Bc     ",
      "                ",
      "                ",
      "                ",
      "                "
    ],
    [
      "                ",
      "                ",
      "         Cc     ",
      "                ",
      "                ",
      "                ",
      "                ",
      "                ",
      "                ",
      "                ",
      "                ",
      "         Cc     ",
      "                ",
      "                ",
      "                ",
      "                "
    ],
    [
      "                ",
      "                ",
      "          c     ",
      "                ",
      "                ",
      "                ",
      "                ",
      "                ",
      "                ",
      "                ",
      "                ",
      "          c     ",
      "                ",
      "                ",
      "                ",
      "                "
    ],
    [
      "                ",
      "                ",
      "          c     ",
      "                ",
      "                ",
      "                ",
      "                ",
      "                ",
      "                ",
      "                ",
      "                ",
      "          c     ",
      "                ",
      "                ",
      "                ",
      "                "
    ],
    [
      "        D       ",
      "        D       ",
      "        D c     ",
      "        D       ",
      "        D       ",
      "        D       ",
      "        D       ",
      "        D       ",
      "        D       ",
      "        D       ",
      "        D       ",
      "        D c     ",
      "        D       ",
      "        D       ",
      "        D       ",
      "        D       "
    ],
    [
      "       EEEFFFFFF",
      "       EEEFFFFFF",
      "       EEEcFFFFF",
      "       EEEFFFFFF",
      "       EEEFFFFFF",
      "       EEEFFFFFF",
      "       EEEFFFFFF",
      "       EEEFFFFFF",
      "       EEEFFFFFF",
      "       EEEFFFFFF",
      "       EEEFFFFFF",
      "       EEEcFFFFF",
      "       EEEFFFFFF",
      "       EEEFFFFFF",
      "       EEEFFFFFF",
      "       EEEFFFFFF"
    ],
    [
      "         aIJJJJJ",
      "         aIJJJJJ",
      "         aIJJJJJ",
      "         aIJJJJJ",
      "         aIJJJJJ",
      "         aIJJJJJ",
      "         aIJJJJJ",
      "         aIJJJJJ",
      "         aIJJJJJ",
      "         aIJJJJJ",
      "         aIJJJJJ",
      "         aIJJJJJ",
      "         aIJJJJJ",
      "         aIJJJJJ",
      "         aIJJJJJ",
      "         aIJJJJJ"
    ],
    [
      "          K  L M",
      "          K  L N",
      "          KOPLQM",
      "          K  L  ",
      "          K  L  ",
      "          K  L  ",
      "          K  L  ",
      "          K  L  ",
      "          K  L  ",
      "          K  L  ",
      "          K  L  ",
      "          KOPLQ ",
      "          K  L R",
      "          K  L R",
      "          K  L R",
      "          K  L  "
    ],
    [
      "          K     ",
      "          K     ",
      "          K     ",
      "          K     ",
      "          K     ",
      "          K     ",
      "          K     ",
      "          K     ",
      "          K     ",
      "          K     ",
      "          K     ",
      "          K     ",
      "          K    R",
      "          K  LLL",
      "          K    R",
      "          K     "
    ],
    [
      "                ",
      "                ",
      "                ",
      "                ",
      "                ",
      "                ",
      "                ",
      "                ",
      "                ",
      "                ",
      "                ",
      "                ",
      "               R",
      "               R",
      "               R",
      "                "
    ]
  ]
}