{
  "name": "multi_oasiscondo_1_floor7",
  "refpalette": "deceasedcraft:multi_oasiscondo_1/multi_oasiscondo_1_floor7_palette",
  "xsize": 16,
  "zsize": 16,
  "slices": [
    [
      "         aaaaaab",
      "         caaaaab",
      "          dddddd",
      "         caaaaab",
      "         aaaaaab",
      "         aaaaaab",
      "         aaaaaae",
      "         aaaaaae",
      "         aaaaaab",
      "         aaaaaab",
      "         aaaaaab",
      "         aaaaaab",
      "         aaaaaab",
      "         aaaaaab",
      "         aaaaaab",
      "         aaaaaab"
    ],
    [
      "        bf     b",
      "        ghijklkb",
      "          dddddd",
      "        gbmnmopb",
      "        hqr    b",
      "        hs rr  b",
      "        htuuwx y",
      "        bAAAAB C",
      "        bDEFI  b",
      "        bJ     b",
      "        hKLMN  b",
      "        hOP!PQ b",
      "        R ST Q b",
      "        hU V Q b",
      "        bW  SQ b",
      "        bXYXZQ b"
    ],
    [
      "        b      b",
      "        gb0 1 2b",
      "          dddddd",
      "        3b4 256b",
      "        b      b",
      "        7      b",
      "        78 9#$ %",
      "        7^^^^& *",
      "        7(     b",
      "        7      b",
      "        7) +-  b",
      "        [O]]]Q b",
      "        7    Q b",
      "        7    Q b",
      "        7    Q b",
      "        7X{X}Q b"
    ],
    [
      "        h      b",
      "        gb|;:::b",
      "          dddddd",
      "        gb'''<>b",
      "        h      b",
      "        7      b",
      "        7    $ ,",
      "        7^^^^& ,",
      "        7      b",
      "        7      b",
      "        7.     b",
      "        []]]]Q b",
      "        7    Q b",
      "        7    Q b",
      "        7    Q b",
      "        7X?X/Q b"
    ],
    [
      "        b      b",
      "        3b  `\u0370 b",
      "          dddddd",
      "        gh\u0371\u0372   b",
      "        b      b",
      "        7  \u0373   b",
      "        7    \u0374 b",
      "        7^^^^\u0375 b",
      "        7      b",
      "        7  \u0376   b",
      "        7      b",
      "        []]]]Q b",
      "        7    Q b",
      "        7  \u0376 Q b",
      "        7    Q b",
      "        7XXXXQ b"
    ],
    [
      "        b\u0377\u0377\u0377\u0377\u0377\u0377b",
      "        3h\u0377\u0377\u0377\u0377\u0377b",
      "          dddddd",
      "        3b\u0377\u0377\u0377\u0377\u0377b",
      "        b\u0377\u0377\u0377\u0377\u0377\u0377b",
      "        b\u0377\u0377\u0377\u0377\u0377\u0377b",
      "        b\u0377\u0377\u0377\u0377\u0377\u0377b",
      "        b\u0377\u0377\u0377\u0377\u0377\u0377b",
      "        h\u0377\u0377\u0377\u0377\u0377\u0377b",
      "        h\u0377\u0377\u0377\u0377\u0377\u0377b",
      "        b\u0377\u0377\u0377\u0377\u0377\u0377b",
      "        b\u0377\u0377\u0377\u0377\u0377\u0377b",
      "        b\u0377\u0377\u0377\u0377\u0377\u0377b",
      "        b\u0377\u0377\u0377\u0377\u0377\u0377b",
      "        h\u0377\u0377\u0377\u0377\u0377\u0377b",
      "        b\u0377\u0377\u0377\u0377\u0377\u0377b"
    ]
  ]
}