{
  "name": "multi_oasiscondo_1_base4",
  "refpalette": "deceasedcraft:multi_oasiscondo_1/multi_oasiscondo_1_base4_palette",
  "xsize": 16,
  "zsize": 16,
  "slices": [
    [
      "vaaaaaaaaaaaaaaa",
      "vaaaaaaaaaaaaaaa",
      "vaaaaaaaaaaaaaaa",
      "vaaaaaaaaaaaaaaa",
      "vaaaaaaaaaaaaaaa",
      "vaaaaaaaaaaaaaaa",
      "vaaaaaaaaaaaaaaa",
      "vaaaaaaaaaaaaaaa",
      "vaaaaaaaaaaaaaaa",
      "vaaaaaaaaaaaaaaa",
      "vaaaaaaaaaaaaaaa",
      "vaaaaaaaaaaaaaaa",
      "vaaaaaaaaaaaaaaa",
      "vaaaaaaaaaaaaaaa",
      "vaaaaaaaaaaaaaaa",
      "vaaaaaaaaaaaaaaa"
    ],
    [
      "vaaaaaaaaaaaaaaa",
      "vaaaaaaaaaaaaaaa",
      "vaaaaaaaaabaaaaa",
      "vaaaaaaaaaaaaaaa",
      "vaaaaaaaaaaaaaaa",
      "vaaaaaaaaaaaaaaa",
      "vaaaaaaaaaaaaaaa",
      "vaaaaaaaaaaaaaaa",
      "vaaaaaaaaaaaaaaa",
      "vaaaaaaaaaaaaaaa",
      "vaaaaaaaaaaaaaaa",
      "vaaaaaaaaabaaaaa",
      "vaaaaaaaaaaaaaaa",
      "vaaaaaaaaaaaaaaa",
      "vaaaaaaaaaaaaaaa",
      "vaaaaaaaaaaaaaaa"
    ],
    [
      "vHHHcccccccccccc",
      "vHHHcccccccccccc",
      "vHHHccccccbccccc",
      "vHHHHccccccccccc",
      "vHHHHHHHHHHHHHHH",
      "vHHHHHHHHHHHHHHH",
      "vHHHHHHHHHHHHHHH",
      "vHHHHHHHHHHHHHHH",
      "vHHHHHHHHHHHHHHH",
      "vHHHHHHHHHHHHHHH",
      "vHHHHccccccccccc",
      "vHHHccccccbddddd",
      "vHHHHHHHcvefffff",
      "vHHHHHHHcvefffff",
      "vHHHHHHHcvefffff",
      "vHHHHHHHcvbddddd"
    ],
    [
      "v    ghhhhhhhhhh",
      "v    ijjjjkjjjjj",
      "v    lkkkmblkkkm",
      "v               ",
      "v               ",
      "v               ",
      "v               ",
      "v               ",
      "v               ",
      "v               ",
      "v               ",
      "v   nnnn obppppp",
      "v   q  r v      ",
      "v   s  t v      ",
      "v   q  r v      ",
      "v   s  t vb     "
    ],
    [
      "v               ",
      "v               ",
      "v         b     ",
      "v               ",
      "v               ",
      "v               ",
      "v               ",
      "v               ",
      "v               ",
      "v               ",
      "v               ",
      "v         bppppp",
      "v        v      ",
      "v        v      ",
      "v        v      ",
      "v        vb     "
    ],
    [
      "v               ",
      "v               ",
      "v         b     ",
      "v               ",
      "v               ",
      "v               ",
      "v               ",
      "v               ",
      "v               ",
      "v               ",
      "v               ",
      "v         bppppp",
      "v        v      ",
      "v        v      ",
      "v        v      ",
      "v        vb     "
    ]
  ]
}