{
  "name": "multi_oasiscondo_1_base3",
  "refpalette": "deceasedcraft:multi_oasiscondo_1/multi_oasiscondo_1_base3_palette",
  "xsize": 16,
  "zsize": 16,
  "slices": [
    [
      "v               ",
      "v               ",
      "v         a     ",
      "v               ",
      "v               ",
      "v               ",
      "v               ",
      "v               ",
      "v               ",
      "v               ",
      "v               ",
      "v         abbbbb",
      "v        v      ",
      "v        v      ",
      "v        v      ",
      "v        va     "
    ],
    [
      "v               ",
      "v               ",
      "v         a     ",
      "v               ",
      "v               ",
      "v               ",
      "v               ",
      "v               ",
      "v               ",
      "v               ",
      "v               ",
      "v         abbbbb",
      "v        v      ",
      "v        v      ",
      "v        v      ",
      "v        va     "
    ],
    [
      "v               ",
      "v               ",
      "v         a     ",
      "v               ",
      "v               ",
      "v               ",
      "v               ",
      "v               ",
      "v               ",
      "v               ",
      "v               ",
      "v         abbbbb",
      "v        v      ",
      "v        v      ",
      "v        v      ",
      "v        va     "
    ],
    [
      "v               ",
      "v               ",
      "v         a     ",
      "v               ",
      "v               ",
      "v               ",
      "v               ",
      "v               ",
      "v               ",
      "v               ",
      "v               ",
      "v         abbbbb",
      "v        v      ",
      "v        v      ",
      "v        v      ",
      "v        va     "
    ],
    [
      "v               ",
      "v               ",
      "v         a     ",
      "v               ",
      "v               ",
      "v               ",
      "v               ",
      "v               ",
      "v               ",
      "v               ",
      "v               ",
      "v         abbbbb",
      "v        v      ",
      "v        v      ",
      "v        v      ",
      "v        va     "
    ],
    [
      "vcccccccccdccccc",
      "vcccccccccdccccc",
      "vdddddddddeddddd",
      "vcccccccccdccccc",
      "vcccccccccdccccc",
      "vcccccccccdccccc",
      "vcccccccccdccccc",
      "vcccccccccdccccc",
      "vcccccccccdccccc",
      "vcccccccccdccccc",
      "vcccccccccdccccc",
      "vdddddddddeddddd",
      "vccccccccvdfffff",
      "vccccccccvdfffff",
      "vccccccccvdfffff",
      "vccccccccveddddd"
    ]
  ]
}