{
  "name": "multi_oasiscondo_1_base2",
  "refpalette": "deceasedcraft:multi_oasiscondo_1/multi_oasiscondo_1_base2_palette",
  "xsize": 16,
  "zsize": 16,
  "slices": [
    [
      "vHHHHHHHHaaHHHHa",
      "vHHHHHHHaaaaHHHa",
      "vHHHHHHHaabaHHHa",
      "vHHHHHHHaaaaHHHH",
      "vHHHHHHHaaaaHHHH",
      "vHHHHHHHaaaaHHHH",
      "vHHHHHHHaaaaHHHH",
      "vHHHHHHHaaaaHHHH",
      "vHHHHHHHaaaaHHHH",
      "vHHHHHHHaaaaHHHH",
      "vHHHHHHHaaaaHHHa",
      "vHHHHHHHaabaHHHa",
      "vHHHHHHHavaaHHHa",
      "vHHHHHHHavaaHHHa",
      "vHHHHHHHavccdddc",
      "vHHHHHHHaveefffe"
    ],
    [
      "vg  h           ",
      "vi  j    kl     ",
      "vg  h    mb     ",
      "vi  j    mn     ",
      "vg  h    mo     ",
      "vi  j    mo     ",
      "vg  h    mo     ",
      "vi  j    mo     ",
      "vg  h    mo     ",
      "vi  j    mo     ",
      "vg  h    pq     ",
      "vi  j    rbsssss",
      "vg  h    v      ",
      "vi  j    v      ",
      "vg  h    v      ",
      "vi  j    v      "
    ],
    [
      "v               ",
      "v               ",
      "v         b     ",
      "v               ",
      "v               ",
      "v               ",
      "v               ",
      "v               ",
      "v               ",
      "v               ",
      "v               ",
      "v         b     ",
      "v        v      ",
      "v        v      ",
      "v        v      ",
      "v        v      "
    ],
    [
      "v               ",
      "v               ",
      "v         b     ",
      "v               ",
      "v               ",
      "v               ",
      "v               ",
      "v               ",
      "v               ",
      "v               ",
      "v               ",
      "v         b     ",
      "v        v      ",
      "v        v      ",
      "v        v      ",
      "v        v      "
    ],
    [
      "v               ",
      "v               ",
      "v         b     ",
      "v               ",
      "v               ",
      "v               ",
      "v               ",
      "v               ",
      "v               ",
      "v               ",
      "v               ",
      "v         b     ",
      "v        v      ",
      "v        v      ",
      "v        v      ",
      "v        v      "
    ],
    [
      "vtttttttttuttttt",
      "vtttttttttuttttt",
      "vuuuuuuuuuwuuuuu",
      "vtttttttttuttttt",
      "vtttttttttuttttt",
      "vtttttttttuttttt",
      "vtttttttttuttttt",
      "vtttttttttuttttt",
      "vtttttttttuttttt",
      "vtttttttttuttttt",
      "vtttttttttuttttt",
      "vuuuuuuuuuwuuuuu",
      "vttttttttvtttttt",
      "vttttttttvtttttt",
      "vttttttttvxxxxxx",
      "vttttttttvyyyyyy"
    ]
  ]
}