{
  "name": "multi_oasiscondo_1_floor5",
  "refpalette": "deceasedcraft:multi_oasiscondo_1/multi_oasiscondo_1_floor5_palette",
  "xsize": 16,
  "zsize": 16,
  "slices": [
    [
      "         aaaaaab",
      "         caaaaab",
      "          dddddd",
      "         caaaaab",
      "         aaaaaae",
      "         aaaaaab",
      "         aaaaaab",
      "         aaaaaab",
      "         aaaaaab",
      "         aaaaaab",
      "         caaaaab",
      "          dddddd",
      "         caaaaab",
      "         aaaaaae",
      "         aaaaaab",
      "         aaaaaab"
    ],
    [
      "        bfg   hb",
      "        ibjklmnb",
      "          dddddd",
      "       ooo pqrsb",
      "       tou pqrwx",
      "       ty    ABb",
      "       ty C  D b",
      "       ty EFIJKb",
      "       ty Lbbbbb",
      "       to  M NOb",
      "       oooPb Qbb",
      "          dddddd",
      "        ibRSTrsb",
      "        bU V r x",
      "        bW   r b",
      "        XYZY0r b"
    ],
    [
      "        b 1    b",
      "        iX234 5b",
      "          dddddd",
      "       ooo   r6b",
      "       7o8   r 9",
      "       7#    A b",
      "       7       b",
      "       7   $BJ b",
      "       7   bbbbb",
      "       7o  %   b",
      "       oooPb^ bb",
      "          dddddd",
      "        iXRSTr&b",
      "        b  V*r 9",
      "        (   )r b",
      "        (Y+Y-r b"
    ],
    [
      "        b 1    b",
      "        [X]{}{}b",
      "          dddddd",
      "       ooo | r;b",
      "        o    r :",
      "        #    A b",
      "        #      b",
      "             '<b",
      "        #  bbbbb",
      "        o  > ,.b",
      "       ooo?b/ bb",
      "          dddddd",
      "        [b  `r;b",
      "        b    r :",
      "        (    r b",
      "        (Y\u0370Y\u0370r b"
    ],
    [
      "        X \u0371    b",
      "        [b\u0372\u0373  \u0374b",
      "          dddddd",
      "       ooo   r\u0375b",
      "        o    r b",
      "        \u0376  \u0377 A b",
      "        \u0376    \u0375 b",
      "        \u0376   \u037a!\u0375b",
      "        \u0376  bbbbb",
      "        o  b\u037b\u037bbb",
      "       ooo\u037cb\u037b\u037bbb",
      "          dddddd",
      "        [b   r b",
      "        b  \u0377 r b",
      "        (    r b",
      "        (YYYYr b"
    ],
    [
      "        b\u037d\u037d\u037d\u037d\u037d\u037db",
      "        iX\u037d\u037d\u037d\u037d\u037db",
      "          dddddd",
      "       ooo\u037d\u037d\u037d\u037d\u037db",
      "       oo\u037d\u037d\u037d\u037d\u037d\u037db",
      "       oo\u037d\u037d\u037d\u037d\u037d\u037db",
      "       oo\u037d\u037d\u037d\u037d<\u037db",
      "       oo\u037d\u037d\u037d\u037d''b",
      "       oo\u037d\u037d\u037d\u037d\u037d\u037db",
      "       oo\u037d\u037d\u037d  \u037db",
      "       ooo\u037d\u037d \u037e\u037db",
      "          dddddd",
      "        ib\u037d\u037d\u037d\u037d\u037db",
      "        X\u037d\u037d\u037d\u037d\u037d\u037db",
      "        b\u037d\u037d\u037d\u037d\u037d\u037db",
      "        b\u037d\u037d\u037d\u037d\u037d\u037db"
    ]
  ]
}