{
  "name": "multi_oasiscondo_1_floor3",
  "refpalette": "deceasedcraft:multi_oasiscondo_1/multi_oasiscondo_1_floor3_palette",
  "xsize": 16,
  "zsize": 16,
  "slices": [
    [
      "         aaaaaab",
      "         caaaadb",
      "          eeeeee",
      "         caaaaab",
      "         aaaaaaf",
      "         aaaaaab",
      "         aaaaaab",
      "         aaaaaab",
      "         aaaaaab",
      "         aaaaaab",
      "         caaaaab",
      "          eeeeee",
      "         caaaaab",
      "         aaaaaaf",
      "         aaaaaab",
      "         aaaaaab"
    ],
    [
      "        bg    hb",
      "        ibjklmnb",
      "          eeeeee",
      "        ibopoqrb",
      "        bs t quw",
      "        b    q b",
      "        xyAyBq b",
      "        bC b  Db",
      "        b  b B b",
      "        bEFbIJKb",
      "        LbMbNOPb",
      "          eeeeee",
      "        ixoQoqrb",
      "        bs RSq w",
      "        xT   q b",
      "        byAyUq b"
    ],
    [
      "        bV    Wb",
      "        ibXYZ01b",
      "          eeee!e",
      "        ix2  q3b",
      "        bs   q 4",
      "        5    q b",
      "        5y6y q b",
      "        5  b   b",
      "        5 7b   b",
      "        b  b899b",
      "        ix#b   b",
      "          eeeeee",
      "        Lb$ %q b",
      "        b^   q 4",
      "        5&   q b",
      "        5y6y*q b"
    ],
    [
      "        b     (b",
      "        Lx))+88b",
      "          eeeeee",
      "        ix   q-b",
      "        x[   q ]",
      "        5    q b",
      "        5y{y{q b",
      "        5} b   b",
      "        5  b  |b",
      "        b  b; :b",
      "        Lb'b   b",
      "          eeeeee",
      "        ix   q-b",
      "        b& < q ]",
      "        5&   q b",
      "        5y{y{q b"
    ],
    [
      "        b      b",
      "        Lx>,   b",
      "          eeeeee",
      "        Lb   q b",
      "        b  . q b",
      "        5    q b",
      "        5yyyyq b",
      "        5??b   b",
      "        5??b   b",
      "        x??b / b",
      "        ix/b   b",
      "          eeeeee",
      "        ib   q b",
      "        b  ` q b",
      "        5&   q b",
      "        5yyyyq b"
    ],
    [
      "        x\u0370\u0370\u0370\u0370\u0370\u0370b",
      "        ib\u0370\u0370\u0370\u0370\u0370b",
      "          eeeeee",
      "        Lb\u0370\u0370\u0370\u0370\u0370b",
      "        x\u0370\u0370\u0370\u0370\u0370\u0370b",
      "        b\u0370\u0370\u0370\u0370\u0370\u0370b",
      "        b\u0370\u0370\u0370\u0370\u0370\u0370b",
      "        x  \u0370\u0370\u0370\u0370b",
      "        b  \u0370\u0370\u0370\u0370b",
      "        b\u0371 \u0370\u0370\u0370\u0370b",
      "        ix\u0370\u0370\u0370\u0370\u0370b",
      "          eeeeee",
      "        Lb\u0370\u0370\u0370\u0370\u0370b",
      "        x\u0370\u0370\u0372\u0370\u0370\u0370b",
      "        b\u0370\u0370\u0370\u0370\u0370\u0370b",
      "        b\u0370\u0370\u0370\u0370\u0370\u0370b"
    ]
  ]
}