{
  "name": "multi_oasiscondo_1_floor6",
  "refpalette": "deceasedcraft:multi_oasiscondo_1/multi_oasiscondo_1_floor6_palette",
  "xsize": 16,
  "zsize": 16,
  "slices": [
    [
      "         aaaaaab",
      "         caaaaab",
      "          dddddd",
      "         caaaaab",
      "         aaaaaab",
      "         aaaaaab",
      "         aaaaaae",
      "         aaaaaae",
      "         aaaaaab",
      "         aaaaaab",
      "         aaaaaab",
      "         aaaaaab",
      "         aaaaaab",
      "         aaaaaab",
      "         aaaaaab",
      "         aaaaaab"
    ],
    [
      "        fg     b",
      "        hbijklkb",
      "          dddddd",
      "        hbmnoppb",
      "        bq    rb",
      "        f      b",
      "        bstuwx y",
      "        bABBCD E",
      "        bF II  b",
      "        fJ     b",
      "        bKkjiL b",
      "        bMMMMN b",
      "        f  OON b",
      "        b    N b",
      "        bO   N b",
      "        fPQPRN b"
    ],
    [
      "        bS     b",
      "        TfU V Wb",
      "          dddddd",
      "        hbXY Z b",
      "        f0     b",
      "        1      b",
      "        12     3",
      "        14 56  7",
      "        18     b",
      "        1      b",
      "        16 9U# b",
      "        $MMMMN b",
      "        1   ON b",
      "        1    N b",
      "        1    N b",
      "        1P%P^N b"
    ],
    [
      "        f      b",
      "        &b*()))b",
      "          dddddd",
      "        hb   ++b",
      "        b0     b",
      "        1      b",
      "        1      -",
      "        1      -",
      "        1      b",
      "        1      b",
      "        1[)[)# b",
      "        $MMMMN b",
      "        1    N b",
      "        1    N b",
      "        1    N b",
      "        1P]P{N b"
    ],
    [
      "        b      b",
      "        Tf} |; b",
      "          dddddd",
      "        Tb++   b",
      "        b0     b",
      "        1  :   b",
      "        1      b",
      "        1      b",
      "        1  '   b",
      "        1      b",
      "        1<>,.? b",
      "        $MMMMN b",
      "        1/   N b",
      "        1  : N b",
      "        1    N b",
      "        1PPPPN b"
    ],
    [
      "        b``````b",
      "        hf`````b",
      "          dddddd",
      "        Tf`````b",
      "        f``````b",
      "        f``````b",
      "        b``````b",
      "        b``````b",
      "        b``````b",
      "        b``````b",
      "        b``````b",
      "        f``````b",
      "        f``````b",
      "        b``````b",
      "        b``````b",
      "        b``````b"
    ]
  ]
}