{
  "name": "multi_oasiscondo_1_base1",
  "refpalette": "deceasedcraft:multi_oasiscondo_1/multi_oasiscondo_1_base1_palette",
  "xsize": 16,
  "zsize": 16,
  "slices": [
    [
      "vHHHHHHHHaaHHHHa",
      "vHHHHHHHaaaaHHHa",
      "vHHHHHHHaabaHHHa",
      "vHHHHHHHaaaaHHHH",
      "vHHHHHHHaaaaHHHH",
      "vHHHHHHHaaaaHHHH",
      "vHHHHHHHaaaaHHHH",
      "vHHHHHHHaaaaHHHH",
      "vHHHHHHHaaaaHHHH",
      "vHHHHHHHaaaaHHHH",
      "vHHHHHHHaaaaHHHa",
      "vHHHHHHHaabaHHHa",
      "vHHHHHHHavaaHHHa",
      "vHHHHHHHavaaHHHa",
      "vHHHHHHHavccdddc",
      "vHHHHHHHaveefffe"
    ],
    [
      "vg  h           ",
      "vi  j    kl     ",
      "vg  h    mb     ",
      "vi  j    mn     ",
      "vg  h    mo     ",
      "vi  j    mo     ",
      "vg  h    mo     ",
      "vi pj    mo     ",
      "vg  h    mo     ",
      "vi  j    mo  q  ",
      "vg  h    rs     ",
      "vi  j    tbuuuuu",
      "vg  h    v      ",
      "vi  j    v      ",
      "vg  h    v      ",
      "vi  j    v      "
    ],
    [
      "v               ",
      "v               ",
      "v         b     ",
      "v               ",
      "v               ",
      "v               ",
      "v               ",
      "v               ",
      "v               ",
      "v               ",
      "v               ",
      "v         b     ",
      "v        v      ",
      "v        v      ",
      "v        v      ",
      "v        v      "
    ],
    [
      "v               ",
      "v               ",
      "v         b     ",
      "v               ",
      "v               ",
      "v               ",
      "v               ",
      "v               ",
      "v               ",
      "v               ",
      "v               ",
      "v         b     ",
      "v        v      ",
      "v        v      ",
      "v        v      ",
      "v        v      "
    ],
    [
      "v               ",
      "v               ",
      "v         b     ",
      "v               ",
      "v               ",
      "v               ",
      "v               ",
      "v               ",
      "v               ",
      "v               ",
      "v               ",
      "v         b     ",
      "v        v      ",
      "v        v      ",
      "v        v      ",
      "v        v      "
    ],
    [
      "vwwwwwwwwwxwwwww",
      "vwwwwwwwwwxwwwww",
      "vxxxxxxxxxyxxxxx",
      "vwwwwwwwwwxwwwww",
      "vwwwwwwwwwxwwwww",
      "vwwwwwwwwwxwwwww",
      "vwwwwwwwwwxwwwww",
      "vwwwwwwwwwxwwwww",
      "vwwwwwwwwwxwwwww",
      "vwwwwwwwwwxwwwww",
      "vwwwwwwwwwxwwwww",
      "vxxxxxxxxxyxxxxx",
      "vwwwwwwwwvwwwwww",
      "vwwwwwwwwvwwwwww",
      "vwwwwwwwwvAAAAAA",
      "vwwwwwwwwvBBBBBB"
    ]
  ]
}