{
  "name": "multi_oasiscondo_1_floor9",
  "refpalette": "deceasedcraft:multi_oasiscondo_1/multi_oasiscondo_1_floor9_palette",
  "xsize": 16,
  "zsize": 16,
  "slices": [
    [
      "         abbbbbc",
      "         abbbbbc",
      "         adbbbbc",
      "         abbbbbc",
      "         abbbbbc",
      "         abbbbbc",
      "         abbbbbc",
      "         abbbbbc",
      "         abbbbbc",
      "         abbbbbc",
      "         ebbbbbc",
      "          dddddd",
      "         eaaaaaf",
      "         aaaaaaf",
      "         aaaaaac",
      "         aaaaaac"
    ],
    [
      "       ghh ijk  ",
      "       ghh  k   ",
      "       ghhd     ",
      "       ghh l    ",
      "       ghhljm   ",
      "       ghh l    ",
      "       ghh      ",
      "       ghh  l   ",
      "       ghh ljl  ",
      "       gnh  l   ",
      "       nnn      ",
      "          dddddd",
      "        ofpqqqrf",
      "        f s t  f",
      "        fu u utw",
      "        fxxxxx y"
    ],
    [
      "       A        ",
      "       A        ",
      "       A  d     ",
      "       A        ",
      "       A        ",
      "       A        ",
      "       A        ",
      "       A        ",
      "       A        ",
      "       An       ",
      "       nnn      ",
      "          dddddd",
      "        BfCsDEFf",
      "        f      f",
      "        I      w",
      "        I      J"
    ],
    [
      "                ",
      "                ",
      "          d     ",
      "                ",
      "                ",
      "                ",
      "                ",
      "                ",
      "                ",
      "        n       ",
      "       nnn      ",
      "          dddddd",
      "        Bf     f",
      "        K      f",
      "        I      w",
      "        I      w"
    ],
    [
      "        L       ",
      "        L       ",
      "        L d     ",
      "        L       ",
      "        L       ",
      "        L       ",
      "        L       ",
      "        L       ",
      "        L       ",
      "        n       ",
      "       nnn      ",
      "          dddddd",
      "        Bf     f",
      "        f      f",
      "        I      f",
      "        I      f"
    ],
    [
      "       nnnMMMMMM",
      "       nnnMMMMMM",
      "       nnndMMMMM",
      "       nnnMMMMMM",
      "       nnnMMMMMM",
      "       nnnMMMMMM",
      "       nnnMMMMMM",
      "       nnnMMMMMM",
      "       nnnMMMMMM",
      "       nnnMMMMMM",
      "       nnnMMMMMM",
      "          dddddd",
      "        BfNNNNNf",
      "        fNNNNNNf",
      "        fNNNNNNf",
      "        fNNNNNNf"
    ]
  ]
}