{
  "name": "multi_oasiscondo_1_ground",
  "refpalette": "deceasedcraft:multi_oasiscondo_1/multi_oasiscondo_1_ground_palette",
  "xsize": 16,
  "zsize": 16,
  "slices": [
    [
      "aaaaaaaaaaaHHHHa",
      "aaaaaaaaaaaaHHHa",
      "bbbbbbbbbbcaHHHa",
      "dddddddddbaaHHHa",
      "deeeeedddbaaHHHa",
      "eefffeeddbaaHHHa",
      "efffffeddbaaHHHa",
      "efffffeddbaaHHHa",
      "efffffeddbaaHHHa",
      "efffffeddbaaHHHa",
      "efffffeddbaaHHHa",
      "efffffeddbcaHHHa",
      "efffffeddbaaHHHa",
      "efffffeddbaaHHHa",
      "efffffeddbgghhhg",
      "efffffeddbiijjji"
    ],
    [
      "                ",
      "                ",
      "         kc     ",
      "        l       ",
      "        m       ",
      "  nnn   m       ",
      " nooon  m       ",
      " nofon  m       ",
      " nofon  m       ",
      " nofon  m       ",
      " nofon  l       ",
      " nofon  lkc     ",
      " nofon  l       ",
      " nofon  m       ",
      " nofon  m       ",
      " nofon  m       "
    ],
    [
      "                ",
      "                ",
      "          c     ",
      "                ",
      "                ",
      "                ",
      "                ",
      "                ",
      "   p            ",
      "                ",
      "                ",
      "   p      c     ",
      "                ",
      "                ",
      "   p            ",
      "                "
    ],
    [
      "                ",
      "                ",
      "          c     ",
      "                ",
      "                ",
      "                ",
      "                ",
      "                ",
      "   m            ",
      "                ",
      "                ",
      "   m      c     ",
      "                ",
      "                ",
      "   m            ",
      "                "
    ],
    [
      "                ",
      "                ",
      "          c     ",
      "                ",
      "                ",
      "                ",
      "                ",
      "                ",
      "   l            ",
      "                ",
      "                ",
      "   l      c     ",
      "                ",
      "                ",
      "   l            ",
      "                "
    ],
    [
      "                ",
      "                ",
      "          c     ",
      "                ",
      "                ",
      "                ",
      "                ",
      "                ",
      "   l            ",
      "                ",
      "                ",
      "   l      c     ",
      "                ",
      "                ",
      "   l            ",
      "                "
    ]
  ]
}