{
  "name": "multi_oasiscondo_1_floor2",
  "refpalette": "deceasedcraft:multi_oasiscondo_1/multi_oasiscondo_1_floor2_palette",
  "xsize": 16,
  "zsize": 16,
  "slices": [
    [
      "         aaaaaab",
      "         caaaaab",
      "          dddddd",
      "         caaaaab",
      "         aaaaaae",
      "         aaaaaab",
      "         aaaaaab",
      "         aaaaaab",
      "         aaaaaab",
      "         aaaaaab",
      "         caaaaab",
      "          dddddd",
      "         caaaaab",
      "         aaaaaae",
      "         aaaaaab",
      "         aaaaaab"
    ],
    [
      "        bf     b",
      "        gbhijkjb",
      "          dddddd",
      "        gb   lmb",
      "        b    l n",
      "        o    l b",
      "        bpqprl b",
      "        bs b   b",
      "        b  b   b",
      "        bt b   b",
      "        gb b   b",
      "          dddddd",
      "        gouwulxb",
      "        by A l n",
      "        o    l b",
      "        opqprl b"
    ],
    [
      "        b      b",
      "        goB   Cb",
      "          dddddd",
      "        go   l b",
      "        b    l D",
      "        E    l b",
      "        EpFpIl b",
      "        E  b   b",
      "        E  b   b",
      "        b  b   b",
      "        goJb  mb",
      "          dddddd",
      "        KbL  l b",
      "        by   l D",
      "        E    l b",
      "        EpFpIl b"
    ],
    [
      "        o      b",
      "        goMNOOOb",
      "          dddddd",
      "        gb  ml b",
      "        b    l P",
      "        E    l b",
      "        EpQpQl b",
      "        E  b   b",
      "        E  b   b",
      "        o  b  mb",
      "        KoRb  mb",
      "          dddddd",
      "        gb   lSb",
      "        b    l P",
      "        ET   l b",
      "        EpQpQl b"
    ],
    [
      "        b      b",
      "        gb     b",
      "          dddddd",
      "        Kb  mlmb",
      "        bm U l b",
      "        E    l b",
      "        Eppppl b",
      "        EVVbm  b",
      "        EVVb  mb",
      "        bVVb U b",
      "        goUb mmb",
      "          dddddd",
      "        go   l b",
      "        b  W l b",
      "        E    l b",
      "        Eppppl b"
    ],
    [
      "        bXXXXXXb",
      "        KbXXXXXb",
      "          dddddd",
      "        goXXXXXb",
      "        oXXXXXXb",
      "        bXXXXXXb",
      "        bXXXXXXb",
      "        b  XXXXb",
      "        o  XXXXb",
      "        bY XXXXb",
      "        KbXXXXXb",
      "          dddddd",
      "        KbXXXXXb",
      "        oXXXXXXb",
      "        bXXXXXXb",
      "        oXXXXXXb"
    ]
  ]
}