{
  "name": "multi_oasiscondo_1_floor4",
  "refpalette": "deceasedcraft:multi_oasiscondo_1/multi_oasiscondo_1_floor4_palette",
  "xsize": 16,
  "zsize": 16,
  "slices": [
    [
      "         aaaaaab",
      "         cadeaab",
      "          ffffff",
      "         caaaaab",
      "         aaaaaag",
      "         aaaaaab",
      "         aaaaaab",
      "         aaaaaab",
      "         aaaaaab",
      "         aaaaaab",
      "         caaaaab",
      "          ffffff",
      "         caaaaab",
      "         aaaaaag",
      "         aaaaaab",
      "         aaaaaab"
    ],
    [
      "        bh    ib",
      "        jbklmnob",
      "          ffffff",
      "       pppqqqrsb",
      "       tp      u",
      "       tw  xyA b",
      "       tw BCDEFb",
      "       tw BCIJKb",
      "       tw Lbbbbb",
      "       tpM N   b",
      "       pppObPQ b",
      "          ffffff",
      "        RbSTUrVb",
      "        bW XYr Z",
      "        b0 11r b",
      "        23435r b"
    ],
    [
      "        b6     b",
      "        j2789 ob",
      "          ffffff",
      "       ppp#$ r%b",
      "       ^p&     *",
      "       ^   () +b",
      "       ^    -  b",
      "       ^    [ ]b",
      "       ^   bbbbb",
      "       ^p  {  }b",
      "       ppp|b; :b",
      "          ffffff",
      "        Rb'<>r b",
      "        2,   r .",
      "        ?/ 11r b",
      "        ?3`3\u0370r b"
    ],
    [
      "        2      b",
      "        jb\u0371\u0371\u0372\u0372ob",
      "          ffffff",
      "       ppp \u0373 r\u0374b",
      "        p\u0375     \u0376",
      "        \u0377     \u037ab",
      "              \u037bb",
      "              \u037cb",
      "        \u0377  bbbbb",
      "        p  \u037d   b",
      "       ppp b+ \u037eb",
      "          ffffff",
      "        jb   r\u0374b",
      "        b    r \u0376",
      "        ?  11r b",
      "        ?3\u037f3\u037fr b"
    ],
    [
      "        b      b",
      "        Rb\u0384\u0385\u0386\u0387\u0388b",
      "          ffffff",
      "       ppp   r b",
      "        p\u0389     b",
      "        \u038a  \u038c  \u038eb",
      "        \u038a     \u038fb",
      "        \u038a     \u0390b",
      "        \u038a  bbbbb",
      "        p  b\u0391\u0391\u0391b",
      "       ppp\u0392b\u0391\u0391\u0391b",
      "          ffffff",
      "        R2   r!b",
      "        b  \u0393 r\u0394b",
      "        ?  11r b",
      "        ?3333r b"
    ],
    [
      "        b\u0395\u0395\u0395\u0395\u0395\u0395b",
      "        j2\u0395\u0395\u0395\u0395\u0395b",
      "          ffffff",
      "       ppp\u0395\u0395\u0395\u0395\u0395b",
      "       pp\u0395\u0395\u0395\u0395\u0395\u0395b",
      "       pp\u0395\u0395\u0395\u0395\u0395\u0395b",
      "       pp\u0395\u0395\u0395\u0395\u0395\u0395b",
      "       pp\u0395\u0395\u0395\u0395\u0395\u0395b",
      "       pp\u0395\u0395\u0395\u0395\u0395\u0395b",
      "       pp\u0395\u0395\u0395   b",
      "       ppp\u0395\u0395  \u0396b",
      "          ffffff",
      "        jb\u0395\u0395\u0395\u0395\u0395b",
      "        2\u0395\u0395\u0395\u0395\u0395\u0395b",
      "        b\u0395\u0395\u0395\u0395\u0395\u0395b",
      "        b\u0395\u0395\u0395\u0395\u0395\u0395b"
    ]
  ]
}