{
  "name": "multi_oasiscondo_1_floor10",
  "refpalette": "deceasedcraft:multi_oasiscondo_1/multi_oasiscondo_1_floor10_palette",
  "xsize": 16,
  "zsize": 16,
  "slices": [
    [
      "         aaaaaab",
      "         caaaaab",
      "          dddddd",
      "         ceeeeef",
      "         aeeeeef",
      "         aeeeeef",
      "         aeeeeef",
      "         aeeeeef",
      "         aeeeeef",
      "         aeeeeef",
      "         aeeeeef",
      "         adbbbbb",
      "         aghhhhb",
      "         aghhhhb",
      "         aghhhhb",
      "         aghhhhb"
    ],
    [
      "        ijkkkk l",
      "        minoopqr",
      "          dddddd",
      "       sssttttt ",
      "       usw xyA  ",
      "       uww      ",
      "       uww      ",
      "       uww      ",
      "       uww      ",
      "       uww      ",
      "       uww      ",
      "       uwwd     ",
      "       uwwBC    ",
      "       uwwBC D  ",
      "       uwwBC D  ",
      "       uwwBC    "
    ],
    [
      "        iE     F",
      "        mI J K r",
      "          dddddd",
      "       sssLLLLL ",
      "       Ms       ",
      "       M        ",
      "       M        ",
      "       M        ",
      "       M        ",
      "       M        ",
      "       M        ",
      "       M  d     ",
      "       M  t     ",
      "       M  t     ",
      "       M  t     ",
      "       M  t     "
    ],
    [
      "        iE     r",
      "        mi     r",
      "          dddddd",
      "       sssLL L  ",
      "        s       ",
      "                ",
      "                ",
      "                ",
      "                ",
      "                ",
      "                ",
      "          d     ",
      "                ",
      "                ",
      "                ",
      "                "
    ],
    [
      "        iE     i",
      "        Ni     i",
      "          dddddd",
      "       sss L    ",
      "        s       ",
      "        O       ",
      "        O       ",
      "        O       ",
      "        O       ",
      "        O       ",
      "        O       ",
      "        O d     ",
      "        O       ",
      "        O       ",
      "        O       ",
      "        O       "
    ],
    [
      "        iPPPPPPi",
      "        miPPPPPi",
      "          dddddd",
      "       sssQQQQQQ",
      "       sssQQQQQQ",
      "       sssQQQQQQ",
      "       sssQQQQQQ",
      "       sssQQQQQQ",
      "       sssQQQQQQ",
      "       sssQQQQQQ",
      "       sssQQQQQQ",
      "       sssdQQQQQ",
      "       sssQQQQQQ",
      "       sssQQQQQQ",
      "       sssQQQQQQ",
      "       sssQQQQQQ"
    ]
  ]
}