{
  "name": "multi_oasiscondo_1_floor8",
  "refpalette": "deceasedcraft:multi_oasiscondo_1/multi_oasiscondo_1_floor8_palette",
  "xsize": 16,
  "zsize": 16,
  "slices": [
    [
      "         aaaaaab",
      "         caaadeb",
      "          fffgdf",
      "         caaaaab",
      "         aaaaaab",
      "         aaaaaab",
      "         aaaaaab",
      "         aaaaaab",
      "         aaaaaab",
      "         aaaaaah",
      "         aaaaaab",
      "         aaaaaab",
      "         aaaaaab",
      "         aaaaaab",
      "         aaaaaab",
      "         aaaaaab"
    ],
    [
      "        bi j  kb",
      "        lbmnop b",
      "          ffqrgf",
      "        lstut!wb",
      "        bx yA  b",
      "        bBC   Db",
      "        bEEEEFEb",
      "        bx IJ Kb",
      "        bL MJ Kb",
      "        sL NJ  O",
      "        sP QR Sb",
      "        b  T  Ub",
      "        sV WX Yb",
      "        b VZ0 Ub",
      "        b     1b",
      "        b232  4b"
    ],
    [
      "        s      b",
      "        lb5    b",
      "          fff67f",
      "        lb8 9#wb",
      "        b$   % b",
      "        ^A     b",
      "        ^EEEE&Eb",
      "        ^   *  b",
      "        ^(  )  b",
      "        ^   +  -",
      "        ^[ !  ]b",
      "        {     }b",
      "        ^  |   b",
      "        ^  ;  :b",
      "        ^      b",
      "        ^2'2  <b"
    ],
    [
      "        b      b",
      "        >b,.???b",
      "          ffffff",
      "        lb  /JJb",
      "        s      b",
      "        ^      b",
      "        ^EEEE`Eb",
      "        ^      b",
      "        ^      b",
      "        ^      \u0370",
      "        ^  T  ]b",
      "        {     \u0371b",
      "        ^     \u0371b",
      "        ^     \u0371b",
      "        ^     \u0372b",
      "        ^2\u03732  ,b"
    ],
    [
      "        b      b",
      "        ls\u0374    b",
      "          ffffff",
      "        >s   \u0375\u0376b",
      "        b\u0377  \u037a  b",
      "        ^      b",
      "        ^EEEEEEb",
      "        ^      b",
      "        ^  \u037a   b",
      "        ^      b",
      "        ^  TT \u037bb",
      "        {     \u037cb",
      "        ^  \u037d  \u037eb",
      "        ^      b",
      "        ^      b",
      "        ^222  \u037fb"
    ],
    [
      "        s\u0384\u0384\u0384\u0384\u0384\u0384b",
      "        >b\u0384\u0384\u0384\u0384\u0384b",
      "          ffffff",
      "        >b\u0384\u0384\u0384\u0384\u0384b",
      "        s\u0384\u0384\u0384\u0384\u0384\u0384b",
      "        b\u0384\u0384\u0384\u0384\u0384\u0384b",
      "        b\u0384\u0384\u0384\u0384\u0384\u0384b",
      "        s\u0384\u0384\u0384\u0384\u0384\u0384b",
      "        b\u0384\u0384\u0384\u0384\u0384\u0384b",
      "        b\u0384\u0384\u0384\u0384\u0384\u0384b",
      "        b\u0384\u0384\u0384\u0384\u0384\u0384b",
      "        s\u0384\u0384\u0384\u0384\u0384\u0384b",
      "        s\u0384\u0384\u0384\u0384\u0384\u0384b",
      "        b\u0384\u0384\u0384\u0384\u0384\u0384b",
      "        b\u0384\u0384\u0384\u0384\u0384\u0384b",
      "        s\u0384\u0384\u0384\u0384\u0384\u0384b"
    ]
  ]
}