{
  "name": "multi_oasiscondo_1_floor11",
  "refpalette": "deceasedcraft:multi_oasiscondo_1/multi_oasiscondo_1_floor11_palette",
  "xsize": 16,
  "zsize": 16,
  "slices": [
    [
      "         abbbbbc",
      "         dbbbbbc",
      "          eeeeee",
      "         daaaaaf",
      "         aaaaaaf",
      "         aaaaaag",
      "         aaaaaag",
      "         aaaaaag",
      "         aaaaaag",
      "         aaaaaag",
      "         aaaaaag",
      "         aeaaaag",
      "         aaaaaag",
      "         aaaaaag",
      "         aaaaaag",
      "         aaaaaag"
    ],
    [
      "       hij      ",
      "       iiikkkkk ",
      "          eeeeee",
      "         llmmmmf",
      "         ln   of",
      "         l pp  q",
      "         lrsst q",
      "         lrsstuw",
      "         lrsstxw",
      "         lrsst q",
      "         l yy Aq",
      "         le   Aq",
      "         l pp Bq",
      "         lr!Ct q",
      "         lrCCtuw",
      "         lrCCtxw"
    ],
    [
      "       Di       ",
      "       iiiEEEEE ",
      "          eeeeee",
      "         ll    f",
      "         lF    f",
      "         l     q",
      "         l     q",
      "         l  I J ",
      "         l    K ",
      "         l     q",
      "         l    Lq",
      "         le   Lq",
      "         l    Lq",
      "         l     q",
      "         l    J ",
      "         l    K "
    ],
    [
      "        i       ",
      "       iiiEE E  ",
      "          eeeeee",
      "         ll    f",
      "         l     f",
      "         l     q",
      "         l     q",
      "         l     q",
      "         l     q",
      "         l     q",
      "         l    Lq",
      "         le   Lq",
      "         l    Lq",
      "         l     q",
      "         l     q",
      "         l     q"
    ],
    [
      "        i       ",
      "       iii E    ",
      "          eeeeee",
      "         ll    f",
      "         l     f",
      "         l     f",
      "         l     f",
      "         l     f",
      "         l     f",
      "         l     f",
      "         l     f",
      "         le    f",
      "         l     f",
      "         l     f",
      "         l     f",
      "         l     f"
    ],
    [
      "       iiiMMMMMM",
      "       iiiMMMMMM",
      "          eeeeee",
      "         llMMMMf",
      "         lMMMMMf",
      "         lMMMMMf",
      "         lMMMMMf",
      "         lMMMMMf",
      "         lMMMMMf",
      "         lMMMMMf",
      "         lMMMMMf",
      "         leMMMMf",
      "         lMMMMMf",
      "         lMMMMMf",
      "         lMMMMMf",
      "         lMMMMMf"
    ]
  ]
}