{
  "name": "multi_sunkenclub_6_ground",
  "refpalette": "deceasedcraft:multi_sunkenclub_6/multi_sunkenclub_6_ground_palette",
  "xsize": 16,
  "zsize": 16,
  "slices": [
    [
      "aaaaaaaaaaaaaaaa",
      "bbcbbdbbbcccccca",
      "bbcbdbbbbceeeeca",
      " fcbbbbdbceeeeca",
      "  cbbdbbbceeeeca",
      "  cbbbdbbceeeeca",
      "  cbbddbacggggca",
      "  cbddbbbceeeeca",
      "  cbbdbbbceeeeca",
      "  cbdbdbbceeeeca",
      "  cbddbbbceeeeca",
      "  cbbddbbceeeeca",
      "  cbbbdbbceeeeca",
      "  cbbdbbacggggca",
      "  cbbddbbceeeeca",
      "  cbbbdbbceeeeca"
    ],
    [
      "~~~~~~~~~~~~~~~~",
      "hij~~~~~~jjjjjj~",
      "~ij~~~~~~jiiiij~",
      "~ij~~~~~~ji~~ij~",
      "~ij~~~~~~ji~~ij~",
      "~ij~~~~~~ji~~ij~",
      "~ik~~~~~lki~~ik~",
      "~ij~~~~~~ji~~ij~",
      "~ij~~~~~~ji~~ij~",
      "~ijm~~~~~ji~~ij~",
      "~ijn~~~~~ji~~ij~",
      "~ij~~~~~~ji~~ij~",
      "~ij~~~~~~ji~~ij~",
      "~ik~~~~~lki~~ik~",
      "~ij~~~~~~ji~~ij~",
      "~ij~~~~~~ji~~ij~"
    ],
    [
      "~~~~~~~~~~~~~~~~",
      "~~~~~~~~~~~~~~~~",
      "~~~~~~~~~~~~~~~~",
      "~~~~~~~~~~~~~~~~",
      "~~~~~~~~~~~~~~~~",
      "~~~~~~~~~~~~~~~~",
      "~~o~~~~~~~~~~~o~",
      "~~~~~~~~~~~~~~~~",
      "~~~~~~~~~~~~~~~~",
      "~~~~~~~~~~~~~~~~",
      "~~~~~~~~~~~~~~~~",
      "~~~~~~~~~~~~~~~~",
      "~~~~~~~~~~~~~~~~",
      "~~~~~~~~~o~~~~~~",
      "~~~~~~~~~~~~~~~~",
      "~~~~~~~~~~~~~~~~"
    ],
    [
      "~~~~~~~~~~~~~~~~",
      "~~~~~~~~~~~~~~~~",
      "~~~~~~~~~~~~~~~~",
      "~~~~~~~~~~~~~~~~",
      "~~~~~~~~~~~~~~~~",
      "~~~~~~~~~~~~~~~~",
      "~~~~~~~~~~~~~~~~",
      "~~~~~~~~~~~~~~~~",
      "~~~~~~~~~~~~~~~~",
      "~~~~~~~~~~~~~~~~",
      "~~~~~~~~~~~~~~~~",
      "~~~~~~~~~~~~~~~~",
      "~~~~~~~~~~~~~~~~",
      "~~~~~~~~~~~~~~~~",
      "~~~~~~~~~~~~~~~~",
      "~~~~~~~~~~~~~~~~"
    ],
    [
      "~~~~~~~~~~~~~~~~",
      "~~~~~~~~~~~~~~~~",
      "~~~~~~~~~~~~~~~~",
      "~~~~~~~~~~~~~~~~",
      "~~~~~~~~~~~~~~~~",
      "~~~~~~~~~~~~~~~~",
      "~~~~~~~~~~~~~~~~",
      "~~~~~~~~~~~~~~~~",
      "~~~~~~~~~~~~~~~~",
      "~~~~~~~~~~~~~~~~",
      "~~~~~~~~~~~~~~~~",
      "~~~~~~~~~~~~~~~~",
      "~~~~~~~~~~~~~~~~",
      "~~~~~~~~~~~~~~~~",
      "~~~~~~~~~~~~~~~~",
      "~~~~~~~~~~~~~~~~"
    ],
    [
      "~~~~~~~~~~~~~~~~",
      "~~~~~~~~~~~~~~~~",
      "~~~~~~~~~~~~~~~~",
      "~~~~~~~~~~~~~~~~",
      "~~~~~~~~~~~~~~~~",
      "~~~~~~~~~~~~~~~~",
      "~~~~~~~~~~~~~~~~",
      "~~~~~~~~~~~~~~~~",
      "~~~~~~~~~~~~~~~~",
      "~~~~~~~~~~~~~~~~",
      "~~~~~~~~~~~~~~~~",
      "~~~~~~~~~~~~~~~~",
      "~~~~~~~~~~~~~~~~",
      "~~~~~~~~~~~~~~~~",
      "~~~~~~~~~~~~~~~~",
      "~~~~~~~~~~~~~~~~"
    ]
  ]
}