{
  "name": "multi_storageyard_1_ground",
  "refpalette": "deceasedcraft:multi_storageyard_1/multi_storageyard_1_ground_palette",
  "xsize": 16,
  "zsize": 16,
  "slices": [
    [
      "zzz=zz======z=zz",
      "azzzzzz======bzz",
      "bzzzzzz===b==zbz",
      "bzzzzzz==bb=bz=z",
      "zzzzzzz=cbbzbb=z",
      "zzzzzzz=cbzzbbcz",
      "zzzzzzz==b=zbbc=",
      "zzzzzzz==cbzcbb=",
      "zzzzzzz==cbzcbbc",
      "zzzzzzz==cbz=bbc",
      "z=zzzzz==bcz=bbz",
      "b=zzzzz==bzzcbcz",
      "bbzz====zcb=bbcz",
      "bz==zz==cb==bbc=",
      "azz==z=bcbbzzbb=",
      "ababbbazbbbzzbbz"
    ],
    [
      "  ddddd  e  f   ",
      " fghhhg       f ",
      "  giiigj  kkkk  ",
      "  ghhhgj  lmml n",
      " fgiiig   lmml n",
      "fnghhhgn  okkp  ",
      " ngiiign  k  k  ",
      "nnghhhg   k  k  ",
      " ngiiig   okkp  ",
      "f ghhhgn  lmml  ",
      " ngiiign  okkp f",
      "  ghhhg   qqqq  ",
      "  rrrrr f      f",
      "sn  ff          ",
      "snn  n     f    ",
      "sssssssf        "
    ],
    [
      "  dt td         ",
      "  uiuiu         ",
      "  gwxyg   ABBA  ",
      "  uw xue  CDDC  ",
      "  g  Eg   FIIF  ",
      "  J EEun  KIIK  ",
      " ng LEg   MIIN  ",
      " nJ  LJ   MIIN  ",
      "  g  Og   PIIP  ",
      "  J OOu   QIIR  ",
      "  g OOgn   SII  ",
      "  uiuiu   TUUT  ",
      "  rV Vr   W  W  ",
      "s               ",
      "sn              ",
      "sssssss         "
    ],
    [
      "  dt td         ",
      "  uiuiu         ",
      "  g wxg         ",
      "  J   J         ",
      "  g   g         ",
      "  J  Eu         ",
      "  g  Lg         ",
      "  J   J         ",
      "  g   g   XYYX  ",
      "  J  Ou   Z001  ",
      "  g  Og     21  ",
      "  uiJiu  3T44T5 ",
      "  rV Vr         ",
      "                ",
      "                ",
      "                "
    ],
    [
      "  dt td         ",
      "  uiJiu         ",
      "  g   g         ",
      "  J   J         ",
      "  g   g         ",
      "  J   J         ",
      "  g   g         ",
      "  J   J         ",
      "  g   g   X66X  ",
      "  J   J   Z  1  ",
      "  g  Og  78  9# ",
      "  uiJiu  s$$$$s ",
      "  rV Vr         ",
      "                ",
      "                ",
      "                "
    ],
    [
      "  ddddd         ",
      "  g%%%g         ",
      "  giiig         ",
      "  g%%%g         ",
      "  giiig         ",
      "  g%%%g         ",
      "  giiig         ",
      "  g%%%g         ",
      "  giiig   XXXX  ",
      "  g%%%g   ^&*(  ",
      "  giiig   ))))  ",
      "  g%%%g         ",
      "  rrrrr         ",
      "                ",
      "                ",
      "                "
    ]
  ]
}