{
  "name": "multi_flatapartment_1_floor2",
  "refpalette": "deceasedcraft:multi_flatapartment_1/multi_flatapartment_1_floor2_palette",
  "xsize": 16,
  "zsize": 16,
  "slices": [
    [
      "                ",
      "aaabaaabaaaabaaa",
      "cccccccddddddccc",
      "ccccccceeeeeeccc",
      "ccccccceeeeeeccc",
      "cccccccddddddccc",
      "ccccccce  feeccc",
      "ccccccce   eeccc",
      "ccccccce geeeccc",
      "ccccccceeeeeeccc",
      "ccccccceeeeeeccc",
      "cchiccceeeeeeccc",
      "ccjikcceeeeeeccc",
      "ckhhccceeeeeeccc",
      "ahlbaaabaaaabaaa",
      "                "
    ],
    [
      "                ",
      "mnolamabammabama",
      "  p q ra!s sat  ",
      "uu  w xay   aA  ",
      "BCDEFIrays  at  ",
      "JJJa  KbaaaLbM  ",
      "  JaNOPa    aQ  ",
      "  RaS Ta   UaV  ",
      "  Wap XagYZ aX  ",
      "uu0a   1F 2 3   ",
      "4567aaab8 U baaa",
      "9#k j$%a ^  a&*(",
      ")p   + a -N[a   ",
      "  ] p )1   -{   ",
      "n} p|nabammabama",
      "                "
    ],
    [
      "                ",
      ";;p o;oba;;aba;a",
      "       a    a   ",
      "       ay   a   ",
      "       oy   a   ",
      ":::o   baaa'b   ",
      "   a   a    a<  ",
      "  >p  ,a.   a?  ",
      "   a  /aY   a/  ",
      "  `h \u0370 \u0371    \u0372 \u0370 ",
      "  + |aab\u0373  \u0374baaa",
      "     +\u0375a    a\u0376\u0377 ",
      "      \u037aa\u0373  \u0374a\u037b  ",
      "       \u0371    \u037c   ",
      ";    ;aba;;aba;a",
      "                "
    ],
    [
      "                ",
      ";;   ;aba;;aba;a",
      "       o    a   ",
      "       a    a   ",
      "       as   a   ",
      ":::a  \u037dbaaaab\u037e  ",
      "   a   a.   a   ",
      "   a   a\u037f   a   ",
      "   a  /a    a/  ",
      "   a   \u0384    \u0385   ",
      "   \u0386oaab    baaa",
      "       a    a   ",
      "       a    a   ",
      "       \u0384    \u0385   ",
      ";    ;aba;;aba;a",
      "                "
    ],
    [
      "                ",
      "aa\u0386looabaaaabaaa",
      "   a   a    a   ",
      "\u0387  a \u0388 a    a \u0387 ",
      "   a   a    a   ",
      "aaaaaaabaaaabaaa",
      "   a   a\u037f\u0389  a   ",
      "\u038a  a   a    a   ",
      "   a \u038c\u038ea    a\u038e\u038c ",
      "   a   a    a   ",
      "aaaaaaab    baaa",
      "   \u0386   a    a   ",
      "\u038c    \u0388 a    a \u0388 ",
      "       a    a   ",
      "ol\u038f \u038foabaaaabaaa",
      "                "
    ],
    [
      "                ",
      "\u0390\u0390\u0390\u0391\u0390\u0390\u0390\u0391\u0390\u0390\u0390\u0390\u0391\u0390\u0390\u0390",
      "dddddddddddddddd",
      "dddadddaddddaddd",
      "dddadddaddddaddd",
      "aaaaaaaaaaaaaaaa",
      "dddaddda f\u0389 addd",
      "dddaddda    addd",
      "dddaddda ge addd",
      "dddaddda\u0392\u0392\u0392\u0392addd",
      "aaaaaaaaddddaaaa",
      "dddadddaddddaddd",
      "dddadddaddddaddd",
      "dddddddddddddddd",
      "\u0390\u0390\u0390p\u0390\u0390\u0390\u0391\u0390\u0390\u0390\u0390\u0391\u0390\u0390\u0390",
      "                "
    ]
  ]
}