{
  "name": "multi_flatapartment_1_top",
  "refpalette": "deceasedcraft:multi_flatapartment_1/multi_flatapartment_1_top_palette",
  "xsize": 16,
  "zsize": 16,
  "slices": [
    [
      "                ",
      "                ",
      "aaabaaabaaaabaaa",
      "cccccccccccccccc",
      "cccccccccccccccc",
      "cccccccddddddccc",
      "cccccccd  ecdccc",
      "cccccccd   cdccc",
      "cccccccd   cdccc",
      "cccccccdccccdccc",
      "cccccccddddddccc",
      "cccccccccccccccc",
      "cccccccccccccccc",
      "aaabaaabaaaabaaa",
      "                ",
      "                "
    ],
    [
      "                ",
      "                ",
      "fffgfffgffffgfff",
      "   g   g    g   ",
      "                ",
      "       hiiiih   ",
      "       i    j   ",
      "       i   ki   ",
      "       illlki   ",
      "       mn   i   ",
      "       hiiiih   ",
      "                ",
      "   g   g    g   ",
      "fffgfffgffffgfff",
      "                ",
      "                "
    ],
    [
      "                ",
      "                ",
      "                ",
      "                ",
      "                ",
      "       hiooih   ",
      "       i    p   ",
      "       i    i   ",
      "       i    i   ",
      "       q    i   ",
      "       hiooih   ",
      "                ",
      "                ",
      "                ",
      "                ",
      "                "
    ],
    [
      "                ",
      "                ",
      "                ",
      "                ",
      "                ",
      "       hiiiih   ",
      "       iaaaai   ",
      "       iaaaai   ",
      "       iaaaai   ",
      "       iaaaai   ",
      "       hiiiih   ",
      "                ",
      "                ",
      "                ",
      "                ",
      "                "
    ],
    [
      "                ",
      "                ",
      "                ",
      "                ",
      "                ",
      "       r    r   ",
      "        !       ",
      "                ",
      "                ",
      "                ",
      "       r    r   ",
      "                ",
      "                ",
      "                ",
      "                ",
      "                "
    ],
    [
      "                ",
      "                ",
      "                ",
      "                ",
      "                ",
      "                ",
      "                ",
      "                ",
      "                ",
      "                ",
      "                ",
      "                ",
      "                ",
      "                ",
      "                ",
      "                "
    ]
  ]
}