{
  "name": "multi_flatapartment_1_floor1",
  "refpalette": "deceasedcraft:multi_flatapartment_1/multi_flatapartment_1_floor1_palette",
  "xsize": 16,
  "zsize": 16,
  "slices": [
    [
      "                ",
      "aaabaaabaaaabaaa",
      "cccccccddddddccc",
      "ccccccceeeeeeccc",
      "ccccccceeeeeeccc",
      "cccccccddddddccc",
      "ccccccce  feeccc",
      "ccccccce   eeccc",
      "ccccccce geeeccc",
      "ccccccceeeeeeccc",
      "ccccccceeeeeeccc",
      "ccccccceeeeeeccc",
      "ccccccceeeeeeccc",
      "ccccccceeeeeeccc",
      "aaabaaabaaaabaaa",
      "                "
    ],
    [
      "                ",
      "hhabahabahhabaha",
      "      ia!j jak  ",
      "ll    man   ao  ",
      "pqrs  ianj  ak  ",
      "ttta  ubaaawbx  ",
      "  ta  ya    aA  ",
      "  Ba  Ca    aD  ",
      "  Ea  FagI  aF  ",
      "llJa   K    L  M",
      "NOPaaaab    baaa",
      "QRQSTUMa    aVUT",
      "       a    a   ",
      "       K    L   ",
      "hhabahabahhabaha",
      "                "
    ],
    [
      "                ",
      "WWabaWabaWWabaWa",
      "       a    a   ",
      "       an   a   ",
      "       an   a   ",
      "XXXa   baaaYb   ",
      "   a   a    a   ",
      "  Za  0a1   a2  ",
      "   a  3aI   a3  ",
      "   a 4 5    6 47",
      "   aaaab8  9baaa",
      "     # a    a # ",
      "      $a8  9a%  ",
      "       5    6   ",
      "WWabaWabaWWabaWa",
      "                "
    ],
    [
      "                ",
      "WWabaWabaWWabaWa",
      "       a    a   ",
      "       a    a   ",
      "       aj   a   ",
      "XXXa  ^baaaab&  ",
      "   a   a1   a   ",
      "   a   a*   a   ",
      "   a  3a    a3  ",
      "   a   (    )   ",
      "   aaaab    baaa",
      "   +   a    a   ",
      "       a    a   ",
      "       (    )   ",
      "WWabaWabaWWabaWa",
      "                "
    ],
    [
      "                ",
      "aaabaaabaaaabaaa",
      "   a   a    a   ",
      "-  a [ a    a - ",
      "   a   a    a   ",
      "aaaaaaabaaaabaaa",
      "   a   a*]  a   ",
      "{  a   a    a   ",
      "   a }|a    a|} ",
      "   a   a    a   ",
      "aaaaaaab    baaa",
      "   a   a    a   ",
      "}  a [ a    a [ ",
      "   a   a    a   ",
      "aaabaaabaaaabaaa",
      "                "
    ],
    [
      "                ",
      ";;;:;;;:;;;;:;;;",
      "dddddddddddddddd",
      "dddadddaddddaddd",
      "dddadddaddddaddd",
      "aaaaaaaaaaaaaaaa",
      "dddaddda f] addd",
      "dddaddda    addd",
      "dddaddda ge addd",
      "dddaddda''''addd",
      "aaaaaaaaddddaaaa",
      "dddadddaddddaddd",
      "dddadddaddddaddd",
      "dddddddddddddddd",
      ";;;:;;;:;;;;:;;;",
      "                "
    ]
  ]
}