{
  "name": "multi_flatapartment_1_ground",
  "refpalette": "deceasedcraft:multi_flatapartment_1/multi_flatapartment_1_ground_palette",
  "xsize": 16,
  "zsize": 16,
  "slices": [
    [
      "aaabbbbbbbbbbbbb",
      "aaaaaaaabbbbaaaa",
      "aaaaaaaabbbbaaaa",
      "aaaaaaaabbbbaaaa",
      "aaaaaaaabbbbaaaa",
      "acaaaaaaaaaaaaad",
      "ecaaaaaaddddaaaa",
      "fadaaaaaddddaaaa",
      "aaaadaaaddddaaaa",
      "eaaaaaaaddddaaaa",
      "daaaaaaaaaaaaaaa",
      "aaaaaaaaddddaaaa",
      "aaaaaaaaddddaaaa",
      "aaaaaaaaddddaaaa",
      "aaaaaaaaddddaaaa",
      "aaabbbbbddddbbbb"
    ],
    [
      "   ggggg    gggg",
      "   hiiihg  ghiii",
      "   j  klg  gmj  ",
      "    n  lg  gm op",
      " q r  slggggmr  ",
      "   hiiihtttth   ",
      "   j  ku   wxj  ",
      " y r  su   Axr  ",
      "c BC  kuD  Axj  ",
      " E r  suF  Axr  ",
      " I hJJJh    h   ",
      "K  j  kl    mj  ",
      "    L  l    m  M",
      "   r  sl    mr  ",
      "   hJJJh    hJJJ",
      "   ggggg    gggg"
    ],
    [
      "                ",
      "   N   N    N   ",
      "                ",
      "                ",
      "                ",
      "   N   NttttN   ",
      "       u   wx   ",
      "       uD  Ax   ",
      "       uF  Ox   ",
      "       u   Ax   ",
      "   N   N    N   ",
      "                ",
      "                ",
      "                ",
      "   N   N    N   ",
      "                "
    ],
    [
      "                ",
      "  PNP PNP  PNP P",
      "                ",
      "                ",
      "                ",
      "   N   NPPPPN   ",
      "       PD   P   ",
      "       PF   P   ",
      "       P    P   ",
      "       P    P   ",
      "   N   N    N   ",
      "                ",
      "                ",
      "                ",
      "  PNP PNP  PNP P",
      "                "
    ],
    [
      "                ",
      "QQQNQQQNQQQQNQQQ",
      "   R   R    R   ",
      "                ",
      "                ",
      "   N   NttttN   ",
      "       uFS  x   ",
      "       u    x   ",
      "       u    x   ",
      "       u    x   ",
      "   N   N    N   ",
      "                ",
      "                ",
      "   R   R    R   ",
      "QQQNQQQNQQQQNQQQ",
      "                "
    ],
    [
      "                ",
      "QQQQQQQQQQQQQQQQ",
      "aaaaaaaaaaaaaaaa",
      "   a   a    a   ",
      "   a   a    a   ",
      "aaaaaaaNNNNNNaaa",
      "   a   N TS N   ",
      "   a   N    N   ",
      "   a   N    N   ",
      "   a   N    N   ",
      "aaaaaaaNNNNNNaaa",
      "   a   a    a   ",
      "   a   a    a   ",
      "aaaaaaaaaaaaaaaa",
      "QQQQQQQQQQQQQQQQ",
      "                "
    ]
  ]
}