{
  "name": "multi_flatapartment_1_floor3",
  "refpalette": "deceasedcraft:multi_flatapartment_1/multi_flatapartment_1_floor3_palette",
  "xsize": 16,
  "zsize": 16,
  "slices": [
    [
      "                ",
      "aaabaaabaaaabaaa",
      "cccccccddddddccc",
      "ccccccceeeeeeccc",
      "ccccccceeeeeeccc",
      "cccccccddddddccc",
      "ccccccce  feeccc",
      "ccccccce   eeccc",
      "ccccccce geeeccc",
      "ccccccceeeeeeccc",
      "ccccccceeeeeeccc",
      "ccccccceeeeeeccc",
      "ccccccceeeeeeccc",
      "ccccccceeeeeeccc",
      "aaabaaabaaaabaaa",
      "                "
    ],
    [
      "                ",
      "hhabahabahhabaha",
      "      ia!j jak  ",
      "ll    man   ao  ",
      "pqrs  ianj  ak  ",
      "ttta  ubaaawbx  ",
      "  ta  ya    aA  ",
      "  Ba  Ca    aD  ",
      "  Ea  FagI  aF  ",
      "llJa   K        ",
      "LMNaaaab    baaa",
      "OPOQRSTa    aTSR",
      "       a    a   ",
      "       U    V   ",
      "hhabahabahhabaha",
      "                "
    ],
    [
      "                ",
      "WWabaWabaWWabaWa",
      "       a    a   ",
      "       an   a   ",
      "       an   a   ",
      "XXXa   baaaYb   ",
      "   a  Za    a   ",
      "  0a  1a2   a3  ",
      "   a  4aI   a4  ",
      "   a 5 6      5 ",
      "   aaaab7  8baaa",
      "     9 a    a 9 ",
      "      #a7  8a$  ",
      "       %    ^   ",
      "WWabaWabaWWabaWa",
      "                "
    ],
    [
      "                ",
      "WWabaWabaWWabaWa",
      "       a    a   ",
      "       a    a   ",
      "       aj   a   ",
      "XXXa  &baaaab*  ",
      "   a   a2   a   ",
      "   a   a(   a   ",
      "   a  4a    a4  ",
      "   a   )    +   ",
      "   aaaab    baaa",
      "   -   a    a   ",
      "       a    a   ",
      "       )    +   ",
      "WWabaWabaWWabaWa",
      "                "
    ],
    [
      "                ",
      "aaabaaabaaaabaaa",
      "   a   a    a   ",
      "[  a ] a    a [ ",
      "   a   a    a   ",
      "aaaaaaabaaaabaaa",
      "   a   a({  a   ",
      "}  a   a    a   ",
      "   a |;a    a;| ",
      "   a   a    a   ",
      "aaaaaaab    baaa",
      "   a   a    a   ",
      "|  a ] a    a ] ",
      "   a   a    a   ",
      "aaabaaabaaaabaaa",
      "                "
    ],
    [
      "                ",
      ":::':::'::::':::",
      "dddddddddddddddd",
      "dddadddaddddaddd",
      "dddadddaddddaddd",
      "aaaaaaaaaaaaaaaa",
      "dddaddda f{ addd",
      "dddaddda    addd",
      "dddaddda ge addd",
      "dddaddda<<<<addd",
      "aaaaaaaaddddaaaa",
      "dddadddaddddaddd",
      "dddadddaddddaddd",
      "dddddddddddddddd",
      ":::':::'::::':::",
      "                "
    ]
  ]
}