{
  "name": "multi_nuclearpowerplant_24_base2",
  "refpalette": "deceasedcraft:multi_nuclearpowerplant_24/multi_nuclearpowerplant_24_base2_palette",
  "xsize": 16,
  "zsize": 16,
  "slices": [
    [
      " =aa            ",
      "  =ab           ",
      "  =aa           ",
      "   =ac          ",
      "   =aa          ",
      "    =ac         ",
      "    =ac         ",
      "    =ac         ",
      "    =ac         ",
      "    =ac         ",
      "    =ac         ",
      "   =aa          ",
      "   =ac          ",
      "  =aa           ",
      "  =ab           ",
      " =aa            "
    ],
    [
      " =aa            ",
      "  =ab           ",
      "  =aa           ",
      "   =a           ",
      "   =aa          ",
      "    =a          ",
      "    =a          ",
      "    =a          ",
      "    =a          ",
      "    =a          ",
      "    =a          ",
      "   =aa          ",
      "   =a           ",
      "  =aa           ",
      "  =ab           ",
      " =aa            "
    ],
    [
      " =aa            ",
      "  =a            ",
      "  =aa           ",
      "   =a           ",
      "   =aa          ",
      "    =a          ",
      "    =a          ",
      "    =a          ",
      "    =a          ",
      "    =a          ",
      "    =a          ",
      "   =aa          ",
      "   =a           ",
      "  =aa           ",
      "  =a            ",
      " =aa            "
    ],
    [
      " =aa            ",
      "  =a            ",
      "  =aa           ",
      "   =a           ",
      "   =aa          ",
      "    =a          ",
      "    =a          ",
      "    =a          ",
      "    =a          ",
      "    =a          ",
      "    =a          ",
      "   =aa          ",
      "   =a           ",
      "  =aa           ",
      "  =a            ",
      " =aa            "
    ],
    [
      "=aa             ",
      "==ac            ",
      " =aa            ",
      "  =ac           ",
      "  =aa           ",
      "  ==ac          ",
      "   =ac          ",
      "   =ac          ",
      "   =ac          ",
      "   =ac          ",
      "  ==ac          ",
      "  =aa           ",
      "  =ac           ",
      " =aa            ",
      "==ac            ",
      "=aa             "
    ],
    [
      "=aa            d",
      "==ac            ",
      " =aa            ",
      "  =ac           ",
      "  =aa           ",
      "  ==ac          ",
      "   =ac          ",
      "   =ac          ",
      "   =ac          ",
      "   =ac          ",
      "  ==ac          ",
      "  =aa           ",
      "  =ac           ",
      " =aa            ",
      "==ac            ",
      "=aa            d"
    ]
  ]
}