{
  "name": "multi_nuclearpowerplant_24_base1",
  "refpalette": "deceasedcraft:multi_nuclearpowerplant_24/multi_nuclearpowerplant_24_base1_palette",
  "xsize": 16,
  "zsize": 16,
  "slices": [
    [
      "=aa           bc",
      "==ad          bb",
      " =aa           b",
      "  =ad          b",
      "  =aa          b",
      "  ==ad         b",
      "   =ad         b",
      "   =ad         b",
      "   =ad         b",
      "   =ad         b",
      "  ==ad         b",
      "  =aa          b",
      "  =ad          b",
      " =aa           b",
      "==ad          bb",
      "=aa           bc"
    ],
    [
      "=aa           e ",
      "==ad          ee",
      " =aa           e",
      "  =ad          e",
      "  =aa          e",
      "  ==ad         e",
      "   =ad         e",
      "   =ad         e",
      "   =ad         e",
      "   =ad         e",
      "  ==ad         e",
      "  =aa          e",
      "  =ad          e",
      " =aa           e",
      "==ad          ee",
      "=aa           e "
    ],
    [
      "=aa             ",
      "==ad            ",
      " =aa            ",
      "  =ad           ",
      "  =aa           ",
      "  ==ad          ",
      "   =ad          ",
      "   =ad          ",
      "   =ad          ",
      "   =ad          ",
      "  ==ad          ",
      "  =aa           ",
      "  =ad           ",
      " =aa            ",
      "==ad            ",
      "=aa             "
    ],
    [
      "=aa             ",
      "==a             ",
      " =aa            ",
      "  =a            ",
      "  =aa           ",
      "  ==a           ",
      "   =a           ",
      "   =a           ",
      "   =a           ",
      "   =a           ",
      "  ==a           ",
      "  =aa           ",
      "  =a            ",
      " =aa            ",
      "==a             ",
      "=aa             "
    ],
    [
      "=aa             ",
      "==a             ",
      " =aa            ",
      "  =a            ",
      "  =aa           ",
      "  ==a           ",
      "   =a           ",
      "   =a           ",
      "   =a           ",
      "   =a           ",
      "  ==a           ",
      "  =aa           ",
      "  =a            ",
      " =aa            ",
      "==a             ",
      "=aa             "
    ],
    [
      "=aa             ",
      "==a             ",
      " =aa            ",
      "  =a            ",
      "  =aa           ",
      "  ==a           ",
      "   =a           ",
      "   =a           ",
      "   =a           ",
      "   =a           ",
      "  ==a           ",
      "  =aa           ",
      "  =a            ",
      " =aa            ",
      "==a             ",
      "=aa             "
    ]
  ]
}