{
  "name": "multi_nuclearpowerplant_24_base4",
  "refpalette": "deceasedcraft:multi_nuclearpowerplant_24/multi_nuclearpowerplant_24_base4_palette",
  "xsize": 16,
  "zsize": 16,
  "slices": [
    [
      "a  ==bc         ",
      "a   =bb         ",
      "a    =bc        ",
      "a    =bc        ",
      "a    =bb        ",
      "deeeee=bffffffff",
      "      =bc       ",
      "      =bc       ",
      "      =bc       ",
      "      =bc       ",
      "deeeee=bffffffff",
      "a    =bb        ",
      "a    =bc        ",
      "a    =bc        ",
      "a   =bb         ",
      "a  ==bc         "
    ],
    [
      "   ==bc         ",
      "    =bb         ",
      "     =bc        ",
      "     =bc        ",
      "ghhhh=bbiiiiiiii",
      "jjjjjjjjjjjjjjjj",
      "kkkkkk=bllllllll",
      "      =bc       ",
      "      =bc       ",
      "hhhhhh=biiiiiiii",
      "jjjjjjjjjjjjjjjj",
      "gkkkk=bbllllllll",
      "     =bc        ",
      "     =bc        ",
      "    =bb         ",
      "   ==bc         "
    ],
    [
      "   ==b          ",
      "    =bb         ",
      "     =b         ",
      "     =b         ",
      "     =bb        ",
      "     m=bnnnnnnnn",
      "      =b        ",
      "      =b        ",
      "      =b        ",
      "      =b        ",
      "     m=bnnnnnnnn",
      "     =bb        ",
      "     =b         ",
      "     =b         ",
      "    =bb         ",
      "   ==b          "
    ],
    [
      "  =bbo          ",
      "   =bb          ",
      "   ==bc         ",
      "    =bc         ",
      "    =bb         ",
      "     =b         ",
      "     =bc        ",
      "     =bc        ",
      "     =bc        ",
      "     =bc        ",
      "     =b         ",
      "    =bb         ",
      "    =bc         ",
      "   ==bc         ",
      "   =bb          ",
      "  =bbo          "
    ],
    [
      "  =bbo          ",
      "   =bb          ",
      "   ==bc         ",
      "    =bc         ",
      "    =bb         ",
      "     =b         ",
      "     =bc        ",
      "     =bc        ",
      "     =bc        ",
      "     =bc        ",
      "     =b         ",
      "    =bb         ",
      "    =bc         ",
      "   ==bc         ",
      "   =bb          ",
      "  =bbo          "
    ],
    [
      "  =bbo          ",
      "   =bb          ",
      "   ==bc         ",
      "    =bc         ",
      "    =bb         ",
      "     =b         ",
      "     =bc        ",
      "     =bc        ",
      "     =bc        ",
      "     =bc        ",
      "     =b         ",
      "    =bb         ",
      "    =bc         ",
      "   ==bc         ",
      "   =bb          ",
      "  =bbo          "
    ]
  ]
}