{
  "name": "multi_nuclearpowerplant_24_base5",
  "refpalette": "deceasedcraft:multi_nuclearpowerplant_24/multi_nuclearpowerplant_24_base5_palette",
  "xsize": 16,
  "zsize": 16,
  "slices": [
    [
      "       =        ",
      "                ",
      "                ",
      "        =       ",
      "                ",
      "                ",
      "         =      ",
      "                ",
      "                ",
      "         =      ",
      "                ",
      "                ",
      "        =       ",
      "                ",
      "                ",
      "       =        "
    ],
    [
      "      a         ",
      "                ",
      "                ",
      "       b        ",
      "       a        ",
      "        b       ",
      "        a       ",
      "                ",
      "                ",
      "        b       ",
      "        a       ",
      "       b        ",
      "       a        ",
      "                ",
      "                ",
      "      b         "
    ],
    [
      "                ",
      "                ",
      "                ",
      "                ",
      "       =        ",
      "        =       ",
      "                ",
      "                ",
      "                ",
      "                ",
      "        =       ",
      "       =        ",
      "                ",
      "                ",
      "                ",
      "                "
    ],
    [
      "cccccdef        ",
      "cccccdeff       ",
      "ccccccdef       ",
      "ccccccdef       ",
      "ccccccd=ff      ",
      "cccccccd=f      ",
      "cccccccdef      ",
      "cccccccdef      ",
      "cccccccdef      ",
      "cccccccdef      ",
      "cccccccd=f      ",
      "ccccccd=ff      ",
      "ccccccdef       ",
      "ccccccdef       ",
      "cccccdeff       ",
      "cccccdef        "
    ],
    [
      "     =gh        ",
      "     =gg        ",
      "      =gh       ",
      "      =gh       ",
      "      =gg       ",
      "       =gh      ",
      "       =gh      ",
      "       =gh      ",
      "       =gh      ",
      "       =gh      ",
      "       =gh      ",
      "      =gg       ",
      "      =gh       ",
      "      =gh       ",
      "     =gg        ",
      "     =gh        "
    ],
    [
      "i    =g         ",
      "     =gg        ",
      "      =g        ",
      "      =g        ",
      "      =gg       ",
      "i      =g       ",
      "       =g       ",
      "       =g       ",
      "       =g       ",
      "       =g       ",
      "i      =g       ",
      "      =gg       ",
      "      =g        ",
      "      =g        ",
      "     =gg        ",
      "i    =g         "
    ]
  ]
}