{
  "name": "multi_nuclearpowerplant_24_base11",
  "refpalette": "deceasedcraft:multi_nuclearpowerplant_24/multi_nuclearpowerplant_24_base11_palette",
  "xsize": 16,
  "zsize": 16,
  "slices": [
    [
      "a      aa      a",
      "bccccccbbccccccb",
      "b      bb      b",
      "                ",
      "                ",
      "                ",
      "                ",
      "                ",
      "                ",
      "                ",
      "                ",
      "                ",
      "                ",
      "b      bb      b",
      "bccccccbbccccccb",
      "d      dd      d"
    ],
    [
      "a      aa      a",
      "bccccccbbccccccb",
      "b      bb      b",
      "                ",
      "                ",
      "                ",
      "                ",
      "                ",
      "                ",
      "                ",
      "                ",
      "                ",
      "                ",
      "b      bb      b",
      "bccccccbbccccccb",
      "d      dd      d"
    ],
    [
      "a      aa      a",
      "bccccccbbccccccb",
      "effffffeeffffffe",
      "b      bb      b",
      "b      bb      b",
      "b      bb      b",
      "b      bb      b",
      "b      bb      b",
      "b      bb      b",
      "b      bb      b",
      "b      bb      b",
      "b      bb      b",
      "b      bb      b",
      "effffffeeffffffe",
      "bccccccbbccccccb",
      "d      dd      d"
    ],
    [
      "       gg       ",
      "b      bb      b",
      "bccccccbbccccccb",
      "bccccccbbccccccb",
      "bccccccbbccccccb",
      "bhhhhhhbbhhhhhhb",
      "b      bbccccccb",
      "b      bbccccccb",
      "b      bbccccccb",
      "b      bbccccccb",
      "bhhhhhhbbhhhhhhb",
      "b      bbccccccb",
      "b      bbccccccb",
      "b      bbccccccb",
      "b      bb      b",
      "       ii       "
    ],
    [
      "       jj       ",
      "       kk       ",
      "l      ll      l",
      "l      ll      l",
      "l      ll      l",
      "l      ll      l",
      "l      ll      l",
      "l      ll      l",
      "l      ll      l",
      "l      ll      l",
      "l      ll      l",
      "l      ll      l",
      "l      ll      l",
      "l      ll      l",
      "       mm       ",
      "       jj       "
    ],
    [
      "      noon      ",
      "       pp       ",
      "       pp       ",
      "       pp       ",
      "       pp       ",
      "       pp       ",
      "       pp       ",
      "       pp       ",
      "       pp       ",
      "       pp       ",
      "       pp       ",
      "       pp       ",
      "       pp       ",
      "       pp       ",
      "       pp       ",
      "      nqqn      "
    ]
  ]
}