{
  "name": "multi_nuclearpowerplant_24_base3",
  "refpalette": "deceasedcraft:multi_nuclearpowerplant_24/multi_nuclearpowerplant_24_base3_palette",
  "xsize": 16,
  "zsize": 16,
  "slices": [
    [
      "  =aa           ",
      "   =aa          ",
      "   ==a          ",
      "    =a          ",
      "    =aa         ",
      "     =a         ",
      "     =a         ",
      "     =a         ",
      "     =a         ",
      "     =a         ",
      "     =a         ",
      "    =aa         ",
      "    =a          ",
      "   ==a          ",
      "   =aa          ",
      "  =aa           "
    ],
    [
      "  =aa           ",
      "   =aa          ",
      "   ==a          ",
      "    =a          ",
      "    =aa         ",
      "     =a         ",
      "     =a         ",
      "     =a         ",
      "     =a         ",
      "     =a         ",
      "     =a         ",
      "    =aa         ",
      "    =a          ",
      "   ==a          ",
      "   =aa          ",
      "  =aa           "
    ],
    [
      " =aab           ",
      "  =aa           ",
      "  =aac          ",
      "   =ac          ",
      "   =aa          ",
      "    =ac         ",
      "    =ac         ",
      "    =ac         ",
      "    =ac         ",
      "    =ac         ",
      "    =ac         ",
      "   =aa          ",
      "   =ac          ",
      "  =aac          ",
      "  =aa           ",
      " =aab           "
    ],
    [
      " =aab           ",
      "  =aa           ",
      "  =aac          ",
      "   =ac          ",
      "   =aa          ",
      "    =ac         ",
      "    =ac         ",
      "    =ac         ",
      "    =ac         ",
      "    =ac         ",
      "    =ac         ",
      "   =aa          ",
      "   =ac          ",
      "  =aac          ",
      "  =aa           ",
      " =aab           "
    ],
    [
      " =aa            ",
      "  =aa           ",
      "  =aa           ",
      "   =ac          ",
      "   =aa          ",
      "    =ac         ",
      "    =ac         ",
      "    =ac         ",
      "    =ac         ",
      "    =ac         ",
      "    =ac         ",
      "   =aa          ",
      "   =ac          ",
      "  =aa           ",
      "  =aa           ",
      " =aa            "
    ],
    [
      " =aa            ",
      "  =ab           ",
      "  =aa           ",
      "   =ac          ",
      "   =aa          ",
      "    =ac         ",
      "    =ac         ",
      "    =ac         ",
      "    =ac         ",
      "    =ac         ",
      "    =ac         ",
      "   =aa          ",
      "   =ac          ",
      "  =aa           ",
      "  =ab           ",
      " =aa            "
    ]
  ]
}