{
  "name": "multi_nuclearpowerplant_24_base7",
  "refpalette": "deceasedcraft:multi_nuclearpowerplant_24/multi_nuclearpowerplant_24_base7_palette",
  "xsize": 16,
  "zsize": 16,
  "slices": [
    [
      "aaaaaaaabc      ",
      "aaaaaaaabbc     ",
      "aaaaaaaaabc     ",
      "aaaaaaaaabc     ",
      "aaaaaaaaabbc    ",
      "aaaaaaaaaabc    ",
      "aaaaaaaaaabc    ",
      "aaaaaaaaaabc    ",
      "aaaaaaaaaabc    ",
      "aaaaaaaaaabc    ",
      "aaaaaaaaaabc    ",
      "aaaaaaaaabbc    ",
      "aaaaaaaaabc     ",
      "aaaaaaaaabc     ",
      "aaaaaaaabbc     ",
      "aaaaaaaabc      "
    ],
    [
      "aaaaaaaabc      ",
      "aaaaaaaabbc     ",
      "aaaaaaaaabc     ",
      "aaaaaaaaabc     ",
      "aaaaaaaaabbc    ",
      "aaaaaaaaaabc    ",
      "aaaaaaaaaabc    ",
      "aaaaaaaaaabc    ",
      "aaaaaaaaaabc    ",
      "aaaaaaaaaabc    ",
      "aaaaaaaaaabc    ",
      "aaaaaaaaabbc    ",
      "aaaaaaaaabc     ",
      "aaaaaaaaabc     ",
      "aaaaaaaabbc     ",
      "aaaaaaaabc      "
    ],
    [
      "aaaaaaaabc      ",
      "aaaaaaaabbc     ",
      "aaaaaaaaabc     ",
      "aaaaaaaaabc     ",
      "aaaaaaaaabbc    ",
      "aaaaaaaaaad     ",
      "aaaaaaaaaad     ",
      "aaaaaaaaaad     ",
      "aaaaaaaaaad     ",
      "aaaaaaaaaad     ",
      "aaaaaaaaaad     ",
      "aaaaaaaaabbc    ",
      "aaaaaaaaabc     ",
      "aaaaaaaaabc     ",
      "aaaaaaaabbc     ",
      "aaaaaaaabc      "
    ],
    [
      "aaaaaaaabc      ",
      "aaaaaaaabbc     ",
      "aaaaaaaaabc     ",
      "aaaaaaaaabc     ",
      "aaaaaaaaabbc    ",
      "aaaaaaaaaad     ",
      "aaaaaaaaaad     ",
      "aaaaaaaaaad     ",
      "aaaaaaaaaad     ",
      "aaaaaaaaaad     ",
      "aaaaaaaaaad     ",
      "aaaaaaaaabbc    ",
      "aaaaaaaaabc     ",
      "aaaaaaaaabc     ",
      "aaaaaaaabbc     ",
      "aaaaaaaabc      "
    ],
    [
      "aaaaaaaabc      ",
      "aaaaaaaabbc     ",
      "aaaaaaaaabc     ",
      "aaaaaaaaabc     ",
      "aaaaaaaaabbc    ",
      "aaaaaaaaaabc    ",
      "aaaaaaaaaabc    ",
      "aaaaaaaaaabc    ",
      "aaaaaaaaaabc    ",
      "aaaaaaaaaabc    ",
      "aaaaaaaaaabc    ",
      "aaaaaaaaabbc    ",
      "aaaaaaaaabc     ",
      "aaaaaaaaabc     ",
      "aaaaaaaabbc     ",
      "aaaaaaaabc      "
    ],
    [
      "        b eeffff",
      "        bb effff",
      "         b effff",
      "         b gefff",
      "         bb efff",
      "          b efff",
      "          b efff",
      "          b efff",
      "          b efff",
      "          b efff",
      "          b efff",
      "         bb efff",
      "         b gefff",
      "         b effff",
      "        bb effff",
      "        b eeffff"
    ]
  ]
}