{
  "name": "multi_nuclearpowerplant_24_base8",
  "refpalette": "deceasedcraft:multi_nuclearpowerplant_24/multi_nuclearpowerplant_24_base8_palette",
  "xsize": 16,
  "zsize": 16,
  "slices": [
    [
      "aaaabac==defffff",
      "    g  c==deffff",
      "    g  c==deffff",
      "    g  c==deffff",
      "    g   c==defff",
      "aaaabaaac==defff",
      "    h   c==defff",
      "    h   c==defff",
      "    h   c==defff",
      "    h   c==defff",
      "aaaabaaac==defff",
      "    g   c==defff",
      "    g  c==deffff",
      "    g  c==deffff",
      "    g  c==deffff",
      "aaaabac==defffff"
    ],
    [
      "iiiiiiiicj======",
      "iiiiiiiiccj=====",
      "iiiiiiiiicj=====",
      "iiiiiiiiicj=====",
      "iiiiiiiiiccj====",
      "iiiiiiiiiicj====",
      "iiiiiiiiiikjllll",
      "iiiiiiiiiikjllll",
      "iiiiiiiiiikjllll",
      "iiiiiiiiiikjllll",
      "iiiiiiiiiicj====",
      "iiiiiiiiiccj====",
      "iiiiiiiiicj=====",
      "iiiiiiiiicj=====",
      "iiiiiiiiccj=====",
      "iiiiiiiicj======"
    ],
    [
      "mmmmmmmmcnoooooo",
      "mmmmmmmmccnooooo",
      "mmmmmmmmmcnooooo",
      "mmmmmmmmmcnooooo",
      "mmmmmmmmmccnoooo",
      "mmmmmmmmmmcnoooo",
      "mmmmmmmmmmklllll",
      "mmmmmmmmmmmpmmmm",
      "mmmmmmmmmmmpmmmm",
      "mmmmmmmmmmklllll",
      "mmmmmmmmmmcnoooo",
      "mmmmmmmmmccnoooo",
      "mmmmmmmmmcnooooo",
      "mmmmmmmmmcnooooo",
      "mmmmmmmmccnooooo",
      "mmmmmmmmcnoooooo"
    ],
    [
      "mmmmmmmmcnoooooo",
      "mmmmmmmmccnooooo",
      "mmmmmmmmmcnooooo",
      "mmmmmmmmmcnooooo",
      "mmmmmmmmmccnoooo",
      "mmmmmmmmmmcnoooo",
      "mmmmmmmmmmklllll",
      "mmmmmmmmmmklllll",
      "mmmmmmmmmmklllll",
      "mmmmmmmmmmklllll",
      "mmmmmmmmmmcnoooo",
      "mmmmmmmmmccnoooo",
      "mmmmmmmmmcnooooo",
      "mmmmmmmmmcnooooo",
      "mmmmmmmmccnooooo",
      "mmmmmmmmcnoooooo"
    ],
    [
      "mmmmmmmmcjqqrrrr",
      "mmmmmmmmccjqrrrr",
      "mmmmmmmmmcjqrrrr",
      "mmmmmmmmmcjqqrrr",
      "mmmmmmmmmccjqrrr",
      "mmmmmmmmmmcjqrrr",
      "mmmmmmmmmmcjqrrr",
      "mmmmmmmmmmcjqrrr",
      "mmmmmmmmmmcjqrrr",
      "mmmmmmmmmmcjqrrr",
      "mmmmmmmmmmcjqrrr",
      "mmmmmmmmmccjqrrr",
      "mmmmmmmmmcjqqrrr",
      "mmmmmmmmmcjqrrrr",
      "mmmmmmmmccjqrrrr",
      "mmmmmmmmcjqqrrrr"
    ],
    [
      "mmmmmmmmcn      ",
      "mmmmmmmmccn     ",
      "mmmmmmmmmcn     ",
      "mmmmmmmmmcn     ",
      "mmmmmmmmmccn    ",
      "mmmmmmmmmmcn    ",
      "mmmmmmmmmmcn    ",
      "mmmmmmmmmmcn    ",
      "mmmmmmmmmmcn    ",
      "mmmmmmmmmmcn    ",
      "mmmmmmmmmmcn    ",
      "mmmmmmmmmccn    ",
      "mmmmmmmmmcn     ",
      "mmmmmmmmmcn     ",
      "mmmmmmmmccn     ",
      "mmmmmmmmcn      "
    ]
  ]
}