{
  "name": "multi_nuclearpowerplant_24_top",
  "refpalette": "deceasedcraft:multi_nuclearpowerplant_24/multi_nuclearpowerplant_24_top_palette",
  "xsize": 16,
  "zsize": 16,
  "slices": [
    [
      "aab             ",
      "aab             ",
      "=aab            ",
      " =ab            ",
      " =aa            ",
      " =aac           ",
      "  =ac           ",
      "  =ac           ",
      "  =ac           ",
      "  =ac           ",
      " =aac           ",
      " =aa            ",
      " =ab            ",
      "=aab            ",
      "aab             ",
      "aab             "
    ],
    [
      "aab             ",
      "aab             ",
      "=aab            ",
      " =ab            ",
      " =aa            ",
      " =aac           ",
      "  =ac           ",
      "  =ac           ",
      "  =ac           ",
      "  =ac           ",
      " =aac           ",
      " =aa            ",
      " =ab            ",
      "=aab            ",
      "aab             ",
      "aab             "
    ],
    [
      "aa              ",
      "aab             ",
      "=aa             ",
      " =ab            ",
      " =aa            ",
      " =aa            ",
      "  =ac           ",
      "  =ac           ",
      "  =ac           ",
      "  =ac           ",
      " =aa            ",
      " =aa            ",
      " =ab            ",
      "=aa             ",
      "aab             ",
      "aa              "
    ],
    [
      "ab              ",
      "aab             ",
      "=aa             ",
      " =ab            ",
      " =ab            ",
      " =aa            ",
      "  =ac           ",
      "  =ac           ",
      "  =ac           ",
      "  =ac           ",
      " =aa            ",
      " =ab            ",
      " =ab            ",
      "=aa             ",
      "aab             ",
      "ab              "
    ],
    [
      "ab              ",
      "aa              ",
      "=aa             ",
      " =a             ",
      " =ab            ",
      " =aa            ",
      "  =a            ",
      "  =a            ",
      "  =a            ",
      "  =a            ",
      " =aa            ",
      " =ab            ",
      " =a             ",
      "=aa             ",
      "aa              ",
      "ab              "
    ],
    [
      "ab              ",
      "aa              ",
      "=aa             ",
      " =a             ",
      " =ab            ",
      " =aa            ",
      "  =a            ",
      "  =a            ",
      "  =a            ",
      "  =a            ",
      " =aa            ",
      " =ab            ",
      " =a             ",
      "=aa             ",
      "aa              ",
      "ab              "
    ],
    [
      "ab              ",
      "aa              ",
      "=aa             ",
      " =a             ",
      " =ab            ",
      " =aa            ",
      "  =a            ",
      "  =a            ",
      "  =a            ",
      "  =a            ",
      " =aa            ",
      " =ab            ",
      " =a             ",
      "=aa             ",
      "aa              ",
      "ab              "
    ],
    [
      "ab              ",
      "aa              ",
      "=aa             ",
      " =a             ",
      " =ab            ",
      " =aa            ",
      "  =a            ",
      "  =a            ",
      "  =a            ",
      "  =a            ",
      " =aa            ",
      " =ab            ",
      " =a             ",
      "=aa             ",
      "aa              ",
      "ab              "
    ],
    [
      "a               ",
      "aa              ",
      "=aa             ",
      " =a             ",
      " =a             ",
      " =aa            ",
      "  =a            ",
      "  =a            ",
      "  =a            ",
      "  =a            ",
      " =aa            ",
      " =a             ",
      " =a             ",
      "=aa             ",
      "aa              ",
      "a               "
    ],
    [
      "a               ",
      "aa              ",
      "=aa             ",
      " =a             ",
      " =a             ",
      " =aa            ",
      "  =a            ",
      "  =a            ",
      "  =a            ",
      "  =a            ",
      " =aa            ",
      " =a             ",
      " =a             ",
      "=aa             ",
      "aa              ",
      "a               "
    ],
    [
      "a               ",
      "aa              ",
      "=aa             ",
      " =a             ",
      " =a             ",
      " =aa            ",
      "  =a            ",
      "  =a            ",
      "  =a            ",
      "  =a            ",
      " =aa            ",
      " =a             ",
      " =a             ",
      "=aa             ",
      "aa              ",
      "a               "
    ],
    [
      "a               ",
      "aa              ",
      "=aa             ",
      " =a             ",
      " =a             ",
      " =aa            ",
      "  =a            ",
      "  =a            ",
      "  =a            ",
      "  =a            ",
      " =aa            ",
      " =a             ",
      " =a             ",
      "=aa             ",
      "aa              ",
      "a               "
    ],
    [
      "a               ",
      "aa              ",
      "=aa             ",
      " =a             ",
      " =a             ",
      " =aa            ",
      "  =a            ",
      "  =a            ",
      "  =a            ",
      "  =a            ",
      " =aa            ",
      " =a             ",
      " =a             ",
      "=aa             ",
      "aa              ",
      "a               "
    ],
    [
      "a               ",
      "aa              ",
      "=aa             ",
      " =a             ",
      " =a             ",
      " =aa            ",
      "  =a            ",
      "  =a            ",
      "  =a            ",
      "  =a            ",
      " =aa            ",
      " =a             ",
      " =a             ",
      "=aa             ",
      "aa              ",
      "a               "
    ],
    [
      "a               ",
      "aa              ",
      "=aa             ",
      " =a             ",
      " =a             ",
      " =aa            ",
      "  =a            ",
      "  =a            ",
      "  =a            ",
      "  =a            ",
      " =aa            ",
      " =a             ",
      " =a             ",
      "=aa             ",
      "aa              ",
      "a               "
    ],
    [
      "ab              ",
      "aa              ",
      "=aa             ",
      " =a             ",
      " =ab            ",
      " =aa            ",
      "  =a            ",
      "  =a            ",
      "  =a            ",
      "  =a            ",
      " =aa            ",
      " =ab            ",
      " =a             ",
      "=aa             ",
      "aa              ",
      "ab              "
    ],
    [
      "ab              ",
      "aa              ",
      "=aa             ",
      " =a             ",
      " =ab            ",
      " =aa            ",
      "  =a            ",
      "  =a            ",
      "  =a            ",
      "  =a            ",
      " =aa            ",
      " =ab            ",
      " =a             ",
      "=aa             ",
      "aa              ",
      "ab              "
    ],
    [
      "aa              ",
      "aa              ",
      "=aa             ",
      " =a             ",
      " =aa            ",
      " =aa            ",
      "  =a            ",
      "  =a            ",
      "  =a            ",
      "  =a            ",
      " =aa            ",
      " =aa            ",
      " =a             ",
      "=aa             ",
      "aa              ",
      "aa              "
    ],
    [
      "aa              ",
      "aac             ",
      "=aa             ",
      " =ac            ",
      " =aa            ",
      " =aac           ",
      "  =ac           ",
      "  =ac           ",
      "  =ac           ",
      "  =ac           ",
      " =aac           ",
      " =aa            ",
      " =ac            ",
      "=aa             ",
      "aac             ",
      "aa              "
    ],
    [
      "aa              ",
      "aac             ",
      "=aa             ",
      " =ac            ",
      " =aa            ",
      " =aac           ",
      "  =ac           ",
      "  =ac           ",
      "  =ac           ",
      "  =ac           ",
      " =aac           ",
      " =aa            ",
      " =ac            ",
      "=aa             ",
      "aac             ",
      "aa              "
    ],
    [
      "daa             ",
      "dda             ",
      " daa            ",
      "  da            ",
      "  daa           ",
      "  dda           ",
      "   da           ",
      "   da           ",
      "   da           ",
      "   da           ",
      "  dda           ",
      "  daa           ",
      "  da            ",
      " daa            ",
      "dda             ",
      "daa             "
    ]
  ]
}