{
  "name": "multi_nuclearpowerplant_24_ground",
  "refpalette": "deceasedcraft:multi_nuclearpowerplant_24/multi_nuclearpowerplant_24_ground_palette",
  "xsize": 16,
  "zsize": 16,
  "slices": [
    [
      "=aa             ",
      "==a             ",
      " =aa            ",
      "  =a            ",
      "  =aa           ",
      "  ==a           ",
      "   =a           ",
      "   =a           ",
      "   =a           ",
      "   =a           ",
      "  ==a           ",
      "  =aa           ",
      "  =a            ",
      " =aa            ",
      "==a             ",
      "=aa             "
    ],
    [
      "=aa             ",
      "==a             ",
      " =aa            ",
      "  =a            ",
      "  =aa           ",
      "  ==a           ",
      "   =a           ",
      "   =a           ",
      "   =a           ",
      "   =a           ",
      "  ==a           ",
      "  =aa           ",
      "  =a            ",
      " =aa            ",
      "==a             ",
      "=aa             "
    ],
    [
      "=aa             ",
      "==a             ",
      " =aa            ",
      "  =a            ",
      "  =aa           ",
      "  ==a           ",
      "   =a           ",
      "   =a           ",
      "   =a           ",
      "   =a           ",
      "  ==a           ",
      "  =aa           ",
      "  =a            ",
      " =aa            ",
      "==a             ",
      "=aa             "
    ],
    [
      "=aa             ",
      "==a             ",
      " =aa            ",
      "  =a            ",
      "  =aa           ",
      "  ==a           ",
      "   =a           ",
      "   =a           ",
      "   =a           ",
      "   =a           ",
      "  ==a           ",
      "  =aa           ",
      "  =a            ",
      " =aa            ",
      "==a             ",
      "=aa             "
    ],
    [
      "=aa             ",
      "==a             ",
      " =aa            ",
      "  =a            ",
      "  =aa           ",
      "  ==a           ",
      "   =a           ",
      "   =a           ",
      "   =a           ",
      "   =a           ",
      "  ==a           ",
      "  =aa           ",
      "  =a            ",
      " =aa            ",
      "==a             ",
      "=aa             "
    ],
    [
      "aab             ",
      "aab             ",
      "=aab            ",
      " =ab            ",
      " =aa            ",
      " =aac           ",
      "  =ac           ",
      "  =ac           ",
      "  =ac           ",
      "  =ac           ",
      " =aac           ",
      " =aa            ",
      " =ab            ",
      "=aab            ",
      "aab             ",
      "aab             "
    ]
  ]
}