{
  "name": "multi_nuclearpowerplant_24_base9",
  "refpalette": "deceasedcraft:multi_nuclearpowerplant_24/multi_nuclearpowerplant_24_base9_palette",
  "xsize": 16,
  "zsize": 16,
  "slices": [
    [
      "                ",
      "                ",
      "                ",
      "                ",
      "                ",
      "                ",
      "                ",
      "                ",
      "                ",
      "                ",
      "                ",
      "                ",
      "                ",
      "                ",
      "                ",
      "                "
    ],
    [
      "                ",
      "                ",
      "                ",
      "                ",
      "                ",
      "                ",
      "                ",
      "                ",
      "                ",
      "                ",
      "                ",
      "                ",
      "                ",
      "                ",
      "                ",
      "                "
    ],
    [
      "                ",
      "                ",
      "                ",
      "                ",
      "                ",
      "                ",
      "                ",
      "                ",
      "                ",
      "                ",
      "                ",
      "                ",
      "                ",
      "                ",
      "                ",
      "                "
    ],
    [
      "aaaaaaaa        ",
      "aaaaaaaaa       ",
      "aaaaaaaaa       ",
      "aaaaaaaaa       ",
      "aaaaaaaaaa      ",
      "aaaaaaaaaa      ",
      "aaaaaaaaaa      ",
      "aaaaaaaaaa      ",
      "aaaaaaaaaa      ",
      "aaaaaaaaaa      ",
      "aaaaaaaaaa      ",
      "aaaaaaaaaa      ",
      "aaaaaaaaa       ",
      "aaaaaaaaa       ",
      "aaaaaaaaa       ",
      "aaaaaaaa        "
    ],
    [
      "b  cdbef        ",
      "    g  ef       ",
      "       ef       ",
      "       ef       ",
      "    h   ef      ",
      "b  cdb  ef      ",
      "    g   ef      ",
      "        ef      ",
      "        ef      ",
      "    h   ef      ",
      "b  cdb  ef      ",
      "    g   ef      ",
      "       ef       ",
      "       ef       ",
      "    h  ef       ",
      "b  cdbef        "
    ],
    [
      "    d e=f       ",
      "       e=f      ",
      "       e=f      ",
      "       e=f      ",
      "        e=f     ",
      "    d   e=f     ",
      "        e=f     ",
      "        e=f     ",
      "        e=f     ",
      "        e=f     ",
      "    d   e=f     ",
      "        e=f     ",
      "       e=f      ",
      "       e=f      ",
      "       e=f      ",
      "    d e=f       "
    ]
  ]
}