{
  "name": "multi_oasiscondo_15_ground",
  "refpalette": "deceasedcraft:multi_oasiscondo_15/multi_oasiscondo_15_ground_palette",
  "xsize": 16,
  "zsize": 16,
  "slices": [
    [
      "aaaaaabccccccccc",
      "aaaaaabccccccccc",
      "aaaaaabccccccccc",
      "aaaaaabcccdddccc",
      "aaaaabbccdddddcc",
      "aaaabebcdddddddc",
      "bbbbbbccdddddddc",
      "cccccccddddddddc",
      "cccccddddddddddc",
      "ccccdddddddddddc",
      "cccddddddddddddc",
      "cccddddddddddddc",
      "cccddddddddddddc",
      "ccccddddddddddcc",
      "cccccddddddddccc",
      "cccccccccccccccc"
    ],
    [
      " f  g h         ",
      "f  g gh         ",
      " i  g h         ",
      "  j   h   kkk   ",
      "l i  hh  kmmmk  ",
      " i  he  kmnnnmk ",
      "hhhhho  kmnnnmk ",
      "       kmnnnnmk ",
      "     kkmnnnnnmk ",
      "    kmmnnnnnnmk ",
      "   kmnnnnnnnnmk ",
      "   kmnnnnnnnnmk ",
      "   kmnnnnnnnnmk ",
      "    kmmmmmmmmk  ",
      "     kkkkkkkk   ",
      "                "
    ],
    [
      "      h         ",
      "      h         ",
      "      h         ",
      "      h         ",
      "     hh         ",
      "    he          ",
      "hhhhh           ",
      "                ",
      "                ",
      "                ",
      "                ",
      "                ",
      "                ",
      "                ",
      "                ",
      "                "
    ],
    [
      "      h         ",
      "      h         ",
      "      h         ",
      "      h         ",
      "     hh         ",
      "    he          ",
      "hhhhh           ",
      "                ",
      "                ",
      "                ",
      "                ",
      "                ",
      "                ",
      "                ",
      "                ",
      "                "
    ],
    [
      "      h         ",
      "      h         ",
      "      h         ",
      "      h         ",
      "     hh         ",
      "    he          ",
      "hhhhh           ",
      "                ",
      "                ",
      "                ",
      "                ",
      "                ",
      "                ",
      "                ",
      "                ",
      "                "
    ],
    [
      "      h         ",
      "      h         ",
      "      h         ",
      "      h         ",
      "     hh         ",
      "    he          ",
      "hhhhh           ",
      "                ",
      "                ",
      "                ",
      "                ",
      "                ",
      "                ",
      "                ",
      "                ",
      "                "
    ]
  ]
}