{
  "name": "multi_oasiscondo_15_floor4",
  "refpalette": "deceasedcraft:multi_oasiscondo_15/multi_oasiscondo_15_floor4_palette",
  "xsize": 16,
  "zsize": 16,
  "slices": [
    [
      "abbbbbb         ",
      "bbbbbbb         ",
      "bbbbbbb         ",
      "bbbbbbc         ",
      "bbbbbbc         ",
      "bbbbbd          ",
      "bbbee           ",
      "                ",
      "                ",
      "                ",
      "                ",
      "                ",
      "                ",
      "                ",
      "                ",
      "               f"
    ],
    [
      "aghi jkl        ",
      "i   j mn        ",
      "oppqpprl        ",
      " s   tuw        ",
      " xy  Aa         ",
      "Bxy Cd          ",
      "DEala           ",
      "lalF            ",
      "                ",
      "                ",
      "                ",
      "                ",
      "                ",
      "                ",
      "                ",
      "                "
    ],
    [
      "aI    JK        ",
      "      !L        ",
      "MppNppKK        ",
      " O  P K         ",
      " xQ  Rl         ",
      " xS  d          ",
      "TxKKl           ",
      "KKK             ",
      "                ",
      "                ",
      "                ",
      "                ",
      "                ",
      "                ",
      "                ",
      "                "
    ],
    [
      "a      K        ",
      "       K        ",
      "UppUppKK        ",
      " V    K         ",
      " xW  Xa         ",
      " xY  d          ",
      " xKKa           ",
      "KKK             ",
      "                ",
      "                ",
      "                ",
      "                ",
      "                ",
      "                ",
      "                ",
      "                "
    ],
    [
      "a Z  Z K        ",
      "       K        ",
      "ppppppKK        ",
      " x000 K         ",
      " x0001l         ",
      " x000d          ",
      " xKKl           ",
      "KKK             ",
      "                ",
      "                ",
      "                ",
      "                ",
      "                ",
      "                ",
      "                ",
      "                "
    ],
    [
      "a222222a        ",
      "2222222a        ",
      "222222al        ",
      "22   2a3        ",
      "22   2a         ",
      "22  4d          ",
      "22aaa           ",
      "all5            ",
      "                ",
      "                ",
      "                ",
      "                ",
      "                ",
      "                ",
      "                ",
      "                "
    ]
  ]
}