{
  "name": "multi_oasiscondo_15_base2",
  "refpalette": "deceasedcraft:multi_oasiscondo_15/multi_oasiscondo_15_base2_palette",
  "xsize": 16,
  "zsize": 16,
  "slices": [
    [
      "HHHHHHHHHHHHHHHv",
      "HHHHHHHHHHHHHHHv",
      "HHHHHHHHHHHHHHHv",
      "HHHHHHHHHHHHHHHv",
      "HHHHHHHHHHHHHHHv",
      "HHHHHaHHHHHHHHHv",
      "HHHHHHHHHHHHHHHv",
      "HHHHHHHHHHHHHHHv",
      "HHHHHHHHHHHHHHHv",
      "HHHHHHHHHHHHHHHv",
      "HHHHHHHHHHHHHHHv",
      "HHHHHHHHHHHHHHHv",
      "HHHHHHHHHHHHHHHv",
      "HHHHHHHHHHHHHHHv",
      "HHHHHHHHHHHbbbbv",
      "vvvvvvvvvvvvvvvv"
    ],
    [
      "           c  dv",
      "           e  fv",
      "           c  dv",
      "           e  fv",
      "           c  dv",
      "     a     e  fv",
      "           c  dv",
      "           e  fv",
      "           c  dv",
      "           e  fv",
      "           c  dv",
      "           e  fv",
      "           c  dv",
      "           e  fv",
      "           ggggv",
      "vvvvvvvvvvvvvvvv"
    ],
    [
      "               v",
      "               v",
      "               v",
      "               v",
      "               v",
      "     a         v",
      "               v",
      "               v",
      "               v",
      "               v",
      "               v",
      "               v",
      "               v",
      "               v",
      "               v",
      "vvvvvvvvvvvvvvvv"
    ],
    [
      "               v",
      "               v",
      "               v",
      "               v",
      "               v",
      "     a         v",
      "               v",
      "               v",
      "               v",
      "               v",
      "               v",
      "               v",
      "               v",
      "               v",
      "               v",
      "vvvvvvvvvvvvvvvv"
    ],
    [
      "               v",
      "               v",
      "               v",
      "               v",
      "               v",
      "     a         v",
      "               v",
      "               v",
      "               v",
      "               v",
      "               v",
      "               v",
      "               v",
      "               v",
      "               v",
      "vvvvvvvvvvvvvvvv"
    ],
    [
      "hhhhhihhhhhhhhhv",
      "hhhhhihhhhhhhhhv",
      "hhhhhihhhhhhhhhv",
      "hhhhhihhhhhhhhhv",
      "hhhhhihhhhhhhhhv",
      "iiiiijiiiiiiiiiv",
      "hhhhhihhhhhhhhhv",
      "hhhhhihhhhhhhhhv",
      "hhhhhihhhhhhhhhv",
      "hhhhhihhhhhhhhhv",
      "hhhhhihhhhhhhhhv",
      "hhhhhihhhhhhhhhv",
      "hhhhhihhhhhhhhhv",
      "hhhhhihhhhhhhhhv",
      "hhhhhihhhhhhhhhv",
      "vvvvvvvvvvvvvvvv"
    ]
  ]
}