{
  "name": "multi_oasiscondo_15_floor5",
  "refpalette": "deceasedcraft:multi_oasiscondo_15/multi_oasiscondo_15_floor5_palette",
  "xsize": 16,
  "zsize": 16,
  "slices": [
    [
      "abbcccb         ",
      "bbbcccb         ",
      "bbbcccb         ",
      "bbbbbbd         ",
      "bbbbbbd         ",
      "bbbbbe          ",
      "bbbff           ",
      "                ",
      "                ",
      "                ",
      "                ",
      "                ",
      "                ",
      "                ",
      "                ",
      "                "
    ],
    [
      "a     ga        ",
      "  hi  jk        ",
      "lman  aa        ",
      " oampmkq        ",
      " rst uk         ",
      " w   e          ",
      "xraak           ",
      "kaay            ",
      "                ",
      "                ",
      "                ",
      "                ",
      "                ",
      "                ",
      "                ",
      "                "
    ],
    [
      "a     AB        ",
      "  h   CB        ",
      "Dma   BB        ",
      " oamEmB         ",
      " rF  IJ         ",
      " K  Le          ",
      "MrBBk           ",
      "BBB             ",
      "                ",
      "                ",
      "                ",
      "                ",
      "                ",
      "                ",
      "                ",
      "                "
    ],
    [
      "a      B        ",
      "  h    B        ",
      "Nma   BB        ",
      " OamNmB         ",
      " rP   k         ",
      " Q  Re          ",
      " rBBa           ",
      "BBB             ",
      "                ",
      "                ",
      "                ",
      "                ",
      "                ",
      "                ",
      "                ",
      "                "
    ],
    [
      "a S  S B        ",
      "  h    B        ",
      "mma   BB        ",
      "  ammmB         ",
      " rTTTUa         ",
      " rTTTe          ",
      " rBBa           ",
      "BBB             ",
      "                ",
      "                ",
      "                ",
      "                ",
      "                ",
      "                ",
      "                ",
      "                "
    ],
    [
      "aVVVVVVa        ",
      "VVVVVVVa        ",
      "VVVVVVak        ",
      "VVVVVVaW        ",
      "VV   Va         ",
      "VV  Xe          ",
      "VVaak           ",
      "kaky            ",
      "                ",
      "                ",
      "                ",
      "                ",
      "                ",
      "                ",
      "                ",
      "                "
    ]
  ]
}