{
  "name": "multi_oasiscondo_15_base3",
  "refpalette": "deceasedcraft:multi_oasiscondo_15/multi_oasiscondo_15_base3_palette",
  "xsize": 16,
  "zsize": 16,
  "slices": [
    [
      "abbbaav        v",
      "cdddccv        v",
      "      v        v",
      "      v        v",
      "      v        v",
      "     ev        v",
      "      v        v",
      "      v        v",
      "      v        v",
      "      v        v",
      "      f        v",
      "      f        v",
      "      f        v",
      "      f        v",
      "      f        v",
      "vvvvvvvvvvvvvvvv"
    ],
    [
      "      v        v",
      "      v        v",
      "      v        v",
      "      v        v",
      "      v        v",
      "     ev        v",
      "      v        v",
      "      v        v",
      "      v        v",
      "      v        v",
      "      v        v",
      "      v        v",
      "      v        v",
      "      v        v",
      "      v        v",
      "vvvvvvvvvvvvvvvv"
    ],
    [
      "      v        v",
      "      v        v",
      "      v        v",
      "      v        v",
      "      v        v",
      "     ev        v",
      "      v        v",
      "      v        v",
      "      v        v",
      "      v        v",
      "      v        v",
      "      v        v",
      "      v        v",
      "      v        v",
      "      v        v",
      "vvvvvvvvvvvvvvvv"
    ],
    [
      "      v        v",
      "      v        v",
      "      v        v",
      "      v        v",
      "      v        v",
      "     ev        v",
      "      v        v",
      "      v        v",
      "      v        v",
      "      v        v",
      "      v        v",
      "      v        v",
      "      v        v",
      "      v        v",
      "      v        v",
      "vvvvvvvvvvvvvvvv"
    ],
    [
      "      v        v",
      "      v        v",
      "      v        v",
      "      v        v",
      "      v        v",
      "     ev        v",
      "      v        v",
      "      v        v",
      "      v        v",
      "      v        v",
      "      v        v",
      "      v        v",
      "      v        v",
      "      v        v",
      "      v        v",
      "vvvvvvvvvvvvvvvv"
    ],
    [
      "ggggghvggggggggv",
      "ggggghvggggggggv",
      "ggggghvggggggggv",
      "ggggghvggggggggv",
      "ggggghvggggggggv",
      "hhhhhihhhhhhhhhv",
      "ggggghvggggggggv",
      "ggggghvggggggggv",
      "ggggghvggggggggv",
      "ggggghvggggggggv",
      "ggggghvggggggggv",
      "ggggghvggggggggv",
      "ggggghvggggggggv",
      "ggggghvggggggggv",
      "ggggghvggggggggv",
      "vvvvvvvvvvvvvvvv"
    ]
  ]
}