{
  "name": "multi_oasiscondo_15_floor11",
  "refpalette": "deceasedcraft:multi_oasiscondo_15/multi_oasiscondo_15_floor11_palette",
  "xsize": 16,
  "zsize": 16,
  "slices": [
    [
      "aaaaaab         ",
      "ccccccb         ",
      "ccccccb         ",
      "ccccccd         ",
      "ccccecd         ",
      "cccccf          ",
      "bbbgg           ",
      "                ",
      "                ",
      "                ",
      "                ",
      "                ",
      "                ",
      "                ",
      "                ",
      "                "
    ],
    [
      "      hhi       ",
      "   j  hhi       ",
      "  jkj hhi       ",
      "      hil       ",
      "m   j hi        ",
      "     fll        ",
      "hhhhhll         ",
      "hhhnnl          ",
      "nnnl            ",
      "                ",
      "                ",
      "                ",
      "                ",
      "                ",
      "                ",
      "                "
    ],
    [
      "        o       ",
      "        o       ",
      "        o       ",
      "       oo       ",
      "       o        ",
      "     foo        ",
      "     oo         ",
      "   ooo          ",
      "oooo            ",
      "                ",
      "                ",
      "                ",
      "                ",
      "                ",
      "                ",
      "                "
    ],
    [
      "                ",
      "                ",
      "                ",
      "                ",
      "                ",
      "     f          ",
      "                ",
      "                ",
      "                ",
      "                ",
      "                ",
      "                ",
      "                ",
      "                ",
      "                ",
      "                "
    ],
    [
      "       p        ",
      "       p        ",
      "       p        ",
      "      qp        ",
      "      p         ",
      "     f          ",
      "   rs           ",
      "ssss            ",
      "                ",
      "                ",
      "                ",
      "                ",
      "                ",
      "                ",
      "                ",
      "                "
    ],
    [
      "ttttttlll       ",
      "ttttttlll       ",
      "ttttttlll       ",
      "ttttttlll       ",
      "ttttttll        ",
      "tttttfll        ",
      "lllllll         ",
      "llllll          ",
      "llll            ",
      "                ",
      "                ",
      "                ",
      "                ",
      "                ",
      "                ",
      "                "
    ]
  ]
}