{
  "name": "multi_oasiscondo_15_floor3",
  "refpalette": "deceasedcraft:multi_oasiscondo_15/multi_oasiscondo_15_floor3_palette",
  "xsize": 16,
  "zsize": 16,
  "slices": [
    [
      "abbbbbb         ",
      "bbbbbbb         ",
      "bbbbbbb         ",
      "bbbbbbc         ",
      "bbbbbbc         ",
      "bbbbbd          ",
      "bbbee           ",
      "                ",
      "                ",
      "                ",
      "                ",
      "                ",
      "                ",
      "                ",
      "                ",
      "                "
    ],
    [
      "afgh ijk        ",
      " ll   ma        ",
      "noopooaa        ",
      " qr stau        ",
      " wxryAa         ",
      "BwxyCd          ",
      "DEaaa           ",
      "aakF            ",
      "                ",
      "                ",
      "                ",
      "                ",
      "                ",
      "                ",
      "                ",
      "                "
    ],
    [
      "a I   JK        ",
      "      LK        ",
      "MooNooKK        ",
      " O    K         ",
      " wP  Qk         ",
      " wR  d          ",
      "SwKKa           ",
      "KKK             ",
      "                ",
      "                ",
      "                ",
      "                ",
      "                ",
      "                ",
      "                ",
      "                "
    ],
    [
      "a      K        ",
      "       K        ",
      "TooTooKK        ",
      " U    K         ",
      " wV  Wa         ",
      " wX  d          ",
      " wKKk           ",
      "KKK             ",
      "                ",
      "                ",
      "                ",
      "                ",
      "                ",
      "                ",
      "                ",
      "                "
    ],
    [
      "a Y  Y K        ",
      "       K        ",
      "ooooooKK        ",
      " wZZ0 K         ",
      " wZZZ1a         ",
      " wZZZd          ",
      " wKKa           ",
      "KKK             ",
      "                ",
      "                ",
      "                ",
      "                ",
      "                ",
      "                ",
      "                ",
      "                "
    ],
    [
      "a222222a        ",
      "2222222a        ",
      "222222ak        ",
      "223 32ku        ",
      "2245 2a         ",
      "22 36d          ",
      "22aaa           ",
      "kaaF            ",
      "                ",
      "                ",
      "                ",
      "                ",
      "                ",
      "                ",
      "                ",
      "                "
    ]
  ]
}