{
  "name": "multi_oasiscondo_15_floor10",
  "refpalette": "deceasedcraft:multi_oasiscondo_15/multi_oasiscondo_15_floor10_palette",
  "xsize": 16,
  "zsize": 16,
  "slices": [
    [
      "abbbbbb         ",
      "bbbbbbb         ",
      "bbbbbbb         ",
      "bbbbbbc         ",
      "bbbbbbc         ",
      "bbbbbd          ",
      "bbbee           ",
      "                ",
      "                ",
      "                ",
      "                ",
      "                ",
      "                ",
      "                ",
      "                ",
      "                "
    ],
    [
      "f  g g h        ",
      "  ijkklm        ",
      " n opqmm        ",
      "grs  tmu        ",
      " wx   m         ",
      "gwyA d          ",
      " Bmmm           ",
      "mmhC            ",
      "                ",
      "                ",
      "                ",
      "                ",
      "                ",
      "                ",
      "                ",
      "                "
    ],
    [
      "       D        ",
      "   EFEID        ",
      "     JDD        ",
      " K    D         ",
      " L    m         ",
      " KM  d          ",
      " NDDm           ",
      "DDD             ",
      "                ",
      "                ",
      "                ",
      "                ",
      "                ",
      "                ",
      "                ",
      "                "
    ],
    [
      "O      D        ",
      "       D        ",
      "      DD        ",
      "      D         ",
      "      h         ",
      "     d          ",
      "  DDm           ",
      "DDD             ",
      "                ",
      "                ",
      "                ",
      "                ",
      "                ",
      "                ",
      "                ",
      "                "
    ],
    [
      "m      D        ",
      "       D        ",
      "      DD        ",
      "      D         ",
      "      m         ",
      "     d          ",
      "  DDm           ",
      "DDD             ",
      "                ",
      "                ",
      "                ",
      "                ",
      "                ",
      "                ",
      "                ",
      "                "
    ],
    [
      "mPPPPPPm        ",
      "PPPPPPPm        ",
      "PPPPPPmh        ",
      "PPPPPPmu        ",
      "PPPPPPm         ",
      "PPPPPd          ",
      "PPmmm           ",
      "mmhC            ",
      "                ",
      "                ",
      "                ",
      "                ",
      "                ",
      "                ",
      "                ",
      "                "
    ]
  ]
}