{
  "name": "multi_oasiscondo_15_base4",
  "refpalette": "deceasedcraft:multi_oasiscondo_15/multi_oasiscondo_15_base4_palette",
  "xsize": 16,
  "zsize": 16,
  "slices": [
    [
      "aaaaaaaaaaaaaaav",
      "aaaaaaaaaaaaaaav",
      "aaaaaaaaaaaaaaav",
      "aaaaaaaaaaaaaaav",
      "aaaaaaaaaaaaaaav",
      "aaaaaaaaaaaaaaav",
      "aaaaaaaaaaaaaaav",
      "aaaaaaaaaaaaaaav",
      "aaaaaaaaaaaaaaav",
      "aaaaaaaaaaaaaaav",
      "aaaaaaaaaaaaaaav",
      "aaaaaaaaaaaaaaav",
      "aaaaaaaaaaaaaaav",
      "aaaaaaaaaaaaaaav",
      "aaaaaaaaaaaaaaav",
      "vvvvvvvvvvvvvvvv"
    ],
    [
      "aaaaaaaaaaaaaaav",
      "aaaaaaaaaaaaaaav",
      "aaaaaaaaaaaaaaav",
      "aaaaaaaaaaaaaaav",
      "aaaaaaaaaaaaaaav",
      "aaaaabaaaaaaaaav",
      "aaaaaaaaaaaaaaav",
      "aaaaaaaaaaaaaaav",
      "aaaaaaaaaaaaaaav",
      "aaaaaaaaaaaaaaav",
      "aaaaaaaaaaaaaaav",
      "aaaaaaaaaaaaaaav",
      "aaaaaaaaaaaaaaav",
      "aaaaaaaaaaaaaaav",
      "aaaaaaaaaaaaaaav",
      "vvvvvvvvvvvvvvvv"
    ],
    [
      "aaaaaavcHHHHHHHv",
      "aaaaaavcHHHHHHHv",
      "aaaaaavcHHHHHHHv",
      "aaaaaavcHHHHHHHv",
      "aaaaaavcHHHHHHHv",
      "aaaaabvcHHHHHHHv",
      "aaaaaavcHHHHHHHv",
      "aaaaaavcHHHHHHHv",
      "ddddddvcHHHHHHHv",
      "ddddddvcHHHHHHHv",
      "cHHHccccccccHHHv",
      "HHHHHccccccHHHHv",
      "HHHHHHHHHHHHHHHv",
      "HHHHHHHHHHHHHHHv",
      "HHHHHHHHHHHHHHHv",
      "vvvvvvvvvvvvvvvv"
    ],
    [
      "aaaaaav e  f   v",
      "aaaaaav g  h   v",
      "aaaaaav e  f   v",
      "aaaaaav g  h   v",
      "aaaaaav e  f   v",
      "dddddbv g  h   v",
      "ddddddv e  f   v",
      "ddddddv g  h   v",
      "cHHHccv e  f   v",
      "ijjjiiv g  h   v",
      "klllkkk mmmm   v",
      "               v",
      "               v",
      "               v",
      "               v",
      "vvvvvvvvvvvvvvvv"
    ],
    [
      "aaaaaav        v",
      "aaaaaav        v",
      "ddddddv        v",
      "ddddddv        v",
      "ddddddv        v",
      "cHHHcbv        v",
      "ijjjiiv        v",
      "klllkkv        v",
      "      v        v",
      "      v        v",
      "               v",
      "               v",
      "               v",
      "               v",
      "               v",
      "vvvvvvvvvvvvvvvv"
    ],
    [
      "ddddddv        v",
      "ddddddv        v",
      "cHHHccv        v",
      "ijjjiiv        v",
      "klllkkv        v",
      "     bv        v",
      "      v        v",
      "      v        v",
      "      v        v",
      "      v        v",
      "               v",
      "               v",
      "               v",
      "               v",
      "               v",
      "vvvvvvvvvvvvvvvv"
    ]
  ]
}