{
  "name": "multi_oasiscondo_15_base1",
  "refpalette": "deceasedcraft:multi_oasiscondo_15/multi_oasiscondo_15_base1_palette",
  "xsize": 16,
  "zsize": 16,
  "slices": [
    [
      "HHHHHHHHHHHHHHHv",
      "HHHHHHHHHHHHHHHv",
      "HHHHHHHHHHHHHHHv",
      "HHHHHHHHHHHHHHHv",
      "HHHHHHHHHHHHHHHv",
      "HHHHHaHHHHHHHHHv",
      "HHHHHHHHHHHHHHHv",
      "HHHHHHHHHHHHHHHv",
      "HHHHHHHHHHHHHHHv",
      "HHHHHHHHHHHHHHHv",
      "HHHHHHHHHHHHHHHv",
      "HHHHHHHHHHHHHHHv",
      "HHHHHHHHHHHHHHHv",
      "HHHHHHHHHHHHHHHv",
      "HHHHHHHHHHHbbbbv",
      "vvvvvvvvvvvvvvvv"
    ],
    [
      "           c  dv",
      "           e  fv",
      "           c  dv",
      "           e  fv",
      "           c  dv",
      "     a     e  fv",
      "           c  dv",
      "           eg fv",
      "           c  dv",
      "           e  fv",
      "           c  dv",
      "           e  fv",
      "           c  dv",
      "           e  fv",
      "           hhhhv",
      "vvvvvvvvvvvvvvvv"
    ],
    [
      "               v",
      "               v",
      "               v",
      "               v",
      "               v",
      "     a         v",
      "               v",
      "               v",
      "               v",
      "               v",
      "               v",
      "               v",
      "               v",
      "               v",
      "               v",
      "vvvvvvvvvvvvvvvv"
    ],
    [
      "               v",
      "               v",
      "               v",
      "               v",
      "               v",
      "     a         v",
      "               v",
      "               v",
      "               v",
      "               v",
      "               v",
      "               v",
      "               v",
      "               v",
      "               v",
      "vvvvvvvvvvvvvvvv"
    ],
    [
      "               v",
      "               v",
      "               v",
      "               v",
      "               v",
      "     a         v",
      "               v",
      "               v",
      "               v",
      "               v",
      "               v",
      "               v",
      "               v",
      "               v",
      "               v",
      "vvvvvvvvvvvvvvvv"
    ],
    [
      "iiiiijiiiiiiiiiv",
      "iiiiijiiiiiiiiiv",
      "iiiiijiiiiiiiiiv",
      "iiiiijiiiiiiiiiv",
      "iiiiijiiiiiiiiiv",
      "jjjjjkjjjjjjjjjv",
      "iiiiijiiiiiiiiiv",
      "iiiiijiiiiiiiiiv",
      "iiiiijiiiiiiiiiv",
      "iiiiijiiiiiiiiiv",
      "iiiiijiiiiiiiiiv",
      "iiiiijiiiiiiiiiv",
      "iiiiijiiiiiiiiiv",
      "iiiiijiiiiiiiiiv",
      "iiiiijiiiiiiiiiv",
      "vvvvvvvvvvvvvvvv"
    ]
  ]
}