{
  "name": "multi_oasiscondo_15_floor6",
  "refpalette": "deceasedcraft:multi_oasiscondo_15/multi_oasiscondo_15_floor6_palette",
  "xsize": 16,
  "zsize": 16,
  "slices": [
    [
      "abbbbbb         ",
      "bbbbbbb         ",
      "bbbbbbb         ",
      "bbbbbbc         ",
      "bbbbbbc         ",
      "bbbbbd          ",
      "bbbee           ",
      "                ",
      "                ",
      "                ",
      "                ",
      "                ",
      "                ",
      "                ",
      "                ",
      "               f"
    ],
    [
      "aghij kl        ",
      " mm   na        ",
      "oppqppla        ",
      " r  stau        ",
      " wx  ya         ",
      "Awx Bd          ",
      "CDaaa           ",
      "laaE            ",
      "                ",
      "                ",
      "                ",
      "                ",
      "                ",
      "                ",
      "                ",
      "                "
    ],
    [
      "aFIJK LM        ",
      "      LM        ",
      "NppOppMM        ",
      " P    M         ",
      " wQ  Rl         ",
      " wS  d          ",
      "TwMMl           ",
      "MMM             ",
      "                ",
      "                ",
      "                ",
      "                ",
      "                ",
      "                ",
      "                ",
      "                "
    ],
    [
      "a      M        ",
      "       M        ",
      "UppUppMM        ",
      " V    M         ",
      " wW  Xl         ",
      " wYZ d          ",
      " wMMa           ",
      "MMM             ",
      "                ",
      "                ",
      "                ",
      "                ",
      "                ",
      "                ",
      "                ",
      "                "
    ],
    [
      "a 0  0 M        ",
      "       M        ",
      "ppppppMM        ",
      " w111 M         ",
      " w1112a         ",
      " w111d          ",
      " wMMa           ",
      "MMM             ",
      "                ",
      "                ",
      "                ",
      "                ",
      "                ",
      "                ",
      "                ",
      "                "
    ],
    [
      "a333333a        ",
      "3333333l        ",
      "333333aa        ",
      "33   3a4        ",
      "33   3a         ",
      "33  5d          ",
      "33all           ",
      "laa6            ",
      "                ",
      "                ",
      "                ",
      "                ",
      "                ",
      "                ",
      "                ",
      "                "
    ]
  ]
}