{
  "name": "multi_oasiscondo_15_floor8",
  "refpalette": "deceasedcraft:multi_oasiscondo_15/multi_oasiscondo_15_floor8_palette",
  "xsize": 16,
  "zsize": 16,
  "slices": [
    [
      "abbbbbb         ",
      "bbbbbbb         ",
      "bbbbbbb         ",
      "bbbbbbc         ",
      "bbbbbbc         ",
      "bbbbbd          ",
      "bbbee           ",
      "                ",
      "                ",
      "                ",
      "                ",
      "                ",
      "                ",
      "                ",
      "                ",
      "               f"
    ],
    [
      "aghi jka        ",
      "     jla        ",
      "mnnonnpa        ",
      " q   ras        ",
      " tu  wa         ",
      "xtu yd          ",
      "ABaap           ",
      "apaC            ",
      "                ",
      "                ",
      "                ",
      "                ",
      "                ",
      "                ",
      "                ",
      "                "
    ],
    [
      "aDE   FI        ",
      "      JI        ",
      "KnnLnnII        ",
      " M  N I         ",
      " tO  Pa         ",
      " tQ  d          ",
      "RtIIa           ",
      "III             ",
      "                ",
      "                ",
      "                ",
      "                ",
      "                ",
      "                ",
      "                ",
      "                "
    ],
    [
      "a      I        ",
      "       I        ",
      "SnnSnnII        ",
      " T    I         ",
      " tU  Vp         ",
      " tW  d          ",
      " tIIa           ",
      "III             ",
      "                ",
      "                ",
      "                ",
      "                ",
      "                ",
      "                ",
      "                ",
      "                "
    ],
    [
      "a X  X I        ",
      "       I        ",
      "nnnnnnII        ",
      " tYYY I         ",
      " tYYYZa         ",
      " tYYYd          ",
      " tIIp           ",
      "III             ",
      "                ",
      "                ",
      "                ",
      "                ",
      "                ",
      "                ",
      "                ",
      "                "
    ],
    [
      "a000000a        ",
      "0000000p        ",
      "000000aa        ",
      "00   0a1        ",
      "00   0p         ",
      "00  2d          ",
      "00aaa           ",
      "aap3            ",
      "                ",
      "                ",
      "                ",
      "                ",
      "                ",
      "                ",
      "                ",
      "                "
    ]
  ]
}