{
  "name": "multi_oasiscondo_15_floor9",
  "refpalette": "deceasedcraft:multi_oasiscondo_15/multi_oasiscondo_15_floor9_palette",
  "xsize": 16,
  "zsize": 16,
  "slices": [
    [
      "abbbbbc         ",
      "abbbbbc         ",
      "abbbbbc         ",
      "abbbbbd         ",
      "abbbbbd         ",
      "abbbbe          ",
      "cccff           ",
      "                ",
      "                ",
      "                ",
      "                ",
      "                ",
      "                ",
      "                ",
      "                ",
      "                "
    ],
    [
      "   g  hhi       ",
      "      hhi       ",
      "   j  hhi       ",
      "  jkj hil       ",
      "   j  hi        ",
      "     ell        ",
      "hhhhhll         ",
      "hhhmml          ",
      "mmml            ",
      "                ",
      "                ",
      "                ",
      "                ",
      "                ",
      "                ",
      "                "
    ],
    [
      "        n       ",
      "        n       ",
      "        n       ",
      "       nn       ",
      "       n        ",
      "     enn        ",
      "     nn         ",
      "   nnn          ",
      "nnnn            ",
      "                ",
      "                ",
      "                ",
      "                ",
      "                ",
      "                ",
      "                "
    ],
    [
      "                ",
      "                ",
      "                ",
      "                ",
      "                ",
      "     e          ",
      "                ",
      "                ",
      "                ",
      "                ",
      "                ",
      "                ",
      "                ",
      "                ",
      "                ",
      "                "
    ],
    [
      "       o        ",
      "       o        ",
      "       o        ",
      "      po        ",
      "      o         ",
      "     e          ",
      "   qr           ",
      "rrrr            ",
      "                ",
      "                ",
      "                ",
      "                ",
      "                ",
      "                ",
      "                ",
      "                "
    ],
    [
      "sssssslll       ",
      "sssssslll       ",
      "sssssslll       ",
      "sssssslll       ",
      "ssssssll        ",
      "sssssell        ",
      "lllllll         ",
      "llllll          ",
      "llll            ",
      "                ",
      "                ",
      "                ",
      "                ",
      "                ",
      "                ",
      "                "
    ]
  ]
}