{
  "name": "multi_oasiscondo_15_floor7",
  "refpalette": "deceasedcraft:multi_oasiscondo_15/multi_oasiscondo_15_floor7_palette",
  "xsize": 16,
  "zsize": 16,
  "slices": [
    [
      "abbbbbb         ",
      "bbbbbbb         ",
      "bbbbbbb         ",
      "bbbbbbc         ",
      "bbbbbbc         ",
      "bbbbbd          ",
      "bbbee           ",
      "                ",
      "                ",
      "                ",
      "                ",
      "                ",
      "                ",
      "                ",
      "                ",
      "                "
    ],
    [
      "afgh ijk        ",
      "     ila        ",
      "mnnonnaa        ",
      " p  qras        ",
      " tu wxa         ",
      "ytu Ad          ",
      "B!aka           ",
      "kCkD            ",
      "                ",
      "                ",
      "                ",
      "                ",
      "                ",
      "                ",
      "                ",
      "                "
    ],
    [
      "a  E  FI        ",
      "      JI        ",
      "KnnLnnII        ",
      " M  N I         ",
      " tO  Pa         ",
      " tQ  d          ",
      "RtIIa           ",
      "III             ",
      "                ",
      "                ",
      "                ",
      "                ",
      "                ",
      "                ",
      "                ",
      "                "
    ],
    [
      "a      I        ",
      "       I        ",
      "SnnSnnII        ",
      " T    I         ",
      " tU  Va         ",
      " tW  d          ",
      " tIIk           ",
      "III             ",
      "                ",
      "                ",
      "                ",
      "                ",
      "                ",
      "                ",
      "                ",
      "                "
    ],
    [
      "a X  X I        ",
      "       I        ",
      "nnnnnnII        ",
      " tYYY I         ",
      " tYYYZa         ",
      " tYYYd          ",
      " tIIa           ",
      "III             ",
      "                ",
      "                ",
      "                ",
      "                ",
      "                ",
      "                ",
      "                ",
      "                "
    ],
    [
      "a000000a        ",
      "0000000k        ",
      "000000aa        ",
      "00   0k1        ",
      "00   0k         ",
      "00  2d          ",
      "00aak           ",
      "aakD            ",
      "                ",
      "                ",
      "                ",
      "                ",
      "                ",
      "                ",
      "                ",
      "                "
    ]
  ]
}