{
  "name": "multi_oasiscondo_15_floor2",
  "refpalette": "deceasedcraft:multi_oasiscondo_15/multi_oasiscondo_15_floor2_palette",
  "xsize": 16,
  "zsize": 16,
  "slices": [
    [
      "abbbbbb         ",
      "bbbbbbb         ",
      "bbbbbbb         ",
      "bbbbbbc         ",
      "bbbbbbc         ",
      "bbbbbd          ",
      "bbbee           ",
      "                ",
      "                ",
      "                ",
      "                ",
      "                ",
      "                ",
      "                ",
      "                ",
      "               f"
    ],
    [
      "aghi jka        ",
      "     jlm        ",
      "noopooaa        ",
      " q   ras        ",
      " tu  wm         ",
      "xtuyAd          ",
      "BCaaa           ",
      "maaD            ",
      "                ",
      "                ",
      "                ",
      "                ",
      "                ",
      "                ",
      "                ",
      "                "
    ],
    [
      "aEF    I        ",
      "      JI        ",
      "KooLooII        ",
      " M  N I         ",
      " tO  Pa         ",
      " tQ  d          ",
      " tIIm           ",
      "III             ",
      "                ",
      "                ",
      "                ",
      "                ",
      "                ",
      "                ",
      "                ",
      "                "
    ],
    [
      "a      I        ",
      "       I        ",
      "RooRooII        ",
      " S    I         ",
      " tT  Ua         ",
      " tV  d          ",
      " tIIa           ",
      "III             ",
      "                ",
      "                ",
      "                ",
      "                ",
      "                ",
      "                ",
      "                ",
      "                "
    ],
    [
      "a W  W I        ",
      "       I        ",
      "ooooooII        ",
      " tXXX I         ",
      " tXXXYm         ",
      " tXXXd          ",
      " tIIa           ",
      "III             ",
      "                ",
      "                ",
      "                ",
      "                ",
      "                ",
      "                ",
      "                ",
      "                "
    ],
    [
      "aZZZZZZm        ",
      "ZZZZZZZa        ",
      "ZZZZZZaa        ",
      "ZZ   Za0        ",
      "ZZ   Za         ",
      "ZZ  1d          ",
      "ZZaaa           ",
      "ama2            ",
      "                ",
      "                ",
      "                ",
      "                ",
      "                ",
      "                ",
      "                ",
      "                "
    ]
  ]
}