{
  "name": "building_hotelc_floor1",
  "refpalette": "deceasedcraft:building_hotelc/building_hotelc_floor1_palette",
  "xsize": 16,
  "zsize": 16,
  "slices": [
    [
      "                ",
      " aaaaaaaaaaaaaa ",
      " abbbbbbbbbbbba ",
      " abbbbbbbbbbbba ",
      " abbbbbbbbbbbba ",
      " abbbccccccccca ",
      " dbbbc  effbbba ",
      " dbbbc   gfbbba ",
      " dbbbc  hhfbbia ",
      " dbbbc jkffbbi  ",
      " dbbbccccccbbi  ",
      " dbbbbbbllcbbi  ",
      " dbbbbbbllcbbi  ",
      " abbbbbbllmiin  ",
      " aaoooooaaaa    ",
      "                "
    ],
    [
      "                ",
      " aaaaaaaaaaaaaa ",
      " ap   qrrs   ta ",
      " au          ta ",
      " aw  xyAyAx  ta ",
      " a  BcaaaacaCaa ",
      " a  Da eEF    a ",
      " a  Ia  g J   a ",
      " a  Ka    J  ia ",
      " a  La  jj   i  ",
      " aMaacaaaacN i  ",
      " a OPPOnQRaS i  ",
      " a  TT n UaV i  ",
      " aW      Xaiin  ",
      " aaaaaaaaaaa    ",
      "                "
    ],
    [
      "                ",
      " aaaaaaaaaaaaaa ",
      " a   Y    Y  Za ",
      " a0           a ",
      " a   x12 3x  4a ",
      " a   caaaaca5aa ",
      " 6   a7EF     a ",
      " 6  8a9g      a ",
      " 6   a       ia ",
      " 6  #a       i  ",
      " a$aacaaaac% i  ",
      " a Y  Yn ^a  i  ",
      " a     n  a  i  ",
      " a        aiin  ",
      " aaaaaaa&&aa    ",
      "                "
    ],
    [
      "                ",
      " aaaaaaaaaaaaaa ",
      " a            a ",
      " a            a ",
      " a   x    x   a ",
      " a   caaaaca*aa ",
      " a   a(F      a ",
      " a   a)+      a ",
      " a  -a9      ia ",
      " a   a       i  ",
      " a*aacaaaac[ i  ",
      " a     n ]a  i  ",
      " a     n  a  i  ",
      " a       {aiin  ",
      " aaaaaaaaaaa    ",
      "                "
    ],
    [
      "                ",
      " aaaaaaaaaaaaaa ",
      " a            a ",
      " &            a ",
      " &   x    x   a ",
      " a   caaaacaaaa ",
      " a   a        a ",
      " a   a}       a ",
      " a   a)+     ia ",
      " a   a7|     i  ",
      " aaaacaaaac  i  ",
      " a     n  a  i  ",
      " a     n  a  i  ",
      " a     n  aiin  ",
      " aa6666666aa    ",
      "                "
    ],
    [
      "                ",
      " aaaaaaaaaaaaaa ",
      " a;;;;;;;;;;;;a ",
      " a;;;;;;;;;;;;a ",
      " a;;;;;;;;;;;;a ",
      " a;;;:aaaacaaaa ",
      " a;;;a   oooooa ",
      " a;;;a    ooooa ",
      " a;;;a}h  oooia ",
      " a;;;a(k|ooooi  ",
      " a''':aaaacooi  ",
      " a;;;;;;;;aooi  ",
      " a;;;;;;;;aooi  ",
      " a;;;;;;;;aiin  ",
      " aaaaaaaaaaa    ",
      "                "
    ]
  ]
}