{
  "name": "building_hotelc_floor1_90",
  "refpalette": "deceasedcraft:building_hotelc/building_hotelc_floor1_palette_90",
  "xsize": 16,
  "zsize": 16,
  "slices": [
    [
      "                ",
      " aaaaaaaa       ",
      " abbbcbbiiiiin  ",
      " abbbcbbbbbbbi  ",
      " abbbcbbbbbbbia ",
      " abbbcffffcccma ",
      " abbbcfghfcllla ",
      " abbbce hkcllla ",
      " abbbc   jcbbbo ",
      " abbbc    cbbbo ",
      " abbbccccccbbbo ",
      " abbbbbbbbbbbbo ",
      " abbbbbbbbbbbbo ",
      " abbbbbbbbbbbba ",
      " aaaaadddddddaa ",
      "                "
    ],
    [
      "                ",
      " aaaaaaaa       ",
      " attta  iiiiin  ",
      " a   C       i  ",
      " a   a    NSVia ",
      " a  xc JJ caaaa ",
      " as AaF  jaRUXa ",
      " ar yaEg jaQ  a ",
      " ar Aae   ann a ",
      " aq ya    aO  a ",
      " a  xcaaaacPT a ",
      " a   BDIKLaPT a ",
      " a        aO  a ",
      " apuw     M  Wa ",
      " aaaaaaaaaaaaaa ",
      "                "
    ],
    [
      "                ",
      " aaaaaaaa       ",
      " aZ 4a  iiiiin  ",
      " a   5       i  ",
      " a   a    %  ia ",
      " aY xc    caaaa ",
      " a  3a    a^  & ",
      " a   aF   a   & ",
      " a  2aEg  ann a ",
      " a  1a79  aY  a ",
      " aY xcaaaac   a ",
      " a     8 #a   a ",
      " a        aY  a ",
      " a 0      $   a ",
      " aaaaa6666aaaaa ",
      "                "
    ],
    [
      "                ",
      " aaaaaaaa       ",
      " a   a  iiiiin  ",
      " a   *       i  ",
      " a   a    [  ia ",
      " a  xc    caaaa ",
      " a   a    a] {a ",
      " a   a    a   a ",
      " a   aF+  ann a ",
      " a   a()9 a   a ",
      " a  xcaaaac   a ",
      " a      - a   a ",
      " a        a   a ",
      " a        *   a ",
      " aaaaaaaaaaaaaa ",
      "                "
    ],
    [
      "                ",
      " aaaaaaaa       ",
      " a   a  iiiiin  ",
      " a   a       i  ",
      " a   a       ia ",
      " a  xc    caaaa ",
      " a   a    a   6 ",
      " a   a    a   6 ",
      " a   a  +|annn6 ",
      " a   a })7a   6 ",
      " a  xcaaaac   6 ",
      " a        a   6 ",
      " a        a   6 ",
      " a        a   a ",
      " aa&&aaaaaaaaaa ",
      "                "
    ],
    [
      "                ",
      " aaaaaaaa       ",
      " a;;;aooiiiiin  ",
      " a;;;aoooooooi  ",
      " a;;;aoooooooia ",
      " a;;;coooocaaaa ",
      " a;;;ao  oa;;;a ",
      " a;;;a   |a;;;a ",
      " a;;;a  hka;;;a ",
      " a;;;a  }(a;;;a ",
      " a;;;:aaaa:;;;a ",
      " a;;;;;;;;';;;a ",
      " a;;;;;;;;';;;a ",
      " a;;;;;;;;';;;a ",
      " aaaaaaaaaaaaaa ",
      "                "
    ]
  ]
}