{
  "name": "building_hotelc_base2_270",
  "refpalette": "deceasedcraft:building_hotelc/building_hotelc_base2_palette_270",
  "xsize": 16,
  "zsize": 16,
  "slices": [
    [
      "vvvvvvvvvvvvvvvv",
      "vaaaaaaaaaaaaaav",
      "vahhhcbbbbbbbbav",
      "vahhhcbbbbbbbbav",
      "vahhhcbbbbbbbbav",
      "vahhhcddddcbbbav",
      "vahhhcfeeecbbbav",
      "vahhhceeefcbbbav",
      "vahhhceeeecbbbav",
      "vahhhceefecbbbav",
      "vahhhcggggcbbbav",
      "vabbbbbbbbbbbbav",
      "vabbbbbbbbbbbbav",
      "vabbbbbbbbbbbbav",
      "vaaaaaaaaaaaaaav",
      "vvvvvvvvvvvvvvvv"
    ],
    [
      "vvvvvvvvvvvvvvvv",
      "vaaaaaaaaaaaaaav",
      "vaRMIc       iav",
      "va   F       iav",
      "vaR  cnnnn   iav",
      "va   cooooc   av",
      "vaSN cqAspm  jav",
      "vaTO cpBwqm  kav",
      "vaQPJcD!xrm  kav",
      "vaQQKcsCqsm  lav",
      "vaLLLcooooc   av",
      "va    tttt   iav",
      "va           iav",
      "vaiii Eyyu iiiav",
      "vaaaaaaaaaaaaaav",
      "vvvvvvvvvvvvvvvv"
    ],
    [
      "vvvvvvvvvvvvvvvv",
      "vaaaaaaaaaaaaaav",
      "va5  c       iav",
      "va6  1       iav",
      "va5  c       Uav",
      "va6  cooooc   av",
      "va73 cqWspm   av",
      "va84 cpZXqm   av",
      "vahhhcW0YWm   av",
      "vaLLLmsWqsm   av",
      "va   cooooc   av",
      "va            av",
      "va           iav",
      "vaii2      Viiav",
      "vaaaaaaaaaaaaaav",
      "vvvvvvvvvvvvvvvv"
    ],
    [
      "vvvvvvvvvvvvvvvv",
      "vaaaaaaaaaaaaaav",
      "va   c        av",
      "va   c^       av",
      "va   c        av",
      "va  &cooooc   av",
      "va)K*cqWspm   av",
      "va(((cp%#qm   av",
      "vaLLLmWD$Wm   av",
      "va   msWq9m   av",
      "va   cooooc   av",
      "va            av",
      "va            av",
      "va            av",
      "vaaaaaaaaaaaaaav",
      "vvvvvvvvvvvvvvvv"
    ],
    [
      "vvvvvvvvvvvvvvvv",
      "vaaaaaaaaaaaaaav",
      "va   c        av",
      "va   c        av",
      "va   c        av",
      "va   cooooc   av",
      "va(((cqWspm   av",
      "vaLLLmp[+qm   av",
      "va   mWC-Wm   av",
      "va   msWqWm   av",
      "va   cooooc   av",
      "va            av",
      "va            av",
      "va            av",
      "vaaaaaaaaaaaaaav",
      "vvvvvvvvvvvvvvvv"
    ],
    [
      "vvvvvvvvvvvvvvvv",
      "vaaaaaaaaaaaaaav",
      "va}}}c]]]]]]]]av",
      "va}}}c]]]]]]]]av",
      "va}}}c]]]]]]]]av",
      "va(((cooooc   av",
      "vaLLLmqW9pm   av",
      "va   mpZ{qm   av",
      "va   mWX[Wm   av",
      "va   msWqWm   av",
      "va   cooooc   av",
      "va            av",
      "va            av",
      "va            av",
      "vaaaaaaaaaaaaaav",
      "vvvvvvvvvvvvvvvv"
    ]
  ]
}