{
  "name": "building_hotelc_floor2",
  "refpalette": "deceasedcraft:building_hotelc/building_hotelc_floor2_palette",
  "xsize": 16,
  "zsize": 16,
  "slices": [
    [
      "                ",
      " aaaaaaaaaaaaaa ",
      " abbbbbbbbbbbba ",
      " abbbbbbbbbbbba ",
      " abbbbbbbbbbbba ",
      " abbbccccccccca ",
      " dbbbc  effbbba ",
      " dbbbc   gfbbba ",
      " dbbbc  hhfbbia ",
      " dbbbc jkffbbi  ",
      " dbbbccccccbbi  ",
      " dbbbbbbllcbbi  ",
      " dbbbbbbllcbbi  ",
      " abbbbbbllmiin  ",
      " aaoooooaaaa    ",
      "                "
    ],
    [
      "                ",
      " aaaaaaaaaaaaaa ",
      " ap   qrrs   ta ",
      " au          ta ",
      " aw  xyAyAx  ta ",
      " a  BcaaaacaCaa ",
      " a  Da eEF    a ",
      " a  Ia  g J   a ",
      " a  Ka    J  ia ",
      " a  La  jj   i  ",
      " aMaacaaaacN i  ",
      " a O POnQRaS i  ",
      " a   T n UaV i  ",
      " a       Waiin  ",
      " aaaaaaaaaaa    ",
      "                "
    ],
    [
      "                ",
      " aaaaaaaaaaaaaa ",
      " a   X    Y  Za ",
      " a            a ",
      " a   x0 1 x  2a ",
      " a  3caaaaca4aa ",
      " 5   a6EF     a ",
      " 5   a7g      a ",
      " 5  8a       ia ",
      " 5  9a       i  ",
      " a#aacaaaac$ i  ",
      " a X  Yn %a  i  ",
      " a     n  a  i  ",
      " a        aiin  ",
      " aaaaaaa^^aa    ",
      "                "
    ],
    [
      "                ",
      " aaaaaaaaaaaaaa ",
      " a            a ",
      " a            a ",
      " a   x    x   a ",
      " a   caaaaca&aa ",
      " a   a*F      a ",
      " a   a()      a ",
      " a  +a7      ia ",
      " a   a       i  ",
      " a&aacaaaac- i  ",
      " a     n [a  i  ",
      " a     n  a  i  ",
      " a       ]aiin  ",
      " aaaaaaaaaaa    ",
      "                "
    ],
    [
      "                ",
      " aaaaaaaaaaaaaa ",
      " a            a ",
      " ^            a ",
      " ^   x    x   a ",
      " a   caaaacaaaa ",
      " a   a        a ",
      " a   a{       a ",
      " a   a()     ia ",
      " a   a6}     i  ",
      " aaaacaaaac  i  ",
      " a     n  a  i  ",
      " a     n  a  i  ",
      " a     n  aiin  ",
      " aa5555555aa    ",
      "                "
    ],
    [
      "                ",
      " aaaaaaaaaaaaaa ",
      " a||||||||||||a ",
      " a||||||||||||a ",
      " a||||||||||||a ",
      " a|||;aaaacaaaa ",
      " a|||a   oooooa ",
      " a|||a    ooooa ",
      " a|||a{h  oooia ",
      " a|||a*k}ooooi  ",
      " a:::;aaaacooi  ",
      " a||||||||aooi  ",
      " a||||||||aooi  ",
      " a||||||||aiin  ",
      " aaaaaaaaaaa    ",
      "                "
    ]
  ]
}