{
  "name": "building_hotelc_floor2_90",
  "refpalette": "deceasedcraft:building_hotelc/building_hotelc_floor2_palette_90",
  "xsize": 16,
  "zsize": 16,
  "slices": [
    [
      "                ",
      " aaaaaaaa       ",
      " abbbcbbiiiiin  ",
      " abbbcbbbbbbbi  ",
      " abbbcbbbbbbbia ",
      " abbbcffffcccma ",
      " abbbcfghfcllla ",
      " abbbce hkcllla ",
      " abbbc   jcbbbo ",
      " abbbc    cbbbo ",
      " abbbccccccbbbo ",
      " abbbbbbbbbbbbo ",
      " abbbbbbbbbbbbo ",
      " abbbbbbbbbbbba ",
      " aaaaadddddddaa ",
      "                "
    ],
    [
      "                ",
      " aaaaaaaa       ",
      " attta  iiiiin  ",
      " a   C       i  ",
      " a   a    NSVia ",
      " a  xc JJ caaaa ",
      " as AaF  jaRUWa ",
      " ar yaEg jaQ  a ",
      " ar Aae   ann a ",
      " aq ya    aO  a ",
      " a  xcaaaacPT a ",
      " a   BDIKLa   a ",
      " a        aO  a ",
      " apuw     M   a ",
      " aaaaaaaaaaaaaa ",
      "                "
    ],
    [
      "                ",
      " aaaaaaaa       ",
      " aZ 2a  iiiiin  ",
      " a   4       i  ",
      " a   a    $  ia ",
      " aY xc    caaaa ",
      " a   a    a%  ^ ",
      " a  1aF   a   ^ ",
      " a   aEg  ann a ",
      " a  0a67  aY  a ",
      " aX xcaaaac   a ",
      " a   3  89a   a ",
      " a        aX  a ",
      " a        #   a ",
      " aaaaa5555aaaaa ",
      "                "
    ],
    [
      "                ",
      " aaaaaaaa       ",
      " a   a  iiiiin  ",
      " a   &       i  ",
      " a   a    -  ia ",
      " a  xc    caaaa ",
      " a   a    a[ ]a ",
      " a   a    a   a ",
      " a   aF)  ann a ",
      " a   a*(7 a   a ",
      " a  xcaaaac   a ",
      " a      + a   a ",
      " a        a   a ",
      " a        &   a ",
      " aaaaaaaaaaaaaa ",
      "                "
    ],
    [
      "                ",
      " aaaaaaaa       ",
      " a   a  iiiiin  ",
      " a   a       i  ",
      " a   a       ia ",
      " a  xc    caaaa ",
      " a   a    a   5 ",
      " a   a    a   5 ",
      " a   a  )}annn5 ",
      " a   a {(6a   5 ",
      " a  xcaaaac   5 ",
      " a        a   5 ",
      " a        a   5 ",
      " a        a   a ",
      " aa^^aaaaaaaaaa ",
      "                "
    ],
    [
      "                ",
      " aaaaaaaa       ",
      " a|||aooiiiiin  ",
      " a|||aoooooooi  ",
      " a|||aoooooooia ",
      " a|||coooocaaaa ",
      " a|||ao  oa|||a ",
      " a|||a   }a|||a ",
      " a|||a  hka|||a ",
      " a|||a  {*a|||a ",
      " a|||;aaaa;|||a ",
      " a||||||||:|||a ",
      " a||||||||:|||a ",
      " a||||||||:|||a ",
      " aaaaaaaaaaaaaa ",
      "                "
    ]
  ]
}