{
  "name": "building_hotelc_floor3_270",
  "refpalette": "deceasedcraft:building_hotelc/building_hotelc_floor3_palette_270",
  "xsize": 16,
  "zsize": 16,
  "slices": [
    [
      "                ",
      " aadddddddaaaaa ",
      " abbbbbbbbbbbba ",
      " obbbbbbbbbbbba ",
      " obbbbbbbbbbbba ",
      " obbbccccccbbba ",
      " obbbc    cbbba ",
      " obbbcj   cbbba ",
      " alllckh ecbbba ",
      " alllcfhgfcbbba ",
      " amcccffffcbbba ",
      " aibbbbbbbcbbba ",
      "  ibbbbbbbcbbba ",
      "  niiiiibbcbbba ",
      "       aaaaaaaa ",
      "                "
    ],
    [
      "                ",
      " aaaaaaaaaaaaaa ",
      " a   M     wupa ",
      " a  Oa        a ",
      " a TPaLKIDB   a ",
      " a TPcaaaacx  a ",
      " a  Oa    ay qa ",
      " a nna   eaA ra ",
      " a  Qaj gEay ra ",
      " aWURaj  FaA sa ",
      " aaaac JJ cx  a ",
      " aiVSN    a   a ",
      "  i       C   a ",
      "  niiiii  attta ",
      "       aaaaaaaa ",
      "                "
    ],
    [
      "                ",
      " aaaaa5555aaaaa ",
      " a   #      Z a ",
      " a  Xa        a ",
      " a   a98      a ",
      " a   caaaacx Xa ",
      " a  !a  76a1  a ",
      " a nna  gEa2  a ",
      " ^   a   Fa2  a ",
      " ^  %a    a   a ",
      " aaaac    cx Xa ",
      " ai  $    a   a ",
      "  i       4   a ",
      "  niiiii  a30Ya ",
      "       aaaaaaaa ",
      "                "
    ],
    [
      "                ",
      " aaaaaaaaaaaaaa ",
      " a   &        a ",
      " a   a        a ",
      " a   a +      a ",
      " a   caaaacx  a ",
      " a   a 7(*a   a ",
      " a nna  )Fa   a ",
      " a   a    a   a ",
      " a] [a    a   a ",
      " aaaac    cx  a ",
      " ai  -    a   a ",
      "  i       &   a ",
      "  niiiii  a   a ",
      "       aaaaaaaa ",
      "                "
    ],
    [
      "                ",
      " aaaaaaaaaa^^aa ",
      " a   a        a ",
      " 5   a        a ",
      " 5   a        a ",
      " 5   caaaacx  a ",
      " 5   a6({ a   a ",
      " 5nnna})  a   a ",
      " 5   a    a   a ",
      " 5   a    a   a ",
      " aaaac    cx  a ",
      " ai       a   a ",
      "  i       a   a ",
      "  niiiii  a   a ",
      "       aaaaaaaa ",
      "                "
    ],
    [
      "                ",
      " aaaaaaaaaaaaaa ",
      " a|||:||||||||a ",
      " a|||:||||||||a ",
      " a|||:||||||||a ",
      " a|||;aaaa;|||a ",
      " a|||a*{  a|||a ",
      " a|||akh  a|||a ",
      " a|||a}   a|||a ",
      " a|||ao  oa|||a ",
      " aaaacooooc|||a ",
      " aioooooooa|||a ",
      "  ioooooooa|||a ",
      "  niiiiiooa|||a ",
      "       aaaaaaaa ",
      "                "
    ]
  ]
}