{
  "name": "building_hotelc_top_90",
  "refpalette": "deceasedcraft:building_hotelc/building_hotelc_top_palette_90",
  "xsize": 16,
  "zsize": 16,
  "slices": [
    [
      "                ",
      " aaaaaaaa       ",
      " abbbcbbiiiiim  ",
      " abbbcbbbbbbbi  ",
      " abbbcbbbbbbbia ",
      " abbbceeeebbbla ",
      " abbbcegheebbba ",
      " abbbcf hkebbba ",
      " abbbc   jebbbn ",
      " abbbc    ebbbn ",
      " abbbccccccbbbn ",
      " abbbcbbbbebbbn ",
      " abbbceeeeebbbn ",
      " abbbcbbbbebbba ",
      " aaaaadddddddaa ",
      "                "
    ],
    [
      "                ",
      " aaaaaaaa       ",
      " au  w  iiiiim  ",
      " au  r   EyE i  ",
      " au  r       ia ",
      " at  c DD    Ia ",
      " ar  aC  j   Ea ",
      " as  aBg j   ya ",
      " as  af   j  Ea ",
      " ar  a    j   a ",
      " aq  caaaac  Ea ",
      " ap  aAAAAF  ya ",
      " ap  ayyyyF  Ea ",
      " ao  axxxxF  Ia ",
      " aaaaaaaaaaaaaa ",
      "                "
    ],
    [
      "                ",
      " aaaaaaaa       ",
      " a      iiiiim  ",
      " aP       W  i  ",
      " aO  Q       ia ",
      " aN  c       Xa ",
      " aM  a        Z ",
      " a   aC       Z ",
      " a   aBg      a ",
      " aL  aSU      a ",
      " a   caaaac   a ",
      " aK  a       Ya ",
      " aJ  a T V    a ",
      " a   a       Xa ",
      " aaaaaRRRRaaaaa ",
      "                "
    ],
    [
      "                ",
      " aaaaaaaa       ",
      " a      iiiiim  ",
      " a           i  ",
      " a           ia ",
      " a4  c       7a ",
      " a3  a        a ",
      " a2  a        a ",
      " a3  aC6      a ",
      " a2  aF5U     a ",
      " a1  caaaac   a ",
      " a0  a        a ",
      " a0  a        a ",
      " a   a       7a ",
      " aaaaaaaaaaaaaa ",
      "                "
    ],
    [
      "                ",
      " aaaaaaaa       ",
      " a      iiiiim  ",
      " a           i  ",
      " a           ia ",
      " a   c        a ",
      " a   a        R ",
      " a   a        R ",
      " a   a  69    R ",
      " a   a 85S    R ",
      " a   caaaac   R ",
      " a   a        R ",
      " a   a        R ",
      " a   a        a ",
      " aaZZaaaaaaaaaa ",
      "                "
    ],
    [
      "                ",
      " aaaaaaaa       ",
      " a###nnniiiiim  ",
      " a###nnnnnnnni  ",
      " a###nnnnnnnnia ",
      " a###cnnnnnnnna ",
      " a###a   nnnnna ",
      " a###a   9nnnna ",
      " a###a  hknnnna ",
      " a###a  8Fnnnna ",
      " a###caaaacnnna ",
      " a###annnnnnnna ",
      " a###annnnnnnna ",
      " a###annnnnnnna ",
      " aaaaaaaaaaaaaa ",
      "                "
    ],
    [
      "                ",
      " aaaaaaaa       ",
      " a$$$bbbiiiiim  ",
      " a$$$bbbbbbbbi  ",
      " a$$$bbbbbbbbia ",
      " a$$$eeeeebbbla ",
      " a$$$e  heebbba ",
      " a$$$e  hkebbba ",
      " a$$$e   jebbbn ",
      " a$$$e    ebbbn ",
      " a$$$eeeeeebbbn ",
      " a$$$bbbbbbbbbn ",
      " a$$$bbbbbbbbbn ",
      " a$$$bbbbbbbbba ",
      " aaaaadddddddaa ",
      "                "
    ],
    [
      "                ",
      " aaaaaaaa       ",
      " %^^^&--iiiiim  ",
      " %^^^)   [{| i  ",
      " %^^^(       ia ",
      " %^^^(DDD    Ia ",
      " %^^^(j  j  '<a ",
      " %^^^(j  j  :<a ",
      " %^^^(j   j :<a ",
      " %^^^(j   j :<a ",
      " %^^^(8888  :<a ",
      " %^^^(      ;<a ",
      " %^^^*      ]]a ",
      " %^^^&++++]}]]a ",
      " aaaaaaaaaaaaaa ",
      "                "
    ],
    [
      "                ",
      " aaaaaa`        ",
      " a???/iiiiiiim  ",
      " a???        i  ",
      " a???        ia ",
      " a...        Xa ",
      " a...        \u0370Z ",
      " a...        \u0370Z ",
      " a,,,        \u0370a ",
      " a,,,        \u0370a ",
      " a,,,        \u0370a ",
      " a>>>        \u0370a ",
      " a>>>         a ",
      " a>>>/       ]a ",
      " aaaaaRRRRaaaaa ",
      "                "
    ],
    [
      "                ",
      " aaaa`          ",
      " a\u0371 iiiiiiiiim  ",
      " a\u0371          i  ",
      " a\u0371          ia ",
      " a\u0371          7a ",
      " a\u0371           a ",
      " a\u0371           a ",
      " a\u0371           a ",
      " a\u0371           a ",
      " a\u0371           a ",
      " a\u0371           a ",
      " a\u0371           a ",
      " a\u0371           a ",
      " aaaaaaaaaaaaaa ",
      "                "
    ],
    [
      "                ",
      " aa`            ",
      " a\u0372\u0373\u0371iiiiiiiim  ",
      " a\u0372\u0374\u0374        i  ",
      " a\u0372\u0374\u0374        ia ",
      " a\u0372\u0374\u0374         a ",
      " a\u0372\u0374\u0374         R ",
      " a\u0372\u0374\u0374         R ",
      " a\u0372\u0374\u0374         R ",
      " a\u0372\u0374\u0374         R ",
      " a\u0372\u0374\u0374         R ",
      " a\u0372\u0374\u0374         R ",
      " a\u0372\u0374\u0374         R ",
      " a\u0372\u0373\u0371         a ",
      " aaaaaaaaaaaaaa ",
      "                "
    ],
    [
      "                ",
      " `              ",
      " `  \u0372\u0373\u0371iiiiiim  ",
      " `   \u0374\u0374      i  ",
      " `   \u0374\u0374      ia ",
      " `   \u0374\u0374       a ",
      " `   \u0374\u0374       a ",
      " `   \u0374\u0374       a ",
      " `   \u0374\u0374       a ",
      " `   \u0374\u0374       a ",
      " `   \u0374\u0374       a ",
      " `   \u0374\u0374       a ",
      " `   \u0374\u0374       a ",
      " `  \u0372\u0373\u0371       a ",
      " `aaaaaaaaaaaaa ",
      "                "
    ],
    [
      "                ",
      "                ",
      "      \u0372\u0373\u0371iiiim  ",
      "       \u0374\u0374    i  ",
      "       \u0374\u0374    ia ",
      "       \u0374\u0374     a ",
      "       \u0374\u0374     a ",
      "       \u0374\u0374     a ",
      "       \u0374\u0374     a ",
      "       \u0374\u0374     a ",
      "       \u0374\u0374     a ",
      "       \u0374\u0374     a ",
      "       \u0374\u0374     a ",
      "      \u0372\u0373\u0371     a ",
      "   `aaaaaaaaaaa ",
      "                "
    ],
    [
      "                ",
      "                ",
      "        \u0372\u0373\u0371iim  ",
      "         \u0374\u0374  i  ",
      "         \u0374\u0374  ia ",
      "         \u0374\u0374   a ",
      "         \u0374\u0374   a ",
      "         \u0374\u0374   a ",
      "         \u0374\u0374   a ",
      "         \u0374\u0374   a ",
      "         \u0374\u0374   a ",
      "         \u0374\u0374   a ",
      "         \u0374\u0374   a ",
      "        \u0372\u0373\u0371   a ",
      "     `aaaaaaaaa ",
      "                "
    ],
    [
      "                ",
      "                ",
      "          \u0372\u0373\u0371m  ",
      "           \u0374\u0374i  ",
      "           \u0374\u0374ia ",
      "           \u0374\u0374\u0377a ",
      "           \u0374\u0374\u0376a ",
      "           \u0374\u0374\u0375a ",
      "           \u0374\u0374\u0376a ",
      "           \u0374\u0374\u0375a ",
      "           \u0374\u0374\u0376a ",
      "           \u0374\u0374\u0375a ",
      "           \u0374\u0374\u0376a ",
      "          \u0372\u0373\u0371\u0375a ",
      "       `aaaaaaa ",
      "                "
    ],
    [
      "                ",
      "                ",
      "            \u0372\u0373  ",
      "             \u0373  ",
      "             \u0373a ",
      "             \u0373a ",
      "             \u0373a ",
      "             \u0373a ",
      "             \u0373a ",
      "             \u0373a ",
      "             \u0373a ",
      "             \u0373a ",
      "             \u0373a ",
      "            \u0372\u0373a ",
      "         `aaaaa ",
      "                "
    ],
    [
      "                ",
      "                ",
      "                ",
      "                ",
      "              a ",
      "              a ",
      "              a ",
      "              a ",
      "              a ",
      "              a ",
      "              a ",
      "              a ",
      "              a ",
      "              a ",
      "           `aaa ",
      "                "
    ],
    [
      "                ",
      "                ",
      "                ",
      "                ",
      "              a ",
      "              a ",
      "              a ",
      "              a ",
      "              a ",
      "              a ",
      "              a ",
      "              a ",
      "              a ",
      "              a ",
      "             `a ",
      "                "
    ]
  ]
}