{
  "name": "building_hotelc_floor1_180",
  "refpalette": "deceasedcraft:building_hotelc/building_hotelc_floor1_palette_180",
  "xsize": 16,
  "zsize": 16,
  "slices": [
    [
      "                ",
      "    aaaaoooooaa ",
      "  niimllbbbbbba ",
      "  ibbcllbbbbbbd ",
      "  ibbcllbbbbbbd ",
      "  ibbccccccbbbd ",
      "  ibbffkj cbbbd ",
      " aibbfhh  cbbbd ",
      " abbbfg   cbbbd ",
      " abbbffe  cbbbd ",
      " acccccccccbbba ",
      " abbbbbbbbbbbba ",
      " abbbbbbbbbbbba ",
      " abbbbbbbbbbbba ",
      " aaaaaaaaaaaaaa ",
      "                "
    ],
    [
      "                ",
      "    aaaaaaaaaaa ",
      "  niiaX      Wa ",
      "  i VaU n TT  a ",
      "  i SaRQnOPPO a ",
      "  i NcaaaacaaMa ",
      "  i   jj  aL  a ",
      " ai  J    aK  a ",
      " a   J g  aI  a ",
      " a    FEe aD  a ",
      " aaCacaaaacB  a ",
      " at  xAyAyx  wa ",
      " at          ua ",
      " at   srrq   pa ",
      " aaaaaaaaaaaaaa ",
      "                "
    ],
    [
      "                ",
      "    aa&&aaaaaaa ",
      "  niia        a ",
      "  i  a  n     a ",
      "  i  a^ nY  Y a ",
      "  i %caaaacaa$a ",
      "  i       a#  6 ",
      " ai       a   6 ",
      " a      g9a8  6 ",
      " a     FE7a   6 ",
      " aa5acaaaac   a ",
      " a4  x3 21x   a ",
      " a           0a ",
      " aZ  Y    Y   a ",
      " aaaaaaaaaaaaaa ",
      "                "
    ],
    [
      "                ",
      "    aaaaaaaaaaa ",
      "  niia{       a ",
      "  i  a  n     a ",
      "  i  a] n     a ",
      "  i [caaaacaa*a ",
      "  i       a   a ",
      " ai      9a-  a ",
      " a      +)a   a ",
      " a      F(a   a ",
      " aa*acaaaac   a ",
      " a   x    x   a ",
      " a            a ",
      " a            a ",
      " aaaaaaaaaaaaaa ",
      "                "
    ],
    [
      "                ",
      "    aa6666666aa ",
      "  niia  n     a ",
      "  i  a  n     a ",
      "  i  a  n     a ",
      "  i  caaaacaaaa ",
      "  i     |7a   a ",
      " ai     +)a   a ",
      " a       }a   a ",
      " a        a   a ",
      " aaaacaaaac   a ",
      " a   x    x   & ",
      " a            & ",
      " a            a ",
      " aaaaaaaaaaaaaa ",
      "                "
    ],
    [
      "                ",
      "    aaaaaaaaaaa ",
      "  niia;;;;;;;;a ",
      "  iooa;;;;;;;;a ",
      "  iooa;;;;;;;;a ",
      "  ioocaaaa:'''a ",
      "  ioooo|k(a;;;a ",
      " aiooo  h}a;;;a ",
      " aoooo    a;;;a ",
      " aooooo   a;;;a ",
      " aaaacaaaa:;;;a ",
      " a;;;;;;;;;;;;a ",
      " a;;;;;;;;;;;;a ",
      " a;;;;;;;;;;;;a ",
      " aaaaaaaaaaaaaa ",
      "                "
    ]
  ]
}