{
  "name": "building_hotelc_base1_270",
  "refpalette": "deceasedcraft:building_hotelc/building_hotelc_base1_palette_270",
  "xsize": 16,
  "zsize": 16,
  "slices": [
    [
      "vvvvvvvvvvvvvvvv",
      "vaaaaaaaaaaaaaav",
      "vabbbbbbbbbbbbav",
      "vabbbbbbbbbbbbav",
      "vabbbbbbbbbbbbav",
      "vaooodffffdcccav",
      "va   ehiige   av",
      "va   egljhe   av",
      "va   eimkie   av",
      "va   enihie   av",
      "va   dffffd   av",
      "va            av",
      "va            av",
      "va            av",
      "vaaaaaaaaaaaaaav",
      "vvvvvvvvvvvvvvvv"
    ],
    [
      "vvvvvvvvvvvvvvvv",
      "vaaaaaaaaaaaaaav",
      "va            av",
      "va            av",
      "va    qqqq    av",
      "va   dffffdpppav",
      "va   ehiigecccav",
      "va   egtrhe   av",
      "va   eiusie   av",
      "va   eiihie   av",
      "va   dffffd   av",
      "va            av",
      "va            av",
      "va            av",
      "vaaaaaaaaaaaaaav",
      "vvvvvvvvvvvvvvvv"
    ],
    [
      "vvvvvvvvvvvvvvvv",
      "vaaaaaaaaaaaaaav",
      "va   w    w   av",
      "va            av",
      "va            av",
      "va   dffffd   av",
      "va   ehiigdpppav",
      "va   egAxhecccav",
      "va   eiByie   av",
      "va   eiihie   av",
      "va   dffffd   av",
      "va            av",
      "va            av",
      "va            av",
      "vaaaaaaaaaaaaaav",
      "vvvvvvvvvvvvvvvv"
    ],
    [
      "vvvvvvvvvvvvvvvv",
      "vaaaaaaaaaaaaaav",
      "va   C    C   av",
      "va            av",
      "va            av",
      "va   dffffd   av",
      "va   ehiigd   av",
      "va   egEDhdpppav",
      "va   eiFuiecccav",
      "va   eiihie   av",
      "va   dffffd   av",
      "va            av",
      "va            av",
      "va            av",
      "vaaaaaaaaaaaaaav",
      "vvvvvvvvvvvvvvvv"
    ],
    [
      "vvvvvvvvvvvvvvvv",
      "vaaaaaaaaaaaaaav",
      "va   I    I   av",
      "va            av",
      "va            av",
      "va   dffffd   av",
      "va   ehMigd   av",
      "va   eJDKJd   av",
      "va   emDxidpppav",
      "va   eixLiecccav",
      "va   dffffd   av",
      "va            av",
      "va            av",
      "va            av",
      "vaaaaaaaaaaaaaav",
      "vvvvvvvvvvvvvvvv"
    ],
    [
      "vvvvvvvvvvvvvvvv",
      "vaaaaaaaaaaaaaav",
      "vaNNNNNNNNNNNNav",
      "vaNNNNNNNNNNNNav",
      "vaNNNNNNNNNNNNav",
      "vaNNNdOOOOd   av",
      "vaNNNdDDPDd   av",
      "vaNNNdDDDDd   av",
      "vaNNNdDDDPd   av",
      "vaNNNdDDDDdpppav",
      "vaNNNdQQQQdcccav",
      "vaNNNNNNNNNNNNav",
      "vaNNNNNNNNNNNNav",
      "vaNNNNNNNNNNNNav",
      "vaaaaaaaaaaaaaav",
      "vvvvvvvvvvvvvvvv"
    ]
  ]
}