{
  "name": "building_hotelc_top",
  "refpalette": "deceasedcraft:building_hotelc/building_hotelc_top_palette",
  "xsize": 16,
  "zsize": 16,
  "slices": [
    [
      "                ",
      " aaaaaaaaaaaaaa ",
      " abbbbbbbbbbbba ",
      " abbbbbbbbbbbba ",
      " abbbbbbbbbbbba ",
      " acccccccccccca ",
      " dbebc  feebbba ",
      " dbebc   gebbba ",
      " dbebc  hhebbia ",
      " dbebc jkeebbi  ",
      " deeeceeeebbbi  ",
      " dbbbbbbbbbbbi  ",
      " dbbbbbbbbbbbi  ",
      " abbbbbbbbliim  ",
      " aannnnnaaaa    ",
      "                "
    ],
    [
      "                ",
      " aaaaaaaaaaaaaa ",
      " aoppqrssrtuuua ",
      " a            a ",
      " a            a ",
      " aaaacaaaacrrwa ",
      " axyAa fBC    a ",
      " axyAa  g D   a ",
      " axyAa    D  ia ",
      " axyAa  jj  Ei  ",
      " aFFFcjj    yi  ",
      " a          Ei  ",
      " a           i  ",
      " aIEyE EyEIiim  ",
      " aaaaaaaaaaa    ",
      "                "
    ],
    [
      "                ",
      " aaaaaaaaaaaaaa ",
      " a JK L  MNOP a ",
      " a            a ",
      " a            a ",
      " aaaacaaaacQ  a ",
      " R   aSBC     a ",
      " R T aUg      a ",
      " R   a       ia ",
      " R V a       i  ",
      " a   c      Wi  ",
      " a           i  ",
      " a           i  ",
      " aX Y     Xiim  ",
      " aaaaaaaZZaa    ",
      "                "
    ],
    [
      "                ",
      " aaaaaaaaaaaaaa ",
      " a 00123234   a ",
      " a            a ",
      " a            a ",
      " aaaacaaaac   a ",
      " a   aFC      a ",
      " a   a56      a ",
      " a   aU      ia ",
      " a   a       i  ",
      " a   c       i  ",
      " a           i  ",
      " a           i  ",
      " a7       7iim  ",
      " aaaaaaaaaaa    ",
      "                "
    ],
    [
      "                ",
      " aaaaaaaaaaaaaa ",
      " a            a ",
      " Z            a ",
      " Z            a ",
      " aaaacaaaac   a ",
      " a   a        a ",
      " a   a8       a ",
      " a   a56     ia ",
      " a   aS9     i  ",
      " a   c       i  ",
      " a           i  ",
      " a           i  ",
      " a         iim  ",
      " aaRRRRRRRaa    ",
      "                "
    ],
    [
      "                ",
      " aaaaaaaaaaaaaa ",
      " a############a ",
      " a############a ",
      " a############a ",
      " aaaacaaaacnnna ",
      " annna    nnnna ",
      " annna    nnnna ",
      " annna8h  nnnia ",
      " annnaFk9nnnni  ",
      " annncnnnnnnni  ",
      " annnnnnnnnnni  ",
      " annnnnnnnnnni  ",
      " annnnnnnnniim  ",
      " aaaaaaaaaaa    ",
      "                "
    ],
    [
      "                ",
      " aaaaaaaaaaaaaa ",
      " a$$$$$$$$$$$$a ",
      " a$$$$$$$$$$$$a ",
      " a$$$$$$$$$$$$a ",
      " abbbeeeeeebbba ",
      " dbbbe    ebbba ",
      " dbbbe    ebbba ",
      " dbbbe  hhebbia ",
      " dbbbe jkeebbi  ",
      " dbbbeeeeebbbi  ",
      " dbbbbbbbbbbbi  ",
      " dbbbbbbbbbbbi  ",
      " abbbbbbbbliim  ",
      " aannnnnaaaa    ",
      "                "
    ],
    [
      "                ",
      " a%%%%%%%%%%%%a ",
      " a^^^^^^^^^^^^a ",
      " a^^^^^^^^^^^^a ",
      " a^^^^^^^^^^^^a ",
      " a&*(((((((()&a ",
      " a+  8jjjjD  -a ",
      " a+  8    D  -a ",
      " a+  8    D  ia ",
      " a+  8  jj  [i  ",
      " a]   jj    {i  ",
      " a}         |i  ",
      " a]];::::'   i  ",
      " a]]<<<<<<Iiim  ",
      " aaaaaaaaaaa    ",
      "                "
    ],
    [
      "                ",
      " aaaaaaaaaaaaaa ",
      " a>>>,,,...???a ",
      " a>>>,,,...???a ",
      " a>>>,,,...???a ",
      " a/          /a ",
      " R           ia ",
      " R           i` ",
      " R           i  ",
      " R           i  ",
      " a           i  ",
      " a           i  ",
      " a           i  ",
      " a] \u0370\u0370\u0370\u0370\u0370\u0370Xiim  ",
      " aaaaaaaZZaa    ",
      "                "
    ],
    [
      "                ",
      " aaaaaaaaaaaaaa ",
      " a\u0371\u0371\u0371\u0371\u0371\u0371\u0371\u0371\u0371\u0371\u0371\u0371a ",
      " a            a ",
      " a           ia ",
      " a           i` ",
      " a           i  ",
      " a           i  ",
      " a           i  ",
      " a           i  ",
      " a           i  ",
      " a           i  ",
      " a           i  ",
      " a        7iim  ",
      " aaaaaaaaaaa    ",
      "                "
    ],
    [
      "                ",
      " aaaaaaaaaaaaaa ",
      " a\u0372\u0372\u0372\u0372\u0372\u0372\u0372\u0372\u0372\u0372\u0372\u0372a ",
      " a\u0373\u0374\u0374\u0374\u0374\u0374\u0374\u0374\u0374\u0374\u0374\u0373` ",
      " a\u0371\u0374\u0374\u0374\u0374\u0374\u0374\u0374\u0374\u0374\u0374\u0371  ",
      " a           i  ",
      " a           i  ",
      " a           i  ",
      " a           i  ",
      " a           i  ",
      " a           i  ",
      " a           i  ",
      " a           i  ",
      " a         iim  ",
      " aaRRRRRRRaa    ",
      "                "
    ],
    [
      "                ",
      " `````````````` ",
      " a              ",
      " a              ",
      " a\u0372          \u0372  ",
      " a\u0373\u0374\u0374\u0374\u0374\u0374\u0374\u0374\u0374\u0374\u0374\u0373  ",
      " a\u0371\u0374\u0374\u0374\u0374\u0374\u0374\u0374\u0374\u0374\u0374\u0371  ",
      " a           i  ",
      " a           i  ",
      " a           i  ",
      " a           i  ",
      " a           i  ",
      " a           i  ",
      " a         iim  ",
      " aaaaaaaaaaa    ",
      "                "
    ],
    [
      "                ",
      "                ",
      "                ",
      " `              ",
      " a              ",
      " a              ",
      " a\u0372          \u0372  ",
      " a\u0373\u0374\u0374\u0374\u0374\u0374\u0374\u0374\u0374\u0374\u0374\u0373  ",
      " a\u0371\u0374\u0374\u0374\u0374\u0374\u0374\u0374\u0374\u0374\u0374\u0371  ",
      " a           i  ",
      " a           i  ",
      " a           i  ",
      " a           i  ",
      " a         iim  ",
      " aaaaaaaaaaa    ",
      "                "
    ],
    [
      "                ",
      "                ",
      "                ",
      "                ",
      "                ",
      " `              ",
      " a              ",
      " a              ",
      " a\u0372          \u0372  ",
      " a\u0373\u0374\u0374\u0374\u0374\u0374\u0374\u0374\u0374\u0374\u0374\u0373  ",
      " a\u0371\u0374\u0374\u0374\u0374\u0374\u0374\u0374\u0374\u0374\u0374\u0371  ",
      " a           i  ",
      " a           i  ",
      " a         iim  ",
      " aaaaaaaaaaa    ",
      "                "
    ],
    [
      "                ",
      "                ",
      "                ",
      "                ",
      "                ",
      "                ",
      "                ",
      " `              ",
      " a              ",
      " a              ",
      " a\u0372          \u0372  ",
      " a\u0373\u0374\u0374\u0374\u0374\u0374\u0374\u0374\u0374\u0374\u0374\u0373  ",
      " a\u0371\u0374\u0374\u0374\u0374\u0374\u0374\u0374\u0374\u0374\u0374\u0371  ",
      " a\u0375\u0376\u0375\u0376\u0375\u0376\u0375\u0376\u0377iim  ",
      " aaaaaaaaaaa    ",
      "                "
    ],
    [
      "                ",
      "                ",
      "                ",
      "                ",
      "                ",
      "                ",
      "                ",
      "                ",
      "                ",
      " `              ",
      " a              ",
      " a              ",
      " a\u0372          \u0372  ",
      " a\u0373\u0373\u0373\u0373\u0373\u0373\u0373\u0373\u0373\u0373\u0373\u0373  ",
      " aaaaaaaaaaa    ",
      "                "
    ],
    [
      "                ",
      "                ",
      "                ",
      "                ",
      "                ",
      "                ",
      "                ",
      "                ",
      "                ",
      "                ",
      "                ",
      " `              ",
      " a              ",
      " a              ",
      " aaaaaaaaaaa    ",
      "                "
    ],
    [
      "                ",
      "                ",
      "                ",
      "                ",
      "                ",
      "                ",
      "                ",
      "                ",
      "                ",
      "                ",
      "                ",
      "                ",
      "                ",
      " `              ",
      " aaaaaaaaaaa    ",
      "                "
    ]
  ]
}