{
  "name": "building_hotelc_ground_90",
  "refpalette": "deceasedcraft:building_hotelc/building_hotelc_ground_palette_90",
  "xsize": 16,
  "zsize": 16,
  "slices": [
    [
      "aaaaaaaaafffffff",
      "abbbbbbbbfffffff",
      "abggggggffffffff",
      "abffffffffffffff",
      "abffffffffffffba",
      "abeeebffffffffba",
      "ab   bfggfffffba",
      "ab   bfgggffffba",
      "ab   b!gggffffba",
      "ab   bfggfffffba",
      "ab   bffffffffba",
      "abdddbffffffffba",
      "abcccbffffffffba",
      "abcccbffffffffba",
      "abbbbbbbbbbbbbba",
      "aaaaaaaaaaaaaaaa"
    ],
    [
      "                ",
      " hhhhhhhhE  E   ",
      " hkkkkkkBBJLBE  ",
      " h           B  ",
      " h           Bh ",
      " h   b       Oh ",
      " h   hsxy    Nh ",
      " h   hrwAy   Mh ",
      " h   hquxt    h ",
      " h   hpty     h ",
      " h   ho   I I h ",
      " hhhhh   DFFFFh ",
      " hj  n   C K  h ",
      " hilmh        h ",
      " hhhhhhhhhhhhhh ",
      "                "
    ],
    [
      "                ",
      " hhhhhhhhE  E   ",
      " h      BBYZBE  ",
      " h           B  ",
      " h           Bh ",
      " h   b       xh ",
      " h   h X      1 ",
      " h   hs x     1 ",
      " h   hrw      h ",
      " h   hUW      h ",
      " h   hTV      h ",
      " hhhhh       0h ",
      " h   R        h ",
      " h PQh        h ",
      " hhhhhSSSShhhhh ",
      "                "
    ],
    [
      "                ",
      " hhhhhhhhEEEE   ",
      " h      BBBBBE  ",
      " h           B  ",
      " h           Bh ",
      " h   b       Xh ",
      " h   h        h ",
      " h   h  X     h ",
      " h   hs8      h ",
      " h   h67W     h ",
      " h   h5TV     h ",
      " hhhhh        h ",
      " h   4        h ",
      " h 23h     9# h ",
      " hhhhhhhhhhhhhh ",
      "                "
    ],
    [
      "                ",
      " hhhhhhhh       ",
      " h      BBBBBE  ",
      " h           B  ",
      " h           Bh ",
      " h   b        h ",
      " h   h        S ",
      " h   h  u     S ",
      " h   h  8%    S ",
      " h   h $7U    S ",
      " h   h55TV    S ",
      " hhhhh        S ",
      " h   h        S ",
      " h   h        h ",
      " hh11hhhhhhhhhh ",
      "                "
    ],
    [
      "                ",
      " hhhhhhhh       ",
      " h&&&&&&BBBBBE  ",
      " h&&&&&&&&&&&B  ",
      " h&&&&&&&&&&&Bh ",
      " h&&&b&&&&&&&&h ",
      " h&&&h&  &&&&&h ",
      " h&&&h   % &&&h ",
      " h&&&h  (e &&&h ",
      " h&&&h  $6 &&&h ",
      " h&&&h***) &&&h ",
      " hhhhh&&&&&&&&h ",
      " h^^^h&&&&&&&&h ",
      " h^^^h&&&&&&&&h ",
      " hhhhhhhhhhhhhh ",
      "                "
    ]
  ]
}