{
  "name": "building_hotelc_floor1_270",
  "refpalette": "deceasedcraft:building_hotelc/building_hotelc_floor1_palette_270",
  "xsize": 16,
  "zsize": 16,
  "slices": [
    [
      "                ",
      " aadddddddaaaaa ",
      " abbbbbbbbbbbba ",
      " obbbbbbbbbbbba ",
      " obbbbbbbbbbbba ",
      " obbbccccccbbba ",
      " obbbc    cbbba ",
      " obbbcj   cbbba ",
      " alllckh ecbbba ",
      " alllcfhgfcbbba ",
      " amcccffffcbbba ",
      " aibbbbbbbcbbba ",
      "  ibbbbbbbcbbba ",
      "  niiiiibbcbbba ",
      "       aaaaaaaa ",
      "                "
    ],
    [
      "                ",
      " aaaaaaaaaaaaaa ",
      " aW  M     wupa ",
      " a  Oa        a ",
      " a TPaLKIDB   a ",
      " a TPcaaaacx  a ",
      " a  Oa    ay qa ",
      " a nna   eaA ra ",
      " a  Qaj gEay ra ",
      " aXURaj  FaA sa ",
      " aaaac JJ cx  a ",
      " aiVSN    a   a ",
      "  i       C   a ",
      "  niiiii  attta ",
      "       aaaaaaaa ",
      "                "
    ],
    [
      "                ",
      " aaaaa6666aaaaa ",
      " a   $      0 a ",
      " a  Ya        a ",
      " a   a# 8     a ",
      " a   caaaacx Ya ",
      " a  Ya  97a1  a ",
      " a nna  gEa2  a ",
      " &   a   Fa   a ",
      " &  ^a    a3  a ",
      " aaaac    cx Ya ",
      " ai  %    a   a ",
      "  i       5   a ",
      "  niiiii  a4 Za ",
      "       aaaaaaaa ",
      "                "
    ],
    [
      "                ",
      " aaaaaaaaaaaaaa ",
      " a   *        a ",
      " a   a        a ",
      " a   a -      a ",
      " a   caaaacx  a ",
      " a   a 9)(a   a ",
      " a nna  +Fa   a ",
      " a   a    a   a ",
      " a{ ]a    a   a ",
      " aaaac    cx  a ",
      " ai  [    a   a ",
      "  i       *   a ",
      "  niiiii  a   a ",
      "       aaaaaaaa ",
      "                "
    ],
    [
      "                ",
      " aaaaaaaaaa&&aa ",
      " a   a        a ",
      " 6   a        a ",
      " 6   a        a ",
      " 6   caaaacx  a ",
      " 6   a7)} a   a ",
      " 6nnna|+  a   a ",
      " 6   a    a   a ",
      " 6   a    a   a ",
      " aaaac    cx  a ",
      " ai       a   a ",
      "  i       a   a ",
      "  niiiii  a   a ",
      "       aaaaaaaa ",
      "                "
    ],
    [
      "                ",
      " aaaaaaaaaaaaaa ",
      " a;;;';;;;;;;;a ",
      " a;;;';;;;;;;;a ",
      " a;;;';;;;;;;;a ",
      " a;;;:aaaa:;;;a ",
      " a;;;a(}  a;;;a ",
      " a;;;akh  a;;;a ",
      " a;;;a|   a;;;a ",
      " a;;;ao  oa;;;a ",
      " aaaacooooc;;;a ",
      " aioooooooa;;;a ",
      "  ioooooooa;;;a ",
      "  niiiiiooa;;;a ",
      "       aaaaaaaa ",
      "                "
    ]
  ]
}