{
  "name": "building_hotelc_ground",
  "refpalette": "deceasedcraft:building_hotelc/building_hotelc_ground_palette",
  "xsize": 16,
  "zsize": 16,
  "slices": [
    [
      "aaaaaaaaaaaaaaaa",
      "abbbbbbbbbbbbbba",
      "abccd     effgba",
      "abccd     effgba",
      "abccd     effgba",
      "abbbbbbbbbbffgba",
      "abfffff!fffffgba",
      "abffffggggfffgba",
      "abffffggggffffba",
      "abfffffggfffffff",
      "abffffffffffffff",
      "abffffffffffffff",
      "abffffffffffffff",
      "abffffffffffffff",
      "abbbbbbbbbbbffff",
      "aaaaaaaaaaaaffff"
    ],
    [
      "                ",
      " hhhhhhhhhhhhhh ",
      " hijh        kh ",
      " hl h        kh ",
      " hm h        kh ",
      " hhnhhhhhhb  kh ",
      " h   opqrs   kh ",
      " h    tuwx   kh ",
      " h    yxAy   Bh ",
      " h CD  ty    BE ",
      " h  FI       J  ",
      " h KF        L  ",
      " h  FI       BE ",
      " h  F   MNOBBE  ",
      " hhhhhhhhhhh    ",
      "                "
    ],
    [
      "                ",
      " hhhhhhhhhhhhhh ",
      " h  h         h ",
      " hP h         h ",
      " hQ h         h ",
      " hhRhhhhhhb   h ",
      " S   TUrs     h ",
      " S   VWw X    h ",
      " S      x    Bh ",
      " S           BE ",
      " h           Y  ",
      " h           Z  ",
      " h           BE ",
      " h  0     xBBE  ",
      " hhhhhhh11hh    ",
      "                "
    ],
    [
      "                ",
      " hhhhhhhhhhhhhh ",
      " h  h         h ",
      " h2 h         h ",
      " h3 h         h ",
      " hh4hhhhhhb   h ",
      " h   56s      h ",
      " h   T78      h ",
      " h   VW X    Bh ",
      " h           BE ",
      " h           BE ",
      " h9          BE ",
      " h#          BE ",
      " h        XBBE  ",
      " hhhhhhhhhhh    ",
      "                "
    ],
    [
      "                ",
      " hhhhhhhhhhhhhh ",
      " h  h         h ",
      " 1  h         h ",
      " 1  h         h ",
      " hhhhhhhhhb   h ",
      " h   5        h ",
      " h   5$       h ",
      " h   T78u    Bh ",
      " h   VU%     B  ",
      " h           B  ",
      " h           B  ",
      " h           B  ",
      " h         BBE  ",
      " hhSSSSSSShh    ",
      "                "
    ],
    [
      "                ",
      " hhhhhhhhhhhhhh ",
      " h^^h&&&&&&&&&h ",
      " h^^h&&&&&&&&&h ",
      " h^^h&&&&&&&&&h ",
      " hhhhhhhhhb&&&h ",
      " h&&&*   &&&&&h ",
      " h&&&*    &&&&h ",
      " h&&&*$(  &&&Bh ",
      " h&&&)6e%&&&&B  ",
      " h&&&    &&&&B  ",
      " h&&&&&&&&&&&B  ",
      " h&&&&&&&&&&&B  ",
      " h&&&&&&&&&BBE  ",
      " hhhhhhhhhhh    ",
      "                "
    ]
  ]
}