{
  "name": "building_hotelc_base1_90",
  "refpalette": "deceasedcraft:building_hotelc/building_hotelc_base1_palette_90",
  "xsize": 16,
  "zsize": 16,
  "slices": [
    [
      "vvvvvvvvvvvvvvvv",
      "vaaaaaaaaaaaaaav",
      "va            av",
      "va            av",
      "va            av",
      "va   dffffd   av",
      "va   eihine   av",
      "va   eikmie   av",
      "va   ehjlge   av",
      "va   egiihe   av",
      "vacccdffffdoooav",
      "vabbbbbbbbbbbbav",
      "vabbbbbbbbbbbbav",
      "vabbbbbbbbbbbbav",
      "vaaaaaaaaaaaaaav",
      "vvvvvvvvvvvvvvvv"
    ],
    [
      "vvvvvvvvvvvvvvvv",
      "vaaaaaaaaaaaaaav",
      "va            av",
      "va            av",
      "va            av",
      "va   dffffd   av",
      "va   eihiie   av",
      "va   eisuie   av",
      "va   ehrtge   av",
      "vacccegiihe   av",
      "vapppdffffd   av",
      "va    qqqq    av",
      "va            av",
      "va            av",
      "vaaaaaaaaaaaaaav",
      "vvvvvvvvvvvvvvvv"
    ],
    [
      "vvvvvvvvvvvvvvvv",
      "vaaaaaaaaaaaaaav",
      "va            av",
      "va            av",
      "va            av",
      "va   dffffd   av",
      "va   eihiie   av",
      "va   eiyBie   av",
      "vacccehxAge   av",
      "vapppdgiihe   av",
      "va   dffffd   av",
      "va            av",
      "va            av",
      "va   w    w   av",
      "vaaaaaaaaaaaaaav",
      "vvvvvvvvvvvvvvvv"
    ],
    [
      "vvvvvvvvvvvvvvvv",
      "vaaaaaaaaaaaaaav",
      "va            av",
      "va            av",
      "va            av",
      "va   dffffd   av",
      "va   eihiie   av",
      "vaccceiuFie   av",
      "vapppdhDEge   av",
      "va   dgiihe   av",
      "va   dffffd   av",
      "va            av",
      "va            av",
      "va   C    C   av",
      "vaaaaaaaaaaaaaav",
      "vvvvvvvvvvvvvvvv"
    ],
    [
      "vvvvvvvvvvvvvvvv",
      "vaaaaaaaaaaaaaav",
      "va            av",
      "va            av",
      "va            av",
      "va   dffffd   av",
      "vaccceiLxie   av",
      "vapppdixDme   av",
      "va   dJKDJe   av",
      "va   dgiMhe   av",
      "va   dffffd   av",
      "va            av",
      "va            av",
      "va   I    I   av",
      "vaaaaaaaaaaaaaav",
      "vvvvvvvvvvvvvvvv"
    ],
    [
      "vvvvvvvvvvvvvvvv",
      "vaaaaaaaaaaaaaav",
      "vaNNNNNNNNNNNNav",
      "vaNNNNNNNNNNNNav",
      "vaNNNNNNNNNNNNav",
      "vacccdQQQQdNNNav",
      "vapppdDDDDdNNNav",
      "va   dPDDDdNNNav",
      "va   dDDDDdNNNav",
      "va   dDPDDdNNNav",
      "va   dOOOOdNNNav",
      "vaNNNNNNNNNNNNav",
      "vaNNNNNNNNNNNNav",
      "vaNNNNNNNNNNNNav",
      "vaaaaaaaaaaaaaav",
      "vvvvvvvvvvvvvvvv"
    ]
  ]
}