{
  "name": "building_hotelc_floor3_180",
  "refpalette": "deceasedcraft:building_hotelc/building_hotelc_floor3_palette_180",
  "xsize": 16,
  "zsize": 16,
  "slices": [
    [
      "                ",
      "    aaaaoooooaa ",
      "  niimllbbbbbba ",
      "  ibbcllbbbbbbd ",
      "  ibbcllbbbbbbd ",
      "  ibbccccccbbbd ",
      "  ibbffkj cbbbd ",
      " aibbfhh  cbbbd ",
      " abbbfg   cbbbd ",
      " abbbffe  cbbbd ",
      " acccccccccbbba ",
      " abbbbbbbbbbbba ",
      " abbbbbbbbbbbba ",
      " abbbbbbbbbbbba ",
      " aaaaaaaaaaaaaa ",
      "                "
    ],
    [
      "                ",
      "    aaaaaaaaaaa ",
      "  niiaW       a ",
      "  i VaU n TT  a ",
      "  i SaRQnOPPO a ",
      "  i NcaaaacaaMa ",
      "  i   jj  aL  a ",
      " ai  J    aK  a ",
      " a   J g  aI  a ",
      " a    FEe aD  a ",
      " aaCacaaaacB  a ",
      " at  xAyAyx  wa ",
      " at          ua ",
      " at   srrq   pa ",
      " aaaaaaaaaaaaaa ",
      "                "
    ],
    [
      "                ",
      "    aa^^aaaaaaa ",
      "  niia        a ",
      "  i  a  n     a ",
      "  i  a% n!  X a ",
      "  i $caaaacaa#a ",
      "  i       a9  5 ",
      " ai       a8  5 ",
      " a      g7a   5 ",
      " a     FE6a   5 ",
      " aa4acaaaac   a ",
      " a3  x 221x   a ",
      " a0          Za ",
      " aY  X    X   a ",
      " aaaaaaaaaaaaaa ",
      "                "
    ],
    [
      "                ",
      "    aaaaaaaaaaa ",
      "  niia]       a ",
      "  i  a  n     a ",
      "  i  a[ n     a ",
      "  i -caaaacaa&a ",
      "  i       a   a ",
      " ai      7a+  a ",
      " a      )(a   a ",
      " a      F*a   a ",
      " aa&acaaaac   a ",
      " a   x    x   a ",
      " a            a ",
      " a            a ",
      " aaaaaaaaaaaaaa ",
      "                "
    ],
    [
      "                ",
      "    aa5555555aa ",
      "  niia  n     a ",
      "  i  a  n     a ",
      "  i  a  n     a ",
      "  i  caaaacaaaa ",
      "  i     }6a   a ",
      " ai     )(a   a ",
      " a       {a   a ",
      " a        a   a ",
      " aaaacaaaac   a ",
      " a   x    x   ^ ",
      " a            ^ ",
      " a            a ",
      " aaaaaaaaaaaaaa ",
      "                "
    ],
    [
      "                ",
      "    aaaaaaaaaaa ",
      "  niia||||||||a ",
      "  iooa||||||||a ",
      "  iooa||||||||a ",
      "  ioocaaaa;:::a ",
      "  ioooo}k*a|||a ",
      " aiooo  h{a|||a ",
      " aoooo    a|||a ",
      " aooooo   a|||a ",
      " aaaacaaaa;|||a ",
      " a||||||||||||a ",
      " a||||||||||||a ",
      " a||||||||||||a ",
      " aaaaaaaaaaaaaa ",
      "                "
    ]
  ]
}