{
  "name": "building_hotelc_top_270",
  "refpalette": "deceasedcraft:building_hotelc/building_hotelc_top_palette_270",
  "xsize": 16,
  "zsize": 16,
  "slices": [
    [
      "                ",
      " aadddddddaaaaa ",
      " abbbebbbbcbbba ",
      " nbbbeeeeecbbba ",
      " nbbbebbbbcbbba ",
      " nbbbccccccbbba ",
      " nbbbe    cbbba ",
      " nbbbej   cbbba ",
      " abbbekh fcbbba ",
      " abbbeehgecbbba ",
      " albbbeeeecbbba ",
      " aibbbbbbbcbbba ",
      "  ibbbbbbbcbbba ",
      "  miiiiibbcbbba ",
      "       aaaaaaaa ",
      "                "
    ],
    [
      "                ",
      " aaaaaaaaaaaaaa ",
      " aI  Fxxxxa  oa ",
      " aE  Fyyyya  pa ",
      " ay  FAAAAa  pa ",
      " aE  caaaac  qa ",
      " a   j    a  ra ",
      " aE  j   fa  sa ",
      " ay   j gBa  sa ",
      " aE   j  Ca  ra ",
      " aI    DD c  ta ",
      " ai       r  ua ",
      "  i EyE   r  ua ",
      "  miiiii  w  ua ",
      "       aaaaaaaa ",
      "                "
    ],
    [
      "                ",
      " aaaaaRRRRaaaaa ",
      " aX       a   a ",
      " a    V T a  Ja ",
      " aY       a  Ka ",
      " a   caaaac   a ",
      " a      USa  La ",
      " a      gBa   a ",
      " Z       Ca   a ",
      " Z        a  Ma ",
      " aX       c  Na ",
      " ai       Q  Oa ",
      "  i  W       Pa ",
      "  miiiii      a ",
      "       aaaaaaaa ",
      "                "
    ],
    [
      "                ",
      " aaaaaaaaaaaaaa ",
      " a7       a   a ",
      " a        a  0a ",
      " a        a  0a ",
      " a   caaaac  1a ",
      " a     U5Fa  2a ",
      " a      6Ca  3a ",
      " a        a  2a ",
      " a        a  3a ",
      " a7       c  4a ",
      " ai           a ",
      "  i           a ",
      "  miiiii      a ",
      "       aaaaaaaa ",
      "                "
    ],
    [
      "                ",
      " aaaaaaaaaaZZaa ",
      " a        a   a ",
      " R        a   a ",
      " R        a   a ",
      " R   caaaac   a ",
      " R    S58 a   a ",
      " R    96  a   a ",
      " R        a   a ",
      " R        a   a ",
      " a        c   a ",
      " ai           a ",
      "  i           a ",
      "  miiiii      a ",
      "       aaaaaaaa ",
      "                "
    ],
    [
      "                ",
      " aaaaaaaaaaaaaa ",
      " annnnnnnna###a ",
      " annnnnnnna###a ",
      " annnnnnnna###a ",
      " annncaaaac###a ",
      " annnnF8  a###a ",
      " annnnkh  a###a ",
      " annnn9   a###a ",
      " annnnn   a###a ",
      " annnnnnnnc###a ",
      " ainnnnnnnn###a ",
      "  innnnnnnn###a ",
      "  miiiiinnn###a ",
      "       aaaaaaaa ",
      "                "
    ],
    [
      "                ",
      " aadddddddaaaaa ",
      " abbbbbbbbb$$$a ",
      " nbbbbbbbbb$$$a ",
      " nbbbbbbbbb$$$a ",
      " nbbbeeeeee$$$a ",
      " nbbbe    e$$$a ",
      " nbbbej   e$$$a ",
      " abbbekh  e$$$a ",
      " abbbeeh  e$$$a ",
      " albbbeeeee$$$a ",
      " aibbbbbbbb$$$a ",
      "  ibbbbbbbb$$$a ",
      "  miiiiibbb$$$a ",
      "       aaaaaaaa ",
      "                "
    ],
    [
      "                ",
      " aaaaaaaaaaaaaa ",
      " a]]}]++++&^^^% ",
      " a]]      *^^^% ",
      " a<;      (^^^% ",
      " a<:  8888(^^^% ",
      " a<: j   j(^^^% ",
      " a<: j   j(^^^% ",
      " a<:  j  j(^^^% ",
      " a<'  j  j(^^^% ",
      " aI    DDD(^^^% ",
      " ai       (^^^% ",
      "  i |{[   )^^^% ",
      "  miiiii--&^^^% ",
      "       aaaaaaaa ",
      "                "
    ],
    [
      "                ",
      " aaaaaRRRRaaaaa ",
      " a]       />>>a ",
      " a         >>>a ",
      " a\u0370        >>>a ",
      " a\u0370        ,,,a ",
      " a\u0370        ,,,a ",
      " a\u0370        ,,,a ",
      " Z\u0370        ...a ",
      " Z\u0370        ...a ",
      " aX        ...a ",
      " ai        ???a ",
      "  i        ???a ",
      "  miiiiiii/???a ",
      "        `aaaaaa ",
      "                "
    ],
    [
      "                ",
      " aaaaaaaaaaaaaa ",
      " a           \u0371a ",
      " a           \u0371a ",
      " a           \u0371a ",
      " a           \u0371a ",
      " a           \u0371a ",
      " a           \u0371a ",
      " a           \u0371a ",
      " a           \u0371a ",
      " a7          \u0371a ",
      " ai          \u0371a ",
      "  i          \u0371a ",
      "  miiiiiiiii \u0371a ",
      "          `aaaa ",
      "                "
    ],
    [
      "                ",
      " aaaaaaaaaaaaaa ",
      " a         \u0371\u0373\u0372a ",
      " R         \u0374\u0374\u0372a ",
      " R         \u0374\u0374\u0372a ",
      " R         \u0374\u0374\u0372a ",
      " R         \u0374\u0374\u0372a ",
      " R         \u0374\u0374\u0372a ",
      " R         \u0374\u0374\u0372a ",
      " R         \u0374\u0374\u0372a ",
      " a         \u0374\u0374\u0372a ",
      " ai        \u0374\u0374\u0372a ",
      "  i        \u0374\u0374\u0372a ",
      "  miiiiiiii\u0371\u0373\u0372a ",
      "            `aa ",
      "                "
    ],
    [
      "                ",
      " aaaaaaaaaaaaa` ",
      " a       \u0371\u0373\u0372  ` ",
      " a       \u0374\u0374   ` ",
      " a       \u0374\u0374   ` ",
      " a       \u0374\u0374   ` ",
      " a       \u0374\u0374   ` ",
      " a       \u0374\u0374   ` ",
      " a       \u0374\u0374   ` ",
      " a       \u0374\u0374   ` ",
      " a       \u0374\u0374   ` ",
      " ai      \u0374\u0374   ` ",
      "  i      \u0374\u0374   ` ",
      "  miiiiii\u0371\u0373\u0372  ` ",
      "              ` ",
      "                "
    ],
    [
      "                ",
      " aaaaaaaaaaa`   ",
      " a     \u0371\u0373\u0372      ",
      " a     \u0374\u0374       ",
      " a     \u0374\u0374       ",
      " a     \u0374\u0374       ",
      " a     \u0374\u0374       ",
      " a     \u0374\u0374       ",
      " a     \u0374\u0374       ",
      " a     \u0374\u0374       ",
      " a     \u0374\u0374       ",
      " ai    \u0374\u0374       ",
      "  i    \u0374\u0374       ",
      "  miiii\u0371\u0373\u0372      ",
      "                ",
      "                "
    ],
    [
      "                ",
      " aaaaaaaaa`     ",
      " a   \u0371\u0373\u0372        ",
      " a   \u0374\u0374         ",
      " a   \u0374\u0374         ",
      " a   \u0374\u0374         ",
      " a   \u0374\u0374         ",
      " a   \u0374\u0374         ",
      " a   \u0374\u0374         ",
      " a   \u0374\u0374         ",
      " a   \u0374\u0374         ",
      " ai  \u0374\u0374         ",
      "  i  \u0374\u0374         ",
      "  mii\u0371\u0373\u0372        ",
      "                ",
      "                "
    ],
    [
      "                ",
      " aaaaaaa`       ",
      " a\u0375\u0371\u0373\u0372          ",
      " a\u0376\u0374\u0374           ",
      " a\u0375\u0374\u0374           ",
      " a\u0376\u0374\u0374           ",
      " a\u0375\u0374\u0374           ",
      " a\u0376\u0374\u0374           ",
      " a\u0375\u0374\u0374           ",
      " a\u0376\u0374\u0374           ",
      " a\u0377\u0374\u0374           ",
      " ai\u0374\u0374           ",
      "  i\u0374\u0374           ",
      "  m\u0371\u0373\u0372          ",
      "                ",
      "                "
    ],
    [
      "                ",
      " aaaaa`         ",
      " a\u0373\u0372            ",
      " a\u0373             ",
      " a\u0373             ",
      " a\u0373             ",
      " a\u0373             ",
      " a\u0373             ",
      " a\u0373             ",
      " a\u0373             ",
      " a\u0373             ",
      " a\u0373             ",
      "  \u0373             ",
      "  \u0373\u0372            ",
      "                ",
      "                "
    ],
    [
      "                ",
      " aaa`           ",
      " a              ",
      " a              ",
      " a              ",
      " a              ",
      " a              ",
      " a              ",
      " a              ",
      " a              ",
      " a              ",
      " a              ",
      "                ",
      "                ",
      "                ",
      "                "
    ],
    [
      "                ",
      " a`             ",
      " a              ",
      " a              ",
      " a              ",
      " a              ",
      " a              ",
      " a              ",
      " a              ",
      " a              ",
      " a              ",
      " a              ",
      "                ",
      "                ",
      "                ",
      "                "
    ]
  ]
}