{
  "name": "building_hotelc_base2_180",
  "refpalette": "deceasedcraft:building_hotelc/building_hotelc_base2_palette_180",
  "xsize": 16,
  "zsize": 16,
  "slices": [
    [
      "vvvvvvvvvvvvvvvv",
      "vaaaaaaaaaaaaaav",
      "vabbbhhhhhhhhhav",
      "vabbbhhhhhhhhhav",
      "vabbbhhhhhhhhhav",
      "vabbbcccccccccav",
      "vabbbgeeefdbbbav",
      "vabbbgeeeedbbbav",
      "vabbbgfeeedbbbav",
      "vabbbgeefedbbbav",
      "vabbbccccccbbbav",
      "vabbbbbbbbbbbbav",
      "vabbbbbbbbbbbbav",
      "vabbbbbbbbbbbbav",
      "vaaaaaaaaaaaaaav",
      "vvvvvvvvvvvvvvvv"
    ],
    [
      "vvvvvvvvvvvvvvvv",
      "vaaaaaaaaaaaaaav",
      "vai  LQQTS R Rav",
      "vai  LQPON   Mav",
      "vai  LKJ     Iav",
      "va   cccccccFcav",
      "vaE tosDpqon  av",
      "vay toC!BAon  av",
      "vay toqxwson  av",
      "vau tosrqpon  av",
      "va   cmmmmc   av",
      "vai           av",
      "vai           av",
      "vaiii lkkj iiiav",
      "vaaaaaaaaaaaaaav",
      "vvvvvvvvvvvvvvvv"
    ],
    [
      "vvvvvvvvvvvvvvvv",
      "vaaaaaaaaaaaaaav",
      "vai   Lh876565av",
      "vai   Lh43    av",
      "va2   Lh      av",
      "va   cmccccc1cav",
      "va   osWpqo   av",
      "va   oW0ZWo   av",
      "va   oqYXso   av",
      "va   osWqpo   av",
      "va   cmmmmc   av",
      "vaV           av",
      "vai           av",
      "vaii       Uiiav",
      "vaaaaaaaaaaaaaav",
      "vvvvvvvvvvvvvvvv"
    ],
    [
      "vvvvvvvvvvvvvvvv",
      "vaaaaaaaaaaaaaav",
      "va     L()    av",
      "va     L(K    av",
      "va     L(*&   av",
      "va   cmmccccccav",
      "va   osWpqo ^ av",
      "va   oWD%Wo   av",
      "va   oq$#so   av",
      "va   o9Wqpo   av",
      "va   cmmmmc   av",
      "va            av",
      "va            av",
      "va            av",
      "vaaaaaaaaaaaaaav",
      "vvvvvvvvvvvvvvvv"
    ],
    [
      "vvvvvvvvvvvvvvvv",
      "vaaaaaaaaaaaaaav",
      "va      L(    av",
      "va      L(    av",
      "va      L(    av",
      "va   cmmmcccccav",
      "va   osWpqo   av",
      "va   oWC[Wo   av",
      "va   oq-+so   av",
      "va   oWWqpo   av",
      "va   cmmmmc   av",
      "va            av",
      "va            av",
      "va            av",
      "vaaaaaaaaaaaaaav",
      "vvvvvvvvvvvvvvvv"
    ],
    [
      "vvvvvvvvvvvvvvvv",
      "vaaaaaaaaaaaaaav",
      "va       L(}}}av",
      "va       L(}}}av",
      "va       L(}}}av",
      "va   cmmmmccccav",
      "va   osWpqo]]]av",
      "va   oWXZWo]]]av",
      "va   oq[{9o]]]av",
      "va   oWWqpo]]]av",
      "va   cmmmmc]]]av",
      "va         ]]]av",
      "va         ]]]av",
      "va         ]]]av",
      "vaaaaaaaaaaaaaav",
      "vvvvvvvvvvvvvvvv"
    ]
  ]
}