{
  "name": "building_hotelc_base2",
  "refpalette": "deceasedcraft:building_hotelc/building_hotelc_base2_palette",
  "xsize": 16,
  "zsize": 16,
  "slices": [
    [
      "vvvvvvvvvvvvvvvv",
      "vaaaaaaaaaaaaaav",
      "vabbbbbbbbbbbbav",
      "vabbbbbbbbbbbbav",
      "vabbbbbbbbbbbbav",
      "vabbbccccccbbbav",
      "vabbbdefeegbbbav",
      "vabbbdeeefgbbbav",
      "vabbbdeeeegbbbav",
      "vabbbdfeeegbbbav",
      "vacccccccccbbbav",
      "vahhhhhhhhhbbbav",
      "vahhhhhhhhhbbbav",
      "vahhhhhhhhhbbbav",
      "vaaaaaaaaaaaaaav",
      "vvvvvvvvvvvvvvvv"
    ],
    [
      "vvvvvvvvvvvvvvvv",
      "vaaaaaaaaaaaaaav",
      "vaiii jkkl iiiav",
      "va           iav",
      "va           iav",
      "va   cmmmmc   av",
      "va  nopqrsot uav",
      "va  noswxqot yav",
      "va  noAB!Cot yav",
      "va  noqpDsot Eav",
      "vacFccccccc   av",
      "vaI     JKL  iav",
      "vaM   NOPQL  iav",
      "vaR R STQQL  iav",
      "vaaaaaaaaaaaaaav",
      "vvvvvvvvvvvvvvvv"
    ],
    [
      "vvvvvvvvvvvvvvvv",
      "vaaaaaaaaaaaaaav",
      "vaiiU       iiav",
      "va           iav",
      "va           Vav",
      "va   cmmmmc   av",
      "va   opqWso   av",
      "va   osXYqo   av",
      "va   oWZ0Wo   av",
      "va   oqpWso   av",
      "vac1cccccmc   av",
      "va      hL   2av",
      "va    34hL   iav",
      "va565678hL   iav",
      "vaaaaaaaaaaaaaav",
      "vvvvvvvvvvvvvvvv"
    ],
    [
      "vvvvvvvvvvvvvvvv",
      "vaaaaaaaaaaaaaav",
      "va            av",
      "va            av",
      "va            av",
      "va   cmmmmc   av",
      "va   opqW9o   av",
      "va   os#$qo   av",
      "va   oW%DWo   av",
      "va ^ oqpWso   av",
      "vaccccccmmc   av",
      "va   &*(L     av",
      "va    K(L     av",
      "va    )(L     av",
      "vaaaaaaaaaaaaaav",
      "vvvvvvvvvvvvvvvv"
    ],
    [
      "vvvvvvvvvvvvvvvv",
      "vaaaaaaaaaaaaaav",
      "va            av",
      "va            av",
      "va            av",
      "va   cmmmmc   av",
      "va   opqWWo   av",
      "va   os+-qo   av",
      "va   oW[CWo   av",
      "va   oqpWso   av",
      "vacccccmmmc   av",
      "va    (L      av",
      "va    (L      av",
      "va    (L      av",
      "vaaaaaaaaaaaaaav",
      "vvvvvvvvvvvvvvvv"
    ],
    [
      "vvvvvvvvvvvvvvvv",
      "vaaaaaaaaaaaaaav",
      "va]]]         av",
      "va]]]         av",
      "va]]]         av",
      "va]]]cmmmmc   av",
      "va]]]opqWWo   av",
      "va]]]o9{[qo   av",
      "va]]]oWZXWo   av",
      "va]]]oqpWso   av",
      "vaccccmmmmc   av",
      "va}}}(L       av",
      "va}}}(L       av",
      "va}}}(L       av",
      "vaaaaaaaaaaaaaav",
      "vvvvvvvvvvvvvvvv"
    ]
  ]
}