{
  "name": "building_hotelc_base1",
  "refpalette": "deceasedcraft:building_hotelc/building_hotelc_base1_palette",
  "xsize": 16,
  "zsize": 16,
  "slices": [
    [
      "vvvvvvvvvvvvvvvv",
      "vaaaaaaaaaaaaaav",
      "vabbbc        av",
      "vabbbc        av",
      "vabbbc        av",
      "vabbbdeeeed   av",
      "vabbbfghiif   av",
      "vabbbfijkhf   av",
      "vabbbfilmif   av",
      "vabbbfhginf   av",
      "vabbbdeeeed   av",
      "vabbbo        av",
      "vabbbo        av",
      "vabbbo        av",
      "vaaaaaaaaaaaaaav",
      "vvvvvvvvvvvvvvvv"
    ],
    [
      "vvvvvvvvvvvvvvvv",
      "vaaaaaaaaaaaaaav",
      "va   pc       av",
      "va   pc       av",
      "va   pc       av",
      "va   deeeed   av",
      "va  qfghiif   av",
      "va  qfirshf   av",
      "va  qfituif   av",
      "va  qfhgiif   av",
      "va   deeeed   av",
      "va            av",
      "va            av",
      "va            av",
      "vaaaaaaaaaaaaaav",
      "vvvvvvvvvvvvvvvv"
    ],
    [
      "vvvvvvvvvvvvvvvv",
      "vaaaaaaaaaaaaaav",
      "va    pc      av",
      "va    pc      av",
      "va    pc      av",
      "vaw  ddeeed   av",
      "va   fghiif   av",
      "va   fixyhf   av",
      "va   fiABif   av",
      "va   fhgiif   av",
      "vaw  deeeed   av",
      "va            av",
      "va            av",
      "va            av",
      "vaaaaaaaaaaaaaav",
      "vvvvvvvvvvvvvvvv"
    ],
    [
      "vvvvvvvvvvvvvvvv",
      "vaaaaaaaaaaaaaav",
      "va     pc     av",
      "va     pc     av",
      "va     pc     av",
      "vaC  dddeed   av",
      "va   fghiif   av",
      "va   fiDuhf   av",
      "va   fiEFif   av",
      "va   fhgiif   av",
      "vaC  deeeed   av",
      "va            av",
      "va            av",
      "va            av",
      "vaaaaaaaaaaaaaav",
      "vvvvvvvvvvvvvvvv"
    ],
    [
      "vvvvvvvvvvvvvvvv",
      "vaaaaaaaaaaaaaav",
      "va      pc    av",
      "va      pc    av",
      "va      pc    av",
      "vaI  dddded   av",
      "va   fgJiif   av",
      "va   fiKxLf   av",
      "va   fMDDxf   av",
      "va   fhJmif   av",
      "vaI  deeeed   av",
      "va            av",
      "va            av",
      "va            av",
      "vaaaaaaaaaaaaaav",
      "vvvvvvvvvvvvvvvv"
    ],
    [
      "vvvvvvvvvvvvvvvv",
      "vaaaaaaaaaaaaaav",
      "vaNNN    pcNNNav",
      "vaNNN    pcNNNav",
      "vaNNN    pcNNNav",
      "vaNNNddddddNNNav",
      "vaNNNODDPDQNNNav",
      "vaNNNOPDDDQNNNav",
      "vaNNNODDDDQNNNav",
      "vaNNNODDDDQNNNav",
      "vaNNNddddddNNNav",
      "vaNNNNNNNNNNNNav",
      "vaNNNNNNNNNNNNav",
      "vaNNNNNNNNNNNNav",
      "vaaaaaaaaaaaaaav",
      "vvvvvvvvvvvvvvvv"
    ]
  ]
}