{
  "name": "building_hotelc_base2_90",
  "refpalette": "deceasedcraft:building_hotelc/building_hotelc_base2_palette_90",
  "xsize": 16,
  "zsize": 16,
  "slices": [
    [
      "vvvvvvvvvvvvvvvv",
      "vaaaaaaaaaaaaaav",
      "vabbbbbbbbbbbbav",
      "vabbbbbbbbbbbbav",
      "vabbbbbbbbbbbbav",
      "vabbbcggggchhhav",
      "vabbbcefeechhhav",
      "vabbbceeeechhhav",
      "vabbbcfeeechhhav",
      "vabbbceeefchhhav",
      "vabbbcddddchhhav",
      "vabbbbbbbbchhhav",
      "vabbbbbbbbchhhav",
      "vabbbbbbbbchhhav",
      "vaaaaaaaaaaaaaav",
      "vvvvvvvvvvvvvvvv"
    ],
    [
      "vvvvvvvvvvvvvvvv",
      "vaaaaaaaaaaaaaav",
      "vaiii uyyE iiiav",
      "vai           av",
      "vai   tttt    av",
      "va   coooocLLLav",
      "val  msqCscKQQav",
      "vak  mrx!DcJPQav",
      "vak  mqwBpc OTav",
      "vaj  mpsAqc NSav",
      "va   cooooc   av",
      "vai   nnnnc  Rav",
      "vai       F   av",
      "vai       cIMRav",
      "vaaaaaaaaaaaaaav",
      "vvvvvvvvvvvvvvvv"
    ],
    [
      "vvvvvvvvvvvvvvvv",
      "vaaaaaaaaaaaaaav",
      "vaiiV      2iiav",
      "vai           av",
      "va            av",
      "va   cooooc   av",
      "va   msqWsmLLLav",
      "va   mWY0Wchhhav",
      "va   mqXZpc 48av",
      "va   mpsWqc 37av",
      "va   cooooc  6av",
      "vaU       c  5av",
      "vai       1  6av",
      "vai       c  5av",
      "vaaaaaaaaaaaaaav",
      "vvvvvvvvvvvvvvvv"
    ],
    [
      "vvvvvvvvvvvvvvvv",
      "vaaaaaaaaaaaaaav",
      "va            av",
      "va            av",
      "va            av",
      "va   cooooc   av",
      "va   m9qWsm   av",
      "va   mW$DWmLLLav",
      "va   mq#%pc(((av",
      "va   mpsWqc*K)av",
      "va   cooooc&  av",
      "va        c   av",
      "va       ^c   av",
      "va        c   av",
      "vaaaaaaaaaaaaaav",
      "vvvvvvvvvvvvvvvv"
    ],
    [
      "vvvvvvvvvvvvvvvv",
      "vaaaaaaaaaaaaaav",
      "va            av",
      "va            av",
      "va            av",
      "va   cooooc   av",
      "va   mWqWsm   av",
      "va   mW-CWm   av",
      "va   mq+[pmLLLav",
      "va   mpsWqc(((av",
      "va   cooooc   av",
      "va        c   av",
      "va        c   av",
      "va        c   av",
      "vaaaaaaaaaaaaaav",
      "vvvvvvvvvvvvvvvv"
    ],
    [
      "vvvvvvvvvvvvvvvv",
      "vaaaaaaaaaaaaaav",
      "va            av",
      "va            av",
      "va            av",
      "va   cooooc   av",
      "va   mWqWsm   av",
      "va   mW[XWm   av",
      "va   mq{Zpm   av",
      "va   mp9WqmLLLav",
      "va   cooooc(((av",
      "va]]]]]]]]c}}}av",
      "va]]]]]]]]c}}}av",
      "va]]]]]]]]c}}}av",
      "vaaaaaaaaaaaaaav",
      "vvvvvvvvvvvvvvvv"
    ]
  ]
}