{
  "name": "building_hotelc_ground_270",
  "refpalette": "deceasedcraft:building_hotelc/building_hotelc_ground_palette_270",
  "xsize": 16,
  "zsize": 16,
  "slices": [
    [
      "aaaaaaaaaaaaaaaa",
      "abbbbbbbbbbbbbba",
      "abffffffffbcccba",
      "abffffffffbcccba",
      "abffffffffbdddba",
      "abffffffffb   ba",
      "abfffffggfb   ba",
      "abffffggg!b   ba",
      "abffffgggfb   ba",
      "abfffffggfb   ba",
      "abffffffffbeeeba",
      "abffffffffffffba",
      "ffffffffffffffba",
      "ffffffffggggggba",
      "fffffffbbbbbbbba",
      "fffffffaaaaaaaaa"
    ],
    [
      "                ",
      " hhhhhhhhhhhhhh ",
      " h        hmlih ",
      " h  K C   n  jh ",
      " hFFFFD   hhhhh ",
      " h I I   oh   h ",
      " h     ytph   h ",
      " h    txuqh   h ",
      " hM   yAwrh   h ",
      " hN    yxsh   h ",
      " hO       b   h ",
      " hB           h ",
      "  B           h ",
      "  EBLJBBkkkkkkh ",
      "   E  Ehhhhhhhh ",
      "                "
    ],
    [
      "                ",
      " hhhhhSSSShhhhh ",
      " h        hQP h ",
      " h        R   h ",
      " h0       hhhhh ",
      " h      VTh   h ",
      " h      WUh   h ",
      " h      wrh   h ",
      " 1     x sh   h ",
      " 1      X h   h ",
      " hx       b   h ",
      " hB           h ",
      "  B           h ",
      "  EBZYBB      h ",
      "   E  Ehhhhhhhh ",
      "                "
    ],
    [
      "                ",
      " hhhhhhhhhhhhhh ",
      " h #9     h32 h ",
      " h        4   h ",
      " h        hhhhh ",
      " h     VT5h   h ",
      " h     W76h   h ",
      " h      8sh   h ",
      " h     X  h   h ",
      " h        h   h ",
      " hX       b   h ",
      " hB           h ",
      "  B           h ",
      "  EBBBBB      h ",
      "   EEEEhhhhhhhh ",
      "                "
    ],
    [
      "                ",
      " hhhhhhhhhh11hh ",
      " h        h   h ",
      " S        h   h ",
      " S        hhhhh ",
      " S    VT55h   h ",
      " S    U7$ h   h ",
      " S    %8  h   h ",
      " S     u  h   h ",
      " S        h   h ",
      " h        b   h ",
      " hB           h ",
      "  B           h ",
      "  EBBBBB      h ",
      "       hhhhhhhh ",
      "                "
    ],
    [
      "                ",
      " hhhhhhhhhhhhhh ",
      " h&&&&&&&&h^^^h ",
      " h&&&&&&&&h^^^h ",
      " h&&&&&&&&hhhhh ",
      " h&&& )***h&&&h ",
      " h&&& 6$  h&&&h ",
      " h&&& e(  h&&&h ",
      " h&&& %   h&&&h ",
      " h&&&&&  &h&&&h ",
      " h&&&&&&&&b&&&h ",
      " hB&&&&&&&&&&&h ",
      "  B&&&&&&&&&&&h ",
      "  EBBBBB&&&&&&h ",
      "       hhhhhhhh ",
      "                "
    ]
  ]
}