{
  "name": "building_hotelc_base1_180",
  "refpalette": "deceasedcraft:building_hotelc/building_hotelc_base1_palette_180",
  "xsize": 16,
  "zsize": 16,
  "slices": [
    [
      "vvvvvvvvvvvvvvvv",
      "vaaaaaaaaaaaaaav",
      "va        obbbav",
      "va        obbbav",
      "va        obbbav",
      "va   deeeedbbbav",
      "va   fnighfbbbav",
      "va   fimlifbbbav",
      "va   fhkjifbbbav",
      "va   fiihgfbbbav",
      "va   deeeedbbbav",
      "va        cbbbav",
      "va        cbbbav",
      "va        cbbbav",
      "vaaaaaaaaaaaaaav",
      "vvvvvvvvvvvvvvvv"
    ],
    [
      "vvvvvvvvvvvvvvvv",
      "vaaaaaaaaaaaaaav",
      "va            av",
      "va            av",
      "va            av",
      "va   deeeed   av",
      "va   fiighfq  av",
      "va   fiutifq  av",
      "va   fhsrifq  av",
      "va   fiihgfq  av",
      "va   deeeed   av",
      "va       cp   av",
      "va       cp   av",
      "va       cp   av",
      "vaaaaaaaaaaaaaav",
      "vvvvvvvvvvvvvvvv"
    ],
    [
      "vvvvvvvvvvvvvvvv",
      "vaaaaaaaaaaaaaav",
      "va            av",
      "va            av",
      "va            av",
      "va   deeeed  wav",
      "va   fiighf   av",
      "va   fiBAif   av",
      "va   fhyxif   av",
      "va   fiihgf   av",
      "va   deeedd  wav",
      "va      cp    av",
      "va      cp    av",
      "va      cp    av",
      "vaaaaaaaaaaaaaav",
      "vvvvvvvvvvvvvvvv"
    ],
    [
      "vvvvvvvvvvvvvvvv",
      "vaaaaaaaaaaaaaav",
      "va            av",
      "va            av",
      "va            av",
      "va   deeeed  Cav",
      "va   fiighf   av",
      "va   fiFEif   av",
      "va   fhuDif   av",
      "va   fiihgf   av",
      "va   deeddd  Cav",
      "va     cp     av",
      "va     cp     av",
      "va     cp     av",
      "vaaaaaaaaaaaaaav",
      "vvvvvvvvvvvvvvvv"
    ],
    [
      "vvvvvvvvvvvvvvvv",
      "vaaaaaaaaaaaaaav",
      "va            av",
      "va            av",
      "va            av",
      "va   deeeed  Iav",
      "va   fimJhf   av",
      "va   fxDDMf   av",
      "va   fLxKif   av",
      "va   fiiJgf   av",
      "va   dedddd  Iav",
      "va    cp      av",
      "va    cp      av",
      "va    cp      av",
      "vaaaaaaaaaaaaaav",
      "vvvvvvvvvvvvvvvv"
    ],
    [
      "vvvvvvvvvvvvvvvv",
      "vaaaaaaaaaaaaaav",
      "vaNNNNNNNNNNNNav",
      "vaNNNNNNNNNNNNav",
      "vaNNNNNNNNNNNNav",
      "vaNNNddddddNNNav",
      "vaNNNQDDDDONNNav",
      "vaNNNQDDDDONNNav",
      "vaNNNQDDDPONNNav",
      "vaNNNQDPDDONNNav",
      "vaNNNddddddNNNav",
      "vaNNNcp    NNNav",
      "vaNNNcp    NNNav",
      "vaNNNcp    NNNav",
      "vaaaaaaaaaaaaaav",
      "vvvvvvvvvvvvvvvv"
    ]
  ]
}