{
  "name": "building_hotelc_ground_180",
  "refpalette": "deceasedcraft:building_hotelc/building_hotelc_ground_palette_180",
  "xsize": 16,
  "zsize": 16,
  "slices": [
    [
      "ffffaaaaaaaaaaaa",
      "ffffbbbbbbbbbbba",
      "ffffffffffffffba",
      "ffffffffffffffba",
      "ffffffffffffffba",
      "ffffffffffffffba",
      "fffffffggfffffba",
      "abffffggggffffba",
      "abgfffggggffffba",
      "abgfffff!fffffba",
      "abgffbbbbbbbbbba",
      "abgffe     dccba",
      "abgffe     dccba",
      "abgffe     dccba",
      "abbbbbbbbbbbbbba",
      "aaaaaaaaaaaaaaaa"
    ],
    [
      "                ",
      "    hhhhhhhhhhh ",
      "  EBBONM   F  h ",
      " EB       IF  h ",
      "  L        FK h ",
      "  J       IF  h ",
      " EB    yt  DC h ",
      " hB   yAxy    h ",
      " hk   xwut    h ",
      " hk   srqpo   h ",
      " hk  bhhhhhhnhh ",
      " hk        h mh ",
      " hk        h lh ",
      " hk        hjih ",
      " hhhhhhhhhhhhhh ",
      "                "
    ],
    [
      "                ",
      "    hh11hhhhhhh ",
      "  EBBx     0  h ",
      " EB           h ",
      "  Z           h ",
      "  Y           h ",
      " EB           S ",
      " hB    x      S ",
      " h    X wWV   S ",
      " h     srUT   S ",
      " h   bhhhhhhRhh ",
      " h         h Qh ",
      " h         h Ph ",
      " h         h  h ",
      " hhhhhhhhhhhhhh ",
      "                "
    ],
    [
      "                ",
      "    hhhhhhhhhhh ",
      "  EBBX        h ",
      " EB          #h ",
      " EB          9h ",
      " EB           h ",
      " EB           h ",
      " hB    X WV   h ",
      " h      87T   h ",
      " h      s65   h ",
      " h   bhhhhhh4hh ",
      " h         h 3h ",
      " h         h 2h ",
      " h         h  h ",
      " hhhhhhhhhhhhhh ",
      "                "
    ],
    [
      "                ",
      "    hhSSSSSSShh ",
      "  EBB         h ",
      "  B           h ",
      "  B           h ",
      "  B           h ",
      "  B     %UV   h ",
      " hB    u87T   h ",
      " h       $5   h ",
      " h        5   h ",
      " h   bhhhhhhhhh ",
      " h         h  1 ",
      " h         h  1 ",
      " h         h  h ",
      " hhhhhhhhhhhhhh ",
      "                "
    ],
    [
      "                ",
      "    hhhhhhhhhhh ",
      "  EBB&&&&&&&&&h ",
      "  B&&&&&&&&&&&h ",
      "  B&&&&&&&&&&&h ",
      "  B&&&&    &&&h ",
      "  B&&&&%e6)&&&h ",
      " hB&&&  ($*&&&h ",
      " h&&&&    *&&&h ",
      " h&&&&&   *&&&h ",
      " h&&&bhhhhhhhhh ",
      " h&&&&&&&&&h^^h ",
      " h&&&&&&&&&h^^h ",
      " h&&&&&&&&&h^^h ",
      " hhhhhhhhhhhhhh ",
      "                "
    ]
  ]
}