{
  "name": "building_hotelc_top_180",
  "refpalette": "deceasedcraft:building_hotelc/building_hotelc_top_palette_180",
  "xsize": 16,
  "zsize": 16,
  "slices": [
    [
      "                ",
      "    aaaannnnnaa ",
      "  miilbbbbbbbba ",
      "  ibbbbbbbbbbbd ",
      "  ibbbbbbbbbbbd ",
      "  ibbbeeeeceeed ",
      "  ibbeekj cbebd ",
      " aibbehh  cbebd ",
      " abbbeg   cbebd ",
      " abbbeef  cbebd ",
      " acccccccccccca ",
      " abbbbbbbbbbbba ",
      " abbbbbbbbbbbba ",
      " abbbbbbbbbbbba ",
      " aaaaaaaaaaaaaa ",
      "                "
    ],
    [
      "                ",
      "    aaaaaaaaaaa ",
      "  miiIEyE EyEIa ",
      "  i           a ",
      "  iE          a ",
      "  iy    jjcFFFa ",
      "  iE  jj  aAyxa ",
      " ai  D    aAyxa ",
      " a   D g  aAyxa ",
      " a    CBf aAyxa ",
      " awrrcaaaacaaaa ",
      " a            a ",
      " a            a ",
      " auuutrssrqppoa ",
      " aaaaaaaaaaaaaa ",
      "                "
    ],
    [
      "                ",
      "    aaZZaaaaaaa ",
      "  miiX     Y Xa ",
      "  i           a ",
      "  i           a ",
      "  iW      c   a ",
      "  i       a V R ",
      " ai       a   R ",
      " a      gUa T R ",
      " a     CBSa   R ",
      " a  Qcaaaacaaaa ",
      " a            a ",
      " a            a ",
      " a PONM  L KJ a ",
      " aaaaaaaaaaaaaa ",
      "                "
    ],
    [
      "                ",
      "    aaaaaaaaaaa ",
      "  mii7       7a ",
      "  i           a ",
      "  i           a ",
      "  i       c   a ",
      "  i       a   a ",
      " ai      Ua   a ",
      " a      65a   a ",
      " a      CFa   a ",
      " a   caaaacaaaa ",
      " a            a ",
      " a            a ",
      " a   43232100 a ",
      " aaaaaaaaaaaaaa ",
      "                "
    ],
    [
      "                ",
      "    aaRRRRRRRaa ",
      "  mii         a ",
      "  i           a ",
      "  i           a ",
      "  i       c   a ",
      "  i     9Sa   a ",
      " ai     65a   a ",
      " a       8a   a ",
      " a        a   a ",
      " a   caaaacaaaa ",
      " a            Z ",
      " a            Z ",
      " a            a ",
      " aaaaaaaaaaaaaa ",
      "                "
    ],
    [
      "                ",
      "    aaaaaaaaaaa ",
      "  miinnnnnnnnna ",
      "  innnnnnnnnnna ",
      "  innnnnnnnnnna ",
      "  innnnnnncnnna ",
      "  innnn9kFannna ",
      " ainnn  h8annna ",
      " annnn    annna ",
      " annnn    annna ",
      " annncaaaacaaaa ",
      " a############a ",
      " a############a ",
      " a############a ",
      " aaaaaaaaaaaaaa ",
      "                "
    ],
    [
      "                ",
      "    aaaannnnnaa ",
      "  miilbbbbbbbba ",
      "  ibbbbbbbbbbbd ",
      "  ibbbbbbbbbbbd ",
      "  ibbbeeeeebbbd ",
      "  ibbeekj ebbbd ",
      " aibbehh  ebbbd ",
      " abbbe    ebbbd ",
      " abbbe    ebbbd ",
      " abbbeeeeeebbba ",
      " a$$$$$$$$$$$$a ",
      " a$$$$$$$$$$$$a ",
      " a$$$$$$$$$$$$a ",
      " aaaaaaaaaaaaaa ",
      "                "
    ],
    [
      "                ",
      "    aaaaaaaaaaa ",
      "  miiI<<<<<<]]a ",
      "  i   '::::;]]a ",
      "  i|         }a ",
      "  i{    jj   ]a ",
      "  i[  jj  8  +a ",
      " ai  D    8  +a ",
      " a-  D    8  +a ",
      " a-  Djjjj8  +a ",
      " a&)((((((((*&a ",
      " a^^^^^^^^^^^^a ",
      " a^^^^^^^^^^^^a ",
      " a^^^^^^^^^^^^a ",
      " a%%%%%%%%%%%%a ",
      "                "
    ],
    [
      "                ",
      "    aaZZaaaaaaa ",
      "  miiX\u0370\u0370\u0370\u0370\u0370\u0370 ]a ",
      "  i           a ",
      "  i           a ",
      "  i           a ",
      "  i           R ",
      "  i           R ",
      " `i           R ",
      " ai           R ",
      " a/          /a ",
      " a???...,,,>>>a ",
      " a???...,,,>>>a ",
      " a???...,,,>>>a ",
      " aaaaaaaaaaaaaa ",
      "                "
    ],
    [
      "                ",
      "    aaaaaaaaaaa ",
      "  mii7        a ",
      "  i           a ",
      "  i           a ",
      "  i           a ",
      "  i           a ",
      "  i           a ",
      "  i           a ",
      "  i           a ",
      " `i           a ",
      " ai           a ",
      " a            a ",
      " a\u0371\u0371\u0371\u0371\u0371\u0371\u0371\u0371\u0371\u0371\u0371\u0371a ",
      " aaaaaaaaaaaaaa ",
      "                "
    ],
    [
      "                ",
      "    aaRRRRRRRaa ",
      "  mii         a ",
      "  i           a ",
      "  i           a ",
      "  i           a ",
      "  i           a ",
      "  i           a ",
      "  i           a ",
      "  i           a ",
      "  i           a ",
      "  \u0371\u0374\u0374\u0374\u0374\u0374\u0374\u0374\u0374\u0374\u0374\u0371a ",
      " `\u0373\u0374\u0374\u0374\u0374\u0374\u0374\u0374\u0374\u0374\u0374\u0373a ",
      " a\u0372\u0372\u0372\u0372\u0372\u0372\u0372\u0372\u0372\u0372\u0372\u0372a ",
      " aaaaaaaaaaaaaa ",
      "                "
    ],
    [
      "                ",
      "    aaaaaaaaaaa ",
      "  mii         a ",
      "  i           a ",
      "  i           a ",
      "  i           a ",
      "  i           a ",
      "  i           a ",
      "  i           a ",
      "  \u0371\u0374\u0374\u0374\u0374\u0374\u0374\u0374\u0374\u0374\u0374\u0371a ",
      "  \u0373\u0374\u0374\u0374\u0374\u0374\u0374\u0374\u0374\u0374\u0374\u0373a ",
      "  \u0372          \u0372a ",
      "              a ",
      "              a ",
      " `````````````` ",
      "                "
    ],
    [
      "                ",
      "    aaaaaaaaaaa ",
      "  mii         a ",
      "  i           a ",
      "  i           a ",
      "  i           a ",
      "  i           a ",
      "  \u0371\u0374\u0374\u0374\u0374\u0374\u0374\u0374\u0374\u0374\u0374\u0371a ",
      "  \u0373\u0374\u0374\u0374\u0374\u0374\u0374\u0374\u0374\u0374\u0374\u0373a ",
      "  \u0372          \u0372a ",
      "              a ",
      "              a ",
      "              ` ",
      "                ",
      "                ",
      "                "
    ],
    [
      "                ",
      "    aaaaaaaaaaa ",
      "  mii         a ",
      "  i           a ",
      "  i           a ",
      "  \u0371\u0374\u0374\u0374\u0374\u0374\u0374\u0374\u0374\u0374\u0374\u0371a ",
      "  \u0373\u0374\u0374\u0374\u0374\u0374\u0374\u0374\u0374\u0374\u0374\u0373a ",
      "  \u0372          \u0372a ",
      "              a ",
      "              a ",
      "              ` ",
      "                ",
      "                ",
      "                ",
      "                ",
      "                "
    ],
    [
      "                ",
      "    aaaaaaaaaaa ",
      "  mii\u0377\u0376\u0375\u0376\u0375\u0376\u0375\u0376\u0375a ",
      "  \u0371\u0374\u0374\u0374\u0374\u0374\u0374\u0374\u0374\u0374\u0374\u0371a ",
      "  \u0373\u0374\u0374\u0374\u0374\u0374\u0374\u0374\u0374\u0374\u0374\u0373a ",
      "  \u0372          \u0372a ",
      "              a ",
      "              a ",
      "              ` ",
      "                ",
      "                ",
      "                ",
      "                ",
      "                ",
      "                ",
      "                "
    ],
    [
      "                ",
      "    aaaaaaaaaaa ",
      "  \u0373\u0373\u0373\u0373\u0373\u0373\u0373\u0373\u0373\u0373\u0373\u0373a ",
      "  \u0372          \u0372a ",
      "              a ",
      "              a ",
      "              ` ",
      "                ",
      "                ",
      "                ",
      "                ",
      "                ",
      "                ",
      "                ",
      "                ",
      "                "
    ],
    [
      "                ",
      "    aaaaaaaaaaa ",
      "              a ",
      "              a ",
      "              ` ",
      "                ",
      "                ",
      "                ",
      "                ",
      "                ",
      "                ",
      "                ",
      "                ",
      "                ",
      "                ",
      "                "
    ],
    [
      "                ",
      "    aaaaaaaaaaa ",
      "              ` ",
      "                ",
      "                ",
      "                ",
      "                ",
      "                ",
      "                ",
      "                ",
      "                ",
      "                ",
      "                ",
      "                ",
      "                ",
      "                "
    ]
  ]
}