{
  "name": "multi_courtyardofficetower_4_floor18",
  "refpalette": "deceasedcraft:multi_courtyardofficetower_4/multi_courtyardofficetower_4_floor18_palette",
  "xsize": 16,
  "zsize": 16,
  "slices": [
    [
      "                ",
      "                ",
      "                ",
      "                ",
      "                ",
      "                ",
      "                ",
      "                ",
      "   a       a    ",
      "   a       a    ",
      "   a   b   a   b",
      "cccacccccccacccc",
      "dddddddddddddddd",
      "dddddddddddddddd",
      "dddddddddddddddd",
      "eeeeeeeeeeeeeeee"
    ],
    [
      "                ",
      "                ",
      "                ",
      "                ",
      "                ",
      "                ",
      "                ",
      "                ",
      "   a       a    ",
      "   a       a    ",
      "   a   b   a   b",
      "ffgagfffffgagfff",
      "hij hij hij hij ",
      "                ",
      "                ",
      "kkkk       kkkk "
    ],
    [
      "                ",
      "                ",
      "                ",
      "                ",
      "                ",
      "                ",
      "                ",
      "                ",
      "   a       a    ",
      "   a       a    ",
      "   a   b   a   b",
      "ffgagfffffgagfff",
      " l       m   n  ",
      "                ",
      "                ",
      "                "
    ],
    [
      "                ",
      "                ",
      "                ",
      "                ",
      "                ",
      "                ",
      "                ",
      "                ",
      "   a       a    ",
      "   a       a    ",
      "   a   b   a   b",
      "ffgagfffffgagfff",
      "                ",
      "                ",
      "                ",
      "                "
    ],
    [
      "                ",
      "                ",
      "                ",
      "                ",
      "                ",
      "                ",
      "                ",
      "                ",
      "   a       a    ",
      "   a       a    ",
      "   a   b   a   b",
      "ffgagfffffgagfff",
      "                ",
      "                ",
      "                ",
      "                "
    ],
    [
      "                ",
      "                ",
      "                ",
      "                ",
      "                ",
      "                ",
      "                ",
      "                ",
      "   a       a    ",
      "   a       a    ",
      "   a   b   a   b",
      "ffgagfffffgagfff",
      "                ",
      "                ",
      "                ",
      "                "
    ]
  ]
}