{
  "name": "multi_courtyardofficetower_4_floor17",
  "refpalette": "deceasedcraft:multi_courtyardofficetower_4/multi_courtyardofficetower_4_floor17_palette",
  "xsize": 16,
  "zsize": 16,
  "slices": [
    [
      "                ",
      "                ",
      "                ",
      "                ",
      "                ",
      "                ",
      "                ",
      "                ",
      "   a       a    ",
      "   a       a    ",
      "   a   b   a   b",
      "cccacccccccacccc",
      "dddddddddddddddd",
      "dddddddddddddddd",
      "dddddddddddddddd",
      "eeeeeeeeeeeeeeee"
    ],
    [
      "                ",
      "                ",
      "                ",
      "                ",
      "                ",
      "                ",
      "                ",
      "                ",
      "   a       a    ",
      "   a       a    ",
      "   a   b   a   b",
      "ffgagfffffgagfff",
      "  hih j   hih   ",
      "k  j  l    m    ",
      "         n      ",
      "oooo       oooo "
    ],
    [
      "                ",
      "                ",
      "                ",
      "                ",
      "                ",
      "                ",
      "                ",
      "                ",
      "   a       a    ",
      "   a       a    ",
      "   a   b   a   b",
      "ffgagfffffgagfff",
      "           p    ",
      "                ",
      "                ",
      "                "
    ],
    [
      "                ",
      "                ",
      "                ",
      "                ",
      "                ",
      "                ",
      "                ",
      "                ",
      "   a       a    ",
      "   a       a    ",
      "   a   b   a   b",
      "ffgagfffffgagfff",
      "                ",
      "                ",
      "                ",
      "                "
    ],
    [
      "                ",
      "                ",
      "                ",
      "                ",
      "                ",
      "                ",
      "                ",
      "                ",
      "   a       a    ",
      "   a       a    ",
      "   a   b   a   b",
      "ffgagfffffgagfff",
      "   q       q    ",
      "                ",
      "                ",
      "                "
    ],
    [
      "                ",
      "                ",
      "                ",
      "                ",
      "                ",
      "                ",
      "                ",
      "                ",
      "   a       a    ",
      "   a       a    ",
      "   a   b   a   b",
      "ffgagfffffgagfff",
      "rrrarrrrrrrrrrrr",
      "rsrarsrrrsrrrsrr",
      "rrrarrrrrrrrrrrr",
      "qqqaqqqqqqqqqqqq"
    ]
  ]
}