{
  "name": "multi_courtyardofficetower_4_floor14",
  "refpalette": "deceasedcraft:multi_courtyardofficetower_4/multi_courtyardofficetower_4_floor14_palette",
  "xsize": 16,
  "zsize": 16,
  "slices": [
    [
      "                ",
      "                ",
      "                ",
      "                ",
      "                ",
      "                ",
      "                ",
      "                ",
      "   a       a    ",
      "   a       a    ",
      "   a   b   a   b",
      "ccdadcccccdadccc",
      "                ",
      "                ",
      "                ",
      "eeefeeeeeeefeeeg"
    ],
    [
      "                ",
      "                ",
      "                ",
      "                ",
      "                ",
      "                ",
      "                ",
      "                ",
      "   a       a    ",
      "   a       a    ",
      "   a   b   a   b",
      "ccdadcccccdadccc",
      "                ",
      "                ",
      "                ",
      "eeefeeeeeeefeeeg"
    ],
    [
      "                ",
      "                ",
      "                ",
      "                ",
      "                ",
      "                ",
      "                ",
      "                ",
      "   a       a    ",
      "   a       a    ",
      "   a   b   a   b",
      "ccdadcccccdadccc",
      "                ",
      "                ",
      "                ",
      "eeefeeeeeeefeeeg"
    ],
    [
      "                ",
      "                ",
      "                ",
      "                ",
      "                ",
      "                ",
      "                ",
      "                ",
      "   a       a    ",
      "   a       a    ",
      "   a   b   a   b",
      "ccdadcccccdadccc",
      "                ",
      "                ",
      "                ",
      "eeefeeeeeeefeeeh"
    ],
    [
      "                ",
      "                ",
      "                ",
      "                ",
      "                ",
      "                ",
      "                ",
      "                ",
      "   a       a    ",
      "   a       a    ",
      "   a   b   a   b",
      "ccdadcccccdadccc",
      "                ",
      "                ",
      "                ",
      "eeefeeeeeeefeeei"
    ],
    [
      "                ",
      "                ",
      "                ",
      "                ",
      "                ",
      "                ",
      "                ",
      "                ",
      "   a       a    ",
      "   a       a    ",
      "   a   b   a   b",
      "ccdadcccccdadccc",
      "jjjajjjjjjjjjjjj",
      "jkjajkjjjkjjjkjj",
      "jjjajjjjjjjjjjjj",
      "lllallllllllllll"
    ]
  ]
}