{
  "name": "multi_courtyardofficetower_4_floor13",
  "refpalette": "deceasedcraft:multi_courtyardofficetower_4/multi_courtyardofficetower_4_floor13_palette",
  "xsize": 16,
  "zsize": 16,
  "slices": [
    [
      "                ",
      "                ",
      "                ",
      "                ",
      "                ",
      "                ",
      "                ",
      "                ",
      "   a       a    ",
      "   a       a    ",
      "   a   b   a   b",
      "ccdadcccccdadccc",
      "eeeeeeeeeeeeeeee",
      "ffffffffffffffff",
      "ffffffffffffffff",
      "gggggggggggggggh"
    ],
    [
      "                ",
      "                ",
      "                ",
      "                ",
      "                ",
      "                ",
      "                ",
      "                ",
      "   a       a    ",
      "   a       a    ",
      "   a   b   a   b",
      "ccdadcccccdadccc",
      "  ijk     ijk   ",
      "                ",
      "                ",
      "lllmlllllllmllln"
    ],
    [
      "                ",
      "                ",
      "                ",
      "                ",
      "                ",
      "                ",
      "                ",
      "                ",
      "   a       a    ",
      "   a       a    ",
      "   a   b   a   b",
      "ccdadcccccdadccc",
      "                ",
      "                ",
      "                ",
      "lllmlllllllmlllo"
    ],
    [
      "                ",
      "                ",
      "                ",
      "                ",
      "                ",
      "                ",
      "                ",
      "                ",
      "   a       a    ",
      "   a       a    ",
      "   a   b   a   b",
      "ccdadcccccdadccc",
      "                ",
      "                ",
      "                ",
      "lllmlllllllmlllo"
    ],
    [
      "                ",
      "                ",
      "                ",
      "                ",
      "                ",
      "                ",
      "                ",
      "                ",
      "   a       a    ",
      "   a       a    ",
      "   a   b   a   b",
      "ccdadcccccdadccc",
      "                ",
      "                ",
      "                ",
      "lllmlllllllmlll "
    ],
    [
      "                ",
      "                ",
      "                ",
      "                ",
      "                ",
      "                ",
      "                ",
      "                ",
      "   a       a    ",
      "   a       a    ",
      "   a   b   a   b",
      "ccdadcccccdadccc",
      "                ",
      "                ",
      "                ",
      "lllmlllllllmlll "
    ]
  ]
}