{
  "name": "multi_courtyardofficetower_4_floor20",
  "refpalette": "deceasedcraft:multi_courtyardofficetower_4/multi_courtyardofficetower_4_floor20_palette",
  "xsize": 16,
  "zsize": 16,
  "slices": [
    [
      "                ",
      "                ",
      "                ",
      "                ",
      "                ",
      "                ",
      "                ",
      "                ",
      "   a       a    ",
      "   a       a    ",
      "   a   b   a   b",
      "ccdadcccccdadccc",
      "eeefeeeeeeefeeee",
      "ggggggghgggggggh",
      "ggggggghgggggggh",
      "ggggggghggggggg!"
    ],
    [
      "                ",
      "                ",
      "                ",
      "                ",
      "                ",
      "                ",
      "                ",
      "                ",
      "   a       a    ",
      "   a       a    ",
      "   a   b   a   b",
      "bbiaibbbbbiaibbb",
      "jjjkjjjjjjjkjjjj",
      "    lmnonpq lmno",
      "  r lsnontq lsno",
      " uwxlynonAq lyno"
    ],
    [
      "                ",
      "                ",
      "                ",
      "                ",
      "                ",
      "                ",
      "                ",
      "                ",
      "   a       a    ",
      "   a       a    ",
      "   a       a    ",
      "   a       a    ",
      "   B       B    ",
      "               C",
      "       D       E",
      "       F        "
    ],
    [
      "                ",
      "                ",
      "                ",
      "                ",
      "                ",
      "                ",
      "                ",
      "                ",
      "   a       a    ",
      "   a       a    ",
      "   a       a    ",
      "   a       a    ",
      "   I       I    ",
      "                ",
      "                ",
      "                "
    ],
    [
      "                ",
      "                ",
      "                ",
      "                ",
      "                ",
      "                ",
      "                ",
      "                ",
      "   a       a    ",
      "   a       a    ",
      "   a       a    ",
      "   a       a    ",
      "   I       I    ",
      "                ",
      "                ",
      "                "
    ],
    [
      "                ",
      "                ",
      "                ",
      "                ",
      "                ",
      "                ",
      "                ",
      "                ",
      "   a       a    ",
      "   a       a    ",
      "   a       a    ",
      "   a       a    ",
      "   J       J    ",
      "                ",
      "                ",
      "                "
    ]
  ]
}