{
  "name": "multi_courtyardofficetower_4_ground",
  "refpalette": "deceasedcraft:multi_courtyardofficetower_4/multi_courtyardofficetower_4_ground_palette",
  "xsize": 16,
  "zsize": 16,
  "slices": [
    [
      "aaaaaaaaaaaaaaaa",
      "bacaaaaaaacaaaaa",
      "dbccaccaccaaaccc",
      "ddbccccccccccccc",
      "bddbcacccccacccc",
      "cbddbccccaccacca",
      "acbddbaacaaaaaca",
      "caabddbaaaaaaaaa",
      "aaaebddbaaaeaaaa",
      "aaaeabddbaaeaaaa",
      "aaaeaabddbaeaaaa",
      "aaaeaaabddbeaaaa",
      "aaaaaaaabddbaaaa",
      "aaaaaaaaabddbaaa",
      "aaaaaaaaaabddbaa",
      "caaaaaaaaaabddba"
    ],
    [
      "            f   ",
      "    f           ",
      "                ",
      "                ",
      "     g          ",
      "                ",
      "                ",
      "        f       ",
      "   e      fef   ",
      "  fe      fef ff",
      "f  ef      e h  ",
      "   ef      e f f",
      " f   f g       f",
      " f   i f        ",
      "  f   f       g ",
      "      f fh      "
    ],
    [
      "                ",
      "                ",
      "                ",
      "                ",
      "                ",
      "                ",
      "                ",
      "                ",
      "   e       ef   ",
      "   e      fe    ",
      "   e       e j  ",
      "   ef      e   f",
      " f              ",
      "     k          ",
      "                ",
      "         j      "
    ],
    [
      "                ",
      "                ",
      "                ",
      "                ",
      "                ",
      "                ",
      "                ",
      "                ",
      "   e       e    ",
      "   e       e    ",
      "   e       e f  ",
      "   e       e    ",
      "                ",
      "     j          ",
      "                ",
      "         f      "
    ],
    [
      "                ",
      "                ",
      "                ",
      "                ",
      "                ",
      "                ",
      "                ",
      "                ",
      "   e       e    ",
      "   e       e    ",
      "   e       e f  ",
      "   e       e    ",
      "                ",
      "     f          ",
      "                ",
      "         f      "
    ],
    [
      "                ",
      "                ",
      "                ",
      "                ",
      "                ",
      "                ",
      "                ",
      "                ",
      "   e       e    ",
      "   e       e    ",
      "   e       e l  ",
      "   e       e    ",
      "     f          ",
      "    ff          ",
      "     l          ",
      "         f      "
    ]
  ]
}