{
  "name": "multi_oasiscondo_14_ground",
  "refpalette": "deceasedcraft:multi_oasiscondo_14/multi_oasiscondo_14_ground_palette",
  "xsize": 16,
  "zsize": 16,
  "slices": [
    [
      "      abbcdddddc",
      "      abbcdddddc",
      "      abbcdddddc",
      "      abbcdddddc",
      "     eabbcdddddc",
      "      abbcdddddc",
      "      abbcdddddc",
      "      abbcdddddc",
      "      abbcdddddc",
      "      abbcdddddc",
      "      abbccdddcc",
      "      afcccccccc",
      "      fggggggggg",
      "eeeeeehggggggggg",
      "iiiiiijjjggggggg",
      "iiiiiicjgggggggg"
    ],
    [
      "       k  lmdml ",
      "       k  lmdml ",
      "       k  lmdml ",
      "       n  lmdml ",
      "     eon  lmdml ",
      "       n  lmdml ",
      "       k  lmdml ",
      "       k  lmdml ",
      "       k  lmdml ",
      "       k  lmmml ",
      "       k   lll  ",
      "       f        ",
      "      fp        ",
      "eeeeee          ",
      "qqqqqqjjj       ",
      "r    stj        "
    ],
    [
      "                ",
      "            u   ",
      "                ",
      "                ",
      "     e      u   ",
      "                ",
      "                ",
      "            u   ",
      "                ",
      "                ",
      "                ",
      "       f        ",
      "      fp        ",
      "eeeeee          ",
      "qqqqqqjjj       ",
      "      tj        "
    ],
    [
      "                ",
      "            k   ",
      "                ",
      "                ",
      "     e      k   ",
      "                ",
      "                ",
      "            k   ",
      "                ",
      "                ",
      "                ",
      "       f        ",
      "      fp        ",
      "eeeeee          ",
      "wx yxAjjj       ",
      "      tj        "
    ],
    [
      "                ",
      "            n   ",
      "                ",
      "                ",
      "     e      n   ",
      "                ",
      "                ",
      "            n   ",
      "                ",
      "                ",
      "                ",
      "       f        ",
      "      fp        ",
      "eeeeee          ",
      "  B   jjj       ",
      "      tj        "
    ],
    [
      "                ",
      "            n   ",
      "                ",
      "                ",
      "     e      n   ",
      "                ",
      "                ",
      "            n   ",
      "                ",
      "                ",
      "                ",
      "       f        ",
      "      fp        ",
      "eeeeee          ",
      "  C   jjj       ",
      "      tj        "
    ]
  ]
}