{
  "name": "multi_oasiscondo_14_floor7",
  "refpalette": "deceasedcraft:multi_oasiscondo_14/multi_oasiscondo_14_floor7_palette",
  "xsize": 16,
  "zsize": 16,
  "slices": [
    [
      "abbbbbb         ",
      "abbbbbb         ",
      "abbbbbb         ",
      "abbbbbb         ",
      "abbbbbb         ",
      "abbbbbb         ",
      "abbbbbb         ",
      "abbbbbb         ",
      "cbbbbbb         ",
      "cbbbbbb         ",
      "abbbbbb         ",
      "adefbbb         ",
      "agh!ijk         ",
      "llllll          ",
      "abbbbbk         ",
      "abbbbbb         "
    ],
    [
      "a mnopoa        ",
      "a m   qa        ",
      "a m r sa        ",
      "a mtuwxa        ",
      "a myyyyA        ",
      "a  BCDEa        ",
      "a      a        ",
      "a  FIJKa        ",
      "L MNNNNA        ",
      "O PQRRSa        ",
      "aTU  VWA        ",
      "a X YWZA        ",
      "ae ej012        ",
      "llllll          ",
      "a3 45!a6        ",
      "a    78a        "
    ],
    [
      "a m9o#o$        ",
      "a m    $        ",
      "a m    $        ",
      "a m%^&*$        ",
      "a m(((()        ",
      "a  +-[]$        ",
      "a      $        ",
      "a     {$        ",
      "} |;;;;$        ",
      ":  ' W<$$       ",
      "a               ",
      "a      A        ",
      "aj d  >,        ",
      "llllll          ",
      ". 5  5a2        ",
      "a ?  /`a        "
    ],
    [
      "a m\u0370o\u0371o$        ",
      "a m    $        ",
      "a m    $        ",
      "a m    $        ",
      "a m(((()        ",
      "a     \u0372$        ",
      "a      $        ",
      "a      $        ",
      "\u0373 |;;;;$        ",
      "\u0373      $        ",
      "a      $        ",
      "a      \u0374        ",
      "ad\u0375 0\u03761,        ",
      "llllll          ",
      "\u0377\u037aX \u037a a6        ",
      "a      a        "
    ],
    [
      "a moooo$        ",
      "a m    $        ",
      "a m \u037b  $        ",
      "a m    $        ",
      "a m(((()        ",
      "a      $        ",
      "a   \u037b  $        ",
      "a      $        ",
      "a \u037c;;;;$$       ",
      "a P             ",
      "a   \u037d  $        ",
      "a      A        ",
      "aX  U A\u037e        ",
      "llllll          ",
      "\u037fX55 Xa6        ",
      "aX     a        "
    ],
    [
      "a\u0384\u0384\u0384\u0384\u0384\u0384A        ",
      "a\u0384\u0384\u0384\u0384\u0384\u0384a        ",
      "a\u0384\u0384\u0384\u0384\u0384\u0384a        ",
      "a\u0384\u0384\u0384\u0384\u0384\u0384a        ",
      "a\u0384\u0384\u0384\u0384\u0384\u0384a        ",
      "a\u0384\u0384\u0384\u0384\u0384\u0384A        ",
      "a\u0384\u0384\u0384\u0384\u0384\u0384a        ",
      "a\u0384\u0384\u0384\u0384\u0384\u0384A        ",
      "a\u0384\u0384\u0384\u0384\u0384\u0384A        ",
      "a\u0384\u0384\u0384\u0384\u0384\u03841        ",
      "a\u0384\u0384\u0384\u0384\u0384\u0384A        ",
      "a\u0384\u0384\u0384\u0384\u0384\u0384A        ",
      "a\u0384\u0384\u0384\u0384\u038412        ",
      "llllll          ",
      "a\u0384\u0384\u0384\u0384\u0384a2        ",
      "a\u0384\u0384\u0384\u0384\u0384\u0384a        "
    ]
  ]
}