{
  "name": "multi_oasiscondo_14_floor3",
  "refpalette": "deceasedcraft:multi_oasiscondo_14/multi_oasiscondo_14_floor3_palette",
  "xsize": 16,
  "zsize": 16,
  "slices": [
    [
      "abbbbbb         ",
      "abbbbbb         ",
      "cbbbbbb         ",
      "abbbbbd         ",
      "eeeeee          ",
      "abbbbbd         ",
      "abbbbfb         ",
      "abbbbbb         ",
      "abbbbbb         ",
      "abbbbbb         ",
      "abbbbbb         ",
      "cbbbbbb         ",
      "abbbbbd         ",
      "eeeeee          ",
      "abbbbbd         ",
      "abbbbbb         "
    ],
    [
      "ag  ahia        ",
      "ag  j ka        ",
      "l  manop        ",
      "aqrsatpu        ",
      "eeeeee          ",
      "aw xafyA        ",
      "aBBBaCDp        ",
      "a   a fE        ",
      "a   afFy        ",
      "a IJiKip        ",
      "a I   La        ",
      "l I M Np        ",
      "aOIPQRaA        ",
      "eeeeee          ",
      "aSTSUVpu        ",
      "a     Wa        "
    ],
    [
      "a   aXiY        ",
      "a   Z  Y        ",
      "0   a1 a        ",
      "a23 a4yA        ",
      "eeeeee          ",
      "a   a5p6        ",
      "a777a  y        ",
      "a   a 8Y        ",
      "a   a  Y        ",
      "a I9i#iY        ",
      "a I    Y        ",
      "0 I   Na        ",
      "a$I% ^EA        ",
      "eeeeee          ",
      "a& *()aA        ",
      "a     +a        "
    ],
    [
      "a   a-iY        ",
      "a   [  Y        ",
      "]   a  a        ",
      "a{}|a;pu        ",
      "eeeeee          ",
      "a   a:E'        ",
      "aBBBa  p        ",
      "a   a  Y        ",
      "a   a <Y        ",
      "a I-i-iY        ",
      "a I    Y        ",
      "] I ! >p        ",
      "a,I   p'        ",
      "eeeeee          ",
      "a...?/au        ",
      "a      a        "
    ],
    [
      "a   aiiY        ",
      "a   a  Y        ",
      "a   a  a        ",
      "a` \u0370a\u0371aA        ",
      "eeeeee          ",
      "a   a\u0372EA        ",
      "a777a \u0373a        ",
      "a   a\u0374 Y        ",
      "a   a\u0374\u0374Y        ",
      "a IiiiiY        ",
      "a I    Y        ",
      "a I \u0375  a        ",
      "a I   aA        ",
      "eeeeee          ",
      "a\u0376\u0377   pu        ",
      "a      p        "
    ],
    [
      "a\u037a\u037a\u037a\u037a\u037a\u037ap        ",
      "a\u037a\u037a\u037a\u037a\u037a\u037aa        ",
      "a\u037a\u037a\u037a\u037a\u037a\u037ap        ",
      "a\u037a\u037a\u037a\u037a\u037aau        ",
      "eeeeee          ",
      "a\u037a\u037a\u037a\u037a\u037apu        ",
      "a\u037a\u037a\u037a\u037a fp        ",
      "a\u037a\u037a\u037a\u037a  p        ",
      "a\u037a\u037a\u037a\u037a  a        ",
      "a\u037a\u037a\u037a\u037a\u037a\u037aa        ",
      "a\u037a\u037a\u037a\u037a\u037a\u037ap        ",
      "a\u037a\u037a\u037a\u037b\u037a\u037aa        ",
      "a\u037a\u037a\u037a\u037a\u037apu        ",
      "eeeeee          ",
      "a\u037a\u037a\u037a\u037a\u037aaA        ",
      "a\u037a\u037a\u037a\u037a\u037a\u037aa        "
    ]
  ]
}