{
  "name": "multi_oasiscondo_14_floor4",
  "refpalette": "deceasedcraft:multi_oasiscondo_14/multi_oasiscondo_14_floor4_palette",
  "xsize": 16,
  "zsize": 16,
  "slices": [
    [
      "abbbbbb         ",
      "abbbbbb         ",
      "cbbbbbb         ",
      "abbbbbd         ",
      "eeeeee          ",
      "abbbbbd         ",
      "abbbbbb         ",
      "abbbbbb         ",
      "abbbbbb         ",
      "abbbbbb         ",
      "abbbbbb         ",
      "cbbbbbb         ",
      "abbbbbd         ",
      "eeeeee          ",
      "abbbbbd         ",
      "abbbbbb         "
    ],
    [
      "a fghiha        ",
      "a f   ja        ",
      "k f l ma        ",
      "anfopoaq        ",
      "eeeeee          ",
      "arstauwww       ",
      "axy ABCwD       ",
      "aaaaaEFID       ",
      "aJKLMN ID       ",
      "a   O  ID       ",
      "a     PID       ",
      "Q f R SwD       ",
      "aTfoUowww       ",
      "eeee!e          ",
      "aVJVWKXq        ",
      "aY    Za        "
    ],
    [
      "a f0h1h2        ",
      "a f    2        ",
      "3 f   ma        ",
      "a f4  a5        ",
      "eeeeee          ",
      "a6  auwww       ",
      "a7  8F w9       ",
      "aaaa#   9       ",
      "a $% ^  9       ",
      "a      &9       ",
      "a      &9       ",
      "* f    w9       ",
      "a f  (www       ",
      "eeee)e          ",
      "a+ -[$]5        ",
      "a     {X        "
    ],
    [
      "a f}h}h2        ",
      "a f    2        ",
      "| f   ;a        ",
      "a:f   Xq        ",
      "eeeeee          ",
      "a'  a<www       ",
      "a>  ,  w        ",
      "aaaa.           ",
      "a?/`   &        ",
      "a      &        ",
      "a \u0370\u0370   &        ",
      "| f    w        ",
      "a:f   www       ",
      "eeeeee          ",
      "a???\u0371\u0372\u03735        ",
      "a      a        "
    ],
    [
      "a fhhhh2        ",
      "a f    2        ",
      "a f \u0374  X        ",
      "a f   aq        ",
      "eeeeee          ",
      "a\u0375\u0375\u0375a\u0376www       ",
      "a\u0375\u0375\u0375a  w        ",
      "aaaaa  \u0377        ",
      "a\u037a\u037b\u037c   \u0377        ",
      "a      \u0377        ",
      "a \u0370 \u0374  \u0377        ",
      "a f    w        ",
      "a f   www       ",
      "eeeeee          ",
      "a\u037d   \u037eXq        ",
      "a      a        "
    ],
    [
      "a\u037f\u037f\u037f\u037f\u037f\u037fX        ",
      "a\u037f\u037f\u037f\u037f\u037f\u037fa        ",
      "a\u037f\u037f\u037f\u037f\u037f\u037fa        ",
      "a\u037f\u037f\u037f\u037f\u037faq        ",
      "eeeeee          ",
      "a\u0384  \u037f\u037fwww       ",
      "a   \u037f\u037f\u037fww       ",
      "a\u037f\u037f\u037f\u037f\u037f\u037fww       ",
      "a\u037f\u037f\u037f\u037f\u037f\u037fww       ",
      "a\u037f\u037f\u037f\u037f\u037f\u037fww       ",
      "a\u037f\u037f\u037f\u037f\u037f\u037fww       ",
      "a\u037f\u037f\u037f\u037f\u037f\u037fww       ",
      "a\u037f\u037f\u037f\u037f\u037fwww       ",
      "eeeeee          ",
      "a\u037f\u037f\u037f\u037f\u037faq        ",
      "a\u037f\u037f\u037f\u037f\u037f\u037fX        "
    ]
  ]
}