{
  "name": "multi_oasiscondo_14_top",
  "refpalette": "deceasedcraft:multi_oasiscondo_14/multi_oasiscondo_14_top_palette",
  "xsize": 16,
  "zsize": 16,
  "slices": [
    [
      "aaaaaab         ",
      "aaaaaab         ",
      "aaaaaab         ",
      "aaaaaab         ",
      "aaaaacb         ",
      "aaaaaab         ",
      "aaaaaab         ",
      "aaaaaab         ",
      "aaaaaab         ",
      "aaaaaab         ",
      "aaaaaab         ",
      "aaaaaab         ",
      "aaaaaab         ",
      "aaaaacb         ",
      "aaaaaab         ",
      "aaaaaab         "
    ],
    [
      "dddddaeee       ",
      "dddddaeee       ",
      "dddddaeee       ",
      "dddddaeee       ",
      "dddddceee       ",
      "dddddaeee       ",
      "dddddaeee       ",
      "dddddaeee       ",
      "dddddaeee       ",
      "dddddaeee       ",
      "dddddaeee       ",
      "dddddaeee       ",
      "dddddaeee       ",
      "dddddceee       ",
      "dddddaeee       ",
      "dddddaeee       "
    ],
    [
      "fffffdggh       ",
      "fffffdggh       ",
      "fffffdggh       ",
      "fffffdggh       ",
      "fffffcggh       ",
      "fffffdggh       ",
      "fffffdggh       ",
      "fffffdggh       ",
      "fffffdggh       ",
      "fffffdggh       ",
      "fffffdggh       ",
      "fffffdggh       ",
      "fffffdggh       ",
      "fffffcggh       ",
      "fffffdggh       ",
      "fffffdggh       "
    ],
    [
      "     iiij       ",
      "     ikij       ",
      "     iiij       ",
      "     iiij       ",
      "     clij       ",
      "     iiij       ",
      "     iiij       ",
      "     ikij       ",
      "     iiij       ",
      "     iiij       ",
      "     ikij       ",
      "     iiij       ",
      "     iiij       ",
      "     clij       ",
      "     iiij       ",
      "     iiij       "
    ],
    [
      "        j       ",
      "        j       ",
      "        j       ",
      "        j       ",
      "     c  j       ",
      "        j       ",
      "        j       ",
      "        j       ",
      "        j       ",
      "        j       ",
      "        j       ",
      "        j       ",
      "        j       ",
      "     c  j       ",
      "        j       ",
      "        j       "
    ],
    [
      "                ",
      "                ",
      "                ",
      "                ",
      "m    c          ",
      "                ",
      "                ",
      "                ",
      "                ",
      "                ",
      "                ",
      "                ",
      "                ",
      "m    c          ",
      "                ",
      "                "
    ],
    [
      "                ",
      "                ",
      "                ",
      "                ",
      "n    c          ",
      "                ",
      "                ",
      "                ",
      "                ",
      "                ",
      "                ",
      "                ",
      "                ",
      "n    c          ",
      "                ",
      "                "
    ],
    [
      "                ",
      "                ",
      "                ",
      "                ",
      "o    c          ",
      "                ",
      "                ",
      "                ",
      "                ",
      "                ",
      "                ",
      "                ",
      "                ",
      "o    c          ",
      "                ",
      "                "
    ],
    [
      "                ",
      "                ",
      "                ",
      "                ",
      "     c          ",
      "                ",
      "                ",
      "                ",
      "                ",
      "                ",
      "                ",
      "                ",
      "                ",
      "     c          ",
      "                ",
      "                "
    ],
    [
      "                ",
      "                ",
      "                ",
      "                ",
      "     c          ",
      "                ",
      "                ",
      "                ",
      "                ",
      "                ",
      "                ",
      "                ",
      "                ",
      "     c          ",
      "                ",
      "                "
    ],
    [
      "       p        ",
      "       p        ",
      "       p        ",
      "       p        ",
      "     c p        ",
      "       p        ",
      "       p        ",
      "       p        ",
      "       p        ",
      "       p        ",
      "       p        ",
      "       p        ",
      "       p        ",
      "     c p        ",
      "       p        ",
      "       p        "
    ],
    [
      "qqqqqqeee       ",
      "qqqqqqeee       ",
      "qqqqqqeee       ",
      "qqqqqqeee       ",
      "qqqqqceee       ",
      "qqqqqqeee       ",
      "qqqqqqeee       ",
      "qqqqqqeee       ",
      "qqqqqqeee       ",
      "qqqqqqeee       ",
      "qqqqqqeee       ",
      "qqqqqqeee       ",
      "qqqqqqeee       ",
      "qqqqqceee       ",
      "qqqqqqeee       ",
      "qqqqqqeee       "
    ],
    [
      "gggggrb         ",
      "gggggrb         ",
      "gggggrb         ",
      "gggggrb         ",
      "gggggrb         ",
      "gggggrb         ",
      "gggggrb         ",
      "gggggrb         ",
      "gggggrb         ",
      "gggggrb         ",
      "gggggrb         ",
      "gggggrb         ",
      "gggggrb         ",
      "gggggrb         ",
      "gggggrb         ",
      "gggggrb         "
    ],
    [
      "  s  t          ",
      "u s  t          ",
      "u s  t          ",
      "u s  t          ",
      " wsxyt          ",
      "  s  t          ",
      "  s  t          ",
      "  s  t          ",
      "  s  t          ",
      "  s  t          ",
      "  s  t          ",
      "  s  t          ",
      "  s  t          ",
      "Awsxyt          ",
      "B s  t          ",
      "A s  t          "
    ],
    [
      "     t          ",
      "u    t          ",
      "sss  t          ",
      "u    t          ",
      "     t          ",
      "     t          ",
      "     t          ",
      "     t          ",
      "     t          ",
      "     t          ",
      "     t          ",
      "     t          ",
      "     t          ",
      "     t          ",
      "     t          ",
      "     t          "
    ],
    [
      "                ",
      "u               ",
      "u               ",
      "u               ",
      "                ",
      "                ",
      "                ",
      "                ",
      "                ",
      "                ",
      "                ",
      "                ",
      "                ",
      "                ",
      "                ",
      "                "
    ]
  ]
}