{
  "name": "multi_oasiscondo_14_floor1",
  "refpalette": "deceasedcraft:multi_oasiscondo_14/multi_oasiscondo_14_floor1_palette",
  "xsize": 16,
  "zsize": 16,
  "slices": [
    [
      "                ",
      "            a   ",
      "                ",
      "                ",
      "     b      a   ",
      "                ",
      "                ",
      "            a   ",
      "                ",
      "                ",
      "                ",
      "       c        ",
      "      cd        ",
      "bbbbbb          ",
      "  e   fff       ",
      "      gf        "
    ],
    [
      "                ",
      "                ",
      "                ",
      "                ",
      "     b          ",
      "                ",
      "                ",
      "                ",
      "                ",
      "                ",
      "                ",
      "       c        ",
      "      cd        ",
      "bbbbbb          ",
      "  h   fff       ",
      "      gf        "
    ],
    [
      "                ",
      "                ",
      "                ",
      "                ",
      "     b          ",
      "                ",
      "                ",
      "                ",
      "                ",
      "                ",
      "                ",
      "       c        ",
      "      cd        ",
      "bbbbbb          ",
      "      fff       ",
      "      gf        "
    ],
    [
      "                ",
      "                ",
      "                ",
      "                ",
      "     b          ",
      "                ",
      "                ",
      "                ",
      "                ",
      "                ",
      "                ",
      "       c        ",
      "      cd        ",
      "bbbbbb          ",
      "      fff       ",
      "      gf        "
    ],
    [
      "      i         ",
      "      i         ",
      "      i         ",
      "      i         ",
      "     bi         ",
      "      i         ",
      "      i         ",
      "      i         ",
      "      i         ",
      "      i         ",
      "      i         ",
      "      ic        ",
      "      cd        ",
      "bbbbbb          ",
      "      fff       ",
      "      gf        "
    ],
    [
      "jjjjjjcc        ",
      "jjjjjjcc        ",
      "jjjjjjcc        ",
      "jjjjjjcc        ",
      "jjjjjbcc        ",
      "jjjjjjcc        ",
      "jjjjjjcc        ",
      "jjjjjjcc        ",
      "jjjjjjcc        ",
      "jjjjjjcc        ",
      "jjjjjjcc        ",
      "jjjjjjcc        ",
      "jjjjjjcd        ",
      "bbbbbb          ",
      "jjjjjjfff       ",
      "jjjjjjfff       "
    ]
  ]
}