{
  "name": "multi_oasiscondo_14_base3",
  "refpalette": "deceasedcraft:multi_oasiscondo_14/multi_oasiscondo_14_base3_palette",
  "xsize": 16,
  "zsize": 16,
  "slices": [
    [
      "vvvvvvv        v",
      "aaaaaav        v",
      "aaaaaav        v",
      "aaaaaav        v",
      "aaaaabv        v",
      "aaaaaav        v",
      "aaaaaav        v",
      "aaaaaav        v",
      "aaaaaav        v",
      "aaaaaav        v",
      "aaaaaav        v",
      "aaaaaav        v",
      "ccccccv        v",
      "cccccbv        v",
      "ccccccv        v",
      "dHHHddv        v"
    ],
    [
      "vvvvvvv        v",
      "aaaaaav        v",
      "aaaaaav        v",
      "aaaaaav        v",
      "aaaaabv        v",
      "aaaaaav        v",
      "aaaaaav        v",
      "aaaaaav        v",
      "aaaaaav        v",
      "ccccccv        v",
      "ccccccv        v",
      "ccccccv        v",
      "dHHHddv        v",
      "efffebv        v",
      "ghhhggv        v",
      "      v        v"
    ],
    [
      "vvvvvvv        v",
      "aaaaaav        v",
      "aaaaaav        v",
      "aaaaaav        v",
      "aaaaabv        v",
      "aaaaaav        v",
      "ccccccv        v",
      "ccccccv        v",
      "ccccccv        v",
      "dHHHddv        v",
      "efffeev        v",
      "ghhhggv        v",
      "      v        v",
      "     bv        v",
      "      v        v",
      "      v        v"
    ],
    [
      "vvvvvvv        v",
      "aaaaaav        v",
      "aaaaaav        v",
      "ccccccv        v",
      "cccccbv        v",
      "ccccccv        v",
      "dHHHddv        v",
      "efffeev        v",
      "ghhhggv        v",
      "      v        v",
      "      v        v",
      "      v        v",
      "      v        v",
      "     bv        v",
      "      v        v",
      "      v        v"
    ],
    [
      "vvvvvvv        v",
      "ccccccv        v",
      "ccccccv        v",
      "dHHHddv        v",
      "efffebv        v",
      "ghhhggv        v",
      "      v        v",
      "      v        v",
      "      v        v",
      "      v        v",
      "      v        v",
      "      v        v",
      "      v        v",
      "iiiiibv        v",
      "      v        v",
      "      v        v"
    ],
    [
      "dHHHddvjjjjjjjjv",
      "efffeevjjjjjjjjv",
      "ghhhggvjjjjjjjjv",
      "      vjjjjjjjjv",
      "     klllllllllv",
      "      vjjjjjjjjv",
      "      vjjjjjjjjv",
      "      vjjjjjjjjv",
      "      vjjjjjjjjv",
      "      vjjjjjjjjv",
      "      vjjjjjjjjv",
      "      vjjjjjjjjv",
      "      vjjjjjjjjv",
      "lllllklllllllllv",
      "jjjjjlvjjjjjjjjv",
      "jjjjjlvjjjjjjjjv"
    ]
  ]
}