{
  "name": "multi_oasiscondo_14_floor6",
  "refpalette": "deceasedcraft:multi_oasiscondo_14/multi_oasiscondo_14_floor6_palette",
  "xsize": 16,
  "zsize": 16,
  "slices": [
    [
      "abbbbbb         ",
      "abbbbbb         ",
      "abbbbbb         ",
      "abbbbbb         ",
      "abbbbbb         ",
      "abbbbbb         ",
      "abbbbbb         ",
      "abbbbbb         ",
      "cbbbbbb         ",
      "cbbbbbb         ",
      "abbbbbb         ",
      "abbbbbb         ",
      "abbbbbd         ",
      "eeeeee          ",
      "abbbbbd         ",
      "abbbbbb         "
    ],
    [
      "a fghihj        ",
      "a f   ka        ",
      "a f  lma        ",
      "a f   kj        ",
      "a fnoooa        ",
      "a pqrstj        ",
      "a     ua        ",
      "a  ww xa        ",
      "y ABCCDa        ",
      "E FIJKLa        ",
      "a      a        ",
      "a     Ma        ",
      "aNNOPQaR        ",
      "eeeeee          ",
      "asSsrqaR        ",
      "a     Ta        "
    ],
    [
      "a fUhVhW        ",
      "a f   XW        ",
      "a f    W        ",
      "a f Y ZW        ",
      "a fnooo0        ",
      "a 123 4W        ",
      "a      W        ",
      "a     5W        ",
      "6  7 8 W        ",
      "9     #W        ",
      "a      W        ",
      "a     $j        ",
      "a % ^&aR        ",
      "eeeeee          ",
      "a* (!2)R        ",
      "a     Ta        "
    ],
    [
      "a f+h-hW        ",
      "a f    W        ",
      "a f Y  W        ",
      "a f    W        ",
      "a foooo0        ",
      "a 1[[[]W        ",
      "a      W        ",
      "a      W        ",
      "{      W        ",
      "{      W        ",
      "a      W        ",
      "a     $a        ",
      "a}}   a|        ",
      "eeeeee          ",
      "a;;;:'j|        ",
      "a      a        "
    ],
    [
      "a fhhhhW        ",
      "a f    W        ",
      "a fY!  W        ",
      "a f    W        ",
      "a foooo0        ",
      "a <> , W        ",
      "a      W        ",
      "a   .  W        ",
      "a      W        ",
      "a      W        ",
      "a   ?  W        ",
      "a     $a        ",
      "a   }}aR        ",
      "eeeeee          ",
      "a/ ` \u0370)|        ",
      "a      a        "
    ],
    [
      "a\u0371\u0371\u0371\u0371\u0371\u0371a        ",
      "a\u0371\u0371\u0371\u0371\u0371\u0371j        ",
      "a\u0371\u0371\u0371\u0371\u0371\u0371)        ",
      "a\u0371\u0371\u0371\u0371\u0371\u0371j        ",
      "a\u0371\u0371\u0371\u0371\u0371\u0371j        ",
      "a\u0371\u0371\u0371\u0371\u0371\u0371a        ",
      "a\u0371\u0371\u0371\u0371\u0371\u0371a        ",
      "a\u0371\u0371\u0371\u0371\u0371\u0371j        ",
      "a\u0371\u0371\u0371\u0371\u0371\u0371j        ",
      "a\u0371\u0371\u0371\u0371\u0371\u0371a        ",
      "a\u0371\u0371\u0371\u0371\u0371\u0371a        ",
      "a\u0371\u0371\u0371\u0371\u0371\u0371a        ",
      "a\u0371\u0371\u0371\u0371\u0371a|        ",
      "eeeeee          ",
      "a\u0371\u0371\u0371\u0371\u0371j\u0372        ",
      "a\u0371\u0371\u0371\u0371\u0371\u0371j        "
    ]
  ]
}