{
  "name": "multi_oasiscondo_14_floor2",
  "refpalette": "deceasedcraft:multi_oasiscondo_14/multi_oasiscondo_14_floor2_palette",
  "xsize": 16,
  "zsize": 16,
  "slices": [
    [
      "abbbbbb         ",
      "abbbbbb         ",
      "cbbbbbb         ",
      "abbbbbd         ",
      "eeeeee          ",
      "abbbbfd         ",
      "abbbbbb         ",
      "abbbbbb         ",
      "abbbbbb         ",
      "abbbbbb         ",
      "abbbbbb         ",
      "cbbbbbb         ",
      "abbbbbd         ",
      "eeeeee          ",
      "abbbbbd         ",
      "abbbbbb         "
    ],
    [
      "a ghijik        ",
      "a g    a        ",
      "l g m na        ",
      "aogpqpkr        ",
      "eeeeee          ",
      "as tauar        ",
      "awx ayAa        ",
      "aB  aCDa        ",
      "a EFaIJk        ",
      "a gKiLia        ",
      "a gMNOPk        ",
      "l gQR Sk        ",
      "aogtSTkr        ",
      "eeeeee          ",
      "aUVUWXar        ",
      "a  Y Z0a        "
    ],
    [
      "a g1i2i3        ",
      "a g   43        ",
      "5 g   nk        ",
      "a6g7 8a9        ",
      "eeeeee          ",
      "a#  a$kr        ",
      "a%  a  k        ",
      "a^  a  3        ",
      "a  &a *3        ",
      "a gKi(i3        ",
      "a g)+  3        ",
      "5 g   -a        ",
      "a[g   k9        ",
      "eeeeee          ",
      "a] {}|k9        ",
      "a     ;a        "
    ],
    [
      "a g:i'i3        ",
      "a g   <3        ",
      "> g    a        ",
      "a,g   ar        ",
      "eeeeee          ",
      "a.  a?ar        ",
      "a/  a  a        ",
      "a`  a  3        ",
      "a   a \u03703        ",
      "a g:i:i3        ",
      "a g    3        ",
      "> g    a        ",
      "a,g   ar        ",
      "eeeeee          ",
      "a\u0371\u0371\u0371\u0372!\u03739        ",
      "a      a        "
    ],
    [
      "a giiii3        ",
      "a g    3        ",
      "a g \u0374  k        ",
      "a g   kr        ",
      "eeeeee          ",
      "a\u0375  a\u0376k9        ",
      "a \u0376 a\u0377\u0377a        ",
      "a   a\u0377\u03773        ",
      "a   a\u0377\u03773        ",
      "a giiii3        ",
      "a g    3        ",
      "a g \u0374  a        ",
      "a g   kr        ",
      "eeeeee          ",
      "a\u037a\u037a] Zk\u037b        ",
      "a      k        "
    ],
    [
      "a\u037c\u037c\u037c\u037c\u037c\u037ca        ",
      "a\u037c\u037c\u037c\u037c\u037c\u037ca        ",
      "a\u037c\u037c\u037c\u037c\u037c\u037ck        ",
      "a\u037c\u037c\u037c\u037c\u037ca9        ",
      "eeeeee          ",
      "a\u037c\u037c\u037c\u037c\u037ca9        ",
      "a\u037c\u037c\u037c\u037c \u037dk        ",
      "a\u037c\u037c\u037c\u037c  a        ",
      "a\u037c\u037c\u037c\u037c  a        ",
      "a\u037c\u037c\u037c\u037c\u037c\u037ck        ",
      "a\u037c\u037c\u037c\u037c\u037c\u037ca        ",
      "a\u037c\u037c\u037c\u037c\u037c\u037ca        ",
      "a\u037c\u037c\u037c\u037c\u037ca9        ",
      "eeeeee          ",
      "a\u037c\u037c\u037c\u037c\u037ck9        ",
      "a\u037c\u037c\u037c\u037c\u037c\u037ca        "
    ]
  ]
}