{
  "name": "multi_oasiscondo_14_base1",
  "refpalette": "deceasedcraft:multi_oasiscondo_14/multi_oasiscondo_14_base1_palette",
  "xsize": 16,
  "zsize": 16,
  "slices": [
    [
      "      vaHHHHHHHv",
      "      vaHHHHHHHv",
      "      vaHHHHHHHv",
      "      vaHHHHHHHv",
      "     bvaHHHHHHHv",
      "      vaHHHHHHHv",
      "      vaHHHHHHHv",
      "      vaHHHHHHHv",
      "      vaHHHHHHHv",
      "      vaHHHHHHHv",
      "      vaHHHHHHHv",
      "      vaHHHHHHHv",
      "ccccccvaHHHHHHHv",
      "dddddbaaHHHHHHHv",
      "aHHHaaaaHHHHHHHv",
      "HHHHHaaHHHHHHHHv"
    ],
    [
      "      v    e  fv",
      "      v    g  hv",
      "      v    e  fv",
      "      v    g  hv",
      "     bv    e  fv",
      "      v    g  hv",
      "      v    e  fv",
      "      v    gi hv",
      "      v    e  fv",
      "ccccccv    g  hv",
      "ddddddv    e  fv",
      "jjjjjjv    g  hv",
      "aHHHaav    e  fv",
      "klllkbm    g  hv",
      "nooonn     e  fv",
      "           g  hv"
    ],
    [
      "      v        v",
      "      v        v",
      "      v        v",
      "      v        v",
      "     bv        v",
      "      v        v",
      "ccccccv        v",
      "ddddddv        v",
      "jjjjjjv        v",
      "aHHHaav        v",
      "klllkkv        v",
      "nooonnv        v",
      "      v        v",
      "     b         v",
      "               v",
      "               v"
    ],
    [
      "      v        v",
      "      v        v",
      "      v        v",
      "ccccccv        v",
      "dddddbv        v",
      "jjjjjjv        v",
      "aHHHaav        v",
      "klllkkv        v",
      "nooonnv        v",
      "      v        v",
      "      v        v",
      "      v        v",
      "      v        v",
      "     b         v",
      "               v",
      "               v"
    ],
    [
      "ccccccv        v",
      "ddddddv        v",
      "jjjjjjv        v",
      "aHHHaav        v",
      "klllkbv        v",
      "nooonnv        v",
      "      v        v",
      "      v        v",
      "      v        v",
      "      v        v",
      "      v        v",
      "      v        v",
      "      v        v",
      "pppppb         v",
      "               v",
      "               v"
    ],
    [
      "aHHHaavccccccccv",
      "klllkkvccccccccv",
      "nooonnvccccccccv",
      "      vccccccccv",
      "     qrrrrrrrrrv",
      "      vccccccccv",
      "      vccccccccv",
      "      vccccccccv",
      "      vccccccccv",
      "      vccccccccv",
      "      vccccccccv",
      "      vccccccccv",
      "      vccccccccv",
      "rrrrrqrrrrrrrrrv",
      "cccccrcccccccccv",
      "cccccrcccccccccv"
    ]
  ]
}