{
  "name": "multi_oasiscondo_14_floor8",
  "refpalette": "deceasedcraft:multi_oasiscondo_14/multi_oasiscondo_14_floor8_palette",
  "xsize": 16,
  "zsize": 16,
  "slices": [
    [
      "abbbbbb         ",
      "abbbbbb         ",
      "abbbbbb         ",
      "abbbbbb         ",
      "abbbbbb         ",
      "abbbbbb         ",
      "cbbbbbb         ",
      "abbbbbb         ",
      "abbbbbb         ",
      "abbbbbb         ",
      "abbbbbb         ",
      "abbbbbb         ",
      "abdbbbe         ",
      "ffffff          ",
      "abbbbbe         ",
      "abbbbbb         "
    ],
    [
      "aghijkjl        ",
      "amnop qa        ",
      "ar     a        ",
      "as     l        ",
      "ar    ta        ",
      "auw   xl        ",
      "yAB   Cl        ",
      "aAB D Ca        ",
      "aA EF Ia        ",
      "aJKJJJJa        ",
      "aELMNOPl        ",
      "a QR  Sl        ",
      "aT UVWlX        ",
      "ffffff          ",
      "aYZY01l2        ",
      "a     3l        "
    ],
    [
      "a4o5j6j7        ",
      "ad     7        ",
      "a8     7        ",
      "a      7        ",
      "a      9        ",
      "a#     7        ",
      "$%     7        ",
      "a^     7        ",
      "a&     7        ",
      "aJ JJJJ7        ",
      "a *(   7        ",
      "a      a        ",
      "aT)+  -2        ",
      "ffffff          ",
      "a[ ]{}a2        ",
      "a     |a        "
    ],
    [
      "a;  j:j7        ",
      "a'     7        ",
      "a<     7        ",
      "a<     7        ",
      "a<     9        ",
      "a>     7        ",
      ",      7        ",
      "a      7        ",
      "a      7        ",
      "aJ.JJJJ7        ",
      "a      7        ",
      "a      l        ",
      "aAA?  l/        ",
      "ffffff          ",
      "a```\u0370;a/        ",
      "a      a        "
    ],
    [
      "a\u0371 \u0372jjj7        ",
      "a      7        ",
      "a      7        ",
      "a   \u0373  7        ",
      "a      9        ",
      "a\u0374     7        ",
      "a      7        ",
      "a   \u0375  7        ",
      "a      7        ",
      "aJJJJJJ7        ",
      "a      7        ",
      "a  \u0376  \u0377l        ",
      "a \u037a   l/        ",
      "ffffff          ",
      "a\u037b\u037c   l2        ",
      "a      a        "
    ],
    [
      "a\u037d\u037d\u037d\u037d\u037d\u037da        ",
      "a\u037d\u037d\u037d\u037d\u037d\u037dl        ",
      "a\u037d\u037d\u037d\u037d\u037d\u037da        ",
      "a\u037d\u037d\u037d\u037d\u037d\u037da        ",
      "a\u037d\u037d\u037d\u037d\u037d\u037da        ",
      "a\u037d\u037d\u037d\u037d\u037d\u037da        ",
      "a\u037d\u037d\u037d\u037d\u037d\u037dl        ",
      "a\u037d\u037d\u037d\u037d\u037d\u037da        ",
      "a\u037d\u037d\u037d\u037d\u037d\u037dl        ",
      "a\u037d\u037d\u037d\u037d\u037d\u037dl        ",
      "a\u037d\u037d\u037d\u037d\u037d\u037da        ",
      "a\u037d\u037d\u037d\u037d\u037d\u037da        ",
      "a\u037d\u037d\u037d\u037d\u037da2        ",
      "ffffff          ",
      "a\u037d\u037d\u037d\u037d\u037da2        ",
      "a\u037d\u037d\u037d\u037d\u037d\u037dl        "
    ]
  ]
}