{
  "name": "multi_oasiscondo_14_floor9",
  "refpalette": "deceasedcraft:multi_oasiscondo_14/multi_oasiscondo_14_floor9_palette",
  "xsize": 16,
  "zsize": 16,
  "slices": [
    [
      "abbbbbb         ",
      "abbbbbb         ",
      "cbbbbbb         ",
      "cbbbbbd         ",
      "eeeeee          ",
      "afffffd         ",
      "afffffb         ",
      "afffffb         ",
      "afffffb         ",
      "afffffb         ",
      "afffffb         ",
      "af!fffb         ",
      "afffffb         ",
      "affffeb         ",
      "afffffb         ",
      "afffffb         "
    ],
    [
      "g      c        ",
      "h      c        ",
      "c i i  c        ",
      "cjkkklmn        ",
      "eeeeee          ",
      "      ooo       ",
      "    p qor       ",
      "   pspqqr       ",
      "    p qqr       ",
      "      qqr       ",
      "    t qqr       ",
      "  t stqqr       ",
      "    t qqr       ",
      "     eqqr       ",
      "   p  qqr       ",
      "  psu qqr       "
    ],
    [
      "w      x        ",
      "h      x        ",
      "c      c        ",
      "c yAy cn        ",
      "eeeeee          ",
      "      ooo       ",
      "       oB       ",
      "        B       ",
      "        B       ",
      "        B       ",
      "        B       ",
      "        B       ",
      "        B       ",
      "     e  B       ",
      "        B       ",
      "        B       "
    ],
    [
      "h      x        ",
      "h      x        ",
      "c      c        ",
      "c     cC        ",
      "eeeeee          ",
      "      ooo       ",
      "       o        ",
      "                ",
      "                ",
      "                ",
      "                ",
      "                ",
      "                ",
      "     e          ",
      "                ",
      "                "
    ],
    [
      "c      x        ",
      "c      x        ",
      "c      m        ",
      "c     cn        ",
      "eeeeee          ",
      "      ooo       ",
      "       o        ",
      "       D        ",
      "       D        ",
      "       D        ",
      "       D        ",
      "       D        ",
      "       D        ",
      "     e D        ",
      "       D        ",
      "       D        "
    ],
    [
      "cEEEEEEc        ",
      "cEEEEEEm        ",
      "cEEEEEEc        ",
      "cEEEEEcn        ",
      "eeeeee          ",
      "FFFFFFooo       ",
      "FFFFFFooo       ",
      "FFFFFFooo       ",
      "FFFFFFooo       ",
      "FFFFFFooo       ",
      "FFFFFFooo       ",
      "FFFFFFooo       ",
      "FFFFFFooo       ",
      "FFFFFeooo       ",
      "FFFFFFooo       ",
      "FFFFFFooo       "
    ]
  ]
}