{
  "name": "multi_oasiscondo_14_floor5",
  "refpalette": "deceasedcraft:multi_oasiscondo_14/multi_oasiscondo_14_floor5_palette",
  "xsize": 16,
  "zsize": 16,
  "slices": [
    [
      "abbbbbb         ",
      "abbbbbb         ",
      "cbbbbbb         ",
      "abbbbbd         ",
      "eeeeee          ",
      "abbbbbd         ",
      "abbbbbb         ",
      "abbbbbb         ",
      "abbbbbb         ",
      "abbbbbb         ",
      "abbbbbb         ",
      "cbbbbbb         ",
      "abbbbbd         ",
      "eeeeee          ",
      "abbbbbd         ",
      "abbbbbb         "
    ],
    [
      "a fghihj        ",
      "a f    a        ",
      "k f l mj        ",
      "anfopoaq        ",
      "eeeeee          ",
      "arstauwww       ",
      "ax  y  wA       ",
      "aaaaa  BA       ",
      "aCDDC  BA       ",
      "a EE   BA       ",
      "a     FBA       ",
      "k     IwA       ",
      "aJKKLMwww       ",
      "eeeeee          ",
      "aNONPQjq        ",
      "a     Ra        "
    ],
    [
      "a fShThU        ",
      "a f    U        ",
      "V f   mj        ",
      "aWf  Xjq        ",
      "eeeeee          ",
      "aY  auwww       ",
      "a Z 0 1w2       ",
      "aaaaa  32       ",
      "a4  5   2       ",
      "a       2       ",
      "a       2       ",
      "V     6w2       ",
      "a 78 9www       ",
      "eeeeee          ",
      "a# $%^aq        ",
      "a     &a        "
    ],
    [
      "a f*h(hU        ",
      "a f    U        ",
      ") f   +a        ",
      "a-f[  j]        ",
      "eeeeee          ",
      "a{  a}www       ",
      "a|  ;  w        ",
      "aaaaa  3        ",
      "a               ",
      "a      3        ",
      "a      3        ",
      ")      w        ",
      "a--:::www       ",
      "eeeeee          ",
      "a'''<>aq        ",
      "a      j        "
    ],
    [
      "a fhhhhU        ",
      "a f    U        ",
      "a f[,  a        ",
      "a f!  j.        ",
      "eeeeee          ",
      "a???a/www       ",
      "a???a  w        ",
      "aaaaa  `        ",
      "a      `        ",
      "a      `        ",
      "a   ,  `        ",
      "a      w        ",
      "a    \u0370www       ",
      "eeeeee          ",
      "a \u0371  \u0372j.        ",
      "a      a        "
    ],
    [
      "a\u0373\u0373\u0373\u0373\u0373\u0373a        ",
      "a\u0373\u0373\u0373\u0373\u0373\u0373j        ",
      "a\u0373\u0373\u0373\u0373\u0373\u0373a        ",
      "a\u0373\u0373\u0373\u0373\u0373\u0374.        ",
      "eeeeee          ",
      "a\u0375  \u0373\u0373www       ",
      "a   \u0373\u0373\u0373ww       ",
      "a\u0373\u0373\u0373\u0373\u0373\u0373ww       ",
      "a\u0373\u0376\u0373\u0373\u0373\u0373ww       ",
      "a\u0373\u0373\u0373\u0373\u0373\u0373ww       ",
      "a\u0373\u0373\u0373\u0373\u0373\u0373ww       ",
      "a\u0373\u0373\u0373\u0373\u0373\u0373ww       ",
      "a\u0373\u0373\u0373\u0373\u0373www       ",
      "eeeeee          ",
      "a\u0373\u0373\u0373\u0373\u0373a.        ",
      "a\u0373\u0373\u0373\u0373\u0373\u0373j        "
    ]
  ]
}