{
  "name": "multi_oasiscondo_14_base2",
  "refpalette": "deceasedcraft:multi_oasiscondo_14/multi_oasiscondo_14_base2_palette",
  "xsize": 16,
  "zsize": 16,
  "slices": [
    [
      "      vaHHHHHHHv",
      "      vaHHHHHHHv",
      "      vaHHHHHHHv",
      "      vaHHHHHHHv",
      "     bvaHHHHHHHv",
      "      vaHHHHHHHv",
      "      vaHHHHHHHv",
      "      vaHHHHHHHv",
      "      vaHHHHHHHv",
      "      vaHHHHHHHv",
      "      vaHHHHHHHv",
      "      vaHHHHHHHv",
      "ccccccvaHHHHHHHv",
      "dddddbaaHHHHHHHv",
      "aHHHaaaaHHHHHHHv",
      "HHHHHaaHHHHHHHHv"
    ],
    [
      "      v    e  fv",
      "      v    g  hv",
      "      v    e  fv",
      "      v    g  hv",
      "     bv    e  fv",
      "      v    g  hv",
      "      v    e  fv",
      "      v    g  hv",
      "      v    e  fv",
      "ccccccv    g  hv",
      "ddddddv    e  fv",
      "iiiiiiv    g  hv",
      "aHHHaav    e  fv",
      "jkkkjbl    g  hv",
      "mnnnmm     e  fv",
      "           g  hv"
    ],
    [
      "      v        v",
      "      v        v",
      "      v        v",
      "      v        v",
      "     bv        v",
      "      v        v",
      "ccccccv        v",
      "ddddddv        v",
      "iiiiiiv        v",
      "aHHHaav        v",
      "jkkkjjv        v",
      "mnnnmmv        v",
      "      v        v",
      "     b         v",
      "               v",
      "               v"
    ],
    [
      "      v        v",
      "      v        v",
      "      v        v",
      "ccccccv        v",
      "dddddbv        v",
      "iiiiiiv        v",
      "aHHHaav        v",
      "jkkkjjv        v",
      "mnnnmmv        v",
      "      v        v",
      "      v        v",
      "      v        v",
      "      v        v",
      "     b         v",
      "               v",
      "               v"
    ],
    [
      "ccccccv        v",
      "ddddddv        v",
      "iiiiiiv        v",
      "aHHHaav        v",
      "jkkkjbv        v",
      "mnnnmmv        v",
      "      v        v",
      "      v        v",
      "      v        v",
      "      v        v",
      "      v        v",
      "      v        v",
      "      v        v",
      "ooooob         v",
      "               v",
      "               v"
    ],
    [
      "aHHHaavccccccccv",
      "jkkkjjvccccccccv",
      "mnnnmmvccccccccv",
      "      vccccccccv",
      "     pqqqqqqqqqv",
      "      vccccccccv",
      "      vccccccccv",
      "      vccccccccv",
      "      vccccccccv",
      "      vccccccccv",
      "      vccccccccv",
      "      vccccccccv",
      "      vccccccccv",
      "qqqqqpqqqqqqqqqv",
      "cccccqcccccccccv",
      "cccccqcccccccccv"
    ]
  ]
}