{
  "name": "multi_oasiscondo_14_base4",
  "refpalette": "deceasedcraft:multi_oasiscondo_14/multi_oasiscondo_14_base4_palette",
  "xsize": 16,
  "zsize": 16,
  "slices": [
    [
      "aaaaaaaaaaaaaaav",
      "aaaaaaaaaaaaaaav",
      "aaaaaaaaaaaaaaav",
      "aaaaaaaaaaaaaaav",
      "aaaaaaaaaaaaaaav",
      "aaaaaaaaaaaaaaav",
      "aaaaaaaaaaaaaaav",
      "aaaaaaaaaaaaaaav",
      "aaaaaaaaaaaaaaav",
      "aaaaaaaaaaaaaaav",
      "aaaaaaaaaaaaaaav",
      "aaaaaaaaaaaaaaav",
      "aaaaaaaaaaaaaaav",
      "aaaaaaaaaaaaaaav",
      "aaaaaaaaaaaaaaav",
      "aaaaaaaaaaaaaaav"
    ],
    [
      "aaaaaaaaaaaaaaav",
      "aaaaaaaaaaaaaaav",
      "aaaaaaaaaaaaaaav",
      "aaaaaaaaaaaaaaav",
      "aaaaabaaaaaaaaav",
      "aaaaaaaaaaaaaaav",
      "aaaaaaaaaaaaaaav",
      "aaaaaaaaaaaaaaav",
      "aaaaaaaaaaaaaaav",
      "aaaaaaaaaaaaaaav",
      "aaaaaaaaaaaaaaav",
      "aaaaaaaaaaaaaaav",
      "aaaaaaaaaaaaaaav",
      "aaaaabaaaaaaaaav",
      "aaaaaaaaaaaaaaav",
      "aaaaaaaaaaaaaaav"
    ],
    [
      "vvvvvvvcHHHHHHHv",
      "aaaaaavcHHHHHHHv",
      "aaaaaavcHHHHHHHv",
      "aaaaaavcHHHHHHHv",
      "aaaaabvcHHHHHHHv",
      "aaaaaavcHHHHHHHv",
      "aaaaaavcHHHHHHHv",
      "aaaaaavcHHHHHHHv",
      "aaaaaavcHHHHHHHv",
      "aaaaaavcHHHHHHHv",
      "aaaaaavcHHHHHHHv",
      "aaaaaavcHHHHHHHv",
      "aaaaaavcHHHHHHHv",
      "aaaaabvcHHHHHHHv",
      "aaaaaavcHHHHHHHv",
      "aaaaaavcHHHHHHHv"
    ],
    [
      "vvvvvvv d  e   v",
      "aaaaaav f  g   v",
      "aaaaaav d  e   v",
      "aaaaaav f  g   v",
      "aaaaabv d  e   v",
      "aaaaaav f  g   v",
      "aaaaaav d  e   v",
      "aaaaaav f  g   v",
      "aaaaaav d  e   v",
      "aaaaaav f  g   v",
      "aaaaaav d  e   v",
      "aaaaaav f  g   v",
      "aaaaaav d  e   v",
      "aaaaabv f  g   v",
      "aaaaaav d  e   v",
      "aaaaaav f  g   v"
    ],
    [
      "vvvvvvv        v",
      "aaaaaav        v",
      "aaaaaav        v",
      "aaaaaav        v",
      "aaaaabv        v",
      "aaaaaav        v",
      "aaaaaav        v",
      "aaaaaav        v",
      "aaaaaav        v",
      "aaaaaav        v",
      "aaaaaav        v",
      "aaaaaav        v",
      "aaaaaav        v",
      "aaaaabv        v",
      "aaaaaav        v",
      "aaaaaav        v"
    ],
    [
      "vvvvvvv        v",
      "aaaaaav        v",
      "aaaaaav        v",
      "aaaaaav        v",
      "aaaaabv        v",
      "aaaaaav        v",
      "aaaaaav        v",
      "aaaaaav        v",
      "aaaaaav        v",
      "aaaaaav        v",
      "aaaaaav        v",
      "aaaaaav        v",
      "aaaaaav        v",
      "aaaaabv        v",
      "aaaaaav        v",
      "hhhhhhv        v"
    ]
  ]
}