{
  "name": "multi_oasiscondo_14_floor11",
  "refpalette": "deceasedcraft:multi_oasiscondo_14/multi_oasiscondo_14_floor11_palette",
  "xsize": 16,
  "zsize": 16,
  "slices": [
    [
      "abbbbbc         ",
      "abbbbbc         ",
      "abbbbbc         ",
      "abbb!bc         ",
      "abbbbdc         ",
      "abbbbbc         ",
      "abbbbbc         ",
      "abbbbbc         ",
      "abbbbbc         ",
      "abbbbbc         ",
      "abbbbbc         ",
      "ebbbbbc         ",
      "ecccccf         ",
      "dddddd          ",
      "ghhhhhf         ",
      "ghhhhhc         "
    ],
    [
      "ij  k l         ",
      "im    l         ",
      "n  o pl         ",
      "n   q l         ",
      "n r  dl         ",
      "nr s  l         ",
      "n r   l         ",
      "ij    l         ",
      "im  t l         ",
      "n t  tl         ",
      "n   u l         ",
      "e     l         ",
      "ewxxxll         ",
      "dddddd          ",
      " yyyyyAAA       ",
      "      BAC       "
    ],
    [
      " D    l         ",
      " E    l         ",
      "n     l         ",
      "n     l         ",
      "n    dl         ",
      "n     l         ",
      "n     l         ",
      " D    l         ",
      " E    l         ",
      "n     l         ",
      "n     l         ",
      "e     l         ",
      "eFIJKll         ",
      "dddddd          ",
      " LLLLLAAA       ",
      "       AM       "
    ],
    [
      "n     l         ",
      "n     l         ",
      "n     l         ",
      "n     l         ",
      "n    dl         ",
      "n     l         ",
      "n     l         ",
      "n     l         ",
      "n     l         ",
      "n     l         ",
      "n     l         ",
      "e     l         ",
      "eF   ll         ",
      "dddddd          ",
      " LLL LAAA       ",
      "       A        "
    ],
    [
      "e     l         ",
      "e     l         ",
      "e     l         ",
      "e     l         ",
      "e    dl         ",
      "e     l         ",
      "e     l         ",
      "e     l         ",
      "e     l         ",
      "e     l         ",
      "e     l         ",
      "e     l         ",
      "e    ll         ",
      "dddddd          ",
      "  L   AAA       ",
      "       A        "
    ],
    [
      "eNNNNNl         ",
      "eNNNNNl         ",
      "eNNNNNl         ",
      "eNNNNNl         ",
      "eNNNNdl         ",
      "eNNNNNl         ",
      "eNNNNNl         ",
      "eNNNNNl         ",
      "eNNNNNl         ",
      "eNNNNNl         ",
      "eNNNNNl         ",
      "eNNNNNl         ",
      "eNNNNll         ",
      "dddddd          ",
      "NNNNNNAAA       ",
      "NNNNNNAAA       "
    ]
  ]
}