{
  "name": "multi_oasiscondo_14_floor10",
  "refpalette": "deceasedcraft:multi_oasiscondo_14/multi_oasiscondo_14_floor10_palette",
  "xsize": 16,
  "zsize": 16,
  "slices": [
    [
      "abbbbcd         ",
      "abbbbcd         ",
      "abbbbcd         ",
      "abbbbcd         ",
      "aaaaaed         ",
      "fgggggd         ",
      "fgggggd         ",
      "fgggggd         ",
      "fgggggd         ",
      "fgggggd         ",
      "fgggggd         ",
      "fgggggd         ",
      "fgggggh         ",
      "eeeeee          ",
      "adddddh         ",
      "adddddd         "
    ],
    [
      "    ijkkl       ",
      "  m ijkkl       ",
      "  m ijkkl       ",
      "    ijkkl       ",
      "     ekkl       ",
      "      kkl       ",
      "      kkl       ",
      "      kkl       ",
      "      kkl       ",
      "      kkl       ",
      "      kkl       ",
      "  nop kql       ",
      " rrrrrqqq       ",
      "eeeeee          ",
      "stuuuwxy        ",
      "A B B  x        "
    ],
    [
      "     r  C       ",
      "     r  C       ",
      "     r  C       ",
      "     r  C       ",
      "     e  C       ",
      "        C       ",
      "        C       ",
      "        C       ",
      "        C       ",
      "        C       ",
      "        C       ",
      "       qC       ",
      " DDDDDqqq       ",
      "eeeeee          ",
      "sEFEF xy        ",
      "I      x        "
    ],
    [
      "                ",
      "                ",
      "                ",
      "                ",
      "     e          ",
      "                ",
      "                ",
      "                ",
      "                ",
      "                ",
      "                ",
      "       q        ",
      " D DDDqqq       ",
      "eeeeee          ",
      "s     xJ        ",
      "s      x        "
    ],
    [
      "       K        ",
      "       K        ",
      "       K        ",
      "       K        ",
      "     e K        ",
      "       K        ",
      "       K        ",
      "       K        ",
      "       K        ",
      "       K        ",
      "       K        ",
      "       q        ",
      "    D qqq       ",
      "eeeeee          ",
      "x     xy        ",
      "x      L        "
    ],
    [
      "MMMMMMqqq       ",
      "MMMMMMqqq       ",
      "MMMMMMqqq       ",
      "MMMMMMqqq       ",
      "MMMMMeqqq       ",
      "MMMMMMqqq       ",
      "MMMMMMqqq       ",
      "MMMMMMqqq       ",
      "MMMMMMqqq       ",
      "MMMMMMqqq       ",
      "MMMMMMqqq       ",
      "MMMMMMqqq       ",
      "MMMMMMqqq       ",
      "eeeeee          ",
      "xNNNNNLJ        ",
      "xNNNNNNx        "
    ]
  ]
}