{
  "name": "multi_verticalschool_0_floor5",
  "refpalette": "deceasedcraft:multi_verticalschool_0/multi_verticalschool_0_floor5_palette",
  "xsize": 16,
  "zsize": 16,
  "slices": [
    [
      "                ",
      "                ",
      "                ",
      "                ",
      "                ",
      "     aaaaaaaaaaa",
      "     aaaaaaaaaaa",
      "     aabbbbbbbbb",
      "     aabbbbbbbbb",
      "     aabbbbbbbbb",
      "     aabbbbbbbbb",
      "     aabbbbbbbbb",
      "     aabbbbbbbbb",
      "     aabbbbbbbbb",
      "     aabbbbbbbbb",
      "     aabbbbbbbbb"
    ],
    [
      "                ",
      "                ",
      "                ",
      "                ",
      "                ",
      "     aaaaaaaaaaa",
      "     acccccccccc",
      "     ac         ",
      "     ac         ",
      "     acd    d   ",
      "     ac         ",
      "     ac         ",
      "     ac         ",
      "     ac         ",
      "     acd    d   ",
      "     ac         "
    ],
    [
      "                ",
      "                ",
      "                ",
      "                ",
      "                ",
      "     aaaaaaaaaaa",
      "     acccccccccc",
      "     ac    e    ",
      "     ace        ",
      "     acd    d   ",
      "     ac         ",
      "     ac       e ",
      "     ac         ",
      "     ac         ",
      "     acde   de  ",
      "     ac     e   "
    ],
    [
      "                ",
      "                ",
      "                ",
      "                ",
      "                ",
      "     aaaaaaaaaaa",
      "     abbbbbbbbbb",
      "     abbbbbbbbbb",
      "     abbbbbbbbbb",
      "     abbbbbbbbbb",
      "     abbbbbbbbbb",
      "     abbbbbbbbbb",
      "     abbbbbbbbbb",
      "     abbbbbbbbbb",
      "     abbbbbbbbbb",
      "     abbbbbbbbbb"
    ],
    [
      "                ",
      "                ",
      "                ",
      "                ",
      "                ",
      "     aaaaaaaaaaa",
      "     afggggggggg",
      "     ah ijk ijk ",
      "     a          ",
      "     a          ",
      "     a          ",
      "     a          ",
      "     a          ",
      "     a          ",
      "     a          ",
      "     a          "
    ],
    [
      "                ",
      "                ",
      "                ",
      "                ",
      "                ",
      "     aaaaaaaaaaa",
      "     afggggggggg",
      "     al         ",
      "     a          ",
      "     a          ",
      "     a          ",
      "     a          ",
      "     a          ",
      "     a          ",
      "     a          ",
      "     a          "
    ]
  ]
}