{
  "name": "multi_verticalschool_0_ground",
  "refpalette": "deceasedcraft:multi_verticalschool_0/multi_verticalschool_0_ground_palette",
  "xsize": 16,
  "zsize": 16,
  "slices": [
    [
      "aaaaHHHHHHHHHHHH",
      "aaHHHHHHHHHHHHHH",
      "aHHHHHHHHHHHHHHH",
      "aHHHHHHHHHHHHHHH",
      "HHHHHHHHHaaaaaaa",
      "HHHHHHHaabbbbbbb",
      "HHHHHHacbbbbbbbb",
      "HHHHHacbbbbbbbbb",
      "HHHHHacbcccccccc",
      "HHHHacbbcccccccc",
      "HHHHacbbcccccccc",
      "HHHHacbbcccccccc",
      "HHHHacbbcccccccc",
      "HHHHacbbcccccccc",
      "HHHHacbbcccccccc",
      "HHHHacbbcccccccc"
    ],
    [
      "                ",
      "                ",
      "                ",
      "                ",
      "                ",
      "                ",
      "                ",
      "       ddddddddd",
      "       deeeeeeee",
      "       deeeeeeee",
      "       deeeeeeee",
      "       deeeeeeee",
      "       deeeeeeee",
      "       deeeeeeee",
      "       deeeeeeee",
      "       deeeeeeff"
    ],
    [
      "                ",
      "                ",
      "                ",
      "                ",
      "                ",
      "                ",
      "                ",
      "       ggggggggg",
      "       gcccccccc",
      "       gcccccccc",
      "       gcchhhhhh",
      "       gcchhhhhh",
      "       gcchhhhhh",
      "       gcchhhhhh",
      "       gcchhhhhh",
      "       gcchhhhhh"
    ],
    [
      "                ",
      "                ",
      "                ",
      "                ",
      "                ",
      "                ",
      "                ",
      "       ggggggggg",
      "       gcccccccc",
      "       gciiiiiii",
      "       gcihhhhhh",
      "       gcih   jj",
      "       gcih     ",
      "       gcih     ",
      "       gcih     ",
      "       gcih     "
    ],
    [
      "                ",
      "                ",
      "                ",
      "                ",
      "                ",
      "                ",
      "                ",
      "       ggggggggg",
      "       gcccccccc",
      "       gc  kkl  ",
      "       gcl      ",
      "       gck      ",
      "       gc       ",
      "       gc       ",
      "       gc       ",
      "       gc       "
    ],
    [
      "                ",
      "                ",
      "                ",
      "                ",
      "                ",
      "                ",
      "                ",
      "       ggggggggg",
      "       gcccccccc",
      "       gc    m  ",
      "       gcm      ",
      "       gc       ",
      "       gc       ",
      "       gc       ",
      "       gc       ",
      "       gc       "
    ]
  ]
}