{
  "name": "multi_verticalschool_0_floor14",
  "refpalette": "deceasedcraft:multi_verticalschool_0/multi_verticalschool_0_floor14_palette",
  "xsize": 16,
  "zsize": 16,
  "slices": [
    [
      "                ",
      "                ",
      "                ",
      "                ",
      "                ",
      "          aaaaaa",
      "        aabbbbbb",
      "       abb      ",
      "      abc       ",
      "      ab        ",
      "     ab         ",
      "     ab         ",
      "     ab         ",
      "     ab         ",
      "     ab         ",
      "     ab         "
    ],
    [
      "                ",
      "                ",
      "                ",
      "                ",
      "                ",
      "          aaaaaa",
      "        aabbbbbb",
      "       abb      ",
      "      ab        ",
      "      ab        ",
      "     ab         ",
      "     ab         ",
      "     ab         ",
      "     ab         ",
      "     ab         ",
      "     ab         "
    ],
    [
      "                ",
      "                ",
      "                ",
      "                ",
      "                ",
      "          aaaaaa",
      "        aabbbbbb",
      "       abb      ",
      "      ab        ",
      "      ab        ",
      "     ab         ",
      "     ab         ",
      "     ab         ",
      "     ab         ",
      "     ab         ",
      "     ab         "
    ],
    [
      "                ",
      "                ",
      "                ",
      "                ",
      "                ",
      "          aaaaaa",
      "        aabbbbbb",
      "       abb      ",
      "      ab        ",
      "      ab        ",
      "     ab         ",
      "     ab         ",
      "     ab         ",
      "     ab         ",
      "     ab         ",
      "     ab         "
    ],
    [
      "                ",
      "                ",
      "                ",
      "                ",
      "                ",
      "          aaaaaa",
      "        aabbbbbb",
      "       abbdddddd",
      "      abdddddddd",
      "      abddddeeff",
      "     abddddddddd",
      "     abddddddddd",
      "     abddddddddd",
      "     abddddddddd",
      "     abdddddeeee",
      "     abddddddddd"
    ],
    [
      "                ",
      "                ",
      "                ",
      "                ",
      "                ",
      "          aaaaaa",
      "        aabbbbbb",
      "       abbbbbbbb",
      "      abbbgggggg",
      "      abbgghhhhh",
      "     abbgghhhhhh",
      "     abbghhhhhhh",
      "     abbghhhhhhh",
      "     abbghhhhhhh",
      "     abbghhhhhhh",
      "     abbghhhhhhh"
    ]
  ]
}