{
  "name": "multi_verticalschool_0_floor6",
  "refpalette": "deceasedcraft:multi_verticalschool_0/multi_verticalschool_0_floor6_palette",
  "xsize": 16,
  "zsize": 16,
  "slices": [
    [
      "                ",
      "                ",
      "                ",
      "                ",
      "                ",
      "     aaaaaaaaaaa",
      "     abccccccccc",
      "     ad         ",
      "     a          ",
      "     a          ",
      "     a          ",
      "     a          ",
      "     a          ",
      "     a          ",
      "     a          ",
      "     a          "
    ],
    [
      "                ",
      "                ",
      "                ",
      "                ",
      "                ",
      "     aaaaaaaaaaa",
      "     abccccccccc",
      "     aef       g",
      "     aef       g",
      "     aef       g",
      "     aef       g",
      "     aef       g",
      "     aef       g",
      "     aef       g",
      "     aef       g",
      "     aef       g"
    ],
    [
      "                ",
      "                ",
      "                ",
      "                ",
      "                ",
      "     aaaaaaaaaaa",
      "     aaaaaaaaaaa",
      "     aahiiiiiiih",
      "     aahiiiiiiih",
      "     aahiiiiiiih",
      "     aahiiiiiiih",
      "     aahiiiiiiih",
      "     aahiiiiiiih",
      "     aahiiiiiiih",
      "     aahiiiiiiih",
      "     aahiiiiiiih"
    ],
    [
      "                ",
      "                ",
      "                ",
      "                ",
      "                ",
      "     jjjjjjjjjjj",
      "     j          ",
      "     j          ",
      "     j          ",
      "     j          ",
      "     j          ",
      "     j          ",
      "     j          ",
      "     j          ",
      "     j          ",
      "     j          "
    ],
    [
      "                ",
      "                ",
      "                ",
      "                ",
      "                ",
      "                ",
      "                ",
      "                ",
      "                ",
      "                ",
      "                ",
      "                ",
      "                ",
      "                ",
      "                ",
      "                "
    ],
    [
      "                ",
      "                ",
      "                ",
      "                ",
      "                ",
      "                ",
      "                ",
      "                ",
      "                ",
      "                ",
      "                ",
      "                ",
      "                ",
      "                ",
      "                ",
      "                "
    ]
  ]
}