{
  "name": "multi_verticalschool_0_floor13",
  "refpalette": "deceasedcraft:multi_verticalschool_0/multi_verticalschool_0_floor13_palette",
  "xsize": 16,
  "zsize": 16,
  "slices": [
    [
      "                ",
      "                ",
      "                ",
      "                ",
      "                ",
      "                ",
      "                ",
      "                ",
      "                ",
      "                ",
      "                ",
      "                ",
      "                ",
      "                ",
      "                ",
      "                "
    ],
    [
      "                ",
      "                ",
      "                ",
      "                ",
      "                ",
      "                ",
      "                ",
      "                ",
      "                ",
      "                ",
      "                ",
      "                ",
      "                ",
      "                ",
      "                ",
      "                "
    ],
    [
      "                ",
      "                ",
      "                ",
      "                ",
      "                ",
      "                ",
      "          aaaaaa",
      "        aa      ",
      "       a  bbbbbb",
      "       a bbccccc",
      "      a bbcbbbbb",
      "      a bcbbbbbb",
      "      a bcbbbbbb",
      "      a bcbbbbbb",
      "      a bcbbbbbb",
      "      a bcbbbbbb"
    ],
    [
      "                ",
      "                ",
      "                ",
      "                ",
      "                ",
      "          dddddd",
      "        ddeeeeee",
      "       deeffffff",
      "      deffffffff",
      "      deffffffff",
      "     defffffffff",
      "     defffffffff",
      "     defffffffff",
      "     defffffffff",
      "     defffffffff",
      "     defffffffff"
    ],
    [
      "                ",
      "                ",
      "                ",
      "                ",
      "                ",
      "          dddddd",
      "        ddeeeeee",
      "       dee      ",
      "      deg       ",
      "      de    h  h",
      "     de     i  j",
      "     de     k  j",
      "     de     i  j",
      "     de     k  i",
      "     de         ",
      "     de         "
    ],
    [
      "                ",
      "                ",
      "                ",
      "                ",
      "                ",
      "          dddddd",
      "        ddeellll",
      "       dee      ",
      "      dem       ",
      "      de    j  h",
      "     de     h  n",
      "     de     o  h",
      "     dl     !  h",
      "     dl     k  i",
      "     dl         ",
      "     dl         "
    ]
  ]
}