{
  "name": "multi_verticalschool_0_base1",
  "refpalette": "deceasedcraft:multi_verticalschool_0/multi_verticalschool_0_base1_palette",
  "xsize": 16,
  "zsize": 16,
  "slices": [
    [
      "vvvvvvvvvvvvvvvv",
      "vvvvv           ",
      "vvv             ",
      "vv              ",
      "vv              ",
      "v        aaaaaaa",
      "v      aabbbbbbb",
      "v     abb       ",
      "v     abc       ",
      "v    ab         ",
      "v    ab         ",
      "v    ab         ",
      "v    ab         ",
      "v    ab         ",
      "v    ab         ",
      "v    ab         "
    ],
    [
      "vvvvvvvvvvvvvvvv",
      "vvvvv           ",
      "vvv             ",
      "vv              ",
      "vv              ",
      "v        aaaaaaa",
      "v      aabbbbbbb",
      "v     abb       ",
      "v     ab        ",
      "v    ab         ",
      "v    ab         ",
      "v    ab         ",
      "v    ab         ",
      "v    ab         ",
      "v    ab        d",
      "v    ab       ed"
    ],
    [
      "vvvvvvvvvvvvvvvv",
      "vvvvv           ",
      "vvv             ",
      "vv              ",
      "vv              ",
      "v        aaaaaaa",
      "v      aabbbbbbb",
      "v     abb       ",
      "v     ab        ",
      "v    ab         ",
      "v    ab         ",
      "v    ab         ",
      "v    ab         ",
      "v    ab         ",
      "v    ab       fg",
      "v    ab       f "
    ],
    [
      "vvvvvvvvvvvvvvvv",
      "vvvvv           ",
      "vvv             ",
      "vv              ",
      "vv              ",
      "v        aaaaaaa",
      "v      aabbbbbbb",
      "v     abb       ",
      "v     ab        ",
      "v    ab         ",
      "v    ab         ",
      "v    ab         ",
      "v    ab         ",
      "v    ab         ",
      "v    ab         ",
      "v    ab         "
    ],
    [
      "vvvvvvvvvvvvvvvv",
      "vvvvv           ",
      "vvv             ",
      "vv              ",
      "vv              ",
      "v        aaaaaaa",
      "v      aabbbbbbb",
      "v     abbhhhhhhh",
      "v     abhh      ",
      "v    abhh       ",
      "v    abh        ",
      "v    abh        ",
      "v    abh        ",
      "v    abh        ",
      "v    abh        ",
      "v    abh        "
    ],
    [
      "vvvvvvvvvvvvvvvv",
      "vddddddddddddddd",
      "vddddddddddddddd",
      "vddddddddddddddd",
      "vddddddddddddddd",
      "vddddddddaaaaaaa",
      "vddddddaaiiiiiii",
      "vdddddaiijjjjjjj",
      "vdddddaijjkkkkkk",
      "vddddaijjkk     ",
      "vddddaijkk      ",
      "vddddaijk       ",
      "vddddaijk       ",
      "vddddaijk       ",
      "vddddaijk       ",
      "vddddaijk       "
    ]
  ]
}