{
  "name": "multi_verticalschool_0_base2",
  "refpalette": "deceasedcraft:multi_verticalschool_0/multi_verticalschool_0_base2_palette",
  "xsize": 16,
  "zsize": 16,
  "slices": [
    [
      "vvvvvvvvvvvvvvvv",
      "vvvvvvvvvvvvvvvv",
      "vvvvvvvvvvvvvvvv",
      "vvvvvvvvvvvvvvvv",
      "vvvvvvvvvvvvvvvv",
      "vvvvvvvvvvvvvvvv",
      "vvvvvvvvvvvvvvvv",
      "vvvvvvvvvvvvvvvv",
      "vvvvvvvvvvvvvvvv",
      "vvvvvvvvvvvvvvvv",
      "vvvvvvvvvvvvvvvv",
      "vvvvvvvvvvvvvvvv",
      "vvvvvvvvvvvvvvvv",
      "vvvvvvvvvvvvvvvv",
      "vvvvvvvvvvvvvvvv",
      "vvvvvvvvvvvvvvvv"
    ],
    [
      "vvvvvvvvvvvvvvvv",
      "vaaaaaaaaaaaaaaa",
      "vaaaaaaaaaaaaaaa",
      "vaaaaaaaaaaaaaaa",
      "vaaaaaaaaaaaaaaa",
      "vaaaaaaaaaaaaaaa",
      "vaaaaaaaaaaaaaaa",
      "vaaaaaaaaaaaaaaa",
      "vaaaaaaaaaaaaaaa",
      "vaaaaaaaaaaaaaaa",
      "vaaaaaaaaaaaaaaa",
      "vaaaaaaaaaaaaaaa",
      "vaaaaaaaaaaaaaaa",
      "vaaaaaaaaaaaaaaa",
      "vaaaaaaaaaaaaaaa",
      "vaaaaaaaaaaaaaaa"
    ],
    [
      "vvvvvvvvvvvvvvvv",
      "vaaaaaaaaaaaaaaa",
      "vaaaaaaaaaaaaaaa",
      "vaaaaaaaaaaaaaaa",
      "vaaaaaaaaaaaaaaa",
      "vaaaaaaaaaaaaaaa",
      "vaaaaaaaaaaaaaaa",
      "vaaaaaaaaaaaaaaa",
      "vaaaaaaaaaaaaaaa",
      "vaaaaaaaaaaaaaaa",
      "vaaaaaaaaaaaaaaa",
      "vaaaaaaaaaaaaaaa",
      "vaaaaaaaaaaaaaaa",
      "vaaaaaaaaaaaaaaa",
      "vaaaaaaaaaaaaaaa",
      "vaaaaaaaaaaaaaaa"
    ],
    [
      "vvvvvvvvvvvvvvvv",
      "vvvvvbbbbbbbbbbb",
      "vvvbbbbbbbbbbbbb",
      "vvbbbbbbbbbbbbbb",
      "vvbbbbbbbbbbbbbb",
      "vbbbbbbbbccccccc",
      "vbbbbbbccddddddd",
      "vbbbbbcddeeeeeee",
      "vbbbbbcdeeeeeeee",
      "vbbbbcdeeeeeeeee",
      "vbbbbcdeeeeeeeee",
      "vbbbbcdeeeeeeeee",
      "vbbbbcdeeeeeeeee",
      "vbbbbcdeeeeeeeee",
      "vbbbbcdeeeeeeeee",
      "vbbbbcdeeeeeeeee"
    ],
    [
      "vvvvvvvvvvvvvvvv",
      "vvvvv           ",
      "vvv             ",
      "vv              ",
      "vv         f    ",
      "v        ccccccc",
      "v      ccggggggg",
      "v     cgghhhhhhh",
      "v     cg!hhhhhhh",
      "v    cghhhhhhhhh",
      "v    cghhhhhhhhh",
      "v   icghhhhhhhhh",
      "v    cghhhhhhhhh",
      "v    cghhhhhhhhh",
      "v    cghhhhhhhhh",
      "v    cghhhhhhhhh"
    ],
    [
      "vvvvvvvvvvvvvvvv",
      "vvvvv           ",
      "vvv             ",
      "vv              ",
      "vv              ",
      "v        ccccccc",
      "v      ccggggggg",
      "v     cgg       ",
      "v     cgj   k   ",
      "v    cg    k k  ",
      "v    cg         ",
      "v    cg  l  k  m",
      "v    cg   l     ",
      "v    cg l       ",
      "v    cg  l      ",
      "v    cg         "
    ]
  ]
}