{
  "name": "building_factorycdamaged_ground_270",
  "refpalette": "deceasedcraft:building_factorycdamaged/building_factorycdamaged_ground_palette_270",
  "xsize": 16,
  "zsize": 16,
  "slices": [
    [
      "zzzzzzzzzzzzzzzz",
      "zzzzzzzzzzzzzbzz",
      "zzzzzzzzzzzzzzzz",
      "zz====b===b=zzbz",
      "zzcccclccccczzzz",
      "zz====mkb===zzzz",
      "zzz==========zaz",
      "zavghgngghevaazz",
      "aavggoffggfvaaza",
      "aavgffgfgfgvazaz",
      "azvgejggjigvazza",
      "zad========dzazz",
      "azz=========zzzz",
      "zzzzzzzzzzzzzzzz",
      "zzzzzzzzzzzzzzzz",
      "zzzzzzzzzzzzzzzz"
    ],
    [
      " x x  4x    xppp",
      "pCxPPPxxPPPxC s ",
      "xJJJJJJJJJJJxtt ",
      "C-)Q#   tVbJxx  ",
      "C-+   5 YW!Jxxt ",
      "xJ-% 8   XsJDyup",
      "pxK^ 862yEEKExu ",
      "x8[&    Z  LEA q",
      " {]*    0  Mu wr",
      "xFL*    0 QNFB  ",
      "x}LL      DODy  ",
      "|}K       RKIu  ",
      " xJ($9731 SJDx p",
      "xxJJJJJJJJJJxx  ",
      " CxTTTxxTTTxCxp ",
      " xxx p p pU  pp "
    ],
    [
      "                ",
      " Cx   x    xC   ",
      "xJJ'''JJ'''J    ",
      "C-`       tJxs  ",
      "C-[        Jx   ",
      "xJ-?       JD   ",
      " |K^ .    yKE;  ",
      " }\u0370     ,  :yu  ",
      " |\u0371        :    ",
      "  }        :    ",
      " |L       <O;   ",
      " |K/      >K    ",
      " xJ$  9    Ju   ",
      " xJ'''JJ'''Jx   ",
      " Cx    x    C   ",
      "                "
    ],
    [
      "                ",
      " C          C   ",
      " JJ'''JJ'''J    ",
      "C-2        J    ",
      "C-2        Jx   ",
      " J-\u0374       J    ",
      "  K^       Ky   ",
      " F\u0375        \u0373    ",
      "  F        \u0373    ",
      " |\u0371        \u0373    ",
      "  \u0371        \u0373    ",
      "  K        K\u0372   ",
      "  J        J    ",
      " xJ'''JJ'''Jx   ",
      " C          C   ",
      "                "
    ],
    [
      "                ",
      " C          C   ",
      " \u037aJ\u0377\u0377\u0377JJ\u0377\u0377\u0377J    ",
      "\u037a-J        J    ",
      "\u037a-J        J    ",
      " \u037a-        J    ",
      "  K^       K    ",
      "           \u0376    ",
      "           \u0376    ",
      "           \u0376    ",
      "  F        \u0376    ",
      "  K        K    ",
      "  J        J    ",
      "  J\u0377\u0377\u0377JJ\u0377\u0377\u0377J    ",
      " C          C   ",
      "                "
    ],
    [
      "                ",
      " C          C   ",
      "  J222JJ222J    ",
      " -J\u037f\u037e      b    ",
      " -J\u037f\u037e      J    ",
      "  J\u037f\u037e      J    ",
      "  K^\u037e      K    ",
      " \u037bK\u037e\u037e      K\u037b   ",
      " \u037bK        K\u037b   ",
      " \u037bK \u037d    \u037c K\u037b   ",
      " \u037bK \u037d    \u037d K\u037b   ",
      "  K        K    ",
      "  J        J    ",
      "  J222JJ222J    ",
      " C          C   ",
      "                "
    ]
  ]
}