{
  "name": "building_factorycdamaged_top",
  "refpalette": "deceasedcraft:building_factorycdamaged/building_factorycdamaged_top_palette",
  "xsize": 16,
  "zsize": 16,
  "slices": [
    [
      "                ",
      "                ",
      "                ",
      " a bbbbbbbbbbba ",
      " cd eeeeeeeeeef ",
      " c         g ef ",
      " ch   iiijjiief ",
      " ce          ef ",
      " ce          ef ",
      " ce          ef ",
      " ce          ef ",
      " cekk  l jjiief ",
      " cem   l     ef ",
      " ceeeeeeeeeeeef ",
      " ankknnnnnnnnna ",
      "                "
    ],
    [
      "                ",
      "                ",
      "        opppppp ",
      " d    oopoppppp ",
      "    dhhqqqqqqrs ",
      "        tuuttrs ",
      "      wttxxttr  ",
      "  h    t   ttr  ",
      "  r          r  ",
      "  r          r  ",
      "  r          r  ",
      "  rk     ww! r  ",
      "  rm   y    gr  ",
      "  rrrrrrrrrrrr  ",
      " a kk         a ",
      "                "
    ],
    [
      "                ",
      "                ",
      "                ",
      "                ",
      "                ",
      "                ",
      "      o  AA  pp ",
      " oB  dA  AA  pp ",
      " sC  CD tuuttrs ",
      " sC  uCttuuttrs ",
      "  rt   t   ttr  ",
      "  r t    ww  r  ",
      "  rm   gg   gr  ",
      "  rrrrrrrrrrrr  ",
      " a kk         a ",
      "                "
    ],
    [
      "                ",
      "                ",
      "                ",
      "                ",
      "                ",
      "                ",
      "                ",
      "                ",
      "                ",
      "                ",
      " pp  AA  AA  pp ",
      " pp  AAAAAAAApp ",
      " srm uuuuuuuurs ",
      " srqqqqqqqqqqrs ",
      " ankknnnnnnnnna ",
      "                "
    ],
    [
      "                ",
      "                ",
      "                ",
      "                ",
      "                ",
      "                ",
      "                ",
      "                ",
      "                ",
      "                ",
      "                ",
      "                ",
      "  E   Fy        ",
      "  lIIJFKK       ",
      " ppILpppppppppp ",
      " pppppppppppppp "
    ],
    [
      "                ",
      "                ",
      "                ",
      "                ",
      "                ",
      "                ",
      "                ",
      "                ",
      "                ",
      "                ",
      "                ",
      "                ",
      "                ",
      "     J M        ",
      "    w           ",
      "                "
    ],
    [
      "                ",
      "                ",
      "                ",
      "                ",
      "                ",
      "                ",
      "                ",
      "                ",
      "                ",
      "                ",
      "                ",
      "                ",
      "                ",
      "                ",
      "   Nw           ",
      "                "
    ],
    [
      "                ",
      "                ",
      "                ",
      "                ",
      "                ",
      "                ",
      "                ",
      "                ",
      "                ",
      "                ",
      "                ",
      "                ",
      "                ",
      "                ",
      "    O           ",
      "                "
    ],
    [
      "                ",
      "                ",
      "                ",
      "                ",
      "                ",
      "                ",
      "                ",
      "                ",
      "                ",
      "                ",
      "                ",
      "                ",
      "                ",
      "                ",
      "    O           ",
      "                "
    ]
  ]
}