{
  "name": "building_factorycdamaged_ground_180",
  "refpalette": "deceasedcraft:building_factorycdamaged/building_factorycdamaged_ground_palette_180",
  "xsize": 16,
  "zsize": 16,
  "slices": [
    [
      "zzzazaaazzzzzzzz",
      "zzzzazaaazzzzzzz",
      "zzzzdvvvvz=c=zzz",
      "zzz==gggg==c=zzz",
      "zzz==efgh==c=zzz",
      "zzz==jfog==c=zzz",
      "zzz==ggfn=mlbzzz",
      "zzz==gffg=kc=zzz",
      "zzz==jggg=bc=zzz",
      "zzz==ifgh==c=zzz",
      "zzz==ggfe==cbzzz",
      "zzz=dvvvv==c=zzz",
      "zzzzzaaaa=zzzzzz",
      "zzzzazzaazzzzzbz",
      "zzzzzzazzazzbzzz",
      "zzzzzazazzzzzzzz"
    ],
    [
      "  x |xx xpxCCxp ",
      "xCxx}}F{8xJ--JCx",
      "xxJJKLL][K-+)Jx ",
      "xTJ( L**&^% QJPx",
      " TJ$        #JP ",
      "pTJ9     88  JP ",
      " xJ7     6 5 Jx4",
      "pxJ3     2   Jxx",
      " TJ1  00Zy YtJP ",
      "pTJ      EXWVJP ",
      "UTJSRDQ  Es!bJP ",
      " xJJKONMLKJJJJx ",
      " CxDIDFuEEDxxxCx",
      "pxxxuyB Axyxxt p",
      "pp     w uut tsp",
      "   p   rq p    p"
    ],
    [
      "          xCCx  ",
      " Cxx|| |}|J--JC ",
      " xJJKL}\u0371\u0370K-[`Jx ",
      "  '$/    ^?  '  ",
      "  '          '  ",
      "  '      .   '  ",
      "  J9         Jx ",
      " xJ          J  ",
      "  '     ,    '  ",
      "  '          '  ",
      "  ' ><   y  t'  ",
      "  JJKO:::KJJJJx ",
      " Cxu ;  yEDxx C ",
      "        u;  s   ",
      "                ",
      "                "
    ],
    [
      "           CC   ",
      " Cx   | F J--JC ",
      "  JJK\u0371\u0371F\u0375K-22J  ",
      "  '      ^\u0374  '  ",
      "  '          '  ",
      "  '          '  ",
      "  J          J  ",
      "  J          J  ",
      "  '          '  ",
      "  '          '  ",
      "  '          '  ",
      "  JJK\u0373\u0373\u0373\u0373KJJJJ  ",
      " Cx \u0372    y x  C ",
      "                ",
      "                ",
      "                "
    ],
    [
      "           \u037a\u037a   ",
      " C        \u037a--\u037aC ",
      "  JJKF   K-JJJ  ",
      "  \u0377      ^   \u0377  ",
      "  \u0377          \u0377  ",
      "  \u0377          \u0377  ",
      "  J          J  ",
      "  J          J  ",
      "  \u0377          \u0377  ",
      "  \u0377          \u0377  ",
      "  \u0377          \u0377  ",
      "  JJK\u0376\u0376\u0376\u0376KJJJJ  ",
      " C            C ",
      "                ",
      "                ",
      "                "
    ],
    [
      "                ",
      " C   \u037b\u037b\u037b\u037b  -- C ",
      "  JJKKKKKKJJJJ  ",
      "  2     \u037e^\u037f\u037f\u037f2  ",
      "  2  \u037d\u037d \u037e\u037e\u037e\u037e\u037e2  ",
      "  2          2  ",
      "  J          J  ",
      "  J          J  ",
      "  2          2  ",
      "  2  \u037d\u037c      2  ",
      "  2          2  ",
      "  JJKKKKKKJJbJ  ",
      " C   \u037b\u037b\u037b\u037b     C ",
      "                ",
      "                ",
      "                "
    ]
  ]
}