{
  "name": "building_factorycdamaged_top_90",
  "refpalette": "deceasedcraft:building_factorycdamaged/building_factorycdamaged_top_palette_90",
  "xsize": 16,
  "zsize": 16,
  "slices": [
    [
      "                ",
      "   affffffffffa ",
      "   beeeeeeeeeen ",
      "   be i    i en ",
      "   begi    i en ",
      "   be j    j en ",
      "   be j    j en ",
      "   be i      en ",
      "   be i    llen ",
      "   be i      en ",
      "   be        en ",
      "   be      k ek ",
      "   b       kmek ",
      "    d heeeeeeen ",
      "   acccccccccca ",
      "                "
    ],
    [
      "                ",
      "  ppss        a ",
      "  pprrrrrrrrrr  ",
      "  ppqttt    gr  ",
      "  ppqttt   ! r  ",
      "  ppqux    w r  ",
      "  poqux    w r  ",
      "  opqtt      r  ",
      "   oq tt    yr  ",
      "   oh w      r  ",
      "    h        r  ",
      "    d        rk ",
      "           kmrk ",
      "       hrrrrrr  ",
      "   d          a ",
      "                "
    ],
    [
      "                ",
      "      ppss    a ",
      "      pprrrrrr  ",
      "        ttt gr  ",
      "        ttt  r  ",
      "      AAuu w r  ",
      "      AAuu w r  ",
      "        tt  gr  ",
      "         tt gr  ",
      "      oADC   r  ",
      "       dCu   r  ",
      "           t rk ",
      "          t mrk ",
      "       BCCrrrr  ",
      "       oss    a ",
      "                "
    ],
    [
      "                ",
      "          ppssa ",
      "          pprrn ",
      "           Auqn ",
      "           Auqn ",
      "          AAuqn ",
      "          AAuqn ",
      "           Auqn ",
      "           Auqn ",
      "          AAuqn ",
      "          AAuqn ",
      "             qk ",
      "            mqk ",
      "          pprrn ",
      "          ppssa ",
      "                "
    ],
    [
      "                ",
      "              pp",
      "              pp",
      "              pp",
      "              pp",
      "              pp",
      "              pp",
      "             Kpp",
      "            yKpp",
      "            FFpp",
      "             Jpp",
      "             ILp",
      "             IIp",
      "            Elpp",
      "              pp",
      "                "
    ],
    [
      "                ",
      "                ",
      "                ",
      "                ",
      "                ",
      "                ",
      "                ",
      "                ",
      "             M  ",
      "                ",
      "             J  ",
      "              w ",
      "                ",
      "                ",
      "                ",
      "                "
    ],
    [
      "                ",
      "                ",
      "                ",
      "                ",
      "                ",
      "                ",
      "                ",
      "                ",
      "                ",
      "                ",
      "                ",
      "              w ",
      "              N ",
      "                ",
      "                ",
      "                "
    ],
    [
      "                ",
      "                ",
      "                ",
      "                ",
      "                ",
      "                ",
      "                ",
      "                ",
      "                ",
      "                ",
      "                ",
      "              O ",
      "                ",
      "                ",
      "                ",
      "                "
    ],
    [
      "                ",
      "                ",
      "                ",
      "                ",
      "                ",
      "                ",
      "                ",
      "                ",
      "                ",
      "                ",
      "                ",
      "              O ",
      "                ",
      "                ",
      "                ",
      "                "
    ]
  ]
}