{
  "name": "building_factorycdamaged_top_180",
  "refpalette": "deceasedcraft:building_factorycdamaged/building_factorycdamaged_top_palette_180",
  "xsize": 16,
  "zsize": 16,
  "slices": [
    [
      "                ",
      " annnnnnnnnkkna ",
      " feeeeeeeeeeeec ",
      " fe     l   mec ",
      " feiijj l  kkec ",
      " fe          ec ",
      " fe          ec ",
      " fe          ec ",
      " fe          ec ",
      " feiijjiii   hc ",
      " fe g         c ",
      " feeeeeeeeee dc ",
      " abbbbbbbbbbb a ",
      "                ",
      "                ",
      "                "
    ],
    [
      "                ",
      " a         kk a ",
      "  rrrrrrrrrrrr  ",
      "  rg    y   mr  ",
      "  r !ww     kr  ",
      "  r          r  ",
      "  r          r  ",
      "  r          r  ",
      "  rtt   t    h  ",
      "  rttxxttw      ",
      " srttuut        ",
      " srqqqqqqhhd    ",
      " pppppopoo    d ",
      " ppppppo        ",
      "                ",
      "                "
    ],
    [
      "                ",
      " a         kk a ",
      "  rrrrrrrrrrrr  ",
      "  rg   gg   mr  ",
      "  r  ww    t r  ",
      "  rtt   t   tr  ",
      " srttuuttCu  Cs ",
      " srttuut DC  Cs ",
      " pp  AA  Ad  Bo ",
      " pp  AA  o      ",
      "                ",
      "                ",
      "                ",
      "                ",
      "                ",
      "                "
    ],
    [
      "                ",
      " annnnnnnnnkkna ",
      " srqqqqqqqqqqrs ",
      " sruuuuuuuu mrs ",
      " ppAAAAAAAA  pp ",
      " pp  AA  AA  pp ",
      "                ",
      "                ",
      "                ",
      "                ",
      "                ",
      "                ",
      "                ",
      "                ",
      "                ",
      "                "
    ],
    [
      " pppppppppppppp ",
      " ppppppppppLIpp ",
      "       KKFJIIl  ",
      "        yF   E  ",
      "                ",
      "                ",
      "                ",
      "                ",
      "                ",
      "                ",
      "                ",
      "                ",
      "                ",
      "                ",
      "                ",
      "                "
    ],
    [
      "                ",
      "           w    ",
      "        M J     ",
      "                ",
      "                ",
      "                ",
      "                ",
      "                ",
      "                ",
      "                ",
      "                ",
      "                ",
      "                ",
      "                ",
      "                ",
      "                "
    ],
    [
      "                ",
      "           wN   ",
      "                ",
      "                ",
      "                ",
      "                ",
      "                ",
      "                ",
      "                ",
      "                ",
      "                ",
      "                ",
      "                ",
      "                ",
      "                ",
      "                "
    ],
    [
      "                ",
      "           O    ",
      "                ",
      "                ",
      "                ",
      "                ",
      "                ",
      "                ",
      "                ",
      "                ",
      "                ",
      "                ",
      "                ",
      "                ",
      "                ",
      "                "
    ],
    [
      "                ",
      "           O    ",
      "                ",
      "                ",
      "                ",
      "                ",
      "                ",
      "                ",
      "                ",
      "                ",
      "                ",
      "                ",
      "                ",
      "                ",
      "                ",
      "                "
    ]
  ]
}