{
  "name": "building_factorycdamaged_ground_90",
  "refpalette": "deceasedcraft:building_factorycdamaged/building_factorycdamaged_ground_palette_90",
  "xsize": 16,
  "zsize": 16,
  "slices": [
    [
      "zzzzzzzzzzzzzzzz",
      "zzzzzzzzzzzzzzzz",
      "zzzzzzzzzzzzzzzz",
      "zzzz=========zza",
      "zzazd========daz",
      "azzavgijggjegvza",
      "zazavgfgfgffgvaa",
      "azaavfggffoggvaa",
      "zzaavehggnghgvaz",
      "zaz==========zzz",
      "zzzz===bkm====zz",
      "zzzzccccclcccczz",
      "zbzz=b===b====zz",
      "zzzzzzzzzzzzzzzz",
      "zzbzzzzzzzzzzzzz",
      "zzzzzzzzzzzzzzzz"
    ],
    [
      " pp  Up p p xxx ",
      " pxCxTTTxxTTTxC ",
      "  xxJJJJJJJJJJxx",
      "p xDJS 1379$(Jx ",
      "  uIKR       K}|",
      "  yDOD      LL}x",
      "  BFNQ 0    *LFx",
      "rw uM  0    *]{ ",
      "q AEL  Z    &[8x",
      " uxEKEEy268 ^Kxp",
      "puyDJsX   8 %-Jx",
      " txxJ!WY 5   +-C",
      "  xxJbVt   #Q)-C",
      " ttxJJJJJJJJJJJx",
      " s CxPPPxxPPPxCp",
      "pppx    x4  x x "
    ],
    [
      "                ",
      "   C    x    xC ",
      "   xJ'''JJ'''Jx ",
      "   uJ    9  $Jx ",
      "    K>      /K| ",
      "   ;O<       L| ",
      "    :        }  ",
      "    :        \u0371| ",
      "  uy:  ,     \u0370} ",
      "  ;EKy    . ^K| ",
      "   DJ       ?-Jx",
      "   xJ        [-C",
      "  sxJt       `-C",
      "    J'''JJ'''JJx",
      "   Cx    x   xC ",
      "                "
    ],
    [
      "                ",
      "   C          C ",
      "   xJ'''JJ'''Jx ",
      "    J        J  ",
      "   \u0372K        K  ",
      "    \u0373        \u0371  ",
      "    \u0373        \u0371| ",
      "    \u0373        F  ",
      "    \u0373        \u0375F ",
      "   yK       ^K  ",
      "    J       \u0374-J ",
      "   xJ        2-C",
      "    J        2-C",
      "    J'''JJ'''JJ ",
      "   C          C ",
      "                "
    ],
    [
      "                ",
      "   C          C ",
      "    J\u0377\u0377\u0377JJ\u0377\u0377\u0377J  ",
      "    J        J  ",
      "    K        K  ",
      "    \u0376        F  ",
      "    \u0376           ",
      "    \u0376           ",
      "    \u0376           ",
      "    K       ^K  ",
      "    J        -\u037a ",
      "    J        J-\u037a",
      "    J        J-\u037a",
      "    J\u0377\u0377\u0377JJ\u0377\u0377\u0377J\u037a ",
      "   C          C ",
      "                "
    ],
    [
      "                ",
      "   C          C ",
      "    J222JJ222J  ",
      "    J        J  ",
      "    K        K  ",
      "   \u037bK \u037d    \u037d K\u037b ",
      "   \u037bK \u037c    \u037d K\u037b ",
      "   \u037bK        K\u037b ",
      "   \u037bK      \u037e\u037eK\u037b ",
      "    K      \u037e^K  ",
      "    J      \u037e\u037fJ  ",
      "    J      \u037e\u037fJ- ",
      "    b      \u037e\u037fJ- ",
      "    J222JJ222J  ",
      "   C          C ",
      "                "
    ]
  ]
}