{
  "name": "building_factorycdamaged_ground",
  "refpalette": "deceasedcraft:building_factorycdamaged/building_factorycdamaged_ground_palette",
  "xsize": 16,
  "zsize": 16,
  "slices": [
    [
      "zzzzzzzzazazzzzz",
      "zzzbzzazzazzzzzz",
      "zbzzzzzaazzazzzz",
      "zzzzzz=aaaazzzzz",
      "zzz=c==vvvvd=zzz",
      "zzzbc==efgg==zzz",
      "zzz=c==hgfi==zzz",
      "zzz=cb=gggj==zzz",
      "zzz=ck=gffg==zzz",
      "zzzblm=nfgg==zzz",
      "zzz=c==gofj==zzz",
      "zzz=c==hgfe==zzz",
      "zzz=c==gggg==zzz",
      "zzz=c=zvvvvdzzzz",
      "zzzzzzzaaazazzzz",
      "zzzzzzzzaaazazzz"
    ],
    [
      "p    p qr   p   ",
      "pst tuu w     pp",
      "p txxyxA Byuxxxp",
      "xCxxxDEEuFDIDxC ",
      " xJJJJKLMNOKJJx ",
      " PJb!sE  QDRSJTU",
      " PJVWXE      JTp",
      " PJtY yZ00  1JT ",
      "xxJ   2     3Jxp",
      "4xJ 5 6     7Jx ",
      " PJ  88     9JTp",
      " PJ#        $JT ",
      "xPJQ %^&**L (JTx",
      " xJ)+-K[]LLKJJxx",
      "xCJ--Jx8{F}}xxCx",
      " pxCCxpx xx| x  "
    ],
    [
      "                ",
      "                ",
      "   s  ;u        ",
      " C xxDEy  ; uxC ",
      " xJJJJK:::OKJJ  ",
      "  't  y   <> '  ",
      "  '          '  ",
      "  '    ,     '  ",
      "  J          Jx ",
      " xJ         9J  ",
      "  '   .      '  ",
      "  '          '  ",
      "  '  ?^    /$'  ",
      " xJ`[-K\u0370\u0371}LKJJx ",
      " CJ--J|}| ||xxC ",
      "  xCCx          "
    ],
    [
      "                ",
      "                ",
      "                ",
      " C  x y    \u0372 xC ",
      "  JJJJK\u0373\u0373\u0373\u0373KJJ  ",
      "  '          '  ",
      "  '          '  ",
      "  '          '  ",
      "  J          J  ",
      "  J          J  ",
      "  '          '  ",
      "  '          '  ",
      "  '  \u0374^      '  ",
      "  J22-K\u0375F\u0371\u0371KJJ  ",
      " CJ--J F |   xC ",
      "   CC           "
    ],
    [
      "                ",
      "                ",
      "                ",
      " C            C ",
      "  JJJJK\u0376\u0376\u0376\u0376KJJ  ",
      "  \u0377          \u0377  ",
      "  \u0377          \u0377  ",
      "  \u0377          \u0377  ",
      "  J          J  ",
      "  J          J  ",
      "  \u0377          \u0377  ",
      "  \u0377          \u0377  ",
      "  \u0377   ^      \u0377  ",
      "  JJJ-K   FKJJ  ",
      " C\u037a--\u037a        C ",
      "   \u037a\u037a           "
    ],
    [
      "                ",
      "                ",
      "                ",
      " C     \u037b\u037b\u037b\u037b   C ",
      "  JbJJKKKKKKJJ  ",
      "  2          2  ",
      "  2      \u037c\u037d  2  ",
      "  2          2  ",
      "  J          J  ",
      "  J          J  ",
      "  2          2  ",
      "  2\u037e\u037e\u037e\u037e\u037e \u037d\u037d  2  ",
      "  2\u037f\u037f\u037f^\u037e     2  ",
      "  JJJJKKKKKKJJ  ",
      " C --  \u037b\u037b\u037b\u037b   C ",
      "                "
    ]
  ]
}