{
  "name": "building_factorycdamaged_top_270",
  "refpalette": "deceasedcraft:building_factorycdamaged/building_factorycdamaged_top_palette_270",
  "xsize": 16,
  "zsize": 16,
  "slices": [
    [
      "                ",
      " acccccccccca   ",
      " neeeeeeeh d    ",
      " kemk       b   ",
      " ke k      eb   ",
      " ne        eb   ",
      " ne      i eb   ",
      " nell    i eb   ",
      " ne      i eb   ",
      " ne j    j eb   ",
      " ne j    j eb   ",
      " ne i    igeb   ",
      " ne i    i eb   ",
      " neeeeeeeeeeb   ",
      " affffffffffa   ",
      "                "
    ],
    [
      "                ",
      " a          d   ",
      "  rrrrrrh       ",
      " krmk           ",
      " kr        d    ",
      "  r        h    ",
      "  r      w ho   ",
      "  ry    tt qo   ",
      "  r      ttqpo  ",
      "  r w    xuqop  ",
      "  r w    xuqpp  ",
      "  r !   tttqpp  ",
      "  rg    tttqpp  ",
      "  rrrrrrrrrrpp  ",
      " a        sspp  ",
      "                "
    ],
    [
      "                ",
      " a    sso       ",
      "  rrrrCCB       ",
      " krm t          ",
      " kr t           ",
      "  r   uCd       ",
      "  r   CDAo      ",
      "  rg tt         ",
      "  rg  tt        ",
      "  r w uuAA      ",
      "  r w uuAA      ",
      "  r  ttt        ",
      "  rg ttt        ",
      "  rrrrrrpp      ",
      " a    sspp      ",
      "                "
    ],
    [
      "                ",
      " asspp          ",
      " nrrpp          ",
      " kqm            ",
      " kq             ",
      " nquAA          ",
      " nquAA          ",
      " nquA           ",
      " nquA           ",
      " nquAA          ",
      " nquAA          ",
      " nquA           ",
      " nquA           ",
      " nrrpp          ",
      " asspp          ",
      "                "
    ],
    [
      "                ",
      "pp              ",
      "pplE            ",
      "pII             ",
      "pLI             ",
      "ppJ             ",
      "ppFF            ",
      "ppKy            ",
      "ppK             ",
      "pp              ",
      "pp              ",
      "pp              ",
      "pp              ",
      "pp              ",
      "pp              ",
      "                "
    ],
    [
      "                ",
      "                ",
      "                ",
      "                ",
      " w              ",
      "  J             ",
      "                ",
      "  M             ",
      "                ",
      "                ",
      "                ",
      "                ",
      "                ",
      "                ",
      "                ",
      "                "
    ],
    [
      "                ",
      "                ",
      "                ",
      " N              ",
      " w              ",
      "                ",
      "                ",
      "                ",
      "                ",
      "                ",
      "                ",
      "                ",
      "                ",
      "                ",
      "                ",
      "                "
    ],
    [
      "                ",
      "                ",
      "                ",
      "                ",
      " O              ",
      "                ",
      "                ",
      "                ",
      "                ",
      "                ",
      "                ",
      "                ",
      "                ",
      "                ",
      "                ",
      "                "
    ],
    [
      "                ",
      "                ",
      "                ",
      "                ",
      " O              ",
      "                ",
      "                ",
      "                ",
      "                ",
      "                ",
      "                ",
      "                ",
      "                ",
      "                ",
      "                ",
      "                "
    ]
  ]
}