{
  "name": "multi_gallery_2_base1",
  "refpalette": "deceasedcraft:multi_gallery_2/multi_gallery_2_base1_palette",
  "xsize": 16,
  "zsize": 16,
  "slices": [
    [
      "vvvvvvvvvvvvvvvv",
      "aaaaabbaaaaaaaaa",
      "        c       ",
      "                ",
      "                ",
      "                ",
      "                ",
      "    deef        ",
      "   g hi    j    ",
      "   g        k   ",
      "    g           ",
      "    g           ",
      "     g          ",
      "     g          ",
      "      g         ",
      "      g         "
    ],
    [
      "vvvvvvvvvvvvvvvv",
      "aaaaallaaaaaaaaa",
      "        m       ",
      "                ",
      "                ",
      "                ",
      "                ",
      "    deef        ",
      "   g       j    ",
      "   g        j   ",
      "    g           ",
      "    g           ",
      "     g          ",
      "     g          ",
      "      g         ",
      "      g         "
    ],
    [
      "vvvvvvvvvvvvvvvv",
      "aaaaaaaaaaaaaaaa",
      "                ",
      "                ",
      "                ",
      "                ",
      "                ",
      "    deef        ",
      "   g       j!   ",
      "   g        j   ",
      "    g           ",
      "    g           ",
      "     g          ",
      "     g          ",
      "      g         ",
      "      g         "
    ],
    [
      "vvvvvvvvvvvvvvvv",
      "aaaaaaaaaaaaaaaa",
      "                ",
      "                ",
      "n               ",
      "n               ",
      " n              ",
      " n  deef        ",
      "  ng       jj   ",
      "  ng        j   ",
      "   ng           ",
      "   ng           ",
      "    ng          ",
      "    ng          ",
      "     ng         ",
      "     ng         "
    ],
    [
      "vvvvvvvvvvvvvvvv",
      "aaaaaaaaaaaaaaaa",
      "opppqqqqpppppppp",
      "oppppppppppppppp",
      "aopppppppppppppp",
      "aopppppppppppppp",
      " aoppppppppppppp",
      " aoppeepppqqqqpp",
      "  aoppppppqqqqpp",
      "  aoppppppqqqqpp",
      "   aopppppqqqqpp",
      "   aoppppppppppp",
      "    aopppppppppp",
      "    aopppppppppp",
      "     aoppppppppp",
      "     aoppppppppp"
    ],
    [
      "vvvvvvvvvvvvvvvv",
      "aaaaaaaaaaaaaaaa",
      "rrrrrrrrrrrrrrrr",
      "rrrrrrrrrrrrrrrr",
      "arrrrrrrrrrrrrrr",
      "arrrrrrrrrrrrrrr",
      "rarroooorrrrrrrr",
      "rarrossooooorrrr",
      "t aroooooooooooo",
      "t arrrrroooooooo",
      "   arrrrrrrroooo",
      "   arrrrrrrrrrrr",
      "    arrrrrrrrrrr",
      "    arrrrrrrrrrr",
      "     arrrrrrrrrr",
      "     arrrrrrrrrr"
    ]
  ]
}