{
  "name": "multi_gallery_2_base2",
  "refpalette": "deceasedcraft:multi_gallery_2/multi_gallery_2_base2_palette",
  "xsize": 16,
  "zsize": 16,
  "slices": [
    [
      "vvvvvvvvvvvvvvvv",
      "aaaaaaaaaaaaaaaa",
      "aaaaaaaaaaaaaaaa",
      "aaaaaaaaaaaaaaaa",
      "aaaaaaaaaaaaaaaa",
      "aaaaaaaaaaaaaaaa",
      "aaaaaaaaaaaaaaaa",
      "aaaaaaaaaaaaaaaa",
      "aaaaaaaaaaaaaaaa",
      "aaaaaaaaaaaaaaaa",
      "aaaaaaaaaaaaaaaa",
      "aaaaaaaaaaaaaaaa",
      "aaaaaaaaaaaaaaaa",
      "aaaaaaaaaaaaaaaa",
      "aaaaaaaaaaaaaaaa",
      "aaaaaaaaaaaaaaaa"
    ],
    [
      "vvvvvvvvvvvvvvvv",
      "aaaaaaaaaaaaaaaa",
      "aaaaaaaaaaaaaaaa",
      "aaaaaaaaaaaaaaaa",
      "aaaaaaaaaaaaaaaa",
      "aaaaaaaaaaaaaaaa",
      "aaaaaaaaaaaaaaaa",
      "aaaaaaaaaaaaaaaa",
      "aaaaaaaaaaaaaaaa",
      "aaaaaaaaaaaaaaaa",
      "aaaaaaaaaaaaaaaa",
      "aaaaaaaaaaaaaaaa",
      "aaaaaaaaaaaaaaaa",
      "aaaaaaaaaaaaaaaa",
      "aaaaaaaaaaaaaaaa",
      "aaaaaaaaaaaaaaaa"
    ],
    [
      "vvvvvvvvvvvvvvvv",
      "bbbbbbbbbbbbbbbb",
      "bccccccccccccccc",
      "bccccccccccccccc",
      "abcccccccccccccc",
      "abcccccccccccccc",
      "aabccccccddddddc",
      "aabccccccdeeeedc",
      "aaabcccccdeeeedc",
      "aaabcccccdeeeedc",
      "aaaabccccdeeeedc",
      "aaaabccccddddddc",
      "aaaaabcccccccccc",
      "aaaaabcccccccccc",
      "aaaaaabccccccccc",
      "aaaaaabccccccccc"
    ],
    [
      "vvvvvvvvvvvvvvvv",
      "ffffffffffffffff",
      "g          hi   ",
      "g               ",
      "jg              ",
      "jg              ",
      "jjg  kl         ",
      "jjg mnno  pppp  ",
      "jjjq      pppp  ",
      "jjjq      pppp  ",
      "jjjjq     pppp  ",
      "jjjjq           ",
      "jjjjjq          ",
      "jjjjjq          ",
      "jjjjjjq         ",
      "jjjjjjq         "
    ],
    [
      "vvvvvvvvvvvvvvvv",
      "fffffrrfffffffff",
      "                ",
      "                ",
      "                ",
      "                ",
      "                ",
      "    mnno  s  s  ",
      "   q            ",
      "   q            ",
      "    q     s  s  ",
      "    q           ",
      "     q          ",
      "     q          ",
      "      q         ",
      "      q         "
    ],
    [
      "vvvvvvvvvvvvvvvv",
      "fffffttfffffffff",
      "        u       ",
      "                ",
      "                ",
      "                ",
      "                ",
      "    mnno        ",
      "   q wx    y    ",
      "   q            ",
      "    q           ",
      "    q           ",
      "     q          ",
      "     q          ",
      "      q         ",
      "      q         "
    ]
  ]
}