{
  "name": "multi_gallery_2_ground",
  "refpalette": "deceasedcraft:multi_gallery_2/multi_gallery_2_ground_palette",
  "xsize": 16,
  "zsize": 16,
  "slices": [
    [
      "aaaaaaaaaaaaaaaa",
      "aaaaaaaaaaaaaaba",
      "aaaaaaaaaaaaaaca",
      "aaaaaaaaaaaaaaaa",
      "aaaaaaaaaaaaaaaa",
      "ddeffffffaaaaaaa",
      "deffggggfffffaaa",
      "deffghigggggffff",
      "ejefgggggggggggg",
      "e efffffgggggggg",
      "  jedddfffffgggg",
      "   edddddddfffff",
      "   jeddddddddddf",
      "    eddddddddddd",
      "    jedddddddddd",
      "     edddddddddd"
    ],
    [
      "                ",
      "                ",
      "                ",
      "                ",
      "                ",
      "kkl             ",
      "k     m         ",
      "kl   no m       ",
      " pp m       m m ",
      "l p      m   m  ",
      "  pp            ",
      "   pq    q      ",
      "   pp  r        ",
      "    p       q   ",
      "    ppr   r     ",
      "     p          "
    ],
    [
      "                ",
      "                ",
      "                ",
      "                ",
      "                ",
      "  s             ",
      "     no         ",
      " s   no         ",
      "     no         ",
      "s               ",
      "                ",
      "                ",
      "                ",
      "                ",
      "                ",
      "                "
    ],
    [
      "                ",
      "                ",
      "                ",
      "                ",
      "                ",
      "  s   t         ",
      "     no         ",
      " s              ",
      "     no         ",
      "s    t          ",
      "                ",
      "                ",
      "                ",
      "                ",
      "                ",
      "                "
    ],
    [
      "                ",
      "                ",
      "                ",
      "                ",
      "      t         ",
      "  s   t         ",
      "                ",
      " s              ",
      "                ",
      "s    t          ",
      "     t          ",
      "                ",
      "                ",
      "                ",
      "u       www     ",
      "p      wwww     "
    ],
    [
      "                ",
      "                ",
      "                ",
      "      x         ",
      "      t         ",
      "  y             ",
      "                ",
      " y              ",
      "                ",
      "y               ",
      "     t          ",
      "     A          ",
      "uuu             ",
      "BBp             ",
      "Cpp             ",
      "pp       w      "
    ]
  ]
}