{
  "name": "multi_gallery_2_floor1",
  "refpalette": "deceasedcraft:multi_gallery_2/multi_gallery_2_floor1_palette",
  "xsize": 16,
  "zsize": 16,
  "slices": [
    [
      "                ",
      "    aaa         ",
      "   bcccccaa     ",
      "   ccddccccccaa ",
      "  bcdddddddccccc",
      "  ccdddddddddddc",
      " bcddddddddddddd",
      " ccddddddddddddd",
      "bcdddddddddddddd",
      "ccdddddddddddddd",
      "cddddddddddddddd",
      "cccccddddddddddd",
      "eeeffccccddddddd",
      "  ff ggggccccddd",
      " ff      ggggccc",
      "             ggg"
    ],
    [
      "                ",
      "                ",
      "    hhh         ",
      "    h  hhhh     ",
      "   h    ij hhhh ",
      "   h           h",
      "  h             ",
      "  h             ",
      "kh              ",
      "gh              ",
      "h               ",
      "       l        ",
      "   ffmmmm  l    ",
      "   f ggggmmmm  l",
      "         ggggmmm",
      "       n     ggg"
    ],
    [
      "                ",
      "                ",
      "    hhh         ",
      "    h  hhhh     ",
      "   h       hhhh ",
      "   h           h",
      " kh             ",
      " gh             ",
      "gh              ",
      "gh              ",
      "                ",
      "       o        ",
      "     mmmm  p    ",
      "     ggggmmmm  q",
      "         ggggmmm",
      "             ggg"
    ],
    [
      "                ",
      "                ",
      "    hhh         ",
      "    h  hhhh     ",
      "  kh       hhhh ",
      "  gh           h",
      " gh             ",
      " gh             ",
      "g               ",
      "g               ",
      "                ",
      "                ",
      "     mmmm       ",
      "     ggggmmmm   ",
      "         ggggmmm",
      "rr  k        ggg"
    ],
    [
      "                ",
      "                ",
      "   khhh         ",
      "   gh  hhhh     ",
      "  gh       hhhh ",
      "  gh           h",
      " g              ",
      " g              ",
      "gs              ",
      "g               ",
      "r               ",
      "rr              ",
      "tr   hhhh       ",
      "trr  gggghhhh   ",
      "ttrr k   ggk hhh",
      "  ttg           "
    ],
    [
      "                ",
      "   gkkk         ",
      "   guuukkkk     ",
      "   gwwwuuuukkkk ",
      "  gwwwwwwwwuuuuk",
      "  gwwwwwwwwwwwwu",
      " grwwwwwwwwwwwww",
      " grwwwwwwwwwwwww",
      "xtrwwwwwwwwywwww",
      "xtrrwwwwwwwAwwww",
      " ttrwwwwwwwwwwww",
      "  trwwwwwwwwwwww",
      "  ttruuuuwwwwwww",
      "   trgggguuuuwww",
      "    tg   gggguuu",
      "             kkk"
    ]
  ]
}