{
  "name": "multi_verticalschool_7_floor24",
  "refpalette": "deceasedcraft:multi_verticalschool_7/multi_verticalschool_7_floor24_palette",
  "xsize": 16,
  "zsize": 16,
  "slices": [
    [
      " aaaaaaaaaaa    ",
      " a    a    a    ",
      " a    a    a    ",
      " a    a    a    ",
      " a    a    a    ",
      " aaaaaaaaaaa    ",
      "  b       c     ",
      "  b             ",
      "          c     ",
      "  b       c     ",
      " aaaaaaaaaaa    ",
      " adef   a  a    ",
      " adef   ag a    ",
      " addh   a  a    ",
      " add    ai a    ",
      " aaaaaaaaaaa    "
    ],
    [
      " aaaaaaaaaaa    ",
      " a    a    a    ",
      " a    a    a    ",
      " a    a    a    ",
      " a    a    a    ",
      " aaaaaaaaaaa    ",
      "  b       c     ",
      "  b       c     ",
      "  b       c     ",
      "  b       c     ",
      " aaaaaaaaaaa    ",
      " a  ef  a  a    ",
      " a  ef  ag a    ",
      " a  j   a  a    ",
      " a      ai a    ",
      " aaaaaaaaaaa    "
    ],
    [
      " aaaaaaaaaaa    ",
      " a    a    a    ",
      " a    a    a    ",
      " a    a    a    ",
      " a    a    a    ",
      " aaaaaaaaaaa    ",
      "  b       c     ",
      "  b       c     ",
      "  b       c     ",
      "  b       c     ",
      " aaaaaaaaaaa    ",
      " a   efka  a    ",
      " a  lefkag a    ",
      " a   jkka  a    ",
      " a    kkai a    ",
      " aaaaaaaaaaa    "
    ],
    [
      " aaaaaaaaaaa    ",
      " a    a    a    ",
      " a    a    a    ",
      " a    a    a    ",
      " a    a    a    ",
      " aaaaaaaaaaa    ",
      " mn       om    ",
      " mn       om    ",
      " mn       om    ",
      " mn       om    ",
      " aaaaaaaaaaa    ",
      " a    ddap a    ",
      " a   lddag a    ",
      " a   qrda  a    ",
      " a   qrdai a    ",
      " aaaaaaaaaaa    "
    ],
    [
      " aaaaaaaaaaa    ",
      " a    a    a    ",
      " a    a    a    ",
      " a    a    a    ",
      " a    a    a    ",
      " aaaaaaaaaaa    ",
      " astttttttua    ",
      " auttttttuua    ",
      " auttttttuua    ",
      " attttttttua    ",
      " aaaaaaaaaaa    ",
      " a      appa    ",
      " a   w  ag a    ",
      " a  qr  a  a    ",
      " a  qr  ai a    ",
      " aaaaaaaaaaa    "
    ],
    [
      "xaaaaaaaaaaaxxxx",
      "xa    a    axxxx",
      "xa    a    axxxx",
      "xa    a    axxxx",
      "xa    a    axxxx",
      "xaaaaaaaaaaaxxxx",
      "xayyyyyyyyyaxxxx",
      "xayyAyyyAyyaxxxx",
      "xayyAyyyAyyaxxxx",
      "xayyyyyyyyyaxxxx",
      "xaaaaaaaaaaaxxxx",
      "xakk    appaxxxx",
      "xakkw   agpaxxxx",
      "xakqrh  ap axxxx",
      "xakqr   ai axxxx",
      "xaaaaaaaaaaaxxxx"
    ]
  ]
}