{
  "name": "multi_verticalschool_7_floor21",
  "refpalette": "deceasedcraft:multi_verticalschool_7/multi_verticalschool_7_floor21_palette",
  "xsize": 16,
  "zsize": 16,
  "slices": [
    [
      " aaaaaaaaaaa    ",
      " a    a    a    ",
      " a    a    a    ",
      " a    a    a    ",
      " a    a    a    ",
      " aa  aaa  aa    ",
      "   bb   bb      ",
      "                ",
      "                ",
      "       c  d     ",
      " aaaaaaeaaea    ",
      " afgh   a  a    ",
      " afgh   ai a    ",
      " affj   ak a    ",
      " aff    ak a    ",
      " aaaaaaaaaaa    "
    ],
    [
      " aaaaaaaaaaa    ",
      " a    a    a    ",
      " a    a    a    ",
      " a    a    a    ",
      " a    a    a    ",
      " aaaaaaaaaaa    ",
      "                ",
      "                ",
      "                ",
      "                ",
      " aaaaaaaaaaa    ",
      " a  gh lam a    ",
      " a  gh  an a    ",
      " a  o   a  a    ",
      " a      ak a    ",
      " aaaaaaaaaaa    "
    ],
    [
      "paaaaaaaaaaaqqqq",
      "pa    a    aqqqq",
      "pa    a    aqqqq",
      "pa    a    aqqqq",
      "pa    a    aqqqq",
      "paaaaaaaaaaaqqqq",
      "parrrrrrrrraqqqq",
      "parrsrrrsrraqqqq",
      "parrsrrrsrraqqqq",
      "parrrrrrrrraqqqq",
      "paaaaaaaaaaaqqqq",
      "pa   ghta  aqqqq",
      "pa  ughtaw aqqqq",
      "pa   otta  aqqqq",
      "pa    ttak aqqqq",
      "paaaaaaaaaaaqqqq"
    ],
    [
      "xaaaaaaaaaaayyyy",
      "xa    a    ayyyy",
      "xa    a    ayyyy",
      "xa    a    ayyyy",
      "xa    a    ayyyy",
      "xa aaaA aaaayyyy",
      "xyyyyyyyyyyyyyyy",
      "xyyyyyyyyyyyyyyy",
      "xyyyyyyyyyyyyyyy",
      "xyyyyyyyyyyyyyyy",
      "xaaaaaaaaaaayyyy",
      "xa    ffaBBayyyy",
      "xa   uffaBBayyyy",
      "xa   CDfaBBayyyy",
      "xa   CDfaEFayyyy",
      "xaaaaaaaaaaayyyy"
    ],
    [
      "aaaaaaaaaaaaII  ",
      "aa    a    aJK  ",
      "aa    a    aLK  ",
      "aa    a    a K  ",
      "aa    a    aLK  ",
      "aaaMMaaaMMaa K  ",
      "aNOPQ  OPQ      ",
      "aN              ",
      "aN              ",
      "aN              ",
      "aaaaaaaRaaSa    ",
      "aa      aT aU   ",
      "aa   V  aW aX   ",
      "aa  CD  a  aY   ",
      "aa  CD  akZa0   ",
      "aaaaaaaaaaaa    "
    ],
    [
      "aaaaaaaaaaaa    ",
      "aa    a    a 1  ",
      "aa    a    a 2  ",
      "aa    a    a    ",
      "aa    a    a 3  ",
      "aaa  aaa  aa 4  ",
      "a  56   56      ",
      "a               ",
      "a7              ",
      "a               ",
      "aaaaaaa8aa9a    ",
      "aatt    aT a#   ",
      "aattV   aW a$   ",
      "aatCDj  a% a^   ",
      "aatCD   ak a#   ",
      "aaaaaaaaaaaa    "
    ]
  ]
}