{
  "name": "multi_verticalschool_7_floor31",
  "refpalette": "deceasedcraft:multi_verticalschool_7/multi_verticalschool_7_floor31_palette",
  "xsize": 16,
  "zsize": 16,
  "slices": [
    [
      " aaaaaaaaaa     ",
      " a    a    a    ",
      " a    a    a    ",
      " a    a    a    ",
      " a    a    a    ",
      " aaaaaaaaaaaaaaa",
      " a              ",
      " a              ",
      " a              ",
      " a              ",
      " aaaaaaaaaaaaaaa",
      " abcd    e a    ",
      " afg    h  a    ",
      " aij    h  a    ",
      " aik    hl a    ",
      " aaaaaaaaaa     "
    ],
    [
      " aaaaaaaaaa     ",
      " a    a    a    ",
      " a    a    a    ",
      " a    a    a    ",
      " a    a    a  mm",
      " aaaaaaaaaaaaaaa",
      " a         n    ",
      " a         n    ",
      " a         n    ",
      " a         n    ",
      " aaaaaaaaaaaaaaa",
      " aop     e a  qq",
      " afr       a    ",
      " ast       a    ",
      " aiu     l a    ",
      " aaaaaaaaaa     "
    ],
    [
      " aaaaaaaaaa     ",
      " a    a    a    ",
      " a    a    a    ",
      " a    a    a    ",
      " a    a    a  ww",
      " aaaaaaaaaaaaaaa",
      " axxxxxxxxya    ",
      " axxxxxxxxxa    ",
      " axxxxxxxxxa    ",
      " axxxxxxxxAa    ",
      " aaaaaaaaaaaaaaa",
      " a       e a  BB",
      " aC        a    ",
      " aD        a    ",
      " al      l a    ",
      " aaaaaaaaaa     "
    ],
    [
      " aaaaaaaaaa     ",
      " a    a    a    ",
      " a    a    a    ",
      " a    a    a    ",
      " a    a    a    ",
      " aaaaaaaaaaaaaaa",
      " aEEEEEEEEEa    ",
      " aEEFEEEFEEa    ",
      " aEEFEEEFEEa    ",
      " aEEEEEEEEEa    ",
      " aaaaaaaaaaaaaaa",
      " a       e a    ",
      " a         a    ",
      " a         a    ",
      " allllllll a    ",
      " aaaaaaaaaa     "
    ],
    [
      "IaaaaaaaaaaJJJJJ",
      "IaKKKKKKKKKaJJJJ",
      "IaK  KKK  KaJJJJ",
      "IaK  KKK  KaJJJJ",
      "IaKKKKKKKKKaJJJJ",
      "IaKKKKKKKKKaaaaa",
      "IaKKKKKKKKKaIIII",
      "IaKKKKKKKKKaIIII",
      "IaKKKKKKKKKaIIII",
      "IaKKKKKKKKKaIIII",
      "Iaaaaaaaaaaaaaaa",
      "Ia       e aJJJJ",
      "Ia         aJJJJ",
      "Ia         aJJJJ",
      "Ia  l    l aJJJJ",
      "IaaaaaaaaaaJJJJJ"
    ],
    [
      "LaaaaaaaaaaaMMMM",
      "LaN       NaKKKK",
      "LaOPQR RQPOaKKKK",
      "LaS       SaKKKK",
      "LaN       NaKKKK",
      "LaOTU   UTOaKKKK",
      "LaV       VaKKKK",
      "LaW       WaKKKK",
      "La         aKKKK",
      "La        XaKKKK",
      "Laaaaaaaa aaKKKK",
      "La         aKKKK",
      "La         aKKKK",
      "La         aKKKK",
      "La  l    l aKKKK",
      "LaaaaaaaaaaaMMMM"
    ]
  ]
}