{
  "name": "multi_verticalschool_7_floor16",
  "refpalette": "deceasedcraft:multi_verticalschool_7/multi_verticalschool_7_floor16_palette",
  "xsize": 16,
  "zsize": 16,
  "slices": [
    [
      " aaaaaaaaaaa    ",
      " a    a    a    ",
      " a    a    a    ",
      " a    a    a    ",
      " a    a    a    ",
      " aa  aaa  aa    ",
      "   bb   bb      ",
      "                ",
      "                ",
      "       c  d     ",
      " aaaaaaeaaea    ",
      " afgh   ai a    ",
      " afgh   aj a    ",
      " affk   al a   m",
      " aff    al a    ",
      " aaaaaaaaaaa    "
    ],
    [
      " aaaaaaaaaaa    ",
      " a    a    a    ",
      " a    a    a    ",
      " a    a    a    ",
      " a    a    a    ",
      " aaaaaaaaaaa    ",
      "                ",
      "                ",
      "                ",
      "                ",
      " aaaaaaaaaaa    ",
      " a  gh nai a    ",
      " a  gh  ao a    ",
      " a  p   a  a   q",
      " a      al a    ",
      " aaaaaaaaaaa    "
    ],
    [
      " aaaaaaaaaaa    ",
      " a    a    a    ",
      " a    a    a    ",
      " a    a    a    ",
      " a    a    a    ",
      " aaaaaaaaaaa    ",
      "                ",
      "                ",
      "                ",
      "                ",
      " aaaaaaaaaaa    ",
      " a   ghrai a    ",
      " a  sghrao a    ",
      " a   prrat a   q",
      " a    rral a    ",
      " aaaaaaaaaaa    "
    ],
    [
      " aaaaaaaaaaa    ",
      " a    a    a    ",
      " a    a    a    ",
      " a    a    a    ",
      " a    a    a    ",
      " aaaaaaaaaaa    ",
      "                ",
      "                ",
      "                ",
      "                ",
      " aaaaaaaaaaa    ",
      " a    ffai a    ",
      " a   sffaj a    ",
      " a   uwfal a   x",
      " a   uwfal a    ",
      " aaaaaaaaaaa    "
    ],
    [
      "yaaaaaaaaaaa    ",
      "ya    a    a    ",
      "ya    a    a    ",
      "ya    a    a    ",
      "ya    a    a    ",
      "yaaaaaaaaaaa    ",
      "y          y    ",
      "y          y    ",
      "y          y    ",
      "y          y    ",
      "yaaaaaaaaaaa    ",
      "ya      a  a    ",
      "ya   A  aB a    ",
      "ya  uw  a  a    ",
      "ya  uw  al a    ",
      "yaaaaaaaaaaa    "
    ],
    [
      "aaaaaaaaaaaa    ",
      "aa    a    a    ",
      "aa    a    a    ",
      "aa    a    a    ",
      "aa    a    a    ",
      "aaaaaaaaaaaa    ",
      "a          a    ",
      "a          a    ",
      "a          a    ",
      "a          a    ",
      "aaaaaaaaaaaa    ",
      "aarr    a  a    ",
      "aarrA   aC a    ",
      "aaruwk  a  a    ",
      "aaruw   al a    ",
      "aaaaaaaaaaaa    "
    ]
  ]
}