{
  "name": "multi_verticalschool_7_floor1",
  "refpalette": "deceasedcraft:multi_verticalschool_7/multi_verticalschool_7_floor1_palette",
  "xsize": 16,
  "zsize": 16,
  "slices": [
    [
      " aaaaaaaaaaa    ",
      " a    a    a    ",
      " a    a    a    ",
      " a    a    a    ",
      " a    a    a    ",
      " aaaaaaaaaaa    ",
      "                ",
      "                ",
      "                ",
      "                ",
      " aaaaaaaaaaa    ",
      " abcd   a  a    ",
      " abcd   ae a    ",
      " abbf   a  a    ",
      " abb    ag a    ",
      " aaaaaaaaaaa    "
    ],
    [
      " aaaaaaaaaaa    ",
      " a    a    a    ",
      " a    a    a    ",
      " a    a    a    ",
      " a    a    a    ",
      " aaaaaaaaaaa    ",
      " h         h    ",
      " h         h    ",
      " h         h    ",
      " h         h    ",
      " aaaaaaaaaaa    ",
      " a  cd  a  a    ",
      " a  cd  ae a    ",
      " a  i   a  a    ",
      " a      ag a    ",
      " aaaaaaaaaaa    "
    ],
    [
      " aaaaaaaaaaa    ",
      " a    a    a    ",
      " a    a    a    ",
      " a    a    a    ",
      " a    a    a    ",
      " aaaaaaaaaaa    ",
      " a         a    ",
      " a         a    ",
      " a         a    ",
      " a         a    ",
      " aaaaaaaaaaa    ",
      " a   cdja  a    ",
      " a  kcdjae a    ",
      " a   ijja  a    ",
      " a    jjag a    ",
      " aaaaaaaaaaa    "
    ],
    [
      " aaaaaaaaaaa    ",
      " a    a    a    ",
      " a    a    a    ",
      " a    a    a    ",
      " a    a    a    ",
      " aaaaaaaaaaa    ",
      " a         a    ",
      " a         a    ",
      " a         a    ",
      " a         a    ",
      " aaaaaaaaaaa    ",
      " a    bba  a    ",
      " a   kbbae a    ",
      " a   lmba  a    ",
      " a   lmbag a    ",
      " aaaaaaaaaaa    "
    ],
    [
      " aaaaaaaaaaa    ",
      " a    a    a    ",
      " a    a    a    ",
      " a    a    a    ",
      " a    a    a    ",
      " aaaaaaaaaaa    ",
      " a         a    ",
      " a         a    ",
      " a         a    ",
      " a         a    ",
      " aaaaaaaaaaa    ",
      " a      a  a    ",
      " a   n  ae a    ",
      " a  lm  a  a    ",
      " a  lm  ag a    ",
      " aaaaaaaaaaa    "
    ],
    [
      " aaaaaaaaaaa    ",
      " a    a    a    ",
      " a    a    a    ",
      " a    a    a    ",
      " a    a    a    ",
      " aaaaaaaaaaa    ",
      " a         a    ",
      " a         a    ",
      " a         a    ",
      " a         a    ",
      " aaaaaaaaaaa    ",
      " ajj    a  a    ",
      " ajjn   ae a    ",
      " ajlmf  a  a    ",
      " ajlm   ag a    ",
      " aaaaaaaaaaa    "
    ]
  ]
}