{
  "name": "multi_verticalschool_7_floor11",
  "refpalette": "deceasedcraft:multi_verticalschool_7/multi_verticalschool_7_floor11_palette",
  "xsize": 16,
  "zsize": 16,
  "slices": [
    [
      "  aaaaaaaaa  b  ",
      " a    a    a b  ",
      " a    a    a b  ",
      " a    a    a b  ",
      " a    a    a b  ",
      " aaaaaaaaaaa b  ",
      " c         a b  ",
      " c         a b  ",
      " c         a b  ",
      " c         a b  ",
      " aaaaaaaaaaa b  ",
      " adef   ag a b  ",
      " adef   ah a b  ",
      " addi   aj a b  ",
      " add    aj a b  ",
      "  aaaaaaaaa  a  "
    ],
    [
      "  aaaaaaaaa  b  ",
      " a    a    a b  ",
      " a    a    a b  ",
      " a    a    a b  ",
      " a    a    a b  ",
      " aaaaaaaaaaa b  ",
      " a         a b  ",
      " a         a b  ",
      " a         a b  ",
      " a         a b  ",
      " aaaaaaaaaaa b  ",
      " a  ef  a  a b  ",
      " a  ef  a! a b  ",
      " a  k   a  a b  ",
      " a      aj a b  ",
      "  aaaaaaaaa  a  "
    ],
    [
      "  aaaaaaaaa  b  ",
      " a    a    a b  ",
      " a    a    a b  ",
      " a    a    a b  ",
      " a    a    a b  ",
      " aaaaaaaaaaa b  ",
      " a         a b  ",
      " a         a b  ",
      " a         a b  ",
      " a         a b  ",
      " aaaaaaaaaaa b  ",
      " a   efla  a b  ",
      " a  meflan a b  ",
      " a   klla  a b  ",
      " a    llaj a b  ",
      "  aaaaaaaaa  a  "
    ],
    [
      "  aaaaaaaaa ob  ",
      " a    a    aob  ",
      " a    a    aob  ",
      " a    a    aob  ",
      " a    a    aob  ",
      " aaaaaaaaaaaob  ",
      " a         aob  ",
      " a         aob  ",
      " a         aob  ",
      " a         aob  ",
      " aaaaaaaaaaaob  ",
      " a    dda  aob  ",
      " a   mddap aob  ",
      " a   qrda  aob  ",
      " a   qrdaj aob  ",
      " saaaaaaaaasoa  "
    ],
    [
      "  aaaaaaaaa tuwx",
      " a    a    atuwx",
      " a    a    atuwx",
      " a    a    atuwx",
      " a    a    atuwx",
      " aaaaaaaaaaauuwx",
      " ayyyyyyyyAatuwx",
      " ayyyyyyyyyatuwx",
      " ayyyyyyyyyatuwx",
      " ayyyyyyyyBatuwx",
      " aaaaaaaaaaauuwx",
      " a      a  atuwx",
      " a   C  aD atuwx",
      " a  qr  a  atuwx",
      " a  qr  aj atuwx",
      " EaaaaaaaaaEtuwx"
    ],
    [
      "  aaaaaaaaa FuIJ",
      " a    a    aFuIJ",
      " a    a    aFuIJ",
      " a    a    aFuIJ",
      " a    a    aFuIJ",
      " aKaaaaaaaaauuIL",
      " aMMMMMMMMMaMLLL",
      " aMMNMMMOMMaMLLL",
      " aMMNMMMOMMaMLLL",
      " aMMMMMMMMMaMLJL",
      " aaaaaaaaaaauuIJ",
      " all    a  aFuIJ",
      " allC   aD aFuIJ",
      " alqri  a  aFuIJ",
      " alqr   aj aFuIJ",
      "  aaaaaaaaa FuIJ"
    ]
  ]
}