{
  "name": "multi_verticalschool_7_floor3",
  "refpalette": "deceasedcraft:multi_verticalschool_7/multi_verticalschool_7_floor3_palette",
  "xsize": 16,
  "zsize": 16,
  "slices": [
    [
      " aaaaaaaaaaa    ",
      " a    a    a    ",
      " a    a    a    ",
      " a    a    a    ",
      " a    a    a    ",
      " aa  aaa  aa    ",
      "   bb   bb      ",
      "                ",
      "                ",
      "       c  d     ",
      " aaaaaaeaaea    ",
      " afgh   a  a    ",
      " afgh   ai a    ",
      " affj   ak a    ",
      " aff    ak a    ",
      " aaaaaaaaaaa    "
    ],
    [
      " aaaaaaaaaaa    ",
      " a    a    a    ",
      " a    a    a    ",
      " a    a    a    ",
      " a    a    a    ",
      " aaaaaaaaaaa    ",
      "                ",
      "                ",
      "                ",
      "                ",
      " aaaaaaaaaaa    ",
      " a  gh lam a    ",
      " a  gh  an a    ",
      " a  o   a  a    ",
      " a      ak a    ",
      " aaaaaaaaaaa    "
    ],
    [
      " aaaaaaaaaaa    ",
      " a    a    a    ",
      " a    a    a    ",
      " a    a    a    ",
      " a    a    a    ",
      " aaaaaaaaaaa    ",
      "                ",
      "                ",
      "                ",
      "                ",
      " aaaaaaaaaaa    ",
      " a   ghpa  a    ",
      " a  qghpar a    ",
      " a   oppa  a    ",
      " a    ppak a    ",
      " aaaaaaaaaaa    "
    ],
    [
      " aaaaaaaaaaa    ",
      " a    a    a    ",
      " a    a    a    ",
      " a    a    a    ",
      " a    a    a    ",
      " aaaaaaaaaaa    ",
      " a         a    ",
      " a         a    ",
      " a         a    ",
      " a         a    ",
      " aaaaaaaaaaa    ",
      " a    ffa  a    ",
      " a   qffar a    ",
      " a   stfa  a    ",
      " a   stfak a    ",
      " aaaaaaaaaaa    "
    ],
    [
      "uaaaaaaaaaaauuuw",
      "ua    a    auuuu",
      "ua    a    auuuu",
      "ua    a    auuuu",
      "ua    a    auuuu",
      "uaaaaaaaaaaauuuw",
      "uauuuuuuuuuauuuu",
      "uauuwuuuwuuauuuu",
      "uauuwuuuwuuauuuu",
      "uauuuuuuuuuauuuu",
      "uaaaaaaaaaaauuuw",
      "ua      a  auuuu",
      "ua   x  ar auuuu",
      "ua  st  a  auuuu",
      "ua  st  ak auuuu",
      "uaaaaaaaaaaauuuw"
    ],
    [
      "yaaaaaaaaaaaAAAA",
      "ya    a    aAAAA",
      "ya    a    aAAAA",
      "ya    a    aAAAA",
      "Aa    a    auuua",
      "yaBaaaaaaaaaC DE",
      "yFFFFFFFFFFFC DE",
      "yFFFFFFFFFFFC DE",
      "yFFFFFFFFFFFC DE",
      "yFFFFFFFFFFFC DE",
      "yaaaaaaaaaaaC DE",
      "yapp    a  auuua",
      "yappx   ar aAAAA",
      "yapstj  a  aAAAA",
      "yapst   ak aAAAA",
      "AaaaaaaaaaaaAAAA"
    ]
  ]
}