{
  "name": "multi_verticalschool_7_base1",
  "refpalette": "deceasedcraft:multi_verticalschool_7/multi_verticalschool_7_base1_palette",
  "xsize": 16,
  "zsize": 16,
  "slices": [
    [
      "aaaaaaaaaaaa   b",
      " a    acccca   b",
      " a    ad  ea   f",
      " a    ad  ea   b",
      " a    ag  ea   h",
      " aa  aaa  aa   b",
      " a ii   ii     f",
      " j             f",
      " j             f",
      "ka     l       f",
      "aaaaaaamaaaa   b",
      " anop   aqra   h",
      " anop   a sa   b",
      " annt   a sa   f",
      " ann    a ra   b",
      "aaaaaaauauaa   b"
    ],
    [
      "aaaaaaaaaaaa   b",
      " a    acccca   b",
      " a    ad  ea   b",
      " a    ad  ea   b",
      " a    ag  ea   h",
      " aaaaaaaaaaa   b",
      " a             b",
      " a             b",
      " a             b",
      "ka             b",
      "aaaaaaaaaaaa   b",
      " a  op waqra   h",
      " a  op  a xa   b",
      " a  y   a xa   b",
      " a      a ra   b",
      "aaaaaaaaaaaa   b"
    ],
    [
      "aaaaaaaaaaaa   b",
      " a    acccca   b",
      " a    aAAAAa   b",
      " a    aABBAa   b",
      " a    aAAAAa   h",
      " aaaaaaaaaaa   b",
      " a             b",
      " a             b",
      " a             b",
      "ka             b",
      "aaaaaaaaaaaa   b",
      " a   opCaqra   h",
      " a  DopCa Ea   b",
      " a   yCCa Ea   b",
      " a    CCa ra   b",
      "aaaaaaaaaaaa   b"
    ],
    [
      "aaaaaaaaaaaa   b",
      " a    acccca   b",
      " a    acccca   b",
      " a    acccca   b",
      " a    acccca   h",
      " aaaaaaaaaaa   b",
      " a             b",
      " a             b",
      " a             b",
      "ka             b",
      "aaaaaaaaaaaa   b",
      " a    nnaqFa   h",
      " a   Dnna  a   b",
      " a   IJna  a   b",
      " a   IJnaKFa   b",
      "aaaaaaaaaaaa   b"
    ],
    [
      "aaaaaaaaaaaaLLLb",
      " a    a    aLLLb",
      " a    a    aLLLb",
      " a    a    aLMLb",
      " a    a    aLMLh",
      " aaaaaaaaaaaLMLb",
      " aNNNNNNNNOPLLLb",
      " aNNNNNNNNNPLLLb",
      " aNNNNNNNNNPLLLb",
      "kaNNNNNNNNQPLLLb",
      "aaaaaaaaaaaaLMLb",
      " a      aqFaLMLh",
      " a   R  a FaLMLb",
      " a  IJ  a FaLLLb",
      "Fa  IJ  aFFaLLLb",
      "aaaaaaaaaaFaLLLb"
    ],
    [
      "aaaaaaaaaaaaAAAS",
      "Ta    a    aAAAS",
      "Ta    a    aAAAS",
      "Ta    a    aAAAS",
      "Ta    a    aAAAS",
      "TaaaaaaaaaaaAAAS",
      "TaUUUUUUUUUaAAAS",
      "TaUUBUUUBUUaAAAS",
      "TaUUBUUUBUUaAAAS",
      "VaUUUUUUUUUaAAAS",
      "aaaaaaaaaaaaAAAS",
      "TaCC    aq aAAAS",
      "TaCCR   a  aAAAS",
      "TaCIJt  a  aAAAS",
      "TaCIJ   aF aAAAS",
      "aaaaaaaaaaaaAAAS"
    ]
  ]
}