{
  "name": "multi_verticalschool_7_floor9",
  "refpalette": "deceasedcraft:multi_verticalschool_7/multi_verticalschool_7_floor9_palette",
  "xsize": 16,
  "zsize": 16,
  "slices": [
    [
      "aabbbbbbbbbbcccc",
      "ab    b    b    ",
      "ab    b    b    ",
      "bb    b    b    ",
      "bb    b    b    ",
      "bd bbbd bbbb    ",
      "aaaaaaaaaaab    ",
      "aaaaaaaaaaab    ",
      "aaaaaaaaaaab    ",
      "aaaaaaaaaaab    ",
      "bbbbbbbbbbbb    ",
      "bbefg   bhhb    ",
      "bbefg   bhhb    ",
      "bbeei   bhhb    ",
      "bbee    bjkb    ",
      "bbbbbbbbbbbb    "
    ],
    [
      "  bbbbbbbbbbcccc",
      " b    b    b    ",
      " b    b    b    ",
      "bb    b    b    ",
      "bb    b    b    ",
      "bbbllbbbllbb    ",
      "  mno  mno b    ",
      "           b    ",
      "           b    ",
      "           b    ",
      "bbpbbbbbbbqb    ",
      "bb  fg  b  b    ",
      "bb  fg  br b    ",
      "bb  s   b  b    ",
      "bb      bjtb    ",
      "bbbbbbbbbbbb    "
    ],
    [
      "  bbbbbbbbbbcccc",
      " b    b    b    ",
      " b    b    b    ",
      "bb    b    b    ",
      "bb    b    b    ",
      "bbb  bbb  bb    ",
      "   uw   uw b    ",
      "           b    ",
      "           b    ",
      "           b    ",
      "bbxbbbbbbbyb    ",
      "bb   fgAb  b    ",
      "bb  BfgAbr b    ",
      "bb   sAAbC b    ",
      "bb    AAbj b    ",
      "bbbbbbbbbbbb    "
    ],
    [
      "  bbbbbbbbbbcccc",
      " b    b    b    ",
      " b    b    b    ",
      "bb    b    b    ",
      "bb    b    b    ",
      "bbb  bbb  bb    ",
      "   DD   DD b    ",
      "           b    ",
      "           b    ",
      "  E       Fb    ",
      "bbIbbbbbbbIb    ",
      "bb    eeb  b    ",
      "bb   Beebr b    ",
      "bb   JKebj b    ",
      "bb   JKebj b    ",
      "bbbbbbbbbbbbL   "
    ],
    [
      "MMbbbbbbbbbbcccc",
      "Mb    b    b    ",
      "Mb    b    b    ",
      "bb    b    b    ",
      "bb    b    b    ",
      "bbbbbbbbbbbb    ",
      "MMMMMMMMMMMb    ",
      "NMMMNMMMNMMb    ",
      "NMMMNMMMNMMb    ",
      "MMMMMMMMMMMb    ",
      "bbbbbbbbbbbb    ",
      "bbO     bP b    ",
      "bb   Q  bR b    ",
      "bb  JK  b  b    ",
      "bb  JK  bj b    ",
      "bbbbbbbbbbbbS   "
    ],
    [
      "eebbbbbbbbbbcccc",
      "eb    b    b    ",
      "eb    b    b    ",
      "eb    b    b T  ",
      "eb    b    b    ",
      "ebUbbbbbbbbb    ",
      "VVVVVVVVVVVb W  ",
      "VVVVVVVVVVVb    ",
      "VVVVVVVVVVVb    ",
      "VVVVVVVVVVVb    ",
      "Vbbbbbbbbbbb    ",
      "VbAA    b  b    ",
      "VbAAQ   bX b    ",
      "VbAJKi  b  b    ",
      "VbAJK   bj b    ",
      "VVbbbbbbbbbb    "
    ]
  ]
}