{
  "name": "multi_verticalschool_7_floor17",
  "refpalette": "deceasedcraft:multi_verticalschool_7/multi_verticalschool_7_floor17_palette",
  "xsize": 16,
  "zsize": 16,
  "slices": [
    [
      "aaaaaaaaaaaa    ",
      "aa    a    a    ",
      "aa    a    a    ",
      "aa    a    a    ",
      "aa    a    a    ",
      "aaaaaaaaaaaa    ",
      "a          a    ",
      "a          a    ",
      "a          a    ",
      "a          a    ",
      "aaaaaaaaaaaa    ",
      "aabcd   a  a    ",
      "aabcd   ae a    ",
      "aabbf   a  a    ",
      "aabb    ag a    ",
      "aahaaaaaaaaa    "
    ],
    [
      "aaaaaaaaaaaa    ",
      "aa    a    a    ",
      "aa    a    a    ",
      "aa    a    a    ",
      "aa    a    a    ",
      "aaaaaaaaaaaa    ",
      "aiiiiiiiiija    ",
      "aiiiiiiiiiia    ",
      "aiiiiiiiiiia    ",
      "aiiiiiiiiika    ",
      "aaaaaaaaaaaa    ",
      "aa  cd  a  a    ",
      "aa  cd  al a    ",
      "aa  m   a  a    ",
      "aa      ag a    ",
      "aanaaaaaaaaa    "
    ],
    [
      "aaaaaaaaaaaa    ",
      "aa    a    a    ",
      "aa    a    a    ",
      "aa    a    a    ",
      "aa    a    a    ",
      "aaaaaaaaaaaa    ",
      "aooooooooooa    ",
      "aoopoooopooa    ",
      "aoopoooopooa    ",
      "aooooooooooa    ",
      "aaaaaaaaaaaa    ",
      "aa   cdqa  a    ",
      "aa  rcdqal a    ",
      "aa   mqqa  a    ",
      "aas   qqag a    ",
      "aataaaaaaaaa    "
    ],
    [
      "oaaaaaaaaaaaou  ",
      "oa    a    aou  ",
      "oa    a    aou  ",
      "oa    a    aou  ",
      "oa    a    aou  ",
      "ow aaaw aaaaou  ",
      "ooooooooooooouuu",
      "oooooooooooooooo",
      "oooooooooooooooo",
      "ooooooooooooouuu",
      "xaaaaaaaaaaaou  ",
      "xa    bbayyaou  ",
      "xa   rbbayyaou  ",
      "xa   ABbayyaou  ",
      "xa   ABbaCDaou  ",
      "xaaaaaaaaaaaou  "
    ],
    [
      " aaaaaaaaaaa E  ",
      " a    a    a E  ",
      " a    a    a E  ",
      " a    a    a E  ",
      " a    a    a E  ",
      " aaFFaaaFFaa E  ",
      "  IJK  IJK    LL",
      "                ",
      "                ",
      "  MNO         PP",
      "QaaaaaaRaaSa E  ",
      " a      a  a E  ",
      " a   T  aU a E  ",
      " a  AB  a  a E  ",
      " a  AB  agVa E  ",
      " aaaaaaaaaaa E  "
    ],
    [
      " aaaaaaaaaaa    ",
      " a    a    a    ",
      " a    a    a    ",
      " a    a    a    ",
      " a    a    a    ",
      " aa  aaa  aa    ",
      "   WX   WX      ",
      "                ",
      "                ",
      "                ",
      " aaaaaaYaaZa    ",
      " aqq    a  a    ",
      " aqqT   aU a    ",
      " aqABf  a0 a    ",
      " aqAB   ag a    ",
      " aaaaaaaaaaa    "
    ]
  ]
}