{
  "name": "multi_verticalschool_7_floor19",
  "refpalette": "deceasedcraft:multi_verticalschool_7/multi_verticalschool_7_floor19_palette",
  "xsize": 16,
  "zsize": 16,
  "slices": [
    [
      " aaaaaaaaaaa    ",
      " a    a    a    ",
      " a    a    a    ",
      " a    a    a    ",
      " a    a    a    ",
      " aa  aaa  aa    ",
      "   bb   bb      ",
      "                ",
      "                ",
      "       c  d     ",
      " aaaaaaeaaea    ",
      " afgh   ai a    ",
      " afgh   a!ja    ",
      " affk   al a    ",
      " aff    al a    ",
      " aaaaaaaaaaa    "
    ],
    [
      " aaaaaaaaaaa    ",
      " a    a    a    ",
      " a    a    a    ",
      " a    a    a    ",
      " a    a    a    ",
      " aaaaaaaaaaa    ",
      "                ",
      "                ",
      "                ",
      "                ",
      " aaaaaaaaaaa    ",
      " a  gh man a    ",
      " a  gh  ao a    ",
      " a  p   aq a    ",
      " a      al a    ",
      " aaaaaaaaaaa    "
    ],
    [
      "raaaaaaaaaaa    ",
      "ra    a    a    ",
      "ra    a    a    ",
      "ra    a    a    ",
      "ra    a    a    ",
      "raaaaaaaaaaa    ",
      "rasssssssssa    ",
      "rasstsssussa    ",
      "rasstsssussa    ",
      "rasssssssssa    ",
      "raaaaaaaaaaa    ",
      "ra   ghwa  a    ",
      "ra  xghway a    ",
      "ra   pwwa ja    ",
      "ra    wwal a    ",
      "raaaaaaaaaaa    "
    ],
    [
      "AaaaaaaaaaaaAB  ",
      "Aa    a    aAB  ",
      "Aa    a    aAB  ",
      "Aa    a    aAB  ",
      "Aa    a    aAB  ",
      "AC aaaC aaaaAB  ",
      "AAAAAAAAAAAAABBB",
      "AAAAAAAAAAAAAAAA",
      "AAAAAAAAAAAAAAAA",
      "AAAAAAAAAAAAABBB",
      "DaaaaaaaaaaaAB  ",
      "Da    ffaEEaAB  ",
      "Da   xffaEEaAB  ",
      "Da   FIfaEEaAB  ",
      "Da   FIfaJKaAB  ",
      "DaaaaaaaaaaaAB  "
    ],
    [
      " aaaaaaaaaaa L  ",
      " a    a    a L  ",
      " a    a    a L  ",
      " a    a    a L  ",
      " a    a    a L  ",
      " aaMMaaaMMaa L  ",
      "  NOP  NOP    QQ",
      "                ",
      "                ",
      "  RST         UU",
      "VaaaaaaWaaXa L  ",
      " a      a  a L  ",
      " a   Y  aZ a L  ",
      " a  FI  a  a L  ",
      " a  FI  al0a L  ",
      " aaaaaaaaaaa L  "
    ],
    [
      " aaaaaaaaaaa    ",
      " a    a    a    ",
      " a    a    a    ",
      " a    a    a    ",
      " a    a    a    ",
      " aa  aaa  aa    ",
      "   12   12      ",
      "                ",
      "                ",
      "                ",
      " aaaaaa3aa4a    ",
      " aww    a  a    ",
      " awwY   aZ a    ",
      " awFIk  a5 a    ",
      " awFI   al a    ",
      " aaaaaaaaaaa    "
    ]
  ]
}