{
  "name": "multi_verticalschool_7_ground",
  "refpalette": "deceasedcraft:multi_verticalschool_7/multi_verticalschool_7_ground_palette",
  "xsize": 16,
  "zsize": 16,
  "slices": [
    [
      "abbbbbbbbbbbaaca",
      "ab    b    baaca",
      "ab    b    baaca",
      "ab    b    baaca",
      "ab    b    baaca",
      "ad bbbd bbbbaaca",
      "eeeeeeeeeeeeeeee",
      "eeeeeeeeeeeeeeee",
      "eeeeeeeeeeeeeeee",
      "eeeeeeeeeeeeeeee",
      "abbbbbbbbbbbaaca",
      "abfgh   bijbaaca",
      "abfgh   bjjbaaca",
      "abffk   bjjbaaca",
      "abff    blmbaaca",
      "abbbbbbbbbbbaaca"
    ],
    [
      " bbbbbbbbbbb  n ",
      " b    b    b  n ",
      " b    b    b  n ",
      " b    b    b  n ",
      " b    b    b  n ",
      " bboobbboobb  n ",
      " pqrs  qrs t    ",
      " p         t    ",
      " p         t    ",
      " p         t    ",
      " bubbbbbbbbb  n ",
      " b  gh  bw b  n ",
      " b  gh  bxyb  n ",
      " b  A   bxBb  n ",
      " b      bCDb  n ",
      " bbbbbbbbbbb  n "
    ],
    [
      " bbbbbbbbbbb    ",
      " b    b    b    ",
      " b    b    b    ",
      " b    b    b    ",
      " b    b    b    ",
      " bb  bbb  bb    ",
      "   EF   EF      ",
      "                ",
      "                ",
      "                ",
      " bIbbbbbbbbb    ",
      " b   ghJb  b    ",
      " b  KghJbxLb    ",
      " b   AJJbxMb    ",
      " b    JJbC b    ",
      " bbbbbbbbbbb    "
    ],
    [
      " bbbbbbbbbbb    ",
      " b    b    b    ",
      " b    b    b    ",
      " b    b    b    ",
      " b    b    b    ",
      " bb  bbb  bb    ",
      "   NN   NN      ",
      "                ",
      "                ",
      "  O             ",
      " bPbbbbbbbbb    ",
      " b    ffb  b    ",
      " b   KffbQ b    ",
      " b   RSfbT b    ",
      " b   RSfbC b    ",
      " bbbbbbbbbbb    "
    ],
    [
      " bbbbbbbbbbb    ",
      " b    b    b    ",
      " b    b    b    ",
      " b    b    b    ",
      " b    b    b    ",
      " bbbbbbbbbbb    ",
      "                ",
      "                ",
      "                ",
      "                ",
      " bbbbbbbbbbb    ",
      " bU     b  b    ",
      " b   V  bQ b    ",
      " b  RS  b  b    ",
      " b  RS  bC b    ",
      " bbbbbbbbbbb    "
    ],
    [
      " bbbbbbbbbbb    ",
      " b    b    b    ",
      " b    b    b    ",
      " b    b    b    ",
      " b    b    b    ",
      " bbbbbbbbbbb    ",
      "                ",
      "                ",
      "                ",
      "                ",
      " bbbbbbbbbbb    ",
      " bJJ    b  b    ",
      " bJJV   bQ b    ",
      " bJRSk  b  b    ",
      " bJRS   bC b    ",
      " bbbbbbbbbbb    "
    ]
  ]
}