{
  "name": "multi_verticalschool_7_floor5",
  "refpalette": "deceasedcraft:multi_verticalschool_7/multi_verticalschool_7_floor5_palette",
  "xsize": 16,
  "zsize": 16,
  "slices": [
    [
      "abbbbbbbbbbbaacc",
      "ab    b    baacc",
      "ab    b    baacc",
      "ab    b    baacc",
      "ab    b    baacc",
      "abbbbbbbbbbbaacc",
      "aaaaaaaaaaaaaacc",
      "aaaaaaaaaaaaaacc",
      "aaaaaaaaaaaaaacc",
      "aaaaaaaaaaaaaacc",
      "abbbbbbbbbbbaacc",
      "abdef   b  baacc",
      "abdef   bg baacc",
      "abddh   b  baacc",
      "abdd    bi baacc",
      "abbbbbbbbbbbaacc"
    ],
    [
      "jbbbbbbbbbbb  bc",
      "jb    b    b  bc",
      "jb    b    b  bc",
      "jb    b    b  bc",
      "jb    b    b  bc",
      "jbbbbbbbbbbb  bc",
      "jb            bc",
      "jb            bc",
      "jb            bc",
      "jb            bc",
      "jbkbbbbbbbbb  bc",
      "jb  ef  b  b  bc",
      "jb  ef  bg b  bc",
      "jb  l   b  b  bc",
      "jb      bi b  bc",
      "jbbbbbbbbbbb  bc"
    ],
    [
      "jbbbbbbbbbbb  bc",
      "jb    b    b  bc",
      "jb    b    b  bc",
      "jb    b    b  bc",
      "jb    b    b  bc",
      "jbbbbbbbbbbb  bc",
      "jb            bc",
      "jb            bc",
      "jb            bc",
      "jb            bc",
      "jbmbbbbbbbbb  bc",
      "jb   efnb  b  bc",
      "jb  oefnbg b  bc",
      "jb   lnnb  b  bc",
      "jb    nnbi b  bc",
      "jbbbbbbbbbbb  bc"
    ],
    [
      "jbbbbbbbbbbbaaac",
      "jb    b    baaac",
      "jb    b    baaac",
      "jb    b    baaac",
      "jb    b    baaac",
      "jp bbbp bbbbaaac",
      "jbaaaaaaaaaaaaac",
      "jbaaaaaaaaaaaaac",
      "jbaaaaaaaaaaaaac",
      "jbaaaaaaaaaaaaac",
      "jbqbbbbbbbbbaaac",
      "jbr   ddbqqbaaac",
      "jb   oddbqqbaaac",
      "jb   stdbqqbaaac",
      "jb   stdbuwbaaac",
      "jbbbbbbbbbbbaaac"
    ],
    [
      " bbbbbbbbbbb  bc",
      " b    b    b  bc",
      " b    b    b  bc",
      " b    b    b  bc",
      " b    b    b  bc",
      " bbxxbbbxxbb  bc",
      " yABC  ABC    bc",
      " y            bc",
      " y            bc",
      " y            bc",
      " bbbbbbDbbEb  bc",
      " b      bF b  bc",
      " b   I  bJ b  bc",
      " b  st  b  b  bc",
      " b  st  biKb  bc",
      " bbbbbbbbbbb  bc"
    ],
    [
      " bbbbbbbbbbb  bc",
      " b    b    b  bc",
      " b    b    b  bc",
      " b    b    b  bc",
      " b    b    b  bc",
      " bb  bbb  bb  bc",
      " y LM   LM    bc",
      " y            bc",
      " y            bc",
      " y            bc",
      " bbbbbbNbbOb  bc",
      " bnn    bF b  bc",
      " bnnI   bJ b  bc",
      " bnsth  bP b  bc",
      " bnst   bi b  bc",
      " bbbbbbbbbbb  bc"
    ]
  ]
}