{
  "name": "multi_verticalschool_7_floor14",
  "refpalette": "deceasedcraft:multi_verticalschool_7/multi_verticalschool_7_floor14_palette",
  "xsize": 16,
  "zsize": 16,
  "slices": [
    [
      " aaaaaaaaaaa    ",
      " abbbba    a    ",
      " ac  da    a    ",
      " ac  da    a    ",
      " ae  da    a    ",
      " aa  aaa  aa    ",
      "   ff   ff      ",
      "                ",
      "                ",
      "       g  h     ",
      "aaaaaaaiaaia    ",
      "jaklm   an a    ",
      "oaklm   ap a    ",
      " akkq   ar a    ",
      " akk    ar a    ",
      "aaaaaaaaaaaaaaas"
    ],
    [
      " aaaaaaaaaaa    ",
      " abbbba    a    ",
      " ac  da    a    ",
      " ac  da    a    ",
      " ae  da    a    ",
      " aaaaaaaaaaa    ",
      "                ",
      "                ",
      "                ",
      "                ",
      "aaaaaaaaaaaa    ",
      "ta  lm uan a    ",
      "wa  lm  ax a    ",
      " a  y   a  a    ",
      " a      ar a    ",
      "aaaaaaaaaaaaaaaa"
    ],
    [
      " aaaaaaaaaaa    ",
      " abbbba    a    ",
      " aAAAAa    a    ",
      " aABBAa    a    ",
      " aAAAAa    a    ",
      " aaaaaaaaaaa    ",
      "                ",
      "                ",
      "                ",
      "                ",
      "aaaaaaaaaaaa    ",
      " a   lmCan a    ",
      "Da  ElmCax a    ",
      " a   yCCaF a    ",
      " a    CCar a    ",
      "aaaaaaaaaaaaaaaa"
    ],
    [
      " aaaaaaaaaaa    ",
      " abbbba    a    ",
      " abbbba    a    ",
      " abbbba    a    ",
      " abbbba    a    ",
      " aaaaaaaaaaa    ",
      "                ",
      "                ",
      "                ",
      "                ",
      "aaaaaaaaaaaa    ",
      " a    kkan a    ",
      " a   Ekkap a    ",
      " a   IJkar a    ",
      " a   IJkar a    ",
      "aaaaaaaaaaaaaaaa"
    ],
    [
      "Aaaaaaaaaaaa    ",
      "Aa    a    a    ",
      "Aa    a    a    ",
      "Aa    a    a    ",
      "Aa    a    a    ",
      "Aaaaaaaaaaaa    ",
      "AK         K    ",
      "AK         K    ",
      "AK         K    ",
      "AK         K    ",
      "aaaaaaaaaaaa    ",
      "La      a  a    ",
      "La   M  aN a    ",
      "La  IJ  a  a    ",
      "La  IJ  ar a    ",
      "aaaaaaaaaaaaaaaa"
    ],
    [
      "aaaaaaaaaaaa    ",
      "aa    a    a    ",
      "aa    a    a    ",
      "aa    a    a    ",
      "aa    a    a    ",
      "aaaaaaaaaaaa    ",
      "aa         a    ",
      "aa         a    ",
      "aa         a    ",
      "aa         a    ",
      "aaaaaaaaaaaa    ",
      "aaCC    a  a    ",
      "aaCCM   aO a    ",
      "aaCIJq  a  a    ",
      "aaCIJ   ar a    ",
      "aaaaaaaaaaaaaaaa"
    ]
  ]
}