{
  "name": "multi_verticalschool_7_floor20",
  "refpalette": "deceasedcraft:multi_verticalschool_7/multi_verticalschool_7_floor20_palette",
  "xsize": 16,
  "zsize": 16,
  "slices": [
    [
      " aaaaaaaaaaa    ",
      " a    a    a    ",
      " a    a    a    ",
      " a    a    a    ",
      " a    a    a    ",
      " aa  aaa  aa    ",
      "   bb   bb      ",
      "                ",
      "                ",
      "       c  d     ",
      " aaaaaaeaaea    ",
      " afgh   a  a    ",
      " afgh   ai a    ",
      " affj   ak a    ",
      " aff    ak a    ",
      " aaaaaaaaaaa    "
    ],
    [
      " aaaaaaaaaaa    ",
      " a    a    a    ",
      " a    a    a    ",
      " a    a    a    ",
      " a    a    a    ",
      " aaaaaaaaaaa    ",
      "                ",
      "                ",
      "                ",
      "                ",
      " aaaaaaaaaaa    ",
      " a  gh lam a    ",
      " a  gh  a  a    ",
      " a  n   a  a    ",
      " a      ak a    ",
      " aaaaaaaaaaa    "
    ],
    [
      "oaaaaaaaaaaa    ",
      "oa    a    a    ",
      "oa    a    a    ",
      "oa    a    a    ",
      "oa    a    a    ",
      "oaaaaaaaaaaa    ",
      "oapppppppppa    ",
      "oappqppprppa    ",
      "oappqppprppa    ",
      "oapppppppppa    ",
      "oaaaaaaaaaaa    ",
      "oa   ghsa  a    ",
      "oa  tghsau a    ",
      "oa   nssa  a    ",
      "oa    ssak a    ",
      "oaaaaaaaaaaa    "
    ],
    [
      "waaaaaaaaaaawx  ",
      "wa    a    awx  ",
      "wa    a    awx  ",
      "wa    a    awx  ",
      "wa    a    awx  ",
      "wy aaay aaaawx  ",
      "wwwwwwwwwwwwwxxx",
      "wwwwwwwwwwwwwwww",
      "wwwwwwwwwwwwwwww",
      "wwwwwwwwwwwwwxxx",
      "Aaaaaaaaaaaawx  ",
      "Aa    ffaBBawx  ",
      "Aa   tffaBBawx  ",
      "Aa   CDfaBBawx  ",
      "Aa   CDfaEFawx  ",
      "Aaaaaaaaaaaawx  "
    ],
    [
      " aaaaaaaaaaa I  ",
      " a    a    a I  ",
      " a    a    a I  ",
      " a    a    a I  ",
      " a    a    a I  ",
      " aaJJaaaJJaa I  ",
      "  KLM  KLM    NN",
      "                ",
      "                ",
      "  OPQ         RR",
      "SaaaaaaTaaUa I  ",
      " a      a  a I  ",
      " a   V  ai a I  ",
      " a  CD  a  a I  ",
      " a  CD  akWa I  ",
      " aaaaaaaaaaa I  "
    ],
    [
      " aaaaaaaaaaa    ",
      " a    a    a    ",
      " a    a    a    ",
      " a    a    a    ",
      " a    a    a    ",
      " aa  aaa  aa    ",
      "   XY   XY      ",
      "                ",
      "                ",
      "                ",
      " aaaaaaZaa0a    ",
      " ass    a  a    ",
      " assV   ai a    ",
      " asCDj  a1 a    ",
      " asCD   ak a    ",
      " aaaaaaaaaaa    "
    ]
  ]
}