{
  "name": "multi_verticalschool_7_floor7",
  "refpalette": "deceasedcraft:multi_verticalschool_7/multi_verticalschool_7_floor7_palette",
  "xsize": 16,
  "zsize": 16,
  "slices": [
    [
      " aaaaaaaaaaa    ",
      " a    a    a    ",
      " a    a    a    ",
      " a    a    a    ",
      " a    a    a    ",
      " aaaaaaaaaaa    ",
      " a         a    ",
      " a         a    ",
      " a         a    ",
      " a         a    ",
      " aaaaaaaaaaa    ",
      " abcd   a  a    ",
      " abcd   ae a    ",
      " abbf   a  a    ",
      " abb    ag a    ",
      " aaaaaaaaaaa    "
    ],
    [
      " aaaaaaaaaaa    ",
      " a    a    a    ",
      " a    a    a    ",
      " a    a    a    ",
      " a    a    a    ",
      " aaaaaaaaaaa    ",
      " ahhiiiiiiia    ",
      " aiiiiiiiiia    ",
      " aiiiiiiiiia    ",
      " ajiiiiiiiia    ",
      " aaaaaaaaaaa    ",
      " a  cd  a  a    ",
      " a  cd  ak a    ",
      " a  l   a  a    ",
      " a      ag a    ",
      " aaaaaaaaaaa    "
    ],
    [
      "maaaaaaaaaaa    ",
      "ma    a    a    ",
      "ma    a    a    ",
      "ma    a    a    ",
      "ma    a    a    ",
      "maaaaaaaaaaa    ",
      "mannnnnnnnna    ",
      "mannonnnonna    ",
      "mannonnnonna    ",
      "mannnnnnnnna    ",
      "maaaaaaaaaaa    ",
      "ma   cdpa  a    ",
      "ma  qcdpak a    ",
      "ma   lppa  a    ",
      "ma    ppag a    ",
      "maaaaaaaaaaa    "
    ],
    [
      "aaaaaaaaaaaarrrr",
      "aa    a    arrrr",
      "aa    a    arrrr",
      "aa    a    arrrr",
      "aa    a    arrrr",
      "as aaas aaaarrrr",
      "nnnnnnnnnnnarrrr",
      "nnnnnnnnnnnarrrr",
      "nnnnnnnnnnnarrrr",
      "nnnnnnnnnnnarrrr",
      "aaaaaaaaaaaarrrr",
      "aa    bbattarrrr",
      "aa   qbbattarrrr",
      "aa   uwbattarrrr",
      "aa   uwbaxyarrrr",
      "aaaaaaaaaaaarrrr"
    ],
    [
      "aaaaaaaaaaaa   A",
      "aa    a    a   A",
      "aa    a    a   A",
      "aa    a    a   A",
      "aa    a    a   A",
      "aaaBBaaaBBaa   A",
      "  CDE  CDE     A",
      "               A",
      "               A",
      "               A",
      "aaaaaaaFaaIa   A",
      "aa      aJ a   A",
      "aa   K  aL a   A",
      "aa  uw  a  a   A",
      "aa  uw  agMa   A",
      "aaaaaaaaaaaa   A"
    ],
    [
      "aaaaaaaaaaaa    ",
      "aa    a    a    ",
      "aa    a    a    ",
      "aa    a    a    ",
      "aa    a    a    ",
      "aaa  aaa  aa    ",
      "   NO   NO      ",
      "                ",
      "                ",
      "                ",
      "aaaaaaaPaaQa    ",
      "aapp    aJ a    ",
      "aappK   aL a    ",
      "aapuwf  aR a    ",
      "aapuw   ag a    ",
      "aaaaaaaaaaaa    "
    ]
  ]
}