{
  "name": "multi_verticalschool_7_floor13",
  "refpalette": "deceasedcraft:multi_verticalschool_7/multi_verticalschool_7_floor13_palette",
  "xsize": 16,
  "zsize": 16,
  "slices": [
    [
      "  aaaaaaaaa     ",
      " a    a    a    ",
      "ba    a    ac   ",
      "da    a    ac   ",
      " a    a    ac   ",
      " aaaaaaaaaaa    ",
      " a              ",
      " a              ",
      " a              ",
      " a              ",
      " aaaaaaaaaaa    ",
      " aefg   a  ac   ",
      " aefg   ah ac   ",
      " aeei   a  ac   ",
      " aee    aj a    ",
      "  aaaaaaaaa     "
    ],
    [
      "  aaaaaaaaa     ",
      "ba    a    a    ",
      "da    a    ak   ",
      " a    a    ak   ",
      " a    a    ak   ",
      " aaaaaaaaaaa    ",
      " a         l    ",
      " a         l    ",
      " a         l    ",
      " a         l    ",
      " aaaaaaaaaaa    ",
      " a  fg  a  ak   ",
      " a  fg  ah ak   ",
      " a  m   a  ak   ",
      " a      aj a    ",
      "  aaaaaaaaa     "
    ],
    [
      "blaaaaaaaaalllll",
      "da    a    allll",
      " a    a    allll",
      " a    a    allll",
      " a    a    allll",
      " anaaaaaaaaallll",
      "laoooooooooallll",
      "laoopooopooallll",
      "laoopooopooallll",
      "laoooooooooallll",
      "laaaaaaaaaaallll",
      "la   fgqa  allll",
      "la  rfgqah allll",
      "la   mqqa  allll",
      "la    qqaj allll",
      "llaaaaaaaaalllll"
    ],
    [
      "saaaaaaaaaaatttt",
      " auuuua    atttt",
      " awwwwa    atttt",
      " awwwwa    atttt",
      " a wwwa    atttt",
      " a aaax aaaatttt",
      "tttttttttttttttt",
      "tttttttttttttttt",
      "tttttttttttttttt",
      "tttttttttttttttt",
      "aaaaaaaaaaaatttt",
      "ya    eeaAAatttt",
      "ya   reeaAAatttt",
      "ya   BCeaAAatttt",
      "ya   BCeaDEatttt",
      "aaaaaaaaaaaaaaaa"
    ],
    [
      " aaaaaaaaaaaFFF ",
      " auuuua    aIJ  ",
      " aK  La    a    ",
      " aK  La    aMM  ",
      " aN  La    a    ",
      "OaaPPaaaPPaaQR  ",
      "  STU  STU      ",
      "                ",
      "                ",
      "                ",
      "aaaaaaaVaaWaIJ  ",
      "Xa      aY a    ",
      "Xa   Z  a0 aMM  ",
      " a  BC  a  a    ",
      "1a  BC  aj2aQR  ",
      "aaaaaaaaaaaaaaa3"
    ],
    [
      " aaaaaaaaaaa444 ",
      " auuuua    a    ",
      " aK  La    a    ",
      " aK  La    a    ",
      " a5  La    a    ",
      " aa  aaa  aa    ",
      "   67   67      ",
      "                ",
      "                ",
      "                ",
      "aaaaaaa8aa9a    ",
      "#aqq    aY a    ",
      "$aqqZ   a0 a    ",
      " aqBCi  a% a    ",
      "^aqBC   aj a    ",
      "aaaaaaaaaaaaaaa&"
    ]
  ]
}