{
  "name": "multi_verticalschool_7_floor15",
  "refpalette": "deceasedcraft:multi_verticalschool_7/multi_verticalschool_7_floor15_palette",
  "xsize": 16,
  "zsize": 16,
  "slices": [
    [
      "aaaaaaaaaaaa    ",
      "aa    a    a    ",
      "aa    a    a    ",
      "aa    a    a    ",
      "aa    a    a    ",
      "aaaaaaaaaaaa    ",
      "aa         a    ",
      "aa         a    ",
      "aa         a    ",
      "aa         a    ",
      "aaaaaaaaaaaa    ",
      "aabcd   a  a    ",
      "aabcd   ae a    ",
      "aabbf   a  a    ",
      "aabb    ag a    ",
      "aaaaaaaaaaaaaaaa"
    ],
    [
      "aaaaaaaaaaaa    ",
      "aa    a    a    ",
      "aa    a    a    ",
      "aa    a    a    ",
      "aa    a    a    ",
      "aaaaaaaaaaaa    ",
      "aahhhiiiiija    ",
      "aahhhhiiiiha    ",
      "aahhhhiiiiha    ",
      "aahhhiiiiiia    ",
      "aaaaaaaaaaaa    ",
      "aa  cd  a  a    ",
      "aa  cd  ak a    ",
      "aa  l   a  a    ",
      "aa      ag a    ",
      "aaaaaaaaaaaaaaaa"
    ],
    [
      "aaaaaaaaaaaamnnn",
      "aa    a    amnnn",
      "aa    a    amnnn",
      "aa    a    amnnn",
      "aa    a    amnnn",
      "aaaaaaaaaaaamnnn",
      "aaoooooooooamnnn",
      "aaoopooopooamnnn",
      "aaoopooopooamnnn",
      "aaoooooooooamnnn",
      "aaaaaaaaaaaamnnn",
      "aa   cdqa  amnnn",
      "aa  rcdqak amnnn",
      "aa   lqqa  amnnn",
      "aa    qqag ammmm",
      "aaaaaaaaaaaaaaaa"
    ],
    [
      "oaaaaaaaaaaaooos",
      "oa    a    aooos",
      "oa    a    aooos",
      "oa    a    aooos",
      "oa    a    aooos",
      "ot aaat aaaaoooo",
      "oooooooooooooooo",
      "oooooooooooooooo",
      "oooooooooooooooo",
      "oooooooooooooooo",
      "oaaaaaaaaaaaoooo",
      "oa    bbauuaooos",
      "oa   rbbauuaooos",
      "oa   wxbauuaooos",
      "oa   wxbayAaooos",
      "oaaaaaaaaaaaooos"
    ],
    [
      " aaaaaaaaaaa  BC",
      " a    a    a  BC",
      " a    a    a  BC",
      " a    a    a  BC",
      " a    a    a  BC",
      " aaDDaaaDDaa   E",
      "  FIJ  FIJ      ",
      "                ",
      "                ",
      "                ",
      " aaaaaaKaaLa   M",
      " a      aN a  BC",
      " a   O  aP a  BC",
      " a  wx  a  a  BC",
      " a  wx  agQa  BC",
      " aaaaaaaaaaa  BC"
    ],
    [
      " aaaaaaaaaaa    ",
      " a    a    a   R",
      " a    a    a   S",
      " a    a    a    ",
      " a    a    a   S",
      " aa  aaa  aa    ",
      "   TU   TU      ",
      "                ",
      "                ",
      "                ",
      " aaaaaaVaaWa    ",
      " aqq    aN a    ",
      " aqqO   aP a   X",
      " aqwxf  aY a   Z",
      " aqwx   ag a   S",
      " aaaaaaaaaaa   S"
    ]
  ]
}