{
  "name": "multi_verticalschool_7_floor30",
  "refpalette": "deceasedcraft:multi_verticalschool_7/multi_verticalschool_7_floor30_palette",
  "xsize": 16,
  "zsize": 16,
  "slices": [
    [
      "abbbbbbbbbbccccc",
      "ab    b    bcccc",
      "ab    b    bcccc",
      "ab    b    bbbbb",
      "ab    b    baaaa",
      "ab bbbd bbbbaaaa",
      "abeeeeeeeeeeeeee",
      "abeeeeeeeeeeeeee",
      "abeeeeeeeeeeeeee",
      "abeeeeeeeeeeeeee",
      "abbbbbbbbbbbaaaa",
      "abffg   bhhbaaaa",
      "abffg   bhhbbbbb",
      "abffi   bhhbcccc",
      "abff    bjkbcccc",
      "abbbbbbbbbbccccc"
    ],
    [
      " bbbbbbbbbb     ",
      " b    b    b@@@@",
      " b    b    bllll",
      " b    b    beeee",
      " b    b    bmmmm",
      " bbnnbbbnnbb    ",
      " bopq  opq      ",
      " b              ",
      " b              ",
      " b              ",
      " brbbbbbbbsb    ",
      " b      bt buuwu",
      " b      b  beeee",
      " b      b  bllll",
      " b      bxyb@@@@",
      " bbbbbbbbbb     "
    ],
    [
      " bbbbbbbbbbAAAAA",
      " b    b    beeee",
      " b    b    beeee",
      " b    b    beeee",
      " b    b    b  B ",
      " bb  bbb  bb    ",
      " b CD   CD      ",
      " b              ",
      " b              ",
      " b              ",
      " bEbbbbbbbFb    ",
      " b      bt bI J ",
      " b      b  beeee",
      " b      b  beeee",
      " b      bx beeee",
      " bbbbbbbbbbAAAAA"
    ],
    [
      " bbbbbbbbbbyyyyy",
      " b    b    bKLLL",
      " b    b    beeee",
      " b    b    beeee",
      " b    b    bMMMM",
      " bb  bbb  bbNNNN",
      " b OO   OO      ",
      " b              ",
      " b              ",
      " bP       Q     ",
      " bRbbbbbbbRbNNNN",
      " b      bt bMMMM",
      " b      b  beeee",
      " b      b  beeee",
      " b      bx bSTTT",
      " bbbbbbbbbbUUUUU"
    ],
    [
      " bbbbbbbbbb     ",
      " b    b    b    ",
      " b    b    b    ",
      " b    b    bKLLL",
      " b    b    beeee",
      " bbbbbbbbbbbbbbb",
      " b              ",
      " b              ",
      " b              ",
      " b              ",
      " bbbbbbbbbbbbbbb",
      " bV     bt beeee",
      " b      b  bSTTT",
      " b      b  b    ",
      " b      bx b    ",
      " bbbbbbbbbb     "
    ],
    [
      " bbbbbbbbbb     ",
      " b    b    b    ",
      " b    b    b    ",
      " b    b    b    ",
      " b    b    b    ",
      " bbbbbbbbbbbbbbb",
      " b              ",
      " b              ",
      " b              ",
      " b              ",
      " bbbbbbbbbbbbbbb",
      " bhhhhhhbt b    ",
      " bhhhhhhb  b    ",
      " bhhhhhhb  b    ",
      " bhhhhhhbx b    ",
      " bbbbbbbbbb     "
    ]
  ]
}