{
  "name": "multi_verticalschool_7_floor4",
  "refpalette": "deceasedcraft:multi_verticalschool_7/multi_verticalschool_7_floor4_palette",
  "xsize": 16,
  "zsize": 16,
  "slices": [
    [
      " aaaaaaaaaaa    ",
      " a    a    ab   ",
      " a    a    ac   ",
      " a    a    a    ",
      " a    a    adde ",
      " a aaaf aaaaghi ",
      " jkkkkkkkkkaghil",
      " jkkkkkkkkkaghi ",
      " jkkkkkkkkkaghil",
      " jkkkkkkkkkaghil",
      " aaaaaaaaaaaghi ",
      " amno   appadde ",
      " amno   appa    ",
      " ammq   appab   ",
      " amm    arsac   ",
      " aaaaaaaaaaa    "
    ],
    [
      " aaaaaaaaaaa    ",
      " a    a    a    ",
      " a    a    a    ",
      " a    a    a    ",
      " a    a    at   ",
      " aauuaaauuaa    ",
      "  wxy  wxy A    ",
      "           A    ",
      "           A    ",
      "           A    ",
      " aBaaaaaaaCa    ",
      " a  no  a  aD   ",
      " a  no  aE a    ",
      " a  F   a  a    ",
      " a      aI a    ",
      " aaaaaaaaaaa    "
    ],
    [
      " aaaaaaaaaaa    ",
      " a    a    a    ",
      " a    a    a    ",
      " a    a    a    ",
      " a    a    a    ",
      " aa  aaa  aa    ",
      "   JK   JK A    ",
      "           A    ",
      "           A    ",
      "           A    ",
      " aLaaaaaaaMa    ",
      " a   noNa  a    ",
      " a  OnoNaE a    ",
      " a   FNNaP a    ",
      " a    NNaI a    ",
      " aaaaaaaaaaa    "
    ],
    [
      " aaaaaaaaaaa    ",
      " a    a    a    ",
      " a    a    a    ",
      " a    a    a    ",
      " a    a    a    ",
      " aa  aaa  aa    ",
      "   QQ   QQ A    ",
      "           A    ",
      "           A    ",
      "  R       SA    ",
      " aTaaaaaaaTa    ",
      " a    mma  a    ",
      " a   OmmaE a    ",
      " a   UVmaI a    ",
      " a   UVmaI a    ",
      " aaaaaaaaaaa    "
    ],
    [
      " aaaaaaaaaaa    ",
      " a    a    a    ",
      " a    a    a    ",
      " a    a    a    ",
      " a    a    a    ",
      " aaaaaaaaaaa    ",
      "           A    ",
      "           A    ",
      "           A    ",
      "           A    ",
      " aaaaaaaaaaa    ",
      " aW     aX a    ",
      " a   Y  aZ a    ",
      " a  UV  a  a    ",
      " a  UV  aI a    ",
      " aaaaaaaaaaa    "
    ],
    [
      "0aaaaaaaaaaa0112",
      "0a    a    a0112",
      "0a    a    a0112",
      "0a    a    a0112",
      "0a    a    a0112",
      "0aaaaaaaaaaa0112",
      "0111011101110112",
      "0111011101110112",
      "0111011101110112",
      "0111011101110112",
      "0aaaaaaaaaaa0112",
      "0aNN    a  a0112",
      "0aNNY   a3 a0112",
      "0aNUVq  a  a0112",
      "0aNUV   aI a0112",
      "0aaaaaaaaaaa0112"
    ]
  ]
}