{
  "name": "multi_verticalschool_7_floor29",
  "refpalette": "deceasedcraft:multi_verticalschool_7/multi_verticalschool_7_floor29_palette",
  "xsize": 16,
  "zsize": 16,
  "slices": [
    [
      "abbbbbbbbbbbcccc",
      "ab    b    bcccc",
      "ab    b    bcccc",
      "ab    b    bcccc",
      "ab    b    bcccc",
      "ad bbbd bbbbcccc",
      "accccccccccccccc",
      "accccccccccccccc",
      "accccccccccccccc",
      "accccccccccccccc",
      "abbbbbbbbbbbcccc",
      "abefg   bhhbcccc",
      "abefg   bhhbcccc",
      "abeei   bhhbcccc",
      "abee    bjkbcccc",
      "abbbbbbbbbbbcccc"
    ],
    [
      "lbbbbbbbbbbb    ",
      "lb    b    b    ",
      "lb    b    b    ",
      "lb    b    b    ",
      "lb    b    b    ",
      "lbbmmbbbmmbb    ",
      "lnopq  opq      ",
      "l               ",
      "l               ",
      "ln              ",
      "lbrbbbbbbbsb    ",
      "lb  fg  b  b    ",
      "lb  fg  bt b    ",
      "lb  u   b  b    ",
      "lb      bwxb    ",
      "lbbbbbbbbbbb    "
    ],
    [
      " bbbbbbbbbbb    ",
      " b    b    b    ",
      " b    b    b    ",
      " b    b    b    ",
      " b    b    b    ",
      " bb  bbb  bb    ",
      "   yA   yA      ",
      "                ",
      "                ",
      "                ",
      " bBbbbbbbbCb    ",
      " b   fgDb  b    ",
      " b  EfgDbt b    ",
      " b   uDDbF b    ",
      " b    DDbw b    ",
      " bbbbbbbbbbb    "
    ],
    [
      " bbbbbbbbbbb    ",
      " b    b    b    ",
      " b    b    b    ",
      " b    b    b    ",
      " b    b    b    ",
      " bb  bbb  bb    ",
      "   II   II      ",
      "                ",
      "                ",
      "  J       K     ",
      " bLbbbbbbbLb    ",
      " b    eeb  b    ",
      " b   Eeebt b    ",
      " b   MNebw b    ",
      " b   MNebw b    ",
      " bbbbbbbbbbb    "
    ],
    [
      " bbbbbbbbbbb    ",
      " b    b    b    ",
      " b    b    b    ",
      " b    b    b    ",
      " b    b    b    ",
      " bbbbbbbbbbb    ",
      "                ",
      "                ",
      "                ",
      "                ",
      " bbbbbbbbbbb    ",
      " bO     bP b    ",
      " b   Q  b  b    ",
      " b  MN  b  b    ",
      " b  MN  bw b    ",
      " bbbbbbbbbbb    "
    ],
    [
      "RbbbbbbbbbbbSTTS",
      "Rb    b    bSSSS",
      "Rb    b    bSSSS",
      "Rb    b    bSSSS",
      "Rb    b    bSSSS",
      "RbbbbbbbbbbbSUUS",
      "RbVVVVVVVVVbSSSS",
      "RbVVWVVVXVVbSSSS",
      "RbVVWVVVXVVbSSSS",
      "RbVVVVVVVVVbSSSS",
      "RbbbbbbbbbbbSUUS",
      "RbDD    b  bSSSS",
      "RbDDQ   bY bSSSS",
      "RbDMNi  b  bSSSS",
      "RbDMN   bw bSSSS",
      "RbbbbbbbbbbbSTTS"
    ]
  ]
}