{
  "name": "multi_verticalschool_7_floor10",
  "refpalette": "deceasedcraft:multi_verticalschool_7/multi_verticalschool_7_floor10_palette",
  "xsize": 16,
  "zsize": 16,
  "slices": [
    [
      "  aaaaaaaaaabccc",
      " a    a    a    ",
      " a    a    a d  ",
      " a    a    aefg ",
      " a    a    a h  ",
      " a aaai aaaa h  ",
      " jkkkkkkkkka    ",
      " jkkkkkkkkka h  ",
      " jkkkkkkkkka h  ",
      " jkkkkkkkkkal m ",
      " aaaaaaaaaaa h  ",
      " anop   aqqa h  ",
      " anop   aqqal m ",
      " annr   aqqa h  ",
      " ann    asta h  ",
      "  aaaaaaaaaa u  "
    ],
    [
      "  aaaaaaaaawwxxx",
      " a    a    abyyy",
      " a    a    ayyyy",
      " a    a    ayAyy",
      " a    a    ay yy",
      " aaBBaaaBBaay yy",
      "  CDE  CDE ayFyy",
      "           ay yy",
      "           ay yy",
      "           ay yy",
      " aIaaaaaaaJay yy",
      " a  op  aK ay yy",
      " a  op  aL ay yy",
      " a  M   a  ay yy",
      " a      aNOay yy",
      "  aaaaaaaaaayPyy"
    ],
    [
      "  aaaaaaaaa QaRR",
      " a    a    aaP  ",
      " a    a    a P  ",
      " a    a    a S  ",
      " a    a    a P  ",
      " aa  aaa  aa P  ",
      "   TU   TU a P  ",
      "           a P  ",
      "           a P  ",
      "           a P  ",
      " aVaaaaaaaWa P  ",
      " a   opXaK a P  ",
      " a  YopXaL a P  ",
      " a   MXXaZ a P  ",
      " a    XXaN a P  ",
      "  aaaaaaaaaa P  "
    ],
    [
      "  aaaaaaaaa 0122",
      " a    a    a0122",
      " a    a    a0122",
      " a    a    a0122",
      " a    a    a0122",
      " aa  aaa  aa0122",
      "   33   33 a0122",
      "           a0122",
      "           a0122",
      "  4       5a0122",
      " a6aaaaaaa6a0122",
      " a    nnaK a0122",
      " a   Ynna7 a0122",
      " a   89naN a0122",
      " a   89naN a0122",
      "  aaaaaaaaaa0a22"
    ],
    [
      "  aaaaaaaaa #1  ",
      " a    a    a#1  ",
      " a    a    a#1  ",
      " a    a    a#1  ",
      " a    a    a#1  ",
      " aaaaaaaaaaa#1$ ",
      "           a#1% ",
      "           a#1^ ",
      "           a#1  ",
      "           a#1  ",
      " aaaaaaaaaaa#1  ",
      " a&     aK a#1  ",
      " a   *  aL a#1  ",
      " a  89  a  a#1  ",
      " a  89  aN a#1  ",
      "  aaaaaaaaaaaa  "
    ],
    [
      "  aaaaaaaaa  (  ",
      " a    a    a (  ",
      " a    a    a (  ",
      " a    a    a (  ",
      " a    a    a (  ",
      " aaaaaaaaaaa (  ",
      "           a (  ",
      "           a (  ",
      "           a (  ",
      "           a (  ",
      " aaaaaaaaaaa (  ",
      " aXX    aK a (  ",
      " aXX*   aL a (  ",
      " aX89r  aZ a (  ",
      " aX89   aN a (  ",
      "  aaaaaaaaa)aa  "
    ]
  ]
}