{
  "name": "multi_verticalschool_7_floor2",
  "refpalette": "deceasedcraft:multi_verticalschool_7/multi_verticalschool_7_floor2_palette",
  "xsize": 16,
  "zsize": 16,
  "slices": [
    [
      " aaaaaaaaaaa    ",
      " a    a    a    ",
      " a    a    a    ",
      " a    a    a    ",
      " a    a    a    ",
      " aaaaaaaaaaa    ",
      " a         a    ",
      " a         a    ",
      " a         a    ",
      " a         a    ",
      " aaaaaaaaaaa    ",
      " abcd   a  a    ",
      " abcd   ae a    ",
      " abbf   a  a    ",
      " abb    ag a    ",
      " aaaaaaaaaaa    "
    ],
    [
      " aaaaaaaaaaa    ",
      " a    a    a    ",
      " a    a    a    ",
      " a    a    a    ",
      " a    a    a    ",
      " aaaaaaaaaaa    ",
      " ahhhhhhhhia    ",
      " ahhhhhhhhha    ",
      " ahhhhhhhhha    ",
      " ahhhhhhhhja    ",
      " aaaaaaaaaaa    ",
      " a  cd  a  a    ",
      " a  cd  ae a    ",
      " a  k   a  a    ",
      " a      ag a    ",
      " aaaaaaaaaaa    "
    ],
    [
      "laaaaaaaaaaallll",
      "la    a    allll",
      "la    a    allll",
      "la    a    allll",
      "la    a    allll",
      "laaaaaaaaaaallll",
      "lammmmmmmmmallll",
      "lammnmmmnmmallll",
      "lammnmmmnmmallll",
      "lammmmmmmmmallll",
      "laaaaaaaaaaallll",
      "la   cdoa  allll",
      "la  pcdoae allll",
      "la   kooa  allll",
      "la    ooag allll",
      "laaaaaaaaaaallll"
    ],
    [
      "maaaaaaaaaaammmm",
      "ma    a    ammmm",
      "ma    a    ammmm",
      "ma    a    ammmm",
      "ma    a    ammmm",
      "mq aaaq aaaammmm",
      "mmmmmmmmmmmmmmmm",
      "mmmmmmmmmmmmmmmm",
      "mmmmmmmmmmmmmmmm",
      "mmmmmmmmmmmmmmmm",
      "maaaaaaaaaaammmm",
      "ma    bbarrammmm",
      "ma   pbbarrammmm",
      "ma   stbarrammmm",
      "ma   stbauwammmm",
      "maaaaaaaaaaammmm"
    ],
    [
      " aaaaaaaaaaa    ",
      " a    a    ax   ",
      " a    a    ax   ",
      " a    a    ax   ",
      " a    a    ax   ",
      " aayyaaayyaa    ",
      "  ABC  ABC      ",
      "                ",
      "                ",
      "                ",
      " aaaaaaDaaEa    ",
      " a      a  ax   ",
      " a   F  aI ax   ",
      " a  st  a  ax   ",
      " a  st  agJax   ",
      " aaaaaaaaaaa    "
    ],
    [
      " aaaaaaaaaaa    ",
      " a    a    a    ",
      " a    a    a    ",
      " a    a    a    ",
      " a    a    a    ",
      " aa  aaa  aa    ",
      "   KL   KL      ",
      "                ",
      "                ",
      "                ",
      " aaaaaaMaaNa    ",
      " aoo    a  a    ",
      " aooF   aI a    ",
      " aostf  aO a    ",
      " aost   ag a    ",
      " aaaaaaaaaaa    "
    ]
  ]
}