{
  "name": "multi_verticalschool_7_floor12",
  "refpalette": "deceasedcraft:multi_verticalschool_7/multi_verticalschool_7_floor12_palette",
  "xsize": 16,
  "zsize": 16,
  "slices": [
    [
      "  aaaaaaaaa  bc ",
      " a    a    a bc ",
      " a    a    a bc ",
      " a    a    a bc ",
      " a    a    a bc ",
      " a aaad aaaabbc ",
      " aeeeeeeeeeef   ",
      " aeeeeeeeeeef   ",
      " aeeeeeeeeeef   ",
      " aeeeeeeeeeef   ",
      " aaaaaaaaaaabbc ",
      " aghi   ajja bc ",
      " aghi   ajja bc ",
      " aggk   ajja bc ",
      " agg    alma bc ",
      "  aaaaaaaaa  bc "
    ],
    [
      "  aaaaaaaaa   n ",
      " a    a    a  n ",
      " a    a    a  n ",
      " a    a    a  n ",
      " a    a    a  n ",
      " aaooaaaooaabbn ",
      " apqr  pqr      ",
      " a              ",
      " a              ",
      " a      s       ",
      " ataaaaaaauabbn ",
      " a  hi  a  a  n ",
      " a  hi  aw a  n ",
      " a  x   a  a  n ",
      " a      ayAa  n ",
      "  aaaaaaaaa     "
    ],
    [
      "  aaaaaaaaa     ",
      " a    a    a    ",
      " a    a    a    ",
      " a    a    a    ",
      " a    a    a    ",
      " aa  aaa  aa    ",
      " a BC   BC      ",
      " a              ",
      " a              ",
      " a       s      ",
      " aDaaaaaaaEa    ",
      " a   hiFa  a    ",
      " a  IhiFaw a    ",
      " a   xFFaJ a    ",
      " a    FFay a    ",
      "  aaaaaaaaa     "
    ],
    [
      "  aaaaaaaaa     ",
      " a    a    a    ",
      " a    a    a    ",
      " a    a    a    ",
      " a    a    a    ",
      "Kaa  aaa  aaaaaa",
      "Ka LL   LL MKKKa",
      "Ka         MKKKa",
      "Ka         MKKKa",
      "KaN       sMKKKa",
      "KaOaaaaaaaOaKKKa",
      "Ka    gga  aKKKa",
      "Ka   Iggaw aKKKa",
      "Ka   PQgay aKKKa",
      "Ka   PQgay aKKKa",
      "KRaaaaaaaaaRKKKa"
    ],
    [
      "  aaaaaaaaa     ",
      " a    a    a    ",
      " a    a    a    ",
      " a    a    a    ",
      "Sa    a    aIIII",
      "eaaaaaaaaaaa   b",
      "ea         T   b",
      "ea         T U b",
      "ea         T U b",
      "ea           U b",
      "eaaaaaaaaaaa U b",
      "eaV     aW a U b",
      "ea   X  aY a U b",
      "ea  PQ  a  a U b",
      "ea  PQ  ay a U b",
      "eeaaaaaaaaaZZU b"
    ],
    [
      "  aaaaaaaaa     ",
      " a    a    a    ",
      " a    a    a    ",
      "Sa    a    a    ",
      "0a    a    a    ",
      " aaaaaaaaaaa    ",
      " a              ",
      " a              ",
      " a              ",
      " a              ",
      " aaaaaaaaaaa    ",
      " aFF    a  a    ",
      " aFFX   a1 a    ",
      " aFPQk  a  a    ",
      " aFPQ   ay a    ",
      " 2aaaaaaaaa     "
    ]
  ]
}