{
  "name": "multi_verticalschool_7_base2",
  "refpalette": "deceasedcraft:multi_verticalschool_7/multi_verticalschool_7_base2_palette",
  "xsize": 16,
  "zsize": 16,
  "slices": [
    [
      "vvvvvvvvvvvvvvvv",
      "vvvvvvvvvvvvvvvv",
      "vvvvvvvvvvvvvvvv",
      "vvvvvvvvvvvvvvvv",
      "vvvvvvvvvvvvvvvv",
      "vvvvvvvvvvvvvvvv",
      "vvvvvvvvvvvvvvvv",
      "vvvvvvvvvvvvvvvv",
      "vvvvvvvvvvvvvvvv",
      "vvvvvvvvvvvvvvvv",
      "vvvvvvvvvvvvvvvv",
      "vvvvvvvvvvvvvvvv",
      "vvvvvvvvvvvvvvvv",
      "vvvvvvvvvvvvvvvv",
      "vvvvvvvvvvvvvvvv",
      "vvvvvvvvvvvvvvvv"
    ],
    [
      "abbbaaaaaaaaaaaa",
      "aaaaaaaaaaaaaaaa",
      "aaaaaaaaaaaaaaaa",
      "aaaaaaaaaaaaaaaa",
      "aaaaaaaaaaaaaaaa",
      "aaaaaaaaaaaaaaaa",
      "aaaaaaaaaaaaaaaa",
      "aaaaaaaaaaaaaaaa",
      "aaaaaaaaaaaaaaaa",
      "aaaaaaaaaaaaaaaa",
      "aaaaaaaaaaaaaaaa",
      "aaaaaaaaaaaaaaaa",
      "aaaaaaaaaaaaaaaa",
      "aaaaaaaaaaaaaaaa",
      "aaaaaaaaaaaaaaaa",
      "abbbaaaaaaaaaaaa"
    ],
    [
      "abbbbbbbbbbbaaaa",
      "abccccbccccbaaaa",
      "abccccbccccbaaaa",
      "abccccbccccbaaaa",
      "abccccbccccbaaaa",
      "abbbbbbbbbbbaaaa",
      "aaaaaaaaaaaaaaaa",
      "aaaaaaaaaaaaaaaa",
      "aaaaaaaaaaaaaaaa",
      "aaaaaaaaaaaaaaaa",
      "aaaaaaaaaaaaaaaa",
      "aaaaaaaaaaaaaaaa",
      "aaaaaaaaaaaaaaaa",
      "aaaaaaaaaaaaaaaa",
      "aaaaaaaaaaaaaaaa",
      "abbbaaaaaaaaaaaa"
    ],
    [
      "bbbbbbbbbbbbddde",
      "fb    bggggbddde",
      "fb    bhhhhbddde",
      "fb    bhhhhbddde",
      "fb    b hhhbddde",
      "fi bbbi bbbbddde",
      "fbddddddddddddde",
      "fbddddddddddddde",
      "fbddddddddddddde",
      "fbddddddddddddde",
      "bbbbbbbbbbbbddde",
      "fbffffffbffbddde",
      "fbffffffbffbddde",
      "fbffffffbffbddde",
      "fbffffffbffbddde",
      "bbbbbbbbbbbbddde"
    ],
    [
      "bbbbbbbbbbbb   j",
      "kb    bggggb   j",
      "lb    bm  nb    ",
      "kb    bm  nb   j",
      " b    bo  nb   p",
      "qbbrrbbbrrbb   j",
      " bstu  stu     r",
      " w             r",
      " x             r",
      "yb             r",
      "bbbbbbbAbbbb   j",
      " wB     bCDb   p",
      " EF  I  b Jb   j",
      "KbfffL  b Jb    ",
      "MbfffL  b Db   j",
      "bbbbbbbxbNbb   j"
    ],
    [
      "bbbbbbbbbbbb   j",
      "lb    bggggb   j",
      " b    bm  nb    ",
      "Ob    bm  nb   j",
      " b    bP  nb   p",
      " bb  bbb  bb   j",
      " b QR   QR      ",
      " S              ",
      " T              ",
      "yb              ",
      "bbbbbbbUbbbb   j",
      " SV     bCDb   p",
      " WX I   b Yb   j",
      " bffLZ  b Yb    ",
      " bffL   b Db   j",
      "bbbbbbbTb0bb   j"
    ]
  ]
}