{
  "name": "multi_verticalschool_7_floor22",
  "refpalette": "deceasedcraft:multi_verticalschool_7/multi_verticalschool_7_floor22_palette",
  "xsize": 16,
  "zsize": 16,
  "slices": [
    [
      "aaaaaaaaaaaa    ",
      "aa    a    a    ",
      "aa    a    a    ",
      "aa    a    a    ",
      "aa    a    a    ",
      "aaa  aaa  aa    ",
      "ab cc   cc      ",
      "ab              ",
      "ab              ",
      "ab     d  e     ",
      "aaaaaaafaafa    ",
      "aaghi   aj a    ",
      "aaghi   ak a    ",
      "aaggl   am a    ",
      "aagg    am a    ",
      "aaaaaaaaaaaa    "
    ],
    [
      "aaaaaaaaaaaa    ",
      "aa    a    a    ",
      "aa    a    a    ",
      "aa    a    a    ",
      "aa    a    a    ",
      "aaaaaaaaaaaa    ",
      "an              ",
      "an              ",
      "an              ",
      "an              ",
      "aaaaaaaaaaaa    ",
      "aa  hi oaj a    ",
      "aa  hi  ap a    ",
      "aa  q   a  a    ",
      "aa      am a    ",
      "aaaaaaaaaaaa    "
    ],
    [
      "raaaaaaaaaaa    ",
      "sa    a    a    ",
      "sa    a    a    ",
      "sa    a    a    ",
      "sa    a    a    ",
      "saaaaaaaaaaa    ",
      "st              ",
      "st              ",
      "st              ",
      "st              ",
      "saaaaaaaaaaa    ",
      "sa   hiuaj a    ",
      "sa  whiuap a    ",
      "sa   quuax a    ",
      "sa    uuam a    ",
      "raaaaaaaaaaa    "
    ],
    [
      "!aaaaaaaaaaa    ",
      "ya    a    a    ",
      "Aa    a    a    ",
      "Ba    a    a    ",
      "Ca    a    a    ",
      " aaaaaaaaaaa    ",
      " uu             ",
      " uu             ",
      " uu             ",
      " uu             ",
      " aaaaaaaaaaa    ",
      "Aa    ggaj a    ",
      "Ba   wggak a    ",
      "Ca   DEgam a    ",
      "ya   DEgam a    ",
      "Faaaaaaaaaaa    "
    ],
    [
      "Iaaaaaaaaaaa    ",
      " a    a    a    ",
      " a    a    a    ",
      " a    a    a    ",
      " a    a    a    ",
      " aaaaaaaaaaa    ",
      "  Juu      K    ",
      "   uu      K    ",
      "   uu      K    ",
      "  Luu      K    ",
      " aaaaaaaaaaa    ",
      " a      aj a    ",
      " a   M  ap a    ",
      " a  DE  a  a    ",
      " a  DE  am a    ",
      "Iaaaaaaaaaaa    "
    ],
    [
      "Naaaaaaaaaaa    ",
      " a    a    a    ",
      " a    a    a    ",
      " a    a    a    ",
      " a    a    a    ",
      " aaaaaaaaaaa    ",
      "    Juu    a    ",
      "     uu    a    ",
      "     uu    a    ",
      "    Ouu    a    ",
      " aaaaaaaaaaa    ",
      " auu    aj a    ",
      " auuM   ap a    ",
      " auDEl  ax a    ",
      " auDE   am a    ",
      "Naaaaaaaaaaa    "
    ]
  ]
}