{
  "name": "multi_verticalschool_7_floor6",
  "refpalette": "deceasedcraft:multi_verticalschool_7/multi_verticalschool_7_floor6_palette",
  "xsize": 16,
  "zsize": 16,
  "slices": [
    [
      " aaaaaaaaaaa  ab",
      " a    a    a  ab",
      " a    a    a  ab",
      " a    a    a  ab",
      " a    a    a  ab",
      " aa  aaa  aa  ab",
      " c dd   dd    ab",
      " c            ab",
      " c            ab",
      " c     e  f   ab",
      " aaaaaagaaga  ab",
      " ahij   ak a  ab",
      " ahij   al a  ab",
      " ahhm   an a  ab",
      " ahh    an a  ab",
      " aaaaaaaaaaa  ab"
    ],
    [
      "oaaaaaaaaaaappab",
      "oa    a    appab",
      "oa    a    appab",
      "oa    a    appab",
      "oa    a    appab",
      "oaaaaaaaaaaappab",
      "oa         appab",
      "oa         appab",
      "oa         appab",
      "oa         appab",
      "oaaaaaaaaaaappab",
      "oa  ij qak appab",
      "oa  ij  ar appab",
      "oa  s   a  appab",
      "oa      an appab",
      "oaaaaaaaaaaappab"
    ],
    [
      "baaaaaaaaaaabbbb",
      "ba    a    abbbb",
      "ba    a    abbbb",
      "ba    a    abbbb",
      "ba    a    abbbb",
      "baaaaaaaaaaabbbb",
      "ba         abbbb",
      "ba         abbbb",
      "ba         abbbb",
      "ba         abbbb",
      "baaaaaaaaaaabbbb",
      "ba   ijtak abbbb",
      "ba  uijtar abbbb",
      "ba   sttaw abbbb",
      "ba    ttan abbbb",
      "baaaaaaaaaaabbbb"
    ],
    [
      " aaaaaaaaaaa   x",
      " a    a    a   x",
      " a    a    a   x",
      " a    a    a   x",
      " a    a    a   x",
      " aaaaaaaaaaa   x",
      " a         a   x",
      " a         a   x",
      " a         a   x",
      " a         a   x",
      " aaaaaaaaaaa   x",
      " a    hhak a   x",
      " a   uhhal a   x",
      " a   yAhan a   x",
      " a   yAhan a   x",
      " aaaaaaaaaaa   x"
    ],
    [
      " aaaaaaaaaaa    ",
      " a    a    a    ",
      " a    a    a    ",
      " a    a    a    ",
      " a    a    a    ",
      " aaaaaaaaaaa    ",
      " a         a    ",
      " a         a    ",
      " a         a    ",
      " a         a    ",
      " aaaaaaaaaaa    ",
      " a      a  a    ",
      " a   B  aC a    ",
      " a  yA  a  a    ",
      " a  yA  an a    ",
      " aaaaaaaaaaa    "
    ],
    [
      " aaaaaaaaaaa    ",
      " a    a    a    ",
      " a    a    a    ",
      " a    a    a    ",
      " a    a    a    ",
      " aaaaaaaaaaa    ",
      " a         a    ",
      " a         a    ",
      " a         a    ",
      " a         a    ",
      " aaaaaaaaaaa    ",
      " att    a  a    ",
      " attB   aD a    ",
      " atyAm  a  a    ",
      " atyA   an a    ",
      " aaaaaaaaaaa    "
    ]
  ]
}