{
  "name": "multi_verticalschool_7_top",
  "refpalette": "deceasedcraft:multi_verticalschool_7/multi_verticalschool_7_top_palette",
  "xsize": 16,
  "zsize": 16,
  "slices": [
    [
      "abcbbdddbbcb    ",
      "abe       eb    ",
      "abe       eb    ",
      "abe       eb    ",
      "abf       fb    ",
      "abg       gb    ",
      "abh       hb    ",
      "ab         b ij ",
      "ab         b kl ",
      "ab        mb    ",
      "abbbbbbbb bb    ",
      "ab         b    ",
      "ab         b    ",
      "ab         b    ",
      "ab  n    n b    ",
      "abbbndddbnbb    "
    ],
    [
      " bbbbbbbbbbb    ",
      " booooooooob    ",
      " booooooooob    ",
      " booooooooob    ",
      " booooooooob    ",
      " booooooooob    ",
      " booooooooob    ",
      " booooooooobi   ",
      " booooooooobk   ",
      " boooooooopb    ",
      " bbbbbbbbbbb    ",
      " booooooooob    ",
      " booooooooob    ",
      " booooooooob    ",
      " booooooonob    ",
      " bbbbbbbbbbb    "
    ],
    [
      " qqqqqqqqqqq    ",
      " q         q    ",
      " q  rsssr  q    ",
      " q  stuws  q    ",
      " q  sxyAs  q    ",
      " q  sBCDs  q    ",
      " q  rsssr  q    ",
      " q         j    ",
      " q         l    ",
      " q         q    ",
      " qqqqqqqqqqq    ",
      " q         q    ",
      " q         q    ",
      " q         q    ",
      " q EEEEEEE q    ",
      " qqqqqqqqqqq    "
    ],
    [
      "                ",
      "                ",
      "    F   F       ",
      "     IJK        ",
      "     LMN        ",
      "     OPQ        ",
      "    F   F       ",
      "                ",
      "                ",
      "                ",
      "                ",
      "                ",
      "                ",
      "                ",
      "   EEEEEEE      ",
      "                "
    ],
    [
      "                ",
      "                ",
      "                ",
      "     RST        ",
      "     UVW        ",
      "     XYZ        ",
      "                ",
      "                ",
      "                ",
      "                ",
      "                ",
      "                ",
      "                ",
      "                ",
      "   0000000      ",
      "                "
    ],
    [
      "                ",
      "                ",
      "                ",
      "                ",
      "                ",
      "                ",
      "                ",
      "                ",
      "                ",
      "                ",
      "                ",
      "                ",
      "                ",
      "                ",
      "                ",
      "                "
    ]
  ]
}