{
  "name": "multi_verticalschool_7_floor18",
  "refpalette": "deceasedcraft:multi_verticalschool_7/multi_verticalschool_7_floor18_palette",
  "xsize": 16,
  "zsize": 16,
  "slices": [
    [
      " aaaaaaaaaaa    ",
      " a    a    a    ",
      " a    a    a    ",
      " a    a    a    ",
      " a    a    a    ",
      " aa  aaa  aa    ",
      "   bb   bb      ",
      "                ",
      "                ",
      "       c  d     ",
      " aaaaaaeaaea    ",
      " afgh   a  a    ",
      " afgh   ai a    ",
      " affj   ak a    ",
      " aff    ak a    ",
      " aaaaaaaaaaa    "
    ],
    [
      " aaaaaaaaaaa    ",
      " a    a    a    ",
      " a    a    a    ",
      " a    a    a    ",
      " a    a    a    ",
      " aaaaaaaaaaa    ",
      "                ",
      "                ",
      "                ",
      "                ",
      " aaaaaaaaaaa    ",
      " a  gh lam a    ",
      " a  gh  an a    ",
      " a  o   a  a    ",
      " a      ak a    ",
      " aaaaaaaaaaa    "
    ],
    [
      "paaaaaaaaaaa    ",
      "pa    a    a    ",
      "pa    a    a    ",
      "pa    a    a    ",
      "pa    a    a    ",
      "paaaaaaaaaaa    ",
      "paqqqqqqqqqa    ",
      "paqqrqqqrqqa    ",
      "paqqrqqqrqqa    ",
      "paqqqqqqqqqa    ",
      "paaaaaaaaaaa    ",
      "pa   ghsa  a    ",
      "pa  tghsau a    ",
      "pa   ossa  a    ",
      "pa    ssak a    ",
      "paaaaaaaaaaa    "
    ],
    [
      "waaaaaaaaaaawx  ",
      "wa    a    awx  ",
      "wa    a    awx  ",
      "wa    a    awx  ",
      "wa    a    awx  ",
      "wy aaay aaaawx  ",
      "wwwwwwwwwwwwwxxx",
      "wwwwwwwwwwwwwwww",
      "wwwwwwwwwwwwwwww",
      "wwwwwwwwwwwwwxxx",
      "Aaaaaaaaaaaawx  ",
      "Aa    ffaBBawx  ",
      "Aa   tffaBBawx  ",
      "Aa   CDfaBBawx  ",
      "Aa   CDfaEFawx  ",
      "Aaaaaaaaaaaawx  "
    ],
    [
      " aaaaaaaaaaa I  ",
      " a    a    a I  ",
      " a    a    a I  ",
      " a    a    a I  ",
      " a    a    a I  ",
      " aaJJaaaJJaa I  ",
      "  KLM  KLM    NN",
      "                ",
      "                ",
      "  OPQ         RR",
      "SaaaaaaTaaUa I  ",
      " a      aV a I  ",
      " a   W  aX a I  ",
      " a  CD  aY a I  ",
      " a  CD  akZa I  ",
      " aaaaaaaaaaa I  "
    ],
    [
      " aaaaaaaaaaa    ",
      " a    a    a    ",
      " a    a    a    ",
      " a    a    a    ",
      " a    a    a    ",
      " aa  aaa  aa    ",
      "   01   01      ",
      "                ",
      "                ",
      "                ",
      " aaaaaa2aa3a    ",
      " ass    a  a    ",
      " assW   a45a    ",
      " asCDj  a6 a    ",
      " asCD   ak a    ",
      " aaaaaaaaaaa    "
    ]
  ]
}