{
  "name": "multi_verticalschool_7_floor23",
  "refpalette": "deceasedcraft:multi_verticalschool_7/multi_verticalschool_7_floor23_palette",
  "xsize": 16,
  "zsize": 16,
  "slices": [
    [
      " aaaaaaaaaaa    ",
      " a    a    a    ",
      " a    a    a    ",
      " a    a    a    ",
      " a    a    a    ",
      " aaaaaaaaaaa    ",
      "      bcc  a    ",
      "       cc  a    ",
      "       cc  a    ",
      "      dcc  a    ",
      " aaaaaaaaaaa    ",
      " aefg   ah a    ",
      " aefg   ai a    ",
      " aeej   ak a    ",
      " aee    ak a    ",
      " aaaaaaaaaaa    "
    ],
    [
      "laaaaaaaaaaammmm",
      "la    a    ammmm",
      "la    a    ammmm",
      "la    a    ammmm",
      "la    a    ammmm",
      "laaaaaaaaaaammmm",
      "l       nccommmm",
      "l        ccommmm",
      "l        ccommmm",
      "l       pccommmm",
      "laaaaaaaaaaammmm",
      "la  fg  a  ammmm",
      "la  fg  aq ammmm",
      "la  r   a  ammmm",
      "la      ak ammmm",
      "laaaaaaaaaaammmm"
    ],
    [
      "saaaaaaaaaaatttu",
      "sa    a    atttu",
      "sa    a    atttt",
      "sa    a    atttt",
      "sa    a    atttt",
      "saaaaaaaaaaawttt",
      "sa        bcxttt",
      "sa         cxttt",
      "sa         cxttt",
      "sa        pcxttt",
      "saaaaaaaaaaawttt",
      "sa   fgca  ayttt",
      "sa  AfgcaB ayttt",
      "sa   rcca  ayytt",
      "sa    ccak ayytt",
      "saaaaaaaaaaayytt"
    ],
    [
      "Caaaaaaaaaaa    ",
      "Ca    a    a    ",
      "Ca    a    a    ",
      "Ca    a    a    ",
      "Ca    a    a    ",
      "CaaaaaaaaaaaD   ",
      "Co              ",
      "Co              ",
      "Co              ",
      "Co              ",
      "CaaaaaaaaaaaD   ",
      "Ca    eea  a    ",
      "Ca   AeeaE a    ",
      "Ca   xFea  aI   ",
      "Ca   xFeak aII  ",
      "CaaaaaaaaaaaJI  "
    ],
    [
      "Kaaaaaaaaaaa    ",
      "Ka    a    a    ",
      "Ka    a    a    ",
      " a    a    a    ",
      "Ka    a    a    ",
      "Kaaaaaaaaaaa    ",
      "K               ",
      "K               ",
      "K               ",
      "K               ",
      "Kaaaaaaaaaaa    ",
      "Ka      a  a    ",
      "Ka   L  aM a    ",
      " a  xF  a  a    ",
      "Ka  xF  ak a    ",
      "KaaaaaaaaaaaN   "
    ],
    [
      " aaaaaaaaaaa    ",
      " a    a    a    ",
      " a    a    a    ",
      " a    a    a    ",
      " a    a    a    ",
      " aaaaaaaaaaa    ",
      "                ",
      "  O             ",
      "                ",
      "          P     ",
      " aaaaaaaaaaa    ",
      " acc    a  a    ",
      " accL   aM a    ",
      " acxFj  a  a    ",
      " acxF   ak a    ",
      " aaaaaaaaaaa    "
    ]
  ]
}