{
  "name": "multi_verticalschool_7_floor8",
  "refpalette": "deceasedcraft:multi_verticalschool_7/multi_verticalschool_7_floor8_palette",
  "xsize": 16,
  "zsize": 16,
  "slices": [
    [
      "aaaaaaaaaaaa    ",
      "aa    a    a    ",
      "aa    a    a    ",
      "aa    a    a    ",
      "aa    a    a    ",
      "aaa  aaa  aa    ",
      "   bb   bb      ",
      "                ",
      "                ",
      "       c  d     ",
      "aaaaaaaeaaea    ",
      "aafgh   ai a    ",
      "aafgh   aj a    ",
      "aaffk   al a    ",
      "aaff    al a    ",
      "aaaaaaaaaaaa    "
    ],
    [
      "aaaaaaaaaaaa  ma",
      "aa    a    a  ma",
      "aa    a    a  ma",
      "aa    a    a  ma",
      "aa    a    a  ma",
      "aaaaaaaaaaaa  ma",
      "na         a  ma",
      "na         a  ma",
      "na         a  ma",
      "na         a  ma",
      "aaaaaaaaaaaa  ma",
      "aa  gh oai a  ma",
      "aa  gh  ap a  ma",
      "aa  q   a  a  ma",
      "aa      al a  ma",
      "aaaaaaaaaaaa  ma"
    ],
    [
      "rraaaaaaaaaanass",
      "ra    a    anass",
      "ra    a    anass",
      "aa    a    anass",
      "aa    a    anass",
      "aaaaaaaaaaaanass",
      "aa         anass",
      "aa         anass",
      "aa         anass",
      "aa         anass",
      "aaaaaaaaaaaanass",
      "aa   ghtai anass",
      "aa  ughtap anass",
      "aa   qttaw anass",
      "aa    ttal anass",
      "aaaaaaaaaaaanass"
    ],
    [
      "  aaaaaaaaaasssx",
      " a    a    asssy",
      " a    a    asss ",
      "aa    a    asssy",
      "aa    a    asss ",
      "aaaaaaaaaaaasssy",
      "aa         assA ",
      "aa         assA ",
      "aa         assA ",
      "aa         assy ",
      "aaaaaaaaaaaass  ",
      "aa    ffai assy ",
      "aa   uffaj ass  ",
      "aa   BCfal assy ",
      "aa   BCfal ass  ",
      "aaaaaaaaaaaassy "
    ],
    [
      "  aaaaaaaaaaxxxx",
      " a    a    a y  ",
      " a    a    a    ",
      "aa    a    a y  ",
      "aa    a    a    ",
      "aaaaaaaaaaaa y  ",
      "aaDEEEEEEEEa    ",
      "aaEEEEEEEEEa    ",
      "aaEEEEEEEEEa    ",
      "aaFEEEEEEEEay   ",
      "aaaaaaaaaaaa    ",
      "aa      a  ay   ",
      "aa   I  a  a    ",
      "aa  BC  a  ay   ",
      "aa  BC  al a    ",
      "aaaaaaaaaaaay   "
    ],
    [
      "nmaaaaaaaaaaxxxx",
      "na    a    a    ",
      "ma    a    a    ",
      "aa    a    a    ",
      "aa    a    a    ",
      "aaaaaaaaaaaa    ",
      "aaJJJJJJJJJa    ",
      "aaJJKJJJKJJa    ",
      "aaJJKJJJKJJa    ",
      "aaJJJJJJJJJa    ",
      "aaaaaaaaaaaa    ",
      "aatt    a  a    ",
      "aattI   aL a    ",
      "aatBCk  a  a    ",
      "aatBC   al a    ",
      "aaaaaaaaaaaa    "
    ]
  ]
}