{
  "name": "multi_taigaresidence_4_floor7",
  "refpalette": "deceasedcraft:multi_taigaresidence_4/multi_taigaresidence_4_floor7_palette",
  "xsize": 16,
  "zsize": 16,
  "slices": [
    [
      "aaaaabccccccde  ",
      "fffgabhiiiiiijj ",
      "   kabhlllllie  ",
      "   kabhlllllie  ",
      "   kabhlllllie  ",
      "   kabhmllllijj ",
      "   kabhiiiiiie  ",
      "   kabhnnnnnhe  ",
      "   kabhnnnnnhe  ",
      "   kabhnnnnnie  ",
      "   kab  nnnnijj ",
      "   kaboiiiiiie  ",
      "   kabhhk   ie  ",
      "   kabhh    ie  ",
      "pppqabhiiiiiijj ",
      "aaaaabccccccde  "
    ],
    [
      "          m r   ",
      "ssss  iiiiiiijj ",
      "   s  t     i   ",
      "   s  i     u   ",
      "   s  i ww  i   ",
      "   s  imxw  ijj ",
      "   s  iiiiiii   ",
      "   s  iyyy  A   ",
      "   s  B     A   ",
      "   s  C    hi   ",
      "   s DiEFEIhijj ",
      "   s  iiiiiii   ",
      "   s  i     u   ",
      "   s  J     i   ",
      "ssss  iiiiiiijj ",
      "       KKKKKr   "
    ],
    [
      "            r   ",
      "      iiiiiiijj ",
      "      L     i   ",
      "      i         ",
      "      i   M i   ",
      "      imN O ijj ",
      "      iiiiiii   ",
      "      iyyy  A   ",
      "      P     A   ",
      "      Q    hi   ",
      "      iEEEIhijj ",
      "      iiiiiii   ",
      "      i         ",
      "      R     i   ",
      "      iiiiiiijj ",
      "         K Kr   "
    ],
    [
      "                ",
      "      iiiiiiijj ",
      "      S     i   ",
      "      i         ",
      "      i     i   ",
      "      imNw  ijj ",
      "      iiiiiii   ",
      "     Tiyyy  A   ",
      "      S     A   ",
      "      S    hi   ",
      "     UiEEEIhijj ",
      "      iiiiiii   ",
      "      i         ",
      "      S     i   ",
      "      iiiiiiijj ",
      "                "
    ],
    [
      "                ",
      "      iiiiiiijj ",
      "      i     i   ",
      "      i     i   ",
      "      i     i   ",
      "      imN   ijj ",
      "      iiiiiii   ",
      "      iyyy  A   ",
      "      i     A   ",
      "      i    hi   ",
      "      iEEEIhijj ",
      "      iiiiiii   ",
      "      i     i   ",
      "      i     i   ",
      "      iiiiiiijj ",
      "                "
    ],
    [
      "                ",
      "      iiiiiiijj ",
      "      illllVi   ",
      "      illllli   ",
      "      illllli   ",
      "      imNlllijj ",
      "      illllli   ",
      "      iWWWWWi   ",
      "      iWWWWWi   ",
      "      iWWWWWi   ",
      "      iWWWWWijj ",
      "      illllli   ",
      "      illllli   ",
      "      illllli   ",
      "      iiiiiiijj ",
      "                "
    ]
  ]
}