{
  "name": "multi_taigaresidence_4_floor3",
  "refpalette": "deceasedcraft:multi_taigaresidence_4/multi_taigaresidence_4_floor3_palette",
  "xsize": 16,
  "zsize": 16,
  "slices": [
    [
      "aaaaabcddeeefg  ",
      "hhhiabcffffffjj ",
      "   kabclllllfg  ",
      "   kabclllllfg  ",
      "   kabclllllfg  ",
      "   kabclllllfjj ",
      "   kabcffffffg  ",
      "   kabc     cg  ",
      "   kabc     cg  ",
      "   kabc     fg  ",
      "   kab      fjj ",
      "   kabmffffffg  ",
      "   kabcck   fg  ",
      "   kabccn   fg  ",
      "ooopabcffffffjj ",
      "aaaaabcddeeefg  "
    ],
    [
      "      fqqrstf   ",
      "uuuu  fffffffjj ",
      "   u  w     f   ",
      "   u  f     x   ",
      "   u  f  yA f   ",
      "   u  f BCCDfjj ",
      "   u  fffffff   ",
      "   u  f     E   ",
      "   u  F     E   ",
      "   u  I     f   ",
      "   u Jf     fjj ",
      "   u  fffffff   ",
      "   u  f     x   ",
      "   u  K Ln  f   ",
      "uuuu  fffffffjj ",
      "      fMMrNOf   "
    ],
    [
      "      fPPr  f   ",
      "      fffffffjj ",
      "      Q     f   ",
      "      f         ",
      "      f  RS f   ",
      "      fTTCCDfjj ",
      "      fffffff   ",
      "      f     E   ",
      "      U     E   ",
      "      V     f   ",
      "      f     fjj ",
      "      fffffff   ",
      "      f         ",
      "      W  Ln f   ",
      "      fffffffjj ",
      "      fXXr  f   "
    ],
    [
      "      fY r  f   ",
      "      fffffffjj ",
      "      Z     f   ",
      "      f         ",
      "      f     f   ",
      "      fT    fjj ",
      "      fffffff   ",
      "      f     E   ",
      "      Z     E   ",
      "      Z     f   ",
      "     0f     fjj ",
      "      fffffff   ",
      "      f   Zn    ",
      "      Z   Lcf   ",
      "      fffffffjj ",
      "      f 1r  f   "
    ],
    [
      "      f  r  f   ",
      "      fffffffjj ",
      "      f     f   ",
      "      f     f   ",
      "      f     f   ",
      "      fT    fjj ",
      "      fffffff   ",
      "      f     E   ",
      "      f     E   ",
      "      f     f   ",
      "      f     fjj ",
      "      fffffff   ",
      "      f  Zk f   ",
      "      f     f   ",
      "      fffffffjj ",
      "      f  r  f   "
    ],
    [
      "      flllllf   ",
      "      fffffffjj ",
      "      fT    f   ",
      "      fT    f   ",
      "      fT    f   ",
      "      fTTTTTfjj ",
      "      fffffff   ",
      "      f     E   ",
      "      f     E   ",
      "      f     f   ",
      "      f     fjj ",
      "      fffffff   ",
      "      f Zk  f   ",
      "      f     f   ",
      "      fffffffjj ",
      "      flllllf   "
    ]
  ]
}