{
  "name": "multi_taigaresidence_4_floor1",
  "refpalette": "deceasedcraft:multi_taigaresidence_4/multi_taigaresidence_4_floor1_palette",
  "xsize": 16,
  "zsize": 16,
  "slices": [
    [
      "aaaaabccccccde  ",
      "fffgabhddddddii ",
      "   jabhkkkkkde  ",
      "   jabhkkkkkde  ",
      "   jabhkkkkkde  ",
      "   jabhkkkkkdii ",
      "   jabhdddddde  ",
      "   jabh     he  ",
      "   jabh     he  ",
      "   jabh     de  ",
      "   jab      dii ",
      "   jabldddddde  ",
      "   jabhhj   de  ",
      "   jabhhm   de  ",
      "nnnoabhddddddii ",
      "aaaaabccccccde  "
    ],
    [
      "      dp dqrd   ",
      "ssss  dddddddii ",
      "   s  t     d   ",
      "   s  d     u   ",
      "   s  d  wx d   ",
      "   s  d y!ABdii ",
      "   s  ddddddd   ",
      " C s  d     D   ",
      "   s  E     D   ",
      "   s  F     d   ",
      "   s Id     dii ",
      "   s  ddddddd   ",
      "   s  d     u   ",
      "   s  J Km  d   ",
      "ssss  dddddddii ",
      "      dL dMNd   "
    ],
    [
      "      d Od  d   ",
      "      dddddddii ",
      "      P     d   ",
      "      d         ",
      "      d  QR d   ",
      "      dSSAABdii ",
      "      ddddddd   ",
      " C    d     D   ",
      "      T     D   ",
      "      U     d   ",
      "      d     dii ",
      "      ddddddd   ",
      "      d         ",
      "      V  Km d   ",
      "      dddddddii ",
      "      d Od  d   "
    ],
    [
      "      dW d  d   ",
      "      dddddddii ",
      "      X     d   ",
      "      d         ",
      "      d     d   ",
      " C    dS    dii ",
      "      ddddddd   ",
      " C   Yd     D   ",
      "C     X     D   ",
      "      X     d   ",
      "     Zd     dii ",
      "      ddddddd   ",
      "      d   Xm    ",
      "      X   Khd   ",
      "      dddddddii ",
      "      d0 d  d   "
    ],
    [
      "      d  d  d   ",
      "      dddddddii ",
      "      d     d   ",
      "C     d     d   ",
      "      d     d   ",
      " C    dS    dii ",
      "      ddddddd   ",
      " 1    d     D   ",
      "C     d     D   ",
      "      d     d   ",
      "      d     dii ",
      "      ddddddd   ",
      " C    d  Xj d   ",
      "      d     d   ",
      "      dddddddii ",
      "      d  d  d   "
    ],
    [
      "      dkkkkkd   ",
      "      dddddddii ",
      "      dS    d   ",
      "1     dS    d   ",
      "      dS    d   ",
      " 1    dSSSSSdii ",
      "      ddddddd   ",
      " 1    d     D   ",
      "1     d     D   ",
      "      d     d   ",
      " 1    d     dii ",
      "      ddddddd   ",
      " 1    d Xj  d   ",
      "      d     d   ",
      "      dddddddii ",
      "      dkkkkkd   "
    ]
  ]
}