{
  "name": "multi_taigaresidence_4_base2",
  "refpalette": "deceasedcraft:multi_taigaresidence_4/multi_taigaresidence_4_base2_palette",
  "xsize": 16,
  "zsize": 16,
  "slices": [
    [
      "HHHHHHHHHHHHabbv",
      "HHHaaaaaaaaaabbv",
      "HHHaccdeeeeeabbv",
      "HHHaccdeeeeeabbv",
      "HHHaccdeeeeeabbv",
      "HHHaccdeeeeeabbv",
      "HHHcccdaaaaaabbv",
      "HHHcccd     abbv",
      "HHHcccd     abbv",
      "HHHcccd     abbv",
      "HHHacc      abbv",
      "HHHaccfaaaaaabbv",
      "HHHaccddddddabbv",
      "HHHaccddddddabbv",
      "HHHaaaaaaaaaabbv",
      "HHHHHHHHHHHHabbv"
    ],
    [
      "          ggabbv",
      " hhaaaaaaaaaabbv",
      " ija  k     abbv",
      "   a  a     abbv",
      " lma  a  no abbv",
      "  pa  aqrss abbv",
      "   t uaaaaaaabbv",
      "   w  a     abbv",
      "   x  y     abbv",
      "   t  A     abbv",
      "  Ba Ca     abbv",
      " ija  aaaaaaabbv",
      "   a  a   ddabbv",
      " lma  D Edddabbv",
      " hhaaaaaaaaaabbv",
      "          ggabbv"
    ],
    [
      "            abbv",
      "   aaaaaaaaaabbv",
      "   a  F     abbv",
      "   a  a     abbv",
      "   a  a  IJ abbv",
      "  pa  aqqss abbv",
      "   t  aaaaaaabbv",
      "   K  a     abbv",
      "   L  M     abbv",
      "   t  N     abbv",
      "  Ba  a     abbv",
      "   a  aaaaaaabbv",
      "   a  a   ddabbv",
      "   a  O  Eddabbv",
      "   aaaaaaaaaabbv",
      "            abbv"
    ],
    [
      "      P     abbv",
      "   aaaaaaaaaabbv",
      "   a  Q     abbv",
      "   a  a     abbv",
      "   a  a     abbv",
      "  pa  aq    abbv",
      "  Rt  aaaaaaabbv",
      "  Rt Sa     abbv",
      "  Rt  Q     abbv",
      "  Rt  Q     abbv",
      "  Ba Ta     abbv",
      "   a  aaaaaaabbv",
      "   a  a   ddabbv",
      "   a  Q   Edabbv",
      "   aaaaaaaaaabbv",
      "      P     abbv"
    ],
    [
      "     qa     abbv",
      "aaaaaaaaaaaaabbv",
      "   a  a     abbv",
      "   a  a     abbv",
      "   a  a     abbv",
      "   a  aq    abbv",
      "   a  aaaaaaabbv",
      "   a  a     abbv",
      "   a  a     abbv",
      "   a  a     abbv",
      "   a  a     abbv",
      "   a  aaaaaaabbv",
      "   a  a  QU abbv",
      "   a  a     abbv",
      "aaaaaaaaaaaaabbv",
      "     qa     abbv"
    ],
    [
      "eeeeeeaRRRRRabbv",
      "aaaaaaaaaaaaabbv",
      "eeeaeeaq    abbv",
      "eeeaeeaq    abbv",
      "eeeaeeaq    abbv",
      "eeeaeeaqqqqqabbv",
      "eeeaeeaaaaaaabbv",
      "eeeaeea     abbv",
      "eeeaeea     abbv",
      "eeeaeea     abbv",
      "eeeaeea     abbv",
      "eeeaeeaaaaaaabbv",
      "eeeaeea QU  abbv",
      "eeeaeea     abbv",
      "aaaaaaaaaaaaabbv",
      "eeeeeeaRRRRRabbv"
    ]
  ]
}