{
  "name": "multi_taigaresidence_4_floor5",
  "refpalette": "deceasedcraft:multi_taigaresidence_4/multi_taigaresidence_4_floor5_palette",
  "xsize": 16,
  "zsize": 16,
  "slices": [
    [
      "aaaaabcddeeefg  ",
      "hhhiabcffffffjj ",
      "   kabclllllfg  ",
      "   kabclllllfg  ",
      "   kabclllllfg  ",
      "   kabclllllfjj ",
      "   kabcffffffg  ",
      "   kabc     cg  ",
      "   kabc     cg  ",
      "   kabc     fg  ",
      "   kab      fjj ",
      "   kabmffffffg  ",
      "   kabcck   fg  ",
      "   kabccn   fg  ",
      "ooopabcffffffjj ",
      "aaaaabcddeeefg  "
    ],
    [
      "      fqqrstf   ",
      "uuuu  fffffffjj ",
      "   u  w     f   ",
      "   u  f     x   ",
      "   u  f  yA f   ",
      "   u  f BCC fjj ",
      "   u  fffffff   ",
      "   u  f     D   ",
      "   u  E     D   ",
      "   u  F     f   ",
      "   u If     fjj ",
      "   u  fffffff   ",
      "   u  fJ    x   ",
      "   u  KLMn  f   ",
      "uuuu  fffffffjj ",
      "      fNNrOPf   "
    ],
    [
      "      fQQr  f   ",
      "      fffffffjj ",
      "      R     f   ",
      "      f         ",
      "      f  ST f   ",
      "      fUUCC fjj ",
      "      fffffff   ",
      "      f     D   ",
      "      V     D   ",
      "      W     f   ",
      "      f     fjj ",
      "      fffffff   ",
      "      f         ",
      "      X  Mn f   ",
      "      fffffffjj ",
      "      fYYr  f   "
    ],
    [
      "      f  r  f   ",
      "      fffffffjj ",
      "      Z     f   ",
      "      f         ",
      "      f     f   ",
      "      fU    fjj ",
      "      fffffff   ",
      "     !f     D   ",
      "      Z     D   ",
      "      Z     f   ",
      "     0f     fjj ",
      "      fffffff   ",
      "      f   Zn    ",
      "      Z   Mcf   ",
      "      fffffffjj ",
      "      f !r  f   "
    ],
    [
      "      f  r  f   ",
      "      fffffffjj ",
      "      f     f   ",
      "      f     f   ",
      "      f     f   ",
      "      fU1   fjj ",
      "      fffffff   ",
      "      f     D   ",
      "      f     D   ",
      "      f     f   ",
      "      f     fjj ",
      "      fffffff   ",
      "      f  Zk f   ",
      "      f     f   ",
      "      fffffffjj ",
      "      f  r  f   "
    ],
    [
      "      flllllf   ",
      "      fffffffjj ",
      "      fU    f   ",
      "      fU    f   ",
      "      fU    f   ",
      "      fUUUUUfjj ",
      "      fffffff   ",
      "      f     D   ",
      "      f     D   ",
      "      f     f   ",
      "      f     fjj ",
      "      fffffff   ",
      "      f Zk  f   ",
      "      f     f   ",
      "      fffffffjj ",
      "      flllllf   "
    ]
  ]
}