{
  "name": "multi_taigaresidence_4_ground",
  "refpalette": "deceasedcraft:multi_taigaresidence_4/multi_taigaresidence_4_ground_palette",
  "xsize": 16,
  "zsize": 16,
  "slices": [
    [
      "aaaaaabHHHHHHHHH",
      "aaaaaaabbbbbbccd",
      "aaaaaaaeeeeebadd",
      "aaaaaaaeeeeebadd",
      "aaaaaaaeeeeebadd",
      "aaaaaaaeeeeebccd",
      "aaaaaaabbbbbbadd",
      "aaaaaaa     aadd",
      "aaaaaaa     aadd",
      "aaaaaaa     badd",
      "aaaaaa      bccd",
      "aaaaaafbbbbbbadd",
      "aaaaaaaag   badd",
      "aaaaaaaah   badd",
      "aaaaaabbbbbbbccd",
      "aaaaaabHHHHHHHHH"
    ],
    [
      "      b         ",
      "      bbbbbbbcc ",
      "      i  jklb   ",
      "   m  b     n   ",
      "   m  b o o b   ",
      "p  m  bqqqqqbcc ",
      "pr m  bbbbbbb   ",
      "p  m  b     s   ",
      "p  m  t     s   ",
      "pr m  u     b   ",
      "p  m wb     bcc ",
      "   m  bbbbbbb   ",
      "   m  b     n   ",
      "      x yh  b   ",
      "      bbbbbbbcc ",
      "      b         "
    ],
    [
      "      b         ",
      "      bbbbbbbcc ",
      "      A     b   ",
      "      bB        ",
      "      b     b   ",
      "      b CCD bcc ",
      "      bbbbbbb   ",
      "E     b     s   ",
      "      F     s   ",
      "      I     b   ",
      "E     b     bcc ",
      "      bbbbbbb   ",
      "      b         ",
      "      J  yh b   ",
      "      bbbbbbbcc ",
      "      b         "
    ],
    [
      "      b     K   ",
      "      bbbbbbbcc ",
      "      L     b   ",
      "      b         ",
      "      b     b   ",
      "      b CDC bcc ",
      "      bbbbbbb   ",
      "     Mb     s   ",
      "      L     s   ",
      "      L     b   ",
      "     Nb     bcc ",
      "      bbbbbbb   ",
      "      b   Lh    ",
      "      L   yab   ",
      "      bbbbbbbcc ",
      "      b     K   "
    ],
    [
      "      b     b   ",
      "      bbbbbbbcc ",
      "      b     b   ",
      "      b     b   ",
      "      b     b   ",
      "      b     bcc ",
      "      bbbbbbb   ",
      "      b     s   ",
      "      b     s   ",
      "      b     b   ",
      "      b     bcc ",
      "      bbbbbbb   ",
      "      b  Lg b   ",
      "      b     b   ",
      "      bbbbbbbcc ",
      "      b     b   "
    ],
    [
      "      bOOOOOb   ",
      "      bbbbbbbcc ",
      "      bP    b   ",
      "      bP    b   ",
      "      bP    b   ",
      "      bPPPPPbcc ",
      "      bbbbbbb   ",
      "      b     s   ",
      "      b     s   ",
      "      b     b   ",
      "      b     bcc ",
      "      bbbbbbb   ",
      "      b Lg  b   ",
      "      b     b   ",
      "      bbbbbbbcc ",
      "      beeeeeb   "
    ]
  ]
}