{
  "name": "multi_taigaresidence_4_floor2",
  "refpalette": "deceasedcraft:multi_taigaresidence_4/multi_taigaresidence_4_floor2_palette",
  "xsize": 16,
  "zsize": 16,
  "slices": [
    [
      "aaaaabccccccde  ",
      "fffgabcddddddhh ",
      "@@@iabcjjjjjde  ",
      "@@@iabcjjjjjde  ",
      "@@@iabcjjjjjde  ",
      "@@@iabcjjjjjdhh ",
      "@@@iabcdddddde  ",
      "@@@iabc     ce  ",
      "@@@iabc     ce  ",
      "@@@iabc     de  ",
      "@@@iab      dhh ",
      "@@@iabkdddddde  ",
      "@@@iabcci   de  ",
      "@@@iabccl   de  ",
      "mmmnabcddddddhh ",
      "aaaaabcccooode  "
    ],
    [
      "         pqrd   ",
      "ssss  dddddddhh ",
      "   s  t     d   ",
      "   s  d     u   ",
      "   s  d  wx d   ",
      "   s  dyABBCdhh ",
      "   s  ddddddd   ",
      "   s  d     D   ",
      "   s  E     D   ",
      "   s  F     d   ",
      "   s Id     dhh ",
      "   s  ddddddd   ",
      "   s  d     u   ",
      "   s  J Kl  d   ",
      "ssss  dddddddhh ",
      "        LdMNd   "
    ],
    [
      "      O  P  d   ",
      "      dddddddhh ",
      "      Q     d   ",
      "      d         ",
      "      d  RS d   ",
      "      dTTBB dhh ",
      "      ddddddd   ",
      "      d     D   ",
      "      U     D   ",
      "      V     d   ",
      "      d     dhh ",
      "      ddddddd   ",
      "      d         ",
      "      W  Kl d   ",
      "      dddddddhh ",
      "      O  d  d   "
    ],
    [
      "            d   ",
      "      dddddddhh ",
      "      X     d   ",
      "      d         ",
      "      d     d   ",
      "      dT    dhh ",
      "      ddddddd   ",
      "     Yd     D   ",
      "      X     D   ",
      "      X     d   ",
      "     Zd     dhh ",
      "      ddddddd   ",
      "      d   Xl    ",
      "      X   Kcd   ",
      "      dddddddhh ",
      "         d  d   "
    ],
    [
      "            d   ",
      "      dddddddhh ",
      "      d     d   ",
      "      d     d   ",
      "      dy    d   ",
      "      dT    dhh ",
      "      ddddddd   ",
      "      d     D   ",
      "      d     D   ",
      "      d     d   ",
      "      d     dhh ",
      "      ddddddd   ",
      "      d  Xi d   ",
      "      d     d   ",
      "      dddddddhh ",
      "         d  d   "
    ],
    [
      "      000000d   ",
      "      dddddddhh ",
      "      dT    d   ",
      "      dT    d   ",
      "      dT    d   ",
      "      dTTTTTdhh ",
      "      ddddddd   ",
      "      d     D   ",
      "      d     D   ",
      "      d     d   ",
      "      d     dhh ",
      "      ddddddd   ",
      "      d Xi  d   ",
      "      d     d   ",
      "      dddddddhh ",
      "      000djjd   "
    ]
  ]
}