{
  "name": "multi_taigaresidence_4_base1",
  "refpalette": "deceasedcraft:multi_taigaresidence_4/multi_taigaresidence_4_base1_palette",
  "xsize": 16,
  "zsize": 16,
  "slices": [
    [
      "HHHHHHHHHHHHabbv",
      "HHHaaaaaaaaaabbv",
      "HHHaccdeeeeeabbv",
      "HHHaccdeeeeeabbv",
      "HHHaccdeeeeeabbv",
      "HHHaccdeeeeeabbv",
      "HHHcccdaaaaaabbv",
      "HHHcccd     abbv",
      "HHHcccd     abbv",
      "HHHcccd     abbv",
      "HHHacc      abbv",
      "HHHaccfaaaaaabbv",
      "HHHaccddg   abbv",
      "HHHaccddh   abbv",
      "HHHaaaaaaaaaabbv",
      "HHHHHHHHHHHHabbv"
    ],
    [
      "          iiabbv",
      " jjaaaaaaaaaabbv",
      " kla  m     abbv",
      "   a  a     abbv",
      " noa  a  pq abbv",
      "  ra  astuu abbv",
      "   w xaaaaaaabbv",
      "   y  a     abbv",
      "   A  B     abbv",
      "   w  C     abbv",
      "  Da Ea     abbv",
      " kla  aaaaaaabbv",
      "   a  a     abbv",
      " noa  F Ih  abbv",
      " jjaaaaaaaaaabbv",
      "          iiabbv"
    ],
    [
      "            abbv",
      "   aaaaaaaaaabbv",
      "   a  J     abbv",
      "   a  a     abbv",
      "   a  a  KL abbv",
      "  ra  assuu abbv",
      "   w  aaaaaaabbv",
      "   M  a     abbv",
      "   N  O     abbv",
      "   w  P     abbv",
      "  Da  a     abbv",
      "   a  aaaaaaabbv",
      "   a  a     abbv",
      "   a  Q  Ih abbv",
      "   aaaaaaaaaabbv",
      "            abbv"
    ],
    [
      "      R     abbv",
      "   aaaaaaaaaabbv",
      "   a  S     abbv",
      "   a  a     abbv",
      "   a  a     abbv",
      "  ra  as    abbv",
      "  Tw  aaaaaaabbv",
      "  Tw Ua     abbv",
      "  Tw  S     abbv",
      "  Tw  S     abbv",
      "  Da Va     abbv",
      "   a  aaaaaaabbv",
      "   a  a   Sdabbv",
      "   a  S   Idabbv",
      "   aaaaaaaaaabbv",
      "      R     abbv"
    ],
    [
      "     sa     abbv",
      "aaaaaaaaaaaaabbv",
      "   a  a     abbv",
      "   a  a     abbv",
      "   a  a     abbv",
      "   a  as    abbv",
      "   a  aaaaaaabbv",
      "   a  a     abbv",
      "   a  a     abbv",
      "   a  a     abbv",
      "   a  a     abbv",
      "   a  aaaaaaabbv",
      "   a  a  Sg abbv",
      "   a  a     abbv",
      "aaaaaaaaaaaaabbv",
      "     sa     abbv"
    ],
    [
      "eeeeeeaTTTTTabbv",
      "aaaaaaaaaaaaabbv",
      "eeeaeeas    abbv",
      "eeeaeeas    abbv",
      "eeeaeeas    abbv",
      "eeeaeeasssssabbv",
      "eeeaeeaaaaaaabbv",
      "eeeaeea     abbv",
      "eeeaeea     abbv",
      "eeeaeea     abbv",
      "eeeaeea     abbv",
      "eeeaeeaaaaaaabbv",
      "eeeaeea Sg  abbv",
      "eeeaeea     abbv",
      "aaaaaaaaaaaaabbv",
      "eeeeeeaTTTTTabbv"
    ]
  ]
}