{
  "name": "multi_taigaresidence_4_floor6",
  "refpalette": "deceasedcraft:multi_taigaresidence_4/multi_taigaresidence_4_floor6_palette",
  "xsize": 16,
  "zsize": 16,
  "slices": [
    [
      "aaaaabcdddddef  ",
      "ggghabceeeeeeii ",
      "   jabckkkkkef  ",
      "   jabckkkkkef  ",
      "   jabckkkkkef  ",
      "   jabckkkkkeii ",
      "   jabceeeeeef  ",
      "   jabc     cf  ",
      "   jabc     cf  ",
      "   jabc     ef  ",
      "   jab      eii ",
      "   jableeeeeef  ",
      "   jabccj   ef  ",
      "   jabccm   ef  ",
      "nnnoabceeeeeeii ",
      "aaaaabcdddddef  "
    ],
    [
      "      epqr se   ",
      "tttt  eeeeeeeii ",
      "   t  u     e   ",
      "   t  e     w   ",
      "   t  e  xy e   ",
      "   t  e ABBCeii ",
      "   t  eeeeeee   ",
      "   t  e     D   ",
      "   t  E     D   ",
      "   t  F     e   ",
      "   t Ie     eii ",
      "   t  eeeeeee   ",
      "   t  e     w   ",
      "   t  J Km  e   ",
      "tttt  eeeeeeeii ",
      "      eLMN Oe   "
    ],
    [
      "      e   P e   ",
      "      eeeeeeeii ",
      "      Q     e   ",
      "      e         ",
      "      e  RS e   ",
      "      eTTBB eii ",
      "      eeeeeee   ",
      "      e     D   ",
      "      U     D   ",
      "      V     e   ",
      "      e     eii ",
      "      eeeeeee   ",
      "      e         ",
      "      W  Km e   ",
      "      eeeeeeeii ",
      "      e   X e   "
    ],
    [
      "      e   Y e   ",
      "      eeeeeeeii ",
      "      Z     e   ",
      "      e         ",
      "      e     e   ",
      "      eT    eii ",
      "      eeeeeee   ",
      "     0e     D   ",
      "      Z     D   ",
      "      Z     e   ",
      "     1e     eii ",
      "      eeeeeee   ",
      "      e   Zm    ",
      "      Z   Kce   ",
      "      eeeeeeeii ",
      "      e   2 e   "
    ],
    [
      "      e     e   ",
      "      eeeeeeeii ",
      "      e     e   ",
      "      e     e   ",
      "      e     e   ",
      "      eT    eii ",
      "      eeeeeee   ",
      "      e     D   ",
      "      e     D   ",
      "      e     e   ",
      "      e     eii ",
      "      eeeeeee   ",
      "      e  Zj e   ",
      "      e     e   ",
      "      eeeeeeeii ",
      "      e     e   "
    ],
    [
      "      ekkkkke   ",
      "      eeeeeeeii ",
      "      eT    e   ",
      "      eT    e   ",
      "      eT    e   ",
      "      eTTTTTeii ",
      "      eeeeeee   ",
      "      e     D   ",
      "      e     D   ",
      "      e     e   ",
      "      e     eii ",
      "      eeeeeee   ",
      "      e Zj  e   ",
      "      e     e   ",
      "      eeeeeeeii ",
      "      ekkkkke   "
    ]
  ]
}