{
  "name": "multi_taigaresidence_4_floor4",
  "refpalette": "deceasedcraft:multi_taigaresidence_4/multi_taigaresidence_4_floor4_palette",
  "xsize": 16,
  "zsize": 16,
  "slices": [
    [
      "aaaaabcddeeefg  ",
      "hhhiabcffffffjj ",
      "   kabclllllfg  ",
      "   kabclllllfg  ",
      "   kabclllllfg  ",
      "   kabclllllfjj ",
      "   kabcffffffg  ",
      "   kabc     cg  ",
      "   kabc     cg  ",
      "   kabc     fg  ",
      "   kab      fjj ",
      "   kabmffffffg  ",
      "   kabcck   fg  ",
      "   kabccn   fg  ",
      "ooopabcffffffjj ",
      "aaaaabcddeeefg  "
    ],
    [
      "      fqqrstf   ",
      "uuuu  fffffffjj ",
      "   u  w     f   ",
      "   u  f     x   ",
      "   u  f  yABf   ",
      "   u  f CDD!fjj ",
      "   u  fffffff   ",
      "   u  f     E   ",
      "   u  F     E   ",
      "   u  I     f   ",
      "   u Jf     fjj ",
      "   u  fffffff   ",
      "   u  f     x   ",
      "   u  K Ln  f   ",
      "uuuu  fffffffjj ",
      "      fMMrNOf   "
    ],
    [
      "      fPPr  f   ",
      "      fffffffjj ",
      "      Q     f   ",
      "      f         ",
      "      f  RS f   ",
      "      fTTDD fjj ",
      "      fffffff   ",
      "      f     E   ",
      "      U     E   ",
      "      V     f   ",
      "      f     fjj ",
      "      fffffff   ",
      "      f         ",
      "      W  Ln f   ",
      "      fffffffjj ",
      "      fXXr  f   "
    ],
    [
      "      f  rY f   ",
      "      fffffffjj ",
      "      Z     f   ",
      "      f         ",
      "      f     f   ",
      "      fT    fjj ",
      "      fffffff   ",
      "     0f     E   ",
      "      Z     E   ",
      "      Z     f   ",
      "     1f     fjj ",
      "      fffffff   ",
      "      f   Zn    ",
      "      Z   Lcf   ",
      "      fffffffjj ",
      "      f !r2 f   "
    ],
    [
      "      f  r  f   ",
      "      fffffffjj ",
      "      f     f   ",
      "      f     f   ",
      "      f     f   ",
      "      fT    fjj ",
      "      fffffff   ",
      "      f     E   ",
      "      f     E   ",
      "      f     f   ",
      "      f     fjj ",
      "      fffffff   ",
      "      f  Zk f   ",
      "      f     f   ",
      "      fffffffjj ",
      "      f  r  f   "
    ],
    [
      "      flllllf   ",
      "      fffffffjj ",
      "      fT  BBf   ",
      "      fT   Bf   ",
      "      fTB   f   ",
      "      fTTTTTfjj ",
      "      fffffff   ",
      "      f     E   ",
      "      f     E   ",
      "      f     f   ",
      "      f     fjj ",
      "      fffffff   ",
      "      f Zk  f   ",
      "      f     f   ",
      "      fffffffjj ",
      "      flllllf   "
    ]
  ]
}