{
  "name": "multi_planecrash1_4_ground",
  "refpalette": "deceasedcraft:multi_planecrash1_4/multi_planecrash1_4_ground_palette",
  "xsize": 16,
  "zsize": 16,
  "slices": [
    [
      "aaaaaaaaaaaaaabb",
      "aaaaaaaaaaaaaabb",
      "aaaaaaaaaaaaaaab",
      "aaaaaaaaaaaaaaaa",
      "aaaaaaaaaaaaaaaa",
      "aaaaaaaaaaaaaaaa",
      "aaaaaaaaaaaaaaaa",
      "aaaaaaaaaaacaaaa",
      "aaaaaaaaaaaaaaaa",
      "aaaaaaaaaaaaaaaa",
      "aaaaaaaaaaaaaaaa",
      "aaaaaaaaaaaaaaaa",
      "aaaaaaaaaaaaaaaa",
      "aaaaaaaaaaaaaaaa",
      "aaaaaaaaaaaaaaaa",
      "aaaaaaaaaaaaaaaa"
    ],
    [
      "aaaaaaabbbbbbbbb",
      "aaaaaaabbbbbbbbb",
      "aaaaaaabbbbbbbbb",
      "aaaaaaabbbbbbbbb",
      "aaaabaabbbbbbbbb",
      "aaaabaababbbbbbb",
      "aaaabaaaaababbbb",
      "aaaaaaababadabbb",
      "aaaaaaabbbbababb",
      "baaaaabbbbbbaaab",
      "baaaaabbbbbbbabb",
      "baaaaabbbbbbbbbb",
      "baaaaabbbabbbbbb",
      "baaaaabbaaabbbbb",
      "bbaaaabaabaabbbb",
      "bbbaaaabaaabbbbb"
    ],
    [
      "aaaaaaabbbbbbbbb",
      "aaaaaaabbbbbbbbb",
      "aaaaaaabbbbbbbbb",
      "aaaaaaabbbbbbbbb",
      "aaaabaabbbbbbbbb",
      "aaaabaababbbbbbb",
      "aaaabaaaaababbbb",
      "aaaaaaababaeabbb",
      "aaaaaaabbbbababb",
      "baaaaabbbbbbaaab",
      "baaaaabbbbbbbabb",
      "baaaaabbbbbbbbbb",
      "baaaaabbbabbbbbb",
      "baaaaabbaaabbbbb",
      "bbaaaabaabaabbbb",
      "bbbaaaafaaabbbbb"
    ],
    [
      "aaaaaaabbbbbbbbb",
      "aaaaaaabbbbbbbbb",
      "aaaaaaabbbbbbbbb",
      "aaaaaaabbbbbbbbb",
      "aaaabaabbbbbbbbb",
      "aaaabaababbbbbbb",
      "aaaabaaaaababbbb",
      "aaaaaaababagabbb",
      "aaaaaaabbbbababb",
      "baaaaabbbbbbaaab",
      "baaaaabbbbbbbabb",
      "baaaaabbbbbbbbbb",
      "baaaaabbbabbbbbb",
      "baaaaabbaaabbbbb",
      "bbaaaabaabaabbbb",
      "bbbaaaaeaaabbbbb"
    ],
    [
      "aaaaaaabbbbbbbbb",
      "aaaaaaabbbbbbbbb",
      "aaaaaaabbbbbbbbb",
      "aaaaaaabbbbbbbbb",
      "aaaabaabbbbbbbbb",
      "aaaabaababbbbbbb",
      "aaaabaaaaababbbb",
      "aaaaaaababagabbb",
      "aaaaaaabbbbababb",
      "baaaaabbbbbbaaab",
      "baaaaabbbbbbbabb",
      "baaaaabbbbbbbbbb",
      "baaaaabbbabbbbbb",
      "baaaaabbaaabbbbb",
      "bbaaaabaabaabbbb",
      "bbbaaaagaaabbbbb"
    ],
    [
      "aaaaaaabbbbbbbbb",
      "aaaaaaabbbbbbbbb",
      "aaaaaaabbbbbbbbb",
      "aaaaaaabbbbbbbbb",
      "aaaabaabbbbbbbbb",
      "aaaabaababbbbbbb",
      "aaaabaaaaababbbb",
      "aaaaaaababagabbb",
      "aaaaaaabbbbababb",
      "baaaaabbbbbbaaab",
      "baaaaabbbbbbbabb",
      "baaaaabbbbbbbbbb",
      "baaaaabbbabbbbbb",
      "baaaaabbaaabbbbb",
      "bbaaaabaabaabbbb",
      "bbbaaaagaaabbbbb"
    ]
  ]
}