{
  "name": "multi_planecrash1_4_floor1",
  "refpalette": "deceasedcraft:multi_planecrash1_4/multi_planecrash1_4_floor1_palette",
  "xsize": 16,
  "zsize": 16,
  "slices": [
    [
      "abcccdaeeeeeeeee",
      "abcccdaeeeeeeeee",
      "abcccdaeeeeeeeee",
      "abcccdaeeeeeeeee",
      "abccfdaeeeeeeeee",
      "acccgcaeaeeeeeee",
      "accchcaaiaeaeeje",
      "acccccaeaeakahje",
      "abcccdaeeeeaeaee",
      "eaaccaeeeeeeaiae",
      "eacccaeeeeeeeaee",
      "eacccaeeeeeeeeee",
      "eacccaeeeaeeeeee",
      "eacccaeealaeeeee",
      "eeaccaeamenaeeee",
      "eeeaacakaoaeeeee"
    ],
    [
      "pqrehqeeeeeeeeee",
      "qqsetqueeeeeeeee",
      "qqvweqqxeeeeeeee",
      "qqyezfAxxeeeeeee",
      "qqreBfueeeeeeeee",
      "qqseequeeeeeeeee",
      "qqveeqCeeeeeeeee",
      "Dqyehqeeeeeeeeee",
      "eqreEqeeeeeeeeee",
      "eqFaGqeeeeeeeeee",
      "eHIeJKeeeeeeeeee",
      "eHIeJKeeeeeeeeee",
      "eLIeMNeeeeeeeeee",
      "eLqOqNeeeeeeeeee",
      "eePeeQeeeeeeeeee",
      "eeeeeeeeeeeeeeee"
    ],
    [
      "eReeeReeeeeeeeee",
      "eqeeeqeeeeeeeeee",
      "eReeeeeeeeeeeeee",
      "eqeeejeeeeeeeeee",
      "eReeeeeeeeeeeeee",
      "eqeeeheeeeeeeeee",
      "eReeeeeeeeeeeeee",
      "eqeeejeeeeeeeeee",
      "eReeeeeeeeeeeeee",
      "eqSeeqeeeeeeeeee",
      "eqeeeqeeeeeeeeee",
      "eqeeTqeeeeeeeeee",
      "eqeeeqeeeeeeeeee",
      "eqUVWWeeeeeeeeee",
      "eeeeeeeeeeeeeeee",
      "eeeeeeeeeeeeeeee"
    ],
    [
      "eXKCjYeeeeeeeeee",
      "eYKCgjeeeeeeeeee",
      "eXjCBjeeeeeeeeee",
      "eXfZQeeeeeeeeeee",
      "eYfCQeeeeeeeeeee",
      "eYjCeeeeeeeeeeee",
      "eXfCeeeeeeeeeeee",
      "eXj0gee1eeeeeeee",
      "CXKCfBhCeeeeeeee",
      "CqqqjfhCeeeeeeee",
      "Hq2ejhK3eeeeeeee",
      "Hq2e4jKeeeeeeeee",
      "eX254jeeeeeeeeee",
      "eYqqqeeeeeeeeeee",
      "eeqCPeeeeeeeeeee",
      "ee6eeeeeeeeeeeee"
    ],
    [
      "eeYAeeeeeeeeeeee",
      "eeYjeeeeeeeeeeee",
      "eeefxeeeeeeeeeee",
      "eeeBeeeeeeeeeeee",
      "eeeBeeeeeeeeeeee",
      "eeejeeeeeeeeeeee",
      "eeeBxeeeeeeeeeee",
      "Neejxe7eQeeeeeee",
      "NeYjeeeBeeeeeeee",
      "NeY8ee79Qeeeeeee",
      "!eYqxeL@Qeeeeeee",
      "eeYqYxejeeeeeeee",
      "eeYqYeeeeeeeeeee",
      "eeYqxeeeeeeeeeee",
      "eeeqeeeeeeeeeeee",
      "eeeqeeeeeeeeeeee"
    ],
    [
      "eeeeeeeeeeeeeeee",
      "eeeeeeeeeeeeeeee",
      "eeeeeeeeeeeeeeee",
      "eeeeeeeeeeeeeeee",
      "eeeeeeeeeeeeeeee",
      "eeeeeeeeeeeeeeee",
      "eeeeeeeeeeeeeeee",
      "eeeeeeexeeeeeeee",
      "eeeeeee#eeeeeeee",
      "eeeeeeeeeeeeeeee",
      "eeeeeeeeeeeeeeee",
      "eeeeeeeeeeeeeeee",
      "eeeeeeeeeeeeeeee",
      "eeeeeeeeeeeeeeee",
      "eeeeeeeeeeeeeeee",
      "eeeeeeeeeeeeeeee"
    ]
  ]
}