{
  "name": "multi_residentialf_1_ground",
  "refpalette": "deceasedcraft:multi_residentialf_1/multi_residentialf_1_ground_palette",
  "xsize": 16,
  "zsize": 16,
  "slices": [
    [
      "abcddddddddddcbb",
      "abcddddddddddcbb",
      "abcddddddddddcbb",
      "abcddddddddddcbb",
      "abcddddddddddcbb",
      "aacddddddddddcbb",
      "aacddddddddddcbb",
      "abccccccccccccbb",
      "abebbbbbbabbbebb",
      "abebbbaabbbbbebb",
      "abebbabbbabaaebb",
      "abeeeeeeeeeeeebb",
      "abbbbbbbbbbbbbbb",
      "abbbbbbbbbbbbbbb",
      "abbbbbbbbbbbbbbb",
      "aaaaaaaaaaaaaaaa"
    ],
    [
      "  fffff  g !ff h",
      "  eijjk   ll e h",
      "  f          f h",
      "  e mno    pqe h",
      "  f        rrf h",
      "  s        tue h",
      "  w        xye h",
      " AfeeBBCDBBeef h",
      "  EFIJIK  FKIE h",
      "  EJFF  JFJFJE h",
      "  EKF KFI I  E h",
      "  fLLLLLLLLLLf h",
      "               h",
      "               h",
      "               h",
      "                "
    ],
    [
      "  fffff  MMMff  ",
      "  N OPQ     RN  ",
      "  f         Sf  ",
      "  N          N  ",
      "  f        rrf  ",
      "  T        U e  ",
      "  V        x e  ",
      "  feeBBWXBBeef  ",
      "                ",
      "                ",
      "                ",
      " YffffffffffffY ",
      " eeeeeeeeeeeeee ",
      "                ",
      "                ",
      "                "
    ],
    [
      "  fffff     ff  ",
      "  N        Z N  ",
      "  f          f  ",
      "  N  0  0    N  ",
      "  f        rrf  ",
      "  N        x 1  ",
      "  N        x 1  ",
      "  feeBB22BBeef  ",
      "                ",
      " YYY        YYY ",
      " eeeeeeeeeeeeee ",
      " 33333333333333 ",
      "                ",
      "                ",
      "                ",
      "                "
    ],
    [
      "  ffffffffffff  ",
      "  NdddddddZ  N  ",
      "  fddddddd   f  ",
      "  Nddddddd   N  ",
      "  fddddddddddf  ",
      "  fddddddddddf  ",
      "  fddddddddddf  ",
      " YffffffffffffY ",
      " eee        eee ",
      " 333        333 ",
      "   4  4  4  4   ",
      "                ",
      "                ",
      "                ",
      "                ",
      "                "
    ],
    [
      "  ffffffffffff  ",
      "  N56657    8N  ",
      "  f 99 #$% ^ f  ",
      "  N    & %   N  ",
      "  f*      (()f  ",
      " YfY+ -[  ] )fY ",
      " eeeN{}|  ;Neee ",
      " 333NNNNNNNN333 ",
      "   4        4   ",
      "                ",
      "   :  :  :  :   ",
      "                ",
      "                ",
      "                ",
      "                ",
      "                "
    ]
  ]
}