{
  "name": "multi_residentialf_1_floor1",
  "refpalette": "deceasedcraft:multi_residentialf_1/multi_residentialf_1_floor1_palette",
  "xsize": 16,
  "zsize": 16,
  "slices": [
    [
      "  aaaaaaaaaaaa  ",
      "  bc  de     b  ",
      "  a    f   g a  ",
      " hah   i    hah ",
      " jjj        jjj ",
      " kkk        kkk ",
      "   l        l   ",
      "                ",
      "   m        m   ",
      "                ",
      "   m  m  m  m   ",
      "                ",
      "                ",
      "                ",
      "                ",
      "                "
    ],
    [
      "  aabbbaabbbaa  ",
      " hah        hah ",
      " jjj       gjjj ",
      " kkk        kkk ",
      "   n    o   n   ",
      "                ",
      "   p        p   ",
      "                ",
      "   p        p   ",
      "                ",
      "   p  p  p  p   ",
      "                ",
      "                ",
      "                ",
      "                ",
      "                "
    ],
    [
      " jjjjjjjjjjjjjj ",
      " kkkkkkkkkkkkkk ",
      "  kkqqqqqqqqkk  ",
      "  kkqqqqqqqqkk  ",
      "  kkqqqqqqqqkk  ",
      "  kkqqqqqqqqkk  ",
      "  kkqqqqqqqqkk  ",
      "  kkqqqqqqqqkk  ",
      "  kkqqqqqqqqkk  ",
      "  kkqqqqqqqqkk  ",
      "  kkkkkkkkkkkk  ",
      "  kkkkkkkkkkkk  ",
      "                ",
      "                ",
      "                ",
      "                "
    ],
    [
      "                ",
      "                ",
      "                ",
      "                ",
      "                ",
      "                ",
      "                ",
      "                ",
      "                ",
      "                ",
      "                ",
      "                ",
      "                ",
      "                ",
      "                ",
      "                "
    ],
    [
      "                ",
      "                ",
      "                ",
      "                ",
      "                ",
      "                ",
      "                ",
      "                ",
      "                ",
      "                ",
      "                ",
      "                ",
      "                ",
      "                ",
      "                ",
      "                "
    ],
    [
      "                ",
      "                ",
      "                ",
      "                ",
      "                ",
      "                ",
      "                ",
      "                ",
      "                ",
      "                ",
      "                ",
      "                ",
      "                ",
      "                ",
      "                ",
      "                "
    ]
  ]
}