{
  "xsize": 16,
  "zsize": 16,
  "refpalette": "lce2:base",
  "slices": [
    [
      "            Ͷ   ",
      "           !Ͷ!  ",
      "            Ͷ   ",
      "           Ͷ    ",
      "           Ͷ    ",
      "          Ͷ     ",
      "         Ͷ      ",
      "Ͷ      ͶͶ       ",
      " ͶͶͶͶͶͶ         ",
      "ͶͶ     ͶͶͶͶ     ",
      "  Ͷ   Ͷ    Ͷ    ",
      "   Ͷ Ͷ      Ͷ   ",
      "   Ͷ Ͷ      Ͷ   ",
      "   Ͷ Ͷ      Ͷ   ",
      "   Ͷ Ͷ      Ͷ   ",
      "  Ͷ   Ͷ    Ͷ    "
    ],
    [
      "           !Ͷ!  ",
      "           !Ͷ!  ",
      "            Ͷ   ",
      "           Ͷ    ",
      "           Ͷ    ",
      "          Ͷ     ",
      "         Ͷ      ",
      "Ͷ      ͶͶ       ",
      " ͶͶͶͶͶͶ         ",
      "ͶͶ     ͶͶͶͶ     ",
      "  Ͷ   Ͷ    Ͷ    ",
      "   Ͷ Ͷ      Ͷ   ",
      "   Ͷ Ͷ      Ͷ   ",
      "   Ͷ Ͷ      Ͷ   ",
      "   Ͷ Ͷ      Ͷ   ",
      "  Ͷ   Ͷ    Ͷ    "
    ],
    [
      "           !Ͷ!  ",
      "            Ͷ   ",
      "            Ͷ   ",
      "           Ͷ    ",
      "           Ͷ    ",
      "          Ͷ     ",
      "         Ͷ      ",
      "Ͷ      ͶͶ       ",
      " ͶͶͶͶͶͶ         ",
      "ͶͶ     ͶͶͶͶ     ",
      "  Ͷ   Ͷ    Ͷ    ",
      "   Ͷ Ͷ      Ͷ   ",
      "   Ͷ Ͷ      Ͷ   ",
      "   Ͷ Ͷ      Ͷ   ",
      "   Ͷ Ͷ      Ͷ   ",
      "  Ͷ   Ͷ    Ͷ    "
    ],
    [
      "           !Ͷ!  ",
      "            Ͷ   ",
      "            Ͷ   ",
      "           Ͷ    ",
      "           Ͷ    ",
      "          Ͷ     ",
      "         Ͷ      ",
      "Ͷ      ͶͶ       ",
      " ͶͶͶͶͶͶ         ",
      "ͶͶ     ͶͶͶͶ     ",
      "  Ͷ   Ͷ    Ͷ    ",
      "   Ͷ Ͷ      Ͷ   ",
      "   Ͷ Ͷ      Ͷ   ",
      "   Ͷ Ͷ      Ͷ   ",
      "   Ͷ Ͷ      Ͷ   ",
      "  Ͷ   Ͷ    Ͷ    "
    ],
    [
      "           !Ͷ!  ",
      "            Ͷ   ",
      "            Ͷ   ",
      "           Ͷ    ",
      "           Ͷ    ",
      "          Ͷ     ",
      "         Ͷ      ",
      "Ͷ      ͶͶ       ",
      " ͶͶͶͶͶͶ         ",
      "ͶͶ     ͶͶͶͶ     ",
      "  Ͷ   Ͷ    Ͷ    ",
      "   Ͷ Ͷ      Ͷ   ",
      "   Ͷ Ͷ      Ͷ   ",
      "   Ͷ Ͷ      Ͷ   ",
      "   Ͷ Ͷ      Ͷ   ",
      "  Ͷ   Ͷ    Ͷ    "
    ],
    [
      "            Ͷ   ",
      "            Ͷ   ",
      "            Ͷ   ",
      "           Ͷ    ",
      "           Ͷ    ",
      "          Ͷ     ",
      "         Ͷ      ",
      "Ͷ      ͶͶ       ",
      " ͶͶͶͶͶͶ         ",
      "ͶͶ     ͶͶͶͶ     ",
      "  Ͷ   Ͷ         ",
      "   Ͷ Ͷ          ",
      "   Ͷ Ͷ          ",
      "   Ͷ Ͷ          ",
      "   Ͷ Ͷ      Ͷ   ",
      "  Ͷ   Ͷ    Ͷ    "
    ]
  ]
}