{
  "name": "multi_workerquarters_0_base1",
  "refpalette": "deceasedcraft:multi_workerquarters_0/multi_workerquarters_0_base1_palette",
  "xsize": 16,
  "zsize": 16,
  "slices": [
    [
      "vvvvvvvvvvvvvvvv",
      "vzzzzzzzzzzzzzzz",
      "vzzzzzzzzzzzzzzz",
      "vzzzzzzzzzzzzzzz",
      "vzzzzzzzzzzzzzzz",
      "vzzzzzzzzzzzzzzz",
      "vzzzzzzzzzzzzzzz",
      "vzzzzzzzzzzzzzzz",
      "vzzzzzzzzzzzzzzz",
      "vzzzzzzzzzzzzzzz",
      "vzzzzzzzzzzzzzzz",
      "vzzzzzzzzzzzzzzz",
      "vzzzzzzzzzzzzzzz",
      "vzzzzzzzzzzzzzzz",
      "vzzzzzzzzzzzzzzz",
      "vvvvvvvvvvvvvvvv"
    ],
    [
      "vvvvvvvvvvvvvvvv",
      "vzzzzzzzzzzzzzzz",
      "vzzzzzzzzzzzzzzz",
      "vzzzzzzzzzzzzzzz",
      "vzzzzzzzzzzzzzzz",
      "vzzzzzzzzzzzzzzz",
      "vzzzzzzzzzzzzzzz",
      "vzzzzzzzzzzzzzzz",
      "vzzzzzzzzzzzzzzz",
      "vzzzzzzzzzzzzzzz",
      "vzzzzzzzzzzzzzzz",
      "vzzzzzzzzzzzzzzz",
      "vzzzzzzzzzzzzzzz",
      "vzzzzzzzzzzzzzzz",
      "vzzzzzzzzzzzzzzz",
      "vvvvvvvvvvvvvvvv"
    ],
    [
      "vvvvvvvvvvvvvvvv",
      "vzzzzzzzzzzzzzzz",
      "vzzzzzzzzzzzzzzz",
      "vzzzzzzzzzzzzzzz",
      "vzzzzzzzzzzzzzzz",
      "vzzzzzzzzzzzzzzz",
      "vzzzzzzzzzzzzzzz",
      "vzzzzzzzzzzzzzzz",
      "vzzzzzzzzzzzzzzz",
      "vzzzzzzzzzzzzzzz",
      "vzzzzzzzzzzzzzzz",
      "vzzzzzzzzzzzzzzz",
      "vzzzzzzzzzzzzzzz",
      "vzzzzzzzzzzzzzzz",
      "vzzzzzzzzzzzzzzz",
      "vvvvvvvvvvvvvvvv"
    ],
    [
      "vvvvvvvvvvvvvvvv",
      "vzzzzzzzzzzzzzzz",
      "vzzzzzzzzzzzzzzz",
      "vzzzzzzzzzzzzzzz",
      "vzzzzzzzzzzzzzzz",
      "vzzzzzzzzzzzzzzz",
      "vzzzzzzzzzzzzzzz",
      "vzzzzzzzzzzzzzzz",
      "vzzzzzzzzzzzzzzz",
      "vzzzzzzzzzzzzzzz",
      "vzzzzzzzzzzzzzzz",
      "vzzzzzzzzzzzzzzz",
      "vzzzzzzzzzzzzzzz",
      "vzzzzzzzzzzzzzzz",
      "vzzzzzzzzzzzzzzz",
      "vvvvvvvvvvvvvvvv"
    ],
    [
      "vvvvvvvvvvvvvvvv",
      "vzzzzzzzzzzzzzzz",
      "vzzzzzzzzzzzzzzz",
      "vzzzzzzzzzzzzzzz",
      "vzzzzzzzzzzzzzzz",
      "vzzzzzzzzzzzzzzz",
      "vzzzzzzzzzzzzzzz",
      "vzzzzzzzzzzzzzzz",
      "vzzzzzzzzzzzzzzz",
      "vzzzzzzzzzzzzzzz",
      "vzzzzzzzzzzzzzzz",
      "vzzzzzzzzzzzzzzz",
      "vzzzzzzzzzzzzzzz",
      "vzzzzzzzzzzzzzzz",
      "vzzzzzzzzzzzzzzz",
      "vvvvvvvvvvvvvvvv"
    ],
    [
      "vvvvvvvvvvvvvvvv",
      "vzzzzzzzzzzzzzzz",
      "vzzzzzzzzzzzzzzz",
      "vzzzzzzzzzzzzzzz",
      "vzzzzzzzzzzzzzzz",
      "vzzzzzzzzzzzzzzz",
      "vzzzzzzzzzzzzzzz",
      "vzzzzzzzzzzzzzzz",
      "vzzzzzzzzzzzzzzz",
      "vzzzzzzzzzz!zzzz",
      "vzzzzzzzzzzzzzzz",
      "vzzzzzzzzzzzzzzz",
      "vzzzzzzzzzzzzzzz",
      "vzzzzzzzzzzzzzzz",
      "vzzzzzzzzzzzzzzz",
      "vvvvvvvvvvvvvvvv"
    ]
  ]
}