{
  "name": "multi_workerquarters_0_ground",
  "refpalette": "deceasedcraft:multi_workerquarters_0/multi_workerquarters_0_ground_palette",
  "xsize": 16,
  "zsize": 16,
  "slices": [
    [
      "zzaazzzaazzzzazz",
      "zbbabbbabbbabbaa",
      "abzz=zz=!z=aaaaz",
      "zba=======zzzzzz",
      "zaa======z=zzzzz",
      "abzz==zzzzzzzzzz",
      "zbaz=zzzzzzzzzzz",
      "aaa=zzzzzzzzzz=z",
      "zazzzzzzzzzzzzz=",
      "z=zzzzzzzzzzzz==",
      "zaz=zzzzzzzzzzz=",
      "zzz=zzzzzzzzzzz=",
      "zzzzzzzzzzzzzzz=",
      "zzzzzzzzzzzzzzz=",
      "zzzzzzzzzzzzzzz=",
      "zzzzzzzzzzzzzzz="
    ],
    [
      "cc  c dddc cedc ",
      " ffffffffffffff ",
      "dfdd    g       ",
      " fd    h   e ci ",
      "cf     j c  c i ",
      " fdc  c       i ",
      "efdc   c  c  c  ",
      "d          k    ",
      "d clmmmmmmmmmmmn",
      "c  loppqqqororon",
      "   loppqqqororrs",
      "c  loppqqqororon",
      "c dlmmmmmmmmmmmn",
      " cdddt          ",
      " edd            ",
      "   c c   dccdde "
    ],
    [
      "      dd    ~   ",
      " ffffffffffffff ",
      " fd             ",
      " f     h   ~    ",
      " f              ",
      " f              ",
      "~f              ",
      "     u w        ",
      "   lxmymymxmymxn",
      "   Ar    BrCDErF",
      "    y    IJKL M ",
      "   Ar  NOPrQQQrF",
      "   lxmymymxmymxn",
      "   d            ",
      " ~              ",
      "             d~ "
    ],
    [
      "                ",
      "                ",
      "                ",
      "       h        ",
      "                ",
      "                ",
      "                ",
      "                ",
      "   lxmymymxmRmxn",
      "   ArS    rT UrF",
      "    y     V   W ",
      "   Ar    or X rF",
      "   lxmymymxmymxn",
      "                ",
      "                ",
      "                "
    ],
    [
      "                ",
      "                ",
      "                ",
      "       h        ",
      "                ",
      "                ",
      "                ",
      "                ",
      "   lxmymymxmymxn",
      "   ArY   Zr   rF",
      "    R  0  1 2 1 ",
      "   Ar    3r   rF",
      "   lxmymymxmymxn",
      "                ",
      "                ",
      "                "
    ],
    [
      "                ",
      "       4        ",
      "      555       ",
      "      5h5       ",
      "      555       ",
      "      5 5       ",
      "      5 5       ",
      "     65 5       ",
      "   lmmmmmmmmmmmn",
      "   l7r7r7r7r7r7n",
      "   l7r7r7r7r7r7n",
      "   l7r7r7r7r7r7n",
      "   lmmmmmmmmmmmn",
      "                ",
      "                ",
      "                "
    ]
  ]
}