{
  "name": "multi_workerquarters_0_top",
  "refpalette": "deceasedcraft:multi_workerquarters_0/multi_workerquarters_0_top_palette",
  "xsize": 16,
  "zsize": 16,
  "slices": [
    [
      "                ",
      "     aaaaa      ",
      "     bcccbdd    ",
      "     be!ebdd    ",
      "     bcccbdd    ",
      "     beeebdd    ",
      "     bcccbdd    ",
      "     beeebdd    ",
      "  dddbcccbdddddd",
      "  ddfbeeebfddddd",
      "  ddfbcccbfddghh",
      "  ddfbeeebfddfij",
      "  dddbcccbdddfij",
      "     kkkkkdddfij",
      "          dddghh",
      "                "
    ],
    [
      "                ",
      "     al la      ",
      "     menemop    ",
      "     bqrqbst    ",
      "     uw wu t    ",
      "     bx xbst    ",
      "     nq qn t    ",
      "     bw wbst    ",
      "  yoonx xn  oooo",
      "  A  bB  b      ",
      "  A          gCh",
      "  A  bDEFb   IjJ",
      "  KLLmenem      ",
      "     kM MkANOIjJ",
      "          KLPgCh",
      "                "
    ],
    [
      "                ",
      "     al la      ",
      "     menem      ",
      "     bqQqbR     ",
      "     uw wu      ",
      "     bx xbR     ",
      "     nq qn      ",
      "     bw wbR     ",
      "     nx xn      ",
      "     b  Sb      ",
      "             gCh",
      "     bTUVb   Ij ",
      "     menem      ",
      "     kM Mk   IjW",
      "             gCh",
      "                "
    ],
    [
      "                ",
      "     al la      ",
      "     menem      ",
      "     b   bR     ",
      "     uX Yu      ",
      "     b Z bR     ",
      "     n   n      ",
      "     b   bR     ",
      "     n   n      ",
      "     b Z b      ",
      "     n   n   gCh",
      "     b 0 b   Ij ",
      "     menem1  123",
      "     kM Mk   Ij ",
      "             gCh",
      "                "
    ],
    [
      "                ",
      "     aaaaa      ",
      "     b444b      ",
      "     beeeb      ",
      "     b444b      ",
      "     beeeb      ",
      "     b444b      ",
      "     beeeb      ",
      "     b444b      ",
      "     beeeb      ",
      "     b444b   ghh",
      "     beeeb   g5j",
      "     b444b   g5j",
      "     kkkkk   g5j",
      "             ghh",
      "                "
    ]
  ]
}