{
  "name": "multi_gallery_0_ground",
  "refpalette": "deceasedcraft:multi_gallery_0/multi_gallery_0_ground_palette",
  "xsize": 16,
  "zsize": 16,
  "slices": [
    [
      "aaaaaaaaaaaaaaab",
      "aaaaaaaaaaaaaaab",
      "aaaaaaaaaaaaaabb",
      "aaaaaaaaaaaaaabb",
      "aaaaaaaaaaaaabbb",
      "aaaaaaaaaaaaabbb",
      "aaaaaaaaaaaabbbb",
      "aaaaaaaaaaaabbba",
      "aaaaaaaaaaabbbba",
      "aaaaaaaaaaabbbaa",
      "aaaaaaaaaabbbbac",
      "aaaaaaaaaabbbaac",
      "aaaaaaaaabbbbac ",
      "aaaaaaaaabbbaac ",
      "aaaaaaaabbbbac  ",
      "aaaaaaaabbbaac  "
    ],
    [
      "                ",
      "                ",
      "                ",
      "                ",
      "                ",
      "                ",
      "                ",
      "               d",
      "               d",
      "              dd",
      "              d ",
      "             dde",
      "             d  ",
      "            dde ",
      "            d   ",
      "           dde  "
    ],
    [
      "                ",
      "                ",
      "                ",
      "                ",
      "                ",
      "                ",
      "                ",
      "                ",
      "                ",
      "                ",
      "                ",
      "               f",
      "                ",
      "              f ",
      "                ",
      "             f  "
    ],
    [
      "                ",
      "                ",
      "                ",
      "                ",
      "                ",
      "                ",
      "                ",
      "                ",
      "                ",
      "                ",
      "                ",
      "               f",
      "                ",
      "              f ",
      "                ",
      "             g  "
    ],
    [
      "                ",
      "                ",
      "                ",
      "                ",
      "                ",
      "                ",
      "                ",
      "                ",
      "                ",
      "                ",
      "                ",
      "               f",
      "                ",
      "              g ",
      "             hii",
      "             jkk"
    ],
    [
      "                ",
      "                ",
      "                ",
      "                ",
      "                ",
      "                ",
      "                ",
      "                ",
      "                ",
      "                ",
      "                ",
      "               g",
      "              hi",
      "              jk",
      "             jll",
      "             j  "
    ]
  ]
}