{
  "name": "multi_gallery_0_base2",
  "refpalette": "deceasedcraft:multi_gallery_0/multi_gallery_0_base2_palette",
  "xsize": 16,
  "zsize": 16,
  "slices": [
    [
      "vvvvvvvvvvvvvvvv",
      "vaaaaaaaaaaaaaaa",
      "vaaaaaaaaaaaaaaa",
      "vaaaaaaaaaaaaaaa",
      "vaaaaaaaaaaaaaaa",
      "vaaaaaaaaaaaaaaa",
      "vaaaaaaaaaaaaaaa",
      "vaaaaaaaaaaaaaaa",
      "vaaaaaaaaaaaaaaa",
      "vaaaaaaaaaaaaaaa",
      "vaaaaaaaaaaaaaaa",
      "vaaaaaaaaaaaaaaa",
      "vaaaaaaaaaaaaaaa",
      "vaaaaaaaaaaaaaaa",
      "vaaaaaaaaaaaaaaa",
      "vaaaaaaaaaaaaaaa"
    ],
    [
      "vvvvvvvvvvvvvvvv",
      "vaaaaaaaaaaaaaaa",
      "vaaaaaaaaaaaaaaa",
      "vaaaaaaaaaaaaaaa",
      "vaaaaaaaaaaaaaaa",
      "vaaaaaaaaaaaaaaa",
      "vaaaaaaaaaaaaaaa",
      "vaaaaaaaaaaaaaaa",
      "vaaaaaaaaaaaaaaa",
      "vaaaaaaaaaaaaaaa",
      "vaaaaaaaaaaaaaaa",
      "vaaaaaaaaaaaaaaa",
      "vaaaaaaaaaaaaaaa",
      "vaaaaaaaaaaaaaaa",
      "vaaaaaaaaaaaaaaa",
      "vaaaaaaaaaaaaaaa"
    ],
    [
      "vvvvvvvvvvvvvvvv",
      "vbbbbbbbbbbbbbbb",
      "vbcccccaaaaaaaaa",
      "vbcccccaaaaaaaaa",
      "vbcccccaaaaaaaaa",
      "vbcccccaaaaaaaaa",
      "vbcccccaaaaaaaaa",
      "vbcccccaaaaaaaaa",
      "vbcccccaaaaaaaaa",
      "vbcccccaaaaaaaaa",
      "vbcccccaaaaaaaaa",
      "vbcccccaaaaaaaaa",
      "vbcccccaaaaaaaaa",
      "vbcccccaaaaaaaaa",
      "vbcccccaaaaaaaaa",
      "vbcccccaaaaaaaaa"
    ],
    [
      "vvvvvvvvvvvvvvvv",
      "vddddddddddddddd",
      "vefg   hiiiiiiii",
      "vefj   hiiiiiiii",
      "vkl    miiiiiiii",
      "vnoop qriiiiiiii",
      "vns t qmiiiiiiii",
      "vnoop qriiiiiiii",
      "vns t qmiiiiiiii",
      "vnoop qriiiiiiii",
      "vns t qmiiiiiiii",
      "vnoop qriiiiiiii",
      "vns t  miiiiiiii",
      "vddddudriiiiiiii",
      "vdwx  ymiiiiiiii",
      "vdAA  yriiiiiiii"
    ],
    [
      "vvvvvvvvvvvvvvvv",
      "vddddddddddddddd",
      "vef             ",
      "vef             ",
      "vkBC  DEl       ",
      "vnoop  FI       ",
      "vn  J KEL       ",
      "vnoop MFN       ",
      "vn  J KEO       ",
      "vnoop MFI       ",
      "vn  J KEL       ",
      "vnoop MFN       ",
      "vn  J  EO       ",
      "vddddPdFI       ",
      "vd    QEl       ",
      "vd    RF        "
    ],
    [
      "vvvvvvvvvvvvvvvv",
      "vddddddddddddddd",
      "vef             ",
      "vef             ",
      "vk     mB       ",
      "vnoop Sr!       ",
      "vn  p Tm        ",
      "vnoop Tr        ",
      "vn  p Tm        ",
      "vnoop TrU       ",
      "vn  p Tm        ",
      "vnoop Vr        ",
      "vn  p  m        ",
      "vddddddrW       ",
      "vdX   YmB       ",
      "vdZ   0r        "
    ]
  ]
}