{
  "name": "multi_gallery_0_base1",
  "refpalette": "deceasedcraft:multi_gallery_0/multi_gallery_0_base1_palette",
  "xsize": 16,
  "zsize": 16,
  "slices": [
    [
      "vvvvvvvvvvvvvvvv",
      "vaaaaaaaaaaaaaaa",
      "vbc             ",
      "vbc             ",
      "vd     e        ",
      "vfggh  i        ",
      "vf  h  e        ",
      "vfggh  i        ",
      "vf  h  e        ",
      "vfggh  i        ",
      "vf  h  e        ",
      "vfggh  i        ",
      "vf  h  e        ",
      "vaaaaaai        ",
      "va!   je        ",
      "vak   li        "
    ],
    [
      "vvvvvvvvvvvvvvvv",
      "vaaaaaaaaaaaaaaa",
      "vbc   mc        ",
      "vbc   mc        ",
      "vd     n        ",
      "vfggh  o        ",
      "vf  h  n        ",
      "vfggh  o        ",
      "vf  h  n        ",
      "vfggh  o        ",
      "vf  h  n        ",
      "vfggh  o        ",
      "vf  h  n        ",
      "vaaaaaao        ",
      "vap    n        ",
      "vaq    o        "
    ],
    [
      "vvvvvvvvvvvvvvvv",
      "vaaaaaaaaaaaaaaa",
      "vbc   mc        ",
      "vbc   mc        ",
      "vd     e        ",
      "vfrrr  i        ",
      "vf  r  e        ",
      "vf  r  i        ",
      "vf  r  e        ",
      "vf  r  i        ",
      "vf  r  e        ",
      "vf  r  i        ",
      "vf  r  e        ",
      "vaaaaaai        ",
      "vak    e        ",
      "vas    i        "
    ],
    [
      "vvvvvvvvvvvvvvvv",
      "vaaaaaaaaaaaaaaa",
      "vbtuuuwc       x",
      "vbtuuuwc       x",
      "vd     n        ",
      "vffffffo        ",
      "vfyffffn        ",
      "vffffffo        ",
      "vfyffffn        ",
      "vffffffo        ",
      "vfyffffn        ",
      "vffffffo        ",
      "vfyffffn        ",
      "vaaaaaao        ",
      "va     n        ",
      "va     o        "
    ],
    [
      "vvvvvvvvvvvvvvvv",
      "vaAAAAAaaaaaaaaa",
      "vd     c       a",
      "vd     c       a",
      "vdB    e        ",
      "vfCDDDDi        ",
      "vfEEEEEe        ",
      "vfFF  Ei        ",
      "vfEEEEEe        ",
      "vfF FFEi        ",
      "vfEEEEEe        ",
      "vfF   Ei        ",
      "vfEEEEEe        ",
      "vaaaaaEi        ",
      "va    Ee        ",
      "va    Ei        "
    ],
    [
      "vvvvvvvvvvvvvvvv",
      "vaaaaaaaaaaaaaaa",
      "vadddddDDDDDDDDa",
      "vadddddDDDDDDDDa",
      "vadddddaDDDDDDDD",
      "vaDDDDDaDDDDDDDD",
      "vaDDDDDaDDDDDDDD",
      "vaDDDDDaDDDDDDDD",
      "vaDDDDDaDDDDDDDD",
      "vaDDDDDaDDDDDDDD",
      "vaDDDDDaDDDDDDDI",
      "vaDDDDDaDDDDDDDI",
      "vaDDDDDaDDDDDDI ",
      "vaDDDDDaDDDDDDI ",
      "vaDDDDDaDDDDDI  ",
      "vaDDDDDaDDDDDI  "
    ]
  ]
}