{
  "name": "multi_flatlarge_0_floor2",
  "refpalette": "deceasedcraft:multi_flatlarge_0/multi_flatlarge_0_floor2_palette",
  "xsize": 16,
  "zsize": 16,
  "slices": [
    [
      "                ",
      "                ",
      "                ",
      "   abbbbbbbbabbb",
      "  cddddddeeebeee",
      "  bddddddeeebeee",
      "  bddddddeeebeee",
      "  bddddddeeebeee",
      "  bdddddddddbddd",
      "  bdddddddddbddd",
      "  bdddddddddbddd",
      "  bdddddddddbddd",
      "  bdddddddddbddd",
      "  bdddddddddbddd",
      "  cfffffffffffff",
      "  gfffffffffffff"
    ],
    [
      "                ",
      "                ",
      "                ",
      "   abhhhhihbabhi",
      "  cjk   lh  b  h",
      "  bjm   nh obo h",
      "  cp    qh rbs h",
      "  c tt  uh wbx h",
      "  cyAA bbbBbbbCb",
      "  cD   E   FbI  ",
      "  cJ   b   KbL  ",
      "  cM  NbOP QbR S",
      "  cJ  TbOP QbR S",
      "  bU  Nb   VbW  ",
      "  cXXYXXXXXXZXXX",
      "  0             "
    ],
    [
      "                ",
      "                ",
      "                ",
      "   ab111hi1bab1i",
      "  c2 345 h 6b7 h",
      "  b2     h obo h",
      "  c8     h  b  h",
      "  19     h  b  h",
      "  c    bbb#bbb$b",
      "  c    %   FbI  ",
      "  c    b    b   ",
      "  19   b    b   ",
      "  c    b    b   ",
      "  b^   b    b   ",
      "  cXX&XXXXXX XXX",
      "                "
    ],
    [
      "                ",
      "                ",
      "                ",
      "   ab111hi1bab1i",
      "  c2 *() h +b- h",
      "  b2     h  b  h",
      "  c8     h  b  h",
      "  1[     h ]b{ h",
      "  c    bbb}bbb}b",
      "  c    c   FbI  ",
      "  c    b    b   ",
      "  1[  |b    b   ",
      "  c   |b    b   ",
      "  b   |b    b   ",
      "  cXX}XXXXXX XXX",
      "                "
    ],
    [
      "                ",
      "                ",
      "                ",
      "   abbbbbbbbabbb",
      "  c      b;;b;;b",
      "  b      b;;b;;b",
      "  b:     b;;b;;b",
      "  b      b;;b;;b",
      "  b    bbbbbbbbb",
      "  b    b    b   ",
      "  b    b    b   ",
      "  b    b    b   ",
      "  b    b    b   ",
      "  b    b    b   ",
      "  cXXXXXXXXX XXX",
      "                "
    ],
    [
      "                ",
      "                ",
      "                ",
      "   a''''''''a'''",
      "  cfffffffffbfff",
      "  'fffffff  b  f",
      "  'fffffff <b< f",
      "  'fffffff  b  f",
      "  'fffffffffbfff",
      "  'fffffffffbfff",
      "  'fffffffffbfff",
      "  'fffffffffbfff",
      "  'fffffffffbfff",
      "  'fffffffffbfff",
      "  c>>>>>>>>>>>>>",
      "  ,............."
    ]
  ]
}