{
  "name": "multi_flatlarge_0_ground",
  "refpalette": "deceasedcraft:multi_flatlarge_0/multi_flatlarge_0_ground_palette",
  "xsize": 16,
  "zsize": 16,
  "slices": [
    [
      "HHHHHHHHHHHHHHHH",
      "HHHHHHHHHHHHHHHH",
      "HHHaaaaaaaaaaaaa",
      "HHabbbbbbbbbbbbb",
      "HHacddddddddcddd",
      "HHabdddddddddddd",
      "HHabdddddddddddd",
      "HHabdddddddddddd",
      "HHabdddddddddddd",
      "HHabdddddddddddd",
      "HHabdddddddddddd",
      "HHabdddddddddddd",
      "HHabdddddddddddd",
      "HHabdddddddddddd",
      "HHacddddddddcddd",
      "HHaccccccccccccc"
    ],
    [
      "                ",
      "                ",
      "                ",
      "   eeeeeeeeeeeee",
      "   fghghghghfghg",
      "   e            ",
      "   e            ",
      "   eijijijij iji",
      "   e            ",
      "   e            ",
      "   e            ",
      "   e    ghgh ghg",
      "   e            ",
      "   e            ",
      "   f    ijijfiji",
      "   klklkkklllkkl"
    ],
    [
      "                ",
      "                ",
      "                ",
      "                ",
      "   m        m   ",
      "                ",
      "                ",
      "                ",
      "                ",
      "                ",
      "                ",
      "                ",
      "                ",
      "                ",
      "   m        m   ",
      "                "
    ],
    [
      "                ",
      "                ",
      "                ",
      "                ",
      "   m        m   ",
      "                ",
      "                ",
      "                ",
      "                ",
      "                ",
      "                ",
      "                ",
      "                ",
      "                ",
      "   m        m   ",
      "                "
    ],
    [
      "                ",
      "                ",
      "                ",
      "                ",
      "   mnnnnnnnnmnnn",
      "   o        p   ",
      "   o        p   ",
      "   o        p   ",
      "   o        p   ",
      "   o        p   ",
      "   o        p   ",
      "   o        p   ",
      "   o        p   ",
      "   o        p   ",
      "   mppppppppmppp",
      "   o            "
    ],
    [
      "                ",
      "                ",
      "                ",
      "  pppppppppppppp",
      "  pqqqqqqqqqqqqq",
      "  pqrrrrrrrrqrrr",
      "  pqrrrrrrrrqrrr",
      "  pqrrrrrrrrqrrr",
      "  pqrrrrrrrrqrrr",
      "  pqrrrrrrrrqrrr",
      "  pqrrrrrrrrqrrr",
      "  pqrrrrrrrrqrrr",
      "  pqrrrrrrrrqrrr",
      "  pqrrrrrrrrqrrr",
      "  pqqqqqqqqqqqqq",
      "  pqrrrrrrrrqrrr"
    ]
  ]
}