{
  "name": "multi_sunkenmonumentpark_4_base1",
  "refpalette": "deceasedcraft:multi_sunkenmonumentpark_4/multi_sunkenmonumentpark_4_base1_palette",
  "xsize": 16,
  "zsize": 16,
  "slices": [
    [
      "vvvvvvvvvvvvvvvv",
      "aaaaaaaaaaaaaaaa",
      "aaaaaaaaaaaaaaaa",
      "aaaaaaaaaaaaaaaa",
      "aaaaaaaaaaaaaaaa",
      "aaaaaaaaaaaaaaaa",
      "aaaaaaaaaaaaaaaa",
      "aaaaaaaaaaaaaaaa",
      "aaaaaaaaaaaaaaaa",
      "aaaaaaaaaaaaaaaa",
      "aaaaaaaaaaaaaaaa",
      "aaaaaaaaaaaaaaaa",
      "aaaaaaaaaaaaaaaa",
      "aaaaaaaaaaaaaaaa",
      "aaaaaaaaaaaaaaaa",
      "aaaaaaaaaaaaaaaa"
    ],
    [
      "vvvvvvvvvvvvvvvv",
      "aaaaaaaaaaaaaaaa",
      "aaaaaaaaaaaaaaaa",
      "aaaaaaaaaaaaaaaa",
      "aaaaaaaaaaaaaaaa",
      "aaaaaaaaaaaaaaaa",
      "aaaaaaaaaaaaaaaa",
      "aaaaaaaaaaaaaaaa",
      "aaaaaaaaaaaaaaaa",
      "aaaaaaaaaaaaaaaa",
      "aaaaaaaaaaaaaaaa",
      "aaaaaaaaaaaaaaaa",
      "aaaaaaaaaaaaaaaa",
      "aaaaaaaaaaaaaaaa",
      "aaaaaaaaaaaaaaaa",
      "aaaaaaaaaaaaaaaa"
    ],
    [
      "vvvvvvvvvvvvvvvv",
      "aaaaaaaaaaaaaaaa",
      "aaaaaaaaaaaaaaaa",
      "aaaaaaaaaaaaaaaa",
      "aaaaaaaaaaaaaaaa",
      "aaaaaaaaaaaaaaaa",
      "aaaaaaaaaaaaaaaa",
      "aaaaaaaaaaaaaaaa",
      "aaaaaaaaaaaaaaaa",
      "aaaaaaaaaaaaaaaa",
      "aaaaaaaaaaaaaaaa",
      "aaaaaaaaaaaaaaaa",
      "aaaaaaaaaaaaaaaa",
      "aaaaaaabbbbbbbcc",
      "aaaabbbbbbbbbbcc",
      "aaabbbbbbbbbbbcc"
    ],
    [
      "vvvvvvvvvvvvvvvv",
      "aaaaaaaaaaaddddd",
      "aaaaaaaaaaaddddd",
      "aaaaaaaaaaaddddd",
      "aaaaaaaaaaaddddd",
      "aaaaaaaaaaaddddd",
      "aaaaaaaaaaaaaaaa",
      "aaaaaaaaaaaaaaaa",
      "aaaaaaaaaaaaaaaa",
      "aaaaaaaaaaaaaaaa",
      "aabbbbbbbbbbbbcc",
      "bbbbbbbbbbbbbbcc",
      "bbbbbbbbbbbbbbcc",
      "bbbbbbbeeeeeeeff",
      "bbbbeee       gg",
      "bbbe    hh      "
    ],
    [
      "vvvvvvvvvvvvvvvv",
      "           ddddd",
      "           ddddd",
      "           ddddd",
      "           ddddd",
      "           ddddd",
      "           dddcc",
      "bbbbbbbbbbbbbbcc",
      "bbbbbbbbbbbbbbcc",
      "bbbbbbbbbbbbbbcc",
      "bbeeeeeeeeeeeeff",
      "ee  i         gg",
      "   h h ih h     ",
      "  ih            ",
      " i              ",
      " h              "
    ],
    [
      "vvvvvvvvvvvvvvvv",
      "           ddddd",
      "           ddddd",
      "           ddddd",
      "bbbbbbbbbbbddddd",
      "bbbbbbbbbbbdddcc",
      "bbbbbbbbbbbdddcc",
      "eeeeeeeeeeedddff",
      "  j     i  kl gg",
      " i   i    h     ",
      " h              ",
      "    m           ",
      "       m        ",
      "  m             ",
      " m              ",
      "                "
    ]
  ]
}