{
  "name": "multi_sunkenmonumentpark_4_ground",
  "refpalette": "deceasedcraft:multi_sunkenmonumentpark_4/multi_sunkenmonumentpark_4_ground_palette",
  "xsize": 16,
  "zsize": 16,
  "slices": [
    [
      "aaaaaaaaaaaabbcc",
      "aaaaaaaaaaaabbcc",
      "ddddddddddaabbcc",
      "dddddddddddabbcc",
      "eeeeeeeeeeeabbff",
      "    g g  g aaahh",
      "g     i i  aaa  ",
      "           aaa  ",
      "  j     k  aaa  ",
      " k   k    aaal  ",
      "          lmmm  ",
      "    n     mm    ",
      "       n        ",
      "  n             ",
      " n              ",
      "                "
    ],
    [
      "                ",
      "   i            ",
      "g  igo          ",
      "    i   g  p    ",
      "           p    ",
      "    k k  k pqq  ",
      "k          aqq  ",
      "           aqq  ",
      "  k     n  abb  ",
      " n   n    abbb  ",
      "          abbb  ",
      "    n     aaaa  ",
      "       n aaaaa  ",
      "  n      aaaaa  ",
      " n       aaammmm",
      "        mmmmmmmm"
    ],
    [
      "                ",
      "                ",
      "k   kj          ",
      "        k       ",
      "                ",
      "    n n  n      ",
      "n          p    ",
      "           p    ",
      "  n     n  p    ",
      " n   n    r     ",
      "          p     ",
      "    s     pqqq  ",
      "       s aqqqq  ",
      "  n      aqqqq  ",
      " s       abbbbaa",
      "        abbbbbbb"
    ],
    [
      "                ",
      "                ",
      "n   nk          ",
      "        n       ",
      "                ",
      "    n n  n      ",
      "n               ",
      "                ",
      "  n     s       ",
      " s              ",
      "                ",
      "                ",
      "         r      ",
      "  s      p    tt",
      "         p     u",
      "        r       "
    ],
    [
      "                ",
      "                ",
      "n   nn          ",
      "        n       ",
      "                ",
      "    s n  s      ",
      "s               ",
      "                ",
      "  s             ",
      "                ",
      "                ",
      "                ",
      "                ",
      "                ",
      "                ",
      "                "
    ],
    [
      "                ",
      "                ",
      "s    n          ",
      "        s       ",
      "                ",
      "      s         ",
      "                ",
      "                ",
      "                ",
      "                ",
      "                ",
      "                ",
      "                ",
      "                ",
      "                ",
      "                "
    ]
  ]
}