{
  "name": "multi_workerquarters_1_top",
  "refpalette": "deceasedcraft:multi_workerquarters_1/multi_workerquarters_1_top_palette",
  "xsize": 16,
  "zsize": 16,
  "slices": [
    [
      "                ",
      "                ",
      "                ",
      "                ",
      "                ",
      "                ",
      "                ",
      "                ",
      "aaaab           ",
      "aaaac           ",
      "dddddddddeaaafa ",
      "ghghghghgiaaaaa ",
      "ghghghghjiaaaaa ",
      "ghghghghgiaaaaa ",
      "dddddddddeaaafa ",
      "                "
    ],
    [
      "                ",
      "                ",
      "                ",
      "                ",
      "                ",
      "                ",
      "                ",
      "                ",
      "kkkk            ",
      "                ",
      "ldmdndldmekkkko ",
      "p qrrstuh    wx ",
      "             yx ",
      "pABCDstuhE   Fx ",
      "ldmdndldmeIIIIJ ",
      "                "
    ],
    [
      "                ",
      "                ",
      "                ",
      "                ",
      "                ",
      "                ",
      "                ",
      "                ",
      "                ",
      "                ",
      "ldmdndldme      ",
      "  !  stuh       ",
      "             K  ",
      " ABLMstuh       ",
      "ldmdndldme      ",
      "                "
    ],
    [
      "                ",
      "                ",
      "                ",
      "                ",
      "                ",
      "                ",
      "                ",
      "                ",
      "                ",
      "                ",
      "ldndndldme      ",
      "N     N h       ",
      " O   P  n       ",
      "Q R   Q h       ",
      "ldndndldme      ",
      "                "
    ],
    [
      "                ",
      "                ",
      "                ",
      "                ",
      "                ",
      "                ",
      "                ",
      "                ",
      "                ",
      "                ",
      "ddddddddde      ",
      "ShShShShSe      ",
      "ShShShShSe      ",
      "ShShShShSe      ",
      "ddddddddde      ",
      "                "
    ]
  ]
}