{
  "name": "multi_workerquarters_1_ground",
  "refpalette": "deceasedcraft:multi_workerquarters_1/multi_workerquarters_1_ground_palette",
  "xsize": 16,
  "zsize": 16,
  "slices": [
    [
      "zzzzzzzaaazzaazz",
      "azzzaabbbaabbaaz",
      "zzzzzaazz=aazabz",
      "zzzzzzz===z==zbz",
      "zzzzzzzz!z====ba",
      "zzzzzzzzzzzz=zba",
      "zzzzzzzzzzzzz=aa",
      "=zz=zzzzzzz=zzaz",
      "z==zzz=z=====zzz",
      "====zzz=====zzzz",
      "===zzzzzzzzzzzzz",
      "===zzzzzzzzzzzzz",
      "===zzzzzzzzzzzzz",
      "===zzzzzzzzzzzzz",
      "=z=zzzzzzzzzzzzz",
      "z=z==zzzzzzzzzzz"
    ],
    [
      "    ccdd   c dd ",
      "   c   eeeeeeee ",
      " f     gc  dddec",
      "   h     ic  deg",
      " j k  c lm    e ",
      "    cc ino p cdd",
      " qc             ",
      "    r   s    c c",
      "c        t   du ",
      "    wwp  x  ddd ",
      "  yAAAAAAAAAAAB ",
      "  yACCCCCCCCCABc",
      "  DCCCCCCCCCCCBc",
      "  yACCCCCCCCCAB ",
      "  yAAAAAAAAAAABc",
      "  dd ddgc cc  c "
    ],
    [
      "       d     d  ",
      "       eeeeeeee ",
      "       ~    dde ",
      "              e~",
      "         E    e ",
      "        F       ",
      "                ",
      "                ",
      "        t       ",
      "        x    d  ",
      "  yIAJKKKKKJAIB ",
      "  LCM       NCO ",
      "   P        QI  ",
      "  LC!RSTUVVTWCO ",
      "  yIAIAIAIAIAIB ",
      "   d   ~        "
    ],
    [
      "                ",
      "                ",
      "             d  ",
      "                ",
      "                ",
      "                ",
      "                ",
      "                ",
      "       t        ",
      "       x        ",
      "  yIAJKKKKKJAIB ",
      "  LCX       YCO ",
      "   Z         I  ",
      "  LC0 12 3456CO ",
      "  yIA7A7A7AIAIB ",
      "        8       "
    ],
    [
      "                ",
      "                ",
      "                ",
      "                ",
      "                ",
      "                ",
      "                ",
      "                ",
      "      t         ",
      "      x         ",
      "  yIAJKKKKKJAIB ",
      "  LC        9CO ",
      "   7  #   # 9I  ",
      "  LC    $   %CO ",
      "  yIA7A7^7A7AIB ",
      "        ^       "
    ],
    [
      "                ",
      "                ",
      "                ",
      "                ",
      "                ",
      "                ",
      "                ",
      "                ",
      "     t          ",
      "     x          ",
      "  yAAAAAAAAAAAB ",
      "  y&C&C&C&C&C&B ",
      "  y&C&C&C&C&C&B ",
      "  y&C&C&C&C&C&B ",
      "  yAAAAAAAAAAAB ",
      "        *       "
    ]
  ]
}