{
  "name": "multi_laboratory_10_top",
  "refpalette": "deceasedcraft:multi_laboratory_10/multi_laboratory_10_top_palette",
  "xsize": 16,
  "zsize": 16,
  "slices": [
    [
      "                ",
      "                ",
      "abbba           ",
      "cdcccbb         ",
      "ceccccb         ",
      "fffffgga        ",
      "    fggb        ",
      "    fggb        ",
      "    fhdb        ",
      "    fggb        ",
      "    fggb        ",
      "    fggb        ",
      "  iifggb        ",
      "jjjjfgga        ",
      "jjjjfggb        ",
      "kkkkfhdl        "
    ],
    [
      "                ",
      "                ",
      "bbbbb           ",
      "     ba         ",
      "      b         ",
      "mfmmn  b        ",
      "    m  b        ",
      "    m  b        ",
      "    f  b        ",
      "    m  a        ",
      "    m  b        ",
      "    m  b        ",
      "    m  b        ",
      "    m  b        ",
      "    m  a        ",
      "opppf  b        "
    ],
    [
      "                ",
      "                ",
      "bbabb           ",
      "     ba         ",
      "      b         ",
      "qfmmn  b        ",
      "    m  b        ",
      "    m  b        ",
      "    f  b        ",
      "    q  b        ",
      "    m  b        ",
      "    m  b        ",
      "    m  b        ",
      "    m  b        ",
      "    q  b        ",
      "rpppf  b        "
    ],
    [
      "                ",
      "                ",
      "bbbbb           ",
      "     bb         ",
      "      b         ",
      "qfmmn  b        ",
      "    m  b        ",
      "    m  b        ",
      "    f  b        ",
      "    q  b        ",
      "    m  b        ",
      "    m  a        ",
      "    m  b        ",
      "    m  b        ",
      "    q  b        ",
      "spppf  b        "
    ],
    [
      "                ",
      "                ",
      "bbbba           ",
      "     bb         ",
      "      b         ",
      "qfmmn  b        ",
      "    m  b        ",
      "    m  b        ",
      "    f  b        ",
      "    q  b        ",
      "    m  b        ",
      "    m  b        ",
      "    m  b        ",
      "    m  b        ",
      "    q  b        ",
      "ppppf  b        "
    ],
    [
      "                ",
      "                ",
      "babbb           ",
      "     bb         ",
      "      b         ",
      "fffff  b        ",
      "ttttf  b        ",
      "ttttf  b        ",
      "ttttf  b        ",
      "ttttf  b        ",
      "ttttf  b        ",
      "ttttf  b        ",
      "ttttf  b        ",
      "ttttf  b        ",
      "ttttf  b        ",
      "fffff  b        "
    ],
    [
      "                ",
      "                ",
      "bbbbb           ",
      "     bb         ",
      "      b         ",
      "uuuuu  b        ",
      "    u  b        ",
      "www u  b        ",
      "  w u  b        ",
      "  w u  b        ",
      "x w u  b        ",
      "  w u  y        ",
      "  w u  y        ",
      "www u  y        ",
      "    u           ",
      "uuuuu           "
    ],
    [
      "                ",
      "                ",
      "bbbbb           ",
      "     bb         ",
      "      b         ",
      "       y        ",
      "       y        ",
      "       y        ",
      "                ",
      "                ",
      "                ",
      "                ",
      "                ",
      "                ",
      "                ",
      "                "
    ]
  ]
}