{
  "name": "multi_laboratory_10_base3",
  "refpalette": "deceasedcraft:multi_laboratory_10/multi_laboratory_10_base3_palette",
  "xsize": 16,
  "zsize": 16,
  "slices": [
    [
      "vvvvvvvvvvvvvvvv",
      "aaaaaaaaaaaaaaav",
      "bbbbbbbbbbbbbcav",
      "    d========cav",
      "    d========cav",
      "ddddd========cav",
      "    d========cav",
      "    d========cav",
      "    d========cav",
      "    d========cav",
      "    d========cav",
      " e  d========cav",
      " effd========cav",
      "ggggd========cav",
      "ggggd========cav",
      "dddddhhhhhhhhcav"
    ],
    [
      "vvvvvvvvvvvvvvvv",
      "aaaaaaaaaaaaaaav",
      "bbbbbbbbbbbbbcav",
      "    ijk    lmbav",
      "    in      obav",
      "iiiidp       bav",
      "    iq      mbav",
      "    ir      obav",
      "    ir      qbav",
      "    i      lmbav",
      "    is      obav",
      "gg  it      qbav",
      "ffu i       !bav",
      "    i       wbav",
      "    x       wbav",
      "yiiidiiiiiiiicav"
    ],
    [
      "vvvvvvvvvvvvvvvv",
      "aaaaaaaaaaaaaaav",
      "bbbbbbbbbbbbbcav",
      "    i      lmbav",
      "    i        bav",
      "iiiidp      qbav",
      "    iq     lmbav",
      "    iq       bav",
      "    i       qbav",
      "gg  i       mbav",
      "ffu i        bav",
      "  u i       qbav",
      "    i        bav",
      "    i       Abav",
      "    B       Cbav",
      "Diiidiiiiiiiicav"
    ],
    [
      "vvvvvvvvvvvvvvvv",
      "aaaaaaaaaaaaaaav",
      "bbbbbbbbbbbbbcav",
      "    i       pbav",
      "    i        bav",
      "iiiidp      qbav",
      "ggggiq      pbav",
      "ggggi        bav",
      "ffu i       qbav",
      "  u i       pbav",
      "    i        bav",
      "    i       qbav",
      "    i        bav",
      "    i        bav",
      "    i       Ebav",
      "Fiiidiiiiiiiicav"
    ],
    [
      "vvvvvvvvvvvvvvvv",
      "aaaaaaaaaaaaaaav",
      "bbbbbbbbbbbbbcav",
      "    ip      Ibav",
      "    ip      pbav",
      "iiiidp      pbav",
      "    ip      Ibav",
      "    iJK     pbav",
      " effiJK     pbav",
      "  ggiJK     Ibav",
      "    iJK     pbav",
      "    ip      pbav",
      "    ippppppppbav",
      "    i       pbav",
      "    i       pbav",
      "iiiidiiiiiiiicav"
    ],
    [
      "vvvvvvvvvvvvvvvv",
      "aaaaaaaaaaaaaaav",
      "bbbbbbbbbbbbbcav",
      "    iLLLLLLLLbav",
      "    iLLLLLLLLbav",
      "iiiidLLLLLLLLbav",
      "    iLLLLLLLLbav",
      "    iLLLLLLLLbav",
      "    iLLLLLLLLbav",
      " e  iLLLLLLLLbav",
      " effiLLLLLLLLbav",
      "  ggiLLLLLLLLbav",
      "    iLLLLLLLLbav",
      "    iLLLLLLLLbav",
      "    iLLLLLLLLbav",
      "iiiidiiiiiiiicav"
    ]
  ]
}