{
  "name": "multi_laboratory_10_base1",
  "refpalette": "deceasedcraft:multi_laboratory_10/multi_laboratory_10_base1_palette",
  "xsize": 16,
  "zsize": 16,
  "slices": [
    [
      "vvvvvvvvvvvvvvvv",
      "aaaaaaaaaaaaaaav",
      "bbbbbbbbbbbbbcav",
      "    d========cav",
      "    d========cav",
      "ddddd========cav",
      "    d========cav",
      "    d========cav",
      "    d========cav",
      "    d========cav",
      "    d========cav",
      " e  d========cav",
      " effd========cav",
      "ggggd========cav",
      "ggggd========cav",
      "dddddhhhhhhhhcav"
    ],
    [
      "vvvvvvvvvvvvvvvv",
      "aaaaaaaaaaaaaaav",
      "bbbbbbbbbbbbbcav",
      "    ijjjjk lmbav",
      "    nokjj   pbav",
      "qqqqdrj     pbav",
      "    qps    lmbav",
      "    q!s     pbav",
      "    qs      pbav",
      "    qt     lmbav",
      "    qt      pbav",
      "gg  qu      pbav",
      "ffw q       xbav",
      "    q       ybav",
      "    A    BC ybav",
      "Dqqqdqqqqqqqqcav"
    ],
    [
      "vvvvvvvvvvvvvvvv",
      "aaaaaaaaaaaaaaav",
      "bbbbbbbbbbbbbcav",
      "    iojk   lmbav",
      "    noE     pbav",
      "qqqqdr      pbav",
      "    qpp    lmbav",
      "    q       pbav",
      "    q       pbav",
      "gg  q      lmbav",
      "ffw q       pbav",
      "  w q       pbav",
      "    q        bav",
      "    q        bav",
      "    F        bav",
      "Iqqqdqqqqqqqqcav"
    ],
    [
      "vvvvvvvvvvvvvvvv",
      "aaaaaaaaaaaaaaav",
      "bbbbbbbbbbbbbcav",
      "    no      rbav",
      "    i       pbav",
      "qqqqdr      pbav",
      "ggggqp      rbav",
      "ggggq       pbav",
      "ffw q       pbav",
      "  w q       rbav",
      "    q       pbav",
      "    q       pbav",
      "    q        bav",
      "    q        bav",
      "    q        bav",
      "Jqqqdqqqqqqqqcav"
    ],
    [
      "vvvvvvvvvvvvvvvv",
      "aaaaaaaaaaaaaaav",
      "bbbbbbbbbbbbbcav",
      "    qr      Kbav",
      "    qr      rbav",
      "qqqqdr      rbav",
      "    qr      Kbav",
      "    qLM     rbav",
      " effqLM     rbav",
      "  ggqLM     Kbav",
      "    qLM     rbav",
      "    qr      rbav",
      "    qrrrrrrrrbav",
      "    q       rbav",
      "    q       rbav",
      "qqqqdqqqqqqqqcav"
    ],
    [
      "vvvvvvvvvvvvvvvv",
      "aaaaaaaaaaaaaaav",
      "bbbbbbbbbbbbbcav",
      "NNNNqNNNNNNNNbav",
      "NNNNqNNNNNNNNbav",
      "qqqqdNNNNNNNNbav",
      "    qNNNNNNNNbav",
      "    qNNNNNNNNbav",
      "    qNNNNNNNNbav",
      " e  qNNNNNNNNbav",
      " effqNNNNNNNNbav",
      "  ggqNNNNNNNNbav",
      "    qNNNNNNNNbav",
      "    qNNNNNNNNbav",
      "    qNNNNNNNNbav",
      "qqqqdqqqqqqqqcav"
    ]
  ]
}