{
  "name": "multi_laboratory_10_base5",
  "refpalette": "deceasedcraft:multi_laboratory_10/multi_laboratory_10_base5_palette",
  "xsize": 16,
  "zsize": 16,
  "slices": [
    [
      "vvvvvvvvvvvvvvvv",
      "aaaaaaaaaaaaaaav",
      "bbbbccccccccccav",
      "    deeeeeeeecav",
      "    deeeeeeeecav",
      "fffffeeeeeeeecav",
      "    feeeeeeeecav",
      "    fggggggggcav",
      "    f   hiiiicav",
      "    f        cav",
      "    f        cav",
      " j  f        cav",
      " jkkf        cav",
      "llllf        cav",
      "llllf        cav",
      "ddddfddddddddcav"
    ],
    [
      "vvvvvvvvvvvvvvvv",
      "aaaaaaaaaaaaaaav",
      "bbbbccccccccccav",
      "    dgmnomnopcav",
      "    dg      qcav",
      "ddddfg      pcav",
      "    dgmnomnopcav",
      "    dggggggrgcav",
      "    d    sssscav",
      "    d        cav",
      "    d        cav",
      "ll  d        cav",
      "kkt d        cav",
      "    d        cav",
      "    d        cav",
      "ddddfddddddddcav"
    ],
    [
      "vvvvvvvvvvvvvvvv",
      "aaaaaaaaaaaaaaav",
      "bbbbccccccccccav",
      "    dgmnomno cav",
      "    dg      ucav",
      "ddddfg       cav",
      "    dgmnomno cav",
      "    dggggggwgcav",
      "    d        cav",
      "ll  d        cav",
      "kkt d        cav",
      "  t d        cav",
      "    d        cav",
      "    d        cav",
      "    d        cav",
      "ddddfddddddddcav"
    ],
    [
      "vvvvvvvvvvvvvvvv",
      "aaaaaaaaaaaaaaav",
      "bbbbccccccccccav",
      "    dg      xcav",
      "    dg       cav",
      "ddddfg      ycav",
      "lllldg      Acav",
      "lllldggggggggcav",
      "kkt d        cav",
      "  t d        cav",
      "    d        cav",
      "    d        cav",
      "    d        cav",
      "    d        cav",
      "    d        cav",
      "ddddfddddddddcav"
    ],
    [
      "vvvvvvvvvvvvvvvv",
      "aaaaaaaaaaaaaaav",
      "bbbbccccccccccav",
      "    dg       cav",
      "    dg       cav",
      "ddddfg      ycav",
      "    dg     yycav",
      "    dggggggggcav",
      " jkkd        cav",
      "  lld        cav",
      "    d        cav",
      "    d        cav",
      "    d        cav",
      "    d        cav",
      "    d        cav",
      "ddddfddddddddcav"
    ],
    [
      "vvvvvvvvvvvvvvvv",
      "aaaaaaaaaaaaaaav",
      "bbbbccccccccccav",
      "    dBBBBBBBBcav",
      "    dBBBBBBBBcav",
      "ddddfBBBBBBBBcav",
      "    dBBBBBBBBcav",
      "    dddddddddcav",
      "    dBBBBBBBBcav",
      " j  dBBBBBBBBcav",
      " jkkdBBBBBBBBcav",
      "  lldBBBBBBBBcav",
      "    dBBBBBBBBcav",
      "    dBBBBBBBBcav",
      "    dBBBBBBBBcav",
      "ddddfddddddddcav"
    ]
  ]
}