{
  "name": "multi_laboratory_10_ground",
  "refpalette": "deceasedcraft:multi_laboratory_10/multi_laboratory_10_ground_palette",
  "xsize": 16,
  "zsize": 16,
  "slices": [
    [
      "zzzzzzzzzzzzzzzz",
      "zazaaaaaazzzzzzz",
      "bbbbbcvccaazzzzz",
      "bbbbbbbvvcaczzzz",
      "bbbbbbbvvazaazzz",
      "dddddbbbvcaaaaza",
      "    dbbbccaazazz",
      "    dbbbvvcaaaaz",
      "    dbbbvcazazzz",
      "    dbbbvccaazaz",
      "    dbbbvaaaaaza",
      " e  dbbbvcacaazz",
      " effdbbbvcaaazza",
      "ggggdbbbvccaaaaz",
      "ggggdbbbvcaazaaz",
      "hhhhdbbbvvaaaaaz"
    ],
    [
      " i     i  i  i  ",
      "  i         i  i",
      "jjjjj       ii  ",
      "     jj        i",
      "      j   i   i ",
      "kdkkl  j        ",
      "    k  j       i",
      "    k  j  mn    ",
      "    d  j   i    ",
      "    k  j        ",
      "    k  j  nop   ",
      "gg  k  q        ",
      "ff  k           ",
      "    k     nmpm  ",
      "    k          i",
      "rsssd           "
    ],
    [
      "                ",
      "                ",
      "jjjtj           ",
      "     tj         ",
      "      j         ",
      "udkkl  j        ",
      "    k  j        ",
      "    k  j        ",
      "    d  j        ",
      "gg  u  j        ",
      "ff  k  t        ",
      "    k  j        ",
      "    k  q        ",
      "    k           ",
      "    u           ",
      "wsssd           "
    ],
    [
      "                ",
      "                ",
      "ttttx           ",
      "     tt         ",
      "      x         ",
      "udkkl  t        ",
      "ggggk  t        ",
      "ggggk  x        ",
      "ff  d  t        ",
      "    u  t        ",
      "    k  x        ",
      "    k  x        ",
      "    k  j        ",
      "    k  q        ",
      "    u           ",
      "ysssd           "
    ],
    [
      "                ",
      "                ",
      "ttxxt           ",
      "     tx         ",
      "      t         ",
      "udkkl  x        ",
      "    k  t        ",
      "    k  x        ",
      "  ffd  x        ",
      "  ggu  x        ",
      "    k  t        ",
      "    k  x        ",
      "    k  t        ",
      "    k  j        ",
      "    u  q        ",
      "ssssd           "
    ],
    [
      "                ",
      "                ",
      "txtxt           ",
      "     xt         ",
      "      t         ",
      "kdkkl  x        ",
      "    k  x        ",
      "    k  t        ",
      "    d  x        ",
      "    k  t        ",
      "  ffk  x        ",
      "  ggk  x        ",
      "    k  x        ",
      "    k  t        ",
      "    k  j        ",
      "ssssd  q        "
    ]
  ]
}