{
  "name": "multi_laboratory_10_base2",
  "refpalette": "deceasedcraft:multi_laboratory_10/multi_laboratory_10_base2_palette",
  "xsize": 16,
  "zsize": 16,
  "slices": [
    [
      "vvvvvvvvvvvvvvvv",
      "aaaaaaaaaaaaaaav",
      "bbbbbbbbbbbbbcav",
      "    d========cav",
      "    d========cav",
      "ddddd========cav",
      "    d========cav",
      "    d========cav",
      "    d========cav",
      "    d========cav",
      "    d========cav",
      " e  d========cav",
      " effd========cav",
      "ggggd========cav",
      "ggggd========cav",
      "dddddhhhhhhhhcav"
    ],
    [
      "vvvvvvvvvvvvvvvv",
      "aaaaaaaaaaaaaaav",
      "bbbbbbbbbbbbbcav",
      "    ijklll mnbav",
      "    io      pbav",
      "iiiidq      !bav",
      "    ir      nbav",
      "    is      pbav",
      "    is      rbav",
      "    i      mnbav",
      "    it      ubav",
      "gg  iw      rbav",
      "ffx i        bav",
      "    i       ybav",
      "    A       ybav",
      "Biiidiiiiiiiicav"
    ],
    [
      "vvvvvvvvvvvvvvvv",
      "aaaaaaaaaaaaaaav",
      "bbbbbbbbbbbbbcav",
      "    i      mnbav",
      "    i       ubav",
      "iiiidq      rbav",
      "    ir     mnbav",
      "    ir      pbav",
      "    i       rbav",
      "gg  i       nbav",
      "ffx i       pbav",
      "  x i       rbav",
      "    i        bav",
      "    i        bav",
      "    C       Dbav",
      "Eiiidiiiiiiiicav"
    ],
    [
      "vvvvvvvvvvvvvvvv",
      "aaaaaaaaaaaaaaav",
      "bbbbbbbbbbbbbcav",
      "    i       qbav",
      "    i       pbav",
      "iiiidq      rbav",
      "ggggir      qbav",
      "ggggi       pbav",
      "ffx i       rbav",
      "  x i       qbav",
      "    i       pbav",
      "    i       rbav",
      "    i        bav",
      "    i        bav",
      "    i       Fbav",
      "Iiiidiiiiiiiicav"
    ],
    [
      "vvvvvvvvvvvvvvvv",
      "aaaaaaaaaaaaaaav",
      "bbbbbbbbbbbbbcav",
      "    iq      Jbav",
      "    iq      qbav",
      "iiiidq      qbav",
      "    iq      Jbav",
      "    iKL     qbav",
      " effiKL     qbav",
      "  ggiKL     Jbav",
      "    iKL     qbav",
      "    iq      qbav",
      "    iqqqqqqqqbav",
      "    i       qbav",
      "    i       qbav",
      "iiiidiiiiiiiicav"
    ],
    [
      "vvvvvvvvvvvvvvvv",
      "aaaaaaaaaaaaaaav",
      "bbbbbbbbbbbbbcav",
      "    iMMMMMMMMbav",
      "    iMMMMMMMMbav",
      "iiiidMMMMMMMMbav",
      "    iMMMMMMMMbav",
      "    iMMMMMMMMbav",
      "    iMMMMMMMMbav",
      " e  iMMMMMMMMbav",
      " effiMMMMMMMMbav",
      "  ggiMMMMMMMMbav",
      "    iMMMMMMMMbav",
      "    iMMMMMMMMbav",
      "    iMMMMMMMMbav",
      "iiiidiiiiiiiicav"
    ]
  ]
}