{
  "name": "multi_laboratory_10_base6",
  "refpalette": "deceasedcraft:multi_laboratory_10/multi_laboratory_10_base6_palette",
  "xsize": 16,
  "zsize": 16,
  "slices": [
    [
      "vvvvvvvvvvvvvvvv",
      "aaaaaaaaaaaaaaav",
      "bbbbccccccccccav",
      "  dde========cav",
      "   de========cav",
      "eeeee========cav",
      "====e========cav",
      "====effffffffcav",
      "====effffffffcav",
      "====effffffffcav",
      "====effffffffcav",
      "====effffffffcav",
      "====effffffffcav",
      "====effffffffcav",
      "====effffffffcav",
      "eeeeeffffffffcav"
    ],
    [
      "vvvvvvvvvvvvvvvv",
      "aaaaaaaaaaaaaaav",
      "bbbbcbbbbbbbbcav",
      "   dghhhiij kcav",
      "   lghh     mcav",
      "ggggenn     ocav",
      "pqrsgn      tcav",
      "u s gwwwxywwwcav",
      " ABpgCC     Dcav",
      "BuE g     F Icav",
      "q  ug       Icav",
      "JJKugL      Dcav",
      "MMNOg      FIcav",
      "  P g  F  Q Icav",
      "   Rg  SSSSSTcav",
      "UgggeVgggggggcav"
    ],
    [
      "vvvvvvvvvvvvvvvv",
      "aaaaaaaaaaaaaaav",
      "bbbbcbbbbbbbbcav",
      "   dghh     Wcav",
      "    gh      Wcav",
      "ggggen      Wcav",
      "q   g       Wcav",
      "    gwwwXYwwwcav",
      "!   g       Zcav",
      "JJ  g        cav",
      "MMN gL      0cav",
      "  N g        cav",
      "    g       0cav",
      "    g        cav",
      "    g   1 123cav",
      "4ggge5gggggggcav"
    ],
    [
      "vvvvvvvvvvvvvvvv",
      "aaaaaaaaaaaaaaav",
      "bbbbcbbbbbbbbcav",
      "    gh      6cav",
      "    gn      7cav",
      "gggge       8cav",
      "JJJJg       9cav",
      "JJJJgwwwwwwwwcav",
      "MMN g#$      cav",
      "  N gL      %cav",
      "    g       ^cav",
      "    g       ^cav",
      "    g       ^cav",
      "    g       &cav",
      "    g        cav",
      "*ggge*gggggggcav"
    ],
    [
      "vvvvvvvvvvvvvvvv",
      "aaaaaaaaaaaaaaav",
      "bbbbcbbbbbbbbcav",
      "    g        cav",
      "    g        cav",
      "gggge        cav",
      "    g        cav",
      "    gwwwwwwwwcav",
      " (MMg )      cav",
      "  JJg       ^cav",
      "   qg       ^cav",
      "    g       &cav",
      "    g       %cav",
      "    g       ^cav",
      "    g        cav",
      "ggggeggggggggcav"
    ],
    [
      "vvvvvvvvvvvvvvvv",
      "aaaaaaaaaaaaaaav",
      "bbbbcbbbbbbbbcav",
      "    g++++++++cav",
      "    g++++++++cav",
      "gggge++++++++cav",
      "    g++++++++cav",
      "    gwwwwwwwwcav",
      "    g  )     cav",
      " (  g       ^cav",
      " (MMg       %cav",
      "  JJg       ^cav",
      "    g       &cav",
      "    g       %cav",
      "    g        cav",
      "ggggeggggggggcav"
    ]
  ]
}