{
  "name": "multi_laboratory_10_base4",
  "refpalette": "deceasedcraft:multi_laboratory_10/multi_laboratory_10_base4_palette",
  "xsize": 16,
  "zsize": 16,
  "slices": [
    [
      "vvvvvvvvvvvvvvvv",
      "aaaaaaaaaaaaaaav",
      "bbbbccccccccccav",
      "    d========cav",
      "    d========cav",
      "ddddd========cav",
      "    d========cav",
      "    d========cav",
      "    d========cav",
      "    d========cav",
      "    d========cav",
      " e  d========cav",
      " effd========cav",
      "ggggd========cav",
      "ggggd========cav",
      "dddddhhhhhhhhcav"
    ],
    [
      "vvvvvvvvvvvvvvvv",
      "aaaaaaaaaaaaaaav",
      "bbbbbbbbbbbbbcav",
      "    ijklll mnbav",
      "    io      pbav",
      "iiiidq       bav",
      "    ir      nbav",
      "    is ttt  pbav",
      "    is uwu  rbav",
      "    i  uwu mnbav",
      "    ix uwu  ybav",
      "gg  iA wpw  rbav",
      "ffB i        bav",
      "    i       Cbav",
      "    D       Cbav",
      "Eiiidiiiiiiiicav"
    ],
    [
      "vvvvvvvvvvvvvvvv",
      "aaaaaaaaaaaaaaav",
      "bbbbbbbbbbbbbcav",
      "    i!     mnbav",
      "    i       ybav",
      "iiiidq      rbav",
      "    ir     mnbav",
      "    ir ttt  pbav",
      "    i  FFF  rbav",
      "gg  i  FFI  nbav",
      "ffB i  FFF  pbav",
      "  B i  ppp  rbav",
      "    i   J    bav",
      "    i        bav",
      "    K       Lbav",
      "Miiidiiiiiiiicav"
    ],
    [
      "vvvvvvvvvvvvvvvv",
      "aaaaaaaaaaaaaaav",
      "bbbbbbbbbbbbbcav",
      "    i       qbav",
      "    i       pbav",
      "iiiidq      rbav",
      "ggggir      qbav",
      "ggggi  ttt  pbav",
      "ffB i   F   rbav",
      "  B i  FFF  qbav",
      "    i   F   pbav",
      "    i       rbav",
      "    i        bav",
      "    i        bav",
      "    i       Nbav",
      "Oiiidiiiiiiiicav"
    ],
    [
      "vvvvvvvvvvvvvvvv",
      "aaaaaaaaaaaaaaav",
      "bbbbbbbbbbbbbcav",
      "    iq      Pbav",
      "    iq      qbav",
      "iiiidq      qbav",
      "    iq      Pbav",
      "    iQR     qbav",
      " effiQR     qbav",
      "  ggiQR     Pbav",
      "    iQR     qbav",
      "    iq      qbav",
      "    iqqqqqqqqbav",
      "    i       qbav",
      "    i       qbav",
      "iiiidiiiiiiiicav"
    ],
    [
      "vvvvvvvvvvvvvvvv",
      "aaaaaaaaaaaaaaav",
      "bbbbbbbbbbbbbcav",
      "    iSSSSSSSSbav",
      "    iSSSSSSSSbav",
      "iiiidSSSSSSSSbav",
      "    iSSSSSSSSbav",
      "    iSSSSSSSSbav",
      "    iSSSSSSSSbav",
      " e  iSSSSSSSSbav",
      " effiSSSSSSSSbav",
      "  ggiSSSSSSSSbav",
      "    iSSSSSSSSbav",
      "    iSSSSSSSSbav",
      "    iSSSSSSSSbav",
      "iiiidiiiiiiiicav"
    ]
  ]
}