{
  "name": "multi_thering_23_base1",
  "refpalette": "deceasedcraft:multi_thering_23/multi_thering_23_base1_palette",
  "xsize": 16,
  "zsize": 16,
  "slices": [
    [
      "abbbbbbbbbbbbbbv",
      "bbbbbbbbbbbbbbbv",
      "bbbbbbbbbbbbbbbv",
      "bbbbbbbbbbbbbbbv",
      "bbbbbbbbbbbbbbbv",
      "bbbbbbbbbbbbbbbv",
      "bbbbbbbbbbbbbbbv",
      "bbbbbbbbbbbbbbbv",
      "bbbbbbbbbbbbbbbv",
      "bbbbbbbbbbbbbbbv",
      "bbbbbbbbbbbbbbbv",
      "bbbbbbbbbbbbbbbv",
      "bbbbbbbbbbbbbbbv",
      "bbbbbbbbbbbbbbbv",
      "bbbbbbbbbbbbbbbv",
      "bbbbbbbbbbbbbbbv"
    ],
    [
      "abbbbbbbbbbbbbbv",
      "bbbbbbbbbbbbbbbv",
      "bbbbbbbbbbbbbbbv",
      "bbbbbbbbbbbbbbbv",
      "bbbbbbbbbbbbbbbv",
      "bbbbbbbbbbbbbbbv",
      "bbbbbbbbbbbbbbbv",
      "bbbbbbbbbbbbbbbv",
      "bbbbbbbbbbbbbbbv",
      "bbbbbbbbbbbbbbbv",
      "bbbbbbbbbbbbbbbv",
      "bbbbbbbbbbbbbbbv",
      "bbbbbbbbbbbbbbbv",
      "bbbbbbbbbbbbbbbv",
      "bbbbbbbbbbbbbbbv",
      "bbbbbbbbbbbbbbbv"
    ],
    [
      "abbbbbbbbbbbbbbv",
      "bbbbbbbbbbbbbbbv",
      "bbbbbbbbbbbbbbbv",
      "bbbbbbbbbbbbbbbv",
      "bbbbbbbbbbbbbbbv",
      "bbbbbbbbbbbbbbbv",
      "bbbbbbbbbbbbbbbv",
      "bbbbbbbbbbbbbbbv",
      "bbbbbbbbbbbbbbbv",
      "bbbbbbbbbbbbbbbv",
      "bbbbbbbbbbbbbbbv",
      "bbbbbbbbbbbbbbbv",
      "bbbbbbbbbbbbbbbv",
      "bbbbbbbbbbbbbbbv",
      "bbbbbbbbbbbbbbbv",
      "bbbbbbbbbbbbbbbv"
    ],
    [
      "abbbbbbbbbbbbbbv",
      "bbbbbbbbbbbbbbbv",
      "bbbbbbbbbbbbbbbv",
      "bbbbbbbbbbbbbbbv",
      "bbbbbbbbbbbbbbbv",
      "bbbbbbbbbbbbbbbv",
      "bbbbbbbbbbbbbbbv",
      "bbbbbbbbbbbbbbbv",
      "bbbbbbbbbbbbbbbv",
      "bbbbbbbbbbbbbbbv",
      "bbbbbbbbbbbbbbbv",
      "bbbbbbbbbbbbbbbv",
      "bbbbbbbbbbbbbbbv",
      "bbbbbbbbbbbbbbbv",
      "bbbbbbbbbbbbbbbv",
      "bbbbbbbbbbbbbbbv"
    ],
    [
      "abbbbbbbbbbbbbbv",
      "bbbbbbbbbbbbbbbv",
      "bbbbbbbbbbbbbbbv",
      "bbbbbbbbbbbbbbbv",
      "bbbbbbbbbbbbbbbv",
      "bbbbbbbbbbbbbbbv",
      "bbbbbbbbbbbbbbbv",
      "bbbbbbbbbbbbbbbv",
      "bbbbbbbbbbbbbbbv",
      "bbbbbbbbbbbbbbbv",
      "bbbbbbbbbbbbbbbv",
      "bbbbbbbbbbbbbbbv",
      "bbbbbbbbbbbbbbbv",
      "bbbbbbbbbbbbbbbv",
      "bbbbbbbbbbbbbbbv",
      "bbbbbbbbbbbbbbbv"
    ],
    [
      "accccccccccccccv",
      "cccccccccccccccv",
      "cccccccccccccccv",
      "cccccccccccccccv",
      "cccccccccccccccv",
      "cccccccccccccccv",
      "cccccccccccccccv",
      "cccccccccccccccv",
      "cccccccccccccccv",
      "cccccccccccccccv",
      "cccccccccccccccv",
      "cccccccccccccccv",
      "cccccccccccccccv",
      "cccccccccccccccv",
      "cccccccccccccccv",
      "cccccccccccccccv"
    ]
  ]
}