{
  "name": "multi_thering_23_floor7",
  "refpalette": "deceasedcraft:multi_thering_23/multi_thering_23_floor7_palette",
  "xsize": 16,
  "zsize": 16,
  "slices": [
    [
      "      abbbac    ",
      "     aabbbac    ",
      "     abbbac     ",
      "    aabbbac     ",
      "    abbbbac     ",
      "    abbbac      ",
      "   aabbbac      ",
      "  aabbbacc      ",
      "ddabbbbac       ",
      "eaabbbacc       ",
      "aabbbbac        ",
      "abbbbac         ",
      "abbbaac         ",
      "bbbbac          ",
      "bbbac           ",
      "bbacc           "
    ],
    [
      "       f gh     ",
      "       figh     ",
      "      ffgh      ",
      "      fjgh      ",
      "     ffigh      ",
      "     fjgh       ",
      "     fjgh       ",
      "    ffgh        ",
      "   ffjgh        ",
      "   fjgh         ",
      "  ffjgh         ",
      " ffjgh          ",
      " fighh          ",
      "ffjgh           ",
      "fjgh            ",
      "jgh             "
    ],
    [
      "         g      ",
      "         g      ",
      "        g       ",
      "        g       ",
      "        g       ",
      "       g        ",
      "       g        ",
      "      g         ",
      "      g         ",
      "     g          ",
      "     g          ",
      "    g           ",
      "   g            ",
      "   g            ",
      "  g             ",
      " g              "
    ],
    [
      "                ",
      "                ",
      "                ",
      "                ",
      "                ",
      "                ",
      "                ",
      "                ",
      "                ",
      "                ",
      "                ",
      "                ",
      "                ",
      "                ",
      "                ",
      "                "
    ],
    [
      "                ",
      "                ",
      "                ",
      "                ",
      "                ",
      "                ",
      "                ",
      "                ",
      "                ",
      "                ",
      "                ",
      "                ",
      "                ",
      "                ",
      "                ",
      "                "
    ],
    [
      "                ",
      "                ",
      "                ",
      "                ",
      "                ",
      "                ",
      "                ",
      "                ",
      "                ",
      "                ",
      "                ",
      "                ",
      "                ",
      "                ",
      "                ",
      "                "
    ]
  ]
}