{
  "name": "building_apartmentsmallb_floor2_180",
  "refpalette": "deceasedcraft:building_apartmentsmallb/building_apartmentsmallb_floor2_palette_180",
  "xsize": 16,
  "zsize": 16,
  "slices": [
    [
      "                ",
      "  kkkkkkkkkkkk  ",
      " ijjjjjjhjjjjjg ",
      " ijjjjjjhjjjjjg ",
      " ijjjjjjhjjjjjg ",
      " ijjjjjjjjjjjjg ",
      " ijjjjjjhjjjjjg ",
      " ijjjjjjjcccccg ",
      " ijjjjjjhcccccg ",
      " ihhchhhhhhhhhg ",
      "  acccccccccca  ",
      "  accffffffcca  ",
      "  acce    dcca  ",
      "  aaabbbbbbaaa  ",
      "                ",
      "                "
    ],
    [
      "                ",
      " hhhhhhhhhhhhhh ",
      " hUT0  XhZY  Mh ",
      " hUT   XhWV RQh ",
      " hUT    hS  RQh ",
      " hP  OO N    Mh ",
      " hLKJIIIhEFEEEh ",
      " hD     C   B!h ",
      " hA  yxxhwuts h ",
      " hhhrhhhhhhhhhh ",
      " ha          ah ",
      "  a qpoooonm a  ",
      "  l      de  l  ",
      "  aaaaaaaaaaaa  ",
      "                ",
      "                "
    ],
    [
      "                ",
      " hh////hh////hh ",
      " {]?..,>h<'':;- ",
      " {]    |h}    - ",
      " {]     h[    - ",
      " h+     )    (h ",
      " h!  K *hE&EEEh ",
      " ^      %    B$ ",
      " hK# y98h7  s6h ",
      " hhh5hhhhhhhhhh ",
      " ha  4       ah ",
      "  a 23333332 a  ",
      "  1     de   1  ",
      "  aaaaaaaaaaaa  ",
      "                ",
      "                "
    ],
    [
      "                ",
      " hh////hh////hh ",
      " {]\u037e\u037d\u037d\u037c h\u037b\u037a\u037a\u0377 - ",
      " {]     h     - ",
      " {]     h     - ",
      " h      \u0375     h ",
      " h      hEEEEEh ",
      " \u0376      \u0375     \u0374 ",
      " h   y\u0373\u0372h\u0371\u0370 s`h ",
      " hhhfhhhhhhhhhh ",
      " ha          ah ",
      "  a 22222222 a  ",
      "  1    de    1  ",
      "  aaaaaaaaaaaa  ",
      "                ",
      "                "
    ],
    [
      "                ",
      " hh\u0386\u0386\u0386\u0386hh\u0386\u0386\u0386\u0386hh ",
      " /\u0385     h     / ",
      " /      h     / ",
      " /      h     / ",
      " h   \u0384  h     h ",
      " h      hEEEEEh ",
      " {      h     - ",
      " h   y  h     h ",
      " hhhhhhhhhhhhhh ",
      " ha          ah ",
      "  a 2\u037f\u037f\u037f\u037f\u037f\u037f2 a  ",
      "  l   de     l  ",
      "  aaaaaaaaaaaa  ",
      "                ",
      "                "
    ],
    [
      "                ",
      " hhhhhhhhhhhhhh ",
      " h\u0390\u0390\u0390\u0390\u0390\u0390h\u0390\u0390\u0390\u0390\u0390h ",
      " h\u0390\u0390\u0390\u0390\u0390\u0390h\u0390\u0390\u0390\u0390\u0390h ",
      " h\u0390\u0390\u0390\u0390\u0390\u0390h\u0390\u0390\u0390\u0390\u0390h ",
      " h\u0390\u0390\u0390\u0390\u0390\u0390h\u0390\u0390\u0390\u0390\u0390h ",
      " h\u0390\u0390\u0390\u0390\u0390\u0390h\u0390\u0390\u0390\u0390\u0390h ",
      " h\u0390\u0390\u0390\u0390\u0390\u0390h\u038f\u038f\u038f\u038f\u038fh ",
      " h\u0390\u0390\u0390\u0390\u0390\u0390h\u038f\u038f\u038f\u038f\u038fh ",
      " hhhhhhhhhhhhhh ",
      " ha          ah ",
      "  a \u038e\u038c\u038a\u038a\u038a\u038a\u0389\u0388 a  ",
      "  a\u0387\u0387de    \u0387\u0387a  ",
      "  aaaaaaaaaaaa  ",
      "                ",
      "                "
    ]
  ]
}