{
  "name": "building_apartmentsmallb_top_270",
  "refpalette": "deceasedcraft:building_apartmentsmallb/building_apartmentsmallb_top_palette_270",
  "xsize": 16,
  "zsize": 16,
  "slices": [
    [
      "                ",
      "  eeeeeeee      ",
      " jffffffffaaaa  ",
      " jffffffffccca  ",
      " jffiiffffccca  ",
      " jffiiggggcc b  ",
      " jffffffffcc b  ",
      " jffffffffcc b  ",
      " jffffffffcc b  ",
      " jffffffffcc b  ",
      " jffffffffccdb  ",
      " jffffffffccca  ",
      " jffffffffccca  ",
      " jffffffffaaaa  ",
      "  hhhhhhhh      ",
      "                "
    ],
    [
      "                ",
      "                ",
      "  qqqqqqqqaaaa  ",
      "  q uu    anka  ",
      "  qxiit  raola  ",
      "  qxiit  ga ma  ",
      "  q ww    a ma  ",
      "  q     r a ma  ",
      "  q    rssa ma  ",
      "  q     ssa ma  ",
      "  q       a ma  ",
      "  q       p  a  ",
      "  q       a  a  ",
      "  qqqqqqqqaaaa  ",
      "                ",
      "                "
    ],
    [
      "                ",
      "                ",
      "          aaaa  ",
      "         gEBya  ",
      "    LK   gaCla  ",
      "    KK   ga Aa  ",
      "          a  a  ",
      "        r a  a  ",
      "        !Ia  a  ",
      "        IJa  a  ",
      "          a  a  ",
      "          F  a  ",
      "          aD a  ",
      "          aaaa  ",
      "                ",
      "                "
    ],
    [
      "                ",
      "                ",
      "          aaaa  ",
      "          aMMa  ",
      "          aMMa  ",
      "          aMMa  ",
      "          aMMa  ",
      "          aMMa  ",
      "          aMMa  ",
      "          aMMa  ",
      "          aMMa  ",
      "          aMMa  ",
      "          aMMa  ",
      "          aaaa  ",
      "                ",
      "                "
    ],
    [
      "                ",
      "                ",
      "                ",
      "                ",
      "                ",
      "                ",
      "                ",
      "                ",
      "                ",
      "                ",
      "                ",
      "                ",
      "                ",
      "                ",
      "                ",
      "                "
    ],
    [
      "                ",
      "                ",
      "                ",
      "                ",
      "                ",
      "                ",
      "                ",
      "                ",
      "                ",
      "                ",
      "                ",
      "                ",
      "                ",
      "                ",
      "                ",
      "                "
    ]
  ]
}