{
  "name": "building_apartmentsmallb_floor3_180",
  "refpalette": "deceasedcraft:building_apartmentsmallb/building_apartmentsmallb_floor3_palette_180",
  "xsize": 16,
  "zsize": 16,
  "slices": [
    [
      "                ",
      "  kkkkkkkkkkkk  ",
      " ijjjjjjhjjjjjg ",
      " ijjjjjjhjjjjjg ",
      " ijjjjjjhjjjjjg ",
      " ijjjjjjjjjjjjg ",
      " ijjjjjjhjjjjjg ",
      " ijjjjjjjcccccg ",
      " ijjjjjjhcccccg ",
      " ihhchhhhhhhhhg ",
      "  acccccccccca  ",
      "  accffffffcca  ",
      "  acce    dcca  ",
      "  aaabbbbbbaaa  ",
      "                ",
      "                "
    ],
    [
      "                ",
      " hhhhhhhhhhhhhh ",
      " hUTY  WhX   Kh ",
      " hUT   WhV  QPh ",
      " hUT M  hSR QPh ",
      " hON  M L    Kh ",
      " hJ IFFFhDEDDDh ",
      " hC     B     h ",
      " hA  yxxhwuts h ",
      " hhhrhhhhhhhhhh ",
      " ha          ah ",
      "  a qpoooonm a  ",
      "  l      de  l  ",
      "  aaaaaaaaaaaa  ",
      "                ",
      "                "
    ],
    [
      "                ",
      " hh<<<<hh<<<<hh ",
      " ]['::; h'::;|- ",
      " ][    }h{    - ",
      " ][     h     - ",
      " h+     )    (h ",
      " h*  !& hD^DDDh ",
      " %      $     # ",
      " h98 y76h5  s4h ",
      " hhh3hhhhhhhhhh ",
      " ha  2       ah ",
      "  a 01111110 a  ",
      "  Z     de   Z  ",
      "  aaaaaaaaaaaa  ",
      "                ",
      "                "
    ],
    [
      "                ",
      " hh<<<<hh<<<<hh ",
      " ][\u0374\u0373\u0373\u0372 h\u0374\u0373\u0373\u0372 - ",
      " ][     h     - ",
      " ][     h     - ",
      " h\u0371     `     h ",
      " h      hDDDDDh ",
      " \u0370      `     / ",
      " h   y ?h., s>h ",
      " hhhfhhhhhhhhhh ",
      " ha          ah ",
      "  a 00000000 a  ",
      "  Z    de    Z  ",
      "  aaaaaaaaaaaa  ",
      "                ",
      "                "
    ],
    [
      "                ",
      " hh\u037b\u037b\u037b\u037bhh\u037b\u037b\u037b\u037bhh ",
      " <\u037a     h     < ",
      " <      h     < ",
      " <\u0377     h     < ",
      " h   \u0376  h     h ",
      " h      hDDDDDh ",
      " ]      h     - ",
      " h   y  h     h ",
      " hhhhhhhhhhhhhh ",
      " ha          ah ",
      "  a 0\u0375\u0375\u0375\u0375\u0375\u03750 a  ",
      "  l   de     l  ",
      "  aaaaaaaaaaaa  ",
      "                ",
      "                "
    ],
    [
      "                ",
      " hhhhhhhhhhhhhh ",
      " h\u0387\u0387\u0387\u0387\u0387\u0387h\u0387\u0387\u0387\u0387\u0387h ",
      " h\u0387\u0387\u0387\u0387\u0387\u0387h\u0387\u0387\u0387\u0387\u0387h ",
      " h\u0387\u0387\u0387\u0387\u0387\u0387h\u0387\u0387\u0387\u0387\u0387h ",
      " h\u0387\u0387\u0387\u0387\u0387\u0387h\u0387\u0387\u0387\u0387\u0387h ",
      " h\u0387\u0387\u0387\u0387\u0387\u0387h\u0387\u0387\u0387\u0387\u0387h ",
      " h\u0387\u0387\u0387\u0387\u0387\u0387h\u0386\u0386\u0386\u0386\u0386h ",
      " h\u0387\u0387\u0387\u0387\u0387\u0387h\u0386\u0386\u0386\u0386\u0386h ",
      " hhhhhhhhhhhhhh ",
      " ha          ah ",
      "  a \u0385\u0384\u037f\u037f\u037f\u037f\u037e\u037d a  ",
      "  a\u037c\u037cde    \u037c\u037ca  ",
      "  aaaaaaaaaaaa  ",
      "                ",
      "                "
    ]
  ]
}