{
  "name": "building_apartmentsmallb_floor3_90",
  "refpalette": "deceasedcraft:building_apartmentsmallb/building_apartmentsmallb_floor3_palette_90",
  "xsize": 16,
  "zsize": 16,
  "slices": [
    [
      "                ",
      "      iiiiiiii  ",
      "  aaaahjjjjjjjk ",
      "  accchjjjjjjjk ",
      "  accccjjjjjjjk ",
      "  befchjjjjjjjk ",
      "  b fchjjjjjjjk ",
      "  b fchjjjjjjjk ",
      "  b fchhjhjhhhk ",
      "  b fchccjjjjjk ",
      "  bdfchccjjjjjk ",
      "  accchccjjjjjk ",
      "  accchccjjjjjk ",
      "  aaaahccjjjjjk ",
      "      gggggggg  ",
      "                "
    ],
    [
      "                ",
      "     hhhhhhhhhh ",
      "  alaahACJOUUUh ",
      "  a   h   NTTTh ",
      "  a q r  I   Yh ",
      "  a p hy F M  h ",
      "  a o hx FM   h ",
      "  a o hx F  WWh ",
      "  a o hhBhLhhhh ",
      "  ado hw D SVXh ",
      "  aen hu E R  h ",
      "  a m ht D    h ",
      "  a   hs D QQ h ",
      "  alaah  DKPPKh ",
      "     hhhhhhhhhh ",
      "                "
    ],
    [
      "                ",
      "     hhh%hh]]]h ",
      "  aZaah9 *+[[[h ",
      "  a   h8     '< ",
      "  a 0 3      :< ",
      "  a 12hy !   :< ",
      "  a 1 h7 &   ;< ",
      "  a 1 h6    } h ",
      "  ad1 hh$h)hhhh ",
      "  ae1 h5 D  {'< ",
      "  a 1 h  ^   :< ",
      "  a 0 h  D   :< ",
      "  a   hs D   ;< ",
      "  aZaah4 D(  |h ",
      "     hhh#hh---h ",
      "                "
    ],
    [
      "                ",
      "     hhh\u0370hh]]]h ",
      "  aZaah   \u0371[[[h ",
      "  a   h      \u0374< ",
      "  a 0 f      \u0373< ",
      "  a 0 hy     \u0373< ",
      "  a 0 h      \u0372< ",
      "  ad0 h?      h ",
      "  ae0 hh`h`hhhh ",
      "  a 0 h. D   \u0374< ",
      "  a 0 h, D   \u0373< ",
      "  a 0 h  D   \u0373< ",
      "  a   hs D   \u0372< ",
      "  aZaah> D    h ",
      "     hhh/hh---h ",
      "                "
    ],
    [
      "                ",
      "     hhh]hh<<<h ",
      "  alaah    \u0377 \u037ah ",
      "  a   h       \u037b ",
      "  a 0 h       \u037b ",
      "  a \u0375 hy  \u0376   \u037b ",
      "  ad\u0375 h       \u037b ",
      "  ae\u0375 h       h ",
      "  a \u0375 hhhhhhhhh ",
      "  a \u0375 h  D    \u037b ",
      "  a \u0375 h  D    \u037b ",
      "  a 0 h  D    \u037b ",
      "  a   h  D    \u037b ",
      "  alaah  D    h ",
      "     hhh-hh<<<h ",
      "                "
    ],
    [
      "                ",
      "     hhhhhhhhhh ",
      "  aaaah\u0387\u0387\u0387\u0387\u0387\u0387\u0387h ",
      "  a\u037c  h\u0387\u0387\u0387\u0387\u0387\u0387\u0387h ",
      "  a\u037c\u0385 h\u0387\u0387\u0387\u0387\u0387\u0387\u0387h ",
      "  ad\u0384 h\u0387\u0387\u0387\u0387\u0387\u0387\u0387h ",
      "  ae\u037f h\u0387\u0387\u0387\u0387\u0387\u0387\u0387h ",
      "  a \u037f h\u0387\u0387\u0387\u0387\u0387\u0387\u0387h ",
      "  a \u037f hhhhhhhhh ",
      "  a \u037f h\u0386\u0386\u0387\u0387\u0387\u0387\u0387h ",
      "  a \u037e h\u0386\u0386\u0387\u0387\u0387\u0387\u0387h ",
      "  a\u037c\u037d h\u0386\u0386\u0387\u0387\u0387\u0387\u0387h ",
      "  a\u037c  h\u0386\u0386\u0387\u0387\u0387\u0387\u0387h ",
      "  aaaah\u0386\u0386\u0387\u0387\u0387\u0387\u0387h ",
      "     hhhhhhhhhh ",
      "                "
    ]
  ]
}