{
  "name": "building_apartmentsmallb_floor1_180",
  "refpalette": "deceasedcraft:building_apartmentsmallb/building_apartmentsmallb_floor1_palette_180",
  "xsize": 16,
  "zsize": 16,
  "slices": [
    [
      "                ",
      "  kkkkkkkkkkkk  ",
      " ijjjjjjhjjjjjg ",
      " ijjjjjjhjjjjjg ",
      " ijjjjjjhjjjjjg ",
      " ijjjjjjjjjjjjg ",
      " ijjjjjjhjjjjjg ",
      " ijjjjjjjcccccg ",
      " ijjjjjjhcccccg ",
      " ihhchhhhhhhhhg ",
      "  acccccccccca  ",
      "  accffffffcca  ",
      "  acce    dcca  ",
      "  aaabbbbbbaaa  ",
      "                ",
      "                "
    ],
    [
      "                ",
      " hhhhhhhhhhhhhh ",
      " hTSY  VhXW  Lh ",
      " hTS   VhU  QPh ",
      " hTS    hR  QPh ",
      " hO  NN M    Lh ",
      " hK JIIIhEFEEEh ",
      " hD     C  B  h ",
      " hA  yxxhwuts h ",
      " hhhrhhhhhhhhhh ",
      " ha          ah ",
      "  a qpoooonm a  ",
      "  l      de  l  ",
      "  aaaaaaaaaaaa  ",
      "                ",
      "                "
    ],
    [
      "                ",
      " hh....hh....hh ",
      " ][,>><'h:;;|(- ",
      " ][    }h{    - ",
      " ][     h!    - ",
      " h+     )    (h ",
      " h   * &hE^EEEh ",
      " %      $     # ",
      " h98 y76h5  s4h ",
      " hhh3hhhhhhhhhh ",
      " ha  2       ah ",
      "  a 01111110 a  ",
      "  Z     de   Z  ",
      "  aaaaaaaaaaaa  ",
      "                ",
      "                "
    ],
    [
      "                ",
      " hh....hh....hh ",
      " ][\u037d\u037c\u037c\u037b h\u037a\u0377\u0377\u0376 - ",
      " ][     h     - ",
      " ][     h     - ",
      " h\u0375     \u0373     h ",
      " h      hEEEEEh ",
      " \u0374      \u0373     \u0372 ",
      " h   y\u0371\u0370h`/ s?h ",
      " hhhfhhhhhhhhhh ",
      " ha          ah ",
      "  a 00000000 a  ",
      "  Z    de    Z  ",
      "  aaaaaaaaaaaa  ",
      "                ",
      "                "
    ],
    [
      "                ",
      " hh\u0385\u0385\u0385\u0385hh\u0385\u0385\u0385\u0385hh ",
      " .      h     . ",
      " .\u0384     h     . ",
      " .      h     . ",
      " h   \u037f  h     h ",
      " h      hEEEEEh ",
      " ]      h     - ",
      " h   y  h     h ",
      " hhhhhhhhhhhhhh ",
      " ha          ah ",
      "  a 0\u037e\u037e\u037e\u037e\u037e\u037e0 a  ",
      "  l   de     l  ",
      "  aaaaaaaaaaaa  ",
      "                ",
      "                "
    ],
    [
      "                ",
      " hhhhhhhhhhhhhh ",
      " h\u038f\u038f\u038f\u038f\u038f\u038fh\u038f\u038f\u038f\u038f\u038fh ",
      " h\u038f\u038f\u038f\u038f\u038f\u038fh\u038f\u038f\u038f\u038f\u038fh ",
      " h\u038f\u038f\u038f\u038f\u038f\u038fh\u038f\u038f\u038f\u038f\u038fh ",
      " h\u038f\u038f\u038f\u038f\u038f\u038fh\u038f\u038f\u038f\u038f\u038fh ",
      " h\u038f\u038f\u038f\u038f\u038f\u038fh\u038f\u038f\u038f\u038f\u038fh ",
      " h\u038f\u038f\u038f\u038f\u038f\u038fh\u038e\u038e\u038e\u038e\u038eh ",
      " h\u038f\u038f\u038f\u038f\u038f\u038fh\u038e\u038e\u038e\u038e\u038eh ",
      " hhhhhhhhhhhhhh ",
      " ha          ah ",
      "  a \u038c\u038a\u0389\u0389\u0389\u0389\u0388\u0387 a  ",
      "  a\u0386\u0386de    \u0386\u0386a  ",
      "  aaaaaaaaaaaa  ",
      "                ",
      "                "
    ]
  ]
}