{
  "name": "building_apartmentsmallb_floor2",
  "refpalette": "deceasedcraft:building_apartmentsmallb/building_apartmentsmallb_floor2_palette",
  "xsize": 16,
  "zsize": 16,
  "slices": [
    [
      "                ",
      "                ",
      "  aaabbbbbbaaa  ",
      "  accd    ecca  ",
      "  accffffffcca  ",
      "  acccccccccca  ",
      " ghhhhhhhhhchhi ",
      " gccccchjjjjjji ",
      " gcccccjjjjjjji ",
      " gjjjjjhjjjjjji ",
      " gjjjjjjjjjjjji ",
      " gjjjjjhjjjjjji ",
      " gjjjjjhjjjjjji ",
      " gjjjjjhjjjjjji ",
      "  kkkkkkkkkkkk  ",
      "                "
    ],
    [
      "                ",
      "                ",
      "  aaaaaaaaaaaa  ",
      "  l  ed      l  ",
      "  a mnoooopq a  ",
      " ha          ah ",
      " hhhhhhhhhhrhhh ",
      " h stuwhxxy  Ah ",
      " h!B   C     Dh ",
      " hEEEFEhIIIJKLh ",
      " hM    N OO  Ph ",
      " hQR  Sh    TUh ",
      " hQR VWhX   TUh ",
      " hM  YZhX  0TUh ",
      " hhhhhhhhhhhhhh ",
      "                "
    ],
    [
      "                ",
      "                ",
      "  aaaaaaaaaaaa  ",
      "  1   ed     1  ",
      "  a 23333332 a  ",
      " ha       4  ah ",
      " hhhhhhhhhh5hhh ",
      " h6s  7h89y #Kh ",
      " $B    %      ^ ",
      " hEEE&Eh* K  !h ",
      " h(    )     +h ",
      " -    [h     ]{ ",
      " -    }h|    ]{ ",
      " -;:''<h>,..?]{ ",
      " hh////hh////hh ",
      "                "
    ],
    [
      "                ",
      "                ",
      "  aaaaaaaaaaaa  ",
      "  1    ed    1  ",
      "  a 22222222 a  ",
      " ha          ah ",
      " hhhhhhhhhhfhhh ",
      " h`s \u0370\u0371h\u0372\u0373y   h ",
      " \u0374     \u0375      \u0376 ",
      " hEEEEEh      h ",
      " h     \u0375      h ",
      " -     h     ]{ ",
      " -     h     ]{ ",
      " - \u0377\u037a\u037a\u037bh \u037c\u037d\u037d\u037e]{ ",
      " hh////hh////hh ",
      "                "
    ],
    [
      "                ",
      "                ",
      "  aaaaaaaaaaaa  ",
      "  l     ed   l  ",
      "  a 2\u037f\u037f\u037f\u037f\u037f\u037f2 a  ",
      " ha          ah ",
      " hhhhhhhhhhhhhh ",
      " h     h  y   h ",
      " -     h      { ",
      " hEEEEEh      h ",
      " h     h  \u0384   h ",
      " /     h      / ",
      " /     h      / ",
      " /     h     \u0385/ ",
      " hh\u0386\u0386\u0386\u0386hh\u0386\u0386\u0386\u0386hh ",
      "                "
    ],
    [
      "                ",
      "                ",
      "  aaaaaaaaaaaa  ",
      "  a\u0387\u0387    ed\u0387\u0387a  ",
      "  a \u0388\u0389\u038a\u038a\u038a\u038a\u038c\u038e a  ",
      " ha          ah ",
      " hhhhhhhhhhhhhh ",
      " h\u038f\u038f\u038f\u038f\u038fh\u0390\u0390\u0390\u0390\u0390\u0390h ",
      " h\u038f\u038f\u038f\u038f\u038fh\u0390\u0390\u0390\u0390\u0390\u0390h ",
      " h\u0390\u0390\u0390\u0390\u0390h\u0390\u0390\u0390\u0390\u0390\u0390h ",
      " h\u0390\u0390\u0390\u0390\u0390h\u0390\u0390\u0390\u0390\u0390\u0390h ",
      " h\u0390\u0390\u0390\u0390\u0390h\u0390\u0390\u0390\u0390\u0390\u0390h ",
      " h\u0390\u0390\u0390\u0390\u0390h\u0390\u0390\u0390\u0390\u0390\u0390h ",
      " h\u0390\u0390\u0390\u0390\u0390h\u0390\u0390\u0390\u0390\u0390\u0390h ",
      " hhhhhhhhhhhhhh ",
      "                "
    ]
  ]
}