{
  "name": "building_apartmentsmallb_top",
  "refpalette": "deceasedcraft:building_apartmentsmallb/building_apartmentsmallb_top_palette",
  "xsize": 16,
  "zsize": 16,
  "slices": [
    [
      "                ",
      "                ",
      "  aaabbbbbbaaa  ",
      "  acc     dcca  ",
      "  acccccccccca  ",
      "  acccccccccca  ",
      " efffgffffffffh ",
      " efffgffffffffh ",
      " efffgffffffffh ",
      " efffgffffffffh ",
      " effiiffffffffh ",
      " effiiffffffffh ",
      " effffffffffffh ",
      " effffffffffffh ",
      "  jjjjjjjjjjjj  ",
      "                "
    ],
    [
      "                ",
      "                ",
      "  aaaaaaaaaaaa  ",
      "  aklmmmmmm  a  ",
      "  ano        a  ",
      "  aaaaaaaaapaa  ",
      "  q rg  ss   q  ",
      "  q    rss   q  ",
      "  q     r    q  ",
      "  q tt       q  ",
      "  quiiw      q  ",
      "  quiiw      q  ",
      "  q xx       q  ",
      "  qqqqqqqqqqqq  ",
      "                ",
      "                "
    ],
    [
      "                ",
      "                ",
      "  aaaaaaaaaaaa  ",
      "  aylA       a  ",
      "  aBC       Da  ",
      "  aEaaaaaaaFaa  ",
      "   ggg  IJ      ",
      "       r!I      ",
      "                ",
      "                ",
      "    KK          ",
      "    LK          ",
      "                ",
      "                ",
      "                ",
      "                "
    ],
    [
      "                ",
      "                ",
      "  aaaaaaaaaaaa  ",
      "  aMMMMMMMMMMa  ",
      "  aMMMMMMMMMMa  ",
      "  aaaaaaaaaaaa  ",
      "                ",
      "                ",
      "                ",
      "                ",
      "                ",
      "                ",
      "                ",
      "                ",
      "                ",
      "                "
    ],
    [
      "                ",
      "                ",
      "                ",
      "                ",
      "                ",
      "                ",
      "                ",
      "                ",
      "                ",
      "                ",
      "                ",
      "                ",
      "                ",
      "                ",
      "                ",
      "                "
    ],
    [
      "                ",
      "                ",
      "                ",
      "                ",
      "                ",
      "                ",
      "                ",
      "                ",
      "                ",
      "                ",
      "                ",
      "                ",
      "                ",
      "                ",
      "                ",
      "                "
    ]
  ]
}