{
  "name": "building_apartmentsmallb_top_90",
  "refpalette": "deceasedcraft:building_apartmentsmallb/building_apartmentsmallb_top_palette_90",
  "xsize": 16,
  "zsize": 16,
  "slices": [
    [
      "                ",
      "      hhhhhhhh  ",
      "  aaaaffffffffj ",
      "  acccffffffffj ",
      "  acccffffffffj ",
      "  bdccffffffffj ",
      "  b ccffffffffj ",
      "  b ccffffffffj ",
      "  b ccffffffffj ",
      "  b ccffffffffj ",
      "  b ccggggiiffj ",
      "  acccffffiiffj ",
      "  acccffffffffj ",
      "  aaaaffffffffj ",
      "      eeeeeeee  ",
      "                "
    ],
    [
      "                ",
      "                ",
      "  aaaaqqqqqqqq  ",
      "  a  a       q  ",
      "  a  p       q  ",
      "  am a       q  ",
      "  am ass     q  ",
      "  am assr    q  ",
      "  am a r     q  ",
      "  am a    ww q  ",
      "  am ag  tiixq  ",
      "  aloar  tiixq  ",
      "  akna    uu q  ",
      "  aaaaqqqqqqqq  ",
      "                ",
      "                "
    ],
    [
      "                ",
      "                ",
      "  aaaa          ",
      "  a Da          ",
      "  a  F          ",
      "  a  a          ",
      "  a  aJI        ",
      "  a  aI!        ",
      "  a  a r        ",
      "  a  a          ",
      "  aA ag   KK    ",
      "  alCag   KL    ",
      "  ayBEg         ",
      "  aaaa          ",
      "                ",
      "                "
    ],
    [
      "                ",
      "                ",
      "  aaaa          ",
      "  aMMa          ",
      "  aMMa          ",
      "  aMMa          ",
      "  aMMa          ",
      "  aMMa          ",
      "  aMMa          ",
      "  aMMa          ",
      "  aMMa          ",
      "  aMMa          ",
      "  aMMa          ",
      "  aaaa          ",
      "                ",
      "                "
    ],
    [
      "                ",
      "                ",
      "                ",
      "                ",
      "                ",
      "                ",
      "                ",
      "                ",
      "                ",
      "                ",
      "                ",
      "                ",
      "                ",
      "                ",
      "                ",
      "                "
    ],
    [
      "                ",
      "                ",
      "                ",
      "                ",
      "                ",
      "                ",
      "                ",
      "                ",
      "                ",
      "                ",
      "                ",
      "                ",
      "                ",
      "                ",
      "                ",
      "                "
    ]
  ]
}