{
  "name": "building_apartmentsmallb_ground_180",
  "refpalette": "deceasedcraft:building_apartmentsmallb/building_apartmentsmallb_ground_palette_180",
  "xsize": 16,
  "zsize": 16,
  "slices": [
    [
      "aaaaaaafaffffaaa",
      "adddddddddddddda",
      "adeeeeecccccccda",
      "adeeeeecccccccda",
      "adeeeeecccccccda",
      "adeeeeecccccccda",
      "adeeeeecccccccda",
      "adeeeeeccccc!cda",
      "adccccccccccccda",
      "adccccccccccccda",
      "adbccccccccccbda",
      "aabccccccccccbaa",
      "aabccccccccccbaa",
      "aabbbbbbbbbbbbaa",
      "aaaaaaaaaaaaaaaa",
      "aaaaaaaaaaaaaaaa"
    ],
    [
      "                ",
      " ttttttkkCDDCkk ",
      " trwrwyp  BA uk ",
      " t sryxp     uk ",
      " tqy xsp      k ",
      " twrsy p     uk ",
      " txyxwrp     uk ",
      " ts rq p    onk ",
      " kmmmmm      lk ",
      " k           lk ",
      " kb    bbbbbbbk ",
      "  b    j     b  ",
      "  biiihcccg  b  ",
      "  bbbbbbbbbbbb  ",
      "                ",
      "                "
    ],
    [
      "                ",
      " ttttttkkC  Ckk ",
      " t IxI    LK  t ",
      " t   J        t ",
      " t J          t ",
      " tI  J        t ",
      " t J I        t ",
      " t            t ",
      " k            k ",
      " k            k ",
      " kb    bbbbbbbk ",
      "  b    F     b  ",
      "  bEEE ccg   b  ",
      "  bbbbbbbbbbbb  ",
      "                ",
      "                "
    ],
    [
      "                ",
      " ttttttkkCRRCkk ",
      " t            t ",
      " t            t ",
      " t            t ",
      " t            t ",
      " t            t ",
      " t            t ",
      " k            k ",
      " k        QP  k ",
      " kb    bbbbbbbk ",
      "  b    O     b  ",
      "  bENEMcg    b  ",
      "  bbbbbbbbbbbb  ",
      "                ",
      "                "
    ],
    [
      "                ",
      " UTTTTTkkCCCCkk ",
      " T            T ",
      " T            T ",
      " T            T ",
      " T            T ",
      " T            T ",
      " T            T ",
      " k            k ",
      " k            k ",
      " kbbbbbbbbbbbbk ",
      "  bbbbbS     b  ",
      "  bccccg     b  ",
      "  bbbbbbbbbbbb  ",
      "                ",
      "                "
    ],
    [
      "                ",
      " kkkkkkkkkkkkkk ",
      " kddddddddddddk ",
      " kddddddddddddk ",
      " kddddddddddddk ",
      " kddddddddddddk ",
      " kddddddddddddk ",
      " kddddddddddddk ",
      " kddddddddddddk ",
      " kddddddddddddk ",
      " kbbbbbbbbbbbbk ",
      "  bbbbS      b  ",
      "  bcccg    VVb  ",
      "  bbbbbbbbbbbb  ",
      "                ",
      "                "
    ]
  ]
}