{
  "name": "building_apartmentsmallb_floor2_90",
  "refpalette": "deceasedcraft:building_apartmentsmallb/building_apartmentsmallb_floor2_palette_90",
  "xsize": 16,
  "zsize": 16,
  "slices": [
    [
      "                ",
      "      iiiiiiii  ",
      "  aaaahjjjjjjjk ",
      "  accchjjjjjjjk ",
      "  accccjjjjjjjk ",
      "  befchjjjjjjjk ",
      "  b fchjjjjjjjk ",
      "  b fchjjjjjjjk ",
      "  b fchhjhjhhhk ",
      "  b fchccjjjjjk ",
      "  bdfchccjjjjjk ",
      "  accchccjjjjjk ",
      "  accchccjjjjjk ",
      "  aaaahccjjjjjk ",
      "      gggggggg  ",
      "                "
    ],
    [
      "                ",
      "     hhhhhhhhhh ",
      "  alaahADLPUUUh ",
      "  a   h  K TTTh ",
      "  a q r  J   0h ",
      "  a p hy IO   h ",
      "  a o hx IO   h ",
      "  a o hx I  XXh ",
      "  a o hhChNhhhh ",
      "  ado hw E SWZh ",
      "  aen hu F  VYh ",
      "  a m ht E    h ",
      "  a   hsBE RR h ",
      "  alaah !EMQQMh ",
      "     hhhhhhhhhh ",
      "                "
    ],
    [
      "                ",
      "     hhh^hh{{{h ",
      "  a1aahK !+]]]h ",
      "  a   h#     ?/ ",
      "  a 2 5      ./ ",
      "  a 34hy K   ./ ",
      "  a 3 h9     ,/ ",
      "  a 3 h8 *  |>h ",
      "  ad3 hh%h)hhhh ",
      "  ae3 h7 E [}</ ",
      "  a 3 h  &   '/ ",
      "  a 2 h  E   '/ ",
      "  a   hs E   :/ ",
      "  a1aah6BE(  ;h ",
      "     hhh$hh---h ",
      "                "
    ],
    [
      "                ",
      "     hhh\u0376hh{{{h ",
      "  a1aah    ]]]h ",
      "  a   h      \u037e/ ",
      "  a 2 f      \u037d/ ",
      "  a 2 hy     \u037d/ ",
      "  a 2 h\u0373     \u037c/ ",
      "  ad2 h\u0372      h ",
      "  ae2 hh\u0375h\u0375hhhh ",
      "  a 2 h\u0371 E   \u037b/ ",
      "  a 2 h\u0370 E   \u037a/ ",
      "  a 2 h  E   \u037a/ ",
      "  a   hs E   \u0377/ ",
      "  a1aah` E    h ",
      "     hhh\u0374hh---h ",
      "                "
    ],
    [
      "                ",
      "     hhh{hh///h ",
      "  alaah      \u0385h ",
      "  a   h       \u0386 ",
      "  a 2 h       \u0386 ",
      "  a \u037f hy  \u0384   \u0386 ",
      "  ad\u037f h       \u0386 ",
      "  ae\u037f h       h ",
      "  a \u037f hhhhhhhhh ",
      "  a \u037f h  E    \u0386 ",
      "  a \u037f h  E    \u0386 ",
      "  a 2 h  E    \u0386 ",
      "  a   h  E    \u0386 ",
      "  alaah  E    h ",
      "     hhh-hh///h ",
      "                "
    ],
    [
      "                ",
      "     hhhhhhhhhh ",
      "  aaaah\u0390\u0390\u0390\u0390\u0390\u0390\u0390h ",
      "  a\u0387  h\u0390\u0390\u0390\u0390\u0390\u0390\u0390h ",
      "  a\u0387\u038e h\u0390\u0390\u0390\u0390\u0390\u0390\u0390h ",
      "  ad\u038c h\u0390\u0390\u0390\u0390\u0390\u0390\u0390h ",
      "  ae\u038a h\u0390\u0390\u0390\u0390\u0390\u0390\u0390h ",
      "  a \u038a h\u0390\u0390\u0390\u0390\u0390\u0390\u0390h ",
      "  a \u038a hhhhhhhhh ",
      "  a \u038a h\u038f\u038f\u0390\u0390\u0390\u0390\u0390h ",
      "  a \u0389 h\u038f\u038f\u0390\u0390\u0390\u0390\u0390h ",
      "  a\u0387\u0388 h\u038f\u038f\u0390\u0390\u0390\u0390\u0390h ",
      "  a\u0387  h\u038f\u038f\u0390\u0390\u0390\u0390\u0390h ",
      "  aaaah\u038f\u038f\u0390\u0390\u0390\u0390\u0390h ",
      "     hhhhhhhhhh ",
      "                "
    ]
  ]
}