{
  "name": "building_apartmentsmallb_ground_270",
  "refpalette": "deceasedcraft:building_apartmentsmallb/building_apartmentsmallb_ground_palette_270",
  "xsize": 16,
  "zsize": 16,
  "slices": [
    [
      "aaaaaaaaaaaaaaaa",
      "addddddddddaaaaa",
      "adccccccccbbbbaa",
      "fdccccc!cccccbaa",
      "fdcccccccccccbaa",
      "fdcccccccccccbaa",
      "fdcccccccccccbaa",
      "adcccccccccccbaa",
      "fdcccccccccccbaa",
      "adeeeeeecccccbaa",
      "adeeeeeecccccbaa",
      "adeeeeeecccccbaa",
      "adeeeeeecccccbaa",
      "adeeeeeeccbbbbaa",
      "addddddddddaaaaa",
      "aaaaaaaaaaaaaaaa"
    ],
    [
      "                ",
      " kkkkkkkkkk     ",
      " kuu uunllbbbb  ",
      " C     o  b  b  ",
      " DA       b  b  ",
      " DB       b gb  ",
      " C        b cb  ",
      " k        b cb  ",
      " kpppppp  bjcb  ",
      " tyxs r m   hb  ",
      " twyxywqm   ib  ",
      " trr sxrm   ib  ",
      " twsyry m   ib  ",
      " tr qwxsm bbbb  ",
      " tttttttkkk     ",
      "                "
    ],
    [
      "                ",
      " kttttttkkk     ",
      " k        bbbb  ",
      " C        b  b  ",
      "  K       b  b  ",
      "  L       b  b  ",
      " C        b gb  ",
      " k        b cb  ",
      " k        bFcb  ",
      " t           b  ",
      " tIJ JI     Eb  ",
      " tx         Eb  ",
      " tI J J     Eb  ",
      " t   I    bbbb  ",
      " tttttttkkk     ",
      "                "
    ],
    [
      "                ",
      " kttttttkkk     ",
      " k        bbbb  ",
      " C        b  b  ",
      " R       Pb  b  ",
      " R       Qb  b  ",
      " C        b  b  ",
      " k        b gb  ",
      " k        bOcb  ",
      " t          Mb  ",
      " t          Eb  ",
      " t          Nb  ",
      " t          Eb  ",
      " t        bbbb  ",
      " tttttttkkk     ",
      "                "
    ],
    [
      "                ",
      " kTTTTTTkkk     ",
      " k        bbbb  ",
      " C        b  b  ",
      " C        b  b  ",
      " C        b  b  ",
      " C        b  b  ",
      " k        b  b  ",
      " k        bSgb  ",
      " T        bbcb  ",
      " T        bbcb  ",
      " T        bbcb  ",
      " T        bbcb  ",
      " T        bbbb  ",
      " UTTTTTTkkk     ",
      "                "
    ],
    [
      "                ",
      " kkkkkkkkkk     ",
      " kddddddddbbbb  ",
      " kddddddddb Vb  ",
      " kddddddddb Vb  ",
      " kddddddddb  b  ",
      " kddddddddb  b  ",
      " kddddddddb  b  ",
      " kddddddddb  b  ",
      " kddddddddbSgb  ",
      " kddddddddbbcb  ",
      " kddddddddbbcb  ",
      " kddddddddbbcb  ",
      " kddddddddbbbb  ",
      " kkkkkkkkkk     ",
      "                "
    ]
  ]
}