{
  "name": "building_apartmentsmallb_floor3",
  "refpalette": "deceasedcraft:building_apartmentsmallb/building_apartmentsmallb_floor3_palette",
  "xsize": 16,
  "zsize": 16,
  "slices": [
    [
      "                ",
      "                ",
      "  aaabbbbbbaaa  ",
      "  accd    ecca  ",
      "  accffffffcca  ",
      "  acccccccccca  ",
      " ghhhhhhhhhchhi ",
      " gccccchjjjjjji ",
      " gcccccjjjjjjji ",
      " gjjjjjhjjjjjji ",
      " gjjjjjjjjjjjji ",
      " gjjjjjhjjjjjji ",
      " gjjjjjhjjjjjji ",
      " gjjjjjhjjjjjji ",
      "  kkkkkkkkkkkk  ",
      "                "
    ],
    [
      "                ",
      "                ",
      "  aaaaaaaaaaaa  ",
      "  l  ed      l  ",
      "  a mnoooopq a  ",
      " ha          ah ",
      " hhhhhhhhhhrhhh ",
      " h stuwhxxy  Ah ",
      " h     B     Ch ",
      " hDDDEDhFFFI Jh ",
      " hK    L M  NOh ",
      " hPQ RSh  M TUh ",
      " hPQ  VhW   TUh ",
      " hK   XhW  YTUh ",
      " hhhhhhhhhhhhhh ",
      "                "
    ],
    [
      "                ",
      "                ",
      "  aaaaaaaaaaaa  ",
      "  Z   ed     Z  ",
      "  a 01111110 a  ",
      " ha       2  ah ",
      " hhhhhhhhhh3hhh ",
      " h4s  5h67y 89h ",
      " #     $      % ",
      " hDDD^Dh &!  *h ",
      " h(    )     +h ",
      " -     h     [] ",
      " -    {h}    [] ",
      " -|;::'h ;::'[] ",
      " hh<<<<hh<<<<hh ",
      "                "
    ],
    [
      "                ",
      "                ",
      "  aaaaaaaaaaaa  ",
      "  Z    ed    Z  ",
      "  a 00000000 a  ",
      " ha          ah ",
      " hhhhhhhhhhfhhh ",
      " h>s ,.h? y   h ",
      " /     `      \u0370 ",
      " hDDDDDh      h ",
      " h     `     \u0371h ",
      " -     h     [] ",
      " -     h     [] ",
      " - \u0372\u0373\u0373\u0374h \u0372\u0373\u0373\u0374[] ",
      " hh<<<<hh<<<<hh ",
      "                "
    ],
    [
      "                ",
      "                ",
      "  aaaaaaaaaaaa  ",
      "  l     ed   l  ",
      "  a 0\u0375\u0375\u0375\u0375\u0375\u03750 a  ",
      " ha          ah ",
      " hhhhhhhhhhhhhh ",
      " h     h  y   h ",
      " -     h      ] ",
      " hDDDDDh      h ",
      " h     h  \u0376   h ",
      " <     h     \u0377< ",
      " <     h      < ",
      " <     h     \u037a< ",
      " hh\u037b\u037b\u037b\u037bhh\u037b\u037b\u037b\u037bhh ",
      "                "
    ],
    [
      "                ",
      "                ",
      "  aaaaaaaaaaaa  ",
      "  a\u037c\u037c    ed\u037c\u037ca  ",
      "  a \u037d\u037e\u037f\u037f\u037f\u037f\u0384\u0385 a  ",
      " ha          ah ",
      " hhhhhhhhhhhhhh ",
      " h\u0386\u0386\u0386\u0386\u0386h\u0387\u0387\u0387\u0387\u0387\u0387h ",
      " h\u0386\u0386\u0386\u0386\u0386h\u0387\u0387\u0387\u0387\u0387\u0387h ",
      " h\u0387\u0387\u0387\u0387\u0387h\u0387\u0387\u0387\u0387\u0387\u0387h ",
      " h\u0387\u0387\u0387\u0387\u0387h\u0387\u0387\u0387\u0387\u0387\u0387h ",
      " h\u0387\u0387\u0387\u0387\u0387h\u0387\u0387\u0387\u0387\u0387\u0387h ",
      " h\u0387\u0387\u0387\u0387\u0387h\u0387\u0387\u0387\u0387\u0387\u0387h ",
      " h\u0387\u0387\u0387\u0387\u0387h\u0387\u0387\u0387\u0387\u0387\u0387h ",
      " hhhhhhhhhhhhhh ",
      "                "
    ]
  ]
}