{
  "name": "building_apartmentsmallb_top_180",
  "refpalette": "deceasedcraft:building_apartmentsmallb/building_apartmentsmallb_top_palette_180",
  "xsize": 16,
  "zsize": 16,
  "slices": [
    [
      "                ",
      "  jjjjjjjjjjjj  ",
      " hffffffffffffe ",
      " hffffffffffffe ",
      " hffffffffiiffe ",
      " hffffffffiiffe ",
      " hffffffffgfffe ",
      " hffffffffgfffe ",
      " hffffffffgfffe ",
      " hffffffffgfffe ",
      "  acccccccccca  ",
      "  acccccccccca  ",
      "  accd     cca  ",
      "  aaabbbbbbaaa  ",
      "                ",
      "                "
    ],
    [
      "                ",
      "                ",
      "  qqqqqqqqqqqq  ",
      "  q       xx q  ",
      "  q      wiiuq  ",
      "  q      wiiuq  ",
      "  q       tt q  ",
      "  q    r     q  ",
      "  q   ssr    q  ",
      "  q   ss  gr q  ",
      "  aapaaaaaaaaa  ",
      "  a        ona  ",
      "  a  mmmmmmlka  ",
      "  aaaaaaaaaaaa  ",
      "                ",
      "                "
    ],
    [
      "                ",
      "                ",
      "                ",
      "                ",
      "          KL    ",
      "          KK    ",
      "                ",
      "                ",
      "      I!r       ",
      "      JI  ggg   ",
      "  aaFaaaaaaaEa  ",
      "  aD       CBa  ",
      "  a       Alya  ",
      "  aaaaaaaaaaaa  ",
      "                ",
      "                "
    ],
    [
      "                ",
      "                ",
      "                ",
      "                ",
      "                ",
      "                ",
      "                ",
      "                ",
      "                ",
      "                ",
      "  aaaaaaaaaaaa  ",
      "  aMMMMMMMMMMa  ",
      "  aMMMMMMMMMMa  ",
      "  aaaaaaaaaaaa  ",
      "                ",
      "                "
    ],
    [
      "                ",
      "                ",
      "                ",
      "                ",
      "                ",
      "                ",
      "                ",
      "                ",
      "                ",
      "                ",
      "                ",
      "                ",
      "                ",
      "                ",
      "                ",
      "                "
    ],
    [
      "                ",
      "                ",
      "                ",
      "                ",
      "                ",
      "                ",
      "                ",
      "                ",
      "                ",
      "                ",
      "                ",
      "                ",
      "                ",
      "                ",
      "                ",
      "                "
    ]
  ]
}