{
  "name": "building_apartmentsmallb_ground",
  "refpalette": "deceasedcraft:building_apartmentsmallb/building_apartmentsmallb_ground_palette",
  "xsize": 16,
  "zsize": 16,
  "slices": [
    [
      "aaaaaaaaaaaaaaaa",
      "aaaaaaaaaaaaaaaa",
      "aabbbbbbbbbbbbaa",
      "aabccccccccccbaa",
      "aabccccccccccbaa",
      "adbccccccccccbda",
      "adccccccccccccda",
      "adccccccccccccda",
      "adc!ccccceeeeeda",
      "adccccccceeeeeda",
      "adccccccceeeeeda",
      "adccccccceeeeeda",
      "adccccccceeeeeda",
      "adccccccceeeeeda",
      "adddddddddddddda",
      "aaaffffafaaaaaaa"
    ],
    [
      "                ",
      "                ",
      "  bbbbbbbbbbbb  ",
      "  b  gccchiiib  ",
      "  b     j    b  ",
      " kbbbbbbb    bk ",
      " kl           k ",
      " kl      mmmmmk ",
      " kno    p qr st ",
      " ku     prwxyxt ",
      " ku     p ysrwt ",
      " k      psx yqt ",
      " ku     pxyrs t ",
      " ku AB  pywrwrt ",
      " kkCDDCkktttttt ",
      "                "
    ],
    [
      "                ",
      "                ",
      "  bbbbbbbbbbbb  ",
      "  b   gcc EEEb  ",
      "  b     F    b  ",
      " kbbbbbbb    bk ",
      " k            k ",
      " k            k ",
      " t            t ",
      " t        I J t ",
      " t        J  It ",
      " t          J t ",
      " t        J   t ",
      " t  KL    IxI t ",
      " kkC  Ckktttttt ",
      "                "
    ],
    [
      "                ",
      "                ",
      "  bbbbbbbbbbbb  ",
      "  b    gcMENEb  ",
      "  b     O    b  ",
      " kbbbbbbb    bk ",
      " k  PQ        k ",
      " k            k ",
      " t            t ",
      " t            t ",
      " t            t ",
      " t            t ",
      " t            t ",
      " t            t ",
      " kkCRRCkktttttt ",
      "                "
    ],
    [
      "                ",
      "                ",
      "  bbbbbbbbbbbb  ",
      "  b     gccccb  ",
      "  b     Sbbbbb  ",
      " kbbbbbbbbbbbbk ",
      " k            k ",
      " k            k ",
      " T            T ",
      " T            T ",
      " T            T ",
      " T            T ",
      " T            T ",
      " T            T ",
      " kkCCCCkkTTTTTU ",
      "                "
    ],
    [
      "                ",
      "                ",
      "  bbbbbbbbbbbb  ",
      "  bVV    gcccb  ",
      "  b      Sbbbb  ",
      " kbbbbbbbbbbbbk ",
      " kddddddddddddk ",
      " kddddddddddddk ",
      " kddddddddddddk ",
      " kddddddddddddk ",
      " kddddddddddddk ",
      " kddddddddddddk ",
      " kddddddddddddk ",
      " kddddddddddddk ",
      " kkkkkkkkkkkkkk ",
      "                "
    ]
  ]
}