{
  "name": "building_apartmentsmallb_floor3_270",
  "refpalette": "deceasedcraft:building_apartmentsmallb/building_apartmentsmallb_floor3_palette_270",
  "xsize": 16,
  "zsize": 16,
  "slices": [
    [
      "                ",
      "  gggggggg      ",
      " kjjjjjcchaaaa  ",
      " kjjjjjcchccca  ",
      " kjjjjjcchccca  ",
      " kjjjjjcchcfdb  ",
      " kjjjjjcchcf b  ",
      " khhhjhjhhcf b  ",
      " kjjjjjjjhcf b  ",
      " kjjjjjjjhcf b  ",
      " kjjjjjjjhcfeb  ",
      " kjjjjjjjcccca  ",
      " kjjjjjjjhccca  ",
      " kjjjjjjjhaaaa  ",
      "  iiiiiiii      ",
      "                "
    ],
    [
      "                ",
      " hhhhhhhhhh     ",
      " hKPPKD  haala  ",
      " h QQ D sh   a  ",
      " h    D th m a  ",
      " h  R E uh nea  ",
      " hXVS D wh oda  ",
      " hhhhLhBhh o a  ",
      " hWW  F xh o a  ",
      " h   MF xh o a  ",
      " h  M F yh p a  ",
      " hY   I  r q a  ",
      " hTTTN   h   a  ",
      " hUUUOJCAhaala  ",
      " hhhhhhhhhh     ",
      "                "
    ],
    [
      "                ",
      " h---hh#hhh     ",
      " h|  (D 4haaZa  ",
      " <;   D sh   a  ",
      " <:   D  h 0 a  ",
      " <:   ^  h 1 a  ",
      " <'{  D 5h 1ea  ",
      " hhhh)h$hh 1da  ",
      " h }    6h 1 a  ",
      " <;   & 7h 1 a  ",
      " <:   ! yh21 a  ",
      " <:      3 0 a  ",
      " <'     8h   a  ",
      " h[[[+* 9haaZa  ",
      " h]]]hh%hhh     ",
      "                "
    ],
    [
      "                ",
      " h---hh/hhh     ",
      " h    D >haaZa  ",
      " <\u0372   D sh   a  ",
      " <\u0373   D  h 0 a  ",
      " <\u0373   D ,h 0 a  ",
      " <\u0374   D .h 0 a  ",
      " hhhh`h`hh 0ea  ",
      " h      ?h 0da  ",
      " <\u0372      h 0 a  ",
      " <\u0373     yh 0 a  ",
      " <\u0373      f 0 a  ",
      " <\u0374      h   a  ",
      " h[[[\u0371   haaZa  ",
      " h]]]hh\u0370hhh     ",
      "                "
    ],
    [
      "                ",
      " h<<<hh-hhh     ",
      " h    D  haala  ",
      " \u037b    D  h   a  ",
      " \u037b    D  h 0 a  ",
      " \u037b    D  h \u0375 a  ",
      " \u037b    D  h \u0375 a  ",
      " hhhhhhhhh \u0375 a  ",
      " h       h \u0375ea  ",
      " \u037b       h \u0375da  ",
      " \u037b   \u0376  yh \u0375 a  ",
      " \u037b       h 0 a  ",
      " \u037b       h   a  ",
      " h\u037a \u0377    haala  ",
      " h<<<hh]hhh     ",
      "                "
    ],
    [
      "                ",
      " hhhhhhhhhh     ",
      " h\u0387\u0387\u0387\u0387\u0387\u0386\u0386haaaa  ",
      " h\u0387\u0387\u0387\u0387\u0387\u0386\u0386h  \u037ca  ",
      " h\u0387\u0387\u0387\u0387\u0387\u0386\u0386h \u037d\u037ca  ",
      " h\u0387\u0387\u0387\u0387\u0387\u0386\u0386h \u037e a  ",
      " h\u0387\u0387\u0387\u0387\u0387\u0386\u0386h \u037f a  ",
      " hhhhhhhhh \u037f a  ",
      " h\u0387\u0387\u0387\u0387\u0387\u0387\u0387h \u037f a  ",
      " h\u0387\u0387\u0387\u0387\u0387\u0387\u0387h \u037fea  ",
      " h\u0387\u0387\u0387\u0387\u0387\u0387\u0387h \u0384da  ",
      " h\u0387\u0387\u0387\u0387\u0387\u0387\u0387h \u0385\u037ca  ",
      " h\u0387\u0387\u0387\u0387\u0387\u0387\u0387h  \u037ca  ",
      " h\u0387\u0387\u0387\u0387\u0387\u0387\u0387haaaa  ",
      " hhhhhhhhhh     ",
      "                "
    ]
  ]
}