{
  "name": "building_apartmentsmallb_floor1_90",
  "refpalette": "deceasedcraft:building_apartmentsmallb/building_apartmentsmallb_floor1_palette_90",
  "xsize": 16,
  "zsize": 16,
  "slices": [
    [
      "                ",
      "      iiiiiiii  ",
      "  aaaahjjjjjjjk ",
      "  accchjjjjjjjk ",
      "  accccjjjjjjjk ",
      "  befchjjjjjjjk ",
      "  b fchjjjjjjjk ",
      "  b fchjjjjjjjk ",
      "  b fchhjhjhhhk ",
      "  b fchccjjjjjk ",
      "  bdfchccjjjjjk ",
      "  accchccjjjjjk ",
      "  accchccjjjjjk ",
      "  aaaahccjjjjjk ",
      "      gggggggg  ",
      "                "
    ],
    [
      "                ",
      "     hhhhhhhhhh ",
      "  alaahADKOTTTh ",
      "  a   h    SSSh ",
      "  a q r  J   Yh ",
      "  a p hy IN   h ",
      "  a o hx IN   h ",
      "  a o hx I  VVh ",
      "  a o hhChMhhhh ",
      "  ado hw E RUXh ",
      "  aen hu F   Wh ",
      "  a m htBE    h ",
      "  a   hs E QQ h ",
      "  alaah  ELPPLh ",
      "     hhhhhhhhhh ",
      "                "
    ],
    [
      "                ",
      "     hhh%hh]]]h ",
      "  aZaah9  +[[[h ",
      "  a   h8     ,. ",
      "  a 0 3      >. ",
      "  a 12hy *   >. ",
      "  a 1 h7     <. ",
      "  a 1 h6 &  }'h ",
      "  ad1 hh$h)hhhh ",
      "  ae1 h5 E !{:. ",
      "  a 1 h  ^   ;. ",
      "  a 0 h  E   ;. ",
      "  a   hs E   |. ",
      "  aZaah4 E(  (h ",
      "     hhh#hh---h ",
      "                "
    ],
    [
      "                ",
      "     hhh\u0374hh]]]h ",
      "  aZaah   \u0375[[[h ",
      "  a   h      \u037d. ",
      "  a 0 f      \u037c. ",
      "  a 0 hy     \u037c. ",
      "  a 0 h\u0371     \u037b. ",
      "  ad0 h\u0370      h ",
      "  ae0 hh\u0373h\u0373hhhh ",
      "  a 0 h` E   \u037a. ",
      "  a 0 h/ E   \u0377. ",
      "  a 0 h  E   \u0377. ",
      "  a   hs E   \u0376. ",
      "  aZaah? E    h ",
      "     hhh\u0372hh---h ",
      "                "
    ],
    [
      "                ",
      "     hhh]hh...h ",
      "  alaah     \u0384 h ",
      "  a   h       \u0385 ",
      "  a 0 h       \u0385 ",
      "  a \u037e hy  \u037f   \u0385 ",
      "  ad\u037e h       \u0385 ",
      "  ae\u037e h       h ",
      "  a \u037e hhhhhhhhh ",
      "  a \u037e h  E    \u0385 ",
      "  a \u037e h  E    \u0385 ",
      "  a 0 h  E    \u0385 ",
      "  a   h  E    \u0385 ",
      "  alaah  E    h ",
      "     hhh-hh...h ",
      "                "
    ],
    [
      "                ",
      "     hhhhhhhhhh ",
      "  aaaah\u038f\u038f\u038f\u038f\u038f\u038f\u038fh ",
      "  a\u0386  h\u038f\u038f\u038f\u038f\u038f\u038f\u038fh ",
      "  a\u0386\u038c h\u038f\u038f\u038f\u038f\u038f\u038f\u038fh ",
      "  ad\u038a h\u038f\u038f\u038f\u038f\u038f\u038f\u038fh ",
      "  ae\u0389 h\u038f\u038f\u038f\u038f\u038f\u038f\u038fh ",
      "  a \u0389 h\u038f\u038f\u038f\u038f\u038f\u038f\u038fh ",
      "  a \u0389 hhhhhhhhh ",
      "  a \u0389 h\u038e\u038e\u038f\u038f\u038f\u038f\u038fh ",
      "  a \u0388 h\u038e\u038e\u038f\u038f\u038f\u038f\u038fh ",
      "  a\u0386\u0387 h\u038e\u038e\u038f\u038f\u038f\u038f\u038fh ",
      "  a\u0386  h\u038e\u038e\u038f\u038f\u038f\u038f\u038fh ",
      "  aaaah\u038e\u038e\u038f\u038f\u038f\u038f\u038fh ",
      "     hhhhhhhhhh ",
      "                "
    ]
  ]
}