{
  "name": "building_apartmentsmallb_floor1",
  "refpalette": "deceasedcraft:building_apartmentsmallb/building_apartmentsmallb_floor1_palette",
  "xsize": 16,
  "zsize": 16,
  "slices": [
    [
      "                ",
      "                ",
      "  aaabbbbbbaaa  ",
      "  accd    ecca  ",
      "  accffffffcca  ",
      "  acccccccccca  ",
      " ghhhhhhhhhchhi ",
      " gccccchjjjjjji ",
      " gcccccjjjjjjji ",
      " gjjjjjhjjjjjji ",
      " gjjjjjjjjjjjji ",
      " gjjjjjhjjjjjji ",
      " gjjjjjhjjjjjji ",
      " gjjjjjhjjjjjji ",
      "  kkkkkkkkkkkk  ",
      "                "
    ],
    [
      "                ",
      "                ",
      "  aaaaaaaaaaaa  ",
      "  l  ed      l  ",
      "  a mnoooopq a  ",
      " ha          ah ",
      " hhhhhhhhhhrhhh ",
      " h stuwhxxy  Ah ",
      " h  B  C     Dh ",
      " hEEEFEhIIIJ Kh ",
      " hL    M NN  Oh ",
      " hPQ  Rh    STh ",
      " hPQ  UhV   STh ",
      " hL  WXhV  YSTh ",
      " hhhhhhhhhhhhhh ",
      "                "
    ],
    [
      "                ",
      "                ",
      "  aaaaaaaaaaaa  ",
      "  Z   ed     Z  ",
      "  a 01111110 a  ",
      " ha       2  ah ",
      " hhhhhhhhhh3hhh ",
      " h4s  5h67y 89h ",
      " #     $      % ",
      " hEEE^Eh& *   h ",
      " h(    )     +h ",
      " -    !h     [] ",
      " -    {h}    [] ",
      " -(|;;:h'<>>,[] ",
      " hh....hh....hh ",
      "                "
    ],
    [
      "                ",
      "                ",
      "  aaaaaaaaaaaa  ",
      "  Z    ed    Z  ",
      "  a 00000000 a  ",
      " ha          ah ",
      " hhhhhhhhhhfhhh ",
      " h?s /`h\u0370\u0371y   h ",
      " \u0372     \u0373      \u0374 ",
      " hEEEEEh      h ",
      " h     \u0373     \u0375h ",
      " -     h     [] ",
      " -     h     [] ",
      " - \u0376\u0377\u0377\u037ah \u037b\u037c\u037c\u037d[] ",
      " hh....hh....hh ",
      "                "
    ],
    [
      "                ",
      "                ",
      "  aaaaaaaaaaaa  ",
      "  l     ed   l  ",
      "  a 0\u037e\u037e\u037e\u037e\u037e\u037e0 a  ",
      " ha          ah ",
      " hhhhhhhhhhhhhh ",
      " h     h  y   h ",
      " -     h      ] ",
      " hEEEEEh      h ",
      " h     h  \u037f   h ",
      " .     h      . ",
      " .     h     \u0384. ",
      " .     h      . ",
      " hh\u0385\u0385\u0385\u0385hh\u0385\u0385\u0385\u0385hh ",
      "                "
    ],
    [
      "                ",
      "                ",
      "  aaaaaaaaaaaa  ",
      "  a\u0386\u0386    ed\u0386\u0386a  ",
      "  a \u0387\u0388\u0389\u0389\u0389\u0389\u038a\u038c a  ",
      " ha          ah ",
      " hhhhhhhhhhhhhh ",
      " h\u038e\u038e\u038e\u038e\u038eh\u038f\u038f\u038f\u038f\u038f\u038fh ",
      " h\u038e\u038e\u038e\u038e\u038eh\u038f\u038f\u038f\u038f\u038f\u038fh ",
      " h\u038f\u038f\u038f\u038f\u038fh\u038f\u038f\u038f\u038f\u038f\u038fh ",
      " h\u038f\u038f\u038f\u038f\u038fh\u038f\u038f\u038f\u038f\u038f\u038fh ",
      " h\u038f\u038f\u038f\u038f\u038fh\u038f\u038f\u038f\u038f\u038f\u038fh ",
      " h\u038f\u038f\u038f\u038f\u038fh\u038f\u038f\u038f\u038f\u038f\u038fh ",
      " h\u038f\u038f\u038f\u038f\u038fh\u038f\u038f\u038f\u038f\u038f\u038fh ",
      " hhhhhhhhhhhhhh ",
      "                "
    ]
  ]
}