{
  "name": "building_apartmentsmallb_floor1_270",
  "refpalette": "deceasedcraft:building_apartmentsmallb/building_apartmentsmallb_floor1_palette_270",
  "xsize": 16,
  "zsize": 16,
  "slices": [
    [
      "                ",
      "  gggggggg      ",
      " kjjjjjcchaaaa  ",
      " kjjjjjcchccca  ",
      " kjjjjjcchccca  ",
      " kjjjjjcchcfdb  ",
      " kjjjjjcchcf b  ",
      " khhhjhjhhcf b  ",
      " kjjjjjjjhcf b  ",
      " kjjjjjjjhcf b  ",
      " kjjjjjjjhcfeb  ",
      " kjjjjjjjcccca  ",
      " kjjjjjjjhccca  ",
      " kjjjjjjjhaaaa  ",
      "  iiiiiiii      ",
      "                "
    ],
    [
      "                ",
      " hhhhhhhhhh     ",
      " hLPPLE  haala  ",
      " h QQ E sh   a  ",
      " h    EBth m a  ",
      " hW   F uh nea  ",
      " hXUR E wh oda  ",
      " hhhhMhChh o a  ",
      " hVV  I xh o a  ",
      " h   NI xh o a  ",
      " h   NI yh p a  ",
      " hY   J  r q a  ",
      " hSSS    h   a  ",
      " hTTTOKDAhaala  ",
      " hhhhhhhhhh     ",
      "                "
    ],
    [
      "                ",
      " h---hh#hhh     ",
      " h(  (E 4haaZa  ",
      " .|   E sh   a  ",
      " .;   E  h 0 a  ",
      " .;   ^  h 1 a  ",
      " .:{! E 5h 1ea  ",
      " hhhh)h$hh 1da  ",
      " h'}  & 6h 1 a  ",
      " .<     7h 1 a  ",
      " .>   * yh21 a  ",
      " .>      3 0 a  ",
      " .,     8h   a  ",
      " h[[[+  9haaZa  ",
      " h]]]hh%hhh     ",
      "                "
    ],
    [
      "                ",
      " h---hh\u0372hhh     ",
      " h    E ?haaZa  ",
      " .\u0376   E sh   a  ",
      " .\u0377   E  h 0 a  ",
      " .\u0377   E /h 0 a  ",
      " .\u037a   E `h 0 a  ",
      " hhhh\u0373h\u0373hh 0ea  ",
      " h      \u0370h 0da  ",
      " .\u037b     \u0371h 0 a  ",
      " .\u037c     yh 0 a  ",
      " .\u037c      f 0 a  ",
      " .\u037d      h   a  ",
      " h[[[\u0375   haaZa  ",
      " h]]]hh\u0374hhh     ",
      "                "
    ],
    [
      "                ",
      " h...hh-hhh     ",
      " h    E  haala  ",
      " \u0385    E  h   a  ",
      " \u0385    E  h 0 a  ",
      " \u0385    E  h \u037e a  ",
      " \u0385    E  h \u037e a  ",
      " hhhhhhhhh \u037e a  ",
      " h       h \u037eea  ",
      " \u0385       h \u037eda  ",
      " \u0385   \u037f  yh \u037e a  ",
      " \u0385       h 0 a  ",
      " \u0385       h   a  ",
      " h \u0384     haala  ",
      " h...hh]hhh     ",
      "                "
    ],
    [
      "                ",
      " hhhhhhhhhh     ",
      " h\u038f\u038f\u038f\u038f\u038f\u038e\u038ehaaaa  ",
      " h\u038f\u038f\u038f\u038f\u038f\u038e\u038eh  \u0386a  ",
      " h\u038f\u038f\u038f\u038f\u038f\u038e\u038eh \u0387\u0386a  ",
      " h\u038f\u038f\u038f\u038f\u038f\u038e\u038eh \u0388 a  ",
      " h\u038f\u038f\u038f\u038f\u038f\u038e\u038eh \u0389 a  ",
      " hhhhhhhhh \u0389 a  ",
      " h\u038f\u038f\u038f\u038f\u038f\u038f\u038fh \u0389 a  ",
      " h\u038f\u038f\u038f\u038f\u038f\u038f\u038fh \u0389ea  ",
      " h\u038f\u038f\u038f\u038f\u038f\u038f\u038fh \u038ada  ",
      " h\u038f\u038f\u038f\u038f\u038f\u038f\u038fh \u038c\u0386a  ",
      " h\u038f\u038f\u038f\u038f\u038f\u038f\u038fh  \u0386a  ",
      " h\u038f\u038f\u038f\u038f\u038f\u038f\u038fhaaaa  ",
      " hhhhhhhhhh     ",
      "                "
    ]
  ]
}