{
  "name": "building_apartmentsmallb_floor2_270",
  "refpalette": "deceasedcraft:building_apartmentsmallb/building_apartmentsmallb_floor2_palette_270",
  "xsize": 16,
  "zsize": 16,
  "slices": [
    [
      "                ",
      "  gggggggg      ",
      " kjjjjjcchaaaa  ",
      " kjjjjjcchccca  ",
      " kjjjjjcchccca  ",
      " kjjjjjcchcfdb  ",
      " kjjjjjcchcf b  ",
      " khhhjhjhhcf b  ",
      " kjjjjjjjhcf b  ",
      " kjjjjjjjhcf b  ",
      " kjjjjjjjhcfeb  ",
      " kjjjjjjjcccca  ",
      " kjjjjjjjhccca  ",
      " kjjjjjjjhaaaa  ",
      "  iiiiiiii      ",
      "                "
    ],
    [
      "                ",
      " hhhhhhhhhh     ",
      " hMQQME! haala  ",
      " h RR EBsh   a  ",
      " h    E th m a  ",
      " hYV  F uh nea  ",
      " hZWS E wh oda  ",
      " hhhhNhChh o a  ",
      " hXX  I xh o a  ",
      " h   OI xh o a  ",
      " h   OI yh p a  ",
      " h0   J  r q a  ",
      " hTTT K  h   a  ",
      " hUUUPLDAhaala  ",
      " hhhhhhhhhh     ",
      "                "
    ],
    [
      "                ",
      " h---hh$hhh     ",
      " h;  (EB6haa1a  ",
      " /:   E sh   a  ",
      " /'   E  h 2 a  ",
      " /'   &  h 3 a  ",
      " /<}[ E 7h 3ea  ",
      " hhhh)h%hh 3da  ",
      " h>|  * 8h 3 a  ",
      " /,     9h 3 a  ",
      " /.   K yh43 a  ",
      " /.      5 2 a  ",
      " /?     #h   a  ",
      " h]]]+! Khaa1a  ",
      " h{{{hh^hhh     ",
      "                "
    ],
    [
      "                ",
      " h---hh\u0374hhh     ",
      " h    E `haa1a  ",
      " /\u0377   E sh   a  ",
      " /\u037a   E  h 2 a  ",
      " /\u037a   E \u0370h 2 a  ",
      " /\u037b   E \u0371h 2 a  ",
      " hhhh\u0375h\u0375hh 2ea  ",
      " h      \u0372h 2da  ",
      " /\u037c     \u0373h 2 a  ",
      " /\u037d     yh 2 a  ",
      " /\u037d      f 2 a  ",
      " /\u037e      h   a  ",
      " h]]]    haa1a  ",
      " h{{{hh\u0376hhh     ",
      "                "
    ],
    [
      "                ",
      " h///hh-hhh     ",
      " h    E  haala  ",
      " \u0386    E  h   a  ",
      " \u0386    E  h 2 a  ",
      " \u0386    E  h \u037f a  ",
      " \u0386    E  h \u037f a  ",
      " hhhhhhhhh \u037f a  ",
      " h       h \u037fea  ",
      " \u0386       h \u037fda  ",
      " \u0386   \u0384  yh \u037f a  ",
      " \u0386       h 2 a  ",
      " \u0386       h   a  ",
      " h\u0385      haala  ",
      " h///hh{hhh     ",
      "                "
    ],
    [
      "                ",
      " hhhhhhhhhh     ",
      " h\u0390\u0390\u0390\u0390\u0390\u038f\u038fhaaaa  ",
      " h\u0390\u0390\u0390\u0390\u0390\u038f\u038fh  \u0387a  ",
      " h\u0390\u0390\u0390\u0390\u0390\u038f\u038fh \u0388\u0387a  ",
      " h\u0390\u0390\u0390\u0390\u0390\u038f\u038fh \u0389 a  ",
      " h\u0390\u0390\u0390\u0390\u0390\u038f\u038fh \u038a a  ",
      " hhhhhhhhh \u038a a  ",
      " h\u0390\u0390\u0390\u0390\u0390\u0390\u0390h \u038a a  ",
      " h\u0390\u0390\u0390\u0390\u0390\u0390\u0390h \u038aea  ",
      " h\u0390\u0390\u0390\u0390\u0390\u0390\u0390h \u038cda  ",
      " h\u0390\u0390\u0390\u0390\u0390\u0390\u0390h \u038e\u0387a  ",
      " h\u0390\u0390\u0390\u0390\u0390\u0390\u0390h  \u0387a  ",
      " h\u0390\u0390\u0390\u0390\u0390\u0390\u0390haaaa  ",
      " hhhhhhhhhh     ",
      "                "
    ]
  ]
}