{
  "name": "building_apartmentsmallb_ground_90",
  "refpalette": "deceasedcraft:building_apartmentsmallb/building_apartmentsmallb_ground_palette_90",
  "xsize": 16,
  "zsize": 16,
  "slices": [
    [
      "aaaaaaaaaaaaaaaa",
      "aaaaadddddddddda",
      "aabbbbcceeeeeeda",
      "aabccccceeeeeeda",
      "aabccccceeeeeeda",
      "aabccccceeeeeeda",
      "aabccccceeeeeeda",
      "aabcccccccccccdf",
      "aabcccccccccccda",
      "aabcccccccccccdf",
      "aabcccccccccccdf",
      "aabcccccccccccdf",
      "aabccccc!cccccdf",
      "aabbbbccccccccda",
      "aaaaadddddddddda",
      "aaaaaaaaaaaaaaaa"
    ],
    [
      "                ",
      "     kkkttttttt ",
      "  bbbb msxwq rt ",
      "  bi   m yryswt ",
      "  bi   mrxs rrt ",
      "  bi   mqwyxywt ",
      "  bh   m r sxyt ",
      "  bcjb  ppppppk ",
      "  bc b        k ",
      "  bc b        C ",
      "  bg b       BD ",
      "  b  b       AD ",
      "  b  b  o     C ",
      "  bbbbllnuu uuk ",
      "     kkkkkkkkkk ",
      "                "
    ],
    [
      "                ",
      "     kkkttttttt ",
      "  bbbb    I   t ",
      "  bE     J J It ",
      "  bE         xt ",
      "  bE     IJ JIt ",
      "  b           t ",
      "  bcFb        k ",
      "  bc b        k ",
      "  bg b        C ",
      "  b  b       L  ",
      "  b  b       K  ",
      "  b  b        C ",
      "  bbbb        k ",
      "     kkkttttttk ",
      "                "
    ],
    [
      "                ",
      "     kkkttttttt ",
      "  bbbb        t ",
      "  bE          t ",
      "  bN          t ",
      "  bE          t ",
      "  bM          t ",
      "  bcOb        k ",
      "  bg b        k ",
      "  b  b        C ",
      "  b  bQ       R ",
      "  b  bP       R ",
      "  b  b        C ",
      "  bbbb        k ",
      "     kkkttttttk ",
      "                "
    ],
    [
      "                ",
      "     kkkTTTTTTU ",
      "  bbbb        T ",
      "  bcbb        T ",
      "  bcbb        T ",
      "  bcbb        T ",
      "  bcbb        T ",
      "  bgSb        k ",
      "  b  b        k ",
      "  b  b        C ",
      "  b  b        C ",
      "  b  b        C ",
      "  b  b        C ",
      "  bbbb        k ",
      "     kkkTTTTTTk ",
      "                "
    ],
    [
      "                ",
      "     kkkkkkkkkk ",
      "  bbbbddddddddk ",
      "  bcbbddddddddk ",
      "  bcbbddddddddk ",
      "  bcbbddddddddk ",
      "  bgSbddddddddk ",
      "  b  bddddddddk ",
      "  b  bddddddddk ",
      "  b  bddddddddk ",
      "  b  bddddddddk ",
      "  bV bddddddddk ",
      "  bV bddddddddk ",
      "  bbbbddddddddk ",
      "     kkkkkkkkkk ",
      "                "
    ]
  ]
}