{
  "name": "multi_courtyardofficetower_13_ground",
  "refpalette": "deceasedcraft:multi_courtyardofficetower_13/multi_courtyardofficetower_13_ground_palette",
  "xsize": 16,
  "zsize": 16,
  "slices": [
    [
      "aaaaaaaaaaaaaaaa",
      "aaaaaaaaaaaaaaaa",
      "aaaaaaaaaaaaaaaa",
      "aaaaaaaaaaaaaaaa",
      "aaaaaaaaaaaaaaaa",
      "aaaaaaaaaaaaaaaa",
      "bbbbbbbbbbbbbbbb",
      "cccccccccccccccc",
      "bbbbbbbbbbbbbbbb",
      "aaaaaaaaaaaaaaaa",
      "aaaaaaaaaaaaaaaa",
      "addddddddaaaaaaa",
      "adeeeeeedaaaaaaa",
      "ad      daaaaaaa",
      "ad      daaaaaaa",
      "ad      daaaaaaa"
    ],
    [
      "f     g f  g f  ",
      "hf  f       f   ",
      "             g  ",
      "   gf           ",
      " ff     ff     f",
      " i  jkl  i      ",
      "                ",
      "                ",
      "                ",
      "                ",
      "ffffffffffffffff",
      " mmmmmmmmf      ",
      " m      mf f    ",
      " m      mf    g ",
      " m      mf  g f ",
      " m      mf      "
    ],
    [
      "      n    n    ",
      "o               ",
      "             n  ",
      "   n            ",
      "                ",
      "                ",
      "                ",
      "                ",
      "                ",
      "                ",
      "                ",
      "                ",
      "                ",
      "              n ",
      "            n   ",
      "                "
    ],
    [
      "      f    f    ",
      "n               ",
      "             f  ",
      "   f            ",
      "                ",
      "                ",
      "                ",
      "                ",
      "                ",
      "                ",
      "                ",
      "                ",
      "                ",
      "              f ",
      "            f   ",
      "                "
    ],
    [
      "      f    f    ",
      "f               ",
      "   f         f  ",
      "  fff           ",
      "   f            ",
      "                ",
      "                ",
      "                ",
      "                ",
      "                ",
      "                ",
      "                ",
      "                ",
      "              f ",
      "            f   ",
      "                "
    ],
    [
      "p     f    f    ",
      "ff              ",
      "f  p         f  ",
      "   ff           ",
      "   f            ",
      "                ",
      "                ",
      "                ",
      "                ",
      "                ",
      "                ",
      "                ",
      "                ",
      "              f ",
      "            f   ",
      "                "
    ]
  ]
}