{
  "name": "multi_courtyardofficetower_13_base1",
  "refpalette": "deceasedcraft:multi_courtyardofficetower_13/multi_courtyardofficetower_13_base1_palette",
  "xsize": 16,
  "zsize": 16,
  "slices": [
    [
      "vvvvvvvaaaaaaaav",
      "vvvvvvvaaaaaaaav",
      "vvvvvvvaaaaaaaav",
      "vvvvvvvvaaaaaaav",
      "vvvvvvvvaaaaaaav",
      "vvvvvvvvaaaaaaav",
      "vvvvvvvvaaaaaaav",
      "vvvvvvvvaaaaaaav",
      "avvvvvvvaaaaaaav",
      "avvvvvvvaaaaaaav",
      "avvvvvvvaaaaaaav",
      "avvvvvvvvaaaaaav",
      "aaaaaaaaaaaaaaav",
      "aaaaaaaaaaaaaaav",
      "aaaaaaaaaaaaaaav",
      "aaaaaaaaaaaaaaav"
    ],
    [
      "vbHHHbvaaaaaaaav",
      "vbHHHbvaaaaaaaav",
      "vbHHHbvaaaaaaaav",
      "vbHHHbbvaaaaaaav",
      "vbHHHHbvaaaaaaav",
      "vbHHHHbvaaaaaaav",
      "vbHHHHbvaaaaaaav",
      "vbbHHHbvaaaaaaav",
      "avbHHHbvaaaaaaav",
      "avbHHHbvaaaaaaav",
      "avbHHHbvaaaaaaav",
      "avbHHHbbvaaaaaav",
      "avvvvvvvvaaaaaav",
      "avvvvvvvvaaaaaav",
      "avvvvvvvvaaaaaav",
      "aaaaaaaaaaaaaaav"
    ],
    [
      "v     vaaaaaaaav",
      "v     vaaaaaaaav",
      "v     vaaaaaaaav",
      "v      vaaaaaaav",
      "v      vaaaaaaav",
      "v      vaaaaaaav",
      "v      vaaaaaaav",
      "v      vaaaaaaav",
      "av     vaaaaaaav",
      "av     vaaaaaaav",
      "av     vaaaaaaav",
      "avcdddccvaaaaaav",
      "aveffffevaaaaaav",
      "avbHHHHbvaaaaaav",
      "avbHHHHbvaaaaaav",
      "avvvvvvvvaaaaaav"
    ],
    [
      "v     vaaaaaaaav",
      "v     vaaaaaaaav",
      "v     vaaaaaaaav",
      "v      vaaaaaaav",
      "v      vaaaaaaav",
      "v      vaaaaaaav",
      "v      vaaaaaaav",
      "v      vaaaaaaav",
      "av     vaaaaaaav",
      "av     vaaaaaaav",
      "av     vaaaaaaav",
      "av      vaaaaaav",
      "av      vaaaaaav",
      "av      vaaaaaav",
      "avcddddcvaaaaaav",
      "aveefffevaaaaaav"
    ],
    [
      "v     vaaaaaaaav",
      "v     vaaaaaaaav",
      "v     vaaaaaaaav",
      "v      vaaaaaaav",
      "v      vaaaaaaav",
      "v      vaaaaaaav",
      "v      vaaaaaaav",
      "v      vaaaaaaav",
      "av     vaaaaaaav",
      "av     vaaaaaaav",
      "av     vaaaaaaav",
      "av      vaaaaaav",
      "av      vaaaaaav",
      "av      vaaaaaav",
      "av      vaaaaaav",
      "av      vaaaaaav"
    ],
    [
      "vgggggvaaaaaaaav",
      "vgggggvaaaaaaaav",
      "vgggggvaaaaaaaav",
      "vggggggvaaaaaaav",
      "vggggggvaaaaaaav",
      "vggggggvaaaaaaav",
      "vggggggvaaaaaaav",
      "vggggggvaaaaaaav",
      "avgggggvaaaaaaav",
      "avgggggvaaaaaaav",
      "avgggggvaaaaaaav",
      "av      vaaaaaav",
      "av      vaaaaaav",
      "av      vaaaaaav",
      "av      vaaaaaav",
      "av      vaaaaaav"
    ]
  ]
}