{
  "name": "multi_verticalschool_11_floor17",
  "refpalette": "deceasedcraft:multi_verticalschool_11/multi_verticalschool_11_floor17_palette",
  "xsize": 16,
  "zsize": 16,
  "slices": [
    [
      "aaaaaaaaaaaaaaa ",
      "            bbba",
      "               a",
      "               a",
      "               a",
      "               a",
      "       c       a",
      "               a",
      "               a",
      "               a",
      "               a",
      "       c       a",
      "               a",
      "               a",
      "               a",
      "               a"
    ],
    [
      "aaaaaaaaaaaaaaa ",
      "            bbba",
      "               a",
      "               a",
      "               a",
      "               a",
      "       c       a",
      "               a",
      "               a",
      "               a",
      "               a",
      "       c       a",
      "               a",
      "               a",
      "               a",
      "               a"
    ],
    [
      "aaaaaaaaaaaaaaad",
      "    eeeeeeeebbba",
      "    eeeeeeeeeeea",
      "    eeeeeeeeeeea",
      "    eeeeeeeeeeea",
      "    eeeeeeeeeeea",
      "    eeefeeeeeeea",
      "    eeeeeeeeeeea",
      "    eeeeeeeeeeea",
      "    eeeeeeeeeeea",
      "    eeeeeeeeeeea",
      "    eeefeeeeeeea",
      "    eeeeeeeeeeea",
      "    eeeeeeeeeeea",
      "    eeeeeeeeeeea",
      "    eeeeeeeeeeea"
    ],
    [
      "gggggggggggggggg",
      "hhhhiiiiiiiibbbg",
      "jjjhikkkkkkkkkig",
      "  jhikkkkkkkkkig",
      "  jhikkkkkkkkkig",
      "  jhikkkkkkkkkig",
      "  jhikkkkkkkkkig",
      "  jhikkkkkkkkkig",
      "  jhikkkkkkkkkig",
      "  jhikkkkkkkkkig",
      "  jhikkkkklkkkig",
      "  jhikkkkmlmkkig",
      "  jhikkkkknmlkig",
      "  jhikkkkkknokig",
      "  jhikkkkkkkknog",
      "  jhikkkkkkkkkig"
    ],
    [
      "    p           ",
      "    iiiiiiiibbb ",
      "qq  irsssrssssi ",
      "  t u         i ",
      "  t w         i ",
      "  t ix xx xx xi ",
      "  t iy AB AB yi ",
      "  t i Cx      i ",
      "  t ixy y xx xi ",
      "  t iyDEx AB yi ",
      "  t i  FCI J xi ",
      "  t ix x  K Lyi ",
      "  t iy yxM  I i ",
      "  t N   y     i ",
      "  t O    P      ",
      "  t iQRSSSSSTUi "
    ],
    [
      "                ",
      "    VVVVVVVVbbb ",
      "    VssWssssrsV ",
      "    X         Y ",
      "    Z         Y ",
      "    V         V ",
      "    Y0 12 D2 3Y ",
      "    Y         Y ",
      "    Y         Y ",
      "    Y1     1 2Y ",
      "    Y         Y ",
      "    Y         Y ",
      "    V4 1      V ",
      "    5         Y ",
      "    6           ",
      "    V1   7   89 "
    ]
  ]
}