{
  "name": "multi_verticalschool_11_floor19",
  "refpalette": "deceasedcraft:multi_verticalschool_11/multi_verticalschool_11_floor19_palette",
  "xsize": 16,
  "zsize": 16,
  "slices": [
    [
      "                ",
      "    aaaaaaaabbb ",
      "    accccccc ca ",
      "    d         d ",
      "    d         d ",
      "    a         a ",
      "    d         d ",
      "    d         d ",
      "    d         d ",
      "    d         d ",
      "    d         d ",
      "    d         d ",
      "    a         a ",
      "    d         d ",
      "    d         d ",
      "    ae        a "
    ],
    [
      "                ",
      "    aaaaaaaabbb ",
      "    a         a ",
      "    a         a ",
      "    a         a ",
      "    a         a ",
      "    a         a ",
      "    a         a ",
      "    a         a ",
      "    a         a ",
      "    a         a ",
      "    a         a ",
      "    a         a ",
      "    a         a ",
      "    a         a ",
      "    af        a "
    ],
    [
      "gggggggggggggggg",
      "    aaaaaaaabbbg",
      "    ahhhhhhhhhag",
      "    ahhhhhhhhhag",
      "    ahihhjhhihag",
      "    ahhhhhhhhhag",
      "    ahhhhhhhhhag",
      "    ahjhhihhihag",
      "    ahhhhhhhhhag",
      "    ahhhhhhhhhag",
      "    ahihhihhihag",
      "    ahhhhhhhhhag",
      "    ahhhhhhhhhag",
      "    ahjhhihhihag",
      "    ahhhhhhhhhag",
      "    ahhhhhhhhhag"
    ],
    [
      "kkkkkkkkkkkkkkkk",
      "llllmmmmmmmmbbbk",
      "nnnlmooooooooomk",
      "  nlmooooooooomk",
      "  nlmooooooooomk",
      "  nlmooooooooomk",
      "  nlmooooooooomk",
      "  nlmooooooooomk",
      "  nlmooooooooomk",
      "  nlmooooooooomk",
      "  nlmooooooooomk",
      "  nlmooooooooomk",
      "  nlmooooooooomk",
      "  nlmooooooooomk",
      "  nlmooooooooomk",
      "  nlmooooooooomk"
    ],
    [
      "    p           ",
      "    mmmmmmmmbbb ",
      "qq  mrsssrssssm ",
      "  t u         m ",
      "  t w         m ",
      "  t mx xx xx xm ",
      "  t my AB AB ym ",
      "  t m         m ",
      "  t mx xx xx xm ",
      "  t my AB AB ym ",
      "  t m         m ",
      "  t mx xx xx xm ",
      "  t my AB AB ym ",
      "  t u         m ",
      "  t w    C    m ",
      "  t mDEFFFFFIIm "
    ],
    [
      "                ",
      "    aaaaaaaabbb ",
      "    assJssssrsa ",
      "    K         d ",
      "    L         d ",
      "    a         a ",
      "    dM NO PO Qd ",
      "    d         d ",
      "    d         d ",
      "    dN R   P !d ",
      "    d         d ",
      "    d         d ",
      "    aS NP  O Na ",
      "    K         d ",
      "    L         d ",
      "    a N  T   Ua "
    ]
  ]
}