{
  "name": "multi_verticalschool_11_floor10",
  "refpalette": "deceasedcraft:multi_verticalschool_11/multi_verticalschool_11_floor10_palette",
  "xsize": 16,
  "zsize": 16,
  "slices": [
    [
      "                ",
      "           abbbc",
      "                ",
      "                ",
      "                ",
      "                ",
      "                ",
      "                ",
      "                ",
      "                ",
      "                ",
      "                ",
      "                ",
      "                ",
      "                ",
      "ddddddddddddddd "
    ],
    [
      "                ",
      "            bbb ",
      "                ",
      "                ",
      "                ",
      "                ",
      "                ",
      "                ",
      "                ",
      "                ",
      "                ",
      "                ",
      "                ",
      "                ",
      "                ",
      "ddddddddddddddd "
    ],
    [
      "                ",
      "            bbb ",
      "                ",
      "                ",
      "                ",
      "eeeeeeeeeeeeeeee",
      "                ",
      "ffffffffffffffff",
      "fggggggggggggggg",
      "gfffffffffffffff",
      "ffffffffffffffff",
      "ffffffffffffffff",
      "ffffffffffffffff",
      "ffffffffffffffff",
      "ffffffffffffffff",
      "dddddddddddddddf"
    ],
    [
      "                ",
      "            bbb ",
      "                ",
      "                ",
      "                ",
      "hhhhhhhhhhhhhhhh",
      "iiiiiiiiiiiiiiii",
      "jjjjjjjjjjjjjjjj",
      "jjjjjjjjjjjjjjjj",
      "jjjjjjjjjjjjjjjj",
      "jjjjjjjjjjjjjjjj",
      "jjkkkkkkjjjjjjjj",
      "jjkkkkkkjjjjjjjj",
      "jjkkkkkkjjjjjjjj",
      "jjkkkkkkjjjjjjjj",
      "jjkkkkkkjjjjjjjj"
    ],
    [
      "                ",
      "            bbb ",
      "                ",
      "                ",
      "                ",
      "llllllllllllllll",
      "iiiiiiiiiiiiiiii",
      "    mn      opq ",
      "                ",
      "                ",
      "                ",
      "                ",
      "   rrrr         ",
      "   rrrr         ",
      "   rrrr         ",
      "                "
    ],
    [
      "                ",
      "            bbb ",
      "                ",
      "                ",
      "                ",
      "                ",
      "ssssssssssssssss",
      "                ",
      "                ",
      "                ",
      "                ",
      "                ",
      "                ",
      "   tuut         ",
      "                ",
      "                "
    ]
  ]
}