{
  "name": "multi_verticalschool_11_floor7",
  "refpalette": "deceasedcraft:multi_verticalschool_11/multi_verticalschool_11_floor7_palette",
  "xsize": 16,
  "zsize": 16,
  "slices": [
    [
      "                ",
      "            aaa ",
      "                ",
      "                ",
      "                ",
      "                ",
      "                ",
      "                ",
      "                ",
      "                ",
      "                ",
      "                ",
      "                ",
      "                ",
      "                ",
      "                "
    ],
    [
      "                ",
      "            aaa ",
      "                ",
      "                ",
      "                ",
      "                ",
      "                ",
      "                ",
      "                ",
      "                ",
      "                ",
      "                ",
      "                ",
      "                ",
      "                ",
      "                "
    ],
    [
      "                ",
      "            aaa ",
      "                ",
      "                ",
      "                ",
      "                ",
      "                ",
      "                ",
      "                ",
      "                ",
      "                ",
      "bbbbbbbbbbbbbbbb",
      "                ",
      "cccccccccccccccc",
      "dddddddddddddddd",
      "cccccccccccccccc"
    ],
    [
      "                ",
      "            aaa ",
      "                ",
      "                ",
      "                ",
      "                ",
      "                ",
      "                ",
      "                ",
      "                ",
      "eeeeeeeeeeeeeeee",
      "ffffffffffffffff",
      "gggggggggggggggg",
      "hhhhhhhhhhhhhhhh",
      "hhhhhhhhhhhhhhhh",
      "iiiiiiiiiiiiiiih"
    ],
    [
      "                ",
      "            aaa ",
      "                ",
      "                ",
      "                ",
      "                ",
      "                ",
      "                ",
      "                ",
      "                ",
      "eeeeeeeeeeeeeeee",
      "ffffffffffffffff",
      "    j        j  ",
      "                ",
      "                ",
      "iiiiiiiiiiiiiii "
    ],
    [
      "                ",
      "            aaa ",
      "                ",
      "                ",
      "                ",
      "                ",
      "                ",
      "                ",
      "                ",
      "                ",
      "eeeeeeeeeeeeeeee",
      "kkfffffkkkkfffff",
      "    l        l  ",
      "                ",
      "                ",
      "iiiiiiiiiiiiiii "
    ]
  ]
}