{
  "name": "multi_verticalschool_11_floor22",
  "refpalette": "deceasedcraft:multi_verticalschool_11/multi_verticalschool_11_floor22_palette",
  "xsize": 16,
  "zsize": 16,
  "slices": [
    [
      "aaaaaaaaaaaaaaa ",
      "bbbbbbbbbbbbccca",
      "dddddddddddddbba",
      "             dba",
      "             dba",
      "             dba",
      "             dba",
      "             dba",
      "             dba",
      "             dba",
      "             dba",
      "             dba",
      "             dba",
      "             dba",
      "             dba",
      "             dba"
    ],
    [
      "aaaaaaaaaaaaaaae",
      "ffffffffffffccca",
      "gggggggggggggffa",
      "             gfa",
      "             gfa",
      "             gfa",
      "             gfa",
      "             gfa",
      "             gfa",
      "             gfa",
      "             gfa",
      "             gfa",
      "             gfa",
      "             gfa",
      "             gfa",
      "             gfa"
    ],
    [
      "hhhhhhhhhhhhhhhh",
      "hhhhhhhhhhhhccci",
      "hhhhhhhhhhhhhhhh",
      "             hhh",
      "             hhh",
      "             hhh",
      "             hhh",
      "             hhh",
      "             hhh",
      "             hhh",
      "             hhh",
      "             hhh",
      "             hhh",
      "             hhh",
      "             hhh",
      "             hhh"
    ],
    [
      "                ",
      " jklm  jklm cccn",
      "oooooooooooooo  ",
      "             o p",
      "             o p",
      "             o  ",
      "             o  ",
      "             o  ",
      "             o p",
      "             o p",
      "             o  ",
      "             o  ",
      "             o  ",
      "             o q",
      "             o q",
      "             o  "
    ],
    [
      "                ",
      "    !       cccr",
      "                ",
      "                ",
      "                ",
      "                ",
      "                ",
      "                ",
      "                ",
      "                ",
      "                ",
      "                ",
      "                ",
      "                ",
      "                ",
      "                "
    ],
    [
      "                ",
      "            cccs",
      "                ",
      "                ",
      "                ",
      "                ",
      "                ",
      "                ",
      "                ",
      "                ",
      "                ",
      "                ",
      "                ",
      "                ",
      "                ",
      "                "
    ]
  ]
}