{
  "name": "multi_verticalschool_11_floor31",
  "refpalette": "deceasedcraft:multi_verticalschool_11/multi_verticalschool_11_floor31_palette",
  "xsize": 16,
  "zsize": 16,
  "slices": [
    [
      "                ",
      "            aaa ",
      "                ",
      "                ",
      "                ",
      "                ",
      "                ",
      "             b  ",
      "             bc ",
      "             b  ",
      "                ",
      "                ",
      "                ",
      "                ",
      "                ",
      "                "
    ],
    [
      "                ",
      "            aaa ",
      "     dddd       ",
      "                ",
      "                ",
      "                ",
      "                ",
      "                ",
      "              c ",
      "                ",
      "                ",
      "                ",
      "                ",
      "                ",
      "                ",
      "          e     "
    ],
    [
      "                ",
      "     f  f   aaa ",
      "     gggg       ",
      "                ",
      "                ",
      "                ",
      "                ",
      "                ",
      "              c ",
      "                ",
      "                ",
      "                ",
      "                ",
      "                ",
      "                ",
      "                "
    ],
    [
      "                ",
      "     h  h   aaa ",
      "     i  i       ",
      "                ",
      "                ",
      "                ",
      "                ",
      "                ",
      "              c ",
      "                ",
      "                ",
      "                ",
      "                ",
      "                ",
      "                ",
      "                "
    ],
    [
      "jjjjjjjjjjjjjjjj",
      "kkkkklkklkkkaaaj",
      "mmnnnnnnnnmmmmkj",
      "ooooooooooooomkj",
      "ooooooooooooomkj",
      "ooooooooooooomkj",
      "ooooooooooooonkj",
      "ooooooooooooonkj",
      "ooooooooooooonlj",
      "ooooooooooooonkj",
      "ooooooooooooonkj",
      "ooooooooooooonkj",
      "ooooooooooooonkj",
      "ooooooooooooonkj",
      "nnnnnnmmmmnnnnkj",
      "kkkkkkkkkkkkkkkj"
    ],
    [
      "pppppppppppppppp",
      "aaaaaaaaaaaaaaap",
      "qqqqqqqqqqqqqqap",
      "qqqqqqqqqqqqqqap",
      "qqqqqqqqqqqqqqap",
      "qqqqqqqqqqqqqqap",
      "qqqqqqqqqqqqqqap",
      "qqqqqqqqqqqqqqap",
      "qqqqqqqqqqqqqqap",
      "qqqqqqqqqqqqqqap",
      "qqqqqqqqqqqqqqap",
      "qqqqqqqqqqqqqqap",
      "qqqqqqqqqqqqqqap",
      "qqqqqqqqqqqqqqap",
      "qqqqqqqqqqqqqqap",
      "qqqqqqqqqqqqqqap"
    ]
  ]
}