{
  "name": "multi_verticalschool_11_floor25",
  "refpalette": "deceasedcraft:multi_verticalschool_11/multi_verticalschool_11_floor25_palette",
  "xsize": 16,
  "zsize": 16,
  "slices": [
    [
      "aaaaaaaaaaaaaaaa",
      "bbbbbbbbbbbbccca",
      "bdddddddddddddba",
      "bdddddddddddddba",
      "bdddddddddddddba",
      "bdddddddddddddba",
      "bdddddddddddddba",
      "bdddddddddddddba",
      "bdddddddddddddba",
      "bdddddddddddddba",
      "bdddddddddddddba",
      "bdddddddddddddba",
      "bdddddddddddddba",
      "bdddddddddddddba",
      "bdddddddddddddba",
      "bdddddddddddddba"
    ],
    [
      "eeeeeeeeeeeeeeee",
      "bbbbbbbbbbbbcccf",
      "bgghiiiiiiijggbf",
      "k             bf",
      "l     mmm     bf",
      "b     nnn   oobf",
      "b    mnpnm  oobf",
      "b    mnpn m   bf",
      "boo  mnpnm    bf",
      "boo m n!nm    bf",
      "b    mnpnm    bf",
      "b    mnpn   oobf",
      "b     nnnm  oobf",
      "q     mmm     bf",
      "r             bf",
      "bst         stbf"
    ],
    [
      "                ",
      "uuuuuuuuuuuuccc ",
      "uggwxy ABC!Dggu ",
      "E             u ",
      "F             I ",
      "u             I ",
      "u     J K     I ",
      "I             I ",
      "I     L M     u ",
      "I     N       u ",
      "I       O     I ",
      "u     P       I ",
      "u             I ",
      "Q             I ",
      "R             u ",
      "u     SSS   TUu "
    ],
    [
      "                ",
      "uuuuuuuuuuuuccc ",
      "uggV        ggu ",
      "I             u ",
      "I             I ",
      "u             I ",
      "u             I ",
      "I             I ",
      "I             u ",
      "I             u ",
      "I             I ",
      "u             I ",
      "u             I ",
      "I             I ",
      "I             u ",
      "uW    SSS     u "
    ],
    [
      "                ",
      "uuuuuuuuuuuuccc ",
      "uXY         Z u ",
      "u             u ",
      "u             u ",
      "u             u ",
      "u             u ",
      "u             u ",
      "u             u ",
      "u             u ",
      "u      0      u ",
      "u             u ",
      "u             u ",
      "u             u ",
      "u             u ",
      "u1            u "
    ],
    [
      "2222222222222222",
      "uuuuuuuuuuuuccc2",
      "u3333333333333u2",
      "u3333333333333u2",
      "u3345533355533u2",
      "u3333333333333u2",
      "u3333333333333u2",
      "u3355533355533u2",
      "u3333333333333u2",
      "u3333333333333u2",
      "u3355533355533u2",
      "u3333333333333u2",
      "u3333333333333u2",
      "u3355533355533u2",
      "u3333333333333u2",
      "u3333333333333u2"
    ]
  ]
}