{
  "name": "multi_verticalschool_11_floor18",
  "refpalette": "deceasedcraft:multi_verticalschool_11/multi_verticalschool_11_floor18_palette",
  "xsize": 16,
  "zsize": 16,
  "slices": [
    [
      "                ",
      "    aaaaaaaabbb ",
      "    accccccccca ",
      "    d         d ",
      "    d         d ",
      "    a         a ",
      "    d         d ",
      "    d         d ",
      "    d         d ",
      "    d         d ",
      "    d         d ",
      "    d         d ",
      "    a         a ",
      "    d         d ",
      "    d         d ",
      "    ae        a "
    ],
    [
      "                ",
      "    aaaaaaaabbb ",
      "    a         a ",
      "    a         a ",
      "    a         a ",
      "    a         a ",
      "    a         a ",
      "    a         a ",
      "    a         a ",
      "    a         a ",
      "    a         a ",
      "    a         a ",
      "    a         a ",
      "    a         a ",
      "    a         a ",
      "    af        a "
    ],
    [
      "gggggggggggggggg",
      "    aaaaaaaabbbg",
      "    ahhhhhhhhhag",
      "    ahhhhhhhhhag",
      "    ahihhjhhjhag",
      "    ahhhhhhhhhag",
      "    ahhhhhhhhhag",
      "    ahjhhjhhjhag",
      "    ahhhhhhhhhag",
      "    ahhhhhhhhhag",
      "    ahjhhihhjhag",
      "    ahhhhhhhhhag",
      "    ahhhhhhhhhag",
      "    ahihhjhhjhag",
      "    ahhhhhhhhhag",
      "    ahhhhhhhhhag"
    ],
    [
      "kkkkkkkkkkkkkkkk",
      "llllmmmmmmmmbbbk",
      "nnnlmooooooooomk",
      "  nlmooooooooomk",
      "  nlmooooooooomk",
      "  nlmooooooooomk",
      "  nlmooooooooomk",
      "  nlmooooooooomk",
      "  nlmooooooooomk",
      "  nlmooooooooomk",
      "  nlmooooooooomk",
      "  nlmooooooooomk",
      "  nlmooooooooomk",
      "  nlmooooooooomk",
      "  nlmooooooooomk",
      "  nlmooooooooomk"
    ],
    [
      "    p           ",
      "    mmmmmmmmbbb ",
      "qq  mrrrrrrrrsm ",
      "  t u         m ",
      "  t w         m ",
      "  t mx xx xx xm ",
      "  t my AB AB ym ",
      "  t m         m ",
      "  t mx xx xx xm ",
      "  t my AB AB ym ",
      "  t m         m ",
      "  t mx xx xx xm ",
      "  t my AB AB ym ",
      "  t C         m ",
      "  t wD   E    m ",
      "  t mFIJJJJJKLm "
    ],
    [
      "                ",
      "    aaaaaaaabbb ",
      "    arsMrsrs!ra ",
      "    N         d ",
      "    O         d ",
      "    a         a ",
      "    dP P  QR  d ",
      "    d         d ",
      "    d         d ",
      "    dQ PQ  P Qd ",
      "    d         d ",
      "    d         d ",
      "    aP  S Q  Pa ",
      "    T         d ",
      "    O         d ",
      "    aU   V   !a "
    ]
  ]
}