{
  "name": "multi_verticalschool_11_floor3",
  "refpalette": "deceasedcraft:multi_verticalschool_11/multi_verticalschool_11_floor3_palette",
  "xsize": 16,
  "zsize": 16,
  "slices": [
    [
      "                ",
      "            aaa ",
      "                ",
      "                ",
      "                ",
      "                ",
      "                ",
      "                ",
      "                ",
      "                ",
      "                ",
      "                ",
      "                ",
      "                ",
      "                ",
      "   bbbbb   bbbbb"
    ],
    [
      "                ",
      "            aaa ",
      "                ",
      "                ",
      "                ",
      "                ",
      "                ",
      "                ",
      "                ",
      "                ",
      "                ",
      "                ",
      "                ",
      "                ",
      "                ",
      "                "
    ],
    [
      "                ",
      "            aaa ",
      "                ",
      "                ",
      "                ",
      "                ",
      "                ",
      "                ",
      "                ",
      "                ",
      "                ",
      "                ",
      "                ",
      "                ",
      "                ",
      "                "
    ],
    [
      "                ",
      "            aaa ",
      "                ",
      "                ",
      "                ",
      "                ",
      "                ",
      "                ",
      "                ",
      "                ",
      "                ",
      "                ",
      "                ",
      "                ",
      "                ",
      "                "
    ],
    [
      "cccccccccccccccc",
      "cccdcccdcccdaaad",
      "cccccccccccccccc",
      "cccccccccccccccc",
      "cccccccccccccccc",
      "cccccccccccccccc",
      "cccdcccdcccdcccd",
      "cccccccccccccccc",
      "cccccccccccccccc",
      "cccccccccccccccc",
      "cccccccccccccccc",
      "cccdcccdcccdcccd",
      "cccccccccccccccc",
      "cccccccccccccccc",
      "cccccccccccccccc",
      "cccccccccccccccc"
    ],
    [
      "ccccccceeeeeeeee",
      "fffffffceeegaaae",
      "fffffccegegegeee",
      "ffcccegeggggeeee",
      "cceeegggggggeeee",
      "eeggggegggggeheg",
      "gegggggggggeeeee",
      "ggggggggggegeeee",
      "ggggggggggggeege",
      "gggeeggggggegege",
      "eegeeeggggggeeeg",
      "eeeeegggggggeeee",
      "eeeeeegggggeehee",
      "eeeggeggggggeeee",
      "eeeegeegggggeeee",
      "eeeeeeggggggeeee"
    ]
  ]
}