{
  "name": "multi_verticalschool_11_floor30",
  "refpalette": "deceasedcraft:multi_verticalschool_11/multi_verticalschool_11_floor30_palette",
  "xsize": 16,
  "zsize": 16,
  "slices": [
    [
      "aaaaaaaaaaaaaaaa",
      "bbbbbbbbbbbbccca",
      "ddddddddddddddba",
      "deeeeeeeeeeeedba",
      "deeeeeedddddddba",
      "feeeeedeeeeeedba",
      "ghieedeeeeeeedba",
      "hhgfededddddddba",
      "hhhgjddedeeeedba",
      "gf!hhiedddddddba",
      "jejfgfjeeeeeedba",
      "deeeeiiieeeeedba",
      "deeeeeedddddddba",
      "deeeeeeeeeeeedba",
      "ddddddddddddddba",
      "bbbbbbbbbbbbbbba"
    ],
    [
      "                ",
      "            ccc ",
      "                ",
      "                ",
      "               k",
      "   l            ",
      " m              ",
      "   m            ",
      "n   o           ",
      " m   mp         ",
      "         l      ",
      "  pq r          ",
      "       r s   r  ",
      "                ",
      "                ",
      "                "
    ],
    [
      "             t  ",
      "            ccc ",
      "                ",
      "                ",
      "                ",
      "                ",
      "                ",
      "                ",
      "                ",
      "                ",
      "                ",
      "                ",
      "                ",
      "                ",
      "                ",
      "                "
    ],
    [
      "                ",
      "            ccc ",
      "                ",
      "                ",
      "                ",
      "                ",
      "                ",
      "                ",
      "                ",
      "                ",
      "                ",
      "                ",
      "                ",
      "                ",
      "                ",
      "                "
    ],
    [
      "                ",
      "            ccc ",
      "                ",
      "                ",
      "                ",
      "                ",
      "                ",
      "                ",
      "             uw ",
      "                ",
      "                ",
      "                ",
      "                ",
      "                ",
      "                ",
      "                "
    ],
    [
      "                ",
      "            ccc ",
      "                ",
      "                ",
      "                ",
      "                ",
      "                ",
      "             x  ",
      "             yA ",
      "             x  ",
      "                ",
      "                ",
      "                ",
      "                ",
      "                ",
      "                "
    ]
  ]
}