{
  "name": "multi_verticalschool_11_floor1",
  "refpalette": "deceasedcraft:multi_verticalschool_11/multi_verticalschool_11_floor1_palette",
  "xsize": 16,
  "zsize": 16,
  "slices": [
    [
      "                ",
      "            aaa ",
      "                ",
      "                ",
      "                ",
      "                ",
      "                ",
      "                ",
      "                ",
      "                ",
      "bbbbbbbbbbbbbbcd",
      "eeeeeeeeeeeeeeee",
      "                ",
      "                ",
      "                ",
      "                "
    ],
    [
      "ffffffffffffffcg",
      "ffffffffffffaaah",
      "ffffffffffffffcg",
      "ffffffffffffffcg",
      "ffffffffffffffcg",
      "ifffffifffffifcg",
      "ifffffifffffifcg",
      "ffffffffffffffcg",
      "ffffffffffffffcg",
      "ffffffffffffffcg",
      "bbbbbbbbbbbbbbcc",
      "eeeeeeeeeeeeeeee",
      "                ",
      "                ",
      "                ",
      "                "
    ],
    [
      "jjjjjjjjjjjjjbkk",
      "jjjjjjjjjjjjaaak",
      "jjjjjjjjjjjjjbkk",
      "jjjjjjjjjjjjjbkk",
      "jjjjjjjjjjjjjblk",
      "jjjjjjjjjjjjjbkl",
      "jjjjjjjjjjjjjbll",
      "jjjjjjjjjjjjjbll",
      "jjjjjjjjjjjjjblk",
      "jjjjjjjjjjjjjbmm",
      "bbbbbbbbbbbbbbbb",
      "eeeeeeeeeeeeeeee",
      "                ",
      "                ",
      "                ",
      "                "
    ],
    [
      "                ",
      "            aaa ",
      "                ",
      "                ",
      "                ",
      "                ",
      "                ",
      "                ",
      "                ",
      "     nop  nop qq",
      "rrrrrrrrrrrrrrrr",
      "ssssssssssssssss",
      "                ",
      "                ",
      "                ",
      "                "
    ],
    [
      "                ",
      "            aaa ",
      "                ",
      "                ",
      "                ",
      "                ",
      "                ",
      "                ",
      "                ",
      "              tt",
      "                ",
      "                ",
      "                ",
      "                ",
      "                ",
      "                "
    ],
    [
      "                ",
      "            aaa ",
      "                ",
      "                ",
      "                ",
      "                ",
      "                ",
      "                ",
      "                ",
      "                ",
      "                ",
      "                ",
      "                ",
      "                ",
      "                ",
      "                "
    ]
  ]
}