{
  "name": "multi_verticalschool_11_floor20",
  "refpalette": "deceasedcraft:multi_verticalschool_11/multi_verticalschool_11_floor20_palette",
  "xsize": 16,
  "zsize": 16,
  "slices": [
    [
      "                ",
      "    aaaaaaaabbb ",
      "    accccccccca ",
      "    d         d ",
      "    d         d ",
      "    a         a ",
      "    d         d ",
      "    d         d ",
      "    d         d ",
      "    d         d ",
      "    d         d ",
      "    d         d ",
      "    a         a ",
      "    d         d ",
      "    d         d ",
      "    ae        a "
    ],
    [
      "                ",
      "    aaaaaaaabbb ",
      "    a         a ",
      "    a         a ",
      "    a         a ",
      "    a         a ",
      "    a         a ",
      "    a         a ",
      "    a         a ",
      "    a         a ",
      "    a         a ",
      "    a         a ",
      "    a         a ",
      "    a         a ",
      "    a         a ",
      "    af        a "
    ],
    [
      "gggggggggggggggg",
      "    aaaaaaaabbbg",
      "    ahhhhhhhhhag",
      "    ahhhhhhhhhag",
      "    ahihhihhihag",
      "    ahhhhhhhhhag",
      "    ahhhhhhhhhag",
      "    ahihhihhihag",
      "    ahhhhhhhhhag",
      "    ahhhhhhhhhag",
      "    ahihhihhihag",
      "    ahhhhhhhhhag",
      "    ahhhhhhhhhag",
      "    ahihhjhhihag",
      "    ahhhhhhhhhag",
      "    ahhhhhhhhhag"
    ],
    [
      "kkkkkkkkkkkkkkkk",
      "llllmmmmmmmmbbbk",
      "nnnlmooooooooomk",
      "  nlmooooooooomk",
      "  nlmooooooooomk",
      "  nlmooooooooomk",
      "  nlmooooooooomk",
      "  nlmooooooooomk",
      "  nlmooooooooomk",
      "  nlmooooooooomk",
      "  nlmooooooooomk",
      "  nlmooooooooomk",
      "  nlmooooooooomk",
      "  nlmooooooooomk",
      "  nlmooooooooomk",
      "  nlmooooooooomk"
    ],
    [
      "    p           ",
      "    mmmmmmmmbbb ",
      "qq  mrrrsrsrsrm ",
      "  t u         m ",
      "  t w         m ",
      "  t mx xx xx xm ",
      "  t my AB AB ym ",
      "  t m         m ",
      "  t mx xx xx xm ",
      "  t my AB AB ym ",
      "  t m         m ",
      "  t mx xx xx xm ",
      "  t my AB AB ym ",
      "  t C         m ",
      "  t w    D    m ",
      "  t mEFIJJJJKKm "
    ],
    [
      "                ",
      "    aaaaaaaabbb ",
      "    arsrrLrrrsa ",
      "    M         d ",
      "    N         d ",
      "    a         a ",
      "    dO P  QR Rd ",
      "    d         d ",
      "    d         d ",
      "    dQ SO RO Td ",
      "    d         d ",
      "    d         d ",
      "    aO R  OU  a ",
      "    V         d ",
      "    N         d ",
      "    a W  X    a "
    ]
  ]
}