{
  "name": "multi_verticalschool_11_floor27",
  "refpalette": "deceasedcraft:multi_verticalschool_11/multi_verticalschool_11_floor27_palette",
  "xsize": 16,
  "zsize": 16,
  "slices": [
    [
      "aaaaaaaaaaaaaaaa",
      "bbbbbbbbbbbbccca",
      "bddeeeddbdddddba",
      "bddeeeddbdddddba",
      "bddeeeddbdddddba",
      "bddeeeddbdddddba",
      "bddeeeddbdddddba",
      "bddeeeddbdddddba",
      "bddeeeddbdddddba",
      "bddeeeddbdddddba",
      "bddeeeddbdddddba",
      "bdddddddbdddddba",
      "bdddddddbdddddba",
      "bdddddddbdddddba",
      "bdddddddbdddddba",
      "bdddddddbdddddba"
    ],
    [
      "ffffffffffffffff",
      "bbbbbbbbbbbbcccg",
      "b  hij  bkkklmbg",
      "b nhojn bpq rsbg",
      "b  htj  bq u !bg",
      "b  hwj  bx    bg",
      "b nhojn by    bg",
      "b  hoj  bA    bg",
      "b  hij  B    Cbg",
      "b nhtjn D    Cbg",
      "b  hwj  bx    bg",
      "b  EEE  by    bg",
      "b       bA    bg",
      "F       b IJKKbg",
      "L       bMJNJKbg",
      "b       bOkkkkbg"
    ],
    [
      "                ",
      "PPPPPPPPPPPPccc ",
      "P  QQQ  PkkkRSP ",
      "T U   U P   VWP ",
      "T       P     T ",
      "P       PX    T ",
      "P U   U PY    T ",
      "P      ZP     T ",
      "T       0     P ",
      "T U   U 1     P ",
      "P      ZP     T ",
      "P       PY    T ",
      "P       PX    T ",
      "2       P IJ3 T ",
      "4       P JNJ P ",
      "P       P5kkkkP "
    ],
    [
      "                ",
      "PPPPPPPPPPPPccc ",
      "P  666  Pkkk78P ",
      "T       P     P ",
      "T       P9    T ",
      "P       P     T ",
      "P       P     T ",
      "P       P     T ",
      "T       #    $P ",
      "T       #    $P ",
      "P       P     T ",
      "P       P     T ",
      "P       P     T ",
      "T       P%IJ3 T ",
      "T       P^JNJ P ",
      "P       P5kkkkP "
    ],
    [
      "                ",
      "PPPPPPPPPPPPccc ",
      "P       Pkkk &P ",
      "P       P    KP ",
      "P       P    KP ",
      "P       P    KP ",
      "P       P    KP ",
      "P       P    KP ",
      "P       P    &P ",
      "P       P    &P ",
      "P       P    KP ",
      "P       P    KP ",
      "P       P    KP ",
      "P       PKKJKKP ",
      "P       P*JNJKP ",
      "P       P(kkkkP "
    ],
    [
      "))))))))))))))))",
      "PPPPPPPPPPPPccc)",
      "P+++++++P+++++P)",
      "P+++++++P+++++P)",
      "P++---++P+++++P)",
      "P+++++++P+++++P)",
      "P+++++++P+++++P)",
      "P++---++P+++++P)",
      "P+++++++P+++++P)",
      "P+++++++P+++++P)",
      "P++[[[++P+++++P)",
      "P+++++++P+++++P)",
      "P+++++++P+++++P)",
      "P++[[[++P++k++P)",
      "P+++++++P+k]k+P)",
      "P+++++++P++k++P)"
    ]
  ]
}