{
  "name": "multi_verticalschool_11_base2",
  "refpalette": "deceasedcraft:multi_verticalschool_11/multi_verticalschool_11_base2_palette",
  "xsize": 16,
  "zsize": 16,
  "slices": [
    [
      "vvvvvvvvvvvvvvvv",
      "vvvvvvvvvvvvvvvv",
      "vvvvvvvvvvvvvvvv",
      "vvvvvvvvvvvvvvvv",
      "vvvvvvvvvvvvvvvv",
      "vvvvvvvvvvvvvvvv",
      "vvvvvvvvvvvvvvvv",
      "vvvvvvvvvvvvvvvv",
      "vvvvvvvvvvvvvvvv",
      "vvvvvvvvvvvvvvvv",
      "vvvvvvvvvvvvvvvv",
      "vvvvvvvvvvvvvvvv",
      "vvvvvvvvvvvvvvvv",
      "vvvvvvvvvvvvvvvv",
      "vvvvvvvvvvvvvvvv",
      "vvvvvvvvvvvvvvvv"
    ],
    [
      "aaaaaaaaaaaaaaaa",
      "aaaaaaaaaaaabbba",
      "aaaaaaaaaaaaaaaa",
      "aaaaaaaaaaaaaaaa",
      "aaaaaaaaaaaaaaaa",
      "aaaaaaaaaaaaaaaa",
      "aaaaaaaaaaaaaaaa",
      "aaaaaaaaaaaaaaaa",
      "aaaaaaaaaaaaaaaa",
      "aaaaaaaaaaaaaaaa",
      "aaaaaaaaaaaaaaaa",
      "aaaaaaaaaaaaaaaa",
      "aaaaaaaaaaaaaaaa",
      "aaaaaaaaaaaaaaaa",
      "aaaaaaaaaaaaaaaa",
      "aaaaaaaaaaaaaaaa"
    ],
    [
      "aaaaaaaaaaaaaaaa",
      "aaaaaaaaaaaabbba",
      "aaaaaaaaaaaaaaaa",
      "aaaaaaaaaaaaaaaa",
      "aaaaaaaaaaaaaaaa",
      "aaaaaaaaaaaaaaaa",
      "aaaaaaaaaaaaaaaa",
      "aaaaaaaaaaaaaaaa",
      "aaaaaaaaaaaaaaaa",
      "aaaaaaaaaaaaaaaa",
      "aaaaaaaaaaaaaaaa",
      "aaaaaaaaaaaaaaaa",
      "aaaaaaaaaaaaaaaa",
      "aaaaaaaaaaaaaaaa",
      "aaaaaaaaaaaaaaaa",
      "aaaaaaaaaaaaaaaa"
    ],
    [
      "bcHHHHHHHHHHHHHH",
      "bcHHHHHHHHHHbbbH",
      "bcHHHHHHHHHHHHHH",
      "bcHHHHHHHHHHHHHH",
      "bcHHHHHHHHHHHHHH",
      "bcHHHHHHHHHHHHHH",
      "bcHHHHHHHHHHHHHH",
      "bcHHHHHHHHHHHHHH",
      "bcHHHHHHHHHHHHHH",
      "bcHHHHHHHHHHHHHH",
      "bcHHHHHHHHHHHHHH",
      "bcHHHHHHHHHHHHHH",
      "bcHHHHHHHHHHHHHH",
      "bcHHHHHHHHHHHHHH",
      "bcHHHHHHHHHHHHHH",
      "bcHHHHHHHHHHHHHH"
    ],
    [
      "b        d  efd ",
      "b        ggghhhg",
      "b        i  jfi ",
      "b        dk efd ",
      "b        i  jfi ",
      "b        d  efd ",
      "b        i  jfi ",
      "b        d  efd ",
      "b        i  jfi ",
      "b        d  efd ",
      "b        i  jfi ",
      "b        d  efd ",
      "b        i  jfi ",
      "b        d  efd ",
      "b        i ljfi ",
      "b        d  efd "
    ],
    [
      "b               ",
      "b           hhh ",
      "b               ",
      "b               ",
      "b               ",
      "b               ",
      "b               ",
      "b               ",
      "b               ",
      "b               ",
      "b               ",
      "b               ",
      "b               ",
      "b               ",
      "b               ",
      "b               "
    ]
  ]
}