{
  "name": "multi_verticalschool_11_floor8",
  "refpalette": "deceasedcraft:multi_verticalschool_11/multi_verticalschool_11_floor8_palette",
  "xsize": 16,
  "zsize": 16,
  "slices": [
    [
      "                ",
      "            aaa ",
      "                ",
      "                ",
      "                ",
      "                ",
      "                ",
      "                ",
      "                ",
      "                ",
      "bbbbbbbbbbbbbbbb",
      "cccccccccccccccc",
      "    d        d  ",
      "                ",
      "                ",
      "eeeeeeeeeeeeeee "
    ],
    [
      "                ",
      "            aaa ",
      "                ",
      "                ",
      "                ",
      "                ",
      "                ",
      "                ",
      "                ",
      "                ",
      "bbbbbbbbbbbbbbbb",
      "cccccccccccccccc",
      "ffffffffffffffff",
      "gggggggggggggggg",
      "gggggggggggggggg",
      "eeeeeeeeeeeeeeeg"
    ],
    [
      "                ",
      "            aaa ",
      "                ",
      "                ",
      "                ",
      "                ",
      "                ",
      "                ",
      "                ",
      "                ",
      "bbbbbbbbbbbbbbbb",
      "cccccccccccccccc",
      "cccccccccccccccc",
      "hhhhhhhhhhhhhhhh",
      "iiiiiiiiiiiiiiii",
      "eeeeeeeeeeeeeeei"
    ],
    [
      "                ",
      "            aaa ",
      "                ",
      "                ",
      "                ",
      "                ",
      "                ",
      "                ",
      "                ",
      "                ",
      "                ",
      "                ",
      "                ",
      "jjjjkjjjjjjjjjkj",
      "                ",
      "eeeeeeeeeeeeeee "
    ],
    [
      "                ",
      "            aaa ",
      "                ",
      "                ",
      "                ",
      "                ",
      "                ",
      "                ",
      "                ",
      "                ",
      "                ",
      "                ",
      "                ",
      "                ",
      "                ",
      "eeeeeeeeeeeeeee "
    ],
    [
      "llmmmmmmmmmmmmml",
      "mmmmmmmmmmmmaaam",
      "mmmmmmmmmmmmmmmm",
      "mmmmmmmmmmmmmmmm",
      "mmmmmmmmmmmmmmmm",
      "mmmmmmmmmmmmmmmm",
      "mmmmmmmmmmmmmmmm",
      "mmmmmmmmmmmmmmmm",
      "mmmmmmmmmmmmmmmm",
      "mmmmmmmmmmmmmmmm",
      "mmmmmmmmmmmmmmmm",
      "mmmmmmmmmmmmmmmm",
      "mmmmmmmmmmmmmmmm",
      "mmmmmmmmmmmmmmmm",
      "mmmmmmmmmmmmmmmm",
      "eeeeeeeeeeeeeeem"
    ]
  ]
}