{
  "name": "multi_verticalschool_11_floor21",
  "refpalette": "deceasedcraft:multi_verticalschool_11/multi_verticalschool_11_floor21_palette",
  "xsize": 16,
  "zsize": 16,
  "slices": [
    [
      "                ",
      "    aaaaaaaabbb ",
      "    ac cccc!cca ",
      "    d         d ",
      "    d         d ",
      "    a         a ",
      "    d         d ",
      "    d         d ",
      "    d         d ",
      "    d         d ",
      "    d         d ",
      "    d         d ",
      "    a         a ",
      "    d         d ",
      "    d         d ",
      "    ae        a "
    ],
    [
      "                ",
      "    aaaaaaaabbb ",
      "    a         a ",
      "    a         a ",
      "    a         a ",
      "    a         a ",
      "    a         a ",
      "    a         a ",
      "    a         a ",
      "    a         a ",
      "    a         a ",
      "    a         a ",
      "    a         a ",
      "    a         a ",
      "    a         a ",
      "    af        a "
    ],
    [
      "gggggggggggggggg",
      "hhhhaaaaaaaabbbg",
      "iiiiajjjjjjjjjag",
      "iiiiajjjjjjjjjag",
      "iiiiajkjjkjjkjag",
      "iiiiajjjjjjjjjag",
      "iiiiajjjjjjjjjag",
      "iiiiajljjkjjkjag",
      "iiiiajjjjjjjjjag",
      "iiiiajjjjjjjjjag",
      "iiiiajljjkjjkjag",
      "iiiiajjjjjjjjjag",
      "iiiiajjjjjjjjjag",
      "iiiiajljjkjjljag",
      "iiiiajjjjjjjjjag",
      "iiiiajjjjjjjjjag"
    ],
    [
      "mmmmmmmmmmmmmmmm",
      "mmmmmmmmmmmmbbbm",
      "nnnnnnnnnnnnnnmm",
      "nnnnnnnnnnnnnnmm",
      "nnnnnnnnnnnnnnmm",
      "nnnnnnnnnnnnnnmm",
      "nnnnnnnnnnnnnnmm",
      "nnnnnnnnnnnnnnmm",
      "nnnnnnnnnnnnnnmm",
      "nnnnnnnnnnnnnnmm",
      "nnnnnnnnnnnnnnmm",
      "nnnnnnnnnnnnnnmm",
      "nnnnnnnnnnnnnnmm",
      "nnnnnnnnnnnnnnmm",
      "nnnnnnnnnnnnnnmm",
      "nnnnnnnnnnnnnnmm"
    ],
    [
      "ooooooooooooooop",
      "qqqqqqqqqqqqbbbo",
      "rrrrrrrrrrrrrqqo",
      "             rqo",
      "     s s s   rqo",
      "    tuuuuuw  rqo",
      "    xxxxxxx  rqo",
      "    yAAAAAB  rqo",
      "     C C C   rqo",
      "             rqo",
      "     s s s   rqo",
      "    tuuuuuw  rqo",
      "    xxxxxxx  rqo",
      "    yAAAAAB  rqo",
      "    C C C C  rqo",
      "             rqo"
    ],
    [
      "ooooooooooooooo ",
      "qqqqqqqqqqqqbbbo",
      "rrrrrrrrrrrrrqqo",
      "             rqo",
      "             rqo",
      "    DEFEIE   rqo",
      "    JJJJJJJ  rqo",
      "     KFKIK   rqo",
      "             rqo",
      "             rqo",
      "             rqo",
      "    LEFEIE   rqo",
      "    JJJJJJJ  rqo",
      "    M NO  P  rqo",
      "             rqo",
      "             rqo"
    ]
  ]
}