{
  "name": "multi_verticalschool_11_floor28",
  "refpalette": "deceasedcraft:multi_verticalschool_11/multi_verticalschool_11_floor28_palette",
  "xsize": 16,
  "zsize": 16,
  "slices": [
    [
      "aaaaaaaaaaaaaaaa",
      "bbbbbbbbbbbbccca",
      "bdddddddddddddba",
      "bdddddddddddddba",
      "bdddddddddddddba",
      "bdddddddddddddba",
      "bdddddddddddddba",
      "bdddddddddddddba",
      "bdddddddddddddba",
      "bdddddddddddddba",
      "bdddddddddddddba",
      "bdddddddddddddba",
      "bdddddddddddddba",
      "bdddddddddddddba",
      "bdddddddddddddba",
      "bdddddddddddddba"
    ],
    [
      "eeeeeeeeeeeeeeee",
      "bbbbbbbbbbbbcccf",
      "bghi!jkl mnmombf",
      "p qqqqq       bf",
      "r             bf",
      "b             bf",
      "b stuwx stuwx bf",
      "b yAAAB yAAAB bf",
      "b             bf",
      "b             bf",
      "b stuwx stuwx bf",
      "b yAAAB yAAAB bf",
      "b             bf",
      "p      C      bf",
      "r   yADEDAB   bf",
      "bFI         JJbf"
    ],
    [
      "                ",
      "KKKKKKKKKKKKccc ",
      "KLMNNNOPMNNNNOK ",
      "Q RRRRR       K ",
      "S             T ",
      "K             T ",
      "K  U     V W  T ",
      "T    W     X  T ",
      "T             K ",
      "T             K ",
      "T  V Y        T ",
      "K   U    ZU0  T ",
      "K             T ",
      "Q             T ",
      "S    1ZW23    K ",
      "K45    6    77K "
    ],
    [
      "                ",
      "KKKKKKKKKKKKccc ",
      "K8999#9$%%%%%%K ",
      "T ^^^^^       K ",
      "T             T ",
      "K             T ",
      "K             T ",
      "T             T ",
      "T             K ",
      "T             K ",
      "T             T ",
      "K             T ",
      "K             T ",
      "T             T ",
      "T             K ",
      "K&          *(K "
    ],
    [
      "                ",
      "KKKKKKKKKKKKccc ",
      "K        ) +X-K ",
      "K             K ",
      "K             K ",
      "K             K ",
      "K             K ",
      "K             K ",
      "K             K ",
      "K             K ",
      "K             K ",
      "K             K ",
      "K             K ",
      "K             K ",
      "K             K ",
      "K[            K "
    ],
    [
      "]]]]]]]]]]]]]]]]",
      "KKKKKKKKKKKKccc]",
      "K{{{{{{{{{{{{{K]",
      "K{{{{{{{{{{{{{K]",
      "K{{}}}{{{}}}{{K]",
      "K{{{{{{{{{{{{{K]",
      "K{{{{{{{{{{{{{K]",
      "K{{}}}{{{}}}{{K]",
      "K{{{{{{{{{{{{{K]",
      "K{{{{{{{{{{{{{K]",
      "K{{}}}{{{||}{{K]",
      "K{{{{{{{{{{{{{K]",
      "K{{{{{{{{{{{{{K]",
      "K{{}}|{{{}}}{{K]",
      "K{{{{{{{{{{{{{K]",
      "K{{{{{{{{{{{{{K]"
    ]
  ]
}