{
  "name": "multi_verticalschool_11_floor11",
  "refpalette": "deceasedcraft:multi_verticalschool_11/multi_verticalschool_11_floor11_palette",
  "xsize": 16,
  "zsize": 16,
  "slices": [
    [
      "                ",
      "            aaa ",
      "                ",
      "                ",
      "                ",
      "                ",
      "bbbbbbbbbbbbbbbb",
      "                ",
      "                ",
      "                ",
      "                ",
      "                ",
      "                ",
      "    cd          ",
      "                ",
      "             e  "
    ],
    [
      "                ",
      "            aaa ",
      "                ",
      "                ",
      "                ",
      "                ",
      "bbbbbbbbbbbbbbbb",
      "                ",
      "                ",
      "                ",
      "                ",
      "                ",
      "                ",
      "                ",
      "                ",
      "             f  "
    ],
    [
      "                ",
      "            aaa ",
      "                ",
      "                ",
      "                ",
      "                ",
      "bbbbbbbbbbbbbbbb",
      "                ",
      "                ",
      "                ",
      "                ",
      "                ",
      "                ",
      "                ",
      "                ",
      "             g  "
    ],
    [
      "                ",
      "            aaa ",
      "                ",
      "                ",
      "                ",
      "hhhhhhhhhhhhhhhh",
      "bbbbbbbbbbbbbbbb",
      "                ",
      "                ",
      "                ",
      "                ",
      "                ",
      "                ",
      "                ",
      "                ",
      "                "
    ],
    [
      "                ",
      "            aaa ",
      "                ",
      "                ",
      "                ",
      "iiiiiiiiiiiiiiii",
      "jjjjjjjjjjjjjjjj",
      "kkkkkkkkkkkkkkkk",
      "llllllllllllllll",
      "llllllllllllllll",
      "llllllllllllllll",
      "llllllllllllllll",
      "lllmmmmlllllllll",
      "lllmllmlllllllll",
      "lllmmmmlllllllll",
      "llllllllllllllll"
    ],
    [
      "                ",
      "            aaa ",
      "                ",
      "                ",
      "                ",
      "nnnnnnnnnnnnnnnn",
      "jjjjjjjjjjjjjjjj",
      "jooooooooooooooo",
      "oopppppppppppppp",
      "ppppppppppqqqqqq",
      "pppppppqqqqqqqqq",
      "ppppppqqqqqqqqqq",
      "ppppqqqqqqqqqqqq",
      "pppqqqqqqqpppppp",
      "pppqqqqqpppppppp",
      "ppqqqqqppppppppp"
    ]
  ]
}