{
  "name": "multi_verticalschool_11_floor15",
  "refpalette": "deceasedcraft:multi_verticalschool_11/multi_verticalschool_11_floor15_palette",
  "xsize": 16,
  "zsize": 16,
  "slices": [
    [
      "aaaaaaaaaaaaaaa ",
      "aaaaaaaaaaaabbba",
      "            acda",
      "            ae a",
      "            ac a",
      "            ac a",
      "            ac a",
      "            ac a",
      "            ac a",
      "            ac a",
      "            ac a",
      "            ac a",
      "            ac a",
      "            ac a",
      "            ae a",
      "            ac a"
    ],
    [
      "aaaaaaaaaaaaaaa ",
      "aaaaaaaaaaaabbba",
      "            adda",
      "            ad a",
      "            a  a",
      "            ad a",
      "            afga",
      "            ad a",
      "            a  a",
      "            a  a",
      "            a  a",
      "            afga",
      "            ad a",
      "            a  a",
      "            ad a",
      "            adda"
    ],
    [
      "aaaaaaaaaaaaaaah",
      "aaaaaaaaaaaabbba",
      "iiiiiiiiiiiiajja",
      "kkkkkkkkkkkiajja",
      "kkkkkkkkkkkiajja",
      "kkkkkkkkkkkiajja",
      "kkkkkkkkkkkiajja",
      "kkkkkkkkkkkiajja",
      "kkkkkkkkkkkiajja",
      "kkkkkkkkkkkiajja",
      "kkkkkkkkkkkiajja",
      "kkkkkkkkkkkiajja",
      "kkkkkkkkkkkiajja",
      "kkkkkkkkkkkiajja",
      "kkkkkkkkkkkiajja",
      "kkkkkkkkkkkiajja"
    ],
    [
      "lllllllllllllmll",
      "nnnnnnnnnnnnbbbo",
      "nnnnnnnnnnnnnnno",
      "nnnnnnnnnnnnnnno",
      "pnnnnnnnnnnnnnno",
      "pnnnnnnnnnnnnnno",
      "pnnnnnnnnnnnnnno",
      "pnnnnnnnnnnnnnnm",
      "pnnnnnnnnnnnnnnl",
      "pnnnnnnnnnnnnnnl",
      "pnnnnnnnnnnnnnnm",
      "pnnnnnnnnnnnnnno",
      "pnnnnnnnnnnnnnno",
      "pnnnnnnnnnnnnnno",
      "pnnnnnnnnnnnnnno",
      "pnnnnnnnnnnnnnno"
    ],
    [
      "                ",
      "            bbb ",
      "        q   rrrs",
      "t      urw  xxxs",
      "my      A      s",
      "my          xxxs",
      "myxrx       rrrs",
      "myxrx   q   xxxB",
      "myxrx  urw      ",
      "myxrx   A       ",
      "myxrx       xxxC",
      "my      q   rrrs",
      "my     urw  xxxs",
      "my      A      s",
      "myxrx       xxxs",
      "myxrx       rrrs"
    ],
    [
      "                ",
      "            bbb ",
      "              DE",
      "        F      E",
      "               E",
      "I              E",
      "J            K E",
      "L  M            ",
      "   N    !       ",
      "J               ",
      "I  O            ",
      "P            QRE",
      "        S      E",
      "P              E",
      "J              E",
      "   T        KU E"
    ]
  ]
}