{
  "name": "multi_verticalschool_11_ground",
  "refpalette": "deceasedcraft:multi_verticalschool_11/multi_verticalschool_11_ground_palette",
  "xsize": 16,
  "zsize": 16,
  "slices": [
    [
      "a            abb",
      "a          cdddb",
      "a            abb",
      "a            abb",
      "a            abb",
      "a            abb",
      "a            abb",
      "a            abb",
      "a            abb",
      "a            abb",
      "a            aaa",
      "a            aee",
      "a            aee",
      "a            aee",
      "a            aee",
      "a            aee"
    ],
    [
      "fffffffffffffffg",
      "ffffffffffffdddg",
      "fffffffffffffffg",
      "fhhhhhhhhhhhhffg",
      "fffffffffffffffg",
      "fffffffffffffffg",
      "fffffffffffffffg",
      "fhhhhhhhhhhhhffg",
      "fffffffffffffffg",
      "fffffffffffffffg",
      "ffffffffffffffff",
      "iiiiiiiiiiiiiiii",
      "j             j ",
      "j             j ",
      "j             j ",
      "j             j "
    ],
    [
      "kkkkkkkkkkkkkl  ",
      "kkkkkkkkkkkkddd ",
      "kkkkkkkkkkkkkl  ",
      "kkkkkkkkkkkkkl  ",
      "kkkkkkkkkkkkkl  ",
      "kkkkkkkkkkkkkl  ",
      "kkkkkkkkkkkkkl  ",
      "kkkkkkkkkkkkkl  ",
      "kkkkkkkkkkkkkl  ",
      "kkkkkkkkkkkkkl  ",
      "aaaaaaaaaaaaaafm",
      "nnnnnnnnnnnnnnnn",
      "                ",
      "                ",
      "                ",
      "                "
    ],
    [
      "                ",
      "            ddd ",
      "                ",
      "                ",
      "                ",
      "                ",
      "                ",
      "                ",
      "                ",
      "op q rop q      ",
      "aaaaaaaaaaaaaafm",
      "nnnnnnnnnnnnnnnn",
      "                ",
      "                ",
      "                ",
      "                "
    ],
    [
      "                ",
      "            ddd ",
      "                ",
      "                ",
      "                ",
      "                ",
      "                ",
      "                ",
      "                ",
      "   s     s      ",
      "aaaaaaaaaaaaaafm",
      "nnnnnnnnnnnnnnnn",
      "                ",
      "                ",
      "                ",
      "                "
    ],
    [
      "                ",
      "            ddd ",
      "                ",
      "                ",
      "                ",
      "                ",
      "                ",
      "                ",
      "                ",
      "   t     t      ",
      "aaaaaaaaaaaaaafm",
      "nnnnnnnnnnnnnnnn",
      "                ",
      "                ",
      "                ",
      "                "
    ]
  ]
}