{
  "name": "multi_verticalschool_11_floor9",
  "refpalette": "deceasedcraft:multi_verticalschool_11/multi_verticalschool_11_floor9_palette",
  "xsize": 16,
  "zsize": 16,
  "slices": [
    [
      "aaaaaaaaaaaabccc",
      "aaaaaaaaaaaadddb",
      "eeeeeeeeeeeeeeee",
      "eeeeeeeeeeeeeeee",
      "eeeeeeeeeeeeeeee",
      "eeeeeeeeeeeeeeee",
      "eeeeeeeeeeeeeeee",
      "aaaaaaeaaaaaaaee",
      "aaaaaaeaaaaaaaee",
      "aaaaaaeaaaaaaaee",
      "aaaaaaeaaaaaaaee",
      "aaaaaaeaaaaaaaee",
      "aaaaaaeaaaaaaaee",
      "aaaaaaeaaaaaaaee",
      "aaaaaaeaaaaaaaee",
      "fffffffffffffffe"
    ],
    [
      "            gh i",
      "            dddj",
      "                ",
      "                ",
      "                ",
      "                ",
      "kkkklkmkkkkkkk  ",
      "    n k       k ",
      " o o  k   p   k ",
      "qqqq  k rqqqs k ",
      "t!tqu k  qtq  k ",
      "qqqq  k rqtqs k ",
      "w w   k  xtx  k ",
      "      k      yl ",
      "ABBBACkDABBBACk ",
      "fffffffffffffff "
    ],
    [
      "             E j",
      "            ddd ",
      "                ",
      "                ",
      "                ",
      "                ",
      "kkkk khkkkkkkk  ",
      "    F k       k ",
      "      k       k ",
      "      k       k ",
      "      k       k ",
      "      k       k ",
      "      k       k ",
      "      k      I  ",
      "  JK Lk MNO P k ",
      "fffffffffffffff "
    ],
    [
      "              j ",
      "            ddd ",
      "                ",
      "                ",
      "                ",
      "                ",
      "kkkkkkQkkkkkkk  ",
      "      k       k ",
      "      k       k ",
      "      k       k ",
      "      k       k ",
      "      k       k ",
      "      k       k ",
      "      k       k ",
      "      k       k ",
      "fffffffffffffff "
    ],
    [
      "qqqqqqqqqqqq j  ",
      "qqqqqqqqqqqqddd ",
      "qqqqqqqqqqqqqqqq",
      "qqqqqqqqqqqqqqqq",
      "qqqqqqqqqqqqqqqq",
      "qqqqqqqqqqqqqqqq",
      "ffffffffffffffqq",
      "RRRRRSfSRRRRRRfq",
      "RRRRRRfRRRRRRRfq",
      "RRRRRRfRRRRRRRfq",
      "RRRRRRfRRRRRRRfq",
      "RRRRRRfRRRRRRRfq",
      "RRRRRRfRRRRRRRfq",
      "RRRRRRfRRRRRRRfq",
      "RRRRRTfTRRRRRRfq",
      "fffffffffffffffq"
    ],
    [
      "jjjjjjjjjjjjj   ",
      "jjUUUUUUUUUUddd ",
      "UUUUUUUUUUUUUUUU",
      "UUUUUUUUUUUUUUUU",
      "UUUUUUUUUUUUUUUU",
      "UUUUUUUUUUUUUUUU",
      "UUUUUUUUUUUUUUUU",
      "UUUUUUUUUUUUUUUU",
      "UUUUUUUUUUUUUUUU",
      "UUUUUUUUUUUUUUUU",
      "UUUUUUUUUUUUUUUU",
      "UUUUUUUUUUUUUUUU",
      "UUUUUUUUUUUUUUUU",
      "UUUUUUUUUUUUUUUU",
      "UUUUUUUUUUUUUUUU",
      "fffffffffffffffU"
    ]
  ]
}