{
  "name": "multi_verticalschool_11_floor13",
  "refpalette": "deceasedcraft:multi_verticalschool_11/multi_verticalschool_11_floor13_palette",
  "xsize": 16,
  "zsize": 16,
  "slices": [
    [
      "                ",
      "            aaa ",
      "                ",
      "                ",
      "                ",
      "                ",
      "                ",
      "                ",
      "                ",
      "                ",
      "                ",
      "                ",
      "                ",
      "                ",
      "                ",
      "                "
    ],
    [
      "                ",
      "            aaa ",
      "                ",
      "                ",
      "                ",
      "                ",
      "                ",
      "                ",
      "                ",
      "                ",
      "                ",
      "                ",
      "                ",
      "                ",
      "                ",
      "                "
    ],
    [
      "bbbbbbbbbbbbbbbb",
      "bbbbbbbbbbbbaaab",
      "bbbbbbbbbbbbbbbb",
      "bbbbbbbbbbbbbbbb",
      "bbbbbbbbbbbbbbbb",
      "bbbbbbbbbbbbbbbb",
      "bbbbbbbbbbbbbbbb",
      "bbbbbbbbbbbbbbbb",
      "bbbbbbbbbbbbbbbb",
      "bbbbbbbbbbbbbbbb",
      "bbbbbbbbbbbbbbbb",
      "bbbbbbbbbbbbbbbb",
      "bbbbbbbbbbbbbbbb",
      "bbbbbbbbbbbbbbbb",
      "bbbbbbbbbbbbbbbb",
      "bbbbbbbbbbbbbbbb"
    ],
    [
      "cccccccccccccccc",
      "ddddddddddddaaad",
      "eeeeeeeeeeeedfff",
      "eeeeeeeeeeeedfff",
      "eeeeeeeeeeeedfff",
      "eeeeeeeeeeeedfff",
      "eeeeeeeeeeeedfff",
      "eeeeeeeeeeeedfff",
      "eeeeeeeeeeeedfff",
      "eeeeeeeeeeeedfff",
      "eeeeeeeeeeeedfff",
      "eeeeeeeeeeeedfff",
      "eeeeeeeeeeeedfff",
      "eeeeeeeeeeeedfff",
      "eeeggeeeeeeedfff",
      "eeggggeeeeeedfff"
    ],
    [
      "          hhhhh ",
      "         dddaaad",
      "            diii",
      "            d   ",
      "            d   ",
      "               j",
      "               i",
      "                ",
      "                ",
      "                ",
      "                ",
      "               j",
      "               i",
      "            d   ",
      "          kld   ",
      "    m       djjj"
    ],
    [
      "          n o p ",
      "         dddaaad",
      "            d qq",
      "            d   ",
      "            d   ",
      "               r",
      "               s",
      "                ",
      "                ",
      "                ",
      "                ",
      "               r",
      "               s",
      "            d   ",
      "            d   ",
      "            d t!"
    ]
  ]
}