{
  "name": "multi_verticalschool_11_floor29",
  "refpalette": "deceasedcraft:multi_verticalschool_11/multi_verticalschool_11_floor29_palette",
  "xsize": 16,
  "zsize": 16,
  "slices": [
    [
      "aaaaaaaaaaaaaaaa",
      "bbbbbbbbbbbbccca",
      "bdddddddddddddba",
      "bdddddddddddddba",
      "bdddddddddddddba",
      "bdddddddddddddba",
      "bdddddddddddddba",
      "bdddddddddddddba",
      "bdddddddddddddba",
      "bdddddddddddddba",
      "bdddddddddddddba",
      "bdddddddddddddba",
      "bdddddddddddddba",
      "bdddddddddddddba",
      "bdddddddddddddba",
      "bdddddddddddddba"
    ],
    [
      "eeeeeeeeeeeeeeee",
      "bbbbbbbbbbbbcccf",
      "bghhihhj klk kbf",
      "m nnnnn       bf",
      "o             bf",
      "b             bf",
      "b pqrst pqrst bf",
      "b uwwwx uwwwx bf",
      "b             bf",
      "b             bf",
      "b pqrst pqrst bf",
      "b uwwwx uwwwx bf",
      "b             bf",
      "y      A      bf",
      "o   uwBCBwx   bf",
      "bDE         FFbf"
    ],
    [
      "                ",
      "IIIIIIIIIIIIccc ",
      "IJKLLLMNKLLLLMI ",
      "O PPPPP       I ",
      "Q             R ",
      "I             R ",
      "I  S T        R ",
      "R  U      h   R ",
      "R             I ",
      "R             I ",
      "R    !   V T  R ",
      "I  UWX   YS   R ",
      "I             R ",
      "Z             R ",
      "Q    0UX12    I ",
      "I3h    4    55I "
    ],
    [
      "                ",
      "IIIIIIIIIIIIccc ",
      "I67777!8999999I ",
      "R #####       I ",
      "R             R ",
      "I             R ",
      "I             R ",
      "R             R ",
      "R             I ",
      "R             I ",
      "R             R ",
      "I             R ",
      "I             R ",
      "R             R ",
      "R             I ",
      "I$          % I "
    ],
    [
      "                ",
      "IIIIIIIIIIIIccc ",
      "I        ^&*&(I ",
      "I             I ",
      "I             I ",
      "I             I ",
      "I             I ",
      "I             I ",
      "I             I ",
      "I             I ",
      "I             I ",
      "I             I ",
      "I             I ",
      "I             I ",
      "I             I ",
      "I)            I "
    ],
    [
      "++++++++++++++++",
      "IIIIIIIIIIIIccc+",
      "I-------------I+",
      "I-------------I+",
      "I--[[[---[[[--I+",
      "I-------------I+",
      "I-------------I+",
      "I--[[[---[[]--I+",
      "I-------------I+",
      "I-------------I+",
      "I--[[[---[[[--I+",
      "I-------------I+",
      "I-------------I+",
      "I--[[[---[[]--I+",
      "I-------------I+",
      "I-------------I+"
    ]
  ]
}