{
  "name": "multi_verticalschool_11_floor26",
  "refpalette": "deceasedcraft:multi_verticalschool_11/multi_verticalschool_11_floor26_palette",
  "xsize": 16,
  "zsize": 16,
  "slices": [
    [
      "aaaaaaaaaaaaaaaa",
      "bbbbbbbbbbbbccca",
      "bdddddddddddddba",
      "bdddddddddddddba",
      "bdddddddddddddba",
      "bdddddddddddddba",
      "bdddddddddddddba",
      "bdddddddddddddba",
      "bdddddddddddddba",
      "bdddddddddddddba",
      "bdddddddddddddba",
      "bdddddddddddddba",
      "bdddddddddddddba",
      "bdddddddddddddba",
      "bdddddddddddddba",
      "bdddddddddddddba"
    ],
    [
      "eeeeeeeeeeeeeeee",
      "bbbbbbbbbbbbcccf",
      "bgghiiiiiiijggbf",
      "k             bf",
      "l     mmm     bf",
      "b     nnn   oobf",
      "b    mnpnm  oobf",
      "b    mnpnm    bf",
      "boo  mnpnm    bf",
      "boo  mnpnm    bf",
      "b    mnpnm    bf",
      "b    mnpnm  oobf",
      "b     nnn   oobf",
      "k     mmm     bf",
      "l             bf",
      "bqr         qrbf"
    ],
    [
      "                ",
      "ssssssssssssccc ",
      "sggt uwxyABCggs ",
      "D             s ",
      "E             F ",
      "s             F ",
      "s             F ",
      "F             F ",
      "F             s ",
      "F             s ",
      "F             F ",
      "s             F ",
      "s             F ",
      "D             F ",
      "E             s ",
      "sI    JJJ   KLs "
    ],
    [
      "                ",
      "ssssssssssssccc ",
      "sgg         ggs ",
      "F             s ",
      "F             F ",
      "s             F ",
      "s             F ",
      "F             F ",
      "F             s ",
      "F             s ",
      "F             F ",
      "s             F ",
      "s             F ",
      "F             F ",
      "F             s ",
      "sM    JJJ     s "
    ],
    [
      "                ",
      "ssssssssssssccc ",
      "sN!          Os ",
      "s             s ",
      "s             s ",
      "s             s ",
      "s             s ",
      "s             s ",
      "s             s ",
      "s             s ",
      "s      P      s ",
      "s             s ",
      "s             s ",
      "s             s ",
      "s             s ",
      "sQ            s "
    ],
    [
      "RRRRRRRRRRRRRRRR",
      "sssssssssssscccR",
      "sSSSSSSSSSSSSSsR",
      "sSSSSSSSSSSSSSsR",
      "sSSTTTSSSTTTSSsR",
      "sSSSSSSSSSSSSSsR",
      "sSSSSSSSSSSSSSsR",
      "sSSTTTSSSTTTSSsR",
      "sSSSSSSSSSSSSSsR",
      "sSSSSSSSSSSSSSsR",
      "sSSTTTSSSTUUSSsR",
      "sSSSSSSSSSSSSSsR",
      "sSSSSSSSSSSSSSsR",
      "sSSUUUSSSTTTSSsR",
      "sSSSSSSSSSSSSSsR",
      "sSSSSSSSSSSSSSsR"
    ]
  ]
}