{
  "name": "multi_verticalschool_11_floor23",
  "refpalette": "deceasedcraft:multi_verticalschool_11/multi_verticalschool_11_floor23_palette",
  "xsize": 16,
  "zsize": 16,
  "slices": [
    [
      "                ",
      "            aaa ",
      "                ",
      "                ",
      "                ",
      "                ",
      "                ",
      "                ",
      "                ",
      "                ",
      "                ",
      "                ",
      "                ",
      "                ",
      "                ",
      "                "
    ],
    [
      "bbbbbbbbbbbbbbbb",
      "ccccccccccccaaab",
      "dddddddddddddcbb",
      "dddddddddddddcbb",
      "dddddddddddddcbb",
      "dddddddddddddcbb",
      "dddddddddddddcbb",
      "dddddddddddddcbb",
      "dddddddddddddcbb",
      "dddddddddddddcbb",
      "dddddddddddddcbb",
      "dddddddddddddcbb",
      "dddddddddddddcbb",
      "dddddddddddddcbb",
      "dddddddddddddcbb",
      "dddddddddddddcbb"
    ],
    [
      "eeeeeeeeeeeeefgh",
      "ffffffffffffaaah",
      "iiiiiiiiiiiiifgh",
      "iiiiiiiiiiiiifgh",
      "ffffffffffffffgh",
      "jjjjjjjjjjjjjfgh",
      "ffffffffffffffgh",
      "kkkkkkkkkkkkkfgh",
      "kkkkkkkkkkkkkfgh",
      "ffffffffffffffgh",
      "lllllllllllllfgh",
      "lllllllllllllfgh",
      "ffffffffffffffgh",
      "miiiiiiiiiiiifgh",
      "nfffffffffffffgh",
      "nmjjjjjjjjjjjfgh"
    ],
    [
      "              op",
      "            aaap",
      "              op",
      "              op",
      "              op",
      "              op",
      "              op",
      "              op",
      "              op",
      "              op",
      "              op",
      "              op",
      "              op",
      "              op",
      "              op",
      "              op"
    ],
    [
      "                ",
      "            aaaq",
      "               q",
      "               q",
      "               q",
      "               q",
      "               q",
      "               q",
      "                ",
      "               q",
      "               q",
      "               q",
      "               q",
      "                ",
      "               q",
      "                "
    ],
    [
      "                ",
      "            aaa ",
      "                ",
      "                ",
      "                ",
      "                ",
      "                ",
      "                ",
      "                ",
      "                ",
      "                ",
      "                ",
      "                ",
      "                ",
      "                ",
      "                "
    ]
  ]
}