{
  "name": "multi_verticalschool_11_floor14",
  "refpalette": "deceasedcraft:multi_verticalschool_11/multi_verticalschool_11_floor14_palette",
  "xsize": 16,
  "zsize": 16,
  "slices": [
    [
      "                ",
      "         aaabbba",
      "            accc",
      "            a   ",
      "            a   ",
      "                ",
      "                ",
      "                ",
      "                ",
      "                ",
      "                ",
      "                ",
      "                ",
      "            a   ",
      "            a   ",
      "            addd"
    ],
    [
      "                ",
      "         aaabbba",
      "            aef ",
      "            a   ",
      "            a   ",
      "                ",
      "                ",
      "                ",
      "                ",
      "                ",
      "                ",
      "                ",
      "                ",
      "            a   ",
      "            a   ",
      "            aghg"
    ],
    [
      "                ",
      "         aaabbba",
      "            a   ",
      "            a   ",
      "            a   ",
      "                ",
      "                ",
      "                ",
      "                ",
      "                ",
      "                ",
      "                ",
      "                ",
      "            a   ",
      "            a   ",
      "            a   "
    ],
    [
      "                ",
      "         aaabbba",
      "            a   ",
      "            a   ",
      "            a   ",
      "                ",
      "                ",
      "                ",
      "                ",
      "                ",
      "                ",
      "                ",
      "                ",
      "            a   ",
      "            a   ",
      "            a   "
    ],
    [
      "iiiiiiiiiijjjjjj",
      "kkkkkkkkkaaabbba",
      "            alll",
      "            alll",
      "            amll",
      "            kmll",
      "            kmll",
      "            kmll",
      "            kmll",
      "            kmll",
      "            kmll",
      "            kmll",
      "            kmll",
      "            amll",
      "            alll",
      "            alll"
    ],
    [
      "aaaaaaaaaaaaaaan",
      "aaaaaaaaaaaabbba",
      "            ao a",
      "            a  a",
      "            a  a",
      "            a  a",
      "            apqa",
      "            ao a",
      "            a  a",
      "            a  a",
      "            a  a",
      "            apqa",
      "            ao a",
      "            a  a",
      "            a  a",
      "            a  a"
    ]
  ]
}