{
  "name": "multi_verticalschool_18_floor14",
  "refpalette": "deceasedcraft:multi_verticalschool_18/multi_verticalschool_18_floor14_palette",
  "xsize": 16,
  "zsize": 16,
  "slices": [
    [
      "    a    bc     ",
      "    a    bc     ",
      "    a    bc     ",
      "    a    bc     ",
      "    a    bc     ",
      "    a    bc     ",
      "    a    bc     ",
      "    a   dbc     ",
      "    a    bc     ",
      "    a    bc     ",
      "    a    bc     ",
      "    a    bc     ",
      "    a    bc     ",
      "    a    bc     ",
      "aaaa     bc     ",
      "         bc     "
    ],
    [
      " e  a    bc     ",
      "    a    bc     ",
      "    a    bc     ",
      "    a    bc     ",
      "    a    bc     ",
      "    a    bc     ",
      "    a    bc     ",
      "    a    bc     ",
      "    a    bc     ",
      "    a    bc     ",
      "    a    bc     ",
      "    a    bc     ",
      "    a    bc     ",
      "    a    bc     ",
      "aaaa     bc     ",
      "         bc     "
    ],
    [
      "    a    bc     ",
      "    a    bc     ",
      "    a    bc     ",
      "    a    bc     ",
      "    a    bc     ",
      "    a    bc     ",
      "    a    bc     ",
      "    a    bc     ",
      "    a    bc     ",
      "    a    bc     ",
      "    a    bc     ",
      "    a    bc     ",
      "    a    bc     ",
      "    a    bc     ",
      "aaaa     bc     ",
      "         bc     "
    ],
    [
      "fff a    bc     ",
      "fff a    bc     ",
      "fff a    bc     ",
      "fff a    bc     ",
      "fff a    bc     ",
      "fff a    bc     ",
      "fff a    bc     ",
      "fff a    bc     ",
      "fff a    bc     ",
      "fff a    bc     ",
      "fff a    bc     ",
      "fff a    bc     ",
      "fff a    bc     ",
      "fff a    bc     ",
      "aaaa     bc     ",
      "         bc     "
    ],
    [
      "ghgiajjjkbc     ",
      "ghgiajjjkbc     ",
      "ghgiajjjkbc     ",
      "ghgiajjjkbc     ",
      "ghgiajjjkbc     ",
      "ghgiajjjkbc     ",
      "ghgiajjjkbc     ",
      "ghgiajjjkbc     ",
      "ghgiajjjkbc     ",
      "ghgiajjjkbc     ",
      "ghgiajjjkbc     ",
      "ghgiajjjkbc     ",
      "ghgiajjjkbc     ",
      "ghgiajjjkbc     ",
      "aaaajjjjkbc     ",
      "jjjjjjjjkbc     "
    ],
    [
      "lllllllmbbc     ",
      "lllllllmbbc     ",
      "lllllllmbbc     ",
      "lllllllmbbc     ",
      "lllllllmbbc     ",
      "lllllllmbbc     ",
      "lllllllmbbc     ",
      "lllllllmbbc     ",
      "lllllllmbbc     ",
      "lllllllmbbc     ",
      "lllllllmbbc     ",
      "lllllllmbbc     ",
      "lllllllmbbc     ",
      "lllllllmbbc     ",
      "lllllllmbbc     ",
      "llllllmmbbc     "
    ]
  ]
}