{
  "name": "multi_verticalschool_18_floor9",
  "refpalette": "deceasedcraft:multi_verticalschool_18/multi_verticalschool_18_floor9_palette",
  "xsize": 16,
  "zsize": 16,
  "slices": [
    [
      "aaab  c         ",
      "aaab            ",
      "aaab            ",
      "aaab  c         ",
      "aaab cc         ",
      "aaab            ",
      "aaab            ",
      "aaab            ",
      "aaab  c         ",
      "aaab ccc        ",
      "aaab            ",
      "aaab            ",
      "aaab            ",
      "aaab            ",
      "aaab  cc        ",
      "aaab            "
    ],
    [
      "   b  c         ",
      "   b            ",
      "   b            ",
      "   b  c         ",
      "   b ccc        ",
      "   b  c         ",
      "   b            ",
      "   b            ",
      "   b  c         ",
      "   b ccc        ",
      "   b  c         ",
      "   b            ",
      "   b            ",
      "   b  c         ",
      "   b ccc        ",
      "   b  c         "
    ],
    [
      "   b            ",
      "   b            ",
      "   b            ",
      "   b  c         ",
      "   b  cc        ",
      "   b  c         ",
      "   b            ",
      "   b            ",
      "   b  c         ",
      "   b  c         ",
      "   b            ",
      "   b            ",
      "   b            ",
      "   b  c         ",
      "   b ccc        ",
      "   b  c         "
    ],
    [
      "   b            ",
      "   b            ",
      "   b            ",
      "   b            ",
      "   b  c         ",
      "   b  c         ",
      "   b            ",
      "   b            ",
      "   b ~          ",
      "   b  c         ",
      "   b            ",
      "   b            ",
      "   b            ",
      "   b            ",
      "   b cc         ",
      "   b  c         "
    ],
    [
      "ddeb            ",
      "ddeb            ",
      "ddeb            ",
      "ddeb ~          ",
      "ddeb  c         ",
      "ddeb            ",
      "ddeb            ",
      "ddeb            ",
      "ddeb            ",
      "ddeb            ",
      "ddeb            ",
      "ddeb            ",
      "ddeb            ",
      "ddeb            ",
      "ddeb  c         ",
      "ddeb            "
    ],
    [
      "ffgb            ",
      "ffgb            ",
      "ffgb            ",
      "ffgb            ",
      "ffgb            ",
      "ffgb            ",
      "ffgb            ",
      "ffgb            ",
      "ffgb            ",
      "ffgb            ",
      "ffgb            ",
      "ffgb            ",
      "ffgb            ",
      "ffgb            ",
      "ffgb            ",
      "fggb            "
    ]
  ]
}