{
  "name": "multi_verticalschool_18_floor29",
  "refpalette": "deceasedcraft:multi_verticalschool_18/multi_verticalschool_18_floor29_palette",
  "xsize": 16,
  "zsize": 16,
  "slices": [
    [
      "aabc            ",
      "aabc            ",
      "aabc            ",
      "aabc            ",
      "aabc            ",
      "aabc            ",
      "aabc            ",
      "aabc            ",
      "aabc            ",
      "aabc            ",
      "aabc            ",
      "aabc            ",
      "aabc            ",
      "aabc            ",
      "aabc            ",
      "aabc            "
    ],
    [
      "debf            ",
      "debf            ",
      "gebf            ",
      "debf            ",
      "d bf            ",
      "dhbf            ",
      "debf            ",
      "dhbf            ",
      "debf            ",
      "debf            ",
      "d bf            ",
      "debf            ",
      "gebf            ",
      "d bf            ",
      "dhbf            ",
      "debf            "
    ],
    [
      "i j             ",
      "i j             ",
      "  j             ",
      "i j             ",
      "i j             ",
      "i j             ",
      "  j             ",
      "i j             ",
      "i j             ",
      "i j             ",
      "i j             ",
      "i j             ",
      "  j             ",
      "  j             ",
      "i j             ",
      "i j             "
    ],
    [
      "  j             ",
      "  j             ",
      "  j             ",
      "  j             ",
      "  j             ",
      "  j             ",
      "  j             ",
      "  j             ",
      "  j             ",
      "  j             ",
      "  j             ",
      "  j             ",
      "  j             ",
      "  j             ",
      "  j             ",
      "  j             "
    ],
    [
      "  j             ",
      "  j             ",
      "  j             ",
      "  j             ",
      "  j             ",
      "  j             ",
      "  j             ",
      "  j             ",
      "  j             ",
      "  j             ",
      "  j             ",
      "  j             ",
      "  j             ",
      "  j             ",
      "  j             ",
      "  j             "
    ],
    [
      "kkjl            ",
      "kkjl            ",
      "kkjl            ",
      "kkjl            ",
      "kkjl            ",
      "kkjl            ",
      "kkjl            ",
      "kkjl            ",
      "kkjl            ",
      "kkjl            ",
      "kkjl            ",
      "kkjl            ",
      "kkjl            ",
      "kkjl            ",
      "kkjl            ",
      "kkjl            "
    ]
  ]
}