{
  "name": "multi_verticalschool_18_floor20",
  "refpalette": "deceasedcraft:multi_verticalschool_18/multi_verticalschool_18_floor20_palette",
  "xsize": 16,
  "zsize": 16,
  "slices": [
    [
      "  a             ",
      "  a             ",
      " ba             ",
      "  a             ",
      "  a             ",
      "  a             ",
      "  a             ",
      "  a             ",
      "  a             ",
      "  a             ",
      "  a             ",
      " ba             ",
      "  a             ",
      "  a             ",
      " ba             ",
      "  a             "
    ],
    [
      "  a             ",
      "  a             ",
      "  a             ",
      "  a             ",
      "  a             ",
      "  a             ",
      "  a             ",
      "  a             ",
      "  a             ",
      "  a             ",
      "  a             ",
      "  a             ",
      "  a             ",
      "  a             ",
      "  a             ",
      "  a             "
    ],
    [
      "ccad            ",
      "ccad            ",
      "ccad            ",
      "ccad            ",
      "ccad            ",
      "ccad            ",
      "ccad            ",
      "ccad            ",
      "ccad            ",
      "ccad            ",
      "ccad            ",
      "ccad            ",
      "ccad            ",
      "ccad            ",
      "ccad            ",
      "ccad            "
    ],
    [
      "eefg            ",
      "eefg            ",
      "eefg            ",
      "eefg            ",
      "eefg            ",
      "eefg            ",
      "eefg            ",
      "eefg            ",
      "eefg            ",
      "eefg            ",
      "eefg            ",
      "eefg            ",
      "eefg            ",
      "eefg            ",
      "eefg            ",
      "eefg            "
    ],
    [
      "hifj            ",
      "kifj            ",
      "klfj            ",
      "hifj            ",
      "kifj            ",
      "klfj            ",
      "kifj            ",
      "kifj            ",
      "kmfj            ",
      "kifj            ",
      "kifj            ",
      "klfj            ",
      "kifj            ",
      "kifj            ",
      "hlfj            ",
      "kifj            "
    ],
    [
      "  a             ",
      "  a             ",
      " na             ",
      "  a             ",
      "  a             ",
      " na             ",
      "  a             ",
      "  o             ",
      " pa             ",
      "  a             ",
      "  a             ",
      " na             ",
      "  a             ",
      "  a             ",
      " na             ",
      "  a             "
    ]
  ]
}