{
  "name": "multi_verticalschool_18_floor15",
  "refpalette": "deceasedcraft:multi_verticalschool_18/multi_verticalschool_18_floor15_palette",
  "xsize": 16,
  "zsize": 16,
  "slices": [
    [
      "       a        ",
      "     bac        ",
      "       c        ",
      "       c        ",
      "       c        ",
      "       c        ",
      "     dac        ",
      "       c        ",
      "       c        ",
      "       c        ",
      "       c        ",
      "     dac        ",
      "       c        ",
      "       a        ",
      "       c        ",
      "      cc        "
    ],
    [
      "                ",
      "      c         ",
      "       ~        ",
      "                ",
      "                ",
      "                ",
      "      c         ",
      "                ",
      "                ",
      "                ",
      "                ",
      "      c         ",
      "       ~        ",
      "                ",
      "                ",
      "                "
    ],
    [
      "ef g            ",
      "ef g  h         ",
      "ef g            ",
      "ef g            ",
      "ef g            ",
      "ef g            ",
      "ef g  h         ",
      "ef g            ",
      "ef g            ",
      "ef g            ",
      "ef g            ",
      "ef g  h         ",
      "ef g            ",
      "ef g            ",
      "ef g            ",
      "ff g            "
    ],
    [
      "iijk            ",
      "iijk hh         ",
      "iijk  h         ",
      "lijk            ",
      "lijk            ",
      "iijk  h         ",
      "iijk  hh        ",
      "lijk  h         ",
      "iijk            ",
      "iljk            ",
      "iijk  h         ",
      "lijk  h         ",
      "lijk            ",
      "iijk            ",
      "iljk            ",
      "iijk            "
    ],
    [
      "  jm  h         ",
      "  jm hhh        ",
      "  jm  h         ",
      "  jm            ",
      "  jm            ",
      "  jm  h         ",
      "  jm hhh        ",
      "  jm  h         ",
      "  jm            ",
      "  jm            ",
      "  jm  h         ",
      "  jm hhh        ",
      "  jm  h         ",
      "  jm            ",
      "  jm            ",
      "  jm            "
    ],
    [
      "  n   h         ",
      "  n   hh        ",
      "  n   h         ",
      "  n             ",
      "  n             ",
      "  n             ",
      "  n   hh        ",
      "  n   h         ",
      "  n             ",
      "  n             ",
      "  n             ",
      "  n  hh         ",
      "  n   h         ",
      "  n             ",
      "  n             ",
      "  n             "
    ]
  ]
}