{
  "name": "multi_verticalschool_18_floor19",
  "refpalette": "deceasedcraft:multi_verticalschool_18/multi_verticalschool_18_floor19_palette",
  "xsize": 16,
  "zsize": 16,
  "slices": [
    [
      "  a             ",
      "  a             ",
      " ba             ",
      "  a             ",
      "  a             ",
      "  a             ",
      "  a             ",
      "  a             ",
      "  a             ",
      "  a             ",
      "  a             ",
      " ba             ",
      "  a             ",
      "  a             ",
      " ba             ",
      "  a             "
    ],
    [
      "  a             ",
      "  a             ",
      "  a             ",
      "  a             ",
      "  a             ",
      "  a             ",
      "  a             ",
      "  a             ",
      "  a             ",
      "  a             ",
      "  a             ",
      "  a             ",
      "  a             ",
      "  a             ",
      "  a             ",
      "  a             "
    ],
    [
      "ccad            ",
      "ccad            ",
      "ccad            ",
      "ccad            ",
      "ccad            ",
      "ccad            ",
      "ccad            ",
      "ccad            ",
      "ccad            ",
      "ccad            ",
      "ccad            ",
      "ccad            ",
      "ccad            ",
      "ccad            ",
      "ccad            ",
      "ccad            "
    ],
    [
      "eefg            ",
      "eefg            ",
      "eefg            ",
      "eefg            ",
      "eefg            ",
      "eefg            ",
      "eefg            ",
      "eefg            ",
      "eefg            ",
      "eefg            ",
      "eefg            ",
      "eefg            ",
      "eefg            ",
      "eefg            ",
      "eefg            ",
      "eefg            "
    ],
    [
      "hifj            ",
      "hifj            ",
      "hkfj            ",
      "hifj            ",
      "hifj            ",
      "lkfj            ",
      "lifj            ",
      "hifj            ",
      "hkfj            ",
      "hifj            ",
      "hifj            ",
      "hkfj            ",
      "hifj            ",
      "hifj            ",
      "hkfj            ",
      "hifj            "
    ],
    [
      "  a             ",
      "  a             ",
      " ma             ",
      "  a             ",
      "  a             ",
      " ma             ",
      "  a             ",
      "  a             ",
      "                ",
      "  a             ",
      "  a             ",
      " ma             ",
      "  a             ",
      "  a             ",
      " ma             ",
      "  a             "
    ]
  ]
}