{
  "name": "multi_verticalschool_18_floor8",
  "refpalette": "deceasedcraft:multi_verticalschool_18/multi_verticalschool_18_floor8_palette",
  "xsize": 16,
  "zsize": 16,
  "slices": [
    [
      "        abc     ",
      "         bc     ",
      "         bc     ",
      "         bc     ",
      "         bc     ",
      "         bc     ",
      "         bc     ",
      "         bc     ",
      "dddefddddbc     ",
      "         bc     ",
      "         bc     ",
      "         bc     ",
      "         bc     ",
      "         bc     ",
      "         bc     ",
      "         bc     "
    ],
    [
      "gggggggggbc     ",
      "gggggggggbc     ",
      "gggggggggbc     ",
      "gggggggggbc     ",
      "gggggggggbc     ",
      "gggggggggbc     ",
      "gggggggggbc     ",
      "gggggggggbc     ",
      "dddddddddbc     ",
      "hhhhhhhhibc     ",
      "hhhhhhhhibc     ",
      "hhhhhhhhibc     ",
      "hhhhhhhhibc     ",
      "hhhhhhhhibc     ",
      "hhhhhhhhibc     ",
      "hhhhhhhhibc     "
    ],
    [
      "jjjjjjjkbbc     ",
      "jjjjjjjkbbc     ",
      "jjjjjjjkbbc     ",
      "jjjjjjjkbbc     ",
      "jjjjjjjkbbc     ",
      "jjjjjjjkbbc     ",
      "jjjjjjjkbbc     ",
      "jjjjjjjkbbc     ",
      "jjjjjjjkbbc     ",
      "jjjjjjjkbbc     ",
      "jjjjjjjkbbc     ",
      "jjjjjjjkbbc     ",
      "jjjjjjjkbbc     ",
      "jjjjjjjkbbc     ",
      "jjjjjjjkbbc     ",
      "jjjjjjkkbbc     "
    ],
    [
      "       l        ",
      "       l        ",
      "       l        ",
      "       l        ",
      "     mnl        ",
      "       l        ",
      "       n        ",
      "       l        ",
      "       l        ",
      "     mnl        ",
      "       l        ",
      "       l        ",
      "       l        ",
      "       l        ",
      "     onn        ",
      "      ll        "
    ],
    [
      "                ",
      "                ",
      "                ",
      "                ",
      "      l         ",
      "       ~        ",
      "                ",
      "                ",
      "                ",
      "      l         ",
      "                ",
      "                ",
      "                ",
      "                ",
      "      l         ",
      "                "
    ],
    [
      "pq r            ",
      "pq r            ",
      "pq r            ",
      "pq r            ",
      "pq r  s         ",
      "pq r            ",
      "pq r            ",
      "pq r            ",
      "pq r            ",
      "pq r  s         ",
      "pq r            ",
      "pq r            ",
      "pq r            ",
      "pq r            ",
      "pq r  s         ",
      "qq r            "
    ]
  ]
}