{
  "name": "multi_verticalschool_18_floor10",
  "refpalette": "deceasedcraft:multi_verticalschool_18/multi_verticalschool_18_floor10_palette",
  "xsize": 16,
  "zsize": 16,
  "slices": [
    [
      "  ab            ",
      "  ab            ",
      "  ab            ",
      "  ab            ",
      "  ab            ",
      "  ab            ",
      "  ab            ",
      "  ab            ",
      "  ab            ",
      "  ab            ",
      "  ab            ",
      "  ab            ",
      "  ab            ",
      "  ab            ",
      "  ab            ",
      " aab            "
    ],
    [
      "                ",
      "                ",
      "                ",
      "                ",
      "                ",
      "                ",
      "                ",
      "                ",
      "                ",
      "                ",
      "                ",
      "                ",
      "                ",
      "                ",
      "                ",
      "                "
    ],
    [
      "cccccccccccdc e ",
      "cccccccccccdc e ",
      "cccccccccccdc e ",
      "cccccccccccdc e ",
      "cccccccccccdc e ",
      "cccccccccccdc e ",
      "cccccccccccdc e ",
      "cccccccccccdc e ",
      "cccccccccccdc e ",
      "cccccccccccdc e ",
      "cccccccccccdc e ",
      "cccccccccccdc e ",
      "cccccccccccdc e ",
      "cccccccccccdc e ",
      "cccccccccccdc e ",
      "cccccccccccdc e "
    ],
    [
      "ffghhhhhhhhhhij ",
      "fgghhhhhhhhhhij ",
      "fghhhhhhhhhhhij ",
      "ghhhhhhhhhhhhij ",
      "hhhhhhhhhhhhhij ",
      "hhhhhhhhhhhhhij ",
      "hhhhhhhhhhhhhij ",
      "hhhhhhhhhhhhhij ",
      "hhhhhhhhhhhhhij ",
      "hhhhhhhhhhhhhij ",
      "hhhhhhhhhhhhhij ",
      "hhhhhhhhhhhhhij ",
      "hhhhhhhhhhhhhij ",
      "hhhhhhhhhhhhhij ",
      "hhhhhhhhhhhhhij ",
      "hhhkkkkkkhhhhij "
    ],
    [
      "  l         mib ",
      " a           ib ",
      "             ib ",
      "             ib ",
      "             ib ",
      "             ib ",
      "             ib ",
      "            nib ",
      "            oib ",
      "            mib ",
      "             ib ",
      "             ib ",
      "             ib ",
      "             ib ",
      "             ib ",
      "             ib "
    ],
    [
      "             p  ",
      " a    q      p  ",
      "             p  ",
      "             p  ",
      "             p  ",
      "             p  ",
      "     rq      p  ",
      "             p  ",
      "     rq      p  ",
      "             p  ",
      "     r       p  ",
      "             p  ",
      "             p  ",
      "             p  ",
      "             p  ",
      "             p  "
    ]
  ]
}