{
  "name": "multi_verticalschool_18_floor13",
  "refpalette": "deceasedcraft:multi_verticalschool_18/multi_verticalschool_18_floor13_palette",
  "xsize": 16,
  "zsize": 16,
  "slices": [
    [
      "                ",
      "                ",
      "                ",
      "                ",
      "                ",
      "                ",
      "                ",
      "                ",
      "                ",
      "                ",
      "                ",
      "                ",
      "                ",
      "                ",
      "                ",
      "                "
    ],
    [
      "                ",
      "                ",
      "                ",
      "                ",
      "                ",
      "                ",
      "                ",
      "                ",
      "                ",
      "                ",
      "                ",
      "                ",
      "                ",
      "                ",
      "                ",
      "                "
    ],
    [
      "aaaaaaba c      ",
      "aaaaaaba c      ",
      "aaaaaaba c      ",
      "aaaaaaba c      ",
      "aaaaaaba c      ",
      "aaaaaaba c      ",
      "aaaaaaba c      ",
      "aaaaaaba c      ",
      "aaaaaaba c      ",
      "aaaaaaba c      ",
      "aaaaaaba c      ",
      "aaaaaaba c      ",
      "aaaaaaba c      ",
      "aaaaaaba c      ",
      "aaaaaaba c      ",
      "aaaaabaa c      "
    ],
    [
      "deeefdddghi     ",
      "deeefdddghi     ",
      "deeefdddghi     ",
      "deeefdddghi     ",
      "deeefdddghi     ",
      "deeefdddghi     ",
      "deeefdddghi     ",
      "deeefdddghi     ",
      "deeefdddghi     ",
      "deeefdddghi     ",
      "deeefdddghi     ",
      "deeefdddghi     ",
      "deeefdddghi     ",
      "deeefdddghi     ",
      "ffffddddghi     ",
      "ddddddddghi     "
    ],
    [
      "jk lf    hi     ",
      "jkl f    hi     ",
      "mnnnf    hi     ",
      "m l f    hi     ",
      "mll f    hi     ",
      "mnnnf    hi     ",
      "m   f    hi     ",
      "o   f   phi     ",
      "onnnf    hi     ",
      "o   f    hi     ",
      "o  lf    hi     ",
      "onnnf    hi     ",
      "jkllf    hi     ",
      "jkl f    hi     ",
      "ffff     hi     ",
      "         hi     "
    ],
    [
      "  jjf    hi     ",
      "  jjf    hi     ",
      " jjjf    qi     ",
      " jjjf    qi     ",
      " jjjf    qi     ",
      " jjjf    hi     ",
      " jjjf    hi     ",
      " jjjf   rhi     ",
      " jjjf    hi     ",
      " jjjf    hi     ",
      " jjjf    qi     ",
      " jjjf    qi     ",
      "  jjf    qi     ",
      "  jjf    qi     ",
      "ffff     hi     ",
      "         hi     "
    ]
  ]
}