{
  "name": "multi_verticalschool_18_floor16",
  "refpalette": "deceasedcraft:multi_verticalschool_18/multi_verticalschool_18_floor16_palette",
  "xsize": 16,
  "zsize": 16,
  "slices": [
    [
      "  a             ",
      "  a   b         ",
      "  a   b         ",
      "  a             ",
      "  a             ",
      "  a  ~          ",
      "  a   b         ",
      "  a             ",
      "  a ~           ",
      "  a~~           ",
      "  a  ~          ",
      "  a   b         ",
      "  a             ",
      "  a             ",
      "  a             ",
      "  a             "
    ],
    [
      "  a  ~          ",
      "  a   b         ",
      "  a             ",
      "  a             ",
      "  a             ",
      "  a             ",
      "  a             ",
      "  a             ",
      "  a             ",
      "  a    ~        ",
      "  a  ~          ",
      "  a             ",
      "  a             ",
      "  a             ",
      "  a             ",
      "  a             "
    ],
    [
      "  a             ",
      "  a             ",
      "  a             ",
      "  a             ",
      "  a             ",
      "  a             ",
      "  a             ",
      "  a             ",
      "  a             ",
      "  a             ",
      "  a             ",
      "  a             ",
      "  a             ",
      "  a             ",
      "  a             ",
      "  a             "
    ],
    [
      "ccad            ",
      "ccad            ",
      "ccad            ",
      "ccad            ",
      "ccad            ",
      "ccad            ",
      "ccad            ",
      "ccad            ",
      "ccad            ",
      "ccad            ",
      "ccad            ",
      "ccad            ",
      "ccad            ",
      "ccad            ",
      "ccad            ",
      "ccad            "
    ],
    [
      "cefg            ",
      "chfg            ",
      "chfg            ",
      "cefg            ",
      "cefg            ",
      "cefg            ",
      "chfg            ",
      "chfg            ",
      "cefg            ",
      "cefg            ",
      "cefg            ",
      "chfg            ",
      "chfg            ",
      "cefg            ",
      "cefg            ",
      "cefg            "
    ],
    [
      "ggfi            ",
      "ggfi            ",
      "ggfi            ",
      "ggfi            ",
      "ggfi            ",
      "ggfi            ",
      "ggfi            ",
      "ggfi            ",
      "ggfi            ",
      "ggfi            ",
      "ggfi            ",
      "ggfi            ",
      "ggfi            ",
      "ggfi            ",
      "ggfi            ",
      "ggfi            "
    ]
  ]
}