{
  "name": "multi_verticalschool_18_floor31",
  "refpalette": "deceasedcraft:multi_verticalschool_18/multi_verticalschool_18_floor31_palette",
  "xsize": 16,
  "zsize": 16,
  "slices": [
    [
      "  a             ",
      "  a             ",
      "  a             ",
      "  a             ",
      "  a             ",
      "  a             ",
      "  a             ",
      "  a             ",
      "  a             ",
      "  a             ",
      "  a             ",
      "  a             ",
      "  a             ",
      "  a             ",
      "  a             ",
      "  a             "
    ],
    [
      "  a             ",
      "  a             ",
      "  a             ",
      "  a             ",
      "  a             ",
      "  a             ",
      "  a             ",
      "  a             ",
      "  a             ",
      "  a             ",
      "  a             ",
      "  a             ",
      "  a             ",
      "  a             ",
      "  a             ",
      "  a             "
    ],
    [
      "  a             ",
      "  a             ",
      "  a             ",
      "  a             ",
      "  a             ",
      "  a             ",
      "  a             ",
      "  a             ",
      "  a             ",
      "  a             ",
      "  a             ",
      "  a             ",
      "  a             ",
      "  a             ",
      "  a             ",
      "  a             "
    ],
    [
      "  ab            ",
      "  ab            ",
      "  ab            ",
      "  ab            ",
      "  ab            ",
      "  ab            ",
      "  ab            ",
      "  ab            ",
      "  ab            ",
      "  ab            ",
      "  ab            ",
      "  ab            ",
      "  ab            ",
      "  ab            ",
      "  ab            ",
      "  ab            "
    ],
    [
      "ccde            ",
      "ccde            ",
      "ccde            ",
      "ccde            ",
      "ccde            ",
      "ccde            ",
      "ccde            ",
      "ccde            ",
      "ccde            ",
      "ccde            ",
      "ccde            ",
      "ccde            ",
      "ccde            ",
      "ccde            ",
      "ccde            ",
      "ccde            "
    ],
    [
      "eeee            ",
      "eeee            ",
      "eeee            ",
      "eeee            ",
      "eeee            ",
      "eeee            ",
      "eeee            ",
      "eeee            ",
      "eeee            ",
      "eeee            ",
      "eeee            ",
      "eeee            ",
      "eeee            ",
      "eeee            ",
      "eeee            ",
      "eeee            "
    ]
  ]
}