{
  "name": "multi_verticalschool_18_floor11",
  "refpalette": "deceasedcraft:multi_verticalschool_18/multi_verticalschool_18_floor11_palette",
  "xsize": 16,
  "zsize": 16,
  "slices": [
    [
      "             a  ",
      " b    c      a  ",
      "             a  ",
      "             a  ",
      "             a  ",
      "             a  ",
      "     dc      a  ",
      "             a  ",
      "     dc      a  ",
      "             a  ",
      "     d       a  ",
      "             a  ",
      "             a  ",
      "             a  ",
      "             a  ",
      "             a  "
    ],
    [
      "             a  ",
      " b    c      a  ",
      "             a  ",
      "             a  ",
      "             a  ",
      "             a  ",
      "     dc      a  ",
      "             a  ",
      "     dc      a  ",
      "             a  ",
      "     d       a  ",
      "             a  ",
      "             a  ",
      "             a  ",
      "             a  ",
      "             a  "
    ],
    [
      "             a  ",
      " b   ef      a  ",
      "             a  ",
      "             a  ",
      "             a  ",
      "             a  ",
      "     ef      a  ",
      "             a  ",
      "     ef      a  ",
      "             a  ",
      "     ef      a  ",
      "             a  ",
      "             a  ",
      "             a  ",
      "             a  ",
      "             a  "
    ],
    [
      "             ag ",
      " b   hh      ag ",
      "             ag ",
      "            ~ag ",
      "             ag ",
      "             ag ",
      "     hh      ag ",
      "             ag ",
      "     hh      ag ",
      "             ag ",
      "     hh      ag ",
      "             ag ",
      "             ag ",
      "             ag ",
      "             ag ",
      "             ag "
    ],
    [
      "   ijjjjiiiiklm ",
      "no iiiiiiiiiklm ",
      "n iiiiiiiiiiklm ",
      " iiiiiiiiiiiklm ",
      "iiiiiiiiiiiiklm ",
      "iiiiiiiiiiiiklm ",
      "iiiiiiiiiiiiklm ",
      "iiiijjjjiiiiklm ",
      "iiiijiijiiiiklm ",
      "iiiijjjjiiiiklm ",
      "iiiiiiiiiiiiklm ",
      "iiiiiiiiiiiiklm ",
      "iiiiiiiiiiiiklm ",
      "iiiiiiiiiiiiklm ",
      "iiiiiiiiiiiiklm ",
      "iiiiiiiiiiiiklm "
    ],
    [
      "pplqrrrssssrtlu ",
      "wllrrrrssssrtlu ",
      "wlrrrrrssssrtlu ",
      "llrrrrrssssrtlu ",
      "rxrrrrrssssrtlu ",
      "rrrrrrrssssrtlu ",
      "xrrrrrrssssrtlu ",
      "xrxrrrrssssrtlu ",
      "rrrrrrrssssrtlu ",
      "xrrrrrrssssrtlu ",
      "rxrrrrrssssrtlu ",
      "rrrrrrrssssrtlu ",
      "rrrrrrssssrrtlu ",
      "rrrrrrssssrrtlu ",
      "xrrrrsssssrrtlu ",
      "rrrrsssssrrrtlu "
    ]
  ]
}