{
  "name": "multi_verticalschool_18_floor21",
  "refpalette": "deceasedcraft:multi_verticalschool_18/multi_verticalschool_18_floor21_palette",
  "xsize": 16,
  "zsize": 16,
  "slices": [
    [
      "  a             ",
      "  a             ",
      " ba             ",
      "  a             ",
      "  a             ",
      "  a             ",
      "  a             ",
      "  a             ",
      "  a             ",
      "  a             ",
      "  a             ",
      " ba             ",
      "  a             ",
      "  a             ",
      "  a             ",
      "  a             "
    ],
    [
      "  a             ",
      "  a             ",
      "  a             ",
      "  a             ",
      "  a             ",
      "  a             ",
      "  a             ",
      "  a             ",
      "  a             ",
      "  a             ",
      "  a             ",
      "  a             ",
      "  a             ",
      "  a             ",
      "  a             ",
      "  a             "
    ],
    [
      "ccad            ",
      "ccad            ",
      "ccad            ",
      "ccad            ",
      "ccad            ",
      "ccad            ",
      "ccad            ",
      "ccad            ",
      "ccad            ",
      "ccad            ",
      "ccad            ",
      "ccad            ",
      "ccad            ",
      "ccad            ",
      "ccad            ",
      "ccad            "
    ],
    [
      "eefg            ",
      "eefg            ",
      "eefg            ",
      "eefg            ",
      "eefg            ",
      "eefg            ",
      "eefg            ",
      "eefg            ",
      "eefg            ",
      "eefg            ",
      "eefg            ",
      "eefg            ",
      "eefg            ",
      "eefg            ",
      "eefg            ",
      "eefg            "
    ],
    [
      "ggfh            ",
      "ggfh            ",
      "ggfh            ",
      "ggfh            ",
      "ggfh            ",
      "ggfh            ",
      "ggfh            ",
      "ggfh            ",
      "ggfh            ",
      "ggfh            ",
      "ggfh            ",
      "ggfh            ",
      "ggfh            ",
      "ggfh            ",
      "ggfh            ",
      "ggfh            "
    ],
    [
      "                ",
      "                ",
      "                ",
      "                ",
      "                ",
      "                ",
      "                ",
      "                ",
      "                ",
      "                ",
      "                ",
      "                ",
      "                ",
      "                ",
      "                ",
      "                "
    ]
  ]
}