{
  "name": "multi_verticalschool_18_floor17",
  "refpalette": "deceasedcraft:multi_verticalschool_18/multi_verticalschool_18_floor17_palette",
  "xsize": 16,
  "zsize": 16,
  "slices": [
    [
      "                ",
      "                ",
      "                ",
      "                ",
      "                ",
      "                ",
      "                ",
      "                ",
      "                ",
      "                ",
      "                ",
      "                ",
      "                ",
      "                ",
      "                ",
      "                "
    ],
    [
      "                ",
      "                ",
      "                ",
      "                ",
      "                ",
      "                ",
      "                ",
      "                ",
      "                ",
      "                ",
      "                ",
      "                ",
      "                ",
      "                ",
      "                ",
      "                "
    ],
    [
      "ab c            ",
      "ab c            ",
      "ab c            ",
      "ab c            ",
      "ab c            ",
      "ab c            ",
      "ab c            ",
      "ab c            ",
      "ab c            ",
      "ab c            ",
      "ab c            ",
      "ab c            ",
      "ab c            ",
      "ab c            ",
      "ab c            ",
      "bb c            "
    ],
    [
      "ddef            ",
      "ddef            ",
      "ddef            ",
      "ddef            ",
      "ddef            ",
      "ddef            ",
      "ddef            ",
      "ddef            ",
      "ddef            ",
      "ddef            ",
      "ddef            ",
      "ddef            ",
      "ddef            ",
      "ddef            ",
      "ddef            ",
      "ddef            "
    ],
    [
      "ghei            ",
      "ghei            ",
      "gjei            ",
      "ghei            ",
      "ghei            ",
      "gjei            ",
      "ghei            ",
      "khei            ",
      "gjei            ",
      "ghei            ",
      "ghei            ",
      "gjei            ",
      "ghei            ",
      "khei            ",
      "gjei            ",
      "ghei            "
    ],
    [
      "  l             ",
      "  l             ",
      " ml             ",
      "  l             ",
      "  l             ",
      " ml             ",
      "  l             ",
      "  l             ",
      " ml             ",
      "  l             ",
      "  l             ",
      " ml             ",
      "  l             ",
      "  l             ",
      " ml             ",
      "  l             "
    ]
  ]
}