{
  "name": "multi_verticalschool_18_floor22",
  "refpalette": "deceasedcraft:multi_verticalschool_18/multi_verticalschool_18_floor22_palette",
  "xsize": 16,
  "zsize": 16,
  "slices": [
    [
      "                ",
      "                ",
      "                ",
      "                ",
      "                ",
      "                ",
      "                ",
      "                ",
      "                ",
      "                ",
      "                ",
      "                ",
      "                ",
      "                ",
      "                ",
      "                "
    ],
    [
      "abaac           ",
      "abaac           ",
      "abaac           ",
      "abaac           ",
      "abaac           ",
      "abaac           ",
      "abaac           ",
      "abaac           ",
      "abaac           ",
      "abaac           ",
      "abaac           ",
      "abaac           ",
      "abaac           ",
      "abaac           ",
      "abaac           ",
      "abaac           "
    ],
    [
      "dddde           ",
      "dddde           ",
      "dddde           ",
      "dddde           ",
      "dddde           ",
      "dddde           ",
      "dddde           ",
      "dddde           ",
      "dddde           ",
      "dddde           ",
      "dddde           ",
      "dddde           ",
      "dddde           ",
      "dddde           ",
      "dddde           ",
      "dddde           "
    ],
    [
      "   fe           ",
      "   fe           ",
      "   fe           ",
      "   fe           ",
      "   fe           ",
      "   fe           ",
      "   fe           ",
      "   fe           ",
      "   fe           ",
      "   fe           ",
      "   fe           ",
      "   fe           ",
      "   fe           ",
      "   fe           ",
      "   ge           ",
      "   fe           "
    ],
    [
      "   fe           ",
      "   fe           ",
      "   fe           ",
      "   fe           ",
      "   fe           ",
      "   fe           ",
      "   fe           ",
      "   fe           ",
      "   fe           ",
      "   fe           ",
      "   fe           ",
      "   fe           ",
      "   fe           ",
      "   fe           ",
      "   he           ",
      "   fe           "
    ],
    [
      "   fe           ",
      "   fe           ",
      "   fe           ",
      "   fe           ",
      "   fe           ",
      "   fe           ",
      "   fe           ",
      "   fe           ",
      "   fe           ",
      "   fe           ",
      "   fe           ",
      "   fe           ",
      "   fe           ",
      "   fe           ",
      "   ie           ",
      "   fe           "
    ]
  ]
}