{
  "name": "multi_verticalschool_18_floor26",
  "refpalette": "deceasedcraft:multi_verticalschool_18/multi_verticalschool_18_floor26_palette",
  "xsize": 16,
  "zsize": 16,
  "slices": [
    [
      "aabc            ",
      "aabc            ",
      "aabc            ",
      "aabc            ",
      "aabc            ",
      "aabc            ",
      "aabc            ",
      "aabc            ",
      "aabc            ",
      "aabc            ",
      "aabc            ",
      "aabc            ",
      "aabc            ",
      "aabc            ",
      "aabc            ",
      "aabc            "
    ],
    [
      "debf            ",
      "debf            ",
      "debf            ",
      "debf            ",
      "dgbf            ",
      "dgbf            ",
      "debf            ",
      "hebf            ",
      "d bf            ",
      "debf            ",
      "debf            ",
      "debf            ",
      "debf            ",
      "dgbf            ",
      "d bf            ",
      "hebf            "
    ],
    [
      "  i             ",
      "j i             ",
      "j i             ",
      "j i             ",
      "j i             ",
      "j i             ",
      "j i             ",
      "  i             ",
      "j i             ",
      "j i             ",
      "j i             ",
      "  i             ",
      "j i             ",
      "j i             ",
      "j i             ",
      "  i             "
    ],
    [
      "  i             ",
      "  i             ",
      "  i             ",
      "  i             ",
      "  i             ",
      "  i             ",
      "  i             ",
      "  i             ",
      "  i             ",
      "  i             ",
      "  i             ",
      "  i             ",
      "  i             ",
      "  i             ",
      "  i             ",
      "  i             "
    ],
    [
      "  i             ",
      "  i             ",
      "  i             ",
      "  i             ",
      "  i             ",
      "  i             ",
      "  i             ",
      "  i             ",
      "  i             ",
      "  i             ",
      "  i             ",
      "  i             ",
      "  i             ",
      "  i             ",
      "  i             ",
      "  i             "
    ],
    [
      "kkil            ",
      "kkil            ",
      "kkil            ",
      "kkil            ",
      "kkil            ",
      "kkil            ",
      "kkil            ",
      "kkil            ",
      "kkil            ",
      "kkil            ",
      "kkil            ",
      "kkil            ",
      "kkil            ",
      "kkil            ",
      "kkil            ",
      "kkil            "
    ]
  ]
}