{
  "name": "multi_verticalschool_18_floor23",
  "refpalette": "deceasedcraft:multi_verticalschool_18/multi_verticalschool_18_floor23_palette",
  "xsize": 16,
  "zsize": 16,
  "slices": [
    [
      "   ab           ",
      "   ab           ",
      "   ab           ",
      "   ab           ",
      "    b           ",
      "   ab           ",
      "   ab           ",
      "   ab           ",
      "   ab           ",
      "    b           ",
      "   ab           ",
      "   ab           ",
      "   ab           ",
      "   ab           ",
      "    b           ",
      "   ab           "
    ],
    [
      "ccdeb           ",
      "ccdeb           ",
      "ccdeb           ",
      "ccdeb           ",
      "ccdeb           ",
      "ccdeb           ",
      "ccdeb           ",
      "ccdeb           ",
      "ccdeb           ",
      "ccdeb           ",
      "ccdeb           ",
      "ccdeb           ",
      "ccdeb           ",
      "ccdeb           ",
      "ccdeb           ",
      "ccdeb           "
    ],
    [
      "bbfbb           ",
      "bbfbb           ",
      "bbfbb           ",
      "bbfbb           ",
      "bbfbb           ",
      "bbfbb           ",
      "bbfbb           ",
      "bbfbb           ",
      "bbfbb           ",
      "bbfbb           ",
      "bbfbb           ",
      "bbfbb           ",
      "bbfbb           ",
      "bbfbb           ",
      "bbfbb           ",
      "bbfbb           "
    ],
    [
      "g   g           ",
      "g   g           ",
      "g   g           ",
      "g   g           ",
      "g   g           ",
      "g   g           ",
      "g   g           ",
      "g   g           ",
      "g   g           ",
      "g   g           ",
      "g   g           ",
      "g   g           ",
      "g   g           ",
      "g   g           ",
      "g   g           ",
      "g   g           "
    ],
    [
      "                ",
      "                ",
      "                ",
      "                ",
      "                ",
      "                ",
      "                ",
      "                ",
      "                ",
      "                ",
      "                ",
      "                ",
      "                ",
      "                ",
      "                ",
      "                "
    ],
    [
      "                ",
      "                ",
      "                ",
      "                ",
      "                ",
      "                ",
      "                ",
      "                ",
      "                ",
      "                ",
      "                ",
      "                ",
      "                ",
      "                ",
      "                ",
      "                "
    ]
  ]
}