{
  "name": "multi_verticalschool_18_floor7",
  "refpalette": "deceasedcraft:multi_verticalschool_18/multi_verticalschool_18_floor7_palette",
  "xsize": 16,
  "zsize": 16,
  "slices": [
    [
      "                ",
      "                ",
      "                ",
      "                ",
      "                ",
      "                ",
      "                ",
      "                ",
      "                ",
      "                ",
      "                ",
      "                ",
      "                ",
      "                ",
      "                ",
      "                "
    ],
    [
      "                ",
      "                ",
      "                ",
      "                ",
      "                ",
      "                ",
      "                ",
      "                ",
      "                ",
      "                ",
      "                ",
      "                ",
      "                ",
      "                ",
      "                ",
      "                "
    ],
    [
      "aaaaaaba c      ",
      "aaaaaaba c      ",
      "aaaaaaba c      ",
      "aaaaaaba c      ",
      "aaaaaaba c      ",
      "aaaaaaba c      ",
      "aaaaaaba c      ",
      "aaaaaaba c      ",
      "aaaaaaba c      ",
      "aaaaaaba c      ",
      "aaaaaaba c      ",
      "aaaaaaba c      ",
      "aaaaaaba c      ",
      "aaaaaaba c      ",
      "aaaaaaba c      ",
      "aaaaabaa c      "
    ],
    [
      "dddddddddef     ",
      "dddddddddef     ",
      "ddddddgddef     ",
      "ddddddgddef     ",
      "ddddddgddef     ",
      "ddddddgddef     ",
      "dddddddddef     ",
      "dddddddddef     ",
      "hhhhhhhhdef     ",
      "iiiiiiiidef     ",
      "iiiiiiiidef     ",
      "iiiiiiiidef     ",
      "iiiiiiiidef     ",
      "iiiiiiiidef     ",
      "iiiiiiiidef     ",
      "iiiiiiiidef     "
    ],
    [
      "j       kef     ",
      "l       mef     ",
      "no    p qef     ",
      "n     p ref     ",
      "s     p ref     ",
      "tu    p wef     ",
      "tu      mef     ",
      "tu    x !ef     ",
      "hhhyAhhhhef     ",
      "         ef     ",
      "         ef     ",
      "         ef     ",
      "         ef     ",
      "         ef     ",
      "         ef     ",
      "         ef     "
    ],
    [
      "B       Cef     ",
      "        Def     ",
      "E        Ff     ",
      "         Ff     ",
      "         Ff     ",
      "I        Ff     ",
      "        Jef     ",
      "        Kef     ",
      "hhhLMhhhhef     ",
      "  N  N   ef     ",
      "         ef     ",
      "         Ff     ",
      "         Ff     ",
      "         Ff     ",
      "         Ff     ",
      "         ef     "
    ]
  ]
}