{
  "name": "multi_verticalschool_18_floor27",
  "refpalette": "deceasedcraft:multi_verticalschool_18/multi_verticalschool_18_floor27_palette",
  "xsize": 16,
  "zsize": 16,
  "slices": [
    [
      "aabc            ",
      "aabc            ",
      "aabc            ",
      "aabc            ",
      "aabc            ",
      "aabc            ",
      "aabc            ",
      "aabc            ",
      "aabc            ",
      "aabc            ",
      "aabc            ",
      "aabc            ",
      "aabc            ",
      "aabc            ",
      "aabc            ",
      "aabc            "
    ],
    [
      "debf            ",
      "debf            ",
      "dgbf            ",
      "debf            ",
      "dgbf            ",
      "hebf            ",
      "d bf            ",
      "debf            ",
      "debf            ",
      "debf            ",
      "debf            ",
      "dgbf            ",
      "d bf            ",
      "hebf            ",
      "debf            ",
      "dgbf            "
    ],
    [
      "i j             ",
      "i j             ",
      "  j             ",
      "i j             ",
      "i j             ",
      "  j             ",
      "i j             ",
      "i j             ",
      "  j             ",
      "i j             ",
      "i j             ",
      "i j             ",
      "i j             ",
      "  j             ",
      "i j             ",
      "  j             "
    ],
    [
      "  j             ",
      "  j             ",
      "  j             ",
      "  j             ",
      "  j             ",
      "  j             ",
      "  j             ",
      "  j             ",
      "  j             ",
      "  j             ",
      "  j             ",
      "  j             ",
      "  j             ",
      "  j             ",
      "  j             ",
      "  j             "
    ],
    [
      "  j             ",
      "  j             ",
      "  j             ",
      "  j             ",
      "  j             ",
      "  j             ",
      "  j             ",
      "  j             ",
      "  j             ",
      "  j             ",
      "  j             ",
      "  j             ",
      "  j             ",
      "  j             ",
      "  j             ",
      "  j             "
    ],
    [
      "kkjl            ",
      "kkjl            ",
      "kkjl            ",
      "kkjl            ",
      "kkjl            ",
      "kkjl            ",
      "kkjl            ",
      "kkjl            ",
      "kkjl            ",
      "kkjl            ",
      "kkjl            ",
      "kkjl            ",
      "kkjl            ",
      "kkjl            ",
      "kkjl            ",
      "kkjl            "
    ]
  ]
}