{
  "name": "multi_verticalschool_18_base1",
  "refpalette": "deceasedcraft:multi_verticalschool_18/multi_verticalschool_18_base1_palette",
  "xsize": 16,
  "zsize": 16,
  "slices": [
    [
      "            a   ",
      "           bcdee",
      "           bf gh",
      "           bi  j",
      "           b  gh",
      "           bceee",
      "            k   ",
      "                ",
      "                ",
      "                ",
      "                ",
      "                ",
      "                ",
      "                ",
      "                ",
      "            a   "
    ],
    [
      "            a   ",
      "           bclmn",
      "           b    ",
      "           b    ",
      "           b    ",
      "           bcnnn",
      "            o   ",
      "                ",
      "                ",
      "                ",
      "                ",
      "                ",
      "                ",
      "                ",
      "                ",
      "            a   "
    ],
    [
      "                ",
      "            pqqq",
      "            rsss",
      "            rs t",
      "            rsss",
      "            pqqq",
      "                ",
      "                ",
      "                ",
      "                ",
      "                ",
      "                ",
      "                ",
      "                ",
      "                ",
      "                "
    ],
    [
      "                ",
      "                ",
      "                ",
      "              u ",
      "                ",
      "                ",
      "                ",
      "                ",
      "                ",
      "                ",
      "                ",
      "                ",
      "                ",
      "                ",
      "                ",
      "                "
    ],
    [
      "                ",
      "                ",
      "                ",
      "                ",
      "                ",
      "                ",
      "                ",
      "                ",
      "                ",
      "                ",
      "                ",
      "                ",
      "                ",
      "                ",
      "                ",
      "                "
    ],
    [
      "wwxxwwwwwwwwwwww",
      "wwwwwwwwwwwwwwww",
      "wwwwwwwwwwwwwwww",
      "wwwwwyywwwwwwwyy",
      "wwwwwwwwwwwwwwww",
      "wwwwwwwwwwwwwwww",
      "wwwwwwwwwwwwwwww",
      "wwwwwwwwwwwwwwww",
      "wwwwwwwwwwwwwwww",
      "wwwwwwwwwwwwwwww",
      "wwwwwyywwwwwwwyy",
      "wwwwwwwwwwwwwwww",
      "wwwwwwwwwwwwwwww",
      "wwwwwwwwwwwwwwww",
      "wwwwwwwwwwwwwwww",
      "wwwwwwwwwwwwwwww"
    ]
  ]
}