{
  "name": "multi_verticalschool_18_floor18",
  "refpalette": "deceasedcraft:multi_verticalschool_18/multi_verticalschool_18_floor18_palette",
  "xsize": 16,
  "zsize": 16,
  "slices": [
    [
      "  a             ",
      "  a             ",
      " ba             ",
      "  a             ",
      "  a             ",
      "  a             ",
      "  a             ",
      "  a             ",
      "  a             ",
      "  a             ",
      "  a             ",
      " ba             ",
      "  a             ",
      "  a             ",
      " ba             ",
      "  a             "
    ],
    [
      "  a             ",
      "  a             ",
      "  a             ",
      "  a             ",
      "  a             ",
      "  a             ",
      "  a             ",
      "  a             ",
      "  a             ",
      "  a             ",
      "  a             ",
      "  a             ",
      "  a             ",
      "  a             ",
      "  a             ",
      "  a             "
    ],
    [
      "ccad            ",
      "ccad            ",
      "ccad            ",
      "ccad            ",
      "ccad            ",
      "ccad            ",
      "ccad            ",
      "ccad            ",
      "ccad            ",
      "ccad            ",
      "ccad            ",
      "ccad            ",
      "ccad            ",
      "ccad            ",
      "ccad            ",
      "ccad            "
    ],
    [
      "eefg            ",
      "eefg            ",
      "eefg            ",
      "eefg            ",
      "eefg            ",
      "eefg            ",
      "eefg            ",
      "eefg            ",
      "eefg            ",
      "eefg            ",
      "eefg            ",
      "eefg            ",
      "eefg            ",
      "eefg            ",
      "eefg            ",
      "eefg            "
    ],
    [
      "hifj            ",
      "hifj            ",
      "hkfj            ",
      "lifj            ",
      "hifj            ",
      " mfj            ",
      "  fj            ",
      "l fj            ",
      "hkfj            ",
      "hifj            ",
      "hifj            ",
      "hkfj            ",
      "lifj            ",
      "hifj            ",
      "hkfj            ",
      "hifj            "
    ],
    [
      "  a             ",
      "  a             ",
      " na             ",
      "  a             ",
      "  a             ",
      " oa             ",
      "  a             ",
      "                ",
      "  p             ",
      "  a             ",
      "  a             ",
      " na             ",
      "  a             ",
      "  a             ",
      " na             ",
      "  a             "
    ]
  ]
}