{
  "name": "building_apartmentsmalld_top_270",
  "refpalette": "deceasedcraft:building_apartmentsmalld/building_apartmentsmalld_top_palette_270",
  "xsize": 16,
  "zsize": 16,
  "slices": [
    [
      "                ",
      "  bbbbbbbbbbbb  ",
      " jcccccccccccca ",
      " jceeeeeeeeeeca ",
      " jceeeceeeeeeca ",
      " jccccceeeeeeca ",
      "  i gfeeeeeeeca ",
      "  i hfceeeeeeca ",
      "  i hfceeeeeeca ",
      "  i hfceeeeeeca ",
      " jccceceeeeeeca ",
      " jceeeceeeeeeca ",
      " jceeeceeeeeeca ",
      " jcccccccccccca ",
      "  dddddddddddd  ",
      "                "
    ],
    [
      "                ",
      " kkkkkkkkkkkkkk ",
      " kcccccccccccck ",
      " kcxt ql     ck ",
      " kcttlc      ck ",
      " kccccc   mm ck ",
      "  c   r   mm ck ",
      "  c u c   ol ck ",
      "  c w c   o  ck ",
      "  c w c   nmlck ",
      " kcccsc   pn ck ",
      " kc!l c   l  ck ",
      " kcy lcl   l ck ",
      " kcccccccccccck ",
      " kkkkkkkkkkkkkk ",
      "                "
    ],
    [
      "                ",
      "                ",
      "  ccBBFccDBBcc  ",
      "  cOO I      c  ",
      "  cOO cE     c  ",
      "  ccccc   mm A  ",
      "  B   J   mm B  ",
      "  B  Lc      B  ",
      "  C   c      B  ",
      "  c P c   pn B  ",
      "  cccMc   pp C  ",
      "  cQ  c   o  c  ",
      "  cQ NKoooo  c  ",
      "  ccBBFccDBBcc  ",
      "                ",
      "                "
    ],
    [
      "                ",
      "                ",
      "  cccccccccccc  ",
      "  cTUTcT     c  ",
      "  cTUTcT     c  ",
      "  cccccT  RR c  ",
      "  cTUTcT  SR c  ",
      "  cTUTcT     c  ",
      "  cTUTcT     c  ",
      "  cTUTcT   S c  ",
      "  cccccT     c  ",
      "  cTUTcT     c  ",
      "  cTUTcT     c  ",
      "  cccccccccccc  ",
      "                ",
      "                "
    ],
    [
      "                ",
      "                ",
      "  VVVVVVVVVVVV  ",
      "  V   W      V  ",
      "  V   W      V  ",
      "  VWWWW      V  ",
      "  V   W      V  ",
      "  V   W      V  ",
      "  V   W      V  ",
      "  V   W      V  ",
      "  VWWWW      V  ",
      "  V   W      V  ",
      "  V   W      V  ",
      "  VVVVVVVVVVVV  ",
      "                ",
      "                "
    ],
    [
      "                ",
      "                ",
      "                ",
      "                ",
      "                ",
      "                ",
      "                ",
      "                ",
      "                ",
      "                ",
      "                ",
      "                ",
      "                ",
      "                ",
      "                ",
      "                "
    ]
  ]
}