{
  "name": "building_apartmentsmalld_top",
  "refpalette": "deceasedcraft:building_apartmentsmalld/building_apartmentsmalld_top_palette",
  "xsize": 16,
  "zsize": 16,
  "slices": [
    [
      "                ",
      "  aaaaaaaaaaaa  ",
      " bccccccccccccd ",
      " bceeeeeeeeeecd ",
      " bceeeeeeeeeecd ",
      " bceeeeeeeeeecd ",
      " bceeeeeeeeeecd ",
      " bceeeeeeeeeecd ",
      " bceeeeeeeeeecd ",
      " bceccecccccccd ",
      " bceecffffeeecd ",
      " bceecghhhceecd ",
      " bceec    ceecd ",
      " bcccciiiiccccd ",
      "  jjjj    jjjj  ",
      "                "
    ],
    [
      "                ",
      " kkkkkkkkkkkkkk ",
      " kcccccccccccck ",
      " kc      l   ck ",
      " kc  mml mn lck ",
      " kc  mmoonpl ck ",
      " kc          ck ",
      " kc          ck ",
      " kcl        lck ",
      " kcqccrccccccck ",
      " kc lc    s lck ",
      " kcttc uwwcl ck ",
      " kcxtc    c!yck ",
      " kcccccccccccck ",
      " kkkkk    kkkkk ",
      "                "
    ],
    [
      "                ",
      "                ",
      "  cccABBBBCccc  ",
      "  c          c  ",
      "  B  mm  np  B  ",
      "  B  mm  ppooB  ",
      "  D         oD  ",
      "  c         oc  ",
      "  c E       oc  ",
      "  FIccJcccccKF  ",
      "  B  c L  M NB  ",
      "  BOOc   Pc  B  ",
      "  cOOc    cQQc  ",
      "  ccccBBCccccc  ",
      "                ",
      "                "
    ],
    [
      "                ",
      "                ",
      "  cccccccccccc  ",
      "  c          c  ",
      "  c  RR  S   c  ",
      "  c  RS      c  ",
      "  c          c  ",
      "  c          c  ",
      "  cTTTTTTTTTTc  ",
      "  cccccccccccc  ",
      "  cTTcTTTTcTTc  ",
      "  cUUcUUUUcUUc  ",
      "  cTTcTTTTcTTc  ",
      "  cccccccccccc  ",
      "                ",
      "                "
    ],
    [
      "                ",
      "                ",
      "  VVVVVVVVVVVV  ",
      "  V          V  ",
      "  V          V  ",
      "  V          V  ",
      "  V          V  ",
      "  V          V  ",
      "  V          V  ",
      "  VWWWWWWWWWWV  ",
      "  V  W    W  V  ",
      "  V  W    W  V  ",
      "  V  W    W  V  ",
      "  VVVVVVVVVVVV  ",
      "                ",
      "                "
    ],
    [
      "                ",
      "                ",
      "                ",
      "                ",
      "                ",
      "                ",
      "                ",
      "                ",
      "                ",
      "                ",
      "                ",
      "                ",
      "                ",
      "                ",
      "                ",
      "                "
    ]
  ]
}