{
  "name": "building_apartmentsmalld_floor3_270",
  "refpalette": "deceasedcraft:building_apartmentsmalld/building_apartmentsmalld_floor3_palette_270",
  "xsize": 16,
  "zsize": 16,
  "slices": [
    [
      "                ",
      "  bbbbbbbbbbbb  ",
      " lddddddddcccca ",
      " lddddddddcccca ",
      " lddddddddcccca ",
      " lffffdddddddda ",
      "  k hgfddddddda ",
      "  k igfddddddda ",
      "  k igdddddddda ",
      "  k jgfddddddda ",
      " lffffdddddddda ",
      " ldddddddddddda ",
      " ldddddddddddda ",
      " ldddddddddddda ",
      "  eeeeeeeeeeee  ",
      "                "
    ],
    [
      "                ",
      " mmmmmmmmmmmmmm ",
      " m       mFBtnm ",
      " m VV P  L  uom ",
      " mTWWTP  m    m ",
      " mffffP  mmmwmm ",
      "  f   fmNmIC pm ",
      "  f X f  mJ  qm ",
      "  f X Q  m  xqm ",
      "  fjY f  M   rm ",
      " mffffR  mmmmmm ",
      " m0      Dyyy m ",
      " m1   SO   D  m ",
      " m2UZUSO  KEAsm ",
      " mmmmmmmmmmmmmm ",
      "                "
    ],
    [
      "                ",
      " 4333mm33mm33mm ",
      " 5       mD  63 ",
      " 5    }  )    3 ",
      " m/  '} [m ^  3 ",
      " mffff}{ mmm%m4 ",
      "  `   fm]m & 73 ",
      "  `  <f  m   85 ",
      "  \u0370.  |  m(  95 ",
      "  fY  f  + * #3 ",
      " mffff;  mm!mm4 ",
      " m\u0371  >   - D  5 ",
      " 3\u0372           5 ",
      " 3 ? ,:      $3 ",
      " 433333333333mm ",
      "                "
    ],
    [
      "                ",
      " 4355mm55mm55mm ",
      " 5       m   \u03733 ",
      " 5       \u0375    5 ",
      " m    \u037a  m    5 ",
      " mffff\u037b  mmm\u0374m4 ",
      "  f   fm\u0377m    3 ",
      "  f.  f  m    5 ",
      "  f\u037d  a  m    5 ",
      "  f   f  \u0376    3 ",
      " mffff\u037c  mmmmm4 ",
      " m            5 ",
      " 3            5 ",
      " 3            3 ",
      " 433535555353mm ",
      "                "
    ],
    [
      "                ",
      " 4333mm33mm33mm ",
      " 5       m!   3 ",
      " 5       mD   3 ",
      " m       m    3 ",
      " mffff   mmmmm4 ",
      "  f.  fmmm    3 ",
      "  f\u037d  f  m    5 ",
      "  \u0384   f  m    5 ",
      "  \u0384   f  m    3 ",
      " mffff   mmmmm4 ",
      " m            5 ",
      " 3  \u037f      \u037e  5 ",
      " 3            3 ",
      " 433333333333mm ",
      "                "
    ],
    [
      "                ",
      " mmmmmmmmmmmmmm ",
      " m\u0385\u0385\u0385\u0385\u0385\u0385\u0385\u0385\u0385\u0385\u0385\u0385m ",
      " m\u0385\u0385\u0385\u0385\u0385\u0385\u0385\u0385\u0385\u0385\u0385\u0385m ",
      " m\u0385\u0385\u0385\u0385\u0385\u0385\u0385\u0385\u0385\u0385\u0385\u0385m ",
      " mffff\u0385\u0385\u0385\u0385\u0385\u0385\u0385\u0385m ",
      "  f\u037d\u0386 f\u0385\u0385\u0385\u0385\u0385\u0385\u0385m ",
      "  f   f\u0385\u0385\u0385\u0385\u0385\u0385\u0385m ",
      "  f   f\u0385\u0385\u0385\u0385\u0385\u0385\u0385m ",
      "  f   f\u0385\u0385\u0385\u0385\u0385\u0385\u0385m ",
      " mffff\u0385\u0385\u0385\u0385\u0385\u0385\u0385\u0385m ",
      " m\u0385\u0385\u0385\u0385\u0385\u0385\u0385\u0385\u0385\u0385\u0385\u0385m ",
      " m\u0385\u0385\u0385\u0385\u0385\u0385\u0385\u0385\u0385\u0385\u0385\u0385m ",
      " m\u0385\u0385\u0385\u0385\u0385\u0385\u0385\u0385\u0385\u0385\u0385\u0385m ",
      " mmmmmmmmmmmmmm ",
      "                "
    ]
  ]
}