{
  "name": "building_apartmentsmalld_floor1",
  "refpalette": "deceasedcraft:building_apartmentsmalld/building_apartmentsmalld_floor1_palette",
  "xsize": 16,
  "zsize": 16,
  "slices": [
    [
      "                ",
      "  aaaaaaaaaaaa  ",
      " bcccddddddddde ",
      " bcccddddddddde ",
      " bcccddddddddde ",
      " bcccddddddddde ",
      " bdddddddddddde ",
      " bdddddddddddde ",
      " bdddddddddddde ",
      " bddddffdfdddde ",
      " bdddfggggfddde ",
      " bdddfhiijfddde ",
      " bdddf    fddde ",
      " bdddfkkkkfddde ",
      "  llll    llll  ",
      "                "
    ],
    [
      "                ",
      " mmmmmmmmmmmmmm ",
      " mnopmqrrsm  tm ",
      " muw x  y mA Bm ",
      " mC  mD   mA Em ",
      " mF  mIJ  mA Km ",
      " mmLmmmmmMm   m ",
      " m    N       m ",
      " m    m     OOm ",
      " m !PPffQfR SSm ",
      " m  Tf    f  Um ",
      " m VWf XYZf  0m ",
      " m VWf   jf  Um ",
      " m  Tffffff123m ",
      " mmmmm    mmmmm ",
      "                "
    ],
    [
      "                ",
      " m444546645664m ",
      " m7  m  89m  #m ",
      " 4   $    m   4 ",
      " 4  %m^  &*   4 ",
      " m  (m  ) m   4 ",
      " mm+mmmmm-m[  4 ",
      " 4  ] {       4 ",
      " 4   }m       4 ",
      " m |||ff;f: ' 4 ",
      " m  <f >  f, .4 ",
      " 4   f    f   4 ",
      " 4   f  ?Zf  /4 ",
      " 4  <f``\u0370ff\u0371\u0372\u03734 ",
      " 566mm    mm445 ",
      "                "
    ],
    [
      "                ",
      " m466546645664m ",
      " m\u0374  m    m   m ",
      " 6   \u0375    m   4 ",
      " 6   m    m   6 ",
      " m\u0376  m    m   4 ",
      " mm\u0377mmmmm\u037am   6 ",
      " 6    \u037b       6 ",
      " 6    m       6 ",
      " m \u037c\u037d ffaf\u037e   6 ",
      " m   f    f   4 ",
      " 6   f    f   6 ",
      " 6   f ?\u037f f   4 ",
      " 4   ffffff\u0384  4 ",
      " 566mm    mm445 ",
      "                "
    ],
    [
      "                ",
      " m444546645664m ",
      " m   m    m   m ",
      " 4   m    m   4 ",
      " 4   m    m \u0385 4 ",
      " m   m    m   4 ",
      " mmmmmmmmmm   4 ",
      " 4    m       4 ",
      " 4    m       4 ",
      " m    ffff    4 ",
      " m   f    f   4 ",
      " 4   f    f \u0386 4 ",
      " 4   f?\u037f  f   4 ",
      " 4   fff\u0387\u0387f   4 ",
      " 566mm    mm445 ",
      "                "
    ],
    [
      "                ",
      " mmmmmmmmmmmmmm ",
      " m\u0388\u0388\u0388\u0388\u0388\u0388\u0388\u0388\u0388\u0388\u0388\u0388m ",
      " m\u0388\u0388\u0388\u0388\u0388\u0388\u0388\u0388\u0388\u0388\u0388\u0388m ",
      " m\u0388\u0388\u0388\u0388\u0388\u0388\u0388\u0388\u0388\u0388\u0388\u0388m ",
      " m\u0388\u0388\u0388\u0388\u0388\u0388\u0388\u0388\u0388\u0388\u0388\u0388m ",
      " m\u0388\u0388\u0388\u0388\u0388\u0388\u0388\u0388\u0388\u0388\u0388\u0388m ",
      " m\u0388\u0388\u0388\u0388\u0388\u0388\u0388\u0388\u0388\u0388\u0388\u0388m ",
      " m\u0388\u0388\u0388\u0388\u0388\u0388\u0388\u0388\u0388\u0388\u0388\u0388m ",
      " m\u0388\u0388\u0388\u0388ffff\u0388\u0388\u0388\u0388m ",
      " m\u0388\u0388\u0388f    f\u0388\u0388\u0388m ",
      " m\u0388\u0388\u0388f\u0389   f\u0388\u0388\u0388m ",
      " m\u0388\u0388\u0388f\u037f   f\u0388\u0388\u0388m ",
      " m\u0388\u0388\u0388ffffff\u0388\u0388\u0388m ",
      " mmmmm    mmmmm ",
      "                "
    ]
  ]
}