{
  "name": "building_apartmentsmalld_floor2_90",
  "refpalette": "deceasedcraft:building_apartmentsmalld/building_apartmentsmalld_floor2_palette_90",
  "xsize": 16,
  "zsize": 16,
  "slices": [
    [
      "                ",
      "  eeeeeeeeeeee  ",
      " addddddddddddl ",
      " addddddddddddl ",
      " addddddddddddl ",
      " addddddddffffl ",
      " adddddddfgj k  ",
      " addddddddgi k  ",
      " adddddddfgi k  ",
      " adddddddfgh k  ",
      " addddddddffffl ",
      " accccddddddddl ",
      " accccddddddddl ",
      " accccddddddddl ",
      "  bbbbbbbbbbbb  ",
      "                "
    ],
    [
      "                ",
      " mmmmmmmmmmmmmm ",
      " msyCI  MQSYS1m ",
      " m     M Q   0m ",
      " m xxx       Zm ",
      " mmmmmm  Pffffm ",
      " mrw  K  f Xjf  ",
      " mq   m  O W f  ",
      " mq  Fm  f V f  ",
      " mp BEmLmf   f  ",
      " mmummm  Nffffm ",
      " m    m  NRUURm ",
      " mo   J  N TT m ",
      " mntADm       m ",
      " mmmmmmmmmmmmmm ",
      "                "
    ],
    [
      "                ",
      " mm222222222223 ",
      " 29       > .\u03712 ",
      " 4           \u03702 ",
      " 4    [   [  `m ",
      " 3mm&mm  :ffffm ",
      " 28 ^ -  f  Xf  ",
      " 47  )m  ;  ,/  ",
      " 4    m  f<  ?  ",
      " 26 % m{mf   ?  ",
      " 3m#mmm }|ffffm ",
      " 2  $(m] |'  %m ",
      " 2    +  |    4 ",
      " 25  *m       4 ",
      " mm22mm22mm2223 ",
      "                "
    ],
    [
      "                ",
      " mm242444424223 ",
      " 2            2 ",
      " 4            2 ",
      " 4            m ",
      " 3mmmmm  \u037cffffm ",
      " 2    \u0376  f   f  ",
      " 4    m  a  \u037df  ",
      " 4    m  f  ,f  ",
      " 2    m\u0377mf   f  ",
      " 3m\u0373mmm  \u037bffffm ",
      " 4    m  \u037a    m ",
      " 4    \u0375       4 ",
      " 2\u0372  \u0374m       4 ",
      " mm44mm44mm4423 ",
      "                "
    ],
    [
      "                ",
      " mm222222222223 ",
      " 2            2 ",
      " 4  \u037e      \u037f  2 ",
      " 4       \u037c    m ",
      " 3mmmmm  !ffffm ",
      " 2    m \u037cf   \u0384  ",
      " 4    m  f   \u0384  ",
      " 4    m  f  \u037df  ",
      " 2    mmmf  ,f  ",
      " 3mmmmm   ffffm ",
      " 2    m       m ",
      " 2    m       4 ",
      " 2    m       4 ",
      " mm22mm22mm2223 ",
      "                "
    ],
    [
      "                ",
      " mmmmmmmmmmmmmm ",
      " m\u0385\u0385\u0385\u0385\u0385\u0385\u0385\u0385\u0385\u0385\u0385\u0385m ",
      " m\u0385\u0385\u0385\u0385\u0385\u0385\u0385\u0385\u0385\u0385\u0385\u0385m ",
      " m\u0385\u0385\u0385\u0385\u0385\u0385\u0385\u0385\u0385\u0385\u0385\u0385m ",
      " m\u0385\u0385\u0385\u0385\u0385\u0385\u0385\u0385ffffm ",
      " m\u0385\u0385\u0385\u0385\u0385\u0385\u0385f   f  ",
      " m\u0385\u0385\u0385\u0385\u0385\u0385\u0385f   f  ",
      " m\u0385\u0385\u0385\u0385\u0385\u0385\u0385f   f  ",
      " m\u0385\u0385\u0385\u0385\u0385\u0385\u0385f \u0386\u037df  ",
      " m\u0385\u0385\u0385\u0385\u0385\u0385\u0385\u0385ffffm ",
      " m\u0385\u0385\u0385\u0385\u0385\u0385\u0385\u0385\u0385\u0385\u0385\u0385m ",
      " m\u0385\u0385\u0385\u0385\u0385\u0385\u0385\u0385\u0385\u0385\u0385\u0385m ",
      " m\u0385\u0385\u0385\u0385\u0385\u0385\u0385\u0385\u0385\u0385\u0385\u0385m ",
      " mmmmmmmmmmmmmm ",
      "                "
    ]
  ]
}