{
  "name": "building_apartmentsmalld_top_90",
  "refpalette": "deceasedcraft:building_apartmentsmalld/building_apartmentsmalld_top_palette_90",
  "xsize": 16,
  "zsize": 16,
  "slices": [
    [
      "                ",
      "  dddddddddddd  ",
      " accccccccccccj ",
      " aceeeeeeceeecj ",
      " aceeeeeeceeecj ",
      " aceeeeeececccj ",
      " aceeeeeecfh i  ",
      " aceeeeeecfh i  ",
      " aceeeeeecfh i  ",
      " aceeeeeeefg i  ",
      " aceeeeeecccccj ",
      " aceeeeeeceeecj ",
      " aceeeeeeeeeecj ",
      " accccccccccccj ",
      "  bbbbbbbbbbbb  ",
      "                "
    ],
    [
      "                ",
      " kkkkkkkkkkkkkk ",
      " kcccccccccccck ",
      " kc l   lcl yck ",
      " kc  l   c l!ck ",
      " kc np   csccck ",
      " kclmn   c w c  ",
      " kc  o   c w c  ",
      " kc lo   c u c  ",
      " kc mm   r   c  ",
      " kc mm   ccccck ",
      " kc      clttck ",
      " kc     lq txck ",
      " kcccccccccccck ",
      " kkkkkkkkkkkkkk ",
      "                "
    ],
    [
      "                ",
      "                ",
      "  ccBBDccFBBcc  ",
      "  c  ooooKN Qc  ",
      "  c  o   c  Qc  ",
      "  C pp   cMccc  ",
      "  B np   c P c  ",
      "  B      c   C  ",
      "  B      cL  B  ",
      "  B mm   J   B  ",
      "  A mm   ccccc  ",
      "  c     Ec OOc  ",
      "  c      I OOc  ",
      "  ccBBDccFBBcc  ",
      "                ",
      "                "
    ],
    [
      "                ",
      "                ",
      "  cccccccccccc  ",
      "  c     TcTUTc  ",
      "  c     TcTUTc  ",
      "  c     Tccccc  ",
      "  c S   TcTUTc  ",
      "  c     TcTUTc  ",
      "  c     TcTUTc  ",
      "  c RS  TcTUTc  ",
      "  c RR  Tccccc  ",
      "  c     TcTUTc  ",
      "  c     TcTUTc  ",
      "  cccccccccccc  ",
      "                ",
      "                "
    ],
    [
      "                ",
      "                ",
      "  VVVVVVVVVVVV  ",
      "  V      W   V  ",
      "  V      W   V  ",
      "  V      WWWWV  ",
      "  V      W   V  ",
      "  V      W   V  ",
      "  V      W   V  ",
      "  V      W   V  ",
      "  V      WWWWV  ",
      "  V      W   V  ",
      "  V      W   V  ",
      "  VVVVVVVVVVVV  ",
      "                ",
      "                "
    ],
    [
      "                ",
      "                ",
      "                ",
      "                ",
      "                ",
      "                ",
      "                ",
      "                ",
      "                ",
      "                ",
      "                ",
      "                ",
      "                ",
      "                ",
      "                ",
      "                "
    ]
  ]
}