{
  "name": "building_apartmentsmalld_top_180",
  "refpalette": "deceasedcraft:building_apartmentsmalld/building_apartmentsmalld_top_palette_180",
  "xsize": 16,
  "zsize": 16,
  "slices": [
    [
      "                ",
      "  jjjj    jjjj  ",
      " dcccciiiiccccb ",
      " dceec    ceecb ",
      " dceechhhgceecb ",
      " dceeeffffceecb ",
      " dccccccceccecb ",
      " dceeeeeeeeeecb ",
      " dceeeeeeeeeecb ",
      " dceeeeeeeeeecb ",
      " dceeeeeeeeeecb ",
      " dceeeeeeeeeecb ",
      " dceeeeeeeeeecb ",
      " dccccccccccccb ",
      "  aaaaaaaaaaaa  ",
      "                "
    ],
    [
      "                ",
      " kkkkk    kkkkk ",
      " kcccccccccccck ",
      " kcy!c    ctxck ",
      " kc lcwwu cttck ",
      " kcl s    cl ck ",
      " kcccccccrccqck ",
      " kcl        lck ",
      " kc          ck ",
      " kc          ck ",
      " kc lpnoomm  ck ",
      " kcl nm lmm  ck ",
      " kc   l      ck ",
      " kcccccccccccck ",
      " kkkkkkkkkkkkkk ",
      "                "
    ],
    [
      "                ",
      "                ",
      "  cccccCBBcccc  ",
      "  cQQc    cOOc  ",
      "  B  cP   cOOB  ",
      "  BN M  L c  B  ",
      "  FKcccccJccIF  ",
      "  co       E c  ",
      "  co         c  ",
      "  Do         D  ",
      "  Boopp  mm  B  ",
      "  B  pn  mm  B  ",
      "  c          c  ",
      "  cccCBBBBAccc  ",
      "                ",
      "                "
    ],
    [
      "                ",
      "                ",
      "  cccccccccccc  ",
      "  cTTcTTTTcTTc  ",
      "  cUUcUUUUcUUc  ",
      "  cTTcTTTTcTTc  ",
      "  cccccccccccc  ",
      "  cTTTTTTTTTTc  ",
      "  c          c  ",
      "  c          c  ",
      "  c      SR  c  ",
      "  c   S  RR  c  ",
      "  c          c  ",
      "  cccccccccccc  ",
      "                ",
      "                "
    ],
    [
      "                ",
      "                ",
      "  VVVVVVVVVVVV  ",
      "  V  W    W  V  ",
      "  V  W    W  V  ",
      "  V  W    W  V  ",
      "  VWWWWWWWWWWV  ",
      "  V          V  ",
      "  V          V  ",
      "  V          V  ",
      "  V          V  ",
      "  V          V  ",
      "  V          V  ",
      "  VVVVVVVVVVVV  ",
      "                ",
      "                "
    ],
    [
      "                ",
      "                ",
      "                ",
      "                ",
      "                ",
      "                ",
      "                ",
      "                ",
      "                ",
      "                ",
      "                ",
      "                ",
      "                ",
      "                ",
      "                ",
      "                "
    ]
  ]
}