{
  "name": "building_apartmentsmalld_ground_270",
  "refpalette": "deceasedcraft:building_apartmentsmalld/building_apartmentsmalld_ground_palette_270",
  "xsize": 16,
  "zsize": 16,
  "slices": [
    [
      "aaaaaaaaaaaaaaaa",
      "accccccccccccccb",
      "acddddddddddddca",
      "acddddddddddddca",
      "acddddddddddddca",
      "aceeeeedddddddda",
      "aaedddddddddddab",
      "aaedddddddddddbb",
      "aaedddddddddddbb",
      "aaedddddddddddba",
      "aceeeeeddddddddb",
      "acddddddddddddcb",
      "acddddddddddddca",
      "acddddddddddddca",
      "acccccccccccccca",
      "aaaaaaaaaaaaaaaa"
    ],
    [
      "                ",
      " cccccccccccccc ",
      " c       mmm gc ",
      " cC          gc ",
      " cDAttro     gc ",
      " ceeeeep     hf ",
      "  e          i  ",
      "  e         kj  ",
      "  e         lj  ",
      "  ehx        i  ",
      " ceeeeep     hf ",
      " cEByu       gc ",
      " c           gc ",
      " cswwwsq nnn gc ",
      " cccccccccccccc ",
      "                "
    ],
    [
      "                ",
      " fLIIccLIIIIIff ",
      " L           Ff ",
      " L           Fc ",
      " c           Fc ",
      " ceeeeeM     hf ",
      "  Q          i  ",
      "  Q         J   ",
      "  RP        K   ",
      "  ex         i  ",
      " ceeeeeM     hf ",
      " cS          Fc ",
      " I           Fc ",
      " IOOOOON     Ff ",
      " ffffccLIIIIIff ",
      "                "
    ],
    [
      "                ",
      " fLIIccLIIIIIff ",
      " L           Ff ",
      " L           Fc ",
      " c W         Tc ",
      " ceeeeeV     hf ",
      "  e          i  ",
      "  eP         i  ",
      "  eX         i  ",
      "  e          i  ",
      " ceeeeeV     hf ",
      " c           Fc ",
      " I           Uc ",
      " IOOOOON     Ff ",
      " ffffccLIIIIIff ",
      "                "
    ],
    [
      "                ",
      " fLIIccLIIIIIff ",
      " L           hf ",
      " L           hc ",
      " c           hc ",
      " ceeeee      hf ",
      "  eP         h  ",
      "  eX         h  ",
      "  Z          h  ",
      "  Z          h  ",
      " ceeeee      hf ",
      " c           hc ",
      " I           hc ",
      " IgggggY     hf ",
      " ffffccLIIIIIff ",
      "                "
    ],
    [
      "                ",
      " cccccccccccccc ",
      " cddddddddddddc ",
      " cddddddddddddc ",
      " cddddddddddddc ",
      " ceeeeedddddddc ",
      "  eX1 0dddddddc ",
      "  e   0dddddddc ",
      "  e   0dddddddc ",
      "  e   0dddddddc ",
      " ceeeeedddddddc ",
      " cddddddddddddc ",
      " cddddddddddddc ",
      " cddddddddddddc ",
      " cccccccccccccc ",
      "                "
    ]
  ]
}