{
  "name": "building_apartmentsmalld_floor1_270",
  "refpalette": "deceasedcraft:building_apartmentsmalld/building_apartmentsmalld_floor1_palette_270",
  "xsize": 16,
  "zsize": 16,
  "slices": [
    [
      "                ",
      "  bbbbbbbbbbbb  ",
      " lddddddddcccca ",
      " lddddddddcccca ",
      " lddddddddcccca ",
      " lffffdddddddda ",
      "  k hgfddddddda ",
      "  k igfddddddda ",
      "  k igdddddddda ",
      "  k jgfddddddda ",
      " lffffdddddddda ",
      " ldddddddddddda ",
      " ldddddddddddda ",
      " ldddddddddddda ",
      "  eeeeeeeeeeee  ",
      "                "
    ],
    [
      "                ",
      " mmmmmmmmmmmmmm ",
      " m       mFCunm ",
      " m VV !  L  wom ",
      " mTWWTP  m   pm ",
      " mffffP  mmmxmm ",
      "  f   fmNmID qm ",
      "  f X f  mJ  rm ",
      "  f Y Q  m  yrm ",
      "  fjZ f  M   sm ",
      " mffffR  mmmmmm ",
      " m1       AAA m ",
      " m2   SO      m ",
      " m3U0USO  KEBtm ",
      " mmmmmmmmmmmmmm ",
      "                "
    ],
    [
      "                ",
      " 5444mm44mm44mm ",
      " 6       m   74 ",
      " 6    |  +    4 ",
      " m<  <| ]m(%  4 ",
      " mffff|} mmm$m5 ",
      "  `   fm{m ^  4 ",
      "  `  >f  m    6 ",
      "  \u0370?  ;  m)  86 ",
      "  fZ  f  - & 94 ",
      " mffff:  mm*mm5 ",
      " m\u0371  ,   [    6 ",
      " 4\u0372   '       6 ",
      " 4\u0373/ .       #4 ",
      " 544444444444mm ",
      "                "
    ],
    [
      "                ",
      " 5466mm66mm66mm ",
      " 6       m\u0376  \u03744 ",
      " 6    \u037c  \u0377    6 ",
      " m    \u037d  m    6 ",
      " mffff   mmm\u0375m5 ",
      "  f   fm\u037bm    4 ",
      "  f?  f  m    6 ",
      "  f\u037f  a  m    6 ",
      "  f   f  \u037a    4 ",
      " mffff\u037e  mmmmm5 ",
      " m\u0384           6 ",
      " 4            6 ",
      " 4            4 ",
      " 544646666464mm ",
      "                "
    ],
    [
      "                ",
      " 5444mm44mm44mm ",
      " 6       m    4 ",
      " 6       m    4 ",
      " m       m    4 ",
      " mffff   mmmmm5 ",
      "  f?  fmmm    4 ",
      "  f\u037f  f  m    6 ",
      "  \u0387   f  m    6 ",
      "  \u0387   f  m    4 ",
      " mffff   mmmmm5 ",
      " m            6 ",
      " 4  \u0386      \u0385  6 ",
      " 4            4 ",
      " 544444444444mm ",
      "                "
    ],
    [
      "                ",
      " mmmmmmmmmmmmmm ",
      " m\u0388\u0388\u0388\u0388\u0388\u0388\u0388\u0388\u0388\u0388\u0388\u0388m ",
      " m\u0388\u0388\u0388\u0388\u0388\u0388\u0388\u0388\u0388\u0388\u0388\u0388m ",
      " m\u0388\u0388\u0388\u0388\u0388\u0388\u0388\u0388\u0388\u0388\u0388\u0388m ",
      " mffff\u0388\u0388\u0388\u0388\u0388\u0388\u0388\u0388m ",
      "  f\u037f\u0389 f\u0388\u0388\u0388\u0388\u0388\u0388\u0388m ",
      "  f   f\u0388\u0388\u0388\u0388\u0388\u0388\u0388m ",
      "  f   f\u0388\u0388\u0388\u0388\u0388\u0388\u0388m ",
      "  f   f\u0388\u0388\u0388\u0388\u0388\u0388\u0388m ",
      " mffff\u0388\u0388\u0388\u0388\u0388\u0388\u0388\u0388m ",
      " m\u0388\u0388\u0388\u0388\u0388\u0388\u0388\u0388\u0388\u0388\u0388\u0388m ",
      " m\u0388\u0388\u0388\u0388\u0388\u0388\u0388\u0388\u0388\u0388\u0388\u0388m ",
      " m\u0388\u0388\u0388\u0388\u0388\u0388\u0388\u0388\u0388\u0388\u0388\u0388m ",
      " mmmmmmmmmmmmmm ",
      "                "
    ]
  ]
}