{
  "name": "building_apartmentsmalld_floor2_180",
  "refpalette": "deceasedcraft:building_apartmentsmalld/building_apartmentsmalld_floor2_palette_180",
  "xsize": 16,
  "zsize": 16,
  "slices": [
    [
      "                ",
      "  llll    llll  ",
      " edddfkkkkfdddb ",
      " edddf    fdddb ",
      " edddfjiihfdddb ",
      " edddfggggfdddb ",
      " eddddfdffddddb ",
      " eddddddddddddb ",
      " eddddddddddddb ",
      " eddddddddddddb ",
      " edddddddddcccb ",
      " edddddddddcccb ",
      " edddddddddcccb ",
      " edddddddddcccb ",
      "  aaaaaaaaaaaa  ",
      "                "
    ],
    [
      "                ",
      " mmmmm    mmmmm ",
      " m10ZffffffR  m ",
      " mS  fj   fUT m ",
      " mY  fXWV fUT m ",
      " mS  f    fR  m ",
      " mQQ PfOffNNN m ",
      " mM      m    m ",
      " m M     L    m ",
      " m   mKmmmmmJmm ",
      " mI xm  FEm  Dm ",
      " mC xm   Bm  Am ",
      " my xmw   u  tm ",
      " ms  mrqqpm onm ",
      " mmmmmmmmmmmmmm ",
      "                "
    ],
    [
      "                ",
      " 322mm    mm443 ",
      " 2\u0371\u0370`ff/??f%  2 ",
      " 2.  fX,  f   2 ",
      " 2   f    f   2 ",
      " 2> [f  < f'  m ",
      " 2   :f;ff||| m ",
      " 2       m}   2 ",
      " 2       { ]  2 ",
      " 2  [m-mmmmm+mm ",
      " 2   m )  m( *m ",
      " 2   &^  %m$  2 ",
      " 2   m    #   2 ",
      " m9  m87 6m  5m ",
      " m244324423222m ",
      "                "
    ],
    [
      "                ",
      " 322mm    mm443 ",
      " 2   ffffff   2 ",
      " 2   f \u037d, f   4 ",
      " 4   f    f   4 ",
      " 2   f    f   m ",
      " 4   \u037cfaff\u037b\u037a  m ",
      " 4       m    4 ",
      " 4       \u0377    4 ",
      " 4   m\u0376mmmmm\u0375mm ",
      " 2   m    m  \u0374m ",
      " 4   m    m   4 ",
      " 2   m    \u0373   4 ",
      " m   m    m  \u0372m ",
      " m244324423442m ",
      "                "
    ],
    [
      "                ",
      " 322mm    mm443 ",
      " 2   f\u0384\u0384fff   2 ",
      " 2   f  \u037d,f   2 ",
      " 2 \u037f f    f   2 ",
      " 2   f    f   m ",
      " 2  \u037c!ffff    m ",
      " 2    \u037c  m    2 ",
      " 2       m    2 ",
      " 2   mmmmmmmmmm ",
      " 2   m    m   m ",
      " 2 \u037e m    m   2 ",
      " 2   m    m   2 ",
      " m   m    m   m ",
      " m244324423222m ",
      "                "
    ],
    [
      "                ",
      " mmmmm    mmmmm ",
      " m\u0385\u0385\u0385ffffff\u0385\u0385\u0385m ",
      " m\u0385\u0385\u0385f   \u037df\u0385\u0385\u0385m ",
      " m\u0385\u0385\u0385f   \u0386f\u0385\u0385\u0385m ",
      " m\u0385\u0385\u0385f    f\u0385\u0385\u0385m ",
      " m\u0385\u0385\u0385\u0385ffff\u0385\u0385\u0385\u0385m ",
      " m\u0385\u0385\u0385\u0385\u0385\u0385\u0385\u0385\u0385\u0385\u0385\u0385m ",
      " m\u0385\u0385\u0385\u0385\u0385\u0385\u0385\u0385\u0385\u0385\u0385\u0385m ",
      " m\u0385\u0385\u0385\u0385\u0385\u0385\u0385\u0385\u0385\u0385\u0385\u0385m ",
      " m\u0385\u0385\u0385\u0385\u0385\u0385\u0385\u0385\u0385\u0385\u0385\u0385m ",
      " m\u0385\u0385\u0385\u0385\u0385\u0385\u0385\u0385\u0385\u0385\u0385\u0385m ",
      " m\u0385\u0385\u0385\u0385\u0385\u0385\u0385\u0385\u0385\u0385\u0385\u0385m ",
      " m\u0385\u0385\u0385\u0385\u0385\u0385\u0385\u0385\u0385\u0385\u0385\u0385m ",
      " mmmmmmmmmmmmmm ",
      "                "
    ]
  ]
}