{
  "name": "building_apartmentsmalld_floor3_180",
  "refpalette": "deceasedcraft:building_apartmentsmalld/building_apartmentsmalld_floor3_palette_180",
  "xsize": 16,
  "zsize": 16,
  "slices": [
    [
      "                ",
      "  llll    llll  ",
      " edddfkkkkfdddb ",
      " edddf    fdddb ",
      " edddfjiihfdddb ",
      " edddfggggfdddb ",
      " eddddfdffddddb ",
      " eddddddddddddb ",
      " eddddddddddddb ",
      " eddddddddddddb ",
      " edddddddddcccb ",
      " edddddddddcccb ",
      " edddddddddcccb ",
      " edddddddddcccb ",
      "  aaaaaaaaaaaa  ",
      "                "
    ],
    [
      "                ",
      " mmmmm    mmmmm ",
      " m210ffffffT  m ",
      " mU  fj   fWV m ",
      " mZ  fYXX fWV m ",
      " mU  f    fT  m ",
      " mSS RfQffPPP m ",
      " mOO     m    m ",
      " m       N    m ",
      " m  DmMmmmmmLmm ",
      " mK ym  JIm  Fm ",
      " mEDym   Cm  Bm ",
      " mA ym x  w utm ",
      " ms  mrqqpm onm ",
      " mmmmmmmmmmmmmm ",
      "                "
    ],
    [
      "                ",
      " 433mm    mm554 ",
      " 3 \u0372\u0371ff\u0370``f/  3 ",
      " 3?  fY.  f   3 ",
      " 3   f    f   3 ",
      " 3, >f  < f'  m ",
      " 3:  ;f|ff}}} m ",
      " 3       m{   3 ",
      " 3       ] [  3 ",
      " 3  -m+mmmmm)mm ",
      " 3   m (  m  Dm ",
      " 3  D!*  &m^  3 ",
      " 3   m    %   3 ",
      " m$  m#987m  6m ",
      " m355435534333m ",
      "                "
    ],
    [
      "                ",
      " 433mm    mm554 ",
      " 3   ffffff   3 ",
      " 3   f \u037d. f   5 ",
      " 5   f    f   5 ",
      " 3   f    f   m ",
      " 5   \u037cfaff\u037b\u037a  m ",
      " 5       m    5 ",
      " 5       \u0377    5 ",
      " 5   m\u0376mmmmm\u0375mm ",
      " 3   m    m   m ",
      " 5   m    m   5 ",
      " 3   m    \u0374   5 ",
      " m   m    m  \u0373m ",
      " m355435534553m ",
      "                "
    ],
    [
      "                ",
      " 433mm    mm554 ",
      " 3   f\u0384\u0384fff   3 ",
      " 3   f  \u037d.f   3 ",
      " 3 \u037f f    f   3 ",
      " 3   f    f   m ",
      " 3    ffff    m ",
      " 3       m    3 ",
      " 3       m    3 ",
      " 3   mmmmmmmmmm ",
      " 3   m    m D!m ",
      " 3 \u037e m    m   3 ",
      " 3   m    m   3 ",
      " m   m    m   m ",
      " m355435534333m ",
      "                "
    ],
    [
      "                ",
      " mmmmm    mmmmm ",
      " m\u0385\u0385\u0385ffffff\u0385\u0385\u0385m ",
      " m\u0385\u0385\u0385f   \u037df\u0385\u0385\u0385m ",
      " m\u0385\u0385\u0385f   \u0386f\u0385\u0385\u0385m ",
      " m\u0385\u0385\u0385f    f\u0385\u0385\u0385m ",
      " m\u0385\u0385\u0385\u0385ffff\u0385\u0385\u0385\u0385m ",
      " m\u0385\u0385\u0385\u0385\u0385\u0385\u0385\u0385\u0385\u0385\u0385\u0385m ",
      " m\u0385\u0385\u0385\u0385\u0385\u0385\u0385\u0385\u0385\u0385\u0385\u0385m ",
      " m\u0385\u0385\u0385\u0385\u0385\u0385\u0385\u0385\u0385\u0385\u0385\u0385m ",
      " m\u0385\u0385\u0385\u0385\u0385\u0385\u0385\u0385\u0385\u0385\u0385\u0385m ",
      " m\u0385\u0385\u0385\u0385\u0385\u0385\u0385\u0385\u0385\u0385\u0385\u0385m ",
      " m\u0385\u0385\u0385\u0385\u0385\u0385\u0385\u0385\u0385\u0385\u0385\u0385m ",
      " m\u0385\u0385\u0385\u0385\u0385\u0385\u0385\u0385\u0385\u0385\u0385\u0385m ",
      " mmmmmmmmmmmmmm ",
      "                "
    ]
  ]
}