{
  "name": "building_apartmentsmalld_floor3",
  "refpalette": "deceasedcraft:building_apartmentsmalld/building_apartmentsmalld_floor3_palette",
  "xsize": 16,
  "zsize": 16,
  "slices": [
    [
      "                ",
      "  aaaaaaaaaaaa  ",
      " bcccddddddddde ",
      " bcccddddddddde ",
      " bcccddddddddde ",
      " bcccddddddddde ",
      " bdddddddddddde ",
      " bdddddddddddde ",
      " bdddddddddddde ",
      " bddddffdfdddde ",
      " bdddfggggfddde ",
      " bdddfhiijfddde ",
      " bdddf    fddde ",
      " bdddfkkkkfddde ",
      "  llll    llll  ",
      "                "
    ],
    [
      "                ",
      " mmmmmmmmmmmmmm ",
      " mno mpqqrm  sm ",
      " mtu w  x my Am ",
      " mB  mC   myDEm ",
      " mF  mIJ  my Km ",
      " mmLmmmmmMmD  m ",
      " m    N       m ",
      " m    m     OOm ",
      " m PPPffQfR SSm ",
      " m  Tf    f  Um ",
      " m VWf XXYf  Zm ",
      " m VWf   jf  Um ",
      " m  Tffffff012m ",
      " mmmmm    mmmmm ",
      "                "
    ],
    [
      "                ",
      " m333435534553m ",
      " m6  m789#m  $m ",
      " 3   %    m   3 ",
      " 3  ^m&  *!D  3 ",
      " mD  m  ( m   3 ",
      " mm)mmmmm+m-  3 ",
      " 3  [ ]       3 ",
      " 3   {m       3 ",
      " m }}}ff|f;  :3 ",
      " m  'f <  f> ,3 ",
      " 3   f    f   3 ",
      " 3   f  .Yf  ?3 ",
      " 3  /f``\u0370ff\u0371\u0372 3 ",
      " 455mm    mm334 ",
      "                "
    ],
    [
      "                ",
      " m355435534553m ",
      " m\u0373  m    m   m ",
      " 5   \u0374    m   3 ",
      " 5   m    m   5 ",
      " m   m    m   3 ",
      " mm\u0375mmmmm\u0376m   5 ",
      " 5    \u0377       5 ",
      " 5    m       5 ",
      " m  \u037a\u037bffaf\u037c   5 ",
      " m   f    f   3 ",
      " 5   f    f   5 ",
      " 5   f .\u037d f   3 ",
      " 3   ffffff   3 ",
      " 455mm    mm334 ",
      "                "
    ],
    [
      "                ",
      " m333435534553m ",
      " m   m    m   m ",
      " 3   m    m   3 ",
      " 3   m    m \u037e 3 ",
      " m!D m    m   3 ",
      " mmmmmmmmmm   3 ",
      " 3    m       3 ",
      " 3    m       3 ",
      " m    ffff    3 ",
      " m   f    f   3 ",
      " 3   f    f \u037f 3 ",
      " 3   f.\u037d  f   3 ",
      " 3   fff\u0384\u0384f   3 ",
      " 455mm    mm334 ",
      "                "
    ],
    [
      "                ",
      " mmmmmmmmmmmmmm ",
      " m\u0385\u0385\u0385\u0385\u0385\u0385\u0385\u0385\u0385\u0385\u0385\u0385m ",
      " m\u0385\u0385\u0385\u0385\u0385\u0385\u0385\u0385\u0385\u0385\u0385\u0385m ",
      " m\u0385\u0385\u0385\u0385\u0385\u0385\u0385\u0385\u0385\u0385\u0385\u0385m ",
      " m\u0385\u0385\u0385\u0385\u0385\u0385\u0385\u0385\u0385\u0385\u0385\u0385m ",
      " m\u0385\u0385\u0385\u0385\u0385\u0385\u0385\u0385\u0385\u0385\u0385\u0385m ",
      " m\u0385\u0385\u0385\u0385\u0385\u0385\u0385\u0385\u0385\u0385\u0385\u0385m ",
      " m\u0385\u0385\u0385\u0385\u0385\u0385\u0385\u0385\u0385\u0385\u0385\u0385m ",
      " m\u0385\u0385\u0385\u0385ffff\u0385\u0385\u0385\u0385m ",
      " m\u0385\u0385\u0385f    f\u0385\u0385\u0385m ",
      " m\u0385\u0385\u0385f\u0386   f\u0385\u0385\u0385m ",
      " m\u0385\u0385\u0385f\u037d   f\u0385\u0385\u0385m ",
      " m\u0385\u0385\u0385ffffff\u0385\u0385\u0385m ",
      " mmmmm    mmmmm ",
      "                "
    ]
  ]
}