{
  "name": "building_apartmentsmalld_floor3_90",
  "refpalette": "deceasedcraft:building_apartmentsmalld/building_apartmentsmalld_floor3_palette_90",
  "xsize": 16,
  "zsize": 16,
  "slices": [
    [
      "                ",
      "  eeeeeeeeeeee  ",
      " addddddddddddl ",
      " addddddddddddl ",
      " addddddddddddl ",
      " addddddddffffl ",
      " adddddddfgj k  ",
      " addddddddgi k  ",
      " adddddddfgi k  ",
      " adddddddfgh k  ",
      " addddddddffffl ",
      " accccddddddddl ",
      " accccddddddddl ",
      " accccddddddddl ",
      "  bbbbbbbbbbbb  ",
      "                "
    ],
    [
      "                ",
      " mmmmmmmmmmmmmm ",
      " msAEK  OSUZU2m ",
      " m  D   OS   1m ",
      " m yyyD      0m ",
      " mmmmmm  Rffffm ",
      " mr   M  f Yjf  ",
      " mqx  m  Q X f  ",
      " mq  Jm  f X f  ",
      " mp CImNmf   f  ",
      " mmwmmm  Pffffm ",
      " m    m  PTWWTm ",
      " mou  L  P VV m ",
      " mntBFm       m ",
      " mmmmmmmmmmmmmm ",
      "                "
    ],
    [
      "                ",
      " mm333333333334 ",
      " 3$      :, ? 3 ",
      " 5           \u03723 ",
      " 5  D -   >  \u0371m ",
      " 4mm!mm  ;ffffm ",
      " 3# * +  f  Yf  ",
      " 59  (m  |  .\u0370  ",
      " 58   m  f<  `  ",
      " 37 & m]mf   `  ",
      " 4m%mmm {}ffffm ",
      " 3  ^ m[ }'  /m ",
      " 3    )  }    5 ",
      " 36  Dm       5 ",
      " mm33mm33mm3334 ",
      "                "
    ],
    [
      "                ",
      " mm353555535334 ",
      " 3            3 ",
      " 5            3 ",
      " 5            m ",
      " 4mmmmm  \u037cffffm ",
      " 3    \u0376  f   f  ",
      " 5    m  a  \u037df  ",
      " 5    m  f  .f  ",
      " 3    m\u0377mf   f  ",
      " 4m\u0374mmm  \u037bffffm ",
      " 5    m  \u037a    m ",
      " 5    \u0375       5 ",
      " 3\u0373   m       5 ",
      " mm55mm55mm5534 ",
      "                "
    ],
    [
      "                ",
      " mm333333333334 ",
      " 3            3 ",
      " 5  \u037e      \u037f  3 ",
      " 5            m ",
      " 4mmmmm   ffffm ",
      " 3    m  f   \u0384  ",
      " 5    m  f   \u0384  ",
      " 5    m  f  \u037df  ",
      " 3    mmmf  .f  ",
      " 4mmmmm   ffffm ",
      " 3    m       m ",
      " 3   Dm       5 ",
      " 3   !m       5 ",
      " mm33mm33mm3334 ",
      "                "
    ],
    [
      "                ",
      " mmmmmmmmmmmmmm ",
      " m\u0385\u0385\u0385\u0385\u0385\u0385\u0385\u0385\u0385\u0385\u0385\u0385m ",
      " m\u0385\u0385\u0385\u0385\u0385\u0385\u0385\u0385\u0385\u0385\u0385\u0385m ",
      " m\u0385\u0385\u0385\u0385\u0385\u0385\u0385\u0385\u0385\u0385\u0385\u0385m ",
      " m\u0385\u0385\u0385\u0385\u0385\u0385\u0385\u0385ffffm ",
      " m\u0385\u0385\u0385\u0385\u0385\u0385\u0385f   f  ",
      " m\u0385\u0385\u0385\u0385\u0385\u0385\u0385f   f  ",
      " m\u0385\u0385\u0385\u0385\u0385\u0385\u0385f   f  ",
      " m\u0385\u0385\u0385\u0385\u0385\u0385\u0385f \u0386\u037df  ",
      " m\u0385\u0385\u0385\u0385\u0385\u0385\u0385\u0385ffffm ",
      " m\u0385\u0385\u0385\u0385\u0385\u0385\u0385\u0385\u0385\u0385\u0385\u0385m ",
      " m\u0385\u0385\u0385\u0385\u0385\u0385\u0385\u0385\u0385\u0385\u0385\u0385m ",
      " m\u0385\u0385\u0385\u0385\u0385\u0385\u0385\u0385\u0385\u0385\u0385\u0385m ",
      " mmmmmmmmmmmmmm ",
      "                "
    ]
  ]
}