{
  "name": "building_apartmentsmalld_ground",
  "refpalette": "deceasedcraft:building_apartmentsmalld/building_apartmentsmalld_ground_palette",
  "xsize": 16,
  "zsize": 16,
  "slices": [
    [
      "abaaaabbbabbaaaa",
      "accccdabbbdcccca",
      "acddddddddddddca",
      "acddddddddddddca",
      "acddddddddddddca",
      "acddddddddddddca",
      "acddddddddddddca",
      "acddddddddddddca",
      "acddddddddddddca",
      "acdddeddddedddca",
      "acdddeddddedddca",
      "acdddeddddedddca",
      "acdddeddddedddca",
      "acdddeeeeeedddca",
      "acccccaaaaccccca",
      "aaaaaaaaaaaaaaaa"
    ],
    [
      "                ",
      " ccccf    fcccc ",
      " cggghijjihgggc ",
      " c     kl     c ",
      " cm          nc ",
      " cm          nc ",
      " cm          nc ",
      " c            c ",
      " c  op    p  qc ",
      " c  re    e  sc ",
      " c  te    eu wc ",
      " c  te   xey wc ",
      " c  Ae   heB wc ",
      " c CDeeeeeeE sc ",
      " ccccc    ccccc ",
      "                "
    ],
    [
      "                ",
      " ffccf    fccff ",
      " fFFFhi  ihFFFf ",
      " I     JK     I ",
      " I            I ",
      " I            I ",
      " I            I ",
      " I            I ",
      " L   M    M  NL ",
      " c   e    e  Oc ",
      " c   e    e  Oc ",
      " I   e    e  Of ",
      " I   e  Pxe  Of ",
      " L   eQQReeS Of ",
      " fLLcc    ccIIf ",
      "                "
    ],
    [
      "                ",
      " ffccf    fccff ",
      " fFFThiiiihFUFf ",
      " I            I ",
      " I            I ",
      " I            I ",
      " I            I ",
      " I            I ",
      " L   V    V  NL ",
      " c   e    e  Oc ",
      " c   e    e  Oc ",
      " I   e    e  Of ",
      " I  We PX e  Of ",
      " L   eeeeee  Of ",
      " fLLcc    ccIIf ",
      "                "
    ],
    [
      "                ",
      " ffccf    fccff ",
      " fhhhhhhhhhhhhf ",
      " I            I ",
      " I            I ",
      " I            I ",
      " I            I ",
      " I            I ",
      " L           YL ",
      " c   e    e  gc ",
      " c   e    e  gc ",
      " I   e    e  gf ",
      " I   ePX  e  gf ",
      " L   eeeZZe  gf ",
      " fLLcc    ccIIf ",
      "                "
    ],
    [
      "                ",
      " cccccccccccccc ",
      " cddddddddddddc ",
      " cddddddddddddc ",
      " cddddddddddddc ",
      " cddddddddddddc ",
      " cddddddddddddc ",
      " cddddddddddddc ",
      " cddddddddddddc ",
      " cddde0000edddc ",
      " cddde    edddc ",
      " cddde1   edddc ",
      " cdddeX   edddc ",
      " cdddeeeeeedddc ",
      " ccccc    ccccc ",
      "                "
    ]
  ]
}