{
  "name": "building_apartmentsmalld_floor1_90",
  "refpalette": "deceasedcraft:building_apartmentsmalld/building_apartmentsmalld_floor1_palette_90",
  "xsize": 16,
  "zsize": 16,
  "slices": [
    [
      "                ",
      "  eeeeeeeeeeee  ",
      " addddddddddddl ",
      " addddddddddddl ",
      " addddddddddddl ",
      " addddddddffffl ",
      " adddddddfgj k  ",
      " addddddddgi k  ",
      " adddddddfgi k  ",
      " adddddddfgh k  ",
      " addddddddffffl ",
      " accccddddddddl ",
      " accccddddddddl ",
      " accccddddddddl ",
      "  bbbbbbbbbbbb  ",
      "                "
    ],
    [
      "                ",
      " mmmmmmmmmmmmmm ",
      " mtBEK  OSU0U3m ",
      " m      OS   2m ",
      " m AAA       1m ",
      " mmmmmm  Rffffm ",
      " ms   M  f Zjf  ",
      " mry  m  Q Y f  ",
      " mr  Jm  f X f  ",
      " mq DImNmf   f  ",
      " mmxmmm  Pffffm ",
      " mp   m  PTWWTm ",
      " mow  L  ! VV m ",
      " mnuCFm       m ",
      " mmmmmmmmmmmmmm ",
      "                "
    ],
    [
      "                ",
      " mm444444444445 ",
      " 4#       . /\u03734 ",
      " 6       '   \u03724 ",
      " 6    [   ,  \u0371m ",
      " 5mm*mm  :ffffm ",
      " 49 & -  f  Zf  ",
      " 68  )m  ;  ?\u0370  ",
      " 6    m  f>  `  ",
      " 4  ^ m{mf   `  ",
      " 5m$mmm }|ffffm ",
      " 4  %(m] |<  <m ",
      " 4    +  |    6 ",
      " 47   m       6 ",
      " mm44mm44mm4445 ",
      "                "
    ],
    [
      "                ",
      " mm464666646445 ",
      " 4            4 ",
      " 6            4 ",
      " 6           \u0384m ",
      " 5mmmmm  \u037effffm ",
      " 4    \u037a  f   f  ",
      " 6    m  a  \u037ff  ",
      " 6    m  f  ?f  ",
      " 4    m\u037bmf   f  ",
      " 5m\u0375mmm   ffffm ",
      " 6    m  \u037d    m ",
      " 6    \u0377  \u037c    6 ",
      " 4\u0374  \u0376m       6 ",
      " mm66mm66mm6645 ",
      "                "
    ],
    [
      "                ",
      " mm444444444445 ",
      " 4            4 ",
      " 6  \u0385      \u0386  4 ",
      " 6            m ",
      " 5mmmmm   ffffm ",
      " 4    m  f   \u0387  ",
      " 6    m  f   \u0387  ",
      " 6    m  f  \u037ff  ",
      " 4    mmmf  ?f  ",
      " 5mmmmm   ffffm ",
      " 4    m       m ",
      " 4    m       6 ",
      " 4    m       6 ",
      " mm44mm44mm4445 ",
      "                "
    ],
    [
      "                ",
      " mmmmmmmmmmmmmm ",
      " m\u0388\u0388\u0388\u0388\u0388\u0388\u0388\u0388\u0388\u0388\u0388\u0388m ",
      " m\u0388\u0388\u0388\u0388\u0388\u0388\u0388\u0388\u0388\u0388\u0388\u0388m ",
      " m\u0388\u0388\u0388\u0388\u0388\u0388\u0388\u0388\u0388\u0388\u0388\u0388m ",
      " m\u0388\u0388\u0388\u0388\u0388\u0388\u0388\u0388ffffm ",
      " m\u0388\u0388\u0388\u0388\u0388\u0388\u0388f   f  ",
      " m\u0388\u0388\u0388\u0388\u0388\u0388\u0388f   f  ",
      " m\u0388\u0388\u0388\u0388\u0388\u0388\u0388f   f  ",
      " m\u0388\u0388\u0388\u0388\u0388\u0388\u0388f \u0389\u037ff  ",
      " m\u0388\u0388\u0388\u0388\u0388\u0388\u0388\u0388ffffm ",
      " m\u0388\u0388\u0388\u0388\u0388\u0388\u0388\u0388\u0388\u0388\u0388\u0388m ",
      " m\u0388\u0388\u0388\u0388\u0388\u0388\u0388\u0388\u0388\u0388\u0388\u0388m ",
      " m\u0388\u0388\u0388\u0388\u0388\u0388\u0388\u0388\u0388\u0388\u0388\u0388m ",
      " mmmmmmmmmmmmmm ",
      "                "
    ]
  ]
}