{
  "name": "building_apartmentsmalld_floor1_180",
  "refpalette": "deceasedcraft:building_apartmentsmalld/building_apartmentsmalld_floor1_palette_180",
  "xsize": 16,
  "zsize": 16,
  "slices": [
    [
      "                ",
      "  llll    llll  ",
      " edddfkkkkfdddb ",
      " edddf    fdddb ",
      " edddfjiihfdddb ",
      " edddfggggfdddb ",
      " eddddfdffddddb ",
      " eddddddddddddb ",
      " eddddddddddddb ",
      " eddddddddddddb ",
      " edddddddddcccb ",
      " edddddddddcccb ",
      " edddddddddcccb ",
      " edddddddddcccb ",
      "  aaaaaaaaaaaa  ",
      "                "
    ],
    [
      "                ",
      " mmmmm    mmmmm ",
      " m321ffffffT  m ",
      " mU  fj   fWV m ",
      " m0  fZYX fWV m ",
      " mU  f    fT  m ",
      " mSS RfQffPP! m ",
      " mOO     m    m ",
      " m       N    m ",
      " m   mMmmmmmLmm ",
      " mK Am  JIm  Fm ",
      " mE Am   Dm  Cm ",
      " mB Am y  x wum ",
      " mt  msrrqmponm ",
      " mmmmmmmmmmmmmm ",
      "                "
    ],
    [
      "                ",
      " 544mm    mm665 ",
      " 4\u0373\u0372\u0371ff\u0370``f<  4 ",
      " 4/  fZ?  f   4 ",
      " 4   f    f   4 ",
      " 4. ,f  > f<  m ",
      " 4 ' :f;ff||| m ",
      " 4       m}   4 ",
      " 4       { ]  4 ",
      " 4  [m-mmmmm+mm ",
      " 4   m )  m(  m ",
      " 4   *&  ^m%  4 ",
      " 4   m    $   4 ",
      " m#  m98  m  7m ",
      " m466546645444m ",
      "                "
    ],
    [
      "                ",
      " 544mm    mm665 ",
      " 4  \u0384ffffff   4 ",
      " 4   f \u037f? f   6 ",
      " 6   f    f   6 ",
      " 4   f    f   m ",
      " 6   \u037efaff \u037d\u037c m ",
      " 6       m    6 ",
      " 6       \u037b    6 ",
      " 6   m\u037ammmmm\u0377mm ",
      " 4   m    m  \u0376m ",
      " 6   m    m   6 ",
      " 4   m    \u0375   6 ",
      " m   m    m  \u0374m ",
      " m466546645664m ",
      "                "
    ],
    [
      "                ",
      " 544mm    mm665 ",
      " 4   f\u0387\u0387fff   4 ",
      " 4   f  \u037f?f   4 ",
      " 4 \u0386 f    f   4 ",
      " 4   f    f   m ",
      " 4    ffff    m ",
      " 4       m    4 ",
      " 4       m    4 ",
      " 4   mmmmmmmmmm ",
      " 4   m    m   m ",
      " 4 \u0385 m    m   4 ",
      " 4   m    m   4 ",
      " m   m    m   m ",
      " m466546645444m ",
      "                "
    ],
    [
      "                ",
      " mmmmm    mmmmm ",
      " m\u0388\u0388\u0388ffffff\u0388\u0388\u0388m ",
      " m\u0388\u0388\u0388f   \u037ff\u0388\u0388\u0388m ",
      " m\u0388\u0388\u0388f   \u0389f\u0388\u0388\u0388m ",
      " m\u0388\u0388\u0388f    f\u0388\u0388\u0388m ",
      " m\u0388\u0388\u0388\u0388ffff\u0388\u0388\u0388\u0388m ",
      " m\u0388\u0388\u0388\u0388\u0388\u0388\u0388\u0388\u0388\u0388\u0388\u0388m ",
      " m\u0388\u0388\u0388\u0388\u0388\u0388\u0388\u0388\u0388\u0388\u0388\u0388m ",
      " m\u0388\u0388\u0388\u0388\u0388\u0388\u0388\u0388\u0388\u0388\u0388\u0388m ",
      " m\u0388\u0388\u0388\u0388\u0388\u0388\u0388\u0388\u0388\u0388\u0388\u0388m ",
      " m\u0388\u0388\u0388\u0388\u0388\u0388\u0388\u0388\u0388\u0388\u0388\u0388m ",
      " m\u0388\u0388\u0388\u0388\u0388\u0388\u0388\u0388\u0388\u0388\u0388\u0388m ",
      " m\u0388\u0388\u0388\u0388\u0388\u0388\u0388\u0388\u0388\u0388\u0388\u0388m ",
      " mmmmmmmmmmmmmm ",
      "                "
    ]
  ]
}