{
  "name": "building_apartmentsmalld_ground_180",
  "refpalette": "deceasedcraft:building_apartmentsmalld/building_apartmentsmalld_ground_palette_180",
  "xsize": 16,
  "zsize": 16,
  "slices": [
    [
      "aaaaaaaaaaaaaaaa",
      "acccccaaaaccccca",
      "acdddeeeeeedddca",
      "acdddeddddedddca",
      "acdddeddddedddca",
      "acdddeddddedddca",
      "acdddeddddedddca",
      "acddddddddddddca",
      "acddddddddddddca",
      "acddddddddddddca",
      "acddddddddddddca",
      "acddddddddddddca",
      "acddddddddddddca",
      "acddddddddddddca",
      "accccdbbbadcccca",
      "aaaabbabbbaaaaba"
    ],
    [
      "                ",
      " ccccc    ccccc ",
      " cs EeeeeeeDC c ",
      " cw Beh   eA  c ",
      " cw yex   et  c ",
      " cw ue    et  c ",
      " cs  e    er  c ",
      " cq  p    po  c ",
      " c            c ",
      " cn          mc ",
      " cn          mc ",
      " cn          mc ",
      " c     lk     c ",
      " cggghijjihgggc ",
      " ccccf    fcccc ",
      "                "
    ],
    [
      "                ",
      " fIIcc    ccLLf ",
      " fO SeeRQQe   L ",
      " fO  exP  e   I ",
      " fO  e    e   I ",
      " cO  e    e   c ",
      " cO  e    e   c ",
      " LN  M    M   L ",
      " I            I ",
      " I            I ",
      " I            I ",
      " I            I ",
      " I     KJ     I ",
      " fFFFhi  ihFFFf ",
      " ffccf    fccff ",
      "                "
    ],
    [
      "                ",
      " fIIcc    ccLLf ",
      " fO  eeeeee   L ",
      " fO  e XP eW  I ",
      " fO  e    e   I ",
      " cO  e    e   c ",
      " cO  e    e   c ",
      " LN  V    V   L ",
      " I            I ",
      " I            I ",
      " I            I ",
      " I            I ",
      " I            I ",
      " fFUFhiiiihTFFf ",
      " ffccf    fccff ",
      "                "
    ],
    [
      "                ",
      " fIIcc    ccLLf ",
      " fg  eZZeee   L ",
      " fg  e  XPe   I ",
      " fg  e    e   I ",
      " cg  e    e   c ",
      " cg  e    e   c ",
      " LY           L ",
      " I            I ",
      " I            I ",
      " I            I ",
      " I            I ",
      " I            I ",
      " fhhhhhhhhhhhhf ",
      " ffccf    fccff ",
      "                "
    ],
    [
      "                ",
      " ccccc    ccccc ",
      " cdddeeeeeedddc ",
      " cddde   Xedddc ",
      " cddde   1edddc ",
      " cddde    edddc ",
      " cddde0000edddc ",
      " cddddddddddddc ",
      " cddddddddddddc ",
      " cddddddddddddc ",
      " cddddddddddddc ",
      " cddddddddddddc ",
      " cddddddddddddc ",
      " cddddddddddddc ",
      " cccccccccccccc ",
      "                "
    ]
  ]
}