{
  "name": "building_apartmentsmalld_floor2",
  "refpalette": "deceasedcraft:building_apartmentsmalld/building_apartmentsmalld_floor2_palette",
  "xsize": 16,
  "zsize": 16,
  "slices": [
    [
      "                ",
      "  aaaaaaaaaaaa  ",
      " bcccddddddddde ",
      " bcccddddddddde ",
      " bcccddddddddde ",
      " bcccddddddddde ",
      " bdddddddddddde ",
      " bdddddddddddde ",
      " bdddddddddddde ",
      " bddddffdfdddde ",
      " bdddfggggfddde ",
      " bdddfhiijfddde ",
      " bdddf    fddde ",
      " bdddfkkkkfddde ",
      "  llll    llll  ",
      "                "
    ],
    [
      "                ",
      " mmmmmmmmmmmmmm ",
      " mno mpqqrm  sm ",
      " mt  u   wmx ym ",
      " mA  mB   mx Cm ",
      " mD  mEF  mx Im ",
      " mmJmmmmmKm   m ",
      " m    L     M m ",
      " m    m      Mm ",
      " m NNNffOfP QQm ",
      " m  Rf    f  Sm ",
      " m TUf VWXf  Ym ",
      " m TUf   jf  Sm ",
      " m  RffffffZ01m ",
      " mmmmm    mmmmm ",
      "                "
    ],
    [
      "                ",
      " m222324423442m ",
      " m5  m6 78m  9m ",
      " 2   #    m   2 ",
      " 2  $m%  ^&   2 ",
      " m* (m  ) m   2 ",
      " mm+mmmmm-m[  2 ",
      " 2  ] {       2 ",
      " 2   }m       2 ",
      " m |||ff;f:   2 ",
      " m  'f <  f[ >2 ",
      " 2   f    f   2 ",
      " 2   f  ,Xf  .2 ",
      " 2  %f??/ff`\u0370\u03712 ",
      " 344mm    mm223 ",
      "                "
    ],
    [
      "                ",
      " m244324423442m ",
      " m\u0372  m    m   m ",
      " 4   \u0373    m   2 ",
      " 4   m    m   4 ",
      " m\u0374  m    m   2 ",
      " mm\u0375mmmmm\u0376m   4 ",
      " 4    \u0377       4 ",
      " 4    m       4 ",
      " m  \u037a\u037bffaf\u037c   4 ",
      " m   f    f   2 ",
      " 4   f    f   4 ",
      " 4   f ,\u037d f   2 ",
      " 2   ffffff   2 ",
      " 344mm    mm223 ",
      "                "
    ],
    [
      "                ",
      " m222324423442m ",
      " m   m    m   m ",
      " 2   m    m   2 ",
      " 2   m    m \u037e 2 ",
      " m   m    m   2 ",
      " mmmmmmmmmm   2 ",
      " 2    m       2 ",
      " 2    m  \u037c    2 ",
      " m    ffff!\u037c  2 ",
      " m   f    f   2 ",
      " 2   f    f \u037f 2 ",
      " 2   f,\u037d  f   2 ",
      " 2   fff\u0384\u0384f   2 ",
      " 344mm    mm223 ",
      "                "
    ],
    [
      "                ",
      " mmmmmmmmmmmmmm ",
      " m\u0385\u0385\u0385\u0385\u0385\u0385\u0385\u0385\u0385\u0385\u0385\u0385m ",
      " m\u0385\u0385\u0385\u0385\u0385\u0385\u0385\u0385\u0385\u0385\u0385\u0385m ",
      " m\u0385\u0385\u0385\u0385\u0385\u0385\u0385\u0385\u0385\u0385\u0385\u0385m ",
      " m\u0385\u0385\u0385\u0385\u0385\u0385\u0385\u0385\u0385\u0385\u0385\u0385m ",
      " m\u0385\u0385\u0385\u0385\u0385\u0385\u0385\u0385\u0385\u0385\u0385\u0385m ",
      " m\u0385\u0385\u0385\u0385\u0385\u0385\u0385\u0385\u0385\u0385\u0385\u0385m ",
      " m\u0385\u0385\u0385\u0385\u0385\u0385\u0385\u0385\u0385\u0385\u0385\u0385m ",
      " m\u0385\u0385\u0385\u0385ffff\u0385\u0385\u0385\u0385m ",
      " m\u0385\u0385\u0385f    f\u0385\u0385\u0385m ",
      " m\u0385\u0385\u0385f\u0386   f\u0385\u0385\u0385m ",
      " m\u0385\u0385\u0385f\u037d   f\u0385\u0385\u0385m ",
      " m\u0385\u0385\u0385ffffff\u0385\u0385\u0385m ",
      " mmmmm    mmmmm ",
      "                "
    ]
  ]
}