{
  "name": "building_apartmentsmalld_floor2_270",
  "refpalette": "deceasedcraft:building_apartmentsmalld/building_apartmentsmalld_floor2_palette_270",
  "xsize": 16,
  "zsize": 16,
  "slices": [
    [
      "                ",
      "  bbbbbbbbbbbb  ",
      " lddddddddcccca ",
      " lddddddddcccca ",
      " lddddddddcccca ",
      " lffffdddddddda ",
      "  k hgfddddddda ",
      "  k igfddddddda ",
      "  k igdddddddda ",
      "  k jgfddddddda ",
      " lffffdddddddda ",
      " ldddddddddddda ",
      " ldddddddddddda ",
      " ldddddddddddda ",
      "  eeeeeeeeeeee  ",
      "                "
    ],
    [
      "                ",
      " mmmmmmmmmmmmmm ",
      " m       mDAtnm ",
      " m TT N  J   om ",
      " mRUURN  m    m ",
      " mffffN  mmmumm ",
      "  f   fmLmEB pm ",
      "  f V f  mF  qm ",
      "  f W O  m   qm ",
      "  fjX f  K  wrm ",
      " mffffP  mmmmmm ",
      " mZ       xxx m ",
      " m0   Q M     m ",
      " m1SYSQM  ICysm ",
      " mmmmmmmmmmmmmm ",
      "                "
    ],
    [
      "                ",
      " 3222mm22mm22mm ",
      " 4       m*  52 ",
      " 4    |  +    2 ",
      " m%  '| ]m($  2 ",
      " mffff|} mmm#m3 ",
      "  ?   fm{m % 62 ",
      "  ?  <f  m    4 ",
      "  /,  ;  m)  74 ",
      "  fX  f  - ^ 82 ",
      " mffff:  mm&mm3 ",
      " m`  [   [    4 ",
      " 2\u0370           4 ",
      " 2\u0371. >       92 ",
      " 322222222222mm ",
      "                "
    ],
    [
      "                ",
      " 3244mm44mm44mm ",
      " 4       m\u0374  \u03722 ",
      " 4       \u0375    4 ",
      " m    \u037a  m    4 ",
      " mffff\u037b  mmm\u0373m3 ",
      "  f   fm\u0377m    2 ",
      "  f,  f  m    4 ",
      "  f\u037d  a  m    4 ",
      "  f   f  \u0376    2 ",
      " mffff\u037c  mmmmm3 ",
      " m            4 ",
      " 2            4 ",
      " 2            2 ",
      " 322424444242mm ",
      "                "
    ],
    [
      "                ",
      " 3222mm22mm22mm ",
      " 4       m    2 ",
      " 4       m    2 ",
      " m       m    2 ",
      " mffff   mmmmm3 ",
      "  f,  fmmm    2 ",
      "  f\u037d  f  m    4 ",
      "  \u0384   f  m    4 ",
      "  \u0384   f\u037c m    2 ",
      " mffff!  mmmmm3 ",
      " m    \u037c       4 ",
      " 2  \u037f      \u037e  4 ",
      " 2            2 ",
      " 322222222222mm ",
      "                "
    ],
    [
      "                ",
      " mmmmmmmmmmmmmm ",
      " m\u0385\u0385\u0385\u0385\u0385\u0385\u0385\u0385\u0385\u0385\u0385\u0385m ",
      " m\u0385\u0385\u0385\u0385\u0385\u0385\u0385\u0385\u0385\u0385\u0385\u0385m ",
      " m\u0385\u0385\u0385\u0385\u0385\u0385\u0385\u0385\u0385\u0385\u0385\u0385m ",
      " mffff\u0385\u0385\u0385\u0385\u0385\u0385\u0385\u0385m ",
      "  f\u037d\u0386 f\u0385\u0385\u0385\u0385\u0385\u0385\u0385m ",
      "  f   f\u0385\u0385\u0385\u0385\u0385\u0385\u0385m ",
      "  f   f\u0385\u0385\u0385\u0385\u0385\u0385\u0385m ",
      "  f   f\u0385\u0385\u0385\u0385\u0385\u0385\u0385m ",
      " mffff\u0385\u0385\u0385\u0385\u0385\u0385\u0385\u0385m ",
      " m\u0385\u0385\u0385\u0385\u0385\u0385\u0385\u0385\u0385\u0385\u0385\u0385m ",
      " m\u0385\u0385\u0385\u0385\u0385\u0385\u0385\u0385\u0385\u0385\u0385\u0385m ",
      " m\u0385\u0385\u0385\u0385\u0385\u0385\u0385\u0385\u0385\u0385\u0385\u0385m ",
      " mmmmmmmmmmmmmm ",
      "                "
    ]
  ]
}