{
  "name": "building_apartmentsmalld_ground_90",
  "refpalette": "deceasedcraft:building_apartmentsmalld/building_apartmentsmalld_ground_palette_90",
  "xsize": 16,
  "zsize": 16,
  "slices": [
    [
      "aaaaaaaaaaaaaaaa",
      "acccccccccccccca",
      "acddddddddddddca",
      "acddddddddddddca",
      "bcddddddddddddca",
      "bddddddddeeeeeca",
      "abdddddddddddeaa",
      "bbdddddddddddeaa",
      "bbdddddddddddeaa",
      "badddddddddddeaa",
      "addddddddeeeeeca",
      "acddddddddddddca",
      "acddddddddddddca",
      "acddddddddddddca",
      "bcccccccccccccca",
      "aaaaaaaaaaaaaaaa"
    ],
    [
      "                ",
      " cccccccccccccc ",
      " cg nnn qswwwsc ",
      " cg           c ",
      " cg       uyBEc ",
      " fh     peeeeec ",
      "  i        xhe  ",
      "  jl         e  ",
      "  jk         e  ",
      "  i          e  ",
      " fh     peeeeec ",
      " cg     orttADc ",
      " cg          Cc ",
      " cg mmm       c ",
      " cccccccccccccc ",
      "                "
    ],
    [
      "                ",
      " ffIIIIILccffff ",
      " fF     NOOOOOI ",
      " cF           I ",
      " cF          Sc ",
      " fh     Meeeeec ",
      "  i         xe  ",
      "   K        PR  ",
      "   J         Q  ",
      "  i          Q  ",
      " fh     Meeeeec ",
      " cF           c ",
      " cF           L ",
      " fF           L ",
      " ffIIIIILccIILf ",
      "                "
    ],
    [
      "                ",
      " ffIIIIILccffff ",
      " fF     NOOOOOI ",
      " cU           I ",
      " cF           c ",
      " fh     Veeeeec ",
      "  i          e  ",
      "  i         Xe  ",
      "  i         Pe  ",
      "  i          e  ",
      " fh     Veeeeec ",
      " cT         W c ",
      " cF           L ",
      " fF           L ",
      " ffIIIIILccIILf ",
      "                "
    ],
    [
      "                ",
      " ffIIIIILccffff ",
      " fh     YgggggI ",
      " ch           I ",
      " ch           c ",
      " fh      eeeeec ",
      "  h          Z  ",
      "  h          Z  ",
      "  h         Xe  ",
      "  h         Pe  ",
      " fh      eeeeec ",
      " ch           c ",
      " ch           L ",
      " fh           L ",
      " ffIIIIILccIILf ",
      "                "
    ],
    [
      "                ",
      " cccccccccccccc ",
      " cddddddddddddc ",
      " cddddddddddddc ",
      " cddddddddddddc ",
      " cdddddddeeeeec ",
      " cddddddd0   e  ",
      " cddddddd0   e  ",
      " cddddddd0   e  ",
      " cddddddd0 1Xe  ",
      " cdddddddeeeeec ",
      " cddddddddddddc ",
      " cddddddddddddc ",
      " cddddddddddddc ",
      " cccccccccccccc ",
      "                "
    ]
  ]
}