{
  "name": "multi_nuclearpowerplant_2_base7",
  "refpalette": "deceasedcraft:multi_nuclearpowerplant_2/multi_nuclearpowerplant_2_base7_palette",
  "xsize": 16,
  "zsize": 16,
  "slices": [
    [
      "vaaaaaaaabcccccc",
      "vaaaaaaabccccccc",
      "vaaaaaaabccccccc",
      "vaaaaaabcccccccc",
      "vaaaaaabcccccccc",
      "vaaaaabccccccccc",
      "vaaaaabccccccccc",
      "vaaaaabccccccccc",
      "vaaaabcccccccccc",
      "vaaaabcccccccccc",
      "vaaaabcccccccccc",
      "vaaaabcccccccccc",
      "vaaabccccccccccc",
      "vaaabccccccccccc",
      "vaaabcccdccccccc",
      "vaaabccccccccccc"
    ],
    [
      "vaaaaaaaabcccccc",
      "vaaaaaaabccccccc",
      "vaaaaaaabccccccc",
      "vaaaaaabcccccccc",
      "vaaaaaabcccccccc",
      "vaaaaabccccccccc",
      "vaaaaabccccccccc",
      "vaaaaabccccccccc",
      "vaaaabcccccccccc",
      "vaaaabcccccccccc",
      "vaaaabcccccccccc",
      "vaaaabcccccccccc",
      "vaaabccccccccccc",
      "vaaabccccccccccc",
      "vaaabcccdccccccc",
      "vaaabccccccccccc"
    ],
    [
      "vaaaaaaaabcccccc",
      "vaaaaaaabccccccc",
      "vaaaaaaabccccccc",
      "vaaaaaabcccccccc",
      "vaaaaaabcccccccc",
      "vaaaaabccccccccc",
      "vaaaaabccccccccc",
      "vaaaaabccccccccc",
      "vaaaabcccccccccc",
      "vaaaabcccccccccc",
      "vaaaabcccccccccc",
      "vaaaabcccccccccc",
      "vaaabccccccccccc",
      "vaaabccccccccccc",
      "vaaabcccdccccccc",
      "vaaabccccccccccc"
    ],
    [
      "vaaaaaaaabcccccc",
      "vaaaaaaabccccccc",
      "vaaaaaaabccccccc",
      "vaaaaaabcccccccc",
      "vaaaaaabcccccccc",
      "vaaaaabccccccccc",
      "vaaaaabccccccccc",
      "vaaaaabccccccccc",
      "vaaaabcccccccccc",
      "vaaaabcccccccccc",
      "vaaaabcccccccccc",
      "vaaaabcccccccccc",
      "vaaabccccccccccc",
      "vaaabccccccccccc",
      "vaaabcccdccccccc",
      "vaaabccccccccccc"
    ],
    [
      "vaaaaaaaabcccccc",
      "vaaaaaaabccccccc",
      "vaaaaaaabccccccc",
      "vaaaaaabcccccccc",
      "vaaaaaabcccccccc",
      "vaaaaabccccccccc",
      "vaaaaabccccccccc",
      "vaaaaabccccccccc",
      "vaaaabcccccccccc",
      "vaaaabcccccccccc",
      "vaaaabcccccccccc",
      "vaaaabcccccccccc",
      "vaaabccccccccccc",
      "vaaabccccccccccc",
      "vaaabcccdccccccc",
      "vaaabccccccccccc"
    ],
    [
      "veeeeeeeebcccccc",
      "veeeeeeebccccccc",
      "veeeeeeebccccccc",
      "veeeeeebcccccccc",
      "veeeeeebcccccccc",
      "veeeeebccccccccc",
      "veeeeebccccccccc",
      "veeeeebccccccccc",
      "veeeebcccccccccc",
      "veeeebcccccccccc",
      "veeeebcccccccccc",
      "veeeebcccccccccc",
      "veeebccccccccccc",
      "veeebccccccccccc",
      "veeebcccdccccccc",
      "veeebccccccccccc"
    ]
  ]
}