{
  "name": "multi_nuclearpowerplant_2_ground",
  "refpalette": "deceasedcraft:multi_nuclearpowerplant_2/multi_nuclearpowerplant_2_ground_palette",
  "xsize": 16,
  "zsize": 16,
  "slices": [
    [
      "zzazaazaaabcc   ",
      "zzazzaaaabbc    ",
      "zazaaaaaabcc    ",
      "zzazaaaabbc     ",
      "zzaaaaaabcc     ",
      "azzaaaabbc      ",
      "zzaaaaabcc      ",
      "zazaaaabc       ",
      "zaaaaabbc       ",
      "aaaaaabcc       ",
      "zzaaaabc        ",
      "zazaaabc        ",
      "aaaaabbc        ",
      "aaaaabcc        ",
      "zaaaabc         ",
      "aaaaabc         "
    ],
    [
      "   d     eacccc ",
      "        fzzccc  ",
      "  d     gaccc   ",
      " d     fzzccc   ",
      "d      ezccc    ",
      " d    fzzccc    ",
      " d    ezccc     ",
      "d     ezccc     ",
      "d    fazcc      ",
      "     fzccc      ",
      "     ezccc      ",
      "     gzcc       ",
      "    fazcc       ",
      "    fzccc       ",
      "    ezccc       ",
      "    ezcc        "
    ],
    [
      "          hzzccc",
      "         hhzcccc",
      "         hzzccc ",
      "        hhzccc  ",
      "        hzzccc  ",
      "       hhzccc   ",
      "       hzzccc   ",
      "       hzccc    ",
      "      hhzccc    ",
      "      hzzccc    ",
      "      hzccc     ",
      "      hzccc     ",
      "     hhzccc     ",
      "     hazcc      ",
      "     hzccc      ",
      "     hzccc      "
    ],
    [
      "          h  zzc",
      "         hh zzcc",
      "         h  zccc",
      "        hh zzccc",
      "        h  zcccc",
      "       hh zzccc ",
      "       h zzcccc ",
      "       h zzccc  ",
      "      hh zzccc  ",
      "      h izccc   ",
      "      h zzccc   ",
      "      h zzccc   ",
      "     hh zccc    ",
      "     h  zccc    ",
      "     h zzccc    ",
      "     h azcc     "
    ],
    [
      "          j   zz",
      "         j  d zz",
      "         j  dzzz",
      "        j  d zzc",
      "        j  kazcc",
      "       j  d zzcc",
      "       j dzzzccc",
      "       j d zzccc",
      "      j  dzzccc ",
      "      j   zzccc ",
      "      j k zzcc  ",
      "      j d zccc  ",
      "     j   zzccc  ",
      "     j  dzzcc   ",
      "     j  dzccc   ",
      "     j  dzccc   "
    ],
    [
      "                ",
      "               z",
      "                ",
      "               z",
      "             kzz",
      "              zc",
      "             zzc",
      "            zzcc",
      "            zacc",
      "           zzccc",
      "            zccc",
      "           zaccc",
      "          lzccc ",
      "          dzccc ",
      "          zzcc  ",
      "          zccc  "
    ]
  ]
}