{
  "name": "multi_nuclearpowerplant_2_base4",
  "refpalette": "deceasedcraft:multi_nuclearpowerplant_2/multi_nuclearpowerplant_2_base4_palette",
  "xsize": 16,
  "zsize": 16,
  "slices": [
    [
      "vaaaaaaaab      ",
      "vaaaaaaab       ",
      "vaaaaaaab       ",
      "vaaaaaab        ",
      "vaaaaaab        ",
      "vaaaaab         ",
      "vaaaaab         ",
      "vaaaaab         ",
      "vaaaab          ",
      "vaaaab          ",
      "vaaaab          ",
      "vaaaab          ",
      "vaaab           ",
      "vaaab           ",
      "vaaab           ",
      "vaaab           "
    ],
    [
      "vaaaaaaaab      ",
      "vaaaaaaab       ",
      "vaaaaaaab       ",
      "vaaaaaab        ",
      "vaaaaaab        ",
      "vaaaaab         ",
      "vaaaaab         ",
      "vaaaaab         ",
      "vaaaab          ",
      "vaaaab          ",
      "vaaaab          ",
      "vaaaab          ",
      "vaaab           ",
      "vaaab           ",
      "vaaab           ",
      "vaaab           "
    ],
    [
      "vaaaaaaaab      ",
      "vaaaaaaab       ",
      "vaaaaaaab       ",
      "vaaaaaab        ",
      "vaaaaaab        ",
      "vaaaaab         ",
      "vaaaaab         ",
      "vaaaaab         ",
      "vaaaab          ",
      "vaaaab          ",
      "vaaaab          ",
      "vaaaab          ",
      "vaaab           ",
      "vaaab           ",
      "vaaab           ",
      "vaaab           "
    ],
    [
      "vaaaaaaaab      ",
      "vaaaaaaab       ",
      "vaaaaaaab       ",
      "vaaaaaab        ",
      "vaaaaaab        ",
      "vaaaaab         ",
      "vaaaaab         ",
      "vaaaaab         ",
      "vaaaab          ",
      "vaaaab          ",
      "vaaaab          ",
      "vaaaab          ",
      "vaaab           ",
      "vaaab           ",
      "vaaab           ",
      "vaaab           "
    ],
    [
      "vaaaaaaaab      ",
      "vaaaaaaab       ",
      "vaaaaaaab       ",
      "vaaaaaab        ",
      "vaaaaaab        ",
      "vaaaaab         ",
      "vaaaaab         ",
      "vaaaaab         ",
      "vaaaab          ",
      "vaaaab          ",
      "vaaaab          ",
      "vaaaab          ",
      "vaaab           ",
      "vaaab           ",
      "vaaab           ",
      "vaaab           "
    ],
    [
      "vaaaaaaaab      ",
      "vaaaaaaab       ",
      "vaaaaaaab       ",
      "vaaaaaab        ",
      "vaaaaaab        ",
      "vaaaaab         ",
      "vaaaaab         ",
      "vaaaaab         ",
      "vaaaab          ",
      "vaaaab          ",
      "vaaaab          ",
      "vaaaab          ",
      "vaaab           ",
      "vaaab           ",
      "vaaab           ",
      "vaaab           "
    ]
  ]
}