{
  "name": "multi_nuclearpowerplant_2_base3",
  "refpalette": "deceasedcraft:multi_nuclearpowerplant_2/multi_nuclearpowerplant_2_base3_palette",
  "xsize": 16,
  "zsize": 16,
  "slices": [
    [
      "vaa      bccccc ",
      "vaa     bccccc  ",
      "vaa     bcccc   ",
      "vaa    bccccc   ",
      "vaa    bcccc    ",
      "vaa   bccccc    ",
      "vaa   bccccc    ",
      "vaa   bcccc     ",
      "vaa  bccccc     ",
      "vaa  bccccc     ",
      "vaa  bcccc      ",
      "vaa  bcccc      ",
      "vaa bccccc      ",
      "vaa bcccc       ",
      "vaa bcccc       ",
      "vaa bcccc       "
    ],
    [
      "v d      e    f ",
      "v d     e    f  ",
      "v d     e   g   ",
      "v d    e    f   ",
      "v d    eh  g    ",
      "v d   e    g    ",
      "v d   e    f    ",
      "v d   e   g     ",
      "v d  e    g     ",
      "v d  e    f     ",
      "v d  e   g      ",
      "v d  e   g      ",
      "v d e    f      ",
      "v d e   g       ",
      "v d eh  g       ",
      "v d e   g       "
    ],
    [
      "v        e      ",
      "v       e       ",
      "v       e       ",
      "v      e        ",
      "v      e        ",
      "v     e         ",
      "v     e         ",
      "v     e         ",
      "v    e          ",
      "v    e          ",
      "v    e          ",
      "v    e          ",
      "v   e           ",
      "v   e           ",
      "v   e           ",
      "v   e           "
    ],
    [
      "v        e      ",
      "v       e       ",
      "v       e       ",
      "v      e        ",
      "v      e        ",
      "v     e         ",
      "v     e         ",
      "v     e         ",
      "v    e          ",
      "v    e          ",
      "v    e          ",
      "v    e          ",
      "v   e           ",
      "v   e           ",
      "v   e           ",
      "v   e           "
    ],
    [
      "v        e      ",
      "v       e       ",
      "v       e       ",
      "v      e        ",
      "v      e        ",
      "v     e         ",
      "v     e         ",
      "v     e         ",
      "v    e          ",
      "v    e          ",
      "v    e          ",
      "v    e          ",
      "v   e           ",
      "v   e           ",
      "v   e           ",
      "v   e           "
    ],
    [
      "v        e      ",
      "v       e       ",
      "v       e       ",
      "v      e        ",
      "v      e        ",
      "v     e         ",
      "v     e         ",
      "v     e         ",
      "v    e          ",
      "v    e          ",
      "v    e          ",
      "v    e          ",
      "v   e           ",
      "v   e           ",
      "v   e           ",
      "v   e           "
    ]
  ]
}