{
  "name": "multi_nuclearpowerplant_2_base6",
  "refpalette": "deceasedcraft:multi_nuclearpowerplant_2/multi_nuclearpowerplant_2_base6_palette",
  "xsize": 16,
  "zsize": 16,
  "slices": [
    [
      "vvvvvvvvva      ",
      "vvvvvvvva       ",
      "vvvvvvvva       ",
      "vvvvvvva        ",
      "vvvvvvvab       ",
      "vvvvvva         ",
      "vvvvvva         ",
      "vvvvvva         ",
      "vvvvva          ",
      "vvvvva          ",
      "vvvvva          ",
      "vvvvva          ",
      "vvvva           ",
      "vvvva           ",
      "vvvvab  c       ",
      "vvvva           "
    ],
    [
      "vdddddddde      ",
      "vddddddde       ",
      "vddddddde       ",
      "vdddddde        ",
      "vdddddde        ",
      "vddddde         ",
      "vddddde         ",
      "vddddde         ",
      "vdddde          ",
      "vdddde          ",
      "vdddde          ",
      "vdddde          ",
      "vddde           ",
      "vddde           ",
      "vddde   f       ",
      "vddde           "
    ],
    [
      "vgggggggge      ",
      "vggggggge       ",
      "vggggggge       ",
      "vgggggge        ",
      "vgggggge        ",
      "vggggge         ",
      "vggggge         ",
      "vggggge         ",
      "vgggge          ",
      "vgggge          ",
      "vgggge          ",
      "vgggge          ",
      "vgghe           ",
      "vgghe          i",
      "vgghe   f      j",
      "vgghe          k"
    ],
    [
      "vgggggggge      ",
      "vggggggge       ",
      "vggggggge       ",
      "vgggggge        ",
      "vgggggge        ",
      "vggggge         ",
      "vggggge         ",
      "vggggge         ",
      "vgggge          ",
      "vgggge          ",
      "vgggge          ",
      "vgggge          ",
      "vggle           ",
      "vggle         i ",
      "vggle   f     j ",
      "vggle         k "
    ],
    [
      "vgggggggge      ",
      "vggggggge       ",
      "vggggggge       ",
      "vgggggge        ",
      "vgggggge        ",
      "vggggge         ",
      "vggggge         ",
      "vggggge         ",
      "vgggge          ",
      "vgggge          ",
      "vgggge          ",
      "vgggge          ",
      "vggle           ",
      "vggle        i  ",
      "vggle   f    j  ",
      "vggle        k  "
    ],
    [
      "vgggggggge      ",
      "vggggggge       ",
      "vggggggge       ",
      "vgggggge        ",
      "vgggggge        ",
      "vggggge         ",
      "vggggge         ",
      "vggggge         ",
      "vgggge          ",
      "vgggge          ",
      "vgggge          ",
      "vgggge          ",
      "vggle           ",
      "vggle       i   ",
      "vggle   f   j   ",
      "vggle       k   "
    ]
  ]
}