{
  "name": "multi_nuclearpowerplant_2_base1",
  "refpalette": "deceasedcraft:multi_nuclearpowerplant_2/multi_nuclearpowerplant_2_base1_palette",
  "xsize": 16,
  "zsize": 16,
  "slices": [
    [
      "vaaaaaaaabzccccc",
      "vaaaaaaabzcccccc",
      "vaaaaaaabzcccccc",
      "vaaaaaabzccccccc",
      "vaaaaaabzccccccc",
      "vaaaaabzcccccccc",
      "vaaaaabzcccccccc",
      "vaaaaabzcccccccc",
      "vaaaabzccccccccc",
      "vaaaabzccccccccc",
      "vaaaabzccccccccc",
      "vaaaabzccccccccc",
      "vaaabddddccccccc",
      "vaaabddddccccccc",
      "vaaabddddccccccc",
      "vaaabddddccccccc"
    ],
    [
      "veeeeeeeefg     ",
      "veeeeeeefg      ",
      "veeeeeeefg      ",
      "veeeeeefg       ",
      "veeeeeefg       ",
      "veeeeefg        ",
      "veeeeefg        ",
      "veeeeefg        ",
      "veeeefg h       ",
      "veeeefg i       ",
      "veeeefg j       ",
      "veeeefg         ",
      "veeefkkkk       ",
      "veeef           ",
      "veeef           ",
      "veeefll         "
    ],
    [
      "veeeeeeeef      ",
      "veeeeeeef       ",
      "veeeeeeef       ",
      "veeeeeef        ",
      "veeeeeef        ",
      "veeeeef         ",
      "veeeeef         ",
      "veeeeef         ",
      "veeeef          ",
      "veeeef          ",
      "veeeef          ",
      "veeeef          ",
      "veeef           ",
      "veeef           ",
      "veeef           ",
      "veeef           "
    ],
    [
      "veeeeeeeef      ",
      "veeeeeeef       ",
      "veeeeeeef       ",
      "veeeeeef        ",
      "veeeeeef        ",
      "veeeeef         ",
      "veeeeef         ",
      "veeeeef         ",
      "veeeef          ",
      "veeeef          ",
      "veeeef          ",
      "veeeef          ",
      "veeef           ",
      "veeef           ",
      "veeef           ",
      "veeef           "
    ],
    [
      "veeeeeeeef      ",
      "veeeeeeef       ",
      "veeeeeeef       ",
      "veeeeeef        ",
      "veeeeeefm       ",
      "veeeeef         ",
      "veeeeef         ",
      "veeeeef         ",
      "veeeef          ",
      "veeeef          ",
      "veeeef          ",
      "veeeef          ",
      "veeef           ",
      "veeef           ",
      "veeefm          ",
      "veeef           "
    ],
    [
      "veeeeeeeefn     ",
      "veeeeeeefnn     ",
      "veeeeeeefn      ",
      "veeeeeefnn      ",
      "veeeeeefn       ",
      "veeeeefnn       ",
      "veeeeefn        ",
      "veeeeefn        ",
      "veeeefnn        ",
      "veeeefn         ",
      "veeeefn         ",
      "veeeefn         ",
      "veeefnn         ",
      "veeefn          ",
      "veeefn          ",
      "veeefn          "
    ]
  ]
}