{
  "name": "multi_nuclearpowerplant_2_base5",
  "refpalette": "deceasedcraft:multi_nuclearpowerplant_2/multi_nuclearpowerplant_2_base5_palette",
  "xsize": 16,
  "zsize": 16,
  "slices": [
    [
      "vaaaaaaaab      ",
      "vaaaaaaab       ",
      "vaaaaaaab       ",
      "vaaaaaab        ",
      "vaaaaaab        ",
      "vaaaaab         ",
      "vaaaaab         ",
      "vaaaaab         ",
      "vaaaab          ",
      "vaaaab          ",
      "vaaaab          ",
      "vaaaab          ",
      "vaacb           ",
      "vaadeffffffg    ",
      "vaadefffhffi    ",
      "vaadeffffffj    "
    ],
    [
      "vaaaaaaaab      ",
      "vaaaaaaab       ",
      "vaaaaaaab       ",
      "vaaaaaab        ",
      "vaaaaaab        ",
      "vaaaaab         ",
      "vaaaaab         ",
      "vaaaaab         ",
      "vaaaab          ",
      "vaaaab          ",
      "vaaaab          ",
      "vaaaab          ",
      "vaacb           ",
      "vaak llllll     ",
      "vaakm           ",
      "vaak nnnn       "
    ],
    [
      "vaaaaaaaab      ",
      "vaaaaaaab       ",
      "vaaaaaaab       ",
      "vaaaaaab        ",
      "vaaaaaab        ",
      "vaaaaab         ",
      "vaaaaab         ",
      "vaaaaab         ",
      "vaaaab          ",
      "vaaaab          ",
      "vaaaab          ",
      "vaaaab          ",
      "vaacb           ",
      "vaao            ",
      "vaaop           ",
      "vaao            "
    ],
    [
      "vaaaaaaaab      ",
      "vaaaaaaab       ",
      "vaaaaaaab       ",
      "vaaaaaab        ",
      "vaaaaaab        ",
      "vaaaaab         ",
      "vaaaaab         ",
      "vaaaaab         ",
      "vaaaab          ",
      "vaaaab          ",
      "vaaaab          ",
      "vaaaab          ",
      "vaacb           ",
      "vaaq            ",
      "vaaqr           ",
      "vaaq            "
    ],
    [
      "vaaaaaaaab      ",
      "vaaaaaaab       ",
      "vaaaaaaab       ",
      "vaaaaaab        ",
      "vaaaaaab        ",
      "vaaaaab         ",
      "vaaaaab         ",
      "vaaaaab         ",
      "vaaaab          ",
      "vaaaab          ",
      "vaaaab          ",
      "vaaaab          ",
      "vaacb           ",
      "vaas            ",
      "vaas            ",
      "vaas            "
    ],
    [
      "vaaaaaaaab      ",
      "vaaaaaaab       ",
      "vaaaaaaab       ",
      "vaaaaaab        ",
      "vaaaaaab        ",
      "vaaaaab         ",
      "vaaaaab         ",
      "vaaaaab         ",
      "vaaaab          ",
      "vaaaab          ",
      "vaaaab          ",
      "vaaaab          ",
      "vaacb           ",
      "vaacb           ",
      "vaacb           ",
      "vaacb           "
    ]
  ]
}