{
  "name": "multi_nuclearpowerplant_2_base11",
  "refpalette": "deceasedcraft:multi_nuclearpowerplant_2/multi_nuclearpowerplant_2_base11_palette",
  "xsize": 16,
  "zsize": 16,
  "slices": [
    [
      "vaaabcdeeeedc   ",
      "vaaabcdeeeedc   ",
      "vaaabc dddd c   ",
      "vaaabc      c   ",
      "vaaabc      c   ",
      "vaaabc      @   ",
      "vaaabcfg    @   ",
      "vaaabc      @   ",
      "vaaabc      @   ",
      "vaaabc      @   ",
      "vaaabc      @   ",
      "vaaabc      @   ",
      "vaaabc      @   ",
      "vaaabcfddddh@   ",
      "vaaabci    j@   ",
      "vaaabc     j@   "
    ],
    [
      "vaaabcdeeeedc   ",
      "vaaabcdeeeedc   ",
      "vaaabc dddd c   ",
      "vaaabc      c   ",
      "vaaabc      c   ",
      "vaaabc      @   ",
      "vaaabcfg    @   ",
      "vaaabc      @   ",
      "vaaabc      @   ",
      "vaaabc      @   ",
      "vaaabc      @   ",
      "vaaabc      @   ",
      "vaaabc      @   ",
      "vaaabcfddddh@   ",
      "vaaabci    j@   ",
      "vaaabc     j@   "
    ],
    [
      "vaaabcdeeeedc   ",
      "vaaabcdeeeedc   ",
      "vaaabc dddd c   ",
      "vaaabc      c   ",
      "vaaabc     kc   ",
      "vaaabc     lc   ",
      "vaaabcfg   lc   ",
      "vaaabc     lc   ",
      "vaaabc     lc   ",
      "vaaabc     lc   ",
      "vaaabc     lc   ",
      "vaaabc     lc   ",
      "vaaabcmnnnnlc   ",
      "vaaabcfoooopc   ",
      "vaaabcqqqqqqc   ",
      "vaaabc      c   "
    ],
    [
      "vaaabcdeeeedc   ",
      "vaaabcdeeeedc   ",
      "vaaabc dddd c   ",
      "vaaabc      c   ",
      "vaaabc      c   ",
      "vaaabc    rsc   ",
      "vaaabcfg  rtc   ",
      "vaaabc    rsc   ",
      "vaaabc      c   ",
      "vaaabc      c   ",
      "vaaabc      c   ",
      "vaaabc      c   ",
      "vaaabc    rsc   ",
      "vaaabcf   ruc   ",
      "vaaabc    rsc   ",
      "vaaabc      c   "
    ],
    [
      "vaaabcdwwwwdc   ",
      "vaaabcdwwwwdc   ",
      "vaaabc dddd c   ",
      "vaaabc      c   ",
      "vaaabc      c   ",
      "vaaabc    rxc   ",
      "vaaabcfg  yAc   ",
      "vaaabc    rBc   ",
      "vaaabc      c   ",
      "vaaabc      c   ",
      "vaaabc      c   ",
      "vaaabc      c   ",
      "vaaabc    rxc   ",
      "vaaabcf   CDc   ",
      "vaaabc    rBc   ",
      "vaaabc      c   "
    ],
    [
      "vaaabcdbbbbdc   ",
      "vaaabcdbbbbdc   ",
      "vaaabc dddd c   ",
      "vaaabc      c   ",
      "vaaabc      c   ",
      "vaaabc    rxc   ",
      "vaaabcfg   Ec   ",
      "vaaabc    rBc   ",
      "vaaabc      c   ",
      "vaaabc      c   ",
      "vaaabc      c   ",
      "vaaabc      c   ",
      "vaaabc    rsc   ",
      "vaaabcf   yFc   ",
      "vaaabc    rsc   ",
      "vaaabc      c   "
    ]
  ]
}