{
  "name": "multi_nuclearpowerplant_2_base8",
  "refpalette": "deceasedcraft:multi_nuclearpowerplant_2/multi_nuclearpowerplant_2_base8_palette",
  "xsize": 16,
  "zsize": 16,
  "slices": [
    [
      "vaaabbcddddddddd",
      "vaaabbcddddddddd",
      "vaaabbcddddddddd",
      "vaaabbcddddddddd",
      "vaaabbcddddddddd",
      "vaaabbcddddddddd",
      "vaaabbcddddddddd",
      "vaaabbcddddddddd",
      "vaaabbcddddddddd",
      "vaaabbcddddddddd",
      "vaaabbcddddddddd",
      "vaaabbcddddddddd",
      "vaaabbcddddddddd",
      "vaaabbcddddddddd",
      "vaaabbcddddddddd",
      "vaaabbcddddddddd"
    ],
    [
      "vaaabbbbbeffffff",
      "vaaabbbbefffffff",
      "vaaabbbbefffffff",
      "vaaabbbeffffffff",
      "vaaabbbeffffffff",
      "vaaabbefffffffff",
      "vaaabbefffffffff",
      "vaaabbefffffffff",
      "vaaabeffffffffff",
      "vaaabeffffffffff",
      "vaaabeffffffffff",
      "vaaabeffffffffff",
      "vaaaefffffffffff",
      "vaaaefffffffffff",
      "vaaaefffffffffff",
      "vaaaefffffffffff"
    ],
    [
      "vaaaaaaaaghhhhhh",
      "vaaaaaaaghhhhhhh",
      "vaaaaaaaghhhhhhh",
      "vaaaaaaghhhhhhhh",
      "vaaaaaaghhhhhhhh",
      "vaaaaaghhhhhhhhh",
      "vaaaaaghhhhhhhhh",
      "vaaaaaghhhhhhhhh",
      "vaaaaghhhhhhhhhh",
      "vaaaaghhhhhhhhhh",
      "vaaaaghhhhhhhhhh",
      "vaaaaghhhhhhhhhh",
      "vaaaghhhhhhhhhhh",
      "vaaaghhhhhhhhhhh",
      "vaaaghhhihhhhhhh",
      "vaaaghhhhhhhhhhh"
    ],
    [
      "vaaaaaaaaghhhhhh",
      "vaaaaaaaghhhhhhh",
      "vaaaaaaaghhhhhhh",
      "vaaaaaaghhhhhhhh",
      "vaaaaaaghhhhhhhh",
      "vaaaaaghhhhhhhhh",
      "vaaaaaghhhhhhhhh",
      "vaaaaaghhhhhhhhh",
      "vaaaaghhhhhhhhhh",
      "vaaaaghhhhhhhhhh",
      "vaaaaghhhhhhhhhh",
      "vaaaaghhhhhhhhhh",
      "vaaaghhhhhhhhhhh",
      "vaaaghhhhhhhhhhh",
      "vaaaghhhjhhhhhhh",
      "vaaaghhhhhhhhhhh"
    ],
    [
      "vaaaaaaaaghhhhhh",
      "vaaaaaaaghhhhhhh",
      "vaaaaaaaghhhhhhh",
      "vaaaaaaghhhhhhhh",
      "vaaaaaaghhhhhhhh",
      "vaaaaaghhhhhhhhh",
      "vaaaaaghhhhhhhhh",
      "vaaaaaghhhhhhhhh",
      "vaaaaghhhhhhhhhh",
      "vaaaaghhhhhhhhhh",
      "vaaaaghhhhhhhhhh",
      "vaaaaghhhhhhhhhh",
      "vaaaghhhhhhhhhhh",
      "vaaaghhhhhhhhhhh",
      "vaaaghhhjhhhhhhh",
      "vaaaghhhhhhhhhhh"
    ],
    [
      "vaaaaaaaaghhhhhh",
      "vaaaaaaaghhhhhhh",
      "vaaaaaaaghhhhhhh",
      "vaaaaaaghhhhhhhh",
      "vaaaaaaghhhhhhhh",
      "vaaaaaghhhhhhhhh",
      "vaaaaaghhhhhhhhh",
      "vaaaaaghhhhhhhhh",
      "vaaaaghhhhhhhhhh",
      "vaaaaghhhhhhhhhh",
      "vaaaaghhhhhhhhhh",
      "vaaaaghhhhhhhhhh",
      "vaaaghhhhhhhhhhh",
      "vaaaghhhhhhhhhhh",
      "vaaaghhhjhhhhhhh",
      "vaaaghhhhhhhhhhh"
    ]
  ]
}