{
  "name": "multi_nuclearpowerplant_2_base10",
  "refpalette": "deceasedcraft:multi_nuclearpowerplant_2/multi_nuclearpowerplant_2_base10_palette",
  "xsize": 16,
  "zsize": 16,
  "slices": [
    [
      "vaaabcbbbbbbc   ",
      "vaaabcbbbbbbc   ",
      "vaaabcdbbbbdc   ",
      "vaaabcedddd c   ",
      "vaaabceffff c   ",
      "vaaabce   ghc   ",
      "vaaabcij  klc   ",
      "vaaabce   gmc   ",
      "vaaabce     c   ",
      "vaaabce     c   ",
      "vaaabce     c   ",
      "vaaabce     c   ",
      "vaaabce   gnc   ",
      "vaaabci   goc   ",
      "vaaabce   gnc   ",
      "vaaabce     c   "
    ],
    [
      "vaaabc      c   ",
      "vaaabc      c   ",
      "vaaabc      c   ",
      "vaaabcp     c   ",
      "vaaabcp     c   ",
      "vaaabcp   ghc   ",
      "vaaabc    qrc   ",
      "vaaabcp   gmc   ",
      "vaaabcp     c   ",
      "vaaabcp     c   ",
      "vaaabcp     c   ",
      "vaaabcp     c   ",
      "vaaabcp     c   ",
      "vaaabcp    sc   ",
      "vaaabcp     c   ",
      "vaaabcp     c   "
    ],
    [
      "vaaabc      c   ",
      "vaaabc      c   ",
      "vaaabc      c   ",
      "vaaabc      c   ",
      "vaaabc      c   ",
      "vaaabc    gnc   ",
      "vaaabc    goc   ",
      "vaaabc    gnc   ",
      "vaaabc      c   ",
      "vaaabc      c   ",
      "vaaabc      c   ",
      "vaaabc      c   ",
      "vaaabc      c   ",
      "vaaabc     sc   ",
      "vaaabc      c   ",
      "vaaabc      c   "
    ],
    [
      "vaaabc      c   ",
      "vaaabc      c   ",
      "vaaabc      c   ",
      "vaaabc      c   ",
      "vaaabc      c   ",
      "vaaabc      c   ",
      "vaaabc     sc   ",
      "vaaabc      c   ",
      "vaaabc      c   ",
      "vaaabc      c   ",
      "vaaabc      c   ",
      "vaaabc      c   ",
      "vaaabc      c   ",
      "vaaabc     sc   ",
      "vaaabc      c   ",
      "vaaabc      c   "
    ],
    [
      "vaaabc      c   ",
      "vaaabc      c   ",
      "vaaabc      c   ",
      "vaaabc      c   ",
      "vaaabc      c   ",
      "vaaabc      c   ",
      "vaaabc sssssc   ",
      "vaaabc      c   ",
      "vaaabc      c   ",
      "vaaabc      c   ",
      "vaaabc      c   ",
      "vaaabc      c   ",
      "vaaabc      c   ",
      "vaaabc sssssc   ",
      "vaaabc      c   ",
      "vaaabc      c   "
    ],
    [
      "vaaabc      c   ",
      "vaaabc      c   ",
      "vaaabc      c   ",
      "vaaabc      c   ",
      "vaaabc      c   ",
      "vaaabc      c   ",
      "vaaabc s    c   ",
      "vaaabc      c   ",
      "vaaabc      c   ",
      "vaaabc      c   ",
      "vaaabc      c   ",
      "vaaabc      c   ",
      "vaaabc      c   ",
      "vaaabc s    c   ",
      "vaaabc      c   ",
      "vaaabc      c   "
    ]
  ]
}