{
  "name": "multi_nuclearpowerplant_2_base12",
  "refpalette": "deceasedcraft:multi_nuclearpowerplant_2/multi_nuclearpowerplant_2_base12_palette",
  "xsize": 16,
  "zsize": 16,
  "slices": [
    [
      "vaaaaaaaaaaaaaaa",
      "vaaaaaaaaaaaaaaa",
      "vaaaaaaaaaaaaaaa",
      "vaaaaaaaaaaaaaaa",
      "vaaaaaaaaaaaaaaa",
      "vaaaaaaaaaaaaaaa",
      "vaaaaaaaaaaaaaaa",
      "vaaaaaaaaaaaaaaa",
      "vaaaaaaaaaaaaaaa",
      "vaaaaaaaaaaaaaaa",
      "vaaaaaaaaaaaaaaa",
      "vaaaaaaaaaaaaaaa",
      "vaaaaaaaaaaaaaaa",
      "vaaaaaaaaaaaaaaa",
      "vaaaaaaaaaaaaaaa",
      "vaaaaaaaaaaaaaaa"
    ],
    [
      "vaaabbbbbbbbbbbb",
      "vaaabbbbbbbbbbbb",
      "vaaabbbbbbbbbbbb",
      "vaaabbbbbbbbbbbb",
      "vaaabbbbbbbbbbbb",
      "vaaabbbbbbbbbbbb",
      "vaaabbbbbbbbbbbb",
      "vaaabbbbbbbbbbbb",
      "vaaabbbbbbbbbbbb",
      "vaaabbbbbbbbbbbb",
      "vaaabbbbbbbbbbbb",
      "vaaabbbbbbbbbbbb",
      "vaaabbbbbbbbbbbb",
      "vaaabbbbbbbbbbbb",
      "vaaabbbbbbbbbbbb",
      "vaaabbbbbbbbbbbb"
    ],
    [
      "vaaabc======cddd",
      "vaaabc======cddd",
      "vaaabcc====ccddd",
      "vaaabceccccecddd",
      "vaaabceeeeeecddd",
      "vaaabceeeeeecddd",
      "vaaabceeeeeecddd",
      "vaaabceeeeeecddd",
      "vaaabceeeeeecddd",
      "vaaabceeeeeecddd",
      "vaaabceeeeeecddd",
      "vaaabceeeeeecddd",
      "vaaabceeeeeecddd",
      "vaaabceeeeeecddd",
      "vaaabceeeeeecddd",
      "vaaabceeeeeecddd"
    ],
    [
      "vaaabfbbbbbbf   ",
      "vaaabfbbbbbbf   ",
      "vaaabfgbbbbgf   ",
      "vaaabf gggg f   ",
      "vaaabfhiiiijf   ",
      "vaaabfkl mn f   ",
      "vaaabfop  q f   ",
      "vaaabfr  sq f   ",
      "vaaabfr  tq f   ",
      "vaaabfr   u f   ",
      "vaaabf      f   ",
      "vaaabf  s w f   ",
      "vaaabfxyyAB f   ",
      "vaaabfoCCCCDf   ",
      "vaaabfEEEEEEf   ",
      "vaaabfFFFFFFf   "
    ],
    [
      "vaaabfIbbbbIf   ",
      "vaaabfIbbbbIf   ",
      "vaaabf IIII f   ",
      "vaaabf      f   ",
      "vaaabf      f   ",
      "vaaabfJ     @   ",
      "vaaabfop  K @   ",
      "vaaabf    L @   ",
      "vaaabf    M @   ",
      "vaaabf    N @   ",
      "vaaabf      @   ",
      "vaaabf      @   ",
      "vaaabfNwO   @   ",
      "vaaabfoIIIIP@   ",
      "vaaabfQ    R@   ",
      "vaaabf     R@   "
    ],
    [
      "vaaabfISSSSIf   ",
      "vaaabfISSSSIf   ",
      "vaaabf IIII f   ",
      "vaaabf      f   ",
      "vaaabf      f   ",
      "vaaabf      @   ",
      "vaaabfop    @   ",
      "vaaabfT     @   ",
      "vaaabfU     @   ",
      "vaaabf      @   ",
      "vaaabf      @   ",
      "vaaabf      @   ",
      "vaaabf      @   ",
      "vaaabfoIIIIP@   ",
      "vaaabfQ    R@   ",
      "vaaabf     R@   "
    ]
  ]
}