{
  "name": "multi_nuclearpowerplant_2_base2",
  "refpalette": "deceasedcraft:multi_nuclearpowerplant_2/multi_nuclearpowerplant_2_base2_palette",
  "xsize": 16,
  "zsize": 16,
  "slices": [
    [
      "v        a      ",
      "v       a       ",
      "v       a       ",
      "v      a        ",
      "v      a        ",
      "v     a         ",
      "v     a         ",
      "v     a         ",
      "v    a          ",
      "v    a          ",
      "v    a          ",
      "v    a          ",
      "v   a           ",
      "v   a           ",
      "v   a           ",
      "v   a           "
    ],
    [
      "v        a      ",
      "v       a       ",
      "v       a       ",
      "v      a        ",
      "v      a        ",
      "v     a         ",
      "v     a         ",
      "v     a         ",
      "v    a          ",
      "v    a          ",
      "v    a          ",
      "v    a          ",
      "v   a           ",
      "v   a           ",
      "v   a           ",
      "v   a           "
    ],
    [
      "v        a      ",
      "v       a       ",
      "v       a       ",
      "v      a        ",
      "v      a        ",
      "v     a         ",
      "v     a         ",
      "v     a         ",
      "v    a          ",
      "v    a          ",
      "v    a          ",
      "v    a          ",
      "v   a           ",
      "v   a           ",
      "v   a           ",
      "v   a           "
    ],
    [
      "v        a      ",
      "v       a       ",
      "v       a       ",
      "v      a        ",
      "v      a        ",
      "v     a         ",
      "v     a         ",
      "v     a         ",
      "v    a          ",
      "v    a          ",
      "v    a          ",
      "v    a          ",
      "v   a           ",
      "v   a           ",
      "v   a           ",
      "v   a           "
    ],
    [
      "v        a      ",
      "v       a       ",
      "v       a       ",
      "v      a        ",
      "v      a        ",
      "v     a         ",
      "v     a         ",
      "v     a         ",
      "v    a          ",
      "v    a          ",
      "v    a          ",
      "v    a          ",
      "v   a           ",
      "v   a           ",
      "v   a           ",
      "v   a           "
    ],
    [
      "v        abbbbbb",
      "v       abbbbbbb",
      "v       abbbbbbb",
      "v      abbbbbbbb",
      "v      abbbbbbbb",
      "v     abbbbbbbbb",
      "v     abbbbbbbbb",
      "v     abbbbbbbbb",
      "v    abbbbbbbbbb",
      "v    abbbbbbbbbb",
      "v    abbbbbbbbbb",
      "v    abbbbbbbbbb",
      "v   a    bbbbbbb",
      "v   a    bbbbbbb",
      "v   a    bbbbbbb",
      "v   a    bbbbbbb"
    ]
  ]
}