{
  "name": "multi_verticalschool_21_base2",
  "refpalette": "deceasedcraft:multi_verticalschool_21/multi_verticalschool_21_base2_palette",
  "xsize": 16,
  "zsize": 16,
  "slices": [
    [
      "vvvvvvvvvvvvvvvv",
      "vvvvvvvvvvvvvvvv",
      "vvvvvvvvvvvvvvvv",
      "vvvvvvvvvvvvvvvv",
      "vvvvvvvvvvvvvvvv",
      "vvvvvvvvvvvvvvvv",
      "vvvvvvvvvvvvvvvv",
      "vvvvvvvvvvvvvvvv",
      "vvvvvvvvvvvvvvvv",
      "vvvvvvvvvvvvvvvv",
      "vvvvvvvvvvvvvvvv",
      "vvvvvvvvvvvvvvvv",
      "vvvvvvvvvvvvvvvv",
      "vvvvvvvvvvvvvvvv",
      "vvvvvvvvvvvvvvvv",
      "vvvvvvvvvvvvvvvv"
    ],
    [
      "aaaaaaaaaaabbbbv",
      "aaaaaaacccabbbbv",
      "aaaaaaaaaaabbbbv",
      "aaaaaaaaaaabbbbv",
      "aaaaaaaaaaabbbbv",
      "aaaaaaaaaaabbbbv",
      "aaaaaaaaaaabbbbv",
      "aaaaaaaaaaabbbbv",
      "aaaaaaaaaaabbbbv",
      "aaaaaaaaaaabbbbv",
      "aaaaaaaaaaabbbbv",
      "aaaaaaaaaaabbbbv",
      "aaaaaaaaaaabbbbv",
      "aaaaaaaaaaabbbbv",
      "aaaaaaaaaaabbbbv",
      "aaaaaaaaaaabbbbv"
    ],
    [
      "aaaaaaaaaaabbbbv",
      "aaaaaaacccabbbbv",
      "aaaaaaaaaaabbbbv",
      "aaaaaaaaaaabbbbv",
      "aaaaaaaaaaabbbbv",
      "aaaaaaaaaaabbbbv",
      "aaaaaaaaaaabbbbv",
      "aaaaaaaaaaabbbbv",
      "aaaaaaaaaaabbbbv",
      "aaaaaaaaaaabbbbv",
      "aaaaaaaaaaabbbbv",
      "aaaaaaaaaaabbbbv",
      "aaaaaaaaaaabbbbv",
      "aaaaaaaaaaabbbbv",
      "aaaaaaaaaaabbbbv",
      "aaaaaaaaaaabbbbv"
    ],
    [
      "HHHHHHHHHdebbbbv",
      "HHHHHHHcccebbbbv",
      "HHHHHHHHHdebbbbv",
      "HHHHHHHHHdebbbbv",
      "HHHHHHHHHdebbbbv",
      "HHHHHHHHHdebbbbv",
      "HHHHHHHHHdebbbbv",
      "HHHHHHHHHdebbbbv",
      "HHHHHHHHHdebbbbv",
      "HHHHHHHHHdebbbbv",
      "HHHHHHHHHdebbbbv",
      "HHHHHHHHHdebbbbv",
      "HHHHHHHHHdebbbbv",
      "HHHHHHHHHdebbbbv",
      "HHHHHHHHHdebbbbv",
      "HHHHHHHHHdebbbbv"
    ],
    [
      "   f      ebbbbv",
      "       cccebbbbv",
      "   g      ebbbbv",
      "hhhihjkl  ebbbbv",
      "mmmmmhj   ebbbbv",
      "mmmmmhj   ebbbbv",
      "mmmmmhj   ebbbbv",
      "hhhihjkn  ebbbbv",
      "   f      ebbbbv",
      "   g      ebbbbv",
      "hhhihjkl  ebbbbv",
      "mmmmmhj   ebbbbv",
      "mmmmmhj   ebbbbv",
      "mmmmmhj   ebbbbv",
      "hhhihjkn  ebbbbv",
      "   f      ebbbbv"
    ],
    [
      "          obbbbv",
      "       cccobbbbv",
      "          obbbbv",
      "ppqrsppt  obbbbv",
      "uuuuuwx   obbbbv",
      "uuuuuwx   obbbbv",
      "uuuuuwx   obbbbv",
      "ppqysppt  obbbbv",
      "          obbbbv",
      "          obbbbv",
      "ppqrsppt  obbbbv",
      "uuuuuwx   obbbbv",
      "uuuuuwx   obbbbv",
      "uuuuuwx   obbbbv",
      "ppqysppt  obbbbv",
      "          obbbbv"
    ]
  ]
}