{
  "name": "multi_verticalschool_21_base1",
  "refpalette": "deceasedcraft:multi_verticalschool_21/multi_verticalschool_21_base1_palette",
  "xsize": 16,
  "zsize": 16,
  "slices": [
    [
      "aaaa a    bccccv",
      "       dddbccccv",
      "eeeeee    bccccv",
      "fffffff   bccccv",
      "ghghgifj  bccccv",
      " k l ifj  bccccv",
      "ghghgifj  bccccv",
      "ffffmff   bccccv",
      "aaaa a    bccccv",
      "eeeeee    bccccv",
      "fffffff   bccccv",
      "ghghgifj  bccccv",
      " k l ifj  bccccv",
      "ghghgifj  bccccv",
      "ffffmff   bccccv",
      "aaaa a    bccccv"
    ],
    [
      "          bccccv",
      "       dddbccccv",
      "          bccccv",
      "nnnnnno   bccccv",
      "      p   bccccv",
      "      p   bccccv",
      "      p   bccccv",
      "nnnnqno   bccccv",
      "          bccccv",
      "          bccccv",
      "nnnnnno   bccccv",
      "      p   bccccv",
      "      p   bccccv",
      "      p   bccccv",
      "nnnnqno   bccccv",
      "          bccccv"
    ],
    [
      "          bccccv",
      "       dddbccccv",
      "          bccccv",
      "rrrrrrs   bccccv",
      "ttttttu   bccccv",
      "www  tu   bccccv",
      "ttttttu   bccccv",
      "rrrrrrs   bccccv",
      "          bccccv",
      "          bccccv",
      "rrrrrrs   bccccv",
      "ttttttu   bccccv",
      "www  tu   bccccv",
      "ttttttu   bccccv",
      "rrrrrrs   bccccv",
      "          bccccv"
    ],
    [
      "          bccccv",
      "       dddbccccv",
      "          bccccv",
      "          bccccv",
      "          bccccv",
      "   xy     bccccv",
      "          bccccv",
      "          bccccv",
      "          bccccv",
      "          bccccv",
      "          bccccv",
      "          bccccv",
      "   xy     bccccv",
      "          bccccv",
      "          bccccv",
      "          bccccv"
    ],
    [
      "          bccccv",
      "       dddbccccv",
      "          bccccv",
      "          bccccv",
      "          bccccv",
      "          bccccv",
      "          bccccv",
      "          bccccv",
      "          bccccv",
      "          bccccv",
      "          bccccv",
      "          bccccv",
      "          bccccv",
      "          bccccv",
      "          bccccv",
      "          bccccv"
    ],
    [
      "AAAAAAAAAABccccv",
      "AAAAAAAdddBccccv",
      "AAAAAAAAAABccccv",
      "AAAAAAAAAABccccv",
      "AAAAAAAAAABccccv",
      "AAAAAAACCABccccv",
      "AAAAAAAAAABccccv",
      "AAAAAAAAAABccccv",
      "AAAAAAAAAABccccv",
      "AAAAAAAAAABccccv",
      "AAAAAAAAAABccccv",
      "AAAAAAAAAABccccv",
      "AAAAAAACCABccccv",
      "AADDAAAAAABccccv",
      "DD  DAAAAABccccv",
      "     DAAAABccccv"
    ]
  ]
}