{
  "name": "multi_verticalschool_21_ground",
  "refpalette": "deceasedcraft:multi_verticalschool_21/multi_verticalschool_21_ground_palette",
  "xsize": 16,
  "zsize": 16,
  "slices": [
    [
      "aaaaaaabcccdccdc",
      "aaaaaaabcccdccdc",
      "aaaaaaabcccdccdc",
      "aaaaaaabcccdccdc",
      "aaaaaaabcccdccdc",
      "aaaaaaabcccdccdc",
      "aaaaaaabcccdccdc",
      "aaaaaaabcccdccdc",
      "aaaaaaabccdeeeec",
      "aaaaaaabddeeffec",
      "bbbbbbbbeeffffec",
      "ccccddeeggggggec",
      "ccddeeffffffffec",
      "ddeeffffffffffec",
      "ee  egggggggggec",
      "     effffffffec"
    ],
    [
      "hhhhhhhij  kllk ",
      "hhhhhhhij  kllk ",
      "hhhhhhhij  kllk ",
      "hhhhhhhij  kllk ",
      "hhhhhhhij  kllk ",
      "hhhhhhhij  kllk ",
      "hhhhhhhij  kllk ",
      "hhhhhhhij  kllk ",
      "hhhhhhhij k     ",
      "hhhhhhhijk      ",
      "iiiiiiiij       ",
      "jjjjjjjjj       ",
      "  kk            ",
      "kkmm            ",
      "mmnom           ",
      "n   om          "
    ],
    [
      "       pq       ",
      "       pq       ",
      "       pq       ",
      " r s   pq       ",
      " r t   pq       ",
      "   t   pq       ",
      "uwwx   pq       ",
      "       pq       ",
      " y     pq       ",
      "y yy   pq       ",
      "AAAABCpiq       ",
      "qqqqqqqqq       ",
      "                ",
      "                ",
      "                ",
      "                "
    ],
    [
      "       pq       ",
      "       pq       ",
      "       pq       ",
      "       pq       ",
      "       pq       ",
      "       pq       ",
      "       pq       ",
      "       pq       ",
      "       pq       ",
      "       pq       ",
      "D  EF piq       ",
      "IIIIIIqqq       ",
      "                ",
      "                ",
      "                ",
      "                "
    ],
    [
      "       pq       ",
      "       pq       ",
      "       pq       ",
      "       pq       ",
      "       pq       ",
      "       pq       ",
      "       pq       ",
      "       pq       ",
      "       pq       ",
      "       pq       ",
      "      piq       ",
      "IIIIIIqqq       ",
      "                ",
      "                ",
      "                ",
      "                "
    ],
    [
      "       pq       ",
      "       pq       ",
      "       pq       ",
      "       pq       ",
      "       pq       ",
      "       pq       ",
      "       pq       ",
      "       pq       ",
      "       pq       ",
      "       pq       ",
      "pppppppiq       ",
      "qqqqqqqqq       ",
      "                ",
      "                ",
      "                ",
      "                "
    ]
  ]
}