{
  "name": "multi_verticalschool_21_floor1",
  "refpalette": "deceasedcraft:multi_verticalschool_21/multi_verticalschool_21_floor1_palette",
  "xsize": 16,
  "zsize": 16,
  "slices": [
    [
      "       ab       ",
      "    c  ab       ",
      "       ab       ",
      "       ab       ",
      "       ab       ",
      "       ab       ",
      "       ab       ",
      "    c  ab       ",
      "       ab       ",
      "       ab       ",
      "aaaaaaadb       ",
      "bbbbbbbbb       ",
      "                ",
      "                ",
      "                ",
      "                "
    ],
    [
      "  efffgdb       ",
      "  efhfgdb       ",
      "  efffgdb       ",
      " effffgdb       ",
      "eeffffgdb       ",
      "ffffffgdb       ",
      "ffffffgdb       ",
      "ffffhfgdb       ",
      "ffffffgdb       ",
      "gggggggdb       ",
      "ddddddddb       ",
      "bbbbbbbbb       ",
      "                ",
      "                ",
      "                ",
      "                "
    ],
    [
      "ifjkkljmb       ",
      "ifjkkkjmb       ",
      "ifjkkkjmb       ",
      "fjllkljmb       ",
      "jjlkkkjmb       ",
      "llkkkljmb       ",
      "kkkklljmb       ",
      "kkkllljmb       ",
      "lllklljmb       ",
      "jjjjjjjmb       ",
      "mmmmmmmmb       ",
      "bbbbbbbbb       ",
      "                ",
      "                ",
      "                ",
      "                "
    ],
    [
      "  n   opq       ",
      "  r   opq       ",
      "  n   opq       ",
      " n    opq       ",
      "rn    opq       ",
      "      opq       ",
      "      opq       ",
      "      opq       ",
      "      opq       ",
      "ooooooopq       ",
      "ppppppppq       ",
      "qqqqqqqqq       ",
      "                ",
      "                ",
      "                ",
      "                "
    ],
    [
      "      s         ",
      "      s         ",
      "      s         ",
      "      s         ",
      "      s         ",
      "      s         ",
      "      s         ",
      "      s         ",
      "      s         ",
      "sssssss         ",
      "                ",
      "                ",
      "                ",
      "                ",
      "                ",
      "                "
    ],
    [
      "                ",
      "                ",
      "                ",
      "                ",
      "                ",
      "                ",
      "                ",
      "                ",
      "                ",
      "                ",
      "                ",
      "                ",
      "                ",
      "                ",
      "                ",
      "                "
    ]
  ]
}