{
  "name": "multi_alienresearch_8_base5",
  "refpalette": "deceasedcraft:multi_alienresearch_8/multi_alienresearch_8_base5_palette",
  "xsize": 16,
  "zsize": 16,
  "slices": [
    [
      "vvvvvvvvvvvvvvvv",
      "aaaaaaaaaaaaaaaa",
      "bccaaaaaaaaaaaaa",
      "dddccaaaaaaaaaaa",
      "   ddccaaaaaaaaa",
      "     ddccaaaaaaa",
      "       ddcaaaaaa",
      "         dcaaaaa",
      "          dbcaaa",
      "           dbaaa",
      "ee          dcaa",
      "ffee         dca",
      "gfffe         dc",
      "hiiffe        dc",
      " hhgfff        d",
      "h  hiffe       d"
    ],
    [
      "vvvvvvvvvvvvvvvv",
      "aaaaaaaaaaaaaaaa",
      "cccaaaaaaaaaaaaa",
      "d  ccaaaaaaaaaaa",
      "     ccaaaaaaaaa",
      "       ccaaaaaaa",
      "         caaaaaa",
      "          caaaaa",
      "           ccaaa",
      "           dcaaa",
      "             caa",
      "              ca",
      "j              c",
      "kjj            c",
      "kkkj            ",
      "kkkkjl          "
    ],
    [
      "vvvvvvvvvvvvvvvv",
      "aaaaaaaaaaaaaaaa",
      "ccmaaaaaaaaaaaaa",
      "d  mmaaaaaaaaaaa",
      "     mmaaaaaaaaa",
      "       mmaaaaaaa",
      "         maaaaaa",
      "          maaaaa",
      "           caaaa",
      "           dcaaa",
      "             maa",
      "              ma",
      "               m",
      "               m",
      "                ",
      "                "
    ],
    [
      "vvvvvvvvvvvvvvvv",
      "aaaaaaaaaaaaaaaa",
      "cmmaaaaaaaaaaaaa",
      "   mmaaaaaaaaaaa",
      "     mmaaaaaaaaa",
      "       mmaaaaaaa",
      "         maaaaaa",
      "          maaaaa",
      "           caaaa",
      "           dcaaa",
      "             maa",
      "              ma",
      "               m",
      "               m",
      "                ",
      "                "
    ],
    [
      "vvvvvvvvvvvvvvvv",
      "aaaaaaaaaaaaaaaa",
      "cmaaaaaaaaaaaaaa",
      "  mmmaaaaaaaaaaa",
      "     mmaaaaaaaaa",
      "       maaaaaaaa",
      "        mmaaaaaa",
      "          maaaaa",
      "           caaaa",
      "           dcaaa",
      "             maa",
      "              ma",
      "              ma",
      "               m",
      "                ",
      "                "
    ],
    [
      "vvvvvvvvvvvvvvvv",
      "aaaaaaaaaaaaaaaa",
      "maaaaaaaaaaaaaaa",
      " mmmaaaaaaaaaaaa",
      "    mmaaaaaaaaaa",
      "      mmaaaaaaaa",
      "        mmaaaaaa",
      "          maaaaa",
      "           caaaa",
      "           dcaaa",
      "             maa",
      "              ma",
      "              ma",
      "               m",
      "               m",
      "                "
    ]
  ]
}