{
  "name": "multi_alienresearch_8_ground",
  "refpalette": "deceasedcraft:multi_alienresearch_8/multi_alienresearch_8_ground_palette",
  "xsize": 16,
  "zsize": 16,
  "slices": [
    [
      "zazzzzzazzazzzaz",
      "zzzazazzzzzazzza",
      "zzazzzazzzazazaz",
      "aazzzzazazazazaz",
      "zzaazzzazzzazazz",
      "zaazazazaazzaaza",
      "azaazzaaazzaazaa",
      "baazzbabaaaazaza",
      "zazazaaazzbazazz",
      "zbaaabzabazzabaa",
      "bbabbabzazbbazbz",
      "bbbbabzbbbbabbzb",
      "bzabbbbabbbabbab",
      "babbbzbbbbbbzbbb",
      "bbbbbbbbbazbbbbb",
      "bbbbbbbzbbbbbbza"
    ],
    [
      "      c         ",
      "             c  ",
      "c   c  c        ",
      "dddddddddddddddd",
      "c   cc   c     c",
      "                ",
      "    c           ",
      "   c        c   ",
      "c   c           ",
      "                ",
      "                ",
      "              c ",
      "                ",
      "                ",
      "                ",
      "       c        "
    ],
    [
      "                ",
      "                ",
      "                ",
      "ddddddddddddddd ",
      "                ",
      "                ",
      "                ",
      "                ",
      "                ",
      "                ",
      "                ",
      "                ",
      "                ",
      "                ",
      "                ",
      "                "
    ],
    [
      "                ",
      "                ",
      "                ",
      "dddddddddddddd d",
      "                ",
      "                ",
      "                ",
      "                ",
      "                ",
      "                ",
      "                ",
      "                ",
      "                ",
      "                ",
      "                ",
      "                "
    ],
    [
      "                ",
      "                ",
      "                ",
      "eeeeeeeeeeeeeee ",
      "                ",
      "                ",
      "                ",
      "                ",
      "                ",
      "                ",
      "                ",
      "                ",
      "                ",
      "                ",
      "                ",
      "                "
    ],
    [
      "                ",
      "                ",
      "                ",
      "                ",
      "                ",
      "                ",
      "                ",
      "                ",
      "                ",
      "                ",
      "                ",
      "                ",
      "                ",
      "                ",
      "                ",
      "                "
    ]
  ]
}