{
  "name": "multi_alienresearch_8_base4",
  "refpalette": "deceasedcraft:multi_alienresearch_8/multi_alienresearch_8_base4_palette",
  "xsize": 16,
  "zsize": 16,
  "slices": [
    [
      "vvvvvvvvvvvvvvvv",
      "aaaaaaaaaaaaaaaa",
      "baaaaaaaaaaaaaaa",
      " bbbaaaaaaaaaaaa",
      "    bbaaaaaaaaaa",
      "      bbaaaaaaaa",
      "        baaaaaaa",
      "         baaaaaa",
      "          bcaaaa",
      "           dcaaa",
      "            baaa",
      "             baa",
      "              ba",
      "               b",
      "               b",
      "                "
    ],
    [
      "vvvvvvvvvvvvvvvv",
      "aaaaaaaaaaaaaaaa",
      "aaaaaaaaaaaaaaaa",
      "bbbaaaaaaaaaaaaa",
      "   bbaaaaaaaaaaa",
      "     bbaaaaaaaaa",
      "       bbaaaaaaa",
      "         baaaaaa",
      "          baaaaa",
      "           caaaa",
      "          d baaa",
      "             baa",
      "              ba",
      "              ba",
      "               b",
      "               b"
    ],
    [
      "vvvvvvvvvvvvvvvv",
      "aaaaaaaaaaaaaaaa",
      "aaaaaaaaaaaaaaaa",
      "bbaaaaaaaaaaaaaa",
      "  bbbaaaaaaaaaaa",
      "     bbaaaaaaaaa",
      "       baaaaaaaa",
      "        baaaaaaa",
      "         bbaaaaa",
      "           caaaa",
      "          d baaa",
      "            baaa",
      "             baa",
      "              ba",
      "               b",
      "               b"
    ],
    [
      "vvvvvvvvvvvvvvvv",
      "aaaaaaaaaaaaaaaa",
      "aaaaaaaaaaaaaaaa",
      "baaaaaaaaaaaaaaa",
      " bbbaaaaaaaaaaaa",
      "    bbaaaaaaaaaa",
      "      bbaaaaaaaa",
      "        baaaaaaa",
      "         baaaaaa",
      "          caaaaa",
      "          dcaaaa",
      "            baaa",
      "             baa",
      "              ba",
      "              ba",
      "               b"
    ],
    [
      "vvvvvvvvvvvvvvvv",
      "aaaaaaaaaaaaaaaa",
      "aaaaaaaaaaaaaaaa",
      "aaaaaaaaaaaaaaaa",
      "bbbaaaaaaaaaaaaa",
      "   bbaaaaaaaaaaa",
      "     bbaaaaaaaaa",
      "       baaaaaaaa",
      "        bbaaaaaa",
      "          caaaaa",
      "          dcaaaa",
      "            baaa",
      "            baaa",
      "             baa",
      "              ba",
      "              ba"
    ],
    [
      "vvvvvvvvvvvvvvvv",
      "aaaaaaaaaaaaaaaa",
      "aaaaaaaaaaaaaaaa",
      "aaaaaaaaaaaaaaaa",
      "baaaaaaaaaaaaaaa",
      " bbbaaaaaaaaaaaa",
      "    bbaaaaaaaaaa",
      "      baaaaaaaaa",
      "       bbaaaaaaa",
      "         baaaaaa",
      "         ecaaaaa",
      "         debaaaa",
      "            baaa",
      "            baaa",
      "             baa",
      "              ba"
    ]
  ]
}