{
  "name": "multi_alienresearch_8_base8",
  "refpalette": "deceasedcraft:multi_alienresearch_8/multi_alienresearch_8_base8_palette",
  "xsize": 16,
  "zsize": 16,
  "slices": [
    [
      "vvvvvvvvvvvvvvvv",
      "aaaaaaaaaaaaaaaa",
      "aaaaaaaaaaaaaaaa",
      "aaaaaaaaaaaaaaaa",
      "aaaaaaaaaaaaaaaa",
      "aaaaaaaaaaaaaaaa",
      "aaaaaaaaaaaaaaaa",
      "aaaaaaaaaaaaaaaa",
      "aaaaaaaaaaaaaaaa",
      "baaaaaaaaaaaaaaa",
      "bbbaaaaaaaaaaaaa",
      "  bbbaaaaaaaaaaa",
      "    bbaaaaaaaaaa",
      "     bcaaaaaaaaa",
      "      ccaaaaaaaa",
      "d    efbbaaaaaaa"
    ],
    [
      "vvvvvvvvvvvvvvvv",
      "aaaaaaaaaaaaaaaa",
      "aaaaaaaaaaaaaaaa",
      "aaaaaaaaaaaaaaaa",
      "aaaaaaaaaaaaaaaa",
      "aaaaaaaaaaaaaaaa",
      "aaaaaaaaaaaaaaaa",
      "aaaaaaaaaaaaaaaa",
      "baaaaaaaaaaaaaaa",
      " bbaaaaaaaaaaaaa",
      "   bbaaaaaaaaaaa",
      "     baaaaaaaaaa",
      "      baaaaaaaaa",
      "       caaaaaaaa",
      "      e baaaaaaa",
      "d     g hbaaaaaa"
    ],
    [
      "vvvvvvvvvvvvvvvv",
      "aaaaaaaaaaaaaaaa",
      "aaaaaaaaaaaaaaaa",
      "aaaaaaaaaaaaaaaa",
      "aaaaaaaaaaaaaaaa",
      "aaaaaaaaaaaaaaaa",
      "aaaaaaaaaaaaaaaa",
      "aaaaaaaaaaaaaaaa",
      "bbbaaaaaaaaaaaaa",
      "   bbaaaaaaaaaaa",
      "     baaaaaaaaaa",
      "      baaaaaaaaa",
      "       ccaaaaaaa",
      "       ecaaaaaaa",
      "         baaaaaa",
      "         ibaaaaa"
    ],
    [
      "vvvvvvvvvvvvvvvv",
      "aaaaaaaaaaaaaaaa",
      "aaaaaaaaaaaaaaaa",
      "aaaaaaaaaaaaaaaa",
      "aaaaaaaaaaaaaaaa",
      "aaaaaaaaaaaaaaaa",
      "aaaaaaaaaaaaaaaa",
      "bbaaaaaaaaaaaaaa",
      "  bbbaaaaaaaaaaa",
      "     baaaaaaaaaa",
      "      baaaaaaaaa",
      "       bcaaaaaaa",
      "        ecaaaaaa",
      "         baaaaaa",
      "          baaaaa",
      "           baaaa"
    ],
    [
      "vvvvvvvvvvvvvvvv",
      "aaaaaaaaaaaaaaaa",
      "aaaaaaaaaaaaaaaa",
      "aaaaaaaaaaaaaaaa",
      "aaaaaaaaaaaaaaaa",
      "aaaaaaaaaaaaaaaa",
      "bbaaaaaaaaaaaaaa",
      "  bbaaaaaaaaaaaa",
      "    bbaaaaaaaaaa",
      "      baaaaaaaaa",
      "       bbaaaaaaa",
      "         caaaaaa",
      "        e baaaaa",
      "          baaaaa",
      "           baaaa",
      "            baaa"
    ],
    [
      "vvvvvvvvvvvvvvvv",
      "aaaaaaaaaaaaaaaa",
      "aaaaaaaaaaaaaaaa",
      "aaaaaaaaaaaaaaaa",
      "aaaaaaaaaaaaaaaa",
      "baaaaaaaaaaaaaaa",
      " bbbaaaaaaaaaaaa",
      "    baaaaaaaaaaa",
      "     bbaaaaaaaaa",
      "       baaaaaaaa",
      "        baaaaaaa",
      "         caaaaaa",
      "        e baaaaa",
      "           baaaa",
      "            baaa",
      "            baaa"
    ]
  ]
}