{
  "name": "multi_alienresearch_8_base7",
  "refpalette": "deceasedcraft:multi_alienresearch_8/multi_alienresearch_8_base7_palette",
  "xsize": 16,
  "zsize": 16,
  "slices": [
    [
      "vvvvvvvvvvvvvvvv",
      "aaaaaaaaaaaaaaaa",
      "aaaaaaaaaaaaaaaa",
      "aaaaaaaaaaaaaaaa",
      "aaaaaaaaaaaaaaaa",
      "bbbaaaaaaaaaaaaa",
      "cccbbaaaaaaaaaaa",
      "   ccbaaaaaaaaaa",
      "     cbbaaaaaaaa",
      "      ccbaaaaaaa",
      "        cdaaaaaa",
      "         cdaaaaa",
      "        e cbaaaa",
      "           cbaaa",
      "           cbaaa",
      "            cbaa"
    ],
    [
      "vvvvvvvvvvvvvvvv",
      "aaaaaaaaaaaaaaaa",
      "aaaaaaaaaaaaaaaa",
      "aaaaaaaaaaaaaaaa",
      "baaaaaaaaaaaaaaa",
      " bbbaaaaaaaaaaaa",
      "    bbaaaaaaaaaa",
      "      baaaaaaaaa",
      "       bbaaaaaaa",
      "         baaaaaa",
      "         fgaaaaa",
      "         cfbaaaa",
      "        h   baaa",
      "       c    baaa",
      "             baa",
      "              ba"
    ],
    [
      "vvvvvvvvvvvvvvvv",
      "aaaaaaaaaaaaaaaa",
      "aaaaaaaaaaaaaaaa",
      "aaaaaaaaaaaaaaaa",
      "bbbaaaaaaaaaaaaa",
      "   bbaaaaaaaaaaa",
      "     bbaaaaaaaaa",
      "       baaaaaaaa",
      "        bbaaaaaa",
      "          gaaaaa",
      "          cgaaaa",
      "            baaa",
      "            baaa",
      "       h     baa",
      "      c       ba",
      "     e        ba"
    ],
    [
      "vvvvvvvvvvvvvvvv",
      "aaaaaaaaaaaaaaaa",
      "aaaaaaaaaaaaaaaa",
      "baaaaaaaaaaaaaaa",
      " bbbaaaaaaaaaaaa",
      "    bbaaaaaaaaaa",
      "      bbaaaaaaaa",
      "        baaaaaaa",
      "         baaaaaa",
      "          gaaaaa",
      "          cgaaaa",
      "            baaa",
      "             baa",
      "              ba",
      "              ba",
      "     c         b"
    ],
    [
      "vvvvvvvvvvvvvvvv",
      "aaaaaaaaaaaaaaaa",
      "aaaaaaaaaaaaaaaa",
      "bbaaaaaaaaaaaaaa",
      "  bbbaaaaaaaaaaa",
      "     bbaaaaaaaaa",
      "       baaaaaaaa",
      "        baaaaaaa",
      "         bbaaaaa",
      "           gaaaa",
      "          c baaa",
      "            baaa",
      "             baa",
      "              ba",
      "               b",
      "               b"
    ],
    [
      "vvvvvvvvvvvvvvvv",
      "aaaaaaaaaaaaaaaa",
      "aaaaaaaaaaaaaaaa",
      "bbbaaaaaaaaaaaaa",
      "   bbaaaaaaaaaaa",
      "     bbaaaaaaaaa",
      "       bbaaaaaaa",
      "         baaaaaa",
      "          baaaaa",
      "           gaaaa",
      "          c baaa",
      "             baa",
      "              ba",
      "              ba",
      "               b",
      "               b"
    ]
  ]
}