{
  "name": "multi_alienresearch_8_base6",
  "refpalette": "deceasedcraft:multi_alienresearch_8/multi_alienresearch_8_base6_palette",
  "xsize": 16,
  "zsize": 16,
  "slices": [
    [
      "vvvvvvvvvvvvvvvv",
      "aaaaaaaaaaaaaaaa",
      "baaaaaaaaaaaaaaa",
      " bbbaaaaaaaaaaaa",
      "    bbaaaaaaaaaa",
      "      bbaaaaaaaa",
      "        baaaaaaa",
      "         baaaaaa",
      "          bcaaaa",
      "           dcaaa",
      "            baaa",
      "             baa",
      "              ba",
      "               b",
      "               b",
      "                "
    ],
    [
      "vvvvvvvvvvvvvvvv",
      "aaaaaaaaaaaaaaaa",
      "baaaaaaaaaaaaaaa",
      " bbbaaaaaaaaaaaa",
      "    bbaaaaaaaaaa",
      "      bbaaaaaaaa",
      "        bbaaaaaa",
      "          baaaaa",
      "           caaaa",
      "           dcaaa",
      "             baa",
      "              ba",
      "              ba",
      "               b",
      "               b",
      "                "
    ],
    [
      "vvvvvvvvvvvvvvvv",
      "aaaaaaaaaaaaaaaa",
      "cbaaaaaaaaaaaaaa",
      "  bbbaaaaaaaaaaa",
      "     bbaaaaaaaaa",
      "       baaaaaaaa",
      "        bbaaaaaa",
      "          baaaaa",
      "           caaaa",
      "           dcaaa",
      "             baa",
      "              ba",
      "              ba",
      "               b",
      "                ",
      "                "
    ],
    [
      "vvvvvvvvvvvvvvvv",
      "aaaaaaaaaaaaaaaa",
      "cbbaaaaaaaaaaaaa",
      "   bbaaaaaaaaaaa",
      "     bbaaaaaaaaa",
      "       bbaaaaaaa",
      "         baaaaaa",
      "          baaaaa",
      "           caaaa",
      "           dcaaa",
      "             baa",
      "              ba",
      "               b",
      "               b",
      "                ",
      "                "
    ],
    [
      "vvvvvvvvvvvvvvvv",
      "aaaaaaaaaaaaaaaa",
      "ccbaaaaaaaaaaaaa",
      "d  bbaaaaaaaaaaa",
      "     bbaaaaaaaaa",
      "       bbaaaaaaa",
      "         baaaaaa",
      "          baaaaa",
      "           caaaa",
      "           dcaaa",
      "             baa",
      "              ba",
      "               b",
      "e              b",
      "fgh             ",
      " fee            "
    ],
    [
      "vvvvvvvvvvvvvvvv",
      "aaaaaaaaaaaaaaaa",
      "cccaaaaaaaaaaaaa",
      "d  ccaaaaaaaaaaa",
      "     ccaaaaaaaaa",
      "       ccaaaaaaa",
      "         caaaaaa",
      "          caaaaa",
      "           ccaaa",
      "           dcaaa",
      "             caa",
      "i             ca",
      "jii            c",
      "klmii          c",
      "@nkjei          ",
      "n@kkjei         "
    ]
  ]
}