{
  "name": "multi_alienresearch_8_base3",
  "refpalette": "deceasedcraft:multi_alienresearch_8/multi_alienresearch_8_base3_palette",
  "xsize": 16,
  "zsize": 16,
  "slices": [
    [
      "vvvvvvvvvvvvvvvv",
      "aaaaaaaaaaaaaaaa",
      "bbbbbbbbbbbbbbbb",
      "bbbbbbbbbbbbbbbb",
      "aaaaaaaaaaaaaaaa",
      "cccddddddddddddd",
      "eeeccddddddddddd",
      "fffeecdddddddddd",
      "fffffeccdddddddd",
      "ffffffeecddddddd",
      "ffffffffegdddddd",
      "hffffffffegddddd",
      "ihhfffffffecdddd",
      " iihhffffffecddd",
      "   ihhfffffecddd",
      "    ihhfffffecdd"
    ],
    [
      "vvvvvvvvvvvvvvvv",
      "ajaaaaaajaaaaaaj",
      " k      k      k",
      "                ",
      "aaaaaaaaaaaaaaaa",
      "cddddddddddddddd",
      " cccdddddddddddd",
      " l! cddddddddddd",
      "  l  ccddddddddd",
      "      kcdddddddd",
      "        cddddddd",
      "mn       hdddddd",
      " mm     e cddddd",
      "   mm      cdddd",
      "     op    qcddd",
      "      o     cddd"
    ],
    [
      "vvvvvvvvvvvvvvvv",
      "ajaaaaaajaaaaaaj",
      "                ",
      "                ",
      "aaaaaaaaaaaaaaaa",
      "dddddddddddddddd",
      "ccdddddddddddddd",
      "  ccdddddddddddd",
      "    ccdddddddddd",
      "      cddddddddd",
      "       ccddddddd",
      "m        hdddddd",
      " mm     e cddddd",
      "   mm     cddddd",
      "     or    cdddd",
      "      o     cddd"
    ],
    [
      "vvvvvvvvvvvvvvvv",
      "ajaaaaaajaaaaaaj",
      "                ",
      "                ",
      "aaaaaaaaaaaaaaaa",
      "dddddddddddddddd",
      "dddddddddddddddd",
      "ccdddddddddddddd",
      "  cccddddddddddd",
      "     cdddddddddd",
      "      cddddddddd",
      "m      chddddddd",
      " mm     ehdddddd",
      "   mm    cdddddd",
      "     o    cddddd",
      "      o    cdddd"
    ],
    [
      "vvvvvvvvvvvvvvvv",
      "ajaaaaaajaaaaaaj",
      "                ",
      "                ",
      "aaaaaaaaaaaaaaaa",
      "dddddddddddddddd",
      "dddddddddddddddd",
      "dddddddddddddddd",
      "cccddddddddddddd",
      "   ccddddddddddd",
      "     cdddddddddd",
      "m     cddddddddd",
      " mm    hhddddddd",
      "   mm  ehddddddd",
      "     o   cdddddd",
      "      o   cddddd"
    ],
    [
      "vvvvvvvvvvvvvvvv",
      "ajaaaaaajaaaaaaj",
      "                ",
      "                ",
      "aaaaaaaaaaaaaaaa",
      "dddddddddddddddd",
      "dddddddddddddddd",
      "dddddddddddddddd",
      "cddddddddddddddd",
      " ccddddddddddddd",
      "   ccddddddddddd",
      "s    cdddddddddd",
      " ss   cddddddddd",
      "   ss  hdddddddd",
      "     me cddddddd",
      "      m  cdddddd"
    ]
  ]
}