{
  "name": "multi_arcfurnace_0_ground",
  "refpalette": "deceasedcraft:multi_arcfurnace_0/multi_arcfurnace_0_ground_palette",
  "xsize": 16,
  "zsize": 16,
  "slices": [
    [
      "zaazzzzzzzzzzzzz",
      "aaazzzzzzzzzzzzz",
      "aazbbbbbbbbbbbzz",
      "aaabbbbbbbbbbbzz",
      "aaabbbbbbbbbbbzz",
      "zaabbbbbbbbbbbzz",
      "zaabbbbbbbbbbbzz",
      "aaabbbbbbbbbbbzz",
      "zaabbbbbbbbbbbzz",
      "aaabbbbbbbbbbbzz",
      "aaabbbbbbbbbbbzz",
      "aaabbbbbbbbbbbzz",
      "zaabbbbbbbbbbbzz",
      "aaabbcdddddcbbzz",
      "zaabbcbbbbbcbbzz",
      "aaabbcbbbbbcbbzz"
    ],
    [
      "                ",
      "                ",
      "   eeeeeeeeeee  ",
      "   efgggfhi fe  ",
      "   jk    l  me  ",
      "   e     noooe  ",
      "   ep    q  me  ",
      "   epr   hs  e  ",
      "   ep    tttte  ",
      "   ep  r    ue  ",
      "   e wxxy  k e  ",
      "   ennnnnnnAne  ",
      "   e         e  ",
      "   B         e  ",
      "   B  CCDCC  e  ",
      "   B  CEEEC  e  "
    ],
    [
      "                ",
      "                ",
      "   eeeeeeeeeee  ",
      "   efF Ifh  fe  ",
      "   J     K   e  ",
      "   e     noooe  ",
      "   L     M   e  ",
      "   LN    h   e  ",
      "   LO    tttte  ",
      "   LP       ue  ",
      "   e   Q     e  ",
      "   enLLLLnnRne  ",
      "   e         e  ",
      "   B         e  ",
      "   B  DSSSD  e  ",
      "   B  DTTTD  e  "
    ],
    [
      "                ",
      "                ",
      "   eeUVWeUVWee  ",
      "   ef   fh  fe  ",
      "   L     h   e  ",
      "   e     noooe  ",
      "   L     h   e  ",
      "   L     h   e  ",
      "   L     tttte  ",
      "   L        ue  ",
      "   e         e  ",
      "   enLLLLnnnne  ",
      "   e         e  ",
      "   B         e  ",
      "   B  CSSSC  e  ",
      "   B   TTT   e  "
    ],
    [
      "                ",
      "                ",
      "   eeeeeeeeeee  ",
      "   ef   fh  fe  ",
      "  Xe     h   e  ",
      "  Xe     noooe  ",
      "  Xe     h   e  ",
      "  Xe     h   e  ",
      "  Xe     tttte  ",
      "  Xe        ue  ",
      "   e         e  ",
      "   ennnnnnnnne  ",
      "   e  YYYYYYYe  ",
      "  XeZ YYYYYYYe  ",
      "  XeZ  fSf YYe  ",
      "  XeZ  TTT YYe  "
    ],
    [
      "                ",
      "                ",
      "   eeeeeeeeeee  ",
      "   ef   fbbbfe  ",
      "   e    0bbbbe  ",
      "   e    0bbbbe  ",
      "   e    0bbbbe  ",
      "   e    0bbbbe  ",
      "   e    0bbbbe  ",
      "   e    0bbbue  ",
      "   e    0bbbbe  ",
      "   ennnnnnnnne  ",
      "   e  1      e  ",
      "   e  23333  e  ",
      "   e   fSf 1 e  ",
      "   e    S  1 e  "
    ]
  ]
}