{
  "name": "multi_communitycenter_4_base1",
  "refpalette": "deceasedcraft:multi_communitycenter_4/multi_communitycenter_4_base1_palette",
  "xsize": 16,
  "zsize": 16,
  "slices": [
    [
      "HHHHHHHHHHHHHHHH",
      "HHHHHHHHHHHHHHHH",
      "HHHHHHHHHHHHHHHH",
      "HHHHHHHHHHHHHHHH",
      "HHHHHHHHHHHHHHHH",
      "HHHHHHHHHHHHHHHH",
      "HHHHHHHHHHHHHHHH",
      "HHHHHHHHHHHHHHHH",
      "HHHHHHHHHHHHHHHH",
      "HHHHHHHHHHHHHHHH",
      "HHHHHHHHHHHHHHHH",
      "HHHHHHHHHHHHHHHH",
      "HHHHHHHHHHHHHHHH",
      "HHHHHHHHHHHHHHHH",
      "HHHHHHHHHHHHHHHH",
      "HHHHHHHHHHHHHHHH"
    ],
    [
      "                ",
      "abab abab abab a",
      "cdcd cdcd cdcd c",
      "           e    ",
      "    f    f    f ",
      "abab abab abab a",
      "                ",
      "                ",
      "                ",
      "                ",
      "cdcd cdcd cdcd c",
      "    f    f    f ",
      "                ",
      "abab abab abab a",
      "cdcd cdcd cdcd c",
      "                "
    ],
    [
      "                ",
      "                ",
      "                ",
      "                ",
      "    f    f    f ",
      "                ",
      "                ",
      "                ",
      "                ",
      "                ",
      "                ",
      "    f    f    f ",
      "                ",
      "                ",
      "                ",
      "                "
    ],
    [
      "                ",
      "                ",
      "                ",
      "                ",
      "    f    f    f ",
      "                ",
      "                ",
      "                ",
      "                ",
      "                ",
      "                ",
      "    f    f    f ",
      "                ",
      "                ",
      "                ",
      "                "
    ],
    [
      "    f    f    f ",
      "    f    f    f ",
      "    f    f    f ",
      "    f    f    f ",
      "ggggfggggfggggfg",
      "    f    f    f ",
      "    f    f    f ",
      "    f    f    f ",
      "    f    f    f ",
      "    f    f    f ",
      "    f    f    f ",
      "ggggfggggfggggfg",
      "    f    f    f ",
      "    f    f    f ",
      "    f    f    f ",
      "    f    f    f "
    ],
    [
      "hhhhhhhhhhhhhhhh",
      "hhhhhhhhhhhhhhhh",
      "hhhhhhhhhhhhhhhh",
      "hhhhhhhhhhhhhhhh",
      "hhhhhhhhhhhhhhhh",
      "hhhhhhhhhhhhhhhh",
      "hhhhhhhhhhhhhhhh",
      "hhhhhhhhhhhhhhhh",
      "hhhhhhhhhhhhhhhh",
      "hhhhhhhhhhhhhhhh",
      "hhhhhhhhhhhhhhhh",
      "hhhhhhhhhhhhhhhh",
      "hhhhhhhhhhhhhhhh",
      "hhhhhhhhhhhhhhhh",
      "hhhhhhhhhhhhhhhh",
      "hhhhhhhhhhhhhhhh"
    ]
  ]
}