{
  "name": "multi_communitycenter_4_ground",
  "refpalette": "deceasedcraft:multi_communitycenter_4/multi_communitycenter_4_ground_palette",
  "xsize": 16,
  "zsize": 16,
  "slices": [
    [
      "aabcddeffffedddg",
      "ahbcddeffffeddig",
      "aabcddeffffeddig",
      "ahbcddeffffeddig",
      "aabcddeffffedddg",
      "ahbcddeffffeddig",
      "aabcddeffffeddig",
      "jjjcddeffffeddig",
      "kkkkkddeffeddddg",
      "llllkdddeeddddig",
      "llllkkddddddddig",
      "lllllkkkddddddig",
      "llllllkkkkkkkkkm",
      "llllllmkkkkkkkkm",
      "mlllllmkkkkkkkkm",
      "kmllllmkkkkkkkkm"
    ],
    [
      "   c  effffe  no",
      "  pc  effffe  qo",
      "   c  effffe  qr",
      "   c  effffe  qo",
      "   c  effffe  no",
      "  pc  effffe  qo",
      "   c  effffe  qr",
      "jjjc  effffe  qo",
      "ssssc teffet  no",
      "u  wc  teet   qo",
      "x uxcc        qr",
      "u  u ccc  yy  qo",
      "  u A jcBCDECBcj",
      " ux FFI   JJ   I",
      "K u             ",
      " K  w           "
    ],
    [
      "LLLB          no",
      "   B           o",
      "   c           r",
      "   c           o",
      "   B          no",
      "   B    ~      o",
      "   B           r",
      "jjjc           o",
      "ssssc         no",
      "    B          o",
      "    BB         r",
      "     BBc       o",
      "      jcBCMNCBcj",
      "      I        I",
      "K       O       ",
      " K              "
    ],
    [
      "PPPc          no",
      "QQQc           o",
      "LLLc           r",
      "LLLc           o",
      "LLLB          no",
      "   B    ~      o",
      "   B           r",
      "jjjc           o",
      "ssssc         no",
      "    B          o",
      "    BB         r",
      "     BBc       o",
      "      jcBCCCCBcj",
      "      I        I",
      "K       R       ",
      " K              "
    ],
    [
      "  Sc          no",
      "PPPc           o",
      "PPPc           o",
      "PPPc           o",
      "PPPc          no",
      "QQQc    ~      o",
      "QQQc           o",
      "jjjc           o",
      "ccccc         no",
      "    c          o",
      "    cc         o",
      "     ccc       o",
      "      jcBBBBBBcj",
      "      I        I",
      "I     I R    O I",
      " I    I        I"
    ],
    [
      "  S           Tg",
      "  S           Tg",
      " USV          Tg",
      "  SV          Tg",
      "WWSc          ng",
      "PPPc    ~     Tg",
      "PPXc          Tg",
      "PPXc          Tg",
      "PPPcc         Tg",
      "QQQQc         Tg",
      "QQQQcc        Tg",
      "QQQQQccc      Tg",
      "QQQQQQjccccccccc",
      "jQQQQQjLLLLLLLLj",
      "jjQQQQjLRO O RLj",
      " jjQQQjLO O  OLj"
    ]
  ]
}