{
  "name": "multi_oasiscondo_13_base2",
  "refpalette": "deceasedcraft:multi_oasiscondo_13/multi_oasiscondo_13_base2_palette",
  "xsize": 16,
  "zsize": 16,
  "slices": [
    [
      "aHHHHaaHHHHHHHHv",
      "aHHHaaaaHHHHHHHv",
      "aHHHabaaHHHHHHHv",
      "HHHHaaaaHHHHHHHv",
      "HHHHaaaaHHHHHHHv",
      "HHHHaaaaHHHHHHHv",
      "HHHHaaaaHHHHHHHv",
      "HHHHaaaaHHHHHHHv",
      "HHHHaaaaHHHHHHHv",
      "HHHHaaaaHHHHHHHv",
      "aHHHaaaaHHHHHHHv",
      "aHHHabaaHHHHHHHv",
      "aHHHaavaHHHHHHHv",
      "aHHHaavaHHHHHHHv",
      "cdddccvaHHHHHHHv",
      "efffeevaHHHHHHHv"
    ],
    [
      "           g  hv",
      "     ij    k  lv",
      "     bm    g  hv",
      "     nm    k  lv",
      "     om    g  hv",
      "     om    k  lv",
      "     om    g  hv",
      "     om    k  lv",
      "     om    g  hv",
      "     om    k  lv",
      "     pq    g  hv",
      "rrrrrbs    k  lv",
      "      v    g  hv",
      "      v    k  lv",
      "      v    g  hv",
      "      v    k  lv"
    ],
    [
      "               v",
      "               v",
      "     b         v",
      "               v",
      "               v",
      "               v",
      "               v",
      "               v",
      "               v",
      "               v",
      "               v",
      "     b         v",
      "      v        v",
      "      v        v",
      "      v        v",
      "      v        v"
    ],
    [
      "               v",
      "               v",
      "     b         v",
      "               v",
      "               v",
      "               v",
      "               v",
      "               v",
      "               v",
      "               v",
      "               v",
      "     b         v",
      "      v        v",
      "      v        v",
      "      v        v",
      "      v        v"
    ],
    [
      "               v",
      "               v",
      "     b         v",
      "               v",
      "               v",
      "               v",
      "               v",
      "               v",
      "               v",
      "               v",
      "               v",
      "     b         v",
      "      v        v",
      "      v        v",
      "      v        v",
      "      v        v"
    ],
    [
      "tttttutttttttttv",
      "tttttutttttttttv",
      "uuuuuwuuuuuuuuuv",
      "tttttutttttttttv",
      "tttttutttttttttv",
      "tttttutttttttttv",
      "tttttutttttttttv",
      "tttttutttttttttv",
      "tttttutttttttttv",
      "tttttutttttttttv",
      "tttttutttttttttv",
      "uuuuuwuuuuuuuuuv",
      "ttttttvttttttttv",
      "ttttttvttttttttv",
      "xxxxxxvttttttttv",
      "yyyyyyvttttttttv"
    ]
  ]
}