{
  "name": "multi_oasiscondo_13_floor5",
  "refpalette": "deceasedcraft:multi_oasiscondo_13/multi_oasiscondo_13_floor5_palette",
  "xsize": 16,
  "zsize": 16,
  "slices": [
    [
      "abbbbbb         ",
      "cbbbbbd         ",
      "eeeeee          ",
      "cbbbbbd         ",
      "cbbbbbb         ",
      "cbbbbbb         ",
      "cbbbbbb         ",
      "cbbbbbb         ",
      "cbbbbbb         ",
      "abbbbbb         ",
      "cbbbbbd         ",
      "eeeeee          ",
      "cbbbbbd         ",
      "cbbbbbb         ",
      "cbbbbbb         ",
      "cbbbbbb         "
    ],
    [
      "fgh   ic        ",
      "cjhklmcn        ",
      "eeeeee          ",
      "copqcrsss       ",
      "ct  u wsx       ",
      "cccccy Ax       ",
      "cBCDEF Ax       ",
      "c   I  Ax       ",
      "c J   KAx       ",
      "f h LMKsx       ",
      "cjhkNksss       ",
      "eeeeee          ",
      "cOPQcRcn        ",
      "cS ScRqc        ",
      "c TUc VW        ",
      "cU  c Xc        "
    ],
    [
      "Y h   ZW        ",
      "c0h1 2cn        ",
      "eeeeee          ",
      "c3  crsss       ",
      "c   4 5s6       ",
      "ccccc  76       ",
      "c 89#$  6       ",
      "c       6       ",
      "c J   % 6       ",
      "Y h   Ks6       ",
      "c^h  &sss       ",
      "eeeeee          ",
      "c * c(cn        ",
      "c   c  c        ",
      "c   c  )        ",
      "c   c  )        "
    ],
    [
      "+ h    c        ",
      "c-h   cn        ",
      "eeeeee          ",
      "c[  c]sss       ",
      "c{  }  s        ",
      "ccccc  7        ",
      "c|;:   7        ",
      "c               ",
      "c J    7        ",
      "+ h    s        ",
      "c-h   sss       ",
      "eeeeee          ",
      "c   c'cn        ",
      "c   c  W        ",
      "c   c <)        ",
      "c   c >)        "
    ],
    [
      "cgh ,  c        ",
      "c!h   cn        ",
      "eeeeee          ",
      "cg .c?sss       ",
      "c. .c  s        ",
      "ccccc  /        ",
      "c`\u0370\u0371   /        ",
      "c      /        ",
      "c J ,  /        ",
      "c h    s        ",
      "c h   sss       ",
      "eeeeee          ",
      "c \u0372 c?cn        ",
      "c   c..c        ",
      "c   c..)        ",
      "c   c..)        "
    ],
    [
      "c\u0373\u0373\u0373\u0373\u0373\u0373c        ",
      "c\u0373\u0373\u0373\u0373\u0373c\u0374        ",
      "eeeeee          ",
      "c!g \u0373\u0373sss       ",
      "c gg\u0373\u0373\u0373ss       ",
      "c\u0373\u0373\u0373\u0373\u0373\u0373ss       ",
      "c\u0373\u0373\u0373\u0373\u0373\u0373ss       ",
      "c\u0373\u0373\u0373\u0373\u0373\u0373ss       ",
      "c\u0373\u0373\u0373\u0373\u0373\u0373ss       ",
      "c\u0373\u0373\u0373\u0373\u0373\u0373ss       ",
      "c\u0373\u0373\u0373\u0373\u0373sss       ",
      "eeeeee          ",
      "c\u0373\u0373\u0373\u0373\u0373c\u0374        ",
      "c\u0373\u0373\u0373\u0373 \u0375c        ",
      "c\u0373\u0373\u0373\u0373  W        ",
      "c\u0373\u0373\u0373\u0373  c        "
    ]
  ]
}