{
  "name": "multi_oasiscondo_13_floor3",
  "refpalette": "deceasedcraft:multi_oasiscondo_13/multi_oasiscondo_13_floor3_palette",
  "xsize": 16,
  "zsize": 16,
  "slices": [
    [
      "abbbbbb         ",
      "cbbbbbd         ",
      "eeeeee          ",
      "cbbbbfd         ",
      "gbbbb b         ",
      "cbbbbbb         ",
      "cbbbbbb         ",
      "cbbbbbb         ",
      "cbbbbbb         ",
      "abbbbbb         ",
      "cbbbbbd         ",
      "eeeeee          ",
      "cbbbbbd         ",
      "cbbbbbb         ",
      "cbbbbbb         ",
      "cbbbbbb         "
    ],
    [
      "h i jklc        ",
      "cminongp        ",
      "eeqeee          ",
      "grstc uw        ",
      "xyABcCDc        ",
      "g   cE c        ",
      "cFIJc Ku        ",
      "cLM NJOc        ",
      "cPi QRSc        ",
      "hTiUVWXc        ",
      "cYinZ0cp        ",
      "eeeeee          ",
      "c123cScw        ",
      "c 4 c5Dc        ",
      "c67 c  u        ",
      "c   c Kc        "
    ],
    [
      "8 i   9c        ",
      "c#i5 $uw        ",
      "ee!eee          ",
      "%^&tc*cp        ",
      "    c  c        ",
      "p   c  (        ",
      "u   ) +(        ",
      "c-p   O(        ",
      "c[i    (        ",
      "8mi   ]c        ",
      "c i{}|cw        ",
      "eeeeee          ",
      "c1; c*cw        ",
      "c : c  u        ",
      "c ' c  (        ",
      "c   c 5(        "
    ],
    [
      "< i    u        ",
      "c i   cw        ",
      "eeeeee          ",
      ">  ,c.up        ",
      "    c  c        ",
      "?   c  (        ",
      "u   c /(        ",
      "c i O`O(        ",
      "c i    (        ",
      "<\u0370i    c        ",
      "c\u0371i   cw        ",
      "eeeeee          ",
      "c\u0372  c.up        ",
      "c   c  c        ",
      "c   c  (        ",
      "c   c /(        "
    ],
    [
      "c i \u0373  c        ",
      "c i   uw        ",
      "eeeeee          ",
      "c   c5uw        ",
      "% \u0374 c \u0375c        ",
      "\u0376   c \u0375(        ",
      "c   c\u0375\u0375(        ",
      "c iOOOO(        ",
      "c i    (        ",
      "c i \u0373  c        ",
      "c i   cp        ",
      "eeeeee          ",
      "c   c\u0377uw        ",
      "c \u037a c\u0375\u0375c        ",
      "c   c\u0375\u0375(        ",
      "c   c\u0375\u0375(        "
    ],
    [
      "c\u037b\u037b\u037b\u037b\u037b\u037bc        ",
      "c\u037b\u037b\u037b\u037b\u037bcp        ",
      "eeeeee          ",
      "c\u037b\u037b\u037b\u037b\u037bcp        ",
      "c\u037b\u037b\u037b\u037b  c        ",
      "c\u037b\u037b\u037b\u037b  c        ",
      "c\u037b\u037b\u037b\u037b  c        ",
      "c\u037b\u037b\u037b\u037b\u037b\u037bc        ",
      "c\u037b\u037b\u037b\u037b\u037b\u037bu        ",
      "c\u037b\u037b\u037b\u037b\u037b\u037bc        ",
      "c\u037b\u037b\u037b\u037b\u037bcw        ",
      "eeeeee          ",
      "c\u037b\u037b\u037b\u037b\u037bcp        ",
      "c\u037b\u037c\u037b\u037b \u037du        ",
      "c\u037b\u037b\u037b\u037b  c        ",
      "c\u037b\u037b\u037b\u037b  c        "
    ]
  ]
}