{
  "name": "multi_oasiscondo_13_base1",
  "refpalette": "deceasedcraft:multi_oasiscondo_13/multi_oasiscondo_13_base1_palette",
  "xsize": 16,
  "zsize": 16,
  "slices": [
    [
      "aHHHHaaHHHHHHHHv",
      "aHHHaaaaHHHHHHHv",
      "aHHHabaaHHHHHHHv",
      "HHHHaaaaHHHHHHHv",
      "HHHHaaaaHHHHHHHv",
      "HHHHaaaaHHHHHHHv",
      "HHHHaaaaHHHHHHHv",
      "HHHHaaaaHHHHHHHv",
      "HHHHaaaaHHHHHHHv",
      "HHHHaaaaHHHHHHHv",
      "aHHHaaaaHHHHHHHv",
      "aHHHabaaHHHHHHHv",
      "aHHHaavaHHHHHHHv",
      "aHHHaavaHHHHHHHv",
      "cdddccvaHHHHHHHv",
      "efffeevaHHHHHHHv"
    ],
    [
      "           g  hv",
      "     ij    k  lv",
      "     bm    g  hv",
      "     nm    k  lv",
      "     om    g  hv",
      "     om    k  lv",
      "     om    g  hv",
      " p   om    kq lv",
      "     om    g  hv",
      "     om    k  lv",
      "     rs    g  hv",
      "tttttbu    k  lv",
      "      v    g  hv",
      "      v    k wlv",
      "      v    g  hv",
      "      v    k  lv"
    ],
    [
      "               v",
      "               v",
      "     b         v",
      "               v",
      "               v",
      "               v",
      "               v",
      "               v",
      "               v",
      "               v",
      "               v",
      "     b         v",
      "      v        v",
      "      v        v",
      "      v        v",
      "      v        v"
    ],
    [
      "               v",
      "               v",
      "     b         v",
      "               v",
      "               v",
      "               v",
      "               v",
      "               v",
      "               v",
      "               v",
      "               v",
      "     b         v",
      "      v        v",
      "      v        v",
      "      v        v",
      "      v        v"
    ],
    [
      "               v",
      "               v",
      "     b         v",
      "               v",
      "               v",
      "               v",
      "               v",
      "               v",
      "               v",
      "               v",
      "               v",
      "     b         v",
      "      v        v",
      "      v        v",
      "      v        v",
      "      v        v"
    ],
    [
      "xxxxxyxxxxxxxxxv",
      "xxxxxyxxxxxxxxxv",
      "yyyyyAyyyyyyyyyv",
      "xxxxxyxxxxxxxxxv",
      "xxxxxyxxxxxxxxxv",
      "xxxxxyxxxxxxxxxv",
      "xxxxxyxxxxxxxxxv",
      "xxxxxyxxxxxxxxxv",
      "xxxxxyxxxxxxxxxv",
      "xxxxxyxxxxxxxxxv",
      "xxxxxyxxxxxxxxxv",
      "yyyyyAyyyyyyyyyv",
      "xxxxxxvxxxxxxxxv",
      "xxxxxxvxxxxxxxxv",
      "BBBBBBvxxxxxxxxv",
      "CCCCCCvxxxxxxxxv"
    ]
  ]
}