{
  "name": "multi_oasiscondo_13_floor9",
  "refpalette": "deceasedcraft:multi_oasiscondo_13/multi_oasiscondo_13_floor9_palette",
  "xsize": 16,
  "zsize": 16,
  "slices": [
    [
      "abbbcbd         ",
      "abbbbbe         ",
      "ffffff          ",
      "gddddde         ",
      "gdddddd         ",
      "hdddddd         ",
      "hdddddd         ",
      "hdddddd         ",
      "hdddddd         ",
      "gdddddd         ",
      "gddddde         ",
      "ffffff          ",
      "gddddde         ",
      "gdddddd         ",
      "hdddddd         ",
      "hdddddd         "
    ],
    [
      " i j  klm       ",
      "  n iilll       ",
      "ffffff          ",
      "goop!pgq        ",
      "g  rr sg        ",
      "t uuu  g        ",
      "w      g        ",
      "x     yA        ",
      "t BBB  g        ",
      "gC    sg        ",
      "gDDDDDgE        ",
      "ffffff          ",
      "gFIIIJgq        ",
      "g K K  g        ",
      "t      g        ",
      "w      g        "
    ],
    [
      "   L   lM       ",
      "      lll       ",
      "ffffff          ",
      "gopoooAq        ",
      "g     rg        ",
      "t      N        ",
      "O      N        ",
      "P     QN        ",
      "t      N        ",
      "g     Rg        ",
      "gSTTTUAq        ",
      "ffffff          ",
      "gVWXWXgq        ",
      "g      A        ",
      "t      N        ",
      "O      N        "
    ],
    [
      "   i   l        ",
      "      lll       ",
      "ffffff          ",
      "grYZ 0gq        ",
      "g      A        ",
      "t      N        ",
      "t      N        ",
      "t      N        ",
      "t      N        ",
      "g      g        ",
      "g12341gq        ",
      "ffffff          ",
      "g     gq        ",
      "g      g        ",
      "t      N        ",
      "t      N        "
    ],
    [
      "       l        ",
      "      lll       ",
      "ffffff          ",
      "g     gE        ",
      "g      g        ",
      "g      N        ",
      "g      N        ",
      "g      N        ",
      "g      N        ",
      "g      g        ",
      "g     gE        ",
      "ffffff          ",
      "g     gq        ",
      "g      g        ",
      "g      N        ",
      "g      N        "
    ],
    [
      "555555lll       ",
      "555555lll       ",
      "ffffff          ",
      "g66666Aq        ",
      "g666666g        ",
      "g666666g        ",
      "g666666g        ",
      "g666666g        ",
      "g666666g        ",
      "g666666g        ",
      "g66666gE        ",
      "ffffff          ",
      "g66666gq        ",
      "g666666g        ",
      "g666666A        ",
      "g666666g        "
    ]
  ]
}