{
  "name": "multi_oasiscondo_13_floor11",
  "refpalette": "deceasedcraft:multi_oasiscondo_13/multi_oasiscondo_13_floor11_palette",
  "xsize": 16,
  "zsize": 16,
  "slices": [
    [
      "abbccbd         ",
      "abcbbbd         ",
      "abbcbed         ",
      "abccbbd         ",
      "accbbbd         ",
      "acbcbbd         ",
      "abbccbd         ",
      "accbcbd         ",
      "abccbbd         ",
      "acbbbbd         ",
      "abbbbbf         ",
      "eeeeee          ",
      "gdddddf         ",
      "ghhhhhd         ",
      "ihhhhhd         ",
      "ihhhhhd         "
    ],
    [
      " j   jkkl       ",
      " m  n kkl       ",
      " o  oekkl       ",
      " p   jkkl       ",
      "    q kkl       ",
      "      kkl       ",
      "      kkl       ",
      "      kkl       ",
      "      kkl       ",
      "  rst kul       ",
      " pppppuuu       ",
      "eeeeee          ",
      "gwxxxyy         ",
      "g  A  y         ",
      "B A A y         ",
      "B  C  y         "
    ],
    [
      " o      D       ",
      "    p   D       ",
      "     e  D       ",
      " q      D       ",
      "        D       ",
      "        D       ",
      "        D       ",
      "        D       ",
      "        D       ",
      "       uD       ",
      " jjjjjuuu       ",
      "eeeeee          ",
      "gEFI yy         ",
      "g     y         ",
      "B     y         ",
      "B     y         "
    ],
    [
      "                ",
      "    j           ",
      "     e          ",
      "                ",
      "                ",
      "                ",
      "                ",
      "                ",
      "                ",
      "       u        ",
      " jjj juuu       ",
      "eeeeee          ",
      "gE   yy         ",
      "g     y         ",
      "B     y         ",
      "B     y         "
    ],
    [
      "       J        ",
      "    j  J        ",
      "     e J        ",
      "       J        ",
      "       J        ",
      "       J        ",
      "       J        ",
      "       J        ",
      "       J        ",
      "       u        ",
      "  j   uuu       ",
      "eeeeee          ",
      "g    yy         ",
      "g     y         ",
      "g     y         ",
      "g     y         "
    ],
    [
      "KKKKKKuuu       ",
      "KKKKKKuuu       ",
      "KKKKKeuuu       ",
      "KKKKKKuuu       ",
      "KKKKKKuuu       ",
      "KKKKKKuuu       ",
      "KKKKKKuuu       ",
      "KKKKKKuuu       ",
      "KKKKKKuuu       ",
      "KKKKKKuuu       ",
      "KKKKKKuuu       ",
      "eeeeee          ",
      "gKKKKyy         ",
      "gKKKKKy         ",
      "gKKKKKy         ",
      "gKKKKKy         "
    ]
  ]
}