{
  "name": "multi_oasiscondo_13_floor2",
  "refpalette": "deceasedcraft:multi_oasiscondo_13/multi_oasiscondo_13_floor2_palette",
  "xsize": 16,
  "zsize": 16,
  "slices": [
    [
      "abbbbbb         ",
      "cbbbbbd         ",
      "eeeeee          ",
      "cbbbbbd         ",
      "cbbbbbb         ",
      "cbbbbbb         ",
      "cbbbbbb         ",
      "cbbbbbb         ",
      "cbbbbbb         ",
      "abbbbbb         ",
      "cbbbbbd         ",
      "eeeeee          ",
      "cbbbbbd         ",
      "cbbbbbb         ",
      "cbbbbbb         ",
      "cbbbbbb         "
    ],
    [
      "f g h ic        ",
      "cjgklmcn        ",
      "eeeeee          ",
      "c   c co        ",
      "c   c pq        ",
      "c   c  q        ",
      "c   c rc        ",
      "c gstutc        ",
      "c w    q        ",
      "f xyA BC        ",
      "c wD Ecn        ",
      "eeeeee          ",
      "cFIJcKco        ",
      "c LMcNOq        ",
      "c  Pc  c        ",
      "cQ  c Rc        "
    ],
    [
      "S g h Tc        ",
      "cUgklmco        ",
      "eeeeee          ",
      "c   cVcn        ",
      "c   c  c        ",
      "c   c  W        ",
      "c   c  W        ",
      "c gXtYtW        ",
      "c x    W        ",
      "S w    q        ",
      "c gDDDqZ        ",
      "ee012e          ",
      "c345cVcn        ",
      "c   c  q        ",
      "c   c6 W        ",
      "c   c  W        "
    ],
    [
      "7 g    c        ",
      "c8g9  qo        ",
      "eeeeee          ",
      "c   c#co        ",
      "c   c  c        ",
      "c   c  W        ",
      "c   c  W        ",
      "c g$t%tW        ",
      "c w    W        ",
      "7 x^   c        ",
      "c wDD cn        ",
      "ee0&ee          ",
      "c*  c#qn        ",
      "c(  c  c        ",
      "c)  c  W        ",
      "c   c +W        "
    ],
    [
      "c g -  c        ",
      "c g   qn        ",
      "eeeeee          ",
      "c   c[co        ",
      "c [ c]]q        ",
      "c   c]]W        ",
      "c   c]]W        ",
      "c gttttW        ",
      "c g    W        ",
      "c w    c        ",
      "c gD  cn        ",
      "eee0ee          ",
      "c   c{qn        ",
      "c}{ c]]c        ",
      "c!| c]]W        ",
      "c|  c]]W        "
    ],
    [
      "c;;;;;;q        ",
      "c;;;;;CZ        ",
      "eeeeee          ",
      "c;;;;;qo        ",
      "c;;;; :c        ",
      "c;;;;  q        ",
      "c;;;;  c        ",
      "c;;;;;;c        ",
      "c;;;;;;q        ",
      "c;;';;;c        ",
      "c;;;;;co        ",
      "eeeeee          ",
      "c;;;;;co        ",
      "c;;;; :q        ",
      "c;;;;  c        ",
      "c;;;;  q        "
    ]
  ]
}