{
  "name": "multi_oasiscondo_13_top",
  "refpalette": "deceasedcraft:multi_oasiscondo_13/multi_oasiscondo_13_top_palette",
  "xsize": 16,
  "zsize": 16,
  "slices": [
    [
      "aaaaaab         ",
      "aaaaaab         ",
      "aaaaacb         ",
      "aaaaaab         ",
      "aaaaaab         ",
      "aaaaaab         ",
      "aaaaaab         ",
      "aaaaaab         ",
      "aaaaaab         ",
      "aaaaaab         ",
      "aaaaaab         ",
      "aaaaacb         ",
      "aaaaaab         ",
      "aaaaaab         ",
      "aaaaaab         ",
      "aaaaaab         "
    ],
    [
      "dddddaeee       ",
      "dddddaeee       ",
      "dddddceee       ",
      "dddddaeee       ",
      "dddddaeee       ",
      "dddddaeee       ",
      "dddddaeee       ",
      "dddddaeee       ",
      "dddddaeee       ",
      "dddddaeee       ",
      "dddddaeee       ",
      "dddddceee       ",
      "dddddaeee       ",
      "dddddaeee       ",
      "dddddaeee       ",
      "dddddaeee       "
    ],
    [
      "fffffdggh       ",
      "fffffdggh       ",
      "fffffcggh       ",
      "fffffdggh       ",
      "fffffdggh       ",
      "fffffdggh       ",
      "fffffdggh       ",
      "fffffdggh       ",
      "fffffdggh       ",
      "fffffdggh       ",
      "fffffdggh       ",
      "fffffcggh       ",
      "fffffdggh       ",
      "fffffdggh       ",
      "fffffdggh       ",
      "fffffdggh       "
    ],
    [
      "     iiij       ",
      "     iiij       ",
      "     ckij       ",
      "     iiij       ",
      "     iiij       ",
      "     ilij       ",
      "     iiij       ",
      "     iiij       ",
      "     ilij       ",
      "     iiij       ",
      "     iiij       ",
      "     ckij       ",
      "     iiij       ",
      "     iiij       ",
      "     ilij       ",
      "     iiij       "
    ],
    [
      "        j       ",
      "        j       ",
      "     c  j       ",
      "        j       ",
      "        j       ",
      "        j       ",
      "        j       ",
      "        j       ",
      "        j       ",
      "        j       ",
      "        j       ",
      "     c  j       ",
      "        j       ",
      "        j       ",
      "        j       ",
      "        j       "
    ],
    [
      "                ",
      "                ",
      "m    c          ",
      "                ",
      "                ",
      "                ",
      "                ",
      "                ",
      "                ",
      "                ",
      "                ",
      "m    c          ",
      "                ",
      "                ",
      "                ",
      "                "
    ],
    [
      "                ",
      "                ",
      "n    c          ",
      "                ",
      "                ",
      "                ",
      "                ",
      "                ",
      "                ",
      "                ",
      "                ",
      "n    c          ",
      "                ",
      "                ",
      "                ",
      "                "
    ],
    [
      "                ",
      "                ",
      "o    c          ",
      "                ",
      "                ",
      "                ",
      "                ",
      "                ",
      "                ",
      "                ",
      "                ",
      "o    c          ",
      "                ",
      "                ",
      "                ",
      "                "
    ],
    [
      "                ",
      "                ",
      "     c          ",
      "                ",
      "                ",
      "                ",
      "                ",
      "                ",
      "                ",
      "                ",
      "                ",
      "     c          ",
      "                ",
      "                ",
      "                ",
      "                "
    ],
    [
      "                ",
      "                ",
      "     c          ",
      "                ",
      "                ",
      "                ",
      "                ",
      "                ",
      "                ",
      "                ",
      "                ",
      "     c          ",
      "                ",
      "                ",
      "                ",
      "                "
    ],
    [
      "       p        ",
      "       p        ",
      "     c p        ",
      "       p        ",
      "       p        ",
      "       p        ",
      "       p        ",
      "       p        ",
      "       p        ",
      "       p        ",
      "       p        ",
      "     c p        ",
      "       p        ",
      "       p        ",
      "       p        ",
      "       p        "
    ],
    [
      "qqqqqqeee       ",
      "qqqqqqeee       ",
      "qqqqqceee       ",
      "qqqqqqeee       ",
      "qqqqqqeee       ",
      "qqqqqqeee       ",
      "qqqqqqeee       ",
      "qqqqqqeee       ",
      "qqqqqqeee       ",
      "qqqqqqeee       ",
      "qqqqqqeee       ",
      "qqqqqceee       ",
      "qqqqqqeee       ",
      "qqqqqqeee       ",
      "qqqqqqeee       ",
      "qqqqqqeee       "
    ],
    [
      "gggggrb         ",
      "gggggrb         ",
      "gggggrb         ",
      "gggggrb         ",
      "gggggrb         ",
      "gggggrb         ",
      "gggggrb         ",
      "gggggrb         ",
      "gggggrb         ",
      "gggggrb         ",
      "gggggrb         ",
      "gggggrb         ",
      "gggggrb         ",
      "gggggrb         ",
      "gggggrb         ",
      "gggggrb         "
    ],
    [
      "s t  u          ",
      "s t  u          ",
      " wtxyu          ",
      "  t  u          ",
      "s t  u          ",
      "s t  u          ",
      "s t  u          ",
      "  t  u          ",
      "  t  u          ",
      "  t  u          ",
      "  t  u          ",
      " wtxyu          ",
      "A t  u          ",
      "A t  u          ",
      "A t  u          ",
      "  t  u          "
    ],
    [
      "     u          ",
      "B    u          ",
      "     u          ",
      "     u          ",
      "B    u          ",
      "     u          ",
      "B    u          ",
      "     u          ",
      "     u          ",
      "     u          ",
      "     u          ",
      "     u          ",
      "A    u          ",
      "ttt  u          ",
      "A    u          ",
      "     u          "
    ],
    [
      "C               ",
      "C               ",
      "                ",
      "                ",
      "C               ",
      "C               ",
      "C               ",
      "                ",
      "                ",
      "                ",
      "                ",
      "                ",
      "A               ",
      "A               ",
      "A               ",
      "                "
    ],
    [
      "C               ",
      "C               ",
      "                ",
      "                ",
      "C               ",
      "C               ",
      "C               ",
      "                ",
      "                ",
      "                ",
      "                ",
      "                ",
      "                ",
      "                ",
      "                ",
      "                "
    ],
    [
      "C               ",
      "C               ",
      "                ",
      "                ",
      "C               ",
      "C               ",
      "C               ",
      "                ",
      "                ",
      "                ",
      "                ",
      "                ",
      "                ",
      "                ",
      "                ",
      "                "
    ],
    [
      "C               ",
      "C               ",
      "                ",
      "                ",
      "C               ",
      "C               ",
      "C               ",
      "                ",
      "                ",
      "                ",
      "                ",
      "                ",
      "                ",
      "                ",
      "                ",
      "                "
    ]
  ]
}