{
  "name": "multi_oasiscondo_13_base4",
  "refpalette": "deceasedcraft:multi_oasiscondo_13/multi_oasiscondo_13_base4_palette",
  "xsize": 16,
  "zsize": 16,
  "slices": [
    [
      "aaaaaaaaaaaaaaav",
      "aaaaaaaaaaaaaaav",
      "aaaaaaaaaaaaaaav",
      "aaaaaaaaaaaaaaav",
      "aaaaaaaaaaaaaaav",
      "aaaaaaaaaaaaaaav",
      "aaaaaaaaaaaaaaav",
      "aaaaaaaaaaaaaaav",
      "aaaaaaaaaaaaaaav",
      "aaaaaaaaaaaaaaav",
      "aaaaaaaaaaaaaaav",
      "aaaaaaaaaaaaaaav",
      "aaaaaaaaaaaaaaav",
      "aaaaaaaaaaaaaaav",
      "aaaaaaaaaaaaaaav",
      "aaaaaaaaaaaaaaav"
    ],
    [
      "aaaaaaaaaaaaaaav",
      "aaaaaaaaaaaaaaav",
      "aaaaabaaaaaaaaav",
      "aaaaaaaaaaaaaaav",
      "aaaaaaaaaaaaaaav",
      "aaaaaaaaaaaaaaav",
      "aaaaaaaaaaaaaaav",
      "aaaaaaaaaaaaaaav",
      "aaaaaaaaaaaaaaav",
      "aaaaaaaaaaaaaaav",
      "aaaaaaaaaaaaaaav",
      "aaaaabaaaaaaaaav",
      "aaaaaaaaaaaaaaav",
      "aaaaaaaaaaaaaaav",
      "aaaaaaaaaaaaaaav",
      "aaaaaaaaaaaaaaav"
    ],
    [
      "ccccccccccccHHHv",
      "ccccccccccccHHHv",
      "cccccbccccccHHHv",
      "cccccccccccHHHHv",
      "HHHHHHHHHHHHHHHv",
      "HHHHHHHHHHHHHHHv",
      "HHHHHHHHHHHHHHHv",
      "HHHHHHHHHHHHHHHv",
      "HHHHHHHHHHHHHHHv",
      "HHHHHHHHHHHHHHHv",
      "cccccccccccHHHHv",
      "dddddbccccccHHHv",
      "eeeeefvcHHHHHHHv",
      "eeeeefvcHHHHHHHv",
      "eeeeefvcHHHHHHHv",
      "dddddbvcHHHHHHHv"
    ],
    [
      "ggggggggggh    v",
      "iiiiijiiiik    v",
      "ljjjmbljjjm    v",
      "               v",
      "               v",
      "               v",
      "               v",
      "               v",
      "               v",
      "               v",
      "               v",
      "nnnnnbo pppp   v",
      "      v q  r   v",
      "      v s  t   v",
      "      v q  r   v",
      "     bv s  t   v"
    ],
    [
      "               v",
      "               v",
      "     b         v",
      "               v",
      "               v",
      "               v",
      "               v",
      "               v",
      "               v",
      "               v",
      "               v",
      "nnnnnb         v",
      "      v        v",
      "      v        v",
      "      v        v",
      "     bv        v"
    ],
    [
      "               v",
      "               v",
      "     b         v",
      "               v",
      "               v",
      "               v",
      "               v",
      "               v",
      "               v",
      "               v",
      "               v",
      "nnnnnb         v",
      "      v        v",
      "      v        v",
      "      v        v",
      "     bv        v"
    ]
  ]
}