{
  "name": "multi_oasiscondo_13_floor8",
  "refpalette": "deceasedcraft:multi_oasiscondo_13/multi_oasiscondo_13_floor8_palette",
  "xsize": 16,
  "zsize": 16,
  "slices": [
    [
      "abbbbbb         ",
      "cbbbbbd         ",
      "eeeeee          ",
      "cbbbbbd         ",
      "cbbbbbb         ",
      "cbbbbbb         ",
      "cbbbbbb         ",
      "cbbbbbb         ",
      "cbbbbbb         ",
      "cbbbbbb         ",
      "cbbbbbb         ",
      "bbbbbbb         ",
      "cbbbbbb         ",
      "cbbbbbb         ",
      "cbbbbbb         ",
      "cbbbbbb         "
    ],
    [
      "f g h ic        ",
      "cjgklkcm        ",
      "eeeeee          ",
      "cn opqrm        ",
      "cst u wc        ",
      "cst    c        ",
      "cn   xyc        ",
      "cABB AAr        ",
      "cC   D r        ",
      "cC  EF c        ",
      "cC uIJKr        ",
      "cC  L!cc        ",
      "cC  gMNc        ",
      "cC  gO c        ",
      "cPQPc  r        ",
      "c   c Rc        "
    ],
    [
      "S g   Tc        ",
      "cUgV Wcm        ",
      "eeeeee          ",
      "cV  XYcm        ",
      "c      r        ",
      "c      Z        ",
      "c0     Z        ",
      "cABB AAZ        ",
      "cC   12Z        ",
      "cC  3  Z        ",
      "cC  45 Z        ",
      "cC  gcc6        ",
      "cC  g7 Z        ",
      "cC  g  Z        ",
      "cP8Pc  Z        ",
      "c   c  Z        "
    ],
    [
      "9 g    c        ",
      "c#g   cm        ",
      "eeeeee          ",
      "c     cm        ",
      "c      c        ",
      "c      Z        ",
      "c      Z        ",
      "cABB AAZ        ",
      "c$  %^ Z        ",
      "c&  *  Z        ",
      "c   () Z        ",
      "c+  gcc6        ",
      "c-  g[ Z        ",
      "c-  g  Z        ",
      "cP]Pc  Z        ",
      "c   c {Z        "
    ],
    [
      "c g }  c        ",
      "c g   rm        ",
      "eeeeee          ",
      "c     c|        ",
      "c      c        ",
      "c }  ; Z        ",
      "c      Z        ",
      "cAAAAAAZ        ",
      "c   g::Z        ",
      "c ' g::Z        ",
      "c   g::Z        ",
      "c   gcc6        ",
      "c ; g' Z        ",
      "c   g::Z        ",
      "cPPPc::Z        ",
      "c ' c::Z        "
    ],
    [
      "c<<<<<<c        ",
      "c<<<<<c|        ",
      "eeeeee          ",
      "c<<<<<r|        ",
      "c<<<<<<c        ",
      "c<<<<<<r        ",
      "c<<<<<<c        ",
      "c<<<<<<c        ",
      "c<<<<  c        ",
      "c<<<<  c        ",
      "c<<<<><c        ",
      "c<<<<<<c        ",
      "c<<<<<<c        ",
      "c<<<< >c        ",
      "c<<<<  c        ",
      "c<<<<  c        "
    ]
  ]
}