{
  "name": "multi_oasiscondo_13_floor4",
  "refpalette": "deceasedcraft:multi_oasiscondo_13/multi_oasiscondo_13_floor4_palette",
  "xsize": 16,
  "zsize": 16,
  "slices": [
    [
      "abbbbbb         ",
      "cbbbbbd         ",
      "eeeeee          ",
      "cbbbbbd         ",
      "cbbbbbb         ",
      "cbbbbbb         ",
      "cbbbbbb         ",
      "cbbbbbb         ",
      "cbbbbbb         ",
      "abbbbbb         ",
      "cbbbbbd         ",
      "eeeeee          ",
      "cbbbbbd         ",
      "cbbbbbb         ",
      "cbbbbbb         ",
      "cbbbbbb         "
    ],
    [
      "f g h ij        ",
      "ckglmlcn        ",
      "eeeeee          ",
      "c  oc ppp       ",
      "cq  r  ps       ",
      "ccccc  ts       ",
      "c      ts       ",
      "c      ts       ",
      "c     uts       ",
      "f g   ups       ",
      "cug wuppp       ",
      "eeeeee          ",
      "cx  cycA        ",
      "cBC cDEc        ",
      "cF  cI j        ",
      "c   c!Jc        "
    ],
    [
      "K g    c        ",
      "cLgM NcA        ",
      "eeeeee          ",
      "cO  c ppp       ",
      "c   P  pQ       ",
      "ccccc   Q       ",
      "c       Q       ",
      "c       Q       ",
      "c       Q       ",
      "K g   upQ       ",
      "c g   ppp       ",
      "eeeeee          ",
      "cR  cScn        ",
      "cT  c  c        ",
      "cU  cV W        ",
      "c   cI W        "
    ],
    [
      "X g    c        ",
      "cYg   cA        ",
      "eeeeee          ",
      "cZ  c ppp       ",
      "c   0  p        ",
      "ccccc           ",
      "cI              ",
      "c               ",
      "c               ",
      "X g    p        ",
      "c g  Ippp       ",
      "eeeeee          ",
      "c1  c2cA        ",
      "c3  c  c        ",
      "c4  c  W        ",
      "c   c 5W        "
    ],
    [
      "c g 6  j        ",
      "c g   cn        ",
      "eeeeee          ",
      "c777c8ppp       ",
      "c777c  p        ",
      "ccccc           ",
      "c I             ",
      "c               ",
      "c   8           ",
      "c g   Ip        ",
      "cIgI Ippp       ",
      "eeeeee          ",
      "c9  c#cA        ",
      "c$# c77j        ",
      "c   c77W        ",
      "c   c77W        "
    ],
    [
      "c%%%%%%c        ",
      "c%%%%%cn        ",
      "eeeeee          ",
      "c^  %%ppp       ",
      "c   %%%pp       ",
      "c%%%%%%pp       ",
      "c%%%%%%pp       ",
      "c%%%%%%pp       ",
      "c%%%%%%pp       ",
      "c%%%%%%pp       ",
      "c%%%%%ppp       ",
      "eeeeee          ",
      "c%%%%%jn        ",
      "c%%%% ^c        ",
      "c%%%%  c        ",
      "c%%%%  c        "
    ]
  ]
}