{
  "name": "multi_oasiscondo_13_floor6",
  "refpalette": "deceasedcraft:multi_oasiscondo_13/multi_oasiscondo_13_floor6_palette",
  "xsize": 16,
  "zsize": 16,
  "slices": [
    [
      "abccccc         ",
      "defcccg         ",
      "hhhhhh          ",
      "dcccccg         ",
      "dcccccc         ",
      "dcccccc         ",
      "dcccccc         ",
      "dcccccc         ",
      "dcccccc         ",
      "dcccccc         ",
      "dcccccc         ",
      "ccccccc         ",
      "dcccccc         ",
      "dcccccc         ",
      "dcccccc         ",
      "dcccccc         "
    ],
    [
      "i j k ld        ",
      "dmjnondp        ",
      "hhhhhh          ",
      "dq drrdp        ",
      "ds t  ud        ",
      "ds jwxyA        ",
      "dBCBBBBA        ",
      "dD    Ed        ",
      "dF  IJKd        ",
      "dF  IJKd        ",
      "dL    EA        ",
      "dMNMMMMd        ",
      "dOPQdRSd        ",
      "dO Tdw A        ",
      "dO Ud VA        ",
      "d   d Wd        "
    ],
    [
      "X j   Yd        ",
      "d jZ 0dp        ",
      "hhhhhh          ",
      "d1 dP d2        ",
      "ds34  5d        ",
      "ds j   6        ",
      "dB7BBBB6        ",
      "d     86        ",
      "d9     6        ",
      "d#     6        ",
      "d$    %6        ",
      "dM^MMMM&        ",
      "d  !d* 6        ",
      "d  Pd  6        ",
      "d   d( 6        ",
      "d   d )6        "
    ],
    [
      "+ j    d        ",
      "d-j   dp        ",
      "hhhhhh          ",
      "dddd[]A2        ",
      "d{ }  |d        ",
      "d{ j   6        ",
      "dB;BBBB6        ",
      "d      6        ",
      "d      6        ",
      "d      6        ",
      "d      6        ",
      "dM:MMMM&        ",
      "d  Pd' 6        ",
      "d   d  6        ",
      "d   d  6        ",
      "d   d <6        "
    ],
    [
      "d j >  d        ",
      "d j   d2        ",
      "hhhhhh          ",
      "dddd P,.        ",
      "d?/j` PA        ",
      "d? j\u0370\u0370 6        ",
      "dBBBBBB6        ",
      "d /  \u0371 6        ",
      "d      6        ",
      "d      6        ",
      "d \u0371  \u0371 6        ",
      "dMMMMMM&        ",
      "d   d/ 6        ",
      "d > d\u0370\u03706        ",
      "d   d\u0370\u03706        ",
      "d   d\u0370\u03706        "
    ],
    [
      "d\u0372\u0372\u0372\u0372\u0372\u0372A        ",
      "d\u0372\u0372\u0372\u0372\u0372d2        ",
      "hhhhhh          ",
      "d\u0372\u0372\u0372P!\u03732        ",
      "d\u0372\u0372\u0372  \u0372d        ",
      "d\u0372\u0372\u0372  \u0372A        ",
      "d\u0372\u0372\u0372\u0372\u0372\u0372d        ",
      "d\u0372\u0372\u0372\u0372\u0372\u0372A        ",
      "d\u0372\u0372\u0372\u0372\u0372\u0372d        ",
      "d\u0372\u0372\u0372\u0372\u0372\u0372d        ",
      "d\u0372\u0372\u0372\u0372\u0372\u0372d        ",
      "d\u0372\u0372\u0372\u0372\u0372\u0372d        ",
      "d\u0372\u0372\u0372\u0372\u0372\u0372A        ",
      "d\u0372\u0372\u0372\u0372 \u0374d        ",
      "d\u0372\u0372\u0372\u0372  d        ",
      "d\u0372\u0372\u0372\u0372  d        "
    ]
  ]
}