{
  "name": "multi_oasiscondo_13_floor10",
  "refpalette": "deceasedcraft:multi_oasiscondo_13/multi_oasiscondo_13_floor10_palette",
  "xsize": 16,
  "zsize": 16,
  "slices": [
    [
      "abbbbbb         ",
      "abbbbbc         ",
      "dddddd          ",
      "efffffc         ",
      "efffffb         ",
      "efffffb         ",
      "efffffb         ",
      "efffffb         ",
      "efffffb         ",
      "efffffb         ",
      "efffffb         ",
      "aaaaadb         ",
      "agggghb         ",
      "agggghb         ",
      "ag!gghb         ",
      "agggghb         "
    ],
    [
      "i     jk        ",
      "lmnonnkp        ",
      "dddddd          ",
      " qqqqqrrr       ",
      "  stu wrx       ",
      "      wwx       ",
      "      wwx       ",
      "      wwx       ",
      "      wwx       ",
      "      wwx       ",
      "      wwx       ",
      "     dwwx       ",
      "    yAwwx       ",
      "  B yAwwx       ",
      "  B yAwwx       ",
      "    yAwwx       "
    ],
    [
      "C      D        ",
      "lEnnooDp        ",
      "dddddd          ",
      " FFFFFrrr       ",
      "       rI       ",
      "        I       ",
      "        I       ",
      "        I       ",
      "        I       ",
      "        I       ",
      "        I       ",
      "     d  I       ",
      "     q  I       ",
      "     q  I       ",
      "     q  I       ",
      "     q  I       "
    ],
    [
      "l      k        ",
      "lJKLLMkN        ",
      "dddddd          ",
      "  F FFrrr       ",
      "       r        ",
      "                ",
      "                ",
      "                ",
      "                ",
      "                ",
      "                ",
      "     d          ",
      "                ",
      "                ",
      "                ",
      "                "
    ],
    [
      "k      k        ",
      "k     kp        ",
      "dddddd          ",
      "     Frrr       ",
      "       r        ",
      "       O        ",
      "       O        ",
      "       O        ",
      "       O        ",
      "       O        ",
      "       O        ",
      "     d O        ",
      "       O        ",
      "       O        ",
      "       O        ",
      "       O        "
    ],
    [
      "kPPPPPPk        ",
      "kPPPPPDp        ",
      "dddddd          ",
      "QQQQQQrrr       ",
      "QQQQQQrrr       ",
      "QQQQQQrrr       ",
      "QQQQQQrrr       ",
      "QQQQQQrrr       ",
      "QQQQQQrrr       ",
      "QQQQQQrrr       ",
      "QQQQQQrrr       ",
      "QQQQQdrrr       ",
      "QQQQQQrrr       ",
      "QQQQQQrrr       ",
      "QQQQQQrrr       ",
      "QQQQQQrrr       "
    ]
  ]
}