{
  "name": "multi_oasiscondo_13_floor7",
  "refpalette": "deceasedcraft:multi_oasiscondo_13/multi_oasiscondo_13_floor7_palette",
  "xsize": 16,
  "zsize": 16,
  "slices": [
    [
      "abbbbbb         ",
      "cbbbbbd         ",
      "eeeeee          ",
      "cbbbbbd         ",
      "cbbbbbb         ",
      "cbbbbbb         ",
      "cbbbbbb         ",
      "cbbbbbb         ",
      "cbbbbbb         ",
      "cbbbbbb         ",
      "cbbbbbb         ",
      "bbbbbbb         ",
      "cbbbbbb         ",
      "cbbbbbb         ",
      "cbbbbbb         ",
      "cbbbbbb         "
    ],
    [
      "f gh  ic        ",
      "cjgkl cm        ",
      "eeeeee          ",
      "cnnnnocm        ",
      "cpqqqqrc        ",
      "c   s  t        ",
      "cuwwwwwc        ",
      "c gxyyxt        ",
      "c g AA t        ",
      "c g    c        ",
      "c g    c        ",
      "c guwwBt        ",
      "c   c  t        ",
      "c   cC c        ",
      "c   c  t        ",
      "c   c Dc        "
    ],
    [
      "E gF   c        ",
      "cIg  Jcm        ",
      "eeeeee          ",
      "cKKKKKcL        ",
      "cMNOPQRt        ",
      "c      S        ",
      "cTwwwwwS        ",
      "c g!  US        ",
      "c g    S        ",
      "c g    S        ",
      "c g    S        ",
      "c gTwwVW        ",
      "c   cX S        ",
      "c   c  S        ",
      "c   cY S        ",
      "c   c  S        "
    ],
    [
      "Z g    c        ",
      "c0g   cL        ",
      "eeeeee          ",
      "cKKKKKtL        ",
      "c      c        ",
      "c      S        ",
      "c1wwwwwS        ",
      "c2g    S        ",
      "c g    S        ",
      "c g    S        ",
      "c g    S        ",
      "c g1ww3W        ",
      "c   c4 S        ",
      "c   c  S        ",
      "c   c  S        ",
      "c   c 5S        "
    ],
    [
      "c g 6  c        ",
      "c g   cm        ",
      "eeeeee          ",
      "cKKKKKcm        ",
      "c      c        ",
      "c 7  8 S        ",
      "cwwwwwwS        ",
      "c!g    S        ",
      "c2g    S        ",
      "c g 6  S        ",
      "c g    S        ",
      "c gwwwwW        ",
      "c  8c99S        ",
      "c   c99S        ",
      "c   c99S        ",
      "c  8c99S        "
    ],
    [
      "c######t        ",
      "c#####tm        ",
      "eeeeee          ",
      "c#####tL        ",
      "c######c        ",
      "c######c        ",
      "c######t        ",
      "c######c        ",
      "c######c        ",
      "c######c        ",
      "c######c        ",
      "c######c        ",
      "c######t        ",
      "c#### $c        ",
      "c####  c        ",
      "c####  c        "
    ]
  ]
}