{
  "name": "multi_oasiscondo_13_base3",
  "refpalette": "deceasedcraft:multi_oasiscondo_13/multi_oasiscondo_13_base3_palette",
  "xsize": 16,
  "zsize": 16,
  "slices": [
    [
      "               v",
      "               v",
      "     a         v",
      "               v",
      "               v",
      "               v",
      "               v",
      "               v",
      "               v",
      "               v",
      "               v",
      "bbbbba         v",
      "      v        v",
      "      v        v",
      "      v        v",
      "     av        v"
    ],
    [
      "               v",
      "               v",
      "     a         v",
      "               v",
      "               v",
      "               v",
      "               v",
      "               v",
      "               v",
      "               v",
      "               v",
      "bbbbba         v",
      "      v        v",
      "      v        v",
      "      v        v",
      "     av        v"
    ],
    [
      "               v",
      "               v",
      "     a         v",
      "               v",
      "               v",
      "               v",
      "               v",
      "               v",
      "               v",
      "               v",
      "               v",
      "bbbbba         v",
      "      v        v",
      "      v        v",
      "      v        v",
      "     av        v"
    ],
    [
      "               v",
      "               v",
      "     a         v",
      "               v",
      "               v",
      "               v",
      "               v",
      "               v",
      "               v",
      "               v",
      "               v",
      "bbbbba         v",
      "      v        v",
      "      v        v",
      "      v        v",
      "     av        v"
    ],
    [
      "               v",
      "               v",
      "     a         v",
      "               v",
      "               v",
      "               v",
      "               v",
      "               v",
      "               v",
      "               v",
      "               v",
      "bbbbba         v",
      "      v        v",
      "      v        v",
      "      v        v",
      "     av        v"
    ],
    [
      "cccccdcccccccccv",
      "cccccdcccccccccv",
      "dddddedddddddddv",
      "cccccdcccccccccv",
      "cccccdcccccccccv",
      "cccccdcccccccccv",
      "cccccdcccccccccv",
      "cccccdcccccccccv",
      "cccccdcccccccccv",
      "cccccdcccccccccv",
      "cccccdcccccccccv",
      "dddddedddddddddv",
      "fffffdvccccccccv",
      "fffffdvccccccccv",
      "fffffdvccccccccv",
      "dddddevccccccccv"
    ]
  ]
}