{
  "name": "multi_oasiscondo_13_ground",
  "refpalette": "deceasedcraft:multi_oasiscondo_13/multi_oasiscondo_13_ground_palette",
  "xsize": 16,
  "zsize": 16,
  "slices": [
    [
      "aHHHHaaaaaaaaaaa",
      "aHHHaaaaaaaaaaaa",
      "aHHHabcccccccccc",
      "aHHHaacddddddddd",
      "aHHHaacdddeeeeed",
      "aHHHaacddeefffee",
      "aHHHaacddefffffe",
      "aHHHaacddefffffe",
      "aHHHaacddefffffe",
      "aHHHaacddefffffe",
      "aHHHaacddefffffe",
      "aHHHabcddefffffe",
      "aHHHaacddefffffe",
      "aHHHaacddefffffe",
      "ghhhggcddefffffe",
      "ijjjiicddefffffe"
    ],
    [
      "                ",
      "                ",
      "     bk         ",
      "       l        ",
      "       m        ",
      "       m   nnn  ",
      "       m  nooon ",
      "       m  nofon ",
      "       m  nofon ",
      "       m  nofon ",
      "       l  nofon ",
      "     bkl  nofon ",
      "       l  nofon ",
      "       m  nofon ",
      "       m  nofon ",
      "       m  nofon "
    ],
    [
      "                ",
      "                ",
      "     b          ",
      "                ",
      "                ",
      "                ",
      "                ",
      "                ",
      "            p   ",
      "                ",
      "                ",
      "     b      p   ",
      "                ",
      "                ",
      "            p   ",
      "                "
    ],
    [
      "                ",
      "                ",
      "     b          ",
      "                ",
      "                ",
      "                ",
      "                ",
      "                ",
      "            m   ",
      "                ",
      "                ",
      "     b      m   ",
      "                ",
      "                ",
      "            m   ",
      "                "
    ],
    [
      "                ",
      "                ",
      "     b          ",
      "                ",
      "                ",
      "                ",
      "                ",
      "                ",
      "            l   ",
      "                ",
      "                ",
      "     b      l   ",
      "                ",
      "                ",
      "            l   ",
      "                "
    ],
    [
      "                ",
      "                ",
      "     b          ",
      "                ",
      "                ",
      "                ",
      "                ",
      "                ",
      "            l   ",
      "                ",
      "                ",
      "     b      l   ",
      "                ",
      "                ",
      "            l   ",
      "                "
    ]
  ]
}