{
  "name": "building_apartmentsmallbbroken_ground",
  "refpalette": "deceasedcraft:building_apartmentsmallbbroken/building_apartmentsmallbbroken_ground_palette",
  "xsize": 16,
  "zsize": 16,
  "slices": [
    [
      "abaccbbcdcbbcbac",
      "aaccbbedbfebbaac",
      "acggggggggggggab",
      "baghhhhhhhhhhgaa",
      "aaghhhhhhhhihgaa",
      "ajghhhhihihhhgja",
      "ajhhhhhkilkhihjc",
      "ajhhhhkilmlihhja",
      "ajhhhhiimnooocja",
      "ajhhhihllooocbja",
      "ajhhhhiiiooccpja",
      "ajhhhhihkcocbbja",
      "ajhhhhhhhbcbppja",
      "ajhhhhhihbppbpjc",
      "cjjjjjjjjjjjjjja",
      "aaacccqaaaacaaaa"
    ],
    [
      " rs t uw   w u  ",
      "   x r lyxr rA s",
      "w BCgCBBBCBgBB u",
      "uDC  Ehih FFFBA ",
      "  g I JI     gs ",
      " KgCgCB      gK ",
      "LMN O         K ",
      " MN          PK ",
      " K           Q  ",
      " RS           T ",
      " KS          UT ",
      " K           QT ",
      " KS     V  Q    ",
      " MS     VQ U  T ",
      " MKW  XKKT TTTT ",
      "                "
    ],
    [
      "                ",
      "                ",
      "  YgggCBgCCgCZ  ",
      "  g   0hh1222C  ",
      "  B          g  ",
      " MggCgC34    CM ",
      " K            K ",
      " M            K ",
      " T       l      ",
      " T              ",
      " T            T ",
      " T            T ",
      " T            T ",
      " T            T ",
      " MKW  WKK TTTTT ",
      "                "
    ],
    [
      "                ",
      "                ",
      "  ggggCBCggggC  ",
      "  g    0i!222g  ",
      "  C     511  g  ",
      " KggCCBBC    gM ",
      " M            M ",
      " K            K ",
      " T       m    T ",
      " T       l      ",
      " T            T ",
      " T            T ",
      " T            T ",
      " T            T ",
      " KMW6 XMKTTTTT  ",
      "                "
    ],
    [
      "                ",
      "                ",
      "  CggggCggggCg  ",
      "  g     7ihhhg  ",
      "  g     8ggggg  ",
      " KgCgCCgg9CCgg# ",
      " K            K ",
      " K        l   K ",
      " $      lm    % ",
      "         ^    % ",
      " $      l     & ",
      " &            & ",
      " &            $ ",
      " &              ",
      " KKWXWWKM%%&&%* ",
      "                "
    ],
    [
      "                ",
      "                ",
      "  ggg(gg)ggCg+  ",
      "  g--    Ehhhg  ",
      "  g      8gggg  ",
      " MgggCBgBBggggM ",
      " KjjjeljjjjdjjM ",
      " MjjdljejdljjjK ",
      " Kjjjdedl^mjjjM ",
      " KjjjeleefljjjK ",
      " KjjjeefeejjjjK ",
      " KjjjjleldjjjjK ",
      " KjjjjjldjjjjjK ",
      " MjjjjjjjjjjjjM ",
      " MKMKKMM[MKKMKM ",
      "                "
    ]
  ]
}