{
  "name": "building_apartmentsmallbbroken_ground_180",
  "refpalette": "deceasedcraft:building_apartmentsmallbbroken/building_apartmentsmallbbroken_ground_palette_180",
  "xsize": 16,
  "zsize": 16,
  "slices": [
    [
      "aaaacaaaaqcccaaa",
      "ajjjjjjjjjjjjjjc",
      "cjpbppbhihhhhhja",
      "ajppbcbhhhhhhhja",
      "ajbbcockhihhhhja",
      "ajpccooiiihhhhja",
      "ajbcooollhihhhja",
      "ajcooonmiihhhhja",
      "ajhhilmlikhhhhja",
      "cjhihklikhhhhhja",
      "ajghhhihihhhhgja",
      "aaghihhhhhhhhgaa",
      "aaghhhhhhhhhhgab",
      "baggggggggggggca",
      "caabbefbdebbccaa",
      "cabcbbcdcbbccaba"
    ],
    [
      "                ",
      " TTTT TKKX  WKM ",
      " T  U QV     SM ",
      "    Q  V     SK ",
      " TQ           K ",
      " TU          SK ",
      " T           SR ",
      "  Q           K ",
      " KP          NM ",
      " K         O NML",
      " Kg      BCgCgK ",
      " sg     IJ I g  ",
      " ABFFF hihE  CDu",
      "u BBgBCBBBCgCB w",
      "s Ar rxyl r x   ",
      "  u w   wu t sr "
    ],
    [
      "                ",
      " TTTTT KKW  WKM ",
      " T            T ",
      " T            T ",
      " T            T ",
      " T            T ",
      "              T ",
      "      l       T ",
      " K            M ",
      " K            K ",
      " MC    43CgCggM ",
      "  g          B  ",
      "  C2221hh0   g  ",
      "  ZCgCCgBCgggY  ",
      "                ",
      "                "
    ],
    [
      "                ",
      "  TTTTTKMX 6WMK ",
      " T            T ",
      " T            T ",
      " T            T ",
      " T            T ",
      "      l       T ",
      " T    m       T ",
      " K            K ",
      " M            M ",
      " Mg    CBBCCggK ",
      "  g  115     C  ",
      "  g222!i0    g  ",
      "  CggggCBCgggg  ",
      "                ",
      "                "
    ],
    [
      "                ",
      " *%&&%%MKWWXWKK ",
      "              & ",
      " $            & ",
      " &            & ",
      " &     l      $ ",
      " %    ^         ",
      " %    ml      $ ",
      " K   l        K ",
      " K            K ",
      " #ggCC9ggCCgCgK ",
      "  ggggg8     g  ",
      "  ghhhi7     g  ",
      "  gCggggCggggC  ",
      "                ",
      "                "
    ],
    [
      "                ",
      " MKMKKM[MMKKMKM ",
      " MjjjjjjjjjjjjM ",
      " KjjjjjdljjjjjK ",
      " KjjjjdleljjjjK ",
      " KjjjjeefeejjjK ",
      " KjjjlfeelejjjK ",
      " Mjjjm^ldedjjjK ",
      " KjjjldjejldjjM ",
      " MjjdjjjjlejjjK ",
      " MggggBBgBCgggM ",
      "  gggg8      g  ",
      "  ghhhE    --g  ",
      "  +gCgg)gg(ggg  ",
      "                ",
      "                "
    ]
  ]
}