{
  "name": "building_apartmentsmallbbroken_top_270",
  "refpalette": "deceasedcraft:building_apartmentsmallbbroken/building_apartmentsmallbbroken_top_palette_270",
  "xsize": 16,
  "zsize": 16,
  "slices": [
    [
      "                ",
      "  nnnnnnnn      ",
      " yuuuuuggobbba  ",
      " yuuuuuggoggfb  ",
      " yuuuquggpgfgc  ",
      " yuxmlwlqqfjhd  ",
      " yuuummmlrlk e  ",
      " ypolmrmmmmk d  ",
      "  xmrlmmmlf  d  ",
      " yuuxmlruqgk d  ",
      " yuuuququsgjie  ",
      " yuuuuuuwggggb  ",
      " yuuuuuuuogggb  ",
      " yuuuuuuuobbbb  ",
      "  tttttttt      ",
      "                "
    ],
    [
      "                ",
      " ossoosooso     ",
      " s2662W PobbCA  ",
      " o(77 X  s   c  ",
      " sZ   YUQs F B  ",
      " }) 8 Z wq IDb  ",
      " s+%l3   N JEb  ",
      " |pl  N    J c  ",
      " p-     R  K b  ",
      " ;[^  ZNlq J x  ",
      " s]&9 l  p L b  ",
      " :{*3 0  O M c  ",
      " o###4  So   c  ",
      " o$$$51VTobbCa  ",
      " sosoooosoo     ",
      "                "
    ],
    [
      "                ",
      " s\u037a\u037d\u037aoo soo     ",
      " s    W \u0373obb,'  ",
      " \u0385    X \u0374o   c  ",
      "         s / <  ",
      "        \u0375\u0372 ` B  ",
      " \u0386         \u0370.B  ",
      " ;p\u037el      \u0371?<  ",
      " \u0387\u0375        \u0370 >  ",
      "         ; ` c  ",
      "      3  s ` B  ",
      " \u0385         / <  ",
      " \u0385       s   <  ",
      " s\u0384*\u037b\u0377   obb,c  ",
      " o\u037f\u037f\u037coo\u0376oos     ",
      "                "
    ],
    [
      "                ",
      " o\u037d\u037a\u037aoo\u0392sso     ",
      " o    W \u0390obb,b  ",
      " \u0385    W \u0374s   <  ",
      " \u0385    X  o / <  ",
      "         \u038e / x  ",
      " \u0385    Y    \u038a <  ",
      " sss\u0394l       m  ",
      " o          \u037dm  ",
      "           \u038c x  ",
      " \u0385      \u0391\u038f / <  ",
      "         j / m  ",
      " \u0385       o   \u0388  ",
      " o\u0395      obb,\u0389  ",
      " s\u037f\u037c\u037cso\u0393sos     ",
      "                "
    ],
    [
      "                ",
      " s \u0385\u0385so\u037doos     ",
      " s    WPPobbCb  ",
      " \u039a    W  o   \u0396  ",
      " \u039a    W  s / <  ",
      " \u039a    X    \u038c m  ",
      " \u039b    X      m  ",
      " osospxl        ",
      " o              ",
      "         \u0399 \u0397Em  ",
      " \u039c   !P \u0391s \u0398 <  ",
      " \u039b       s / x  ",
      " \u039a       o   c  ",
      " oP      obbCB  ",
      " o\u0385 \u0385os\u037coop     ",
      "                "
    ],
    [
      "                ",
      " ooosoooss\u03a5     ",
      " s\u03a8\u03a8\u03a8\u03a8\u03a8\u03a7\u03a7obbbb  ",
      " o\u03a8\u03a8\u03a8\u03a8\u03a8\u03a7\u03a7s  \u039e<A ",
      " o\u03a8\u03a8\u03a8\u03a8\u03a8\u03a7\u03a7s \u0398\u039ex  ",
      " s\u03a8\u03a8\u03a8\u03a8\u03a8\u03a7\u03a7\u0387   m  ",
      " o\u03a8\u03a8\u03a8\u03a8\u03a8\u03a7\u03a7\u0399      ",
      " sooooooo       ",
      " o\u03a8\u03a8\u03a8\u03a8\u03a8\u03a8\u03a8\u0399      ",
      " s\u03a8\u03a8\u03a8\u03a8\u03a8\u03a8\u03a8s \u03a1\u039f   ",
      " s\u03a8\u03a8\u03a8\u03a8\u03a8\u03a8\u03a8o \u03a3Em  ",
      " o\u03a8\u03a8\u03a8\u03a8\u03a8\u03a8\u03a8s \u03a4\u03a0m  ",
      " o\u03a8\u03a8\u03a8\u03a8\u03a8\u03a8\u03a8s  \u03a0<\u039d ",
      " s\u03a8\u03a8\u03a8\u03a8\u03a8\u03a8\u03a8obbbb  ",
      " ssosspsos\u03a6     ",
      "                "
    ],
    [
      "                ",
      "  nnnnnnnn      ",
      " yuuuuuggobbbb\u03a9 ",
      " yuuuuuggogg\u03aaq\u03a9 ",
      " yuuuuuggogfmm\u039d ",
      " yuuuuuggo\u03aa x   ",
      " yuuuuuggok     ",
      " yossususp      ",
      " yuuuuuuuo\u037d     ",
      " yuuuuuuuof     ",
      " yuuuuuuuogki   ",
      " yuuuuuuug\u03aa<qm  ",
      " yuuuuuuupf<mq\u039d ",
      " yuuuuuuuobbBb\u03a9 ",
      "  tttttttt      ",
      "                "
    ],
    [
      "                ",
      " ooooooosoo     ",
      " s2662W  s\u03b0bC\u03ab\u03a9 ",
      " oP77 X ~o  \u03ac \u039d ",
      " s(   Y~\u03b2o F    ",
      " o)     ~s \u03aeD   ",
      " o\u03b9\u03b8\u03b6 Y  s      ",
      " soop s po      ",
      " o--\u03b7 \u03b4\u03b3 s      ",
      " o  ]\u03b5\u03b4 \u03b3o      ",
      " o\u03ba\u03b7  \u03b4O\u0391\u03b1 \u03ae    ",
      " o{] *0  OO\u03af  \u039d ",
      " s###* * p    A ",
      " o$$$51VTobC\u03adBA ",
      " soosososso     ",
      "                "
    ],
    [
      "                ",
      " o\u037a\u037a\u037aos\u03c0oos     ",
      " s!P  W \u0373o b\u03a9\u03bb\u03a9 ",
      " \u0385\u03c5   W \u0374o    \u03a9 ",
      " \u0385\u03c6   X  s /  \u039d ",
      " \u0385\u03c6      o `    ",
      " \u0385\u03c7\u03c4\u03c2 X \u03bfo      ",
      " ooos o oo      ",
      " o\u03c8     \u03bfo \u03bd  \u039d ",
      " \u0385\u03c5      o      ",
      " \u0385\u03c6      s \u03be  \u039d ",
      " \u0385\u03c6        /  A ",
      " \u0385\u03c7      s    \u03a9 ",
      " s\u0384\u0384\u03c3\u0377\u03c1 *ob, \u03bc\u03a9 ",
      " o\u037f\u037f\u037foo so\u03a5     ",
      "                "
    ],
    [
      "                ",
      " s\u037a\u037a\u037dso\u0392oso     ",
      " oP   W \u0390o b\u03ab\u03b0\u03a9 ",
      " \u0385\u03d1   W \u0374o    \u03c9 ",
      " \u0385\u03d2   W  o /  \u03c9 ",
      " \u0385\u03d2   X  s /  \u03ca ",
      " \u0385\u03d3   X  o \u03be  \u03cb ",
      " oooo\u03d0o\u03d0oo \u03bd    ",
      " o       o \u03be  \u039d ",
      " \u0385\u03d1      o    \u03cc ",
      " \u0385\u03d2      o /  \u03c9 ",
      " \u0385\u03d2        \u03ce  \u03cb ",
      " \u0385\u03d3      o    \u03c9 ",
      " o\u0384\u037b     sb  \u03cd\u03ab ",
      " o\u037f\u037f\u037coo\u0393os\u03cf     ",
      "                "
    ],
    [
      "                ",
      " s\u0385\u0385\u0385oo\u037aoss     ",
      " o    W  o bbC\u03d4 ",
      " \u039a    W  s    b ",
      " \u039a    W  o /  b ",
      " \u039a    W  o \u0398  b ",
      " \u039a    W  o \u0398  c ",
      " oooooooso \u0371  B ",
      " o       o \u038c \u037dB ",
      " \u039b       s \u0371 EB ",
      " \u039a   \u03d6  \u0391o \u0398  c ",
      " \u039a       o /  b ",
      " \u039a       o    b ",
      " o       oc \u03d5Cb ",
      " o\u0385\u0385 so\u037fos\u03cf     ",
      "                "
    ],
    [
      "                ",
      " ooooosossp     ",
      " o\u03a8\u03a8\u03a8\u03a8\u03a8\u03a7\u03a7s\u03df\u03bbbc\u03d7 ",
      " o\u03a8\u03a8\u03a8\u03a8\u03a8\u03a7\u03a7o    B ",
      " o\u03a8\u03a8\u03a8\u03a8\u03a8\u03a7\u03a7o \u03dc \u039eb ",
      " o\u03a8\u03a8\u03a8\u03a8\u03a8\u03a7\u03a7o \u03dd  b ",
      " s\u03a8\u03a8\u03a8\u03a8\u03a8\u03a7\u03a7o \u03de  b ",
      " sooooooos \u03de  \u03d4 ",
      " o\u03a8\u03a8\u03a8\u03a8\u03a8\u03a8\u03a8o \u03de  c ",
      " o\u03a8\u03a8\u03a8\u03a8\u03a8\u03a8\u03a8o \u03de \u03d9\u03d8 ",
      " s\u03a8\u03a8\u03a8\u03a8\u03a8\u03a8\u03a8o \u03a3 \u03dab ",
      " o\u03a8\u03a8\u03a8\u03a8\u03a8\u03a8\u03a8o \u03a4  b ",
      " o\u03a8\u03a8\u03a8\u03a8\u03a8\u03a8\u03a8o    c ",
      " o\u03a8\u03a8\u03a8\u03a8\u03a8\u03a8\u03a8oa\u03df\u03dbbA ",
      " ooooooss\u03e0      ",
      "                "
    ],
    [
      "                ",
      "  nnnnnnnn      ",
      " yuuuuuggo \u03b0bbc ",
      " yuuuuuggog\u03e3 \u03e1b ",
      " yuuuuuggogg fb ",
      " yuuuuuggogj \u03dad ",
      " yuuuuuggogj  d ",
      " yooououoogk  d ",
      " yuuuuuuuogj  e ",
      " yuuuuuuuogj  e ",
      " yuuuuuuuogk id ",
      " yuuuuuuuggf gb ",
      " yuuuuuuuogj\u03e2gb ",
      " yuuuuuuuo\u03a9  cb ",
      "  tttttttt      ",
      "                "
    ],
    [
      "                ",
      " ooooooooos     ",
      " o2662W  s \u03b0bCb ",
      " o 77 W \u0374o   \u03e5\u03bbA",
      " o    W Qo F  \u03bcA",
      " o  \u03f2 \u03f0 \u03ecs I \u03ac\u03e4\u03a9",
      " o\u03b9\u03b8\u03b6 W \u03edo K gg\u03a9",
      " oooo\u03f1o\u03efos J \u03e6\u039eA",
      " o--  \u03b4 \u03b3o J  \u03bb ",
      " o \u03f3  \u03b4 \u03b3o J  \u03e4\u03a9",
      " o  ] \u03b4 \u0391o\u03eaL  \u03bc\u03a9",
      " o{   0  \u03eb \u03af  \u03e4\u03a9",
      " o### ] \u03ees    \u03bb\u03a9",
      " o$$$51VTo\u03ab\u03e9\u03e8\u03e7b ",
      " oooooosos\u0394     ",
      "                "
    ],
    [
      "                ",
      " o\u037a\u037d\u037aso\u03c0oso     ",
      " o(  \u03fcW \u0373s  b,\u03bbA",
      " \u0385\u0400   W \u0374s    \u03b0A",
      " \u0385\u0401   W  o /  \u03b0\u039d",
      " \u0385\u0401   \u03fb  o `  \u03b0\u03a9",
      "  \u0402\u03ff\u03fe W \u03bfo ` \u03f4\u03b0\u03a9",
      " oooo\u03fdo\u03faoo `  \u03d9\u03a9",
      " o      \u03f7o \u03be  \u03da\u03a9",
      " \u0385\u0400     \u03f8o `  \u03b0A",
      " \u0385\u0401     \u0391o\u03f5`  \u03b0\u03a9",
      " \u0385\u0401      \u03f6 /  \u03b0\u03a9",
      " \u0385\u0402     \u03f9o    \u03b0A",
      " o\u0384\u0384\u0384\u0377   ob\u03df  \u03e4\u03a9",
      " o\u037c\u037f\u037cos\u0376oos     ",
      "                "
    ],
    [
      "                ",
      " o\u037a\u037a\u037aoo\u0392oss     ",
      " o    W \u0390s  \u03bb\u03a9\u03b0\u039d",
      " \u0385\u0406   W \u0374s     \u03a9",
      " \u0385\u0407   W  o /  \u03b0\u03a9",
      " \u0385\u0407   W \u0403o /  \u03b0\u03a9",
      " \u0385\u0408   W \u0404o /  \u03b0\u03a9",
      " oooo\u03d0o\u03d0oo /   \u03a9",
      " o      \u0404o /  \u03d9\u03a9",
      " \u0385\u0406     \u0405o /  \u03da\u03a9",
      " \u0385\u0407     \u0391o /  \u03b0\u03a9",
      " \u0385\u0407      j /  \u03b0\u03a9",
      " \u0385\u0408      s    \u03b0A",
      " o\u0384\u0384\u0384    ob,  \u03cd\u03a9",
      " o\u037c\u037f\u037foo\u0393oso     ",
      "                "
    ],
    [
      "                ",
      " o\u0385\u0385\u0385oo\u037assp     ",
      " o    W  o  bbC\u03a9",
      " \u039a    W  p    \u03b0\u03ab",
      " \u039a    W  s /  \u03b0\u03ab",
      " \u039b    W  o \u0398   \u03ab",
      " \u039a    W  s \u0398  \u03b0\u03ab",
      " ooooooooo \u0398  \u03b0\u03ab",
      " o       o \u0398   \u03ab",
      " \u039a       o \u0398  i\u03ab",
      " \u039a   \u03d6  \u0391o \u0398  \u03da\u03a9",
      " \u039a       s /  \u03b0\u03a9",
      " \u039a       o    \u03b0\u03ab",
      " o       ob  \u03dfC\u03ab",
      " o\u0385\u0385\u0385oo\u037foos     ",
      "                "
    ],
    [
      "                ",
      " ooooooooss     ",
      " o\u03a8\u03a8\u03a8\u03a8\u03a8\u03a7\u03a7s \u03df\u03bbbbb",
      " o\u03a8\u03a8\u03a8\u03a8\u03a8\u03a7\u03a7o  \u03bbggb",
      " o\u03a8\u03a8\u03a8\u03a8\u03a8\u03a7\u03a7s \u040c\u03bbggb",
      " o\u03a8\u03a8\u03a8\u03a8\u03a8\u03a7\u03a7s \u03dd   d",
      " o\u03a8\u03a8\u03a8\u03a8\u03a8\u03a7\u03a7o \u03de   d",
      " ooooooooo \u03de   e",
      " s\u03a8\u03a8\u03a8\u03a8\u03a8\u03a8\u03a8o \u03de   d",
      " s\u03a8\u03a8\u03a8\u03a8\u03a8\u03a8\u03a8o \u040d   d",
      " o\u03a8\u03a8\u03a8\u03a8\u03a8\u03a8\u03a8o \u03a3  \u03d9d",
      " o\u03a8\u03a8\u03a8\u03a8\u03a8\u03a8\u03a8o \u03a4 \u040agb",
      " o\u03a8\u03a8\u03a8\u03a8\u03a8\u03a8\u03a8s   gfb",
      " o\u03a8\u03a8\u03a8\u03a8\u03a8\u03a8\u03a8ob\u03df \u040bb\u0409",
      " ooooooosss     ",
      "                "
    ],
    [
      "                ",
      "  nnnnnnnn      ",
      " y\u03a8\u03a8\u03a8\u03a8\u03a8\u03a8\u03a8\u03a8  \u03b0bba",
      " y\u03a8\u03a8\u03a8\u03a8\u03a8\u03a8\u03a8\u03a8 \u0414\u0412\u0411\u040eb",
      " y\u03a8\u03a8\u0416\u0416\u03a8\u03a8\u03a8\u03a8  \u03b0 \u040fb",
      " y\u03a8\u03a8\u0416\u0417\u0414\u0414\u0414\u0414g \u03b0  b",
      " y\u03a8\u03a8\u03a8\u03a8\u03a8\u03a8\u03a8\u03a8g    b",
      "  \u03a8\u03a8\u03a8\u03a8\u03a8\u03a8\u03a8\u03a8g    b",
      "  \u03a8\u03a8\u03a8\u03a8\u03a8\u03a8\u03a8\u03a8g\u0415   b",
      " y\u03a8\u03a8\u03a8\u03a8\u03a8\u03a8\u03a8\u03a8g\u0415   \u03ab",
      " y\u03a8\u03a8\u03a8\u03a8\u03a8\u03a8\u03a8\u03a8gg   b",
      " y\u03a8\u03a8\u03a8\u03a8\u03a8\u03a8\u03a8\u03a8gg   b",
      "  \u03a8\u03a8\u03a8\u03a8\u03a8\u03a8\u03a8\u03a8gg  \u0410b",
      " y\u03a8\u03a8\u03a8\u03a8\u03a8\u03a8\u03a8\u03a8b \u0413\u03dfcb",
      "  tttttttt      ",
      "                "
    ],
    [
      "                ",
      "                ",
      "  \u041f\u041f\u041f\u041f\u041f \u041f    bbb",
      "  \u041f \u0426\u0426      \u03b0  b",
      "  \u041f\u042a\u0416\u0416\u0424     \u03b0 \u040fa",
      " \u041f\u041f\u042a\u0416\u0427\u0424 \u041d\u0414a \u03b0  b",
      "  \u0425 \u0428\u0428  \u0420 b    b",
      "   \u042b   \u0410 \u041db    b",
      "  \u041f \u0421 \u0425 \u0421\u041eb\u0419   b",
      "  \u041f  \u0429  \u0422\u041eb    b",
      "  \u041f \u0410 \u0423   b\u041a   b",
      "  \u041f\u0425   \u0410  \u041c\u041b   b",
      "  \u0410     \u0423 b    b",
      "  \u041f\u041f\u041f\u041f\u041f\u041f\u041f\u041fb\u03e9\u0418\u03e8bb",
      "                ",
      "                "
    ],
    [
      "                ",
      "                ",
      "            \u03b0bba",
      "            \u03b0\u0419\u0419\u03a9",
      "    \u042e    \u0414  \u03b0\u0419\u0419 ",
      " \u0420       \u0414   \u0419\u0419\u041a",
      "          b  \u0419\u0419a",
      "          b  \u042c\u0419a",
      "         \u041db   \u0419a",
      "         \u041db  \u0419\u0419a",
      "          b   \u0419\u041a",
      "          \u042d   \u0419a",
      "          b   \u0419a",
      "  \u0420      \u0420b\u03df  b\u041a",
      "                ",
      "                "
    ],
    [
      "                ",
      "                ",
      "             \u041a  ",
      "                ",
      "                ",
      "                ",
      "                ",
      "          a     ",
      "          \u041a     ",
      "          b     ",
      "          b\u042f    ",
      "          b\u0419    ",
      "          b\u0419    ",
      "          b\u03ab    ",
      "                ",
      "                "
    ]
  ]
}