{
  "name": "building_apartmentsmallbbroken_ground_90",
  "refpalette": "deceasedcraft:building_apartmentsmallbbroken/building_apartmentsmallbbroken_ground_palette_90",
  "xsize": 16,
  "zsize": 16,
  "slices": [
    [
      "ccbaaacaaaaaacaa",
      "aaaaajjjjjjjjjja",
      "bagggghhcbpbppja",
      "cbghhhihoccbpbja",
      "bbghihhiooccbpjc",
      "beghhhkloooocpja",
      "cfghhilmnoocbbja",
      "dbghhhilmlikhhja",
      "cdghhikiilihhija",
      "beghhhhkihiihhjq",
      "bbghhhhhhihhhhjc",
      "cbghhhhhhhhhhhjc",
      "ccghhhhhhhhhhhjc",
      "acgggghhhhhhhhja",
      "bacaajjjjjjjjjja",
      "aaabaaaaaaaaaaca"
    ],
    [
      " su             ",
      "   AsKKK TTT TT ",
      "uABBgg PQ UQ  T ",
      " rBF          T ",
      "w gF        QUT ",
      " rBF            ",
      " xC          QT ",
      " yBh        VVK ",
      "wlBiI         K ",
      "u BhJB        X ",
      " rCE C          ",
      "t g IgO         ",
      " xC  C        W ",
      "s BCggNN SS SSK ",
      "r  D KMMKRKKKMM ",
      "  wu  L         "
    ],
    [
      "                ",
      "     MKK  TTTTT ",
      "  ZCgC        T ",
      "  C2          T ",
      "  g2          T ",
      "  C2          T ",
      "  C1    l       ",
      "  gh 4        K ",
      "  Bh 3        K ",
      "  C0 C        W ",
      "  g  g          ",
      "  g  C          ",
      "  g  g        W ",
      "  YgBg        K ",
      "     MKMTTTTTTM ",
      "                "
    ],
    [
      "                ",
      "     MMKT TTTT  ",
      "  Cggg        T ",
      "  g2          T ",
      "  g2          T ",
      "  g21         T ",
      "  g!1   ml    T ",
      "  Ci5C        K ",
      "  B0 B        M ",
      "  C  B        X ",
      "  g  C          ",
      "  g  C        6 ",
      "  g  g        W ",
      "  ggCg        M ",
      "     KMKTTTTTTK ",
      "                "
    ],
    [
      "                ",
      "     #KK%%&&$ * ",
      "  gggg        % ",
      "  Chgg        & ",
      "  ghgC        & ",
      "  ghgC l      % ",
      "  gig9  m^    % ",
      "  g78g  l l   M ",
      "  C  g        K ",
      "  g  C        W ",
      "  g  C        W ",
      "  g  g        X ",
      "  g  C        W ",
      "  Cggg        K ",
      "     KKK$ $&&&K ",
      "                "
    ],
    [
      "                ",
      "     MMKMKKKKMM ",
      "  +gggjjjjjjjjK ",
      "  ghggjjjjjjjjM ",
      "  ChggdjjjjjjjK ",
      "  ghggjlmljjjjK ",
      "  gE8Bjd^fedjjM ",
      "  )  Bjjleeldj[ ",
      "  g  gjedefeljM ",
      "  g  BljeleljjM ",
      "  (  CeldeejjjK ",
      "  g- gjdjjjjjjK ",
      "  g- gjjjjjjjjM ",
      "  ggggjjjjjjjjK ",
      "     MKMKKKKKMM ",
      "                "
    ]
  ]
}