{
  "name": "building_apartmentsmallbbroken_ground_270",
  "refpalette": "deceasedcraft:building_apartmentsmallbbroken/building_apartmentsmallbbroken_ground_palette_270",
  "xsize": 16,
  "zsize": 16,
  "slices": [
    [
      "acaaaaaaaaaabaaa",
      "ajjjjjjjjjjaacab",
      "ajhhhhhhhhggggca",
      "cjhhhhhhhhhhhgcc",
      "cjhhhhhhhhhhhgbc",
      "cjhhhhihhhhhhgbb",
      "qjhhiihikhhhhgeb",
      "ajihhiliikihhgdc",
      "ajhhkilmlihhhgbd",
      "ajbbcoonmlihhgfc",
      "ajpcoooolkhhhgeb",
      "cjpbccooihhihgbb",
      "ajbpbccohihhhgbc",
      "ajppbpbchhggggab",
      "ajjjjjjjjjjaaaaa",
      "aacaaaaaacaaabcc"
    ],
    [
      "         L  uw  ",
      " MMKKKRKMMK D  r",
      " KSS SS NNggCB s",
      " W        C  Cx ",
      "         OgI g t",
      "          C ECr ",
      " X        BJhB u",
      " K         IiBlw",
      " KVV        hBy ",
      " TQ          Cx ",
      "            FBr ",
      " TUQ        Fg w",
      " T          FBr ",
      " T  QU QP ggBBAu",
      " TT TTT KKKsA   ",
      "             us "
    ],
    [
      "                ",
      " MTTTTTTMKM     ",
      " K        gBgY  ",
      " W        g  g  ",
      "          C  g  ",
      "          g  g  ",
      " W        C 0C  ",
      " K        3 hB  ",
      " K        4 hg  ",
      "       l    1C  ",
      " T          2C  ",
      " T          2g  ",
      " T          2C  ",
      " T        CgCZ  ",
      " TTTTT  KKM     ",
      "                "
    ],
    [
      "                ",
      " KTTTTTTKMK     ",
      " M        gCgg  ",
      " W        g  g  ",
      " 6        C  g  ",
      "          C  g  ",
      " X        B  C  ",
      " M        B 0B  ",
      " K        C5iC  ",
      " T    lm   1!g  ",
      " T         12g  ",
      " T          2g  ",
      " T          2g  ",
      " T        gggC  ",
      "  TTTT TKMM     ",
      "                "
    ],
    [
      "                ",
      " K&&&$ $KKK     ",
      " K        gggC  ",
      " W        C  g  ",
      " X        g  g  ",
      " W        C  g  ",
      " W        C  g  ",
      " K        g  C  ",
      " M   l l  g87g  ",
      " %    ^m  9gig  ",
      " %      l Cghg  ",
      " &        Cghg  ",
      " &        gghC  ",
      " %        gggg  ",
      " * $&&%%KK#     ",
      "                "
    ],
    [
      "                ",
      " MMKKKKKMKM     ",
      " Kjjjjjjjjgggg  ",
      " Mjjjjjjjjg -g  ",
      " Kjjjjjjdjg -g  ",
      " KjjjeedleC  (  ",
      " MjjlelejlB  g  ",
      " Mjlefedejg  g  ",
      " [jdleeljjB  )  ",
      " Mjjdef^djB8Eg  ",
      " Kjjjjlmljgghg  ",
      " KjjjjjjjdgghC  ",
      " Mjjjjjjjjgghg  ",
      " Kjjjjjjjjggg+  ",
      " MMKKKKMKMM     ",
      "                "
    ]
  ]
}