{
  "name": "building_apartmentsmallbbroken_top_90",
  "refpalette": "deceasedcraft:building_apartmentsmallbbroken/building_apartmentsmallbbroken_top_palette_90",
  "xsize": 16,
  "zsize": 16,
  "slices": [
    [
      "                ",
      "      tttttttt  ",
      "  bbbbouuuuuuuy ",
      "  bgggouuuuuuuy ",
      "  bggggwuuuuuuy ",
      "  eijgsuququuuy ",
      "  d kgqurlmxuuy ",
      "  d  flmmmlrmx  ",
      "  d kmmmmrmlopy ",
      "  e klrlmmmuuuy ",
      "  dhjfqqlwlmxuy ",
      "  cgfgpgguquuuy ",
      "  bfggogguuuuuy ",
      "  abbbogguuuuuy ",
      "      nnnnnnnn  ",
      "                "
    ],
    [
      "                ",
      "     oosoooosos ",
      "  aCbboTV15$$$o ",
      "  c   oS  4###o ",
      "  c M O  0 3*{: ",
      "  b L p  l 9&]s ",
      "  x J qlNZ  ^[; ",
      "  b K  R     -p ",
      "  c J    N  lp| ",
      "  bEJ N   3l%+s ",
      "  bDI qw Z 8 )} ",
      "  B F sQUY   Zs ",
      "  c   s  X 77(o ",
      "  ACbboP W2662s ",
      "     osoosoosso ",
      "                "
    ],
    [
      "                ",
      "     soo\u0376oo\u037c\u037f\u037fo ",
      "  c,bbo   \u0377\u037b*\u0384s ",
      "  <   s       \u0385 ",
      "  < /         \u0385 ",
      "  B ` s  3      ",
      "  c ` ;         ",
      "  > \u0370        \u0375\u0387 ",
      "  <?\u0371      l\u037ep; ",
      "  B.\u0370         \u0386 ",
      "  B ` \u0372\u0375        ",
      "  < / s         ",
      "  c   o\u0374 X    \u0385 ",
      "  ',bbo\u0373 W    s ",
      "     oos oo\u037a\u037d\u037as ",
      "                "
    ],
    [
      "                ",
      "     sos\u0393os\u037c\u037c\u037fs ",
      "  \u0389,bbo      \u0395o ",
      "  \u0388   o       \u0385 ",
      "  m / j         ",
      "  < / \u038f\u0391      \u0385 ",
      "  x \u038c           ",
      "  m\u037d          o ",
      "  m       l\u0394sss ",
      "  < \u038a    Y    \u0385 ",
      "  x / \u038e         ",
      "  < / o  X    \u0385 ",
      "  <   s\u0374 W    \u0385 ",
      "  b,bbo\u0390 W    o ",
      "     oss\u0392oo\u037a\u037a\u037do ",
      "                "
    ],
    [
      "                ",
      "     poo\u037cso\u0385 \u0385o ",
      "  BCbbo      Po ",
      "  c   o       \u039a ",
      "  x / s       \u039b ",
      "  < \u0398 s\u0391 P!   \u039c ",
      "  mE\u0397 \u0399         ",
      "              o ",
      "        lxpsoso ",
      "  m      X    \u039b ",
      "  m \u038c    X    \u039a ",
      "  < / s  W    \u039a ",
      "  \u0396   o  W    \u039a ",
      "  bCbboPPW    s ",
      "     soo\u037dos\u0385\u0385 s ",
      "                "
    ],
    [
      "                ",
      "     \u03a6sospssoss ",
      "  bbbbo\u03a8\u03a8\u03a8\u03a8\u03a8\u03a8\u03a8s ",
      " \u039d<\u03a0  s\u03a8\u03a8\u03a8\u03a8\u03a8\u03a8\u03a8o ",
      "  m\u03a0\u03a4 s\u03a8\u03a8\u03a8\u03a8\u03a8\u03a8\u03a8o ",
      "  mE\u03a3 o\u03a8\u03a8\u03a8\u03a8\u03a8\u03a8\u03a8s ",
      "   \u039f\u03a1 s\u03a8\u03a8\u03a8\u03a8\u03a8\u03a8\u03a8s ",
      "      \u0399\u03a8\u03a8\u03a8\u03a8\u03a8\u03a8\u03a8o ",
      "       ooooooos ",
      "      \u0399\u03a7\u03a7\u03a8\u03a8\u03a8\u03a8\u03a8o ",
      "  m   \u0387\u03a7\u03a7\u03a8\u03a8\u03a8\u03a8\u03a8s ",
      "  x\u039e\u0398 s\u03a7\u03a7\u03a8\u03a8\u03a8\u03a8\u03a8o ",
      " A<\u039e  s\u03a7\u03a7\u03a8\u03a8\u03a8\u03a8\u03a8o ",
      "  bbbbo\u03a7\u03a7\u03a8\u03a8\u03a8\u03a8\u03a8s ",
      "     \u03a5ssooosooo ",
      "                "
    ],
    [
      "                ",
      "      tttttttt  ",
      " \u03a9bBbbouuuuuuuy ",
      " \u039dqm<fpuuuuuuuy ",
      "  mq<\u03aaguuuuuuuy ",
      "   ikgouuuuuuuy ",
      "     fouuuuuuuy ",
      "     \u037douuuuuuuy ",
      "      psusussoy ",
      "     kogguuuuuy ",
      "   x \u03aaogguuuuuy ",
      " \u039dmmfgogguuuuuy ",
      " \u03a9q\u03aaggogguuuuuy ",
      " \u03a9bbbbogguuuuuy ",
      "      nnnnnnnn  ",
      "                "
    ],
    [
      "                ",
      "     ossososoos ",
      " AB\u03adCboTV15$$$o ",
      " A    p * *###s ",
      " \u039d  \u03afOO  0* ]{o ",
      "    \u03ae \u03b1\u0391O\u03b4  \u03b7\u03bao ",
      "      o\u03b3 \u03b4\u03b5]  o ",
      "      s \u03b3\u03b4 \u03b7--o ",
      "      op s poos ",
      "      s  Y \u03b6\u03b8\u03b9o ",
      "   D\u03ae s~     )o ",
      "    F o\u03b2~Y   (s ",
      " \u039d \u03ac  o~ X 77Po ",
      " \u03a9\u03abCb\u03b0s  W2662s ",
      "     oosooooooo ",
      "                "
    ],
    [
      "                ",
      "     \u03a5os oo\u037f\u037f\u037fo ",
      " \u03a9\u03bc ,bo* \u03c1\u0377\u03c3\u0384\u0384s ",
      " \u03a9    s      \u03c7\u0385 ",
      " A  /        \u03c6\u0385 ",
      " \u039d  \u03be s      \u03c6\u0385 ",
      "      o      \u03c5\u0385 ",
      " \u039d  \u03bd o\u03bf     \u03c8o ",
      "      oo o sooo ",
      "      o\u03bf X \u03c2\u03c4\u03c7\u0385 ",
      "    ` o      \u03c6\u0385 ",
      " \u039d  / s  X   \u03c6\u0385 ",
      " \u03a9    o\u0374 W   \u03c5\u0385 ",
      " \u03a9\u03bb\u03a9b o\u0373 W  P!s ",
      "     soo\u03c0so\u037a\u037a\u037ao ",
      "                "
    ],
    [
      "                ",
      "     \u03cfso\u0393oo\u037c\u037f\u037fo ",
      " \u03ab\u03cd  bs     \u037b\u0384o ",
      " \u03c9    o      \u03d3\u0385 ",
      " \u03cb  \u03ce        \u03d2\u0385 ",
      " \u03c9  / o      \u03d2\u0385 ",
      " \u03cc    o      \u03d1\u0385 ",
      " \u039d  \u03be o       o ",
      "    \u03bd oo\u03d0o\u03d0oooo ",
      " \u03cb  \u03be o  X   \u03d3\u0385 ",
      " \u03ca  / s  X   \u03d2\u0385 ",
      " \u03c9  / o  W   \u03d2\u0385 ",
      " \u03c9    o\u0374 W   \u03d1\u0385 ",
      " \u03a9\u03b0\u03abb o\u0390 W   Po ",
      "     oso\u0392os\u037d\u037a\u037as ",
      "                "
    ],
    [
      "                ",
      "     \u03cfso\u037fos \u0385\u0385o ",
      " bC\u03d5 co       o ",
      " b    o       \u039a ",
      " b  / o       \u039a ",
      " c  \u0398 o\u0391  \u03d6   \u039a ",
      " BE \u0371 s       \u039b ",
      " B\u037d \u038c o       o ",
      " B  \u0371 osooooooo ",
      " c  \u0398 o  W    \u039a ",
      " b  \u0398 o  W    \u039a ",
      " b  / o  W    \u039a ",
      " b    s  W    \u039a ",
      " \u03d4Cbb o  W    o ",
      "     sso\u037aoo\u0385\u0385\u0385s ",
      "                "
    ],
    [
      "                ",
      "      \u03e0ssoooooo ",
      " Ab\u03db\u03dfao\u03a8\u03a8\u03a8\u03a8\u03a8\u03a8\u03a8o ",
      " c    o\u03a8\u03a8\u03a8\u03a8\u03a8\u03a8\u03a8o ",
      " b  \u03a4 o\u03a8\u03a8\u03a8\u03a8\u03a8\u03a8\u03a8o ",
      " b\u03da \u03a3 o\u03a8\u03a8\u03a8\u03a8\u03a8\u03a8\u03a8s ",
      " \u03d8\u03d9 \u03de o\u03a8\u03a8\u03a8\u03a8\u03a8\u03a8\u03a8o ",
      " c  \u03de o\u03a8\u03a8\u03a8\u03a8\u03a8\u03a8\u03a8o ",
      " \u03d4  \u03de sooooooos ",
      " b  \u03de o\u03a7\u03a7\u03a8\u03a8\u03a8\u03a8\u03a8s ",
      " b  \u03dd o\u03a7\u03a7\u03a8\u03a8\u03a8\u03a8\u03a8o ",
      " b\u039e \u03dc o\u03a7\u03a7\u03a8\u03a8\u03a8\u03a8\u03a8o ",
      " B    o\u03a7\u03a7\u03a8\u03a8\u03a8\u03a8\u03a8o ",
      " \u03d7cb\u03bb\u03dfs\u03a7\u03a7\u03a8\u03a8\u03a8\u03a8\u03a8o ",
      "     pssosooooo ",
      "                "
    ],
    [
      "                ",
      "      tttttttt  ",
      " bc  \u03a9ouuuuuuuy ",
      " bg\u03e2jgouuuuuuuy ",
      " bg fgguuuuuuuy ",
      " di kgouuuuuuuy ",
      " e  jgouuuuuuuy ",
      " e  jgouuuuuuuy ",
      " d  kgoououoooy ",
      " d  jgogguuuuuy ",
      " d\u03da jgogguuuuuy ",
      " bf ggogguuuuuy ",
      " b\u03e1 \u03e3gogguuuuuy ",
      " cbb\u03b0 ogguuuuuy ",
      "      nnnnnnnn  ",
      "                "
    ],
    [
      "                ",
      "     \u0394sosoooooo ",
      " b\u03e7\u03e8\u03e9\u03aboTV15$$$o ",
      "\u03a9\u03bb    s\u03ee ] ###o ",
      "\u03a9\u03e4  \u03af \u03eb  0   {o ",
      "\u03a9\u03bc  L\u03eao\u0391 \u03b4 ]  o ",
      "\u03a9\u03e4  J o\u03b3 \u03b4  \u03f3 o ",
      " \u03bb  J o\u03b3 \u03b4  --o ",
      "A\u039e\u03e6 J so\u03efo\u03f1oooo ",
      "\u03a9gg K o\u03ed W \u03b6\u03b8\u03b9o ",
      "\u03a9\u03e4\u03ac I s\u03ec \u03f0 \u03f2  o ",
      "A\u03bc  F oQ W    o ",
      "A\u03bb\u03e5   o\u0374 W 77 o ",
      " bCb\u03b0 s  W2662o ",
      "     sooooooooo ",
      "                "
    ],
    [
      "                ",
      "     soo\u0376so\u037c\u037f\u037co ",
      "\u03a9\u03e4  \u03dfbo   \u0377\u0384\u0384\u0384o ",
      "A\u03b0    o\u03f9     \u0402\u0385 ",
      "\u03a9\u03b0  / \u03f6      \u0401\u0385 ",
      "\u03a9\u03b0  `\u03f5o\u0391     \u0401\u0385 ",
      "A\u03b0  ` o\u03f8     \u0400\u0385 ",
      "\u03a9\u03da  \u03be o\u03f7      o ",
      "\u03a9\u03d9  ` oo\u03fao\u03fdoooo ",
      "\u03a9\u03b0\u03f4 ` o\u03bf W \u03fe\u03ff\u0402  ",
      "\u03a9\u03b0  ` o  \u03fb   \u0401\u0385 ",
      "\u039d\u03b0  / o  W   \u0401\u0385 ",
      "A\u03b0    s\u0374 W   \u0400\u0385 ",
      "A\u03bb,b  s\u0373 W\u03fc  (o ",
      "     oso\u03c0os\u037a\u037d\u037ao ",
      "                "
    ],
    [
      "                ",
      "     oso\u0393oo\u037f\u037f\u037co ",
      "\u03a9\u03cd  ,bo    \u0384\u0384\u0384o ",
      "A\u03b0    s      \u0408\u0385 ",
      "\u03a9\u03b0  / j      \u0407\u0385 ",
      "\u03a9\u03b0  / o\u0391     \u0407\u0385 ",
      "\u03a9\u03da  / o\u0405     \u0406\u0385 ",
      "\u03a9\u03d9  / o\u0404      o ",
      "\u03a9   / oo\u03d0o\u03d0oooo ",
      "\u03a9\u03b0  / o\u0404 W   \u0408\u0385 ",
      "\u03a9\u03b0  / o\u0403 W   \u0407\u0385 ",
      "\u03a9\u03b0  / o  W   \u0407\u0385 ",
      "\u03a9     s\u0374 W   \u0406\u0385 ",
      "\u039d\u03b0\u03a9\u03bb  s\u0390 W    o ",
      "     sso\u0392oo\u037a\u037a\u037ao ",
      "                "
    ],
    [
      "                ",
      "     soo\u037foo\u0385\u0385\u0385o ",
      "\u03abC\u03df  bo       o ",
      "\u03ab\u03b0    o       \u039a ",
      "\u03a9\u03b0  / s       \u039a ",
      "\u03a9\u03da  \u0398 o\u0391  \u03d6   \u039a ",
      "\u03abi  \u0398 o       \u039a ",
      "\u03ab   \u0398 o       o ",
      "\u03ab\u03b0  \u0398 ooooooooo ",
      "\u03ab\u03b0  \u0398 s  W    \u039a ",
      "\u03ab   \u0398 o  W    \u039b ",
      "\u03ab\u03b0  / s  W    \u039a ",
      "\u03ab\u03b0    p  W    \u039a ",
      "\u03a9Cbb  o  W    o ",
      "     pss\u037aoo\u0385\u0385\u0385o ",
      "                "
    ],
    [
      "                ",
      "     sssooooooo ",
      "\u0409b\u040b \u03dfbo\u03a8\u03a8\u03a8\u03a8\u03a8\u03a8\u03a8o ",
      "bfg   s\u03a8\u03a8\u03a8\u03a8\u03a8\u03a8\u03a8o ",
      "bg\u040a \u03a4 o\u03a8\u03a8\u03a8\u03a8\u03a8\u03a8\u03a8o ",
      "d\u03d9  \u03a3 o\u03a8\u03a8\u03a8\u03a8\u03a8\u03a8\u03a8o ",
      "d   \u040d o\u03a8\u03a8\u03a8\u03a8\u03a8\u03a8\u03a8s ",
      "d   \u03de o\u03a8\u03a8\u03a8\u03a8\u03a8\u03a8\u03a8s ",
      "e   \u03de ooooooooo ",
      "d   \u03de o\u03a7\u03a7\u03a8\u03a8\u03a8\u03a8\u03a8o ",
      "d   \u03dd s\u03a7\u03a7\u03a8\u03a8\u03a8\u03a8\u03a8o ",
      "bgg\u03bb\u040c s\u03a7\u03a7\u03a8\u03a8\u03a8\u03a8\u03a8o ",
      "bgg\u03bb  o\u03a7\u03a7\u03a8\u03a8\u03a8\u03a8\u03a8o ",
      "bbb\u03bb\u03df s\u03a7\u03a7\u03a8\u03a8\u03a8\u03a8\u03a8o ",
      "     ssoooooooo ",
      "                "
    ],
    [
      "                ",
      "      tttttttt  ",
      "bc\u03df\u0413 b\u03a8\u03a8\u03a8\u03a8\u03a8\u03a8\u03a8\u03a8y ",
      "b\u0410  gg\u03a8\u03a8\u03a8\u03a8\u03a8\u03a8\u03a8\u03a8  ",
      "b   gg\u03a8\u03a8\u03a8\u03a8\u03a8\u03a8\u03a8\u03a8y ",
      "b   gg\u03a8\u03a8\u03a8\u03a8\u03a8\u03a8\u03a8\u03a8y ",
      "\u03ab   \u0415g\u03a8\u03a8\u03a8\u03a8\u03a8\u03a8\u03a8\u03a8y ",
      "b   \u0415g\u03a8\u03a8\u03a8\u03a8\u03a8\u03a8\u03a8\u03a8  ",
      "b    g\u03a8\u03a8\u03a8\u03a8\u03a8\u03a8\u03a8\u03a8  ",
      "b    g\u03a8\u03a8\u03a8\u03a8\u03a8\u03a8\u03a8\u03a8y ",
      "b  \u03b0 g\u0414\u0414\u0414\u0414\u0417\u0416\u03a8\u03a8y ",
      "b\u040f \u03b0  \u03a8\u03a8\u03a8\u03a8\u0416\u0416\u03a8\u03a8y ",
      "b\u040e\u0411\u0412\u0414 \u03a8\u03a8\u03a8\u03a8\u03a8\u03a8\u03a8\u03a8y ",
      "abb\u03b0  \u03a8\u03a8\u03a8\u03a8\u03a8\u03a8\u03a8\u03a8y ",
      "      nnnnnnnn  ",
      "                "
    ],
    [
      "                ",
      "                ",
      "bb\u03e8\u0418\u03e9b\u041f\u041f\u041f\u041f\u041f\u041f\u041f\u041f  ",
      "b    b \u0423     \u0410  ",
      "b   \u041b\u041c  \u0410   \u0425\u041f  ",
      "b   \u041ab   \u0423 \u0410 \u041f  ",
      "b    b\u041e\u0422  \u0429  \u041f  ",
      "b   \u0419b\u041e\u0421 \u0425 \u0421 \u041f  ",
      "b    b\u041d \u0410   \u042b   ",
      "b    b \u0420  \u0428\u0428 \u0425  ",
      "b  \u03b0 a\u0414\u041d \u0424\u0427\u0416\u042a\u041f\u041f ",
      "a\u040f \u03b0     \u0424\u0416\u0416\u042a\u041f  ",
      "b  \u03b0      \u0426\u0426 \u041f  ",
      "bbb    \u041f \u041f\u041f\u041f\u041f\u041f  ",
      "                ",
      "                "
    ],
    [
      "                ",
      "                ",
      "\u041ab  \u03dfb\u0420      \u0420  ",
      "a\u0419   b          ",
      "a\u0419   \u042d          ",
      "\u041a\u0419   b          ",
      "a\u0419\u0419  b\u041d         ",
      "a\u0419   b\u041d         ",
      "a\u0419\u042c  b          ",
      "a\u0419\u0419  b          ",
      "\u041a\u0419\u0419   \u0414       \u0420 ",
      " \u0419\u0419\u03b0  \u0414    \u042e    ",
      "\u03a9\u0419\u0419\u03b0            ",
      "abb\u03b0            ",
      "                ",
      "                "
    ],
    [
      "                ",
      "                ",
      "    \u03abb          ",
      "    \u0419b          ",
      "    \u0419b          ",
      "    \u042fb          ",
      "     b          ",
      "     \u041a          ",
      "     a          ",
      "                ",
      "                ",
      "                ",
      "                ",
      "  \u041a             ",
      "                ",
      "                "
    ]
  ]
}