{
  "name": "building_apartmentsmallbbroken_top_180",
  "refpalette": "deceasedcraft:building_apartmentsmallbbroken/building_apartmentsmallbbroken_top_palette_180",
  "xsize": 16,
  "zsize": 16,
  "slices": [
    [
      "                ",
      "  yyyyy yyyyyy  ",
      " tuuuuuxpuuuuun ",
      " tuuuuumouxuuun ",
      " tuuuuxrlumuuun ",
      " tuuuqmlmmlquun ",
      " tuuuulmrmwuuun ",
      " tuuuqrmmmlgggn ",
      " tuuwuummlqgggn ",
      " toogsqlmrqpoon ",
      "  bggggfmlfggb  ",
      "  bggjk kkjfgb  ",
      "  bggi    hgfb  ",
      "  bbbedddedcba  ",
      "                ",
      "                "
    ],
    [
      "                ",
      " soo:s;p|s}soso ",
      " o$#{][-p+)Z(2s ",
      " s$#*&^ l%  76s ",
      " o$#39   l8 76o ",
      " o54     3   2o ",
      " o1 0lZ N ZYXWs ",
      " oV   N    U  o ",
      " sTS  lR  wQ Po ",
      " oooOpq  Nqssos ",
      " ob          bo ",
      "  b MLJKJJIF b  ",
      "  C      ED  C  ",
      "  accbxbcbbBcA  ",
      "                ",
      "                "
    ],
    [
      "                ",
      " os\u0385\u0385  \u0387;\u0386  \u0385ss ",
      " \u037f\u0384    \u0375p     \u037a ",
      " \u037f*     \u037e     \u037d ",
      " \u037c\u037b     l     \u037a ",
      " o\u0377           o ",
      " o   3      XWo ",
      " \u0376              ",
      " o        \u0375 \u0374\u0373s ",
      " oos s;   \u0372sooo ",
      " sb          bo ",
      "  b /``\u0370\u0371\u0370`/ b  ",
      "  ,     ?.   ,  ",
      "  c<<Bc><BB<c'  ",
      "                ",
      "                "
    ],
    [
      "                ",
      " so\u0385 \u0385 os\u0385 \u0385\u0385oo ",
      " \u037f\u0395     s     \u037d ",
      " \u037c      s     \u037a ",
      " \u037c      \u0394     \u037a ",
      " s      l     o ",
      " o       Y XWWo ",
      " \u0393            \u0392 ",
      " s   \u0391      \u0374\u0390s ",
      " oooj\u038f    \u038eosos ",
      " sb          bo ",
      "  b //\u038c  \u038a// b  ",
      "  ,    \u037d     ,  ",
      "  \u0389\u0388m<xmm<x<<b  ",
      "                ",
      "                "
    ],
    [
      "                ",
      " oo\u039a\u039b\u039c oo\u039b\u039a\u039a\u039ass ",
      " \u0385P     s       ",
      "        o     \u0385 ",
      " \u0385      s     \u0385 ",
      " o   !  p     s ",
      " s   P  xXXWWWo ",
      " \u037c      l    P\u037d ",
      " o   \u0391       Po ",
      " oooss\u0399    sooo ",
      " pb          bs ",
      "  b /\u0398\u0397   \u038c/ b  ",
      "  C   E      C  ",
      "  Bcx<m  mm<\u0396b  ",
      "                ",
      "                "
    ],
    [
      "                ",
      " ssoossososooso ",
      " s\u03a8\u03a8\u03a8\u03a8\u03a8\u03a8o\u03a8\u03a8\u03a8\u03a8\u03a8o ",
      " o\u03a8\u03a8\u03a8\u03a8\u03a8\u03a8o\u03a8\u03a8\u03a8\u03a8\u03a8o ",
      " s\u03a8\u03a8\u03a8\u03a8\u03a8\u03a8o\u03a8\u03a8\u03a8\u03a8\u03a8s ",
      " s\u03a8\u03a8\u03a8\u03a8\u03a8\u03a8o\u03a8\u03a8\u03a8\u03a8\u03a8o ",
      " p\u03a8\u03a8\u03a8\u03a8\u03a8\u03a8o\u03a8\u03a8\u03a8\u03a8\u03a8o ",
      " s\u03a8\u03a8\u03a8\u03a8\u03a8\u03a8o\u03a7\u03a7\u03a7\u03a7\u03a7o ",
      " o\u03a8\u03a8\u03a8\u03a8\u03a8\u03a8o\u03a7\u03a7\u03a7\u03a7\u03a7s ",
      " sossos\u0399 \u0399\u0387ssos ",
      " \u03a6b          b\u03a5 ",
      "  b \u03a4\u03a3\u03a1    \u0398 b  ",
      "  b\u03a0\u03a0E\u039f    \u039e\u039eb  ",
      "  b<mm    mx<b  ",
      "   \u039d        A   ",
      "                "
    ],
    [
      "                ",
      "  yyyyyyyyyyyy  ",
      " tuuuuuuouuuuun ",
      " tuuuuuusuuuuun ",
      " tuuuuuusuuuuun ",
      " tuuuuuuuuuuuun ",
      " tuuuuuusuuuuun ",
      " tuuuuuuugggggn ",
      " tuuuuuusgggggn ",
      " topgooopooooon ",
      "  bf\u03aagf\u037d k\u03aaggb  ",
      "  b<<k     fgb  ",
      "  Bmqi    xm\u03aab  ",
      "  bqm      mqb  ",
      "  \u03a9\u039d       \u039d\u03a9\u03a9  ",
      "                "
    ],
    [
      "                ",
      " sosoooosoososo ",
      " o$#{\u03ba -o\u03b9)(P2o ",
      " o$#]\u03b7 -o\u03b8  76o ",
      " s$#  ]\u03b7p\u03b6  76o ",
      " o5** \u03b5      2o ",
      " s1 0\u03b4\u03b4\u03b4sY YXWo ",
      " oV* O \u03b3   ~  o ",
      " sT  \u0391\u03b3 p ~\u03b2~ s ",
      " sopO\u03b1osossooso ",
      " ob O        \u03b0o ",
      "  C \u03af\u03ae    \u03aeF b  ",
      "  \u03ad       D \u03acC  ",
      "  B          \u03ab  ",
      "  AA\u039d       \u039d\u03a9  ",
      "                "
    ],
    [
      "                ",
      " os\u0385\u0385\u0385\u0385oo\u0385\u0385\u0385\u0385so ",
      " \u037f\u0384\u03c7\u03c6\u03c6\u03c5\u03c8o\u03c7\u03c6\u03c6\u03c5!\u037a ",
      " \u037f\u0384     o\u03c4   P\u037a ",
      " \u037f\u03c3     s\u03c2    \u037a ",
      " o\u0377           o ",
      " o\u03c1     oX XWWs ",
      "              \u03c0 ",
      " s*    \u03bfo\u03bf  \u0374\u0373o ",
      " oos sooooosooo ",
      " \u03a5b           s ",
      "  , /\u03be \u03bd  `/ b  ",
      "             \u03a9  ",
      "  \u03bc          \u03bb  ",
      "  \u03a9\u03a9A\u039d \u039d   \u039d\u03a9\u03a9  ",
      "                "
    ],
    [
      "                ",
      " oo\u0385\u0385\u0385\u0385oo\u0385\u0385\u0385\u0385os ",
      " \u037f\u0384\u03d3\u03d2\u03d2\u03d1 o\u03d3\u03d2\u03d2\u03d1P\u037a ",
      " \u037f\u037b     o     \u037a ",
      " \u037c      o     \u037d ",
      " o      \u03d0     s ",
      " o      oXXWWWo ",
      " \u0393      \u03d0     \u0392 ",
      " o      o   \u0374\u0390o ",
      " sso ooooosooos ",
      " \u03cfb           o ",
      "    \u03ce/ \u03be\u03bd\u03be// b  ",
      "             \u03ab  ",
      "  \u03cd          \u03b0  ",
      "  \u03ab\u03c9\u03cb\u03c9\u03cc\u039d \u03cb\u03ca\u03c9\u03c9\u03a9  ",
      "                "
    ],
    [
      "                ",
      " oo\u039a\u039a\u039a\u039boo\u039a\u039a\u039a\u039aos ",
      " \u0385      o     \u0385 ",
      " \u0385      o     \u0385 ",
      "        o     \u0385 ",
      " s   \u03d6  o     o ",
      " o      oWWWWWo ",
      " \u037f      o     \u037a ",
      " o   \u0391  s     o ",
      " soooosooooosos ",
      " \u03cfc           s ",
      "    /\u0398\u0371\u038c\u0371\u0398\u0398/ b  ",
      "  \u03d5          b  ",
      "  C   E\u037d     C  ",
      "  bbbcBBBcbbb\u03d4  ",
      "                "
    ],
    [
      "                ",
      " oooosoossooooo ",
      " o\u03a8\u03a8\u03a8\u03a8\u03a8\u03a8o\u03a8\u03a8\u03a8\u03a8\u03a8o ",
      " o\u03a8\u03a8\u03a8\u03a8\u03a8\u03a8o\u03a8\u03a8\u03a8\u03a8\u03a8o ",
      " o\u03a8\u03a8\u03a8\u03a8\u03a8\u03a8o\u03a8\u03a8\u03a8\u03a8\u03a8o ",
      " o\u03a8\u03a8\u03a8\u03a8\u03a8\u03a8o\u03a8\u03a8\u03a8\u03a8\u03a8o ",
      " o\u03a8\u03a8\u03a8\u03a8\u03a8\u03a8o\u03a8\u03a8\u03a8\u03a8\u03a8s ",
      " s\u03a8\u03a8\u03a8\u03a8\u03a8\u03a8o\u03a7\u03a7\u03a7\u03a7\u03a7o ",
      " s\u03a8\u03a8\u03a8\u03a8\u03a8\u03a8o\u03a7\u03a7\u03a7\u03a7\u03a7s ",
      " \u03e0oooooosooooss ",
      "  a          \u03dfp ",
      "  \u03df \u03a4\u03a3\u03de\u03de\u03de\u03de\u03dd\u03dc \u03bb  ",
      "  \u03db          b  ",
      "  b  \u03da\u03d9    \u039e c  ",
      "  Acbb\u03d8c\u03d4bbbB\u03d7  ",
      "                "
    ],
    [
      "                ",
      "  yyyyyyyyyyyy  ",
      " tuuuuuuouuuuun ",
      " tuuuuuuouuuuun ",
      " tuuuuuuouuuuun ",
      " tuuuuuuuuuuuun ",
      " tuuuuuuouuuuun ",
      " tuuuuuuugggggn ",
      " tuuuuuuogggggn ",
      " toogooooooooon ",
      "  \u03a9gggggggggg   ",
      "   jfkjjkjjg\u03e3\u03b0  ",
      "   \u03e2         b  ",
      "  cggi    \u03daf\u03e1b  ",
      "  bbbdeedddbbc  ",
      "                "
    ],
    [
      "                ",
      " oooooooooooooo ",
      " o$#{  -o\u03b9   2o ",
      " o$#  \u03f3-o\u03b8  76o ",
      " o$# ]  o\u03b6\u03f2 76o ",
      " o5     \u03f1    2o ",
      " o1]0\u03b4\u03b4\u03b4oW\u03f0WWWo ",
      " sV     \u03ef     o ",
      " oT\u03ee \u0391\u03b3\u03b3o\u03ed\u03ecQ\u0374 o ",
      " sos\u03ebooososooso ",
      " \u0394\u03ab  \u03ea        s ",
      "  \u03e9 \u03afLJJJKIF \u03b0  ",
      "  \u03e8          b  ",
      "  \u03e7     \u03e6g\u03ac \u03e5C  ",
      "  b\u03bb\u03e4\u03bc\u03e4\u03bb\u039eg\u03e4\u03bc\u03bbb  ",
      "   \u03a9\u03a9\u03a9\u03a9 A\u03a9\u03a9AA   "
    ],
    [
      "                ",
      " oo\u0385\u0385\u0385\u0385oo \u0385\u0385\u0385oo ",
      " \u037c\u0384\u0402\u0401\u0401\u0400 o\u0402\u0401\u0401\u0400(\u037a ",
      " \u037f\u0384     o\u03ff    \u037d ",
      " \u037c\u0384     o\u03fe    \u037a ",
      " o\u0377     \u03fd    \u03fcs ",
      " s      oW\u03fbWWWo ",
      " \u0376      \u03fa     \u03c0 ",
      " o \u03f9 \u0391\u03f8\u03f7o\u03bf  \u0374\u0373o ",
      " ooo\u03f6ooooooosss ",
      " sb  \u03f5        o ",
      "  \u03df /``\u03be```/    ",
      "             b  ",
      "         \u03f4   ,  ",
      "  \u03e4\u03b0\u03b0\u03b0\u03b0\u03da\u03d9\u03b0\u03b0\u03b0\u03b0\u03bb  ",
      "  \u03a9A\u03a9\u03a9A\u03a9\u03a9\u03a9\u03a9\u039dAA  "
    ],
    [
      "                ",
      " oo\u0385\u0385\u0385\u0385oo\u0385\u0385\u0385\u0385oo ",
      " \u037c\u0384\u0408\u0407\u0407\u0406 o\u0408\u0407\u0407\u0406 \u037a ",
      " \u037f\u0384     o     \u037a ",
      " \u037f\u0384     o     \u037a ",
      " o      \u03d0     o ",
      " o      oWWWWWo ",
      " \u0393      \u03d0     \u0392 ",
      " o   \u0391\u0405\u0404o\u0404\u0403 \u0374\u0390o ",
      " sosjooooooosss ",
      " ob           s ",
      "  , ////////    ",
      "             \u03bb  ",
      "             \u03a9  ",
      "  \u03cd\u03b0\u03b0\u03b0\u03da\u03d9 \u03b0\u03b0\u03b0 \u03b0  ",
      "  \u03a9A\u03a9\u03a9\u03a9\u03a9\u03a9\u03a9\u03a9\u03a9\u03a9\u039d  "
    ],
    [
      "                ",
      " oo\u039a\u039a\u039a\u039aoo\u039a\u039b\u039a\u039aoo ",
      " \u0385      o     \u0385 ",
      " \u0385      o     \u0385 ",
      " \u0385      o     \u0385 ",
      " o   \u03d6  o     o ",
      " o      oWWWWWo ",
      " \u037f      o     \u037a ",
      " o   \u0391  o     s ",
      " ooosoooosospos ",
      " sb           p ",
      "    /\u0398\u0398\u0398\u0398\u0398\u0398/    ",
      "             b  ",
      "  \u03df          b  ",
      "  C\u03b0\u03b0\u03dai \u03b0\u03b0 \u03b0\u03b0C  ",
      "  \u03ab\u03ab\u03a9\u03a9\u03ab\u03ab\u03ab\u03ab\u03ab\u03ab\u03ab\u03a9  "
    ],
    [
      "                ",
      " ooooossooooooo ",
      " o\u03a8\u03a8\u03a8\u03a8\u03a8\u03a8o\u03a8\u03a8\u03a8\u03a8\u03a8o ",
      " o\u03a8\u03a8\u03a8\u03a8\u03a8\u03a8o\u03a8\u03a8\u03a8\u03a8\u03a8o ",
      " o\u03a8\u03a8\u03a8\u03a8\u03a8\u03a8o\u03a8\u03a8\u03a8\u03a8\u03a8o ",
      " o\u03a8\u03a8\u03a8\u03a8\u03a8\u03a8o\u03a8\u03a8\u03a8\u03a8\u03a8o ",
      " o\u03a8\u03a8\u03a8\u03a8\u03a8\u03a8o\u03a8\u03a8\u03a8\u03a8\u03a8o ",
      " o\u03a8\u03a8\u03a8\u03a8\u03a8\u03a8o\u03a7\u03a7\u03a7\u03a7\u03a7o ",
      " s\u03a8\u03a8\u03a8\u03a8\u03a8\u03a8o\u03a7\u03a7\u03a7\u03a7\u03a7o ",
      " sosoooooossoss ",
      " sb           s ",
      "  \u03df \u03a4\u03a3\u040d\u03de\u03de\u03de\u03dd\u040c \u03df  ",
      "           \u03bb\u03bb\u03bb  ",
      "  \u040bg\u040a      ggb  ",
      "  bfg\u03d9     ggb  ",
      "  \u0409bbdddeddbbb  "
    ],
    [
      "                ",
      "  y yyy  yyyyy  ",
      " t\u03a8\u03a8\u03a8\u03a8\u03a8\u03a8\u03a8\u03a8\u03a8\u03a8\u03a8\u03a8n ",
      " t\u03a8\u03a8\u03a8\u03a8\u03a8\u03a8\u03a8\u03a8\u03a8\u03a8\u03a8\u03a8n ",
      " t\u03a8\u03a8\u03a8\u03a8\u03a8\u03a8\u03a8\u03a8\u0416\u0416\u03a8\u03a8n ",
      " t\u03a8\u03a8\u03a8\u03a8\u03a8\u03a8\u03a8\u03a8\u0417\u0416\u03a8\u03a8n ",
      " t\u03a8\u03a8\u03a8\u03a8\u03a8\u03a8\u03a8\u03a8\u0414\u03a8\u03a8\u03a8n ",
      " t\u03a8\u03a8\u03a8\u03a8\u03a8\u03a8\u03a8\u03a8\u0414\u03a8\u03a8\u03a8n ",
      " t\u03a8\u03a8\u03a8\u03a8\u03a8\u03a8\u03a8\u03a8\u0414\u03a8\u03a8\u03a8n ",
      " t\u03a8\u03a8\u03a8\u03a8\u03a8\u03a8\u03a8\u03a8\u0414\u03a8\u03a8\u03a8n ",
      "  bgggggggg     ",
      "   ggg\u0415\u0415    \u0414   ",
      "  \u0413       \u03b0\u03b0\u0412\u03b0  ",
      "  \u03df         \u0411b  ",
      "  c\u0410       \u040f\u040eb  ",
      "  bbbb\u03abbbbbbba  "
    ],
    [
      "                ",
      "          \u041f     ",
      "  \u041f\u0410\u041f\u041f\u041f\u041f \u0425\u041f\u041f\u041f\u041f  ",
      "  \u041f \u0425   \u042b \u042a\u042a \u041f  ",
      "  \u041f  \u0410 \u0421 \u0428\u0416\u0416\u0426\u041f  ",
      "  \u041f   \u0429  \u0428\u0427\u0416\u0426\u041f  ",
      "  \u041f  \u0423 \u0425  \u0424\u0424 \u041f  ",
      "  \u041f \u0410   \u0410       ",
      "  \u041f\u0423  \u0422\u0421 \u0420\u041d  \u041f  ",
      "  \u041f   \u041e\u041e\u041d \u0414     ",
      "  bb\u041cbbbbba     ",
      "  \u03e9 \u041b\u041a \u0419        ",
      "  \u0418       \u03b0\u03b0\u03b0   ",
      "  \u03e8          b  ",
      "  b        \u040f b  ",
      "  bbbbbbbbbabb  "
    ],
    [
      "                ",
      "          \u0420     ",
      "  \u0420             ",
      "                ",
      "           \u042e    ",
      "                ",
      "                ",
      "                ",
      "                ",
      "  \u0420   \u041d\u041d  \u0414\u0414    ",
      "  bb\u042dbbbbb      ",
      "  \u03df             ",
      "           \u03b0\u03b0\u03b0  ",
      "      \u0419 \u042c\u0419\u0419\u0419\u0419b  ",
      "  b\u0419\u0419\u0419\u0419\u0419\u0419\u0419\u0419\u0419\u0419b  ",
      "  \u041aaa\u041aaaaa\u041a \u03a9a  "
    ],
    [
      "                ",
      "                ",
      "                ",
      "                ",
      "                ",
      "                ",
      "                ",
      "                ",
      "                ",
      "                ",
      "  bbbbb\u041aa       ",
      "  \u03ab\u0419\u0419\u042f          ",
      "                ",
      "             \u041a  ",
      "                ",
      "                "
    ]
  ]
}