{
  "name": "building_apartmentsmallbbroken_top",
  "refpalette": "deceasedcraft:building_apartmentsmallbbroken/building_apartmentsmallbbroken_top_palette",
  "xsize": 16,
  "zsize": 16,
  "slices": [
    [
      "                ",
      "                ",
      "  abcdedddebbb  ",
      "  bfgh    iggb  ",
      "  bgfjkk kjggb  ",
      "  bggflmfggggb  ",
      " noopqrmlqsgoot ",
      " ngggqlmmuuwuut ",
      " nggglmmmrquuut ",
      " nuuuwmrmluuuut ",
      " nuuqlmmlmquuut ",
      " nuuumulrxuuuut ",
      " nuuuxuomuuuuut ",
      " nuuuuupxuuuuut ",
      "  yyyyyy yyyyy  ",
      "                "
    ],
    [
      "                ",
      "                ",
      "  AcBbbcbxbcca  ",
      "  C  DE      C  ",
      "  b FIJJKJLM b  ",
      " ob          bo ",
      " sossqN  qpOooo ",
      " oP Qw  Rl  STs ",
      " o  U    N   Vo ",
      " sWXYZ N Zl0 1o ",
      " o2   3     45o ",
      " o67 8l   93#$o ",
      " s67  %l ^&*#$s ",
      " s2(Z)+p-[]{#$o ",
      " osos}s|p;s:oos ",
      "                "
    ],
    [
      "                ",
      "                ",
      "  'c<BB<>cB<<c  ",
      "  ,   .?     ,  ",
      "  b /`\u0370\u0371\u0370``/ b  ",
      " ob          bs ",
      " ooos\u0372   ;s soo ",
      " s\u0373\u0374 \u0375        o ",
      "              \u0376 ",
      " oWX      3   o ",
      " o           \u0377o ",
      " \u037a     l     \u037b\u037c ",
      " \u037d     \u037e     *\u037f ",
      " \u037a     p\u0375    \u0384\u037f ",
      " ss\u0385  \u0386;\u0387  \u0385\u0385so ",
      "                "
    ],
    [
      "                ",
      "                ",
      "  b<<x<mmx<m\u0388\u0389  ",
      "  ,     \u037d    ,  ",
      "  b //\u038a  \u038c// b  ",
      " ob          bs ",
      " soso\u038e    \u038fjooo ",
      " s\u0390\u0374      \u0391   s ",
      " \u0392            \u0393 ",
      " oWWX Y       o ",
      " o     l      s ",
      " \u037a     \u0394      \u037c ",
      " \u037a     s      \u037c ",
      " \u037d     s     \u0395\u037f ",
      " oo\u0385\u0385 \u0385so \u0385 \u0385os ",
      "                "
    ],
    [
      "                ",
      "                ",
      "  b\u0396<mm  m<xcB  ",
      "  C      E   C  ",
      "  b /\u038c   \u0397\u0398/ b  ",
      " sb          bp ",
      " ooos    \u0399ssooo ",
      " oP       \u0391   o ",
      " \u037dP    l      \u037c ",
      " oWWWXXx  P   s ",
      " s     p  !   o ",
      " \u0385     s      \u0385 ",
      " \u0385     o        ",
      "       s     P\u0385 ",
      " ss\u039a\u039a\u039a\u039boo \u039c\u039b\u039aoo ",
      "                "
    ],
    [
      "                ",
      "   A        \u039d   ",
      "  b<xm    mm<b  ",
      "  b\u039e\u039e    \u039fE\u03a0\u03a0b  ",
      "  b \u0398    \u03a1\u03a3\u03a4 b  ",
      " \u03a5b          b\u03a6 ",
      " soss\u0387\u0399 \u0399sossos ",
      " s\u03a7\u03a7\u03a7\u03a7\u03a7o\u03a8\u03a8\u03a8\u03a8\u03a8\u03a8o ",
      " o\u03a7\u03a7\u03a7\u03a7\u03a7o\u03a8\u03a8\u03a8\u03a8\u03a8\u03a8s ",
      " o\u03a8\u03a8\u03a8\u03a8\u03a8o\u03a8\u03a8\u03a8\u03a8\u03a8\u03a8p ",
      " o\u03a8\u03a8\u03a8\u03a8\u03a8o\u03a8\u03a8\u03a8\u03a8\u03a8\u03a8s ",
      " s\u03a8\u03a8\u03a8\u03a8\u03a8o\u03a8\u03a8\u03a8\u03a8\u03a8\u03a8s ",
      " o\u03a8\u03a8\u03a8\u03a8\u03a8o\u03a8\u03a8\u03a8\u03a8\u03a8\u03a8o ",
      " o\u03a8\u03a8\u03a8\u03a8\u03a8o\u03a8\u03a8\u03a8\u03a8\u03a8\u03a8s ",
      " osoososossooss ",
      "                "
    ],
    [
      "                ",
      "  \u03a9\u03a9\u039d       \u039d\u03a9  ",
      "  bqm      mqb  ",
      "  b\u03aamx    iqmB  ",
      "  bgf     k<<b  ",
      "  bgg\u03aak \u037dfg\u03aafb  ",
      " nooooopooogpot ",
      " ngggggsuuuuuut ",
      " nggggguuuuuuut ",
      " nuuuuusuuuuuut ",
      " nuuuuuuuuuuuut ",
      " nuuuuusuuuuuut ",
      " nuuuuusuuuuuut ",
      " nuuuuuouuuuuut ",
      "  yyyyyyyyyyyy  ",
      "                "
    ],
    [
      "                ",
      "  \u03a9\u039d       \u039dAA  ",
      "  \u03ab          B  ",
      "  C\u03ac D       \u03ad  ",
      "  b F\u03ae    \u03ae\u03af C  ",
      " o\u03b0        O bo ",
      " osoossoso\u03b1Opos ",
      " s ~\u03b2~ p \u03b3\u0391  Ts ",
      " o  ~   \u03b3 O *Vo ",
      " oWXY Ys\u03b4\u03b4\u03b40 1s ",
      " o2      \u03b5 **5o ",
      " o67  \u03b6p\u03b7]  #$s ",
      " o67  \u03b8o- \u03b7]#$o ",
      " o2P()\u03b9o- \u03ba{#$o ",
      " ososoosoooosos ",
      "                "
    ],
    [
      "                ",
      "  \u03a9\u03a9\u039d   \u039d \u039dA\u03a9\u03a9  ",
      "  \u03bb          \u03bc  ",
      "  \u03a9             ",
      "  b /`  \u03bd \u03be/ ,  ",
      " s           b\u03a5 ",
      " ooosooooos soo ",
      " o\u0373\u0374  \u03bfo\u03bf    *s ",
      " \u03c0              ",
      " sWWX Xo     \u03c1o ",
      " o           \u0377o ",
      " \u037a    \u03c2s     \u03c3\u037f ",
      " \u037aP   \u03c4o     \u0384\u037f ",
      " \u037a!\u03c5\u03c6\u03c6\u03c7o\u03c8\u03c5\u03c6\u03c6\u03c7\u0384\u037f ",
      " os\u0385\u0385\u0385\u0385oo\u0385\u0385\u0385\u0385so ",
      "                "
    ],
    [
      "                ",
      "  \u03a9\u03c9\u03c9\u03ca\u03cb \u039d\u03cc\u03c9\u03cb\u03c9\u03ab  ",
      "  \u03b0          \u03cd  ",
      "  \u03ab             ",
      "  b //\u03be\u03bd\u03be /\u03ce    ",
      " o           b\u03cf ",
      " sooosooooo oss ",
      " o\u0390\u0374   o      o ",
      " \u0392     \u03d0      \u0393 ",
      " oWWWXXo      o ",
      " s     \u03d0      o ",
      " \u037d     o      \u037c ",
      " \u037a     o     \u037b\u037f ",
      " \u037aP\u03d1\u03d2\u03d2\u03d3o \u03d1\u03d2\u03d2\u03d3\u0384\u037f ",
      " so\u0385\u0385\u0385\u0385oo\u0385\u0385\u0385\u0385oo ",
      "                "
    ],
    [
      "                ",
      "  \u03d4bbbcBBBcbbb  ",
      "  C     \u037dE   C  ",
      "  b          \u03d5  ",
      "  b /\u0398\u0398\u0371\u038c\u0371\u0398/    ",
      " s           c\u03cf ",
      " sosooooosoooos ",
      " o     s  \u0391   o ",
      " \u037a     o      \u037f ",
      " oWWWWWo      o ",
      " o     o  \u03d6   s ",
      " \u0385     o        ",
      " \u0385     o      \u0385 ",
      " \u0385     o      \u0385 ",
      " so\u039a\u039a\u039a\u039aoo\u039b\u039a\u039a\u039aoo ",
      "                "
    ],
    [
      "                ",
      "  \u03d7Bbbb\u03d4c\u03d8bbcA  ",
      "  c \u039e    \u03d9\u03da  b  ",
      "  b          \u03db  ",
      "  \u03bb \u03dc\u03dd\u03de\u03de\u03de\u03de\u03a3\u03a4 \u03df  ",
      " p\u03df          a  ",
      " ssoooosoooooo\u03e0 ",
      " s\u03a7\u03a7\u03a7\u03a7\u03a7o\u03a8\u03a8\u03a8\u03a8\u03a8\u03a8s ",
      " o\u03a7\u03a7\u03a7\u03a7\u03a7o\u03a8\u03a8\u03a8\u03a8\u03a8\u03a8s ",
      " s\u03a8\u03a8\u03a8\u03a8\u03a8o\u03a8\u03a8\u03a8\u03a8\u03a8\u03a8o ",
      " o\u03a8\u03a8\u03a8\u03a8\u03a8o\u03a8\u03a8\u03a8\u03a8\u03a8\u03a8o ",
      " o\u03a8\u03a8\u03a8\u03a8\u03a8o\u03a8\u03a8\u03a8\u03a8\u03a8\u03a8o ",
      " o\u03a8\u03a8\u03a8\u03a8\u03a8o\u03a8\u03a8\u03a8\u03a8\u03a8\u03a8o ",
      " o\u03a8\u03a8\u03a8\u03a8\u03a8o\u03a8\u03a8\u03a8\u03a8\u03a8\u03a8o ",
      " ooooossoosoooo ",
      "                "
    ],
    [
      "                ",
      "  cbbdddeedbbb  ",
      "  b\u03e1f\u03da    iggc  ",
      "  b         \u03e2   ",
      "  \u03b0\u03e3gjjkjjkfj   ",
      "   gggggggggg\u03a9  ",
      " nooooooooogoot ",
      " ngggggouuuuuut ",
      " nggggguuuuuuut ",
      " nuuuuuouuuuuut ",
      " nuuuuuuuuuuuut ",
      " nuuuuuouuuuuut ",
      " nuuuuuouuuuuut ",
      " nuuuuuouuuuuut ",
      "  yyyyyyyyyyyy  ",
      "                "
    ],
    [
      "   AA\u03a9\u03a9A \u03a9\u03a9\u03a9\u03a9   ",
      "  b\u03bb\u03bc\u03e4g\u039e\u03bb\u03e4\u03bc\u03e4\u03bbb  ",
      "  C\u03e5 \u03acg\u03e6     \u03e7  ",
      "  b          \u03e8  ",
      "  \u03b0 FIKJJJL\u03af \u03e9  ",
      " s        \u03ea  \u03ab\u0394 ",
      " osoososooo\u03ebsos ",
      " o \u0374Q\u03ec\u03edo\u03b3\u03b3\u0391 \u03eeTo ",
      " o     \u03ef     Vs ",
      " oWWW\u03f0Wo\u03b4\u03b4\u03b40]1o ",
      " o2    \u03f1     5o ",
      " o67 \u03f2\u03b6o  ] #$o ",
      " o67  \u03b8o-\u03f3  #$o ",
      " o2   \u03b9o-  {#$o ",
      " oooooooooooooo ",
      "                "
    ],
    [
      "  AA\u039d\u03a9\u03a9\u03a9\u03a9A\u03a9\u03a9A\u03a9  ",
      "  \u03bb\u03b0\u03b0\u03b0\u03b0\u03d9\u03da\u03b0\u03b0\u03b0\u03b0\u03e4  ",
      "  ,   \u03f4         ",
      "  b             ",
      "    /```\u03be``/ \u03df  ",
      " o        \u03f5  bs ",
      " sssooooooo\u03f6ooo ",
      " o\u0373\u0374  \u03bfo\u03f7\u03f8\u0391 \u03f9 o ",
      " \u03c0     \u03fa      \u0376 ",
      " oWWW\u03fbWo      s ",
      " s\u03fc    \u03fd     \u0377o ",
      " \u037a    \u03feo     \u0384\u037c ",
      " \u037d    \u03ffo     \u0384\u037f ",
      " \u037a(\u0400\u0401\u0401\u0402o \u0400\u0401\u0401\u0402\u0384\u037c ",
      " oo\u0385\u0385\u0385 oo\u0385\u0385\u0385\u0385oo ",
      "                "
    ],
    [
      "  \u039d\u03a9\u03a9\u03a9\u03a9\u03a9\u03a9\u03a9\u03a9\u03a9A\u03a9  ",
      "  \u03b0 \u03b0\u03b0\u03b0 \u03d9\u03da\u03b0\u03b0\u03b0\u03cd  ",
      "  \u03a9             ",
      "  \u03bb             ",
      "    //////// ,  ",
      " s           bo ",
      " sssooooooojsos ",
      " o\u0390\u0374 \u0403\u0404o\u0404\u0405\u0391   o ",
      " \u0392     \u03d0      \u0393 ",
      " oWWWWWo      o ",
      " o     \u03d0      o ",
      " \u037a     o     \u0384\u037f ",
      " \u037a     o     \u0384\u037f ",
      " \u037a \u0406\u0407\u0407\u0408o \u0406\u0407\u0407\u0408\u0384\u037c ",
      " oo\u0385\u0385\u0385\u0385oo\u0385\u0385\u0385\u0385oo ",
      "                "
    ],
    [
      "  \u03a9\u03ab\u03ab\u03ab\u03ab\u03ab\u03ab\u03ab\u03a9\u03a9\u03ab\u03ab  ",
      "  C\u03b0\u03b0 \u03b0\u03b0 i\u03da\u03b0\u03b0C  ",
      "  b          \u03df  ",
      "  b             ",
      "    /\u0398\u0398\u0398\u0398\u0398\u0398/    ",
      " p           bs ",
      " sopsosoooosooo ",
      " s     o  \u0391   o ",
      " \u037a     o      \u037f ",
      " oWWWWWo      o ",
      " o     o  \u03d6   o ",
      " \u0385     o      \u0385 ",
      " \u0385     o      \u0385 ",
      " \u0385     o      \u0385 ",
      " oo\u039a\u039a\u039b\u039aoo\u039a\u039a\u039a\u039aoo ",
      "                "
    ],
    [
      "  bbbddedddbb\u0409  ",
      "  bgg     \u03d9gfb  ",
      "  bgg      \u040ag\u040b  ",
      "  \u03bb\u03bb\u03bb           ",
      "  \u03df \u040c\u03dd\u03de\u03de\u03de\u040d\u03a3\u03a4 \u03df  ",
      " s           bs ",
      " ssossoooooosos ",
      " o\u03a7\u03a7\u03a7\u03a7\u03a7o\u03a8\u03a8\u03a8\u03a8\u03a8\u03a8s ",
      " o\u03a7\u03a7\u03a7\u03a7\u03a7o\u03a8\u03a8\u03a8\u03a8\u03a8\u03a8o ",
      " o\u03a8\u03a8\u03a8\u03a8\u03a8o\u03a8\u03a8\u03a8\u03a8\u03a8\u03a8o ",
      " o\u03a8\u03a8\u03a8\u03a8\u03a8o\u03a8\u03a8\u03a8\u03a8\u03a8\u03a8o ",
      " o\u03a8\u03a8\u03a8\u03a8\u03a8o\u03a8\u03a8\u03a8\u03a8\u03a8\u03a8o ",
      " o\u03a8\u03a8\u03a8\u03a8\u03a8o\u03a8\u03a8\u03a8\u03a8\u03a8\u03a8o ",
      " o\u03a8\u03a8\u03a8\u03a8\u03a8o\u03a8\u03a8\u03a8\u03a8\u03a8\u03a8o ",
      " ooooooossooooo ",
      "                "
    ],
    [
      "  abbbbbb\u03abbbbb  ",
      "  b\u040e\u040f       \u0410c  ",
      "  b\u0411         \u03df  ",
      "  \u03b0\u0412\u03b0\u03b0       \u0413  ",
      "   \u0414    \u0415\u0415ggg   ",
      "     ggggggggb  ",
      " n\u03a8\u03a8\u03a8\u0414\u03a8\u03a8\u03a8\u03a8\u03a8\u03a8\u03a8\u03a8t ",
      " n\u03a8\u03a8\u03a8\u0414\u03a8\u03a8\u03a8\u03a8\u03a8\u03a8\u03a8\u03a8t ",
      " n\u03a8\u03a8\u03a8\u0414\u03a8\u03a8\u03a8\u03a8\u03a8\u03a8\u03a8\u03a8t ",
      " n\u03a8\u03a8\u03a8\u0414\u03a8\u03a8\u03a8\u03a8\u03a8\u03a8\u03a8\u03a8t ",
      " n\u03a8\u03a8\u0416\u0417\u03a8\u03a8\u03a8\u03a8\u03a8\u03a8\u03a8\u03a8t ",
      " n\u03a8\u03a8\u0416\u0416\u03a8\u03a8\u03a8\u03a8\u03a8\u03a8\u03a8\u03a8t ",
      " n\u03a8\u03a8\u03a8\u03a8\u03a8\u03a8\u03a8\u03a8\u03a8\u03a8\u03a8\u03a8t ",
      " n\u03a8\u03a8\u03a8\u03a8\u03a8\u03a8\u03a8\u03a8\u03a8\u03a8\u03a8\u03a8t ",
      "  yyyyy  yyy y  ",
      "                "
    ],
    [
      "  bbabbbbbbbbb  ",
      "  b \u040f        b  ",
      "  b          \u03e8  ",
      "   \u03b0\u03b0\u03b0       \u0418  ",
      "        \u0419 \u041a\u041b \u03e9  ",
      "     abbbbb\u041cbb  ",
      "     \u0414 \u041d\u041e\u041e   \u041f  ",
      "  \u041f  \u041d\u0420 \u0421\u0422  \u0423\u041f  ",
      "       \u0410   \u0410 \u041f  ",
      "  \u041f \u0424\u0424  \u0425 \u0423  \u041f  ",
      "  \u041f\u0426\u0416\u0427\u0428  \u0429   \u041f  ",
      "  \u041f\u0426\u0416\u0416\u0428 \u0421 \u0410  \u041f  ",
      "  \u041f \u042a\u042a \u042b   \u0425 \u041f  ",
      "  \u041f\u041f\u041f\u041f\u0425 \u041f\u041f\u041f\u041f\u0410\u041f  ",
      "     \u041f          ",
      "                "
    ],
    [
      "  a\u03a9 \u041aaaaa\u041aaa\u041a  ",
      "  b\u0419\u0419\u0419\u0419\u0419\u0419\u0419\u0419\u0419\u0419b  ",
      "  b\u0419\u0419\u0419\u0419\u042c \u0419      ",
      "  \u03b0\u03b0\u03b0           ",
      "             \u03df  ",
      "      bbbbb\u042dbb  ",
      "    \u0414\u0414  \u041d\u041d   \u0420  ",
      "                ",
      "                ",
      "                ",
      "                ",
      "    \u042e           ",
      "                ",
      "             \u0420  ",
      "     \u0420          ",
      "                "
    ],
    [
      "                ",
      "                ",
      "  \u041a             ",
      "                ",
      "          \u042f\u0419\u0419\u03ab  ",
      "       a\u041abbbbb  ",
      "                ",
      "                ",
      "                ",
      "                ",
      "                ",
      "                ",
      "                ",
      "                ",
      "                ",
      "                "
    ]
  ]
}