{
  "name": "multi_verticalschool_5_floor6",
  "refpalette": "deceasedcraft:multi_verticalschool_5/multi_verticalschool_5_floor6_palette",
  "xsize": 16,
  "zsize": 16,
  "slices": [
    [
      "                ",
      "                ",
      "                ",
      "                ",
      "                ",
      "aaaaaaaaaaaaaaaa",
      "bcccccccccccccca",
      "d             ca",
      "              ca",
      "              ca",
      "              ca",
      "              ca",
      "              ca",
      "              ca",
      "              ca",
      "              ca"
    ],
    [
      "                ",
      "                ",
      "                ",
      "                ",
      "                ",
      "aaaaaaaaaaaaaaaa",
      "bcccccccccccccca",
      "efffffffffffffca",
      "efffffffffffffca",
      "efffffffffffffca",
      "efffffffffffffca",
      "efffffffffffffca",
      "efffffffffffffca",
      "efffffffffffffca",
      "efffffffffffffca",
      "efffffffffffffca"
    ],
    [
      "                ",
      "                ",
      "                ",
      "                ",
      "                ",
      "aaaaaaaaaaaaaaaa",
      "aaaaaaaaaaaaaaaa",
      "aaaaaaaaaaaaaaaa",
      "aaaaaaaaaaaaaaaa",
      "aaaaaaaaaaaaaaaa",
      "aaaaaaaaaaaaaaaa",
      "aaaaaaaaaaaaaaaa",
      "aaaaaaaaaaaaaaaa",
      "aaaaaaaaaaaaaaaa",
      "aaaaaaaaaaaaaaaa",
      "aaaaaaaaaaaaaaaa"
    ],
    [
      "                ",
      "                ",
      "                ",
      "                ",
      "                ",
      "gggggggggggggggg",
      "               g",
      "               g",
      "               g",
      "               g",
      "               g",
      "               g",
      "               g",
      "               g",
      "               g",
      "               g"
    ],
    [
      "                ",
      "                ",
      "                ",
      "                ",
      "                ",
      "                ",
      "                ",
      "                ",
      "                ",
      "                ",
      "                ",
      "                ",
      "                ",
      "                ",
      "                ",
      "                "
    ],
    [
      "                ",
      "                ",
      "                ",
      "                ",
      "                ",
      "                ",
      "                ",
      "                ",
      "                ",
      "                ",
      "                ",
      "                ",
      "                ",
      "                ",
      "                ",
      "                "
    ]
  ]
}