{
  "name": "multi_verticalschool_5_base1",
  "refpalette": "deceasedcraft:multi_verticalschool_5/multi_verticalschool_5_base1_palette",
  "xsize": 16,
  "zsize": 16,
  "slices": [
    [
      "vvvvvvvvvvvvvvvv",
      "                ",
      "                ",
      "                ",
      "                ",
      "aaaaaaaaaaaaa   ",
      "bbbbbbbbbbbbbaa ",
      "             bba",
      "             cba",
      "               b",
      "               b",
      "               b",
      "               b",
      "               b",
      "               b",
      "               b"
    ],
    [
      "vvvvvvvvvvvvvvvv",
      "                ",
      "                ",
      "                ",
      "                ",
      "aaaaaaaaaaaaa   ",
      "bbbbbbbbbbbbbaa ",
      "             bba",
      "             dba",
      "               b",
      "               b",
      "               b",
      "               b",
      " e             b",
      "fe             b",
      "fe             b"
    ],
    [
      "vvvvvvvvvvvvvvvv",
      "                ",
      "                ",
      "                ",
      "                ",
      "aaaaaaaaaaaaa   ",
      "bbbbbbbbbbbbbaa ",
      "             bba",
      "              ba",
      "               b",
      "               b",
      "               b",
      " gg            b",
      "hife           b",
      "jife           b",
      " ife           b"
    ],
    [
      "vvvvvvvvvvvvvvvv",
      "                ",
      "                ",
      "                ",
      "                ",
      "aaaaaaaaaaaaa   ",
      "bbbbbbbbbbbbbaa ",
      "             bba",
      "              ba",
      "               b",
      "               b",
      "               b",
      "  gg           b",
      "   ik          b",
      "   iff         b",
      "   iff         b"
    ],
    [
      "vvvvvvvvvvvvvvvv",
      "                ",
      "                ",
      "                ",
      "                ",
      "aaaaaaaaaaaaa   ",
      "bbbbbbbbbbbbbaa ",
      "lllllllllllllbba",
      "            llba",
      "             llb",
      "              lb",
      "              lb",
      "              lb",
      "    gg        lb",
      "     h        lb",
      "     hg       lb"
    ],
    [
      "vvvvvvvvvvvvvvvv",
      "ffffffffffffffff",
      "ffffffffffffffff",
      "ffffffffffffffff",
      "ffffffffffffffff",
      "aaaaaaaaaaaaafff",
      "mmmmmmmmmmmmmaaf",
      "nnnnnnnnnnnnnmma",
      "oooooooooooonnma",
      "           oonnm",
      "            oonm",
      "             onm",
      "             onm",
      "             onm",
      "             onm",
      "             onm"
    ]
  ]
}