{
  "name": "multi_verticalschool_5_floor5",
  "refpalette": "deceasedcraft:multi_verticalschool_5/multi_verticalschool_5_floor5_palette",
  "xsize": 16,
  "zsize": 16,
  "slices": [
    [
      "                ",
      "                ",
      "                ",
      "                ",
      "                ",
      "aaaaaaaaaaaaaaaa",
      "aaaaaaaaaaaaaaaa",
      "bbbbbbbbbbbbbbaa",
      "bbbbbbbbbbbbbbaa",
      "bbbbbbbbbbbbbbaa",
      "bbbbbbbbbbbbbbaa",
      "bbbbbbbbbbbbbbaa",
      "bbbbbbbbbbbbbbaa",
      "bbbbbbbbbbbbbbaa",
      "bbbbbbbbbbbbbbaa",
      "bbbbbbbbbbbbbbaa"
    ],
    [
      "                ",
      "                ",
      "                ",
      "                ",
      "                ",
      "aaaaaaaaaaaaaaaa",
      "ccccccccccccccca",
      "             dca",
      "              ca",
      " e    e    e  ca",
      "              ca",
      "              ca",
      "              ca",
      "              ca",
      " e    e    e  ca",
      "              ca"
    ],
    [
      "                ",
      "                ",
      "                ",
      "                ",
      "                ",
      "aaaaaaaaaaaaaaaa",
      "ccccccccccccccca",
      "           d dca",
      "             dca",
      " e    e   de  ca",
      "              ca",
      "              ca",
      "              ca",
      " d       d    ca",
      " e    ed   e  ca",
      "              ca"
    ],
    [
      "                ",
      "                ",
      "                ",
      "                ",
      "                ",
      "aaaaaaaaaaaaaaaa",
      "bbbbbbbbbbbbbbba",
      "bbbbbbbbbbbbbbba",
      "bbbbbbbbbbbbbbba",
      "bbbbbbbbbbbbbbba",
      "bbbbbbbbbbbbbbba",
      "bbbbbbbbbbbbbbba",
      "bbbbbbbbbbbbbbba",
      "bbbbbbbbbbbbbbba",
      "bbbbbbbbbbbbbbba",
      "bbbbbbbbbbbbbbba"
    ],
    [
      "                ",
      "                ",
      "                ",
      "                ",
      "                ",
      "aaaaaaaaaaaaaaaa",
      "fcccccccccccccca",
      "g hij hij hij ca",
      "              ca",
      "              ca",
      "              ca",
      "              ca",
      "              ca",
      "              ca",
      "              ca",
      "              ca"
    ],
    [
      "                ",
      "                ",
      "                ",
      "                ",
      "                ",
      "aaaaaaaaaaaaaaaa",
      "fcccccccccccccca",
      "k             ca",
      "              ca",
      "              ca",
      "              ca",
      "              ca",
      "              ca",
      "              ca",
      "              ca",
      "              ca"
    ]
  ]
}