{
  "name": "multi_verticalschool_5_floor14",
  "refpalette": "deceasedcraft:multi_verticalschool_5/multi_verticalschool_5_floor14_palette",
  "xsize": 16,
  "zsize": 16,
  "slices": [
    [
      "                ",
      "                ",
      "                ",
      "                ",
      "                ",
      "aaaaaaaaaaaaaaaa",
      "bbbbbbbbbbbbbbbb",
      "                ",
      "                ",
      "                ",
      "                ",
      "                ",
      "                ",
      "                ",
      "                ",
      "                "
    ],
    [
      "                ",
      "                ",
      "                ",
      "                ",
      "                ",
      "aaaaaaaaaaaaaaaa",
      "bbbbbbbbbbbbbbbb",
      "                ",
      "                ",
      "                ",
      "                ",
      "                ",
      "                ",
      "                ",
      "                ",
      "                "
    ],
    [
      "                ",
      "                ",
      "                ",
      "                ",
      "                ",
      "aaaaaaaaaaaaaaaa",
      "bbbbbbbbbbbbbbbb",
      "                ",
      "                ",
      "                ",
      "                ",
      "                ",
      "                ",
      "                ",
      "                ",
      "                "
    ],
    [
      "                ",
      "                ",
      "                ",
      "                ",
      "                ",
      "aaaaaaaaaaaaaaaa",
      "bbbbbbbbbbbbbbbb",
      "                ",
      "                ",
      "                ",
      "                ",
      "                ",
      "                ",
      "                ",
      "                ",
      "                "
    ],
    [
      "                ",
      "                ",
      "                ",
      "                ",
      "                ",
      "aaaaaaaaaaaaaaaa",
      "bbbbbbbbbbbbbbbb",
      "cccccccccccccccc",
      "cccccccccccccccc",
      "cccccddddcccccdd",
      "cccccccccccccccc",
      "cccccccccccccccc",
      "cccccccccccccccc",
      "cccccccccccccccc",
      "cccccddddcccccee",
      "cccccccccccccccc"
    ],
    [
      "                ",
      "                ",
      "                ",
      "                ",
      "                ",
      "aaaaaaaaaaaaaaaa",
      "bbbbbbbbbbbbbbbb",
      "bbbbbbbbbbbbbbbb",
      "ffffffffffffffff",
      "gggggggggggggggg",
      "gggggggggggggggg",
      "gggggggggggggggg",
      "gggggggggggggggg",
      "gggggggggggggggg",
      "gggggggggggggggg",
      "gggggggggggggggg"
    ]
  ]
}