{
  "name": "multi_verticalschool_5_floor1",
  "refpalette": "deceasedcraft:multi_verticalschool_5/multi_verticalschool_5_floor1_palette",
  "xsize": 16,
  "zsize": 16,
  "slices": [
    [
      "                ",
      "                ",
      "                ",
      "                ",
      "                ",
      "                ",
      "                ",
      "aaaaaaaaaaaaaaaa",
      "bbbbbbbbbbbbbbbb",
      "  c    d efgbh  ",
      "         efgbh  ",
      "         eggbh  ",
      "       d  igbh  ",
      "          igbh  ",
      "          igbh  ",
      "          igbh  "
    ],
    [
      "                ",
      "                ",
      "                ",
      "                ",
      "                ",
      "                ",
      "                ",
      "aaaaaaaaaaaaaaaa",
      "bbbbbbbbbbbbbbbb",
      "  j    c  kgfgbh",
      "          lgfgbh",
      "           gfgbh",
      "       c   gggbh",
      "            igbh",
      "            igbh",
      "            igbh"
    ],
    [
      "                ",
      "                ",
      "                ",
      "                ",
      "                ",
      "                ",
      "                ",
      "aaaaaaaaaaaaaaaa",
      "bbbbbbbbbbbbbbbb",
      "       c     iig",
      "          m kiig",
      "            niig",
      "       c     iig",
      "              ig",
      "              ig",
      "              ig"
    ],
    [
      "                ",
      "                ",
      "                ",
      "                ",
      "                ",
      "                ",
      "                ",
      "oooooooooooooooo",
      "pppppppppppppppp",
      "       c        ",
      "          d     ",
      "            d   ",
      "       j        ",
      "                ",
      "                ",
      "                "
    ],
    [
      "                ",
      "                ",
      "                ",
      "                ",
      "                ",
      "                ",
      "                ",
      "                ",
      "                ",
      "       j  j     ",
      "         jjj    ",
      "          j c   ",
      "                ",
      "                ",
      "                ",
      "                "
    ],
    [
      "                ",
      "                ",
      "                ",
      "                ",
      "                ",
      "                ",
      "                ",
      "                ",
      "                ",
      "          j     ",
      "         jjj    ",
      "          j c   ",
      "                ",
      "                ",
      "                ",
      "                "
    ]
  ]
}