{
  "name": "multi_verticalschool_5_ground",
  "refpalette": "deceasedcraft:multi_verticalschool_5/multi_verticalschool_5_ground_palette",
  "xsize": 16,
  "zsize": 16,
  "slices": [
    [
      "HHHHHHHHHHHHHHHH",
      "HHHHHHHHHHHHHHHH",
      "HHHHHHHHHHHHHHHH",
      "HHHHHHHHHHHHHHHH",
      "aaaaaaaaaaaaaaaa",
      "bbbbbbbbbbbbbbbb",
      "bbbbbbbbbbbbbbbb",
      "bbbbbbbbbbbbbbbb",
      "ccddddddddcccccc",
      "ce        ffcccc",
      "ce          fccc",
      "ce          fccc",
      "ce           gcc",
      "ce           gcc",
      "ce           gcc",
      "ce           gcc"
    ],
    [
      "                ",
      "                ",
      "                ",
      "                ",
      "                ",
      "                ",
      "                ",
      "hhhhhhhhhhhhhhhh",
      "iiiiiiiiiiiiiiii",
      "iice      iiiiii",
      "iice        iiii",
      "iice        iiii",
      "iice         iii",
      "iice         iii",
      "iice         iii",
      "jice         iii"
    ],
    [
      "                ",
      "                ",
      "                ",
      "                ",
      "                ",
      "                ",
      "                ",
      "kkkkkkkkkkkkkkkk",
      "cccccccccccccccc",
      "ccccce    ccclll",
      "llllce      clll",
      "llllce      ccll",
      "llllce       cll",
      "llllce       cll",
      "llllce       cll",
      "llllce       cll"
    ],
    [
      "                ",
      "                ",
      "                ",
      "                ",
      "                ",
      "                ",
      "                ",
      "kkkkkkkkkkkkkkkk",
      "cccccccccccccccc",
      "mmmmmmce  nnno p",
      "llllllce    n   ",
      "qqqqqlce    nn  ",
      "    qlce     n  ",
      "    qlce     n  ",
      "    qlce     n  ",
      "    qlce     n  "
    ],
    [
      "                ",
      "                ",
      "                ",
      "                ",
      "                ",
      "                ",
      "                ",
      "kkkkkkkkkkkkkkkk",
      "cccccccccccccccc",
      " rsr  lmce   t  ",
      "      lmce      ",
      "      lmce      ",
      "      lmce      ",
      "      llce      ",
      "      qlce      ",
      "      qlce      "
    ],
    [
      "                ",
      "                ",
      "                ",
      "                ",
      "                ",
      "                ",
      "                ",
      "kkkkkkkkkkkkkkkk",
      "cccccccccccccccc",
      "  t    sqlce u  ",
      "        qlce    ",
      "       rqlce    ",
      "       sqlce    ",
      "        qlce    ",
      "        qlce    ",
      "        qlce    "
    ]
  ]
}