{
  "name": "multi_verticalschool_5_floor15",
  "refpalette": "deceasedcraft:multi_verticalschool_5/multi_verticalschool_5_floor15_palette",
  "xsize": 16,
  "zsize": 16,
  "slices": [
    [
      "                ",
      "                ",
      "                ",
      "                ",
      "                ",
      "                ",
      "                ",
      "                ",
      "aaabaabaaaaaaaaa",
      "   b    b    b  ",
      "   c    d    d  ",
      "                ",
      "                ",
      "                ",
      "                ",
      "                "
    ],
    [
      "                ",
      "                ",
      "                ",
      "                ",
      "                ",
      "                ",
      "                ",
      "                ",
      "         ~      ",
      "   a    a    a  ",
      "                ",
      "                ",
      "                ",
      "                ",
      "                ",
      "                "
    ],
    [
      "                ",
      "                ",
      "                ",
      "                ",
      "                ",
      "                ",
      "                ",
      "                ",
      "                ",
      "   e    e    e  ",
      "                ",
      "                ",
      "ffffffffffffffff",
      "                ",
      "gggggggggggggggg",
      "ghhhhhhhhhhhhhhh"
    ],
    [
      "                ",
      "                ",
      "                ",
      "                ",
      "                ",
      "                ",
      "                ",
      "                ",
      "   e    e       ",
      "   e   ee   ee  ",
      "   e    e       ",
      "                ",
      "iiiiiiiiiiiiiiii",
      "jjjjjjjjjjjjjjjj",
      "kkkkkkkkkkkkkkkk",
      "llllllklllklllll"
    ],
    [
      "                ",
      "                ",
      "                ",
      "                ",
      "                ",
      "                ",
      "                ",
      "                ",
      "   e    e    e  ",
      "  eee  ee   eee ",
      "   e    e    e  ",
      "                ",
      "mmmmmmmmmmmmmmmm",
      "jjjjjjjjjjjjjjjj",
      "nnnnnnnnnnnnnnnn",
      "                "
    ],
    [
      "                ",
      "                ",
      "                ",
      "                ",
      "                ",
      "                ",
      "                ",
      "                ",
      "   e    e    e  ",
      "   ee   ee   ee ",
      "        e       ",
      "                ",
      "                ",
      "oooooooooooooooo",
      "                ",
      "                "
    ]
  ]
}