{
  "name": "multi_verticalschool_5_floor4",
  "refpalette": "deceasedcraft:multi_verticalschool_5/multi_verticalschool_5_floor4_palette",
  "xsize": 16,
  "zsize": 16,
  "slices": [
    [
      "                ",
      "                ",
      "                ",
      "                ",
      "                ",
      "                ",
      "                ",
      "                ",
      "                ",
      "                ",
      "                ",
      "                ",
      "                ",
      "aaaaaaaaaaaaaaaa",
      "abbbbbbbbbbbbbbb",
      "bb              "
    ],
    [
      "                ",
      "                ",
      "                ",
      "                ",
      "                ",
      "                ",
      "                ",
      "                ",
      "                ",
      "                ",
      "                ",
      "                ",
      "                ",
      "                ",
      " c ccccccccc ccc",
      "cc              "
    ],
    [
      "                ",
      "                ",
      "                ",
      "                ",
      "                ",
      "                ",
      "                ",
      "                ",
      "                ",
      "                ",
      "                ",
      "                ",
      "                ",
      "                ",
      "                ",
      "                "
    ],
    [
      "                ",
      "                ",
      "                ",
      "                ",
      "                ",
      "                ",
      "                ",
      "                ",
      "                ",
      "                ",
      "                ",
      "                ",
      "                ",
      "                ",
      "                ",
      "                "
    ],
    [
      "                ",
      "                ",
      "                ",
      "                ",
      "                ",
      "                ",
      "                ",
      "                ",
      "                ",
      "                ",
      "                ",
      "                ",
      "                ",
      "                ",
      "                ",
      "                "
    ],
    [
      "                ",
      "                ",
      "                ",
      "                ",
      "                ",
      "dddddddddddddddd",
      "eeeeeeeeeeeeeeed",
      "eeeeeeeeeeeeeeed",
      "feeefeeefeeefeed",
      "feeefeeefeeefeed",
      "feeefeeefeeefeed",
      "feeefeeefeeefeed",
      "feeefeeefeeefeed",
      "feeefeeefeeefeed",
      "feeefeeefeeefeed",
      "feeefeeefeeefeed"
    ]
  ]
}