{
  "name": "multi_verticalschool_5_base2",
  "refpalette": "deceasedcraft:multi_verticalschool_5/multi_verticalschool_5_base2_palette",
  "xsize": 16,
  "zsize": 16,
  "slices": [
    [
      "vvvvvvvvvvvvvvvv",
      "vvvvvvvvvvvvvvvv",
      "vvvvvvvvvvvvvvvv",
      "vvvvvvvvvvvvvvvv",
      "vvvvvvvvvvvvvvvv",
      "vvvvvvvvvvvvvvvv",
      "vvvvvvvvvvvvvvvv",
      "vvvvvvvvvvvvvvvv",
      "vvvvvvvvvvvvvvvv",
      "vvvvvvvvvvvvvvvv",
      "vvvvvvvvvvvvvvvv",
      "vvvvvvvvvvvvvvvv",
      "vvvvvvvvvvvvvvvv",
      "vvvvvvvvvvvvvvvv",
      "vvvvvvvvvvvvvvvv",
      "vvvvvvvvvvvvvvvv"
    ],
    [
      "vvvvvvvvvvvvvvvv",
      "aaaaaaaaaaaaaaaa",
      "aaaaaaaaaaaaaaaa",
      "aaaaaaaaaaaaaaaa",
      "aaaaaaaaaaaaaaaa",
      "aaaaaaaaaaaaaaaa",
      "aaaaaaaaaaaaaaaa",
      "aaaaaaaaaaaaaaaa",
      "aaaaaaaaaaaaaaaa",
      "aaaaaaaaaaaaaaaa",
      "aaaaaaaaaaaaaaaa",
      "aaaaaaaaaaaaaaaa",
      "aaaaaaaaaaaaaaaa",
      "aaaaaaaaaaaaaaaa",
      "aaaaaaaaaaaaaaaa",
      "aaaaaaaaaaaaaaaa"
    ],
    [
      "vvvvvvvvvvvvvvvv",
      "aaaaaaaaaaaaaaaa",
      "aaaaaaaaaaaaaaaa",
      "aaaaaaaaaaaaaaaa",
      "aaaaaaaaaaaaaaaa",
      "aaaaaaaaaaaaaaaa",
      "aaaaaaaaaaaaaaaa",
      "aaaaaaaaaaaaaaaa",
      "aaaaaaaaaaaaaaaa",
      "aaaaaaaaaaaaaaaa",
      "aaaaaaaaaaaaaaaa",
      "aaaaaaaaaaaaaaaa",
      "aaaaaaaaaaaaaaaa",
      "aaaaaaaaaaaaaaaa",
      "aaaaaaaaaaaaaaaa",
      "aaaaaaaaaaaaaaaa"
    ],
    [
      "vvvvvvvvvvvvvvvv",
      "bbbbbbbbbbbbbbbb",
      "bbbbbbbbbbbbbbbb",
      "bbbbbbbbbbbbbbbb",
      "bbbbbbbbbbbbbbbb",
      "cccccccccccccbbb",
      "dddddddddddddccb",
      "eeeeeeeeeeeeeddc",
      "eeeeeeeeeeeeeedc",
      "eeeeeeeeeeeeeeed",
      "eeeeeeeeeeeeeeed",
      "eeeeeeeeeeeeeeed",
      "eeeeeeeeeeeeeeed",
      "eeeeeeeeeeeeeeed",
      "eeeeeeeeeeeeeeed",
      "eeeeeeeeeeeeeeed"
    ],
    [
      "vvvvvvvvvvvvvvvv",
      "                ",
      "                ",
      "                ",
      "          f     ",
      "ccccccccccccc   ",
      "gggggggggggggcc ",
      "hhhhhhhhhhhhhggc",
      "hhhhhhhhhhhhhigc",
      "hhhhhhhhhhhhhhhg",
      "hhhhhhhhhhhhhhhg",
      "hhhhhhhhhhhhhhhg",
      "hhhhhhhhhhhhhhhg",
      "hhhhhhhhhhhhhhhg",
      "hhhhhhhhhhhhhhhg",
      "hhhhhhhhhhhhhhhg"
    ],
    [
      "vvvvvvvvvvvvvvvv",
      "                ",
      "                ",
      "                ",
      "                ",
      "ccccccccccccc   ",
      "gggggggggggggcc ",
      "             ggc",
      "         j   kgc",
      "        j j    g",
      "l    m   j     g",
      " l m  m     n  g",
      "l    m     n n g",
      "            n  g",
      "               g",
      "               g"
    ]
  ]
}