{
  "name": "multi_alienresearch_14_base8",
  "refpalette": "deceasedcraft:multi_alienresearch_14/multi_alienresearch_14_base8_palette",
  "xsize": 16,
  "zsize": 16,
  "slices": [
    [
      "aaaaaaaaaaaaaaav",
      "bbbbcdddddddddcv",
      "baaacdddddddddcv",
      "baddcdddddddddcv",
      "baddcdddddddddcv",
      "baddcdddddddddcv",
      "baddcdddddddddcv",
      "baddcdddddddddcv",
      "baddcdddddddddcv",
      "baddcdddddddddcv",
      "baddcdddddddddcv",
      "aaddcdddddddddcv",
      "ddddcdddddddddcv",
      "ddddcdddddddddcv",
      "ddddcdddddddddcv",
      "ddddcdddddddddcv"
    ],
    [
      "aaaaaaaaaaaaaaav",
      "bbbbc  efffg  cv",
      "baaach efffg  cv",
      "ba ich efffg  cv",
      "ba jck  lll   cv",
      "ba mc         cv",
      "ba  n         cv",
      "ba  o         cv",
      "ba pc    q   qcv",
      "ba rcs  qt q tcv",
      "ba ucw    q  qcv",
      "aaxacy        cv",
      "aA  cB        cv",
      "aaaacC   q   qcv",
      "Di icC  qtq  tcv",
      " j jc    q   qcv"
    ],
    [
      "aaaaaaaaaaaaaaav",
      "bbbbc   E E   cv",
      "baaac    F    cv",
      "ba  c   E E   cv",
      "ba  c         cv",
      "ba  c         cv",
      "ba  I         cv",
      "ba  J         cv",
      "ba  c         cv",
      "ba  cK   !   Lcv",
      "ba  cM        cv",
      "aaNacO        cv",
      "a  Pc         cv",
      "aaaacQ        cv",
      "    cR       Scv",
      "    c         cv"
    ],
    [
      "aaaaaaaaaaaaaaav",
      "bbbbc   FFF   cv",
      "baaac   F F   cv",
      "ba  c   FFF   cv",
      "ba  c    T    cv",
      "ba  c         cv",
      "ba  c         cv",
      "ba  c         cv",
      "ba  c         cv",
      "ba  cU        cv",
      "ba  cV        cv",
      "aaaacU        cv",
      "aW XcV        cv",
      "aaaacU        cv",
      "    cV        cv",
      "    c         cv"
    ],
    [
      "aaaaaaaaaaaaaaav",
      "bbbbc   FFF   cv",
      "baaac   F F   cv",
      "ba  c   FFF   cv",
      "ba  c         cv",
      "ba  c         cv",
      "ba  c         cv",
      "ba  c         cv",
      "ba  c         cv",
      "ba  cR        cv",
      "ba  c         cv",
      "aaaac         cv",
      "a   cR        cv",
      "aaaacY        cv",
      "    c         cv",
      "    c         cv"
    ],
    [
      "aaaaaaaaaaaaaaav",
      "bbbbc   FFF   cv",
      "baaac   F F   cv",
      "ba  c   FFF   cv",
      "ba  c         cv",
      "ba  c         cv",
      "ba  c         cv",
      "ba  c         cv",
      "ba  c         cv",
      "ba  c         cv",
      "ba  c         cv",
      "aaaac         cv",
      "aZZZc         cv",
      "aaaac         cv",
      "    c         cv",
      "    c         cv"
    ]
  ]
}