{
  "name": "multi_alienresearch_14_base5",
  "refpalette": "deceasedcraft:multi_alienresearch_14/multi_alienresearch_14_base5_palette",
  "xsize": 16,
  "zsize": 16,
  "slices": [
    [
      "  a           bv",
      "  a           bv",
      "  a           bv",
      " a            bv",
      " a            bv",
      "a             bv",
      "a             bv",
      "              bv",
      "              bv",
      "              bv",
      "              bv",
      "              bv",
      "              bv",
      "              bv",
      "              bv",
      "              bv"
    ],
    [
      "  a           bv",
      "  a           bv",
      "  a           bv",
      " a            bv",
      " a            bv",
      "a             bv",
      "a             bv",
      "              bv",
      "              bv",
      "              bv",
      "              bv",
      "              bv",
      "              bv",
      "              bv",
      "              bv",
      "              bv"
    ],
    [
      "  a           bv",
      "  a           bv",
      "  a           bv",
      " a            bv",
      " a            bv",
      "a             bv",
      "a             bv",
      "              bv",
      "              bv",
      "              bv",
      "              bv",
      "              bv",
      "              bv",
      "              bv",
      "              bv",
      "              bv"
    ],
    [
      "  a           bv",
      "  a           bv",
      "  a           bv",
      " a            bv",
      " a            bv",
      "a             bv",
      "a             bv",
      "              bv",
      "              bv",
      "              bv",
      "              bv",
      "              bv",
      "              bv",
      "              bv",
      "              bv",
      "              bv"
    ],
    [
      "  a           bv",
      "  a           bv",
      "  a           bv",
      " a            bv",
      " a            bv",
      "a             bv",
      "a             bv",
      "              bv",
      "              bv",
      "              bv",
      "              bv",
      "              bv",
      "              bv",
      "              bv",
      "              bv",
      "              bv"
    ],
    [
      "  c           bv",
      "  c           bv",
      "  c           bv",
      " c            bv",
      " c d   ddddd  bv",
      "c             bv",
      "c             bv",
      "              bv",
      "              bv",
      " ddd   ddddd  bv",
      "              bv",
      "              bv",
      "              bv",
      "              bv",
      "dddd   ddddd  bv",
      "   d          bv"
    ]
  ]
}