{
  "name": "multi_alienresearch_14_base4",
  "refpalette": "deceasedcraft:multi_alienresearch_14/multi_alienresearch_14_base4_palette",
  "xsize": 16,
  "zsize": 16,
  "slices": [
    [
      " abcccccccccccdv",
      "abbcccccccccccdv",
      "aebcccccccccccdv",
      "abccccccccccccdv",
      "bbccccccccccccdv",
      "bcccccccccccccdv",
      "bcccccccccccccdv",
      "ccccccccccccccdv",
      "ccccccccccccccdv",
      "ccccccccccccccdv",
      "ccccccccccccccdv",
      "ccccccccccccccdv",
      "ccccccccccccccdv",
      "ccccccccccccccdv",
      "ccccccccccccccdv",
      "ccccccccccccccdv"
    ],
    [
      " bfffffffffffffv",
      " bfffffffffffffv",
      " bfffffffffffffv",
      "bffffffffffffffv",
      "bffffffffffffffv",
      "fffffffffffffffv",
      "fffffffffffffffv",
      "fffffffffffffffv",
      "fffffffffffffffv",
      "fffffffffffffffv",
      "fffffffffffffffv",
      "fffffffffffffffv",
      "fffffffffffffffv",
      "fffffffffffffffv",
      "fffffffffffffffv",
      "fffffffffffffffv"
    ],
    [
      " gfffffffffffffv",
      " gfffffffffffffv",
      "gffffffffffffffv",
      "gffffffffffffffv",
      "gffffffffffffffv",
      "fffffffffffffffv",
      "fffffffffffffffv",
      "fffffffffffffffv",
      "fffffffffffffffv",
      "fffffffffffffffv",
      "fffffffffffffffv",
      "fffffffffffffffv",
      "fffffffffffffffv",
      "fffffffffffffffv",
      "fffffffffffffffv",
      "fffffffffffffffv"
    ],
    [
      " gfffffffffffffv",
      "gffffffffffffffv",
      "gffffffffffffffv",
      "gffffffffffffffv",
      "fffffffffffffffv",
      "fffffffffffffffv",
      "fffffffffffffffv",
      "fffffffffffffffv",
      "fffffffffffffffv",
      "fffffffffffffffv",
      "fffffffffffffffv",
      "fffffffffffffffv",
      "fffffffffffffffv",
      "fffffffffffffffv",
      "fffffffffffffffv",
      "fffffffffffffffv"
    ],
    [
      "gffffffffffffffv",
      "gffffffffffffffv",
      "gffffffffffffffv",
      "fffffffffffffffv",
      "fffffffffffffffv",
      "fffffffffffffffv",
      "fffffffffffffffv",
      "fffffffffffffffv",
      "fffffffffffffffv",
      "fffffffffffffffv",
      "fffffffffffffffv",
      "fffffffffffffffv",
      "fffffffffffffffv",
      "fffffffffffffffv",
      "fffffffffffffffv",
      "fffffffffffffffv"
    ],
    [
      "gffffffffffffffv",
      "fffffffffffffffv",
      "fffffffffffffffv",
      "fffffffffffffffv",
      "fffffffffffffffv",
      "fffffffffffffffv",
      "fffffffffffffffv",
      "fffffffffffffffv",
      "fffffffffffffffv",
      "fffffffffffffffv",
      "fffffffffffffffv",
      "fffffffffffffffv",
      "fffffffffffffffv",
      "fffffffffffffffv",
      "fffffffffffffffv",
      "fffffffffffffffv"
    ]
  ]
}