{
  "name": "multi_alienresearch_14_ground",
  "refpalette": "deceasedcraft:multi_alienresearch_14/multi_alienresearch_14_ground_palette",
  "xsize": 16,
  "zsize": 16,
  "slices": [
    [
      "abcdeeeedzcvfzzz",
      "bbcedeededcvfggz",
      "bbcdzdeddecffgzz",
      "bbceddeeeecvfgzz",
      "bbheeddeehcvgfzz",
      "bbczzedeeecvfzgz",
      "bbczddeedecffgzz",
      "bbcdzdeeddcvffzz",
      "bbcddeeeedcvvgzz",
      "bbceeeeeeecvfgzz",
      "bbcdeeeedecvgfzz",
      "bbheeeeeehcvfgzz",
      "bbcedeeeddcffgzz",
      "bbcehhhhezcvfzgz",
      "bbcdh  hedcvggzz",
      "bbcdhiihdecffgzz"
    ],
    [
      "         jk  l  ",
      "          k  l m",
      "    m     k  l  ",
      "          k  l  ",
      "  noopqocnk  l m",
      "  om   r  k  l  ",
      "  os     rk  l  ",
      "  o m     k  l  ",
      "  o       k  l m",
      "  ctu wwwxk  l  ",
      "  ctt!utyAk  lm ",
      "  nccccccnk  lm ",
      "  c     B k  l  ",
      "  c iiii sk  l  ",
      "  cCiDEi  k  l  ",
      "  c iDEi  k  l  "
    ],
    [
      "         jF  l  ",
      "         j   l  ",
      "          I  l  ",
      "          J  l  ",
      "  nKLMNLLnJ  l  ",
      "  K       O  l  ",
      "  K      jJ  l  ",
      "  L       F  l  ",
      "  L      jF  l  ",
      "  KP      J  l  ",
      "  LttQQ   J  l  ",
      "  nLLLLLLnJ  l  ",
      "  L       J  l  ",
      "  L      jI  l  ",
      "  L      jF  l  ",
      "  L      jF  l  "
    ],
    [
      "          F  l  ",
      "         jF  l  ",
      "          R  l  ",
      "          J  l  ",
      "  nLKSSLKnJ  l  ",
      "  K      j   l  ",
      "  L      jJ  l  ",
      "  K      jF  l  ",
      "  K      j   l  ",
      "  L      jI  l  ",
      "  L       J  l  ",
      "  nLLLLLLnJ  l  ",
      "  L       J  l  ",
      "  K      jI  l  ",
      "  L      jF  l  ",
      "  L      jF  l  "
    ],
    [
      "         jF  T  ",
      "          F  T  ",
      "         jJ  T  ",
      "          J  T  ",
      "  nKLLLLLnJ  T  ",
      "  LU     jI  T  ",
      "  VU      J  T  ",
      "  VU     jF  T  ",
      "  WU     jF  T  ",
      "  WU      R  T  ",
      "  LU      J  T  ",
      "  nLLLLLLnJ  T  ",
      "  LU      J  T  ",
      "  VU      J  T  ",
      "  WU     j   T  ",
      "  VU      F  T  "
    ],
    [
      "         XJY    ",
      "         XJY    ",
      "         XJY    ",
      "         XJ     ",
      "  nLLLXnnnJ     ",
      "  L      XJ     ",
      "  K      XJZ    ",
      "  K      XJZ    ",
      "  K      XJY    ",
      "  L      XJY    ",
      "  L      XJ     ",
      "  nLLLXnnnJ     ",
      "  L      XJ     ",
      "  L      XJY    ",
      "  L      XJZ    ",
      "  L      XJY    "
    ]
  ]
}