{
  "name": "multi_alienresearch_14_base6",
  "refpalette": "deceasedcraft:multi_alienresearch_14/multi_alienresearch_14_base6_palette",
  "xsize": 16,
  "zsize": 16,
  "slices": [
    [
      " abcccccccccccdv",
      "abbcccccccccccdv",
      "aebcccccccccccdv",
      "abccccccccccccdv",
      "bbccccccccccccdv",
      "bcccccccccccccdv",
      "bcccccccccccccdv",
      "ccccccccccccccdv",
      "ccccccccccccccdv",
      "ccccccccccccccdv",
      "ccccccccccccccdv",
      "ccccccccccccccdv",
      "ccccccccccccccdv",
      "ccccccccccccccdv",
      "ccccccccccccccdv",
      "ccccccccccccccdv"
    ],
    [
      "  f     ggg  hdv",
      "  f    ijk   hdv",
      "  fl    jk   hdv",
      " f k   ijm   ndv",
      " f op   jm   ndv",
      "f  k   ijm   ndv",
      "f  q    jk   hdv",
      "       ijk   hdv",
      "        ggg  hdv",
      "        i    hdv",
      "             hdv",
      "              dv",
      "              dv",
      "  r          sdv",
      "ttt           dv",
      "uuwxp        ydv"
    ],
    [
      "  A      B   Cdv",
      "  A     DE   Fdv",
      "  A     IJ   Cdv",
      " A            dv",
      " A K    L    Mdv",
      "A       D     dv",
      "A       NO   Cdv",
      "        D    Cdv",
      "         P   Cdv",
      "             Cdv",
      "             Cdv",
      "              dv",
      "              dv",
      "              dv",
      "  Q           dv",
      "  RS          dv"
    ],
    [
      "  A          Cdv",
      "  A          Cdv",
      "  A          Cdv",
      " A            dv",
      " A            dv",
      "A             dv",
      "A            Cdv",
      "             Cdv",
      "             Tdv",
      "             Cdv",
      "             Cdv",
      "              dv",
      "              dv",
      "              dv",
      "              dv",
      "              dv"
    ],
    [
      "  A          Udv",
      "  A          Edv",
      "  A          Vdv",
      " A            dv",
      " A            dv",
      "A             dv",
      "A            !dv",
      "             Vdv",
      "             Wdv",
      "             !dv",
      "             Vdv",
      "              dv",
      "              dv",
      "              dv",
      "              dv",
      "              dv"
    ],
    [
      "  A           dv",
      "  A           dv",
      "  A           dv",
      " A            dv",
      " A            dv",
      "A             dv",
      "A             dv",
      "              dv",
      "              dv",
      "              dv",
      "              dv",
      "              dv",
      "              dv",
      "              dv",
      "              dv",
      "              dv"
    ]
  ]
}