{
  "name": "multi_alienresearch_14_base7",
  "refpalette": "deceasedcraft:multi_alienresearch_14/multi_alienresearch_14_base7_palette",
  "xsize": 16,
  "zsize": 16,
  "slices": [
    [
      "aaaaaaaaaaaaaaav",
      "bbbbcdd eee   cv",
      "baaacdd eee   cv",
      "baffcdd eee   cv",
      "baffcdd       cv",
      "baffcdd       cv",
      "baffcdd       cv",
      "baffcdd       cv",
      "baffcdd       cv",
      "baffcdd       cv",
      "baffcdd       cv",
      "aaffcdd       cv",
      "ffffcdd       cv",
      "ffffcdd       cv",
      "ffffcdd       cv",
      "ffffcdd       cv"
    ],
    [
      "gbbbaaaaaaaaaaav",
      "bbbbchi       cv",
      "baaac i       cv",
      "ba jc i       cv",
      "ba kc i       cv",
      "ba lc i       cv",
      "ba  m i       cv",
      "ba  n i       cv",
      "ba oc i       cv",
      "ba pc i       cv",
      "ba qc i       cv",
      "aarac i       cv",
      "as  c i       cv",
      "aaaac i       cv",
      "tj jc i       cv",
      " k kc i       cv"
    ],
    [
      "gbbbaaaaaaaaaaav",
      "gbbbc         cv",
      "gaaac         cv",
      "ba  c         cv",
      "ba  c         cv",
      "ba  c         cv",
      "ba  u         cv",
      "ba  w         cv",
      "ba  c         cv",
      "ba  c         cv",
      "ba  c         cv",
      "aaxac         cv",
      "a  yc         cv",
      "aaaac         cv",
      "    c         cv",
      "    c         cv"
    ],
    [
      " gbbaaaaaaaaaaav",
      "gbbbc         cv",
      "gaaac         cv",
      "ga  c         cv",
      "ba  c         cv",
      "ba  c         cv",
      "ba  c         cv",
      "ba  c         cv",
      "ba  c         cv",
      "ba  c         cv",
      "ba  c         cv",
      "aaaac         cv",
      "a  Ac         cv",
      "aaaac         cv",
      "    c         cv",
      "    c         cv"
    ],
    [
      " gbbaaaaaaaaaaav",
      " gbbc         cv",
      "gaaac         cv",
      "ga  c         cv",
      "ga  c         cv",
      "ba  c         cv",
      "ba  c         cv",
      "ba  c         cv",
      "ba  c         cv",
      "ba  c         cv",
      "ba  c         cv",
      "aaaac         cv",
      "a!  c         cv",
      "aaaac         cv",
      "    c         cv",
      "    c         cv"
    ],
    [
      " Bbbaaaaaaaaaaav",
      " Bbbc         cv",
      " Baac         cv",
      "Ba  c         cv",
      "Ba  c         cv",
      "ba  c         cv",
      "ba  c         cv",
      "ba  c         cv",
      "ba  c         cv",
      "ba  c         cv",
      "ba  c         cv",
      "aaaac         cv",
      "aCCCc         cv",
      "aaaac         cv",
      "    c         cv",
      "    c         cv"
    ]
  ]
}