{
  "name": "multi_alienresearch_14_top",
  "refpalette": "deceasedcraft:multi_alienresearch_14/multi_alienresearch_14_top_palette",
  "xsize": 16,
  "zsize": 16,
  "slices": [
    [
      "       abcd     ",
      "       abcd     ",
      "       abcd     ",
      "       abcd     ",
      "  efeeeabcd     ",
      "       abcd     ",
      "       abcd     ",
      "       abcd     ",
      "       abcd     ",
      "       abcd     ",
      "       abcd     ",
      "  efeeeabcd     ",
      "       abcd     ",
      "       abcd     ",
      "       abcd     ",
      "       abcd     "
    ],
    [
      "  f abcg        ",
      "  f abcg        ",
      "  f abc         ",
      "  f abcg        ",
      "feeeabcg        ",
      "  f abgg        ",
      "  f abcg        ",
      "  f abcg        ",
      "  f abcg        ",
      "  f abcg        ",
      "  f abc         ",
      "feeeabcg        ",
      "  f abcg        ",
      "  f abcg        ",
      "  f abcg        ",
      "  f abcg        "
    ],
    [
      " abcg           ",
      " ab             ",
      " abc            ",
      " abcg           ",
      "eabcg           ",
      " abcg           ",
      " abgg           ",
      " abcg           ",
      "  bcg           ",
      " abcg           ",
      " abcg           ",
      "eabcg           ",
      " abc            ",
      " abcg           ",
      " abgg           ",
      " abcg           "
    ],
    [
      "cg              ",
      "cg              ",
      "hg              ",
      "cg              ",
      "cg              ",
      "hg              ",
      "cg              ",
      "cg              ",
      "i               ",
      "c               ",
      "cg              ",
      "hg              ",
      "cg              ",
      "cg              ",
      "hg              ",
      "cg              "
    ]
  ]
}