{
  "name": "multi_sunkenclub_1_base2",
  "refpalette": "deceasedcraft:multi_sunkenclub_1/multi_sunkenclub_1_base2_palette",
  "xsize": 16,
  "zsize": 16,
  "slices": [
    [
      "vvvvvvvvvvvvvvvv",
      "vvvvvvvvvvvvvvvv",
      "vvvvvvvvvvvvvvvv",
      "vvvvvvvvvvvvvvvv",
      "vvvvvvvvvvvvvvvv",
      "vvvvvvvvvvvvvvvv",
      "vvvvvvvvvvvvvvvv",
      "vvvvvvvvvvvvvvvv",
      "vvvvvvvvvvvvvvvv",
      "vvvvvvvvvvvvvvvv",
      "vvvvvvvvvvvvvvvv",
      "vvvvvvvvvvvvvvvv",
      "vvvvvvvvvvvvvvvv",
      "vvvvvvvvvvvvvvvv",
      "vvvvvvvvvvvvvvvv",
      "vvvvvvvvvvvvvvvv"
    ],
    [
      "vaaaaaaaaaaaaaaa",
      "vaaaaaaaaaaaaaaa",
      "vaaaaaaaaaaaaaaa",
      "vaaaaaaaaaaaaaaa",
      "vaaaaabaaaaaabaa",
      "vaaaaacaaaaaacca",
      "vaaaaccaaaaaaccc",
      "vccccccaaaaaaccc",
      "vccccccaaaaaaccc",
      "vccccccaaaaaaccc",
      "vccccccaaaaaaccc",
      "vcccccbaaaaaabcc",
      "vccccccaaaaaaccc",
      "vccccccaaaaaaccc",
      "vccccccaaaaaaccc",
      "vccccccaaaaaaccc"
    ],
    [
      "vaaaaad e  f daa",
      "vaaaaadgg  ggdaa",
      "vaaaaad!    hdaa",
      "vaaaaadii  iidaa",
      "vcccccbjjjjjjbcc",
      "vccccckjjjjjjl c",
      "vcccc kmnojjj   ",
      "vccccp jjjjjjl  ",
      "vcccp kjjjjjj   ",
      "vccc  kmnojjj   ",
      "vccc pkjjjjjjl  ",
      "vccc  bjjjjjjb  ",
      "vccc   jjjjjjlqq",
      "vccc qkmnojjj qr",
      "vccc qkjjjjjjlqs",
      "vccc qkjjjjjjlqr"
    ],
    [
      "vaaaaad t  u daa",
      "vcccccdgg  ggdcc",
      "vcccccdw    xdcc",
      "vcccccdii  iidcc",
      "vcccc b      b  ",
      "vccc  k      l  ",
      "vccc  k         ",
      "vccc         l  ",
      "vccc  k      l  ",
      "vccc  k         ",
      "vccc  k      l  ",
      "vccc  b      b  ",
      "vccc  k      l  ",
      "vccc  k        y",
      "vccc  k      l A",
      "vccc  k      l y"
    ],
    [
      "vcccccd B  C dcc",
      "vcccccdDDEEDDdcc",
      "vccc  d      d  ",
      "vccc  dFFEEFFd  ",
      "vccc  b  II  b  ",
      "vccc  J      K  ",
      "vccc  J      K  ",
      "vccc  J      K  ",
      "vccc  J      K  ",
      "vccc  J         ",
      "vccc  J      K  ",
      "vccc  b      b  ",
      "vccc  J      K  ",
      "vccc  J      K  ",
      "vccc  J      K  ",
      "vccc  J      K  "
    ],
    [
      "vcccp L      L  ",
      "vcccp L      L  ",
      "vccc  L      L  ",
      "vccc  L      L  ",
      "vccc  bLLLLLLb  ",
      "vccc  L      L  ",
      "vccc  L      L  ",
      "vccc  L      L  ",
      "vccc  L      L  ",
      "vccc  L      L  ",
      "vccc  L      L  ",
      "vccc  b      b  ",
      "vccc  L      L  ",
      "vccc  L      L  ",
      "vccc  L      L  ",
      "vccc  L      L  "
    ]
  ]
}