{
  "name": "multi_farmhouse1_4_top",
  "refpalette": "deceasedcraft:multi_farmhouse1_4/multi_farmhouse1_4_top_palette",
  "xsize": 16,
  "zsize": 16,
  "slices": [
    [
      "aaaaaaaaaaaaaaaa",
      "aaaaaaaaaaaaaaaa",
      "aaaaaaaaaaaaaaaa",
      "bbbbbbbbbbbbbbbb",
      "ccdeeeeeeeeddccc",
      "aadaaaaaaaafaaaa",
      "aadgaaaaaaafaaaa",
      "aadhhhhhhhhddaaa",
      "aadeeeeeeeeidaaa",
      "aadeeeeeeeeidaaa",
      "aadeeeeeeeeidaaa",
      "bbdeeeeeeeejdbbb",
      "cccccccccccccccc",
      "aaaaaaaaaaaaaaaa",
      "aaaaaaaaaaaaaaaa",
      "aaaaaaaaaaaaaaaa"
    ],
    [
      "aaaaaaaaaaaaaaaa",
      "aaaaaaaaaaaaaaaa",
      "aaaaaaaaaaaaaaaa",
      "aaaaaaaaaaaaaaaa",
      "kkkkkkkkkkkkkkkk",
      "ccdlaaaaaalfcccc",
      "aadammmmmmmfaaaa",
      "aadaaaaaaalddaaa",
      "aadnonaaaapddaaa",
      "aadqarstaauddaaa",
      "bbdlvrwlxyzddbbb",
      "AAAAAAAAAAAjAAAA",
      "aaaaaaaaaaaaaaaa",
      "aaaaaaaaaaaaaaaa",
      "aaaaaaaaaaaaaaaa",
      "aaaaaaaaaaaaaaaa"
    ],
    [
      "aaaaaaaaaaaaaaaa",
      "aaaaaaaaaaaaaaaa",
      "aaaaaaaaaaaaaaaa",
      "aaaaaaaaaaaaaaaa",
      "aaaaaaaaaaaaaaaa",
      "kkkkkkBBBBkkkkkk",
      "ccdaaaaaaaafcccc",
      "aadaaaaaaaaddaaa",
      "aadnCnaaaaaddaaa",
      "bbdDarEaaalddbbb",
      "AAAAAAAAAAAAAAAA",
      "aaaaaaaaaaajaaaa",
      "aaaaaaaaaaaaaaaa",
      "aaaaaaaaaaaaaaaa",
      "aaaaaaaaaaaaaaaa",
      "aaaaaaaaaaaaaaaa"
    ],
    [
      "aaaaaaaaaaaaaaaa",
      "aaaaaaaaaaaaaaaa",
      "aaaaaaaaaaaaaaaa",
      "aaaaaaaaaaaaaaaa",
      "aaaaaaaaaaaaaaaa",
      "aaaaaaaaaaaaaaaa",
      "kkkkkkBBBBkkkkkk",
      "ccdaaaaaallddccc",
      "bbdnnnaaaalddbbb",
      "AAAAAAAAAAAAAAAA",
      "aaaaaaaaaaaaaaaa",
      "aaaaaaaaaaaFaaaa",
      "aaaaaaaaaaaaaaaa",
      "aaaaaaaaaaaaaaaa",
      "aaaaaaaaaaaaaaaa",
      "aaaaaaaaaaaaaaaa"
    ],
    [
      "aaaaaaaaaaaaaaaa",
      "aaaaaaaaaaaaaaaa",
      "aaaaaaaaaaaaaaaa",
      "aaaaaaaaaaaaaaaa",
      "aaaaaaaaaaaaaaaa",
      "aaaaaaaaaaaaaaaa",
      "aaaaaaaaaaaaaaaa",
      "kkkkkkkkkkkkkkkk",
      "AAAAAAAAAAAAAAAA",
      "aaaaaaaaaaaaaaaa",
      "aaaaaaaaaaaaaaaa",
      "aaaaaaaaaaaFaaaa",
      "aaaaaaaaaaaaaaaa",
      "aaaaaaaaaaaaaaaa",
      "aaaaaaaaaaaaaaaa",
      "aaaaaaaaaaaaaaaa"
    ],
    [
      "aaaaaaaaaaaaaaaa",
      "aaaaaaaaaaaaaaaa",
      "aaaaaaaaaaaaaaaa",
      "aaaaaaaaaaaaaaaa",
      "aaaaaaaaaaaaaaaa",
      "aaaaaaaaaaaaaaaa",
      "aaaaaaaaaaaaaaaa",
      "aaaaaaaaaaaaaaaa",
      "aaaaaaaaaaaaaaaa",
      "aaaaaaaaaaaaaaaa",
      "aaaaaaaaaaaaaaaa",
      "aaaaaaaaaaaFaaaa",
      "aaaaaaaaaaaaaaaa",
      "aaaaaaaaaaaaaaaa",
      "aaaaaaaaaaaaaaaa",
      "aaaaaaaaaaaaaaaa"
    ]
  ]
}