{
  "name": "multi_farmhouse1_4part2_floor1",
  "refpalette": "deceasedcraft:multi_farmhouse1_4/multi_farmhouse1_4part2_floor1_palette",
  "xsize": 16,
  "zsize": 16,
  "slices": [
    [
      "aaaaaaaaaaaaaaaa",
      "aaaaaaaaaaaaaaaa",
      "aaaaaaaaaaaaaaaa",
      "aaaaaaaaaaaaaaaa",
      "aaaaaaaaaaaaaaaa",
      "aaaaaaaaaaaaaaaa",
      "aaaaaaaaaaaaaaaa",
      "aaaaaaaaaaaaaaaa",
      "aaaaaaaaaaaaaaaa",
      "aaaaaaaaaaaaaaaa",
      "aaaaaaaaaaaaaaaa",
      "aaaaaaaaaaaaaaaa",
      "aaaaaaaaaaaaaaaa",
      "aaaaaaaaaaaaaaaa",
      "aaaaaaaaaaaaaaaa",
      "aaaaaaaaaaaaaaaa"
    ],
    [
      "aaaaaaaaaaaaaaaa",
      "aaaaaaaaaaaaaaaa",
      "aaaaaaaaaaaaaaaa",
      "aaaaaaaaaaaaaaaa",
      "aaaaaaaaaaaaaaaa",
      "aaaaaaaaaaaaaaaa",
      "aaaaaaaaaaaaaaaa",
      "aaaaaaaaaaaaaaaa",
      "aaaaaaaaaaaaaaaa",
      "aaaaaaaaaaaaaaaa",
      "aaaaaaaaaaaaaaaa",
      "aaaaaaaaaaaaaaaa",
      "aaaaaaaaaaaaaaaa",
      "aaaaaaaaaaaaaaaa",
      "aaaaaaaaaaaaaaaa",
      "aaaaaaaaaaaaaaaa"
    ],
    [
      "aaaaaaaaaaaaaaaa",
      "aaaaaaaaaaaaaaaa",
      "aaaaaaaaaaaaaaaa",
      "aaaaaaaaaaaaaaaa",
      "aaaaaaaaaaaaaaaa",
      "aaaaaaaaaaaaaaaa",
      "aaaaaaaaaaaaaaaa",
      "aaaaaaaaaaaaaaaa",
      "aaaaaaaaaaaaaaaa",
      "aaaaaaaaaaaaaaaa",
      "aaaaaaaaaaaaaaaa",
      "aaaaaaaaaaaaaaaa",
      "aaaaaaaaaaaaaaaa",
      "aaaaaaaaaaaaaaaa",
      "aaaaaaaaaaaaaaaa",
      "aaaaaaaaaaaaaaaa"
    ],
    [
      "aaaaaaaaaaaaaaaa",
      "aaaaaaaaaaaaaaaa",
      "aaaaaaaaaaaaaaaa",
      "aaaaaaaaaaaaaaaa",
      "aaaaaaaaaaaaaaaa",
      "aaaaaaaaaaaaaaaa",
      "aaaaaaaaaaaaaaaa",
      "aaaaaaaaaaaaaaaa",
      "aaaaaaaaaaaaaaaa",
      "aaaaaaaaaaaaaaaa",
      "aaaaaaaaaaaaaaaa",
      "aaaaaaaaaaaaaaaa",
      "aaaaaaaaaaaaaaaa",
      "aaaaaaaaaaaaaaaa",
      "aaaaaaaaaaaaaaaa",
      "aaaaaaaaaaaaaaaa"
    ],
    [
      "aaaaaaaaaaaaaaaa",
      "aaaaaaaaaaaaaaaa",
      "aaaaaaaaaaaaaaaa",
      "aaaaaaaaaaaaaaaa",
      "aaaaaaaaaaaaaaaa",
      "aaaaaaaaaaaaaaaa",
      "aaaaaaaaaaaaaaaa",
      "aaaaaaaaaaaaaaaa",
      "aaaaaaaaaaabaaaa",
      "aaaaaaaaaaaaaaaa",
      "aaaaaaaaaaaaaaaa",
      "aaaaaaaaaaacaaaa",
      "aaaaaaaaaaaaaaaa",
      "aaaaaaaaaaaaaaaa",
      "aaaaaaaaaaaaaaaa",
      "aaaaaaaaaaaaaaaa"
    ],
    [
      "aaaaaaaaaaaaaaaa",
      "aaaaaaaaaaaaaaaa",
      "aaaaaaaaaaaaaaaa",
      "aaaaaaaaaaaaaaaa",
      "aaaaaaaaaaaaaaaa",
      "aaaaaaaaaaaaaaaa",
      "aaaaaaaaaaaaaaaa",
      "aaaaaaaaaaaaaaaa",
      "aaaaaaaaaaaaaaaa",
      "aaaaaaaaaaaaaaaa",
      "aaaaaaaaaaaaaaaa",
      "aaaaaaaaaaacaaaa",
      "aaaaaaaaaaaaaaaa",
      "aaaaaaaaaaaaaaaa",
      "aaaaaaaaaaaaaaaa",
      "aaaaaaaaaaaaaaaa"
    ]
  ]
}