{
  "name": "multi_farmhouse1_4_floor1",
  "refpalette": "deceasedcraft:multi_farmhouse1_4/multi_farmhouse1_4_floor1_palette",
  "xsize": 16,
  "zsize": 16,
  "slices": [
    [
      "aaaaaaaaaaaaaaaa",
      "aaaaaaaaaaaaaaaa",
      "aaaaaaaaaaaaaaaa",
      "aaaaaaaaaaaaaaaa",
      "aaaaaaaaaaaaaaaa",
      "aaaaaaaaaaaaaaaa",
      "aaaaaaaaaaaaaaaa",
      "aaaaaaaaaaaaaaaa",
      "aaaaaaaaaaaaaaaa",
      "aaaaaaaaaaaaaaaa",
      "aaaaaaaaaaaaaaaa",
      "aaaaaaaaaaaaaaaa",
      "aaaaaaaaaaaaaaaa",
      "aaaaaaaaaaaaaaaa",
      "bbbbaaaaaaabbbbb",
      "bbbbbbbbbbbbbbbb"
    ],
    [
      "bbbbabbabbbbbbbb",
      "bbbabaababbbbbbb",
      "bbbbaaaaaabbbbbb",
      "bbbbbbbbbbbbbbbb",
      "baaaaaaaaaaaaaac",
      "baaaaaaaaaaaaaac",
      "baaaaaaaaaaaaaac",
      "baaaaaaaaaaaaaac",
      "baaaaaaaaaaaaaac",
      "baaaaaaaaaaaaaac",
      "baaaaaaaaaaaaaac",
      "baaaaaaaaaaaaaac",
      "bbbbbbbbbbbbbbbb",
      "bbbbbbbbbbbbbbbb",
      "ddddbbbbbbbddddd",
      "dddddddddddddddd"
    ],
    [
      "ddddeddeddddfddd",
      "dddedggdeddddddd",
      "ddddeeeegedddddd",
      "hhhhhhhhhhhhhhhh",
      "dcccccccccccccij",
      "dcccccccccccccij",
      "dcccccccccccccij",
      "dcccccccccccccij",
      "dcccccccccccccij",
      "dcccccccccccccij",
      "dcccccccccccccij",
      "dcccccccccccccij",
      "kkkkkkkkkkkkkkkk",
      "dddddddddddddddd",
      "dddddddddddddddd",
      "dddddddddddddddd"
    ],
    [
      "ddddddddddddlddd",
      "dddddddddddddddd",
      "dddddeeddddddddd",
      "hhhhhhhhhhhhhhhh",
      "ddmnoopqpormmddd",
      "ddmddddddddsdddd",
      "ddmtdddddddudddd",
      "ddmddddddddmmddd",
      "ddmvddgddddwmxdd",
      "ddmeevdddddwmydd",
      "ddmezedAAddwmydd",
      "ddmeeegAAAdwmxdd",
      "kkkkkkkkkkkkkkkk",
      "dddddddddddddddd",
      "dddddddddddddddd",
      "dddddddddddddddd"
    ],
    [
      "dddddddddddddddd",
      "dddddddddddddddd",
      "dddddddddddddddd",
      "hhhhhhhhhhhhhhhh",
      "ddmdodpqdddmmddd",
      "ddmddddddddBdddd",
      "ddmtdddddddCdddd",
      "ddmddddddddmmddd",
      "ddmddddddddDmEdd",
      "ddmFddddddddmddd",
      "ddmevdddddddmddd",
      "ddmGeFdAdddHmEdd",
      "kkkkkkkkkkkkkkkk",
      "dddddddddddddddd",
      "dddddddddddddddd",
      "dddddddddddddddd"
    ],
    [
      "dddddddddddddddd",
      "dddddddddddddddd",
      "dddddddddddddddd",
      "hhhhhhhhhhhhhhhh",
      "ddmdddpddddmmddd",
      "ddmddddddddIdddd",
      "ddmtdddddddIdddd",
      "ddmddddddddmmddd",
      "ddmddddddddJmddd",
      "ddmddddddddJmddd",
      "ddmFdddddddJmddd",
      "ddmFeddddddHmddd",
      "kkkkkkkkkkkkkkkk",
      "dddddddddddddddd",
      "dddddddddddddddd",
      "dddddddddddddddd"
    ]
  ]
}