{
  "name": "multi_terraceplaza_12_floor1",
  "refpalette": "deceasedcraft:multi_terraceplaza_12/multi_terraceplaza_12_floor1_palette",
  "xsize": 16,
  "zsize": 16,
  "slices": [
    [
      "      a         ",
      "   b  a         ",
      "      a         ",
      "      a         ",
      "      c         ",
      "      a         ",
      "      a         ",
      "   d  a         ",
      "      a         ",
      "      a         ",
      "      a         ",
      "      aeeeeeeeee",
      "ffffffafffffffff",
      "gggggggggggggggg",
      "hhhhhhhhhhhhhhhh",
      "hhhhhhhhhhhhhhhh"
    ],
    [
      "iiiiiij         ",
      "iiiiiij         ",
      "iiiiiij         ",
      "iiiiiij         ",
      "jjjjjjcjjjjjjjjj",
      "      j         ",
      "      j         ",
      "   d  j         ",
      "      jeeeeeeeee",
      "ffffffjfffffffff",
      "gggggggggggggggg",
      "kkkkkkllllllllll",
      "mmmmmmmmmmmmmmmm",
      "                ",
      "nnnnnnnnnnnnnnnn",
      "                "
    ],
    [
      "oooooop         ",
      "oooooop         ",
      "oooooop         ",
      "oooooop         ",
      "      c         ",
      "eeeeeejeeeeeeeee",
      "ffffffjfffffffff",
      "gggggggggggggggg",
      "kkkkkkllllllllll",
      "mmmmmmmmmmmmmmmm",
      "                ",
      "                ",
      "                ",
      "                ",
      "                ",
      "                "
    ],
    [
      "      q         ",
      "rsrrrsq         ",
      "      qeeeeeeeee",
      "eeeeeeffffffffff",
      "ttttttcjjjjjjjjj",
      "hhhhhhhhhhhhhhhh",
      "mmmmmmmmmmmmmmmm",
      "                ",
      "                ",
      "                ",
      "                ",
      "                ",
      "                ",
      "                ",
      "                ",
      "                "
    ],
    [
      "      ffffffffff",
      "eeeeeegggggggggg",
      "llllllllllllllll",
      "hhhhhhhhhhhhhhhh",
      "uuuuuuuuuuuuuuuu",
      "nnnnnnnnnnnnnnnn",
      "                ",
      "                ",
      "                ",
      "                ",
      "                ",
      "                ",
      "                ",
      "                ",
      "                ",
      "                "
    ],
    [
      "wwwwwxmmmmmmmmmm",
      "                ",
      "                ",
      "                ",
      "                ",
      "                ",
      "                ",
      "                ",
      "                ",
      "                ",
      "                ",
      "                ",
      "                ",
      "                ",
      "                ",
      "                "
    ]
  ]
}