{
  "name": "multi_terraceplaza_12_base2",
  "refpalette": "deceasedcraft:multi_terraceplaza_12/multi_terraceplaza_12_base2_palette",
  "xsize": 16,
  "zsize": 16,
  "slices": [
    [
      "aaaaaaaaaaaaaaaa",
      "aaaaaaaaaaaaaaaa",
      "aaaaaaaaaaaaaaaa",
      "aaaaaaaaaaaaaaaa",
      "aaaaaabaaaaaaaaa",
      "aaaaaaaaaaaaaaaa",
      "aaaaaaaaaaaaaaaa",
      "aaaaaaaaaaaaaaaa",
      "aaaaaaaaaaaaaaaa",
      "aaaaaaaaaaaaaaaa",
      "aaaaaaaaaaaaaaaa",
      "aaaaaaaaaaaaaaaa",
      "aaaaaaaaaaaaaaaa",
      "aaaaaaaaaaaaaaaa",
      "aaaaaaaaaaaaaaaa",
      "aaaaaabaaaaaaaaa"
    ],
    [
      " c  defdge  c   ",
      " h  iifiii  h   ",
      "      f         ",
      " j  iifiii  j   ",
      " c  debdge  c  k",
      " h  iifiii  h   ",
      "      f         ",
      " j  iifiii  j   ",
      " c  defdge  c   ",
      " h  iifiii  h   ",
      "      f         ",
      " j  iifiii  j   ",
      " c  defdge  c   ",
      " h  iifiii  h   ",
      "    llflll     k",
      "   mnnbnnno     "
    ],
    [
      " p   qr         ",
      "      r         ",
      "      r         ",
      "      r         ",
      "      b ps     k",
      "      r         ",
      "      r         ",
      "      r         ",
      "     prt        ",
      "      r         ",
      "      r         ",
      "      r         ",
      " u    rp!       ",
      "      r         ",
      "      r        k",
      "    wwbwww      "
    ],
    [
      "                ",
      "                ",
      "                ",
      "                ",
      "      b        k",
      "                ",
      "                ",
      "                ",
      "                ",
      "                ",
      "                ",
      "                ",
      "                ",
      "                ",
      "               k",
      "      b         "
    ],
    [
      "                ",
      "                ",
      "                ",
      "                ",
      "      b        k",
      "                ",
      "                ",
      "                ",
      "                ",
      "                ",
      "                ",
      "                ",
      "                ",
      "                ",
      "               k",
      "      b         "
    ],
    [
      "               k",
      "               k",
      "               k",
      "               k",
      "      b        k",
      "               k",
      "               k",
      "               k",
      "               k",
      "               k",
      "               k",
      "               k",
      "               k",
      "               k",
      "               k",
      "      b         "
    ]
  ]
}