{
  "name": "multi_terraceplaza_12_base1",
  "refpalette": "deceasedcraft:multi_terraceplaza_12/multi_terraceplaza_12_base1_palette",
  "xsize": 16,
  "zsize": 16,
  "slices": [
    [
      "               a",
      "               a",
      "               a",
      "               a",
      "      b        a",
      "               a",
      "               a",
      "               a",
      "               a",
      "               a",
      "               a",
      "               a",
      "               a",
      "               a",
      "               a",
      "      b         "
    ],
    [
      "               a",
      "               a",
      "               a",
      "               a",
      "      b        a",
      "               a",
      "               a",
      "               a",
      "               a",
      "               a",
      "               a",
      "               a",
      "               a",
      "               a",
      "               a",
      "      b         "
    ],
    [
      "               a",
      "               a",
      "               a",
      "               a",
      "      b        a",
      "               a",
      "               a",
      "               a",
      "               a",
      "               a",
      "               a",
      "               a",
      "               a",
      "               a",
      "               a",
      "      b         "
    ],
    [
      "              ca",
      "              ca",
      "              ca",
      "              ca",
      "      b       ca",
      "              ca",
      "              ca",
      "              ca",
      "              ca",
      "              ca",
      "              ca",
      "              ca",
      "              ca",
      "              ca",
      "dddddddddddddddd",
      "      b         "
    ],
    [
      "eeeeeeeeeeeeeeef",
      "eeeeeeeeeeeeeeef",
      "eeeeeeeeeeeeeeef",
      "eeeeeeeeeeeeeeef",
      "eeeeeebeeeeeeeef",
      "eeeeeeeeeeeeeeef",
      "eeeeeeeeeeeeeeef",
      "eeeeeeeeeeeeeeef",
      "eeeeeeeeeeeeeeef",
      "eeeeeeeeeeeeeeef",
      "eeeeeeeeeeeeeeef",
      "eeeeeeeeeeeeeeef",
      "eeeeeeeeeeeeeeef",
      "eeeeeeeeeeeeeeef",
      "dddddddddddddddd",
      "ccccccbccccccccc"
    ],
    [
      "gggggghggggggggi",
      "gggggghggggggggi",
      "gggggghggggggggi",
      "gggggghggggggggi",
      "hhhhhhbhhhhhhhhh",
      "gggggghggggggggi",
      "gggggghggggggggi",
      "gggggghggggggggi",
      "gggggghggggggggi",
      "gggggghggggggggi",
      "gggggghggggggggi",
      "gggggghggggggggi",
      "gggggghggggggggi",
      "gggggghggggggggi",
      "gggggghggggggggg",
      "hhhhhhbhhhhhhhhh"
    ]
  ]
}