{
  "name": "multi_terraceplaza_12_ground",
  "refpalette": "deceasedcraft:multi_terraceplaza_12/multi_terraceplaza_12_ground_palette",
  "xsize": 16,
  "zsize": 16,
  "slices": [
    [
      "aaaaaabccccccccc",
      "aaaaaabccccccccc",
      "aaaaaabccccccccd",
      "aaaaaabcccccccce",
      "aaaaaafcccccccce",
      "aaaaaabccccccccc",
      "aaaaaabccccccccc",
      "aaaaaabccccccccc",
      "aaaaaabccccccccc",
      "aaaaaabccccccccc",
      "aaaaaabccccccccc",
      "aaaaaabccccccccc",
      "aaaaaabccccccccc",
      "aaaaaabccccccccc",
      "aaaaaabccccccccc",
      "bbbbbbfbbbbbbbbb"
    ],
    [
      "                ",
      "      g        d",
      "      h       ij",
      "   kkkh        l",
      "  mnnnf        l",
      "   oooh         ",
      "   pqrh         ",
      "   s st         ",
      "      h         ",
      "  u  uh         ",
      "  w  wh         ",
      "  x  xh         ",
      "      t         ",
      "ss ss h    yy   ",
      "prAprBh    CD   ",
      "EEEEEEfEEEFIIFEE"
    ],
    [
      "               d",
      "      g       ij",
      "      h        l",
      "      h         ",
      "   JJJf         ",
      "      h         ",
      "    K h         ",
      "      t         ",
      "      h         ",
      "      h         ",
      "  L  Mh         ",
      "      h         ",
      "      t         ",
      "      h         ",
      "  K  Nh    OP   ",
      "EEEEEEfEEEF  FEE"
    ],
    [
      "              ij",
      "      g        l",
      "      h         ",
      "      h         ",
      "      f         ",
      "      h         ",
      "      h         ",
      "      t         ",
      "      h         ",
      "      h         ",
      "      h         ",
      "      h         ",
      "      t         ",
      "      h         ",
      "      h    QQ   ",
      "EEEEEEfEEEFRSFEE"
    ],
    [
      "               l",
      "      g         ",
      "      h         ",
      "      h         ",
      "      f         ",
      "      h         ",
      "      h         ",
      "      t         ",
      "      h         ",
      "      h         ",
      "      h         ",
      "      h         ",
      "      t         ",
      "      h         ",
      "      h         ",
      "EEEEEEfEEEFFFFEE"
    ],
    [
      "     TUV        ",
      "   W TUV        ",
      "      U         ",
      "      U         ",
      "      f         ",
      "      U         ",
      "      U         ",
      "   X  U         ",
      "      U         ",
      "      U         ",
      "      U         ",
      "      U         ",
      "   X  U         ",
      "      U         ",
      "YYYYYYUYYYYYYYYY",
      "ZZZZZZfEEEEEEEEE"
    ]
  ]
}