{
  "name": "multi_cafe_3_ground",
  "refpalette": "deceasedcraft:multi_cafe_3/multi_cafe_3_ground_palette",
  "xsize": 16,
  "zsize": 16,
  "slices": [
    [
      "aa=bbbbbbbbbbbcc",
      "aa=bbbbbbbbbbbcc",
      "aa=bbbbbbbbbbbdc",
      "aa=bbbbbbbbbbbcc",
      "aa=bbbbbbbbbbbcc",
      "aa=bbbbbbbbbbbcc",
      "aa=bbbbbbbbbbbcc",
      "aa=bbbbbbbbbbbdc",
      "aa=bbbbbbbbbbbcc",
      "aa=bbbbbbbbbbbdc",
      "aa============cc",
      "eeeeeffffeeeffcc",
      "ffffffffffffffcc",
      "ffffffffffffffcc",
      "cccccccccccccccc",
      "cccccccccccccccc"
    ],
    [
      "          g ghij",
      " kk       g lhi ",
      "  mno   p g qqr ",
      "s mtu     g whi ",
      "  mt      g whi ",
      "  mtu     g whij",
      "s mt      g whi ",
      "  mto   p xyqqrj",
      "  mtu      ABhi ",
      "s mn       CDhrj",
      "  mmmEFIEmmm==i ",
      "JJJJJK  LJJJ Mij",
      "             Mij",
      "              i ",
      "NjOj j  P QR RRj",
      "P RN   j O NQOQj"
    ],
    [
      "            Shi ",
      " kk       T Uhi ",
      "  mVW   p XYqqr ",
      "  m         Zhi ",
      "  m       0 1hi ",
      "  m2      3 4hi ",
      "  m       5 6hi ",
      "  m W   p   qqr ",
      "  m7       8Bhi ",
      "  m9       #Dhr ",
      "  mmmE$%Emmm==i ",
      "     K  L    Mi ",
      "             Mi ",
      "              i ",
      "                ",
      "                "
    ],
    [
      " ^^         &m  ",
      " **         (hi ",
      "  m W   p   qqr ",
      "  m         )hi ",
      "  m         &m  ",
      "  m         &m  ",
      "  m         (hi ",
      "  m W   p   qqr ",
      "  m        +Bhi ",
      "  m        -[hr ",
      "  mmmEEEEmmm==i ",
      "     ]^^{    Mi ",
      "             Mi ",
      "              i ",
      "                ",
      "                "
    ],
    [
      "  m         }h| ",
      "  m         ;h| ",
      "  m W   p   qqr ",
      "  m         :h| ",
      "  m         'h| ",
      "  m         <h| ",
      "  m         >h| ",
      "  m W   p   qqr ",
      "  m        ,Bh| ",
      "  m        .?hr ",
      "  mmmmmmmmmm==i ",
      "             Mi ",
      "             Mi ",
      "              i ",
      "                ",
      "                "
    ],
    [
      "  m          hi ",
      "  m          hi ",
      "  m W / p   qqr ",
      "  m          hi ",
      "  m          hi ",
      "  m          hi ",
      "  m          hi ",
      "  m W / p   qqr ",
      "  m        ,Bhi ",
      "  m        .`hr ",
      "  mmmmmmmmmm==i ",
      "             Mi ",
      "             Mi ",
      "              i ",
      "                ",
      "                "
    ]
  ]
}