{
  "name": "multi_cafe_3_floor1",
  "refpalette": "deceasedcraft:multi_cafe_3/multi_cafe_3_floor1_palette",
  "xsize": 16,
  "zsize": 16,
  "slices": [
    [
      " ab        cdef ",
      " ab        ghef ",
      " ab iji k   llm ",
      " ab        cdef ",
      " ab        gdef ",
      " ab        cdef ",
      " ab        gdef ",
      " ab ini k   llm ",
      " ab        opef ",
      " ab        q!em ",
      " abbbbbbbbbb==f ",
      " aaaaaaaaaaaarf ",
      "             rf ",
      "              f ",
      "                ",
      "                "
    ],
    [
      " s=     akkkkef ",
      " t=     akkkkef ",
      " u=wwwwwkkkkllm ",
      " t=     akkkkef ",
      " u=     akkkkef ",
      " t=     akkkkef ",
      " t=     akkkkef ",
      " x=wwwwwkkkkllm ",
      "  =     akkkpef ",
      "  =     akkkkem ",
      "  ============f ",
      "             rf ",
      "             rf ",
      "              f ",
      "                ",
      "                "
    ],
    [
      " y=     l   ABf ",
      " t=     l  AABf ",
      " C=     k DEllm ",
      " t=     l   FBf ",
      " x=     l  FIBf ",
      " t=     l   FBf ",
      " t=     l  JFBf ",
      " x=     k   llm ",
      "  =     l  EKBf ",
      "  =     l  BBBm ",
      "  ============f ",
      "           LLMf ",
      "           LLMf ",
      "              f ",
      "                ",
      "                "
    ],
    [
      "  =NNNNNl OOOOP ",
      "  =NNNNNlEOOOOP ",
      "  =     k   llm ",
      "  =NNNNNl OOOOP ",
      "  =NNNNNl OOOOP ",
      "  =NNNNNl OOOOP ",
      "  =NNNNNl OOOOP ",
      "  =     k   llm ",
      "  =NNNNNl OOOOP ",
      "  =NNNNNlE    m ",
      "  ========OOOOP ",
      "   LLLLLLMQOOOP ",
      "   LLLLLLMQRRRf ",
      "          OOOOf ",
      "                ",
      "                "
    ],
    [
      "LMmOOORSSSS     ",
      "LMmOOOSSSS      ",
      "LMmTTTTTmmUUUUU ",
      "LMmOOOSSSS      ",
      "LMmOOORSSSS     ",
      "LMmOOORSSSS     ",
      "LMmOOOSSSS      ",
      "LMmTTTTTmmUUUUU ",
      "LMmOOOSSSS      ",
      "LMmmmmVVWVUUUUU ",
      "LMOOOOSSSS      ",
      "LMQOOORSSSS     ",
      "LMQRRRRSSSS     ",
      "  OOOOSSSS      ",
      "                ",
      "                "
    ],
    [
      "SSU             ",
      "SSU             ",
      "SSU             ",
      "SSU             ",
      "SSU             ",
      "SSU             ",
      "SSU             ",
      "SSU             ",
      "SSU             ",
      "SSUUUU~         ",
      "SS              ",
      "SSS             ",
      "SSS             ",
      "SS              ",
      "                ",
      "                "
    ]
  ]
}