{
  "name": "multi_residentialsurvivor_0_ground",
  "refpalette": "deceasedcraft:multi_residentialsurvivor_0/multi_residentialsurvivor_0_ground_palette",
  "xsize": 16,
  "zsize": 16,
  "slices": [
    [
      "abbbababbbbbbbbb",
      "abbbbaaabbbbbbba",
      "abbbcccccccbbbbb",
      "bbbbcddddddeeeee",
      "abbacddddddfffff",
      "aabbcddddddfffff",
      "aaaacddddddfffff",
      "ababcddddddfffff",
      "aabbcddddddfffff",
      "abbbcddddddfffff",
      "bbbbcddddddfffff",
      "abbbcddddddfffff",
      "abbbcddddddeeeee",
      "ababcccccccbbbbb",
      "aaaabbbbaaabbbbb",
      "aaaaaaaabaaabbaa"
    ],
    [
      " ghh g hghhhhhhh",
      "                ",
      "    ijjkjjkhhghh",
      "    l  mnopeeeee",
      "    kq rnsptuwxy",
      "    A BmCDpE  Fy",
      "    IJAKLL M   I",
      "    INN O  P  FQ",
      "    INR  STPU FV",
      "    INB   SW  Iy",
      "    AX        O ",
      "    kR YZ01   Fy",
      "    l2R3445eeeee",
      "    677k89khhhhg",
      "       #        ",
      "                "
    ],
    [
      "                ",
      "                ",
      "    IIIk$$k     ",
      "    I  mLLpe%eee",
      "    k  ^& p * xy",
      "    A  mCCp   Fy",
      "    I(!)L     Fy",
      "    INU   T   F+",
      "    I-         [",
      "    IN     q  Fy",
      "    A           ",
      "    k]      D DI",
      "    I{D }|;e%eee",
      "    IIIk:'k     ",
      "                ",
      "                "
    ],
    [
      "                ",
      "              l)",
      "    I Ik$$k   l<",
      "    I  mLLpe%eee",
      "    k  m> pLL  y",
      "    A  mCCp   Fy",
      "      ,L  T   Fy",
      "    IN.   ? . F/",
      "    I&        F/",
      "    I`        Fy",
      "    A&         I",
      "    k       D Fy",
      "    I&DD   e%eee",
      "    I Ik77k   l\u0370",
      "              l)",
      "                "
    ],
    [
      "                ",
      "   (\u0371        l) ",
      "   (kkkkkkk  l) ",
      "   (kddddddeee<J",
      "   (kddd>ddddddd",
      "   (kdddddTddddd",
      "   (kddddd?ddddd",
      "   (kddddd ddddd",
      "   (kddddd ddddd",
      "   (kddddddddddd",
      "   (kddddddddddd",
      "   (kddddddddddd",
      "   (kddddddeee\u0370X",
      "   (kkkkkkk  l) ",
      "   (\u0371        l) ",
      "                "
    ],
    [
      "                ",
      "    (\u0371      l)  ",
      "    (kkkjjk l)  ",
      "    (AS L\u0372\u0373ee)  ",
      "    (A R\u0374\u0375SAA<JJ",
      "    (A    \u0374A\u0376\u0376\u0376\u0376",
      "    (A,  \u0377 \u037a\u037b\u037cO\u037d",
      "    (A,   \u0374\u037a    ",
      "    (A\u037e   \u0374XO \u037f ",
      "    (A    R    \u0384",
      "    (AY \u0385 \u0386AA\u0376\u0376\u0376",
      "    (A\u0387 \u0388 \u0389AA\u0370XX",
      "    (A\u0387\u0387\u038a\u038c\u038eee)  ",
      "    (kkk77k l)  ",
      "    (\u0371      l)  ",
      "                "
    ]
  ]
}