{
  "name": "multi_residentialsurvivor_0_floor1",
  "refpalette": "deceasedcraft:multi_residentialsurvivor_0/multi_residentialsurvivor_0_floor1_palette",
  "xsize": 16,
  "zsize": 16,
  "slices": [
    [
      "                ",
      "     ab    cd   ",
      "     aeeffecd   ",
      "     a  gghid   ",
      "     a     jd   ",
      "     a     jklll",
      "     am    n    ",
      "     ao    n    ",
      "     a     jp   ",
      "     a         q",
      "     a     jrsss",
      "     a     jd   ",
      "     atuw xid   ",
      "     aeeffecd   ",
      "     ab    cd   ",
      "                "
    ],
    [
      "                ",
      "      ab  cd    ",
      "      aeeeed    ",
      "      a yyAd    ",
      "      a    d    ",
      "      a    d    ",
      "      a    kllll",
      "      a    j    ",
      "      a    j B  ",
      "      a    rssss",
      "      a    d    ",
      "      a    d    ",
      "      a CCDd    ",
      "      aeeeed    ",
      "      ab  cd    ",
      "                "
    ],
    [
      "                ",
      "       abcd     ",
      "       aeed     ",
      "       a  d     ",
      "       a  d     ",
      "       a  d     ",
      "       aE d     ",
      "       a  klllll",
      "       a  rsssss",
      "       aB d     ",
      "       a  d     ",
      "       a  d     ",
      "       aFId     ",
      "       aeed     ",
      "       abcd     ",
      "                "
    ],
    [
      "                ",
      "        ad      ",
      "        ad      ",
      "        ad      ",
      "        ad      ",
      "        ad      ",
      "        ad      ",
      "        ad      ",
      "        ad      ",
      "        ad      ",
      "        ad      ",
      "        ad      ",
      "        ad      ",
      "        ad      ",
      "        ad      ",
      "                "
    ],
    [
      "                ",
      "                ",
      "                ",
      "                ",
      "                ",
      "                ",
      "                ",
      "                ",
      "                ",
      "                ",
      "                ",
      "                ",
      "                ",
      "                ",
      "                ",
      "                "
    ],
    [
      "                ",
      "                ",
      "                ",
      "                ",
      "                ",
      "                ",
      "                ",
      "                ",
      "                ",
      "                ",
      "                ",
      "                ",
      "                ",
      "                ",
      "                ",
      "                "
    ]
  ]
}