{
  "name": "multi_verticalschool_10_floor15",
  "refpalette": "deceasedcraft:multi_verticalschool_10/multi_verticalschool_10_floor15_palette",
  "xsize": 16,
  "zsize": 16,
  "slices": [
    [
      "                ",
      "                ",
      "                ",
      "                ",
      "                ",
      "                ",
      "                ",
      "                ",
      "aaaabaaaaaaaaaba",
      "  b    b    b   ",
      "  c    d    c   ",
      "                ",
      "                ",
      "                ",
      "                ",
      "                "
    ],
    [
      "                ",
      "                ",
      "                ",
      "                ",
      "                ",
      "                ",
      "                ",
      "                ",
      "  ~~         ~  ",
      "  a    a    a   ",
      "                ",
      "                ",
      "                ",
      "                ",
      "                ",
      "                "
    ],
    [
      "                ",
      "                ",
      "                ",
      "                ",
      "                ",
      "                ",
      "                ",
      "                ",
      "                ",
      "  e    e    e   ",
      "                ",
      "                ",
      "ffffffffffffffff",
      "                ",
      "gggggggggggggggg",
      "hhhhhhhhhhhhhhhg"
    ],
    [
      "                ",
      "                ",
      "                ",
      "                ",
      "                ",
      "                ",
      "                ",
      "                ",
      "  e    e        ",
      "  ee  eee  ee   ",
      "            e   ",
      "                ",
      "iiiiiiiiiiiiiiii",
      "jjjjjjjjjjjjjjjj",
      "kkkkkkkkkkkkkkkk",
      "llkllkklllllllll"
    ],
    [
      "                ",
      "                ",
      "                ",
      "                ",
      "                ",
      "                ",
      "                ",
      "                ",
      "  e    e    e   ",
      " eee  ee   eee  ",
      "  e    e    e   ",
      "                ",
      "mmmmmmmmmmmmmmmm",
      "jjjjjjjjjjjjjjjj",
      "nnnnnnnnnnnnnnnn",
      "                "
    ],
    [
      "                ",
      "                ",
      "                ",
      "                ",
      "                ",
      "                ",
      "                ",
      "                ",
      "       e    e   ",
      " eee   e   ee   ",
      "       e        ",
      "                ",
      "                ",
      "oooooooooooooooo",
      "                ",
      "                "
    ]
  ]
}