{
  "name": "multi_verticalschool_10_base2",
  "refpalette": "deceasedcraft:multi_verticalschool_10/multi_verticalschool_10_base2_palette",
  "xsize": 16,
  "zsize": 16,
  "slices": [
    [
      "vvvvvvvvvvvvvvvv",
      "vvvvvvvvvvvvvvvv",
      "vvvvvvvvvvvvvvvv",
      "vvvvvvvvvvvvvvvv",
      "vvvvvvvvvvvvvvvv",
      "vvvvvvvvvvvvvvvv",
      "vvvvvvvvvvvvvvvv",
      "vvvvvvvvvvvvvvvv",
      "vvvvvvvvvvvvvvvv",
      "vvvvvvvvvvvvvvvv",
      "vvvvvvvvvvvvvvvv",
      "vvvvvvvvvvvvvvvv",
      "vvvvvvvvvvvvvvvv",
      "vvvvvvvvvvvvvvvv",
      "vvvvvvvvvvvvvvvv",
      "vvvvvvvvvvvvvvvv"
    ],
    [
      "vvvvvvvvvvvvvvvv",
      "aaaaaaaaaaaaaaaa",
      "aaaaaaaaaaaabbba",
      "aaaaaaaaaaaaaaaa",
      "aaaaaaaaaaaaaaaa",
      "aaaaaaaaaaaaaaaa",
      "aaaaaaaaaaaaaaaa",
      "aaaaaaaaaaaaaaaa",
      "aaaaaaaaaaaaaaaa",
      "aaaaaaaaaaaaaaaa",
      "aaaaaaaaaaaaaaaa",
      "aaaaaaaaaaaaaaaa",
      "aaaaaaaaaaaaaaaa",
      "aaaaaaaaaaaaaaaa",
      "aaaaaaaaaaaaaaaa",
      "aaaaaaaaaaaaaaaa"
    ],
    [
      "vvvvvvvvvvvvvvvv",
      "aaaaaaaaaaaaaaaa",
      "aaaaaaaaaaaabbba",
      "aaaaaaaaaaaaaaaa",
      "aaaaaaaaaaaaaaaa",
      "aaaaaaaaaaaaaaaa",
      "aaaaaaaaaaaaaaaa",
      "aaaaaaaaaaaaaaaa",
      "aaaaaaaaaaaaaaaa",
      "aaaaaaaaaaaaaaaa",
      "aaaaaaaaaaaaaaaa",
      "aaaaaaaaaaaaaaaa",
      "aaaaaaaaaaaaaaaa",
      "aaaaaaaaaaaaaaaa",
      "aaaaaaaaaaaaaaaa",
      "aaaaaaaaaaaaaaaa"
    ],
    [
      "vvvvvvvvvvvvvvvv",
      "cccccccccccccccc",
      "bdddddddddddbbbd",
      "bdHHHHHHHHHHHHHH",
      "bdHHHHHHHHHHHHHH",
      "bdHHHHHHHHHHHHHH",
      "bdHHHHHHHHHHHHHH",
      "bdHHHHHHHHHHHHHH",
      "bdHHHHHHHHHHHHHH",
      "bdHHHHHHHHHHHHHH",
      "bdHHHHHHHHHHHHHH",
      "bdHHHHHHHHHHHHHH",
      "bdHHHHHHHHHHHHHH",
      "bdHHHHHHHHHHHHHH",
      "bdHHHHHHHHHHHHHH",
      "bdHHHHHHHHHHHHHH"
    ],
    [
      "vvvvvvvvvvvvvvvv",
      "cccccccccccccccc",
      "e           bbb ",
      "e               ",
      "e               ",
      "e               ",
      "e               ",
      "e               ",
      "e               ",
      "b               ",
      "b               ",
      "b               ",
      "b               ",
      "b               ",
      "b               ",
      "b        f  ghf "
    ],
    [
      "vvvvvvvvvvvvvvvv",
      "iiiiiiiiiiiiiiii",
      "            bbb ",
      "                ",
      "                ",
      "                ",
      "                ",
      "                ",
      "                ",
      "b               ",
      "b               ",
      "b               ",
      "b               ",
      "b               ",
      "b               ",
      "b               "
    ]
  ]
}