{
  "name": "multi_verticalschool_10_base1",
  "refpalette": "deceasedcraft:multi_verticalschool_10/multi_verticalschool_10_base1_palette",
  "xsize": 16,
  "zsize": 16,
  "slices": [
    [
      "vvvvvvvvvvvvvvvv",
      "aaaaaaaaaaaaaaaa",
      "            bbb ",
      "                ",
      "                ",
      "                ",
      "                ",
      "                ",
      "                ",
      "b               ",
      "b               ",
      "b               ",
      "b               ",
      "b               ",
      "b               ",
      "b               "
    ],
    [
      "vvvvvvvvvvvvvvvv",
      "aaaaaaaaaaaaaaaa",
      "            bbb ",
      "                ",
      "                ",
      "                ",
      "                ",
      "                ",
      "                ",
      "b               ",
      "b               ",
      "b               ",
      "b               ",
      "b               ",
      "b               ",
      "b               "
    ],
    [
      "vvvvvvvvvvvvvvvv",
      "aaaaaaaaaaaaaaaa",
      "            bbb ",
      "                ",
      "                ",
      "                ",
      "                ",
      "                ",
      "                ",
      "b               ",
      "b               ",
      "b               ",
      "b               ",
      "b               ",
      "b               ",
      "b               "
    ],
    [
      "vvvvvvvvvvvvvvvv",
      "aaaaaaaaaaaaaaaa",
      "            bbb ",
      "                ",
      "                ",
      "                ",
      "                ",
      "                ",
      "                ",
      "b               ",
      "b               ",
      "b               ",
      "b               ",
      "b               ",
      "b               ",
      "b               "
    ],
    [
      "vvvvvvvvvvvvvvvv",
      "aaaaaaaaaaaaaaaa",
      "c           bbb ",
      "c               ",
      "c               ",
      "c               ",
      "c               ",
      "c               ",
      "c               ",
      "b               ",
      "b               ",
      "bccccccccc      ",
      "b         cc    ",
      "b           c   ",
      "b           c   ",
      "b            c  "
    ],
    [
      "vvvvvvvvvvvvvvvv",
      "bddddddddddddddd",
      "beeeeeeeeeeebbbe",
      "beeeeeeeeeeeeeee",
      "beeeeeeeeeeeeeee",
      "beeeeeeeeeeeeeee",
      "beeeeeeeeeeeeeee",
      "beeeeeeeeeeeeeee",
      "beeeeeeeeeeeeeee",
      "beeeeeeeeeeeeeee",
      "beeeeeeeeeeeeeee",
      "bbbbbbbbbbeeeeee",
      "b         bbeeee",
      "b           beee",
      "b           beee",
      "b            bee"
    ]
  ]
}