{
  "name": "multi_verticalschool_10_floor9",
  "refpalette": "deceasedcraft:multi_verticalschool_10/multi_verticalschool_10_floor9_palette",
  "xsize": 16,
  "zsize": 16,
  "slices": [
    [
      "                ",
      "                ",
      "                ",
      "                ",
      "                ",
      "                ",
      "                ",
      "                ",
      "                ",
      "                ",
      "                ",
      "                ",
      " aaaaaaaaaaaaaaa",
      "abbbbbbbbbbbbbbb",
      "bbccccccccccde!b",
      "ccccccccccccdeee"
    ],
    [
      "                ",
      "                ",
      "                ",
      "                ",
      "                ",
      "                ",
      "                ",
      "                ",
      "                ",
      "                ",
      "                ",
      "                ",
      " aaaaaaaaaaaaaaa",
      "af ghhhhhhi ffff",
      "ff  j j  j  klmf",
      "no      j   k   "
    ],
    [
      "                ",
      "                ",
      "                ",
      "                ",
      "                ",
      "                ",
      "                ",
      "                ",
      "                ",
      "                ",
      "                ",
      "                ",
      " aaaaaaaaaaaaaaa",
      "afpqr s  tuwffff",
      "ff             f",
      "               x"
    ],
    [
      "                ",
      "                ",
      "                ",
      "                ",
      "                ",
      "                ",
      "                ",
      "                ",
      "                ",
      "                ",
      "                ",
      "                ",
      " aaaaaaaaaaaaaaa",
      "afyyyyyyyyyyffff",
      "ff            xf",
      "              x "
    ],
    [
      "                ",
      "                ",
      "                ",
      "                ",
      "                ",
      "                ",
      "                ",
      "                ",
      "                ",
      "                ",
      "                ",
      "                ",
      " aaaaaaaaaaaaaaa",
      "afffffffffffffff",
      "ffAAAAAAAAAA x f",
      "AAAAAAAAAAAA x  "
    ],
    [
      "                ",
      "                ",
      "                ",
      "                ",
      "                ",
      "                ",
      "                ",
      "                ",
      "                ",
      "                ",
      "                ",
      "                ",
      " aaaaaaaaaaaaaaa",
      "addddddddddddddd",
      "dxxxxxxxxxxxx  d",
      "xxxxxxxxxxxxx   "
    ]
  ]
}