{
  "name": "multi_verticalschool_10_ground",
  "refpalette": "deceasedcraft:multi_verticalschool_10/multi_verticalschool_10_ground_palette",
  "xsize": 16,
  "zsize": 16,
  "slices": [
    [
      "HHHHHHHHHHHHHHHH",
      "HHHHHHHHHHHHHHHH",
      "HHHHHHHHHHHHHHHH",
      "HHHHHHHHHHHHHHHH",
      "aaaaaaaaaaaaaaaa",
      "bbbbbbbbbbbbbbbb",
      "bbbbbbbbbbbbbbbb",
      "bbbbbbbbbbbbbbbb",
      "cccccccccccccccc",
      "cddddddddddddddd",
      "cddddddddddddddd",
      "ccccccccccdddddd",
      "c         ccdddd",
      "c           cddd",
      "c           cddd",
      "c            cdd"
    ],
    [
      "                ",
      "                ",
      "                ",
      "                ",
      "                ",
      "                ",
      "                ",
      "eeeeeeeeeeeeeeee",
      "ffffffffffffffff",
      "fffffffffffffffg",
      "fffffffffffffffg",
      "fffffffffffffffg",
      "fffffffffffffffg",
      "fffffffffffffffg",
      "fffffffffffffffg",
      "fhhhhhhhhhhhhffg"
    ],
    [
      "                ",
      "                ",
      "                ",
      "                ",
      "                ",
      "                ",
      "                ",
      "iiiiiiiiiiiiiiii",
      "ccccccccccccccfj",
      "kkkkkkkkkkkkkl  ",
      "kkkkkkkkkkkkkl  ",
      "kkkkkkkkkkkkkl  ",
      "kkkkkkkkkkkkkl  ",
      "kkkkkkkkkkkkkl  ",
      "kkkkkkkkkkkkkl  ",
      "kkkkkkkkkkkkkl  "
    ],
    [
      "                ",
      "                ",
      "                ",
      "                ",
      "                ",
      "                ",
      "                ",
      "iiiiiiiiiiiiiiii",
      "ccccccccccccccfj",
      "mn o pmn o      ",
      "                ",
      "                ",
      "                ",
      "                ",
      "                ",
      "                "
    ],
    [
      "                ",
      "                ",
      "                ",
      "                ",
      "                ",
      "                ",
      "                ",
      "iiiiiiiiiiiiiiii",
      "ccccccccccccccfj",
      "   q     q      ",
      "                ",
      "                ",
      "                ",
      "                ",
      "                ",
      "                "
    ],
    [
      "                ",
      "                ",
      "                ",
      "                ",
      "                ",
      "                ",
      "                ",
      "iiiiiiiiiiiiiiii",
      "ccccccccccccccfj",
      "   r     r      ",
      "                ",
      "                ",
      "                ",
      "                ",
      "                ",
      "                "
    ]
  ]
}