{
  "name": "multi_verticalschool_10_floor13",
  "refpalette": "deceasedcraft:multi_verticalschool_10/multi_verticalschool_10_floor13_palette",
  "xsize": 16,
  "zsize": 16,
  "slices": [
    [
      "                ",
      "                ",
      "                ",
      "                ",
      "                ",
      "                ",
      "                ",
      "                ",
      "                ",
      "                ",
      "                ",
      "                ",
      "                ",
      "                ",
      "                ",
      "                "
    ],
    [
      "                ",
      "                ",
      "                ",
      "                ",
      "                ",
      "                ",
      "                ",
      "                ",
      "                ",
      "                ",
      "                ",
      "                ",
      "                ",
      "                ",
      "                ",
      "                "
    ],
    [
      "                ",
      "                ",
      "                ",
      "                ",
      "                ",
      "                ",
      "aaaaaaaaaaaaaaaa",
      "                ",
      "bbbbbbbbbbbbbbbb",
      "cccccccccccccccc",
      "bbbbbbbbbbbbbbbb",
      "bbbbbbbbbbbbbbbb",
      "bbbbbbbbbbbbbbbb",
      "bbbbbbbbbbbbbbbb",
      "bbbbbbbbbbbbbbbb",
      "bbbbbbbbbbbbbbbb"
    ],
    [
      "                ",
      "                ",
      "                ",
      "                ",
      "                ",
      "dddddddddddddddd",
      "eeeeeeeeeeeeeeee",
      "ffffffffffffffff",
      "ffffffffffffffff",
      "ffffffffffffffff",
      "ffffffffffffffff",
      "ffffffffffffffff",
      "ffffffffffffffff",
      "ffffffffffffffff",
      "ffffffffffffffff",
      "ffffffffffffffff"
    ],
    [
      "                ",
      "                ",
      "                ",
      "                ",
      "                ",
      "dddddddddddddddd",
      "eeeeeeeeeeeeeeee",
      "                ",
      "                ",
      " ghhhhhi j  k  l",
      "         m  l  !",
      "         l  m  m",
      "         k  m  k",
      "         l  j  l",
      "                ",
      "                "
    ],
    [
      "                ",
      "                ",
      "                ",
      "                ",
      "                ",
      "dddddddddddddddd",
      "nneeeeennnneeeee",
      "                ",
      "                ",
      "    o p  l  m  k",
      "         j  j  m",
      "         q  r  j",
      "         j  j  m",
      "         k  j  k",
      "                ",
      "                "
    ]
  ]
}