{
  "name": "multi_verticalschool_10_floor21",
  "refpalette": "deceasedcraft:multi_verticalschool_10/multi_verticalschool_10_floor21_palette",
  "xsize": 16,
  "zsize": 16,
  "slices": [
    [
      "                ",
      "                ",
      "                ",
      "                ",
      "                ",
      "                ",
      "                ",
      "                ",
      "                ",
      "                ",
      "                ",
      "                ",
      "                ",
      "aaaaaaaaaaaaaaaa",
      " b  b     b  b  ",
      "                "
    ],
    [
      "                ",
      "                ",
      "                ",
      "                ",
      "                ",
      "                ",
      "                ",
      "                ",
      "                ",
      "                ",
      "                ",
      "                ",
      "                ",
      "aaaaaaaaaaaaaaaa",
      "                ",
      "                "
    ],
    [
      "                ",
      "                ",
      "                ",
      "                ",
      "                ",
      "                ",
      "                ",
      "                ",
      "                ",
      "                ",
      "                ",
      "                ",
      "cccccccccccccccc",
      "aaaaaaaaaaaaaaaa",
      "dddddddddddddddd",
      "dddddddddddddddd"
    ],
    [
      "                ",
      "                ",
      "                ",
      "                ",
      "                ",
      "                ",
      "                ",
      "                ",
      "                ",
      "                ",
      "                ",
      "                ",
      "eeeeeeeeeeeeeeee",
      "ffffffffffffffff",
      "gggggggggggggggg",
      "gggggggggggggggg"
    ],
    [
      "                ",
      "                ",
      "                ",
      "                ",
      "                ",
      "                ",
      "                ",
      "                ",
      "                ",
      "                ",
      "                ",
      "                ",
      "hhhhhhhhhhhhhhhh",
      "ffffffffffffffff",
      "eeeeeeeeeeeeeeee",
      "eeeeeeeeeeeeeeee"
    ],
    [
      "                ",
      "                ",
      "                ",
      "                ",
      "                ",
      "                ",
      "                ",
      "                ",
      "                ",
      "                ",
      "                ",
      "                ",
      "                ",
      "                ",
      "                ",
      "                "
    ]
  ]
}