{
  "name": "multi_verticalschool_10_floor1",
  "refpalette": "deceasedcraft:multi_verticalschool_10/multi_verticalschool_10_floor1_palette",
  "xsize": 16,
  "zsize": 16,
  "slices": [
    [
      "                ",
      "                ",
      "                ",
      "                ",
      "                ",
      "                ",
      "                ",
      "aaaaaaaaaaaaaaaa",
      "bbbbbbbbbbbbbbcd",
      "                ",
      "                ",
      "                ",
      "                ",
      "                ",
      "                ",
      "                "
    ],
    [
      "                ",
      "                ",
      "                ",
      "                ",
      "                ",
      "                ",
      "                ",
      "aaaaaaaaaaaaaaaa",
      "bbbbbbbbbbbbbbcc",
      "eeeeeeeeeeeeeecf",
      "eeeeeeeeeeeeeecf",
      "eeeeeeeeeeeeeecf",
      "geeeeegeeeeegecf",
      "geeeeegeeeeegecf",
      "eeeeeeeeeeeeeecf",
      "eeeeeeeeeeeeeecf"
    ],
    [
      "                ",
      "                ",
      "                ",
      "                ",
      "                ",
      "                ",
      "                ",
      "aaaaaaaaaaaaaaaa",
      "bbbbbbbbbbbbbbbb",
      "hhhhhhhhhhhhhbii",
      "hhhhhhhhhhhhhbjj",
      "hhhhhhhhhhhhhbkj",
      "hhhhhhhhhhhhhbjj",
      "hhhhhhhhhhhhhbjj",
      "hhhhhhhhhhhhhbkk",
      "hhhhhhhhhhhhhbjk"
    ],
    [
      "                ",
      "                ",
      "                ",
      "                ",
      "                ",
      "                ",
      "                ",
      "llllllllllllllll",
      "mmmmmmmmmmmmmmmm",
      "nop  nop  nop qq",
      "                ",
      "                ",
      "                ",
      "                ",
      "                ",
      "                "
    ],
    [
      "                ",
      "                ",
      "                ",
      "                ",
      "                ",
      "                ",
      "                ",
      "                ",
      "                ",
      "              rr",
      "                ",
      "                ",
      "                ",
      "                ",
      "                ",
      "                "
    ],
    [
      "                ",
      "                ",
      "                ",
      "                ",
      "                ",
      "                ",
      "                ",
      "                ",
      "                ",
      "                ",
      "                ",
      "                ",
      "                ",
      "                ",
      "                ",
      "                "
    ]
  ]
}