{
  "name": "multi_nuclearpowerplant_30_base7",
  "refpalette": "deceasedcraft:multi_nuclearpowerplant_30/multi_nuclearpowerplant_30_base7_palette",
  "xsize": 16,
  "zsize": 16,
  "slices": [
    [
      "                ",
      "                ",
      "a               ",
      "                ",
      "                ",
      "                ",
      "                ",
      "                ",
      "                ",
      "                ",
      "                ",
      "                ",
      "       a    a bb",
      "                ",
      "        cd d    ",
      "         ede    "
    ],
    [
      "                ",
      "                ",
      "a               ",
      "                ",
      "                ",
      "                ",
      "                ",
      "                ",
      "                ",
      "                ",
      "                ",
      "                ",
      "       a    a bb",
      "                ",
      "                ",
      "                "
    ],
    [
      "                ",
      "                ",
      "a               ",
      "                ",
      "                ",
      "                ",
      "                ",
      "                ",
      "                ",
      "                ",
      "                ",
      "                ",
      "       a    a bb",
      "       f    f   ",
      "                ",
      "                "
    ],
    [
      "                ",
      "                ",
      "a               ",
      "                ",
      "                ",
      "                ",
      "                ",
      "                ",
      "                ",
      "                ",
      "                ",
      "            g   ",
      "       a    a bb",
      "       aaaaaaaaa",
      "       a    a   ",
      "       a    a   "
    ],
    [
      "                ",
      "                ",
      "a               ",
      "                ",
      "                ",
      "                ",
      "                ",
      "                ",
      "                ",
      "                ",
      "                ",
      "                ",
      "            a bb",
      "        hhhhiihh",
      "        hhhjjhjh",
      "        hjjdjjhh"
    ],
    [
      "kkkkkkkk     kkk",
      "kkkkkkkk     kkk",
      "akkkkkkk     kkk",
      "kkkkkkkk     kkk",
      "kkkkkkkk     kkk",
      "kkkkkkkkkkkkkkkk",
      "kkkkkkkkkkkkkkkk",
      "kkkkkkkkkkkkkkkk",
      "kkkkkkkkkkkkkkkk",
      "kkkkkkkkkkkkkkkk",
      "k               ",
      "k               ",
      "k           a  b",
      "k       elmld ll",
      "k       ln     o",
      "k      al       "
    ]
  ]
}