{
  "name": "multi_nuclearpowerplant_30_ground",
  "refpalette": "deceasedcraft:multi_nuclearpowerplant_30/multi_nuclearpowerplant_30_ground_palette",
  "xsize": 16,
  "zsize": 16,
  "slices": [
    [
      "             abc",
      "              ab",
      "              ab",
      "               a",
      "               a",
      "               a",
      "                ",
      "        d       ",
      "                ",
      "                ",
      "                ",
      "               d",
      "                ",
      "                ",
      "                ",
      "                "
    ],
    [
      "      eeeeeeeeee",
      "      eeeeeeeeee",
      "       eeeeeeeee",
      "       eeeeeeeee",
      "d      eeeeeeeee",
      "       eeeeeeeee",
      "        feeeeeee",
      "        fffeeeee",
      "          fffeee",
      "            ffee",
      "             fff",
      "               f",
      "                ",
      "                ",
      "                ",
      "                "
    ],
    [
      "eeeeeeezzzzzzzzz",
      "eeeeeeeezzzzzzzz",
      "eeeeeeeezzzzzzzz",
      "feeeeeeezzzzzzzz",
      "ffffeeeezzzzzzzz",
      "   ffffezzzzzzzz",
      "      fffzzzzzzz",
      "        fffzzzzz",
      "          fffzzz",
      "            ffzz",
      "             fff",
      "               f",
      "                ",
      "                ",
      "                ",
      "                "
    ],
    [
      "zzzzzzz         ",
      "zzzzzzzz  g     ",
      "zzzzzzzz      gh",
      "fzzzzzzzi   e   ",
      "jfffzzzz        ",
      "   ffffz        ",
      "      ffk       ",
      "        kkk     ",
      "          kk   g",
      "                ",
      "                ",
      "                ",
      "                ",
      "                ",
      "                ",
      "                "
    ],
    [
      "                ",
      "                ",
      "                ",
      "k               ",
      "jkkk            ",
      "   k            ",
      "                ",
      "                ",
      "                ",
      "                ",
      "                ",
      "                ",
      "                ",
      "                ",
      "                ",
      "                "
    ],
    [
      "                ",
      "                ",
      "                ",
      "                ",
      "                ",
      "                ",
      "                ",
      "                ",
      "                ",
      "                ",
      "                ",
      "                ",
      "                ",
      "                ",
      "                ",
      "                "
    ]
  ]
}