{
  "name": "multi_nuclearpowerplant_30_base10",
  "refpalette": "deceasedcraft:multi_nuclearpowerplant_30/multi_nuclearpowerplant_30_base10_palette",
  "xsize": 16,
  "zsize": 16,
  "slices": [
    [
      "           abc  ",
      "           abc  ",
      "         dddbc  ",
      "         efdbc  ",
      "         dgdbc  ",
      "          habc  ",
      "           abc  ",
      "           abc  ",
      "           abi  ",
      "           abc  ",
      "           abc  ",
      "           abj  ",
      "           abc  ",
      "           abc  ",
      "           abc  ",
      "           abc  "
    ],
    [
      "           ak   ",
      "           ak   ",
      "         dddk   ",
      "         efdk   ",
      "         dddk   ",
      "           ak   ",
      "           ak   ",
      "           ak   ",
      "           aklm ",
      "           ak   ",
      "           ak   ",
      "           ak   ",
      "           ak   ",
      "           ak   ",
      "           ak   ",
      "           ak   "
    ],
    [
      "           ak   ",
      "           ak   ",
      "         dddk   ",
      "         efdk   ",
      "         dddk   ",
      "           ak   ",
      "           ak   ",
      "           ak   ",
      "           akl  ",
      "           ak   ",
      "           ak   ",
      "           ak   ",
      "           ak   ",
      "           ak   ",
      "           ak   ",
      "           ak   "
    ],
    [
      "           ak   ",
      "           ak   ",
      "         dddk   ",
      "         dfdk   ",
      "         dddk   ",
      "           ak   ",
      "           ak   ",
      "           ak   ",
      "           akl  ",
      "           ak   ",
      "           ak   ",
      "           ak   ",
      "           ak   ",
      "           ak   ",
      "           ak   ",
      "           ak   "
    ],
    [
      "           ak   ",
      "          hak   ",
      "         dgdk   ",
      "        n fdk   ",
      "         dddk   ",
      "           ak   ",
      "           ak   ",
      "           ak   ",
      "           akl  ",
      "           ak   ",
      "           ak   ",
      "           ak   ",
      "           ak   ",
      "           ak   ",
      "           ak   ",
      "           ak   "
    ],
    [
      "           ak   ",
      "           ak   ",
      "         dddk   ",
      "         dddk   ",
      "         dddk   ",
      "           ak   ",
      "           ak   ",
      "           ak   ",
      "           akl  ",
      "           ak   ",
      "           ak   ",
      "           ak   ",
      "           ak   ",
      "           ak   ",
      "           ak   ",
      "           ak   "
    ]
  ]
}