{
  "name": "multi_nuclearpowerplant_30_base3",
  "refpalette": "deceasedcraft:multi_nuclearpowerplant_30/multi_nuclearpowerplant_30_base3_palette",
  "xsize": 16,
  "zsize": 16,
  "slices": [
    [
      "abbbbbbbbbbbbbbb",
      "abbbbbbbbbbbbbbb",
      "cabbbbbbbbbbbbbb",
      "dabbbbbbbbbbbbbb",
      "dabbbbbbbbbbbbbb",
      "ddabbbbbbbbbbbbb",
      " dabbbbbbbbbbbbb",
      " dabbbbbbbbbbbbb",
      " dabbbbbbbbbbbbb",
      " ddabbbbbbbbbbbb",
      "  dabbbbbbbbbbbb",
      "  dabbbbbbbbbbbb",
      "  dabbbbbbbbbbbb",
      "  dabbbbbbbbbbbb",
      "  dabbbbbbbbbbbb",
      "  dabbbbbbbbbbbb"
    ],
    [
      "e   fghijkjil   ",
      "e   fggggggggg  ",
      "me  fffffffffff ",
      " e   nop   nopq ",
      " e  rsotr usot  ",
      "  e wsot  xsoty ",
      "  e  sot  Asot  ",
      "  e  BoC  DBoC  ",
      "  e  EEE F EEE  ",
      "   e  A         ",
      "   e    III   II",
      "   e    nopJ  no",
      "   e  F sot   so",
      "   e x  sot  xso",
      "   e    sotK  so",
      "   e    BoC   Bo"
    ],
    [
      "e   LgMNO PQR   ",
      "e   Lggggggggg  ",
      "me  LLLLLLLLLLL ",
      " e   STU   VWX  ",
      " e   YTZ   AW0  ",
      "  e  1T2   1W2  ",
      "  e  VT3   4W5  ",
      "  e  UT3   !W   ",
      "  e             ",
      "   e            ",
      "   e            ",
      "   e    6TZ   7T",
      "   e    ST0   8T",
      "   e    1T2   1T",
      "   e     T9    T",
      "   e    #T9   $T"
    ],
    [
      "e   Lg          ",
      "e   Lggggggggg  ",
      "me  LLLLLLLLLLL ",
      " e              ",
      " e              ",
      "  e             ",
      "  e             ",
      "  e             ",
      "  e             ",
      "   e            ",
      "   e            ",
      "   e            ",
      "   e            ",
      "   e            ",
      "   e            ",
      "   e            "
    ],
    [
      "e   %^          ",
      "e   %^^^^^^^^^  ",
      "me  %%%%%%%%%%% ",
      " e              ",
      " e              ",
      "  e             ",
      "  e             ",
      "  e             ",
      "  e             ",
      "   e            ",
      "   e            ",
      "   e            ",
      "   e            ",
      "   e            ",
      "   e            ",
      "   e            "
    ],
    [
      "e               ",
      "e               ",
      "me              ",
      " e              ",
      " e              ",
      "  e             ",
      "  e             ",
      "  e             ",
      "  e             ",
      "   e            ",
      "   e            ",
      "   e            ",
      "   e            ",
      "   e            ",
      "   e            ",
      "   e            "
    ]
  ]
}