{
  "name": "multi_nuclearpowerplant_30_base2",
  "refpalette": "deceasedcraft:multi_nuclearpowerplant_30/multi_nuclearpowerplant_30_base2_palette",
  "xsize": 16,
  "zsize": 16,
  "slices": [
    [
      "a               ",
      "a               ",
      "ba              ",
      " a              ",
      " a              ",
      "  a             ",
      "  a             ",
      "  a             ",
      "  a             ",
      "   a            ",
      "   a            ",
      "   a            ",
      "   a            ",
      "   a            ",
      "   a            ",
      "   a            "
    ],
    [
      "a               ",
      "a               ",
      "ba              ",
      " a              ",
      " a              ",
      "  a             ",
      "  a             ",
      "  a             ",
      "  a             ",
      "   a            ",
      "   a            ",
      "   a            ",
      "   a            ",
      "   a            ",
      "   a            ",
      "   a            "
    ],
    [
      "a               ",
      "a               ",
      "ba              ",
      " a              ",
      " a              ",
      "  a             ",
      "  a             ",
      "  a             ",
      "  a             ",
      "   a            ",
      "   a            ",
      "   a            ",
      "   a            ",
      "   a            ",
      "   a            ",
      "   a            "
    ],
    [
      "a               ",
      "a               ",
      "ba              ",
      " a              ",
      " a              ",
      "  a             ",
      "  a             ",
      "  a             ",
      "  a             ",
      "   a            ",
      "   a            ",
      "   a            ",
      "   a            ",
      "   a            ",
      "   a            ",
      "   a            "
    ],
    [
      "c               ",
      "c               ",
      "dc              ",
      "dc              ",
      "dc              ",
      "ddc             ",
      " dc             ",
      " dc             ",
      " dc             ",
      " ddc            ",
      "  dc            ",
      "  dc            ",
      "  dc            ",
      "  dc            ",
      "  dc            ",
      "  dc            "
    ],
    [
      "eeeeeeeeeeeeeeee",
      "eeeeeeeeeeeeeeee",
      "deeefffeeeefffee",
      "deeeeeeeeeeeeeee",
      "deeeeeeeeeeeeeee",
      "ddeeeeeeeeeeeeee",
      "gdeeeeeeeeeeeeee",
      "gdeeeeeeeeeeeeee",
      "gdeeeeeeeeeeeeee",
      "gddeeefffeeeeeff",
      "ggdeeeeeeeeeeeee",
      "ggdeeeeeeeeeeeee",
      "ggdeeeeeeeeeeeee",
      "ggdeeeeeeeeeeeee",
      "ggdeeeeeeeeeeeee",
      "ggdeeeeeeeeeeeee"
    ]
  ]
}