{
  "name": "multi_nuclearpowerplant_30_base6",
  "refpalette": "deceasedcraft:multi_nuclearpowerplant_30/multi_nuclearpowerplant_30_base6_palette",
  "xsize": 16,
  "zsize": 16,
  "slices": [
    [
      "aaaaaaaabbbbbaaa",
      "aaaaaaaabcccbaaa",
      "daaaaaaabcecbaaa",
      "aaaaaaaabcccbaaa",
      "aaafaaaabbbbbaaa",
      "aaaaaagaaaaaaaaa",
      "aahaaaaaaaaaaaaa",
      "aaiaaaaaaaaaaaaa",
      "aaaaaaaaaaaaaaaa",
      "aaaaafaaaaaaaaaa",
      "abbbbbbbbbbbbbbb",
      "abcccccccccccccc",
      "abc         j  k",
      "abc     lm     m",
      "abc     m       ",
      "abc    nm       "
    ],
    [
      "                ",
      "         jjj    ",
      "j  o     j j    ",
      "p   qm   jjj r  ",
      "    s  t        ",
      " u wx  x        ",
      " w  xw  m       ",
      " m xtxx         ",
      "   w   w        ",
      "      m  y      ",
      "          y     ",
      "  AAAAAAAAAAAAAA",
      "  A        BjC k",
      "  A            m",
      "  A             ",
      "  AD    mx     x"
    ],
    [
      "                ",
      "         r r    ",
      "j         E     ",
      "     F   III    ",
      "          J     ",
      "          J     ",
      "          J     ",
      "          J     ",
      "          J     ",
      "          K     ",
      "                ",
      "   LLLM     LLLL",
      "  N         O kk",
      "  N            m",
      "  N             ",
      "  N             "
    ],
    [
      "                ",
      "         I      ",
      "j         P     ",
      "         I I    ",
      "         Q R    ",
      "         Q R    ",
      "         Q!R    ",
      "         Q R    ",
      "           R    ",
      "           R    ",
      "                ",
      "                ",
      "            O kk",
      "              mm",
      "                ",
      "        m       "
    ],
    [
      "                ",
      "         I~     ",
      "j        eSe    ",
      "         III    ",
      "          y     ",
      "          y     ",
      "          y     ",
      "          y     ",
      "          y     ",
      "                ",
      "                ",
      "                ",
      "              kk",
      "            TTUU",
      "        V     mm",
      "        V      m"
    ],
    [
      "                ",
      "         IeW    ",
      "j        eSe    ",
      "         III    ",
      "                ",
      "                ",
      "                ",
      "                ",
      "                ",
      "                ",
      "                ",
      "                ",
      "                ",
      "              XX",
      "               Y",
      "               Y"
    ]
  ]
}