{
  "name": "multi_nuclearpowerplant_30_base12",
  "refpalette": "deceasedcraft:multi_nuclearpowerplant_30/multi_nuclearpowerplant_30_base12_palette",
  "xsize": 16,
  "zsize": 16,
  "slices": [
    [
      "aaaaaaaaaaaaaaaa",
      "aaaaaaaaaaaaaaaa",
      "aaaaaaaaaaaaaaaa",
      "aaaaaaaaaaaaaaaa",
      "aaaaaaaaaaaaaaaa",
      "aaaaaaaaaaaaaaaa",
      "aaaaaaaaaaaaaaaa",
      "aaaaaaaaaaaaaaaa",
      "aaaaaaaaaaaaaaaa",
      "aaaaaaaaaaaaaaaa",
      "aaaaaaaaaaaaaaaa",
      "aaaaaaaaaaaaaaaa",
      "aaaaaaaaaaaaaaaa",
      "aaaaaaaaaaaaaaaa",
      "aaaaaaaaaaaaaaaa",
      "aaaaaaaaaaaaaaaa"
    ],
    [
      "bbbbbbbbbbbbbbbb",
      "bbbbbbbbbbbbbbbb",
      "bbbbbbbbbbbbbbbb",
      "bbbbbbbbbbbbbbbb",
      "bbbbbbbbbbbbbbbb",
      "bbbbbbbbbbbbbbbb",
      "bbbbbbbbbbbbbbbb",
      "bbbbbbbbbbbbbbbb",
      "bbbbbbbbbbbbbbbb",
      "bbbbbbbbbbbbbbbb",
      "bbbbbbbbbbbbbbbb",
      "bbbbbbbbbbbbbbbb",
      "bbbbbbbbbbbbbbbb",
      "bbbbbbbbbbbbbbbb",
      "bbbbbbbbbbbbbbbb",
      "bbbbbbbbbbbbbbbb"
    ],
    [
      "cccccccccccde===",
      "ccccccccffffe===",
      "ccccccccffffe===",
      "ccccccccff fe===",
      "ccccccccffffe===",
      "ccccccccffffe===",
      "cccccccccccde===",
      "cccccccccccde===",
      "ccccccccccc e===",
      "ccccccccccc e===",
      "ccccccccccc e===",
      "ccccccccccc e===",
      "ccccccccccc e===",
      "ccccccccccc e===",
      "ccccccccccc e===",
      "ccccccccccc e==="
    ],
    [
      "           dgbhh",
      "           dgbhh",
      "         fffgbhh",
      "         fifgbhh",
      "         fffgbhh",
      "           dgbhh",
      "           djbhh",
      "           djbhh",
      "           @jbhh",
      "           @jbhh",
      "           @jbhh",
      "           @jbhh",
      "           @jbhh",
      "           @kbhh",
      "           @jbhh",
      "           @jbhh"
    ],
    [
      "           dgbll",
      "           dgbll",
      "         mmmgbll",
      "         mlmgbll",
      "         mmmgbll",
      "           dgbll",
      "           djbll",
      "           d bll",
      "           @ nll",
      "           @ bll",
      "           @ bll",
      "           @ bll",
      "           @ bll",
      "           @obll",
      "           @pbll",
      "           @pbll"
    ],
    [
      "           dgbll",
      "           dgbll",
      "         mmmgbll",
      "         qlmgbll",
      "         mmmgbll",
      "           dgbll",
      "           djbll",
      "           d bll",
      "           @ nll",
      "           @ bll",
      "           @ bll",
      "           @ bll",
      "           @ bll",
      "           @obll",
      "           @pbll",
      "           @pbll"
    ]
  ]
}