{
  "name": "multi_nuclearpowerplant_30_base9",
  "refpalette": "deceasedcraft:multi_nuclearpowerplant_30/multi_nuclearpowerplant_30_base9_palette",
  "xsize": 16,
  "zsize": 16,
  "slices": [
    [
      "           ab   ",
      "           ab   ",
      "         ccab   ",
      "         cdab   ",
      "         ccab   ",
      "           ab   ",
      "           ab   ",
      "           ab   ",
      "           abe  ",
      "           ab   ",
      "           ab   ",
      "           ab   ",
      "           ab   ",
      "           ab   ",
      "           ab   ",
      "           ab   "
    ],
    [
      "           ab   ",
      "           ab   ",
      "           ab   ",
      "           ab   ",
      "           ab   ",
      "           ab   ",
      "           ab   ",
      "           ab   ",
      "           abe  ",
      "           ab   ",
      "           ab   ",
      "           ab   ",
      "           ab   ",
      "           ab   ",
      "           ab   ",
      "           ab   "
    ],
    [
      "           ab   ",
      "           ab   ",
      "           ab   ",
      "           ab   ",
      "           ab   ",
      "           ab   ",
      "           ab   ",
      "           ab   ",
      "           abe  ",
      "           ab   ",
      "           ab   ",
      "           ab   ",
      "           ab   ",
      "           ab   ",
      "           ab   ",
      "           ab   "
    ],
    [
      "           ab   ",
      "           ab   ",
      "           ab   ",
      "           ab   ",
      "           ab   ",
      "           ab   ",
      "           ab   ",
      "           ab   ",
      "           abefg",
      "           ab   ",
      "           ab   ",
      "           ab   ",
      "           ab   ",
      "           ab   ",
      "           ab   ",
      "           ab   "
    ],
    [
      "           ab   ",
      "           ab   ",
      "           ab   ",
      "           ab   ",
      "           ab   ",
      "           ab   ",
      "           ab   ",
      "           ab   ",
      "           abeee",
      "           ab   ",
      "           ab   ",
      "           ab   ",
      "           ab   ",
      "           ab   ",
      "           ab   ",
      "           ab   "
    ],
    [
      "           ab   ",
      "           ab   ",
      "           ab   ",
      "           ab   ",
      "           ab   ",
      "           ab   ",
      "           ab   ",
      "           ab   ",
      "           abeh ",
      "           ab   ",
      "           ab   ",
      "           ab   ",
      "           ab   ",
      "           ab   ",
      "           ab   ",
      "           ab   "
    ]
  ]
}