{
  "name": "multi_nuclearpowerplant_30_base8",
  "refpalette": "deceasedcraft:multi_nuclearpowerplant_30/multi_nuclearpowerplant_30_base8_palette",
  "xsize": 16,
  "zsize": 16,
  "slices": [
    [
      "aaaaaaaaab cd   ",
      "aaaaaaaaab cd   ",
      "aaaaaaaaab cd   ",
      "aaaaaaaaab cd   ",
      "aaaaaaaaab cd   ",
      "aaaaaaaaab cd   ",
      "aaaaaaaaab cd   ",
      "aaaaaaaaab cd   ",
      "aaaaaaaaab cde  ",
      "aaaaaaaaab cd   ",
      "aaaaaaaaab cd   ",
      "aaaaaaaaab cd   ",
      "aaaaaaaaab cd   ",
      "aaaaaaaaab cd   ",
      "aaaaaaaaab cd   ",
      "aaaaaaaaab cd   "
    ],
    [
      "=========fgfhiii",
      "=========fgfhiii",
      "=========fgfhiii",
      "=========fgfhiii",
      "=========fgfhiii",
      "=========fgfhiii",
      "=========fgfhiii",
      "=========fgfhiii",
      "=========fgfhjii",
      "=========fgfhiii",
      "=========fgfhiii",
      "=========fgfhiii",
      "=========fgfhiii",
      "=========fgfhiii",
      "=========fgfhiii",
      "=========fgfhiii"
    ],
    [
      "kkkkkkkkkflfdkkk",
      "kkkkkkkkkflfdkkk",
      "kkkkkkkkkflfdkkk",
      "kkkkkkkkkflfdkkk",
      "kkkkkkkkkflfdkkk",
      "kkkkkkkkkflfdkkk",
      "kkkkkkkkkflfdkkk",
      "kkkkkkkkkflfdkkk",
      "kkkkkkkkkflfdkkk",
      "kkkkkkkkkflfdkkk",
      "kkkkkkkkkflfdkkk",
      "kkkkkkkkkflfdkkk",
      "kkkkkkkkkflfdkkk",
      "kkkkkkkkkflfdkkk",
      "kkkkkkkkkflfdkkk",
      "kkkkkkkkkflfdkkk"
    ],
    [
      "kkkkkkkkkfffdkkk",
      "kkkkkkkkkfffdkkk",
      "kkkkkkkkkfffdkkk",
      "kkkkkkkkkfffdkkk",
      "kkkkkkkkkfffdkkk",
      "kkkkkkkkkfffdkkk",
      "kkkkkkkkkfffdkkk",
      "kkkkkkkkkfffdkkk",
      "kkkkkkkkkfffdkkk",
      "kkkkkkkkkfffdkkk",
      "kkkkkkkkkfffdkkk",
      "kkkkkkkkkfffdkkk",
      "kkkkkkkkkfffdkkk",
      "kkkkkkkkkfffdkkk",
      "kkkkkkkkkfffdkkk",
      "kkkkkkkkkfffdkkk"
    ],
    [
      "hhhhhhhhhhhhhhhh",
      "hhhhhhhhhhhhhhhh",
      "jhhhhhhhhhhhhhhh",
      "hhhhhhhhhhhhhhhh",
      "hhhhhhhhhhhhhhhh",
      "hhhhhhhhhhhhhhhh",
      "hhhhhhhhhhhhhhhh",
      "hhhhhhhhhhhhhhhh",
      "hhhhhhhhhhhhhhhh",
      "hhhhhhhhhhhhhhhh",
      "hhhhhhhhhhhhhhhh",
      "hhhhhhmmmmmmmmmm",
      "hhhhhhmjnnnnjnnn",
      "hhhhhhmo========",
      "hhhhhhmo========",
      "hhhhhhmo========"
    ],
    [
      "                ",
      "                ",
      "e               ",
      "                ",
      "                ",
      "                ",
      "                ",
      "                ",
      "                ",
      "                ",
      "         p      ",
      "       q        ",
      "       errrrepss",
      "       r      tt",
      "      uwxyyA    ",
      "       BxCCA    "
    ]
  ]
}