{
  "name": "multi_nuclearpowerplant_30_base11",
  "refpalette": "deceasedcraft:multi_nuclearpowerplant_30/multi_nuclearpowerplant_30_base11_palette",
  "xsize": 16,
  "zsize": 16,
  "slices": [
    [
      "           abcdd",
      "           abcdd",
      "         eeebcdd",
      "         fdebcdd",
      "         eeebcdd",
      "           abcdd",
      "           agcdd",
      "           a cdd",
      "           @ hdd",
      "           @ cdd",
      "           @ cdd",
      "           @ cdd",
      "           @ cdd",
      "           @icdd",
      "           @jcdd",
      "           @jcdd"
    ],
    [
      "           abcdd",
      "           abcdd",
      "         eeebcdd",
      "         fdebcdd",
      "         eeebcdd",
      "           abcdd",
      "           agcdd",
      "           a cdd",
      "           @ hdd",
      "           @ cdd",
      "           @ cdd",
      "           @ cdd",
      "           @ cdd",
      "           @icdd",
      "           @jcdd",
      "           @jcdd"
    ],
    [
      "           abcdd",
      "          kabcdd",
      "         elebcdd",
      "         fdebcdd",
      "         eeebcdd",
      "           abcdd",
      "           agcdd",
      "           agcdd",
      "           @ghdd",
      "           @gcdd",
      "           @gcdd",
      "           @gcdd",
      "           @gcdd",
      "           @mcdd",
      "           @gcdd",
      "           @gcdd"
    ],
    [
      "           abcdd",
      "           abcdd",
      "         eeebcdd",
      "         fdebcdd",
      "         eeebcdd",
      "           abcdd",
      "           abcdd",
      "           agcdd",
      "           a hdd",
      "           a cdd",
      "           a cdd",
      "           ancdd",
      "           aocdd",
      "           amcdd",
      "           apcdd",
      "           apcdd"
    ],
    [
      "           abcdd",
      "           abcdd",
      "         eeebcdd",
      "         fdebcdd",
      "         eeebcdd",
      "           abcdd",
      "           abcdd",
      "           agcdd",
      "           a hdd",
      "           a cdd",
      "           a cdd",
      "           a cdd",
      "           a cdd",
      "           a cdd",
      "           a cdd",
      "           a cdd"
    ],
    [
      "           abcdd",
      "           abcdd",
      "         eeebcdd",
      "         fdebcdd",
      "         eeebcdd",
      "           abcdd",
      "           abcdd",
      "           agcdd",
      "           aghdd",
      "           agcdd",
      "           agcdd",
      "           agcdd",
      "           agcdd",
      "           agcdd",
      "           agcdd",
      "           agcdd"
    ]
  ]
}