{
  "name": "multi_nuclearpowerplant_30_base1",
  "refpalette": "deceasedcraft:multi_nuclearpowerplant_30/multi_nuclearpowerplant_30_base1_palette",
  "xsize": 16,
  "zsize": 16,
  "slices": [
    [
      "aaaaaaaaaaaaaaaa",
      "aaaaaaaaaaaaaaaa",
      "baaaaaaaaaaaaaaa",
      "baaaaaaaaaaaaaaa",
      "baaaaaaaaaaaaaaa",
      "baaaaaaaaaaaaaaa",
      "baaaaaaaaaaaaaaa",
      "bbaaaaaaaaaaaaaa",
      "bbaaaaaaaaaaaaaa",
      "bbaaaaaaaaaaaaaa",
      "bbaaaaaaaaaaaaaa",
      "bbaaaaaaaaaaaaaa",
      "bbaaaaaaaaaaaaaa",
      "bbaaaaaaaaaaaaaa",
      "bbbaaaaaaaaaaaaa",
      "bbbaaaaaaaaaaaaa"
    ],
    [
      "cdbaaaaaaaaaaaaa",
      "cdbaaaaaaaaaaaaa",
      " cbaaaaaaaaaaaaa",
      " cdbaaaaaaaaaaaa",
      " cdbaaaaaaaaaaaa",
      " cdbaaaaaaaaaaaa",
      " cdbaaaaaaaaaaaa",
      "  cbaaaaaaaaaaaa",
      "  cdbaaaaaaaaaaa",
      "  cdbaaaaaaaaaaa",
      "  cdbaaaaaaaaaaa",
      "  cdbaaaaaaaaaaa",
      "  cdbaaaaaaaaaaa",
      "  cdbaaaaaaaaaaa",
      "   cbaaaaaaaaaaa",
      "   cdbaaaaaaaaaa"
    ],
    [
      "   cbaaaaaaaaaaa",
      "   cdbaaaaaaaaaa",
      "   cdbaaaaaaaaaa",
      "    cbaaaaaaaaaa",
      "    cdbaaaaaaaaa",
      "    cdbaaaaaaaaa",
      "    cdbaaaaaaaaa",
      "    cdbaaaaaaaaa",
      "     cbaaaaaaaaa",
      "     cdbaaaaaaaa",
      "     cdbaaaaaaaa",
      "     cdbaaaaaaaa",
      "     cdbaaaaaaaa",
      "     cdbaaaaaaaa",
      "     cdbaaaaaaaa",
      "      cdbaaaaaaa"
    ],
    [
      "     cdbaaaaaaaa",
      "      cbaaaaaaaa",
      "      cdbaaaaaaa",
      "      cdbaaaaaaa",
      "       cbaaaaaaa",
      "       cdbaaaaaa",
      "       cdbaaaaaa",
      "       cdbaaaaaa",
      "       cdbaaaaaa",
      "        cdbaaaaa",
      "        cdbaaaaa",
      "        cdbaaaaa",
      "        cdbaaaaa",
      "        cdbaaaaa",
      "        cdbaaaaa",
      "         cdbaaaa"
    ],
    [
      "        cdbaaaaa",
      "        cdbaaaaa",
      "         cdbaaaa",
      "         cdbaaaa",
      "         cdbaaaa",
      "          cbaaaa",
      "          cdbaaa",
      "          cdbaaa",
      "          cdbaaa",
      "           cbaaa",
      "           cdbaa",
      "           cdbaa",
      "           cdbaa",
      "           cdbaa",
      "           cdbaa",
      "            cbaa"
    ],
    [
      "           cbaaa",
      "           cdbaa",
      "            cbaa",
      "            cdba",
      "            cdba",
      "            cdba",
      "             cdb",
      "             cdb",
      "             cdb",
      "             cdb",
      "              cd",
      "              cd",
      "              cd",
      "              cd",
      "              cd",
      "              cd"
    ]
  ]
}