{
  "name": "multi_thering_2_floor6",
  "refpalette": "deceasedcraft:multi_thering_2/multi_thering_2_floor6_palette",
  "xsize": 16,
  "zsize": 16,
  "slices": [
    [
      "               a",
      "                ",
      "                ",
      "                ",
      "                ",
      "                ",
      "                ",
      "                ",
      "                ",
      "                ",
      "                ",
      "                ",
      "                ",
      "                ",
      "                ",
      "               a"
    ],
    [
      "               a",
      "                ",
      "                ",
      "                ",
      "                ",
      "                ",
      "                ",
      "                ",
      "                ",
      "                ",
      "                ",
      "                ",
      "                ",
      "                ",
      "                ",
      "               a"
    ],
    [
      "               a",
      "                ",
      "                ",
      "                ",
      "                ",
      "                ",
      "                ",
      "                ",
      "                ",
      "                ",
      "                ",
      "                ",
      "                ",
      "                ",
      "                ",
      "               a"
    ],
    [
      "               a",
      "                ",
      "                ",
      "                ",
      "                ",
      "                ",
      "                ",
      "                ",
      "                ",
      "                ",
      "                ",
      "                ",
      "                ",
      "                ",
      "                ",
      "               a"
    ],
    [
      "        bcccccca",
      "        bccccccc",
      "       bcccccccc",
      "       bcccccccc",
      "       bcccccccc",
      "       bcccccccc",
      "       bcccccccc",
      "       bcccccccc",
      "       bcccccccc",
      "       bcccccccc",
      "       bcccccccc",
      "       bcccccccc",
      "       bcccccccc",
      "       bcccccccc",
      "        bccccccc",
      "        bccccccc"
    ],
    [
      "      bcccdeffea",
      "      bcccdfefee",
      "     bccccdffeee",
      "     bbgchdffeee",
      "     bcccddeffee",
      "     bcccddfffee",
      "     bcccddffefe",
      "     bcccddffeee",
      "     bcccddffeee",
      "     bcccddffeee",
      "     bcccddfffee",
      "     bcccddfffee",
      "     bbgcidffeee",
      "     bccccdfffee",
      "      bcccdfffee",
      "      bcccdeffee"
    ]
  ]
}