{
  "name": "multi_thering_2_floor7",
  "refpalette": "deceasedcraft:multi_thering_2/multi_thering_2_floor7_palette",
  "xsize": 16,
  "zsize": 16,
  "slices": [
    [
      "    abcccb     d",
      "    abcccb      ",
      "   abcccbb      ",
      "   abcccb       ",
      "   abcccbe      ",
      "   abcccbf      ",
      "   abcccbg      ",
      "   abcccb       ",
      "   abcccb       ",
      "   abcccbe      ",
      "   abcccbf      ",
      "   abcccbg      ",
      "   abcccb       ",
      "   abcccbb      ",
      "    abcccb      ",
      "    abcccb      "
    ],
    [
      "     hijk      d",
      "     hikk       ",
      "    hilk        ",
      "    hijk        ",
      "    hilk        ",
      "    hijk        ",
      "    hijk        ",
      "    hijk        ",
      "    hijk        ",
      "    hi k        ",
      "    hijk        ",
      "    hijk        ",
      "    hijk        ",
      "    hijk        ",
      "     hikk       ",
      "     hilk       "
    ],
    [
      "      i        d",
      "      i         ",
      "     i          ",
      "     i          ",
      "     i          ",
      "     i          ",
      "     i          ",
      "     i          ",
      "     i          ",
      "     i          ",
      "     i          ",
      "     i          ",
      "     i          ",
      "     i          ",
      "      i         ",
      "      i         "
    ],
    [
      "               d",
      "                ",
      "                ",
      "                ",
      "                ",
      "                ",
      "                ",
      "                ",
      "                ",
      "                ",
      "                ",
      "                ",
      "                ",
      "                ",
      "                ",
      "                "
    ],
    [
      "               d",
      "                ",
      "                ",
      "                ",
      "                ",
      "                ",
      "                ",
      "                ",
      "                ",
      "                ",
      "                ",
      "                ",
      "                ",
      "                ",
      "                ",
      "                "
    ],
    [
      "               d",
      "                ",
      "                ",
      "                ",
      "                ",
      "                ",
      "                ",
      "                ",
      "                ",
      "                ",
      "                ",
      "                ",
      "                ",
      "                ",
      "                ",
      "                "
    ]
  ]
}