{
  "name": "multi_thering_2_base2",
  "refpalette": "deceasedcraft:multi_thering_2/multi_thering_2_base2_palette",
  "xsize": 16,
  "zsize": 16,
  "slices": [
    [
      "vaaaaaaaaaaaaaab",
      "vaaaaaaaaaaaaaaa",
      "vaaaaaaaaaaaaaaa",
      "vaaaaaaaaaaaaaaa",
      "vaaaaaaaaaaaaaaa",
      "vaaaaaaaaaaaaaaa",
      "vaaaaaaaaaaaaaaa",
      "vaaaaaaaaaaaaaaa",
      "vaaaaaaaaaaaaaaa",
      "vaaaaaaaaaaaaaaa",
      "vaaaaaaaaaaaaaaa",
      "vaaaaaaaaaaaaaaa",
      "vaaaaaaaaaaaaaaa",
      "vaaaaaaaaaaaaaaa",
      "vaaaaaaaaaaaaaaa",
      "vaaaaaaaaaaaaaab"
    ],
    [
      "vaaaaaaaaaaaaaab",
      "vaaaaaaaaaaaaaaa",
      "vaaaaaaaaaaaaaaa",
      "vaaaaaaaaaaaaaaa",
      "vaaaaaaaaaaaaaaa",
      "vaaaaaaaaaaaaaaa",
      "vaaaaaaaaaaaaaaa",
      "vaaaaaaaaaaaaaaa",
      "vaaaaaaaaaaaaaaa",
      "vaaaaaaaaaaaaaaa",
      "vaaaaaaaaaaaaaaa",
      "vaaaaaaaaaaaaaaa",
      "vaaaaaaaaaaaaaaa",
      "vaaaaaaaaaaaaaaa",
      "vaaaaaaaaaaaaaaa",
      "vaaaaaaaaaaaaaab"
    ],
    [
      "vccccccccccccccb",
      "vccccccccccccccc",
      "vccccccccccccccc",
      "vccccccccccccccc",
      "vccccccccccccccc",
      "vccccccccccccccc",
      "vccccccccccccccc",
      "vccccccccccccccc",
      "vccccccccccccccc",
      "vccccccccccccccc",
      "vccccccccccccccc",
      "vccccccccccccccc",
      "vccccccccccccccc",
      "vccccccccccccccc",
      "vccccccccccccccc",
      "vccccccccccccccb"
    ],
    [
      "vdeeeefggggggggd",
      "vdeeeefggggggggd",
      "vdeeeedggggggggd",
      "vdeeeedggggggggd",
      "vdeeeedggggggggd",
      "vdeeeedggggggggd",
      "vdeeeedggggggggf",
      "vdeeeedggggggggf",
      "vdeeeedggggggggf",
      "vdeeeedggggggggf",
      "vdeeeedggggggggd",
      "vdeehedggggggggd",
      "vdeeeedggggggggd",
      "vdeeeedggggggggd",
      "vdeeeefggggggggd",
      "vdeeeefggggggggd"
    ],
    [
      "vd ij          k",
      "vd lj         mn",
      "vd    d       on",
      "vd pqqd       on",
      "vd r sd d     tn",
      "vd pqqd u      n",
      "vd r sdwux     y",
      "vdggggd u       ",
      "vdggggd u       ",
      "vd A sdwux     B",
      "vdCpDDd u      n",
      "vd EFsd d     mn",
      "vdIpDDd       on",
      "vd    d       on",
      "vd ij         tn",
      "vd lj          k"
    ],
    [
      "vd JK          k",
      "vd JL          n",
      "vd    d        n",
      "vd pqqd        n",
      "vd M  d N      n",
      "vd pqqd        n",
      "vd M  d O      y",
      "vdggggd P       ",
      "vdggggd         ",
      "vd Q  d O      B",
      "vd pDDd R      n",
      "vd S  d T      n",
      "vd pDDd        n",
      "vd    d        n",
      "vd JL          n",
      "vd JK          k"
    ]
  ]
}