{
  "name": "multi_thering_2_base1",
  "refpalette": "deceasedcraft:multi_thering_2/multi_thering_2_base1_palette",
  "xsize": 16,
  "zsize": 16,
  "slices": [
    [
      "va bc          d",
      "va ef          g",
      "va    a        g",
      "va hiia        g",
      "va h  a        g",
      "va hiia        g",
      "va h  a        j",
      "vakkkka        l",
      "vakkkka        l",
      "va h  a        m",
      "va hnna        g",
      "va h  a        g",
      "va hnna        g",
      "va    a        g",
      "va bf          g",
      "va ec          d"
    ],
    [
      "va op q        d",
      "va rs q        g",
      "va    a        g",
      "va hiia        g",
      "va h  a        g",
      "va hiia        g",
      "va h  at       g",
      "vakkkkau       g",
      "vakkkkaw       g",
      "va h  ax       g",
      "va hnna        g",
      "va h  a        g",
      "va hnna        g",
      "va    a        g",
      "va os q        g",
      "va rp q        d"
    ],
    [
      "vayAA a        d",
      "vayAA a        g",
      "vayAA a        g",
      "vakkiia        g",
      "vakk  a        g",
      "vakkiia        g",
      "vakk  aB       g",
      "vakkkkaC       g",
      "vakkkkaD       g",
      "vakk  aE       g",
      "vakknna        g",
      "vakk  a        g",
      "vakknna        g",
      "vayAA a        g",
      "vayAA a        g",
      "vayAA a        d"
    ],
    [
      "vaFIIIa        d",
      "vaFIIIa        g",
      "vaFIIIa        g",
      "vaIIIIa        g",
      "vaIIIJa        g",
      "vaIIIIa        g",
      "vaIIIJa        g",
      "vaIIIIa        g",
      "vaIIIIa        g",
      "vaIIIJa        g",
      "vaIIIIa        g",
      "vaIIIJa        g",
      "vaIIIIa        g",
      "vaFIIIa        g",
      "vaFIIIa        g",
      "vaFIIIa        d"
    ],
    [
      "vaK  La        d",
      "vaK   a        g",
      "vaK   a        g",
      "vaK  La        g",
      "vaKKKKa        g",
      "vaKL  a        g",
      "vaKKKKa        g",
      "vaK   a        g",
      "vaK   a        g",
      "vaKKKKa        g",
      "vaKL  a        g",
      "vaKKKKa        g",
      "vaK   a        g",
      "vaK   a        g",
      "vaK   a        g",
      "vaK   a        d"
    ],
    [
      "vaMMMMaIIIIIIIId",
      "vaMMMMaIIIIIIIIg",
      "vaMMMMaIIIIIIIIg",
      "vaMMMMaIIIIIIIIg",
      "vaMMMMaIIIIIIIIg",
      "vaMMMMaIIIIIIIIg",
      "vaMMMMaIIIIIIIIg",
      "vaMMMMaIIIIIIIIg",
      "vaMMMMaIIIIIIIIg",
      "vaMMMMaIIIIIIIIg",
      "vaMMMMaIIIIIIIIg",
      "vaMMMMaIIIIIIIIg",
      "vaMMMMaIIIIIIIIg",
      "vaMMMMaIIIIIIIIg",
      "vaMMMMaIIIIIIIIg",
      "vaMMMMaIIIIIIIId"
    ]
  ]
}