{
  "name": "multi_thering_2_ground",
  "refpalette": "deceasedcraft:multi_thering_2/multi_thering_2_ground_palette",
  "xsize": 16,
  "zsize": 16,
  "slices": [
    [
      "aHHHHHHHHHHabccd",
      "aHHHHHHHHHHabccd",
      "aHHHaaaaHHHabccd",
      "aHHaHHHHaHHabccd",
      "aHHaHHHHaHHabccd",
      "aHHaHHHHaHHabccd",
      "aHHaHHHHaHHabccd",
      "aHHaHHHHaHHabccd",
      "aHHaHHHHaHHabccd",
      "aHHaHHHHaHHabccd",
      "aHHaHHHHaHHabccd",
      "aHHaHHHHaHHabccd",
      "aHHaHHHHaHHabccd",
      "aHHaHHHHaHHabccd",
      "aHHaHHHHaHHabccd",
      "aHHaeeeeaHHabccd"
    ],
    [
      "               f",
      "              gh",
      "              gh",
      "    i  j      gh",
      "    k  l      gh",
      "    i  j      gh",
      "    km l      gh",
      "    i  j      gh",
      "    k  l      gh",
      "    i  j      gh",
      "    k  l      gh",
      "    i  j      gh",
      "    k  l      gh",
      "    i  j      gh",
      "    k  l      gh",
      "    hhhh       f"
    ],
    [
      "               f",
      "               n",
      "               n",
      "               n",
      "               n",
      "               n",
      "               n",
      "               n",
      "               n",
      "               n",
      "               n",
      "               n",
      "               n",
      "               n",
      "               n",
      "               f"
    ],
    [
      "               f",
      "                ",
      "                ",
      "                ",
      "                ",
      "                ",
      "                ",
      "                ",
      "                ",
      "                ",
      "                ",
      "                ",
      "                ",
      "                ",
      "                ",
      "               f"
    ],
    [
      "               f",
      "                ",
      "                ",
      "                ",
      "                ",
      "                ",
      "                ",
      "                ",
      "                ",
      "                ",
      "                ",
      "                ",
      "                ",
      "                ",
      "                ",
      "     o         f"
    ],
    [
      "               f",
      "                ",
      "                ",
      "                ",
      "                ",
      "                ",
      "                ",
      "                ",
      "                ",
      "                ",
      "                ",
      "                ",
      "                ",
      "                ",
      "                ",
      "     p         f"
    ]
  ]
}