{
  "name": "multi_farmhouse1_3_floor1",
  "refpalette": "deceasedcraft:multi_farmhouse1_3/multi_farmhouse1_3_floor1_palette",
  "xsize": 16,
  "zsize": 16,
  "slices": [
    [
      "aaaaaaaaaaaaaaaa",
      "aaaaaaaaaaaaaaaa",
      "aaaaaaaaaaaaaaaa",
      "aaaaaaaaaaaaaaaa",
      "aaaaaaaaaaaaaaaa",
      "aaaaaaaaaaaaaaaa",
      "aaaaaaaaaaaaaaaa",
      "aaaaaaaaaaaaaaaa",
      "aaaaaaaaaaaaaaaa",
      "aaaaaaaaaaaaaaaa",
      "aaaaaaaaaaaaaaaa",
      "aaaaaaaaaaaaaaaa",
      "aaaaaaaaaaaaaaaa",
      "aaaaaaaaaaaaaaaa",
      "aaaaaaaaaaaaaaaa",
      "aabbbbbbbbbaaaaa"
    ],
    [
      "cdcddcdccdccdccc",
      "cdccdcdddcdcdccd",
      "cdcddddddcdddddd",
      "cddddccddcdddcdd",
      "cdcddddcddcdcddd",
      "dddddcddcdcddddd",
      "ddecdddddddddddd",
      "cddddddddddddddd",
      "dddddddddddddcdd",
      "dcddddcddddddddd",
      "cddddddddddddddd",
      "dddddddddddddddd",
      "dddddddddddddddd",
      "ccdccfccdcdcdcdd",
      "fcccccccccccdcdc",
      "ccaaaaaaaaaccccc"
    ],
    [
      "cgcggcgccgccgccc",
      "cgccgcgggcgcgccg",
      "cgcggggggcgggggg",
      "cggggccggcgggcgg",
      "cgcggggcggcgcggg",
      "gggggcggcgcggggg",
      "gghcgggggggggggg",
      "cggggggggggggggg",
      "gggggggggggggcgg",
      "gcggggcggggggggg",
      "cggggggggggggggg",
      "gggggggggggggggg",
      "gggggggggggggggg",
      "ccgcciccgcgcgcgg",
      "icccccccccccgcgc",
      "cccccccccccccccc"
    ],
    [
      "cccccccccccccccc",
      "cccccccccccccccc",
      "cccccccccccccccc",
      "cccccccccccccccc",
      "cccccccccccccccc",
      "cccccccccccccccc",
      "cccccccccccccccc",
      "cccccccccccccccc",
      "cccccccccccccccc",
      "cccccccccccccccc",
      "cccccccccccccccc",
      "cccccccccccccccc",
      "cccccccccccccccc",
      "cccccccccccccccc",
      "cccccccccccccccc",
      "cccccccccccccccc"
    ],
    [
      "cccccccccccccccc",
      "cccccccccccccccc",
      "cccccccccccccccc",
      "cccccccccccccccc",
      "cccccccccccccccc",
      "cccccccccccccccc",
      "cccccccccccccccc",
      "cccccccccccccccc",
      "cccccccccccccccc",
      "cccccccccccccccc",
      "cccccccccccccccc",
      "cccccccccccccccc",
      "cccccccccccccccc",
      "cccccccccccccccc",
      "cccccccccccccccc",
      "cccccccccccccccc"
    ],
    [
      "cccccccccccccccc",
      "cccccccccccccccc",
      "cccccccccccccccc",
      "cccccccccccccccc",
      "cccccccccccccccc",
      "cccccccccccccccc",
      "cccccccccccccccc",
      "cccccccccccccccc",
      "cccccccccccccccc",
      "cccccccccccccccc",
      "cccccccccccccccc",
      "cccccccccccccccc",
      "cccccccccccccccc",
      "cccccccccccccccc",
      "cccccccccccccccc",
      "cccccccccccccccc"
    ]
  ]
}