{
  "name": "multi_flatlarge_2_floor3",
  "refpalette": "deceasedcraft:multi_flatlarge_2/multi_flatlarge_2_floor3_palette",
  "xsize": 16,
  "zsize": 16,
  "slices": [
    [
      "                ",
      "                ",
      "                ",
      "aaaaab  baaaaaaa",
      "cccccadeacccccff",
      "cccccaaaacccccff",
      "cccccaccacccccff",
      "cccccaccacccccff",
      "cccccaccaccccccc",
      "cccccaccaccccccc",
      "cccccaccaccccccc",
      "cccccaccaccccccc",
      "cccccaccaccccccc",
      "cccccaggaccccccc",
      "gggggggggggggggg",
      "gggggggggggggggg"
    ],
    [
      "                ",
      "                ",
      "                ",
      "hhhhab  bahhhhih",
      "j   kadeal   mh ",
      "n   oaaaap   qh ",
      "r    as a    th ",
      "u  wwasxaww  uh ",
      "aa yAaB aCy aaaD",
      " E  FaB aI  J   ",
      " a  Kax aL  a   ",
      "MaI Na  aO FaPQ ",
      "MaR Sa  aT UaPQ ",
      " aI NaVWaO Fa   ",
      "XXXYXZ  ZX0XXXXX",
      "                "
    ],
    [
      "                ",
      "                ",
      "                ",
      "h111ab  ba111hi1",
      " 234 adea 234 h ",
      "     a55a     h ",
      "     a  a     h ",
      "     a  a     h ",
      "aa   a  a   aaa6",
      " 7   a  a   8   ",
      " a  9a  a#  a   ",
      " a   a  a   a   ",
      " a   a  a   a   ",
      " a   aV$a   a   ",
      "XXX%X    X^XXXXX",
      "                "
    ],
    [
      "                ",
      "                ",
      "                ",
      "h111ab  ba111hi1",
      " &*( adea &*( h ",
      "     aaaa     h ",
      "     a  a     h ",
      "     a  a     h ",
      "aa   a  a   aaaV",
      " d   a  a   e   ",
      " a   a  a   a   ",
      " a)  a  a  +a   ",
      " a)  a  a  +a   ",
      " a)  aVVa  +a   ",
      "XXXVX    XVXXXXX",
      "                "
    ],
    [
      "                ",
      "                ",
      "                ",
      "aaaaab  baaaaaaa",
      "     adea     a-",
      "     aaaa     a-",
      "     a  a     a-",
      "     a  a     a-",
      "aa   a  a   aaaa",
      " a   a  a   a   ",
      " a   a  a   a   ",
      " a   a  a   a   ",
      " a   a  a   a   ",
      " a   aaaa   a   ",
      "XXXXX    XXXXXXX",
      "                "
    ],
    [
      "                ",
      "                ",
      "                ",
      "55555b  b5555555",
      "gggggadeaggggggg",
      "gggggaaaagggggg ",
      "ggggga[[agggggg ",
      "ggggga[[agggggg ",
      "ggggga[[aggggggg",
      "ggggga[[aggggggg",
      "ggggga[[aggggggg",
      "ggggga[[aggggggg",
      "ggggga[[aggggggg",
      "gggggaaaaggggggg",
      "]]]]]]]]]]]]]]]]",
      "[[[[[[[[[[[[[[[["
    ]
  ]
}