{
  "name": "multi_flatlarge_2_ground",
  "refpalette": "deceasedcraft:multi_flatlarge_2/multi_flatlarge_2_ground_palette",
  "xsize": 16,
  "zsize": 16,
  "slices": [
    [
      "HHHHHHHHHHHHHHHH",
      "HHHHHHHHHHHHHHHH",
      "aaaaaaaaaaaaaaaa",
      "bbbbbbccbbbbbbbb",
      "dddddccccddddddd",
      "ddddddccdddddddd",
      "ddddddccdddddddd",
      "ddddddccdddddddd",
      "ddddddccdddddddd",
      "ddddddccdddddddd",
      "ddddddccdddddddd",
      "dccccccccccccddd",
      "dccccccccccccddd",
      "dccccccccccccddd",
      "dccccccccccccddd",
      "cccccccccccccccc"
    ],
    [
      "                ",
      "                ",
      "                ",
      "eeeeeeffeeeeeeee",
      "ghghgijfihghghgh",
      "      jj        ",
      "      ff        ",
      "klklk fj lklklkl",
      "      jf        ",
      "      fj        ",
      "      jf        ",
      "gh mn fj mn g   ",
      "  opq jj pqo    ",
      "   pq jf pq     ",
      "kl rsittirs k   ",
      "uuwuwx  ywuuwwwu"
    ],
    [
      "                ",
      "                ",
      "                ",
      "                ",
      "     A  A       ",
      "                ",
      "                ",
      "                ",
      "                ",
      "                ",
      "                ",
      "                ",
      "                ",
      "                ",
      "     A  A       ",
      "                "
    ],
    [
      "                ",
      "                ",
      "                ",
      "                ",
      "     A  A       ",
      "                ",
      "                ",
      "                ",
      "                ",
      "                ",
      "                ",
      "                ",
      "                ",
      "                ",
      "     A  A       ",
      "                "
    ],
    [
      "                ",
      "                ",
      "                ",
      "                ",
      "BBBBBABBABBBBBBB",
      "     C  C       ",
      "     C  C       ",
      "     C  C       ",
      "     C  C       ",
      "     C  C       ",
      "     C  C       ",
      "     C  C       ",
      "     C  C       ",
      "     C  C       ",
      "CCCCCACCACCCCCCC",
      "                "
    ],
    [
      "                ",
      "                ",
      "                ",
      "CCCCCCCCCCCCCCCC",
      "DDDDDDDDDDDDDDDD",
      "EEEEEDEEDEEEEEEE",
      "EEEEEDEEDEEEEEEE",
      "EEEEEDEEDEEEEEEE",
      "EEEEEDEEDEEEEEEE",
      "EEEEEDEEDEEEEEEE",
      "EEEEEDEEDEEEEEEE",
      "EEEEEDEEDEEEEEEE",
      "EEEEEDEEDEEEEEEE",
      "EEEEEDEEDEEEEEEE",
      "DDDDDDDDDDDDDDDD",
      "EEEEEDEEDEEEEEEE"
    ]
  ]
}