{
  "name": "multi_flatlarge_2_top",
  "refpalette": "deceasedcraft:multi_flatlarge_2/multi_flatlarge_2_top_palette",
  "xsize": 16,
  "zsize": 16,
  "slices": [
    [
      "                ",
      "                ",
      "                ",
      "aaaaab  baaaaaaa",
      "cccccdefdccccccc",
      "cccccaaaaccccccc",
      "cccccaccaccccccc",
      "cccccaccaccccccc",
      "cccccaccaccccccc",
      "cccccaccaccccccc",
      "cccccaccaccccccc",
      "cccccaccaccccccc",
      "cccccaccaccccccc",
      "cccccccccccccccc",
      "gggggaccaggggggg",
      "hhhhhaccahhhhhhh"
    ],
    [
      "                ",
      "                ",
      "                ",
      "bbbbbb  bbbbbbbb",
      "     iefi       ",
      "     aaaa       ",
      "     a  a       ",
      "     a  a       ",
      "     a  a       ",
      "     a  a       ",
      "     a  a       ",
      "     a  a       ",
      "     a  a       ",
      "                ",
      "bbbbba  abbbbbbb",
      "     a  a       "
    ],
    [
      "                ",
      "                ",
      "                ",
      "                ",
      "     j  j       ",
      "     aaaa       ",
      "     a  a       ",
      "     a  a       ",
      "     a  a       ",
      "     a  a       ",
      "     a  a       ",
      "     a  a       ",
      "     a  a       ",
      "                ",
      "     a  a       ",
      "     k  k       "
    ],
    [
      "                ",
      "                ",
      "                ",
      "                ",
      "    llllll      ",
      "    llllll      ",
      "    llllll      ",
      "    llllll      ",
      "    llllll      ",
      "    llllll      ",
      "    llllll      ",
      "    llllll      ",
      "    llllll      ",
      "    llllll      ",
      "    llllll      ",
      "    llllll      "
    ]
  ]
}