{
  "name": "building_premiumclothstore_ground_270",
  "refpalette": "deceasedcraft:building_premiumclothstore/building_premiumclothstore_ground_palette_270",
  "xsize": 16,
  "zsize": 16,
  "slices": [
    [
      "aaaaaaaaaaaaaaaa",
      "aaaaabbbbbbbbbba",
      "DDDqDb   qhchcba",
      "FE   b w q c cba",
      "FE   b   dididba",
      "FE   B        ba",
      "FE   C        ba",
      "FE    x trojjeba",
      "FE    y ukpnkeba",
      "FE   C        ba",
      "FE   B        ba",
      "FE   b   sfglfba",
      "FE   bA  qmlfgba",
      "DDDqDb   qlgmfba",
      "aaaaabbbbbbbbbba",
      "aaaaaaaaaaaaaaaa"
    ],
    [
      "                ",
      "  VVVbbbbbbbbbb ",
      " BBqBb   q c!cb ",
      "     b   qIcIcb ",
      "     b   dKdKdb ",
      "     B        b ",
      "     C        b ",
      "     C  SQPNLeb ",
      "     C  TROOMeb ",
      "     C        b ",
      "     B        b ",
      "     b   sIIIIb ",
      "     b   qJJJJb ",
      " BBqBb U qJJJJb ",
      "  VVVbbbbbbbbbb ",
      "                "
    ],
    [
      "                ",
      "     bbbbbbbbbb ",
      "   q b   q c cb ",
      "     b   q c cb ",
      "     b   dddddb ",
      "     B        b ",
      "     B        b ",
      "     B   WWWWWb ",
      "     B   XXXXXb ",
      "     B        b ",
      "     B        b ",
      "     b   sflmlb ",
      "     b   qlfggb ",
      "   q b   qmglmb ",
      "     bbbbbbbbbb ",
      "                "
    ],
    [
      "                ",
      "     bbbbbbbbbb ",
      "   q b531eJJJJb ",
      "     b   eJJJJb ",
      "     b   eYYYYb ",
      "     b   Z    b ",
      "     b   0    b ",
      "     b   Z    b ",
      "     b   0    b ",
      "     b   Z    b ",
      "     b   0    b ",
      "     b   eIIIIb ",
      "     b   eJJJJb ",
      "   q b642eJJJJb ",
      "     bbbbbbbbbb ",
      "                "
    ],
    [
      "                ",
      "     7888888887 ",
      "   # 8        8 ",
      "     8        8 ",
      "     8        8 ",
      "     8        8 ",
      "     8        8 ",
      "     8        8 ",
      "     8        8 ",
      "     8        8 ",
      "     8        8 ",
      "     8   9    8 ",
      "     8        8 ",
      "   # 8        8 ",
      "     7888888887 ",
      "                "
    ],
    [
      "                ",
      " $$$$$$$$$$$$$$ ",
      " $&&&$qqqqqqqq$ ",
      " $&&&$q%%%%%%q$ ",
      " $&&&$q%^^^^%q$ ",
      " $&&&$q%^^^^%q$ ",
      " $&&&$q%^^^^%q$ ",
      " $&&&$q%^^^^%q$ ",
      " $&&&$q%^^^^%q$ ",
      " $&&&$q%^^^^%q$ ",
      " $&&&$q%^^^^%q$ ",
      " $&&&$q%^^^^%q$ ",
      " $&&&$q%%%%%%q$ ",
      " $&&&$qqqqqqqq$ ",
      " $$$$$$$$$$$$$$ ",
      "                "
    ]
  ]
}