{
  "name": "building_premiumclothstore_ground_180",
  "refpalette": "deceasedcraft:building_premiumclothstore/building_premiumclothstore_ground_palette_180",
  "xsize": 16,
  "zsize": 16,
  "slices": [
    [
      "aaDFFFFFFFFFFDaa",
      "aaDEEEEEEEEEEDaa",
      "aaD          Daa",
      "aaq          qaa",
      "aaD          Daa",
      "abbbbBC  CBbbbba",
      "ab A   yx     ba",
      "ab          w ba",
      "ab     ut     ba",
      "abqqs  kr  dqqba",
      "ablmf  po  i hba",
      "abglg  nj  dccba",
      "abmfl  kj  i hba",
      "abfgf  ee  dccba",
      "abbbbbbbbbbbbbba",
      "aaaaaaaaaaaaaaaa"
    ],
    [
      "                ",
      "  B          B  ",
      " VB          BV ",
      " Vq          qV ",
      " VB          BV ",
      " bbbbBCCCCBbbbb ",
      " b            b ",
      " bU           b ",
      " b     TS     b ",
      " bqqs  RQ  dqqb ",
      " bJJI  OP  KI b ",
      " bJJI  ON  dccb ",
      " bJJI  ML  KI!b ",
      " bJJI  ee  dccb ",
      " bbbbbbbbbbbbbb ",
      "                "
    ],
    [
      "                ",
      "                ",
      "                ",
      "  q          q  ",
      "                ",
      " bbbbBBBBBBbbbb ",
      " b            b ",
      " b            b ",
      " b            b ",
      " bqqs  XW  dqqb ",
      " bmlf  XW  d  b ",
      " bgfl  XW  dccb ",
      " blgm  XW  d  b ",
      " bmgl  XW  dccb ",
      " bbbbbbbbbbbbbb ",
      "                "
    ],
    [
      "                ",
      "                ",
      "                ",
      "  q          q  ",
      "                ",
      " bbbbbbbbbbbbbb ",
      " b6          5b ",
      " b4          3b ",
      " b2          1b ",
      " beee0Z0Z0Zeeeb ",
      " bJJI      YJJb ",
      " bJJI      YJJb ",
      " bJJI      YJJb ",
      " bJJI      YJJb ",
      " bbbbbbbbbbbbbb ",
      "                "
    ],
    [
      "                ",
      "                ",
      "                ",
      "  #          #  ",
      "                ",
      " 78888888888887 ",
      " 8            8 ",
      " 8            8 ",
      " 8            8 ",
      " 8  9         8 ",
      " 8            8 ",
      " 8            8 ",
      " 8            8 ",
      " 8            8 ",
      " 78888888888887 ",
      "                "
    ],
    [
      "                ",
      " $$$$$$$$$$$$$$ ",
      " $&&&&&&&&&&&&$ ",
      " $&&&&&&&&&&&&$ ",
      " $&&&&&&&&&&&&$ ",
      " $$$$$$$$$$$$$$ ",
      " $qqqqqqqqqqqq$ ",
      " $q%%%%%%%%%%q$ ",
      " $q%^^^^^^^^%q$ ",
      " $q%^^^^^^^^%q$ ",
      " $q%^^^^^^^^%q$ ",
      " $q%^^^^^^^^%q$ ",
      " $q%%%%%%%%%%q$ ",
      " $qqqqqqqqqqqq$ ",
      " $$$$$$$$$$$$$$ ",
      "                "
    ]
  ]
}