{
  "name": "building_premiumclothstore_ground_90",
  "refpalette": "deceasedcraft:building_premiumclothstore/building_premiumclothstore_ground_palette_90",
  "xsize": 16,
  "zsize": 16,
  "slices": [
    [
      "aaaaaaaaaaaaaaaa",
      "abbbbbbbbbbaaaaa",
      "abfmglq   bDqDDD",
      "abgflmq  Ab   EF",
      "abflgfs   b   EF",
      "ab        B   EF",
      "ab        C   EF",
      "abeknpku y    EF",
      "abejjort x    EF",
      "ab        C   EF",
      "ab        B   EF",
      "abdidid   b   EF",
      "abc c q w b   EF",
      "abchchq   bDqDDD",
      "abbbbbbbbbbaaaaa",
      "aaaaaaaaaaaaaaaa"
    ],
    [
      "                ",
      " bbbbbbbbbbVVV  ",
      " bJJJJq U bBqBB ",
      " bJJJJq   b     ",
      " bIIIIs   b     ",
      " b        B     ",
      " b        C     ",
      " beMOORT  C     ",
      " beLNPQS  C     ",
      " b        C     ",
      " b        B     ",
      " bdKdKd   b     ",
      " bcIcIq   b     ",
      " bc!c q   bBqBB ",
      " bbbbbbbbbbVVV  ",
      "                "
    ],
    [
      "                ",
      " bbbbbbbbbb     ",
      " bmlgmq   b q   ",
      " bggflq   b     ",
      " blmlfs   b     ",
      " b        B     ",
      " b        B     ",
      " bXXXXX   B     ",
      " bWWWWW   B     ",
      " b        B     ",
      " b        B     ",
      " bddddd   b     ",
      " bc c q   b     ",
      " bc c q   b q   ",
      " bbbbbbbbbb     ",
      "                "
    ],
    [
      "                ",
      " bbbbbbbbbb     ",
      " bJJJJe246b q   ",
      " bJJJJe   b     ",
      " bIIIIe   b     ",
      " b    0   b     ",
      " b    Z   b     ",
      " b    0   b     ",
      " b    Z   b     ",
      " b    0   b     ",
      " b    Z   b     ",
      " bYYYYe   b     ",
      " bJJJJe   b     ",
      " bJJJJe135b q   ",
      " bbbbbbbbbb     ",
      "                "
    ],
    [
      "                ",
      " 7888888887     ",
      " 8        8 #   ",
      " 8        8     ",
      " 8    9   8     ",
      " 8        8     ",
      " 8        8     ",
      " 8        8     ",
      " 8        8     ",
      " 8        8     ",
      " 8        8     ",
      " 8        8     ",
      " 8        8     ",
      " 8        8 #   ",
      " 7888888887     ",
      "                "
    ],
    [
      "                ",
      " $$$$$$$$$$$$$$ ",
      " $qqqqqqqq$&&&$ ",
      " $q%%%%%%q$&&&$ ",
      " $q%^^^^%q$&&&$ ",
      " $q%^^^^%q$&&&$ ",
      " $q%^^^^%q$&&&$ ",
      " $q%^^^^%q$&&&$ ",
      " $q%^^^^%q$&&&$ ",
      " $q%^^^^%q$&&&$ ",
      " $q%^^^^%q$&&&$ ",
      " $q%^^^^%q$&&&$ ",
      " $q%%%%%%q$&&&$ ",
      " $qqqqqqqq$&&&$ ",
      " $$$$$$$$$$$$$$ ",
      "                "
    ]
  ]
}