{
  "name": "building_premiumclothstore_ground",
  "refpalette": "deceasedcraft:building_premiumclothstore/building_premiumclothstore_ground_palette",
  "xsize": 16,
  "zsize": 16,
  "slices": [
    [
      "aaaaaaaaaaaaaaaa",
      "abbbbbbbbbbbbbba",
      "abccd  ee  fgfba",
      "abh i  jk  lfmba",
      "abccd  jn  glgba",
      "abh i  op  fmlba",
      "abqqd  rk  sqqba",
      "ab     tu     ba",
      "ab w          ba",
      "ab     xy   A ba",
      "abbbbBC  CBbbbba",
      "aaD          Daa",
      "aaq          qaa",
      "aaD          Daa",
      "aaDEEEEEEEEEEDaa",
      "aaDFFFFFFFFFFDaa"
    ],
    [
      "                ",
      " bbbbbbbbbbbbbb ",
      " bccd  ee  IJJb ",
      " b!IK  LM  IJJb ",
      " bccd  NO  IJJb ",
      " b IK  PO  IJJb ",
      " bqqd  QR  sqqb ",
      " b     ST     b ",
      " b           Ub ",
      " b            b ",
      " bbbbBCCCCBbbbb ",
      " VB          BV ",
      " Vq          qV ",
      " VB          BV ",
      "  B          B  ",
      "                "
    ],
    [
      "                ",
      " bbbbbbbbbbbbbb ",
      " bccd  WX  lgmb ",
      " b  d  WX  mglb ",
      " bccd  WX  lfgb ",
      " b  d  WX  flmb ",
      " bqqd  WX  sqqb ",
      " b            b ",
      " b            b ",
      " b            b ",
      " bbbbBBBBBBbbbb ",
      "                ",
      "  q          q  ",
      "                ",
      "                ",
      "                "
    ],
    [
      "                ",
      " bbbbbbbbbbbbbb ",
      " bJJY      IJJb ",
      " bJJY      IJJb ",
      " bJJY      IJJb ",
      " bJJY      IJJb ",
      " beeeZ0Z0Z0eeeb ",
      " b1          2b ",
      " b3          4b ",
      " b5          6b ",
      " bbbbbbbbbbbbbb ",
      "                ",
      "  q          q  ",
      "                ",
      "                ",
      "                "
    ],
    [
      "                ",
      " 78888888888887 ",
      " 8            8 ",
      " 8            8 ",
      " 8            8 ",
      " 8            8 ",
      " 8         9  8 ",
      " 8            8 ",
      " 8            8 ",
      " 8            8 ",
      " 78888888888887 ",
      "                ",
      "  #          #  ",
      "                ",
      "                ",
      "                "
    ],
    [
      "                ",
      " $$$$$$$$$$$$$$ ",
      " $qqqqqqqqqqqq$ ",
      " $q%%%%%%%%%%q$ ",
      " $q%^^^^^^^^%q$ ",
      " $q%^^^^^^^^%q$ ",
      " $q%^^^^^^^^%q$ ",
      " $q%^^^^^^^^%q$ ",
      " $q%%%%%%%%%%q$ ",
      " $qqqqqqqqqqqq$ ",
      " $$$$$$$$$$$$$$ ",
      " $&&&&&&&&&&&&$ ",
      " $&&&&&&&&&&&&$ ",
      " $&&&&&&&&&&&&$ ",
      " $$$$$$$$$$$$$$ ",
      "                "
    ]
  ]
}