{
  "name": "multi_filmworkstower_1_ground",
  "refpalette": "deceasedcraft:multi_filmworkstower_1/multi_filmworkstower_1_ground_palette",
  "xsize": 16,
  "zsize": 16,
  "slices": [
    [
      "aaaabc       dee",
      "aaafbg  h    dee",
      "aaaabc h h   dee",
      "aaaabg  h    dee",
      "aaafbc    h  dee",
      "aaaabg       dee",
      "aaaabc   h h dee",
      "aaafbg    h  dee",
      "aaaabc  i    dee",
      "aaaabg i  i  dee",
      "aaafbc  i    dee",
      "aaaabg       dee",
      "aaaab ddddddddee",
      "aaaabeeeeeeeeeee",
      "aaaabeeeeeeeeeee",
      "aaaabeeeeeeeeeee"
    ],
    [
      "    jk          ",
      "   jlk          ",
      "    jk          ",
      "    jk          ",
      "   jlk          ",
      "    jk          ",
      "    jk          ",
      "   jlk          ",
      "    jk          ",
      "    jk          ",
      "   jlk          ",
      "    jk          ",
      "     m          ",
      "     nlo        ",
      "     n          ",
      "     n     p    "
    ],
    [
      "     jq         ",
      "    jlq         ",
      "     jq         ",
      "     jq         ",
      "    jlq         ",
      "     jq         ",
      "     jq         ",
      "    jlq         ",
      "     jq         ",
      "     jq         ",
      "    jlq         ",
      "     jq         ",
      "      m         ",
      "      nlo       ",
      "      n         ",
      "      n    r    "
    ],
    [
      "      jq        ",
      "     jlq        ",
      "      jq        ",
      "      jq        ",
      "     jlq        ",
      "      jq        ",
      "      jq        ",
      "     jlq        ",
      "      jq        ",
      "      jq        ",
      "     jlq        ",
      "      jq        ",
      "       m        ",
      "       nlo      ",
      "       n        ",
      "       n   s    "
    ],
    [
      "       jq       ",
      "      jlq       ",
      "       jq       ",
      "       jq       ",
      "      jlq       ",
      "       jq       ",
      "       jq       ",
      "      jlq       ",
      "       jq       ",
      "       jq       ",
      "      jlq       ",
      "       jq       ",
      "        m       ",
      "        nlo     ",
      "        n       ",
      "        n  s    "
    ],
    [
      "        jq      ",
      "       jlq      ",
      "        jq      ",
      "        jq      ",
      "       jlq      ",
      "        jq      ",
      "        jq      ",
      "       jlq      ",
      "        jq      ",
      "        jq      ",
      "       jlq      ",
      "        jq      ",
      "         m      ",
      "         nlo    ",
      "         n      ",
      "         n t    "
    ]
  ]
}