{
  "name": "multi_filmworkstower_1_floor1",
  "refpalette": "deceasedcraft:multi_filmworkstower_1/multi_filmworkstower_1_floor1_palette",
  "xsize": 16,
  "zsize": 16,
  "slices": [
    [
      "         ab     ",
      "        acb     ",
      "         ab     ",
      "         ab     ",
      "        acb     ",
      "         ab     ",
      "         ab     ",
      "        acb     ",
      "         ab     ",
      "         ab     ",
      "        acb     ",
      "         ab     ",
      "          d     ",
      "          ecf   ",
      "          eg    ",
      "          eh    "
    ],
    [
      "          ab    ",
      "         acb    ",
      "          ab    ",
      "          ab    ",
      "         acb    ",
      "          ab    ",
      "          ab    ",
      "         acb    ",
      "          ab    ",
      "          ab    ",
      "         acb    ",
      "          ab    ",
      "           d    ",
      "           ecf  ",
      "           ijjjj",
      "           ikklk"
    ],
    [
      "           ab   ",
      "          acb   ",
      "           ab   ",
      "           ab   ",
      "          acb   ",
      "           ab   ",
      "           ab   ",
      "          acb   ",
      "           ab   ",
      "           ab   ",
      "          acb   ",
      "           ab   ",
      "            d   ",
      "            eccc",
      "            imm ",
      "            innn"
    ],
    [
      "            ab  ",
      "           acb  ",
      "            ab  ",
      "            ab  ",
      "           acb  ",
      "            ab  ",
      "            ab  ",
      "           acb  ",
      "            ab  ",
      "            ab  ",
      "           acb  ",
      "            ab  ",
      "             d  ",
      "             ecc",
      "             emm",
      "             e  "
    ],
    [
      "             ab ",
      "            acb ",
      "             ab ",
      "             ab ",
      "            acb ",
      "             ab ",
      "             ab ",
      "            acb ",
      "             ab ",
      "             ab ",
      "            acb ",
      "             ab ",
      "              d ",
      "              ec",
      "              em",
      "              e "
    ],
    [
      "              ab",
      "             acb",
      "              ab",
      "              ab",
      "             acb",
      "              ab",
      "              ab",
      "             acb",
      "              ab",
      "              ab",
      "             acb",
      "              ab",
      "               d",
      "               e",
      "               e",
      "               e"
    ]
  ]
}