{
  "name": "multi_filmworkstower_1_base2",
  "refpalette": "deceasedcraft:multi_filmworkstower_1/multi_filmworkstower_1_base2_palette",
  "xsize": 16,
  "zsize": 16,
  "slices": [
    [
      "vaaabccccccccccc",
      "vaaabccccccccccc",
      "vaaabccccccccccc",
      "vaaabccccccccccc",
      "vaaabccccccccccc",
      "vaaabccccccccccc",
      "vaaabccccccccccc",
      "vaaabccccccccccc",
      "vaaabccccccccccc",
      "vaaabccccccccccc",
      "vaaabccccccccccc",
      "vaaabccccccccccc",
      "vaaabbbbbbbbbbbb",
      "vaaabccccccccccc",
      "vaaabccccccccccc",
      "vaaabccccccccccc"
    ],
    [
      "vaaadddddddd    ",
      "vaaadddddddd e  ",
      "vaaadddddddd f g",
      "vaaadddddddd f  ",
      "vaaadddddddd f  ",
      "vaaadddddddd h  ",
      "vaaadddddddd f  ",
      "vaaadddddddd f  ",
      "vaaadddddddd f  ",
      "vaaadddddddd f  ",
      "vaaadddddddd e  ",
      "vaaadddddddd    ",
      "vaaabbbbbbbbbbbb",
      "vaaai       jklm",
      "vaaaino      p  ",
      "vaaavqo    r    "
    ],
    [
      "vaaad           ",
      "vaaad ss        ",
      "vaaadtuut       ",
      "vaaadwxxwy      ",
      "vaaadABBC       ",
      "vaaadDEEF    I  ",
      "vaaadJKKL       ",
      "vaaadwMMwy      ",
      "vaaadtNNt       ",
      "vaaadOFDO       ",
      "vaaad           ",
      "vaaadPPQPR      ",
      "vaaabbbbbbbbbbbb",
      "vaaai        STU",
      "vaaai           ",
      "vaaavq          "
    ],
    [
      "vaaad           ",
      "vaaadVWWX       ",
      "vaaadYZ0Y       ",
      "vaaad1Z01       ",
      "vaaad1ss1       ",
      "vaaad2  3       ",
      "vaaad2443       ",
      "vaaad2113       ",
      "vaaad 55        ",
      "vaaad6  6       ",
      "vaaad           ",
      "vaaad  7        ",
      "vaaabbbbbbbbbbbb",
      "vaaai           ",
      "vaaai           ",
      "vaaavq          "
    ],
    [
      "vaaad           ",
      "vaaad           ",
      "vaaad           ",
      "vaaad           ",
      "vaaad 88        ",
      "vaaad 99        ",
      "vaaad ##        ",
      "vaaad           ",
      "vaaad           ",
      "vaaad           ",
      "vaaad           ",
      "vaaad           ",
      "vaaabbbbbbbbbbbb",
      "vaaai           ",
      "vaaai           ",
      "vaaavq          "
    ],
    [
      "vaaad           ",
      "vaaad           ",
      "vaaad           ",
      "vaaad           ",
      "vaaad           ",
      "vaaad           ",
      "vaaad           ",
      "vaaad           ",
      "vaaad           ",
      "vaaad           ",
      "vaaad           ",
      "vaaad           ",
      "vaaabbbbbbbbbbbb",
      "vaaai$          ",
      "vaaai%          ",
      "vaaavq          "
    ]
  ]
}