{
  "name": "multi_filmworkstower_1_base1",
  "refpalette": "deceasedcraft:multi_filmworkstower_1/multi_filmworkstower_1_base1_palette",
  "xsize": 16,
  "zsize": 16,
  "slices": [
    [
      "vaaab           ",
      "vaaab           ",
      "vaaab           ",
      "vaaab           ",
      "vaaab           ",
      "vaaab           ",
      "vaaab           ",
      "vaaab           ",
      "vaaab           ",
      "vaaab           ",
      "vaaab           ",
      "vaaab           ",
      "vaaacccccccccccc",
      "vaaad           ",
      "vaaade          ",
      "vaaavf          "
    ],
    [
      "vaaab           ",
      "vaaab           ",
      "vaaab           ",
      "vaaab           ",
      "vaaab           ",
      "vaaab           ",
      "vaaab           ",
      "vaaab           ",
      "vaaab           ",
      "vaaab           ",
      "vaaab           ",
      "vaaab           ",
      "vaaacccccccccccc",
      "vaaad           ",
      "vaaad           ",
      "vaaade          "
    ],
    [
      "vaaab           ",
      "vaaab           ",
      "vaaab           ",
      "vaaab           ",
      "vaaab           ",
      "vaaab           ",
      "vaaab           ",
      "vaaab           ",
      "vaaab           ",
      "vaaab           ",
      "vaaab           ",
      "vaaab           ",
      "vaaacccccccccccc",
      "vaaad           ",
      "vaaad           ",
      "vaaad           "
    ],
    [
      "vaaab           ",
      "vaaab           ",
      "vaaab           ",
      "vaaab           ",
      "vaaab           ",
      "vaaab           ",
      "vaaab           ",
      "vaaab           ",
      "vaaab           ",
      "vaaab           ",
      "vaaab           ",
      "vaaab           ",
      "vaaacccccccccccc",
      "vaaad           ",
      "vaaad           ",
      "vaaad           "
    ],
    [
      "vaaacggggggggggg",
      "vaaacggggggggggg",
      "vaaacggggggggggg",
      "vaaacggggggggggg",
      "vaaacggggggggggg",
      "vaaacggggggggggg",
      "vaaacggggggggggg",
      "vaaacggggggggggg",
      "vaaacggggggggggg",
      "vaaacggggggggggg",
      "vaaacggggggggggg",
      "vaaacggggggggggg",
      "vaaacccccccccccc",
      "vaaacggggggggggg",
      "vaaacggggggggggg",
      "vaaacggggggggggg"
    ],
    [
      "vaaachhhhhhhhccc",
      "vaaachhhhhhhhccc",
      "vaaachhhhhhhhccc",
      "vaaachhhhhhhhccc",
      "vaaachhhhhhhhccc",
      "vaaachhhhhhhhccc",
      "vaaachhhhhhhhccc",
      "vaaachhhhhhhhccc",
      "vaaachhhhhhhhccc",
      "vaaachhhhhhhhccc",
      "vaaachhhhhhhhccc",
      "vaaachhhhhhhhccc",
      "vaaac cccccccccc",
      "vaaacccccccccccc",
      "vaaacccccccccccc",
      "vaaacccccccccccc"
    ]
  ]
}