{
  "name": "multi_gunstore_3_base1",
  "refpalette": "deceasedcraft:multi_gunstore_3/multi_gunstore_3_base1_palette",
  "xsize": 16,
  "zsize": 16,
  "slices": [
    [
      "vvvvvvvvvvvvvvvv",
      "aaaaaaaaaaaaaaav",
      "aaaaaaaaaaaaaaav",
      "aaaaaaaaaaaaaaav",
      "aaaaaaaaaaaaaaav",
      "aaaaaaaaaaaaaaav",
      "aaaaaaaaaaaaaaav",
      "aaaaaaaaaaaaaaav",
      "aaaaaaaaaaaaaaav",
      "aaaaaaaaaaaaaaav",
      "aaaaaaaaaaaaaaav",
      "aaaaaaaaaaaaaaav",
      "aaaaaaaaaaaaaaav",
      "aaaaaaaaaaaaaaav",
      "aaaaaaaaaaaaaaav",
      "vvvvvvvvvvvvvvvv"
    ],
    [
      "vvvvvvvvvvvvvvvv",
      "aaaaaaaaaaaaaaav",
      "aaaaaaaaaaaaaaav",
      "aaaaaaaaaaaaaaav",
      "aaaaaaaaaaaaaaav",
      "aaaaaaaaaaaaaaav",
      "aaaaaaaaaaaaaaav",
      "aaaaaaaaaaaaaaav",
      "aaaaaaaaaaaaaaav",
      "aaaaaaaaaaaaaaav",
      "aaaaaaaaaaaaaaav",
      "aaaaaaaaaaaaaaav",
      "aaaaaaaaaaaaaaav",
      "aaaaaaaaaaaaaaav",
      "aaaaaaaaaaaaaaav",
      "vvvvvvvvvvvvvvvv"
    ],
    [
      "vvvvvvvvvvvvvvvv",
      "aaaaaaaaaaaaaaav",
      "aaaaaaaaaaaaaaav",
      "bbbbbbbbbaaaaaav",
      "ccccccccbvvvvvvv",
      "ccccccccdddddddv",
      "ccccccccdddddddv",
      "ccccccccdddddddv",
      "ccccccccdddddddv",
      "ccccccccdddddddv",
      "ccccccccdddddddv",
      "ccccccccbvvvvvvv",
      "bbbbbbbbbaaaaaav",
      "aaaaaaaaaaaaaaav",
      "aaaaaaaaaaaaaaav",
      "vvvvvvvvvvvvvvvv"
    ],
    [
      "vvvvvvvvvvvvvvvv",
      "aaaaaaaaaaaaaaav",
      "aaaaaaaaaaaaaaav",
      "bbbbbbbbbaaaaaav",
      "eefghee bvvvvvvv",
      "        i   j kv",
      "  lll   m n nokv",
      "        p   qr!v",
      "        i  s  kv",
      "tuwxyAp m    okv",
      "        pB  r kv",
      "CDEEEFC bvvvvvvv",
      "bbbbbbbbbaaaaaav",
      "aaaaaaaaaaaaaaav",
      "aaaaaaaaaaaaaaav",
      "vvvvvvvvvvvvvvvv"
    ],
    [
      "vvvvvvvvvvvvvvvv",
      "aaaaaaaaaaaaaaav",
      "aaaaaaaaaaaaaaav",
      "bbbbbbbbbaaaaaav",
      "        bvvvvvvv",
      "              Iv",
      "             JKv",
      "              kv",
      "              Iv",
      "             J v",
      "              Lv",
      "     M  bvvvvvvv",
      "bbbbbbbbbaaaaaav",
      "aaaaaaaaaaaaaaav",
      "aaaaaaaaaaaaaaav",
      "vvvvvvvvvvvvvvvv"
    ],
    [
      "vvvvvvvvvvvvvvvv",
      "aaaaaaaaaaaaaaav",
      "aaaaaaaaaaaaaaav",
      "bbbbbbbbbaaaaaav",
      "        bvvvvvvv",
      "         NNNNNNv",
      "        ONNNNNNv",
      "         NNNNNNv",
      "         NNNNNNv",
      "        ONNNNNNv",
      "         NNNNNNv",
      "   P    bvvvvvvv",
      "bbbbbbbbbaaaaaav",
      "aaaaaaaaaaaaaaav",
      "aaaaaaaaaaaaaaav",
      "vvvvvvvvvvvvvvvv"
    ]
  ]
}