{
  "name": "multi_gunstore_3_ground",
  "refpalette": "deceasedcraft:multi_gunstore_3/multi_gunstore_3_ground_palette",
  "xsize": 16,
  "zsize": 16,
  "slices": [
    [
      "HHHHHHHHHHHHHHHH",
      "HHHHHHHHHHHHHHHH",
      "aaaaaaaaaaaaaaaa",
      "bcccccbbbddddddd",
      "        bddddddd",
      "        bddddddd",
      "        bddddddd",
      "        bddddddd",
      "        bddddddd",
      "        bddddddd",
      "        bddddddd",
      " e      bddddddd",
      "bfffffbbbddddddd",
      "aaaaaaaaaaaaaaaa",
      "HHHHHHHHHHHHHHHH",
      "HHHHHHHHHHHHHHHH"
    ],
    [
      "                ",
      "                ",
      "                ",
      "bgggggbbbh      ",
      "i     i bh      ",
      "        bh      ",
      "       jbh      ",
      "        bh      ",
      "        bh      ",
      "       jbh      ",
      "        bh      ",
      "k     k bh      ",
      "bgggggbbbh      ",
      "                ",
      "                ",
      "                "
    ],
    [
      "                ",
      "                ",
      "llllllllll      ",
      "bbbbbbbbb       ",
      "        b       ",
      "        b       ",
      "       mb       ",
      "       nb       ",
      "       ob       ",
      "       pb       ",
      "       qb       ",
      "        b       ",
      "bbbbbbbbb       ",
      "rrrrrrrrrr      ",
      "                ",
      "                "
    ],
    [
      "                ",
      "                ",
      "ssssssssll      ",
      "bbbbbbbbb       ",
      "        b       ",
      "   t    b       ",
      "   u    b       ",
      "   u    b       ",
      "   u    b       ",
      "   u    b       ",
      "   w    b       ",
      "        b       ",
      "bbbbbbbbb       ",
      "ssssssssrr      ",
      "                ",
      "                "
    ],
    [
      "                ",
      "                ",
      "xsssssssyy      ",
      "AsssssssBB      ",
      "ssssssssBB      ",
      "CCCDCCCsBB      ",
      "CCCECCCsBB      ",
      "CCCECCCsBB      ",
      "CCCECCCsBB      ",
      "CCCECCCsBB      ",
      "CCCDCCCsBB      ",
      "ssssssssBB      ",
      "AsssssssBB      ",
      "xsssssssFF      ",
      "                ",
      "                "
    ],
    [
      "                ",
      "                ",
      " xxxxxxxxx      ",
      " xxxxxxxxx      ",
      "xxxxxxxxxx      ",
      "IIIIIJxxxx      ",
      "xxxxxxxxxx      ",
      "xxxxxxxxxx      ",
      "xxxxxxxxxx      ",
      "xxxxxxxxxx      ",
      "IIIIIJxxxx      ",
      "xxxxxxxxxx      ",
      " xxxxxxxxx      ",
      " xxxxxxxxx      ",
      "                ",
      "                "
    ]
  ]
}