{
  "name": "multi_sunkenclub_8_base1",
  "refpalette": "deceasedcraft:multi_sunkenclub_8/multi_sunkenclub_8_base1_palette",
  "xsize": 16,
  "zsize": 16,
  "slices": [
    [
      "  ab    ba    cv",
      "  abbbbbba     v",
      "aaaaaaaaaa    dv",
      "bbabbbbbba    ev",
      " bab    ba    cv",
      " bab    ba     v",
      " bab    ba    cv",
      " bab    ba    ev",
      "bbabbbbbba    cv",
      "aaaaaaaaaa    dv",
      "              ev",
      "              cv",
      "              ev",
      "               v",
      "eedeeee edce eev",
      "vvvvvvvvvvvvvvvv"
    ],
    [
      "fffffffffg    cv",
      "fffffffffg     v",
      "fffffffffg    dv",
      "fffffffffg     v",
      "fffffffffg    cv",
      "fffffffffg     v",
      "fffffffffg     v",
      "fffffffffg    ev",
      "fffffffffg    ev",
      "gggggggggg    dv",
      "              cv",
      "               v",
      "              ev",
      "               v",
      "e de e  cdce ecv",
      "vvvvvvvvvvvvvvvv"
    ],
    [
      "         h     v",
      "    i i ih     v",
      " jk !    d    dv",
      " jl   m  h     v",
      " jn  mom h     v",
      " jp m m  h     v",
      " jqmom m h     v",
      "rjs m momh     v",
      "tju    m h    ev",
      "hhdhhhhhhd    dv",
      "              cv",
      "               v",
      "               v",
      "               v",
      "  de e  cd e  cv",
      "vvvvvvvvvvvvvvvv"
    ],
    [
      "               v",
      "               v",
      " wx yyyyyd    dv",
      " w             v",
      " wA            v",
      " wB            v",
      " wC            v",
      " w             v",
      " w            ev",
      "  d      d    dv",
      "               v",
      "               v",
      "               v",
      "               v",
      "  de    cd    cv",
      "vvvvvvvvvvvvvvvv"
    ],
    [
      "               v",
      "               v",
      "         d    dv",
      "               v",
      "               v",
      "               v",
      "               v",
      "               v",
      "               v",
      "  d      d    dv",
      "               v",
      "               v",
      "               v",
      "               v",
      "  d      d    cv",
      "vvvvvvvvvvvvvvvv"
    ],
    [
      "bbbbbbbbb      v",
      "bbbbbbbbb      v",
      "bbbbDbbEbd    dv",
      "bbbbbbbbb      v",
      "bbEbbbbbb      v",
      "bbbbbbbbb      v",
      "bbbbbbbbb      v",
      "bbDbbbbEb      v",
      "bbbbbbbbb      v",
      "  d      d    dv",
      "               v",
      "               v",
      "               v",
      "               v",
      "  d      d     v",
      "vvvvvvvvvvvvvvvv"
    ]
  ]
}