{
  "name": "multi_sunkenclub_8_base2",
  "refpalette": "deceasedcraft:multi_sunkenclub_8/multi_sunkenclub_8_base2_palette",
  "xsize": 16,
  "zsize": 16,
  "slices": [
    [
      "vvvvvvvvvvvvvvvv",
      "vvvvvvvvvvvvvvvv",
      "vvvvvvvvvvvvvvvv",
      "aaaaaaaaavvvvvvv",
      "aaaaaaaaavvvvvvv",
      "aaaaaaaaavvvvvvv",
      "aaaaaaaaavvvvvvv",
      "aaaaaaaaavvvvvvv",
      "aaaaaaaaavvvvvvv",
      "vvvvvvvvvvvvvvvv",
      "vvvvvvvvvvvvvvvv",
      "vvvvvvvvvvvvvvvv",
      "vvvvvvvvvvvvvvvv",
      "vvvvvvvvvvvvvvvv",
      "vvvvvvvvvvvvvvvv",
      "vvvvvvvvvvvvvvvv"
    ],
    [
      "bccccccccccdcbev",
      "ccccccccccbdcbev",
      "aafaaaaaafdccghv",
      "iijiijjijaddcbev",
      "jiiijiiijaddcbev",
      "iiiiiiiiiadbcbev",
      "iiiiiiiijaddcbev",
      "iiiijiiiiaddcbev",
      "ijijiijijabdcbev",
      "aafaaaaaafddckhv",
      "dddddbdcddddcbev",
      "dbcdddbdddbccbev",
      "cccccccccccccbev",
      "bbkbbbbbbgbbbbev",
      "eeheeeeeeheeeeev",
      "vvvvvvvvvvvvvvvv"
    ],
    [
      "lm          nopv",
      "mm q q      ropv",
      "  f      f qn hv",
      "     s      n pv",
      "            topv",
      "   s   s    ropv",
      "s s         n pv",
      "            nopv",
      "s    s      ropv",
      "  f      f  n hv",
      "            rupv",
      "  q        qtopv",
      "nrnnntntnrnnn pv",
      "oo o oooo o oopv",
      "pphpppppphpppppv",
      "vvvvvvvvvvvvvvvv"
    ],
    [
      "w            xpv",
      "             xpv",
      "  f      f    hv",
      "              pv",
      "             xpv",
      "             xyv",
      "              pv",
      "             xpv",
      "             xpv",
      "  f      f    hv",
      "             ABv",
      "             xpv",
      "              pv",
      "xx x xxxx x xxpv",
      "pyhppyppphpppppv",
      "vvvvvvvvvvvvvvvv"
    ],
    [
      "              yv",
      "              pv",
      "  f      f    hv",
      "              pv",
      "              yv",
      "              yv",
      "              pv",
      "              pv",
      "              yv",
      "  f      f    hv",
      "              yv",
      "              pv",
      "              pv",
      "              pv",
      "pyhyppppphyppppv",
      "vvvvvvvvvvvvvvvv"
    ],
    [
      "              yv",
      "              pv",
      "  f      f    hv",
      "              pv",
      "              yv",
      "              yv",
      "              yv",
      "              pv",
      "              yv",
      "  f      f    hv",
      "              pv",
      "              pv",
      "              pv",
      "              pv",
      "pphypppyphyppppv",
      "vvvvvvvvvvvvvvvv"
    ]
  ]
}