{
  "name": "multi_sunkenclub_8_ground",
  "refpalette": "deceasedcraft:multi_sunkenclub_8/multi_sunkenclub_8_ground_palette",
  "xsize": 16,
  "zsize": 16,
  "slices": [
    [
      "aaaabbabacddddce",
      "abaabaaaacddddce",
      "aabaabaaecffffce",
      "babbbaaaacddddce",
      "ababaabaacddddce",
      "baaaaaaagcddddce",
      "aaabaaaahcddddce",
      "aaaaaaaiicddddce",
      "aaeaahihicddddce",
      "ccccccccccffffce",
      "ddfddddddfddddce",
      "ddfddddddfddddce",
      "ddfddddddfddddce",
      "ddfddddddfddddce",
      "ccccccccccccccce",
      "eeeeeeeeeeeeeeee"
    ],
    [
      "~~~~~~~~~jk~~kj~",
      "~~~~~~~~~jk~~kj~",
      "~~~~~~~~lmk~~km~",
      "~~~~~~~~~jk~~kj~",
      "~~~~~~~~~jk~~kj~",
      "~~~~~~~~~jk~~kj~",
      "~~~~~~~~~jk~~kj~",
      "~~~~~~~~~jk~~kj~",
      "~~l~~~~~~jk~~kj~",
      "jjmjjjjjjmk~~km~",
      "kkkkkkkkkkk~~kj~",
      "~~~~~~~~~~~~~kj~",
      "~~~~~~~~~~~~~kj~",
      "kkkkkkkkkkkkkkj~",
      "jjmjjjjjjmjjjjj~",
      "~~~~~~~~~~~~~~~~"
    ],
    [
      "~~~~~~~~~~~~~~~~",
      "~~~~~~~~~~~~~~~~",
      "~~~~~~~~~~~~~~n~",
      "~~~~~~~~~~~~~~~~",
      "~~~~~~~~~~~~~~~~",
      "~~~~~~~~~~~~~~~~",
      "~~~~~~~~~~~~~~~~",
      "~~~~~~~~~~~~~~~~",
      "~~~~~~~~~~~~~~~~",
      "~~n~~~~~~n~~~~~~",
      "~~~~~~~~~~~~~~~~",
      "~~~~~~~~~~~~~~~~",
      "~~~~~~~~~~~~~~~~",
      "~~~~~~~~~~~~~~~~",
      "~~~~~~~~~~~~~~~~",
      "~~~~~~~~~~~~~~~~"
    ],
    [
      "~~~~~~~~~~~~~~~~",
      "~~~~~~~~~~~~~~~~",
      "~~~~~~~~~~~~~~~~",
      "~~~~~~~~~~~~~~~~",
      "~~~~~~~~~~~~~~~~",
      "~~~~~~~~~~~~~~~~",
      "~~~~~~~~~~~~~~~~",
      "~~~~~~~~~~~~~~~~",
      "~~~~~~~~~~~~~~~~",
      "~~~~~~~~~~~~~~~~",
      "~~~~~~~~~~~~~~~~",
      "~~~~~~~~~~~~~~~~",
      "~~~~~~~~~~~~~~~~",
      "~~~~~~~~~~~~~~~~",
      "~~~~~~~~~~~~~~~~",
      "~~~~~~~~~~~~~~~~"
    ],
    [
      "~~~~~~~~~~~~~~~~",
      "~~~~~~~~~~~~~~~~",
      "~~~~~~~~~~~~~~~~",
      "~~~~~~~~~~~~~~~~",
      "~~~~~~~~~~~~~~~~",
      "~~~~~~~~~~~~~~~~",
      "~~~~~~~~~~~~~~~~",
      "~~~~~~~~~~~~~~~~",
      "~~~~~~~~~~~~~~~~",
      "~~~~~~~~~~~~~~~~",
      "~~~~~~~~~~~~~~~~",
      "~~~~~~~~~~~~~~~~",
      "~~~~~~~~~~~~~~~~",
      "~~~~~~~~~~~~~~~~",
      "~~~~~~~~~~~~~~~~",
      "~~~~~~~~~~~~~~~~"
    ],
    [
      "~~~~~~~~~~~~~~~~",
      "~~~~~~~~~~~~~~~~",
      "~~~~~~~~~~~~~~~~",
      "~~~~~~~~~~~~~~~~",
      "~~~~~~~~~~~~~~~~",
      "~~~~~~~~~~~~~~~~",
      "~~~~~~~~~~~~~~~~",
      "~~~~~~~~~~~~~~~~",
      "~~~~~~~~~~~~~~~~",
      "~~~~~~~~~~~~~~~~",
      "~~~~~~~~~~~~~~~~",
      "~~~~~~~~~~~~~~~~",
      "~~~~~~~~~~~~~~~~",
      "~~~~~~~~~~~~~~~~",
      "~~~~~~~~~~~~~~~~",
      "~~~~~~~~~~~~~~~~"
    ]
  ]
}