{
  "name": "multi_hospital_5_base4",
  "refpalette": "deceasedcraft:multi_hospital_5/multi_hospital_5_base4_palette",
  "xsize": 16,
  "zsize": 16,
  "slices": [
    [
      "abbbbbbbbbbbbbbv",
      "abbbbbbbbbbbbbbv",
      "abbbbbbbbbbbbbbv",
      "abbbbbbbbbbbbbbv",
      "abbbbbbbbbbbbbbv",
      "abbbbbbbbbbbbbbv",
      "bbbbbbbbbbbbbbbv",
      "bbbbbbbbbbbbbbbv",
      "bbbbbbbbbbbbbbbv",
      "bbbbbbbbbbbbbbbv",
      "bbbbbbbbbbbbbbbv",
      "bbbbbbbbbbbbbbbv",
      "bbbbbbbbbbbbbbbv",
      "bbbbbbbbbbbbbbbv",
      "bbbbbbbbbbbbbbbv",
      "vvvvvvvvvvvvvvvv"
    ],
    [
      "abbbbbbbbbbbbbbv",
      "abbbbbbbbbbbbbbv",
      "abbbbbbbbbbbbbbv",
      "abbbbbbbbbbbbbbv",
      "abbbbbbbbbbbbbbv",
      "abbbbbbbbbbbbbbv",
      "bbbbbbbbbbbbbbbv",
      "bbbbbbbbbbbbbbbv",
      "bbbbbbbbbbbbbbbv",
      "bbbbbbbbbbbbbbbv",
      "bbbbbbbbbbbbbbbv",
      "bbbbbbbbbbbbbbbv",
      "bbbbbbbbbbbbbbbv",
      "bbbbbbbbbbbbbbbv",
      "bbbbbbbbbbbbbbbv",
      "vvvvvvvvvvvvvvvv"
    ],
    [
      "abbbbbbbbbbbbbbv",
      "abbbbbbbbbbbbbbv",
      "abbbbbbbbbbbbbbv",
      "abbbbbbbbbbbbbbv",
      "ccbbbbbbbbbbbbbv",
      "abbbbbbbbbbbbbbv",
      "bbbbbbbbbbbbbbbv",
      "bbbbbbbbbbbbbbbv",
      "bbbbbbbbbbbbbbbv",
      "bbbbbbbbbbbbbbbv",
      "bbbbbbbbbbbbbbbv",
      "bbbbbbbbbbbbbbbv",
      "bbbbbbbbbbbbbbbv",
      "bbbbbbbbbbbbbbbv",
      "bbbbbbbbbbbbbbbv",
      "vvvvvvvvvvvvvvvv"
    ],
    [
      "abbbbbbbbbbbbbbv",
      "abbbbbbbbbbbbbbv",
      "abbbbbbbbbbbbbbv",
      "abbbbbbbbbbbbbbv",
      "acbbbbbbbbbbbbbv",
      "acbbbbbbbbbbbbbv",
      "ccbbbbbbbbbbbbbv",
      "bbbbbbbbbbbbbbbv",
      "bbbbbbbbbbbbbbbv",
      "bbbbbbbbbbbbbbbv",
      "bbbbbbbbbbbbbbbv",
      "bbbbbbbbbbbbbbbv",
      "bbbbbbbbbbbbbbbv",
      "bbbbbbbbbbbbbbbv",
      "bbbbbbbbbbbbbbbv",
      "vvvvvvvvvvvvvvvv"
    ],
    [
      "addbbbbbbbbbbbbv",
      "addbbbbbbbbbbbbv",
      "abbbbbbbbbbbbbbv",
      "abbbbbbbbbbbbbbv",
      "abbbbbbbbbbbbbbv",
      "abbbbbbbbbbbbbbv",
      "bbbbbbbbbbbbbbbv",
      "bbbbbbbbbbbbbbbv",
      "bbbbbbbbbbbbbbbv",
      "bbbbbbbbbbbbbbbv",
      "bbbbbbbbbbbbbbbv",
      "bbbbbbbbbbbbbbbv",
      "bbbbbbbbbbbbbbbv",
      "bbbbbbbbbbbbbbbv",
      "bbbbbbbbbbbbbbbv",
      "vvvvvvvvvvvvvvvv"
    ],
    [
      "addbbbbbbbbbbbbv",
      "addbbbbbbbbbbbbv",
      "abbbbbbbbbbbbbbv",
      "abbbbbbbbbbbbbbv",
      "abbbbbbbbbbbbbbv",
      "abbbbbbbbbbbbbbv",
      "bbbbbbbbbbbbbbbv",
      "bbbbbbbbbbbbbbbv",
      "bbbbbbbbbbbbbbbv",
      "bbbbbbbbbbbbbbbv",
      "bbbbbbbbbbbbbbbv",
      "bbbbbbbbbbbbbbbv",
      "bbbbbbbbbbbbbbbv",
      "bbbbbbbbbbbbbbbv",
      "bbbbbbbbbbbbbbbv",
      "vvvvvvvvvvvvvvvv"
    ]
  ]
}