{
  "name": "multi_hospital_5_base1",
  "refpalette": "deceasedcraft:multi_hospital_5/multi_hospital_5_base1_palette",
  "xsize": 16,
  "zsize": 16,
  "slices": [
    [
      "ab           bcv",
      "ac           ccv",
      "ac           ccv",
      "ad           cev",
      "ac           ccv",
      "fff         ffcv",
      "              cv",
      "              cv",
      "f             cv",
      "g             cv",
      "g             cv",
      "g             cv",
      "f             cv",
      "cccccccccccccccv",
      "hiiiiiiiiiiiiiiv",
      "vvvvvvvvvvvvvvvv"
    ],
    [
      "fb           bcv",
      "jc           ccv",
      " c           ccv",
      " k           cev",
      "lc           ccv",
      "fffmmmmmmmmmffcv",
      "              cv",
      "              cv",
      "f             cv",
      "f             cv",
      "f             cv",
      "f             cv",
      "f             cv",
      "cccccccccccccccv",
      "hiiiiiiiiiiiiiiv",
      "vvvvvvvvvvvvvvvv"
    ],
    [
      "fb           bcv",
      "nc           ccv",
      " c           ccv",
      " k           cev",
      " c           ccv",
      "fffmmmmmmmmmffcv",
      "              cv",
      "              cv",
      "f             cv",
      "f             cv",
      "f             cv",
      "f             cv",
      "f             cv",
      "cccccccccccccccv",
      "hiiiiiiiiiiiiiiv",
      "vvvvvvvvvvvvvvvv"
    ],
    [
      "fb           bcv",
      " c           ccv",
      " c           ccv",
      " k           cov",
      "pc qqqqqqqqq ccv",
      "ffffffffffffffcv",
      "              cv",
      "              cv",
      "f             cv",
      "f             cv",
      "f             cv",
      "f             cv",
      "f             cv",
      "cccccccccccccccv",
      "hiiiiiiiiiiiiiiv",
      "vvvvvvvvvvvvvvvv"
    ],
    [
      "fbrrrrrrrrrrrbcv",
      "rcrrrrrrrrrrrccv",
      "rcrrrrrrrrrrrccv",
      "rrrrrrrrrrrrrrcv",
      "rcrrrrrrrrrrrccv",
      "ffffffffffffffcv",
      "              cv",
      "              cv",
      "f             cv",
      "f             cv",
      "f             cv",
      "f             cv",
      "f             cv",
      "cccccccccccccccv",
      "hiiiiiiiiiiiiiiv",
      "vvvvvvvvvvvvvvvv"
    ],
    [
      "fssssssssssssbcv",
      "sssssssssssssccv",
      "sssssssssssssccv",
      "sssssssssssssccv",
      "sssssssssssssccv",
      "fssssssssssssfcv",
      "sssssssssssssscv",
      "sssssssssssssscv",
      "fssssssssssssscv",
      "fssssssssssssscv",
      "fssssssssssssscv",
      "fssssssssssssscv",
      "fssssssssssssscv",
      "cccccccccccccccv",
      "hiiiiiiiiiiiiiiv",
      "vvvvvvvvvvvvvvvv"
    ]
  ]
}