{
  "name": "multi_hospital_5_top",
  "refpalette": "deceasedcraft:multi_hospital_5/multi_hospital_5_top_palette",
  "xsize": 16,
  "zsize": 16,
  "slices": [
    [
      "abbcccbbcccbbd  ",
      "abbcccbbcccbbd  ",
      "abbcccbbcccbbd  ",
      "abbcccbbcccbbd  ",
      "abbcccbbcccbbd  ",
      "abbcccbbcccbbd  ",
      "aeeeeeeeeeeeed  ",
      "fgh          i  ",
      "agh             ",
      "jgh             ",
      "jgh             ",
      "jgh             ",
      "agh             ",
      "kgh             ",
      "                ",
      "                "
    ],
    [
      "lgmnnnoonnnoo   ",
      "pgmnnnoonnnoo   ",
      "lgmnnnoonnnoo   ",
      "qgmnnnoonnnoo   ",
      "qgmnnnoonnnoo   ",
      "qgmnnnoonnnoo   ",
      "lgmoooooooooo   ",
      "pgiiiiiiiiiiii  ",
      "agh             ",
      "agh             ",
      "agh             ",
      "agh             ",
      "agh             ",
      "kgh             ",
      "                ",
      "                "
    ],
    [
      "rgh             ",
      "ggh             ",
      " gh             ",
      "sgh             ",
      " gh             ",
      "tgh             ",
      "ugh             ",
      "ggh             ",
      "agh             ",
      "agh             ",
      "agh             ",
      "agh             ",
      "agh             ",
      "kgh             ",
      "                ",
      "                "
    ],
    [
      " a              ",
      "ga              ",
      " a              ",
      " w              ",
      " w              ",
      " w              ",
      " a              ",
      "ga              ",
      "agh             ",
      "agh             ",
      "agh             ",
      "agh             ",
      "agh             ",
      "kgh             ",
      "                ",
      "                "
    ],
    [
      " gh             ",
      "ggh             ",
      " gh             ",
      " gh             ",
      " gh             ",
      " gh             ",
      " gh             ",
      "ggh             ",
      "agh             ",
      "agh             ",
      "agh             ",
      "agh             ",
      "agh             ",
      "kgh             ",
      "                ",
      "                "
    ],
    [
      " gh             ",
      "ggh             ",
      " gh             ",
      " gh             ",
      " gh             ",
      " gh             ",
      " gh             ",
      "ggh             ",
      "agh             ",
      "agh             ",
      "agh             ",
      "agh             ",
      "agh             ",
      "kgh             ",
      "                ",
      "                "
    ],
    [
      "igh             ",
      "igh             ",
      "igh             ",
      "igh             ",
      "igh             ",
      "igh             ",
      "igh             ",
      "igh             ",
      "agh             ",
      "jgh             ",
      "jgh             ",
      "jgh             ",
      "agh             ",
      "kgh             ",
      "                ",
      "                "
    ],
    [
      " x              ",
      "yx              ",
      " x              ",
      "yx              ",
      " x              ",
      "Ax              ",
      " x              ",
      "yx              ",
      "ak              ",
      "a               ",
      "ak              ",
      "a               ",
      "ak              ",
      "k               ",
      "                ",
      "                "
    ],
    [
      " x              ",
      " x              ",
      " x              ",
      " x              ",
      " x              ",
      " x              ",
      " x              ",
      " x              ",
      "ak              ",
      "a               ",
      "ak              ",
      "a               ",
      "ak              ",
      "k               ",
      "                ",
      "                "
    ],
    [
      " w              ",
      " w              ",
      " w              ",
      " w              ",
      " w              ",
      " w              ",
      " x              ",
      " x              ",
      "ak              ",
      "a               ",
      "ak              ",
      "a               ",
      "ak              ",
      "k               ",
      "                ",
      "                "
    ],
    [
      " x              ",
      " x              ",
      " x              ",
      " x              ",
      " x              ",
      " x              ",
      " x              ",
      " x              ",
      "ak              ",
      "a               ",
      "ak              ",
      "a               ",
      "ak              ",
      "k               ",
      "                ",
      "                "
    ],
    [
      "ixB             ",
      "ixB             ",
      "ixB             ",
      "ixB             ",
      "ixB             ",
      "ixB             ",
      "ixB             ",
      "ixB             ",
      "axB             ",
      "axB             ",
      "axB             ",
      "axB             ",
      "axB             ",
      "xxB             ",
      "BBB             ",
      "                "
    ],
    [
      "C C             ",
      "C C             ",
      "C C             ",
      "C C             ",
      "C C             ",
      "C C             ",
      "C C             ",
      "C C             ",
      "C C             ",
      "C C             ",
      "C C             ",
      "C C             ",
      "C C             ",
      "  C             ",
      "CCC             ",
      "                "
    ]
  ]
}