{
  "name": "multi_hospital_5_base2",
  "refpalette": "deceasedcraft:multi_hospital_5/multi_hospital_5_base2_palette",
  "xsize": 16,
  "zsize": 16,
  "slices": [
    [
      "abbccccccccccccv",
      "abbccccccccccccv",
      "dccccccccccccccv",
      "dccccccccccccccv",
      "dccccccccccccccv",
      "dccccccccccccccv",
      "cccccccccccccccv",
      "cccccccccccccccv",
      "dccccccccccccccv",
      "eccccccccccccccv",
      "eccccccccccccccv",
      "eccccccccccccccv",
      "dccccccccccccccv",
      "fccccccccccccccv",
      "bccccccccccccccv",
      "vvvvvvvvvvvvvvvv"
    ],
    [
      "abbccccccccccccv",
      "abbccccccccccccv",
      "dccccccccccccccv",
      "dccccccccccccccv",
      "dccccccccccccccv",
      "dccccccccccccccv",
      "cccccccccccccccv",
      "cccccccccccccccv",
      "dccccccccccccccv",
      "dccccccccccccccv",
      "dccccccccccccccv",
      "dccccccccccccccv",
      "dccccccccccccccv",
      "fccccccccccccccv",
      "bccccccccccccccv",
      "vvvvvvvvvvvvvvvv"
    ],
    [
      "ddddddddddddddfv",
      "ddddddddddddddfv",
      "ddddddddddddddfv",
      "ddddddddddddddfv",
      "ddddddddddddddfv",
      "ddddddddddddddfv",
      "ddddddddddddddfv",
      "ddddddddddddddfv",
      "ddddddddddddddfv",
      "ddddddddddddddfv",
      "ddddddddddddddfv",
      "ddddddddddddddfv",
      "ddddddddddddddfv",
      "fffffffffffffffv",
      "bccccccccccccccv",
      "vvvvvvvvvvvvvvvv"
    ],
    [
      "dgghhggggghhggfv",
      "dfghhhhhhhhhgffv",
      "dfghhhhhhhhhgffv",
      "dihhhhhhhhhhhifv",
      "dfhhhhhhhhhhhffv",
      "dddjjjjjjjjjddfv",
      "eeeeeeeeeeeeeefv",
      "eeeeeeeeeeeeeefv",
      " eeeeeeeeeeeeefv",
      "eeeeeeeeeeeeeefv",
      "eeeeeeeeeeeeeefv",
      "eeeeeeeeeeeeeefv",
      "deeeeeeeeeeeeefv",
      "fffffffffffffffv",
      "bccccccccccccccv",
      "vvvvvvvvvvvvvvvv"
    ],
    [
      "dgk  lllll  mgfv",
      "dfn         offv",
      "dfn         offv",
      "dp          qfav",
      "dfq          ffv",
      "ddd         ddfv",
      "r       s    tfv",
      "r  s u u u   tfv",
      "dw  xyyyyyx  Afv",
      "B  CDEEEEEFI Jfv",
      "K   xLLLLLx  Mfv",
      "N  O P P P   tfv",
      "d     Q      tfv",
      "fffffffffffffffv",
      "bccccccccccccccv",
      "vvvvvvvvvvvvvvvv"
    ],
    [
      "dg   RSTU    gfv",
      "dfV         Wffv",
      "dfX         Yffv",
      "dp          Zfav",
      "dfZ          ffv",
      "ddd         ddfv",
      "             0fv",
      "             Wfv",
      "d    1T2T 3  4fv",
      "B   5     Q  6fv",
      "7     Q  O8   fv",
      "9            #fv",
      "d             fv",
      "fffffffffffffffv",
      "bccccccccccccccv",
      "vvvvvvvvvvvvvvvv"
    ]
  ]
}