{
  "name": "multi_hospital_5_base3",
  "refpalette": "deceasedcraft:multi_hospital_5/multi_hospital_5_base3_palette",
  "xsize": 16,
  "zsize": 16,
  "slices": [
    [
      "abbccccccccccccv",
      "abbccccccccccccv",
      "accccccccccccccv",
      "accccccccccccccv",
      "accccccccccccccv",
      "accccccccccccccv",
      "cccccccccccccccv",
      "cccccccccccccccv",
      "cccccccccccccccv",
      "cccccccccccccccv",
      "cccccccccccccccv",
      "cccccccccccccccv",
      "cccccccccccccccv",
      "cccccccccccccccv",
      "cccccccccccccccv",
      "vvvvvvvvvvvvvvvv"
    ],
    [
      "abbccccccccccccv",
      "abbccccccccccccv",
      "accccccccccccccv",
      "accccccccccccccv",
      "accccccccccccccv",
      "accccccccccccccv",
      "cccccccccccccccv",
      "cccccccccccccccv",
      "cccccccccccccccv",
      "cccccccccccccccv",
      "cccccccccccccccv",
      "cccccccccccccccv",
      "cccccccccccccccv",
      "cccccccccccccccv",
      "cccccccccccccccv",
      "vvvvvvvvvvvvvvvv"
    ],
    [
      "abbccccccccccccv",
      "abbccccccccccccv",
      "accccccccccccccv",
      "accccccccccccccv",
      "accccccccccccccv",
      "accccccccccccccv",
      "cccccccccccccccv",
      "cccccccccccccccv",
      "cccccccccccccccv",
      "cccccccccccccccv",
      "cccccccccccccccv",
      "cccccccccccccccv",
      "cccccccccccccccv",
      "cccccccccccccccv",
      "cccccccccccccccv",
      "vvvvvvvvvvvvvvvv"
    ],
    [
      "abbccccccccccccv",
      "abbccccccccccccv",
      "accccccccccccccv",
      "accccccccccccccv",
      "accccccccccccccv",
      "accccccccccccccv",
      "cccccccccccccccv",
      "cccccccccccccccv",
      "cccccccccccccccv",
      "cccccccccccccccv",
      "cccccccccccccccv",
      "cccccccccccccccv",
      "cccccccccccccccv",
      "cccccccccccccccv",
      "cccccccccccccccv",
      "vvvvvvvvvvvvvvvv"
    ],
    [
      "dbbccccccccccccv",
      "dbbccccccccccccv",
      "accccccccccccccv",
      "accccccccccccccv",
      "accccccccccccccv",
      "accccccccccccccv",
      "cccccccccccccccv",
      "cccccccccccccccv",
      "cccccccccccccccv",
      "cccccccccccccccv",
      "cccccccccccccccv",
      "cccccccccccccccv",
      "cccccccccccccccv",
      "cccccccccccccccv",
      "cccccccccccccccv",
      "vvvvvvvvvvvvvvvv"
    ],
    [
      "dbbccccccccccccv",
      "dbbccccccccccccv",
      "accccccccccccccv",
      "accccccccccccccv",
      "accccccccccccccv",
      "accccccccccccccv",
      "cccccccccccccccv",
      "cccccccccccccccv",
      "accccccccccccccv",
      "accccccccccccccv",
      "accccccccccccccv",
      "accccccccccccccv",
      "accccccccccccccv",
      "eccccccccccccccv",
      "bccccccccccccccv",
      "vvvvvvvvvvvvvvvv"
    ]
  ]
}