{
  "name": "multi_hospital_5_ground",
  "refpalette": "deceasedcraft:multi_hospital_5/multi_hospital_5_ground_palette",
  "xsize": 16,
  "zsize": 16,
  "slices": [
    [
      "a bcdce ddd  fgg",
      "a  ddd  ddd  fgg",
      "a  ddd  ddd  fgg",
      "a  ddd bcdce fgg",
      "h bcdce ddd  fgg",
      "h  ddd       fgg",
      "h   i        fgg",
      "hjkllllllllkjmgg",
      " aaaaaaaaaaaa gg",
      "aaaaaaaaaaaaa gg",
      "aaaaaaaaaaaaa gg",
      "aaaaaaaaaaaaa gg",
      "haaaaaaaaaaaa gg",
      "aaaaaaaaaaaaaagg",
      "gggggggggggggggg",
      "gggggggggggggggg"
    ],
    [
      "n  opq rstsu wx ",
      "n rstsuy  AB wx ",
      "n y  CByD CB wx ",
      "n yD EByF IB wx ",
      "h yF IBrJKJB wx ",
      "h rJLJB M M  wx ",
      "h  N N       wx ",
      "hj          jmx ",
      "hO          P x ",
      "Q     R     P x ",
      "S   R   RTR P x ",
      "U    V TWX TP x ",
      "hPPPPPPPPPPPP x ",
      "Y             x ",
      "xxxxxxxxxxxxxxZ ",
      "                "
    ],
    [
      "n 0111234546 w  ",
      "n 34!4637  6 w  ",
      "n 37  638  6 w  ",
      "n 38  639 #6 w  ",
      "h 39 #63$%$6 w  ",
      "h 3$^$6      w  ",
      "h            w  ",
      "hj          jm  ",
      "h           &   ",
      "Q           &   ",
      "*           &   ",
      "(        W  &   ",
      "h&&&&&&&&&&&&   ",
      "Y               ",
      "                ",
      "                "
    ],
    [
      "n  )+) rs-su n  ",
      "n rs-suy[] B n  ",
      "n y{] By[] B n  ",
      "n y}] By[] B n  ",
      "h y[] Br|]|u n  ",
      "h r|]|u ;:;  n  ",
      "h  ;:;       w  ",
      "hj          jm  ",
      "h           &   ",
      "Q           &   ",
      "Q           &   ",
      "Q           &   ",
      "h&&nnnhnnn&&&   ",
      "Y               ",
      "                ",
      "                "
    ],
    [
      "n       ' '  n  ",
      "n  ' '  <<<  n  ",
      "n  <<<  < <  n  ",
      "n  < <  < <  n  ",
      "h  < <  < <  n  ",
      "h  < <       n  ",
      "h            w  ",
      "hjjjjjjjjjjjjm  ",
      "hjmmmmmmmmmj>   ",
      "hjmmmmmmmmmj>   ",
      "hjmmmmmmmmmj>   ",
      "hjjjjjjjjjjj>   ",
      "h>>>>>>>>>>>>   ",
      "Y               ",
      "                ",
      "                "
    ],
    [
      "h            w  ",
      "h            w  ",
      "h            w  ",
      "h            w  ",
      "h            w  ",
      "h            w  ",
      "h,,,,,,,,,,,,w  ",
      "h............m  ",
      "h.         ..   ",
      "h.         ..   ",
      "h.         ..   ",
      "h............   ",
      "h............   ",
      "Y               ",
      "                ",
      "                "
    ]
  ]
}