{
  "name": "multi_filmworkstower_5_floor2",
  "refpalette": "deceasedcraft:multi_filmworkstower_5/multi_filmworkstower_5_floor2_palette",
  "xsize": 16,
  "zsize": 16,
  "slices": [
    [
      "a      bcccccccc",
      "a      bcccccccc",
      "a      bcccccccc",
      "a      bcccccccc",
      "a      bcccccccc",
      "a      bcccccccc",
      "a    d bcccccccc",
      "a    eeecccccccc",
      "a    fffgccccccc",
      "a    f   ccccccc",
      "a    f  fccccccc",
      "a    f  fccccccc",
      "h    ffffccccccc",
      "ijjjjjjjjjjjjjjj",
      "ifffffffffffffff",
      "iiiiiiiiiiiiiiii"
    ],
    [
      "ka     l  mn o p",
      "fa     l  m  o q",
      "ka     l  mn o r",
      "ka     l  m     ",
      "fa     l        ",
      "ka   d l     mmm",
      "ka  stul        ",
      "fa  w xx       y",
      "ka   ffff   AB  ",
      "ka   f  fC  DB o",
      "fa   f  EF  IB  ",
      "ka   f  EJ     K",
      " h   ffff       ",
      " iLLLLLLLLLLLLLL",
      " i              ",
      " iiiiiiiiiiiiiii"
    ],
    [
      " ka       L     ",
      "kfa       L     ",
      " ka       L     ",
      " ka       L     ",
      "kfa  d          ",
      " ka stu      LLL",
      " ka             ",
      "kfa             ",
      " ka  ffff   !B  ",
      " ka  f  f   MB  ",
      "kfa  f   N  OB  ",
      " ka  f   P      ",
      "  h  ffff       ",
      "  i             ",
      "  i             ",
      "  iiiiiiiiiiiiii"
    ],
    [
      "  kQ            ",
      " kfQ            ",
      "  kQ            ",
      "  kQ d          ",
      " kfQwtu         ",
      "  kQ            ",
      "  kQ            ",
      " kfQ            ",
      "  kQ ffff       ",
      "  kQ f  f       ",
      " kfQ f  RS      ",
      "  kQ f  RS      ",
      "   h ffff       ",
      "   i            ",
      "   i            ",
      "   iiiiiiiiiiiii"
    ],
    [
      "  Tj            ",
      "  fj            ",
      "  Tj d          ",
      "  Tjstu         ",
      "  fj            ",
      "  Tj            ",
      "  Tj            ",
      "  fj            ",
      "  Tj ffff       ",
      "  Tj f  f       ",
      "  fj f  f       ",
      "  Tj f  f       ",
      "   h ffff       ",
      "   i            ",
      "   i            ",
      "   iiiiiiiiiiiii"
    ],
    [
      "   fQ           ",
      "  TfQd          ",
      "   fQtu         ",
      "   fQ           ",
      "  TfQ           ",
      "   fQ           ",
      "   fQ           ",
      "  TfQ           ",
      "   fQffff       ",
      "   fQf  f       ",
      "  TfQf  f       ",
      "   fQf  f       ",
      "    hffff       ",
      "    i           ",
      "    i           ",
      "    iiiiiiiiiiii"
    ]
  ]
}