{
  "name": "multi_filmworkstower_5_floor4",
  "refpalette": "deceasedcraft:multi_filmworkstower_5/multi_filmworkstower_5_floor4_palette",
  "xsize": 16,
  "zsize": 16,
  "slices": [
    [
      "   ab   cddddddd",
      "   cb   cddddddd",
      "   ab   cddddddd",
      "   ab   cddddddd",
      "   cb   cddddddd",
      "   ab   cddddddd",
      "   a  efcddddddd",
      "   cb ghcddddddd",
      "   acccciddddddd",
      "   ajc   ddddddd",
      "   cjc  cddddddd",
      "   ajc  cddddddd",
      "    kccccddddddd",
      "    lddddddddddd",
      "    lddddddddddd",
      "    llllllllllll"
    ],
    [
      "   ab   m   n   ",
      "   cb   m   o   ",
      "   ab   m      p",
      "   a    m      p",
      "   cb   m       ",
      "   a    m   q   ",
      "   a  r m   n   ",
      "   c gs         ",
      "   acccct   o   ",
      "   au@  cw     p",
      "   cu@  xy      ",
      "   au@  xA  q   ",
      "    kcccc   n   ",
      "    l       o   ",
      "    l           ",
      "    llllllllllll"
    ],
    [
      "   ab       B   ",
      "   cb           ",
      "   a            ",
      "   a            ",
      "   c            ",
      "   a            ",
      "   aCr      D   ",
      "   chs          ",
      "   accccE       ",
      "   au@  c       ",
      "   cu@   F      ",
      "   au@   I      ",
      "    kcccc   J   ",
      "    l           ",
      "    l           ",
      "    llllllllllll"
    ],
    [
      "   a            ",
      "   c            ",
      "   a            ",
      "   a            ",
      "   c            ",
      "   aC           ",
      "   aKm          ",
      "   c            ",
      "   accccL       ",
      "   au@  c       ",
      "   cu@  MN      ",
      "   au@  MN      ",
      "    kcccc       ",
      "    l           ",
      "    l           ",
      "    llllllllllll"
    ],
    [
      "   a            ",
      "   c            ",
      "   a            ",
      "   a            ",
      "   chO          ",
      "   aKm          ",
      "   a            ",
      "   c            ",
      "   akccc        ",
      "   au@  c       ",
      "   cu@  c       ",
      "   au@  c       ",
      "    kcccc       ",
      "    l           ",
      "    l           ",
      "    llllllllllll"
    ],
    [
      "   aPQQQcQQQQQQQ",
      "   cPQQQcQQQQQQQ",
      "   aPQQQcQQQQQQQ",
      "   aPQQQcQQQRQQQ",
      "   c SO cQQQQQQQ",
      "   a T  cQQQQQQQ",
      "   a    cQQQQQQQ",
      "   c    cQQQQQQQ",
      "   akccccQQQRQQQ",
      "   au@  cQQQQQQQ",
      "   cu@  cQQQQQQQ",
      "   au@  cQQQQQQQ",
      "    kccccccccccc",
      "    lQQQRQQQRQQQ",
      "    lQQQQQQQQQQQ",
      "    llllllllllll"
    ]
  ]
}