{
  "name": "multi_filmworkstower_5_floor9",
  "refpalette": "deceasedcraft:multi_filmworkstower_5/multi_filmworkstower_5_floor9_palette",
  "xsize": 16,
  "zsize": 16,
  "slices": [
    [
      "   abbbbcddddddd",
      "   cbbbbcddddddd",
      "   abbbbcddddddd",
      "   acccccddddddd",
      "   c  efcddddddd",
      "   a  gfcddddddd",
      "   a   fcddddddd",
      "   c  hfcddddddd",
      "   acccciddddddd",
      "   ajc   ddddddd",
      "   cjc  cddddddd",
      "   ajc  cddddddd",
      "    kccccddddddd",
      "    lfffcddddddd",
      "    lfffcddddddd",
      "    llllllllllll"
    ],
    [
      "   a  m c       ",
      "   c no p    q  ",
      "   ar s c    qtu",
      "   accccw    qxy",
      "   c    c    q  ",
      "   a   AB       ",
      "   a  CDE       ",
      "   c hF c    q  ",
      "   accccw    qtu",
      "   aI@  cJ   qxy",
      "   cI@  KL   q  ",
      "   aI@  KM      ",
      "    kcccc       ",
      "    lNN O    q  ",
      "    l   c    qtu",
      "    llllllllllll"
    ],
    [
      "   a  P c       ",
      "   c    Q    q  ",
      "   a  R c    qST",
      "   accccU    qVW",
      "   c    c    q  ",
      "   a    X       ",
      "   aYC  Z       ",
      "   cfF  c    q  ",
      "   accccU    q0T",
      "   aI@  c    q12",
      "   cI@   3   q  ",
      "   aI@   4      ",
      "    kcccc       ",
      "    lNN 5    q  ",
      "    l   c    qVT",
      "    llllllllllll"
    ],
    [
      "   a 67 c       ",
      "   c 89 #       ",
      "   a $% c       ",
      "   acccc^       ",
      "   c    c       ",
      "   aY  &#       ",
      "   a*A &(       ",
      "   c    c       ",
      "   akccc^       ",
      "   aI@  c       ",
      "   cI@  )+      ",
      "   aI@  )+      ",
      "    kcccc       ",
      "    l-- c[      ",
      "    l   c       ",
      "    llllllllllll"
    ],
    [
      "   a ]{ c       ",
      "   c  {}c       ",
      "   a |{ c       ",
      "   acccc        ",
      "   cf;  c       ",
      "   a*A  c       ",
      "   a    c       ",
      "   c    c       ",
      "   acccc        ",
      "   aI@  c       ",
      "   cI@  c       ",
      "   aI@  c       ",
      "    kcccc       ",
      "    l:: c       ",
      "    l   c       ",
      "    llllllllllll"
    ],
    [
      "   a''''c<<<<<<<",
      "   c''''c<<<<<<<",
      "   a''''c<<<<<<<",
      "   acccc><<<><<<",
      "   c e; c<<<<<<<",
      "   a g  c<<<<<<<",
      "   a    c<<<<<<<",
      "   c    c<<<<<<<",
      "   acccc><<<><<<",
      "   aI@  c<<<<<<<",
      "   cI@  c<<<<<<<",
      "   aI@  c<<<<<<<",
      "    kccccccccccc",
      "    l<<<c<<<><<<",
      "    l<<<c<<<<<<<",
      "    llllllllllll"
    ]
  ]
}