{
  "name": "multi_filmworkstower_5_ground",
  "refpalette": "deceasedcraft:multi_filmworkstower_5/multi_filmworkstower_5_ground_palette",
  "xsize": 16,
  "zsize": 16,
  "slices": [
    [
      "aaaaaaaaabcccccc",
      "aaaaaaaaabcccccc",
      "aaaaaaaaabcccccc",
      "aaaaaaaaabcccccc",
      "aaaaaaaaabcccccc",
      "aaaaaaaaabcccccc",
      "aaaaaaaaabcccccc",
      "aaaaaaaaabcccccc",
      "aaaaabbbdbcccccc",
      "aaaaabc  bcccccc",
      "aaaaabccbbcccccc",
      "aaaaabccbbccccce",
      "aaaaabbbbbbbb ee",
      "aaaaaaaaabeeeeff",
      "aaaaaaaabbffffff",
      "aaaaaaaabfffffff"
    ],
    [
      "         g      ",
      "         ghh i  ",
      "         g   j  ",
      "         g   k  ",
      "        lghh    ",
      "         m      ",
      "         n      ",
      "        lghh    ",
      "     oooog   i  ",
      "    poqrog   j  ",
      "    st  oghh k  ",
      "    ut  og     w",
      "     ooooxbbbyww",
      "         gwwwwAA",
      "      BeeeCAAAA ",
      "        cAAA    "
    ],
    [
      "          g     ",
      "          ghh   ",
      "          g     ",
      "          g     ",
      "        lgghh   ",
      "         D      ",
      "         E      ",
      "        lgghh   ",
      "     oooo g     ",
      "     oqqo g     ",
      "    F   o ghh   ",
      "    I   o g     ",
      "     oooo xbbby ",
      "          g     ",
      "     BeeeeeC    ",
      "        c       "
    ],
    [
      "           g    ",
      "           ghh  ",
      "           g    ",
      "           g    ",
      "        lggghh  ",
      "        lggg    ",
      "        lggg    ",
      "        lggghh  ",
      "     oooo  g    ",
      "     oqqo  g    ",
      "    JK  o  ghh  ",
      "    JK  o  g    ",
      "     oooo  xbbby",
      "           g    ",
      "    BeeeeeeeC   ",
      "        cL      "
    ],
    [
      "            g   ",
      "            ghh ",
      "            g   ",
      "            g   ",
      "            ghh ",
      "            g   ",
      "            g   ",
      "            ghh ",
      "     oooo   g   ",
      "     oqqo   g   ",
      "     o  o   ghh ",
      "     o  o   g   ",
      "     oooo   xbbb",
      "            g   ",
      "   BeeeeeeeeeC  ",
      "        cM      "
    ],
    [
      "       NeeO  g  ",
      "       NeL   ghh",
      "       NP    g  ",
      "             g  ",
      "             ghh",
      "             g  ",
      "             g  ",
      "             ghh",
      "     oooo    g  ",
      "     oeeo    g  ",
      "     oeeo    ghh",
      "     oeeo    g  ",
      "     oooo    xbb",
      "             g  ",
      "  BeeeeeeeeeeeC ",
      "        cQ      "
    ]
  ]
}