{
  "name": "multi_filmworkstower_5_floor6",
  "refpalette": "deceasedcraft:multi_filmworkstower_5/multi_filmworkstower_5_floor6_palette",
  "xsize": 16,
  "zsize": 16,
  "slices": [
    [
      "   abbbbcddddddd",
      "   cbbbbcddddddd",
      "   abbbbcddddddd",
      "   acccccddddddd",
      "   c  efcddddddd",
      "   a  gfcddddddd",
      "   a   fcddddddd",
      "   c  hfcddddddd",
      "   acccciddddddd",
      "   ajc   ddddddd",
      "   cjc  cddddddd",
      "   ajc  cddddddd",
      "    kccccddddddd",
      "    lddddddddddd",
      "    lddddddddddd",
      "    llllllllllll"
    ],
    [
      "   a  m c    gn ",
      "   c op q    rs ",
      "   at u c    wx ",
      "   accccy   ABCD",
      "   c    c    EF ",
      "   a   IJ    gn ",
      "   a  sKL    rs ",
      "   c hM c   Nwx ",
      "   accccy   ABCD",
      "   aO@  cP   EFQ",
      "   cO@  RS   gn ",
      "   aO@  RT   rs ",
      "    kcccc    wx ",
      "    lUVWX   ABCD",
      "    l        EF ",
      "    llllllllllll"
    ],
    [
      "   a  Y c       ",
      "   c    Z       ",
      "   a  0 c    N1 ",
      "   acccc2    34 ",
      "   c    c    56 ",
      "   a    7       ",
      "   a8s  9       ",
      "   cfM  c     1 ",
      "   acccc2    34 ",
      "   aO@  c    5# ",
      "   cO@   $      ",
      "   aO@   %      ",
      "    kcccc     1 ",
      "    l   ^    34 ",
      "    l        5& ",
      "    llllllllllll"
    ],
    [
      "   a *( c       ",
      "   c )+ -       ",
      "   a [] c       ",
      "   acccc{       ",
      "   c    c       ",
      "   a8  }-       ",
      "   a|I };       ",
      "   c    c       ",
      "   akccc{       ",
      "   aO@  c       ",
      "   cO@  :'      ",
      "   aO@  :'      ",
      "    kcccc       ",
      "    l   ^       ",
      "    l           ",
      "    llllllllllll"
    ],
    [
      "   a <> c       ",
      "   c  >,c       ",
      "   a .> c       ",
      "   acccc        ",
      "   cf?  c       ",
      "   a|I  c       ",
      "   a    c       ",
      "   c    c       ",
      "   acccc        ",
      "   aO@  c       ",
      "   cO@  c       ",
      "   aO@  c       ",
      "    kcccc       ",
      "    l           ",
      "    l           ",
      "    llllllllllll"
    ],
    [
      "   a////c```````",
      "   c////c```````",
      "   a////c```````",
      "   acccc\u0370```\u0370```",
      "   c e? c```````",
      "   a g  c```````",
      "   a    c```````",
      "   c    c```````",
      "   acccc\u0370```\u0370```",
      "   aO@  c```````",
      "   cO@  c```````",
      "   aO@  c```````",
      "    kccccccccccc",
      "    l```\u0370```\u0370```",
      "    l```````````",
      "    llllllllllll"
    ]
  ]
}