{
  "name": "multi_filmworkstower_5_base1",
  "refpalette": "deceasedcraft:multi_filmworkstower_5/multi_filmworkstower_5_base1_palette",
  "xsize": 16,
  "zsize": 16,
  "slices": [
    [
      "             a  ",
      "             a  ",
      "             a  ",
      "             a  ",
      "             a  ",
      "             a  ",
      "             a  ",
      "             a  ",
      "             a  ",
      "             a  ",
      "             a  ",
      "             a  ",
      "bbbbbbbbb   ca  ",
      "   d         a  ",
      "   d         a  ",
      "   d         a  "
    ],
    [
      "            ea  ",
      "             a  ",
      "             a  ",
      "             a  ",
      "             a  ",
      "             a  ",
      "             a  ",
      "             a  ",
      "             a  ",
      "             a  ",
      "             a  ",
      "            fa  ",
      "bbbbbbbbbg hca  ",
      "   d        ea  ",
      "   d         a  ",
      "   d         a  "
    ],
    [
      "            ia  ",
      "            ia  ",
      "            ia  ",
      "            ia  ",
      "            ia  ",
      "            ia  ",
      "            ia  ",
      "            ia  ",
      "            ia  ",
      "            ia  ",
      "            ia  ",
      "            ia  ",
      "bbbbbbbbbbjjca  ",
      "   d        ia  ",
      "   d        ia  ",
      "   d        ia  "
    ],
    [
      "   k            ",
      "   k            ",
      "   k            ",
      "   k            ",
      "   k            ",
      "   k            ",
      "   k            ",
      "   k            ",
      "   k            ",
      "   k            ",
      "   k            ",
      "   k            ",
      "bbbbbbbbbbglcm  ",
      "   d            ",
      "   d            ",
      "   d            "
    ],
    [
      "nnnoppppppppqprr",
      "nnnoppppppppqprs",
      "nnnoppppppppqprs",
      "nnnoppppppppqprs",
      "nnnoppppppppqprs",
      "nnnoppppppppqprs",
      "nnnoppppppppqprs",
      "nnnoppppppppqprs",
      "nnnoppppppppqprs",
      "nnnoppppppppqprs",
      "nnnoppppppppqprs",
      "nnnoppppppppqprs",
      "bbbbbbbbbbbptprs",
      "nnnoppppppppqprs",
      "nnnoppppppppqprs",
      "nnnoppppppppqprs"
    ],
    [
      "bbbbbbbbbbbbbbbb",
      "bbbbbbbbbbbbbbbb",
      "bbbbbbbbbbbbbbbb",
      "bbbbbbbbbbbbbbbb",
      "bbbbbbbbbbbbbbbb",
      "bbbbbbbbbbbbbbbb",
      "bbbbbbbbbbbbbbbb",
      "bbbbbbbbbbbbbbbb",
      "bbbbbbbbbbbbbbbb",
      "bbbbbbbbbbbbbbbb",
      "bbbbbbbbbbbbbbbb",
      "bbbbbbbbbbbbbbbb",
      "bbbbbbbbbbbbb bb",
      "bbbbbbbbbbbbbbbb",
      "bbbbbbbbbbbbbbbb",
      "bbbbbbbbbbbbbbbb"
    ]
  ]
}