{
  "name": "multi_filmworkstower_5_floor8",
  "refpalette": "deceasedcraft:multi_filmworkstower_5/multi_filmworkstower_5_floor8_palette",
  "xsize": 16,
  "zsize": 16,
  "slices": [
    [
      "   abbbbcddddddd",
      "   cbbbbcddddddd",
      "   abbbbcddddddd",
      "   acccccddddddd",
      "   c  efcddddddd",
      "   a  gfcddddddd",
      "   a   fcddddddd",
      "   c  hfcddddddd",
      "   acccciddddddd",
      "   ajc   ddddddd",
      "   cjc  cddddddd",
      "   ajc  cddddddd",
      "    kccccddddddd",
      "    lfffcddddddd",
      "    lfffcddddddd",
      "    llllllllllll"
    ],
    [
      "   a  m c no no ",
      "   c pq r       ",
      "   as t c       ",
      "   accccu     ww",
      "   c    c       ",
      "   a   xy      A",
      "   a  BCD      A",
      "   c hE c       ",
      "   accccu     FF",
      "   aI@  cJ      ",
      "   cI@  KL      ",
      "   aI@  KM     A",
      "    kcccc      A",
      "    lNO P       ",
      "    lQ  c       ",
      "    llllllllllll"
    ],
    [
      "   a  R c       ",
      "   c    S       ",
      "   a  T c       ",
      "   accccU     VV",
      "   c    c       ",
      "   a    W       ",
      "   aXB  Y       ",
      "   cfE  c       ",
      "   accccU     ZZ",
      "   aI@  c       ",
      "   cI@   0      ",
      "   aI@   1      ",
      "    kcccc       ",
      "    l23 4       ",
      "    l   c       ",
      "    llllllllllll"
    ],
    [
      "   a 56 c       ",
      "   c 78 9       ",
      "   a #$ c       ",
      "   acccc%       ",
      "   c    c       ",
      "   aX  ^9       ",
      "   a&x ^*       ",
      "   c    c       ",
      "   akccc%       ",
      "   aI@  c       ",
      "   cI@  ()      ",
      "   aI@  ()      ",
      "    kcccc       ",
      "    l   c+      ",
      "    l   c       ",
      "    llllllllllll"
    ],
    [
      "   a -[ c       ",
      "   c  []c       ",
      "   a {[ c       ",
      "   acccc        ",
      "   cf}  c       ",
      "   a&x  c       ",
      "   a    c       ",
      "   c    c       ",
      "   acccc        ",
      "   aI@  c       ",
      "   cI@  c       ",
      "   aI@  c       ",
      "    kcccc       ",
      "    l   c       ",
      "    l   c       ",
      "    llllllllllll"
    ],
    [
      "   a||||c;;;;;;;",
      "   c||||c;;;;;;;",
      "   a||||c;;;;;;;",
      "   acccc:;;;:;;;",
      "   c e} c;;;;;;;",
      "   a g  c;;;;;;;",
      "   a    c;;;;;;;",
      "   c    c;;;;;;;",
      "   acccc:;;;:;;;",
      "   aI@  c;;;;;;;",
      "   cI@  c;;;;;;;",
      "   aI@  c;;;;;;;",
      "    kccccccccccc",
      "    l;;;c;;;:;;;",
      "    l;;;c;;;;;;;",
      "    llllllllllll"
    ]
  ]
}