{
  "name": "multi_filmworkstower_5_floor1",
  "refpalette": "deceasedcraft:multi_filmworkstower_5/multi_filmworkstower_5_floor1_palette",
  "xsize": 16,
  "zsize": 16,
  "slices": [
    [
      "     abc de   f ",
      "     abcgb    fh",
      "     abbi     f ",
      "              f ",
      "              fh",
      "              f ",
      "              f ",
      "              fh",
      "     jjjj     f ",
      "     j  j     f ",
      "     j  j     fh",
      "     j  j     f ",
      "     jjjj     kl",
      "              f ",
      " mbbbbbbbbbbbbbn",
      "        o       "
    ],
    [
      "  dbbc         f",
      "   pbc         f",
      "    ibbc       f",
      "               f",
      "               f",
      "               f",
      "               f",
      "               f",
      "     jjjj      f",
      "     j  j      f",
      "     j  j      f",
      "     j  j      f",
      "     jjjj      k",
      "               f",
      "bbbbbbbbbbbbbbbb",
      "qqqrqqqqoqqqqrqq"
    ],
    [
      "  de            ",
      "   bg           ",
      "    ic          ",
      "                ",
      "                ",
      "                ",
      "                ",
      "                ",
      "     jjjj       ",
      "     j  j       ",
      "     j  j       ",
      "     j  j       ",
      "     jjjj       ",
      "jjjjjjjjjjjjjjjj",
      "                ",
      "ssssssssssssssss"
    ],
    [
      "                ",
      "                ",
      "                ",
      "                ",
      "                ",
      "                ",
      "                ",
      "                ",
      "     jjjj       ",
      "     j  j       ",
      "     j  j       ",
      "     j  j       ",
      "     jjjj       ",
      "jjjjjjjjjjjjjjjj",
      "                ",
      "                "
    ],
    [
      "                ",
      "                ",
      "                ",
      "                ",
      "                ",
      "                ",
      "                ",
      "                ",
      "     jjjj       ",
      "     j  j       ",
      "     j  j       ",
      "     j  j       ",
      "     jjjj       ",
      "jjjjjjjjjjjjjjjj",
      "h               ",
      "                "
    ],
    [
      "        jttttttt",
      "        jttutttu",
      "        jttutttu",
      "        jttutttu",
      "        jttutttu",
      "        jttutttu",
      "        jttutttu",
      "        jttutttu",
      "     jjjjttutttu",
      "     j  jttutttu",
      "     j  jttutttu",
      "     j  jttttttt",
      "     jjjjjjjjjjj",
      "jjjjjjjjjjjjjjjj",
      "hhhhhhhhhhhhhhhh",
      "                "
    ]
  ]
}