{
  "name": "multi_filmworkstower_5_floor3",
  "refpalette": "deceasedcraft:multi_filmworkstower_5/multi_filmworkstower_5_floor3_palette",
  "xsize": 16,
  "zsize": 16,
  "slices": [
    [
      "   abccc        ",
      "  dabefg        ",
      "   ab           ",
      "   ab           ",
      "  dab           ",
      "   ab           ",
      "   ab           ",
      "  dab           ",
      "   abaaaa       ",
      "   aba  a       ",
      "  daba  a       ",
      "   aba  a       ",
      "    haaaa       ",
      "    i           ",
      "    i           ",
      "    iiiiiiiiiiii"
    ],
    [
      "   dj k l       ",
      "   aj mnl       ",
      "   dj  g        ",
      "   dj           ",
      "   aj           ",
      "   dj           ",
      "   dj           ",
      "   aj           ",
      "   daaaaa       ",
      "   do@  a       ",
      "   ao@  a       ",
      "   do@  a       ",
      "    haaaa       ",
      "    i           ",
      "    i           ",
      "    iiiiiiiiiiii"
    ],
    [
      "   dj           ",
      "   aj           ",
      "   dj mnl       ",
      "   dj  g        ",
      "   aj           ",
      "   dj           ",
      "   dj           ",
      "   aj           ",
      "   daaaaa       ",
      "   do@  a       ",
      "   ao@  a       ",
      "   do@  a       ",
      "    haaaa       ",
      "    i           ",
      "    i           ",
      "    iiiiiiiiiiii"
    ],
    [
      "   dj           ",
      "   aj           ",
      "   dj           ",
      "   dj mnl       ",
      "   aj  g        ",
      "   dj           ",
      "   dj           ",
      "   aj           ",
      "   daaaaa       ",
      "   do@  a       ",
      "   ao@  a       ",
      "   do@  a       ",
      "    haaaa       ",
      "    i           ",
      "    i           ",
      "    iiiiiiiiiiii"
    ],
    [
      "   dj           ",
      "   aj           ",
      "   dj           ",
      "   dj           ",
      "   aj mnl       ",
      "   dj  g        ",
      "   dj           ",
      "   aj           ",
      "   daaaaa       ",
      "   do@  a       ",
      "   ao@  a       ",
      "   do@  a       ",
      "    haaaa       ",
      "    i           ",
      "    i           ",
      "    iiiiiiiiiiii"
    ],
    [
      "   dj   appppppp",
      "   aj   appqqqqq",
      "   dj   apqqrrrr",
      "   dj   apqrssss",
      "   aj   apqrssss",
      "   dj mnapqrssss",
      "   dj  gapqrssss",
      "   aj   apqrssss",
      "   daaaaapqrssss",
      "   do@  apqqrrrr",
      "   ao@  appqqqqq",
      "   do@  appppppp",
      "    haaaaaaaaaaa",
      "    ippppppppppp",
      "    ippppppppppp",
      "    iiiiiiiiiiii"
    ]
  ]
}