{
  "name": "multi_filmworkstower_5_base2",
  "refpalette": "deceasedcraft:multi_filmworkstower_5/multi_filmworkstower_5_base2_palette",
  "xsize": 16,
  "zsize": 16,
  "slices": [
    [
      "aaaaaaaaaaaaab  ",
      "aaaaaaaaaaaaabcc",
      "aaaaaaaaaaaaab  ",
      "aaaaaaaaaaaaab  ",
      "aaaaaaaaaaaaab  ",
      "aaaaaaaaaaaaab  ",
      "aaaaaaaaaaaaabdd",
      "aaaaaaaaaaaaab  ",
      "aaaaaaaaaaaaabcc",
      "aaaaaaaaaaaaabee",
      "aaaaaaaaaaaaab f",
      "aaaaaaaaaaaaab f",
      "ggggggaaaaaaab f",
      "aaaaaaaaaaaaabee",
      "aaaaaaaaaaaaabdd",
      "aaaaaaaaaaaaab  "
    ],
    [
      "hij          b  ",
      "             b  ",
      "             bcc",
      "             b  ",
      "             b  ",
      "             bdd",
      "             b  ",
      "             b  ",
      "             b  ",
      "             bcc",
      "             bee",
      "klm          b e",
      "ggggggn    opbee",
      "             bdd",
      "             b  ",
      "             bcc"
    ],
    [
      "q            b  ",
      "             b  ",
      "             b  ",
      "             bcc",
      "             bdd",
      "             b  ",
      "             b  ",
      "             b  ",
      "             b  ",
      "             b  ",
      "             bcr",
      "             b s",
      "ggggggg     pbdt",
      "   u         b  ",
      "   u         b  ",
      "   u         b  "
    ],
    [
      "            wb  ",
      "             b  ",
      "             b  ",
      "             b  ",
      "             b  ",
      "             b  ",
      "             b  ",
      "             b  ",
      "             b  ",
      "             b  ",
      "             b  ",
      "            xby ",
      "gggggggn    pb  ",
      "   A        wb  ",
      "   A         b  ",
      "   A         b  "
    ],
    [
      "            Bb  ",
      "            Bb  ",
      "            Bb  ",
      "            Bb  ",
      "            Bb  ",
      "            Bb  ",
      "            Bb  ",
      "            Bb  ",
      "            Bb  ",
      "            Bb  ",
      "            Bb  ",
      "            Bb  ",
      "gggggggg   Cpb  ",
      "   A        Bb  ",
      "   A        Bb  ",
      "   A        Bb  "
    ],
    [
      "             b  ",
      "             b  ",
      "             b  ",
      "             b  ",
      "             b  ",
      "             b  ",
      "             b  ",
      "             b  ",
      "             b  ",
      "             b  ",
      "             b  ",
      "             b  ",
      "ggggggggn   pb  ",
      "   A         b  ",
      "   A         b  ",
      "   A         b  "
    ]
  ]
}