{
  "name": "multi_filmworkstower_5_floor5",
  "refpalette": "deceasedcraft:multi_filmworkstower_5/multi_filmworkstower_5_floor5_palette",
  "xsize": 16,
  "zsize": 16,
  "slices": [
    [
      "   abbbbcddddddd",
      "   cbbbbcddddddd",
      "   abbbbcddddddd",
      "   acccccddddddd",
      "   c  efcddddddd",
      "   a  gfcddddddd",
      "   a   fcddddddd",
      "   c  hfcddddddd",
      "   acccciddddddd",
      "   ajc   ddddddd",
      "   cjc  cddddddd",
      "   ajc  cddddddd",
      "    kccccddddddd",
      "    lddddddddddd",
      "    lddddddddddd",
      "    llllllllllll"
    ],
    [
      "   a  m c    gn ",
      "   c op q    rs ",
      "   at u c    wx ",
      "   acccc!   yABC",
      "   c    c    DE ",
      "   a   FI    gn ",
      "   a  sJK    rs ",
      "   c hL c    wx ",
      "   accccM   yABC",
      "   aN@  cO   DE ",
      "   cN@  PQ   gn ",
      "   aN@  PR   rs ",
      "    kcccc    wx ",
      "    lSTUV   yABC",
      "    l        DE ",
      "    llllllllllll"
    ],
    [
      "   a  W c       ",
      "   c    X       ",
      "   a  Y c    Z0 ",
      "   acccc1    23 ",
      "   c    c    45 ",
      "   a    6       ",
      "   a7s  8       ",
      "   cfL  c    90 ",
      "   acccc#    23 ",
      "   aN@  c    4$ ",
      "   cN@   %      ",
      "   aN@   ^      ",
      "    kcccc    &0 ",
      "    l   *    23 ",
      "    l        4  ",
      "    llllllllllll"
    ],
    [
      "   a () c       ",
      "   c +- [       ",
      "   a ]{ c       ",
      "   acccc        ",
      "   c    c       ",
      "   a7  }[       ",
      "   a|F };       ",
      "   c    c       ",
      "   akccc:       ",
      "   aN@  c       ",
      "   cN@  '<      ",
      "   aN@  '<      ",
      "    kcccc       ",
      "    l   *       ",
      "    l           ",
      "    llllllllllll"
    ],
    [
      "   a >, c       ",
      "   c  ,.c       ",
      "   a ?, c       ",
      "   acccc        ",
      "   cf/  c       ",
      "   a|F  c       ",
      "   a    c       ",
      "   c    c       ",
      "   acccc        ",
      "   aN@  c       ",
      "   cN@  c       ",
      "   aN@  c       ",
      "    kcccc       ",
      "    l   `       ",
      "    l           ",
      "    llllllllllll"
    ],
    [
      "   a\u0370\u0370\u0370\u0370c\u0371\u0371\u0371\u0371\u0371\u0371\u0371",
      "   c\u0370\u0370\u0370\u0370c\u0371\u0371\u0371\u0371\u0371\u0371\u0371",
      "   a\u0370\u0370\u0370\u0370c\u0371\u0371\u0371\u0371\u0371\u0371\u0371",
      "   acccc\u0372\u0371\u0371\u0371\u0372\u0371\u0371\u0371",
      "   c e/ c\u0371\u0371\u0371\u0371\u0371\u0371\u0371",
      "   a g  c\u0371\u0371\u0371\u0371\u0371\u0371\u0371",
      "   a    c\u0371\u0371\u0371\u0371\u0371\u0371\u0371",
      "   c    c\u0371\u0371\u0371\u0371\u0371\u0371\u0371",
      "   acccc\u0372\u0371\u0371\u0371\u0372\u0371\u0371\u0371",
      "   aN@  c\u0371\u0371\u0371\u0371\u0371\u0371\u0371",
      "   cN@  c\u0371\u0371\u0371\u0371\u0371\u0371\u0371",
      "   aN@  c\u0371\u0371\u0371\u0371\u0371\u0371\u0371",
      "    kccccccccccc",
      "    l\u0371\u0371\u0371\u0372\u0371\u0371\u0371\u0372\u0371\u0371\u0371",
      "    l\u0371\u0371\u0371\u0371\u0371\u0371\u0371\u0371\u0371\u0371\u0371",
      "    llllllllllll"
    ]
  ]
}