{
  "name": "multi_filmworkstower_5_floor11",
  "refpalette": "deceasedcraft:multi_filmworkstower_5/multi_filmworkstower_5_floor11_palette",
  "xsize": 16,
  "zsize": 16,
  "slices": [
    [
      "   abbbbcddddddd",
      "   cbbbbcddddddd",
      "   abbbbcddddddd",
      "   acccccddddddd",
      "   c  efcddddddd",
      "   a  gfcddddddd",
      "   a   fcddddddd",
      "   c  hfcddddddd",
      "   acccciddddddd",
      "   ajc   ddddddd",
      "   cjc  cddddddd",
      "   ajc  cddddddd",
      "    kccccddddddd",
      "    lfffcddddddd",
      "    lfffcddddddd",
      "    llllllllllll"
    ],
    [
      "   a  m c       ",
      "   c no p    q  ",
      "   ar s ct   quw",
      "   accccxq   qyA",
      "   c    cqB C D ",
      "   a   EFqq     ",
      "   a  IJKqLM A N",
      "   c hO cqq  P Q",
      "   accccxqRA  ST",
      "   aU@  cV  P WX",
      "   cU@  YZ   0  ",
      "   aU@  Y1 2    ",
      "    kcccc  C    ",
      "    l33 45   q  ",
      "    l   c    quw",
      "    llllllllllll"
    ],
    [
      "   a  6 c       ",
      "   c    7    q  ",
      "   a  8 c    q9#",
      "   acccc$    %  ",
      "   c    c!      ",
      "   a    ^q&     ",
      "   a*I  (B      ",
      "   cfO  cqM     ",
      "   acccc$      )",
      "   aU@  c     +-",
      "   cU@   [      ",
      "   aU@   ]      ",
      "    kcccc       ",
      "    l33 {    q  ",
      "    l   c    q2#",
      "    llllllllllll"
    ],
    [
      "   a }| c       ",
      "   c ;: '       ",
      "   a <> c       ",
      "   acccc,       ",
      "   c    c       ",
      "   a*  .'       ",
      "   a?E ./       ",
      "   c    c`      ",
      "   akccc,       ",
      "   aU@  c       ",
      "   cU@  \u0370\u0371      ",
      "   aU@  \u0370\u0371      ",
      "    kcccc       ",
      "    l\u0372\u0372 c\u0373      ",
      "    l   c       ",
      "    llllllllllll"
    ],
    [
      "   a \u0374\u0375 c       ",
      "   c  \u0375\u0376c       ",
      "   a \u0377\u0375 c       ",
      "   acccc        ",
      "   cf\u037a  c       ",
      "   a?E  c       ",
      "   a    c       ",
      "   c    c       ",
      "   acccc        ",
      "   aU@  c       ",
      "   cU@  c       ",
      "   aU@  c       ",
      "    kcccc       ",
      "    l\u037b\u037b c       ",
      "    l   c       ",
      "    llllllllllll"
    ],
    [
      "   a\u037c\u037c\u037c\u037cc\u037d\u037d\u037d\u037d\u037d\u037d\u037d",
      "   c\u037c\u037c\u037c\u037cc\u037d\u037d\u037d\u037d\u037d\u037d\u037d",
      "   a\u037c\u037c\u037c\u037cc\u037d\u037d\u037d\u037d\u037d\u037d\u037d",
      "   acccc\u037e\u037d\u037d\u037d\u037e\u037d\u037d\u037d",
      "   c e\u037a c\u037d\u037d\u037d\u037d\u037d\u037d\u037d",
      "   a g  c\u037d\u037d\u037d\u037d\u037d\u037d\u037d",
      "   a    c\u037d\u037d\u037d\u037d\u037d\u037d\u037d",
      "   c    c\u037d\u037d\u037d\u037d\u037d\u037d\u037d",
      "   acccc\u037e\u037d\u037d\u037d\u037e\u037d\u037d\u037d",
      "   aU@  c\u037d\u037d\u037d\u037d\u037d\u037d\u037d",
      "   cU@  c\u037d\u037d\u037d\u037d\u037d\u037d\u037d",
      "   aU@  c\u037d\u037d\u037d\u037d\u037d\u037d\u037d",
      "    kccccccccccc",
      "    l\u037d\u037d\u037dc\u037d\u037d\u037d\u037e\u037d\u037d\u037d",
      "    l\u037d\u037d\u037dc\u037d\u037d\u037d\u037d\u037d\u037d\u037d",
      "    llllllllllll"
    ]
  ]
}