{
  "name": "multi_filmworkstower_5_floor10",
  "refpalette": "deceasedcraft:multi_filmworkstower_5/multi_filmworkstower_5_floor10_palette",
  "xsize": 16,
  "zsize": 16,
  "slices": [
    [
      "   abbbbcddddddd",
      "   cbbbbcddddddd",
      "   abbbbcddddddd",
      "   acccccddddddd",
      "   c  efcddddddd",
      "   a  gfcddddddd",
      "   a   fcddddddd",
      "   c  hfcddddddd",
      "   acccciddddddd",
      "   ajc   ddddddd",
      "   cjc  cddddddd",
      "   ajc  cddddddd",
      "    kccccddddddd",
      "    lfffcddddddd",
      "    lfffcddddddd",
      "    llllllllllll"
    ],
    [
      "   a  m c       ",
      "   c no p    q r",
      "   as t c    quw",
      "   accccx    qyA",
      "   c    c    q B",
      "   a   CD       ",
      "   a  EFI       ",
      "   c hJ c    q  ",
      "   accccx    quw",
      "   aK@  cL   qyA",
      "   cK@  MN   qO ",
      "   aK@  MP      ",
      "    kcccc       ",
      "    lQQ R    q  ",
      "    l   c    quw",
      "    llllllllllll"
    ],
    [
      "   a  S c       ",
      "   c    T    q  ",
      "   a  U c    qVW",
      "   accccX    qYZ",
      "   c    c    q  ",
      "   a    0       ",
      "   a1E  2       ",
      "   cfJ  c    q  ",
      "   accccX    q3W",
      "   aK@  c    q4Z",
      "   cK@   5   q  ",
      "   aK@   6      ",
      "    kcccc       ",
      "    lQQ 7    q  ",
      "    l   c    q8W",
      "    llllllllllll"
    ],
    [
      "   a 9# c       ",
      "   c $% ^       ",
      "   a &* c       ",
      "   acccc(       ",
      "   c    c       ",
      "   a1  )^       ",
      "   a+C )-       ",
      "   c    c       ",
      "   akccc(       ",
      "   aK@  c       ",
      "   cK@  []      ",
      "   aK@  []      ",
      "    kcccc       ",
      "    l{} c|      ",
      "    l   c       ",
      "    llllllllllll"
    ],
    [
      "   a ;: c       ",
      "   c  :'c       ",
      "   a <: c       ",
      "   acccc        ",
      "   cf>  c       ",
      "   a+C  c       ",
      "   a    c       ",
      "   c    c       ",
      "   acccc        ",
      "   aK@  c       ",
      "   cK@  c       ",
      "   aK@  c       ",
      "    kcccc       ",
      "    l,, c       ",
      "    l   c       ",
      "    llllllllllll"
    ],
    [
      "   a....c???????",
      "   c....c???????",
      "   a....c???????",
      "   acccc/???/???",
      "   c e> c???????",
      "   a g  c???????",
      "   a    c???????",
      "   c    c???????",
      "   acccc/???/???",
      "   aK@  c???????",
      "   cK@  c???????",
      "   aK@  c???????",
      "    kccccccccccc",
      "    l???c???/???",
      "    l???c???????",
      "    llllllllllll"
    ]
  ]
}