{
  "name": "multi_filmworkstower_5_top",
  "refpalette": "deceasedcraft:multi_filmworkstower_5/multi_filmworkstower_5_top_palette",
  "xsize": 16,
  "zsize": 16,
  "slices": [
    [
      "   abbbbcddddddd",
      "   cbbbbcddddddd",
      "   abbbbcddddddd",
      "   acccccdddcccc",
      "   c  efcddccccc",
      "   a  gfcddccccc",
      "   a   fcddccccc",
      "   c  hfcddccccc",
      "   accccidddcccc",
      "   ajc   ddddddd",
      "   cjc  cddddddd",
      "   ajc  cddddddd",
      "    kccccddddddd",
      "    lddddddddddd",
      "    lddddddddddd",
      "    llllllllllll"
    ],
    [
      "   a  m c       ",
      "   c no p       ",
      "   aq r c       ",
      "   accccs    tt ",
      "   c    c   tuut",
      "   a   wx  tu!uu",
      "   a  yAB  tuuuu",
      "   c hC c   tuut",
      "   accccs    tt ",
      "   aD@  cE      ",
      "   cD@  FI      ",
      "   aD@  FJ      ",
      "    kccccKKKKKKL",
      "    lMNNOw P    ",
      "    l           ",
      "    llllllllllll"
    ],
    [
      "   a  Q c       ",
      "   c    R       ",
      "   a  S c       ",
      "   accccT       ",
      "   c    c       ",
      "   a    U     V ",
      "   aWy  X     Y ",
      "   cfC  c       ",
      "   accccT       ",
      "   aD@  c       ",
      "   cD@   Z      ",
      "   aD@   0      ",
      "    kcccc 1234 5",
      "    l  67       ",
      "    l           ",
      "    llllllllllll"
    ],
    [
      "   a 89 c       ",
      "   c #$ %       ",
      "   a ^& c       ",
      "   acccc*       ",
      "   c    c       ",
      "   aW  (%     V ",
      "   a)w (+     Y ",
      "   c    c       ",
      "   akccc*       ",
      "   aD@  c       ",
      "   cD@  -[      ",
      "   aD@  -]      ",
      "    kcccc      {",
      "    l           ",
      "    l           ",
      "    llllllllllll"
    ],
    [
      "   a }| c       ",
      "   c  |;c       ",
      "   a :| c       ",
      "   acccc        ",
      "   cf'  c       ",
      "   a)w  c     < ",
      "   a    c     > ",
      "   c    c       ",
      "   acccc        ",
      "   aD@  c       ",
      "   cD@  c       ",
      "   aD@  c       ",
      "    kcccc      {",
      "    l           ",
      "    l           ",
      "    llllllllllll"
    ],
    [
      "   a,,,,c       ",
      "   c,,,,c       ",
      "   a ,,,c       ",
      "   acccc        ",
      "   c e' c       ",
      "   a g  c    .? ",
      "   a    c    .? ",
      "   c    c       ",
      "   acccc        ",
      "   aD@  c       ",
      "   cD@  c       ",
      "   aD@  c       ",
      "    kcccc      {",
      "    l           ",
      "    l           ",
      "    llllllllllll"
    ],
    [
      "   affffc       ",
      "   cf/ffc       ",
      "   affffc       ",
      "   acccc        ",
      "   c  efc       ",
      "   a  gfc     ` ",
      "   a   fc     \u0370 ",
      "   c  hfc       ",
      "   acccc        ",
      "   ajc  c       ",
      "   cjc  c       ",
      "   ajc  c       ",
      "    kcccc      {",
      "    l           ",
      "    l           ",
      "    llllllllllll"
    ],
    [
      "   a\u0371 \u0372 c       ",
      "   c\u0373/  c       ",
      "   a\u0373\u0373\u0374 c       ",
      "   acccc        ",
      "   c    c       ",
      "   a   wc       ",
      "   a  yAc       ",
      "   c hC c      \u0375",
      "   acccc        ",
      "   aD@  c       ",
      "   cD@  c       ",
      "   aD@  c       ",
      "    kcccc      {",
      "    l           ",
      "    l           ",
      "    llllllllllll"
    ],
    [
      "   a  \u0372 c       ",
      "   c\u0376\u0377  c       ",
      "   a\u037a\u037b  c       ",
      "   acccc        ",
      "   c    c   \u0375   ",
      "   a    c       ",
      "   aWy  c       ",
      "   cfC  c      \u037c",
      "   acccc        ",
      "   aD@  c       ",
      "   cD@  c       ",
      "   aD@  c       ",
      "    kcccc      {",
      "    l           ",
      "    l           ",
      "    llllllllllll"
    ],
    [
      "   a  \u0372 c       ",
      "   c\u037d\u037e  c       ",
      "   a\u037f\u0384  c       ",
      "   acccc        ",
      "   c    c   \u037c  \u0375",
      "   aW   c       ",
      "   a)w  c       ",
      "   c    c   \u0375  \u037c",
      "   akccc        ",
      "   aD@  c       ",
      "   cD@  c       ",
      "   aD@  c       ",
      "    kcccc      {",
      "    l           ",
      "    l           ",
      "    llllllllllll"
    ],
    [
      "   a  \u0372 c       ",
      "   c\u037d\u037e  c       ",
      "   a\u037f\u0384  c       ",
      "   acccc        ",
      "   cf'  c   \u037c\u0385\u0385\u037c",
      "   a)w  c   \u0385  \u0385",
      "   a    c   \u0385  \u0385",
      "   c    c   \u037c\u0385\u0385\u037c",
      "   acccc        ",
      "   aD@  c       ",
      "   cD@  c       ",
      "   aD@  c       ",
      "    kcccc      \u0386",
      "    l           ",
      "    l           ",
      "    llllllllllll"
    ],
    [
      "   a  \u0372 c\u0387\u0387\u0387\u0387\u0387\u0387\u0387",
      "   c\u0388\u0389  c\u0387\u0387\u0387\u0387\u0387\u0387\u0387",
      "   a\u038a\u038c  c\u0387\u0387\u038e\u038e\u038e\u038e\u038e",
      "   acccc\u038f\u0387\u038e\u038e\u038f\u038f\u038f\u038f",
      "   c e' c\u0387\u038e\u038f\u0390\u0391\u0391\u0390",
      "   a g  c\u0387\u038e\u038f\u0391cc\u0391",
      "   a    c\u0387\u038e\u038f\u0391cc\u0391",
      "   c    c\u0387\u038e\u038f\u0390\u0391\u0391\u0390",
      "   acccc\u038f\u0387\u038e\u038e\u038f\u038f\u038f\u038f",
      "   aD@  c\u0387\u0387\u038e\u038e\u038e\u038e\u038e",
      "   cD@  c\u0387\u0387\u0387\u0387\u0387\u0387\u0387",
      "   aD@  c\u0387\u0387\u0387\u0387\u0387\u0387\u0387",
      "    kccccccccccc",
      "    l\u0387\u0387\u0387\u0387\u0387\u0387\u0387\u0387\u0387\u0387\u0387",
      "    l\u0387\u0387\u0387\u0387\u0387\u0387\u0387\u0387\u0387\u0387\u0387",
      "    llllllllllll"
    ],
    [
      "   a  \u0372\u0392cfffffff",
      "   c   \u0392cfffffff",
      "   a   \u0392cfffffff",
      "   acccccfffffff",
      "   c  efcfff ff ",
      "   a  g cfffffff",
      "   a    cfffffff",
      "   c    cfff ff ",
      "   acccccfffffff",
      "   ajcffcfffffff",
      "   cjc fcfffffff",
      "   ajc fcfffffff",
      "    kcccffffffff",
      "    lfffffffffff",
      "    lfffffffffff",
      "    llllllllllll"
    ],
    [
      "   a    c   \u0393\u0393\u0393\u0393",
      "   c   \u0394\u0395   \u0393\u0393\u0393\u0393",
      "   a   \u0394c   \u0393\u0393\u0393\u0393",
      "   accccc   \u0393\u0393\u0393\u0393",
      "   c    \u0396   \u0393\u0393\u0393\u0393",
      "   a   gc   \u0393\u0393\u0393\u0393",
      "   a    c   \u0393\u0393\u0393\u0393",
      "   c    c   \u0393\u0393\u0393\u0393",
      "   accccc   \u0393\u0393\u0393\u0393",
      "   a\u0397 \u0398 \u0399   \u0393\u0393\u0393\u0393",
      "   c\u039a\u039b  c   \u0393\u0393\u0393\u0393",
      "   a \u039b  c   \u0393\u0393\u0393\u0393",
      "    kccc        ",
      "    l           ",
      "    l           ",
      "    llllllllllll"
    ],
    [
      "   a    c       ",
      "   c    \u039c       ",
      "   a    c       ",
      "   accccc       ",
      "   c    \u039d       ",
      "   a    c       ",
      "   a    c       ",
      "   c    c       ",
      "   accccc       ",
      "   a\u039e   \u039f       ",
      "   c\u039a   c       ",
      "   a    c       ",
      "    kccc        ",
      "                ",
      "                ",
      "                "
    ],
    [
      "   a    c\u03a0      ",
      "   c    c\u03a1      ",
      "   a    c       ",
      "   accccc       ",
      "   c    c\u03a3      ",
      "   a    c       ",
      "   a    c       ",
      "   c    c       ",
      "   accccc       ",
      "   a\u03a4\u03a5\u03a5\u03a6c\u03a7      ",
      "   c\u039a\u03a8\u03a9 c       ",
      "   a  \u03aa c\u03a0      ",
      "    kccc        ",
      "                ",
      "                ",
      "                "
    ],
    [
      "    ttttttt     ",
      "   \u03abcccccct     ",
      "    ttttttt     ",
      "    ttttttt     ",
      "   \u03abcccccct     ",
      "    ttttttt     ",
      "    ttttttt     ",
      "   \u03abcccccct     ",
      "    ttttttt     ",
      "    ttttttt     ",
      "   \u03abcccccct     ",
      "    ttttttt     ",
      "    \u03ac\u03ac          ",
      "                ",
      "                ",
      "                "
    ],
    [
      "                ",
      "                ",
      "                ",
      "                ",
      "                ",
      "                ",
      "                ",
      "                ",
      "                ",
      "                ",
      "                ",
      "                ",
      "     \u03ac\u03ac         ",
      "                ",
      "                ",
      "                "
    ],
    [
      "                ",
      "                ",
      "                ",
      "                ",
      "                ",
      "                ",
      "                ",
      "                ",
      "                ",
      "                ",
      "                ",
      "                ",
      "      \u03ac\u03ac        ",
      "                ",
      "                ",
      "                "
    ],
    [
      "                ",
      "                ",
      "                ",
      "                ",
      "                ",
      "                ",
      "                ",
      "                ",
      "                ",
      "                ",
      "                ",
      "                ",
      "       \u03ac\u03ac       ",
      "                ",
      "                ",
      "                "
    ],
    [
      "                ",
      "                ",
      "                ",
      "                ",
      "                ",
      "                ",
      "                ",
      "                ",
      "                ",
      "                ",
      "                ",
      "                ",
      "        \u03ac\u03ac      ",
      "                ",
      "                ",
      "                "
    ],
    [
      "                ",
      "                ",
      "                ",
      "                ",
      "                ",
      "                ",
      "                ",
      "                ",
      "                ",
      "                ",
      "                ",
      "                ",
      "         \u03ac\u03ac     ",
      "                ",
      "                ",
      "                "
    ],
    [
      "                ",
      "                ",
      "                ",
      "                ",
      "                ",
      "                ",
      "                ",
      "                ",
      "                ",
      "                ",
      "                ",
      "                ",
      "          \u03ac\u03ac    ",
      "                ",
      "                ",
      "                "
    ],
    [
      "                ",
      "                ",
      "                ",
      "                ",
      "                ",
      "                ",
      "                ",
      "                ",
      "                ",
      "                ",
      "                ",
      "                ",
      "           \u03ac\u03ac   ",
      "                ",
      "                ",
      "                "
    ],
    [
      "                ",
      "                ",
      "                ",
      "                ",
      "                ",
      "                ",
      "                ",
      "                ",
      "                ",
      "                ",
      "                ",
      "                ",
      "            \u03ac\u03ac  ",
      "                ",
      "                ",
      "                "
    ],
    [
      "                ",
      "                ",
      "                ",
      "                ",
      "                ",
      "                ",
      "                ",
      "                ",
      "                ",
      "                ",
      "                ",
      "                ",
      "             \u03ac\u03ac ",
      "                ",
      "                ",
      "                "
    ],
    [
      "                ",
      "                ",
      "                ",
      "                ",
      "                ",
      "                ",
      "                ",
      "                ",
      "                ",
      "                ",
      "                ",
      "                ",
      "              \u03ac\u03ac",
      "                ",
      "                ",
      "                "
    ],
    [
      "                ",
      "                ",
      "                ",
      "                ",
      "                ",
      "                ",
      "                ",
      "                ",
      "                ",
      "                ",
      "                ",
      "                ",
      "               \u03ac",
      "                ",
      "                ",
      "                "
    ]
  ]
}