{
  "name": "multi_filmworkstower_5_base3",
  "refpalette": "deceasedcraft:multi_filmworkstower_5/multi_filmworkstower_5_base3_palette",
  "xsize": 16,
  "zsize": 16,
  "slices": [
    [
      "aaaaaaaaaaaabbbb",
      "aaaaaaaaaaaabbbb",
      "aaaaaaaaaaaabbbb",
      "aaaaaaaaaaaabbbb",
      "aaaaaaaaaaaabbbb",
      "aaaaaaaaaaaabbbb",
      "aaaaaaaaaaaabbbb",
      "aaaaaaaaaaaabbbb",
      "aaaaaaaaaaaabbbb",
      "aaaaaaaaaaaabbbb",
      "aaaaaaaaaaaabbbb",
      "aaaaaaaaaaaabbbb",
      "abbbbbaaaaaabbbb",
      "aaaaaaaaaaaabbbb",
      "aaaaaaaaaaaabbbb",
      "aaaaaaaaaaaabbbb"
    ],
    [
      "aaaaaaaaaaaabcdd",
      "aaaaaaaaaaaabcee",
      "aaaaaaaaaaaabcef",
      "aaaaaaaaaaaabcee",
      "aaaaaaaaaaaabcee",
      "aaaaaaaaaaaabcef",
      "aaaaaaaaaaaabcee",
      "aaaaaaaaaaaabcdd",
      "aaaaaaaaaaaabcdd",
      "aaaaaaaaaaaabcee",
      "aaaaaaaaaaaabcee",
      "aaaaaaaaaaaabcee",
      "abbbbbaaaaaabcee",
      "aaaaaaaaaaaabcee",
      "aaaaaaaaaaaabcdd",
      "aaaaaaaaaaaabcgg"
    ],
    [
      "aaaaaaaaaaaabc  ",
      "aaaaaaaaaaaabcee",
      "aaaaaaaaaaaabchf",
      "aaaaaaaaaaaabchh",
      "aaaaaaaaaaaabchh",
      "aaaaaaaaaaaabchf",
      "aaaaaaaaaaaabcee",
      "aaaaaaaaaaaabc  ",
      "aaaaaaaaaaaabc  ",
      "aaaaaaaaaaaabcee",
      "aaaaaaaaaaaabchh",
      "aaaaaaaaaaaabchh",
      "abbbbbaaaaaabchh",
      "aaaaaaaaaaaabcei",
      "aaaaaaaaaaaabcjj",
      "aaaaaaaaaaaabckk"
    ],
    [
      "aaaaaaaaaaaabc  ",
      "aaaaaaaaaaaabcee",
      "aaaaaaaaaaaabc l",
      "aaaaaaaaaaaabc  ",
      "aaaaaaaaaaaabc  ",
      "aaaaaaaaaaaabcmn",
      "aaaaaaaaaaaabcee",
      "aaaaaaaaaaaabc  ",
      "aaaaaaaaaaaabc  ",
      "aaaaaaaaaaaabcee",
      "aaaaaaaaaaaabc  ",
      "aaaaaaaaaaaabc  ",
      "abbbbbaaaaaabcop",
      "aaaaaaaaaaaabcee",
      "aaaaaaaaaaaabc  ",
      "aaaaaaaaaaaabcqq"
    ],
    [
      "aaaaaaaaaaaabc  ",
      "aaaaaaaaaaaabrsr",
      "aaaaaaaaaaaabc  ",
      "aaaaaaaaaaaabc  ",
      "aaaaaaaaaaaabc  ",
      "aaaaaaaaaaaabc  ",
      "aaaaaaaaaaaabrsr",
      "aaaaaaaaaaaabc  ",
      "aaaaaaaaaaaabc  ",
      "aaaaaaaaaaaabese",
      "aaaaaaaaaaaabc  ",
      "aaaaaaaaaaaabc  ",
      "abbbbbaaaaaabc  ",
      "aaaaaaaaaaaabese",
      "aaaaaaaaaaaabc  ",
      "aaaaaaaaaaaabc  "
    ],
    [
      "aaaaaaaaaaaabctt",
      "aaaaaaaaaaaabcee",
      "aaaaaaaaaaaabc  ",
      "aaaaaaaaaaaabc  ",
      "aaaaaaaaaaaabc  ",
      "aaaaaaaaaaaabc  ",
      "aaaaaaaaaaaabcei",
      "aaaaaaaaaaaabcuu",
      "aaaaaaaaaaaabc  ",
      "aaaaaaaaaaaabcee",
      "aaaaaaaaaaaabc w",
      "aaaaaaaaaaaabc x",
      "abbbbbaaaaaabc y",
      "aaaaaaaaaaaabcee",
      "aaaaaaaaaaaabc  ",
      "aaaaaaaaaaaabc  "
    ]
  ]
}