{
  "name": "multi_filmworkstower_5_floor7",
  "refpalette": "deceasedcraft:multi_filmworkstower_5/multi_filmworkstower_5_floor7_palette",
  "xsize": 16,
  "zsize": 16,
  "slices": [
    [
      "   abbbbcddddddd",
      "   cbbbbcddddddd",
      "   abbbbcddddddd",
      "   acccccddddddd",
      "   c  efcddddddd",
      "   a  gfcddddddd",
      "   a   fcddddddd",
      "   c  hfcddddddd",
      "   acccciddddddd",
      "   ajc   ddddddd",
      "   cjc  cddddddd",
      "   ajc  cddddddd",
      "    kccccddddddd",
      "    lddddddddddd",
      "    lddddddddddd",
      "    llllllllllll"
    ],
    [
      "   a  m c    gn ",
      "   c op q    rs ",
      "   at u c    wx ",
      "   accccy   ABCD",
      "   c    c    EF ",
      "   a   IJ    gn ",
      "   a  sKL    rs ",
      "   c hM c    wx ",
      "   accccy   ABCD",
      "   aN@  cO   EF ",
      "   cN@  PQ   gn ",
      "   aN@  PR   rs ",
      "    kcccc    wx ",
      "    lSTUV   ABCD",
      "    l        EF ",
      "    llllllllllll"
    ],
    [
      "   a  W c       ",
      "   c    X       ",
      "   a  Y c    Z0 ",
      "   acccc1    23 ",
      "   c    c    45 ",
      "   a    6       ",
      "   a7s  8       ",
      "   cfM  c    90 ",
      "   acccc1    23 ",
      "   aN@  c    4# ",
      "   cN@   $      ",
      "   aN@   %      ",
      "    kcccc    ^0 ",
      "    l   &    23 ",
      "    l        4* ",
      "    llllllllllll"
    ],
    [
      "   a () c       ",
      "   c +- [       ",
      "   a ]{ c       ",
      "   acccc}       ",
      "   c    c       ",
      "   a7  |[       ",
      "   a;I |:       ",
      "   c    c       ",
      "   akccc}       ",
      "   aN@  c       ",
      "   cN@  '<      ",
      "   aN@  '<      ",
      "    kcccc       ",
      "    l   &       ",
      "    l           ",
      "    llllllllllll"
    ],
    [
      "   a >, c       ",
      "   c  ,.c       ",
      "   a !, c       ",
      "   acccc        ",
      "   cf?  c       ",
      "   a;I  c       ",
      "   a    c       ",
      "   c    c       ",
      "   acccc        ",
      "   aN@  c       ",
      "   cN@  c       ",
      "   aN@  c       ",
      "    kcccc       ",
      "    l           ",
      "    l           ",
      "    llllllllllll"
    ],
    [
      "   a////c```````",
      "   c////c```````",
      "   a////c```````",
      "   acccc\u0370```\u0370```",
      "   c e? c```````",
      "   a g  c```````",
      "   a    c```````",
      "   c    c```````",
      "   acccc\u0370```\u0370```",
      "   aN@  c```````",
      "   cN@  c```````",
      "   aN@  c```````",
      "    kccccccccccc",
      "    l```\u0370```\u0370```",
      "    l```````````",
      "    llllllllllll"
    ]
  ]
}