{
  "name": "multi_militarybase_5_base2",
  "refpalette": "deceasedcraft:multi_militarybase_5/multi_militarybase_5_base2_palette",
  "xsize": 16,
  "zsize": 16,
  "slices": [
    [
      " abbbcccccccccvv",
      " abbbcccccccccvv",
      "avaaaaaaavaaavvv",
      "babbbccccaccccvv",
      "dabbbccccaccccvv",
      "babbcccccaccccvv",
      "evfccccccaccccvv",
      "cacccccccaccccvv",
      "cacccccccaccccvv",
      "cacccccccaccccvv",
      "avaaaaaaavaaavvv",
      "gacccccccaccccvv",
      "gacccccccaccccvv",
      "gacccccccaccccvv",
      "gvcccccccvccccvv",
      "vvvvvvvvvvvvvvvv"
    ],
    [
      " h           ivv",
      " j        klm vv",
      "jv h   novpppvvv",
      "   q     r  stvv",
      "         ruw  vv",
      "         r    vv",
      "xvf      ruwq vv",
      "         r  y vv",
      "       A ruw  vv",
      "  BC   D r    vv",
      "xvxx   xxvE  vvv",
      "FpI          !vv",
      " pIJ   J      vv",
      " pKLK KLK     vv",
      " vM  M   vNNNNvv",
      "vvvvvvvvvvvvvvvv"
    ],
    [
      "              vv",
      "              vv",
      " v       vpppvvv",
      "         r    vv",
      "         r    vv",
      "         r    vv",
      "xvf      r    vv",
      "         r    vv",
      "         r    vv",
      "         r    vv",
      "xvxx   xxv   vvv",
      " p            vv",
      " p           Ovv",
      " pPQP RQR    Svv",
      "TvM      v    vv",
      "vvvvvvvvvvvvvvvv"
    ],
    [
      "              vv",
      "              vv",
      " v       vpppvvv",
      "         r    vv",
      "         r    vv",
      "         r    vv",
      "xvf      r    vv",
      "         r    vv",
      "         r    vv",
      "         r    vv",
      "xvxxxxxxxv   vvv",
      " p            vv",
      " p            vv",
      " p            vv",
      "Uv       v    vv",
      "vvvvvvvvvvvvvvvv"
    ],
    [
      " r            vv",
      " r            vv",
      "rv       vpppvvv",
      "         j    vv",
      "         j    vv",
      "         j    vv",
      "jvf      j    vv",
      " j       j    vv",
      " j       j    vv",
      " j       j    vv",
      "xvjjjjjjjv   vvv",
      "Vp            vv",
      "Vp            vv",
      "Vp            vv",
      "Vv       v    vv",
      "vvvvvvvvvvvvvvvv"
    ],
    [
      " WXXXXXXXXXXXYvv",
      " WXXXXXXXXXXXYvv",
      "Wvaaaaaaavaaavvv",
      "XaXXXXXXXaXXXYvv",
      "XaXXXXXXXaXXXYvv",
      "XaXXXXXXXaXXXYvv",
      "XvfXXXXXXaXXXYvv",
      "XaXXXXXXXaXXXYvv",
      "XaXXXXXXXaXXXYvv",
      "XaXXXXXXXaXXXYvv",
      "avaaaaaaavaaavvv",
      "ZaXXXXXXXaXXXYvv",
      " aXXXXXXXaXXXYvv",
      "ZaXXXXXXXaXXXYvv",
      "YvYYYYYYYvYYYYvv",
      "vvvvvvvvvvvvvvvv"
    ]
  ]
}