{
  "name": "multi_militarybase_5_base1",
  "refpalette": "deceasedcraft:multi_militarybase_5/multi_militarybase_5_base1_palette",
  "xsize": 16,
  "zsize": 16,
  "slices": [
    [
      " abbbcccccccccvv",
      " abbbcdcccccccvv",
      "avaaaaaaavaaavvv",
      "baebbdcccaccccvv",
      "babbbccccaccccvv",
      "babbdccccaccccvv",
      "fvgcccccdaccccvv",
      "cacccdcccaccccvv",
      "cacccccccaccccvv",
      "caccccdccaccccvv",
      "avaaaaaaavaaavvv",
      "cacccccccaccccvv",
      "cacccccccaccccvv",
      "cacccccccaccccvv",
      "cvcccccccvccccvv",
      "vvvvvvvvvvvvvvvv"
    ],
    [
      " hij  kl m    vv",
      " h  n  o  pqqpvv",
      "hv     r vsssvvv",
      "      o  tu  wvv",
      "x     yAot  BCvv",
      "      kl t   Cvv",
      "Dvg  n   E   Cvv",
      " sF o    t  ICvv",
      "JsKL  MN t M Cvv",
      " s      ot O wvv",
      " vDDDPDDDvsisvvv",
      " s       s   Qvv",
      " R       s S Qvv",
      " s       sMT Qvv",
      "UvVWVWVWVvQQQQvv",
      "vvvvvvvvvvvvvvvv"
    ],
    [
      "      X       vv",
      "          ppppvv",
      " v       vsssvvv",
      "         t    vv",
      "         t   YZv",
      "       r t    0v",
      "Dv       1    0v",
      " s       t   Y0v",
      "Js       t    Zv",
      " s       t   2vv",
      " vDDD3DDDvs svvv",
      " s       s   4vv",
      " 5       s    vv",
      " s       s   6vv",
      "UvV V V VvQ 6!vv",
      "vvvvvvvvvvvvvvvv"
    ],
    [
      "              vv",
      "          p7p7vv",
      " v       vsssvvv",
      "         t    vv",
      "         t    0v",
      "         t    0v",
      "Dv       t    0v",
      " s       t    Zv",
      "Js       t    0v",
      " s       t    vv",
      " vDDDDDDDvsssvvv",
      " s       s   Jvv",
      " s       s    vv",
      " s       s    vv",
      " v8 8 8 8vJ   vv",
      "vvvvvvvvvvvvvvvv"
    ],
    [
      " 9            vv",
      " 9           #vv",
      "9v       vsssvvv",
      "         h    vv",
      "         h    vv",
      "         h    vv",
      "Dv       h    vv",
      " s       h    vv",
      "Js       h    vv",
      " s       h    vv",
      " vhhhhhhhvsssvvv",
      " s       s   Jvv",
      " s       s    vv",
      " s       s    vv",
      " v$ $ $ $vJ   vv",
      "vvvvvvvvvvvvvvvv"
    ],
    [
      "%a^^^^^^^^^^^Jvv",
      "%a^^^^^^^^^^^Jvv",
      "avaaaaaaavaaavvv",
      "^a^^^^^^^a^^^Jvv",
      "^a^^^^^^^a^^^Jvv",
      "^a^^^^^^^a^^^Jvv",
      "&v^^^^^^^a^^^Jvv",
      "^a^^^^^^^a^^^Jvv",
      "Ja^^^^^^^a^^^Jvv",
      "^a^^^^^^^a^^^Jvv",
      "avaaaaaaavaaavvv",
      "^a^^^^^^^a^^^Jvv",
      "^a^^^^^^^a^^^Jvv",
      "^a^^^^^^^a^^^Jvv",
      "JvJJJJJJJvJJJJvv",
      "vvvvvvvvvvvvvvvv"
    ]
  ]
}