{
  "name": "multi_militarybase_5_base3",
  "refpalette": "deceasedcraft:multi_militarybase_5/multi_militarybase_5_base3_palette",
  "xsize": 16,
  "zsize": 16,
  "slices": [
    [
      " abbbcccccccccvv",
      "dabbbcccccccccvv",
      "avaaaaaaavaaavvv",
      "babbbccccaccccvv",
      "babbbccccaccccvv",
      "babbcccccaccccvv",
      "evcccccccaccccvv",
      "cacccccccaccccvv",
      "cacccccccaccccvv",
      "cccccccccaccccvv",
      "avaaaaaaavaaavvv",
      "cacccccccaccccvv",
      "cacccccccaccccvv",
      "cacccccccaccccvv",
      "cvcccccccvccccvv",
      "vvvvvvvvvvvvvvvv"
    ],
    [
      " f  ghij jijklvv",
      " f   jmj jmj lvv",
      "fv       vnnnvvv",
      "     jij opqqrvv",
      "  st jmj o   uvv",
      "          s  wvv",
      " vx   y   A  wvv",
      "     BC      wvv",
      "     ji  oD  uvv",
      " j EF mj oD  Ivv",
      " v       vn nvvv",
      " jijJjij nK  Lvv",
      " jmjBjmj nK  Lvv",
      "         nKMMLvv",
      " vNNOjEj vKPLLvv",
      "vvvvvvvvvvvvvvvv"
    ],
    [
      "      y   Q   vv",
      "              vv",
      " v       vnnnvvv",
      "         oR   vv",
      "         o   Svv",
      "              vv",
      " vx           vv",
      "              vv",
      "         o    vv",
      "      T  o   Uvv",
      " v       vn nvvv",
      "  !      nK   vv",
      "         n   Lvv",
      "         nKMVLvv",
      " v       vW!LLvv",
      "vvvvvvvvvvvvvvvv"
    ],
    [
      "              vv",
      "             Vvv",
      " v       vnnnvvv",
      "         o!   vv",
      "         o   Xvv",
      "         o   Yvv",
      " vx      o   Xvv",
      "         o   Yvv",
      "         o   Yvv",
      "         o    vv",
      " v       vnnvvvv",
      "         n    vv",
      "         n   Vvv",
      "         n    vv",
      " v       vKVZZvv",
      "vvvvvvvvvvvvvvvv"
    ],
    [
      " 0            vv",
      " 0            vv",
      "0v       vnnnvvv",
      "         f    vv",
      "         f    vv",
      "         f   1vv",
      " vx      f   1vv",
      "         f   1vv",
      "         f    vv",
      "         f    vv",
      "fvfffffffvnnnvvv",
      "         n    vv",
      "         n    vv",
      "         n    vv",
      " v       v   Vvv",
      "vvvvvvvvvvvvvvvv"
    ],
    [
      " 2333333333331vv",
      " 2333333333331vv",
      "2vaaaaaaavaaavvv",
      "3a3333333a3331vv",
      "3a3333333a3331vv",
      "3a3333333a3331vv",
      "3vx333333a3331vv",
      "3a3333333a3331vv",
      "3a3333333a3331vv",
      "3a3333333a3331vv",
      "avaaaaaaavaaavvv",
      "3a3333333a3331vv",
      "3a3333333a3331vv",
      "3a3333333a3331vv",
      "1v1111111v1111vv",
      "vvvvvvvvvvvvvvvv"
    ]
  ]
}