{
  "name": "multi_militarybase_5_ground",
  "refpalette": "deceasedcraft:multi_militarybase_5/multi_militarybase_5_ground_palette",
  "xsize": 16,
  "zsize": 16,
  "slices": [
    [
      "aaaabcccaccaazdz",
      "aaaaaaaaaaaazzdz",
      "aaaaaaaaaaaazadz",
      "aeaacacccccaazdz",
      "aaaaaaaaabaazzdz",
      "aaaaaaaaaaaaaadz",
      "aaaaaaaaaaaazadz",
      "aaaaaaaaaaaazzdz",
      "faaaaaaaaaaaazdz",
      "aaaaaaaaaaaazzdz",
      "aaaaaaaaaaaaazdz",
      "aaaaaaaaaaaazadz",
      "azzzaazzazazzzdz",
      "aazzzzazaazzaadz",
      "dddddddddddddddz",
      "zzzzzzzzzzzzzzzz"
    ],
    [
      "        g    hij",
      " k  l  k   m  d ",
      "  n   op k   md ",
      "q k r  s      d ",
      "qq  t      u wd ",
      " qq p  xxx    d ",
      "  qy  ABBBA CDd ",
      "  qn EBFBFBI wd ",
      "f q  EBFFFBI wd ",
      "  q  EBFBFBI  d ",
      "  q   ABBBA  wd ",
      "qqqrJ  KKK    d ",
      "      L       d ",
      "   ww D   w  Dd ",
      "ddddddddddddddd ",
      "                "
    ],
    [
      "          M   N ",
      "              d ",
      "              d ",
      "q             d ",
      "qq            d ",
      " qq           d ",
      "  q         CDd ",
      "  q           d ",
      "f q     O     d ",
      "  q           d ",
      "  q     ~     d ",
      "qqq           d ",
      "      L       d ",
      "      D      Dd ",
      "ddddddddddddddd ",
      "                "
    ],
    [
      "           P  Q ",
      "              d ",
      "              d ",
      "q             d ",
      "qq            d ",
      " qq           d ",
      "  q         CDd ",
      "  q           d ",
      "  q           d ",
      "  q           d ",
      "  q    ~~     d ",
      "qqq           d ",
      "      L       d ",
      "      D      Dd ",
      "ddddddddddddddd ",
      "                "
    ],
    [
      "          R   d ",
      "              d ",
      "              d ",
      "S             d ",
      "SS            d ",
      " SS           d ",
      "  S         CDd ",
      "  S           d ",
      "  S           d ",
      "  S           d ",
      "  S     ~     d ",
      "SSS           d ",
      "      L       d ",
      "      D      Dd ",
      "ddddddddddddddd ",
      "                "
    ],
    [
      "             TU ",
      "             TU ",
      "             TU ",
      "             TU ",
      "             TU ",
      "             TU ",
      "            CVW ",
      "             TX ",
      "             TU ",
      "             TU ",
      "        ~    TU ",
      "             TU ",
      "      L      TU ",
      "TTTTTTVTTTTTTVY ",
      "ZZZZZZ!ZZZZZZYY ",
      "                "
    ]
  ]
}