{
  "name": "multi_convenientstore_2_ground",
  "refpalette": "deceasedcraft:multi_convenientstore_2/multi_convenientstore_2_ground_palette",
  "xsize": 16,
  "zsize": 16,
  "slices": [
    [
      "aaaaaaaaaabcHHca",
      "aaaaaaaaaabcHHca",
      "bbbbbbbbbbbcHHca",
      "HHHHHHHHHHccHHca",
      "HHHHHHHHHHccHHca",
      "HHHHHHHHHHccHHca",
      "HHHHHHHHHHcHHHca",
      "HHHHHHHHHHHHHHca",
      "HHHHHHHHHHHHHHca",
      "HHHHHHHHHHHHHHca",
      "ccccccccccccHHca",
      "bbbbbbbbbbbcHHcb",
      "bbbbbbbbbbbcHHcb",
      "bbbbbbbbbbbcHHcb",
      "bbbbbbbbbbbcHHcb",
      "bbbbbbbbbbbcHHcb"
    ],
    [
      "dddddddddef     ",
      "eeeeeeeeeef     ",
      "fffffffffff     ",
      "ghghghghgh  ij  ",
      "k               ",
      "      l     m   ",
      "nonononono      ",
      "                ",
      "    p           ",
      " m              ",
      "                ",
      "fffffffffff    f",
      "bbbbbbbbbbb    f",
      "bbbbbbbbbbb    f",
      "bbbbbbbbbbb    q",
      "rrrrrrrrrrbsttsq"
    ],
    [
      "                ",
      "                ",
      "                ",
      "                ",
      "                ",
      "                ",
      "                ",
      "                ",
      "                ",
      "                ",
      "                ",
      "                ",
      "      u         ",
      "w xxxxuyAyy     ",
      "BCCCCCccccy     ",
      "  D   EFIJy     "
    ],
    [
      "                ",
      "                ",
      "                ",
      "                ",
      "                ",
      "                ",
      "                ",
      "                ",
      "                ",
      "                ",
      "                ",
      "                ",
      "      u         ",
      "w xxxxuyKyy     ",
      "BCCCCCccCcy     ",
      "      E   y     "
    ],
    [
      "                ",
      "                ",
      "                ",
      "                ",
      "                ",
      "                ",
      "                ",
      "                ",
      "                ",
      "                ",
      "                ",
      "                ",
      "      u         ",
      "L xxxxuy yy     ",
      "BCCCCCccCcy     ",
      "      E   y     "
    ],
    [
      "                ",
      "                ",
      "                ",
      "                ",
      "                ",
      "                ",
      "                ",
      "                ",
      "                ",
      "                ",
      "                ",
      "                ",
      "      u         ",
      "x xxxxuy yy     ",
      "CCCCCCccCcy     ",
      "      E   y     "
    ]
  ]
}