{
  "name": "multi_timbertower_2_floor1",
  "refpalette": "deceasedcraft:multi_timbertower_2/multi_timbertower_2_floor1_palette",
  "xsize": 16,
  "zsize": 16,
  "slices": [
    [
      "   abcddefffgggg",
      "   abcddffefgggg",
      "   hbcdedfffgigg",
      "   abcdddefegggg",
      "   abcdedfdedded",
      "   abcddfefffedd",
      "   abcddddfedefd",
      "   abcddeeedfddf",
      "   abcddefdddedd",
      "   hbcdeddfdeddd",
      "   abcddeddddddd",
      "   abcdddddddddd",
      "   aaahaaaaaahaa",
      "                ",
      "                ",
      "                "
    ],
    [
      "   ajkl    m n  ",
      "   ajko    p n! ",
      "   hjqo    r iss",
      "   ajko    t    ",
      "   ajul         ",
      "   ajqo         ",
      "   ajkl         ",
      "   ajko         ",
      "   ajqo         ",
      "   hjuo         ",
      "   ajkl         ",
      "   ajkw      w  ",
      "   aaahaaaaaahaa",
      "                ",
      "                ",
      "                "
    ],
    [
      "   ajx     y nAA",
      "   ajx       nBA",
      "   hjC       iss",
      "   aDx          ",
      "   aj           ",
      "   ajC          ",
      "   ajx          ",
      "   aDx          ",
      "   ajC          ",
      "   hD           ",
      "   ajx          ",
      "   ajx          ",
      "   aaahaaaaaahaa",
      "                ",
      "                ",
      "                "
    ],
    [
      "   aj        n  ",
      "   a         nE ",
      "   hj        iss",
      "   aD           ",
      "   aD           ",
      "   aj           ",
      "   aj           ",
      "   a            ",
      "   aj           ",
      "   hj           ",
      "   aj           ",
      "   aD           ",
      "   aaahaaaaaFI  ",
      "                ",
      "                ",
      "                "
    ],
    [
      "   aD        J  ",
      "   a         J  ",
      "   hj        iss",
      "   a            ",
      "   a            ",
      "   a            ",
      "   aj           ",
      "   a            ",
      "   a            ",
      "   h            ",
      "   aj           ",
      "   a            ",
      "   aaahaFF      ",
      "                ",
      "                ",
      "                "
    ],
    [
      "   F       K i  ",
      "   F       K i  ",
      "   I      LMNiii",
      "   F       O N  ",
      "   F        PMQQ",
      "   F         L  ",
      "   F            ",
      "   F            ",
      "   F            ",
      "   I            ",
      "   F            ",
      "   F            ",
      "   FFF          ",
      "                ",
      "                ",
      "                "
    ]
  ]
}