{
  "name": "multi_timbertower_2_ground",
  "refpalette": "deceasedcraft:multi_timbertower_2/multi_timbertower_2_ground_palette",
  "xsize": 16,
  "zsize": 16,
  "slices": [
    [
      "HHHvvHHHHHHHHHHv",
      "HHHvvHHHHHHHHHHH",
      "HHHvvHaHHHHHHaHH",
      "HHHvvHHHHHHHHHHH",
      "HHHvvHHHHHHHHHHH",
      "HHHvvHHHHHHHHHHH",
      "HHHvvHHHHHHHHHHH",
      "HHHvvHHHHHHHHHHH",
      "HHHvvHHHHHHHHHHH",
      "HHHvvHaHHHHHHaHH",
      "HHHvvHHHHHHHHHHH",
      "HHHvvvvvvvvvvvvv",
      "HHHvvvvvvvvvvvvv",
      "HHHbbbcbbbbbbcbb",
      "HHHbcbccbbcccbcb",
      "HHHbbbbbcbbbccbb"
    ],
    [
      "   def g    h ij",
      "   deh i      fg",
      "  kle am    ka  ",
      "   def g     nhi",
      "   deh i        ",
      "   def g        ",
      "   deh i        ",
      "   deooo        ",
      "   de   pfgfgqfg",
      "  kle a p r  a  ",
      "   de   phihi hi",
      "   deeeeeeeeeeee",
      "   dddlddddddldd",
      "   sst stssts ts",
      "                ",
      "                "
    ],
    [
      "   d            ",
      "   d            ",
      "   l  a      a  ",
      "   d            ",
      "   d            ",
      "   d            ",
      "   d            ",
      "   d            ",
      "   d            ",
      "   l  a      a  ",
      "   d            ",
      "   d            ",
      "   dddlddddddldd",
      "                ",
      "                ",
      "                "
    ],
    [
      "   d            ",
      "   d            ",
      "   l  a      a  ",
      "   d            ",
      "   d            ",
      "   d            ",
      "   d            ",
      "   d            ",
      "   d            ",
      "   l  a      a  ",
      "   d            ",
      "   d            ",
      "   dddlddddddldd",
      "                ",
      "                ",
      "                "
    ],
    [
      "   d            ",
      "   d            ",
      "   l  a      a  ",
      "   d            ",
      "   d            ",
      "   d            ",
      "   d            ",
      "   d            ",
      "   d            ",
      "   l  a      a  ",
      "   d            ",
      "   d            ",
      "   dddlddddddldd",
      "                ",
      "                ",
      "                "
    ],
    [
      "   duuauuuuuuauu",
      "   duuauuuuuuauu",
      "  ulaaaaaaaaaaaa",
      "  ujuuauuuuuuauu",
      "  ujuuauuuuuuauu",
      "  ujuuauuuuuuauu",
      "  ujuuauuuuuuauu",
      "  ujuuauuuuuuauu",
      "  ujuuauuuuuuauu",
      "  ulaaaaaaaaaaaa",
      "   duuauuuuuuauu",
      "   duuauuuuuuauu",
      "   dddlddddddldd",
      "                ",
      "                ",
      "                "
    ]
  ]
}