{
  "name": "multi_verticalschool_22_base2",
  "refpalette": "deceasedcraft:multi_verticalschool_22/multi_verticalschool_22_base2_palette",
  "xsize": 16,
  "zsize": 16,
  "slices": [
    [
      "vvvvvvvvvvvvvvvv",
      "vvvvvvvvvvvvvvvv",
      "vvvvvvvvvvvvvvvv",
      "vvvvvvvvvvvvvvvv",
      "vvvvvvvvvvvvvvvv",
      "vvvvvvvvvvvvvvvv",
      "vvvvvvvvvvvvvvvv",
      "vvvvvvvvvvvvvvvv",
      "vvvvvvvvvvvvvvvv",
      "vvvvvvvvvvvvvvvv",
      "vvvvvvvvvvvvvvvv",
      "vvvvvvvvvvvvvvvv",
      "vvvvvvvvvvvvvvvv",
      "vvvvvvvvvvvvvvvv",
      "vvvvvvvvvvvvvvvv",
      "vvvvvvvvvvvvvvvv"
    ],
    [
      "aaaaaaabbbaccccv",
      "aaaaaaaaaaaccccv",
      "aaaaaaaaaaaccccv",
      "aaaaaaaaaaaccccv",
      "aaaaaaaaaaaccccv",
      "aaaaaaaaaaaccccv",
      "aaaaaaaaaaaccccv",
      "aaaaaaaaaaaccccv",
      "aaaaaaaaaaaccccv",
      "aaaaaaaaaaaccccv",
      "aaaaaaaaaaaccccv",
      "aaaaaaaaaaaccccv",
      "aaaaaaaaaaaccccv",
      "aaaaaaaaaaaccccv",
      "aaaaaaaaaaaccccv",
      "aaaaaaabbbaccccv"
    ],
    [
      "aaaaaaabbbaccccv",
      "aaaaaaaaaaaccccv",
      "aaaaaaaaaaaccccv",
      "aaaaaaaaaaaccccv",
      "aaaaaaaaaaaccccv",
      "aaaaaaaaaaaccccv",
      "aaaaaaaaaaaccccv",
      "aaaaaaaaaaaccccv",
      "aaaaaaaaaaaccccv",
      "aaaaaaaaaaaccccv",
      "aaaaaaaaaaaccccv",
      "aaaaaaaaaaaccccv",
      "aaaaaaaaaaaccccv",
      "aaaaaaaaaaaccccv",
      "aaaaaaaaaaaccccv",
      "aaaaaaabbbaccccv"
    ],
    [
      "HHHHHHHbbbdddddv",
      "HHHHHHHHHedaaadv",
      "HHHHHHHHHedaaadv",
      "HHHHHHHHHedaaadv",
      "HHHfHHHHHedaaadv",
      "ghghghghgidaaadv",
      "ghghghghgidaaadv",
      "ghghghghgidaaadv",
      "ghghghghgidaaadv",
      "ghghghghgidaaadv",
      "ghghghghgidaaadv",
      "HHHfHHHHHedaaadv",
      "HHHHHHHHHedaaadv",
      "HHHHHHHHHedaaadv",
      "HHHHHHHHHedaaadv",
      "HHHHHHHbbbdddddv"
    ],
    [
      "       bbbdddddv",
      "          djjjdv",
      "          kkkkdv",
      "          lkkkdv",
      "   m      lkkkdv",
      "          lkkkdv",
      "          lkkkdv",
      "          lkkkdv",
      "          lkkkdv",
      "          lkkkdv",
      "          lkkkdv",
      "   n      lkkkdv",
      "          lkkkdv",
      "          kkkkdv",
      "          djjjdv",
      "       bbbdddddv"
    ],
    [
      "       bbboppppv",
      "          oqqqpv",
      "          r   pv",
      "            s pv",
      "            s pv",
      "            s pv",
      "            s pv",
      "              pv",
      "              pv",
      "            s pv",
      "            s pv",
      "            s pv",
      "            s pv",
      "          r   pv",
      "          oqqqpv",
      "       bbboppppv"
    ]
  ]
}