{
  "name": "multi_verticalschool_22_base1",
  "refpalette": "deceasedcraft:multi_verticalschool_22/multi_verticalschool_22_base1_palette",
  "xsize": 16,
  "zsize": 16,
  "slices": [
    [
      "       aaabccccv",
      "          bdddcv",
      "          e   cv",
      "              cv",
      "              cv",
      "              cv",
      "              cv",
      "              cv",
      "              cv",
      "              cv",
      "              cv",
      "              cv",
      "              cv",
      "          e   cv",
      "          bdddcv",
      "       aaabccccv"
    ],
    [
      "       aaabccccv",
      "          bd dcv",
      "          e   cv",
      "              cv",
      "              cv",
      "              cv",
      "              cv",
      "              cv",
      "              cv",
      "              cv",
      "              cv",
      "              cv",
      "              cv",
      "          e   cv",
      "          bdddcv",
      "       aaabccccv"
    ],
    [
      "       aaabccccv",
      "          b  dcv",
      "          f   cv",
      "          g   cv",
      "          h   cv",
      "          h   cv",
      "          h   cv",
      "          h   cv",
      "          h   cv",
      "          h   cv",
      "          h   cv",
      "          h   cv",
      "          i   cv",
      "          j   cv",
      "          bdd cv",
      "       aaabccccv"
    ],
    [
      "       aaabccccv",
      "          b   cv",
      "          k   cv",
      "          g   cv",
      "          h   cv",
      "          h   cv",
      "          h   cv",
      "          h   cv",
      "          h   cv",
      "          h   cv",
      "          h   cv",
      "          h   cv",
      "          i   cv",
      "          l   cv",
      "          b   cv",
      "       aaabccccv"
    ],
    [
      "       aaabccccv",
      "          b   cv",
      "          bmmmcv",
      "          bmmmcv",
      "          bmmmcv",
      "          bmmmcv",
      "          bmmmcv",
      "          bmmmcv",
      "          bmmmcv",
      "          bmmmcv",
      "          bmmmcv",
      "          bmmmcv",
      "          bmmmcv",
      "          bmmmcv",
      "          b   cv",
      "       aaabccccv"
    ],
    [
      "      naaaooooov",
      "       nppoqqqov",
      "        npommmov",
      "         npmmmov",
      "          npmmov",
      "           npmov",
      "           npmov",
      "       rr  npmov",
      "       rrnnpmmov",
      "      nnnppmmmov",
      "   nnnppppommmov",
      "nnnpppppppommmov",
      "ppppppppppommmov",
      "ppppppppppommmov",
      "ppppppppppoqqqov",
      "pppppppaaaooooov"
    ]
  ]
}