{
  "name": "multi_casino_12_base1",
  "refpalette": "deceasedcraft:multi_casino_12/multi_casino_12_base1_palette",
  "xsize": 16,
  "zsize": 16,
  "slices": [
    [
      "vvvvvvvvvvvvvvvv",
      "aaaaaaaaaaaaaaav",
      "bbbbbbbbbbbbbbav",
      "c  cdc c   cdbav",
      "            cbav",
      "             bav",
      "            cbav",
      "  e     f   cbav",
      "             bav",
      "            cbav",
      "            cbav",
      "            dbav",
      "            cbav",
      "        e   cbav",
      "             bav",
      "             bav"
    ],
    [
      "vvvvvvvvvvvvvvvv",
      "aaaaaaaaaaaaaaav",
      "bbbbbbbbbbbbbbav",
      "   cd       dbav",
      "             bav",
      "             bav",
      "             bav",
      "  e     f   cbav",
      "             bav",
      "             bav",
      "            cbav",
      "            dbav",
      "            cbav",
      "        e    bav",
      "             bav",
      "             bav"
    ],
    [
      "vvvvvvvvvvvvvvvv",
      "aaaaaaaaaaaaaaav",
      "bbbbbbbbbbbbbbav",
      "    d       dbav",
      "             bav",
      "             bav",
      "             bav",
      "  g    hf    bav",
      "        i    bav",
      "             bav",
      "             bav",
      "            dbav",
      "             bav",
      "        g    bav",
      "             bav",
      "             bav"
    ],
    [
      "vvvvvvvvvvvvvvvv",
      "aaaaaaaaaaaaaaav",
      "bbbbbbbbbbbbbbav",
      "    d       dbav",
      "             bav",
      "             bav",
      "             bav",
      "  j     f    bav",
      "             bav",
      "             bav",
      "             bav",
      "            dbav",
      "             bav",
      "        j    bav",
      "             bav",
      "             bav"
    ],
    [
      "vvvvvvvvvvvvvvvv",
      "aaaaaaaaaaaaaaav",
      "bbbbbbbbbbbbbbav",
      "    d       dbav",
      "kkkkklkkkkkl bav",
      "kkkkkklkkklk bav",
      "kkkkkkklklkk bav",
      "mknkmkkkfkkk bav",
      "kkkkkkklklkk bav",
      "kkkkkklkkklk bav",
      "kkkkklkkkkkl bav",
      "mkkkmkkkmkkkdbav",
      "kkklkkkkkkkk bav",
      "kklkkkkknkkk bav",
      "klkkkkkkkkkk bav",
      "mkkkmkkkmkkk bav"
    ],
    [
      "vvvvvvvvvvvvvvvv",
      "aaaaaaaaaaaaaaav",
      "bbbbbbbbbbbbbbav",
      "oooodooooooodbav",
      "ppppqfpppppfrbav",
      "qqqqqqfqqqfprbav",
      "qqqqqqqfqfqprbav",
      "sqqqsqqqfqqprbav",
      "qqqqqqqfqfqprbav",
      "qqqqqqfqqqfprbav",
      "qqqqqfqqqqqfrbav",
      "sqqqfqqqsqqqdbav",
      "qqqfqqqqqqqprbav",
      "qqfqqqqqqqqprbav",
      "qfqqqqqqqqqprbav",
      "fqqqsqqqsqqprbav"
    ]
  ]
}