{
  "name": "multi_casino_12_base9",
  "refpalette": "deceasedcraft:multi_casino_12/multi_casino_12_base9_palette",
  "xsize": 16,
  "zsize": 16,
  "slices": [
    [
      "vvvvvvvvvvvvvvvv",
      "aaaaaaaaaaaaaaav",
      "aaaaaaaaaaaaaaav",
      "aaaaaaaaaaaaaaav",
      "aaaaaaaaaaaaaaav",
      "aaaaaaaaaaaaaaav",
      "aaaaaaaaaaaaaaav",
      "bbbbbbbbbaaaaaav",
      "bbbbbbbbbaaaaaav",
      "bbbbbbbbbaaaaaav",
      "bbbbbbbbbaaaaaav",
      "bbbbbbbbbaaaaaav",
      "bbbbbbbbbaaaaaav",
      "bbbbbbbbbaaaaaav",
      "bbbbbbbbbaaaaaav",
      "bbbbbbbbbaaaaaav"
    ],
    [
      "vvvvvvvvvvvvvvvv",
      "aaaaaaaaaaaaaaav",
      "aaaaaaaaaaaaaaav",
      "aaaaaaaaaaaaaaav",
      "aaaaaaaaaaaaaaav",
      "aaaaaaaaaaaaaaav",
      "aaaaaaaaaaaaaaav",
      "ccccccccdaaaaaav",
      "cccccccccaaaaaav",
      "cccccccccaaaaaav",
      "cccccccccaaaaaav",
      "cccccccccaaaaaav",
      "cccccccccaaaaaav",
      "cccccccccaaaaaav",
      "cccccccccaaaaaav",
      "cccccccccaaaaaav"
    ],
    [
      "vvvvvvvvvvvvvvvv",
      "aaaaaaaaaaaaaaav",
      "aaaaaaaaaaaaaaav",
      "aaaaaaaaaaaaaaav",
      "aaaaaaaaaaaaaaav",
      "aaaaaaaaaaaaaaav",
      "aaaaaaaaaaaaaaav",
      "ccccccccdaaaaaav",
      "cccccccccaaaaaav",
      "cccccccccaaaaaav",
      "cccccccccaaaaaav",
      "cccccccccaaaaaav",
      "cccccccccaaaaaav",
      "cccccccccaaaaaav",
      "cccccccccaaaaaav",
      "cccccccccaaaaaav"
    ],
    [
      "vvvvvvvvvvvvvvvv",
      "aaaaaaaaaaaaaaav",
      "aaaaaaaaaaaaaaav",
      "aaaaaaaaaaaaaaav",
      "aaaaaaaaaaaaaaav",
      "aaaaaaaaaaaaaaav",
      "aaaaaaaaaaaaaaav",
      "ccccccccdaaaaaav",
      "cccccccccaaaaaav",
      "cccccccccaaaaaav",
      "cccccccccaaaaaav",
      "cccccccccaaaaaav",
      "cccccccccaaaaaav",
      "cccccccccaaaaaav",
      "cccccccccaaaaaav",
      "cccccccccaaaaaav"
    ],
    [
      "vvvvvvvvvvvvvvvv",
      "aaaaaaaaaaaaaaav",
      "aaaaaaaaaaaaaaav",
      "aaaaaaaaaaaaaaav",
      "aaaaaaaaaaaaaaav",
      "aaaaaaaaaaaaaaav",
      "aaaaaaaaaaaaaaav",
      "ccccccccdaaaaaav",
      "cccccccccaaaaaav",
      "cccccccccaaaaaav",
      "cccccccccaaaaaav",
      "cccccccccaaaaaav",
      "cccccccccaaaaaav",
      "cccccccccaaaaaav",
      "cccccccccaaaaaav",
      "cccccccccaaaaaav"
    ],
    [
      "vvvvvvvvvvvvvvvv",
      "aaaaaaaaaaaaaaav",
      "aaaaaaaaaaaaaaav",
      "aaaaaaaaaaaaaaav",
      "aaaaaaaaaaaaaaav",
      "aaaaaaaaaaaaaaav",
      "aaaaaaaaaaaaaaav",
      "ccccccccdaaaaaav",
      "cccccccdcaaaaaav",
      "ccccccdccaaaaaav",
      "cccccdcccaaaaaav",
      "ccccdccccaaaaaav",
      "cccdcccccaaaaaav",
      "ccdccccccaaaaaav",
      "cdcccccccaaaaaav",
      "dccccccccaaaaaav"
    ]
  ]
}