{
  "name": "multi_casino_12_base2",
  "refpalette": "deceasedcraft:multi_casino_12/multi_casino_12_base2_palette",
  "xsize": 16,
  "zsize": 16,
  "slices": [
    [
      "vvvvvvvvvvvvvvvv",
      "aaaaaaaaaaaaaaav",
      "bbbbbbbbbbbbbbav",
      "ccccdcccccccdbav",
      "eeeeeeeeeeeecbav",
      "fffffffffffecbav",
      "ggggggggggfecbav",
      "gggggggghgfecbav",
      "ggggggggggfecbav",
      "ggggggggggfecbav",
      "ggggggggggfecbav",
      "ggggggggggfedbav",
      "ggggggggggfecbav",
      "ggggggggggfecbav",
      "ggggggggggfecbav",
      "ggggggggggfecbav"
    ],
    [
      "vvvvvvvvvvvvvvvv",
      "aaaaaaaaaaaaaaav",
      "bbbbbbbbbbbbbbav",
      "iiiidiiiiiiidbav",
      "    j       ibav",
      "            ibav",
      "            ibav",
      "klkmmnooh   ibav",
      "ppppqr  s   ibav",
      "t u u   s   ibav",
      "       wx   ibav",
      "      uyA  Bdbav",
      "       CA   ibav",
      " D    uCE   ibav",
      "FIJ    CK   ibav",
      "      LCE   ibav"
    ],
    [
      "vvvvvvvvvvvvvvvv",
      "aaaaaaaaaaaaaaav",
      "bbbbbbbbbbbbbbav",
      "iiiidiiiiiiidbav",
      "            ibav",
      "            ibav",
      "            ibav",
      "  M NO  h   ibav",
      "     P      ibav",
      "            ibav",
      "       QR   ibav",
      "        !   dbav",
      "        S   ibav",
      "            ibav",
      "            ibav",
      "            ibav"
    ],
    [
      "vvvvvvvvvvvvvvvv",
      "aaaaaaaaaaaaaaav",
      "bbbbbbbbbbbbbbav",
      "iiiidiiiiiiidbav",
      "            ibav",
      "            ibav",
      "            ibav",
      "TUTUTU  h   ibav",
      "     V      ibav",
      "            ibav",
      "       WX   ibav",
      "        Y   dbav",
      "        X   ibav",
      "        Y   ibav",
      "        X   ibav",
      "        Y   ibav"
    ],
    [
      "vvvvvvvvvvvvvvvv",
      "aaaaaaaaaaaaaaav",
      "bbbbbbbbbbbbbbav",
      "iiiidiiiiiiidbav",
      "            ibav",
      "            ibav",
      "            ibav",
      "  Z     h   ibav",
      "            ibav",
      "            ibav",
      "            ibav",
      "            dbav",
      "        0   ibav",
      "        Z   ibav",
      "            ibav",
      "            ibav"
    ],
    [
      "vvvvvvvvvvvvvvvv",
      "aaaaaaaaaaaaaaav",
      "bbbbbbbbbbbbbbav",
      "i iidiii i idbav",
      "            ibav",
      "            ibav",
      "            ibav",
      "  Z     h   ibav",
      "            ibav",
      "            ibav",
      "            ibav",
      "            dbav",
      "            ibav",
      "        Z   ibav",
      "            ibav",
      "             bav"
    ]
  ]
}