{
  "name": "multi_casino_12_base8",
  "refpalette": "deceasedcraft:multi_casino_12/multi_casino_12_base8_palette",
  "xsize": 16,
  "zsize": 16,
  "slices": [
    [
      "vvvvvvvvvvvvvvvv",
      "aaaaaaaaaaaaaaav",
      "bbbbbbbbbbbbbbav",
      "ccccdcccccccdbav",
      "eeeeeeeeeeeecbav",
      "fffffffffffecbav",
      "ggggggggggfecbav",
      "gggggggghgfecbav",
      "ggggggggggfecbav",
      "ggggggggggfecbav",
      "ggggggggggfecbav",
      "ggggggggggfedbav",
      "ggggggggggfecbav",
      "ggggggggggfecbav",
      "ggggggggggfecbav",
      "ggggggggggfecbav"
    ],
    [
      "vvvvvvvvvvvvvvvv",
      "aaaaaaaaaaaaaaav",
      "bbbbbbbbbbbbbbav",
      "iiiidiiiiiiidbav",
      "    j       ibav",
      "            ibav",
      "            ibav",
      "kklm    h   ibav",
      "    noop    ibav",
      "       q    ibav",
      "    rr q    ibav",
      "    rr s   tdbav",
      "        u   ibav",
      "        w   ibav",
      "        x   ibav",
      "       yx   ibav"
    ],
    [
      "vvvvvvvvvvvvvvvv",
      "aaaaaaaaaaaaaaav",
      "bbbbbbbbbbbbbbav",
      "iiiidiiiiiiidbav",
      "            ibav",
      "            ibav",
      "            ibav",
      "ABC     h   ibav",
      "            ibav",
      "            ibav",
      "            ibav",
      "            dbav",
      "            ibav",
      "        D   ibav",
      "        !   ibav",
      "        E   ibav"
    ],
    [
      "vvvvvvvvvvvvvvvv",
      "aaaaaaaaaaaaaaav",
      "bbbbbbbbbbbbbbav",
      "iiiidiiiiiiidbav",
      "            ibav",
      "            ibav",
      "            ibav",
      "        h   ibav",
      "            ibav",
      "            ibav",
      "            ibav",
      "            dbav",
      "            ibav",
      "            ibav",
      "            ibav",
      "            ibav"
    ],
    [
      "vvvvvvvvvvvvvvvv",
      "aaaaaaaaaaaaaaav",
      "bbbbbbbbbbbbbbav",
      "iiiidiiiiiiidbav",
      "            ibav",
      "            ibav",
      "            ibav",
      "        h   ibav",
      "            ibav",
      "            ibav",
      "            ibav",
      "            dbav",
      "            ibav",
      "            ibav",
      "            ibav",
      "            ibav"
    ],
    [
      "vvvvvvvvvvvvvvvv",
      "aaaaaaaaaaaaaaav",
      "bbbbbbbbbbbbbbav",
      "i iidiii i idbav",
      "            ibav",
      "            ibav",
      "            ibav",
      "        h   ibav",
      "            ibav",
      "            ibav",
      "            ibav",
      "            dbav",
      "            ibav",
      "            ibav",
      "            ibav",
      "             bav"
    ]
  ]
}