{
  "name": "multi_casino_12_base7",
  "refpalette": "deceasedcraft:multi_casino_12/multi_casino_12_base7_palette",
  "xsize": 16,
  "zsize": 16,
  "slices": [
    [
      "vvvvvvvvvvvvvvvv",
      "aaaaaaaaaaaaaaav",
      "bbbbbbbbbbbbbbav",
      "c  cdc c   cdbav",
      "            cbav",
      "             bav",
      "            cbav",
      "        e   cbav",
      "             bav",
      "            cbav",
      "            cbav",
      "            dbav",
      "            cbav",
      "            cbav",
      "             bav",
      "             bav"
    ],
    [
      "vvvvvvvvvvvvvvvv",
      "aaaaaaaaaaaaaaav",
      "bbbbbbbbbbbbbbav",
      "   cd       dbav",
      "             bav",
      "             bav",
      "             bav",
      "        e   cbav",
      "             bav",
      "             bav",
      "            cbav",
      "            dbav",
      "            cbav",
      "             bav",
      "             bav",
      "             bav"
    ],
    [
      "vvvvvvvvvvvvvvvv",
      "aaaaaaaaaaaaaaav",
      "bbbbbbbbbbbbbbav",
      "    d       dbav",
      "             bav",
      "             bav",
      "             bav",
      "       fe    bav",
      "        g    bav",
      "             bav",
      "             bav",
      "            dbav",
      "             bav",
      "             bav",
      "             bav",
      "             bav"
    ],
    [
      "vvvvvvvvvvvvvvvv",
      "aaaaaaaaaaaaaaav",
      "bbbbbbbbbbbbbbav",
      "    d       dbav",
      "             bav",
      "             bav",
      "             bav",
      "        e    bav",
      "             bav",
      "             bav",
      "             bav",
      "            dbav",
      "             bav",
      "             bav",
      "             bav",
      "             bav"
    ],
    [
      "vvvvvvvvvvvvvvvv",
      "aaaaaaaaaaaaaaav",
      "bbbbbbbbbbbbbbav",
      "    d       dbav",
      "hhhhhihhhhhi bav",
      "hhhhhhihhhih bav",
      "hhhhhhhihihh bav",
      "jhhhjhhhehhh bav",
      "hhhhhhhihihh bav",
      "hhhhhhihhhih bav",
      "hhhhhihhhhhi bav",
      "jhhhjhhhjhhhdbav",
      "hhhihhhhhhhh bav",
      "hhihhhhhhhhh bav",
      "hihhhhhhhhhh bav",
      "jhhhjhhhjhhh bav"
    ],
    [
      "vvvvvvvvvvvvvvvv",
      "aaaaaaaaaaaaaaav",
      "bbbbbbbbbbbbbbav",
      "kkkkdkkkkkkkdbav",
      "llllmelllllenbav",
      "mmmmmmemmmelnbav",
      "mmmmmmmememlnbav",
      "ommmommmemmlnbav",
      "mmmmmmmememlnbav",
      "mmmmmmemmmelnbav",
      "mmmmmemmmmmenbav",
      "ommmemmmommmdbav",
      "mmmemmmmmmmlnbav",
      "mmemmmmmmmmlnbav",
      "memmmmmmmmmlnbav",
      "emmmommmommlnbav"
    ]
  ]
}