{
  "name": "multi_casino_12_base4",
  "refpalette": "deceasedcraft:multi_casino_12/multi_casino_12_base4_palette",
  "xsize": 16,
  "zsize": 16,
  "slices": [
    [
      "vvvvvvvvvvvvvvvv",
      "aaaaaaaaaaaaaaav",
      "bbbbbbbbbbbbbbav",
      "ccccdcccccccdbav",
      "eeeeeeeeeeeecbav",
      "fffffffffffecbav",
      "ggggggggggfecbav",
      "gggggggghgfecbav",
      "ggggggggggfecbav",
      "ggggggggggfecbav",
      "ggggggggggfecbav",
      "ggggggggggfedbav",
      "ggggggggggfecbav",
      "ggggggggggfecbav",
      "ggggggggggfecbav",
      "ggggggggggfecbav"
    ],
    [
      "vvvvvvvvvvvvvvvv",
      "aaaaaaaaaaaaaaav",
      "bbbbbbbbbbbbbbav",
      "iiiidiiiiiiidbav",
      "    j       ibav",
      "            ibav",
      "            ibav",
      "k       h   ibav",
      "l    k      ibav",
      "mnk  l      ibav",
      "o  kpmnk    ibav",
      "k    o     qdbav",
      "     k      ibav",
      "      k     ibav",
      "      l     ibav",
      "    kpmnk   ibav"
    ],
    [
      "vvvvvvvvvvvvvvvv",
      "aaaaaaaaaaaaaaav",
      "bbbbbbbbbbbbbbav",
      "iiiidiiiiiiidbav",
      "            ibav",
      "            ibav",
      "            ibav",
      "        h   ibav",
      "r           ibav",
      " s   r      ibav",
      "t   u s     ibav",
      "     t      dbav",
      "            ibav",
      "            ibav",
      "      r     ibav",
      "     u s    ibav"
    ],
    [
      "vvvvvvvvvvvvvvvv",
      "aaaaaaaaaaaaaaav",
      "bbbbbbbbbbbbbbav",
      "iiiidiiiiiiidbav",
      "            ibav",
      "            ibav",
      "            ibav",
      "        h   ibav",
      "r           ibav",
      " s   r      ibav",
      "t   u s     ibav",
      "     t      dbav",
      "            ibav",
      "            ibav",
      "      r     ibav",
      "     u s    ibav"
    ],
    [
      "vvvvvvvvvvvvvvvv",
      "aaaaaaaaaaaaaaav",
      "bbbbbbbbbbbbbbav",
      "iiiidiiiiiiidbav",
      "            ibav",
      "            ibav",
      "            ibav",
      "        h   ibav",
      "w           ibav",
      "xy   w      ibav",
      "A   Bxy     ibav",
      "     A      dbav",
      "            ibav",
      "            ibav",
      "      w     ibav",
      "     Bxy    ibav"
    ],
    [
      "vvvvvvvvvvvvvvvv",
      "aaaaaaaaaaaaaaav",
      "bbbbbbbbbbbbbbav",
      "i iidiii i idbav",
      "            ibav",
      "            ibav",
      "            ibav",
      "        h   ibav",
      "C           ibav",
      " D   C      ibav",
      "E   F D     ibav",
      "     E      dbav",
      "            ibav",
      "            ibav",
      "      I     ibav",
      "     J!K     bav"
    ]
  ]
}