{
  "name": "multi_casino_12_base6",
  "refpalette": "deceasedcraft:multi_casino_12/multi_casino_12_base6_palette",
  "xsize": 16,
  "zsize": 16,
  "slices": [
    [
      "vvvvvvvvvvvvvvvv",
      "aaaaaaaaaaaaaaav",
      "bbbbbbbbbbbbbbav",
      "ccccdcccccccdbav",
      "eeeeeeeeeeeecbav",
      "fffffffffffecbav",
      "ggggggggggfecbav",
      "gggggggghgfecbav",
      "ggggggggggfecbav",
      "ggggggggggfecbav",
      "ggggggggggfecbav",
      "ggggggggggfedbav",
      "ggggggggggfecbav",
      "ggggggggggfecbav",
      "ggggggggggfecbav",
      "ggggggggggfecbav"
    ],
    [
      "vvvvvvvvvvvvvvvv",
      "aaaaaaaaaaaaaaav",
      "bbbbbbbbbbbbbbav",
      "iiiidiiiiiiidbav",
      "    j       ibav",
      "            ibav",
      "            ibav",
      "klkmmnooh   ibav",
      "ppppqr  s   ibav",
      "t t t   s   ibav",
      "       uw   ibav",
      "      txy  Adbav",
      "       By   ibav",
      " C    tBD   ibav",
      "EFI    BJ   ibav",
      " K    LBD   ibav"
    ],
    [
      "vvvvvvvvvvvvvvvv",
      "aaaaaaaaaaaaaaav",
      "bbbbbbbbbbbbbbav",
      "iiiidiiiiiiidbav",
      "            ibav",
      "            ibav",
      "            ibav",
      "  M NO  h   ibav",
      "     P      ibav",
      "            ibav",
      "       QR   ibav",
      "        S   dbav",
      "        T   ibav",
      "        U   ibav",
      "            ibav",
      "            ibav"
    ],
    [
      "vvvvvvvvvvvvvvvv",
      "aaaaaaaaaaaaaaav",
      "bbbbbbbbbbbbbbav",
      "iiiidiiiiiiidbav",
      "            ibav",
      "            ibav",
      "            ibav",
      "VWVWVW  h   ibav",
      "     X      ibav",
      "            ibav",
      "       YZ   ibav",
      "        0   dbav",
      "        Z   ibav",
      "        0   ibav",
      "        Z   ibav",
      "        0   ibav"
    ],
    [
      "vvvvvvvvvvvvvvvv",
      "aaaaaaaaaaaaaaav",
      "bbbbbbbbbbbbbbav",
      "iiiidiiiiiiidbav",
      "            ibav",
      "            ibav",
      "            ibav",
      "12345   h   ibav",
      "            ibav",
      "            ibav",
      "            ibav",
      "            dbav",
      "        6   ibav",
      "        3   ibav",
      "        7   ibav",
      "        8   ibav"
    ],
    [
      "vvvvvvvvvvvvvvvv",
      "aaaaaaaaaaaaaaav",
      "bbbbbbbbbbbbbbav",
      "i iidiii i idbav",
      "            ibav",
      "            ibav",
      "            ibav",
      "  3     h   ibav",
      "            ibav",
      "            ibav",
      "            ibav",
      "            dbav",
      "            ibav",
      "        3   ibav",
      "            ibav",
      "             bav"
    ]
  ]
}