{
  "name": "multi_terraceplaza_33_ground",
  "refpalette": "deceasedcraft:multi_terraceplaza_33/multi_terraceplaza_33_ground_palette",
  "xsize": 16,
  "zsize": 16,
  "slices": [
    [
      "aaaabcddefghiHHH",
      "aaaabcddefghiHHH",
      "aaaabcddefgjiHHH",
      "aaaabcddefghiHHH",
      "aaaaklmdefghiHHH",
      "aaaabcddefghiHHH",
      "aaaabcddefgjiHHH",
      "aaaabcddefghiHHH",
      "aaaabcddefghiHHH",
      "aaaabcddefghiHHH",
      "aaaabcddefghiHHH",
      "aaaabcddefghiHHH",
      "aaaabcddefghiHHH",
      "aaaabcddefgjiHHH",
      "aaaabcddefghiHHH",
      "nnnnklmdefghiHHH"
    ],
    [
      "opq  c  r st    ",
      "ouu  c  r st    ",
      "!    c  r sw    ",
      "ouu  c  r sx    ",
      "ypq k   A Bx    ",
      "ouu  c  r sx    ",
      "o    c  r sw    ",
      "ouu  c  r st    ",
      "opq  c  r st    ",
      "ouu  c  r st    ",
      "y    c  r st    ",
      "     c  r st    ",
      "     c  r st    ",
      "u uu c  r sw    ",
      "CCCC c  r sx    ",
      "DDDDk   A Bx    "
    ],
    [
      "EFI     JKs     ",
      "E    c  LKs     ",
      "E    c  JKsM    ",
      "E    c  LK      ",
      "EN  k   JKO     ",
      "E    c  JK      ",
      "E    c  LKsM    ",
      "E       LKs     ",
      "EFP  c  JKs     ",
      "E    c  LKs     ",
      "Q       JKs     ",
      "     c  JKs     ",
      "        LKs     ",
      "     c  JKsM    ",
      "N  R c  JK      ",
      "DDDDk   JKO     "
    ],
    [
      "        JK      ",
      "        LK      ",
      "        JK      ",
      "        LK      ",
      "    k   JKt     ",
      "        JK      ",
      "        LK      ",
      "        LK      ",
      "        JK      ",
      "        LK      ",
      "        JK      ",
      "        JK      ",
      "        LK      ",
      "        JK      ",
      "        JK      ",
      "DDDDk   JKt     "
    ],
    [
      "        JK      ",
      "        LK      ",
      "        JK      ",
      "        LK      ",
      "    k   JKt     ",
      "        JK      ",
      "        LK      ",
      "        LK      ",
      "        JK      ",
      "        LK      ",
      "        JK      ",
      "        JK      ",
      "        LK      ",
      "        JK      ",
      "        JK      ",
      "DDDDk   JKt     "
    ],
    [
      " S  T   JK      ",
      "    T   LK      ",
      "    T   JK      ",
      "    T   LK      ",
      "    k   JK      ",
      "        JK      ",
      "        LK      ",
      " S      LK      ",
      "        JK      ",
      "        LK      ",
      "        JK      ",
      "        JK      ",
      " S      LK      ",
      "        JK      ",
      "UUUUUVWWJK      ",
      "XXXXkYWWJK      "
    ]
  ]
}