{
  "name": "multi_terraceplaza_33_base2",
  "refpalette": "deceasedcraft:multi_terraceplaza_33/multi_terraceplaza_33_base2_palette",
  "xsize": 16,
  "zsize": 16,
  "slices": [
    [
      "aaaaaaaaaaabcccv",
      "aaaaaaaaaaabcccv",
      "aaaaaaaaaaabcccv",
      "aaaaaaaaaaabcccv",
      "aaaaaaaaaaabcccv",
      "aaaaaaaaaaabcccv",
      "aaaaaaaaaaabcccv",
      "aaaaaaaaaaabcccv",
      "aaaaaaaaaaabcccv",
      "aaaaaaaaaaabcccv",
      "aaaaaaaaaaabcccv",
      "aaaaaaaaaaabcccv",
      "aaaaaaaaaaabcccv",
      "aaaaaaaaaaabcccv",
      "aaaaaaaaaaabcccv",
      "aaaaaaaaaaabcccv"
    ],
    [
      "defegeehdijbcccv",
      "deegefghdijbcccv",
      " kkkkkk dijbcccv",
      "        dijbcccv",
      " lllllm  nnbcccv",
      "        dojbcccv",
      " pp  pp dojbcccv",
      "dqqhdrrhdojbcccv",
      "dqqhdrrhdojbcccv",
      " kk  kk dojbcccv",
      " pp  pp dsjbcccv",
      "d!ihdtthdojbcccv",
      "diihdtthdojbcccv",
      " kk  kk dojbcccv",
      "         nnbcccv",
      " lllllm  unbcccv"
    ],
    [
      " w  wx   dybcccv",
      "  Awx w  dybcccv",
      "         dybcccv",
      "         dybcccv",
      "         nnbcccv",
      "         dBbcccv",
      "         dBbcccv",
      "  C  DC  dBbcccv",
      " E   FD  dBbcccv",
      "         dBbcccv",
      "         dBbcccv",
      "     IJ  dBbcccv",
      "  K  IC  dBbcccv",
      "         dBbcccv",
      "         nnbcccv",
      "         Lnbcccv"
    ],
    [
      "          Mbcccv",
      "           bcccv",
      "          Fbcccv",
      "          Mbcccv",
      "         nnbcccv",
      "           bcccv",
      "          Nbcccv",
      "           bcccv",
      "          Obcccv",
      "           bcccv",
      "          Nbcccv",
      "           bcccv",
      "           bcccv",
      "          Nbcccv",
      "         nnbcccv",
      "         Pnbcccv"
    ],
    [
      "           bcccv",
      "           bcccv",
      "           bcccv",
      "           bcccv",
      "         nnbcccv",
      "           bcccv",
      "           bcccv",
      "           bcccv",
      "           bcccv",
      "           bcccv",
      "           bcccv",
      "           bcccv",
      "           bcccv",
      "           bcccv",
      "         nnbcccv",
      "          nbcccv"
    ],
    [
      "         nQbcccv",
      "         nRbcccv",
      "         nQbcccv",
      "         nRbcccv",
      "         nnbcccv",
      "         nQbcccv",
      "         nRbcccv",
      "         nQbcccv",
      "         nRbcccv",
      "         nQbcccv",
      "         nRbcccv",
      "         nQbcccv",
      "         nRbcccv",
      "         nQbcccv",
      "         nnbcccv",
      "          nbcccv"
    ]
  ]
}