{
  "name": "multi_terraceplaza_33_base1",
  "refpalette": "deceasedcraft:multi_terraceplaza_33/multi_terraceplaza_33_base1_palette",
  "xsize": 16,
  "zsize": 16,
  "slices": [
    [
      "        abcdeeev",
      "        fbcdeeev",
      "         bcdeeev",
      "        gbcdeeev",
      "        abbdeeev",
      "        hbcdeeev",
      "        abcdeeev",
      "        ibcdeeev",
      "        abcdeeev",
      "        jbcdeeev",
      "        abcdeeev",
      "        fbcdeeev",
      "         bcdeeev",
      "        ibcdeeev",
      "         bbdeeev",
      "          bdeeev"
    ],
    [
      "        ab deeev",
      "        kb deeev",
      "        abldeeev",
      "        mbldeeev",
      "        abbdeeev",
      "        hbldeeev",
      "        ab deeev",
      "        gbldeeev",
      "        ab deeev",
      "         b deeev",
      "        abldeeev",
      "        kb deeev",
      "         bldeeev",
      "        nbldeeev",
      "         bldeeev",
      "          bdeeev"
    ],
    [
      "         b deeev",
      "         b deeev",
      "         b deeev",
      "         b deeev",
      "         bbdeeev",
      "         bldeeev",
      "         bldeeev",
      "         b deeev",
      "         b deeev",
      "         b deeev",
      "         b deeev",
      "         b deeev",
      "         b deeev",
      "         b deeev",
      "         bldeeev",
      "          bdeeev"
    ],
    [
      " oopqqqqqb deeev",
      " oopqqqqqbrdeeev",
      " oopqqqqqbldeeev",
      " oopqqqqqb deeev",
      " oopqssqqbbdeeev",
      " oopqqsssbldeeev",
      " oopqqqqqbldeeev",
      " oopqqqqqbrdeeev",
      " oopqqqqqbldeeev",
      " oopqqqqqb deeev",
      " oopqqqqqbldeeev",
      " oopqqqqqb deeev",
      " oopqqqqqbrdeeev",
      " oopqqqqqb deeev",
      "ppppqqqqqb deeev",
      "          tdeeev"
    ],
    [
      "uuwpxxxxxxydeeev",
      "uuwpxAAAxxydeeev",
      "uuwpxxxxxxydeeev",
      "uuwpxxxxxxydeeev",
      "uuwpxxxxxxydeeev",
      "uuwpxxxxxxydeeev",
      "uuwpxxxxxxydeeev",
      "uuwpxAAAxxydeeev",
      "uuwpxxxxxxydeeev",
      "uuwpxxxxxxydeeev",
      "uuwpxxxxxxydeeev",
      "uuwpxxxxxxydeeev",
      "uuwpxAAAxxydeeev",
      "uuwpxxxxxxydeeev",
      "ppppxxxxxxydeeev",
      "xxxxxxxxxxBdeeev"
    ],
    [
      "CCDpEFeeeeedeeev",
      "CCDpEFeeeeedeeev",
      "CCDpEFeeeeedeeev",
      "CCDpEFeeeeedeeev",
      "EEEEIJeeeeedeeev",
      "CCDpEFeeeeedeeev",
      "CCDpEFeeeeedeeev",
      "CCDpEFeeeeedeeev",
      "CCDpEFeeeeedeeev",
      "CCDpEFeeeeedeeev",
      "CCDpEFeeeeedeeev",
      "CCDpEFeeeeedeeev",
      "CCDpEFeeeeedeeev",
      "CCDpEFeeeeedeeev",
      "ppppEFeeeeedeeev",
      "EEEEIJeeeeedeeev"
    ]
  ]
}