{
  "name": "multi_terraceplaza_33_floor1",
  "refpalette": "deceasedcraft:multi_terraceplaza_33/multi_terraceplaza_33_floor1_palette",
  "xsize": 16,
  "zsize": 16,
  "slices": [
    [
      " a  bc  de      ",
      "    bc  fe      ",
      "    bc  de      ",
      "    bc  fe      ",
      "    gc  de      ",
      "        de      ",
      "        fe      ",
      " a      fe      ",
      "        de      ",
      "        fe      ",
      "        de      ",
      "    hijjde      ",
      "kkkkkljjfe      ",
      "mmmmmnjjde      ",
      "nnnnnn  de      ",
      "nnnnnn  de      "
    ],
    [
      "oooopqr de      ",
      "oooopqr fe      ",
      "oooopqr de      ",
      "oooopqr fe      ",
      "ppppgsr de      ",
      "     t  de      ",
      "        fe      ",
      " u      fe      ",
      "    hijjde      ",
      "kkkkkljjfe      ",
      "mmmmmnjjde      ",
      "wwwwxn  de      ",
      "yyyyyn  fe      ",
      "     A  de      ",
      "BBBBBB  de      ",
      "                "
    ],
    [
      "qqqqCD  de      ",
      "q!qqCD  fe      ",
      "qqqqCD  de      ",
      "qqqqCD  fe      ",
      "    gE  de      ",
      "hhhhhijjde      ",
      "kkkkkljjfe      ",
      "mmmmmnjjfe      ",
      "wwwwxn  de      ",
      "yyyyyn  fe      ",
      "     A  de      ",
      "     B  de      ",
      "                ",
      "                ",
      "                ",
      "                "
    ],
    [
      "        de      ",
      "F IF D  fe      ",
      "    hijjde      ",
      "hhhhkljjfe      ",
      "JJJJgnjjde      ",
      "nnnnnn  de      ",
      "yyyyyn  fe      ",
      "     A  fe      ",
      "     B  de      ",
      "                ",
      "                ",
      "                ",
      "                ",
      "                ",
      "                ",
      "                "
    ],
    [
      "    kljjde      ",
      "hhhhmnjjfe      ",
      "xxxxxn  de      ",
      "nnnnnn  fe      ",
      "AAAAAA  de      ",
      "BBBBBB  de      ",
      "                ",
      "                ",
      "                ",
      "                ",
      "                ",
      "                ",
      "                ",
      "                ",
      "                ",
      "                "
    ],
    [
      "KKKLyn  de      ",
      "     A  fe      ",
      "     B  de      ",
      "                ",
      "                ",
      "                ",
      "                ",
      "                ",
      "                ",
      "                ",
      "                ",
      "                ",
      "                ",
      "                ",
      "                ",
      "                "
    ]
  ]
}