{
  "name": "multi_terraceplaza_4_floor2",
  "refpalette": "deceasedcraft:multi_terraceplaza_4/multi_terraceplaza_4_floor2_palette",
  "xsize": 16,
  "zsize": 16,
  "slices": [
    [
      "      ab        ",
      "      ab        ",
      "      ac        ",
      "      ab        ",
      "      ac        ",
      "      ab        ",
      "      ab        ",
      "      ac        ",
      "      ac        ",
      "      abddefgggg",
      "      acddhijjjj",
      "      abddkljjjj",
      "      ab  kmmmmm",
      "      ac  kn    ",
      "      ab  o     ",
      "      ab  p     "
    ],
    [
      "      ab        ",
      "      ab        ",
      "      ac        ",
      "      ab        ",
      "      ac        ",
      "      ab        ",
      "      abddejjjjj",
      "      acddhiiiii",
      "      acddklllll",
      "      ab  kkkkkk",
      "      ac  kkkkkk",
      "      ab  o     ",
      "      ab  p     ",
      "                ",
      "                ",
      "                "
    ],
    [
      "      ab        ",
      "      ab        ",
      "      ac        ",
      "      abddejjjjj",
      "      acddhiiiii",
      "      abddklqqqq",
      "      ab  kmmmmm",
      "      ac  knnnnn",
      "      ac  oooooo",
      "      ab  pppppp",
      "                ",
      "                ",
      "                ",
      "                ",
      "                ",
      "                "
    ],
    [
      "      abddejjjjj",
      "      abddhiiiii",
      "      acddklqqqq",
      "      ab  kmmmmm",
      "      ac  knnnnn",
      "      ab  o     ",
      "      ab  p     ",
      "                ",
      "                ",
      "                ",
      "                ",
      "                ",
      "                ",
      "                ",
      "                ",
      "                "
    ],
    [
      "      ab  kmmmmm",
      "      ab  knnnnn",
      "      ac  o     ",
      "      ab  p     ",
      "                ",
      "                ",
      "                ",
      "                ",
      "                ",
      "                ",
      "                ",
      "                ",
      "                ",
      "                ",
      "                ",
      "                "
    ],
    [
      "      ab  p     ",
      "                ",
      "                ",
      "                ",
      "                ",
      "                ",
      "                ",
      "                ",
      "                ",
      "                ",
      "                ",
      "                ",
      "                ",
      "                ",
      "                ",
      "                "
    ]
  ]
}