{
  "name": "multi_terraceplaza_4_base2",
  "refpalette": "deceasedcraft:multi_terraceplaza_4/multi_terraceplaza_4_base2_palette",
  "xsize": 16,
  "zsize": 16,
  "slices": [
    [
      "vabbabbabbbbcccc",
      "vabbabbabbbbcccc",
      "vabbabbabbbbcccc",
      "vabbabbabbbbcccc",
      "vabbabbabbbbcccc",
      "vabbbbbbbbbbcccc",
      "vabbbbbbbbbbcccc",
      "vabbabbabbbbcccc",
      "vabbabbabbbbcccc",
      "vabbaaaaaaaacccc",
      "vabbabbabbbbcccc",
      "vabbabbabbbbcccc",
      "vabbabbabbbbcccc",
      "vabbabbabbbbcccc",
      "vabbbbbbbbbbcccc",
      "vabbbbbbbbbbcccc"
    ],
    [
      "va  a  ade fg   ",
      "va ha  ade fg i ",
      "va  a  aj  fg i ",
      "va  a  a   fg i ",
      "va  a  a   fg i ",
      "va  k  l   fg i ",
      "va  m  n   og i ",
      "va  a  ap   g i ",
      "va  a  ap   q   ",
      "va  aaaaaaaarr  ",
      "va hastau  fg   ",
      "va  assau  fg i ",
      "va  as a!  fg i ",
      "va  aw a   fg i ",
      "va  k  l   fg i ",
      "va  m  n   fg i "
    ],
    [
      "va  a  a   xy   ",
      "va  a  a   Ay   ",
      "va  a  a   By   ",
      "va  a  a   Cy   ",
      "va  a  a   Dy   ",
      "va  E  F   Iy   ",
      "va  J  K        ",
      "va  a  aL   M   ",
      "va  a  aL       ",
      "va  aaaaaaaarr  ",
      "va  aNta   Oy   ",
      "va  aN aP  Qy   ",
      "va  aw a   Ry   ",
      "va  a  a   Sy   ",
      "va  E  F   Ty   ",
      "va  J  K   Uy   "
    ],
    [
      "va  a  a        ",
      "va  a  a        ",
      "va  a  a        ",
      "va  a  a        ",
      "va  a  a        ",
      "va  V  W        ",
      "va  V  W        ",
      "va  a  a        ",
      "va  a  a        ",
      "va  aaaaaaaarr  ",
      "va  a ta        ",
      "va  a  a        ",
      "va  a  a        ",
      "va  a  a        ",
      "va  V  W        ",
      "va  V  W        "
    ],
    [
      "va  a  aX       ",
      "va  a  aX       ",
      "va  a  a        ",
      "va  a  a        ",
      "va  a  a        ",
      "va  a  a        ",
      "va  a  a        ",
      "va  a  a        ",
      "va  a  a        ",
      "va  aaaaaaaarr  ",
      "va  a  aX       ",
      "va  a  aX       ",
      "va  a  a        ",
      "va  a  a        ",
      "va  a  a        ",
      "va  a  a        "
    ],
    [
      "va  aYYaZ  01r  ",
      "va  aYYa   02r  ",
      "va  aYYa   01r  ",
      "va  aYYa   02r  ",
      "va  aYYa   01r  ",
      "va  aYYa   02r  ",
      "va  aYYa   01r  ",
      "va  aYYa   02r  ",
      "va  aYYa   01r  ",
      "va  aaaaaaaarr  ",
      "va  aYYaZ  01r  ",
      "va  aYYa   02r  ",
      "va  aYYa   01r  ",
      "va  aYYa   02r  ",
      "va  aYYa   01r  ",
      "va  aYYa   02r  "
    ]
  ]
}