{
  "name": "multi_terraceplaza_4_ground",
  "refpalette": "deceasedcraft:multi_terraceplaza_4/multi_terraceplaza_4_ground_palette",
  "xsize": 16,
  "zsize": 16,
  "slices": [
    [
      "HHHabcdeffghiiii",
      "HHHajcdeffghiiii",
      "HHHajcdeffghiiii",
      "HHHajcdeffghiiii",
      "HHHajcdeffghiiii",
      "HHHajcdeffghiiii",
      "HHHajcdeffghiiii",
      "HHHabcdeffghiiii",
      "HHHajcdeffghiiii",
      "HHHajcdefklmnnnn",
      "HHHajcdeffghiii!",
      "HHHabcdeffghiiii",
      "HHHajcdeffghiiii",
      "HHHajcdeffghiiii",
      "HHHajcdeffghiiii",
      "HHHajcdeffghiiii"
    ],
    [
      "    op q  g rs  ",
      "    tp q  g ru  ",
      "    tp q  g rs  ",
      "    tp q  g r   ",
      "    tp q  g rsw ",
      "    tp q  g nxn ",
      "    tp q  g nyAn",
      "    op q  g n!yn",
      "    Bp q  g nAAn",
      "    BC D   mnnnn",
      "    Bp q  g EFIJ",
      "    op q  g E   ",
      "    tp q  g K   ",
      "    tp q  g E   ",
      "    tp q  gLMNOO",
      "    tp q  gL  PP"
    ],
    [
      "    QpRS    rs  ",
      "     pRS  g rs  ",
      "     pRT    r   ",
      "     pRS  g rs  ",
      "     pRT  g r   ",
      "     pRS  g nUn ",
      "     pRS    q  n",
      "    QpRT  g q  n",
      "      RT    nVAn",
      "     WRS   mnnnn",
      "      RT  g  X  ",
      "    QpRS        ",
      "     pRS        ",
      "     pRT  g Y   ",
      "     pRS  g Z012",
      "     pRS        "
    ],
    [
      "      RS    rs  ",
      "      RS    r   ",
      "      RT    r   ",
      "      RS    rs  ",
      "      RT    r   ",
      "      RS    n3n ",
      "      RS    n  n",
      "      RT    n  n",
      "      RT    n yn",
      "     tRS   mnnnn",
      "      RT    45  ",
      "      RS    4   ",
      "      RS    4   ",
      "      RT    4   ",
      "      RS    4466",
      "      RS        "
    ],
    [
      "      RS    r   ",
      "      RS    r   ",
      "      RT    r   ",
      "      RS    rs  ",
      "      RT    rs  ",
      "      RS    nnn ",
      "      RS    n  n",
      "      RT    n  n",
      "      RT    n  n",
      "     tRS   mnnnn",
      "      RT    7   ",
      "      RS    8   ",
      "      RS    9   ",
      "      RT    9   ",
      "      RS     #$ ",
      "      RS        "
    ],
    [
      "      RS   %r   ",
      "      RS   %r   ",
      "      RT   %r   ",
      "      RS   %r   ",
      "      RT   %rs  ",
      "      RS   %nnn ",
      "      RS   %   n",
      "      RT   %   n",
      "      RT   %   n",
      "      RS   mnnnn",
      "      RT   %    ",
      "      RS   %    ",
      "      RS   %  ^ ",
      "      RT   %    ",
      "      RS   % &  ",
      "      RS   %    "
    ]
  ]
}