{
  "name": "multi_terraceplaza_4_floor1",
  "refpalette": "deceasedcraft:multi_terraceplaza_4/multi_terraceplaza_4_floor1_palette",
  "xsize": 16,
  "zsize": 16,
  "slices": [
    [
      "      ab  cde   ",
      "      ab  cde   ",
      "      af  cde   ",
      "      ab  cdeg  ",
      "      af  cdeg  ",
      "      ab  cdhhh ",
      "      ab  cd   h",
      "      af  cd   h",
      "      af  cd   h",
      "      ab  cihhhh",
      "      af  cd    ",
      "      ab  cd    ",
      "      ab  cd  j ",
      "      af  cd    ",
      "      ab  cd k  ",
      "      ab  cd    "
    ],
    [
      "      ab lmnoooo",
      "      ab lmnoopo",
      "      af lmnoooo",
      "      ab lmnoooo",
      "      af lmnoooo",
      "      ab lmnoooo",
      "      ab lmnoooo",
      "      af lmnoooo",
      "      af lmnoooo",
      "      abqqrinnnn",
      "      af lmnoooo",
      "      ab lmnoooo",
      "      ab lmnoooo",
      "      af lmnoooo",
      "      ab lmnoooo",
      "      ab lmnoooo"
    ],
    [
      "      ab  stuuuu",
      "      ab  stuuuu",
      "      af  stuuuu",
      "      ab  stuuuu",
      "      af  stuuuu",
      "      ab  stuuuu",
      "      ab  stuuuu",
      "      af  stuuuu",
      "      af  stuuuu",
      "      ab  wixxxx",
      "      af  stmyym",
      "      ab  stmmyy",
      "      ab  stmmym",
      "      af  stymmm",
      "      ab  stmymm",
      "      ab  stmmmm"
    ],
    [
      "      ab  s     ",
      "      ab  s o   ",
      "      af  s A   ",
      "      ab  s A   ",
      "      af  s A   ",
      "      ab  s A   ",
      "      ab  s o   ",
      "      af  s     ",
      "      af  s     ",
      "      ab   iB C ",
      "      af  s     ",
      "      ab  s  D  ",
      "      ab  s  E  ",
      "      af  s  F  ",
      "      ab  s     ",
      "      ab  s     "
    ],
    [
      "      ab        ",
      "      ab    I   ",
      "      af  s J   ",
      "      ab  s I   ",
      "      af    K   ",
      "      ab  s J   ",
      "      ab  s I   ",
      "      af        ",
      "      af  s     ",
      "      ab   i    ",
      "      af        ",
      "      ab  s     ",
      "      ab        ",
      "      af  s     ",
      "      ab  s     ",
      "      abLLMN    "
    ],
    [
      "      ab        ",
      "      ab        ",
      "      af        ",
      "      ab        ",
      "      af        ",
      "      ab        ",
      "      ab        ",
      "      af        ",
      "      af        ",
      "      ab   i    ",
      "      af        ",
      "      ab        ",
      "      abLLMN    ",
      "      afLLOPQRRR",
      "      abLLSuQRRR",
      "      ab  STQRRR"
    ]
  ]
}