{
  "name": "multi_terraceplaza_4_base1",
  "refpalette": "deceasedcraft:multi_terraceplaza_4/multi_terraceplaza_4_base1_palette",
  "xsize": 16,
  "zsize": 16,
  "slices": [
    [
      "va  a  bc  def  ",
      "va  a  b   def  ",
      "va  a  b   def  ",
      "va  a  b   def  ",
      "va  a  b   def  ",
      "va  a gb   def  ",
      "va  ag b   defh ",
      "va  a!ib   def  ",
      "va  aiib   defj ",
      "va  abbb   dffk ",
      "va  aggbc  defl ",
      "va  ag b   defk ",
      "va  a  b   defl ",
      "va  a  b   defk ",
      "va  a  b   defm ",
      "va  a  b   defk "
    ],
    [
      "va  a   c  d f  ",
      "va  a      d f  ",
      "va  a      d f  ",
      "va  a      d f  ",
      "va  a      d f  ",
      "va  a      d f  ",
      "va  a      d fn ",
      "va  ag     d fk ",
      "va  ag     d fo ",
      "va  a      dffk ",
      "va  a   c  d fk ",
      "va  a      d fk ",
      "va  a      d fo ",
      "va  a      d fk ",
      "va  a      d fp ",
      "va  a      d fk "
    ],
    [
      "va  a   c  d f  ",
      "va  a      dqf  ",
      "va  a      d f  ",
      "va  a      d f  ",
      "va  a      d f  ",
      "va  a      d f  ",
      "va  a      d f  ",
      "va  a      dqf  ",
      "va  a      d f  ",
      "va  a      dff  ",
      "va  a   c  d f  ",
      "va  a      dqf  ",
      "va  a      d f  ",
      "va  a      d f  ",
      "va  a      d f  ",
      "va  a      d f  "
    ],
    [
      "va  acccc   cfr ",
      "va  ac      cfr ",
      "va  ac      cfr ",
      "va  ac      cfr ",
      "va  ac      cfr ",
      "va  ac      cfr ",
      "va  ac      cfr ",
      "va  ac      cfr ",
      "va  ac      cfr ",
      "va  ac  cccccfr ",
      "va  acccc   cfr ",
      "va  ac      cfr ",
      "va  ac      cfr ",
      "va  ac      cfr ",
      "va  ac      cfr ",
      "va  ac      cfr "
    ],
    [
      "va  assssssstuww",
      "va  assssssstuww",
      "va  assssssstuww",
      "va  assssssstuww",
      "va  assssssstuww",
      "va  assssssstuww",
      "va  assssssstuww",
      "va  assssssstuww",
      "va  assssssstuww",
      "va  assssssstuww",
      "va  assssssstuww",
      "va  assssssstuww",
      "va  assssssstuww",
      "va  assssssstuww",
      "va  assssssstuww",
      "va gassssssstuww"
    ],
    [
      "vassaxxxxxyABCBB",
      "vassaxxxxxyABCBB",
      "vassaxxxxxyABCBB",
      "vassaxxxxxyABCBB",
      "vassaxxxxxyABCBB",
      "vassaxxxxxyABCBB",
      "vassaxxxxxyABCBB",
      "vassaxxxxxyABCBB",
      "vassaxxxxxyABCBB",
      "vassaxxxxxDEAAAA",
      "vassaxxxxxyABCBB",
      "vassaxxxxxyABCBB",
      "vassaxxxxxyABCBB",
      "vassaxxxxxyABCBB",
      "vassaxxxxxyABCBB",
      "vassaxxxxxyABCBB"
    ]
  ]
}