{
  "name": "multi_nuclearpowerplant_12_base6",
  "refpalette": "deceasedcraft:multi_nuclearpowerplant_12/multi_nuclearpowerplant_12_base6_palette",
  "xsize": 16,
  "zsize": 16,
  "slices": [
    [
      "   abbbbbbbbbbbb",
      "   abbbbbbbbbbbb",
      "   abbbbbbbbbbbb",
      "   aabbbbbbbbbbb",
      "    abbbbbbbbbbb",
      "    abbbbbbbbbbb",
      "    aabbbbbbbbbb",
      "     abbbbbbbbbb",
      "c    abbbbbbbbbb",
      "dc   aabbbbbbbbb",
      "aec   abbbbbbbbb",
      "vadc  aabbbbbbbb",
      "vvaec  abbbbbbbb",
      "vvvadc aabbbbbbb",
      "vvvvaec abbbbbbb",
      "vvvvvadcaabbbbbb"
    ],
    [
      "   fg           ",
      "   fh           ",
      "   fi           ",
      "   ff           ",
      "    f           ",
      "    f           ",
      "    ff          ",
      "     f          ",
      "     f          ",
      "     ff         ",
      "j     f         ",
      "kj    ff        ",
      "kkj    f        ",
      "kkkj   ff       ",
      "kkkkj   f       ",
      "kkkkkj  ff      "
    ],
    [
      "                ",
      "                ",
      "                ",
      "                ",
      "                ",
      "                ",
      "                ",
      "                ",
      "                ",
      "                ",
      "j               ",
      "ej              ",
      "eej             ",
      "eeej            ",
      "eeeej           ",
      "eeeeej          "
    ],
    [
      "                ",
      "                ",
      "                ",
      "                ",
      "                ",
      "                ",
      "                ",
      "                ",
      "                ",
      "                ",
      "j               ",
      "ej              ",
      "eej             ",
      "eeej            ",
      "eeeej           ",
      "eeeeej          "
    ],
    [
      "                ",
      "                ",
      "                ",
      "                ",
      "                ",
      "                ",
      "                ",
      "                ",
      "                ",
      "                ",
      "j               ",
      "ej              ",
      "eej             ",
      "eeej            ",
      "eeeej           ",
      "eeeeej          "
    ],
    [
      "                ",
      "                ",
      "                ",
      "                ",
      "                ",
      "                ",
      "                ",
      "                ",
      "                ",
      "                ",
      "j               ",
      "ej              ",
      "eej             ",
      "eeej            ",
      "eeeej           ",
      "eeeeej          "
    ]
  ]
}