{
  "name": "multi_nuclearpowerplant_12_base2",
  "refpalette": "deceasedcraft:multi_nuclearpowerplant_12/multi_nuclearpowerplant_12_base2_palette",
  "xsize": 16,
  "zsize": 16,
  "slices": [
    [
      "                ",
      "                ",
      "                ",
      "                ",
      "                ",
      "                ",
      "                ",
      "                ",
      "                ",
      "                ",
      "a               ",
      " a              ",
      "  a             ",
      "   a            ",
      "    a           ",
      "     a          "
    ],
    [
      "                ",
      "                ",
      "                ",
      "                ",
      "                ",
      "                ",
      "                ",
      "                ",
      "                ",
      "                ",
      "a               ",
      " a              ",
      "  a             ",
      "   a            ",
      "    a           ",
      "     a          "
    ],
    [
      "                ",
      "                ",
      "                ",
      "                ",
      "                ",
      "                ",
      "                ",
      "                ",
      "                ",
      "                ",
      "a               ",
      " a              ",
      "  a             ",
      "   a            ",
      "    a           ",
      "     a          "
    ],
    [
      "                ",
      "                ",
      "                ",
      "                ",
      "                ",
      "                ",
      "                ",
      "                ",
      "                ",
      "                ",
      "a               ",
      " a              ",
      "  a             ",
      "   a            ",
      "    a           ",
      "     a          "
    ],
    [
      "                ",
      "                ",
      "                ",
      "                ",
      "                ",
      "                ",
      "                ",
      "                ",
      "                ",
      "                ",
      "a               ",
      " a              ",
      "  a             ",
      "   a            ",
      "    a           ",
      "     a          "
    ],
    [
      "bbbbbb          ",
      "bbbbbbb         ",
      "bbbbbbbb        ",
      "bbbbbbbbb       ",
      "bbbbbbbbb       ",
      "bbbbbbbbbb      ",
      "bbbbbbbbbbb     ",
      "bbbbbbbbbbbb    ",
      "bbbbbbbbbbbbbb  ",
      "bbbbbbbbbbbbbbb ",
      "abbbbbbbbbbbbbbb",
      " abbbbbbbbbbbbbb",
      "  abbbbbbbbbbbbb",
      "   abbbbbbbbbbbb",
      "    abbbbbbbbbbb",
      "     abbbbbbbbbb"
    ]
  ]
}