{
  "name": "multi_nuclearpowerplant_12_base7",
  "refpalette": "deceasedcraft:multi_nuclearpowerplant_12/multi_nuclearpowerplant_12_base7_palette",
  "xsize": 16,
  "zsize": 16,
  "slices": [
    [
      "aaab            ",
      "aaab            ",
      "aaab            ",
      "aaab            ",
      "aaaab           ",
      "aaaab           ",
      "aaaab           ",
      "aaaaab          ",
      "aaaaab          ",
      "aaaaab          ",
      "baaaaab         ",
      "cbaaaab         ",
      "ccbaaaab        ",
      "cccbaaab        ",
      "ccccbaaab       ",
      "cccccbaab       "
    ],
    [
      "aaab            ",
      "aaab            ",
      "aaab            ",
      "aaab            ",
      "aaaab           ",
      "aaaab           ",
      "aaaab           ",
      "aaaaab          ",
      "aaaaab          ",
      "aaaaab          ",
      "baaaaab         ",
      "cbaaaab         ",
      "ccbaaaab        ",
      "cccbaaab        ",
      "ccccbaaab       ",
      "cccccbaab       "
    ],
    [
      "aaab            ",
      "aaab            ",
      "aaab            ",
      "aaab            ",
      "aaaab           ",
      "aaaab           ",
      "aaaab           ",
      "aaaaab          ",
      "aaaaab          ",
      "aaaaab          ",
      "baaaaab         ",
      "cbaaaab         ",
      "ccbaaaab        ",
      "cccbaaab        ",
      "ccccbaaab       ",
      "cccccbaab       "
    ],
    [
      "aaab            ",
      "aaab            ",
      "aaab            ",
      "aaab            ",
      "aaaab           ",
      "aaaab           ",
      "aaaab           ",
      "aaaaab          ",
      "aaaaab          ",
      "aaaaab          ",
      "baaaaab         ",
      "cbaaaab         ",
      "ccbaaaab        ",
      "cccbaaab        ",
      "ccccbaaab       ",
      "cccccbaab       "
    ],
    [
      "aaab            ",
      "aaab            ",
      "aaab            ",
      "aaab            ",
      "aaaab           ",
      "aaaab           ",
      "aaaab           ",
      "aaaaab          ",
      "aaaaab          ",
      "aaaaab          ",
      "baaaaab         ",
      "cbaaaab         ",
      "ccbaaaab        ",
      "cccbaaab        ",
      "ccccbaaab       ",
      "cccccbaab       "
    ],
    [
      "aaabdddddddddddd",
      "aaabdddddddddddd",
      "aaabdddddddddddd",
      "aaabdddddddddddd",
      "aaaabddddddddddd",
      "aaaabddddddddddd",
      "aaaabddddddddddd",
      "aaaaabdddddddddd",
      "aaaaabdddddddddd",
      "aaaaabdddddddddd",
      "baaaaabddddddddd",
      "ebaaaabddddddddd",
      "eebaaaabdddddddd",
      "eeebaaabdddddddd",
      "eeeebaaabddddddd",
      "eeeeebaabddddddd"
    ]
  ]
}