{
  "name": "multi_nuclearpowerplant_12_ground",
  "refpalette": "deceasedcraft:multi_nuclearpowerplant_12/multi_nuclearpowerplant_12_ground_palette",
  "xsize": 16,
  "zsize": 16,
  "slices": [
    [
      "                ",
      "                ",
      "                ",
      "                ",
      "                ",
      "a               ",
      "aa              ",
      "aaa             ",
      "baaa            ",
      "bbaaa           ",
      "cbbaaa          ",
      "ccbbaaa         ",
      "cccbbaaa        ",
      "ccccbbaaa       ",
      "cccccbbaaaa     ",
      "ccccccbbaaaa    "
    ],
    [
      "                ",
      "                ",
      "a               ",
      "aa              ",
      "aa              ",
      "aaa             ",
      "aaaa            ",
      "zaaaa           ",
      "zzaaaa          ",
      "zzzaaaa         ",
      "dzzzaaaa        ",
      " dzzcaaaaa      ",
      "  ezzcaaaaaa    ",
      "   ezzzaaaaaaa  ",
      "    dzzzaaaaaaaa",
      "     ezzzaaaaaaa"
    ],
    [
      "a               ",
      "aa              ",
      "aaa             ",
      "aaaa            ",
      "zaaaa           ",
      "zaaaaa          ",
      "zzaaaaa         ",
      " zzaaaaa        ",
      "f zcaaaaaa      ",
      "ff zzaaaaaaa    ",
      " ff zzaaaaaaaaa ",
      "  ff zzaaaaaaaaa",
      "   ff zzzaaaaaaa",
      "    ff zzzzaaaaa",
      "     ff zzzzzaaa",
      "      ff czzzzzc"
    ],
    [
      "aaaa            ",
      "aaaaa           ",
      "zaaaaaa         ",
      "zzaaaaaa        ",
      " zzaaaaaa       ",
      " zzzaaaaaaa     ",
      "ghzzzaaaaaaaa   ",
      "   zzzaaaaaaaaa ",
      "f   zzzaaaaaaaaa",
      "ff  izczzaaaaaaa",
      " ff  czzzzzaaaaa",
      "  ff   zzzczzzaa",
      "   ff    zzzzzzz",
      "    ff  hgzzzzzz",
      "     ff      zzz",
      "      ff    i z "
    ],
    [
      "zzaaaaaa        ",
      "zzzaaaaaaa      ",
      " zzcaaaaaaaa    ",
      " gzzzzaaaaaaaa  ",
      " igzzzzaaaaaaaaa",
      "  g zzzzaaaaaaaa",
      "     zzzzzaaaaaa",
      "    h zzzzzzaaaa",
      "       zzzzzzzaa",
      "j       gczzzzzz",
      " j     ggg zzzzz",
      "  j         zhzz",
      "   k     h      ",
      "    l     gg i  ",
      "     l          ",
      "      l         "
    ],
    [
      "hzzzzaaaaaaaaa  ",
      " zgzzzzaaaaaaaaa",
      " g  zzzzzaaaaaaa",
      "     zzzzzzaaaaa",
      "   g ggzzzzzzaaa",
      "     g  zzzzzzzz",
      "       zzgzzzzzz",
      "      i    zzzzz",
      "       g g    zz",
      "            iggg",
      "            g   ",
      "              gg",
      "                ",
      "                ",
      "                ",
      "                "
    ]
  ]
}