{
  "name": "multi_nuclearpowerplant_12_base1",
  "refpalette": "deceasedcraft:multi_nuclearpowerplant_12/multi_nuclearpowerplant_12_base1_palette",
  "xsize": 16,
  "zsize": 16,
  "slices": [
    [
      "aaaaaabb        ",
      "aaaaaaabb       ",
      "aaaaaaaabb      ",
      "aaaaaaaaab      ",
      "aaaaaaaaabb     ",
      "aaaaaaaaaabb    ",
      "aaaaaaaaaaabb   ",
      "aaaaaaaaaaaabbb ",
      "aaaaaaaaaaaaaabb",
      "zaaaaaaaaaaaaaab",
      "czaaaaaaaaaaaaaa",
      "dczaaaaaaaaaaaaa",
      "ddczaaaaaaaaaaaa",
      "dddczaaaaaaaaaaa",
      "ddddczaaaaaaaaaa",
      "dddddczaaaaaaaaa"
    ],
    [
      "      ee        ",
      "       ee       ",
      "        ee      ",
      "         e      ",
      "         ee     ",
      "          ee    ",
      "           ee   ",
      "            eee ",
      "              ee",
      "f              e",
      "gf              ",
      "hgf             ",
      "hhgf            ",
      "hhhgf           ",
      "hhhhgf          ",
      "hhhhhgf         "
    ],
    [
      "                ",
      "                ",
      "                ",
      "                ",
      "                ",
      "                ",
      "                ",
      "                ",
      "                ",
      "                ",
      "g               ",
      "hg              ",
      "hhg             ",
      "hhhg            ",
      "hhhhg           ",
      "hhhhhg          "
    ],
    [
      "                ",
      "                ",
      "                ",
      "                ",
      "                ",
      "                ",
      "                ",
      "                ",
      "                ",
      "                ",
      "g               ",
      "hg              ",
      "hhg             ",
      "hhhg            ",
      "hhhhg           ",
      "hhhhhg          "
    ],
    [
      "                ",
      "                ",
      "                ",
      "                ",
      "                ",
      "                ",
      "                ",
      "                ",
      "                ",
      "                ",
      "g               ",
      "hg              ",
      "hhgi            ",
      "hhhg            ",
      "hhhhg           ",
      "hhhhhg          "
    ],
    [
      "                ",
      "                ",
      "                ",
      "                ",
      "                ",
      "                ",
      "                ",
      "                ",
      "b               ",
      "bb              ",
      "gbb             ",
      "hgbb            ",
      "hhgbb           ",
      "hhhgbb          ",
      "hhhhgbb         ",
      "hhhhhgbb        "
    ]
  ]
}