{
  "name": "multi_nuclearpowerplant_12_base11",
  "refpalette": "deceasedcraft:multi_nuclearpowerplant_12/multi_nuclearpowerplant_12_base11_palette",
  "xsize": 16,
  "zsize": 16,
  "slices": [
    [
      "                ",
      "                ",
      "                ",
      "                ",
      "                ",
      "                ",
      "           a    ",
      "         bbcd bb",
      "       eebfgdhbf",
      "iiiiiiiiiijkiiil",
      "mmmmmmmmmmnnmmmn",
      "oooooooooooooooo",
      "oooooooooooooooo",
      "oooooooooooooooo",
      "oooooooooooooooo",
      "oooooooooooooooo"
    ],
    [
      "                ",
      "                ",
      "                ",
      "                ",
      "                ",
      "                ",
      "                ",
      "         bppd bp",
      "       eebqpd br",
      "iiiiiiiiiissiiit",
      "mmmmmmmmmmnnmmmn",
      "oooooooooooooooo",
      "oooooooooooooooo",
      "oooooooooooooooo",
      "oooooooooooooooo",
      "oooooooooooooooo"
    ],
    [
      "                ",
      "                ",
      "                ",
      "                ",
      "                ",
      "                ",
      "                ",
      "                ",
      "       ee u    u",
      "iiiiiiiiiiiiiiii",
      "mmmmmmmmmmmmmmmm",
      "oooooooooooooooo",
      "oooooooooooooooo",
      "oooooooooooooooo",
      "oooooooooooooooo",
      "oooooooooooooooo"
    ],
    [
      "                ",
      "                ",
      "                ",
      "                ",
      "                ",
      "                ",
      "                ",
      "                ",
      "       ee w    w",
      "iiiiiiiiiiiiiiii",
      "mmmmmmmmmmmmmmmm",
      "oooooooooooooooo",
      "oooooooooooooooo",
      "oooooooooooooooo",
      "oooooooooooooooo",
      "oooooooooooooooo"
    ],
    [
      "      xyyyyyyyyy",
      "       AAAAAAAAA",
      "                ",
      "                ",
      "                ",
      "                ",
      "                ",
      "                ",
      "       ee w    w",
      "iiiiiiiiiiiiiiii",
      "mmmmmmmmmmmmmmmm",
      "oooooooooooooooo",
      "oooooooooooooooo",
      "oooooooooooooooo",
      "oooooooooooooooo",
      "oooooooooooooooo"
    ],
    [
      "      B         ",
      "       CCCCCCCCC",
      "                ",
      "                ",
      "                ",
      "                ",
      "                ",
      "                ",
      "       ee w    w",
      "iiiiiiiiiiiiiiii",
      "mmmmmmmmmmmmmmmm",
      "oooooooooooooooo",
      "oooooooooooooooo",
      "oooooooooooooooo",
      "oooooooooooooooo",
      "oooooooooooooooo"
    ]
  ]
}