{
  "name": "multi_nuclearpowerplant_12_base8",
  "refpalette": "deceasedcraft:multi_nuclearpowerplant_12/multi_nuclearpowerplant_12_base8_palette",
  "xsize": 16,
  "zsize": 16,
  "slices": [
    [
      "aaaaaaaaaaaaaaaa",
      "aaaaaaaaaaaaaaaa",
      "aaaaaaaaaaaaaaaa",
      "aaaaaaaaaaaaaaaa",
      "aaaaaaaaaaaaaaaa",
      "aaaaaaaaaaaaaaaa",
      "aaaaaaaaaaaaaaaa",
      "aaaaaaaaaaaaaaaa",
      "aaaaaaaaaaaaaaaa",
      "bbbbbbbbbbbbbbbb",
      "cccccccccccccccc",
      "dccccccccccccccc",
      "ddcccccccccccccc",
      "dddccccccccccccc",
      "ddddcccccccccccc",
      "dddddccccccccccc"
    ],
    [
      "eeef============",
      "eeef============",
      "eeef============",
      "eeef============",
      "eeeef===========",
      "eeeef===========",
      "eeeef===========",
      "eeeeef==========",
      "eeeeef==========",
      "eeeeef==========",
      "feeeeef=========",
      "dfeeeef=========",
      "ddfeeeef========",
      "dddfeeef========",
      "ddddfeeef=======",
      "dddddfeef======="
    ],
    [
      "ggghdddddddddddd",
      "ggghdddddddddddd",
      "ggghdddddddddddd",
      "ggghdddddddddddd",
      "gggghddddddddddd",
      "gggghddddddddddd",
      "gggghddddddddddd",
      "ggggghdddddddddd",
      "ggggghdddddddddd",
      "ggggghdddddddddd",
      "hggggghddddddddd",
      "dhgggghddddddddd",
      "ddhgggghdddddddd",
      "dddhggghdddddddd",
      "ddddhggghddddddd",
      "dddddhgghddddddd"
    ],
    [
      "ggghdddddddddddd",
      "ggghdddddddddddd",
      "ggghdddddddddddd",
      "ggghdddddddddddd",
      "gggghddddddddddd",
      "gggghddddddddddd",
      "gggghddddddddddd",
      "ggggghdddddddddd",
      "ggggghdddddddddd",
      "ggggghdddddddddd",
      "hggggghddddddddd",
      "dhgggghddddddddd",
      "ddhgggghdddddddd",
      "dddhggghdddddddd",
      "ddddhggghddddddd",
      "dddddhgghddddddd"
    ],
    [
      "ggghffffffffffff",
      "ggghffffffffffff",
      "ggghffffffffffff",
      "ggghffffffffffff",
      "gggghfffffffffff",
      "gggghfffffffffff",
      "gggghfffffffffff",
      "ggggghffffffffff",
      "ggggghffffffffff",
      "ggggghffffffffff",
      "hggggghfffffffff",
      "dhgggghfffffffff",
      "ddhgggghffffffff",
      "dddhggghffffffff",
      "ddddhggghfffffff",
      "dddddhgghfffffff"
    ],
    [
      "gggh            ",
      "gggh            ",
      "gggh            ",
      "gggh            ",
      "ggggh           ",
      "ggggh           ",
      "ggggh           ",
      "gggggh          ",
      "gggggh          ",
      "gggggh          ",
      "hgggggh         ",
      "dhggggh         ",
      "ddhggggh        ",
      "dddhgggh        ",
      "ddddhgggh       ",
      "dddddhggh       "
    ]
  ]
}