{
  "name": "multi_terraceplaza_18_floor2",
  "refpalette": "deceasedcraft:multi_terraceplaza_18/multi_terraceplaza_18_floor2_palette",
  "xsize": 16,
  "zsize": 16,
  "slices": [
    [
      "                ",
      "                ",
      "                ",
      "                ",
      "                ",
      "                ",
      "                ",
      "                ",
      "                ",
      "abcddddddddddcba",
      "eecffffffffffcee",
      "ggcffffffffffcgg",
      "hh            hh",
      "ii            ii",
      "                ",
      "                "
    ],
    [
      "                ",
      "                ",
      "                ",
      "                ",
      "                ",
      "                ",
      "jjckkkkkkkkkkcjj",
      "eecffffffffffcee",
      "ggcffffffffffcgg",
      "llllllllllllllll",
      "llllllllllllllll",
      "                ",
      "                ",
      "                ",
      "                ",
      "                "
    ],
    [
      "                ",
      "                ",
      "                ",
      "jjckkkkkkkkkkcjj",
      "eecffffffffffcee",
      "ggcffffffffffcgg",
      "hh            hh",
      "ii            ii",
      "mmmmmmmmmmmmmmmm",
      "nnnnnnnnnnnnnnnn",
      "                ",
      "                ",
      "                ",
      "                ",
      "                ",
      "                "
    ],
    [
      "jjckkkkkkkkkkcjj",
      "eecffffffffffcee",
      "ggcffffffffffcgg",
      "hh            hh",
      "ii            ii",
      "                ",
      "                ",
      "                ",
      "                ",
      "                ",
      "                ",
      "                ",
      "                ",
      "                ",
      "                ",
      "                "
    ],
    [
      "hh            hh",
      "ii            ii",
      "                ",
      "                ",
      "                ",
      "                ",
      "                ",
      "                ",
      "                ",
      "                ",
      "                ",
      "                ",
      "                ",
      "                ",
      "                ",
      "                "
    ],
    [
      "                ",
      "                ",
      "                ",
      "                ",
      "                ",
      "                ",
      "                ",
      "                ",
      "                ",
      "                ",
      "                ",
      "                ",
      "                ",
      "                ",
      "                ",
      "                "
    ]
  ]
}