{
  "name": "multi_terraceplaza_18_base2",
  "refpalette": "deceasedcraft:multi_terraceplaza_18/multi_terraceplaza_18_base2_palette",
  "xsize": 16,
  "zsize": 16,
  "slices": [
    [
      "abccccccccccccba",
      "abccccccccccccba",
      "abccccccccccccba",
      "abccccccccccccba",
      "abccccccccccccba",
      "abccccccccccccba",
      "abccccccccccccba",
      "abccccccccccccba",
      "abdccccccccccdba",
      "aefgccccccccgfea",
      "ahdiiiiiiiiiidha",
      "ahiiiiiiiiiiiiha",
      "ahiiiiiiiiiiiiha",
      "ahiiiiiiiiiiiiha",
      "ahiiiiiiiiiiiiha",
      "ahiiiiiiiiiiiiha"
    ],
    [
      "                ",
      "                ",
      "                ",
      "                ",
      "                ",
      "                ",
      "                ",
      "                ",
      " jkkk      kkkl ",
      " e mknnnnnnkm e ",
      "ockkkcccccckkkcp",
      "qccccccccccccccr",
      "scttttttttttttcr",
      "scuwxxxxxxxxwucy",
      "scuwwwwwwwwwwucy",
      " cuwA!BAABCAwucy"
    ],
    [
      "                ",
      "                ",
      "                ",
      "                ",
      "                ",
      "                ",
      "                ",
      "                ",
      "                ",
      " e D        D e ",
      "oE            Fp",
      " cnnnnnnnnnnnncI",
      " ccccccccccccccI",
      " cccccccccccccc ",
      " cttttttttttttc ",
      " cuxxxxxxxxxxuc "
    ],
    [
      "                ",
      "                ",
      "                ",
      "                ",
      "                ",
      "                ",
      "                ",
      "                ",
      "                ",
      " e J        J e ",
      "oK            Lp",
      " K            L ",
      " E            FM",
      " cnnnnnnnnnnnnc ",
      " ccccccccNNNNNc ",
      " ccccccccccccccO"
    ],
    [
      "                ",
      "                ",
      "                ",
      "                ",
      "                ",
      "                ",
      "                ",
      "                ",
      "                ",
      " e P        P e ",
      "oK            Lp",
      " K            L ",
      " K            L ",
      " K            L ",
      " E      cQQQQQc ",
      " cnnnnnncgggggc "
    ],
    [
      "                ",
      "                ",
      "                ",
      "                ",
      "                ",
      "                ",
      "                ",
      "                ",
      "                ",
      " eRR        R e ",
      "oK            Lp",
      "SK            L ",
      "TK            L ",
      "SK            L ",
      "TK            L ",
      "SK       UUUUUL "
    ]
  ]
}