{
  "name": "multi_terraceplaza_18_base1",
  "refpalette": "deceasedcraft:multi_terraceplaza_18/multi_terraceplaza_18_base1_palette",
  "xsize": 16,
  "zsize": 16,
  "slices": [
    [
      "                ",
      "                ",
      "                ",
      "                ",
      "                ",
      "                ",
      "                ",
      "                ",
      "   a        a   ",
      " baa        aab ",
      "cd a        a ef",
      "gd            eg",
      "gd            eg",
      "gd            eg",
      "gd            eg",
      "gd            eg"
    ],
    [
      "                ",
      "                ",
      "                ",
      "                ",
      "                ",
      "                ",
      "                ",
      "                ",
      "            a   ",
      " b aa      aaab ",
      "cd a        a ef",
      " d            e ",
      " d            e ",
      " d            e ",
      " d            e ",
      " d            e "
    ],
    [
      "                ",
      "                ",
      "                ",
      "                ",
      "                ",
      "                ",
      "                ",
      "                ",
      "            a   ",
      " b a        a b ",
      "cd            ef",
      " d            e ",
      " d            e ",
      " d            e ",
      " d            e ",
      " d            e "
    ],
    [
      "h              h",
      "hi            jh",
      "hk            jh",
      "hi            lh",
      "hi            jh",
      "hi            lh",
      "hk            jh",
      "h              h",
      "h              h",
      "hb          a bh",
      "h              h",
      "h              h",
      "h              h",
      "h              h",
      "h              h",
      "h              h"
    ],
    [
      "h              h",
      "h              h",
      "h              h",
      "h              h",
      "h              h",
      "h              h",
      "h              h",
      "h              h",
      "h              h",
      "hb            bh",
      "h              h",
      "h              h",
      "h              h",
      "h              h",
      "h              h",
      "h              h"
    ],
    [
      "mn            nh",
      "mn            nh",
      "mn            nh",
      "mn            nh",
      "mn            nh",
      "mn            nh",
      "mn            nh",
      "mn            nh",
      "mn            nh",
      "nb            bn",
      "mn            nh",
      "mn            nh",
      "mn            nh",
      "mn            nh",
      "mn            nh",
      "mn            nh"
    ]
  ]
}