{
  "name": "multi_terraceplaza_18_floor1",
  "refpalette": "deceasedcraft:multi_terraceplaza_18/multi_terraceplaza_18_floor1_palette",
  "xsize": 16,
  "zsize": 16,
  "slices": [
    [
      "                ",
      "                ",
      "                ",
      "                ",
      "                ",
      "                ",
      "                ",
      "                ",
      "                ",
      " a            a ",
      "                ",
      "                ",
      "b              b",
      "cd            ec",
      "e              d",
      "                "
    ],
    [
      "fg            gf",
      "fg            gf",
      "fg            gf",
      "fg            gf",
      "fg            gf",
      "fg            gf",
      "fg            gf",
      "fg            gf",
      "fg            gf",
      "ga            ag",
      "hg            gh",
      "bg            gb",
      "cg            gc",
      "eg            gd",
      " g            g ",
      " g            g "
    ],
    [
      "ij            ki",
      "ij            ki",
      "ij            ki",
      "ilmnnnnnnnnnnoli",
      "ilmnnnnnnnnnnoli",
      "ij            ki",
      "ij            ki",
      "ij            ki",
      "ij            ki",
      "paq          rap",
      "pj            kp",
      "cj            kc",
      "ej            kd",
      " j            k ",
      " j            k ",
      " j            k "
    ],
    [
      " s            s ",
      " s            s ",
      " s            s ",
      " tttttttttttttt ",
      " uuuuuuuuuuuuuu ",
      " s            s ",
      " s            s ",
      " s            s ",
      " s            s ",
      "ea            ad",
      "es            sd",
      "es            sd",
      " s            s ",
      " s            s ",
      " s            s ",
      " s            s "
    ],
    [
      "                ",
      "                ",
      "                ",
      "                ",
      "                ",
      "                ",
      "                ",
      "                ",
      "                ",
      " a            a ",
      "                ",
      "                ",
      "                ",
      "                ",
      "                ",
      "nnwxxxxxxxxxxwnn"
    ],
    [
      "                ",
      "                ",
      "                ",
      "                ",
      "                ",
      "                ",
      "                ",
      "                ",
      "                ",
      " a            a ",
      "                ",
      "                ",
      "nnwxxxxxxxxxxwnn",
      "yywAAAAAAAAAAwyy",
      "llwAAAAAAAAAAwll",
      "BB            BB"
    ]
  ]
}