{
  "name": "multi_nuclearpowerplant_19_base10",
  "refpalette": "deceasedcraft:multi_nuclearpowerplant_19/multi_nuclearpowerplant_19_base10_palette",
  "xsize": 16,
  "zsize": 16,
  "slices": [
    [
      "                ",
      "                ",
      "                ",
      "                ",
      "                ",
      "                ",
      "aaaaaaaaaaaaaaaa",
      "aaaaaaaaaaaaaaaa",
      " b     cc b     ",
      "dddddddddddddddd",
      "eeeeeeeeeeeeeeee",
      "ffffffffffffffff",
      "ffffffffffffffff",
      "ffffffffffffffff",
      "ffffffffffffffff",
      "ffffffffffffffff"
    ],
    [
      "                ",
      "                ",
      "                ",
      "                ",
      "                ",
      "gggggggggggggggg",
      "                ",
      "gggggggggggggggg",
      " b     cc b     ",
      "dddddddddddddddd",
      "eeeeeeeeeeeeeeee",
      "ffffffffffffffff",
      "ffffffffffffffff",
      "ffffffffffffffff",
      "ffffffffffffffff",
      "ffffffffffffffff"
    ],
    [
      "                ",
      "                ",
      "                ",
      "                ",
      "                ",
      "                ",
      "                ",
      "                ",
      " b     cc b     ",
      "dddddddddddddddd",
      "eeeeeeeeeeeeeeee",
      "ffffffffffffffff",
      "ffffffffffffffff",
      "ffffffffffffffff",
      "ffffffffffffffff",
      "ffffffffffffffff"
    ],
    [
      "                ",
      "                ",
      "                ",
      "                ",
      "                ",
      "                ",
      "                ",
      "                ",
      " b     cc b     ",
      "dddddddddddddddd",
      "eeeeeeeeeeeeeeee",
      "ffffffffffffffff",
      "ffffffffffffffff",
      "ffffffffffffffff",
      "ffffffffffffffff",
      "ffffffffffffffff"
    ],
    [
      "                ",
      "                ",
      "                ",
      "                ",
      "                ",
      "                ",
      "                ",
      "                ",
      " b     cc b     ",
      "dddddddddddddddd",
      "eeeeeeeeeeeeeeee",
      "ffffffffffffffff",
      "ffffffffffffffff",
      "ffffffffffffffff",
      "ffffffffffffffff",
      "ffffffffffffffff"
    ],
    [
      "                ",
      "                ",
      "                ",
      "                ",
      "                ",
      "                ",
      "                ",
      "                ",
      " b     cc b     ",
      "dddddddddddddddd",
      "eeeeeeeeeeeeeeee",
      "ffffffffffffffff",
      "ffffffffffffffff",
      "ffffffffffffffff",
      "ffffffffffffffff",
      "ffffffffffffffff"
    ]
  ]
}