{
  "name": "multi_nuclearpowerplant_19_ground",
  "refpalette": "deceasedcraft:multi_nuclearpowerplant_19/multi_nuclearpowerplant_19_ground_palette",
  "xsize": 16,
  "zsize": 16,
  "slices": [
    [
      "                ",
      "                ",
      "                ",
      "                ",
      "        a       ",
      "       bc       ",
      "        c       ",
      "        c       ",
      "        c       ",
      "        c       ",
      "        c       ",
      "      d cd      ",
      "      e ce      ",
      "        c       ",
      "        c       ",
      "        c       "
    ],
    [
      "                ",
      "                ",
      "                ",
      "                ",
      "                ",
      "                ",
      "                ",
      "                ",
      "                ",
      "                ",
      "                ",
      "                ",
      "      d  d      ",
      "      e  e      ",
      "f               ",
      "ffff            "
    ],
    [
      "                ",
      "                ",
      "                ",
      "                ",
      "                ",
      "                ",
      "                ",
      "                ",
      "                ",
      "                ",
      "                ",
      "fffff         ff",
      "ffffffffffffffff",
      "ffffffffffffffff",
      "ffffffffffffffff",
      "ffffffffffffffff"
    ],
    [
      "                ",
      "                ",
      "                ",
      "                ",
      "                ",
      "                ",
      "             fff",
      "         fffffff",
      "ffffffffffffffff",
      "ffffffffffffffff",
      "ffffffffffffffff",
      "ffffffffffffffff",
      "zzzzfffffffffffz",
      "zzzzzzzzzzzzzzzz",
      "zzzzzzzzzzzzzzzz",
      "zzzzzzzzzzzzzzzz"
    ],
    [
      "              ff",
      "            ffff",
      "          ffffff",
      "        ffffffff",
      "f   ffffffffffff",
      "ffffffffffffffff",
      "ffffffffffffffff",
      "ffffffffffffffzz",
      "ffffffffffzzzzzz",
      "zzzzzzzzzzzzzzzz",
      "zzzzzzzzzzzzzzzz",
      "zzzzzzzzzzzgzzzz",
      "zh  zgzzzzzzzgzz",
      "   i   zh    z  ",
      "ij   ii  j i iii",
      "      hihi      "
    ],
    [
      "   fffffffffffff",
      "fffffffffffffffz",
      "fffffffffffffzzz",
      "fffffffffffzzzzz",
      "fffffffffzzzzzzz",
      "fffffzzzzzzzzzzz",
      "zzzzzzzzzzzzzzzz",
      "zzzzzzzzzgzzzz z",
      "zzzzzzzzzzz   i ",
      "  zh  zji    ij ",
      "    i   i    i  ",
      "i  i        i   ",
      "       h i      ",
      "                ",
      "                ",
      "                "
    ]
  ]
}