{
  "name": "multi_nuclearpowerplant_19_top",
  "refpalette": "deceasedcraft:multi_nuclearpowerplant_19/multi_nuclearpowerplant_19_top_palette",
  "xsize": 16,
  "zsize": 16,
  "slices": [
    [
      "aaaaaaaazzzzzzzz",
      "aaaazzzzzzzzzzz ",
      "zzzzzzbzzzzzz  c",
      "zzzzzzzzzzz cz  ",
      "bbzzzzzzzz      ",
      "zzzzzz  d  c   c",
      "   ezccc     cc ",
      "     c     d    ",
      "                ",
      "  d             ",
      "                ",
      "                ",
      "                ",
      "                ",
      "                ",
      "                "
    ],
    [
      "zzzzzzzz   c    ",
      "zzzz         c  ",
      "  dzz      c    ",
      "    c     c     ",
      " c c d  c       ",
      "    cc          ",
      "                ",
      "                ",
      "                ",
      "                ",
      "                ",
      "                ",
      "                ",
      "                ",
      "                ",
      "                "
    ],
    [
      "c c             ",
      "c  c            ",
      "   c            ",
      "                ",
      "                ",
      "                ",
      "                ",
      "                ",
      "                ",
      "                ",
      "                ",
      "                ",
      "                ",
      "                ",
      "                ",
      "                "
    ]
  ]
}