{
  "name": "multi_nuclearpowerplant_19_base12",
  "refpalette": "deceasedcraft:multi_nuclearpowerplant_19/multi_nuclearpowerplant_19_base12_palette",
  "xsize": 16,
  "zsize": 16,
  "slices": [
    [
      "aaaaaaaaaaaaaaaa",
      "aaaaaaaaaaaaaaaa",
      "aaaaaaaaaaaaaaaa",
      "aaaaaaaaaaaaaaaa",
      "aaaaaaaaaaaaaaaa",
      "aaaaaaaaaaaaaaaa",
      "aaaaaaaaaaaaaaaa",
      "aaaaaaaaaaaaaaaa",
      "aaaaaaaaaaaaaaaa",
      "aaaaaaaaaaaaaaaa",
      "aaaaaaaaaaaaaaaa",
      "aaaaaaaaaaaaaaaa",
      "aaaaaaaaaaaaaaaa",
      "aaaaaaaaaaaaaaaa",
      "aaaaaaaaaaaaaaaa",
      "aaaaaaaaaaaaaaaa"
    ],
    [
      "bbbbbbbbbbbbbbbb",
      "bbbbbbbbbbbbbbbb",
      "bbbbbbbbbbbbbbbb",
      "bbbbbbbbbbbbbbbb",
      "bbbbbbbbbbbbbbbb",
      "bbbbbbbbbbbbbbbb",
      "bbbbbbbbbbbbbbbb",
      "bbbbbbbbbbbbbbbb",
      "bbbbbbbbbbbbbbbb",
      "bbbbbbbbbbbbbbbb",
      "bbbbbbbbbbbbbbbb",
      "aaaaaaaaaaaaaaaa",
      "aaaaaaaaaaaaaaaa",
      "aaaaaaaaaaaaaaaa",
      "aaaaaaaaaaaaaaaa",
      "aaaaaaaaaaaaaaaa"
    ],
    [
      "cccccccccccccccc",
      "cccccccccccccccc",
      "cccccccccccccccc",
      "cccccccccccccccc",
      "cccccccccccccccc",
      "cccccccccccccccc",
      "dddddddccddddddd",
      "edfdeedccdeedfde",
      "edfdeedccdeedfde",
      "egggeeggggeeggge",
      "ebbbeebbbbeebbbe",
      "aaaaaaaaaaaaaaaa",
      "aaaaaaaaaaaaaaaa",
      "aaaaaaaaaaaaaaaa",
      "aaaaaaaaaaaaaaaa",
      "aaaaaaaaaaaaaaaa"
    ],
    [
      "                ",
      "                ",
      "                ",
      "                ",
      "                ",
      "                ",
      "                ",
      "hi jhhi  jhhi jh",
      "kiljkkimmjkkiljk",
      "ngggnnggggnngggn",
      "ebbbeebbbbeebbbe",
      "aaaaaaaaaaaaaaaa",
      "aaaaaaaaaaaaaaaa",
      "aaaaaaaaaaaaaaaa",
      "aaaaaaaaaaaaaaaa",
      "aaaaaaaaaaaaaaaa"
    ],
    [
      "                ",
      "                ",
      "                ",
      "                ",
      "                ",
      "                ",
      "o    o     o    ",
      "fi jjfi  jjfi jj",
      "kipjqkimmjqkirjq",
      "sgggtsggggtugggt",
      "ebbbeebbbbeebbbe",
      "aaaaaaaaaaaaaaaa",
      "aaaaaaaaaaaaaaaa",
      "aaaaaaaaaaaaaaaa",
      "aaaaaaaaaaaaaaaa",
      "aaaaaaaaaaaaaaaa"
    ],
    [
      "                ",
      "                ",
      "                ",
      "                ",
      "                ",
      "                ",
      "                ",
      "wi jjwi  jjwi jj",
      "kixjqkimmjqkixjq",
      "sgggtsggggtugggt",
      "ebbbeebbbbeebbbe",
      "aaaaaaaaaaaaaaaa",
      "aaaaaaaaaaaaaaaa",
      "aaaaaaaaaaaaaaaa",
      "aaaaaaaaaaaaaaaa",
      "aaaaaaaaaaaaaaaa"
    ]
  ]
}