{
  "name": "multi_nuclearpowerplant_19_base1",
  "refpalette": "deceasedcraft:multi_nuclearpowerplant_19/multi_nuclearpowerplant_19_base1_palette",
  "xsize": 16,
  "zsize": 16,
  "slices": [
    [
      "                ",
      "      abab      ",
      "     cdddde     ",
      "     cdddde     ",
      "     fddddg     ",
      "     cdddde     ",
      "     fddddg     ",
      "     ~hhii      ",
      "     jkkkk      ",
      "ll    kkkk    ll",
      "mllll kkkk llllm",
      "mmmmllllllllmmmm",
      "mmmmmmmmmmmmmmmm",
      "mmmmmmmmmmmmmmmm",
      "mmmmmmmmmmmmmmmm",
      "mmmmmmmmmmmmmmmm"
    ],
    [
      "                ",
      "      abba      ",
      "     f    e     ",
      "     c    e     ",
      "     c    e     ",
      "     f    e     ",
      "     f!nopg     ",
      "      i  h      ",
      "     qrrrrs     ",
      "tt   q    s   tt",
      " ttttq    stttt ",
      "    tq    st    ",
      "    uu    uu    ",
      "                ",
      "                ",
      "                "
    ],
    [
      "                ",
      "      bbbb      ",
      "     w    x     ",
      "     w    x     ",
      "     w    x     ",
      "     w    x     ",
      "     w yA x     ",
      "      h  i      ",
      "                ",
      "                ",
      "                ",
      "                ",
      "                ",
      "                ",
      "                ",
      "                "
    ],
    [
      "                ",
      "      bbbb      ",
      "     fBBBBe     ",
      "     fBBBBe     ",
      "     fBBBBe     ",
      "     fBBBBe     ",
      "     fBBBBe     ",
      "      iiii      ",
      "                ",
      "                ",
      "                ",
      "                ",
      "                ",
      "                ",
      "                ",
      "                "
    ],
    [
      "                ",
      "                ",
      "                ",
      "                ",
      "        C       ",
      "      DE D      ",
      "      D  D      ",
      "      D  D      ",
      "      F  F      ",
      "      F  F      ",
      "      F  F      ",
      "      F  F      ",
      "      F  F      ",
      "      F  F      ",
      "      F  F      ",
      "      F  F      "
    ],
    [
      "                ",
      "                ",
      "                ",
      "                ",
      "        I       ",
      "      JKLJ      ",
      "      M  M      ",
      "      M  M      ",
      "      M  M      ",
      "      M  M      ",
      "      M  M      ",
      "      N  N      ",
      "      O  O      ",
      "      O  O      ",
      "      O  O      ",
      "      O  O      "
    ]
  ]
}