{
  "name": "multi_nuclearpowerplant_19_base11",
  "refpalette": "deceasedcraft:multi_nuclearpowerplant_19/multi_nuclearpowerplant_19_base11_palette",
  "xsize": 16,
  "zsize": 16,
  "slices": [
    [
      "                ",
      "                ",
      "                ",
      "                ",
      "                ",
      "                ",
      "a    a     a    ",
      "bc ddbc  ddbc dd",
      "ecfdgechhdgecfdg",
      "ijjjkijjjjkljjjk",
      "mnnnmmnnnnmmnnnm",
      "oooooooooooooooo",
      "oooooooooooooooo",
      "oooooooooooooooo",
      "oooooooooooooooo",
      "oooooooooooooooo"
    ],
    [
      "                ",
      "                ",
      "                ",
      "                ",
      "                ",
      "                ",
      "                ",
      "pc dppc  dppc dp",
      "pc dqpchhdrpc ds",
      "tjjjuujjjjuujjju",
      "mnnnmmnnnnmmnnnm",
      "oooooooooooooooo",
      "oooooooooooooooo",
      "oooooooooooooooo",
      "oooooooooooooooo",
      "oooooooooooooooo"
    ],
    [
      "                ",
      "                ",
      "                ",
      "                ",
      "                ",
      "                ",
      "                ",
      "                ",
      "    w  hh w    w",
      "jjjjjjjjjjjjjjjj",
      "nnnnnnnnnnnnnnnn",
      "oooooooooooooooo",
      "oooooooooooooooo",
      "oooooooooooooooo",
      "oooooooooooooooo",
      "oooooooooooooooo"
    ],
    [
      "                ",
      "                ",
      "                ",
      "                ",
      "                ",
      "                ",
      "                ",
      "                ",
      "    x  hh x    x",
      "jjjjjjjjjjjjjjjj",
      "nnnnnnnnnnnnnnnn",
      "oooooooooooooooo",
      "oooooooooooooooo",
      "oooooooooooooooo",
      "oooooooooooooooo",
      "oooooooooooooooo"
    ],
    [
      "yyyyyyyyyyyyyyyy",
      "AAAAAAAAAAAAAAAA",
      "                ",
      "                ",
      "                ",
      "                ",
      "                ",
      "                ",
      " xxxx  hh x    x",
      "jjjjjjjjjjjjjjjj",
      "nnnnnnnnnnnnnnnn",
      "oooooooooooooooo",
      "oooooooooooooooo",
      "oooooooooooooooo",
      "oooooooooooooooo",
      "oooooooooooooooo"
    ],
    [
      "                ",
      "BBBBBBBBBBBBBBBB",
      "                ",
      "                ",
      "                ",
      "                ",
      "                ",
      "                ",
      " x     hh x     ",
      "jjjjjjjjjjjjjjjj",
      "nnnnnnnnnnnnnnnn",
      "oooooooooooooooo",
      "oooooooooooooooo",
      "oooooooooooooooo",
      "oooooooooooooooo",
      "oooooooooooooooo"
    ]
  ]
}