{
  "name": "building_office1a_ground_180",
  "refpalette": "deceasedcraft:building_office1a/building_office1a_ground_palette_180",
  "xsize": 16,
  "zsize": 16,
  "slices": [
    [
      "aaaaaaaaaaaaaaaa",
      "adddddddddddddda",
      "adedddddddddddda",
      "adedddddddddddda",
      "adedddddeeeeeeda",
      "abedddddeddddeba",
      "abedddddeddddeba",
      "abeddddddeeeeeba",
      "abcddddddddddcba",
      "abcddddddddddcba",
      "abcddddddddddcba",
      "abcddddddddddcba",
      "abcddddddddddcba",
      "abccccccccccccba",
      "abbbbbbbbbbbbbba",
      "aaaaaaaaaaaaaaaa"
    ],
    [
      "                ",
      " uuuuuuuuuuuuuu ",
      " B           Au ",
      " y           xu ",
      " ueq   !eweeeeu ",
      " fg    re ts gf ",
      " fg    re    gf ",
      " feq    qeeeeef ",
      " fgpon  k    gf ",
      " fg     km   gf ",
      " fglll  k    gf ",
      " fg     k    gf ",
      " fgjih       gf ",
      " fggggggggggggf ",
      " ffffffffffffff ",
      "                "
    ],
    [
      "                ",
      " uuLggggggggLuu ",
      " K           ru ",
      " J           ru ",
      " uef    eIeeeeu ",
      "  g    Fe  tsg  ",
      "  g     e    g  ",
      "  ef    feeeee  ",
      "  g     E    g  ",
      "  g          g  ",
      "  g     D    g  ",
      "  g     C    g  ",
      "  g          g  ",
      "  gggggggggggg  ",
      "                ",
      "                "
    ],
    [
      "                ",
      " uuLggggggggLuu ",
      " Q           ru ",
      " P           ru ",
      " ueM    eeeeeeu ",
      "  g     e   Og  ",
      "  g     e  Nsg  ",
      "  eM    Meeeee  ",
      "  g          g  ",
      "  g          g  ",
      "  g          g  ",
      "  g          g  ",
      "  g          g  ",
      "  gggggggggggg  ",
      "                ",
      "                "
    ],
    [
      "                ",
      " uuuuuuuuuuuuuu ",
      " u           ru ",
      " u           ru ",
      " ue     eeeeeeu ",
      "  g     e    g  ",
      "  g     e NR g  ",
      "  e      eeeee  ",
      "  g          g  ",
      "  g          g  ",
      "  g          g  ",
      "  g          g  ",
      "  g          g  ",
      "  gggggggggggg  ",
      "                ",
      "                "
    ],
    [
      "                ",
      " uuuuuuuuuuuuuu ",
      " uWTUUUUUUUUUru ",
      " uWTUUUUUUUUUru ",
      " ueTUUUUeeeeeeu ",
      "  gTUUUUeV   g  ",
      "  gTUUUUeNR  g  ",
      " SSTUUUUUeeeeSS ",
      " SSTUUUUUUUUTSS ",
      " SSTUUUUUUUUTSS ",
      " SSTUUUUUUUUTSS ",
      " SSTUUUUUUUUTSS ",
      " SSTTTTTTTTTTSS ",
      " SSSSSSSSSSSSSS ",
      " SSSSSSSSSSSSSS ",
      "                "
    ]
  ]
}