{
  "name": "building_office1a_floor2_270",
  "refpalette": "deceasedcraft:building_office1a/building_office1a_floor2_palette_270",
  "xsize": 16,
  "zsize": 16,
  "slices": [
    [
      "                ",
      " iiii  c        ",
      " ibbdeecaaaaaa  ",
      " ibbd  dbbbbba  ",
      " ibbd  dbbbbba  ",
      " ibbdg dbbbbba  ",
      " ibbdhfdbbbbba  ",
      " ibbdddbbbbbba  ",
      " ibbbbbbbbbbba  ",
      " ibbbbbbbbbbba  ",
      " ibbbbbbbbbbba  ",
      " ibbbbbbbbbbba  ",
      " ibbbbbbbbbbba  ",
      " ibbdeecaaaaaa  ",
      " iiii  c        ",
      "                "
    ],
    [
      "                ",
      " IIII  c        ",
      " IM deecjjjjjj  ",
      " IN d  dq    j  ",
      " IOKdg d r  kj  ",
      " I  dE dwsol j  ",
      " I  J  dxtpm j  ",
      " I  dddBy n  j  ",
      " I   CCBArq  j  ",
      " I  CF Bwsol j  ",
      " I   CDBxtpm j  ",
      " I     k uqn j  ",
      " I           j  ",
      " IPLdeecjjjjjj  ",
      " IIII  c        ",
      "                "
    ],
    [
      "                ",
      " IIII  c        ",
      " I  deecjjjjjj  ",
      " 63 dg d     j  ",
      " e42dE d     j  ",
      " e  d  dWUQ  j  ",
      " e  1  dXVR  j  ",
      " e  dddZ     j  ",
      " e     Z     j  ",
      " e   0 ZWUS  j  ",
      " e     ZYVT  j  ",
      " e           j  ",
      " 6           j  ",
      " I5 deecjjjjjj  ",
      " IIII  c        ",
      "                "
    ],
    [
      "                ",
      " IIII  c        ",
      " I  deecjjjjjj  ",
      " 6% dfgd     j  ",
      " e4#d 9d     j  ",
      " e  d  d     j  ",
      " e  d  d     j  ",
      " e  ddd!     j  ",
      " e     7     j  ",
      " e           j  ",
      " e     8     j  ",
      " e           j  ",
      " 6           j  ",
      " I^$deecjjjjjj  ",
      " IIII  c        ",
      "                "
    ],
    [
      "                ",
      " IIII  c        ",
      " I--deecjjjjjj  ",
      " I--d  d     j  ",
      " I][d +d     j  ",
      " I  d 9d     j  ",
      " I  d  d     j  ",
      " I  ddd&     j  ",
      " I     *     j  ",
      " I     *     j  ",
      " I     (     j  ",
      " I     *     j  ",
      " I     )     j  ",
      " I{ deecjjjjjj  ",
      " IIII  c        ",
      "                "
    ],
    [
      "                ",
      " IIII  c        ",
      " I :deecjjjjjj  ",
      " I: d  d}}}}}j  ",
      " I''d  d||||}j  ",
      " I||d +d||||}j  ",
      " I||d;9d||||}j  ",
      " I||ddd|||||}j  ",
      " I||||||||||}j  ",
      " I||||||||||}j  ",
      " I||||||||||}j  ",
      " I||||||||||}j  ",
      " I}}}}}}}}}}}j  ",
      " I<<deecjjjjjj  ",
      " IIII  c        ",
      "                "
    ]
  ]
}