{
  "name": "building_office1a_floor3",
  "refpalette": "deceasedcraft:building_office1a/building_office1a_floor3_palette",
  "xsize": 16,
  "zsize": 16,
  "slices": [
    [
      "                ",
      "                ",
      "  aaaaaaaaaaaa  ",
      "  abbbbbbbbbba  ",
      "  abbbbbbbbbba  ",
      "  abbbbbbbbbba  ",
      "  abbbbbbbbbba  ",
      "  abbbbbbbbbba  ",
      " ccddddbbbbbbcc ",
      "  e   fdbbbbbe  ",
      "  e  ghdbbbbbe  ",
      " iddddddbbbbbdi ",
      " ibbbbbbbbbbbbi ",
      " ibbbbbbbbbbbbi ",
      " iiiiiiiiiiiiii ",
      "                "
    ],
    [
      "                ",
      "                ",
      "  jjjjjjjjjjjj  ",
      "  jk l l l   j  ",
      "  jm noooopq j  ",
      "  jm rsssst  j  ",
      "  ju w wxw   j  ",
      "  jy         j  ",
      " ccdddddddABdcc ",
      "  e    dC    e  ",
      "  e gD dE    e  ",
      " FddddIdJ    dF ",
      " F  K        LF ",
      " FMNO        LF ",
      " FFFFFFFFFFFFFF ",
      "                "
    ],
    [
      "                ",
      "                ",
      "  jjjjjjjjjjjj  ",
      "  jP         j  ",
      "  jP Q Q  R  j  ",
      "  jP STU Q   j  ",
      "  jP         j  ",
      "  jV         j  ",
      " ccdddddddWXdcc ",
      "  e    dY    e  ",
      "  egD  d     e  ",
      " FddddZd     dF ",
      " F  0        LF ",
      " F 12        LF ",
      " FF3eeeeeeee3FF ",
      "                "
    ],
    [
      "                ",
      "                ",
      "  jjjjjjjjjjjj  ",
      "  j4         j  ",
      "  j4         j  ",
      "  j4         j  ",
      "  j4         j  ",
      "  j5         j  ",
      " ccddddddd66dcc ",
      "  eg7  d     e  ",
      "  ef   d     e  ",
      " Fdddddd     dF ",
      " F  8        LF ",
      " F 92        LF ",
      " FF3eeeeeeee3FF ",
      "                "
    ],
    [
      "                ",
      "                ",
      "  jjjjjjjjjjjj  ",
      "  j          j  ",
      "  j          j  ",
      "  j          j  ",
      "  j          j  ",
      "  j          j  ",
      " ccddddddddddcc ",
      "  e #7 d     e  ",
      "  e    d     e  ",
      " Fdddddd     dF ",
      " F$$%        !F ",
      " F$$^        &F ",
      " FFFFFFFFFFFFFF ",
      "                "
    ],
    [
      "                ",
      "                ",
      "  jjjjjjjjjjjj  ",
      "  j**********j  ",
      "  j*((((((((*j  ",
      "  j*((((((((*j  ",
      "  j*((((((((*j  ",
      "  j*))))))))*j  ",
      " ccddddddddddcc ",
      "  e  #7d((((*e  ",
      "  e   +d((((*e  ",
      " Fdddddd((((*dF ",
      " F- [(((((((*]F ",
      " F -[(((((((*]F ",
      " FFFFFFFFFFFFFF ",
      "                "
    ]
  ]
}