{
  "name": "building_office1a_floor3_180",
  "refpalette": "deceasedcraft:building_office1a/building_office1a_floor3_palette_180",
  "xsize": 16,
  "zsize": 16,
  "slices": [
    [
      "                ",
      " iiiiiiiiiiiiii ",
      " ibbbbbbbbbbbbi ",
      " ibbbbbbbbbbbbi ",
      " idbbbbbddddddi ",
      "  ebbbbbdhg  e  ",
      "  ebbbbbdf   e  ",
      " ccbbbbbbddddcc ",
      "  abbbbbbbbbba  ",
      "  abbbbbbbbbba  ",
      "  abbbbbbbbbba  ",
      "  abbbbbbbbbba  ",
      "  abbbbbbbbbba  ",
      "  aaaaaaaaaaaa  ",
      "                ",
      "                "
    ],
    [
      "                ",
      " FFFFFFFFFFFFFF ",
      " FL        ONMF ",
      " FL        K  F ",
      " Fd    JdIddddF ",
      "  e    Ed Dg e  ",
      "  e    Cd    e  ",
      " ccdBAdddddddcc ",
      "  j         yj  ",
      "  j   wxw w uj  ",
      "  j  tssssr mj  ",
      "  j qpoooon mj  ",
      "  j   l l l kj  ",
      "  jjjjjjjjjjjj  ",
      "                ",
      "                "
    ],
    [
      "                ",
      " FF3eeeeeeee3FF ",
      " FL        21 F ",
      " FL        0  F ",
      " Fd     dZddddF ",
      "  e     d  Dge  ",
      "  e    Yd    e  ",
      " ccdXWdddddddcc ",
      "  j         Vj  ",
      "  j         Pj  ",
      "  j   Q UTS Pj  ",
      "  j  R  Q Q Pj  ",
      "  j         Pj  ",
      "  jjjjjjjjjjjj  ",
      "                ",
      "                "
    ],
    [
      "                ",
      " FF3eeeeeeee3FF ",
      " FL        29 F ",
      " FL        8  F ",
      " Fd     ddddddF ",
      "  e     d   fe  ",
      "  e     d  7ge  ",
      " ccd66dddddddcc ",
      "  j         5j  ",
      "  j         4j  ",
      "  j         4j  ",
      "  j         4j  ",
      "  j         4j  ",
      "  jjjjjjjjjjjj  ",
      "                ",
      "                "
    ],
    [
      "                ",
      " FFFFFFFFFFFFFF ",
      " F&        ^$$F ",
      " F!        %$$F ",
      " Fd     ddddddF ",
      "  e     d    e  ",
      "  e     d 7# e  ",
      " ccddddddddddcc ",
      "  j          j  ",
      "  j          j  ",
      "  j          j  ",
      "  j          j  ",
      "  j          j  ",
      "  jjjjjjjjjjjj  ",
      "                ",
      "                "
    ],
    [
      "                ",
      " FFFFFFFFFFFFFF ",
      " F]*((((((([- F ",
      " F]*((((((([ -F ",
      " Fd*((((ddddddF ",
      "  e*((((d+   e  ",
      "  e*((((d7#  e  ",
      " ccddddddddddcc ",
      "  j*))))))))*j  ",
      "  j*((((((((*j  ",
      "  j*((((((((*j  ",
      "  j*((((((((*j  ",
      "  j**********j  ",
      "  jjjjjjjjjjjj  ",
      "                ",
      "                "
    ]
  ]
}