{
  "name": "building_office1a_top_180",
  "refpalette": "deceasedcraft:building_office1a/building_office1a_top_palette_180",
  "xsize": 16,
  "zsize": 16,
  "slices": [
    [
      "                ",
      " iiiiiiiiiiiiii ",
      " ibbbbbbbbbbbbi ",
      " ibbbbbbbbbbbbi ",
      " idbbbbbddddddi ",
      "  ebbbbbdhg  e  ",
      "  ebbbbbdf   e  ",
      " ccbbbbbbddddcc ",
      "  abbbbbbbbbba  ",
      "  abbbbbbbbbba  ",
      "  abbbbbbbbbba  ",
      "  abbbbbbbbbba  ",
      "  abbbbbbbbbba  ",
      "  aaaaaaaaaaaa  ",
      "                ",
      "                "
    ],
    [
      "                ",
      " qqqqqqqqqqqqqq ",
      " qD        Cxwq ",
      " qB  As    yxwq ",
      " qduuts drddddq ",
      "  eppp  d o  e  ",
      "  e     d    e  ",
      " cc     nddddcc ",
      "  j kk    kk j  ",
      "  j kl mm lk j  ",
      "  j kl mm lk j  ",
      "  j kk    kk j  ",
      "  j          j  ",
      "  jjjjjjjjjjjj  ",
      "                ",
      "                "
    ],
    [
      "                ",
      " qqOeeeeeeeeOqq ",
      " qN         LKq ",
      " qM         LKq ",
      " qdJ I  dFddddq ",
      "  e     d    e  ",
      "  e     d    e  ",
      " cc     Eddddcc ",
      "                ",
      "                ",
      "                ",
      "                ",
      "                ",
      "                ",
      "                ",
      "                "
    ],
    [
      "                ",
      " qqOeeeeeeeeOqq ",
      " qU         L q ",
      " qT         L q ",
      " qdSRRRQddddddq ",
      "  e     d    e  ",
      "  e     d    e  ",
      " cc     Pddddcc ",
      "                ",
      "                ",
      "                ",
      "                ",
      "                ",
      "                ",
      "                ",
      "                "
    ],
    [
      "                ",
      " qqqqqqqqqqqqqq ",
      " qYXXXXXXXXXXXq ",
      " qYXXXXXXXXXXXq ",
      " qddddddddddddq ",
      "  dddddddddddd  ",
      "  dddddddddddd  ",
      " ccddddddddddcc ",
      "  VWWWWWWWWWWV  ",
      "  VWWWWWWWWWWV  ",
      "  VWWWWWWWWWWV  ",
      "  VWWWWWWWWWWV  ",
      "  VWWWWWWWWWWV  ",
      "  VVVVVVVVVVVV  ",
      "                ",
      "                "
    ],
    [
      "                ",
      " qqqqqqqqqqqqqq ",
      " q111111111111q ",
      " q111111111111q ",
      " q111111111111q ",
      "                ",
      "                ",
      " ccZZ0ZZZZ0ZZcc ",
      "                ",
      "                ",
      "                ",
      "                ",
      "                ",
      "                ",
      "                ",
      "                "
    ]
  ]
}