{
  "name": "building_office1a_ground_90",
  "refpalette": "deceasedcraft:building_office1a/building_office1a_ground_palette_90",
  "xsize": 16,
  "zsize": 16,
  "slices": [
    [
      "aaaaaaaaaaaaaaaa",
      "abbbbbbbbbbdddda",
      "abcccccceeeeeeda",
      "abcdddddddddddda",
      "abcdddddddddddda",
      "abcdddddddddddda",
      "abcdddddddddddda",
      "abcdddddddddddda",
      "abcddddddeeeddda",
      "abcdddddeddeddda",
      "abcdddddeddeddda",
      "abcdddddeddeddda",
      "abcdddddeddeddda",
      "abcccccceeeeddda",
      "abbbbbbbbbbdddda",
      "aaaaaaaaaaaaaaaa"
    ],
    [
      "                ",
      " ffffffffffuyBu ",
      " fggggggegge  u ",
      " fgj l pq  q  u ",
      " fgi l o      u ",
      " fgh l n      u ",
      " fg           u ",
      " fg      rr!  u ",
      " fg kkkkqeee  u ",
      " fg   m e  w  u ",
      " fg     e te  u ",
      " fg     e se  u ",
      " fg     e  e  u ",
      " fggggggeggexAu ",
      " ffffffffffuuuu ",
      "                "
    ],
    [
      "                ",
      "           uJKu ",
      "  ggggggegge  u ",
      "  g     f  f  L ",
      "  g           g ",
      "  g           g ",
      "  g           g ",
      "  g       F   g ",
      "  g CD Efeee  g ",
      "  g     e  I  g ",
      "  g     e  e  g ",
      "  g     e te  g ",
      "  g     e se  L ",
      "  ggggggeggerru ",
      "           uuuu ",
      "                "
    ],
    [
      "                ",
      "           uPQu ",
      "  ggggggegge  u ",
      "  g     M  M  L ",
      "  g           g ",
      "  g           g ",
      "  g           g ",
      "  g           g ",
      "  g     Meee  g ",
      "  g     e  e  g ",
      "  g     e  e  g ",
      "  g     eN e  g ",
      "  g     esOe  L ",
      "  ggggggeggerru ",
      "           uuuu ",
      "                "
    ],
    [
      "                ",
      "           uuuu ",
      "  ggggggegge  u ",
      "  g           u ",
      "  g           u ",
      "  g           u ",
      "  g           u ",
      "  g           u ",
      "  g      eee  u ",
      "  g     e  e  u ",
      "  g     eN e  u ",
      "  g     eR e  u ",
      "  g     e  e  u ",
      "  ggggggeggerru ",
      "           uuuu ",
      "                "
    ],
    [
      "                ",
      " SSSSSSSS  uuuu ",
      " SSSSSSSSggeWWu ",
      " SSTTTTTTTTTTTu ",
      " SSTUUUUUUUUUUu ",
      " SSTUUUUUUUUUUu ",
      " SSTUUUUUUUUUUu ",
      " SSTUUUUUUUUUUu ",
      " SSTUUUUUeeeUUu ",
      " SSTUUUUeNVeUUu ",
      " SSTUUUUeR eUUu ",
      " SSTUUUUe  eUUu ",
      " SSTTTTTe  eUUu ",
      " SSSSSSSSggerru ",
      " SSSSSSSS  uuuu ",
      "                "
    ]
  ]
}