{
  "name": "building_office1a_floor2",
  "refpalette": "deceasedcraft:building_office1a/building_office1a_floor2_palette",
  "xsize": 16,
  "zsize": 16,
  "slices": [
    [
      "                ",
      "                ",
      "  aaaaaaaaaaaa  ",
      "  abbbbbbbbbba  ",
      "  abbbbbbbbbba  ",
      "  abbbbbbbbbba  ",
      "  abbbbbbbbbba  ",
      "  abbbbbbbbbba  ",
      " ccddddbbbbbbcc ",
      "  e   fdbbbbbe  ",
      "  e  ghdbbbbbe  ",
      " iddddddbbbbbdi ",
      " ibbbbbbbbbbbbi ",
      " ibbbbbbbbbbbbi ",
      " iiiiiiiiiiiiii ",
      "                "
    ],
    [
      "                ",
      "                ",
      "  jjjjjjjjjjjj  ",
      "  j k        j  ",
      "  j  lm  lmn j  ",
      "  j  opnqopq j  ",
      "  j rst rstu j  ",
      "  jq wxyAwx  j  ",
      " ccddddBBBBk cc ",
      "  e    dC D  e  ",
      "  e gE dCFC  e  ",
      " IddddJd C   dI ",
      " I  K        LI ",
      " IMNO        PI ",
      " IIIIIIIIIIIIII ",
      "                "
    ],
    [
      "                ",
      "                ",
      "  jjjjjjjjjjjj  ",
      "  j          j  ",
      "  j          j  ",
      "  j  QR  ST  j  ",
      "  j  UV  UV  j  ",
      "  j  WX  WY  j  ",
      " ccddddZZZZ  cc ",
      "  e    d     e  ",
      "  egE  d 0   e  ",
      " Idddd1d     dI ",
      " I  2         I ",
      " I 34        5I ",
      " II6eeeeeeee6II ",
      "                "
    ],
    [
      "                ",
      "                ",
      "  jjjjjjjjjjjj  ",
      "  j          j  ",
      "  j          j  ",
      "  j          j  ",
      "  j          j  ",
      "  j          j  ",
      " ccdddd!7 8  cc ",
      "  eg9  d     e  ",
      "  ef   d     e  ",
      " Idddddd     dI ",
      " I  #        $I ",
      " I %4        ^I ",
      " II6eeeeeeee6II ",
      "                "
    ],
    [
      "                ",
      "                ",
      "  jjjjjjjjjjjj  ",
      "  j          j  ",
      "  j          j  ",
      "  j          j  ",
      "  j          j  ",
      "  j          j  ",
      " ccdddd&**(*)cc ",
      "  e +9 d     e  ",
      "  e    d     e  ",
      " Idddddd     dI ",
      " I--[         I ",
      " I--]        {I ",
      " IIIIIIIIIIIIII ",
      "                "
    ],
    [
      "                ",
      "                ",
      "  jjjjjjjjjjjj  ",
      "  j}}}}}}}}}}j  ",
      "  j}||||||||}j  ",
      "  j}||||||||}j  ",
      "  j}||||||||}j  ",
      "  j}||||||||}j  ",
      " ccdddd|||||}cc ",
      "  e  +9d||||}e  ",
      "  e   ;d||||}e  ",
      " Idddddd||||}dI ",
      " I: '|||||||}<I ",
      " I :'|||||||}<I ",
      " IIIIIIIIIIIIII ",
      "                "
    ]
  ]
}