{
  "name": "building_office1a_top_270",
  "refpalette": "deceasedcraft:building_office1a/building_office1a_top_palette_270",
  "xsize": 16,
  "zsize": 16,
  "slices": [
    [
      "                ",
      " iiii  c        ",
      " ibbdeecaaaaaa  ",
      " ibbd  dbbbbba  ",
      " ibbd  dbbbbba  ",
      " ibbdg dbbbbba  ",
      " ibbdhfdbbbbba  ",
      " ibbdddbbbbbba  ",
      " ibbbbbbbbbbba  ",
      " ibbbbbbbbbbba  ",
      " ibbbbbbbbbbba  ",
      " ibbbbbbbbbbba  ",
      " ibbbbbbbbbbba  ",
      " ibbdeecaaaaaa  ",
      " iiii  c        ",
      "                "
    ],
    [
      "                ",
      " qqqq  c        ",
      " qwwdeecjjjjjj  ",
      " qxxd  d     j  ",
      " qCyd  dkkkk j  ",
      " q  do dkllk j  ",
      " q  r  d     j  ",
      " q  dddn mm  j  ",
      " q       mm  j  ",
      " q ss        j  ",
      " q Atp  kllk j  ",
      " q  up  kkkk j  ",
      " q  up       j  ",
      " qDBdeecjjjjjj  ",
      " qqqq  c        ",
      "                "
    ],
    [
      "                ",
      " qqqq  c        ",
      " qKKdeec        ",
      " OLLd  d        ",
      " e  d  d        ",
      " e  d  d        ",
      " e  F  d        ",
      " e  dddE        ",
      " e              ",
      " e              ",
      " e  I           ",
      " e              ",
      " O  J           ",
      " qNMdeec        ",
      " qqqq  c        ",
      "                "
    ],
    [
      "                ",
      " qqqq  c        ",
      " q  deec        ",
      " OLLd  d        ",
      " e  d  d        ",
      " e  d  d        ",
      " e  d  d        ",
      " e  dddP        ",
      " e  Q           ",
      " e  R           ",
      " e  R           ",
      " e  R           ",
      " O  S           ",
      " qUTdeec        ",
      " qqqq  c        ",
      "                "
    ],
    [
      "                ",
      " qqqq  c        ",
      " qXXdddcVVVVVV  ",
      " qXXddddWWWWWV  ",
      " qXXddddWWWWWV  ",
      " qXXddddWWWWWV  ",
      " qXXddddWWWWWV  ",
      " qXXddddWWWWWV  ",
      " qXXddddWWWWWV  ",
      " qXXddddWWWWWV  ",
      " qXXddddWWWWWV  ",
      " qXXddddWWWWWV  ",
      " qXXddddWWWWWV  ",
      " qYYdddcVVVVVV  ",
      " qqqq  c        ",
      "                "
    ],
    [
      "                ",
      " qqqq  c        ",
      " q111  c        ",
      " q111  Z        ",
      " q111  Z        ",
      " q111  0        ",
      " q111  Z        ",
      " q111  Z        ",
      " q111  Z        ",
      " q111  Z        ",
      " q111  0        ",
      " q111  Z        ",
      " q111  Z        ",
      " q111  c        ",
      " qqqq  c        ",
      "                "
    ]
  ]
}