{
  "name": "building_office1a_top_90",
  "refpalette": "deceasedcraft:building_office1a/building_office1a_top_palette_90",
  "xsize": 16,
  "zsize": 16,
  "slices": [
    [
      "                ",
      "        c  iiii ",
      "  aaaaaaceedbbi ",
      "  abbbbbbbbbbbi ",
      "  abbbbbbbbbbbi ",
      "  abbbbbbbbbbbi ",
      "  abbbbbbbbbbbi ",
      "  abbbbbbbbbbbi ",
      "  abbbbbbdddbbi ",
      "  abbbbbdfhdbbi ",
      "  abbbbbd gdbbi ",
      "  abbbbbd  dbbi ",
      "  abbbbbd  dbbi ",
      "  aaaaaaceedbbi ",
      "        c  iiii ",
      "                "
    ],
    [
      "                ",
      "        c  qqqq ",
      "  jjjjjjceedBDq ",
      "  j       pu  q ",
      "  j kkkk  pu  q ",
      "  j kllk  ptA q ",
      "  j        ss q ",
      "  j  mm       q ",
      "  j  mm nddd  q ",
      "  j     d  r  q ",
      "  j kllkd od  q ",
      "  j kkkkd  dyCq ",
      "  j     d  dxxq ",
      "  jjjjjjceedwwq ",
      "        c  qqqq ",
      "                "
    ],
    [
      "                ",
      "        c  qqqq ",
      "        ceedMNq ",
      "           J  O ",
      "              e ",
      "           I  e ",
      "              e ",
      "              e ",
      "        Eddd  e ",
      "        d  F  e ",
      "        d  d  e ",
      "        d  d  e ",
      "        d  dLLO ",
      "        ceedKKq ",
      "        c  qqqq ",
      "                "
    ],
    [
      "                ",
      "        c  qqqq ",
      "        ceedTUq ",
      "           S  O ",
      "           R  e ",
      "           R  e ",
      "           R  e ",
      "           Q  e ",
      "        Pddd  e ",
      "        d  d  e ",
      "        d  d  e ",
      "        d  d  e ",
      "        d  dLLO ",
      "        ceed  q ",
      "        c  qqqq ",
      "                "
    ],
    [
      "                ",
      "        c  qqqq ",
      "  VVVVVVcdddYYq ",
      "  VWWWWWddddXXq ",
      "  VWWWWWddddXXq ",
      "  VWWWWWddddXXq ",
      "  VWWWWWddddXXq ",
      "  VWWWWWddddXXq ",
      "  VWWWWWddddXXq ",
      "  VWWWWWddddXXq ",
      "  VWWWWWddddXXq ",
      "  VWWWWWddddXXq ",
      "  VWWWWWddddXXq ",
      "  VVVVVVcdddXXq ",
      "        c  qqqq ",
      "                "
    ],
    [
      "                ",
      "        c  qqqq ",
      "        c  111q ",
      "        Z  111q ",
      "        Z  111q ",
      "        0  111q ",
      "        Z  111q ",
      "        Z  111q ",
      "        Z  111q ",
      "        Z  111q ",
      "        0  111q ",
      "        Z  111q ",
      "        Z  111q ",
      "        c  111q ",
      "        c  qqqq ",
      "                "
    ]
  ]
}