{
  "name": "building_office1a_floor3_90",
  "refpalette": "deceasedcraft:building_office1a/building_office1a_floor3_palette_90",
  "xsize": 16,
  "zsize": 16,
  "slices": [
    [
      "                ",
      "        c  iiii ",
      "  aaaaaaceedbbi ",
      "  abbbbbbbbbbbi ",
      "  abbbbbbbbbbbi ",
      "  abbbbbbbbbbbi ",
      "  abbbbbbbbbbbi ",
      "  abbbbbbbbbbbi ",
      "  abbbbbbdddbbi ",
      "  abbbbbdfhdbbi ",
      "  abbbbbd gdbbi ",
      "  abbbbbd  dbbi ",
      "  abbbbbd  dbbi ",
      "  aaaaaaceedbbi ",
      "        c  iiii ",
      "                "
    ],
    [
      "                ",
      "        c  FFFF ",
      "  jjjjjjceedLLF ",
      "  j     d     F ",
      "  j q   B     F ",
      "  j pt  A     F ",
      "  jlosw d     F ",
      "  j osx dCEJ  F ",
      "  jlosw dddd  F ",
      "  j os  d  I  F ",
      "  jlnrw d Dd  F ",
      "  j     d gdKOF ",
      "  jkmmuyd  d NF ",
      "  jjjjjjceed MF ",
      "        c  FFFF ",
      "                "
    ],
    [
      "                ",
      "        c  FFFF ",
      "  jjjjjjceedLLF ",
      "  j     d     3 ",
      "  j     X     e ",
      "  j R   W     e ",
      "  j  Q  d     e ",
      "  j     dY    e ",
      "  j QU  dddd  e ",
      "  j  T  d  Z  e ",
      "  j QS  d  d  e ",
      "  j     d Dd02e ",
      "  jPPPPVd gd 13 ",
      "  jjjjjjceed  F ",
      "        c  FFFF ",
      "                "
    ],
    [
      "                ",
      "        c  FFFF ",
      "  jjjjjjceedLLF ",
      "  j     d     3 ",
      "  j     6     e ",
      "  j     6     e ",
      "  j     d     e ",
      "  j     d     e ",
      "  j     dddd  e ",
      "  j     d  d  e ",
      "  j     d  d  e ",
      "  j     d7 d82e ",
      "  j44445dgfd 93 ",
      "  jjjjjjceed  F ",
      "        c  FFFF ",
      "                "
    ],
    [
      "                ",
      "        c  FFFF ",
      "  jjjjjjceed!&F ",
      "  j     d     F ",
      "  j     d     F ",
      "  j     d     F ",
      "  j     d     F ",
      "  j     d     F ",
      "  j     dddd  F ",
      "  j     d  d  F ",
      "  j     d7 d  F ",
      "  j     d# d%^F ",
      "  j     d  d$$F ",
      "  jjjjjjceed$$F ",
      "        c  FFFF ",
      "                "
    ],
    [
      "                ",
      "        c  FFFF ",
      "  jjjjjjceed]]F ",
      "  j*****d*****F ",
      "  j*((()d(((((F ",
      "  j*((()d(((((F ",
      "  j*((()d(((((F ",
      "  j*((()d(((((F ",
      "  j*((()dddd((F ",
      "  j*((()d7+d((F ",
      "  j*((()d# d((F ",
      "  j*((()d  d[[F ",
      "  j*****d  d -F ",
      "  jjjjjjceed- F ",
      "        c  FFFF ",
      "                "
    ]
  ]
}