{
  "name": "building_office1a_floor1_180",
  "refpalette": "deceasedcraft:building_office1a/building_office1a_floor1_palette_180",
  "xsize": 16,
  "zsize": 16,
  "slices": [
    [
      "                ",
      " iiiiiiiiiiiiii ",
      " ibbbbbbbbbbbbi ",
      " ibbbbbbbbbbbbi ",
      " idbbbbbddddddi ",
      "  ebbbbbdhg  e  ",
      "  ebbbbbdf   e  ",
      " ccbbbbbbddddcc ",
      "  abbbbbbbbbba  ",
      "  abbbbbbbbbba  ",
      "  abbbbbbbbbba  ",
      "  abbbbbbbbbba  ",
      "  abbbbbbbbbba  ",
      "  aaaaaaaaaaaa  ",
      "                ",
      "                "
    ],
    [
      "                ",
      " BBBBBBBBBBBBBB ",
      " BM        LKJB ",
      " BI        FEDB ",
      " Bd   x dCddddB ",
      "  e  xAxd yg e  ",
      "  e   x d    e  ",
      " cc  wwwwddddcc ",
      "  j uts uts  j  ",
      "  j  qpr qpo j  ",
      "  j  nm  nm  j  ",
      "  j  lk  lk  j  ",
      "  j          j  ",
      "  jjjjjjjjjjjj  ",
      "                ",
      "                "
    ],
    [
      "                ",
      " BB2eeeeeeee2BB ",
      " B1        0Z B ",
      " B         Y  B ",
      " Bd     dXddddB ",
      "  e   W d  yge  ",
      "  e     d    e  ",
      " cc  VVVVddddcc ",
      "  j  UT  UT  j  ",
      "  j  SR  SR  j  ",
      "  j  QP  ON  j  ",
      "  j          j  ",
      "  j          j  ",
      "  jjjjjjjjjjjj  ",
      "                ",
      "                "
    ],
    [
      "                ",
      " BB2eeeeeeee2BB ",
      " B#        09 B ",
      " B8        7  B ",
      " Bd     ddddddB ",
      "  e     d   fe  ",
      "  e     d  6ge  ",
      " cc  5 43ddddcc ",
      "  j          j  ",
      "  j          j  ",
      "  j          j  ",
      "  j          j  ",
      "  j          j  ",
      "  jjjjjjjjjjjj  ",
      "                ",
      "                "
    ],
    [
      "                ",
      " BBBBBBBBBBBBBB ",
      " B[        -((B ",
      " B+        )((B ",
      " Bd     ddddddB ",
      "  e     d    e  ",
      "  e     d 6* e  ",
      " cc&%^%%$ddddcc ",
      "  j          j  ",
      "  j          j  ",
      "  j          j  ",
      "  j          j  ",
      "  j          j  ",
      "  jjjjjjjjjjjj  ",
      "                ",
      "                "
    ],
    [
      "                ",
      " BBBBBBBBBBBBBB ",
      " B:]{{{{{{{;| B ",
      " B:]{{{{{{{; |B ",
      " Bd]{{{{ddddddB ",
      "  e]{{{{d}   e  ",
      "  e]{{{{d6*  e  ",
      " cc]{{{{{ddddcc ",
      "  j]{{{{{{{{]j  ",
      "  j]{{{{{{{{]j  ",
      "  j]{{{{{{{{]j  ",
      "  j]{{{{{{{{]j  ",
      "  j]]]]]]]]]]j  ",
      "  jjjjjjjjjjjj  ",
      "                ",
      "                "
    ]
  ]
}