{
  "name": "building_office1a_floor2_180",
  "refpalette": "deceasedcraft:building_office1a/building_office1a_floor2_palette_180",
  "xsize": 16,
  "zsize": 16,
  "slices": [
    [
      "                ",
      " iiiiiiiiiiiiii ",
      " ibbbbbbbbbbbbi ",
      " ibbbbbbbbbbbbi ",
      " idbbbbbddddddi ",
      "  ebbbbbdhg  e  ",
      "  ebbbbbdf   e  ",
      " ccbbbbbbddddcc ",
      "  abbbbbbbbbba  ",
      "  abbbbbbbbbba  ",
      "  abbbbbbbbbba  ",
      "  abbbbbbbbbba  ",
      "  abbbbbbbbbba  ",
      "  aaaaaaaaaaaa  ",
      "                ",
      "                "
    ],
    [
      "                ",
      " IIIIIIIIIIIIII ",
      " IP        ONMI ",
      " IL        K  I ",
      " Id   C dJddddI ",
      "  e  CFCd Eg e  ",
      "  e  D Cd    e  ",
      " cc kBBBBddddcc ",
      "  j  xwAyxw qj  ",
      "  j utsr tsr j  ",
      "  j qpoqnpo  j  ",
      "  j nml  ml  j  ",
      "  j        k j  ",
      "  jjjjjjjjjjjj  ",
      "                ",
      "                "
    ],
    [
      "                ",
      " II6eeeeeeee6II ",
      " I5        43 I ",
      " I         2  I ",
      " Id     d1ddddI ",
      "  e   0 d  Ege  ",
      "  e     d    e  ",
      " cc  ZZZZddddcc ",
      "  j  YW  XW  j  ",
      "  j  VU  VU  j  ",
      "  j  TS  RQ  j  ",
      "  j          j  ",
      "  j          j  ",
      "  jjjjjjjjjjjj  ",
      "                ",
      "                "
    ],
    [
      "                ",
      " II6eeeeeeee6II ",
      " I^        4% I ",
      " I$        #  I ",
      " Id     ddddddI ",
      "  e     d   fe  ",
      "  e     d  9ge  ",
      " cc  8 7!ddddcc ",
      "  j          j  ",
      "  j          j  ",
      "  j          j  ",
      "  j          j  ",
      "  j          j  ",
      "  jjjjjjjjjjjj  ",
      "                ",
      "                "
    ],
    [
      "                ",
      " IIIIIIIIIIIIII ",
      " I{        ]--I ",
      " I         [--I ",
      " Id     ddddddI ",
      "  e     d    e  ",
      "  e     d 9+ e  ",
      " cc)*(**&ddddcc ",
      "  j          j  ",
      "  j          j  ",
      "  j          j  ",
      "  j          j  ",
      "  j          j  ",
      "  jjjjjjjjjjjj  ",
      "                ",
      "                "
    ],
    [
      "                ",
      " IIIIIIIIIIIIII ",
      " I<}|||||||': I ",
      " I<}|||||||' :I ",
      " Id}||||ddddddI ",
      "  e}||||d;   e  ",
      "  e}||||d9+  e  ",
      " cc}|||||ddddcc ",
      "  j}||||||||}j  ",
      "  j}||||||||}j  ",
      "  j}||||||||}j  ",
      "  j}||||||||}j  ",
      "  j}}}}}}}}}}j  ",
      "  jjjjjjjjjjjj  ",
      "                ",
      "                "
    ]
  ]
}