{
  "name": "building_office1a_floor1_270",
  "refpalette": "deceasedcraft:building_office1a/building_office1a_floor1_palette_270",
  "xsize": 16,
  "zsize": 16,
  "slices": [
    [
      "                ",
      " iiii  c        ",
      " ibbdeecaaaaaa  ",
      " ibbd  dbbbbba  ",
      " ibbd  dbbbbba  ",
      " ibbdg dbbbbba  ",
      " ibbdhfdbbbbba  ",
      " ibbdddbbbbbba  ",
      " ibbbbbbbbbbba  ",
      " ibbbbbbbbbbba  ",
      " ibbbbbbbbbbba  ",
      " ibbbbbbbbbbba  ",
      " ibbbbbbbbbbba  ",
      " ibbdeecaaaaaa  ",
      " iiii  c        ",
      "                "
    ],
    [
      "                ",
      " BBBB  c        ",
      " BJDdeecjjjjjj  ",
      " BKEd  d     j  ",
      " BLFdg d o   j  ",
      " B  dy dspmk j  ",
      " B  C  dtqnl j  ",
      " B  dddwu    j  ",
      " B   x w r   j  ",
      " B  xAxwspmk j  ",
      " B   x wtqnl j  ",
      " B      u    j  ",
      " B           j  ",
      " BMIdeecjjjjjj  ",
      " BBBB  c        ",
      "                "
    ],
    [
      "                ",
      " BBBB  c        ",
      " B  deecjjjjjj  ",
      " 2Z dg d     j  ",
      " e0Ydy d     j  ",
      " e  d  dTRN  j  ",
      " e  X  dUSO  j  ",
      " e  dddV     j  ",
      " e     V     j  ",
      " e   W VTRP  j  ",
      " e     VUSQ  j  ",
      " e           j  ",
      " 2           j  ",
      " B1 deecjjjjjj  ",
      " BBBB  c        ",
      "                "
    ],
    [
      "                ",
      " BBBB  c        ",
      " B  deecjjjjjj  ",
      " 29 dfgd     j  ",
      " e07d 6d     j  ",
      " e  d  d     j  ",
      " e  d  d     j  ",
      " e  ddd3     j  ",
      " e     4     j  ",
      " e           j  ",
      " e     5     j  ",
      " e           j  ",
      " 2           j  ",
      " B#8deecjjjjjj  ",
      " BBBB  c        ",
      "                "
    ],
    [
      "                ",
      " BBBB  c        ",
      " B((deecjjjjjj  ",
      " B((d  d     j  ",
      " B-)d *d     j  ",
      " B  d 6d     j  ",
      " B  d  d     j  ",
      " B  ddd$     j  ",
      " B     %     j  ",
      " B     %     j  ",
      " B     ^     j  ",
      " B     %     j  ",
      " B     &     j  ",
      " B[+deecjjjjjj  ",
      " BBBB  c        ",
      "                "
    ],
    [
      "                ",
      " BBBB  c        ",
      " B |deecjjjjjj  ",
      " B| d  d]]]]]j  ",
      " B;;d  d{{{{]j  ",
      " B{{d *d{{{{]j  ",
      " B{{d}6d{{{{]j  ",
      " B{{ddd{{{{{]j  ",
      " B{{{{{{{{{{]j  ",
      " B{{{{{{{{{{]j  ",
      " B{{{{{{{{{{]j  ",
      " B{{{{{{{{{{]j  ",
      " B]]]]]]]]]]]j  ",
      " B::deecjjjjjj  ",
      " BBBB  c        ",
      "                "
    ]
  ]
}