{
  "name": "building_office1a_floor2_90",
  "refpalette": "deceasedcraft:building_office1a/building_office1a_floor2_palette_90",
  "xsize": 16,
  "zsize": 16,
  "slices": [
    [
      "                ",
      "        c  iiii ",
      "  aaaaaaceedbbi ",
      "  abbbbbbbbbbbi ",
      "  abbbbbbbbbbbi ",
      "  abbbbbbbbbbbi ",
      "  abbbbbbbbbbbi ",
      "  abbbbbbbbbbbi ",
      "  abbbbbbdddbbi ",
      "  abbbbbdfhdbbi ",
      "  abbbbbd gdbbi ",
      "  abbbbbd  dbbi ",
      "  abbbbbd  dbbi ",
      "  aaaaaaceedbbi ",
      "        c  iiii ",
      "                "
    ],
    [
      "                ",
      "        c  IIII ",
      "  jjjjjjceedLPI ",
      "  j           I ",
      "  j nqu k     I ",
      "  j mptxBDC   I ",
      "  j loswB FC  I ",
      "  j  qrABCC   I ",
      "  j  n yBddd  I ",
      "  j mptxd  J  I ",
      "  j loswd Ed  I ",
      "  jk  r d gdKOI ",
      "  j    qd  d NI ",
      "  jjjjjjceed MI ",
      "        c  IIII ",
      "                "
    ],
    [
      "                ",
      "        c  IIII ",
      "  jjjjjjceed 5I ",
      "  j           6 ",
      "  j           e ",
      "  j  TVYZ     e ",
      "  j  SUWZ 0   e ",
      "  j     Z     e ",
      "  j     Zddd  e ",
      "  j  RVXd  1  e ",
      "  j  QUWd  d  e ",
      "  j     d Ed24e ",
      "  j     d gd 36 ",
      "  jjjjjjceed  I ",
      "        c  IIII ",
      "                "
    ],
    [
      "                ",
      "        c  IIII ",
      "  jjjjjjceed$^I ",
      "  j           6 ",
      "  j           e ",
      "  j     8     e ",
      "  j           e ",
      "  j     7     e ",
      "  j     !ddd  e ",
      "  j     d  d  e ",
      "  j     d  d  e ",
      "  j     d9 d#4e ",
      "  j     dgfd %6 ",
      "  jjjjjjceed  I ",
      "        c  IIII ",
      "                "
    ],
    [
      "                ",
      "        c  IIII ",
      "  jjjjjjceed {I ",
      "  j     )     I ",
      "  j     *     I ",
      "  j     (     I ",
      "  j     *     I ",
      "  j     *     I ",
      "  j     &ddd  I ",
      "  j     d  d  I ",
      "  j     d9 d  I ",
      "  j     d+ d[]I ",
      "  j     d  d--I ",
      "  jjjjjjceed--I ",
      "        c  IIII ",
      "                "
    ],
    [
      "                ",
      "        c  IIII ",
      "  jjjjjjceed<<I ",
      "  j}}}}}}}}}}}I ",
      "  j}||||||||||I ",
      "  j}||||||||||I ",
      "  j}||||||||||I ",
      "  j}||||||||||I ",
      "  j}|||||ddd||I ",
      "  j}||||d9;d||I ",
      "  j}||||d+ d||I ",
      "  j}||||d  d''I ",
      "  j}}}}}d  d :I ",
      "  jjjjjjceed: I ",
      "        c  IIII ",
      "                "
    ]
  ]
}