{
  "name": "building_office1a_top",
  "refpalette": "deceasedcraft:building_office1a/building_office1a_top_palette",
  "xsize": 16,
  "zsize": 16,
  "slices": [
    [
      "                ",
      "                ",
      "  aaaaaaaaaaaa  ",
      "  abbbbbbbbbba  ",
      "  abbbbbbbbbba  ",
      "  abbbbbbbbbba  ",
      "  abbbbbbbbbba  ",
      "  abbbbbbbbbba  ",
      " ccddddbbbbbbcc ",
      "  e   fdbbbbbe  ",
      "  e  ghdbbbbbe  ",
      " iddddddbbbbbdi ",
      " ibbbbbbbbbbbbi ",
      " ibbbbbbbbbbbbi ",
      " iiiiiiiiiiiiii ",
      "                "
    ],
    [
      "                ",
      "                ",
      "  jjjjjjjjjjjj  ",
      "  j          j  ",
      "  j kk    kk j  ",
      "  j kl mm lk j  ",
      "  j kl mm lk j  ",
      "  j kk    kk j  ",
      " ccddddn     cc ",
      "  e    d     e  ",
      "  e  o d  pppe  ",
      " qddddrd stuudq ",
      " qwxy    sA  Bq ",
      " qwxC        Dq ",
      " qqqqqqqqqqqqqq ",
      "                "
    ],
    [
      "                ",
      "                ",
      "                ",
      "                ",
      "                ",
      "                ",
      "                ",
      "                ",
      " ccddddE     cc ",
      "  e    d     e  ",
      "  e    d     e  ",
      " qddddFd  I Jdq ",
      " qKL         Mq ",
      " qKL         Nq ",
      " qqOeeeeeeeeOqq ",
      "                "
    ],
    [
      "                ",
      "                ",
      "                ",
      "                ",
      "                ",
      "                ",
      "                ",
      "                ",
      " ccddddP     cc ",
      "  e    d     e  ",
      "  e    d     e  ",
      " qddddddQRRRSdq ",
      " q L         Tq ",
      " q L         Uq ",
      " qqOeeeeeeeeOqq ",
      "                "
    ],
    [
      "                ",
      "                ",
      "  VVVVVVVVVVVV  ",
      "  VWWWWWWWWWWV  ",
      "  VWWWWWWWWWWV  ",
      "  VWWWWWWWWWWV  ",
      "  VWWWWWWWWWWV  ",
      "  VWWWWWWWWWWV  ",
      " ccddddddddddcc ",
      "  dddddddddddd  ",
      "  dddddddddddd  ",
      " qddddddddddddq ",
      " qXXXXXXXXXXXYq ",
      " qXXXXXXXXXXXYq ",
      " qqqqqqqqqqqqqq ",
      "                "
    ],
    [
      "                ",
      "                ",
      "                ",
      "                ",
      "                ",
      "                ",
      "                ",
      "                ",
      " ccZZ0ZZZZ0ZZcc ",
      "                ",
      "                ",
      " q111111111111q ",
      " q111111111111q ",
      " q111111111111q ",
      " qqqqqqqqqqqqqq ",
      "                "
    ]
  ]
}