{
  "name": "building_office1a_floor1_90",
  "refpalette": "deceasedcraft:building_office1a/building_office1a_floor1_palette_90",
  "xsize": 16,
  "zsize": 16,
  "slices": [
    [
      "                ",
      "        c  iiii ",
      "  aaaaaaceedbbi ",
      "  abbbbbbbbbbbi ",
      "  abbbbbbbbbbbi ",
      "  abbbbbbbbbbbi ",
      "  abbbbbbbbbbbi ",
      "  abbbbbbbbbbbi ",
      "  abbbbbbdddbbi ",
      "  abbbbbdfhdbbi ",
      "  abbbbbd gdbbi ",
      "  abbbbbd  dbbi ",
      "  abbbbbd  dbbi ",
      "  aaaaaaceedbbi ",
      "        c  iiii ",
      "                "
    ],
    [
      "                ",
      "        c  BBBB ",
      "  jjjjjjceedIMB ",
      "  j           B ",
      "  j    u      B ",
      "  j lnqtw x   B ",
      "  j kmpswxAx  B ",
      "  j   r w x   B ",
      "  j    uwddd  B ",
      "  j lnqtd  C  B ",
      "  j kmpsd yd  B ",
      "  j   o d gdFLB ",
      "  j     d  dEKB ",
      "  jjjjjjceedDJB ",
      "        c  BBBB ",
      "                "
    ],
    [
      "                ",
      "        c  BBBB ",
      "  jjjjjjceed 1B ",
      "  j           2 ",
      "  j           e ",
      "  j  QSUV     e ",
      "  j  PRTV W   e ",
      "  j     V     e ",
      "  j     Vddd  e ",
      "  j  OSUd  X  e ",
      "  j  NRTd  d  e ",
      "  j     d ydY0e ",
      "  j     d gd Z2 ",
      "  jjjjjjceed  B ",
      "        c  BBBB ",
      "                "
    ],
    [
      "                ",
      "        c  BBBB ",
      "  jjjjjjceed8#B ",
      "  j           2 ",
      "  j           e ",
      "  j     5     e ",
      "  j           e ",
      "  j     4     e ",
      "  j     3ddd  e ",
      "  j     d  d  e ",
      "  j     d  d  e ",
      "  j     d6 d70e ",
      "  j     dgfd 92 ",
      "  jjjjjjceed  B ",
      "        c  BBBB ",
      "                "
    ],
    [
      "                ",
      "        c  BBBB ",
      "  jjjjjjceed+[B ",
      "  j     &     B ",
      "  j     %     B ",
      "  j     ^     B ",
      "  j     %     B ",
      "  j     %     B ",
      "  j     $ddd  B ",
      "  j     d  d  B ",
      "  j     d6 d  B ",
      "  j     d* d)-B ",
      "  j     d  d((B ",
      "  jjjjjjceed((B ",
      "        c  BBBB ",
      "                "
    ],
    [
      "                ",
      "        c  BBBB ",
      "  jjjjjjceed::B ",
      "  j]]]]]]]]]]]B ",
      "  j]{{{{{{{{{{B ",
      "  j]{{{{{{{{{{B ",
      "  j]{{{{{{{{{{B ",
      "  j]{{{{{{{{{{B ",
      "  j]{{{{{ddd{{B ",
      "  j]{{{{d6}d{{B ",
      "  j]{{{{d* d{{B ",
      "  j]{{{{d  d;;B ",
      "  j]]]]]d  d |B ",
      "  jjjjjjceed| B ",
      "        c  BBBB ",
      "                "
    ]
  ]
}