{
  "name": "building_office1a_floor3_270",
  "refpalette": "deceasedcraft:building_office1a/building_office1a_floor3_palette_270",
  "xsize": 16,
  "zsize": 16,
  "slices": [
    [
      "                ",
      " iiii  c        ",
      " ibbdeecaaaaaa  ",
      " ibbd  dbbbbba  ",
      " ibbd  dbbbbba  ",
      " ibbdg dbbbbba  ",
      " ibbdhfdbbbbba  ",
      " ibbdddbbbbbba  ",
      " ibbbbbbbbbbba  ",
      " ibbbbbbbbbbba  ",
      " ibbbbbbbbbbba  ",
      " ibbbbbbbbbbba  ",
      " ibbbbbbbbbbba  ",
      " ibbdeecaaaaaa  ",
      " iiii  c        ",
      "                "
    ],
    [
      "                ",
      " FFFF  c        ",
      " FM deecjjjjjj  ",
      " FN d  dyummkj  ",
      " FOKdg d     j  ",
      " F  dD d wrnlj  ",
      " F  I  d  so j  ",
      " F  dddd wsolj  ",
      " F  JECd xso j  ",
      " F     d wsolj  ",
      " F     A  tp j  ",
      " F     B   q j  ",
      " F     d     j  ",
      " FLLdeecjjjjjj  ",
      " FFFF  c        ",
      "                "
    ],
    [
      "                ",
      " FFFF  c        ",
      " F  deecjjjjjj  ",
      " 31 dg dVPPPPj  ",
      " e20dD d     j  ",
      " e  d  d  SQ j  ",
      " e  Z  d  T  j  ",
      " e  dddd  UQ j  ",
      " e    Yd     j  ",
      " e     d  Q  j  ",
      " e     W   R j  ",
      " e     X     j  ",
      " 3     d     j  ",
      " FLLdeecjjjjjj  ",
      " FFFF  c        ",
      "                "
    ],
    [
      "                ",
      " FFFF  c        ",
      " F  deecjjjjjj  ",
      " 39 dfgd54444j  ",
      " e28d 7d     j  ",
      " e  d  d     j  ",
      " e  d  d     j  ",
      " e  dddd     j  ",
      " e     d     j  ",
      " e     d     j  ",
      " e     6     j  ",
      " e     6     j  ",
      " 3     d     j  ",
      " FLLdeecjjjjjj  ",
      " FFFF  c        ",
      "                "
    ],
    [
      "                ",
      " FFFF  c        ",
      " F$$deecjjjjjj  ",
      " F$$d  d     j  ",
      " F^%d #d     j  ",
      " F  d 7d     j  ",
      " F  d  d     j  ",
      " F  dddd     j  ",
      " F     d     j  ",
      " F     d     j  ",
      " F     d     j  ",
      " F     d     j  ",
      " F     d     j  ",
      " F&!deecjjjjjj  ",
      " FFFF  c        ",
      "                "
    ],
    [
      "                ",
      " FFFF  c        ",
      " F -deecjjjjjj  ",
      " F- d  d*****j  ",
      " F[[d  d)(((*j  ",
      " F((d #d)(((*j  ",
      " F((d+7d)(((*j  ",
      " F((dddd)(((*j  ",
      " F(((((d)(((*j  ",
      " F(((((d)(((*j  ",
      " F(((((d)(((*j  ",
      " F(((((d)(((*j  ",
      " F*****d*****j  ",
      " F]]deecjjjjjj  ",
      " FFFF  c        ",
      "                "
    ]
  ]
}