{
  "name": "building_office1a_floor1",
  "refpalette": "deceasedcraft:building_office1a/building_office1a_floor1_palette",
  "xsize": 16,
  "zsize": 16,
  "slices": [
    [
      "                ",
      "                ",
      "  aaaaaaaaaaaa  ",
      "  abbbbbbbbbba  ",
      "  abbbbbbbbbba  ",
      "  abbbbbbbbbba  ",
      "  abbbbbbbbbba  ",
      "  abbbbbbbbbba  ",
      " ccddddbbbbbbcc ",
      "  e   fdbbbbbe  ",
      "  e  ghdbbbbbe  ",
      " iddddddbbbbbdi ",
      " ibbbbbbbbbbbbi ",
      " ibbbbbbbbbbbbi ",
      " iiiiiiiiiiiiii ",
      "                "
    ],
    [
      "                ",
      "                ",
      "  jjjjjjjjjjjj  ",
      "  j          j  ",
      "  j  kl  kl  j  ",
      "  j  mn  mn  j  ",
      "  j opq rpq  j  ",
      "  j  stu stu j  ",
      " ccddddwwww  cc ",
      "  e    d x   e  ",
      "  e gy dxAx  e  ",
      " BddddCd x   dB ",
      " BDEF        IB ",
      " BJKL        MB ",
      " BBBBBBBBBBBBBB ",
      "                "
    ],
    [
      "                ",
      "                ",
      "  jjjjjjjjjjjj  ",
      "  j          j  ",
      "  j          j  ",
      "  j  NO  PQ  j  ",
      "  j  RS  RS  j  ",
      "  j  TU  TU  j  ",
      " ccddddVVVV  cc ",
      "  e    d     e  ",
      "  egy  d W   e  ",
      " BddddXd     dB ",
      " B  Y         B ",
      " B Z0        1B ",
      " BB2eeeeeeee2BB ",
      "                "
    ],
    [
      "                ",
      "                ",
      "  jjjjjjjjjjjj  ",
      "  j          j  ",
      "  j          j  ",
      "  j          j  ",
      "  j          j  ",
      "  j          j  ",
      " ccdddd34 5  cc ",
      "  eg6  d     e  ",
      "  ef   d     e  ",
      " Bdddddd     dB ",
      " B  7        8B ",
      " B 90        #B ",
      " BB2eeeeeeee2BB ",
      "                "
    ],
    [
      "                ",
      "                ",
      "  jjjjjjjjjjjj  ",
      "  j          j  ",
      "  j          j  ",
      "  j          j  ",
      "  j          j  ",
      "  j          j  ",
      " ccdddd$%%^%&cc ",
      "  e *6 d     e  ",
      "  e    d     e  ",
      " Bdddddd     dB ",
      " B(()        +B ",
      " B((-        [B ",
      " BBBBBBBBBBBBBB ",
      "                "
    ],
    [
      "                ",
      "                ",
      "  jjjjjjjjjjjj  ",
      "  j]]]]]]]]]]j  ",
      "  j]{{{{{{{{]j  ",
      "  j]{{{{{{{{]j  ",
      "  j]{{{{{{{{]j  ",
      "  j]{{{{{{{{]j  ",
      " ccdddd{{{{{]cc ",
      "  e  *6d{{{{]e  ",
      "  e   }d{{{{]e  ",
      " Bdddddd{{{{]dB ",
      " B| ;{{{{{{{]:B ",
      " B |;{{{{{{{]:B ",
      " BBBBBBBBBBBBBB ",
      "                "
    ]
  ]
}