{
  "name": "building_office1a_ground_270",
  "refpalette": "deceasedcraft:building_office1a/building_office1a_ground_palette_270",
  "xsize": 16,
  "zsize": 16,
  "slices": [
    [
      "aaaaaaaaaaaaaaaa",
      "addddbbbbbbbbbba",
      "adddeeeeccccccba",
      "adddeddedddddcba",
      "adddeddedddddcba",
      "adddeddedddddcba",
      "adddeddedddddcba",
      "adddeeeddddddcba",
      "addddddddddddcba",
      "addddddddddddcba",
      "addddddddddddcba",
      "addddddddddddcba",
      "addddddddddddcba",
      "adeeeeeeccccccba",
      "addddbbbbbbbbbba",
      "aaaaaaaaaaaaaaaa"
    ],
    [
      "                ",
      " uuuuffffffffff ",
      " uAxeggeggggggf ",
      " u  e  e     gf ",
      " u  es e     gf ",
      " u  et e     gf ",
      " u  w  e m   gf ",
      " u  eeeqkkkk gf ",
      " u  !rr      gf ",
      " u           gf ",
      " u      n l hgf ",
      " u      o l igf ",
      " u  q  qp l jgf ",
      " u  eggeggggggf ",
      " uByuffffffffff ",
      "                "
    ],
    [
      "                ",
      " uuuu           ",
      " urreggegggggg  ",
      " L  es e     g  ",
      " g  et e     g  ",
      " g  e  e     g  ",
      " g  I  e     g  ",
      " g  eeefE DC g  ",
      " g   F       g  ",
      " g           g  ",
      " g           g  ",
      " g           g  ",
      " L  f  f     g  ",
      " u  eggegggggg  ",
      " uKJu           ",
      "                "
    ],
    [
      "                ",
      " uuuu           ",
      " urreggegggggg  ",
      " L  eOse     g  ",
      " g  e Ne     g  ",
      " g  e  e     g  ",
      " g  e  e     g  ",
      " g  eeeM     g  ",
      " g           g  ",
      " g           g  ",
      " g           g  ",
      " g           g  ",
      " L  M  M     g  ",
      " u  eggegggggg  ",
      " uQPu           ",
      "                "
    ],
    [
      "                ",
      " uuuu           ",
      " urreggegggggg  ",
      " u  e  e     g  ",
      " u  e Re     g  ",
      " u  e Ne     g  ",
      " u  e  e     g  ",
      " u  eee      g  ",
      " u           g  ",
      " u           g  ",
      " u           g  ",
      " u           g  ",
      " u           g  ",
      " u  eggegggggg  ",
      " uuuu           ",
      "                "
    ],
    [
      "                ",
      " uuuu  SSSSSSSS ",
      " urreggSSSSSSSS ",
      " uUUe  eTTTTTSS ",
      " uUUe  eUUUUTSS ",
      " uUUe ReUUUUTSS ",
      " uUUeVNeUUUUTSS ",
      " uUUeeeUUUUUTSS ",
      " uUUUUUUUUUUTSS ",
      " uUUUUUUUUUUTSS ",
      " uUUUUUUUUUUTSS ",
      " uUUUUUUUUUUTSS ",
      " uTTTTTTTTTTTSS ",
      " uWWeggSSSSSSSS ",
      " uuuu  SSSSSSSS ",
      "                "
    ]
  ]
}