{
  "name": "building_office1a_ground",
  "refpalette": "deceasedcraft:building_office1a/building_office1a_ground_palette",
  "xsize": 16,
  "zsize": 16,
  "slices": [
    [
      "aaaaaaaaaaaaaaaa",
      "abbbbbbbbbbbbbba",
      "abccccccccccccba",
      "abcddddddddddcba",
      "abcddddddddddcba",
      "abcddddddddddcba",
      "abcddddddddddcba",
      "abcddddddddddcba",
      "abeeeeeddddddeba",
      "abeddddedddddeba",
      "abeddddedddddeba",
      "adeeeeeedddddeda",
      "addddddddddddeda",
      "addddddddddddeda",
      "adddddddddddddda",
      "aaaaaaaaaaaaaaaa"
    ],
    [
      "                ",
      " ffffffffffffff ",
      " fggggggggggggf ",
      " fg       hijgf ",
      " fg    k     gf ",
      " fg    k  lllgf ",
      " fg   mk     gf ",
      " fg    k  nopgf ",
      " feeeeeq    qef ",
      " fg    er    gf ",
      " fg st er    gf ",
      " ueeeewe!   qeu ",
      " ux           y ",
      " uA           B ",
      " uuuuuuuuuuuuuu ",
      "                "
    ],
    [
      "                ",
      "                ",
      "  gggggggggggg  ",
      "  g          g  ",
      "  g    C     g  ",
      "  g    D     g  ",
      "  g          g  ",
      "  g    E     g  ",
      "  eeeeef    fe  ",
      "  g    e     g  ",
      "  gst  eF    g  ",
      " ueeeeIe    feu ",
      " ur           J ",
      " ur           K ",
      " uuLggggggggLuu ",
      "                "
    ],
    [
      "                ",
      "                ",
      "  gggggggggggg  ",
      "  g          g  ",
      "  g          g  ",
      "  g          g  ",
      "  g          g  ",
      "  g          g  ",
      "  eeeeeM    Me  ",
      "  gsN  e     g  ",
      "  gO   e     g  ",
      " ueeeeee    Meu ",
      " ur           P ",
      " ur           Q ",
      " uuLggggggggLuu ",
      "                "
    ],
    [
      "                ",
      "                ",
      "  gggggggggggg  ",
      "  g          g  ",
      "  g          g  ",
      "  g          g  ",
      "  g          g  ",
      "  g          g  ",
      "  eeeee      e  ",
      "  g RN e     g  ",
      "  g    e     g  ",
      " ueeeeee     eu ",
      " ur           u ",
      " ur           u ",
      " uuuuuuuuuuuuuu ",
      "                "
    ],
    [
      "                ",
      " SSSSSSSSSSSSSS ",
      " SSSSSSSSSSSSSS ",
      " SSTTTTTTTTTTSS ",
      " SSTUUUUUUUUTSS ",
      " SSTUUUUUUUUTSS ",
      " SSTUUUUUUUUTSS ",
      " SSTUUUUUUUUTSS ",
      " SSeeeeUUUUUTSS ",
      "  g  RNeUUUUTg  ",
      "  g   VeUUUUTg  ",
      " ueeeeeeUUUUTeu ",
      " urUUUUUUUUUTWu ",
      " urUUUUUUUUUTWu ",
      " uuuuuuuuuuuuuu ",
      "                "
    ]
  ]
}