{
  "name": "multi_courtyardofficetower_5_floor6",
  "refpalette": "deceasedcraft:multi_courtyardofficetower_5/multi_courtyardofficetower_5_floor6_palette",
  "xsize": 16,
  "zsize": 16,
  "slices": [
    [
      "      aaa      b",
      "      aaa      b",
      "      aaa      b",
      "   c  aaa  c   b",
      "      aaa      b",
      "      aaa      b",
      "      aaa      b",
      "      aaa      b",
      "      aaa      b",
      "      aaa      b",
      "      aaa      b",
      "   c  aaa      b",
      "      aaa      b",
      "      aaa      b",
      "      aaa      b",
      "bbbbbbbbbbbbbbbb"
    ],
    [
      "   ddde fddd   e",
      "      e f      e",
      "      e f      e",
      "e  c  e f  c  fe",
      "e     e f     f ",
      "e     e f     f ",
      "e     e f     f ",
      "e     e!f     f ",
      "e     e f     f ",
      "e     e f     f ",
      "e     e f     f ",
      "e  c  e f     fe",
      "      e f      e",
      "      e f      e",
      "   ggge fggg   e",
      "dddd       dddd "
    ],
    [
      "                ",
      "                ",
      "                ",
      "   c       c    ",
      "                ",
      "                ",
      "                ",
      "                ",
      "                ",
      "                ",
      "                ",
      "   c            ",
      "                ",
      "                ",
      "                ",
      "                "
    ],
    [
      "                ",
      "                ",
      "                ",
      "   c       c    ",
      "                ",
      "                ",
      "                ",
      "                ",
      "                ",
      "                ",
      "                ",
      "   c            ",
      "                ",
      "                ",
      "                ",
      "                "
    ],
    [
      "                ",
      "                ",
      "                ",
      "   c       c    ",
      "                ",
      "                ",
      "                ",
      "                ",
      "                ",
      "                ",
      "                ",
      "   c            ",
      "                ",
      "                ",
      "                ",
      "                "
    ],
    [
      "   c           h",
      "   c           h",
      "   c           h",
      "cccccccccccccccc",
      "   c       i   h",
      "   c           h",
      "   c           h",
      "   c           h",
      "   c           h",
      "   c           h",
      "   c           h",
      "   cj          h",
      "   c           h",
      "   c           h",
      "   c           h",
      "hhhchhhhhhhhhhhh"
    ]
  ]
}