{
  "name": "multi_courtyardofficetower_5_floor16",
  "refpalette": "deceasedcraft:multi_courtyardofficetower_5/multi_courtyardofficetower_5_floor16_palette",
  "xsize": 16,
  "zsize": 16,
  "slices": [
    [
      "       aaaa    b",
      "      aaaa     b",
      "     aaaa      b",
      "   caaaa   c   b",
      "   aaaa        b",
      "  aaaa         b",
      " aaaa          b",
      "aaaa           b",
      "aaa            b",
      "aa             b",
      "a              b",
      "   c           b",
      "               b",
      "               b",
      "               b",
      "bbbbbbbbbbbbbbbb"
    ],
    [
      "   dddde  fe   e",
      "     gd  fe    e",
      "    gd  fe     e",
      "e  cd  fe  c  ge",
      "e fe  fe      g ",
      "efe   e       g ",
      "ee  gd        g ",
      "d  gd         g ",
      "  gd          g ",
      " gd           g ",
      "gd            g ",
      "d  c          ge",
      "               e",
      "               e",
      "   fffffffff   e",
      "dddd       dddd "
    ],
    [
      "                ",
      "                ",
      "                ",
      "   c       c    ",
      "                ",
      "                ",
      "                ",
      "                ",
      "                ",
      "                ",
      "                ",
      "   c            ",
      "                ",
      "                ",
      "                ",
      "                "
    ],
    [
      "                ",
      "                ",
      "                ",
      "   c       c    ",
      "                ",
      "                ",
      "                ",
      "                ",
      "                ",
      "                ",
      "                ",
      "   c            ",
      "                ",
      "                ",
      "                ",
      "                "
    ],
    [
      "                ",
      "                ",
      "                ",
      "   c       c    ",
      "                ",
      "                ",
      "                ",
      "                ",
      "                ",
      "                ",
      "                ",
      "   c            ",
      "                ",
      "                ",
      "                ",
      "                "
    ],
    [
      "   c           h",
      "   c           h",
      "   c           h",
      "cccccccccccccccc",
      "   c       i   h",
      "   c           h",
      "   c           h",
      "   c           h",
      "   c           h",
      "   c           h",
      "   c           h",
      "   cj          h",
      "   c           h",
      "   c           h",
      "   c           h",
      "hhhchhhhhhhhhhhh"
    ]
  ]
}