{
  "name": "multi_courtyardofficetower_5_floor14",
  "refpalette": "deceasedcraft:multi_courtyardofficetower_5/multi_courtyardofficetower_5_floor14_palette",
  "xsize": 16,
  "zsize": 16,
  "slices": [
    [
      "               a",
      "               a",
      "               a",
      "   b       b   c",
      "     d  e      a",
      "        ee     a",
      "    d   e      a",
      "   ddd  fff    a",
      "    d  fffff   a",
      "       ffgff   a",
      "     d fffff   a",
      "   b    fff    c",
      "               a",
      "               a",
      "               a",
      "aaacaaaaaaacaaah"
    ],
    [
      "               a",
      "               a",
      "               a",
      "   b       b   c",
      "     e         a",
      "        d      a",
      "               a",
      "   dd          a",
      "    d    f     a",
      "        fgf    a",
      "     e   f     a",
      "   b           c",
      "               a",
      "               a",
      "               a",
      "aaacaaaaaaacaaah"
    ],
    [
      "               a",
      "               a",
      "               a",
      "   b       b   c",
      "               a",
      "        e      a",
      "               a",
      "    d   fff    a",
      "       fffff   a",
      "       ffgff   a",
      "       fffff   a",
      "   b    fff    c",
      "               a",
      "               a",
      "               a",
      "aaacaaaaaaacaaah"
    ],
    [
      "               a",
      "               a",
      "               a",
      "   b       b   c",
      "               a",
      "               a",
      "               a",
      "    d          a",
      "         d     a",
      "        dgd    a",
      "         d     a",
      "   b           c",
      "               a",
      "               a",
      "               a",
      "aaacaaaaaaacaaai"
    ],
    [
      "               a",
      "               a",
      "               a",
      "   b       b   c",
      "               a",
      "               a",
      "               a",
      "               a",
      "               a",
      "         d     a",
      "               a",
      "   b           c",
      "               a",
      "               a",
      "               a",
      "aaacaaaaaaacaaaj"
    ],
    [
      "   b           k",
      "   b           k",
      "   b           k",
      "bbbbbbbbbbbbbbbb",
      "   b       l   k",
      "   b           k",
      "   b           k",
      "   b           k",
      "   b           k",
      "   b     d     k",
      "   b           k",
      "   bm          k",
      "   b           k",
      "   b           k",
      "   b           k",
      "kkkbkkkkkkkkkkkk"
    ]
  ]
}