{
  "name": "multi_courtyardofficetower_5_floor7",
  "refpalette": "deceasedcraft:multi_courtyardofficetower_5/multi_courtyardofficetower_5_floor7_palette",
  "xsize": 16,
  "zsize": 16,
  "slices": [
    [
      "               a",
      "               a",
      "               a",
      "   b       b   a",
      "               a",
      "               a",
      "ccccccccccccccca",
      "ccccccccccccccca",
      "ccccccccccccccca",
      "               a",
      "               a",
      "   b           a",
      "               a",
      "               a",
      "               a",
      "aaaaaaaaaaaaaaaa"
    ],
    [
      "   ddddddddd   e",
      "               e",
      "               e",
      "e  b       b  fe",
      "e             f ",
      "e             f ",
      "ddddddddddddddd ",
      "                ",
      "ggggggggggggggg ",
      "e             f ",
      "e             f ",
      "e  b          fe",
      "               e",
      "               e",
      "   ggggggggg   e",
      "dddd       dddd "
    ],
    [
      "                ",
      "                ",
      "                ",
      "   b       b    ",
      "                ",
      "                ",
      "                ",
      "                ",
      "                ",
      "                ",
      "                ",
      "   b            ",
      "                ",
      "                ",
      "                ",
      "                "
    ],
    [
      "                ",
      "                ",
      "                ",
      "   b       b    ",
      "                ",
      "                ",
      "                ",
      "                ",
      "                ",
      "                ",
      "                ",
      "   b            ",
      "                ",
      "                ",
      "                ",
      "                "
    ],
    [
      "                ",
      "                ",
      "                ",
      "   b       b    ",
      "                ",
      "                ",
      "                ",
      "                ",
      "                ",
      "                ",
      "                ",
      "   b            ",
      "                ",
      "                ",
      "                ",
      "                "
    ],
    [
      "   b           h",
      "   b           h",
      "   b           h",
      "bbbbbbbbbbbbbbbb",
      "   b       i   h",
      "   b           h",
      "   b           h",
      "   b           h",
      "   b           h",
      "   b           h",
      "   b           h",
      "   bj          h",
      "   b           h",
      "   b           h",
      "   b           h",
      "hhhbhhhhhhhhhhhh"
    ]
  ]
}