{
  "name": "multi_courtyardofficetower_5_floor18",
  "refpalette": "deceasedcraft:multi_courtyardofficetower_5/multi_courtyardofficetower_5_floor18_palette",
  "xsize": 16,
  "zsize": 16,
  "slices": [
    [
      "               a",
      "               a",
      "               a",
      "   b       b   a",
      "              ca",
      "             cca",
      "            ccca",
      "           cccca",
      "          cccc a",
      "         cccc  a",
      "        cccc   a",
      "   b   cccc    a",
      "      cccc     a",
      "     cccc      a",
      "    cccc       a",
      "aaaaaaaaaaaaaaaa"
    ],
    [
      "   ddddddddd   e",
      "               e",
      "               e",
      "e  b       b  fe",
      "e            fe ",
      "e           fe  ",
      "e          fe   ",
      "e         fe  f ",
      "e        fe  fee",
      "e       g   fe e",
      "e      gd  fe  e",
      "e  b  gd  g    e",
      "     gd  gd   ca",
      "    gd  gd    ca",
      "   gd  gd      e",
      "dddd    ddddddd "
    ],
    [
      "                ",
      "                ",
      "                ",
      "   b       b    ",
      "                ",
      "                ",
      "                ",
      "                ",
      "                ",
      "                ",
      "                ",
      "   b          ff",
      "             gh ",
      "             ah ",
      "            ccad",
      "                "
    ],
    [
      "                ",
      "                ",
      "                ",
      "   b       b    ",
      "                ",
      "                ",
      "                ",
      "                ",
      "                ",
      "                ",
      "                ",
      "   b            ",
      "             f  ",
      "            fe  ",
      "           ghh e",
      "            aad "
    ],
    [
      "                ",
      "                ",
      "                ",
      "   b       b    ",
      "                ",
      "                ",
      "                ",
      "                ",
      "                ",
      "                ",
      "                ",
      "   b            ",
      "                ",
      "                ",
      "                ",
      "           g  e "
    ],
    [
      "                ",
      "                ",
      "                ",
      "   b       b    ",
      "                ",
      "                ",
      "                ",
      "                ",
      "                ",
      "                ",
      "                ",
      "   b            ",
      "                ",
      "                ",
      "                ",
      "              f "
    ]
  ]
}