{
  "name": "multi_courtyardofficetower_5_floor13",
  "refpalette": "deceasedcraft:multi_courtyardofficetower_5/multi_courtyardofficetower_5_floor13_palette",
  "xsize": 16,
  "zsize": 16,
  "slices": [
    [
      "aaaaaaaaaaaaaaab",
      "aaaaaaaaaaaaaaab",
      "aaaaaaaaaaaaaaab",
      "aaacaaaaaaacaaab",
      "aaaaaaaaaaaaaaab",
      "aaaaaaaaaaaaaaab",
      "aaaaaaaaaaaaaaab",
      "aaaaaaaaaaaaaaab",
      "aaaaaaaaaaaaaaab",
      "aaaaaaaaadaaaaab",
      "aaaaaaaaaaaaaaab",
      "aaacaaaaaaaaaaab",
      "aaaaaaaaaaaaaaab",
      "aaaaaaaaaaaaaaab",
      "aaaaaaaaaaaaaaab",
      "bbbbbbbbbbbbbbbe"
    ],
    [
      "               f",
      "   ggggg gggg  f",
      "  hiiiiiiiiihg f",
      " gicaaaaaaacig j",
      " giaaaaaaaaai  f",
      " giaaaaaaaaaig f",
      " giaaaaaaaaaig f",
      " giaaaaaaaaaig f",
      " giaaaaaaaaaig f",
      " giaaaaaadaaig f",
      " giaaaaaaaaaig f",
      " gicaaaaaaaaig j",
      "  hiiiiiiiiihg f",
      "  ggg gggg gg  f",
      "               f",
      "fffjfffffffjfffk"
    ],
    [
      "               f",
      "               f",
      "   iiiiii ii   f",
      "  icggg gggci  j",
      "  ig lii ilgi  f",
      "  igih il igi  f",
      "   g ii iihgi  f",
      "  igm i i i    f",
      "  igiihi   gi  f",
      "  igi i  n gi  f",
      "  ig li h igi  f",
      "  icgggg gggi  j",
      "   iiiiii ii   f",
      "               f",
      "               f",
      "fffjfffffffjfffi"
    ],
    [
      "               f",
      "               f",
      "    i ii  i    f",
      "  ic       ci  j",
      "  i  k    k i  f",
      "        k      f",
      "          ! i  f",
      "  i o          f",
      "  i      p     f",
      "        pnp    f",
      "  i  k   p     f",
      "  ic           j",
      "   i i         f",
      "               f",
      "               f",
      "fffjfffffffjfffi"
    ],
    [
      "               f",
      "               f",
      "               f",
      "   c q     c   j",
      "    qqq q i    f",
      "     q qqq     f",
      "               f",
      "    k   ppp    f",
      "       ppppp   f",
      "     q ppnpp   f",
      "    qqqppppp   f",
      "   c q  ppp    j",
      "               f",
      "               f",
      "               f",
      "fffjfffffffjfff "
    ],
    [
      "               f",
      "               f",
      "               f",
      "   c q     c   j",
      "    qqq q i    f",
      "     q qqq     f",
      "    i   q      f",
      "   ii          f",
      "         p     f",
      "     q  pnp    f",
      "    qqq  p     f",
      "   c q         j",
      "               f",
      "               f",
      "               f",
      "fffjfffffffjfff "
    ]
  ]
}