{
  "name": "multi_courtyardofficetower_5_ground",
  "refpalette": "deceasedcraft:multi_courtyardofficetower_5/multi_courtyardofficetower_5_ground_palette",
  "xsize": 16,
  "zsize": 16,
  "slices": [
    [
      "aaaaaaaaaaaabccb",
      "aaaaaaaaaaaaabcc",
      "daaaaaaaaaaaaabc",
      "aaaeaaaaaaaeaaab",
      "aaaaaaafaaaaaaab",
      "aaaaaaaaagggggaa",
      "aaaaaaaggghh ggg",
      "daaaaaggh     ig",
      "aaaaaagi hh h   ",
      "aaaaagg  h    hh",
      "aaaaagh  h   h b",
      "aaaeaghh   j   b",
      "aaaaagk  h h hbc",
      "aaaaagg h    bcc",
      "adaaaag   h bccb",
      "aaaaaagg   bccba"
    ],
    [
      "h    h    h     ",
      " h              ",
      "    h     h     ",
      "   eh    h ehh  ",
      " h     j    h   ",
      " h  hh          ",
      "                ",
      "    h         h ",
      " l     h h      ",
      "h  h           h",
      "   h            ",
      "   e       j    ",
      "      i         ",
      "   h            ",
      "   hh     h     ",
      "k               "
    ],
    [
      "     h          ",
      "                ",
      "                ",
      "   e       eh   ",
      "       j        ",
      " h              ",
      "                ",
      "              m ",
      " n     m        ",
      "                ",
      "           h    ",
      "   e      hjh   ",
      "      h    h    ",
      "   h            ",
      "                ",
      "i               "
    ],
    [
      "                ",
      "                ",
      "      ooo       ",
      "   e ooooo e    ",
      "     oojoo      ",
      "     hoooo      ",
      "      ooo       ",
      "                ",
      " i       hhhhh  ",
      "        hhhhhhh ",
      "        hhhhhhh ",
      "   e    hhhjhhh ",
      "      h hhhhhhh ",
      "        hhhhhhh ",
      "         hhhhh  ",
      "h               "
    ],
    [
      "                ",
      "                ",
      "                ",
      "   e   o   e    ",
      "      ojo       ",
      "       o        ",
      "                ",
      "                ",
      " h         h    ",
      "         hhhhh  ",
      "         hhhhh  ",
      "   e    hhhjhhh ",
      "      m  hhhhh  ",
      "         hhhh   ",
      "           h    ",
      "h               "
    ],
    [
      "                ",
      "                ",
      "      ooo       ",
      "   e ooooo e    ",
      "     oojoo      ",
      "     hoooo      ",
      "      ooo       ",
      " m              ",
      "hh              ",
      " h              ",
      "          hhh   ",
      "   e      hjh   ",
      "          hhh   ",
      "                ",
      "                ",
      "h               "
    ]
  ]
}