{
  "name": "park_12",
  "refpalette": "deceasedcraft:parks/park_12_palette",
  "xsize": 16,
  "zsize": 16,
  "slices": [
    [
      "aaaaabccccdaaaaa",
      "aeeeeeeeeeeeeeea",
      "aeeeeeeeeeeeeeea",
      "aeeeeeeeeeeeeeea",
      "aeeeaffffffaeeea",
      "geeehijjjjikeeeg",
      "ceeehjjjjjjkeeec",
      "ceeehjjjjjjkeeec",
      "ceeehjjjjjjkeeec",
      "ceeehjjjjjjkeeec",
      "leeehijjjjikeeel",
      "aeeeammmmmmaeeea",
      "aeeeeeeeeeeeeeea",
      "aeeeeeeeeeeeeeea",
      "aeeeeeeeeeeeeeea",
      "aaaaabccccdaaaaa"
    ],
    [
      "    n      n    ",
      "                ",
      "                ",
      "                ",
      "n              n",
      "     oopqoo     ",
      "     opr qo     ",
      "     qs psr     ",
      "     prq r      ",
      "     oqrspo     ",
      "     oopqoo     ",
      "n              n",
      "                ",
      "                ",
      "                ",
      "    n      n    "
    ],
    [
      "    t      t    ",
      "                ",
      "                ",
      "                ",
      "t              t",
      "                ",
      "                ",
      "                ",
      "                ",
      "                ",
      "                ",
      "t              t",
      "                ",
      "                ",
      "                ",
      "    t      t    "
    ],
    [
      "    t      t    ",
      "                ",
      "                ",
      "                ",
      "t              t",
      "                ",
      "                ",
      "                ",
      "                ",
      "                ",
      "                ",
      "t              t",
      "                ",
      "                ",
      "                ",
      "    t      t    "
    ],
    [
      "    t      t    ",
      "    u      w    ",
      "    x      x    ",
      "                ",
      "twy          Aut",
      "                ",
      "                ",
      "                ",
      "                ",
      "                ",
      "                ",
      "tuy          Awt",
      "                ",
      "    B      B    ",
      "    u      w    ",
      "    t      t    "
    ],
    [
      "    C      C    ",
      "    D      D    ",
      "                ",
      "                ",
      "ED            DF",
      "                ",
      "                ",
      "                ",
      "                ",
      "                ",
      "                ",
      "ED            DF",
      "                ",
      "                ",
      "    D      D    ",
      "    I      I    "
    ]
  ]
}