{
  "name": "park_10",
  "refpalette": "deceasedcraft:parks/park_10_palette",
  "xsize": 16,
  "zsize": 16,
  "slices": [
    [
      "aaaaaaabbaaaaaaa",
      "acdddcabbacdddca",
      "aefffeabbaefffea",
      "aegggeabbaegggea",
      "aegggeabbaegggea",
      "achhhcabbachhhca",
      "aaaaaaabbaaaaaaa",
      "bbbbbbbbbbbbbbbb",
      "bbbbbbbbbbbbbbbb",
      "aaaaaaabbaaaaaaa",
      "aciiicabbaciiica",
      "aegggeabbaegggea",
      "aegggeabbaegggea",
      "aefffeabbaefffea",
      "acdddcabbacdddca",
      "aaaaaaabbaaaaaaa"
    ],
    [
      "                ",
      " jjjjj    jjjjj ",
      " j  kj    jlk j ",
      " jmnoj    jnomj ",
      " j   j    j   j ",
      " j   j    j   j ",
      "                ",
      "                ",
      "                ",
      "                ",
      " j   j    j   j ",
      " j   j    j   j ",
      " jmpqj    jpqmj ",
      " jk rj    jk lj ",
      " jjjjj    jjjjj ",
      "                "
    ],
    [
      "                ",
      "                ",
      "    ~       ~   ",
      "                ",
      "                ",
      "                ",
      "                ",
      "                ",
      "                ",
      "                ",
      "                ",
      "                ",
      "             s  ",
      "  ~        ~    ",
      "                ",
      "                "
    ]
  ]
}