{
  "name": "park_11",
  "refpalette": "deceasedcraft:parks/park_11_palette",
  "xsize": 16,
  "zsize": 16,
  "slices": [
    [
      "vaaaavvvvvvaaaav",
      "bccccccccccccccd",
      "bccccvvvvvvccccd",
      "bccccveeeevccccd",
      "bccccveffevccccd",
      "vcvvvveffevvvvvv",
      "vcveeeeffeeeeghh",
      "vcvefffffffffijj",
      "vcvefffffffffijj",
      "vcveeeeffeeeeghh",
      "vcvvvveffevvvvvv",
      "bccccveffevccccd",
      "bccccveeeevccccd",
      "bccccvvvvvvccccd",
      "bccccccccccccccd",
      "vkkkkvvvvvvkkkkv"
    ],
    [
      "vllllvmvvmvllllv",
      "ncccccccccccccco",
      "nccccvvvvvvcccco",
      "nccccvppppvcccco",
      "nccccvpffpvcccco",
      "vcvvvveffevvvvvv",
      "mcvppeeffeeeg   ",
      "vcvpffffffffi   ",
      "vcvpffffffffi   ",
      "mcvppeeffeeeg   ",
      "vcvvvveffevvvvvv",
      "nccccvpffpvcccco",
      "nccccvppppvcccco",
      "nccccvvvvvvcccco",
      "ncccccccccccccco",
      "vqqqqvmvvmvqqqqv"
    ],
    [
      "vvvvvvvvvvvvvvvv",
      "vrpppppppppppprv",
      "vppppvvvvvvppppv",
      "vppppvssssvppppv",
      "vppppvstusvppppv",
      "vpvvvv    vvvvvv",
      "vpvss      v    ",
      "vpvsw           ",
      "vpvsx           ",
      "vpvss      v    ",
      "vpvvvv    vvvvvv",
      "vppppvsyAsvppppv",
      "vppppvssssvppppv",
      "vppppvvvvvvppppv",
      "vrpppppppppppprv",
      "vvvvvvvvvvvvvvvv"
    ],
    [
      "                ",
      " BBBCDE D C BBB ",
      " B  C      CC B ",
      " BCF       CFCB ",
      "  CC        C   ",
      " C              ",
      " E         I    ",
      " D              ",
      "                ",
      " J         I    ",
      " K              ",
      "  K          C  ",
      " B L       CFCB ",
      " BKK          B ",
      " BBBKJ EDJCCBBB ",
      "                "
    ],
    [
      "                ",
      "                ",
      "                ",
      "   ~        ~   ",
      "                ",
      "                ",
      "                ",
      "                ",
      "                ",
      "                ",
      "                ",
      "                ",
      "   ~        ~   ",
      "                ",
      "                ",
      "                "
    ]
  ]
}