{
  "name": "park_5",
  "refpalette": "deceasedcraft:parks/park_5_palette",
  "xsize": 16,
  "zsize": 16,
  "slices": [
    [
      "aaaaaaaaaaaaaaaa",
      "abbbbbbcbbbbbbba",
      "abbbcccccbccbbba",
      "abbcbcdbbdbbcbba",
      "abbccbeeeebcbbba",
      "abccbeffffebccba",
      "abcdeffffffedcba",
      "acbbeffffffebbca",
      "accbeffffffebcca",
      "abcdeffffffedcba",
      "abbcbeffffebccba",
      "abbbcbeeeebcccba",
      "abbcccdbbdcccbba",
      "abbbcbccccccbbba",
      "abbbbbbccbbbbbba",
      "aaaaaaaaaaaaaaaa"
    ],
    [
      "                ",
      "   g        h   ",
      "              i ",
      " ii   jjjj   i  ",
      "     jffffj     ",
      "    jfkffkfj    ",
      " h jfkfkkfkf    ",
      "   jffkkkkffj   ",
      "   jffkkkkffj   ",
      "   jfkfkkfkfj h ",
      "    jfkffkfj    ",
      "      ffffj     ",
      " i    jj j    g ",
      "             li ",
      " hil        hg  ",
      "                "
    ],
    [
      "                ",
      "                ",
      "                ",
      "                ",
      "      aaaa      ",
      "                ",
      "    a m  m a    ",
      "    a      a    ",
      "    a      a    ",
      "    a m  m a    ",
      "                ",
      "      aaaa      ",
      "                ",
      "             n  ",
      "   n            ",
      "                "
    ]
  ]
}