{
  "name": "park_deadzone_4",
  "refpalette": "deceasedcraft:parks/park_deadzone_4_palette",
  "xsize": 16,
  "zsize": 16,
  "slices": [
    [
      "                ",
      "                ",
      "     aaaaaa     ",
      "   aabbbbbbaa   ",
      "   abbcdddbba   ",
      "  abbdddeddbba  ",
      "  abde zz deba  ",
      "  abddzzzzddba  ",
      "  abdczzczedba  ",
      "  abdd zz ddba  ",
      "  abbddedddbba  ",
      "   abbdddcbba   ",
      "   aabbbbbbaa   ",
      "     aaaaaa     ",
      "                ",
      "                "
    ],
    [
      "                ",
      "                ",
      "                ",
      "                ",
      "       cff      ",
      "     ff  ff     ",
      "       cg f     ",
      "    c  gcg f    ",
      "    f gcc  f    ",
      "    ff cg cf    ",
      "     ff cff     ",
      "      fff       ",
      "                ",
      "                ",
      "                ",
      "                "
    ],
    [
      "                ",
      "                ",
      "                ",
      "                ",
      "        ff      ",
      "     f   ff     ",
      "    ff    ff    ",
      "    f      f    ",
      "    f      f    ",
      "    ff          ",
      "     ff         ",
      "      ff        ",
      "                ",
      "                ",
      "                ",
      "                "
    ]
  ]
}