{
  "name": "park_8",
  "refpalette": "deceasedcraft:parks/park_8_palette",
  "xsize": 16,
  "zsize": 16,
  "slices": [
    [
      "aaaaaaaaaaaaaaaa",
      "abbbcccccccccbba",
      "abddceeeeeeecdda",
      "afffffeeeeeecdda",
      "afeeefeeeeeecdda",
      "afeeegeeeegecdda",
      "afeeefeeeeeecdda",
      "afehhhhheeeecdda",
      "afeheeehffffffda",
      "affheeeheeeeefda",
      "abihegeheegeefda",
      "abgheeeheeeeefda",
      "abghhhhheeeeefba",
      "abgeeeefeeeeefba",
      "abigggifffffffba",
      "aaaaaaaaaaaaaaaa"
    ],
    [
      "                ",
      "    ccccccccc   ",
      "    cjjjjjjjc   ",
      " kffffjjjjjjc   ",
      " keeeljjjjjjc   ",
      " keeegjjjjgjc   ",
      " keeefjjjjjjc   ",
      " kehhhhhjjjjc   ",
      " keheeehflffff  ",
      " kkheeeheeeeef  ",
      "  mhegeheegeef  ",
      "  mheeeheeeeef  ",
      "  mhhhhheeeeek  ",
      "  m    keeeeek  ",
      "  mmmmmkkkkkkk  ",
      "                "
    ],
    [
      "                ",
      "                ",
      "                ",
      " fffff          ",
      " fjjjno         ",
      " fjjjg    g     ",
      " fjjjf          ",
      " fjhlhhh o      ",
      " fjheeehfnffff  ",
      " ffheeehjjjjjf  ",
      "   hegehjjgjjf  ",
      "   heeeljjjjjf  ",
      "   hhhhhjjjjjf  ",
      "       fjjjjjf  ",
      "       fffffff  ",
      "                "
    ],
    [
      "                ",
      "                ",
      "                ",
      "                ",
      "                ",
      "     g    g     ",
      "    o           ",
      "   hnhhh        ",
      "   hjjjhkkkkkk  ",
      "   hjjjh     k  ",
      "   hjgjh  g  k  ",
      "   hjjjno    k  ",
      "   hhhhh     k  ",
      "       k     k  ",
      "       kkkkkkk  ",
      "                "
    ],
    [
      "                ",
      "                ",
      "                ",
      "                ",
      "                ",
      "     g    g     ",
      "                ",
      "                ",
      "                ",
      "                ",
      "     g    g     ",
      "                ",
      "                ",
      "                ",
      "                ",
      "                "
    ],
    [
      "                ",
      "                ",
      "                ",
      "                ",
      "                ",
      "     pppppp     ",
      "     p    p     ",
      "     p    p     ",
      "     p    p     ",
      "     p    p     ",
      "     pppppp     ",
      "                ",
      "                ",
      "                ",
      "                ",
      "                "
    ]
  ]
}