{
  "name": "park_deadzone_10",
  "refpalette": "deceasedcraft:parks/park_deadzone_10_palette",
  "xsize": 16,
  "zsize": 16,
  "slices": [
    [
      "  aa aaaa aa  aa",
      "ababzbabbzzbaa a",
      " bbzbbzbbzbbaza ",
      "azbzzzbzzbzzzbaa",
      "abzzzzzzzzzzbbb ",
      "aabzzzzzzzzzzzb ",
      "azzzzzzzzzzzzbza",
      "azzbzzzzzzzzzbba",
      "azbzzzczzzzzbzaa",
      "azbzzd@dzzzzzbza",
      " bzbzzczzzzzzzz ",
      "abbzzbzzzzzzzbba",
      "aazbbbzzzbzbbza ",
      "aaabzbbzbzbbzbb ",
      " aaabazbzabzaaa ",
      "a  a  aaaaa  a  "
    ],
    [
      "                ",
      "    ef   e      ",
      "  f   e         ",
      " g hij ee  e    ",
      "  iiii azz      ",
      "  i z bzaa  ee  ",
      " eef zzbbzaz  e ",
      "    zbzzbbzze   ",
      "   ezdddbbz     ",
      " e ezdkdbzzz    ",
      "     dddzzae e  ",
      "   ee azbze e   ",
      "  e    ez       ",
      "    e           ",
      "                ",
      "                "
    ],
    [
      "                ",
      "                ",
      "   h            ",
      "   h            ",
      "    i    e      ",
      "    i le        ",
      "     e          ",
      "     mn         ",
      "    eopo  e     ",
      "    ep p  e     ",
      "     opoe       ",
      "         e      ",
      "                ",
      "                ",
      "                ",
      "                "
    ],
    [
      "                ",
      "   h            ",
      "                ",
      "   h            ",
      "                ",
      "                ",
      "      q         ",
      "      n         ",
      "     oro        ",
      "      s         ",
      "     o o        ",
      "                ",
      "                ",
      "                ",
      "                ",
      "                "
    ],
    [
      "                ",
      "   t            ",
      "                ",
      "   l            ",
      "   h            ",
      "                ",
      "                ",
      "                ",
      "     pup        ",
      "     usu        ",
      "     pup        ",
      "                ",
      "                ",
      "                ",
      "                ",
      "                "
    ],
    [
      "                ",
      "                ",
      "                ",
      "                ",
      "   h            ",
      "                ",
      "                ",
      "                ",
      "                ",
      "      p         ",
      "                ",
      "                ",
      "                ",
      "                ",
      "                ",
      "                "
    ]
  ]
}