{
  "name": "park_6",
  "refpalette": "deceasedcraft:parks/park_6_palette",
  "xsize": 16,
  "zsize": 16,
  "slices": [
    [
      "aaaaaaaaaaaaaaaa",
      "abbbbbbbbbbbbbba",
      "abbbbbbbbbbccbba",
      "abbcccccbbbbbdba",
      "abbccccccbdbdbba",
      "abbccccccdddbbba",
      "abbccccccdbddbba",
      "abbcccccbbddbbba",
      "abbbbbbbbbddbbba",
      "abbbbbbbbbdddbba",
      "abbbbbbbbbbddbba",
      "abbbbbbbbbbddbba",
      "abbbbbbbbbbddbba",
      "abbbbbbbbbddbbba",
      "abbbbbbbbbbddbba",
      "aaaaaaaaaaaaaaaa"
    ],
    [
      "                ",
      "   ef  gf  hh   ",
      "  iiiiiii jkkl  ",
      " minnnnnio pp   ",
      " ginqqqna       ",
      "  inqqqna    r  ",
      " oinqqqna       ",
      "  innnnnie  ee  ",
      " eiiiiiiif    r ",
      " o efo mor   e  ",
      " s gs s         ",
      "   sss  te      ",
      "  s us  e       ",
      "    s  s     r  ",
      " es   r   r     ",
      "                "
    ],
    [
      "                ",
      "                ",
      "            w   ",
      "   xxxxx        ",
      "   x yAx        ",
      "   xB           ",
      "   xC  x        ",
      "   xxxxx        ",
      "                ",
      "                ",
      "                ",
      "                ",
      "    ~           ",
      "                ",
      "                ",
      "                "
    ],
    [
      "                ",
      "                ",
      "   DDDDD        ",
      "     x          ",
      "    E           ",
      "                ",
      "                ",
      "     x          ",
      "   FFFFF        ",
      "                ",
      "                ",
      "                ",
      "                ",
      "                ",
      "                ",
      "                "
    ],
    [
      "                ",
      "                ",
      "                ",
      "   DDDDD        ",
      "   II  I        ",
      "   IIIII        ",
      "   II  I        ",
      "   FFFFF        ",
      "                ",
      "                ",
      "                ",
      "                ",
      "                ",
      "                ",
      "                ",
      "                "
    ],
    [
      "                ",
      "                ",
      "                ",
      "                ",
      "   JJJJJ        ",
      "   J   J        ",
      "   JJJJJ        ",
      "                ",
      "                ",
      "                ",
      "                ",
      "                ",
      "                ",
      "                ",
      "                ",
      "                "
    ]
  ]
}