{
  "name": "multi_courtyardofficetower_6_floor8",
  "refpalette": "deceasedcraft:multi_courtyardofficetower_6/multi_courtyardofficetower_6_floor8_palette",
  "xsize": 16,
  "zsize": 16,
  "slices": [
    [
      "aaaaaaaaaaaaaaaa",
      "aaaaaaaaaaaaaaaa",
      "aaaaaaaaaaaaaaaa",
      "aaabaaaaaaabaaaa",
      "caaaaaaaaaaaaaaa",
      "dcaaaaaaaaaaaaaa",
      "ddcaaaaaaaaaaaaa",
      "ddcaaaaaaaaaaaaa",
      "dddcaaaaaaaaaaaa",
      "dddcaaaaaaaaaaaa",
      "dddcaaaaaaaaaaaa",
      "eeebaaaaaaabaaaa",
      "   beeeeeeebaaaa",
      "   b   f   beeee",
      "   b       b   f",
      "   b       b    "
    ],
    [
      "                ",
      "                ",
      "                ",
      "   bgggggggb h h",
      "      ijk    l l",
      "             h h",
      "             m m",
      "             h h",
      " n           m m",
      "                ",
      "o    p   p g    ",
      "qqrbstuwstub    ",
      "   brqqqqqrbx   ",
      "   b   f   brqqq",
      "   b       b   f",
      "   b       b    "
    ],
    [
      "                ",
      "                ",
      "                ",
      "   byyyyyyyb    ",
      "                ",
      "                ",
      "                ",
      "                ",
      "                ",
      "                ",
      "           A    ",
      "qqrbBC  BC b    ",
      "   brqqqqqrb    ",
      "   b   f   brqqq",
      "   b       b   f",
      "   b       b    "
    ],
    [
      "                ",
      "                ",
      "                ",
      "   byyyyyyyb    ",
      "                ",
      "                ",
      "                ",
      "                ",
      "                ",
      "                ",
      "           D    ",
      "qqrb       b    ",
      "   brqqqqqrbEFFF",
      "   b   f   brqqq",
      "   b       b   f",
      "   b       b    "
    ],
    [
      "                ",
      "                ",
      "                ",
      "   b       b    ",
      "                ",
      "                ",
      "                ",
      "                ",
      "                ",
      "                ",
      "                ",
      "qqrb       b    ",
      "   brqqqqqrbIJJJ",
      "   b   f   brqqq",
      "   b       b   f",
      "   b       b    "
    ],
    [
      "                ",
      "                ",
      "                ",
      "   b       b    ",
      "                ",
      "                ",
      "                ",
      "                ",
      "                ",
      "                ",
      "                ",
      "qqrb       b    ",
      "   brqqqqqrb!KKK",
      "   b   f   brqqq",
      "   b       b   f",
      "   b       b    "
    ]
  ]
}