{
  "name": "multi_courtyardofficetower_6_floor20",
  "refpalette": "deceasedcraft:multi_courtyardofficetower_6/multi_courtyardofficetower_6_floor20_palette",
  "xsize": 16,
  "zsize": 16,
  "slices": [
    [
      "aaab       cdde ",
      "aaab        bb  ",
      "aaab        bb  ",
      "aaafbbbbbbbbbbbb",
      "aaaaaaaaaaaaaaaa",
      "aaaaaaaaaaaaaaaa",
      "aaaaaaaaaaaaaaaa",
      "aaaaaaaaaaaaaaaa",
      "aaaaaaaaaaaaaaaa",
      "aaaaaaaaaaaaaaaa",
      "ggghaaaaaaahaaaa",
      "iijfgggggggfaaaa",
      "   fjiiiiijfgggg",
      "   f   k   fjiii",
      "   f       f   k",
      "   f       f    "
    ],
    [
      "d  c            ",
      "d  c       c  e ",
      "l  c       c  e ",
      "   fmmmmmmmm  mm",
      "n               ",
      "                ",
      "  o             ",
      " pqn  o         ",
      "  r  pqn        ",
      "      r         ",
      "ssst       t u u",
      "kkwfsssssssfxyyy",
      "   fwkkkkkwfssss",
      "   f   k   fwkkk",
      "   f       f   k",
      "   f       f    "
    ],
    [
      "                ",
      "                ",
      "                ",
      "   f            ",
      "                ",
      "                ",
      "                ",
      "  A             ",
      "      B         ",
      "                ",
      "   C       C    ",
      "   f       f A D",
      "   f       f    ",
      "   f       f    ",
      "   f       f    ",
      "   f       f    "
    ],
    [
      "                ",
      "                ",
      "                ",
      "   f            ",
      "                ",
      "                ",
      "                ",
      "                ",
      "                ",
      "                ",
      "   E       E    ",
      "   f       f    ",
      "   f       f    ",
      "   f       f    ",
      "   f       f    ",
      "   f       f    "
    ],
    [
      "                ",
      "                ",
      "                ",
      "   f            ",
      "                ",
      "                ",
      "                ",
      "                ",
      "                ",
      "                ",
      "   E       E    ",
      "   f       f    ",
      "   f       f    ",
      "   f       f    ",
      "   f       f    ",
      "   f       f    "
    ],
    [
      "                ",
      "                ",
      "                ",
      "   f            ",
      "                ",
      "                ",
      "                ",
      "                ",
      "                ",
      "                ",
      "   F       F    ",
      "   f       f    ",
      "   f       f    ",
      "   f       f    ",
      "   f       f    ",
      "   f       f    "
    ]
  ]
}