{
  "name": "multi_courtyardofficetower_6_floor19",
  "refpalette": "deceasedcraft:multi_courtyardofficetower_6/multi_courtyardofficetower_6_floor19_palette",
  "xsize": 16,
  "zsize": 16,
  "slices": [
    [
      "               a",
      "                ",
      "                ",
      "   b       b   c",
      "   d       d    ",
      "   e       e    ",
      "   e       e    ",
      "   f       f    ",
      "   e       e    ",
      "   e       e    ",
      "   g       g    ",
      "hhib       b    ",
      "   bihhhhhib    ",
      "   b   j   bihhh",
      "   b       b   j",
      "   b       b    "
    ],
    [
      "               k",
      "                ",
      "                ",
      "   b       b    ",
      "                ",
      "                ",
      "                ",
      "                ",
      "                ",
      "                ",
      "                ",
      "hhib       b    ",
      "   bihhhhhib    ",
      "   b   j   bihhh",
      "   b       b   j",
      "   b       b    "
    ],
    [
      "                ",
      "                ",
      "                ",
      "   b       b    ",
      "                ",
      "                ",
      "                ",
      "                ",
      "                ",
      "                ",
      "                ",
      "hhib       b    ",
      "   bihhhhhib    ",
      "   b   j   bihhh",
      "   b       b   j",
      "   b       b    "
    ],
    [
      "                ",
      "                ",
      "                ",
      "   b       b    ",
      "                ",
      "                ",
      "                ",
      "                ",
      "                ",
      "                ",
      "                ",
      "hhib       b    ",
      "   bihhhhhib    ",
      "   b   j   bihhh",
      "   b       b   j",
      "   b       b    "
    ],
    [
      "                ",
      "                ",
      "                ",
      "   b       b    ",
      "                ",
      "                ",
      "                ",
      "                ",
      "                ",
      "                ",
      "                ",
      "hhib       b    ",
      "   bihhhhhib    ",
      "   b   j   bihhh",
      "   b       b   j",
      "   b       b    "
    ],
    [
      "lllb        mm  ",
      "lnlb            ",
      "lllb       o    ",
      "bbbbbbbbbbbbbbbb",
      "lllbllllllllllll",
      "lnlblnlllnlllnll",
      "lllbllllllllllll",
      "lllbllllllllllll",
      "lllbllllllllllll",
      "lnlblnlllnlllnll",
      "lllbllllllllllll",
      "hhiblllllllbllll",
      "   bihhhhhibllll",
      "   b   j   bihhh",
      "   b       b   j",
      "   b       b    "
    ]
  ]
}