{
  "name": "multi_courtyardofficetower_6_floor15",
  "refpalette": "deceasedcraft:multi_courtyardofficetower_6/multi_courtyardofficetower_6_floor15_palette",
  "xsize": 16,
  "zsize": 16,
  "slices": [
    [
      "aaaaaaaaaaaaaaaa",
      "aaaaaaaaaaaaaaaa",
      "aaaaaaaaaaaaaaaa",
      "bbbcaaaaaaacaaaa",
      "dddbaaaaaaaaaaaa",
      "dddbaaaaaaaaaaaa",
      "dddbaaaaaaaaaaaa",
      "dddbaaaaaaaaaaaa",
      "dddbaaaaaaaaaaaa",
      "dddbaaaaaaaaaaaa",
      "dddbaaaaaaaaaaaa",
      "bbbcaaaaaaacaaaa",
      "   cbbbbbbbcaaaa",
      "   c   e   cbbbb",
      "   c       c   e",
      "   c       c    "
    ],
    [
      "                ",
      "          fgh   ",
      "ijk      lllll  ",
      "mmmc     nocon  ",
      "p qm      rqst  ",
      " u m     wxqy   ",
      "  Am      BqC   ",
      "   m            ",
      "   D            ",
      "   E            ",
      "   m            ",
      "FFIcJKLLLKMc N O",
      "   cIFFFFFIcPQQQ",
      "   c   e   cIFFF",
      "   c       c   e",
      "   c       c    "
    ],
    [
      "                ",
      "                ",
      "         RRRRR  ",
      "mmmc     STcU   ",
      "  Vm      WVX   ",
      "   m      YVZ   ",
      "   m      0V1   ",
      "   m            ",
      "   2            ",
      "   3            ",
      "   m            ",
      "FFIc4567455c    ",
      "   cIFFFFFIc    ",
      "   c   e   cIFFF",
      "   c       c   e",
      "   c       c    "
    ],
    [
      "                ",
      "                ",
      "                ",
      "mmmc       c    ",
      "  8m            ",
      "   m            ",
      "   m            ",
      "   m            ",
      "   9            ",
      "   #            ",
      "   m            ",
      "FFIc       c    ",
      "   cIFFFFFIc    ",
      "   c   e   cIFFF",
      "   c       c   e",
      "   c       c    "
    ],
    [
      "                ",
      "                ",
      "                ",
      "mmmc       c    ",
      "   m            ",
      "   m            ",
      "   m            ",
      "   m            ",
      "   m            ",
      "   m            ",
      "   m            ",
      "FFIc       c    ",
      "   cIFFFFFIc    ",
      "   c   e   cIFFF",
      "   c       c   e",
      "   c       c    "
    ],
    [
      "$$$c$$$$$$$$$$$$",
      "$%$c$%$$$%$$$%$$",
      "$$$c$$$$$$$$$$$$",
      "cccccccccccccccc",
      "$$$c$$$$$$$$$$$$",
      "$%$c$%$$$%$$$%$$",
      "$$$c$$$$$$$$$$$$",
      "$$$c$$$$$$$$$$$$",
      "$$$c$$$$$$$$$$$$",
      "$%$c$%$$$%$$$%$$",
      "$$$c$$$$$$$$$$$$",
      "FFIc$$$$$$$c$$$$",
      "   cIFFFFFIc$$$$",
      "   c   e   cIFFF",
      "   c       c   e",
      "   c       c    "
    ]
  ]
}