{
  "name": "multi_courtyardofficetower_6_floor17",
  "refpalette": "deceasedcraft:multi_courtyardofficetower_6/multi_courtyardofficetower_6_floor17_palette",
  "xsize": 16,
  "zsize": 16,
  "slices": [
    [
      "aaaaaaaaaaaaaaaa",
      "aaaaaaaaaaaaaaaa",
      "aaaaaaaaaaaaaaaa",
      "bbbcaaaaaaacaaaa",
      "dddbaaaaaaaaaaaa",
      "dddbaaaaaaaaaaaa",
      "dddbaaaaaaaaaaaa",
      "dddbaaaaaaaaaaaa",
      "dddbaaaaaaaaaaaa",
      "dddbaaaaaaaaaaaa",
      "dddbaaaaaaaaaaaa",
      "bbbcaaaaaaacaaaa",
      "   cbbbbbbbcaaaa",
      "   c   e   cbbbb",
      "   c       c   e",
      "   c       c    "
    ],
    [
      "                ",
      "     f   ghi   j",
      "klmnnnopqnnnn   ",
      "rrrcsftuwxycABj ",
      "CDErFIy   JEK   ",
      " CDr      LEM  j",
      "   rN     OEP   ",
      "  QrRQ   y S    ",
      " Q T      sU  V ",
      "   W  X  QFU Y  ",
      "   rTf Q  ZS    ",
      "001c       c 2 3",
      "   c1000001c4555",
      "   c   e   c1000",
      "   c       c   e",
      "   c       c    "
    ],
    [
      "                ",
      "                ",
      "   UUUA67UUU    ",
      "rrrc  8    c    ",
      "  9r       9!   ",
      "   r       9#   ",
      "   r       9    ",
      "   r       U    ",
      "   $       U    ",
      "   %       U    ",
      "   r       U    ",
      "001c       c    ",
      "   c1000001c    ",
      "   c   e   c1000",
      "   c       c   e",
      "   c       c    "
    ],
    [
      "                ",
      "                ",
      "     ^& ^       ",
      "rrrc       c    ",
      "  *r            ",
      "   r            ",
      "   r            ",
      "   r       (    ",
      "   )       +    ",
      "   -            ",
      "   r            ",
      "001c       c    ",
      "   c1000001c    ",
      "   c   e   c1000",
      "   c       c   e",
      "   c       c    "
    ],
    [
      "                ",
      "                ",
      "                ",
      "rrrc       c    ",
      "   r            ",
      "   r            ",
      "   r            ",
      "   r            ",
      "   r            ",
      "   r            ",
      "   r            ",
      "001c       c    ",
      "   c1000001c    ",
      "   c   e   c1000",
      "   c       c   e",
      "   c       c    "
    ],
    [
      "[[[c[[[[[[[[[[[[",
      "[][c[][[[][[[][[",
      "[[[c[[[[[[[[[[[[",
      "cccccccccccccccc",
      "[[[c[[[[[[[[[[[[",
      "[][c[][[[][[[][[",
      "[[[c[[[[[[[[[[[[",
      "[[[c[[[[[[[[[[[[",
      "[[[c[[[[[[[[[[[[",
      "[][c[][[[][[[][[",
      "[[[c[[[[[[[[[[[[",
      "001c[[[[[[[c[[[[",
      "   c1000001c[[[[",
      "   c   e   c1000",
      "   c       c   e",
      "   c       c    "
    ]
  ]
}