{
  "name": "multi_courtyardofficetower_6_floor14",
  "refpalette": "deceasedcraft:multi_courtyardofficetower_6/multi_courtyardofficetower_6_floor14_palette",
  "xsize": 16,
  "zsize": 16,
  "slices": [
    [
      "                ",
      "                ",
      "                ",
      "aaabaaaaaaabaaaa",
      "                ",
      "                ",
      "                ",
      "                ",
      "                ",
      "                ",
      "                ",
      "ccdb       b    ",
      "   bdcccccdb    ",
      "   b   e   bdccc",
      "   b       b   e",
      "   b       b    "
    ],
    [
      "                ",
      "                ",
      "                ",
      "aaabaaaaaaabaaaa",
      "                ",
      "                ",
      "                ",
      "                ",
      "                ",
      "                ",
      "                ",
      "ccdb       b    ",
      "   bdcccccdb    ",
      "   b   e   bdccc",
      "   b       b   e",
      "   b       b    "
    ],
    [
      "                ",
      "                ",
      "                ",
      "aaabaaaaaaabaaaa",
      "                ",
      "                ",
      "                ",
      "                ",
      "                ",
      "                ",
      "                ",
      "ccdb       b    ",
      "   bdcccccdb    ",
      "   b   e   bdccc",
      "   b       b   e",
      "   b       b    "
    ],
    [
      "                ",
      "                ",
      "                ",
      "aaabaaaaaaabaaaa",
      "                ",
      "                ",
      "                ",
      "                ",
      "                ",
      "                ",
      "                ",
      "ccdb       b    ",
      "   bdcccccdb    ",
      "   b   e   bdccc",
      "   b       b   e",
      "   b       b    "
    ],
    [
      "                ",
      "                ",
      "                ",
      "aaabaaaaaaabaaaa",
      "                ",
      "                ",
      "                ",
      "                ",
      "                ",
      "                ",
      "                ",
      "ccdb       b    ",
      "   bdcccccdb    ",
      "   b   e   bdccc",
      "   b       b   e",
      "   b       b    "
    ],
    [
      "fffbffffffffffff",
      "fgfbfgfffgfffgff",
      "fffbffffffffffff",
      "bbbbbbbbbbbbbbbb",
      "fffbffffffffffff",
      "fgfbfgfffgfffgff",
      "fffbffffffffffff",
      "fffbffffffffffff",
      "fffbffffffffffff",
      "fgfbfgfffgfffgff",
      "fffbffffffffffff",
      "ccdbfffffffbffff",
      "   bdcccccdbffff",
      "   b   e   bdccc",
      "   b       b   e",
      "   b       b    "
    ]
  ]
}