{
  "name": "multi_courtyardofficetower_6_floor5",
  "refpalette": "deceasedcraft:multi_courtyardofficetower_6/multi_courtyardofficetower_6_floor5_palette",
  "xsize": 16,
  "zsize": 16,
  "slices": [
    [
      "aaaaaaaaaaaaaaaa",
      "aaaaaaaaaaaaaaaa",
      "aaaaaaaaaaaaaaaa",
      "aaabaaaaaaabaaaa",
      "aaaaaaaaaaaaaaaa",
      "aaaaaaaaaaaaaaaa",
      "aaaaaaaaaaaaaaaa",
      "aaaaaaaaaaaaaaaa",
      "aaaaaaaaaaaaaaaa",
      "aaaaaaaaaaaaaaaa",
      "aaaaaaaaaaaaaaaa",
      "cccbaaaaaaabaaaa",
      "   bcccccccbaaaa",
      "   b   d   bcccc",
      "   b       b   d",
      "   b       b    "
    ],
    [
      "         e      ",
      "e fghij j fgh e ",
      " kkkkke lkkkkk  ",
      " mnbomp qmnbom r",
      "  stu w x stu   ",
      " ystu     stu A ",
      "  BtCD E FBtCy  ",
      " q       IJ   K ",
      "    L   q       ",
      " e   Mj    q  e ",
      "     i   j      ",
      "NNObPQRRRQSb T U",
      "   bONNNNNObVWWW",
      "   b   d   bONNN",
      "   b       b   d",
      "   b       b    "
    ],
    [
      "                ",
      "                ",
      " llll    lllll  ",
      "   b     XKbY   ",
      "  Z0       01   ",
      "  203     403   ",
      "  I0       0    ",
      "                ",
      "                ",
      "                ",
      "                ",
      "NNOb5 67A 8b    ",
      "   bONNNNNOb    ",
      "   b   d   bONNN",
      "   b       b   d",
      "   b       b    "
    ],
    [
      "                ",
      "                ",
      "                ",
      "   b       b    ",
      "                ",
      "                ",
      "                ",
      "                ",
      "                ",
      "                ",
      "                ",
      "NNOb       b    ",
      "   bONNNNNOb    ",
      "   b   d   bONNN",
      "   b       b   d",
      "   b       b    "
    ],
    [
      "                ",
      "                ",
      "                ",
      "   b       b    ",
      "                ",
      "                ",
      "                ",
      "                ",
      "                ",
      "                ",
      "                ",
      "NNOb       b    ",
      "   bONNNNNOb    ",
      "   b   d   bONNN",
      "   b       b   d",
      "   b       b    "
    ],
    [
      "999b999999999999",
      "9#9b9#999#999#99",
      "999b999999999999",
      "bbbbbbbbbbbbbbbb",
      "999b999999999999",
      "9#9b9#999#999#99",
      "999b999999999999",
      "999b999999999999",
      "999b999999999999",
      "9#9b9#999#999#99",
      "999b999999999999",
      "NNOb9999999b9999",
      "   bONNNNNOb9999",
      "   b   d   bONNN",
      "   b       b   d",
      "   b       b    "
    ]
  ]
}