{
  "name": "multi_courtyardofficetower_6_floor7",
  "refpalette": "deceasedcraft:multi_courtyardofficetower_6/multi_courtyardofficetower_6_floor7_palette",
  "xsize": 16,
  "zsize": 16,
  "slices": [
    [
      "aaaaaaaaaaaaaaaa",
      "aaaaaaaaaaaaaaaa",
      "aaaaaaaaaaaaaaaa",
      "aaabaaaaaaabaaaa",
      "aaaaaaaaaaaaaaaa",
      "aaaaaaaaaaaaaaaa",
      "aaaaaaaaaaaaaaaa",
      "aaaaaaaaaaaaaaaa",
      "aaaaaaaaaaaaaaaa",
      "aaaaaaaaaaaaaaaa",
      "aaaaaaaaaaaaaaaa",
      "cccbaaaaaaabaaaa",
      "   bcccccccbaaaa",
      "   b   d   bcccc",
      "   b       b   d",
      "   b       b    "
    ],
    [
      "                ",
      "  efg     efg   ",
      " hhhhhi  hhhhh  ",
      " jkbljmn jkblj  ",
      "  opqri   opqs  ",
      " topqi   topq   ",
      "  upw x   upw   ",
      "                ",
      "                ",
      "                ",
      "                ",
      "yyAbBCDDDCEb F I",
      "   bAyyyyyAbJKKK",
      "   b   d   bAyyy",
      "   b       b   d",
      "   b       b    "
    ],
    [
      "                ",
      "                ",
      " LLLLL   LLLLL  ",
      " r bMN   OObP   ",
      "   Qi     OQR   ",
      "  SQi     TQU   ",
      "  VQr     WQP   ",
      "                ",
      "                ",
      "                ",
      "                ",
      "yyAbLLLLLLLb    ",
      "   bAyyyyyAb    ",
      "   b   d   bAyyy",
      "   b       b   d",
      "   b       b    "
    ],
    [
      "                ",
      "                ",
      "                ",
      "   b       b    ",
      "                ",
      "                ",
      "                ",
      "                ",
      "                ",
      "                ",
      "                ",
      "yyAb      Xb    ",
      "   bAyyyyyAb    ",
      "   b   d   bAyyy",
      "   b       b   d",
      "   b       b    "
    ],
    [
      "                ",
      "                ",
      "                ",
      "   b       b    ",
      "                ",
      "                ",
      "                ",
      "                ",
      "                ",
      "                ",
      "                ",
      "yyAb       b    ",
      "   bAyyyyyAb    ",
      "   b   d   bAyyy",
      "   b       b   d",
      "   b       b    "
    ],
    [
      "YYYbYYYYYYYYYYYY",
      "YZYbYZYYYZYYYZYY",
      "YYYbYYYYYYYYYYYY",
      "bbbbbbbbbbbbbbbb",
      "YYYbYYYYYYYYYYYY",
      "YZYbYZYYYZYYYZYY",
      "YYYbYYYYYYYYYYYY",
      "YYYbYYYYYYYYYYYY",
      "YYYbYYYYYYYYYYYY",
      "YZYbYZYYYZYYYZYY",
      "YYYbYYYYYYYYYYYY",
      "yyAbYYYYYYYbYYYY",
      "   bAyyyyyAbYYYY",
      "   b   d   bAyyy",
      "   b       b   d",
      "   b       b    "
    ]
  ]
}