{
  "name": "multi_courtyardofficetower_6_floor13",
  "refpalette": "deceasedcraft:multi_courtyardofficetower_6/multi_courtyardofficetower_6_floor13_palette",
  "xsize": 16,
  "zsize": 16,
  "slices": [
    [
      "aaaaaaaaaaaaaaaa",
      "aaaaaaaaaaaaaaaa",
      "aaaaaaaaaaaaaaaa",
      "bbbcbbbbbbbcbbbb",
      "dddddddddddddddd",
      "dddddddddddddddd",
      "dddddddddddddddd",
      "dddddddddddddddd",
      "dddddddddddddddd",
      "dddddddddddddddd",
      "bbbddddddddddddd",
      "eefcbbbbbbbcdddd",
      "   cfeeeeefcbbbb",
      "   c   g   cfeee",
      "   c       c   g",
      "   c       c    "
    ],
    [
      "                ",
      "                ",
      "                ",
      "hhhchhhhhhhchhhh",
      "                ",
      "  i i i i i i   ",
      " jjjjjjjjjjjjj  ",
      "kjlm!mmmmmmmmj  ",
      " jjjjjjjjjjjjj  ",
      "  n n non n n   ",
      "                ",
      "eefc       cpqqq",
      "   cfeeeeefcrqqq",
      "   c   g   cfeee",
      "   c       c   g",
      "   c       c    "
    ],
    [
      "                ",
      "                ",
      "                ",
      "hhhchhhhhhhchhhh",
      "                ",
      "                ",
      "                ",
      "             s  ",
      "                ",
      "                ",
      "                ",
      "eefc       c t t",
      "   cfeeeeefc u w",
      "   c   g   cfeee",
      "   c       c   g",
      "   c       c    "
    ],
    [
      "                ",
      "                ",
      "                ",
      "hhhchhhhhhhchhhh",
      "                ",
      "                ",
      "                ",
      "                ",
      "                ",
      "                ",
      "                ",
      "eefc       c    ",
      "   cfeeeeefc    ",
      "   c   g   cfeee",
      "   c       c   g",
      "   c       c    "
    ],
    [
      "                ",
      "                ",
      "                ",
      "hhhchhhhhhhchhhh",
      "                ",
      "                ",
      "                ",
      "                ",
      "                ",
      "                ",
      "                ",
      "eefc       c    ",
      "   cfeeeeefc    ",
      "   c   g   cfeee",
      "   c       c   g",
      "   c       c    "
    ],
    [
      "                ",
      "                ",
      "                ",
      "hhhchhhhhhhchhhh",
      "                ",
      "                ",
      "                ",
      "                ",
      "                ",
      "                ",
      "                ",
      "eefc       c    ",
      "   cfeeeeefc    ",
      "   c   g   cfeee",
      "   c       c   g",
      "   c       c    "
    ]
  ]
}