{
  "name": "multi_courtyardofficetower_6_floor18",
  "refpalette": "deceasedcraft:multi_courtyardofficetower_6/multi_courtyardofficetower_6_floor18_palette",
  "xsize": 16,
  "zsize": 16,
  "slices": [
    [
      "aaaaaaaaaaaaaaaa",
      "aaaaaaaaaaaaaaaa",
      "aaaaaaaaaaaaaaaa",
      "aaabaaaaaaabaaaa",
      "cccaaaaaaaaaaaaa",
      "cccaaaaaaaaaaaaa",
      "cccaaaaaaaaaaaaa",
      "cccaaaaaaaaaaaaa",
      "cccaaaaaaaaaaaaa",
      "cccaaaaaaaaaaaaa",
      "cccaaaaaaaaaaaaa",
      "dddbaaaaaaabaaaa",
      "   bdddddddbaaaa",
      "   b   e   bdddd",
      "   b       b   e",
      "   b       b    "
    ],
    [
      "                ",
      "                ",
      "                ",
      "   b       b    ",
      "fff             ",
      "ggf             ",
      "hgf             ",
      "h fiiiiiiiiiiiii",
      " gf             ",
      " gf             ",
      " gf             ",
      "jjkblimimilb    ",
      "   bkjjjjjkbnnop",
      "   b   e   bkjjj",
      "   b       b   e",
      "   b       b    "
    ],
    [
      "                ",
      "                ",
      "                ",
      "   b       b    ",
      "                ",
      "                ",
      "                ",
      "   qrsrtuw xyyAB",
      "                ",
      "                ",
      "                ",
      "jjkbCC D  Eb    ",
      "   bkjjjjjkbFFI!",
      "   b   e   bkjjj",
      "   b       b   e",
      "   b       b    "
    ],
    [
      "            JJ  ",
      "                ",
      "                ",
      "   b       b    ",
      "                ",
      "                ",
      "                ",
      "                ",
      "                ",
      "                ",
      "                ",
      "jjkb       b    ",
      "   bkjjjjjkb    ",
      "   b   e   bkjjj",
      "   b       b   e",
      "   b       b    "
    ],
    [
      "           KLLM ",
      "            NMJ ",
      "              J ",
      "   b       b    ",
      "                ",
      "                ",
      "   OPOPOPOP OPOP",
      "  QRSRSRSRSTRSRS",
      "                ",
      "                ",
      "                ",
      "jjkb       b    ",
      "   bkjjjjjkb    ",
      "   b   e   bkjjj",
      "   b       b   e",
      "   b       b    "
    ],
    [
      "               U",
      "            KVLM",
      "             KLM",
      "   b       b  N ",
      "                ",
      "                ",
      "                ",
      "   WXX YZ01W 232",
      "h               ",
      "                ",
      "                ",
      "jjkb       b    ",
      "   bkjjjjjkb    ",
      "   b   e   bkjjj",
      "   b       b   e",
      "   b       b    "
    ]
  ]
}