{
  "name": "multi_courtyardofficetower_6_floor3",
  "refpalette": "deceasedcraft:multi_courtyardofficetower_6/multi_courtyardofficetower_6_floor3_palette",
  "xsize": 16,
  "zsize": 16,
  "slices": [
    [
      "                ",
      "                ",
      "       a        ",
      "   b cdddc b    ",
      "     e   e      ",
      "                ",
      "                ",
      "                ",
      "                ",
      "                ",
      "                ",
      "ffgb       b    ",
      "   bgfffffgb    ",
      "   b   h   bgfff",
      "   b       b   h",
      "   b       b    "
    ],
    [
      "                ",
      "                ",
      "                ",
      "   b cdddc b    ",
      "     e   e      ",
      "                ",
      "                ",
      "                ",
      "                ",
      "                ",
      "                ",
      "ffgb       b    ",
      "   bgfffffgb    ",
      "   b   h   bgfff",
      "   b       b   h",
      "   b       b    "
    ],
    [
      "                ",
      "                ",
      "                ",
      "   b cdddc b    ",
      "                ",
      "                ",
      "                ",
      "                ",
      "                ",
      "                ",
      "                ",
      "ffgb       b    ",
      "   bgfffffgb    ",
      "   b   h   bgfff",
      "   b       b   h",
      "   b       b    "
    ],
    [
      "                ",
      "                ",
      "                ",
      "   b ij  i b    ",
      "                ",
      "                ",
      "                ",
      "                ",
      "                ",
      "                ",
      "                ",
      "ffgb       b    ",
      "   bgfffffgb    ",
      "   b   h   bgfff",
      "   b       b   h",
      "   b       b    "
    ],
    [
      "                ",
      "                ",
      "                ",
      "   bklmmmlnb    ",
      "                ",
      "                ",
      "                ",
      "                ",
      "                ",
      "                ",
      "                ",
      "ffgb       b    ",
      "   bgfffffgb    ",
      "   b   h   bgfff",
      "   b       b   h",
      "   b       b    "
    ],
    [
      "oooboooooooooooo",
      "opobopooopooopoo",
      "oooboooooooooooo",
      "bbbbbbbbbbbbbbbb",
      "oooboooooooooooo",
      "opobopooopooopoo",
      "oooboooooooooooo",
      "oooboooooooooooo",
      "oooboooooooooooo",
      "opobopooopooopoo",
      "oooboooooooooooo",
      "ffgboooooooboooo",
      "   bgfffffgboooo",
      "   b   h   bgfff",
      "   b       b   h",
      "   b       b    "
    ]
  ]
}