{
  "name": "multi_courtyardofficetower_6_floor2",
  "refpalette": "deceasedcraft:multi_courtyardofficetower_6/multi_courtyardofficetower_6_floor2_palette",
  "xsize": 16,
  "zsize": 16,
  "slices": [
    [
      "aaaaaaaaaaaaaaaa",
      "aaaaaaaaaaaaaaaa",
      "aaaaaaaaaaaaaaaa",
      "aaabaaaaaaabaaaa",
      "aaaaaaaaaaaaaaaa",
      "aaaaaaaaaaaaaaaa",
      "aaaaaaaaaaaaaaaa",
      "aaaaaaaaaaaaaaaa",
      "aaaaaaaaaaaaaaaa",
      "aaaaaaaaaaaaaaaa",
      "cccaaaaaaaaaaaaa",
      "ddebcccccccbaaaa",
      "   bedddddebcccc",
      "   b   f   beddd",
      "   b       b   f",
      "   b       b    "
    ],
    [
      "                ",
      "                ",
      "      ghi       ",
      "   bjklmnkjb    ",
      "                ",
      "       o       p",
      "      pqr       ",
      "r  o   s   o    ",
      "  pqr     pqr   ",
      "   s       s   o",
      "              pq",
      "ddeb       b   s",
      "   bedddddeb    ",
      "   b   f   beddd",
      "   b       b   f",
      "   b       b    "
    ],
    [
      "                ",
      "                ",
      "                ",
      "   btkuuuktb    ",
      "     w   w      ",
      "                ",
      "                ",
      "                ",
      "                ",
      "                ",
      "                ",
      "ddeb       b    ",
      "   bedddddeb    ",
      "   b   f   beddd",
      "   b       b   f",
      "   b       b    "
    ],
    [
      "                ",
      "                ",
      "                ",
      "   bxkuuukxb    ",
      "     w   w      ",
      "                ",
      "                ",
      "                ",
      "                ",
      "                ",
      "                ",
      "ddeb       b    ",
      "   bedddddeb    ",
      "   b   f   beddd",
      "   b       b   f",
      "   b       b    "
    ],
    [
      "                ",
      "                ",
      "       y        ",
      "   bxkuuukxb    ",
      "     w   w      ",
      "                ",
      "                ",
      "                ",
      "                ",
      "                ",
      "                ",
      "ddeb       b    ",
      "   bedddddeb    ",
      "   b   f   beddd",
      "   b       b   f",
      "   b       b    "
    ],
    [
      "                ",
      "                ",
      "       !        ",
      "   bxkuuukxb    ",
      "     w   w      ",
      "                ",
      "                ",
      "                ",
      "                ",
      "                ",
      "                ",
      "ddeb       b    ",
      "   bedddddeb    ",
      "   b   f   beddd",
      "   b       b   f",
      "   b       b    "
    ]
  ]
}