{
  "name": "multi_courtyardofficetower_6_floor22",
  "refpalette": "deceasedcraft:multi_courtyardofficetower_6/multi_courtyardofficetower_6_floor22_palette",
  "xsize": 16,
  "zsize": 16,
  "slices": [
    [
      "   a       a    ",
      "   a       a    ",
      "   a       a    ",
      "aaaaaaaaaaaaaaaa",
      "   a       a    ",
      "   a       a    ",
      "   a       a    ",
      "   a       a    ",
      "   a       a    ",
      "   a       a    ",
      "   a       a    ",
      "aaaaaaaaaaaaaaaa",
      "   a       a    ",
      "   a       a    ",
      "   a       a    ",
      "   a       a    "
    ],
    [
      "bbcacbbbbbcacbbb",
      "bbcacbbbbbcacbbb",
      "cccacccccccacccc",
      "aaaaaaaaaaaaaaaa",
      "cccacccccccacccc",
      "bbcacbbbbbcacbbb",
      "bbcacbbbbbcacbbb",
      "bbcacbbbbbcacbbb",
      "bbcacbbbbbcacbbb",
      "bbcacbbbbbcacbbb",
      "cccacccccccacccc",
      "aaaaaaaaaaaaaaaa",
      "   a       a    ",
      "   a       a    ",
      "   a       a    ",
      "   a       a    "
    ],
    [
      "   a       a    ",
      "   a       a    ",
      "   a       a    ",
      "aaaaaaaaaaaaaaaa",
      "   a       a    ",
      "   a       a    ",
      "   a       a    ",
      "   a       a    ",
      "   a       a    ",
      "   a       a    ",
      "   a       a    ",
      "aaaaaaaaaaaaaaaa",
      "   a       a    ",
      "   a       a    ",
      "   a       a    ",
      "   a       a    "
    ],
    [
      "   a       a    ",
      "   a       a    ",
      "   a       a    ",
      "aaaaaaaaaaaaaaaa",
      "   a       a    ",
      "   a       a    ",
      "   a       a    ",
      "   a       a    ",
      "   a       a    ",
      "   a       a    ",
      "   a       a    ",
      "aaaaaaaaaaaaaaaa",
      "   a       a    ",
      "   a       a    ",
      "   a       a    ",
      "   a       a    "
    ],
    [
      "   a       a    ",
      "   a       a    ",
      "   a       a    ",
      "aaaaaaaaaaaaaaaa",
      "   a       a    ",
      "   a       a    ",
      "   a       a    ",
      "   a       a    ",
      "   a       a    ",
      "   a       a    ",
      "   a       a    ",
      "aaaaaaaaaaaaaaaa",
      "   a       a    ",
      "   a       a    ",
      "   a       a    ",
      "   a       a    "
    ],
    [
      "   a       a    ",
      "   a       a    ",
      "   a       a    ",
      "aaaaaaaaaaaaaaaa",
      "   a       a    ",
      "   a       a    ",
      "   a       a    ",
      "   a       a    ",
      "   a       a    ",
      "   a       a    ",
      "   a       a    ",
      "aaaaaaaaaaaaaaaa",
      "   a       a    ",
      "   a       a    ",
      "   a       a    ",
      "   a       a    "
    ]
  ]
}