{
  "name": "multi_courtyardofficetower_6_floor16",
  "refpalette": "deceasedcraft:multi_courtyardofficetower_6/multi_courtyardofficetower_6_floor16_palette",
  "xsize": 16,
  "zsize": 16,
  "slices": [
    [
      "aaaaaaaaaaaaaaaa",
      "aaaaaaaaaaaaaaaa",
      "aaaaaaaaaaaaaaaa",
      "bbbcaaaaaaacaaaa",
      "dddbaaaaaaaaaaaa",
      "dddbaaaaaaaaaaaa",
      "dddbaaaaaaaaaaaa",
      "dddbaaaaaaaaaaaa",
      "dddbaaaaaaaaaaaa",
      "dddbaaaaaaaaaaaa",
      "dddbaaaaaaaaaaaa",
      "bbbcaaaaaaacaaaa",
      "   cbbbbbbbcaaaa",
      "   c   e   cbbbb",
      "   c       c   e",
      "   c       c    "
    ],
    [
      "                ",
      "          fgh   ",
      "iiijjj   jjjjj  ",
      "kkkclm   mlcno  ",
      "p !kq     rsq   ",
      " t ku w x ysuA  ",
      "  BkC     DsC   ",
      "   k            ",
      "   E            ",
      "   F            ",
      "   k            ",
      "IIJcKKKKKKKc L M",
      "   cJIIIIIJcNOOO",
      "   c   e   cJIII",
      "   c       c   e",
      "   c       c    "
    ],
    [
      "                ",
      "                ",
      "   KKK   KKKKK  ",
      "kkkcPQ   RScT   ",
      "  UkV     WXY   ",
      "   kZ     0X1   ",
      "   kP     VX2   ",
      "   k            ",
      "   3            ",
      "   4            ",
      "   k            ",
      "IIJcKK   KKc    ",
      "   cJIIIIIJc    ",
      "   c   e   cJIII",
      "   c       c   e",
      "   c       c    "
    ],
    [
      "                ",
      "                ",
      "                ",
      "kkkc       c    ",
      "   k            ",
      "   k            ",
      "   k            ",
      "   k            ",
      "   5            ",
      "   6            ",
      "   k            ",
      "IIJc       c    ",
      "   cJIIIIIJc    ",
      "   c   e   cJIII",
      "   c       c   e",
      "   c       c    "
    ],
    [
      "                ",
      "                ",
      "                ",
      "kkkc       c    ",
      "   k            ",
      "   k            ",
      "   k            ",
      "   k            ",
      "   k            ",
      "   k            ",
      "   k            ",
      "IIJc       c    ",
      "   cJIIIIIJc    ",
      "   c   e   cJIII",
      "   c       c   e",
      "   c       c    "
    ],
    [
      "777c777777777777",
      "787c787778777877",
      "777c777777777777",
      "cccccccccccccccc",
      "777c777777777777",
      "787c787778777877",
      "777c777777777777",
      "777c777777777777",
      "777c777777777777",
      "787c787778777877",
      "777c777777777777",
      "IIJc7777777c7777",
      "   cJIIIIIJc7777",
      "   c   e   cJIII",
      "   c       c   e",
      "   c       c    "
    ]
  ]
}