{
  "name": "multi_courtyardofficetower_6_base1",
  "refpalette": "deceasedcraft:multi_courtyardofficetower_6/multi_courtyardofficetower_6_base1_palette",
  "xsize": 16,
  "zsize": 16,
  "slices": [
    [
      "aaaaaaaaaaaaaaaa",
      "aaaaaaaaaaaaaaaa",
      "aaaaaaaaaaaaaaaa",
      "aaabaaaaaaabaaaa",
      "aaaaaaaaaaaaaaaa",
      "aaaaaaaaaaaaaaaa",
      "aaaaaaaaaaaaaaaa",
      "aaaaaaaaaaaaaaaa",
      "aaaaaaaaaaaaaaaa",
      "aaaaaaaaaaaaaaaa",
      "aaaaaaaaaaaaaaaa",
      "aaabaaaaaaabaaaa",
      "aaabaaaaaaabaaaa",
      "aaabaaaaaaabaaaa",
      "aaabaaaaaaabaaaa",
      "aaaaaaaaaaaaaaaa"
    ],
    [
      "cccccccccccccccc",
      "cccccccccccccccc",
      "cccccccccccccccc",
      "cccbcccccccbcccc",
      "cccccccccccccccc",
      "cccccccccccccccc",
      "cccccccccccccccc",
      "dddddddddddddddd",
      "eeeeeeeeeeeeeeee",
      "eeeeeeeeeeeeeeee",
      "dddddddddddddddd",
      "aaabaaaaaaabaaaa",
      "aaabaaaaaaabaaaa",
      "aaabaaaaaaabaaaa",
      "aaabaaaaaaabaaaa",
      "aaaaaaaaaaaaaaaa"
    ],
    [
      "cccccccccccccccc",
      "cccccccccccccccc",
      "cccccccccccccccc",
      "cccbcccccccbcccc",
      "cccccccccccccccc",
      "cccccccccccccccc",
      "cccccccccccccccc",
      "ffffffffffffffff",
      "                ",
      "                ",
      "ffffffffffffffff",
      "aaabaaaaaaabaaaa",
      "aaabaaaaaaabaaaa",
      "aaabaaaaaaabaaaa",
      "aaabaaaaaaabaaaa",
      "aaaaaaaaaaaaaaaa"
    ],
    [
      "cccccccccccccccc",
      "cccccccccccccccc",
      "cccccccccccccccc",
      "cccbcccccccbcccc",
      "cccccccccccccccc",
      "cccccccccccccccc",
      "cccccccccccccccc",
      "ffffffffffffffff",
      "                ",
      "                ",
      "ffffffffffffffff",
      "aaabaaaaaaabaaaa",
      "aaabaaaaaaabaaaa",
      "aaabaaaaaaabaaaa",
      "aaabaaaaaaabaaaa",
      "aaaaaaaaaaaaaaaa"
    ],
    [
      "cccccccccccccccc",
      "cccccccccccccccc",
      "cccccccccccccccc",
      "cccbcccccccbcccc",
      "cccccccccccccccc",
      "cccccccccccccccc",
      "cccccccccccccccc",
      "ffffffffffffffff",
      "                ",
      "                ",
      "ffffffffffffffff",
      "aaabaaaaaaabaaaa",
      "aaabaaaaaaabaaaa",
      "aaabaaaaaaabaaaa",
      "aaabaaaaaaabaaaa",
      "aaaaaaaaaaaaaaaa"
    ],
    [
      "cccccccccccccccc",
      "cccccccccccccccc",
      "cccccccccccccccc",
      "cccbcccccccbcccc",
      "cccccccccccccccc",
      "cccccccccccccccc",
      "cccccccccccccccc",
      "ffffffffffffffff",
      "gggggggggggggggg",
      "gggggggggggggggg",
      "ffffffffffffffff",
      "aaabaaaaaaabaaaa",
      "aaabaaaaaaabaaaa",
      "aaabaaaaaaabaaaa",
      "aaabaaaaaaabaaaa",
      "aaaaaaaaaaaaaaaa"
    ]
  ]
}