{
  "name": "multi_courtyardofficetower_6_ground",
  "refpalette": "deceasedcraft:multi_courtyardofficetower_6/multi_courtyardofficetower_6_ground_palette",
  "xsize": 16,
  "zsize": 16,
  "slices": [
    [
      "aaaaaaabbbcddcaa",
      "aaaaaaaaacddcaaa",
      "aaaaaaaacddcaaaa",
      "eaafaaacddcfaaaa",
      "aaaaaacddcaaaaaa",
      "aaaaacddcaaaaaaa",
      "aaaacdddcccccccc",
      "aaacdddddddddddd",
      "gacdddcccccccccc",
      "acddccaaaaaaaaaa",
      "cddcaaaaaaaaaaaa",
      "ddcfaaaaaaafaaaa",
      "dcafaaaaaaafaaaa",
      "caafaaaaaaafaaaa",
      "aaafaaaaaaafaaaa",
      "aaaaaaaaaaaaaaaa"
    ],
    [
      "h h  h        ih",
      "h    h j        ",
      "   h  hi     h j",
      "   fh      f   h",
      "                ",
      " hh       j klm ",
      "h               ",
      "  i             ",
      "n               ",
      "        h       ",
      "       h hhhh   ",
      "   f hjh   fh   ",
      "   fh    j f h  ",
      "   fh    h fh   ",
      "   f   hh  fh   ",
      "oh            hh"
    ],
    [
      "                ",
      "       p        ",
      "               p",
      "   fh      f    ",
      "                ",
      "  h       p     ",
      "                ",
      "                ",
      "n               ",
      "                ",
      "          h     ",
      "   f  p    f    ",
      "   fh    p f    ",
      "   f       fh   ",
      "   f       f    ",
      "qh              "
    ],
    [
      "                ",
      "       h        ",
      "               h",
      "   f       f   h",
      "                ",
      "          h     ",
      "rr              ",
      "rrr             ",
      "nrr             ",
      "rrr             ",
      "rr              ",
      "   f  h    f    ",
      "   f     h f    ",
      "   f       f    ",
      "   f       f    ",
      "p  s       s    "
    ],
    [
      "                ",
      "       h       h",
      "              hh",
      "   f       f   h",
      "          h     ",
      "          hh    ",
      "          h     ",
      "r               ",
      "nr              ",
      "r               ",
      "      h         ",
      "   f hht   f    ",
      "   f     h f    ",
      "   f       f    ",
      "   f       f    ",
      "h  s       s    "
    ],
    [
      "                ",
      "       h       h",
      "              th",
      "   f       f    ",
      "                ",
      "         hhh    ",
      "rr        h     ",
      "rrr             ",
      "nrr             ",
      "rrr             ",
      "rr    h         ",
      "   f hhh   f    ",
      "   f  h  t f    ",
      "   f       f    ",
      "t  f       f    ",
      "hh f       f    "
    ]
  ]
}