{
  "name": "multi_courtyardofficetower_6_floor6",
  "refpalette": "deceasedcraft:multi_courtyardofficetower_6/multi_courtyardofficetower_6_floor6_palette",
  "xsize": 16,
  "zsize": 16,
  "slices": [
    [
      "aaaaaaaaaaaaaaaa",
      "aaaaaaaaaaaaaaaa",
      "aaaaaaaaaaaaaaaa",
      "aaabaaaaaaabaaaa",
      "aaaaaaaaaaaaaaaa",
      "aaaaaaaaaaaaaaaa",
      "aaaaaaaaaaaaaaaa",
      "aaaaaaaaaaaaaaaa",
      "aaaaaaaaaaaaaaaa",
      "aaaaaaaaaaaaaaaa",
      "aaaaaaaaaaaaaaaa",
      "cccbaaaaaaabaaaa",
      "   bcccccccbaaaa",
      "   b   d   bcccc",
      "   b       b   d",
      "   b       b    "
    ],
    [
      "                ",
      "  efg     efg   ",
      " hhhhh   hhhhh  ",
      " ijbki   ijbki  ",
      "  lmn     lmn   ",
      "o lmnp   olmn   ",
      "  qmr     qmrp  ",
      "                ",
      "                ",
      "                ",
      "                ",
      "sstbuwxxxwyb A B",
      "   btssssstbCDDD",
      "   b   d   btsss",
      "   b       b   d",
      "   b       b    "
    ],
    [
      "                ",
      "                ",
      " EEEEE   EEEEE  ",
      " FIb     JKbL   ",
      "  MNO     PNO   ",
      "  QNR     SNR   ",
      "  ONT     UNV   ",
      "                ",
      "                ",
      "                ",
      "                ",
      "sstbEEEEEEEb    ",
      "   btssssstb    ",
      "   b   d   btsss",
      "   b       b   d",
      "   b       b    "
    ],
    [
      "                ",
      "                ",
      "                ",
      "   b       b    ",
      "                ",
      "                ",
      "                ",
      "                ",
      "                ",
      "                ",
      "                ",
      "sstbW  XY  b    ",
      "   btssssstb    ",
      "   b   d   btsss",
      "   b       b   d",
      "   b       b    "
    ],
    [
      "                ",
      "                ",
      "                ",
      "   b       b    ",
      "                ",
      "                ",
      "                ",
      "                ",
      "                ",
      "                ",
      "                ",
      "sstb       b    ",
      "   btssssstb    ",
      "   b   d   btsss",
      "   b       b   d",
      "   b       b    "
    ],
    [
      "ZZZbZZZZZZZZZZZZ",
      "Z0ZbZ0ZZZ0ZZZ0ZZ",
      "ZZZbZZZZZZZZZZZZ",
      "bbbbbbbbbbbbbbbb",
      "ZZZbZZZZZZZZZZZZ",
      "Z0ZbZ0ZZZ0ZZZ0ZZ",
      "ZZZbZZZZZZZZZZZZ",
      "ZZZbZZZZZZZZZZZZ",
      "ZZZbZZZZZZZZZZZZ",
      "Z0ZbZ0ZZZ0ZZZ0ZZ",
      "ZZZbZZZZZZZZZZZZ",
      "sstbZZZZZZZbZZZZ",
      "   btssssstbZZZZ",
      "   b   d   btsss",
      "   b       b   d",
      "   b       b    "
    ]
  ]
}