{
  "name": "multi_courtyardofficetower_6_floor10",
  "refpalette": "deceasedcraft:multi_courtyardofficetower_6/multi_courtyardofficetower_6_floor10_palette",
  "xsize": 16,
  "zsize": 16,
  "slices": [
    [
      "aaaaaaaaaaaaaaaa",
      "aaaaaaaaaaaaaaaa",
      "bbbbbbbbbbbbbbbb",
      "cccdcccccccdcccc",
      "bbbbbbbbbbbbbbbb",
      "bbbbbbbbbbbbbbbb",
      "bcbccbbcbbbcbcbc",
      "cccccccbbcccbbbc",
      "cccccccbbbcccbcc",
      "ccccccbbcbcccbbc",
      "eeefcccccccfcbcc",
      "gghdeeeeeeedccbb",
      "   dhggggghdeeee",
      "   d   i   dhggg",
      "   d       d   i",
      "   d       d    "
    ],
    [
      "                ",
      "                ",
      "                ",
      "jjjdjjjkjjjdjjjj",
      "                ",
      "                ",
      "                ",
      "                ",
      "                ",
      "                ",
      "lllm  nop  m  qr",
      "iisdllllllld    ",
      "   dsiiiiisdllll",
      "   d   i   dsiii",
      "   d       d   i",
      "   d       d    "
    ],
    [
      "                ",
      "                ",
      "                ",
      "   d       d    ",
      "                ",
      "                ",
      "                ",
      "                ",
      "                ",
      "                ",
      "   t       t    ",
      "   d       d    ",
      "   d       d    ",
      "   d       d    ",
      "   d       d    ",
      "   d       d    "
    ],
    [
      "                ",
      "                ",
      "                ",
      "   d       d    ",
      "                ",
      "                ",
      "                ",
      "                ",
      "                ",
      "                ",
      "   j       j    ",
      "   d       d    ",
      "   d       d    ",
      "   d       d    ",
      "   d       d    ",
      "   d       d    "
    ],
    [
      "                ",
      "                ",
      "                ",
      "   d       d    ",
      "                ",
      "                ",
      "                ",
      "                ",
      "                ",
      "                ",
      "   u       u    ",
      "   d       d    ",
      "   d       d    ",
      "   d       d    ",
      "   d       d    ",
      "   d       d    "
    ],
    [
      "                ",
      "                ",
      "                ",
      "   d       d    ",
      "                ",
      "                ",
      "                ",
      "                ",
      "                ",
      "                ",
      "   u       u    ",
      "   d       d    ",
      "   d       d    ",
      "   d       d    ",
      "   d       d    ",
      "   d       d    "
    ]
  ]
}