{
  "name": "multi_courtyardofficetower_6_floor9",
  "refpalette": "deceasedcraft:multi_courtyardofficetower_6/multi_courtyardofficetower_6_floor9_palette",
  "xsize": 16,
  "zsize": 16,
  "slices": [
    [
      "                ",
      "                ",
      "                ",
      "   a       a    ",
      "                ",
      "                ",
      "                ",
      "                ",
      "                ",
      "                ",
      "                ",
      "bbca       a    ",
      "   acbbbbbca    ",
      "   a   d   acbbb",
      "   a       a   d",
      "   a       a    "
    ],
    [
      "                ",
      "                ",
      "                ",
      "   a       a    ",
      "                ",
      "                ",
      "                ",
      "                ",
      "                ",
      "                ",
      "                ",
      "bbca       a    ",
      "   acbbbbbca    ",
      "   a   d   acbbb",
      "   a       a   d",
      "   a       a    "
    ],
    [
      "                ",
      "                ",
      "                ",
      "   a       a    ",
      "                ",
      "                ",
      "                ",
      "                ",
      "                ",
      "                ",
      "                ",
      "bbca       a    ",
      "   acbbbbbca    ",
      "   a   d   acbbb",
      "   a       a   d",
      "   a       a    "
    ],
    [
      "                ",
      "                ",
      "                ",
      "   a       a    ",
      "                ",
      "                ",
      "                ",
      "                ",
      "                ",
      "                ",
      "                ",
      "bbca       a    ",
      "   acbbbbbca    ",
      "   a   d   acbbb",
      "   a       a   d",
      "   a       a    "
    ],
    [
      "                ",
      "                ",
      "                ",
      "   a       a    ",
      "                ",
      "                ",
      "                ",
      "                ",
      "                ",
      "                ",
      "                ",
      "bbca       a    ",
      "   acbbbbbca    ",
      "   a   d   acbbb",
      "   a       a   d",
      "   a       a    "
    ],
    [
      "eeeaeeeeeeeeeeee",
      "efeaefeeefeeefee",
      "eeeaeeeeeeeeeeee",
      "aaaaaaaaaaaaaaaa",
      "eeeaeeeeeeeeeeee",
      "efeaefeeefeeefee",
      "eeeaeeeeeeeeeeee",
      "eeeaeeeeeeeeeeee",
      "eeeaeeeeeeeeeeee",
      "efeaefeeefeeefee",
      "eeeaeeeeeeeeeeee",
      "bbcaeeeeeeeaeeee",
      "   acbbbbbcaeeee",
      "   a   d   acbbb",
      "   a       a   d",
      "   a       a    "
    ]
  ]
}