{
  "name": "multi_courtyardofficetower_6_floor12",
  "refpalette": "deceasedcraft:multi_courtyardofficetower_6/multi_courtyardofficetower_6_floor12_palette",
  "xsize": 16,
  "zsize": 16,
  "slices": [
    [
      "                ",
      "                ",
      "                ",
      "   a       a    ",
      "                ",
      "                ",
      "                ",
      "                ",
      "                ",
      "                ",
      "                ",
      "   a       a    ",
      "   a       a    ",
      "   a       a    ",
      "   a       a    ",
      "   a       a    "
    ],
    [
      "                ",
      "                ",
      "                ",
      "   a       a    ",
      "                ",
      "                ",
      "                ",
      "                ",
      "                ",
      "                ",
      "                ",
      "   a       a    ",
      "   a       a    ",
      "   a       a    ",
      "   a       a    ",
      "   a       a    "
    ],
    [
      "                ",
      "                ",
      "                ",
      "   a       a    ",
      "                ",
      "                ",
      "                ",
      "                ",
      "                ",
      "                ",
      "                ",
      "   a       a    ",
      "   a       a    ",
      "   a       a    ",
      "   a       a    ",
      "   a       a    "
    ],
    [
      "                ",
      "                ",
      "                ",
      "   a       a    ",
      "                ",
      "                ",
      "                ",
      "                ",
      "                ",
      "                ",
      "                ",
      "   a       a    ",
      "   a       a    ",
      "   a       a    ",
      "   a       a    ",
      "   a       a    "
    ],
    [
      "                ",
      "                ",
      "                ",
      "   a       a    ",
      "                ",
      "                ",
      "                ",
      "                ",
      "                ",
      "                ",
      "                ",
      "   a       a    ",
      "   a       a    ",
      "   a       a    ",
      "   a       a    ",
      "   a       a    "
    ],
    [
      "bbbabcbbbbbbbbbb",
      "bbbabccccccccccc",
      "bbbabbbbbbbbbbbb",
      "aaaaaaaaaaaaaaaa",
      "bbbabbbbbbbbbbbb",
      "bbbabbbbbbbbbbbb",
      "bbbabbbbbbbbbbbb",
      "bbbabbbbbbbbbbbb",
      "bbbabbbbbbbbbbbb",
      "bbbabbbbbbbbbbbb",
      "   abbbbbbbbbbbb",
      "ddea       abbbb",
      "   aedddddea    ",
      "   a   d   aeddd",
      "   a       a   d",
      "   a       a    "
    ]
  ]
}