{
  "name": "multi_courtyardofficetower_6_floor4",
  "refpalette": "deceasedcraft:multi_courtyardofficetower_6/multi_courtyardofficetower_6_floor4_palette",
  "xsize": 16,
  "zsize": 16,
  "slices": [
    [
      "aaaaaaaaaaaaaaaa",
      "aaaaaaaaaaaaaaaa",
      "aaaaaaaaaaaaaaaa",
      "aaabaaaaaaabaaaa",
      "aaaaaaaaaaaaaaaa",
      "aaaaaaaaaaaaaaaa",
      "aaaaaaaaaaaaaaaa",
      "aaaaaaaaaaaaaaaa",
      "aaaaaaaaaaaaaaaa",
      "aaaaaaaaaaaaaaaa",
      "aaaaaaaaaaaaaaaa",
      "cccbaaaaaaabaaaa",
      "   bcccccccbaaaa",
      "   b   d   bcccc",
      "   b       b   d",
      "   b       b    "
    ],
    [
      "                ",
      "  efg     efg   ",
      " hhhhh   hhhhh  ",
      " ijbki   ijbki  ",
      "  lmn     lmno  ",
      " plmnq   plmn   ",
      "  rms     rms   ",
      "                ",
      "                ",
      "                ",
      "                ",
      "ttubwxyyyxAb B C",
      "   butttttubDEEE",
      "   b   d   buttt",
      "   b       b   d",
      "   b       b    "
    ],
    [
      "                ",
      "                ",
      " FFFFF   FFFFF  ",
      " IJb K   LMbN   ",
      "   OP      OP   ",
      "  QOR     QOR   ",
      "  POS     PO    ",
      "                ",
      "                ",
      "                ",
      "                ",
      "ttubTKUVTKKb    ",
      "   butttttub    ",
      "   b   d   buttt",
      "   b       b   d",
      "   b       b    "
    ],
    [
      "                ",
      "                ",
      "                ",
      "   b       b    ",
      "                ",
      "                ",
      "                ",
      "                ",
      "                ",
      "                ",
      "                ",
      "ttub       b    ",
      "   butttttub    ",
      "   b   d   buttt",
      "   b       b   d",
      "   b       b    "
    ],
    [
      "                ",
      "                ",
      "                ",
      "   b       b    ",
      "                ",
      "                ",
      "                ",
      "                ",
      "                ",
      "                ",
      "                ",
      "ttub       b    ",
      "   butttttub    ",
      "   b   d   buttt",
      "   b       b   d",
      "   b       b    "
    ],
    [
      "WWWbWWWWWWWWWWWW",
      "WXWbWXWWWXWWWXWW",
      "WWWbWWWWWWWWWWWW",
      "bbbbbbbbbbbbbbbb",
      "WWWbWWWWWWWWWWWW",
      "WXWbWXWWWXWWWXWW",
      "WWWbWWWWWWWWWWWW",
      "WWWbWWWWWWWWWWWW",
      "WWWbWWWWWWWWWWWW",
      "WXWbWXWWWXWWWXWW",
      "WWWbWWWWWWWWWWWW",
      "ttubWWWWWWWbWWWW",
      "   butttttubWWWW",
      "   b   d   buttt",
      "   b       b   d",
      "   b       b    "
    ]
  ]
}