{
  "name": "multi_courtyardofficetower_6_floor1",
  "refpalette": "deceasedcraft:multi_courtyardofficetower_6/multi_courtyardofficetower_6_floor1_palette",
  "xsize": 16,
  "zsize": 16,
  "slices": [
    [
      "                ",
      "       a        ",
      "               b",
      "   c       c    ",
      "                ",
      "         bb     ",
      "                ",
      "d               ",
      "ed              ",
      "d               ",
      "      b         ",
      "   c  bb   c    ",
      "   c  a    c    ",
      "   c       c    ",
      "b  c       c    ",
      "bb c       c    "
    ],
    [
      "                ",
      "                ",
      "               a",
      "   c       c    ",
      "                ",
      "          b     ",
      "                ",
      "                ",
      "e               ",
      "                ",
      "                ",
      "   c  b    c    ",
      "   c       c    ",
      "   c       c    ",
      "b  c       c    ",
      "bb c       c    "
    ],
    [
      "                ",
      "                ",
      "                ",
      "   c       c    ",
      "                ",
      "                ",
      "                ",
      "d               ",
      "ed              ",
      "d               ",
      "                ",
      "   c       c    ",
      "   c       c    ",
      "   c       c    ",
      "   c       c    ",
      "b  c       c    "
    ],
    [
      "                ",
      "                ",
      "                ",
      "   c       c    ",
      "                ",
      "                ",
      "                ",
      "                ",
      "d               ",
      "                ",
      "                ",
      "   c       c    ",
      "   c       c    ",
      "   c       c    ",
      "   c       c    ",
      "b  c       c    "
    ],
    [
      "                ",
      "                ",
      "                ",
      "   c       c    ",
      "                ",
      "                ",
      "                ",
      "                ",
      "                ",
      "                ",
      "                ",
      "   c       c    ",
      "   c       c    ",
      "   c       c    ",
      "   c       c    ",
      "b  c       c    "
    ],
    [
      "fffcffffffffffff",
      "fffcffffffffffff",
      "fffcffffffffffff",
      "cccccccccccccccc",
      "fffcffffffffffff",
      "fffcffffffffffff",
      "fffcffffffffffff",
      "fffcffffffffffff",
      "fffcffffffffffff",
      "fffcffffffffffff",
      "   cffffffffffff",
      "gghc       cffff",
      "   chggggghc    ",
      "   c   g   chggg",
      "   c       c   g",
      "   c       c    "
    ]
  ]
}