{
  "name": "multi_casino_3_floor5",
  "refpalette": "deceasedcraft:multi_casino_3/multi_casino_3_floor5_palette",
  "xsize": 16,
  "zsize": 16,
  "slices": [
    [
      "      ab        ",
      "      cb        ",
      "      ab        ",
      "      cbd       ",
      "      ab        ",
      "      cb        ",
      "      ab        ",
      "      ab    d   ",
      "      abbbbbbbbb",
      "      caaacacaca",
      "                ",
      "                ",
      "                ",
      "                ",
      "                ",
      "                "
    ],
    [
      "      ab        ",
      "      ab        ",
      "      ab        ",
      "      cbd       ",
      "      ab        ",
      "      ab        ",
      "      ab        ",
      "      cb    d   ",
      "      abbbbbbbbb",
      "      aacaaacaaa",
      "                ",
      "                ",
      "                ",
      "                ",
      "                ",
      "                "
    ],
    [
      "      ab        ",
      "      ab        ",
      "      abd       ",
      "      cb        ",
      "      abd       ",
      "      ab        ",
      "      ab        ",
      "      cb   d d  ",
      "      abbbbbbbbb",
      "      aacaaacaaa",
      "                ",
      "                ",
      "                ",
      "                ",
      "                ",
      "                "
    ],
    [
      "      ab        ",
      "      abd       ",
      "      ab        ",
      "      cb        ",
      "      ab        ",
      "      abd       ",
      "      ab        ",
      "      cb  d   d ",
      "      aebbbbbbbb",
      "      aacaaacaaa",
      "                ",
      "                ",
      "                ",
      "                ",
      "                ",
      "                "
    ],
    [
      "      ab        ",
      "      abd       ",
      "      ab        ",
      "      cb        ",
      "      ab        ",
      "      abd       ",
      "      ab        ",
      "      cb  d   d ",
      "      aebbbbbbbb",
      "      aacaaacaaa",
      "                ",
      "                ",
      "                ",
      "                ",
      "                ",
      "                "
    ],
    [
      "      abd       ",
      "      abf       ",
      "      abf       ",
      "      cbf       ",
      "      abf       ",
      "      abf       ",
      "      abd       ",
      "      aegdhhhhhd",
      "      aiebbbbbbb",
      "       aaaaacaaa",
      "                ",
      "                ",
      "                ",
      "                ",
      "                ",
      "                "
    ]
  ]
}