{
  "name": "multi_casino_3_floor23",
  "refpalette": "deceasedcraft:multi_casino_3/multi_casino_3_floor23_palette",
  "xsize": 16,
  "zsize": 16,
  "slices": [
    [
      "       a        ",
      "      ba        ",
      "       a    c   ",
      "      ba        ",
      "       a    d  e",
      "      ba       f",
      "       a        ",
      "      bag       ",
      "       aaaaaaaaa",
      "        b b b b ",
      "                ",
      "                ",
      "                ",
      "                ",
      "                ",
      "                "
    ],
    [
      "       h       i",
      "      bh       i",
      "       h    d  i",
      "      bh        ",
      "       h    d   ",
      "      bh        ",
      "       h        ",
      "      bhg       ",
      "       ahhhhhhhh",
      "        b b b b ",
      "                ",
      "                ",
      "                ",
      "                ",
      "                ",
      "                "
    ],
    [
      "       h        ",
      "      bh        ",
      "       h    d   ",
      "      bh   c    ",
      "       h    d   ",
      "      bh        ",
      "       h        ",
      "      bhg       ",
      "       ahhhhhhhh",
      "        b b b b ",
      "                ",
      "                ",
      "                ",
      "                ",
      "                ",
      "                "
    ],
    [
      "       h        ",
      "      bh        ",
      "       h    d   ",
      "      bh   d c  ",
      "       h    d   ",
      "      bh        ",
      "       h        ",
      "      bhg       ",
      "       ahhhhhhhh",
      "        b b b b ",
      "                ",
      "                ",
      "                ",
      "                ",
      "                ",
      "                "
    ],
    [
      "       h        ",
      "      bh  jjkjj ",
      "       h  j d j ",
      "      bh  ld dm ",
      "       h  j d j ",
      "      bh  jjkjj ",
      "       h        ",
      "      bhg       ",
      "       ahhhhhhhh",
      "        b b b b ",
      "                ",
      "                ",
      "                ",
      "                ",
      "                ",
      "                "
    ],
    [
      "       hnooooooo",
      "      bhnoopppoo",
      "       hnopqrqpo",
      "      bhnoprrrpo",
      "       hnopqrqpo",
      "      bhnoopppoo",
      "       hnooooooo",
      "      bhgnnnnnnn",
      "       ahhhhhhhh",
      "        b b b b ",
      "                ",
      "                ",
      "                ",
      "                ",
      "                ",
      "                "
    ]
  ]
}