{
  "name": "multi_casino_3_floor4",
  "refpalette": "deceasedcraft:multi_casino_3/multi_casino_3_floor4_palette",
  "xsize": 16,
  "zsize": 16,
  "slices": [
    [
      "      a bbbbbbbb",
      "      c bbbbbbbb",
      "      a bbbbbbbb",
      "      a bbbbbbbb",
      "      a bbbbbbbb",
      "      c bbbbbbbb",
      "      a bbbbbbbb",
      "      a dbbbbbbb",
      "      a         ",
      "      caaacaaaca",
      "                ",
      "                ",
      "                ",
      "                ",
      "                ",
      "                "
    ],
    [
      "      ae  fgggh ",
      "      ce  ijjj k",
      "      ael jmmmjg",
      "      aen jm mjg",
      "      ael jmmmjg",
      "      ce   jjjop",
      "      ae        ",
      "      aed  qnq  ",
      "      aeeeeeeeee",
      "      caaacaaaca",
      "                ",
      "                ",
      "                ",
      "                ",
      "                ",
      "                "
    ],
    [
      "      ae        ",
      "      ce   rst  ",
      "      ae      u ",
      "      aew   x y ",
      "      ae      A ",
      "      ce        ",
      "      aed       ",
      "      ae d      ",
      "      aeeeeeeeee",
      "      caaacaaaca",
      "                ",
      "                ",
      "                ",
      "                ",
      "                ",
      "                "
    ],
    [
      "      ae        ",
      "      ce        ",
      "      ae        ",
      "      ae        ",
      "      ae        ",
      "      ced       ",
      "      ae        ",
      "      ae  d     ",
      "      aeeeeeeeee",
      "      caaacaaaca",
      "                ",
      "                ",
      "                ",
      "                ",
      "                ",
      "                "
    ],
    [
      "      ae        ",
      "      ce        ",
      "      ae        ",
      "      ae        ",
      "      ae        ",
      "      ced       ",
      "      ae        ",
      "      ae  d     ",
      "      aeeeeeeeee",
      "      caaacaaaca",
      "                ",
      "                ",
      "                ",
      "                ",
      "                ",
      "                "
    ],
    [
      "      ae        ",
      "      ce        ",
      "      ae        ",
      "      ae        ",
      "      aed       ",
      "      ce        ",
      "      ae        ",
      "      ae   d    ",
      "      aeeeeeeeee",
      "      caaacaaaca",
      "                ",
      "                ",
      "                ",
      "                ",
      "                ",
      "                "
    ]
  ]
}