{
  "name": "multi_casino_3_base1",
  "refpalette": "deceasedcraft:multi_casino_3/multi_casino_3_base1_palette",
  "xsize": 16,
  "zsize": 16,
  "slices": [
    [
      "vaab    cddde   ",
      "vaab    cddde   ",
      "vaabf   cddde   ",
      "vaabg   cdddeeee",
      "vaabf hicddddddd",
      "vaab   jkddddddd",
      "vaab    cddddddd",
      "vaabf   lmnmmmmm",
      "vaab      jo    ",
      "vaab       p    ",
      "vaabf           ",
      "vaabgf  f  fgf  ",
      "vaabbbbbbbbbbbbb",
      "vaaaaaaaaaaaaaaa",
      "vaaaaaaaaaaaaaaa",
      "vvvvvvvvvvvvvvvv"
    ],
    [
      "vaab    cq  r   ",
      "vaab    cq  r   ",
      "vaabf   cqstr   ",
      "vaabg   cr  rrrr",
      "vaab    c    uwx",
      "vaab  h y    A B",
      "vaab   pcC  r   ",
      "vaab    lmDmmmmm",
      "vaab     h      ",
      "vaab      p     ",
      "vaabf           ",
      "vaabg      fg   ",
      "vaabbbbbbbbbbbbb",
      "vaaaaaaaaaaaaaaa",
      "vaaaaaaaaaaaaaaa",
      "vvvvvvvvvvvvvvvv"
    ],
    [
      "vaab    cE  r   ",
      "vaab    c   r   ",
      "vaab    c FIr   ",
      "vaabg   cr  rrJJ",
      "vaab    c    K L",
      "vaab    M    N  ",
      "vaab    c  Or   ",
      "vaab    lmPmmmmm",
      "vaab            ",
      "vaab            ",
      "vaab            ",
      "vaabg       g   ",
      "vaabbbbbbbbbbbbb",
      "vaaaaaaaaaaaaaaa",
      "vaaaaaaaaaaaaaaa",
      "vvvvvvvvvvvvvvvv"
    ],
    [
      "vaab    c   r   ",
      "vaab    c   r   ",
      "vaab    c   r   ",
      "vaabg   crQQrrRR",
      "vaab    c   S   ",
      "vaab    c   S   ",
      "vaab    c   r   ",
      "vaab    lmmmmmmm",
      "vaab            ",
      "vaab            ",
      "vaab            ",
      "vaabg       g   ",
      "vaabbbbbbbbbbbbb",
      "vaaaaaaaaaaaaaaa",
      "vaaaaaaaaaaaaaaa",
      "vvvvvvvvvvvvvvvv"
    ],
    [
      "vaab TTTU   rTTV",
      "vaab TTTU   rTVT",
      "vaab TTTU   rVTT",
      "vaabgTTTUrrrrrrr",
      "vaab VTTU   r   ",
      "vaab TVTU W r   ",
      "vaab TTVU   r   ",
      "vaab TTTlXXXXXXX",
      "vaab TTVTVTTTTTT",
      "vaab TVTTTVTTTTT",
      "vaab VTTTTTVTTTT",
      "vaabg       g   ",
      "vaabbbbbbbbbbbbb",
      "vaaaaaaaaaaaaaaa",
      "vaaaaaaaaaaaaaaa",
      "vvvvvvvvvvvvvvvv"
    ],
    [
      "vaabYZ000000000l",
      "vaabYZ00000000l0",
      "vaabYZ0000000l00",
      "vaabg0000000l000",
      "vaabYl00000l0000",
      "vaabYZl000l00000",
      "vaabYZ0l0l000000",
      "vaabYZ00l0000000",
      "vaabYZ0l0l000000",
      "vaabYZl000l00000",
      "vaabYlZZZZZl0ZZZ",
      "vaabg1111111g111",
      "vaabbbbbbbbbbbbb",
      "vaaaaaaaaaaaaaaa",
      "vaaaaaaaaaaaaaaa",
      "vvvvvvvvvvvvvvvv"
    ]
  ]
}