{
  "name": "multi_casino_3_floor15",
  "refpalette": "deceasedcraft:multi_casino_3/multi_casino_3_floor15_palette",
  "xsize": 16,
  "zsize": 16,
  "slices": [
    [
      "       a        ",
      "      ba        ",
      "       a        ",
      "      bac       ",
      "       a        ",
      "      ba        ",
      "       a        ",
      "      ba    c   ",
      "       aaaaaaaaa",
      "        b b b b ",
      "                ",
      "                ",
      "                ",
      "                ",
      "                ",
      "                "
    ],
    [
      "       d        ",
      "      bd        ",
      "       d        ",
      "      bdc       ",
      "       d        ",
      "      bd        ",
      "       d        ",
      "      bd    c   ",
      "       adddddddd",
      "        b b b b ",
      "                ",
      "                ",
      "                ",
      "                ",
      "                ",
      "                "
    ],
    [
      "       d       e",
      "      bd        ",
      "       d        ",
      "      bd        ",
      "       dc       ",
      "      bd        ",
      "       d        ",
      "      bd   c    ",
      "       adddddddd",
      "        b b b b ",
      "                ",
      "                ",
      "                ",
      "                ",
      "                ",
      "                "
    ],
    [
      "       d       f",
      "      bd        ",
      "       d        ",
      "      bd        ",
      "       d        ",
      "      bdc       ",
      "       d        ",
      "      bd  c     ",
      "       adddddddd",
      "        b b b b ",
      "                ",
      "                ",
      "                ",
      "                ",
      "                ",
      "                "
    ],
    [
      "       d      ff",
      "      bd       f",
      "       d        ",
      "      bd        ",
      "       d        ",
      "      bdc       ",
      "       d        ",
      "      bd  c     ",
      "       adddddddd",
      "        b b b b ",
      "                ",
      "                ",
      "                ",
      "                ",
      "                ",
      "                "
    ],
    [
      "       dghhhhijk",
      "      bdghhhhhgj",
      "       dghhhhhhl",
      "      bdghhhhhhh",
      "       dghhhhhhh",
      "      bdghhhhhhh",
      "       dchhhhhhh",
      "      bdecgggggg",
      "       adddddddd",
      "        b b b b ",
      "                ",
      "                ",
      "                ",
      "                ",
      "                ",
      "                "
    ]
  ]
}