{
  "name": "multi_casino_3_floor24",
  "refpalette": "deceasedcraft:multi_casino_3/multi_casino_3_floor24_palette",
  "xsize": 16,
  "zsize": 16,
  "slices": [
    [
      "       abbbbbbbb",
      "      cabbbbbbbb",
      "       abbbbb!bb",
      "      cabbbbbdbb",
      "       abbbbbbbb",
      "      cabbbbbbbb",
      "       abbbbbbbb",
      "      caebbbbbbb",
      "       aaaaaaaaa",
      "        c c c c ",
      "                ",
      "                ",
      "                ",
      "                ",
      "                ",
      "                "
    ],
    [
      "       fghiiiiih",
      "      cfjhk    h",
      "       fjhk ll h",
      "      cfmhk ll h",
      "       fjhk    h",
      "      cfmhkkkkkh",
      "       fnhhhhhhh",
      "      cfeoppqprs",
      "       affffffff",
      "        c c c c ",
      "                ",
      "                ",
      "                ",
      "                ",
      "                ",
      "                "
    ],
    [
      "       f        ",
      "      cf        ",
      "       f        ",
      "      cf        ",
      "       f        ",
      "      cf        ",
      "       f        ",
      "      cfe       ",
      "       affffffff",
      "        c c c c ",
      "                ",
      "                ",
      "                ",
      "                ",
      "                ",
      "                "
    ],
    [
      "       f        ",
      "      cf        ",
      "       f        ",
      "      cf        ",
      "       f        ",
      "      cf        ",
      "       f        ",
      "      cfe       ",
      "       affffffff",
      "        c c c c ",
      "                ",
      "                ",
      "                ",
      "                ",
      "                ",
      "                "
    ],
    [
      "       f        ",
      "      cf        ",
      "       f        ",
      "      cf        ",
      "       f        ",
      "      cf        ",
      "       f        ",
      "      cfe       ",
      "       affffffff",
      "        c c c c ",
      "                ",
      "                ",
      "                ",
      "                ",
      "                ",
      "                "
    ],
    [
      "       f        ",
      "      cf        ",
      "       f        ",
      "      cf        ",
      "       f    t  u",
      "      cf       w",
      "       f        ",
      "      cfe       ",
      "       affffffff",
      "        c c c c ",
      "                ",
      "                ",
      "                ",
      "                ",
      "                ",
      "                "
    ]
  ]
}