{
  "name": "multi_casino_3_floor6",
  "refpalette": "deceasedcraft:multi_casino_3/multi_casino_3_floor6_palette",
  "xsize": 16,
  "zsize": 16,
  "slices": [
    [
      "      abcddddddd",
      "      abcddddddd",
      "      abcddddddd",
      "      abcddddddd",
      "      abcddddddd",
      "      abcddddddd",
      "      accddddddd",
      "      aefccccccc",
      "      ghecbbbbbb",
      "       gaaaaaaaa",
      "                ",
      "                ",
      "                ",
      "                ",
      "                ",
      "                "
    ],
    [
      "      ab  ij j  ",
      "      kb lmmmmm ",
      "      ab lmnnmmo",
      "      abpqr  nm ",
      "      ab   s nmo",
      "      ab   tlmmu",
      "      ac     rr ",
      "      aef   p   ",
      "       hecbbbbbb",
      "        aaaaaaka",
      "                ",
      "                ",
      "                ",
      "                ",
      "                ",
      "                "
    ],
    [
      "      abf       ",
      "      kb        ",
      "      ab   wx   ",
      "      aby    A  ",
      "      ab     B  ",
      "      ac        ",
      "      aef       ",
      "      CD f  y  f",
      "       hDecbbbbb",
      "        Caaaaaka",
      "                ",
      "                ",
      "                ",
      "                ",
      "                ",
      "                "
    ],
    [
      "      ab        ",
      "      kbf       ",
      "      ab        ",
      "      abE       ",
      "      ac        ",
      "      aef       ",
      "      gD        ",
      "      CD  f E f ",
      "       hDDecbbbb",
      "        Cgaaaaka",
      "                ",
      "                ",
      "                ",
      "                ",
      "                ",
      "                "
    ],
    [
      "      ab        ",
      "      kbf       ",
      "      ab        ",
      "      ab        ",
      "      ac        ",
      "      aef       ",
      "       D        ",
      "      CD  f   f ",
      "       hDDecbbbb",
      "        C aaaaka",
      "                ",
      "                ",
      "                ",
      "                ",
      "                ",
      "                "
    ],
    [
      "      ab        ",
      "      ab        ",
      "      abf       ",
      "      ac        ",
      "      aef       ",
      "      CD        ",
      "       D        ",
      "      CD   f f  ",
      "       hDDDecbbb",
      "        C Caaaaa",
      "                ",
      "                ",
      "                ",
      "                ",
      "                ",
      "                "
    ]
  ]
}