{
  "name": "multi_casino_3_base6",
  "refpalette": "deceasedcraft:multi_casino_3/multi_casino_3_base6_palette",
  "xsize": 16,
  "zsize": 16,
  "slices": [
    [
      "vaabcdeddddddfff",
      "vaabcdeddddddfff",
      "vaabcdeddddddfff",
      "vaabgdeddddddddd",
      "vaabcdeddddddddd",
      "vaabcdeddddddddd",
      "vaabcdeddddddddd",
      "vaabcdedhddddddd",
      "vaabcdeddddddddd",
      "vaabcdeeeeeeeeee",
      "vaabcddddddddddd",
      "vaabgcccccccgccc",
      "vaabbbbbbbbbbbbb",
      "vaaaaaaaaaaaaaaa",
      "vaaaaaaaaaaaaaaa",
      "vvvvvvvvvvvvvvvv"
    ],
    [
      "vaabi   jkjlm   ",
      "vaabi   jnn     ",
      "vaabi   jo      ",
      "vaabgp  jq     m",
      "vaabi   jq     r",
      "vaabi  sjt    nu",
      "vaabi   jwxyyAnB",
      "vaabi   huuuuuuu",
      "vaabi     s     ",
      "vaabi           ",
      "vaabi       C   ",
      "vaabgiiiiiiigiii",
      "vaabbbbbbbbbbbbb",
      "vaaaaaaaaaaaaaaa",
      "vaaaaaaaaaaaaaaa",
      "vvvvvvvvvvvvvvvv"
    ],
    [
      "vaabi DEj jFm   ",
      "vaabi   jnn     ",
      "vaabi   jI      ",
      "vaabg   jJ     m",
      "vaabi   jI     K",
      "vaabi  sj     nu",
      "vaabi   jL M Mn ",
      "vaabi   huuuuuuu",
      "vaabi     s    N",
      "vaabi          O",
      "vaabi           ",
      "vaabgiiiiiiigiii",
      "vaabbbbbbbbbbbbb",
      "vaaaaaaaaaaaaaaa",
      "vaaaaaaaaaaaaaaa",
      "vvvvvvvvvvvvvvvv"
    ],
    [
      "vaabi   j jPm   ",
      "vaabi DEjnn     ",
      "vaabi   jQ      ",
      "vaabg   jR     m",
      "vaabi   jR     S",
      "vaabi  sjT    nu",
      "vaabi   j UVVWn ",
      "vaabi   huuuuuuu",
      "vaabi     s   N ",
      "vaabi         O ",
      "vaabi           ",
      "vaabgiiiiiiigiii",
      "vaabbbbbbbbbbbbb",
      "vaaaaaaaaaaaaaaa",
      "vaaaaaaaaaaaaaaa",
      "vvvvvvvvvvvvvvvv"
    ],
    [
      "vaabi   jXYYm   ",
      "vaabi   jnnZ0   ",
      "vaabi DEjZZZ0   ",
      "vaabg   jZZZZ00m",
      "vaabi   jZZ!ZZZY",
      "vaabi  sjZZZZZnY",
      "vaabi   jZZZZZnX",
      "vaabi   huuuuuuu",
      "vaabi     s  N  ",
      "vaabi        O  ",
      "vaabi           ",
      "vaabgiiiiiiigiii",
      "vaabbbbbbbbbbbbb",
      "vaaaaaaaaaaaaaaa",
      "vaaaaaaaaaaaaaaa",
      "vvvvvvvvvvvvvvvv"
    ],
    [
      "vaab    j12 m   ",
      "vaabi   j12 m   ",
      "vaabi   j1  m   ",
      "vaabg DEj12 mmmm",
      "vaabi   j122    ",
      "vaab   sj12 2 2 ",
      "vaabi   j1111111",
      "vaabi   huuuuuuu",
      "vaab      s N   ",
      "vaabi       O   ",
      "vaabi           ",
      "vaabgi ii iigi i",
      "vaabbbbbbbbbbbbb",
      "vaaaaaaaaaaaaaaa",
      "vaaaaaaaaaaaaaaa",
      "vvvvvvvvvvvvvvvv"
    ]
  ]
}