{
  "name": "multi_casino_3_base9",
  "refpalette": "deceasedcraft:multi_casino_3/multi_casino_3_base9_palette",
  "xsize": 16,
  "zsize": 16,
  "slices": [
    [
      "vaaaaaaabbbbbbbb",
      "vaaaaaaabbbbbbbb",
      "vaaaaaaabbbbbbbb",
      "vaaaaaaabbbbbbbb",
      "vaaaaaaabbbbbbbb",
      "vaaaaaaabbbbbbbb",
      "vaaaaaaabbbbbbbb",
      "vaaaaaaabbbbbbbb",
      "vaaaaaaaaaaaaaaa",
      "vaaaaaaaaaaaaaaa",
      "vaaaaaaaaaaaaaaa",
      "vaaaaaaaaaaaaaaa",
      "vaaaaaaaaaaaaaaa",
      "vaaaaaaaaaaaaaaa",
      "vaaaaaaaaaaaaaaa",
      "vvvvvvvvvvvvvvvv"
    ],
    [
      "vaaaaaaacd  @   ",
      "vaaaaaaac   ef  ",
      "vaaaaaaacg    h ",
      "vaaaaaaacij   k@",
      "vaaaaaaaci      ",
      "vaaaaaaacij     ",
      "vaaaaaaacg  lmmm",
      "vaaaaaaanccccccc",
      "vaaaaaaaaaaaaaaa",
      "vaaaaaaaaaaaaaaa",
      "vaaaaaaaaaaaaaaa",
      "vaaaaaaaaaaaaaaa",
      "vaaaaaaaaaaaaaaa",
      "vaaaaaaaaaaaaaaa",
      "vaaaaaaaaaaaaaaa",
      "vvvvvvvvvvvvvvvv"
    ],
    [
      "vaaaaaaaco  @   ",
      "vaaaaaaac   pq  ",
      "vaaaaaaacr    s ",
      "vaaaaaaacr    t@",
      "vaaaaaaacr      ",
      "vaaaaaaacu      ",
      "vaaaaaaacw    x ",
      "vaaaaaaanccccccc",
      "vaaaaaaaaaaaaaaa",
      "vaaaaaaaaaaaaaaa",
      "vaaaaaaaaaaaaaaa",
      "vaaaaaaaaaaaaaaa",
      "vaaaaaaaaaaaaaaa",
      "vaaaaaaaaaaaaaaa",
      "vaaaaaaaaaaaaaaa",
      "vvvvvvvvvvvvvvvv"
    ],
    [
      "vaaaaaaac   @   ",
      "vaaaaaaac   yA  ",
      "vaaaaaaacB    C ",
      "vaaaaaaacr    D@",
      "vaaaaaaacB      ",
      "vaaaaaaacu      ",
      "vaaaaaaacE      ",
      "vaaaaaaanccccccc",
      "vaaaaaaaaaaaaaaa",
      "vaaaaaaaaaaaaaaa",
      "vaaaaaaaaaaaaaaa",
      "vaaaaaaaaaaaaaaa",
      "vaaaaaaaaaaaaaaa",
      "vaaaaaaaaaaaaaaa",
      "vaaaaaaaaaaaaaaa",
      "vvvvvvvvvvvvvvvv"
    ],
    [
      "vaaaaaaac   F   ",
      "vaaaaaaac   FFI ",
      "vaaaaaaac     F ",
      "vaaaaaaac     FF",
      "vaaaaaaac       ",
      "vaaaaaaac       ",
      "vaaaaaaac       ",
      "vaaaaaaanccccccc",
      "vaaaaaaaaaaaaaaa",
      "vaaaaaaaaaaaaaaa",
      "vaaaaaaaaaaaaaaa",
      "vaaaaaaaaaaaaaaa",
      "vaaaaaaaaaaaaaaa",
      "vaaaaaaaaaaaaaaa",
      "vaaaaaaaaaaaaaaa",
      "vvvvvvvvvvvvvvvv"
    ],
    [
      "vaaaaaaacbbbFJJn",
      "vaaaaaaacbbbcFnJ",
      "vaaaaaaacbbbbnFJ",
      "vaaaaaaacbbbnbcF",
      "vaaaaaaacbbnbbbb",
      "vaaaaaaacbnbbbbb",
      "vaaaaaaacnbbbbbb",
      "vaaaaaaanccccccc",
      "vaaaaaaaaaaaaaaa",
      "vaaaaaaaaaaaaaaa",
      "vaaaaaaaaaaaaaaa",
      "vaaaaaaaaaaaaaaa",
      "vaaaaaaaaaaaaaaa",
      "vaaaaaaaaaaaaaaa",
      "vaaaaaaaaaaaaaaa",
      "vvvvvvvvvvvvvvvv"
    ]
  ]
}