{
  "name": "multi_casino_3_floor19",
  "refpalette": "deceasedcraft:multi_casino_3/multi_casino_3_floor19_palette",
  "xsize": 16,
  "zsize": 16,
  "slices": [
    [
      "       abccccccc",
      "      dabccccccc",
      "       abccccccc",
      "      dabccccccc",
      "       abccccccc",
      "      dabccccccc",
      "       abccccccc",
      "      daebbbbbbb",
      "       aaaaaaaaa",
      "        d d d d ",
      "                ",
      "                ",
      "                ",
      "                ",
      "                ",
      "                "
    ],
    [
      "       f ghhg   ",
      "      df  ii    ",
      "       f  jj   k",
      "      df        ",
      "       f        ",
      "      dfl      m",
      "       f        ",
      "      dfe  n   o",
      "       affffffff",
      "        d d d d ",
      "                ",
      "                ",
      "                ",
      "                ",
      "                ",
      "                "
    ],
    [
      "       f p  p   ",
      "      df        ",
      "       f       q",
      "      df       r",
      "       f        ",
      "      df       s",
      "       f        ",
      "      dfe  !    ",
      "       affffffff",
      "        d d d d ",
      "                ",
      "                ",
      "                ",
      "                ",
      "                ",
      "                "
    ],
    [
      "       f        ",
      "      df        ",
      "       f       q",
      "      df        ",
      "       f        ",
      "      df        ",
      "       f        ",
      "      dfe       ",
      "       affffffff",
      "        d d d d ",
      "                ",
      "                ",
      "                ",
      "                ",
      "                ",
      "                "
    ],
    [
      "       f        ",
      "      df        ",
      "       f       t",
      "      df        ",
      "       f        ",
      "      df        ",
      "       f        ",
      "      dfe       ",
      "       affffffff",
      "        d d d d ",
      "                ",
      "                ",
      "                ",
      "                ",
      "                ",
      "                "
    ],
    [
      "       fuwwwwwww",
      "      dfuwwwwwww",
      "       fuwwwwwww",
      "      dfuwwwwwww",
      "       fuwwwwwww",
      "      dfuwwwwwww",
      "       fuwwwwwww",
      "      dfeuuuuuuu",
      "       affffffff",
      "        d d d d ",
      "                ",
      "                ",
      "                ",
      "                ",
      "                ",
      "                "
    ]
  ]
}