{
  "name": "multi_casino_3_floor21",
  "refpalette": "deceasedcraft:multi_casino_3/multi_casino_3_floor21_palette",
  "xsize": 16,
  "zsize": 16,
  "slices": [
    [
      "       abccccccc",
      "      dabccccccc",
      "       abccccccc",
      "      dabccccccc",
      "       abccccccc",
      "      dabccccccc",
      "       abccccccc",
      "      daebbbbbbb",
      "       aaaaaaaaa",
      "        d d d d ",
      "                ",
      "                ",
      "                ",
      "                ",
      "                ",
      "                "
    ],
    [
      "       f!ghhg   ",
      "      dfi jj    ",
      "       fk ll   m",
      "      df        ",
      "       f        ",
      "      dfn      o",
      "       f        ",
      "      dfe  pq  r",
      "       affffffff",
      "        d d d d ",
      "                ",
      "                ",
      "                ",
      "                ",
      "                ",
      "                "
    ],
    [
      "       fst  u   ",
      "      df        ",
      "       f       w",
      "      df       x",
      "       f        ",
      "      df       y",
      "       f        ",
      "      dfe  A    ",
      "       affffffff",
      "        d d d d ",
      "                ",
      "                ",
      "                ",
      "                ",
      "                ",
      "                "
    ],
    [
      "       f        ",
      "      df        ",
      "       f       w",
      "      df        ",
      "       f        ",
      "      df        ",
      "       f        ",
      "      dfe       ",
      "       affffffff",
      "        d d d d ",
      "                ",
      "                ",
      "                ",
      "                ",
      "                ",
      "                "
    ],
    [
      "       f        ",
      "      df        ",
      "       f       B",
      "      df        ",
      "       f        ",
      "      df        ",
      "       f        ",
      "      dfe       ",
      "       affffffff",
      "        d d d d ",
      "                ",
      "                ",
      "                ",
      "                ",
      "                ",
      "                "
    ],
    [
      "       fCDDDDDDD",
      "      dfCDDDDDDD",
      "       fCDDDDDDD",
      "      dfCDDDDDDD",
      "       fCDDDDDDD",
      "      dfCDDDDDDD",
      "       fCDDDDDDD",
      "      dfeCCCCCCC",
      "       affffffff",
      "        d d d d ",
      "                ",
      "                ",
      "                ",
      "                ",
      "                ",
      "                "
    ]
  ]
}