{
  "name": "multi_casino_3_base4",
  "refpalette": "deceasedcraft:multi_casino_3/multi_casino_3_base4_palette",
  "xsize": 16,
  "zsize": 16,
  "slices": [
    [
      "vaabcdeddddddfff",
      "vaabcdeddddddfff",
      "vaabcdeddddddfff",
      "vaabgdeddddddddd",
      "vaabcdeddddddddd",
      "vaabcdeddddddddd",
      "vaabcdeddddddddd",
      "vaabcdedhddddddd",
      "vaabcdeddddddddd",
      "vaabcdeeeeeeeeee",
      "vaabcddddddddddd",
      "vaabgcccccccgccc",
      "vaabbbbbbbbbbbbb",
      "vaaaaaaaaaaaaaaa",
      "vaaaaaaaaaaaaaaa",
      "vvvvvvvvvvvvvvvv"
    ],
    [
      "vaabi   jkjlm   ",
      "vaabi   jnn     ",
      "vaabi   jo      ",
      "vaabgp  jq     m",
      "vaabi   jq     r",
      "vaabi  sjt    nu",
      "vaabi   jwxyyAnB",
      "vaabi   huuuuuuu",
      "vaabi     s     ",
      "vaabi           ",
      "vaabi       C   ",
      "vaabgiiiiiiigiii",
      "vaabbbbbbbbbbbbb",
      "vaaaaaaaaaaaaaaa",
      "vaaaaaaaaaaaaaaa",
      "vvvvvvvvvvvvvvvv"
    ],
    [
      "vaabi DEj jFm   ",
      "vaabi   jnn     ",
      "vaabi   jIJ     ",
      "vaabg   j      m",
      "vaabi   jI     K",
      "vaabi  sj     nu",
      "vaabi   jL M Mn ",
      "vaabi   huuuuuuu",
      "vaabi     s    N",
      "vaabi          O",
      "vaabi           ",
      "vaabgiiiiiiigiii",
      "vaabbbbbbbbbbbbb",
      "vaaaaaaaaaaaaaaa",
      "vaaaaaaaaaaaaaaa",
      "vvvvvvvvvvvvvvvv"
    ],
    [
      "vaabi   j jPm   ",
      "vaabi DEjnn     ",
      "vaabi   jQ      ",
      "vaabg   jR     m",
      "vaabi   jR     S",
      "vaabi  sjT    nu",
      "vaabi   jUVWWXn ",
      "vaabi   huuuuuuu",
      "vaabi     s   N ",
      "vaabi         O ",
      "vaabi           ",
      "vaabgiiiiiiigiii",
      "vaabbbbbbbbbbbbb",
      "vaaaaaaaaaaaaaaa",
      "vaaaaaaaaaaaaaaa",
      "vvvvvvvvvvvvvvvv"
    ],
    [
      "vaabi   jYZZm   ",
      "vaabi   jnn01   ",
      "vaabi DEj0001   ",
      "vaabg   j000011m",
      "vaabi   j002000Z",
      "vaabi  sj00000nZ",
      "vaabi   j00000nY",
      "vaabi   huuuuuuu",
      "vaabi     s  N  ",
      "vaabi        O  ",
      "vaabi           ",
      "vaabgiiiiiiigiii",
      "vaabbbbbbbbbbbbb",
      "vaaaaaaaaaaaaaaa",
      "vaaaaaaaaaaaaaaa",
      "vvvvvvvvvvvvvvvv"
    ],
    [
      "vaab    j34 m   ",
      "vaabi   j34 m   ",
      "vaabi   j3  m   ",
      "vaabg DEj34 mmmm",
      "vaabi   j344    ",
      "vaab   sj34 4 4 ",
      "vaabi   j3333333",
      "vaabi   huuuuuuu",
      "vaab      s N   ",
      "vaabi       O   ",
      "vaabi           ",
      "vaabgi ii iigi i",
      "vaabbbbbbbbbbbbb",
      "vaaaaaaaaaaaaaaa",
      "vaaaaaaaaaaaaaaa",
      "vvvvvvvvvvvvvvvv"
    ]
  ]
}