{
  "name": "multi_casino_3_floor16",
  "refpalette": "deceasedcraft:multi_casino_3/multi_casino_3_floor16_palette",
  "xsize": 16,
  "zsize": 16,
  "slices": [
    [
      "       abbbbbbbb",
      "      cabbbbbbbb",
      "       abbbbbbbb",
      "      cabbbbbbbb",
      "       abbbbbbbb",
      "      cabbbbbbbb",
      "       abbbbbbbb",
      "      cadbbbbbbb",
      "       aaaaaaaaa",
      "        c c c c ",
      "                ",
      "                ",
      "                ",
      "                ",
      "                ",
      "                "
    ],
    [
      "       e f g   h",
      "      ce ijkl mj",
      "       e ijkl  m",
      "      ce n o    ",
      "       e f g   h",
      "      ce ijkl pj",
      "       e ijkl  m",
      "      cedn o    ",
      "       aeeeeeeee",
      "        c c c c ",
      "                ",
      "                ",
      "                ",
      "                ",
      "                ",
      "                "
    ],
    [
      "       e        ",
      "      ce    q  r",
      "       e  ! q   ",
      "      ce        ",
      "       e        ",
      "      ce  s q  t",
      "       ed   q   ",
      "      ce d      ",
      "       aeeeeeeee",
      "        c c c c ",
      "                ",
      "                ",
      "                ",
      "                ",
      "                ",
      "                "
    ],
    [
      "       e        ",
      "      cu        ",
      "       e        ",
      "      cu        ",
      "       e        ",
      "      cud       ",
      "       e        ",
      "      ce  d     ",
      "       aeewewewe",
      "        c c c c ",
      "                ",
      "                ",
      "                ",
      "                ",
      "                ",
      "                "
    ],
    [
      "       e        ",
      "      cu        ",
      "       e        ",
      "      cu        ",
      "       e        ",
      "      cud       ",
      "       e        ",
      "      ce  d     ",
      "       aeewewewe",
      "        c c c c ",
      "                ",
      "                ",
      "                ",
      "                ",
      "                ",
      "                "
    ],
    [
      "       e        ",
      "      cu        ",
      "       e        ",
      "      cu        ",
      "       ed       ",
      "      cu        ",
      "       e        ",
      "      ce   d    ",
      "       aeewewewe",
      "        c c c c ",
      "                ",
      "                ",
      "                ",
      "                ",
      "                ",
      "                "
    ]
  ]
}