{
  "name": "multi_casino_3_floor28",
  "refpalette": "deceasedcraft:multi_casino_3/multi_casino_3_floor28_palette",
  "xsize": 16,
  "zsize": 16,
  "slices": [
    [
      "       abcccddbb",
      "      eabccdddcb",
      "       abccdcddc",
      "      eabccccddd",
      "       abccccdcd",
      "      eabccccccc",
      "       abccccccc",
      "      eafbbbbbbb",
      "       aaaaaaaaa",
      "        e e e e ",
      "                ",
      "                ",
      "                ",
      "                ",
      "                ",
      "                "
    ],
    [
      "       g  h     ",
      "      eg  h     ",
      "       g        ",
      "      eg        ",
      "       g   i    ",
      "      eg      jj",
      "       g ~      ",
      "      egf       ",
      "       agggggggg",
      "        e e e e ",
      "                ",
      "                ",
      "                ",
      "                ",
      "                ",
      "                "
    ],
    [
      "       g        ",
      "      eg        ",
      "       g        ",
      "      eg        ",
      "       g   ~    ",
      "      eg        ",
      "       g        ",
      "      e f       ",
      "         ggggggg",
      "        e e e e ",
      "                ",
      "                ",
      "                ",
      "                ",
      "                ",
      "                "
    ],
    [
      "       gf       ",
      "      eg        ",
      "       g        ",
      "      eg        ",
      "       g        ",
      "      e         ",
      "                ",
      "      e f      f",
      "           ggggg",
      "        e e e e ",
      "                ",
      "                ",
      "                ",
      "                ",
      "                ",
      "                "
    ],
    [
      "       g        ",
      "      egf       ",
      "       g        ",
      "      e         ",
      "                ",
      "      e         ",
      "                ",
      "      e f     f ",
      "             ggg",
      "        e e e e ",
      "                ",
      "                ",
      "                ",
      "                ",
      "                ",
      "                "
    ],
    [
      "       g        ",
      "      e         ",
      "        f       ",
      "      e k       ",
      "                ",
      "      e         ",
      "                ",
      "      e f   kf  ",
      "               g",
      "        e e e e ",
      "                ",
      "                ",
      "                ",
      "                ",
      "                ",
      "                "
    ]
  ]
}