{
  "name": "multi_casino_3_ground",
  "refpalette": "deceasedcraft:multi_casino_3/multi_casino_3_ground_palette",
  "xsize": 16,
  "zsize": 16,
  "slices": [
    [
      "HHHHabcddddddddd",
      "HHHHabcddddddddd",
      "HHHHabcddddddddd",
      "HHHHabcddddddddd",
      "HHHHabcddddddddd",
      "HHHHabcddddddddd",
      "HHeeebcddddddddd",
      "HHeefbcdgddddddd",
      "HHeeebcddddddddd",
      "HHHHabcccccccccc",
      "HHHHabbbbbbbbbbb",
      "HHHHHaaefeaaaaaa",
      "HHHHHHHeeeHHHHHH",
      "HHHHHHHeeeHHHHHH",
      "HHHHHHHHHHHHHHHH",
      "HHHHHHHHHHHHHHHH"
    ],
    [
      "     h  ij      ",
      "  kl h  i m     ",
      "     h  i  n    ",
      "     h  op      ",
      "     h  o    q  ",
      "  rs h  o t   m ",
      "  uuuw  o   p  x",
      "  uyAw  gooooiii",
      "  uuuw          ",
      "     h          ",
      "     hhBBBhhhhhh",
      "       uAu      ",
      "       uyuC   D ",
      "       uuur   E ",
      "                ",
      "                "
    ],
    [
      "        i       ",
      "        i       ",
      "        i       ",
      "        oF      ",
      "        o       ",
      "        o I     ",
      "        g   F   ",
      "   JA   Kgoooiii",
      "                ",
      "                ",
      "                ",
      "        A       ",
      "        J       ",
      "                ",
      "                ",
      "                "
    ],
    [
      "        i       ",
      "        i       ",
      "        o       ",
      "        oL      ",
      "        o       ",
      "        g       ",
      "            L   ",
      "    A     goooii",
      "                ",
      "                ",
      "                ",
      "        A       ",
      "                ",
      "                ",
      "                ",
      "                "
    ],
    [
      "        i       ",
      "        o       ",
      "        o       ",
      "        o       ",
      "        o       ",
      "        g       ",
      "                ",
      "    A     gooooi",
      "                ",
      "                ",
      "                ",
      "        A       ",
      "                ",
      "                ",
      "                ",
      "                "
    ],
    [
      "        i       ",
      "        o       ",
      "        o       ",
      "        o       ",
      "        g       ",
      "                ",
      "                ",
      "    A      goooi",
      "                ",
      "                ",
      "                ",
      "        A       ",
      "                ",
      "                ",
      "                ",
      "                "
    ]
  ]
}