{
  "name": "multi_casino_3_base7",
  "refpalette": "deceasedcraft:multi_casino_3/multi_casino_3_base7_palette",
  "xsize": 16,
  "zsize": 16,
  "slices": [
    [
      "vaab    cddde   ",
      "vaab    cddde   ",
      "vaabf   cddde   ",
      "vaabg   cdddeeee",
      "vaabf  hcddddddd",
      "vaab   ijddddddd",
      "vaab    cddddddd",
      "vaabf   klmlllll",
      "vaab      in    ",
      "vaab            ",
      "vaabf           ",
      "vaabgf  f  fgf  ",
      "vaabbbbbbbbbbbbb",
      "vaaaaaaaaaaaaaaa",
      "vaaaaaaaaaaaaaaa",
      "vvvvvvvvvvvvvvvv"
    ],
    [
      "vaab    co pq   ",
      "vaab    co  q   ",
      "vaabf   corsq   ",
      "vaabg   cq  qqqq",
      "vaab    c    tuw",
      "vaab   xy    A B",
      "vaab    cC  q   ",
      "vaab    klDlllll",
      "vaab      x     ",
      "vaab            ",
      "vaabf           ",
      "vaabg      fg   ",
      "vaabbbbbbbbbbbbb",
      "vaaaaaaaaaaaaaaa",
      "vaaaaaaaaaaaaaaa",
      "vvvvvvvvvvvvvvvv"
    ],
    [
      "vaab    cE  q   ",
      "vaab    c   q   ",
      "vaab    cFIJq   ",
      "vaabg   cq  qqKK",
      "vaab    c    L M",
      "vaab    N    O  ",
      "vaab    c  Pq   ",
      "vaab    klQlllll",
      "vaab            ",
      "vaab            ",
      "vaab            ",
      "vaabg       g   ",
      "vaabbbbbbbbbbbbb",
      "vaaaaaaaaaaaaaaa",
      "vaaaaaaaaaaaaaaa",
      "vvvvvvvvvvvvvvvv"
    ],
    [
      "vaab    c   q   ",
      "vaab    c   q   ",
      "vaab    c   q   ",
      "vaabg   cqRRqqSS",
      "vaab    c   T   ",
      "vaab    c   T   ",
      "vaab    c   q   ",
      "vaab    klllllll",
      "vaab            ",
      "vaab            ",
      "vaab            ",
      "vaabg       g   ",
      "vaabbbbbbbbbbbbb",
      "vaaaaaaaaaaaaaaa",
      "vaaaaaaaaaaaaaaa",
      "vvvvvvvvvvvvvvvv"
    ],
    [
      "vaab UUUV   qUUW",
      "vaab UUUV   qUWU",
      "vaab UUUV   qWUU",
      "vaabgUUUVqqqqqqq",
      "vaab WUUV   q   ",
      "vaab UWUV X q   ",
      "vaab UUWV   q   ",
      "vaab UUUkYYYYYYY",
      "vaab UUWUWUUUUUU",
      "vaab UWUUUWUUUUU",
      "vaab WUUUUUWUUUU",
      "vaabg       g   ",
      "vaabbbbbbbbbbbbb",
      "vaaaaaaaaaaaaaaa",
      "vaaaaaaaaaaaaaaa",
      "vvvvvvvvvvvvvvvv"
    ],
    [
      "vaabZ0111111111k",
      "vaabZ011111111k1",
      "vaabZ01111111k11",
      "vaabg1111111k111",
      "vaabZk11111k1111",
      "vaabZ0k111k11111",
      "vaabZ01k1k111111",
      "vaabZ011k1111111",
      "vaabZ01k1k111111",
      "vaabZ0k111k11111",
      "vaabZk00000k1000",
      "vaabg2222222g222",
      "vaabbbbbbbbbbbbb",
      "vaaaaaaaaaaaaaaa",
      "vaaaaaaaaaaaaaaa",
      "vvvvvvvvvvvvvvvv"
    ]
  ]
}