{
  "name": "multi_casino_3_floor27",
  "refpalette": "deceasedcraft:multi_casino_3/multi_casino_3_floor27_palette",
  "xsize": 16,
  "zsize": 16,
  "slices": [
    [
      "       a        ",
      "      ba        ",
      "       a        ",
      "      ba        ",
      "       a        ",
      "      ba        ",
      "       a        ",
      "      bac       ",
      "       aaaaaaaaa",
      "        b b b b ",
      "                ",
      "                ",
      "                ",
      "                ",
      "                ",
      "                "
    ],
    [
      "       d        ",
      "      bd        ",
      "       d        ",
      "      bd        ",
      "       d        ",
      "      bd        ",
      "       d        ",
      "      bdc       ",
      "       adddddddd",
      "        b b b b ",
      "                ",
      "                ",
      "                ",
      "                ",
      "                ",
      "                "
    ],
    [
      "       d        ",
      "      bd        ",
      "       d        ",
      "      bd        ",
      "       d        ",
      "      bd        ",
      "       d        ",
      "      bdc       ",
      "       adddddddd",
      "        b b b b ",
      "                ",
      "                ",
      "                ",
      "                ",
      "                ",
      "                "
    ],
    [
      "       d        ",
      "      bd        ",
      "       d        ",
      "      bd        ",
      "       d        ",
      "      bd        ",
      "       d        ",
      "      bdc       ",
      "       adddddddd",
      "        b b b b ",
      "                ",
      "                ",
      "                ",
      "                ",
      "                ",
      "                "
    ],
    [
      "       d        ",
      "      bd        ",
      "       d        ",
      "      bd        ",
      "       d        ",
      "      bd        ",
      "       d        ",
      "      bdc       ",
      "       adddddddd",
      "        b b b b ",
      "                ",
      "                ",
      "                ",
      "                ",
      "                ",
      "                "
    ],
    [
      "       defffffff",
      "      bdefffffff",
      "       defffffff",
      "      bdefffffff",
      "       defffffff",
      "      bdefffffff",
      "       defffffff",
      "      bdceeeeeee",
      "       adddddddd",
      "        b b b b ",
      "                ",
      "                ",
      "                ",
      "                ",
      "                ",
      "                "
    ]
  ]
}