{
  "name": "multi_casino_3_floor14",
  "refpalette": "deceasedcraft:multi_casino_3/multi_casino_3_floor14_palette",
  "xsize": 16,
  "zsize": 16,
  "slices": [
    [
      "       abbbbbbbb",
      "      cabbbbbbbb",
      "       abbbbbbbb",
      "      cabbbbbbbb",
      "       abbbbbbbb",
      "      cabbbbbbbb",
      "       abbbbbbbb",
      "      cadbbbbbbb",
      "       aaaaaaaaa",
      "        c c c c ",
      "                ",
      "                ",
      "                ",
      "                ",
      "                ",
      "                "
    ],
    [
      "       e   f   g",
      "      ce        ",
      "       e h      ",
      "      ce i      ",
      "       e j      ",
      "      ce  k     ",
      "       e   lmn  ",
      "      ced       ",
      "       aeeeeeeee",
      "        c c c c ",
      "                ",
      "                ",
      "                ",
      "                ",
      "                ",
      "                "
    ],
    [
      "       ed  o    ",
      "      ce        ",
      "       e        ",
      "      ce        ",
      "       e        ",
      "      ce  !     ",
      "       ed       ",
      "      ce d     d",
      "       aeeeeeeee",
      "        c c c c ",
      "                ",
      "                ",
      "                ",
      "                ",
      "                ",
      "                "
    ],
    [
      "       e        ",
      "      ced       ",
      "       e        ",
      "      ce        ",
      "       e        ",
      "      ced       ",
      "       e        ",
      "      ce  d   d ",
      "       aeeeeeeee",
      "        c c c c ",
      "                ",
      "                ",
      "                ",
      "                ",
      "                ",
      "                "
    ],
    [
      "       e        ",
      "      ced       ",
      "       e        ",
      "      ce        ",
      "       e        ",
      "      ced       ",
      "       e        ",
      "      ce  d   d ",
      "       aeeeeeeee",
      "        c c c c ",
      "                ",
      "                ",
      "                ",
      "                ",
      "                ",
      "                "
    ],
    [
      "       e        ",
      "      ce        ",
      "       ed       ",
      "      ce        ",
      "       ed       ",
      "      ce        ",
      "       e        ",
      "      ce   d d  ",
      "       aeeeeeeee",
      "        c c c c ",
      "                ",
      "                ",
      "                ",
      "                ",
      "                ",
      "                "
    ]
  ]
}