{
  "name": "multi_casino_3_floor17",
  "refpalette": "deceasedcraft:multi_casino_3/multi_casino_3_floor17_palette",
  "xsize": 16,
  "zsize": 16,
  "slices": [
    [
      "       a        ",
      "      bc        ",
      "       a        ",
      "      bcd       ",
      "       a        ",
      "      bc        ",
      "       a        ",
      "      be    d   ",
      "       eeafafafa",
      "        b b b b ",
      "                ",
      "                ",
      "                ",
      "                ",
      "                ",
      "                "
    ],
    [
      "       a        ",
      "      bc        ",
      "       a        ",
      "      bcd       ",
      "       a        ",
      "      bc        ",
      "       a        ",
      "      ba    d   ",
      "       eaafafafa",
      "        b b b b ",
      "                ",
      "                ",
      "                ",
      "                ",
      "                ",
      "                "
    ],
    [
      "       a        ",
      "      bc        ",
      "       ad       ",
      "      bc        ",
      "       ad       ",
      "      bc        ",
      "       a        ",
      "      ba   d d  ",
      "       eaafafafa",
      "        b b b b ",
      "                ",
      "                ",
      "                ",
      "                ",
      "                ",
      "                "
    ],
    [
      "       a        ",
      "      bgd       ",
      "       a        ",
      "      bg        ",
      "       a        ",
      "      bgd       ",
      "       a        ",
      "      ba  d   d ",
      "       eaahahaha",
      "        b b b b ",
      "                ",
      "                ",
      "                ",
      "                ",
      "                ",
      "                "
    ],
    [
      "       a        ",
      "      bad       ",
      "       a        ",
      "      ba        ",
      "       a        ",
      "      bad       ",
      "       a        ",
      "      ba  d   d ",
      "       eaaaaaaaa",
      "        b b b b ",
      "                ",
      "                ",
      "                ",
      "                ",
      "                ",
      "                "
    ],
    [
      "       adiiiiiii",
      "      bajiiiiiii",
      "       ajiiiiiii",
      "      bajiiiiiii",
      "       ajiiiiiii",
      "      bajiiiiiii",
      "       adiiiiiii",
      "      bakdjjjjjd",
      "       eaaaaaaaa",
      "        b b b b ",
      "                ",
      "                ",
      "                ",
      "                ",
      "                ",
      "                "
    ]
  ]
}