{
  "name": "multi_casino_3_floor22",
  "refpalette": "deceasedcraft:multi_casino_3/multi_casino_3_floor22_palette",
  "xsize": 16,
  "zsize": 16,
  "slices": [
    [
      "       abbbbbbbb",
      "      cabbbbbbbb",
      "       abbbbbbbb",
      "      cabbbbdebb",
      "       abb!bbbbb",
      "      cabbbbbbbb",
      "       abbbbbbbb",
      "      cafbbbbbbb",
      "       aaaaaaaaa",
      "        c c c c ",
      "                ",
      "                ",
      "                ",
      "                ",
      "                ",
      "                "
    ],
    [
      "       ghijjjjji",
      "      cgkil    i",
      "       gmil nn i",
      "      cgmil nn i",
      "       gkil    i",
      "      cgmillllli",
      "       goiiiiiii",
      "      cgfpqrqqqs",
      "       agggggggg",
      "        c c c c ",
      "                ",
      "                ",
      "                ",
      "                ",
      "                ",
      "                "
    ],
    [
      "       g        ",
      "      cg        ",
      "       g        ",
      "      cg        ",
      "       g        ",
      "      cg        ",
      "       g        ",
      "      cgf       ",
      "       agggggggg",
      "        c c c c ",
      "                ",
      "                ",
      "                ",
      "                ",
      "                ",
      "                "
    ],
    [
      "       g        ",
      "      cg        ",
      "       g        ",
      "      cg        ",
      "       g        ",
      "      cg        ",
      "       g        ",
      "      cgf       ",
      "       agggggggg",
      "        c c c c ",
      "                ",
      "                ",
      "                ",
      "                ",
      "                ",
      "                "
    ],
    [
      "       g        ",
      "      cg        ",
      "       g        ",
      "      cg        ",
      "       g        ",
      "      cg        ",
      "       g        ",
      "      cgf       ",
      "       agggggggg",
      "        c c c c ",
      "                ",
      "                ",
      "                ",
      "                ",
      "                ",
      "                "
    ],
    [
      "       g        ",
      "      cg        ",
      "       g        ",
      "      cg        ",
      "       g    t  u",
      "      cg       w",
      "       g        ",
      "      cgf       ",
      "       agggggggg",
      "        c c c c ",
      "                ",
      "                ",
      "                ",
      "                ",
      "                ",
      "                "
    ]
  ]
}