{
  "name": "multi_casino_3_floor7",
  "refpalette": "deceasedcraft:multi_casino_3/multi_casino_3_floor7_palette",
  "xsize": 16,
  "zsize": 16,
  "slices": [
    [
      "      ab        ",
      "      ab        ",
      "      ac        ",
      "      ade       ",
      "      fg        ",
      "      hg        ",
      "       g        ",
      "      hg    e   ",
      "       gggggdcbb",
      "        h hfaaaa",
      "                ",
      "                ",
      "                ",
      "                ",
      "                ",
      "                "
    ],
    [
      "      ab        ",
      "      ab        ",
      "      ac        ",
      "      ade       ",
      "       i        ",
      "      hi        ",
      "       i        ",
      "      hi    e   ",
      "       giiiidcbb",
      "        h h aaaa",
      "                ",
      "                ",
      "                ",
      "                ",
      "                ",
      "                "
    ],
    [
      "      ab        ",
      "      ac        ",
      "      ad        ",
      "      hi        ",
      "       ie       ",
      "      hi        ",
      "       i        ",
      "      hi   e    ",
      "       giiiiidcb",
      "        h h haaa",
      "                ",
      "                ",
      "                ",
      "                ",
      "                ",
      "                "
    ],
    [
      "      ac        ",
      "      ad        ",
      "      fi        ",
      "      hi        ",
      "       i        ",
      "      hie       ",
      "       i        ",
      "      hi  e     ",
      "       giiiiiidc",
      "        h h hfaa",
      "                ",
      "                ",
      "                ",
      "                ",
      "                ",
      "                "
    ],
    [
      "      ac        ",
      "      ad        ",
      "       i        ",
      "      hi        ",
      "       i        ",
      "      hie       ",
      "       i        ",
      "      hi  e     ",
      "       giiiiiidc",
      "        h h h aa",
      "                ",
      "                ",
      "                ",
      "                ",
      "                ",
      "                "
    ],
    [
      "      ad        ",
      "      hi        ",
      "       i        ",
      "      hi        ",
      "       i        ",
      "      hi        ",
      "       ie       ",
      "      hije      ",
      "       giiiiiiid",
      "        h h h ha",
      "                ",
      "                ",
      "                ",
      "                ",
      "                ",
      "                "
    ]
  ]
}