{
  "name": "multi_casino_3_base5",
  "refpalette": "deceasedcraft:multi_casino_3/multi_casino_3_base5_palette",
  "xsize": 16,
  "zsize": 16,
  "slices": [
    [
      "vaab    cddde   ",
      "vaab    cddde   ",
      "vaabf   cddde   ",
      "vaabg   cdddeeee",
      "vaabf hicddddddd",
      "vaab   jkddddddd",
      "vaab    cddddddd",
      "vaabf   lmnmmmmm",
      "vaab      jo    ",
      "vaab       p    ",
      "vaabf           ",
      "vaabgf  f  fgf  ",
      "vaabbbbbbbbbbbbb",
      "vaaaaaaaaaaaaaaa",
      "vaaaaaaaaaaaaaaa",
      "vvvvvvvvvvvvvvvv"
    ],
    [
      "vaab    cq  r   ",
      "vaab    cq  r   ",
      "vaabf   cqstr   ",
      "vaabg   cr  rrrr",
      "vaab    c    uwx",
      "vaab  h y    A B",
      "vaab   pcC  r   ",
      "vaab    lmDmmmmm",
      "vaab     h      ",
      "vaab      p     ",
      "vaabf           ",
      "vaabg      fg   ",
      "vaabbbbbbbbbbbbb",
      "vaaaaaaaaaaaaaaa",
      "vaaaaaaaaaaaaaaa",
      "vvvvvvvvvvvvvvvv"
    ],
    [
      "vaab    cE  r   ",
      "vaab    cF  r   ",
      "vaab    c IJr   ",
      "vaabg   cr  rrKK",
      "vaab    c    L M",
      "vaab    N    O  ",
      "vaab    c  Pr   ",
      "vaab    lmQmmmmm",
      "vaab            ",
      "vaab            ",
      "vaab            ",
      "vaabg       g   ",
      "vaabbbbbbbbbbbbb",
      "vaaaaaaaaaaaaaaa",
      "vaaaaaaaaaaaaaaa",
      "vvvvvvvvvvvvvvvv"
    ],
    [
      "vaab    c   r   ",
      "vaab    c   r   ",
      "vaab    c   r   ",
      "vaabg   crRRrrSS",
      "vaab    c   T   ",
      "vaab    c   T   ",
      "vaab    c   r   ",
      "vaab    lmmmmmmm",
      "vaab            ",
      "vaab            ",
      "vaab            ",
      "vaabg       g   ",
      "vaabbbbbbbbbbbbb",
      "vaaaaaaaaaaaaaaa",
      "vaaaaaaaaaaaaaaa",
      "vvvvvvvvvvvvvvvv"
    ],
    [
      "vaab UUUV   rUUW",
      "vaab UUUV   rUWU",
      "vaab UUUV   rWUU",
      "vaabgUUUVrrrrrrr",
      "vaab WUUV   r   ",
      "vaab UWUV X r   ",
      "vaab UUWV   r   ",
      "vaab UUUlYYYYYYY",
      "vaab UUWUWUUUUUU",
      "vaab UWUUUWUUUUU",
      "vaab WUUUUUWUUUU",
      "vaabg       g   ",
      "vaabbbbbbbbbbbbb",
      "vaaaaaaaaaaaaaaa",
      "vaaaaaaaaaaaaaaa",
      "vvvvvvvvvvvvvvvv"
    ],
    [
      "vaabZ0111111111l",
      "vaabZ011111111l1",
      "vaabZ01111111l11",
      "vaabg1111111l111",
      "vaabZl11111l1111",
      "vaabZ0l111l11111",
      "vaabZ01l1l111111",
      "vaabZ011l1111111",
      "vaabZ01l1l111111",
      "vaabZ0l111l11111",
      "vaabZl00000l1000",
      "vaabg2222222g222",
      "vaabbbbbbbbbbbbb",
      "vaaaaaaaaaaaaaaa",
      "vaaaaaaaaaaaaaaa",
      "vvvvvvvvvvvvvvvv"
    ]
  ]
}