{
  "name": "multi_casino_3_floor10",
  "refpalette": "deceasedcraft:multi_casino_3/multi_casino_3_floor10_palette",
  "xsize": 16,
  "zsize": 16,
  "slices": [
    [
      "       abbbbbbbb",
      "      cabbbbbbbb",
      "       abbbbbbbb",
      "      cabbbbbbbb",
      "       abbbbbbbb",
      "      cabbbbbbbb",
      "       abbbbbbbb",
      "      cadbbbbbbb",
      "       aaaaaaaaa",
      "        c c c c ",
      "                ",
      "                ",
      "                ",
      "                ",
      "                ",
      "                "
    ],
    [
      "       e   fff  ",
      "      ce   gh   ",
      "       e       f",
      "      cei     jf",
      "       e k    lf",
      "      ce  m     ",
      "       e   n    ",
      "      ced   i   ",
      "       aeeeeeeee",
      "        c c c c ",
      "                ",
      "                ",
      "                ",
      "                ",
      "                ",
      "                "
    ],
    [
      "       ed       ",
      "      ce        ",
      "       e        ",
      "      ceo       ",
      "       e        ",
      "      ce  p     ",
      "       ed       ",
      "      ce d  o  d",
      "       aeeeeeeee",
      "        c c c c ",
      "                ",
      "                ",
      "                ",
      "                ",
      "                ",
      "                "
    ],
    [
      "       e        ",
      "      ced       ",
      "       e        ",
      "      ceq       ",
      "       e        ",
      "      ced       ",
      "       e        ",
      "      ce  d q d ",
      "       aeeeeeeee",
      "        c c c c ",
      "                ",
      "                ",
      "                ",
      "                ",
      "                ",
      "                "
    ],
    [
      "       e        ",
      "      ced       ",
      "       e        ",
      "      ce        ",
      "       e        ",
      "      ced       ",
      "       e        ",
      "      ce  d   d ",
      "       aeeeeeeee",
      "        c c c c ",
      "                ",
      "                ",
      "                ",
      "                ",
      "                ",
      "                "
    ],
    [
      "       e        ",
      "      ce        ",
      "       ed       ",
      "      ce        ",
      "       ed       ",
      "      ce        ",
      "       e        ",
      "      ce   d d  ",
      "       aeeeeeeee",
      "        c c c c ",
      "                ",
      "                ",
      "                ",
      "                ",
      "                ",
      "                "
    ]
  ]
}