{
  "name": "multi_casino_3_floor20",
  "refpalette": "deceasedcraft:multi_casino_3/multi_casino_3_floor20_palette",
  "xsize": 16,
  "zsize": 16,
  "slices": [
    [
      "       abccccccc",
      "      dabccccccc",
      "       abccccccc",
      "      dabccccccc",
      "       abccccccc",
      "      dabccccccc",
      "       abccccccc",
      "      daebbbbbbb",
      "       aaaaaaaaa",
      "        d d d d ",
      "                ",
      "                ",
      "                ",
      "                ",
      "                ",
      "                "
    ],
    [
      "       f ghhg   ",
      "      df  ii    ",
      "       f  jj   k",
      "      df        ",
      "       f        ",
      "      dfl      m",
      "       f        ",
      "      dfe  n    ",
      "       affffffff",
      "        d d d d ",
      "                ",
      "                ",
      "                ",
      "                ",
      "                ",
      "                "
    ],
    [
      "       f o  p   ",
      "      df        ",
      "       f       q",
      "      df       r",
      "       f        ",
      "      df       s",
      "       f        ",
      "      dfe  t    ",
      "       affffffff",
      "        d d d d ",
      "                ",
      "                ",
      "                ",
      "                ",
      "                ",
      "                "
    ],
    [
      "       f        ",
      "      df        ",
      "       f       q",
      "      df        ",
      "       f        ",
      "      df        ",
      "       f        ",
      "      dfe       ",
      "       affffffff",
      "        d d d d ",
      "                ",
      "                ",
      "                ",
      "                ",
      "                ",
      "                "
    ],
    [
      "       f        ",
      "      df        ",
      "       f       u",
      "      df        ",
      "       f        ",
      "      df        ",
      "       f        ",
      "      dfe       ",
      "       affffffff",
      "        d d d d ",
      "                ",
      "                ",
      "                ",
      "                ",
      "                ",
      "                "
    ],
    [
      "       fwxxxxxxx",
      "      dfwxxxxxxx",
      "       fwxxxxxxx",
      "      dfwxxxxxxx",
      "       fwxxxxxxx",
      "      dfwxxxxxxx",
      "       fwxxxxxxx",
      "      dfewwwwwww",
      "       affffffff",
      "        d d d d ",
      "                ",
      "                ",
      "                ",
      "                ",
      "                ",
      "                "
    ]
  ]
}