{
  "name": "multi_casino_3_floor3",
  "refpalette": "deceasedcraft:multi_casino_3/multi_casino_3_floor3_palette",
  "xsize": 16,
  "zsize": 16,
  "slices": [
    [
      "      a bccccccc",
      "      a bccccccc",
      "      a bccccccc",
      "      d eccccccc",
      "      a bccccccc",
      "      a bccccccc",
      "      a bccccccc",
      "      d bbbbebbb",
      "      a         ",
      "      aadaaadaaa",
      "                ",
      "                ",
      "                ",
      "                ",
      "                ",
      "                "
    ],
    [
      "      a bf      ",
      "      a bghf    ",
      "      a bbbbbbbb",
      "      d e    iii",
      "      a bj k  i ",
      "      a b l     ",
      "      a bm n o o",
      "      d bbbbebbb",
      "      a         ",
      "      aadaaadaaa",
      "                ",
      "                ",
      "                ",
      "                ",
      "                ",
      "                "
    ],
    [
      "      a b       ",
      "      a bgf     ",
      "      a bbbbbbbb",
      "      d b    ii ",
      "      a epqr    ",
      "      a bs t    ",
      "      a buwx y y",
      "      d bbbebbbb",
      "      a         ",
      "      aadaaadaaa",
      "                ",
      "                ",
      "                ",
      "                ",
      "                ",
      "                "
    ],
    [
      "      a b       ",
      "      a b!      ",
      "      a bbbbbbbb",
      "      d b       ",
      "      a bABC    ",
      "      a eD E    ",
      "      a bFIJKLKL",
      "      d bbebbbbb",
      "      a         ",
      "      aadaaadaaa",
      "                ",
      "                ",
      "                ",
      "                ",
      "                ",
      "                "
    ],
    [
      "      a b       ",
      "      a b       ",
      "      a bbbbbbbb",
      "      d b       ",
      "      a bMNO    ",
      "      a eP Q    ",
      "      a bRST    ",
      "      d bbebbbbb",
      "      a         ",
      "      aadaaadaaa",
      "                ",
      "                ",
      "                ",
      "                ",
      "                ",
      "                "
    ],
    [
      "      a b       ",
      "      d bUUUUUUU",
      "      a bbbbbbbb",
      "      d b       ",
      "      a bVWX    ",
      "      d bYZ0    ",
      "      a e123    ",
      "      d  ebbbbbb",
      "      a         ",
      "      dadadadada",
      "                ",
      "                ",
      "                ",
      "                ",
      "                ",
      "                "
    ]
  ]
}