{
  "name": "multi_casino_3_floor26",
  "refpalette": "deceasedcraft:multi_casino_3/multi_casino_3_floor26_palette",
  "xsize": 16,
  "zsize": 16,
  "slices": [
    [
      "       abbbbbbbb",
      "      cabbbbbbbb",
      "       abbbbbbbb",
      "      cabbbbbbbb",
      "       abbbbbbbb",
      "      cabbbbbbbb",
      "       abbbbbbbb",
      "      cadbbbbbbb",
      "       aaaaaaaaa",
      "        c c c c ",
      "                ",
      "                ",
      "                ",
      "                ",
      "                ",
      "                "
    ],
    [
      "       efg      ",
      "      ce     h  ",
      "       e    ij  ",
      "      ce  klmn  ",
      "       e  klmj  ",
      "      ceo   in p",
      "       eqr   s  ",
      "      ced       ",
      "       aeeeeeeee",
      "        c c c c ",
      "                ",
      "                ",
      "                ",
      "                ",
      "                ",
      "                "
    ],
    [
      "       et       ",
      "      ce     u  ",
      "       e    wj  ",
      "      ce     n x",
      "       e     j  ",
      "      cey   An B",
      "       e     C  ",
      "      ced       ",
      "       aeeeeeeee",
      "        c c c c ",
      "                ",
      "                ",
      "                ",
      "                ",
      "                ",
      "                "
    ],
    [
      "       e        ",
      "      ce        ",
      "       e     D  ",
      "      ce     D  ",
      "       e     E  ",
      "      ce     D  ",
      "       e        ",
      "      ced       ",
      "       aeeeeeeee",
      "        c c c c ",
      "                ",
      "                ",
      "                ",
      "                ",
      "                ",
      "                "
    ],
    [
      "       e        ",
      "      ce        ",
      "       e        ",
      "      ce        ",
      "       e        ",
      "      ce        ",
      "       e        ",
      "      ced       ",
      "       aeeeeeeee",
      "        c c c c ",
      "                ",
      "                ",
      "                ",
      "                ",
      "                ",
      "                "
    ],
    [
      "       e        ",
      "      ce        ",
      "       e        ",
      "      ce        ",
      "       e        ",
      "      ce        ",
      "       e        ",
      "      ced       ",
      "       aeeeeeeee",
      "        c c c c ",
      "                ",
      "                ",
      "                ",
      "                ",
      "                ",
      "                "
    ]
  ]
}