{
  "name": "multi_casino_3_base8",
  "refpalette": "deceasedcraft:multi_casino_3/multi_casino_3_base8_palette",
  "xsize": 16,
  "zsize": 16,
  "slices": [
    [
      "vaabcdeddddddfff",
      "vaabcdeddddddfff",
      "vaabcdeddddddfff",
      "vaabgdeddddddddd",
      "vaabcdeddddddddd",
      "vaabcdeddddddddd",
      "vaabcdeddddddddd",
      "vaabcdedhddddddd",
      "vaabcdeddddddddd",
      "vaabcdeeeeeeeeee",
      "vaabcddddddddddd",
      "vaabgcccccccgccc",
      "vaabbbbbbbbbbbbb",
      "vaaaaaaaaaaaaaaa",
      "vaaaaaaaaaaaaaaa",
      "vvvvvvvvvvvvvvvv"
    ],
    [
      "vaabi   jkjlm   ",
      "vaabi   jnn     ",
      "vaabi   jo      ",
      "vaabgp  jq     m",
      "vaabi   jq     r",
      "vaabi  sjt    nu",
      "vaabi   jwxyyAnB",
      "vaabi   huuuuuuu",
      "vaabi     s     ",
      "vaabi           ",
      "vaabi       C   ",
      "vaabgiiiiiiigiii",
      "vaabbbbbbbbbbbbb",
      "vaaaaaaaaaaaaaaa",
      "vaaaaaaaaaaaaaaa",
      "vvvvvvvvvvvvvvvv"
    ],
    [
      "vaabi  Dj jEm   ",
      "vaabi   jnn     ",
      "vaabi   jFI     ",
      "vaabg   j      m",
      "vaabi   jF     J",
      "vaabi  sj     nu",
      "vaabi   jKLM Mn ",
      "vaabi   huuuuuuu",
      "vaabi     s    N",
      "vaabi           ",
      "vaabi           ",
      "vaabgiiiiiiigiii",
      "vaabbbbbbbbbbbbb",
      "vaaaaaaaaaaaaaaa",
      "vaaaaaaaaaaaaaaa",
      "vvvvvvvvvvvvvvvv"
    ],
    [
      "vaabi   j jOm   ",
      "vaabi  Djnn     ",
      "vaabi   jP      ",
      "vaabg   jQ     m",
      "vaabi   jQ     R",
      "vaabi  sjS    nu",
      "vaabi   jTUVVWn ",
      "vaabi   huuuuuuu",
      "vaabi     s   N ",
      "vaabi           ",
      "vaabi           ",
      "vaabgiiiiiiigiii",
      "vaabbbbbbbbbbbbb",
      "vaaaaaaaaaaaaaaa",
      "vaaaaaaaaaaaaaaa",
      "vvvvvvvvvvvvvvvv"
    ],
    [
      "vaabi   jXYYm   ",
      "vaabi   jnnZ0   ",
      "vaabi  DjZZZ0   ",
      "vaabg   jZZZZ00m",
      "vaabi   jZZ1ZZZY",
      "vaabi  sjZZZZZnY",
      "vaabi   jZZZZZnX",
      "vaabi   huuuuuuu",
      "vaabi     s  N  ",
      "vaabi           ",
      "vaabi           ",
      "vaabgiiiiiiigiii",
      "vaabbbbbbbbbbbbb",
      "vaaaaaaaaaaaaaaa",
      "vaaaaaaaaaaaaaaa",
      "vvvvvvvvvvvvvvvv"
    ],
    [
      "vaab    j23 m   ",
      "vaabi   j23 m   ",
      "vaabi   j2  m   ",
      "vaabg  Dj23 mmmm",
      "vaabi   j233    ",
      "vaab   sj23 3 3 ",
      "vaabi   j2222222",
      "vaabi   huuuuuuu",
      "vaab      s N   ",
      "vaabi           ",
      "vaabi           ",
      "vaabgi ii iigi i",
      "vaabbbbbbbbbbbbb",
      "vaaaaaaaaaaaaaaa",
      "vaaaaaaaaaaaaaaa",
      "vvvvvvvvvvvvvvvv"
    ]
  ]
}