{
  "name": "multi_casino_3_floor25",
  "refpalette": "deceasedcraft:multi_casino_3/multi_casino_3_floor25_palette",
  "xsize": 16,
  "zsize": 16,
  "slices": [
    [
      "       a        ",
      "      ba        ",
      "       a    c   ",
      "      ba        ",
      "       a    d   ",
      "      ba        ",
      "       a        ",
      "      bae       ",
      "       aaaaaaaaa",
      "        b b b b ",
      "                ",
      "                ",
      "                ",
      "                ",
      "                ",
      "                "
    ],
    [
      "       f       g",
      "      bf       g",
      "       f    d  g",
      "      bf       g",
      "       f    d  g",
      "      bf       g",
      "       f       g",
      "      bfe       ",
      "       affffffff",
      "        b b b b ",
      "                ",
      "                ",
      "                ",
      "                ",
      "                ",
      "                "
    ],
    [
      "       f        ",
      "      bf        ",
      "       f    d   ",
      "      bf   c   g",
      "       f    d  g",
      "      bf       g",
      "       f       g",
      "      bfe       ",
      "       affffffff",
      "        b b b b ",
      "                ",
      "                ",
      "                ",
      "                ",
      "                ",
      "                "
    ],
    [
      "       f        ",
      "      bf  h   h ",
      "       f    d   ",
      "      bf   d c g",
      "       f    d  g",
      "      bf  h   hg",
      "       f       g",
      "      bfe       ",
      "       affffffff",
      "        b b b b ",
      "                ",
      "                ",
      "                ",
      "                ",
      "                ",
      "                "
    ],
    [
      "       f        ",
      "      bf  iijii ",
      "       f  i k i ",
      "      bf  lk kmg",
      "       f  i k ig",
      "      bf  iijiig",
      "       f       g",
      "      bfe       ",
      "       affffffff",
      "        b b b b ",
      "                ",
      "                ",
      "                ",
      "                ",
      "                ",
      "                "
    ],
    [
      "       fnoooooop",
      "      bfnooqqqop",
      "       fnoqrsrqp",
      "      bfnoqsssqo",
      "       fnoqrsrqo",
      "      bfnooqqqoo",
      "       fnooooooo",
      "      bfennnnnnn",
      "       affffffff",
      "        b b b b ",
      "                ",
      "                ",
      "                ",
      "                ",
      "                ",
      "                "
    ]
  ]
}