{
  "name": "multi_casino_3_floor18",
  "refpalette": "deceasedcraft:multi_casino_3/multi_casino_3_floor18_palette",
  "xsize": 16,
  "zsize": 16,
  "slices": [
    [
      "       abccccccc",
      "      dabccccccc",
      "       abccccccc",
      "      dabccccccc",
      "       abccccccc",
      "      dabccccccc",
      "       abccccccc",
      "      daebbbbbbb",
      "       aaaaaaaaa",
      "        d d d d ",
      "                ",
      "                ",
      "                ",
      "                ",
      "                ",
      "                "
    ],
    [
      "       f ghhg   ",
      "      df  ii    ",
      "       f  jj   k",
      "      df        ",
      "       f        ",
      "      dfl      m",
      "       fn       ",
      "      dfe  o   p",
      "       affffffff",
      "        d d d d ",
      "                ",
      "                ",
      "                ",
      "                ",
      "                ",
      "                "
    ],
    [
      "       f q  r   ",
      "      df        ",
      "       f       s",
      "      df       t",
      "       f        ",
      "      df       u",
      "       f        ",
      "      dfe  w    ",
      "       affffffff",
      "        d d d d ",
      "                ",
      "                ",
      "                ",
      "                ",
      "                ",
      "                "
    ],
    [
      "       f        ",
      "      df        ",
      "       f       s",
      "      df        ",
      "       f        ",
      "      df        ",
      "       f        ",
      "      dfe       ",
      "       affffffff",
      "        d d d d ",
      "                ",
      "                ",
      "                ",
      "                ",
      "                ",
      "                "
    ],
    [
      "       f        ",
      "      df        ",
      "       f       x",
      "      df        ",
      "       f        ",
      "      df        ",
      "       f        ",
      "      dfe       ",
      "       affffffff",
      "        d d d d ",
      "                ",
      "                ",
      "                ",
      "                ",
      "                ",
      "                "
    ],
    [
      "       fyAAAAAAA",
      "      dfyAAAAAAA",
      "       fyAAAAAAA",
      "      dfyAAAAAAA",
      "       fyAAAAAAA",
      "      dfyAAAAAAA",
      "       fyAAAAAAA",
      "      dfeyyyyyyy",
      "       affffffff",
      "        d d d d ",
      "                ",
      "                ",
      "                ",
      "                ",
      "                ",
      "                "
    ]
  ]
}