{
  "name": "multi_planecrash1_5_ground",
  "refpalette": "deceasedcraft:multi_planecrash1_5/multi_planecrash1_5_ground_palette",
  "xsize": 16,
  "zsize": 16,
  "slices": [
    [
      "aaaaaaaaaaaaaaaa",
      "aaaaaaaaaaaaaaaa",
      "aaaaaaaaaaaaaaaa",
      "aabaaaaaaaaaaaaa",
      "aaaaaaaaaaaaaacc",
      "aaaaaaaaaaaaaccc",
      "aaaaaaaaaaaaccca",
      "aaaaaaaaaaaaccaa",
      "aaaaaaaaaaaccaaa",
      "aaaaaaaaaaccaaaa",
      "aaaaaaaaaccaaaaa",
      "aaaaaaaaccccaaaa",
      "aaaaaaaccccccaaa",
      "aaaaaaccccccccaa",
      "aaaaacccccccccca",
      "caaacccccccccccc"
    ],
    [
      "aacaaacacacccccc",
      "deafcacccccccccc",
      "agahcaaccccccccc",
      "agifaaaacccccccc",
      "ajklacaccccccccc",
      "amkmaccccccccccc",
      "aabaaccccccccccc",
      "aabaaccccccccccc",
      "caaacccccccccccc",
      "ccaccccccccccccc",
      "cccccccccccccccc",
      "cccccccccccccccc",
      "cccccccccccccccc",
      "cccccccccccccccc",
      "cccccccccccccccc",
      "cccccccccccccccc"
    ],
    [
      "aacaaacacacccccc",
      "gaaafacccccccccc",
      "daanoaaccccccccc",
      "dpaqraaacccccccc",
      "agggacaccccccccc",
      "agggaccccccccccc",
      "agggaccccccccccc",
      "adgraccccccccccc",
      "casacccccccccccc",
      "ccaccccccccccccc",
      "cccccccccccccccc",
      "cccccccccccccccc",
      "cccccccccccccccc",
      "cccccccccccccccc",
      "cccccccccccccccc",
      "cccccccccccccccc"
    ],
    [
      "aacaaacacacccccc",
      "tgaeaacccccccccc",
      "alafuaaccccccccc",
      "alvgaaaacccccccc",
      "agggacaccccccccc",
      "awgxaccccccccccc",
      "adgraccccccccccc",
      "cakacccccccccccc",
      "cccccccccccccccc",
      "cccccccccccccccc",
      "cccccccccccccccc",
      "cccccccccccccccc",
      "cccccccccccccccc",
      "cccccccccccccccc",
      "cccccccccccccccc",
      "cccccccccccccccc"
    ],
    [
      "aacaaacacacccccc",
      "atataacccccccccc",
      "atatuaaccccccccc",
      "aagaaaaacccccccc",
      "aagaacaccccccccc",
      "cagacccccccccccc",
      "ccgccccccccccccc",
      "cckccccccccccccc",
      "ccyccccccccccccc",
      "cccccccccccccccc",
      "cccccccccccccccc",
      "cccccccccccccccc",
      "cccccccccccccccc",
      "cccccccccccccccc",
      "cccccccccccccccc",
      "cccccccccccccccc"
    ],
    [
      "accccacacacccccc",
      "aaaaaccccccccccc",
      "aatauaaccccccccc",
      "cazaaaaacccccccc",
      "cagaccaccccccccc",
      "ccgccccccccccccc",
      "ccgccccccccccccc",
      "ccgccccccccccccc",
      "cckccccccccccccc",
      "cccccccccccccccc",
      "cccccccccccccccc",
      "cccccccccccccccc",
      "cccccccccccccccc",
      "cccccccccacccccc",
      "cccccccccccccccc",
      "ccccccccccccccca"
    ]
  ]
}