{
  "name": "multi_verticalschool_6_floor26",
  "refpalette": "deceasedcraft:multi_verticalschool_6/multi_verticalschool_6_floor26_palette",
  "xsize": 16,
  "zsize": 16,
  "slices": [
    [
      "aaaaaaaaaaaaaaaa",
      "abbbccccccccdddd",
      "aceeeeeeeeecdddd",
      "aceeeeeeeeecdddd",
      "aceeeeeeeeecdddd",
      "aceeeeeeeeecdddd",
      "acccccccccccdddd",
      "aceeeeeeeeecdddd",
      "aceeeeeeeeecdddd",
      "aceeeeeeeeecdddd",
      "aceeeeeeeeecdddd",
      "acccccccccccdddd",
      "acfffffffffcdddd",
      "acfffffffffcdddd",
      "acfffffffffcdddd",
      "acfffffffffcdddd"
    ],
    [
      "gggggggggggggggg",
      "hbbbcccccccci  i",
      "hcjkjkjk        ",
      "hc k k k        ",
      "hclmlmlm   c    ",
      "hc       nnc    ",
      "hccccccccccc    ",
      "hc       ooc    ",
      "hcpqpqpq   c    ",
      "hc k k k        ",
      "hcrkrkrk        ",
      "hccccccccccc    ",
      "hcs  tu wxyc    ",
      "hcA BC     D    ",
      "hcs  Eu    F    ",
      "hcA      IIc    "
    ],
    [
      "                ",
      " bbbJJJJJJJJ    ",
      " J k k k        ",
      " J k k k        ",
      " JKmKmKm   J    ",
      " J      L  J    ",
      " JJJJJJJJJJJ    ",
      " J      M  J    ",
      " JNqNqNq   J    ",
      " J k k k        ",
      " J k k k        ",
      " JJJJJJJJJJJ    ",
      " J!  O     J    ",
      " JP        Q    ",
      " JR  S     T    ",
      " JU      VWJ    "
    ],
    [
      "                ",
      " bbbJJJJJJJJ    ",
      " J k k k   X    ",
      " J k k k   X    ",
      " Jmmmmmm   J    ",
      " J       YZJ    ",
      " JJJJJJJJJJJ    ",
      " J       01J    ",
      " Jqqqqqq   J    ",
      " J k k k   X    ",
      " J k k k   X    ",
      " JJJJJJJJJJJ    ",
      " J         J    ",
      " J         X    ",
      " J         X    ",
      " J         J    "
    ],
    [
      "                ",
      " bbbJJJJJJJJ    ",
      " 2         J    ",
      " 2         J    ",
      " 2         J    ",
      " 2         J    ",
      " JJJJJJJJJJJ    ",
      " 2         J    ",
      " 2         J    ",
      " 2         J    ",
      " 2         J    ",
      " JJJJJJJJJJJ    ",
      " 2         J    ",
      " 2         J    ",
      " 2         J    ",
      " 2         J    "
    ],
    [
      "3333333333333333",
      "3bbbJJJJJJJJ4444",
      "3J555555555J6666",
      "3J555555555J6666",
      "3J555555555J6666",
      "3J555555555J6666",
      "3JJJJJJJJJJJ6776",
      "3J555555555J6666",
      "3J555555555J6666",
      "3J555555555J6666",
      "3J555555555J6666",
      "3JJJJJJJJJJJ6886",
      "3J555555555J6666",
      "3J559555955J6666",
      "3J559555955J6666",
      "3J555555555J6666"
    ]
  ]
}