{
  "name": "multi_verticalschool_6_floor2",
  "refpalette": "deceasedcraft:multi_verticalschool_6/multi_verticalschool_6_floor2_palette",
  "xsize": 16,
  "zsize": 16,
  "slices": [
    [
      "  a             ",
      " bbb            ",
      "     cddeee     ",
      "     cdfg       ",
      "     cdfg       ",
      "     cdfh       ",
      "     cdfh       ",
      "     cdfh       ",
      "     cdfh       ",
      "     cdfh       ",
      "     cddeee     ",
      "                ",
      "                ",
      "                ",
      "                ",
      "                "
    ],
    [
      "  i             ",
      " bbb            ",
      "   cddeee       ",
      "   cdfg         ",
      "   cdfg         ",
      "   cdfg         ",
      "   cdfg         ",
      "   cdfh         ",
      "   cdfh         ",
      "   cdfh         ",
      "   cddeee       ",
      "                ",
      "                ",
      "                ",
      "                ",
      "                "
    ],
    [
      "                ",
      " bbb            ",
      "ccddeee         ",
      "ccdfh           ",
      "ccdfh           ",
      "ccdfh           ",
      "ccdfh           ",
      "ccdfh           ",
      "ccdfh           ",
      "ccdfh           ",
      "ccddeee         ",
      "j               ",
      "j               ",
      "kkkkkkkkkkkkkkkk",
      "llllllllllllllll",
      "kkkkkkkkkkkkkkkk"
    ],
    [
      "                ",
      " bbb            ",
      "ddeee           ",
      "ffg             ",
      "ffg             ",
      "ffg             ",
      "ffh             ",
      "ffh             ",
      "ffh             ",
      "ffh             ",
      "fdeee           ",
      "fd              ",
      "fddddddddddddddd",
      "ffffffffffffffff",
      "ffffffffffffffff",
      "ffffffffffffffff"
    ],
    [
      "                ",
      " bbb            ",
      "eee             ",
      "                ",
      "                ",
      "                ",
      "                ",
      "                ",
      "                ",
      "                ",
      " ee             ",
      " e              ",
      " eeeeeeeeeeeeeee",
      "                ",
      "                ",
      "                "
    ],
    [
      "                ",
      " bbb            ",
      "                ",
      "                ",
      "                ",
      "                ",
      "                ",
      "                ",
      "                ",
      "                ",
      "                ",
      "                ",
      "                ",
      "                ",
      "                ",
      "                "
    ]
  ]
}