{
  "name": "multi_verticalschool_6_floor4",
  "refpalette": "deceasedcraft:multi_verticalschool_6/multi_verticalschool_6_floor4_palette",
  "xsize": 16,
  "zsize": 16,
  "slices": [
    [
      "   aaaaaaaaaabbb",
      " cccddddddddaeee",
      " addddddddaaeeee",
      "adddddddaaeeeeee",
      "adddddaaeeeeeeeb",
      "adddaaeeeeeebbb ",
      "adaaeeeeebbb    ",
      "aaeeeebbb       ",
      "beebbb          ",
      " bb             ",
      "                ",
      "               f",
      "           fffg ",
      "       fffg     ",
      "   fffg         ",
      "  g             "
    ],
    [
      "                ",
      " ccc hi   i     ",
      "       i h      ",
      "  g i           ",
      "    h           ",
      " hi             ",
      "                ",
      "                ",
      "                ",
      "                ",
      "                ",
      "                ",
      "              j ",
      "          j     ",
      "      j         ",
      "  j             "
    ],
    [
      "                ",
      " ccc            ",
      "                ",
      " kj             ",
      "                ",
      "                ",
      "                ",
      "                ",
      "                ",
      "                ",
      "                ",
      "                ",
      "              f ",
      "          f     ",
      "      f         ",
      "  f             "
    ],
    [
      "                ",
      " ccc            ",
      "                ",
      " kkk            ",
      "  k             ",
      "                ",
      "                ",
      "                ",
      "                ",
      "                ",
      "                ",
      "                ",
      "                ",
      "                ",
      "                ",
      "                "
    ],
    [
      "                ",
      " ccc            ",
      "                ",
      "                ",
      "                ",
      "                ",
      "                ",
      "                ",
      "                ",
      "                ",
      "                ",
      "                ",
      "                ",
      "                ",
      "                ",
      "                "
    ],
    [
      "lmmmlmmmlmmmlmmn",
      "lccclmmmlmmmlmmn",
      "lmmmlmmmlmmmlmmn",
      "lmmmlmmmlmmmlmmn",
      "lmmmlmmmlmmmlmmn",
      "lmmmlmmmlmmmlmmn",
      "lmmmlmmmlmmmlmmn",
      "lmmmlmmmlmmmlmmn",
      "lmmmlmmmlmmmlmmn",
      "lmmmlmmmlmmmlmmn",
      "lmmmlmmmlmmmlmmn",
      "lmmmlmmmlmmmlmmn",
      "lmmmlmmmlmmmlmmn",
      "lmmmlmmmlmmmlmmn",
      "lmmmlmmmlmmmlmmn",
      "lmmmlmmmlmmmlmmn"
    ]
  ]
}