{
  "name": "multi_verticalschool_6_floor9",
  "refpalette": "deceasedcraft:multi_verticalschool_6/multi_verticalschool_6_floor9_palette",
  "xsize": 16,
  "zsize": 16,
  "slices": [
    [
      "            abcc",
      " ddd       abccc",
      "          abbbbb",
      "         abbbbbb",
      "        abbbbbbb",
      "       abbbbbbbb",
      "      abbbbbbbbb",
      "     abbbbbbcccc",
      "    abbbbbbccccc",
      "   abbbbbbcccccc",
      "  abbbbbbccccccc",
      " abbbbbbcccccccc",
      "abbbbbbccccccccc",
      "bbbbbbcccccccccc",
      "bbbbbccccccccccc",
      "bbbbeeeeeeeeeeee"
    ],
    [
      "            afg ",
      " ddd       af   ",
      "          a h   ",
      "         a      ",
      "        a       ",
      "       a        ",
      "      a     iiii",
      "     a     i    ",
      "    a     i  j j",
      "   a     i  kkkk",
      "  a     i  lkmmm",
      " a     i    kkkk",
      "a     i     n n ",
      "     op         ",
      "    iq    rsttts",
      "   ieeeeeeeeeeee"
    ],
    [
      "            afu ",
      " ddd       af   ",
      "          a     ",
      "         a      ",
      "        a       ",
      "       a        ",
      "      a     iiii",
      "     a     i    ",
      "    a     i     ",
      "   a     i      ",
      "  a     i       ",
      " a     i        ",
      "a     i         ",
      "      w         ",
      "    ix      yA  ",
      "   ieeeeeeeeeeee"
    ],
    [
      "            af  ",
      " ddd       af   ",
      "          a     ",
      "         a      ",
      "        a       ",
      "       a        ",
      "      a     iiii",
      "     a     i    ",
      "    a     i     ",
      "   a     i      ",
      "  a     i       ",
      " a     i        ",
      "a     i         ",
      "     i          ",
      "    i           ",
      "   ieeeeeeeeeeee"
    ],
    [
      "            afkk",
      " ddd       afkkk",
      "          aBkkkk",
      "         aBkkkkk",
      "        aBkkkkkk",
      "       aBkkkkkkk",
      "      aBkkkkeeee",
      "     aBkkkkeCCCC",
      "    aBkkkkeCCCCC",
      "   aBkkkkeCCCCCC",
      "  aBkkkkeCCCCCCC",
      " aBkkkkeCCCCCCCC",
      "aBkkkkeCCCCCCCCC",
      "BkkkkeCCCCCCCCCC",
      "kkkkeDCCCCCCCCCC",
      "kkkeeeeeeeeeeeee"
    ],
    [
      "            aEFF",
      " ddd       aEFFF",
      "          aEFFFF",
      "         aEFFFFI",
      "        aEFFFFII",
      "       aEFFFFIII",
      "      aEFFFFIIII",
      "     aEFFFFIIIII",
      "    aEFFFFIIIIII",
      "   aEFFFFIIIIIII",
      "  aEFFFFIIIIIIII",
      " aEFFFFIIIIIIIII",
      "aEFFFFIIIIIIIIII",
      "EFFFFIIIIIIIIIII",
      "FFFFIIIIIIIIIIII",
      "FFFIIIIIIIIIIIee"
    ]
  ]
}