{
  "name": "multi_verticalschool_6_top",
  "refpalette": "deceasedcraft:multi_verticalschool_6/multi_verticalschool_6_top_palette",
  "xsize": 16,
  "zsize": 16,
  "slices": [
    [
      "aaaaaaaaaaaaaaaa",
      "abbbbbbbbbbbbbbb",
      "ab              ",
      "ab ccc ccc  dddd",
      "ab cec cec  dddd",
      "ab ccc ccc  dddd",
      "ab          dddd",
      "ab          dddd",
      "ab          dddd",
      "ab ccc ccc  dddd",
      "ab cec cec  dddd",
      "ab ccc ccc  dddd",
      "ab          dddd",
      "ab  e   e   dddd",
      "ab          dddd",
      "ab              "
    ],
    [
      "                ",
      "                ",
      "                ",
      "   fgf fgf      ",
      "   gfg gfg      ",
      "   fgf fgf      ",
      "    hi  hi      ",
      "    j   j       ",
      "                ",
      "   fgf fgf      ",
      "   gfg gfg      ",
      "   fgf fgf      ",
      "                ",
      "    e   e       ",
      "                ",
      "                "
    ],
    [
      "                ",
      "                ",
      "                ",
      "   klk klk      ",
      "   lkl lkl      ",
      "   klk klk      ",
      "                ",
      "    m   m       ",
      "    n   n       ",
      "   klk klk      ",
      "   lkl lkl      ",
      "   klk klk      ",
      "                ",
      "    e   e       ",
      "                ",
      "                "
    ],
    [
      "                ",
      "                ",
      "                ",
      "   opo opo      ",
      "   popnpop      ",
      "   opo opo      ",
      "                ",
      "                ",
      "                ",
      "   opo opo      ",
      "   popnpop      ",
      "   opo opo      ",
      "    qi  qi      ",
      "    m   m       ",
      "                ",
      "                "
    ],
    [
      "                ",
      "                ",
      "                ",
      "                ",
      "                ",
      "                ",
      "                ",
      "                ",
      "                ",
      "                ",
      "                ",
      "                ",
      "                ",
      "                ",
      "                ",
      "                "
    ],
    [
      "                ",
      "                ",
      "                ",
      "                ",
      "                ",
      "                ",
      "                ",
      "                ",
      "                ",
      "                ",
      "                ",
      "                ",
      "                ",
      "                ",
      "                ",
      "                "
    ]
  ]
}