{
  "name": "multi_verticalschool_6_floor6",
  "refpalette": "deceasedcraft:multi_verticalschool_6/multi_verticalschool_6_floor6_palette",
  "xsize": 16,
  "zsize": 16,
  "slices": [
    [
      "  a    b      cd",
      " eeeffffffff  cd",
      " g         h  cd",
      " g         h  cd",
      " g         f  cd",
      " cfhhfffffff  cd",
      " c      i  f  cd",
      " c   jk illf  cd",
      " cm     i  f  cd",
      " cm  jk illf  cd",
      " c      i  f  cd",
      " cm  jk illf  cd",
      " gn       of  cd",
      " gn       of  cd",
      " g         f  cd",
      " cpqpqpqpqpf  cd"
    ],
    [
      "rssssssssssssscd",
      "reeeffffffffsscd",
      "rctttttttttfsscd",
      "rctttttttttfsscd",
      "rctttttttttfsscd",
      "rcffffffffffsscd",
      "rctttutttttfsscd",
      "rctttutttttfsscd",
      "rctttutttttfsscd",
      "rctttutttttfsscd",
      "rctttutttttfsscd",
      "rctttutttttfsscd",
      "rctttttttttfsscd",
      "rctttttttttfsscd",
      "rctttttttttfsscd",
      "rctttttttttfsscd"
    ],
    [
      "dddddddddddddddd",
      "deeedddddddddddd",
      "dddddddddddddddd",
      "dddddddddddddddd",
      "dddddddddddddddd",
      "dddddddddddddddd",
      "dddddddddddddddd",
      "dddddddddddddddd",
      "dddddddddddddddd",
      "dddddddddddddddd",
      "dddddddddddddddd",
      "dddddddddddddddd",
      "dddddddddddddddd",
      "dddddddddddddddd",
      "dddddddddddddddd",
      "dddddddddddddddd"
    ],
    [
      "               w",
      " eee           w",
      "               w",
      "               w",
      "               w",
      "               w",
      "               w",
      "               w",
      "               w",
      "               w",
      "               w",
      "               w",
      "               w",
      "               w",
      "               w",
      "               w"
    ],
    [
      "                ",
      " eee            ",
      "                ",
      "                ",
      "                ",
      "                ",
      "                ",
      "                ",
      "                ",
      "                ",
      "                ",
      "                ",
      "                ",
      "                ",
      "                ",
      "                "
    ],
    [
      "                ",
      " eee            ",
      "                ",
      "                ",
      "                ",
      "                ",
      "                ",
      "                ",
      "                ",
      "                ",
      "                ",
      "                ",
      "                ",
      "                ",
      "                ",
      "                "
    ]
  ]
}