{
  "name": "multi_verticalschool_6_ground",
  "refpalette": "deceasedcraft:multi_verticalschool_6/multi_verticalschool_6_ground_palette",
  "xsize": 16,
  "zsize": 16,
  "slices": [
    [
      "ab           cdd",
      " eee         cdd",
      "  fg         cdd",
      " hij  k     addd",
      " hijggk     addd",
      "ahijk     aadddd",
      "dllllllllldddddd",
      "dddddddddddddddd",
      "dddddddddddddddd",
      "dddddddddddddddd",
      "dddddddddddddddd",
      "mmmmmmmmmmmmmmmm",
      "mmmmmmmmmmmmmmmm",
      "nnnnnnnnnnnnnmmm",
      "mmmmmmmmmmmmmnmm",
      "mmmmmmmmmmmmmmnm"
    ],
    [
      "hodb         ooo",
      "heee         ooo",
      "hgg          ooo",
      "ij          oooo",
      "ij          oooo",
      "oj        oooooo",
      "oooooooooooooooo",
      "oooooooooooooooo",
      "oooooooooooooooo",
      "oooooooooooooooo",
      "oooooooooooooooo",
      "pppppppppppppppp",
      "                ",
      "qqqqqqqqqqqqq   ",
      "             q  ",
      "              q "
    ],
    [
      "rrrddb       drr",
      "ieee         drr",
      "jk           drr",
      "            ddrr",
      "            drrr",
      "d         dddrrr",
      "dddddddddddrrrrr",
      "rrrrrrrrrrrrrrrr",
      "rrrrrrrrrrrrrrrr",
      "rrrrrrrrrrrrrrrr",
      "dddddddddddddddd",
      "ssssssssssssssss",
      "                ",
      "                ",
      "                ",
      "                "
    ],
    [
      "   ttddb     t  ",
      " eee         t  ",
      "             t  ",
      "            tt  ",
      "            t   ",
      "t         ttt   ",
      "ttttttttttt     ",
      "                ",
      "                ",
      " u     u     u w",
      "dddddddddddddddd",
      "ssssssssssssssss",
      "                ",
      "                ",
      "                ",
      "                "
    ],
    [
      "    tttddb      ",
      " eee            ",
      "                ",
      "                ",
      "                ",
      "                ",
      "                ",
      "                ",
      "                ",
      " x     x     x  ",
      "dddddddddddddddd",
      "ssssssssssssssss",
      "                ",
      "                ",
      "                ",
      "                "
    ],
    [
      "      tttddb    ",
      " eee            ",
      "                ",
      "                ",
      "                ",
      "                ",
      "                ",
      "                ",
      "                ",
      " y     y     y  ",
      "dddddddddddddddd",
      "ssssssssssssssss",
      "                ",
      "                ",
      "                ",
      "                "
    ]
  ]
}