{
  "name": "multi_verticalschool_6_floor21",
  "refpalette": "deceasedcraft:multi_verticalschool_6/multi_verticalschool_6_floor21_palette",
  "xsize": 16,
  "zsize": 16,
  "slices": [
    [
      "                ",
      " aaabbbbbbbb    ",
      " b c c c   d    ",
      " b c c c   d    ",
      " beeeeee   b    ",
      " b       fgb    ",
      " bbbbbbbbbbb    ",
      " b       hib    ",
      " bjjjjjj   b    ",
      " b c c c   d    ",
      " b c c c   d    ",
      " bbbbbbbbbbb    ",
      "      klm       ",
      "        nn      ",
      "      oo        ",
      "       plq      "
    ],
    [
      "                ",
      " aaabbbbbbbb    ",
      " r         b    ",
      " r         b    ",
      " r         b    ",
      " r         b    ",
      " bbbbbbbbbbb    ",
      " r         b    ",
      " r         b    ",
      " r         b    ",
      " r         b    ",
      " bbbbbbbbbbb    ",
      "     klm        ",
      "       nn       ",
      "       oo       ",
      "        plq     "
    ],
    [
      "ssssssssssssssss",
      "saaabbbbbbbbtttt",
      "sbuuuuuuuuubwwww",
      "sbuuuuuuuuubwwww",
      "sbuuuuuuuuubwwww",
      "sbuuuuuuuuubwwww",
      "sbbbbbbbbbbbwwww",
      "sbuuuuuuuuubwwww",
      "sbuuuuuuuuubwwww",
      "sbuuuuuuuuubwwww",
      "sbuuuuuuuuubwwww",
      "sbbbbbbbbbbbwwww",
      "s   klm     wwww",
      "s     nn    wwww",
      "s       oo  wwww",
      "s        plqwwww"
    ],
    [
      "xxxxxxxxxxxxxxxx",
      "xaaaxxxxxxxxxxxx",
      "xyyyyyyyyyyyyyyy",
      "xyyyyyyyyyyyyyyy",
      "xyyyyyyyyyyyyyyy",
      "xyyyyyyyyyyyyyyy",
      "xyyyyyyyyyyyyyyy",
      "xyyyyyyyyyyyyyyy",
      "xyyyyAAAAAAyyyyy",
      "xyyyyAAAAAAyyyyy",
      "xyyyyAAAAAAyyyyy",
      "xyyyyyyyyyyyyyyy",
      "xyyyBm      yyyy",
      "xyyy nn     yyyy",
      "xyyy     oo yyyy",
      "xyyy      pByyyy"
    ],
    [
      "CDDDDDDDDDDDDDDD",
      "DaaaEEEEEEEEEEEE",
      "DFFFFFFFIIFFJJJJ",
      "DF      KKL     ",
      "DM      KK      ",
      "DM      KK      ",
      "DF              ",
      "DM              ",
      "DM              ",
      "DF  N  OO  P    ",
      "DM              ",
      "DM    QRRS      ",
      "DF  nnnnnnnnT   ",
      "DM Unn      T   ",
      "DM U      ooT   ",
      "DF U            "
    ],
    [
      " DDDDDDDDDDDDDDD",
      "DaaaEEEEEEEEEEEE",
      "DFFFFFIIFFJJJJJJ",
      "DF    KKL       ",
      "DV    KK        ",
      "D     KK        ",
      "DF              ",
      "DW              ",
      "DX              ",
      "DF              ",
      "DY              ",
      "DZ              ",
      "DF              ",
      "D0              ",
      "D               ",
      "DF              "
    ]
  ]
}