{
  "name": "multi_verticalschool_6_floor20",
  "refpalette": "deceasedcraft:multi_verticalschool_6/multi_verticalschool_6_floor20_palette",
  "xsize": 16,
  "zsize": 16,
  "slices": [
    [
      "                ",
      " aaabbbbbbbb    ",
      " b c c c   d    ",
      " b c c c   d    ",
      " beeeeee   b    ",
      " b       fgb    ",
      " bbbbbbbbbbb    ",
      " b       hib    ",
      " bjjjjjj   b    ",
      " b c c c   d    ",
      " b c c c   d    ",
      " bbbbbbbbbbb    ",
      "      klm       ",
      "        nn      ",
      "      oo        ",
      "       plq      "
    ],
    [
      "                ",
      " aaabbbbbbbb    ",
      " r         b    ",
      " r         b    ",
      " r         b    ",
      " r         b    ",
      " bbbbbbbbbbb    ",
      " r         b    ",
      " r         b    ",
      " r         b    ",
      " r         b    ",
      " bbbbbbbbbbb    ",
      "     klm        ",
      "       nn       ",
      "       oo       ",
      "        plq     "
    ],
    [
      "ssssssssssssssss",
      "saaabbbbbbbb    ",
      "sbtttttttttb    ",
      "sbtttttttttb    ",
      "sbtttttttttb    ",
      "sbtttttttttb    ",
      "sbbbbbbbbbbb    ",
      "sbtttttttttb    ",
      "sbtttttttttb    ",
      "sbtttttttttb    ",
      "sbtttttttttb    ",
      "sbbbbbbbbbbb    ",
      "s   klm   uu    ",
      "s     nn        ",
      "s       oo      ",
      "s   uu   plq    "
    ],
    [
      "wwwwwwwwwwwwwwww",
      "waaaxxxxxxxxyyyy",
      "wxAAAAAAAAAxyBBB",
      "wxAAAAAAAAAxyB  ",
      "wxAAAAAAAAAxyB  ",
      "wxAAAAAAAAAxyB  ",
      "wxxxxxxxxxxxyB  ",
      "wxAAAAAAAAAxyB  ",
      "wxAAAAAAAAAxyB  ",
      "wxAAAAAAAAAxyB  ",
      "wxAAAAAAAAAxyB  ",
      "wxxxxxxxxxxxyB  ",
      "yyyyCm   klCyB  ",
      "yyyy nn    nyB  ",
      "yyyyo    oo yB  ",
      "yyyyClq   pCyB  "
    ],
    [
      "           D    ",
      " aaaxxxxxxxx    ",
      " xEcEcEcF  I  JJ",
      " x c c cK    L  ",
      " xMeMeMe   x L  ",
      " x       NNx L  ",
      " xxxxxxxxxxx L  ",
      " x       OOx L  ",
      " xPjPjPj   x L  ",
      " x c c c     L  ",
      " xQcQcQc     L  ",
      "Rxxxxxxxxxxx L  ",
      "        klm  L  ",
      "   Snn    nnTL  ",
      "   Soo    ooTL  ",
      "     plq     L  "
    ],
    [
      "                ",
      " aaabbbbbbbb    ",
      " b c c c        ",
      " b c c c        ",
      " bUeUeUe   b    ",
      " b      V  b    ",
      " bbbbbbbbbbb    ",
      " b      W  b    ",
      " bXjXjXj   b    ",
      " b c c c        ",
      " b c c c        ",
      " bbbbbbbbbbb    ",
      "       klm      ",
      "         nn     ",
      "     oo         ",
      "      plq       "
    ]
  ]
}