{
  "name": "multi_verticalschool_6_floor27",
  "refpalette": "deceasedcraft:multi_verticalschool_6/multi_verticalschool_6_floor27_palette",
  "xsize": 16,
  "zsize": 16,
  "slices": [
    [
      "aaaaaaaaaaaaaaaa",
      "abbbccccccccdddd",
      "aceeeeeeeeecdddd",
      "aceeeeeeeeecdddd",
      "aceeeeeeeeecdddd",
      "aceeeeeeeeecdddd",
      "acccccccccccdddd",
      "aceeeeeeeeecdddd",
      "aceeeeeeeeecdddd",
      "aceeeeeeeeecdddd",
      "aceeeeeeeeecdddd",
      "acccccccccccdddd",
      "acfffffffffcdddd",
      "acfffffffffcdddd",
      "acfffffffffcdddd",
      "acfffffffffcdddd"
    ],
    [
      "gggggggggggggggg",
      "hbbbcccccccci  i",
      "hcjkjkjk        ",
      "hc k k k        ",
      "hclmlmlm   c    ",
      "hc       nnc    ",
      "hccccccccccc    ",
      "hc  o o  ppc    ",
      "hcqrsrqr   c    ",
      "hc k k k        ",
      "hctk!ktk        ",
      "hccccccccccc    ",
      "hcu w  xyyxc    ",
      "hc A AB C  D    ",
      "hc         E    ",
      "hcF        c    "
    ],
    [
      "                ",
      " bbbIIIIIIII    ",
      " I k k k        ",
      " I k k k        ",
      " IJmJmJm   I    ",
      " I      K  I    ",
      " IIIIIIIIIII    ",
      " I      L  I    ",
      " IMrNrMr   I    ",
      " I k k k        ",
      " I kok k        ",
      " IIIIIIIIIII    ",
      " IO O  PQR I    ",
      " I         S    ",
      " I         T    ",
      " I         I    "
    ],
    [
      "                ",
      " bbbIIIIIIII    ",
      " I k k k   U    ",
      " I k k k   U    ",
      " Immmmmm   I    ",
      " I       VWI    ",
      " IIIIIIIIIII    ",
      " I       XYI    ",
      " Irrrrrr   I    ",
      " I k k k   U    ",
      " I k k k   U    ",
      " IIIIIIIIIII    ",
      " I     Z0Z0I    ",
      " I         U    ",
      " I         U    ",
      " I         I    "
    ],
    [
      "                ",
      " bbbIIIIIIII    ",
      " 1         I    ",
      " 1         I    ",
      " 1         I    ",
      " 1         I    ",
      " IIIIIIIIIII    ",
      " 1         I    ",
      " 1         I    ",
      " 1         I    ",
      " 1         I    ",
      " IIIIIIIIIII    ",
      " 1     2324I    ",
      " 1         I    ",
      " 1         I    ",
      " 1         I    "
    ],
    [
      "5555555555555555",
      "5bbbIIIIIIII6666",
      "5I777777777I8888",
      "5I777777777I8888",
      "5I777777777I8888",
      "5I777777777I8888",
      "5IIIIIIIIIII8998",
      "5I777777777I8888",
      "5I777777777I8888",
      "5I777777777I8888",
      "5I777777777I8888",
      "5IIIIIIIIIII8##8",
      "5I777777777I8888",
      "5I77$777$77I8888",
      "5I77$777$77I8888",
      "5I777777777I8888"
    ]
  ]
}