{
  "name": "multi_verticalschool_6_floor30",
  "refpalette": "deceasedcraft:multi_verticalschool_6/multi_verticalschool_6_floor30_palette",
  "xsize": 16,
  "zsize": 16,
  "slices": [
    [
      "aaaaaaaaaaaaaaaa",
      "abbbcccccccccccc",
      "acdddddddddddddd",
      "acdeeeeeeeeeeeed",
      "acdddddddeeeeeed",
      "acdeeeeeedeeeffg",
      "acdeeeeeeedefhif",
      "acdddddddedefjjj",
      "acdeeeededdeefif",
      "acdddddddedeeedf",
      "acdeeeeeeedeeeed",
      "acdeeeeeedeeeeed",
      "acdddddddeeeeeed",
      "acdeeeeeeeeeeeed",
      "acdddddddddddddd",
      "accccccccccccccc"
    ],
    [
      "  k             ",
      " bbb            ",
      "           l    ",
      "              m ",
      "             n o",
      "           l  p ",
      "            lqjr",
      "        n  n h  ",
      "           mo so",
      "               t",
      "              o ",
      "             p  ",
      "u               ",
      "                ",
      "                ",
      "                "
    ],
    [
      "  w             ",
      " bbb            ",
      "                ",
      "                ",
      "                ",
      "                ",
      "             x  ",
      "                ",
      "                ",
      "                ",
      "                ",
      "                ",
      "                ",
      "                ",
      "                ",
      "                "
    ],
    [
      "                ",
      " bbb            ",
      "                ",
      "                ",
      "                ",
      "                ",
      "                ",
      "                ",
      "                ",
      "                ",
      "                ",
      "                ",
      "                ",
      "                ",
      "                ",
      "                "
    ],
    [
      "                ",
      " bbb            ",
      "                ",
      "                ",
      "                ",
      "                ",
      "                ",
      "                ",
      " yA             ",
      "                ",
      "                ",
      "                ",
      "                ",
      "                ",
      "                ",
      "                "
    ],
    [
      "                ",
      " bbb            ",
      "                ",
      "                ",
      "                ",
      "                ",
      "                ",
      "  B             ",
      " CD             ",
      "  B             ",
      "                ",
      "                ",
      "                ",
      "                ",
      "                ",
      "                "
    ]
  ]
}