{
  "name": "multi_verticalschool_6_floor23",
  "refpalette": "deceasedcraft:multi_verticalschool_6/multi_verticalschool_6_floor23_palette",
  "xsize": 16,
  "zsize": 16,
  "slices": [
    [
      "                ",
      " aaa            ",
      "                ",
      "                ",
      "                ",
      "                ",
      "                ",
      "                ",
      "                ",
      "                ",
      "                ",
      "                ",
      "                ",
      "                ",
      "                ",
      "                "
    ],
    [
      "bbbbbbbbbbbbbbbb",
      "baaacccccccccccc",
      "bbcddddddddddddd",
      "bbcddddddddddddd",
      "bbcddddddddddddd",
      "bbcddddddddddddd",
      "bbcddddddddddddd",
      "bbcddddddddddddd",
      "bbcddddddddddddd",
      "bbcddddddddddddd",
      "bbcddddddddddddd",
      "bbcddddddddddddd",
      "bbcddddddddddddd",
      "bbcddddddddddddd",
      "bbcddddddddddddd",
      "bbcddddddddddddd"
    ],
    [
      "efgggggggghhhhhh",
      "eaaafffffgijjjjj",
      "eekkkkkkfgglllll",
      "eekkkmkmffgillll",
      "eekmmmmmmfggjjjj",
      "eekkmmmmmffginnn",
      "eekooooooofggjjj",
      "eekpmmmmmpffgiqq",
      "eekprmrrrpsfggqq",
      "eekprrrrrpsffgij",
      "eekprrmrmpssfggt",
      "eekprmmmrpssffgi",
      "eekprmrrrpsssfgg",
      "eekprrrrrpsssffg",
      "eekpmrrmrpssssfg",
      "eekpmmmmmpssssff"
    ],
    [
      "uwx             ",
      "uaaayABC        ",
      "uD              ",
      "uE              ",
      "uD FIJJJKL      ",
      "uE MNJJJOP      ",
      "uD QQQQQQQ      ",
      "uE RSSSSSRCy    ",
      "uE R     R T    ",
      "uE R     R U    ",
      "uE R     R      ",
      "uE R VJW R      ",
      "uE R     R      ",
      "uD R     X   Cy ",
      "uE R     R    T ",
      "uE RYVJWYR    U "
    ],
    [
      "Z               ",
      "Zaaa0  1        ",
      "Z               ",
      "Z               ",
      "Z  2345567      ",
      "Z  8664349      ",
      "   #######      ",
      "Z  RRRRRRR1$    ",
      "Z  R     R      ",
      "Z  R     R      ",
      "   R     R      ",
      "Z  R %^& R      ",
      "Z  R     R      ",
      "Z  R     *   1  ",
      "Z  R     R      ",
      "Z  R ()+ R      "
    ],
    [
      "                ",
      " aaa   -        ",
      "                ",
      "                ",
      "                ",
      "                ",
      "                ",
      "   [[[[[[[-     ",
      "   RRRRRRR      ",
      "   RRRRRRR      ",
      "   R     R      ",
      "   R ]]] R      ",
      "   R     R      ",
      "   R     R   -  ",
      "   R     R      ",
      "   R {{{ R      "
    ]
  ]
}