{
  "name": "multi_verticalschool_6_floor1",
  "refpalette": "deceasedcraft:multi_verticalschool_6/multi_verticalschool_6_floor1_palette",
  "xsize": 16,
  "zsize": 16,
  "slices": [
    [
      "        aaabbc  ",
      " ddd            ",
      "                ",
      "                ",
      "                ",
      "                ",
      "                ",
      "                ",
      "                ",
      "                ",
      "bbbbbbbbbbbbbbbb",
      "eeeeeeeeeeeeeeee",
      "                ",
      "                ",
      "                ",
      "                "
    ],
    [
      "          aaabbc",
      " ddd           c",
      "               c",
      "               c",
      "               c",
      "               c",
      "               c",
      "               c",
      "               c",
      "               c",
      "bbbbbbbbbbbbbbbb",
      "eeeeeeeeeeeeeeee",
      "                ",
      "                ",
      "                ",
      "                "
    ],
    [
      "            aaab",
      " ddd           b",
      "             cbb",
      "             cbf",
      "             cbf",
      "             cbf",
      "             cbf",
      "             cbf",
      "             cbf",
      "             cbf",
      "bbbbbbbbbbbbbbbb",
      "eeeeeeeeeeeeeeee",
      "                ",
      "                ",
      "                ",
      "                "
    ],
    [
      "              aa",
      " ddd           a",
      "           cbbaa",
      "           cbfg ",
      "           cbfg ",
      "           cbfg ",
      "           cbfh ",
      "           cbfh ",
      "           cbfh ",
      "           cbfh ",
      "aaaaaaaaaaacbbaa",
      "iiiiiiiiiiiiiiii",
      "                ",
      "                ",
      "                ",
      "                "
    ],
    [
      "                ",
      " ddd            ",
      "         cbbaaa ",
      "         cbfh   ",
      "         cbfh   ",
      "         cbfh   ",
      "         cbfh   ",
      "         cbfh   ",
      "         cbfh   ",
      "         cbfh   ",
      "         cbbaaa ",
      "                ",
      "                ",
      "                ",
      "                ",
      "                "
    ],
    [
      "                ",
      " ddd            ",
      "       cbbaaa   ",
      "       cbfhg    ",
      "       cbfhg    ",
      "       cbfhg    ",
      "       cbfhg    ",
      "       cbfh     ",
      "       cbfh     ",
      "       cbfh     ",
      "       cbbaaa   ",
      "                ",
      "                ",
      "                ",
      "                ",
      "                "
    ]
  ]
}