{
  "name": "multi_verticalschool_6_floor7",
  "refpalette": "deceasedcraft:multi_verticalschool_6/multi_verticalschool_6_floor7_palette",
  "xsize": 16,
  "zsize": 16,
  "slices": [
    [
      "                ",
      " aaa            ",
      "                ",
      "                ",
      "                ",
      "                ",
      "                ",
      "                ",
      "                ",
      "                ",
      "                ",
      "                ",
      "                ",
      "                ",
      "                ",
      "                "
    ],
    [
      "                ",
      " aaa            ",
      "                ",
      "                ",
      "                ",
      "                ",
      "                ",
      "                ",
      "                ",
      "                ",
      "                ",
      "                ",
      "                ",
      "                ",
      "                ",
      "                "
    ],
    [
      "                ",
      " aaa            ",
      "                ",
      "                ",
      "                ",
      "                ",
      "                ",
      "                ",
      "                ",
      "                ",
      "                ",
      "bbbbbbbbbbbbbbbb",
      "                ",
      "cccccccccccccccc",
      "dddddddddddddddd",
      "cccccccccccccccc"
    ],
    [
      "                ",
      " aaa            ",
      "                ",
      "                ",
      "                ",
      "                ",
      "                ",
      "                ",
      "                ",
      "                ",
      "eeeeeeeeeeeeeeee",
      "ffffffffffffffff",
      "gggggggggggggggg",
      "hhhhhhhhhhhhhhhh",
      "hhhhhhhhhhhhhhhh",
      "hiiiiiiiiiiiiiii"
    ],
    [
      "                ",
      " aaa            ",
      "                ",
      "                ",
      "                ",
      "                ",
      "                ",
      "                ",
      "                ",
      "                ",
      "eeeeeeeeeeeeeeee",
      "ffffffffffffffff",
      "  j        j    ",
      "                ",
      "                ",
      " iiiiiiiiiiii  i"
    ],
    [
      "                ",
      " aaa            ",
      "                ",
      "                ",
      "                ",
      "                ",
      "                ",
      "                ",
      "                ",
      "                ",
      "eeeeeeeeeeeeeeee",
      "fffffkkkkfffffkk",
      "  l        l    ",
      "                ",
      "                ",
      " iiiiiiiiiiii  i"
    ]
  ]
}