{
  "name": "multi_verticalschool_6_floor18",
  "refpalette": "deceasedcraft:multi_verticalschool_6/multi_verticalschool_6_floor18_palette",
  "xsize": 16,
  "zsize": 16,
  "slices": [
    [
      "                ",
      " aaabbbbbbbb    ",
      " b c c c   d    ",
      " b c c c   d    ",
      " beeeeee   b    ",
      " b       fgb    ",
      " bbbbbbbbbbb    ",
      " b       hib    ",
      " bjjjjjj   b    ",
      " b c c c   d    ",
      " b c c c   d    ",
      " bbbbbbbbbbb    ",
      "      klm       ",
      "        nn      ",
      "      oo        ",
      "       plq      "
    ],
    [
      "                ",
      " aaabbbbbbbb    ",
      " r         b    ",
      " r         b    ",
      " r         b    ",
      " r         b    ",
      " bbbbbbbbbbb    ",
      " r         b    ",
      " r         b    ",
      " r         b    ",
      " r         b    ",
      " bbbbbbbbbbb    ",
      "     klm        ",
      "       nn       ",
      "       oo       ",
      "        plq     "
    ],
    [
      "ssssssssssssssss",
      "saaabbbbbbbb    ",
      "sbtttttttttb    ",
      "sbtttttttttb    ",
      "sbtttttttttb    ",
      "sbtttttttttb    ",
      "sbbbbbbbbbbb    ",
      "sbtttttttttb    ",
      "sbtttttttttb    ",
      "sbtttttttttb    ",
      "sbtttttttttb    ",
      "sbbbbbbbbbbb    ",
      "s   klm   uu    ",
      "s     nn        ",
      "s       oo      ",
      "s   uu   plq    "
    ],
    [
      "wwwwwwwwwwwwwwww",
      "waaaxxxxxxxxyyyy",
      "wxAAAAAAAAAxyBBB",
      "wxAAAAAAAAAxyB  ",
      "wxAAAAAAAAAxyB  ",
      "wxAAAAAAAAAxyB  ",
      "wxxxxxxxxxxxyB  ",
      "wxAAAAAAAAAxyB  ",
      "wxAAAAAAAAAxyB  ",
      "wxAAAAAAAAAxyB  ",
      "wxAAAAAAAAAxyB  ",
      "wxxxxxxxxxxxyB  ",
      "yyyyCm   klCyB  ",
      "yyyy nn    nyB  ",
      "yyyyo    oo yB  ",
      "yyyyClq   pCyB  "
    ],
    [
      "           D    ",
      " aaaxxxxxxxx    ",
      " x!cEcEc      FF",
      " x c c c     I  ",
      " xJeKeKe   x I  ",
      " xL      MMx I  ",
      " xxxxxxxxxxx I  ",
      " x  N    OOx I  ",
      " xPjPjPj   x I  ",
      " x c c c     I  ",
      " xQcQcQc     I  ",
      "Rxxxxxxxxxxx I  ",
      "        klm  I  ",
      "   Snn    nnTI  ",
      "   Soo    ooTI  ",
      "     plq     I  "
    ],
    [
      "                ",
      " aaabbbbbbbb    ",
      " bLc c c        ",
      " b c c c        ",
      " bUeVeVe   b    ",
      " b      W  b    ",
      " bbbbbbbbbbb    ",
      " b      X  b    ",
      " bYjYjYj   b    ",
      " b c c c        ",
      " b c c c        ",
      " bbbbbbbbbbb    ",
      "       klm      ",
      "         nn     ",
      "     oo         ",
      "      plq       "
    ]
  ]
}