{
  "name": "multi_verticalschool_6_floor17",
  "refpalette": "deceasedcraft:multi_verticalschool_6/multi_verticalschool_6_floor17_palette",
  "xsize": 16,
  "zsize": 16,
  "slices": [
    [
      " aaaaaaaaaaaaaaa",
      "abbbcccccccc    ",
      "acd d de  ec    ",
      "ac         c    ",
      "ac         c    ",
      "ac         c    ",
      "ac         c    ",
      "ac         c    ",
      "ac         c    ",
      "ac         c    ",
      "acd d d    c    ",
      "accccccccccc    ",
      "ac    fgh       ",
      "ac      ii      ",
      "ac    jj        ",
      "ac     kgl      "
    ],
    [
      " aaaaaaaaaaaaaaa",
      "abbbcccccccc    ",
      "acd dedee ec    ",
      "ace        c    ",
      "ac         c    ",
      "ac         c    ",
      "ac         c    ",
      "ac         c    ",
      "ac         c    ",
      "ace        c    ",
      "acded d    c    ",
      "accccccccccc    ",
      "ac   fgh        ",
      "ac     ii       ",
      "ac     jj       ",
      "ac      kgl     "
    ],
    [
      "maaaaaaaaaaaaaaa",
      "abbbcccccccc    ",
      "acdndndnnnnc    ",
      "acnnnnnnnnnc    ",
      "acnnnnnnnnnc    ",
      "acnnnnnnnnnc    ",
      "acnnnnnnnnnc    ",
      "acnnnnnnnnnc    ",
      "acnnnnnnnnnc    ",
      "acnnnnnnnnnc    ",
      "acdndndnnnnc    ",
      "accccccccccc    ",
      "ac  fgh   oo    ",
      "ac    ii        ",
      "ac      jj      ",
      "ac  oo   kgl    "
    ],
    [
      "pppppppppppppppp",
      "pbbbqqqqqqqqrrrr",
      "pqsssssssssqrttt",
      "pqsssssssssqrt  ",
      "pqsssssssssqrt  ",
      "pqsssssssssqrt  ",
      "pqqqqqqqqqqqrt  ",
      "pqsssssssssqrt  ",
      "pqsssssssssqrt  ",
      "pqsssssssssqrt  ",
      "pqsssssssssqrt  ",
      "pqqqqqqqqqqqrt  ",
      "rrrruh   fgurt  ",
      "rrrr ii    irt  ",
      "rrrrj    jj rt  ",
      "rrrrugl   kurt  "
    ],
    [
      "           w    ",
      " bbbqqqqqqqq    ",
      " qxyxyxy      AA",
      " q y y y     B  ",
      " qCDCDCD   q B  ",
      " q       EEq B  ",
      " qqqqqqqqqqq B  ",
      " q       FFq B  ",
      " qIJIJIJ   q B  ",
      " q y y y     B  ",
      " qKyKyKy     B  ",
      "Lqqqqqqqqqqq B  ",
      "        fgh  B  ",
      "   Mii    iiNB  ",
      "   Mjj    jjNB  ",
      "     kgl     B  "
    ],
    [
      "                ",
      " bbbcccccccc    ",
      " c y y y        ",
      " c y y y        ",
      " cODODOD   c    ",
      " c      P  c    ",
      " ccccccccccc    ",
      " c      Q  c    ",
      " cRJRJRJ   c    ",
      " c y y y        ",
      " c y y y        ",
      " ccccccccccc    ",
      "       fgh      ",
      "         ii     ",
      "     jj         ",
      "      kgl       "
    ]
  ]
}