{
  "name": "multi_verticalschool_6_floor19",
  "refpalette": "deceasedcraft:multi_verticalschool_6/multi_verticalschool_6_floor19_palette",
  "xsize": 16,
  "zsize": 16,
  "slices": [
    [
      "                ",
      " aaabbbbbbbb    ",
      " b c c c   d    ",
      " b c c c   d    ",
      " beeeeee   b    ",
      " b       fgb    ",
      " bbbbbbbbbbb    ",
      " b       hib    ",
      " bjjjjjj   b    ",
      " b c c c   d    ",
      " b c c c   d    ",
      " bbbbbbbbbbb    ",
      "      klm       ",
      "        nn      ",
      "      oo        ",
      "       plq      "
    ],
    [
      "                ",
      " aaabbbbbbbb    ",
      " r         b    ",
      " r         b    ",
      " r         b    ",
      " r         b    ",
      " bbbbbbbbbbb    ",
      " r         b    ",
      " r         b    ",
      " r         b    ",
      " r         b    ",
      " bbbbbbbbbbb    ",
      "     klm        ",
      "       nn       ",
      "       oo       ",
      "        plq     "
    ],
    [
      "ssssssssssssssss",
      "saaabbbbbbbb    ",
      "sbtttttttttb    ",
      "sbtttttttttb    ",
      "sbtttttttttb    ",
      "sbtttttttttb    ",
      "sbbbbbbbbbbb    ",
      "sbtttttttttb    ",
      "sbtttttttttb    ",
      "sbtttttttttb    ",
      "sbtttttttttb    ",
      "sbbbbbbbbbbb    ",
      "s   klm   uu    ",
      "s     nn        ",
      "s       oo      ",
      "s   uu   plq    "
    ],
    [
      "wwwwwwwwwwwwwwww",
      "waaaxxxxxxxxyyyy",
      "wxAAAAAAAAAxyBBB",
      "wxAAAAAAAAAxyB  ",
      "wxAAAAAAAAAxyB  ",
      "wxAAAAAAAAAxyB  ",
      "wxxxxxxxxxxxyB  ",
      "wxAAAAAAAAAxyB  ",
      "wxAAAAAAAAAxyB  ",
      "wxAAAAAAAAAxyB  ",
      "wxAAAAAAAAAxyB  ",
      "wxxxxxxxxxxxyB  ",
      "yyyyCm   klCyB  ",
      "yyyy nn    nyB  ",
      "yyyyo    oo yB  ",
      "yyyyClq   pCyB  "
    ],
    [
      "           D    ",
      " aaaxxxxxxxx    ",
      " xEcEcEc      FF",
      " x c c c     I  ",
      " xJeJeJe   x I  ",
      " x       KKx I  ",
      " xxxxxxxxxxx I  ",
      " x       LLx I  ",
      " xMjMjMj   x I  ",
      " x c c c     I  ",
      " xNcNcNc     I  ",
      "Oxxxxxxxxxxx I  ",
      "        klm  I  ",
      "   Pnn    nnQI  ",
      "   Poo    ooQI  ",
      "     plq     I  "
    ],
    [
      "                ",
      " aaabbbbbbbb    ",
      " b c c c        ",
      " b c c c        ",
      " bReReRe   b    ",
      " b      S  b    ",
      " bbbbbbbbbbb    ",
      " b      !  b    ",
      " bTjTjTj   b    ",
      " b c c c        ",
      " b c c c        ",
      " bbbbbbbbbbb    ",
      "       klm      ",
      "         nn     ",
      "     oo         ",
      "      plq       "
    ]
  ]
}