{
  "name": "multi_verticalschool_6_floor5",
  "refpalette": "deceasedcraft:multi_verticalschool_6/multi_verticalschool_6_floor5_palette",
  "xsize": 16,
  "zsize": 16,
  "slices": [
    [
      "aaaaaaaaaaaaaabb",
      "acccaaaaaaaaaabb",
      "aaaaaaaaaaaaaabb",
      "aaaaaaaaaaaaaabb",
      "aaaaaaaaaaaaaabb",
      "aaaaaaaaaaaaaabb",
      "aaaaaaaaaaaaaabb",
      "aaaaaaaaaaaaaabb",
      "aaaaaaaaaaaaaabb",
      "aaaaaaaaaaaaaabb",
      "aaaaaaaaaaaaaabb",
      "aaaaaaaaaaaaaabb",
      "aaaaaaaaaaaaaabb",
      "aaaaaaaaaaaaaabb",
      "aaaaaaaaaaaaaabb",
      "aaaaaaaaaaaaaabb"
    ],
    [
      "              db",
      "ecccffffffffffdb",
      "e             db",
      "e             db",
      "e             db",
      "e   g      g  db",
      "e       hij   db",
      "e             db",
      "e       hij   db",
      "e   g      g  db",
      "e       hij   db",
      "eii     k     db",
      "e l     hij   db",
      "emhmg      g  db",
      "ehmh          db",
      "emhm          db"
    ],
    [
      " k            db",
      "ecccffffffffffdb",
      "ekk  k  k     db",
      "ek            db",
      "e   k         db",
      "e   g      g  db",
      "e       n o   db",
      "e       k     db",
      "ek      n o   db",
      "e   g      g  db",
      "e       nko   db",
      "e             db",
      "e       n o   db",
      "epnpg      g  db",
      "enpn          db",
      "epnp          db"
    ],
    [
      "aaaaaaaaaaaaaaab",
      "ecccffffffffaaab",
      "edqqqqqqqqqfaaab",
      "edqqqqqqqqqfaaab",
      "edqqqqqqqqqfaaab",
      "edfqqfffffffaaab",
      "edqqqqqqqqqfaaab",
      "edqqqqqqqqqfaaab",
      "edqqqqqqqqqfaaab",
      "edqqqqqqqqqfaaab",
      "edqqqqqqqqqfaaab",
      "edqqqqqqqqqfaaab",
      "edqqqqqqqqqfaaab",
      "edqqqqqqqqqfaaab",
      "edqqqqqqqqqfaaab",
      "edqqqqqqqqqfaaab"
    ],
    [
      "  r stuuuutw  db",
      " cccffffffff  db",
      " dx           db",
      " dx           db",
      " dy  yABBBCf  db",
      " df  fffffff  db",
      " dD  y  E Ff  db",
      " dD  yI JKKf  db",
      " dD  y  E Ff  db",
      " dD  yI JKKf  db",
      " dD  y  E Ff  db",
      " dD  yI JKKf  db",
      " dL       Mf  db",
      " dL       Mf  db",
      " d         f  db",
      " d N N N N f  db"
    ],
    [
      "  O PQPrPRP   db",
      " cccSSSSSSSS  db",
      " d  T         db",
      " d            db",
      " dU  U     S  db",
      " dS  SSSSSSS  db",
      " d   UV W  S  db",
      " dX  U  JKKS  db",
      " d   U  W  S  db",
      " d   U  JKKS  db",
      " dY  U  W  S  db",
      " d   U  JKKS  db",
      " d         S  db",
      " d         S  db",
      " d         S  db",
      " dZNZNZNZNZS  db"
    ]
  ]
}