{
  "name": "multi_verticalschool_6_base1",
  "refpalette": "deceasedcraft:multi_verticalschool_6/multi_verticalschool_6_base1_palette",
  "xsize": 16,
  "zsize": 16,
  "slices": [
    [
      "a              b",
      "cddd           b",
      "ef             b",
      "               b",
      "               b",
      "g              b",
      "               b",
      "               b",
      "              hi",
      "               j",
      "               j",
      "               j",
      "               j",
      "               j",
      "               j",
      " kkkkk         j"
    ],
    [
      "ef             b",
      " ddd           b",
      "               b",
      "               b",
      "               b",
      "               b",
      "               b",
      "               b",
      "              hi",
      "               j",
      "               j",
      "               j",
      "               j",
      "               j",
      "               j",
      "l    k         j"
    ],
    [
      " gm            b",
      " ddd           b",
      "               b",
      "               b",
      "               b",
      "               b",
      "               b",
      "               b",
      "              hi",
      "               j",
      "               j",
      "               j",
      "               j",
      "               j",
      "               j",
      "lllll          j"
    ],
    [
      "  ggaaa        b",
      " ddd           b",
      "               b",
      "               b",
      "               b",
      "               b",
      "               b",
      "               b",
      "              hi",
      "               j",
      "               j",
      "               j",
      "               j",
      "               j",
      "               j",
      "               j"
    ],
    [
      "   neeef      ob",
      " dddcccf      ob",
      "    aaa       ob",
      "              ob",
      "              ob",
      "             oob",
      "            ooob",
      "ooooooooooooooob",
      "iiiiiiiiiiiiiiii",
      "pppppppppppppppj",
      "pppppppppppppppj",
      "ppppppqppppppqpj",
      "ppppppqppppppqpj",
      "ppppppqppppppqpj",
      "pppppppppppppppj",
      "pppppppppppppppj"
    ],
    [
      "             rst",
      " ddd   f     rst",
      "   neeef     rst",
      "   accg      rst",
      "   acc      rrst",
      "   a       rrsst",
      "rrrrrrrrrrrrssut",
      "sssssssssssssuut",
      "iiiiiiiiiiiiiiii",
      "wwwwwwwwwwwwwwwt",
      "wwwwwwwwwwwwwwwt",
      "wwwwwwwwwwwwwwwt",
      "wwwwwwwwwwwwwwwt",
      "wwwwwwwwwwwwwwwt",
      "wwwwwwwwwwwwwwwt",
      "wwwwwwwwwwwwwwwt"
    ]
  ]
}