{
  "name": "multi_verticalschool_6_floor31",
  "refpalette": "deceasedcraft:multi_verticalschool_6/multi_verticalschool_6_floor31_palette",
  "xsize": 16,
  "zsize": 16,
  "slices": [
    [
      "                ",
      " aaa            ",
      "                ",
      "                ",
      "                ",
      "                ",
      "                ",
      "  b             ",
      " cb             ",
      "  b             ",
      "                ",
      "                ",
      "                ",
      "                ",
      "                ",
      "                "
    ],
    [
      "                ",
      " aaa            ",
      "       dddd     ",
      "                ",
      "                ",
      "                ",
      "                ",
      "                ",
      " c              ",
      "                ",
      "                ",
      "                ",
      "                ",
      "                ",
      "                ",
      "  e             "
    ],
    [
      "                ",
      " aaa   f  f     ",
      "       dddd     ",
      "                ",
      "                ",
      "                ",
      "                ",
      "                ",
      " c              ",
      "                ",
      "                ",
      "                ",
      "                ",
      "                ",
      "                ",
      "                "
    ],
    [
      "                ",
      " aaa   g  g     ",
      "       h  h     ",
      "                ",
      "                ",
      "                ",
      "                ",
      "                ",
      " c              ",
      "                ",
      "                ",
      "                ",
      "                ",
      "                ",
      "                ",
      "                "
    ],
    [
      "iiiiiiiiiiiiiiii",
      "iaaajjjkjjkjjjjj",
      "ijllllllllmmmmll",
      "ijlnnnnnnnnnnnnn",
      "ijlnnnnnnnnnnnnn",
      "ijlnnnnnnnnnnnnn",
      "ijmnnnnnnnnnnnnn",
      "ijmnnnnnnnnnnnnn",
      "ikmnnnnnnnnnnnnn",
      "ijmnnnnnnnnnnnnn",
      "ijmnnnnnnnnnnnnn",
      "ijmnnnnnnnnnnnnn",
      "ijmnnnnnnnnnnnnn",
      "ijmnnnnnnnnnnnnn",
      "ijmmmmllllmmmmmm",
      "ijjjjjjjjjjjjjjj"
    ],
    [
      "oooooooooooooooo",
      "oaaaaaaaaaaaaaaa",
      "oapppppppppppppp",
      "oapppppppppppppp",
      "oappqpppqppppppp",
      "oapppppppppppppp",
      "oapppppppppppppp",
      "oapppppppppppppp",
      "oapppppppppppppp",
      "oapppppppppppppp",
      "oappqpppqppppppp",
      "oapppppppppppppp",
      "oapppppppppppppp",
      "oapprppprppppppp",
      "oapppppppppppppp",
      "oassssssssstpppp"
    ]
  ]
}