{
  "name": "multi_verticalschool_6_floor3",
  "refpalette": "deceasedcraft:multi_verticalschool_6/multi_verticalschool_6_floor3_palette",
  "xsize": 16,
  "zsize": 16,
  "slices": [
    [
      "                ",
      " aaa            ",
      "                ",
      "                ",
      "                ",
      "                ",
      "                ",
      "                ",
      "                ",
      "                ",
      "                ",
      "                ",
      "                ",
      "                ",
      "                ",
      "                "
    ],
    [
      "                ",
      " aaa            ",
      "                ",
      "                ",
      "                ",
      "                ",
      "                ",
      "                ",
      "                ",
      "                ",
      "                ",
      "                ",
      "                ",
      "                ",
      "                ",
      "                "
    ],
    [
      "                ",
      " aaa            ",
      "                ",
      "                ",
      "                ",
      "                ",
      "                ",
      "                ",
      "                ",
      "                ",
      "                ",
      "                ",
      "                ",
      "                ",
      "                ",
      "                "
    ],
    [
      "                ",
      " aaa            ",
      "                ",
      "                ",
      "                ",
      "                ",
      "                ",
      "                ",
      "                ",
      "                ",
      "                ",
      "                ",
      "                ",
      "                ",
      "                ",
      "                "
    ],
    [
      "bbbbbbbbbbbbbbbb",
      "baaabbbcbbbcbbbc",
      "bbbbbbbbbbbbbbbb",
      "bbbbbbbbbbbbbbbb",
      "bbbbbbbbbbbbbbbb",
      "bbbbbbbbbbbbbbbb",
      "bbbcbbbcbbbcbbbc",
      "bbbbbbbbbbbbbbbb",
      "bbbbbbbbbbbbbbbb",
      "bbbbbbbbbbbbbbbb",
      "bbbbbbbbbbbbbbbb",
      "bbbcbbbcbbbcbbbc",
      "bbbbbbbbbbbbbbbb",
      "bbbbbbbbbbbbbbbb",
      "bbbbbbbbbbbbbbbb",
      "bbbbbbbbbbbbbbbb"
    ],
    [
      "dddbbbbbbbbbbbbb",
      "daaaeeeeeeeebeee",
      "dbeeeeeeeebbeeee",
      "beeeeeeebbeeeeee",
      "beeeeebbeeeeeeeb",
      "beeebbeeeeeebbbd",
      "bebbeeeeebbbdddf",
      "bbeeeebbbddfffff",
      "beebbbfddffdffff",
      "dbbddddfffffffff",
      "dfdfffffffffffdf",
      "fffffffffffddddd",
      "ffffdfffdddddddd",
      "fffddddddddddddd",
      "ffdddddddddddddd",
      "fddddddddddddddd"
    ]
  ]
}