{
  "name": "multi_verticalschool_6_floor24",
  "refpalette": "deceasedcraft:multi_verticalschool_6/multi_verticalschool_6_floor24_palette",
  "xsize": 16,
  "zsize": 16,
  "slices": [
    [
      "                ",
      " aaa            ",
      "                ",
      "                ",
      "                ",
      "                ",
      "                ",
      "                ",
      "                ",
      "   bbbbbbb      ",
      "   ccccccc      ",
      "   ccccccc      ",
      "   c     c      ",
      "   c     c      ",
      "   c     c      ",
      "   c bbb c      "
    ],
    [
      "                ",
      " aaa            ",
      "                ",
      "                ",
      "                ",
      "                ",
      "                ",
      "                ",
      "                ",
      "                ",
      "                ",
      "   bbbbbbb      ",
      "   ccccccc      ",
      "   ccccccc      ",
      "   c     c      ",
      "   c     c      "
    ],
    [
      "                ",
      " aaa            ",
      "                ",
      "                ",
      "                ",
      "                ",
      "                ",
      "                ",
      "                ",
      "                ",
      "                ",
      "                ",
      "                ",
      "   bbbbbbb      ",
      "   ccccccc      ",
      "   ccccccc      "
    ],
    [
      "                ",
      " aaa            ",
      "                ",
      "                ",
      "                ",
      "                ",
      "                ",
      "                ",
      "                ",
      "                ",
      "                ",
      "                ",
      "                ",
      "                ",
      "                ",
      "   bbbbbbb      "
    ],
    [
      "                ",
      " aaa            ",
      "                ",
      "                ",
      "                ",
      "                ",
      "                ",
      "                ",
      "                ",
      "                ",
      "                ",
      "                ",
      "                ",
      "                ",
      "                ",
      "                "
    ],
    [
      "deeeeeeeeeeeeeee",
      "eaaaeeeeeeeeeeee",
      "eeeeeeeeeeeeeeee",
      "eeeeeeeeeeeeeeee",
      "eeeeeeeeeeeeeeee",
      "eeeeeeeeeeeeeeee",
      "eeeeeeeeeeeeeeee",
      "eeeeeeeeeeeeeeee",
      "eeeeeeeeeeeeeeee",
      "eeeeeeeeeeeeeeee",
      "eeeeeeeeeeeeeeee",
      "eeeeeeeeeeeeeeee",
      "eeeeeeeeeeeeeeee",
      "eeeeeeeeeeeeeeee",
      "eeeeeeeeeeeeeeee",
      "eeeeeeeeeeeeeeee"
    ]
  ]
}