{
  "name": "multi_verticalschool_6_floor16",
  "refpalette": "deceasedcraft:multi_verticalschool_6/multi_verticalschool_6_floor16_palette",
  "xsize": 16,
  "zsize": 16,
  "slices": [
    [
      "                ",
      " aaabbbbbbbb    ",
      " b c c c   d    ",
      " b c c c   d    ",
      " beeeeee   b    ",
      " b       fgb    ",
      " bbbbbbbbbbb   h",
      " b       ijb    ",
      " bkkkkkk   b    ",
      " b c c c   d    ",
      " b c c c   d   h",
      " bbbbbbbbbbb    ",
      "      lmn       ",
      "        oo      ",
      "      pp       h",
      "       qmr      "
    ],
    [
      "                ",
      " aaabbbbbbbb    ",
      " s         b    ",
      " s         b    ",
      " s         b    ",
      " s         b    ",
      " bbbbbbbbbbb   t",
      " s         b    ",
      " s         b    ",
      " s         b    ",
      " s         b   t",
      " bbbbbbbbbbb    ",
      "     lmn        ",
      "       oo       ",
      "       pp      t",
      "        qmr     "
    ],
    [
      "                ",
      " aaabbbbbbbb    ",
      " buuuuuuuuub    ",
      " buuuuuuuuub    ",
      " buuuuuuuuub    ",
      " buuuuuuuuub    ",
      " bbbbbbbbbbb   t",
      " buuuuuuuuub    ",
      " buuuuuuuuub    ",
      " buuuuuuuuub    ",
      " buuuuuuuuub   t",
      " bbbbbbbbbbb    ",
      " b  lmn   ww    ",
      " b    oo        ",
      " b      pp     x",
      " b  ww   qmr    "
    ],
    [
      "y               ",
      " aaabbbbbbbb    ",
      " bABABABBBBb    ",
      " bBBBBBBBBBb    ",
      " bBBBBBBBBBb    ",
      " bBBBBBBBBBb    ",
      " bBBBBBBBBBb   x",
      " bBBBBBBBBBb    ",
      " bBBBBBBBBBb    ",
      " bBBBBBBBBBb    ",
      " bABABABBBBb   x",
      " bbbbbbbbbbb    ",
      " bCCDn   lmDCE  ",
      " bCC oo    oCE  ",
      " bCCp    pp CE  ",
      " bCCDmr   qDCE  "
    ],
    [
      "yyyyyyyyyyyyyyyy",
      "yaaabbbbbbbb    ",
      "ybAFA AF  Fb    ",
      "ybF   F    b    ",
      "yb         b    ",
      "yb         b    ",
      "yb         b    ",
      "yb         b    ",
      "ybF        b    ",
      "ybF        b    ",
      "ybAFA AF   b    ",
      "ybbbbbbbbbbb    ",
      "yb      lmn IJ  ",
      "yb  oo    ooKL  ",
      "yb  pp    ppKL  ",
      "yb   qmr    MN  "
    ],
    [
      "OPPPPPPPPPPPPPPP",
      "Paaabbbbbbbb    ",
      "PbA A A    b    ",
      "Pb         b    ",
      "Pb         b    ",
      "Pb         b    ",
      "Pb         b    ",
      "Pb         b    ",
      "Pb         b    ",
      "PbF        b    ",
      "PbA A A    b    ",
      "Pbbbbbbbbbbb    ",
      "Pb     lmn      ",
      "Pb       oo     ",
      "Pb   pp         ",
      "Pb    qmr       "
    ]
  ]
}