{
  "name": "multi_verticalschool_6_floor15",
  "refpalette": "deceasedcraft:multi_verticalschool_6/multi_verticalschool_6_floor15_palette",
  "xsize": 16,
  "zsize": 16,
  "slices": [
    [
      " aaaaaaaaaaaaaaa",
      "abbbaaaaaaaaaaaa",
      "aa         a    ",
      "aa cdc cdc a    ",
      "aa dcd dcd a    ",
      "aa cdc cdc a    ",
      "aa         a    ",
      "aa  e   e  a    ",
      "aa         a    ",
      "aa         a    ",
      "aa       f a    ",
      "aagaaaaaaaaa    ",
      "aah   ijk       ",
      "aa      ll      ",
      "aa    mm        ",
      "aa     njo      "
    ],
    [
      " aaaaaaaaaaaaaaa",
      "abbbaaaaaaaaaaaa",
      "aa         a    ",
      "aa pqp pqp a    ",
      "aa qpq qpq a    ",
      "aa pqp pqp a    ",
      "aa         a    ",
      "aa  r   r  a    ",
      "aa         a    ",
      "aa         a    ",
      "aa         a    ",
      "aaaaaaaaaaaa    ",
      "aa   ijk        ",
      "aa     ll       ",
      "aa     mm       ",
      "aa      njo     "
    ],
    [
      "saaaaaaaaaaaaaaa",
      "abbbaaaaaaaaaaaa",
      "aatttttttttauuuu",
      "aatttttttttauwww",
      "aatttttttttauwww",
      "aatttttttttauwww",
      "aatttttttttauwww",
      "aattetttettauwww",
      "aatttttttttauwww",
      "aatttttttttauwww",
      "aatttttttttauwww",
      "aaaaaaaaaaaauwww",
      "aa  ijk   xxuwww",
      "aa    ll    uwww",
      "aa      mm  uwww",
      "aa  xx   njouwww"
    ],
    [
      "yAyyyyyyyyyyyyyA",
      "ybbbBBBBBBBBCCCC",
      "ABDDDDDDDDDBCCCC",
      "ABDDDDDDDDDBCCCC",
      "ABDDDDDDDDDBCCCE",
      "ABDDDDDDDDDBCCCE",
      "ABBBBBBBBBBBCCCE",
      "ABDDDDDDDDDBCCCE",
      "ABDDDDDDDDDBCCCE",
      "ABDDDDDDDDDBCCCE",
      "ABDDDDDDDDDBCCCE",
      "ABBBBBBBBBBBCCCE",
      "CCCCFk   ijFCCCE",
      "CCCC ll    lCCCE",
      "CCCCm    mm CCCE",
      "CCCCFjo   nFCCCE"
    ],
    [
      "                ",
      " bbbBBBBBBBB    ",
      "IBJKJKJK        ",
      "LB K K K       M",
      "IBNONONO   B  PA",
      "IB       QQB  PA",
      "IBBBBBBBBBBB  PA",
      "LB       RRB  PA",
      "IBSTSTST   B  PA",
      "LB K K K      PA",
      "IBUKUKUK      PA",
      "IBBBBBBBBBBB  PA",
      "        ijk   PA",
      "   Vll    llW PA",
      "   Vmm    mmW PA",
      "     njo      PA"
    ],
    [
      "                ",
      " bbbXXXXXXXX    ",
      " X K K K        ",
      " X K K K        ",
      " XYOYOYO   X   Z",
      " X      0  X   L",
      " XXXXXXXXXXX   1",
      " X      2  X   I",
      " X3T3T3T   X   I",
      " X K K K       Z",
      " X K K K       1",
      " XXXXXXXXXXX   L",
      "       ijk     I",
      "         ll    I",
      "     mm        1",
      "      njo      4"
    ]
  ]
}