{
  "name": "multi_verticalschool_6_floor22",
  "refpalette": "deceasedcraft:multi_verticalschool_6/multi_verticalschool_6_floor22_palette",
  "xsize": 16,
  "zsize": 16,
  "slices": [
    [
      " aaaaaaaaaaaaaaa",
      "abbbcccccccccccc",
      "adddeeddffffffff",
      "ad  ggh         ",
      "ai  gg          ",
      "ai  gg          ",
      "ad              ",
      "ai              ",
      "ai              ",
      "ad              ",
      "ai              ",
      "ai              ",
      "ad              ",
      "ai              ",
      "ai              ",
      "ad              "
    ],
    [
      "jaaaaaaaaaaaaaaa",
      "abbbdddddddddddd",
      "adeeddkkkkkkkkkk",
      "adggl           ",
      "adgg            ",
      "adgg            ",
      "ad              ",
      "ad              ",
      "ad              ",
      "ad              ",
      "ad              ",
      "ad              ",
      "ad              ",
      "ad              ",
      "ad              ",
      "ad              "
    ],
    [
      "mmmmmmmmmmmmmmmm",
      "nbbbmmmmmmmmmmmm",
      "mmmmmmmmmmmmmmmm",
      "moh             ",
      "mo              ",
      "mo              ",
      "mo              ",
      "mo              ",
      "mo              ",
      "mo              ",
      "mo              ",
      "mo              ",
      "mo              ",
      "mo              ",
      "mo              ",
      "mo              "
    ],
    [
      "                ",
      "pbbb qrst  qrst ",
      " uuuuuuuuuuuuuuu",
      "                ",
      "                ",
      "                ",
      " u              ",
      " u              ",
      "wu              ",
      "wu              ",
      " u              ",
      " u              ",
      " u              ",
      "wu              ",
      "wu              ",
      " u              "
    ],
    [
      "                ",
      "xbbb       y    ",
      "                ",
      "                ",
      "                ",
      "                ",
      "                ",
      "                ",
      "                ",
      "                ",
      "                ",
      "                ",
      "                ",
      "                ",
      "                ",
      "                "
    ],
    [
      "                ",
      "Abbb            ",
      "                ",
      "                ",
      "                ",
      "                ",
      "                ",
      "                ",
      "                ",
      "                ",
      "                ",
      "                ",
      "                ",
      "                ",
      "                ",
      "                "
    ]
  ]
}