{
  "name": "multi_verticalschool_6_floor14",
  "refpalette": "deceasedcraft:multi_verticalschool_6/multi_verticalschool_6_floor14_palette",
  "xsize": 16,
  "zsize": 16,
  "slices": [
    [
      "                ",
      "abbbaaaaaaaaaaa ",
      "ca d d d   e    ",
      " a d d d   e    ",
      " affffff   a    ",
      "ca       gha    ",
      "iaaaaaaaaaaa    ",
      "ja       kla    ",
      " ammmmmm   a    ",
      " a d d d   e    ",
      "ca d d d   e    ",
      "aaaaaaaaaaaa    ",
      "      nop       ",
      "        qq      ",
      "      rr        ",
      "       sot      "
    ],
    [
      "                ",
      "abbbaaaaaaaaaaa ",
      "ua         a    ",
      " a         a    ",
      " a         a    ",
      "ua         a    ",
      "iaaaaaaaaaaa    ",
      "ua         a    ",
      " a         a    ",
      " a         a    ",
      "ua         a    ",
      "aaaaaaaaaaaa    ",
      "     nop        ",
      "       qq       ",
      "       rr       ",
      "        sot     "
    ],
    [
      "                ",
      "abbbaaaaaaaaaaa ",
      "waxxxxxxxxxa    ",
      " axxxxxxxxxa    ",
      " axxxxxxxxxa    ",
      "!axxxxxxxxxa    ",
      "iaaaaaaaaaaa    ",
      " axxxxxxxxxa    ",
      " axxxxxxxxxa    ",
      " axxxxxxxxxa    ",
      " axxxxxxxxxa    ",
      "aaaaaaaaaaaa    ",
      " y  nop   AA    ",
      " y    qq        ",
      " y      rr      ",
      " y  AA   sot    "
    ],
    [
      "                ",
      "abbbaaaaaaaaaaa ",
      " aBBBBBBBBBa    ",
      " aBBCBBBCBBa    ",
      " aBBBBBBBBBa    ",
      " aBBBBBBBBBa    ",
      "iaBBBBBBBBBa    ",
      " aBBBBBBBBBa    ",
      " aBBBBBBBBBa    ",
      " aBBBBBBBBBa    ",
      " aBBBBBBBBBa    ",
      "aaaaaaaaaaaa    ",
      " aDEFp   noFED  ",
      " aDE qq    qED  ",
      " aDEr    rr ED  ",
      " aDEFot   sFED  "
    ],
    [
      "IIIIIIIIIIIIIIJJ",
      "abbbaaaaaaaaaaay",
      "Ba         a    ",
      "Ba iKi iKi a    ",
      "Ba iii iii a    ",
      "Ba iLi iLi a    ",
      "Ma NOP QON a    ",
      "Ba RL  ~S~ a    ",
      "Ba   R  ~ Ta    ",
      "Ba   RRT UUa    ",
      "Ba  RR  UVVa    ",
      "aaWaaaaaaaaa    ",
      "xa      nop XY  ",
      "xa Zqq    qq01  ",
      "xa Zrr    rr01  ",
      "xa   sot    23  "
    ],
    [
      "4aaaaaaaaaaaaaaa",
      "abbbaaaaaaaaaaaa",
      "aa         a    ",
      "aa 565 565 a    ",
      "aa 656 656 a    ",
      "aa 565 565 a    ",
      "aa         a    ",
      "aa  C      a    ",
      "aa         a    ",
      "aa   R   T a    ",
      "aa       U7a    ",
      "aa8aaaaaaaaa    ",
      "aa     nop      ",
      "aa       qq     ",
      "aa   rr         ",
      "aa    sot       "
    ]
  ]
}