{
  "name": "multi_verticalschool_6_floor8",
  "refpalette": "deceasedcraft:multi_verticalschool_6/multi_verticalschool_6_floor8_palette",
  "xsize": 16,
  "zsize": 16,
  "slices": [
    [
      "                ",
      " aaa            ",
      "                ",
      "                ",
      "                ",
      "                ",
      "                ",
      "                ",
      "                ",
      "                ",
      "bbbbbbbbbbbbbbbb",
      "cccccccccccccccc",
      "  d        d    ",
      "                ",
      "                ",
      " eeeeeeeeeeeeffe"
    ],
    [
      "                ",
      " aaa            ",
      "                ",
      "                ",
      "                ",
      "                ",
      "                ",
      "                ",
      "                ",
      "                ",
      "bbbbbbbbbbbbbbbb",
      "cccccccccccccccc",
      "gggggggggggggggg",
      "hhhhhhhhhhhhhhhh",
      "hhhhhhhhhhhhhhhh",
      "heeeeeeeeeeeeeee"
    ],
    [
      "                ",
      " aaa            ",
      "                ",
      "                ",
      "                ",
      "                ",
      "                ",
      "                ",
      "                ",
      "                ",
      "bbbbbbbbbbbbbbbb",
      "cccccccccccccccc",
      "cccccccccccccccc",
      "iiiiiiiiiiiiiiii",
      "jjjjjjjjjjjjjjjj",
      "jjjjeeeeeeeeeeee"
    ],
    [
      "                ",
      " aaa            ",
      "                ",
      "                ",
      "                ",
      "                ",
      "                ",
      "                ",
      "                ",
      "                ",
      "                ",
      "                ",
      "                ",
      "kkkkklklkkkllkkk",
      "                ",
      "    eeeeeeeeeeee"
    ],
    [
      "                ",
      " aaa            ",
      "                ",
      "                ",
      "                ",
      "                ",
      "                ",
      "                ",
      "                ",
      "                ",
      "                ",
      "                ",
      "                ",
      "                ",
      "                ",
      "    eeeeeeeeeeee"
    ],
    [
      "            m nn",
      " aaa       m nno",
      "          m nnon",
      "         m nnonn",
      "        m nnonnn",
      "       m nnonnnn",
      "      m nnonnnnn",
      "     m nnonnnnnn",
      "    m nnonnnnnnn",
      "   m nnonnnnnnnn",
      "  m nnonnnnnnnnn",
      " m nnonnnnnnnnnn",
      "m nnonnnnnnnnnnn",
      " nnonnnnnnnnnnnn",
      "nnonnnnnnnnnnnnn",
      "nonneeeeeeeeeeee"
    ]
  ]
}