{
  "name": "multi_verticalschool_6_floor29",
  "refpalette": "deceasedcraft:multi_verticalschool_6/multi_verticalschool_6_floor29_palette",
  "xsize": 16,
  "zsize": 16,
  "slices": [
    [
      "aaaaaaaaaaaaaaaa",
      "abbbccccccccdddd",
      "aceeeeeeeeecdddd",
      "aceeeeeeeeecdddd",
      "aceeeeeeeeecdddd",
      "aceeeeeeeeecdddd",
      "acccccccccccdddd",
      "aceeeeeeeeecdddd",
      "aceeeeeeeeecdddd",
      "aceeeeeeeeecdddd",
      "aceeeeeeeeecdddd",
      "acccccccccccdddd",
      "acfffffffffcdddd",
      "acfffffffffcdddd",
      "acfffffffffcdddd",
      "acfffffffffcdddd"
    ],
    [
      "gggggggggggggggg",
      "hbbbcccccccci  i",
      "hcjkjkjk        ",
      "hc k k k        ",
      "hclmlmlm   c    ",
      "hc       nnc    ",
      "hccccccccccc    ",
      "hc       ooc    ",
      "hcpqrqpq   c    ",
      "hc ksk kt       ",
      "hcukukuk w x    ",
      "hccccccccccc    ",
      "hcyABBBBBAyc    ",
      "hc    C    D    ",
      "hc  C      E    ",
      "hcFF      Ic    "
    ],
    [
      "                ",
      " bbbJJJJJJJJ    ",
      " J k k k        ",
      " J k k k        ",
      " JKmKmKm   J    ",
      " J      L  J    ",
      " JJJJJJJJJJJ    ",
      " J      M  J    ",
      " JNqOqNq   J    ",
      " J k k k        ",
      " J k k k        ",
      " JJJJJJJJJJJ    ",
      " JP! QR STUJ    ",
      " J         V    ",
      " J         W    ",
      " J X       J    "
    ],
    [
      "                ",
      " bbbJJJJJJJJ    ",
      " J k k k   Y    ",
      " J k k k   Y    ",
      " Jmmmmmm   J    ",
      " J       Z0J    ",
      " JJJJJJJJJJJ    ",
      " J       12J    ",
      " Jqqqqqq   J    ",
      " J k k k   Y    ",
      " J k k k   Y    ",
      " JJJJJJJJJJJ    ",
      " J    3    J    ",
      " J        45    ",
      " J        45    ",
      " J         J    "
    ],
    [
      "                ",
      " bbbJJJJJJJJ    ",
      " 6         J    ",
      " 6         J    ",
      " 6         J    ",
      " 6         J    ",
      " JJJJJJJJJJJ    ",
      " 6         J    ",
      " 6         J    ",
      " 6         J    ",
      " 6         J    ",
      " JJJJJJJJJJJ    ",
      " 6         J    ",
      " 6         J    ",
      " 6         J    ",
      " 6         J    "
    ],
    [
      "7777777777777777",
      "7bbbJJJJJJJJ8888",
      "7J999999999J####",
      "7J999999999J####",
      "7J999999999J####",
      "7J999999999J####",
      "7JJJJJJJJJJJ#$$#",
      "7J999999999J####",
      "7J999999999J####",
      "7J999999999J####",
      "7J999999999J####",
      "7JJJJJJJJJJJ#$$#",
      "7J999999999J####",
      "7J99%999%99J####",
      "7J99%999%99J####",
      "7J999999999J####"
    ]
  ]
}