{
  "name": "multi_verticalschool_6_base2",
  "refpalette": "deceasedcraft:multi_verticalschool_6/multi_verticalschool_6_base2_palette",
  "xsize": 16,
  "zsize": 16,
  "slices": [
    [
      "vvvvvvvvvvvvvvvv",
      "vvvvvvvvvvvvvvvv",
      "vvvvvvvvvvvvvvvv",
      "vvvvvvvvvvvvvvvv",
      "vvvvvvvvvvvvvvvv",
      "vvvvvvvvvvvvvvvv",
      "vvvvvvvvvvvvvvvv",
      "vvvvvvvvvvvvvvvv",
      "vvvvvvvvvvvvvvvv",
      "vvvvvvvvvvvvvvvv",
      "vvvvvvvvvvvvvvvv",
      "vvvvvvvvvvvvvvvv",
      "vvvvvvvvvvvvvvvv",
      "vvvvvvvvvvvvvvvv",
      "vvvvvvvvvvvvvvvv",
      "vvvvvvvvvvvvvvvv"
    ],
    [
      "aaaaaaaaaaaaaaaa",
      "abbbaaaaaaaaaaaa",
      "aaaaaaaaaaaaaaaa",
      "aaaaaaaaaaaaaaaa",
      "aaaaaaaaaaaaaaaa",
      "aaaaaaaaaaaaaaaa",
      "aaaaaaaaaaaaaaaa",
      "aaaaaaaaaaaaaaaa",
      "aaaaaaaaaaaaaaaa",
      "aaaaaaaaaaaaaaaa",
      "aaaaaaaaaaaaaaaa",
      "aaaaaaaaaaaaaaaa",
      "aaaaaaaaaaaaaaaa",
      "aaaaaaaaaaaaaaaa",
      "aaaaaaaaaaaaaaaa",
      "aaaaaaaaaaaaaaaa"
    ],
    [
      "aaaaaaaaaaaaaaaa",
      "abbbaaaaaaaaaaaa",
      "aaaaaaaaaaaaaaaa",
      "aaaaaaaaaaaaaaaa",
      "aaaaaaaaaaaaaaaa",
      "aaaaaaaaaaaaaaaa",
      "aaaaaaaaaaaaaaaa",
      "aaaaaaaaaaaaaaaa",
      "aaaaaaaaaaaaaaaa",
      "aaaaaaaaaaaaaaaa",
      "aaaaaaaaaaaaaaaa",
      "aaaaaaaaaaaaaaaa",
      "aaaaaaaaaaaaaaaa",
      "aaaaaaaaaaaaaaaa",
      "aaaaaaaaaaaaaaaa",
      "aaaaaaaaaaaaaaaa"
    ],
    [
      "cccccccccccccccd",
      "cbbbcccccccccccd",
      "cccccccccccccccd",
      "cccccccccccccccd",
      "cccccccccccccccd",
      "cccccccccccccccd",
      "cccccccccccccccd",
      "cccccccccccccccd",
      "eeeeeeeeeeeeeeee",
      "cccccccccccccccd",
      "cccccccccccccccd",
      "cccccccccccccccd",
      "cccccccccccccccd",
      "cccccccccccccccd",
      "cccccccccccccccd",
      "cccccccccccccccd"
    ],
    [
      "fffffffffffffffg",
      "fhhhfffffffffffg",
      "fffffffffffffffg",
      "fijffffffffffffg",
      "fijffffffffffffg",
      "fijffffffffffffg",
      "fffffffffffffffg",
      "fffffffffffffffg",
      "kkkkkkkkkkkkkkle",
      "               d",
      "               d",
      "               d",
      " m  m          d",
      "nnnnnnno       d",
      " p  p          d",
      "               d"
    ],
    [
      "               g",
      " hhh           g",
      "iqq            g",
      "jr             g",
      "jr             g",
      "sr             g",
      " tt            g",
      "               g",
      "              ue",
      "               w",
      "               w",
      "               w",
      "               w",
      "               w",
      "               w",
      "               w"
    ]
  ]
}