{
  "name": "multi_verticalschool_6_floor25",
  "refpalette": "deceasedcraft:multi_verticalschool_6/multi_verticalschool_6_floor25_palette",
  "xsize": 16,
  "zsize": 16,
  "slices": [
    [
      "aaaaaaaaaaaaaaaa",
      "abbbccccccccdddd",
      "aceeeeeeeeecdddd",
      "aceeeeeeeeecdddd",
      "aceeeeeeeeecdddd",
      "aceeeeeeeeecdddd",
      "acccccccccccdddd",
      "aceeeeeeeeecdddd",
      "aceeeeeeeeecdddd",
      "aceeeeeeeeecdddd",
      "aceeeeeeeeecdddd",
      "acccccccccccdddd",
      "acfffffffffcdddd",
      "acfffffffffcdddd",
      "acfffffffffcdddd",
      "acfffffffffcdddd"
    ],
    [
      "gggggggggggggggg",
      "hbbbcccccccci  i",
      "hcjkjkjk        ",
      "hc k k k        ",
      "hclmlmlm   c    ",
      "hc       nnc    ",
      "hccccccccccc    ",
      "hc       ooc    ",
      "hcpqpqpq   c    ",
      "hc k k k        ",
      "hcrkrkrk        ",
      "hccccccccccc    ",
      "hcs  tu wxyc    ",
      "hcA BC     D    ",
      "hcs  Eu    F    ",
      "hcA      IIc    "
    ],
    [
      "                ",
      " bbbJJJJJJJJ    ",
      " J k k k        ",
      " J k k k        ",
      " JKmKmKmL  J    ",
      " J      !L J    ",
      " JJJJJJJJJJJ    ",
      " J      M  J    ",
      " JNqNqNq   J    ",
      " J k k k        ",
      " J k k k        ",
      " JJJJJJJJJJJ    ",
      " JO        J    ",
      " J   P     Q    ",
      " JR  S     T    ",
      " JU      V J    "
    ],
    [
      "                ",
      " bbbJJJJJJJJ    ",
      " J k k k   W    ",
      " J k k k   W    ",
      " Jmmmmmm   J    ",
      " J      LXYJ    ",
      " JJJJJJJJJJJ    ",
      " J       Z0J    ",
      " Jqqqqqq   J    ",
      " J k k k   W    ",
      " J k k k   W    ",
      " JJJJJJJJJJJ    ",
      " J         J    ",
      " J         W    ",
      " J         W    ",
      " J         J    "
    ],
    [
      "                ",
      " bbbJJJJJJJJ    ",
      " 1         J    ",
      " 1         J    ",
      " 1         J    ",
      " 1         J    ",
      " JJJJJJJJJJJ    ",
      " 1         J    ",
      " 1         J    ",
      " 1         J    ",
      " 1         J    ",
      " JJJJJJJJJJJ    ",
      " 1         J    ",
      " 1         J    ",
      " 1         J    ",
      " 1         J    "
    ],
    [
      "2222222222222222",
      "2bbbJJJJJJJJ3333",
      "2J444444444J5555",
      "2J444444444J5555",
      "2J444444444J5555",
      "2J444444444J5555",
      "2JJJJJJJJJJJ5665",
      "2J444444444J5555",
      "2J444444444J5555",
      "2J444444444J5555",
      "2J444444444J5555",
      "2JJJJJJJJJJJ5775",
      "2J444444444J5555",
      "2J448444844J5555",
      "2J448444844J5555",
      "2J444444444J5555"
    ]
  ]
}