{
  "name": "multi_verticalschool_6_floor13",
  "refpalette": "deceasedcraft:multi_verticalschool_6/multi_verticalschool_6_floor13_palette",
  "xsize": 16,
  "zsize": 16,
  "slices": [
    [
      "                ",
      " aaa            ",
      "                ",
      "                ",
      "                ",
      "                ",
      "                ",
      "                ",
      "                ",
      "                ",
      "                ",
      "                ",
      "                ",
      "                ",
      "                ",
      "                "
    ],
    [
      "                ",
      " aaa            ",
      "                ",
      "                ",
      "                ",
      "                ",
      "                ",
      "                ",
      "                ",
      "                ",
      "                ",
      "                ",
      "                ",
      "                ",
      "                ",
      "                "
    ],
    [
      "bbbbbbbbbbbbbbbb",
      "baaabbbbbbbbbbbb",
      "bbbbbbbbbbbbbbbb",
      "bbbbbbbbbbbbbbbb",
      "bbbbbbbbbbbbbbbb",
      "bbbbbbbbbbbbbbbb",
      "bbbbbbbbbbbbbbbb",
      "bbbbbbbbbbbbbbbb",
      "bbbbbbbbbbbbbbbb",
      "bbbbbbbbbbbbbbbb",
      "bbbbbbbbbbbbbbbb",
      "bbbbbbbbbbbbbbbb",
      "bbbbbbbbbbbbbbbb",
      "bbbbbbbbbbbbbbbb",
      "bbbbbbbbbbbbbbbb",
      "bbbbbbbbbbbbbbbb"
    ],
    [
      "cccccccccccccccc",
      "daaaeeeeeeeedddd",
      "cefffffffffegggg",
      "cefffffffffegggg",
      "cefffffffffegggg",
      "cefffffffffegggg",
      "ceeeeeeeeeeegggg",
      "cefffffffffegggg",
      "cefffffffffegggg",
      "cefffffffffegggg",
      "cefffffffffegggg",
      "deeeeeeeeeeegggg",
      "ggggggggghhigggg",
      "gggggggggggggggg",
      "gggggggggggggggg",
      "ggggihhggggggggg"
    ],
    [
      "jj kjjjj jjjjj  ",
      "daaaddddddddddd ",
      "ldmnmnmn        ",
      " d n n n        ",
      " dopopop   d    ",
      "ld       qqd    ",
      "rddddddddddd    ",
      " d       ssd    ",
      " dtututu   d    ",
      " d n n n        ",
      " dwnwnwn        ",
      "dddddddddddd    ",
      "        xhy     ",
      "          AA    ",
      "    BB          ",
      "     ChD        "
    ],
    [
      "EF I!J K LLM N  ",
      "daaaddddddddddd ",
      "Od n n n        ",
      " d n n n        ",
      " dPpPpPp   d    ",
      "Od      Q  d    ",
      "rddddddddddd    ",
      "Od      R  d    ",
      " dSuSuSu   d    ",
      " d n n n        ",
      "Od n n n        ",
      "dddddddddddd    ",
      "       xhy      ",
      "         AA     ",
      "     BB         ",
      "      ChD       "
    ]
  ]
}