{
  "name": "multi_verticalschool_6_floor28",
  "refpalette": "deceasedcraft:multi_verticalschool_6/multi_verticalschool_6_floor28_palette",
  "xsize": 16,
  "zsize": 16,
  "slices": [
    [
      "aaaaaaaaaaaaaaaa",
      "abbbccccccccdddd",
      "aceeeeeeeeecdddd",
      "aceeeeeeeeecdddd",
      "aceeeeeeeeecdddd",
      "aceeeeeeeeecdddd",
      "acccccccccccdddd",
      "aceeeeeeeeecdddd",
      "aceeeeeeeeecdddd",
      "aceeeeeeeeecdddd",
      "aceeeeeeeeecdddd",
      "acccccccccccdddd",
      "acfffffffffcdddd",
      "acfffffffffcdddd",
      "acfffffffffcdddd",
      "acfffffffffcdddd"
    ],
    [
      "gggggggggggggggg",
      "hbbbcccccccci  i",
      "hcjkjkjk        ",
      "hc k k k        ",
      "hclmlmlm   c    ",
      "hc       nnc    ",
      "hccccccccccc    ",
      "hc       ooc    ",
      "hcpqpqpq   c    ",
      "hc k k k        ",
      "hcrkrkrk        ",
      "hccccccccccc    ",
      "hcstuuuuutsc    ",
      "hc  w w    x    ",
      "hc         y    ",
      "hcAB      Cc    "
    ],
    [
      "                ",
      " bbbDDDDDDDD    ",
      " D k k k        ",
      " D k k k        ",
      " DEmEmEm   D    ",
      " D      F  D    ",
      " DDDDDDDDDDD    ",
      " D      I  D    ",
      " DJqJqJq   D    ",
      " D k k k        ",
      " D k k k        ",
      " DDDDDDDDDDD    ",
      " DKL MNOP QD    ",
      " D         R    ",
      " D         S    ",
      " DT        D    "
    ],
    [
      "                ",
      " bbbDDDDDDDD    ",
      " D k k k   U    ",
      " D k k k   U    ",
      " Dmmmmmm   D    ",
      " D       VWD    ",
      " DDDDDDDDDDD    ",
      " D       XYD    ",
      " Dqqqqqq   D    ",
      " D k k k   U    ",
      " D k k k   U    ",
      " DDDDDDDDDDD    ",
      " D    Z    D    ",
      " D        01    ",
      " D        01    ",
      " D         D    "
    ],
    [
      "                ",
      " bbbDDDDDDDD    ",
      " 2         D    ",
      " 2         D    ",
      " 2         D    ",
      " 2         D    ",
      " DDDDDDDDDDD    ",
      " 2         D    ",
      " 2         D    ",
      " 2         D    ",
      " 2         D    ",
      " DDDDDDDDDDD    ",
      " 2         D    ",
      " 2         D    ",
      " 2         D    ",
      " 2         D    "
    ],
    [
      "3333333333333333",
      "3bbbDDDDDDDD4444",
      "3D555555555D6666",
      "3D555555555D6666",
      "3D555555555D6666",
      "3D555555555D6666",
      "3DDDDDDDDDDD6776",
      "3D555555555D6666",
      "3D555555555D6666",
      "3D555555555D6666",
      "3D555555555D6666",
      "3DDDDDDDDDDD6886",
      "3D555555555D6666",
      "3D559555#55D6666",
      "3D559555#55D6666",
      "3D555555555D6666"
    ]
  ]
}