{
  "name": "multi_verticalschool_9_base2",
  "refpalette": "deceasedcraft:multi_verticalschool_9/multi_verticalschool_9_base2_palette",
  "xsize": 16,
  "zsize": 16,
  "slices": [
    [
      "vvvvvvvvvvvvvvvv",
      "vvvvvvvvvvvvvvvv",
      "vvvvvvvvvvvvvvvv",
      "vvvvvvvvvvvvvvvv",
      "vvvvvvvvvvvvvvvv",
      "vvvvvvvvvvvvvvvv",
      "vvvvvvvvvvvvvvvv",
      "vvvvvvvvvvvvvvvv",
      "vvvvvvvvvvvvvvvv",
      "vvvvvvvvvvvvvvvv",
      "vvvvvvvvvvvvvvvv",
      "vvvvvvvvvvvvvvvv",
      "vvvvvvvvvvvvvvvv",
      "vvvvvvvvvvvvvvvv",
      "vvvvvvvvvvvvvvvv",
      "vvvvvvvvvvvvvvvv"
    ],
    [
      "aaaaaaaaaaaaaaaa",
      "aaaaaaaaaaaaaaaa",
      "aaaaaaaaaaaaaaaa",
      "aaaaaaaaaaaaaaaa",
      "aaaaaaaaaaaaaaaa",
      "aaaaaaaaaaaaaaaa",
      "aaaaaaaaaaaaaaaa",
      "aaaaaaaaaaaaaaaa",
      "aaaaaaaaaaaaaaaa",
      "aaaaaaaaaaaaaaaa",
      "aaaaaaaaaaaaaaaa",
      "aaaaaaaaaaaaaaaa",
      "aaaaaaaaaaaaaaaa",
      "abbbaaaaaaaaaaaa",
      "aaaaaaaaaaaaaaaa",
      "vvvvvvvvvvvvvvvv"
    ],
    [
      "aaaaaaaaaaaaaaaa",
      "aaaaaaaaaaaaaaaa",
      "aaaaaaaaaaaaaaaa",
      "aaaaaaaaaaaaaaaa",
      "aaaaaaaaaaaaaaaa",
      "aaaaaaaaaaaaaaaa",
      "aaaaaaaaaaaaaaaa",
      "aaaaaaaaaaaaaaaa",
      "aaaaaaaaaaaaaaaa",
      "aaaaaaaaaaaaaaaa",
      "aaaaaaaaaaaaaaaa",
      "aaaaaaaaaaaaaaaa",
      "aaaaaaaaaaaaaaaa",
      "abbbaaaaaaaaaaaa",
      "aaaaaaaaaaaaaaaa",
      "vvvvvvvvvvvvvvvv"
    ],
    [
      "aaaaaaaaaaaaaabc",
      "aaaaaaaaaaaaaacc",
      "aaaaaaaaaaaaaacc",
      "aaaaaaaaaaaaaacc",
      "aaaaaaaaaaaaaacc",
      "aaaaaaaaaaaaaacc",
      "aaaaaaaaaaaaaacc",
      "aaaaaaaaaaaaaacc",
      "aaaaaaaaaaaaaacc",
      "aaaaaaaaaaaavddc",
      "aaaaaaaaaaaaavvd",
      "aaaaaaaaaaaaaaav",
      "aaaaaaaaaaaaaaaa",
      "abbbaaaaaaaaaaaa",
      "aaaaaaaaaaaaaaaa",
      "vvvvvvvvvvvvvvvv"
    ],
    [
      "aaaaaaaaaaaeebfg",
      "aaaaaaaaaaabbchi",
      "aaaaaaaaaaacccHi",
      "aaaaaaaaaaacccHi",
      "aaaaaaaaaaacccHi",
      "aaaaaaaaaaacccHi",
      "aaaaaaaaaaacccHi",
      "aaaaaaaaaaacccHi",
      "aaaaaaaaaaabbchi",
      "aaaaaaaaaaaavddg",
      "aaaaaaaaaaaaavvd",
      "aaaaaaaaaaaaaaav",
      "aaaaaaaaaaaaaaaa",
      "abbbaaaaaaaaaaaa",
      "aaaaaaaaaaaaaaaa",
      "vvvvvvvvvvvvvvvv"
    ],
    [
      "aaaaaaaaeeejjfk ",
      "aaaaaaaabbbffl  ",
      "aaaaaaaaccchgm  ",
      "aaaaaaaacccHim  ",
      "aaaaaaaacccHim  ",
      "aaaaaaaacccHim  ",
      "aaaaaaaacccHim  ",
      "aaaaaaaaccchgm  ",
      "aaaaaaaabbbbbl  ",
      "aaaaaaaaaaaavnn ",
      "aaaaaaaaaaaaavvn",
      "aaaaaaaaaaaaaaav",
      "aaaaaaaaaaaaaaaa",
      "abbbaaaaaaaaaaaa",
      "aaaaaaaaaaaaaaaa",
      "vvvvvvvvvvvvvvvv"
    ]
  ]
}