{
  "name": "multi_verticalschool_9_base1",
  "refpalette": "deceasedcraft:multi_verticalschool_9/multi_verticalschool_9_base1_palette",
  "xsize": 16,
  "zsize": 16,
  "slices": [
    [
      "aaaaabbbccd     ",
      "aaaaaeeefffgh   ",
      "aaaaaiiijkl     ",
      "aaaaaiiiHmn     ",
      "aaaaaiiiHmn     ",
      "aaaaaiiiHmn     ",
      "aaaaaiiiHmn     ",
      "aaaaaiiijkl     ",
      "aaaaaeeeeeeee   ",
      "aaaaaaaaaaaavoo ",
      "aaaaaaaaaaaaavvo",
      "aaaaaaaaaaaaaaav",
      "aaaaaaaaaaaaaaaa",
      "aeeeaaaaaaaaaaaa",
      "aaaaaaaaaaaaaaaa",
      "vvvvvvvvvvvvvvvv"
    ],
    [
      "aabbbccd        ",
      "aaeeefffgh      ",
      "aaiiijkl        ",
      "aaiiiHmn        ",
      "aaiiiHmn        ",
      "aaiiiHmn        ",
      "aaiiiHmn        ",
      "aaiiijkl        ",
      "aaeeeeeeeeeee   ",
      "aaaaaaaaaaaavoo ",
      "aaaaaaaaaaaaavvo",
      "aaaaaaaaaaaaaaav",
      "aaaaaaaaaaaaaaaa",
      "aeeeaaaaaaaaaaaa",
      "aaaaaaaaaaaaaaaa",
      "vvvvvvvvvvvvvvvv"
    ],
    [
      "bbccd           ",
      "eefffgh         ",
      "iijkl           ",
      "iiHmn           ",
      "iiHmn           ",
      "iiHmn           ",
      "iiHmn           ",
      "iijkl           ",
      "eeeeeeeeeeeee   ",
      "aaaaaaaaaaaavoo ",
      "aaaaaaaaaaaaavvo",
      "aaaaaaaaaaaaaaav",
      "aaaaaaaaaaaaaaaa",
      "aeeeaaaaaaaaaaaa",
      "aaaaaaaaaaaaaaaa",
      "vvvvvvvvvvvvvvvv"
    ],
    [
      "cd              ",
      "ffgh            ",
      "kl              ",
      "mn              ",
      "mn              ",
      "mn              ",
      "mn              ",
      "kl              ",
      "eeeeeeeeeeeee   ",
      "aaaaaaaaaaaavoo ",
      "aaaaaaaaaaaaavvo",
      "aaaaaaaaaaaaaaav",
      "aaaaaaaaaaaaaaaa",
      "aeeeaaaaaaaaaaaa",
      "aaaaaaaaaaaaaaaa",
      "vvvvvvvvvvvvvvvv"
    ],
    [
      "                ",
      "h               ",
      "                ",
      "                ",
      "                ",
      "                ",
      "                ",
      "                ",
      "eeeeeeeeeeeeeppp",
      "aaaaaaaaaaaavoo ",
      "aaaaaaaaaaaaavvo",
      "aaaaaaaaaaaaaaav",
      "aaaaaaaaaaaaaaaa",
      "aeeeaaaaaaaaaaaa",
      "aaaaaaaaaaaaaaaa",
      "vvvvvvvvvvvvvvvv"
    ],
    [
      "                ",
      "                ",
      "                ",
      "                ",
      "                ",
      "                ",
      "                ",
      "                ",
      "eeeeeeeeeeeeeeee",
      "iiiiiiiiiiiivqqr",
      "iiiiiiiiiiiiivvq",
      "iiiiiiiiiiiiiiiv",
      "iiiiiiiiiiiiiiii",
      "ieeeiiiiiiiiiiii",
      "iiiiiiiiiiiiiiii",
      "vvvvvvvvvvvvvvvv"
    ]
  ]
}