{
  "name": "multi_verticalschool_9_floor5",
  "refpalette": "deceasedcraft:multi_verticalschool_9/multi_verticalschool_9_floor5_palette",
  "xsize": 16,
  "zsize": 16,
  "slices": [
    [
      "aaaaaaaaaaaaaabb",
      "aaaaaaaaaaaaaabb",
      "aaaaaaaaaaaaaabb",
      "aaaaaaaaaaaaaabb",
      "aaaaaaaaaaaaaabb",
      "aaaaaaaaaaaaaabb",
      "aaaaaaaaaaaaaabb",
      "aaaaaaaaaaaaaabb",
      "aaaaaaaaaaaaaabb",
      "bbbbbbbbbbbbbbbb",
      "bbbbbbbbbbbbbbbb",
      "                ",
      "                ",
      "                ",
      "                ",
      "                "
    ],
    [
      "              cb",
      " d    d    d  cb",
      "              cb",
      "              cb",
      "              cb",
      "              cb",
      " d    d    d  cb",
      "              cb",
      "              cb",
      "cccccccccccccccb",
      "bbbbbbbbbbbbbbbb",
      "                ",
      "                ",
      "                ",
      "                ",
      "                "
    ],
    [
      "      e       cb",
      " d    d    de cb",
      "              cb",
      "        e     cb",
      "              cb",
      " e         e  cb",
      " d    d   ed  cb",
      "              cb",
      "   e         ecb",
      "cccccccccccccccb",
      "bbbbbbbbbbbbbbbb",
      "                ",
      "                ",
      "                ",
      "                ",
      "                "
    ],
    [
      "aaaaaaaaaaaaaaab",
      "aaaaaaaaaaaaaaab",
      "aaaaaaaaaaaaaaab",
      "aaaaaaaaaaaaaaab",
      "aaaaaaaaaaaaaaab",
      "aaaaaaaaaaaaaaab",
      "aaaaaaaaaaaaaaab",
      "aaaaaaaaaaaaaaab",
      "aaaaaaaaaaaaaaab",
      "aaaaaaaaaaaaaaab",
      "bbbbbbbbbbbbbbbb",
      "                ",
      "                ",
      "                ",
      "                ",
      "                "
    ],
    [
      "              cb",
      "              cb",
      "              cb",
      "              cb",
      "              cb",
      "              cb",
      "              cb",
      "              cb",
      "f ghi ghi ghi cb",
      "jccccccccccccccb",
      "bbbbbbbbbbbbbbbb",
      "                ",
      "                ",
      "                ",
      "                ",
      "                "
    ],
    [
      "              cb",
      "              cb",
      "              cb",
      "              cb",
      "              cb",
      "              cb",
      "              cb",
      "              cb",
      "k             cb",
      "jccccccccccccccb",
      "bbbbbbbbbbbbbbbb",
      "                ",
      "                ",
      "                ",
      "                ",
      "                "
    ]
  ]
}