{
  "name": "multi_verticalschool_9_floor4",
  "refpalette": "deceasedcraft:multi_verticalschool_9/multi_verticalschool_9_floor4_palette",
  "xsize": 16,
  "zsize": 16,
  "slices": [
    [
      "aa            aa",
      "baaaaaaaaaaaaaa ",
      "bbbbbbbbbbbbbbbb",
      "                ",
      "                ",
      "                ",
      "                ",
      "                ",
      "                ",
      "                ",
      "                ",
      "                ",
      "                ",
      "                ",
      "                ",
      "                "
    ],
    [
      "c             cc",
      " cccccc ccccccc ",
      "                ",
      "                ",
      "                ",
      "                ",
      "                ",
      "                ",
      "                ",
      "                ",
      "                ",
      "                ",
      "                ",
      "                ",
      "                ",
      "                "
    ],
    [
      "                ",
      "                ",
      "                ",
      "                ",
      "                ",
      "                ",
      "                ",
      "                ",
      "                ",
      "                ",
      "                ",
      "                ",
      "                ",
      "                ",
      "                ",
      "                "
    ],
    [
      "                ",
      "                ",
      "                ",
      "                ",
      "                ",
      "                ",
      "                ",
      "                ",
      "                ",
      "                ",
      "                ",
      "                ",
      "                ",
      "                ",
      "                ",
      "                "
    ],
    [
      "                ",
      "                ",
      "                ",
      "                ",
      "                ",
      "                ",
      "                ",
      "                ",
      "                ",
      "                ",
      "                ",
      "                ",
      "                ",
      "                ",
      "                ",
      "                "
    ],
    [
      "deeedeeedeeedeef",
      "deeedeeedeeedeef",
      "deeedeeedeeedeef",
      "deeedeeedeeedeef",
      "deeedeeedeeedeef",
      "deeedeeedeeedeef",
      "deeedeeedeeedeef",
      "deeedeeedeeedeef",
      "eeeeeeeeeeeeeeef",
      "eeeeeeeeeeeeeeef",
      "ffffffffffffffff",
      "                ",
      "                ",
      "                ",
      "                ",
      "                "
    ]
  ]
}