{
  "name": "multi_verticalschool_9_floor6",
  "refpalette": "deceasedcraft:multi_verticalschool_9/multi_verticalschool_9_floor6_palette",
  "xsize": 16,
  "zsize": 16,
  "slices": [
    [
      "              ab",
      "              ab",
      "              ab",
      "              ab",
      "              ab",
      "              ab",
      "              ab",
      "              ab",
      "c             ab",
      "daaaaaaaaaaaaaab",
      "bbbbbbbbbbbbbbbb",
      "                ",
      "                ",
      "                ",
      "                ",
      "                "
    ],
    [
      "efffffffffffffab",
      "efffffffffffffab",
      "efffffffffffffab",
      "efffffffffffffab",
      "efffffffffffffab",
      "efffffffffffffab",
      "efffffffffffffab",
      "efffffffffffffab",
      "efffffffffffffab",
      "daaaaaaaaaaaaaab",
      "bbbbbbbbbbbbbbbb",
      "                ",
      "                ",
      "                ",
      "                ",
      "                "
    ],
    [
      "bbbbbbbbbbbbbbbb",
      "bbbbbbbbbbbbbbbb",
      "bbbbbbbbbbbbbbbb",
      "bbbbbbbbbbbbbbbb",
      "bbbbbbbbbbbbbbbb",
      "bbbbbbbbbbbbbbbb",
      "bbbbbbbbbbbbbbbb",
      "bbbbbbbbbbbbbbbb",
      "bbbbbbbbbbbbbbbb",
      "bbbbbbbbbbbbbbbb",
      "bbbbbbbbbbbbbbbb",
      "                ",
      "                ",
      "                ",
      "                ",
      "                "
    ],
    [
      "               g",
      "               g",
      "               g",
      "               g",
      "               g",
      "               g",
      "               g",
      "               g",
      "               g",
      "               g",
      "gggggggggggggggg",
      "                ",
      "                ",
      "                ",
      "                ",
      "                "
    ],
    [
      "                ",
      "                ",
      "                ",
      "                ",
      "                ",
      "                ",
      "                ",
      "                ",
      "                ",
      "                ",
      "                ",
      "                ",
      "                ",
      "                ",
      "                ",
      "                "
    ],
    [
      "                ",
      "                ",
      "                ",
      "                ",
      "                ",
      "                ",
      "                ",
      "                ",
      "                ",
      "                ",
      "                ",
      "                ",
      "                ",
      "                ",
      "                ",
      "                "
    ]
  ]
}