{
  "name": "building_gasstation_ground_270",
  "refpalette": "deceasedcraft:building_gasstation/building_gasstation_ground_palette_270",
  "xsize": 16,
  "zsize": 16,
  "slices": [
    [
      "aHHHHHHHHHHHHHba",
      "aHHHHHHHHHHHHHHa",
      "aHHHHHHHHHHHHHHa",
      "aHHHHHHHHHHHHHHa",
      "aHHbbbbbbbbbbHHa",
      "aHHHHHHHHHHHHHHa",
      "aHHHHHHHHHHHHHHa",
      "aHHbbbbbbbbbbHHa",
      "aHHbbbbbbbbbbHHa",
      "aHHbbbbbbbbbbHHa",
      "aHHbbbbbbbbbbHHa",
      "accbbbbbbbbbbcca",
      "aaabbbbbbbbbbaaa",
      "aaabbbbbbbbbbaaa",
      "aaaaaaaaaaaaaaaa",
      "aaaaaaaaaaaaaaaa"
    ],
    [
      "              d ",
      "                ",
      "   s ls ls l    ",
      "   t mt mt m    ",
      "   j Ej gj nj   ",
      "                ",
      "                ",
      " hekFFkquuqkkhe ",
      "   kK B Aw ok   ",
      "   kLIC    ok   ",
      " ifkkkk  x pkif ",
      " ggkMJk  xr!kgg ",
      "   kN D  y pk   ",
      "   kkkkkkkkkk   ",
      "                ",
      "                "
    ],
    [
      "              d ",
      "                ",
      "                ",
      "                ",
      "   j Vj  j Oj   ",
      "                ",
      "                ",
      "   kWWkq  qkk   ",
      "   k  T SQ  k   ",
      "   kXL      k   ",
      "   kkkk  y Pk   ",
      "   k  k  R pk   ",
      "   k  U  x Pk   ",
      "   kkkkkkkkkk   ",
      "                ",
      "                "
    ],
    [
      "              Y ",
      "                ",
      "                ",
      "                ",
      "   j  j  j  j   ",
      "                ",
      "                ",
      "   ZZZZZZZZZZ   ",
      "   Z       0Z   ",
      "   Z       1Z   ",
      "   Zkkk     Z   ",
      "   Z  k    rZ   ",
      "   Z  k     Z   ",
      "   Z22Z22Z22Z   ",
      "                ",
      "                "
    ],
    [
      "                ",
      "                ",
      "                ",
      "                ",
      "   k  k  k  k   ",
      "   3  6  3  3   ",
      "                ",
      "   kkkkkkkkkk   ",
      "   k       4k   ",
      "   k  3  6 5k   ",
      "   kkkkkkkkkk   ",
      "   k77k     k   ",
      "   k77k    rk   ",
      "   kkkkkkkkkk   ",
      "                ",
      "                "
    ],
    [
      "                ",
      "  888888888888  ",
      "  8gggggggggg8  ",
      "  8gggggggggg8  ",
      "  8bbbbbbbbbb8  ",
      "  8bggggggggb8  ",
      "  8bggggggggb8  ",
      "  8bbbbbbbbbb8  ",
      "  8bggggggggb8  ",
      "  8bggggggggb8  ",
      "  8bbbbbbbbbb8  ",
      "  8bggggggggb8  ",
      "  8bggggggggb8  ",
      "  8bbbbbbbbbb8  ",
      "  888888888888  ",
      "                "
    ]
  ]
}