{
  "name": "building_gasstation_ground_180",
  "refpalette": "deceasedcraft:building_gasstation/building_gasstation_ground_palette_180",
  "xsize": 16,
  "zsize": 16,
  "slices": [
    [
      "aaaaaaaaaaaaaaaa",
      "aaaacHHHHHHHHHHH",
      "aaaacHHHHHHHHHHH",
      "aabbbbbbbHHbHHHH",
      "aabbbbbbbHHbHHHH",
      "aabbbbbbbHHbHHHH",
      "aabbbbbbbHHbHHHH",
      "aabbbbbbbHHbHHHH",
      "aabbbbbbbHHbHHHH",
      "aabbbbbbbHHbHHHH",
      "aabbbbbbbHHbHHHH",
      "aabbbbbbbHHbHHHH",
      "aabbbbbbbHHbHHHH",
      "aaaacHHHHHHHHHHH",
      "aaaacHHHHHHHHHHb",
      "aaaaaaaaaaaaaaaa"
    ],
    [
      "                ",
      "    gi  h       ",
      "    gf  e       ",
      "  kkkkkkk  jts  ",
      "  kNMkLKF       ",
      "  k JkI F  Eml  ",
      "  kDkkCBk  jts  ",
      "  k     q       ",
      "  k    Au  gml  ",
      "  kyxx wu  jts  ",
      "  k r   q       ",
      "  kp!pook  nml  ",
      "  kkkkkkk  j    ",
      "    gi  h       ",
      "    gf  e      d",
      "                "
    ],
    [
      "                ",
      "                ",
      "                ",
      "  kkkkkkk  j    ",
      "  k  kX W       ",
      "  k  kL W  V    ",
      "  kUkk Tk  j    ",
      "  k     q       ",
      "  k    S        ",
      "  kxRy Q   j    ",
      "  k     q       ",
      "  kPpP  k  O    ",
      "  kkkkkkk  j    ",
      "                ",
      "               d",
      "                "
    ],
    [
      "                ",
      "                ",
      "                ",
      "  ZZZZZZZ  j    ",
      "  2  k  Z       ",
      "  2  k  Z       ",
      "  Zkkk  Z  j    ",
      "  2     Z       ",
      "  2     Z       ",
      "  Z     Z  j    ",
      "  2     Z       ",
      "  2 r 10Z       ",
      "  ZZZZZZZ  j    ",
      "                ",
      "               Y",
      "                "
    ],
    [
      "                ",
      "                ",
      "                ",
      "  kkkkkkk 3k    ",
      "  k77k  k       ",
      "  k77k  k       ",
      "  kkkk3 k 6k    ",
      "  k  k  k       ",
      "  k  k  k       ",
      "  k  k6 k 3k    ",
      "  k  k  k       ",
      "  kr k54k       ",
      "  kkkkkkk 3k    ",
      "                ",
      "                ",
      "                "
    ],
    [
      "                ",
      "                ",
      " 88888888888888 ",
      " 8bbbbbbbbbbgg8 ",
      " 8bggbggbggbgg8 ",
      " 8bggbggbggbgg8 ",
      " 8bggbggbggbgg8 ",
      " 8bggbggbggbgg8 ",
      " 8bggbggbggbgg8 ",
      " 8bggbggbggbgg8 ",
      " 8bggbggbggbgg8 ",
      " 8bggbggbggbgg8 ",
      " 8bbbbbbbbbbgg8 ",
      " 88888888888888 ",
      "                ",
      "                "
    ]
  ]
}