{
  "name": "building_gasstation_ground_90",
  "refpalette": "deceasedcraft:building_gasstation/building_gasstation_ground_palette_90",
  "xsize": 16,
  "zsize": 16,
  "slices": [
    [
      "aaaaaaaaaaaaaaaa",
      "aaaaaaaaaaaaaaaa",
      "aaabbbbbbbbbbaaa",
      "aaabbbbbbbbbbaaa",
      "accbbbbbbbbbbcca",
      "aHHbbbbbbbbbbHHa",
      "aHHbbbbbbbbbbHHa",
      "aHHbbbbbbbbbbHHa",
      "aHHbbbbbbbbbbHHa",
      "aHHHHHHHHHHHHHHa",
      "aHHHHHHHHHHHHHHa",
      "aHHbbbbbbbbbbHHa",
      "aHHHHHHHHHHHHHHa",
      "aHHHHHHHHHHHHHHa",
      "aHHHHHHHHHHHHHHa",
      "abHHHHHHHHHHHHHa"
    ],
    [
      "                ",
      "                ",
      "   kkkkkkkkkk   ",
      "   kp y  D Nk   ",
      " ggk!rx  kJMkgg ",
      " fikp x  kkkkfi ",
      "   ko    CILk   ",
      "   ko wA B Kk   ",
      " ehkkquuqkFFkeh ",
      "                ",
      "                ",
      "   jn jg jE j   ",
      "    m tm tm t   ",
      "    l sl sl s   ",
      "                ",
      " d              "
    ],
    [
      "                ",
      "                ",
      "   kkkkkkkkkk   ",
      "   kP x  U  k   ",
      "   kp R  k  k   ",
      "   kP y  kkkk   ",
      "   k      LXk   ",
      "   k  QS T  k   ",
      "   kkq  qkWWk   ",
      "                ",
      "                ",
      "   jO j  jV j   ",
      "                ",
      "                ",
      "                ",
      " d              "
    ],
    [
      "                ",
      "                ",
      "   Z22Z22Z22Z   ",
      "   Z     k  Z   ",
      "   Zr    k  Z   ",
      "   Z     kkkZ   ",
      "   Z1       Z   ",
      "   Z0       Z   ",
      "   ZZZZZZZZZZ   ",
      "                ",
      "                ",
      "   j  j  j  j   ",
      "                ",
      "                ",
      "                ",
      " Y              "
    ],
    [
      "                ",
      "                ",
      "   kkkkkkkkkk   ",
      "   kr    k77k   ",
      "   k     k77k   ",
      "   kkkkkkkkkk   ",
      "   k5 6  3  k   ",
      "   k4       k   ",
      "   kkkkkkkkkk   ",
      "                ",
      "   3  3  6  3   ",
      "   k  k  k  k   ",
      "                ",
      "                ",
      "                ",
      "                "
    ],
    [
      "                ",
      "  888888888888  ",
      "  8bbbbbbbbbb8  ",
      "  8bggggggggb8  ",
      "  8bggggggggb8  ",
      "  8bbbbbbbbbb8  ",
      "  8bggggggggb8  ",
      "  8bggggggggb8  ",
      "  8bbbbbbbbbb8  ",
      "  8bggggggggb8  ",
      "  8bggggggggb8  ",
      "  8bbbbbbbbbb8  ",
      "  8gggggggggg8  ",
      "  8gggggggggg8  ",
      "  888888888888  ",
      "                "
    ]
  ]
}