{
  "name": "building_gasstation_ground",
  "refpalette": "deceasedcraft:building_gasstation/building_gasstation_ground_palette",
  "xsize": 16,
  "zsize": 16,
  "slices": [
    [
      "aaaaaaaaaaaaaaaa",
      "bHHHHHHHHHHcaaaa",
      "HHHHHHHHHHHcaaaa",
      "HHHHbHHbbbbbbbaa",
      "HHHHbHHbbbbbbbaa",
      "HHHHbHHbbbbbbbaa",
      "HHHHbHHbbbbbbbaa",
      "HHHHbHHbbbbbbbaa",
      "HHHHbHHbbbbbbbaa",
      "HHHHbHHbbbbbbbaa",
      "HHHHbHHbbbbbbbaa",
      "HHHHbHHbbbbbbbaa",
      "HHHHbHHbbbbbbbaa",
      "HHHHHHHHHHHcaaaa",
      "HHHHHHHHHHHcaaaa",
      "aaaaaaaaaaaaaaaa"
    ],
    [
      "                ",
      "d      e  fg    ",
      "       h  ig    ",
      "    j  kkkkkkk  ",
      "  lmn  koop!pk  ",
      "       q   r k  ",
      "  stj  uw xxyk  ",
      "  lmg  uA    k  ",
      "       q     k  ",
      "  stj  kBCkkDk  ",
      "  lmE  F IkJ k  ",
      "       FKLkMNk  ",
      "  stj  kkkkkkk  ",
      "       e  fg    ",
      "       h  ig    ",
      "                "
    ],
    [
      "                ",
      "d               ",
      "                ",
      "    j  kkkkkkk  ",
      "    O  k  PpPk  ",
      "       q     k  ",
      "    j   Q yRxk  ",
      "        S    k  ",
      "       q     k  ",
      "    j  kT kkUk  ",
      "    V  W Lk  k  ",
      "       W Xk  k  ",
      "    j  kkkkkkk  ",
      "                ",
      "                ",
      "                "
    ],
    [
      "                ",
      "Y               ",
      "                ",
      "    j  ZZZZZZZ  ",
      "       Z01 r 2  ",
      "       Z     2  ",
      "    j  Z     Z  ",
      "       Z     2  ",
      "       Z     2  ",
      "    j  Z  kkkZ  ",
      "       Z  k  2  ",
      "       Z  k  2  ",
      "    j  ZZZZZZZ  ",
      "                ",
      "                ",
      "                "
    ],
    [
      "                ",
      "                ",
      "                ",
      "    k3 kkkkkkk  ",
      "       k45k rk  ",
      "       k  k  k  ",
      "    k3 k 6k  k  ",
      "       k  k  k  ",
      "       k  k  k  ",
      "    k6 k 3kkkk  ",
      "       k  k77k  ",
      "       k  k77k  ",
      "    k3 kkkkkkk  ",
      "                ",
      "                ",
      "                "
    ],
    [
      "                ",
      "                ",
      " 88888888888888 ",
      " 8ggbbbbbbbbbb8 ",
      " 8ggbggbggbggb8 ",
      " 8ggbggbggbggb8 ",
      " 8ggbggbggbggb8 ",
      " 8ggbggbggbggb8 ",
      " 8ggbggbggbggb8 ",
      " 8ggbggbggbggb8 ",
      " 8ggbggbggbggb8 ",
      " 8ggbggbggbggb8 ",
      " 8ggbbbbbbbbbb8 ",
      " 88888888888888 ",
      "                ",
      "                "
    ]
  ]
}