{
  "name": "multi_flatmedium_2_top",
  "refpalette": "deceasedcraft:multi_flatmedium_2/multi_flatmedium_2_top_palette",
  "xsize": 16,
  "zsize": 16,
  "slices": [
    [
      " aaaavvvvvvbbbc ",
      " addavevvvvbbbc ",
      " addvevvevvbbbc ",
      " addavvvvevbbbc ",
      " faaavvvvvvfbba ",
      " avvvvavvvvbbbc ",
      " avvvvvvvevbbbc ",
      " avvvvavvvvbbbc ",
      " avvvvavevvbbbc ",
      " avvvvavevvbbbc ",
      " avvvvavvevbbbc ",
      " avvvvavvevbbbc ",
      " avvvvavvevbbbc ",
      " fvaaaaveevfbba ",
      " addavvvvvvbbbc ",
      " addavvevvebbbc "
    ],
    [
      " aaaaghiijkl ma ",
      " no!a     pqr a ",
      " s  t  u  wlx a ",
      " ayAa BC  Dq Ea ",
      " faaaFIIIJIf  a ",
      " aKLjja M  a Na ",
      " sO  PQ R SaTUa ",
      " s  V aW  Xa  Y ",
      " a    aZ r0am   ",
      " a  V a1  0a 2N ",
      " s 3  a4  562 Y ",
      " s  78a9  #a  a ",
      " a Fjja$% ^a Ra ",
      " f&aaaa    fY a ",
      " a*(a)+--[ amU  ",
      " s ]ax{}}  |*;N "
    ],
    [
      " a::a  ' <Dl  r ",
      " > ,a     .%    ",
      " >  ?     />    ",
      " a  a     Dl    ",
      " faaaFIII`If  n ",
      " a \u0370DDa    6    ",
      " >\u0371   \u0372   \u0373>    ",
      " >\u0374   a\u0375  \u0376>    ",
      " a\u0377  \u037aa\u037b   6    ",
      " a\u0377   a    a    ",
      " >\u0371   a   \u0373     ",
      " >\u0374   a   \u0376>    ",
      " a FDDa\u037c   6    ",
      " f\u037daaaa   \u037af  n ",
      " a  a \u037e\u037f\u0384  a\u0385   ",
      " >  a      \u0386    "
    ],
    [
      " aaaa:::::D\u0387    ",
      " > \u0388a           ",
      " >  \u0389           ",
      " a \u038aa      q    ",
      " faaaFIIIIIf  n ",
      " a  DDa    a    ",
      " >\u038c   \u038e   \u038f>    ",
      " >\u0390   a\u0391  \u0392>    ",
      " a    a\u0393   a    ",
      " a    a\u0394   6    ",
      " >\u038c   a\u0393  \u038f>    ",
      " >\u0390   a\u0394  \u0392>    ",
      " a FDDa\u0395   a    ",
      " fIaaaa    f  n ",
      " a \u0396a      6    ",
      " >  a      \u0397    "
    ],
    [
      " aaaa\u0398\u0398\u0398\u0398\u0398\u0398a    ",
      " a\u0399\u0399a      \u0387    ",
      " a\u0399\u0399a      \u039a    ",
      " a\u0399\u0399a      a    ",
      " faaa\u039b\u039b\u039b\u039b\u039b\u039bf  n ",
      " a    a\u039c   a    ",
      " a    a\u039c \u039d a    ",
      " a    a\u039c   6    ",
      " a    a\u039c   6    ",
      " a    a\u039c   a    ",
      " a    a\u039c \u039e a    ",
      " a    a\u039c   6    ",
      " a    a\u039c   a    ",
      " faaaaa\u039c   f  n ",
      " a\u0399\u0399a      a    ",
      " a\u0399\u0399a \u039f  \u03a0 6    "
    ],
    [
      " YbbbbbbbbbY  \u03a1 ",
      " Yb\u03a3bbbbbbbY  \u03a1 ",
      " Yb bbbbbbbY  \u03a1 ",
      " Yb bbbbbbbY  \u03a1 ",
      " fbbbbbbbbbf  f ",
      " YbbbbbbbbbY  \u03a1 ",
      " YbbbbbbbbbY  \u03a1 ",
      " YbbbbbbbbbY  \u03a1 ",
      " YbbbbbbbbbY  \u03a1 ",
      " YbbbbbbbbbY  \u03a1 ",
      " YbbbbbbbbbY  \u03a1 ",
      " YbbbbbbbbbY  \u03a1 ",
      " YbbbbbbbbbY  \u03a1 ",
      " fbbbbbbbbbf  f ",
      " Yb bbbbbbbY  \u03a1 ",
      " Yb bbbbbbbY  \u03a1 "
    ],
    [
      " abbb\u03a4\u03a4\u03a4\u03a4\u03a4\u03a4bbba ",
      " abbb\u03a4\u03a4\u03a4\u03a4\u03a4\u03a4bbba ",
      " abbb\u03a4\u03a4\u03a4\u03a4\u03a4\u03a4bbba ",
      " abbb\u03a4\u03a4\u03a4\u03a4\u03a4\u03a4bbba ",
      " abbb\u03a4\u03a4\u03a4\u03a4\u03a4\u03a4\u03a5bba ",
      " abbb\u03a4\u03a4\u03a4\u03a4\u03a4\u03a4bbba ",
      " abbb\u03a4\u03a4\u03a4\u03a4\u03a4\u03a4bbba ",
      " abbb\u03a4\u03a4\u03a4\u03a4\u03a4\u03a4bbba ",
      " abbb\u03a4\u03a4\u03a4\u03a4\u03a4\u03a4bbba ",
      " abbb\u03a4\u03a4\u03a4\u03a4\u03a4\u03a4bbba ",
      " abbb\u03a4\u03a4\u03a4\u03a4\u03a4\u03a4bbba ",
      " abbb\u03a4\u03a4\u03a4\u03a4\u03a4\u03a4bbba ",
      " abbb\u03a4\u03a4\u03a4\u03a4\u03a4\u03a4bbba ",
      " abbb\u03a4\u03a4\u03a4\u03a4\u03a4\u03a4\u03a5bba ",
      " abbb\u03a4\u03a4\u03a4\u03a4\u03a4\u03a4bbba ",
      " abbb\u03a4\u03a4\u03a4\u03a4\u03a4\u03a4bbba "
    ],
    [
      " s            s ",
      " s            s ",
      " s            s ",
      " s            s ",
      " n       \u03a6\u03a7\u03a5  n ",
      " s    \u03a8       s ",
      " s   \u03a8\u03a9\u03a8      s ",
      " s    \u03a8  \u03a6\u03a7   s ",
      " s   \u03aa        s ",
      " s            s ",
      " s    \u03a8  \u03a6\u03a7   s ",
      " s   \u03a8\u03a9\u03a8      s ",
      " s    \u03a8       s ",
      " n       \u03a6\u03a7\u03a5  n ",
      " s            s ",
      " s            s "
    ],
    [
      "                ",
      "                ",
      "                ",
      "                ",
      " \u03ab       \u03a5\u03a5\u03a5  \u03ab ",
      "     \u03a9\u03a9\u03a9 \u03a5      ",
      "     \u03a9\u03ac\u03a9 \u03a5      ",
      "     \u03a9\u03ad\u03a9 \u03a5      ",
      "      ~  \u03a5      ",
      "         \u03a5      ",
      "     \u03a9\u03a9\u03a9 \u03a5      ",
      "     \u03a9\u03ac\u03a9 \u03a5      ",
      "     \u03a9\u03a9\u03a9 \u03a5      ",
      " \u03ab       \u03a5\u03a5\u03a5  \u03ab ",
      "         \u03a5      ",
      "         \u03a5      "
    ],
    [
      "                ",
      "                ",
      "                ",
      "                ",
      "                ",
      "      \u03a9\u03a9        ",
      "     \u03aa \u03a9        ",
      "       \u03a9        ",
      "                ",
      "                ",
      "     \u03a9\u03a9\u03a9        ",
      "     \u03a9\u03ac\u03a9        ",
      "     \u03aa\u03a9\u03a9        ",
      "                ",
      "                ",
      "                "
    ],
    [
      "                ",
      "                ",
      "                ",
      "                ",
      "                ",
      "                ",
      "       \u03a9        ",
      "       \u03aa        ",
      "                ",
      "                ",
      "     \u03aa \u03a9        ",
      "     \u03a9 \u03a9        ",
      "       \u03a9        ",
      "                ",
      "                ",
      "                "
    ],
    [
      "                ",
      "                ",
      "                ",
      "                ",
      "                ",
      "                ",
      "                ",
      "                ",
      "                ",
      "                ",
      "                ",
      "       \u03a9        ",
      "       \u03a9        ",
      "                ",
      "                ",
      "                "
    ]
  ]
}