{
  "name": "multi_flatmedium_2_floor4",
  "refpalette": "deceasedcraft:multi_flatmedium_2/multi_flatmedium_2_floor4_palette",
  "xsize": 16,
  "zsize": 16,
  "slices": [
    [
      " aaaavvvvvvbbbc ",
      " addavvvvvvbbbc ",
      " addvvvvvvvbbbc ",
      " addavvvvvvbbbc ",
      " eaaavvvvvvebba ",
      " avvvvavvvvbbbc ",
      " avvvvvvvvvbbbc ",
      " avvvvavvvvbbbc ",
      " avvvvavvvvbbbc ",
      " avvvvavvvvbbbc ",
      " avvvvavvvvbbbc ",
      " avvvvavvvvbbbc ",
      " avvvvavvvvbbbc ",
      " evaaaavvvvebba ",
      " addavvvvvvbbbc ",
      " addavvvvvvbbbc "
    ],
    [
      " aaaa!fffffa  a ",
      " g  ah i  ja  a ",
      " g  k     la  a ",
      " amna o  p a  a ",
      " eaaaqqqqrqe  a ",
      " ah ffall ha  a ",
      " g    s   ta  a ",
      " g  p a  uwa  a ",
      " a i  a o xa  a ",
      " a    al  xa  a ",
      " g    ay  Aa  a ",
      " g uhlay  xa  a ",
      " a  f!a  u a  a ",
      " eBaaaaCCC e  a ",
      " a DaEFIIJ a  a ",
      " g Ka      L  a "
    ],
    [
      " aMMaMMMMMMa    ",
      " N Oa     PN    ",
      " N  Q     RN    ",
      " a  a     Sa    ",
      " eaaaqqqqTqe  U ",
      " a   Va    a    ",
      " NW   X   YN    ",
      " NZ   a   0N    ",
      " a   Sa    a    ",
      " a    a    a    ",
      " NW   a!  YN    ",
      " NZ   a   0N    ",
      " a  1la    a    ",
      " e2aaaa   Se  U ",
      " a  a      a3   ",
      " N  a      4    "
    ],
    [
      " aaaaMMMMMMa    ",
      " N 5a     6N    ",
      " N  7     8N    ",
      " a 9a      a    ",
      " eaaaqqqqqqe  U ",
      " a    ah   a    ",
      " N#   $   %N    ",
      " N^   a   &N    ",
      " a    a    a    ",
      " a    a    a    ",
      " N#   a   %N    ",
      " N^   a   &N    ",
      " a    a    a    ",
      " eqaaaa    e  U ",
      " a *a      a    ",
      " N  a      (    "
    ],
    [
      " aaaa))))))a    ",
      " a++a-    ha    ",
      " a++a      a    ",
      " a++a  h   a    ",
      " eaaa[[[[[[e  U ",
      " ah  ha]  ha    ",
      " a    a] { a    ",
      " a    a]   a    ",
      " ah  ha]   a    ",
      " a    a]   a    ",
      " a    a] }ha    ",
      " a    a]   a    ",
      " ah  ha]   a    ",
      " eaaaaa]   e  U ",
      " a++a      a    ",
      " a++a |  ; a    "
    ],
    [
      " :bbbbbbbbb:  ' ",
      " :b<bbbbbbb:  ' ",
      " :b bbbbbbb:  ' ",
      " :b bbbbbbb:  ' ",
      " ebbbbbbbbbe  e ",
      " :bbbbbbbbb:  ' ",
      " :bbbbbbbbb:  ' ",
      " :bbbbbbbbb:  ' ",
      " :bbbbbbbbb:  ' ",
      " :bbbbbbbbb:  ' ",
      " :bbbbbbbbb:  ' ",
      " :bbbbbbbbb:  ' ",
      " :bbbbbbbbb:  ' ",
      " ebbbbbbbbbe  e ",
      " :b bbbbbbb:  ' ",
      " :b bbbbbbb:  ' "
    ]
  ]
}