{
  "name": "multi_flatmedium_2_floor3",
  "refpalette": "deceasedcraft:multi_flatmedium_2/multi_flatmedium_2_floor3_palette",
  "xsize": 16,
  "zsize": 16,
  "slices": [
    [
      " aaaavvvvvvbbbc ",
      " addavvvvvvbbbc ",
      " addvvvvvevbbbc ",
      " addavvvvvvbbbc ",
      " faaavvvvvvfbba ",
      " avvvvavvvvbbbc ",
      " avvvvvvvvvbbbc ",
      " avvvvavvvvbbbc ",
      " avvvvavvvvbbbc ",
      " avvvvavvvvbbbc ",
      " avvvvavvvvbbbc ",
      " avvvvavvvvbbbc ",
      " avvvvavvvvbbbc ",
      " fvaaaavvvvfbba ",
      " addavvvvvvbbbc ",
      " addavvvvvvbbbc "
    ],
    [
      " aaaaghhghha  i ",
      " j! akll  ma  a ",
      " n op qq rsa  a ",
      " atua     wa  a ",
      " faaaxyyyAyf  a ",
      " aBChha   Da  a ",
      " n    E   Fa  a ",
      " n  IJaK  La  a ",
      " a   MaN  Oa  a ",
      " a  IJaP  Oa  a ",
      " n    aQ  Ra  a ",
      " n  STaU  Va  W ",
      " a xhhaX  Ya  a ",
      " fZaaaa000 f  a ",
      " a 1a23445 a  a ",
      " n 6a      7  a "
    ],
    [
      " a88a888899a    ",
      " # $a%    ^#    ",
      " #  &     *#    ",
      " a  a     (a    ",
      " faaaxyyy)yf  j ",
      " a +99a    a    ",
      " #-   [   ]#    ",
      " #{   a}  |#    ",
      " a   (a;  :a    ",
      " a    a'  <a    ",
      " #-   a>  ]#    ",
      " #{ ,!a   |#    ",
      " a x99a.   a    ",
      " f?aaaa   (f  j ",
      " a  a/`\u0370\u0370  a\u0371   ",
      " #  a      \u0372    "
    ],
    [
      " aaaa888899a    ",
      " # \u0373a     \u0374#    ",
      " #  \u0375     \u0376#    ",
      " a \u0377a      a    ",
      " faaaxyyyyyf  j ",
      " a  99a    a    ",
      " #\u037a   \u037b   \u037c#    ",
      " #\u037d   a\u037e  \u037f#    ",
      " a    a\u0384   a    ",
      " a    a\u0385   a    ",
      " #\u037a   a\u0384  \u037c#    ",
      " #\u037d   a\u0385  \u037f#    ",
      " a x99a\u0386   a    ",
      " fyaaaa    f  j ",
      " a \u0387a      a    ",
      " #  a      \u0388    "
    ],
    [
      " aaaa\u0389\u0389\u0389\u0389\u0389\u0389a    ",
      " a\u038a\u038aa      a    ",
      " a\u038a\u038aa      a    ",
      " a\u038a\u038aa      a    ",
      " faaa\u038c\u038c\u038c\u038c\u038c\u038cf  j ",
      " a    a\u038e   a    ",
      " a    a\u038e \u038f a    ",
      " a    a\u038e   a    ",
      " a    a\u038e   a    ",
      " a    a\u038e   a    ",
      " a    a\u038e \u0390 a    ",
      " a    a\u038e   a    ",
      " a    a\u038e   a    ",
      " faaaaa\u038e   f  j ",
      " a\u038a\u038aa      a    ",
      " a\u038a\u038aa \u0391  \u0392 a    "
    ],
    [
      " \u0393bbbbbbbbb\u0393  \u0394 ",
      " \u0393b\u0395bbbbbbb\u0393  \u0394 ",
      " \u0393b bbbbbbb\u0393  \u0394 ",
      " \u0393b bbbbbbb\u0393  \u0394 ",
      " fbbbbbbbbbf  f ",
      " \u0393bbbbbbbbb\u0393  \u0394 ",
      " \u0393bbbbbbbbb\u0393  \u0394 ",
      " \u0393bbbbbbbbb\u0393  \u0394 ",
      " \u0393bbbbbbbbb\u0393  \u0394 ",
      " \u0393bbbbbbbbb\u0393  \u0394 ",
      " \u0393bbbbbbbbb\u0393  \u0394 ",
      " \u0393bbbbbbbbb\u0393  \u0394 ",
      " \u0393bbbbbbbbb\u0393  \u0394 ",
      " fbbbbbbbbbf  f ",
      " \u0393b bbbbbbb\u0393  \u0394 ",
      " \u0393b bbbbbbb\u0393  \u0394 "
    ]
  ]
}