{
  "name": "multi_flatmedium_2_ground",
  "refpalette": "deceasedcraft:multi_flatmedium_2/multi_flatmedium_2_ground_palette",
  "xsize": 16,
  "zsize": 16,
  "slices": [
    [
      "aabbbbbbbbbbbbaa",
      "aacbbbbbbccbbbaa",
      "aaccbbbbbcbbbbaa",
      "aadbbbbbbb!bbbaa",
      "aebbbebbbbebbbea",
      "aabbbbbbbbbbbbaa",
      "aabbbbbbbbbbbbaa",
      "aabbbbbbbbbbbbaa",
      "aabbbbbbbbbbbbaa",
      "aabbbbbbbbbbbbaa",
      "aabbbbbbccbbbbaa",
      "aabbbbcbbcbbbbaa",
      "aabbbcbbbbbbbbaa",
      "aebbbebbbbebbbea",
      "aabbbbbbbbbbbbaa",
      "aabbbbbbbbbbbbaa"
    ],
    [
      " f  gh ig ji  f ",
      "    klmnk  n  f ",
      " f  go ig  i  f ",
      " f  kpqnk  n  f ",
      " r  sr s srs  r ",
      " ft g  ig  i  f ",
      " f  k unkw n tf ",
      " f  g qigx i  f ",
      " f  k ynk  n    ",
      "    gA igB i    ",
      " f  k Cn  sn  f ",
      "    g  ig  is f ",
      " fs k  nkC n  f ",
      " r  sr ssDrs  r ",
      " f  g  ig  i  f ",
      " f  k  nkE n sf "
    ],
    [
      "                ",
      "                ",
      "                ",
      "                ",
      " F   F    F   F ",
      "                ",
      "                ",
      "                ",
      "                ",
      "                ",
      "                ",
      "                ",
      "                ",
      " F   F    F   F ",
      "                ",
      "                "
    ],
    [
      "                ",
      "                ",
      "                ",
      "                ",
      " F   F    F   F ",
      "                ",
      "                ",
      "                ",
      "                ",
      "                ",
      "                ",
      "                ",
      "                ",
      " F   F    F   F ",
      "                ",
      "                "
    ],
    [
      " I   I    I   I ",
      " I   I    I   I ",
      " I   I    I   I ",
      " I   I    I   I ",
      " FIIIFIIIIFIIIF ",
      " I   I    I   I ",
      " I   I    I   I ",
      " I   I    I   I ",
      " I   I    I   I ",
      " I   I    I   I ",
      " I   I    I   I ",
      " I   I    I   I ",
      " I   I    I   I ",
      " FIIIFIIIIFIIIF ",
      " I   I    I   I ",
      " I   I    I   I "
    ],
    [
      " JbbbbbbbbbbbbJ ",
      " JbbbbbbbbbbbbJ ",
      " JbbbbbbbbbbbbJ ",
      " JbbbbbbbbbbbbJ ",
      " JbbbbbbbbbbbbJ ",
      " JbbbbbbbbbbbbJ ",
      " JbbbbbbbbbbbbJ ",
      " JbbbbbbbbbbbbJ ",
      " JbbbbbbbbbbbbJ ",
      " JbbbbbbbbbbbbJ ",
      " JbbbbbbbbbbbbJ ",
      " JbbbbbbbbbbbbJ ",
      " JbbbbbbbbbbbbJ ",
      " JbbbbbbbbbbbbJ ",
      " JbbbbbbbbbbbbJ ",
      " JbbbbbbbbbbbbJ "
    ]
  ]
}