{
  "name": "multi_flatmedium_2_floor5",
  "refpalette": "deceasedcraft:multi_flatmedium_2/multi_flatmedium_2_floor5_palette",
  "xsize": 16,
  "zsize": 16,
  "slices": [
    [
      " aaaavvvvvvbbbc ",
      " addavvvvvvbbbc ",
      " addvvvvvvvbbbc ",
      " addavvvvvvbbbc ",
      " eaaavvvvvvebba ",
      " avvvvavvvvbbbc ",
      " avvvvvvvvvbbbc ",
      " avvvvavvvvbbbc ",
      " avvvvavvvvbbbc ",
      " avvvvavvvvbbbc ",
      " avvvvavvvvbbbc ",
      " avvvvavvvvbbbc ",
      " avvvvavvvvbbbc ",
      " evaaaavvvvebba ",
      " addavvvvvvbbbc ",
      " addavvvvvvbbbc "
    ],
    [
      " aaaafggfgga  a ",
      " h  a ii  ja  a ",
      " h  k ll  ma  a ",
      " anoa     pa  a ",
      " eaaaqrrrsre  a ",
      " atugga    a  a ",
      " h    w   xa  a ",
      " h  yAaB  Ca  a ",
      " a   DaE  Fa  a ",
      " a  yAaI  Fa  a ",
      " h    aJ  Ka  a ",
      " h  LMaN  Oa  a ",
      " a qggaP  Qa  a ",
      " eRaaaaSSS e  a ",
      " a TaUVWWX a  a ",
      " h Ya      Z  a "
    ],
    [
      " a00a000011a    ",
      " 2 3a     42    ",
      " 2  5      2    ",
      " a  a     6a    ",
      " eaaaqrrr7re  8 ",
      " a  11a    a    ",
      " 29   #   $2    ",
      " 2%   a^  &2    ",
      " a   6a*   a    ",
      " a    a    a    ",
      " 29   a   $2    ",
      " 2%   a   &2    ",
      " a q11a(   a    ",
      " e)aaaa   6e  8 ",
      " a  a      a+   ",
      " 2  a      -    "
    ],
    [
      " aaaa000011a    ",
      " 2 [a     ]2    ",
      " 2  {      2    ",
      " a }a      a    ",
      " eaaaqrrrrre  8 ",
      " a  11a    a    ",
      " 2|   ;   :2    ",
      " 2'   a<  >2    ",
      " a    a,   a    ",
      " a    a.   a    ",
      " 2|   a,  :2    ",
      " 2'   a.  >2    ",
      " a q11a?   a    ",
      " eraaaa    e  8 ",
      " a /a      a    ",
      " 2  a      `    "
    ],
    [
      " aaaa\u0370\u0370\u0370\u0370\u0370\u0370a    ",
      " a\u0371\u0371a      a    ",
      " a\u0371\u0371a      a    ",
      " a\u0371\u0371a      a    ",
      " eaaa\u0372\u0372\u0372\u0372\u0372\u0372e  8 ",
      " a    a\u0373   a    ",
      " a    a\u0373 \u0374 a    ",
      " a    a\u0373   a    ",
      " a    a\u0373   a    ",
      " a    a\u0373   a    ",
      " a    a\u0373 \u0375 a    ",
      " a    a\u0373   a    ",
      " a    a\u0373   a    ",
      " eaaaaa\u0373   e  8 ",
      " a\u0371\u0371a      a    ",
      " a\u0371\u0371a \u0376  \u0377 a    "
    ],
    [
      " \u037abbbbbbbbb\u037a  \u037b ",
      " \u037ab\u037cbbbbbbb\u037a  \u037b ",
      " \u037ab bbbbbbb\u037a  \u037b ",
      " \u037ab bbbbbbb\u037a  \u037b ",
      " ebbbbbbbbbe  e ",
      " \u037abbbbbbbbb\u037a  \u037b ",
      " \u037abbbbbbbbb\u037a  \u037b ",
      " \u037abbbbbbbbb\u037a  \u037b ",
      " \u037abbbbbbbbb\u037a  \u037b ",
      " \u037abbbbbbbbb\u037a  \u037b ",
      " \u037abbbbbbbbb\u037a  \u037b ",
      " \u037abbbbbbbbb\u037a  \u037b ",
      " \u037abbbbbbbbb\u037a  \u037b ",
      " ebbbbbbbbbe  e ",
      " \u037ab bbbbbbb\u037a  \u037b ",
      " \u037ab bbbbbbb\u037a  \u037b "
    ]
  ]
}