{
  "name": "multi_flatmedium_2_floor1",
  "refpalette": "deceasedcraft:multi_flatmedium_2/multi_flatmedium_2_floor1_palette",
  "xsize": 16,
  "zsize": 16,
  "slices": [
    [
      " aaaavvvvvvbbbc ",
      " addavevvvvbbbc ",
      " addavvvevvbbbc ",
      " addavvvvvebbbc ",
      " fvaavavvvvfbba ",
      " avvvvavvevbbbc ",
      " avvvvavevvbbbc ",
      " avvvvavvvvbbbc ",
      " avvvvavvvvbbgc ",
      " avvvvavvvvbbbc ",
      " avvvvavvvvbbbc ",
      " avvvvavevvbbbc ",
      " avvvvavvvvbbgc ",
      " fvaavavvvefbba ",
      " addavvvevvbgbc ",
      " addavevvevbbbc "
    ],
    [
      " aaaahiijkja  a ",
      " l  amn o pa  a ",
      " l qarstuwxa  a ",
      " a yaABCDEoa  a ",
      " fFaaIaJJK f  a ",
      " L   Ma    a  a ",
      " N OP Q n  J  R ",
      " NSTUV!WXY Z  a ",
      " a0110a1111a  R ",
      " a2112a3iiia4 a ",
      " l 55 am 67aL a ",
      " l 88 a9 r#L4 a ",
      " a    a$ %^R  a ",
      " f&aa*a(   f  a ",
      " a ya )+B-[a  a ",
      " l qa      ]  R "
    ],
    [
      " ajjakjk  ka    ",
      " { }a     |{    ",
      " {  ;     :{    ",
      " a' a <    a    ",
      " k>aa,a.  ?f  / ",
      "     ?a    ;    ",
      "      a         ",
      " {    Q    `    ",
      " a\u0370\u0370\u0370\u0370a\u0371\u0371\u0371\u0371a    ",
      " ajjjjajjjja    ",
      " {    a   \u0372{    ",
      " {    a\u0373        ",
      " a   ?a    \u0374    ",
      " f\u0375aa\u0376a\u0377  ?f  / ",
      " a  a   <\u037a\u0371a\u037b   ",
      " {  a      \u037c    "
    ],
    [
      " aaaa\u037d\u037d\u037dk ja    ",
      " { \u037e;     \u037f{    ",
      " {  a     \u0384{    ",
      " a \u0385a      a    ",
      " Rjaaja\u0386   f  / ",
      "      a    a    ",
      "      a    \u0387    ",
      "      a    \u0387    ",
      " R\u0370\u0370\u0370\u0370a\u0371\u0371\u0371\u0371a    ",
      " ajjjja\u037d\u0388\u037d\u0388a    ",
      " {    a   \u0389{    ",
      " {    a    {    ",
      " a    a    a    ",
      " f\u0370aa\u0370a\u038a   f  / ",
      " a \u0385a      a    ",
      " {  a      \u0387    "
    ],
    [
      " aaaa\u038c\u038c\u038c\u038c\u038c\u038ca    ",
      " a\u038e\u038ea      a    ",
      " a\u038e\u038ea \u038f  \u0390 a    ",
      " a\u038e\u038ea      a    ",
      " faaaaa\u038c\u038c\u038c\u038cf  / ",
      " \u0391    a    a    ",
      "   \u0392  a  \u0392 a    ",
      " R    a    a    ",
      " a\u0393\u0393\u0393\u0393a\u0393\u0393\u0393\u0393a    ",
      " a\u038c\u038c\u038c\u038ca\u038c\u038c\u038c\u038ca    ",
      " a    a    a    ",
      " a \u0392  a  \u0390 a    ",
      " a    a    a    ",
      " faaaaa\u0393\u0393\u0393\u0393f  / ",
      " a\u038e\u038ea      a    ",
      " a\u038e\u038ea \u038f  \u0392 a    "
    ],
    [
      " \u0394bbbbbbbbb\u0394  \u0395 ",
      " \u0394b\u0396bbbbbbb\u0394  \u0395 ",
      " \u0394b bbbbbbb\u0394  \u0395 ",
      " \u0394b bbbbbbb\u0394  \u0395 ",
      " fbbbbbbbbbf  f ",
      " \u0394bbbbbbbbb\u0394  \u0395 ",
      " \u0394bbbbbbbbb\u0394  \u0395 ",
      " \u0394bbbbbbbbb\u0394  \u0395 ",
      " \u0394bbbbbbbbb\u0394  \u0395 ",
      " \u0394bbbbbbbbb\u0394  \u0395 ",
      " \u0394bbbbbbbbb\u0394  \u0395 ",
      " \u0394bbbbbbbbb\u0394  \u0395 ",
      " \u0394bbbbbbbbb\u0394  \u0395 ",
      " fbbbbbbbbbf  f ",
      " \u0394b bbbbbbb\u0394  \u0395 ",
      " \u0394b bbbbbbb\u0394  \u0395 "
    ]
  ]
}