{
  "name": "multi_flatmedium_2_floor2",
  "refpalette": "deceasedcraft:multi_flatmedium_2/multi_flatmedium_2_floor2_palette",
  "xsize": 16,
  "zsize": 16,
  "slices": [
    [
      " aaaavvvvvvbbbc ",
      " addavvvvvvbbbc ",
      " addavvvvvvbbbc ",
      " addavvvvvvbbbc ",
      " evaavavvvvebba ",
      " avvvvavvvvbbbc ",
      " avvvvavvvvbbbc ",
      " avvvvavvvvbbbc ",
      " avvvvavvvvbbbc ",
      " avvvvavvvvbbbc ",
      " avvvvavvvvbbbc ",
      " avvvvavvvvbbbc ",
      " avvvvavvvvbbbc ",
      " evaavavvvvebba ",
      " addavvvvvvbbbc ",
      " addavvvvvvbbbc "
    ],
    [
      " aaaafgghhha  a ",
      " i  aj   kla  a ",
      " imna    koa  a ",
      " a pa qrs  a  a ",
      " etaauawx  e  a ",
      " a    ay A a  a ",
      " i B  aC   D  a ",
      " i EFIaJKL M  a ",
      " aNOO!aOOOOa  a ",
      " aPOOOaQggga  a ",
      " i RRSajk  a  a ",
      " i TTUaV   a  a ",
      " a    aW   a  a ",
      " eXaaYaZ k e  a ",
      " a pa 0112 a  a ",
      " i na   k  D  a "
    ],
    [
      " ahhahhhhhha    ",
      " 3 4a     53    ",
      " 3  a     63    ",
      " a 7a 8    a    ",
      " e9aa#a $ %e  ^ ",
      " a   %a    a&   ",
      " 3    a    *    ",
      " 3  ()a    +    ",
      " a----a[[[[a    ",
      " ahhhhahhhha    ",
      " 3   ]a   53    ",
      " 3   {a   63    ",
      " a   %a}   a    ",
      " e|aa;a:  %e  ^ ",
      " a  a  '<> a&   ",
      " 3  a      *    "
    ],
    [
      " aaaa,,,hhha    ",
      " 3 .a     ?3    ",
      " 3/ a     `3    ",
      " a \u0370a      a    ",
      " ehaaha    e  ^ ",
      " a    a    a    ",
      " 3   \u0371a    \u0372    ",
      " 3    a    \u0372    ",
      " a----a[[[[a    ",
      " ahhhhahhhha    ",
      " 3   \u0373a\u0374  ?3    ",
      " 3   \u0375a\u0376  `3    ",
      " a    a    a    ",
      " e-aa-a\u0377   e  ^ ",
      " a \u0370a      a    ",
      " 3  a      \u0372    "
    ],
    [
      " aaaa\u037a\u037a\u037a\u037a\u037a\u037aa    ",
      " a\u037b\u037ba      a    ",
      " a\u037b\u037ba \u037c  \u037d a    ",
      " a\u037b\u037ba      a    ",
      " eaaaaa\u037a\u037a\u037a\u037ae  ^ ",
      " a    a    a    ",
      " a \u037e  a  \u037e a    ",
      " a    a    a    ",
      " a\u037f\u037f\u037f\u037fa\u037f\u037f\u037f\u037fa    ",
      " a\u037a\u037a\u037a\u037aa\u037a\u037a\u037a\u037aa    ",
      " a    a    a    ",
      " a \u037e  a  \u037d a    ",
      " a    a    a    ",
      " eaaaaa\u037f\u037f\u037f\u037fe  ^ ",
      " a\u037b\u037ba      a    ",
      " a\u037b\u037ba \u037c  \u037e a    "
    ],
    [
      " \u0384bbbbbbbbb\u0384  \u0385 ",
      " \u0384b\u0386bbbbbbb\u0384  \u0385 ",
      " \u0384b bbbbbbb\u0384  \u0385 ",
      " \u0384b bbbbbbb\u0384  \u0385 ",
      " ebbbbbbbbbe  e ",
      " \u0384bbbbbbbbb\u0384  \u0385 ",
      " \u0384bbbbbbbbb\u0384  \u0385 ",
      " \u0384bbbbbbbbb\u0384  \u0385 ",
      " \u0384bbbbbbbbb\u0384  \u0385 ",
      " \u0384bbbbbbbbb\u0384  \u0385 ",
      " \u0384bbbbbbbbb\u0384  \u0385 ",
      " \u0384bbbbbbbbb\u0384  \u0385 ",
      " \u0384bbbbbbbbb\u0384  \u0385 ",
      " ebbbbbbbbbe  e ",
      " \u0384b bbbbbbb\u0384  \u0385 ",
      " \u0384b bbbbbbb\u0384  \u0385 "
    ]
  ]
}