{
  "name": "multi_timbertower_3_floor6",
  "refpalette": "deceasedcraft:multi_timbertower_3/multi_timbertower_3_floor6_palette",
  "xsize": 16,
  "zsize": 16,
  "slices": [
    [
      "                ",
      "                ",
      "                ",
      "                ",
      "                ",
      "                ",
      "                ",
      "                ",
      "                ",
      "                ",
      "    a      a    ",
      "bcccdbbbcccdbbbc",
      "eeeefeeeeeefeeee",
      "gggghgggggghgggg",
      "ijjjgggggggggggg",
      "i   gggggggggggg"
    ],
    [
      "                ",
      "                ",
      "                ",
      "                ",
      "                ",
      "                ",
      "                ",
      "                ",
      "                ",
      "                ",
      "                ",
      "bcccabbbcccabbbc",
      "                ",
      "k   hllllllhllll",
      "ijjjimnnooppqqqr",
      "i   im         r"
    ],
    [
      "                ",
      "                ",
      "                ",
      "                ",
      "                ",
      "                ",
      "                ",
      "                ",
      "                ",
      "                ",
      "                ",
      "bcccabbbcccabbbc",
      "                ",
      "k   hllllllhllll",
      "ijjji  s tuwxxxr",
      "i   iy         r"
    ],
    [
      "                ",
      "                ",
      "                ",
      "                ",
      "                ",
      "                ",
      "                ",
      "                ",
      "                ",
      "                ",
      "                ",
      "bcccabbbcccabbbc",
      "                ",
      "k   hllllllhllll",
      "ijjji AAAA  B Cr",
      "i   i          r"
    ],
    [
      "                ",
      "                ",
      "                ",
      "                ",
      "                ",
      "                ",
      "                ",
      "                ",
      "                ",
      "                ",
      "                ",
      "bcccabbbcccabbbc",
      "                ",
      "k   hllllllhllll",
      "ijjjiDEEEEDDDDDF",
      "i   iDIDDJDDDJDF"
    ],
    [
      "                ",
      "                ",
      "                ",
      "                ",
      "                ",
      "                ",
      "                ",
      "                ",
      "                ",
      "                ",
      "                ",
      "bcccabbbcccabbbc",
      "    d      d    ",
      "KKKKhKKKKKKhKKKK",
      "iLLLMEEEEEEMEEEE",
      "i   M NC NCMCNCC"
    ]
  ]
}