{
  "name": "multi_timbertower_3_floor8",
  "refpalette": "deceasedcraft:multi_timbertower_3/multi_timbertower_3_floor8_palette",
  "xsize": 16,
  "zsize": 16,
  "slices": [
    [
      "                ",
      "                ",
      "                ",
      "                ",
      "                ",
      "                ",
      "                ",
      "                ",
      "                ",
      "                ",
      "                ",
      "  a b c  a bcc  ",
      "ddddeddddddedddd",
      "ffffgffffffgffff",
      "hiiiffffffffjjjj",
      "h   ffffffffjjjj"
    ],
    [
      "                ",
      "                ",
      "                ",
      "                ",
      "                ",
      "                ",
      "                ",
      "                ",
      "                ",
      "                ",
      "                ",
      "  a b c  a b c  ",
      "    e      e    ",
      "k   gllllllgllll",
      "hiiimn o  p     ",
      "h   mq    p     "
    ],
    [
      "                ",
      "                ",
      "                ",
      "                ",
      "                ",
      "                ",
      "                ",
      "                ",
      "                ",
      "                ",
      "                ",
      "  a b c  a b c  ",
      "    e      e    ",
      "k   g      g    ",
      "hiiimr   p      ",
      "h   m    p      "
    ],
    [
      "                ",
      "                ",
      "                ",
      "                ",
      "                ",
      "                ",
      "                ",
      "                ",
      "                ",
      "                ",
      "                ",
      "  a b c  a b c  ",
      "    e      e    ",
      "k   g      g    ",
      "hiiims  p       ",
      "h   m   p       "
    ],
    [
      "                ",
      "                ",
      "                ",
      "                ",
      "                ",
      "                ",
      "                ",
      "                ",
      "                ",
      "                ",
      "                ",
      "  a b c  a b c  ",
      "    e      e    ",
      "k   gllllllgllll",
      "hiiimttp        ",
      "h   mttp        "
    ],
    [
      "                ",
      "                ",
      "                ",
      "                ",
      "                ",
      "                ",
      "                ",
      "                ",
      "                ",
      "                ",
      "                ",
      "  a b c  a b c  ",
      "    e      e    ",
      "uuuuguuuuuuguuuu",
      "wxxxw      w    ",
      "w   w      w    "
    ]
  ]
}