{
  "name": "multi_timbertower_3_floor9",
  "refpalette": "deceasedcraft:multi_timbertower_3/multi_timbertower_3_floor9_palette",
  "xsize": 16,
  "zsize": 16,
  "slices": [
    [
      "                ",
      "                ",
      "                ",
      "                ",
      "                ",
      "                ",
      "                ",
      "                ",
      "                ",
      "                ",
      "                ",
      "  a b c  a b c  ",
      "ddddeddddddedddd",
      "ffffgffffffgffff",
      "hiiif           ",
      "h   f           "
    ],
    [
      "                ",
      "                ",
      "                ",
      "                ",
      "                ",
      "                ",
      "                ",
      "                ",
      "                ",
      "                ",
      "                ",
      "  a b c  a b c  ",
      "    e      e    ",
      "j   gkkkkkkgkkkk",
      "hiiil           ",
      "h   l           "
    ],
    [
      "                ",
      "                ",
      "                ",
      "                ",
      "                ",
      "                ",
      "                ",
      "                ",
      "                ",
      "                ",
      "                ",
      "  a b c  a b c  ",
      "    e      e    ",
      "j   g      g    ",
      "hiiil           ",
      "h   l           "
    ],
    [
      "                ",
      "                ",
      "                ",
      "                ",
      "                ",
      "                ",
      "                ",
      "                ",
      "                ",
      "                ",
      "                ",
      "  a b c  a b c  ",
      "   ae  ca  ec   ",
      "j   g      g    ",
      "hiiil           ",
      "h   l           "
    ],
    [
      "                ",
      "                ",
      "                ",
      "                ",
      "                ",
      "                ",
      "                ",
      "                ",
      "                ",
      "                ",
      "                ",
      "  a b c  a b c  ",
      "   ae  ca  ec   ",
      "j   gkkkkkkgkkkk",
      "hiiil           ",
      "h   l           "
    ],
    [
      "                ",
      "                ",
      "                ",
      "                ",
      "                ",
      "                ",
      "                ",
      "                ",
      "                ",
      "                ",
      "                ",
      "  a b c  a b c  ",
      "ca aec ca aec ca",
      "mmmmgmmmmmmgmmmm",
      "nooonpppdddndddd",
      "n   npqpdddndddd"
    ]
  ]
}