{
  "name": "multi_timbertower_3_floor12",
  "refpalette": "deceasedcraft:multi_timbertower_3/multi_timbertower_3_floor12_palette",
  "xsize": 16,
  "zsize": 16,
  "slices": [
    [
      "                ",
      "                ",
      "                ",
      "                ",
      "                ",
      "                ",
      "                ",
      "                ",
      "                ",
      "                ",
      "                ",
      "    a      a    ",
      "bcccdbbbcccdbbbc",
      "eeeefeeeeeefeeee",
      "ghhheeeeeeeeeeee",
      "g   eeeeeeeeeeee"
    ],
    [
      "                ",
      "                ",
      "                ",
      "                ",
      "                ",
      "                ",
      "                ",
      "                ",
      "                ",
      "                ",
      "                ",
      "    a      a    ",
      "bcccdbbbcccdbbbc",
      "i   fjjjjjjfjjjj",
      "ghhhg kl  mno  l",
      "g   gp   qrnstu "
    ],
    [
      "                ",
      "                ",
      "                ",
      "                ",
      "                ",
      "                ",
      "                ",
      "                ",
      "                ",
      "                ",
      "                ",
      "    a      a    ",
      "bcccdbbbcccdbbbc",
      "i   fjwwwwjfjwww",
      "ghhhg xyyABnCDEE",
      "g   gF     n    "
    ],
    [
      "                ",
      "                ",
      "                ",
      "                ",
      "                ",
      "                ",
      "                ",
      "                ",
      "                ",
      "                ",
      "                ",
      "    a      a    ",
      "bcccdbbbcccdbbbc",
      "i   fjIIIIjfjIII",
      "ghhhg JKKL n MNN",
      "g   g      n    "
    ],
    [
      "                ",
      "                ",
      "                ",
      "                ",
      "                ",
      "                ",
      "                ",
      "                ",
      "                ",
      "                ",
      "                ",
      "    a      a    ",
      "bcccdbbbcccdbbbc",
      "i   fjjjjjjfjjjj",
      "ghhhg      n    ",
      "g   g      n    "
    ],
    [
      "                ",
      "                ",
      "                ",
      "                ",
      "                ",
      "                ",
      "                ",
      "                ",
      "                ",
      "                ",
      "                ",
      "    a      a    ",
      "bcccdbbbcccdbbbc",
      "OOOOfOOOOOOfOOOO",
      "PQQQP      P    ",
      "P   P      P    "
    ]
  ]
}