{
  "name": "multi_timbertower_3_floor5",
  "refpalette": "deceasedcraft:multi_timbertower_3/multi_timbertower_3_floor5_palette",
  "xsize": 16,
  "zsize": 16,
  "slices": [
    [
      "                ",
      "                ",
      "                ",
      "                ",
      "                ",
      "                ",
      "                ",
      "                ",
      "                ",
      "                ",
      "    a      a    ",
      "bcccdbbbcccdbbbc",
      "eeeefeeeeeefeeee",
      "gggghgggggghgggg",
      "ijjjgggggggggggg",
      "i   gggggggggggg"
    ],
    [
      "                ",
      "                ",
      "                ",
      "                ",
      "                ",
      "                ",
      "                ",
      "                ",
      "                ",
      "                ",
      "    a      a    ",
      "bcccdbbbcccdbbbc",
      "                ",
      "k   hllllllhmmmm",
      "ijjjn  op qrq   ",
      "i   n      r   s"
    ],
    [
      "                ",
      "                ",
      "                ",
      "                ",
      "                ",
      "                ",
      "                ",
      "                ",
      "                ",
      "                ",
      "    a      a    ",
      "bcccdbbbcccdbbbc",
      "                ",
      "k   hllllllhmttt",
      "ijjjn     uru   ",
      "i   n      r    "
    ],
    [
      "                ",
      "                ",
      "                ",
      "                ",
      "                ",
      "                ",
      "                ",
      "                ",
      "                ",
      "                ",
      "    a      a    ",
      "bcccdbbbcccdbbbc",
      "                ",
      "k   hllllllhmwww",
      "ijjjn     xrx   ",
      "i   n      r    "
    ],
    [
      "                ",
      "                ",
      "                ",
      "                ",
      "                ",
      "                ",
      "                ",
      "                ",
      "                ",
      "                ",
      "    a      a    ",
      "bcccdbbbcccdbbbc",
      "                ",
      "k   hmmmmmmhmmmm",
      "ijjjyAAAAAABAAAA",
      "i   yACAADABADAA"
    ],
    [
      "                ",
      "                ",
      "                ",
      "                ",
      "                ",
      "                ",
      "                ",
      "                ",
      "                ",
      "                ",
      "    a      a    ",
      "bcccdbbbcccdbbbc",
      "    E      E    ",
      "FFFFhFFFFFFhFFFF",
      "IJJJI    KLI K K",
      "I   I M KMLI M K"
    ]
  ]
}