{
  "name": "multi_timbertower_3_ground",
  "refpalette": "deceasedcraft:multi_timbertower_3/multi_timbertower_3_ground_palette",
  "xsize": 16,
  "zsize": 16,
  "slices": [
    [
      "abaaaaaababaaaaa",
      "aabbbabbaabbbbab",
      "aaaabaaaaaabaaaa",
      "vvvvvvvvvvvvvvvv",
      "cvvvvvvvcvvvvvvv",
      "vvvvvvvvccvvvvvv",
      "vvvvdvvvvvvdvvvv",
      "vvvvvvvvvvvvvvvv",
      "vvvvvvvvvvvvvvvv",
      "vvvvvvvvvvvvvvvv",
      "vvvvvvvvvvvvvvvv",
      "vvvvvvvvvvvvvvvv",
      "vvvvvvvvvvvvvvvv",
      "vvvvdvvvvvvdvvvv",
      "efffvvvvvvvvvvvv",
      "e   vvvvvvvvvvvv"
    ],
    [
      "                ",
      "                ",
      "g hg ggh gg ghg ",
      "iiiijiiiiiijiiii",
      " klmn op o qerrr",
      "so mt o    uerrr",
      "eeeed   o  derrr",
      "wxyABl    lCerrr",
      "w  DBEF  I Cerrr",
      "wJ  BFKI  l errr",
      "LLMLB      Cerrr",
      " lNOn      Cerrr",
      " PQPBlR    Serrr",
      "TTTTdRUR  lderrr",
      "efffBRR   l!errr",
      "e   BVRlR lCerrr"
    ],
    [
      "                ",
      "                ",
      "                ",
      "iiiijiiiiiijiiii",
      "    W   X  Yerrr",
      "Z  l0      Yerrr",
      "eeeed      derrr",
      "w   B       errr",
      "w   B1     2errr",
      "w  3Bl     lerrr",
      "LL4LB       errr",
      "  lPW      5errr",
      " 6lOB      lerrr",
      "TTTTd Rl   derrr",
      "efffBR7    lerrr",
      "e   B8      errr"
    ],
    [
      "                ",
      "                ",
      "                ",
      "iiiijiiiiiijiiii",
      "   lB   X99drrrr",
      "    B    99drrrr",
      "eeeeddddddddrrrr",
      "w   B    99drrrr",
      "w   B    99drrrr",
      "w#  B    99drrrr",
      "LLLLB    99drrrr",
      "   $B    99drrrr",
      "   lB   l99drrrr",
      "TTTTddddddddrrrr",
      "efffBl   99drrrr",
      "e   B    99drrrr"
    ],
    [
      "                ",
      "                ",
      "                ",
      "iiiijiiiiiijiiii",
      "  ll%99eerrrr   ",
      " l l%99eerrrr   ",
      "eeeed99eerrrr   ",
      "    %99eerrrr   ",
      "    %99eerrrr   ",
      "    %99eerrrr   ",
      "^^^^%99eerrrr   ",
      "   l%99eerrrr   ",
      "  ll%99eerrrr   ",
      "TTTTd99eerrdr   ",
      "efff%99eerrrr   ",
      "e   %99eerrrr   "
    ],
    [
      "                ",
      "                ",
      "                ",
      "iiiijiiiiiij&&  ",
      "9999drrrr  *    ",
      "9999drrrr       ",
      "dddddrrrr       ",
      "eeeedrrrr       ",
      "eeeedrrrr       ",
      "eeeedrrrr       ",
      "eeeedrrrr       ",
      "9999drrrr       ",
      "9999drrrr       ",
      "dddddrrrr  (    ",
      "dfffdrrrr       ",
      "d   drrrr       "
    ]
  ]
}