{
  "name": "multi_timbertower_3_base2",
  "refpalette": "deceasedcraft:multi_timbertower_3/multi_timbertower_3_base2_palette",
  "xsize": 16,
  "zsize": 16,
  "slices": [
    [
      "vvvvvvvvvvvvvvvv",
      "aaaaaaaaaaaaaaaa",
      "aaaaaaaaaaaaaaaa",
      "vvvvvvvvvvvvvvvv",
      "vvvvvvvvvvvvvvvv",
      "HHHHHHHHHHHHHHHH",
      "HHHHbHHHHHHbHHHH",
      "HHHHHHHHHHHHHHHH",
      "HHHHHHHHHHHHHHHH",
      "HHHHHHHHHHHHHHHH",
      "HHHHHHHHHHHHHHHH",
      "HHHHHHHHHHHHHHHH",
      "HHHHHHHHHHHHHHHH",
      "vvvvbHHHHHHbHHHH",
      "vcccvHHHHHHHHHHH",
      "vdddvHHHHHHHHHHH"
    ],
    [
      "vvvvvvvvvvvvvvvv",
      "aaaaaaaaaaaaaaaa",
      "aaaaaaaaaaaaaaaa",
      "vvvvvvvvvvvvvvvv",
      "eeeeeeeeeeeeeeee",
      "fgfg fgfgfg fgfg",
      "    b      b    ",
      "hihijhihihijhihi",
      "                ",
      "                ",
      "                ",
      "                ",
      "    kfgfgfgkfgfg",
      "llllb   m  b    ",
      "ncccohihihi hihi",
      "ndppo           "
    ],
    [
      "vvvvvvvvvvvvvvvv",
      "aaaaaaaaaaaaaaaa",
      "aaaaaaaaaaaaaaaa",
      "vvvvvvvvvvvvvvvv",
      "                ",
      "                ",
      "    b      b    ",
      "                ",
      "                ",
      "                ",
      "                ",
      "                ",
      "                ",
      "llllb      b    ",
      "nccco           ",
      "ndppo           "
    ],
    [
      "vvvvvvvvvvvvvvvv",
      "aaaaaaaaaaaaaaaa",
      "aaaaaaaaaaaaaaaa",
      "vvvvvvvvvvvvvvvv",
      "                ",
      "                ",
      "    b      b    ",
      "                ",
      "                ",
      "                ",
      "                ",
      "                ",
      "                ",
      "llllb      b    ",
      "nccco           ",
      "ndppo           "
    ],
    [
      "vvvvvvvvvvvvvvvv",
      "aaaaaaaaaaaaaaaa",
      "aaaaaaaaaaaaaaaa",
      "vvvvvvvvvvvvvvvv",
      "                ",
      "                ",
      "    b      b    ",
      "                ",
      "                ",
      "                ",
      "                ",
      "                ",
      "                ",
      "llllb      b    ",
      "nccco           ",
      "ndddo           "
    ],
    [
      "vvvvvvvvvvvvvvvv",
      "aaaaaaaaaaaaaaaa",
      "aaaaaaaaaaaaaaaa",
      "vvvvvvvvvvvvvvvv",
      "vvvvvvvvvvvvvvvv",
      "qqqqqqqqqqqqqqqq",
      "bbbbbbbbbbbbbbbb",
      "qqqqbqqqqqqbqqqq",
      "qqqqbqqqqqqbqqqq",
      "qqqqbqqqqqqbqqqq",
      "qqqqbqqqqqqbqqqq",
      "qqqqbqqqqqqbqqqq",
      "qqqqbqqqqqqbqqqq",
      "bbbbbbbbbbbbbbbb",
      "bcccbqqqqqqqqqqq",
      "b   bqqqqqqqqqqq"
    ]
  ]
}