{
  "name": "multi_timbertower_3_floor13",
  "refpalette": "deceasedcraft:multi_timbertower_3/multi_timbertower_3_floor13_palette",
  "xsize": 16,
  "zsize": 16,
  "slices": [
    [
      "                ",
      "                ",
      "                ",
      "                ",
      "                ",
      "                ",
      "                ",
      "                ",
      "                ",
      "                ",
      "                ",
      "    a      a    ",
      "bcccdbbbcccdbbbc",
      "eeeefeeeeeefeeee",
      "ghhheeeeeeeeeeee",
      "g   eeeeeeeeeeee"
    ],
    [
      "                ",
      "                ",
      "                ",
      "                ",
      "                ",
      "                ",
      "                ",
      "                ",
      "                ",
      "                ",
      "                ",
      "    a      a    ",
      "bcccdbbbcccdbbbc",
      "i   fjjjjjjfjjjj",
      "ghhhgk     lmnoo",
      "g   gk pqr lmmnn"
    ],
    [
      "                ",
      "                ",
      "                ",
      "                ",
      "                ",
      "                ",
      "                ",
      "                ",
      "                ",
      "                ",
      "                ",
      "    a      a    ",
      "bcccdbbbcccdbbbc",
      "i   fjjjjjjfjjjj",
      "ghhhgk     lms  ",
      "g   g  tuw lmnxy"
    ],
    [
      "                ",
      "                ",
      "                ",
      "                ",
      "                ",
      "                ",
      "                ",
      "                ",
      "                ",
      "                ",
      "                ",
      "    a      a    ",
      "bcccdbbbcccdbbbc",
      "i   fjjjjjjfjjjj",
      "ghhhg      ABBBB",
      "g   g      A C s"
    ],
    [
      "                ",
      "                ",
      "                ",
      "                ",
      "                ",
      "                ",
      "                ",
      "                ",
      "                ",
      "                ",
      "                ",
      "    a      a    ",
      "bcccdbbbcccdbbbc",
      "i   fAAAAAAfDDDD",
      "ghhhg      lBBBB",
      "g   g      l ss "
    ],
    [
      "                ",
      "                ",
      "                ",
      "                ",
      "                ",
      "                ",
      "                ",
      "                ",
      "                ",
      "                ",
      "                ",
      "    a      a    ",
      "bcccdbbbcccdbbbc",
      "EEEEfEEEEEEf    ",
      "FIIIFJKJJJJFBBBB",
      "F   F      FBBBB"
    ]
  ]
}