{
  "name": "multi_timbertower_3_floor10",
  "refpalette": "deceasedcraft:multi_timbertower_3/multi_timbertower_3_floor10_palette",
  "xsize": 16,
  "zsize": 16,
  "slices": [
    [
      "                ",
      "                ",
      "                ",
      "                ",
      "                ",
      "                ",
      "                ",
      "                ",
      "                ",
      "                ",
      "                ",
      "  a b c  a b c  ",
      "ca adc ca adc ca",
      "eeeefeeeeeefeeee",
      "ghhheeeeeeeeeeee",
      "g   eeeeeeeeeeee"
    ],
    [
      "                ",
      "                ",
      "                ",
      "                ",
      "                ",
      "                ",
      "                ",
      "                ",
      "                ",
      "                ",
      "                ",
      "    b      b    ",
      "ca adc ca adc ca",
      "i   fjjjjjjfkkkk",
      "ghhhlmnoopmq! r ",
      "g   l      qstuu"
    ],
    [
      "                ",
      "                ",
      "                ",
      "                ",
      "                ",
      "                ",
      "                ",
      "                ",
      "                ",
      "                ",
      "                ",
      "    b      b    ",
      "ca adc ca adc ca",
      "i   fjjjjjjfkwww",
      "ghhhlx    xq    ",
      "g   l      qy A "
    ],
    [
      "                ",
      "                ",
      "                ",
      "                ",
      "                ",
      "                ",
      "                ",
      "                ",
      "                ",
      "                ",
      "                ",
      "    b      b    ",
      "ca adc ca adc ca",
      "i   fjjjjjjfkBBB",
      "ghhhlC    Cq    ",
      "g   l      q    "
    ],
    [
      "                ",
      "                ",
      "                ",
      "                ",
      "                ",
      "                ",
      "                ",
      "                ",
      "                ",
      "                ",
      "                ",
      "    b      b    ",
      "ca adc ca adc ca",
      "i   fDEDEDEfkkkk",
      "ghhhl      qFFFF",
      "g   l      qFIFF"
    ],
    [
      "                ",
      "                ",
      "                ",
      "                ",
      "                ",
      "                ",
      "                ",
      "                ",
      "                ",
      "                ",
      "                ",
      "    b      b    ",
      "caaadcccaaadccca",
      "JJJJfJJJJJJfJJJJ",
      "KLLLKFFFFFFK M M",
      "K   KFNFFNFK O M"
    ]
  ]
}