{
  "name": "multi_timbertower_3_floor7",
  "refpalette": "deceasedcraft:multi_timbertower_3/multi_timbertower_3_floor7_palette",
  "xsize": 16,
  "zsize": 16,
  "slices": [
    [
      "                ",
      "                ",
      "                ",
      "                ",
      "                ",
      "                ",
      "                ",
      "                ",
      "                ",
      "                ",
      "                ",
      "abbbcaaabbbcaaab",
      "ddddeddddddedddd",
      "ffffgffffffgffff",
      "hiiif===========",
      "h   f==========="
    ],
    [
      "                ",
      "                ",
      "                ",
      "                ",
      "                ",
      "                ",
      "                ",
      "                ",
      "                ",
      "                ",
      "                ",
      "abbbcaaabbbcaaab",
      "    e      e    ",
      "j   gkkkkkkgkkkk",
      "hiiihzzzzlzzmzll",
      "h   hzzlznzlz!zz"
    ],
    [
      "                ",
      "                ",
      "                ",
      "                ",
      "                ",
      "                ",
      "                ",
      "                ",
      "                ",
      "                ",
      "                ",
      "abbbcaaabbbcaaab",
      "    e      e    ",
      "j   gkkkkkkgkkkk",
      "hiiihopoq nn orn",
      "h   h oroqnroqso"
    ],
    [
      "                ",
      "                ",
      "                ",
      "                ",
      "                ",
      "                ",
      "                ",
      "                ",
      "                ",
      "                ",
      "                ",
      "  bbcaaabbbcaaab",
      "    e      e    ",
      "j   gkkkkkkgkkkk",
      "hiiihq    qnq   ",
      "h   h         ~ "
    ],
    [
      "                ",
      "                ",
      "                ",
      "                ",
      "                ",
      "                ",
      "                ",
      "                ",
      "                ",
      "                ",
      "                ",
      "  bbc aabb caaab",
      "    e      e    ",
      "j   gkkkkkkgkkkk",
      "hiiihqq    qq   ",
      "h   h           "
    ],
    [
      "                ",
      "                ",
      "                ",
      "                ",
      "                ",
      "                ",
      "                ",
      "                ",
      "                ",
      "                ",
      "                ",
      "  b c aabb caa  ",
      "    e      e    ",
      "ttttgttttttgtttt",
      "uwwwuxxxxxxuxxxx",
      "u   uxxxxxxuxxxx"
    ]
  ]
}