{
  "name": "multi_gallery_7_ground",
  "refpalette": "deceasedcraft:multi_gallery_7/multi_gallery_7_ground_palette",
  "xsize": 16,
  "zsize": 16,
  "slices": [
    [
      "aaaabbbbbcdbbbbb",
      "eeeaaaaabbbbbbbb",
      "eeeeeeeaaaaabbbb",
      "eeeeeeeeeeeaaaaa",
      "ffffffffffffffff",
      "                ",
      "                ",
      "                ",
      "                ",
      "                ",
      "                ",
      "                ",
      "ffffffffffffffff",
      "gggggggggggggggg",
      "gggggggggggggggg",
      "gggggggggggggggg"
    ],
    [
      "       h ij     ",
      "            h   ",
      "               h",
      "                ",
      "ffffffffffffffff",
      "                ",
      "                ",
      "                ",
      "                ",
      "                ",
      "                ",
      "                ",
      "ffffffffffffffff",
      "                ",
      "                ",
      "                "
    ],
    [
      "         ij     ",
      "         ij     ",
      "                ",
      "                ",
      "fffffffffffffffk",
      "                ",
      "                ",
      "                ",
      "                ",
      "                ",
      "         llll   ",
      "         llllllm",
      "fffffffffffffffk",
      "                ",
      "                ",
      "                "
    ],
    [
      "                ",
      "         ij     ",
      "         n      ",
      "                ",
      "fffkkkkkk       ",
      "                ",
      "                ",
      "l               ",
      "lllmm           ",
      "lllmmmmmm       ",
      "lllmmmmmm       ",
      "lllmmmmmm       ",
      "fffkkkkkk       ",
      "                ",
      "                ",
      "                "
    ],
    [
      "                ",
      "                ",
      "         n      ",
      "         n      ",
      "                ",
      "                ",
      "                ",
      "                ",
      "                ",
      "                ",
      "                ",
      "                ",
      "                ",
      "                ",
      "                ",
      "                "
    ],
    [
      "                ",
      "                ",
      "                ",
      "         n      ",
      "         o      ",
      "                ",
      "                ",
      "                ",
      "                ",
      "                ",
      "                ",
      "                ",
      "                ",
      "                ",
      "                ",
      "                "
    ]
  ]
}