{
  "name": "multi_gallery_7_base1",
  "refpalette": "deceasedcraft:multi_gallery_7/multi_gallery_7_base1_palette",
  "xsize": 16,
  "zsize": 16,
  "slices": [
    [
      "        abbc  d ",
      "                ",
      "                ",
      "eeeeeeeeeeeeeeee",
      "fffggbhhhiii    ",
      "gggggbhhhiji    ",
      "gggggbhhhiii    ",
      "gggggbhhhiii    ",
      "gggggbhhhiii    ",
      "gggggbhhhiii    ",
      "bbbggbhhhiji    ",
      "bbbggbhhhiii    ",
      "ffffffffffffffff",
      "gggggggggggggggg",
      "gggggggggggggggg",
      "vvvvvvvvvvvvvvvv"
    ],
    [
      "        abbc    ",
      "                ",
      "                ",
      "eeeeeeeeeeeeeeee",
      "fffffkfffhhhhhhi",
      "llllllhhhhhhhhhi",
      "llllllhhhhhhhhhi",
      "llllllhhhhhhhhhi",
      "llllllhhhhhhhhhi",
      "llllllhhhhhhhhhi",
      "mnobbbbbbhhhhhhi",
      "mnobbbbbbhhhhhhi",
      "fffffkffffffffff",
      "gggggggggggggggg",
      "gggggggggggggggg",
      "vvvvvvvvvvvvvvvv"
    ],
    [
      "        abbc    ",
      "                ",
      "  p           p ",
      "eeeeeeeeeeeeeeee",
      "fffffqfffffkfffh",
      "  rsssllllllhhhh",
      "   sssllllllhhhh",
      "   sssllllllhhhh",
      "   sssllllllhhhh",
      "   sssllllllhhhh",
      "  tuwxmnobbbbbbh",
      "  tuwxmnobbbbbbh",
      "fffffqfffffkffff",
      "gggggegggggggggg",
      "gggggggggggggggg",
      "vvvvvvvvvvvvvvvv"
    ],
    [
      "        abbc    ",
      "                ",
      "                ",
      "eeeeeeeeeeeeeeee",
      "fffffffffffqffff",
      "  y    ABsssllll",
      "         sssllll",
      "         sssllll",
      "         sssllll",
      "         sssllll",
      "        tuwxmnob",
      "        tuwxmnob",
      "fffffffffffqffff",
      "gggggggggggegggg",
      "gggggggggggggggg",
      "vvvvvvvvvvvvvvvv"
    ],
    [
      "CCDDDDCCCbbCCCCC",
      "CCCCCCCCCCCCCCCC",
      "CCCCCCCCCCCCCCCC",
      "eeeeeeeeeeeeeeee",
      "ffffffffffffffff",
      "              rs",
      "               s",
      "               s",
      "               s",
      "               s",
      "              tu",
      "              tu",
      "ffffffffffffffff",
      "gggggggggggggggg",
      "gggggggggggggggg",
      "vvvvvvvvvvvvvvvv"
    ],
    [
      "hhhhEEEEEFFEEEEE",
      "hhhhhhhhEEEEEEEE",
      "hhhhhhhhhhhhEEEE",
      "hhhhhhhhhhhhhhhh",
      "ffffffffffffffff",
      "              I ",
      "                ",
      "                ",
      "                ",
      "                ",
      "                ",
      "                ",
      "ffffffffffffffff",
      "gggggggggggggggg",
      "gggggggggggggggg",
      "vvvvvvvvvvvvvvvv"
    ]
  ]
}