{
  "name": "multi_gallery_7_base2",
  "refpalette": "deceasedcraft:multi_gallery_7/multi_gallery_7_base2_palette",
  "xsize": 16,
  "zsize": 16,
  "slices": [
    [
      "aaaaaaaaaaaaaaaa",
      "aaaaaaaaaaaaaaaa",
      "aaaaaaaaaaaaaaaa",
      "aaaaaaaaaaaaaaaa",
      "aaaaaaaaaaaaaaaa",
      "aaaaaaaaaaaaaaaa",
      "aaaaaaaaaaaaaaaa",
      "aaaaaaaaaaaaaaaa",
      "aaaaaaaaaaaaaaaa",
      "aaaaaaaaaaaaaaaa",
      "aaaaaaaaaaaaaaaa",
      "aaaaaaaaaaaaaaaa",
      "bbbbbbbbbbbbbbbb",
      "aaaaaaaaaaaaaaaa",
      "aaaaaaaaaaaaaaaa",
      "vvvvvvvvvvvvvvvv"
    ],
    [
      "aaaaaaaaaaaaaaaa",
      "aaaaaaaaaaaaaaaa",
      "aaaaaaaaaaaaaaaa",
      "aaaaaaaaaaaaaaaa",
      "aaaaaaaaaaaaaaaa",
      "aaaaaaaaaaaaaaaa",
      "aaaaaaaaaaaaaaaa",
      "aaaaaaaaaaaaaaaa",
      "aaaaaaaaaaaaaaaa",
      "aaaaaaaaaaaaaaaa",
      "aaaaaaaaaaaaaaaa",
      "aaaaaaaaaaaaaaaa",
      "bbbbbbbbbbbbbbbb",
      "cccccccccccccccc",
      "aaaaaaaaaaaaaaaa",
      "vvvvvvvvvvvvvvvv"
    ],
    [
      "deffffeddddddeff",
      "deeeeeeddddddeee",
      "dddddddddddddddd",
      "cccccccccccccccc",
      "aaaaaghhhhhhhhhh",
      "aaaaaghhhhhhhhhh",
      "aaaaaghhhhhhhhhh",
      "aaaaaghhhhhhhhhh",
      "aaaaaghhhhhhhhhh",
      "aaaaaghhhhhhhhhh",
      "aaaaaghhhhhhhhhh",
      "aaaaaghhhhhhhhhh",
      "bbbbbbbbbbbbbbbb",
      "iiiiiiiiiiiiiiii",
      "cccccccccccccccc",
      "vvvvvvvvvvvvvvvv"
    ],
    [
      "  jjjj  kggl  jj",
      "                ",
      "                ",
      "mmmmmmmmmnommmmm",
      "aaaaagpq        ",
      "aaaaagp         ",
      "aaaaagrp       s",
      "aaaaagpp   tu  s",
      "aaaaagprp      s",
      "aaaaagwpq  tu  s",
      "aaaaagp!p  xy  s",
      "aaaaagprp  AB  s",
      "bbbbbbbbbbbbbbbb",
      "cccccccccccccccc",
      "aaaaaaaaaaaaaaaa",
      "vvvvvvvvvvvvvvvv"
    ],
    [
      "        kggl  C ",
      "                ",
      "                ",
      "mmmmmmmmmDEmmmmm",
      "aaaaag          ",
      "aaaaag          ",
      "aaaaag          ",
      "aaaaag          ",
      "aaaaag          ",
      "aaaaag          ",
      "aaaaag         F",
      "aaaaag         I",
      "bbbbbbbbbbbbbbbb",
      "aaaaaaaaaaaaaaaa",
      "aaaaaaaaaaaaaaaa",
      "vvvvvvvvvvvvvvvv"
    ],
    [
      "        kggl  CJ",
      "                ",
      "                ",
      "mmmmmmmmmmmmmmmm",
      "aaaaag          ",
      "aaaaag          ",
      "aaaaag          ",
      "aaaaag          ",
      "aaaaag          ",
      "aaaaag          ",
      "aaaaag          ",
      "aaaaag          ",
      "bbbbbbbbbbbbbbbb",
      "aaaaaaaaaaaaaaaa",
      "aaaaaaaaaaaaaaaa",
      "vvvvvvvvvvvvvvvv"
    ]
  ]
}