{
  "name": "multi_gallery_7_floor1",
  "refpalette": "deceasedcraft:multi_gallery_7/multi_gallery_7_floor1_palette",
  "xsize": 16,
  "zsize": 16,
  "slices": [
    [
      "aaaaaaaaaaaaaaaa",
      "aaaaaaaaaaaaaaaa",
      "baaaaaaaaaaaaaaa",
      "cbbbbaaaaaaaaaaa",
      " ccccbbbbaaaaaaa",
      "     ccccbbbbaaa",
      "         ccccbbb",
      "             ccc",
      "                ",
      "                ",
      "                ",
      "                ",
      "                ",
      "                ",
      "                ",
      "                "
    ],
    [
      "  d             ",
      "     d          ",
      "e  f            ",
      "ceeee  f        ",
      " cccceeee  f    ",
      "     cccceeee  f",
      "         cccceee",
      "             ccc",
      "                ",
      "                ",
      "                ",
      "                ",
      "                ",
      "                ",
      "                ",
      "                "
    ],
    [
      "                ",
      "                ",
      "e  g            ",
      "ceeee  !        ",
      " cccceeee  h    ",
      "     cccceeee  i",
      "         cccceee",
      "             ccc",
      "                ",
      "                ",
      "                ",
      "                ",
      "                ",
      "                ",
      "                ",
      "                "
    ],
    [
      "                ",
      "                ",
      "e               ",
      "ceeee           ",
      " cccceeee       ",
      "     cccceeee   ",
      "         cccceee",
      "             ccc",
      "                ",
      "                ",
      "                ",
      "                ",
      "                ",
      "                ",
      "                ",
      "                "
    ],
    [
      "                ",
      "                ",
      "j               ",
      " jjjj           ",
      "     jjjj       ",
      "         jjjj   ",
      "             jjj",
      "                ",
      "                ",
      "                ",
      "                ",
      "                ",
      "                ",
      "                ",
      "                ",
      "                "
    ],
    [
      "kkkkkkkkkkklkkkk",
      "kkkkkkkkkkklkkkk",
      "mkkkkkkkkkkkkkkk",
      "nmmmmkkkkkkkkkkk",
      " nnnnmmmmkkkkkkk",
      "     nnnnmmmmkkk",
      "         nnnnmmm",
      "             nnn",
      "                ",
      "                ",
      "                ",
      "                ",
      "                ",
      "                ",
      "                ",
      "                "
    ]
  ]
}