{
  "name": "multi_casino_14_base7",
  "refpalette": "deceasedcraft:multi_casino_14/multi_casino_14_base7_palette",
  "xsize": 16,
  "zsize": 16,
  "slices": [
    [
      "             abv",
      "             abv",
      "            cabv",
      "            dabv",
      "            cabv",
      "             abv",
      "             abv",
      "       ef   cabv",
      "             abv",
      "            cabv",
      "            cabv",
      "            dabv",
      "            cabv",
      "             abv",
      "             abv",
      "            cabv"
    ],
    [
      "             abv",
      "             abv",
      "             abv",
      "            dabv",
      "             abv",
      "             abv",
      "       g     abv",
      "       !f    abv",
      "       h     abv",
      "             abv",
      "            cabv",
      "            dabv",
      "            cabv",
      "             abv",
      " i           abv",
      "j            abv"
    ],
    [
      "             abv",
      "             abv",
      "             abv",
      "            dabv",
      "             abv",
      "             abv",
      "       g     abv",
      "       kf    abv",
      "       h     abv",
      "             abv",
      "             abv",
      "i           dabv",
      "             abv",
      "             abv",
      " l           abv",
      "m   i        abv"
    ],
    [
      "             abv",
      "             abv",
      "             abv",
      "            dabv",
      "             abv",
      "             abv",
      "             abv",
      "       nf    abv",
      "             abv",
      "             abv",
      "             abv",
      "l           dabv",
      "             abv",
      "             abv",
      "ll           abv",
      "ml  l        abv"
    ],
    [
      "opoooooooooo abv",
      "oopooooooooo abv",
      "ooopoooooooo abv",
      "qoooqoooqooodabv",
      "ooooopooooop abv",
      "oooooopooopo abv",
      "ooooooopopoo abv",
      "qoooqooofooo abv",
      "ooooooopopoo abv",
      "pppooopooopo abv",
      "l ppppooooop abv",
      "l   rpooqooodabv",
      "   j poooooo abv",
      "  j  ppooooo abv",
      " m    pooooo abv",
      "mo  llpoqooo abv"
    ],
    [
      "sfssssssssstuabv",
      "ssfsssssssstuabv",
      "sssfssssssstuabv",
      "wsssfssswsssdabv",
      "sssssfsssssfuabv",
      "ssssssfsssftuabv",
      "sssssssfsfstuabv",
      "wssswsssfsstuabv",
      "sssssssfsfstuabv",
      "ssssssfsssftuabv",
      "mmsssfsssssfuabv",
      "mwwwfssswsssdabv",
      "wwwfwsssssstuabv",
      "wwfwwsssssstuabv",
      "wfwwwmssssstuabv",
      "fswwmmsswsstuabv"
    ]
  ]
}