{
  "name": "multi_casino_14_base9",
  "refpalette": "deceasedcraft:multi_casino_14/multi_casino_14_base9_palette",
  "xsize": 16,
  "zsize": 16,
  "slices": [
    [
      "aaaaaaaaabbbbbbv",
      "aaaaaaaaabbbbbbv",
      "aaaaaaaaabbbbbbv",
      "aaaaaaaaabbbbbbv",
      "aaaaaaaaabbbbbbv",
      "aaaaaaaaabbbbbbv",
      "aaaaaaaaabbbbbbv",
      "aaaaaaaaabbbbbbv",
      "aaaaaaaaabbbbbbv",
      "aaaaaaaaabbbbbbv",
      "aaaaaaaaabbbbbbv",
      "aaaaaaaaabbbbbbv",
      "aaaaaaaaabbbbbbv",
      "aaaaaaaaabbbbbbv",
      "aaaaaaaaabbbbbbv",
      "aaaaaaaaabbbbbbv"
    ],
    [
      "cccccccccbbbbbbv",
      "cccccccccbbbbbbv",
      "cccccccccbbbbbbv",
      "cccccccccbbbbbbv",
      "cccccccccbbbbbbv",
      "ccccbbbbbbbbbbbv",
      "cbbbbbbbbbbbbbbv",
      "bbbbbbbbdbbbbbbv",
      "bbbbbbbbbbbbbbbv",
      "bbbbbbbbbbbbbbbv",
      "bbbbbbbbbbbbbbbv",
      "bbbbbbbbbbbbbbbv",
      "bbbbbbbbbbbbbbbv",
      "bbbbbbbbbbbbbbbv",
      "bbbbbbbbbbbbbbbv",
      "bbbbbbbbbbbbbbbv"
    ],
    [
      "cccccccccbbbbbbv",
      "cccccccccbbbbbbv",
      "cccccccccbbbbbbv",
      "cccccccccbbbbbbv",
      "cccccccccbbbbbbv",
      "ccccbbbbbbbbbbbv",
      "cbbbbbbbbbbbbbbv",
      "bbbbbbbbdbbbbbbv",
      "bbbbbbbbbbbbbbbv",
      "bbbbbbbbbbbbbbbv",
      "bbbbbbbbbbbbbbbv",
      "bbbbbbbbbbbbbbbv",
      "bbbbbbbbbbbbbbbv",
      "bbbbbbbbbbbbbbbv",
      "bbbbbbbbbbbbbbbv",
      "bbbbbbbbbbbbbbbv"
    ],
    [
      "cccccccccbbbbbbv",
      "cccccccccbbbbbbv",
      "cccccccccbbbbbbv",
      "cccccccccbbbbbbv",
      "cccccccccbbbbbbv",
      "ccccbbbbbbbbbbbv",
      "cbbbbbbbbbbbbbbv",
      "bbbbbbbbdbbbbbbv",
      "bbbbbbbbbbbbbbbv",
      "bbbbbbbbbbbbbbbv",
      "bbbbbbbbbbbbbbbv",
      "bbbbbbbbbbbbbbbv",
      "bbbbbbbbbbbbbbbv",
      "bbbbbbbbbbbbbbbv",
      "bbbbbbbbbbbbbbbv",
      "bbbbbbbbbbbbbbbv"
    ],
    [
      "cccccccccbbbbbbv",
      "cccccccccbbbbbbv",
      "cccccccccbbbbbbv",
      "cccccccccbbbbbbv",
      "cccccccccbbbbbbv",
      "ccccbbbbbbbbbbbv",
      "cbbbbbbbbbbbbbbv",
      "bbbbbbbbdbbbbbbv",
      "bbbbbbbbbbbbbbbv",
      "bbbbbbbbbbbbbbbv",
      "bbbbbbbbbbbbbbbv",
      "bbbbbbbbbbbbbbbv",
      "bbbbbbbbbbbbbbbv",
      "bbbbbbbbbbbbbbbv",
      "bbbbbbbbbbbbbbbv",
      "bbbbbbbbbbbbbbbv"
    ],
    [
      "cdcccccccbbbbbbv",
      "ccdccccccbbbbbbv",
      "cccdcccccbbbbbbv",
      "ccccdccccbbbbbbv",
      "cccccdcccbbbbbbv",
      "ccccbbdbbbbbbbbv",
      "cbbbbbbdbbbbbbbv",
      "bbbbbbbbdbbbbbbv",
      "bbbbbbbdbbbbbbbv",
      "bbbbbbdbbbbbbbbv",
      "bbbbbdbbbbbbbbbv",
      "bbbbdbbbbbbbbbbv",
      "bbbdbbbbbbbbbbbv",
      "bbdbbbbbbbbbbbbv",
      "bdbbbbbbbbbbbbbv",
      "dbbbbbbbbbbbbbbv"
    ]
  ]
}