{
  "name": "multi_casino_14_base2",
  "refpalette": "deceasedcraft:multi_casino_14/multi_casino_14_base2_palette",
  "xsize": 16,
  "zsize": 16,
  "slices": [
    [
      "aaaaaaaaaabcdefv",
      "aaaaaaaaaabcdefv",
      "aaaaaaaaaabcdefv",
      "aaaaaaaaaabcgefv",
      "aaaaaaaaaabcdefv",
      "aaaaaaaaaabcdefv",
      "aaaaaaaaaabcdefv",
      "aaaaaaaahabcdefv",
      "aaaaaaaaaabcdefv",
      "aaaaaaaaaabcdefv",
      "aaaaaaaaaabcdefv",
      "aaaaaaaaaabcgefv",
      "aaaaaaaaaabcdefv",
      "aaaaaaaaaabcdefv",
      "aaaaaaaaaabcdefv",
      "aaaaaaaaaabcdefv"
    ],
    [
      "            iefv",
      "   jklmnj   iefv",
      "            iefv",
      "   jklmnj  ogefv",
      "            iefv",
      "   jklmnj   iefv",
      "l           iefv",
      "lp     qh   iefv",
      "l     j     iefv",
      "lp    r     iefv",
      "l   jkmnj   iefv",
      "lp    s    ogefv",
      "l     j     iefv",
      "p     j     iefv",
      "      r     iefv",
      "    jkmnj   iefv"
    ],
    [
      "     tu     iefv",
      "    wxxy    iefv",
      "     tu     iefv",
      "    wxxy    gefv",
      "     tu     iefv",
      "    wxxy    iefv",
      "A     u     iefv",
      "B       h   iefv",
      "            iefv",
      "C     D     iefv",
      "E    FlI    iefv",
      "      J     gefv",
      "K           iefv",
      "            iefv",
      "      D     iefv",
      "     FlI    iefv"
    ],
    [
      "            iefv",
      "     LM     iefv",
      "            iefv",
      "     LM     gefv",
      "            iefv",
      "     LM     iefv",
      "            iefv",
      "        h   iefv",
      "            iefv",
      "      N     iefv",
      "     OlP    iefv",
      "      Q     gefv",
      "            iefv",
      "            iefv",
      "      N     iefv",
      "     OlP    iefv"
    ],
    [
      "            iefv",
      "     RR     iefv",
      "            iefv",
      "     RR     gefv",
      "            iefv",
      "     RR     iefv",
      "            iefv",
      "        h   iefv",
      "            iefv",
      "      S     iefv",
      "     T U    iefv",
      "      V     gefv",
      "            iefv",
      "            iefv",
      "      S     iefv",
      "     T U    iefv"
    ],
    [
      "            iefv",
      "             efv",
      "            iefv",
      "            gefv",
      "            iefv",
      "            iefv",
      "             efv",
      "        h   iefv",
      "            iefv",
      "            iefv",
      "      W     iefv",
      "            gefv",
      "            iefv",
      "            iefv",
      "             efv",
      "      W     iefv"
    ]
  ]
}