{
  "name": "multi_casino_14_base4",
  "refpalette": "deceasedcraft:multi_casino_14/multi_casino_14_base4_palette",
  "xsize": 16,
  "zsize": 16,
  "slices": [
    [
      "aaaaaaaaaabcdefv",
      "aaaaaaaaaabcdefv",
      "aaaaaaaaaabcdefv",
      "aaaaaaaaaabcgefv",
      "aaaaaaaaaabcdefv",
      "aaaaaaaaaabcdefv",
      "aaaaaaaaaabcdefv",
      "aaaaaaaahabcdefv",
      "aaaaaaaaaabcdefv",
      "aaaaaaaaaabcdefv",
      "aaaaaaaaaabcdefv",
      "aaaaaaaaaabcgefv",
      "aaaaaaaaaabcdefv",
      "aaaaaaaaaabcdefv",
      "aaaaaaaaaabcdefv",
      "aaaaaaaaaabcdefv"
    ],
    [
      "     iij    kefv",
      "    illmn   kefv",
      "    illl    kefv",
      "    illlo  pgefv",
      "i   illmn   kefv",
      "li   iiq    kefv",
      "li          kefv",
      "li     rh   kefv",
      "li          kefv",
      "li   iij    kefv",
      "i   illmn   kefv",
      "    illlo  pgefv",
      "    illls   kefv",
      "    illmn   kefv",
      "     iiq    kefv",
      "            kefv"
    ],
    [
      "            kefv",
      "            kefv",
      "            kefv",
      "            gefv",
      "            kefv",
      "            kefv",
      "            kefv",
      "        h   kefv",
      "            kefv",
      "            kefv",
      "            kefv",
      "            gefv",
      "            kefv",
      "            kefv",
      "            kefv",
      "            kefv"
    ],
    [
      "            kefv",
      "            kefv",
      "            kefv",
      "            gefv",
      "            kefv",
      "            kefv",
      "            kefv",
      "        h   kefv",
      "            kefv",
      "            kefv",
      "            kefv",
      "            gefv",
      "            kefv",
      "            kefv",
      "            kefv",
      "            kefv"
    ],
    [
      "            kefv",
      "            kefv",
      "            kefv",
      "            gefv",
      "            kefv",
      "            kefv",
      "            kefv",
      "        h   kefv",
      "            kefv",
      "            kefv",
      "            kefv",
      "            gefv",
      "            kefv",
      "            kefv",
      "            kefv",
      "            kefv"
    ],
    [
      "            kefv",
      "             efv",
      "            kefv",
      "            gefv",
      "            kefv",
      "            kefv",
      "             efv",
      "        h   kefv",
      "            kefv",
      "            kefv",
      "            kefv",
      "            gefv",
      "            kefv",
      "            kefv",
      "             efv",
      "            kefv"
    ]
  ]
}