{
  "name": "multi_casino_14_base5",
  "refpalette": "deceasedcraft:multi_casino_14/multi_casino_14_base5_palette",
  "xsize": 16,
  "zsize": 16,
  "slices": [
    [
      "             abv",
      "             abv",
      "            cabv",
      "            dabv",
      "            cabv",
      "             abv",
      "             abv",
      "        e   cabv",
      "             abv",
      "            cabv",
      "            cabv",
      "            dabv",
      "            cabv",
      "             abv",
      "             abv",
      "            cabv"
    ],
    [
      "             abv",
      "             abv",
      "             abv",
      "            dabv",
      "             abv",
      "             abv",
      "             abv",
      "        e    abv",
      "             abv",
      "             abv",
      "            cabv",
      "            dabv",
      "            cabv",
      "             abv",
      "             abv",
      "             abv"
    ],
    [
      "             abv",
      "             abv",
      "             abv",
      "            dabv",
      "             abv",
      "             abv",
      "        f    abv",
      "       ge    abv",
      "        h    abv",
      "             abv",
      "             abv",
      "            dabv",
      "             abv",
      "             abv",
      "             abv",
      "             abv"
    ],
    [
      "             abv",
      "             abv",
      "             abv",
      "            dabv",
      "             abv",
      "             abv",
      "             abv",
      "        e    abv",
      "             abv",
      "             abv",
      "             abv",
      "            dabv",
      "             abv",
      "             abv",
      "             abv",
      "             abv"
    ],
    [
      "ijiiiiiiiiii abv",
      "iijiiiiiiiii abv",
      "iiijiiiiiiii abv",
      "kiiikiiikiiidabv",
      "iiiiijiiiiij abv",
      "iiiiiijiiiji abv",
      "iiiiiiijijii abv",
      "kiiikiiieiii abv",
      "iiiiiiijijii abv",
      "iiiiiijiiiji abv",
      "iiiiijiiiiij abv",
      "kiiikiiikiiidabv",
      "iiijiiiiiiii abv",
      "iijiiiiiiiii abv",
      "ijiiiiiiiiii abv",
      "kiiikiiikiii abv"
    ],
    [
      "lelllllllllmnabv",
      "llellllllllmnabv",
      "lllelllllllmnabv",
      "olllelllollldabv",
      "lllllelllllenabv",
      "llllllelllemnabv",
      "lllllllelelmnabv",
      "olllolllellmnabv",
      "lllllllelelmnabv",
      "llllllelllemnabv",
      "lllllelllllenabv",
      "olllelllollldabv",
      "lllelllllllmnabv",
      "llellllllllmnabv",
      "lelllllllllmnabv",
      "elllolllollmnabv"
    ]
  ]
}