{
  "name": "multi_casino_14_base8",
  "refpalette": "deceasedcraft:multi_casino_14/multi_casino_14_base8_palette",
  "xsize": 16,
  "zsize": 16,
  "slices": [
    [
      "aaaaaaaaaabcdefv",
      "aaaaaaaaaabcdefv",
      "aaaaaaaaaabcdefv",
      "aaaaaaaaaabcgefv",
      "aaaaaaaaaabcdefv",
      "aaaabbbbbbbcdefv",
      "abbbbhhhhhbcdefv",
      "bbhhhhhhihbcdefv",
      "hhhhhhhhhhbcdefv",
      "hhhhhhhhhhbcdefv",
      "hhhhhhhhhhbcdefv",
      "hhhhhhhhhhbcgefv",
      "hhhhhhhhhhbcdefv",
      "hhhhhhhhhhbcdefv",
      "hhhhhhhhhhbcdefv",
      "hhhhhhhhhhbcdefv"
    ],
    [
      "jk  k   k   lefv",
      "k           lefv",
      "  m   m     lefv",
      " mjm mjm   ngefv",
      "  m   m     lefv",
      "            lefv",
      "            lefv",
      "    ooooi   lefv",
      "  ooohhhh   lefv",
      "ooohhhhhh   lefv",
      "ohhhhhhhh   lefv",
      "hhhhhhhhh  ngefv",
      "hhhhhhhhhp  lefv",
      "hhhhhhhhhq  lefv",
      "hhhhhhhhhq  lefv",
      "hhhhhhhhhq  lefv"
    ],
    [
      "r           lefv",
      "            lefv",
      "            lefv",
      "            gefv",
      "            lefv",
      "            lefv",
      "            lefv",
      "        i   lefv",
      "            lefv",
      "            lefv",
      "            lefv",
      "            gefv",
      "            lefv",
      "            lefv",
      "            lefv",
      "!           lefv"
    ],
    [
      "            lefv",
      "            lefv",
      "            lefv",
      "            gefv",
      "            lefv",
      "            lefv",
      "            lefv",
      "        i   lefv",
      "            lefv",
      "            lefv",
      "            lefv",
      "            gefv",
      "            lefv",
      "            lefv",
      "            lefv",
      "            lefv"
    ],
    [
      "            lefv",
      "            lefv",
      "            lefv",
      "            gefv",
      "            lefv",
      "            lefv",
      "            lefv",
      "        i   lefv",
      "            lefv",
      "            lefv",
      "            lefv",
      "            gefv",
      "            lefv",
      "            lefv",
      "            lefv",
      "            lefv"
    ],
    [
      "            lefv",
      "             efv",
      "            lefv",
      "            gefv",
      "            lefv",
      "            lefv",
      "             efv",
      "        i   lefv",
      "            lefv",
      "            lefv",
      "            lefv",
      "            gefv",
      "            lefv",
      "            lefv",
      "             efv",
      "            lefv"
    ]
  ]
}