{
  "name": "multi_casino_14_ground",
  "refpalette": "deceasedcraft:multi_casino_14/multi_casino_14_ground_palette",
  "xsize": 16,
  "zsize": 16,
  "slices": [
    [
      "HHHHHHHHHHHHHHHH",
      "HHHHHHHHHHHHHHHH",
      "HHHHHHHHHHHHHHHH",
      "HHHHHHHHHHHHHHHH",
      "aaaaaaaaaaaabHHH",
      "cdddddddcddabHHH",
      "cdddddddcddabHHH",
      "ecccccccfccabHHH",
      "cdddddddcddabHHH",
      "cdggggggggghbHHH",
      "cdggggggggghbHHH",
      "cdggggggggghbHHH",
      "cdggggggggghbHHH",
      "cdggggggggghbHHH",
      "cdddddddcddabHHH",
      "eccccccceccabHHH"
    ],
    [
      "iiiiiiiiiiij    ",
      "                ",
      "                ",
      "kkkkkkkkkkkl    ",
      "mmmmmmmmmmmm    ",
      "nooonooonoom    ",
      "          om    ",
      "        p  m    ",
      "           m    ",
      "    q~~q   r    ",
      "   stuutuwxr    ",
      "   y A  BC r    ",
      "   stuutuDxr    ",
      "    E  E   r    ",
      "           m    ",
      "        p  m    "
    ],
    [
      "                ",
      "                ",
      "                ",
      "                ",
      "                ",
      "F   F   F       ",
      "                ",
      "        I       ",
      "                ",
      "      ~         ",
      "  JKLMNM        ",
      "  JKO NLP       ",
      "  JKLQNQ        ",
      "                ",
      "                ",
      "        I       "
    ],
    [
      "                ",
      "                ",
      "                ",
      "                ",
      "                ",
      "                ",
      "                ",
      "        o       ",
      "                ",
      "      ~         ",
      "                ",
      "                ",
      "                ",
      "                ",
      "                ",
      "        o       "
    ],
    [
      "                ",
      "                ",
      "                ",
      "                ",
      "                ",
      "                ",
      "                ",
      "        R       ",
      "                ",
      "      ~         ",
      "                ",
      "                ",
      "                ",
      "                ",
      "                ",
      "        R       "
    ],
    [
      "                ",
      "                ",
      "                ",
      "                ",
      "                ",
      "                ",
      "                ",
      "        R       ",
      "                ",
      "      ~         ",
      "                ",
      "                ",
      "                ",
      "                ",
      "                ",
      "        R       "
    ]
  ]
}