{
  "name": "multi_casino_14_base6",
  "refpalette": "deceasedcraft:multi_casino_14/multi_casino_14_base6_palette",
  "xsize": 16,
  "zsize": 16,
  "slices": [
    [
      "aaaaaaaaaabcdefv",
      "aaaaaaaaaabcdefv",
      "aaaaaaaaaabcdefv",
      "aaaaaaaaaabcgefv",
      "aaaaaaaaaabcdefv",
      "aaaaaaaaaabcdefv",
      "aaaaaaaaaabcdefv",
      "aaaaaaaahabcdefv",
      "aaaaaaaaaabcdefv",
      "aaaaaaaaaabcdefv",
      "aaaaaaaaaabcdefv",
      "aaaaaaaaaabcgefv",
      "aaaaaaaaaabcdefv",
      "aaaaaaaaaabcdefv",
      "aaaaaaaaaabcdefv",
      "aaaaaaaaaabcdefv"
    ],
    [
      "   ijkjl    mefv",
      "   nk!kn    mefv",
      "   ijkjl    mefv",
      "    ono    pgefv",
      "            mefv",
      "    qnq     mefv",
      "jn ijkjl    mefv",
      "jl nk knh   mefv",
      "jn ijkjl    mefv",
      "    ono     mefv",
      "            mefv",
      "    qnq    pgefv",
      "   ijkjl    mefv",
      "   nk kn    mefv",
      "   ijkjl    mefv",
      "    ono     mefv"
    ],
    [
      "    rsr     mefv",
      "    sts     mefv",
      "    rsr     mefv",
      "            gefv",
      "            mefv",
      "            mefv",
      "s   usw     mefv",
      "r   sts h   mefv",
      "s   usw     mefv",
      "            mefv",
      "            mefv",
      "            gefv",
      "    usw     mefv",
      "    sts     mefv",
      "    usw     mefv",
      "            mefv"
    ],
    [
      "            mefv",
      "     x      mefv",
      "            mefv",
      "            gefv",
      "            mefv",
      "            mefv",
      "            mefv",
      "     x  h   mefv",
      "            mefv",
      "            mefv",
      "            mefv",
      "            gefv",
      "            mefv",
      "     x      mefv",
      "            mefv",
      "            mefv"
    ],
    [
      "            mefv",
      "            mefv",
      "            mefv",
      "            gefv",
      "            mefv",
      "            mefv",
      "            mefv",
      "        h   mefv",
      "            mefv",
      "            mefv",
      "            mefv",
      "            gefv",
      "            mefv",
      "            mefv",
      "            mefv",
      "            mefv"
    ],
    [
      "            mefv",
      "             efv",
      "            mefv",
      "            gefv",
      "            mefv",
      "            mefv",
      "             efv",
      "        h   mefv",
      "            mefv",
      "            mefv",
      "            mefv",
      "            gefv",
      "            mefv",
      "            mefv",
      "             efv",
      "            mefv"
    ]
  ]
}