{
  "name": "multi_alienresearch_0_base8",
  "refpalette": "deceasedcraft:multi_alienresearch_0/multi_alienresearch_0_base8_palette",
  "xsize": 16,
  "zsize": 16,
  "slices": [
    [
      "vvvvvvvvvvvvvvvv",
      "vaaaaaaaaaaaaaaa",
      "vaaaaaaaaaaaaaaa",
      "vaaaaaaaaaaaaaaa",
      "vaaaaaaaaaaaaaaa",
      "vaaaaaaaaaaaaaaa",
      "vaaaaaaaaaaaaaaa",
      "vaaaaaaaaaaaaaaa",
      "vaaaaaaaaaaaaaaa",
      "vaaaaaaaaaaaaaaa",
      "vaaaaaaaaaaaaaaa",
      "vaaaaaaaaaaaaaaa",
      "vaaaaaaaaaaaaaab",
      "vaaaaaaaaaaaaacb",
      "vaaaaaaaaaaaacc ",
      "vaaaaaaaaaaabb d"
    ],
    [
      "vvvvvvvvvvvvvvvv",
      "vaaaaaaaaaaaaaaa",
      "vaaaaaaaaaaaaaaa",
      "vaaaaaaaaaaaaaaa",
      "vaaaaaaaaaaaaaaa",
      "vaaaaaaaaaaaaaaa",
      "vaaaaaaaaaaaaaaa",
      "vaaaaaaaaaaaaaaa",
      "vaaaaaaaaaaaaaaa",
      "vaaaaaaaaaaaaaaa",
      "vaaaaaaaaaaaaaaa",
      "vaaaaaaaaaaaaaab",
      "vaaaaaaaaaaaaab ",
      "vaaaaaaaaaaaac  ",
      "vaaaaaaaaaaab d ",
      "vaaaaaaaaaab    "
    ],
    [
      "vvvvvvvvvvvvvvvv",
      "vaaaaaaaaaaaaaaa",
      "vaaaaaaaaaaaaaaa",
      "vaaaaaaaaaaaaaaa",
      "vaaaaaaaaaaaaaaa",
      "vaaaaaaaaaaaaaaa",
      "vaaaaaaaaaaaaaaa",
      "vaaaaaaaaaaaaaaa",
      "vaaaaaaaaaaaaaaa",
      "vaaaaaaaaaaaaaaa",
      "vaaaaaaaaaaaaaab",
      "vaaaaaaaaaaaaab ",
      "vaaaaaaaaaaacc  ",
      "vaaaaaaaaaaacd  ",
      "vaaaaaaaaaab    ",
      "vaaaaaaaaab     "
    ],
    [
      "vvvvvvvvvvvvvvvv",
      "vaaaaaaaaaaaaaaa",
      "vaaaaaaaaaaaaaaa",
      "vaaaaaaaaaaaaaaa",
      "vaaaaaaaaaaaaaaa",
      "vaaaaaaaaaaaaaaa",
      "vaaaaaaaaaaaaaaa",
      "vaaaaaaaaaaaaaaa",
      "vaaaaaaaaaaaaaaa",
      "vaaaaaaaaaaaaaab",
      "vaaaaaaaaaaaaab ",
      "vaaaaaaaaaaacb  ",
      "vaaaaaaaaaacd   ",
      "vaaaaaaaaaab    ",
      "vaaaaaaaaab     ",
      "vaaaaaaaab      "
    ],
    [
      "vvvvvvvvvvvvvvvv",
      "vaaaaaaaaaaaaaaa",
      "vaaaaaaaaaaaaaaa",
      "vaaaaaaaaaaaaaaa",
      "vaaaaaaaaaaaaaaa",
      "vaaaaaaaaaaaaaaa",
      "vaaaaaaaaaaaaaaa",
      "vaaaaaaaaaaaaaaa",
      "vaaaaaaaaaaaaaab",
      "vaaaaaaaaaaaaab ",
      "vaaaaaaaaaaabb  ",
      "vaaaaaaaaaac    ",
      "vaaaaaaaaab d   ",
      "vaaaaaaaaab     ",
      "vaaaaaaaab      ",
      "vaaaaaaab       "
    ],
    [
      "vvvvvvvvvvvvvvvv",
      "vaaaaaaaaaaaaaaa",
      "vaaaaaaaaaaaaaaa",
      "vaaaaaaaaaaaaaaa",
      "vaaaaaaaaaaaaaaa",
      "vaaaaaaaaaaaaaaa",
      "vaaaaaaaaaaaaaaa",
      "vaaaaaaaaaaaaaaa",
      "vaaaaaaaaaaaaabb",
      "vaaaaaaaaaaaab  ",
      "vaaaaaaaaaaab   ",
      "vaaaaaaaaaac    ",
      "vaaaaaaaaab d   ",
      "vaaaaaaaab      ",
      "vaaaaaaab       ",
      "vaaaaaaab       "
    ]
  ]
}