{
  "name": "multi_alienresearch_0_ground",
  "refpalette": "deceasedcraft:multi_alienresearch_0/multi_alienresearch_0_ground_palette",
  "xsize": 16,
  "zsize": 16,
  "slices": [
    [
      "zzzaaaazazzazzzz",
      "zzzzaaaazzaazaaz",
      "zazaaaazazzzaaza",
      "zzzaazaazzazzzaz",
      "zzzaaaaaaazzazza",
      "zzazaaaaazaazzzz",
      "zzaaaaazaaaazbaa",
      "zazaazaazaczaazz",
      "zzzzaaaazacdazba",
      "zzaaaaaaazcdzazz",
      "zzaazaaazacdazza",
      "zzzaaaazazcdazbb",
      "zzzzaaaaazcdabab",
      "zzaaazazzacdzbzb",
      "zzzaaaaaaacdbbbz",
      "zzzaaaaaazcdzabb"
    ],
    [
      "e         e    e",
      " ee         e   ",
      "           e    ",
      " e      e  fffff",
      "e          f e  ",
      "           fe  e",
      "          gf    ",
      "          gh   e",
      "e  e      g  e  ",
      "                ",
      "e         g     ",
      "  e             ",
      "          g     ",
      " e        g e   ",
      "          g     ",
      "                "
    ],
    [
      "                ",
      "                ",
      "                ",
      "           fffff",
      "           f    ",
      "           f    ",
      "           f    ",
      "           h    ",
      "                ",
      "                ",
      "                ",
      "                ",
      "                ",
      "                ",
      "                ",
      "                "
    ],
    [
      "                ",
      "                ",
      "                ",
      "           fffff",
      "           f    ",
      "           f    ",
      "           f    ",
      "           h    ",
      "                ",
      "                ",
      "                ",
      "                ",
      "                ",
      "                ",
      "                ",
      "                "
    ],
    [
      "                ",
      "                ",
      "                ",
      "           iiiii",
      "           i    ",
      "           i    ",
      "           i    ",
      "                ",
      "                ",
      "                ",
      "                ",
      "                ",
      "                ",
      "                ",
      "                ",
      "                "
    ],
    [
      "                ",
      "                ",
      "                ",
      "                ",
      "                ",
      "                ",
      "                ",
      "           j    ",
      "                ",
      "                ",
      "                ",
      "                ",
      "                ",
      "                ",
      "                ",
      "                "
    ]
  ]
}