{
  "name": "multi_alienresearch_0_base4",
  "refpalette": "deceasedcraft:multi_alienresearch_0/multi_alienresearch_0_base4_palette",
  "xsize": 16,
  "zsize": 16,
  "slices": [
    [
      "vvvvvvvvvvvvvvvv",
      "vaaaaaaaaaaaaaaa",
      "vaaaaaaaaaaaaaaa",
      "vaaaaaaaaaaaaaaa",
      "vaaaaaaaaaaaaaab",
      "vaaaaaaaaaaaabb ",
      "vaaaaaaaaaaab   ",
      "vaaaaaaaaaab    ",
      "vaaaaaaaacb     ",
      "vaaaaaaacd      ",
      "vaaaaaaab       ",
      "vaaaaaab        ",
      "vaaaaab         ",
      "vaaaab          ",
      "vaaaab          ",
      "vaaab           "
    ],
    [
      "vvvvvvvvvvvvvvvv",
      "vaaaaaaaaaaaaaaa",
      "vaaaaaaaaaaaaaaa",
      "vaaaaaaaaaaaaaaa",
      "vaaaaaaaaaaaaaaa",
      "vaaaaaaaaaaaaabb",
      "vaaaaaaaaaaabb  ",
      "vaaaaaaaaaab    ",
      "vaaaaaaaaab     ",
      "vaaaaaaaac      ",
      "vaaaaaaab d     ",
      "vaaaaaab        ",
      "vaaaaab         ",
      "vaaaaab         ",
      "vaaaab          ",
      "vaaaab          "
    ],
    [
      "vvvvvvvvvvvvvvvv",
      "vaaaaaaaaaaaaaaa",
      "vaaaaaaaaaaaaaaa",
      "vaaaaaaaaaaaaaaa",
      "vaaaaaaaaaaaaaaa",
      "vaaaaaaaaaaaaabb",
      "vaaaaaaaaaaaab  ",
      "vaaaaaaaaaaab   ",
      "vaaaaaaaaabb    ",
      "vaaaaaaaac      ",
      "vaaaaaaab d     ",
      "vaaaaaaab       ",
      "vaaaaaab        ",
      "vaaaaab         ",
      "vaaaab          ",
      "vaaaab          "
    ],
    [
      "vvvvvvvvvvvvvvvv",
      "vaaaaaaaaaaaaaaa",
      "vaaaaaaaaaaaaaaa",
      "vaaaaaaaaaaaaaaa",
      "vaaaaaaaaaaaaaaa",
      "vaaaaaaaaaaaaaab",
      "vaaaaaaaaaaaabb ",
      "vaaaaaaaaaaab   ",
      "vaaaaaaaaaab    ",
      "vaaaaaaaaac     ",
      "vaaaaaaaacd     ",
      "vaaaaaaab       ",
      "vaaaaaab        ",
      "vaaaaab         ",
      "vaaaaab         ",
      "vaaaab          "
    ],
    [
      "vvvvvvvvvvvvvvvv",
      "vaaaaaaaaaaaaaaa",
      "vaaaaaaaaaaaaaaa",
      "vaaaaaaaaaaaaaaa",
      "vaaaaaaaaaaaaaaa",
      "vaaaaaaaaaaaaaaa",
      "vaaaaaaaaaaaaabb",
      "vaaaaaaaaaaaab  ",
      "vaaaaaaaaaabb   ",
      "vaaaaaaaaac     ",
      "vaaaaaaaacd     ",
      "vaaaaaaab       ",
      "vaaaaaaab       ",
      "vaaaaaab        ",
      "vaaaaab         ",
      "vaaaaab         "
    ],
    [
      "vvvvvvvvvvvvvvvv",
      "vaaaaaaaaaaaaaaa",
      "vaaaaaaaaaaaaaaa",
      "vaaaaaaaaaaaaaaa",
      "vaaaaaaaaaaaaaaa",
      "vaaaaaaaaaaaaaaa",
      "vaaaaaaaaaaaaaab",
      "vaaaaaaaaaaaaab ",
      "vaaaaaaaaaaabb  ",
      "vaaaaaaaaaab    ",
      "vaaaaaaaaace    ",
      "vaaaaaaaabed    ",
      "vaaaaaaab       ",
      "vaaaaaaab       ",
      "vaaaaaab        ",
      "vaaaaab         "
    ]
  ]
}