{
  "name": "multi_alienresearch_0_base7",
  "refpalette": "deceasedcraft:multi_alienresearch_0/multi_alienresearch_0_base7_palette",
  "xsize": 16,
  "zsize": 16,
  "slices": [
    [
      "vvvvvvvvvvvvvvvv",
      "vaaaaaaaaaaaaaaa",
      "vaaaaaaaaaaaaaaa",
      "vaaaaaaaaaaaaaaa",
      "vaaaaaaaaaaaaaaa",
      "vaaaaaaaaaaaaaaa",
      "vaaaaaaaaaaaaaaa",
      "vaaaaaaaaaaaaaab",
      "vaaaaaaaaaaaabbc",
      "vaaaaaaaaaaabcc ",
      "vaaaaaaaaaadc   ",
      "vaaaaaaaaadc    ",
      "vaaaaaaaabc e   ",
      "vaaaaaaabc      ",
      "vaaaaaaabc      ",
      "vaaaaaabc       "
    ],
    [
      "vvvvvvvvvvvvvvvv",
      "vaaaaaaaaaaaaaaa",
      "vaaaaaaaaaaaaaaa",
      "vaaaaaaaaaaaaaaa",
      "vaaaaaaaaaaaaaaa",
      "vaaaaaaaaaaaaaaa",
      "vaaaaaaaaaaaaaab",
      "vaaaaaaaaaaaaab ",
      "vaaaaaaaaaaabb  ",
      "vaaaaaaaaaab    ",
      "vaaaaaaaaafg    ",
      "vaaaaaaaabgc    ",
      "vaaaaaaab   h   ",
      "vaaaaaaab    c  ",
      "vaaaaaab        ",
      "vaaaaab         "
    ],
    [
      "vvvvvvvvvvvvvvvv",
      "vaaaaaaaaaaaaaaa",
      "vaaaaaaaaaaaaaaa",
      "vaaaaaaaaaaaaaaa",
      "vaaaaaaaaaaaaaaa",
      "vaaaaaaaaaaaaaaa",
      "vaaaaaaaaaaaaabb",
      "vaaaaaaaaaaaab  ",
      "vaaaaaaaaaabb   ",
      "vaaaaiaaaaf     ",
      "vaaaaaaaafc     ",
      "vaaaaaaab       ",
      "vaaaaaaab       ",
      "vaaaaaab     h  ",
      "vaaaaab       c ",
      "vaaaaab        e"
    ],
    [
      "vvvvvvvvvvvvvvvv",
      "vaaaaaaaaaaaaaaa",
      "vaaaaaaaaaaaaaaa",
      "vaaaaaaaaaaaaaaa",
      "vaaaaaaaaaaaaaaa",
      "vaaaaaaaaaaaaaab",
      "vaaaaaaaaaaaabb ",
      "vaaaaaaaaaaab   ",
      "vaaaaaaaaaab    ",
      "vaaaaaaaaaf     ",
      "vaaaaaaaafc     ",
      "vaaaaaaab       ",
      "vaaaaaab        ",
      "vaaaaab         ",
      "vaaaaab         ",
      "vaaaab         c"
    ],
    [
      "vvvvvvvvvvvvvvvv",
      "vaaaaaaaaaaaaaaa",
      "vaaaaaaaaaaaaaaa",
      "vaaaaaaaaaaaaaaa",
      "vaaaaaaaaaaaaaaa",
      "vaaaaaaaaaaaaabb",
      "vaaaaaaaaaaaab  ",
      "vaaaaaaaaaaab   ",
      "vaaaaaaaaabb    ",
      "vaaaaaaaaf      ",
      "vaaaaaaab c     ",
      "vaaaaaaab       ",
      "vaaaaaab        ",
      "vaaaaab         ",
      "vaaaab          ",
      "vaaaab          "
    ],
    [
      "vvvvvvvvvvvvvvvv",
      "vaaaaaaaaaaaaaaa",
      "vaaaaaaaaaaaaaaa",
      "vaaaaaaaaaaaaaaa",
      "vaaaaaaaaaaaaaaa",
      "vaaaaaaaaaaaaabb",
      "vaaaaaaaaaaabb  ",
      "vaaaaaaaaaab    ",
      "vaaaaaaaaab     ",
      "vaaaaaaaaf      ",
      "vaaaaaaab c     ",
      "vaaaaaab        ",
      "vaaaaab         ",
      "vaaaaab         ",
      "vaaaab          ",
      "vaaaab          "
    ]
  ]
}