{
  "name": "multi_alienresearch_0_base3",
  "refpalette": "deceasedcraft:multi_alienresearch_0/multi_alienresearch_0_base3_palette",
  "xsize": 16,
  "zsize": 16,
  "slices": [
    [
      "vvvvvvvvvvvvvvvv",
      "vaaaaaaaaaaaaaaa",
      "vaaaaaaaaaaaaaaa",
      "vaaaaaaaaaaaaaaa",
      "vaaaaaaaaaaaaaaa",
      "vaaaaaaaaaaaaaaa",
      "vaaaaaaaaaaaaaaa",
      "vaaaaaaaaaaaaaab",
      "vaaaaaaaaaaaabbc",
      "vaaaaaaaaaaabccd",
      "vaaaaaaaaaaecddd",
      "vaaaaaaaaaecdddd",
      "vaaaaaaaabcddddd",
      "vaaaaaaabcdddddd",
      "vaaaaaaabcdddddf",
      "vaaaaaabcdddddff"
    ],
    [
      "vvvvvvvvvvvvvvvv",
      "vaaaaaaaaaaaaaaa",
      "vaaaaaaaaaaaaaaa",
      "vaaaaaaaaaaaaaaa",
      "vaaaaaaaaaaaaaaa",
      "vaaaaaaaaaaaaaaa",
      "vaaaaaaaaaaaaaaa",
      "vaaaaaaaaaaaaaaa",
      "vaaaaaaaaaaaaabb",
      "vaaaaaaaaaaaabgh",
      "vaaaaaaaaaaab   ",
      "vaaaaaaaaaaf    ",
      "vaaaaaaaaab c   ",
      "vaaaaaaaab      ",
      "vaaaaaaabi    jk",
      "vaaaaaaab     k "
    ],
    [
      "vvvvvvvvvvvvvvvv",
      "vaaaaaaaaaaaaaaa",
      "vaaaaaaaaaaaaaaa",
      "vaaaaaaaaaaaaaaa",
      "vaaaaaaaaaaaaaaa",
      "vaaaaaaaaaaaaaaa",
      "vaaaaaaaaaaaaaaa",
      "vaaaaaaaaaaaaaaa",
      "vaaaaaaaaaaaaaab",
      "vaaaaaaaaaaaaab ",
      "vaaaaaaaaaaabb  ",
      "vaaaaaaaaaaf    ",
      "vaaaaaaaaab c   ",
      "vaaaaaaaaab     ",
      "vaaaaaaaab    lk",
      "vaaaaaaab     k "
    ],
    [
      "vvvvvvvvvvvvvvvv",
      "vaaaaaaaaaaaaaaa",
      "vaaaaaaaaaaaaaaa",
      "vaaaaaaaaaaaaaaa",
      "vaaaaaaaaaaaaaaa",
      "vaaaaaaaaaaaaaaa",
      "vaaaaaaaaaaaaaaa",
      "vaaaaaaaaaaaaaaa",
      "vaaaaaaaaaaaaaaa",
      "vaaaaaaaaaaaaaab",
      "vaaaaaaaaaaaaab ",
      "vaaaaaaaaaaafb  ",
      "vaaaaaaaaaafc   ",
      "vaaaaaaaaaab    ",
      "vaaaaaaaaab    k",
      "vaaaaaaaab    k "
    ],
    [
      "vvvvvvvvvvvvvvvv",
      "vaaaaaaaaaaaaaaa",
      "vaaaaaaaaaaaaaaa",
      "vaaaaaaaaaaaaaaa",
      "vaaaaaaaaaaaaaaa",
      "vaaaaaaaaaaaaaaa",
      "vaaaaaaaaaaaaaaa",
      "vaaaaaaaaaaaaaaa",
      "vaaaaaaaaaaaaaaa",
      "vaaaaaaaaaaaaaaa",
      "vaaaaaaaaaaaaaab",
      "vaaaaaaaaaaaaab ",
      "vaaaaaaaaaaaff  ",
      "vaaaaaaaaaaafc  ",
      "vaaaaaaaaaab   k",
      "vaaaaaaaaab   k "
    ],
    [
      "vvvvvvvvvvvvvvvv",
      "vaaaaaaaaaaaaaaa",
      "vaaaaaaaaaaaaaaa",
      "vaaaaaaaaaaaaaaa",
      "vaaaaaaaaaaaaaaa",
      "vaaaaaaaaaaaaaaa",
      "vaaaaaaaaaaaaaaa",
      "vaaaaaaaaaaaaaaa",
      "vaaaaaaaaaaaaaaa",
      "vaaaaaaaaaaaaaaa",
      "vaaaaaaaaaaaaaaa",
      "vaaaaaaaaaaaaaab",
      "vaaaaaaaaaaaaab ",
      "vaaaaaaaaaaaaf  ",
      "vaaaaaaaaaaab cm",
      "vaaaaaaaaaab  m "
    ]
  ]
}