{
  "name": "multi_alienresearch_0_base6",
  "refpalette": "deceasedcraft:multi_alienresearch_0/multi_alienresearch_0_base6_palette",
  "xsize": 16,
  "zsize": 16,
  "slices": [
    [
      "vvvvvvvvvvvvvvvv",
      "vaaaaaaaaaaaaaaa",
      "vaaaaaaaaaaaaaaa",
      "vaaaaaaaaaaaaaaa",
      "vaaaaaaaaaaaaaab",
      "vaaaaaaaaaaaabb ",
      "vaaaaaaaaaaab   ",
      "vaaaaaaaaaab    ",
      "vaaaaaaaacb     ",
      "vaaaaaaacd      ",
      "vaaaaaaab       ",
      "vaaaaaab        ",
      "vaaaaab         ",
      "vaaaab          ",
      "vaaaab          ",
      "vaaab           "
    ],
    [
      "vvvvvvvvvvvvvvvv",
      "vaaaaaaaaaaaaaaa",
      "vaaaaaaaaaaaaaaa",
      "vaaaaaaaaaaaaaaa",
      "vaaaaaaaaaaaaaab",
      "vaaaaaaaaaaaabb ",
      "vaaaaaaaaaabb   ",
      "vaaaaaaaaab     ",
      "vaaaaaaaac      ",
      "vaaaaaaacd      ",
      "vaaaaaab        ",
      "vaaaaab         ",
      "vaaaaab         ",
      "vaaaab          ",
      "vaaaab          ",
      "vaaab           "
    ],
    [
      "vvvvvvvvvvvvvvvv",
      "vaaaaaaaaaaaaaaa",
      "vaaaaaaaaaaaaaaa",
      "vaaaaaaaaaaaaaaa",
      "vaaaaaaaaaaaaabb",
      "vaaaaaaaaaaaab  ",
      "vaaaaaaaaaabb   ",
      "vaaaaaaaaab     ",
      "vaaaaaaaac      ",
      "vaaaaaaacd      ",
      "vaaaaaab        ",
      "vaaaaab         ",
      "vaaaaab         ",
      "vaaaab          ",
      "vaaab           ",
      "vaaab           "
    ],
    [
      "vvvvvvvvvvvvvvvv",
      "vaaaaaaaaaaaaaaa",
      "vaaaaaaaaaaaaaaa",
      "vaaaaaaaaaaaaaaa",
      "vaaaaaaaaaaaaabb",
      "vaaaaaaaaaaabb  ",
      "vaaaaaaaaaab    ",
      "vaaaaaaaaab     ",
      "vaaaaaaaac      ",
      "vaaaaaaacd      ",
      "vaaaaaab        ",
      "vaaaaab         ",
      "vaaaab          ",
      "vaaaab          ",
      "vaaab           ",
      "vaaab           "
    ],
    [
      "vvvvvvvvvvvvvvvv",
      "vaaaaaaaaaaaaaaa",
      "vaaaaaaaaaaaaaaa",
      "vaaaaaaaaaaaaaaa",
      "vaaaaaaaaaaaaabb",
      "vaaaaaaaaaaabb  ",
      "vaaaaaaaaaab    ",
      "vaaaaaaaaab     ",
      "vaaaaaaaac      ",
      "vaaaaaaacd      ",
      "vaaaaaab        ",
      "vaaaaab         ",
      "vaaaab          ",
      "vaaaab          ",
      "vaaab           ",
      "vaaab           "
    ],
    [
      "vvvvvvvvvvvvvvvv",
      "vaaaaaaaaaaaaaaa",
      "vaaaaaaaaaaaaaaa",
      "vaaaaaaaaaaaaaaa",
      "vaaaaaaaaaaaaacc",
      "vaaaaaaaaaaacc  ",
      "vaaaaaaaaaac    ",
      "vaaaaaaaaac     ",
      "vaaaaaaacc      ",
      "vaaaaaaacd      ",
      "vaaaaaac        ",
      "vaaaaac         ",
      "vaaaac          ",
      "vaaaac          ",
      "vaaac          e",
      "vaaac         ef"
    ]
  ]
}