{
  "name": "multi_alienresearch_0_base5",
  "refpalette": "deceasedcraft:multi_alienresearch_0/multi_alienresearch_0_base5_palette",
  "xsize": 16,
  "zsize": 16,
  "slices": [
    [
      "vvvvvvvvvvvvvvvv",
      "vaaaaaaaaaaaaaaa",
      "vaaaaaaaaaaaaaaa",
      "vaaaaaaaaaaaaaaa",
      "vaaaaaaaaaaaaabb",
      "vaaaaaaaaaaabbcc",
      "vaaaaaaaaaabcc  ",
      "vaaaaaaaaabc    ",
      "vaaaaaaabdc     ",
      "vaaaaaaadc      ",
      "vaaaaaabc       ",
      "vaaaaabc        ",
      "vaaaabc         ",
      "vaaaabc        e",
      "vaaabc        ff",
      "vaaabc       eff"
    ],
    [
      "vvvvvvvvvvvvvvvv",
      "vaaaaaaaaaaaaaaa",
      "vaaaaaaaaaaaaaaa",
      "vaaaaaaaaaaaaaaa",
      "vaaaaaaaaaaaaabb",
      "vaaaaaaaaaaabb  ",
      "vaaaaaaaaaab    ",
      "vaaaaaaaaab     ",
      "vaaaaaaabb      ",
      "vaaaaaaabc      ",
      "vaaaaaab        ",
      "vaaaaab         ",
      "vaaaab          ",
      "vaaaab          ",
      "vaaab           ",
      "vaaab          g"
    ],
    [
      "vvvvvvvvvvvvvvvv",
      "vaaaaaaaaaaaaaaa",
      "vaaaaaaaaaaaaaaa",
      "vaaaaaaaaaaaaaaa",
      "vaaaaaaaaaaaaahh",
      "vaaaaaaaaaaahh  ",
      "vaaaaaaaaaah    ",
      "vaaaaaaaaah     ",
      "vaaaaaaaab      ",
      "vaaaaaaabc      ",
      "vaaaaaah        ",
      "vaaaaah         ",
      "vaaaah          ",
      "vaaaah          ",
      "vaaah           ",
      "vaaah           "
    ],
    [
      "vvvvvvvvvvvvvvvv",
      "vaaaaaaaaaaaaaaa",
      "vaaaaaaaaaaaaaaa",
      "vaaaaaaaaaaaaaaa",
      "vaaaaaaaaaaaaahh",
      "vaaaaaaaaaaahh  ",
      "vaaaaaaaaaah    ",
      "vaaaaaaaaah     ",
      "vaaaaaaaab      ",
      "vaaaaaaabc      ",
      "vaaaaaah        ",
      "vaaaaah         ",
      "vaaaah          ",
      "vaaaah          ",
      "vaaah           ",
      "vaaah           "
    ],
    [
      "vvvvvvvvvvvvvvvv",
      "vaaaaaaaaaaaaaaa",
      "vaaaaaaaaaaaaaaa",
      "vaaaaaaaaaaaaaaa",
      "vaaaaaaaaaaaaahh",
      "vaaaaaaaaaaaah  ",
      "vaaaaaaaaaahh   ",
      "vaaaaaaaaah     ",
      "vaaaaaaaab      ",
      "vaaaaaaabc      ",
      "vaaaaaah        ",
      "vaaaaah         ",
      "vaaaaah         ",
      "vaaaah          ",
      "vaaah           ",
      "vaaah           "
    ],
    [
      "vvvvvvvvvvvvvvvv",
      "vaaaaaaaaaaaaaaa",
      "vaaaaaaaaaaaaaaa",
      "vaaaaaaaaaaaaaaa",
      "vaaaaaaaaaaaaaah",
      "vaaaaaaaaaaaahh ",
      "vaaaaaaaaaahh   ",
      "vaaaaaaaaah     ",
      "vaaaaaaaab      ",
      "vaaaaaaabc      ",
      "vaaaaaah        ",
      "vaaaaah         ",
      "vaaaaah         ",
      "vaaaah          ",
      "vaaaah          ",
      "vaaah           "
    ]
  ]
}