{
  "name": "multi_apartmentmedium_1_floor3",
  "refpalette": "deceasedcraft:multi_apartmentmedium_1/multi_apartmentmedium_1_floor3_palette",
  "xsize": 16,
  "zsize": 16,
  "slices": [
    [
      "   a    a       ",
      "   a    a       ",
      "  ba    ac   b  ",
      "  bddedddddddb  ",
      "  f     dg  hf  ",
      "  i     e    i  ",
      "  i     deeddi  ",
      "  i     d    i  ",
      "  i     d    i  ",
      "  i     d    i  ",
      "  f     e    f  ",
      "  bj    d    b  ",
      "  bbfiffkfifbb  ",
      "                ",
      "                ",
      "                "
    ],
    [
      "   l   ma       ",
      "   n    a       ",
      "  ba    ao   b  ",
      "  bddddddddddb  ",
      "  b     dppppb  ",
      "  b     dppppb  ",
      "  b  q  dddddb  ",
      "  b     d    b  ",
      "  b     d    b  ",
      "  b  r  d    b  ",
      "  b     d    b  ",
      "  b     d    b  ",
      "  bbbbbbbbbbbb  ",
      "                ",
      "                ",
      "                "
    ],
    [
      "   a  sta       ",
      "   au  ma       ",
      "  bauuuuao   b  ",
      "  bddddddddddb  ",
      "  wxxxxxd    y  ",
      "  wxxxxxd    y  ",
      "  wxxxxxdddddy  ",
      "  wxxxxxdxxxxy  ",
      "  wxxxxxdxxxxy  ",
      "  wxxxxxdxxxxy  ",
      "  wxxxxxdxxxxy  ",
      "  bxxxxxdxxxxb  ",
      "  bbAAAAAAAAbb  ",
      "                ",
      "                ",
      "                "
    ],
    [
      "   aB C a       ",
      "   aDDDta       ",
      "  baDDDDao   b  ",
      "  bddDdddddddb  ",
      "  wEEEEEEDDDDy  ",
      "  wEEEEEEDDDDy  ",
      "  wEEEEEEDEEEy  ",
      "  wEEEEEEEEEEy  ",
      "  wEEEEEEEEEEy  ",
      "  wEEEEEEEEEEy  ",
      "  wEEEEEEEEEEy  ",
      "  bEEEEEEEEEEb  ",
      "  bbAAAAAAAAbb  ",
      "                ",
      "                ",
      "                "
    ],
    [
      "   aFI  l       ",
      "   a JJ l       ",
      "  ba    aK   b  ",
      "  bddLdddddddb  ",
      "  bM   NdOPQ b  ",
      "  bR    S    b  ",
      "  bT UU dVWddb  ",
      "  bXYZZ d   0b  ",
      "  b1234 d  56b  ",
      "  b     d  56b  ",
      "  b     7 8 0b  ",
      "  b9#$$%d^&*9b  ",
      "  bbbbbbbbbbbb  ",
      "                ",
      "                ",
      "                "
    ],
    [
      "   a (  a)      ",
      "   a    a)      ",
      "  ba  + a-   b  ",
      "  bdd[dddddddb  ",
      "  f    ]d  Q{f  ",
      "  i     }    i  ",
      "  i     d|Wddi  ",
      "  i ;   d  : i  ",
      "  i     d    i  ",
      "  i     d    i  ",
      "  f     '    f  ",
      "  bj <  d   >b  ",
      "  bbfiffkfifbb  ",
      "                ",
      "                ",
      "                "
    ]
  ]
}