{
  "name": "multi_apartmentmedium_1_ground",
  "refpalette": "deceasedcraft:multi_apartmentmedium_1/multi_apartmentmedium_1_ground_palette",
  "xsize": 16,
  "zsize": 16,
  "slices": [
    [
      "abbcddddcbbbbbba",
      "abbcddddcbbbbbba",
      "abecddddcbbbbeba",
      "abefffffffbbfeba",
      "abeggggggggggeba",
      "abeggggggggggeba",
      "abeggggggggggeba",
      "abeggggggggggeba",
      "abeggggggggggeba",
      "abeggggggggggeba",
      "abeggggggggggeba",
      "abeggggggggggeba",
      "abeebbbbbbbbeeba",
      "abbbbbbbbbbbbbba",
      "aaaaaaaaaaaaaaaa",
      "aaaaaaaaaaaaaaaa"
    ],
    [
      "   ch   c       ",
      "   cdiijc       ",
      "  ecddddck   e  ",
      "  efffffff  fe  ",
      "  elmmmmmn  oe  ",
      "  e     pn  qe  ",
      "  erssssst  qe  ",
      "  e         ue  ",
      "  ew  x  y  qe  ",
      "  eA  B  B  oe  ",
      "  eC  D  x  qe  ",
      "  eC   EF   qe  ",
      "  eeIJK  KJIee  ",
      "                ",
      "                ",
      "                "
    ],
    [
      "   c    c       ",
      "   cdLM c       ",
      "  ecdddNcO   e  ",
      "  efffffff  fe  ",
      "  IPQRQ!RS   I  ",
      "  J          J  ",
      "  J   T  U   J  ",
      "  J          J  ",
      "  J   D  D   J  ",
      "  J   x  x   J  ",
      "  I   B  y  VI  ",
      "  e    WX    e  ",
      "  eeIJK  KJIee  ",
      "                ",
      "                ",
      "                "
    ],
    [
      "   cY   c       ",
      "   cZ0  c       ",
      "  ecN11 cO   e  ",
      "  efffffff  fe  ",
      "  I2QQRRQ3   I  ",
      "  J          J  ",
      "  J          J  ",
      "  J          J  ",
      "  J          J  ",
      "  J          J  ",
      "  I          I  ",
      "  e          e  ",
      "  eeIJK44KJIee  ",
      "                ",
      "                ",
      "                "
    ],
    [
      "   cZ0  5       ",
      "   c 6  5       ",
      "  ec    c7   e  ",
      "  effffffffffe  ",
      "  I          I  ",
      "  J          J  ",
      "  J          J  ",
      "  J          J  ",
      "  J          J  ",
      "  J          J  ",
      "  I          I  ",
      "  e          e  ",
      "  eeIJKKKKJIee  ",
      "                ",
      "                ",
      "                "
    ],
    [
      "   c 6  c8      ",
      "   c    c8      ",
      "  ec    c9   e  ",
      "  effffffffffe  ",
      "  I          I  ",
      "  J          J  ",
      "  J          J  ",
      "  J          J  ",
      "  J          J  ",
      "  J          J  ",
      "  I          I  ",
      "  e          e  ",
      "  eeIJJJJJJIee  ",
      "                ",
      "                ",
      "                "
    ]
  ]
}