{
  "name": "multi_apartmentmedium_1_floor1",
  "refpalette": "deceasedcraft:multi_apartmentmedium_1/multi_apartmentmedium_1_floor1_palette",
  "xsize": 16,
  "zsize": 16,
  "slices": [
    [
      "   a    a       ",
      "   a    a       ",
      "  ba    ac   b  ",
      "  bddddddddddb  ",
      "  e          e  ",
      "  f          f  ",
      "  f          f  ",
      "  f          f  ",
      "  f          f  ",
      "  f          f  ",
      "  e          e  ",
      "  b          b  ",
      "  bbeffffffebb  ",
      "                ",
      "                ",
      "                "
    ],
    [
      "   g   ha       ",
      "   i    a       ",
      "  ba    aj   b  ",
      "  bddddddddddb  ",
      "  b          b  ",
      "  b          b  ",
      "  b          b  ",
      "  b          b  ",
      "  b          b  ",
      "  b          b  ",
      "  b          b  ",
      "  b          b  ",
      "  bbbbbbbbbbbb  ",
      "                ",
      "                ",
      "                "
    ],
    [
      "   a  kla       ",
      "   am  ha       ",
      "  bammmmaj   b  ",
      "  bddddddddddb  ",
      "  noooooooooop  ",
      "  noooooooooop  ",
      "  noooooooooop  ",
      "  noooooooooop  ",
      "  noooooooooop  ",
      "  noooooooooop  ",
      "  noooooooooop  ",
      "  boooooooooob  ",
      "  bbqqqqqqqqbb  ",
      "                ",
      "                ",
      "                "
    ],
    [
      "   ar s a       ",
      "   atttla       ",
      "  battttaj   b  ",
      "  bddtdddddddb  ",
      "  nuuuuuuttttp  ",
      "  nuuuuuuttttp  ",
      "  nuuuuuutuuup  ",
      "  nuuuuuuuuuup  ",
      "  nuuuuuuuuuup  ",
      "  nuuuuuuuuuup  ",
      "  nuuuuuuuuuup  ",
      "  buuuuuuuuuub  ",
      "  bbqqqqqqqqbb  ",
      "                ",
      "                ",
      "                "
    ],
    [
      "   awx  g       ",
      "   a yy g       ",
      "  ba    aA   b  ",
      "  bddBdddddddb  ",
      "  bC   DdEFI b  ",
      "  bJ    K    b  ",
      "  bL MM dNOddb  ",
      "  bPQRR d   Sb  ",
      "  bTUVW d  XYb  ",
      "  b     d  XYb  ",
      "  b     Z 0 Sb  ",
      "  b12334d5671b  ",
      "  bbbbbbbbbbbb  ",
      "                ",
      "                ",
      "                "
    ],
    [
      "   a 8  a9      ",
      "   a    a9      ",
      "  ba  # a$   b  ",
      "  bdd%dddddddb  ",
      "  e    ^d  I&e  ",
      "  f     *    f  ",
      "  f    (d)Oddf  ",
      "  f +   d  - f  ",
      "  f     d    f  ",
      "  f    (d    f  ",
      "  e     [    e  ",
      "  b] {  d   }b  ",
      "  bbefee|efebb  ",
      "                ",
      "                ",
      "                "
    ]
  ]
}