{
  "name": "multi_apartmentmedium_1_top",
  "refpalette": "deceasedcraft:multi_apartmentmedium_1/multi_apartmentmedium_1_top_palette",
  "xsize": 16,
  "zsize": 16,
  "slices": [
    [
      "   a    a       ",
      "   a    a       ",
      "  ba    ac   b  ",
      "  bddedddddddb  ",
      "  f     dg  hf  ",
      "  i     e    i  ",
      "  i     deeddi  ",
      "  i     d    i  ",
      "  i     d    i  ",
      "  i     d    i  ",
      "  f     e    f  ",
      "  bj    d    b  ",
      "  bbfiffkfifbb  ",
      "                ",
      "                ",
      "                "
    ],
    [
      "   l   ma       ",
      "   n    a       ",
      "  ba    ao   b  ",
      "  bddddddddddb  ",
      "  b     dppppb  ",
      "  b     dppppb  ",
      "  b  q  dddddb  ",
      "  b     d    b  ",
      "  b     d    b  ",
      "  b  r  d    b  ",
      "  b     d    b  ",
      "  b     d    b  ",
      "  bbbbbbbbbbbb  ",
      "                ",
      "                ",
      "                "
    ],
    [
      "   a  sta       ",
      "   a   ma       ",
      "  bauuuuao   b  ",
      "  bddddddddddb  ",
      "  wxxxxxd    y  ",
      "  wxxxxxd    y  ",
      "  wxxxxxdddddy  ",
      "  wxxxxxdxxxxy  ",
      "  wxxxxxdxxxxy  ",
      "  wxxxxxdxxxxy  ",
      "  wxxxxxdxxxxy  ",
      "  bxxxxxdxxxxb  ",
      "  bbAAAAAAAAbb  ",
      "                ",
      "                ",
      "                "
    ],
    [
      "   a  B a       ",
      "   aCCCta       ",
      "  baCCCCao   b  ",
      "  bddCdddddddb  ",
      "  wtttttttttty  ",
      "  wCCCCCCCCCCy  ",
      "  wCCCCCCCCCCy  ",
      "  wCCCCCCCCCCy  ",
      "  wCCCCCCCCCCy  ",
      "  wCCCCCCCCCCy  ",
      "  wCCCCCCCCCCy  ",
      "  bCCCCCCCCCCb  ",
      "  bbAAAAAAAAbb  ",
      "                ",
      "                ",
      "                "
    ],
    [
      "   a    l       ",
      "   aDDD l       ",
      "  ba    aE   b  ",
      "  bdd dddddddb  ",
      "  b          b  ",
      "  b          b  ",
      "  b          b  ",
      "  b          b  ",
      "  b          b  ",
      "  b          b  ",
      "  b          b  ",
      "  b          b  ",
      "  bbbbbbbbbbbb  ",
      "                ",
      "                ",
      "                "
    ],
    [
      "   a    aF      ",
      "   a    aF      ",
      "  ba  I aJ   b  ",
      "  bdd dddddddb  ",
      "  K          K  ",
      "  K          K  ",
      "  K          K  ",
      "  K          K  ",
      "  K          K  ",
      "  K          K  ",
      "  K          K  ",
      "  b          b  ",
      "  bbKKKKKKKKbb  ",
      "                ",
      "                ",
      "                "
    ],
    [
      "   llllll       ",
      "   llllll       ",
      "  bllllll    b  ",
      "  bddddddddddb  ",
      "  b          b  ",
      "  b          b  ",
      "  b          b  ",
      "  b          b  ",
      "  b          b  ",
      "  b          b  ",
      "  b          b  ",
      "  b          b  ",
      "  bbbbbbbbbbbb  ",
      "                ",
      "                ",
      "                "
    ],
    [
      "                ",
      "                ",
      "  L          L  ",
      "  L          L  ",
      "  L          L  ",
      "  L          L  ",
      "  L          L  ",
      "  L          L  ",
      "  L          L  ",
      "  L          L  ",
      "  L          L  ",
      "  L          L  ",
      "  LLLLLLLLLLLL  ",
      "                ",
      "                ",
      "                "
    ]
  ]
}