{
  "name": "multi_nuclearpowerplant_37_base8",
  "refpalette": "deceasedcraft:multi_nuclearpowerplant_37/multi_nuclearpowerplant_37_base8_palette",
  "xsize": 16,
  "zsize": 16,
  "slices": [
    [
      "                ",
      "                ",
      "                ",
      "                ",
      "                ",
      "                ",
      "                ",
      "           a a  ",
      "    a       b   ",
      "           a a  ",
      "                ",
      "                ",
      "                ",
      "                ",
      "                ",
      "                "
    ],
    [
      "cccccccccccccccc",
      "cccccccccccccccc",
      "cccccccccccccccc",
      "cccccccccccccccc",
      "cccccccccccccccc",
      "cccccccccccccccc",
      "cccccccccccccccc",
      "cccccccccccccccc",
      "ccccccccccccdccc",
      "cccccccccccccccc",
      "cccccccccccccccc",
      "cccccccccccccccc",
      "cccccccccccccccc",
      "cccccccccccccccc",
      "cccccccccccccccc",
      "cccccccccccccccc"
    ],
    [
      "eeeeeeeeeeefgfee",
      "eeeeeeeeeeefgfee",
      "eeeeeeeeeeefgfee",
      "eeeeeeeeeeefgfee",
      "eeeeeeeeeeefgfee",
      "eeeeeeeeeeefgfee",
      "eeeeeeeeeeefgfee",
      "eeeeeeeeeeefhfee",
      "eeeeeeeeeeefifee",
      "eeeeeeeeeeefhfee",
      "eeeeeeeeeeefgfee",
      "eeeeeeeeeeefgfee",
      "eeeeeeeeeeefgfee",
      "eeeeeeeeeeefgfee",
      "eeeeeeeeeeefgfee",
      "eeeeeeeeeeefgfee"
    ],
    [
      "eeeeeeeeeeeefeee",
      "eeeeeeeeeeeefeee",
      "eeeeeeeeeeeefeee",
      "eeeeeeeeeeeefeee",
      "eeeeeeeeeeeefeee",
      "eeeeeeeeeeeefeee",
      "eeeeeeeeeeeefeee",
      "eeeeeeeeeeeefeee",
      "eeeeeeeeeeeefeee",
      "eeeeeeeeeeeefeee",
      "eeeeeeeeeeeefeee",
      "eeeeeeeeeeeefeee",
      "eeeeeeeeeeeefeee",
      "eeeeeeeeeeeefeee",
      "eeeeeeeeeeeefeee",
      "eeeeeeeeeeeefeee"
    ],
    [
      "jjjjk===========",
      "jjjjjk==========",
      "jjjjjjk=========",
      "jjjjjjjk========",
      "jjjjjjjjk=======",
      "jjjjjjjjjk======",
      "jjjjjjjjjjk=====",
      "jjjjjjjjjjjk====",
      "jjjjjjjjjjjjkk==",
      "jjjjjjjjjjjjjjkk",
      "jjjjjjjjjjjjjjjj",
      "lllllllljjjjjjll",
      "mnmmmmnljjjjjjlo",
      "======pljjjjjjlo",
      "======pljjjjjjlo",
      "======pljjjjjjlo"
    ],
    [
      "    =nnnnnnnnnnn",
      "     =nnnnnnnnnn",
      "      =nnnnnnnnn",
      "       =nnnnnnnn",
      "        =nnnnnnn",
      "         =nnnnnn",
      "         q=nnnnn",
      "           =nnnn",
      "            ==nn",
      "              ==",
      "          r     ",
      "      s         ",
      " atttta         ",
      "      t         ",
      "   aa t         ",
      "   aa t         "
    ]
  ]
}