{
  "name": "multi_nuclearpowerplant_37_base1",
  "refpalette": "deceasedcraft:multi_nuclearpowerplant_37/multi_nuclearpowerplant_37_base1_palette",
  "xsize": 16,
  "zsize": 16,
  "slices": [
    [
      "aaabcccc========",
      "aaabccccc=======",
      "aaaabccccc======",
      "aaaabcccccc=====",
      "aaaabccccccc====",
      "aaaaabccccccc===",
      "aaaaabccccccccc=",
      "aaaaaabccccccccc",
      "aaaaaabddddddddd",
      "aaaaaabddefgfehi",
      "aaaaaabdd jkjjll",
      "aaaaaaaddmmmmmmm",
      "aaaaaaadd    n  ",
      "aaaaaaadd  opq  ",
      "aaaaaaadd  rsst ",
      "aaaaaaadd   u   "
    ],
    [
      "aaabcccccccccccc",
      "aaabcccccccccccc",
      "aaaabccccccccccc",
      "aaaabccccccccccc",
      "aaaabccccccccccc",
      "aaaaabcccccccccc",
      "aaaaabcccccccccc",
      "aaaaaabccccccccc",
      "aaaaaabddddddddd",
      "aaaaaabddewxweyA",
      "aaaaaabdd  BCD E",
      "aaaaaaadd       ",
      "aaaaaaaddF      ",
      "aaaaaaadd       ",
      "aaaaaaaddI  J K ",
      "aaaaaaadd       "
    ],
    [
      "aaabcccccccccccc",
      "aaabcccccccccccc",
      "aaaabccccccccccc",
      "aaaabccccccccccc",
      "aaaabccccccccccc",
      "aaaaabcccccccccc",
      "aaaaabcccccccccc",
      "aaaaaabccccccccc",
      "aaaaaabddddddddd",
      "aaaaaabddeLkgeMA",
      "aaaaaabddN   O P",
      "aaaaaaadd       ",
      "aaaaaaaddF      ",
      "aaaaaaadd       ",
      "aaaaaaadd       ",
      "aaaaaaadd       "
    ],
    [
      "aaabcccccccccccc",
      "aaabcccccccccccc",
      "aaaabccccccccccc",
      "aaaabccccccccccc",
      "aaaabccccccccccc",
      "aaaaabcccccccccc",
      "aaaaabcccccccccc",
      "aaaaaabccccccccc",
      "aaaaaabddddddddd",
      "aaaaaabddeeeeeee",
      "aaaaaabddQQQQQQQ",
      "aaaaaaadd       ",
      "aaaaaaadd       ",
      "aaaaaaadd       ",
      "aaaaaaadd       ",
      "aaaaaaadd       "
    ],
    [
      "aaabcccccccccccc",
      "aaabcccccccccccc",
      "aaaabccccccccccc",
      "aaaabccccccccccc",
      "aaaabccccccccccc",
      "aaaaabcccccccccc",
      "aaaaabcccccccccc",
      "aaaaaabccccccccc",
      "aaaaaabddddddddd",
      "aaaaaabddRRRRRRR",
      "aaaaaabddSSSSSSS",
      "aaaaaaadd       ",
      "aaaaaaadd       ",
      "aaaaaaadd       ",
      "aaaaaaadd       ",
      "aaaaaaadd       "
    ],
    [
      "aaabcccTT TTcccc",
      "aaabccccTkcTcccc",
      "aaaabccccccccccc",
      "aaaabccccccccccc",
      "aaaabccccccccccc",
      "aaaaabcccccccccc",
      "aaaaabcccccccccc",
      "aaaaaabccccccccc",
      "aaaaaabddddddddd",
      "aaaaaabddUVVVVVV",
      "baaaaabddWWWWWWW",
      "baaaaaaddWWWWWWW",
      "baaaaaaddWWXWWXW",
      "baaaaaaddWWXWWXW",
      "baaaaaaddWWXWWXW",
      "baaaaaaddWWXWWXW"
    ]
  ]
}