{
  "name": "multi_nuclearpowerplant_37_base5",
  "refpalette": "deceasedcraft:multi_nuclearpowerplant_37/multi_nuclearpowerplant_37_base5_palette",
  "xsize": 16,
  "zsize": 16,
  "slices": [
    [
      "    =a      bb  ",
      "     =a      bb ",
      "      =a      bb",
      "       =a      b",
      "        =a      ",
      "         =a     ",
      "          =a    ",
      "           =aa  ",
      "            ==aa",
      "              ==",
      "                ",
      "                ",
      " c              ",
      "dc              ",
      "ec              ",
      "fc              "
    ],
    [
      "    =a      bb  ",
      "     =a      bb ",
      "      =a      bb",
      "       =a      b",
      "        =a      ",
      "         =a     ",
      "          =a    ",
      "           =aa  ",
      "            ==aa",
      "              ==",
      "                ",
      "                ",
      "                ",
      "                ",
      "g               ",
      "                "
    ],
    [
      "    =a      bb  ",
      "     =a      bb ",
      "      =a      bb",
      "       =a      b",
      "        =a      ",
      "         =a     ",
      "          =a    ",
      "           =aa  ",
      "            ==aa",
      "              ==",
      "                ",
      "                ",
      "                ",
      "                ",
      "                ",
      "                "
    ],
    [
      "    =a      bb  ",
      "     =a      bb ",
      "      =a      bb",
      "       =a      b",
      "        =a      ",
      "         =a     ",
      "          =a    ",
      "           =aa  ",
      "            ==aa",
      "              ==",
      "                ",
      "                ",
      "                ",
      "                ",
      "                ",
      "                "
    ],
    [
      "    =a      bb  ",
      "     =a      bb ",
      "      =a      bb",
      "       =a      b",
      "        =a      ",
      "         =a     ",
      "          =a    ",
      "           =aa  ",
      "            ==aa",
      "              ==",
      "                ",
      "                ",
      "                ",
      "                ",
      "                ",
      "                "
    ],
    [
      "    =a      bb  ",
      "     =a      bb ",
      "      =a      bb",
      "       =a      b",
      "        =a      ",
      "         =a     ",
      "          =a    ",
      "           =aa  ",
      "            ==aa",
      "              ==",
      "                ",
      "                ",
      "                ",
      "                ",
      "                ",
      "                "
    ]
  ]
}