{
  "name": "multi_nuclearpowerplant_37_ground",
  "refpalette": "deceasedcraft:multi_nuclearpowerplant_37/multi_nuclearpowerplant_37_ground_palette",
  "xsize": 16,
  "zsize": 16,
  "slices": [
    [
      "aaabccc      dde",
      "baabccc    zddcd",
      "baacbcccdcddcccc",
      "baacbccccccccccc",
      "fbccbccccccccccc",
      "fbcccbcccccccccc",
      "gbcccbcccccccccc",
      "gcccccbccccccccc",
      "gcccccbccccccccc",
      "ccccccbccccccccc",
      "ccccccbccccccccc",
      "hccccccbcccccccc",
      "hhcccccbcccccccc",
      " hhccccbcccccccc",
      " ghhcccbcccccccc",
      " gfhhccbcccccccc"
    ],
    [
      "cccc            ",
      "ccccz           ",
      "ccccze        z ",
      "cccczz zczzc zzz",
      "cccczzzzzzzzzzzz",
      "ccczzzzzzzzezzza",
      "ccczzzzzzzzzzzzz",
      "ccczzzzzzzzzzzzz",
      "cczzzzzzzzzzzzzz",
      "cczzzzzzzzzzzzzz",
      "czzzzzzzzzzzzzzz",
      "hzzzzzzzzzzzzzzz",
      "hhzzzzzzzzzzzzzz",
      " hhzzzzzzzzzzzzz",
      "  hhzzzzzzzzzzzz",
      "   hhzzzzzzzzzzz"
    ],
    [
      "zez             ",
      "zzzc            ",
      "zzzz            ",
      "zzzz          c ",
      "zzzzz e         ",
      "zzzz            ",
      "ezz             ",
      "zzzc   c     i  ",
      "zz              ",
      "zz              ",
      "z  i            ",
      "j               ",
      "jj   k          ",
      " jj  k kk       ",
      "  jj            ",
      "   j         ki "
    ],
    [
      "                ",
      "                ",
      "                ",
      "                ",
      "                ",
      "                ",
      "                ",
      "                ",
      "                ",
      "k               ",
      "                ",
      "                ",
      "                ",
      "                ",
      "                ",
      "                "
    ],
    [
      "                ",
      "                ",
      "                ",
      "                ",
      "                ",
      "                ",
      "                ",
      "                ",
      "                ",
      "                ",
      "                ",
      "                ",
      "                ",
      "                ",
      "                ",
      "                "
    ],
    [
      "                ",
      "                ",
      "                ",
      "                ",
      "                ",
      "                ",
      "                ",
      "                ",
      "                ",
      "                ",
      "                ",
      "                ",
      "                ",
      "                ",
      "                ",
      "                "
    ]
  ]
}