{
  "name": "multi_nuclearpowerplant_37_base12",
  "refpalette": "deceasedcraft:multi_nuclearpowerplant_37/multi_nuclearpowerplant_37_base12_palette",
  "xsize": 16,
  "zsize": 16,
  "slices": [
    [
      "aaaaaaaaaaaaaaaa",
      "aaaaaaaaaaaaaaaa",
      "aaaaaaaaaaaaaaaa",
      "aaaaaaaaaaaaaaaa",
      "aaaaaaaaaaaaaaaa",
      "aaaaaaaaaaaaaaaa",
      "aaaaaaaaaaaaaaaa",
      "aaaaaaaaaaaaaaaa",
      "aaaaaaaaaaaaaaaa",
      "aaaaaaaaaaaaaaaa",
      "aaaaaaaaaaaaaaaa",
      "aaaaaaaaaaaaaaaa",
      "aaaaaaaaaaaaaaaa",
      "aaaaaaaaaaaaaaaa",
      "aaaaaaaaaaaaaaaa",
      "aaaaaaaaaaaaaaaa"
    ],
    [
      "bbbbbbbbbbbbbbbb",
      "bbbbbbbbbbbbbbbb",
      "bbbbbbbbbbbbbbbb",
      "bbbbbbbbbbbbbbbb",
      "bbbbbbbbbbbbbbbb",
      "bbbbbbbbbbbbbbbb",
      "bbbbbbbbbbbbbbbb",
      "bbbbbbbbbbbbbbbb",
      "bbbbbbbbbbbbbbbb",
      "bbbbbbbbbbbbbbbb",
      "bbbbbbbbbbbbbbbb",
      "bbbbbbbbbbbbbbbb",
      "bbbbbbbbbbbbbbbb",
      "bbbbbbbbbbbbbbbb",
      "bbbbbbbbbbbbbbbb",
      "bbbbbbbbbbbbbbbb"
    ],
    [
      "================",
      "================",
      "================",
      "================",
      "================",
      "================",
      "================",
      "================",
      "================",
      "================",
      "================",
      "================",
      "================",
      "================",
      "================",
      "================"
    ],
    [
      "cccccccccccccccc",
      "cccccccccccccccc",
      "cccccccccccccccc",
      "cccccccccccccccc",
      "cccccccccccccccc",
      "cccccccccccccccc",
      "cccccccccccccccc",
      "cccccccccccccccc",
      "cccccccccccccccc",
      "cccccccccccccccc",
      "cccccccccccccccc",
      "cccccccccccccccc",
      "cccccccccccccccc",
      "cccccccccccccccc",
      "cccccccccccccccc",
      "cccccccccccccccc"
    ],
    [
      "deedeedeedeedeed",
      "dddddddddddddddd",
      "deedeedeedeedeed",
      "deedeedeedeedeed",
      "dddddddddddddddd",
      "deedeedeedeedeed",
      "deedeedeedeedeed",
      "dddddddddddddddd",
      "deedeedeedeedeed",
      "deedeedeedeedeed",
      "dddddddddddddddd",
      "deedeedeedeedeed",
      "deedeedeedeedeed",
      "fddddddddddddddd",
      "deedeedeedeedeed",
      "deedeedeedeedeed"
    ],
    [
      "dghdhidghdhidghd",
      "dddddddddddddddd",
      "dgjdjidgjdjidgjd",
      "dhidghdhidghdhid",
      "dddddddddddddddd",
      "djidgjdjidgjdjid",
      "dghdhidghdhidghd",
      "dddddddddddddddd",
      "dgjdjidgjdjidgjd",
      "dhidghdhidghdhid",
      "dddddddddddddddd",
      "djidgjdjidgjdjid",
      "dghdhidghdhidghd",
      "fddddddddddddddd",
      "dgjdjidgjdjidgjd",
      "dhidghdhidghdhid"
    ]
  ]
}