{
  "name": "multi_nuclearpowerplant_37_base2",
  "refpalette": "deceasedcraft:multi_nuclearpowerplant_37/multi_nuclearpowerplant_37_base2_palette",
  "xsize": 16,
  "zsize": 16,
  "slices": [
    [
      "a   =b          ",
      " a   =b         ",
      " a    =b        ",
      "  a    =b       ",
      "  a     =b      ",
      "  a      =b     ",
      "   a      =b    ",
      "   a       =bb  ",
      "    a       ==bb",
      "    a        ===",
      "    a         =b",
      "    a         =b",
      "     a        =b",
      "     a        =b",
      "     a        =b",
      "     a        =b"
    ],
    [
      "a   =b      c   ",
      " a   =b     c   ",
      " a    =b    c   ",
      "  a    =b   c   ",
      "  a     =b  c   ",
      "  a      =b c   ",
      "   a      =bc   ",
      "   a       =bb  ",
      "    a       ==bb",
      "    a        ===",
      "    a         =b",
      "    a         =b",
      "     a        =b",
      "     a        =b",
      "     a        =b",
      "     a        =b"
    ],
    [
      "a   =b      d   ",
      " a   =b     d   ",
      " a    =b    d   ",
      "  a    =b   d   ",
      "  a     =b  d   ",
      "  a      =b d   ",
      "   a      =bd   ",
      "   a       =bb  ",
      "    a       ==bb",
      "   ea        ===",
      "    a         =b",
      "    a         =b",
      "     a        =b",
      "     a        =b",
      "     a        =b",
      "     a        =b"
    ],
    [
      "a  f=bb         ",
      " a ff=bb        ",
      " a  ff=bb       ",
      "  a fff=bb      ",
      "  a ffff=bb     ",
      "  a  ffff=bb    ",
      "   a fffff=bb   ",
      "   a  fffff==bbg",
      "    a ffffff===b",
      "    a fffffff===",
      "    a ffffffff=b",
      "    a  fffhhhf=b",
      "     a fffffff=b",
      "     a fffffff=b",
      "     a fffffff=b",
      "     a fffffff=b"
    ],
    [
      "ijj  ==bk       ",
      " ij   ==bk      ",
      " ijj   ==bk     ",
      "  ij    ==bk    ",
      "  ij     ==bk   ",
      "  ijj     ==bkk ",
      "   ij      ==bbk",
      "   ijj       ==b",
      "    ijlllllllll=",
      "    ij  lmmmmmmm",
      "    ij  lm    l ",
      "    ijj l     l ",
      "     ij l     l ",
      "     ij l     l ",
      "     ij l     l ",
      "     ij l     l "
    ],
    [
      "njjoppp=bbbbbbbb",
      "nnjopppp=bbbbbbb",
      "nnjjopppp=bbbbbb",
      "nnnjoppppp=bbbbb",
      "nnnjopppppp=bbbb",
      "nnnjjopppppp=bbb",
      "nnnnjoppppppp==b",
      "nnnnjjopppppppp=",
      "nnnnnjoqqqqqqqqq",
      "rnnnnjoqqsssssss",
      "nnnnnjoqqtssssss",
      "nnnnnjjqqsssssss",
      "nnnnnnjqqsssssss",
      "nnnnnnjqqsssssss",
      "nnnnnnjqqsssssss",
      "nnnnnnjqqsssssss"
    ]
  ]
}