{
  "name": "multi_nuclearpowerplant_37_base11",
  "refpalette": "deceasedcraft:multi_nuclearpowerplant_37/multi_nuclearpowerplant_37_base11_palette",
  "xsize": 16,
  "zsize": 16,
  "slices": [
    [
      "abcadbabcadbaeea",
      "aaaaaaaaaaaaaaaa",
      "afcadfafcadfafca",
      "adbabcagbabcadba",
      "aaaaaaaaaaaaaaaa",
      "adfafcadfafcadfa",
      "abcadbabcadbabca",
      "aaaaaaaaaaaaaaaa",
      "afcadfafcadfafca",
      "adbabcadbabcadba",
      "aaaaaaaaaaaaaaaa",
      "adfafcadfafcadfa",
      "abeadbabcad!abca",
      "haaaaaaaaaaaaaaa",
      "afcadfafcadfafca",
      "adbabcadbabcadba"
    ],
    [
      "adbabcadbabcadea",
      "aaaaaaaaaaaaaaaa",
      "adfafcagfafcadfa",
      "abcadbabgadbabca",
      "aaaaaaaaaaaaaaaa",
      "afcadfafcadfafca",
      "adbabcadbabcadba",
      "aaaaaaaaaaaaaaaa",
      "adfafcadfafcadfa",
      "abcadbabcadbabca",
      "aaaaaaaaaaaaaaaa",
      "aecadfafcadfafca",
      "adbabcadbabcadba",
      "haaaaaaaaaaaaaaa",
      "adfafcadfafcagga",
      "abcadbabcadbagga"
    ],
    [
      "abcadbabcadbabca",
      "aaaaaaaaaaaaaaaa",
      "afcaaaafcadfafca",
      "adbaaaadbabcadba",
      "aaaaaaaaaaaaaaaa",
      "adfafcadfafcadfa",
      "abcadbabcadbabca",
      "aaaaaaaaaaaaaaaa",
      "afcadfafcadfaaaa",
      "adbabcadbabcaaaa",
      "aaaaaaaaaaaaaaaa",
      "aaaafcaaaafcadfa",
      "aaaadbaaaadbabca",
      "haaaaaaaaaaaaaaa",
      "aaaaaaafcaaaaaaa",
      "aaaaaaadbaaaaaaa"
    ],
    [
      "aaaaaaaaaaaaaaaa",
      "aaaaaaaaaaaaaaaa",
      "aaaaaaaaaaaaaaaa",
      "aaaaaaaaaaaaaaaa",
      "aaaaaaaaaaaaaaaa",
      "aaaaaaaaaaaaaaaa",
      "aaaaaaaaaaaaaaaa",
      "aaaaaaaaaaaaaaaa",
      "aaaaaaaaaaaaaaaa",
      "aaaaaaaaaaaaaaaa",
      "aaaaaaaaaaaaaaaa",
      "aaaaaaaaaaaaaaaa",
      "aaaaaaaaaaaaaaaa",
      "haaaaaaaaaaaaaaa",
      "aaaaaaaaaaaaaaaa",
      "aaaaaaaaaaaaaaaa"
    ],
    [
      "aaaaaaaaaaaaaaaa",
      "aaaaaaaaaaaaaaaa",
      "aaaaaaaaaaaaaaaa",
      "aaaaaaaaaaaaaaaa",
      "aaaaaaaaaaaaaaaa",
      "aaaaaaaaaaaaaaaa",
      "aaaaaaaaaaaaaaaa",
      "aaaaaaaaaaaaaaaa",
      "aaaaaaaaaaaaaaaa",
      "aaaaaaaaaaaaaaaa",
      "aaaaaaaaaaaaaaaa",
      "aaaaaaaaaaaaaaaa",
      "aaaaaaaaaaaaaaaa",
      "haaaaaaaaaaaaaaa",
      "aaaaaaaaaaaaaaaa",
      "aaaaaaaaaaaaaaaa"
    ],
    [
      "aaaaaaaaaaaaaaaa",
      "aaaaaaaaaaaaaaaa",
      "aaaaaaaaaaaaaaaa",
      "aaaaaaaaaaaaaaaa",
      "aaaaaaaaaaaaaaaa",
      "aaaaaaaaaaaaaaaa",
      "aaaaaaaaaaaaaaaa",
      "aaaaaaaaaaaaaaaa",
      "aaaaaaaaaaaaaaaa",
      "aaaaaaaaaaaaaaaa",
      "aaaaaaaaaaaaaaaa",
      "aaaaaaaaaaaaaaaa",
      "aaaaaaaaaaaaaaaa",
      "haaaaaaaaaaaaaaa",
      "aaaaaaaaaaaaaaaa",
      "aaaaaaaaaaaaaaaa"
    ]
  ]
}