{
  "name": "multi_nuclearpowerplant_37_base3",
  "refpalette": "deceasedcraft:multi_nuclearpowerplant_37/multi_nuclearpowerplant_37_base3_palette",
  "xsize": 16,
  "zsize": 16,
  "slices": [
    [
      "a   =bcccc      ",
      "da   =bcccc     ",
      "da    =bcccc    ",
      "dda    =bcccc   ",
      "dda     =bcccc  ",
      "dda      =bccccc",
      "ddda      =bcccc",
      "ddda       =bbcc",
      "dddda      e==bb",
      "dddda      eff==",
      "dddda      effff",
      "dddda      effff",
      "ddddda     effff",
      "ddddda     effff",
      "ddddda     effff",
      "ddddda     effff"
    ],
    [
      "g   =h   i      ",
      " g   =h   i     ",
      " g    =h   i    ",
      "  g    =h   i   ",
      "  g     =h   i  ",
      "  g      =h   jj",
      "  kg      =h    ",
      "   g       =hh  ",
      "l   g      m==hh",
      "   ng      m ===",
      "o   g      m  =h",
      "p  qg      m  =h",
      "r    g     m  sh",
      "r    g     m  th",
      "ru   g     m  th",
      "w    g     m nsh"
    ],
    [
      "g   =h          ",
      " g   =h         ",
      " g    =h        ",
      "  g    =h       ",
      "  g     =h      ",
      "  g      =h     ",
      "  xg      =h    ",
      "   g       =hh  ",
      "    g       ==hh",
      "   yg        ===",
      "    g         =h",
      "A   g         =h",
      "B    g        sh",
      "C    g         D",
      "E    g         F",
      "I    g        sh"
    ],
    [
      "g   =h          ",
      " g   =h         ",
      " g    =h        ",
      "  g    =h       ",
      "  g     =h      ",
      "  g      =h     ",
      "  Jg      =h    ",
      "   g       =hh  ",
      "    g       ==hh",
      "    g        ===",
      "    g         =h",
      "    g        K=h",
      "     g        sh",
      "     g         L",
      "     g         M",
      "     g        sh"
    ],
    [
      "g   =h          ",
      " g   =h         ",
      " g    =h        ",
      "  g    =h       ",
      "  g     =h      ",
      "  g      =h     ",
      "   g      =h    ",
      "   g       =hh  ",
      "    g       ==hh",
      "    g        ===",
      "    g         =h",
      "    g         =h",
      "     g        sh",
      "     g        sN",
      "     g        sN",
      "     g        sh"
    ],
    [
      "g   =h          ",
      " g   =h         ",
      " g    =h        ",
      "  g    =h       ",
      "  g     =h      ",
      "  g      =h     ",
      "   g      =h    ",
      "   g       =hh  ",
      "    g       ==hh",
      "    g        ===",
      "    g         =h",
      "    g         =h",
      "     g        =h",
      "     g        =h",
      "     g        =h",
      "     g        =h"
    ]
  ]
}