{
  "name": "multi_nuclearpowerplant_37_base7",
  "refpalette": "deceasedcraft:multi_nuclearpowerplant_37/multi_nuclearpowerplant_37_base7_palette",
  "xsize": 16,
  "zsize": 16,
  "slices": [
    [
      "    =a      bbcc",
      "     =a      bbc",
      "      =a      bb",
      "       =a      b",
      "        =a      ",
      "         =a     ",
      "         d=a    ",
      "           =aa  ",
      "            ==aa",
      "              ==",
      "          e     ",
      "                ",
      " f    f         ",
      "                ",
      "   gg           ",
      "   !g           "
    ],
    [
      "    =a      bbcc",
      "     =a      bbc",
      "      =a      bb",
      "       =a      b",
      "        =a      ",
      "         =a     ",
      "         d=a    ",
      "           =aa  ",
      "            ==aa",
      "              ==",
      "          e    h",
      "               i",
      " f    f         ",
      "                ",
      "    g           ",
      "                "
    ],
    [
      "    =a      bb  ",
      "     =a      bb ",
      "      =a      bb",
      "       =a      b",
      "        =a      ",
      "         =a     ",
      "         d=a    ",
      "           =aa  ",
      "            ==aa",
      "              ==",
      "          e   h ",
      "              i ",
      " f    f         ",
      " j    j         ",
      "                ",
      "                "
    ],
    [
      "    =a      bb  ",
      "     =a      bb ",
      "      =a      bb",
      "       =a      b",
      "        =a      ",
      "         =a     ",
      "         d=a    ",
      "           =aa  ",
      "            ==aa",
      "              ==",
      "          e  h  ",
      " k           i  ",
      " f    f         ",
      "fffffff         ",
      " f    f         ",
      " f    f         "
    ],
    [
      "    =a      lb  ",
      "     =a      bb ",
      "      =a      bb",
      "       =a      b",
      "        =a      ",
      "         =a     ",
      "         d=a    ",
      "           =aa  ",
      "            ==aa",
      "              ==",
      "          e h   ",
      "            i   ",
      " f    f         ",
      "mmmmmm          ",
      "mmmmmm          ",
      "mmmmmm          "
    ],
    [
      "nnnn=a      bb  ",
      "nnnnn=a      bb ",
      "nnnnnn=a      bb",
      "nnnnnnn=a      b",
      "nnnnnnnn=a      ",
      "nnnnnnnnn=a     ",
      "nnnnnnnnnd=a    ",
      "nnnnnnnnn  =aa  ",
      "nnnnnnnnn   ==aa",
      "nnnnnnnnn     ==",
      "         oph    ",
      "         ooi    ",
      " f    f  oo     ",
      "qqqqqm   oo     ",
      "   rsq   oo     ",
      "   ssq   oo     "
    ]
  ]
}