{
  "name": "multi_nuclearpowerplant_37_base6",
  "refpalette": "deceasedcraft:multi_nuclearpowerplant_37/multi_nuclearpowerplant_37_base6_palette",
  "xsize": 16,
  "zsize": 16,
  "slices": [
    [
      "aaaa=b      cc  ",
      "aaaaa=b      cc ",
      "aaaaaa=b      cc",
      "aaaaaaa=b      c",
      "aaaaaaaa=b      ",
      "aaaaaaaaa=b     ",
      "aaaaaaaaad=b    ",
      "aaaaaaaaaee=bb  ",
      "aaaaaaaaaee ==bb",
      "aaaaaaaaafg   ==",
      "hhhhhhhhh       ",
      "iiiiiiiih       ",
      " j    jih k     ",
      "lllllm ih k     ",
      "   nol ih k     ",
      "   nol ih k     "
    ],
    [
      "    =b      cc  ",
      "     =b      cc ",
      "      =b      cc",
      "       =b      c",
      "        =b      ",
      "         =b     ",
      "         d=b    ",
      "          p=bb  ",
      "          k ==bb",
      "              ==",
      "                ",
      "qqqqqqqq        ",
      "rjs    q        ",
      "lllllm q        ",
      "t tool q        ",
      "tttool q        "
    ],
    [
      "    =b      cc u",
      "     =b      ccu",
      "      =b      cc",
      "       =b      c",
      "        =b      ",
      "         =b     ",
      "         w=b    ",
      "           =bb  ",
      "            ==bb",
      "              ==",
      "                ",
      "xxxyyyyyyyyyyyyy",
      " j y   A        ",
      "lllllm A        ",
      "   nol A        ",
      "   nol A        "
    ],
    [
      "    =b      cc  ",
      "     =b      cc ",
      "      =b      cc",
      "       =b      c",
      "        =b      ",
      "         =b     ",
      "          =b    ",
      "           =bb  ",
      "            ==bb",
      "              ==",
      "   BBBBBBBBBBBBB",
      "  C             ",
      " jC DEEEEEEEEEEE",
      "lllFlm          ",
      "   ool          ",
      "   nol          "
    ],
    [
      "    =b      cc  ",
      "     =b      cc ",
      "      =b      cc",
      "       =b      c",
      "        =b      ",
      "         =b     ",
      "          =b    ",
      "           =bb  ",
      "            ==bb",
      "              ==",
      "                ",
      "   IIIIIIIIIIIII",
      " j I            ",
      "mmmmmm          ",
      "lllllm          ",
      "lllllm          "
    ],
    [
      "    =b      cc  ",
      "     =b      cc ",
      "      =b      cc",
      "       =b      c",
      "        =b      ",
      "         =b     ",
      "          =b    ",
      "           =bb  ",
      "            ==bb",
      "              ==",
      "                ",
      "                ",
      " j              ",
      "jbJ             ",
      "KL              ",
      " L              "
    ]
  ]
}