{
  "name": "multi_timbertower_1_floor2",
  "refpalette": "deceasedcraft:multi_timbertower_1/multi_timbertower_1_floor2_palette",
  "xsize": 16,
  "zsize": 16,
  "slices": [
    [
      "           a b  ",
      "           c b  ",
      "           c bde",
      "           c bff",
      "          gh ihh",
      "           a bhh",
      "           a bhh",
      "           a bhh",
      "           c bhh",
      "           c bhh",
      "           c bhh",
      "          gh ihh",
      "           a bjj",
      "           a b  ",
      "           a b  ",
      "           c b  "
    ],
    [
      "           a k  ",
      "           c kd ",
      "           c kl ",
      "           c k  ",
      "          gh icm",
      "           a n  ",
      "           a n  ",
      "           a n  ",
      "           c n  ",
      "           c n  ",
      "           c n  ",
      "          gh i  ",
      "           a n  ",
      "           a n  ",
      "           a n  ",
      "           c n  "
    ],
    [
      "           a kf ",
      "           c kl ",
      "           c k  ",
      "           c k  ",
      "          gh ico",
      "           a    ",
      "           a    ",
      "           a    ",
      "           c    ",
      "           c    ",
      "           c    ",
      "          gh i  ",
      "           a    ",
      "           a    ",
      "           a    ",
      "           c    "
    ],
    [
      "           a klp",
      "           c k  ",
      "           c k  ",
      "           c k  ",
      "          gh icc",
      "           a    ",
      "           a    ",
      "           a    ",
      "           c    ",
      "           c    ",
      "           c    ",
      "          gh i  ",
      "           a    ",
      "           a    ",
      "           a    ",
      "           c    "
    ],
    [
      "           a q e",
      "           c q p",
      "           c q  ",
      "           c q  ",
      "          gh icc",
      "           a q  ",
      "           a q  ",
      "           a q  ",
      "           c q  ",
      "           c q  ",
      "           c q  ",
      "          gh i  ",
      "           a q  ",
      "           a q  ",
      "           a q  ",
      "           c q  "
    ],
    [
      "           a i  ",
      "           c i e",
      "           c i f",
      "           c idf",
      "          ghriii",
      "           a iss",
      "           a iss",
      "           a iss",
      "           c iss",
      "           c iss",
      "           c iss",
      "          ghriii",
      "           a iss",
      "           a iss",
      "           a iss",
      "           c iss"
    ]
  ]
}