{
  "name": "multi_timbertower_1_ground",
  "refpalette": "deceasedcraft:multi_timbertower_1/multi_timbertower_1_ground_palette",
  "xsize": 16,
  "zsize": 16,
  "slices": [
    [
      "HHHvvvvvvvvvvv  ",
      "HHHvvvvvvvvvvv  ",
      "HHHvvvvvvvvvvvab",
      "HHHvvvvvvvvvvvcc",
      "HHHvvvdvvvvvvdvv",
      "HHHvvvvvvvvvvvvv",
      "HHHeHHHHHHHHHHHH",
      "HHHeHHHHHHHHHHHH",
      "HHHeHHHHHHHHHHHH",
      "HHHeHHHHHHHHHHHH",
      "HHHvvHHHHHHHHHHv",
      "HHHvvHdHHHHHHdHv",
      "HHHvvHHHHHHHHHHv",
      "HHHvvHHHHHHHHHHv",
      "HHHvvHHHHHHHHHHv",
      "HHHvvHHHHHHHHHHv"
    ],
    [
      "   f  g      h  ",
      "   f  g      ha ",
      "   f  g  i i hj ",
      "   f  gklmmlkh  ",
      "  nopqdrrrrrrdps",
      "                ",
      "   t            ",
      "   t            ",
      "   t            ",
      "   t            ",
      "               u",
      "  now dx    nd y",
      "   fwA B       y",
      "   fwC D    A By",
      "   fwA B    C Dy",
      "   fwC D    A By"
    ],
    [
      "   f  g      hc ",
      "   f  g      hj ",
      "   f  g      h  ",
      "   f  g EFI Fh  ",
      "   oJKdLLLLLLdJM",
      "                ",
      "                ",
      "                ",
      "                ",
      "                ",
      "                ",
      "   o  d      d  ",
      "   f            ",
      "   f            ",
      "   f            ",
      "   f            "
    ],
    [
      "   f  g      hjN",
      "   f  g      h  ",
      "   f  g      h  ",
      "   f  g      h  ",
      "   orrdLLLLLLdrr",
      "                ",
      "                ",
      "                ",
      "                ",
      "                ",
      "                ",
      "   o  d      d  ",
      "   f            ",
      "   f            ",
      "   f            ",
      "   f            "
    ],
    [
      "   f  u      u b",
      "   f  u      u N",
      "   f  u      u  ",
      "   f  u      u  ",
      "   ouuduuuuuudrr",
      "                ",
      "                ",
      "                ",
      "                ",
      "                ",
      "                ",
      "   o  d      d  ",
      "   f            ",
      "   f            ",
      "   f            ",
      "   f            "
    ],
    [
      "   fOOdOOOOOOd  ",
      "   fOOdOOOOOOd b",
      "   fOOdOOOOOOd c",
      "   fOOdOOOOOOdac",
      "  Oodddddddddddd",
      "  OuOOdOOOOOOdOO",
      "  OuOOdOOOOOOdOO",
      "  OuOOdOOOOOOdOO",
      "  OuOOdOOOOOOdOO",
      "  OuOOdOOOOOOdOO",
      "  OuOOdOOOOOOdOO",
      "  Oodddddddddddd",
      "   fOOdOOOOOOdOO",
      "   fOOdOOOOOOdOO",
      "   fOOdOOOOOOdOO",
      "   fOOdOOOOOOdOO"
    ]
  ]
}