{
  "name": "multi_timbertower_1_base1",
  "refpalette": "deceasedcraft:multi_timbertower_1/multi_timbertower_1_base1_palette",
  "xsize": 16,
  "zsize": 16,
  "slices": [
    [
      "vaavvHHHHHHHHv  ",
      "vaavvHHHHHHHHv  ",
      "vaavvHHHHHHHHvbc",
      "vaavvHHHHHHHHvdd",
      "vaavvHeHHHHHHevv",
      "vaavvHHHHHHHHvvv",
      "vaavvHHHHHHHHHHH",
      "vaavvHHHHHHHHHHH",
      "vaavvHHHHHHHHHHH",
      "vaavvHHHHHHHHHHH",
      "vaavvHHHHHHHHvvv",
      "vaavvHeHHHHHHeHv",
      "vaavvHHHHHHHHHHv",
      "vaavvHHHHHHHHHHv",
      "vaavvHHHHHHHHHHv",
      "vaavvHHHHHHHHHHv"
    ],
    [
      "vaavfg h     i  ",
      "vaavfj k     ib ",
      "vaavfg h     il ",
      "vaavfj k     i  ",
      "vaavf em    neop",
      "vaavfg h        ",
      "vaavfj k        ",
      "vaavfg h        ",
      "vaavfj k        ",
      "vaavfg h        ",
      "vaavfj k     qvv",
      "vaavf em    re s",
      "vaavfg h       s",
      "vaavfj k    g hs",
      "vaavfg h    j ks",
      "vaavfj k    g hs"
    ],
    [
      "vaav         id ",
      "vaav         il ",
      "vaav         i  ",
      "vaav         i  ",
      "vaav  e      etu",
      "vaav            ",
      "vaav            ",
      "vaav            ",
      "vaav            ",
      "vaav            ",
      "vaav         qvv",
      "vaav  e      e  ",
      "vaav            ",
      "vaav            ",
      "vaav            ",
      "vaav            "
    ],
    [
      "vaav         ilw",
      "vaav         i  ",
      "vaav         i  ",
      "vaav         i  ",
      "vaav  e      exx",
      "vaav            ",
      "vaav            ",
      "vaav            ",
      "vaav            ",
      "vaav            ",
      "vaav         qvv",
      "vaav  e      e  ",
      "vaav            ",
      "vaav            ",
      "vaav            ",
      "vaav            "
    ],
    [
      "vaav         y c",
      "vaav         y w",
      "vaav         y  ",
      "vaav         y  ",
      "vaav  e      exx",
      "vaav            ",
      "vaav            ",
      "vaav            ",
      "vaav            ",
      "vaav            ",
      "vaav         qvv",
      "vaav  e      e  ",
      "vaav            ",
      "vaav            ",
      "vaav            ",
      "vaav            "
    ],
    [
      "vaavvAeAAAAAAe  ",
      "vaavvAeAAAAAAe c",
      "vaavvAeAAAAAAe w",
      "vaavvAeAAAAAAebd",
      "vaavvAeeeeeeeeee",
      "vaavvAeAAAAAAeAA",
      "vaavvAeAAAAAAeAA",
      "vaavvAeAAAAAAeAA",
      "vaavvAeAAAAAAeAA",
      "vaavvAeAAAAAAeAA",
      "vaavvAeAAAAAAevv",
      "vaavvAeeeeeeeeee",
      "vaavvAeAAAAAAeA ",
      "vaavvAeAAAAAAeA ",
      "vaavvAeAAAAAAeA ",
      "vaavvAeAAAAAAeA "
    ]
  ]
}