{
  "name": "multi_timbertower_1_floor14",
  "refpalette": "deceasedcraft:multi_timbertower_1/multi_timbertower_1_floor14_palette",
  "xsize": 16,
  "zsize": 16,
  "slices": [
    [
      "            ab  ",
      "            cb  ",
      "            cbde",
      "            cbff",
      "           ghibb",
      "            abbb",
      "            abbb",
      "            abbb",
      "            cbbb",
      "            cbbb",
      "            cbbb",
      "           ghibb",
      "            abbb",
      "            abbb",
      "            abbb",
      "            cbbb"
    ],
    [
      "            aj  ",
      "            cj  ",
      "            cj  ",
      "            cj  ",
      "           ghick",
      "            alm ",
      "            al  ",
      "            aln ",
      "            clo ",
      "            cl  ",
      "            clm ",
      "           ghip ",
      "            alq ",
      "            alq ",
      "            alr ",
      "            clr "
    ],
    [
      "            aj  ",
      "            cj  ",
      "            cj  ",
      "            cj  ",
      "           ghics",
      "            alt ",
      "            al  ",
      "            al  ",
      "            cl  ",
      "            cl  ",
      "            clt ",
      "           ghi  ",
      "            al  ",
      "            al  ",
      "            al  ",
      "            cl  "
    ],
    [
      "            aj  ",
      "            cj  ",
      "            cj  ",
      "            cj  ",
      "           ghicc",
      "            alu ",
      "            al  ",
      "            al  ",
      "            cl  ",
      "            cl  ",
      "            clu ",
      "           ghiw ",
      "            al  ",
      "            al  ",
      "            al  ",
      "            cl  "
    ],
    [
      "             x  ",
      "             x  ",
      "             x  ",
      "             x  ",
      "             icc",
      "             y  ",
      "             A  ",
      "             y  ",
      "             A  ",
      "             y  ",
      "             A  ",
      "             iAy",
      "             y  ",
      "             A  ",
      "             y  ",
      "             A  "
    ],
    [
      "             BCC",
      "             BCC",
      "             BCC",
      "             BCC",
      "             iDD",
      "             BEE",
      "             BEE",
      "             BEE",
      "             BEE",
      "             BEE",
      "             BEE",
      "             iDD",
      "             BEE",
      "             BEE",
      "             BEE",
      "             BEE"
    ]
  ]
}