{
  "name": "multi_timbertower_1_floor5",
  "refpalette": "deceasedcraft:multi_timbertower_1/multi_timbertower_1_floor5_palette",
  "xsize": 16,
  "zsize": 16,
  "slices": [
    [
      "           abc  ",
      "           dbc  ",
      "           dbcef",
      "           dbcgg",
      "          hijkcc",
      "           abccc",
      "           abccc",
      "           abccc",
      "           dbccc",
      "           dbccc",
      "           dbccc",
      "          hijkbb",
      "           abb  ",
      "           abb  ",
      "           abb  ",
      "           dbb  "
    ],
    [
      "           a l  ",
      "           d le ",
      "           d lm ",
      "           d l  ",
      "          hi kdn",
      "           a o  ",
      "           a o  ",
      "           a opq",
      "           d ors",
      "           d o  ",
      "           d otu",
      "          hi koo",
      "           a o  ",
      "           a o  ",
      "           a o  ",
      "           d o  "
    ],
    [
      "           a lg ",
      "           d lm ",
      "           d l  ",
      "           d l  ",
      "          hi kdw",
      "           a o  ",
      "           a o  ",
      "           a oxx",
      "           d o  ",
      "           d o  ",
      "           d o  ",
      "          hi k  ",
      "           a o  ",
      "           a o  ",
      "           a o  ",
      "           d o  "
    ],
    [
      "           a lmy",
      "           d l  ",
      "           d l  ",
      "           d l  ",
      "          hi kdd",
      "           a o  ",
      "           a o  ",
      "           a o  ",
      "           d o  ",
      "           d o  ",
      "           d o  ",
      "          hi k  ",
      "           a o  ",
      "           a o  ",
      "           a o  ",
      "           d o  "
    ],
    [
      "           a A f",
      "           d A y",
      "           d A  ",
      "           d A  ",
      "          hi kdd",
      "           a B  ",
      "           a C  ",
      "           a B  ",
      "           d C  ",
      "           d B  ",
      "           d C  ",
      "          hi k  ",
      "           a B  ",
      "           a C  ",
      "           a B  ",
      "           d C  "
    ],
    [
      "           a D  ",
      "           d D f",
      "           d D g",
      "           d Deg",
      "          hiEkFF",
      "           a DII",
      "           a DIJ",
      "           a DII",
      "           d DII",
      "           d DIJ",
      "           d DII",
      "          hiEkFF",
      "           a D  ",
      "           a D  ",
      "           a D  ",
      "           d D  "
    ]
  ]
}