{
  "name": "multi_timbertower_1_floor12",
  "refpalette": "deceasedcraft:multi_timbertower_1/multi_timbertower_1_floor12_palette",
  "xsize": 16,
  "zsize": 16,
  "slices": [
    [
      "            ab  ",
      "            cb  ",
      "            cbde",
      "            cbff",
      "           ghibb",
      "            abbb",
      "            abjj",
      "            abjj",
      "            cbjj",
      "            cbjj",
      "            cbbb",
      "           ghibb",
      "            abbb",
      "            abbb",
      "            abbb",
      "            cbbb"
    ],
    [
      "            ak  ",
      "            ckd ",
      "            ckl ",
      "            ck  ",
      "           ghicm",
      "            an  ",
      "            an  ",
      "            an  ",
      "            cn  ",
      "            cnoo",
      "            cnpq",
      "           ghip ",
      "            anr ",
      "            anss",
      "            ant ",
      "            cnuw"
    ],
    [
      "            akf ",
      "            ckl ",
      "            ck  ",
      "            ck  ",
      "           ghicx",
      "            an  ",
      "            an  ",
      "            ay  ",
      "            cy  ",
      "            cnoo",
      "            cnp ",
      "           ghip ",
      "            an A",
      "            anss",
      "            an  ",
      "            cn  "
    ],
    [
      "            aklB",
      "            ck  ",
      "            ck  ",
      "            ck  ",
      "           ghicc",
      "            an  ",
      "            an  ",
      "            aC  ",
      "            cC  ",
      "            cnoo",
      "            cnpD",
      "           ghip ",
      "            an E",
      "            anss",
      "            an  ",
      "            cn  "
    ],
    [
      "            aF e",
      "            cF B",
      "            cF  ",
      "            cF  ",
      "           ghicc",
      "            an  ",
      "            an  ",
      "            an  ",
      "            cn  ",
      "            cnoo",
      "            cnp ",
      "           ghip ",
      "            anI ",
      "            anss",
      "            anI ",
      "            cn  "
    ],
    [
      "            aJ  ",
      "            cJ e",
      "            cJ f",
      "            cJdf",
      "           ghiKK",
      "            aJLL",
      "            aJLL",
      "            aJLL",
      "            cJLL",
      "            cJMM",
      "            cJbb",
      "           ghiKK",
      "            aJbb",
      "            aJbb",
      "            aJII",
      "            cJ  "
    ]
  ]
}