{
  "name": "multi_timbertower_1_floor9",
  "refpalette": "deceasedcraft:multi_timbertower_1/multi_timbertower_1_floor9_palette",
  "xsize": 16,
  "zsize": 16,
  "slices": [
    [
      "            ab  ",
      "            ab  ",
      "           cabde",
      "            abff",
      "           ghibb",
      "            abbb",
      "           jabbb",
      "            abbb",
      "            abbb",
      "           cabbb",
      "            abbb",
      "           ghibb",
      "            abbb",
      "           jabbb",
      "            abbb",
      "            abbb"
    ],
    [
      "             k  ",
      "             kd ",
      "           c kl ",
      "             k  ",
      "           ghicm",
      "             n  ",
      "           j n  ",
      "             n  ",
      "             no ",
      "           c np ",
      "             no ",
      "           ghiq ",
      "             no ",
      "           j np ",
      "             no ",
      "             n  "
    ],
    [
      "             kf ",
      "             kl ",
      "           c k  ",
      "             k  ",
      "           ghicr",
      "             n  ",
      "           j n  ",
      "             n  ",
      "             n  ",
      "           c ns ",
      "             n  ",
      "           ghit ",
      "             n  ",
      "           j n  ",
      "             n  ",
      "             n  "
    ],
    [
      "             klu",
      "             k  ",
      "           c k  ",
      "            ck  ",
      "           ghicc",
      "             n  ",
      "           j n  ",
      "            jn  ",
      "            cn  ",
      "           c n  ",
      "             n  ",
      "           ghiw ",
      "            jn  ",
      "           j n  ",
      "             n  ",
      "             n  "
    ],
    [
      "             x e",
      "             x u",
      "           c x  ",
      "            cx  ",
      "           ghicc",
      "             y  ",
      "           j A  ",
      "            jy  ",
      "            cA  ",
      "           c y  ",
      "             A  ",
      "           ghi  ",
      "            jy  ",
      "           j A  ",
      "             y  ",
      "             A  "
    ],
    [
      "            jB  ",
      "            cB e",
      "           c B f",
      "            cBdf",
      "           ghiCC",
      "            jBDD",
      "           j BDE",
      "            jBDD",
      "            cBDD",
      "           c BDE",
      "            cBDD",
      "           ghiCC",
      "            jB  ",
      "           j B  ",
      "            jB  ",
      "            cB  "
    ]
  ]
}