{
  "name": "multi_timbertower_1_floor10",
  "refpalette": "deceasedcraft:multi_timbertower_1/multi_timbertower_1_floor10_palette",
  "xsize": 16,
  "zsize": 16,
  "slices": [
    [
      "            ab  ",
      "            cb  ",
      "           c bde",
      "            cbff",
      "           ghibb",
      "            abbb",
      "           a bbb",
      "            abbb",
      "            cbbb",
      "           c bbb",
      "            cbbb",
      "           ghijj",
      "            aj  ",
      "           a j  ",
      "            aj  ",
      "            cj  "
    ],
    [
      "            ak  ",
      "            ckd ",
      "             kl ",
      "            ck  ",
      "           ghicm",
      "            an  ",
      "             n  ",
      "            an  ",
      "            cn  ",
      "             n  ",
      "            cn  ",
      "           ghinn",
      "            an  ",
      "             n  ",
      "            an  ",
      "            cn  "
    ],
    [
      "            akf ",
      "            ckl ",
      "             k  ",
      "            ck  ",
      "           ghico",
      "            an  ",
      "             n  ",
      "            an  ",
      "            cn  ",
      "             n  ",
      "            cn  ",
      "           ghi  ",
      "            an  ",
      "             n  ",
      "            an  ",
      "            cn  "
    ],
    [
      "            aklp",
      "            ck  ",
      "             k  ",
      "            ck  ",
      "           ghicc",
      "            an  ",
      "             n  ",
      "            an  ",
      "            cn  ",
      "             n  ",
      "            cn  ",
      "           ghi  ",
      "            an  ",
      "             n  ",
      "            an  ",
      "            cn  "
    ],
    [
      "            aq e",
      "            cq p",
      "             q  ",
      "            cq  ",
      "           ghicc",
      "            ar  ",
      "             s  ",
      "            ar  ",
      "            cs  ",
      "             r  ",
      "            cs  ",
      "           ghi  ",
      "            ar  ",
      "             s  ",
      "            ar  ",
      "            cs  "
    ],
    [
      "            at  ",
      "            ct e",
      "            ct f",
      "            ctdf",
      "           ghiuu",
      "            atww",
      "            atwx",
      "            atww",
      "            ctww",
      "            ctwy",
      "            ctww",
      "           ghiuu",
      "            at  ",
      "            at  ",
      "            at  ",
      "            ct  "
    ]
  ]
}