{
  "name": "multi_timbertower_1_floor1",
  "refpalette": "deceasedcraft:multi_timbertower_1/multi_timbertower_1_floor1_palette",
  "xsize": 16,
  "zsize": 16,
  "slices": [
    [
      "   abcdedfffgg  ",
      "   abcddffffgg  ",
      "   abcddedefgghi",
      "   abcddfeffggjj",
      "   kbcddefffglgg",
      "   abcddffffgggg",
      "   abcddedffgggg",
      "   abcdddfefgggg",
      "   abcddefffgggg",
      "   abcdddeffgggg",
      "   abcddeeffgggg",
      "   kbcdeffffglgg",
      "   abcddfeffgggg",
      "   abcdeffffgggg",
      "   abcddedefgggg",
      "   abcddffffgggg"
    ],
    [
      "   amno      p  ",
      "   amqr      ph ",
      "   amso    t pu ",
      "   amnr    w p  ",
      "   kmnr    x lyA",
      "   amso    B    ",
      "   amqo         ",
      "   amso         ",
      "   amnr         ",
      "   amqo         ",
      "   amsr    w    ",
      "   kmno    x lC ",
      "   amso    B pDD",
      "   amqr    t p E",
      "   amnr      p  ",
      "   amso      p  "
    ],
    [
      "   amF       pj ",
      "   am        pu ",
      "   aIJ     K p  ",
      "   amF       p  ",
      "   kmF       lyL",
      "   aIJ          ",
      "   am           ",
      "   amJ          ",
      "   amF          ",
      "   a            ",
      "   amJ          ",
      "   kmF       l  ",
      "   aIJ       p M",
      "   am      K p  ",
      "   amF       p  ",
      "   amJ       p  "
    ],
    [
      "   am        puN",
      "   a         p  ",
      "   am        p  ",
      "   am        p  ",
      "   kI        lyy",
      "   aI           ",
      "   am           ",
      "   am           ",
      "   am           ",
      "   a            ",
      "   aI           ",
      "   km        l  ",
      "   am        p  ",
      "   am        p  ",
      "   aI        p  ",
      "   am        pOO"
    ],
    [
      "   aI        P i",
      "   a         P N",
      "   a         P  ",
      "   a         P  ",
      "   k         lyy",
      "   am        P  ",
      "   am        P  ",
      "   a         P  ",
      "   aI        P  ",
      "   a         P  ",
      "   a         P  ",
      "   k         l  ",
      "   a         P  ",
      "   aI        P  ",
      "   aI        POO",
      "   a         P  "
    ],
    [
      "   Q       R l  ",
      "   Q       y l i",
      "   Q       y l j",
      "   Q       y lhj",
      "   S      TUVlll",
      "   Q       R lWW",
      "   Q       R lWW",
      "   Q       R lWW",
      "   Q       y lWW",
      "   Q       y lWW",
      "   Q       y lWW",
      "   S      TUVlll",
      "   Q       R l  ",
      "   Q       R lOO",
      "   Q       R l  ",
      "   Q       y l  "
    ]
  ]
}