{
  "name": "multi_timbertower_1_floor6",
  "refpalette": "deceasedcraft:multi_timbertower_1/multi_timbertower_1_floor6_palette",
  "xsize": 16,
  "zsize": 16,
  "slices": [
    [
      "           abc  ",
      "           dbc  ",
      "           dbcef",
      "           dbcgg",
      "          hijkcc",
      "           abccc",
      "           abccc",
      "           abccc",
      "           dbccc",
      "           dbccc",
      "           dbccc",
      "          hijkcc",
      "           abccc",
      "           abccc",
      "           abccc",
      "           dbccc"
    ],
    [
      "           a l  ",
      "           d le ",
      "           d lm ",
      "           d l  ",
      "           h kdn",
      "           a o  ",
      "           a o  ",
      "           a o  ",
      "           d op ",
      "           d oqr",
      "           d os ",
      "           h kt ",
      "           a op ",
      "           a oqr",
      "           a os ",
      "           d opu"
    ],
    [
      "           a lg ",
      "           d lm ",
      "           d l  ",
      "           d l  ",
      "           h kdw",
      "           a o  ",
      "           a o  ",
      "           a o  ",
      "           d o  ",
      "           d ox ",
      "           d o  ",
      "           h ky ",
      "           a o  ",
      "           a oA ",
      "           a o  ",
      "           d o  "
    ],
    [
      "           a lmB",
      "           d l  ",
      "           d l  ",
      "           d l  ",
      "           h kdd",
      "           a o  ",
      "           a o  ",
      "           a o  ",
      "           d o  ",
      "           d o  ",
      "           d o  ",
      "           h kC ",
      "           a o  ",
      "           a o  ",
      "           a o  ",
      "           d o  "
    ],
    [
      "           a D f",
      "           d D B",
      "           d D  ",
      "           d D  ",
      "           h kdd",
      "           a E  ",
      "           a F  ",
      "           a E  ",
      "           d F  ",
      "           d E  ",
      "           d F  ",
      "           h k  ",
      "           a E  ",
      "           a F  ",
      "           a E  ",
      "           d F  "
    ],
    [
      "           a I  ",
      "           d I f",
      "           d I g",
      "           d Ieg",
      "           hikJJ",
      "           a IKK",
      "           a IKL",
      "           a IKK",
      "           d IKK",
      "           d IKL",
      "           d IKK",
      "           hikJJ",
      "           a IKK",
      "           a IKL",
      "           a IKK",
      "           d IKK"
    ]
  ]
}