{
  "name": "multi_timbertower_1_base2",
  "refpalette": "deceasedcraft:multi_timbertower_1/multi_timbertower_1_base2_palette",
  "xsize": 16,
  "zsize": 16,
  "slices": [
    [
      "vaavvHHHHHHHHvvv",
      "vaavvHHHHHHHHvvv",
      "vaavvHHHHHHHHvvv",
      "vaavvHHHHHHHHvvv",
      "vaavvHbHHHHHHbvv",
      "vaavvHHHHHHHHvvv",
      "vaavvHHHHHHHHvvv",
      "vaavvHHHHHHHHvvv",
      "vaavvHHHHHHHHvvv",
      "vaavvHHHHHHHHvvv",
      "vaavvHHHHHHHHvvv",
      "vaavvHbHHHHHHbHH",
      "vaavvHHHHHHHHHHH",
      "vaavvHHHHHHHHHHH",
      "vaavvHHHHHHHHHHH",
      "vaavvHHHHHHHHHHH"
    ],
    [
      "vaavcd e     f  ",
      "vaavcg h     fi ",
      "vaavcd e     fj ",
      "vaavcg h     f  ",
      "vaavc bk    lbmn",
      "vaavcd e        ",
      "vaavcg h        ",
      "vaavcd e        ",
      "vaavcg h        ",
      "vaavcd e        ",
      "vaavcg h     ovv",
      "vaavc bk    lb! ",
      "vaavcd e        ",
      "vaavcg h    d e ",
      "vaavcd e    g h ",
      "vaavcg h    d e "
    ],
    [
      "vaav         fp ",
      "vaav         fj ",
      "vaav         f  ",
      "vaav         f  ",
      "vaav  b      bqr",
      "vaav            ",
      "vaav            ",
      "vaav            ",
      "vaav            ",
      "vaav            ",
      "vaav         ovv",
      "vaav  b      b  ",
      "vaav            ",
      "vaav            ",
      "vaav            ",
      "vaav            "
    ],
    [
      "vaav         fjs",
      "vaav         f  ",
      "vaav         f  ",
      "vaav         f  ",
      "vaav  b      btt",
      "vaav            ",
      "vaav            ",
      "vaav            ",
      "vaav            ",
      "vaav            ",
      "vaav         ovv",
      "vaav  b      bu ",
      "vaav            ",
      "vaav            ",
      "vaav            ",
      "vaav            "
    ],
    [
      "vaav         w x",
      "vaav         w s",
      "vaav         w  ",
      "vaav         w  ",
      "vaav  b      btt",
      "vaav            ",
      "vaav            ",
      "vaav            ",
      "vaav            ",
      "vaav            ",
      "vaav         ovv",
      "vaav  b      buu",
      "vaav         u  ",
      "vaav         u  ",
      "vaav            ",
      "vaav            "
    ],
    [
      "vaavvybyyyyyyb  ",
      "vaavvybyyyyyyb x",
      "vaavvybyyyyyyb p",
      "vaavvybyyyyyybip",
      "vaavvybbbbbbbbbb",
      "vaavvybyyyyyybyy",
      "vaavvybyyyyyybyy",
      "vaavvybyyyyyybyy",
      "vaavvybyyyyyybyy",
      "vaavvybyyyyyybyy",
      "vaavvybyyyyyybvv",
      "vaavvybbbbbbbbbb",
      "vaavvybyyyyyyby ",
      "vaavvybyyyyyyby ",
      "vaavvybyyyyyyby ",
      "vaavvybyyyyyyby "
    ]
  ]
}