{
  "name": "multi_timbertower_1_floor13",
  "refpalette": "deceasedcraft:multi_timbertower_1/multi_timbertower_1_floor13_palette",
  "xsize": 16,
  "zsize": 16,
  "slices": [
    [
      "            ab  ",
      "            cb  ",
      "            cbde",
      "            cbff",
      "           ghibb",
      "            abbb",
      "            abbb",
      "            abbb",
      "            cbbb",
      "            cbbb",
      "            cbbb",
      "           ghibb",
      "            abbb",
      "            abbb",
      "            abbb",
      "            cbbb"
    ],
    [
      "            aj  ",
      "            cjd ",
      "            cjk ",
      "            cj  ",
      "           ghicl",
      "            am  ",
      "            am  ",
      "            am  ",
      "            cm  ",
      "            cm  ",
      "            cm  ",
      "           ghinn",
      "            amo ",
      "            am  ",
      "            am p",
      "            cmqr"
    ],
    [
      "            ajf ",
      "            cjk ",
      "            cj  ",
      "            cj  ",
      "           ghics",
      "            am  ",
      "            am  ",
      "            am  ",
      "            cm  ",
      "            cm  ",
      "            cm  ",
      "           ghinn",
      "            am  ",
      "            am  ",
      "            am  ",
      "            cm  "
    ],
    [
      "            ajkt",
      "            cj  ",
      "            cj  ",
      "            cj  ",
      "           ghicc",
      "            am  ",
      "            am  ",
      "            am  ",
      "            cm  ",
      "            cm  ",
      "            cm  ",
      "           ghinn",
      "            am  ",
      "            am  ",
      "            am  ",
      "            cm  "
    ],
    [
      "            au e",
      "            cu t",
      "            cu  ",
      "            cu  ",
      "           ghicc",
      "            au  ",
      "            au  ",
      "            au  ",
      "            cu  ",
      "            cu  ",
      "            cu  ",
      "           ghinn",
      "            au  ",
      "            au  ",
      "            au  ",
      "            cu  "
    ],
    [
      "            aw  ",
      "            cw e",
      "            cw f",
      "            cwdf",
      "           ghixx",
      "            aw  ",
      "            aw  ",
      "            aw  ",
      "            cw  ",
      "            cw  ",
      "            cwyy",
      "           ghixx",
      "            awAA",
      "            aw  ",
      "            aw  ",
      "            cw  "
    ]
  ]
}