{
  "name": "multi_timbertower_1_floor7",
  "refpalette": "deceasedcraft:multi_timbertower_1/multi_timbertower_1_floor7_palette",
  "xsize": 16,
  "zsize": 16,
  "slices": [
    [
      "           abc  ",
      "           dbc  ",
      "           dbcef",
      "           dbcgg",
      "           hijcc",
      "           abccc",
      "           abccc",
      "           abckk",
      "           dbcll",
      "           dbcll",
      "           dbcll",
      "           hijll",
      "           abcll",
      "           abcll",
      "           abcll",
      "           dbcll"
    ],
    [
      "             m  ",
      "             me ",
      "           d mn ",
      "           d m  ",
      "           hijdo",
      "             p  ",
      "           a p  ",
      "           a p  ",
      "           d p  ",
      "           d p  ",
      "             p  ",
      "           hij  ",
      "           a p  ",
      "           a p  ",
      "             p  ",
      "             p  "
    ],
    [
      "             mg ",
      "             mn ",
      "           d m  ",
      "           d m  ",
      "           hijdq",
      "                ",
      "           a    ",
      "           a    ",
      "           d    ",
      "           d    ",
      "                ",
      "           hij  ",
      "           a    ",
      "           a    ",
      "                ",
      "                "
    ],
    [
      "             mnr",
      "             m  ",
      "           d m  ",
      "             m  ",
      "           hijdd",
      "                ",
      "           a    ",
      "                ",
      "                ",
      "           d    ",
      "                ",
      "           hij  ",
      "                ",
      "           a    ",
      "               s",
      "                "
    ],
    [
      "             p f",
      "             p r",
      "           d p  ",
      "             p  ",
      "           hijdd",
      "             p  ",
      "           a p  ",
      "             p  ",
      "             p  ",
      "           d p  ",
      "             p  ",
      "           hij  ",
      "             p  ",
      "           a p  ",
      "             p s",
      "             p  "
    ],
    [
      "             t  ",
      "             t f",
      "           d t g",
      "             teg",
      "           hijuu",
      "             t  ",
      "           a t  ",
      "             t  ",
      "             t  ",
      "           d t  ",
      "             t  ",
      "           hij  ",
      "             t  ",
      "           a t  ",
      "             t w",
      "             t  "
    ]
  ]
}