{
  "name": "multi_timbertower_1_floor3",
  "refpalette": "deceasedcraft:multi_timbertower_1/multi_timbertower_1_floor3_palette",
  "xsize": 16,
  "zsize": 16,
  "slices": [
    [
      "           abc  ",
      "           dbc  ",
      "           dbcef",
      "           dbcgg",
      "          hijkcc",
      "           abccc",
      "           abccc",
      "           abccc",
      "           dbccc",
      "           dbccc",
      "           dbccc",
      "          hijkcc",
      "           abcll",
      "           abcll",
      "           abcll",
      "           dbcll"
    ],
    [
      "           a m  ",
      "           d me ",
      "           d mn ",
      "           d m  ",
      "          hi kdo",
      "           a p  ",
      "           a p  ",
      "           a pqr",
      "           d p  ",
      "           d p s",
      "           d ptu",
      "          hi kww",
      "           a p x",
      "           a px ",
      "           a p x",
      "           d p  "
    ],
    [
      "           a mg ",
      "           d mn ",
      "           d m  ",
      "           d m  ",
      "          hi kdy",
      "           a p  ",
      "           a p  ",
      "           a pAA",
      "           d p  ",
      "           d p  ",
      "           d pBC",
      "          hi kDD",
      "           a p  ",
      "           a p  ",
      "           a p  ",
      "           d p  "
    ],
    [
      "           a mnE",
      "           d m  ",
      "           d m  ",
      "           d m  ",
      "          hi kdd",
      "           a p  ",
      "           a p  ",
      "           a p  ",
      "           d p  ",
      "           d p  ",
      "           d p  ",
      "          hi kFF",
      "           a p  ",
      "           a p  ",
      "           a p  ",
      "           d p  "
    ],
    [
      "           a I f",
      "           d I E",
      "           d I  ",
      "           d I  ",
      "          hi kdd",
      "           a J  ",
      "           a K  ",
      "           a J  ",
      "           d K  ",
      "           d J  ",
      "           d K  ",
      "          hi k  ",
      "           a J  ",
      "           a K  ",
      "           a J  ",
      "           d K  "
    ],
    [
      "           a L  ",
      "           d L f",
      "           d L g",
      "           d Leg",
      "          hiMkNN",
      "           a LOO",
      "           a LOP",
      "           a LOO",
      "           d LOO",
      "           d LOQ",
      "           d LOO",
      "          hiMkNN",
      "           a L  ",
      "           a L  ",
      "           a L  ",
      "           d L  "
    ]
  ]
}