{
  "name": "multi_planecrash1_3_floor1",
  "refpalette": "deceasedcraft:multi_planecrash1_3/multi_planecrash1_3_floor1_palette",
  "xsize": 16,
  "zsize": 16,
  "slices": [
    [
      "aaaaaaaaaaaaaaaa",
      "aaaaaaaaaaaaaaaa",
      "aaaaaaaaaaaaaaaa",
      "aaaaaaaaaaaaaaaa",
      "aaaaaaaaaaaaaaaa",
      "aaaaaaaaaaaaaaaa",
      "aaabaaaaaaaaaaaa",
      "aacdcaaaaaaaaaaa",
      "aacdcaaaaaaaaaaa",
      "aacdcaaaaaaaaaaa",
      "acdddcaaaaaaaaaa",
      "acdddcaaaaaaaaaa",
      "acdddcaaaaaaaaaa",
      "acdddcaaaaaaaaaa",
      "cedddcaaaaaaaaaa",
      "cedddfcaaaaaaaaa"
    ],
    [
      "aaaaaaaaaaaaaaaa",
      "aaaaaaaaaaaaaaaa",
      "aaaaaaaaaaaaaaaa",
      "aaaaaaaaaaaaaaaa",
      "aaagaaaaaaaaaaaa",
      "aaahaaaaaaaaaaaa",
      "aaihjaaaaaaaaaaa",
      "aahkhaaaaaaaaaaa",
      "aahlhaaaaaaaaaaa",
      "aahmhaaaaaaaaaaa",
      "aihnhjaaaaaaaaaa",
      "aionhjaaaaaaaaaa",
      "apqrqsaaaaaaaaaa",
      "ahaaahaaaaaaaaaa",
      "atuaaaaaaaaaaaaa",
      "ahvawhaaaaaaaaaa"
    ],
    [
      "aaaaaaaaaaaaaaaa",
      "aaaaaaaaaaaaaaaa",
      "aaaaaaaaaaaaaaaa",
      "aaaaaaaaaaaaaaaa",
      "aaaaaaaaaaaaaaaa",
      "aaaxaaaaaaaaaaaa",
      "aaayaaaaaaaaaaaa",
      "aazhAaaaaaaaaaaa",
      "aahBhaaaaaaaaaaa",
      "aiCaDjaaaaaaaaaa",
      "aiEFEjaaaaaaaaaa",
      "ahGahhaaaaaaaaaa",
      "ahaHahaaaaaaaaaa",
      "ahIaJhaaaaaaaaaa",
      "aKaaaaaaaaaaaaaa",
      "ahaaahaaaaaaaaaa"
    ],
    [
      "aaaaaaaaaaaaaaaa",
      "aaaaaaaaaaaaaaaa",
      "aaaaaaaaaaaaaaaa",
      "aaaaaaaaaaaaaaaa",
      "aaaaaaaaaaaaaaaa",
      "aaaaaaaaaaaaaaaa",
      "aaaaaaaaaaaaaaaa",
      "aaaaaaaaaaaaaaaa",
      "aaLMNaaaaaaaaaaa",
      "aaMaOaaaaaaaaaaa",
      "aLMPMNaaaaaaaaaa",
      "aihahjaaaaaaaaaa",
      "azsQpAaaaaaaaaaa",
      "azsRpAaaaaaaaaaa",
      "azsSpAaaaaaaaaaa",
      "azsTpAaaaaaaaaaa"
    ],
    [
      "aaaaaaaaaaaaaaaa",
      "aaaaaaaaaaaaaaaa",
      "aaaaaaaaaaaaaaaa",
      "aaaaaaaaaaaaaaaa",
      "aaaaaaaaaaaaaaaa",
      "aaaaaaaaaaaaaaaa",
      "aaaaaaaaaaaaaaaa",
      "aaaaaaaaaaaaaaaa",
      "aaaaaaaaaaaaaaaa",
      "aaaxaaaaaaaaaaaa",
      "aaxxxaaaaaaaaaaa",
      "aaxxxaaaaaaaaaaa",
      "aaxyxaaaaaaaaaaa",
      "aaxhxaaaaaaaaaaa",
      "aaxhxaaaaaaaaaaa",
      "aaxhxaaaaaaaaaaa"
    ],
    [
      "aaaaaaaaaaaaaaaa",
      "aaaaaaaaaaaaaaaa",
      "aaaaaaaaaaaaaaaa",
      "aaaaaaaaaaaaaaaa",
      "aaaaaaaaaaaaaaaa",
      "aaaaaaaaaaaaaaaa",
      "aaaaaaaaaaaaaaaa",
      "aaaaaaaaaaaaaaaa",
      "aaaaaaaaaaaaaaaa",
      "aaaaaaaaaaaaaaaa",
      "aaaaaaaaaaaaaaaa",
      "aaaaaaaaaaaaaaaa",
      "aaaaaaaaaaaaaaaa",
      "aaaaaaaaaaaaaaaa",
      "aaaaaaaaaaaaaaaa",
      "aaaaaaaaaaaaaaaa"
    ]
  ]
}