{
  "name": "multi_planecrash1_3_ground",
  "refpalette": "deceasedcraft:multi_planecrash1_3/multi_planecrash1_3_ground_palette",
  "xsize": 16,
  "zsize": 16,
  "slices": [
    [
      "aabbbaaaaaaaaaaa",
      "abbbbbaaaaaaaaaa",
      "bbbbbbbaaaaaaaaa",
      "bbbbbbbbaaaaaaaa",
      "bbbbbbbbbaaaaaaa",
      "bbbbbbbbbbaaaaaa",
      "bbbbbbbbbbbaaaaa",
      "bbbbbbbbbbbbaaaa",
      "bbbbbbbbbbbbaaaa",
      "bbbbbbbbbbbbaaaa",
      "bbbbbbbbbbbbbaaa",
      "bbbbbbbbbbbbbaaa",
      "bbbbbbbbbbbbbaaa",
      "bbbbbbbbbbbbbaaa",
      "bbbbbbcbbbbbbaaa",
      "bbbbbbbbbbbbbbaa"
    ],
    [
      "aaaaaaaaaaaaaaaa",
      "aaaaaaaaaaaaaaaa",
      "aaaaaaaaaaaaaaaa",
      "aaaaaaaaaaaaaaaa",
      "aaaaaaaaaaaaaaaa",
      "aaaaaaaaaaaaaaaa",
      "aaaaaaaaaaaaaaaa",
      "aabbbaaaaaaaaaaa",
      "aabbbaaaaaaaaaaa",
      "aabbbaaaaaaaaaaa",
      "abbbbbaaaaaaaaaa",
      "abbbbbaaaaaaaaaa",
      "abbbbbaaaaaaaaaa",
      "abbbbbaaaaaaaaaa",
      "bbbbbbaaaaaaaaaa",
      "bbbbbbbaaaaaaaaa"
    ],
    [
      "aaaaaaaaaaaaaaaa",
      "aaaaaaaaaaaaaaaa",
      "aaaaaaaaaaaaaaaa",
      "aaaaaaaaaaaaaaaa",
      "aaaaaaaaaaaaaaaa",
      "aaaaaaaaaaaaaaaa",
      "aaaaaaaaaaaaaaaa",
      "aabbbaaaaaaaaaaa",
      "aabbbaaaaaaaaaaa",
      "aabbbaaaaaaaaaaa",
      "abbbbbaaaaaaaaaa",
      "abbbbbaaaaaaaaaa",
      "abbbbbaaaaaaaaaa",
      "abbbbbaaaaaaaaaa",
      "bbbbbbaaaaaaaaaa",
      "bbbbbbbaaaaaaaaa"
    ],
    [
      "aaaaaaaaaaaaaaaa",
      "aaaaaaaaaaaaaaaa",
      "aaaaaaaaaaaaaaaa",
      "aaaaaaaaaaaaaaaa",
      "aaaaaaaaaaaaaaaa",
      "aaaaaaaaaaaaaaaa",
      "aaaaaaaaaaaaaaaa",
      "aabbbaaaaaaaaaaa",
      "aabbbaaaaaaaaaaa",
      "aabbbaaaaaaaaaaa",
      "abbbbbaaaaaaaaaa",
      "abbbbbaaaaaaaaaa",
      "abbbbbaaaaaaaaaa",
      "abbbbbaaaaaaaaaa",
      "bbbbbbaaaaaaaaaa",
      "bbbbbbbaaaaaaaaa"
    ],
    [
      "aaaaaaaaaaaaaaaa",
      "aaaaaaaaaaaaaaaa",
      "aaaaaaaaaaaaaaaa",
      "aaaaaaaaaaaaaaaa",
      "aaaaaaaaaaaaaaaa",
      "aaaaaaaaaaaaaaaa",
      "aaaaaaaaaaaaaaaa",
      "aabbbaaaaaaaaaaa",
      "aabbbaaaaaaaaaaa",
      "aabbbaaaaaaaaaaa",
      "abbbbbaaaaaaaaaa",
      "abbbbbaaaaaaaaaa",
      "abbbbbaaaaaaaaaa",
      "abbbbbaaaaaaaaaa",
      "bbbbbbaaaaaaaaaa",
      "bbbbbbbaaaaaaaaa"
    ],
    [
      "aaaaaaaaaaaaaaaa",
      "aaaaaaaaaaaaaaaa",
      "aaaaaaaaaaaaaaaa",
      "aaaaaaaaaaaaaaaa",
      "aaaaaaaaaaaaaaaa",
      "aaaaaaaaaaaaaaaa",
      "aaaaaaaaaaaaaaaa",
      "aabbbaaaaaaaaaaa",
      "aabbbaaaaaaaaaaa",
      "aabbbaaaaaaaaaaa",
      "abbbbbaaaaaaaaaa",
      "abbbbbaaaaaaaaaa",
      "abbbbbaaaaaaaaaa",
      "abbbbbaaaaaaaaaa",
      "bbbbbbaaaaaaaaaa",
      "bbbbbbbaaaaaaaaa"
    ]
  ]
}