{
  "name": "multi_filmworkstower_12_base1",
  "refpalette": "deceasedcraft:multi_filmworkstower_12/multi_filmworkstower_12_base1_palette",
  "xsize": 16,
  "zsize": 16,
  "slices": [
    [
      "vvvvvvvvvvvvvvvv",
      "aaaaaaaaaaaaaaaa",
      "bbbbbbbbbbbbbbbb",
      "cccccdcccccccccc",
      "cccccccccccccccc",
      "cccccccccccccccc",
      "cccccccccccccccc",
      "cceccccccccccccc",
      "ffffffffffffffff",
      "                ",
      "                ",
      "                ",
      "                ",
      "                ",
      " g              ",
      " gh   iiij   kii"
    ],
    [
      "vvvvvvvvvvvvvvvv",
      "aaaaaaaaaaaaaaaa",
      "bbbbbbbbbbbbbbbb",
      "     dll ll ll l",
      "      ll ll ll l",
      "                ",
      "                ",
      "  e             ",
      "ffffffffffffffff",
      "                ",
      "                ",
      "                ",
      "                ",
      "                ",
      " g              ",
      " ghm niij     ki"
    ],
    [
      "vvvvvvvvvvvvvvvv",
      "aaaaaaaaaaaaaaaa",
      "bbbbbbbbbbbbbbbb",
      "     opq pq pq p",
      "      rs rs rs r",
      "                ",
      "                ",
      "  e             ",
      "ffffffffffffffff",
      "                ",
      "                ",
      "                ",
      "                ",
      "                ",
      " g              ",
      " ghttiij       k"
    ],
    [
      "vvvvvvvvvvvvvvvv",
      "aaaaaaaaaaaaaaaa",
      "bbbbbbbbbbbbbbbb",
      "      uwxuw uwxu",
      "      yA yA yA y",
      "                ",
      "                ",
      "eeeeeeeeeeeeeeee",
      "ffffffffffffffff",
      "                ",
      "                ",
      "                ",
      "                ",
      "                ",
      "                ",
      " BhCnij         "
    ],
    [
      "vvvvvvvvvvvvvvvv",
      "aaaaaaaaaaaaaaaa",
      "bbbbbbbbbbbbbbbb",
      "DDDDDDDDDDDfDDDD",
      "DDDDDDDDDDDfDDDD",
      "DDDDDDDDDDDfDDDD",
      "DDDDDDDDDDDfDDDD",
      "DDDDDDDDDDDfDDDD",
      "ffffffffffffffff",
      "EEEEEEEEEEEEEEEE",
      "EEEEEEEEEEEEEEEE",
      "EEEEEEEEEEEEEEEE",
      "EEEEEEEEEEEEEEEE",
      "EEEEEEEEEEEEEEEE",
      "EEEEEEEEEEEEEEEE",
      "EEFEiiEEEEEEEEEE"
    ],
    [
      "vvvvvvvvvvvvvvvv",
      "aaaaaaaaaaaaaaaa",
      "bbbbbbbbbbbbbbbb",
      "iiiiiiiiiiiiiiii",
      "iiiiiiiiiiiiiiii",
      "iiiiiiiiiiiiiiii",
      "iiiiiiiiiiiiiiii",
      "iiiiiiiiiiiiiiii",
      "iiiiiiiiiiiiiiii",
      "iiiiiiiiiiiiiiii",
      "iiiiiiiiiiiiiiii",
      "iiiiiiiiiiiiiiii",
      "iiiiiiiiiiiiiiii",
      "iiiiiiiiiiiiiiii",
      "iiiiiiiiiiiiiiii",
      "i iiiiiiiiiiiiii"
    ]
  ]
}