{
  "name": "multi_filmworkstower_12_base2",
  "refpalette": "deceasedcraft:multi_filmworkstower_12/multi_filmworkstower_12_base2_palette",
  "xsize": 16,
  "zsize": 16,
  "slices": [
    [
      "vvvvvvvvvvvvvvvv",
      "aaaaaaaaaaaaaaaa",
      "bbbbbbbbbbbbbbbb",
      "cccccccccccdcccc",
      "cccccccccccdcccc",
      "cccccccccccdcccc",
      "cccccccccccdcccc",
      "cccccccccccdcccc",
      "dddddddddddddddd",
      "dddddddddddddddd",
      "dddddddddddddddd",
      "dddddddddddddddd",
      "dddddddddddddddd",
      "dddddddddddddddd",
      "eedddddddddddddd",
      " edddddddfffffdd"
    ],
    [
      "vvvvvvvvvvvvvvvv",
      "aaaaaaaaaaaaaaaa",
      "bbbbbbbbbbbbbbbb",
      "    ghigj  j! jg",
      "        k  j  l ",
      "jmj     jjjjjjj ",
      "j nj    o  j  p ",
      "j qj    j  jr j ",
      "jjjjjstjjjjjjjjj",
      "                ",
      "                ",
      "                ",
      "                ",
      "                ",
      "ue              ",
      " ewx    yfffffA "
    ],
    [
      "vvvvvvvvvvvvvvvv",
      "aaaaaaaaaaaaaaaa",
      "bbbbbbbbbbbbbbbb",
      "   B CCDjEFjIJjK",
      "        L MjN O ",
      "jPjQ    jjjjjjj ",
      "j  j    R FjI S ",
      "jT j    jUMjNVj ",
      "jjjjjWXjjjjjjjjj",
      "                ",
      "                ",
      "                ",
      "                ",
      "                ",
      " e              ",
      " ew     fffffff "
    ],
    [
      "vvvvvvvvvvvvvvvv",
      "aaaaaaaaaaaaaaaa",
      "bbbbbbbbbbbbbbbb",
      "    YZZ0j 1j2 jY",
      "        3 4j5 6 ",
      "j7j     jjjjjjj ",
      "j  j    3 1j2 6 ",
      "j8 j    j 4j5 j ",
      "jjjjj9#jjjjjjjjj",
      "                ",
      "                ",
      "                ",
      "                ",
      "                ",
      " e              ",
      " ew    yfffffffA"
    ],
    [
      "vvvvvvvvvvvvvvvv",
      "aaaaaaaaaaaaaaaa",
      "bbbbbbbbbbbbbbbb",
      "        j  j  j ",
      "        j $j% j ",
      "jjj     jjjjjjj ",
      "j  j    j ^j& j ",
      "j  j    j *j  j ",
      "jjjjjjjjjjjjjjjj",
      "                ",
      "                ",
      "                ",
      "                ",
      "                ",
      " e              ",
      " ew(   fffffffff"
    ],
    [
      "vvvvvvvvvvvvvvvv",
      "aaaaaaaaaaaaaaaa",
      "bbbbbbbbbbbbbbbb",
      ")))))))))))j))))",
      ")))))))))))j))))",
      ")))))))))))j))))",
      ")))))))))))j+)))",
      "))-))))))))j))))",
      "jjjjjjjjjjjjjjjj",
      "                ",
      "                ",
      "                ",
      "                ",
      "                ",
      " e              ",
      " ew   yfff[]{fff"
    ]
  ]
}