{
  "name": "multi_flatlarge_5_floor1",
  "refpalette": "deceasedcraft:multi_flatlarge_5/multi_flatlarge_5_floor1_palette",
  "xsize": 16,
  "zsize": 16,
  "slices": [
    [
      "aaaaaaaaaaaaaaaa",
      "aaaaaaaaaaaaaaaa",
      "bcbbbbbbbbcbbbbb",
      "bcbbbbbbbbcbbbbb",
      "bcbbbbbbbbcbbbbb",
      "bcbbbbbbbbcbbbbb",
      "bcbbbbbbbbcbbbbb",
      "bcbbbbbbbbcbbbbb",
      "dcdddbbbbbcbbbbb",
      "dcdddbbbbbcbbbbb",
      "dcdddbbbbbcbbbbb",
      "dcdddbbbbbcbbbbb",
      "cecccccccceccccc",
      "                ",
      "                ",
      "                "
    ],
    [
      "                ",
      "fgffffffhfgfifff",
      "jck   cl mcn oc ",
      "pcq rsct ucw xcy",
      "pcq rscl mcn ocy",
      "jcA   c  BcC  c ",
      "DcE   F  ocl  I ",
      "cccJccc KLcLK cc",
      "McN OP  QQcQQ  P",
      "RcS OT    c    U",
      "VcV OW   XcY   Z",
      " c  O0   1c2   3",
      "cecO4OOOOcecOOOO",
      "                ",
      "                ",
      "                "
    ],
    [
      "                ",
      "f ffffff5f f6fff",
      " c    c   c   c ",
      " c    c   c   c ",
      " c    c   c   c ",
      " c    c  7c8  c ",
      "DcE   9   c   # ",
      "ccc$ccc   c   cc",
      " c  O     c     ",
      " c  O     c     ",
      "VcV O     c     ",
      "%c^ O &*( c (*& ",
      "cec)4O)))cec)))O",
      "                ",
      "                ",
      "                "
    ],
    [
      "                ",
      "f ffffff+f f+fff",
      " c    c-  c  [c ",
      " c    c-  c  [c ",
      " c    c-  c  [c ",
      " c    c   c   c ",
      "DcE   ]   c   { ",
      "ccc+ccc   c   cc",
      "}c| O     c     ",
      " c  O     c     ",
      " c  O     c     ",
      ";c: O '<> c ><' ",
      "cec)4O)))cec)))O",
      "                ",
      "                ",
      "                "
    ],
    [
      "                ",
      "f ffffffff fffff",
      " c    c   c   c ",
      " c    c   c   c ",
      " c    c   c   c ",
      " c    c   c   c ",
      " c    c   c   c ",
      "ccccccc   c   cc",
      ",c,,c     c     ",
      ",c,,c     c     ",
      ",c,,c     c     ",
      ",c,,c     c     ",
      "cecccccccceccccc",
      "                ",
      "                ",
      "                "
    ],
    [
      "................",
      "????????????????",
      "acaaaaaaaacaaaaa",
      "acaaaaaaaacaaaaa",
      "acaaaaaaaacaaaaa",
      "acaaaaaaaacaaaaa",
      "acaaaaaaaacaaaaa",
      "acaaaaaaaacaaaaa",
      " c  aaaaaacaaaaa",
      "/c/ aaaaaacaaaaa",
      " c  aaaaaacaaaaa",
      "acaaaaaaaacaaaaa",
      "`e````````e`````",
      "                ",
      "                ",
      "                "
    ]
  ]
}