{
  "name": "multi_flatlarge_5_ground",
  "refpalette": "deceasedcraft:multi_flatlarge_5/multi_flatlarge_5_ground_palette",
  "xsize": 16,
  "zsize": 16,
  "slices": [
    [
      "aaaaaaaaaaaaaaaa",
      "babbbbbbbbabbbbb",
      "bbbbbbbbbbbbbbbb",
      "bbbbbbbbbbbbbbbb",
      "bbbbbbbbbbbbbbbb",
      "bbbbbbbbbbbbbbbb",
      "bbbbbbbbbbbbbbbb",
      "bbbbbbbbbbbbbbbb",
      "bbbbbbbbbbbbbbbb",
      "bbbbbbbbbbbbbbbb",
      "bbbbbbbbbbbbbbbb",
      "babbbbbbbbabbbbb",
      "bccccccccccccccc",
      "dddddddddddddddd",
      "HHHHHHHHHHHHHHHH",
      "HHHHHHHHHHHHHHHH"
    ],
    [
      "eeefefefeffeefff",
      " ghihihihighihih",
      "                ",
      "                ",
      "  jkjkjkjk jkjkj",
      "                ",
      "                ",
      "                ",
      "  hihihihi hihih",
      "                ",
      "                ",
      " gjkjkjkjkgjkjkj",
      " lllllllllllllll",
      "                ",
      "                ",
      "                "
    ],
    [
      "                ",
      " m        m     ",
      "                ",
      "                ",
      "                ",
      "                ",
      "                ",
      "                ",
      "                ",
      "                ",
      "                ",
      " m        m     ",
      "                ",
      "                ",
      "                ",
      "                "
    ],
    [
      "                ",
      " m        m     ",
      "                ",
      "                ",
      "                ",
      "                ",
      "                ",
      "                ",
      "                ",
      "                ",
      "                ",
      " m        m     ",
      "                ",
      "                ",
      "                ",
      "                "
    ],
    [
      "          n     ",
      "omoooooooomppppp",
      " o        o     ",
      " o        o     ",
      " o        o     ",
      " o        o     ",
      " o        o     ",
      " o        o     ",
      " o        o     ",
      " o        o     ",
      " o        o     ",
      "qmqqqqqqqqmqqqqq",
      "                ",
      "                ",
      "                ",
      "                "
    ],
    [
      "rsrrrrrrrrsooooo",
      "ssssssssssssssss",
      "rsrrrrrrrrsrrrrr",
      "rsrrrrrrrrsrrrrr",
      "rsrrrrrrrrsrrrrr",
      "rsrrrrrrrrsrrrrr",
      "rsrrrrrrrrsrrrrr",
      "rsrrrrrrrrsrrrrr",
      "rsrrrrrrrrsrrrrr",
      "rsrrrrrrrrsrrrrr",
      "rsrrrrrrrrsrrrrr",
      "ssssssssssssssss",
      "oooooooooooooooo",
      "                ",
      "                ",
      "                "
    ]
  ]
}