{
  "name": "multi_flatlarge_5_floor3",
  "refpalette": "deceasedcraft:multi_flatlarge_5/multi_flatlarge_5_floor3_palette",
  "xsize": 16,
  "zsize": 16,
  "slices": [
    [
      "aaaaaaaaaaaaaaaa",
      "aaaaaaaaaaaaaaaa",
      "bcbbbbbbbbcbbbbb",
      "bcbbbbbbbbcbbbbb",
      "bcbbbbbbbbcbbbbb",
      "bcbbbbbbbbcbbbbb",
      "bcbbbbbbbbcbbbbb",
      "bcbbbbbbbbcbbbbb",
      "dcdddbbbbbcbbbbb",
      "dcdddbbbbbcbbbbb",
      "dcdddbbbbbcbbbbb",
      "dcdddbbbbbcbbbbb",
      "cecccccccceccccc",
      "                ",
      "                ",
      "                "
    ],
    [
      "                ",
      "fgffffffhfgfifff",
      "jck   cl mcn oc ",
      "pcq rsct ucw xcy",
      "pcq rscl mcn ocy",
      "AcB   c  CcD  c ",
      "EcF   I  ocl  J ",
      "cccKccc LMcNL cc",
      "OcP QR  SScSS  R",
      "TcU QV    c    W",
      "XcX QY   Zc0   1",
      " c  Q2   3c4   5",
      "cecQ6QQQQcecQQQQ",
      "                ",
      "                ",
      "                "
    ],
    [
      "                ",
      "f ffffff7f f8fff",
      " c    c   c   c ",
      " c    c   c   c ",
      " c    c   c   c ",
      " c    c  9c#  c ",
      "EcF   $   c   % ",
      "ccc^ccc   c   cc",
      " c  Q     c     ",
      " c  Q     c     ",
      "XcX Q     c     ",
      "&c* Q ()+ c ()+ ",
      "cec-6Q---cec---Q",
      "                ",
      "                ",
      "                "
    ],
    [
      "                ",
      "f ffffff[f f[fff",
      " c    c]  c  {c ",
      " c    c]  c  {c ",
      " c    c]  c  {c ",
      " c    c   c   c ",
      "EcF   }   c   | ",
      "ccc[ccc   c   cc",
      ";c: Q     c     ",
      " c  Q     c     ",
      " c  Q     c     ",
      "'c< Q >,. c >,. ",
      "cec-6Q---cec---Q",
      "                ",
      "                ",
      "                "
    ],
    [
      "                ",
      "f ffffffff fffff",
      " c    c   c   c ",
      " c    c   c   c ",
      " c    c   c   c ",
      " c    c   c   c ",
      " c    c   c   c ",
      "ccccccc   c   cc",
      "?c??c     c     ",
      "?c??c     c     ",
      "?c??c     c     ",
      "?c??c     c     ",
      "cecccccccceccccc",
      "                ",
      "                ",
      "                "
    ],
    [
      "////////////////",
      "````````````````",
      "acaaaaaaaacaaaaa",
      "acaaaaaaaacaaaaa",
      "acaaaaaaaacaaaaa",
      "acaaaaaaaacaaaaa",
      "acaaaaaaaacaaaaa",
      "acaaaaaaaacaaaaa",
      " c  aaaaaacaaaaa",
      "\u0370c\u0370 aaaaaacaaaaa",
      " c  aaaaaacaaaaa",
      "acaaaaaaaacaaaaa",
      "\u0371e\u0371\u0371\u0371\u0371\u0371\u0371\u0371\u0371e\u0371\u0371\u0371\u0371\u0371",
      "                ",
      "                ",
      "                "
    ]
  ]
}