{
  "name": "multi_taigaresidence_3_floor2",
  "refpalette": "deceasedcraft:multi_taigaresidence_3/multi_taigaresidence_3_floor2_palette",
  "xsize": 16,
  "zsize": 16,
  "slices": [
    [
      "                ",
      "aaaaaaa         ",
      "aaaaaaabbbbbbbb ",
      "aaaaaaacccccccb ",
      "dddddddeeeeeecb ",
      "ddddddddddddecb ",
      "ddddddddddddecb ",
      "ddddddddddddecb ",
      "ddddddddddddecb ",
      "ddddddddddddecb ",
      "ddddddddddddecb ",
      "ddddddddddddecb ",
      "ddddddddddddecb ",
      "ddddddddddddeaaa",
      "ddddddddddddef  ",
      "ggggghddddddef  "
    ],
    [
      "                ",
      "      a         ",
      "      a         ",
      "      accccccc  ",
      "     eeeiiieec  ",
      "  jj  e    kec  ",
      "      l    kec  ",
      "     ee   mkec  ",
      "   n op    kec  ",
      "  nqn p    kec  ",
      "   n  p    kec  ",
      "    n p   mkec  ",
      "  nq np    kec  ",
      "   n  pr   keaaa",
      "     eeeseeee   ",
      "            t   "
    ],
    [
      "                ",
      "      a         ",
      "      a         ",
      "      a         ",
      "     eee   ee   ",
      "     ue    ke   ",
      "      w     e   ",
      "     ee    xe   ",
      "      p    ye   ",
      "      p    ke   ",
      "      p     e   ",
      "      p    xe   ",
      "      p    ye   ",
      "      p    keaaa",
      "     eeeAeeee   ",
      "                "
    ],
    [
      "                ",
      "      a         ",
      "      a         ",
      "      a         ",
      "     eee   ee   ",
      "      e    ke   ",
      "      B     e   ",
      "     ee     e   ",
      "            e   ",
      "           ke   ",
      "            e   ",
      "            e   ",
      "            e   ",
      "           keaaa",
      "     eeeCeeee   ",
      "                "
    ],
    [
      "                ",
      "      a         ",
      "      a         ",
      "DDDDDDaEEEEEEE  ",
      "eeeeeeeeeeeeeE  ",
      "      e    FeE  ",
      "      e    FeE  ",
      "     ee    FeE  ",
      "           FeE  ",
      "           FeE  ",
      "           FeE  ",
      "           FeE  ",
      "           FeE  ",
      "           Feaaa",
      "     eeeeeeee   ",
      "            e   "
    ],
    [
      "                ",
      "      a         ",
      "IIIIIIa         ",
      "e     aJJJJJJJ  ",
      "eeeeeeeeeeeeeJ  ",
      "      eggghKeJ  ",
      "      eggghLeJ  ",
      "MMMMMeeggghNeJ  ",
      "gggggggggghOeJ  ",
      "gPgPgPPPgghQeJ  ",
      "ggPggPgPgghReJ  ",
      "gPgPgPPPgghSeJ  ",
      "gggggggggghTeJ  ",
      "gggggggggghKeaaa",
      "CCCCCeeeeeeee   ",
      "      UUUUUUe   "
    ]
  ]
}