{
  "name": "multi_taigaresidence_3_floor4",
  "refpalette": "deceasedcraft:multi_taigaresidence_3/multi_taigaresidence_3_floor4_palette",
  "xsize": 16,
  "zsize": 16,
  "slices": [
    [
      "                ",
      "      a         ",
      "      abbbbbbbb ",
      "cdddddaeeeeeeeb ",
      "ccfffcccccccceb ",
      "ggggggggggggceb ",
      "ggggggggggggceb ",
      "ggggggggggggceb ",
      "ggggggggggggceb ",
      "ggggggggggggceb ",
      "ggggggggggggceb ",
      "ggggggggggggceb ",
      "ggggggggghhhceb ",
      "ggggggggghhhcaaa",
      "iiiiiiigghhhcd  ",
      "jjjjjkigghhhcd  "
    ],
    [
      "                ",
      "      a         ",
      "      a         ",
      "c     aeeeeeee  ",
      "cc   ccclllcce  ",
      "m     mn   oce  ",
      "mn p qmrs tuce  ",
      "mn p wmrs  xce  ",
      "m    !mn   !ce  ",
      "m     mmmm yce  ",
      "mA       B yce  ",
      "mC    D  m yce  ",
      "mC    Dt mEmce  ",
      "mFIJKLD  m Mcaaa",
      "ccccccc  mNOc   ",
      "      P  B  Q   "
    ],
    [
      "                ",
      "      a         ",
      "      a         ",
      "c     a         ",
      "cc   ccc   cc   ",
      "m    Rm    Sc   ",
      "m     m     c   ",
      "mT    m     c   ",
      "m     m     c   ",
      "mU   Ummmm yc   ",
      "m        V yc   ",
      "mW       m yc   ",
      "m        mXmc   ",
      "m   YZ   m 0caaa",
      "ccccccc  m  c   ",
      "      1  V      "
    ],
    [
      "                ",
      "      a         ",
      "      a         ",
      "c     a         ",
      "cc   ccc   cc   ",
      "m     m     c   ",
      "m     m     c   ",
      "m     m     c   ",
      "m     m     c   ",
      "m     mmmm  c   ",
      "m        m  c   ",
      "m        m  c   ",
      "m        mmmc   ",
      "m  2     m 3caaa",
      "ccccccc  m  c   ",
      "      4  m      "
    ],
    [
      "                ",
      "      a         ",
      "      a         ",
      "c     a5555555  ",
      "ccccccccccccc5  ",
      "m     m     c5  ",
      "m     m     c5  ",
      "m  6 7m     c5  ",
      "m     m     c5  ",
      "m     mmmm  c5  ",
      "m        m  c5  ",
      "m        m  c5  ",
      "m        mmmc5  ",
      "m        m  caaa",
      "ccccccc  m  c   ",
      "      c  m  c   "
    ],
    [
      "                ",
      "      a         ",
      "888888a         ",
      "c     a9999999  ",
      "ccccccccccccc9  ",
      "############c9  ",
      "############c9  ",
      "############c9  ",
      "############c9  ",
      "############c9  ",
      "############c9  ",
      "############c9  ",
      "############c9  ",
      "############caaa",
      "ccccccc#####c   ",
      "      c#####c   "
    ]
  ]
}