{
  "name": "multi_taigaresidence_3_floor1",
  "refpalette": "deceasedcraft:multi_taigaresidence_3/multi_taigaresidence_3_floor1_palette",
  "xsize": 16,
  "zsize": 16,
  "slices": [
    [
      "                ",
      "                ",
      "                ",
      "      a         ",
      "      a         ",
      "      a         ",
      "      a         ",
      "      a         ",
      "      a         ",
      "      a         ",
      "      a     abb ",
      "      a     a   ",
      "      a     a   ",
      "      a     accc",
      "ddddddaaaaaaae  ",
      "fffffghhhhhhae  "
    ],
    [
      "                ",
      "                ",
      "                ",
      "iiiiiiaiiiiiii  ",
      "aaaaaaaaaaaaai  ",
      "      a     ai  ",
      "      a     ai  ",
      "      a     ai  ",
      "      a     ai  ",
      "      a     ai  ",
      "      a     abb ",
      "      a     a   ",
      "      a     a   ",
      "      a     accc",
      "jjjjjjaaaaaaa   ",
      "      k  l  m   "
    ],
    [
      "                ",
      "                ",
      "                ",
      "      a         ",
      "aaaaaaaaaaaaa   ",
      "      a     a   ",
      "      a     a   ",
      "      a     a   ",
      "      a     a   ",
      "      a     a   ",
      "      a     abb ",
      "      a     a   ",
      "      a     a   ",
      "      a     accc",
      "      aaaaaaa   ",
      "      n  o      "
    ],
    [
      "                ",
      "                ",
      "bbbbbbbbbbbbbbb ",
      "bbbbbbbbbbbbbbb ",
      "aaaaaaaaaaaaabb ",
      "      a     abb ",
      "      a     abb ",
      "      a     abb ",
      "      a     abb ",
      "      a     abb ",
      "      a     abb ",
      "      a     a   ",
      "      a     a   ",
      "      a     accc",
      "      aaaaaaa   ",
      "      a  p      "
    ],
    [
      "                ",
      "                ",
      "                ",
      "                ",
      "aaaaaaaaaaaaa   ",
      "qqqrqqa     a   ",
      "      a     a   ",
      "      a     a   ",
      "      a     a   ",
      "      a     a   ",
      "      a     a   ",
      "      a     a   ",
      "      a     a   ",
      "      a     accc",
      "      aaaaaaa   ",
      "      a  a  a   "
    ],
    [
      "                ",
      "                ",
      "                ",
      "jjjjjjjjjjjjjj  ",
      "aaaaaaaaaaaaaj  ",
      "ssssssatttttaj  ",
      "ssssssatttttaj  ",
      "ssssssatuuutaj  ",
      "ssssssatttttaj  ",
      "ssssssatttttaj  ",
      "ssssssatttttaj  ",
      "ssssssatuuutaj  ",
      "ssssssatttttaj  ",
      "ssssssatttttaccc",
      "jjjjjjaaaaaaa   ",
      "      attttta   "
    ]
  ]
}