{
  "name": "multi_taigaresidence_3_floor7",
  "refpalette": "deceasedcraft:multi_taigaresidence_3/multi_taigaresidence_3_floor7_palette",
  "xsize": 16,
  "zsize": 16,
  "slices": [
    [
      "                ",
      "      a         ",
      "      a         ",
      "bbbbbbaccccccc  ",
      "ddddddddddddec  ",
      "ffffffffffffgc  ",
      "ffffffffffffgc  ",
      "ffffffffffffgc  ",
      "ffffffffffffgc  ",
      "ffffffffffffgc  ",
      "ffffffffffffgc  ",
      "ffffffffffffgc  ",
      "ffffffffffffgc  ",
      "ffffffffffffgaaa",
      "ccccccccccccgh  ",
      "iiiiijkkkkkkgh  "
    ],
    [
      "                ",
      "      aaaaaaaaaa",
      "      aaaaaaaaaa",
      "      lmmmmmmmaa",
      "nnnnnnnnnnnnnmaa",
      "        ooo nmaa",
      "       pqqqrnmaa",
      "   s   pqqqrnmaa",
      "   t   pqqqrnmaa",
      "   t    uuu nmaa",
      "   t  ~     nmaa",
      "tttwttttttt nmaa",
      "          t nmaa",
      "          t nxaa",
      "          t n   ",
      "          t n   "
    ],
    [
      "                ",
      "                ",
      "                ",
      "                ",
      "nnnnnnnnnnnnn   ",
      "            n   ",
      "        yAB n   ",
      "        CDE n   ",
      "        FIJ n   ",
      "            n   ",
      "            n   ",
      "   K        n   ",
      "            n   ",
      "            n   ",
      "            n   ",
      "            n   "
    ],
    [
      "                ",
      "                ",
      "                ",
      "                ",
      "            L   ",
      "                ",
      "        MNO     ",
      "        PQR     ",
      "        STU     ",
      "                ",
      "      ~         ",
      "                ",
      "                ",
      "                ",
      "                ",
      "                "
    ],
    [
      "                ",
      "                ",
      "                ",
      "                ",
      "                ",
      "                ",
      "        VWX     ",
      "        YZ0     ",
      "        123     ",
      "                ",
      "      ~         ",
      "                ",
      "                ",
      "                ",
      "                ",
      "                "
    ],
    [
      "                ",
      "                ",
      "                ",
      "                ",
      "                ",
      "                ",
      "                ",
      "         4      ",
      "                ",
      "                ",
      "      ~         ",
      "                ",
      "                ",
      "                ",
      "                ",
      "                "
    ]
  ]
}