{
  "name": "multi_taigaresidence_3_base2",
  "refpalette": "deceasedcraft:multi_taigaresidence_3/multi_taigaresidence_3_base2_palette",
  "xsize": 16,
  "zsize": 16,
  "slices": [
    [
      "vvvvvvvvvvvvvvvv",
      "aaaaaaaaaaaaaaav",
      "bbbbbbbbbbbbbaav",
      "bcccccbHHHHHbaav",
      "HcccccbHHHHHbaav",
      "HcccccbbbbHHbaav",
      "HcccccbccbHHbaav",
      "bcccccbccbHHbaav",
      "bcccccbccbHHbaav",
      "bcccccbccbHHbaav",
      "bcccccbccbHHbaav",
      "bcccccbccbHHbaav",
      "bcccccbccbHHbaav",
      "bcccccbccbHHbaav",
      "bbbbbbbbbbHHbaav",
      "HHHHHHHHHHHHbaav"
    ],
    [
      "vvvvvvvvvvvvvvvv",
      "aaaaaaaaaaaaaaav",
      "bbbbbbbbbbbbbaav",
      "bdddedbHHHHHbaav",
      "      bHHHHHbaav",
      "     ebbbbHHbaav",
      "    df  gbHHbaav",
      "b    hbigbHHbaav",
      "bj    b  bHHbaav",
      "bj  khblmbHHbaav",
      "b   khb gbHHbaav",
      "bj   hbggbHHbaav",
      "bj    bnnbHHbaav",
      "b!eophbnqbHHbaav",
      "bbbbbbbbbbrrbaav",
      "          rrbaav"
    ],
    [
      "vvvvvvvvvvvvvvvv",
      "aaaaaaaaaaaaaaav",
      "bbbbbbbbbbbbbaav",
      "b  d  bHHHHHbaav",
      "s     bHHHHHbaav",
      "s     bbbbHHbaav",
      "s   kt  gbHHbaav",
      "b     b  bHHbaav",
      "bju  tb  bHHbaav",
      "bju d b  bHHbaav",
      "bw  d b mbrrbaav",
      "bju  ebx brrbaav",
      "bju  tb gb  baav",
      "bwww  bgqb  baav",
      "bbbbbbbbbb  baav",
      "            baav"
    ],
    [
      "vvvvvvvvvvvvvvvv",
      "aaaaaaaaaaaaaaav",
      "bbbbbbbbbbbbbaav",
      "be    bHHHHHbaav",
      "s     bHHHHHbaav",
      "s     bbbbHHbaav",
      "s     byybrrbaav",
      "b    ebyybrrbaav",
      "bA    b  b  baav",
      "bA    b  b  baav",
      "b     b  b  baav",
      "bA    b  b  baav",
      "bA    b  b  baav",
      "b  w eb mb  baav",
      "bbbbbbbbbb  baav",
      "      B     baav"
    ],
    [
      "vvvvvvvvvvvvvvvv",
      "aaaaaaaaaaaaaaav",
      "bbbbbbbbbbbbbaav",
      "bwwwwwbrr   baav",
      "C    wbrr   baav",
      "C    wbrrb  baav",
      "C    wbHHb  baav",
      "b    wbHHb  baav",
      "b    wbDDb  baav",
      "b    wbDDb  baav",
      "b    wbyyb  baav",
      "b    wbyyb  baav",
      "b    wb  b  baav",
      "bwwwwwb  b  baav",
      "bbbbbwbbbb  baav",
      "     wb     baav"
    ],
    [
      "vvvvvvvvvvvvvvvv",
      "aaaaaaaaaaaaaaav",
      "bbbbbbbbbbbbbaav",
      "EEEEEEb     baav",
      "EEEEEEb     baav",
      "EEEEEEb  b  baav",
      "EEEEEEb  b  baav",
      "EEEEEEb  b  baav",
      "EEEEEEbrrb  baav",
      "EEEEEEbrrb  baav",
      "EEEEEEbHHb  baav",
      "EEEEEEbHHb  baav",
      "EEEEEEbDDb  baav",
      "EEEEEEbDDb  baav",
      "EEEEEEbbbbbbbaav",
      "EEEEEEbyyyyybaav"
    ]
  ]
}