{
  "name": "multi_taigaresidence_3_base1",
  "refpalette": "deceasedcraft:multi_taigaresidence_3/multi_taigaresidence_3_base1_palette",
  "xsize": 16,
  "zsize": 16,
  "slices": [
    [
      "vvvvvvvvvvvvvvvv",
      "aaaaaaaaaaaaaaav",
      "bbbbbbbbbbbbbaav",
      "bcccccb     baav",
      "Hcccccb     baav",
      "Hcccccb  b  baav",
      "Hcccccb  b  baav",
      "bcccccb  b  baav",
      "bcccccb  b  baav",
      "bcccccb  b  baav",
      "bcccccb  b  baav",
      "bcccccb  b  baav",
      "bcccccbddbeebaav",
      "bcccccbddbeebaav",
      "bbbbbbbHHbbbbaav",
      "HHHHHHHHHHHHbaav"
    ],
    [
      "vvvvvvvvvvvvvvvv",
      "aaaaaaaaaaaaaaav",
      "bbbbbbbbbbbbbaav",
      "b ffffb     baav",
      "g  hffb     baav",
      "g  i fb  b  baav",
      "g j  kb  b  baav",
      "b   f b  b  baav",
      "bl   kb  beebaav",
      "bl    b  beebaav",
      "b   f b  bmmbaav",
      "bl  nob  bmmbaav",
      "bl   ob  bHHbaav",
      "b kpqob  bHHbaav",
      "bbbbbbb  bddbaav",
      "          ddbaav"
    ],
    [
      "vvvvvvvvvvvvvvvv",
      "aaaaaaaaaaaaaaav",
      "bbbbbbbbbbbbbaav",
      "b  f!fb  eeebaav",
      "g   rjb  eeebaav",
      "g     b  beebaav",
      "g     b  bmmbaav",
      "b   nsb  bmmbaav",
      "blt   b  bHHbaav",
      "blt   b  bHHbaav",
      "bu  nsb  bddbaav",
      "blt f b  bddbaav",
      "blt   b  b  baav",
      "buuu kb  b  baav",
      "bbbbbbb  b  baav",
      "            baav"
    ],
    [
      "vvvvvvvvvvvvvvvv",
      "aaaaaaaaaaaaaaav",
      "bbbbbbbbbbbbbaav",
      "b  i  bmmHHHbaav",
      "g     bmmHHHbaav",
      "g     bmmbHHbaav",
      "g    obeebddbaav",
      "b     beebddbaav",
      "bw   ob  b  baav",
      "bw   ob  b  baav",
      "b     b  b  baav",
      "bw   kb  b  baav",
      "bw    b  b  baav",
      "bk u  b  b  baav",
      "bbbbbbb  b  baav",
      "      x     baav"
    ],
    [
      "vvvvvvvvvvvvvvvv",
      "aaaaaaaaaaaaaaav",
      "bbbbbbbbbbbbbaav",
      "buuuuubdd   baav",
      "y    ubdd   baav",
      "y    ubddb  baav",
      "y    ubHHb  baav",
      "b    ubHHb  baav",
      "b    ubmmb  baav",
      "b    ubmmb  baav",
      "b    ubeeb  baav",
      "b    ubeeb  baav",
      "bk   ub  b  baav",
      "buuuuub  b  baav",
      "bbbbbub  b  baav",
      "     ub     baav"
    ],
    [
      "vvvvvvvvvvvvvvvv",
      "aaaaaaaaaaaaaaav",
      "bbbbbbbbbbbbbaav",
      "AAAAAAb     baav",
      "AAAAAAb     baav",
      "AAAAAAb  b  baav",
      "AAAAAAb  b  baav",
      "AAAAAAb  b  baav",
      "AAAAAAbddb  baav",
      "AAAAAAbddb  baav",
      "AAAAAAbHHb  baav",
      "AAAAAAbHHb  baav",
      "AAAAAAbmmb  baav",
      "AAAAAAbmmb  baav",
      "AAAAAAbbbbbbbaav",
      "AAAAAAbeeeeebaav"
    ]
  ]
}