{
  "name": "multi_taigaresidence_3_floor5",
  "refpalette": "deceasedcraft:multi_taigaresidence_3/multi_taigaresidence_3_floor5_palette",
  "xsize": 16,
  "zsize": 16,
  "slices": [
    [
      "                ",
      "      a         ",
      "      abbbbbbbb ",
      "cdddddaeeeeeeeb ",
      "ccfffcccccccceb ",
      "ggggggggggggceb ",
      "ggggggggggggceb ",
      "ggggggggggggceb ",
      "ggggggggggggceb ",
      "ggggggggggggceb ",
      "ggggggggggggceb ",
      "ggggggggggggceb ",
      "ggggggggghhhceb ",
      "ggggggggghhhcaaa",
      "iiiiiiigghhhcd  ",
      "jjjjjkigghhhcd  "
    ],
    [
      "                ",
      "      a         ",
      "      a         ",
      "c     aeeeeeee  ",
      "cc   ccclllcce  ",
      "mnno pmq rstce  ",
      "mnu  pmw   xce  ",
      "my   AmB C Dce  ",
      "m y  EmFI JKce  ",
      "mL    mmmm Mce  ",
      "mL       JNMce  ",
      "mOP      m Mce  ",
      "mO    Q RmSmce  ",
      "mTUVW XYYm Lcaaa",
      "cccccccQZm0Lc   ",
      "      12QZ0 3   "
    ],
    [
      "                ",
      "      a         ",
      "      a         ",
      "c     a         ",
      "cc   ccc   cc   ",
      "mn4   m44445c   ",
      "my    m    6c   ",
      "m     m    7c   ",
      "m     mF   8c   ",
      "m9    mmmm Mc   ",
      "m#         Mc   ",
      "m$       m Mc   ",
      "m        m%mc   ",
      "m^  & *  m  caaa",
      "ccccccc()m+ c   ",
      "      -0[]0{    "
    ],
    [
      "                ",
      "      a         ",
      "      a         ",
      "c     a         ",
      "cc   ccc   cc   ",
      "m} 44 m 4444c   ",
      "m     m     c   ",
      "m     m     c   ",
      "m     m     c   ",
      "m     mmmm |c   ",
      "m        m  c   ",
      "m;       m :c   ",
      "m        mmmc   ",
      "m        m 'caaa",
      "ccccccc  m  c   ",
      "      <  m {    "
    ],
    [
      "                ",
      "      a         ",
      "      a         ",
      "c     a>>>>>>>  ",
      "ccccccccccccc>  ",
      "m     m     c>  ",
      "m     m     c>  ",
      "m  ,  m     c>  ",
      "m     m     c>  ",
      "m     mmmm  c>  ",
      "m        m  c>  ",
      "m        m  c>  ",
      "m        mmmc>  ",
      "m        m  caaa",
      "ccccccc  m  c   ",
      "      c  m  c   "
    ],
    [
      "                ",
      "      a         ",
      "......a         ",
      "c     a???????  ",
      "ccccccccccccc?  ",
      "////////////c?  ",
      "////////////c?  ",
      "////////////c?  ",
      "////////////c?  ",
      "////////////c?  ",
      "////////////c?  ",
      "////////////c?  ",
      "////////////c?  ",
      "////////////caaa",
      "ccccccc/////c   ",
      "      c/////c   "
    ]
  ]
}