{
  "name": "multi_taigaresidence_3_ground",
  "refpalette": "deceasedcraft:multi_taigaresidence_3/multi_taigaresidence_3_ground_palette",
  "xsize": 16,
  "zsize": 16,
  "slices": [
    [
      "aaaaaaaaaaaaaaaa",
      "aaaaaaaaaaaaaaaa",
      "bbbbbbbbbbbbbaaa",
      "ccccccb     baaa",
      "ccccccb     baaa",
      "ccccccb  d  baaa",
      "ccccccb  d  baaa",
      "ccccccb  b  baaa",
      "ccccccb  b  baaa",
      "ccccccb  b  baaa",
      "ccccccb  b  beea",
      "ccccccb  b  bcaa",
      "ccccccbffb  bcaa",
      "ccccccbffb  bggg",
      "ccccccbHHbbbbaaa",
      "ccccccbHHHHHHHHH"
    ],
    [
      "                ",
      "                ",
      "bbbbbbbbbbbbb h ",
      "iiiiiib     b   ",
      "bbbbbbb     b h ",
      " jkl mb     b   ",
      " jnl mb     b h ",
      " jnl ob     b   ",
      " jpl qb     b h ",
      " j!l rb  d  b   ",
      "sjnl mb  d  bee ",
      "tjul mb  b  b   ",
      "  w  xb  b  b   ",
      "y    Ab  b  bggg",
      "BBBBBcb  bbbb   ",
      "      b         "
    ],
    [
      "                ",
      "                ",
      "              C ",
      "      b         ",
      "      b       C ",
      "  D   b         ",
      "  E  Fb       C ",
      "  I  Fb         ",
      "  D  Fb       C ",
      "  D  Jb         ",
      "  K  Lb     bee ",
      "  D  Mb     b   ",
      "     Nb     b   ",
      "      b     bggg",
      "OOOOOcb  bbbb   ",
      "     Cb         "
    ],
    [
      "                ",
      "                ",
      "              O ",
      "      b         ",
      "      b       O ",
      "     Pb         ",
      "    QRb       O ",
      "    QSb         ",
      "    QTb       O ",
      "     Ub         ",
      "     Vb     bee ",
      "     Vb     b   ",
      "     Wb     b   ",
      "     Wb     bggg",
      "     cb  bbbb   ",
      "      b     X   "
    ],
    [
      "                ",
      "                ",
      "              O ",
      "      b         ",
      "      b       O ",
      "      b         ",
      "     Yb       O ",
      "     Yb         ",
      "     Yb       O ",
      "      b         ",
      "      b     bee ",
      "      b     b   ",
      "      b     b   ",
      "      b     bggg",
      "     cb  bbbb   ",
      "      b     b   "
    ],
    [
      "                ",
      "                ",
      "              Z ",
      "      b         ",
      "      b       Z ",
      "      b         ",
      "      b       Z ",
      "      b         ",
      "      b       Z ",
      "      b         ",
      "      b     bee ",
      "      b     b   ",
      "      b     b   ",
      "      b     bggg",
      "     cbbbbbbb   ",
      "      b00000b   "
    ]
  ]
}