{
  "name": "multi_taigaresidence_3_floor6",
  "refpalette": "deceasedcraft:multi_taigaresidence_3/multi_taigaresidence_3_floor6_palette",
  "xsize": 16,
  "zsize": 16,
  "slices": [
    [
      "                ",
      "      a         ",
      "      abbbbbbbb ",
      "ccccccadddddddb ",
      "eeeeeeeffffffdb ",
      "eeeeeeegggggfdb ",
      "eeeeeeegggggfdb ",
      "eeeeeeegggggfdb ",
      "ggggggggggggfdb ",
      "ggggggggggggfdb ",
      "ggggggggggggfdb ",
      "ggggggggggggfdb ",
      "ggggggggggggfdb ",
      "ggggggggggggfaaa",
      "eeeeeeehhhhhfi  ",
      "jjjjjkehhhhhfi  "
    ],
    [
      "                ",
      "      a         ",
      "      a         ",
      "      addddddd  ",
      "     ffflllffd  ",
      "  mm  f nnn fd  ",
      "      o     fd  ",
      "     ff  pp fd  ",
      "qqr   s tuutfd  ",
      "      s wxxxfd  ",
      "y A   B    Cfd  ",
      "y D   sE  FIfd  ",
      "      sE   Jfd  ",
      "  KKK!sE   !faaa",
      "LffffffssMssf   ",
      "     NfO  PQR   "
    ],
    [
      "                ",
      "      a         ",
      "      a         ",
      "      a         ",
      "     fff   ff   ",
      "     SfS T Sf   ",
      "      U     f   ",
      "     ff     f   ",
      "V    Ss     f   ",
      "      sW    f   ",
      "      X     f   ",
      "      sE   Yf   ",
      "      sE   Zf   ",
      "  001 sE   2faaa",
      "3ffffffss4ssf   ",
      "     df         "
    ],
    [
      "                ",
      "      a         ",
      "      a         ",
      "      a         ",
      "     fff   ff   ",
      "      f     f   ",
      "      5     f   ",
      "     ff     f   ",
      "     6s     f   ",
      "      s     f   ",
      "      s     f   ",
      "      s     f   ",
      "      s     f   ",
      "      s7   8faaa",
      "9ffffffsssssf   ",
      "     df         "
    ],
    [
      "                ",
      "      a         ",
      "      a         ",
      "      a#######  ",
      "fffffffffffff#  ",
      "      f     f#  ",
      "      f     f#  ",
      "     ff  $  f#  ",
      "      s     f#  ",
      "      s     f#  ",
      "$    %s     f#  ",
      "      s  ^  f#  ",
      "      s     f#  ",
      "      s     faaa",
      "fffffffsssssf   ",
      "     &f  ^  f   "
    ],
    [
      "                ",
      "      a         ",
      "******a         ",
      "      a(((((((  ",
      "fffffffffffff(  ",
      "jjjjjjf)))))f(  ",
      "jjjjjjf)))))f(  ",
      "+++++ff)))))f(  ",
      "))))))))))))f(  ",
      "))))))))))))f(  ",
      "))))))))))))f(  ",
      "))))))))))))f(  ",
      "))))))))))))f(  ",
      "))))))))))))faaa",
      "fffffff)))))f   ",
      "      f)))))f   "
    ]
  ]
}