{
  "name": "multi_taigaresidence_3_floor3",
  "refpalette": "deceasedcraft:multi_taigaresidence_3/multi_taigaresidence_3_floor3_palette",
  "xsize": 16,
  "zsize": 16,
  "slices": [
    [
      "                ",
      "      a         ",
      "      abbbbbbbb ",
      "cdddddaeeeeeeeb ",
      "ccfffcccccccceb ",
      "ggggggggggggceb ",
      "ggggggggggggceb ",
      "ggggggggggggceb ",
      "ggggggggggggceb ",
      "ggggggggggggceb ",
      "ggggggggggggceb ",
      "ghhhggggggggceb ",
      "ghhhggggggggceb ",
      "ghhhggggggggcaaa",
      "iiiiiiigghhhcd  ",
      "jjjjjkigghhhcd  "
    ],
    [
      "                ",
      "      a         ",
      "      a         ",
      "c     aeeeeeee  ",
      "cc   ccclllcce  ",
      "mn  opm  !qqce  ",
      "mr  opm     ce  ",
      "m ss  m op  ce  ",
      "mmmm tm opssce  ",
      "mu w xm  mmmce  ",
      "my m Am  B uce  ",
      "mmCm Dm tm yce  ",
      "mE w Fm xm oce  ",
      "mI m Fm Am Jcaaa",
      "ccccKcc DmLmc   ",
      "      M  B  N   "
    ],
    [
      "                ",
      "      a         ",
      "      a         ",
      "c     a         ",
      "cc   ccc   cc   ",
      "m     m     c   ",
      "m     m     c   ",
      "m    Om     c   ",
      "mmmm Pm   Q c   ",
      "mR S  m Ommmc   ",
      "mR m  m  T  c   ",
      "mmUm  m Pm  c   ",
      "m  S  m  m  c   ",
      "m Vm  m  m Wcaaa",
      "ccccXcc YmZmc   ",
      "      0  T 1    "
    ],
    [
      "                ",
      "      a         ",
      "      a         ",
      "c     a         ",
      "cc   ccc   cc   ",
      "m     m     c   ",
      "m     m     c   ",
      "m     m     c   ",
      "mmmm 2m     c   ",
      "m! m  m  mmmc   ",
      "m3 m  m  m  c   ",
      "mmmm  m  m  c   ",
      "m  m  m  m  c   ",
      "m 4m  m  m  caaa",
      "cccc5cc  mmmc   ",
      "      6  m 7    "
    ],
    [
      "                ",
      "      a         ",
      "      a         ",
      "c     a8888888  ",
      "ccccccccccccc8  ",
      "m     m     c8  ",
      "m     m     c8  ",
      "m     m     c8  ",
      "mmmm  m     c8  ",
      "m  m  m  mmmc8  ",
      "m  m  m  m  c8  ",
      "mmmm  m  m  c8  ",
      "m  m  m  m  c8  ",
      "m  m  m  m  caaa",
      "ccccccc  mmmc   ",
      "      c  m  c   "
    ],
    [
      "                ",
      "      a         ",
      "999999a         ",
      "c     a#######  ",
      "ccccccccccccc#  ",
      "$$$$$$$$$$$$c#  ",
      "$$$$$$$$$$$$c#  ",
      "$$$$$$$$$$$$c#  ",
      "$$$$$$$$$$$$c#  ",
      "$$$$$$$$$$$$c#  ",
      "$$$$$$$$$$$$c#  ",
      "$$$$$$$$$$$$c#  ",
      "$$$$$$$$$$$$c#  ",
      "$$$$$$$$$$$$caaa",
      "ccccccc$$$$$c   ",
      "      c$$$$$c   "
    ]
  ]
}