{
  "name": "building_office2b_base1_180",
  "refpalette": "deceasedcraft:building_office2b/building_office2b_base1_palette_180",
  "xsize": 16,
  "zsize": 16,
  "slices": [
    [
      "vvvvvvvvvvvvvvvv",
      "vddddddddddddddv",
      "vdhhhhhhhhhhhhdv",
      "vdhhhhhhhhhhhhdv",
      "vdhhhhhhhhhhhhdv",
      "vdhhhhhhhhhhhhdv",
      "vdhhhhhhhhhhhhdv",
      "vdhhhhhhhhhhhhdv",
      "vdhhhhhhhhhhhhdv",
      "vdhhhhhhhhhhhhdv",
      "vdhhhhhhhhhhhhdv",
      "vdhhhhhhhhhccccv",
      "vdhhhihhhhhcaaav",
      "vdhhhgfeeeecbaav",
      "vddddddddddcbbav",
      "vvvvvvvvvvvvvvvv"
    ],
    [
      "vvvvvvvvvvvvvvvv",
      "vddddddddddddddv",
      "vd    rru!rrrrdv",
      "vdq           dv",
      "vdq           dv",
      "vdq   rurrrurrdv",
      "vdq           dv",
      "vd            dv",
      "vd    rrrrrtrrdv",
      "vdq           dv",
      "vdq           dv",
      "vdq   srrrrrrrrv",
      "vdq  pciccccolnv",
      "vd    mgfeeclk v",
      "vddddddddddc j v",
      "vvvvvvvvvvvvvvvv"
    ],
    [
      "vvvvvvvvvvvvvvvv",
      "vddddddddddddddv",
      "vd    rArrArArdv",
      "vd            dv",
      "vd            dv",
      "vd    rrrrBrrrdv",
      "vd            dv",
      "vd            dv",
      "vd    rrArrrrrdv",
      "vd            dv",
      "vd            dv",
      "vd    yrrrrrrrrv",
      "vd    pccicc   v",
      "vd x  w mgfc   v",
      "vddddddddddc   v",
      "vvvvvvvvvvvvvvvv"
    ],
    [
      "vvvvvvvvvvvvvvvv",
      "vddddddddddddddv",
      "vd    JIIIIIIFdv",
      "vd            dv",
      "vdE           dv",
      "vdD           dv",
      "vd            dv",
      "vd            dv",
      "vd            dv",
      "vd            dv",
      "vdE           dv",
      "vdD    Crrrrrrrv",
      "vd     pcccc   v",
      "vd      w mc   v",
      "vddddddddddco ov",
      "vvvvvvvvvvvvvvvv"
    ],
    [
      "vvvvvvvvvvvvvvvv",
      "vddddddddddddddv",
      "vd    TSR QoQQdv",
      "vd            dv",
      "vdO           dv",
      "vdP           dv",
      "vd            dv",
      "vd            dv",
      "vd            dv",
      "vd            dv",
      "vdO           dv",
      "vdN     Mrrrr!rv",
      "vd      pccc   v",
      "vd        wcL Lv",
      "vddddddddddcKoov",
      "vvvvvvvvvvvvvvvv"
    ],
    [
      "vvvvvvvvvvvvvvvv",
      "vddddddddddddddv",
      "vdUUU X  X  Xodv",
      "vdVUU         dv",
      "vdVUU         dv",
      "vdVUU X  X  X dv",
      "vdVUU         dv",
      "vdUUU         dv",
      "vdUUU Y  X  X dv",
      "vdVUU         dv",
      "vdVUU         dv",
      "vdVUU    Wrrrrrv",
      "vdVUU    pccKKLv",
      "vdUUU      cKLKv",
      "vddddddddddcKKKv",
      "vvvvvvvvvvvvvvvv"
    ]
  ]
}