{
  "name": "building_office2b_floor1",
  "refpalette": "deceasedcraft:building_office2b/building_office2b_floor1_palette",
  "xsize": 16,
  "zsize": 16,
  "slices": [
    [
      "                ",
      "                ",
      "   ababababa    ",
      "   cde  fghc    ",
      "   agh  fgga    ",
      "  iajjjjjajaii  ",
      "  kjjjjjjjjjjl  ",
      "  ijjjjjjjjjji  ",
      "  kjjjjjjjjjjl  ",
      "  ijjjjjjjjjji  ",
      "  kjjjjjjjjjjl  ",
      "  ijjjjjjjjjji  ",
      "  kjjjjjjjjjjl  ",
      "  imimimimimii  ",
      "                ",
      "                "
    ],
    [
      "                ",
      "                ",
      "   ababababa    ",
      "   c    fnoc    ",
      "   a ph fq a    ",
      "  ia rrrrasaii  ",
      "  t         ut  ",
      "  i         wi  ",
      "  tx    y   At  ",
      "  iBCD BCD  Ei  ",
      "  tFIJ FIJ  Kt  ",
      "  i L  MN   Oi  ",
      "  t         Kt  ",
      "  itititititii  ",
      "                ",
      "                "
    ],
    [
      "                ",
      "                ",
      "   ababababa    ",
      "   c    f  c    ",
      "   a  phf  a    ",
      "  ia PPPPaQaii  ",
      "  t         Rt  ",
      "  i          i  ",
      "  t         St  ",
      "  iT!U TVW  Xi  ",
      "  tYZ0 1Z0   t  ",
      "  i         2i  ",
      "  t          t  ",
      "  itititititii  ",
      "                ",
      "                "
    ],
    [
      "                ",
      "                ",
      "   ababababa    ",
      "   c   dg34c    ",
      "   a   pg5 a    ",
      "  ia 6666a7aii  ",
      "  t          t  ",
      "  i          i  ",
      "  t          t  ",
      "  i          i  ",
      "  t          t  ",
      "  i          i  ",
      "  t          t  ",
      "  itititititii  ",
      "                ",
      "                "
    ],
    [
      "                ",
      "                ",
      "   ababababa    ",
      "   c  def  c    ",
      "   a    f  a    ",
      "  iaaaaaaaaaii  ",
      "  t          t  ",
      "  i          i  ",
      "  t          t  ",
      "  i          i  ",
      "  t          t  ",
      "  i          i  ",
      "  t          t  ",
      "  itititititii  ",
      "                ",
      "                "
    ],
    [
      "                ",
      "                ",
      "   ababababa    ",
      "   c8de f9#c    ",
      "   a8   f99a    ",
      "  iaaaaaaaaaii  ",
      "  t999999999$t  ",
      "  i999999999$i  ",
      "  t999999999$t  ",
      "  i99%999%99$i  ",
      "  t999999999$t  ",
      "  i999999999$i  ",
      "  t999999999$t  ",
      "  itititititii  ",
      "                ",
      "                "
    ]
  ]
}