{
  "name": "building_office2b_base1_90",
  "refpalette": "deceasedcraft:building_office2b/building_office2b_base1_palette_90",
  "xsize": 16,
  "zsize": 16,
  "slices": [
    [
      "vvvvvvvvvvvvvvvv",
      "vddddddddddddddv",
      "vdhhhhhhhhhhhhdv",
      "vdhhhhhhhhhhhhdv",
      "vdhhhhhhhhhhhhdv",
      "vdgihhhhhhhhhhdv",
      "vdfhhhhhhhhhhhdv",
      "vdehhhhhhhhhhhdv",
      "vdehhhhhhhhhhhdv",
      "vdehhhhhhhhhhhdv",
      "vdehhhhhhhhhhhdv",
      "vcccchhhhhhhhhdv",
      "vbbachhhhhhhhhdv",
      "vbaachhhhhhhhhdv",
      "vaaacddddddddddv",
      "vvvvvvvvvvvvvvvv"
    ],
    [
      "vvvvvvvvvvvvvvvv",
      "vddddddddddddddv",
      "vd qqqq  qqqq dv",
      "vd            dv",
      "vd            dv",
      "vd p          dv",
      "vdmcs  r  r  rdv",
      "vdgir  r  u  rdv",
      "vdfcr  r  r  udv",
      "vdecr  r  r  !dv",
      "vdecr  r  r  rdv",
      "vcccr  t  u  rdv",
      "v lor  r  r  rdv",
      "vjklr  r  r  rdv",
      "v  nrddddddddddv",
      "vvvvvvvvvvvvvvvv"
    ],
    [
      "vvvvvvvvvvvvvvvv",
      "vddddddddddddddv",
      "vd            dv",
      "vdx           dv",
      "vd            dv",
      "vd            dv",
      "vdwpy  r  r  rdv",
      "vd cr  r  r  Adv",
      "vdmcr  A  r  rdv",
      "vdgir  r  r  rdv",
      "vdfcr  r  B  Adv",
      "vcccr  r  r  rdv",
      "v   r  r  r  Adv",
      "v   r  r  r  rdv",
      "v   rddddddddddv",
      "vvvvvvvvvvvvvvvv"
    ],
    [
      "vvvvvvvvvvvvvvvv",
      "vddddddddddddddv",
      "vd  DE    DE  dv",
      "vd            dv",
      "vd            dv",
      "vd            dv",
      "vd           Jdv",
      "vd pC        Idv",
      "vdwcr        Idv",
      "vd cr        Idv",
      "vdmcr        Idv",
      "vcccr        Idv",
      "vo  r        Idv",
      "v   r        Fdv",
      "vo  rddddddddddv",
      "vvvvvvvvvvvvvvvv"
    ],
    [
      "vvvvvvvvvvvvvvvv",
      "vddddddddddddddv",
      "vd  NO    PO  dv",
      "vd            dv",
      "vd            dv",
      "vd            dv",
      "vd           Tdv",
      "vd           Sdv",
      "vd pM        Rdv",
      "vd cr         dv",
      "vdwcr        Qdv",
      "vcccr        odv",
      "vKL r        Qdv",
      "vo  !        Qdv",
      "voL rddddddddddv",
      "vvvvvvvvvvvvvvvv"
    ],
    [
      "vvvvvvvvvvvvvvvv",
      "vddddddddddddddv",
      "vdUVVVVUUVVVVUdv",
      "vdUUUUUUUUUUUUdv",
      "vdUUUUUUUUUUUUdv",
      "vd            dv",
      "vd     Y  X  Xdv",
      "vd            dv",
      "vd            dv",
      "vd pW  X  X  Xdv",
      "vd cr         dv",
      "vcccr         dv",
      "vKKKr  X  X  Xdv",
      "vKLKr        odv",
      "vKKLrddddddddddv",
      "vvvvvvvvvvvvvvvv"
    ]
  ]
}