{
  "name": "building_office2b_floor2",
  "refpalette": "deceasedcraft:building_office2b/building_office2b_floor2_palette",
  "xsize": 16,
  "zsize": 16,
  "slices": [
    [
      "                ",
      "                ",
      "   ababababa    ",
      "   cde  fghc    ",
      "   agh  fgga    ",
      "  iajjjjjajaii  ",
      "  kjjjjjjjjjjl  ",
      "  ijjjjjjjjjji  ",
      "  kjjjjjjjjjjl  ",
      "  ijjjjjjjjjji  ",
      "  kjjjjjjjjjjl  ",
      "  ijjjjjjjjjji  ",
      "  kjjjjjjjjjjl  ",
      "  imimimimimii  ",
      "                ",
      "                "
    ],
    [
      "                ",
      "                ",
      "   ababababa    ",
      "   c    f!nc    ",
      "   a oh fp a    ",
      "  ia qqqqaraii  ",
      "  s         ts  ",
      "  i     u   wi  ",
      "  sxuy  A   Bs  ",
      "  iCDE CDE  Fi  ",
      "  sIJK IJK  Ls  ",
      "  i M   M   Ni  ",
      "  sO        Ls  ",
      "  isisisisisii  ",
      "                ",
      "                "
    ],
    [
      "                ",
      "                ",
      "   ababababa    ",
      "   c    f  c    ",
      "   a  ohf  a    ",
      "  ia PPPPaQaii  ",
      "  s         Rs  ",
      "  i          i  ",
      "  s         Ss  ",
      "  iTUV xWX  Yi  ",
      "  sZ01 201   s  ",
      "  i         3i  ",
      "  s          s  ",
      "  isisisisisii  ",
      "                ",
      "                "
    ],
    [
      "                ",
      "                ",
      "   ababababa    ",
      "   c   dg45c    ",
      "   a   og6 a    ",
      "  ia 7777a8aii  ",
      "  s          s  ",
      "  i          i  ",
      "  s          s  ",
      "  i          i  ",
      "  s          s  ",
      "  i          i  ",
      "  s          s  ",
      "  isisisisisii  ",
      "                ",
      "                "
    ],
    [
      "                ",
      "                ",
      "   ababababa    ",
      "   c  def  c    ",
      "   a    f  a    ",
      "  iaaaaaaaaaii  ",
      "  s          s  ",
      "  i          i  ",
      "  s          s  ",
      "  i          i  ",
      "  s          s  ",
      "  i          i  ",
      "  s          s  ",
      "  isisisisisii  ",
      "                ",
      "                "
    ],
    [
      "                ",
      "                ",
      "   ababababa    ",
      "   c9de f#$c    ",
      "   a9   f##a    ",
      "  iaaaaaaaaaii  ",
      "  s#########%s  ",
      "  i#########%i  ",
      "  s#########%s  ",
      "  i##^###$##%i  ",
      "  s#########%s  ",
      "  i#########%i  ",
      "  s#########%s  ",
      "  isisisisisii  ",
      "                ",
      "                "
    ]
  ]
}