{
  "name": "building_office2b_floor1_90",
  "refpalette": "deceasedcraft:building_office2b/building_office2b_floor1_palette_90",
  "xsize": 16,
  "zsize": 16,
  "slices": [
    [
      "                ",
      "                ",
      "     ilililili  ",
      "     ijjjjjjji  ",
      "  acaajjjjjjjm  ",
      "  bhgjjjjjjjji  ",
      "  aggajjjjjjjm  ",
      "  bffjjjjjjjji  ",
      "  a  jjjjjjjjm  ",
      "  b  jjjjjjjji  ",
      "  aehjjjjjjjjm  ",
      "  bdgjjjjjjjji  ",
      "  acaajjjjjjjm  ",
      "     ikikikiki  ",
      "                ",
      "                "
    ],
    [
      "                ",
      "                ",
      "     ititititi  ",
      "     iuwAEKOKi  ",
      "  acaa       t  ",
      "  bo s       i  ",
      "  anqa   DJ  t  ",
      "  bffr  yCIN i  ",
      "  a  r   BFM t  ",
      "  b hr       i  ",
      "  a pr   DJ  t  ",
      "  b      CIL i  ",
      "  acaa  xBF  t  ",
      "     ititititi  ",
      "                ",
      "                "
    ],
    [
      "                ",
      "                ",
      "     ititititi  ",
      "     iR SX 2 i  ",
      "  acaa       t  ",
      "  b  Q       i  ",
      "  a  a   W0  t  ",
      "  bffP   VZ  i  ",
      "  a hP   T1  t  ",
      "  b pP       i  ",
      "  a  P   U0  t  ",
      "  b      !Z  i  ",
      "  acaa   TY  t  ",
      "     ititititi  ",
      "                ",
      "                "
    ],
    [
      "                ",
      "                ",
      "     ititititi  ",
      "     i       i  ",
      "  acaa       t  ",
      "  b4 7       i  ",
      "  a35a       t  ",
      "  bgg6       i  ",
      "  adp6       t  ",
      "  b  6       i  ",
      "  a  6       t  ",
      "  b          i  ",
      "  acaa       t  ",
      "     ititititi  ",
      "                ",
      "                "
    ],
    [
      "                ",
      "                ",
      "     ititititi  ",
      "     i       i  ",
      "  acaa       t  ",
      "  b  a       i  ",
      "  a  a       t  ",
      "  bffa       i  ",
      "  ae a       t  ",
      "  bd a       i  ",
      "  a  a       t  ",
      "  b  a       i  ",
      "  acaa       t  ",
      "     ititititi  ",
      "                ",
      "                "
    ],
    [
      "                ",
      "                ",
      "     ititititi  ",
      "     i$$$$$$$i  ",
      "  acaa9999999t  ",
      "  b#9a9999999i  ",
      "  a99a999%999t  ",
      "  bffa9999999i  ",
      "  a  a9999999t  ",
      "  be a9999999i  ",
      "  ad a999%999t  ",
      "  b88a9999999i  ",
      "  acaa9999999t  ",
      "     ititititi  ",
      "                ",
      "                "
    ]
  ]
}