{
  "name": "building_office2b_ground",
  "refpalette": "deceasedcraft:building_office2b/building_office2b_ground_palette",
  "xsize": 16,
  "zsize": 16,
  "slices": [
    [
      "aaaaaaaaaaaaaaaa",
      "abbbbbbbbbbbbbba",
      "abccccccccccccba",
      "abcccd    caacba",
      "abccce    caacba",
      "abccccccccccccba",
      "abccccccccccccba",
      "abccccccccccccba",
      "abccccccccccccba",
      "abccccccccccccba",
      "abccccccccccccba",
      "abccccccccccccba",
      "abccccccccccccba",
      "abccccccccccccba",
      "abbbbbbbbbbbbbba",
      "aaaaaaaaaaaaaaaa"
    ],
    [
      "                ",
      " fg  gg  gg  gf ",
      " ghiihhiihhiihg ",
      "  i  j    klli  ",
      "  i  me   kn i  ",
      " gh  oppppokkhg ",
      " gh          hg ",
      "  i          qr ",
      "  i          sr ",
      " gh   t  t   hg ",
      " gh uwwwwwwu hg ",
      "  i x y  y j i  ",
      "  iAB      CDi  ",
      " ghiihhiihhiihg ",
      " fg  gg  gg  gf ",
      "                "
    ],
    [
      "                ",
      " fg  gg  gg  gf ",
      " ghiihhiihhiihg ",
      "  i          i  ",
      "  i   me   E i  ",
      " gh  oFFFFo  hg ",
      " gh          hg ",
      "  i          I  ",
      "  i          J  ",
      " gh          hg ",
      " gh K L  L M hg ",
      "  i          i  ",
      "  iN        Ni  ",
      " ghiihhiihhiihg ",
      " fg  gg  gg  gf ",
      "                "
    ],
    [
      "                ",
      " fg  gg  gg  gf ",
      " ghiihhiihhiihg ",
      "  i    Oe    i  ",
      "  i    me    i  ",
      " gh  oPPPPo  hg ",
      " gh          hg ",
      "  i     Q    i  ",
      "  i          i  ",
      " gh          hg ",
      " gh          hg ",
      "  i          i  ",
      "  iR        Ri  ",
      " ghiihhiihhiihg ",
      " fg  gg  gg  gf ",
      "                "
    ],
    [
      "                ",
      " fgSSggSSggSSgf ",
      " ghTThhTThhTThg ",
      " SU   OdV  WWXS ",
      " SU     V  WWXS ",
      " ghoooooooooohg ",
      " gh          hg ",
      " SU    YZ    XS ",
      " SU    QY    XS ",
      " gh          hg ",
      " gh          hg ",
      " SU          XS ",
      " SU          XS ",
      " gh00hh00hh00hg ",
      " fgSSggSSggSSgf ",
      "                "
    ],
    [
      "                ",
      " fggggggggggggf ",
      " ggoooooooooggg ",
      " ggooOd 1oooggg ",
      " ggoo   1oooggg ",
      " ggoooooooooggg ",
      " gg2222222222gg ",
      " gg2222332222gg ",
      " gg2222332222gg ",
      " gg2222222222gg ",
      " gg2222222222gg ",
      " gg2222222222gg ",
      " gg2222222222gg ",
      " gggggggggggggg ",
      " fggggggggggggf ",
      "                "
    ]
  ]
}