{
  "name": "building_office2b_top_90",
  "refpalette": "deceasedcraft:building_office2b/building_office2b_top_palette_90",
  "xsize": 16,
  "zsize": 16,
  "slices": [
    [
      "                ",
      "                ",
      "     ikikikiki  ",
      "     illllllli  ",
      "  agaalllllllk  ",
      "  bfffllllllli  ",
      "  affamllllllk  ",
      "  beea!lllllli  ",
      "  a  amllllllk  ",
      "  b  amlllllli  ",
      "  adhamllllllk  ",
      "  b  jllllllli  ",
      "  acaalllllllk  ",
      "     ikikikiki  ",
      "                ",
      "                "
    ],
    [
      "                ",
      "                ",
      "     ikikikiki  ",
      "     iu  D  ui  ",
      "  naaa  wC   k  ",
      "  opqr   CJ  i  ",
      "  npqat wC   k  ",
      "  oeeat  B   i  ",
      "  n  at  A   k  ",
      "  o  at  y   i  ",
      "  n  at  xI Lk  ",
      "  o   s  xF Ki  ",
      "  naaa   xE  k  ",
      "     ikikikiki  ",
      "                ",
      "                "
    ],
    [
      "                ",
      "                ",
      "     ikikikiki  ",
      "     it  V  ti  ",
      "   naa   U   k  ",
      "   o N   T   i  ",
      "   nMa   S   k  ",
      "   o aP  R   i  ",
      "   n a       k  ",
      "   o aP  Q   i  ",
      "   n aP  x   k  ",
      "   o  O  x  Wi  ",
      "   naa   x   k  ",
      "     ikikikiki  ",
      "                ",
      "                "
    ],
    [
      "                ",
      "                ",
      "     iZiZiZiZi  ",
      "     i       i  ",
      "    na       3  ",
      "    ofY      i  ",
      "    na       3  ",
      "    oa       i  ",
      "    na       3  ",
      "    oa       i  ",
      "    na   2   3  ",
      "    of   1   i  ",
      "    na   0   3  ",
      "     iXiXiXiXi  ",
      "                ",
      "                "
    ],
    [
      "                ",
      "                ",
      "     iiiiiiiii  ",
      "     i6444444i  ",
      "     i4444444i  ",
      "     i4444444i  ",
      "     i5444444i  ",
      "     i5444444i  ",
      "     i5444444i  ",
      "     i5444444i  ",
      "     i5444444i  ",
      "     i4444444i  ",
      "     i4444444i  ",
      "     iiiiiiiii  ",
      "                ",
      "                "
    ],
    [
      "                ",
      "                ",
      "     777777777  ",
      "     7888888 7  ",
      "     7  9 98 7  ",
      "     7     8 7  ",
      "     7    #$ 7  ",
      "     7     8 7  ",
      "     7     8 7  ",
      "     7     8 7  ",
      "     7    #$ 7  ",
      "     7     8 7  ",
      "     7     8 7  ",
      "     777777777  ",
      "                ",
      "                "
    ]
  ]
}