{
  "name": "building_office2b_floor3",
  "refpalette": "deceasedcraft:building_office2b/building_office2b_floor3_palette",
  "xsize": 16,
  "zsize": 16,
  "slices": [
    [
      "                ",
      "                ",
      "   ababababa    ",
      "   cde  fghc    ",
      "   agh  fgga    ",
      "  iajaaaaajaii  ",
      "  kllllllllllm  ",
      "  illlllllllli  ",
      "  kllllllllllm  ",
      "  illlllllllli  ",
      "  kllllllllllm  ",
      "  illlllllllli  ",
      "  kllllllllllm  ",
      "  inininininii  ",
      "                ",
      "                "
    ],
    [
      "                ",
      "                ",
      "   ababababa    ",
      "   c    fopc    ",
      "   a qh fr a    ",
      "  iasaaaaataii  ",
      "  u  wxyAB   u  ",
      "  i C      C i  ",
      "  u DD   EDD u  ",
      "  iCDDC E DDCi  ",
      "  u F  DD  C u  ",
      "  i   CDDE   i  ",
      "  u     E    u  ",
      "  iuiuiuiuiuii  ",
      "                ",
      "                "
    ],
    [
      "                ",
      "                ",
      "   ababababa    ",
      "   c    f  c    ",
      "   a  qhf  a    ",
      "  iaIaaaaaJaii  ",
      "  u   KLM    u  ",
      "  i          i  ",
      "  u          u  ",
      "  i          i  ",
      "  u          u  ",
      "  i          i  ",
      "  u          u  ",
      "  iuiuiuiuiuii  ",
      "                ",
      "                "
    ],
    [
      "                ",
      "                ",
      "   ababababa    ",
      "   c   dgNOc    ",
      "   a   qgP a    ",
      "  iaQaaaaaQaii  ",
      "  u          u  ",
      "  i          i  ",
      "  u          u  ",
      "  i          i  ",
      "  u          u  ",
      "  i          i  ",
      "  u          u  ",
      "  iuiuiuiuiuii  ",
      "                ",
      "                "
    ],
    [
      "                ",
      "                ",
      "   ababababa    ",
      "   c  def  c    ",
      "   a    f  a    ",
      "  iaaaaaaaaaii  ",
      "  u          u  ",
      "  i          i  ",
      "  u          u  ",
      "  i          i  ",
      "  u          u  ",
      "  i          i  ",
      "  u          u  ",
      "  iuiuiuiuiuii  ",
      "                ",
      "                "
    ],
    [
      "                ",
      "                ",
      "   ababababa    ",
      "   cRde fSTc    ",
      "   aR   fSSa    ",
      "  iaaaaaaaaaii  ",
      "  uSSSSSSSSSSu  ",
      "  iSSSSSSSSSSi  ",
      "  uSSSSSSSSSSu  ",
      "  iSSTSSSSUSSi  ",
      "  uSSSSSSSSSSu  ",
      "  iSSSSSSSSSSi  ",
      "  uSSSSSSSSSSu  ",
      "  iuiuiuiuiuii  ",
      "                ",
      "                "
    ]
  ]
}