{
  "name": "building_office2b_floor2_90",
  "refpalette": "deceasedcraft:building_office2b/building_office2b_floor2_palette_90",
  "xsize": 16,
  "zsize": 16,
  "slices": [
    [
      "                ",
      "                ",
      "     ilililili  ",
      "     ijjjjjjji  ",
      "  acaajjjjjjjm  ",
      "  bhgjjjjjjjji  ",
      "  aggajjjjjjjm  ",
      "  bffjjjjjjjji  ",
      "  a  jjjjjjjjm  ",
      "  b  jjjjjjjji  ",
      "  aehjjjjjjjjm  ",
      "  bdgjjjjjjjji  ",
      "  acaajjjjjjjm  ",
      "     ikikikiki  ",
      "                ",
      "                "
    ],
    [
      "                ",
      "                ",
      "     isisisisi  ",
      "     itwBFLNLi  ",
      "  acaa       s  ",
      "  bn r       i  ",
      "  a!pa   EK  s  ",
      "  bffq uADJM i  ",
      "  a  q   CI  s  ",
      "  b hq       i  ",
      "  a oq  yEK  s  ",
      "  b     uDJM i  ",
      "  acaa  xCI Os  ",
      "     isisisisi  ",
      "                ",
      "                "
    ],
    [
      "                ",
      "                ",
      "     isisisisi  ",
      "     iR SY 3 i  ",
      "  acaa       s  ",
      "  b  Q       i  ",
      "  a  a   X1  s  ",
      "  bffP   W0  i  ",
      "  a hP   x2  s  ",
      "  b oP       i  ",
      "  a  P   V1  s  ",
      "  b      U0  i  ",
      "  acaa   TZ  s  ",
      "     isisisisi  ",
      "                ",
      "                "
    ],
    [
      "                ",
      "                ",
      "     isisisisi  ",
      "     i       i  ",
      "  acaa       s  ",
      "  b5 8       i  ",
      "  a46a       s  ",
      "  bgg7       i  ",
      "  ado7       s  ",
      "  b  7       i  ",
      "  a  7       s  ",
      "  b          i  ",
      "  acaa       s  ",
      "     isisisisi  ",
      "                ",
      "                "
    ],
    [
      "                ",
      "                ",
      "     isisisisi  ",
      "     i       i  ",
      "  acaa       s  ",
      "  b  a       i  ",
      "  a  a       s  ",
      "  bffa       i  ",
      "  ae a       s  ",
      "  bd a       i  ",
      "  a  a       s  ",
      "  b  a       i  ",
      "  acaa       s  ",
      "     isisisisi  ",
      "                ",
      "                "
    ],
    [
      "                ",
      "                ",
      "     isisisisi  ",
      "     i%%%%%%%i  ",
      "  acaa#######s  ",
      "  b$#a#######i  ",
      "  a##a###$###s  ",
      "  bffa#######i  ",
      "  a  a#######s  ",
      "  be a#######i  ",
      "  ad a###^###s  ",
      "  b99a#######i  ",
      "  acaa#######s  ",
      "     isisisisi  ",
      "                ",
      "                "
    ]
  ]
}