{
  "name": "building_office2b_ground_180",
  "refpalette": "deceasedcraft:building_office2b/building_office2b_ground_palette_180",
  "xsize": 16,
  "zsize": 16,
  "slices": [
    [
      "aaaaaaaaaaaaaaaa",
      "abbbbbbbbbbbbbba",
      "abccccccccccccba",
      "abccccccccccccba",
      "abccccccccccccba",
      "abccccccccccccba",
      "abccccccccccccba",
      "abccccccccccccba",
      "abccccccccccccba",
      "abccccccccccccba",
      "abccccccccccccba",
      "abcaac    ecccba",
      "abcaac    dcccba",
      "abccccccccccccba",
      "abbbbbbbbbbbbbba",
      "aaaaaaaaaaaaaaaa"
    ],
    [
      "                ",
      " fg  gg  gg  gf ",
      " ghiihhiihhiihg ",
      "  iDC      BAi  ",
      "  i j y  y x i  ",
      " gh uwwwwwwu hg ",
      " gh   t  t   hg ",
      " rs          i  ",
      " rq          i  ",
      " gh          hg ",
      " ghkkoppppo  hg ",
      "  i nk   em  i  ",
      "  illk    j  i  ",
      " ghiihhiihhiihg ",
      " fg  gg  gg  gf ",
      "                "
    ],
    [
      "                ",
      " fg  gg  gg  gf ",
      " ghiihhiihhiihg ",
      "  iN        Ni  ",
      "  i          i  ",
      " gh M L  L K hg ",
      " gh          hg ",
      "  J          i  ",
      "  I          i  ",
      " gh          hg ",
      " gh  oFFFFo  hg ",
      "  i E   em   i  ",
      "  i          i  ",
      " ghiihhiihhiihg ",
      " fg  gg  gg  gf ",
      "                "
    ],
    [
      "                ",
      " fg  gg  gg  gf ",
      " ghiihhiihhiihg ",
      "  iR        Ri  ",
      "  i          i  ",
      " gh          hg ",
      " gh          hg ",
      "  i          i  ",
      "  i    Q     i  ",
      " gh          hg ",
      " gh  oPPPPo  hg ",
      "  i    em    i  ",
      "  i    eO    i  ",
      " ghiihhiihhiihg ",
      " fg  gg  gg  gf ",
      "                "
    ],
    [
      "                ",
      " fgSSggSSggSSgf ",
      " gh00hh00hh00hg ",
      " SX          US ",
      " SX          US ",
      " gh          hg ",
      " gh          hg ",
      " SX    YQ    US ",
      " SX    ZY    US ",
      " gh          hg ",
      " ghoooooooooohg ",
      " SXWW  V     US ",
      " SXWW  VdO   US ",
      " ghTThhTThhTThg ",
      " fgSSggSSggSSgf ",
      "                "
    ],
    [
      "                ",
      " fggggggggggggf ",
      " gggggggggggggg ",
      " gg2222222222gg ",
      " gg2222222222gg ",
      " gg2222222222gg ",
      " gg2222222222gg ",
      " gg2222332222gg ",
      " gg2222332222gg ",
      " gg2222222222gg ",
      " gggooooooooogg ",
      " gggooo1   oogg ",
      " gggooo1 dOoogg ",
      " gggooooooooogg ",
      " fggggggggggggf ",
      "                "
    ]
  ]
}