{
  "name": "building_office2b_ground_270",
  "refpalette": "deceasedcraft:building_office2b/building_office2b_ground_palette_270",
  "xsize": 16,
  "zsize": 16,
  "slices": [
    [
      "aaaaaaaaaaaaaaaa",
      "abbbbbbbbbbbbbba",
      "abccccccccccccba",
      "abccccccccccccba",
      "abccccccccccccba",
      "abcccccccccedcba",
      "abccccccccc  cba",
      "abccccccccc  cba",
      "abccccccccc  cba",
      "abccccccccc  cba",
      "abccccccccccccba",
      "abcccccccccaacba",
      "abcccccccccaacba",
      "abccccccccccccba",
      "abbbbbbbbbbbbbba",
      "aaaaaaaaaaaaaaaa"
    ],
    [
      "                ",
      " fg  gg  gg  gf ",
      " ghiihhiihhiihg ",
      "  iA         i  ",
      "  iBxu       i  ",
      " gh  w    omjhg ",
      " gh ywt   pe hg ",
      "  i  w    p  i  ",
      "  i  w    p  i  ",
      " gh ywt   p  hg ",
      " gh  w    okkhg ",
      "  iCju    knli  ",
      "  iD      k li  ",
      " ghiihhsqhhiihg ",
      " fg  ggrrgg  gf ",
      "                "
    ],
    [
      "                ",
      " fg  gg  gg  gf ",
      " ghiihhiihhiihg ",
      "  iN         i  ",
      "  i  K       i  ",
      " gh       o  hg ",
      " gh  L    Fm hg ",
      "  i       Fe i  ",
      "  i       F  i  ",
      " gh  L    F  hg ",
      " gh       o  hg ",
      "  i  M     E i  ",
      "  iN         i  ",
      " ghiihhJIhhiihg ",
      " fg  gg  gg  gf ",
      "                "
    ],
    [
      "                ",
      " fg  gg  gg  gf ",
      " ghiihhiihhiihg ",
      "  iR         i  ",
      "  i          i  ",
      " gh       o  hg ",
      " gh       P  hg ",
      "  i       PmOi  ",
      "  i     Q Peei  ",
      " gh       P  hg ",
      " gh       o  hg ",
      "  i          i  ",
      "  iR         i  ",
      " ghiihhiihhiihg ",
      " fg  gg  gg  gf ",
      "                "
    ],
    [
      "                ",
      " fgSSggSSggSSgf ",
      " ghUUhhUUhhUUhg ",
      " S0       o  TS ",
      " S0       o  TS ",
      " gh       o  hg ",
      " gh       o Ohg ",
      " S0    QY o dTS ",
      " S0    YZ oVVTS ",
      " gh       o  hg ",
      " gh       o  hg ",
      " S0       oWWTS ",
      " S0       oWWTS ",
      " ghXXhhXXhhXXhg ",
      " fgSSggSSggSSgf ",
      "                "
    ],
    [
      "                ",
      " fggggggggggggf ",
      " gggggggggggggg ",
      " gg2222222oooog ",
      " gg2222222oooog ",
      " gg2222222o Oog ",
      " gg2222222o dog ",
      " gg2222332o  og ",
      " gg2222332o11og ",
      " gg2222222oooog ",
      " gg2222222oooog ",
      " gg2222222oooog ",
      " gg2222222ggggg ",
      " gggggggggggggg ",
      " fggggggggggggf ",
      "                "
    ]
  ]
}