{
  "name": "building_office2b_floor2_270",
  "refpalette": "deceasedcraft:building_office2b/building_office2b_floor2_palette_270",
  "xsize": 16,
  "zsize": 16,
  "slices": [
    [
      "                ",
      "                ",
      "  ikikikiki     ",
      "  mjjjjjjjaaca  ",
      "  ijjjjjjjjgdb  ",
      "  mjjjjjjjjhea  ",
      "  ijjjjjjjj  b  ",
      "  mjjjjjjjj  a  ",
      "  ijjjjjjjjffb  ",
      "  mjjjjjjjagga  ",
      "  ijjjjjjjjghb  ",
      "  mjjjjjjjaaca  ",
      "  ijjjjjjji     ",
      "  ilililili     ",
      "                ",
      "                "
    ],
    [
      "                ",
      "                ",
      "  isisisisi     ",
      "  sO ICx  aaca  ",
      "  i MJDu     b  ",
      "  s  KEy  qo a  ",
      "  i       qh b  ",
      "  s  IC   q  a  ",
      "  i MJDAu qffb  ",
      "  s  KE   ap!a  ",
      "  i       r nb  ",
      "  s       aaca  ",
      "  iLNLFBwti     ",
      "  isisisisi     ",
      "                ",
      "                "
    ],
    [
      "                ",
      "                ",
      "  isisisisi     ",
      "  s  ZT   aaca  ",
      "  i  0U      b  ",
      "  s  1V   P  a  ",
      "  i       Po b  ",
      "  s  2x   Ph a  ",
      "  i  0W   Pffb  ",
      "  s  1X   a  a  ",
      "  i       Q  b  ",
      "  s       aaca  ",
      "  i 3 YS Ri     ",
      "  isisisisi     ",
      "                ",
      "                "
    ],
    [
      "                ",
      "                ",
      "  isisisisi     ",
      "  s       aaca  ",
      "  i          b  ",
      "  s       7  a  ",
      "  i       7  b  ",
      "  s       7oda  ",
      "  i       7ggb  ",
      "  s       a64a  ",
      "  i       8 5b  ",
      "  s       aaca  ",
      "  i       i     ",
      "  isisisisi     ",
      "                ",
      "                "
    ],
    [
      "                ",
      "                ",
      "  isisisisi     ",
      "  s       aaca  ",
      "  i       a  b  ",
      "  s       a  a  ",
      "  i       a db  ",
      "  s       a ea  ",
      "  i       affb  ",
      "  s       a  a  ",
      "  i       a  b  ",
      "  s       aaca  ",
      "  i       i     ",
      "  isisisisi     ",
      "                ",
      "                "
    ],
    [
      "                ",
      "                ",
      "  isisisisi     ",
      "  s#######aaca  ",
      "  i#######a99b  ",
      "  s###^###a da  ",
      "  i#######a eb  ",
      "  s#######a  a  ",
      "  i#######affb  ",
      "  s###$###a##a  ",
      "  i#######a#$b  ",
      "  s#######aaca  ",
      "  i%%%%%%%i     ",
      "  isisisisi     ",
      "                ",
      "                "
    ]
  ]
}