{
  "name": "building_office2b_floor3_180",
  "refpalette": "deceasedcraft:building_office2b/building_office2b_floor3_palette_180",
  "xsize": 16,
  "zsize": 16,
  "slices": [
    [
      "                ",
      "                ",
      "  iininininini  ",
      "  mllllllllllk  ",
      "  illlllllllli  ",
      "  mllllllllllk  ",
      "  illlllllllli  ",
      "  mllllllllllk  ",
      "  illlllllllli  ",
      "  mllllllllllk  ",
      "  iiajaaaaajai  ",
      "    aggf  hga   ",
      "    chgf  edc   ",
      "    ababababa   ",
      "                ",
      "                "
    ],
    [
      "                ",
      "                ",
      "  iiuiuiuiuiui  ",
      "  u    E     u  ",
      "  i   EDDC   i  ",
      "  u C  DD  F u  ",
      "  iCDD E CDDCi  ",
      "  u DDE   DD u  ",
      "  i C      C i  ",
      "  u   BAyxw  u  ",
      "  iiataaaaasai  ",
      "    a rf hq a   ",
      "    cpof    c   ",
      "    ababababa   ",
      "                ",
      "                "
    ],
    [
      "                ",
      "                ",
      "  iiuiuiuiuiui  ",
      "  u          u  ",
      "  i          i  ",
      "  u          u  ",
      "  i          i  ",
      "  u          u  ",
      "  i          i  ",
      "  u    MLK   u  ",
      "  iiaJaaaaaIai  ",
      "    a  fhq  a   ",
      "    c  f    c   ",
      "    ababababa   ",
      "                ",
      "                "
    ],
    [
      "                ",
      "                ",
      "  iiuiuiuiuiui  ",
      "  u          u  ",
      "  i          i  ",
      "  u          u  ",
      "  i          i  ",
      "  u          u  ",
      "  i          i  ",
      "  u          u  ",
      "  iiaQaaaaaQai  ",
      "    a Pgq   a   ",
      "    cONgd   c   ",
      "    ababababa   ",
      "                ",
      "                "
    ],
    [
      "                ",
      "                ",
      "  iiuiuiuiuiui  ",
      "  u          u  ",
      "  i          i  ",
      "  u          u  ",
      "  i          i  ",
      "  u          u  ",
      "  i          i  ",
      "  u          u  ",
      "  iiaaaaaaaaai  ",
      "    a  f    a   ",
      "    c  fed  c   ",
      "    ababababa   ",
      "                ",
      "                "
    ],
    [
      "                ",
      "                ",
      "  iiuiuiuiuiui  ",
      "  uSSSSSSSSSSu  ",
      "  iSSSSSSSSSSi  ",
      "  uSSSSSSSSSSu  ",
      "  iSSUSSSSTSSi  ",
      "  uSSSSSSSSSSu  ",
      "  iSSSSSSSSSSi  ",
      "  uSSSSSSSSSSu  ",
      "  iiaaaaaaaaai  ",
      "    aSSf   Ra   ",
      "    cTSf edRc   ",
      "    ababababa   ",
      "                ",
      "                "
    ]
  ]
}