{
  "name": "building_office2b_base1_270",
  "refpalette": "deceasedcraft:building_office2b/building_office2b_base1_palette_270",
  "xsize": 16,
  "zsize": 16,
  "slices": [
    [
      "vvvvvvvvvvvvvvvv",
      "vddddddddddcaaav",
      "vdhhhhhhhhhcaabv",
      "vdhhhhhhhhhcabbv",
      "vdhhhhhhhhhccccv",
      "vdhhhhhhhhhhhedv",
      "vdhhhhhhhhhhhedv",
      "vdhhhhhhhhhhhedv",
      "vdhhhhhhhhhhhedv",
      "vdhhhhhhhhhhhfdv",
      "vdhhhhhhhhhhigdv",
      "vdhhhhhhhhhhhhdv",
      "vdhhhhhhhhhhhhdv",
      "vdhhhhhhhhhhhhdv",
      "vddddddddddddddv",
      "vvvvvvvvvvvvvvvv"
    ],
    [
      "vvvvvvvvvvvvvvvv",
      "vddddddddddrn  v",
      "vdr  r  r  rlkjv",
      "vdr  r  r  rol v",
      "vdr  u  t  rcccv",
      "vdr  r  r  rcedv",
      "vd!  r  r  rcedv",
      "vdu  r  r  rcfdv",
      "vdr  u  r  rigdv",
      "vdr  r  r  scmdv",
      "vd          p dv",
      "vd            dv",
      "vd            dv",
      "vd qqqq  qqqq dv",
      "vddddddddddddddv",
      "vvvvvvvvvvvvvvvv"
    ],
    [
      "vvvvvvvvvvvvvvvv",
      "vddddddddddr   v",
      "vdr  r  r  r   v",
      "vdA  r  r  r   v",
      "vdr  r  r  rcccv",
      "vdA  B  r  rcfdv",
      "vdr  r  r  rigdv",
      "vdr  r  A  rcmdv",
      "vdA  r  r  rc dv",
      "vdr  r  r  ypwdv",
      "vd            dv",
      "vd            dv",
      "vd           xdv",
      "vd            dv",
      "vddddddddddddddv",
      "vvvvvvvvvvvvvvvv"
    ],
    [
      "vvvvvvvvvvvvvvvv",
      "vddddddddddr  ov",
      "vdF        r   v",
      "vdI        r  ov",
      "vdI        rcccv",
      "vdI        rcmdv",
      "vdI        rc dv",
      "vdI        rcwdv",
      "vdI        Cp dv",
      "vdJ           dv",
      "vd            dv",
      "vd            dv",
      "vd            dv",
      "vd  ED    ED  dv",
      "vddddddddddddddv",
      "vvvvvvvvvvvvvvvv"
    ],
    [
      "vvvvvvvvvvvvvvvv",
      "vddddddddddr Lov",
      "vdQ        !  ov",
      "vdQ        r LKv",
      "vdo        rcccv",
      "vdQ        rcwdv",
      "vd         rc dv",
      "vdR        Mp dv",
      "vdS           dv",
      "vdT           dv",
      "vd            dv",
      "vd            dv",
      "vd            dv",
      "vd  OP    ON  dv",
      "vddddddddddddddv",
      "vvvvvvvvvvvvvvvv"
    ],
    [
      "vvvvvvvvvvvvvvvv",
      "vddddddddddrLKKv",
      "vdo        rKLKv",
      "vdX  X  X  rKKKv",
      "vd         rcccv",
      "vd         rc dv",
      "vdX  X  X  Wp dv",
      "vd            dv",
      "vd            dv",
      "vdX  X  Y     dv",
      "vd            dv",
      "vdUUUUUUUUUUUUdv",
      "vdUUUUUUUUUUUUdv",
      "vdUVVVVUUVVVVUdv",
      "vddddddddddddddv",
      "vvvvvvvvvvvvvvvv"
    ]
  ]
}