{
  "name": "building_office2b_floor2_180",
  "refpalette": "deceasedcraft:building_office2b/building_office2b_floor2_palette_180",
  "xsize": 16,
  "zsize": 16,
  "slices": [
    [
      "                ",
      "                ",
      "  iimimimimimi  ",
      "  ljjjjjjjjjjk  ",
      "  ijjjjjjjjjji  ",
      "  ljjjjjjjjjjk  ",
      "  ijjjjjjjjjji  ",
      "  ljjjjjjjjjjk  ",
      "  ijjjjjjjjjji  ",
      "  ljjjjjjjjjjk  ",
      "  iiajajjjjjai  ",
      "    aggf  hga   ",
      "    chgf  edc   ",
      "    ababababa   ",
      "                ",
      "                "
    ],
    [
      "                ",
      "                ",
      "  iisisisisisi  ",
      "  sL        Os  ",
      "  iN   M   M i  ",
      "  sL  KJI KJIs  ",
      "  iF  EDC EDCi  ",
      "  sB   A  yuxs  ",
      "  iw   u     i  ",
      "  st         s  ",
      "  iiaraqqqq ai  ",
      "    a pf ho a   ",
      "    cn!f    c   ",
      "    ababababa   ",
      "                ",
      "                "
    ],
    [
      "                ",
      "                ",
      "  iisisisisisi  ",
      "  s          s  ",
      "  i3         i  ",
      "  s   102 10Zs  ",
      "  iY  XWx VUTi  ",
      "  sS         s  ",
      "  i          i  ",
      "  sR         s  ",
      "  iiaQaPPPP ai  ",
      "    a  fho  a   ",
      "    c  f    c   ",
      "    ababababa   ",
      "                ",
      "                "
    ],
    [
      "                ",
      "                ",
      "  iisisisisisi  ",
      "  s          s  ",
      "  i          i  ",
      "  s          s  ",
      "  i          i  ",
      "  s          s  ",
      "  i          i  ",
      "  s          s  ",
      "  iia8a7777 ai  ",
      "    a 6go   a   ",
      "    c54gd   c   ",
      "    ababababa   ",
      "                ",
      "                "
    ],
    [
      "                ",
      "                ",
      "  iisisisisisi  ",
      "  s          s  ",
      "  i          i  ",
      "  s          s  ",
      "  i          i  ",
      "  s          s  ",
      "  i          i  ",
      "  s          s  ",
      "  iiaaaaaaaaai  ",
      "    a  f    a   ",
      "    c  fed  c   ",
      "    ababababa   ",
      "                ",
      "                "
    ],
    [
      "                ",
      "                ",
      "  iisisisisisi  ",
      "  s%#########s  ",
      "  i%#########i  ",
      "  s%#########s  ",
      "  i%##$###^##i  ",
      "  s%#########s  ",
      "  i%#########i  ",
      "  s%#########s  ",
      "  iiaaaaaaaaai  ",
      "    a##f   9a   ",
      "    c$#f ed9c   ",
      "    ababababa   ",
      "                ",
      "                "
    ]
  ]
}