{
  "name": "building_office2b_ground_90",
  "refpalette": "deceasedcraft:building_office2b/building_office2b_ground_palette_90",
  "xsize": 16,
  "zsize": 16,
  "slices": [
    [
      "aaaaaaaaaaaaaaaa",
      "abbbbbbbbbbbbbba",
      "abccccccccccccba",
      "abcaacccccccccba",
      "abcaacccccccccba",
      "abccccccccccccba",
      "abc  cccccccccba",
      "abc  cccccccccba",
      "abc  cccccccccba",
      "abc  cccccccccba",
      "abcdecccccccccba",
      "abccccccccccccba",
      "abccccccccccccba",
      "abccccccccccccba",
      "abbbbbbbbbbbbbba",
      "aaaaaaaaaaaaaaaa"
    ],
    [
      "                ",
      " fg  ggrrgg  gf ",
      " ghiihhqshhiihg ",
      "  il k      Di  ",
      "  ilnk    ujCi  ",
      " ghkko    w  hg ",
      " gh  p   twy hg ",
      "  i  p    w  i  ",
      "  i  p    w  i  ",
      " gh ep   twy hg ",
      " ghjmo    w  hg ",
      "  i       uxBi  ",
      "  i         Ai  ",
      " ghiihhiihhiihg ",
      " fg  gg  gg  gf ",
      "                "
    ],
    [
      "                ",
      " fg  gg  gg  gf ",
      " ghiihhIJhhiihg ",
      "  i         Ni  ",
      "  i E     M  i  ",
      " gh  o       hg ",
      " gh  F    L  hg ",
      "  i  F       i  ",
      "  i eF       i  ",
      " gh mF    L  hg ",
      " gh  o       hg ",
      "  i       K  i  ",
      "  i         Ni  ",
      " ghiihhiihhiihg ",
      " fg  gg  gg  gf ",
      "                "
    ],
    [
      "                ",
      " fg  gg  gg  gf ",
      " ghiihhiihhiihg ",
      "  i         Ri  ",
      "  i          i  ",
      " gh  o       hg ",
      " gh  P       hg ",
      "  ieeP Q     i  ",
      "  iOmP       i  ",
      " gh  P       hg ",
      " gh  o       hg ",
      "  i          i  ",
      "  i         Ri  ",
      " ghiihhiihhiihg ",
      " fg  gg  gg  gf ",
      "                "
    ],
    [
      "                ",
      " fgSSggSSggSSgf ",
      " ghXXhhXXhhXXhg ",
      " STWWo       0S ",
      " STWWo       0S ",
      " gh  o       hg ",
      " gh  o       hg ",
      " STVVo ZY    0S ",
      " STd o YQ    0S ",
      " ghO o       hg ",
      " gh  o       hg ",
      " ST  o       0S ",
      " ST  o       0S ",
      " ghUUhhUUhhUUhg ",
      " fgSSggSSggSSgf ",
      "                "
    ],
    [
      "                ",
      " fggggggggggggf ",
      " gggggggggggggg ",
      " ggggg2222222gg ",
      " goooo2222222gg ",
      " goooo2222222gg ",
      " goooo2222222gg ",
      " go11o2332222gg ",
      " go  o2332222gg ",
      " god o2222222gg ",
      " goO o2222222gg ",
      " goooo2222222gg ",
      " goooo2222222gg ",
      " gggggggggggggg ",
      " fggggggggggggf ",
      "                "
    ]
  ]
}