{
  "name": "building_office2b_floor3_90",
  "refpalette": "deceasedcraft:building_office2b/building_office2b_floor3_palette_90",
  "xsize": 16,
  "zsize": 16,
  "slices": [
    [
      "                ",
      "                ",
      "     imimimimi  ",
      "     illllllli  ",
      "  acaallllllln  ",
      "  bhgjllllllli  ",
      "  aggallllllln  ",
      "  bffallllllli  ",
      "  a  allllllln  ",
      "  b  allllllli  ",
      "  aehallllllln  ",
      "  bdgjllllllli  ",
      "  acaallllllln  ",
      "     ikikikiki  ",
      "                ",
      "                "
    ],
    [
      "                ",
      "                ",
      "     iuiuiuiui  ",
      "     i   C   i  ",
      "  acaa CDDC  u  ",
      "  bp t  DD   i  ",
      "  aoraB E  E u  ",
      "  bffaA  EDDEi  ",
      "  a  ay   DD u  ",
      "  b hax  C C i  ",
      "  a qaw DD   u  ",
      "  b  s CDDF  i  ",
      "  acaa   C   u  ",
      "     iuiuiuiui  ",
      "                ",
      "                "
    ],
    [
      "                ",
      "                ",
      "     iuiuiuiui  ",
      "     i       i  ",
      "  acaa       u  ",
      "  b  J       i  ",
      "  a  a       u  ",
      "  bffaM      i  ",
      "  a haL      u  ",
      "  b qaK      i  ",
      "  a  a       u  ",
      "  b  I       i  ",
      "  acaa       u  ",
      "     iuiuiuiui  ",
      "                ",
      "                "
    ],
    [
      "                ",
      "                ",
      "     iuiuiuiui  ",
      "     i       i  ",
      "  acaa       u  ",
      "  bO Q       i  ",
      "  aNPa       u  ",
      "  bgga       i  ",
      "  adqa       u  ",
      "  b  a       i  ",
      "  a  a       u  ",
      "  b  Q       i  ",
      "  acaa       u  ",
      "     iuiuiuiui  ",
      "                ",
      "                "
    ],
    [
      "                ",
      "                ",
      "     iuiuiuiui  ",
      "     i       i  ",
      "  acaa       u  ",
      "  b  a       i  ",
      "  a  a       u  ",
      "  bffa       i  ",
      "  ae a       u  ",
      "  bd a       i  ",
      "  a  a       u  ",
      "  b  a       i  ",
      "  acaa       u  ",
      "     iuiuiuiui  ",
      "                ",
      "                "
    ],
    [
      "                ",
      "                ",
      "     iuiuiuiui  ",
      "     iSSSSSSSi  ",
      "  acaaSSSSSSSu  ",
      "  bTSaSSSUSSSi  ",
      "  aSSaSSSSSSSu  ",
      "  bffaSSSSSSSi  ",
      "  a  aSSSSSSSu  ",
      "  be aSSSSSSSi  ",
      "  ad aSSSTSSSu  ",
      "  bRRaSSSSSSSi  ",
      "  acaaSSSSSSSu  ",
      "     iuiuiuiui  ",
      "                ",
      "                "
    ]
  ]
}