{
  "name": "building_office2b_top_270",
  "refpalette": "deceasedcraft:building_office2b/building_office2b_top_palette_270",
  "xsize": 16,
  "zsize": 16,
  "slices": [
    [
      "                ",
      "                ",
      "  ikikikiki     ",
      "  klllllllaaca  ",
      "  illlllllj  b  ",
      "  kllllllmahda  ",
      "  illllllma  b  ",
      "  kllllllma  a  ",
      "  illllll!aeeb  ",
      "  kllllllmaffa  ",
      "  illlllllfffb  ",
      "  klllllllaaga  ",
      "  illllllli     ",
      "  ikikikiki     ",
      "                ",
      "                "
    ],
    [
      "                ",
      "                ",
      "  ikikikiki     ",
      "  k  Ex   aaan  ",
      "  iK Fx  s   o  ",
      "  kL Ix  ta  n  ",
      "  i   y  ta  o  ",
      "  k   A  ta  n  ",
      "  i   B  taeeo  ",
      "  k   Cw taqpn  ",
      "  i  JC   rqpo  ",
      "  k   Cw  aaan  ",
      "  iu  D  ui     ",
      "  ikikikiki     ",
      "                ",
      "                "
    ],
    [
      "                ",
      "                ",
      "  ikikikiki     ",
      "  k   x   aan   ",
      "  iW  x  O  o   ",
      "  k   x  Pa n   ",
      "  i   Q  Pa o   ",
      "  k       a n   ",
      "  i   R  Pa o   ",
      "  k   S   aMn   ",
      "  i   T   N o   ",
      "  k   U   aan   ",
      "  it  V  ti     ",
      "  ikikikiki     ",
      "                ",
      "                "
    ],
    [
      "                ",
      "                ",
      "  iXiXiXiXi     ",
      "  3   0   an    ",
      "  i   1   fo    ",
      "  3   2   an    ",
      "  i       ao    ",
      "  3       an    ",
      "  i       ao    ",
      "  3       an    ",
      "  i      Yfo    ",
      "  3       an    ",
      "  i       i     ",
      "  iZiZiZiZi     ",
      "                ",
      "                "
    ],
    [
      "                ",
      "                ",
      "  iiiiiiiii     ",
      "  i4444444i     ",
      "  i4444444i     ",
      "  i4444445i     ",
      "  i4444445i     ",
      "  i4444445i     ",
      "  i4444445i     ",
      "  i4444445i     ",
      "  i4444444i     ",
      "  i4444444i     ",
      "  i4444446i     ",
      "  iiiiiiiii     ",
      "                ",
      "                "
    ],
    [
      "                ",
      "                ",
      "  777777777     ",
      "  7 8     7     ",
      "  7 8     7     ",
      "  7 $#    7     ",
      "  7 8     7     ",
      "  7 8     7     ",
      "  7 8     7     ",
      "  7 $#    7     ",
      "  7 8     7     ",
      "  7 89 9  7     ",
      "  7 8888887     ",
      "  777777777     ",
      "                ",
      "                "
    ]
  ]
}