{
  "name": "building_office2b_base1",
  "refpalette": "deceasedcraft:building_office2b/building_office2b_base1_palette",
  "xsize": 16,
  "zsize": 16,
  "slices": [
    [
      "vvvvvvvvvvvvvvvv",
      "vabbcddddddddddv",
      "vaabceeeefghhhdv",
      "vaaachhhhhihhhdv",
      "vcccchhhhhhhhhdv",
      "vdhhhhhhhhhhhhdv",
      "vdhhhhhhhhhhhhdv",
      "vdhhhhhhhhhhhhdv",
      "vdhhhhhhhhhhhhdv",
      "vdhhhhhhhhhhhhdv",
      "vdhhhhhhhhhhhhdv",
      "vdhhhhhhhhhhhhdv",
      "vdhhhhhhhhhhhhdv",
      "vdhhhhhhhhhhhhdv",
      "vddddddddddddddv",
      "vvvvvvvvvvvvvvvv"
    ],
    [
      "vvvvvvvvvvvvvvvv",
      "v j cddddddddddv",
      "v klceefgm    dv",
      "vnloccccicp  qdv",
      "vrrrrrrrrs   qdv",
      "vd           qdv",
      "vd           qdv",
      "vdrrtrrrrr    dv",
      "vd            dv",
      "vd           qdv",
      "vdrrurrrur   qdv",
      "vd           qdv",
      "vd           qdv",
      "vdrrrr!urr    dv",
      "vddddddddddddddv",
      "vvvvvvvvvvvvvvvv"
    ],
    [
      "vvvvvvvvvvvvvvvv",
      "v   cddddddddddv",
      "v   cfgm w  x dv",
      "v   cciccp    dv",
      "vrrrrrrrry    dv",
      "vd            dv",
      "vd            dv",
      "vdrrrrrArr    dv",
      "vd            dv",
      "vd            dv",
      "vdrrrBrrrr    dv",
      "vd            dv",
      "vd            dv",
      "vdrArArrAr    dv",
      "vddddddddddddddv",
      "vvvvvvvvvvvvvvvv"
    ],
    [
      "vvvvvvvvvvvvvvvv",
      "vo ocddddddddddv",
      "v   cm w      dv",
      "v   ccccp     dv",
      "vrrrrrrrC    Ddv",
      "vd           Edv",
      "vd            dv",
      "vd            dv",
      "vd            dv",
      "vd            dv",
      "vd           Ddv",
      "vd           Edv",
      "vd            dv",
      "vdFIIIIIIJ    dv",
      "vddddddddddddddv",
      "vvvvvvvvvvvvvvvv"
    ],
    [
      "vvvvvvvvvvvvvvvv",
      "vooKcddddddddddv",
      "vL Lcw        dv",
      "v   cccp      dv",
      "vr!rrrrM     Ndv",
      "vd           Odv",
      "vd            dv",
      "vd            dv",
      "vd            dv",
      "vd            dv",
      "vd           Pdv",
      "vd           Odv",
      "vd            dv",
      "vdQQoQ RST    dv",
      "vddddddddddddddv",
      "vvvvvvvvvvvvvvvv"
    ],
    [
      "vvvvvvvvvvvvvvvv",
      "vKKKcddddddddddv",
      "vKLKc      UUUdv",
      "vLKKccp    UUVdv",
      "vrrrrrW    UUVdv",
      "vd         UUVdv",
      "vd         UUVdv",
      "vd X  X  Y UUUdv",
      "vd         UUUdv",
      "vd         UUVdv",
      "vd X  X  X UUVdv",
      "vd         UUVdv",
      "vd         UUVdv",
      "vdoX  X  X UUUdv",
      "vddddddddddddddv",
      "vvvvvvvvvvvvvvvv"
    ]
  ]
}