{
  "name": "building_office2b_top_180",
  "refpalette": "deceasedcraft:building_office2b/building_office2b_top_palette_180",
  "xsize": 16,
  "zsize": 16,
  "slices": [
    [
      "                ",
      "                ",
      "  iikikikikiki  ",
      "  kllllllllllk  ",
      "  illlllllllli  ",
      "  kllllllllllk  ",
      "  illlllllllli  ",
      "  kllllllllllk  ",
      "  illlllllllli  ",
      "  klllm!mmmllk  ",
      "  iiafaaaaajai  ",
      "    affe  h a   ",
      "    gffe  d c   ",
      "    ababababa   ",
      "                ",
      "                "
    ],
    [
      "                ",
      "                ",
      "  iikikikikiki  ",
      "  ku      LK k  ",
      "  i          i  ",
      "  k  J    IFEk  ",
      "  iDCCCBAyxxxi  ",
      "  k w w      k  ",
      "  i          i  ",
      "  ku  ttttts k  ",
      "  iiaraaaaa ai  ",
      "    aqqe    a   ",
      "    appe    a   ",
      "    nonononon   ",
      "                ",
      "                "
    ],
    [
      "                ",
      "                ",
      "  iikikikikiki  ",
      "  kt       W k  ",
      "  i          i  ",
      "  k          k  ",
      "  iVUTSR Qxxxi  ",
      "  k          k  ",
      "  i          i  ",
      "  kt   P PPO k  ",
      "  iiaNaaaaa ai  ",
      "    a M     a   ",
      "    nonononon   ",
      "                ",
      "                ",
      "                "
    ],
    [
      "                ",
      "                ",
      "  ii3i3i3i3i3i  ",
      "  Z          X  ",
      "  i          i  ",
      "  Z          X  ",
      "  i       210i  ",
      "  Z          X  ",
      "  i          i  ",
      "  Z  Y       X  ",
      "  iiafaaaaafai  ",
      "    nonononon   ",
      "                ",
      "                ",
      "                ",
      "                "
    ],
    [
      "                ",
      "                ",
      "  iiiiiiiiiiii  ",
      "  i4444444444i  ",
      "  i4444444444i  ",
      "  i4444444444i  ",
      "  i4444444444i  ",
      "  i4444444444i  ",
      "  i4444444444i  ",
      "  i6445555544i  ",
      "  iiiiiiiiiiii  ",
      "                ",
      "                ",
      "                ",
      "                ",
      "                "
    ],
    [
      "                ",
      "                ",
      "  777777777777  ",
      "  7          7  ",
      "  7888$888$887  ",
      "  789 #   #  7  ",
      "  78         7  ",
      "  789        7  ",
      "  78         7  ",
      "  78         7  ",
      "  777777777777  ",
      "                ",
      "                ",
      "                ",
      "                ",
      "                "
    ]
  ]
}