{
  "name": "building_office2b_floor1_270",
  "refpalette": "deceasedcraft:building_office2b/building_office2b_floor1_palette_270",
  "xsize": 16,
  "zsize": 16,
  "slices": [
    [
      "                ",
      "                ",
      "  ikikikiki     ",
      "  mjjjjjjjaaca  ",
      "  ijjjjjjjjgdb  ",
      "  mjjjjjjjjhea  ",
      "  ijjjjjjjj  b  ",
      "  mjjjjjjjj  a  ",
      "  ijjjjjjjjffb  ",
      "  mjjjjjjjagga  ",
      "  ijjjjjjjjghb  ",
      "  mjjjjjjjaaca  ",
      "  ijjjjjjji     ",
      "  ilililili     ",
      "                ",
      "                "
    ],
    [
      "                ",
      "                ",
      "  ititititi     ",
      "  t  FBx  aaca  ",
      "  i LIC      b  ",
      "  t  JD   rp a  ",
      "  i       rh b  ",
      "  t MFB   r  a  ",
      "  i NICy  rffb  ",
      "  t  JD   aqna  ",
      "  i       s ob  ",
      "  t       aaca  ",
      "  iKOKEAwui     ",
      "  ititititi     ",
      "                ",
      "                "
    ],
    [
      "                ",
      "                ",
      "  ititititi     ",
      "  t  YT   aaca  ",
      "  i  Z!      b  ",
      "  t  0U   P  a  ",
      "  i       Pp b  ",
      "  t  1T   Ph a  ",
      "  i  ZV   Pffb  ",
      "  t  0W   a  a  ",
      "  i       Q  b  ",
      "  t       aaca  ",
      "  i 2 XS Ri     ",
      "  ititititi     ",
      "                ",
      "                "
    ],
    [
      "                ",
      "                ",
      "  ititititi     ",
      "  t       aaca  ",
      "  i          b  ",
      "  t       6  a  ",
      "  i       6  b  ",
      "  t       6pda  ",
      "  i       6ggb  ",
      "  t       a53a  ",
      "  i       7 4b  ",
      "  t       aaca  ",
      "  i       i     ",
      "  ititititi     ",
      "                ",
      "                "
    ],
    [
      "                ",
      "                ",
      "  ititititi     ",
      "  t       aaca  ",
      "  i       a  b  ",
      "  t       a  a  ",
      "  i       a db  ",
      "  t       a ea  ",
      "  i       affb  ",
      "  t       a  a  ",
      "  i       a  b  ",
      "  t       aaca  ",
      "  i       i     ",
      "  ititititi     ",
      "                ",
      "                "
    ],
    [
      "                ",
      "                ",
      "  ititititi     ",
      "  t9999999aaca  ",
      "  i9999999a88b  ",
      "  t999%999a da  ",
      "  i9999999a eb  ",
      "  t9999999a  a  ",
      "  i9999999affb  ",
      "  t999%999a99a  ",
      "  i9999999a9#b  ",
      "  t9999999aaca  ",
      "  i$$$$$$$i     ",
      "  ititititi     ",
      "                ",
      "                "
    ]
  ]
}