{
  "name": "building_office2b_floor3_270",
  "refpalette": "deceasedcraft:building_office2b/building_office2b_floor3_palette_270",
  "xsize": 16,
  "zsize": 16,
  "slices": [
    [
      "                ",
      "                ",
      "  ikikikiki     ",
      "  nlllllllaaca  ",
      "  illllllljgdb  ",
      "  nlllllllahea  ",
      "  illllllla  b  ",
      "  nllllllla  a  ",
      "  illlllllaffb  ",
      "  nlllllllagga  ",
      "  illllllljghb  ",
      "  nlllllllaaca  ",
      "  illllllli     ",
      "  imimimimi     ",
      "                ",
      "                "
    ],
    [
      "                ",
      "                ",
      "  iuiuiuiui     ",
      "  u   C   aaca  ",
      "  i  FDDC s  b  ",
      "  u   DD waq a  ",
      "  i C C  xah b  ",
      "  u DD   ya  a  ",
      "  iEDDE  Aaffb  ",
      "  u E  E Baroa  ",
      "  i   DD  t pb  ",
      "  u  CDDC aaca  ",
      "  i   C   i     ",
      "  iuiuiuiui     ",
      "                ",
      "                "
    ],
    [
      "                ",
      "                ",
      "  iuiuiuiui     ",
      "  u       aaca  ",
      "  i       I  b  ",
      "  u       a  a  ",
      "  i      Kaq b  ",
      "  u      Lah a  ",
      "  i      Maffb  ",
      "  u       a  a  ",
      "  i       J  b  ",
      "  u       aaca  ",
      "  i       i     ",
      "  iuiuiuiui     ",
      "                ",
      "                "
    ],
    [
      "                ",
      "                ",
      "  iuiuiuiui     ",
      "  u       aaca  ",
      "  i       Q  b  ",
      "  u       a  a  ",
      "  i       a  b  ",
      "  u       aqda  ",
      "  i       aggb  ",
      "  u       aPNa  ",
      "  i       Q Ob  ",
      "  u       aaca  ",
      "  i       i     ",
      "  iuiuiuiui     ",
      "                ",
      "                "
    ],
    [
      "                ",
      "                ",
      "  iuiuiuiui     ",
      "  u       aaca  ",
      "  i       a  b  ",
      "  u       a  a  ",
      "  i       a db  ",
      "  u       a ea  ",
      "  i       affb  ",
      "  u       a  a  ",
      "  i       a  b  ",
      "  u       aaca  ",
      "  i       i     ",
      "  iuiuiuiui     ",
      "                ",
      "                "
    ],
    [
      "                ",
      "                ",
      "  iuiuiuiui     ",
      "  uSSSSSSSaaca  ",
      "  iSSSSSSSaRRb  ",
      "  uSSSTSSSa da  ",
      "  iSSSSSSSa eb  ",
      "  uSSSSSSSa  a  ",
      "  iSSSSSSSaffb  ",
      "  uSSSSSSSaSSa  ",
      "  iSSSUSSSaSTb  ",
      "  uSSSSSSSaaca  ",
      "  iSSSSSSSi     ",
      "  iuiuiuiui     ",
      "                ",
      "                "
    ]
  ]
}