{
  "name": "building_office2b_floor1_180",
  "refpalette": "deceasedcraft:building_office2b/building_office2b_floor1_palette_180",
  "xsize": 16,
  "zsize": 16,
  "slices": [
    [
      "                ",
      "                ",
      "  iimimimimimi  ",
      "  ljjjjjjjjjjk  ",
      "  ijjjjjjjjjji  ",
      "  ljjjjjjjjjjk  ",
      "  ijjjjjjjjjji  ",
      "  ljjjjjjjjjjk  ",
      "  ijjjjjjjjjji  ",
      "  ljjjjjjjjjjk  ",
      "  iiajajjjjjai  ",
      "    aggf  hga   ",
      "    chgf  edc   ",
      "    ababababa   ",
      "                ",
      "                "
    ],
    [
      "                ",
      "                ",
      "  iitititititi  ",
      "  tK         t  ",
      "  iO   NM  L i  ",
      "  tK  JIF JIFt  ",
      "  iE  DCB DCBi  ",
      "  tA   y    xt  ",
      "  iw         i  ",
      "  tu         t  ",
      "  iiasarrrr ai  ",
      "    a qf hp a   ",
      "    conf    c   ",
      "    ababababa   ",
      "                ",
      "                "
    ],
    [
      "                ",
      "                ",
      "  iitititititi  ",
      "  t          t  ",
      "  i2         i  ",
      "  t   0Z1 0ZYt  ",
      "  iX  WVT U!Ti  ",
      "  tS         t  ",
      "  i          i  ",
      "  tR         t  ",
      "  iiaQaPPPP ai  ",
      "    a  fhp  a   ",
      "    c  f    c   ",
      "    ababababa   ",
      "                ",
      "                "
    ],
    [
      "                ",
      "                ",
      "  iitititititi  ",
      "  t          t  ",
      "  i          i  ",
      "  t          t  ",
      "  i          i  ",
      "  t          t  ",
      "  i          i  ",
      "  t          t  ",
      "  iia7a6666 ai  ",
      "    a 5gp   a   ",
      "    c43gd   c   ",
      "    ababababa   ",
      "                ",
      "                "
    ],
    [
      "                ",
      "                ",
      "  iitititititi  ",
      "  t          t  ",
      "  i          i  ",
      "  t          t  ",
      "  i          i  ",
      "  t          t  ",
      "  i          i  ",
      "  t          t  ",
      "  iiaaaaaaaaai  ",
      "    a  f    a   ",
      "    c  fed  c   ",
      "    ababababa   ",
      "                ",
      "                "
    ],
    [
      "                ",
      "                ",
      "  iitititititi  ",
      "  t$999999999t  ",
      "  i$999999999i  ",
      "  t$999999999t  ",
      "  i$99%999%99i  ",
      "  t$999999999t  ",
      "  i$999999999i  ",
      "  t$999999999t  ",
      "  iiaaaaaaaaai  ",
      "    a99f   8a   ",
      "    c#9f ed8c   ",
      "    ababababa   ",
      "                ",
      "                "
    ]
  ]
}