{
  "name": "building_office2b_top",
  "refpalette": "deceasedcraft:building_office2b/building_office2b_top_palette",
  "xsize": 16,
  "zsize": 16,
  "slices": [
    [
      "                ",
      "                ",
      "   ababababa    ",
      "   c d  effg    ",
      "   a h  effa    ",
      "  iajaaaaafaii  ",
      "  kllmmm!mlllk  ",
      "  illlllllllli  ",
      "  kllllllllllk  ",
      "  illlllllllli  ",
      "  kllllllllllk  ",
      "  illlllllllli  ",
      "  kllllllllllk  ",
      "  ikikikikikii  ",
      "                ",
      "                "
    ],
    [
      "                ",
      "                ",
      "   nonononon    ",
      "   a    eppa    ",
      "   a    eqqa    ",
      "  ia aaaaaraii  ",
      "  k sttttt  uk  ",
      "  i          i  ",
      "  k      w w k  ",
      "  ixxxyABCCCDi  ",
      "  kEFI    J  k  ",
      "  i          i  ",
      "  k KL      uk  ",
      "  ikikikikikii  ",
      "                ",
      "                "
    ],
    [
      "                ",
      "                ",
      "                ",
      "   nonononon    ",
      "   a     M a    ",
      "  ia aaaaaNaii  ",
      "  k OPP P   tk  ",
      "  i          i  ",
      "  k          k  ",
      "  ixxxQ RSTUVi  ",
      "  k          k  ",
      "  i          i  ",
      "  k W       tk  ",
      "  ikikikikikii  ",
      "                ",
      "                "
    ],
    [
      "                ",
      "                ",
      "                ",
      "                ",
      "   nonononon    ",
      "  iafaaaaafaii  ",
      "  X       Y  Z  ",
      "  i          i  ",
      "  X          Z  ",
      "  i012       i  ",
      "  X          Z  ",
      "  i          i  ",
      "  X          Z  ",
      "  i3i3i3i3i3ii  ",
      "                ",
      "                "
    ],
    [
      "                ",
      "                ",
      "                ",
      "                ",
      "                ",
      "  iiiiiiiiiiii  ",
      "  i4455555446i  ",
      "  i4444444444i  ",
      "  i4444444444i  ",
      "  i4444444444i  ",
      "  i4444444444i  ",
      "  i4444444444i  ",
      "  i4444444444i  ",
      "  iiiiiiiiiiii  ",
      "                ",
      "                "
    ],
    [
      "                ",
      "                ",
      "                ",
      "                ",
      "                ",
      "  777777777777  ",
      "  7         87  ",
      "  7         87  ",
      "  7        987  ",
      "  7         87  ",
      "  7  #   # 987  ",
      "  788$888$8887  ",
      "  7          7  ",
      "  777777777777  ",
      "                ",
      "                "
    ]
  ]
}