{
  "name": "multi_gallery_6_floor1",
  "refpalette": "deceasedcraft:multi_gallery_6/multi_gallery_6_floor1_palette",
  "xsize": 16,
  "zsize": 16,
  "slices": [
    [
      "                ",
      "    a     a     ",
      "                ",
      "                ",
      "                ",
      "                ",
      "                ",
      "                ",
      "bcc             ",
      "bbbbbcc         ",
      "dddbbbbbbcc     ",
      "dddddddbbbbbbcc ",
      "dddddddddddbbbbb",
      "dddddddddddddddb",
      "dddddddddddddddd",
      "dddddddddddddddd"
    ],
    [
      "                ",
      "                ",
      "                ",
      "                ",
      "                ",
      "                ",
      "                ",
      "                ",
      "                ",
      "eee             ",
      "fg eeee         ",
      "       eeee     ",
      "        fg eeee ",
      "               e",
      "   h            ",
      "   i            "
    ],
    [
      "                ",
      "                ",
      "                ",
      "                ",
      "                ",
      "                ",
      "                ",
      "                ",
      "                ",
      "eee             ",
      "   eeee         ",
      "       eeee     ",
      "           eeee ",
      "               e",
      "                ",
      "                "
    ],
    [
      "                ",
      "                ",
      "                ",
      "                ",
      "                ",
      "                ",
      "                ",
      "                ",
      "                ",
      "eee             ",
      "   eeee         ",
      "       eeee     ",
      "           eeee ",
      "               e",
      "                ",
      "                "
    ],
    [
      "                ",
      "                ",
      "                ",
      "                ",
      "                ",
      "                ",
      "                ",
      "                ",
      "                ",
      "eee             ",
      "   eeee         ",
      "       eeee     ",
      "           eeee ",
      "               e",
      "                ",
      "                "
    ],
    [
      "                ",
      "                ",
      "                ",
      "                ",
      "                ",
      "                ",
      "                ",
      "                ",
      "jjj             ",
      "kkkjjjj         ",
      "lllkkkkjjjj     ",
      "lllllllkkkkjjjj ",
      "lllllllllllkkkkj",
      "lllllllllllllllk",
      "lllmllllllllllll",
      "lllnllllllllllll"
    ]
  ]
}