{
  "name": "multi_gallery_6_ground",
  "refpalette": "deceasedcraft:multi_gallery_6/multi_gallery_6_ground_palette",
  "xsize": 16,
  "zsize": 16,
  "slices": [
    [
      "aaaaaaaaaaaaaaaa",
      "babababababababa",
      "babababababababa",
      "babababababababa",
      "babababababababa",
      "babababababababa",
      "babababababababa",
      "aacababababababa",
      "aaaaaacababababa",
      "aaaaaaaaaacababa",
      "aaaaaaaaaaaaaaca",
      "daaaaaaaaaaaaaaa",
      "dddddaaaaaaaaaaa",
      "eeeedddddaaaaaaa",
      "eeeeeeeedddddaaa",
      "eeeeeeeeeeeedddd"
    ],
    [
      "                ",
      "    f     f     ",
      "                ",
      "                ",
      "                ",
      "                ",
      "                ",
      "                ",
      "                ",
      "                ",
      "                ",
      "                ",
      "                ",
      " g              ",
      "     g          ",
      "   g            "
    ],
    [
      "                ",
      "    h     h     ",
      "                ",
      "                ",
      "                ",
      "                ",
      "                ",
      "                ",
      "                ",
      "                ",
      "                ",
      "                ",
      "                ",
      "                ",
      "                ",
      "         ij     "
    ],
    [
      "                ",
      "   kk     kk    ",
      "                ",
      "                ",
      "                ",
      "                ",
      "                ",
      "                ",
      "                ",
      "                ",
      "                ",
      "                ",
      "                ",
      "                ",
      "          l     ",
      "         ij     "
    ],
    [
      "    k     k     ",
      "   kkk    kk    ",
      "    k     k     ",
      "                ",
      "                ",
      "                ",
      "                ",
      "                ",
      "                ",
      "                ",
      "                ",
      "                ",
      "                ",
      "          l     ",
      "          l     ",
      "                "
    ],
    [
      "                ",
      "    kk   kk    k",
      "    k     k     ",
      "                ",
      "                ",
      "                ",
      "                ",
      "                ",
      "                ",
      "                ",
      "                ",
      "                ",
      "          m     ",
      "          l     ",
      "                ",
      "                "
    ]
  ]
}