{
  "name": "multi_thering_19_floor7",
  "refpalette": "deceasedcraft:multi_thering_19/multi_thering_19_floor7_palette",
  "xsize": 16,
  "zsize": 16,
  "slices": [
    [
      "        abcccddd",
      "        accddddd",
      "       cccdddddc",
      "      ccddddddce",
      "   ccccdddddccee",
      "fcccdddddddcce  ",
      "ccdddddddccee   ",
      "dddddddccee     ",
      "dddddcceee      ",
      "ddccceee        ",
      "cceee           ",
      "ee              ",
      "                ",
      "                ",
      "                ",
      "                "
    ],
    [
      "             ggh",
      "           ggghi",
      "          gghjik",
      "        ggghiik ",
      "       ggjhikk  ",
      "    gggghiikk   ",
      "  gggjhiikk     ",
      "ggghhiikk       ",
      "hjiiikk         ",
      "iikkk           ",
      "kk              ",
      "                ",
      "                ",
      "                ",
      "                ",
      "                "
    ],
    [
      "                ",
      "               i",
      "              i ",
      "            ii  ",
      "           i    ",
      "         ii     ",
      "       ii       ",
      "     ii         ",
      "  iii           ",
      "ii              ",
      "                ",
      "                ",
      "                ",
      "                ",
      "                ",
      "                "
    ],
    [
      "                ",
      "                ",
      "                ",
      "                ",
      "                ",
      "                ",
      "                ",
      "                ",
      "                ",
      "                ",
      "                ",
      "                ",
      "                ",
      "                ",
      "                ",
      "                "
    ],
    [
      "                ",
      "                ",
      "                ",
      "                ",
      "                ",
      "                ",
      "                ",
      "                ",
      "                ",
      "                ",
      "                ",
      "                ",
      "                ",
      "                ",
      "                ",
      "                "
    ],
    [
      "                ",
      "                ",
      "                ",
      "                ",
      "                ",
      "                ",
      "                ",
      "                ",
      "                ",
      "                ",
      "                ",
      "                ",
      "                ",
      "                ",
      "                ",
      "                "
    ]
  ]
}