{
  "name": "multi_thering_19_base1",
  "refpalette": "deceasedcraft:multi_thering_19/multi_thering_19_base1_palette",
  "xsize": 16,
  "zsize": 16,
  "slices": [
    [
      "abbbbbbbbbbbbbbb",
      "bbbbbbbbbbbbbbbb",
      "bbbbbbbbbbbbbbbb",
      "bbbbbbbbbbbbbbbb",
      "bbbbbbbbbbbbbbbb",
      "bbbbbbbbbbbbbbbb",
      "bbbbbbbbbbbbbbbb",
      "bbbbbbbbbbbbbbbb",
      "bbbbbbbbbbbbbbbb",
      "bbbbbbbbbbbbbbbb",
      "bbbbbbbbbbbbbbbb",
      "bbbbbbbbbbbbbbbb",
      "bbbbbbbbbbbbbbbb",
      "bbbbbbbbbbbbbbbb",
      "bbbbbbbbbbbbbbbb",
      "vvvvvvvvvvvvvvvv"
    ],
    [
      "abbbbbbbbbbbbbbb",
      "bbbbbbbbbbbbbbbb",
      "bbbbbbbbbbbbbbbb",
      "bbbbbbbbbbbbbbbb",
      "bbbbbbbbbbbbbbbb",
      "bbbbbbbbbbbbbbbb",
      "bbbbbbbbbbbbbbbb",
      "bbbbbbbbbbbbbbbb",
      "bbbbbbbbbbbbbbbb",
      "bbbbbbbbbbbbbbbb",
      "bbbbbbbbbbbbbbbb",
      "bbbbbbbbbbbbbbbb",
      "bbbbbbbbbbbbbbbb",
      "bbbbbbbbbbbbbbbb",
      "bbbbbbbbbbbbbbbb",
      "vvvvvvvvvvvvvvvv"
    ],
    [
      "abbbbbbbbbbbbbbb",
      "bbbbbbbbbbbbbbbb",
      "bbbbbbbbbbbbbbbb",
      "bbbbbbbbbbbbbbbb",
      "bbbbbbbbbbbbbbbb",
      "bbbbbbbbbbbbbbbb",
      "bbbbbbbbbbbbbbbb",
      "bbbbbbbbbbbbbbbb",
      "bbbbbbbbbbbbbbbb",
      "bbbbbbbbbbbbbbbb",
      "bbbbbbbbbbbbbbbb",
      "bbbbbbbbbbbbbbbb",
      "bbbbbbbbbbbbbbbb",
      "bbbbbbbbbbbbbbbb",
      "bbbbbbbbbbbbbbbb",
      "vvvvvvvvvvvvvvvv"
    ],
    [
      "abbbbbbbbbbbbbbb",
      "bbbbbbbbbbbbbbbb",
      "bbbbbbbbbbbbbbbb",
      "bbbbbbbbbbbbbbbb",
      "bbbbbbbbbbbbbbbb",
      "bbbbbbbbbbbbbbbb",
      "bbbbbbbbbbbbbbbb",
      "bbbbbbbbbbbbbbbb",
      "bbbbbbbbbbbbbbbb",
      "bbbbbbbbbbbbbbbb",
      "bbbbbbbbbbbbbbbb",
      "bbbbbbbbbbbbbbbb",
      "bbbbbbbbbbbbbbbb",
      "bbbbbbbbbbbbbbbb",
      "bbbbbbbbbbbbbbbb",
      "vvvvvvvvvvvvvvvv"
    ],
    [
      "abbbbbbbbbbbbbbb",
      "bbbbbbbbbbbbbbbb",
      "bbbbbbbbbbbbbbbb",
      "bbbbbbbbbbbbbbbb",
      "bbbbbbbbbbbbbbbb",
      "bbbbbbbbbbbbbbbb",
      "bbbbbbbbbbbbbbbb",
      "bbbbbbbbbbbbbbbb",
      "bbbbbbbbbbbbbbbb",
      "bbbbbbbbbbbbbbbb",
      "bbbbbbbbbbbbbbbb",
      "bbbbbbbbbbbbbbbb",
      "bbbbbbbbbbbbbbbb",
      "bbbbbbbbbbbbbbbb",
      "bbbbbbbbbbbbbbbb",
      "vvvvvvvvvvvvvvvv"
    ],
    [
      "accccccccccccccc",
      "cccccccccccccccc",
      "cccccccccccccccc",
      "cccccccccccccccc",
      "cccccccccccccccc",
      "cccccccccccccccc",
      "cccccccccccccccc",
      "cccccccccccccccc",
      "cccccccccccccccc",
      "cccccccccccccccc",
      "cccccccccccccccc",
      "cccccccccccccccc",
      "cccccccccccccccc",
      "cccccccccccccccc",
      "cccccccccccccccc",
      "vvvvvvvvvvvvvvvv"
    ]
  ]
}