{
  "name": "multi_verticalschool_3_floor19",
  "refpalette": "deceasedcraft:multi_verticalschool_3/multi_verticalschool_3_floor19_palette",
  "xsize": 16,
  "zsize": 16,
  "slices": [
    [
      "             a  ",
      "             a  ",
      "             ab ",
      "             a  ",
      "             a  ",
      "             ab ",
      "             a  ",
      "             a  ",
      "             a  ",
      "             a  ",
      "             a  ",
      "             a  ",
      "             a  ",
      "             a  ",
      "             ab ",
      "             a  "
    ],
    [
      "             a  ",
      "             a  ",
      "             a  ",
      "             a  ",
      "             a  ",
      "             a  ",
      "             a  ",
      "             a  ",
      "             a  ",
      "             a  ",
      "             a  ",
      "             a  ",
      "             a  ",
      "             a  ",
      "             a  ",
      "             a  "
    ],
    [
      "            cadd",
      "            cadd",
      "            cadd",
      "            cadd",
      "            cadd",
      "            cadd",
      "            cadd",
      "            cadd",
      "            cadd",
      "            cadd",
      "            cadd",
      "            cadd",
      "            cadd",
      "            cadd",
      "            cadd",
      "            cadd"
    ],
    [
      "            efgg",
      "            efgg",
      "            efgg",
      "            efgg",
      "            efgg",
      "            efgg",
      "            efgg",
      "            efgg",
      "            efgg",
      "            efgg",
      "            efgg",
      "            efgg",
      "            efgg",
      "            efgg",
      "            efgg",
      "            efgg"
    ],
    [
      "            hfij",
      "            hfik",
      "            hflk",
      "            hfik",
      "            hfik",
      "            hflk",
      "            hfik",
      "            hfik",
      "            hflk",
      "            hfij",
      "            hfij",
      "            hflk",
      "            hfik",
      "            hfik",
      "            hflk",
      "            hfik"
    ],
    [
      "             a  ",
      "             a  ",
      "             am ",
      "             a  ",
      "             a  ",
      "             am ",
      "             a  ",
      "             a  ",
      "             am ",
      "             a  ",
      "             a  ",
      "             am ",
      "             a  ",
      "             a  ",
      "             am ",
      "             a  "
    ]
  ]
}