{
  "name": "multi_verticalschool_3_floor9",
  "refpalette": "deceasedcraft:multi_verticalschool_3/multi_verticalschool_3_floor9_palette",
  "xsize": 16,
  "zsize": 16,
  "slices": [
    [
      "            abbb",
      "            abbb",
      "            abbb",
      "         c  abbb",
      "         c  abbb",
      "            abbb",
      "            abbb",
      "            abbb",
      "         c  abbb",
      "         cc abbb",
      "         c  abbb",
      "            abbb",
      "            abbb",
      "            abbb",
      "        ccc abbb",
      "            abbb"
    ],
    [
      "         c  a   ",
      "            a   ",
      "            a   ",
      "         c  a   ",
      "        ccc a   ",
      "            a   ",
      "            a   ",
      "            a   ",
      "         c  a   ",
      "        ccc a   ",
      "         c  a   ",
      "            a   ",
      "            a   ",
      "            a   ",
      "        ccc a   ",
      "         c  a   "
    ],
    [
      "         c  a   ",
      "            a   ",
      "            a   ",
      "         c  a   ",
      "        ccc a   ",
      "         c  a   ",
      "            a   ",
      "            a   ",
      "         c  a   ",
      "         c  a   ",
      "            a   ",
      "            a   ",
      "            a   ",
      "         c  a   ",
      "        cc  a   ",
      "         c  a   "
    ],
    [
      "          ~ a   ",
      "            a   ",
      "            a   ",
      "            a   ",
      "         cc a   ",
      "            a   ",
      "            a   ",
      "            a   ",
      "            a   ",
      "         c  a   ",
      "          ~ a   ",
      "            a   ",
      "            a   ",
      "         c  a   ",
      "         c  a   ",
      "            a   "
    ],
    [
      "            adee",
      "            adee",
      "            adee",
      "            adee",
      "         c  adee",
      "          ~ adee",
      "            adee",
      "            adee",
      "            adee",
      "            adee",
      "            adee",
      "            adee",
      "            adee",
      "            adee",
      "         c  adee",
      "          ~ adee"
    ],
    [
      "            afgg",
      "            afgg",
      "            afgg",
      "            afgg",
      "            afgg",
      "            afgg",
      "            afgg",
      "            afgg",
      "            afgg",
      "            afgg",
      "            afgg",
      "            afgg",
      "            afgg",
      "            afgg",
      "            afgg",
      "            affg"
    ]
  ]
}