{
  "name": "multi_verticalschool_3_floor8",
  "refpalette": "deceasedcraft:multi_verticalschool_3/multi_verticalschool_3_floor8_palette",
  "xsize": 16,
  "zsize": 16,
  "slices": [
    [
      "     ab   cd eff",
      "     ab   cg e  ",
      "     ab   chihff",
      "     ab   j     ",
      "     ab   j     ",
      "     ab   chkhll",
      "     ab   cm e  ",
      "     ab   cd ell",
      "     abn  cd e  ",
      "     ab   cd ell",
      "     ab   cd e  ",
      "     ab   cd ell",
      "     ab   cg e  ",
      "     ab   cccccc",
      "     ab         ",
      "     ab         "
    ],
    [
      "     aboppcppppq",
      "     aboppcppppr",
      "     aboppchhhhq",
      "     aboppcppppq",
      "     aboppcppppq",
      "     aboppchhhhq",
      "     aboppcppppr",
      "     aboppcppppq",
      "     aboppcppppr",
      "     aboppcppppq",
      "     aboppcppppr",
      "     aboppcppppq",
      "     aboppcppppr",
      "     aboppcccccc",
      "     abopppppppp",
      "     abopppppppp"
    ],
    [
      "     abbsttttttt",
      "     abbsttttttt",
      "     abbsttttttt",
      "     abbsttttttt",
      "     abbsttttttt",
      "     abbsttttttt",
      "     abbsttttttt",
      "     abbsttttttt",
      "     abbsttttttt",
      "     abbsttttttt",
      "     abbsttttttt",
      "     abbsttttttt",
      "     abbsttttttt",
      "     abbsttttttt",
      "     abbsttttttt",
      "     abbsstttttt"
    ],
    [
      "        u       ",
      "        w       ",
      "        u       ",
      "        w       ",
      "        uwx     ",
      "        u       ",
      "        u       ",
      "        u       ",
      "        u       ",
      "        uwy     ",
      "        u       ",
      "        w       ",
      "        u       ",
      "        u       ",
      "        uwx     ",
      "        uw      "
    ],
    [
      "                ",
      "                ",
      "                ",
      "        ~       ",
      "         u      ",
      "                ",
      "                ",
      "                ",
      "                ",
      "         u      ",
      "                ",
      "                ",
      "                ",
      "        ~       ",
      "         u      ",
      "                "
    ],
    [
      "            A BC",
      "            A BC",
      "            A BC",
      "            A BC",
      "         D  A BC",
      "            A BC",
      "            A BC",
      "            A BC",
      "            A BC",
      "         D  A BC",
      "         D  A BC",
      "            A BC",
      "            A BC",
      "            A BC",
      "         D  A BC",
      "            A BB"
    ]
  ]
}