{
  "name": "multi_verticalschool_3_floor15",
  "refpalette": "deceasedcraft:multi_verticalschool_3/multi_verticalschool_3_floor15_palette",
  "xsize": 16,
  "zsize": 16,
  "slices": [
    [
      "        a       ",
      "        abc     ",
      "        a       ",
      "        b       ",
      "        a       ",
      "        b       ",
      "        abc     ",
      "        a       ",
      "        a       ",
      "        a       ",
      "        a       ",
      "        abd     ",
      "        b       ",
      "        a       ",
      "        a       ",
      "        ab      "
    ],
    [
      "                ",
      "         a      ",
      "                ",
      "                ",
      "                ",
      "        ~       ",
      "         a      ",
      "                ",
      "                ",
      "                ",
      "                ",
      "         a      ",
      "                ",
      "                ",
      "                ",
      "                "
    ],
    [
      "            e fg",
      "         h  e fg",
      "            e fg",
      "            e fg",
      "            e fg",
      "            e fg",
      "         h  e fg",
      "            e fg",
      "            e fg",
      "            e fg",
      "         h  e fg",
      "         hh e fg",
      "            e fg",
      "            e fg",
      "            e fg",
      "            e ff"
    ],
    [
      "         h  ijkk",
      "        hhh ijkk",
      "         h  ijkk",
      "            ijkk",
      "            ijlm",
      "         h  ijll",
      "         hh ijlm",
      "            ijll",
      "            ijll",
      "            ijll",
      "         h  ijml",
      "        hhh ijml",
      "            ijll",
      "            ijll",
      "            ijlm",
      "            ijll"
    ],
    [
      "         h  nj  ",
      "        hhh nj  ",
      "         h  nj  ",
      "            nj  ",
      "            nj  ",
      "         h  nj  ",
      "        hhh nj  ",
      "            nj  ",
      "            nj  ",
      "            nj  ",
      "         h  nj  ",
      "        hh  nj  ",
      "         h  nj  ",
      "            nj  ",
      "            nj  ",
      "            nj  "
    ],
    [
      "             o  ",
      "         hh  o  ",
      "         h   o  ",
      "             o  ",
      "             o  ",
      "         h   o  ",
      "        hh   o  ",
      "         h   o  ",
      "             o  ",
      "             o  ",
      "         h   o  ",
      "         h   o  ",
      "             o  ",
      "             o  ",
      "             o  ",
      "             o  "
    ]
  ]
}