{
  "name": "multi_verticalschool_3_floor3",
  "refpalette": "deceasedcraft:multi_verticalschool_3/multi_verticalschool_3_floor3_palette",
  "xsize": 16,
  "zsize": 16,
  "slices": [
    [
      "             a  ",
      "             a  ",
      "             a  ",
      "             a  ",
      "             a  ",
      "             a  ",
      "             a  ",
      "             a  ",
      "             a  ",
      "             a  ",
      "             a  ",
      "             a  ",
      "             a  ",
      "             a  ",
      "             a  ",
      "             a  "
    ],
    [
      "             a  ",
      "             a  ",
      "             a  ",
      "             a  ",
      "             a  ",
      "             a  ",
      "             a  ",
      "             a  ",
      "             a  ",
      "             a  ",
      "             a  ",
      "             a  ",
      "             a  ",
      "             a  ",
      "             a  ",
      "             a  "
    ],
    [
      "             a  ",
      "             a  ",
      "             a  ",
      "             a  ",
      "             a  ",
      "             a  ",
      "             a  ",
      "             a  ",
      "             a  ",
      "             a  ",
      "             a  ",
      "             a  ",
      "             a  ",
      "             a  ",
      "             a  ",
      "             a  "
    ],
    [
      "            ba  ",
      "            ba  ",
      "            ba  ",
      "            ba  ",
      "            ba  ",
      "            ba  ",
      "            ba  ",
      "            ba  ",
      "            ba  ",
      "            ba  ",
      "            ba  ",
      "            ba  ",
      "            ba  ",
      "            ba  ",
      "            ba  ",
      "            ba  "
    ],
    [
      "            cdee",
      "            cdee",
      "            cdee",
      "            cdee",
      "            cdef",
      "            cdee",
      "            cdee",
      "            cdee",
      "            cdee",
      "            cdef",
      "            cdee",
      "            cdee",
      "            cdee",
      "            cdee",
      "            cdef",
      "            cdee"
    ],
    [
      "            gdhi",
      "            gdhi",
      "            gdhi",
      "            gdhi",
      "            gdhi",
      "            gdhj",
      "            gdhj",
      "            gdhj",
      "            gdhj",
      "            gdhj",
      "            gdhj",
      "            gdhj",
      "            gdhj",
      "            gdhj",
      "            gdhh",
      "            gddh"
    ]
  ]
}