{
  "name": "multi_verticalschool_3_floor14",
  "refpalette": "deceasedcraft:multi_verticalschool_3/multi_verticalschool_3_floor14_palette",
  "xsize": 16,
  "zsize": 16,
  "slices": [
    [
      "     ab    c    ",
      "     ab    c    ",
      "     ab    c    ",
      "     ab    c    ",
      "     ab    c    ",
      "     ab    c    ",
      "     ab    d    ",
      "     abe   d    ",
      "     ab    c    ",
      "     ab    c    ",
      "     ab    c    ",
      "     ab    c    ",
      "     ab    c    ",
      "     ab    c    ",
      "     ab     cccc",
      "     ab         "
    ],
    [
      "     ab    c    ",
      "     ab    c   f",
      "     ab    c    ",
      "     ab    c    ",
      "     ab    c    ",
      "     ab    c    ",
      "     ab    c    ",
      "     ab    c    ",
      "     ab    c    ",
      "     ab    c    ",
      "     ab    c    ",
      "     ab    c    ",
      "     ab    c   f",
      "     ab    c    ",
      "     ab     cccc",
      "     ab         "
    ],
    [
      "     ab    c    ",
      "     ab    c    ",
      "     ab    c    ",
      "     ab    c    ",
      "     ab    c    ",
      "     ab    c    ",
      "     ab    c    ",
      "     ab    c    ",
      "     ab    c    ",
      "     ab    c    ",
      "     ab    c    ",
      "     ab    c    ",
      "     ab    c    ",
      "     ab    c    ",
      "     ab     cccc",
      "     ab         "
    ],
    [
      "     ab    c    ",
      "     ab    c    ",
      "     ab    c    ",
      "     ab    c    ",
      "     ab    c    ",
      "     ab    c    ",
      "     ab    c    ",
      "     ab    c    ",
      "     ab    c    ",
      "     ab    c    ",
      "     ab    c    ",
      "     ab    c    ",
      "     ab    c    ",
      "     ab    c    ",
      "     ab     cccc",
      "     ab         "
    ],
    [
      "     abghhhciiii",
      "     abghhhciiii",
      "     abghhhcijji",
      "     abghhhciiii",
      "     abghhhciiii",
      "     abghhhcikki",
      "     abghhhciiii",
      "     abghhhciiii",
      "     abghhhcijji",
      "     abghhhciiii",
      "     abghhhciiii",
      "     abghhhcijji",
      "     abghhhciiii",
      "     abghhhciiii",
      "     abghhhhcccc",
      "     abghhhhhhhh"
    ],
    [
      "     abblmmmmmmm",
      "     abblmmmmmmm",
      "     abblmmmmmmm",
      "     abblmmmmmmm",
      "     abblmmmmmmm",
      "     abblmmmmmmm",
      "     abblmmmmmmm",
      "     abblmmmmmmm",
      "     abblmmmmmmm",
      "     abblmmmmmmm",
      "     abblmmmmmmm",
      "     abblmmmmmmm",
      "     abblmmmmmmm",
      "     abblmmmmmmm",
      "     abblmmmmmmm",
      "     abbllmmmmmm"
    ]
  ]
}