{
  "name": "multi_verticalschool_3_floor29",
  "refpalette": "deceasedcraft:multi_verticalschool_3/multi_verticalschool_3_floor29_palette",
  "xsize": 16,
  "zsize": 16,
  "slices": [
    [
      "            abcc",
      "            abcc",
      "            abcc",
      "            abcc",
      "            abcc",
      "            abcc",
      "            abcc",
      "            abcc",
      "            abcc",
      "            abcc",
      "            abcc",
      "            abcc",
      "            abcc",
      "            abcc",
      "            abcc",
      "            abcc"
    ],
    [
      "            dbef",
      "            dbgf",
      "            dbgf",
      "            dbgf",
      "            dbgf",
      "            dbgf",
      "            dbgf",
      "            dbgf",
      "            dbef",
      "            dbgf",
      "            dbgf",
      "            db f",
      "            dbgf",
      "            dbef",
      "            db f",
      "            dbgf"
    ],
    [
      "             h i",
      "             h i",
      "             h i",
      "             h i",
      "             h i",
      "             h i",
      "             h i",
      "             h i",
      "             h i",
      "             h  ",
      "             h i",
      "             h i",
      "             h i",
      "             h i",
      "             h i",
      "             h i"
    ],
    [
      "             h  ",
      "             h  ",
      "             h  ",
      "             h  ",
      "             h  ",
      "             h  ",
      "             h  ",
      "             h  ",
      "             h  ",
      "             h  ",
      "             h  ",
      "             h  ",
      "             h  ",
      "             h  ",
      "             h  ",
      "             h  "
    ],
    [
      "             h  ",
      "             h  ",
      "             h  ",
      "             h  ",
      "             h  ",
      "             h  ",
      "             h  ",
      "             h  ",
      "             h  ",
      "             h  ",
      "             h  ",
      "             h  ",
      "             h  ",
      "             h  ",
      "             h  ",
      "             h  "
    ],
    [
      "            jhkk",
      "            jhkk",
      "            jhkk",
      "            jhkk",
      "            jhkk",
      "            jhkk",
      "            jhkk",
      "            jhkk",
      "            jhkk",
      "            jhkk",
      "            jhkk",
      "            jhkk",
      "            jhkk",
      "            jhkk",
      "            jhkk",
      "            jhkk"
    ]
  ]
}