{
  "name": "multi_verticalschool_3_floor5",
  "refpalette": "deceasedcraft:multi_verticalschool_3/multi_verticalschool_3_floor5_palette",
  "xsize": 16,
  "zsize": 16,
  "slices": [
    [
      "     aabbbbbbbbb",
      "     aabbbbbbbbb",
      "     aabbbbbbbbb",
      "     aabbbbbbbbb",
      "     aabbbbbbbbb",
      "     aabbbbbbbbb",
      "     aabbbbbbbbb",
      "     aabbbbbbbbb",
      "     aabbbbbbbbb",
      "     aabbbbbbbbb",
      "     aabbbbbbbbb",
      "     aabbbbbbbbb",
      "     aabbbbbbbbb",
      "     aabbbbbbbbb",
      "     aabbbbbbbbb",
      "     aabbbbbbbbb"
    ],
    [
      "     accdcdcdcdc",
      "     accdcdcdcdc",
      "     accdcdcdcdc",
      "     accdcdcdcdc",
      "     accdcdcdcdc",
      "     accdcdcdcdc",
      "     accdcdcdcdc",
      "     accdcdcdcdc",
      "     accdcdcdcdc",
      "     accdcdcdcdc",
      "     accdcdcdcdc",
      "     accdcdcdcdc",
      "     accdcdcdcdc",
      "     acccccccccc",
      "     acccccccccc",
      "     ae         "
    ],
    [
      "     acfffffffff",
      "     acfffffffff",
      "     acfffffffff",
      "     acfffffffff",
      "     acgfffffffh",
      "     acfffffffff",
      "     acfffffffff",
      "     acfffffffff",
      "     acfffffffff",
      "     acgfffffffh",
      "     acfffffffff",
      "     acfffffffff",
      "     acfffffffff",
      "     acfffffffff",
      "     acccccccccc",
      "     aei        "
    ],
    [
      "     acfffffffff",
      "     acfffffffff",
      "     acfffffffff",
      "     acfffffffff",
      "     acfffffffff",
      "     acfffffffff",
      "     acfffffffff",
      "     acfffffffff",
      "     acfffffffff",
      "     acfffffffff",
      "     acfffffffff",
      "     acfffffffff",
      "     acfffffffff",
      "     acfjfjfjfjf",
      "     acccccccccc",
      "     abbbbbbbbbb"
    ],
    [
      "     a          ",
      "     a          ",
      "     a          ",
      "     a          ",
      "     a          ",
      "     a          ",
      "     a          ",
      "     a          ",
      "     a          ",
      "     a          ",
      "     a          ",
      "     a          ",
      "     a          ",
      "     a          ",
      "     a          ",
      "     a  k k k k "
    ],
    [
      "     a          ",
      "     a          ",
      "     a          ",
      "     a          ",
      "     a          ",
      "     a          ",
      "     a          ",
      "     a          ",
      "     a          ",
      "     a          ",
      "     a          ",
      "     a          ",
      "     a          ",
      "     a          ",
      "     a          ",
      "     a          "
    ]
  ]
}