{
  "name": "multi_verticalschool_3_floor7",
  "refpalette": "deceasedcraft:multi_verticalschool_3/multi_verticalschool_3_floor7_palette",
  "xsize": 16,
  "zsize": 16,
  "slices": [
    [
      "                ",
      "                ",
      "                ",
      "                ",
      "                ",
      "                ",
      "                ",
      "                ",
      "                ",
      "                ",
      "                ",
      "                ",
      "                ",
      "                ",
      "                ",
      "                "
    ],
    [
      "                ",
      "                ",
      "                ",
      "                ",
      "                ",
      "                ",
      "                ",
      "                ",
      "                ",
      "                ",
      "                ",
      "                ",
      "                ",
      "                ",
      "                ",
      "                "
    ],
    [
      "      a bcbbbbbb",
      "      a bcbbbbbb",
      "      a bcbbbbbb",
      "      a bcbbbbbb",
      "      a bcbbbbbb",
      "      a bcbbbbbb",
      "      a bcbbbbbb",
      "      a bcbbbbbb",
      "      a bcbbbbbb",
      "      a bcbbbbbb",
      "      a bcbbbbbb",
      "      a bcbbbbbb",
      "      a bcbbbbbb",
      "      a bcbbbbbb",
      "      a bcbbbbbb",
      "      a bbcbbbbb"
    ],
    [
      "     defgghiiiii",
      "     defgghiiiii",
      "     defgghiiiii",
      "     defggffffff",
      "     defggffffff",
      "     defgghiiiii",
      "     defgghiiiii",
      "     defgghiiiii",
      "     defgghiiiii",
      "     defgghiiiii",
      "     defgghiiiii",
      "     defgghiiiii",
      "     defgghiiiii",
      "     defgghhhhhh",
      "     defgggggggg",
      "     defgggggggg"
    ],
    [
      "     de   hj kll",
      "     de   h  m n",
      "     de   hopoll",
      "     de        q",
      "     de        r",
      "     de   hosott",
      "     de   h  u n",
      "     de   hj ktt",
      "     dew  h  u n",
      "     de   hj ktt",
      "     de   h  u n",
      "     de   hj ktt",
      "     de   h  u n",
      "     de   hhhhhh",
      "     de    xyyyx",
      "     de         "
    ],
    [
      "     de   A  kll",
      "     de   A  B  ",
      "     dC   AoDoll",
      "     dC         ",
      "     dC         ",
      "     dC   AoEott",
      "     de   A  F  ",
      "     de   A  ktt",
      "     deI  A  F  ",
      "     de   A  ktt",
      "     de   A  F  ",
      "     dC   A  ktt",
      "     dC   A JF  ",
      "     dC   AAAAAA",
      "     dC    !   K",
      "     de         "
    ]
  ]
}