{
  "name": "multi_verticalschool_3_base1",
  "refpalette": "deceasedcraft:multi_verticalschool_3/multi_verticalschool_3_base1_palette",
  "xsize": 16,
  "zsize": 16,
  "slices": [
    [
      "v    aa         ",
      "vbbbbbac        ",
      "vvvvvva         ",
      "vddddddaa efghgg",
      "vddddddddaaaaaaa",
      "vddddddddddddddd",
      "vddddddddddddddd",
      "vddddddddddddddd",
      "vddddddddddddddd",
      "vddddddddddddddd",
      "vddddddddddddddd",
      "vddddddddddddddd",
      "vddddddddddddddd",
      "vddddddddddddddd",
      "vddddddddddddddd",
      "vddddddddddddddd"
    ],
    [
      "v    aaia       ",
      "vbbbbbaja       ",
      "vvvvvvaka       ",
      "vddddddaa hehege",
      "vddddddddaaaaaaa",
      "vddddddddddddddd",
      "vddddddddddddddd",
      "vddddddddddddddd",
      "vddddddddddddddd",
      "vddddddddddddddd",
      "vddddddddddddddd",
      "vddddddddddddddd",
      "vddddddddddddddd",
      "vddddddddddddddd",
      "vddddddddddddddd",
      "vddddddddddddddd"
    ],
    [
      "v    aala       ",
      "vbbbbbala       ",
      "vvvvvvala       ",
      "vddddddaa feffhh",
      "vddddddddaaaaaaa",
      "vddddddddddddddm",
      "vddddddddddddddm",
      "vddddddddddddddm",
      "vddddddddddddddm",
      "vddddddddddddddm",
      "vddddddddddddddm",
      "vdddddddddddddda",
      "vddddddddddddddn",
      "vddddddddddddddn",
      "vddddddddddddddn",
      "vddddddddddddddn"
    ],
    [
      "v    aaoa       ",
      "vbbbbbapa       ",
      "vvvvvvaqa       ",
      "vddddddaa r    r",
      "vddddddddaaaaaaa",
      "vdddddddddddmmms",
      "vdddddddddddmmmH",
      "vdddddddddddmmmH",
      "vdddddddddddmmmH",
      "vdddddddddddmmmH",
      "vdddddddddddmmms",
      "vdddddddddddaaat",
      "vdddddddddddnnnu",
      "vdddddddddddnnnu",
      "vdddddddddddnnnu",
      "vdddddddddddnnnu"
    ],
    [
      "v    aawa       ",
      "vbbbbbaxa       ",
      "vvvvvvaxa       ",
      "vddddddaaxyxxxxy",
      "vddddddddaaaaaaa",
      "vddddddddmmmsAB ",
      "vddddddddmmmHCD ",
      "vddddddddmmmHCD ",
      "vddddddddmmmHCD ",
      "vddddddddmmmHCD ",
      "vddddddddmmmsAB ",
      "vddddddddaaatttE",
      "vddddddddnnnuuF ",
      "vddddddddnnnuuF ",
      "vddddddddnnnuuF ",
      "vddddddddnnnuuF "
    ],
    [
      "vIIIIaIIaIIIIIII",
      "vJJJJJaIaIIKIIKI",
      "vvvvvvaIaIIIIIII",
      "vmmmmmmaaIIIIIII",
      "vmmmmmmmmaaaaaaa",
      "vmmmmmmmmsAB    ",
      "vmmmmmmmmHCD    ",
      "vmmmmmmmmHCD    ",
      "vmmmmmmmmHCD    ",
      "vmmmmmmmmHCD    ",
      "vmmmmmmmmsAB    ",
      "vmmmmmmmmtttEL  ",
      "vmmmmmmaauuF    ",
      "vmmmmmannuuF    ",
      "vmmmmmannuuF    ",
      "vmmmmmannuuF    "
    ]
  ]
}