{
  "name": "multi_verticalschool_3_floor13",
  "refpalette": "deceasedcraft:multi_verticalschool_3/multi_verticalschool_3_floor13_palette",
  "xsize": 16,
  "zsize": 16,
  "slices": [
    [
      "                ",
      "                ",
      "                ",
      "                ",
      "                ",
      "                ",
      "                ",
      "                ",
      "                ",
      "                ",
      "                ",
      "                ",
      "                ",
      "                ",
      "                ",
      "                "
    ],
    [
      "                ",
      "                ",
      "                ",
      "                ",
      "                ",
      "                ",
      "                ",
      "                ",
      "                ",
      "                ",
      "                ",
      "                ",
      "                ",
      "                ",
      "                ",
      "                "
    ],
    [
      "      a bcbbbbbb",
      "      a bcbbbbbb",
      "      a bcbbbbbb",
      "      a bcbbbbbb",
      "      a bcbbbbbb",
      "      a bcbbbbbb",
      "      a bcbbbbbb",
      "      a bcbbbbbb",
      "      a bcbbbbbb",
      "      a bcbbbbbb",
      "      a bcbbbbbb",
      "      a bcbbbbbb",
      "      a bcbbbbbb",
      "      a bcbbbbbb",
      "      a bcbbbbbb",
      "      a bbcbbbbb"
    ],
    [
      "     defggghffff",
      "     defggghffff",
      "     defggghffff",
      "     defggghffff",
      "     defggghffff",
      "     defggghffff",
      "     defggghffff",
      "     defggghffff",
      "     defggghffff",
      "     defggghffff",
      "     defggghffff",
      "     defggghffff",
      "     defggghffff",
      "     defggghffff",
      "     defgggghhhh",
      "     defgggggggg"
    ],
    [
      "     de    hi   ",
      "     de    h    ",
      "     de    hj   ",
      "     de    hk   ",
      "     de    hl   ",
      "     de    h    ",
      "     de    m    ",
      "     den   o    ",
      "     de    h    ",
      "     de    hj p ",
      "     de    hk p ",
      "     de    hl p ",
      "     de    h    ",
      "     de    hi q ",
      "     de     hhhh",
      "     de         "
    ],
    [
      "     de    h    ",
      "     de    h    ",
      "     dr    h    ",
      "     dr    h    ",
      "     dr    h    ",
      "     de   sh    ",
      "     de    t    ",
      "     deu   w    ",
      "     de   sh    ",
      "     de    h    ",
      "     dr    h    ",
      "     dr    h    ",
      "     dr    h    ",
      "     dr    hx   ",
      "     de     hhhh",
      "     de         "
    ]
  ]
}