{
  "name": "multi_verticalschool_3_floor17",
  "refpalette": "deceasedcraft:multi_verticalschool_3/multi_verticalschool_3_floor17_palette",
  "xsize": 16,
  "zsize": 16,
  "slices": [
    [
      "                ",
      "                ",
      "                ",
      "                ",
      "                ",
      "                ",
      "                ",
      "                ",
      "                ",
      "                ",
      "                ",
      "                ",
      "                ",
      "                ",
      "                ",
      "                "
    ],
    [
      "                ",
      "                ",
      "                ",
      "                ",
      "                ",
      "                ",
      "                ",
      "                ",
      "                ",
      "                ",
      "                ",
      "                ",
      "                ",
      "                ",
      "                ",
      "                "
    ],
    [
      "            a bc",
      "            a bc",
      "            a bc",
      "            a bc",
      "            a bc",
      "            a bc",
      "            a bc",
      "            a bc",
      "            a bc",
      "            a bc",
      "            a bc",
      "            a bc",
      "            a bc",
      "            a bc",
      "            a bc",
      "            a bb"
    ],
    [
      "            deff",
      "            deff",
      "            deff",
      "            deff",
      "            deff",
      "            deff",
      "            deff",
      "            deff",
      "            deff",
      "            deff",
      "            deff",
      "            deff",
      "            deff",
      "            deff",
      "            deff",
      "            deff"
    ],
    [
      "            gehi",
      "            gehi",
      "            geji",
      "            gehi",
      "            gehi",
      "            geji",
      "            gehi",
      "            gehi",
      "            geji",
      "            gehk",
      "            gehi",
      "            geji",
      "            gehk",
      "            gehi",
      "            geji",
      "            gehi"
    ],
    [
      "             l  ",
      "             l  ",
      "             lm ",
      "             l  ",
      "             l  ",
      "             lm ",
      "             l  ",
      "             l  ",
      "             lm ",
      "             l  ",
      "             l  ",
      "             lm ",
      "             l  ",
      "             l  ",
      "             lm ",
      "             l  "
    ]
  ]
}