{
  "name": "multi_verticalschool_3_floor16",
  "refpalette": "deceasedcraft:multi_verticalschool_3/multi_verticalschool_3_floor16_palette",
  "xsize": 16,
  "zsize": 16,
  "slices": [
    [
      "             a  ",
      "         b   a  ",
      "          ~  a  ",
      "             a  ",
      "             a  ",
      "         b   a  ",
      "         b   a  ",
      "             a  ",
      "             a  ",
      "             a  ",
      "             a  ",
      "         b   a  ",
      "          ~  a  ",
      "             a  ",
      "             a  ",
      "             a  "
    ],
    [
      "             a  ",
      "             a  ",
      "             a  ",
      "             a  ",
      "             a  ",
      "             a  ",
      "         b   a  ",
      "          ~  a  ",
      "             a  ",
      "             a  ",
      "             a  ",
      "             a  ",
      "             a  ",
      "             a  ",
      "             a  ",
      "             a  "
    ],
    [
      "             a  ",
      "             a  ",
      "             a  ",
      "             a  ",
      "             a  ",
      "             a  ",
      "             a  ",
      "             a  ",
      "             a  ",
      "             a  ",
      "             a  ",
      "             a  ",
      "             a  ",
      "             a  ",
      "             a  ",
      "             a  "
    ],
    [
      "            cadd",
      "            cadd",
      "            cadd",
      "            cadd",
      "            cadd",
      "            cadd",
      "            cadd",
      "            cadd",
      "            cadd",
      "            cadd",
      "            cadd",
      "            cadd",
      "            cadd",
      "            cadd",
      "            cadd",
      "            cadd"
    ],
    [
      "            efgd",
      "            efhd",
      "            efhd",
      "            efgd",
      "            efgd",
      "            efgd",
      "            efhd",
      "            efhd",
      "            efgd",
      "            efgd",
      "            efgd",
      "            efhd",
      "            efhd",
      "            efgd",
      "            efgd",
      "            efgd"
    ],
    [
      "            ifee",
      "            ifee",
      "            ifee",
      "            ifee",
      "            ifee",
      "            ifee",
      "            ifee",
      "            ifee",
      "            ifee",
      "            ifee",
      "            ifee",
      "            ifee",
      "            ifee",
      "            ifee",
      "            ifee",
      "            ifee"
    ]
  ]
}