{
  "name": "multi_verticalschool_3_floor26",
  "refpalette": "deceasedcraft:multi_verticalschool_3/multi_verticalschool_3_floor26_palette",
  "xsize": 16,
  "zsize": 16,
  "slices": [
    [
      "            abcc",
      "            abcc",
      "            abcc",
      "            abcc",
      "            abcc",
      "            abcc",
      "            abcc",
      "            abcc",
      "            abcc",
      "            abcc",
      "            abcc",
      "            abcc",
      "            abcc",
      "            abcc",
      "            abcc",
      "            abcc"
    ],
    [
      "            dbef",
      "            dbef",
      "            dbgf",
      "            dbgf",
      "            dbef",
      "            dbef",
      "            dbef",
      "            dbeh",
      "            dbef",
      "            dbef",
      "            dbef",
      "            dbgf",
      "            db f",
      "            dbgf",
      "            dbef",
      "            dbef"
    ],
    [
      "             i j",
      "             i j",
      "             i  ",
      "             i j",
      "             i j",
      "             i j",
      "             i j",
      "             i  ",
      "             i j",
      "             i j",
      "             i j",
      "             i j",
      "             i j",
      "             i j",
      "             i j",
      "             i  "
    ],
    [
      "             i  ",
      "             i  ",
      "             i  ",
      "             i  ",
      "             i  ",
      "             i  ",
      "             i  ",
      "             i  ",
      "             i  ",
      "             i  ",
      "             i  ",
      "             i  ",
      "             i  ",
      "             i  ",
      "             i  ",
      "             i  "
    ],
    [
      "             i  ",
      "             i  ",
      "             i  ",
      "             i  ",
      "             i  ",
      "             i  ",
      "             i  ",
      "             i  ",
      "             i  ",
      "             i  ",
      "             i  ",
      "             i  ",
      "             i  ",
      "             i  ",
      "             i  ",
      "             i  "
    ],
    [
      "            kill",
      "            kill",
      "            kill",
      "            kill",
      "            kill",
      "            kill",
      "            kill",
      "            kill",
      "            kill",
      "            kill",
      "            kill",
      "            kill",
      "            kill",
      "            kill",
      "            kill",
      "            kill"
    ]
  ]
}