{
  "name": "multi_verticalschool_3_floor31",
  "refpalette": "deceasedcraft:multi_verticalschool_3/multi_verticalschool_3_floor31_palette",
  "xsize": 16,
  "zsize": 16,
  "slices": [
    [
      "             a  ",
      "             a  ",
      "             a  ",
      "             a  ",
      "             a  ",
      "             a  ",
      "             a  ",
      "             a  ",
      "             a  ",
      "             a  ",
      "             a  ",
      "             a  ",
      "             a  ",
      "             a  ",
      "             a  ",
      "             a  "
    ],
    [
      "             a  ",
      "             a  ",
      "             a  ",
      "             a  ",
      "             a  ",
      "             a  ",
      "             a  ",
      "             a  ",
      "             a  ",
      "             a  ",
      "             a  ",
      "             a  ",
      "             a  ",
      "             a  ",
      "             a  ",
      "             a  "
    ],
    [
      "             a  ",
      "             a  ",
      "             a  ",
      "             a  ",
      "             a  ",
      "             a  ",
      "             a  ",
      "             a  ",
      "             a  ",
      "             a  ",
      "             a  ",
      "             a  ",
      "             a  ",
      "             a  ",
      "             a  ",
      "             a  "
    ],
    [
      "            ba  ",
      "            ba  ",
      "            ba  ",
      "            ba  ",
      "            ba  ",
      "            ba  ",
      "            ba  ",
      "            ba  ",
      "            ba  ",
      "            ba  ",
      "            ba  ",
      "            ba  ",
      "            ba  ",
      "            ba  ",
      "            ba  ",
      "            ba  "
    ],
    [
      "            cdee",
      "            cdee",
      "            cdee",
      "            cdee",
      "            cdee",
      "            cdee",
      "            cdee",
      "            cdee",
      "            cdee",
      "            cdee",
      "            cdee",
      "            cdee",
      "            cdee",
      "            cdee",
      "            cdee",
      "            cdee"
    ],
    [
      "            cccc",
      "            cccc",
      "            cccc",
      "            cccc",
      "            cccc",
      "            cccc",
      "            cccc",
      "            cccc",
      "            cccc",
      "            cccc",
      "            cccc",
      "            cccc",
      "            cccc",
      "            cccc",
      "            cccc",
      "            cccc"
    ]
  ]
}