{
  "name": "multi_verticalschool_3_floor4",
  "refpalette": "deceasedcraft:multi_verticalschool_3/multi_verticalschool_3_floor4_palette",
  "xsize": 16,
  "zsize": 16,
  "slices": [
    [
      "             ab ",
      "             ab ",
      "             ab ",
      "             ab ",
      "             ab ",
      "             ab ",
      "             ab ",
      "             ab ",
      "             ab ",
      "             ab ",
      "             ab ",
      "             ab ",
      "             ab ",
      "             ab ",
      "             abb",
      "             aab"
    ],
    [
      "              c ",
      "              c ",
      "              c ",
      "              c ",
      "              c ",
      "              c ",
      "              c ",
      "                ",
      "              c ",
      "                ",
      "              c ",
      "              c ",
      "              c ",
      "              c ",
      "              cc",
      "               c"
    ],
    [
      "                ",
      "                ",
      "                ",
      "                ",
      "                ",
      "                ",
      "                ",
      "                ",
      "                ",
      "                ",
      "                ",
      "                ",
      "                ",
      "                ",
      "                ",
      "                "
    ],
    [
      "                ",
      "                ",
      "                ",
      "                ",
      "                ",
      "                ",
      "                ",
      "                ",
      "                ",
      "                ",
      "                ",
      "                ",
      "                ",
      "                ",
      "                ",
      "                "
    ],
    [
      "                ",
      "                ",
      "                ",
      "                ",
      "                ",
      "                ",
      "                ",
      "                ",
      "                ",
      "                ",
      "                ",
      "                ",
      "                ",
      "                ",
      "                ",
      "                "
    ],
    [
      "     deefeeefeee",
      "     deefeeefeee",
      "     deefeeefeee",
      "     deefeeefeee",
      "     deefeeefeee",
      "     deefeeefeee",
      "     deefeeefeee",
      "     deefeeefeee",
      "     deefeeefeee",
      "     deefeeefeee",
      "     deefeeefeee",
      "     deefeeefeee",
      "     deefeeefeee",
      "     deefeeefeee",
      "     deefeeefeee",
      "     deefeeefeee"
    ]
  ]
}