{
  "name": "multi_verticalschool_3_floor23",
  "refpalette": "deceasedcraft:multi_verticalschool_3/multi_verticalschool_3_floor23_palette",
  "xsize": 16,
  "zsize": 16,
  "slices": [
    [
      "           ab   ",
      "           ab   ",
      "           ab   ",
      "           ab   ",
      "           a    ",
      "           ab   ",
      "           ab   ",
      "           ab   ",
      "           ab   ",
      "           a    ",
      "           ab   ",
      "           ab   ",
      "           ab   ",
      "           ab   ",
      "           a    ",
      "           ab   "
    ],
    [
      "           acdee",
      "           acdee",
      "           acdee",
      "           acdee",
      "           acdee",
      "           acdee",
      "           acdee",
      "           acdee",
      "           acdee",
      "           acdee",
      "           acdee",
      "           acdee",
      "           acdee",
      "           acdee",
      "           acdee",
      "           acdee"
    ],
    [
      "           aafaa",
      "           aafaa",
      "           aafaa",
      "           aafaa",
      "           aafaa",
      "           aafaa",
      "           aafaa",
      "           aafaa",
      "           aafaa",
      "           aafaa",
      "           aafaa",
      "           aafaa",
      "           aafaa",
      "           aafaa",
      "           aafaa",
      "           aafaa"
    ],
    [
      "           g   g",
      "           g   g",
      "           g   g",
      "           g   g",
      "           g   g",
      "           g   g",
      "           g   g",
      "           g   g",
      "           g   g",
      "           g   g",
      "           g   g",
      "           g   g",
      "           g   g",
      "           g   g",
      "           g   g",
      "           g   g"
    ],
    [
      "                ",
      "                ",
      "                ",
      "                ",
      "                ",
      "                ",
      "                ",
      "                ",
      "                ",
      "                ",
      "                ",
      "                ",
      "                ",
      "                ",
      "                ",
      "                "
    ],
    [
      "                ",
      "                ",
      "                ",
      "                ",
      "                ",
      "                ",
      "                ",
      "                ",
      "                ",
      "                ",
      "                ",
      "                ",
      "                ",
      "                ",
      "                ",
      "                "
    ]
  ]
}