{
  "name": "multi_verticalschool_3_floor18",
  "refpalette": "deceasedcraft:multi_verticalschool_3/multi_verticalschool_3_floor18_palette",
  "xsize": 16,
  "zsize": 16,
  "slices": [
    [
      "             a  ",
      "             a  ",
      "             ab ",
      "             a  ",
      "             a  ",
      "             ab ",
      "             a  ",
      "             a  ",
      "             ab ",
      "             a  ",
      "             a  ",
      "             ab ",
      "             a  ",
      "             a  ",
      "             a  ",
      "             a  "
    ],
    [
      "             a  ",
      "             a  ",
      "             a  ",
      "             a  ",
      "             a  ",
      "             a  ",
      "             a  ",
      "             a  ",
      "             a  ",
      "             a  ",
      "             a  ",
      "             a  ",
      "             a  ",
      "             a  ",
      "             a  ",
      "             a  "
    ],
    [
      "            cadd",
      "            cadd",
      "            cadd",
      "            cadd",
      "            cadd",
      "            cadd",
      "            cadd",
      "            cadd",
      "            cadd",
      "            cadd",
      "            cadd",
      "            cadd",
      "            cadd",
      "            cadd",
      "            cadd",
      "            cadd"
    ],
    [
      "            efgg",
      "            efgg",
      "            efgg",
      "            efgg",
      "            efgg",
      "            efgg",
      "            efgg",
      "            efgg",
      "            efgg",
      "            efgg",
      "            efgg",
      "            efgg",
      "            efgg",
      "            efgg",
      "            efgg",
      "            efgg"
    ],
    [
      "            hfij",
      "            hfij",
      "            hfkj",
      "            hfil",
      "            hfij",
      "            hfkj",
      "            hfil",
      "            hfij",
      "            hfkj",
      "            hfij",
      "            hfij",
      "            hfkj",
      "            hfij",
      "            hfij",
      "            hfkj",
      "            hfij"
    ],
    [
      "             a  ",
      "             a  ",
      "             am ",
      "             a  ",
      "             a  ",
      "             am ",
      "             a  ",
      "             a  ",
      "             am ",
      "             a  ",
      "             a  ",
      "             am ",
      "             a  ",
      "             a  ",
      "             am ",
      "             a  "
    ]
  ]
}