{
  "name": "multi_verticalschool_3_floor21",
  "refpalette": "deceasedcraft:multi_verticalschool_3/multi_verticalschool_3_floor21_palette",
  "xsize": 16,
  "zsize": 16,
  "slices": [
    [
      "             a  ",
      "             a  ",
      "             ab ",
      "             a  ",
      "             a  ",
      "             a  ",
      "             a  ",
      "             a  ",
      "             ab ",
      "             a  ",
      "             a  ",
      "             ab ",
      "             a  ",
      "             a  ",
      "             ab ",
      "             a  "
    ],
    [
      "             a  ",
      "             a  ",
      "             a  ",
      "             a  ",
      "             a  ",
      "             a  ",
      "             a  ",
      "             a  ",
      "             a  ",
      "             a  ",
      "             a  ",
      "             a  ",
      "             a  ",
      "             a  ",
      "             a  ",
      "             a  "
    ],
    [
      "            cadd",
      "            cadd",
      "            cadd",
      "            cadd",
      "            cadd",
      "            cadd",
      "            cadd",
      "            cadd",
      "            cadd",
      "            cadd",
      "            cadd",
      "            cadd",
      "            cadd",
      "            cadd",
      "            cadd",
      "            cadd"
    ],
    [
      "            efgg",
      "            efgg",
      "            efgg",
      "            efgg",
      "            efgg",
      "            efgg",
      "            efgg",
      "            efgg",
      "            efgg",
      "            efgg",
      "            efgg",
      "            efgg",
      "            efgg",
      "            efgg",
      "            efgg",
      "            efgg"
    ],
    [
      "            hfee",
      "            hfee",
      "            hfee",
      "            hfee",
      "            hfee",
      "            hfee",
      "            hfee",
      "            hfee",
      "            hfee",
      "            hfee",
      "            hfee",
      "            hfee",
      "            hfee",
      "            hfee",
      "            hfee",
      "            hfee"
    ],
    [
      "                ",
      "                ",
      "                ",
      "                ",
      "                ",
      "                ",
      "                ",
      "                ",
      "                ",
      "                ",
      "                ",
      "                ",
      "                ",
      "                ",
      "                ",
      "                "
    ]
  ]
}