{
  "name": "multi_farmhouse1_7_floor1",
  "refpalette": "deceasedcraft:multi_farmhouse1_7/multi_farmhouse1_7_floor1_palette",
  "xsize": 16,
  "zsize": 16,
  "slices": [
    [
      "aaaaaaaaaaaaaaaa",
      "bbaaaaaaaaaaaaaa",
      "bbbbaaaaaaaaaaaa",
      "bbbbaaaaaaaaaaaa",
      "bbbbbaaaaaaaaaaa",
      "bbbbbcaaaaaaaaaa",
      "bbbbbcaaaaaaaaaa",
      "bbbbbaaaaaaaaaaa",
      "bbbbccaaaaaaaaaa",
      "bbbbcccaaaaaaaaa",
      "bbbaacccaaaaaaaa",
      "bbbaaccccaaaaaaa",
      "bbbaaccaaaadaaaa",
      "aaaaaccdcaaaaada",
      "aaaaccccaddadaaa",
      "aaaaccacdaadadaa"
    ],
    [
      "eeeeeefeefffeeeg",
      "aaeeeeeffeeffffe",
      "aaaaefefeffefeeg",
      "aaaaeeeefeefeefe",
      "hhaaceeeeeefeeeg",
      "hhccaeeeeeeeeeee",
      "hhccceeeeeeeeeei",
      "hhcaceeeeeeeeeee",
      "hhaaeeeeeeeeeeej",
      "hhaaeeeeeeeeeeei",
      "hhaeeeeeeeeeeeei",
      "hhaeeeeeeeeeeegg",
      "aaaeeeeeeeeeeeei",
      "eeeeeeeeeeeeeeee",
      "eeeeeeeeeeeeeeei",
      "eeeeeeeeeeeeeegi"
    ],
    [
      "eeeeeekeekkkeeee",
      "eeeeeeekkeekkkke",
      "eeeeekekekkekeee",
      "eeeeeeeekeekeeke",
      "eeeeeeeeeeekeeee",
      "eeeeeeeeeeeeeeee",
      "eeeeeeeeeeeeeeee",
      "eeeeeeeeeeeeeeee",
      "eeeeeeeeeeeeeeee",
      "eeeeeeeeeeeeeeee",
      "eeeeeeeeeeeeeeee",
      "eeeeeeeeeeeeeeee",
      "eeeeeeeeeeeeeeee",
      "eeeeeeeeeeeeeeee",
      "eeeeeeeeeeeeeeee",
      "eeeeeeeeeeeeeeee"
    ],
    [
      "eeeeeeeeeeeeeeee",
      "eeeeeeeeeeeeeeee",
      "eeeeeeeeeeeeeeee",
      "eeeeeeeeeeeeeeee",
      "eeeeeeeeeeeeeeee",
      "eeeeeeeeeeeeeeee",
      "eeeeeeeeeeeeeeee",
      "eeeeeeeeeeeeeeee",
      "eeeeeeeeeeeeeeee",
      "eeeeeeeeeeeeeeee",
      "eeeeeeeeeeeeeeee",
      "eeeeeeeeeeeeeeee",
      "eeeeeeeeeeeeeeee",
      "eeeeeeeeeeeeeeee",
      "eeeeeeeeeeeeeeee",
      "eeeeeeeeeeeeeeee"
    ],
    [
      "eeeeeeeeeeeeeeee",
      "eeeeeeeeeeeeeeee",
      "eeeeeeeeeeeeeeee",
      "eeeeeeeeeeeeeeee",
      "eeeeeeeeeeeeeeee",
      "eeeeeeeeeeeeeeee",
      "eeeeeeeeeeeeeeee",
      "eeeeeeeeeeeeeeee",
      "eeeeeeeeeeeeeeee",
      "eeeeeeeeeeeeeeee",
      "eeeeeeeeeeeeeeee",
      "eeeeeeeeeeeeeeee",
      "eeeeeeeeeeeeeeee",
      "eeeeeeeeeeeeeeee",
      "eeeeeeeeeeeeeeee",
      "eeeeeeeeeeeeeeee"
    ],
    [
      "eeeeeeeeeeeeeeee",
      "eeeeeeeeeeeeeeee",
      "eeeeeeeeeeeeeeee",
      "eeeeeeeeeeeeeeee",
      "eeeeeeeeeeeeeeee",
      "eeeeeeeeeeeeeeee",
      "eeeeeeeeeeeeeeee",
      "eeeeeeeeeeeeeeee",
      "eeeeeeeeeeeeeeee",
      "eeeeeeeeeeeeeeee",
      "eeeeeeeeeeeeeeee",
      "eeeeeeeeeeeeeeee",
      "eeeeeeeeeeeeeeee",
      "eeeeeeeeeeeeeeee",
      "eeeeeeeeeeeeeeee",
      "eeeeeeeeeeeeeeee"
    ]
  ]
}