{
  "name": "multi_arcfurnace_1_ground",
  "refpalette": "deceasedcraft:multi_arcfurnace_1/multi_arcfurnace_1_ground_palette",
  "xsize": 16,
  "zsize": 16,
  "slices": [
    [
      "aaabbcbbbbbcbbzz",
      "zaabbcbbbbbcbbzz",
      "azabbcbbbbbcbbzz",
      "aaabbcccccddbbzz",
      "aaaeeffeeeeeeezz",
      "aaabbffbbbbbbbzz",
      "zaabbffbbbbbbbzz",
      "aaafgfffbbbbbbzz",
      "zaafffffbbbbbbzz",
      "zaafffffbbbbbbzz",
      "aaafffhfbbbbbbzz",
      "aaabbbbbbbbbbbzz",
      "azabbbbbbbbbbbzz",
      "aaabbbbbbbbbbbzz",
      "zaazzzzzzzzzzzzz",
      "aazzzzzzzzzzzzzz"
    ],
    [
      "   i  jkkkj  e  ",
      "   i  kkkkk  e  ",
      "   i  lkmkk  e  ",
      "   e    n    e  ",
      "   el  opppple  ",
      "   e   qrsstqe  ",
      "             e  ",
      "         uuu e  ",
      "         u!u e  ",
      "         uuu e  ",
      "            we  ",
      "     xy    ABe  ",
      "   elxxClADEle  ",
      "   eeeeeeeeeee  ",
      "                ",
      "                "
    ],
    [
      "   i  jFFFj  e  ",
      "   i         e  ",
      "   i  I      e  ",
      "   e    J    e  ",
      "   el       le  ",
      "   e   KL   Me  ",
      "   i         e  ",
      "   i     uuu e  ",
      "   i    Nu u e  ",
      "   i     uuu e  ",
      "   i         e  ",
      "   i        we  ",
      "   elOx l  wle  ",
      "   eeeeeeeeeee  ",
      "                ",
      "                "
    ],
    [
      "   i  jFFFj  e  ",
      "   i   FFF   e  ",
      "   i   FFF   e  ",
      "   e         e  ",
      "   el       le  ",
      "   e         e  ",
      "   i         e  ",
      "   i     uuu e  ",
      "   i     u u e  ",
      "   i     uuu e  ",
      "   i         e  ",
      "   i         e  ",
      "   el   l   le  ",
      "   eePQRePQRee  ",
      "                ",
      "                "
    ],
    [
      "  SeT  FFF UUe  ",
      "  SeT  FFF UUe  ",
      "  SeT      UUe  ",
      "   e       UUe  ",
      "   el       le  ",
      "   e         e  ",
      "  SeT        e  ",
      "  SeT    VVV e  ",
      "  SeT  W V V e  ",
      "  SeT    VVV e  ",
      "  SeT        e  ",
      "  SeT   X   Xe  ",
      "   elXXXlXXXle  ",
      "   eeeeeeeeeee  ",
      "                ",
      "                "
    ],
    [
      "   e    Y  Z e  ",
      "   e       Z e  ",
      "   e       Z e  ",
      "   e       01e  ",
      "   el   W   le  ",
      "   e         e  ",
      "   e         e  ",
      "   eX   XVVVXe  ",
      "   eXXXlXV VXe  ",
      "   eX   XVVVXe  ",
      "   e2   2   2e  ",
      "   e333333333e  ",
      "   e333333333e  ",
      "   44444444444  ",
      "                ",
      "                "
    ]
  ]
}