{
  "name": "multi_communitycenter_0_ground",
  "refpalette": "deceasedcraft:multi_communitycenter_0/multi_communitycenter_0_ground_palette",
  "xsize": 16,
  "zsize": 16,
  "slices": [
    [
      "aaaaaaaaaaaaaaaa",
      "aaaaaaaaaaaaaaaa",
      "aabccccccccccccc",
      "aabccccccccccccc",
      "aabccccccccccccc",
      "aabddddddddddddd",
      "aabddddddddddddd",
      "aabddddddddddddd",
      "aabddddddddddddd",
      "aabddddddddddddd",
      "aabddddddddddddd",
      "aabddddddddddddd",
      "aabeeeeeeeeeeeee",
      "aafeghhgighhgigh",
      "aafjkkkkkkkkkkkk",
      "aafjlkkkkkkkkkkk"
    ],
    [
      "                ",
      "                ",
      "  mn            ",
      "  mn            ",
      "  fnooo p    ooo",
      "  fccccccccccccc",
      "  fccccccccccccc",
      "  fccccccccccccc",
      "  fccccccccccccc",
      "  fddddddddddddd",
      "  fddddddddddddd",
      "  fddddddddddddd",
      "  feqqqqqqqqqqqq",
      "  fe!r s t  u w ",
      "  fr            ",
      "  fx            "
    ],
    [
      "                ",
      "                ",
      "                ",
      "                ",
      "   n            ",
      "   n            ",
      "  mn            ",
      "  mnp     ~     ",
      "  fn    ooooooop",
      "  fccccccccccccc",
      "  fycccccccccccc",
      "  fycccccccccccc",
      "  fccccccccccccc",
      "  feeeeAeAAeAeAe",
      "  fBBBBBBBBBBBBB",
      "  CBBBBBBBBBBBBB"
    ],
    [
      "                ",
      "                ",
      "                ",
      "                ",
      "                ",
      "                ",
      "                ",
      "          ~     ",
      "   n            ",
      "   n            ",
      "  mn            ",
      "  mn       p    ",
      "  fn ooooooo    ",
      "  fccccccccccccc",
      "  fccccccccccccc",
      "  fccccccccccccc"
    ],
    [
      "                ",
      "                ",
      "                ",
      "                ",
      "                ",
      "                ",
      "                ",
      "          ~     ",
      "                ",
      "                ",
      "                ",
      "                ",
      "   n            ",
      "   np           ",
      "  mn            ",
      "  mn            "
    ],
    [
      "                ",
      "                ",
      "                ",
      "                ",
      "                ",
      "                ",
      "                ",
      "          ~     ",
      "                ",
      "                ",
      "                ",
      "                ",
      "                ",
      "                ",
      "                ",
      "                "
    ]
  ]
}