{
  "name": "bridge_1",
  "refpalette": "deceasedcraft:bridge_1_palette",
  "xsize": 16,
  "zsize": 16,
  "slices": [
    [
      "                ",
      "aaaaaaaaaaaaaaaa",
      "bbbbbbbbbbbbbbbb",
      "bbbbbbbbbbbbbbbb",
      "cccdccccccccdccc",
      "aaeeeeeeeeeeeeaa",
      "ffffffffffffffff",
      "ffffffffffffffff",
      "ffffffffffffffff",
      "ffffffffffffffff",
      "aaeeeeeeeeeeeeaa",
      "cccdccccccccdccc",
      "bbbbbbbbbbbbbbbb",
      "bbbbbbbbbbbbbbbb",
      "aaaaaaaaaaaaaaaa",
      "                "
    ],
    [
      "                ",
      "eaggggggggggggae",
      "                ",
      "                ",
      "  hi        j   ",
      "kallllllllllllak",
      "                ",
      "                ",
      "                ",
      "                ",
      "kallllllllllllak",
      "   i        i   ",
      "                ",
      "                ",
      "eaggggggggggggae",
      "                "
    ],
    [
      "                ",
      " m            m ",
      "                ",
      "                ",
      "   n        j   ",
      "                ",
      "                ",
      "                ",
      "                ",
      "                ",
      "                ",
      "   n        n   ",
      "                ",
      "                ",
      " m            m ",
      "                "
    ],
    [
      "                ",
      "                ",
      "                ",
      "            o   ",
      "   p        j   ",
      "                ",
      "                ",
      "                ",
      "                ",
      "                ",
      "                ",
      "   p        p   ",
      "            q   ",
      "                ",
      "                ",
      "                "
    ],
    [
      "                ",
      "                ",
      "                ",
      "            r   ",
      "   s        s   ",
      "                ",
      "                ",
      "                ",
      "                ",
      "                ",
      "                ",
      "   r        r   ",
      "   s            ",
      "                ",
      "                ",
      "                "
    ]
  ],
  "meta": [
    {
      "key": "support",
      "char": "v"
    }
  ]
}