{
  "name": "bridge_deadzone_1",
  "refpalette": "deceasedcraft:bridge_deadzone_1_palette",
  "xsize": 16,
  "zsize": 16,
  "slices": [
    [
      "                ",
      "aabaabbabbaaabbb",
      "cdedcdceeecccddc",
      "ceeccdceccdedeec",
      "faafbaabfffbfaaf",
      "                ",
      "                ",
      "                ",
      "                ",
      "                ",
      "                ",
      "abafbffbaafbfaba",
      "eeeddcccceedeecc",
      "eeedddcddeedeecc",
      "abbffffaabbabbab",
      "                "
    ],
    [
      "                ",
      " gg gb ggbggggbg",
      "                ",
      "                ",
      " zhhhzhgzizhghzz",
      "zh      jh      ",
      "  z zz          ",
      "       zz  zz   ",
      "          z     ",
      "   j z z z    z ",
      "z  z            ",
      "hhhhihhgzghhgzgh",
      "                ",
      "                ",
      " bgggbgggbggggb ",
      "                "
    ],
    [
      "                ",
      "                ",
      "                ",
      "                ",
      "         i      ",
      "                ",
      "                ",
      "                ",
      "                ",
      "                ",
      "                ",
      "    i           ",
      "                ",
      "                ",
      "                ",
      "                "
    ],
    [
      "                ",
      "                ",
      "                ",
      "                ",
      "         i      ",
      "                ",
      "                ",
      "                ",
      "                ",
      "                ",
      "                ",
      "                ",
      "                ",
      "                ",
      "                ",
      "                "
    ]
  ],
  "meta": [
    {
      "key": "support",
      "char": "v"
    }
  ]
}