{
  "name": "highway_open_crossroad",
  "refpalette": "deceasedcraft:highway_open_crossroad_palette",
  "xsize": 16,
  "zsize": 16,
  "slices": [
    [
      "abbbbbbbbbbbbbbb",
      "vvvvvvvvvvvvvvvv",
      "vvvvvvvvvvvvvvvv",
      "vvvvvvvvvvvvvvvv",
      "vvvvvvvvvvvvvvvv",
      "vvvvvvvvvvvvvvvv",
      "vvvvvvvvvvvvvvvv",
      "vvvvvvvvvvvvvvvv",
      "vvvvvvvvvvvvvvvv",
      "vvvvvvvvvvvvvvvv",
      "vvvvvvvvvvvvvvvv",
      "vvvvvvvvvvvvvvvv",
      "vvvvvvvvvvvvvvvv",
      "vvvvvvvvvvvvvvvv",
      "vvvvvvvvvvvvvvvv",
      "accccccccccccccc"
    ],
    [
      "vvvvvvddddvvvvvv",
      "eeeeeeffffeeeeee",
      "HHHHHHHHHHHHHHHH",
      "HHHHHHHHHHHHHHHH",
      "HHHHHHHHHHHHHHHH",
      "HHHHHHHHHHHHHHHH",
      "HHHHHHHHHHHHHHHH",
      "eee=eHHHHHHeeeee",
      "eee=eHHHHHHeeeee",
      "HHHHHHHHHHHHHHHH",
      "HHHHHHHHHHHHHHHH",
      "HHHHHHHHHHHHHHHH",
      "HHHHHHHHHHHHHHHH",
      "HHHHHHHHHHHHHHHH",
      "eeeeeeggggeeeeee",
      "vvvvvvddddvvvvvv"
    ],
    [
      "~~~~~~~~~~~~~~~~",
      "hhhhhh~~~~ihhhhh",
      "jjjjjkkkkkjjjjjj",
      "~~~~~~~~~~~~~~~~",
      "~lm~~lm~~lm~~lm~",
      "~~~~~~~~~~~~~~~~",
      "nnnnnoppppqnnnnn",
      "hhhh~~~~~~i~hhhh",
      "hhhh~i~~~~~~hhhh",
      "jjjjjrkkkkkjjjjj",
      "~~~~~~~~~~~~~~~~",
      "~lm~~lm~~lm~~lm~",
      "~~~~~~~~~~~~~~~~",
      "nnnnnnppppnnnnnn",
      "hhhhhi~~~~hhhhhh",
      "~~~~~~~~~~~~~~~~"
    ],
    [
      "~~~~~~~~~~~~~~~~",
      "~~~~~~~~~~i~~~~~",
      "~~~~~~~~~~~~~~~~",
      "~~~~~~~~~~~~~~~~",
      "~~~~~~~~~~~~~~~~",
      "~~~~~~~~~~~~~~~~",
      "~~~~~~~~~~~~~~~~",
      "~~~~~~~~~~i~~~~~",
      "~~~~~i~~~~~~~~~~",
      "~~~~~~~ ~~~~~~~~",
      "~~~~~~~~~~~~~~~~",
      "~~~~~~~~~~~~~~~~",
      "~~~~~~~~~~~~~~~~",
      "~~~~~~~~~~~~~~~~",
      "~~~~~i~~~~~~~~~~",
      "~~~~~~~~~~~~~~~~"
    ],
    [
      "~~~~~~~~~~s~~~~~",
      "~~~~~~~~~~i~~~~~",
      "~~~~~~~~~~~~~~~~",
      "~~~~~~~~~~~~~~~~",
      "~~~~~~~~~~~~~~~~",
      "~~~~~~~~~~~~~~~~",
      "~~~~~~~~~~~~~~~~",
      "~~~~~~~~~~it~~~~",
      "~~~~ti~~~~~~~~~~",
      "~~~~~~~~~~~~~~~~",
      "~~~~~~~~~~~~~~~~",
      "~~~~~~~~~~~~~~~~",
      "~~~~~~~~~~~~~~~~",
      "~~~~~~~~~~~~~~~~",
      "~~~~~i~~~~~~~~~~",
      "~~~~~t~~~~~~~~~~"
    ],
    [
      "~~~~~~~~~~u~~~~~",
      "~~~~~~~~~~i~~~~~",
      "~~~~~~~~~~~~~~~~",
      "~~~~~~~~~~~~~~~~",
      "~~~~~~~~~~~~~~~~",
      "~~~~~~~~~~~~~~~~",
      "~~~~~~~~~~~~~~~~",
      "~~~~~~~~~~iu~~~~",
      "~~~~ui~~~~~~~~~~",
      "~~~~~~~~~~~~~~~~",
      "~~~~~~~~~~~~~~~~",
      "~~~~~~~~~~~~~~~~",
      "~~~~~~~~~~~~~~~~",
      "~~~~~~~~~~~~~~~~",
      "~~~~~i~~~~~~~~~~",
      "~~~~~u~~~~~~~~~~"
    ],
    [
      "~~~~~~~~~~w~~~~~",
      "~~~~~~~~~~i~~~~~",
      "~~~~~~~~~~~~~~~~",
      "~~~~~~~~~~~~~~~~",
      "~~~~~~~~~~~~~~~~",
      "~~~~~~~~~~~~~~~~",
      "~~~~~~~~~~~~~~~~",
      "~~~~~~~~~~ix~~~~",
      "~~~~xi~~~~~~~~~~",
      "~~~~~~~~~~~~~~~~",
      "~~~~~~~~~~~~~~~~",
      "~~~~~~~~~~~~~~~~",
      "~~~~~~~~~~~~~~~~",
      "~~~~~~~~~~~~~~~~",
      "~~~~~i~~~~~~~~~~",
      "~~~~~x~~~~~~~~~~"
    ]
  ]
}