{
  "name": "highway_bridge_crash",
  "refpalette": "deceasedcraft:highway_bridge_crash_palette",
  "xsize": 16,
  "zsize": 16,
  "slices": [
    [
      "abbbbbbbbbbbbbbb",
      "vvvvvvvvvvvvvvvv",
      "vvvvvvvvvvvvvvvv",
      "vvvvvvvvvvvvvvvv",
      "vvvvvvvvvvvvvvvv",
      "vvvvvvvvvvvvvvvv",
      "vvvvvvvvvvvvvvvv",
      "vvvvvvvvvvvvvvvv",
      "vvvvvvvvvvvvvvvv",
      "vvvvvvvvvvvvvvvv",
      "vvvvvvvvvvvvvvvv",
      "vvvvvvvvvvvvvvvv",
      "vvvvvvvvvvvvvvvv",
      "vvvvvvvvvvvvvvvv",
      "vvvvvvvvvvvvvvvv",
      "acccccccccccccca"
    ],
    [
      "vvvvvvvvvvvvvvvv",
      "================",
      "HHHHHHHHHHHHHHHH",
      "HHHHHHHHHHHHHHHH",
      "HHHHHHHHHHHHHHHH",
      "HHHHHHHHHHHHHHHH",
      "HHHHHHHHHHHHHHHH",
      "==========de====",
      "================",
      "HHHHHHHHHHHHHHHH",
      "HHHHHHHHHHHHHHHH",
      "HHHHHHHHHHHHHHHH",
      "HHHHHHHHHHHHHHHH",
      "HHHHHHHHHHHHHHHH",
      "================",
      "vvvvvvvvvvvvvvvv"
    ],
    [
      "fffgfffffffgffff",
      "hhhhhhhhhhhhhhhh",
      "iiiiiiiiiiiiiiij",
      "~~~~~~~~~~~~~~~~",
      "~kl~~kl~~kl~~kl~",
      "~~~~~~~m~~~~~no~",
      "ppppppqjrstsuppp",
      "w~w~~~sxyABCwwww",
      "wwww~~DjEsjwwwww",
      "iiwwiwwiiiiiFiii",
      "~~~~~~~~~~~~~~~I",
      "~kl~~kl~~kl~~kl~",
      "~~~~~~~~~~~~~~~~",
      "pppppppppppppppp",
      "hhhhhhhhhhhhhhhh",
      "fffgfffffffgffff"
    ],
    [
      "wwwJwwwwwwwwwwww",
      "~~~~~~~~~~~~~~~~",
      "~~~~~~~~~~~~~~~F",
      "~~~~~~~~~~~~~~~~",
      "~~~~~~~~~~~~~~~~",
      "~~~~~~~~~~~~~~~~",
      "~~~~~~KDLLo~~~~~",
      "~~~~~~MN~~O~P~~~",
      "~~~~~~KDLQo~~o~~",
      "~~~~~~~~~~~~~~~~",
      "~~~~~~~~~~~~~~~~",
      "~~~~~~~~~~~~~~~~",
      "~~~~~~~~~~~~~~~~",
      "~~~~~~~~~~~~~~~~",
      "~~~~~~~~~~~~~~~~",
      "wwwJwwwwwwwwwwww"
    ],
    [
      "~~~J~~~~~~~~~~~~",
      "~~~~~~~~~~~~~~~~",
      "~~~~~~~~~~~~~~~~",
      "~~~~~~~~~~~~~~~~",
      "~~~~~~~~~~~~~~~~",
      "~~~~~~~~~~~~~~~~",
      "~~~~~~~~o~~~~~~~",
      "~~~~~~~~oo~~~~~~",
      "~~~~~~~~oo~~~~~~",
      "~~~~~~~~~~~~~~~~",
      "~~~~~~~~~~~~~~~~",
      "~~~~~~~~~~~~~~~~",
      "~ ~~~~~~~~~~~~~~",
      "~~~~~~~~~~~~~~~~",
      "~~~~~~~~~~~~~~~~",
      "~~~J~~~~~~~~~~~~"
    ],
    [
      "   J            ",
      "                ",
      "                ",
      "                ",
      "                ",
      "                ",
      "                ",
      "                ",
      "                ",
      "                ",
      "                ",
      "                ",
      "                ",
      "                ",
      "                ",
      "   J            "
    ],
    [
      "   R            ",
      "                ",
      "                ",
      "                ",
      "                ",
      "                ",
      "                ",
      "                ",
      "                ",
      "                ",
      "                ",
      "                ",
      "                ",
      "                ",
      "                ",
      "   R            "
    ],
    [
      "   S            ",
      "                ",
      "                ",
      "                ",
      "                ",
      "                ",
      "                ",
      "                ",
      "                ",
      "                ",
      "                ",
      "                ",
      "                ",
      "                ",
      "                ",
      "   S            "
    ],
    [
      "   T            ",
      "   T            ",
      "                ",
      "   U            ",
      "                ",
      "                ",
      "                ",
      "                ",
      "                ",
      "                ",
      "                ",
      "                ",
      "   U            ",
      "                ",
      "   T            ",
      "   T            "
    ],
    [
      "                ",
      "   V            ",
      "   V            ",
      "   V            ",
      "                ",
      "                ",
      "                ",
      "                ",
      "                ",
      "                ",
      "                ",
      "                ",
      "   V            ",
      "   V            ",
      "   V            ",
      "                "
    ]
  ],
  "meta": [
    {
      "key": "support",
      "char": "v"
    }
  ]
}