{
  "name": "highway_tunnel",
  "refpalette": "deceasedcraft:highway_tunnel_palette",
  "xsize": 16,
  "zsize": 16,
  "slices": [
    [
      "aaaaaaaaaaaaaaaa",
      "vvvvvvvvvvvvvvvv",
      "vvvvvvvvvvvvvvvv",
      "vvvvvvvvvvvvvvvv",
      "vvvvvvvvvvvvvvvv",
      "vvvvvvvvvvvvvvvv",
      "vvvvvvvvvvvvvvvv",
      "vvvvvvvvvvvvvvvv",
      "vvvvvvvvvvvvvvvv",
      "vvvvvvvvvvvvvvvv",
      "vvvvvvvvvvvvvvvv",
      "vvvvvvvvvvvvvvvv",
      "vvvvvvvvvvvvvvvv",
      "vvvvvvvvvvvvvvvv",
      "vvvvvvvvvvvvvvvv",
      "bbbbbbbbbbbbbbbb"
    ],
    [
      "vvvvvvvvvvvvvvvv",
      "================",
      "HHHHHHHHHHHHHHHH",
      "HHHHHHHHHHHHHHHH",
      "HHHHHHHHHHHHHHHH",
      "HHHHHHHHHHHHHHHH",
      "HHHHHHHHHHHHHHHH",
      "HHHHHHHHHHHHHHHH",
      "HHHHHHHHHHHHHHHH",
      "HHHHHHHHHHHHHHHH",
      "HHHHHHHHHHHHHHHH",
      "HHHHHHHHHHHHHHHH",
      "HHHHHHHHHHHHHHHH",
      "HHHHHHHHHHHHHHHH",
      "================",
      "vvvvvvvvvvvvvvvv"
    ],
    [
      "vvvcvvvvvvvcvvvv",
      "ddd~ddddddd~dddd",
      "eeeeeeeeeeeeeeee",
      "~~~~~~~~~~~~~~~~",
      "~fg~~fg~~fg~~fg~",
      "~~~~~~~~~~~~~~~~",
      "hhhhhhhhhhhhhhhh",
      "iiiiiiiiiiiiiiii",
      "iiiiiiiiiiiiiiii",
      "eeeeeeeeeeeeeeee",
      "~~~~~~~~~~~~~~~~",
      "~fg~~fg~~fg~~fg~",
      "~~~~~~~~~~~~~~~~",
      "hhhhhhhhhhhhhhhh",
      "ddd~ddddddd~dddd",
      "vvvjvvvvvvvjvvvv"
    ],
    [
      "vvvcvvvvvvvcvvvv",
      "~~~~~~~~~~~~~~~~",
      "~~~~~~~~~~~~~~~~",
      "~~~~~~~~~~~~~~~~",
      "~~~~~~~~~~~~~~~~",
      "~~~~~~~~~~~~~~~~",
      "~~~~~~~~~~~~~~~~",
      "~~~~~~~~~~~~~~~~",
      "~~~~~~~~~~~~~~~~",
      "~~~~~~~~~~~~~~~~",
      "~~~~~~~~~~~~~~~~",
      "~~~~~~~~~~~~~~~~",
      "~~~~~~~~~~~~~~~~",
      "~~~~~~~~~~~~~~~~",
      "~~~~~~~~~~~~~~~~",
      "vvvjvvvvvvvjvvvv"
    ],
    [
      "vvvvvvvvvvvvvvvv",
      "kkkkkkkkkkkkkkkk",
      "~~~~~~~~~~~~~~~~",
      "~~~~~~~~~~~~~~~~",
      "~~~~~~~~~~~~~~~~",
      "~~~~~~~~~~~~~~~~",
      "~~~~~~~~~~~~~~~~",
      "~~~~~~~~~~~~~~~~",
      "~~~~~~~~~~~~~~~~",
      "~~~~~~~~~~~~~~~~",
      "~~~~~~~~~~~~~~~~",
      "~~~~~~~~~~~~~~~~",
      "~~~~~~~~~~~~~~~~",
      "~~~~~~~~~~~~~~~~",
      "kkkkkkkkkkkkkkkk",
      "vvvvvvvvvvvvvvvv"
    ],
    [
      "                ",
      "vvvvvvvvvvvvvvvv",
      "vvvvvvvvvvvvvvvv",
      "kkkkkkkkkkkkkkkk",
      "kkkkkkklkkkkkkkk",
      "kkkkkkkkkkkkkkkk",
      "kkkkkkkkkkkkkkkk",
      "kkkkkkkkkkkkkkkk",
      "kkkkkkkkkkkkkkkk",
      "kkkkkkkkkkkkkkkk",
      "kkkkkkkkkkkkkkkk",
      "kkkkkkklkkkkkkkk",
      "kkkkkkkkkkkkkkkk",
      "vvvvvvvvvvvvvvvv",
      "vvvvvvvvvvvvvvvv",
      "                "
    ]
  ]
}