{
  "name": "highway_tunnel_bi",
  "refpalette": "deceasedcraft:highway_tunnel_bi_palette",
  "xsize": 16,
  "zsize": 16,
  "slices": [
    [
      "vvvvvvvvvvvvvvvv",
      "vvvvvvvvvvvvvvvv",
      "vvvvvvvvvvvvvvvv",
      "vvvvvvvvvvvvvvvv",
      "vvvvvvvvvvvvvvvv",
      "vvvvvvvvvvvvvvvv",
      "vvvvvvvvvvvvvvvv",
      "vvvvvvvvvvvvvvvv",
      "vvvvvvvvvvvvvvvv",
      "vvvvvvvvvvvvvvvv",
      "vvvvvvvvvvvvvvvv",
      "vvvvvvvvvvvvvvvv",
      "vvvvvvvvvvvvvvvv",
      "vvvvvvvvvvvvvvvv",
      "vvvvvvvvvvvvvvvv",
      "vvvvvvvvvvvvvvvv"
    ],
    [
      "v=aaaaaHHHHHHH=v",
      "==HHHHHHHHHHHH==",
      "HHHHHHHHHHHHHHHa",
      "HHHHHHHHHHHHHHHa",
      "HHHHHHHHHHHHHHHa",
      "HHHHHHHHHHHHHHHa",
      "HHHHHHHHHHHHHHHa",
      "HHHHHHHHHHHHHHHH",
      "HHHHHHHHHHHHHHHH",
      "aHHHHHHHHHHHHHHH",
      "aHHHHHHHHHHHHHHH",
      "aHHHHHHHHHHHHHHH",
      "aHHHHHHHHHHHHHHH",
      "aHHHHHHHHHHHHHHH",
      "==HHHHHHHHHHHH==",
      "v=HHHHHHHaaaaa=v"
    ],
    [
      "vb~~~~~cc~~~~~bv",
      "bb~~~~~cc~~~~~bb",
      "~~~~~~~~~~~~~~~~",
      "~~~~~~~~~~~~~~~~",
      "~~~~~~~~~~~d~~~~",
      "~~~~~~~~~~~~~~~~",
      "~~~~~~~~~~~~~~~~",
      "cc~~~~~~~~~~~~cc",
      "cc~~~~~~~~~~~~cc",
      "~~~~~~~~~~~~~~~~",
      "~~~~~~~~~~~~~~~~",
      "~~~~~~~~~~~~~~~~",
      "~~~~~~~~~~~~~~~~",
      "~~~~~~~~~~~~~~~~",
      "bb~~~~~cc~~~~~bb",
      "vb~ ~~~cc~~~~~bv"
    ],
    [
      "v~~~~~~~~~~~~~~v",
      "~~~~~~~~~~~~~~~~",
      "~~~~~~~~~~~~~~~~",
      "~~~~~~~~~~~~~~~~",
      "~~~~~~~~~~~e~~~~",
      "~~~~~~~~~~~~~~~~",
      "~~~~~~~~~~~~~~~~",
      "~~~~~~~~~~~~~~~~",
      "~~~~~~~~~~~~~~~~",
      "~~~~~~~~~~~~~~~~",
      "~~~~~~~~~~~~~~~~",
      "~~~~~~~~~~~~~~~~",
      "~~~~~~~~~~~~~~~~",
      "~~~~~~~~~~~~~~~~",
      "~~~~~~~~~~~~~~~~",
      "v~~~~~~~~~~~~~~v"
    ],
    [
      "vf~~~~~~~~~~~~fv",
      "ff~~~~~~~~~~~~ff",
      "~~~~~~~~~~~~~~~~",
      "~~~~~~~~~~~~~~~~",
      "~~~~~~~~~~~~~~~~",
      "~~~~~~~~~~~~~~~~",
      "~~~~~~~~~~~~~~~~",
      "~~~~~~~~~~~~~~~~",
      "~~~~~~~~~~~~~~~~",
      "~~~~~~~~~~~~~~~~",
      "~~~~~~~~~~~~~~~~",
      "~~~~~~~~~~~~~~~~",
      "~~~~~~~~~~~~~~~~",
      "~~~~~~~~~~~~~~~~",
      "ff~~~~~~~~~~~~ff",
      "vf~~~~~~~~~~~~fv"
    ],
    [
      "~vvffffffffffvv~",
      "vvvffffffffffvvv",
      "vvvffffffffffvvv",
      "ffffffffffffffff",
      "ffffgffffffgffff",
      "ffffffffffffffff",
      "ffffffffffffffff",
      "ffffffffffffffff",
      "ffffffffffffffff",
      "ffffffffffffffff",
      "ffffffffffffffff",
      "ffffgffffffgffff",
      "ffffffffffffffff",
      "vvvffffffffffvvv",
      "vvvffffffffffvvv",
      "~vvffffffffffvv~"
    ]
  ]
}