{
  "name": "highway_open_bi",
  "refpalette": "deceasedcraft:highway_open_bi_palette",
  "xsize": 16,
  "zsize": 16,
  "slices": [
    [
      "vvvvvvvvvvvvvvvv",
      "vvvvvvvvvvvvvvvv",
      "vvvvvvvvvvvvvvvv",
      "vvvvvvvvvvvvvvvv",
      "vvvvvvvvvvvvvvvv",
      "vvvvvvvvvvvvvvvv",
      "vvvvvvvvvvvvvvvv",
      "vvvvvvvvvvvvvvvv",
      "vvvvvvvvvvvvvvvv",
      "vvvvvvvvvvvvvvvv",
      "vvvvvvvvvvvvvvvv",
      "vvvvvvvvvvvvvvvv",
      "vvvvvvvvvvvvvvvv",
      "vvvvvvvvvvvvvvvv",
      "vvvvvvvvvvvvvvvv",
      "vvvvvvvvvvvvvvv "
    ],
    [
      "v=aaaaa==HHHHH=v",
      "==HHHHH==HHHHH==",
      "HHHHHHHHHHHHHHHa",
      "HHHHHHHHHHHHHHHa",
      "HHHHHHHHHHHHHHHa",
      "HHHHHHHHHHHHHHHa",
      "HHHHHHHHHHHHHHHa",
      "==HHHHH==HHHHH==",
      "==HHHHH==HHHHH==",
      "aHHHHHHHHHHHHHHH",
      "aHHHHHHHHHHHHHHH",
      "aHHHHHHHHHHHHHHH",
      "aHHHHHHHHHHHHHHH",
      "aHHHHHHHHHHHHHHH",
      "==HHHHH==HHHHH==",
      "v=HHHHH==aaaaa=v"
    ],
    [
      "bc            cb",
      "c              c",
      "                ",
      "                ",
      "                ",
      "                ",
      "                ",
      "                ",
      "                ",
      "                ",
      "                ",
      "                ",
      "                ",
      "                ",
      "c              c",
      "dc            cb"
    ],
    [
      "b              b",
      "                ",
      "                ",
      "                ",
      "                ",
      "                ",
      "                ",
      "                ",
      "                ",
      "                ",
      "                ",
      "                ",
      "                ",
      "                ",
      "                ",
      "               b"
    ],
    [
      "e              e",
      "                ",
      "                ",
      "                ",
      "                ",
      "                ",
      "                ",
      "                ",
      "                ",
      "                ",
      "                ",
      "                ",
      "                ",
      "                ",
      "                ",
      "               e"
    ],
    [
      "e               ",
      "                ",
      "                ",
      "                ",
      "                ",
      "                ",
      "                ",
      "                ",
      "                ",
      "                ",
      "                ",
      "                ",
      "                ",
      "                ",
      "                ",
      "               e"
    ]
  ]
}