{
  "name": "highway_bridge_adboard",
  "refpalette": "deceasedcraft:highway_bridge_adboard_palette",
  "xsize": 16,
  "zsize": 16,
  "slices": [
    [
      "abbbbbbbbbbbbbbb",
      "vvvvvvvvvvvvvvvv",
      "vvvvvvvvvvvvvvvv",
      "vvvvvvvvvvvvvvvv",
      "vvvvvvvvvvvvvvvv",
      "vvvvvvvvvvvvvvvv",
      "vvvvvvvvvvvvvvvv",
      "vvvvvvvvvvvvvvvv",
      "vvvvvvvvvvvvvvvv",
      "vvvvvvvvvvvvvvvv",
      "vvvvvvvvvvvvvvvv",
      "vvvvvvvvvvvvvvvv",
      "vvvvvvvvvvvvvvvv",
      "vvvvvvvvvvvvvvvv",
      "vvvvvvvvvvvvvvvv",
      "accccccccccccccc"
    ],
    [
      "vvvvvvvvvvvvvvvv",
      "================",
      "HHHHHHHHHHHHHHHH",
      "HHHHHHHHHHHHHHHH",
      "HHHHHHHHHHHHHHHH",
      "HHHHHHHHHHHHHHHH",
      "HHHHHHHHHHHHHHHH",
      "================",
      "================",
      "HHHHHHHHHHHHHHHH",
      "HHHHHHHHHHHHHHHH",
      "HHHHHHHHHHHHHHHH",
      "HHHHHHHHHHHHHHHH",
      "HHHHHHHHHHHHHHHH",
      "================",
      "vvvvvvvvvvvvvvvv"
    ],
    [
      "dddedddddddedddd",
      "ffffffffffffffff",
      "gggggggggggggggg",
      "~~~~~~~~~~~~~~~~",
      "~hi~~hi~~hi~~hi~",
      "~~~~~~~~~~~~~~~~",
      "jjjjjjjjjjjjjjjj",
      "kkkkkkkkkkkkkkkk",
      "kkkkkkkkkkkkkkkk",
      "gggggggggggggggg",
      "~~~~~~~~~~~~~~~~",
      "~hi~~hi~~hi~~hi~",
      "~~~~~~~~~~~~~~~~",
      "jjjjjjjjjjjjjjjj",
      "ffffffffffffffff",
      "dddedddddddedddd"
    ],
    [
      "kkklkkkkkkkkkkkk",
      "~~~~~~~~~~~~~~~~",
      "~~~~~~~~~~~~~~~~",
      "~~~~~~~~~~~~~~~~",
      "~~~~~~~~~~~~~~~~",
      "~~~~~~~~~~~~~~~~",
      "~~~~~~~~~~~~~~~~",
      "~~~~~~~~~~~~~~~~",
      "~~~~~~~~~~~~~~~~",
      "~~~~~~~~~~~~~~~~",
      "~~~~~~~~~~~~~~~~",
      "~~~~~~~~~~~~~~~~",
      "~~~~~~~~~~~~~~~~",
      "~~~~~~~~~~~~~~~~",
      "~~~~~~~~~~~~~~~~",
      "kkklkkkkkkkkkkkk"
    ],
    [
      "~~~l~~~~~~~~~~~~",
      "~~~~~~~~~~~~~~~~",
      "~~~~~~~~~~~~~~~~",
      "~~~~~~~~~~~~~~~~",
      "~~~~~~~~~~~~~~~~",
      "~~~~~~~~~~~~~~~~",
      "~~~~~~~~~~~~~~~~",
      "~~~~~~~~~~~~~~~~",
      "~~~~~~~~~~~~~~~~",
      "~~~~~~~~~~~~~~~~",
      "~~~~~~~~~~~~~~~~",
      "~~~~~~~~~~~~~~~~",
      "~~~~~~~~~~~~~~~~",
      "~~~~~~~~~~~~~~~~",
      "~~~~~~~~~~~~~~~~",
      "~~~l~~~~~~~~~~~~"
    ],
    [
      "~~~l~~~~~~~~~~~~",
      "~~~~~~~~~~~~~~~~",
      "~~~~~~~~~~~~~~~~",
      "~~~~~~~~~~~~~~~~",
      "~~~~~~~~~~~~~~~~",
      "~~~~~~~~~~~~~~~~",
      "~~~~~~~~~~~~~~~~",
      "~~~~~~~~~~~~~~~~",
      "~~~~~~~~~~~~~~~~",
      "~~~~~~~~~~~~~~~~",
      "~~~~~~~~~~~~~~~~",
      "~~~~~~~~~~~~~~~~",
      "~~~~~~~~~~~~~~~~",
      "~~~~~~~~~~~~~~~~",
      "~~~~~~~~~~~~~~~~",
      "~~~l~~~~~~~~~~~~"
    ],
    [
      "~~~m~~~~~~~~~~~~",
      "~~~~~~~~~~~~~~~~",
      "~~~~~~~~~~~~~~~~",
      "~~~~~~~~~~~~~~~~",
      "~~~~~~~~~~~~~~~~",
      "~~~~~~~~~~~~~~~~",
      "~~~~~~~~~~~~~~~~",
      "~~~~~~~~~~~~~~~~",
      "~~~~~~~~~~~~~~~~",
      "~~~~~~~~~~~~~~~~",
      "~~~~~~~~~~~~~~~~",
      "~~~~~~~~~~~~~~~~",
      "~~~~~~~~~~~~~~~~",
      "~~~~~~~~~~~~~~~~",
      "~~~~~~~~~~~~~~~~",
      "~~~m~~~~~~~~~~~~"
    ],
    [
      "~~~n~~~~~~~~~~~~",
      "~~~~~~~~~~~~~~~~",
      "~~~~~~~~~~~~~~~~",
      "~~~~~~~~~~~~~~~~",
      "~~~~~~~~~~~~~~~~",
      "~~~~~~~~~~~~~~~~",
      "~~~~~~~~~~~~~~~~",
      "~~~~~~~~~~~~~~~~",
      "~~~~~~~~~~~~~~~~",
      "~~~~~~~~~~~~~~~~",
      "~~~~~~~~~~~~~~~~",
      "~~~~~~~~~~~~~~~~",
      "~~~~~~~~~~~~~~~~",
      "~~~~~~~~~~~~~~~~",
      "~~~~~~~~~~~~~~~~",
      "~~~n~~~~~~~~~~~~"
    ],
    [
      "~~~k~~~~~~~~~~~~",
      "~~~k~~~~~~~~~~~~",
      "~~~~~~~~~~~~~~~~",
      "~~~op~~~~~~~~~~~",
      "~~~op~~~~~~~~~~~",
      "~~~op~~~~~~~~~~~",
      "~~~~~~~~~~~~~~~~",
      "~~~~~~~~~~~~~~~~",
      "~~~~~~~~~~~~~~~~",
      "~~~~~~~~~~~~~~~~",
      "~~qo~~~~~~~~~~~~",
      "~~qo~~~~~~~~~~~~",
      "~~qo~~~~~~~~~~~~",
      "~~~~~~~~~~~~~~~~",
      "~~~k~~~~~~~~~~~~",
      "~~~k~~~~~~~~~~~~"
    ],
    [
      "                ",
      "   r            ",
      "   r            ",
      "   rp           ",
      "   rp           ",
      "   rp           ",
      "   r            ",
      "   r            ",
      "   r            ",
      "   r            ",
      "  qr            ",
      "  qr            ",
      "  qr            ",
      "   r            ",
      "   r            ",
      "                "
    ]
  ],
  "meta": [
    {
      "key": "support",
      "char": "v"
    }
  ]
}