{
  "name": "highway_bridge_bi",
  "refpalette": "deceasedcraft:highway_bridge_bi_palette",
  "xsize": 16,
  "zsize": 16,
  "slices": [
    [
      "vvvvvvvvvvvvvvvv",
      "vvvvvvvvvvvvvvvv",
      "vvvvvvvvvvvvvvvv",
      "vvvvvvvvvvvvvvvv",
      "vvvvvvvvvvvvvvvv",
      "vvvvvvvvvvvvvvvv",
      "vvvvvvvvvvvvvvvv",
      "vvvvvvvvvvvvvvvv",
      "vvvvvvvvvvvvvvvv",
      "vvvvvvvvvvvvvvvv",
      "vvvvvvvvvvvvvvvv",
      "vvvvvvvvvvvvvvvv",
      "vvvvvvvvvvvvvvvv",
      "vvvvvvvvvvvvvvvv",
      "vvvvvvvvvvvvvvvv",
      "vvvvvvvvvvvvvvv "
    ],
    [
      "v=aaaaa==HHHHH=v",
      "==HHHHH==HHHHH==",
      "HHHHHHHHHHHHHHHa",
      "HHHHHHHHHHHHHHHa",
      "HHHHHHHHHHHHHHHa",
      "HHHHHHHHHHHHHHHa",
      "HHHHHHHHHHHHHHHa",
      "==HHHHHHHHHHHH==",
      "==HHHHHHHHHHHH==",
      "aHHHHHHHHHHHHHHH",
      "aHHHHHHHHHHHHHHH",
      "aHHHHHHHHHHHHHHH",
      "aHHHHHHHHHHHHHHH",
      "aHHHHHHHHHHHHHHH",
      "==HHHHH==HHHHH==",
      "v=HHHHH==aaaaa=v"
    ],
    [
      "bc            cb",
      "cc            cc",
      "                ",
      "                ",
      "                ",
      "                ",
      "                ",
      "                ",
      "                ",
      "                ",
      "                ",
      "                ",
      "                ",
      "                ",
      "cc            cc",
      "bcd           cb"
    ],
    [
      "b              b",
      "                ",
      "                ",
      "                ",
      "                ",
      "                ",
      "                ",
      "                ",
      "                ",
      "                ",
      "                ",
      "                ",
      "                ",
      "                ",
      "                ",
      "b              b"
    ],
    [
      "d              d",
      "                ",
      "                ",
      "                ",
      "                ",
      "                ",
      "                ",
      "                ",
      "                ",
      "                ",
      "                ",
      "                ",
      "                ",
      "                ",
      "                ",
      "d              d"
    ],
    [
      "d               ",
      "                ",
      "                ",
      "                ",
      "                ",
      "                ",
      "                ",
      "                ",
      "                ",
      "                ",
      "                ",
      "                ",
      "                ",
      "                ",
      "                ",
      "               d"
    ]
  ],
  "meta": [
    {
      "key": "support",
      "char": "v"
    }
  ]
}