{
  "name": "rails_horizontal_end",
  "refpalette": "deceasedcraft:rails_horizontal_end_palette",
  "xsize": 16,
  "zsize": 16,
  "slices": [
    [
      "                ",
      "                ",
      "aaaaaaaaaaaaaaaa",
      "HaaaHaaHHaaaHaaa",
      "HHHHHHHHHHHHHHHH",
      "HHHHHHHHHHHHHHHH",
      "HHHHHHHHHHHHHHHH",
      "HHHHHHHHHHHHHHHH",
      "HHHHHHHHH!HHHHHH",
      "HHHHHHHHHHHHHHHH",
      "HHHHHHHHHHHHHHHH",
      "HHHHHHHHHHHHHHHH",
      "HaaaHaaaHaaaHaaa",
      "aaaaaaaaaaaaaaaa",
      "                ",
      "                "
    ],
    [
      "                ",
      "                ",
      "aaaaaaaaaaaaaaaa",
      "baaabaa  aaabaaa",
      "cc ccdc  ceccccc",
      "       fghh hi h",
      "jjjjj    k l kkk",
      "      mg mhh h  ",
      "       m h ehh  ",
      "jjjjjjj gkno   k",
      "      m  hhphi h",
      "ccccicc  ciccccc",
      "baaabaa  aaabaaa",
      "aaaaaaaaaaaaaaaa",
      "                ",
      "                "
    ],
    [
      "                ",
      "                ",
      "aaaaaaaaaaaaaaaa",
      "baaabaa  aaabaaa",
      "      i    i    ",
      "                ",
      "       q        ",
      "                ",
      "        q       ",
      "       mq       ",
      "                ",
      "   i    q       ",
      "baaabaa  aaabaaa",
      "aaaaaaaaaaaaaaaa",
      "                ",
      "                "
    ],
    [
      "                ",
      "                ",
      "aaaaaaaaaaaaaaaa",
      "baaabaa  aaabaaa",
      "         i      ",
      "                ",
      "       p        ",
      "                ",
      "        g       ",
      "                ",
      "        r       ",
      "         i      ",
      "baaabaa  aaabaaa",
      "aaaaaaaaaaaaaaaa",
      "                ",
      "                "
    ],
    [
      "                ",
      "                ",
      "aaaaaaaaaaaaaaaa",
      " aaa aa  aaa aaa",
      "si  si   i isi  ",
      "       gq       ",
      "     i   i      ",
      "                ",
      "                ",
      "       rg       ",
      "   i   g i      ",
      "s i s i  i is   ",
      " aaa aa  aaa aaa",
      "aaaaaaaaaaaaaaaa",
      "                ",
      "                "
    ],
    [
      "                ",
      "                ",
      "                ",
      "tttttttttttttttt",
      "tttttttttttttttt",
      "fffuffuqguffffff",
      "wwwwwwwqqwwwwwww",
      "wwwwwwwHHwwwwwww",
      "wwwwwwwHHwwwwwww",
      "wwwwwwwggwwwwwww",
      "fffffffqqfffffff",
      "tttttttttttttttt",
      "tttttttttttttttt",
      "                ",
      "                ",
      "                "
    ]
  ]
}