{
  "name": "rails_down1",
  "refpalette": "deceasedcraft:rails_down1_palette",
  "xsize": 16,
  "zsize": 16,
  "slices": [
    [
      "                ",
      "                ",
      "a               ",
      "a               ",
      "                ",
      "                ",
      "                ",
      "                ",
      "                ",
      "                ",
      "                ",
      "                ",
      "                ",
      "a               ",
      "a               ",
      "                "
    ],
    [
      "                ",
      "                ",
      "aa              ",
      "ba              ",
      "cc              ",
      "~~              ",
      "~~              ",
      "~~              ",
      "~~              ",
      "~~              ",
      "~~              ",
      "~~              ",
      "cc~             ",
      " a              ",
      "aa              ",
      "                "
    ],
    [
      "                ",
      "                ",
      "aaa             ",
      "daa             ",
      "~~cc            ",
      "~~~~            ",
      "~~~~            ",
      "~~~~            ",
      "~~~~            ",
      "~~~~            ",
      "~~~~            ",
      "~~~~            ",
      "~~cc            ",
      "daa             ",
      "aaa             ",
      "                "
    ],
    [
      "                ",
      "                ",
      "aaaa            ",
      "daaa            ",
      "~~~~cc          ",
      "~~~~~~          ",
      "~~~~~~          ",
      "~~~~~~          ",
      "~~~~~~          ",
      "~~~~~~          ",
      "~~~~~~          ",
      "~~~~~~          ",
      "~~~~cc          ",
      "daaa            ",
      "aaaa            ",
      "                "
    ],
    [
      "                ",
      "                ",
      "aaaaaaa         ",
      "daaaaaa         ",
      "~~~~~~cc        ",
      "~~~~~~~~        ",
      "~~~~~~~~        ",
      "~~~~~~~~        ",
      "~~~~~~~~        ",
      "~~~~~~~~        ",
      "~~~~~~~~        ",
      "~~~~~~~~        ",
      "~~~~~~cc        ",
      "daaaaa          ",
      "aaaaaa          ",
      "                "
    ],
    [
      "                ",
      "                ",
      "aaaaaaaa        ",
      " aaaaaaa        ",
      "~~~~~~~~cc      ",
      "~~~~~~~~~~      ",
      "~~~~~~~~~~      ",
      "~~~~~~~~~~      ",
      "~~~~~~~~~~      ",
      "~~~~~~~~~~      ",
      "~~~~~~~~~~      ",
      "~~~~~~~~~~      ",
      "~~~~~~~~cc      ",
      " aaaaaaa        ",
      "aaaaaaaa        ",
      "                "
    ],
    [
      "               a",
      "               a",
      "       aaaaaaaaa",
      "eeeeeeeaaaaaaaaa",
      "~~~~~~~~~~cc    ",
      "~~~~~~~~~~~~    ",
      "~~~~~~~~~~~~    ",
      "~~~~~~~~~~~~    ",
      "~~~~~~~~~~~~    ",
      "~~~~~~~~~~~~    ",
      "~~~~~~~~~~~~    ",
      "~~~~~~~~~~~~    ",
      "~~~~~~~~~~cc    ",
      "eeeeeeeaaaaaaaaa",
      "~~~~~~~aaaaaaaaa",
      "               a"
    ],
    [
      "               a",
      "               a",
      "               a",
      "effffffeaaaaaaaa",
      "e~~~~~~~~~~~gggg",
      "e~~~~~~~~~~~~~~~",
      "e~~~~~~~~~~~~~~~",
      "e~~~~~~~~~~~~~~~",
      "e~~~~~~~~~~~~~~h",
      "e~~~~~~~~~~~~~~~",
      "e~~~~~~~~~~~~~~~",
      "e~~~~~~~~~~~~~~~",
      "e~~~~~~~~~~~gggg",
      "effffffeaaaaaaaa",
      "~~~~~~~~~~~~~~~a",
      "               a"
    ],
    [
      "               i",
      "               i",
      "               i",
      "efffffffeiiiiiii",
      "f~~~~~~~~~~~~~~~",
      "f~~~~~~~~~~~~~~~",
      "f~~~~~~~~~~~~~~~",
      "f~~~~~~~~~~~~~~~",
      "f~~~~~~~~~~~~~~~",
      "f~~~~~~~~~~~~~~~",
      "f~~~~~~~~~~~~~~~",
      "f~~~~~~~~~~~~~~~",
      "f~~~~~~~~~~~~~~~",
      "efffffffeiiiiiii",
      "~~~~~~~~~~~~~~~i",
      "               i"
    ],
    [
      "                ",
      "                ",
      "                ",
      "e~~~~~~~e~~~~~~~",
      "f~~~~~~~~~~~~~~~",
      "f~~~~~~~~~~~~~~~",
      "f~~~~~~~~~~~~~~~",
      "f~~~~~~~~~~~~~~~",
      "f~~~~~~~~~~~~~~~",
      "f~~~~~~~~~~~~~~~",
      "f~~~~~~~~~~~~~~~",
      "f~~~~~~~~~~~~~~~",
      "f~~~~~~~~~~~~~~~",
      "e~~~~~~~e~~~~~~~",
      "~~~~~~~~~~~~~~~~",
      "                "
    ],
    [
      "                ",
      "                ",
      "                ",
      "jjjkkk~~~e~~~~~~",
      "jlllkl~~~~~~~~~~",
      "jlllkl~~~~~~~~~~",
      "~jjk~~~~~~~~~~~~",
      "jmmmmm~~~~~~~~~~",
      "jmmmmm~~~~~~~~~~",
      "jmmmmm~~~~~~~~~~",
      "~jjk~~~~~~~~~~~~",
      "jlllkl~~~~~~~~~~",
      "jlllkl~~~~~~~~~~",
      "jjjkkk~~~e~~~~~~",
      "~~~~~~~~~~~~~~~~",
      "                "
    ],
    [
      "                ",
      "                ",
      "                ",
      "~~~~~~jjne~~~~~~",
      "~~~~~~lljk~~~~~~",
      "~~~~~~lljk~~~~~~",
      "~~~~jjkk~~~~~~~~",
      "~~~~~~lmm~~~~~~~",
      "~~~~~~lmm~~~~~~~",
      "~~~~~~lmm~~~~~~~",
      "~~~~jjkk~~~~~~~~",
      "~~~~~~lljk~~~~~~",
      "~~~~~~lljk~~~~~~",
      "~~~~~~jjee~~~~~~",
      "~~~~~~~~~~~~~~~~",
      "                "
    ],
    [
      "                ",
      "                ",
      "                ",
      "~~~~~~~~~jekk~~~",
      "~~~~~~~~~lllk~~~",
      "~~~~~~~~~lllk~~~",
      "~~~~~~~~jjkkk~~~",
      "~~~~~~~j~lmmk~~~",
      "~~~~~~~j~lmmk~~~",
      "~~~~~~~j~lmmk~~~",
      "~~~~~~~~jjkkk~~~",
      "~~~~~~~~~lllk~~~",
      "~~~~~~~~~lllk~~~",
      "~~~~~~~~~jekk~~~",
      "~~~~~~~~~~~~~~~~",
      "                "
    ],
    [
      "                ",
      "                ",
      "                ",
      "~~~~~~~~~~~~~~~~",
      "~~~~~~~~~~~~~~~~",
      "~~~~~~~~~~~~~~~~",
      "~~~~~~~~~~~~~~~~",
      "~~~~~~~~~~~~~~~~",
      "~~~~~~~~~~~~~~~~",
      "~~~~~~~~~~~~~~~~",
      "~~~~~~~~~~~~~~~~",
      "~~~~~~~~~~~~~~~~",
      "~~~~~~~~~~~~~~~~",
      "~~~~~~~~~~~~~~~~",
      "                ",
      "                "
    ],
    [
      "                ",
      "                ",
      "                ",
      "~~~~~~~~~~~~~~~~",
      "~~~~~~~~~~~~~~~~",
      "~~~~~~~~~~~~~~~~",
      "~~~~~~~~~~~~~~~~",
      "~~~~~~~~~~~~~~~~",
      "~~~~~~~~~~~~~~~~",
      "~~~~~~~~~~~~~~~~",
      "~~~~~~~~~~~~~~~~",
      "~~~~~~~~~~~~~~~~",
      "~~~~~~~~~~~~~~~~",
      "~~~~~~~~~~~~~~~~",
      "                ",
      "                "
    ],
    [
      "                ",
      "                ",
      "                ",
      "~~~~~~~~~~~~~~~~",
      "~~~~~~~~~~~~~~~~",
      "~~~~~~~~~~~~~~~~",
      "~~~~~~~~~~~~~~~~",
      "~~~~~~~~~~~~~~~~",
      "~~~~~~~~~~~~~~~~",
      "~~~~~~~~~~~~~~~~",
      "~~~~~~~~~~~~~~~~",
      "~~~~~~~~~~~~~~~~",
      "~~~~~~~~~~~~~~~~",
      "~~~~~~~~~~~~~~~~",
      "                ",
      "                "
    ]
  ]
}