{
  "name": "rails_down2",
  "refpalette": "deceasedcraft:rails_down2_palette",
  "xsize": 16,
  "zsize": 16,
  "slices": [
    [
      "                ",
      "                ",
      " aaaaaaaaaaaaaaa",
      "baaaaaaaaaaaaaaa",
      "  aaaaaaaaaaaaaa",
      "  aaaaaaaaaaaaaa",
      "  aaaaaaaaaaaaaa",
      "  aaaaaaaaaaaaaa",
      "  aaaaaaaaaaaaaa",
      "  aaaaaaaaaaaaaa",
      "  aaaaaaaaaaaaaa",
      "  aaaaaaaaaaaaaa",
      "  aaaaaaaaaaaaaa",
      "baaaaaaaaaaaaaaa",
      " aaaaaaaaaaaaaaa",
      "                "
    ],
    [
      "                ",
      "                ",
      " aa  c c c c  aa",
      "daaeee         a",
      "fg eee          ",
      "~~   e   c   c  ",
      "~~              ",
      "~~              ",
      "~~       c   c  ",
      "~~              ",
      "~~              ",
      "~~       c   c  ",
      "fg              ",
      "daa            a",
      " aa  c c c c  aa",
      "                "
    ],
    [
      "                ",
      "                ",
      " aaa c c c c  aa",
      "daaae          a",
      "~~g e          e",
      "~~~      c   c e",
      "~~~            e",
      "~~~            e",
      "~~~      c   c e",
      "~~~           ee",
      "~~~         eee ",
      "~~~      c  ecee",
      "~~g          ee ",
      "daaa           a",
      " aaa c c c c  aa",
      "                "
    ],
    [
      "                ",
      "                ",
      " aaaac c c c  aa",
      "daaaa         ea",
      "~~~g         eee",
      "~~~~     c   ce ",
      "~~~~         eee",
      "~~~~      e eeee",
      "~~~~     c  ecee",
      "~~~~      e eeee",
      "~~~~      eeeee ",
      "~~~~     ceeecee",
      "~~~g      eeeee ",
      "daaaa          a",
      " aaaac c c c  aa",
      "                "
    ],
    [
      "                ",
      "                ",
      " aaaaa c c c  aa",
      "daaa a     e e a",
      "~~~~g       ee  ",
      "~~~~~    c  ec  ",
      "~~~~~       ee  ",
      "~~~~~    e  ee e",
      "~~~~~    c  ecee",
      "~~~~~    eeeeeee",
      "~~~~~     eeeee ",
      "~~~~~    ceeecee",
      "~~~~g     eeeee ",
      "daaaba         a",
      " aaaaa c c c  aa",
      "                "
    ],
    [
      "                ",
      "                ",
      " aaaaaac c c  aa",
      " aaadaa    ee  a",
      "~~~~~g      e   ",
      "~~~~~~   c   c  ",
      "~~~~~~      e   ",
      "~~~~~~      ee  ",
      "~~~~~~   c  ec  ",
      "~~~~~~    eeee  ",
      "~~~~~~    eeeee ",
      "~~~~~~   ceeece ",
      "~~~~~g    eeeee ",
      " aaadaa        a",
      " aaaaaac c c  aa",
      "                "
    ],
    [
      "                ",
      "                ",
      " aaaaaaa c c  aa",
      "~haadaaa    e  a",
      "~~~~~~g         ",
      "~~~~~~~  c   c  ",
      "~~~~~~~         ",
      "~~~~~~~     e   ",
      "~~~~~~~  c  ec  ",
      "~~~~~~~   eeee  ",
      "~~~~~~~   eeee  ",
      "~~~~~~~  c eec  ",
      "~~~~~~g   eee   ",
      "~haadaaa       a",
      " aaaaaaa c c  aa",
      "                "
    ],
    [
      "                ",
      "                ",
      " aaaaaaaac c  aa",
      "~~hadaaaa      a",
      "~~~~~~~g        ",
      "~~~~~~~~ c   c  ",
      "~~~~~~~~        ",
      "~~~~~~~~        ",
      "~~~~~~~~ c   c  ",
      "~~~~~~~~  eee   ",
      "~~~~~~~~   ee   ",
      "~~~~~~~~ c eec  ",
      "~~~~~~~g   ee   ",
      "~~hadaaaa      a",
      " aaaaaaaac c  aa",
      "                "
    ],
    [
      "                ",
      "                ",
      " aaaaaaaaa c  aa",
      "h~~hdaaa a     a",
      "h~~~~~~~g       ",
      "h~~~~~~~~    c  ",
      "h~~~~~~~~       ",
      "h~~~~~~~~       ",
      "h~~~~~~~~    c  ",
      "h~~~~~~~~       ",
      "h~~~~~~~~  ee   ",
      "h~~~~~~~~  eec  ",
      "h~~~~~~~g   e   ",
      "h~~hdaaa a     a",
      " aaaaaaaaa c  aa",
      "                "
    ],
    [
      "                ",
      "                ",
      "aaaaaaaaaaac  aa",
      "a~~~ aaadaa    a",
      "a~~~~~~~~g      ",
      "d~~~~~~~~~   c  ",
      "a~~~~~~~~~      ",
      "a~~~~~~~~~      ",
      "a~~~~~~~~~   c  ",
      "a~~~~~~~~~      ",
      "a~~~~~~~~~      ",
      "d~~~~~~~~~   c  ",
      "a~~~~~~~~g      ",
      "a~~~ aaadaa    a",
      "aaaaaaaaaaac  aa",
      "                "
    ],
    [
      "                ",
      "                ",
      "aaaaaaaaaaaa  aa",
      "a~~~dhaadaaa   a",
      "a~~~~~~~~~g     ",
      "d~~~~~~~~~~  c  ",
      "a~~~~~~~~~~     ",
      "a~~~~~~~~~~     ",
      "a~~~~~~~~~~  c  ",
      "a~~~~~~~~~~     ",
      "a~~~~~~~~~~     ",
      "d~~~~~~~~~~  c  ",
      "a~~~~~~~~~g     ",
      "a~~~dhaadaaa   a",
      "aaaaaaaaaaaa  aa",
      "                "
    ],
    [
      "                ",
      "                ",
      "aaaaaaaaaaaaa aa",
      "a~~~d~hadaaaa  a",
      "a~~~~~~~~~~g    ",
      "d~~~~~~~~~~~    ",
      "a~~~~~~~~~~~    ",
      "a~~~~~~~~~~~    ",
      "a~~~~~~~~~~~    ",
      "a~~~~~~~~~~~    ",
      "a~~~~~~~~~~~    ",
      "d~~~~~~~~~~~    ",
      "a~~~~~~~~~~g    ",
      "a~~~d~hadaaaa  a",
      "aaaaaaaaaaaaa aa",
      "                "
    ],
    [
      "                ",
      "                ",
      "aaaaaaaaaaaaaaaa",
      "a~~~d~~hdaaa aaa",
      "a~~~~~~~~~~~g   ",
      "d~~~~~~~~~~~~~  ",
      "a~~~~~~~~~~~~~  ",
      "a~~~~~~~~~~~~~  ",
      "a~~~~~~~~~~~~~  ",
      "a~~~~~~~~~~~~~  ",
      "a~~~~~~~~~~~~~  ",
      "d~~~~~~~~~~~~~  ",
      "a~~~~~~~~~~~g   ",
      "a~~~d~~hdaaa aaa",
      "aaaaaaaaaaaaaaaa",
      "                "
    ],
    [
      "                ",
      "                ",
      "aaaaaaaaaaaaaaaa",
      "a~~~d~~~ aaadaaa",
      "a~~~~~~~~~~~~fff",
      "d~~~~~~~~~~~~~~~",
      "a~~~~~~~~~~~~~~~",
      "a~~~~~~~~~~~~~~~",
      "a~~~~~~~~~~~~~~i",
      "a~~~~~~~~~~~~~~~",
      "a~~~~~~~~~~~~~~~",
      "d~~~~~~~~~~~~~~~",
      "a~~~~~~~~~~~~fff",
      "a~~~d~~~ aaadaaa",
      "aaaaaaaaaaaaaaaa",
      "                "
    ],
    [
      "                ",
      "                ",
      "aaaaaaaaaaaaaaaa",
      "a~~~d~~~dhaadaaa",
      "a~~~~~~~~~~~~~~~",
      "d~~~~~~~~~~~~~~~",
      "a~~~~~~~~~~~~~~~",
      "a~~~~~~~~~~~~~~~",
      "a~~~~~~~~~~~~~~~",
      "a~~~~~~~~~~~~~~~",
      "a~~~~~~~~~~~~~~~",
      "d~~~~~~~~~~~~~~~",
      "a~~~~~~~~~~~~~~~",
      "a~~~d~~~dhaadaaa",
      "aaaaaaaaaaaaaaaa",
      "                "
    ],
    [
      "                ",
      "                ",
      "aaaaaaaaaaaaaaaa",
      "a~~~d~~~d~hadaaa",
      "a~~~~~~~~~~~~~~~",
      "d~~~~~~~~~~~~~~~",
      "a~~~~~~~~~~~~~~~",
      "a~~~~~~~~~~~~~~~",
      "a~~~~~~~~~~~~~~~",
      "a~~~~~~~~~~~~~~~",
      "a~~~~~~~~~~~~~~~",
      "d~~~~~~~~~~~~~~~",
      "a~~~~~~~~~~~~~~~",
      "a~~~d~~~d~hadaaa",
      "aaaaaaaaaaaaaaaa",
      "                "
    ],
    [
      "                ",
      "                ",
      "aaaaaaaaaaaaaaaa",
      "a~~~d~~~d~~hdaaa",
      "a~~~~~~~~~~~~~~~",
      "d~~~~~~~~~~~~~~~",
      "a~~~~~~~~~~~~~~~",
      "a~~~~~~~~~~~~~~~",
      "a~~~~~~~~~~~~~~~",
      "a~~~~~~~~~~~~~~~",
      "a~~~~~~~~~~~~~~~",
      "d~~~~~~~~~~~~~~~",
      "a~~~~~~~~~~~~~~~",
      "a~~~d~~~d~~hdaaa",
      "aaaaaaaaaaaaaaaa",
      "                "
    ],
    [
      "                ",
      "                ",
      "aaaaaaaaaaaaaaaa",
      "a~~~b~~~b~~~bhhh",
      "a~~~~~~~~~~~~~~~",
      "d~~~~~~~~~~~~~~~",
      "a~~~~~~~~~~~~~~~",
      "a~~~~~~~~~~~~~~~",
      "a~~~~~~~~~~~~~~~",
      "a~~~~~~~~~~~~~~~",
      "a~~~~~~~~~~~~~~~",
      "d~~~~~~~~~~~~~~~",
      "a~~~~~~~~~~~~~~~",
      "a~~~b~~~b~~~bhhh",
      "aaaaaaaaaaaaaaaa",
      "                "
    ],
    [
      "                ",
      "                ",
      "                ",
      " hhhhhhhhhhhhhhh",
      " hhhhhhhhhhhhhhj",
      " ggggggggggggggk",
      " vvvvvvvvvvvvvvl",
      " vvvvvvvvvvvvvvl",
      " vvvvvvvvvvvvvvl",
      " vvvvvvvvvvvvvvl",
      " vvvvvvvvvvvvvvl",
      " ggggggggggggggk",
      " hhhhhhhhhhhhhhj",
      " hhhhhhhhhhhhhhh",
      "                ",
      "                "
    ]
  ]
}