{
  "name": "rails_bend",
  "refpalette": "deceasedcraft:rails_bend_palette",
  "xsize": 16,
  "zsize": 16,
  "slices": [
    [
      " abacccccccccaba",
      " aaacccccccccaaa",
      "aaaacccccccccaaa",
      "ccbacccccccccaaa",
      "cccccccccccccaaa",
      "cccccccccccccaba",
      "cccccccccccccaaa",
      "cccccccccccccaaa",
      "cccccccccccccaaa",
      "cccccccccccccaaa",
      "cccccccccccccaba",
      "cccccccccccccaaa",
      "cccccccccccccaaa",
      "aabacccccccccaaa",
      "aaaacccccccccaaa",
      " abacccccccccaba"
    ],
    [
      " adee~~~f~~~eeda",
      " aae~~~~f~~~~eaa",
      "aaae~~~~f~~~~eaa",
      "aade~~~~f~~~~eaa",
      "eeee~~~~f~~~~eaa",
      "~~~~~~~~f~~~~eda",
      "~~~g~~~~f~~~~eaa",
      "~~~~~h~~f~~~~eaa",
      "i~~~~~~~f~~~~eaa",
      "~~~~~f~~f~~~~eaa",
      "~~h~~~~~f~~~~eda",
      "~~~~~~~~f~~~~eaa",
      "eeee~~~~f~~~~eaa",
      "aade~~~~f~~~~eaa",
      "aaae~~~~f~~~~eaa",
      " adee~~~f~~~eeda"
    ],
    [
      " ad~~~~~~~~~~~da",
      " aa~~~~~~~~~~~aa",
      "aaa~~~~~~~~~~~aa",
      "aad~~~~~~~~~~~aa",
      "~~~~~~~~~~~~~~aa",
      "~~~~~~~~~~~~~~da",
      "~~~~~~~~~~~~~~aa",
      "~~~~~~~~~~~~~~aa",
      "~~~~~~~~~~~~~~aa",
      "~~~~~~~~~~~~~~aa",
      "~~~~~~~~~~~~~~da",
      "~~~~~~~~~~~~~~aa",
      "~~~~~~~~~~~~~~aa",
      "aad~~~~~~~~~~~aa",
      "aaa~~~~~~~~~~~aa",
      " ad~~~~~~~~~~~da"
    ],
    [
      " ad~~~~~~~~~~~da",
      " aa~~~~~~~~~~~aa",
      "aaa~~~~~~~~~~~aa",
      "aad~~~~~~~~~~~aa",
      "~~~~~~~~~~~~~~aa",
      "~~~~~~~~~~~~~~da",
      "~~~~~~~~~~~~~~aa",
      "~~~~~~~~~~~~~~aa",
      "~~~~~~~~~~~~~~aa",
      "~~~~~~~~~~~~~~aa",
      "~~~~~~~~~~~~~~da",
      "~~~~~~~~~~~~~~aa",
      "~~~~~~~~~~~~~~aa",
      "aad~~~~~~~~~~~aa",
      "aaa~~~~~~~~~~~aa",
      " ad~~~~~~~~~~~da"
    ],
    [
      " ad~~~~~~~~~~~da",
      " a~~~~~~~~~~~~~a",
      "aa~~~~~~~~~~~~~a",
      "~~d~~~~~~~~~~~~a",
      "~~~~~~~~~~~~~~~a",
      "~~~~~~~~~~~~~~da",
      "~~~~~~~~~~~~~~~a",
      "~~~~~~~~~~~~~~~a",
      "~~~~~~~~~~~~~~~a",
      "~~~~~~~~~~~~~~~a",
      "~~~~~~~~~~~~~~da",
      "~~~~~~~~~~~~~~~a",
      "~~~~~~~~~~~~~~~a",
      "~~d~~~~~~~~~~~~a",
      "aa~~~~~~~~~~~~~a",
      " ad~~~~~~~~~~~da"
    ],
    [
      " a ~~~~~~~~~~~ a",
      " aj~~~~~~~~~~~ja",
      "aaj~~~~~~~~~~~ja",
      "jj ~~~~~~~~~~~ja",
      "~~~~~~~~~~~~~~ja",
      "~~~~~~~~~~~~~~ a",
      "~~~~~~~~~~~~~~ja",
      "~~~~~~~~~~~~~~ja",
      "~~~~~~~~~~~~~~ja",
      "~~~~~~~~~~~~~~ja",
      "~~~~~~~~~~~~~~ a",
      "~~~~~~~~~~~~~~ja",
      "~~~~~~~~~~~~~~ja",
      "jj ~~~~~~~~~~~ja",
      "aaj~~~~~~~~~~~ja",
      " a ~~~~~~~~~~~ a"
    ],
    [
      " ad~~~~~~~~~~~da",
      " a~~~~~~~~~~~~~a",
      "aa~~~~~~~~~~~~~a",
      "~~d~~~~~~~~~~~~a",
      "~~~~~~~~~~~~~~~a",
      "~~~~~~~~~~~~~~da",
      "~~~~~~~~~~~~~~~a",
      "~~~~~~~~~~~~~~~a",
      "~~~~~~~~~~~~~~~a",
      "~~~~~~~~~~~~~~~a",
      "~~~~~~~~~~~~~~da",
      "~~~~~~~~~~~~~~~a",
      "~~~~~~~~~~~~~~~a",
      "~~d~~~~~~~~~~~~a",
      "aa~~~~~~~~~~~~~a",
      " ad~~~~~~~~~~~da"
    ],
    [
      " abkkkkkkkkkkkba",
      " aa~~~~~~~~~~~aa",
      "aaa~~~~~~~~~~~aa",
      "aab~~~~~~~~~~~aa",
      "k~k~~~~~~~~~~~aa",
      "kkkkkkkkkkkkkkba",
      "k~k~~~~~~~~~~~aa",
      "k~k~~~~~~~~~~~aa",
      "k~k~~~~~~~~~~~aa",
      "k~k~~~~~~~~~~~aa",
      "kkkkkkkkkkkkkkba",
      "k~k~~~~~~~~~~~aa",
      "k~k~~~~~~~~~~~aa",
      "aab~~~~~~~~~~~aa",
      "aaa~~~~~~~~~~~aa",
      " abkkkkkkkkkkkba"
    ],
    [
      "  jaaaaaaaaaaaj ",
      "  jlmmmmmmmmmlj ",
      "  jlmmmmmmmmmlj ",
      "jjjlmmmmmmmmmlj ",
      "jjjlmmmmmmmmmlj ",
      "jjjlmmmmmmmmmlj ",
      "llllmmmmmmmmmlj ",
      "mmmmmmmmmmmmmlj ",
      "mmmmmmmmmmmmmlj ",
      "mmmmmmmmmmmmmlj ",
      "llllmmmmmmmmmlj ",
      "jjjlmmmmmmmmmlj ",
      "jjjlmmmmmmmmmlj ",
      "jjjlmmmmmmmmmlj ",
      "  jlmmmmmmmmmlj ",
      "  jaaaaaaaaaaaj "
    ]
  ]
}