{
  "name": "rails_3split",
  "refpalette": "deceasedcraft:rails_3split_palette",
  "xsize": 16,
  "zsize": 16,
  "slices": [
    [
      "   aHHHHHHHHHa  ",
      "   aHHHHHHHHHa  ",
      "aaaaHHHHHHHHHa a",
      "bHHbHHHHHHHHHbHb",
      "HHHHHHHHHHHHHHHH",
      "HHHHHHHHHHHHHHHH",
      "HHHHHHHHHHHHHHHH",
      "HHHHHHHHHHHHHHHH",
      "HHHHHHHHHHHHHHHH",
      "HHHHHHHHHHHHHHHH",
      "HHHHHHHHHHHHHHHH",
      "HHHHHHHHHHHHHHHH",
      "HHHHHHHHHHHHHHHH",
      "baabHHHHHHHHHbHb",
      "aaaaHHHHHHHHHaaa",
      "   aHHHHHHHHH~  "
    ],
    [
      "   ac~~~d~~~ca  ",
      "   ac~~~d~~~ca  ",
      "aaaac~~~d~~~caaa",
      "eaaec~~~d~~~ceae",
      "ccccc~~~d~~~cccc",
      "~~~~~~~~d~~~~~~~",
      "~~~~~~~~d~~~~~~~",
      "~~~~~~~~d~~~~~~~",
      "ffffffffgfffffff",
      "~~~~~~~~d~~~~~~~",
      "~~~~~~~~d~~~~~~~",
      "~~~~~~~~d~~~~~~~",
      "ccccc~~~d~~~cccc",
      "eaaec~~~d~~~ceae",
      "aaaac~~~d~~~caaa",
      "   ac~~~d~~~ca  "
    ],
    [
      "   a~~~~~~~~~a  ",
      "   a~~~~~~~~~a  ",
      "aaaa~~~~~~~~~aaa",
      "eaae~~~~~~~~~eae",
      "~~~~~~~~~~~~~~~~",
      "~~~~~~~~~~~~~~~~",
      "~~~~~~~~~~~~~~~~",
      "~~~~~~~~~~~~~~~~",
      "~~~~~~~~~~~~~~~~",
      "~~~~~~~~~~~~~~~~",
      "~~~~~~~~~~~~~~~~",
      "~~~~~~~~~~~~~~~~",
      "~~~~~~~~~~~~~~~~",
      "eaae~~~~~~~~~eae",
      "aaaa~~~~~~~~~aaa",
      "   a~~~~~~~~~a  "
    ],
    [
      "   a~~~~~~~~~a  ",
      "   a~~~~~~~~~a  ",
      "aaaa~~~~~~~~~aaa",
      "eaae~~~~~~~~~eae",
      "~~~~~~~~~~~~~~~~",
      "~~~~~~~~~~~~~~~~",
      "~~~~~~~~~~~~~~~~",
      "~~~~~~~~~~~~~~~~",
      "~~~~~~~~~~~~~~~~",
      "~~~~~~~~~~~~~~~~",
      "~~~~~~~~~~~~~~~~",
      "~~~~~~~~~~~~~~~~",
      "~~~~~~~~~~~~~~~~",
      "eaae~~~~~~~~~eae",
      "aaaa~~~~~~~~~aaa",
      "   a~~~~~~~~~a  "
    ],
    [
      "   a~~~~~~~~~a  ",
      "   a~~~~~~~~~a  ",
      "aaaa~~~~~~~~~aaa",
      "eaae~~~~~~~~~eae",
      "~~~~~~~~~~~~~~~~",
      "~~~~~~~~~~~~~~~~",
      "~~~~~~~~~~~~~~~~",
      "~~~~~~~~~~~~~~~~",
      "~~~~~~~~~~~~~~~~",
      "~~~~~~~~~~~~~~~~",
      "~~~~~~~~~~~~~~~~",
      "~~~~~~~~~~~~~~~~",
      "~~~~~~~~~~~~~~~~",
      "eaae~~~~~~~~~eae",
      "aaaa~~~~~~~~~aaa",
      "   a~~~~~~~~~a  "
    ],
    [
      "   h~~~~~~~~~h  ",
      "   h~~~~~~~~~h  ",
      "aaah~~~~~~~~~haa",
      "~hh~~~~~~~~~~~h~",
      "~~~~~~~~~~~~~~~~",
      "~~~~~~~~~~~~~~~~",
      "~~~~~~~~~~~~~~~~",
      "~~~~~~~~~~~~~~~~",
      "~~~~~~~~~~~~~~~~",
      "~~~~~~~~~~~~~~~~",
      "~~~~~~~~~~~~~~~~",
      "~~~~~~~~~~~~~~~~",
      "~~~~~~~~~~~~~~~~",
      "~hh~~~~~~~~~~~h~",
      "aaah~~~~~~~~~haa",
      "   h~~~~~~~~~h  "
    ],
    [
      "   a~~~~~~~~~a  ",
      "   a~~~~~~~~~a  ",
      "aaaa~~~~~~~~~aaa",
      "eaae~~~~~~~~~eae",
      "~~~~~~~~~~~~~~~~",
      "~~~~~~~~~~~~~~~~",
      "~~~~~~~~~~~~~~~~",
      "~~~~~~~~~~~~~~~~",
      "~~~~~~~~~~~~~~~~",
      "~~~~~~~~~~~~~~~~",
      "~~~~~~~~~~~~~~~~",
      "~~~~~~~~~~~~~~~~",
      "~~~~~~~~~~~~~~~~",
      "eaae~~~~~~~~~eae",
      "aaaa~~~~~~~~~aaa",
      "   a~~~~~~~~~a  "
    ],
    [
      "   a~iiiiiii~a  ",
      "   ai~~~~~~~ia  ",
      "aaaai~~~~~~~iaaa",
      "~aabi~~~~~~~iba~",
      "iiiiiiiiiiiiiiii",
      "i~~~i~~~~~~~i~~i",
      "i~~~i~~~~~~~i~~i",
      "i~~~i~~~~~~~i~~i",
      "i~~~i~~~~~~~i~~i",
      "i~~~i~~~~~~~i~~i",
      "i~~~i~~~~~~~i~~i",
      "i~~~i~~~~~~~i~~i",
      "iiiiiiiiiiiiiiii",
      "~aabi~~~~~~~iba~",
      "aaaai~~~~~~~iaaa",
      "   a~iiiiiii~a  "
    ],
    [
      "    hhaaaaahh   ",
      "    hhjkkkjhh   ",
      "    hhjkkkjhh   ",
      "hhhhhhjkkkjhhhhh",
      "hhhhhhjkkkjhhhhh",
      "hhhhhhjkkkjhhhhh",
      "jjjjjjjkkkjjjjjj",
      "kkkkkkkkkkkkkkkk",
      "kkkkkkkkkkkkkkkk",
      "kkkkkkkkkkkkkkkk",
      "jjjjjjjkkkjjjjjj",
      "hhhhhhjkkkjhhhhh",
      "hhhhhhjkkkjhhhhh",
      "hhhhhhjkkkjhhhhh",
      "    hhjkkkjhh   ",
      "    hhaaaaahh   "
    ]
  ]
}