{
  "name": "multi_filmworkstower_22_floor2",
  "refpalette": "deceasedcraft:multi_filmworkstower_22/multi_filmworkstower_22_floor2_palette",
  "xsize": 16,
  "zsize": 16,
  "slices": [
    [
      "                ",
      "                ",
      "                ",
      "                ",
      "                ",
      "                ",
      "aaaaaaaaaaaaa   ",
      "bbbbbbbbbbbba   ",
      "cccccccccccba   ",
      "bdddddddddcba   ",
      "ddddddddddcba   ",
      "ddddddddddcba   ",
      "ddddddddddcba   ",
      "ddddddddddcba   ",
      "ddddddddddcba   ",
      "ddddddddddcba   "
    ],
    [
      "                ",
      "                ",
      "                ",
      "                ",
      "                ",
      "                ",
      "aaaaaaaaaaaaa   ",
      "eeeeeeeeeeeea   ",
      "fffffffffffea   ",
      "bg        fea   ",
      "    hiiij fea   ",
      "        k fea   ",
      "     ll m fea   ",
      "        n fea   ",
      "          fea   ",
      "          fea   "
    ],
    [
      "                ",
      "                ",
      "                ",
      "                ",
      "                ",
      "                ",
      "aaaaaaaaaaaaa   ",
      "ooooooooooooa   ",
      "           oa   ",
      " pg        oa   ",
      "           oa   ",
      "           oa   ",
      "           oa   ",
      "        q  oa   ",
      "           oa   ",
      "           oa   "
    ],
    [
      "                ",
      "                ",
      "                ",
      "                ",
      "                ",
      "                ",
      "aaaaaaaaaaaaa   ",
      "ooooooooooooa   ",
      "           oa   ",
      "  pg       oa   ",
      "           oa   ",
      "           oa   ",
      "           oa   ",
      "           oa   ",
      "           oa   ",
      "           oa   "
    ],
    [
      "                ",
      "                ",
      "                ",
      "                ",
      "                ",
      "                ",
      "aaaaaaaaaaaaa   ",
      "ooo oooo oooa   ",
      "           oa   ",
      "   pg       a   ",
      "           oa   ",
      "           oa   ",
      "           oa   ",
      "            a   ",
      "           oa   ",
      "           oa   "
    ],
    [
      "                ",
      "                ",
      "                ",
      "                ",
      "                ",
      "                ",
      "aaaaaaaaaaaaa   ",
      "oo   oo    oa   ",
      "            a   ",
      "    pg      a   ",
      "            a   ",
      "            a   ",
      "           oa   ",
      "            a   ",
      "            a   ",
      "           oa   "
    ]
  ]
}