{
  "name": "multi_filmworkstower_22_base1",
  "refpalette": "deceasedcraft:multi_filmworkstower_22/multi_filmworkstower_22_base1_palette",
  "xsize": 16,
  "zsize": 16,
  "slices": [
    [
      "         a    bv",
      "         a    bv",
      "         a    bv",
      "         a    bv",
      "         a    bv",
      "         a    bv",
      "         a    bv",
      "         a    bv",
      "         a    bv",
      "         ac   bv",
      "         a    bv",
      "         a    bv",
      "         a    bv",
      "         a    bv",
      "         a    bv",
      "         a    bv"
    ],
    [
      "         a    bv",
      "         a    bv",
      "         a    bv",
      "         a    bv",
      "         a    bv",
      "         a    bv",
      "         a    bv",
      "         a    bv",
      "         ad   bv",
      "         ace  bv",
      "         af   bv",
      "         a    bv",
      "         a    bv",
      "         a    bv",
      "         a    bv",
      "         a    bv"
    ],
    [
      "         ag   bv",
      "         ag   bv",
      "         ag   bv",
      "         ag   bv",
      "         ag   bv",
      "         ag   bv",
      "         ag   bv",
      "         ag   bv",
      "         ag   bv",
      "         achhhbv",
      "         ag   bv",
      "         ag   bv",
      "         ag   bv",
      "         ag   bv",
      "         ag   bv",
      "         ag   bv"
    ],
    [
      "   i          bv",
      "   j          bv",
      "   j          bv",
      "   j          bv",
      "   j          bv",
      "   k          bv",
      "   j          bv",
      "   j          bv",
      "   j          bv",
      "   j     lcm  bv",
      "   k          bv",
      "   j          bv",
      "   j          bv",
      "   j          bv",
      "   j          bv",
      "   i          bv"
    ],
    [
      "nonpnonpqrsrrrbv",
      "tutttutpqrsrrrbv",
      "tutttutpqrsrrrbv",
      "tutttutpqrsrrrbv",
      "tutttutpqrsrrrbv",
      "nonpnonpqrsrrrbv",
      "tutttutpqrsrrrbv",
      "tutttutpqrsrrrbv",
      "tutttutpqrsrrrbv",
      "tutttutpqrwrrrbv",
      "nonpnonpqrsrrrbv",
      "tutttutpqrsrrrbv",
      "tutttutpqrsrrrbv",
      "tutttutpqrsrrrbv",
      "tutttutpqrsrrrbv",
      "nonpnonpqrsrrrbv"
    ],
    [
      "xxxxxxxxxxxxxxbv",
      "xxxxxxxxxxxxxxbv",
      "xxxxxxxxxxxxxxbv",
      "xxxxxxxxxxxxxxbv",
      "xxxxxxxxxxxxxxbv",
      "xxxxxxxxxxxxxxbv",
      "xxxxxxxxxxxxxxbv",
      "xxxxxxxxxxxxxxbv",
      "xxxxxxxxxxxxxxbv",
      "xxxxxxxxxxxxxxbv",
      "xxxxxxxxxxxxxxbv",
      "xxxxxxxxxxxxxxbv",
      "xxxxxxxxxxxxxxbv",
      "xxxxxxxxxxxxxxbv",
      "xxxxxxxxxxxxxxbv",
      "xxxxxxxxxxxxxxbv"
    ]
  ]
}