{
  "name": "multi_filmworkstower_22_base3",
  "refpalette": "deceasedcraft:multi_filmworkstower_22/multi_filmworkstower_22_base3_palette",
  "xsize": 16,
  "zsize": 16,
  "slices": [
    [
      "aaaaaaaaaaabbbbv",
      "aaaaaaaaaaabbbbv",
      "aaaaaaaaaaabbbbv",
      "aaaaaaaaaaabbbbv",
      "aaaaaaaaaaabbbbv",
      "aaaaaaaaaaabbbbv",
      "aaaaaaaaaaabbbbv",
      "aaaaaaaaaaabbbbv",
      "aaaaaaaaaaabbbbv",
      "aaaaaaaaaaabbbbv",
      "aaaaaaaaaaabbbbv",
      "aaaaaaaaaaabbbbv",
      "aaaaaaaaaaabbbbv",
      "aaaaaaaaaaabbbbv",
      "aaaaaaaaaaabbbbv",
      "aaaaaaaaaaabbbbv"
    ],
    [
      "cccccccccdabbbbv",
      "cccccccccdabbbbv",
      "cccccccccdabbbbv",
      "cccccccccdabbbbv",
      "cccccccccdabbbbv",
      "cceccccccdabbbbv",
      "ccffcccccdabbbbv",
      "ccgccccccdabbbbv",
      "ccgcfccccdabbbbv",
      "ccgccccccdabbbbv",
      "ccgcccfccdabbbbv",
      "ccgccccccdabbbbv",
      "ccgccccccdabbbbv",
      "ccgecccccdabbbbv",
      "ccgccccccdabbbbv",
      "cfgccfcccdabbbbv"
    ],
    [
      "     h hfdabbbbv",
      " h    h cdabbbbv",
      "   f   fcdabbbbv",
      "         dabbbbv",
      "        fdabbbbv",
      "      i hdabbbbv",
      "jkl      dabbbbv",
      " k       dabbbbv",
      "jkl  h   dabbbbv",
      "mk       dabbbbv",
      "mkl      dabbbbv",
      "mk      fdabbbbv",
      "jkl      dabbbbv",
      "       i dabbbbv",
      "         dabbbbv",
      "         dabbbbv"
    ],
    [
      "         dabbbbv",
      "         dabbbbv",
      "        fdabbbbv",
      "         dabbbbv",
      "         dabbbbv",
      "no       dabbbbv",
      "ppp      dabbbbv",
      " qpr     dabbbbv",
      "sqpr     dabbbbv",
      " qpr     dabbbbv",
      " apr     dabbbbv",
      "sqpr     dabbbbv",
      "  pr     dabbbbv",
      "jtor     dabbbbv",
      "uwx      dabbbbv",
      "         dabbbbv"
    ],
    [
      "         dabbbbv",
      "         dabbbbv",
      "         dabbbbv",
      "         dabbbbv",
      "         dabbbbv",
      " y       dabbbbv",
      "ABC      dabbbbv",
      "DEC      dabbbbv",
      " FC      dabbbbv",
      " IC      dabbbbv",
      " EC      dabbbbv",
      " EJ      dabbbbv",
      " KL      dabbbbv",
      "MnB      dabbbbv",
      "NxO      dabbbbv",
      "         dabbbbv"
    ],
    [
      "         dabbbbv",
      "         dabbbbv",
      "         dabbbbv",
      "         dabbbbv",
      "         dabbbbv",
      "         dabbbbv",
      "         dabbbbv",
      "o        dabbbbv",
      "PQ       dabbbbv",
      "RS       dabbbbv",
      " S       dabbbbv",
      "TQ       dabbbbv",
      " S       dabbbbv",
      "Mp       dabbbbv",
      "UC       dabbbbv",
      "         dabbbbv"
    ]
  ]
}