{
  "name": "multi_filmworkstower_22_floor3",
  "refpalette": "deceasedcraft:multi_filmworkstower_22/multi_filmworkstower_22_floor3_palette",
  "xsize": 16,
  "zsize": 16,
  "slices": [
    [
      "                ",
      "                ",
      "                ",
      "                ",
      "                ",
      "                ",
      "aaaaaaaaaaaaa   ",
      "            a   ",
      "            a   ",
      "     bc     a   ",
      "            a   ",
      "            a   ",
      "            a   ",
      "            a   ",
      "            a   ",
      "            a   "
    ],
    [
      "                ",
      "                ",
      "                ",
      "                ",
      "                ",
      "                ",
      "aaaaaaaaaaaaa   ",
      "            a   ",
      "            a   ",
      "      bcd   a   ",
      "            a   ",
      "            a   ",
      "            a   ",
      "            a   ",
      "            a   ",
      "            a   "
    ],
    [
      "                ",
      "                ",
      "                ",
      "                ",
      "                ",
      "                ",
      "aaaaaaaaaaaaa   ",
      "aaaaaaaaaaaaa   ",
      "eeeeeeeeeeeaa   ",
      "fffffffff eaa   ",
      "gggggggggfeaa   ",
      "gggggggggfeaa   ",
      "gggggggggfeaa   ",
      "gggggggggfeaa   ",
      "gggggggggfeaa   ",
      "gggggggggfeaa   "
    ],
    [
      "                ",
      "                ",
      "                ",
      "                ",
      "                ",
      "                ",
      "                ",
      "                ",
      "                ",
      "                ",
      "hhhhhhhhh       ",
      "iiiiiiiih       ",
      "hhhhhhhhh       ",
      "hhhhhhhhh       ",
      "iiiiiiiih       ",
      "hhhhhhhhh       "
    ],
    [
      "                ",
      "                ",
      "                ",
      "                ",
      "                ",
      "                ",
      "                ",
      "                ",
      "                ",
      "                ",
      "                ",
      "                ",
      "                ",
      "                ",
      "                ",
      "                "
    ],
    [
      "                ",
      "                ",
      "                ",
      "                ",
      "                ",
      "                ",
      "                ",
      "                ",
      "                ",
      "                ",
      "                ",
      "                ",
      "                ",
      "                ",
      "                ",
      "                "
    ]
  ]
}