{
  "name": "multi_filmworkstower_22_base2",
  "refpalette": "deceasedcraft:multi_filmworkstower_22/multi_filmworkstower_22_base2_palette",
  "xsize": 16,
  "zsize": 16,
  "slices": [
    [
      "         abbbbcv",
      "         abbbbcv",
      "         abbbbcv",
      "         abbbbcv",
      "         abbbbcv",
      "         abbbbcv",
      "         abbbbcv",
      "d        abbbbcv",
      "         abbbbcv",
      " e       abbbbcv",
      "fg       abbbbcv",
      "he       abbbbcv",
      "gi       abbbbcv",
      "jk       abbbbcv",
      "lk       abbbbcv",
      "         abbbbcv"
    ],
    [
      "         a    cv",
      "         a    cv",
      "         a    cv",
      "         a    cv",
      "         a    cv",
      "         a    cv",
      "m        a    cv",
      "m        a    cv",
      "n        a    cv",
      "o        apq  cv",
      "         a    cv",
      "         a    cv",
      "         a    cv",
      "r        a    cv",
      "         a    cv",
      "         a    cv"
    ],
    [
      "         a    cv",
      "         a    cv",
      "         a    cv",
      "         a    cv",
      "         a    cv",
      "         a    cv",
      "         a    cv",
      "         a    cv",
      "         a    cv",
      "         ap   cv",
      "         a    cv",
      "         a    cv",
      "         a    cv",
      "rr       a    cv",
      "r        a    cv",
      "         a    cv"
    ],
    [
      "         a    cv",
      "         a    cv",
      "         a    cv",
      "         a    cv",
      "         a    cv",
      "         a    cv",
      "         a    cv",
      "         a    cv",
      "         as   cv",
      "         ap   cv",
      "         at   cv",
      "         a    cv",
      "         a    cv",
      "         a    cv",
      "         a    cv",
      "         a    cv"
    ],
    [
      "         au   cv",
      "         au   cv",
      "         au   cv",
      "         au   cv",
      "         au   cv",
      "         au   cv",
      "         au   cv",
      "         au   cv",
      "         au   cv",
      "         apw  cv",
      "         au   cv",
      "         au   cv",
      "         au   cv",
      "         au   cv",
      "         au   cv",
      "         au   cv"
    ],
    [
      "         a    cv",
      "         a    cv",
      "         a    cv",
      "         a    cv",
      "         a    cv",
      "         a    cv",
      "         a    cv",
      "         a    cv",
      "         a    cv",
      "         ap   cv",
      "         a    cv",
      "         a    cv",
      "         a    cv",
      "         a    cv",
      "         a    cv",
      "         a    cv"
    ]
  ]
}