{
  "name": "multi_thering_16_ground",
  "refpalette": "deceasedcraft:multi_thering_16/multi_thering_16_ground_palette",
  "xsize": 16,
  "zsize": 16,
  "slices": [
    [
      "aaaaaabbbbaaaaaa",
      "acccccccccccccca",
      "acccccccccccccca",
      "acccccccccccccca",
      "acccccccccccccca",
      "bcccccccccccccca",
      "bcccccccccccccca",
      "bcccccccccccccca",
      "acccaaacccccccca",
      "accccdeaccccccca",
      "acccad accccccca",
      "afccag accccccca",
      "a   a  accccccca",
      "a   a  accccccca",
      "a   a  accccccca",
      "aaaaaaaaaaaaaaah"
    ],
    [
      "ijjjjjk  ljjjjja",
      "j              j",
      "j    a        mj",
      "j  n a        oj",
      "jppppa        oj",
      "q r r         oj",
      "              sj",
      "t              j",
      "j   aaa        j",
      "j    u a      mj",
      "jwxya  a      oj",
      "jaAAaB a      oj",
      "j   ag a      oj",
      "j   a  a      sj",
      "j   a  a       j",
      "ajjjjjjjjjjjjjji"
    ],
    [
      "ijjjjjk  ljjjjja",
      "j              j",
      "j    C         j",
      "j              j",
      "j   DE         j",
      "q              j",
      "               j",
      "t              j",
      "j   aaa        j",
      "j    F a       j",
      "j IJa  a       j",
      "ja  a  a       j",
      "j   aB a       j",
      "j   agKa       j",
      "j   a  a       j",
      "ajjjjjjjjjjjjjji"
    ],
    [
      "ijjjjjLMMNjjjjja",
      "j              j",
      "j              j",
      "j              j",
      "j              j",
      "O              j",
      "M              j",
      "P    Q         j",
      "j   aaa        j",
      "j   RS a       j",
      "j TUa  a       j",
      "jaVVa  aW      j",
      "j   a XaY      j",
      "j   aBda       j",
      "j   agga       j",
      "ajjjjjjjjjjjjjji"
    ],
    [
      "ijjjjjjjjjjjjjja",
      "j              j",
      "j              j",
      "j              j",
      "j              j",
      "j              j",
      "j              j",
      "j    Z  0      j",
      "j   aaa        j",
      "j   a  a       j",
      "j   a  a       j",
      "jaaaa Xa1      j",
      "j   a ea2      j",
      "j   a  a       j",
      "j   a  a       j",
      "ajjjjjjjjjjjjjji"
    ],
    [
      "ijjjjjjjjjjjjjja",
      "j              j",
      "j              j",
      "j              j",
      "j              j",
      "j              j",
      "j              j",
      "j       3      j",
      "j   aaa 0      j",
      "j   a  a       j",
      "j   aKXa       j",
      "jaaaa ea       j",
      "j   a  a       j",
      "j   a  a       j",
      "j   a  a       j",
      "ajjjjjjjjjjjjjji"
    ]
  ]
}