{
  "name": "multi_thering_16_floor15",
  "refpalette": "deceasedcraft:multi_thering_16/multi_thering_16_floor15_palette",
  "xsize": 16,
  "zsize": 16,
  "slices": [
    [
      "a              b",
      "                ",
      "                ",
      "                ",
      "                ",
      "                ",
      "                ",
      "                ",
      "                ",
      "                ",
      "                ",
      " bbbb           ",
      "c   b           ",
      "c   b           ",
      "c   b           ",
      "bccc           a"
    ],
    [
      "a              b",
      "                ",
      "                ",
      "                ",
      "                ",
      "                ",
      "                ",
      "                ",
      "                ",
      "                ",
      "                ",
      " bbbb           ",
      "c   b           ",
      "c   b           ",
      "c   b           ",
      "bccc           a"
    ],
    [
      "a              b",
      " dddddddddddddd ",
      " d            d ",
      " d            d ",
      " d            d ",
      " d            d ",
      " d            d ",
      " d            d ",
      " d            d ",
      " d            d ",
      " d            d ",
      " bbbb         d ",
      "c   b         d ",
      "c   b         d ",
      "c   bdddddddddd ",
      "bccc           a"
    ],
    [
      "abbbbbbbbbbbbbbb",
      "befffeffffefffeb",
      "bfgggfggggfgggfb",
      "bfgggfggggfgggfb",
      "bfgggfggggfgggfb",
      "befffeffffefffeb",
      "bfgggfggggfgggfb",
      "bfgggfggggfgggfb",
      "bfgggfggggfgggfb",
      "bfgggfggggfgggfb",
      "befffeffffefffeb",
      "bbbbbfggggfgggfb",
      "b   bfggggfgggfb",
      "bhijkfggggfgggfb",
      "bhjlbeffffefffeb",
      "bbbbbbbbbbbbbbba"
    ],
    [
      "ammmmmmmmmmmmmmm",
      "mnnnnnnnnnnnnnnm",
      "mnooonoooonooonm",
      "mnooonoooonooonm",
      "mnooonoooonooonm",
      "mnnnnnnnnnnnnnnm",
      "mnooonoooonooonm",
      "mnooonoooonooonm",
      "mnooonoooonooonm",
      "mnooonoooonooonm",
      "mnnnnnnnnnnnnnnm",
      "mnnnnnoooonooonm",
      "mnnnnnoooonooonm",
      "mpppnnoooonooonm",
      "mqqqnnnnnnnnnnnm",
      "mmmmmmmmmmmmmmma"
    ],
    [
      "f              f",
      "                ",
      "                ",
      "                ",
      "                ",
      "                ",
      "                ",
      "                ",
      "f              f",
      "                ",
      "                ",
      "                ",
      "                ",
      "                ",
      "                ",
      "                "
    ]
  ]
}