{
  "name": "multi_thering_16_floor4",
  "refpalette": "deceasedcraft:multi_thering_16/multi_thering_16_floor4_palette",
  "xsize": 16,
  "zsize": 16,
  "slices": [
    [
      "abbbbbbbbbbbbbbb",
      "bcccccccccbccccb",
      "bcccccccccbccccb",
      "bcccdddcccbccccb",
      "bcccdddccbdddccb",
      "bbbbbbbbcbdddccb",
      "beeeeeeeeebccccb",
      "beeeeeeefecccccb",
      "beeebbbeeebccccb",
      "beeeeggbcbbbbbbb",
      "beeebghbccddcccb",
      "bieebj bccddcccb",
      "b   b  bccddcccb",
      "b   b  bcccccccb",
      "b   b  bcccccccb",
      "bbbbbbbbbbbbbbba"
    ],
    [
      "akkkkkkkkkkkkkkb",
      "kl       mbn  lk",
      "k   o o  pbqr  k",
      "k stuw x yboo  k",
      "kABtC DE bF I  k",
      "kbbbbbbbJbKL M k",
      "kN        bOP  k",
      "kN        Q    k",
      "k   bbb   bRSTUk",
      "k    V bWbbbbbbk",
      "kXYZb  b m0 M12k",
      "kb33b4 b p5 M6 k",
      "k   bj b yF7   k",
      "k   b  b UOP   k",
      "k   b  b      lk",
      "bkkkkkkkkkkkkkka"
    ],
    [
      "akkkkkkkkkkkkkkb",
      "k!        b8  9k",
      "k   o o   b    k",
      "k  t #$% ^boo  k",
      "k8 t & * b ()  k",
      "kbbbbbbb+b  &M k",
      "k         b-[  k",
      "k         ]    k",
      "k   bbb   b   Uk",
      "k    { b}bbbbbbk",
      "k |;b  b   :M 'k",
      "kb  b  b < $M  k",
      "k   b4 b < >   k",
      "k   bj,b U [   k",
      "k   b  b      .k",
      "bkkkkkkkkkkkkkka"
    ],
    [
      "akkkkkkkkkkkkkkb",
      "k        ?b    k",
      "k   ooo  /b    k",
      "k  t   ` \u0370boo  k",
      "k  t \u0371 \u0372 b   M k",
      "kbbbbbbbgb  \u0371M k",
      "k         b\u0373\u0374  k",
      "k    \u0375    g    k",
      "k   bbb   b\u0376\u0377\u037aUk",
      "k   \u037b\u037c bgbbbbbbk",
      "k \u037d\u037db  b \u037e \u037fM  k",
      "kb\u0384\u0384b  b \u0385  M  k",
      "k   b \u0386b \u0387  M  k",
      "k   b4gb U\u0373\u0374   k",
      "k   bjjb       k",
      "bkkkkkkkkkkkkkka"
    ],
    [
      "akkkkkkkkkkkkkkb",
      "k         b    k",
      "k   \u0388\u0388\u0388  <b    k",
      "k  \u0389\u038a\u038a\u038a\u038c  b\u0388\u0388  k",
      "k  \u0389\u038a\u038a\u038a\u038c b\u038a\u038a\u038a\u038c k",
      "kbbbbbbbbb\u038a\u038a\u038a\u038c k",
      "k         b\u038e\u038e  k",
      "k         b    k",
      "k   bbb   b  \u038f\u038fk",
      "k   b  bbbbbbbbk",
      "k   b  b \u0389\u038a\u038a\u038c  k",
      "kbbbb \u0386b \u0389\u038a\u038a\u038c  k",
      "k   b hb \u0389\u038a\u038a\u038c  k",
      "k   b  b  \u038e\u038e   k",
      "k   b  b       k",
      "bkkkkkkkkkkkkkka"
    ],
    [
      "akkkkkkkkkkkkkkb",
      "k\u0390\u0390\u0390\u0390\u0390\u0390\u0390\u0390\u0390b\u0390\u0390\u0390\u0390k",
      "k\u0390\u038a\u038a\u038a\u038a\u038a\u038a\u038a\u038ab\u038a\u038a\u038a\u0390k",
      "k\u0390\u038a\u038a   \u038a\u038a\u038ab\u038a\u038a\u038a\u0390k",
      "k\u0390\u038a\u038a \u0391\u0391\u038a\u038ab\u0391  \u038a\u0390k",
      "kbbbbbbbbb\u0391  \u038a\u0390k",
      "k\u0392\u0392\u0392\u0392\u0392\u0392\u0392\u0392\u0392b\u038a\u038a\u038a\u0390k",
      "k\u0392\u0392\u0392\u0392\u0392\u0392\u0392!\u0392b\u038a\u038a\u038a\u0390k",
      "k\u0392\u0392\u0392bbb\u0392\u0392\u0392b\u038a\u038a\u038a\u0390k",
      "k\u0392\u0392\u0392b  bbbbbbbbk",
      "k\u0392\u0392\u0392b,\u0386b\u038a\u038a\u0391\u0391\u038a\u038a\u0390k",
      "kbbbb hb\u038a\u038a  \u038a\u038a\u0390k",
      "k   b  b\u038a\u038a  \u038a\u038a\u0390k",
      "k   b  b\u038a\u038a\u038a\u038a\u038a\u038a\u0390k",
      "k   b  b\u0390\u0390\u0390\u0390\u0390\u0390\u0390k",
      "bkkkkkkkkkkkkkka"
    ]
  ]
}