{
  "name": "multi_thering_16_floor12",
  "refpalette": "deceasedcraft:multi_thering_16/multi_thering_16_floor12_palette",
  "xsize": 16,
  "zsize": 16,
  "slices": [
    [
      "abbbbbbbbbbbbbbb",
      "bccccccccccccddb",
      "bccccccccccccddb",
      "bccccccccccccddb",
      "bccccccccccccddb",
      "bbbbbbbbcbbbbbbb",
      "beeeeeeeeebccccb",
      "beeeeeeefebccccb",
      "beeebbbeeebccccb",
      "beeeeggbcbbccccb",
      "beeebghbcccccccb",
      "bieebj bcccccccb",
      "b   b  bcccccccb",
      "b   b  bddddcccb",
      "b   b  bddddcccb",
      "bbbbbbbbbbbbbbba"
    ],
    [
      "akkkkkkkkkkkkkkb",
      "klm     noppqrsk",
      "k   tuw no  x  k",
      "k yyA!B  C  DE k",
      "kFIIFuJ     KLMk",
      "kbbbbbbbNbbbbbbk",
      "kO        bP  Qk",
      "kO        bRS mk",
      "k   bbb   bRS  k",
      "k    T bUbbPVW k",
      "kXYZb  b 01123 k",
      "kb44b5 b 676 8 k",
      "k   bj b9 99   k",
      "k   b  b#$  %  k",
      "k   b  b^&rs*((k",
      "bkkkkkkkkkkkkkka"
    ],
    [
      "akkkkkkkkkkkkkkb",
      "k )      +- [  k",
      "k    ]{      } k",
      "k    ]|      ; k",
      "k:  :]|   ''K  k",
      "kbbbbbbb<bbbbbbk",
      "k         b>   k",
      "k        ,b   .k",
      "k   bbb   b    k",
      "k    ? b/bb: ` k",
      "k \u0370\u0371b  b \u0372!\u0373\u0373] k",
      "kb  b  b       k",
      "k   b5 b9 99   k",
      "k   bj\u0374b \u0375 \u0376   k",
      "k   b  b''  \u0377\u037a k",
      "bkkkkkkkkkkkkkka"
    ],
    [
      "akkkkkkkkkkkkkkb",
      "k           \u037b  k",
      "k    ]\u037c     \u037d\u037e k",
      "k    ]\u037f     K  k",
      "k    ]\u0384     K  k",
      "kbbbbbbbgbbbbbbk",
      "k         b    k",
      "k        \u0385b    k",
      "k   bbb   b    k",
      "k   \u0386\u0387 bgbb]]] k",
      "k \u0388\u0388b  b \u0389\u038a\u038a\u038c] k",
      "kb\u038e\u038eb  b       k",
      "k   b \u038fb9999   k",
      "k   b5gb   \u0390\u0391  k",
      "k   bjjb    \u0392  k",
      "bkkkkkkkkkkkkkka"
    ],
    [
      "akkkkkkkkkkkkkkb",
      "k           \u0393  k",
      "k           \u0393  k",
      "k           \u0393  k",
      "k           \u0393  k",
      "kbbbbbbbbbbbbbbk",
      "k         b    k",
      "k         b    k",
      "k   bbb   b    k",
      "k   b  bbbb    k",
      "k   b  b \u0394\u0394    k",
      "kbbbb \u038fb       k",
      "k   b hb\u0395\u0395\u0395\u0395   k",
      "k   b  b   \u0393   k",
      "k   b  b   \u0393   k",
      "bkkkkkkkkkkkkkka"
    ],
    [
      "akkkkkkkkkkkkkkb",
      "k\u0396\u0396\u0396\u0396\u0396\u0396\u0396\u0396\u0396\u0396\u0396\u0396\u0397\u0397k",
      "k\u0396\u0396\u0396\u0396\u0396\u0396\u0396\u0396\u0396\u0396\u0396\u0396\u0397\u0397k",
      "k\u0396\u0396\u0396\u0396\u0396\u0396\u0396\u0396\u0396\u0396\u0396\u0396\u0397\u0397k",
      "k\u0396\u0396\u0396\u0396\u0396\u0396\u0396\u0396\u0396\u0396\u0396\u0396\u0397\u0397k",
      "kbbbbbbbbbbbbbbk",
      "k\u0398\u0398\u0398\u0398\u0398\u0398\u0398\u0398\u0398b\u0396\u0396\u0396\u0396k",
      "k\u0398\u0398\u0398\u0398\u0398\u0398\u0398\u0399\u0398b\u0396\u0396\u0396\u0396k",
      "k\u0398\u0398\u0398bbb\u0398\u0398\u0398b\u0396\u0396\u0396\u0396k",
      "k\u0398\u0398\u0398b  bbbb\u0396\u0396\u0396\u0396k",
      "k\u0398\u0398\u0398b\u0374\u038fb\u0396\u0396\u0396\u0396\u0396\u0396\u0396k",
      "kbbbb hb\u0396\u0396\u0396\u0396\u0396\u0396\u0396k",
      "k   b  b\u0396\u0396\u0396\u0396\u0396\u0396\u0396k",
      "k   b  b\u0397\u0397\u0397\u0397\u0396\u0396\u0396k",
      "k   b  b\u0397\u0397\u0397\u0397\u0396\u0396\u0396k",
      "bkkkkkkkkkkkkkka"
    ]
  ]
}