{
  "name": "multi_thering_16_floor14",
  "refpalette": "deceasedcraft:multi_thering_16/multi_thering_16_floor14_palette",
  "xsize": 16,
  "zsize": 16,
  "slices": [
    [
      "abbbbbbbbbbbbbbb",
      "bccccccccccccccb",
      "bddddddddddddccb",
      "bcccccccccccddcb",
      "bddddddddddccdcb",
      "beeeeeeeeeddcdcb",
      "bffffffffeedcdcb",
      "bfffffffffedcdcb",
      "bfffffffffedcdcb",
      "bffffggfffedcdcb",
      "bffff hfffedcdcb",
      "bijjb  fffedcdcb",
      "b   b  fffedcdcb",
      "b   b  fffedcdcb",
      "b   b  fffedcdcb",
      "bbbbbbbbbbbbbbba"
    ],
    [
      "akkkkkkkkkkkkkkb",
      "lmmmmmmmmmmmmmmn",
      "lddddddddddddmmn",
      "opppppppppppddmn",
      "oqqqqqqqqqqppdmn",
      "orsssrssssqqpdmn",
      "o tu  tu rsqpdmn",
      "o         sqpdmn",
      "o        wsqpdmn",
      "o      x ysqpdmn",
      "oABCoD x  rqpdmn",
      "obEEb  x  sqpdmn",
      "F   b  x wsqpdmn",
      "F   b  x ysqpdmn",
      "F   b  x  rqpdmn",
      "bFFFDDDDDDDDDIIa"
    ],
    [
      "aJJJJJJJJJJJJJJb",
      "oKKKKKKKKKKKKKLx",
      "o            KKx",
      "              Kx",
      "              Kx",
      " M   M        Kx",
      "         M    Kx",
      "              Kx",
      "              Kx",
      "              Kx",
      "  NO      M   Kx",
      " b  b         Kx",
      "F   b         Kx",
      "F   b         Kx",
      "F   b     M   Kx",
      "bFFF         DDa"
    ],
    [
      "a              b",
      "                ",
      "                ",
      "                ",
      "                ",
      " P   P          ",
      "         P      ",
      "                ",
      "                ",
      "                ",
      "  QR      P     ",
      " bSSb           ",
      "F   b           ",
      "F   b           ",
      "F   b     P     ",
      "bFFF           a"
    ],
    [
      "a              b",
      "                ",
      "                ",
      "                ",
      "                ",
      "                ",
      "                ",
      "                ",
      "                ",
      "                ",
      "                ",
      " bbbb           ",
      "F   b           ",
      "F   b           ",
      "F   b           ",
      "bFFF           a"
    ],
    [
      "a              b",
      "                ",
      "                ",
      "                ",
      "                ",
      "                ",
      "                ",
      "                ",
      "                ",
      "                ",
      "                ",
      " bbbb           ",
      "F   b           ",
      "F   b           ",
      "F   b           ",
      "bFFF           a"
    ]
  ]
}