{
  "name": "multi_thering_16_floor10",
  "refpalette": "deceasedcraft:multi_thering_16/multi_thering_16_floor10_palette",
  "xsize": 16,
  "zsize": 16,
  "slices": [
    [
      "abbbbbbbbbbbbbbc",
      "b              b",
      "b              b",
      "b              b",
      "b              b",
      "b              b",
      "b              b",
      "b              b",
      "b   ccc        b",
      "b   cddc       b",
      "b   cdec       b",
      "bccccf c       b",
      "b   c  c       b",
      "b   c  c       b",
      "b   c  c       b",
      "cbbbbbbbbbbbbbba"
    ],
    [
      "abbbbbbbbbbbbbbc",
      "b              b",
      "b              b",
      "b              b",
      "b              b",
      "b              b",
      "b              b",
      "b       g      b",
      "b   ccc        b",
      "b   c  c       b",
      "b   c  c       b",
      "bcccch c       b",
      "b   cf c       b",
      "b   c  c       b",
      "b   c  c       b",
      "cbbbbbbbbbbbbbba"
    ],
    [
      "abbbbbbbbbbbbbbc",
      "b              b",
      "b              b",
      "b              b",
      "b              b",
      "b              b",
      "b              b",
      "b      gg      b",
      "b   ccc        b",
      "b   c  c       b",
      "b   c  c       b",
      "bcccc  c       b",
      "b   ch c       b",
      "b   cfic       b",
      "b   c  c       b",
      "cbbbbbbbbbbbbbba"
    ],
    [
      "abbbbbbbbbbbbbbc",
      "b              b",
      "b              b",
      "b              b",
      "b              b",
      "b              b",
      "b              b",
      "b      gg      b",
      "b   ccc g      b",
      "b   c  c       b",
      "b   c  c       b",
      "bcccc  c       b",
      "b   c jc       b",
      "b   chdc       b",
      "b   cffc       b",
      "cbbbbbbbbbbbbbba"
    ],
    [
      "abbbbbbbbbbbbbbc",
      "b              b",
      "b              b",
      "b              b",
      "b              b",
      "b              b",
      "b      kk      b",
      "b     kllk     b",
      "b   cccllk     b",
      "b   c  ck      b",
      "b   c  c       b",
      "bcccc jc       b",
      "b   c ec       b",
      "b   c  c       b",
      "b   c  c       b",
      "cbbbbbbbbbbbbbba"
    ],
    [
      "abbbbbbbbbbbbbbc",
      "bmmmmmmmmmmmmmmb",
      "bmmmmmmmmmmmmmmb",
      "bmmmmmmmmmmmmmmb",
      "bmmmmmnnnnmmmmmb",
      "bmmmmnoooonmmmmb",
      "bmmmnooppoonmmmb",
      "bmmmnopqqponmmmb",
      "bmmmcccqqponmmmb",
      "bmmmc  cpoonmmmb",
      "bmmmcijcoonmmmmb",
      "bcccc ecnnmmmmmb",
      "b   c  cmmmmmmmb",
      "b   c  cmmmmmmmb",
      "b   c  cmmmmmmmb",
      "cbbbbbbbbbbbbbba"
    ]
  ]
}