{
  "name": "multi_thering_16_base1",
  "refpalette": "deceasedcraft:multi_thering_16/multi_thering_16_base1_palette",
  "xsize": 16,
  "zsize": 16,
  "slices": [
    [
      "a bcdcefghgihj k",
      "l              k",
      "l              k",
      "l             mk",
      "n             ok",
      "              pk",
      "      q       pk",
      "              dk",
      "n             ok",
      "l             mk",
      "l rr          ok",
      "lkssk  t      ck",
      "luw k  t      dk",
      "l   kx t      pk",
      "l  ykABt      ok",
      "kkkkkkkkkkkkkkkC"
    ],
    [
      "a  DDDDDDDDDD  k",
      "l              k",
      "l              k",
      "l              k",
      "n             Ek",
      "              Ek",
      "              Ek",
      "              Ek",
      "n             Ek",
      "l              k",
      "l             Ek",
      "lkkkk  t      Ek",
      "luw k  t      Ek",
      "l   k Ft      Ek",
      "l  IkxAt      Ek",
      "kkkkkkkkkkkkkkkC"
    ],
    [
      "a              k",
      "l              k",
      "l              k",
      "l              k",
      "n              k",
      "               k",
      "               k",
      "               k",
      "n              k",
      "l              k",
      "l              k",
      "lkkkk  t       k",
      "lJKKk Ft       k",
      "lJJJk Lt       k",
      "lJJJk  t       k",
      "kkkkkkkkkkkkkkkC"
    ],
    [
      "a              k",
      "l              k",
      "l              k",
      "l              k",
      "n              k",
      "               k",
      "               k",
      "               k",
      "n              k",
      "l              k",
      "l              k",
      "lkkkk Ft       k",
      "l   k Lt       k",
      "l   k  t       k",
      "l   k  t       k",
      "kkkkkkkkkkkkkkkC"
    ],
    [
      "a              k",
      "l              k",
      "l              k",
      "l              k",
      "n              k",
      "               k",
      "               k",
      "               k",
      "n              k",
      "l              k",
      "l     F        k",
      "lkkkk Lt       k",
      "l   k  t       k",
      "l   k  t       k",
      "l   k  t       k",
      "kkkkkkkkkkkkkkkC"
    ],
    [
      "aMMMMMMMMMMMMMMk",
      "lAAAAAAAAAAAAAAk",
      "lAAAAAAAAAAAAAAk",
      "lAAAAAAAAAAAAAAk",
      "nMMMMMMMMAAAAAAk",
      "nnnnnnnnnMAAAAAk",
      "NNNNNNNNnnMAAAAk",
      "nnnnnnnnNnnMAAAk",
      "nMMMMMMnnNnMAAAk",
      "lAAAAAAMnNnMAAAk",
      "lOOOOOLMnNnMAAAk",
      "lkkkk  PnNnMAAAk",
      "l   k  PnNnMAAAk",
      "l   k  PnNnMAAAk",
      "l   k  PnNnMAAAk",
      "kkkkkkkkkkkkkkkC"
    ]
  ]
}