{
  "name": "multi_thering_16_base2",
  "refpalette": "deceasedcraft:multi_thering_16/multi_thering_16_base2_palette",
  "xsize": 16,
  "zsize": 16,
  "slices": [
    [
      "abbbbbbbbbbbbbbb",
      "bbbbbbbbbbbbbbbb",
      "bbbbbbbbbbbbbbbb",
      "bbbbbbbbbbbbbbbb",
      "bbbbbbbbbbbbbbbb",
      "bbbbbbbbbbbbbbbb",
      "bbbbbbbbbbbbbbbb",
      "bbbbbbbbbbbbbbbb",
      "bbbbbbbbbbbbbbbb",
      "bbbbbbbbbbbbbbbb",
      "bbbbbbbbbbbbbbbb",
      "bbbbbbbbbbbbbbbb",
      "bbbbbbbbbbbbbbbb",
      "bbbbbbbbbbbbbbbb",
      "bbbbbbbbbbbbbbbb",
      "bbbbbbbbbbbbbbba"
    ],
    [
      "abbbbbbbbbbbbbbb",
      "bbbbbbbbbbbbbbbb",
      "bbbbbbbbbbbbbbbb",
      "bbbbbbbbbbbbbbbb",
      "bbbbbbbbbbbbbbbb",
      "bbbbbbbbbbbbbbbb",
      "bbbbbbbbbbbbbbbb",
      "bbbbbbbbbbbbbbbb",
      "bbbbbbbbbbbbbbbb",
      "bbbbbbbbbbbbbbbb",
      "bbbbbbbbbbbbbbbb",
      "bbbbbbbbbbbbbbbb",
      "bbbbbbbbbbbbbbbb",
      "bbbbbbbbbbbbbbbb",
      "bbbbbbbbbbbbbbbb",
      "bbbbbbbbbbbbbbba"
    ],
    [
      "accccccccccccccc",
      "cccccccccccccccc",
      "cccccccccccccccc",
      "cccccccccccccccc",
      "cccccccccccccccc",
      "cccccccccccccccc",
      "cccccccccccccccc",
      "cccccccccccccccc",
      "cccccccccccccccc",
      "cccccccccccccccc",
      "cccccccccccccccc",
      "cccccccccccccccc",
      "cccccccccccccccc",
      "cccccccccccccccc",
      "cccccccccccccccc",
      "ccccccccccccccca"
    ],
    [
      "deeffffffffffeed",
      "deeeeeeeeeeeeeed",
      "deeeeeeeeeeeeeed",
      "deeeeeeeeeeeeeed",
      "deeeeeeeeeffeeed",
      "geeeefffeeffeeed",
      "geeeefhfeeffeeed",
      "geeeefffeeffeeed",
      "deeeeeeeeeffeeed",
      "deeeeeeeeeffeeed",
      "deeeeeeeeeffeeed",
      "dijjdkeeeeffeeed",
      "dlmmdkeeeeeeeeed",
      "dmnmdkeeeeeeeeed",
      "dmmmdke!eeeeeeed",
      "ddddddddddddddda"
    ],
    [
      "o  ppqqrrrsrs  d",
      "t              d",
      "t              d",
      "t         uw  xd",
      "y         AB  Cd",
      "     DDD  EF  Id",
      "     DxD  AB  Id",
      "     DDD  EF  Jd",
      "y         AB  Cd",
      "t         EF  xd",
      "tKLM      AB  Cd",
      "tdNNdO P  EF  Qd",
      "tRS dk P  TU  Jd",
      "t   dk P      Id",
      "t  Vdk P     WCd",
      "ddddddddddddddda"
    ],
    [
      "o X          Y d",
      "t              d",
      "t              d",
      "t             Zd",
      "y         01  Cd",
      "      2   34   d",
      "     567  89   d",
      "      #   84   d",
      "y         01  Cd",
      "t         34  Zd",
      "t $%      31  Cd",
      "td  d  P  89   d",
      "t^S dO P       d",
      "t   dk P       d",
      "t  &dk P  *(  Cd",
      "ddddddddddddddda"
    ]
  ]
}