{
  "name": "multi_thering_16_floor6",
  "refpalette": "deceasedcraft:multi_thering_16/multi_thering_16_floor6_palette",
  "xsize": 16,
  "zsize": 16,
  "slices": [
    [
      "abbbbbbbbbbbbbbb",
      "bccccccccccccccb",
      "bcdddddcddddddcb",
      "bcdddddcddddddcb",
      "bcdddddcddddddcb",
      "bcdddddcddddddcb",
      "bcdddddcddddddcb",
      "bcdddddcddddddcb",
      "bceebbbfcccccccb",
      "bceebggbddddddcb",
      "bceebghbddddddcb",
      "bbbbbi bddddddcb",
      "b   b  bddddddcb",
      "b   b  bddddddcb",
      "b   b  bcccccccb",
      "bbbbbbbbbbbbbbba"
    ],
    [
      "a               ",
      " jjjjjjjjjjjjjj ",
      " jjjjjjjjjjjjjj ",
      " jjjjjjjjjjjjjj ",
      " jjjjjjjjjjjjjj ",
      " jjjjjjjjjjjjjj ",
      " jjjjjjjjjjjjjj ",
      " jjjjjjjjjjjjjj ",
      " jeebbbkjjjjjjj ",
      " jeeb  bjjjjjjj ",
      " jeeb  bjjjjjjj ",
      "bbbbbl bjjjjjjj ",
      "m   bi bjjjjjjj ",
      "m   b  bjjjjjjj ",
      "m   b  bjjjjjjj ",
      "bmmmmmmb       a"
    ],
    [
      "a               ",
      "                ",
      "                ",
      "                ",
      "                ",
      "                ",
      "                ",
      "                ",
      "  nnbbb         ",
      "  nnb  b        ",
      "  nnb  b        ",
      "bbbbb  b        ",
      "m   bl b        ",
      "m   biob        ",
      "m   b  b        ",
      "bmmmmmmb       a"
    ],
    [
      "a               ",
      "                ",
      "                ",
      "                ",
      "                ",
      "                ",
      "                ",
      "                ",
      "    bbb         ",
      "    b  b        ",
      "    b  b        ",
      "bbbbb  b        ",
      "m   b pb        ",
      "m   blgb        ",
      "m   biib        ",
      "bmmmmmmb       a"
    ],
    [
      "aqqqqqqqqqqqqqr ",
      "qqqqqqqqqqqqqqqr",
      "rrqqqqqqqqqqqqqq",
      "  rqqqqqqqqqqqqq",
      "   rrqqqqqqqqqqq",
      "     rqqqqqqqqqq",
      "      rqqqqqqqqq",
      "       rqqqqqqqq",
      "    bbb rqqqqqqq",
      "    b  b rqqqqqq",
      "    b  b  rqqqqq",
      "bbbbb pb   rqqqq",
      "m   b hb   rqqqq",
      "m   b  b    rqqq",
      "m   b  b     rqq",
      "bmmmmmmb     rqa"
    ],
    [
      "asssttttssssqqqq",
      "ssssstttttsssqqq",
      "uuwstststttsssqq",
      "   wssstttttsssq",
      "    uwsstttttsss",
      "      wsststtsss",
      "       wssstttss",
      "        wssststs",
      "    bbb  wssttts",
      "    b  b  wsstts",
      "    bopb   wsttt",
      "bbbbb hb   xsstt",
      "m   b  b    wsss",
      "m   b  b     wst",
      "m   b  b     xss",
      "bmmmmmmb     xsa"
    ]
  ]
}