{
  "name": "multi_thering_16_floor7",
  "refpalette": "deceasedcraft:multi_thering_16/multi_thering_16_floor7_palette",
  "xsize": 16,
  "zsize": 16,
  "slices": [
    [
      "a         bcddee",
      "             dde",
      "ffg         b dd",
      "hhig          cd",
      "hhhifg         b",
      "hhhhhig       b ",
      "hhhhhhig        ",
      "hhhhhhhjk       ",
      "lhhhlhlddd      ",
      "lhhhlmml dd     ",
      "lhhhlmnl  dd    ",
      "lopplq l   d    ",
      "l   l  l   dd   ",
      "l   l  l    dd  ",
      "l   l  l     d  ",
      "lrrrrrrl     d a"
    ],
    [
      "a         st  uu",
      "               u",
      "            s   ",
      "              t ",
      "               s",
      "              s ",
      "                ",
      "                ",
      "w   l lwxx      ",
      "x   ly l xx     ",
      "xABCl  l  xx    ",
      "llDDlE l   x    ",
      "r   lq l   xw   ",
      "r   l  l    xx  ",
      "r   l  l     x  ",
      "lrrrrrrl     x a"
    ],
    [
      "a         Fs    ",
      "                ",
      "            F   ",
      "              s ",
      "               F",
      "              F ",
      "                ",
      "                ",
      "    l l         ",
      "    lI l        ",
      "  JKl  l        ",
      "ll  l  l        ",
      "r   lE l        ",
      "r   lqLl        ",
      "r   l  l        ",
      "lrrrrrrl       a"
    ],
    [
      "a         FF    ",
      "                ",
      "            F   ",
      "              F ",
      "               F",
      "              F ",
      "                ",
      "                ",
      "    lMl         ",
      "    lN l        ",
      "  OPl  l        ",
      "llQQl  l        ",
      "r   l Rl        ",
      "r   lEml        ",
      "r   lqql        ",
      "lrrrrrrl       a"
    ],
    [
      "a         SF    ",
      "                ",
      "            S   ",
      "              F ",
      "               S",
      "              F ",
      "                ",
      "                ",
      "    lll         ",
      "    l  l        ",
      "    l  l        ",
      "lllll Rl        ",
      "r   l nl        ",
      "r   l  l        ",
      "r   l  l        ",
      "lrrrrrrl       a"
    ],
    [
      "a          S    ",
      "                ",
      "                ",
      "              S ",
      "                ",
      "              S ",
      "                ",
      "                ",
      "    lll         ",
      "    l  l        ",
      "    lLRl        ",
      "lllll nl        ",
      "r   l  l        ",
      "r   l  l        ",
      "r   l  l        ",
      "lrrrrrrl       a"
    ]
  ]
}