{
  "name": "multi_thering_16_floor5",
  "refpalette": "deceasedcraft:multi_thering_16/multi_thering_16_floor5_palette",
  "xsize": 16,
  "zsize": 16,
  "slices": [
    [
      "abbbbbbbbbbbbbbb",
      "bccccccccccccccb",
      "bcdc!ccccccccccb",
      "bccccccccccccccb",
      "bccccccccccccccb",
      "bccccccccccccccb",
      "bccccccccccccccb",
      "bcccccccccc!cccb",
      "bccccccccccccccb",
      "bcccbeebbbbbbccb",
      "bcccbefbcccggccb",
      "bhiibj bcccggccb",
      "b   b  bcccggccb",
      "b   b  bcccggccb",
      "b   b  bcccccccb",
      "bbbbbbbbbbbbbbba"
    ],
    [
      "akkkkkkkkkkkkkkb",
      "k            lmk",
      "k n n  o   p lmk",
      "k q q rst  u  mk",
      "k q q  w  xyx lk",
      "k          A   k",
      "kB             k",
      "kB       C C   k",
      "k              k",
      "k   bDEbbbbbbF k",
      "kIJKb  bL M NO k",
      "kbPPbQ bL RSST k",
      "k   bj bL M  T k",
      "k   b  bL RSSO k",
      "k   b  bB      k",
      "bkkkkkkkkkkkkkka"
    ],
    [
      "akkkkkkkkkkkkkkb",
      "k              k",
      "k     UVW      k",
      "k      p       k",
      "k        mXYXm k",
      "k          A   k",
      "k              k",
      "k              k",
      "k       Z001   k",
      "k   b23bbbbbbF k",
      "k 45b  b  678  k",
      "kb  b  b  RSS9 k",
      "k   bQ b# 6789 k",
      "k   bj$b  RSS% k",
      "k   b  b       k",
      "bkkkkkkkkkkkkkka"
    ],
    [
      "akkkkkkkkkkkkkkb",
      "k              k",
      "k              k",
      "k              k",
      "k              k",
      "k              k",
      "k              k",
      "k              k",
      "k              k",
      "k   b^&bbbbbb  k",
      "k **b  b( R )+ k",
      "kb--b  b[ RSS] k",
      "k   b {b} R )] k",
      "k   bQeb} RSS| k",
      "k   bjjb       k",
      "bkkkkkkkkkkkkkka"
    ],
    [
      "akkkkkkkkkkkkkkb",
      "k              k",
      "k              k",
      "k              k",
      "k              k",
      "k              k",
      "k              k",
      "k              k",
      "k              k",
      "k   b;:bbbbbb  k",
      "k   b  b  '<<> k",
      "kbbbb {b  '<<> k",
      "k   b fb  '<<> k",
      "k   b  b  '<<> k",
      "k   b  b,,,,,  k",
      "bkkkkkkkkkkkkkka"
    ],
    [
      "akkkkkkkkkkkkkkb",
      "k..............k",
      "k.????????????.k",
      "k.????????????.k",
      "k.????????????.k",
      "k.????????????.k",
      "k.????????????.k",
      "k.????????????.k",
      "k.????????????.k",
      "k.??b/`bbbbbb?.k",
      "k.??b${b??? \u0370?.k",
      "kbbbb fb???  ?.k",
      "k   b  b??? \u0370?.k",
      "k   b  b??????.k",
      "k   b  b.......k",
      "bkkkkkkkkkkkkkka"
    ]
  ]
}