{
  "name": "multi_thering_16_floor13",
  "refpalette": "deceasedcraft:multi_thering_16/multi_thering_16_floor13_palette",
  "xsize": 16,
  "zsize": 16,
  "slices": [
    [
      "abbbbbbbbbbbbbbb",
      "bccccccccccccddb",
      "bccccccccccccddb",
      "bccccccccccccddb",
      "bccccccccccccddb",
      "bbbbbbbbcbbbbbbb",
      "beeeeeeeeebccccb",
      "beeeeeeefebccccb",
      "beeebbbeeebccccb",
      "beeeeggbcbbccccb",
      "beeebghbcccccccb",
      "bieebj bcccccccb",
      "b   b  bcccccccb",
      "b   b  bddddcccb",
      "b   b  bddddcccb",
      "bbbbbbbbbbbbbbba"
    ],
    [
      "akkkkkkkkkkkkkkb",
      "klm     noppqrsk",
      "k   tuw no  x  k",
      "k yyABC  D   E k",
      "kFIIFuJ     KL k",
      "kbbbbbbbMbbbbbbk",
      "kN        bOP Qk",
      "kN        bOPmnk",
      "k   bbb   bRSF k",
      "k    T bUbbVWXYk",
      "kZ01b  b2334567k",
      "kb88b9 b # $   k",
      "k   bj b% %%Y ^k",
      "k   b  b&*  (  k",
      "k   b  b) rs+--k",
      "bkkkkkkkkkkkkkka"
    ],
    [
      "akkkkkkkkkkkkkkb",
      "k [      ] {}  k",
      "k    6|  ;   : k",
      "k    6       ' k",
      "kQ  <6    >>K ,k",
      "kbbbbbbb.bbbbbbk",
      "k         b    k",
      "k        ?b  Y k",
      "k   bbb   b  / k",
      "k    ` b\u0370bbQ \u0371 k",
      "k \u0372\u0373b  bYn\u0374\u0375\u03756 k",
      "kb  b  b       k",
      "k   b9 b% %%   k",
      "k   bj\u0376b \u0377 \u037a   k",
      "k   b  b>   \u037b$ k",
      "bkkkkkkkkkkkkkka"
    ],
    [
      "akkkkkkkkkkkkkkb",
      "k           \u037c  k",
      "k    6\u037d     \u037e\u037f k",
      "k    6\u0384     K  k",
      "k    6\u0385     K  k",
      "kbbbbbbbgbbbbbbk",
      "k         b    k",
      "k        \u0386b    k",
      "k   bbb   b    k",
      "k   \u0387\u0388 bgbb666 k",
      "k \u0389\u038ab  b \u038c\u038e\u038e\u038f6 k",
      "kb\u0390\u0390b  b       k",
      "k   b \u0391b%%%%   k",
      "k   b9gb   \u0392\u0393  k",
      "k   bjjb    \u0394  k",
      "bkkkkkkkkkkkkkka"
    ],
    [
      "akkkkkkkkkkkkkkb",
      "k           \u0395  k",
      "k     \u0396     \u0395  k",
      "k     \u0396     \u0395  k",
      "k           \u0395  k",
      "kbbbbbbbbbbbbbbk",
      "k         b    k",
      "k         b    k",
      "k   bbb   b\u0397   k",
      "k   b  bbbb\u0398Y  k",
      "k   b  b \u039966\u039a\u037b k",
      "kbbbb \u0391b       k",
      "k   b hb\u039b\u039b\u039b\u039b   k",
      "k   b  b   \u0395   k",
      "k   b  b   \u0395   k",
      "bkkkkkkkkkkkkkka"
    ],
    [
      "akkkkkkkkkkkkkkb",
      "k\u039c\u039c\u039c\u039c\u039c\u039c\u039c\u039c\u039c\u039c\u039c\u039c\u039d\u039dk",
      "k\u039c\u039c\u039c\u039c\u039c\u039c\u039c\u039c\u039c\u039c\u039c\u039c\u039d\u039dk",
      "k\u039c\u039c\u039c\u039c\u039c\u039c\u039c\u039c\u039c\u039c\u039c\u039c\u039d\u039dk",
      "k\u039c\u039c\u039c\u039c\u039c\u039c\u039c\u039c\u039c\u039c\u039c\u039c\u039d\u039dk",
      "kbbbbbbbbbbbbbbk",
      "k\u039e\u039e\u039e\u039e\u039e\u039e\u039e\u039e\u039eb\u039c\u039c\u039c\u039ck",
      "k\u039e\u039e\u039e\u039e\u039e\u039e\u039e!\u039eb\u039c\u039c\u039c\u039ck",
      "k\u039e\u039e\u039ebbb\u039e\u039e\u039eb\u039c\u039c\u039c\u039ck",
      "k\u039e\u039e\u039eb  bbbb\u039c\u039c\u039c\u039ck",
      "k\u039e\u039e\u039eb \u0391b\u039c\u039c\u039c\u039c\u039c\u039c\u039ck",
      "kbbbb hb\u039c\u039c\u039c\u039c\u039c\u039c\u039ck",
      "k   b  b\u039c\u039c\u039c\u039c\u039c\u039c\u039ck",
      "k   b  b\u039d\u039d\u039d\u039d\u039c\u039c\u039ck",
      "k   b  b\u039d\u039d\u039d\u039d\u039c\u039c\u039ck",
      "bkkkkkkkkkkkkkka"
    ]
  ]
}