{
  "name": "multi_thering_16_floor9",
  "refpalette": "deceasedcraft:multi_thering_16/multi_thering_16_floor9_palette",
  "xsize": 16,
  "zsize": 16,
  "slices": [
    [
      "abbbbbbbbbbbbbbb",
      "bccccccccccccccb",
      "bccccccccccccccb",
      "bccccccccccccccb",
      "bccccccccccccccb",
      "bccccccccccccccb",
      "bccccccccccccccb",
      "bccccccddccccccb",
      "ecccbbbddccccccb",
      "eccccffbcccccccb",
      "ecccbfgbcccccccb",
      "bhiibj bcccccccb",
      "b   b  bcccccccb",
      "b   b  bcccccccb",
      "b   b  bcccccccb",
      "bbbbbbbbbbbbbbba"
    ],
    [
      "akkkkkkkkkkkkkkb",
      "klm     n   n  k",
      "kom p  qrp     k",
      "ko  rp  s  qrp k",
      "kom s       s  k",
      "kom            k",
      "kt    uwwu   n k",
      "k     xwww  qrpk",
      "y   bbb!ww   p k",
      "     A bBu     k",
      "CDEFb  b    n  k",
      "kbIIbJ b   qrp k",
      "k   bj b       k",
      "k   b  bK K KK k",
      "k   b  bLMMMMMNk",
      "bkkkkkkkkkkkkkka"
    ],
    [
      "akkkkkkkkkkkkkkb",
      "kO             k",
      "kP      Q      k",
      "k           R  k",
      "kS             k",
      "kT             k",
      "k       U      k",
      "k       V    W k",
      "y   bbb X      k",
      "     Y b       k",
      "C Z0b  b       k",
      "kb  b  b    1  k",
      "k   bJ b       k",
      "k   bj2b       k",
      "k   b  b 34  5 k",
      "bkkkkkkkkkkkkkka"
    ],
    [
      "akkkkkkkkkkkkkkb",
      "k              k",
      "k              k",
      "k              k",
      "k              k",
      "k              k",
      "k              k",
      "k              k",
      "6   bbb        k",
      "7   89 b       k",
      "# $$b  b       k",
      "kb%%b  b       k",
      "k   b ^b       k",
      "k   bJfb       k",
      "k   bjjb       k",
      "bkkkkkkkkkkkkkka"
    ],
    [
      "akkkkkkkkkkkkkkb",
      "k              k",
      "k              k",
      "k              k",
      "k              k",
      "k              k",
      "k              k",
      "k              k",
      "k   bbb        k",
      "k   b  b       k",
      "k   b  b       k",
      "kbbbb ^b       k",
      "k   b gb       k",
      "k   b  b       k",
      "k   b  b       k",
      "bkkkkkkkkkkkkkka"
    ],
    [
      "akkkkkkkkkkkkkkb",
      "k              k",
      "k              k",
      "k              k",
      "k              k",
      "k              k",
      "k              k",
      "k              k",
      "k   bbb        k",
      "k   b  b       k",
      "k   b2^b       k",
      "kbbbb gb       k",
      "k   b  b       k",
      "k   b  b       k",
      "k   b  b       k",
      "bkkkkkkkkkkkkkka"
    ]
  ]
}