{
  "name": "multi_thering_16_floor1",
  "refpalette": "deceasedcraft:multi_thering_16/multi_thering_16_floor1_palette",
  "xsize": 16,
  "zsize": 16,
  "slices": [
    [
      "abbbbbbbbbbbbbbc",
      "b              b",
      "b              b",
      "b              b",
      "b              b",
      "b              b",
      "b              b",
      "b      de      b",
      "b   ccc e      b",
      "b   cffc       b",
      "b   cfgc       b",
      "bcccch c       b",
      "b   c  c       b",
      "b   c  c       b",
      "b   c  c       b",
      "cbbbbbbbbbbbbbba"
    ],
    [
      "abbbbbbbbbbbbbbc",
      "b              b",
      "b              b",
      "b              b",
      "b              b",
      "b              b",
      "b              b",
      "b      ee      b",
      "b   cccde      b",
      "b   c  c       b",
      "b   c  c       b",
      "bcccci c       b",
      "b   ch c       b",
      "b   c  c       b",
      "b   c  c       b",
      "cbbbbbbbbbbbbbba"
    ],
    [
      "abbbbbbbbbbbbbbc",
      "b              b",
      "b              b",
      "b              b",
      "b              b",
      "b              b",
      "b              b",
      "b      ee      b",
      "b   cccee      b",
      "b   c  c       b",
      "b   c  c       b",
      "bcccc  c       b",
      "b   ci c       b",
      "b   chjc       b",
      "b   c  c       b",
      "cbbbbbbbbbbbbbba"
    ],
    [
      "abbbbbbbbbbbbbbc",
      "b              b",
      "b              b",
      "b              b",
      "b              b",
      "b              b",
      "b              b",
      "b      kk      b",
      "b   ccckk      b",
      "b   c  c       b",
      "b   c  c       b",
      "bcccc  c       b",
      "b   c lc       b",
      "b   cifc       b",
      "b   chhc       b",
      "cbbbbbbbbbbbbbba"
    ],
    [
      "abbbbbbbbbbbbbbc",
      "b              b",
      "b              b",
      "b              b",
      "b     mmmm     b",
      "b    mnnnnm    b",
      "b   mnnoonnm   b",
      "b   mnopponm   b",
      "b   cccpponm   b",
      "b   c  connm   b",
      "b   c  cnnm    b",
      "bcccc lcmm     b",
      "b   c gc       b",
      "b   c  c       b",
      "b   c  c       b",
      "cbbbbbbbbbbbbbba"
    ],
    [
      "abbbbbbbbbbbbbbc",
      "bqqqqqqqqqqqqqqb",
      "bqrrrrrrrrrrrrqb",
      "bqrrrrrrrrrrrrqb",
      "bqrrrrrrrrrrrrqb",
      "bqrrrrrrrrrrrrqb",
      "bqrrrrrrrrrrrrqb",
      "bqrrrrrrrrrrrrqb",
      "bqrrcccrrrrrrrqb",
      "bqrrc  crrrrrrqb",
      "bqrrcjlcrrrrrrqb",
      "bcccc gcrrrrrrqb",
      "b   c  crrrrrrqb",
      "b   c  crrrrrrqb",
      "b   c  cqqqqqqqb",
      "cbbbbbbbbbbbbbba"
    ]
  ]
}