{
  "name": "multi_thering_16_floor11",
  "refpalette": "deceasedcraft:multi_thering_16/multi_thering_16_floor11_palette",
  "xsize": 16,
  "zsize": 16,
  "slices": [
    [
      "abbbbbbbbbbbbbbb",
      "bccccccccccccddb",
      "bccccccccccccddb",
      "bccccccccccccddb",
      "bccccccccccccddb",
      "bbbbbbbbcbbbbbbb",
      "beeeeeeeeebccccb",
      "beeeeeeefebccccb",
      "beeebbbeeebccccb",
      "beeeeggbcbbccccb",
      "beeebghbcccccccb",
      "bieebj bcccccccb",
      "b   b  bcccccccb",
      "b   b  bddddcccb",
      "b   b  bddddcccb",
      "bbbbbbbbbbbbbbba"
    ],
    [
      "akkkkkkkkkkkkkkb",
      "klm     noppqrsk",
      "k   tuw xoyAB! k",
      "k CCDEFn I     k",
      "kJKKJuL     AMNk",
      "kbbbbbbbObbbbbbk",
      "kP        bQ  Rk",
      "kP        bST mk",
      "k   bbb   bST  k",
      "k    U bVbbQWX k",
      "kYZ0b  b 1223! k",
      "kb44b5 b  n6 7 k",
      "k   bj b8 88   k",
      "k   b  b9#  $  k",
      "k   b  b% rs^&&k",
      "bkkkkkkkkkkkkkka"
    ],
    [
      "akkkkkkkkkkkkkkb",
      "k *         x  k",
      "k    ()      + k",
      "k    (         k",
      "k-  [(    ]]{  k",
      "kbbbbbbb}bbbbbbk",
      "k         b[   k",
      "k        |b   ;k",
      "k   bbb   b    k",
      "k    : b'bb[ < k",
      "k >,b  b  .??( k",
      "kb  b  b       k",
      "k   b5 b8 88   k",
      "k   bj/b ` \u0370   k",
      "k   b  b]]   \u0371\u0372k",
      "bkkkkkkkkkkkkkka"
    ],
    [
      "akkkkkkkkkkkkkkb",
      "k           \u0373  k",
      "k    (\u0374     \u0375\u0376 k",
      "k    (\u0377     \u037a  k",
      "k    (\u037b     {  k",
      "kbbbbbbbgbbbbbbk",
      "k         b    k",
      "k        \u037cb    k",
      "k   bbb   b    k",
      "k   \u037d\u037e bgbb((\u037f k",
      "k \u0384\u0385b  b \u0386\u0387\u0387\u0388( k",
      "kb\u0389\u0389b  b       k",
      "k   b \u038ab8888   k",
      "k   b5gb   \u038c\u038e  k",
      "k   bjjb    \u038f  k",
      "bkkkkkkkkkkkkkka"
    ],
    [
      "akkkkkkkkkkkkkkb",
      "k           \u0390  k",
      "k           \u0390  k",
      "k     )     \u0390  k",
      "k           \u0390  k",
      "kbbbbbbbbbbbbbbk",
      "k         b    k",
      "k         b    k",
      "k   bbb   b    k",
      "k   b  bbbb    k",
      "k   b  b  \u0391\u0391   k",
      "kbbbb \u038ab       k",
      "k   b hb\u0392\u0392\u0392\u0392   k",
      "k   b  b   \u0390   k",
      "k   b  b   \u0390   k",
      "bkkkkkkkkkkkkkka"
    ],
    [
      "akkkkkkkkkkkkkkb",
      "k\u0393\u0393\u0393\u0393\u0393\u0393\u0393\u0393\u0393\u0393\u0393\u0393\u0394\u0394k",
      "k\u0393\u0393\u0393\u0393\u0393\u0393\u0393\u0393\u0393\u0393\u0393\u0393\u0394\u0394k",
      "k\u0393\u0393\u0393\u0393\u0393\u0393\u0393\u0393\u0393\u0393\u0393\u0393\u0394\u0394k",
      "k\u0393\u0393\u0393\u0393\u0393\u0393\u0393\u0393\u0393\u0393\u0393\u0393\u0394\u0394k",
      "kbbbbbbbbbbbbbbk",
      "k\u0395\u0395\u0395\u0395\u0395\u0395\u0395\u0395\u0395b\u0393\u0393\u0393\u0393k",
      "k\u0395\u0395\u0395\u0395\u0395\u0395\u0395\u0396\u0395b\u0393\u0393\u0393\u0393k",
      "k\u0395\u0395\u0395bbb\u0395\u0395\u0395b\u0393\u0393\u0393\u0393k",
      "k\u0395\u0395\u0395b  bbbb\u0393\u0393\u0393\u0393k",
      "k\u0395\u0395\u0395b/\u038ab\u0393\u0393\u0393\u0393\u0393\u0393\u0393k",
      "kbbbb hb\u0393\u0393\u0393\u0393\u0393\u0393\u0393k",
      "k   b  b\u0393\u0393\u0393\u0393\u0393\u0393\u0393k",
      "k   b  b\u0394\u0394\u0394\u0394\u0393\u0393\u0393k",
      "k   b  b\u0394\u0394\u0394\u0394\u0393\u0393\u0393k",
      "bkkkkkkkkkkkkkka"
    ]
  ]
}