{
  "name": "multi_thering_16_floor3",
  "refpalette": "deceasedcraft:multi_thering_16/multi_thering_16_floor3_palette",
  "xsize": 16,
  "zsize": 16,
  "slices": [
    [
      "abbbbbbbbbbbbbbb",
      "bcccccccccbccccb",
      "bcccccccccbccccb",
      "bcccdddcccbccccb",
      "bcccdddccbdddccb",
      "bbbbbbbbcbdddccb",
      "beeeeeeeeebccccb",
      "beeeeeeefecccccb",
      "beeebbbeeebccccb",
      "beeeeggbcbbbbbbb",
      "beeebghbccddcccb",
      "bieebj bccddcccb",
      "b   b  bccddcccb",
      "b   b  bcccccccb",
      "b   b  bcccccccb",
      "bbbbbbbbbbbbbbba"
    ],
    [
      "akkkkkkkkkkkkkkb",
      "kl       mbn  lk",
      "k   o o  pbqr  k",
      "k stuw x yboo  k",
      "kABtC DE bF I  k",
      "kbbbbbbbJbKL!M k",
      "kN        bOP  k",
      "kN        Q    k",
      "k   bbb   bRSTUk",
      "k    V bWbbbbbbk",
      "kXYZb  b m0 M12k",
      "kb33b4 b p5 M6 k",
      "k   bj b yF7   k",
      "k   b  b UOP   k",
      "k   b  b      lk",
      "bkkkkkkkkkkkkkka"
    ],
    [
      "akkkkkkkkkkkkkkb",
      "k8        b9  #k",
      "k   o o   b    k",
      "k  t $%^  boo  k",
      "k& t * ( b )+  k",
      "kbbbbbbb-b  *M k",
      "k         b[]  k",
      "k         {    k",
      "k   bbb   b}  Uk",
      "k    | b;bbbbbbk",
      "k :'b  b < >M !k",
      "kb  b  b   %M  k",
      "k   b4 b   ,   k",
      "k   bj.b U[]   k",
      "k   b  b      ?k",
      "bkkkkkkkkkkkkkka"
    ],
    [
      "akkkkkkkkkkkkkkb",
      "k        /b    k",
      "k   ooo  `b    k",
      "k  t   \u0370 \u0371boo  k",
      "k  t \u0372 \u0373 b   M k",
      "kbbbbbbbgb  \u0372M k",
      "k         b\u0374\u0375  k",
      "k    \u0376    g    k",
      "k   bbb   b\u0377\u037a\u037bUk",
      "k   \u037c\u037d bgbbbbbbk",
      "k \u037e\u037fb  b \u0384 \u0385M  k",
      "kb\u0386\u0386b  b \u0387  M  k",
      "k   b \u0388b \u0389  M  k",
      "k   b4gb U\u0374\u0375   k",
      "k   bjjb       k",
      "bkkkkkkkkkkkkkka"
    ],
    [
      "akkkkkkkkkkkkkkb",
      "k         b    k",
      "k   \u038a\u038a\u038a  <b    k",
      "k  \u038c\u038e\u038e\u038e\u038f <b\u038a\u038a  k",
      "k  \u038c\u038e\u038e\u038e\u038f b\u038e\u038e\u038e\u038f k",
      "kbbbbbbbbb\u038e\u038e\u038e\u038f k",
      "k         b\u0390\u0390  k",
      "k         b    k",
      "k   bbb   b    k",
      "k   b  bbbbbbbbk",
      "k   b  b \u038c\u038e\u038e\u038f  k",
      "kbbbb \u0388b \u038c\u038e\u038e\u038f  k",
      "k   b hb \u038c\u038e\u038e\u038f  k",
      "k   b  b  \u0390\u0390   k",
      "k   b  b       k",
      "bkkkkkkkkkkkkkka"
    ],
    [
      "akkkkkkkkkkkkkkb",
      "k\u0391\u0391\u0391\u0391\u0391\u0391\u0391\u0391\u0391b\u0391\u0391\u0391\u0391k",
      "k\u0391\u038e\u038e\u038e\u038e\u038e\u038e\u038e\u038eb\u038e\u038e\u038e\u0391k",
      "k\u0391\u038e\u038e   \u038e\u038e\u038eb\u038e\u038e\u038e\u0391k",
      "k\u0391\u038e\u038e \u0392\u0392\u038e\u038eb\u0392  \u038e\u0391k",
      "kbbbbbbbbb\u0392  \u038e\u0391k",
      "k\u0393\u0393\u0393\u0393\u0393\u0393\u0393\u0393\u0393b\u038e\u038e\u038e\u0391k",
      "k\u0393\u0393\u0393\u0393\u0393\u0393\u0393\u0394\u0393b\u038e\u038e\u038e\u0391k",
      "k\u0393\u0393\u0393bbb\u0393\u0393\u0393b\u038e\u038e\u038e\u0391k",
      "k\u0393\u0393\u0393b  bbbbbbbbk",
      "k\u0393\u0393\u0393b.\u0388b\u038e\u038e\u0392\u0392\u038e\u038e\u0391k",
      "kbbbb hb\u038e\u038e  \u038e\u038e\u0391k",
      "k   b  b\u038e\u038e  \u038e\u038e\u0391k",
      "k   b  b\u038e\u038e\u038e\u038e\u038e\u038e\u0391k",
      "k   b  b\u0391\u0391\u0391\u0391\u0391\u0391\u0391k",
      "bkkkkkkkkkkkkkka"
    ]
  ]
}