{
  "name": "multi_thering_16_floor8",
  "refpalette": "deceasedcraft:multi_thering_16/multi_thering_16_floor8_palette",
  "xsize": 16,
  "zsize": 16,
  "slices": [
    [
      "a               ",
      "                ",
      "                ",
      "                ",
      "                ",
      "                ",
      "                ",
      "                ",
      "    bbb         ",
      "    bccb        ",
      "    bcdb        ",
      "bbbbbe b        ",
      "f   b  b        ",
      "f   b  b        ",
      "f   b  b        ",
      "bffffffb       a"
    ],
    [
      "a               ",
      "                ",
      "                ",
      "                ",
      "                ",
      "                ",
      "                ",
      "                ",
      "    bbb         ",
      "    b  b        ",
      "    b  b        ",
      "bbbbbg b        ",
      "f   be b        ",
      "f   b  b        ",
      "f   b  b        ",
      "bffffffb       a"
    ],
    [
      "a               ",
      "                ",
      "                ",
      "                ",
      "                ",
      "                ",
      "                ",
      "                ",
      "    bbb         ",
      "    b  b        ",
      "    b  b        ",
      "bbbbb  b        ",
      "f   bg b        ",
      "f   behb        ",
      "f   b  b        ",
      "bffffffb       a"
    ],
    [
      "a               ",
      "                ",
      "                ",
      "                ",
      "                ",
      "                ",
      "                ",
      "                ",
      "    bbb         ",
      "    b  b        ",
      "    b  b        ",
      "bbbbb  b        ",
      "f   b ib        ",
      "f   bgcb        ",
      "f   beeb        ",
      "bffffffb       a"
    ],
    [
      "a               ",
      "                ",
      "                ",
      "                ",
      "                ",
      "                ",
      "                ",
      "                ",
      "    bbb         ",
      "    b  b        ",
      "    b  b        ",
      "bbbbb ib        ",
      "f   b db        ",
      "f   b  b        ",
      "f   b  b        ",
      "bffffffb       a"
    ],
    [
      "a               ",
      " jjjjjjjjjjjjjj ",
      " jkkkkkkkkkkkkj ",
      " jkkkkkkkkkkkkj ",
      " jkkkkkkkkkkkkj ",
      " jkkkkkkkkkkkkj ",
      " jkkkkkkkkkkkkj ",
      "jjkkkkkkkkkkkkj ",
      "kkkkbbbkkkkkkkj ",
      "kkkkb  bkkkkkkj ",
      "kkkkbhibkkkkkkj ",
      "bbbbb dbkkkkkkj ",
      "f   b  bkkkkkkj ",
      "f   b  bkkkkkkj ",
      "f   b  bjjjjjjj ",
      "bffffffb       a"
    ]
  ]
}