{
  "name": "multi_thering_16_floor2",
  "refpalette": "deceasedcraft:multi_thering_16/multi_thering_16_floor2_palette",
  "xsize": 16,
  "zsize": 16,
  "slices": [
    [
      "abbbbbbbbbbbbbbb",
      "bcccccccccbccccb",
      "bcccccccc!bccccb",
      "bcccdddcccbccccb",
      "bcccdddccbdddccb",
      "bbbbbbbbcbdddccb",
      "beeeeeeeeebccccb",
      "beeeeeeefecccccb",
      "beeebbbeeebccccb",
      "beeeeggbcbbbbbbb",
      "beeebghbccddcccb",
      "bieebj bccddcccb",
      "b   b  bccddcccb",
      "b   b  bcccccccb",
      "b   b  bcccccccb",
      "bbbbbbbbbbbbbbba"
    ],
    [
      "akkkkkkkkkkkkkkb",
      "kl       mbn  lk",
      "k   o o  pbqr  k",
      "k stuw x yboo  k",
      "kABtC DE bF I  k",
      "kbbbbbbbJbKL M k",
      "kN        bOP  k",
      "kN        Q    k",
      "k   bbb   bRSTUk",
      "k    V bWbbbbbbk",
      "kXYZb  b m0 M12k",
      "kb33b4 b p5 M6 k",
      "k   bj b yF7   k",
      "k   b  b UOP   k",
      "k   b  b      lk",
      "bkkkkkkkkkkkkkka"
    ],
    [
      "akkkkkkkkkkkkkkb",
      "k8        b9  #k",
      "k   o o   b    k",
      "k  t $%^ &boo  k",
      "k* t (   b )+  k",
      "kbbbbbbb-b  (M k",
      "k         b[]  k",
      "k         {    k",
      "k   bbb   b  }Uk",
      "k    | b;bbbbbbk",
      "k :'b  b   <M *k",
      "kb  b  b & %M  k",
      "k   b4 b & >   k",
      "k   bj,b U.]   k",
      "k   b  b      ?k",
      "bkkkkkkkkkkkkkka"
    ],
    [
      "akkkkkkkkkkkkkkb",
      "k        /b    k",
      "k   ooo  `b    k",
      "k  t   \u0370 \u0371boo  k",
      "k  t \u0372 \u0373 b   M k",
      "kbbbbbbbgb  \u0372M k",
      "k         b\u0374\u0375  k",
      "k    \u0376    g    k",
      "k   bbb   b\u0377\u037a\u037bUk",
      "k   \u037c\u037d bgbbbbbbk",
      "k \u037e\u037eb  b \u037f \u0384M  k",
      "kb\u0385\u0385b  b \u0386  M  k",
      "k   b \u0387b \u0388  M  k",
      "k   b4gb U\u0374\u0375   k",
      "k   bjjb       k",
      "bkkkkkkkkkkkkkka"
    ],
    [
      "akkkkkkkkkkkkkkb",
      "k        \u0389b    k",
      "k   \u038a\u038a\u038a  &b    k",
      "k  \u038c\u038e\u038e\u038e\u038f  b\u038a\u038a  k",
      "k  \u038c\u038e\u038e\u038e\u038f b\u038e\u038e\u038e\u038f k",
      "kbbbbbbbbb\u038e\u038e\u038e\u038f k",
      "k         b\u0390\u0390  k",
      "k         b    k",
      "k   bbb   b\u0391\u0391  k",
      "k   b  bbbbbbbbk",
      "k   b  b \u038c\u038e\u038e\u038f  k",
      "kbbbb \u0387b \u038c\u038e\u038e\u038f  k",
      "k   b hb \u038c\u038e\u038e\u038f  k",
      "k   b  b  \u0390\u0390   k",
      "k   b  b       k",
      "bkkkkkkkkkkkkkka"
    ],
    [
      "akkkkkkkkkkkkkkb",
      "k\u0392\u0392\u0392\u0392\u0392\u0392\u0392\u0392\u0392b\u0392\u0392\u0392\u0392k",
      "k\u0392\u038e\u038e\u038e\u038e\u038e\u038e\u038e\u038eb\u038e\u038e\u038e\u0392k",
      "k\u0392\u038e\u038e   \u038e\u038e\u038eb\u038e\u038e\u038e\u0392k",
      "k\u0392\u038e\u038e \u0393\u0393\u038e\u038eb\u0393  \u038e\u0392k",
      "kbbbbbbbbb\u0393  \u038e\u0392k",
      "k\u0394\u0394\u0394\u0394\u0394\u0394\u0394\u0394\u0394b\u038e\u038e\u038e\u0392k",
      "k\u0394\u0394\u0394\u0394\u0394\u0394\u0394\u0395\u0394b\u038e\u038e\u038e\u0392k",
      "k\u0394\u0394\u0394bbb\u0394\u0394\u0394b\u038e\u038e\u038e\u0392k",
      "k\u0394\u0394\u0394b  bbbbbbbbk",
      "k\u0394\u0394\u0394b,\u0387b\u038e\u038e\u0393\u0393\u038e\u038e\u0392k",
      "kbbbb hb\u038e\u038e  \u038e\u038e\u0392k",
      "k   b  b\u038e\u038e  \u038e\u038e\u0392k",
      "k   b  b\u038e\u038e\u038e\u038e\u038e\u038e\u0392k",
      "k   b  b\u0392\u0392\u0392\u0392\u0392\u0392\u0392k",
      "bkkkkkkkkkkkkkka"
    ]
  ]
}