{
  "name": "multi_filmworkstower_11_floor1",
  "refpalette": "deceasedcraft:multi_filmworkstower_11/multi_filmworkstower_11_floor1_palette",
  "xsize": 16,
  "zsize": 16,
  "slices": [
    [
      "                ",
      "a               ",
      "                ",
      "                ",
      "a               ",
      "                ",
      "bbc         de  ",
      "                ",
      "f               ",
      "                ",
      "                ",
      "                ",
      "                ",
      "                ",
      "                ",
      "                "
    ],
    [
      "a               ",
      "ga              ",
      "a               ",
      "a               ",
      "ga              ",
      "a               ",
      "bbbc       de   ",
      "a               ",
      "ff              ",
      "                ",
      "                ",
      "                ",
      "                ",
      "                ",
      "                ",
      "                "
    ],
    [
      "ha              ",
      "hgai            ",
      "ha              ",
      "ha              ",
      "hgai            ",
      "ha              ",
      "hbbbcj k jde    ",
      "la              ",
      "gff             ",
      "m               ",
      "                ",
      "                ",
      "                ",
      "                ",
      "                ",
      "                "
    ],
    [
      " na             ",
      " hga            ",
      " ha             ",
      " ha             ",
      " hga            ",
      " ha             ",
      " hbbbbbbbbbcjjjj",
      "ola             ",
      "pgff            ",
      "mm              ",
      "                ",
      "                ",
      "                ",
      "                ",
      "                ",
      "                "
    ],
    [
      " nnaq           ",
      "  hggq     r    ",
      "  haq           ",
      "  haq           ",
      "  hggq     r    ",
      "  haq           ",
      "  hbbbbbbbbbbbbb",
      " olaq           ",
      "spgfff          ",
      "mmm             ",
      "                ",
      "                ",
      "                ",
      "                ",
      "                ",
      "                "
    ],
    [
      "   tgaqqqqqqqqqq",
      "   ngggggggggggg",
      "   hgaqqqqqqqqqq",
      "   hgaqqqqqqqqqq",
      "   hgggggggggggg",
      "   hgaqqqqqqqqqq",
      "   hgbbbbbbbbbbb",
      "  olgaqqqqqqqqqq",
      "sspggfffffffffff",
      "mmmmm           ",
      "                ",
      "                ",
      "                ",
      "                ",
      "                ",
      "                "
    ]
  ]
}