{
  "name": "multi_filmworkstower_11_base1",
  "refpalette": "deceasedcraft:multi_filmworkstower_11/multi_filmworkstower_11_base1_palette",
  "xsize": 16,
  "zsize": 16,
  "slices": [
    [
      "  ab            ",
      "      cdd       ",
      "     edfde      ",
      "      dgd       ",
      "           hi   ",
      "           aa   ",
      "                ",
      "jjjjjjjjjjjjjjjj",
      "                ",
      "                ",
      "                ",
      "                ",
      "                ",
      "kkkkkkkkkkkkkkkk",
      "llllllllllllllll",
      "vvvvvvvvvvvvvvvv"
    ],
    [
      "                ",
      "                ",
      "     e   e      ",
      "                ",
      "                ",
      "                ",
      "                ",
      "jjjjjjjjjjjjjjjj",
      "                ",
      "                ",
      "                ",
      "                ",
      "                ",
      "kkkkkkkkkkkkkkkk",
      "llllllllllllllll",
      "vvvvvvvvvvvvvvvv"
    ],
    [
      "                ",
      "                ",
      "     e   e      ",
      "                ",
      "                ",
      "                ",
      "                ",
      "jjjjjjjjjjjjjjjj",
      "                ",
      "                ",
      "                ",
      "                ",
      "                ",
      "kkkkkkkkkkkkkkkk",
      "llllllllllllllll",
      "vvvvvvvvvvvvvvvv"
    ],
    [
      "   m   m   m    ",
      "   m   m   m    ",
      "   m e m e m    ",
      "   m   m   m    ",
      "   m   m   m    ",
      "                ",
      "                ",
      "                ",
      "                ",
      "                ",
      "                ",
      "                ",
      "                ",
      "kkkkkkkkkkkkkkkk",
      "llllllllllllllll",
      "vvvvvvvvvvvvvvvv"
    ],
    [
      "nonnnonnnonnnonp",
      "nonnnonnnonnnonp",
      "nonnnonnnonnnonp",
      "nqnnnqnnnqnnnqnp",
      "pppppppppppppppp",
      "rrrrrrrrrrrrrrrr",
      "ssssssssssssssss",
      "ssssssssssssssss",
      "ssssssssssssssss",
      "ssssssssssssssss",
      "ssssssssssssssss",
      "ssssssssssssssss",
      "ssssssssssssssss",
      "kkkkkkkkkkkkkkkk",
      "llllllllllllllll",
      "vvvvvvvvvvvvvvvv"
    ],
    [
      "tttttttttttttttt",
      "tttttttttttttttt",
      "tttttttttttttttt",
      "tttttttttttttttt",
      "tttttttttttttttt",
      "tttttttttttttttt",
      "tttttttttttttttt",
      "tttttttttttttttt",
      "tttttttttttttttt",
      "tttttttttttttttt",
      "tttttttttttttttt",
      "tttttttttttttttt",
      "tttttttttttttttt",
      "kkkkkkkkkkkkkkkk",
      "llllllllllllllll",
      "vvvvvvvvvvvvvvvv"
    ]
  ]
}