{
  "name": "multi_filmworkstower_11_floor2",
  "refpalette": "deceasedcraft:multi_filmworkstower_11/multi_filmworkstower_11_floor2_palette",
  "xsize": 16,
  "zsize": 16,
  "slices": [
    [
      "   abccccccccccc",
      "   bbccccccccccc",
      "    dccccccccccc",
      "    dccccccccccc",
      "    dccccccccccc",
      "    dccccccccccc",
      "    dcefeccccccc",
      "   ghhhhhhhhhhhh",
      "iiijeeeeeeeeeeee",
      "kkkkkkkkkkkkkkkk",
      "                ",
      "                ",
      "                ",
      "                ",
      "                ",
      "                "
    ],
    [
      "               l",
      "                ",
      "                ",
      "                ",
      "                ",
      "                ",
      "     meneo      ",
      "    gggggggggggg",
      " iiijjjjjjjjjjjj",
      "kkkkkkkkkkkkkkkk",
      "                ",
      "                ",
      "                ",
      "                ",
      "                ",
      "                "
    ],
    [
      "                ",
      "                ",
      "                ",
      "                ",
      "                ",
      "                ",
      "    mp q ro  s t",
      "                ",
      " iiiiiiiiiiiiiii",
      "kkkkkkkkkkkkkkkk",
      "                ",
      "                ",
      "                ",
      "                ",
      "                ",
      "                "
    ],
    [
      "                ",
      "                ",
      "                ",
      "                ",
      "                ",
      "                ",
      "   mp  u  ro w x",
      "                ",
      "  iiiiiiiiiiiiii",
      "kkkkkkkkkkkkkkkk",
      "                ",
      "                ",
      "                ",
      "                ",
      "                ",
      "                "
    ],
    [
      "                ",
      "                ",
      "                ",
      "                ",
      "                ",
      "                ",
      "  mp   u   roy A",
      "                ",
      "  i iii iii i ii",
      "kkkkkkkkkkkkkkkk",
      "                ",
      "                ",
      "                ",
      "                ",
      "                ",
      "                "
    ],
    [
      "                ",
      "                ",
      "                ",
      "                ",
      "                ",
      "                ",
      " mp    u    ro B",
      "                ",
      "      i  ii    i",
      "kkkkkkkkkkkkkkkk",
      "                ",
      "                ",
      "                ",
      "                ",
      "                ",
      "                "
    ]
  ]
}