{
  "name": "multi_filmworkstower_11_base2",
  "refpalette": "deceasedcraft:multi_filmworkstower_11/multi_filmworkstower_11_base2_palette",
  "xsize": 16,
  "zsize": 16,
  "slices": [
    [
      "abcd            ",
      "effe            ",
      "                ",
      "                ",
      "                ",
      "g           hi  ",
      "                ",
      "jjjjjjjjjjjjjjjj",
      "kkkkkkkkkkkkkkkk",
      "kkkkkkkkkkkkkkkk",
      "kkkkkkkkkkkkkkkk",
      "kkkkkkkkkkkkkkkk",
      "kkkkkkkkkkkkkkkk",
      "llllllllllllllll",
      "mmmmmmmmmmmmmmmm",
      "vvvvvvvvvvvvvvvv"
    ],
    [
      "f nf  opp       ",
      "      p!q       ",
      "      rrp       ",
      "                ",
      "                ",
      "g           hs  ",
      "                ",
      "jjjjjjjjjjjjjjjj",
      "                ",
      "                ",
      "                ",
      "                ",
      "                ",
      "llllllllllllllll",
      "mmmmmmmmmmmmmmmm",
      "vvvvvvvvvvvvvvvv"
    ],
    [
      "     tpppu      ",
      "     wxxxo      ",
      "     txxxu      ",
      "      ==y       ",
      "                ",
      "A           Bs  ",
      "                ",
      "jjjjjjjjjjjjjjjj",
      "                ",
      "                ",
      "                ",
      "                ",
      "                ",
      "llllllllllllllll",
      "mmmmmmmmmmmmmmmm",
      "vvvvvvvvvvvvvvvv"
    ],
    [
      "     tC=Cu      ",
      "     w D u      ",
      "     t E u      ",
      "     wFI o      ",
      "      JJJ       ",
      "A           Bs  ",
      "                ",
      "jjjjjjjjjjjjjjjj",
      "                ",
      "                ",
      "                ",
      "                ",
      "                ",
      "llllllllllllllll",
      "mmmmmmmmmmmmmmmm",
      "vvvvvvvvvvvvvvvv"
    ],
    [
      "  K  tLLLuMN    ",
      "    s OP  s     ",
      "     w QRo      ",
      "    s S   s     ",
      "   NK JJJ   M   ",
      "sN          sT  ",
      "                ",
      "jjjjjjjjjjjjjjjj",
      "                ",
      "                ",
      "                ",
      "                ",
      "                ",
      "llllllllllllllll",
      "mmmmmmmmmmmmmmmm",
      "vvvvvvvvvvvvvvvv"
    ],
    [
      "  KUMt===o ssK  ",
      "    KtVWXuYK    ",
      "     t Z u      ",
      "   MYt   uM     ",
      " Mss  JJJ KsM   ",
      "Y0K         sA  ",
      "                ",
      "jjjjjjjjjjjjjjjj",
      "                ",
      "                ",
      "                ",
      "                ",
      "                ",
      "llllllllllllllll",
      "mmmmmmmmmmmmmmmm",
      "vvvvvvvvvvvvvvvv"
    ]
  ]
}