{
  "name": "multi_filmworkstower_11_floor3",
  "refpalette": "deceasedcraft:multi_filmworkstower_11/multi_filmworkstower_11_floor3_palette",
  "xsize": 16,
  "zsize": 16,
  "slices": [
    [
      "                ",
      "                ",
      "                ",
      "                ",
      "                ",
      "                ",
      "ab     c     def",
      "       g        ",
      "                ",
      "hhhhhhhhhhhhhhhh",
      "                ",
      "                ",
      "                ",
      "                ",
      "                ",
      "                "
    ],
    [
      "                ",
      "                ",
      "                ",
      "                ",
      "                ",
      "                ",
      "b      i      de",
      "       i        ",
      "                ",
      "hhhhhhhhhhhhhhhh",
      "                ",
      "                ",
      "                ",
      "                ",
      "                ",
      "                "
    ],
    [
      "jjjjjjjjjjjjjjjj",
      "jjjjjjjjjjjjjjjj",
      "jjjjjjjjjjjjjjjj",
      "jjjjjjjjjjjjjjjj",
      "jjjjjjjjjjjjjjjj",
      "jjjjjjjjjjjjjjjj",
      "kkkkkkkkkkkkkkkk",
      "llllllllllllllll",
      "hhhhhhhhhhhhhhhh",
      "hhhhhhhhhhhhhhhh",
      "                ",
      "                ",
      "                ",
      "                ",
      "                ",
      "                "
    ],
    [
      "mmmmmmmmmmmmmmmm",
      "nnnnnnnnnnnnnnnn",
      "mmmmmmmmmmmmmmmm",
      "mmmmmmmmmmmmmmmm",
      "nnnnnnnnnnnnnnnn",
      "mmmmmmmmmmmmmmmm",
      "                ",
      "                ",
      "                ",
      "                ",
      "                ",
      "                ",
      "                ",
      "                ",
      "                ",
      "                "
    ],
    [
      "                ",
      "                ",
      "                ",
      "                ",
      "                ",
      "                ",
      "                ",
      "                ",
      "                ",
      "                ",
      "                ",
      "                ",
      "                ",
      "                ",
      "                ",
      "                "
    ],
    [
      "                ",
      "                ",
      "                ",
      "                ",
      "                ",
      "                ",
      "                ",
      "                ",
      "                ",
      "                ",
      "                ",
      "                ",
      "                ",
      "                ",
      "                ",
      "                "
    ]
  ]
}