{
  "name": "building_warehousebdamaged_ground_270",
  "refpalette": "deceasedcraft:building_warehousebdamaged/building_warehousebdamaged_ground_palette_270",
  "xsize": 16,
  "zsize": 16,
  "slices": [
    [
      "azzzzazzzzzaazzz",
      "aaaaazaazzaazaaa",
      "zzaaaaaaaaaaaaaz",
      "zaaaaaaaaadaaaza",
      "zdbbbddbdaaddbbz",
      "zbbbbbbbbbbbbbbz",
      "zbbbbbbcccecccbz",
      "zbbbbbbcccccccbz",
      "zdbbbbbccfccecbz",
      "zbbbbbbfccccccbz",
      "zbbbbbbcccccccbz",
      "zbbbbbbcccgcfcbz",
      "zdbbbbbchcccccbz",
      "zdbbbdbcccceccbz",
      "zbbbdbbbbbbbbbbz",
      "zzzzzzzzzzzzzzzz"
    ],
    [
      "  k k  k        ",
      "     k    E k   ",
      "k B    U K Bup  ",
      "     B m L wwml ",
      "   m  www  Cqqm ",
      "  nommooRt D oni",
      " ^oo ZorSM   !oi",
      "k^o93 ot  F troj",
      " &n440Y T I x o ",
      " *$r5    N s  o ",
      "k*%r6tP  Ot yso ",
      "k or!1tV      ok",
      "k onZZoW P  ttn ",
      "  no7 nX QJ Aro ",
      "   #82nnoononnok",
      " k  k  k k    k "
    ],
    [
      "                ",
      "                ",
      "                ",
      "                ",
      "                ",
      "  oo- n+S    )o ",
      "  nnZ oR     ro ",
      "  n   o       n ",
      "  o[        t o ",
      "  ]           Z(",
      "  {t          Z(",
      "  ox          n ",
      "  ooZ o       o ",
      "  on7 oX      n ",
      "      noonooooo ",
      "                "
    ],
    [
      "                ",
      "                ",
      "                ",
      "                ",
      "                ",
      "  oo -|n  }}}nn ",
      "  ooZZn       o ",
      "  n   o       o ",
      "  o:  ;       o ",
      "  '   ;       o ",
      "  '   ;       o ",
      "  n   ;       o ",
      "  ooZZn       o ",
      "  on 7oX      n ",
      "      ooonoonon ",
      "                "
    ],
    [
      "                ",
      "                ",
      "                ",
      "                ",
      " <<<<<<<<<<<<<  ",
      " <oo,,nonoooooo ",
      " <oo>>o>>>>>>>o ",
      " <o   n       o ",
      " <o.  o'      n ",
      " <o   o' :  : o ",
      " <o   o' :  : o ",
      " <o.  o'      o ",
      " <oo>>o       o ",
      " <oo<<oX      n ",
      " <<<<<ooooonooo ",
      "                "
    ],
    [
      "                ",
      "                ",
      "                ",
      "                ",
      "                ",
      "  SSSSnoonooono ",
      "  SSSSo???????o ",
      "  SSSSo???????o ",
      "  SSSSo???????o ",
      "  SSSSo??`??/?o ",
      "  SSSSo??`??/?n ",
      "  SSSSo???????o ",
      "  SSSSo???????o ",
      "  SSSSoX??????o ",
      "      onooooooo ",
      "                "
    ]
  ]
}