{
  "name": "building_warehousebdamaged_ground_180",
  "refpalette": "deceasedcraft:building_warehousebdamaged/building_warehousebdamaged_ground_palette_180",
  "xsize": 16,
  "zsize": 16,
  "slices": [
    [
      "zzzzzzzzzzzzzzaa",
      "zbddbbbdbbbdazaz",
      "zbbbbbbbbbbbaaaz",
      "zbbbbbbbbbbbaaaz",
      "zdbbbbbbbbbbaaaz",
      "zbdbbbbbbbbdaaza",
      "zbbbbbbbbbbdaaaz",
      "zbccccfcccbbaaaz",
      "zbchccccccbdaazz",
      "zbcccccfccbaaazz",
      "zbccgccccebadaaz",
      "zbecccccccbdaaaa",
      "zbccfcceccbdaaza",
      "zbccccccccbbaaaz",
      "zbbbbbbbbbbbzaaz",
      "zzzzzzzzzzzzazaz"
    ],
    [
      "   kkk  k    k  ",
      "k    **&^^      ",
      "  noo%$noon  B k",
      " #onrrr49oom    ",
      "k87Z!6543 m    k",
      " 2 Z1t 0 Zm B k ",
      " nnotP Yooow    ",
      "knXWV   trowmU k",
      " o     T SRw    ",
      "koQP ON  Mt LK  ",
      " nJ  t IF     E ",
      " o    s   DCwB  ",
      " nAt y xt  qwuk ",
      " nrt s  r!oqmp  ",
      "koonoooooonml   ",
      " k  k   jii     "
    ],
    [
      "                ",
      "                ",
      "  ooo{]onno     ",
      "  noxt [ no     ",
      "  7Z     Z-     ",
      "                ",
      " noo    oon     ",
      " oX      R+     ",
      " o        S     ",
      " n              ",
      " o              ",
      " o              ",
      " o     t        ",
      " o       r)     ",
      " ononZZonoo     ",
      "     ((         "
    ],
    [
      "                ",
      "                ",
      "  oon''onoo     ",
      "  no   : oo     ",
      "   Z     Z      ",
      "  7Z     Z-     ",
      " oon;;;;on|     ",
      " oX       n     ",
      " o              ",
      " n              ",
      " o        }     ",
      " o        }     ",
      " n        }     ",
      " o        n     ",
      " nnooooooon     ",
      "                "
    ],
    [
      "                ",
      " <<<<<<<<<<<    ",
      " <ooooooooo<    ",
      " <oo.  . oo<    ",
      " <<>     >,<    ",
      " <<>     >,<    ",
      " ooooooonon<    ",
      " oX '''' >o<    ",
      " o       >n<    ",
      " o   ::  >o<    ",
      " o       >o<    ",
      " n       >o<    ",
      " o   ::  >o<    ",
      " o       >o<    ",
      " onoooonooo     ",
      "                "
    ],
    [
      "                ",
      "                ",
      "  SSSSSSSSS     ",
      "  SSSSSSSSS     ",
      "  SSSSSSSSS     ",
      "  SSSSSSSSS     ",
      " ooooooooon     ",
      " nX???????o     ",
      " o????????o     ",
      " o???``???n     ",
      " o????????o     ",
      " o????????o     ",
      " o???//???o     ",
      " o????????n     ",
      " oooonooooo     ",
      "                "
    ]
  ]
}