{
  "name": "building_warehousebdamaged_ground",
  "refpalette": "deceasedcraft:building_warehousebdamaged/building_warehousebdamaged_ground_palette",
  "xsize": 16,
  "zsize": 16,
  "slices": [
    [
      "zazazzzzzzzzzzzz",
      "zaazbbbbbbbbbbbz",
      "zaaabbccccccccbz",
      "azaadbcceccfccbz",
      "aaaadbcccccccebz",
      "zaadabeccccgccbz",
      "zzaaabccfcccccbz",
      "zzaadbcccccchcbz",
      "zaaabbcccfccccbz",
      "zaaadbbbbbbbbbbz",
      "azaadbbbbbbbbdbz",
      "zaaabbbbbbbbbbdz",
      "zaaabbbbbbbbbbbz",
      "zaaabbbbbbbbbbbz",
      "zazadbbbdbbbddbz",
      "aazzzzzzzzzzzzzz"
    ],
    [
      "     iij   k  k ",
      "   lmnoooooonook",
      "  pmqo!r  s trn ",
      " kuwq  tx y tAn ",
      "  BwCD   s    o ",
      " E     FI t  Jn ",
      "  KL tM  NO PQok",
      "    wRS T     o ",
      "k Umwort   VWXnk",
      "    woooY Ptonn ",
      " k B mZ 0 t1Z 2 ",
      "k    m 3456!Z78k",
      "    moo94rrrno# ",
      "k B  noon$%oon  ",
      "      ^^&**    k",
      "  k    k  kkk   "
    ],
    [
      "         ((     ",
      "     oonoZZnono ",
      "     )r       o ",
      "        t     o ",
      "              o ",
      "              o ",
      "              n ",
      "     S        o ",
      "     +R      Xo ",
      "     noo    oon ",
      "                ",
      "     -Z     Z7  ",
      "     on [ txon  ",
      "     onno]{ooo  ",
      "                ",
      "                "
    ],
    [
      "                ",
      "     nooooooonn ",
      "     n        o ",
      "     }        n ",
      "     }        o ",
      "     }        o ",
      "              n ",
      "              o ",
      "     n       Xo ",
      "     |no;;;;noo ",
      "     -Z     Z7  ",
      "      Z     Z   ",
      "     oo :   on  ",
      "     oono''noo  ",
      "                ",
      "                "
    ],
    [
      "                ",
      "     ooonoooono ",
      "    <o>       o ",
      "    <o>  ::   o ",
      "    <o>       n ",
      "    <o>       o ",
      "    <o>  ::   o ",
      "    <n>       o ",
      "    <o> '''' Xo ",
      "    <nonooooooo ",
      "    <,>     ><< ",
      "    <,>     ><< ",
      "    <oo .  .oo< ",
      "    <ooooooooo< ",
      "    <<<<<<<<<<< ",
      "                "
    ],
    [
      "                ",
      "     ooooonoooo ",
      "     n????????o ",
      "     o???//???o ",
      "     o????????o ",
      "     o????????o ",
      "     n???``???o ",
      "     o????????o ",
      "     o???????Xn ",
      "     nooooooooo ",
      "     SSSSSSSSS  ",
      "     SSSSSSSSS  ",
      "     SSSSSSSSS  ",
      "     SSSSSSSSS  ",
      "                ",
      "                "
    ]
  ]
}