{
  "name": "building_warehousebdamaged_ground_90",
  "refpalette": "deceasedcraft:building_warehousebdamaged/building_warehousebdamaged_ground_palette_90",
  "xsize": 16,
  "zsize": 16,
  "slices": [
    [
      "zzzzzzzzzzzzzzzz",
      "zbbbbbbbbbbdbbbz",
      "zbcceccccbdbbbdz",
      "zbccccchcbbbbbdz",
      "zbcfcgcccbbbbbbz",
      "zbcccccccbbbbbbz",
      "zbccccccfbbbbbbz",
      "zbceccfccbbbbbdz",
      "zbcccccccbbbbbbz",
      "zbcccecccbbbbbbz",
      "zbbbbbbbbbbbbbbz",
      "zbbddaadbddbbbdz",
      "azaaadaaaaaaaaaz",
      "zaaaaaaaaaaaaazz",
      "aaazaazzaazaaaaa",
      "zzzaazzzzzazzzza"
    ],
    [
      " k    k k  k  k ",
      "konnonoonn28#   ",
      " orA JQ Xn 7on  ",
      " ntt  P WoZZno k",
      "ko      Vt1!ro k",
      " osy tO  Pt6r%*k",
      " o  s N    5r$* ",
      " o x I T Y044n& ",
      "jort F  to 39o^k",
      "io!   MSroZ oo^ ",
      "ino D tRoommon  ",
      " mqqC  www  m   ",
      " lmww L m B     ",
      "  puB K U    B k",
      "   k E    k     ",
      "        k  k k  "
    ],
    [
      "                ",
      " ooooonoon      ",
      " n      Xo 7no  ",
      " o       o Zoo  ",
      " n          xo  ",
      "(Z          t{  ",
      "(Z           ]  ",
      " o t        [o  ",
      " n       o   n  ",
      " or     Ro Znn  ",
      " o)    S+n -oo  ",
      "                ",
      "                ",
      "                ",
      "                ",
      "                "
    ],
    [
      "                ",
      " nonoonooo      ",
      " n      Xo7 no  ",
      " o       nZZoo  ",
      " o       ;   n  ",
      " o       ;   '  ",
      " o       ;   '  ",
      " o       ;  :o  ",
      " o       o   n  ",
      " o       nZZoo  ",
      " nn}}}  n|- oo  ",
      "                ",
      "                ",
      "                ",
      "                ",
      "                "
    ],
    [
      "                ",
      " ooonooooo<<<<< ",
      " n      Xo<<oo< ",
      " o       o>>oo< ",
      " o      'o  .o< ",
      " o :  : 'o   o< ",
      " o :  : 'o   o< ",
      " n      'o  .o< ",
      " o       n   o< ",
      " o>>>>>>>o>>oo< ",
      " oooooonon,,oo< ",
      "  <<<<<<<<<<<<< ",
      "                ",
      "                ",
      "                ",
      "                "
    ],
    [
      "                ",
      " ooooooono      ",
      " o??????XoSSSS  ",
      " o???????oSSSS  ",
      " o???????oSSSS  ",
      " n?/??`??oSSSS  ",
      " o?/??`??oSSSS  ",
      " o???????oSSSS  ",
      " o???????oSSSS  ",
      " o???????oSSSS  ",
      " onooonoonSSSS  ",
      "                ",
      "                ",
      "                ",
      "                ",
      "                "
    ]
  ]
}