{
  "name": "multi_laboratory_0_base3",
  "refpalette": "deceasedcraft:multi_laboratory_0/multi_laboratory_0_base3_palette",
  "xsize": 16,
  "zsize": 16,
  "slices": [
    [
      "vvvvvvvvvvvvvvvv",
      "vaaaaaaaaaaaaaaa",
      "vabbbbbbbbbbcccc",
      "vabddeeedddf    ",
      "vabddeegeddf    ",
      "vabddddehddfffff",
      "vabdddg!eediiiii",
      "vabddddhdediiiii",
      "vabiiieeiiifiiii",
      "vabddeeddddiiiii",
      "vabddjeddeheiiii",
      "vabdde!hehdieeii",
      "vabddddehediieii",
      "vabddhdddddiiiii",
      "vabddddddddiiiii",
      "vabiiiiiiiifiiii"
    ],
    [
      "vvvvvvvvvvvvvvvv",
      "vaaaaaaaaaaaaaaa",
      "vabbbbbbbbbbcccc",
      "vab k ! hllm    ",
      "vab   e noom    ",
      "vab pq r s mmmmm",
      "vab  t  uw x    ",
      "vabyyhrAm  m   B",
      "vabmme emmmf   C",
      "vabhD      mm  E",
      "vabeF Arww ee IE",
      "vab ew  F eJwA E",
      "vab K  ee  Ir  E",
      "vab p    LLmI  C",
      "vab khk  llm  r ",
      "vabmmmmmmmmf    "
    ],
    [
      "vvvvvvvvvvvvvvvv",
      "vaaaaaaaaaaaaaaa",
      "vabbbbbbbbbbcccc",
      "vabMkMNMAllm    ",
      "vab   w  oom    ",
      "vab        mmmmm",
      "vab        O    ",
      "vab P   h Qm    ",
      "vabmmR Fhmmf   S",
      "vabe       J   T",
      "vabew          U",
      "vab A   w      V",
      "vab    Ah      W",
      "vab      LLm   S",
      "vab kXk  llm    ",
      "vabmmmmmmmmf    "
    ],
    [
      "vvvvvvvvvvvvvvvv",
      "vaaaaaaaaaaaaaaa",
      "vabbbbbbbbbbcccc",
      "vabYkYeYZ lm    ",
      "vab      00m    ",
      "vab    1   mmmmm",
      "vab        m    ",
      "vab     w  m    ",
      "vabmmh Fmmmf   2",
      "vabw 3     4    ",
      "vab             ",
      "vab 5    X 4   6",
      "vab        m    ",
      "vab      00m   2",
      "vab7k8k7  lm    ",
      "vabmmmmmmmmf    "
    ],
    [
      "vvvvvvvvvvvvvvvv",
      "vaaaaaaaaaaaaaaa",
      "vabbbbbbbbbbcccc",
      "vab   e h9#m    ",
      "vab9999  99m    ",
      "vab99998 99mmmmm",
      "vab99999N99m    ",
      "vab99999999m    ",
      "vabmmeemmmmf    ",
      "vab99F99999m    ",
      "vab9$ 99999m    ",
      "vab98999989m    ",
      "vab999999%9m    ",
      "vab99999999m    ",
      "vab  h    lm    ",
      "vabmmmmmmmmf    "
    ],
    [
      "vvvvvvvvvvvvvvvv",
      "vaaaaaaaaaaaaaaa",
      "vabbbbbbbbbbcccc",
      "vab#l#e#e lm    ",
      "vab l eee lm    ",
      "vab l hhe lmmmmm",
      "vab l h e lm4444",
      "vab llllellm4444",
      "vabmmmmmmmmf4444",
      "vabllhlllllm4444",
      "vablhe l l m4444",
      "vableh^l^e^m4444",
      "vabl&e^l^e^m4444",
      "vabl^l^l^l^m4444",
      "vab#lll#^l^m4444",
      "vabmmmmmmmmf****"
    ]
  ]
}