{
  "name": "multi_laboratory_0_ground",
  "refpalette": "deceasedcraft:multi_laboratory_0/multi_laboratory_0_ground_palette",
  "xsize": 16,
  "zsize": 16,
  "slices": [
    [
      "zzzzzzzzzzzzzzzz",
      "zzzzazzaazaaabza",
      "zzzzzaavbbbccccc",
      "zazzaabvvccccccc",
      "zzzzaaavbccccccc",
      "azzazabvcccddddd",
      "zzazzzbbcccdeeee",
      "zaazaabvcccdeeee",
      "zazaaabvcccdeeee",
      "zzaazbbvcccdeeee",
      "zazzaavbcccdeee!",
      "zzzaaabbcccdeeee",
      "azazzbbvcccdeeee",
      "zzazaaabcccdeeee",
      "zazazabvcccdeeee",
      "zzzzzabvcccdeeee"
    ],
    [
      "  f  f  f   f   ",
      " ff           f ",
      "   f       ggggg",
      "         gg     ",
      "f h      g      ",
      "    i   g  jkldm",
      " f      g  mnopq",
      "   f    g  mrnop",
      "f f     g  dsrn ",
      "f       g  mtsrs",
      "        g  mtus ",
      " f      g  mtwuw",
      "   f    g  m  w ",
      "        g  mt   ",
      "        g  mt   ",
      "f f     g  dxxxy"
    ],
    [
      "                ",
      "                ",
      "           ggggg",
      "         gg     ",
      "  ~      A      ",
      "        g  jBCdD",
      "        g  m    ",
      "        g  m    ",
      "        g  d   E",
      "        g  D    ",
      "        g  m   E",
      "        A  m    ",
      "        A  m   E",
      "        g  m    ",
      "        g  D    ",
      "        g  dxxxF"
    ],
    [
      "                ",
      "                ",
      "           AAAAA",
      "         AI     ",
      "         I      ",
      "        A  jmmdD",
      "        A  m    ",
      "        A  m    ",
      "        A  d   J",
      "        I  D    ",
      "        A  m   J",
      "        A  m    ",
      "        I  m   J",
      "        A  m    ",
      "        A  D    ",
      "        A  dxxxK"
    ],
    [
      "                ",
      "                ",
      "           IIAIA",
      "         II     ",
      "         I      ",
      "        I  jmmdD",
      "        A  m    ",
      "        I  m    ",
      "        A  d    ",
      "        A  D    ",
      "        I  m    ",
      "        I  m    ",
      "        I  m    ",
      "        A  m    ",
      "        I  D    ",
      "        I  dxxxx"
    ],
    [
      "                ",
      "                ",
      "           AIIAI",
      "         AI     ",
      "         I      ",
      "        A  jmmdm",
      "        I  mLLLL",
      "        I  mLLLL",
      "        I  dLLL ",
      "        A  mLLLL",
      "        I  mLLL ",
      "        I  mLLLL",
      "        A  mLLL ",
      "        I  mLLLL",
      "        I  mLLLL",
      "        I  dxxxx"
    ]
  ]
}