{
  "name": "multi_laboratory_0_base5",
  "refpalette": "deceasedcraft:multi_laboratory_0/multi_laboratory_0_base5_palette",
  "xsize": 16,
  "zsize": 16,
  "slices": [
    [
      "vvvvvvvvvvvvvvvv",
      "vaaaaaaaaaaaaaaa",
      "vabbbbbbbbbbcccc",
      "vab===!====d    ",
      "vab========d    ",
      "vab========ddddd",
      "vab========d    ",
      "vabe ======d    ",
      "vab========d    ",
      "vabe ==ff==d    ",
      "vab =======d    ",
      "vab========d    ",
      "vab========d    ",
      "vab====g===d    ",
      "vabe=======d    ",
      "vadhhhhhhhhdhhhh"
    ],
    [
      "vvvvvvvvvvvvvvvv",
      "vaaaaaaaaaaaaaaa",
      "vabbbbbbbbbbcccc",
      "vabijkllllkh    ",
      "vabi kkkkkkh    ",
      "vabm  nnnn hhhhh",
      "vab             ",
      "vabe            ",
      "vabi  nnnn d    ",
      "vabe  n  n      ",
      "vab   nnnn      ",
      "vabop  q  r     ",
      "vabst kkkk      ",
      "vab  ukffk      ",
      "vabe  kkkk      ",
      "vadhhhhhhhhdhhhh"
    ],
    [
      "vvvvvvvvvvvvvvvv",
      "vaaaaaaaaaaaaaaa",
      "vabbbbbbbbbbcccc",
      "vabw   xlx h    ",
      "vabw       h    ",
      "vab        hhhhh",
      "vab             ",
      "vabe            ",
      "vabw       d    ",
      "vabe            ",
      "vab             ",
      "vabyA           ",
      "vabBC   u       ",
      "vab   D         ",
      "vabe   r        ",
      "vadhhhhhhhhdhhhh"
    ],
    [
      "vvvvvvvvvvvvvvvv",
      "vaaaaaaaaaaaaaaa",
      "vabbbbbbbbbbcccc",
      "vab        h    ",
      "vab        h    ",
      "vab        hhhhh",
      "vabj            ",
      "vabe            ",
      "vab        d    ",
      "vabe            ",
      "vab             ",
      "vab             ",
      "vab             ",
      "vab             ",
      "vabe            ",
      "vadhhhhhhhhdhhhh"
    ],
    [
      "vvvvvvvvvvvvvvvv",
      "vaaaaaaaaaaaaaaa",
      "vabbbbbbbbbbcccc",
      "vabj       h    ",
      "vab        h    ",
      "vabj       hhhhh",
      "vabj            ",
      "vabe            ",
      "vab        d    ",
      "vabe            ",
      "vab             ",
      "vab             ",
      "vab             ",
      "vab             ",
      "vabe            ",
      "vadhhhhhhhhdhhhh"
    ],
    [
      "vvvvvvvvvvvvvvvv",
      "vaaaaaaaaaaaaaaa",
      "vabbbbbbbbbbcccc",
      "vabeEEEE EEh    ",
      "vabeEEEEEEEh    ",
      "vabeEEEEEEEhhhhh",
      "vabeEEEEEEEEEEEE",
      "vabeEEEEEEEEEEEE",
      "vabFEEEEEEEdEEEE",
      "vabeEEEEEEEEEEEE",
      "vabeEEEEEEEEEEEE",
      "vabeEEEEEEEEEEEE",
      "vabeEEEEEEEEEEEE",
      "vabeEEEEEEEEEEEE",
      "vabeEEEEEEEEEEEE",
      "vadhhhhhhhhdhhhh"
    ]
  ]
}