{
  "name": "multi_laboratory_0_base1",
  "refpalette": "deceasedcraft:multi_laboratory_0/multi_laboratory_0_base1_palette",
  "xsize": 16,
  "zsize": 16,
  "slices": [
    [
      "vvvvvvvvvvvvvvvv",
      "vaaaaaaaaaaaaaaa",
      "vabbbbbbbbbbcccc",
      "vabdddddddde    ",
      "vabdddddddde    ",
      "vabddddddddeeeee",
      "vabddddddddfffff",
      "vabddddddddfffff",
      "vabffffffffeffff",
      "vabd!ddddddfffff",
      "vabddddddddfffff",
      "vabddddddddfffff",
      "vabddddddddfffff",
      "vabddddddddfffff",
      "vabddddddddfffff",
      "vabffffffffeffff"
    ],
    [
      "vvvvvvvvvvvvvvvv",
      "vaaaaaaaaaaaaaaa",
      "vabbbbbbbbbbcccc",
      "vab g g hiih    ",
      "vab     hjjh    ",
      "vab     h  hhhhh",
      "vab     k  l  m!",
      "vabnnno h  h   p",
      "vabbbbbbbbbe   q",
      "vabrror h  h   s",
      "vab     k  t   s",
      "vab     h  h   s",
      "vab     huuh   s",
      "vab     hiih   q",
      "vab g g hhhh    ",
      "vabhhhhhhhhe    "
    ],
    [
      "vvvvvvvvvvvvvvvv",
      "vaaaaaaaaaaaaaaa",
      "vabbbbbbbbbbcccc",
      "vabwgwgwhiih    ",
      "vab     hjjh    ",
      "vab     h  hhhhh",
      "vab     x  y    ",
      "vabABA ChDDh    ",
      "vabbbbbbbbbe   E",
      "vab F  IhJJh   K",
      "vab     x  L    ",
      "vab     h  h   M",
      "vab     huuh   M",
      "vab     hiih   E",
      "vabAgAgAhhhh    ",
      "vabhhhhhhhhe    "
    ],
    [
      "vvvvvvvvvvvvvvvv",
      "vaaaaaaaaaaaaaaa",
      "vabbbbbbbbbbcccc",
      "vabNgNgNh ih    ",
      "vab     hOOh    ",
      "vab     h  hhhhh",
      "vab     h  h    ",
      "vabP P  h  h    ",
      "vabbbbbbbbbe   Q",
      "vabR  R h  h    ",
      "vab     h  h    ",
      "vab     h  h   S",
      "vab     hOOh    ",
      "vab     hi h   Q",
      "vabTgTgThhhh    ",
      "vabhhhhhhhhe    "
    ],
    [
      "vvvvvvvvvvvvvvvv",
      "vaaaaaaaaaaaaaaa",
      "vabbbbbbbbbbcccc",
      "vab     hUih    ",
      "vabUUUUUhUUh    ",
      "vabUUUUUhUUhhhhh",
      "vabUUUUUhUUh    ",
      "vabUUUUUhUUh    ",
      "vabbbbbbbbbe    ",
      "vabUUUUUhUUh    ",
      "vabUUUUUhUUh    ",
      "vabUUUUUhUUh    ",
      "vabUUUUUhUUh    ",
      "vabUUUUUhiUh    ",
      "vab     hhhh    ",
      "vabhhhhhhhhe    "
    ],
    [
      "vvvvvvvvvvvvvvvv",
      "vaaaaaaaaaaaaaaa",
      "vabbbbbbbbbbcccc",
      "vabViViViiihWWWW",
      "vab     hiihWWWW",
      "vab     h ihhhhh",
      "vab     h ihXXXX",
      "vab     hiihXXXX",
      "vabhhhhhhhieXXXX",
      "vab     h ihXXXX",
      "vab     h ihXXXX",
      "vab     h ihXXXX",
      "vab     h ihXXXX",
      "vab     hiihXXXX",
      "vabViViViihhXXXX",
      "vabYYYYYYYYeZZZZ"
    ]
  ]
}