{
  "name": "multi_laboratory_0_base6",
  "refpalette": "deceasedcraft:multi_laboratory_0/multi_laboratory_0_base6_palette",
  "xsize": 16,
  "zsize": 16,
  "slices": [
    [
      "vvvvvvvvvvvvvvvv",
      "vaaaaaaaaaaaaaaa",
      "vabbbbbbbbbbcccc",
      "vabdddddddde    ",
      "vabdddddddde    ",
      "vabddddddddeeeee",
      "vabddddddddffff!",
      "vabddddddddfffff",
      "vabffffffffeffff",
      "vabddddddddfffff",
      "vabddddddddfffff",
      "vabddddddddfffff",
      "vabddddddddfffff",
      "vabddddddddfffff",
      "vabddddddddfffff",
      "vabffffffffeffff"
    ],
    [
      "vvvvvvvvvvvvvvvv",
      "vaaaaaaaaaaaaaaa",
      "vabbbbbbbbbbcccc",
      "vabghghghghi    ",
      "vabg g g g i    ",
      "vabjkjkjkjkeiiii",
      "vab        l    ",
      "vabmmnnnnmmi    ",
      "vabiiiiiiiieo   ",
      "vabppqqqqppi    ",
      "vab        r    ",
      "vab        i    ",
      "vabststststiu   ",
      "vab w w w wiu   ",
      "vabxwxwxwxwi!y  ",
      "vaeiiiiiiiieiiiA"
    ],
    [
      "vvvvvvvvvvvvvvvv",
      "vaaaaaaaaaaaaaaa",
      "vabbbbbbbbbbcccc",
      "vabg g g g i    ",
      "vabg g g g i    ",
      "vabjBjBjBjBeiiii",
      "vab        C DD ",
      "vabE      Ei    ",
      "vabiiiiiiiie    ",
      "vabE      Fi    ",
      "vab        I    ",
      "vab        i    ",
      "vabJtJtJtJti    ",
      "vab w w w wi    ",
      "vab w w w wi    ",
      "vaeiiiiiiiieiiiK"
    ],
    [
      "vvvvvvvvvvvvvvvv",
      "vaaaaaaaaaaaaaaa",
      "vabbbbbbbbbbcccc",
      "vabg g g g i    ",
      "vabg g g g i    ",
      "vabjjjjjjjjiiiii",
      "vab        i  L ",
      "vab MNNNNO i    ",
      "vabiiiiiiiie    ",
      "vab PQQQQR i    ",
      "vab        i    ",
      "vab        i    ",
      "vabtttttttti    ",
      "vab w w w wi    ",
      "vab w w w wi    ",
      "vaeiiiiiiiieiiiS"
    ],
    [
      "vvvvvvvvvvvvvvvv",
      "vaaaaaaaaaaaaaaa",
      "vabbbbbbbbbbcccc",
      "vabTUTUTUTUi    ",
      "vabTTTTTTTTi    ",
      "vabTTTTTTTTiiiii",
      "vabTTTTTTTTi    ",
      "vabTTTTTTTTi    ",
      "vabiiiiiiiie    ",
      "vabTTTTTTTTi    ",
      "vabTTTTTTTTi    ",
      "vabTTTTTTTTi    ",
      "vabTTTTTTTTi    ",
      "vabTTTTTTTTi    ",
      "vabUTUTUTUTi    ",
      "vaeiiiiiiiieiiii"
    ],
    [
      "vvvvvvvvvvvvvvvv",
      "vaaaaaaaaaaaaaaa",
      "vabbbbbbbbbbcccc",
      "vab V V V Vi    ",
      "vab V V V Vi    ",
      "vab V V V Viiiii",
      "vab V V V Vi    ",
      "vabVVVVVVVVi    ",
      "vabiiiiiiiie    ",
      "vabVVVVVVVVi    ",
      "vabV V V V i    ",
      "vabV V V V i    ",
      "vabV V V V i    ",
      "vabV V V V i    ",
      "vabV V V V i    ",
      "vaeiiiiiiiieiiii"
    ]
  ]
}