{
  "name": "multi_laboratory_0_base7",
  "refpalette": "deceasedcraft:multi_laboratory_0/multi_laboratory_0_base7_palette",
  "xsize": 16,
  "zsize": 16,
  "slices": [
    [
      "vvvvvvvvvvvvvvvv",
      "vaaaaaaaaaaaabac",
      "vaaaaaaaaaaaaaca",
      "vaaaaaaaaaaaacaa",
      "vaaaaaaaaaaaacac",
      "vaaaaaaaaaacacac",
      "vaaaaaaaaaaaaccd",
      "vaaaaaaaaaaabdad",
      "vaaaaaaaaaabbcba",
      "vaaaaaaaaabbbecf",
      "vaaaaaaaacbbccff",
      "vaaaaaaaacbccbaa",
      "vaaaaaaaabcbbcaa",
      "vaaaaaaaccbbacaa",
      "vaaaaaaaccbaacaa",
      "vaaaaaacbbbaacaa"
    ],
    [
      "vvvvvvvvvvvvvvvv",
      "vaaaaaaaaaaaaaaa",
      "vaaaaaaaaaaagggg",
      "vaaaaaaaaaaaahij",
      "vaaaaaaaaaaad   ",
      "vaaaaaaaaadkl   ",
      "vaaaaaaaaaad    ",
      "vaaaaaaaaad     ",
      "vaaaaaaaamd     ",
      "vaaaaaaaaaffd   ",
      "vaaaaaaaaaaaadno",
      "vaaaaaaaaaaaafff",
      "vaaaaaaaaaaaaaaa",
      "vaaaaaaaafaaaaaa",
      "vaaaaaaafaaaaaaa",
      "vaaaafddfbaacaaa"
    ],
    [
      "vvvvvvvvvvvvvvvv",
      "vaaaaaaaaaaaaaaa",
      "vaaaaaaaaaaagggg",
      "vaaaaaaaaaaa    ",
      "vaaaaaaaaaad    ",
      "vaaaaaaaaa kp   ",
      "vaaaaaaaaf      ",
      "vaaaaaaafd      ",
      "vaaaaaaaq       ",
      "vaaaaaaaad n    ",
      "vaaaaaaaaadfq  r",
      "vaaaaaaaaaafff o",
      "vaaaaaqddfaaaaff",
      "vaaaaas dqfaaaaa",
      "vaaaaf   fcabaaa",
      "vaaafq   faabaaa"
    ],
    [
      "vvvvvvvvvvvvvvvv",
      "vaaaaaaaaaaaaaaa",
      "vaaaaaaaaaaagggg",
      "vaaaaaaaaaa     ",
      "vaaaaaaaaa      ",
      "vaaaaaaaaa k    ",
      "vaaaaaaafn      ",
      "vaaaaaaa        ",
      "vaaaaaaaq       ",
      "vaaaaaaa     t  ",
      "vaaaaaaa   oq  u",
      "vaaaaaa   aaf tn",
      "vaaaaaq  oaaafff",
      "vaaaaa   qfaaaaa",
      "vaaaf    nfaaaaa",
      "vaaaaq   bbbaaaa"
    ],
    [
      "vvvvvvvvvvvvvvvv",
      "vaaaaaaaaaaaaaaa",
      "vaaaaaaaaaaagggg",
      "vaaaaaaaaaaa    ",
      "vaaaaaaaaaam    ",
      "vaaaaaaaaack    ",
      "vaaaaaaaaem     ",
      "vaaaaaaaf       ",
      "vaaaaaaaq      t",
      "vaaaaaaam   mw  ",
      "vaaaaaaa   namtw",
      "vaaaaaa   aaaaaf",
      "vaaaaaq  naaaaaa",
      "vaaaaam  qfaaaaa",
      "vaaaaa    aaaaaa",
      "vaaaaq   eaaaaaa"
    ],
    [
      "vvvvvvvvvvvvvvvv",
      "vaaaaaaaaaaaaaaa",
      "vaaaaaaaaaaagggg",
      "vaaaaaaaaaaa    ",
      "vaaaaaaaaaaa    ",
      "vaaaaaaaaaakmm  ",
      "vaaaaaaaaaaaaxmm",
      "vaaaaaaaaaaacafm",
      "vaaaaaaaammaafaf",
      "vaaaaaaaamaaafff",
      "vaaaaaaaamaaaaff",
      "vaaaaaaaaaaaaaaa",
      "vaaaaaaamfaaaaaa",
      "vaaaaaaaaaaaaaaa",
      "vaaaaaaaaaaaaaaa",
      "vaaaaaamaaaaaaaa"
    ]
  ]
}