{
  "name": "multi_laboratory_0_base4",
  "refpalette": "deceasedcraft:multi_laboratory_0/multi_laboratory_0_base4_palette",
  "xsize": 16,
  "zsize": 16,
  "slices": [
    [
      "vvvvvvvvvvvvvvvv",
      "vaaaaaaaaaaaaaaa",
      "vabbbbbbbbbbcccc",
      "vabdddddddde    ",
      "vabdddddddde    ",
      "vabddddddddeeeee",
      "vabddddddddfffff",
      "vabddddddddfffff",
      "vabffffffffeffff",
      "vabddddddddfffff",
      "vabddddddddfffff",
      "vabddddddddfffff",
      "vabddddddddfffff",
      "vabddddddddfffff",
      "vabddddddddfffff",
      "vabffffffffeffff"
    ],
    [
      "vvvvvvvvvvvvvvvv",
      "vaaaaaaaaaaaaaaa",
      "vabbbbbbbbbbcccc",
      "vab g g hiih    ",
      "vab     hjjh    ",
      "vab     h  hhhhh",
      "vab     k  l   m",
      "vabnooo h  h   p",
      "vabbbbbbbbbe   q",
      "vabrrnr h  h   s",
      "vab     t  u   s",
      "vab     h  h   s",
      "vab     hwwh   s",
      "vab     hiih   q",
      "vab g g hhhh    ",
      "vabhhhhhhhhe    "
    ],
    [
      "vvvvvvvvvvvvvvvv",
      "vaaaaaaaaaaaaaaa",
      "vabbbbbbbbbbcccc",
      "vabxgxgxhiih    ",
      "vab     hjjh    ",
      "vab     h  hhhhh",
      "vab     y  A   B",
      "vabC C DhEEh    ",
      "vabbbbbbbbbe   m",
      "vab F  IhJJh   K",
      "vab     L  M    ",
      "vab     h  h   N",
      "vab     hwwh   N",
      "vab     hiih   m",
      "vabCgCgChhhh    ",
      "vabhhhhhhhhe    "
    ],
    [
      "vvvvvvvvvvvvvvvv",
      "vaaaaaaaaaaaaaaa",
      "vabbbbbbbbbbcccc",
      "vabOgOgOh ih    ",
      "vab     hPPh    ",
      "vab     h  hhhhh",
      "vab     h  h   Q",
      "vabR R  h  h    ",
      "vabbbbbbbbbe   B",
      "vabS  S h  h    ",
      "vab     h  h    ",
      "vab     h  h   T",
      "vab     hPPh   !",
      "vab     hi h   B",
      "vabUgUgUhhhh    ",
      "vabhhhhhhhhe    "
    ],
    [
      "vvvvvvvvvvvvvvvv",
      "vaaaaaaaaaaaaaaa",
      "vabbbbbbbbbbcccc",
      "vab     hVih    ",
      "vabVVVVVhVVh    ",
      "vabVVVVVhVVhhhhh",
      "vabVVVVVhVVh    ",
      "vabVVVVVhVVh    ",
      "vabbbbbbbbbe    ",
      "vabVVVVVhVVh    ",
      "vabVVVVVhVVh    ",
      "vabVVVVVhVVh    ",
      "vabVVVVVhVVh    ",
      "vabVVVVVhiVh    ",
      "vab     hhhh    ",
      "vabhhhhhhhhe    "
    ],
    [
      "vvvvvvvvvvvvvvvv",
      "vaaaaaaaaaaaaaaa",
      "vabbbbbbbbbbcccc",
      "vabWiWiWiiih    ",
      "vab     hiih    ",
      "vab     h ihhhhh",
      "vab     h ihXXXX",
      "vab     hiihXXXX",
      "vabhhhhhhhieXXXX",
      "vab     h ihXXXX",
      "vab     h ihXXXX",
      "vab     h ihXXXX",
      "vab     h ihXXXX",
      "vab     hiihXXXX",
      "vabWiWiWiihhXXXX",
      "vabhhhhhhhheYYYY"
    ]
  ]
}