{
  "name": "multi_laboratory_0_base2",
  "refpalette": "deceasedcraft:multi_laboratory_0/multi_laboratory_0_base2_palette",
  "xsize": 16,
  "zsize": 16,
  "slices": [
    [
      "vvvvvvvvvvvvvvvv",
      "vaaaaaaaaaaaaaaa",
      "vabbbbbbbbbbcccc",
      "vabdddddddde    ",
      "vabdddddddde    ",
      "vabddddddddeeeee",
      "vabddddddddfffff",
      "vabd!ddddddfffff",
      "vabffffffffeffff",
      "vabddddddddfffff",
      "vabddddddddfffff",
      "vabddddddddfffff",
      "vabddddddddfffff",
      "vabddddddddfffff",
      "vabddddddddfffff",
      "vabffffffffeffff"
    ],
    [
      "vvvvvvvvvvvvvvvv",
      "vaaaaaaaaaaaaaaa",
      "vabbbbbbbbbbcccc",
      "vab g g hiih    ",
      "vab     hjjh    ",
      "vab     h  hhhhh",
      "vab     k  l   m",
      "vabnono h  h   p",
      "vabbbbbbbbbe   q",
      "vabroor h  h   s",
      "vab     k  t   s",
      "vab     h  h   s",
      "vab     huuh   s",
      "vab     hiih   q",
      "vab g g hhhh    ",
      "vabhhhhhhhhe    "
    ],
    [
      "vvvvvvvvvvvvvvvv",
      "vaaaaaaaaaaaaaaa",
      "vabbbbbbbbbbcccc",
      "vabwgwgwhiih    ",
      "vab     hjjh    ",
      "vab     h  hhhhh",
      "vab     x  y    ",
      "vabA A BhCCh    ",
      "vabbbbbbbbbe   D",
      "vabE   FhIIh   J",
      "vab     x  K    ",
      "vab     h  h   L",
      "vab     huuh   L",
      "vab     hiih   D",
      "vabAgAgAhhhh    ",
      "vabhhhhhhhhe    "
    ],
    [
      "vvvvvvvvvvvvvvvv",
      "vaaaaaaaaaaaaaaa",
      "vabbbbbbbbbbcccc",
      "vabMgMgMh ih    ",
      "vab     hNNh    ",
      "vab     h  hhhhh",
      "vab     h  h    ",
      "vabO O  h  h    ",
      "vabbbbbbbbbe   P",
      "vabQ  Q h  h    ",
      "vab     h  h    ",
      "vab     h  h   R",
      "vab     hNNh    ",
      "vab     hi h   P",
      "vabSgSgShhhh    ",
      "vabhhhhhhhhe    "
    ],
    [
      "vvvvvvvvvvvvvvvv",
      "vaaaaaaaaaaaaaaa",
      "vabbbbbbbbbbcccc",
      "vab     hTih    ",
      "vabTTTTThTTh    ",
      "vabTTTTThTThhhhh",
      "vabTTTTThTTh    ",
      "vabTTTTThTTh    ",
      "vabbbbbbbbbe    ",
      "vabTTTTThTTh    ",
      "vabTTTTThTTh    ",
      "vabTTTTThTTh    ",
      "vabTTTTThTTh    ",
      "vabTTTTThiTh    ",
      "vab     hhhh    ",
      "vabhhhhhhhhe    "
    ],
    [
      "vvvvvvvvvvvvvvvv",
      "vaaaaaaaaaaaaaaa",
      "vabbbbbbbbbbcccc",
      "vabUiUiUiiih    ",
      "vab     hiih    ",
      "vab     h ihhhhh",
      "vab     h ihVVVV",
      "vab     hiihVVVV",
      "vabhhhhhhhieVVVV",
      "vab     h ihVVVV",
      "vab     h ihVVVV",
      "vab     h ihVVVV",
      "vab     h ihVVVV",
      "vab     hiihVVVV",
      "vabUiUiUiihhVVVV",
      "vabhhhhhhhheWWWW"
    ]
  ]
}