{
  "name": "multi_terraceplaza_29_floor1",
  "refpalette": "deceasedcraft:multi_terraceplaza_29/multi_terraceplaza_29_floor1_palette",
  "xsize": 16,
  "zsize": 16,
  "slices": [
    [
      "    a           ",
      "        b       ",
      "        b       ",
      "        b       ",
      "        cd      ",
      "        ed      ",
      "        cd      ",
      "        ed      ",
      "        cd      ",
      "        cd      ",
      "        ed      ",
      "ffffag  ed      ",
      " fh ig  cd      ",
      " fj ig  ed      ",
      " fjjig  cd      ",
      "ffffig  cd      "
    ],
    [
      "kkkka   b       ",
      "llllk   b       ",
      "mmmlk   cd      ",
      "nnmlk   cd      ",
      "onmlk   cd      ",
      "onmlk   ed      ",
      "onmlk   cd      ",
      "onmlk   ed      ",
      "nnmlk   cd      ",
      "mmmlk   cd      ",
      "llllkp  ed      ",
      "kkkkaqrred      ",
      " fstkuw cd      ",
      " fttkuw ed      ",
      " fttkuw cd      ",
      "ffffkuw cd      "
    ],
    [
      "xxxxa   cd      ",
      "yyyAB   ed      ",
      "AAAAB   cd      ",
      "AAAAB   cd      ",
      "AAAAB   cd      ",
      "AAAAB   ed      ",
      "AAAAB   cd      ",
      "AAAAB   ed      ",
      "AAAAB   cd      ",
      "AAAAB   cd      ",
      "AAAAB   ed      ",
      "ffffaC  ed      ",
      " fsDEF  cd      ",
      " fDDEF  ed      ",
      " fDDEF  cd      ",
      "IfDDEF  cd      "
    ],
    [
      "JJJJa   cd      ",
      "KKL J   ed      ",
      "    J   cd      ",
      "    J   cd      ",
      "    J   cd      ",
      "    J   ed      ",
      "    J   cd      ",
      "MNffJ   ed      ",
      "  OfJ   cd      ",
      "OPQfJ   cd      ",
      "RSTfJ   ed      ",
      "ffffa   ed      ",
      " fUVfF  cd      ",
      " f  fF  ed      ",
      " f  fF  cd      ",
      "WffXfF  cd      "
    ],
    [
      "eeeea   cd      ",
      "YZ0 e   ed      ",
      "    e   cd      ",
      "    e   cd      ",
      "    e   cd      ",
      "    e   ed      ",
      "    e   cd      ",
      "12ffe   ed      ",
      "   be   cd      ",
      "   be   cd      ",
      "O3Ofe   ed      ",
      "ffffa   ed      ",
      " f4 f   cd      ",
      " f  bF  ed      ",
      " f  b   cd      ",
      "5ff6fF  cd      "
    ],
    [
      "eeeea   cd      ",
      "    e   ed      ",
      "    e   cd      ",
      "    e   cd      ",
      "    e   cd      ",
      "    e   ed      ",
      "    e   cd      ",
      "77ffe   ed      ",
      "   fe   cd      ",
      "   fe   cd      ",
      "  8fe   ed      ",
      "ffffa   ed      ",
      " f9 f   cd      ",
      " f  f   ed      ",
      " f  f   cd      ",
      "7ff#f   cd      "
    ]
  ]
}