{
  "name": "multi_terraceplaza_29_floor4",
  "refpalette": "deceasedcraft:multi_terraceplaza_29/multi_terraceplaza_29_floor4_palette",
  "xsize": 16,
  "zsize": 16,
  "slices": [
    [
      "aaaabaa cd      ",
      "aaaaaaa ed      ",
      "aaaaaaa cd      ",
      "aaaaaaa cd      ",
      "aaaaaaa cd      ",
      "aaaaaaa ed      ",
      "aaaaaaa cd      ",
      "aaaaaaa ed      ",
      "aaaaaaa cd      ",
      "aaaaaaa cd      ",
      "aaaaaaa ed      ",
      "ffffb   ed      ",
      " ghgf   cd      ",
      " g gf   ed      ",
      " gigf   cd      ",
      "ggggf   cd      "
    ],
    [
      "    b  jcd      ",
      "kkkk   jed      ",
      "kllk   jcd      ",
      "kmmk   jcd      ",
      "noonp  jcd      ",
      "qqrr   jed      ",
      "       jcd      ",
      "   sp  jed      ",
      "tuwxy  jcd      ",
      "AAAAA  jcd      ",
      "       jed      ",
      "BBBCbDD ed      ",
      " EFIf   cd      ",
      "   If   ed      ",
      "  iIf   cd      ",
      "    f   cd      "
    ],
    [
      "    b   cd      ",
      "        ed      ",
      "        cd      ",
      "        cd      ",
      "JK J    cd      ",
      "        ed      ",
      "        cd      ",
      "   s    ed      ",
      "tLLxy   cd      ",
      "MMMMM   cd      ",
      "        ed      ",
      "BBBNb   ed      ",
      "  O f   cd      ",
      "    f   ed      ",
      "  i f   cd      ",
      "    fPQQcd      "
    ],
    [
      "    b   cd      ",
      "        ed      ",
      "        cd      ",
      "        cd      ",
      "        cd      ",
      "        ed      ",
      "        cd      ",
      " RR     ed      ",
      "tSTUy   cd      ",
      "VVVVV   cd      ",
      "   W    ed      ",
      "BBBBb   ed      ",
      " EX fPQQcd      ",
      "  E fYQQed      ",
      "  i fZQQcd      ",
      "    fZ  cd      "
    ],
    [
      "    b   cd      ",
      "        ed      ",
      "        cd      ",
      "        cd      ",
      "        cd      ",
      "        ed      ",
      "        cd      ",
      "        ed      ",
      "        cd      ",
      "00000PQQcd      ",
      "11111YQQed      ",
      "2222bZQQed      ",
      "ZZ ZZZ  cd      ",
      "ZZZZZZ  ed      ",
      "333333  cd      ",
      "444444  cd      "
    ],
    [
      "    b   cd      ",
      "        ed      ",
      "        cd      ",
      "        cd      ",
      "        cd      ",
      "        ed      ",
      "00000PQQcd      ",
      "11111YQQed      ",
      "55555ZQQcd      ",
      "ZZZZZZ  cd      ",
      "ZZZZZZ  ed      ",
      "333333  ed      ",
      "444444  cd      ",
      "                ",
      "                ",
      "                "
    ]
  ]
}