{
  "name": "multi_terraceplaza_29_ground",
  "refpalette": "deceasedcraft:multi_terraceplaza_29/multi_terraceplaza_29_ground_palette",
  "xsize": 16,
  "zsize": 16,
  "slices": [
    [
      "aHHHbcddeeffgHHH",
      "hiiiacddceefgHHH",
      "hjjjacddckelgHHH",
      "h   acddckefgHHH",
      "    acddckefgHHH",
      "    acddckefgHHH",
      "    acddckefgHHH",
      "    acddckefgHHH",
      "aaaaacddckefgHHH",
      "ddddddddckelgHHH",
      "ddddddddckefgHHH",
      "mmmmbnodckefgHHH",
      "pmqrstddckefgHHH",
      "pmrrstddckelgHHH",
      "pmrrstddckefgHHH",
      "umrrstddckefgHHH"
    ],
    [
      "h   b   wwxx    ",
      "h   h    ywx    ",
      "    h     wA    ",
      "    h     wB    ",
      "    h     wB    ",
      "    h     wB    ",
      "    h     wB    ",
      "    h     wB    ",
      "hhhhh     wB    ",
      "          wA    ",
      "          wx    ",
      "mmmmb   C yx    ",
      "DmE!mt  F wx    ",
      " m Imt  F wA    ",
      "JmI mt  F wB    ",
      "KmmLmt  F wB    "
    ],
    [
      "   Mb           ",
      "         N      ",
      "          wO    ",
      "          w     ",
      "          w     ",
      "          w     ",
      "          w     ",
      "          w     ",
      "          w     ",
      "        F wO    ",
      "        F       ",
      "mmmmb   F N     ",
      "DmPImt  QR      ",
      " m  F   SRwO    ",
      " m  Ft  QRw     ",
      "TmmUm   QRw     "
    ],
    [
      "    b           ",
      "         B      ",
      "                ",
      "                ",
      "                ",
      "                ",
      "                ",
      "        F       ",
      "        F       ",
      "        F       ",
      "VV      SR      ",
      "mmmmb   SRB     ",
      "DmW m   QR      ",
      " m  m   SR      ",
      " m  m   QR      ",
      "XmmYm   QR      "
    ],
    [
      "    b           ",
      "         B      ",
      "                ",
      "                ",
      "                ",
      "        F       ",
      "        F       ",
      "        F       ",
      "        QR      ",
      "        QR      ",
      "ZZ      SR      ",
      "mmmmb   SRB     ",
      "DmW m   QR      ",
      " m  m   SR      ",
      "0m  m   QR      ",
      "mmmmm   QR      "
    ],
    [
      "    b           ",
      "                ",
      "                ",
      "        F       ",
      "        F       ",
      "        F       ",
      "        QR      ",
      "        SR      ",
      "        QR      ",
      "        QR      ",
      "11      SR      ",
      "mmmmb   SR      ",
      "rm2 3   QR      ",
      "rm  3   SR      ",
      "rmI 3   QR      ",
      "mmmm3   QR      "
    ]
  ]
}