{
  "name": "multi_terraceplaza_29_base2",
  "refpalette": "deceasedcraft:multi_terraceplaza_29/multi_terraceplaza_29_base2_palette",
  "xsize": 16,
  "zsize": 16,
  "slices": [
    [
      "HHHHaHHHHbbccccv",
      "HHHHHHHHHbbddddv",
      "HHHHHHHHHbbcdddv",
      "HHHHHHHHHbbcdddv",
      "HHHHHHHHHbbcdddv",
      "dddddddddbbcdddv",
      "dddddddddbbcdddv",
      "dddddddddbbcdddv",
      "ccccdddddbbcdddv",
      "bbbbbbbbbbbcdddv",
      "bbbbbbbbbbbcdddv",
      "ccccacddddcccccv",
      " cddcddddddceeev",
      " cddcddddddceeev",
      " cddcddddddceeev",
      "fcddcddddddceeev"
    ],
    [
      "gggga      ccccv",
      "           h   v",
      "           c  iv",
      "           c  iv",
      " j         c  kv",
      "    l   m  c  iv",
      "           c  iv",
      "           c k v",
      "ccccn   o  c  iv",
      "           c  iv",
      "           c   v",
      "ccccacppppcccccv",
      " cqqcr    rceeev",
      " cqqcs    sceeev",
      " c  cs    sceeev",
      "tccucs    sceeev"
    ],
    [
      "    a      ccccv",
      "           w   v",
      "           c  iv",
      "           c  iv",
      " j         c   v",
      "           c  iv",
      "           c  iv",
      "           c   v",
      "cccc       c  iv",
      "           c  iv",
      "           c   v",
      "ccccacppppcccccv",
      " cxycr    rceeev",
      " cA cB     ceeev",
      " c  c     Bceeev",
      "CccDcB    Bceeev"
    ],
    [
      "    a      ccccv",
      "          EF   v",
      "           c  Iv",
      "           c  Jv",
      " j         c  kv",
      "K          c  Lv",
      "K          c  Jv",
      "K          c   v",
      "cccc       c  Iv",
      "           c  Jv",
      "           c   v",
      "ccccacppppcccccv",
      " cM cr    rceeev",
      " c  cs    sceeev",
      " c  cs    sceeev",
      "NccFcs    sceeev"
    ],
    [
      "    a      cccOv",
      "           c  Ov",
      "           c  Pv",
      "       Q   c  Ov",
      "jj         c  Ov",
      "HHRK       c k!v",
      "HHRK       c kOv",
      "HHRK       c  Ov",
      "cccc       c  Pv",
      "           c  Ov",
      "           c  Ov",
      "ccccacccccccccOv",
      " cS crTTTTrceeOv",
      " c  c!    Bceeev",
      " c  cB     ceeev",
      "ccccc     Bceeev"
    ],
    [
      "UUUUaVVVVVVccccv",
      "VVVVUVVVVVVcVVVv",
      "VVVVUVVVVVVcVVVv",
      "VWVVUVVWVVVcVVVv",
      "VVVVUVVVVVVcVVVv",
      " XYHUVVVVVVcVVVv",
      " XYHUVVVVVVcVVVv",
      " XYHUVVVVVVcVVVv",
      "ccccUVVWVVVcVVVv",
      "VVVVUVVVVVVcVVVv",
      "VVVVUVVVVVVcVVVv",
      "UUUUaccccccccccv",
      " cZVUr    rceeOv",
      " cVVUs    sceeev",
      " cVVUs    sceeev",
      "ccccUs    sceeev"
    ]
  ]
}