{
  "name": "multi_terraceplaza_29_floor2",
  "refpalette": "deceasedcraft:multi_terraceplaza_29/multi_terraceplaza_29_floor2_palette",
  "xsize": 16,
  "zsize": 16,
  "slices": [
    [
      "aaaab   cd      ",
      "    a   ad      ",
      "    a   cd      ",
      "    a   cd      ",
      "    a   cd      ",
      "    a   ad      ",
      "    a   cd      ",
      "eeeea   ad      ",
      "   ea   cd      ",
      "   ea   cd      ",
      "   ea   ad      ",
      "eeeeb   ad      ",
      " ef e   cd      ",
      " e  e   ad      ",
      " e  e   cd      ",
      "eeeee   cd      "
    ],
    [
      "ggggb   cd      ",
      "    h   ad      ",
      "    h   cd      ",
      "    h   cd      ",
      "    h   cd      ",
      "    h   ad      ",
      "    h   cd      ",
      "eeeeh   ad      ",
      "    h   cd      ",
      "    h   cd      ",
      "    h   ad      ",
      "eeeeb   ad      ",
      " ei j   cd      ",
      " e  j   ad      ",
      " e  j   cd      ",
      "eeeej   cd      "
    ],
    [
      "kkkkbl  cd      ",
      "    m   ad      ",
      "    m   cd      ",
      "    m   cd      ",
      "    m   cd      ",
      "    m   ad      ",
      "    m   cd      ",
      "eeeem   ad      ",
      "    m   cd      ",
      "    m   cd      ",
      "    m   ad      ",
      "eeeebl  ad      ",
      " en jl  cd      ",
      " e  jl  ad      ",
      " e  jl  cd      ",
      "eeeejl  cd      "
    ],
    [
      "oooobpqqcd      ",
      "rrrrosttad      ",
      "rrrrosttcd      ",
      "rrrrosttcd      ",
      "rrrrosttcd      ",
      "rrrrosttad      ",
      "rrrrosttcd      ",
      "rrrrosttad      ",
      "rrrrosttcd      ",
      "rrrrosttcd      ",
      "rrrrosttad      ",
      "oooobpqqad      ",
      " euwoxy cd      ",
      " ewwoxy ad      ",
      " ewwoxy cd      ",
      "eeeeoxy cd      "
    ],
    [
      "wjjjbjjjcd      ",
      "wjjjjjjjad      ",
      "wjjjAAAjcd      ",
      "AjjjAAAjcd      ",
      "AjjjAAAjcd      ",
      "AjjjAAAjad      ",
      "AjjjAAAjcd      ",
      "AjjjAAAjad      ",
      "jjjjAAAjcd      ",
      "jjjjAAAjcd      ",
      "jjjjjjjjad      ",
      "eeeebB  ad      ",
      " euCDE  cd      ",
      " eCCDE  ad      ",
      " eCCDE  cd      ",
      "FeCCDE  cd      "
    ],
    [
      "I   b   cd      ",
      "I       ad      ",
      "I    J  cd      ",
      "     K  cd      ",
      "L    M  cd      ",
      "N       ad      ",
      "O       cd      ",
      "     P  ad      ",
      "    QR  cd      ",
      "     S  cd      ",
      "        ad      ",
      "eeeebTTTad      ",
      " eUVeE  cd      ",
      " e  eE  ad      ",
      " eW eE  cd      ",
      "XeeYeE  cd      "
    ]
  ]
}