{
  "name": "multi_terraceplaza_29_floor3",
  "refpalette": "deceasedcraft:multi_terraceplaza_29/multi_terraceplaza_29_floor3_palette",
  "xsize": 16,
  "zsize": 16,
  "slices": [
    [
      "a   b   cd      ",
      "a       ed      ",
      "a       cd      ",
      "        cd      ",
      "        cd      ",
      "        ed      ",
      "        cd      ",
      "        ed      ",
      "        cd      ",
      "     f  cd      ",
      "        ed      ",
      "ggggb   ed      ",
      " gh gi  cd      ",
      " g  j   ed      ",
      " gk j   cd      ",
      "lggmgi  cd      "
    ],
    [
      "a   b   cd      ",
      "an      ed      ",
      "a       cd      ",
      "        cd      ",
      "        cd      ",
      "        ed      ",
      "        cd      ",
      "        ed      ",
      "        cd      ",
      "        cd      ",
      "o o     ed      ",
      "ggggb   ed      ",
      " gp g   cd      ",
      " g  g   ed      ",
      " gk g   cd      ",
      "qggrg   cd      "
    ],
    [
      "a   b   cd      ",
      "a       ed      ",
      "a       cd      ",
      "        cd      ",
      "        cd      ",
      "        ed      ",
      "        cd      ",
      "        ed      ",
      "        cd      ",
      "        cd      ",
      " s      ed      ",
      "ggggb   ed      ",
      " gp g   cd      ",
      " g  g   ed      ",
      " gk g   cd      ",
      "ggggg   cd      "
    ],
    [
      "at  b   cd      ",
      "a       ed      ",
      "a       cd      ",
      "        cd      ",
      "        cd      ",
      "        ed      ",
      "        cd      ",
      "        ed      ",
      "        cd      ",
      "        cd      ",
      " u      ed      ",
      "ggggb   ed      ",
      " gp g   cd      ",
      " g  g   ed      ",
      " gk g   cd      ",
      "ggggg   cd      "
    ],
    [
      "a   b   cd      ",
      "a       ed      ",
      "a       cd      ",
      "        cd      ",
      "        cd      ",
      "        ed      ",
      "        cd      ",
      "        ed      ",
      "        cd      ",
      "        cd      ",
      "        ed      ",
      "ggggb   ed      ",
      " gw g   cd      ",
      " g  g   ed      ",
      " gk g   cd      ",
      "ggggg   cd      "
    ],
    [
      "a   b   cd      ",
      "a       ed      ",
      "a       cd      ",
      "x       cd      ",
      "x       cd      ",
      "x       ed      ",
      "x       cd      ",
      "x       ed      ",
      "x       cd      ",
      "x       cd      ",
      "x       ed      ",
      "ggggb   ed      ",
      " gyAg   cd      ",
      " g Ag   ed      ",
      " gkAg   cd      ",
      "ggggg   cd      "
    ]
  ]
}