{
  "name": "multi_terraceplaza_29_base1",
  "refpalette": "deceasedcraft:multi_terraceplaza_29/multi_terraceplaza_29_base1_palette",
  "xsize": 16,
  "zsize": 16,
  "slices": [
    [
      "HHHHaHHHHbbccccv",
      "HHHHHHHHHbbddddv",
      "HHHHHHHHHbbcdddv",
      "HHHHHHHHHbbcdddv",
      "HHHHHHHHHbbcdddv",
      "    efHHHbbcdddv",
      "    efHHHbbcdddv",
      "    efHHHbbcdddv",
      "ccccdddddbbcdddv",
      "bbbbbbbbbbbcdddv",
      "bbbbbbbbbbbcdddv",
      "ccccaccccccccccv",
      " cgdch    hciijv",
      " cddck    kciiiv",
      " cddc      ciiiv",
      "lcddck    !ciiiv"
    ],
    [
      "mmmma      ccccv",
      "           n   v",
      "           c  ov",
      "           c  ov",
      "ppppp      c   v",
      "           c  ov",
      "           c  ov",
      "           c   v",
      "ccccp      c  ov",
      "           c  ov",
      "           c   v",
      "ccccaccccccccccv",
      " cqrch    hciijv",
      " c  c      ciiiv",
      " c  c      ciiiv",
      "scctc      ciiiv"
    ],
    [
      "    a      ccccv",
      "           u   v",
      "           c  ov",
      "           c  ov",
      " p  p      c   v",
      "           c  ov",
      "           c  ov",
      "           c   v",
      "ccccp      c  ov",
      "           c  ov",
      "           c   v",
      "ccccaccccccccccv",
      " cw ch    hciijv",
      " c  c      ciiiv",
      " c  c      ciiiv",
      "xccyc      ciiiv"
    ],
    [
      "    a      ccccv",
      "          AB   v",
      "           c   v",
      "           c  Cv",
      " p  p      c   v",
      "D          c  Ev",
      "D          c  Cv",
      "D          c   v",
      "ccccp      c  Fv",
      "           c  Cv",
      "           c   v",
      "ccccaccccccccccv",
      " cI cJJJJJJciijv",
      " c  cJJJJJJciiiv",
      " c  cJJJJJKciiiv",
      "LccBcJJJJJJciiiv"
    ],
    [
      "    a      cccjv",
      "           c  jv",
      "           c  Mv",
      "           c  jv",
      "ppppp      c  jv",
      "HHNDp      c  Mv",
      "HHNDp      c  jv",
      "HHNDp      c  jv",
      "ccccp  O   c  Mv",
      "           c  jv",
      "           c  jv",
      "ccccacccccPcccjv",
      " cQ ciiiiijjjjjv",
      " c  ciiiiijciiiv",
      " c  ciiiiijciiiv",
      "ccccciiiiijciiiv"
    ],
    [
      "RRRRaJJJJJJccccv",
      "pHHHRJJJJJJcJJJv",
      "pHHHRJJJJJJcJJJv",
      "pHHHRJJSJJJcJJJv",
      "pTTTRJJJJJJcJJJv",
      " eeeRJJJJJJcJJJv",
      " eeeRJJJJJJcJJJv",
      " eeeRJJJJJJcJJJv",
      "UcccRJJSJJJcJJJv",
      "VVVVRJJJJJJcJJJv",
      "JJJJRJJJJJJcJJJv",
      "RRRRaWcccccccccv",
      " cgJRXiiiiiciiiv",
      " cJJRXiiiiiciiiv",
      " cJJRXiiiiiciiiv",
      "ccccRXiiiiiciiiv"
    ]
  ]
}