{
  "name": "multi_casino_10_base7",
  "refpalette": "deceasedcraft:multi_casino_10/multi_casino_10_base7_palette",
  "xsize": 16,
  "zsize": 16,
  "slices": [
    [
      "                ",
      "                ",
      "                ",
      "                ",
      "                ",
      "                ",
      "                ",
      "a       b       ",
      "                ",
      "                ",
      "                ",
      "                ",
      "                ",
      "                ",
      "                ",
      "                "
    ],
    [
      "                ",
      "                ",
      "                ",
      "                ",
      "                ",
      "                ",
      "                ",
      "a       b       ",
      "                ",
      "                ",
      "                ",
      "                ",
      "                ",
      "                ",
      "               c",
      "                "
    ],
    [
      "                ",
      "                ",
      "                ",
      "                ",
      "                ",
      "                ",
      "        d       ",
      "a      ebf      ",
      "        g       ",
      "                ",
      "                ",
      "                ",
      "                ",
      "                ",
      "               h",
      "            c   "
    ],
    [
      "                ",
      "                ",
      "                ",
      "                ",
      "                ",
      "                ",
      "                ",
      "a       b       ",
      "                ",
      "                ",
      "                ",
      "                ",
      "                ",
      "                ",
      "               h",
      "            h  h"
    ],
    [
      "ijiiiiiiiiiiiiij",
      "iijiiiiiiiiiiiji",
      "iiijiiiiiiiiijii",
      "iiiikiiikiiikiii",
      "iiiiijiiiiijiiii",
      " iiiiijiiijiiiii",
      " iiiiiijijiiiiii",
      "liiikiiibiiikiii",
      " iiiiiijijiiiiii",
      " iiiiijiiijiiijj",
      "iiiiijiiiiijjjj ",
      "iiiikiiikiijl   ",
      "iiijiiiiiiij m  ",
      "iijiiiiiiijj  m ",
      "ijiiiiiiiij    n",
      "kiiikiiikijhh   "
    ],
    [
      "obooooooooooooob",
      "oobooooooooooobo",
      "oooboooooooooboo",
      "oooobooopooobooo",
      "oooooboooooboooo",
      "qooooobooobooooo",
      "qooooooboboooooo",
      "qooopooobooopooo",
      "qooooooboboooooo",
      "qooooobooobooooo",
      "ooooobooooobooon",
      "oooobooopooobppp",
      "oooboooooooopbpp",
      "ooboooooooooppbp",
      "obooooooooonpppb",
      "booopooopoonnppp"
    ]
  ]
}