{
  "name": "multi_casino_10_base1",
  "refpalette": "deceasedcraft:multi_casino_10/multi_casino_10_base1_palette",
  "xsize": 16,
  "zsize": 16,
  "slices": [
    [
      "                ",
      "                ",
      "                ",
      "                ",
      "                ",
      "       aaa      ",
      "      b c d     ",
      "e     bfghd     ",
      "      b i d     ",
      "       jjj      ",
      "                ",
      "                ",
      "                ",
      "                ",
      "                ",
      "                "
    ],
    [
      "                ",
      "                ",
      "                ",
      "                ",
      "                ",
      "                ",
      "                ",
      "e       g       ",
      "                ",
      "                ",
      "                ",
      "                ",
      "                ",
      "                ",
      "                ",
      "                "
    ],
    [
      "                ",
      "                ",
      "                ",
      "                ",
      "                ",
      "                ",
      "        k       ",
      "e      lgm      ",
      "        n       ",
      "                ",
      "                ",
      "                ",
      "                ",
      "                ",
      "                ",
      "                "
    ],
    [
      "                ",
      "                ",
      "                ",
      "                ",
      "                ",
      "                ",
      "                ",
      "e       g       ",
      "                ",
      "                ",
      "                ",
      "                ",
      "                ",
      "                ",
      "                ",
      "                "
    ],
    [
      "opooooooooooooop",
      "oopooooooooooopo",
      "ooopooooooooopoo",
      "ooooqoooqoooqooo",
      "ooooopooooopoooo",
      " ooooopooopooooo",
      " oooooopopoooooo",
      "roooqooogoooqooo",
      " oooooopopoooooo",
      " ooooopooopooooo",
      "ooooopooooopoooo",
      "ooooqoooqoooqooo",
      "ooopooooooooopoo",
      "oopooooooooooopo",
      "opooooooooooooop",
      "qoooqoooqoooqooo"
    ],
    [
      "sgsssssssssssssg",
      "ssgsssssssssssgs",
      "sssgsssssssssgss",
      "ssssgssstsssgsss",
      "sssssgsssssgssss",
      "usssssgsssgsssss",
      "ussssssgsgssssss",
      "ussstsssgssstsss",
      "ussssssgsgssssss",
      "usssssgsssgsssss",
      "sssssgsssssgssss",
      "ssssgssstsssgsss",
      "sssgsssssssssgss",
      "ssgsssssssssssgs",
      "sgsssssssssssssg",
      "gssstssstssstsss"
    ]
  ]
}