{
  "name": "multi_casino_10_base9",
  "refpalette": "deceasedcraft:multi_casino_10/multi_casino_10_base9_palette",
  "xsize": 16,
  "zsize": 16,
  "slices": [
    [
      "aaaaaaaaaaaaaaaa",
      "aaaaaaaaaaaaaaaa",
      "aaaaaaaaaaaaaaaa",
      "aaaaaaaaaaaaaaaa",
      "aaaaaaaaaaaaaaaa",
      "aaaaaaaaaaaaaaaa",
      "aaaaaaaaaaaaaaaa",
      "aaaaaaaaaaaaaaaa",
      "aaaaaaaaaaaaaaaa",
      "aaaaaaaaaaaaaaaa",
      "aaaaaaaaaaaaaaaa",
      "aaaaaaaaaaaaaaaa",
      "aaaaaaaaaaaaaaaa",
      "aaaaaaaaaaaaaaaa",
      "aaaaaaaaaaaaaaaa",
      "aaaaaaaaaaaaaaaa"
    ],
    [
      "  @bbbbbcbbbbbbb",
      " @bbbbbbbbbbbbbb",
      "@bbbbbbbbbbbbbbb",
      "cbbbbbbbbbbbbbbb",
      "bbbbbbbbbbbbbbbb",
      "@bbbbbbbbbbbbbbb",
      "@bbbbbbbbbbbbbbb",
      "@cbbbbbbdbbbbbbe",
      "@bbbbbbbbbbbbbee",
      "@bbbbbbbbbbbeeee",
      "bbbbbbbbbbbeeeee",
      "cbbbbbbbbbeeeeee",
      "bbbbbbbbbbeeeeee",
      "bbbbbbbbbeeeeeee",
      "bbbbbbbbeeeeeeee",
      "bbbbbbbbeeeeeeee"
    ],
    [
      "  @bbbbbcbbbbbbb",
      " @bbbbbbbbbbbbbb",
      "@bbbbbbbbbbbbbbb",
      "cbbbbbbbbbbbbbbb",
      "bbbbbbbbbbbbbbbb",
      "@bbbbbbbbbbbbbbb",
      "@bbbbbbbbbbbbbbb",
      "@cbbbbbbdbbbbbbe",
      "@bbbbbbbbbbbbbee",
      "@bbbbbbbbbbbeeee",
      "bbbbbbbbbbbeeeee",
      "cbbbbbbbbbeeeeee",
      "bbbbbbbbbbeeeeee",
      "bbbbbbbbbeeeeeee",
      "bbbbbbbbeeeeeeee",
      "bbbbbbbbeeeeeeee"
    ],
    [
      "  @bbbbbcbbbbbbb",
      " @bbbbbbbbbbbbbb",
      "@bbbbbbbbbbbbbbb",
      "cbbbbbbbbbbbbbbb",
      "bbbbbbbbbbbbbbbb",
      "@bbbbbbbbbbbbbbb",
      "@bbbbbbbbbbbbbbb",
      "@cbbbbbbdbbbbbbe",
      "@bbbbbbbbbbbbbee",
      "@bbbbbbbbbbbeeee",
      "bbbbbbbbbbbeeeee",
      "cbbbbbbbbbeeeeee",
      "bbbbbbbbbbeeeeee",
      "bbbbbbbbbeeeeeee",
      "bbbbbbbbeeeeeeee",
      "bbbbbbbbeeeeeeee"
    ],
    [
      "  @bbbbbbbbbbbbb",
      " @bbbbbbbbbbbbbb",
      "@bbbbbbbbbbbbbbb",
      "cbbbbbbbbbbbbbbb",
      "bbbbbbbbbbbbbbbb",
      "fbbbbbbbbbbbbbbb",
      "fbbbbbbbbbbbbbbb",
      "fbbbbbbbdbbbbbbe",
      "fbbbbbbbbbbbbbee",
      "fbbbbbbbbbbbeeee",
      "bbbbbbbbbbbeeeee",
      "bbbbbbbbbbeeeeee",
      "bbbbbbbbbbeeeeee",
      "bbbbbbbbbeeeeeee",
      "bbbbbbbbeeeeeeee",
      "bbbbbbbbeeeeeeee"
    ],
    [
      "gdfbbbbbbbbbbbbd",
      "gfdbbbbbbbbbbbdb",
      "fbbdbbbbbbbbbdbb",
      "bbbbdbbbbbbbdbbb",
      "bbbbbdbbbbbdbbbb",
      "fbbbbbdbbbdbbbbb",
      "fbbbbbbdbdbbbbbb",
      "fbbbbbbbdbbbbbbe",
      "fbbbbbbdbdbbbbee",
      "fbbbbbdbbbdbeeee",
      "bbbbbdbbbbbdeeee",
      "bbbbdbbbbbeedeee",
      "bbbdbbbbbbeeedee",
      "bbdbbbbbbeeeeede",
      "bdbbbbbbeeeeeeed",
      "dbbbbbbbeeeeeeee"
    ]
  ]
}