{
  "name": "multi_casino_10_base3",
  "refpalette": "deceasedcraft:multi_casino_10/multi_casino_10_base3_palette",
  "xsize": 16,
  "zsize": 16,
  "slices": [
    [
      "                ",
      "                ",
      "                ",
      "                ",
      "                ",
      "                ",
      "                ",
      "a       b       ",
      "                ",
      "                ",
      "                ",
      "                ",
      "                ",
      "                ",
      "                ",
      "                "
    ],
    [
      "                ",
      "                ",
      "                ",
      "                ",
      "                ",
      "                ",
      "                ",
      "a       b       ",
      "                ",
      "                ",
      "                ",
      "                ",
      "                ",
      "                ",
      "                ",
      "                "
    ],
    [
      "                ",
      "                ",
      "                ",
      "                ",
      "                ",
      "                ",
      "        c       ",
      "a      dbe      ",
      "        f       ",
      "                ",
      "                ",
      "                ",
      "                ",
      "                ",
      "                ",
      "                "
    ],
    [
      "                ",
      "                ",
      "                ",
      "                ",
      "                ",
      "                ",
      "                ",
      "a       b       ",
      "                ",
      "                ",
      "                ",
      "                ",
      "                ",
      "                ",
      "                ",
      "                "
    ],
    [
      "ghgggggggggggggh",
      "gghggggggggggghg",
      "ggghggggggggghgg",
      "ggggigggigggiggg",
      "ggggghggggghgggg",
      " ggggghggghggggg",
      " gggggghghgggggg",
      "jgggigggbgggiggg",
      " gggggghghgggggg",
      " ggggghggghggggg",
      "ggggghggggghgggg",
      "ggggigggigggiggg",
      "ggghggggggggghgg",
      "gghggggggggggghg",
      "ghgggggggggggggh",
      "igggigggigggiggg"
    ],
    [
      "kbkkkkkkkkkkkkkb",
      "kkbkkkkkkkkkkkbk",
      "kkkbkkkkkkkkkbkk",
      "kkkkbkkklkkkbkkk",
      "kkkkkbkkkkkbkkkk",
      "mkkkkkbkkkbkkkkk",
      "mkkkkkkbkbkkkkkk",
      "mkkklkkkbkkklkkk",
      "mkkkkkkbkbkkkkkk",
      "mkkkkkbkkkbkkkkk",
      "kkkkkbkkkkkbkkkk",
      "kkkkbkkklkkkbkkk",
      "kkkbkkkkkkkkkbkk",
      "kkbkkkkkkkkkkkbk",
      "kbkkkkkkkkkkkkkb",
      "bkkklkkklkkklkkk"
    ]
  ]
}