{
  "name": "multi_casino_10_base2",
  "refpalette": "deceasedcraft:multi_casino_10/multi_casino_10_base2_palette",
  "xsize": 16,
  "zsize": 16,
  "slices": [
    [
      "aaaaaaaaaaaaaaaa",
      "aaaaaaaaaaaaaaaa",
      "aaaaaaaaaaaaaaaa",
      "aaaaaaaaaaaaaaaa",
      "aaaaaaaaaaaaaaaa",
      "baaaaaaaaaaaaaaa",
      "baaaaaaaaaaaaaaa",
      "baaaaaaacaaaaaaa",
      "baaaaaaaaaaaaaaa",
      "baaaaaaaaaaaaaaa",
      "aaaaaaaaaaaaaaaa",
      "aaaaaaaaaaaaaaaa",
      "aaaaaaaaaaaaaaaa",
      "aaaaaaaaaaaaaaaa",
      "aaaaaaaaaaaaaaaa",
      "aaaaaaaaaaaaaaaa"
    ],
    [
      "       def      ",
      "                ",
      "                ",
      "                ",
      "                ",
      "g        hijj   ",
      "gk      l  mmn o",
      "gp     jc qrmn o",
      "gs    t   ummnwo",
      "g     x y mmmn o",
      "      lm!mmmA  o",
      "      lmmmmA  oo",
      "       BBBB  Coo",
      "         C  oooo",
      "       ooooooooo",
      "       oooooooD "
    ],
    [
      "                ",
      "                ",
      "                ",
      "                ",
      "                ",
      "                ",
      "                ",
      "g       c      E",
      "                ",
      "               F",
      "               I",
      "                ",
      "              J ",
      "            K F ",
      "       IL E  EM ",
      "       NM O NF  "
    ],
    [
      "                ",
      "                ",
      "                ",
      "                ",
      "                ",
      "b               ",
      "b               ",
      "b       c       ",
      "b               ",
      "b               ",
      "                ",
      "                ",
      "                ",
      "                ",
      "                ",
      "                "
    ],
    [
      "                ",
      "                ",
      "                ",
      "                ",
      "                ",
      "g               ",
      "g               ",
      "g       c       ",
      "g               ",
      "g               ",
      "                ",
      "                ",
      "                ",
      "                ",
      "                ",
      "                "
    ],
    [
      "                ",
      "                ",
      "                ",
      "                ",
      "                ",
      "                ",
      "                ",
      "g       c       ",
      "                ",
      "g               ",
      "                ",
      "                ",
      "                ",
      "                ",
      "                ",
      "                "
    ]
  ]
}