{
  "name": "multi_casino_10_base4",
  "refpalette": "deceasedcraft:multi_casino_10/multi_casino_10_base4_palette",
  "xsize": 16,
  "zsize": 16,
  "slices": [
    [
      "aaaaaaaaaaaaaaaa",
      "aaaaaaaaaaaaaaaa",
      "aaaaaaaaaaaaaaaa",
      "aaaaaaaaaaaaaaaa",
      "aaaaaaabcdaaaaaa",
      "eaaaaaaaaaaaaaaa",
      "eaaaafaaaaaaaaaa",
      "eaaaa aagaaaaaaa",
      "eaaaa!aaaaaaaaaa",
      "eaaaaaaaaaaaaaaa",
      "aaaaaaaaaaaaaaaa",
      "aaaaaaaaaaaaaaaa",
      "aaaaaaaaaaaaaaaa",
      "aaaaaaaaaaaaaaaa",
      "aaaaaaaaaaaaaaaa",
      "aaaaaaaaaaaaaaaa"
    ],
    [
      "       hij      ",
      "                ",
      "                ",
      "       kkk      ",
      "     lmnopml  qr",
      "s    tu   wx yAB",
      "sC  kD    EF yAB",
      "sI  kJ  g EK LAB",
      "sM  kN       yAB",
      "s    tOPP    yAB",
      "     lQRS     Tr",
      "                ",
      "      qqUqq     ",
      "     yAAAAAV    ",
      "     rBBBBBr    ",
      "     rBBBBBr    "
    ],
    [
      "                ",
      "                ",
      "                ",
      "                ",
      "       W X      ",
      "                ",
      "     Y          ",
      "s    Z  g       ",
      "                ",
      "                ",
      "                ",
      "                ",
      "                ",
      "                ",
      "                ",
      "                "
    ],
    [
      "                ",
      "                ",
      "                ",
      "                ",
      "                ",
      "e               ",
      "e       0       ",
      "e      1g2      ",
      "e       3       ",
      "e               ",
      "                ",
      "                ",
      "                ",
      "                ",
      "                ",
      "                "
    ],
    [
      "                ",
      "                ",
      "                ",
      "                ",
      "                ",
      "s               ",
      "s       4       ",
      "s      5g6      ",
      "s               ",
      "s               ",
      "                ",
      "                ",
      "                ",
      "                ",
      "                ",
      "                "
    ],
    [
      "                ",
      "                ",
      "                ",
      "                ",
      "                ",
      "                ",
      "                ",
      "s       g       ",
      "                ",
      "s               ",
      "                ",
      "                ",
      "                ",
      "                ",
      "                ",
      "                "
    ]
  ]
}