{
  "name": "multi_casino_10_base6",
  "refpalette": "deceasedcraft:multi_casino_10/multi_casino_10_base6_palette",
  "xsize": 16,
  "zsize": 16,
  "slices": [
    [
      "aaaaaaaaaaaaaaaa",
      "aaaaaaaaaaaaaaaa",
      "aaaaaaaaaaaaaaaa",
      "aaaaaaaaaaaaaaaa",
      "aaaaaaaaaaaaaaaa",
      "baaaaaaaaaaaaaaa",
      "baaaaaaaaaaaaaaa",
      "baaaaaaacaaaaaaa",
      "baaaaaaaaaaaaaaa",
      "baaaaaaaaaaaaaaa",
      "aaaaaaaaaaaaaaaa",
      "aaaaaaaaaaaaaaaa",
      "aaaaaaaaaaaaaaaa",
      "aaaaaaaaaaaaaaaa",
      "aaaaaaaaaaaaaaaa",
      "aaaaaaaaaaaaaaaa"
    ],
    [
      "       def      ",
      "                ",
      "                ",
      "                ",
      "             ghg",
      "i            jjj",
      "ik         gjlll",
      "im      c  njl l",
      "io         gjlll",
      "i            jjj",
      "       ghg   gpg",
      "       jjj      ",
      "     gjllljg    ",
      "     njl lj     ",
      "     gjllljg    ",
      "       jjj      "
    ],
    [
      "                ",
      "                ",
      "                ",
      "                ",
      "                ",
      "             qrq",
      "            q   ",
      "i       c   r s ",
      "            q   ",
      "             qrq",
      "                ",
      "       qrq      ",
      "      q   q     ",
      "      r s r     ",
      "      q   q     ",
      "       qrq      "
    ],
    [
      "                ",
      "                ",
      "                ",
      "                ",
      "                ",
      "b               ",
      "b               ",
      "b       c     t ",
      "b               ",
      "b               ",
      "                ",
      "                ",
      "                ",
      "        t       ",
      "                ",
      "                "
    ],
    [
      "                ",
      "                ",
      "                ",
      "                ",
      "                ",
      "i               ",
      "i               ",
      "i       c       ",
      "i               ",
      "i               ",
      "                ",
      "                ",
      "                ",
      "                ",
      "                ",
      "                "
    ],
    [
      "                ",
      "                ",
      "                ",
      "                ",
      "                ",
      "                ",
      "                ",
      "i       c       ",
      "                ",
      "i               ",
      "                ",
      "                ",
      "                ",
      "                ",
      "                ",
      "                "
    ]
  ]
}