{
  "name": "multi_casino_10_floor2",
  "refpalette": "deceasedcraft:multi_casino_10/multi_casino_10_floor2_palette",
  "xsize": 16,
  "zsize": 16,
  "slices": [
    [
      "       a a      ",
      "      a   a     ",
      "     a     a    ",
      "    a       a   ",
      "   a         a  ",
      "b a           a ",
      "ca             a",
      "a   ~           ",
      "ca             a",
      "b a           a ",
      "   a         a  ",
      "    a       a   ",
      "     a     a    ",
      "      a   a     ",
      "       a a      ",
      "        a       "
    ],
    [
      "ddddddefeedddddd",
      "dddddefeddeddddd",
      "ddddefeddddedddd",
      "eddefeddddddeddd",
      "edefeddddddddedd",
      "fefedddddddddded",
      "ffedddddddddddde",
      "aedddddddddddddd",
      "ffedddddddddddde",
      "fefedddddddddded",
      "edefeddddddddedd",
      "eddefeddddddeddd",
      "ddddefeddddedddd",
      "dddddefeddeddddd",
      "ddddddefeedddddd",
      "dddddddefedddddd"
    ],
    [
      "                ",
      "                ",
      "                ",
      "                ",
      "                ",
      "g               ",
      "g               ",
      "g   ~           ",
      "g               ",
      "g     ~         ",
      "                ",
      "                ",
      "                ",
      "                ",
      "                ",
      "                "
    ],
    [
      "                ",
      "                ",
      "                ",
      "                ",
      "                ",
      "                ",
      "                ",
      "    ~           ",
      "                ",
      "      ~         ",
      "                ",
      "                ",
      "                ",
      "                ",
      "                ",
      "                "
    ],
    [
      "                ",
      "                ",
      "                ",
      "                ",
      "                ",
      "                ",
      "                ",
      "    ~           ",
      "                ",
      "      ~         ",
      "                ",
      "                ",
      "                ",
      "                ",
      "                ",
      "                "
    ],
    [
      "                ",
      "                ",
      "                ",
      "                ",
      "                ",
      "                ",
      "                ",
      "    ~           ",
      "                ",
      "      ~         ",
      "                ",
      "                ",
      "                ",
      "                ",
      "                ",
      "                "
    ]
  ]
}