{
  "name": "multi_casino_10_base8",
  "refpalette": "deceasedcraft:multi_casino_10/multi_casino_10_base8_palette",
  "xsize": 16,
  "zsize": 16,
  "slices": [
    [
      "aaaaaaaaaaaaaaaa",
      "aaaaaaaaaaaaaaaa",
      "aaaaaaaaaaaaaaaa",
      "aaaaaaaaaaaaaaaa",
      "aaaaaaa bcaaaaaa",
      "daaaaaaaaaaaaaaa",
      "daaaaeaaaaaaaaaa",
      "daaaafaagaaaaaad",
      "daaaacaaaaaaaadd",
      "daaaaaaaaaaadddh",
      "aaaaaaaaaaaddhhh",
      "aaaaaaaaaaddhhhh",
      "aaaaaaaaaadhhhhh",
      "aaaaaaaaaddhhhhh",
      "aaaaaaaaddhhhhhh",
      "aaaaaaaadhhhhhhh"
    ],
    [
      "       ijk     l",
      "                ",
      "                ",
      "      m mm    n ",
      "     opqrspo ntn",
      "     uw   xy  n ",
      " A  mB    CD    ",
      "EF  mI  g CJ    ",
      " K  mL          ",
      "     uMNN       ",
      "     oOPQ     RR",
      "             RRh",
      "     n      RRhh",
      "    ntn    RRhhh",
      " l   n     Rhhhh",
      "ltl       RRhhhh"
    ],
    [
      "                ",
      "                ",
      "                ",
      "                ",
      "      S T U     ",
      "                ",
      "     V          ",
      "E       g       ",
      "     W          ",
      "     X          ",
      "                ",
      "                ",
      "                ",
      "                ",
      "                ",
      " Y              "
    ],
    [
      "                ",
      "                ",
      "                ",
      "                ",
      "                ",
      "d               ",
      "d       Z       ",
      "d      0g1      ",
      "d       2       ",
      "d               ",
      "                ",
      "                ",
      "                ",
      "                ",
      "                ",
      "                "
    ],
    [
      "                ",
      "                ",
      "                ",
      "                ",
      "                ",
      "E               ",
      "E               ",
      "E      3gf      ",
      "E       4       ",
      "E               ",
      "                ",
      "                ",
      "                ",
      "                ",
      "                ",
      "                "
    ],
    [
      "                ",
      "                ",
      "                ",
      "                ",
      "                ",
      "                ",
      "                ",
      "E       g       ",
      "                ",
      "E               ",
      "                ",
      "                ",
      "                ",
      "                ",
      "                ",
      "                "
    ]
  ]
}