{
  "name": "multi_casino_10_ground",
  "refpalette": "deceasedcraft:multi_casino_10/multi_casino_10_ground_palette",
  "xsize": 16,
  "zsize": 16,
  "slices": [
    [
      "HHHHHHHHHHHHHHHH",
      "aaHHHHHHHHHHHHHH",
      "baaHHHHHHHHHHHHH",
      "bbaaaaHHHHHHHHHH",
      "ccbbbaaaaaaaaaaa",
      "cccccbbbbbbadddd",
      "ccccccccccbadddd",
      "ccccccccecbaffff",
      "ccccccccccbadddd",
      "bcccccccccbadddd",
      "ccccccccccbadddd",
      "ccccccccccbadddd",
      "ccccccccccbadddd",
      "ccccccccccbadddd",
      "ccccccccccbadddd",
      "ccccccccccbaffff"
    ],
    [
      "ghi  jkkkkkkkkkk",
      "llgi            ",
      " llghhi         ",
      "  llllghhhhhhhhh",
      "     lllllllllll",
      "           lmnnn",
      "           l    ",
      "    ~   e  l    ",
      "           l    ",
      "o          l    ",
      "       p   l    ",
      "       q   l    ",
      "       r   l    ",
      "           l    ",
      "       p   l    ",
      "       q   l    "
    ],
    [
      "                ",
      "                ",
      "                ",
      "                ",
      "                ",
      "            s   ",
      "        e       ",
      "    ~  ete      ",
      "        e       ",
      "                ",
      "                ",
      "                ",
      "                ",
      "                ",
      "                ",
      "                "
    ],
    [
      "                ",
      "                ",
      "                ",
      "                ",
      "                ",
      "        e       ",
      "                ",
      "    ~ e   e     ",
      "                ",
      "        e       ",
      "                ",
      "                ",
      "                ",
      "                ",
      "                ",
      "                "
    ],
    [
      "                ",
      "                ",
      "                ",
      "                ",
      "                ",
      "        e       ",
      "                ",
      "    ~ e   e     ",
      "                ",
      "        e       ",
      "                ",
      "                ",
      "                ",
      "                ",
      "                ",
      "                "
    ],
    [
      "                ",
      "                ",
      "                ",
      "                ",
      "        e       ",
      "                ",
      "                ",
      "    ~e     e    ",
      "                ",
      "                ",
      "        e       ",
      "                ",
      "                ",
      "                ",
      "                ",
      "                "
    ]
  ]
}