{
  "name": "multi_terraceplaza_16_floor1",
  "refpalette": "deceasedcraft:multi_terraceplaza_16/multi_terraceplaza_16_floor1_palette",
  "xsize": 16,
  "zsize": 16,
  "slices": [
    [
      "                ",
      "                ",
      "                ",
      "                ",
      "                ",
      "                ",
      "                ",
      "                ",
      " a            a ",
      "                ",
      "                ",
      "                ",
      "                ",
      "                ",
      "                ",
      "                "
    ],
    [
      "bc            cb",
      "bc            cb",
      "bc            cb",
      "bc            cb",
      "bc            cb",
      "bc            cb",
      "bc            cb",
      "bc            cb",
      "ca            ac",
      "bc            cb",
      "bc            cb",
      "bc            cb",
      "bc            cb",
      "bc            cb",
      "bc            cb",
      "bc            cb"
    ],
    [
      "de            fd",
      "de            fd",
      "de            fd",
      "de            fd",
      "de            fd",
      "de            fd",
      "de            fd",
      "de            fd",
      "dag          had",
      "de            fd",
      "de            fd",
      "de            fd",
      "de            fd",
      "dijkkkkkkkkkklid",
      "dijkkkkkkkkkklid",
      "de            fd"
    ],
    [
      " m            m ",
      " m            m ",
      " m            m ",
      " m            m ",
      " m            m ",
      " m            m ",
      " m            m ",
      " m            m ",
      " a            a ",
      " m            m ",
      " m            m ",
      " m            m ",
      " m            m ",
      " nnnnnnnnnnnnnn ",
      " oooooooooooooo ",
      " m            m "
    ],
    [
      "                ",
      "                ",
      "                ",
      "                ",
      "                ",
      "                ",
      "                ",
      "                ",
      " a            a ",
      "                ",
      "                ",
      "                ",
      "                ",
      "                ",
      "                ",
      "                "
    ],
    [
      "                ",
      "                ",
      "                ",
      "                ",
      "                ",
      "                ",
      "                ",
      "                ",
      " a            a ",
      "                ",
      "                ",
      "                ",
      "                ",
      "                ",
      "                ",
      "                "
    ]
  ]
}