{
  "name": "multi_terraceplaza_16_base1",
  "refpalette": "deceasedcraft:multi_terraceplaza_16/multi_terraceplaza_16_base1_palette",
  "xsize": 16,
  "zsize": 16,
  "slices": [
    [
      "aaaaaaaaaaaaaaaa",
      "abcddddddddddcba",
      "abef        geba",
      "abff        ggba",
      "ab            ba",
      "ab            ba",
      "ab            ba",
      "ab            ba",
      "dh            hd",
      " f            g ",
      " f            g ",
      " f            g ",
      " f            g ",
      " f            g ",
      " f            g ",
      " f            g "
    ],
    [
      "   iiiiiiiiii   ",
      " jff        ggj ",
      " jff        ggj ",
      " j            j ",
      " j            j ",
      " j            j ",
      " j            j ",
      " j            j ",
      "jh            hj",
      " f            g ",
      " f            g ",
      " f            g ",
      " f            g ",
      " f            g ",
      " f            g ",
      " f            g "
    ],
    [
      "                ",
      "                ",
      "                ",
      "                ",
      "                ",
      "                ",
      "                ",
      "                ",
      " h            h ",
      " f            g ",
      " f            g ",
      " f            g ",
      " f            g ",
      " f            g ",
      " f            g ",
      " f            g "
    ],
    [
      "                ",
      "                ",
      "                ",
      "                ",
      "                ",
      "                ",
      "                ",
      "                ",
      " h            h ",
      "k              k",
      "k              k",
      "kl             k",
      "kl             k",
      "kl             k",
      "kl             k",
      "kl             k"
    ],
    [
      "                ",
      "                ",
      "                ",
      "                ",
      "                ",
      "                ",
      "                ",
      "                ",
      " h            h ",
      "k   m    m  m  k",
      "k              k",
      "k              k",
      "k              k",
      "k              k",
      "k              k",
      "k              k"
    ],
    [
      "nonnnnnnnnnnnnon",
      "nonnnnnnnnnnnnon",
      "nonnnnnnnnnnnnon",
      "nonnnnnnnnnnnnon",
      "nonnnnnnnnnnnnon",
      "nonnnnnnnnnnnnon",
      "nonnnnnnnnnnnnon",
      "nonnnnnnnnnnnnon",
      "ohooooooooooooho",
      "pom mm  mm mm ok",
      "po            ok",
      "po            ok",
      "po            ok",
      "po            ok",
      "po            ok",
      "po            ok"
    ]
  ]
}