{
  "name": "multi_terraceplaza_16_base2",
  "refpalette": "deceasedcraft:multi_terraceplaza_16/multi_terraceplaza_16_base2_palette",
  "xsize": 16,
  "zsize": 16,
  "slices": [
    [
      "aaaaaaaaaaaaaaaa",
      "aaaaaaaaaaaaaaaa",
      "aaaaaaaaaaaaaaaa",
      "aaaaaaaaaaaaaaaa",
      "aaaaaaaaaaaaaaaa",
      "aaaaaaaaaaaaaaaa",
      "aaaaaaaaaaaaaaaa",
      "aabaaaaaaaaaabaa",
      "cdeaaaaaaaaaaedc",
      "fcaaaaaaaaaaaacf",
      "fcaaaaaaaaaaaacf",
      "fcaaaaaaaaaaaacf",
      "fcaaaaaaaaaaaacf",
      "fcaaaaaaaaaaaacf",
      "fcaaaaaaaaaaaacf",
      "fcaaaaaaaaaaaacf"
    ],
    [
      "                ",
      "                ",
      "                ",
      "                ",
      "                ",
      "                ",
      "  b          b  ",
      " ghi        ghi ",
      "jdii        ggdj",
      "k              l",
      "k              l",
      "km            nl",
      "ko            pl",
      "k              l",
      "k              l",
      "km            nl"
    ],
    [
      "                ",
      "                ",
      "                ",
      "                ",
      "                ",
      "  b          b  ",
      " ghi        ghi ",
      "  ii        gg  ",
      "jd            dj",
      "qi            g ",
      " i            g ",
      " i            g ",
      " i            g ",
      "ri            g ",
      " i            g ",
      "si            g "
    ],
    [
      "                ",
      "                ",
      "                ",
      "                ",
      "  b          b  ",
      " ghi        ghi ",
      "  ii        gg  ",
      "                ",
      "jd            dj",
      " i            g ",
      " i            g ",
      " i            g ",
      " i            g ",
      " i            g ",
      " i            g ",
      " i            g "
    ],
    [
      "                ",
      "                ",
      "                ",
      "  b          b  ",
      " ghi        ghi ",
      "  ii        gg  ",
      "                ",
      "                ",
      "jd            dj",
      " i            g ",
      " i            g ",
      " i            g ",
      " i            g ",
      " i            g ",
      " i            g ",
      " i            g "
    ],
    [
      "tuttttttttttttut",
      "tuuuuuuuuuuuuuut",
      "tub          but",
      "tuhi        ghut",
      "tuii        ggut",
      "tu            ut",
      "tu            ut",
      "tu            ut",
      "ud            du",
      " i            g ",
      " i            g ",
      " i            g ",
      " i            g ",
      " i            g ",
      " i            g ",
      " i            g "
    ]
  ]
}