{
  "name": "multi_terraceplaza_16_floor4",
  "refpalette": "deceasedcraft:multi_terraceplaza_16/multi_terraceplaza_16_floor4_palette",
  "xsize": 16,
  "zsize": 16,
  "slices": [
    [
      "                ",
      "                ",
      "                ",
      "                ",
      "                ",
      "aabccccccccccbaa",
      "ddbeeeeeeeeeebdd",
      "ffbeeeeeeeeeebff",
      "gggggggggggggggg",
      "gggggggggggggggg",
      "                ",
      "                ",
      "                ",
      "                ",
      "                ",
      "                "
    ],
    [
      "                ",
      "                ",
      "aabccccccccccbaa",
      "ddbeeeeeeeeeebdd",
      "ffbeeeeeeeeeebff",
      "gg            gg",
      "gg            gg",
      "hhhhhhhhhhhhhhhh",
      "iiiiiiiiiiiiiiii",
      "                ",
      "                ",
      "                ",
      "                ",
      "                ",
      "                ",
      "                "
    ],
    [
      "ddbeeeeeeeeeebdd",
      "ffbeeeeeeeeeebff",
      "gg            gg",
      "gg            gg",
      "hh            hh",
      "ii            ii",
      "                ",
      "                ",
      "                ",
      "                ",
      "                ",
      "                ",
      "                ",
      "                ",
      "                ",
      "                "
    ],
    [
      "gg            gg",
      "hh            hh",
      "ii            ii",
      "                ",
      "                ",
      "                ",
      "                ",
      "                ",
      "                ",
      "                ",
      "                ",
      "                ",
      "                ",
      "                ",
      "                ",
      "                "
    ],
    [
      "                ",
      "                ",
      "                ",
      "                ",
      "                ",
      "                ",
      "                ",
      "                ",
      "                ",
      "                ",
      "                ",
      "                ",
      "                ",
      "                ",
      "                ",
      "                "
    ],
    [
      "                ",
      "                ",
      "                ",
      "                ",
      "                ",
      "                ",
      "                ",
      "                ",
      "                ",
      "                ",
      "                ",
      "                ",
      "                ",
      "                ",
      "                ",
      "                "
    ]
  ]
}