{
  "name": "multi_terraceplaza_16_ground",
  "refpalette": "deceasedcraft:multi_terraceplaza_16/multi_terraceplaza_16_ground_palette",
  "xsize": 16,
  "zsize": 16,
  "slices": [
    [
      "aaaaaaaaaaaaaaaa",
      "aaaaaaaaaaaaaaaa",
      "aaaaaaaaaaaaaaaa",
      "aaaaaaaaaaaaaaaa",
      "aaaaaaaaaaaaaaaa",
      "aaaaaaaaaaaaaaaa",
      "aaaaaaaaaaaaaaaa",
      "aaaaaaaaaaaaaaaa",
      "abcddddddddddeba",
      "afggggggggggggha",
      "af            ha",
      "af            ha",
      "af            ha",
      "af            ha",
      "af            ha",
      "af            ha"
    ],
    [
      "                ",
      "                ",
      "                ",
      "                ",
      " ij          ij ",
      " ij          ij ",
      "                ",
      "  kkkkkkkkkkkk  ",
      " bggggggggggggb ",
      " lggggggggggggl ",
      " l            l ",
      " l            l ",
      " l            l ",
      " l            l ",
      " l            l ",
      " l            l "
    ],
    [
      "                ",
      "                ",
      "                ",
      "                ",
      " mn          mn ",
      " mn          mn ",
      "                ",
      "                ",
      " b            b ",
      "                ",
      "                ",
      "                ",
      "                ",
      "                ",
      "                ",
      "                "
    ],
    [
      "                ",
      "                ",
      "                ",
      "                ",
      " mn          mn ",
      " mn          mn ",
      "                ",
      "                ",
      " b            b ",
      "                ",
      "                ",
      "                ",
      "                ",
      "                ",
      "                ",
      "                "
    ],
    [
      "                ",
      "                ",
      "                ",
      "                ",
      " mn          mn ",
      " mn          mn ",
      "                ",
      "                ",
      " b            b ",
      "                ",
      "                ",
      "                ",
      "                ",
      "                ",
      "                ",
      "                "
    ],
    [
      "                ",
      "                ",
      "                ",
      "                ",
      "                ",
      "                ",
      "                ",
      "                ",
      " b            b ",
      "                ",
      "                ",
      "                ",
      "                ",
      "                ",
      "                ",
      "                "
    ]
  ]
}