{
  "name": "multi_terraceplaza_16_floor2",
  "refpalette": "deceasedcraft:multi_terraceplaza_16/multi_terraceplaza_16_floor2_palette",
  "xsize": 16,
  "zsize": 16,
  "slices": [
    [
      "                ",
      "                ",
      "                ",
      "                ",
      "                ",
      "                ",
      "                ",
      "                ",
      " a            a ",
      "                ",
      "                ",
      "                ",
      "                ",
      "                ",
      "                ",
      "                "
    ],
    [
      "                ",
      "                ",
      "                ",
      "                ",
      "                ",
      "                ",
      "                ",
      "                ",
      " a            a ",
      "                ",
      "                ",
      "                ",
      "                ",
      "                ",
      "                ",
      "                "
    ],
    [
      "                ",
      "                ",
      "                ",
      "                ",
      "                ",
      "                ",
      "                ",
      "                ",
      " a            a ",
      "                ",
      "                ",
      "                ",
      "                ",
      "                ",
      "                ",
      "                "
    ],
    [
      "bc            cb",
      "bc            cb",
      "bc            cb",
      "bc            cb",
      "bc            cb",
      "bc            cb",
      "bc            cb",
      "bc            cb",
      "ca            ac",
      "bc            cb",
      "bc            cb",
      "bc            cb",
      "bc            cb",
      "bc            cb",
      "bc            cb",
      "bc            cb"
    ],
    [
      "defgggggggggghed",
      "defgggggggggghed",
      "defgggggggggghed",
      "defgggggggggghed",
      "di            jd",
      "di            jd",
      "di            jd",
      "di            jd",
      "dak          lad",
      "di            jd",
      "di            jd",
      "di            jd",
      "di            jd",
      "di            jd",
      "di            jd",
      "di            jd"
    ],
    [
      " mmmmmmmmmmmmmm ",
      "                ",
      "                ",
      " nnnnnnnnnnnnnn ",
      " o            o ",
      " o            o ",
      " o            o ",
      " o            o ",
      " a            a ",
      " o            o ",
      " o            o ",
      " o            o ",
      " o            o ",
      " o            o ",
      " o            o ",
      " o            o "
    ]
  ]
}