{
  "name": "multi_nuclearpowerplant_32_base6",
  "refpalette": "deceasedcraft:multi_nuclearpowerplant_32/multi_nuclearpowerplant_32_base6_palette",
  "xsize": 16,
  "zsize": 16,
  "slices": [
    [
      "abc    de       ",
      "abc    fe       ",
      "abc     geeeeeee",
      "abc         f hh",
      "abcccccccccccccc",
      "abbbbbbbbbbbbbbb",
      "aaaaaaaaaaaaaaaa",
      "aaaaaaaaaaaaaaaa",
      "aaaaaaaaaaaaaaaa",
      "aaaaaaaaaaaaaaaa",
      "aaaaaaaaaaaaaaaa",
      "aaaaaaaabbbbbaaa",
      "aaaaaaaabcccbaaa",
      "iaaaaaaabcjcbaaa",
      "aaaaaaaabcccbaaa",
      "aaaaaaaabbbbbaaa"
    ],
    [
      "  kl   mennnnnnn",
      "  k   oiennnnnnn",
      "  k    pgeeeeeee",
      "  k    q   rfshh",
      "  kkkkkkkkkkkkkk",
      "                ",
      "                ",
      "                ",
      "                ",
      "                ",
      "                ",
      "                ",
      "         fff    ",
      "f        f f    ",
      "         fff    ",
      "                "
    ],
    [
      "  t    ue       ",
      "  t    fe       ",
      "  t     geeeeeee",
      "  t       w f hh",
      "   xxxxxxxwxxxxx",
      "          w     ",
      "          w     ",
      "          w     ",
      "          w     ",
      "          w     ",
      "          w     ",
      "          w     ",
      "         yyy    ",
      "f        yAy    ",
      "         yyy    ",
      "                "
    ],
    [
      "       fe       ",
      "        e       ",
      "        geBeeeee",
      "         CDEf hh",
      "         CDE    ",
      "         CDE    ",
      "         CDE    ",
      "         CDE    ",
      "         CDE    ",
      "         CDE    ",
      "         CDE    ",
      "         CDE    ",
      "         yDy    ",
      "f        jFj    ",
      "         yjy    ",
      "                "
    ],
    [
      "        geeeeeee",
      "        geeeeeee",
      "        gggggggg",
      "          I f hh",
      "          I     ",
      "          I     ",
      "          I     ",
      "          I     ",
      "          I     ",
      "          I     ",
      "          I     ",
      "          I     ",
      "         yyy    ",
      "f        jDj    ",
      "         yjy    ",
      "                "
    ],
    [
      "            J KK",
      "            J KK",
      "           LifMM",
      "            f   ",
      "                ",
      "                ",
      "                ",
      "                ",
      "                ",
      "                ",
      "                ",
      "                ",
      "         yyy    ",
      "f        jDj    ",
      "         yjy    ",
      "                "
    ]
  ]
}