{
  "name": "multi_nuclearpowerplant_32_base12",
  "refpalette": "deceasedcraft:multi_nuclearpowerplant_32/multi_nuclearpowerplant_32_base12_palette",
  "xsize": 16,
  "zsize": 16,
  "slices": [
    [
      "aaaaaaaaaaaaaaaa",
      "aaaaaaaaaaaaaaaa",
      "aaaaaaaaaaaaaaaa",
      "aaaaaaaaaaaaaaaa",
      "aaaaaaaaaaaaaaaa",
      "aaaaaaaaaaaaaaaa",
      "aaaaaaaaaaaaaaaa",
      "aaaaaaaaaaaaaaaa",
      "aaaaaaaaaaaaaaaa",
      "aaaaaaaaaaaaaaaa",
      "aaaaaaaaaaaaaaaa",
      "aaaaaaaaaaaaaaaa",
      "aaaaaaaaaaaaaaaa",
      "aaaaaaaaaaaaaaaa",
      "aaaaaaaaaaaaaaaa",
      "aaaaaaaaaaaaaaaa"
    ],
    [
      "bbbbbbbbbbbbbbbb",
      "bbbbbbbbbbbbbbbb",
      "bbbbbbbbbbbbbbbb",
      "bbbbbbbbbbbbbbbb",
      "bbbbbbbbbbbbbbbb",
      "bbbbbbbbbbbbbbbb",
      "bbbbbbbbbbbbbbbb",
      "bbbbbbbbbbbbbbbb",
      "bbbbbbbbbbbbbbbb",
      "bbbbbbbbbbbbbbbb",
      "bbbbbbbbbbbbbbbb",
      "bbbbbbbbbbbbbbbb",
      "bbbbbbbbbbbbbbbb",
      "bbbbbbbbbbbbbbbb",
      "bbbbbbbbbbbbbbbb",
      "bbbbbbbbbbbbbbbb"
    ],
    [
      "ccccccccccc d===",
      "ccccccccccc d===",
      "ccccccccccc d===",
      "ccccccccccc d===",
      "ccccccccccc d===",
      "ccccccccccc d===",
      "ccccccccccc d===",
      "ccccccccccc d===",
      "ccccccccccced===",
      "ccccccccccced===",
      "ccccccccffffd===",
      "ccccccccffffd===",
      "ccccccccff fd===",
      "ccccccccffffd===",
      "ccccccccffffd===",
      "ccccccccccced==="
    ],
    [
      "           @gbhh",
      "           @gbhh",
      "           @ibhh",
      "           @gbhh",
      "           @gbhh",
      "           @gbhh",
      "           @gbhh",
      "           @gbhh",
      "           egbhh",
      "           egbhh",
      "           ejbhh",
      "         fffjbhh",
      "         fkfjbhh",
      "         fffjbhh",
      "l          ejbhh",
      "           ejbhh"
    ],
    [
      "           @mbnn",
      "           @mbnn",
      "           @obnn",
      "           @ bnn",
      "           @ bnn",
      "           @ bnn",
      "           @ bnn",
      "           @ pnn",
      "           e bnn",
      "           egbnn",
      "           ejbnn",
      "         qqqjbnn",
      "         qnqjbnn",
      "         qqqjbnn",
      "           ejbnn",
      "           ejbnn"
    ],
    [
      "           @mbnn",
      "           @mbnn",
      "           @obnn",
      "           @ bnn",
      "           @ bnn",
      "           @ bnn",
      "           @ bnn",
      "           @ pnn",
      "           e bnn",
      "           egbnn",
      "           ejbnn",
      "         qqqjbnn",
      "         rnqjbnn",
      "         qqqjbnn",
      "           ejbnn",
      "           ejbnn"
    ]
  ]
}