{
  "name": "multi_nuclearpowerplant_32_base9",
  "refpalette": "deceasedcraft:multi_nuclearpowerplant_32/multi_nuclearpowerplant_32_base9_palette",
  "xsize": 16,
  "zsize": 16,
  "slices": [
    [
      "           ab   ",
      "           ab   ",
      "           ab   ",
      "           ab   ",
      "           ab   ",
      "           ab   ",
      "           ab   ",
      "           abc  ",
      "           ab   ",
      "           ab   ",
      "           ab   ",
      "         ddab   ",
      "         deab   ",
      "         ddab   ",
      "           ab   ",
      "           ab   "
    ],
    [
      "           ab   ",
      "           ab   ",
      "           ab   ",
      "           ab   ",
      "           ab   ",
      "           ab   ",
      "           ab   ",
      "           abc  ",
      "           ab   ",
      "           ab   ",
      "           ab   ",
      "           ab   ",
      "           ab   ",
      "           ab   ",
      "           ab   ",
      "           ab   "
    ],
    [
      "           ab   ",
      "           ab   ",
      "           ab   ",
      "           ab   ",
      "           ab   ",
      "           ab   ",
      "           ab   ",
      "           abc  ",
      "           ab   ",
      "           ab   ",
      "           ab   ",
      "           ab   ",
      "           ab   ",
      "           ab   ",
      "           ab   ",
      "           ab   "
    ],
    [
      "           ab   ",
      "           ab   ",
      "           ab   ",
      "           ab   ",
      "           ab   ",
      "           ab   ",
      "           ab   ",
      "           abcfg",
      "           ab   ",
      "           ab   ",
      "           ab   ",
      "           ab   ",
      "           ab   ",
      "           ab   ",
      "           ab   ",
      "           ab   "
    ],
    [
      "           ab   ",
      "           ab   ",
      "           ab   ",
      "           ab   ",
      "           ab   ",
      "           ab   ",
      "           ab   ",
      "           abccc",
      "           ab   ",
      "           ab   ",
      "           ab   ",
      "           ab   ",
      "           ab   ",
      "           ab   ",
      "           ab   ",
      "           ab   "
    ],
    [
      "           ab   ",
      "           ab   ",
      "           ab   ",
      "           ab   ",
      "           ab   ",
      "           ab   ",
      "           ab   ",
      "           abch ",
      "           ab   ",
      "           ab   ",
      "           ab   ",
      "           ab   ",
      "           ab   ",
      "           ab   ",
      "           ab   ",
      "           ab   "
    ]
  ]
}