{
  "name": "multi_nuclearpowerplant_32_ground",
  "refpalette": "deceasedcraft:multi_nuclearpowerplant_32/multi_nuclearpowerplant_32_ground_palette",
  "xsize": 16,
  "zsize": 16,
  "slices": [
    [
      "                ",
      "                ",
      "                ",
      "                ",
      "               a",
      "                ",
      "                ",
      "                ",
      "                ",
      "                ",
      "               b",
      "               b",
      "               b",
      "              bc",
      "              bc",
      "             bcd"
    ],
    [
      "                ",
      "                ",
      "                ",
      "                ",
      "               e",
      "             eee",
      "            eeff",
      "          eeefff",
      "        eeefffff",
      "        efffffff",
      "       fffffffff",
      "a      fffffffff",
      "       fffffffff",
      "       fffffffff",
      "      ffffffffff",
      "      ffffffffff"
    ],
    [
      "                ",
      "                ",
      "                ",
      "                ",
      "               e",
      "             eee",
      "            eezz",
      "          eeezzz",
      "        eeezzzzz",
      "      eeezzzzzzz",
      "   eeeefzzzzzzzz",
      "eeeeffffzzzzzzzz",
      "efffffffzzzzzzzz",
      "ffffffffzzzzzzzz",
      "ffffffffzzzzzzzz",
      "fffffffzzzzzzzzz"
    ],
    [
      "                ",
      "                ",
      "                ",
      "                ",
      "                ",
      "                ",
      "                ",
      "          gg    ",
      "        ggg   h ",
      "      eeg       ",
      "   eeeez      h ",
      "ieeezzzz  hh  h ",
      "ezzzzzzz        ",
      "zzzzzzzzz    h  ",
      "zzzzzzzz  h  j h",
      "zzzzzzzz  h    h"
    ],
    [
      "                ",
      "                ",
      "                ",
      "                ",
      "                ",
      "                ",
      "                ",
      "                ",
      "                ",
      "                ",
      "   g            ",
      "iggg            ",
      "g               ",
      "h    h          ",
      "   k            ",
      "  hh            "
    ],
    [
      "                ",
      "                ",
      "                ",
      "                ",
      "                ",
      "                ",
      "                ",
      "                ",
      "                ",
      "                ",
      "                ",
      "                ",
      "                ",
      "                ",
      "                ",
      "                "
    ]
  ]
}