{
  "name": "multi_nuclearpowerplant_32_base10",
  "refpalette": "deceasedcraft:multi_nuclearpowerplant_32/multi_nuclearpowerplant_32_base10_palette",
  "xsize": 16,
  "zsize": 16,
  "slices": [
    [
      "           abc  ",
      "           abc  ",
      "           abc  ",
      "           abc  ",
      "           abc  ",
      "           abc  ",
      "           abc  ",
      "           abd  ",
      "           abc  ",
      "           abc  ",
      "          eabc  ",
      "         fgfbc  ",
      "         hifbc  ",
      "         fffbc  ",
      "           abc  ",
      "           abc  "
    ],
    [
      "           aj   ",
      "           aj   ",
      "           aj   ",
      "           aj   ",
      "           aj   ",
      "           aj   ",
      "           aj   ",
      "           ajkl ",
      "           aj   ",
      "           aj   ",
      "           aj   ",
      "         fffj   ",
      "         hifj   ",
      "         fffj   ",
      "           aj   ",
      "           aj   "
    ],
    [
      "           aj   ",
      "           aj   ",
      "           aj   ",
      "           aj   ",
      "           aj   ",
      "           aj   ",
      "           aj   ",
      "           ajk  ",
      "           aj   ",
      "           aj   ",
      "           aj   ",
      "         fffj   ",
      "         hifj   ",
      "         fffj   ",
      "           aj   ",
      "           aj   "
    ],
    [
      "           aj   ",
      "           aj   ",
      "           aj   ",
      "           aj   ",
      "           aj   ",
      "           aj   ",
      "           aj   ",
      "           ajk  ",
      "           aj   ",
      "           aj   ",
      "           aj   ",
      "         fffj   ",
      "         fifj   ",
      "         fffj   ",
      "           aj   ",
      "           aj   "
    ],
    [
      "           aj   ",
      "           aj   ",
      "           aj   ",
      "           aj   ",
      "           aj   ",
      "           aj   ",
      "           aj   ",
      "           ajk  ",
      "           aj   ",
      "           aj   ",
      "           aj   ",
      "         fffj   ",
      "        m ifj   ",
      "         fgfj   ",
      "          eaj   ",
      "           aj   "
    ],
    [
      "           aj   ",
      "           aj   ",
      "           aj   ",
      "           aj   ",
      "           aj   ",
      "           aj   ",
      "           aj   ",
      "           ajk  ",
      "           aj   ",
      "           aj   ",
      "           aj   ",
      "         fffj   ",
      "         fffj   ",
      "         fffj   ",
      "           aj   ",
      "           aj   "
    ]
  ]
}