{
  "name": "multi_nuclearpowerplant_32_base11",
  "refpalette": "deceasedcraft:multi_nuclearpowerplant_32/multi_nuclearpowerplant_32_base11_palette",
  "xsize": 16,
  "zsize": 16,
  "slices": [
    [
      "           @abcc",
      "           @abcc",
      "           @dbcc",
      "           @ bcc",
      "           @ bcc",
      "           @ bcc",
      "           @ bcc",
      "           @ ecc",
      "           f bcc",
      "           fgbcc",
      "           fhbcc",
      "         iiihbcc",
      "         jcihbcc",
      "         iiihbcc",
      "           fhbcc",
      "           fhbcc"
    ],
    [
      "           @abcc",
      "           @abcc",
      "           @dbcc",
      "           @ bcc",
      "           @ bcc",
      "           @ bcc",
      "           @ bcc",
      "           @ ecc",
      "           f bcc",
      "           fgbcc",
      "           fhbcc",
      "         iiihbcc",
      "         jcihbcc",
      "         iiihbcc",
      "           fhbcc",
      "           fhbcc"
    ],
    [
      "           @gbcc",
      "           @gbcc",
      "           @kbcc",
      "           @gbcc",
      "           @gbcc",
      "           @gbcc",
      "           @gbcc",
      "           @gecc",
      "           fgbcc",
      "           fgbcc",
      "           fhbcc",
      "         iiihbcc",
      "         jcihbcc",
      "         ilihbcc",
      "          mfhbcc",
      "           fhbcc"
    ],
    [
      "           fnbcc",
      "           fnbcc",
      "           fkbcc",
      "           fobcc",
      "           fpbcc",
      "           f bcc",
      "           f bcc",
      "           f ecc",
      "           fgbcc",
      "           fhbcc",
      "           fhbcc",
      "         iiihbcc",
      "         jcihbcc",
      "         iiihbcc",
      "           fhbcc",
      "           fhbcc"
    ],
    [
      "           f bcc",
      "           f bcc",
      "           f bcc",
      "           f bcc",
      "           f bcc",
      "           f bcc",
      "           f bcc",
      "           f ecc",
      "           fgbcc",
      "           fhbcc",
      "           fhbcc",
      "         iiihbcc",
      "         jcihbcc",
      "         iiihbcc",
      "           fhbcc",
      "           fhbcc"
    ],
    [
      "           fgbcc",
      "           fgbcc",
      "           fgbcc",
      "           fgbcc",
      "           fgbcc",
      "           fgbcc",
      "           fgbcc",
      "           fgecc",
      "           fgbcc",
      "           fhbcc",
      "           fhbcc",
      "         iiihbcc",
      "         jcihbcc",
      "         iiihbcc",
      "           fhbcc",
      "           fhbcc"
    ]
  ]
}