{
  "name": "multi_nuclearpowerplant_32_base7",
  "refpalette": "deceasedcraft:multi_nuclearpowerplant_32/multi_nuclearpowerplant_32_base7_palette",
  "xsize": 16,
  "zsize": 16,
  "slices": [
    [
      "         aaa    ",
      "        baaa    ",
      "                ",
      "       c    c dd",
      "                ",
      "                ",
      "                ",
      "                ",
      "                ",
      "                ",
      "                ",
      "                ",
      "                ",
      "c               ",
      "                ",
      "                "
    ],
    [
      "          ea    ",
      "         afa    ",
      "                ",
      "       c    c dd",
      "                ",
      "                ",
      "                ",
      "                ",
      "                ",
      "                ",
      "                ",
      "                ",
      "                ",
      "c               ",
      "                ",
      "                "
    ],
    [
      "         aaa    ",
      "         aaa    ",
      "       g    g   ",
      "       c    c dd",
      "                ",
      "                ",
      "                ",
      "                ",
      "                ",
      "                ",
      "                ",
      "                ",
      "                ",
      "c               ",
      "                ",
      "                "
    ],
    [
      "       c    c   ",
      "       c    c   ",
      "       ccccccccc",
      "       c    c dd",
      "            h   ",
      "                ",
      "                ",
      "                ",
      "                ",
      "                ",
      "                ",
      "                ",
      "                ",
      "c               ",
      "                ",
      "                "
    ],
    [
      "        iiiiiiii",
      "        iiiiiiii",
      "        iiiiiiii",
      "            c dd",
      "                ",
      "                ",
      "                ",
      "                ",
      "                ",
      "                ",
      "                ",
      "                ",
      "                ",
      "c               ",
      "                ",
      "                "
    ],
    [
      "j      ck       ",
      "j       k       ",
      "j       iklkkkkk",
      "j           c dd",
      "j               ",
      "j               ",
      "jjjjjjjjjjjjjjjj",
      "jjjjjjjjjjjjjjjj",
      "jjjjjjjjjjjjjjjj",
      "jjjjjjjjjjjjjjjj",
      "jjjjjjjjjjjjjjjj",
      "jjjjjjjj     jjj",
      "jjjjjjjj     jjj",
      "cjjjjjjj     jjj",
      "jjjjjjjj     jjj",
      "jjjjjjjj     jjj"
    ]
  ]
}