{
  "name": "multi_nuclearpowerplant_32_base3",
  "refpalette": "deceasedcraft:multi_nuclearpowerplant_32/multi_nuclearpowerplant_32_base3_palette",
  "xsize": 16,
  "zsize": 16,
  "slices": [
    [
      "  abcccccccccccc",
      "  abcccccccccccc",
      "  abcccccccccccc",
      "  abcccccccccccc",
      "  abcccccccccccc",
      "  abcccccccccccc",
      " aabcccccccccccc",
      " abccccccccccccc",
      " abccccccccccccc",
      " abccccccccccccc",
      "aabccccccccccccc",
      "abcccccccccccccc",
      "abcccccccccccccc",
      "dbcccccccccccccc",
      "bccccccccccccccc",
      "bccccccccccccccc"
    ],
    [
      "   e   fghi! jgh",
      "   e    khlm  kh",
      "   e  nokhl  okh",
      "   e    khlp  kh",
      "   e   qrhs   rh",
      "   e    ttt  ntt",
      "   e      q     ",
      "  e  uuu   uuu  ",
      "  e  ghi   ghi  ",
      "  e  khl   khl  ",
      "  e okhlw okhl  ",
      " e   khlxy khl  ",
      " e   rhs   rhs  ",
      "Ae  BBBBBBBBBBB ",
      "e   BCCCCCCCCC  ",
      "e   BCDDDDDDD   "
    ],
    [
      "   e    EF    IF",
      "   e     FJ   KF",
      "   e    LFM   LF",
      "   e    NFO   PF",
      "   e    qFQ    F",
      "   e            ",
      "   e            ",
      "  e             ",
      "  e  RFS   NT   ",
      "  e   FU   NTV  ",
      "  e  LFM   LTM  ",
      " e   WF     T   ",
      " e   XFY  yITZ  ",
      "Ae  00000000000 ",
      "e   0CCCCCCCCC  ",
      "e   0CDDDDDDD   "
    ],
    [
      "   e            ",
      "   e            ",
      "   e            ",
      "   e            ",
      "   e            ",
      "   e            ",
      "   e            ",
      "  e             ",
      "  e             ",
      "  e             ",
      "  e             ",
      " e              ",
      " e              ",
      "Ae  000000!0000 ",
      "e   0CCCCCCCCC  ",
      "e   0CDDDDDDD   "
    ],
    [
      "   e            ",
      "   e            ",
      "   e            ",
      "   e            ",
      "   e            ",
      "   e            ",
      "   e            ",
      "  e             ",
      "  e             ",
      "  e             ",
      "  e             ",
      " e              ",
      " e              ",
      "Ae  11111111111 ",
      "e   1222222222  ",
      "e   12          "
    ],
    [
      "   e            ",
      "   e            ",
      "   e            ",
      "   e            ",
      "   e            ",
      "   e            ",
      "   e            ",
      "  e             ",
      "  e             ",
      "  e             ",
      "  e             ",
      " e              ",
      " e              ",
      "Ae              ",
      "e               ",
      "e               "
    ]
  ]
}