{
  "name": "multi_nuclearpowerplant_32_base1",
  "refpalette": "deceasedcraft:multi_nuclearpowerplant_32/multi_nuclearpowerplant_32_base1_palette",
  "xsize": 16,
  "zsize": 16,
  "slices": [
    [
      "aaabbbbbbbbbbbbb",
      "aaabbbbbbbbbbbbb",
      "aabbbbbbbbbbbbbb",
      "aabbbbbbbbbbbbbb",
      "aabbbbbbbbbbbbbb",
      "aabbbbbbbbbbbbbb",
      "aabbbbbbbbbbbbbb",
      "aabbbbbbbbbbbbbb",
      "aabbbbbbbbbbbbbb",
      "abbbbbbbbbbbbbbb",
      "abbbbbbbbbbbbbbb",
      "abbbbbbbbbbbbbbb",
      "abbbbbbbbbbbbbbb",
      "abbbbbbbbbbbbbbb",
      "bbbbbbbbbbbbbbbb",
      "bbbbbbbbbbbbbbbb"
    ],
    [
      "   cdabbbbbbbbbb",
      "   cabbbbbbbbbbb",
      "  cdabbbbbbbbbbb",
      "  cdabbbbbbbbbbb",
      "  cdabbbbbbbbbbb",
      "  cdabbbbbbbbbbb",
      "  cdabbbbbbbbbbb",
      "  cdabbbbbbbbbbb",
      "  cabbbbbbbbbbbb",
      " cdabbbbbbbbbbbb",
      " cdabbbbbbbbbbbb",
      " cdabbbbbbbbbbbb",
      " cdabbbbbbbbbbbb",
      " cabbbbbbbbbbbbb",
      "cdabbbbbbbbbbbbb",
      "cdabbbbbbbbbbbbb"
    ],
    [
      "      cdabbbbbbb",
      "     cdabbbbbbbb",
      "     cdabbbbbbbb",
      "     cdabbbbbbbb",
      "     cdabbbbbbbb",
      "     cdabbbbbbbb",
      "     cdabbbbbbbb",
      "     cabbbbbbbbb",
      "    cdabbbbbbbbb",
      "    cdabbbbbbbbb",
      "    cdabbbbbbbbb",
      "    cdabbbbbbbbb",
      "    cabbbbbbbbbb",
      "   cdabbbbbbbbbb",
      "   cdabbbbbbbbbb",
      "   cabbbbbbbbbbb"
    ],
    [
      "         cdabbbb",
      "        cdabbbbb",
      "        cdabbbbb",
      "        cdabbbbb",
      "        cdabbbbb",
      "        cdabbbbb",
      "        cdabbbbb",
      "       cdabbbbbb",
      "       cdabbbbbb",
      "       cdabbbbbb",
      "       cdabbbbbb",
      "       cabbbbbbb",
      "      cdabbbbbbb",
      "      cdabbbbbbb",
      "      cabbbbbbbb",
      "     cdabbbbbbbb"
    ],
    [
      "            cabb",
      "           cdabb",
      "           cdabb",
      "           cdabb",
      "           cdabb",
      "           cdabb",
      "           cabbb",
      "          cdabbb",
      "          cdabbb",
      "          cdabbb",
      "          cabbbb",
      "         cdabbbb",
      "         cdabbbb",
      "         cdabbbb",
      "        cdabbbbb",
      "        cdabbbbb"
    ],
    [
      "              cd",
      "              cd",
      "              cd",
      "              cd",
      "              cd",
      "              cd",
      "             cda",
      "             cda",
      "             cda",
      "             cda",
      "            cdab",
      "            cdab",
      "            cdab",
      "            cabb",
      "           cdabb",
      "           cabbb"
    ]
  ]
}