{
  "name": "multi_nuclearpowerplant_32_base8",
  "refpalette": "deceasedcraft:multi_nuclearpowerplant_32/multi_nuclearpowerplant_32_base8_palette",
  "xsize": 16,
  "zsize": 16,
  "slices": [
    [
      "aaaaaaaaab cd   ",
      "aaaaaaaaab cd   ",
      "aaaaaaaaab cd   ",
      "aaaaaaaaab cd   ",
      "aaaaaaaaab cd   ",
      "aaaaaaaaab cd   ",
      "aaaaaaaaab cd   ",
      "aaaaaaaaab cde  ",
      "aaaaaaaaab cd   ",
      "aaaaaaaaab cd   ",
      "aaaaaaaaab cd   ",
      "aaaaaaaaab cd   ",
      "aaaaaaaaab cd   ",
      "aaaaaaaaab cd   ",
      "aaaaaaaaab cd   ",
      "aaaaaaaaab cd   "
    ],
    [
      "=========fgfhiii",
      "=========fgfhiii",
      "=========fgfhiii",
      "=========fgfhiii",
      "=========fgfhiii",
      "=========fgfhiii",
      "=========fgfhiii",
      "=========fgfhjii",
      "=========fgfhiii",
      "=========fgfhiii",
      "=========fgfhiii",
      "=========fgfhiii",
      "=========fgfhiii",
      "=========fgfhiii",
      "=========fgfhiii",
      "=========fgfhiii"
    ],
    [
      "kkkkkkkkkflfdkkk",
      "kkkkkkkkkflfdkkk",
      "kkkkkkkkkflfdkkk",
      "kkkkkkkkkflfdkkk",
      "kkkkkkkkkflfdkkk",
      "kkkkkkkkkflfdkkk",
      "kkkkkkkkkflfdkkk",
      "kkkkkkkkkflfdkkk",
      "kkkkkkkkkflfdkkk",
      "kkkkkkkkkflfdkkk",
      "kkkkkkkkkflfdkkk",
      "kkkkkkkkkflfdkkk",
      "kkkkkkkkkflfdkkk",
      "kkkkkkkkkflfdkkk",
      "kkkkkkkkkflfdkkk",
      "kkkkkkkkkflfdkkk"
    ],
    [
      "kkkkkkkkkfffdkkk",
      "kkkkkkkkkfffdkkk",
      "kkkkkkkkkfffdkkk",
      "kkkkkkkkkfffdkkk",
      "kkkkkkkkkfffdkkk",
      "kkkkkkkkkfffdkkk",
      "kkkkkkkkkfffdkkk",
      "kkkkkkkkkfffdkkk",
      "kkkkkkkkkfffdkkk",
      "kkkkkkkkkfffdkkk",
      "kkkkkkkkkfffdkkk",
      "kkkkkkkkkfffdkkk",
      "kkkkkkkkkfffdkkk",
      "kkkkkkkkkfffdkkk",
      "kkkkkkkkkfffdkkk",
      "kkkkkkkkkfffdkkk"
    ],
    [
      "hhhhhhmn========",
      "hhhhhhmn========",
      "hhhhhhmn========",
      "hhhhhhmjoooojooo",
      "hhhhhhmmmmmmmmmm",
      "hhhhhhhhhhhhhhhh",
      "hhhhhhhhhhhhhhhh",
      "hhhhhhhhhhhhhhhh",
      "hhhhhhhhhhhhhhhh",
      "hhhhhhhhhhhhhhhh",
      "hhhhhhhhhhhhhhhh",
      "hhhhhhhhhhhhhhhh",
      "hhhhhhhhhhhhhhhh",
      "jhhhhhhhhhhhhhhh",
      "hhhhhhhhhhhhhhhh",
      "hhhhhhhhhhhhhhhh"
    ],
    [
      "       pqrrr    ",
      "      stqrrr    ",
      "       u      ww",
      "       euuuue xx",
      "       y        ",
      "                ",
      "                ",
      "                ",
      "                ",
      "                ",
      "                ",
      "                ",
      "                ",
      "e               ",
      "                ",
      "                "
    ]
  ]
}