{
  "name": "multi_nuclearpowerplant_32_base2",
  "refpalette": "deceasedcraft:multi_nuclearpowerplant_32/multi_nuclearpowerplant_32_base2_palette",
  "xsize": 16,
  "zsize": 16,
  "slices": [
    [
      "   a            ",
      "   a            ",
      "   a            ",
      "   a            ",
      "   a            ",
      "   a            ",
      "   a            ",
      "  a             ",
      "  a             ",
      "  a             ",
      "  a             ",
      " a              ",
      " a              ",
      "ba              ",
      "a               ",
      "a               "
    ],
    [
      "   a            ",
      "   a            ",
      "   a            ",
      "   a            ",
      "   a            ",
      "   a            ",
      "   a            ",
      "  a             ",
      "  a             ",
      "  a             ",
      "  a             ",
      " a              ",
      " a              ",
      "ba              ",
      "a               ",
      "a               "
    ],
    [
      "   a            ",
      "   a            ",
      "   a            ",
      "   a            ",
      "   a            ",
      "   a            ",
      "   a            ",
      "  a             ",
      "  a             ",
      "  a             ",
      "  a             ",
      " a              ",
      " a              ",
      "ba              ",
      "a               ",
      "a               "
    ],
    [
      "   a            ",
      "   a            ",
      "   a            ",
      "   a            ",
      "   a            ",
      "   a            ",
      "   a            ",
      "  a             ",
      "  a             ",
      "  a             ",
      "  a             ",
      " a              ",
      " a              ",
      "ba              ",
      "a               ",
      "a               "
    ],
    [
      "  cd            ",
      "  cd            ",
      "  cd            ",
      "  cd            ",
      "  cd            ",
      "  cd            ",
      " ccd            ",
      " cd             ",
      " cd             ",
      " cd             ",
      "ccd             ",
      "cd              ",
      "cd              ",
      "cd              ",
      "d               ",
      "d               "
    ],
    [
      "eecfffffffffffff",
      "eecfffffffffffff",
      "eecfffffffffffff",
      "eecfffffffffffff",
      "eecfffffffffffff",
      "eecfffffffffffff",
      "eccfffgggfffffgg",
      "ecffffffffffffff",
      "ecffffffffffffff",
      "ecffffffffffffff",
      "ccffffffffffffff",
      "cfffffffffffffff",
      "cfffffffffffffff",
      "cfffgggffffgggff",
      "ffffffffffffffff",
      "ffffffffffffffff"
    ]
  ]
}