{
  "name": "multi_communitycenter_3_ground",
  "refpalette": "deceasedcraft:multi_communitycenter_3/multi_communitycenter_3_ground_palette",
  "xsize": 16,
  "zsize": 16,
  "slices": [
    [
      "aaaaaaaaaaaaaaaa",
      "aaaaaaaaaaaaaaaa",
      "bbbcaaaaaaaaaaaa",
      "bbbcaaaaaaaaaaad",
      "bbbcaaaaaaaaaadd",
      "eeecaaaaaaaaaadd",
      "eeecaaaaaaaaaadd",
      "eeecaaaaffaaaadd",
      "eeecaaafggfaaaah",
      "eeecaafggggfaadh",
      "eeecaafggggfaadh",
      "eeecaafggggfaadh",
      "iiicaafggggfaaah",
      "jjikaafggggfaadh",
      "llmkaafggggfaadh",
      "lnmkaafggggfaadh"
    ],
    [
      "                ",
      "                ",
      "  op            ",
      " qop           r",
      "ssok          rr",
      "bbbk          rt",
      "bbbk          r ",
      "bbbk   uffu   rw",
      "bbbk  ufggfu  xy",
      "eeek  fggggf  rA",
      "eeek  fggggf  ry",
      "eeek  fggggf  rA",
      "BBik  fggggf  xA",
      "  ik  fggggf  rA",
      "   k  fggggf  ry",
      "  Ck  fggggf  rA"
    ],
    [
      "                ",
      "                ",
      "                ",
      "                ",
      "  o             ",
      "  o            D",
      "  op            ",
      "  op    ~      E",
      "  ok          xy",
      "bbbk           A",
      "bbFk           y",
      "bbFk           A",
      "bbbk          xA",
      "iiik           A",
      "IIIk           y",
      "IIIJ           A"
    ],
    [
      "                ",
      "                ",
      "                ",
      "                ",
      "                ",
      "                ",
      "                ",
      "        ~       ",
      "  o           xy",
      "  o            A",
      "  op           y",
      "  op           A",
      " qok          xA",
      "bbbk           A",
      "bbbk           y",
      "bbbk           A"
    ],
    [
      "                ",
      "                ",
      "                ",
      "                ",
      "                ",
      "                ",
      "                ",
      "        ~       ",
      "              xK",
      "               A",
      "               A",
      "               A",
      "  o           xA",
      "  o            A",
      "q op           A",
      "  op           A"
    ],
    [
      "                ",
      "                ",
      "                ",
      "                ",
      "                ",
      "                ",
      "                ",
      "        ~       ",
      "              LL",
      "              Lh",
      "              Lh",
      "              Lh",
      "              xh",
      "              Lh",
      "              Lh",
      "              Lh"
    ]
  ]
}