{
  "name": "multi_laboratory_9_base4",
  "refpalette": "deceasedcraft:multi_laboratory_9/multi_laboratory_9_base4_palette",
  "xsize": 16,
  "zsize": 16,
  "slices": [
    [
      "aaaaaaaaaaaaaaaa",
      "aaaaaaaaaaaaaaaa",
      "aaaaaaaaaaaaaaaa",
      "aaaaaaaaaaaaaaaa",
      "aaaaaaaaaaaaaaaa",
      "aaaaaaaaaaaaaaaa",
      "aaaaaaaaaaaaaaaa",
      "aaaaaaaaaaaaaaaa",
      "aaaaa!aaaaaaaaaa",
      "aaaaaaaaaaaaaaaa",
      "aaaaaaaaaaaaaaaa",
      "aaaaaaaaaaaaaaaa",
      "aaaaaaaaaaaaaaaa",
      "bbbbbbbbbbbbbbbb",
      "cccccccccccccccc",
      "vvvvvvvvvvvvvvvv"
    ],
    [
      "d     e  d    fe",
      "df   fe  d f   e",
      "d     e  d     e",
      "gf    hiijf   fh",
      "     f          ",
      "           k    ",
      "  lmnoooooonm   ",
      "pppppppppppppppp",
      "  qmrrrssiitmu  ",
      "                ",
      " w   x    x     ",
      " yw Ay x  yx AyA",
      "ww   A   AA   B ",
      "bbbbbbbbbbbbbbbb",
      "cccccccccccccccc",
      "vvvvvvvvvvvvvvvv"
    ],
    [
      "C     k  D      ",
      "E     F  I     J",
      "k     K  I     J",
      "L     M N      O",
      "                ",
      "                ",
      "   PQ RSTUVWP   ",
      "pppppppppppppppp",
      "   P X     YP   ",
      "                ",
      "                ",
      "                ",
      "                ",
      "bbbbbbbbbbbbbbbb",
      "cccccccccccccccc",
      "vvvvvvvvvvvvvvvv"
    ],
    [
      "                ",
      "                ",
      "                ",
      "                ",
      "                ",
      "                ",
      "   Z        Z   ",
      "ppppp0p0p00ppppp",
      "    12121212    ",
      "                ",
      "                ",
      "                ",
      "                ",
      "bbbbbbbbbbbbbbbb",
      "cccccccccccccccc",
      "vvvvvvvvvvvvvvvv"
    ],
    [
      "                ",
      "                ",
      "                ",
      "                ",
      "                ",
      "                ",
      "                ",
      "pppppp000p0ppppp",
      "                ",
      "                ",
      "                ",
      "                ",
      "                ",
      "bbbbbbbbbbbbbbbb",
      "cccccccccccccccc",
      "vvvvvvvvvvvvvvvv"
    ],
    [
      "344p44344544p445",
      "344p44344544p445",
      "544p44544344p443",
      "544p44553344p443",
      "444p44444444p444",
      "444p44444444p444",
      "444p44444444p444",
      "pppppppppppppppp",
      "66666666666666p6",
      "6566656666366656",
      "6366656666566656",
      "6566656666566656",
      "6666666666666666",
      "bbbbbbbbbbbbbbbb",
      "cccccccccccccccc",
      "vvvvvvvvvvvvvvvv"
    ]
  ]
}