{
  "name": "multi_laboratory_9_base3",
  "refpalette": "deceasedcraft:multi_laboratory_9/multi_laboratory_9_base3_palette",
  "xsize": 16,
  "zsize": 16,
  "slices": [
    [
      "aaaaaaaaaaaaaaaa",
      "aaaaaaaaaabaaaaa",
      "aaaaaaacaaaaaaaa",
      "aacaaaaaaaaaaaaa",
      "acaaaaaaaaaaaaaa",
      "bcdbaaaaaaaaaaaa",
      "a  aaaaaaaaa!aaa",
      "dddaaaaaaaaaaa a",
      "baaaa!aaaaaaaaaa",
      "aaacaaaeaaaaaaaa",
      "aaaaaaaacaaaaaaa",
      "aaaaaaaaaaaaaaaa",
      "aaaaaaaaaaaaaaaa",
      "ffffffffffffffff",
      "gggggggggggggggg",
      "vvvvvvvvvvvvvvvv"
    ],
    [
      "hi     j  k    j",
      "h j  kli j     l",
      "h    ml  h m   j",
      " m  nopqqrs     ",
      "it       u      ",
      " w   m xyABC    ",
      "   D  EFFFFIJK  ",
      "dLmMLddddddddddd",
      "  m NNNcOqqPQ RR",
      "   t Siw TUV    ",
      " S i   Wt      X",
      "YZ           Z  ",
      " Y Z01 S Z0  i  ",
      "ffffffffffffffff",
      "gggggggggggggggg",
      "vvvvvvvvvvvvvvvv"
    ],
    [
      "                ",
      "                ",
      "         S      ",
      "                ",
      "                ",
      "                ",
      "       2C3 45   ",
      "d  6cddddddddddd",
      "       c   7    ",
      "                ",
      "                ",
      "                ",
      "                ",
      "ffffffffffffffff",
      "gggggggggggggggg",
      "vvvvvvvvvvvvvvvv"
    ],
    [
      "                ",
      "                ",
      "                ",
      "     6          ",
      "                ",
      "    c           ",
      "   8c       9   ",
      "   ce##dd##ddddd",
      "     $%e$%$%    ",
      "                ",
      "                ",
      "                ",
      "                ",
      "ffffffffffffffff",
      "gggggggggggggggg",
      "vvvvvvvvvvvvvvvv"
    ],
    [
      "                ",
      "                ",
      "                ",
      "     ^          ",
      "    c           ",
      "    e8          ",
      "                ",
      "& *c(#d###dddddd",
      "   8c  c8       ",
      "      )c        ",
      "       8        ",
      "                ",
      "                ",
      "ffffffffffffffff",
      "gggggggggggggggg",
      "vvvvvvvvvvvvvvvv"
    ],
    [
      "+--d--+--[--d--[",
      "[--d--[--[--d--[",
      "[--d--c--+--d--[",
      "[--d-c[[]]--d--[",
      "---dc-------d---",
      "---d--------d---",
      "---d--------d---",
      "dddddddddddddddd",
      "****c***********",
      "*[***ecc**[***[*",
      "*+***+****+***+*",
      "*+***[****]***+*",
      "****************",
      "ffffffffffffffff",
      "gggggggggggggggg",
      "vvvvvvvvvvvvvvvv"
    ]
  ]
}