{
  "name": "multi_laboratory_9_base2",
  "refpalette": "deceasedcraft:multi_laboratory_9/multi_laboratory_9_base2_palette",
  "xsize": 16,
  "zsize": 16,
  "slices": [
    [
      "aaaaaaaaaaaaaaaa",
      "aaaaaaaaaaaaaaaa",
      "aaaaaaaaaaaaaaaa",
      "aaaaaaaaaaaaaaaa",
      "aaaaaaaaaaaaaaaa",
      "aaaaaaaaaaaaaaaa",
      "aaaaaaaaaaaaaaaa",
      "aaaaaaaaaaaaaaaa",
      "aaaaaaaaaaaaaaaa",
      "aaaaaaaaaaaaaaaa",
      "aaaaaaaaaaaaaaaa",
      "aaaaaaaaaaaaaaaa",
      "aaaaaaaaaaaaaaaa",
      "bbbbbbbbbbbbbbbb",
      "cccccccccccccccc",
      "vvvvvvvvvvvvvvvv"
    ],
    [
      "de   fg  d    eg",
      "d     g  de    g",
      "de    g  d    eg",
      "h    eijjke    l",
      "                ",
      "                ",
      "   mnoooooopm   ",
      "qqqqqqqqqqqqqqqq",
      "   mrrrssjjtm   ",
      "                ",
      " u        w   x ",
      "wyw uyw  wyw Ay ",
      " w   w    w   x ",
      "bbbbbbbbbbbbbbbb",
      "cccccccccccccccc",
      "vvvvvvvvvvvvvvvv"
    ],
    [
      "      B        C",
      "C     C  D      ",
      "D     E  F     E",
      "I      JK       ",
      "                ",
      "                ",
      "   L MNOP Q L   ",
      "qqqqqqqqqqqqqqqq",
      "   LRS     TU   ",
      "                ",
      "                ",
      "                ",
      "                ",
      "bbbbbbbbbbbbbbbb",
      "cccccccccccccccc",
      "vvvvvvvvvvvvvvvv"
    ],
    [
      "                ",
      "                ",
      "                ",
      "                ",
      "                ",
      "                ",
      "   V        V   ",
      "qqqqqWqWqWWqqqqq",
      "    XYXYXYXY    ",
      "                ",
      "                ",
      "                ",
      "                ",
      "bbbbbbbbbbbbbbbb",
      "cccccccccccccccc",
      "vvvvvvvvvvvvvvvv"
    ],
    [
      "                ",
      "                ",
      "         !      ",
      "                ",
      "                ",
      "                ",
      "                ",
      "qqqqqWWqWWWqqqqq",
      "                ",
      "                ",
      "                ",
      "                ",
      "                ",
      "bbbbbbbbbbbbbbbb",
      "cccccccccccccccc",
      "vvvvvvvvvvvvvvvv"
    ],
    [
      "Z00q00100Z00q00Z",
      "Z00q00Z00Z00q00Z",
      "Z00q00Z00100q00Z",
      "Z00q00ZZZZ00q00Z",
      "000q00000000q000",
      "000q00000000q000",
      "000q00000000q000",
      "qqqqqqqqqqqqqqqq",
      "2222222222222222",
      "2322232222322232",
      "2322232222322232",
      "2!22232222422232",
      "2222222222222222",
      "bbbbbbbbbbbbbbbb",
      "cccccccccccccccc",
      "vvvvvvvvvvvvvvvv"
    ]
  ]
}