{
  "name": "multi_laboratory_9_base5",
  "refpalette": "deceasedcraft:multi_laboratory_9/multi_laboratory_9_base5_palette",
  "xsize": 16,
  "zsize": 16,
  "slices": [
    [
      "  a     bc   a  ",
      "  a          a  ",
      "  a          a  ",
      "  a        d a  ",
      "  a          a  ",
      "  a          e  ",
      "  a    d     a  ",
      "  a         fa  ",
      "  aaaaaaaaaaaa  ",
      "                ",
      "                ",
      "                ",
      "                ",
      "gggggggggggggggg",
      "hhhhhhhhhhhhhhhh",
      "vvvvvvvvvvvvvvvv"
    ],
    [
      "  a    ij    a  ",
      "  a k   l    a  ",
      "  a          a  ",
      "  a        m a  ",
      "  a    n     a  ",
      "  a          a  ",
      "  a    d     a  ",
      "  a         oa  ",
      "  aaaaaaaaaaaa  ",
      "                ",
      "                ",
      "                ",
      "                ",
      "ggggppgpppppgggg",
      "hhhhhhhhhhhhhhhh",
      "vvvvvvvvvvvvvvvv"
    ],
    [
      "  a    q     a  ",
      "  a f   b    a  ",
      "  a          a  ",
      "  a        m a  ",
      "  a    q     a  ",
      "  a          a  ",
      "  a    d     a  ",
      "  a        f a  ",
      "  aaaaaaaaaaaa  ",
      "                ",
      "                ",
      "                ",
      "                ",
      "gggggpppgpgpgggg",
      "hhhhhhhhhhhhhhhh",
      "vvvvvvvvvvvvvvvv"
    ],
    [
      "  a    f     a  ",
      "  a ff  b    a  ",
      "  a  r       a  ",
      "  a        m a  ",
      "  a    q     a  ",
      "  a         na  ",
      "  a    d    fa  ",
      "  a       o!fa  ",
      "  aaaaaaaaaaaa  ",
      "                ",
      "                ",
      "                ",
      "                ",
      "ggggpgppppgpgggg",
      "hhhhhhhhhhhhhhhh",
      "vvvvvvvvvvvvvvvv"
    ],
    [
      "  a   fffo   a  ",
      "  affoffj    a  ",
      "  a  d       a  ",
      "  a        m a  ",
      "  a    f     a  ",
      "  a         oa  ",
      "  a    d  fofa  ",
      "  a         fa  ",
      "  aaaaaaaaaaaa  ",
      "                ",
      "                ",
      "                ",
      "                ",
      "gggggggggggggggg",
      "hhhhhhhhhhhhhhhh",
      "vvvvvvvvvvvvvvvv"
    ],
    [
      "sstuwuuuuuuwxtss",
      "sstuwuuuuuuwxtss",
      "sstuwyAAAABwutss",
      "sstuwuuuuuuwutss",
      "sstuwuuofuuwutss",
      "sstuwuuuffuwutss",
      "sstuCyAAAABCutss",
      "sstuuxuxxuuuutss",
      "ssttttttttttttss",
      "ssssssssssssssss",
      "ssssssssssssssss",
      "ssssssssssssssss",
      "ssssssssssssssss",
      "gggggggggggggggg",
      "hhhhhhhhhhhhhhhh",
      "vvvvvvvvvvvvvvvv"
    ]
  ]
}