{
  "name": "multi_laboratory_9_ground",
  "refpalette": "deceasedcraft:multi_laboratory_9/multi_laboratory_9_ground_palette",
  "xsize": 16,
  "zsize": 16,
  "slices": [
    [
      "aaaaabccccbaaaaa",
      "aaaaacbccbcaaaaa",
      "aaaaaacbbcaaaaaa",
      "dddaaaaaaaaaaddd",
      "dddaaaaaaaaaaddd",
      "dddaaaaaaaaaaddd",
      "dddaaaaaaaaaaddd",
      "aaaaaaaaaaaaaaaa",
      "aaaaaaaaaaaaaaaa",
      "aaaaaaaaaaaaaaaa",
      "eeeeeeeeeeeeeeee",
      "ffffffffffffffff",
      "ffffffffffffffff",
      "ffffffffffffffff",
      "ggggggggggggzggg",
      "gzzgzggzzzgzgzzz"
    ],
    [
      "   h  i     j   ",
      "  kl     m  nk  ",
      "ooo    p    qooo",
      "rsrl        ntru",
      " s l wwwwww n   ",
      "xyxl  A  A  nyyB",
      "   l CCCCCC n   ",
      "o  l  D  D  n  o",
      "o              o",
      "o    k EF k    o",
      "IJJJJeK  KeJJJJI",
      "                ",
      "                ",
      "              LM",
      "            N   ",
      "  N           N "
    ],
    [
      "   h        j   ",
      "  Ol        nO  ",
      "ooo          ooo",
      " s l        n   ",
      " s l PPPPPP n   ",
      "QyQl        nyyR",
      "   l S      n   ",
      "o  l        n  o",
      "o              o",
      "o    O TU O    o",
      "IJJJVeK  KeVJJJI",
      "                ",
      "                ",
      "             LMM",
      "                ",
      "                "
    ],
    [
      "   h        j   ",
      "  Wl        nW  ",
      "ooo          ooo",
      " s l        n  X",
      " s l PPPPPP n   ",
      "yyyl        nyyy",
      "   l        n   ",
      "o  l        n  o",
      "o              o",
      "o    W    W    o",
      "IJJJVeKKKKeVJJJI",
      "                ",
      "                ",
      "            LMYZ",
      "                ",
      "                "
    ],
    [
      "   h        j   ",
      "   l        n   ",
      "ooo          ooo",
      " s l        n   ",
      " s l PPPPPP n   ",
      "yyyl        nyyy",
      "   l        n   ",
      "o  l        n  o",
      "o  l        n  o",
      "o  l        n  o",
      "IJJJVeKKKKeVJJJI",
      "                ",
      "                ",
      "           LMZZY",
      "                ",
      "                "
    ],
    [
      "000l        n000",
      "000l00000000n000",
      "ooo1222222223ooo",
      "444l00000000n444",
      "454l0PPPPPP0n464",
      "444l00000000n444",
      "454l00 00 00n454",
      "o44l00000000n44o",
      "o54l00000000n46o",
      "o44l00000000n44o",
      "IJJJJeJJJJeJJJJI",
      "                ",
      "                ",
      "          LMZZYY",
      "                ",
      "                "
    ]
  ]
}