{
  "name": "multi_laboratory_9_top",
  "refpalette": "deceasedcraft:multi_laboratory_9/multi_laboratory_9_top_palette",
  "xsize": 16,
  "zsize": 16,
  "slices": [
    [
      "aaaaaaaaaaaaaaaa",
      "aaaaaaaaaaaaaaaa",
      "aaaaaaaaaaaaaaaa",
      "aaaaaaaaaaaaaaaa",
      "aaaaaaaaaaaaaaaa",
      "aaaaaaaaaaaaaaaa",
      "aaaaaaaaaaaaaaaa",
      "aaaaaaaaaaaaaaaa",
      "aaaaaaaaaaaaaaaa",
      "aaaaaaaaaaaaaaaa",
      "bbbbbbbbbbbbbbbb",
      "cccccdeeeedccccc",
      "cccccfggggfccccc",
      "hhhhhhhhhijklklk",
      "                ",
      "                "
    ],
    [
      "mmnopppppppponqr",
      "    qs   tst    ",
      "    qst  tsq    ",
      "                ",
      "                ",
      "                ",
      " uwww      wwww ",
      "xyAAAA    AAAAyx",
      "                ",
      "                ",
      "BBBBBn    nBBBBB",
      "     C    D     ",
      "     C    D     ",
      "jkjjjjjjjjllllll",
      "                ",
      "                "
    ],
    [
      "  nE        En  ",
      "     F          ",
      "          F     ",
      "                ",
      "                ",
      "                ",
      "                ",
      "  F F      F F  ",
      "                ",
      "                ",
      "     n    n     ",
      "    C      D    ",
      "    C      D    ",
      "lllllllkllllklll",
      "                ",
      "                "
    ],
    [
      "  nI        In  ",
      "                ",
      "                ",
      "                ",
      "                ",
      "                ",
      "                ",
      "                ",
      "                ",
      "                ",
      "     n    n     ",
      "   C        D   ",
      "   C        D   ",
      "lJKKlkllKJKllKll",
      "                ",
      "                "
    ],
    [
      "  n          n  ",
      "                ",
      "                ",
      "                ",
      "                ",
      "                ",
      "                ",
      "                ",
      "                ",
      "                ",
      "     n    n     ",
      "  C          D  ",
      "  C          D  ",
      "lKlllKJlJkKlllKl",
      "                ",
      "                "
    ],
    [
      "  b          b  ",
      "  ff        ff  ",
      "   fff    fff   ",
      "     ffffff     ",
      "                ",
      "                ",
      "                ",
      "                ",
      "                ",
      "                ",
      "fffffbffffbfffff",
      " C            D ",
      " C            D ",
      "llJKllllKKllKJJl",
      "                ",
      "                "
    ],
    [
      "LLzMMNNNNNNMMzLL",
      "LLzzMMMNNMMMzzLL",
      "LLLzzzMMMMzzzLLL",
      "LLLLLzzzzzzLLLLL",
      "LLLLLLLLLLLLLLLL",
      "LLLLLLLLLLLLLLLL",
      "LLLLLLLLLLLLLLLL",
      "LLLLLLLLLLLLLLLL",
      "LLLLLLLLLLLLLLLL",
      "LLLLLLLLLLLLLLLL",
      "bbbbbbbbbbbbbbbb",
      "C    d    d    D",
      "C    f    f    D",
      "kllllllllllllllk",
      "                ",
      "                "
    ],
    [
      "  O             ",
      "   O        O   ",
      "    OP    P     ",
      "      OP  O     ",
      "                ",
      "                ",
      "                ",
      "                ",
      "  Q   Q  Q   Q  ",
      " RS  RS  SR  SR ",
      "BBBBBBBBBBBBBBBB",
      "                ",
      "                ",
      "llllllllllllllll",
      "                ",
      "                "
    ],
    [
      "                ",
      "                ",
      "                ",
      "                ",
      "                ",
      "                ",
      "                ",
      "                ",
      "                ",
      " R   R    R   R ",
      "                ",
      "                ",
      "                ",
      "lllllllkllllllll",
      "                ",
      "                "
    ],
    [
      "                ",
      "                ",
      "                ",
      "                ",
      "                ",
      "                ",
      "                ",
      "                ",
      "                ",
      " T   U    T   T ",
      "                ",
      "                ",
      "                ",
      "llllllllllllllll",
      "                ",
      "                "
    ],
    [
      "                ",
      "                ",
      "                ",
      "                ",
      "                ",
      "                ",
      "                ",
      "                ",
      "VWV VWV  VWV VWV",
      "WXW WYW  WXW WXW",
      "VWV VWV  VWV VWV",
      "                ",
      "                ",
      "llllllllllllllll",
      "                ",
      "                "
    ]
  ]
}