{
  "name": "multi_laboratory_9_base1",
  "refpalette": "deceasedcraft:multi_laboratory_9/multi_laboratory_9_base1_palette",
  "xsize": 16,
  "zsize": 16,
  "slices": [
    [
      "aaaaaaaaaaaaaaaa",
      "aaaaaaaaaaaaaaaa",
      "aaaaaaaaaaaaaaaa",
      "aaaaaaaaaaaaaaaa",
      "aaaaaaaaaaaaaaaa",
      "aaaaaaaaaaaaaaaa",
      "aaaaaaaaaaaaaaaa",
      "aaaaaaaaaaaaaaaa",
      "aaaaaaaaaaaaaaaa",
      "aaaaaaaaaaaaaaaa",
      "aaaaaaaaaaaaaaaa",
      "aaaaaaaaaaaaaaaa",
      "aaaaaaaaaaaaaaaa",
      "bbbbbbbbbbbbbbbb",
      "cccccccccccccccc",
      "vvvvvvvvvvvvvvvv"
    ],
    [
      "deeedfgeefgeeeed",
      "ehhi        jhhe",
      "ehk          khe",
      "ek            ke",
      "e  lm  lm  lm  e",
      "e              e",
      "e  lm  lm  lm  e",
      "d              d",
      "en   oooooo    e",
      "en ooooddoooo  e",
      "ep oooooooooo pe",
      "ehpoooooooooophe",
      "ehhddddddddddhhe",
      "bbbbbbbbbbbbbbbb",
      "cccccccccccccccc",
      "vvvvvvvvvvvvvvvv"
    ],
    [
      "deeedqreeqreeeed",
      "e!s          sse",
      "es            se",
      "e              e",
      "e              e",
      "e              e",
      "e              e",
      "d              d",
      "e              e",
      "et     uu      e",
      "e              e",
      "es            se",
      "e!sdwwwwwwwwds!e",
      "bbbbbbbbbbbbbbbb",
      "cccccccccccccccc",
      "vvvvvvvvvvvvvvvv"
    ],
    [
      "deeedxxeexxeeeed",
      "ess          sse",
      "e              e",
      "e              e",
      "e              e",
      "e              e",
      "e              e",
      "d              d",
      "e              e",
      "e              e",
      "e              e",
      "e              e",
      "essdyyyyyyyydsse",
      "bbbbbbbbbbbbbbbb",
      "cccccccccccccccc",
      "vvvvvvvvvvvvvvvv"
    ],
    [
      "deeedeeeeeeeeeed",
      "es            se",
      "e              e",
      "e              e",
      "e              e",
      "e              e",
      "e              e",
      "d              d",
      "e              e",
      "e              e",
      "e  A        A  e",
      "e              e",
      "es dBBBBBBBBd se",
      "bbbbbbbbbbbbbbbb",
      "cccccccccccccccc",
      "vvvvvvvvvvvvvvvv"
    ],
    [
      "deeedeeeeeedeeed",
      "eCCCCCCCCCCCCCCe",
      "eCCCCCCCCCCCCCCe",
      "eCCCDCCCCCCDCCCe",
      "eCCCDCCCCCCDCCCe",
      "eCCCDCCCCCCECCCe",
      "eCCCDCCCCCCDCCCe",
      "dCCCDCCCCCCDCCCd",
      "eCCCCCCCCCCCCCCe",
      "eCCCCCCCCCCCCCCe",
      "eCCACCCCCCCCACCe",
      "eCCCCCCCCCCCCCCe",
      "eCCFFFFFFFFFFCCe",
      "bbbbbbbbbbbbbbbb",
      "cccccccccccccccc",
      "vvvvvvvvvvvvvvvv"
    ]
  ]
}