{
  "name": "multi_laboratory_9_base6",
  "refpalette": "deceasedcraft:multi_laboratory_9/multi_laboratory_9_base6_palette",
  "xsize": 16,
  "zsize": 16,
  "slices": [
    [
      "aaaaaaaaaaaaaaaa",
      "aaaaaaaaaaaaaaaa",
      "aaaaaaaaaaaaaaaa",
      "aaaaaaaaaaaaaaaa",
      "aaaaaaaaaaaaaaaa",
      "aaaaaaaaaaaaaaaa",
      "aaaa!aaaaaaaaaaa",
      "aaaaaaaaaaaaaaaa",
      "aaaaaaaaaaaaaaaa",
      "aaaaaaaaaaaaaaaa",
      "aaaaaaaaaaaaaaaa",
      "aaaaaaaaaaaaaaaa",
      "aaaaaaaaaaaaaaaa",
      "bbbbbbbbbbbbbbbb",
      "cccccccccccccccc",
      "vvvvvvvvvvvvvvvv"
    ],
    [
      "  deefeeggeeed f",
      "  deeeeeegeeedhf",
      " ideefefeefgedj ",
      " ideeeffkgggkdj ",
      " id!eeefggekedj ",
      " ideeeeekegffdj ",
      "  degeeeeekfedh ",
      "  leeeeeeegfed h",
      "  ddddddddddddm ",
      "      nnnn o    ",
      "     innnnj     ",
      "     innnnj     ",
      "      nnnn      ",
      "bbbbbbbbbbbbbbbb",
      "cccccccccccccccc",
      "vvvvvvvvvvvvvvvv"
    ],
    [
      "  p          p q",
      "  p          p  ",
      "  p    q  f  pff",
      "  p    rs   qkkt",
      "  p    r   q p  ",
      "  p     q  urh  ",
      "  p       q f   ",
      "  p        kfp  ",
      "  ppppwxywp  p  ",
      "      w  w      ",
      "      A  B      ",
      "      C  D      ",
      "      w  w      ",
      "bbbbbbbEEbbbbbbb",
      "cccccccccccccccc",
      "vvvvvvvvvvvvvvvv"
    ],
    [
      "  p          p  ",
      "  p          p  ",
      "  p       q  pk ",
      "  p          p  ",
      "  p             ",
      "  p        F    ",
      "  p             ",
      "  p        fkI  ",
      "  ppppwJKwpLpp  ",
      "     MwNMwN     ",
      "      O  P      ",
      "      Q  R      ",
      "     MwNMwN     ",
      "bbbbbbbEEbbbbbbb",
      "cccccccccccccccc",
      "vvvvvvvvvvvvvvvv"
    ],
    [
      "  p     S    p  ",
      "  p          p  ",
      "  p          p  ",
      "  p          I  ",
      "  p          p  ",
      "  p             ",
      "  p          T  ",
      "  p        qfp  ",
      "  ppppwwwwpppp  ",
      "      wwww      ",
      "      wwww      ",
      "      wwww      ",
      "      wwww      ",
      "bbbbbbbbbbbbbbbb",
      "cccccccccccccccc",
      "vvvvvvvvvvvvvvvv"
    ],
    [
      "  p     U    p  ",
      "  p          p  ",
      "  p          p  ",
      "  p      VWXYp  ",
      "  p          p  ",
      "  p             ",
      "  p    Z     f  ",
      "  p         fp  ",
      "  pppppppppppp  ",
      "      0  0      ",
      "      0  0      ",
      "      0  0      ",
      "      0  0      ",
      "bbbbbbbbbbbbbbbb",
      "cccccccccccccccc",
      "vvvvvvvvvvvvvvvv"
    ]
  ]
}