{
  "name": "multi_courtyardofficetower_8_floor14",
  "refpalette": "deceasedcraft:multi_courtyardofficetower_8/multi_courtyardofficetower_8_floor14_palette",
  "xsize": 16,
  "zsize": 16,
  "slices": [
    [
      "                ",
      "                ",
      "                ",
      "                ",
      "                ",
      "                ",
      "                ",
      "                ",
      "   a       a    ",
      "   a       a    ",
      "   a   b   a    ",
      "ccdadcccccdaaaa ",
      "   effffff d    ",
      "   eggggggfc    ",
      "   eggggggfc    ",
      "   eggghggfcb   "
    ],
    [
      "                ",
      "                ",
      "                ",
      "                ",
      "                ",
      "                ",
      "                ",
      "                ",
      "   a       a    ",
      "   a       a    ",
      "   a   b   a    ",
      "ccdadcccccdaaaa ",
      "   e       d    ",
      "   e       c    ",
      "   e  iii  c    ",
      "   e  iji  cb   "
    ],
    [
      "                ",
      "                ",
      "                ",
      "                ",
      "                ",
      "                ",
      "                ",
      "                ",
      "   a       a    ",
      "   a       a    ",
      "   a   b   a    ",
      "ccdadcccccdaaaa ",
      "   e       d    ",
      "   e       c    ",
      "   e  klk  c    ",
      "   e  lkl  cb   "
    ],
    [
      "                ",
      "                ",
      "                ",
      "                ",
      "                ",
      "                ",
      "                ",
      "                ",
      "   a       a    ",
      "   a       a    ",
      "   a   b   a    ",
      "ccdadcccccdaaaa ",
      "   e       d    ",
      "   e       c    ",
      "   e  mnm  c    ",
      "   e  nmn  cb   "
    ],
    [
      "                ",
      "                ",
      "                ",
      "                ",
      "                ",
      "                ",
      "                ",
      "                ",
      "   a       a    ",
      "   a       a    ",
      "   a   b   a    ",
      "ccdadcccccdaaaa ",
      "   e       d    ",
      "   e       c    ",
      "   e       c    ",
      "   e   j   cb   "
    ],
    [
      "                ",
      "                ",
      "                ",
      "                ",
      "                ",
      "                ",
      "                ",
      "                ",
      "   a       a    ",
      "   a       a    ",
      "   a   b   a    ",
      "ccdadcccccdaaaa ",
      "oooaoooooood    ",
      "opoaoooooooc    ",
      "oooaoooooooc    ",
      "oooaooohooocb   "
    ]
  ]
}