{
  "name": "multi_courtyardofficetower_8_floor22",
  "refpalette": "deceasedcraft:multi_courtyardofficetower_8/multi_courtyardofficetower_8_floor22_palette",
  "xsize": 16,
  "zsize": 16,
  "slices": [
    [
      "                ",
      "                ",
      "                ",
      "                ",
      "                ",
      "                ",
      "                ",
      "                ",
      "   a       a    ",
      "   a       a    ",
      "   a       a    ",
      "aaaaaaaaaaaaaaa ",
      "   a       a    ",
      "   a       a    ",
      "   a       a    ",
      "   a       a    "
    ],
    [
      "                ",
      "                ",
      "                ",
      "                ",
      "                ",
      "                ",
      "                ",
      "                ",
      "   a       a    ",
      "   a       a    ",
      "   a       a    ",
      "aaaaaaaaaaaaaaa ",
      "bbbabbbbbbba    ",
      "ccbabcccccba    ",
      "ccbabcccccba    ",
      "ccbabcccccba    "
    ],
    [
      "                ",
      "                ",
      "                ",
      "                ",
      "                ",
      "                ",
      "                ",
      "                ",
      "   a       a    ",
      "   a       a    ",
      "   a       a    ",
      "aaaaaaaaaaaaaaa ",
      "   a       a    ",
      "   a       a    ",
      "   a       a    ",
      "   a       a    "
    ],
    [
      "                ",
      "                ",
      "                ",
      "                ",
      "                ",
      "                ",
      "                ",
      "                ",
      "   a       a    ",
      "   a       a    ",
      "   a       a    ",
      "aaaaaaaaaaaaaaa ",
      "   a       a    ",
      "   a       a    ",
      "   a       a    ",
      "   a       a    "
    ],
    [
      "                ",
      "                ",
      "                ",
      "                ",
      "                ",
      "                ",
      "                ",
      "                ",
      "   a       a    ",
      "   a       a    ",
      "   a       a    ",
      "aaaaaaaaaaaaaaa ",
      "   a       a    ",
      "   a       a    ",
      "   a       a    ",
      "   a       a    "
    ],
    [
      "                ",
      "                ",
      "                ",
      "                ",
      "                ",
      "                ",
      "                ",
      "                ",
      "   a       a    ",
      "   a       a    ",
      "   a       a    ",
      "aaaaaaaaaaaaaaa ",
      "   a       a    ",
      "   a       a    ",
      "   a       a    ",
      "   a       a    "
    ]
  ]
}