{
  "name": "multi_courtyardofficetower_8_base1",
  "refpalette": "deceasedcraft:multi_courtyardofficetower_8/multi_courtyardofficetower_8_base1_palette",
  "xsize": 16,
  "zsize": 16,
  "slices": [
    [
      "vvvvvvvvvvvvvvvv",
      "vvvvvvvvvvvvvvvv",
      "vvvvvvvvvvvvvvvv",
      "vvvvvvvvvvvvvvvv",
      "vvvvvvvvvvvvvvvv",
      "vvvvvvvvvvvvvvvv",
      "vvvvvvvvvvvvvvvv",
      "vvvvvvvvvvvvvvvv",
      "vvvavvvvvvvabvvv",
      "vvvavvvvvvvabbvv",
      "vvvavvvvvvvabbbv",
      "vvvavvvvvvvaaaav",
      "bbbbbbbbbbbvvvvv",
      "bbbbbbbbbbbbbbbv",
      "bbbbbbbbbbbbbbbv",
      "bbbbbbbbbbbbbbbv"
    ],
    [
      "vvvvvvvvvvvvvvvv",
      "cccccccccccccccc",
      "HHHHHHHHHHHHHHHH",
      "HHHHHHHHHHHHHHHH",
      "HHHHHHHHHHHHHHHH",
      "HHHHHHHHHHHHHHHH",
      "ccccccccccccccHH",
      "ccccccccccccvccH",
      "cccacccccccabvcc",
      "cccacccccccabbvc",
      "cccacccccccabbbv",
      "cccacccccccaaaav",
      "dddddddddddvvvvv",
      "eeeeeeedffdbbbbv",
      "eeeeeeedffdbbbbv",
      "eeeeeeedffdbbbbv"
    ],
    [
      "vvvvvvvvvvvvvvvv",
      "                ",
      "                ",
      "                ",
      "                ",
      "                ",
      "                ",
      "g h g h     v   ",
      "   a       abv  ",
      " i a       abbv ",
      "j kaj k    abbbv",
      "lllallll  laaaav",
      "mmmmmmmm  mvvvvv",
      "eeeeeeem  mbbbbv",
      "eeeeeeem  mbbbbv",
      "eeeeeeem  mbbbbv"
    ],
    [
      "vvvvvvvvvvvvvvvv",
      "                ",
      "                ",
      "                ",
      "                ",
      "                ",
      "                ",
      "            v   ",
      "   a       abv  ",
      "   a       abbv ",
      "   a       abbbv",
      "   a       aaaav",
      "mmmmmmmm  mvvvvv",
      "eeeeeeem  mbbbbv",
      "eeeeeeem  mbbbbv",
      "eeeeeeem  mbbbbv"
    ],
    [
      "vvvvvvvvvvvvvvvv",
      "                ",
      "                ",
      "                ",
      "                ",
      "                ",
      "                ",
      "            v   ",
      "   a       abv  ",
      "   a       abbv ",
      "   a       abbbv",
      "   a       aaaav",
      "mmmmmmmm  mvvvvv",
      "eeeeeeem  mbbbbv",
      "eeeeeeem  mbbbbv",
      "eeeeeeem  mbbbbv"
    ],
    [
      "vvvvvvvvvvvvvvvv",
      "nnnnnnnnnnnnnnnn",
      "nnnnnnnnnnnnnnnn",
      "nnnnnnnnnnnnnnnn",
      "nnnnnnnnnnnnnnnn",
      "nnnnnnnnnnnnnnnn",
      "nnnnnnnnnnnnnnnn",
      "nnnonnnnnnnovnnn",
      "nnnannnnnnnabvnn",
      "nnnannnnnnnabbvn",
      "nnnannnnnnnabbbv",
      "nnnannnnnnnaaaav",
      "mmmmmmmmmmmvvvvv",
      "eeeeeeemnnmbbbbv",
      "eeeeeeemnnmbbbbv",
      "eeeeeeemnnmbbbbv"
    ]
  ]
}