{
  "name": "multi_courtyardofficetower_8_ground",
  "refpalette": "deceasedcraft:multi_courtyardofficetower_8/multi_courtyardofficetower_8_ground_palette",
  "xsize": 16,
  "zsize": 16,
  "slices": [
    [
      "aaaaaaaaaaaaaaaa",
      "baaaaaaaaaaaaaaa",
      "aabaaaaaaaaaaaaa",
      "bbbbbbaaaaaaaaaa",
      "bbabbababaaaaaaa",
      "bbabbbbbaaaaaaaa",
      "aabbabbbaaaaaaaa",
      "baaaaabbbaaaaaaa",
      "aaacabbbbaacaaaa",
      "aaacaabbbbacaaaa",
      "aaacaabbabacaaaa",
      "aaacaabbbaacccca",
      "aaaaabbabaaaaaaa",
      "aaaaaaabbbaaaaaa",
      "aaaaaabbbbaaaaaa",
      "aaaaaabbaabaaaaa"
    ],
    [
      "               d",
      "       de de    ",
      "             d  ",
      "              e ",
      "                ",
      "          e     ",
      "             d  ",
      "           d e  ",
      "   c       c    ",
      "   c       c    ",
      " d c       c    ",
      "   c       cccc ",
      "d          d  d ",
      "            d d ",
      "  d        de  d",
      "d  d            "
    ],
    [
      "                ",
      "        f  f    ",
      "                ",
      "              f ",
      "                ",
      "          f     ",
      "                ",
      "             f  ",
      "   c       c    ",
      "   c       c    ",
      "   c       c    ",
      "   c       cccc ",
      "                ",
      "              d ",
      "            f   ",
      "                "
    ],
    [
      "                ",
      "        d  d    ",
      "                ",
      "              d ",
      "                ",
      "          d     ",
      "                ",
      "             d  ",
      "   c       c    ",
      "   c       c    ",
      "   c       c    ",
      "   c       cccc ",
      "                ",
      "                ",
      "            d   ",
      "                "
    ],
    [
      "                ",
      "        d  d    ",
      "                ",
      "              d ",
      "                ",
      "          d     ",
      "                ",
      "             d  ",
      "   c       c    ",
      "   c       c    ",
      "   c       c    ",
      "   c       cccc ",
      "                ",
      "                ",
      "            d   ",
      "                "
    ],
    [
      "                ",
      "        d  d    ",
      "                ",
      "              d ",
      "                ",
      "          d     ",
      "                ",
      "             d  ",
      "   c       c    ",
      "   c       c    ",
      "   c       c    ",
      "   c       cccc ",
      "                ",
      "                ",
      "            g   ",
      " d              "
    ]
  ]
}