{
  "name": "multi_courtyardofficetower_8_floor2",
  "refpalette": "deceasedcraft:multi_courtyardofficetower_8/multi_courtyardofficetower_8_floor2_palette",
  "xsize": 16,
  "zsize": 16,
  "slices": [
    [
      "                ",
      "                ",
      "                ",
      "                ",
      "                ",
      "                ",
      "                ",
      "                ",
      "   a       a    ",
      "   a       a    ",
      "   a   b   a    ",
      "ccdadcccccdaaaa ",
      "eeeeeeeeeeed    ",
      "fffghhhhhhec    ",
      "fffghhhhhhec    ",
      "ffffghhhhhecb   "
    ],
    [
      "                ",
      "                ",
      "                ",
      "                ",
      "                ",
      "                ",
      "                ",
      "                ",
      "   a       a    ",
      "   a       a    ",
      "   a   b   a    ",
      "ccdadcccccdaaaa ",
      "   i       d    ",
      "      j    c    ",
      "     k  k  c    ",
      "      l    cb   "
    ],
    [
      "                ",
      "                ",
      "                ",
      "                ",
      "                ",
      "                ",
      "                ",
      "                ",
      "   a       a    ",
      "   a       a    ",
      "   a   b   a    ",
      "ccdadcccccdaaaa ",
      "   m       d    ",
      "           c    ",
      "           c    ",
      "           cb   "
    ],
    [
      "                ",
      "                ",
      "                ",
      "                ",
      "                ",
      "                ",
      "                ",
      "                ",
      "   a       a    ",
      "   a       a    ",
      "   a   b   a    ",
      "ccdadcccccdaaaa ",
      "   n       d    ",
      "           c    ",
      "           c    ",
      "           cb   "
    ],
    [
      "                ",
      "                ",
      "                ",
      "                ",
      "                ",
      "                ",
      "                ",
      "                ",
      "   a       a    ",
      "   a       a    ",
      "   a   b   a    ",
      "ccdadcccccdaaaa ",
      "           d    ",
      "           c    ",
      "           c    ",
      "           cb   "
    ],
    [
      "                ",
      "                ",
      "                ",
      "                ",
      "                ",
      "                ",
      "                ",
      "                ",
      "   a       a    ",
      "   a       a    ",
      "   a   b   a    ",
      "ccdadcccccdaaaa ",
      "           d    ",
      "           c    ",
      "           c    ",
      "           cb   "
    ]
  ]
}