{
  "name": "multi_courtyardofficetower_8_floor18",
  "refpalette": "deceasedcraft:multi_courtyardofficetower_8/multi_courtyardofficetower_8_floor18_palette",
  "xsize": 16,
  "zsize": 16,
  "slices": [
    [
      "                ",
      "                ",
      "                ",
      "                ",
      "                ",
      "                ",
      "                ",
      "                ",
      "   a       a    ",
      "   a       a    ",
      "   a   b   a    ",
      "cccacccccccaaaa ",
      "dddceeeeeeec    ",
      "dddceeeeeeec    ",
      "dddceeeeeeec    ",
      "dddceeeeeeecb   "
    ],
    [
      "                ",
      "                ",
      "                ",
      "                ",
      "                ",
      "                ",
      "                ",
      "                ",
      "   a       a    ",
      "   a       a    ",
      "   a   b   a    ",
      "ffgagfffffgaaaa ",
      "   h   ijklg    ",
      "   m      nf    ",
      "   opqq   rf    ",
      "   o  st  ufb   "
    ],
    [
      "                ",
      "                ",
      "                ",
      "                ",
      "                ",
      "                ",
      "                ",
      "                ",
      "   a       a    ",
      "   a       a    ",
      "   a   b   a    ",
      "ffgagfffffgaaaa ",
      "   w      xg    ",
      "   y       f    ",
      "   oAqq    f    ",
      "   o   t   fb   "
    ],
    [
      "                ",
      "                ",
      "                ",
      "                ",
      "                ",
      "                ",
      "                ",
      "                ",
      "   a       a    ",
      "   a       a    ",
      "   a   b   a    ",
      "ffgagfffffgaaaa ",
      "   B       g    ",
      "   C       f    ",
      "   oqqq    f    ",
      "   o   t   fb   "
    ],
    [
      "                ",
      "                ",
      "                ",
      "                ",
      "                ",
      "                ",
      "                ",
      "                ",
      "   a       a    ",
      "   a       a    ",
      "   a   b   a    ",
      "ffgagfffffgaaaa ",
      "   o       g    ",
      "   o       f    ",
      "   oqqq    f    ",
      "   o   t   fb   "
    ],
    [
      "                ",
      "                ",
      "                ",
      "                ",
      "                ",
      "                ",
      "                ",
      "                ",
      "   a       a    ",
      "   a       a    ",
      "   a   b   a    ",
      "ffgagfffffgaaaa ",
      "   oDDDDDDEg    ",
      "   oDDDDDDDf    ",
      "   oDDDDDDDf    ",
      "   oDDDDDDDfb   "
    ]
  ]
}