{
  "name": "multi_courtyardofficetower_8_floor13",
  "refpalette": "deceasedcraft:multi_courtyardofficetower_8/multi_courtyardofficetower_8_floor13_palette",
  "xsize": 16,
  "zsize": 16,
  "slices": [
    [
      "                ",
      "                ",
      "                ",
      "                ",
      "                ",
      "                ",
      "                ",
      "                ",
      "   a       a    ",
      "   a       a    ",
      "   a   b   a    ",
      "ccdadcccccdaaaa ",
      "eeeeeeeeeeed    ",
      "fffeggggggec    ",
      "fffeggggggec    ",
      "fffeggggggecb   "
    ],
    [
      "                ",
      "                ",
      "                ",
      "                ",
      "                ",
      "                ",
      "                ",
      "                ",
      "   a       a    ",
      "   a       a    ",
      "   a   b   a    ",
      "ccdadcccccdaaaa ",
      "   h   ijkld    ",
      "   m      nc    ",
      "   opqq   rc    ",
      "   o  st  ucb   "
    ],
    [
      "                ",
      "                ",
      "                ",
      "                ",
      "                ",
      "                ",
      "                ",
      "                ",
      "   a       a    ",
      "   a       a    ",
      "   a   b   a    ",
      "ccdadcccccdaaaa ",
      "   w      xd    ",
      "   y       c    ",
      "   oAqq    c    ",
      "   o   t   cb   "
    ],
    [
      "                ",
      "                ",
      "                ",
      "                ",
      "                ",
      "                ",
      "                ",
      "                ",
      "   a       a    ",
      "   a       a    ",
      "   a   b   a    ",
      "ccdadcccccdaaaa ",
      "   B       d    ",
      "   C       c    ",
      "   oqqq    c    ",
      "   o   t   cb   "
    ],
    [
      "                ",
      "                ",
      "                ",
      "                ",
      "                ",
      "                ",
      "                ",
      "                ",
      "   a       a    ",
      "   a       a    ",
      "   a   b   a    ",
      "ccdadcccccdaaaa ",
      "   o       d    ",
      "   o       c    ",
      "   oqqq    c    ",
      "   o   t   cb   "
    ],
    [
      "                ",
      "                ",
      "                ",
      "                ",
      "                ",
      "                ",
      "                ",
      "                ",
      "   a       a    ",
      "   a       a    ",
      "   a   b   a    ",
      "ccdadcccccdaaaa ",
      "   oDDDDDDEd    ",
      "   oDDDDDDDc    ",
      "   oDDDDDDDc    ",
      "   oDDDFDDDcb   "
    ]
  ]
}