{
  "name": "multi_courtyardofficetower_8_floor8",
  "refpalette": "deceasedcraft:multi_courtyardofficetower_8/multi_courtyardofficetower_8_floor8_palette",
  "xsize": 16,
  "zsize": 16,
  "slices": [
    [
      "                ",
      "                ",
      "                ",
      "                ",
      "                ",
      "                ",
      "                ",
      "                ",
      "   a       a    ",
      "   a       a    ",
      "   a   b   a    ",
      "cccacccccccaaaa ",
      "dddefffffffc    ",
      "dddefffffffc    ",
      "dddefffffffc    ",
      "ddddeffffffcb   "
    ],
    [
      "                ",
      "                ",
      "                ",
      "                ",
      "                ",
      "                ",
      "                ",
      "                ",
      "   a       a    ",
      "   a       a    ",
      "   a   b   a    ",
      "gghahggggghaaaa ",
      "       i   h    ",
      "     j   k g    ",
      "      k    g    ",
      "        j igb   "
    ],
    [
      "                ",
      "                ",
      "                ",
      "                ",
      "                ",
      "                ",
      "                ",
      "                ",
      "   a       a    ",
      "   a       a    ",
      "   a   b   a    ",
      "gghahggggghaaaa ",
      "           h    ",
      "           g    ",
      "           g    ",
      "           gb   "
    ],
    [
      "                ",
      "                ",
      "                ",
      "                ",
      "                ",
      "                ",
      "                ",
      "                ",
      "   a       a    ",
      "   a       a    ",
      "   a   b   a    ",
      "gghahggggghaaaa ",
      "           h    ",
      "           g    ",
      "           g    ",
      "           gb   "
    ],
    [
      "                ",
      "                ",
      "                ",
      "                ",
      "                ",
      "                ",
      "                ",
      "                ",
      "   a       a    ",
      "   a       a    ",
      "   a   b   a    ",
      "gghahggggghaaaa ",
      "           h    ",
      "           g    ",
      "           g    ",
      "           gb   "
    ],
    [
      "                ",
      "                ",
      "                ",
      "                ",
      "                ",
      "                ",
      "                ",
      "                ",
      "   a       a    ",
      "   a       a    ",
      "   a   b   a    ",
      "gghahggggghaaaa ",
      "           h    ",
      "           g    ",
      "           g    ",
      "           gb   "
    ]
  ]
}