{
  "name": "multi_courtyardofficetower_8_floor15",
  "refpalette": "deceasedcraft:multi_courtyardofficetower_8/multi_courtyardofficetower_8_floor15_palette",
  "xsize": 16,
  "zsize": 16,
  "slices": [
    [
      "                ",
      "                ",
      "                ",
      "                ",
      "                ",
      "                ",
      "                ",
      "                ",
      "   a       a    ",
      "   a       a    ",
      "   a   b   a    ",
      "cccacccccccaaaa ",
      "dddceeeeeeec    ",
      "dddceeeeeeec    ",
      "dddceeeeeeec    ",
      "dddceeeeeeecb   "
    ],
    [
      "                ",
      "                ",
      "                ",
      "                ",
      "                ",
      "                ",
      "                ",
      "                ",
      "   a       a    ",
      "   a       a    ",
      "   a   b   a    ",
      "ffgagfffffgaaaa ",
      "   h   ijklg    ",
      "   m      nf    ",
      "   opqq   rf    ",
      "   o  sd  tfb   "
    ],
    [
      "                ",
      "                ",
      "                ",
      "                ",
      "                ",
      "                ",
      "                ",
      "                ",
      "   a       a    ",
      "   a       a    ",
      "   a   b   a    ",
      "ffgagfffffgaaaa ",
      "   u      wg    ",
      "   x       f    ",
      "   oyqq    f    ",
      "   o   d   fb   "
    ],
    [
      "                ",
      "                ",
      "                ",
      "                ",
      "                ",
      "                ",
      "                ",
      "                ",
      "   a       a    ",
      "   a       a    ",
      "   a   b   a    ",
      "ffgagfffffgaaaa ",
      "   A       g    ",
      "   B       f    ",
      "   oqqq    f    ",
      "   o   d   fb   "
    ],
    [
      "                ",
      "                ",
      "                ",
      "                ",
      "                ",
      "                ",
      "                ",
      "                ",
      "   a       a    ",
      "   a       a    ",
      "   a   b   a    ",
      "ffgagfffffgaaaa ",
      "   o       g    ",
      "   o       f    ",
      "   oqqq    f    ",
      "   o   d   fb   "
    ],
    [
      "                ",
      "                ",
      "                ",
      "                ",
      "                ",
      "                ",
      "                ",
      "                ",
      "   a       a    ",
      "   a       a    ",
      "   a   b   a    ",
      "ffgagfffffgaaaa ",
      "CCCaDDDDDDDg    ",
      "CECaDDDDDDDf    ",
      "CCCaDDDDDDDf    ",
      "CCCaDDDDDDDfb   "
    ]
  ]
}