{
  "name": "multi_courtyardofficetower_8_floor7",
  "refpalette": "deceasedcraft:multi_courtyardofficetower_8/multi_courtyardofficetower_8_floor7_palette",
  "xsize": 16,
  "zsize": 16,
  "slices": [
    [
      "                ",
      "                ",
      "                ",
      "                ",
      "                ",
      "                ",
      "                ",
      "                ",
      "   a       a    ",
      "   a       a    ",
      "   a   b   a    ",
      "cccacccccccaaaa ",
      "dddceeeeeeec    ",
      "dddceeeeeeec    ",
      "dddceeeeeeec    ",
      "dddceeeeeeecb   "
    ],
    [
      "                ",
      "                ",
      "                ",
      "                ",
      "                ",
      "                ",
      "                ",
      "                ",
      "   a       a    ",
      "   a       a    ",
      "   a   b   a    ",
      "ffgagfffffgaaaa ",
      "   h   ijk!g    ",
      "   l      mf    ",
      "   nopp   qf    ",
      "   n  rd  sfb   "
    ],
    [
      "                ",
      "                ",
      "                ",
      "                ",
      "                ",
      "                ",
      "                ",
      "                ",
      "   a       a    ",
      "   a       a    ",
      "   a   b   a    ",
      "ffgagfffffgaaaa ",
      "   t      ug    ",
      "   w       f    ",
      "   nxpp    f    ",
      "   n   d   fb   "
    ],
    [
      "                ",
      "                ",
      "                ",
      "                ",
      "                ",
      "                ",
      "                ",
      "                ",
      "   a       a    ",
      "   a       a    ",
      "   a   b   a    ",
      "ffgagfffffgaaaa ",
      "   y       g    ",
      "   A       f    ",
      "   nppp    f    ",
      "   n   d   fb   "
    ],
    [
      "                ",
      "                ",
      "                ",
      "                ",
      "                ",
      "                ",
      "                ",
      "                ",
      "   a       a    ",
      "   a       a    ",
      "   a   b   a    ",
      "ffgagfffffgaaaa ",
      "   n       g    ",
      "   n       f    ",
      "   nppp    f    ",
      "   n   d   fb   "
    ],
    [
      "                ",
      "                ",
      "                ",
      "                ",
      "                ",
      "                ",
      "                ",
      "                ",
      "   a       a    ",
      "   a       a    ",
      "   a   b   a    ",
      "ffgagfffffgaaaa ",
      "BBBaCCCCCCCg    ",
      "BDBaCCCCCCCf    ",
      "BBBaCCCCCCCf    ",
      "BBBaCCCCCCCfb   "
    ]
  ]
}