{
  "name": "multi_courtyardofficetower_8_floor19",
  "refpalette": "deceasedcraft:multi_courtyardofficetower_8/multi_courtyardofficetower_8_floor19_palette",
  "xsize": 16,
  "zsize": 16,
  "slices": [
    [
      "                ",
      "                ",
      "                ",
      "                ",
      "                ",
      "                ",
      "                ",
      "                ",
      "   a       a    ",
      "   a       a    ",
      "   a   b   a    ",
      "ccdadcccccdaaaa ",
      "   effffff d    ",
      "   eggggggfc    ",
      "   eggggggfc    ",
      "   eggghggfcb   "
    ],
    [
      "                ",
      "                ",
      "                ",
      "                ",
      "                ",
      "                ",
      "                ",
      "                ",
      "   a       a    ",
      "   a       a    ",
      "   a   b   a    ",
      "ccdadcccccdaaaa ",
      "   e       d    ",
      "   e       c    ",
      "   e  iii  c    ",
      "   e  ihi  cb   "
    ],
    [
      "                ",
      "                ",
      "                ",
      "                ",
      "                ",
      "                ",
      "                ",
      "                ",
      "   a       a    ",
      "   a       a    ",
      "   a   b   a    ",
      "ccdadcccccdaaaa ",
      "   e       d    ",
      "   e       c    ",
      "   e  jkj  c    ",
      "   e  kjk  cb   "
    ],
    [
      "                ",
      "                ",
      "                ",
      "                ",
      "                ",
      "                ",
      "                ",
      "                ",
      "   a       a    ",
      "   a       a    ",
      "   a   b   a    ",
      "ccdadcccccdaaaa ",
      "   e       d    ",
      "   e       c    ",
      "   e  lml  c    ",
      "   e  mlm  cb   "
    ],
    [
      "                ",
      "                ",
      "                ",
      "                ",
      "                ",
      "                ",
      "                ",
      "                ",
      "   a       a    ",
      "   a       a    ",
      "   a   b   a    ",
      "ccdadcccccdaaaa ",
      "   e       d    ",
      "   e       c    ",
      "   e  non  c    ",
      "   e  ono  cb   "
    ],
    [
      "                ",
      "                ",
      "                ",
      "                ",
      "                ",
      "                ",
      "                ",
      "                ",
      "   a       a    ",
      "   a       a    ",
      "   a   b   a    ",
      "ccdadcccccdaaaa ",
      "pppapppppppd    ",
      "pqpapppppppc    ",
      "pppapppppppc    ",
      "pppapppppppcb   "
    ]
  ]
}