{
  "name": "multi_courtyardofficetower_8_floor17",
  "refpalette": "deceasedcraft:multi_courtyardofficetower_8/multi_courtyardofficetower_8_floor17_palette",
  "xsize": 16,
  "zsize": 16,
  "slices": [
    [
      "                ",
      "                ",
      "                ",
      "                ",
      "                ",
      "                ",
      "                ",
      "                ",
      "   a       a    ",
      "   a       a    ",
      "   a   b   a    ",
      "cccacccccccaaaa ",
      "dddceeeeeeec    ",
      "dddceeeeeeec    ",
      "dddceeeeeeec    ",
      "dddceeeeeeecb   "
    ],
    [
      "                ",
      "                ",
      "                ",
      "                ",
      "                ",
      "                ",
      "                ",
      "                ",
      "   a       a    ",
      "   a       a    ",
      "   a   b   a    ",
      "ffgagfffffgaaaa ",
      "   h   ijklg    ",
      "m  n      of    ",
      "   pqrr   sf    ",
      "mt puwxd  yfb   "
    ],
    [
      "                ",
      "                ",
      "                ",
      "                ",
      "                ",
      "                ",
      "                ",
      "                ",
      "   a       a    ",
      "   a       a    ",
      "   a   b   a    ",
      "ffgagfffffgaaaa ",
      "   A      Bg    ",
      "   C       f    ",
      "   pDrr    f    ",
      "   p   d   fb   "
    ],
    [
      "                ",
      "                ",
      "                ",
      "                ",
      "                ",
      "                ",
      "                ",
      "                ",
      "   a       a    ",
      "   a       a    ",
      "   a   b   a    ",
      "ffgagfffffgaaaa ",
      "   E       g    ",
      "   F       f    ",
      "   prrr    f    ",
      "   p   d   fb   "
    ],
    [
      "                ",
      "                ",
      "                ",
      "                ",
      "                ",
      "                ",
      "                ",
      "                ",
      "   a       a    ",
      "   a       a    ",
      "   a   b   a    ",
      "ffgagfffffgaaaa ",
      "   p       g    ",
      "   p       f    ",
      "   prrr    f    ",
      "   p   d   fb   "
    ],
    [
      "                ",
      "                ",
      "                ",
      "                ",
      "                ",
      "                ",
      "                ",
      "                ",
      "   a       a    ",
      "   a       a    ",
      "   a   b   a    ",
      "ffgagfffffgaaaa ",
      "IIIaJJJJJJJg    ",
      "IKIaJJJJJJJf    ",
      "IIIaJJJJJJJf    ",
      "IIIaJJJJJJJfb   "
    ]
  ]
}