{
  "name": "multi_courtyardofficetower_8_floor9",
  "refpalette": "deceasedcraft:multi_courtyardofficetower_8/multi_courtyardofficetower_8_floor9_palette",
  "xsize": 16,
  "zsize": 16,
  "slices": [
    [
      "                ",
      "                ",
      "                ",
      "                ",
      "                ",
      "                ",
      "                ",
      "                ",
      "   a       a    ",
      "   a       a    ",
      "   a   b   a    ",
      "ccdadcccccdaaaa ",
      "           d    ",
      "           c    ",
      "           c    ",
      "           cb   "
    ],
    [
      "                ",
      "                ",
      "                ",
      "                ",
      "                ",
      "                ",
      "                ",
      "                ",
      "   a       a    ",
      "   a       a    ",
      "   a   b   a    ",
      "ccdadcccccdaaaa ",
      "           d    ",
      "           c    ",
      "           c    ",
      "           cb   "
    ],
    [
      "                ",
      "                ",
      "                ",
      "                ",
      "                ",
      "                ",
      "                ",
      "                ",
      "   a       a    ",
      "   a       a    ",
      "   a   b   a    ",
      "ccdadcccccdaaaa ",
      "           d    ",
      "           c    ",
      "           c    ",
      "           cb   "
    ],
    [
      "                ",
      "                ",
      "                ",
      "                ",
      "                ",
      "                ",
      "                ",
      "                ",
      "   a       a    ",
      "   a       a    ",
      "   a   b   a    ",
      "ccdadcccccdaaaa ",
      "           d    ",
      "           c    ",
      "           c    ",
      "           cb   "
    ],
    [
      "                ",
      "                ",
      "                ",
      "                ",
      "                ",
      "                ",
      "                ",
      "                ",
      "   a       a    ",
      "   a       a    ",
      "   a   b   a    ",
      "ccdadcccccdaaaa ",
      "           d    ",
      "           c    ",
      "           c    ",
      "           cb   "
    ],
    [
      "                ",
      "                ",
      "                ",
      "                ",
      "                ",
      "                ",
      "                ",
      "                ",
      "   a       a    ",
      "   a       a    ",
      "   a   b   a    ",
      "ccdadcccccdaaaa ",
      "eeeaeeeeeeed    ",
      "efeaefeeefec    ",
      "eeeaeeeeeeec    ",
      "eeeaeeeeeeecb   "
    ]
  ]
}