{
  "name": "multi_filmworkstower_16_base1",
  "refpalette": "deceasedcraft:multi_filmworkstower_16/multi_filmworkstower_16_base1_palette",
  "xsize": 16,
  "zsize": 16,
  "slices": [
    [
      "vvvvvvvvvvvvvvvv",
      "aaaaaaaaaaaaaaaa",
      "bbbbbbbbbbbbbbbb",
      "cdccccccccccccce",
      "ccccccccccccccce",
      "ccccccccccccccce",
      "ccccccccccccccce",
      "ccccfccfccfccfce",
      "eeeeeeeeeeeeeeee",
      "            gggg",
      "                ",
      "                ",
      "                ",
      "                ",
      "     h          ",
      "i   jh          "
    ],
    [
      "vvvvvvvvvvvvvvvv",
      "aaaaaaaaaaaaaaaa",
      "bbbbbbbbbbbbbbbb",
      "kd             e",
      "k              l",
      "               m",
      "               e",
      "    f  f  f  f e",
      "eeeeeeeeeeeeeeee",
      "            nnnn",
      "                ",
      "                ",
      "                ",
      "                ",
      "     h          ",
      "io pjh          "
    ],
    [
      "vvvvvvvvvvvvvvvv",
      "aaaaaaaaaaaaaaaa",
      "bbbbbbbbbbbbbbbb",
      "qr             e",
      "s              t",
      "               u",
      "               e",
      "    f  f  f  f e",
      "eeeeeeeeeeeeeeee",
      "            wwww",
      "                ",
      "                ",
      "                ",
      "                ",
      "     h          ",
      "iixxjh          "
    ],
    [
      "vvvvvvvvvvvvvvvv",
      "aaaaaaaaaaaaaaaa",
      "bbbbbbbbbbbbbbbb",
      "y              e",
      "A              e",
      "               e",
      "               e",
      "ffffffffffffffff",
      "eeeeeeeeeeeeeeee",
      "                ",
      "                ",
      "                ",
      "                ",
      "                ",
      "                ",
      "BioCjD          "
    ],
    [
      "vvvvvvvvvvvvvvvv",
      "aaaaaaaaaaaaaaaa",
      "bbbbbbbbbbbbbbbb",
      "EEEEEEEEEEEEEEEe",
      "EEEEEEEEEEEEEEEe",
      "EEEEEEEEEEEEEEEe",
      "EEEEEEEEEEEEEEEe",
      "EEEEEEEEEEEEEEEe",
      "eeeeeeeeeeeeeeee",
      "FFFFFFFFFFFFFFFF",
      "FFFFFFFFFFFFFFFF",
      "FFFFFFFFFFFFFFFF",
      "FFFFFFFFFFFFFFFF",
      "FFFFFFFFFFFFFFFF",
      "FFFFFFFFFFFFFFFF",
      "FiiFIFFFFFFFFFFF"
    ],
    [
      "vvvvvvvvvvvvvvvv",
      "aaaaaaaaaaaaaaaa",
      "bbbbbbbbbbbbbbbb",
      "iiiiiiiiiiiiiiii",
      "iiiiiiiiiiiiiiii",
      "iiiiiiiiiiiiiiii",
      "iiiiiiiiiiiiiiii",
      "iiiiiiiiiiiiiiii",
      "iiiiiiiiiiiiiiii",
      "iiiiiiiiiiiiiiii",
      "iiiiiiiiiiiiiiii",
      "iiiiiiiiiiiiiiii",
      "iiiiiiiiiiiiiiii",
      "iiiiiiiiiiiiiiii",
      "iiiiiiiiiiiiiiii",
      "iiiiiiiiiiiiiiii"
    ]
  ]
}