{
  "name": "multi_filmworkstower_16_base2",
  "refpalette": "deceasedcraft:multi_filmworkstower_16/multi_filmworkstower_16_base2_palette",
  "xsize": 16,
  "zsize": 16,
  "slices": [
    [
      "vvvvvvvvvvvvvvvv",
      "aaaaaaaaaaaaaaaa",
      "bbbbbbbbbbbbbbbb",
      "cccccccccccccccd",
      "cccccccccccccccd",
      "cccccccccccccccd",
      "cccccccccccccccd",
      "cccccccccccccccd",
      "dddddddddddddddd",
      "dddddddddddddddd",
      "dddddddddddddddd",
      "dddddddddddddddd",
      "dddddddddddddddd",
      "dddddddddddddddd",
      "dddddeeeeeeeeeee",
      "ddddde f        "
    ],
    [
      "vvvvvvvvvvvvvvvv",
      "aaaaaaaaaaaaaaaa",
      "bbbbbbbbbbbbbbbb",
      "ghi            j",
      "               j",
      "    jkjjkjjkjjkj",
      "   jl jl jl jl j",
      "   jm jm jm jm j",
      "nojjjjjjjjjjjjjj",
      "                ",
      "                ",
      "                ",
      "                ",
      "                ",
      "     ep pppppppp",
      "   qre          "
    ],
    [
      "vvvvvvvvvvvvvvvv",
      "aaaaaaaaaaaaaaaa",
      "bbbbbbbbbbbbbbbb",
      "ss t           j",
      "               j",
      "   ujwjjwjjwjjwj",
      "   j  j  j  j  j",
      "   j xj xj xj xj",
      "yAjjjjjjjjjjjjjj",
      "                ",
      "                ",
      "                ",
      "                ",
      "                ",
      "     e          ",
      "    re          "
    ],
    [
      "vvvvvvvvvvvvvvvv",
      "aaaaaaaaaaaaaaaa",
      "bbbbbbbbbbbbbbbb",
      "BBC            j",
      "               j",
      "    jDjjDjjDjjDj",
      "   j  j  j  j  j",
      "   j Ej Ej Ej Ej",
      "FIjjjjjjjjjjjjjj",
      "                ",
      "                ",
      "                ",
      "                ",
      "                ",
      "     e          ",
      "    re          "
    ],
    [
      "vvvvvvvvvvvvvvvv",
      "aaaaaaaaaaaaaaaa",
      "bbbbbbbbbbbbbbbb",
      "               j",
      "               j",
      "    jjjjjjjjjjjj",
      "   j  j  j  j  j",
      "   j  j  j  j  j",
      "jjjjjjjjjjjjjjjj",
      "                ",
      "                ",
      "                ",
      "                ",
      "                ",
      "     e          ",
      "   Jre          "
    ],
    [
      "vvvvvvvvvvvvvvvv",
      "aaaaaaaaaaaaaaaa",
      "bbbbbbbbbbbbbbbb",
      "KKKKKKKKKKKKKKKj",
      "KKKKKKKKKKKKKKKj",
      "KKKKKKKKKKKKKKKj",
      "KKKKKKKKKKKKKKKj",
      "KKKKLKKLKKLKKLKj",
      "jjjjjjjjjjjjjjjj",
      "                ",
      "                ",
      "                ",
      "                ",
      "                ",
      "     e          ",
      "M   re          "
    ]
  ]
}