{
  "name": "multi_filmworkstower_16_ground",
  "refpalette": "deceasedcraft:multi_filmworkstower_16/multi_filmworkstower_16_ground_palette",
  "xsize": 16,
  "zsize": 16,
  "slices": [
    [
      "aaaaaaaabbbbbbbb",
      "aaaaaaaabccccccc",
      "aaaaaaaabcHHHHHH",
      "aaaaaaaabcHHHHHH",
      "aaaaaaaabcHHHHHH",
      "aaaaaaaabcHHHHHH",
      "aaaaaaaabcHHHHHH",
      "aaaaaaaabcHHHHHH",
      "aaaaaaaabcHHHHHH",
      "aaaaaaaabcHHHHHH",
      "aaaaaaaabcHHHHHH",
      "aaaaaaaabcHHHHHH",
      "aaaaaaaabcHHHHHH",
      "aaaaaaaabcHHHHHH",
      "aaaaaaaabcHHHHHH",
      "aaaaaaaabcHHHHHH"
    ],
    [
      "d      deeeeeeee",
      "d      de       ",
      "d      de fgfgfg",
      "d      de      h",
      "d  i   de       ",
      "d      de jkjkjk",
      "d      de       ",
      "d      de       ",
      "d      de       ",
      "d      de       ",
      "d      de     fg",
      "d   i  de       ",
      "d      de       ",
      "d      de     jk",
      "d      de     fg",
      "d      de       "
    ],
    [
      "                ",
      "                ",
      "                ",
      "                ",
      "   l            ",
      "                ",
      "                ",
      "                ",
      "                ",
      "                ",
      "                ",
      "    l           ",
      "                ",
      "                ",
      "                ",
      "                "
    ],
    [
      "                ",
      "                ",
      "                ",
      "   d            ",
      "   d            ",
      "   m            ",
      "                ",
      "                ",
      "                ",
      "                ",
      "                ",
      "    d           ",
      "                ",
      "                ",
      "                ",
      "                "
    ],
    [
      "                ",
      "                ",
      "                ",
      "   d            ",
      "  ddd           ",
      "   d            ",
      "                ",
      "                ",
      "                ",
      "                ",
      "    d           ",
      "   ddm          ",
      "                ",
      "                ",
      "                ",
      "                "
    ],
    [
      "                ",
      "                ",
      "                ",
      "   m            ",
      "  mdd           ",
      "                ",
      "                ",
      "                ",
      "                ",
      "                ",
      "    d           ",
      "   mdd          ",
      "    d           ",
      "                ",
      "                ",
      "                "
    ]
  ]
}