{
  "name": "multi_cafe_2_ground",
  "refpalette": "deceasedcraft:multi_cafe_2/multi_cafe_2_ground_palette",
  "xsize": 16,
  "zsize": 16,
  "slices": [
    [
      "aaaaaaaaaaaaaaaa",
      "aaaaaaaaaaaaaaaa",
      "bbbbbbbbbbbbbbaa",
      "bbbbbbbbbbbbbbaa",
      "cccccbbbbcccbbaa",
      "dd============aa",
      "dd=eeeeeeeeeeefa",
      "dd=eeeeeeeeeeeaa",
      "dd=eeeeeeeeeeefa",
      "dd=eeeeeeggggeaa",
      "dd=eeeeeeggggeaa",
      "dd=eeeeeeggggeaa",
      "dd=eeeeeeggggeaa",
      "dd=eeeeeeeeeeefa",
      "dd=eeeeeeeeeeeaa",
      "dd=eeeeeeeeeeeaa"
    ],
    [
      "h ij k    ih ikk",
      "khkhl   khlm m  ",
      "              nk",
      "             on ",
      "pppppq  rppp onk",
      "  ssstuwtsss==nk",
      "x sy         ABk",
      "  sCD        Enk",
      "  sCF   IJKJLLB ",
      "x sC    M M MNn ",
      "  sCD   M M MNn ",
      "  sC    M M MNnk",
      "x sCD   MOMOMNn ",
      "  syF   IPPPLLBk",
      "QRR       S TNn ",
      "          S UNnk"
    ],
    [
      "                ",
      "                ",
      "              n ",
      "             on ",
      "     q  r    on ",
      "  ssstVWtsss==n ",
      "  sX         YB ",
      "  sZ         Y0 ",
      "  s 1   I2K2LLB ",
      "  s     M M MNn ",
      "  s3    M M MNn ",
      "  s     M M MNn ",
      "  s4    M M MNn ",
      "  s51   IPPPLLB ",
      " RR       6 7Nn ",
      "          8  Nn "
    ],
    [
      "                ",
      "                ",
      "              n ",
      "             on ",
      "     9##$    on ",
      "  sssttttsss==n ",
      "  s          %B ",
      "  s          ^0 ",
      "  s 1   IKKKLLB ",
      "  s     M M MNn ",
      "  s     M M &s  ",
      "  s     M M &s  ",
      "  s     M M MNn ",
      "  s 1   IPPPLLB ",
      " **         (Nn ",
      " ##         )s  "
    ],
    [
      "                ",
      "                ",
      "              n ",
      "             on ",
      "             on ",
      "  ssssssssss==n ",
      "  s          +B ",
      "  s          +- ",
      "  s 1   I[[[LLB ",
      "  s     ]ttttN- ",
      "  s     ]ttttN- ",
      "  s     ]ttttN- ",
      "  s     ]tttNN- ",
      "  s 1   I{{{LLB ",
      "  s          N- ",
      "  s         }N- "
    ],
    [
      "                ",
      "                ",
      "              n ",
      "             on ",
      "             on ",
      "  ssssssssss==n ",
      "  s          NB ",
      "  s          Nn ",
      "  s 1 | IKKKLLB ",
      "  s     M ; :Nn ",
      "  s     M'; :Nn ",
      "  s     M<;  Nn ",
      "  s     M  >,Nn ",
      "  s 1 | IPPPLLB ",
      "  s          Nn ",
      "  s          Nn "
    ]
  ]
}