{
  "name": "multi_cafe_2_floor1",
  "refpalette": "deceasedcraft:multi_cafe_2/multi_cafe_2_floor1_palette",
  "xsize": 16,
  "zsize": 16,
  "slices": [
    [
      "                ",
      "                ",
      "              a ",
      "             ba ",
      " ccccccccccccba ",
      " cdddddddddd==a ",
      " cd        efgh ",
      " cd        ifga ",
      " cd jkj l   mmh ",
      " cd        enga ",
      " cd        inga ",
      " cd        eoga ",
      " cd        ipga ",
      " cd jkj l   mmh ",
      " cd        efga ",
      " cd        ifga "
    ],
    [
      "                ",
      "                ",
      "              a ",
      "             ba ",
      "             ba ",
      "  ============a ",
      "  =     cllllgh ",
      " q=    rcllllga ",
      " s=tttttllllmmh ",
      " q=     cllllga ",
      " u=     cllllga ",
      " q=     cllllga ",
      " w=     cllllga ",
      " q=tttttllllmmh ",
      " x=     cllllga ",
      "  =     cllllga "
    ],
    [
      "                ",
      "                ",
      "              a ",
      "           yyAa ",
      "           yyAa ",
      "  ============a ",
      "  =     mr BBBh ",
      " q=     m   rBa ",
      " w=   r!l   mmh ",
      " q=    rm  CrBa ",
      " u=     m   DBa ",
      " q=     m   EBa ",
      " w=     m  FCBa ",
      " q=     l  rmmh ",
      " w=     m   IBa ",
      " q=     m  CCBa "
    ],
    [
      "                ",
      "                ",
      "          JJJJa ",
      "   yyyyyyAKLLLa ",
      "   yyyyyyAKJJJM ",
      "  ========JJJJM ",
      "  =NNNNNmr    h ",
      "  =NNNNNmrJJJJM ",
      "  =     l   mmh ",
      "  =NNNNNm JJJJM ",
      "  =NNNNNm JJJJM ",
      "  =NNNNNm JJJJM ",
      "  =NNNNNm JJJJM ",
      "  =     l   mmh ",
      "  =NNNNNm JJJJM ",
      "  =NNNNNm JJJJM "
    ],
    [
      "                ",
      "                ",
      "  JJJJOOOO      ",
      "yAKLLLLOOOO     ",
      "yAKJJJLOOOO     ",
      "yAJJJJOOOO      ",
      "yAhhhhhhhhPPPPP ",
      "yAhJJJOOOO      ",
      "yAhQQQQQhhPPPPP ",
      "yAhJJJOOOO      ",
      "yAhJJJLOOOO     ",
      "yAhJJJLOOOO     ",
      "yAhJJJOOOO      ",
      "yAhQQQQQhhPPPPP ",
      "yAhJJJOOOO      ",
      "yAhJJJLOOOO     "
    ],
    [
      "                ",
      "                ",
      "OO              ",
      "OOO             ",
      "OOO             ",
      "OO              ",
      "OOPPPP          ",
      "OOP             ",
      "OOP     ~       ",
      "OOP             ",
      "OOP             ",
      "OOP             ",
      "OOP             ",
      "OOP             ",
      "OOP             ",
      "OOP             "
    ]
  ]
}