{
  "name": "front_highrise_residential_body_2",
  "refpalette": "deceasedcraft:fronts/front_highrise_residential_body_2_palette",
  "xsize": 16,
  "zsize": 16,
  "slices": [
    [
      " aaaaa          ",
      "   a a          ",
      "   aaa          ",
      "a    a          ",
      "ab  aa          ",
      "acd aa          ",
      "aef aa          ",
      "fd  aa          ",
      "a g aa          ",
      "a   aa          ",
      " f  aa          ",
      " db  a          ",
      "ahib a          ",
      " djaaa          ",
      "  faaa          ",
      " b aa           "
    ],
    [
      "aaaaaa          ",
      "aa aaa          ",
      "a aaaa          ",
      "aaaaaa          ",
      "a a aa          ",
      "aa aaa          ",
      "aa aaa          ",
      "aaaaaa          ",
      "aaaaaa          ",
      "aa aaa          ",
      "aa aaa          ",
      "a   aa          ",
      "aaaaaa          ",
      "aaaaaa          ",
      "aa aaa          ",
      "aaaaaa          "
    ],
    [
      "aaaaaa          ",
      "aa aaa          ",
      "aaaaaa          ",
      "aaaaaa          ",
      "a   aa          ",
      "a aaaa          ",
      "a aaaa          ",
      "a aaaa          ",
      "a aaaa          ",
      "a aaaa          ",
      "a aaaa          ",
      "a   aa          ",
      "aaaaaa          ",
      "aaaaaa          ",
      "aa aaa          ",
      "aaaaaa          "
    ]
  ]
}