{
  "name": "front_highrise_residential_1",
  "refpalette": "deceasedcraft:fronts/front_highrise_residential_1_palette",
  "xsize": 16,
  "zsize": 16,
  "slices": [
    [
      " aaaaa          ",
      "aa a a          ",
      "aabaaa          ",
      "a    a          ",
      "ab caa          ",
      "a b aa          ",
      "a   aa          ",
      "a   aa          ",
      "a   aa          ",
      "a   aa          ",
      "b   aa          ",
      "   c a          ",
      "a b  a          ",
      "aaaaaa          ",
      "aa aaa          ",
      " aaaa           "
    ],
    [
      "aaaaaa          ",
      "aa aaa          ",
      "aaaaaa          ",
      "aaaaaa          ",
      "a adaa          ",
      "aa aaa          ",
      "aa aaa          ",
      "aaaaaa          ",
      "aaaaaa          ",
      "aa aaa          ",
      "aa aaa          ",
      "a  daa          ",
      "aaaaaa          ",
      "aaaaaa          ",
      "aa aaa          ",
      "aaaaaa          "
    ],
    [
      "aaaaaa          ",
      "aa aaa          ",
      "aaaaaa          ",
      "aaaaaa          ",
      "a  eaa          ",
      "a aaaa          ",
      "a aaaa          ",
      "a aaaa          ",
      "a aaaa          ",
      "a aaaa          ",
      "a aaaa          ",
      "a  eaa          ",
      "aaaaaa          ",
      "aaaaaa          ",
      "aa aaa          ",
      "aaaaaa          "
    ],
    [
      "aaaaaa          ",
      "aa aaa          ",
      "aaaaaa          ",
      "a  aaa          ",
      "a   aa          ",
      "a a aa          ",
      "a a aa          ",
      "a a aa          ",
      "a a aa          ",
      "a a aa          ",
      "a a aa          ",
      "a   aa          ",
      "a  aaa          ",
      "aaaaaa          ",
      "aa aaa          ",
      "aaaaaa          "
    ],
    [
      "aaaaaa          ",
      "aa aaa          ",
      "aaaaaa          ",
      "a    a          ",
      "aa   a          ",
      "aa   a          ",
      "aa   a          ",
      "aa   a          ",
      "aa   a          ",
      "aa   a          ",
      "aa   a          ",
      "aa   a          ",
      "aa   a          ",
      "aaaaaa          ",
      "aa aaa          ",
      "aaaaaa          "
    ],
    [
      "aaaaaa          ",
      "aaaaaa          ",
      "aaaaaa          ",
      "aaaaaa          ",
      "aaaaaa          ",
      "aaaaaa          ",
      "aaaaaa          ",
      "aaaaaa          ",
      "aaaaaa          ",
      "aaaaaa          ",
      "aaaaaa          ",
      "aaaaaa          ",
      "aaaaaa          ",
      "aaaaaa          ",
      "aaaaaa          ",
      "aaaaaa          "
    ]
  ]
}