{
  "name": "front_highrise_residential_body_1",
  "refpalette": "deceasedcraft:fronts/front_highrise_residential_body_1_palette",
  "xsize": 16,
  "zsize": 16,
  "slices": [
    [
      "                ",
      " ab             ",
      " c ddd          ",
      " e   d          ",
      "d   dd          ",
      "af  dd          ",
      "d   dd          ",
      "d   dd          ",
      "d   dd          ",
      "d   dd          ",
      " g  dd          ",
      " hi  d          ",
      "daj  d          ",
      "   ddd          ",
      "   ddd          ",
      " k dd           "
    ],
    [
      "                ",
      "                ",
      "dddddd          ",
      "dddddd          ",
      "d d dd          ",
      "dd ddd          ",
      "dd ddd          ",
      "dddddd          ",
      "dddddd          ",
      "dd ddd          ",
      "dd ddd          ",
      "d   dd          ",
      "dddddd          ",
      "dddddd          ",
      "dd ddd          ",
      "dddddd          "
    ],
    [
      "                ",
      "                ",
      "dddddd          ",
      "dddddd          ",
      "d   dd          ",
      "d dddd          ",
      "d dddd          ",
      "d dddd          ",
      "d dddd          ",
      "d dddd          ",
      "d dddd          ",
      "d   dd          ",
      "dddddd          ",
      "dddddd          ",
      "dd ddd          ",
      "dddddd          "
    ]
  ]
}