{
  "name": "building_hotela_floor4_180",
  "refpalette": "deceasedcraft:building_hotela/building_hotela_floor4_palette_180",
  "xsize": 16,
  "zsize": 16,
  "slices": [
    [
      "                ",
      "              c ",
      "    ffffffffffj ",
      "    feeeeeeeeea ",
      "    feeeeeeeeea ",
      "    feeeeeeeeea ",
      "    f====eeeeea ",
      "    feeiiee===a ",
      "    feeiieeeiia ",
      "    feeiiee=iia ",
      "    fee==ee=iia ",
      "    feeee=h===a ",
      "    feeeehhg  a ",
      "    feeee=d   a ",
      " cccbaaaaaaaaaa ",
      "                "
    ],
    [
      "                ",
      "              c ",
      "    mmmmmmmmmmj ",
      "    mqqqq QPO a ",
      "    mqppq    Na ",
      "    mlkkl    Ma ",
      "    m====jLKJIa ",
      "    mFEj j ===a ",
      "    mD CAj B Aa ",
      "    my jxj = xa ",
      "    muw==u =tsa ",
      "    mqqq =r===a ",
      "    mpqp o ng a ",
      "    mklk =    a ",
      " cccbaaaaaaaaaa ",
      "                "
    ],
    [
      "                ",
      "              c ",
      "    mmmmmmmmmmj ",
      "    m      9  a ",
      "    m         a ",
      "    mS  S    8a ",
      "    m===bj76 5a ",
      "    m43jXj2===a ",
      "    m  1 j 0Z a ",
      "    m! j j =  a ",
      "    muY==u = Xa ",
      "    m   W=V=UUa ",
      "    m    T  nga ",
      "    m S  =   Ra ",
      " cccbaaaaaaaaaa ",
      "                "
    ],
    [
      "                ",
      "              c ",
      "    mmmmmmmmmmj ",
      "    m         a ",
      "    m         a ",
      "    m         a ",
      "    m====j7+)(a ",
      "    m  j^j ===a ",
      "    m  j&j * &a ",
      "    m  j j =  a ",
      "    muY==u = ^a ",
      "    m    =%===a ",
      "    m    $   na ",
      "    m    =  #ha ",
      " cccbaaaaaaaaaa ",
      "                "
    ],
    [
      "                ",
      "              c ",
      "    mmmmmmmmmmj ",
      "    m         a ",
      "    m         a ",
      "    m         a ",
      "    m====j}{]!a ",
      "    m  j j ===a ",
      "    m  j j =  a ",
      "    m  j j =  a ",
      "    m[-==  =  a ",
      "    m    =====a ",
      "    m    =    a ",
      "    m    = #d a ",
      " cccbaaaaaaaaaa ",
      "                "
    ],
    [
      "                ",
      "              c ",
      "    ;;;;;;;;;;j ",
      "    ;|||||||||a ",
      "    ;|||||||||a ",
      "    ;|||||||||a ",
      "    ;|||||||||a ",
      "    ;|||||||||a ",
      "    ;|||||||||a ",
      "    ;|||||||||a ",
      "    ;||||:||||a ",
      "    ;||||=====a ",
      "    ;||||=R   a ",
      "    ;||||=#d  a ",
      " cccbaaaaaaaaaa ",
      "                "
    ]
  ]
}