{
  "name": "building_hotela_ground",
  "refpalette": "deceasedcraft:building_hotela/building_hotela_ground_palette",
  "xsize": 16,
  "zsize": 16,
  "slices": [
    [
      "aaaaaaaaaaaaaaaa",
      "abbbbbbbbbbcbbba",
      "ab   deeeeefaaaa",
      "ab  gheeeeefiiii",
      "ab====eeeeefiiii",
      "abeeeeeeeeefiiii",
      "abeeeejkjkefaiii",
      "abeeeelmlmefnoon",
      "abeeeejkjkefonno",
      "abeeeelmlmefonno",
      "abeeeejkjkefnoon",
      "abeeeelmlmefaiii",
      "abeeeeeeeeefiiii",
      "acffffffffffiiii",
      "abaiiiiiiiiiiiii",
      "aaaiiiiiiiiiiiii"
    ],
    [
      "                ",
      " ppppppppppqbbb ",
      " p      rstu    ",
      " p gw      ux   ",
      " p=yAA     ux   ",
      " pB        ux   ",
      " pC f      uD   ",
      " pCEFI     J    ",
      " pC F     KL    ",
      " pC F     ML    ",
      " pCEFI     J    ",
      " pC f      uD   ",
      " pB        u    ",
      " Nuuuuuuuuuu    ",
      " b              ",
      "                "
    ],
    [
      "                ",
      " ppppppppppqbbb ",
      " pO       Pu    ",
      " pgw       u    ",
      " p=yyA     u    ",
      " pP        u    ",
      " pQ R      uS   ",
      " pQ T      J    ",
      " pQ       U     ",
      " pQ       V     ",
      " pQ W      J    ",
      " pQ R      uS   ",
      " pP        u    ",
      " Nuuuuuuuuuu    ",
      " b              ",
      "                "
    ],
    [
      "                ",
      " ppppppppppqbbb ",
      " phX      Pu    ",
      " pw        u    ",
      " p=yyA     u    ",
      " pP        u    ",
      " p         uY   ",
      " p         J    ",
      " p         J    ",
      " p      Z  J    ",
      " p         J    ",
      " p         uY   ",
      " pP        u    ",
      " Nuuuuuuuuuu    ",
      " b              ",
      "                "
    ],
    [
      "                ",
      " ppppppppppqbbb ",
      " p dX      u    ",
      " p         u    ",
      " p=yAA     u    ",
      " p         u    ",
      " p         u    ",
      " p     00  u    ",
      " p    1ZZ2 u    ",
      " p    1ZZ2 u    ",
      " p     33  u    ",
      " p         u    ",
      " p         u    ",
      " Nuuuuuuuuuu    ",
      " b              ",
      "                "
    ],
    [
      "                ",
      " ppppppppppqbbb ",
      " p  dX=44445    ",
      " p   O=44445    ",
      " p=====44445    ",
      " p4444444445    ",
      " p4444444445    ",
      " p4444466445    ",
      " p4444677645    ",
      " p4444677645    ",
      " p4444466445    ",
      " p4444444445    ",
      " p4444444445    ",
      " N5555555555    ",
      " b              ",
      "                "
    ]
  ]
}