{
  "name": "building_hotela_top",
  "refpalette": "deceasedcraft:building_hotela/building_hotela_top_palette",
  "xsize": 16,
  "zsize": 16,
  "slices": [
    [
      "                ",
      " aaaaaaaaaabccc ",
      " a   d=eeeef    ",
      " a  gh=eeeef    ",
      " a===h=eeeef    ",
      " aii=eeeeeef    ",
      " aii=eeeeeef    ",
      " aiieeeeeeef    ",
      " a=e=ee====f    ",
      " aeeeeeeeeef    ",
      " aeeee=eeeef    ",
      " aeeeeeeeeef    ",
      " aeeeeeeeeef    ",
      " jffffffffff    ",
      " c              ",
      "                "
    ],
    [
      "                ",
      " aaaaaaaaaabccc ",
      " a    =k   l    ",
      " a  m =noppl    ",
      " a===q=rstul    ",
      " awx= yrsAAl    ",
      " aB = yCsssl    ",
      " aD E    FFl    ",
      " a=I= j====l    ",
      " aJ   jKLLKl    ",
      " aMNjq=sOOsl    ",
      " aP j  ssssl    ",
      " aQRjST UVWl    ",
      " jllllllllll    ",
      " c              ",
      "                "
    ],
    [
      "                ",
      " aaaaaaaaaabccc ",
      " a    =X   l    ",
      " a    =  YZl    ",
      " a00=1=2   l    ",
      " a3 =      l    ",
      " a 4=5 6   l    ",
      " a  7    88l    ",
      " a=9= j====l    ",
      " a!   j#  $l    ",
      " a% j1=    l    ",
      " a^ j      l    ",
      " a  j&   * l    ",
      " jllllllllll    ",
      " c              ",
      "                "
    ],
    [
      "                ",
      " aaaaaaaaaabccc ",
      " a    =(   l    ",
      " a    =    l    ",
      " a===)=    l    ",
      " a+-=      l    ",
      " a  =      l    ",
      " a% [      l    ",
      " a=]= j====l    ",
      " a  j j    l    ",
      " a  j{=    l    ",
      " a  j      l    ",
      " a  j      l    ",
      " jllllllllll    ",
      " c              ",
      "                "
    ],
    [
      "                ",
      " aaaaaaaaaabccc ",
      " a    =    l    ",
      " a    =    l    ",
      " a=====    l    ",
      " a  =      l    ",
      " a  =      l    ",
      " a  =      l    ",
      " a=== j====l    ",
      " a  j j    l    ",
      " a  j==    l    ",
      " a  j      l    ",
      " a  j      l    ",
      " jllllllllll    ",
      " c              ",
      "                "
    ],
    [
      "                ",
      " aaaaaaaaaabccc ",
      " a    =  }|;    ",
      " a    =  }|;    ",
      " a=====  }|;    ",
      " a  =    }|;    ",
      " a  =    }|;    ",
      " a  =    }|;    ",
      " a=== j===|;    ",
      " a  j j  }|;    ",
      " a  j==  }|;    ",
      " a  j}}}}}|;    ",
      " a|||||||||;    ",
      " j;;;;;;;;;;    ",
      " c              ",
      "                "
    ],
    [
      "                ",
      " aaaaaaaaaabccc ",
      " a|||||||||f    ",
      " a|||||||||f    ",
      " a|||||||||f    ",
      " a|||||||||f    ",
      " a|||||||||f    ",
      " a|||||||||f    ",
      " a|||||||||f    ",
      " a|||||||||f    ",
      " a|||||||||f    ",
      " a|||||||||f    ",
      " a|||||||||f    ",
      " jffffffffff    ",
      " c              ",
      "                "
    ],
    [
      "                ",
      " aaaaaaaaaa ccc ",
      " a::::::::'<ccc ",
      " a:>>>>>>>a<ccc ",
      " a:>>>>>>>a<ccc ",
      " a:>>>>,,>a<ccc ",
      " a:::::,,>a<ccc ",
      " a:>>>>>>>a<ccc ",
      " a:>>>>>>>a<ccc ",
      " a:>>>>,,>a<ccc ",
      " a:::::,,>a<ccc ",
      " a:>>>>>>>a<ccc ",
      " a.aaaaaaaa<ccc ",
      "  <<<<<<<<<<ccc ",
      " cccccccccccccc ",
      "                "
    ],
    [
      "                ",
      " ??????????     ",
      " ?        ?     ",
      " ?        ?     ",
      " ?        ?     ",
      " ?     /` ?     ",
      " ?     // ?     ",
      " ?        ?     ",
      " ?        ?     ",
      " ?     // ?     ",
      " ?     `/ ?     ",
      " ?        ?     ",
      " ??????????     ",
      "                ",
      "                ",
      "                "
    ]
  ]
}