{
  "name": "building_hotela_floor3_180",
  "refpalette": "deceasedcraft:building_hotela/building_hotela_floor3_palette_180",
  "xsize": 16,
  "zsize": 16,
  "slices": [
    [
      "                ",
      "              c ",
      "    ffffffffffl ",
      "    feeeeeeeeea ",
      "    feeeeeeeeea ",
      "    feeeeeeeeea ",
      "    f====eeeeea ",
      "    feeiiee===a ",
      "    feeiieeeiia ",
      "    feeiieeeiia ",
      "    fee==eekjia ",
      "    feeee=h===a ",
      "    feeeehhg  a ",
      "    feeee=d   a ",
      " cccbaaaaaaaaaa ",
      "                "
    ],
    [
      "                ",
      "              c ",
      "    ooooooooool ",
      "    ossXU W  Va ",
      "    osrrUC T Sa ",
      "    onmmnR   Qa ",
      "    o====lPONMa ",
      "    oLKl l ===a ",
      "    oJ IElCF Ea ",
      "    oD lBl =CBa ",
      "    oyA==yx=wua ",
      "    osss =t===a ",
      "    orsr q pg a ",
      "    omnm =    a ",
      " cccbaaaaaaaaaa ",
      "                "
    ],
    [
      "                ",
      "              c ",
      "    ooooooooool ",
      "    o     +   a ",
      "    o         a ",
      "    o)  (    *a ",
      "    o===bl&^  a ",
      "    o%$l3l#===a ",
      "    o  9 l 876a ",
      "    o5 l l =  a ",
      "    oy4==y = 3a ",
      "    o   2=1=00a ",
      "    o    Z  pga ",
      "    o !  =   Ya ",
      " cccbaaaaaaaaaa ",
      "                "
    ],
    [
      "                ",
      "              c ",
      "    ooooooooool ",
      "    o         a ",
      "    o         a ",
      "    o         a ",
      "    o====l&':;a ",
      "    o  l{l ===a ",
      "    o  l}l | }a ",
      "    o  l l =  a ",
      "    oy4==y = {a ",
      "    o    =]===a ",
      "    o    [   pa ",
      "    o    =  -ha ",
      " cccbaaaaaaaaaa ",
      "                "
    ],
    [
      "                ",
      "              c ",
      "    ooooooooool ",
      "    o         a ",
      "    o         a ",
      "    o         a ",
      "    o====l/?. a ",
      "    o  l l ===a ",
      "    o  l l =  a ",
      "    o  l l =  a ",
      "    o,>==< =  a ",
      "    o    =====a ",
      "    o    =    a ",
      "    o    = -d a ",
      " cccbaaaaaaaaaa ",
      "                "
    ],
    [
      "                ",
      "              c ",
      "    \u0370\u0370\u0370\u0370\u0370\u0370\u0370\u0370\u0370\u0370l ",
      "    \u0370`````````a ",
      "    \u0370`````````a ",
      "    \u0370`````````a ",
      "    \u0370`````````a ",
      "    \u0370`````````a ",
      "    \u0370`````````a ",
      "    \u0370`````````a ",
      "    \u0370`````````a ",
      "    \u0370````=====a ",
      "    \u0370````=Y   a ",
      "    \u0370````=-d  a ",
      " cccbaaaaaaaaaa ",
      "                "
    ]
  ]
}