{
  "name": "building_hotela_base2_180",
  "refpalette": "deceasedcraft:building_hotela/building_hotela_base2_palette_180",
  "xsize": 16,
  "zsize": 16,
  "slices": [
    [
      "vvvvvvvvvvvvvvvv",
      "vaaaaaaaaaaaaaav",
      "vaaaaaaaaaaaaaav",
      "vaaaaaaaaaaaaaav",
      "vaaaaaaaaaaaaaav",
      "vaaaaaaaaaaaaaav",
      "vaaaaaaaaaaaaaav",
      "vaaaaaaaaaaaaaav",
      "vaaaaaaaaaaaaaav",
      "vaaaaaaaaaaaaaav",
      "vaaaaaaaaaaaaaav",
      "vaaaaaaaaaaaaaav",
      "vaaaaaaaaaaaaaav",
      "vaaaaaaaaaaaaaav",
      "vaaaaaaaaaaaaaav",
      "vvvvvvvvvvvvvvvv"
    ],
    [
      "vvvvvvvvvvvvvvvv",
      "vaaaaaaaaaaaaaav",
      "vaaaaaaaaaaaaaav",
      "vaaaaaaaaaaaaaav",
      "vaaaaaaaaaaaaaav",
      "vaaaaaaaaaaaaaav",
      "vaaaaaaaaaaaaaav",
      "vaaaaaaaaaaaaaav",
      "vaaaaaaaaaaaaaav",
      "vaaaaaaaaaaaaaav",
      "vaaaaaaaaaaaaaav",
      "vaaaaaaaaaaaaaav",
      "vaaaaaaaaaaaaaav",
      "vaaaaaaaaaaaaaav",
      "vaaaaaaaaaaaaaav",
      "vvvvvvvvvvvvvvvv"
    ],
    [
      "vvvvvvvvvvvvvvvv",
      "vaaaaaaaaaaaaaav",
      "vaaaaaaaaaaaaaav",
      "vaaaaaaaaaaaaaav",
      "vaaaaaaaaaaaaaav",
      "vaaaaaaaaaaaaaav",
      "vaaaaaaaaaaaaaav",
      "vaaaaaaaaaaaaaav",
      "vaaaaaaaaaaaaaav",
      "vaaaaaaaaaaaaaav",
      "vaaaaaaaaaaaaaav",
      "vaaaaaaaaaaaaaav",
      "vaaaaaaaaaaaaaav",
      "vaaaaaaaaaaaaaav",
      "vaaaaaaaaaaaaaav",
      "vvvvvvvvvvvvvvvv"
    ],
    [
      "vvvvvvvvvvvvvvvv",
      "vbbbbbbbbbbbbbbv",
      "vbbbbbbbbbbbbbbv",
      "vbbbbbbbbbbbbbbv",
      "vbbbbbbbbbbbbbbv",
      "vbbbbbbbbbbbbbbv",
      "vbbbbbbbbbbbbbbv",
      "vbbbbbbbbbbbbbbv",
      "vbbbbbbbbbbbbbbv",
      "vbbbbbbbbbbbbbbv",
      "vbbbbbbbbbbbbbbv",
      "vbbbbbbbbbbbbbbv",
      "vbbbbbbbbbbbbbbv",
      "vbbbbbbbbbbbbbbv",
      "vbbbbbbbbbbbbbbv",
      "vvvvvvvvvvvvvvvv"
    ],
    [
      "vvvvvvvvvvvvvvvv",
      "vccccccccccccccv",
      "vceeeeeeeeeeeegv",
      "vceeeeeeeeeeeegv",
      "vceeeeeeeeeeeegv",
      "vceeeeeeeeeeeegv",
      "vcgeegeeeeeeeegv",
      "vceeeeeeeeeeeegv",
      "vceeeeeeeeeeeegv",
      "vcefeeeeeeeeeegv",
      "vcefeeeeeeeeeegv",
      "vcefeeeeee====cv",
      "vcefeeeeeeeeddcv",
      "vcefeeeeeeeeddcv",
      "vccccccccccccccv",
      "vvvvvvvvvvvvvvvv"
    ],
    [
      "vvvvvvvvvvvvvvvv",
      "vccccccccccccccv",
      "vc!PPOENxN pppgv",
      "vcM  LE    CCCgv",
      "vcM  LE    uuupv",
      "vcK  JEwxw rrrgv",
      "vcgIFgE    pppgv",
      "vcD        CCCgv",
      "vcBAAy wxw uuupv",
      "vctsss     rrrgv",
      "vcqlllk    pppgv",
      "vcmlllk   ====cv",
      "vcmlllk  ommhncv",
      "vcmlllk    jihcv",
      "vccccccccccccccv",
      "vvvvvvvvvvvvvvvv"
    ]
  ]
}