{
  "name": "building_hotela_base2",
  "refpalette": "deceasedcraft:building_hotela/building_hotela_base2_palette",
  "xsize": 16,
  "zsize": 16,
  "slices": [
    [
      "vvvvvvvvvvvvvvvv",
      "vaaaaaaaaaaaaaav",
      "vaaaaaaaaaaaaaav",
      "vaaaaaaaaaaaaaav",
      "vaaaaaaaaaaaaaav",
      "vaaaaaaaaaaaaaav",
      "vaaaaaaaaaaaaaav",
      "vaaaaaaaaaaaaaav",
      "vaaaaaaaaaaaaaav",
      "vaaaaaaaaaaaaaav",
      "vaaaaaaaaaaaaaav",
      "vaaaaaaaaaaaaaav",
      "vaaaaaaaaaaaaaav",
      "vaaaaaaaaaaaaaav",
      "vaaaaaaaaaaaaaav",
      "vvvvvvvvvvvvvvvv"
    ],
    [
      "vvvvvvvvvvvvvvvv",
      "vaaaaaaaaaaaaaav",
      "vaaaaaaaaaaaaaav",
      "vaaaaaaaaaaaaaav",
      "vaaaaaaaaaaaaaav",
      "vaaaaaaaaaaaaaav",
      "vaaaaaaaaaaaaaav",
      "vaaaaaaaaaaaaaav",
      "vaaaaaaaaaaaaaav",
      "vaaaaaaaaaaaaaav",
      "vaaaaaaaaaaaaaav",
      "vaaaaaaaaaaaaaav",
      "vaaaaaaaaaaaaaav",
      "vaaaaaaaaaaaaaav",
      "vaaaaaaaaaaaaaav",
      "vvvvvvvvvvvvvvvv"
    ],
    [
      "vvvvvvvvvvvvvvvv",
      "vaaaaaaaaaaaaaav",
      "vaaaaaaaaaaaaaav",
      "vaaaaaaaaaaaaaav",
      "vaaaaaaaaaaaaaav",
      "vaaaaaaaaaaaaaav",
      "vaaaaaaaaaaaaaav",
      "vaaaaaaaaaaaaaav",
      "vaaaaaaaaaaaaaav",
      "vaaaaaaaaaaaaaav",
      "vaaaaaaaaaaaaaav",
      "vaaaaaaaaaaaaaav",
      "vaaaaaaaaaaaaaav",
      "vaaaaaaaaaaaaaav",
      "vaaaaaaaaaaaaaav",
      "vvvvvvvvvvvvvvvv"
    ],
    [
      "vvvvvvvvvvvvvvvv",
      "vbbbbbbbbbbbbbbv",
      "vbbbbbbbbbbbbbbv",
      "vbbbbbbbbbbbbbbv",
      "vbbbbbbbbbbbbbbv",
      "vbbbbbbbbbbbbbbv",
      "vbbbbbbbbbbbbbbv",
      "vbbbbbbbbbbbbbbv",
      "vbbbbbbbbbbbbbbv",
      "vbbbbbbbbbbbbbbv",
      "vbbbbbbbbbbbbbbv",
      "vbbbbbbbbbbbbbbv",
      "vbbbbbbbbbbbbbbv",
      "vbbbbbbbbbbbbbbv",
      "vbbbbbbbbbbbbbbv",
      "vvvvvvvvvvvvvvvv"
    ],
    [
      "vvvvvvvvvvvvvvvv",
      "vccccccccccccccv",
      "vcddeeeeeeeefecv",
      "vcddeeeeeeeefecv",
      "vc====eeeeeefecv",
      "vgeeeeeeeeeefecv",
      "vgeeeeeeeeeefecv",
      "vgeeeeeeeeeeeecv",
      "vgeeeeeeeeeeeecv",
      "vgeeeeeeeegeegcv",
      "vgeeeeeeeeeeeecv",
      "vgeeeeeeeeeeeecv",
      "vgeeeeeeeeeeeecv",
      "vgeeeeeeeeeeeecv",
      "vccccccccccccccv",
      "vvvvvvvvvvvvvvvv"
    ],
    [
      "vvvvvvvvvvvvvvvv",
      "vccccccccccccccv",
      "vchij    klllmcv",
      "vcnhmmo  klllmcv",
      "vc====   klllmcv",
      "vgppp    klllqcv",
      "vgrrr     ssstcv",
      "vpuuu wxw yAABcv",
      "vgCCC        Dcv",
      "vgppp    EgFIgcv",
      "vgrrr wxwEJ  Kcv",
      "vpuuu    EL  Mcv",
      "vgCCC    EL  Mcv",
      "vgppp NxNEOPP!cv",
      "vccccccccccccccv",
      "vvvvvvvvvvvvvvvv"
    ]
  ]
}