{
  "name": "building_hotela_base1",
  "refpalette": "deceasedcraft:building_hotela/building_hotela_base1_palette",
  "xsize": 16,
  "zsize": 16,
  "slices": [
    [
      "vvvvvvvvvvvvvvvv",
      "vaaaaaaaaaaaaaav",
      "vab c    de  fav",
      "vaghij   de  kav",
      "va====   de  lav",
      "vmnnn    de opav",
      "vm        e  qav",
      "vmrs      t  uav",
      "vm           wav",
      "vmnnn    xm  mav",
      "vm       xy   av",
      "vm AB    xC  Dav",
      "vm       xE  Fav",
      "vmnnn    xIJJKav",
      "vaaaaaaaaaaaaaav",
      "vvvvvvvvvvvvvvvv"
    ],
    [
      "vvvvvvvvvvvvvvvv",
      "vaaaaaaaaaaaaaav",
      "vaL M        Nav",
      "va  j        Oav",
      "va====        av",
      "vm           Pav",
      "vm            av",
      "vm           uav",
      "vm           wav",
      "vm       xm  mav",
      "vm       xL   av",
      "vm       x   Qav",
      "vm       x   Qav",
      "vm       x    av",
      "vaaaaaaaaaaaaaav",
      "vvvvvvvvvvvvvvvv"
    ],
    [
      "vvvvvvvvvvvvvvvv",
      "vaaaaaaaaaaaaaav",
      "vaii        RSav",
      "vaij        RTav",
      "va====      RTav",
      "vm           Tav",
      "vm          RSav",
      "vm   U   V   uav",
      "vm           wav",
      "vm       xmmmmav",
      "vm       x    av",
      "vm   W   x    av",
      "vm       x    av",
      "vm       x    av",
      "vaaaaaaaaaaaaaav",
      "vvvvvvvvvvvvvvvv"
    ],
    [
      "vvvvvvvvvvvvvvvv",
      "vaaaaaaaaaaaaaav",
      "vaii        R!av",
      "vaj         RXav",
      "va====      RXav",
      "vm          RYav",
      "vm          RZav",
      "vm   0   1   uav",
      "vm           wav",
      "vm       xmmmmav",
      "vm       x2223av",
      "vm   1   x2222av",
      "vm       x2222av",
      "vm       x2223av",
      "vaaaaaaaaaaaaaav",
      "vvvvvvvvvvvvvvvv"
    ],
    [
      "vvvvvvvvvvvvvvvv",
      "vaaaaaaaaaaaaaav",
      "va 45 6666666uav",
      "va    7777777uav",
      "va====7777777uav",
      "vm77777777777uav",
      "vm77777777777uav",
      "vm77787778777uav",
      "vm77777779999uav",
      "vm7777777xmmmmav",
      "vm7777777x####av",
      "vm7778777x#  $av",
      "vm7777777x#$$ av",
      "vm7777999x####av",
      "vaaaaaaaaaaaaaav",
      "vvvvvvvvvvvvvvvv"
    ],
    [
      "vvvvvvvvvvvvvvvv",
      "vaaaaaaaaaaaaaav",
      "va  45uuuuuuuuav",
      "va   %uuuuuuuuav",
      "va====uuuuuuuuav",
      "vmuuuuuuuuuuuuav",
      "vmuuuuuuuuuuuuav",
      "vmuuuuuuuuuuuuav",
      "vmuuuuuuuuuuuuav",
      "vmuuuuuuuuuuuuav",
      "vmuuuuuuuu^^^^av",
      "vmuuuuuuuu^^^^av",
      "vmuuuuuuuu^^^^av",
      "vmuuuuuuuu^^^^av",
      "vaaaaaaaaaaaaaav",
      "vvvvvvvvvvvvvvvv"
    ]
  ]
}