{
  "name": "building_hotela_floor4",
  "refpalette": "deceasedcraft:building_hotela/building_hotela_floor4_palette",
  "xsize": 16,
  "zsize": 16,
  "slices": [
    [
      "                ",
      " aaaaaaaaaabccc ",
      " a   d=eeeef    ",
      " a  ghheeeef    ",
      " a===h=eeeef    ",
      " aii=ee==eef    ",
      " aii=eeiieef    ",
      " aiieeeiieef    ",
      " a===eeiieef    ",
      " aeeeee====f    ",
      " aeeeeeeeeef    ",
      " aeeeeeeeeef    ",
      " aeeeeeeeeef    ",
      " jffffffffff    ",
      " c              ",
      "                "
    ],
    [
      "                ",
      " aaaaaaaaaabccc ",
      " a    = klkm    ",
      " a gn o pqpm    ",
      " a===r= qqqm    ",
      " ast= u==wum    ",
      " ax = jxj ym    ",
      " aA B jAC Dm    ",
      " a=== j jEFm    ",
      " aIJKLj====m    ",
      " aM    lkklm    ",
      " aN    qppqm    ",
      " a OPQ qqqqm    ",
      " jmmmmmmmmmm    ",
      " c              ",
      "                "
    ],
    [
      "                ",
      " aaaaaaaaaabccc ",
      " aR   =  S m    ",
      " agn  T    m    ",
      " aUU=V=W   m    ",
      " aX = u==Yum    ",
      " a  = j j !m    ",
      " a Z0 j 1  m    ",
      " a===2jXj34m    ",
      " a5 67jb===m    ",
      " a8    S  Sm    ",
      " a         m    ",
      " a  9      m    ",
      " jmmmmmmmmmm    ",
      " c              ",
      "                "
    ],
    [
      "                ",
      " aaaaaaaaaabccc ",
      " ah#  =    m    ",
      " an   $    m    ",
      " a===%=    m    ",
      " a^ = u==Yum    ",
      " a  = j j  m    ",
      " a& * j&j  m    ",
      " a=== j^j  m    ",
      " a()+7j====m    ",
      " a         m    ",
      " a         m    ",
      " a         m    ",
      " jmmmmmmmmmm    ",
      " c              ",
      "                "
    ],
    [
      "                ",
      " aaaaaaaaaabccc ",
      " a d# =    m    ",
      " a    =    m    ",
      " a=====    m    ",
      " a  =  ==-[m    ",
      " a  = j j  m    ",
      " a  = j j  m    ",
      " a=== j j  m    ",
      " a!]{}j====m    ",
      " a         m    ",
      " a         m    ",
      " a         m    ",
      " jmmmmmmmmmm    ",
      " c              ",
      "                "
    ],
    [
      "                ",
      " aaaaaaaaaabccc ",
      " a  d#=||||;    ",
      " a   R=||||;    ",
      " a=====||||;    ",
      " a||||:||||;    ",
      " a|||||||||;    ",
      " a|||||||||;    ",
      " a|||||||||;    ",
      " a|||||||||;    ",
      " a|||||||||;    ",
      " a|||||||||;    ",
      " a|||||||||;    ",
      " j;;;;;;;;;;    ",
      " c              ",
      "                "
    ]
  ]
}