{
  "name": "building_hotela_floor3_270",
  "refpalette": "deceasedcraft:building_hotela/building_hotela_floor3_palette_270",
  "xsize": 16,
  "zsize": 16,
  "slices": [
    [
      "                ",
      " claaaaaaaaaaaa ",
      "  feeee=iii=  a ",
      "  feeee=iij=  a ",
      "  feeee=eek=g a ",
      "  feeeeeeeehhda ",
      "  feeeeeeee=h=a ",
      "  feee=iii=eeea ",
      "  feee=iii=eeea ",
      "  feee=eeeeeeea ",
      "  feee=eeeeeeea ",
      "  ffffffffffffb ",
      "              c ",
      "              c ",
      "              c ",
      "                "
    ],
    [
      "                ",
      " claaaaaaaaaaaa ",
      "  oVSQM=EBu=  a ",
      "  o   N= Cw=g a ",
      "  o T O=F===p a ",
      "  oW  P C xt  a ",
      "  o CRlllly=q=a ",
      "  oUUn= EB=   a ",
      "  oXrm=lIl=srma ",
      "  osrm=K  Assna ",
      "  ossn=LJDysrma ",
      "  oooooooooooob ",
      "              c ",
      "              c ",
      "              c ",
      "                "
    ],
    [
      "                ",
      " claaaaaaaaaaaa ",
      "  o  * =6 30gYa ",
      "  o    =7  0p a ",
      "  o   ^=8===  a ",
      "  o+  &#   1  a ",
      "  o   lllly=Z=a ",
      "  o  (b3  =2  a ",
      "  o   =l9l=   a ",
      "  o   =$  4  !a ",
      "  o  )=% 5y   a ",
      "  oooooooooooob ",
      "              c ",
      "              c ",
      "              c ",
      "                "
    ],
    [
      "                ",
      " claaaaaaaaaaaa ",
      "  o   ;=} {=pha ",
      "  o   :=   = -a ",
      "  o   '=|===  a ",
      "  o   &    ]  a ",
      "  o   lllly=[=a ",
      "  o   ={} =   a ",
      "  o   =lll=   a ",
      "  o   =   4   a ",
      "  o   =   y   a ",
      "  oooooooooooob ",
      "              c ",
      "              c ",
      "              c ",
      "                "
    ],
    [
      "                ",
      " claaaaaaaaaaaa ",
      "  o    =   =  a ",
      "  o   .=   = da ",
      "  o   ?===== -a ",
      "  o   /    =  a ",
      "  o   llll<===a ",
      "  o   =   =   a ",
      "  o   =lll=   a ",
      "  o   =   >   a ",
      "  o   =   ,   a ",
      "  oooooooooooob ",
      "              c ",
      "              c ",
      "              c ",
      "                "
    ],
    [
      "                ",
      " claaaaaaaaaaaa ",
      "  \u0370````````=  a ",
      "  \u0370````````=  a ",
      "  \u0370````````= da ",
      "  \u0370````````=Y-a ",
      "  \u0370````````===a ",
      "  \u0370```````````a ",
      "  \u0370```````````a ",
      "  \u0370```````````a ",
      "  \u0370```````````a ",
      "  \u0370\u0370\u0370\u0370\u0370\u0370\u0370\u0370\u0370\u0370\u0370\u0370b ",
      "              c ",
      "              c ",
      "              c ",
      "                "
    ]
  ]
}