{
  "name": "building_hotela_base2_90",
  "refpalette": "deceasedcraft:building_hotela/building_hotela_base2_palette_90",
  "xsize": 16,
  "zsize": 16,
  "slices": [
    [
      "vvvvvvvvvvvvvvvv",
      "vaaaaaaaaaaaaaav",
      "vaaaaaaaaaaaaaav",
      "vaaaaaaaaaaaaaav",
      "vaaaaaaaaaaaaaav",
      "vaaaaaaaaaaaaaav",
      "vaaaaaaaaaaaaaav",
      "vaaaaaaaaaaaaaav",
      "vaaaaaaaaaaaaaav",
      "vaaaaaaaaaaaaaav",
      "vaaaaaaaaaaaaaav",
      "vaaaaaaaaaaaaaav",
      "vaaaaaaaaaaaaaav",
      "vaaaaaaaaaaaaaav",
      "vaaaaaaaaaaaaaav",
      "vvvvvvvvvvvvvvvv"
    ],
    [
      "vvvvvvvvvvvvvvvv",
      "vaaaaaaaaaaaaaav",
      "vaaaaaaaaaaaaaav",
      "vaaaaaaaaaaaaaav",
      "vaaaaaaaaaaaaaav",
      "vaaaaaaaaaaaaaav",
      "vaaaaaaaaaaaaaav",
      "vaaaaaaaaaaaaaav",
      "vaaaaaaaaaaaaaav",
      "vaaaaaaaaaaaaaav",
      "vaaaaaaaaaaaaaav",
      "vaaaaaaaaaaaaaav",
      "vaaaaaaaaaaaaaav",
      "vaaaaaaaaaaaaaav",
      "vaaaaaaaaaaaaaav",
      "vvvvvvvvvvvvvvvv"
    ],
    [
      "vvvvvvvvvvvvvvvv",
      "vaaaaaaaaaaaaaav",
      "vaaaaaaaaaaaaaav",
      "vaaaaaaaaaaaaaav",
      "vaaaaaaaaaaaaaav",
      "vaaaaaaaaaaaaaav",
      "vaaaaaaaaaaaaaav",
      "vaaaaaaaaaaaaaav",
      "vaaaaaaaaaaaaaav",
      "vaaaaaaaaaaaaaav",
      "vaaaaaaaaaaaaaav",
      "vaaaaaaaaaaaaaav",
      "vaaaaaaaaaaaaaav",
      "vaaaaaaaaaaaaaav",
      "vaaaaaaaaaaaaaav",
      "vvvvvvvvvvvvvvvv"
    ],
    [
      "vvvvvvvvvvvvvvvv",
      "vbbbbbbbbbbbbbbv",
      "vbbbbbbbbbbbbbbv",
      "vbbbbbbbbbbbbbbv",
      "vbbbbbbbbbbbbbbv",
      "vbbbbbbbbbbbbbbv",
      "vbbbbbbbbbbbbbbv",
      "vbbbbbbbbbbbbbbv",
      "vbbbbbbbbbbbbbbv",
      "vbbbbbbbbbbbbbbv",
      "vbbbbbbbbbbbbbbv",
      "vbbbbbbbbbbbbbbv",
      "vbbbbbbbbbbbbbbv",
      "vbbbbbbbbbbbbbbv",
      "vbbbbbbbbbbbbbbv",
      "vvvvvvvvvvvvvvvv"
    ],
    [
      "vvvvvvvvvvvvvvvv",
      "vccccccccccccccv",
      "vceeeeeeegeeeecv",
      "vcfffffeeeeeeecv",
      "vceeeeeeeeeeeecv",
      "vceeeeeeegeeeecv",
      "vceeeeeeeeeeeecv",
      "vceeeeeeeeeeeecv",
      "vceeeeeeeeeeeecv",
      "vceeeeeeeeeeeecv",
      "vcee=eeeeeeeeecv",
      "vcee=eeeeeeeeecv",
      "vcdd=eeeeeeeeecv",
      "vcdd=eeeeeeeeecv",
      "vccccgggggggggcv",
      "vvvvvvvvvvvvvvvv"
    ],
    [
      "vvvvvvvvvvvvvvvv",
      "vccccccccccccccv",
      "vcmmmqtBDgKMM!cv",
      "vcllllsA I   Pcv",
      "vcllllsA F   Pcv",
      "vcllllsy gJLLOcv",
      "vckkkk   EEEEEcv",
      "vc     w  w  Ncv",
      "vc     x  x  xcv",
      "vc o   w  w  Ncv",
      "vc m=         cv",
      "vcjm=pruCpruCpcv",
      "vcih=pruCpruCpcv",
      "vchn=pruCpruCpcv",
      "vccccggpgggpggcv",
      "vvvvvvvvvvvvvvvv"
    ]
  ]
}