{
  "name": "building_hotela_ground_180",
  "refpalette": "deceasedcraft:building_hotela/building_hotela_ground_palette_180",
  "xsize": 16,
  "zsize": 16,
  "slices": [
    [
      "iiiiiiiiiiiiiaaa",
      "iiiiiiiiiiiiiaba",
      "iiiiffffffffffca",
      "iiiifeeeeeeeeeba",
      "iiiafemlmleeeeba",
      "noonfekjkjeeeeba",
      "onnofemlmleeeeba",
      "onnofekjkjeeeeba",
      "noonfemlmleeeeba",
      "iiiafekjkjeeeeba",
      "iiiifeeeeeeeeeba",
      "iiiifeeeee====ba",
      "iiiifeeeeehg  ba",
      "aaaafeeeeed   ba",
      "abbbcbbbbbbbbbba",
      "aaaaaaaaaaaaaaaa"
    ],
    [
      "                ",
      "              b ",
      "    uuuuuuuuuuN ",
      "    u        Bp ",
      "   Du      f Cp ",
      "    J     IFECp ",
      "    LM     F Cp ",
      "    LK     F Cp ",
      "    J     IFECp ",
      "   Du      f Cp ",
      "   xu        Bp ",
      "   xu     AAy=p ",
      "   xu      wg p ",
      "    utsr      p ",
      " bbbqpppppppppp ",
      "                "
    ],
    [
      "                ",
      "              b ",
      "    uuuuuuuuuuN ",
      "    u        Pp ",
      "   Su      R Qp ",
      "    J      W Qp ",
      "     V       Qp ",
      "     U       Qp ",
      "    J      T Qp ",
      "   Su      R Qp ",
      "    u        Pp ",
      "    u     Ayy=p ",
      "    u       wgp ",
      "    uP       Op ",
      " bbbqpppppppppp ",
      "                "
    ],
    [
      "                ",
      "              b ",
      "    uuuuuuuuuuN ",
      "    u        Pp ",
      "   Yu         p ",
      "    J         p ",
      "    J  Z      p ",
      "    J         p ",
      "    J         p ",
      "   Yu         p ",
      "    u        Pp ",
      "    u     Ayy=p ",
      "    u        wp ",
      "    uP      Xhp ",
      " bbbqpppppppppp ",
      "                "
    ],
    [
      "                ",
      "              b ",
      "    uuuuuuuuuuN ",
      "    u         p ",
      "    u         p ",
      "    u  33     p ",
      "    u 2ZZ1    p ",
      "    u 2ZZ1    p ",
      "    u  00     p ",
      "    u         p ",
      "    u         p ",
      "    u     AAy=p ",
      "    u         p ",
      "    u      Xd p ",
      " bbbqpppppppppp ",
      "                "
    ],
    [
      "                ",
      "              b ",
      "    5555555555N ",
      "    5444444444p ",
      "    5444444444p ",
      "    5446644444p ",
      "    5467764444p ",
      "    5467764444p ",
      "    5446644444p ",
      "    5444444444p ",
      "    5444444444p ",
      "    54444=====p ",
      "    54444=O   p ",
      "    54444=Xd  p ",
      " bbbqpppppppppp ",
      "                "
    ]
  ]
}