{
  "name": "building_hotela_base2_270",
  "refpalette": "deceasedcraft:building_hotela/building_hotela_base2_palette_270",
  "xsize": 16,
  "zsize": 16,
  "slices": [
    [
      "vvvvvvvvvvvvvvvv",
      "vaaaaaaaaaaaaaav",
      "vaaaaaaaaaaaaaav",
      "vaaaaaaaaaaaaaav",
      "vaaaaaaaaaaaaaav",
      "vaaaaaaaaaaaaaav",
      "vaaaaaaaaaaaaaav",
      "vaaaaaaaaaaaaaav",
      "vaaaaaaaaaaaaaav",
      "vaaaaaaaaaaaaaav",
      "vaaaaaaaaaaaaaav",
      "vaaaaaaaaaaaaaav",
      "vaaaaaaaaaaaaaav",
      "vaaaaaaaaaaaaaav",
      "vaaaaaaaaaaaaaav",
      "vvvvvvvvvvvvvvvv"
    ],
    [
      "vvvvvvvvvvvvvvvv",
      "vaaaaaaaaaaaaaav",
      "vaaaaaaaaaaaaaav",
      "vaaaaaaaaaaaaaav",
      "vaaaaaaaaaaaaaav",
      "vaaaaaaaaaaaaaav",
      "vaaaaaaaaaaaaaav",
      "vaaaaaaaaaaaaaav",
      "vaaaaaaaaaaaaaav",
      "vaaaaaaaaaaaaaav",
      "vaaaaaaaaaaaaaav",
      "vaaaaaaaaaaaaaav",
      "vaaaaaaaaaaaaaav",
      "vaaaaaaaaaaaaaav",
      "vaaaaaaaaaaaaaav",
      "vvvvvvvvvvvvvvvv"
    ],
    [
      "vvvvvvvvvvvvvvvv",
      "vaaaaaaaaaaaaaav",
      "vaaaaaaaaaaaaaav",
      "vaaaaaaaaaaaaaav",
      "vaaaaaaaaaaaaaav",
      "vaaaaaaaaaaaaaav",
      "vaaaaaaaaaaaaaav",
      "vaaaaaaaaaaaaaav",
      "vaaaaaaaaaaaaaav",
      "vaaaaaaaaaaaaaav",
      "vaaaaaaaaaaaaaav",
      "vaaaaaaaaaaaaaav",
      "vaaaaaaaaaaaaaav",
      "vaaaaaaaaaaaaaav",
      "vaaaaaaaaaaaaaav",
      "vvvvvvvvvvvvvvvv"
    ],
    [
      "vvvvvvvvvvvvvvvv",
      "vbbbbbbbbbbbbbbv",
      "vbbbbbbbbbbbbbbv",
      "vbbbbbbbbbbbbbbv",
      "vbbbbbbbbbbbbbbv",
      "vbbbbbbbbbbbbbbv",
      "vbbbbbbbbbbbbbbv",
      "vbbbbbbbbbbbbbbv",
      "vbbbbbbbbbbbbbbv",
      "vbbbbbbbbbbbbbbv",
      "vbbbbbbbbbbbbbbv",
      "vbbbbbbbbbbbbbbv",
      "vbbbbbbbbbbbbbbv",
      "vbbbbbbbbbbbbbbv",
      "vbbbbbbbbbbbbbbv",
      "vvvvvvvvvvvvvvvv"
    ],
    [
      "vvvvvvvvvvvvvvvv",
      "vcgggggggggccccv",
      "vceeeeeeeee=ddcv",
      "vceeeeeeeee=ddcv",
      "vceeeeeeeee=eecv",
      "vceeeeeeeee=eecv",
      "vceeeeeeeeeeeecv",
      "vceeeeeeeeeeeecv",
      "vceeeeeeeeeeeecv",
      "vceeeeeeeeeeeecv",
      "vceeeegeeeeeeecv",
      "vceeeeeeeeeeeecv",
      "vceeeeeeefffffcv",
      "vceeeegeeeeeeecv",
      "vccccccccccccccv",
      "vvvvvvvvvvvvvvvv"
    ],
    [
      "vvvvvvvvvvvvvvvv",
      "vcggpgggpggccccv",
      "vcpCurpCurp=nhcv",
      "vcpCurpCurp=hicv",
      "vcpCurpCurp=mjcv",
      "vc         =m cv",
      "vcN  w  w   o cv",
      "vcx  x  x     cv",
      "vcN  w  w     cv",
      "vcEEEEE   kkkkcv",
      "vcOLLJg ysllllcv",
      "vcP   F Asllllcv",
      "vcP   I Asllllcv",
      "vc!MMKgDBtqmmmcv",
      "vccccccccccccccv",
      "vvvvvvvvvvvvvvvv"
    ]
  ]
}