{
  "name": "building_hotela_floor1_90",
  "refpalette": "deceasedcraft:building_hotela/building_hotela_floor1_palette_90",
  "xsize": 16,
  "zsize": 16,
  "slices": [
    [
      "                ",
      " c              ",
      " c              ",
      " c              ",
      " bffffffffffff  ",
      " aeeeeeeeeeeef  ",
      " aeeeeeeeee!ef  ",
      " aei!ieeeeeeef  ",
      " aeeeeeeeeeeef  ",
      " aeeeeeeeeeeef  ",
      " adh=eeeeeeeef  ",
      " a g=eeeeeeeef  ",
      " a  =eeeeeeeef  ",
      " a  =eeeeeeeef  ",
      " aaaaaaaaaaaajc ",
      "                "
    ],
    [
      "                ",
      " c              ",
      " c              ",
      " c              ",
      " bllllllllllll  ",
      " a oqs     B l  ",
      " akkkkk  wwx l  ",
      " aknnnk      l  ",
      " akkkkk    A l  ",
      " a       wwx l  ",
      " a  p        l  ",
      " a mp      y l  ",
      " a gp    wwx l  ",
      " a  =rtu     l  ",
      " aaaaaaaaaaaajc ",
      "                "
    ],
    [
      "                ",
      " c              ",
      " c              ",
      " c              ",
      " bllllllllllll  ",
      " a           l  ",
      " a     F     l  ",
      " a           l  ",
      " a     F     l  ",
      " a     F     l  ",
      " a  D        l  ",
      " a  D        l  ",
      " a mD  F     l  ",
      " aCg=rtE     l  ",
      " aaaaaaaaaaaajc ",
      "                "
    ],
    [
      "                ",
      " c              ",
      " c              ",
      " c              ",
      " bllllllllllll  ",
      " a     F     l  ",
      " aK    F     l  ",
      " aJ    F     l  ",
      " a     F     l  ",
      " a     F     l  ",
      " a  D        l  ",
      " a  D  F     l  ",
      " aI D  F     l  ",
      " ahm=rtE     l  ",
      " aaaaaaaaaaaajc ",
      "                "
    ],
    [
      "                ",
      " c              ",
      " c              ",
      " c              ",
      " bllllllllllll  ",
      " a     P     l  ",
      " a     P     l  ",
      " a     P     l  ",
      " a     P     l  ",
      " a     P     l  ",
      " a  L  P     l  ",
      " aI L  P     l  ",
      " ad L  P     l  ",
      " a  =MNO     l  ",
      " aaaaaaaaaaaajc ",
      "                "
    ],
    [
      "                ",
      " c              ",
      " c              ",
      " c              ",
      " bwwwwwwwwwwww  ",
      " aQQQQQQQQQQQw  ",
      " aQQQQQQQQQQQw  ",
      " aQQQQQQQQQQQw  ",
      " aQQQQQQQQQQQw  ",
      " a===QQQQQQQQw  ",
      " aIC=QQQQQQQQw  ",
      " ad =QQQQQQQQw  ",
      " a  =QQQQQQQQw  ",
      " a  =QRQQQQQQw  ",
      " aaaaaaaaaaaajc ",
      "                "
    ]
  ]
}