{
  "name": "building_hotela_floor1_180",
  "refpalette": "deceasedcraft:building_hotela/building_hotela_floor1_palette_180",
  "xsize": 16,
  "zsize": 16,
  "slices": [
    [
      "                ",
      "              c ",
      "    ffffffffffj ",
      "    feeeeeeeeea ",
      "    fe!eeeeeeea ",
      "    feeeeeeeeea ",
      "    feeeeeeeeea ",
      "    feeeeeeeeea ",
      "    feeeeeeeeea ",
      "    feeeeeeeeea ",
      "    feeieeeeeea ",
      "    fee!ee====a ",
      "    feeieehg  a ",
      "    feeeeed   a ",
      " cccbaaaaaaaaaa ",
      "                "
    ],
    [
      "                ",
      "              c ",
      "    llllllllllj ",
      "    l         a ",
      "    lBx Ax yx a ",
      "    l w  w  w a ",
      "    l w  w  w a ",
      "    l         a ",
      "    l        ua ",
      "    l kkk    ta ",
      "    lsknk    ra ",
      "    lqknk ppp=a ",
      "    loknk  mg a ",
      "    l kkk     a ",
      " cccbaaaaaaaaaa ",
      "                "
    ],
    [
      "                ",
      "              c ",
      "    llllllllllj ",
      "    l         a ",
      "    l         a ",
      "    l         a ",
      "    l         a ",
      "    l         a ",
      "    l F FF  FEa ",
      "    l        ta ",
      "    l        ra ",
      "    l     DDD=a ",
      "    l       mga ",
      "    l        Ca ",
      " cccbaaaaaaaaaa ",
      "                "
    ],
    [
      "                ",
      "              c ",
      "    llllllllllj ",
      "    l         a ",
      "    l         a ",
      "    l         a ",
      "    l         a ",
      "    l         a ",
      "    lFFFFF FFEa ",
      "    l        ta ",
      "    l        ra ",
      "    l     DDD=a ",
      "    l        ma ",
      "    l KJ    Iha ",
      " cccbaaaaaaaaaa ",
      "                "
    ],
    [
      "                ",
      "              c ",
      "    llllllllllj ",
      "    l         a ",
      "    l         a ",
      "    l         a ",
      "    l         a ",
      "    l         a ",
      "    lPPPPPPPPOa ",
      "    l        Na ",
      "    l        Ma ",
      "    l     LLL=a ",
      "    l         a ",
      "    l      Id a ",
      " cccbaaaaaaaaaa ",
      "                "
    ],
    [
      "                ",
      "              c ",
      "    wwwwwwwwwwj ",
      "    wQQQQQQQQQa ",
      "    wQQQQQQQQQa ",
      "    wQQQQQQQQQa ",
      "    wQQQQQQQQQa ",
      "    wQQQQQQQQQa ",
      "    wQQQQQQQQQa ",
      "    wQQQQQQQQRa ",
      "    wQQQQQQQQQa ",
      "    wQQQQ=====a ",
      "    wQQQQ=C   a ",
      "    wQQQQ=Id  a ",
      " cccbaaaaaaaaaa ",
      "                "
    ]
  ]
}