{
  "name": "building_hotela_floor4_90",
  "refpalette": "deceasedcraft:building_hotela/building_hotela_floor4_palette_90",
  "xsize": 16,
  "zsize": 16,
  "slices": [
    [
      "                ",
      " c              ",
      " c              ",
      " c              ",
      " bffffffffffff  ",
      " aeeeeeee=eeef  ",
      " aeeeeeee=eeef  ",
      " aeee=iii=eeef  ",
      " aeee=iii=eeef  ",
      " a=h=eeeeeeeef  ",
      " adhheeeeeeeef  ",
      " a g===e=eeeef  ",
      " a  =iii=eeeef  ",
      " a  =iii=eeeef  ",
      " aaaaaaaaaaaajc ",
      "                "
    ],
    [
      "                ",
      " c              ",
      " c              ",
      " c              ",
      " bmmmmmmmmmmmm  ",
      " akpquyDF=lqqm  ",
      " alqqw  E=kpqm  ",
      " akpq=jCj=kpqm  ",
      " a   =xA =lqqm  ",
      " a=o=ujjjj   m  ",
      " a  r    L  Qm  ",
      " a n===B=K  Pm  ",
      " a g=t  =J  Om  ",
      " a  =sxA=IMN m  ",
      " aaaaaaaaaaaajc ",
      "                "
    ],
    [
      "                ",
      " c              ",
      " c              ",
      " c              ",
      " bmmmmmmmmmmmm  ",
      " a   u! 4=S  m  ",
      " aS  Y  3=   m  ",
      " a   =j1j=   m  ",
      " a  W=  XbS  m  ",
      " a=T=ujjjj   m  ",
      " a  V   27   m  ",
      " a  ===0=6  9m  ",
      " a nU  Z=    m  ",
      " aRgUX  =58  m  ",
      " aaaaaaaaaaaajc ",
      "                "
    ],
    [
      "                ",
      " c              ",
      " c              ",
      " c              ",
      " bmmmmmmmmmmmm  ",
      " a   u   =   m  ",
      " a   Y   =   m  ",
      " a   =jjj=   m  ",
      " a   = &^=   m  ",
      " a=$=ujjjj   m  ",
      " a  %    7   m  ",
      " a  ===*=+   m  ",
      " a# =   =)   m  ",
      " ahn=^ &=(   m  ",
      " aaaaaaaaaaaajc ",
      "                "
    ],
    [
      "                ",
      " c              ",
      " c              ",
      " c              ",
      " bmmmmmmmmmmmm  ",
      " a   [   =   m  ",
      " a   -   =   m  ",
      " a   =jjj=   m  ",
      " a   =   =   m  ",
      " a=== jjjj   m  ",
      " a  =    }   m  ",
      " a# ====={   m  ",
      " ad =   =]   m  ",
      " a  =   =!   m  ",
      " aaaaaaaaaaaajc ",
      "                "
    ],
    [
      "                ",
      " c              ",
      " c              ",
      " c              ",
      " b;;;;;;;;;;;;  ",
      " a|||||||||||;  ",
      " a|||||||||||;  ",
      " a|||||||||||;  ",
      " a|||||||||||;  ",
      " a===:|||||||;  ",
      " a#R=||||||||;  ",
      " ad =||||||||;  ",
      " a  =||||||||;  ",
      " a  =||||||||;  ",
      " aaaaaaaaaaaajc ",
      "                "
    ]
  ]
}