{
  "name": "building_hotela_floor2_90",
  "refpalette": "deceasedcraft:building_hotela/building_hotela_floor2_palette_90",
  "xsize": 16,
  "zsize": 16,
  "slices": [
    [
      "                ",
      " c              ",
      " c              ",
      " c              ",
      " bffffffffffff  ",
      " aeeeeeee=eeef  ",
      " aeeeeeee=eeef  ",
      " aeee=iii=eeef  ",
      " aeee=iii=eeef  ",
      " a=h=eeeeeeeef  ",
      " adhheeeeeeeef  ",
      " a g===e=eeeef  ",
      " a  =iii=eeeef  ",
      " a  =ii!=eeeef  ",
      " aaaaaaaaaaaajc ",
      "                "
    ],
    [
      "                ",
      " c              ",
      " c              ",
      " c              ",
      " bnnnnnnnnnnnn  ",
      " alqrwAEI=mrrn  ",
      " amrrx  F=lqrn  ",
      " alqr=jDj=lqrn  ",
      " ak  =yB =mrrn  ",
      " a=p=wjjjj   n  ",
      " a  s    M  Rn  ",
      " a o===C=L  Qn  ",
      " a g=u  =K  Pn  ",
      " a  =tyB=JNO n  ",
      " aaaaaaaaaaaajc ",
      "                "
    ],
    [
      "                ",
      " c              ",
      " c              ",
      " c              ",
      " bnnnnnnnnnnnn  ",
      " a   w0 5=#  n  ",
      " aT  Z   =   n  ",
      " a   =j3j=   n  ",
      " a  X=  Yb#  n  ",
      " a=U=wjjjj   n  ",
      " a  W   48   n  ",
      " a  ===2=7   n  ",
      " a oV  1=    n  ",
      " aSgVY  =69  n  ",
      " aaaaaaaaaaaajc ",
      "                "
    ],
    [
      "                ",
      " c              ",
      " c              ",
      " c              ",
      " bnnnnnnnnnnnn  ",
      " a   w   =   n  ",
      " a   Z   =   n  ",
      " a   =jjj=   n  ",
      " a   = *&=   n  ",
      " a=%=wjjjj   n  ",
      " a  ^    8   n  ",
      " a  ===(=-   n  ",
      " a$ =   =+   n  ",
      " aho=& *=)   n  ",
      " aaaaaaaaaaaajc ",
      "                "
    ],
    [
      "                ",
      " c              ",
      " c              ",
      " c              ",
      " bnnnnnnnnnnnn  ",
      " a   ]   =   n  ",
      " a   [   =   n  ",
      " a   =jjj=   n  ",
      " a   =   =   n  ",
      " a=== jjjj   n  ",
      " a  =    |   n  ",
      " a$ =====    n  ",
      " ad =   =}   n  ",
      " a  =   ={   n  ",
      " aaaaaaaaaaaajc ",
      "                "
    ],
    [
      "                ",
      " c              ",
      " c              ",
      " c              ",
      " b::::::::::::  ",
      " a;;;;;;;;;;;:  ",
      " a;;;;;;;;;;;:  ",
      " a;;;;;;;;;;;:  ",
      " a;;;;;;;;;;;:  ",
      " a===;;;;;;;;:  ",
      " a$S=;;;;;;;;:  ",
      " ad =;;;;;;;;:  ",
      " a  =;;;;;;;;:  ",
      " a  =;;;;';;;:  ",
      " aaaaaaaaaaaajc ",
      "                "
    ]
  ]
}