{
  "name": "building_hotela_floor3",
  "refpalette": "deceasedcraft:building_hotela/building_hotela_floor3_palette",
  "xsize": 16,
  "zsize": 16,
  "slices": [
    [
      "                ",
      " aaaaaaaaaabccc ",
      " a   d=eeeef    ",
      " a  ghheeeef    ",
      " a===h=eeeef    ",
      " aijkee==eef    ",
      " aiieeeiieef    ",
      " aiieeeiieef    ",
      " a===eeiieef    ",
      " aeeeee====f    ",
      " aeeeeeeeeef    ",
      " aeeeeeeeeef    ",
      " aeeeeeeeeef    ",
      " lffffffffff    ",
      " c              ",
      "                "
    ],
    [
      "                ",
      " aaaaaaaaaabccc ",
      " a    = mnmo    ",
      " a gp q rsro    ",
      " a===t= ssso    ",
      " auw=xy==Ayo    ",
      " aBC= lBl Do    ",
      " aE FClEI Jo    ",
      " a=== l lKLo    ",
      " aMNOPl====o    ",
      " aQ   Rnmmno    ",
      " aS T CUrrso    ",
      " aV  W UXsso    ",
      " loooooooooo    ",
      " c              ",
      "                "
    ],
    [
      "                ",
      " aaaaaaaaaabccc ",
      " aY   =  ! o    ",
      " agp  Z    o    ",
      " a00=1=2   o    ",
      " a3 = y==4yo    ",
      " a  = l l 5o    ",
      " a678 l 9  o    ",
      " a===#l3l$%o    ",
      " a  ^&lb===o    ",
      " a*    (  )o    ",
      " a         o    ",
      " a   +     o    ",
      " loooooooooo    ",
      " c              ",
      "                "
    ],
    [
      "                ",
      " aaaaaaaaaabccc ",
      " ah-  =    o    ",
      " ap   [    o    ",
      " a===]=    o    ",
      " a{ = y==4yo    ",
      " a  = l l  o    ",
      " a} | l}l  o    ",
      " a=== l{l  o    ",
      " a;:'&l====o    ",
      " a         o    ",
      " a         o    ",
      " a         o    ",
      " loooooooooo    ",
      " c              ",
      "                "
    ],
    [
      "                ",
      " aaaaaaaaaabccc ",
      " a d- =    o    ",
      " a    =    o    ",
      " a=====    o    ",
      " a  = <==>,o    ",
      " a  = l l  o    ",
      " a  = l l  o    ",
      " a=== l l  o    ",
      " a .?/l====o    ",
      " a         o    ",
      " a         o    ",
      " a         o    ",
      " loooooooooo    ",
      " c              ",
      "                "
    ],
    [
      "                ",
      " aaaaaaaaaabccc ",
      " a  d-=````\u0370    ",
      " a   Y=````\u0370    ",
      " a=====````\u0370    ",
      " a`````````\u0370    ",
      " a`````````\u0370    ",
      " a`````````\u0370    ",
      " a`````````\u0370    ",
      " a`````````\u0370    ",
      " a`````````\u0370    ",
      " a`````````\u0370    ",
      " a`````````\u0370    ",
      " l\u0370\u0370\u0370\u0370\u0370\u0370\u0370\u0370\u0370\u0370    ",
      " c              ",
      "                "
    ]
  ]
}