{
  "name": "building_hotela_base1_90",
  "refpalette": "deceasedcraft:building_hotela/building_hotela_base1_palette_90",
  "xsize": 16,
  "zsize": 16,
  "slices": [
    [
      "vvvvvvvvvvvvvvvv",
      "vaaaaaaaaaaaaaav",
      "vafklpquwm DFKav",
      "va   o       Jav",
      "va           Jav",
      "vaeeeeet myCEIav",
      "vadddd   xxxxxav",
      "va            av",
      "va            av",
      "va            av",
      "va j=         av",
      "vaci=n   n B nav",
      "va h=n s n A nav",
      "vabg=n r n   nav",
      "vaaaammmmmmmmmav",
      "vvvvvvvvvvvvvvvv"
    ],
    [
      "vvvvvvvvvvvvvvvv",
      "vaaaaaaaaaaaaaav",
      "vaNO P uwm QQ av",
      "va            av",
      "va            av",
      "va       mL   av",
      "va       xxxxxav",
      "va            av",
      "va            av",
      "va            av",
      "va  =         av",
      "vaMj=         av",
      "va  =         av",
      "vaL =         av",
      "vaaaammmmmmmmmav",
      "vvvvvvvvvvvvvvvv"
    ],
    [
      "vvvvvvvvvvvvvvvv",
      "vaaaaaaaaaaaaaav",
      "vaSTTTSuwm    av",
      "vaRRR R  m    av",
      "va       m    av",
      "va       m    av",
      "va     V xxxxxav",
      "va            av",
      "va            av",
      "va            av",
      "va  =  U   W  av",
      "va  =         av",
      "vaij=         av",
      "vaii=         av",
      "vaaaammmmmmmmmav",
      "vvvvvvvvvvvvvvvv"
    ],
    [
      "vvvvvvvvvvvvvvvv",
      "vaaaaaaaaaaaaaav",
      "va!XXYZuwm3223av",
      "vaRRRRR  m2222av",
      "va       m2222av",
      "va       m2222av",
      "va     1 xxxxxav",
      "va            av",
      "va            av",
      "va            av",
      "va  =  0   1  av",
      "va  =         av",
      "vai =         av",
      "vaij=         av",
      "vaaaammmmmmmmmav",
      "vvvvvvvvvvvvvvvv"
    ],
    [
      "vvvvvvvvvvvvvvvv",
      "vaaaaaaaaaaaaaav",
      "vauuuuuuum#$ #av",
      "va6777779m# $#av",
      "va6777779m# $#av",
      "va6777779m####av",
      "va6777789xxxxxav",
      "va677777777779av",
      "va677777777779av",
      "va677777777779av",
      "va  =778777877av",
      "va5 =777777777av",
      "va4 =777777777av",
      "va  =777777777av",
      "vaaaammmmmmmmmav",
      "vvvvvvvvvvvvvvvv"
    ],
    [
      "vvvvvvvvvvvvvvvv",
      "vaaaaaaaaaaaaaav",
      "vauuuuuuuu^^^^av",
      "vauuuuuuuu^^^^av",
      "vauuuuuuuu^^^^av",
      "vauuuuuuuu^^^^av",
      "vauuuuuuuuuuuuav",
      "vauuuuuuuuuuuuav",
      "vauuuuuuuuuuuuav",
      "vauuuuuuuuuuuuav",
      "va5%=uuuuuuuuuav",
      "va4 =uuuuuuuuuav",
      "va  =uuuuuuuuuav",
      "va  =uuuuuuuuuav",
      "vaaaammmmmmmmmav",
      "vvvvvvvvvvvvvvvv"
    ]
  ]
}