{
  "name": "building_hotela_floor4_270",
  "refpalette": "deceasedcraft:building_hotela/building_hotela_floor4_palette_270",
  "xsize": 16,
  "zsize": 16,
  "slices": [
    [
      "                ",
      " cjaaaaaaaaaaaa ",
      "  feeee=iii=  a ",
      "  feeee=iii=  a ",
      "  feeee=e===g a ",
      "  feeeeeeeehhda ",
      "  feeeeeeee=h=a ",
      "  feee=iii=eeea ",
      "  feee=iii=eeea ",
      "  feee=eeeeeeea ",
      "  feee=eeeeeeea ",
      "  ffffffffffffb ",
      "              c ",
      "              c ",
      "              c ",
      "                "
    ],
    [
      "                ",
      " cjaaaaaaaaaaaa ",
      "  m NMI=Axs=  a ",
      "  mO  J=  t=g a ",
      "  mP  K=B===n a ",
      "  mQ  L    r  a ",
      "  m   jjjju=o=a ",
      "  mqql= Ax=   a ",
      "  mqpk=jCj=qpka ",
      "  mqpk=E  wqqla ",
      "  mqql=FDyuqpka ",
      "  mmmmmmmmmmmmb ",
      "              c ",
      "              c ",
      "              c ",
      "                "
    ],
    [
      "                ",
      " cjaaaaaaaaaaaa ",
      "  m  85=  XUgRa ",
      "  m    =Z  Un a ",
      "  m9  6=0===  a ",
      "  m   72   V  a ",
      "  m   jjjju=T=a ",
      "  m  SbX  =W  a ",
      "  m   =j1j=   a ",
      "  m   =3  Y  Sa ",
      "  m  S=4 !u   a ",
      "  mmmmmmmmmmmmb ",
      "              c ",
      "              c ",
      "              c ",
      "                "
    ],
    [
      "                ",
      " cjaaaaaaaaaaaa ",
      "  m   (=& ^=nha ",
      "  m   )=   = #a ",
      "  m   +=*===  a ",
      "  m   7    %  a ",
      "  m   jjjju=$=a ",
      "  m   =^& =   a ",
      "  m   =jjj=   a ",
      "  m   =   Y   a ",
      "  m   =   u   a ",
      "  mmmmmmmmmmmmb ",
      "              c ",
      "              c ",
      "              c ",
      "                "
    ],
    [
      "                ",
      " cjaaaaaaaaaaaa ",
      "  m   !=   =  a ",
      "  m   ]=   = da ",
      "  m   {===== #a ",
      "  m   }    =  a ",
      "  m   jjjj ===a ",
      "  m   =   =   a ",
      "  m   =jjj=   a ",
      "  m   =   -   a ",
      "  m   =   [   a ",
      "  mmmmmmmmmmmmb ",
      "              c ",
      "              c ",
      "              c ",
      "                "
    ],
    [
      "                ",
      " cjaaaaaaaaaaaa ",
      "  ;||||||||=  a ",
      "  ;||||||||=  a ",
      "  ;||||||||= da ",
      "  ;||||||||=R#a ",
      "  ;|||||||:===a ",
      "  ;|||||||||||a ",
      "  ;|||||||||||a ",
      "  ;|||||||||||a ",
      "  ;|||||||||||a ",
      "  ;;;;;;;;;;;;b ",
      "              c ",
      "              c ",
      "              c ",
      "                "
    ]
  ]
}