{
  "name": "building_hotela_floor2_270",
  "refpalette": "deceasedcraft:building_hotela/building_hotela_floor2_palette_270",
  "xsize": 16,
  "zsize": 16,
  "slices": [
    [
      "                ",
      " cjaaaaaaaaaaaa ",
      "  feeee=!ii=  a ",
      "  feeee=iii=  a ",
      "  feeee=e===g a ",
      "  feeeeeeeehhda ",
      "  feeeeeeee=h=a ",
      "  feee=iii=eeea ",
      "  feee=iii=eeea ",
      "  feee=eeeeeeea ",
      "  feee=eeeeeeea ",
      "  ffffffffffffb ",
      "              c ",
      "              c ",
      "              c ",
      "                "
    ],
    [
      "                ",
      " cjaaaaaaaaaaaa ",
      "  n ONJ=Byt=  a ",
      "  nP  K=  u=g a ",
      "  nQ  L=C===o a ",
      "  nR  M    s  a ",
      "  n   jjjjw=p=a ",
      "  nrrm= By=  ka ",
      "  nrql=jDj=rqla ",
      "  nrql=F  xrrma ",
      "  nrrm=IEAwrqla ",
      "  nnnnnnnnnnnnb ",
      "              c ",
      "              c ",
      "              c ",
      "                "
    ],
    [
      "                ",
      " cjaaaaaaaaaaaa ",
      "  n  96=  YVgSa ",
      "  n    =1  Vo a ",
      "  n   7=2===  a ",
      "  n   84   W  a ",
      "  n   jjjjw=U=a ",
      "  n  #bY  =X  a ",
      "  n   =j3j=   a ",
      "  n   =   Z  Ta ",
      "  n  #=5 0w   a ",
      "  nnnnnnnnnnnnb ",
      "              c ",
      "              c ",
      "              c ",
      "                "
    ],
    [
      "                ",
      " cjaaaaaaaaaaaa ",
      "  n   )=* &=oha ",
      "  n   +=   = $a ",
      "  n   -=(===  a ",
      "  n   8    ^  a ",
      "  n   jjjjw=%=a ",
      "  n   =&* =   a ",
      "  n   =jjj=   a ",
      "  n   =   Z   a ",
      "  n   =   w   a ",
      "  nnnnnnnnnnnnb ",
      "              c ",
      "              c ",
      "              c ",
      "                "
    ],
    [
      "                ",
      " cjaaaaaaaaaaaa ",
      "  n   {=   =  a ",
      "  n   }=   = da ",
      "  n    ===== $a ",
      "  n   |    =  a ",
      "  n   jjjj ===a ",
      "  n   =   =   a ",
      "  n   =jjj=   a ",
      "  n   =   [   a ",
      "  n   =   ]   a ",
      "  nnnnnnnnnnnnb ",
      "              c ",
      "              c ",
      "              c ",
      "                "
    ],
    [
      "                ",
      " cjaaaaaaaaaaaa ",
      "  :;;;';;;;=  a ",
      "  :;;;;;;;;=  a ",
      "  :;;;;;;;;= da ",
      "  :;;;;;;;;=S$a ",
      "  :;;;;;;;;===a ",
      "  :;;;;;;;;;;;a ",
      "  :;;;;;;;;;;;a ",
      "  :;;;;;;;;;;;a ",
      "  :;;;;;;;;;;;a ",
      "  ::::::::::::b ",
      "              c ",
      "              c ",
      "              c ",
      "                "
    ]
  ]
}