{
  "name": "building_hotela_top_270",
  "refpalette": "deceasedcraft:building_hotela/building_hotela_top_palette_270",
  "xsize": 16,
  "zsize": 16,
  "slices": [
    [
      "                ",
      " cjaaaaaaaaaaaa ",
      "  feeee=iii=  a ",
      "  feeeeeiii=  a ",
      "  feeee=e===g a ",
      "  feeeeeeeehhda ",
      "  fee=eeeee===a ",
      "  feeee=eeeeeea ",
      "  feeee=eeeeeea ",
      "  feeee=eeeeeea ",
      "  feeee=eeeeeea ",
      "  ffffffffffffb ",
      "              c ",
      "              c ",
      "              c ",
      "                "
    ],
    [
      "                ",
      " cjaaaaaaaaaaaa ",
      "  lQPMJ=DBw=  a ",
      "  lR N I  x=  a ",
      "  ljjj =E===m a ",
      "  lS q     q  a ",
      "  lT =jj yy===a ",
      "  l ssK= Crrnka ",
      "  lUsOL= ssso a ",
      "  lVsOL=FsAtp a ",
      "  lWssK=FsAup a ",
      "  llllllllllllb ",
      "              c ",
      "              c ",
      "              c ",
      "                "
    ],
    [
      "                ",
      " cjaaaaaaaaaaaa ",
      "  l ^%!=  30  a ",
      "  l    9 4 0  a ",
      "  ljjj =7===  a ",
      "  l& 1   5 1  a ",
      "  l  =jj   ===a ",
      "  l   #= 6 2 Xa ",
      "  l    =      a ",
      "  l*   =8   Y a ",
      "  l   $=8   Z a ",
      "  llllllllllllb ",
      "              c ",
      "              c ",
      "              c ",
      "                "
    ],
    [
      "                ",
      " cjaaaaaaaaaaaa ",
      "  l    =% +=  a ",
      "  l    ]  -=  a ",
      "  ljjjj=[===  a ",
      "  l  {     )  a ",
      "  l  =jj   ===a ",
      "  l    =     (a ",
      "  l    =      a ",
      "  l    =      a ",
      "  l    =      a ",
      "  llllllllllllb ",
      "              c ",
      "              c ",
      "              c ",
      "                "
    ],
    [
      "                ",
      " cjaaaaaaaaaaaa ",
      "  l    =   =  a ",
      "  l    =   =  a ",
      "  ljjjj=====  a ",
      "  l  =     =  a ",
      "  l  =jj   ===a ",
      "  l    =      a ",
      "  l    =      a ",
      "  l    =      a ",
      "  l    =      a ",
      "  llllllllllllb ",
      "              c ",
      "              c ",
      "              c ",
      "                "
    ],
    [
      "                ",
      " cjaaaaaaaaaaaa ",
      "  ;|   =   =  a ",
      "  ;|   =   =  a ",
      "  ;|jjj=====  a ",
      "  ;|}=     =  a ",
      "  ;|}=jj   ===a ",
      "  ;|}  =      a ",
      "  ;|}  =      a ",
      "  ;|}}}=}}}}}}a ",
      "  ;|||||||||||a ",
      "  ;;;;;;;;;;;;b ",
      "              c ",
      "              c ",
      "              c ",
      "                "
    ],
    [
      "                ",
      " cjaaaaaaaaaaaa ",
      "  f|||||||||||a ",
      "  f|||||||||||a ",
      "  f|||||||||||a ",
      "  f|||||||||||a ",
      "  f|||||||||||a ",
      "  f|||||||||||a ",
      "  f|||||||||||a ",
      "  f|||||||||||a ",
      "  f|||||||||||a ",
      "  ffffffffffffb ",
      "              c ",
      "              c ",
      "              c ",
      "                "
    ],
    [
      "                ",
      " c aaaaaaaaaaaa ",
      " c<.::::::::::a ",
      " c<a>:>>>:>>>:a ",
      " c<a>:>>>:>>>:a ",
      " c<a>:>>>:>>>:a ",
      " c<a>:>>>:>>>:a ",
      " c<a>,,>>,,>>:a ",
      " c<a>,,>>,,>>:a ",
      " c<a>>>>>>>>>:a ",
      " c<aaaaaaaaaa'a ",
      " c<<<<<<<<<<<<  ",
      " cccccccccccccc ",
      " cccccccccccccc ",
      " cccccccccccccc ",
      "                "
    ],
    [
      "                ",
      "   ???????????? ",
      "   ?          ? ",
      "   ?          ? ",
      "   ?          ? ",
      "   ?          ? ",
      "   ?          ? ",
      "   ? `/  //   ? ",
      "   ? //  /`   ? ",
      "   ?          ? ",
      "   ???????????? ",
      "                ",
      "                ",
      "                ",
      "                ",
      "                "
    ]
  ]
}