{
  "name": "building_hotela_top_180",
  "refpalette": "deceasedcraft:building_hotela/building_hotela_top_palette_180",
  "xsize": 16,
  "zsize": 16,
  "slices": [
    [
      "                ",
      "              c ",
      "    ffffffffffj ",
      "    feeeeeeeeea ",
      "    feeeeeeeeea ",
      "    feeee=eeeea ",
      "    feeeeeeeeea ",
      "    f====ee=e=a ",
      "    feeeeeeeiia ",
      "    feeeeee=iia ",
      "    feeeeee=iia ",
      "    feeee=h===a ",
      "    feeee=hg  a ",
      "    feeee=d   a ",
      " cccbaaaaaaaaaa ",
      "                "
    ],
    [
      "                ",
      "              c ",
      "    llllllllllj ",
      "    lWVU TSjRQa ",
      "    lssss  j Pa ",
      "    lsOOs=qjNMa ",
      "    lKLLKj   Ja ",
      "    l====j =I=a ",
      "    lFF    E Da ",
      "    lsssCy = Ba ",
      "    lAAsry =xwa ",
      "    lutsr=q===a ",
      "    lppon= m  a ",
      "    l   k=    a ",
      " cccbaaaaaaaaaa ",
      "                "
    ],
    [
      "                ",
      "              c ",
      "    llllllllllj ",
      "    l *   &j  a ",
      "    l      j ^a ",
      "    l    =1j %a ",
      "    l$  #j   !a ",
      "    l====j =9=a ",
      "    l88    7  a ",
      "    l   6 5=4 a ",
      "    l      = 3a ",
      "    l   2=1=00a ",
      "    lZY  =    a ",
      "    l   X=    a ",
      " cccbaaaaaaaaaa ",
      "                "
    ],
    [
      "                ",
      "              c ",
      "    llllllllllj ",
      "    l      j  a ",
      "    l      j  a ",
      "    l    ={j  a ",
      "    l    j j  a ",
      "    l====j =]=a ",
      "    l      [ %a ",
      "    l      =  a ",
      "    l      =-+a ",
      "    l    =)===a ",
      "    l    =    a ",
      "    l   (=    a ",
      " cccbaaaaaaaaaa ",
      "                "
    ],
    [
      "                ",
      "              c ",
      "    llllllllllj ",
      "    l      j  a ",
      "    l      j  a ",
      "    l    ==j  a ",
      "    l    j j  a ",
      "    l====j ===a ",
      "    l      =  a ",
      "    l      =  a ",
      "    l      =  a ",
      "    l    =====a ",
      "    l    =    a ",
      "    l    =    a ",
      " cccbaaaaaaaaaa ",
      "                "
    ],
    [
      "                ",
      "              c ",
      "    ;;;;;;;;;;j ",
      "    ;|||||||||a ",
      "    ;|}}}}}j  a ",
      "    ;|}  ==j  a ",
      "    ;|}  j j  a ",
      "    ;|===j ===a ",
      "    ;|}    =  a ",
      "    ;|}    =  a ",
      "    ;|}    =  a ",
      "    ;|}  =====a ",
      "    ;|}  =    a ",
      "    ;|}  =    a ",
      " cccbaaaaaaaaaa ",
      "                "
    ],
    [
      "                ",
      "              c ",
      "    ffffffffffj ",
      "    f|||||||||a ",
      "    f|||||||||a ",
      "    f|||||||||a ",
      "    f|||||||||a ",
      "    f|||||||||a ",
      "    f|||||||||a ",
      "    f|||||||||a ",
      "    f|||||||||a ",
      "    f|||||||||a ",
      "    f|||||||||a ",
      "    f|||||||||a ",
      " cccbaaaaaaaaaa ",
      "                "
    ],
    [
      "                ",
      " cccccccccccccc ",
      " ccc<<<<<<<<<<  ",
      " ccc<aaaaaaaa.a ",
      " ccc<a>>>>>>>:a ",
      " ccc<a>,,:::::a ",
      " ccc<a>,,>>>>:a ",
      " ccc<a>>>>>>>:a ",
      " ccc<a>>>>>>>:a ",
      " ccc<a>,,:::::a ",
      " ccc<a>,,>>>>:a ",
      " ccc<a>>>>>>>:a ",
      " ccc<a>>>>>>>:a ",
      " ccc<'::::::::a ",
      " ccc aaaaaaaaaa ",
      "                "
    ],
    [
      "                ",
      "                ",
      "                ",
      "     ?????????? ",
      "     ?        ? ",
      "     ? /`     ? ",
      "     ? //     ? ",
      "     ?        ? ",
      "     ?        ? ",
      "     ? //     ? ",
      "     ? `/     ? ",
      "     ?        ? ",
      "     ?        ? ",
      "     ?        ? ",
      "     ?????????? ",
      "                "
    ]
  ]
}