{
  "name": "building_hotela_floor2_180",
  "refpalette": "deceasedcraft:building_hotela/building_hotela_floor2_palette_180",
  "xsize": 16,
  "zsize": 16,
  "slices": [
    [
      "                ",
      "              c ",
      "    ffffffffffj ",
      "    feeeeeeeeea ",
      "    feeeeeeeeea ",
      "    feeeeeeeeea ",
      "    f====eeeeea ",
      "    feeiiee===a ",
      "    feeiieeei!a ",
      "    feeiiee=iia ",
      "    fee==ee=iia ",
      "    feeee=h===a ",
      "    feeeehhg  a ",
      "    feeee=d   a ",
      " cccbaaaaaaaaaa ",
      "                "
    ],
    [
      "                ",
      "              c ",
      "    nnnnnnnnnnj ",
      "    nrrrr RQP a ",
      "    nrqqr    Oa ",
      "    nmllm    Na ",
      "    n====jMLKJa ",
      "    nIFj j ===a ",
      "    nE DBj C Ba ",
      "    nA jyj = ya ",
      "    nwx==w =uta ",
      "    nrrr =s===a ",
      "    nqrq p og a ",
      "    nlmlk=    a ",
      " cccbaaaaaaaaaa ",
      "                "
    ],
    [
      "                ",
      "              c ",
      "    nnnnnnnnnnj ",
      "    n         a ",
      "    n         a ",
      "    n#  #    9a ",
      "    n===bj87 6a ",
      "    n5 jYj4===a ",
      "    n  3 j 21 a ",
      "    n0 j j =  a ",
      "    nwZ==w = Ya ",
      "    n   X=W=VVa ",
      "    n    U  oga ",
      "    n T  =   Sa ",
      " cccbaaaaaaaaaa ",
      "                "
    ],
    [
      "                ",
      "              c ",
      "    nnnnnnnnnnj ",
      "    n         a ",
      "    n         a ",
      "    n         a ",
      "    n====j8-+)a ",
      "    n  j&j ===a ",
      "    n  j*j ( *a ",
      "    n  j j =  a ",
      "    nwZ==w = &a ",
      "    n    =^===a ",
      "    n    %   oa ",
      "    n    =  $ha ",
      " cccbaaaaaaaaaa ",
      "                "
    ],
    [
      "                ",
      "              c ",
      "    nnnnnnnnnnj ",
      "    n         a ",
      "    n         a ",
      "    n         a ",
      "    n====j| }{a ",
      "    n  j j ===a ",
      "    n  j j =  a ",
      "    n  j j =  a ",
      "    n][==  =  a ",
      "    n    =====a ",
      "    n    =    a ",
      "    n    = $d a ",
      " cccbaaaaaaaaaa ",
      "                "
    ],
    [
      "                ",
      "              c ",
      "    ::::::::::j ",
      "    :;;;;;;;;;a ",
      "    :;;;;;;;;;a ",
      "    :;;;;;;;;;a ",
      "    :;;;;;;;;'a ",
      "    :;;;;;;;;;a ",
      "    :;;;;;;;;;a ",
      "    :;;;;;;;;;a ",
      "    :;;;;;;;;;a ",
      "    :;;;;=====a ",
      "    :;;;;=S   a ",
      "    :;;;;=$d  a ",
      " cccbaaaaaaaaaa ",
      "                "
    ]
  ]
}