{
  "name": "building_hotela_base1_270",
  "refpalette": "deceasedcraft:building_hotela/building_hotela_base1_palette_270",
  "xsize": 16,
  "zsize": 16,
  "slices": [
    [
      "vvvvvvvvvvvvvvvv",
      "vammmmmmmmmaaaav",
      "van   n r n=gbav",
      "van A n s n=h av",
      "van B n   n=icav",
      "va         =j av",
      "va            av",
      "va            av",
      "va            av",
      "vaxxxxx   ddddav",
      "vaIECym teeeeeav",
      "vaJ           av",
      "vaJ       o   av",
      "vaKFD mwuqplkfav",
      "vaaaaaaaaaaaaaav",
      "vvvvvvvvvvvvvvvv"
    ],
    [
      "vvvvvvvvvvvvvvvv",
      "vammmmmmmmmaaaav",
      "va         = Lav",
      "va         =  av",
      "va         =jMav",
      "va         =  av",
      "va            av",
      "va            av",
      "va            av",
      "vaxxxxx       av",
      "va   Lm       av",
      "va            av",
      "va            av",
      "va QQ mwu P ONav",
      "vaaaaaaaaaaaaaav",
      "vvvvvvvvvvvvvvvv"
    ],
    [
      "vvvvvvvvvvvvvvvv",
      "vammmmmmmmmaaaav",
      "va         =iiav",
      "va         =jiav",
      "va         =  av",
      "va  W   U  =  av",
      "va            av",
      "va            av",
      "va            av",
      "vaxxxxx V     av",
      "va    m       av",
      "va    m       av",
      "va    m  R RRRav",
      "va    mwuSTTTSav",
      "vaaaaaaaaaaaaaav",
      "vvvvvvvvvvvvvvvv"
    ],
    [
      "vvvvvvvvvvvvvvvv",
      "vammmmmmmmmaaaav",
      "va         =jiav",
      "va         = iav",
      "va         =  av",
      "va  1   0  =  av",
      "va            av",
      "va            av",
      "va            av",
      "vaxxxxx 1     av",
      "va2222m       av",
      "va2222m       av",
      "va2222m  RRRRRav",
      "va3223mwuZYXX!av",
      "vaaaaaaaaaaaaaav",
      "vvvvvvvvvvvvvvvv"
    ],
    [
      "vvvvvvvvvvvvvvvv",
      "vammmmmmmmmaaaav",
      "va777777777=  av",
      "va777777777= 4av",
      "va777777777= 5av",
      "va778777877=  av",
      "va977777777776av",
      "va977777777776av",
      "va977777777776av",
      "vaxxxxx9877776av",
      "va####m9777776av",
      "va#$ #m9777776av",
      "va#$ #m9777776av",
      "va# $#muuuuuuuav",
      "vaaaaaaaaaaaaaav",
      "vvvvvvvvvvvvvvvv"
    ],
    [
      "vvvvvvvvvvvvvvvv",
      "vammmmmmmmmaaaav",
      "vauuuuuuuuu=  av",
      "vauuuuuuuuu=  av",
      "vauuuuuuuuu= 4av",
      "vauuuuuuuuu=%5av",
      "vauuuuuuuuuuuuav",
      "vauuuuuuuuuuuuav",
      "vauuuuuuuuuuuuav",
      "vauuuuuuuuuuuuav",
      "va^^^^uuuuuuuuav",
      "va^^^^uuuuuuuuav",
      "va^^^^uuuuuuuuav",
      "va^^^^uuuuuuuuav",
      "vaaaaaaaaaaaaaav",
      "vvvvvvvvvvvvvvvv"
    ]
  ]
}