{
  "name": "building_hotela_top_90",
  "refpalette": "deceasedcraft:building_hotela/building_hotela_top_palette_90",
  "xsize": 16,
  "zsize": 16,
  "slices": [
    [
      "                ",
      " c              ",
      " c              ",
      " c              ",
      " bffffffffffff  ",
      " aeeeeee=eeeef  ",
      " aeeeeee=eeeef  ",
      " aeeeeee=eeeef  ",
      " aeeeeee=eeeef  ",
      " a===eeeee=eef  ",
      " adhheeeeeeeef  ",
      " a g===e=eeeef  ",
      " a  =iiieeeeef  ",
      " a  =iii=eeeef  ",
      " aaaaaaaaaaaajc ",
      "                "
    ],
    [
      "                ",
      " c              ",
      " c              ",
      " c              ",
      " bllllllllllll  ",
      " a puAsF=KssWl  ",
      " a ptAsF=LOsVl  ",
      " a osss =LOsUl  ",
      " aknrrC =Kss l  ",
      " a===yy jj= Tl  ",
      " a  q     q Sl  ",
      " a m===E= jjjl  ",
      " a  =x  I N Rl  ",
      " a  =wBD=JMPQl  ",
      " aaaaaaaaaaaajc ",
      "                "
    ],
    [
      "                ",
      " c              ",
      " c              ",
      " c              ",
      " bllllllllllll  ",
      " a Z   8=$   l  ",
      " a Y   8=   *l  ",
      " a      =    l  ",
      " aX 2 6 =#   l  ",
      " a===   jj=  l  ",
      " a  1 5   1 &l  ",
      " a  ===7= jjjl  ",
      " a  0 4 9    l  ",
      " a  03  =!%^ l  ",
      " aaaaaaaaaaaajc ",
      "                "
    ],
    [
      "                ",
      " c              ",
      " c              ",
      " c              ",
      " bllllllllllll  ",
      " a      =    l  ",
      " a      =    l  ",
      " a      =    l  ",
      " a(     =    l  ",
      " a===   jj=  l  ",
      " a  )     {  l  ",
      " a  ===[=jjjjl  ",
      " a  =-  ]    l  ",
      " a  =+ %=    l  ",
      " aaaaaaaaaaaajc ",
      "                "
    ],
    [
      "                ",
      " c              ",
      " c              ",
      " c              ",
      " bllllllllllll  ",
      " a      =    l  ",
      " a      =    l  ",
      " a      =    l  ",
      " a      =    l  ",
      " a===   jj=  l  ",
      " a  =     =  l  ",
      " a  =====jjjjl  ",
      " a  =   =    l  ",
      " a  =   =    l  ",
      " aaaaaaaaaaaajc ",
      "                "
    ],
    [
      "                ",
      " c              ",
      " c              ",
      " c              ",
      " b;;;;;;;;;;;;  ",
      " a|||||||||||;  ",
      " a}}}}}}=}}}|;  ",
      " a      =  }|;  ",
      " a      =  }|;  ",
      " a===   jj=}|;  ",
      " a  =     =}|;  ",
      " a  =====jjj|;  ",
      " a  =   =   |;  ",
      " a  =   =   |;  ",
      " aaaaaaaaaaaajc ",
      "                "
    ],
    [
      "                ",
      " c              ",
      " c              ",
      " c              ",
      " bffffffffffff  ",
      " a|||||||||||f  ",
      " a|||||||||||f  ",
      " a|||||||||||f  ",
      " a|||||||||||f  ",
      " a|||||||||||f  ",
      " a|||||||||||f  ",
      " a|||||||||||f  ",
      " a|||||||||||f  ",
      " a|||||||||||f  ",
      " aaaaaaaaaaaajc ",
      "                "
    ],
    [
      "                ",
      " cccccccccccccc ",
      " cccccccccccccc ",
      " cccccccccccccc ",
      "  <<<<<<<<<<<<c ",
      " a'aaaaaaaaaa<c ",
      " a:>>>>>>>>>a<c ",
      " a:>>,,>>,,>a<c ",
      " a:>>,,>>,,>a<c ",
      " a:>>>:>>>:>a<c ",
      " a:>>>:>>>:>a<c ",
      " a:>>>:>>>:>a<c ",
      " a:>>>:>>>:>a<c ",
      " a::::::::::.<c ",
      " aaaaaaaaaaaa c ",
      "                "
    ],
    [
      "                ",
      "                ",
      "                ",
      "                ",
      "                ",
      " ????????????   ",
      " ?          ?   ",
      " ?   `/  // ?   ",
      " ?   //  /` ?   ",
      " ?          ?   ",
      " ?          ?   ",
      " ?          ?   ",
      " ?          ?   ",
      " ?          ?   ",
      " ????????????   ",
      "                "
    ]
  ]
}