{
  "name": "building_hotela_base1_180",
  "refpalette": "deceasedcraft:building_hotela/building_hotela_base1_palette_180",
  "xsize": 16,
  "zsize": 16,
  "slices": [
    [
      "vvvvvvvvvvvvvvvv",
      "vaaaaaaaaaaaaaav",
      "vaKJJIx    nnnmv",
      "vaF  Ex       mv",
      "vaD  Cx    BA mv",
      "va   yx       mv",
      "vam  mx    nnnmv",
      "vaw           mv",
      "vau  t      srmv",
      "vaq  e        mv",
      "vapo ed    nnnmv",
      "val  ed   ====av",
      "vak  ed   jihgav",
      "vaf  ed    c bav",
      "vaaaaaaaaaaaaaav",
      "vvvvvvvvvvvvvvvv"
    ],
    [
      "vvvvvvvvvvvvvvvv",
      "vaaaaaaaaaaaaaav",
      "va    x       mv",
      "vaQ   x       mv",
      "vaQ   x       mv",
      "va   Lx       mv",
      "vam  mx       mv",
      "vaw           mv",
      "vau           mv",
      "va            mv",
      "vaP           mv",
      "va        ====av",
      "vaO        j  av",
      "vaN        M Lav",
      "vaaaaaaaaaaaaaav",
      "vvvvvvvvvvvvvvvv"
    ],
    [
      "vvvvvvvvvvvvvvvv",
      "vaaaaaaaaaaaaaav",
      "va    x       mv",
      "va    x       mv",
      "va    x   W   mv",
      "va    x       mv",
      "vammmmx       mv",
      "vaw           mv",
      "vau   V   U   mv",
      "vaSR          mv",
      "vaT           mv",
      "vaTR      ====av",
      "vaTR        jiav",
      "vaSR        iiav",
      "vaaaaaaaaaaaaaav",
      "vvvvvvvvvvvvvvvv"
    ],
    [
      "vvvvvvvvvvvvvvvv",
      "vaaaaaaaaaaaaaav",
      "va3222x       mv",
      "va2222x       mv",
      "va2222x   1   mv",
      "va3222x       mv",
      "vammmmx       mv",
      "vaw           mv",
      "vau   1   0   mv",
      "vaZR          mv",
      "vaYR          mv",
      "vaXR      ====av",
      "vaXR         jav",
      "va!R        iiav",
      "vaaaaaaaaaaaaaav",
      "vvvvvvvvvvvvvvvv"
    ],
    [
      "vvvvvvvvvvvvvvvv",
      "vaaaaaaaaaaaaaav",
      "va####x9997777mv",
      "va $$#x7777777mv",
      "va$  #x7778777mv",
      "va####x7777777mv",
      "vammmmx7777777mv",
      "vau99997777777mv",
      "vau77787778777mv",
      "vau77777777777mv",
      "vau77777777777mv",
      "vau7777777====av",
      "vau7777777    av",
      "vau6666666 54 av",
      "vaaaaaaaaaaaaaav",
      "vvvvvvvvvvvvvvvv"
    ],
    [
      "vvvvvvvvvvvvvvvv",
      "vaaaaaaaaaaaaaav",
      "va^^^^uuuuuuuumv",
      "va^^^^uuuuuuuumv",
      "va^^^^uuuuuuuumv",
      "va^^^^uuuuuuuumv",
      "vauuuuuuuuuuuumv",
      "vauuuuuuuuuuuumv",
      "vauuuuuuuuuuuumv",
      "vauuuuuuuuuuuumv",
      "vauuuuuuuuuuuumv",
      "vauuuuuuuu====av",
      "vauuuuuuuu%   av",
      "vauuuuuuuu54  av",
      "vaaaaaaaaaaaaaav",
      "vvvvvvvvvvvvvvvv"
    ]
  ]
}