{
  "name": "building_hotela_floor1",
  "refpalette": "deceasedcraft:building_hotela/building_hotela_floor1_palette",
  "xsize": 16,
  "zsize": 16,
  "slices": [
    [
      "                ",
      " aaaaaaaaaabccc ",
      " a   deeeeef    ",
      " a  gheeieef    ",
      " a====ee!eef    ",
      " aeeeeeeieef    ",
      " aeeeeeeeeef    ",
      " aeeeeeeeeef    ",
      " aeeeeeeeeef    ",
      " aeeeeeeeeef    ",
      " aeeeeeeeeef    ",
      " aeeeeeee!ef    ",
      " aeeeeeeeeef    ",
      " jffffffffff    ",
      " c              ",
      "                "
    ],
    [
      "                ",
      " aaaaaaaaaabccc ",
      " a     kkk l    ",
      " a gm  knkol    ",
      " a=ppp knkql    ",
      " ar    knksl    ",
      " at    kkk l    ",
      " au        l    ",
      " a         l    ",
      " a w  w  w l    ",
      " a w  w  w l    ",
      " a xy xA xBl    ",
      " a         l    ",
      " jllllllllll    ",
      " c              ",
      "                "
    ],
    [
      "                ",
      " aaaaaaaaaabccc ",
      " aC        l    ",
      " agm       l    ",
      " a=DDD     l    ",
      " ar        l    ",
      " at        l    ",
      " aEF  FF F l    ",
      " a         l    ",
      " a         l    ",
      " a         l    ",
      " a         l    ",
      " a         l    ",
      " jllllllllll    ",
      " c              ",
      "                "
    ],
    [
      "                ",
      " aaaaaaaaaabccc ",
      " ahI    JK l    ",
      " am        l    ",
      " a=DDD     l    ",
      " ar        l    ",
      " at        l    ",
      " aEFF FFFFFl    ",
      " a         l    ",
      " a         l    ",
      " a         l    ",
      " a         l    ",
      " a         l    ",
      " jllllllllll    ",
      " c              ",
      "                "
    ],
    [
      "                ",
      " aaaaaaaaaabccc ",
      " a dI      l    ",
      " a         l    ",
      " a=LLL     l    ",
      " aM        l    ",
      " aN        l    ",
      " aOPPPPPPPPl    ",
      " a         l    ",
      " a         l    ",
      " a         l    ",
      " a         l    ",
      " a         l    ",
      " jllllllllll    ",
      " c              ",
      "                "
    ],
    [
      "                ",
      " aaaaaaaaaabccc ",
      " a  dI=QQQQw    ",
      " a   C=QQQQw    ",
      " a=====QQQQw    ",
      " aQQQQQQQQQw    ",
      " aRQQQQQQQQw    ",
      " aQQQQQQQQQw    ",
      " aQQQQQQQQQw    ",
      " aQQQQQQQQQw    ",
      " aQQQQQQQQQw    ",
      " aQQQQQQQQQw    ",
      " aQQQQQQQQQw    ",
      " jwwwwwwwwww    ",
      " c              ",
      "                "
    ]
  ]
}