{
  "name": "building_hotela_floor1_270",
  "refpalette": "deceasedcraft:building_hotela/building_hotela_floor1_palette_270",
  "xsize": 16,
  "zsize": 16,
  "slices": [
    [
      "                ",
      " cjaaaaaaaaaaaa ",
      "  feeeeeeee=  a ",
      "  feeeeeeee=  a ",
      "  feeeeeeee=g a ",
      "  feeeeeeee=hda ",
      "  feeeeeeeeeeea ",
      "  feeeeeeeeeeea ",
      "  feeeeeeei!iea ",
      "  fe!eeeeeeeeea ",
      "  feeeeeeeeeeea ",
      "  ffffffffffffb ",
      "              c ",
      "              c ",
      "              c ",
      "                "
    ],
    [
      "                ",
      " cjaaaaaaaaaaaa ",
      "  l     utr=  a ",
      "  l xww    pg a ",
      "  l y      pm a ",
      "  l        p  a ",
      "  l xww       a ",
      "  l A    kkkkka ",
      "  l      knnnka ",
      "  l xww  kkkkka ",
      "  l B     sqo a ",
      "  llllllllllllb ",
      "              c ",
      "              c ",
      "              c ",
      "                "
    ],
    [
      "                ",
      " cjaaaaaaaaaaaa ",
      "  l     Etr=gCa ",
      "  l     F  Dm a ",
      "  l        D  a ",
      "  l        D  a ",
      "  l     F     a ",
      "  l     F     a ",
      "  l           a ",
      "  l     F     a ",
      "  l           a ",
      "  llllllllllllb ",
      "              c ",
      "              c ",
      "              c ",
      "                "
    ],
    [
      "                ",
      " cjaaaaaaaaaaaa ",
      "  l     Etr=mha ",
      "  l     F  D Ia ",
      "  l     F  D  a ",
      "  l        D  a ",
      "  l     F     a ",
      "  l     F     a ",
      "  l     F    Ja ",
      "  l     F    Ka ",
      "  l     F     a ",
      "  llllllllllllb ",
      "              c ",
      "              c ",
      "              c ",
      "                "
    ],
    [
      "                ",
      " cjaaaaaaaaaaaa ",
      "  l     ONM=  a ",
      "  l     P  L da ",
      "  l     P  L Ia ",
      "  l     P  L  a ",
      "  l     P     a ",
      "  l     P     a ",
      "  l     P     a ",
      "  l     P     a ",
      "  l     P     a ",
      "  llllllllllllb ",
      "              c ",
      "              c ",
      "              c ",
      "                "
    ],
    [
      "                ",
      " cjaaaaaaaaaaaa ",
      "  wQQQQQQRQ=  a ",
      "  wQQQQQQQQ=  a ",
      "  wQQQQQQQQ= da ",
      "  wQQQQQQQQ=CIa ",
      "  wQQQQQQQQ===a ",
      "  wQQQQQQQQQQQa ",
      "  wQQQQQQQQQQQa ",
      "  wQQQQQQQQQQQa ",
      "  wQQQQQQQQQQQa ",
      "  wwwwwwwwwwwwb ",
      "              c ",
      "              c ",
      "              c ",
      "                "
    ]
  ]
}