{
  "name": "building_hotela_floor2",
  "refpalette": "deceasedcraft:building_hotela/building_hotela_floor2_palette",
  "xsize": 16,
  "zsize": 16,
  "slices": [
    [
      "                ",
      " aaaaaaaaaabccc ",
      " a   d=eeeef    ",
      " a  ghheeeef    ",
      " a===h=eeeef    ",
      " aii=ee==eef    ",
      " aii=eeiieef    ",
      " a!ieeeiieef    ",
      " a===eeiieef    ",
      " aeeeee====f    ",
      " aeeeeeeeeef    ",
      " aeeeeeeeeef    ",
      " aeeeeeeeeef    ",
      " jffffffffff    ",
      " c              ",
      "                "
    ],
    [
      "                ",
      " aaaaaaaaaabccc ",
      " a    =klmln    ",
      " a go p qrqn    ",
      " a===s= rrrn    ",
      " atu= w==xwn    ",
      " ay = jyj An    ",
      " aB C jBD En    ",
      " a=== j jFIn    ",
      " aJKLMj====n    ",
      " aN    mllmn    ",
      " aO    rqqrn    ",
      " a PQR rrrrn    ",
      " jnnnnnnnnnn    ",
      " c              ",
      "                "
    ],
    [
      "                ",
      " aaaaaaaaaabccc ",
      " aS   =  T n    ",
      " ago  U    n    ",
      " aVV=W=X   n    ",
      " aY = w==Zwn    ",
      " a  = j j 0n    ",
      " a 12 j 3  n    ",
      " a===4jYj 5n    ",
      " a6 78jb===n    ",
      " a9    #  #n    ",
      " a         n    ",
      " a         n    ",
      " jnnnnnnnnnn    ",
      " c              ",
      "                "
    ],
    [
      "                ",
      " aaaaaaaaaabccc ",
      " ah$  =    n    ",
      " ao   %    n    ",
      " a===^=    n    ",
      " a& = w==Zwn    ",
      " a  = j j  n    ",
      " a* ( j*j  n    ",
      " a=== j&j  n    ",
      " a)+-8j====n    ",
      " a         n    ",
      " a         n    ",
      " a         n    ",
      " jnnnnnnnnnn    ",
      " c              ",
      "                "
    ],
    [
      "                ",
      " aaaaaaaaaabccc ",
      " a d$ =    n    ",
      " a    =    n    ",
      " a=====    n    ",
      " a  =  ==[]n    ",
      " a  = j j  n    ",
      " a  = j j  n    ",
      " a=== j j  n    ",
      " a{} |j====n    ",
      " a         n    ",
      " a         n    ",
      " a         n    ",
      " jnnnnnnnnnn    ",
      " c              ",
      "                "
    ],
    [
      "                ",
      " aaaaaaaaaabccc ",
      " a  d$=;;;;:    ",
      " a   S=;;;;:    ",
      " a=====;;;;:    ",
      " a;;;;;;;;;:    ",
      " a;;;;;;;;;:    ",
      " a;;;;;;;;;:    ",
      " a;;;;;;;;;:    ",
      " a';;;;;;;;:    ",
      " a;;;;;;;;;:    ",
      " a;;;;;;;;;:    ",
      " a;;;;;;;;;:    ",
      " j::::::::::    ",
      " c              ",
      "                "
    ]
  ]
}