{
  "name": "building_hotela_ground_270",
  "refpalette": "deceasedcraft:building_hotela/building_hotela_ground_palette_270",
  "xsize": 16,
  "zsize": 16,
  "slices": [
    [
      "aaaaaaaaaaaaaaaa",
      "abcbbbbbbbbbbbba",
      "aafeeeeeeee=  ba",
      "iifeeeeeeee=  ba",
      "iifeeeeeeee=g ba",
      "iifeeeeeeee=hdba",
      "iifeljljljeeeeba",
      "iifemkmkmkeeeeba",
      "iifeljljljeeeeba",
      "iifemkmkmkeeeeba",
      "iifeeeeeeeeeeeba",
      "iiffffffffffffca",
      "iiiianoonaiiiaba",
      "iiiiionnoiiiiaba",
      "iiiiionnoiiiiaba",
      "iiiiinooniiiiaaa"
    ],
    [
      "                ",
      " bNpppppppppppp ",
      "  uBCCCCCCB=  p ",
      "  u  E  E  yg p ",
      "  u fFFFFf Aw p ",
      "  u  I  I  A  p ",
      "  u           p ",
      "  u           p ",
      "  u          rp ",
      "  u          sp ",
      "  u   MK     tp ",
      "  uuuJLLJuuuuuq ",
      "    D    Dxxx b ",
      "              b ",
      "              b ",
      "                "
    ],
    [
      "                ",
      " bNpppppppppppp ",
      "  uPQQQQQQP=gOp ",
      "  u        yw p ",
      "  u RW  TR y  p ",
      "  u        A  p ",
      "  u           p ",
      "  u           p ",
      "  u           p ",
      "  u           p ",
      "  u   VU     Pp ",
      "  uuuJ  Juuuuuq ",
      "    S    S    b ",
      "              b ",
      "              b ",
      "                "
    ],
    [
      "                ",
      " bNpppppppppppp ",
      "  uP      P=whp ",
      "  u        y Xp ",
      "  u        y  p ",
      "  u        A  p ",
      "  u           p ",
      "  u           p ",
      "  u   Z       p ",
      "  u           p ",
      "  u          Pp ",
      "  uuuJJJJuuuuuq ",
      "    Y    Y    b ",
      "              b ",
      "              b ",
      "                "
    ],
    [
      "                ",
      " bNpppppppppppp ",
      "  u        =  p ",
      "  u        y dp ",
      "  u        A Xp ",
      "  u        A  p ",
      "  u   11      p ",
      "  u  3ZZ0     p ",
      "  u  3ZZ0     p ",
      "  u   22      p ",
      "  u           p ",
      "  uuuuuuuuuuuuq ",
      "              b ",
      "              b ",
      "              b ",
      "                "
    ],
    [
      "                ",
      " bNpppppppppppp ",
      "  544444444=  p ",
      "  544444444=  p ",
      "  544444444= dp ",
      "  544444444=OXp ",
      "  544466444===p ",
      "  544677644444p ",
      "  544677644444p ",
      "  544466444444p ",
      "  544444444444p ",
      "  555555555555q ",
      "              b ",
      "              b ",
      "              b ",
      "                "
    ]
  ]
}