{
  "name": "building_hotela_ground_90",
  "refpalette": "deceasedcraft:building_hotela/building_hotela_ground_palette_90",
  "xsize": 16,
  "zsize": 16,
  "slices": [
    [
      "aaaiiiinooniiiii",
      "abaiiiionnoiiiii",
      "abaiiiionnoiiiii",
      "abaiiianoonaiiii",
      "acffffffffffffii",
      "abeeeeeeeeeeefii",
      "abeeeekmkmkmefii",
      "abeeeejljljlefii",
      "abeeeekmkmkmefii",
      "abeeeejljljlefii",
      "abdh=eeeeeeeefii",
      "ab g=eeeeeeeefii",
      "ab  =eeeeeeeefii",
      "ab  =eeeeeeeefaa",
      "abbbbbbbbbbbbcba",
      "aaaaaaaaaaaaaaaa"
    ],
    [
      "                ",
      " b              ",
      " b              ",
      " b xxxD    D    ",
      " quuuuuJLLJuuu  ",
      " pt     KM   u  ",
      " ps          u  ",
      " pr          u  ",
      " p           u  ",
      " p           u  ",
      " p  A  I  I  u  ",
      " p wA fFFFFf u  ",
      " p gy  E  E  u  ",
      " p  =BCCCCCCBu  ",
      " ppppppppppppNb ",
      "                "
    ],
    [
      "                ",
      " b              ",
      " b              ",
      " b    S    S    ",
      " quuuuuJ  Juuu  ",
      " pP     UV   u  ",
      " p           u  ",
      " p           u  ",
      " p           u  ",
      " p           u  ",
      " p  A        u  ",
      " p  y RT  WR u  ",
      " p wy        u  ",
      " pOg=PQQQQQQPu  ",
      " ppppppppppppNb ",
      "                "
    ],
    [
      "                ",
      " b              ",
      " b              ",
      " b    Y    Y    ",
      " quuuuuJJJJuuu  ",
      " pP          u  ",
      " p           u  ",
      " p       Z   u  ",
      " p           u  ",
      " p           u  ",
      " p  A        u  ",
      " p  y        u  ",
      " pX y        u  ",
      " phw=P      Pu  ",
      " ppppppppppppNb ",
      "                "
    ],
    [
      "                ",
      " b              ",
      " b              ",
      " b              ",
      " quuuuuuuuuuuu  ",
      " p           u  ",
      " p      22   u  ",
      " p     0ZZ3  u  ",
      " p     0ZZ3  u  ",
      " p      11   u  ",
      " p  A        u  ",
      " pX A        u  ",
      " pd y        u  ",
      " p  =        u  ",
      " ppppppppppppNb ",
      "                "
    ],
    [
      "                ",
      " b              ",
      " b              ",
      " b              ",
      " q555555555555  ",
      " p444444444445  ",
      " p444444664445  ",
      " p444446776445  ",
      " p444446776445  ",
      " p===444664445  ",
      " pXO=444444445  ",
      " pd =444444445  ",
      " p  =444444445  ",
      " p  =444444445  ",
      " ppppppppppppNb ",
      "                "
    ]
  ]
}