{
  "name": "building_hotela_floor3_90",
  "refpalette": "deceasedcraft:building_hotela/building_hotela_floor3_palette_90",
  "xsize": 16,
  "zsize": 16,
  "slices": [
    [
      "                ",
      " c              ",
      " c              ",
      " c              ",
      " bffffffffffff  ",
      " aeeeeeee=eeef  ",
      " aeeeeeee=eeef  ",
      " aeee=iii=eeef  ",
      " aeee=iii=eeef  ",
      " a=h=eeeeeeeef  ",
      " adhheeeeeeeef  ",
      " a g=kee=eeeef  ",
      " a  =jii=eeeef  ",
      " a  =iii=eeeef  ",
      " aaaaaaaaaaaalc ",
      "                "
    ],
    [
      "                ",
      " c              ",
      " c              ",
      " c              ",
      " boooooooooooo  ",
      " amrsyDJL=nsso  ",
      " anssA  K=mrso  ",
      " amrs=lIl=mrXo  ",
      " a   =BE =nUUo  ",
      " a=q=yllllRC o  ",
      " a  tx C P  Wo  ",
      " a p===F=O T o  ",
      " a g=wC =N   o  ",
      " a  =uBE=MQSVo  ",
      " aaaaaaaaaaaalc ",
      "                "
    ],
    [
      "                ",
      " c              ",
      " c              ",
      " c              ",
      " boooooooooooo  ",
      " a   y5 %=)  o  ",
      " a!  4  $=   o  ",
      " a   =l9l=   o  ",
      " a  2=  3b(  o  ",
      " a=Z=yllll   o  ",
      " a  1   #&  +o  ",
      " a  ===8=^   o  ",
      " a p0  7=    o  ",
      " aYg03 6= *  o  ",
      " aaaaaaaaaaaalc ",
      "                "
    ],
    [
      "                ",
      " c              ",
      " c              ",
      " c              ",
      " boooooooooooo  ",
      " a   y   =   o  ",
      " a   4   =   o  ",
      " a   =lll=   o  ",
      " a   = }{=   o  ",
      " a=[=yllll   o  ",
      " a  ]    &   o  ",
      " a  ===|='   o  ",
      " a- =   =:   o  ",
      " ahp={ }=;   o  ",
      " aaaaaaaaaaaalc ",
      "                "
    ],
    [
      "                ",
      " c              ",
      " c              ",
      " c              ",
      " boooooooooooo  ",
      " a   ,   =   o  ",
      " a   >   =   o  ",
      " a   =lll=   o  ",
      " a   =   =   o  ",
      " a===<llll   o  ",
      " a  =    /   o  ",
      " a- =====?   o  ",
      " ad =   =.   o  ",
      " a  =   =    o  ",
      " aaaaaaaaaaaalc ",
      "                "
    ],
    [
      "                ",
      " c              ",
      " c              ",
      " c              ",
      " b\u0370\u0370\u0370\u0370\u0370\u0370\u0370\u0370\u0370\u0370\u0370\u0370  ",
      " a```````````\u0370  ",
      " a```````````\u0370  ",
      " a```````````\u0370  ",
      " a```````````\u0370  ",
      " a===````````\u0370  ",
      " a-Y=````````\u0370  ",
      " ad =````````\u0370  ",
      " a  =````````\u0370  ",
      " a  =````````\u0370  ",
      " aaaaaaaaaaaalc ",
      "                "
    ]
  ]
}