{
  "name": "multi_apartmentmedium_0_top",
  "refpalette": "deceasedcraft:multi_apartmentmedium_0/multi_apartmentmedium_0_top_palette",
  "xsize": 16,
  "zsize": 16,
  "slices": [
    [
      "                ",
      "                ",
      "                ",
      "  aabbbbbbbbaa  ",
      "  acccccccccca  ",
      "  dcccccccccce  ",
      "  dcccccccccce  ",
      "  dcccccccccce  ",
      "  dcccccccccce  ",
      "  dccccccfccce  ",
      "  dccccccffffe  ",
      "  dccccccffffe  ",
      "  aggfggggggga  ",
      "  ahffffhi   a  ",
      "   hjfffh       ",
      "   h k lh       "
    ],
    [
      "                ",
      "                ",
      "                ",
      "  aaaaaaaaaaaa  ",
      "  amnoopgqrsma  ",
      "  a     t u wa  ",
      "  a     g  xya  ",
      "  aABCD g  xya  ",
      "  aEFII g   wa  ",
      "  aJ KK gLMgga  ",
      "  aN    O    a  ",
      "  aP   QgRST a  ",
      "  aggUggggggga  ",
      "  ah    hV   a  ",
      "   W XX h       ",
      "   Y  Z0h       "
    ],
    [
      "                ",
      "                ",
      "                ",
      "  aa12113121aa  ",
      "  a4 5  g   6a  ",
      "  1     7    1  ",
      "  2     g    2  ",
      "  2     g    2  ",
      "  2 8   g  9 2  ",
      "  2     g#Mgg2  ",
      "  2     $    2  ",
      "  1    %g  T^1  ",
      "  agg&ggggggga  ",
      "  ah  * hV   a  ",
      "   h    h       ",
      "   h  ( h       "
    ],
    [
      "                ",
      "                ",
      "                ",
      "  aa12113121aa  ",
      "  a4    g    a  ",
      "  1     )    1  ",
      "  2     g    2  ",
      "  2     g    2  ",
      "  2     g    2  ",
      "  2     g))gg2  ",
      "  2     )    2  ",
      "  1     g+  -1  ",
      "  agg)ggggggga  ",
      "  ah    hV   a  ",
      "   h    h       ",
      "   h    h       "
    ],
    [
      "                ",
      "                ",
      "                ",
      "  aaaaaaaaaaaa  ",
      "  a     g    a  ",
      "  a     g    a  ",
      "  a  [  g    a  ",
      "  a     g    a  ",
      "  a     g    a  ",
      "  a  ]  ggggga  ",
      "  a     g{{{{a  ",
      "  a     g{{{{a  ",
      "  agggggggggga  ",
      "  ah    h}   a  ",
      "   h    Y       ",
      "   h    Y       "
    ],
    [
      "                ",
      "                ",
      "                ",
      "  aa||||||||aa  ",
      "  a;;;;;g;;;;a  ",
      "  :;;;;;g;;;;'  ",
      "  :;;;;;g;;;;'  ",
      "  :;;;;;g;;;;'  ",
      "  :;;;;;g;;;;'  ",
      "  :;;;;;ggggg'  ",
      "  :;;;;;g    '  ",
      "  :;;;;;g    '  ",
      "  agggggggggga  ",
      "  ah    h<   a  ",
      "   h    h>      ",
      "   h    h>      "
    ],
    [
      "                ",
      "                ",
      "                ",
      "  aaaaaaaaaaaa  ",
      "  affffffffffa  ",
      "  affffffffffa  ",
      "  affffffffffa  ",
      "  affffffffffa  ",
      "  affffffffffa  ",
      "  affffffffffa  ",
      "  affffffffffa  ",
      "  ajjjjjjjjjja  ",
      "  agggggggggga  ",
      "  aYYYYYY    a  ",
      "   YYYYYY       ",
      "   YYYYYY       "
    ],
    [
      "                ",
      "                ",
      "                ",
      "  ,,,,,,,,,,,,  ",
      "  ,          ,  ",
      "  ,          ,  ",
      "  ,          ,  ",
      "  ,          ,  ",
      "  ,          ,  ",
      "  ,          ,  ",
      "  ,          ,  ",
      "  ,          ,  ",
      "  ,          ,  ",
      "  ,          ,  ",
      "                ",
      "                "
    ]
  ]
}