{
  "name": "multi_apartmentmedium_0_ground",
  "refpalette": "deceasedcraft:multi_apartmentmedium_0/multi_apartmentmedium_0_ground_palette",
  "xsize": 16,
  "zsize": 16,
  "slices": [
    [
      "aaaaaaaaaaaaaaaa",
      "aaaaaaaaaaaaaaaa",
      "abbbbbbbbbbbbbba",
      "abccccccccccccba",
      "abcddddddddddcba",
      "abcddddddddddcba",
      "abcddddddddddcba",
      "abcddddddddddcba",
      "abcddddddddddcba",
      "abcddddddddddcba",
      "abcddddddddddcba",
      "abcddddddddddcba",
      "abceeddeeebbecba",
      "abcfggggfbbbbcba",
      "abbfggggfbbbbbba",
      "abbfggggfbbbbbba"
    ],
    [
      "                ",
      "                ",
      "                ",
      "  cccccccccccc  ",
      "  c          c  ",
      "  c          c  ",
      "  c          c  ",
      "  c          c  ",
      "  c          c  ",
      "  c          c  ",
      "  c          c  ",
      "  c          c  ",
      "  cee  eee  ec  ",
      "  cfh  hfi   c  ",
      "   fh  hf       ",
      "   fh  hf       "
    ],
    [
      "                ",
      "                ",
      "                ",
      "  ccjkkkkkkjcc  ",
      "  c          c  ",
      "  j          j  ",
      "  k          k  ",
      "  k          k  ",
      "  k          k  ",
      "  k          k  ",
      "  k          k  ",
      "  j          j  ",
      "  cee  eee  ec  ",
      "  cfl  mfn   c  ",
      "   fl  mf       ",
      "   fl  mf       "
    ],
    [
      "                ",
      "                ",
      "                ",
      "  ccjkkkkkkjcc  ",
      "  c          c  ",
      "  j          j  ",
      "  k          k  ",
      "  k          k  ",
      "  k          k  ",
      "  k          k  ",
      "  k          k  ",
      "  j          j  ",
      "  cee  eee  ec  ",
      "  cfl  mfn   c  ",
      "   fl  mf       ",
      "   fl  mf       "
    ],
    [
      "                ",
      "                ",
      "                ",
      "  cccccccccccc  ",
      "  c          c  ",
      "  c          c  ",
      "  c          c  ",
      "  c          c  ",
      "  c          c  ",
      "  c          c  ",
      "  c          c  ",
      "  c          c  ",
      "  ceeeeeeeeeec  ",
      "  cfg   fo   c  ",
      "   fg   p       ",
      "   fg   p       "
    ],
    [
      "                ",
      "                ",
      "                ",
      "  ccqqqqqqqqcc  ",
      "  crrrrrrrrrrc  ",
      "  srrrrrrrrrrt  ",
      "  srrrrrrrrrrt  ",
      "  srrrrrrrrrrt  ",
      "  srrrrrrrrrrt  ",
      "  srrrrrrrrrrt  ",
      "  srrrrrrrrrrt  ",
      "  srrrrrrrrrrt  ",
      "  ceeeeeeeeeec  ",
      "  cfguuufw   c  ",
      "   fg  ufx      ",
      "   fyA  fx      "
    ]
  ]
}