{
  "name": "multi_hospitaldamaged_1_top",
  "refpalette": "deceasedcraft:multi_hospitaldamaged_1/multi_hospitaldamaged_1_top_palette",
  "xsize": 16,
  "zsize": 16,
  "slices": [
    [
      "     abbbbbbbbbb",
      "     cbbbbbbbbbb",
      "     dbbbbbbbbbb",
      "     abbbbbbbbbb",
      "     aebbbbbbbbb",
      "     cebbbbbbbbb",
      "     aebbbbbbbbb",
      "     deeeeeeebbb",
      "     faaacaaghhh",
      "      ijjijcghhh",
      "           aghhh",
      "           aghhh",
      "           cghhh",
      "           aghhh",
      "           agbbb",
      "           cgbbb"
    ],
    [
      "      klmn lo  p",
      "      klqrslt  u",
      "      klwxylt A ",
      "      klllBllCll",
      "      D  EF  I  ",
      "      D    JK   ",
      "      D     K  L",
      "      DDDDDLM NO",
      "           PgQRR",
      "            g   ",
      "           PgSTU",
      "           Pg VW",
      "            g   ",
      "           PgXXX",
      "           PgY  ",
      "            g Z "
    ],
    [
      "      ka0  a    ",
      "      1 2  a3   ",
      "      ka45 a   6",
      "      kaaa7aa8aD",
      "      D         ",
      "      D         ",
      "      D         ",
      "      DDDDD D   ",
      "           Pg9ii",
      "            #   ",
      "           Pg$  ",
      "           Pg% ^",
      "            #   ",
      "           Pg&&&",
      "           Pg  *",
      "            #   "
    ],
    [
      "      1    a    ",
      "      1    a(   ",
      "      1    a   )",
      "      kaaa+aa+aD",
      "      D   -  [  ",
      "      D         ",
      "      D         ",
      "      DDDDDDD   ",
      "           Pg]ii",
      "            #   ",
      "           Pg{} ",
      "           Pg| ;",
      "            #   ",
      "           Pg&&&",
      "           Pg   ",
      "            #   "
    ],
    [
      "      ka   a    ",
      "      1    a    ",
      "      ka   a    ",
      "      kaaaaaaaaa",
      "      D         ",
      "      D         ",
      "      D         ",
      "      DDD DDD   ",
      "           Pg:::",
      "            #'<<",
      "           Pg>>>",
      "           ,g:::",
      "            #'<<",
      "           Pg>>>",
      "           Pg   ",
      "            #   "
    ],
    [
      "      ka   a    ",
      "      ka   a    ",
      "      ka   a    ",
      "      kaaaaaaaaa",
      "      D         ",
      "      D         ",
      "      D         ",
      "      DDDDDDD   ",
      "           Pgiii",
      "            g.??",
      "           Pg/??",
      "           Pg/??",
      "            g.`\u0370",
      "           Pg/&&",
      "           Pg/\u0371\u0371",
      "            g/\u0371\u0371"
    ],
    [
      "     c\u0372\u0372\u0372\u0372\u0372\u0372\u0372\u0372\u0372\u0372",
      "     a\u0372\u0372\u0372\u0372\u0372\u0372\u0372\u0372\u0372\u0372",
      "     a\u0372\u0372\u0372\u0372\u0372\u0372\u0372\u0372\u0372\u0372",
      "     a\u0372\u0372\u0372\u0372\u0372\u0372\u0372\u0372\u0372\u0372",
      "     ae\u0372\u0372\u0372\u0372\u0372\u0372\u0372\u0372\u0372",
      "     ae\u0372\u0372\u0372\u0372\u0372\u0372\u0372\u0372\u0372",
      "     ce\u0372\u0372\u0372\u0372\u0372\u0372\u0372\u0372\u0372",
      "     aeeeeeeeeee",
      "     aaacaca\u0372\u0373\u0373\u0373",
      "     ji jjia\u0372\u0373\u0373\u0374",
      "           a\u0372/\u0373\u0375",
      "           c\u0372\u0373\u0373\u0374",
      "           a\u0372\u0373\u0373\u0373",
      "           a\u0372\u0373\u0373\u0373",
      "           \u0376\u0372\u0373\u0373\u0373",
      "           a\u0372\u0373\u0373\u0373"
    ],
    [
      "      \u0373    P\u0377 \u037a ",
      "      \u0373     \u0377\u037b  ",
      "      \u0373    P\u0377   ",
      "      \u0373     \u0377   ",
      "      \u0373    P\u0377   ",
      "      \u0373     \u0377 \u037c ",
      "      \u0373    P\u0377 \u037d\u037e",
      "      \u0373\u0373\u0373\u0373\u0373\u0373\u0377\u0377\u0377\u0377",
      "           P\u0373  \u037f",
      "            \u0373 \u0384\u0385",
      "            \u0373//\u0386",
      "            \u0373 \u0384\u0387",
      "            \u0373  \u0388",
      "            \u0373   ",
      "            \u0373   ",
      "            \u0373   "
    ],
    [
      "           P\u0377   ",
      "            \u0377   ",
      "           P\u0377   ",
      "            \u0377   ",
      "           P\u0377   ",
      "            \u0377   ",
      "           P\u0377   ",
      "            \u0377\u0377\u0377\u0377",
      "           P    ",
      "                ",
      "                ",
      "               \u0389",
      "                ",
      "                ",
      "                ",
      "                "
    ],
    [
      "           P\u0377   ",
      "            \u0377   ",
      "           P\u0377   ",
      "            \u0377   ",
      "           P\u0377   ",
      "            \u0377   ",
      "           P\u0377   ",
      "            \u0377\u0377\u0377\u0377",
      "           P    ",
      "                ",
      "                ",
      "                ",
      "                ",
      "                ",
      "                ",
      "                "
    ],
    [
      "           P\u0377   ",
      "            \u0377   ",
      "           P\u0377   ",
      "            \u0377   ",
      "           P\u0377   ",
      "            \u0377   ",
      "           P\u0377   ",
      "            \u0377\u0377\u0377\u0377",
      "           P    ",
      "                ",
      "                ",
      "                ",
      "                ",
      "                ",
      "                ",
      "                "
    ],
    [
      "          \u0373\u0374e\u0372\u0372\u0372",
      "          \u0373\u0374e\u0372\u0372\u0372",
      "          \u0373\u0374e\u0372\u0372\u0372",
      "          \u0373\u0374e\u0372\u0372\u0372",
      "          \u0373\u0374e\u0372\u0372\u0372",
      "          \u0373\u0374e\u0372\u0372\u0372",
      "          \u0373\u0374e\u0372\u0372\u0372",
      "          \u0373\u0374eeee",
      "          \u0373\u0374\u0374\u0374\u0374\u0374",
      "          \u0373\u0373\u0373\u0373\u0373\u0373",
      "                ",
      "                ",
      "                ",
      "                ",
      "                ",
      "                "
    ],
    [
      "          \u038a \u038a\u038a\u038a\u038a",
      "          \u038a \u038a\u038a\u038a\u038a",
      "          \u038a \u038a\u038a\u038a\u038a",
      "          \u038a \u038a\u038a\u038a\u038a",
      "          \u038a \u038a\u038a\u038a\u038a",
      "          \u038a \u038a\u038a\u038a\u038a",
      "          \u038a \u038a\u038a\u038a\u038a",
      "          \u038a \u038a\u038a\u038a\u038a",
      "          \u038a     ",
      "          \u038a\u038a\u038a\u038a\u038a\u038a",
      "                ",
      "                ",
      "                ",
      "                ",
      "                ",
      "                "
    ]
  ]
}