{
  "name": "multi_hospitaldamaged_1_base1",
  "refpalette": "deceasedcraft:multi_hospitaldamaged_1/multi_hospitaldamaged_1_base1_palette",
  "xsize": 16,
  "zsize": 16,
  "slices": [
    [
      "vabbbbbbbbbbbbbb",
      "vabbbbbbbbbbbbbb",
      "vabbbbbbbbbbbbbb",
      "vabbbbbbbbbbbbbb",
      "vbbbbbbbbbbbbbbb",
      "vbbbbbbbbbbbbbbb",
      "vbbbbbbbbbbbbbbb",
      "vbbbbbbbbbbbbbbb",
      "vacdeeafgff fgff",
      "va heeaiiiiiiiii",
      "va    ajbjjbjjbj",
      "va    akl kl ml ",
      "va    a l  l  l ",
      "v       n     o ",
      "v               ",
      "v               "
    ],
    [
      "va  pqars ta  uq",
      "va   qar w a   q",
      "vaxyxxaxxAxaxBxx",
      "va    a    a    ",
      "vC              ",
      "vC              ",
      "vC              ",
      "vC              ",
      "va    aD D     D",
      "va    aiiiiEiiii",
      "va    ajbjjbjjbj",
      "va    a F  F  F ",
      "va    a I     J ",
      "v               ",
      "v               ",
      "v               "
    ],
    [
      "va   KaL   a   w",
      "va  MNaOM  a   P",
      "vaxQxxaxxRxaxSxx",
      "va    a    a    ",
      "vC              ",
      "vC              ",
      "vC              ",
      "vC              ",
      "va    a         ",
      "va    aiiiEEEiii",
      "va    ajbjjbjjbj",
      "va    a         ",
      "va    a         ",
      "v               ",
      "v               ",
      "v               "
    ],
    [
      "va    a    a   P",
      "va    a    a  P!",
      "vaxTxxaxxTxaxTxx",
      "va U  a  V a V  ",
      "vC              ",
      "vC              ",
      "vC              ",
      "vC              ",
      "va    a         ",
      "va    aiiiiEiiii",
      "va    ajbjjbjjbj",
      "va    a         ",
      "va    a         ",
      "v               ",
      "v               ",
      "v               "
    ],
    [
      "vaWWWWaWWWWaWWWW",
      "vaWWWWaWWWWaWWWW",
      "vaxxxxaxxxxaxxxx",
      "va    a    a    ",
      "vC              ",
      "vC              ",
      "vC              ",
      "vC              ",
      "va    a X XX X X",
      "va    aiiiiiiiii",
      "vabbbbabbbbbbbbb",
      "vabYYbaYbYYbYYbY",
      "vabYYbaYbYYbYYbY",
      "vYbYYbYYbYYbYYbY",
      "vYbYYbYYbYYbYYbY",
      "vYbYYbYYbYYbYYbY"
    ],
    [
      "vaZZZZaZZZZaZZZZ",
      "vaZZZZaZZZZaZZZZ",
      "vaZZZZaZZZZaZZZZ",
      "vaZZZZaZZZZaZZZZ",
      "vZZZZZZZZZZZZZZZ",
      "vZZZZZZZZZZZZZZZ",
      "vZZZZZZZZZZZZZZZ",
      "vZZZZZZZZZZZZZZZ",
      "vaZZZZaZZZZZZZZZ",
      "vaZZZZaiiiiiiiii",
      "vabbbbabbbbbbbbb",
      "vaZZZZaZZZZZZZZZ",
      "vaZZZZaZZZZZZZZZ",
      "vZZZZZZZZZZZZZZZ",
      "vZZZZZZZZZZZZZZZ",
      "vZZZZZZZZZZZZZZZ"
    ]
  ]
}