{
  "name": "multi_hospitaldamaged_1_ground",
  "refpalette": "deceasedcraft:multi_hospitaldamaged_1/multi_hospitaldamaged_1_ground_palette",
  "xsize": 16,
  "zsize": 16,
  "slices": [
    [
      "aHHbHHHb!cdddeee",
      "aHHbHHHbfddddeee",
      "aHHbHHHbbddddeee",
      "aHHbHHHbbddddeee",
      "cHHbHHHbbddddeee",
      "aHHbHHHbbddddeee",
      "aHHbHHHbggdddeee",
      "aHHbHHHbcdhhhhhe",
      "aHHbHHHbadiidjdd",
      "aHHbHHHbadiidjdd",
      "aHHbHHHbadiidjdd",
      "cHHbHHHbadiidjdd",
      "cHHbHHHbadiidjee",
      "aHHbHHHbadiidjee",
      "aHHbHHHbadiidjee",
      "aHHbHHHbadiidjee"
    ],
    [
      "          klmnop",
      "      q r  stuqw",
      " xy     ABC    w",
      " DE       BF  Iw",
      "         AJK p  ",
      "           L  M ",
      " xy   A   NlmN  ",
      " DE      OhhhhhP",
      "        QR STjUV",
      "        WR STjUX",
      " xy      R STjUY",
      " DE     QR STjU ",
      "        QR STjVV",
      "        WR STjZ ",
      " xy     WR STj 0",
      " DE     QR STj 1"
    ],
    [
      "            2k 3",
      "              45",
      "                ",
      "              67",
      "               8",
      "           9    ",
      "          klm#  ",
      "          hhhhh$",
      "             jUV",
      "             j! ",
      "             jU ",
      "            %jU ",
      "            VjVV",
      "            ^j  ",
      "            Vj  ",
      "            &j  "
    ],
    [
      "           *(  )",
      "                ",
      "                ",
      "               +",
      "               t",
      "           L    ",
      "           lm-  ",
      "          hhhhh ",
      "             jUV",
      "             j[ ",
      "             jU ",
      "            VjU ",
      "            VjVV",
      "            %j  ",
      "            ]j  ",
      "            %j  "
    ],
    [
      "           lm  {",
      "           }   |",
      "                ",
      "              ;:",
      "           '   <",
      "           L   >",
      "           lm   ",
      "          hhhhh ",
      "             jUV",
      "            ,jU ",
      "             jU ",
      "             jU ",
      "             jVV",
      "            .j  ",
      "             j  ",
      "             j  "
    ],
    [
      "      ?????/m`\u0370?",
      "      ?\u0371\u0371?\u0371\u0372\u0373\u0370??",
      "      ???\u0371?\u0370\u0372??\u0370",
      "      \u0371?\u0371\u0371\u0371\u0370\u0373\u0370\u0370\u0370",
      "      ?\u0371\u0371?\u0371\u0372\u0370?\u0370?",
      "      ?????/m``\u0374",
      "      ?????/m```",
      "      ????hhhhh`",
      "           \u0375M```",
      "           \u0375M```",
      "           \u0375M```",
      "           \u0375M\u0376\u0377\u0377",
      "           \u0375M```",
      "           \u0375M```",
      "           \u0375M```",
      "           MM```"
    ]
  ]
}