{
  "name": "multi_policeapartment_0_floor2",
  "refpalette": "deceasedcraft:multi_policeapartment_0/multi_policeapartment_0_floor2_palette",
  "xsize": 16,
  "zsize": 16,
  "slices": [
    [
      "                ",
      "                ",
      "    aaaaaaaaaaaa",
      "    abbbbacccccc",
      "    abbbbacccccc",
      "    abbbbccccccc",
      "    aaaaaacccccc",
      "    accccccccccc",
      "    accccccccccc",
      "    accccccccccc",
      "    aaadaaaaaaaa",
      "    addddddddddd",
      "    addddddddddd",
      "    aaaaaaaaaaad",
      "              ed",
      "              ed"
    ],
    [
      "                ",
      "                ",
      "    aaaaaaaaaaaa",
      "    afghiajkkjlm",
      "    a   na oo  p",
      "    a  q r ss  t",
      "    aaaaaa    uw",
      "    axyABC     D",
      "    aE         p",
      "    aF    IIII t",
      "    aaaJaaaaaaaa",
      "    KL          ",
      "    MNOOOOOOOOO ",
      "    MMKMMMMMMMKL",
      "              PL",
      "              PL"
    ],
    [
      "                ",
      "                ",
      "    aaaaaaaaaaaa",
      "    af   aQ  RST",
      "    aU   a     V",
      "    aUWq X     V",
      "    aaaaaa     Y",
      "    a!E ZC      ",
      "    a          V",
      "    a     0112 V",
      "    aaa3aa4444aa",
      "    5           ",
      "                ",
      "      5       5 ",
      "                ",
      "                "
    ],
    [
      "                ",
      "                ",
      "    aa444566444a",
      "    af777a    S8",
      "    a9  #a     V",
      "    a$%  f     V",
      "    aaaaaa     ^",
      "    a&*&*C     (",
      "    a          V",
      "    a     )++- V",
      "    aaa[aa6666aa",
      "    5           ",
      "                ",
      "      5       5 ",
      "                ",
      "                "
    ],
    [
      "                ",
      "                ",
      "    aaaaaaaaaaaa",
      "    af   a    ]{",
      "    a}   a     f",
      "    a|   a     f",
      "    aaaaaa     f",
      "    a ;: f     f",
      "    a          f",
      "    a          f",
      "    aaaaaaaaaaaa",
      "    5           ",
      "                ",
      "      5       5 ",
      "                ",
      "                "
    ],
    [
      "                ",
      "                ",
      "    566666666666",
      "    6'''''''''''",
      "    6'''''''''''",
      "    6'''''''''''",
      "    6'''''''''''",
      "    6'''''''''''",
      "    6'''''''''''",
      "    6'''''''''''",
      "    6<<<<<<<<<<<",
      "    6           ",
      "    6           ",
      "    566666666666",
      "                ",
      "                "
    ]
  ]
}