{
  "name": "multi_policeapartment_0_ground",
  "refpalette": "deceasedcraft:multi_policeapartment_0/multi_policeapartment_0_ground_palette",
  "xsize": 16,
  "zsize": 16,
  "slices": [
    [
      "aaaaaaaaaaaaaaaa",
      "aaaaaaaaaaaaaaaa",
      "aaaabbbbbbbbbbbb",
      "aaaabccccccccccc",
      "aaaabccccccccccc",
      "aaaabccccccccccc",
      "aaaabccccccccccc",
      "aaaabccccccccccc",
      "aaaabccccccccccc",
      "aaaabccccccccccc",
      "aaaabccccccccccc",
      "aaaabccccccccccc",
      "aaaabccccccccccc",
      "aaaabbdddddddddd",
      "eeeeefeeeeeeeeee",
      "HHHHHHHHHHHHHHHH"
    ],
    [
      "                ",
      "                ",
      "    bbbbbbbbbbbb",
      "    bg         h",
      "    bi jkj  jkj ",
      "    bilmnmolmnmo",
      "    bipqrqspqrqs",
      "    btpquqspquqs",
      "    bw qxq  qxq ",
      "    bwlmymolmymo",
      "    b  qAq  qAq ",
      "    b  BBB  BBB ",
      "    b CCCCCCCCCC",
      "    bbD        E",
      "     F          ",
      "                "
    ],
    [
      "                ",
      "                ",
      "    bbbbbbbbbbbb",
      "    b  I J  I Jh",
      "    b  KKK  KKK ",
      "    b  LqL  LqL ",
      "    b  qMq  q q ",
      "    b  @@@  @@@ ",
      "    bN OOO  OOO ",
      "    b  POP  POP ",
      "    b   P    P  ",
      "    b           ",
      "    bQRRRRRRRRRR",
      "    bbD        E",
      "     S          ",
      "                "
    ],
    [
      "                ",
      "                ",
      "    bbbbbbbbbbbb",
      "    b          h",
      "    b           ",
      "    b   T    T  ",
      "    b  PUP  PUP ",
      "    b  VPP  WPP ",
      "    b           ",
      "    b           ",
      "    b           ",
      "    b           ",
      "    b RRRRRRRRRR",
      "    bbD        E",
      "                ",
      "                "
    ],
    [
      "                ",
      "                ",
      "    bbbbbbbbbbbb",
      "    b          h",
      "    X           ",
      "    X           ",
      "    X           ",
      "    Y           ",
      "    Y           ",
      "    X           ",
      "    X           ",
      "    X           ",
      "    b RRRRRRRRRR",
      "    bbD        E",
      "     Z          ",
      "                "
    ],
    [
      "                ",
      "                ",
      "    bbbbbbbbbbbb",
      "    b          h",
      "    b           ",
      "    b           ",
      "    b           ",
      "    b           ",
      "    b           ",
      "    b           ",
      "    b           ",
      "    b           ",
      "    b RRRRRRRRRR",
      "    bb0111111112",
      "                ",
      "                "
    ]
  ]
}