{
  "name": "multi_policeapartment_0_floor1",
  "refpalette": "deceasedcraft:multi_policeapartment_0/multi_policeapartment_0_floor1_palette",
  "xsize": 16,
  "zsize": 16,
  "slices": [
    [
      "                ",
      "                ",
      "    aaaaaaaaaaaa",
      "    a          b",
      "    a           ",
      "    a           ",
      "    a           ",
      "    a           ",
      "    a           ",
      "    a           ",
      "    a           ",
      "    a           ",
      "    a cccccccccc",
      "    aaaaaaaaaaaa",
      "                ",
      "                "
    ],
    [
      "                ",
      "                ",
      "    aaaaaaaaaaaa",
      "    adeeeeeeeeee",
      "    aeeeeeeeeeee",
      "    aeeff  ff  e",
      "    aeef       e",
      "    aeef      fe",
      "    aeef      fe",
      "    aeef      fe",
      "    aeeffff  ffe",
      "    aeeeeeeeeeee",
      "    adeeeeeeeeee",
      "    aaaaaaaaaaaa",
      "  gggggggggggggg",
      "  ghhhhhhhhhhhhh"
    ],
    [
      "                ",
      "                ",
      "    aaaaaaaaaaaa",
      "    aijjjjjjjjjj",
      "    akkkkllllkkk",
      "    akllllllllll",
      "    akllmmmmmmll",
      "    akllmmmmmmll",
      "    akllmmmmmmll",
      "    akllmmmmmmll",
      "    akllllllllll",
      "    akllllllllll",
      "    aillllllllll",
      "    aaaaaaaaaaaa",
      "                ",
      "                "
    ],
    [
      "                ",
      "                ",
      "    aaaaaaaaaaaa",
      "    ajjjjjjjjjjj",
      "    ajn k    k  ",
      "    aj          ",
      "    aj          ",
      "    aj          ",
      "    aj          ",
      "    aj          ",
      "    aj          ",
      "    ajn     n   ",
      "    akkkkkkkkkkk",
      "    aaaaaaaaaaaa",
      "                ",
      "                "
    ],
    [
      "                ",
      "                ",
      "    oooooooooooo",
      "    opjjqjjjjqjj",
      "    oj  k   nk  ",
      "    oj          ",
      "    oj          ",
      "    oj          ",
      "    oj          ",
      "    oj          ",
      "    oj      n   ",
      "    ojn         ",
      "    opjjjjjjjjjj",
      "    oooooooooooo",
      "                ",
      "                "
    ],
    [
      "                ",
      "                ",
      "    rsssssssssss",
      "    sppppppppppp",
      "    sptttttttttt",
      "    sptttttttttt",
      "    sptttttttttt",
      "    sptttttttttt",
      "    sptttttttttt",
      "    sptttttttttt",
      "    sptttttttttt",
      "    sptttttttttt",
      "    sppppppppppp",
      "    rsssssssssss",
      "                ",
      "                "
    ]
  ]
}