{
  "name": "multi_policeapartment_0_top",
  "refpalette": "deceasedcraft:multi_policeapartment_0/multi_policeapartment_0_top_palette",
  "xsize": 16,
  "zsize": 16,
  "slices": [
    [
      "                ",
      "                ",
      "    aaaaaaaaaaaa",
      "    abbbbacccccc",
      "    abbbbacccccc",
      "    abbbbccccccc",
      "    aaaaaacccccc",
      "    accccccccccc",
      "    accccccccccc",
      "    accccccccccc",
      "    aaadaaaaaaaa",
      "    addddddddddd",
      "    addddddddddd",
      "    aaaaaaaaaaad",
      "              ed",
      "              ed"
    ],
    [
      "                ",
      "                ",
      "    aaaaaaaaaaaa",
      "    afgh a i  jk",
      "    a   lammmmmn",
      "    a  o pqrrqrs",
      "    aaaaaatuwxyA",
      "    aBCDEF     I",
      "    a        JKn",
      "    a     LLLLMs",
      "    aaaNaaaaaaaa",
      "    OP          ",
      "    QRSSSSSSSSS ",
      "    QQOQQQQQQQOP",
      "              TP",
      "              TP"
    ],
    [
      "                ",
      "                ",
      "    aaaaaaaaaaaa",
      "    af   ai   UV",
      "    a    a     W",
      "    a Xo Y     W",
      "    aaaaaa     i",
      "    a   ZF     0",
      "    a          W",
      "    a     1223 W",
      "    aaa4aa5555aa",
      "    6           ",
      "                ",
      "      6       6 ",
      "                ",
      "                "
    ],
    [
      "                ",
      "                ",
      "    aa555677555a",
      "    af888a    U9",
      "    a#  $a     W",
      "    a%^  f     W",
      "    aaaaaa     &",
      "    a*(*(F     )",
      "    a          W",
      "    a     +--[ W",
      "    aaa]aa7777aa",
      "    6           ",
      "                ",
      "      6       6 ",
      "                ",
      "                "
    ],
    [
      "                ",
      "                ",
      "    aaaaaaaaaaaa",
      "    af   ai   { ",
      "    a    a     f",
      "    a}   a     f",
      "    aaaaaa     f",
      "    a   |f     f",
      "    a          f",
      "    a          f",
      "    aaaaaaaaaaaa",
      "    6           ",
      "                ",
      "      6       6 ",
      "                ",
      "                "
    ],
    [
      "                ",
      "                ",
      "    677777777777",
      "    7;;;;;;;;;;;",
      "    7;;;;;;;;;;;",
      "    7;;;;;;;;;;;",
      "    7;;;;;;;;;;;",
      "    7;;;;;;;;;;;",
      "    7;;;;;;;;;;;",
      "    7;;;;;;;;;;;",
      "    7:::::::::::",
      "    7           ",
      "    7           ",
      "    677777777777",
      "                ",
      "                "
    ],
    [
      "                ",
      "                ",
      "    aaaaaaaaaaaa",
      "    abbbbbbbbbbb",
      "    ab'bbbbbbbbb",
      "    abbbbbbbb<<b",
      "    abbbbbbbb<<b",
      "    abbbbbbbb<<b",
      "    ab'bbbbbbbbb",
      "    abbbbbbbbbbb",
      "    aaaaaaaaaaaa",
      "    addddddddddd",
      "    addddddddddd",
      "    aaaaaaaaaaaa",
      "                ",
      "                "
    ],
    [
      "                ",
      "                ",
      "    >>>>>>>>>>>>",
      "    >           ",
      "    > ,         ",
      "    > ,     .<<?",
      "    > ,,,,,,,<<?",
      "    > ,     .<<?",
      "    > ,         ",
      "    >           ",
      "    >>>>>>>>>>>>",
      "                ",
      "                ",
      "                ",
      "                ",
      "                "
    ],
    [
      "                ",
      "                ",
      "                ",
      "                ",
      "                ",
      "            .<<?",
      "            .<<?",
      "            .<<?",
      "                ",
      "                ",
      "                ",
      "                ",
      "                ",
      "                ",
      "                ",
      "                "
    ],
    [
      "                ",
      "                ",
      "                ",
      "                ",
      "                ",
      "              > ",
      "                ",
      "                ",
      "                ",
      "                ",
      "                ",
      "                ",
      "                ",
      "                ",
      "                ",
      "                "
    ],
    [
      "                ",
      "                ",
      "                ",
      "                ",
      "                ",
      "              / ",
      "                ",
      "                ",
      "                ",
      "                ",
      "                ",
      "                ",
      "                ",
      "                ",
      "                ",
      "                "
    ],
    [
      "                ",
      "                ",
      "                ",
      "                ",
      "                ",
      "             // ",
      "              / ",
      "                ",
      "                ",
      "                ",
      "                ",
      "                ",
      "                ",
      "                ",
      "                ",
      "                "
    ]
  ]
}