{
  "name": "multi_policeapartment_0_base1",
  "refpalette": "deceasedcraft:multi_policeapartment_0/multi_policeapartment_0_base1_palette",
  "xsize": 16,
  "zsize": 16,
  "slices": [
    [
      "vvvvvvvvvvvvvvvv",
      "vaaaaaaaaaaaaaaa",
      "vaaaaaaaaaaaaaaa",
      "vaaaaaaaaaaaaaaa",
      "vaaaaaaaaaaaaaaa",
      "vaaaaaaaaaaaaaaa",
      "vaaaaaaaaaaaaaaa",
      "vaaaaaaaaaaaaaaa",
      "vaaaaaaaaaaaaaaa",
      "vaaaaaaaaaaaaaaa",
      "vaaaaaaaaaaaaaaa",
      "vaaaaaaaaaaaaaaa",
      "vaaaaaaaaaaaaaaa",
      "vaaaaaaaaaaaaaaa",
      "vaaaaaaaaaaaaaaa",
      "vaaaaaaaaaaaaaaa"
    ],
    [
      "vvvvvvvvvvvvvvvv",
      "vaaaaaaaaaaaaaaa",
      "vaaaaaaaaaaaaaaa",
      "vaaaaaaaaaaaaaaa",
      "vaaaaaaaaaaaaaaa",
      "vaaaaaaaaaaaaaaa",
      "vaaaaaaaaaaaaaaa",
      "vaaaaaaaaaaaaaaa",
      "vaaaaaaaaaaaaaaa",
      "vaaaaaaaaaaaaaaa",
      "vaaaaaaaaaaaaaaa",
      "vaaaaaaaaaaaaaaa",
      "vaaaaaaaaaaaaaaa",
      "vaaaaaaaaaaaaaaa",
      "vaaaaaaaaaaaaaaa",
      "vaaaaaaaaaaaaaaa"
    ],
    [
      "vvvvvvvvvvvvvvvv",
      "vaaaaaaaaaaaaaaa",
      "vaaaaaaaaaaaaaaa",
      "vaaaaaaaaaaaaaaa",
      "vaaaaaaaaaaaaaaa",
      "vaaaaaaaaaaaaaaa",
      "vaaaaaaaaaaaaaaa",
      "vaaaaaaaaaaaaaaa",
      "vaaaaaaaaaaaaaaa",
      "vaaaaaaaaaaaaaaa",
      "vaaaaaaaaaaaaaaa",
      "vaaaaaaaaaaaaaaa",
      "vaaaaaaaaaaaaaaa",
      "vaaaaaaaaaaaaaaa",
      "vaaaaaaaaaaaaaaa",
      "vaaaaaaaaaaaaaaa"
    ],
    [
      "vvvvvvvvvvvvvvvv",
      "vaaaaaaaaaaaaaaa",
      "vaaaaaaaaaaaaaaa",
      "vaaaaaaaaaaaaaaa",
      "vaaaaaaaaaaaaaaa",
      "vaaaaaaaaaaaaaaa",
      "vaaaaaaaaaaaaaaa",
      "vaaaaaaaaaaaaaaa",
      "vaaaaaaaaaaaaaaa",
      "vaaaaaaaaaaaaaaa",
      "vaaaaaaaaaaaaaaa",
      "vaaaaaaaaaaaaaaa",
      "vaaaaaaaaaaaaaaa",
      "vaaaaaaaaaaaaaaa",
      "vaaaaaaaaaaaaaaa",
      "vaaaaaaaaaaaaaaa"
    ],
    [
      "vvvvvvvvvvvvvvvv",
      "vaaaaaaaaaaaaaaa",
      "vaaaaaaaaaaaaaaa",
      "vaaaaaaaaaaaaaaa",
      "vaaaaaaaaaaaaaaa",
      "vaaaaaaaaaaaaaaa",
      "vaaaaaaaaaaaaaaa",
      "vaaaaaaaaaaaaaaa",
      "vaaaaaaaaaaaaaaa",
      "vaaaaaaaaaaaaaaa",
      "vaaaaaaaaaaaaaaa",
      "vaaaaaaaaaaaaaaa",
      "vaaaaaaaaaaaaaaa",
      "vaaaaaaaaaaaaaaa",
      "vaaaaaaaaaaaaaaa",
      "vaaaaaaaaaaaaaaa"
    ],
    [
      "vvvvvvvvvvvvvvvv",
      "vaaaaaaaaaaaaaaa",
      "vaaabbbbbbbbbbbb",
      "vaaabbbbbbbbbbbb",
      "vaaabbbbbbbbbbbb",
      "vaaabbbbbbbbbbbb",
      "vaaabbbbbbbbbbbb",
      "vaaabbbbbbbbbbbb",
      "vaaabbbbbbbbbbbb",
      "vaaabbbbbbbbbbbb",
      "vaaabbbbbbbbbbbb",
      "vaaabbbbbbbbbbbb",
      "vaaabbbbbbbbbbbb",
      "vaaabbbbbbbbbbbb",
      "vaaaacaaaaaaaaaa",
      "vaaaaaaaaaaaaaaa"
    ]
  ]
}