{
  "name": "multi_policeapartment_0_floor4",
  "refpalette": "deceasedcraft:multi_policeapartment_0/multi_policeapartment_0_floor4_palette",
  "xsize": 16,
  "zsize": 16,
  "slices": [
    [
      "                ",
      "                ",
      "    aaaaaaaaaaaa",
      "    abbbbacccccc",
      "    abbbbacccccc",
      "    abbbbccccccc",
      "    aaaaaacccccc",
      "    accccccccccc",
      "    accccccccccc",
      "    accccccccccc",
      "    aaadaaaaaaaa",
      "    addddddddddd",
      "    addddddddddd",
      "    aaaaaaaaaaad",
      "              ed",
      "              ed"
    ],
    [
      "                ",
      "                ",
      "    aaaaaaaaaaaa",
      "    afgh aijjikl",
      "    a  mna oo  p",
      "    a  q r ss  t",
      "    aaaaaa    uw",
      "    axyABC     D",
      "    a       !  p",
      "    aE    FFFF t",
      "    aaaIaaaaaaaa",
      "    JK      L   ",
      "    MNOOOOOOOOO ",
      "    MMJMMMMMMMJK",
      "              PK",
      "              PK"
    ],
    [
      "                ",
      "                ",
      "    aaaaaaaaaaaa",
      "    af  QaR  RST",
      "    aU   a     V",
      "    aUWq X     V",
      "    aaaaaa     Y",
      "    a Z 0C     1",
      "    a          V",
      "    a     2  3 V",
      "    aaa4aa55 5aa",
      "    6           ",
      "                ",
      "      6       6 ",
      "                ",
      "                "
    ],
    [
      "                ",
      "                ",
      "    aa555677555a",
      "    af888a    S9",
      "    a#  $a     V",
      "    a%^  f     V",
      "    aaaaaa     &",
      "    a*(*(C     )",
      "    a          V",
      "    a     +  - V",
      "    aaa[aa7777aa",
      "    6           ",
      "                ",
      "      6       6 ",
      "                ",
      "                "
    ],
    [
      "                ",
      "                ",
      "    aaaaaaaaaaaa",
      "    af   a    ]{",
      "    a}   a     f",
      "    a    a     f",
      "    aaaaaa     f",
      "    a   |f     f",
      "    a          f",
      "    a          ;",
      "    aaaaaaaaaaaa",
      "    6           ",
      "                ",
      "      6       6 ",
      "                ",
      "                "
    ],
    [
      "                ",
      "                ",
      "    677777777777",
      "    7:::::::::::",
      "    7:::::::::::",
      "    7:::::::::::",
      "    7:::::::::::",
      "    7:::::::::::",
      "    7:::::::::::",
      "    7:::::::::::",
      "    7'''''''''''",
      "    7           ",
      "    7           ",
      "    677777777777",
      "                ",
      "                "
    ]
  ]
}