{
  "name": "multi_policeapartment_0_floor3",
  "refpalette": "deceasedcraft:multi_policeapartment_0/multi_policeapartment_0_floor3_palette",
  "xsize": 16,
  "zsize": 16,
  "slices": [
    [
      "                ",
      "                ",
      "    aaaaaaaaaaaa",
      "    abbbbacccccc",
      "    abbbbacccccc",
      "    abbbbccccccc",
      "    aaaaaacccccc",
      "    accccccccccc",
      "    accccccccccc",
      "    accccccccccc",
      "    aaadaaaaaaaa",
      "    addddddddddd",
      "    addddddddddd",
      "    aaaaaaaaaaad",
      "              ed",
      "              ed"
    ],
    [
      "                ",
      "                ",
      "    aaaaaaaaaaaa",
      "    afgh aijjikl",
      "    a   ma nn  o",
      "    a !p q rr  s",
      "    aaaaaa    tu",
      "    awxyAB     C",
      "    a          o",
      "    aD    EEEE s",
      "    aaaFaaaaaaaa",
      "    IJ          ",
      "    KLMMMMMMMMM ",
      "    KKIKKKKKKKIJ",
      "              NJ",
      "              NJ"
    ],
    [
      "                ",
      "                ",
      "    aaaaaaaaaaaa",
      "    af  OaP  QRS",
      "    aT   a     U",
      "    a Vp W     U",
      "    aaaaaa     X",
      "    a Y ZB     0",
      "    a          U",
      "    a     1223 U",
      "    aaa4aa5555aa",
      "    6           ",
      "                ",
      "      6       6 ",
      "                ",
      "                "
    ],
    [
      "                ",
      "                ",
      "    aa555677555a",
      "    af888a    R9",
      "    a#  $a     U",
      "    a%^  f     U",
      "    aaaaaa     &",
      "    a*(*(B     )",
      "    a          U",
      "    a     +--[ U",
      "    aaa]aa7777aa",
      "    6           ",
      "                ",
      "      6       6 ",
      "                ",
      "                "
    ],
    [
      "                ",
      "                ",
      "    aaaaaaaaaaaa",
      "    af   a    {}",
      "    a|   a     f",
      "    a;   a     f",
      "    aaaaaa     f",
      "    a :' f     f",
      "    a          f",
      "    a          f",
      "    aaaaaaaaaaaa",
      "    6           ",
      "                ",
      "      6       6 ",
      "                ",
      "                "
    ],
    [
      "                ",
      "                ",
      "    677777777777",
      "    7<<<<<<<<<<<",
      "    7<<<<<<<<<<<",
      "    7<<<<<<<<<<<",
      "    7<<<<<<<<<<<",
      "    7<<<<<<<<<<<",
      "    7<<<<<<<<<<<",
      "    7<<<<<<<<<<<",
      "    7>>>>>>>>>>>",
      "    7           ",
      "    7           ",
      "    677777777777",
      "                ",
      "                "
    ]
  ]
}