{
  "name": "multi_thering_0_base1",
  "refpalette": "deceasedcraft:multi_thering_0/multi_thering_0_base1_palette",
  "xsize": 16,
  "zsize": 16,
  "slices": [
    [
      "vvvvvvvvvvvvvvvv",
      "vaaaaaaaaaaaaaaa",
      "vabcbbdbcaeffg  ",
      "va       aeh g  ",
      "va       aeffg  ",
      "va      iaeh g  ",
      "va       jeffg  ",
      "va       je! g  ",
      "va       jeeeg  ",
      "va       aeh g  ",
      "va       aekkg  ",
      "vablblblbaeh g  ",
      "vablblblbaekkg  ",
      "vablblblbaeh g  ",
      "vamnmnmnmaekkg  ",
      "vamompmomaaaaaaq"
    ],
    [
      "vvvvvvvvvvvvvvvv",
      "vaaaaaaaaaaaaaaa",
      "vadbbcbbbarrrg  ",
      "va i     arrrg  ",
      "va     i arrrg  ",
      "va      sarrrg  ",
      "va       arrrg  ",
      "va       arrrg  ",
      "va       arrrg  ",
      "va       arrrg  ",
      "va       arrrg  ",
      "vab b b barrrg  ",
      "vabtb btbarrrg  ",
      "vab bub barrrg  ",
      "vamnmnmnmarrrg  ",
      "vamwmpmpmaaaaaaq"
    ],
    [
      "vvvvvvvvvvvvvvvv",
      "vaaaaaaaaaaaaaaa",
      "vabbbbbbdaxxxg  ",
      "va s     ay xg  ",
      "va   A s a  xg  ",
      "vai     sa  xg  ",
      "va   i   axxxg  ",
      "va       a  xg  ",
      "va       a  xg  ",
      "va       a yxg  ",
      "va       axxxg  ",
      "vabbbbbbba  xg  ",
      "vabbbbbbba  xg  ",
      "vabbbBbbbay xg  ",
      "vammmmmmmaxxxg  ",
      "vammmmmmmaaaaaaq"
    ],
    [
      "vvvvvvvvvvvvvvvv",
      "vaaaaaaaaaaaaaaa",
      "vaCCCCCCCa yyrrr",
      "vaCcCCcCCa  yrrr",
      "vaCCCCCdCa   rrr",
      "vadCdCCCca   rrr",
      "vaCCCcCCCa   rrr",
      "vaCCCCCCCa   rrr",
      "vaCCCCCCCa   rrr",
      "vaCCCCCCCa   rrr",
      "vaCCCCCCCa   rrr",
      "vaCCCCCCCa   rrr",
      "vaCCCCCCCa   rrr",
      "vaCCCCCCCa   rrr",
      "vaCCCCCCCa  yrrr",
      "vaCCCCCCCaaaaaaq"
    ],
    [
      "vvvvvvvvvvvvvvvv",
      "vaaaaaaaaaaaaaaa",
      "vaaaaaaaaaaaaaaa",
      "vaaaaaaaaaaaaaaa",
      "vaaaaaaaaaaaaaaa",
      "vaaaaaaaaaaaaaaa",
      "vaaaaaaaaaaaaaaa",
      "vaaaaaaaaaaaaaaa",
      "vaaaaaaaaaaaaaaa",
      "vaaaaaaaaaaaaaaa",
      "vaaaaaaaaaaaaaaa",
      "vaaaaaaaaaaaaaaa",
      "vaaaaaaaaaaaaaaa",
      "vaaaaaaaaaaaaaaa",
      "vaaaaaaaaaaaaaaa",
      "vaaaaaaaaaaaaaaq"
    ],
    [
      "vvvvvvvvvvvvvvvv",
      "vDDDDDDDDDDDDDDD",
      "vDDDDDDDDDDDDDDD",
      "vDDDDDDDDDDDDDDD",
      "vDDDDDDDDDDDDDDD",
      "vDDDDDDDDDDDDDDD",
      "vDDDDDDDDDDDDDDD",
      "vDDDDDDDDDDDDDDD",
      "vDDDDDDDDDDDDDDD",
      "vDDDDDDDDDDDDDDD",
      "vDDDDDDDDDDDDDDD",
      "vDDDDDDDDDDDDDDD",
      "vDDDDDDDDDDDDDDD",
      "vDDDDDDDDDDDDDDD",
      "vDDDDDDDDDDDDDDD",
      "vDDDDDDDDDDDDDDq"
    ]
  ]
}