{
  "name": "multi_thering_0_base2",
  "refpalette": "deceasedcraft:multi_thering_0/multi_thering_0_base2_palette",
  "xsize": 16,
  "zsize": 16,
  "slices": [
    [
      "vvvvvvvvvvvvvvvv",
      "vaaaaaaaaaaaaaaa",
      "vaaaaaaaaaaaaaaa",
      "vaaaaaaaaaaaaaaa",
      "vaaaaaaaaaaaaaaa",
      "vaaaaaaaaaaaaaaa",
      "vaaaaaaaaaaaaaaa",
      "vaaaaaaaaaaaaaaa",
      "vaaaaaaaaaaaaaaa",
      "vaaaaaaaaaaaaaaa",
      "vaaaaaaaaaaaaaaa",
      "vaaaaaaaaaaaaaaa",
      "vaaaaaaaaaaaaaaa",
      "vaaaaaaaaaaaaaaa",
      "vaaaaaaaaaaaaaaa",
      "vaaaaaaaaaaaaaab"
    ],
    [
      "vvvvvvvvvvvvvvvv",
      "vaaaaaaaaaaaaaaa",
      "vaaaaaaaaaaaaaaa",
      "vaaaaaaaaaaaaaaa",
      "vaaaaaaaaaaaaaaa",
      "vaaaaaaaaaaaaaaa",
      "vaaaaaaaaaaaaaaa",
      "vaaaaaaaaaaaaaaa",
      "vaaaaaaaaaaaaaaa",
      "vaaaaaaaaaaaaaaa",
      "vaaaaaaaaaaaaaaa",
      "vaaaaaaaaaaaaaaa",
      "vaaaaaaaaaaaaaaa",
      "vaaaaaaaaaaaaaaa",
      "vaaaaaaaaaaaaaaa",
      "vaaaaaaaaaaaaaab"
    ],
    [
      "vvvvvvvvvvvvvvvv",
      "vccccccccccccccc",
      "vcddededdccccccc",
      "vcdedddddccccccc",
      "vcdeeddeeccccccc",
      "vcdddededccccccc",
      "vcdddddddccccccc",
      "vcddeddddccccccc",
      "vcdddddedccccccc",
      "vceddddddccccccc",
      "vcdddddddccccccc",
      "vcdddedddccccccc",
      "vcdddddddccccccc",
      "vceddddedccccccc",
      "vcdddddddccccccc",
      "vcdddddddccccccb"
    ],
    [
      "vvvvvvvvvvvvvvvv",
      "vfffffffffffffff",
      "vfgggggggfhhhhhh",
      "vfgigijgifhhhhhh",
      "vfijkjgikfhhhhhh",
      "vfggiggkgfhhhhhh",
      "vfjgggggjghhhhhh",
      "vfgggjgggghhhhhh",
      "vfgggggggghhhhhh",
      "vfiggggggfhhhhhh",
      "vfgggggggfhhhhhh",
      "vflllllllfhhhhhh",
      "vflllllllfhhhhhh",
      "vflllllllfhhhhhh",
      "vfmmmmmmmfhhhhhh",
      "vfmmmmmmmffffffn"
    ],
    [
      "vvvvvvvvvvvvvvvv",
      "vfffffffffffffff",
      "vfjiijjiifoppq  ",
      "vfrstutwrfo  x  ",
      "vfyAtBtB foppq  ",
      "vf CAy  yfo  x D",
      "vfB      Eoppq F",
      "vfI       J  K F",
      "vfL      Eoooq F",
      "vf   y  yfo  M F",
      "vf y     foNNq F",
      "vfl l l lfoIOM P",
      "vflQlQlRlfoNNq  ",
      "vfl l l!lfo  M  ",
      "vfmSmSmSmfoNNq  ",
      "vfmTmUmVmffffffn"
    ],
    [
      "vvvvvvvvvvvvvvvv",
      "vfffffffffffffff",
      "vfijjjlijfoppq  ",
      "vfW X X YfoZ01  ",
      "vf  2 2  foppq  ",
      "vf       foZ01  ",
      "vf       Eoppq  ",
      "vf3       4Z05  ",
      "vf       Eoooq  ",
      "vf       foZ67  ",
      "vf       foNNq  ",
      "vfl8l8l8lfoZ67  ",
      "vfl8l8l8lfoNNq  ",
      "vfl8l8l8lfoZ67  ",
      "vfmSmSmSmfoNNq  ",
      "vfmTmVmTmffffffn"
    ]
  ]
}