{
  "name": "multi_filmworkstower_3_base2",
  "refpalette": "deceasedcraft:multi_filmworkstower_3/multi_filmworkstower_3_base2_palette",
  "xsize": 16,
  "zsize": 16,
  "slices": [
    [
      "vaaabccccccccccc",
      "vaaabccccccccccc",
      "vaaabccccccccccc",
      "vaaabccccccccccc",
      "vaaabccccccccccc",
      "vaaabccccccccccc",
      "vaaabbbbbbbbbbbb",
      "vaaadccccccccccc",
      "vaaadccccccccccc",
      "vaaadccccccccccc",
      "vaaadccccccccccc",
      "vaaadccccccccccc",
      "vaaadccccccccccc",
      "vaaadddddddddddd",
      "vaaaaaaaaaaaaaaa",
      "vvvvvvvvvvvvvvvv"
    ],
    [
      "vaaaefffffff  g ",
      "vaaaefffffff  g ",
      "vaaaefffffff  g ",
      "vaaaefffffff  g ",
      "vaaaefffffff  g ",
      "vaaaefffffff    ",
      "vaaabbbbbbbbbbbb",
      "vaaadhiiiiihiiii",
      "vaaadj     j    ",
      "vaaad           ",
      "vaaad           ",
      "vaaadk     k    ",
      "vaaadhiiiiihiiii",
      "vaaadddddddddddd",
      "vaaaaaaaaaaaaaaa",
      "vvvvvvvvvvvvvvvv"
    ],
    [
      "vaaaefl l m     ",
      "vaaaefnon  l    ",
      "vaaaefo ol      ",
      "vaaaefnonpq     ",
      "vaaaefr  r      ",
      "vaaaef          ",
      "vaaabbbbbbbbbbbb",
      "vaaadhs tsshtt s",
      "vaaadj     j    ",
      "vaaad           ",
      "vaaad           ",
      "vaaadk     k    ",
      "vaaadhts  shs t!",
      "vaaadddddddddddd",
      "vaaaaaaaaaaaaaaa",
      "vvvvvvvvvvvvvvvv"
    ],
    [
      "vaaaer    m     ",
      "vaaae n n       ",
      "vaaae  u        ",
      "vaaaeqn n       ",
      "vaaael          ",
      "vaaae wwwww     ",
      "vaaabbbbbbbbbbbb",
      "vaaadhiiiiihiiii",
      "vaaadj     j    ",
      "vaaad           ",
      "vaaad           ",
      "vaaadk     k    ",
      "vaaadhiiiiihiiii",
      "vaaadddddddddddd",
      "vaaaaaaaaaaaaaaa",
      "vvvvvvvvvvvvvvvv"
    ],
    [
      "vaaae     m     ",
      "vaaae xyA       ",
      "vaaae yBy       ",
      "vaaae CyD       ",
      "vaaae           ",
      "vaaae wwwww     ",
      "vaaabbbbbbbbbbbb",
      "vaaadhst Eth t s",
      "vaaadj     j    ",
      "vaaad           ",
      "vaaad           ",
      "vaaadk     k    ",
      "vaaadhss  tht s ",
      "vaaadddddddddddd",
      "vaaaaaaaaaaaaaaa",
      "vvvvvvvvvvvvvvvv"
    ],
    [
      "vaaae           ",
      "vaaae FIF       ",
      "vaaae IJI       ",
      "vaaae FIF       ",
      "vaaae           ",
      "vaaae wwwww     ",
      "vaaabbbbbbbbbbbb",
      "vaaadhiiiiihiiii",
      "vaaadj     j    ",
      "vaaad           ",
      "vaaad           ",
      "vaaadk     k    ",
      "vaaadhiiiiihiiii",
      "vaaadddddddddddd",
      "vaaaaaaaaaaaaaaa",
      "vvvvvvvvvvvvvvvv"
    ]
  ]
}