{
  "name": "multi_filmworkstower_3_base1",
  "refpalette": "deceasedcraft:multi_filmworkstower_3/multi_filmworkstower_3_base1_palette",
  "xsize": 16,
  "zsize": 16,
  "slices": [
    [
      "vaaab           ",
      "vaaab  c        ",
      "vaaab cdc       ",
      "vaaab  c        ",
      "vaaab           ",
      "vaaab eeeee     ",
      "vaaaffffffffffff",
      "vaaaghii  jhjjii",
      "vaaagk     k    ",
      "vaaag           ",
      "vaaag           ",
      "vaaagl     l    ",
      "vaaaghi i jhjmii",
      "vaaagggggggggggg",
      "vaaaaaaaaaaaaaaa",
      "vvvvvvvvvvvvvvvv"
    ],
    [
      "vaaab           ",
      "vaaab           ",
      "vaaab           ",
      "vaaab           ",
      "vaaab           ",
      "vaaab eeeee     ",
      "vaaaffffffffffff",
      "vaaaghnnnnnhnnnn",
      "vaaagk     k    ",
      "vaaag           ",
      "vaaag           ",
      "vaaagl     l    ",
      "vaaaghnnnnnhnnnn",
      "vaaagggggggggggg",
      "vaaaaaaaaaaaaaaa",
      "vvvvvvvvvvvvvvvv"
    ],
    [
      "vaaab           ",
      "vaaab           ",
      "vaaab           ",
      "vaaab           ",
      "vaaab           ",
      "vaaab           ",
      "vaaaffffffffffff",
      "vaaaghi!j ihiiij",
      "vaaagk     k    ",
      "vaaag           ",
      "vaaag           ",
      "vaaagl     l    ",
      "vaaaghjio ih ii ",
      "vaaagggggggggggg",
      "vaaaaaaaaaaaaaaa",
      "vvvvvvvvvvvvvvvv"
    ],
    [
      "vaaab           ",
      "vaaab           ",
      "vaaab           ",
      "vaaab           ",
      "vaaab           ",
      "vaaab           ",
      "vaaaffffffffffff",
      "vaaagh     h    ",
      "vaaag           ",
      "vaaag           ",
      "vaaag           ",
      "vaaag           ",
      "vaaagh     h    ",
      "vaaagggggggggggg",
      "vaaaaaaaaaaaaaaa",
      "vvvvvvvvvvvvvvvv"
    ],
    [
      "vaaafppppppppppp",
      "vaaafppppppppppp",
      "vaaafppppppppppp",
      "vaaafppppppppppp",
      "vaaafppppppppppp",
      "vaaafppppppppppp",
      "vaaaffffffffffff",
      "vaaagppppppppppp",
      "vaaagppppppppppp",
      "vaaagppppppppppp",
      "vaaagppppppppppp",
      "vaaagppppppppppp",
      "vaaagppppppppppp",
      "vaaagggggggggggg",
      "vaaaaaaaaaaaaaaa",
      "vvvvvvvvvvvvvvvv"
    ],
    [
      "vaaaffffffffffff",
      "vaaaffffffffffff",
      "vaaaffffffffffff",
      "vaaaffffffffffff",
      "vaaaffffffffffff",
      "vaaaffffffffffff",
      "vaaaf ffffffffff",
      "vaaagfffffffffff",
      "vaaagfffffffffff",
      "vaaagfffffffffff",
      "vaaagfffffffffff",
      "vaaagfffffffffff",
      "vaaagfffffffffff",
      "vaaagggggggggggg",
      "vaaaaaaaaaaaaaaa",
      "vvvvvvvvvvvvvvvv"
    ]
  ]
}