{
  "name": "multi_filmworkstower_3_ground",
  "refpalette": "deceasedcraft:multi_filmworkstower_3/multi_filmworkstower_3_ground_palette",
  "xsize": 16,
  "zsize": 16,
  "slices": [
    [
      "aaaabc       cdd",
      "aaaebc f   f cdd",
      "aaaabc   g   cdd",
      "aaaabc      gcdd",
      "aaaebcgf   f cdd",
      "aaaabc   g   cdd",
      "aaaab ccccccccdd",
      "aaaabddddddddddd",
      "aaaabhhhhhhhhhhh",
      "aaaabbbbbbbbbbbb",
      "aaaaaaaaaaaaaaaa",
      "aaaaaaaaaaaaaaaa",
      "aaaaaaaaaaaaaaaa",
      "aaaaaaaaaaaaaaaa",
      "aaaaaaaaaaaaaaaa",
      "aaaaaaaaaaaaaaaa"
    ],
    [
      "    icjjjjjjjk  ",
      "   iecjjjjjjjk  ",
      "    icjjjjjjjk  ",
      "    icjjjjjjjk  ",
      "   iecjjjjjjjk  ",
      "    icjjjjjjjk  ",
      "     lkkkkkkkk  ",
      "     m          ",
      "     noooooooooo",
      "     nnnnnnnnnnn",
      "                ",
      "                ",
      "                ",
      "                ",
      "                ",
      "                "
    ],
    [
      "     ip         ",
      "    iep         ",
      "     ip         ",
      "     ip         ",
      "    iep    q    ",
      "     ip         ",
      "      l         ",
      "      m         ",
      "      nooooooooo",
      "      nnnnnnnnnn",
      "                ",
      "                ",
      "                ",
      "                ",
      "                ",
      "                "
    ],
    [
      "      ip        ",
      "     iep        ",
      "      ip        ",
      "      ip        ",
      "     iep        ",
      "      ip        ",
      "       l        ",
      "       m        ",
      "       noo ooooo",
      "       nnnnnnnnn",
      "                ",
      "                ",
      "                ",
      "                ",
      "                ",
      "                "
    ],
    [
      "       ip       ",
      "      iep       ",
      "       ip       ",
      "       ip       ",
      "      iep       ",
      "       ip       ",
      "        l       ",
      "        m       ",
      "        n  o  o ",
      "        nnnnnnnn",
      "                ",
      "                ",
      "                ",
      "                ",
      "                ",
      "                "
    ],
    [
      "        ip      ",
      "       iep      ",
      "        ip      ",
      "        ip      ",
      "       iep      ",
      "        ip      ",
      "         l      ",
      "         m      ",
      "         n      ",
      "         nnnnnnn",
      "                ",
      "                ",
      "                ",
      "                ",
      "                ",
      "                "
    ]
  ]
}