{
  "name": "multi_sunkenmonumentpark_1_ground",
  "refpalette": "deceasedcraft:multi_sunkenmonumentpark_1/multi_sunkenmonumentpark_1_ground_palette",
  "xsize": 16,
  "zsize": 16,
  "slices": [
    [
      "aabbc    d     e",
      "aabbc f         ",
      "aabbc        e  ",
      "aabbc    d      ",
      "aabbc g h       ",
      "aabbcf  d   d   ",
      "aabbc g        e",
      "aabbc       e   ",
      "aabbc g  d      ",
      "aabbcf          ",
      "aaabc    aij    ",
      "aaaaaaaaaajj    ",
      "kkkkkaaaaaj     ",
      "kkkkkaaaaij     ",
      "llllmn          ",
      "llllmn          "
    ],
    [
      "         e     e",
      "  fg            ",
      "             e  ",
      "         e      ",
      "  g   d d       ",
      "  o     e   e   ",
      "      d        p",
      " f g        e   ",
      "      d  e     j",
      "   g        aaaj",
      "         aaaaaaj",
      "   qqqaaakkaaaaj",
      "     rrrkkkaaajj",
      "     rrrkkkaaajj",
      "              jj",
      "              jj"
    ],
    [
      "         e      ",
      "   d            ",
      "             p  ",
      "         e      ",
      "  d   e e       ",
      "  h     e   e   ",
      "      e         ",
      "   d        p   ",
      "      e  e     a",
      "   d        aaak",
      "         sqqrrkk",
      "      qqq  rrrkk",
      "           rrrkk",
      "           rrrkk",
      "              ak",
      "              ak"
    ],
    [
      "         p      ",
      "   e            ",
      "                ",
      "         p      ",
      "  e   e e       ",
      "  d     p       ",
      "      e         ",
      "   e            ",
      "      e  e     s",
      "   e        sqq ",
      "                ",
      "                ",
      "                ",
      "                ",
      "             t  ",
      "             tu "
    ],
    [
      "                ",
      "   e            ",
      "                ",
      "                ",
      "  e   p p       ",
      "  e             ",
      "      p         ",
      "   e            ",
      "      p  p      ",
      "   e            ",
      "                ",
      "                ",
      "                ",
      "                ",
      "                ",
      "                "
    ],
    [
      "                ",
      "   p            ",
      "                ",
      "                ",
      "  p             ",
      "  e             ",
      "                ",
      "   p            ",
      "                ",
      "   p            ",
      "                ",
      "                ",
      "                ",
      "                ",
      "                ",
      "                "
    ]
  ]
}