{
  "name": "multi_sunkenmonumentpark_1_base1",
  "refpalette": "deceasedcraft:multi_sunkenmonumentpark_1/multi_sunkenmonumentpark_1_base1_palette",
  "xsize": 16,
  "zsize": 16,
  "slices": [
    [
      "vaaaaaaaaaaaaaaa",
      "vaaaaaaaaaaaaaaa",
      "vaaaaaaaaaaaaaaa",
      "vaaaaaaaaaaaaaaa",
      "vaaaaaaaaaaaaaaa",
      "vaaaaaaaaaaaaaaa",
      "vaaaaaaaaaaaaaaa",
      "vaaaaaaaaaaaaaaa",
      "vaaaaaaaaaaaaaaa",
      "vaaaaaaaaaaaaaaa",
      "vaaaaaaaaaaaaaaa",
      "vaaaaaaaaaaaaaaa",
      "vaaaaaaaaaaaaaaa",
      "vaaaaaaaaaaaaaaa",
      "vaaaaaaaaaaaaaaa",
      "vaaaaaaaaaaaaaaa"
    ],
    [
      "vaaaaaaaaaaaaaaa",
      "vaaaaaaaaaaaaaaa",
      "vaaaaaaaaaaaaaaa",
      "vaaaaaaaaaaaaaaa",
      "vaaaaaaaaaaaaaaa",
      "vaaaaaaaaaaaaaaa",
      "vaaaaaaaaaaaaaaa",
      "vaaaaaaaaaaaaaaa",
      "vaaaaaaaaaaaaaaa",
      "vaaaaaaaaaaaaaaa",
      "vaaaaaaaaaaaaaaa",
      "vaaaaaaaaaaaaaaa",
      "vaaaaaaaaaaaaaaa",
      "vaaaaaaaaaaaaaaa",
      "vaaaaaaaaaaaaaaa",
      "vaaaaaaaaaaaaaaa"
    ],
    [
      "vaaaaaaaaaaaaaaa",
      "vaaaaaaaaaaaaaaa",
      "vaaaaaaaaaaaaaaa",
      "vaaaaaaaaaaaaaab",
      "vaaaaaaaaaaaaabb",
      "vaaaaaaaaaaaaabb",
      "vaaaaaaaaaaaaabb",
      "vaaaaaaaaaaaabbb",
      "vaaaaaaaaaaaabbb",
      "vaaaaaaaaaaaabbb",
      "vaaaaaaaaaaaabbb",
      "vaaaaaaaaaaaabbb",
      "vaaaaaaaaaaaabbb",
      "vaaaaaaaaaaaabbb",
      "vaaaaaaaaaaaaccc",
      "vaaaaaaaaaaaaccc"
    ],
    [
      "vaaaaaaaaaabbbbb",
      "vaaaaaaaaaabbbbb",
      "vaaaaaaaaabbbbbb",
      "vaaaaaaaaabbbbbd",
      "vaaaaaaaaabbbbd ",
      "vaaaaaaaaabbbbd ",
      "vaaaaaaaaabbbbde",
      "vaaaaaaaaabbbd  ",
      "vaaaaaaaaabbbdf ",
      "vaaaaaaaaabbbd  ",
      "vaaaaaaaaabbbd  ",
      "vgggggaaaabbbd  ",
      "vgggggaaaabbbd f",
      "vgggggaaaabbbd  ",
      "vgggggaaaaccchi ",
      "vgggggaaaaccchi "
    ],
    [
      "v      bbbbd   e",
      "v      bbbbd    ",
      "v      bbbd  e  ",
      "v      bbbd f   ",
      "v      bbbd     ",
      "v      bbbdfj   ",
      "v      bbbd    k",
      "v      bbbd e   ",
      "v      bbbd     ",
      "v      bbbd f   ",
      "v      bbbd     ",
      "vggggggbbbd     ",
      "vggggggbbbd     ",
      "vggggggbbbd     ",
      "vggggggccchi    ",
      "vggggggccchi    "
    ],
    [
      "v   bbbdfe     k",
      "v   bbbd        ",
      "v   bbbd     k  ",
      "v   bbbdfe      ",
      "v   bbbdj       ",
      "v   bbbdef  l   ",
      "v   bbbd       m",
      "v   bbbd    k   ",
      "v   bbbdfe      ",
      "v   bbbd        ",
      "v   bbbd        ",
      "vgggggggn       ",
      "vgggggggo       ",
      "vggggggg        ",
      "vgggccchi       ",
      "vgggccchi       "
    ]
  ]
}