{
  "name": "building_office3b_floor3_180",
  "refpalette": "deceasedcraft:building_office3b/building_office3b_floor3_palette_180",
  "xsize": 16,
  "zsize": 16,
  "slices": [
    [
      "                ",
      " aaaaaaaaaaaaaa ",
      "  dccl    kccb  ",
      "  efggggggggfe  ",
      " jefiiiiiiiifej ",
      "  efiiiiiiiife  ",
      " hefiiiiiiiifeh ",
      "  efiiiiiiiife  ",
      "  efiiiiiiiife  ",
      " jefiiiiiiiifej ",
      "  efiiiiiiiife  ",
      " hefiiiiiiiifeh ",
      "  efggggggggfe  ",
      "  dccccccccccb  ",
      " aaaaaaaaaaaaaa ",
      "                "
    ],
    [
      "                ",
      " aaaaaaaaaaaaaa ",
      "  d  kl      b  ",
      "  e  FEEEEE  e  ",
      " je          ej ",
      "  e   D D D  e  ",
      " he  AAAAAAA eh ",
      "  e CAB!BBBA e  ",
      "  e  AAAAAAA e  ",
      " je   y y y  ej ",
      "  e          e  ",
      " hexxxx  ww  eh ",
      "  e   u      e  ",
      "  dtsrqmpoonmb  ",
      " aaaaaaaaaaaaaa ",
      "                "
    ],
    [
      "                ",
      " aaaaaaaaaaaaaa ",
      "  d   kl     b  ",
      "  e  RQEEEE  e  ",
      " je          ej ",
      "  e          e  ",
      " he   O P O  eh ",
      "  e  N       e  ",
      "  e  M  LK   e  ",
      " je          ej ",
      "  e          e  ",
      " hexxxx      eh ",
      "  e   J      e  ",
      "  d   qI    Ib  ",
      " aaaaaaaaaaaaaa ",
      "                "
    ],
    [
      "                ",
      " aaaaaaaaaaaaaa ",
      "  d    kl    b  ",
      "  e  RRQEEE  e  ",
      " je          ej ",
      "  e          e  ",
      " he          eh ",
      "  e          e  ",
      "  e          e  ",
      " je          ej ",
      "  e          e  ",
      " hexxxx      eh ",
      "  e   q      e  ",
      "  dXWVqS UT Sb  ",
      " aaaaaaaaaaaaaa ",
      "                "
    ],
    [
      "                ",
      " aaaaaaaaaaaaaa ",
      "  d     kl   b  ",
      "  e  RRRQEE  e  ",
      " je          ej ",
      "  e          e  ",
      " he          eh ",
      "  e          e  ",
      "  e          e  ",
      " je          ej ",
      "  e          e  ",
      " hexxxx      eh ",
      "  e   q      e  ",
      "  d Y q      b  ",
      " aaaaaaaaaaaaaa ",
      "                "
    ],
    [
      "                ",
      " aaaaaaaaaaaaaa ",
      "  d      kl  b  ",
      "  e  RRRRZE  e  ",
      " je          ej ",
      "  e          e  ",
      " he          eh ",
      "  e          e  ",
      "  e          e  ",
      " je          ej ",
      "  e          e  ",
      " hexxxx      eh ",
      "  e   q      e  ",
      "  d   q      b  ",
      " aaaaaaaaaaaaaa ",
      "                "
    ]
  ]
}