{
  "name": "building_office3b_floor1_90",
  "refpalette": "deceasedcraft:building_office3b/building_office3b_floor1_palette_90",
  "xsize": 16,
  "zsize": 16,
  "slices": [
    [
      "                ",
      " a  h j  h j  a ",
      " adeeeeeeeeeeda ",
      " acffffffffffca ",
      " acgiiiiiiiigca ",
      " acgiiiiiiiigla ",
      " acgiiiiiiiig a ",
      " acgiiiiiiiig a ",
      " acgiiiiiiiig a ",
      " acgiiiiiiiig a ",
      " acgiiiiiiiigka ",
      " acgiiiiiiiigca ",
      " acffffffffffca ",
      " abeeeeeeeeeeba ",
      " a  h j  h j  a ",
      "                "
    ],
    [
      "                ",
      " a  h j  h j  a ",
      " adeeeeeeeeeeda ",
      " at AK        a ",
      " as AJ  PP    a ",
      " ar AIMOOQ  Ska ",
      " aqwyFFFFF  Rla ",
      " ap  E NE   R a ",
      " an xD  D   R a ",
      " ao  C  C   R a ",
      " ao  BL BL  R a ",
      " anu          a ",
      " am           a ",
      " abeeeeeeeeeeba ",
      " a  h j  h j  a ",
      "                "
    ],
    [
      "                ",
      " a  h j  h j  a ",
      " adeeeeeeeeeeda ",
      " a  A2        a ",
      " a  A         a ",
      " a  A1345   7 a ",
      " aqVy00000  6ka ",
      " aT  Z  X   Rla ",
      " aU  Y  Y   R a ",
      " au  X  u   R a ",
      " aT  W  W   R a ",
      " aT           a ",
      " a!           a ",
      " abeeeeeeeeeeba ",
      " a  h j  h j  a ",
      "                "
    ],
    [
      "                ",
      " a  h j  h j  a ",
      " adeeeeeeeeeeda ",
      " a# A$        a ",
      " a9 A$        a ",
      " a8 A$      7 a ",
      " aqqy00000  7 a ",
      " a          6ka ",
      " a          Rla ",
      " a          R a ",
      " a          R a ",
      " a            a ",
      " a            a ",
      " abeeeeeeeeeeba ",
      " a  h j  h j  a ",
      "                "
    ],
    [
      "                ",
      " a  h j  h j  a ",
      " adeeeeeeeeeeda ",
      " a^ A&        a ",
      " a% A&        a ",
      " a  A       7 a ",
      " aqqy       7 a ",
      " a          7 a ",
      " a          6ka ",
      " a          Rla ",
      " a          R a ",
      " a            a ",
      " a            a ",
      " abeeeeeeeeeeba ",
      " a  h j  h j  a ",
      "                "
    ],
    [
      "                ",
      " a  h j  h j  a ",
      " adeeeeeeeeeeda ",
      " a  A         a ",
      " a  A         a ",
      " a  A       7 a ",
      " aqqy       7 a ",
      " a          7 a ",
      " a          7 a ",
      " a          *ka ",
      " a          Rla ",
      " a            a ",
      " a            a ",
      " abeeeeeeeeeeba ",
      " a  h j  h j  a ",
      "                "
    ]
  ]
}