{
  "name": "building_office3b_ground_180",
  "refpalette": "deceasedcraft:building_office3b/building_office3b_ground_palette_180",
  "xsize": 16,
  "zsize": 16,
  "slices": [
    [
      "aaaaaaaaaaaaaaaa",
      "abbbbbbbbbbbbbba",
      "aaaddddddddddaaa",
      "aadeffffffffedaa",
      "aadeggggggggedaa",
      "aadeggggggggedaa",
      "aadeggggggggedaa",
      "aadeggggggggedaa",
      "aadeggggggggedaa",
      "aadeggggggggedaa",
      "aadeggggggggedaa",
      "aadeggggggggedaa",
      "aadeffffffffedaa",
      "aaaccccccccccaaa",
      "abbbbbbbbbbbbbba",
      "aaaaaaaaaaaaaaaa"
    ],
    [
      "                ",
      " bbbbbbbbbbbbbb ",
      "  j  IF  E!DDh  ",
      "  k  CBBBBB  k  ",
      " qk   Ayyx   kq ",
      "  k          k  ",
      " lk    ww    kl ",
      "  u          t  ",
      "  s          r  ",
      " qk          kq ",
      "  k  poooon  k  ",
      " lk     m    kl ",
      "  k          k  ",
      "  jiiiiiiiiiih  ",
      " bbbbbbbbbbbbbb ",
      "                "
    ],
    [
      "                ",
      " bbbbbbbbbbbbbb ",
      "  j   IF  E  h  ",
      "  k  RQBBBB  k  ",
      " qk          kq ",
      "  k          k  ",
      " lk          kl ",
      "  P          O  ",
      "  N          M  ",
      " qk          kq ",
      "  k     L    k  ",
      " lk          kl ",
      "  k          k  ",
      "  jJKJJKJJJJih  ",
      " bbbbbbbbbbbbbb ",
      "                "
    ],
    [
      "                ",
      " bbbbbbbbbbbbbb ",
      "  j    IF    h  ",
      "  k  RRQBBB  k  ",
      " qk          kq ",
      "  k          k  ",
      " lk          kl ",
      "  k          k  ",
      "  k          k  ",
      " qk          kq ",
      "  k          k  ",
      " lk          kl ",
      "  k          k  ",
      "  jSJJJJJJJJSh  ",
      " bbbbbbbbbbbbbb ",
      "                "
    ],
    [
      "                ",
      " bbbbbbbbbbbbbb ",
      "  j     IF   h  ",
      "  k  RRRQBB  k  ",
      " qk          kq ",
      "  k          k  ",
      " lk          kl ",
      "  k          k  ",
      "  k          k  ",
      " qk          kq ",
      "  k          k  ",
      " lk          kl ",
      "  k          k  ",
      "  j  JJ SJJJ h  ",
      " bbbbbbbbbbbbbb ",
      "                "
    ],
    [
      "                ",
      " bbbbbbbbbbbbbb ",
      "  j      IF  h  ",
      "  k  RRRRTB  k  ",
      " qk          kq ",
      "  k          k  ",
      " lk          kl ",
      "  k          k  ",
      "  k          k  ",
      " qk          kq ",
      "  k          k  ",
      " lk          kl ",
      "  k          k  ",
      "  j          h  ",
      " bbbbbbbbbbbbbb ",
      "                "
    ]
  ]
}