{
  "name": "building_office3b_floor3_270",
  "refpalette": "deceasedcraft:building_office3b/building_office3b_floor3_palette_270",
  "xsize": 16,
  "zsize": 16,
  "slices": [
    [
      "                ",
      " a  j h  j h  a ",
      " abeeeeeeeeeeba ",
      " acffffffffffca ",
      " acgiiiiiiiigca ",
      " akgiiiiiiiigca ",
      " a giiiiiiiigca ",
      " a giiiiiiiigca ",
      " a giiiiiiiigca ",
      " a giiiiiiiigca ",
      " algiiiiiiiigca ",
      " acgiiiiiiiigca ",
      " acffffffffffca ",
      " adeeeeeeeeeeda ",
      " a  j h  j h  a ",
      "                "
    ],
    [
      "                ",
      " a  j h  j h  a ",
      " abeeeeeeeeeeba ",
      " a           ma ",
      " a    AAA    na ",
      " a E DABAy w oa ",
      " a E  ABA  w oa ",
      " a E DABAy   pa ",
      " a E  A!A    ma ",
      " alE DABAy xuqa ",
      " akF  AAA  x ra ",
      " a     C   x sa ",
      " a         x ta ",
      " adeeeeeeeeeeda ",
      " a  j h  j h  a ",
      "                "
    ],
    [
      "                ",
      " a  j h  j h  a ",
      " abeeeeeeeeeeba ",
      " a           Ia ",
      " a            a ",
      " a E  O       a ",
      " a E    K     a ",
      " a E  P L     a ",
      " alE         Ia ",
      " akQ  O    xJqa ",
      " a R   NM  x  a ",
      " a         x  a ",
      " a         x  a ",
      " adeeeeeeeeeeda ",
      " a  j h  j h  a ",
      "                "
    ],
    [
      "                ",
      " a  j h  j h  a ",
      " abeeeeeeeeeeba ",
      " a           Sa ",
      " a            a ",
      " a E         Ta ",
      " a E         Ua ",
      " alE          a ",
      " akQ         Sa ",
      " a R       xqqa ",
      " a R       x Va ",
      " a         x Wa ",
      " a         x Xa ",
      " adeeeeeeeeeeda ",
      " a  j h  j h  a ",
      "                "
    ],
    [
      "                ",
      " a  j h  j h  a ",
      " abeeeeeeeeeeba ",
      " a            a ",
      " a            a ",
      " a E          a ",
      " alE          a ",
      " akQ          a ",
      " a R          a ",
      " a R       xqqa ",
      " a R       x  a ",
      " a         x Ya ",
      " a         x  a ",
      " adeeeeeeeeeeda ",
      " a  j h  j h  a ",
      "                "
    ],
    [
      "                ",
      " a  j h  j h  a ",
      " abeeeeeeeeeeba ",
      " a            a ",
      " a            a ",
      " alE          a ",
      " akZ          a ",
      " a R          a ",
      " a R          a ",
      " a R       xqqa ",
      " a R       x  a ",
      " a         x  a ",
      " a         x  a ",
      " adeeeeeeeeeeda ",
      " a  j h  j h  a ",
      "                "
    ]
  ]
}