{
  "name": "building_office3b_top_90",
  "refpalette": "deceasedcraft:building_office3b/building_office3b_top_palette_90",
  "xsize": 16,
  "zsize": 16,
  "slices": [
    [
      "                ",
      " a  h j  h j  a ",
      " adeeeeeeeeeeda ",
      " acffffffffff a ",
      " acgiiiiiiiig a ",
      " acgiiiiiiiig a ",
      " acgiiiiiiiig a ",
      " acgiiiiiiiig a ",
      " acgiiiiiiiig a ",
      " acgiiiiiiiig a ",
      " acgiiiiiiiigka ",
      " acgiiiiiiiigca ",
      " acffffffffffca ",
      " abeeeeeeeeeeba ",
      " a  h j  h j  a ",
      "                "
    ],
    [
      "                ",
      " a  h j  h j  a ",
      " adeeeeeeeeeeda ",
      " aln        I a ",
      " aln    A   I a ",
      " alnoquyyEFmI a ",
      " aln pppppp I a ",
      " aln        I a ",
      " alm        I a ",
      " alm  txxD  I a ",
      " alm  sxxC  I a ",
      " a!m  rxxB    a ",
      " alm   ww     a ",
      " abeeeeeeeeeeba ",
      " a  h j  h j  a ",
      "                "
    ],
    [
      "                ",
      " a  h j  h j  a ",
      " adeeeeeeeeeeda ",
      " aJ           a ",
      " aJ           a ",
      " aJ  KLN PQ   a ",
      " aJ           a ",
      " aJ           a ",
      " aJ           a ",
      " aJ           a ",
      " aJ           a ",
      " aJ           a ",
      " aJ    MO     a ",
      " abeeeeeeeeeeba ",
      " a  h j  h j  a ",
      "                "
    ],
    [
      "                ",
      " a  h j  h j  a ",
      " adeeeeeeeeeeda ",
      " aS           a ",
      " aR           a ",
      " aS           a ",
      " aS           a ",
      " aR           a ",
      " aS           a ",
      " aS           a ",
      " aS           a ",
      " aS           a ",
      " aR           a ",
      " abeeeeeeeeeeba ",
      " a  h j  h j  a ",
      "                "
    ],
    [
      "                ",
      " a  h j  h j  a ",
      " adeeeeeeeeeeda ",
      " aT           a ",
      " aS           a ",
      " aS           a ",
      " aS           a ",
      " aS           a ",
      " aT           a ",
      " aS           a ",
      " aS           a ",
      " aS           a ",
      " aT           a ",
      " abeeeeeeeeeeba ",
      " a  h j  h j  a ",
      "                "
    ],
    [
      "                ",
      " a  h j  h j  a ",
      " adeeeeeeeeeeda ",
      " aW          Wa ",
      " aV           a ",
      " aS           a ",
      " aS           a ",
      " a            a ",
      " a            a ",
      " aS           a ",
      " a            a ",
      " aT           a ",
      " aU          Ua ",
      " abeeeeeeeeeeba ",
      " a  h j  h j  a ",
      "                "
    ],
    [
      "                ",
      " a  h j  h j  a ",
      " a eeeeeeeeee a ",
      " aZeeeeeeeeeeZa ",
      " aW          Wa ",
      " a            a ",
      " aY          Ya ",
      " a            a ",
      " a            a ",
      " aY          Ya ",
      " a            a ",
      " aU          Ua ",
      " aXeeeeeeeeeeXa ",
      " a eeeeeeeeee a ",
      " a  h j  h j  a ",
      "                "
    ],
    [
      "                ",
      " a  h j  h j  a ",
      " a            a ",
      " a eeeeeeeeee a ",
      " a0eeeeeeeeee0a ",
      " a0eeeeeeeeee0a ",
      " a0eeeeeeeeee0a ",
      " a0eeeeeeeeee0a ",
      " a0eeeeeeeeee0a ",
      " a0eeeeeeeeee0a ",
      " a0eeeeeeeeee0a ",
      " a0eeeeeeeeee0a ",
      " a eeeeeeeeee a ",
      " a            a ",
      " a  h j  h j  a ",
      "                "
    ],
    [
      "                ",
      " a  h j  h j  a ",
      " a  h j  h j  a ",
      " a  h j  h j  a ",
      " a  h j  h j  a ",
      " a  h j  h j  a ",
      " a  h j  h j  a ",
      " a  h j  h j  a ",
      " a  h j  h j  a ",
      " a  h j  h j  a ",
      " a  h j  h j  a ",
      " a  h j  h j  a ",
      " a  h j  h j  a ",
      " a  h j  h j  a ",
      " a  h j  h j  a ",
      "                "
    ],
    [
      "                ",
      " a  h j  h j  a ",
      " a  h j  h j  a ",
      " a  h j  h j  a ",
      " a  h j  h j  a ",
      " a  h j  h j  a ",
      " a  h j  h j  a ",
      " a  h j  h j  a ",
      " a  h j  h j  a ",
      " a  h j  h j  a ",
      " a  h j  h j  a ",
      " a  h j  h j  a ",
      " a  h j  h j  a ",
      " a  h j  h j  a ",
      " a  h j  h j  a ",
      "                "
    ],
    [
      "                ",
      " a            a ",
      " a            a ",
      " a            a ",
      " a            a ",
      " a            a ",
      " a            a ",
      " a            a ",
      " a            a ",
      " a            a ",
      " a            a ",
      " a            a ",
      " a            a ",
      " a            a ",
      " a            a ",
      "                "
    ]
  ]
}