{
  "name": "building_office3b_floor2_180",
  "refpalette": "deceasedcraft:building_office3b/building_office3b_floor2_palette_180",
  "xsize": 16,
  "zsize": 16,
  "slices": [
    [
      "                ",
      " aaaaaaaaaaaaaa ",
      "  dccl    kccb  ",
      "  efggggggggfe  ",
      " jefiiiiiiiifej ",
      "  efiiiiiiiife  ",
      " hefiiiiiiiifeh ",
      "  efiiiiiiiife  ",
      "  efiiiiiiiife  ",
      " jefiiiiiiiifej ",
      "  efiiiiiiiife  ",
      " hefiiiiiiiifeh ",
      "  efggggggggfe  ",
      "  dccccccccccb  ",
      " aaaaaaaaaaaaaa ",
      "                "
    ],
    [
      "                ",
      " aaaaaaaaaaaaaa ",
      "  d  kl      b  ",
      "  e  UTTTTT  e  ",
      " je          ej ",
      "  e       S  e  ",
      " he QRJ      eh ",
      "  e QPJIFED  e  ",
      "  e  PJ A    e  ",
      " je  OJ   N  ej ",
      "  eMLKJIFED  e  ",
      " heCCCB A    eh ",
      "  eyxwu      e  ",
      "  dtsrqpnoonmb  ",
      " aaaaaaaaaaaaaa ",
      "                "
    ],
    [
      "                ",
      " aaaaaaaaaaaaaa ",
      "  d   kl     b  ",
      "  e  98TTTT  e  ",
      " je          ej ",
      "  e          e  ",
      " he   4      eh ",
      "  e   43271  e  ",
      "  e  64      e  ",
      " je   4      ej ",
      "  e5 !432 1  e  ",
      " heCCCB      eh ",
      "  e   0      e  ",
      "  d   qZVYXWVb  ",
      " aaaaaaaaaaaaaa ",
      "                "
    ],
    [
      "                ",
      " aaaaaaaaaaaaaa ",
      "  d    kl    b  ",
      "  e  998TTT  e  ",
      " je          ej ",
      "  e          e  ",
      " he   4      eh ",
      "  e   4      e  ",
      "  e   4      e  ",
      " je   4      ej ",
      "  e^^^4      e  ",
      " heCCCB      eh ",
      "  e   q      e  ",
      "  d%$#q      b  ",
      " aaaaaaaaaaaaaa ",
      "                "
    ],
    [
      "                ",
      " aaaaaaaaaaaaaa ",
      "  d     kl   b  ",
      "  e  9998TT  e  ",
      " je          ej ",
      "  e          e  ",
      " he          eh ",
      "  e          e  ",
      "  e          e  ",
      " je          ej ",
      "  e*         e  ",
      " heCCCB      eh ",
      "  e   q      e  ",
      "  d&  q      b  ",
      " aaaaaaaaaaaaaa ",
      "                "
    ],
    [
      "                ",
      " aaaaaaaaaaaaaa ",
      "  d      kl  b  ",
      "  e  9999(T  e  ",
      " je          ej ",
      "  e          e  ",
      " he          eh ",
      "  e          e  ",
      "  e          e  ",
      " je          ej ",
      "  e          e  ",
      " heCCCB      eh ",
      "  e   q      e  ",
      "  d   q      b  ",
      " aaaaaaaaaaaaaa ",
      "                "
    ]
  ]
}