{
  "name": "building_office3b_floor1_180",
  "refpalette": "deceasedcraft:building_office3b/building_office3b_floor1_palette_180",
  "xsize": 16,
  "zsize": 16,
  "slices": [
    [
      "                ",
      " aaaaaaaaaaaaaa ",
      "  dccl    kccb  ",
      "  efggggggggfe  ",
      " jefiiiiiiiifej ",
      "  efiiiiiiiife  ",
      " hefiiiiiiiifeh ",
      "  efiiiiiiiife  ",
      "  efiiiiiiiife  ",
      " jefiiiiiiiifej ",
      "  efiiiiiiiife  ",
      " hefiiiiiiiifeh ",
      "  efggggggggfe  ",
      "  dccccccccccb  ",
      " aaaaaaaaaaaaaa ",
      "                "
    ],
    [
      "                ",
      " aaaaaaaaaaaaaa ",
      "  d  kl      b  ",
      "  e  SRRRRR  e  ",
      " je          ej ",
      "  e          e  ",
      " he PQF   L  eh ",
      "  e POFEDCB  e  ",
      "  e  OFN     e  ",
      " je  MF   L  ej ",
      "  eKJIFEDCB  e  ",
      " heAAAy x    eh ",
      "  e   w    u e  ",
      "  dtsrqpnoonmb  ",
      " aaaaaaaaaaaaaa ",
      "                "
    ],
    [
      "                ",
      " aaaaaaaaaaaaaa ",
      "  d   kl     b  ",
      "  e  76RRRR  e  ",
      " je          ej ",
      "  e          e  ",
      " he   0      eh ",
      "  e  50XYuW  e  ",
      "  e  40      e  ",
      " je  30      ej ",
      "  e2 10ZYXW  e  ",
      " heAAAy      eh ",
      "  e   V      e  ",
      "  d   qTUuTT!b  ",
      " aaaaaaaaaaaaaa ",
      "                "
    ],
    [
      "                ",
      " aaaaaaaaaaaaaa ",
      "  d    kl    b  ",
      "  e  776RRR  e  ",
      " je          ej ",
      "  e          e  ",
      " he   0      eh ",
      "  e   0      e  ",
      "  e   0      e  ",
      " je   0      ej ",
      "  e$$$0      e  ",
      " heAAAy      eh ",
      "  e   q      e  ",
      "  d#98q      b  ",
      " aaaaaaaaaaaaaa ",
      "                "
    ],
    [
      "                ",
      " aaaaaaaaaaaaaa ",
      "  d     kl   b  ",
      "  e  7776RR  e  ",
      " je          ej ",
      "  e          e  ",
      " he          eh ",
      "  e          e  ",
      "  e          e  ",
      " je          ej ",
      "  e&&        e  ",
      " heAAAy      eh ",
      "  e   q      e  ",
      "  d^% q      b  ",
      " aaaaaaaaaaaaaa ",
      "                "
    ],
    [
      "                ",
      " aaaaaaaaaaaaaa ",
      "  d      kl  b  ",
      "  e  7777*R  e  ",
      " je          ej ",
      "  e          e  ",
      " he          eh ",
      "  e          e  ",
      "  e          e  ",
      " je          ej ",
      "  e          e  ",
      " heAAAy      eh ",
      "  e   q      e  ",
      "  d   q      b  ",
      " aaaaaaaaaaaaaa ",
      "                "
    ]
  ]
}