{
  "name": "building_office3b_ground_270",
  "refpalette": "deceasedcraft:building_office3b/building_office3b_ground_palette_270",
  "xsize": 16,
  "zsize": 16,
  "slices": [
    [
      "aaaaaaaaaaaaaaaa",
      "abaaaaaaaaaaaaba",
      "abaddddddddddaba",
      "abdeeeeeeeeeecba",
      "abdfggggggggfcba",
      "abdfggggggggfcba",
      "abdfggggggggfcba",
      "abdfggggggggfcba",
      "abdfggggggggfcba",
      "abdfggggggggfcba",
      "abdfggggggggfcba",
      "abdfggggggggfcba",
      "abdeeeeeeeeeecba",
      "abaddddddddddaba",
      "abaaaaaaaaaaaaba",
      "aaaaaaaaaaaaaaaa"
    ],
    [
      "                ",
      " b  q l  q l  b ",
      " bhkkkktrkkkkhb ",
      " bD          ib ",
      " bD          ib ",
      " b!B      n  ib ",
      " bEBx     o  ib ",
      " b By w   om ib ",
      " b By w   o  ib ",
      " bFBA     o  ib ",
      " bIC      p  ib ",
      " b           ib ",
      " b           ib ",
      " bjkkkkuskkkkjb ",
      " b  q l  q l  b ",
      "                "
    ],
    [
      "                ",
      " b  q l  q l  b ",
      " bhkkkkOMkkkkhb ",
      " b           ib ",
      " b           Jb ",
      " bEB         Jb ",
      " b B         Jb ",
      " b B      L  Jb ",
      " bFB         Kb ",
      " bIQ         Jb ",
      " b R         Jb ",
      " b           Kb ",
      " b           Jb ",
      " bjkkkkPNkkkkjb ",
      " b  q l  q l  b ",
      "                "
    ],
    [
      "                ",
      " b  q l  q l  b ",
      " bhkkkkkkkkkkhb ",
      " b           Sb ",
      " b           Jb ",
      " b B         Jb ",
      " b B         Jb ",
      " bFB         Jb ",
      " bIQ         Jb ",
      " b R         Jb ",
      " b R         Jb ",
      " b           Jb ",
      " b           Sb ",
      " bjkkkkkkkkkkjb ",
      " b  q l  q l  b ",
      "                "
    ],
    [
      "                ",
      " b  q l  q l  b ",
      " bhkkkkkkkkkkhb ",
      " b            b ",
      " b           Jb ",
      " b B         Jb ",
      " bFB         Jb ",
      " bIQ         Sb ",
      " b R          b ",
      " b R         Jb ",
      " b R         Jb ",
      " b            b ",
      " b            b ",
      " bjkkkkkkkkkkjb ",
      " b  q l  q l  b ",
      "                "
    ],
    [
      "                ",
      " b  q l  q l  b ",
      " bhkkkkkkkkkkhb ",
      " b            b ",
      " b            b ",
      " bFB          b ",
      " bIT          b ",
      " b R          b ",
      " b R          b ",
      " b R          b ",
      " b R          b ",
      " b            b ",
      " b            b ",
      " bjkkkkkkkkkkjb ",
      " b  q l  q l  b ",
      "                "
    ]
  ]
}