{
  "name": "building_office3b_floor2",
  "refpalette": "deceasedcraft:building_office3b/building_office3b_floor2_palette",
  "xsize": 16,
  "zsize": 16,
  "slices": [
    [
      "                ",
      " aaaaaaaaaaaaaa ",
      "  bccccccccccd  ",
      "  efggggggggfe  ",
      " hefiiiiiiiifeh ",
      "  efiiiiiiiife  ",
      " jefiiiiiiiifej ",
      "  efiiiiiiiife  ",
      "  efiiiiiiiife  ",
      " hefiiiiiiiifeh ",
      "  efiiiiiiiife  ",
      " jefiiiiiiiifej ",
      "  efggggggggfe  ",
      "  bcck    lccd  ",
      " aaaaaaaaaaaaaa ",
      "                "
    ],
    [
      "                ",
      " aaaaaaaaaaaaaa ",
      "  bmnoonpqrstd  ",
      "  e      uwxye  ",
      " he    A BCCCeh ",
      "  e  DEFIJKLMe  ",
      " je  N   JO  ej ",
      "  e    A JP  e  ",
      "  e  DEFIJPQ e  ",
      " he      JRQ eh ",
      "  e  S       e  ",
      " je          ej ",
      "  e  TTTTTU  e  ",
      "  b      lk  d  ",
      " aaaaaaaaaaaaaa ",
      "                "
    ],
    [
      "                ",
      " aaaaaaaaaaaaaa ",
      "  bVWXYVZq   d  ",
      "  e      0   e  ",
      " he      BCCCeh ",
      "  e  1 234! 5e  ",
      " je      4   ej ",
      "  e      46  e  ",
      "  e  17234   e  ",
      " he      4   eh ",
      "  e          e  ",
      " je          ej ",
      "  e  TTTT89  e  ",
      "  b     lk   d  ",
      " aaaaaaaaaaaaaa ",
      "                "
    ],
    [
      "                ",
      " aaaaaaaaaaaaaa ",
      "  b      q#$%d  ",
      "  e      q   e  ",
      " he      BCCCeh ",
      "  e      4^^^e  ",
      " je      4   ej ",
      "  e      4   e  ",
      "  e      4   e  ",
      " he      4   eh ",
      "  e          e  ",
      " je          ej ",
      "  e  TTT899  e  ",
      "  b    lk    d  ",
      " aaaaaaaaaaaaaa ",
      "                "
    ],
    [
      "                ",
      " aaaaaaaaaaaaaa ",
      "  b      q  &d  ",
      "  e      q   e  ",
      " he      BCCCeh ",
      "  e         *e  ",
      " je          ej ",
      "  e          e  ",
      "  e          e  ",
      " he          eh ",
      "  e          e  ",
      " je          ej ",
      "  e  TT8999  e  ",
      "  b   lk     d  ",
      " aaaaaaaaaaaaaa ",
      "                "
    ],
    [
      "                ",
      " aaaaaaaaaaaaaa ",
      "  b      q   d  ",
      "  e      q   e  ",
      " he      BCCCeh ",
      "  e          e  ",
      " je          ej ",
      "  e          e  ",
      "  e          e  ",
      " he          eh ",
      "  e          e  ",
      " je          ej ",
      "  e  T(9999  e  ",
      "  b  lk      d  ",
      " aaaaaaaaaaaaaa ",
      "                "
    ]
  ]
}