{
  "name": "building_office3b_top_270",
  "refpalette": "deceasedcraft:building_office3b/building_office3b_top_palette_270",
  "xsize": 16,
  "zsize": 16,
  "slices": [
    [
      "                ",
      " a  j h  j h  a ",
      " abeeeeeeeeeeba ",
      " acffffffffffca ",
      " acgiiiiiiiigca ",
      " akgiiiiiiiigca ",
      " a giiiiiiiigca ",
      " a giiiiiiiigca ",
      " a giiiiiiiigca ",
      " a giiiiiiiigca ",
      " a giiiiiiiigca ",
      " a giiiiiiiigca ",
      " a ffffffffffca ",
      " adeeeeeeeeeeda ",
      " a  j h  j h  a ",
      "                "
    ],
    [
      "                ",
      " a  j h  j h  a ",
      " abeeeeeeeeeeba ",
      " a     ww   mla ",
      " a    Bxxr  m!a ",
      " a I  Cxxs  mla ",
      " a I  Dxxt  mla ",
      " a I        mla ",
      " a I        nla ",
      " a I pppppp nla ",
      " a ImFEyyuqonla ",
      " a I   A    nla ",
      " a I        nla ",
      " adeeeeeeeeeeda ",
      " a  j h  j h  a ",
      "                "
    ],
    [
      "                ",
      " a  j h  j h  a ",
      " abeeeeeeeeeeba ",
      " a     OM    Ja ",
      " a           Ja ",
      " a           Ja ",
      " a           Ja ",
      " a           Ja ",
      " a           Ja ",
      " a           Ja ",
      " a   QP NLK  Ja ",
      " a           Ja ",
      " a           Ja ",
      " adeeeeeeeeeeda ",
      " a  j h  j h  a ",
      "                "
    ],
    [
      "                ",
      " a  j h  j h  a ",
      " abeeeeeeeeeeba ",
      " a           Ra ",
      " a           Sa ",
      " a           Sa ",
      " a           Sa ",
      " a           Sa ",
      " a           Ra ",
      " a           Sa ",
      " a           Sa ",
      " a           Ra ",
      " a           Sa ",
      " adeeeeeeeeeeda ",
      " a  j h  j h  a ",
      "                "
    ],
    [
      "                ",
      " a  j h  j h  a ",
      " abeeeeeeeeeeba ",
      " a           Ta ",
      " a           Sa ",
      " a           Sa ",
      " a           Sa ",
      " a           Ta ",
      " a           Sa ",
      " a           Sa ",
      " a           Sa ",
      " a           Sa ",
      " a           Ta ",
      " adeeeeeeeeeeda ",
      " a  j h  j h  a ",
      "                "
    ],
    [
      "                ",
      " a  j h  j h  a ",
      " abeeeeeeeeeeba ",
      " aU          Ua ",
      " a           Ta ",
      " a            a ",
      " a           Sa ",
      " a            a ",
      " a            a ",
      " a           Sa ",
      " a           Sa ",
      " a           Va ",
      " aW          Wa ",
      " adeeeeeeeeeeda ",
      " a  j h  j h  a ",
      "                "
    ],
    [
      "                ",
      " a  j h  j h  a ",
      " a eeeeeeeeee a ",
      " aXeeeeeeeeeeXa ",
      " aU          Ua ",
      " a            a ",
      " aY          Ya ",
      " a            a ",
      " a            a ",
      " aY          Ya ",
      " a            a ",
      " aW          Wa ",
      " aZeeeeeeeeeeZa ",
      " a eeeeeeeeee a ",
      " a  j h  j h  a ",
      "                "
    ],
    [
      "                ",
      " a  j h  j h  a ",
      " a            a ",
      " a eeeeeeeeee a ",
      " a0eeeeeeeeee0a ",
      " a0eeeeeeeeee0a ",
      " a0eeeeeeeeee0a ",
      " a0eeeeeeeeee0a ",
      " a0eeeeeeeeee0a ",
      " a0eeeeeeeeee0a ",
      " a0eeeeeeeeee0a ",
      " a0eeeeeeeeee0a ",
      " a eeeeeeeeee a ",
      " a            a ",
      " a  j h  j h  a ",
      "                "
    ],
    [
      "                ",
      " a  j h  j h  a ",
      " a  j h  j h  a ",
      " a  j h  j h  a ",
      " a  j h  j h  a ",
      " a  j h  j h  a ",
      " a  j h  j h  a ",
      " a  j h  j h  a ",
      " a  j h  j h  a ",
      " a  j h  j h  a ",
      " a  j h  j h  a ",
      " a  j h  j h  a ",
      " a  j h  j h  a ",
      " a  j h  j h  a ",
      " a  j h  j h  a ",
      "                "
    ],
    [
      "                ",
      " a  j h  j h  a ",
      " a  j h  j h  a ",
      " a  j h  j h  a ",
      " a  j h  j h  a ",
      " a  j h  j h  a ",
      " a  j h  j h  a ",
      " a  j h  j h  a ",
      " a  j h  j h  a ",
      " a  j h  j h  a ",
      " a  j h  j h  a ",
      " a  j h  j h  a ",
      " a  j h  j h  a ",
      " a  j h  j h  a ",
      " a  j h  j h  a ",
      "                "
    ],
    [
      "                ",
      " a            a ",
      " a            a ",
      " a            a ",
      " a            a ",
      " a            a ",
      " a            a ",
      " a            a ",
      " a            a ",
      " a            a ",
      " a            a ",
      " a            a ",
      " a            a ",
      " a            a ",
      " a            a ",
      "                "
    ]
  ]
}