{
  "name": "building_office3b_floor1_270",
  "refpalette": "deceasedcraft:building_office3b/building_office3b_floor1_palette_270",
  "xsize": 16,
  "zsize": 16,
  "slices": [
    [
      "                ",
      " a  j h  j h  a ",
      " abeeeeeeeeeeba ",
      " acffffffffffca ",
      " acgiiiiiiiigca ",
      " akgiiiiiiiigca ",
      " a giiiiiiiigca ",
      " a giiiiiiiigca ",
      " a giiiiiiiigca ",
      " a giiiiiiiigca ",
      " algiiiiiiiigca ",
      " acgiiiiiiiigca ",
      " acffffffffffca ",
      " adeeeeeeeeeeda ",
      " a  j h  j h  a ",
      "                "
    ],
    [
      "                ",
      " a  j h  j h  a ",
      " abeeeeeeeeeeba ",
      " a           ma ",
      " a          una ",
      " a R  LB LB  oa ",
      " a R   C  C  oa ",
      " a R   D  Dx na ",
      " a R   EN E  pa ",
      " alR  FFFFFywqa ",
      " akS  QOOMIA ra ",
      " a    PP  JA sa ",
      " a        KA ta ",
      " adeeeeeeeeeeda ",
      " a  j h  j h  a ",
      "                "
    ],
    [
      "                ",
      " a  j h  j h  a ",
      " abeeeeeeeeeeba ",
      " a           !a ",
      " a           Ta ",
      " a R   W  W  Ta ",
      " a R   u  X  ua ",
      " a R   Y  Y  Ua ",
      " alR   X  Z  Ta ",
      " ak6  00000yVqa ",
      " a 7   5431A  a ",
      " a         A  a ",
      " a        2A  a ",
      " adeeeeeeeeeeda ",
      " a  j h  j h  a ",
      "                "
    ],
    [
      "                ",
      " a  j h  j h  a ",
      " abeeeeeeeeeeba ",
      " a            a ",
      " a            a ",
      " a R          a ",
      " a R          a ",
      " alR          a ",
      " ak6          a ",
      " a 7  00000yqqa ",
      " a 7      $A 8a ",
      " a        $A 9a ",
      " a        $A #a ",
      " adeeeeeeeeeeda ",
      " a  j h  j h  a ",
      "                "
    ],
    [
      "                ",
      " a  j h  j h  a ",
      " abeeeeeeeeeeba ",
      " a            a ",
      " a            a ",
      " a R          a ",
      " alR          a ",
      " ak6          a ",
      " a 7          a ",
      " a 7       yqqa ",
      " a 7       A  a ",
      " a        &A %a ",
      " a        &A ^a ",
      " adeeeeeeeeeeda ",
      " a  j h  j h  a ",
      "                "
    ],
    [
      "                ",
      " a  j h  j h  a ",
      " abeeeeeeeeeeba ",
      " a            a ",
      " a            a ",
      " alR          a ",
      " ak*          a ",
      " a 7          a ",
      " a 7          a ",
      " a 7       yqqa ",
      " a 7       A  a ",
      " a         A  a ",
      " a         A  a ",
      " adeeeeeeeeeeda ",
      " a  j h  j h  a ",
      "                "
    ]
  ]
}