{
  "name": "building_office3b_top_180",
  "refpalette": "deceasedcraft:building_office3b/building_office3b_top_palette_180",
  "xsize": 16,
  "zsize": 16,
  "slices": [
    [
      "                ",
      " aaaaaaaaaaaaaa ",
      "  d       kccb  ",
      "  efggggggggfe  ",
      " jefiiiiiiiifej ",
      "  efiiiiiiiife  ",
      " hefiiiiiiiifeh ",
      "  efiiiiiiiife  ",
      "  efiiiiiiiife  ",
      " jefiiiiiiiifej ",
      "  efiiiiiiiife  ",
      " hefiiiiiiiifeh ",
      "  efggggggggfe  ",
      "  dccccccccccb  ",
      " aaaaaaaaaaaaaa ",
      "                "
    ],
    [
      "                ",
      " aaaaaaaaaaaaaa ",
      "  d          b  ",
      "  eIIIIIIII  e  ",
      " je  m       ej ",
      "  e  Fp      e  ",
      " he  Ep  DCB eh ",
      "  e Ayp  xxxwe  ",
      "  e  yp  xxxwe  ",
      " je  up  tsr ej ",
      "  e  qp      e  ",
      " he  o       eh ",
      "  ennnnnmmmmme  ",
      "  dllllllll!lb  ",
      " aaaaaaaaaaaaaa ",
      "                "
    ],
    [
      "                ",
      " aaaaaaaaaaaaaa ",
      "  d          b  ",
      "  e          e  ",
      " je          ej ",
      "  e  Q       e  ",
      " he  P       eh ",
      "  e         Oe  ",
      "  e  N      Me  ",
      " je  L       ej ",
      "  e  K       e  ",
      " he          eh ",
      "  e          e  ",
      "  dJJJJJJJJJJb  ",
      " aaaaaaaaaaaaaa ",
      "                "
    ],
    [
      "                ",
      " aaaaaaaaaaaaaa ",
      "  d          b  ",
      "  e          e  ",
      " je          ej ",
      "  e          e  ",
      " he          eh ",
      "  e          e  ",
      "  e          e  ",
      " je          ej ",
      "  e          e  ",
      " he          eh ",
      "  e          e  ",
      "  dSRSSRSSSSRb  ",
      " aaaaaaaaaaaaaa ",
      "                "
    ],
    [
      "                ",
      " aaaaaaaaaaaaaa ",
      "  d          b  ",
      "  e          e  ",
      " je          ej ",
      "  e          e  ",
      " he          eh ",
      "  e          e  ",
      "  e          e  ",
      " je          ej ",
      "  e          e  ",
      " he          eh ",
      "  e          e  ",
      "  dTSSSSTSSSTb  ",
      " aaaaaaaaaaaaaa ",
      "                "
    ],
    [
      "                ",
      " aaaaaaaaaaaaaa ",
      "  dW        Ub  ",
      "  e          e  ",
      " je          ej ",
      "  e          e  ",
      " he          eh ",
      "  e          e  ",
      "  e          e  ",
      " je          ej ",
      "  e          e  ",
      " he          eh ",
      "  e          e  ",
      "  dWVSS  S TUb  ",
      " aaaaaaaaaaaaaa ",
      "                "
    ],
    [
      "                ",
      " aaaaaaaaaaaaaa ",
      "   ZW Y  Y UX   ",
      "  ee        ee  ",
      " jee        eej ",
      "  ee        ee  ",
      " hee        eeh ",
      "  ee        ee  ",
      "  ee        ee  ",
      " jee        eej ",
      "  ee        ee  ",
      " hee        eeh ",
      "  ee        ee  ",
      "   ZW Y  Y UX   ",
      " aaaaaaaaaaaaaa ",
      "                "
    ],
    [
      "                ",
      " aaaaaaaaaaaaaa ",
      "    00000000    ",
      "   eeeeeeeeee   ",
      " j eeeeeeeeee j ",
      "   eeeeeeeeee   ",
      " h eeeeeeeeee h ",
      "   eeeeeeeeee   ",
      "   eeeeeeeeee   ",
      " j eeeeeeeeee j ",
      "   eeeeeeeeee   ",
      " h eeeeeeeeee h ",
      "   eeeeeeeeee   ",
      "    00000000    ",
      " aaaaaaaaaaaaaa ",
      "                "
    ],
    [
      "                ",
      " aaaaaaaaaaaaaa ",
      "                ",
      "                ",
      " jjjjjjjjjjjjjj ",
      "                ",
      " hhhhhhhhhhhhhh ",
      "                ",
      "                ",
      " jjjjjjjjjjjjjj ",
      "                ",
      " hhhhhhhhhhhhhh ",
      "                ",
      "                ",
      " aaaaaaaaaaaaaa ",
      "                "
    ],
    [
      "                ",
      " aaaaaaaaaaaaaa ",
      "                ",
      "                ",
      " jjjjjjjjjjjjjj ",
      "                ",
      " hhhhhhhhhhhhhh ",
      "                ",
      "                ",
      " jjjjjjjjjjjjjj ",
      "                ",
      " hhhhhhhhhhhhhh ",
      "                ",
      "                ",
      " aaaaaaaaaaaaaa ",
      "                "
    ],
    [
      "                ",
      " aaaaaaaaaaaaaa ",
      "                ",
      "                ",
      "                ",
      "                ",
      "                ",
      "                ",
      "                ",
      "                ",
      "                ",
      "                ",
      "                ",
      "                ",
      " aaaaaaaaaaaaaa ",
      "                "
    ]
  ]
}