{
  "name": "building_office3b_ground_90",
  "refpalette": "deceasedcraft:building_office3b/building_office3b_ground_palette_90",
  "xsize": 16,
  "zsize": 16,
  "slices": [
    [
      "aaaaaaaaaaaaaaaa",
      "abaaaaaaaaaaaaba",
      "abaddddddddddaba",
      "abceeeeeeeeeedba",
      "abcfggggggggfdba",
      "abcfggggggggfdba",
      "abcfggggggggfdba",
      "abcfggggggggfdba",
      "abcfggggggggfdba",
      "abcfggggggggfdba",
      "abcfggggggggfdba",
      "abcfggggggggfdba",
      "abceeeeeeeeeedba",
      "abaddddddddddaba",
      "abaaaaaaaaaaaaba",
      "aaaaaaaaaaaaaaaa"
    ],
    [
      "                ",
      " b  l q  l q  b ",
      " bjkkkksukkkkjb ",
      " bi           b ",
      " bi           b ",
      " bi  p      CIb ",
      " bi  o     ABFb ",
      " bi  o   w yB b ",
      " bi mo   w yB b ",
      " bi  o     xBEb ",
      " bi  n      B!b ",
      " bi          Db ",
      " bi          Db ",
      " bhkkkkrtkkkkhb ",
      " b  l q  l q  b ",
      "                "
    ],
    [
      "                ",
      " b  l q  l q  b ",
      " bjkkkkNPkkkkjb ",
      " bJ           b ",
      " bK           b ",
      " bJ         R b ",
      " bJ         QIb ",
      " bK         BFb ",
      " bJ  L      B b ",
      " bJ         B b ",
      " bJ         BEb ",
      " bJ           b ",
      " bi           b ",
      " bhkkkkMOkkkkhb ",
      " b  l q  l q  b ",
      "                "
    ],
    [
      "                ",
      " b  l q  l q  b ",
      " bjkkkkkkkkkkjb ",
      " bS           b ",
      " bJ           b ",
      " bJ         R b ",
      " bJ         R b ",
      " bJ         QIb ",
      " bJ         BFb ",
      " bJ         B b ",
      " bJ         B b ",
      " bJ           b ",
      " bS           b ",
      " bhkkkkkkkkkkhb ",
      " b  l q  l q  b ",
      "                "
    ],
    [
      "                ",
      " b  l q  l q  b ",
      " bjkkkkkkkkkkjb ",
      " b            b ",
      " b            b ",
      " bJ         R b ",
      " bJ         R b ",
      " b          R b ",
      " bS         QIb ",
      " bJ         BFb ",
      " bJ         B b ",
      " bJ           b ",
      " b            b ",
      " bhkkkkkkkkkkhb ",
      " b  l q  l q  b ",
      "                "
    ],
    [
      "                ",
      " b  l q  l q  b ",
      " bjkkkkkkkkkkjb ",
      " b            b ",
      " b            b ",
      " b          R b ",
      " b          R b ",
      " b          R b ",
      " b          R b ",
      " b          TIb ",
      " b          BFb ",
      " b            b ",
      " b            b ",
      " bhkkkkkkkkkkhb ",
      " b  l q  l q  b ",
      "                "
    ]
  ]
}