{
  "name": "building_office3b_ground",
  "refpalette": "deceasedcraft:building_office3b/building_office3b_ground_palette",
  "xsize": 16,
  "zsize": 16,
  "slices": [
    [
      "aaaaaaaaaaaaaaaa",
      "abbbbbbbbbbbbbba",
      "aaaccccccccccaaa",
      "aadeffffffffedaa",
      "aadeggggggggedaa",
      "aadeggggggggedaa",
      "aadeggggggggedaa",
      "aadeggggggggedaa",
      "aadeggggggggedaa",
      "aadeggggggggedaa",
      "aadeggggggggedaa",
      "aadeggggggggedaa",
      "aadeffffffffedaa",
      "aaaddddddddddaaa",
      "abbbbbbbbbbbbbba",
      "aaaaaaaaaaaaaaaa"
    ],
    [
      "                ",
      " bbbbbbbbbbbbbb ",
      "  hiiiiiiiiiij  ",
      "  k          k  ",
      " lk    m     kl ",
      "  k  noooop  k  ",
      " qk          kq ",
      "  r          s  ",
      "  t          u  ",
      " lk    ww    kl ",
      "  k          k  ",
      " qk   xyyA   kq ",
      "  k  BBBBBC  k  ",
      "  hDD!E  FI  j  ",
      " bbbbbbbbbbbbbb ",
      "                "
    ],
    [
      "                ",
      " bbbbbbbbbbbbbb ",
      "  hiJJJJKJJKJj  ",
      "  k          k  ",
      " lk          kl ",
      "  k    L     k  ",
      " qk          kq ",
      "  M          N  ",
      "  O          P  ",
      " lk          kl ",
      "  k          k  ",
      " qk          kq ",
      "  k  BBBBQR  k  ",
      "  h  E  FI   j  ",
      " bbbbbbbbbbbbbb ",
      "                "
    ],
    [
      "                ",
      " bbbbbbbbbbbbbb ",
      "  hSJJJJJJJJSj  ",
      "  k          k  ",
      " lk          kl ",
      "  k          k  ",
      " qk          kq ",
      "  k          k  ",
      "  k          k  ",
      " lk          kl ",
      "  k          k  ",
      " qk          kq ",
      "  k  BBBQRR  k  ",
      "  h    FI    j  ",
      " bbbbbbbbbbbbbb ",
      "                "
    ],
    [
      "                ",
      " bbbbbbbbbbbbbb ",
      "  h JJJS JJ  j  ",
      "  k          k  ",
      " lk          kl ",
      "  k          k  ",
      " qk          kq ",
      "  k          k  ",
      "  k          k  ",
      " lk          kl ",
      "  k          k  ",
      " qk          kq ",
      "  k  BBQRRR  k  ",
      "  h   FI     j  ",
      " bbbbbbbbbbbbbb ",
      "                "
    ],
    [
      "                ",
      " bbbbbbbbbbbbbb ",
      "  h          j  ",
      "  k          k  ",
      " lk          kl ",
      "  k          k  ",
      " qk          kq ",
      "  k          k  ",
      "  k          k  ",
      " lk          kl ",
      "  k          k  ",
      " qk          kq ",
      "  k  BTRRRR  k  ",
      "  h  FI      j  ",
      " bbbbbbbbbbbbbb ",
      "                "
    ]
  ]
}