{
  "name": "building_office3b_top",
  "refpalette": "deceasedcraft:building_office3b/building_office3b_top_palette",
  "xsize": 16,
  "zsize": 16,
  "slices": [
    [
      "                ",
      " aaaaaaaaaaaaaa ",
      "  bccccccccccd  ",
      "  efggggggggfe  ",
      " hefiiiiiiiifeh ",
      "  efiiiiiiiife  ",
      " jefiiiiiiiifej ",
      "  efiiiiiiiife  ",
      "  efiiiiiiiife  ",
      " hefiiiiiiiifeh ",
      "  efiiiiiiiife  ",
      " jefiiiiiiiifej ",
      "  efggggggggfe  ",
      "  bcck       d  ",
      " aaaaaaaaaaaaaa ",
      "                "
    ],
    [
      "                ",
      " aaaaaaaaaaaaaa ",
      "  bl!lllllllld  ",
      "  emmmmmnnnnne  ",
      " he       o  eh ",
      "  e      pq  e  ",
      " je rst  pu  ej ",
      "  ewxxx  py  e  ",
      "  ewxxx  pyA e  ",
      " he BCD  pE  eh ",
      "  e      pF  e  ",
      " je       m  ej ",
      "  e  IIIIIIIIe  ",
      "  b          d  ",
      " aaaaaaaaaaaaaa ",
      "                "
    ],
    [
      "                ",
      " aaaaaaaaaaaaaa ",
      "  bJJJJJJJJJJd  ",
      "  e          e  ",
      " he          eh ",
      "  e       K  e  ",
      " je       L  ej ",
      "  eM      N  e  ",
      "  eO         e  ",
      " he       P  eh ",
      "  e       Q  e  ",
      " je          ej ",
      "  e          e  ",
      "  b          d  ",
      " aaaaaaaaaaaaaa ",
      "                "
    ],
    [
      "                ",
      " aaaaaaaaaaaaaa ",
      "  bRSSSSRSSRSd  ",
      "  e          e  ",
      " he          eh ",
      "  e          e  ",
      " je          ej ",
      "  e          e  ",
      "  e          e  ",
      " he          eh ",
      "  e          e  ",
      " je          ej ",
      "  e          e  ",
      "  b          d  ",
      " aaaaaaaaaaaaaa ",
      "                "
    ],
    [
      "                ",
      " aaaaaaaaaaaaaa ",
      "  bTSSSTSSSSTd  ",
      "  e          e  ",
      " he          eh ",
      "  e          e  ",
      " je          ej ",
      "  e          e  ",
      "  e          e  ",
      " he          eh ",
      "  e          e  ",
      " je          ej ",
      "  e          e  ",
      "  b          d  ",
      " aaaaaaaaaaaaaa ",
      "                "
    ],
    [
      "                ",
      " aaaaaaaaaaaaaa ",
      "  bUT S  SSVWd  ",
      "  e          e  ",
      " he          eh ",
      "  e          e  ",
      " je          ej ",
      "  e          e  ",
      "  e          e  ",
      " he          eh ",
      "  e          e  ",
      " je          ej ",
      "  e          e  ",
      "  bU        Wd  ",
      " aaaaaaaaaaaaaa ",
      "                "
    ],
    [
      "                ",
      " aaaaaaaaaaaaaa ",
      "   XU Y  Y WZ   ",
      "  ee        ee  ",
      " hee        eeh ",
      "  ee        ee  ",
      " jee        eej ",
      "  ee        ee  ",
      "  ee        ee  ",
      " hee        eeh ",
      "  ee        ee  ",
      " jee        eej ",
      "  ee        ee  ",
      "   XU Y  Y WZ   ",
      " aaaaaaaaaaaaaa ",
      "                "
    ],
    [
      "                ",
      " aaaaaaaaaaaaaa ",
      "    00000000    ",
      "   eeeeeeeeee   ",
      " h eeeeeeeeee h ",
      "   eeeeeeeeee   ",
      " j eeeeeeeeee j ",
      "   eeeeeeeeee   ",
      "   eeeeeeeeee   ",
      " h eeeeeeeeee h ",
      "   eeeeeeeeee   ",
      " j eeeeeeeeee j ",
      "   eeeeeeeeee   ",
      "    00000000    ",
      " aaaaaaaaaaaaaa ",
      "                "
    ],
    [
      "                ",
      " aaaaaaaaaaaaaa ",
      "                ",
      "                ",
      " hhhhhhhhhhhhhh ",
      "                ",
      " jjjjjjjjjjjjjj ",
      "                ",
      "                ",
      " hhhhhhhhhhhhhh ",
      "                ",
      " jjjjjjjjjjjjjj ",
      "                ",
      "                ",
      " aaaaaaaaaaaaaa ",
      "                "
    ],
    [
      "                ",
      " aaaaaaaaaaaaaa ",
      "                ",
      "                ",
      " hhhhhhhhhhhhhh ",
      "                ",
      " jjjjjjjjjjjjjj ",
      "                ",
      "                ",
      " hhhhhhhhhhhhhh ",
      "                ",
      " jjjjjjjjjjjjjj ",
      "                ",
      "                ",
      " aaaaaaaaaaaaaa ",
      "                "
    ],
    [
      "                ",
      " aaaaaaaaaaaaaa ",
      "                ",
      "                ",
      "                ",
      "                ",
      "                ",
      "                ",
      "                ",
      "                ",
      "                ",
      "                ",
      "                ",
      "                ",
      " aaaaaaaaaaaaaa ",
      "                "
    ]
  ]
}