{
  "name": "building_office3b_floor3",
  "refpalette": "deceasedcraft:building_office3b/building_office3b_floor3_palette",
  "xsize": 16,
  "zsize": 16,
  "slices": [
    [
      "                ",
      " aaaaaaaaaaaaaa ",
      "  bccccccccccd  ",
      "  efggggggggfe  ",
      " hefiiiiiiiifeh ",
      "  efiiiiiiiife  ",
      " jefiiiiiiiifej ",
      "  efiiiiiiiife  ",
      "  efiiiiiiiife  ",
      " hefiiiiiiiifeh ",
      "  efiiiiiiiife  ",
      " jefiiiiiiiifej ",
      "  efggggggggfe  ",
      "  bcck    lccd  ",
      " aaaaaaaaaaaaaa ",
      "                "
    ],
    [
      "                ",
      " aaaaaaaaaaaaaa ",
      "  bmnoopmqrstd  ",
      "  e      u   e  ",
      " he  ww  xxxxeh ",
      "  e          e  ",
      " je  y y y   ej ",
      "  e AAAAAAA  e  ",
      "  e ABBB!BAC e  ",
      " he AAAAAAA  eh ",
      "  e  D D D   e  ",
      " je          ej ",
      "  e  EEEEEF  e  ",
      "  b      lk  d  ",
      " aaaaaaaaaaaaaa ",
      "                "
    ],
    [
      "                ",
      " aaaaaaaaaaaaaa ",
      "  bI    Iq   d  ",
      "  e      J   e  ",
      " he      xxxxeh ",
      "  e          e  ",
      " je          ej ",
      "  e   KL  M  e  ",
      "  e       N  e  ",
      " he  O P O   eh ",
      "  e          e  ",
      " je          ej ",
      "  e  EEEEQR  e  ",
      "  b     lk   d  ",
      " aaaaaaaaaaaaaa ",
      "                "
    ],
    [
      "                ",
      " aaaaaaaaaaaaaa ",
      "  bS TU SqVWXd  ",
      "  e      q   e  ",
      " he      xxxxeh ",
      "  e          e  ",
      " je          ej ",
      "  e          e  ",
      "  e          e  ",
      " he          eh ",
      "  e          e  ",
      " je          ej ",
      "  e  EEEQRR  e  ",
      "  b    lk    d  ",
      " aaaaaaaaaaaaaa ",
      "                "
    ],
    [
      "                ",
      " aaaaaaaaaaaaaa ",
      "  b      q Y d  ",
      "  e      q   e  ",
      " he      xxxxeh ",
      "  e          e  ",
      " je          ej ",
      "  e          e  ",
      "  e          e  ",
      " he          eh ",
      "  e          e  ",
      " je          ej ",
      "  e  EEQRRR  e  ",
      "  b   lk     d  ",
      " aaaaaaaaaaaaaa ",
      "                "
    ],
    [
      "                ",
      " aaaaaaaaaaaaaa ",
      "  b      q   d  ",
      "  e      q   e  ",
      " he      xxxxeh ",
      "  e          e  ",
      " je          ej ",
      "  e          e  ",
      "  e          e  ",
      " he          eh ",
      "  e          e  ",
      " je          ej ",
      "  e  EZRRRR  e  ",
      "  b  lk      d  ",
      " aaaaaaaaaaaaaa ",
      "                "
    ]
  ]
}