{
  "name": "building_office3b_floor1",
  "refpalette": "deceasedcraft:building_office3b/building_office3b_floor1_palette",
  "xsize": 16,
  "zsize": 16,
  "slices": [
    [
      "                ",
      " aaaaaaaaaaaaaa ",
      "  bccccccccccd  ",
      "  efggggggggfe  ",
      " hefiiiiiiiifeh ",
      "  efiiiiiiiife  ",
      " jefiiiiiiiifej ",
      "  efiiiiiiiife  ",
      "  efiiiiiiiife  ",
      " hefiiiiiiiifeh ",
      "  efiiiiiiiife  ",
      " jefiiiiiiiifej ",
      "  efggggggggfe  ",
      "  bcck    lccd  ",
      " aaaaaaaaaaaaaa ",
      "                "
    ],
    [
      "                ",
      " aaaaaaaaaaaaaa ",
      "  bmnoonpqrstd  ",
      "  e u    w   e  ",
      " he    x yAAAeh ",
      "  e  BCDEFIJKe  ",
      " je  L   FM  ej ",
      "  e     NFO  e  ",
      "  e  BCDEFOP e  ",
      " he  L   FQP eh ",
      "  e          e  ",
      " je          ej ",
      "  e  RRRRRS  e  ",
      "  b      lk  d  ",
      " aaaaaaaaaaaaaa ",
      "                "
    ],
    [
      "                ",
      " aaaaaaaaaaaaaa ",
      "  b!TTuUTq   d  ",
      "  e      V   e  ",
      " he      yAAAeh ",
      "  e  WXYZ01 2e  ",
      " je      03  ej ",
      "  e      04  e  ",
      "  e  WuYX05  e  ",
      " he      0   eh ",
      "  e          e  ",
      " je          ej ",
      "  e  RRRR67  e  ",
      "  b     lk   d  ",
      " aaaaaaaaaaaaaa ",
      "                "
    ],
    [
      "                ",
      " aaaaaaaaaaaaaa ",
      "  b      q89#d  ",
      "  e      q   e  ",
      " he      yAAAeh ",
      "  e      0$$$e  ",
      " je      0   ej ",
      "  e      0   e  ",
      "  e      0   e  ",
      " he      0   eh ",
      "  e          e  ",
      " je          ej ",
      "  e  RRR677  e  ",
      "  b    lk    d  ",
      " aaaaaaaaaaaaaa ",
      "                "
    ],
    [
      "                ",
      " aaaaaaaaaaaaaa ",
      "  b      q %^d  ",
      "  e      q   e  ",
      " he      yAAAeh ",
      "  e        &&e  ",
      " je          ej ",
      "  e          e  ",
      "  e          e  ",
      " he          eh ",
      "  e          e  ",
      " je          ej ",
      "  e  RR6777  e  ",
      "  b   lk     d  ",
      " aaaaaaaaaaaaaa ",
      "                "
    ],
    [
      "                ",
      " aaaaaaaaaaaaaa ",
      "  b      q   d  ",
      "  e      q   e  ",
      " he      yAAAeh ",
      "  e          e  ",
      " je          ej ",
      "  e          e  ",
      "  e          e  ",
      " he          eh ",
      "  e          e  ",
      " je          ej ",
      "  e  R*7777  e  ",
      "  b  lk      d  ",
      " aaaaaaaaaaaaaa ",
      "                "
    ]
  ]
}