{
  "name": "building_office3b_floor3_90",
  "refpalette": "deceasedcraft:building_office3b/building_office3b_floor3_palette_90",
  "xsize": 16,
  "zsize": 16,
  "slices": [
    [
      "                ",
      " a  h j  h j  a ",
      " adeeeeeeeeeeda ",
      " acffffffffffca ",
      " acgiiiiiiiigca ",
      " acgiiiiiiiigla ",
      " acgiiiiiiiig a ",
      " acgiiiiiiiig a ",
      " acgiiiiiiiig a ",
      " acgiiiiiiiig a ",
      " acgiiiiiiiigka ",
      " acgiiiiiiiigca ",
      " acffffffffffca ",
      " abeeeeeeeeeeba ",
      " a  h j  h j  a ",
      "                "
    ],
    [
      "                ",
      " a  h j  h j  a ",
      " adeeeeeeeeeeda ",
      " at x         a ",
      " as x   C     a ",
      " ar x  AAA  Fka ",
      " aqux yABAD Ela ",
      " am    A!A  E a ",
      " ap   yABAD E a ",
      " ao w  ABA  E a ",
      " ao w yABAD E a ",
      " an    AAA    a ",
      " am           a ",
      " abeeeeeeeeeeba ",
      " a  h j  h j  a ",
      "                "
    ],
    [
      "                ",
      " a  h j  h j  a ",
      " adeeeeeeeeeeda ",
      " a  x         a ",
      " a  x         a ",
      " a  x  MN   R a ",
      " aqJx    O  Qka ",
      " aI         Ela ",
      " a     L P  E a ",
      " a     K    E a ",
      " a       O  E a ",
      " a            a ",
      " aI           a ",
      " abeeeeeeeeeeba ",
      " a  h j  h j  a ",
      "                "
    ],
    [
      "                ",
      " a  h j  h j  a ",
      " adeeeeeeeeeeda ",
      " aX x         a ",
      " aW x         a ",
      " aV x       R a ",
      " aqqx       R a ",
      " aS         Qka ",
      " a          Ela ",
      " aU         E a ",
      " aT         E a ",
      " a            a ",
      " aS           a ",
      " abeeeeeeeeeeba ",
      " a  h j  h j  a ",
      "                "
    ],
    [
      "                ",
      " a  h j  h j  a ",
      " adeeeeeeeeeeda ",
      " a  x         a ",
      " aY x         a ",
      " a  x       R a ",
      " aqqx       R a ",
      " a          R a ",
      " a          Qka ",
      " a          Ela ",
      " a          E a ",
      " a            a ",
      " a            a ",
      " abeeeeeeeeeeba ",
      " a  h j  h j  a ",
      "                "
    ],
    [
      "                ",
      " a  h j  h j  a ",
      " adeeeeeeeeeeda ",
      " a  x         a ",
      " a  x         a ",
      " a  x       R a ",
      " aqqx       R a ",
      " a          R a ",
      " a          R a ",
      " a          Zka ",
      " a          Ela ",
      " a            a ",
      " a            a ",
      " abeeeeeeeeeeba ",
      " a  h j  h j  a ",
      "                "
    ]
  ]
}