{
  "name": "building_office3b_floor2_90",
  "refpalette": "deceasedcraft:building_office3b/building_office3b_floor2_palette_90",
  "xsize": 16,
  "zsize": 16,
  "slices": [
    [
      "                ",
      " a  h j  h j  a ",
      " adeeeeeeeeeeda ",
      " acffffffffffca ",
      " acgiiiiiiiigca ",
      " acgiiiiiiiigla ",
      " acgiiiiiiiig a ",
      " acgiiiiiiiig a ",
      " acgiiiiiiiig a ",
      " acgiiiiiiiig a ",
      " acgiiiiiiiigka ",
      " acgiiiiiiiigca ",
      " acffffffffffca ",
      " abeeeeeeeeeeba ",
      " a  h j  h j  a ",
      "                "
    ],
    [
      "                ",
      " a  h j  h j  a ",
      " adeeeeeeeeeeda ",
      " atyCM        a ",
      " asxCL  QQ    a ",
      " arwCKOPPR  Uka ",
      " aquBJJJJJ  Tla ",
      " ap  I  I   T a ",
      " an AF AF   T a ",
      " ao  E  E   T a ",
      " ao  DN D S T a ",
      " an           a ",
      " am           a ",
      " abeeeeeeeeeeba ",
      " a  h j  h j  a ",
      "                "
    ],
    [
      "                ",
      " a  h j  h j  a ",
      " adeeeeeeeeeeda ",
      " a  C5        a ",
      " a  C         a ",
      " a  C! 6    9 a ",
      " aq0B44444  8ka ",
      " aZ  3  3   Tla ",
      " aV  2  2   T a ",
      " aY     7   T a ",
      " aX  1  1   T a ",
      " aW           a ",
      " aV           a ",
      " abeeeeeeeeeeba ",
      " a  h j  h j  a ",
      "                "
    ],
    [
      "                ",
      " a  h j  h j  a ",
      " adeeeeeeeeeeda ",
      " a% C^        a ",
      " a$ C^        a ",
      " a# C^      9 a ",
      " aqqB44444  9 a ",
      " a          8ka ",
      " a          Tla ",
      " a          T a ",
      " a          T a ",
      " a            a ",
      " a            a ",
      " abeeeeeeeeeeba ",
      " a  h j  h j  a ",
      "                "
    ],
    [
      "                ",
      " a  h j  h j  a ",
      " adeeeeeeeeeeda ",
      " a& C*        a ",
      " a  C         a ",
      " a  C       9 a ",
      " aqqB       9 a ",
      " a          9 a ",
      " a          8ka ",
      " a          Tla ",
      " a          T a ",
      " a            a ",
      " a            a ",
      " abeeeeeeeeeeba ",
      " a  h j  h j  a ",
      "                "
    ],
    [
      "                ",
      " a  h j  h j  a ",
      " adeeeeeeeeeeda ",
      " a  C         a ",
      " a  C         a ",
      " a  C       9 a ",
      " aqqB       9 a ",
      " a          9 a ",
      " a          9 a ",
      " a          (ka ",
      " a          Tla ",
      " a            a ",
      " a            a ",
      " abeeeeeeeeeeba ",
      " a  h j  h j  a ",
      "                "
    ]
  ]
}