{
  "name": "building_office3b_floor2_270",
  "refpalette": "deceasedcraft:building_office3b/building_office3b_floor2_palette_270",
  "xsize": 16,
  "zsize": 16,
  "slices": [
    [
      "                ",
      " a  j h  j h  a ",
      " abeeeeeeeeeeba ",
      " acffffffffffca ",
      " acgiiiiiiiigca ",
      " akgiiiiiiiigca ",
      " a giiiiiiiigca ",
      " a giiiiiiiigca ",
      " a giiiiiiiigca ",
      " a giiiiiiiigca ",
      " algiiiiiiiigca ",
      " acgiiiiiiiigca ",
      " acffffffffffca ",
      " adeeeeeeeeeeda ",
      " a  j h  j h  a ",
      "                "
    ],
    [
      "                ",
      " a  j h  j h  a ",
      " abeeeeeeeeeeba ",
      " a           ma ",
      " a           na ",
      " a T S D ND  oa ",
      " a T   E  E  oa ",
      " a T   FA FA na ",
      " a T   I  I  pa ",
      " alT  JJJJJBuqa ",
      " akU  RPPOKCwra ",
      " a    QQ  LCxsa ",
      " a        MCyta ",
      " adeeeeeeeeeeda ",
      " a  j h  j h  a ",
      "                "
    ],
    [
      "                ",
      " a  j h  j h  a ",
      " abeeeeeeeeeeba ",
      " a           Va ",
      " a           Wa ",
      " a T   1  1  Xa ",
      " a T   7     Ya ",
      " a T   2  2  Va ",
      " alT   3  3  Za ",
      " ak8  44444B0qa ",
      " a 9    6 !C  a ",
      " a         C  a ",
      " a        5C  a ",
      " adeeeeeeeeeeda ",
      " a  j h  j h  a ",
      "                "
    ],
    [
      "                ",
      " a  j h  j h  a ",
      " abeeeeeeeeeeba ",
      " a            a ",
      " a            a ",
      " a T          a ",
      " a T          a ",
      " alT          a ",
      " ak8          a ",
      " a 9  44444Bqqa ",
      " a 9      ^C #a ",
      " a        ^C $a ",
      " a        ^C %a ",
      " adeeeeeeeeeeda ",
      " a  j h  j h  a ",
      "                "
    ],
    [
      "                ",
      " a  j h  j h  a ",
      " abeeeeeeeeeeba ",
      " a            a ",
      " a            a ",
      " a T          a ",
      " alT          a ",
      " ak8          a ",
      " a 9          a ",
      " a 9       Bqqa ",
      " a 9       C  a ",
      " a         C  a ",
      " a        *C &a ",
      " adeeeeeeeeeeda ",
      " a  j h  j h  a ",
      "                "
    ],
    [
      "                ",
      " a  j h  j h  a ",
      " abeeeeeeeeeeba ",
      " a            a ",
      " a            a ",
      " alT          a ",
      " ak(          a ",
      " a 9          a ",
      " a 9          a ",
      " a 9       Bqqa ",
      " a 9       C  a ",
      " a         C  a ",
      " a         C  a ",
      " adeeeeeeeeeeda ",
      " a  j h  j h  a ",
      "                "
    ]
  ]
}