{
  "name": "multi_sunkenclub_7_ground",
  "refpalette": "deceasedcraft:multi_sunkenclub_7/multi_sunkenclub_7_ground_palette",
  "xsize": 16,
  "zsize": 16,
  "slices": [
    [
      "  abbbccbaddddae",
      "  abbccbbaddddae",
      "  abcbbbbaddddae",
      "  abccbbbaddddae",
      "  abbbcbeaffffae",
      "  abbcbbba    ae",
      "  abbcbcbaggggae",
      "  abcbcbca    ae",
      "  abbbccca    ae",
      "  abbcbcbaggggae",
      "  abbccbba    ae",
      "  abcbcbeaffffae",
      " aabbccbbaddddae",
      " abbbcbbbaddddae",
      "aabbbbcbbaddddae",
      "abbcbcbbbaddddae"
    ],
    [
      "~hi~~~~~jih~~hi~",
      "~hi~~~~~kih~~hi~",
      "~hi~~~~~~ih~~hi~",
      "~hi~~~~~~ih~~hi~",
      "~hl~~~~~mlh~~hl~",
      "~hi~~~~~~ihhhhi~",
      "~hi~~~~~~iiiiii~",
      "~hin~~~~~oppppq~",
      "~hir~~~~~oppppq~",
      "~hi~~~~~~iiiiii~",
      "~hi~~~~~~ihhhhi~",
      "~hl~~~~~mlh~~hl~",
      "hhi~~~~~~ih~~hi~",
      "hi~~~~~~~ih~~hi~",
      "hi~~~~~~jih~~hi~",
      "i~~~~~~~kih~~hi~"
    ],
    [
      "~~~~~~~~~~~~~~~~",
      "~~~~~~~~~~~~~~~~",
      "~~~~~~~~~~~~~~~~",
      "~~~~~~~~~~~~~~~~",
      "~~s~~~~~~s~~~~~~",
      "~~~~~~~~~~~~~~~~",
      "~~~~~~~~~tiiiii~",
      "~~~~~~~~~~~~~~~~",
      "~~~~~~~~~~~~~~~~",
      "~~~~~~~~~iiiiii~",
      "~~~~~~~~~~~~~~~~",
      "~~~~~~~~ s~~~~s~",
      "~~~~~~~ ~~~~~~~~",
      "~~~~~~~~~~~~~~~~",
      "~~~~~~~~~~~~~~~~",
      "~~~~~~~~~~~~~~~~"
    ],
    [
      "~~~~~~~~~~~~~~~~",
      "~~~~~~~~~~~~~~~~",
      "~~~~~~~~~~~~~~~~",
      "~~~~~~~~~~~~~~~~",
      "~~~~~~~~~~~~~~~~",
      "~~~~~~~~~~~~~~~~",
      "~~~~~~~~~~~~~~~~",
      "~~~~~~~~~~~~~~~~",
      "~~~~~~~~~~~~~~~~",
      "~~~~~~~~~~~~~~~~",
      "~~~~~~~~ ~~~~~~~",
      "~~~~~~~   ~~~~~~",
      "~~~~~~~~ ~~~~~~~",
      "~~~~~~~~~~~~~~~~",
      "~~~~~~~~~~~~~~~~",
      "~~~~~~~~~~~~~~~~"
    ],
    [
      "~~~~~~~~~~~~~~~~",
      "~~~~~~~~~~~~~~~~",
      "~~~~~~~~~~~~~~~~",
      "~~~~~~~~~~~~~~~~",
      "~~~~~~~~~~~~~~~~",
      "~~~~~~~~~~~~~~~~",
      "~~~~~~~~~~~~~~~~",
      "~~~~~~~~~~~~~~~~",
      "~~~~~~~~~~~~~~~~",
      "~~~~~~~   ~~~~~~",
      "~~~~~~     ~~~~~",
      "~~~~~~     ~~~~~",
      "~~~~~~     ~~~~~",
      "~~~~~~~   ~~~~~~",
      "~~~~~~~~~~~~~~~~",
      "~~~~~~~~~~~~~~~~"
    ],
    [
      "~~~~~~~~~~~~~~~~",
      "~~~~~~~~~~~~~~~~",
      "~~~~~~~~~~~~~~~~",
      "~~~~~~~~~~~~~~~~",
      "~~~~~~~~~~~~~~~~",
      "~~~~~~~~~~~~~~~~",
      "~~~~~~~~~~~~~~~~",
      "~~~~~~~~~~~~~~~~",
      "~~~~~~~~~~~~~~~~",
      "~~~~~~~~~~~~~~~~",
      "~~~~~~~~ ~~~~~~~",
      "~~~~~~~   ~~~~~~",
      "~~~~~~~~ ~~~~~~~",
      "~~~~~~~~~~~~~~~~",
      "~~~~~~~~~~~~~~~~",
      "~~~~~~~~~~~~~~~~"
    ]
  ]
}