{
  "name": "multi_sunkenclub_7_base2",
  "refpalette": "deceasedcraft:multi_sunkenclub_7/multi_sunkenclub_7_base2_palette",
  "xsize": 16,
  "zsize": 16,
  "slices": [
    [
      "vvvvvvvvvvvvvvvv",
      "vvvvvvvvvvvvvvvv",
      "vvvvvvvvvvvvvvvv",
      "vvvvvvvvvvvvvvvv",
      "vvvvvvvvvvvvvvvv",
      "vvvvvvvvvvvvvvvv",
      "vvvvvvvvvvvvvvvv",
      "vvvvvvvvvvvvvvvv",
      "vvvvvvvvvvvvvvvv",
      "vvvvvvvvvvvvvvvv",
      "vvvvvvvvvvvvvvvv",
      "vvvvvvvvvvvvvvvv",
      "vvvvvvvvvvvvvvvv",
      "vvvvvvvvvvvvvvvv",
      "vvvvvvvvvvvvvvvv",
      "vvvvvvvvvvvvvvvv"
    ],
    [
      "aaaaaaaaaaaaaaav",
      "aaaaaaaaaaaaaaav",
      "aaaaaaaaaaaaaaav",
      "aaaaaaaaaaaaaaav",
      "aaaaaaaaaaaaaaav",
      "aaaaaaaaaaaaaabv",
      "aaaaaaaaaaaaaabv",
      "ccccccccccccccbv",
      "ccccccccccdccebv",
      "cccccccccccdcebv",
      "cccccccccceccebv",
      "ccfccccccfdec!gv",
      "cccccccccccdcebv",
      "ecccccccccddcebv",
      "ecccccccccdecebv",
      "ecccccccccddcebv"
    ],
    [
      "aaaaaaaaaaaaaaav",
      "aaaaaaaaaaaaaaav",
      "aaaaaaaaaaaaaaav",
      "aaaaaaaaaaaaaaav",
      "ccfccccccfccchgv",
      "ccccccccccddcciv",
      "cccccccccccdcciv",
      "j  jj cccccccciv",
      "   jj      jkliv",
      "j   jj j    m iv",
      "  j         kliv",
      "  f    j f  n gv",
      "oo j jj   j mliv",
      "po     j    kliv",
      "lo jj j     m iv",
      "qo      j   kliv"
    ],
    [
      "aaaaaaaaaaacdabv",
      "ccccccccccccadbv",
      "ccccccccccccdcbv",
      "cccccccccccdccbv",
      "ccfccccccfccc gv",
      "   j  jj    nliv",
      "     j j    m iv",
      "            kliv",
      "             riv",
      "              sv",
      "             riv",
      "  f      f    gv",
      "             riv",
      "t            rsv",
      "r             iv",
      "             riv"
    ],
    [
      "ccccccccccc   iv",
      "ccccccccc     iv",
      "ccccc         iv",
      "              iv",
      "  f      f    gv",
      "             riv",
      "              iv",
      "             riv",
      "              iv",
      "              sv",
      "              iv",
      "  f      f    gv",
      "              iv",
      "              sv",
      "              iv",
      "              iv"
    ],
    [
      "cccccc        sv",
      "              iv",
      "              sv",
      "              iv",
      "  f      f    gv",
      "              sv",
      "              sv",
      "              iv",
      "               v",
      "              sv",
      "              sv",
      "  f      f    gv",
      "               v",
      "              sv",
      "              iv",
      "               v"
    ]
  ]
}