{
  "name": "multi_oasiscondo_9_base2",
  "refpalette": "deceasedcraft:multi_oasiscondo_9/multi_oasiscondo_9_base2_palette",
  "xsize": 16,
  "zsize": 16,
  "slices": [
    [
      "HHHHaHHHHHHHHabb",
      "vvvvvvvvvvvvvbbb",
      "ccccaddddddddaba",
      "  efgbbbbbbbbbbb",
      "  hegbbHHHHHHHHH",
      "hhhegbHHHHHHHHHH",
      "ffffgbHHHHHHHHHH",
      "ffffgbHHHHHHHHHH",
      "ffffgbHHHHHHHHHH",
      "ffffgbHHHHHbbbbb",
      "ffffgbHHHHbbbbbb",
      "fffiabHHHHbbbaba",
      "ffffjbHHHHHHHHvb",
      "ffffjbHHHHHHHHvb",
      "ffffjbHHHHHHHHvk",
      "ffffjbHHHHHHHHvl"
    ],
    [
      "m  nam  nm  na  ",
      "vvvvvvvvvvvvvo  ",
      "ppppa        a a",
      " eq r           ",
      " st u           ",
      "ww  u           ",
      "   xr           ",
      "    r           ",
      "   yu           ",
      "   yu           ",
      "    r           ",
      "   pa     AAAaBa",
      "    r     C  Dv ",
      "    u      E  v ",
      "    u     FIIJv ",
      "   K      LMMNv "
    ],
    [
      "    a        a  ",
      "vvvvvvvvvvvvv   ",
      "OOOOa        a a",
      "eq  r           ",
      " tw u           ",
      "    u           ",
      "   xr           ",
      "    r           ",
      "    u           ",
      "    u           ",
      "    r           ",
      "   Pa        a a",
      "    r         v ",
      "    u         v ",
      "    u         v ",
      "   Q          v "
    ],
    [
      "    a        a  ",
      "vvvvvvvvvvvvv   ",
      "RRRRa        a a",
      "q   r           ",
      "tw  u           ",
      "    u           ",
      "   xr           ",
      "    r           ",
      "    u           ",
      "    u           ",
      "    r           ",
      "    a        a a",
      "    r         v ",
      "    u         v ",
      "    u         v ",
      "    u         v "
    ],
    [
      "    a        a  ",
      "vvvvvvvvvvvvv   ",
      "jjjjSjjjjjjjjS a",
      "    jTTTTTTTTj  ",
      "w   jTTTTTTTTj  ",
      "    jTTTTTTTTj  ",
      "   xjTTTTTTTTj  ",
      "TTTTjTTTTTTTTj  ",
      "TTTTjTTTTTTTTj  ",
      "TTTTjTTTTTTTTj  ",
      "TTTTjTTTTTTTTj  ",
      "jjjjSjjjjjjjjS a",
      "TTTTjTTTTTTTTjv ",
      "TTTTjTTTTTTTTjv ",
      "TTTTjTTTTTTTTjv ",
      "TTTTjTTTTTTTTjv "
    ],
    [
      "jjjjSjjjjjjjjSUU",
      "vvvvjvvvvvvvvjUU",
      "jjjjSjjjjjjjjVjS",
      "   exiiiiiiiWjTj",
      "    xiiiiiiiijTj",
      "TTTTxiiiiiiiijTj",
      "XXXxiiiiiiiiijTj",
      "iiiiiiiiiiiiijTj",
      "iiiiiiiiiiiiYjTj",
      "iiiiiiiiiiiiijTj",
      "iiiiiiiiiiiiijTj",
      "iiiiiiiiiiiiiVjS",
      "iiiiiiiiiiiiijvU",
      "iiiiiiiiiiiiWjvU",
      "iiiiiiiiiiiiijvZ",
      "iiiiiiiiiiiiijv0"
    ]
  ]
}