{
  "name": "multi_oasiscondo_9_floor1",
  "refpalette": "deceasedcraft:multi_oasiscondo_9/multi_oasiscondo_9_floor1_palette",
  "xsize": 16,
  "zsize": 16,
  "slices": [
    [
      "    a        a  ",
      "     bccccccbbd ",
      "eeeeeb       dba",
      "    b       f b ",
      "    b           ",
      "    b           ",
      "gggbd           ",
      "                ",
      "            f   ",
      "                ",
      "                ",
      "               a",
      "                ",
      "           hf   ",
      "                ",
      "                "
    ],
    [
      "    a        a  ",
      "     bccccccbbd ",
      "eeeeeb       dba",
      "    b       h b ",
      "    b           ",
      "    b           ",
      "gggbd           ",
      "                ",
      "                ",
      "                ",
      "                ",
      "               a",
      "                ",
      "            h   ",
      "                ",
      "                "
    ],
    [
      "    a        a  ",
      "     bccccccbbd ",
      "eeeeeb       dba",
      "    b         b ",
      "    b           ",
      "    b           ",
      "gggbd           ",
      "                ",
      "                ",
      "                ",
      "                ",
      "               a",
      "                ",
      "                ",
      "                ",
      "                "
    ],
    [
      "    a        a  ",
      "     bccccccbbd ",
      "eeeeeb       dba",
      "    b         b ",
      "    b           ",
      "i   b           ",
      "jggbd           ",
      "                ",
      "                ",
      "                ",
      "                ",
      "               a",
      "                ",
      "                ",
      "                ",
      "                "
    ],
    [
      "    a        a  ",
      "     bbbbbbbbbd ",
      "eeeeebbbbbbbbbba",
      "    b        bb ",
      "k   b        bb ",
      "li  b        bb ",
      "mjgbd        bb ",
      "             bb ",
      "             bb ",
      "             bb ",
      "             bb ",
      "             bba",
      "             bb ",
      "             bb ",
      "             bb ",
      "             bb "
    ],
    [
      "nnnnannnnnnnnann",
      "nnnnnnnnnnnnnnnn",
      "nnnnnnnnnnnnnnna",
      "   obppppppppnnn",
      "qk ob      ppnnn",
      " liob       pnnn",
      "rmjbd       pnnn",
      "            pnnn",
      "            pnnn",
      "            pnnn",
      "            pnnn",
      "            pnna",
      "            pnnn",
      "            pnnn",
      "            pnnn",
      "            pnnn"
    ]
  ]
}