{
  "name": "multi_oasiscondo_9_floor10",
  "refpalette": "deceasedcraft:multi_oasiscondo_9/multi_oasiscondo_9_floor10_palette",
  "xsize": 16,
  "zsize": 16,
  "slices": [
    [
      "aaaabaaaaaaaabaa",
      "aaaaaaaaaaaaaaaa",
      "aaaaaaaaaaaaaaab",
      "cccdeffffaaaaaaa",
      " ghde   iffaaaaa",
      "  jde     ikaaaa",
      " lmen      kaaaa",
      "           ikaaa",
      "            kaaa",
      "            kaaa",
      "            kaaa",
      "           okaab",
      "            kaaa",
      "            kaaa",
      "            kaaa",
      "            kaaa"
    ],
    [
      "    b        b p",
      "                ",
      "               b",
      "lllqerrrr       ",
      "  gqe   rrr     ",
      "    e     rr    ",
      "  len      r    ",
      "           rr   ",
      "            r   ",
      "            r   ",
      "            r   ",
      "            r  b",
      "            r   ",
      "            r   ",
      "            r   ",
      "            r   "
    ],
    [
      "    b        b  ",
      "                ",
      "               b",
      "    e           ",
      "    e           ",
      "    e     r     ",
      "   en           ",
      "                ",
      "                ",
      "                ",
      "                ",
      "            r  b",
      "                ",
      "                ",
      "                ",
      "                "
    ],
    [
      "    b        b  ",
      "                ",
      "               b",
      "    e           ",
      "    e           ",
      "s   e     r     ",
      "t  en           ",
      "                ",
      "                ",
      "                ",
      "                ",
      "            r  b",
      "                ",
      "                ",
      "                ",
      "                "
    ],
    [
      "    b        b  ",
      "                ",
      "     uuuu      b",
      "    e   wuu     ",
      "h   e     w     ",
      "js  e     rxy   ",
      "mt en       y   ",
      "            xy  ",
      "             y  ",
      "             y  ",
      "             y  ",
      "            ry b",
      "             y  ",
      "             y  ",
      "             y  ",
      "             y  "
    ],
    [
      "AAAAbAAAAAAAAbAA",
      "AAAAAAAAAAAAAAAA",
      "AAAAAAAAAAAAAAAb",
      "   BeCCCCAAAAAAA",
      "gh Be   CCCAAAAA",
      " jsBe     CCAAAA",
      "lmten      CAAAA",
      "           CCAAA",
      "            CAAA",
      "            CAAA",
      "            CAAA",
      "            CAAb",
      "            CAAA",
      "            CAAA",
      "            CAAA",
      "            CAAA"
    ]
  ]
}