{
  "name": "multi_oasiscondo_9_base1",
  "refpalette": "deceasedcraft:multi_oasiscondo_9/multi_oasiscondo_9_base1_palette",
  "xsize": 16,
  "zsize": 16,
  "slices": [
    [
      "HHHHaHHHHHHHHabb",
      "vvvvvvvvvvvvvbbb",
      "ccccaddddddddaba",
      "  efgbbbbbbbbbbb",
      "  hegbbHHHHHHHHH",
      "hhhegbHHHHHHHHHH",
      "ffffgbHHHHHHHHHH",
      "ffffgbHHHHHHHHHH",
      "ffffgbHHHHHHHHHH",
      "ffffgbHHHHHbbbbb",
      "ffffgbHHHHbbbbbb",
      "fffiabHHHHbbbaba",
      "ffffjbHHHHHHHHvb",
      "ffffjbHHHHHHHHvb",
      "ffffjbHHHHHHHHvk",
      "ffffjbHHHHHHHHvl"
    ],
    [
      "m  nam  nm  na  ",
      "vvvvvvvvvvvvvo  ",
      "ppppa        a a",
      " eq r           ",
      " st u           ",
      "ww  u           ",
      "   xr  y        ",
      "    r           ",
      "   Au           ",
      "   Au           ",
      "    r           ",
      "   pa     BBBaCa",
      "    r     D  Ev ",
      "    u      F  v ",
      "    u     IJJKv ",
      "   L      MNNOv "
    ],
    [
      "    a        a  ",
      "vvvvvvvvvvvvv   ",
      "PPPPa        a a",
      "eq  r           ",
      " tw u           ",
      "    u           ",
      "   xr           ",
      "    r           ",
      "    u           ",
      "    u           ",
      "    r           ",
      "   Qa        a a",
      "    r         v ",
      "    u         v ",
      "    u         v ",
      "   R          v "
    ],
    [
      "    a        a  ",
      "vvvvvvvvvvvvv   ",
      "SSSSa        a a",
      "q   r           ",
      "tw  u           ",
      "    u           ",
      "   xr           ",
      "    r           ",
      "    u           ",
      "    u           ",
      "    r           ",
      "    a        a a",
      "    r         v ",
      "    u         v ",
      "    u         v ",
      "    u         v "
    ],
    [
      "    a        a  ",
      "vvvvvvvvvvvvv   ",
      "jjjjTjjjjjjjjT a",
      "    jUUUUUUUUj  ",
      "w   jUUUUUUUUj  ",
      "    jUUUUUUUUj  ",
      "   xjUUUUUUUUj  ",
      "UUUUjUUUUUUUUj  ",
      "UUUUjUUUUUUUUj  ",
      "UUUUjUUUUUUUUj  ",
      "UUUUjUUUUUUUUj  ",
      "jjjjTjjjjjjjjT a",
      "UUUUjUUUUUUUUjv ",
      "UUUUjUUUUUUUUjv ",
      "UUUUjUUUUUUUUjv ",
      "UUUUjUUUUUUUUjv "
    ],
    [
      "jjjjTjjjjjjjjTVV",
      "vvvvjvvvvvvvvjVV",
      "jjjjTjjjjjjjjWjT",
      "   exiiiiiiiXjUj",
      "    xiiiiiiiijUj",
      "UUUUxiiiiiiiijUj",
      "YYYxiiiiiiiiijUj",
      "iiiiiiiiiiiiijUj",
      "iiiiiiiiiiiiXjUj",
      "iiiiiiiiiiiiijUj",
      "iiiiiiiiiiiiijUj",
      "iiiiiiiiiiiiiWjT",
      "iiiiiiiiiiiiijvV",
      "iiiiiiiiiiiiZjvV",
      "iiiiiiiiiiiiijv0",
      "iiiiiiiiiiiiijv1"
    ]
  ]
}