{
  "name": "multi_oasiscondo_9_base4",
  "refpalette": "deceasedcraft:multi_oasiscondo_9/multi_oasiscondo_9_base4_palette",
  "xsize": 16,
  "zsize": 16,
  "slices": [
    [
      "aaaaaaaaaaaaaaaa",
      "aaaaaaaaaaaaaaaa",
      "aaaaaaaaaaaaaaaa",
      "aaaaaaaaaaaaaaaa",
      "aaaaaaaaaaaaaaaa",
      "aaaaaaaaaaaaaaaa",
      "aaaaaaaaaaaaaaaa",
      "aaaaaaaaaaaaaaaa",
      "aaaaaaaaaaaaaaaa",
      "aaaaaaaaaaaaaaaa",
      "aaaaaaaaaaaaaaaa",
      "aaaaaaaaaaaaaaaa",
      "aaaaaaaaaaaaaaaa",
      "aaaaaaaaaaaaaaaa",
      "aaaaaaaaaaaaaaaa",
      "aaaaaaaaaaaaaaaa"
    ],
    [
      "aaaabaaaaaaaabaa",
      "aaaaaaaaaaaaaaaa",
      "aaaabaaaaaaaabab",
      "aaaaaaaaaaaaaaaa",
      "aaaaaaaaaaaaaaaa",
      "aaaaaaaaaaaaaaaa",
      "aaaaaaaaaaaaaaaa",
      "aaaaaaaaaaaaaaaa",
      "aaaaaaaaaaaaaaaa",
      "aaaaaaaaaaaaaaaa",
      "aaaaaaaaaaaaaaaa",
      "aaaabaaaaaaaabab",
      "aaaaaaaaaaaaaaaa",
      "aaaaaaaaaaaaaaaa",
      "aaaaaaaaaaaaaaaa",
      "aaaaaaaaaaaaaaaa"
    ],
    [
      "HHHHbHHHHHHHHbcc",
      "vvvvvvvvvvvvvccc",
      "ddddbeeeeeeeebcb",
      "ffffgccccccccccc",
      "ffffgccHHHHHHHHH",
      "ffffgcHHHHHHHHHH",
      "ffffgcHHHHHHHHHH",
      "ffffgcHHHHHHHHHH",
      "ffffgcHHHHHHHHHH",
      "ffffgcHHHHHHHHHH",
      "ffffgcHHHHHccccc",
      "fffhbcHHHHcccbcb",
      "fffficHHHHHHHHvg",
      "fffficHHHHHHHHvg",
      "fffficHHHHHHHHvg",
      "fffficHHHHHHHHvb"
    ],
    [
      "j  kbj  kj  kblm",
      "vvvvvvvvvvvvvnop",
      "qqqqb        brb",
      "    s           ",
      "    t           ",
      "u   t           ",
      "   ws           ",
      "    s           ",
      "   xt           ",
      "   xt           ",
      "    s           ",
      "   qb     yyybAb",
      "    s     B  Cv ",
      "    t      D  v ",
      "    t     EFFIv ",
      "   J      KLLMvb"
    ],
    [
      "    b        b  ",
      "vvvvvvvvvvvvv   ",
      "NNNNb        b b",
      "    s           ",
      "O   t           ",
      "Pu  t           ",
      "Q  ws           ",
      "    s           ",
      "    t           ",
      "    t           ",
      "    s           ",
      "   Rb        b b",
      "    s         v ",
      "    t         v ",
      "    t         v ",
      "   S          vb"
    ],
    [
      "    b        b  ",
      "vvvvvvvvvvvvv   ",
      "NNNNb        b b",
      "    s           ",
      "TO  t           ",
      " Pu t           ",
      "UQ ws           ",
      "    s           ",
      "    t           ",
      "    t           ",
      "    s           ",
      "    b        b b",
      "    s         v ",
      "    t         v ",
      "    t         v ",
      "    t         vb"
    ]
  ]
}