{
  "name": "multi_oasiscondo_9_floor11",
  "refpalette": "deceasedcraft:multi_oasiscondo_9/multi_oasiscondo_9_floor11_palette",
  "xsize": 16,
  "zsize": 16,
  "slices": [
    [
      "aaaabaaaaaaaabaa",
      "aaaaaaaaaaaaaaaa",
      "aaaaaaaaaaaaaaab",
      "cccdeffffaaaaaaa",
      " ghde   iffaaaaa",
      "  jde     ikaaaa",
      " lmen      kaaaa",
      "           ikaaa",
      "            kaaa",
      "            kaaa",
      "            kaaa",
      "           okaab",
      "            kaaa",
      "            kaaa",
      "            kaaa",
      "            kaaa"
    ],
    [
      "    b        b  ",
      "                ",
      "               b",
      "lllpeqqqq       ",
      "  gpe   qqq     ",
      "    e     qq    ",
      "  len      q    ",
      "           qq   ",
      "            q   ",
      "            q   ",
      "            q   ",
      "            q  b",
      "            q   ",
      "            q   ",
      "            q   ",
      "            q   "
    ],
    [
      "    b        b  ",
      "                ",
      "               b",
      "    e           ",
      "    e           ",
      "    e     q     ",
      "   en           ",
      "                ",
      "                ",
      "                ",
      "                ",
      "            q  b",
      "                ",
      "                ",
      "                ",
      "                "
    ],
    [
      "    b        b  ",
      "                ",
      "               b",
      "    e           ",
      "    e           ",
      "r   e     q     ",
      "s  en           ",
      "                ",
      "                ",
      "                ",
      "                ",
      "            q  b",
      "                ",
      "                ",
      "                ",
      "                "
    ],
    [
      "    b        b  ",
      "                ",
      "     tttt      b",
      "    e   utt     ",
      "h   e     u     ",
      "jr  e     qwx   ",
      "ms en       x   ",
      "            wx  ",
      "             x  ",
      "             x  ",
      "             x  ",
      "            qx b",
      "             x  ",
      "             x  ",
      "             x  ",
      "             x  "
    ],
    [
      "yyyybyyyyyyyybyy",
      "yyyyyyyyyyyyyyyy",
      "yyyyyyyyyyyyyyyb",
      "   AeBBBByyyyyyy",
      "gh Ae   BBByyyyy",
      " jrAe     BByyyy",
      "lmsen      Byyyy",
      "           BByyy",
      "            Byyy",
      "            Byyy",
      "            Byyy",
      "            Byyb",
      "            Byyy",
      "            Byyy",
      "            Byyy",
      "            Byyy"
    ]
  ]
}