{
  "name": "multi_oasiscondo_9_ground",
  "refpalette": "deceasedcraft:multi_oasiscondo_9/multi_oasiscondo_9_ground_palette",
  "xsize": 16,
  "zsize": 16,
  "slices": [
    [
      "aaaabaaaaaaaabcd",
      "aaaaaeffffffeecd",
      "aaaaaegggggghieb",
      "  jaekl     mned",
      "   oekkl    pgcd",
      "qqqqepk     pgcd",
      "rrreiskl    pgcd",
      "ppspppkt    pgcd",
      "pppspkkl    mgcd",
      "pp!ppkl    upgcd",
      "psppkkl    wpgcd",
      "ppskkl     wpncb",
      "kkkkl      xpgcd",
      "ll l        mgcd",
      "            pgcy",
      "            pgcA"
    ],
    [
      "    b        b  ",
      "     eBBCDBBeei ",
      "EFIJIe       ieb",
      " jK e       L e ",
      "  oMe         N ",
      "OOOOe         N ",
      "PPPei         N ",
      "              N ",
      "            L N ",
      "              N ",
      "              N ",
      "              Nb",
      "              N ",
      "            L N ",
      "              N ",
      "              N "
    ],
    [
      "    b        b  ",
      "     eBBQRBBeei ",
      "FIISIe       ieb",
      "jK  e       k e ",
      " oM e           ",
      "TTTTe           ",
      "PPPei           ",
      "                ",
      "            kU  ",
      "                ",
      "                ",
      "               b",
      "                ",
      "           Uk   ",
      "                ",
      "                "
    ],
    [
      "    b        b  ",
      "     eBBVVBBeei ",
      "IIIFIe      Uieb",
      "K   e      Ukke ",
      "oM  e       U   ",
      "TTTTe           ",
      "PPPei           ",
      "            U   ",
      "           kkk  ",
      "            U   ",
      "                ",
      "               b",
      "            U   ",
      "           kkU  ",
      "            k   ",
      "                "
    ],
    [
      "    b        b  ",
      "     eBBBBBBeei ",
      "IIIIIe      kieb",
      "    e      kkke ",
      "    e       k   ",
      "TT Te           ",
      "PPPei           ",
      "            k   ",
      "           kkk  ",
      "            k   ",
      "                ",
      "               b",
      "            k   ",
      "           kkk  ",
      "            k   ",
      "                "
    ],
    [
      "    b        b  ",
      "     eBBBBBBeei ",
      "IIIIIe      Uieb",
      "    e      kkUe ",
      "    e       U   ",
      "    e           ",
      "PPPei           ",
      "            U   ",
      "            k   ",
      "            k   ",
      "                ",
      "               b",
      "            k   ",
      "           kkU  ",
      "            U   ",
      "                "
    ]
  ]
}