{
  "name": "multi_oasiscondo_9_base3",
  "refpalette": "deceasedcraft:multi_oasiscondo_9/multi_oasiscondo_9_base3_palette",
  "xsize": 16,
  "zsize": 16,
  "slices": [
    [
      "    a        a  ",
      "vvvvvvvvvvvvv   ",
      "bbbba        a a",
      "  cde           ",
      " fgdh           ",
      "  idh           ",
      " jkle           ",
      "    e           ",
      "    h           ",
      "    h           ",
      "    e           ",
      "    a        a a",
      "    e         v ",
      "    h         v ",
      "    h         v ",
      "    h         va"
    ],
    [
      "    a        a  ",
      "vvvvvvvvvvvvv   ",
      "bbbba        a a",
      " cm e           ",
      "  noh           ",
      "  j h           ",
      "  jle           ",
      "    e           ",
      "    h           ",
      "    h           ",
      "    e           ",
      "    a        a a",
      "    e         v ",
      "    h         v ",
      "    h         v ",
      "    h         va"
    ],
    [
      "    a        a  ",
      "vvvvvvvvvvvvv   ",
      " b ba        a a",
      "cm  e           ",
      " nj h           ",
      "    h           ",
      "   le           ",
      "    e           ",
      "    h           ",
      "    h           ",
      "    e           ",
      "    a        a a",
      "    e         v ",
      "    h         v ",
      "    h         v ",
      "    h         va"
    ],
    [
      "    a        a  ",
      "vvvvvvvvvvvvv   ",
      "ppppa        a a",
      "m   e           ",
      "nj  h           ",
      "    h           ",
      "   le           ",
      "    e           ",
      "    h           ",
      "    h           ",
      "    e           ",
      "    a        a a",
      "    e         v ",
      "    h         v ",
      "    h         v ",
      "    h         va"
    ],
    [
      "    a        a  ",
      "vvvvvvvvvvvvv   ",
      "qqqqrqqqqqqqqr a",
      "    qssssssssq  ",
      "j   qssssssssq  ",
      "    qssssssssq  ",
      "   lqssssssssq  ",
      "ssssqssssssssq  ",
      "ssssqssssssssq  ",
      "ssssqssssssssq  ",
      "ssssqssssssssq  ",
      "qqqqrqqqqqqqqr a",
      "ssssqssssssssqv ",
      "ssssqssssssssqv ",
      "ssssqssssssssqv ",
      "ssssqssssssssqva"
    ],
    [
      "qqqqrqqqqqqqqrtt",
      "vvvvqvvvvvvvvqtt",
      "qqqqrqqqqqqqquqr",
      "   clwwwwwwwwqsq",
      "    lwwwwwwwwqsq",
      "sssslwwwwwwwwqsq",
      "xxxlwwwwwwwwwqsq",
      "wwwwwwwwwwwwwqsq",
      "wwwwwwwwwwwwwqsq",
      "wwwwwwwwwwwwwqsq",
      "wwwwwwwwwwwwwqsq",
      "wwwwwwwwwwwwwuqr",
      "wwwwwwwwwwwwwqvq",
      "wwwwwwwwwwwwwqvq",
      "wwwwwwwwwwwwwqvq",
      "wwwwwwwwwwwwwqvr"
    ]
  ]
}