{
  "name": "multi_oasiscondo_9_top",
  "refpalette": "deceasedcraft:multi_oasiscondo_9/multi_oasiscondo_9_top_palette",
  "xsize": 16,
  "zsize": 16,
  "slices": [
    [
      "aaaabccccccccbde",
      "aaaaaaaaaaaaaafe",
      "aaaaaaaaaaaaaaab",
      "ggghiccccaaaaaaj",
      " klhi   mccaaaaj",
      "  nhi     moaaaj",
      " pqir      oaaaj",
      "           moaaj",
      "            oaaj",
      "            oaaj",
      "            oaaj",
      "           soaab",
      "            oaaj",
      "            oaaj",
      "            oaaj",
      "            oaaj"
    ],
    [
      "    b        b e",
      "               e",
      "               b",
      "ppptiuuuu      w",
      "  kti   uuu    w",
      "    i     uu   w",
      "  pir      u   w",
      "           uu  w",
      "            u  w",
      "            u  w",
      "            u  w",
      "            u  b",
      "            u  w",
      "            u  w",
      "            u  w",
      "            u  w"
    ],
    [
      "    b        b e",
      "               e",
      "               b",
      "    i          w",
      "    i          w",
      "    i     u    w",
      "   ir          w",
      "               w",
      "               w",
      "               w",
      "               w",
      "            u  b",
      "               w",
      "               w",
      "               w",
      "               w"
    ],
    [
      "    b        b  ",
      "                ",
      "               b",
      "    i           ",
      "    i           ",
      "x   i     u     ",
      "y  ir           ",
      "                ",
      "                ",
      "                ",
      "                ",
      "            u  b",
      "                ",
      "                ",
      "                ",
      "                "
    ],
    [
      "    b        b  ",
      "                ",
      "               b",
      "    i           ",
      "l   i           ",
      "nx  i     u     ",
      "qy ir           ",
      "                ",
      "                ",
      "                ",
      "                ",
      "            u  b",
      "                ",
      "                ",
      "                ",
      "                "
    ],
    [
      "AAAAb        b  ",
      "AAAAAAAAAAAAAAA ",
      "AAAAAAAAAAAAAAAb",
      "   Bi    AAAAAA ",
      "kl Bi      AAAA ",
      " nxBi     u AAA ",
      "pqyir       AAA ",
      "             AA ",
      "             AA ",
      "             AA ",
      "             AA ",
      "            uAAb",
      "             AA ",
      "             AA ",
      "             AA ",
      "             AA "
    ],
    [
      "aaaabccccccccbcC",
      "aaaaaaaaaaaaaaao",
      "aaaaaaaaaaaaaaab",
      "ggghiccccaaaaaao",
      " klhi   mccaaaao",
      "  nhi     moaaao",
      " pqir      oaaao",
      "           moaao",
      "            oaao",
      "            oaao",
      "            oaao",
      "           soaab",
      "            oaao",
      "            oaao",
      "            oaao",
      "            oaao"
    ],
    [
      "    bDDDDDDDDbDD",
      "               D",
      "               b",
      "ppptiuuuu      D",
      "  kti   uuu    D",
      "    i     uu   D",
      "  pir      u   D",
      "           uu  D",
      "            u  D",
      "            u  D",
      "            u  D",
      "            u  b",
      "            u  D",
      "            u  D",
      "            u  D",
      "            u  D"
    ],
    [
      "    b        b  ",
      "                ",
      "               b",
      "    i           ",
      "    i           ",
      "    i     u     ",
      "   ir           ",
      "                ",
      "                ",
      "                ",
      "                ",
      "            u  b",
      "                ",
      "                ",
      "                ",
      "                "
    ],
    [
      "    b        b  ",
      "                ",
      "               b",
      "    i           ",
      "E   i           ",
      "E   i     u     ",
      "y  ir           ",
      "                ",
      "                ",
      "                ",
      "                ",
      "            u  b",
      "                ",
      "                ",
      "                ",
      "                "
    ],
    [
      "    b        b  ",
      "                ",
      "     FFFF      b",
      "    i   IFF     ",
      "iE  i     I     ",
      "JE  i     uKL   ",
      "Dy ir       L   ",
      "            KL  ",
      "             L  ",
      "             L  ",
      "             L  ",
      "            uL b",
      "             L  ",
      "             L  ",
      "             L  ",
      "             L  "
    ],
    [
      "AAAAbAAAAAAAAbAA",
      "AAAAAAAAAAAAAAAA",
      "AAAAAAAAAAAAAAAb",
      "    iMMMMAAAAAAA",
      "iiENi   MMMAAAAA",
      " JENi     MMAAAA",
      "DDyir      MAAAA",
      "           MMAAA",
      "            MAAA",
      "            MAAA",
      "            MAAA",
      "            MAAb",
      "            MAAA",
      "            MAAA",
      "            MAAA",
      "            MAAA"
    ],
    [
      "mmmmmmmmmmmmmmmm",
      "mmmmmmmmmmmmmmmm",
      "mmmmmmmmmmmmmmmm",
      "mmmmimmmmmmmmmmm",
      "iiimi   mmmmmmmm",
      "  Jmi     mmmmmm",
      "DDDir      mmmmm",
      "           mmmmm",
      "            mmmm",
      "            mmmm",
      "            mmmm",
      "            mmmm",
      "            mmmm",
      "            mmmm",
      "            mmmm",
      "            mmmm"
    ],
    [
      "         OOO  OO",
      "         OOO  OO",
      "                ",
      "    iuuuu       ",
      "iiiPi   uuu   OO",
      "    i     uu  OO",
      "DDDir      u  OO",
      "           uu   ",
      "            u   ",
      "            u   ",
      "            u   ",
      "            u   ",
      "            u QQ",
      "            u QQ",
      "            u QQ",
      "            u   "
    ],
    [
      "          R    R",
      "         S S  S ",
      "                ",
      "    i           ",
      "iiiTi         S ",
      "    i          R",
      "DDDir         S ",
      "                ",
      "                ",
      "                ",
      "                ",
      "                ",
      "              QQ",
      "              QQ",
      "              QQ",
      "                "
    ],
    [
      "         RUR  RU",
      "         RRR  RR",
      "                ",
      "VVVVi           ",
      "VVVVi         RR",
      "VVVVi         RU",
      "iiiir         RR",
      "                ",
      "                ",
      "                ",
      "                ",
      "                ",
      "              QQ",
      "              QQ",
      "              QQ",
      "                "
    ],
    [
      "           R  RU",
      "         WRR  RR",
      "                ",
      "                ",
      "              RR",
      "              RU",
      "              RR",
      "                ",
      "                ",
      "                ",
      "                ",
      "                ",
      "              XX",
      "              XX",
      "              XX",
      "                "
    ],
    [
      "           R  RU",
      "          RR  RR",
      "                ",
      "                ",
      "              YR",
      "              RU",
      "              RR",
      "                ",
      "                ",
      "                ",
      "                ",
      "                ",
      "                ",
      "                ",
      "                ",
      "                "
    ],
    [
      "           R  RR",
      "           R  RR",
      "                ",
      "                ",
      "              YR",
      "                ",
      "              RR",
      "                ",
      "                ",
      "                ",
      "                ",
      "                ",
      "                ",
      "                ",
      "                ",
      "                "
    ]
  ]
}