{
  "name": "multi_oasiscondo_9_floor8",
  "refpalette": "deceasedcraft:multi_oasiscondo_9/multi_oasiscondo_9_floor8_palette",
  "xsize": 16,
  "zsize": 16,
  "slices": [
    [
      "aaaabaaaaaaaabaa",
      "aaaaaaaaaaaaaaaa",
      "aaaaaaaaaaaaaaab",
      "cccdefffffffgaaa",
      " hide      jkaaa",
      "  lde       kaaa",
      " mneo       kaaa",
      "            kaaa",
      "            kaaa",
      "            kaaa",
      "            kaaa",
      "           pkaab",
      "            kaaa",
      "            kaaa",
      "            kaaa",
      "            kaaa"
    ],
    [
      "    b        b  ",
      "                ",
      "               b",
      "mmmqerrrrrrr    ",
      "  hqe      rr   ",
      "    e       r   ",
      "  meo       r   ",
      "            r   ",
      "            r   ",
      "            r   ",
      "            r   ",
      "            r  b",
      "            r   ",
      "            r   ",
      "            r   ",
      "            r   "
    ],
    [
      "    bs       b  ",
      "               t",
      "               b",
      "    e           ",
      "    e      r    ",
      "    e           ",
      "   eo           ",
      "                ",
      "                ",
      "                ",
      "                ",
      "            r  b",
      "                ",
      "                ",
      "                ",
      "                "
    ],
    [
      "    b        b  ",
      "                ",
      "               b",
      "    e           ",
      "    e      r    ",
      "u   e           ",
      "w  eo           ",
      "                ",
      "                ",
      "                ",
      "                ",
      "            r  b",
      "                ",
      "                ",
      "                ",
      "                "
    ],
    [
      "    b        b  ",
      "                ",
      "     xxxxxxxx  b",
      "    e        y  ",
      "i   e      r y  ",
      "lu  e        y  ",
      "nw eo        y  ",
      "             y  ",
      "             y  ",
      "             y  ",
      "             y  ",
      "            ry b",
      "             y  ",
      "             y  ",
      "             y  ",
      "             y  "
    ],
    [
      "AAAAbAAAAAAAAbAA",
      "AAAAAAAAAAAAAAAA",
      "AAAAAAAAAAAAAAAb",
      "   BeCCCCCCCCAAA",
      "hi Be      CCAAA",
      " luBe       CAAA",
      "mnweo       CAAA",
      "            CAAA",
      "            CAAA",
      "            CAAA",
      "            CAAA",
      "            CAAb",
      "            CAAA",
      "            CAAA",
      "            CAAA",
      "            CAAA"
    ]
  ]
}