{
  "name": "multi_filmworkstower_4_floor3",
  "refpalette": "deceasedcraft:multi_filmworkstower_4/multi_filmworkstower_4_floor3_palette",
  "xsize": 16,
  "zsize": 16,
  "slices": [
    [
      "                ",
      "                ",
      "                ",
      "                ",
      "                ",
      "                ",
      "    aaaaaaaaaaaa",
      "    a           ",
      "    a           ",
      "    a           ",
      "    a           ",
      "    a           ",
      "    a           ",
      "    a           ",
      "    a           ",
      "    b           "
    ],
    [
      "                ",
      "                ",
      "                ",
      "                ",
      "                ",
      "                ",
      "    aaaaaaaaaaaa",
      "    a           ",
      "    a           ",
      "    a           ",
      "    a           ",
      "    a           ",
      "    a           ",
      "    a           ",
      "    a           ",
      "    bccc        "
    ],
    [
      "                ",
      "                ",
      "                ",
      "                ",
      "                ",
      "                ",
      "    aaaaaaaaaaaa",
      "    a           ",
      "    a           ",
      "    a           ",
      "    a           ",
      "    a           ",
      "    a           ",
      "    a           ",
      "    a           ",
      "    b           "
    ],
    [
      "                ",
      "                ",
      "                ",
      "                ",
      "                ",
      "                ",
      "    aaaaaaaaaaaa",
      "    a           ",
      "    a           ",
      "    a           ",
      "    a           ",
      "    a           ",
      "    a           ",
      "    a           ",
      "    a           ",
      "    b           "
    ],
    [
      "                ",
      "                ",
      "                ",
      "                ",
      "                ",
      "                ",
      "    aaaaaaaaaaaa",
      "    a           ",
      "    a           ",
      "    a           ",
      "    a           ",
      "    a           ",
      "    a           ",
      "    a           ",
      "    a           ",
      "    b           "
    ],
    [
      "                ",
      "                ",
      "                ",
      "                ",
      "                ",
      "                ",
      "    aaaaaaaaaaaa",
      "    addddddddddd",
      "    addeeeeeeeee",
      "    adeeffffffff",
      "    adefgggggggg",
      "    adefgggggggg",
      "    adeeffffffff",
      "    addeeeeeeeee",
      "    addddddddddd",
      "    bhhhhhhhhhhh"
    ]
  ]
}