{
  "name": "multi_filmworkstower_4_base1",
  "refpalette": "deceasedcraft:multi_filmworkstower_4/multi_filmworkstower_4_base1_palette",
  "xsize": 16,
  "zsize": 16,
  "slices": [
    [
      "vvvvvvvvvvvvvvvv",
      "aaaaaaaaaaaaaaaa",
      "bbbbbbbbbbbbbbbb",
      "   ccccccccccccc",
      "   c            ",
      "   c            ",
      "   c            ",
      "   c            ",
      "   ccccccccccccc",
      "                ",
      "                ",
      "                ",
      "                ",
      "                ",
      "             d  ",
      "eeeeeeeee   fd  "
    ],
    [
      "vvvvvvvvvvvvvvvv",
      "aaaaaaaaaaaaaaaa",
      "bbbbbbbbbbbbbbbb",
      "   ccccccccccccc",
      "   c            ",
      "   c            ",
      "   c            ",
      "   c            ",
      "   ccccccccccccc",
      "                ",
      "                ",
      "                ",
      "                ",
      "                ",
      "             d  ",
      "eeeeeeeeeg hfd  "
    ],
    [
      "vvvvvvvvvvvvvvvv",
      "aaaaaaaaaaaaaaaa",
      "bbbbbbbbbbbbbbbb",
      "   ccccccccccccc",
      "   c            ",
      "   c            ",
      "   c            ",
      "   c            ",
      "   ccccccccccccc",
      "                ",
      "                ",
      "                ",
      "                ",
      "                ",
      "             d  ",
      "eeeeeeeeeeiifd  "
    ],
    [
      "vvvvvvvvvvvvvvvv",
      "aaaaaaaaaaaaaaaa",
      "bbbbbbbbbbbbbbbb",
      "   ccccccccccccc",
      "   cjjjjjjjjjjjj",
      "   cjjjjjjjjjjjj",
      "   cjjjjjjjjjjjj",
      "   cjjjjjjjjjjjj",
      "   ccccccccccccc",
      "                ",
      "                ",
      "                ",
      "                ",
      "                ",
      "                ",
      "eeeeeeeeeegkfl  "
    ],
    [
      "vvvvvvvvvvvvvvvv",
      "aaaaaaaaaaaaaaaa",
      "bbbbbbbbbbbbbbbb",
      "mmmccccccccccccc",
      "mmmcnnnnnnnnnnnn",
      "mmmcnnnnnnnnnnnn",
      "mmmcnnnnnnnnnnnn",
      "mmmcnnnnnnnnnnnn",
      "mmmccccccccccccc",
      "mmmmmmmmmmmmmmmm",
      "mmmmmmmmmmmmmmmm",
      "mmmmmmmmmmmmmmmm",
      "mmmmmmmmmmmmmmmm",
      "mmmmmmmmmmmmmmmm",
      "mmmmmmmmmmmmmmmm",
      "eeeeeeeeeeemommm"
    ],
    [
      "vvvvvvvvvvvvvvvv",
      "aaaaaaaaaaaaaaaa",
      "bbbbbbbbbbbbbbbb",
      "eeeeeeeeeeeeeeee",
      "eeeeeeeeeeeeeeee",
      "eeeeeeeeeeeeeeee",
      "eeeeeeeeeeeeeeee",
      "eeeeeeeeeeeeeeee",
      "eeeeeeeeeeeeeeee",
      "eeeeeeeeeeeeeeee",
      "eeeeeeeeeeeeeeee",
      "eeeeeeeeeeeeeeee",
      "eeeeeeeeeeeeeeee",
      "eeeeeeeeeeeeeeee",
      "eeeeeeeeeeeeeeee",
      "eeeeeeeeeeeee ee"
    ]
  ]
}