{
  "name": "multi_filmworkstower_4_base2",
  "refpalette": "deceasedcraft:multi_filmworkstower_4/multi_filmworkstower_4_base2_palette",
  "xsize": 16,
  "zsize": 16,
  "slices": [
    [
      "vvvvvvvvvvvvvvvv",
      "aaaaaaaaaaaaaaaa",
      "bbbbbbbbbbbbbbbb",
      "cccccccccccccccc",
      "cccccccccccccccc",
      "cccccccccccccccc",
      "cccccccccccccccc",
      "cccccccccccccccc",
      "cccccccccccccccc",
      "cccccccccccccccc",
      "cccccccccccccccc",
      "cccccccccccccccc",
      "cccccccccccccccc",
      "cccccccccccccccc",
      "cccccccccccccddd",
      "eeeeeecccccccd  "
    ],
    [
      "vvvvvvvvvvvvvvvv",
      "aaaaaaaaaaaaaaaa",
      "bbbbbbbbbbbbbbbb",
      "   fgggghgggghgg",
      "   i            ",
      "   i            ",
      "   i            ",
      "   ijjjjkjjjjkjj",
      "   fllllfllllfll",
      "    mm m mmm  mm",
      "      m     m   ",
      "                ",
      "                ",
      "                ",
      "             dnn",
      "eeeeeeo    pqd  "
    ],
    [
      "vvvvvvvvvvvvvvvv",
      "aaaaaaaaaaaaaaaa",
      "bbbbbbbbbbbbbbbb",
      "   r sstuw xyA B",
      "                ",
      "                ",
      "                ",
      "     C D   E    ",
      "   rF I rJK Lr M",
      "                ",
      "                ",
      "                ",
      "                ",
      "                ",
      "             d  ",
      "eeeeeee     qd  "
    ],
    [
      "vvvvvvvvvvvvvvvv",
      "aaaaaaaaaaaaaaaa",
      "bbbbbbbbbbbbbbbb",
      "   N         O  ",
      "                ",
      "                ",
      "                ",
      "                ",
      "   N    N    N  ",
      "                ",
      "                ",
      "                ",
      "                ",
      "                ",
      "             d  ",
      "eeeeeeeo    qd  "
    ],
    [
      "vvvvvvvvvvvvvvvv",
      "aaaaaaaaaaaaaaaa",
      "bbbbbbbbbbbbbbbb",
      "   PQQQQRQQQQRQQ",
      "                ",
      "                ",
      "                ",
      "                ",
      "   P    P    P  ",
      "                ",
      "                ",
      "                ",
      "                ",
      "                ",
      "             d  ",
      "eeeeeeee   Sqd  "
    ],
    [
      "vvvvvvvvvvvvvvvv",
      "aaaaaaaaaaaaaaaa",
      "bbbbbbbbbbbbbbbb",
      "   TUUUUTUUUUTUU",
      "   U            ",
      "   U            ",
      "   U            ",
      "   U            ",
      "   TUUUUTUUUUTUU",
      "                ",
      "                ",
      "                ",
      "                ",
      "                ",
      "             d  ",
      "eeeeeeeeo   qd  "
    ]
  ]
}