{
  "name": "multi_filmworkstower_4_floor1",
  "refpalette": "deceasedcraft:multi_filmworkstower_4/multi_filmworkstower_4_floor1_palette",
  "xsize": 16,
  "zsize": 16,
  "slices": [
    [
      "                ",
      "                ",
      "                ",
      "                ",
      "                ",
      "                ",
      "aaaaaaaaaaaaaa  ",
      "              ab",
      "              a ",
      "              a ",
      "              ab",
      "              a ",
      "              a ",
      "              ab",
      "              a ",
      "      cd  e   fg"
    ],
    [
      "                ",
      "                ",
      "                ",
      "                ",
      "                ",
      "                ",
      "aaaaaaaaaaaaaaa ",
      "               a",
      "               a",
      "               a",
      "               a",
      "               a",
      "               a",
      "               a",
      "               a",
      "  hhhdi        f"
    ],
    [
      "                ",
      "                ",
      "                ",
      "                ",
      "                ",
      "                ",
      "aaaaaaaaaaaaaaaa",
      "                ",
      "                ",
      "                ",
      "                ",
      "                ",
      "                ",
      "  hhh           ",
      "  jjjk          ",
      "  jeel          "
    ],
    [
      "                ",
      "                ",
      "                ",
      "                ",
      "                ",
      "                ",
      "aaaaaaaaaaaaaaaa",
      "                ",
      "                ",
      "                ",
      "    mh          ",
      "   njh          ",
      "  ojjh          ",
      "  jeel          ",
      "  j  p          ",
      "  e             "
    ],
    [
      "                ",
      "                ",
      "                ",
      "                ",
      "                ",
      "                ",
      "aaaaaaaaaaaaaaaa",
      "                ",
      "                ",
      "                ",
      "    mjjh        ",
      "   jqejh        ",
      "  or ejh        ",
      "  e  st         ",
      "                ",
      "                "
    ],
    [
      "                ",
      "                ",
      "                ",
      "                ",
      "                ",
      "                ",
      "aaaaaaaaaaaaaaaa",
      "                ",
      "                ",
      "                ",
      "     ejjm       ",
      "       ejn      ",
      "       ejjr     ",
      "      ushhh     ",
      "                ",
      "        wwwwwwww"
    ]
  ]
}