{
  "name": "multi_filmworkstower_4_floor4",
  "refpalette": "deceasedcraft:multi_filmworkstower_4/multi_filmworkstower_4_floor4_palette",
  "xsize": 16,
  "zsize": 16,
  "slices": [
    [
      "                ",
      "                ",
      "                ",
      "                ",
      "                ",
      "                ",
      "    aaaaaaaaaaaa",
      "    abbbbbbbbbbb",
      "    abbbbbbbbbbb",
      "    abbbbbbbbbbb",
      "    abbbbbbbbbbb",
      "    abbbbbbbbbbb",
      "    abbbbbbbbbbb",
      "    abbbbbbbbbbb",
      "    abbbbbbbbbbb",
      "    cdddbbbbbbbb"
    ],
    [
      "                ",
      "                ",
      "                ",
      "                ",
      "                ",
      "                ",
      "    aaaaaaaaaaaa",
      "    a   e       ",
      "    a   f       ",
      "    a   gh   i  ",
      "    a   gj  k   ",
      "    a   lj  m   ",
      "    a   nj     o",
      "    a   lj      ",
      "    apqqlr      ",
      "    cddds   t   "
    ],
    [
      "                ",
      "                ",
      "                ",
      "                ",
      "                ",
      "                ",
      "    aaaaaaaaaaaa",
      "    a           ",
      "    a           ",
      "    a   u       ",
      "    a   w       ",
      "    a   x       ",
      "    a           ",
      "    a   y       ",
      "    aABCD       ",
      "    cdddE       "
    ],
    [
      "                ",
      "                ",
      "                ",
      "                ",
      "                ",
      "                ",
      "    aaaaaaaaaaaa",
      "    a           ",
      "    a           ",
      "    a           ",
      "    a           ",
      "    a           ",
      "    a           ",
      "    a           ",
      "    a!FF        ",
      "    cdddI       "
    ],
    [
      "                ",
      "                ",
      "                ",
      "                ",
      "                ",
      "                ",
      "    aaaaaaaaaaaa",
      "    a           ",
      "    a           ",
      "    a           ",
      "    a           ",
      "    a           ",
      "    a           ",
      "    a           ",
      "    a           ",
      "    cddd        "
    ],
    [
      "                ",
      "                ",
      "                ",
      "                ",
      "                ",
      "                ",
      "    aaaaaaaaaaaa",
      "    aJJJJJJJJJJJ",
      "    aJJJJJJJJJJJ",
      "    aJJJKJJJKJJJ",
      "    aJJJJJJJJJJJ",
      "    aJJJJJJJJJJJ",
      "    aJJJJJJJJJJJ",
      "    aJJJJJJJJJJJ",
      "    aJJJKJJJKJJJ",
      "    cddddddddddd"
    ]
  ]
}