{
  "name": "multi_filmworkstower_4_floor11",
  "refpalette": "deceasedcraft:multi_filmworkstower_4/multi_filmworkstower_4_floor11_palette",
  "xsize": 16,
  "zsize": 16,
  "slices": [
    [
      "                ",
      "                ",
      "                ",
      "                ",
      "                ",
      "                ",
      "    aaaaaaaaaaaa",
      "    abbbbbbbbbbb",
      "    abbbbbbbbbbb",
      "    abbbbbbbbbbb",
      "    abbbbbbbbbbb",
      "    abbbbbbbbbbb",
      "    abbbbbbbbbbb",
      "    abbbbbbbbbbb",
      "    abbbbbbbbbbb",
      "    cdddbbbbbbbb"
    ],
    [
      "                ",
      "                ",
      "                ",
      "                ",
      "                ",
      "                ",
      "    aaaaaaaaaaaa",
      "    a e      fgh",
      "    aijk     f  ",
      "    a l         ",
      "    a    e      ",
      "    a   ijk  f  ",
      "    a    l   fmn",
      "    a        fgh",
      "    aopqr    f  ",
      "    cddds       "
    ],
    [
      "                ",
      "                ",
      "                ",
      "                ",
      "                ",
      "                ",
      "    aaaaaaaaaaaa",
      "    a        ftu",
      "    a        f  ",
      "    a           ",
      "    a           ",
      "    a    w   f  ",
      "    a        fxy",
      "    a        fut",
      "    aA BC    f  ",
      "    cddd        "
    ],
    [
      "                ",
      "                ",
      "                ",
      "                ",
      "                ",
      "                ",
      "    aaaaaaaaaaaa",
      "    a           ",
      "    a           ",
      "    a           ",
      "    a           ",
      "    a           ",
      "    a           ",
      "    a           ",
      "    aDDDE       ",
      "    cddd        "
    ],
    [
      "                ",
      "                ",
      "                ",
      "                ",
      "                ",
      "                ",
      "    aaaaaaaaaaaa",
      "    a           ",
      "    a           ",
      "    a           ",
      "    a           ",
      "    a           ",
      "    a           ",
      "    a           ",
      "    aFI         ",
      "    cddd        "
    ],
    [
      "                ",
      "                ",
      "                ",
      "                ",
      "                ",
      "                ",
      "    aaaaaaaaaaaa",
      "    aJJJJJJJJJJJ",
      "    aJJJJJJJJJJJ",
      "    aJJJKJJJKJJJ",
      "    aJJJJJJJJJJJ",
      "    aJJJJJJJJJJJ",
      "    aJJJJJJJJJJJ",
      "    aJJJJJJJJJJJ",
      "    aJJJKJJJKJJJ",
      "    cddddddddddd"
    ]
  ]
}