{
  "name": "multi_filmworkstower_4_floor10",
  "refpalette": "deceasedcraft:multi_filmworkstower_4/multi_filmworkstower_4_floor10_palette",
  "xsize": 16,
  "zsize": 16,
  "slices": [
    [
      "                ",
      "                ",
      "                ",
      "                ",
      "                ",
      "                ",
      "    aaaaaaaaaaaa",
      "    abbbbbbbbbbb",
      "    abbbbbbbbbbb",
      "    abbbbbbbbbbb",
      "    abbbbbbbbbbb",
      "    abbbbbbbbbbb",
      "    abbbbbbbbbbb",
      "    abbbbbbbbbbb",
      "    abbbbbbbbbbb",
      "    cdddbbbbbbbb"
    ],
    [
      "                ",
      "                ",
      "                ",
      "                ",
      "                ",
      "                ",
      "    aaaaaaaaaaaa",
      "    a e      fgh",
      "    aijk     f l",
      "    a m         ",
      "    a    e      ",
      "    a   ijk  f  ",
      "    a    m   fno",
      "    a        fgh",
      "    apqrs    f  ",
      "    cddd!       "
    ],
    [
      "                ",
      "                ",
      "                ",
      "                ",
      "                ",
      "                ",
      "    aaaaaaaaaaaa",
      "    a        ftu",
      "    a w      f  ",
      "    a           ",
      "    a           ",
      "    a    x   f  ",
      "    a        fyA",
      "    a        ftu",
      "    aB CD    f  ",
      "    cddd        "
    ],
    [
      "                ",
      "                ",
      "                ",
      "                ",
      "                ",
      "                ",
      "    aaaaaaaaaaaa",
      "    a           ",
      "    a           ",
      "    a           ",
      "    a           ",
      "    a           ",
      "    a           ",
      "    a           ",
      "    aEEEF       ",
      "    cddd        "
    ],
    [
      "                ",
      "                ",
      "                ",
      "                ",
      "                ",
      "                ",
      "    aaaaaaaaaaaa",
      "    a           ",
      "    a           ",
      "    a           ",
      "    a           ",
      "    a           ",
      "    a           ",
      "    a           ",
      "    aIJK        ",
      "    cddd        "
    ],
    [
      "                ",
      "                ",
      "                ",
      "                ",
      "                ",
      "                ",
      "    aaaaaaaaaaaa",
      "    aLLLLLLLLLLL",
      "    aLLLLLLLLLLL",
      "    aLLLMLLLMLLL",
      "    aLLLLLLLLLLL",
      "    aLLLLLLLLLLL",
      "    aLLLLLLLLLLL",
      "    aLLLLLLLLLLL",
      "    aLLLMLLLMLLL",
      "    cddddddddddd"
    ]
  ]
}