{
  "name": "multi_filmworkstower_4_floor9",
  "refpalette": "deceasedcraft:multi_filmworkstower_4/multi_filmworkstower_4_floor9_palette",
  "xsize": 16,
  "zsize": 16,
  "slices": [
    [
      "                ",
      "                ",
      "                ",
      "                ",
      "                ",
      "                ",
      "    aaaaaaaaaaaa",
      "    abbbbbbbbbbb",
      "    abbbbbbbbbbb",
      "    abbbbbbbbbbb",
      "    abbbbbbbbbbb",
      "    abbbbbbbbbbb",
      "    abbbbbbbbbbb",
      "    abbbbbbbbbbb",
      "    abbbbbbbbbbb",
      "    cdddbbbbbbbb"
    ],
    [
      "                ",
      "                ",
      "                ",
      "                ",
      "                ",
      "                ",
      "    aaaaaaaaaaaa",
      "    a e      fgh",
      "    aijk     fl ",
      "    a m         ",
      "    a    e      ",
      "    a   ijk  f  ",
      "    a    m   fno",
      "    a        fgh",
      "    apqrs    f  ",
      "    cdddt       "
    ],
    [
      "                ",
      "                ",
      "                ",
      "                ",
      "                ",
      "                ",
      "    aaaaaaaaaaaa",
      "    a        fuw",
      "    a x      f  ",
      "    a           ",
      "    a           ",
      "    a        f  ",
      "    a        fyA",
      "    a        f B",
      "    aC DE    f  ",
      "    cddd        "
    ],
    [
      "                ",
      "                ",
      "                ",
      "                ",
      "                ",
      "                ",
      "    aaaaaaaaaaaa",
      "    a           ",
      "    a           ",
      "    a           ",
      "    a           ",
      "    a           ",
      "    a           ",
      "    a           ",
      "    aFFFI       ",
      "    cddd        "
    ],
    [
      "                ",
      "                ",
      "                ",
      "                ",
      "                ",
      "                ",
      "    aaaaaaaaaaaa",
      "    a           ",
      "    a           ",
      "    a           ",
      "    a           ",
      "    a           ",
      "    a           ",
      "    a           ",
      "    a JK        ",
      "    cddd        "
    ],
    [
      "                ",
      "                ",
      "                ",
      "                ",
      "                ",
      "                ",
      "    aaaaaaaaaaaa",
      "    aLLLLLLLLLLL",
      "    aLLLLLLLLLLL",
      "    aLLLMLLLMLLL",
      "    aLLLLLLLLLLL",
      "    aLLLLLLLLLLL",
      "    aLLLLLLLLLLL",
      "    aLLLLLLLLLLL",
      "    aLLLMLLLMLLL",
      "    cddddddddddd"
    ]
  ]
}