{
  "name": "multi_filmworkstower_4_floor6",
  "refpalette": "deceasedcraft:multi_filmworkstower_4/multi_filmworkstower_4_floor6_palette",
  "xsize": 16,
  "zsize": 16,
  "slices": [
    [
      "                ",
      "                ",
      "                ",
      "                ",
      "                ",
      "                ",
      "    aaaaaaaaaaaa",
      "    abbbbbbbbbbb",
      "    abbbbbbbbbbb",
      "    abbbbbbbbbbb",
      "    abbbbbbbbbbb",
      "    abbbbbbbbbbb",
      "    abbbbbbbbbbb",
      "    abbbbbbbbbbb",
      "    abbbbbbbbbbb",
      "    cdddbbbbbbbb"
    ],
    [
      "                ",
      "                ",
      "                ",
      "                ",
      "                ",
      "                ",
      "    aaaaaaaaaaaa",
      "    a e      fg ",
      "    ahij     kl ",
      "    a m     nopq",
      "    a  e     rs ",
      "    a hij    tu ",
      "    a  m     fg ",
      "    a        kl ",
      "    awxyA   nopq",
      "    cdddB    rs "
    ],
    [
      "                ",
      "                ",
      "                ",
      "                ",
      "                ",
      "                ",
      "    aaaaaaaaaaaa",
      "    a           ",
      "    a        CD ",
      "    a        EF ",
      "    a        I  ",
      "    a  !        ",
      "    a           ",
      "    a        CD ",
      "    aJ KL    EF ",
      "    cddd     I  "
    ],
    [
      "                ",
      "                ",
      "                ",
      "                ",
      "                ",
      "                ",
      "    aaaaaaaaaaaa",
      "    a           ",
      "    a           ",
      "    a           ",
      "    a           ",
      "    a           ",
      "    a           ",
      "    a           ",
      "    aMMMN       ",
      "    cddd        "
    ],
    [
      "                ",
      "                ",
      "                ",
      "                ",
      "                ",
      "                ",
      "    aaaaaaaaaaaa",
      "    a           ",
      "    a           ",
      "    a           ",
      "    a           ",
      "    a           ",
      "    a           ",
      "    a           ",
      "    aO P        ",
      "    cddd        "
    ],
    [
      "                ",
      "                ",
      "                ",
      "                ",
      "                ",
      "                ",
      "    aaaaaaaaaaaa",
      "    aQQQQQQQQQQQ",
      "    aQQQQQQQQQQQ",
      "    aQQQRQQQRQQQ",
      "    aQQQQQQQQQQQ",
      "    aQQQQQQQQQQQ",
      "    aQQQQQQQQQQQ",
      "    aQQQQQQQQQQQ",
      "    aQQQRQQQRQQQ",
      "    cddddddddddd"
    ]
  ]
}