{
  "name": "multi_filmworkstower_4_floor7",
  "refpalette": "deceasedcraft:multi_filmworkstower_4/multi_filmworkstower_4_floor7_palette",
  "xsize": 16,
  "zsize": 16,
  "slices": [
    [
      "                ",
      "                ",
      "                ",
      "                ",
      "                ",
      "                ",
      "    aaaaaaaaaaaa",
      "    abbbbbbbbbbb",
      "    abbbbbbbbbbb",
      "    abbbbbbbbbbb",
      "    abbbbbbbbbbb",
      "    abbbbbbbbbbb",
      "    abbbbbbbbbbb",
      "    abbbbbbbbbbb",
      "    abbbbbbbbbbb",
      "    cdddbbbbbbbb"
    ],
    [
      "                ",
      "                ",
      "                ",
      "                ",
      "                ",
      "                ",
      "    aaaaaaaaaaaa",
      "    a e      fg ",
      "    ahij     kl ",
      "    a m     nopq",
      "    a  e     rs ",
      "    a hij    tu ",
      "    a  m     fg ",
      "    a        kl ",
      "    awxyA   nopq",
      "    cddd!    rs "
    ],
    [
      "                ",
      "                ",
      "                ",
      "                ",
      "                ",
      "                ",
      "    aaaaaaaaaaaa",
      "    a           ",
      "    a B      CD ",
      "    a        EF ",
      "    a        IJ ",
      "    a  K        ",
      "    a           ",
      "    a        LD ",
      "    aM NO    EF ",
      "    cddd     IP "
    ],
    [
      "                ",
      "                ",
      "                ",
      "                ",
      "                ",
      "                ",
      "    aaaaaaaaaaaa",
      "    a           ",
      "    a           ",
      "    a           ",
      "    a           ",
      "    a           ",
      "    a           ",
      "    a           ",
      "    aQQQR       ",
      "    cddd        "
    ],
    [
      "                ",
      "                ",
      "                ",
      "                ",
      "                ",
      "                ",
      "    aaaaaaaaaaaa",
      "    a           ",
      "    a           ",
      "    a           ",
      "    a           ",
      "    a           ",
      "    a           ",
      "    a           ",
      "    a ST        ",
      "    cddd        "
    ],
    [
      "                ",
      "                ",
      "                ",
      "                ",
      "                ",
      "                ",
      "    aaaaaaaaaaaa",
      "    aUUUUUUUUUUU",
      "    aUUUUUUUUUUU",
      "    aUUUVUUUVUUU",
      "    aUUUUUUUUUUU",
      "    aUUUUUUUUUUU",
      "    aUUUUUUUUUUU",
      "    aUUUUUUUUUUU",
      "    aUUUVUUUVUUU",
      "    cddddddddddd"
    ]
  ]
}