{
  "name": "multi_filmworkstower_4_floor8",
  "refpalette": "deceasedcraft:multi_filmworkstower_4/multi_filmworkstower_4_floor8_palette",
  "xsize": 16,
  "zsize": 16,
  "slices": [
    [
      "                ",
      "                ",
      "                ",
      "                ",
      "                ",
      "                ",
      "    aaaaaaaaaaaa",
      "    abbbbbbbbbbb",
      "    abbbbbbbbbbb",
      "    abbbbbbbbbbb",
      "    abbbbbbbbbbb",
      "    abbbbbbbbbbb",
      "    abbbbbbbbbbb",
      "    abbbbbbbbbbb",
      "    abbbbbbbbbbb",
      "    cdddbbbbbbbb"
    ],
    [
      "                ",
      "                ",
      "                ",
      "                ",
      "                ",
      "                ",
      "    aaaaaaaaaaaa",
      "    a           ",
      "    ae   f f f f",
      "    ag  hhhhhhhh",
      "    ag  hiiiii!i",
      "    ag  hhhhhhhh",
      "    aj   k k k k",
      "    al          ",
      "    amno        ",
      "    cdddpppppppp"
    ],
    [
      "                ",
      "                ",
      "                ",
      "                ",
      "                ",
      "                ",
      "    aaaaaaaaaaaa",
      "    a           ",
      "    aq          ",
      "    ar      st t",
      "    au          ",
      "    aw   ts  tx ",
      "    a           ",
      "    a           ",
      "    ay          ",
      "    cdddAAAAAAAA"
    ],
    [
      "                ",
      "                ",
      "                ",
      "                ",
      "                ",
      "                ",
      "    aaaaaaaaaaaa",
      "    a           ",
      "    a           ",
      "    a           ",
      "    a           ",
      "    a           ",
      "    a           ",
      "    a           ",
      "    a           ",
      "    cdddAAAAAAAA"
    ],
    [
      "                ",
      "                ",
      "                ",
      "                ",
      "                ",
      "                ",
      "    aaaaaaaaaaaa",
      "    a           ",
      "    a           ",
      "    a           ",
      "    a           ",
      "    a           ",
      "    a           ",
      "    a           ",
      "    a           ",
      "    cdddBBBBBBBB"
    ],
    [
      "                ",
      "                ",
      "                ",
      "                ",
      "                ",
      "                ",
      "    aaaaaaaaaaaa",
      "    aCCCCCCCCCCC",
      "    aCCCCCCCCCCC",
      "    aCCCDCCCDCCC",
      "    aCCCDCCCDCCC",
      "    aCCCDCCCDCCC",
      "    aCCCCCCCCCCC",
      "    aCCCCCCCCCCC",
      "    aCCCDCCCDCCC",
      "    cddddddddddd"
    ]
  ]
}