{
  "name": "multi_filmworkstower_4_floor5",
  "refpalette": "deceasedcraft:multi_filmworkstower_4/multi_filmworkstower_4_floor5_palette",
  "xsize": 16,
  "zsize": 16,
  "slices": [
    [
      "                ",
      "                ",
      "                ",
      "                ",
      "                ",
      "                ",
      "    aaaaaaaaaaaa",
      "    abbbbbbbbbbb",
      "    abbbbbbbbbbb",
      "    abbbbbbbbbbb",
      "    abbbbbbbbbbb",
      "    abbbbbbbbbbb",
      "    abbbbbbbbbbb",
      "    abbbbbbbbbbb",
      "    abbbbbbbbbbb",
      "    cdddbbbbbbbb"
    ],
    [
      "                ",
      "                ",
      "                ",
      "                ",
      "                ",
      "                ",
      "    aaaaaaaaaaaa",
      "    a e      fg ",
      "    ahij     kl ",
      "    a m     nopq",
      "    a  e     rs ",
      "    a hij    tu ",
      "    a  m     fg ",
      "    a        kl ",
      "    awxyA   nopq",
      "    cdddB    rs "
    ],
    [
      "                ",
      "                ",
      "                ",
      "                ",
      "                ",
      "                ",
      "    aaaaaaaaaaaa",
      "    a           ",
      "    a C       D ",
      "    a        EF ",
      "    a        IJ ",
      "    a  K        ",
      "    a           ",
      "    a        LD ",
      "    aM NO    EF ",
      "    cddd     I  "
    ],
    [
      "                ",
      "                ",
      "                ",
      "                ",
      "                ",
      "                ",
      "    aaaaaaaaaaaa",
      "    a           ",
      "    a           ",
      "    a           ",
      "    a           ",
      "    a           ",
      "    a           ",
      "    a           ",
      "    aPPPQ       ",
      "    cddd        "
    ],
    [
      "                ",
      "                ",
      "                ",
      "                ",
      "                ",
      "                ",
      "    aaaaaaaaaaaa",
      "    a           ",
      "    a           ",
      "    a           ",
      "    a           ",
      "    a           ",
      "    a           ",
      "    a           ",
      "    aRST        ",
      "    cddd        "
    ],
    [
      "                ",
      "                ",
      "                ",
      "                ",
      "                ",
      "                ",
      "    aaaaaaaaaaaa",
      "    aUUUUUUUUUUU",
      "    aUUUUUUUUUUU",
      "    aUUUVUUUVUUU",
      "    aUUUUUUUUUUU",
      "    aUUUUUUUUUUU",
      "    aUUUUUUUUUUU",
      "    aUUUUUUUUUUU",
      "    aUUUVUUUVUUU",
      "    cddddddddddd"
    ]
  ]
}