{
  "name": "multi_filmworkstower_4_ground",
  "refpalette": "deceasedcraft:multi_filmworkstower_4/multi_filmworkstower_4_ground_palette",
  "xsize": 16,
  "zsize": 16,
  "slices": [
    [
      "aaaaaaaaaaaaaaaa",
      "aaaaaaaaaaaaaaaa",
      "aaaaaaaaaaaaaaaa",
      "aaaaaaaaabbbbbbb",
      "aaaaaaaaabcccccc",
      "aaaaaaaaabcccccc",
      "dddddddddbcccccc",
      "eeeeeeeeedcccccc",
      "eeeeeeeeedcccccc",
      "eeeeeeeeedcccccc",
      "eeeeeeeeedcccccc",
      "eeeeeeeeedcccccc",
      "eeeeeeeeedcccccc",
      "eeeeeeeeedcccccc",
      "eebbbeeeedcccccc",
      "eeeeeeeeedddd cc"
    ],
    [
      "                ",
      "                ",
      "        ffffggff",
      "        fhhhhhhh",
      "        fh      ",
      "        fh      ",
      "iiiiiiiiih   j  ",
      "         ikk l  ",
      "         i   m  ",
      "         i      ",
      "    no   ikk    ",
      "   pbo   i   j  ",
      "  qbbo   i   l  ",
      "  bhhr   ikk m  ",
      "  b  r   i      ",
      "  h      sdddt  "
    ],
    [
      "                ",
      "                ",
      "                ",
      "                ",
      "                ",
      "                ",
      "iiiiiiiiii      ",
      "          ikk   ",
      "          i     ",
      "          i     ",
      "    nbbo  ikk   ",
      "   buhbo  i     ",
      "  qw hbo  i     ",
      "  h  xy   ikk   ",
      "          i     ",
      "          sdddt "
    ],
    [
      "                ",
      "                ",
      "                ",
      "                ",
      "                ",
      "                ",
      "iiiiiiiiiii     ",
      "           ikk  ",
      "           i    ",
      "           i    ",
      "     hbbn  ikk  ",
      "       hbp i    ",
      "       hbbwi    ",
      "      Axoooikk  ",
      "           i    ",
      "           sdddt"
    ],
    [
      "                ",
      "                ",
      "                ",
      "                ",
      "                ",
      "                ",
      "iiiiiiiiiiii    ",
      "            ikk ",
      "            i   ",
      "            i   ",
      "       hn   ikk ",
      "        ub  i   ",
      "         qw i   ",
      "       Bhhb ikk ",
      "       Cbbb i   ",
      "        ooo sddd"
    ],
    [
      "                ",
      "                ",
      "                ",
      "                ",
      "                ",
      "                ",
      "iiiiiiiiiiiii   ",
      "             ikk",
      "             i  ",
      "             i  ",
      "             ikk",
      "             i  ",
      "             i  ",
      "          h  ikk",
      "       D  b  i  ",
      "       Bhhb  sdd"
    ]
  ]
}