{
  "name": "multi_militarybase_1_base1",
  "refpalette": "deceasedcraft:multi_militarybase_1/multi_militarybase_1_base1_palette",
  "xsize": 16,
  "zsize": 16,
  "slices": [
    [
      "vaaaaaaaaabbbc  ",
      "vaaaaaaadabbbc  ",
      "vvcccvcccccccvcc",
      "vaaaacadaabbbcbb",
      "vaaaacaaaabbbcbb",
      "vaaaacaaaadbbcbe",
      "vaaaacaadaaafvgg",
      "vaaaacadaaaaacaa",
      "vaaaacaaaaadacaa",
      "vaaaacaaaadaacaa",
      "vvcccvcccccccvcc",
      "vaaaacaaaaaaachh",
      "vaaaacaaaaaaachh",
      "vaaaacaaaaaaachh",
      "vaaaavaaaaaaavhh",
      "vvvvvvvvvvvvvvvv"
    ],
    [
      "vi       j   k  ",
      "vl  mno  o   k  ",
      "vvp  v       vkk",
      "vqrs t       u  ",
      "v w  t x yA  B  ",
      "v C Dt E y F    ",
      "v w  tx  I Afv  ",
      "vJ K t   L      ",
      "v w  t   o      ",
      "vq   t        MN",
      "vvpx vtttttttvOO",
      "vP         Q pR ",
      "vP   m S T S pOO",
      "vUVWXp  Y Z  pR ",
      "v0110v 23W42 vOO",
      "vvvvvvvvvvvvvvvv"
    ],
    [
      "v!              ",
      "vl              ",
      "vvp  v       v  ",
      "v    t          ",
      "v    t          ",
      "v5   t   y      ",
      "v    t   I   v  ",
      "v5   t   L      ",
      "v    t          ",
      "v    t          ",
      "vvp  vtttttttvOO",
      "v6           p7 ",
      "v            pOO",
      "v    p       p  ",
      "v    v 8   8 vOO",
      "vvvvvvvvvvvvvvvv"
    ],
    [
      "vi              ",
      "vl              ",
      "vvp  v       v  ",
      "v    t          ",
      "v    t          ",
      "v    t          ",
      "v    t   y   v  ",
      "v    t   L      ",
      "v    t          ",
      "v    t          ",
      "vvp  vtttttttvOO",
      "v            p  ",
      "v            pOO",
      "v    p       p  ",
      "v9#$9v       vOO",
      "vvvvvvvvvvvvvvvv"
    ],
    [
      "v            t  ",
      "v            t  ",
      "vvpppv       vtt",
      "v    k          ",
      "v    k          ",
      "v    k          ",
      "v    k       v  ",
      "v    k   y      ",
      "v    k          ",
      "v    k          ",
      "vvpppvkkkkkkkvOO",
      "v    p       p%%",
      "v    p       p%%",
      "v    p       p%%",
      "v9  9v       v%%",
      "vvvvvvvvvvvvvvvv"
    ],
    [
      "v^&&&&&&&&&&&c**",
      "v^&&&&&&&&&&&c**",
      "vvcccvcccccccvcc",
      "v^&&&c&&&&&&&c&&",
      "v^&&&c&&&&&&&c&&",
      "v^&&&c&&& &&&c&&",
      "v^&&&c&&& &&&v&&",
      "v^&&&c&&& &&&c&&",
      "v^&&&c&&&y&&&c&&",
      "v^&&&c&&& &&&c&&",
      "vvcccvcccccccvcc",
      "v!&&&c&&&&&&&c (",
      "v^&&&c&)&&&)&c  ",
      "v^&&&c&&&&&&&c( ",
      "v^^^^v^^^^^^^v^^",
      "vvvvvvvvvvvvvvvv"
    ]
  ]
}