{
  "name": "multi_militarybase_1_ground",
  "refpalette": "deceasedcraft:multi_militarybase_1/multi_militarybase_1_ground_palette",
  "xsize": 16,
  "zsize": 16,
  "slices": [
    [
      "abcccccccccccccc",
      "abcccdccccdcdccc",
      "efczczzcgggggggg",
      "zfzzzzzcghhhhggg",
      "zfzzzzzzghhhhggg",
      "zfzczzzcghhhhggg",
      "zfczzzzcg hhhggg",
      "zfzzczzcg hhhhhh",
      "zfzzzzzig hhhhhh",
      "zfzzzzczgjhhhhhh",
      "zfzzzzzcghhhhhhh",
      "zfzzczzcgggggggg",
      "zfczzzczcccczzcc",
      "zfcczzzcczzzzczz",
      "zfffffffffffffff",
      "zzzzzzzzzzzzzzzz"
    ],
    [
      "klmnom l p   q  ",
      "r sm    tu     w",
      " f  xyABCCCCCCD ",
      " fE  t ACFFFFC I",
      " fJ   KKCL M C  ",
      " f N  K C    C  ",
      " fOPK QRC    CCS",
      " f K  K C    TU ",
      " f K    C       ",
      " fK     C     tV",
      " f   NK C      W",
      " fK  X  CCCCCCCC",
      " f      Y       ",
      " fO KK  O K K  K",
      " fffffffffffffff",
      "                "
    ],
    [
      "                ",
      " Z              ",
      " f      001100  ",
      " f      023  0  ",
      " f      1    1  ",
      " f      1    0  ",
      " fOP    0    004",
      " f      0    T 5",
      " f      1       ",
      " f      1       ",
      " f      0       ",
      " f      01111000",
      " f      Y       ",
      " fO     O       ",
      " fffffffffffffff",
      "                "
    ],
    [
      "                ",
      "                ",
      " f      001100  ",
      " f     60    0  ",
      " f     60    1  ",
      " f     60    0  ",
      " fOP   60    000",
      " f     60    T  ",
      " f     60       ",
      " f     60       ",
      " f     60       ",
      " f      00000000",
      " f      Y6666   ",
      " fO     O       ",
      " fffffffffffffff",
      "                "
    ],
    [
      "                ",
      "                ",
      " f      000000  ",
      " f      07   0  ",
      " f      87   0  ",
      " f      87   0  ",
      " fOP    07   008",
      " f      07   T77",
      " f      87      ",
      " f      87      ",
      " f      077777  ",
      " f      08888000",
      " f      Y       ",
      " fO     O       ",
      " fffffffffffffff",
      "                "
    ],
    [
      "        C9999C  ",
      "        C9999C  ",
      " Z      C####C  ",
      " Z      C####C  ",
      " Z      C####C  ",
      " Z$     C####C  ",
      "%^&P    C####CCC",
      " *$     C####T##",
      " Z$     C#######",
      " Z$     C#######",
      " Z$     C#####  ",
      " Z$     CCCCCCCC",
      " Z$     Y       ",
      " (&$$$$$&$$$$$$$",
      " (()+)))-)))))))",
      "                "
    ]
  ]
}