{
  "name": "multi_militarybase_1_base2",
  "refpalette": "deceasedcraft:multi_militarybase_1/multi_militarybase_1_base2_palette",
  "xsize": 16,
  "zsize": 16,
  "slices": [
    [
      "vaaaaaaaaabbbc  ",
      "vaaaaaaaadbbbc  ",
      "vvcccvcccccccvcc",
      "vaaaacaaaabbbcbb",
      "vaaaacdaaabbbcbb",
      "vaaaacaaaaabbcbb",
      "vaaaacaaaaaaevff",
      "vaaaacaaaaaaacaa",
      "vaaaacadaaaaacaa",
      "vaaaacaaaaaaacaa",
      "vvcccvcccccccvcc",
      "vaaaacaaaaaaacgg",
      "vaaaacaaaaaaacgg",
      "vaaaacaaaaaaacgg",
      "vaaaavaaaaaaavgg",
      "vvvvvvvvvvvvvvvv"
    ],
    [
      "vh       i   j  ",
      "vklll        j  ",
      "vvmmmv       vjj",
      "vl no  i        ",
      "vl     pq  rst  ",
      "vluww  xyi  A   ",
      "vBC  DEi   FIvJK",
      "vl ww     L F  M",
      "vl        N     ",
      "vl OP       QR  ",
      "vvJJJvJJJSJJJvJJ",
      "vTUTVWXXX YZ012 ",
      "v3   4    5 61JJ",
      "v7   W 88 Y9 12 ",
      "v!7##v$%%$Y^&vJJ",
      "vvvvvvvvvvvvvvvv"
    ],
    [
      "v               ",
      "vllkl           ",
      "vvmmmv       v  ",
      "vl              ",
      "v*     (        ",
      "vl      )       ",
      "vl          +vJK",
      "vl             M",
      "vB              ",
      "vl              ",
      "vvJJJvJJJ-JJJvJJ",
      "v    W![  Y  1  ",
      "v    ]    {  1JJ",
      "v    W    Y  1  ",
      "v7}  v    Y |vJJ",
      "vvvvvvvvvvvvvvvv"
    ],
    [
      "v               ",
      "vl;ll           ",
      "vvmmmv       v  ",
      "vl              ",
      "vl              ",
      "vl              ",
      "vl          +vJJ",
      "v*              ",
      "vl              ",
      "vl              ",
      "vvJJJvJJJJJJJvJJ",
      "v    W    Y: 1  ",
      "v    W    Y  1JJ",
      "v    W    Y  1  ",
      "v    v    Y 'vJJ",
      "vvvvvvvvvvvvvvvv"
    ],
    [
      "v            <  ",
      "v>           <  ",
      "vvmmmv       v<<",
      "v    j          ",
      "v    j          ",
      "v    j          ",
      "v    j      +vjj",
      "v    j       j  ",
      "v    j       j  ",
      "v    j       j  ",
      "vvJJJvjjjjjjjvJJ",
      "v    W    Y  1,,",
      "v    W    Y  1,,",
      "v    W    Y  1,,",
      "v    v    Y  v,,",
      "vvvvvvvvvvvvvvvv"
    ],
    [
      "v.???????????/  ",
      "v.???????????/  ",
      "vvcccvcccccccv//",
      "v.???c???????c??",
      "v.???c???????c??",
      "v.???c???????c??",
      "v.???c??????+v??",
      "v.???c???????c??",
      "v.???c???????c??",
      "v.???c???????c??",
      "vvcccvcccccccvcc",
      "v.???c???????c>>",
      "v.???c???????c  ",
      "v.???c???????c> ",
      "v....v.......v..",
      "vvvvvvvvvvvvvvvv"
    ]
  ]
}