{
  "name": "multi_militarybase_1_base4",
  "refpalette": "deceasedcraft:multi_militarybase_1/multi_militarybase_1_base4_palette",
  "xsize": 16,
  "zsize": 16,
  "slices": [
    [
      "vaaaaaaaaaaaabcc",
      "vaaaaaaaaaaaabcc",
      "vvbbbbbbbbbbbvbb",
      "vvvvvvvvvvvvvvzz",
      "vzzzzzzzzzzzzzzz",
      "vzzzzzzzzzzzzzzz",
      "vzzzzzzzzzzzzzzz",
      "vzzzzzzzzzzzzzzz",
      "vzzzzzzzzzzzzzzz",
      "vzzzzzzzzzzzzzzz",
      "vzzzzzzzzzzzzzzz",
      "vzzzzzzzzzzzzzzz",
      "vzzzzzzzzzzzzzzz",
      "vzzzzzzzzzzzzzzz",
      "vzzzzzzzzzzzzzzz",
      "vvvvvvvvvvvvvvvv"
    ],
    [
      "v               ",
      "vd            ef",
      "vvghiij hiij vkk",
      "vvvvvvvvvvvvvvzz",
      "vzzzzzzzzzzzzzzz",
      "vzzzzzzzzzzzzzzz",
      "vzzzzzzzzzzzzzzz",
      "vzzzzzzzzzzzzzzz",
      "vzzzzzzzzzzzzzzz",
      "vzzzzzzzzzzzzzzz",
      "vzzzzzzzzzzzzzzz",
      "vzzzzzzzzzzzzzzz",
      "vzzzzzzzzzzzzzzz",
      "vzzzzzzzzzzzzzzz",
      "vzzzzzzzzzzzzzzz",
      "vvvvvvvvvvvvvvvv"
    ],
    [
      "vl              ",
      "v               ",
      "vvg          vkk",
      "vvvvvvvvvvvvvvzz",
      "vzzzzzzzzzzzzzzz",
      "vzzzzzzzzzzzzzzz",
      "vzzzzzzzzzzzzzzz",
      "vzzzzzzzzzzzzzzz",
      "vzzzzzzzzzzzzzzz",
      "vzzzzzzzzzzzzzzz",
      "vzzzzzzzzzzzzzzz",
      "vzzzzzzzzzzzzzzz",
      "vzzzzzzzzzzzzzzz",
      "vzzzzzzzzzzzzzzz",
      "vzzzzzzzzzzzzzzz",
      "vvvvvvvvvvvvvvvv"
    ],
    [
      "v               ",
      "v               ",
      "vv           vkk",
      "vvvvvvvvvvvvvvzz",
      "vzzzzzzzzzzzzzzz",
      "vzzzzzzzzzzzzzzz",
      "vzzzzzzzzzzzzzzz",
      "vzzzzzzzzzzzzzzz",
      "vzzzzzzzzzzzzzzz",
      "vzzzzzzzzzzzzzzz",
      "vzzzzzzzzzzzzzzz",
      "vzzzzzzzzzzzzzzz",
      "vzzzzzzzzzzzzzzz",
      "vzzzzzzzzzzzzzzz",
      "vzzzzzzzzzzzzzzz",
      "vvvvvvvvvvvvvvvv"
    ],
    [
      "v               ",
      "v               ",
      "vv           vkk",
      "vvvvvvvvvvvvvvzz",
      "vzzzzzzzzzzzzzzz",
      "vzzzzzzzzzzzzzzz",
      "vzzzzzzzzzzzzzzz",
      "vzzzzzzzzzzzzzzz",
      "vzzzzzzzzzzzzzzz",
      "vzzzzzzzzzzzzzzz",
      "vzzzzzzzzzzzzzzz",
      "vzzzzzzzzzzzzzzz",
      "vzzzzzzzzzzzzzzz",
      "vzzzzzzzzzzzzzzz",
      "vzzzzzzzzzzzzzzz",
      "vvvvvvvvvvvvvvvv"
    ],
    [
      "vmmmmmmmmmmmmnoo",
      "vmmmmmmmmmmmmnpp",
      "vvbbbbbbbbbbbvbb",
      "vvvvvvvvvvvvvvzz",
      "vzzzzzzzzzzzzzzz",
      "vzzzzzzzzzzzzzzz",
      "vzzzzzzzzzzzzzzz",
      "vzzzzzzzzzzzzzzz",
      "vzzzzzzzzzzzzzzz",
      "vzzzzzzzzzzzzzzz",
      "vzzzzzzzzzzzzzzz",
      "vzzzzzzzzzzzzzzz",
      "vzzzzzzzzzzzzzzz",
      "vzzzzzzzzzzzzzzz",
      "vzzzzzzzzzzzzzzz",
      "vvvvvvvvvvvvvvvv"
    ]
  ]
}