{
  "name": "multi_militarybase_1_base3",
  "refpalette": "deceasedcraft:multi_militarybase_1/multi_militarybase_1_base3_palette",
  "xsize": 16,
  "zsize": 16,
  "slices": [
    [
      "vaaaaaaabcdddce ",
      "vaaaaaaaacdddcff",
      "vvaaaaaagccccvcc",
      "vaaaaabaacdddcdd",
      "vaaaaaahacdddcdd",
      "vaaaaahaacaddcdd",
      "vaaaabbahcaaavii",
      "vaaaaaaaacaaacaa",
      "vaabbaagacaaacaa",
      "vaaaabaggcaaacaa",
      "vvcccvcccvcccvcc",
      "vaaaacaaacaaacjj",
      "vaaaacaaacaaacjj",
      "vaaaacaaacaaacjj",
      "vaaaavaaavaaavjj",
      "vvvvvvvvvvvvvvvv"
    ],
    [
      "vk  lmn      o  ",
      "vk plmnq     oe ",
      "vv  lm       vo ",
      "vr plm       ls ",
      "vk  l        te ",
      "vr p         lu ",
      "vk          wve ",
      "vx  y  A    Bls ",
      "vC           lDu",
      "vCC          lEe",
      "vvFFFvFFFv   vII",
      "vJK      L   LM ",
      "vJK      N   LII",
      "vJK  L O L   LM ",
      "vPQQRvSSSvTUTvII",
      "vvvvvvvvvvvvvvvv"
    ],
    [
      "vV    B      W  ",
      "v   X        Y  ",
      "vv           v  ",
      "vZ  0        m  ",
      "v            W  ",
      "v1           m  ",
      "vx          wv  ",
      "v            l  ",
      "v            ce ",
      "vC           ms ",
      "vvFFFvFFFv   vII",
      "v        L   L  ",
      "v2       3   LII",
      "v    L   L   L  ",
      "v4  5v 67vTU8vII",
      "vvvvvvvvvvvvvvvv"
    ],
    [
      "v               ",
      "v               ",
      "vv           v  ",
      "v               ",
      "v           9#$ ",
      "v               ",
      "v           wv  ",
      "v            c  ",
      "v            A  ",
      "v            %  ",
      "vvFFFvFFFv   vII",
      "v2       L   L  ",
      "v2       L   LII",
      "v2   L   L   L  ",
      "v  ^ v   v&UTvII",
      "vvvvvvvvvvvvvvvv"
    ],
    [
      "v        o   F  ",
      "v        o   F  ",
      "vv       o   vFF",
      "v        o      ",
      "v        o      ",
      "v        o      ",
      "v        o  wv  ",
      "v        o      ",
      "v        o      ",
      "v        o      ",
      "vvFFFvFFFvooovII",
      "v*   L   L   L((",
      "v    L   L   L((",
      "v)   L   L   L((",
      "v    v   v   v((",
      "vvvvvvvvvvvvvvvv"
    ],
    [
      "v+-------c---[  ",
      "v+-------c---[  ",
      "vv-------c---v[[",
      "v+-------c---c--",
      "v+-------c---c--",
      "v+-------c---c--",
      "v+-------c--wv--",
      "v+-------c---c--",
      "v+-------c---c--",
      "v+-------c---c--",
      "vvcccvcccvcccvcc",
      "v+---c---c---c  ",
      "v+---c---c---c* ",
      "v+---c---c---c* ",
      "v++++v+++v+++v++",
      "vvvvvvvvvvvvvvvv"
    ]
  ]
}