{
  "name": "multi_filmworkstower_13_base2",
  "refpalette": "deceasedcraft:multi_filmworkstower_13/multi_filmworkstower_13_base2_palette",
  "xsize": 16,
  "zsize": 16,
  "slices": [
    [
      "abcccccccdddddcc",
      "ebcccccccdddddcc",
      " bcccccccdddddcc",
      " bcccccccdddddcc",
      " bcccccccdddddcc",
      "ebcccccccdddddcc",
      "fbcccccccdddddcc",
      " bcccccccdddddcc",
      "gbcccccccdddddcc",
      "ebcccccccdddddcc",
      " bcccccccdddddcc",
      " bcccccccdddddcc",
      " bccccccchhhhhcc",
      " bcccccccdddddcc",
      " bcccccccdddddcc",
      " bcccccccdddddcc"
    ],
    [
      " b      ijkkklm ",
      "ab      i n   m ",
      "eb      i     m ",
      "eb      i    om ",
      "eb      i    pm ",
      "fb      q  r sm ",
      " b      t  r sm ",
      " b      i    um ",
      "wb      i    om ",
      "wb      i     m ",
      "wb      i  n  m ",
      "wb      ixyyyAm ",
      "wbBC    DhhhhhE ",
      "wb      iFIJKom ",
      "wb      i     m ",
      "wb      i     L "
    ],
    [
      " b      iMNOPQm ",
      " b      i     m ",
      "ab      i     m ",
      "eb      i     m ",
      "fb      i     m ",
      " b      R     m ",
      " b      S     m ",
      " b      i     m ",
      " b      i    Tm ",
      " b      i     m ",
      " b      i     m ",
      " b      i UV Wm ",
      " bB     hhhhhhh ",
      " b      iX   Ym ",
      " b      i     m ",
      " b      i     Z "
    ],
    [
      " b0     i12223m ",
      " b      i     m ",
      " b      i     m ",
      " b      i     m ",
      " b      i     m ",
      " b      4     m ",
      " b      5     m ",
      " b      i     m ",
      " b      i     m ",
      " b      i     m ",
      " b      i     m ",
      " b6     i78889m ",
      " bB    DhhhhhhhE",
      " b0     i#    m ",
      " b      i     m ",
      " b      i     $ "
    ],
    [
      " b%     i^^^^^m ",
      " b%     i^^^^^m ",
      " b%     i^^^^^m ",
      " b%     i^^^^^m ",
      " b%     i^^^^^m ",
      " b%     i^^^^^m ",
      " b%     i^^^^^m ",
      " b%     i^^^^^m ",
      " b%     i^^^^^m ",
      " b%     i^^^^^m ",
      " b%     i^^^^^m ",
      " b%     i^^^^^m ",
      " bB&   hhhhhhhhh",
      " b%     i^^^^^m ",
      " b%     i^^^^^m ",
      " b%     i^^^^^m "
    ],
    [
      " b              ",
      " b              ",
      " b              ",
      " b              ",
      " b              ",
      " b              ",
      " b              ",
      " b              ",
      " b              ",
      " b              ",
      " b              ",
      " b              ",
      " bB   Dhhh*()hhh",
      " b              ",
      " b              ",
      " b              "
    ]
  ]
}