{
  "name": "multi_filmworkstower_13_base1",
  "refpalette": "deceasedcraft:multi_filmworkstower_13/multi_filmworkstower_13_base1_palette",
  "xsize": 16,
  "zsize": 16,
  "slices": [
    [
      " a              ",
      " a              ",
      " a              ",
      " a              ",
      " a              ",
      " a              ",
      " a              ",
      " a              ",
      " a              ",
      " a              ",
      " a              ",
      " a              ",
      " ab   cccd   ecc",
      " a              ",
      " a              ",
      " a              "
    ],
    [
      " af             ",
      " a              ",
      " a              ",
      " a              ",
      " a              ",
      " a              ",
      " a              ",
      " a              ",
      " a              ",
      " a              ",
      " a              ",
      " ag             ",
      " abh iccd     ec",
      " af             ",
      " a              ",
      " a              "
    ],
    [
      " aj             ",
      " aj             ",
      " aj             ",
      " aj             ",
      " aj             ",
      " aj             ",
      " aj             ",
      " aj             ",
      " aj             ",
      " aj             ",
      " aj             ",
      " aj             ",
      " abkkccd       e",
      " aj             ",
      " aj             ",
      " aj             "
    ],
    [
      "                ",
      "                ",
      "                ",
      "                ",
      "                ",
      "                ",
      "                ",
      "                ",
      "                ",
      "                ",
      "                ",
      "                ",
      " lbmicd         ",
      "                ",
      "                ",
      "                "
    ],
    [
      "nopooooooooooooo",
      "nopooooooooooooo",
      "nopooooooooooooo",
      "nopooooooooooooo",
      "nopooooooooooooo",
      "nopooooooooooooo",
      "nopooooooooooooo",
      "nopooooooooooooo",
      "nopooooooooooooo",
      "nopooooooooooooo",
      "nopooooooooooooo",
      "nopooooooooooooo",
      "noqoccoooooooooo",
      "nopooooooooooooo",
      "nopooooooooooooo",
      "nopooooooooooooo"
    ],
    [
      "cccccccccccccccc",
      "cccccccccccccccc",
      "cccccccccccccccc",
      "cccccccccccccccc",
      "cccccccccccccccc",
      "cccccccccccccccc",
      "cccccccccccccccc",
      "cccccccccccccccc",
      "cccccccccccccccc",
      "cccccccccccccccc",
      "cccccccccccccccc",
      "cccccccccccccccc",
      "c cccccccccccccc",
      "cccccccccccccccc",
      "cccccccccccccccc",
      "cccccccccccccccc"
    ]
  ]
}