{
  "name": "multi_filmworkstower_13_base3",
  "refpalette": "deceasedcraft:multi_filmworkstower_13/multi_filmworkstower_13_base3_palette",
  "xsize": 16,
  "zsize": 16,
  "slices": [
    [
      "aaabbbbbbbbbbbbb",
      "aaabbbbbbbbbbbbb",
      "aaabbbbbbbbbbbbb",
      "aaabbbbbbbbbbbbb",
      "aaabbbbbbbbbbbbb",
      "aaabbbbbbbbbbbbb",
      "aaabbbbbbbbbbbbb",
      "aaabbbbbbbbbbbbb",
      "aaabbbbbbbbbbbbb",
      "aaabbbbbbbbbbbbb",
      "aaabbbbbbbbbbbbb",
      "aaabbbbbbbbbbbbb",
      "aaabbbbbbaaaaabb",
      "aaabbbbbbbbbbbbb",
      "aaabbbbbbbbbbbbb",
      "aaabbbbbbbbbbbbb"
    ],
    [
      "cdabbbbbbbbbbbbb",
      "edabbbbbbbbbbbbb",
      "edabbbbbbbbbbbbb",
      "edabbbbbbbbbbbbb",
      "edabbbbbbbbbbbbb",
      "edabbbbbbbbbbbbb",
      "cdabbbbbbbbbbbbb",
      "fdabbbbbbbbbbbbb",
      "gdabbbbbbbbbbbbb",
      "edabbbbbbbbbbbbb",
      "edabbbbbbbbbbbbb",
      "edabbbbbbbbbbbbb",
      "edabbbbbbaaaaabb",
      "edabbbbbbbbbbbbb",
      "edabbbbbbbbbbbbb",
      "edabbbbbbbbbbbbb"
    ],
    [
      "hdabbbbbbbbbbbbb",
      "edabbbbbbbbbbbbb",
      "idabbbbbbbbbbbbb",
      "idabbbbbbbbbbbbb",
      "idabbbbbbbbbbbbb",
      "edabbbbbbbbbbbbb",
      "hdabbbbbbbbbbbbb",
      "jdabbbbbbbbbbbbb",
      "kdabbbbbbbbbbbbb",
      "edabbbbbbbbbbbbb",
      "edabbbbbbbbbbbbb",
      "edabbbbbbbbbbbbb",
      "edabbbbbbaaaaabb",
      "edabbbbbbbbbbbbb",
      "edabbbbbbbbbbbbb",
      "edabbbbbbbbbbbbb"
    ],
    [
      "ldabbbbbbbbbbbbb",
      "edabbbbbbbbbbbbb",
      "mdabbbbbbbbbbbbb",
      " dabbbbbbbbbbbbb",
      " dabbbbbbbbbbbbb",
      "edabbbbbbbbbbbbb",
      "ndabbbbbbbbbbbbb",
      " dabbbbbbbbbbbbb",
      " dabbbbbbbbbbbbb",
      "idabbbbbbbbbbbbb",
      "odabbbbbbbbbbbbb",
      " dabbbbbbbbbbbbb",
      " dabbbbbbaaaaabb",
      " dabbbbbbbbbbbbb",
      " dabbbbbbbbbbbbb",
      " dabbbbbbbbbbbbb"
    ],
    [
      " dabbbbbbbbbbbbb",
      "pdabbbbbbbbbbbbb",
      " dabbbbbbbbbbbbb",
      " dabbbbbbbbbbbbb",
      " dabbbbbbbbbbbbb",
      "pdabbbbbbbbbbbbb",
      " dabbbbbbbbbbbbb",
      " dabbbbbbbbbbbbb",
      " dabbbbbbbbbbbbb",
      "idabbbbbbbbbbbbb",
      " dabbbbbbbbbbbbb",
      " dabbbbbbbbbbbbb",
      " dabbbbbbaaaaabb",
      " dabbbbbbbbbbbbb",
      " dabbbbbbbbbbbbb",
      " dabbbbbbbbbbbbb"
    ],
    [
      " dabbbbbbbbbbbbb",
      "edabbbbbbbbbbbbb",
      " dabbbbbbbbbbbbb",
      " dabbbbbbbbbbbbb",
      " dabbbbbbbbbbbbb",
      "qdabbbbbbbbbbbbb",
      " dabbbbbbbbbbbbb",
      " dabbbbbbbbbbbbb",
      " dabbbbbbbbbbbbb",
      "idabbbbbbbbbbbbb",
      " dabbbbbbbbbbbbb",
      " dabbbbbbbbbbbbb",
      " dabbbbbbaaaaabb",
      " dabbbbbbbbbbbbb",
      " dabbbbbbbbbbbbb",
      " dabbbbbbbbbbbbb"
    ]
  ]
}