{
  "name": "multi_hospitaldamaged_5_top",
  "refpalette": "deceasedcraft:multi_hospitaldamaged_5/multi_hospitaldamaged_5_top_palette",
  "xsize": 16,
  "zsize": 16,
  "slices": [
    [
      "aaaaaab         ",
      "aaaaaab    c    ",
      "aaaaaab         ",
      "aaaaaab         ",
      "aaaaaab         ",
      "aaaaaab         ",
      "aaaaaab         ",
      "aaaaaad         ",
      "aaaaaab         ",
      "aaaaaab    c    ",
      "eeeeeeb    f    ",
      "bdbdbbd    c    ",
      "g ghhg          ",
      "                ",
      "                ",
      "                "
    ],
    [
      "     ib         ",
      "     jb         ",
      " k  l d         ",
      "     ib         ",
      "     jb         ",
      "    l b         ",
      "    i b         ",
      "   jjmb         ",
      " n  l b         ",
      "     ib         ",
      "eeeeeed    f    ",
      "opoo ob         ",
      "      h         ",
      "                ",
      "                ",
      "                "
    ],
    [
      "      d         ",
      "      q         ",
      "      b         ",
      "      b         ",
      "      b         ",
      "      b         ",
      "      b         ",
      "      b         ",
      "      b         ",
      "      b         ",
      "ereeseb         ",
      "o oo ob         ",
      "      g         ",
      "                ",
      "                ",
      "                "
    ],
    [
      "                ",
      "                ",
      "      t         ",
      "      u         ",
      "      u         ",
      "      t         ",
      "      t         ",
      "      t         ",
      "      t         ",
      "      u         ",
      "e eesed         ",
      "o oo ob         ",
      "      h         ",
      "                ",
      "                ",
      "                "
    ],
    [
      "      b         ",
      "      b         ",
      "      b         ",
      "      b         ",
      "      b         ",
      "      b         ",
      "      d         ",
      "      b         ",
      "      b         ",
      "      b         ",
      "eseeseb         ",
      "o oo od         ",
      "      h         ",
      "                ",
      "                ",
      "                "
    ],
    [
      "wwwwwwb         ",
      "wwwwwwb         ",
      "wwwwwwd         ",
      "wwwwwwb         ",
      "wwwwwwb         ",
      "wwwwwwb         ",
      "wwwwwwb         ",
      "wwwwwwb         ",
      "wwwwwwb         ",
      "xxxxxxb         ",
      "eeeeeeb         ",
      "o oo od         ",
      "      g         ",
      "                ",
      "                ",
      "                "
    ],
    [
      "yyyAyyd         ",
      "yyyyyyq         ",
      "yyyyyyb         ",
      "yyyyyyb         ",
      "BBByyyb         ",
      "BCByyyb         ",
      "BBByyyb         ",
      "yyyyyyd         ",
      "yyyyyyb         ",
      "yyyyyyb         ",
      "DDDDDDd         ",
      "dbdbbbb         ",
      "hghhghh         ",
      "                ",
      "                ",
      "                "
    ],
    [
      "                ",
      " E A            ",
      "FFFF            ",
      "IIIFF           ",
      "JIJIF           ",
      "JJJIFK          ",
      "JIJIF           ",
      "IIIFF           ",
      "FFFF            ",
      " L              ",
      "yyyyyy          ",
      "                ",
      "                ",
      "                ",
      "                ",
      "                "
    ],
    [
      "                ",
      " M              ",
      "                ",
      "                ",
      "                ",
      " !   M          ",
      "                ",
      "                ",
      "                ",
      " M              ",
      "                ",
      "                ",
      "                ",
      "                ",
      "                ",
      "                "
    ]
  ]
}