{
  "name": "multi_hospitaldamaged_5_base1",
  "refpalette": "deceasedcraft:multi_hospitaldamaged_5/multi_hospitaldamaged_5_base1_palette",
  "xsize": 16,
  "zsize": 16,
  "slices": [
    [
      "   a bcccccccccv",
      "d    dcccccccccv",
      "d    dcccccccccv",
      "d    dcccccccccv",
      "d    dcccccccccv",
      "d    dcccccccccv",
      "     bcccccccccv",
      "     bcccccccccv",
      "     bcccccccccv",
      "e e ebcccccccccv",
      "efegedcccccccccv",
      "e!e edcccccccccv",
      "ehehedcccccccccv",
      "iiiiidcccccccccv",
      "ddddddcccccccccv",
      "vvvvvvvvvvvvvvvv"
    ],
    [
      "     bcccccccccv",
      "d    dcccccccccv",
      "d    dcccccccccv",
      "d    dcccccccccv",
      "djjjjdcccccccccv",
      "d    dcccccccccv",
      "     bcccccccccv",
      "     bcccccccccv",
      "     bcccccccccv",
      "ekekebcccccccccv",
      "ekekedcccccccccv",
      "ekekedcccccccccv",
      "ehehedcccccccccv",
      "iiiiidcccccccccv",
      "ddddddcccccccccv",
      "vvvvvvvvvvvvvvvv"
    ],
    [
      "     bcccccccccv",
      "d    dcccccccccv",
      "d    dcccccccccv",
      "d    dcccccccccv",
      "djjjjdcccccccccv",
      "d    dcccccccccv",
      "     bcccccccccv",
      "     bcccccccccv",
      "     bcccccccccv",
      "elelebcccccccccv",
      "eleledcccccccccv",
      "eleledcccccccccv",
      "ehehedcccccccccv",
      "iiiiidcccccccccv",
      "ddddddcccccccccv",
      "vvvvvvvvvvvvvvvv"
    ],
    [
      "     bcccccccccv",
      "d    dcccccccccv",
      "d    dcccccccccv",
      "d    dcccccccccv",
      "djjjjdcccccccccv",
      "d    dcccccccccv",
      "     bcccccccccv",
      "     bcccccccccv",
      "     bcccccccccv",
      "e e ebcccccccccv",
      "e e edcccccccccv",
      "e e edcccccccccv",
      "ehehedcccccccccv",
      "iiiiidcccccccccv",
      "ddddddcccccccccv",
      "vvvvvvvvvvvvvvvv"
    ],
    [
      "mmmmmncccccccccv",
      "dmmmmdcccccccccv",
      "dmmmmdcccccccccv",
      "doooodcccccccccv",
      "dppppdcccccccccv",
      "d    dcccccccccv",
      "     bcccccccccv",
      "     bcccccccccv",
      "     bcccccccccv",
      "eeeeebcccccccccv",
      "eeeeedcccccccccv",
      "eeekedcccccccccv",
      "eeeeedcccccccccv",
      "iiiiidcccccccccv",
      "ddddddcccccccccv",
      "vvvvvvvvvvvvvvvv"
    ],
    [
      "iiiiiicccccqcccv",
      "diiiidcccccccccv",
      "diiiidcccccccccv",
      "doooodcccccccccv",
      "diiiidcccccccccv",
      "diiiidcccccqcccv",
      "iiiiiicccccccccv",
      "iiiiiicccccccccv",
      "iiiiiicccccccccv",
      "iiiiiicccccccccv",
      "iiiiidcccccqcccv",
      "iiiiidcccccccccv",
      "iiiiidcccccccccv",
      "iiiiidcccccccccv",
      "ddddddcccccccccv",
      "vvvvvvvvvvvvvvvv"
    ]
  ]
}