{
  "name": "multi_hospitaldamaged_5_ground",
  "refpalette": "deceasedcraft:multi_hospitaldamaged_5/multi_hospitaldamaged_5_ground_palette",
  "xsize": 16,
  "zsize": 16,
  "slices": [
    [
      "aaaaabcccccdccee",
      "bbaaabccccccccee",
      "bbaaabccccccccee",
      "bbaaabccccccccee",
      "bbaaabccccccccee",
      "aaaaabcccccdccee",
      "faaaabccccccccee",
      "gfaaabccccccccee",
      "hfaaabccccccccee",
      "gaaaabccccccccee",
      "bbbbbbccccciccee",
      "ccccccccccccccee",
      "ccccccccccccccee",
      "eeeeeeeeeeeeeeee",
      "eeeeeeeeeeeeeeee",
      "eeeeeeeeeeeeeeee"
    ],
    [
      "j k  lm    n  o ",
      "ppk qlm         ",
      "rsk tlm      uo ",
      " sk wlm      x  ",
      "ppk  lm       o ",
      "yAkq lm    !  o ",
      "BCk  lm       o ",
      " DkEFlm      uo ",
      " IJ  lm      xo ",
      "KKkLLMm       o ",
      "MMMMMMm    n    ",
      "NNNNNNO       o ",
      "        PQ    R ",
      "R SRoooRoooooo  ",
      " T              ",
      " UV             "
    ],
    [
      " Wk  qm    X    ",
      "ppY   m         ",
      " ZY  om         ",
      " ZY   m         ",
      "ppY  q          ",
      "  k  om    0    ",
      "  k  om         ",
      "  k   m         ",
      "  1  om         ",
      "KKk LMm         ",
      "MMMMMMm    X    ",
      "NNNNNN          ",
      "                ",
      "                ",
      "                ",
      "                "
    ],
    [
      "  k        2    ",
      "pp3   m         ",
      " Z3   m         ",
      " 43             ",
      "pp3   m         ",
      "  k   m    56   ",
      "  k   m    7    ",
      "  k             ",
      "  8!  m         ",
      "9Kk  Mm         ",
      "MMMMMMm    2    ",
      "NNNNNN          ",
      "                ",
      "                ",
      "                ",
      "                "
    ],
    [
      "  k# Mm    o$   ",
      "ppk  Mm         ",
      " %k  Mm         ",
      " ^k  Mm         ",
      "ppk# Mm    &    ",
      "  k  Mm    *    ",
      "  k  Mm         ",
      "  k  Mm         ",
      "  k( Mm         ",
      "KKk  Mm         ",
      "MMMMMMm   $oo   ",
      "NNNNNN     o    ",
      "                ",
      "                ",
      "                ",
      "                "
    ],
    [
      "))))))+    oo   ",
      "))))))+    o    ",
      ")+))))+         ",
      "))))))+         ",
      "))))))+    X    ",
      "))))))+         ",
      "))))))+         ",
      "))))))+         ",
      "))))))+         ",
      "))))))+    o    ",
      "------+   oo$   ",
      "--+-+++    o    ",
      "                ",
      "                ",
      "                ",
      "                "
    ]
  ]
}