{
  "name": "multi_hospitaldamaged_5_base2",
  "refpalette": "deceasedcraft:multi_hospitaldamaged_5/multi_hospitaldamaged_5_base2_palette",
  "xsize": 16,
  "zsize": 16,
  "slices": [
    [
      "vvvvvvvvvvvvvvvv",
      "vvvvvvvvvvvvvvvv",
      "vvvvvvvvvvvvvvvv",
      "vvvvvvvvvvvvvvvv",
      "vvvvvvvvvvvvvvvv",
      "vvvvvvvvvvvvvvvv",
      "vvvvvvvvvvvvvvvv",
      "vvvvvvvvvvvvvvvv",
      "vvvvvvvvvvvvvvvv",
      "vvvvvvvvvvvvvvvv",
      "vvvvvvvvvvvvvvvv",
      "vvvvvvvvvvvvvvvv",
      "vvvvvvvvvvvvvvvv",
      "vvvvvvvvvvvvvvvv",
      "vvvvvvvvvvvvvvvv",
      "vvvvvvvvvvvvvvvv"
    ],
    [
      "aaaaaaaaaaaaaaav",
      "aaaaaaaaaaaaaaav",
      "aaaaaaaaaaaaaaav",
      "aaaaaaaaaaaaaaav",
      "aaaaaaaaaaaaaaav",
      "aaaaaaaaaaaaaaav",
      "aaaaaaaaaaaaaaav",
      "aaaaaaaaaaaaaaav",
      "aaaaaaaaaaaaaaav",
      "aaaaaaaaaaaaaaav",
      "aaaaaaaaaaaaaaav",
      "aaaaaaaaaaaaaaav",
      "aaaaaaaaaaaaaaav",
      "aaaaaaaaaaaaaaav",
      "aaaaaaaaaaaaaaav",
      "vvvvvvvvvvvvvvvv"
    ],
    [
      "aaaaaaaaaaaaaaav",
      "aaaaaaaaaaaaaaav",
      "aaaaaaaaaaaaaaav",
      "aaaaaaaaaaaaaaav",
      "aaaaaaaaaaaaaaav",
      "aaaaaaaaaaaaaaav",
      "aaaaaaaaaaaaaaav",
      "aaaaaaaaaaaaaaav",
      "aaaaaaaaaaaaaaav",
      "aaaaaaaaaaaaaaav",
      "aaaaaaaaaaaaaaav",
      "aaaaaaaaaaaaaaav",
      "aaaaaaaaaaaaaaav",
      "aaaaaaaaaaaaaaav",
      "aaaaaaaaaaaaaaav",
      "vvvvvvvvvvvvvvvv"
    ],
    [
      "aaaaaaaaaaaaaaav",
      "aaaaaaaaaaaaaaav",
      "aaaaaaaaaaaaaaav",
      "aaaaaaaaaaaaaaav",
      "aaaaaaaaaaaaaaav",
      "aaaaaaaaaaaaaaav",
      "aaaaaaaaaaaaaaav",
      "aaaaaaaaaaaaaaav",
      "aaaaaaaaaaaaaaav",
      "aaaaaaaaaaaaaaav",
      "aaaaaaaaaaaaaaav",
      "aaaaaaaaaaaaaaav",
      "aaaaaaaaaaaaaaav",
      "aaaaaaaaaaaaaaav",
      "aaaaaaaaaaaaaaav",
      "vvvvvvvvvvvvvvvv"
    ],
    [
      "bbbbbbaaaaaaaaav",
      "bbbbbbaaaaaaaaav",
      "bbbbbbaaaaaaaaav",
      "bbbbbbaaaaaaaaav",
      "bbbbbbaaaaaaaaav",
      "bbbbbbaaaaaaaaav",
      "bbbbbbaaaaaaaaav",
      "bbbbbbaaaaaaaaav",
      "bbbbbbaaaaaaaaav",
      "bbbbbbaaaaaaaaav",
      "bbbbbbaaaaaaaaav",
      "bbbbbbaaaaaaaaav",
      "bbbbbbaaaaaaaaav",
      "bbbbbbaaaaaaaaav",
      "bbbbbbaaaaaaaaav",
      "vvvvvvvvvvvvvvvv"
    ],
    [
      "ccccccaaaaaaaaav",
      "deefgdaaaaaaaaav",
      "deeh daaaaaaaaav",
      "d    daaaaaaaaav",
      "d    daaaaaaaaav",
      "d    daaaaaaaaav",
      " i   jaaaaaaaaav",
      "     jaaaaaaaaav",
      "     jaaaaaaaaav",
      "kkkkkjaaaaaaaaav",
      "kkkkkdaaaaaaaaav",
      "kkkkkdaaaaaaaaav",
      "kkkkkdaaaaaaaaav",
      "llllldaaaaaaaaav",
      "ddddddaaaaaaaaav",
      "vvvvvvvvvvvvvvvv"
    ]
  ]
}