{
  "name": "multi_terraceplaza_31_ground",
  "refpalette": "deceasedcraft:multi_terraceplaza_31/multi_terraceplaza_31_ground_palette",
  "xsize": 16,
  "zsize": 16,
  "slices": [
    [
      "aaaabcddefghiHHH",
      "aaaabcddefgjiHHH",
      "aaaabcddefghiHHH",
      "kkkklmndefghiHHH",
      "opppbcddefghiHHH",
      "opppbcddefgjiHHH",
      "opppbcddefghiHHH",
      "opppbcddefghiHHH",
      "opppbcddefghiHHH",
      "opppbcddefghiHHH",
      "opppbcddefghiHHH",
      "opppbcddefghiHHH",
      "opppbcddefgjiHHH",
      "opppbcddefghiHHH",
      "kkkklmndefghiHHH",
      "oooobcddefghiHHH"
    ],
    [
      "kq k c  r st    ",
      "k uk c  r sw    ",
      "kxyk c  r sA    ",
      "kkkkl   B CA    ",
      "kD!k c  r sA    ",
      "kEFk c  r sw    ",
      "kI k c  r st    ",
      "JkKk c  r st    ",
      "L  M c  r st    ",
      "kN O c  r st    ",
      "kN O c  r st    ",
      "k  P c  r st    ",
      "k    c  r sw    ",
      "kQQR c  r sA    ",
      "kkkkl   B CA    ",
      "ST U c  r sA    "
    ],
    [
      "kV r c  WXs     ",
      "k  r    WXsY    ",
      "k  k    WX      ",
      "kkkkl   ZX0     ",
      "k11k c  WX      ",
      "k  r    ZXsY    ",
      "k  r c  WXs     ",
      "2k3k    WXs     ",
      "4       ZXs     ",
      "k5   c  ZXs     ",
      "k6      WXs     ",
      "7    c  ZXs     ",
      "7    c  WXsY    ",
      "k889 c  WX      ",
      "kkkkl   ZX0     ",
      "#$ % c  WX      "
    ],
    [
      "k  k    WX      ",
      "k  k    WX      ",
      "k^^k    WX      ",
      "kkkkl   ZXt     ",
      "k Fk    WX      ",
      "k  k    ZX      ",
      "k  k    WX      ",
      "&k*k    WX      ",
      "&       ZX      ",
      "k       ZX      ",
      "k       WX      ",
      "&       ZX      ",
      "&       WX      ",
      "k((     WX      ",
      "kkkkl   ZXt     ",
      "        WX      "
    ],
    [
      "k  k    WX      ",
      "k  k    WX      ",
      "k)+k    WX      ",
      "kkkkl   ZXt     ",
      "k  k    WX      ",
      "k  k    ZX      ",
      "k  k    WX      ",
      "kkkk    WX      ",
      "k       ZX      ",
      "k       ZX      ",
      "k       WX      ",
      "k       ZX      ",
      "k       WX      ",
      "k       WX      ",
      "kkkkl   ZXt     ",
      "        WX      "
    ],
    [
      "k   -   WX      ",
      "k   -   WX      ",
      "k   -   WX      ",
      "kkkkl   ZX      ",
      "k   -   WX      ",
      "k   -   ZX      ",
      "k   -   WX      ",
      "kkkk-   WX      ",
      "k   -   ZX      ",
      "k   -   ZX      ",
      "k   -   WX      ",
      "k   -   ZX      ",
      "k   -   WX      ",
      "k   -   WX      ",
      "kkkkl   ZX      ",
      "    -   WX      "
    ]
  ]
}