{
  "name": "multi_terraceplaza_31_base2",
  "refpalette": "deceasedcraft:multi_terraceplaza_31/multi_terraceplaza_31_base2_palette",
  "xsize": 16,
  "zsize": 16,
  "slices": [
    [
      "aaaabccccccbdddv",
      "aaaabccccccbdddv",
      "aaaabbbbbbbbdddv",
      "aaaaeaaaaaabdddv",
      "aaaaaaaaaaabdddv",
      "aaaaaaaaaaabdddv",
      "aaaaaaaaaaabdddv",
      "aaaaaaaaaaabdddv",
      "aaaaaaaaaaabdddv",
      "aaaaaaaaaaabdddv",
      "aaaaaaaaaaabdddv",
      "aaaaaaaaaaabdddv",
      "aaaaaaaaaaabdddv",
      "aaaaaaaaaaabdddv",
      "aaaaaaaaaaabdddv",
      "aaaaaaaaaaabdddv"
    ],
    [
      "fg hb   i hbdddv",
      "f  hbjkkkjlbdddv",
      "f  hbbbbbbbbdddv",
      " mn e    opbdddv",
      "         ppbdddv",
      " qqqqqq rstbdddv",
      "ruuuuuuwrxtbdddv",
      "ruuuuuuwrstbdddv",
      " yyyyyy rAtbdddv",
      " qqqqqq rxtbdddv",
      "ruuuuuuwrxtbdddv",
      "ruuuuuuwrstbdddv",
      " yyyyyy rxtbdddv",
      "        rxtbdddv",
      " BBBBBC  ppbdddv",
      "        rDtbdddv"
    ],
    [
      "EF  b     Ibdddv",
      "E   b JKL Mbdddv",
      "E   bbbbbbbbdddv",
      "    e    Npbdddv",
      "         ppbdddv",
      "         rObdddv",
      " PPPP Q  rRbdddv",
      " PSTPPP  rRbdddv",
      "         rObdddv",
      "         rRbdddv",
      " UUUU U  rObdddv",
      "  UUUU   rObdddv",
      "         rObdddv",
      "         rRbdddv",
      "         ppbdddv",
      "         rVbdddv"
    ],
    [
      "    b     Wbdddv",
      "    b      bdddv",
      "    bbbbbbbbdddv",
      "    e    Xpbdddv",
      "         ppbdddv",
      "          Ybdddv",
      " Z Z0 Z   1bdddv",
      " 00  00    bdddv",
      "          Ybdddv",
      "           bdddv",
      " 23 2 3   Ybdddv",
      "  233     4bdddv",
      "           bdddv",
      "          5bdddv",
      "         ppbdddv",
      "          6bdddv"
    ],
    [
      "    b     7bdddv",
      "    b      bdddv",
      "    bbbbbbbbdddv",
      "    e     pbdddv",
      "         ppbdddv",
      "           bdddv",
      "           bdddv",
      "           bdddv",
      "           bdddv",
      "           bdddv",
      "           bdddv",
      "           bdddv",
      "           bdddv",
      "           bdddv",
      "         ppbdddv",
      "           bdddv"
    ],
    [
      "    b      bdddv",
      "    b      bdddv",
      "    bbbbbbbbdddv",
      "    e     pbdddv",
      "         ppbdddv",
      "         p8bdddv",
      "         p9bdddv",
      "         p8bdddv",
      "         p9bdddv",
      "         p8bdddv",
      "         p9bdddv",
      "         p8bdddv",
      "         p9bdddv",
      "         p8bdddv",
      "         ppbdddv",
      "         p9bdddv"
    ]
  ]
}