{
  "name": "multi_terraceplaza_31_floor1",
  "refpalette": "deceasedcraft:multi_terraceplaza_31/multi_terraceplaza_31_floor1_palette",
  "xsize": 16,
  "zsize": 16,
  "slices": [
    [
      "a   bc  de      ",
      "a   bc  de      ",
      "affgbc  de      ",
      "aaaahc  ie      ",
      "a   bc  de      ",
      "a   bc  ie      ",
      "a   bc  de      ",
      "aaaabc  de      ",
      "a   bc  ie      ",
      "a   bc  ie      ",
      "a   bc  de      ",
      "a   bc  ie      ",
      "a   bc  de      ",
      "a   bc  de      ",
      "aaaahc  ie      ",
      "    bc  de      "
    ],
    [
      "jjjjklm de      ",
      "jjjjklm de      ",
      "ffjjklm de      ",
      "kkkkhnooie      ",
      "jjjjklm de      ",
      "jjjjklm ie      ",
      "jjjjklm de      ",
      "jjjjklm de      ",
      "jjjjklm ie      ",
      "jjjjklm ie      ",
      "jjjjklm de      ",
      "jjjjklm ie      ",
      "jjjjklm de      ",
      "jjjjklm de      ",
      "kkkkhnooie      ",
      "jjjjklm de      "
    ],
    [
      "ppppqr  de      ",
      "ppppqr  de      ",
      "ppppqr  de      ",
      "aaaahs  ie      ",
      "ppppqr  de      ",
      "ppppqr  ie      ",
      "ppppqr  de      ",
      "ppppqr  de      ",
      "ppppqr  ie      ",
      "ppppqr  ie      ",
      "ppppqr  de      ",
      "ppppqr  ie      ",
      "ppppqr  de      ",
      "ppppqr  de      ",
      "pppphs  ie      ",
      "ppppqr  de      "
    ],
    [
      "at a r  de      ",
      "u  a r  de      ",
      "awwa r  de      ",
      "aaaah   ie      ",
      "ax a r  de      ",
      "axya r  ie      ",
      "ax a r  de      ",
      "AaBa r  de      ",
      "A  C r  ie      ",
      "A  C r  ie      ",
      "A  C r  de      ",
      "A  C r  ie      ",
      "DDEE r  de      ",
      "     r  de      ",
      "   Fh   ie      ",
      "I  J r  de      "
    ],
    [
      "a  K r  de      ",
      "L  K    de      ",
      "aMMa r  de      ",
      "aaaah   ie      ",
      "aN a    de      ",
      "aOPK r  ie      ",
      "aQ K    de      ",
      "RaSa    de      ",
      "   T r  ie      ",
      "U  V    ie      ",
      "   W    de      ",
      "     r  ie      ",
      "     r  de      ",
      "     r  de      ",
      "    h   ie      ",
      "X  Y r  de      "
    ],
    [
      "a  a    de      ",
      "a  a    de      ",
      "aZ0a    de      ",
      "aaaah   ie      ",
      "a1 a    de      ",
      "a2 a    ie      ",
      "a3 a    de      ",
      " a4a    de      ",
      "        ie      ",
      "        ie      ",
      "        de      ",
      "        ie      ",
      "        de      ",
      "        de      ",
      "    h   ie      ",
      "   5    de      "
    ]
  ]
}