{
  "name": "multi_terraceplaza_31_floor3",
  "refpalette": "deceasedcraft:multi_terraceplaza_31/multi_terraceplaza_31_floor3_palette",
  "xsize": 16,
  "zsize": 16,
  "slices": [
    [
      " a   b  cd      ",
      "        cd      ",
      "     b  cd      ",
      "    e   fd      ",
      "        cd      ",
      "     b  fd      ",
      "        cd      ",
      "    ghiicd      ",
      "    jkiifd      ",
      "lllmnoiifd      ",
      "lllmpo  cd      ",
      "qqqqqo  fd      ",
      "     r  cd      ",
      "ssssss  cd      ",
      "                ",
      "                "
    ],
    [
      "        cd      ",
      "        cd      ",
      "        cd      ",
      "    e   fd      ",
      "    ghiicd      ",
      "    jkiifd      ",
      "ggggnoiicd      ",
      "lllmpo  cd      ",
      "lllmqo  fd      ",
      "     r  fd      ",
      "     s  cd      ",
      "                ",
      "                ",
      "                ",
      "                ",
      "                "
    ],
    [
      "        cd      ",
      "ggggghiicd      ",
      "jjjjjkiicd      ",
      "tttteoiifd      ",
      "oooooo  cd      ",
      "qqqqqo  fd      ",
      "     r  cd      ",
      "     s  cd      ",
      "                ",
      "                ",
      "                ",
      "                ",
      "                ",
      "                ",
      "                ",
      "                "
    ],
    [
      "nnnnnoiicd      ",
      "pppppo  cd      ",
      "oooooo  cd      ",
      "rrrrrr  fd      ",
      "ssssss  cd      ",
      "                ",
      "                ",
      "                ",
      "                ",
      "                ",
      "                ",
      "                ",
      "                ",
      "                ",
      "                ",
      "                "
    ],
    [
      "     r  cd      ",
      "     s  cd      ",
      "                ",
      "                ",
      "                ",
      "                ",
      "                ",
      "                ",
      "                ",
      "                ",
      "                ",
      "                ",
      "                ",
      "                ",
      "                ",
      "                "
    ],
    [
      "                ",
      "                ",
      "                ",
      "                ",
      "                ",
      "                ",
      "                ",
      "                ",
      "                ",
      "                ",
      "                ",
      "                ",
      "                ",
      "                ",
      "                ",
      "                "
    ]
  ]
}