{
  "name": "multi_terraceplaza_31_floor2",
  "refpalette": "deceasedcraft:multi_terraceplaza_31/multi_terraceplaza_31_floor2_palette",
  "xsize": 16,
  "zsize": 16,
  "slices": [
    [
      "a  ab   cd      ",
      "a  ab   cd      ",
      "a  ab   cd      ",
      "aaaae   fd      ",
      "ag a    cd      ",
      "ah a    fd      ",
      "ai a    cd      ",
      " aaa    cd      ",
      "        fd      ",
      "        fd      ",
      "        cd      ",
      "        fd      ",
      "        cd      ",
      "        cd      ",
      " j  e   fd      ",
      "        cd      "
    ],
    [
      "a  bk   cd      ",
      "a  bk   cd      ",
      "a  bk   cd      ",
      "aaaae   fd      ",
      "a   k   cd      ",
      "a   k   fd      ",
      "a   k   cd      ",
      " aaak   cd      ",
      "    k   fd      ",
      "    k   fd      ",
      "    k   cd      ",
      "    k   fd      ",
      "    k   cd      ",
      "    k   cd      ",
      " l  e   fd      ",
      "        cd      "
    ],
    [
      "aj bmn  cd      ",
      "a  bmn  cd      ",
      "a  bmn  cd      ",
      "aaaaen  fd      ",
      "a   mn  cd      ",
      "a   mn  fd      ",
      "a   mn  cd      ",
      " aaamn  cd      ",
      "    mn  fd      ",
      "    mn  fd      ",
      "    mn  cd      ",
      "    mn  fd      ",
      "    mn  cd      ",
      "    mn  cd      ",
      " l  en  fd      ",
      "        cd      "
    ],
    [
      "opppqrs cd      ",
      "ppppqrs cd      ",
      "ppppqrs cd      ",
      "qqqqetuufd      ",
      "ppppqrs cd      ",
      "ppppqrs fd      ",
      "ppppqrs cd      ",
      "ppppqrs cd      ",
      "ppppqrs fd      ",
      "ppppqrs fd      ",
      "ppppqrs cd      ",
      "ppppqrs fd      ",
      "ppppqrs cd      ",
      "ppppqrs cd      ",
      "qqqqets fd      ",
      "     w  cd      "
    ],
    [
      "xxxxyA  cd      ",
      "xxxxyA  cd      ",
      "xxxxyA  cd      ",
      "BBBBeC  fd      ",
      "rDDryA  cd      ",
      "DrrryA  fd      ",
      "DrrryA  cd      ",
      "rDrryA  cd      ",
      "rrrryA  fd      ",
      "rrrryA  fd      ",
      "rrrryA  cd      ",
      "rrrryA  fd      ",
      "rrrryA  cd      ",
      "EEEEyFIIcd      ",
      "qqqqeJIIfd      ",
      "xxxxxKIIcd      "
    ],
    [
      "LL   A  cd      ",
      "     A  cd      ",
      "     A  cd      ",
      "    e   fd      ",
      "     A  cd      ",
      "  M  A  fd      ",
      "  N  A  cd      ",
      "  O  A  cd      ",
      "     A  fd      ",
      "     A  fd      ",
      "PPPPQFIIcd      ",
      "    RJIIfd      ",
      "QQQQxKIIcd      ",
      "KKKKKK  cd      ",
      "KKKKKK  fd      ",
      "SSSSSS  cd      "
    ]
  ]
}