{
  "name": "multi_terraceplaza_31_base1",
  "refpalette": "deceasedcraft:multi_terraceplaza_31/multi_terraceplaza_31_base1_palette",
  "xsize": 16,
  "zsize": 16,
  "slices": [
    [
      "    a      abbbv",
      "    a      abbbv",
      "    aaaaaaaabbbv",
      "    c     dabbbv",
      "         ddabbbv",
      "         deabbbv",
      "         deabbbv",
      "         deabbbv",
      "         deabbbv",
      "        fdeabbbv",
      "        gdeabbbv",
      "        fdeabbbv",
      "        hdeabbbv",
      "        fdeabbbv",
      "        iddabbbv",
      "        fdeabbbv"
    ],
    [
      "    a      abbbv",
      "    a      abbbv",
      "    aaaaaaaabbbv",
      "    c     dabbbv",
      "         djabbbv",
      "         djabbbv",
      "         d abbbv",
      "         d abbbv",
      "         djabbbv",
      "        fd abbbv",
      "        gd abbbv",
      "        fdjabbbv",
      "        kd abbbv",
      "        fdjabbbv",
      "        fddabbbv",
      "        fdjabbbv"
    ],
    [
      "    a      abbbv",
      "    a      abbbv",
      "    aaaaaaaabbbv",
      "    c     dabbbv",
      "         djabbbv",
      "         d abbbv",
      "         d abbbv",
      "         d abbbv",
      "         d abbbv",
      "         d abbbv",
      "         d abbbv",
      "         d abbbv",
      "         d abbbv",
      "         d abbbv",
      "         ddabbbv",
      "         djabbbv"
    ],
    [
      " llmannnnnoabbbv",
      " llmannnnnnabbbv",
      " llmaaaaaaaabbbv",
      " llmc     pabbbv",
      " llmqrrrsd abbbv",
      " llmqqqqqd abbbv",
      " llmqqqrrdoabbbv",
      " llmqqqqqd abbbv",
      " llmqqqqqd abbbv",
      " llmqqqqqdjabbbv",
      " llmqqqqqdjabbbv",
      " llmqqqqqdoabbbv",
      " llmqqqqqdjabbbv",
      " llmqrrrrdjabbbv",
      " llmrrrrrddabbbv",
      " llmqrrrrd abbbv"
    ],
    [
      "ttumabbbbbwabbbv",
      "ttumabbbbbwabbbv",
      "ttumaaaaaawabbbv",
      "ttumcxxxxxyabbbv",
      "ttumxxxxxxwabbbv",
      "ttumxxxxxxwabbbv",
      "ttumxAAAxxwabbbv",
      "ttumxxxxxxwabbbv",
      "ttumxxxxxxwabbbv",
      "ttumxxxxxxwabbbv",
      "ttumxxxxxxwabbbv",
      "ttumxAAAxxwabbbv",
      "ttumxxxxxxwabbbv",
      "ttumxxxxxxwabbbv",
      "ttumxxxxxxwabbbv",
      "ttumxxxxxxwabbbv"
    ],
    [
      "BBCmDEbbbbbabbbv",
      "BBCmDEbbbbbabbbv",
      "BBCmDEaaaaaabbbv",
      "DDDDcFbbbbbabbbv",
      "BBCmDEbbbbbabbbv",
      "BBCmDEbbbbbabbbv",
      "BBCmDEbbbbbabbbv",
      "BBCmDEbbbbbabbbv",
      "BBCmDEbbbbbabbbv",
      "BBCmDEbbbbbabbbv",
      "BBCmDEbbbbbabbbv",
      "BBCmDEbbbbbabbbv",
      "BBCmDEbbbbbabbbv",
      "BBCmDEbbbbbabbbv",
      "DDDDcFbbbbbabbbv",
      "BBCmDEbbbbbabbbv"
    ]
  ]
}