{
  "name": "multi_residentialsurvivor_1_base1",
  "refpalette": "deceasedcraft:multi_residentialsurvivor_1/multi_residentialsurvivor_1_base1_palette",
  "xsize": 16,
  "zsize": 16,
  "slices": [
    [
      "aaaaaaaaaaaaaaaa",
      "aaaaaaaaaaaaaaaa",
      "abbacaaaaaacaaaa",
      "adddaaaaaaaaaaaa",
      "ddddaaaaaaaaaaaa",
      "bbdeaaaaaaaaaaaa",
      "bbbbbbbaaaaaaaaa",
      "ababbbbbaaaaaaaa",
      "aaabfbbbbbaaaaaa",
      "aaaaabbbbgaaaaaa",
      "aaaaaabhabaaaaaa",
      "aaaaaaaaaaaaaaaa",
      "aaaaaaaaaaaaaaaa",
      "aaaacaaaaaacaaaa",
      "aaaaaaaaaaaaaaaa",
      "aaaaaaaaaaaaaaaa"
    ],
    [
      "aaaaaaaaaaaaaaaa",
      "aaaaaaaaaaaaaaaa",
      "aijacaaaaaacaaaa",
      "kl laaaaaaaaaaaa",
      "l llaaaaaaaaaaaa",
      "m lmaaaaaaaaaaaa",
      "n   opmaaaaaaaaa",
      "a      qggaaaaaa",
      "aaam     rgaaaaa",
      "aaaaast   aaaaaa",
      "aaaaaaj umaaaaaa",
      "aaaaaaagaaaaaaaa",
      "aaaaaaaaaaaaaaaa",
      "aaaacaaaaaacaaaa",
      "aaaaaaaaaaaaaaaa",
      "aaaaaaaaaaaaaaaa"
    ],
    [
      "aaaaaaaaaaaaaaaa",
      "aaaaaaaaaaaaaaaa",
      "aawxcaaaaaacaaaa",
      "    aaaaaaaaaaaa",
      "    aaaaaaaaaaaa",
      "y  yAaaaaaaaaaaa",
      "      BAaaaaaaaa",
      "C       Dgaaaaaa",
      "aa B     rgaaaaa",
      "aaaaa    raaaaaa",
      "aaaaaaE  yaaaaaa",
      "aaaaaaasaaaaaaaa",
      "aaaaaaaaaaaaaaaa",
      "aaaacaaaaaacaaaa",
      "aaaaaaaaaaaaaaaa",
      "aaaaaaaaaaaaaaaa"
    ],
    [
      "aaaaaaaaaaaaaaaa",
      "aaaaaaaaaaaaaaaa",
      "aaaacaaaaaacaaaa",
      "a   Aaaaaaaaaaaa",
      "    aaaaaaaaaaaa",
      "B  y aaaaaaaaaaa",
      "      Eaaaaaaaaa",
      "s      xagaaaaaa",
      "aaFE      aaaaaa",
      "aaaaaF   rgaaaaa",
      "aaaaaag  Baaaaaa",
      "aaaaaaaaaaaaaaaa",
      "aaaaaaaaaaaaaaaa",
      "aaaacaaaaaacaaaa",
      "aaaaaaaaaaaaaaaa",
      "aaaaaaaaaaaaaaaa"
    ],
    [
      "aaaaaaaaaaaaaaaa",
      "aaaaaaaaaaaaaaaa",
      "aaaacaaaaaacaaaa",
      "ax aaaaaaaaaaaaa",
      "i   aaaaaaaaaaaa",
      "E  Baaaaaaaaaaaa",
      "F   Faaaaaaaaaaa",
      "aaFaFaaaggaaaaaa",
      "aaaaaaF  rgaaaaa",
      "aaaaaag  raaaaaa",
      "aaaaaagaFEgaaaaa",
      "aaaaaaaaaaaaaaaa",
      "aaaaaaaaaaaaaaaa",
      "aaaacaaaaaacaaaa",
      "aaaaaaaaaaaaaaaa",
      "aaaaaaaaaaaaaaaa"
    ],
    [
      "aaaaaaaaaaaaaaaa",
      "aaaaaaaaaaaaaaaa",
      "aaaacggggggcaaaa",
      "aaxaggggggggaaaa",
      "ai  ggggggggaaaa",
      "aaFEggggggggaaaa",
      "aaaaggggggggaaaa",
      "aaaaggggggggaaaa",
      "aaaaggg  rggaaaa",
      "aaaaggg   ggaaaa",
      "aaaaggggggggaaaa",
      "aaaaggggggggaaaa",
      "aaaaggggggggaaaa",
      "aaaacggggggcaaaa",
      "aaaaaaaaaaaaaaaa",
      "aaaaaaaaaaaaaaaa"
    ]
  ]
}