{
  "name": "multi_residentialsurvivor_1_ground",
  "refpalette": "deceasedcraft:multi_residentialsurvivor_1/multi_residentialsurvivor_1_ground_palette",
  "xsize": 16,
  "zsize": 16,
  "slices": [
    [
      "aabaaaaaaaaaaaab",
      "abbaaaaaaaaaaaaa",
      "abaavvvvvvvvaaab",
      "aacavddddddvaaab",
      "ceeevddddddvcabb",
      "b!cfvdHHHHdvabbb",
      "abffvdHHHHdvccab",
      "bcbbvdHHHHdvcccb",
      "abbcvdHH gdvcaaa",
      "cacavdHh gdvccbb",
      "faafvdHHHidvccab",
      "ccabvddddddvaacb",
      "caacvddddddvaaab",
      "aabavvddddvvaaab",
      "bbbbaddddddbaabb",
      "bbbabddddddbbbbb"
    ],
    [
      "jj jkjjjjjjjjjj ",
      "                ",
      "k jkvvvvvvvv    ",
      "l lmv nopqrv    ",
      "    v      v    ",
      "  s v    t vu   ",
      "    vw    xvyu  ",
      "    ABC  D vyyE ",
      "   sFI u   vyu  ",
      "s   vC     vy   ",
      "    v     uv  D ",
      "    v J KKxvu   ",
      "llmlvLMNOPPv    ",
      "jj jvvQQQQvv    ",
      "                ",
      "                "
    ],
    [
      "                ",
      "                ",
      "    vvvvvvvv    ",
      "R RSvTUUUVWv    ",
      "    v      v    ",
      "    v      v    ",
      "    vX     v    ",
      "    YX     v    ",
      "    Z0     vy   ",
      "    v      v    ",
      "    v      v    ",
      "    v    L v    ",
      "RR1Rv 234PKv    ",
      "    vvQQQQvv    ",
      "                ",
      "                "
    ],
    [
      "                ",
      "                ",
      "5555vvvvvvvv    ",
      "6S6mvT    Wv    ",
      "    v      7    ",
      "    v      7    ",
      "    v      7    ",
      "    v      v    ",
      "    v      v    ",
      "    v      7    ",
      "    v      7    ",
      "    v      7    ",
      "66m6v 884K v    ",
      "9999vvQQQQvv    ",
      "                ",
      "                "
    ],
    [
      "                ",
      "                ",
      "    vvvvvvvv    ",
      "5555vT    Wv    ",
      "####v      v    ",
      "####v $  % v    ",
      "####v      v    ",
      "####v      v    ",
      "####v      v    ",
      "####v      v    ",
      "####v $    v    ",
      "####v      v    ",
      "9999v ^^^^ v    ",
      "    vvvvvvvv    ",
      "                ",
      "                "
    ],
    [
      "                ",
      "                ",
      "    vvvvvvvv    ",
      "    v&*****v    ",
      "5555v******v    ",
      "((()v******v    ",
      "+-[)v******v    ",
      "   ]{******v    ",
      "  }|v******v    ",
      ";:')v******v    ",
      "((()v****<*v    ",
      "9999v***>,.v    ",
      "    v****?*v    ",
      "    vvvvvvvv    ",
      "                ",
      "                "
    ]
  ]
}