{
  "name": "multi_flatapartment_0_floor2",
  "refpalette": "deceasedcraft:multi_flatapartment_0/multi_flatapartment_0_floor2_palette",
  "xsize": 16,
  "zsize": 16,
  "slices": [
    [
      "                ",
      "     abbbbabbbab",
      "     bccccdddddd",
      "     bccccdddddd",
      "     bccccdddddd",
      "     adddddddddd",
      "     bdddddddddd",
      "     bdddddddddd",
      "     bdddddddddd",
      "     bdddddddddd",
      "     aeeeedddddd",
      "     bccccdddddd",
      "     bccccdddddd",
      "     bccccdddddd",
      "     abbbbabbbab",
      "                "
    ],
    [
      "                ",
      "     abffbabfbab",
      "     bg   h     ",
      "     fi  jbk  l ",
      "     bmno bp qbr",
      "     abbbsbt qbu",
      "     wxyyAB  CbD",
      "     E F IbbbbbD",
      "     JKLL bMN O ",
      "     bPQQRbS  b ",
      "     abbbbb   b ",
      "     bmTU h   b ",
      "     fV  jbWWWW ",
      "     bX   h     ",
      "     abffbabfbab",
      "                "
    ],
    [
      "                ",
      "     abYYbabYbab",
      "     bZ   0   1 ",
      "     Y    b   l ",
      "     b  2 b3  b ",
      "     abbb4b   b5",
      "      5   6   b ",
      "         7bbbbb ",
      "          b !18 ",
      "     w9   b   b ",
      "     abbbbb   b#",
      "     b    0   b ",
      "     Y    bWWWW ",
      "     b$   0     ",
      "     abYYbabYbab",
      "                "
    ],
    [
      "                ",
      "     abYYbabYbab",
      "     b%   b     ",
      "     Y   ^b   l ",
      "     b    b   b ",
      "     abbbbb   b5",
      "     &5   *   b ",
      "          bbbbb ",
      "     Y    b   * ",
      "     b    b   b ",
      "     abbbbb   b ",
      "     b    b   b ",
      "     Y   ^bWWWW ",
      "     b(   b     ",
      "     abYYbabYbab",
      "                "
    ],
    [
      "                ",
      "     abbbbabbbab",
      "     b))))b   b ",
      "     b))))b   b ",
      "     b))))b + b ",
      "     abbbbb   bb",
      "     b5   b   b ",
      "     -    bbbbb ",
      "     b    b   b ",
      "     b    b   b ",
      "     abbbbb   bb",
      "     b))))b   b ",
      "     b))))bWWWb ",
      "     b))))b   b ",
      "     abbbbabbbab",
      "                "
    ],
    [
      "                ",
      "     []]]][]]][]",
      "     ]{{{{{{{{{{",
      "     ]{   b{{{b{",
      "     ]{   b{{{b{",
      "     [{bbbb{{{bb",
      "     ]{{{{b{{{b{",
      "     ]{{{{bbbbb{",
      "     ]{{{{b{{{b{",
      "     ]{{{{b{{{b{",
      "     [{bbbb{{{bb",
      "     ]{   b{{{b{",
      "     ]{   b{{{b{",
      "     ]{{{{{{{{{{",
      "     []]]][]]][]",
      "                "
    ]
  ]
}