{
  "name": "multi_flatapartment_0_ground",
  "refpalette": "deceasedcraft:multi_flatapartment_0/multi_flatapartment_0_ground_palette",
  "xsize": 16,
  "zsize": 16,
  "slices": [
    [
      "HHHHaaaaaaaaaaab",
      "HHHHabbbbbbbbbbb",
      "HHHHabbbbbbbbbbb",
      "HHHHabbbbbbbcbbb",
      "HHHHabbbbbbbbbcb",
      "HHHHabbbbbbbcbbb",
      "HHHHabbbbbbbdede",
      "HHHHabbbcbbbeefd",
      "HHHHabbbbbbbcghf",
      "HHHHabbbbbcebgge",
      "HHHHabbbbbbbbbbe",
      "HHHHabbbbbbbcbcb",
      "HHHHabbbbbbbbbbc",
      "HHHHabbbbbbbbbbb",
      "HHHHabbbbbbbbbbb",
      "HHHHaaaaaaaaaaab"
    ],
    [
      "  ijklllllll ll ",
      "    lmi  jmn nm ",
      "     op  q   r  ",
      "  pq o    s  tuw",
      "  ijlo      w   ",
      "    lm   nmn nmx",
      "    lij wi   y A",
      "  pql    pByA   ",
      "  ijl    iCy Dd ",
      "    lpq  p  EdFd",
      "   Ilm   JmJ  g ",
      "  pqlo       w  ",
      "  ijlo        s ",
      "    loi  j      ",
      "    lmp  qmJJJm ",
      "  pqkllllllllll "
    ],
    [
      "    K           ",
      "     L    L   L ",
      "                ",
      "                ",
      "                ",
      "     L    L   L ",
      "                ",
      "                ",
      "                ",
      "                ",
      "     L    L   f ",
      "                ",
      "                ",
      "                ",
      "     L    L   L ",
      "    K           "
    ],
    [
      "    M           ",
      "     LN  NLN NLN",
      "     N          ",
      "                ",
      "     N          ",
      "     L    L   L ",
      "     N          ",
      "                ",
      "                ",
      "     N          ",
      "     L    L   L ",
      "     N          ",
      "                ",
      "     N          ",
      "     LN  NLN NLN",
      "    M           "
    ],
    [
      "                ",
      "     LOOOOLOOOLO",
      "     O    P   P ",
      "     O          ",
      "     O          ",
      "     LP   L   L ",
      "     O          ",
      "     O          ",
      "     O          ",
      "     O          ",
      "     LP   L   L ",
      "     O          ",
      "     O          ",
      "     O    P   P ",
      "     LOOOOLOOOLO",
      "                "
    ],
    [
      "                ",
      "     OOOOOOOOOOO",
      "     Obbbbbbbbbb",
      "     Ob   b   b ",
      "     Ob   b   b ",
      "     Obbbbbbbbbb",
      "     Ob   b   b ",
      "     Ob   b   b ",
      "     Ob   b   b ",
      "     Ob   b   ! ",
      "     Obbbbbbbbbb",
      "     Ob   b   b ",
      "     Ob   b   b ",
      "     Obbbbbbbbbb",
      "     OOOOOOOOOOO",
      "                "
    ]
  ]
}