{
  "name": "multi_flatapartment_0_floor1",
  "refpalette": "deceasedcraft:multi_flatapartment_0/multi_flatapartment_0_floor1_palette",
  "xsize": 16,
  "zsize": 16,
  "slices": [
    [
      "                ",
      "     abbbbabbbab",
      "     bccccdddddd",
      "     bccccdddddd",
      "     bccccdddddd",
      "     adddddddddd",
      "     bdddddddddd",
      "     bdddddddddd",
      "     bdddddddddd",
      "     bdddddddddd",
      "     aeeeedddddd",
      "     bccccdddddd",
      "     bccccdddddd",
      "     bccccdddddd",
      "     abbbbabbbab",
      "                "
    ],
    [
      "                ",
      "     abffbabfbab",
      "     bg   h     ",
      "     fi  jbk  l ",
      "     bmno bp qbr",
      "     abbbsbt qbu",
      "     bwxx y  AbB",
      "     f    bbbbbB",
      "     f CC bDE F ",
      "     bIJJIbK  b ",
      "     abbbbb   b ",
      "     bmLM h   b ",
      "     fN  jbOOOO ",
      "     bP   h     ",
      "     abffbabfbab",
      "                "
    ],
    [
      "                ",
      "     abQQbabQbab",
      "     bR   S   T ",
      "     Q    b   l ",
      "     b    bU  b ",
      "     abbbVb   bW",
      "     bW   X   b ",
      "     Q   Ybbbbb ",
      "     Q    b !TZ ",
      "     b   0b   b ",
      "     abbbbb   b1",
      "     b    S   b ",
      "     Q    bOOOO ",
      "     b2   S     ",
      "     abQQbabQbab",
      "                "
    ],
    [
      "                ",
      "     abQQbabQbab",
      "     b3   b     ",
      "     Q   4b   l ",
      "     b    b   b ",
      "     abbbbb   bW",
      "     bW   5   b ",
      "     Q    bbbbb ",
      "     Q    b   5 ",
      "     b    b   b ",
      "     abbbbb   b ",
      "     b    b   b ",
      "     Q   4bOOOO ",
      "     b6   b     ",
      "     abQQbabQbab",
      "                "
    ],
    [
      "                ",
      "     abbbbabbbab",
      "     b7777b   b ",
      "     b7777b   b ",
      "     b7777b 8 b ",
      "     abbbbb   bb",
      "     bW   b   b ",
      "     b    bbbbb ",
      "     b    b   b ",
      "     b    b   b ",
      "     abbbbb   bb",
      "     b7777b   b ",
      "     b7777bOOOb ",
      "     b7777b   b ",
      "     abbbbabbbab",
      "                "
    ],
    [
      "                ",
      "     9####9###9#",
      "     #$$$$$$$$$$",
      "     #$   b$$$b$",
      "     #$   b$$$b$",
      "     9$bbbb$$$bb",
      "     #$$$$b$$$b$",
      "     #$$$$bbbbb$",
      "     #$$$$b$$$b$",
      "     #$$$$b$$$b$",
      "     9$bbbb$$$bb",
      "     #$   b$$$b$",
      "     #$   b$$$b$",
      "     #$$$$$$$$$$",
      "     9####9###9#",
      "                "
    ]
  ]
}