{
  "name": "multi_flatapartment_0_floor3",
  "refpalette": "deceasedcraft:multi_flatapartment_0/multi_flatapartment_0_floor3_palette",
  "xsize": 16,
  "zsize": 16,
  "slices": [
    [
      "                ",
      "     abbbbabbbab",
      "     bccccdddddd",
      "     bccccdddddd",
      "     bccccdddddd",
      "     adddddddddd",
      "     bdddddddddd",
      "     bdddddddddd",
      "     bdddddddddd",
      "     bdddddddddd",
      "     aeeeedddddd",
      "     bccccdddddd",
      "     bccccdddddd",
      "     bccccdddddd",
      "     abbbbabbbab",
      "                "
    ],
    [
      "                ",
      "     abffbabfbab",
      "     bg   h     ",
      "     fi  jbk  l ",
      "     bmno bp qbr",
      "     abbbsbt qbu",
      "     bwxx    ybA",
      "     f    bbbbbA",
      "     f BB bCD   ",
      "     bEFFEbI  b ",
      "     abbbbb   b ",
      "     bmJK h   b ",
      "     fL  jbMMMM ",
      "     bN   h     ",
      "     abffbabfbab",
      "                "
    ],
    [
      "                ",
      "     abOObabObab",
      "     bP   Q   R ",
      "     O    b   l ",
      "     b    bS  b ",
      "     abbbTb   bU",
      "     bU       b ",
      "     O   Vbbbbb ",
      "     O    b !R  ",
      "     bW   b   b ",
      "     abbbbb   bX",
      "     b    Q   b ",
      "     O    bMMMM ",
      "     bY   Q     ",
      "     abOObabObab",
      "                "
    ],
    [
      "                ",
      "     abOObabObab",
      "     bZ   b     ",
      "     O   0b   l ",
      "     b    b   b ",
      "     abbbbb   bU",
      "     bU   1   b ",
      "     O    bbbbb ",
      "     O    b   1 ",
      "     b    b   b ",
      "     abbbbb   b ",
      "     b    b   b ",
      "     O   0bMMMM ",
      "     b2   b     ",
      "     abOObabObab",
      "                "
    ],
    [
      "                ",
      "     abbbbabbbab",
      "     b3333b   b ",
      "     b3333b   b ",
      "     b3333b 4 b ",
      "     abbbbb   bb",
      "     bU   b   b ",
      "     b    bbbbb ",
      "     b    b   b ",
      "     b    b   b ",
      "     abbbbb   bb",
      "     b3333b   b ",
      "     b3333bMMMb ",
      "     b3333b   b ",
      "     abbbbabbbab",
      "                "
    ],
    [
      "                ",
      "     56666566656",
      "     67777777777",
      "     67   b777b7",
      "     67   b777b7",
      "     57bbbb777bb",
      "     67777b777b7",
      "     67777bbbbb7",
      "     67777b777b7",
      "     67777b777b7",
      "     57bbbb777bb",
      "     67   b777b7",
      "     67   b777b7",
      "     67777777777",
      "     56666566656",
      "                "
    ]
  ]
}