{
  "name": "scattered_cabin_1_floor1",
  "refpalette": "deceasedcraft:scattered_cabin_1/scattered_cabin_1_floor1_palette",
  "xsize": 16,
  "zsize": 16,
  "slices": [
    [
      "aaaaaaaaaaaaaaaa",
      "aaaaaaaaaaaaaaaa",
      "aaaaaaaaaaabbbaa",
      "aaaaaaaaaaabbbaa",
      "aaaaaaaaaaabbbaa",
      "aaaaaaaaaaabbbaa",
      "aaaaaaaaaaabbbaa",
      "aaaaaaaaaaaaaaaa",
      "aaaaaaaaaaaaccaa",
      "ccaaaaaaaaaccaaa",
      "caccacaaaaacccaa",
      "accccaccaacccaaa",
      "aacacccccccccaaa",
      "aaaaaaccacdcaaaa",
      "aaaaaaaaccccaaaa",
      "aaaaaaaaaaaaaaaa"
    ],
    [
      "eeeeeeeeeeeeeeee",
      "eeeefeeegeheeehe",
      "egeeeeeeeehiiihj",
      "eeeeeeeeeehiiihe",
      "ekeeeeeeeehiiihe",
      "eeeeeeeeeehiiihe",
      "eeeeeeeeeehiiihj",
      "egeeeegeelhmmmhe",
      "eeeeeeeeeeeeeeee",
      "eeeeeeeeeeeeeeee",
      "eeeeeeeeeeeeeeeg",
      "eeeeeeeeeeeeeeee",
      "eeeeeeeeeeeeeeee",
      "eeeeeeeeeeneoeee",
      "eegeeeeeeeeeoefe",
      "eeeeeekgeeeeeeee"
    ],
    [
      "eeeeeeeeeeeeeeee",
      "eeeepeeepeqeeere",
      "epeeeeeeeeqstsre",
      "eeeeeeeeeequevre",
      "eeeeeeeeeeqwexre",
      "eeeeeeeeeeqyezre",
      "eeeeeeeeeeqABAre",
      "epeeeepeeeqeeere",
      "eeeeeeeeeeeeeeee",
      "eeeeeeeeeeeeeeee",
      "eeeeeeeeeeeeeeep",
      "eeeeeeeeeeeeeeee",
      "eeeeeeeeeeeeeeee",
      "eeeeeeeeeeeeeeee",
      "eepeeeeeeeeeeepe",
      "eeeeeeepeeeeeeee"
    ],
    [
      "eeeeeeeeeeeeeeee",
      "eeeeeeeeeeCDeCDe",
      "eeeeeeeeeeCsEsDe",
      "eeeeeeeeeeCFeGDe",
      "eeeeeeeeeeCeeGDe",
      "eeeeeeeeeeCGeeDe",
      "eeeeeeeeeeCAHADe",
      "eeeeeeeeeeCDeCDe",
      "eeeeeeeeeeeeeeee",
      "eeeeeeeeeeeeeeee",
      "eeeeeeeeeeeeeeee",
      "eeeeeeeeeeeeeeee",
      "eeeeeeeeeeeeeeee",
      "eeeeeeeeeeeeeeee",
      "eeeeeeeeeeeeeeee",
      "eeeeeeeeeeeeeeee"
    ],
    [
      "eeeeeeeeeeeeeeee",
      "eeeeeeeeeeeIeJee",
      "eeeeeeeeeeeKsKee",
      "eeeeeeeeeeeIeJee",
      "eeeeeeeeeeeIeJee",
      "eeeeeeeeeeeIeJee",
      "eeeeeeeeeeeKLKee",
      "eeeeeeeeeeeIeJee",
      "eeeeeeeeeeeeeeee",
      "eeeeeeeeeeeeeeee",
      "eeeeeeeeeeeeeeee",
      "eeeeeeeeeeeeeeee",
      "eeeeeeeeeeeeeeee",
      "eeeeeeeeeeeeeeee",
      "eeeeeeeeeeeeeeee",
      "eeeeeeeeeeeeeeee"
    ],
    [
      "eeeeeeeeeeeeeeee",
      "eeeeeeeeeeeqeree",
      "eeeeeeeeeeeqsree",
      "eeeeeeeeeeeqMree",
      "eeeeeeeeeeeqNree",
      "eeeeeeeeeeeqGree",
      "eeeeeeeeeeeqLree",
      "eeeeeeeeeeeqeree",
      "eeeeeeeeeeeeeeee",
      "eeeeeeeeeeeeeeee",
      "eeeeeeeeeeeeeeee",
      "eeeeeeeeeeeeeeee",
      "eeeeeeeeeeeeeeee",
      "eeeeeeeeeeeeeeee",
      "eeeeeeeeeeeeeeee",
      "eeeeeeeeeeeeeeee"
    ]
  ]
}