{
  "name": "multi_sunkenmonumentpark_11_base1",
  "refpalette": "deceasedcraft:multi_sunkenmonumentpark_11/multi_sunkenmonumentpark_11_base1_palette",
  "xsize": 16,
  "zsize": 16,
  "slices": [
    [
      "aaaaaaaaaaaaaaaa",
      "aaaaaaaaaaaaaaaa",
      "aaaaaaaaaaaaaaaa",
      "aaaaaaaaaaaaaaaa",
      "aaaaaaaaaaaaaaaa",
      "aaaaaaaaaaaaaaaa",
      "aaaaaaaaaaaaaaaa",
      "aaaaaaaaaaaaaaaa",
      "aaaaaaaaaaaaaaaa",
      "aaaaaaaaaaaaaaaa",
      "aaaaaaaaaaaaaaaa",
      "aaaaaaaaaaaaaaaa",
      "aaaaaaaaaaaaaaaa",
      "aaaaaaaaaaaaaaaa",
      "aaaaaaaaaaaaaaaa",
      "vvvvvvvvvvvvvvvv"
    ],
    [
      "aaaaaaaaaaaaaaaa",
      "aaaaaaaaaaaaaaaa",
      "aaaaaaaaaaaaaaaa",
      "aaaaaaaaaaaaaaaa",
      "aaaaaaaaaaaaaaaa",
      "aaaaaaaaaaaaaaaa",
      "aaaaaaaaaaaaaaaa",
      "aaaaaaaaaaaaaaaa",
      "aaaaaaaaaaaaaaaa",
      "aaaaaaaaaaaaaaaa",
      "aaaaaaaaaaaaaaaa",
      "aaaaaaaaaaaaaaaa",
      "aaaaaaaaaaaaaaaa",
      "aaaaaaaaaaaaaaaa",
      "aaaaaaaaaaaaaaaa",
      "vvvvvvvvvvvvvvvv"
    ],
    [
      "bbcccccccccccaaa",
      "bbccccccccccaaaa",
      "bbcccccccaaaaaaa",
      "aaaaaaaaaaaaaaaa",
      "aaaaaaaaaaaaaaaa",
      "aaaaaaaaaaaaaaaa",
      "aaaaaaaaaaaaaaaa",
      "aaaaaaaaaaaaaaaa",
      "aaaaaaaaaaaaaaaa",
      "aaaaaaaaaaaaaaaa",
      "aaaaaaaaaaaaaaaa",
      "aaaaaaaaaaaaaaaa",
      "aaaaaaaaaaaaaaaa",
      "aaaaaaaaaaaaaaaa",
      "aaaaaaaaaaaaaaaa",
      "vvvvvvvvvvvvvvvv"
    ],
    [
      "      d d   eccc",
      "ff      geeecccc",
      "hheeeeeeeccccccc",
      "bbcccccccccccccc",
      "bbcccccccccccccc",
      "bbccccccccccccaa",
      "aaaaaaaaaaaaaaaa",
      "aaaaaaaaaaaaaaaa",
      "aaaaaaaaaaaaaaaa",
      "aaaaaaaaaaaaaaaa",
      "iiiiiaaaaaaaaaaa",
      "iiiiiaaaaaaaaaaa",
      "iiiiiaaaaaaaaaaa",
      "iiiiiaaaaaaaaaaa",
      "iiiiiaaaaaaaaaaa",
      "vvvvvvvvvvvvvvvv"
    ],
    [
      "                ",
      "        j     g ",
      "          g k d ",
      "    d     d  g  ",
      "ff     d      ee",
      "hheeeeeeeeeeeecc",
      "bbcccccccccccccc",
      "bbcccccccccccccc",
      "bbcccccccccccccc",
      "iiiii           ",
      "iiiii           ",
      "iiiii           ",
      "iiiii           ",
      "iiiii           ",
      "iiiii           ",
      "vvvvvvvvvvvvvvvv"
    ],
    [
      "                ",
      "        l     j ",
      "          j m   ",
      "             j  ",
      "                ",
      "                ",
      "         g d   g",
      "ff no  k    gd  ",
      "hhiiieeeeeeeeeee",
      "bbiiiccccccccccc",
      "bbiiiccccccccccc",
      "bbiiiccccccccccc",
      "iiiii           ",
      "iiiii           ",
      "iiiii           ",
      "vvvvvvvvvvvvvvvv"
    ]
  ]
}