{
  "name": "multi_sunkenmonumentpark_11_ground",
  "refpalette": "deceasedcraft:multi_sunkenmonumentpark_11/multi_sunkenmonumentpark_11_ground_palette",
  "xsize": 16,
  "zsize": 16,
  "slices": [
    [
      "                ",
      "        a     a ",
      "          a b   ",
      "             a  ",
      "    cc          ",
      "  cccd          ",
      "  deee   b     b",
      "  eee  f    b   ",
      "  eee           ",
      "  eee   g hg    ",
      "iieee   h     gh",
      "jjkkelllllllllll",
      "mmkkennnnnnnnnnn",
      "mmkkeennnnnnnnnn",
      "mmkkeeeeeeeeeeee",
      "mmkkeeeeeeeeeeee"
    ],
    [
      "cccccccc        ",
      "cccceee o     a ",
      "  eeeee   a a   ",
      "  eeeee      a  ",
      "  eeee          ",
      "  kkke          ",
      "  kkke   a     a",
      "  kke  b    a   ",
      "  ppe           ",
      "  ppe   b  b    ",
      "  ppq         b ",
      "    q           ",
      "    q      g   h",
      "        g  hr   ",
      "                ",
      "         h      "
    ],
    [
      "kkkkkkke        ",
      "eekkkke       o ",
      "  ppppe   o a   ",
      "  ppppe      o  ",
      "  pppq          ",
      "     q          ",
      "     s   a     a",
      "    q  a    a   ",
      "    q           ",
      "    q   a  a    ",
      "              a ",
      "                ",
      "           b    ",
      "        b   f   ",
      "                ",
      "                "
    ],
    [
      "       s        ",
      "t     q         ",
      "uu    q     o   ",
      "      s         ",
      "                ",
      "                ",
      "               a",
      "       a    o   ",
      "                ",
      "        a  a    ",
      "              a ",
      "                ",
      "           a    ",
      "        a   b   ",
      "                ",
      "                "
    ],
    [
      "                ",
      "                ",
      "                ",
      "                ",
      "                ",
      "                ",
      "                ",
      "       o        ",
      "                ",
      "        a  o    ",
      "              o ",
      "                ",
      "           a    ",
      "        a   a   ",
      "                ",
      "                "
    ],
    [
      "                ",
      "                ",
      "                ",
      "                ",
      "                ",
      "                ",
      "                ",
      "                ",
      "                ",
      "        o       ",
      "                ",
      "                ",
      "           o    ",
      "        o   a   ",
      "                ",
      "                "
    ]
  ]
}