{
  "name": "multi_sunkenmonumentpark_3_ground",
  "refpalette": "deceasedcraft:multi_sunkenmonumentpark_3/multi_sunkenmonumentpark_3_ground_palette",
  "xsize": 16,
  "zsize": 16,
  "slices": [
    [
      "aabbc           ",
      "aabbc d         ",
      "aabbc           ",
      "aabbc e    f    ",
      "aabbc           ",
      "aabbc       g g ",
      "aabbc  e        ",
      "aabbc d         ",
      "aabbbc   h      ",
      "aabbbc   e  d   ",
      "aabbbbcc   hh   ",
      "aabbbbbbcccccccc",
      "aaabbbbbbbbbbbbb",
      "aaaabbbbbbbbbbbb",
      "aiaaaaaaaaaaaaaa",
      "aaaaaaaaaaaaaaaa"
    ],
    [
      " he             ",
      "      f         ",
      "                ",
      "  h   g    g    ",
      "                ",
      "   e        j j ",
      "  h    g        ",
      "      f         ",
      "   h            ",
      "         g  f   ",
      "   e h          ",
      "     h          ",
      "     e h hh e   ",
      "        e   h d ",
      "             h  ",
      "                "
    ],
    [
      "  g             ",
      "      g         ",
      "                ",
      "      j    j    ",
      "                ",
      "   g        j j ",
      "       j        ",
      "      g         ",
      "                ",
      "         j  g   ",
      "   g            ",
      "                ",
      "     g      g   ",
      "        g     f ",
      "                ",
      "                "
    ],
    [
      "  j             ",
      "      j         ",
      "                ",
      "      j    j    ",
      "                ",
      "   j        k k ",
      "       j        ",
      "      j         ",
      "                ",
      "         j  j   ",
      "   j            ",
      "                ",
      "     j      j   ",
      "        j     g ",
      "                ",
      "                "
    ],
    [
      "  j             ",
      "      j         ",
      "                ",
      "      k    k    ",
      "                ",
      "   j            ",
      "       k        ",
      "      j         ",
      "                ",
      "            j   ",
      "   j            ",
      "                ",
      "     j      j   ",
      "        j     j ",
      "                ",
      "                "
    ],
    [
      "  k             ",
      "                ",
      "                ",
      "                ",
      "                ",
      "   k            ",
      "                ",
      "      k         ",
      "                ",
      "            k   ",
      "   k            ",
      "                ",
      "     j      k   ",
      "        k     j ",
      "                ",
      "                "
    ]
  ]
}