{
  "name": "multi_taigaresidence_0_floor6",
  "refpalette": "deceasedcraft:multi_taigaresidence_0/multi_taigaresidence_0_floor6_palette",
  "xsize": 16,
  "zsize": 16,
  "slices": [
    [
      "                ",
      "          a     ",
      "  bbbbbbbba     ",
      "  bcccccccaddddd",
      "  bceeeeeeffffff",
      "  bcegggggffffff",
      "  bcegggggffffff",
      "  bcegggggffffff",
      "  bceggggggggggg",
      "  bceggggggggggg",
      "  bceggggggggggg",
      "  bceggggggggggg",
      "  bceggggggggggg",
      " aaaeggggggggggg",
      "   heiiiiiffffff",
      "   heiiiiifjkkkk"
    ],
    [
      "                ",
      "          a     ",
      "          a     ",
      "   ccccccca     ",
      "   ceellleee    ",
      "   ce!mnooe  pp ",
      "   ceq    r     ",
      "   ces  ttee    ",
      "   ceu  ww    xy",
      "   ceA          ",
      "   ceBBBB     C ",
      "   ceD  E     F ",
      "   ceIJ B KLM   ",
      " aaaeN  B KLM O ",
      "    eBBPBQeeeeee",
      "    R     e!    "
    ],
    [
      "                ",
      "          a     ",
      "          a     ",
      "          a     ",
      "    ee   eee    ",
      "    e   STeU    ",
      "    e     V     ",
      "    e     ee    ",
      "    eW     U    ",
      "    eX Y        ",
      "    eBBBB       ",
      "    e!  Z       ",
      "    e  0B       ",
      " aaaeN  B      Y",
      "    eBB1B2eeeeee",
      "      3   ec    "
    ],
    [
      "                ",
      "          a     ",
      "          a     ",
      "          a     ",
      "    ee   eee    ",
      "    e4    e     ",
      "    e5    6     ",
      "    e7    ee    ",
      "    e4     8    ",
      "    e5          ",
      "    eBBBB       ",
      "    e   B       ",
      "    e   B       ",
      " aaae   B       ",
      "    eBBBBBeeeeee",
      "          ec    "
    ],
    [
      "                ",
      "          a     ",
      "          a     ",
      "   9999999a     ",
      "   9eeeeeeeeeeee",
      "   9e#    e     ",
      "   9e#    e     ",
      "   9e  $  ee    ",
      "   9e           ",
      "   9e#          ",
      "   9eBBBB  %    ",
      "   9e   B       ",
      "   9e % B       ",
      " aaae   B       ",
      "    eBBBBBeeeeee",
      "    e  $  e^    "
    ],
    [
      "                ",
      "          a     ",
      "          a&&&&&",
      "   *******a     ",
      "   *eeeeeeeeeeee",
      "   *e(((((ekkkkk",
      "   *e(((((ekkkkk",
      "   *e(((((ee))))",
      "   *e(((((((((((",
      "   *e(((((((((((",
      "   *e(((((((((((",
      "   *e(((((((((((",
      "   *e(((((((((((",
      " aaae(((((((((((",
      "    e(((((eeeeee",
      "    e(((((e     "
    ]
  ]
}