{
  "name": "multi_taigaresidence_0_ground",
  "refpalette": "deceasedcraft:multi_taigaresidence_0/multi_taigaresidence_0_ground_palette",
  "xsize": 16,
  "zsize": 16,
  "slices": [
    [
      "aaaaaaaaaaaaaaaa",
      "aaaaaaaaaaaaaaaa",
      "aaaabbbbbbbbbbbb",
      "aaaabcccccbccccc",
      "aaaabbbbbbbccccc",
      "aaaabccccccccccc",
      "aaaabccccccccccc",
      "aaaabccccccccccc",
      "aaaabccccccccccc",
      "aaaabccccccdcccc",
      "aaeebccccccccccc",
      "aaacbccccccccccd",
      "aaacbccccccccccc",
      "afffbccccccccccc",
      "aaacbccccccccccc",
      "aaacbccccccccccc"
    ],
    [
      "                ",
      "                ",
      "  g bbbbbbbbbbbb",
      "    bhhhhhbhhhhh",
      "  g bbbbbbbbbbbb",
      "    bijk ijk ijk",
      "  g bljm ljm ljm",
      "    b           ",
      "  g b   n opq   ",
      "    b   rjr  r s",
      "  eebtru r srjr ",
      "    bw    u     ",
      "    bwr   r r rn",
      " fffbx    yAAAB ",
      "    bcC  CcCCCCC",
      "    DE     FIIJ!"
    ],
    [
      "                ",
      "                ",
      "  K             ",
      "          b     ",
      "  K       b     ",
      "              L ",
      "  K       L     ",
      "                ",
      "  K             ",
      "         M      ",
      "  eebN       L  ",
      "    b           ",
      "    bL          ",
      " fffb          O",
      "    bcP  PcPPPPP",
      "          K     "
    ],
    [
      "                ",
      "                ",
      "  P             ",
      "          b     ",
      "  P       b     ",
      "                ",
      "  P             ",
      "                ",
      "  P             ",
      "                ",
      "  eeb           ",
      "    b           ",
      "    b           ",
      " fffb         O ",
      "    bc    c     ",
      "                "
    ],
    [
      "                ",
      "                ",
      "  P             ",
      "          b     ",
      "  P       b     ",
      "                ",
      "  P             ",
      "                ",
      "  P             ",
      "                ",
      "  eeb           ",
      "    b           ",
      "    b           ",
      " fffb        O  ",
      "    bc    c     ",
      "    b           "
    ],
    [
      "                ",
      "                ",
      "  Q             ",
      "          b     ",
      "  Q       b     ",
      "                ",
      "  Q       R     ",
      "                ",
      "  Q             ",
      "                ",
      "  eeb           ",
      "    b           ",
      "    bS    R     ",
      " fffb       O   ",
      "    bc    c     ",
      "    b           "
    ]
  ]
}