{
  "name": "multi_taigaresidence_0_floor5",
  "refpalette": "deceasedcraft:multi_taigaresidence_0/multi_taigaresidence_0_floor5_palette",
  "xsize": 16,
  "zsize": 16,
  "slices": [
    [
      "                ",
      "          a     ",
      "  bbbbbbbba     ",
      "  b    cccaddddd",
      "  b efeghhhhiiih",
      "  bcfjfklkkkkkkk",
      "  bchfmkkkkkkkkk",
      "  bchknklkkkkkkk",
      "  bchkkkkkkkkkkk",
      "  bchkkkkkkkkkkk",
      "  bchkkkkkkkkkkk",
      "  bchkkkkkkkkooo",
      "  bchkkkkkkkkooo",
      " aaahkkkkkkkkooo",
      "   dhoookkpppppp",
      "   dhoookkpqrrrr"
    ],
    [
      "                ",
      "          a     ",
      "          a     ",
      "        cca     ",
      "       sthhh   h",
      "       e uwx   y",
      "    eA uBCwx D E",
      "   che F  w DI J",
      "   ch!KIL wM www",
      "   chwww NwO P Q",
      "   chQ R  wS w T",
      "   chT wM wU wVw",
      "   ch  wO w  P W",
      " aaahX wS wYYw Z",
      "    hw0w1 hh2hhh",
      "    34 5  6     "
    ],
    [
      "                ",
      "          a     ",
      "          a     ",
      "          a     ",
      "         hhh   h",
      "          w7    ",
      "          w8    ",
      "    t     w9 #  ",
      "    hN #  w$ www",
      "    hwww% w  ^ &",
      "    h  *  w  w &",
      "    h (w$ w) w+w",
      "    h  w  w  ^  ",
      " aaah- w  w[xw] ",
      "    hw{w  hh}hhh",
      "     | ;  :     "
    ],
    [
      "                ",
      "          a     ",
      "          a     ",
      "          a     ",
      "         hhh   h",
      "          w     ",
      "    '     w     ",
      "    h     w     ",
      "    h     w  www",
      "    hwww  w< w  ",
      "    h  w  w  w !",
      "    h  w  w  www",
      "    h  w  w  w  ",
      " aaah  w  w>>w, ",
      "    hwww  hh.hhh",
      "     ? w  /     "
    ],
    [
      "                ",
      "          a     ",
      "          a     ",
      "   ```````a     ",
      "   `'thhhhhhhhhh",
      "   `s     w     ",
      "   `h  \u0370  w  \u0370 \u0371",
      "   `h     w     ",
      "   `h  \u0372  w  www",
      "   `hwww  w  w  ",
      "   `h  w  w \u0373w  ",
      "   `h \u0371w  w  www",
      "   `h  w  w  w  ",
      " aaah  w  w  w  ",
      "    hwww  hhhhhh",
      "    h  w  h     "
    ],
    [
      "                ",
      "          a     ",
      "          a\u0374\u0374\u0374\u0374\u0374",
      "   \u0375\u0375\u0375\u0375\u0375\u0375\u0375a     ",
      "   \u0375hhhhhhhhhhhh",
      "   \u0375h\u0376\u0376\u0376\u0376\u0376\u0376\u0376\u0376\u0376\u0376\u0376",
      "   \u0375h\u0376\u0376\u0376\u0376\u0376\u0376\u0376\u0376\u0376\u0376\u0376",
      "   \u0375h\u0376\u0376\u0376\u0376\u0376\u0376\u0376\u0376\u0376\u0376\u0376",
      "   \u0375h\u0376\u0376\u0376\u0376\u0376\u0376\u0376\u0376\u0376\u0376\u0376",
      "   \u0375h\u0376\u0376\u0376\u0376\u0376\u0376\u0376\u0376\u0376\u0376\u0376",
      "   \u0375h\u0376\u0376\u0376\u0376\u0376\u0376\u0376\u0376\u0376\u0376\u0376",
      "   \u0375h\u0376\u0376\u0376\u0376\u0376\u0376\u0376\u0376\u0376\u0376\u0376",
      "   \u0375h\u0376\u0376\u0376\u0376\u0376\u0376\u0376\u0376\u0376\u0376\u0376",
      " aaah\u0376\u0376\u0376\u0376\u0376\u0376\u0376\u0376\u0376\u0376\u0376",
      "    h\u0376\u0376\u0376\u0376\u0376hhhhhh",
      "    h\u0376\u0376\u0376\u0376\u0376h     "
    ]
  ]
}