{
  "name": "multi_taigaresidence_0_floor3",
  "refpalette": "deceasedcraft:multi_taigaresidence_0/multi_taigaresidence_0_floor3_palette",
  "xsize": 16,
  "zsize": 16,
  "slices": [
    [
      "                ",
      "          a     ",
      "  bbbbbbbba     ",
      "  bcccccccaddddd",
      "  bceeeeeeeefffe",
      "  bceggggggggggg",
      "  bceggggggggggg",
      "  bceggggggggggg",
      "  bceggggggggggg",
      "  bceggggggggggg",
      "  bceggggggggggg",
      "  bcegggggggghhh",
      "  bcegggggggghhh",
      " aaaegggggggghhh",
      "   dehhhggiiiiii",
      "   dehhhggijkkkk"
    ],
    [
      "                ",
      "          a     ",
      "          a     ",
      "   ccccccca     ",
      "   ceellleee   e",
      "   cemn   opq  r",
      "   ce     opq  s",
      "   ce  pq o  tt ",
      "   cettpq ou ooo",
      "   ceooo  ow x y",
      "   cey A  oB o C",
      "   ceC ou oD oEo",
      "   ceF ow oI x J",
      " aaaeK oB oI o L",
      "    eoMoD eeNeee",
      "    O  A  P     "
    ],
    [
      "                ",
      "          a     ",
      "          a     ",
      "          a     ",
      "    ee   eee   e",
      "    e     o     ",
      "    e     o!    ",
      "    e     oQ  R ",
      "    eSTU  oV ooo",
      "    eoooQ o  W X",
      "    e  Y  o  o X",
      "    e  oV oF oZo",
      "    e  o  o  W  ",
      " aaae! o  o  o0 ",
      "    eo1o2 ee3eee",
      "     4 Y  5     "
    ],
    [
      "                ",
      "          a     ",
      "          a     ",
      "          a     ",
      "    ee   eee   e",
      "    e     o     ",
      "    e     o     ",
      "    e     o     ",
      "    e     o  ooo",
      "    eooo  o  o  ",
      "    e  o  o  o 6",
      "    e  o  o  ooo",
      "    e  o  o  o  ",
      " aaae  o  o  o7 ",
      "    eooo  ee8eee",
      "     9 o  #     "
    ],
    [
      "                ",
      "          a     ",
      "          a     ",
      "   $$$$$$$a     ",
      "   $eeeeeeeeeeee",
      "   $e     o     ",
      "   $e     o     ",
      "   $e     o     ",
      "   $e     o  ooo",
      "   $eooo  o  o  ",
      "   $e  o  o  o  ",
      "   $e  o  o  ooo",
      "   $e  o  o  o  ",
      " aaae  o  o  o  ",
      "    eooo  eeeeee",
      "    e  o  e     "
    ],
    [
      "                ",
      "          a     ",
      "          a%%%%%",
      "   ^^^^^^^a     ",
      "   ^eeeeeeeeeeee",
      "   ^e&&&&&&&&&&&",
      "   ^e&&&&&&&&&&&",
      "   ^e&&&&&&&&&&&",
      "   ^e&&&&&&&&&&&",
      "   ^e&&&&&&&&&&&",
      "   ^e&&&&&&&&&&&",
      "   ^e&&&&&&&&&&&",
      "   ^e&&&&&&&&&&&",
      " aaae&&&&&&&&&&&",
      "    e&&&&&eeeeee",
      "    e&&&&&e     "
    ]
  ]
}