{
  "name": "multi_taigaresidence_0_floor4",
  "refpalette": "deceasedcraft:multi_taigaresidence_0/multi_taigaresidence_0_floor4_palette",
  "xsize": 16,
  "zsize": 16,
  "slices": [
    [
      "                ",
      "          a     ",
      "  bbbbbbbba     ",
      "  bcccccccaddddd",
      "  bceeeeeeeefffe",
      "  bceggggggggggg",
      "  bceggggggggggg",
      "  bceggggggggggg",
      "  bceggggggggggg",
      "  bceggggggggggg",
      "  bceggggggggggg",
      "  bceggggggggggg",
      "  bcehhhgggggggg",
      " aaaehhhgggggggg",
      "   dehhhggiiiiii",
      "   dehhhggijkkkk"
    ],
    [
      "                ",
      "          a     ",
      "          a     ",
      "   ccccccca     ",
      "   ceellleee   e",
      "   cem   no!    ",
      "   cep  qros t n",
      "   ceuw qrox t n",
      "   ce    no     ",
      "   cey oooo     ",
      "   cey A       B",
      "   cey o CD    E",
      "   ceoFo CD    E",
      " aaaeI o  DJKLMN",
      "    eOPo  eeeeee",
      "    Q! A  R     "
    ],
    [
      "                ",
      "          a     ",
      "          a     ",
      "          a     ",
      "    ee   eee   e",
      "    e    So     ",
      "    e     o     ",
      "    eT    o    U",
      "    e    Vo     ",
      "    ey ooooW   W",
      "    ey X  Y     ",
      "    ey o        ",
      "    eoZo       0",
      " aaae1 o  234   ",
      "    e  o  eeeeee",
      "       X  5     "
    ],
    [
      "                ",
      "          a     ",
      "          a     ",
      "          a     ",
      "    ee   eee   e",
      "    e     o     ",
      "    e     o     ",
      "    e     o     ",
      "    e     o     ",
      "    e  oooo     ",
      "    e  o        ",
      "    e  o        ",
      "    eooo        ",
      " aaae6 o     7  ",
      "    e  o  eeeeee",
      "       o  8     "
    ],
    [
      "                ",
      "          a     ",
      "          a     ",
      "   9999999a     ",
      "   9eeeeeeeeeeee",
      "   9e     o     ",
      "   9e     o     ",
      "   9e     o  #  ",
      "   9e     o     ",
      "   9e  oooo     ",
      "   9e  o        ",
      "   9e  o        ",
      "   9eooo        ",
      " aaae  o        ",
      "    e  o  eeeeee",
      "    e  o  e     "
    ],
    [
      "                ",
      "          a     ",
      "          a$$$$$",
      "   %%%%%%%a     ",
      "   %eeeeeeeeeeee",
      "   %e^^^^^^^^^^^",
      "   %e^^^^^^^^^^^",
      "   %e^^^^^^^^^^^",
      "   %e^^^^^^^^^^^",
      "   %e^^^^^^^^^^^",
      "   %e^^^^^^^^^^^",
      "   %e^^^^^^^^^^^",
      "   %e^^^^^^^^^^^",
      " aaae^^^^^^^^^^^",
      "    e^^^^^eeeeee",
      "    e^^^^^e     "
    ]
  ]
}