{
  "name": "multi_taigaresidence_0_floor2",
  "refpalette": "deceasedcraft:multi_taigaresidence_0/multi_taigaresidence_0_floor2_palette",
  "xsize": 16,
  "zsize": 16,
  "slices": [
    [
      "                ",
      "          aaaaaa",
      "  bbbbbbbbaaaaaa",
      "  bcccccccaaaaaa",
      "  bcddddddeeeeee",
      "  bcdeeeeeeeeeee",
      "  bcdeeeeeeeeeee",
      "  bcdeeeeeeeeeee",
      "  bcdeeeeeeeeeee",
      "  bcdeeeeeeeeeee",
      "  bcdeeeeeeeeeee",
      "  bcdeeeeeeeeeee",
      "  bcdeeeeeeeeeee",
      " aaadeeeeeeeeeee",
      "   fdeeeeeeeeeee",
      "   fdeeeeeeghhhh"
    ],
    [
      "                ",
      "          a     ",
      "          a     ",
      "   ccccccca     ",
      "   cddiiiddd    ",
      "   cdj   kd  ll ",
      "   cdj    m     ",
      "   cdj n  dd    ",
      "   cdj    o  pp ",
      "   cdj    oqrsst",
      "   cdj    o rsst",
      "   cdj n  o rsst",
      "   cdj    oqrsst",
      " aaadj    o  uu ",
      "    ddddwddd    ",
      "    x           "
    ],
    [
      "                ",
      "          a     ",
      "          a     ",
      "          a     ",
      "    dd   ddd    ",
      "    dj    dy    ",
      "    dA    B     ",
      "    dC    dd    ",
      "    d     o     ",
      "    dj    o     ",
      "    dA    o     ",
      "    dC    o     ",
      "    d     o     ",
      " aaadj    o     ",
      "    ddddDddd    ",
      "                "
    ],
    [
      "                ",
      "          a     ",
      "          a     ",
      "          a     ",
      "    dd   ddd    ",
      "    dj    d     ",
      "    d     E     ",
      "    d     dd    ",
      "    d           ",
      "    dj          ",
      "    d           ",
      "    d           ",
      "    d           ",
      " aaadj          ",
      "    ddddFddd    ",
      "                "
    ],
    [
      "                ",
      "          a     ",
      "          a     ",
      "   IIIIIIIaJJJJJ",
      "   Idddddddddddd",
      "   IdK    d     ",
      "   IdK    d     ",
      "   IdK    dd    ",
      "   IdK          ",
      "   IdK          ",
      "   IdK          ",
      "   IdK          ",
      "   IdK          ",
      " aaadK          ",
      "    dddddddd    ",
      "    d           "
    ],
    [
      "                ",
      "          a     ",
      "          aLLLLL",
      "   MMMMMMMa     ",
      "   Mdddddddddddd",
      "   MdNghhhd     ",
      "   MdOghhhd     ",
      "   MdPghhhddQQQQ",
      "   MdRghhhhhhhhh",
      "   MdSghhTTThhTh",
      "   MdUghhThThThT",
      "   MdVghhhThhhTh",
      "   MdWghhhhhhhhh",
      " aaadNghhhhhhhhh",
      "    ddddddddFFFF",
      "    dXXXXXX     "
    ]
  ]
}