{
  "name": "multi_taigaresidence_0_floor1",
  "refpalette": "deceasedcraft:multi_taigaresidence_0/multi_taigaresidence_0_floor1_palette",
  "xsize": 16,
  "zsize": 16,
  "slices": [
    [
      "                ",
      "                ",
      "                ",
      "          a     ",
      "          a     ",
      "     bbbbbc     ",
      "     bbbbbc     ",
      "     bbbbbc     ",
      "     bbbbbc     ",
      "     bbbbbc     ",
      "  ddabbbbbc     ",
      "    abbbbbc     ",
      "    abbbbbc     ",
      " eeeabbbbbcf    ",
      "   gahhhhhhhhhhh",
      "   gaiiiiiiiiiii"
    ],
    [
      "                ",
      "                ",
      "                ",
      "   jjjjjjjajjjjj",
      "   jaaaaaaaaaaaa",
      "   ja  klmn     ",
      "   ja!   on     ",
      "   jap q rn     ",
      "   jas q pn     ",
      "   jat    n     ",
      "  ddauwx  n     ",
      "    ay    n     ",
      "    aA    n     ",
      " eeeaA          ",
      "    a      BBBBB",
      "    C           "
    ],
    [
      "                ",
      "                ",
      "                ",
      "          a     ",
      "    aaaaaaaaaaaa",
      "    aD          ",
      "    a           ",
      "    a           ",
      "    a           ",
      "    a           ",
      "  dda           ",
      "    ay          ",
      "    aA          ",
      " eeeaA          ",
      "    aD    D     ",
      "                "
    ],
    [
      "                ",
      "                ",
      "  dddddddddddddd",
      "  dddddddddddddd",
      "  ddaaaaaaaaaaaa",
      "  dda           ",
      "  dda           ",
      "  dda           ",
      "  dda           ",
      "  dda           ",
      "  dda           ",
      "    a           ",
      "    a           ",
      " eeea           ",
      "    a           ",
      "                "
    ],
    [
      "                ",
      "                ",
      "                ",
      "                ",
      "    aaaaaaaaaaaa",
      "    a        EFF",
      "    a           ",
      "    a           ",
      "    a           ",
      "    a           ",
      "    a           ",
      "    a           ",
      "    a           ",
      " eeea           ",
      "    a           ",
      "    a           "
    ],
    [
      "                ",
      "                ",
      "                ",
      "   BBBBBBBBBBBBB",
      "   Baaaaaaaaaaaa",
      "   BaIIIIIIIIIII",
      "   BaIIIIIIIIIII",
      "   BaIIIIIIIIIII",
      "   BaIIIIIIIIIII",
      "   BaIIIIIIIIIII",
      "   BaIIIIIIIIIII",
      "   BaIIIIIIIIIII",
      "   BaIIIIIIIIIII",
      " eeeaIIIIIIIIIII",
      "    aBBBBBBBBBBB",
      "    a           "
    ]
  ]
}