{
  "name": "multi_timbertower_6_ground",
  "refpalette": "deceasedcraft:multi_timbertower_6/multi_timbertower_6_ground_palette",
  "xsize": 16,
  "zsize": 16,
  "slices": [
    [
      "abbbbbabbbbabbbb",
      "baabaabaababaabb",
      "bbabbbbbbabbbbbb",
      "vvvvvvvvvvvvvvbb",
      "vvvvcccccddddbbb",
      "vvvvcccccddddbbb",
      "vvevcccccddddbbb",
      "vvvvcccccddddbbb",
      "vvvvcccccddddbbb",
      "vvvvcccccddddbbb",
      "vvvvcccccddddbbb",
      "vvvvcccccddddbbb",
      "vvvvcccccddddbbb",
      "vvevcccccddddbbb",
      "vvvvcccccddddbbb",
      "vvvvcccccddddbbb"
    ],
    [
      "                ",
      "                ",
      "ff fffg f ffg   ",
      "hhihhhhhhihhjj  ",
      "ddeccddddk      ",
      "ddeccdddd       ",
      "ddeccdddd       ",
      "ddeccdddd       ",
      "ddeccdddd       ",
      "ddeccdddd       ",
      "ddeccdddd       ",
      "ddeccdddd       ",
      "ddeccdddd       ",
      "ddeccdddd       ",
      "ddeccdddd       ",
      "ddeccdddd       "
    ],
    [
      "                ",
      "                ",
      "                ",
      "hhihhhhhjl      ",
      "ddddd           ",
      "ddddd           ",
      "ddddd           ",
      "ddddd           ",
      "ddddd           ",
      "ddddd           ",
      "ddddd           ",
      "ddddd           ",
      "ddddd           ",
      "ddedd           ",
      "ddddd           ",
      "ddddd           "
    ],
    [
      "                ",
      "                ",
      "                ",
      "hhihjj          ",
      "d k             ",
      "d               ",
      "d               ",
      "d               ",
      "d               ",
      "d               ",
      "d               ",
      "d               ",
      "d               ",
      "d e             ",
      "d m             ",
      "d               "
    ],
    [
      "                ",
      "                ",
      "                ",
      "jj              ",
      "                ",
      "                ",
      "                ",
      "                ",
      "                ",
      "                ",
      "                ",
      "                ",
      "                ",
      "  n             ",
      "                ",
      "                "
    ],
    [
      "                ",
      "                ",
      "                ",
      "                ",
      "                ",
      "                ",
      "                ",
      "                ",
      "                ",
      "                ",
      "                ",
      "                ",
      "                ",
      "  e             ",
      "                ",
      "                "
    ]
  ]
}