{
  "name": "multi_militaryradiocamp_0_ground",
  "refpalette": "deceasedcraft:multi_militaryradiocamp_0/multi_militaryradiocamp_0_ground_palette",
  "xsize": 16,
  "zsize": 16,
  "slices": [
    [
      "zzaazaazzaazzaaz",
      "zbbbbzabbbbbbbbz",
      "zbccccczddddd=ez",
      "abccccczddddddd=",
      "abccccczdddddddd",
      "aaccccczdddddddd",
      "zzcccccddddddddd",
      "zbfffffcddezdddd",
      "zbcccccz=zzz=ddd",
      "abzzgzzzzzzzeddd",
      "zbzzzzzzezzzzddd",
      "zbzzzzzzzzzzzzdd",
      "abzzzzzzzzzz=dd=",
      "abzzzzzzzzzzze=z",
      "zbbbbbazbbbbzbbb",
      "zaazzaazazzazzaa"
    ],
    [
      "                ",
      " hiiiiihjjjjjhjj",
      " ik ilmi    noo ",
      " ip iqris  t  uw",
      " iixi yiA   A BC",
      " iD  E iF   FI  ",
      " iJKL  M   t    ",
      " iN OPQi        ",
      " ihRSThiU       ",
      " hii iihV       ",
      " jWXhXW         ",
      " jYXXXZ         ",
      " jWXXXW 0       ",
      " j 111 h2345 3 0",
      " hjjjjjhjjjjjhjj",
      "                "
    ],
    [
      "                ",
      " hiiiiihjjjjjhjj",
      " i 6i  i     o  ",
      " i  i  7   t  8 ",
      " ii9i  7    #   ",
      " i$    i%       ",
      " i^    &   t    ",
      " i     i        ",
      " ihR*(hi        ",
      " hii iih        ",
      " jW(g(W         ",
      " j Sg           ",
      " jW   W         ",
      " j     h        ",
      " hjjjjjhjjjjjhjj",
      "                "
    ],
    [
      "                ",
      " hiiiiih)))))+))",
      " i  i  i        ",
      " i  i  7   -[]][",
      " ii{i  7   }]][[",
      " i     i   -]]][",
      " i     |   -[[]]",
      " i;   ;i        ",
      " ih 11hi        ",
      " hi:::ih        ",
      " '<(g(<>        ",
      " ' *g, >        ",
      " '<   <>        ",
      " '     +        ",
      " +.....+.....+..",
      "                "
    ],
    [
      "                ",
      " h?????h        ",
      " /``X``\u0370        ",
      " /``X``\u0370        ",
      " /XXX``\u0370        ",
      " /`````\u0370        ",
      " /`````\u0370        ",
      " /gg`gg\u0370        ",
      " /gg`gg\u0370        ",
      " h\u0371:::\u0371h        ",
      "  <111<         ",
      "    <           ",
      "  <   <         ",
      "                ",
      "                ",
      "                "
    ],
    [
      "                ",
      " \u0372+++++\u0372        ",
      " +     +        ",
      " +     +        ",
      " +     +        ",
      " +     +        ",
      " +?? ??+        ",
      " +gg gg+        ",
      " +gg gg+        ",
      " \u0372+++++\u0372        ",
      "  \u0373WWW\u0373         ",
      "  \u0373\u0374R\u0374\u0373         ",
      "  \u0373WWW\u0373         ",
      "                ",
      "                ",
      "                "
    ]
  ]
}