{
  "name": "multi_flatlarge_4_ground",
  "refpalette": "deceasedcraft:multi_flatlarge_4/multi_flatlarge_4_ground_palette",
  "xsize": 16,
  "zsize": 16,
  "slices": [
    [
      "HHHHHHHHHHHHHHHH",
      "HHHHHHHHHHHHHHHH",
      "aaaaaaaaaaaaaaaa",
      "bbbbbbbbbbbbbbbb",
      "cdccccccccdbbbbb",
      "ccccccccccbbbbbb",
      "ccccccccccbbbbbb",
      "ccccccccccbbbbbb",
      "cccccccccccccccc",
      "cccccccccccccccc",
      "cccccccccccccccc",
      "cccccccccccccccc",
      "cccccccccccccccc",
      "cccccccccccccccc",
      "cdccccccccdccccc",
      "dddddddddddddddd"
    ],
    [
      "                ",
      "                ",
      "                ",
      "eeeeeeeeeee     ",
      "fghfhfhfhfg     ",
      "          e     ",
      "          e     ",
      "i jijijijieeeeee",
      "                ",
      "                ",
      "                ",
      "  hfhfhfhf hfhfh",
      "                ",
      "                ",
      " gjijijijigjijij",
      "kklkklkklklkkllk"
    ],
    [
      "                ",
      "                ",
      "                ",
      "                ",
      " m        m     ",
      "                ",
      "                ",
      "                ",
      "                ",
      "                ",
      "                ",
      "                ",
      "                ",
      "                ",
      " m        m     ",
      "                "
    ],
    [
      "                ",
      "                ",
      "                ",
      "                ",
      " m        m     ",
      "                ",
      "                ",
      "                ",
      "                ",
      "                ",
      "                ",
      "                ",
      "                ",
      "                ",
      " m        m     ",
      "                "
    ],
    [
      "                ",
      "                ",
      "                ",
      "                ",
      "nmnnnnnnnnm     ",
      " o        p     ",
      " o        p     ",
      " o        p     ",
      " o        p     ",
      " o        p     ",
      " o        p     ",
      " o        p     ",
      " o        p     ",
      " o        p     ",
      "omoooooooom     ",
      "          p     "
    ],
    [
      "                ",
      "                ",
      "                ",
      "oooooooooooo    ",
      "qqqqqqqqqqqo    ",
      "rqrrrrrrrrqo    ",
      "rqrrrrrrrrqo    ",
      "rqrrrrrrrrqo    ",
      "rqrrrrrrrrqo    ",
      "rqrrrrrrrrqo    ",
      "rqrrrrrrrrqo    ",
      "rqrrrrrrrrqo    ",
      "rqrrrrrrrrqo    ",
      "rqrrrrrrrrqo    ",
      "qqqqqqqqqqqo    ",
      "rqrrrrrrrrqo    "
    ]
  ]
}