{
  "name": "multi_flatlarge_4_floor1",
  "refpalette": "deceasedcraft:multi_flatlarge_4/multi_flatlarge_4_floor1_palette",
  "xsize": 16,
  "zsize": 16,
  "slices": [
    [
      "                ",
      "                ",
      "                ",
      "abaaaaaaaab     ",
      "cacccdddddde    ",
      "cacccdddddda    ",
      "cacccdddddda    ",
      "cacccdddddda    ",
      "daddddddddda    ",
      "daddddddddda    ",
      "daddddddddda    ",
      "daddddddddda    ",
      "daddddddddda    ",
      "dadddddddddaffff",
      "gggggggggggggggg",
      "gggggggggggggggg"
    ],
    [
      "                ",
      "                ",
      "                ",
      "abahihhhhab     ",
      " a  hj   kle    ",
      "mam hn   ola    ",
      "paq hr    se    ",
      "tau hw  xx e    ",
      "aaayaaa AABe    ",
      "CaD   E   Fe    ",
      "IaJ   a   Ke    ",
      "LaM NOaP  Qe    ",
      "LaM NOaR  Ke    ",
      "SaT   aP  UaVVVV",
      "WXWWWWWWYWWe    ",
      "                "
    ],
    [
      "                ",
      "                ",
      "                ",
      "abaZihZZZab     ",
      "0a1 h 234 5e    ",
      "mam h     5a    ",
      " a  h     6e    ",
      " a  h     7Z    ",
      "aaa8aaa    e    ",
      "CaD   9    e    ",
      " a    a    e    ",
      " a    a   7Z    ",
      " a    a    e    ",
      " a    a   #a    ",
      "W WWWWWW$WWe    ",
      "                "
    ],
    [
      "                ",
      "                ",
      "                ",
      "abaZihZZZab     ",
      "%a^ h &*( 5e    ",
      " a  h     5a    ",
      " a  h     6e    ",
      ")a+ h     -Z    ",
      "aaa[aaa    e    ",
      "CaD   e    e    ",
      " a    a    e    ",
      " a    a]  -Z    ",
      " a    a]   e    ",
      " a    a]   a    ",
      "W WWWWWW[WWe    ",
      "                "
    ],
    [
      "                ",
      "                ",
      "                ",
      "abaaaaaaaab     ",
      "{a{{a      e    ",
      "{a{{a      a    ",
      "{a{{a     }a    ",
      "{a{{a      a    ",
      "aaaaaaa    a    ",
      " a    a    a    ",
      " a    a    a    ",
      " a    a    a    ",
      " a    a    a    ",
      " a    a    a    ",
      "W WWWWWWWWWe    ",
      "                "
    ],
    [
      "                ",
      "                ",
      "                ",
      "|b||||||||b     ",
      "gaggggggggge    ",
      " a  ggggggg|    ",
      ";a; ggggggg|    ",
      " a  ggggggg|    ",
      "gaggggggggg|    ",
      "gaggggggggg|    ",
      "gaggggggggg|    ",
      "gaggggggggg|    ",
      "gaggggggggg|    ",
      "gaggggggggg|::::",
      "'''''''''''e<<<<",
      "<<<<<<<<<<<<<<<<"
    ]
  ]
}