{
  "name": "building_office5_floor1_180",
  "refpalette": "deceasedcraft:building_office5/building_office5_floor1_palette_180",
  "xsize": 16,
  "zsize": 16,
  "slices": [
    [
      "                ",
      " aabaabaabaabaa ",
      " acccccccccccca ",
      " bccccccccccccb ",
      " acccccccccccca ",
      " acccccccccccca ",
      " bccccccccccccb ",
      " acccccccccccca ",
      " acccccccccccca ",
      " bccccccccccccb ",
      " accccccccgf ca ",
      " acccccccced ca ",
      " bcccccccc   cb ",
      " acccccccccccca ",
      " aabaabaabaabaa ",
      "                "
    ],
    [
      "                ",
      " hhbhhbhhbhhbhh ",
      " h     u ttttth ",
      " b  t   xtBB!tb ",
      " h  w   xxxxBth ",
      " h Awy  xxxxBth ",
      " b  w   xxxxttb ",
      " h Awy  xxxxx h ",
      " h  w        uh ",
      " b  t    srbbbb ",
      " h       q po h ",
      " h    nbmb d  h ",
      " b    bl b    b ",
      " hkjkjbi b    h ",
      " hhbhhbhhbhhbhh ",
      "                "
    ],
    [
      "                ",
      " CCbCCbCCbCCbCC ",
      " C     T      C ",
      " b  S         b ",
      " C  R         C ",
      " C  Q         C ",
      " b  P         b ",
      " C            C ",
      " C  P        OC ",
      " b        Nbbbb ",
      " C       M  p C ",
      " C    LbKb dJ C ",
      " b    bI b    b ",
      " CFE Db  b    C ",
      " CCbCCbCCbCCbCC ",
      "                "
    ],
    [
      "                ",
      " CCbCCbCCbCCbCC ",
      " C            C ",
      " b            b ",
      " C            C ",
      " C            C ",
      " b            b ",
      " C            C ",
      " C            C ",
      " b        Zbbbb ",
      " C       Y    C ",
      " C    Xbbb dW C ",
      " b    bV b UJ b ",
      " C    b  b    C ",
      " CCbCCbCCbCCbCC ",
      "                "
    ],
    [
      "                ",
      " CCbCCbCCbCCbCC ",
      " C            C ",
      " b            b ",
      " C            C ",
      " C            C ",
      " b            b ",
      " C            C ",
      " C            C ",
      " b        3bbbb ",
      " C       2    C ",
      " C     bbb d  C ",
      " b    b  b10  b ",
      " C    b  b    C ",
      " CCbCCbCCbCCbCC ",
      "                "
    ],
    [
      "                ",
      " 44b44b44b44b44 ",
      " 45555555555554 ",
      " b566666666665b ",
      " 45666666666654 ",
      " 45668666686654 ",
      " b566666666665b ",
      " 45666666666654 ",
      " 45666666666654 ",
      " b566666666bb5b ",
      " 456676666   54 ",
      " 456666bbbgd 54 ",
      " b5666b  b0  5b ",
      " 45555555555554 ",
      " 44b44b44b44b44 ",
      "                "
    ]
  ]
}