{
  "name": "building_office5_ground_90",
  "refpalette": "deceasedcraft:building_office5/building_office5_ground_palette_90",
  "xsize": 16,
  "zsize": 16,
  "slices": [
    [
      "ccbaaaaaaaaaabcc",
      "ccc=aa=aa=aa=ccc",
      "bcccbaaaaaabcccb",
      "a=cccbaaaabccc=a",
      "aabcccbbbbcccbaa",
      "aaabccccccccbaaa",
      "a=aabccccccbaa=a",
      "aaaabcceeccbaaaa",
      "aaaabcceeccbaaaa",
      "a=cccccccccbaa=a",
      "abcdddccccccbaaa",
      "abcd!dcbbbcccbaa",
      "a=cdddcaaabccc=a",
      "abcccccaaaabcccb",
      "abb=bb=aa=aa=ccc",
      "aaaaaaaaaaaaabcc"
    ],
    [
      "                ",
      "   =gg=  =gg=   ",
      "     gggggg     ",
      " =     sw     = ",
      " g            g ",
      " gg          gg ",
      " =g    q     g= ",
      "  gj   ru   yg  ",
      "  gi   qr   xg  ",
      " =hhhn  q    g= ",
      " f    o      gg ",
      " f  kmh       g ",
      " =   lhpt     = ",
      " f    hgggg     ",
      " ff=ff=  =gg=   ",
      "                "
    ],
    [
      "                ",
      "   =  =  =  =   ",
      "                ",
      " =            = ",
      "                ",
      "                ",
      " =            = ",
      "       r        ",
      "                ",
      " =hhhB        = ",
      " f    C         ",
      " f  k h         ",
      " =  Amh       = ",
      " f    h         ",
      " ff=ff=  =  =   ",
      "                "
    ],
    [
      "                ",
      " DD=DD=DD=DD=DD ",
      " D            D ",
      " =            = ",
      " D            D ",
      " D            D ",
      " =            = ",
      " D            D ",
      " D            D ",
      " =hhhhI       = ",
      " D    h       D ",
      " D Ek h       D ",
      " = AF h       = ",
      " D    h       D ",
      " DD=DD=DD=DD=DD ",
      "                "
    ],
    [
      "                ",
      " JJ=JJ=JJ=JJ=JJ ",
      " JKKKKKKKKKKKKJ ",
      " =K          K= ",
      " JK          KJ ",
      " JK          KJ ",
      " =K          K= ",
      " JK          KJ ",
      " JK          KJ ",
      " =hhhhN      K= ",
      " JKM  h      KJ ",
      " JKLk h      KJ ",
      " =K   h      K= ",
      " JKKKKhKKKKKKKJ ",
      " JJ=JJ=JJ=JJ=JJ ",
      "                "
    ],
    [
      "                ",
      " OOOOOOOOOOOOOO ",
      " OPPPPPPPPPPPPO ",
      " OPQQQQQQQQQQPO ",
      " OPQQQQQQQQQQPO ",
      " OPQQQQQQQQQQPO ",
      " OPQQQQQQQQQQPO ",
      " OPQQQQQQQQQQPO ",
      " OPQQQQQQQQQQPO ",
      " OPhhhSQQQQQQPO ",
      " OPLR hQQQQQQPO ",
      " OP k hQQQQQQPO ",
      " OP   hQQQQQQPO ",
      " OPPPPPPPPPPPPO ",
      " OOOOOOOOOOOOOO ",
      "                "
    ]
  ]
}