{
  "name": "building_office5_floor2_90",
  "refpalette": "deceasedcraft:building_office5/building_office5_floor2_palette_90",
  "xsize": 16,
  "zsize": 16,
  "slices": [
    [
      "                ",
      " aabaabaabaabaa ",
      " acccccccccccca ",
      " bccccccccccccb ",
      " acccccccccccca ",
      " acccccccccccca ",
      " bccccccccccccb ",
      " acccccccccccca ",
      " acccccccccccca ",
      " bccccccccccccb ",
      " ac egcccccccca ",
      " ac dfcccccccca ",
      " bc   ccccccccb ",
      " acccccccccccca ",
      " aabaabaabaabaa ",
      "                "
    ],
    [
      "                ",
      " hhbhhbhhbhhbhh ",
      " hm     BEJJNRh ",
      " bl q     I   b ",
      " hk qw  C  L  h ",
      " hjoqu  ADFFMQh ",
      " bbbq w BEJJNPb ",
      " hinb     I   h ",
      " h  p      K  h ",
      " bbbbty ADFFMQb ",
      " h    x BEJJNPh ",
      " h  dsb   I   h ",
      " b   rb    K  b ",
      " h    b ADFFMOh ",
      " hhbhhbhhbhhbhh ",
      "                "
    ],
    [
      "                ",
      " SSbSSbSSbSSbSS ",
      " SV      9$^*VS ",
      " bU 2         b ",
      " S  1         S ",
      " ST 0    8#%8 S ",
      " bbbZ     $^9 b ",
      " S Wb         S ",
      " S  Y         S ",
      " bbbb3   7#%( b ",
      " S    4  6$^* S ",
      " S  d b       S ",
      " b  Xsb       b ",
      " S    b  5#%&VS ",
      " SSbSSbSSbSSbSS ",
      "                "
    ],
    [
      "                ",
      " SSbSSbSSbSSbSS ",
      " S)          )S ",
      " b  2         b ",
      " S            S ",
      " S            S ",
      " bbb          b ",
      " S -b         S ",
      " S  b         S ",
      " bbbb]        b ",
      " S    {       S ",
      " S +d b       S ",
      " b X[ b       b ",
      " S    b      )S ",
      " SSbSSbSSbSSbSS ",
      "                "
    ],
    [
      "                ",
      " SSbSSbSSbSSbSS ",
      " S            S ",
      " b  2         b ",
      " S            S ",
      " S            S ",
      " bbb          b ",
      " S  b         S ",
      " S  b         S ",
      " bbbb;        b ",
      " S |  :       S ",
      " S }d b       S ",
      " b    b       b ",
      " S    b       S ",
      " SSbSSbSSbSSbSS ",
      "                "
    ],
    [
      "                ",
      " ''b''b''b''b'' ",
      " '<<<<<<<<<<<<' ",
      " b<>>>>>>>>>><b ",
      " '<>>>>>>>>>><' ",
      " '<>>,>>>>,>><' ",
      " b<b>>>>>>>>><b ",
      " '<!b>>>>>>>><' ",
      " '< b>>>>>>>><' ",
      " b<bb>>>>>>>><b ",
      " '<}g >>>>.>><' ",
      " '< d b>>>>>><' ",
      " b<   b>>>>>><b ",
      " '<<<<<<<<<<<<' ",
      " ''b''b''b''b'' ",
      "                "
    ]
  ]
}