{
  "name": "building_office5_floor2",
  "refpalette": "deceasedcraft:building_office5/building_office5_floor2_palette",
  "xsize": 16,
  "zsize": 16,
  "slices": [
    [
      "                ",
      " aabaabaabaabaa ",
      " acccccccccccca ",
      " bc   ccccccccb ",
      " ac decccccccca ",
      " ac fgcccccccca ",
      " bccccccccccccb ",
      " acccccccccccca ",
      " acccccccccccca ",
      " bccccccccccccb ",
      " acccccccccccca ",
      " acccccccccccca ",
      " bccccccccccccb ",
      " acccccccccccca ",
      " aabaabaabaabaa ",
      "                "
    ],
    [
      "                ",
      " hhbhhbhhbhhbhh ",
      " h    b ibjklmh ",
      " b    b nbo   b ",
      " h  d bpbqqqq h ",
      " h rs t   uw  h ",
      " bbbbxy  w    b ",
      " h            h ",
      " hA  BA  BAC Bh ",
      " bD  ED  ED  Eb ",
      " hF IJF IJF IJh ",
      " hFK JFK JFL Jh ",
      " bM  NM  NM  Nb ",
      " hO  PQ  PQ  Rh ",
      " hhbhhbhhbhhbhh ",
      "                "
    ],
    [
      "                ",
      " SSbSSbSSbSSbSS ",
      " S    b  bT UVS ",
      " b    b Wb    b ",
      " S Xd bYbZ012 S ",
      " S s  3       S ",
      " bbbb4        b ",
      " S            S ",
      " S            S ",
      " b5  67   8  9b ",
      " S#  $#  $#  $S ",
      " S%  ^%  ^%  ^S ",
      " b&  *(  98  *b ",
      " SV          VS ",
      " SSbSSbSSbSSbSS ",
      "                "
    ],
    [
      "                ",
      " SSbSSbSSbSSbSS ",
      " S    b  b   )S ",
      " b X+ b -b    b ",
      " S [d bbb   2 S ",
      " S    ]       S ",
      " bbbb{        b ",
      " S            S ",
      " S            S ",
      " b            b ",
      " S            S ",
      " S            S ",
      " b            b ",
      " S)          )S ",
      " SSbSSbSSbSSbSS ",
      "                "
    ],
    [
      "                ",
      " SSbSSbSSbSSbSS ",
      " S    b  b    S ",
      " b  }|b  b    b ",
      " S  d bbb   2 S ",
      " S    ;       S ",
      " bbbb:        b ",
      " S            S ",
      " S            S ",
      " b            b ",
      " S            S ",
      " S            S ",
      " b            b ",
      " S            S ",
      " SSbSSbSSbSSbSS ",
      "                "
    ],
    [
      "                ",
      " ''b''b''b''b'' ",
      " '<<<<<<<<<<<<' ",
      " b<  }b !b>>><b ",
      " '< dgbbb>>>><' ",
      " '<   >>>>,>><' ",
      " b<bb>>>>>>>><b ",
      " '<>>>>>>>>>><' ",
      " '<>>>>>>>>>><' ",
      " b<>>>>>>>>>><b ",
      " '<>>.>>>>,>><' ",
      " '<>>>>>>>>>><' ",
      " b<>>>>>>>>>><b ",
      " '<<<<<<<<<<<<' ",
      " ''b''b''b''b'' ",
      "                "
    ]
  ]
}