{
  "name": "building_office5_floor3_270",
  "refpalette": "deceasedcraft:building_office5/building_office5_floor3_palette_270",
  "xsize": 16,
  "zsize": 16,
  "slices": [
    [
      "                ",
      " aabaabaabaabaa ",
      " acccccccccccca ",
      " bcccccccc   cb ",
      " accccccccfd ca ",
      " accccccccge ca ",
      " bccccccccccccb ",
      " acccccccccccca ",
      " acccccccccccca ",
      " bccccccccccccb ",
      " acccccccccccca ",
      " acccccccccccca ",
      " bccccccccccccb ",
      " acccccccccccca ",
      " aabaabaabaabaa ",
      "                "
    ],
    [
      "                ",
      " hhbhhbhhbhhbhh ",
      " hROJJEB b    h ",
      " b  M    br   b ",
      " h   K   bsd  h ",
      " hSPLLFC x    h ",
      " bTOJJEB ytbbbb ",
      " h  M      p  h ",
      " h   K     bnih ",
      " bSPLLFC  uqbbb ",
      " hTOJJEBA wqojh ",
      " h QN  D   q kh ",
      " b  MKI   uq lb ",
      " hUPLLFC     mh ",
      " hhbhhbhhbhhbhh ",
      "                "
    ],
    [
      "                ",
      " VVbVVbVVbVVbVV ",
      " VZ ^IA  b    V ",
      " b       bs1  b ",
      " V       b d  V ",
      " V *&%8  7    V ",
      " b (^I9   6bbbb ",
      " V         2  V ",
      " V         b0 V ",
      " b )&%#    3bbb ",
      " V + N     4 WV ",
      " V           XV ",
      " b         5 Yb ",
      " VZ*&%$      ZV ",
      " VVbVVbVVbVVbVV ",
      "                "
    ],
    [
      "                ",
      " VVbVVbVVbVVbVV ",
      " V-      b    V ",
      " b       b {1 b ",
      " V       b d[ V ",
      " V       |    V ",
      " b        }bbbb ",
      " V         b  V ",
      " V         b] V ",
      " b          bbb ",
      " V            V ",
      " V            V ",
      " b         5  b ",
      " V-          -V ",
      " VVbVVbVVbVVbVV ",
      "                "
    ],
    [
      "                ",
      " VVbVVbVVbVVbVV ",
      " V       b    V ",
      " b       b    b ",
      " V       b d; V ",
      " V       <  : V ",
      " b        'bbbb ",
      " V         b  V ",
      " V         b  V ",
      " b          bbb ",
      " V            V ",
      " V            V ",
      " b         5  b ",
      " V            V ",
      " VVbVVbVVbVVbVV ",
      "                "
    ],
    [
      "                ",
      " >>b>>b>>b>>b>> ",
      " >,,,,,,,,,,,,> ",
      " b,......b   ,b ",
      " >,......b d ,> ",
      " >,..?.... g;,> ",
      " b,........bb,b ",
      " >,........b ,> ",
      " >,........b ,> ",
      " b,.........b,b ",
      " >,..!....?..,> ",
      " >,..........,> ",
      " b,..........,b ",
      " >,,,,,,,,,,,,> ",
      " >>b>>b>>b>>b>> ",
      "                "
    ]
  ]
}