{
  "name": "building_office5_floor1_270",
  "refpalette": "deceasedcraft:building_office5/building_office5_floor1_palette_270",
  "xsize": 16,
  "zsize": 16,
  "slices": [
    [
      "                ",
      " aabaabaabaabaa ",
      " acccccccccccca ",
      " bcccccccc   cb ",
      " accccccccfd ca ",
      " accccccccge ca ",
      " bccccccccccccb ",
      " acccccccccccca ",
      " acccccccccccca ",
      " bccccccccccccb ",
      " acccccccccccca ",
      " acccccccccccca ",
      " bccccccccccccb ",
      " acccccccccccca ",
      " aabaabaabaabaa ",
      "                "
    ],
    [
      "                ",
      " hhbhhbhhbhhbhh ",
      " httttt ub    h ",
      " bt!BBtx bo   b ",
      " htBxxxx bpd  h ",
      " htBxxxx r    h ",
      " bttxxxx sqbbbb ",
      " h xxxxx   m  h ",
      " hu        blih ",
      " b         nbbb ",
      " h   y y     jh ",
      " h twwwwwt   kh ",
      " b   A A     jb ",
      " h           kh ",
      " hhbhhbhhbhhbhh ",
      "                "
    ],
    [
      "                ",
      " CCbCCbCCbCCbCC ",
      " C      Ob    C ",
      " b       bpJ  b ",
      " C       b d  C ",
      " C       N    C ",
      " b        Mbbbb ",
      " C         K  C ",
      " CT        bI C ",
      " b         Lbbb ",
      " C           DC ",
      " C SRQP P     C ",
      " b           Eb ",
      " C           FC ",
      " CCbCCbCCbCCbCC ",
      "                "
    ],
    [
      "                ",
      " CCbCCbCCbCCbCC ",
      " C       b    C ",
      " b       b WJ b ",
      " C       b dU C ",
      " C       Z    C ",
      " b        Ybbbb ",
      " C         b  C ",
      " C         bV C ",
      " b         Xbbb ",
      " C            C ",
      " C            C ",
      " b            b ",
      " C            C ",
      " CCbCCbCCbCCbCC ",
      "                "
    ],
    [
      "                ",
      " CCbCCbCCbCCbCC ",
      " C       b    C ",
      " b       b    b ",
      " C       b d0 C ",
      " C       3  1 C ",
      " b        2bbbb ",
      " C         b  C ",
      " C         b  C ",
      " b          bbb ",
      " C            C ",
      " C            C ",
      " b            b ",
      " C            C ",
      " CCbCCbCCbCCbCC ",
      "                "
    ],
    [
      "                ",
      " 44b44b44b44b44 ",
      " 45555555555554 ",
      " b5666666b   5b ",
      " 45666666b d 54 ",
      " 456686666 g054 ",
      " b566666666bb5b ",
      " 4566666666b 54 ",
      " 4566666666b 54 ",
      " b5666666666b5b ",
      " 45668666676654 ",
      " 45666666666654 ",
      " b566666666665b ",
      " 45555555555554 ",
      " 44b44b44b44b44 ",
      "                "
    ]
  ]
}