{
  "name": "building_office5_floor1_90",
  "refpalette": "deceasedcraft:building_office5/building_office5_floor1_palette_90",
  "xsize": 16,
  "zsize": 16,
  "slices": [
    [
      "                ",
      " aabaabaabaabaa ",
      " acccccccccccca ",
      " bccccccccccccb ",
      " acccccccccccca ",
      " acccccccccccca ",
      " bccccccccccccb ",
      " acccccccccccca ",
      " acccccccccccca ",
      " bccccccccccccb ",
      " ac egcccccccca ",
      " ac dfcccccccca ",
      " bc   ccccccccb ",
      " acccccccccccca ",
      " aabaabaabaabaa ",
      "                "
    ],
    [
      "                ",
      " hhbhhbhhbhhbhh ",
      " hk           h ",
      " bj     A A   b ",
      " hk   twwwwwt h ",
      " hj     y y   h ",
      " bbbn         b ",
      " hilb        uh ",
      " h  m   xxxxx h ",
      " bbbbqs xxxxttb ",
      " h    r xxxxBth ",
      " h  dpb xxxxBth ",
      " b   ob xtBB!tb ",
      " h    bu ttttth ",
      " hhbhhbhhbhhbhh ",
      "                "
    ],
    [
      "                ",
      " CCbCCbCCbCCbCC ",
      " CF           C ",
      " bE           b ",
      " C     P PQRS C ",
      " CD           C ",
      " bbbL         b ",
      " C Ib        TC ",
      " C  K         C ",
      " bbbbM        b ",
      " C    N       C ",
      " C  d b       C ",
      " b  Jpb       b ",
      " C    bO      C ",
      " CCbCCbCCbCCbCC ",
      "                "
    ],
    [
      "                ",
      " CCbCCbCCbCCbCC ",
      " C            C ",
      " b            b ",
      " C            C ",
      " C            C ",
      " bbbX         b ",
      " C Vb         C ",
      " C  b         C ",
      " bbbbY        b ",
      " C    Z       C ",
      " C Ud b       C ",
      " b JW b       b ",
      " C    b       C ",
      " CCbCCbCCbCCbCC ",
      "                "
    ],
    [
      "                ",
      " CCbCCbCCbCCbCC ",
      " C            C ",
      " b            b ",
      " C            C ",
      " C            C ",
      " bbb          b ",
      " C  b         C ",
      " C  b         C ",
      " bbbb2        b ",
      " C 1  3       C ",
      " C 0d b       C ",
      " b    b       b ",
      " C    b       C ",
      " CCbCCbCCbCCbCC ",
      "                "
    ],
    [
      "                ",
      " 44b44b44b44b44 ",
      " 45555555555554 ",
      " b566666666665b ",
      " 45666666666654 ",
      " 45667666686654 ",
      " b5b6666666665b ",
      " 45 b6666666654 ",
      " 45 b6666666654 ",
      " b5bb666666665b ",
      " 450g 666686654 ",
      " 45 d b66666654 ",
      " b5   b6666665b ",
      " 45555555555554 ",
      " 44b44b44b44b44 ",
      "                "
    ]
  ]
}