{
  "name": "building_office5_top_180",
  "refpalette": "deceasedcraft:building_office5/building_office5_top_palette_180",
  "xsize": 16,
  "zsize": 16,
  "slices": [
    [
      "                ",
      " aabaabaabaabaa ",
      " acccccccccccca ",
      " bccccccccccccb ",
      " acccccccccccca ",
      " acccccccccccca ",
      " bccccccccccccb ",
      " acccccccccccca ",
      " acccccccccccca ",
      " bccccccccccccb ",
      " accccccccg  ca ",
      " accccccfced ca ",
      " bcccccccc   cb ",
      " acccccccccccca ",
      " aabaabaabaabaa ",
      "                "
    ],
    [
      "                ",
      " hhbhhbhhbhhbhh ",
      " hiiiiiiiiiiiih ",
      " bi          ib ",
      " hi   m   m  ih ",
      " hi   f   f  ih ",
      " bi fffffff  ib ",
      " hi f        ih ",
      " hi f        ih ",
      " bi f     liiib ",
      " hi j!   k   ih ",
      " hi jjfffi d ih ",
      " bi      i   ib ",
      " hiiiiiiiiiiiih ",
      " hhbhhbhhbhhbhh ",
      "                "
    ],
    [
      "                ",
      " nnbnnbnnbnnbnn ",
      " noooooooooooon ",
      " bo          ob ",
      " no          on ",
      " no          on ",
      " bo          ob ",
      " no          on ",
      " no          on ",
      " bo       tiiib ",
      " no qq   s r in ",
      " no qq   ipd in ",
      " bo      i   ib ",
      " noooooooiiiiin ",
      " nnbnnbnnbnnbnn ",
      "                "
    ],
    [
      "                ",
      "                ",
      "                ",
      "                ",
      "                ",
      "                ",
      "                ",
      "                ",
      "                ",
      "          uuuu  ",
      "         uuuuu  ",
      "    w    uuuuu  ",
      "         uuuuu  ",
      "         uuuuu  ",
      "                ",
      "                "
    ],
    [
      "                ",
      "                ",
      "                ",
      "                ",
      "                ",
      "                ",
      "                ",
      "                ",
      "                ",
      "                ",
      "                ",
      "    x           ",
      "                ",
      "                ",
      "                ",
      "                "
    ],
    [
      "                ",
      "                ",
      "                ",
      "                ",
      "                ",
      "                ",
      "                ",
      "                ",
      "                ",
      "                ",
      "                ",
      "    y           ",
      "                ",
      "                ",
      "                ",
      "                "
    ]
  ]
}