{
  "name": "building_office5_ground",
  "refpalette": "deceasedcraft:building_office5/building_office5_ground_palette",
  "xsize": 16,
  "zsize": 16,
  "slices": [
    [
      "aaaaaaaaaaaaabcc",
      "abb=bb=aa=aa=ccc",
      "abcccccaaaabcccb",
      "a=cdddcaaabccc=a",
      "abcd!dcbbbcccbaa",
      "abcdddccccccbaaa",
      "a=cccccccccbaa=a",
      "aaaabcceeccbaaaa",
      "aaaabcceeccbaaaa",
      "a=aabccccccbaa=a",
      "aaabccccccccbaaa",
      "aabcccbbbbcccbaa",
      "a=cccbaaaabccc=a",
      "bcccbaaaaaabcccb",
      "ccc=aa=aa=aa=ccc",
      "ccbaaaaaaaaaabcc"
    ],
    [
      "                ",
      " ff=ff=  =gg=   ",
      " f    hgggg     ",
      " =    hij     = ",
      " f  k h       g ",
      " f lm n      gg ",
      " =hhho       g= ",
      "  gp   qrq  sg  ",
      "  gt  qru   wg  ",
      " =g          g= ",
      " gg          gg ",
      " g            g ",
      " =     xy     = ",
      "     gggggg     ",
      "   =gg=  =gg=   ",
      "                "
    ],
    [
      "                ",
      " ff=ff=  =  =   ",
      " f    h         ",
      " =    h       = ",
      " f Ak h         ",
      " f m  B         ",
      " =hhhC        = ",
      "        r       ",
      "                ",
      " =            = ",
      "                ",
      "                ",
      " =            = ",
      "                ",
      "   =  =  =  =   ",
      "                "
    ],
    [
      "                ",
      " DD=DD=DD=DD=DD ",
      " D    h       D ",
      " = AE h       = ",
      " D Fk h       D ",
      " D    h       D ",
      " =hhhhI       = ",
      " D            D ",
      " D            D ",
      " =            = ",
      " D            D ",
      " D            D ",
      " =            = ",
      " D            D ",
      " DD=DD=DD=DD=DD ",
      "                "
    ],
    [
      "                ",
      " JJ=JJ=JJ=JJ=JJ ",
      " JKKKKhKKKKKKKJ ",
      " =K LMh      K= ",
      " JK k h      KJ ",
      " JK   h      KJ ",
      " =hhhhN      K= ",
      " JK          KJ ",
      " JK          KJ ",
      " =K          K= ",
      " JK          KJ ",
      " JK          KJ ",
      " =K          K= ",
      " JKKKKKKKKKKKKJ ",
      " JJ=JJ=JJ=JJ=JJ ",
      "                "
    ],
    [
      "                ",
      " OOOOOOOOOOOOOO ",
      " OPPPPPPPPPPPPO ",
      " OP  LhQQQQQQPO ",
      " OP kRhQQQQQQPO ",
      " OP   hQQQQQQPO ",
      " OPhhhSQQQQQQPO ",
      " OPQQQQQQQQQQPO ",
      " OPQQQQQQQQQQPO ",
      " OPQQQQQQQQQQPO ",
      " OPQQQQQQQQQQPO ",
      " OPQQQQQQQQQQPO ",
      " OPQQQQQQQQQQPO ",
      " OPPPPPPPPPPPPO ",
      " OOOOOOOOOOOOOO ",
      "                "
    ]
  ]
}