{
  "name": "building_office5_ground_180",
  "refpalette": "deceasedcraft:building_office5/building_office5_ground_palette_180",
  "xsize": 16,
  "zsize": 16,
  "slices": [
    [
      "ccbaaaaaaaaaabcc",
      "ccc=aa=aa=aa=ccc",
      "bcccbaaaaaabcccb",
      "a=cccbaaaabccc=a",
      "aabcccbbbbcccbaa",
      "aaabccccccccbaaa",
      "a=aabccccccbaa=a",
      "aaaabcceeccbaaaa",
      "aaaabcceeccbaaaa",
      "a=aabccccccccc=a",
      "aaabccccccdddcba",
      "aabcccbbbcd!dcba",
      "a=cccbaaacdddc=a",
      "bcccbaaaacccccba",
      "ccc=aa=aa=bb=bba",
      "ccbaaaaaaaaaaaaa"
    ],
    [
      "                ",
      "   =gg=  =gg=   ",
      "     gggggg     ",
      " =     yx     = ",
      " g            g ",
      " gg          gg ",
      " =g          g= ",
      "  gw   urq  tg  ",
      "  gs  qrq   pg  ",
      " =g       ohhh= ",
      " gg      n ml f ",
      " g       h k  f ",
      " =     jih    = ",
      "     ggggh    f ",
      "   =gg=  =ff=ff ",
      "                "
    ],
    [
      "                ",
      "   =  =  =  =   ",
      "                ",
      " =            = ",
      "                ",
      "                ",
      " =            = ",
      "                ",
      "       r        ",
      " =        Chhh= ",
      "         B  m f ",
      "         h kA f ",
      " =       h    = ",
      "         h    f ",
      "   =  =  =ff=ff ",
      "                "
    ],
    [
      "                ",
      " DD=DD=DD=DD=DD ",
      " D            D ",
      " =            = ",
      " D            D ",
      " D            D ",
      " =            = ",
      " D            D ",
      " D            D ",
      " =       Ihhhh= ",
      " D       h    D ",
      " D       h kF D ",
      " =       h EA = ",
      " D       h    D ",
      " DD=DD=DD=DD=DD ",
      "                "
    ],
    [
      "                ",
      " JJ=JJ=JJ=JJ=JJ ",
      " JKKKKKKKKKKKKJ ",
      " =K          K= ",
      " JK          KJ ",
      " JK          KJ ",
      " =K          K= ",
      " JK          KJ ",
      " JK          KJ ",
      " =K      Nhhhh= ",
      " JK      h   KJ ",
      " JK      h k KJ ",
      " =K      hML K= ",
      " JKKKKKKKhKKKKJ ",
      " JJ=JJ=JJ=JJ=JJ ",
      "                "
    ],
    [
      "                ",
      " OOOOOOOOOOOOOO ",
      " OPPPPPPPPPPPPO ",
      " OPQQQQQQQQQQPO ",
      " OPQQQQQQQQQQPO ",
      " OPQQQQQQQQQQPO ",
      " OPQQQQQQQQQQPO ",
      " OPQQQQQQQQQQPO ",
      " OPQQQQQQQQQQPO ",
      " OPQQQQQQShhhPO ",
      " OPQQQQQQh   PO ",
      " OPQQQQQQhRk PO ",
      " OPQQQQQQhL  PO ",
      " OPPPPPPPPPPPPO ",
      " OOOOOOOOOOOOOO ",
      "                "
    ]
  ]
}