{
  "name": "building_office5_top_90",
  "refpalette": "deceasedcraft:building_office5/building_office5_top_palette_90",
  "xsize": 16,
  "zsize": 16,
  "slices": [
    [
      "                ",
      " aabaabaabaabaa ",
      " acccccccccccca ",
      " bccccccccccccb ",
      " acccccccccccca ",
      " acccccccccccca ",
      " bccccccccccccb ",
      " acccccccccccca ",
      " accfccccccccca ",
      " bccccccccccccb ",
      " ac egcccccccca ",
      " ac d cccccccca ",
      " bc   ccccccccb ",
      " acccccccccccca ",
      " aabaabaabaabaa ",
      "                "
    ],
    [
      "                ",
      " hhbhhbhhbhhbhh ",
      " hiiiiiiiiiiiih ",
      " bi          ib ",
      " hi jjffff   ih ",
      " hi j!   f   ih ",
      " bi f    ffm ib ",
      " hi f    f   ih ",
      " hi f    f   ih ",
      " biiik   f   ib ",
      " hi   l  ffm ih ",
      " hi d i      ih ",
      " bi   i      ib ",
      " hiiiiiiiiiiiih ",
      " hhbhhbhhbhhbhh ",
      "                "
    ],
    [
      "                ",
      " nnbnnbnnbnnbnn ",
      " noooooooooooon ",
      " bo          ob ",
      " no qq       on ",
      " no qq       on ",
      " bo          ob ",
      " no          on ",
      " no          on ",
      " biiis       ob ",
      " ni p t      on ",
      " ni dri      on ",
      " bi   i      ob ",
      " niiiiiooooooon ",
      " nnbnnbnnbnnbnn ",
      "                "
    ],
    [
      "                ",
      "                ",
      "                ",
      "                ",
      "    w           ",
      "                ",
      "                ",
      "                ",
      "                ",
      "  uuuu          ",
      "  uuuuu         ",
      "  uuuuu         ",
      "  uuuuu         ",
      "  uuuuu         ",
      "                ",
      "                "
    ],
    [
      "                ",
      "                ",
      "                ",
      "                ",
      "    x           ",
      "                ",
      "                ",
      "                ",
      "                ",
      "                ",
      "                ",
      "                ",
      "                ",
      "                ",
      "                ",
      "                "
    ],
    [
      "                ",
      "                ",
      "                ",
      "                ",
      "    y           ",
      "                ",
      "                ",
      "                ",
      "                ",
      "                ",
      "                ",
      "                ",
      "                ",
      "                ",
      "                ",
      "                "
    ]
  ]
}