{
  "name": "building_office5_floor1",
  "refpalette": "deceasedcraft:building_office5/building_office5_floor1_palette",
  "xsize": 16,
  "zsize": 16,
  "slices": [
    [
      "                ",
      " aabaabaabaabaa ",
      " acccccccccccca ",
      " bc   ccccccccb ",
      " ac decccccccca ",
      " ac fgcccccccca ",
      " bccccccccccccb ",
      " acccccccccccca ",
      " acccccccccccca ",
      " bccccccccccccb ",
      " acccccccccccca ",
      " acccccccccccca ",
      " bccccccccccccb ",
      " acccccccccccca ",
      " aabaabaabaabaa ",
      "                "
    ],
    [
      "                ",
      " hhbhhbhhbhhbhh ",
      " h    b ibjkjkh ",
      " b    b lb    b ",
      " h  d bmbn    h ",
      " h op q       h ",
      " bbbbrs    t  b ",
      " hu        w  h ",
      " h xxxxx  ywA h ",
      " bttxxxx   w  b ",
      " htBxxxx  ywA h ",
      " htBxxxx   w  h ",
      " bt!BBtx   t  b ",
      " httttt u     h ",
      " hhbhhbhhbhhbhh ",
      "                "
    ],
    [
      "                ",
      " CCbCCbCCbCCbCC ",
      " C    b  bD EFC ",
      " b    b Ib    b ",
      " C Jd bKbL    C ",
      " C p  M       C ",
      " bbbbN        b ",
      " CO        P  C ",
      " C            C ",
      " b         P  b ",
      " C         Q  C ",
      " C         R  C ",
      " b         S  b ",
      " C      T     C ",
      " CCbCCbCCbCCbCC ",
      "                "
    ],
    [
      "                ",
      " CCbCCbCCbCCbCC ",
      " C    b  b    C ",
      " b JU b Vb    b ",
      " C Wd bbbX    C ",
      " C    Y       C ",
      " bbbbZ        b ",
      " C            C ",
      " C            C ",
      " b            b ",
      " C            C ",
      " C            C ",
      " b            b ",
      " C            C ",
      " CCbCCbCCbCCbCC ",
      "                "
    ],
    [
      "                ",
      " CCbCCbCCbCCbCC ",
      " C    b  b    C ",
      " b  01b  b    b ",
      " C  d bbb     C ",
      " C    2       C ",
      " bbbb3        b ",
      " C            C ",
      " C            C ",
      " b            b ",
      " C            C ",
      " C            C ",
      " b            b ",
      " C            C ",
      " CCbCCbCCbCCbCC ",
      "                "
    ],
    [
      "                ",
      " 44b44b44b44b44 ",
      " 45555555555554 ",
      " b5  0b  b6665b ",
      " 45 dgbbb666654 ",
      " 45   666676654 ",
      " b5bb666666665b ",
      " 45666666666654 ",
      " 45666666666654 ",
      " b566666666665b ",
      " 45668666686654 ",
      " 45666666666654 ",
      " b566666666665b ",
      " 45555555555554 ",
      " 44b44b44b44b44 ",
      "                "
    ]
  ]
}