{
  "name": "building_office5_floor4_180",
  "refpalette": "deceasedcraft:building_office5/building_office5_floor4_palette_180",
  "xsize": 16,
  "zsize": 16,
  "slices": [
    [
      "                ",
      " aabaabaabaabaa ",
      " acccccccccccca ",
      " bccccccccccccb ",
      " acccccccccccca ",
      " acccccccccccca ",
      " bccccccccccccb ",
      " acccccccccccca ",
      " acccccccccccca ",
      " bccccccccccccb ",
      " accccccccgf ca ",
      " acccccccced ca ",
      " bcccccccc   cb ",
      " acccccccccccca ",
      " aabaabaabaabaa ",
      "                "
    ],
    [
      "                ",
      " hhbhhbhhbhhbhh ",
      " hJ          Ih ",
      " b   F F F F  b ",
      " h  AAAAAAAAA h ",
      " h EABDCCC!BA h ",
      " b  AAAAAAAAA b ",
      " h   y y y y  h ",
      " h            h ",
      " b       xwbbbb ",
      " hputut  s rq h ",
      " h   pobnb d  h ",
      " b    bm b    b ",
      " h lkjbi b    h ",
      " hhbhhbhhbhhbhh ",
      "                "
    ],
    [
      "                ",
      " KKbKKbKKbKKbKK ",
      " KW          WK ",
      " b            b ",
      " K      T T   K ",
      " K   VVVVVVU  K ",
      " b    T   T   b ",
      " K            K ",
      " K            K ",
      " b        Sbbbb ",
      " KPRRRR  Q  r K ",
      " K   PObNb dM K ",
      " b    bL b    b ",
      " K    b  b    K ",
      " KKbKKbKKbKKbKK ",
      "                "
    ],
    [
      "                ",
      " KKbKKbKKbKKbKK ",
      " K3          3K ",
      " b            b ",
      " K            K ",
      " K            K ",
      " b            b ",
      " K            K ",
      " K            K ",
      " b        2bbbb ",
      " KPRRRR  1    K ",
      " K   P0bbb dZ K ",
      " b    bY b XM b ",
      " K    b  b    K ",
      " KKbKKbKKbKKbKK ",
      "                "
    ],
    [
      "                ",
      " KKbKKbKKbKKbKK ",
      " K            K ",
      " b            b ",
      " K            K ",
      " K            K ",
      " b            b ",
      " K            K ",
      " K            K ",
      " b        9bbbb ",
      " K7RRRR  8    K ",
      " K   76bbb d  K ",
      " b    b  b54  b ",
      " K    b  b    K ",
      " KKbKKbKKbKKbKK ",
      "                "
    ],
    [
      "                ",
      " ##b##b##b##b## ",
      " #$$$$$$$$$$$$# ",
      " b$%%%%%%%%%%$b ",
      " #$%%%%%%%%%%$# ",
      " #$%%&%%%%^%%$# ",
      " b$%%%%%%%%%%$b ",
      " #$%%%%%%%%%%$# ",
      " #$%%%%%%%%%%$# ",
      " b$%%%%%%%%bb$b ",
      " #$%%%%%%%   $# ",
      " #$%%%%bbbgd $# ",
      " b$%%%b  b4  $b ",
      " #$$$$$$$$$$$$# ",
      " ##b##b##b##b## ",
      "                "
    ]
  ]
}