{
  "name": "building_office5_floor3_180",
  "refpalette": "deceasedcraft:building_office5/building_office5_floor3_palette_180",
  "xsize": 16,
  "zsize": 16,
  "slices": [
    [
      "                ",
      " aabaabaabaabaa ",
      " acccccccccccca ",
      " bccccccccccccb ",
      " acccccccccccca ",
      " acccccccccccca ",
      " bccccccccccccb ",
      " acccccccccccca ",
      " acccccccccccca ",
      " bccccccccccccb ",
      " accccccccgf ca ",
      " acccccccced ca ",
      " bcccccccc   cb ",
      " acccccccccccca ",
      " aabaabaabaabaa ",
      "                "
    ],
    [
      "                ",
      " hhbhhbhhbhhbhh ",
      " hU  TS  TS  Rh ",
      " bP QOP  OP  Ob ",
      " hLMNJL MJL MJh ",
      " hLK JLK JLK Jh ",
      " bFI EF  EF  Eb ",
      " hC DBC  BC  Bh ",
      " h   A        h ",
      " b       yxbbbb ",
      " h u wu  t sr h ",
      " h qqqqbpb d  h ",
      " b   obn b    b ",
      " hmlkjbi b    h ",
      " hhbhhbhhbhhbhh ",
      "                "
    ],
    [
      "                ",
      " VVbVVbVVbVVbVV ",
      " VZ          ZV ",
      " b*  +)  (*   b ",
      " V&   &  ^&  ^V ",
      " V%  N%  I%  IV ",
      " b$   #  98  Ab ",
      " V            V ",
      " V            V ",
      " b        7bbbb ",
      " V       6  s V ",
      " V 5 43b2b d1 V ",
      " b    b0 b    b ",
      " VZYXWb  b    V ",
      " VVbVVbVVbVVbVV ",
      "                "
    ],
    [
      "                ",
      " VVbVVbVVbVVbVV ",
      " V-          -V ",
      " b            b ",
      " V            V ",
      " V            V ",
      " b            b ",
      " V            V ",
      " V            V ",
      " b        |bbbb ",
      " V       }    V ",
      " V 5   bbb d{ V ",
      " b    b] b [1 b ",
      " V-   b  b    V ",
      " VVbVVbVVbVVbVV ",
      "                "
    ],
    [
      "                ",
      " VVbVVbVVbVVbVV ",
      " V            V ",
      " b            b ",
      " V            V ",
      " V            V ",
      " b            b ",
      " V            V ",
      " V            V ",
      " b        <bbbb ",
      " V       '    V ",
      " V 5   bbb d  V ",
      " b    b  b:;  b ",
      " V    b  b    V ",
      " VVbVVbVVbVVbVV ",
      "                "
    ],
    [
      "                ",
      " >>b>>b>>b>>b>> ",
      " >,,,,,,,,,,,,> ",
      " b,..........,b ",
      " >,..........,> ",
      " >,..!....?..,> ",
      " b,..........,b ",
      " >,..........,> ",
      " >,..........,> ",
      " b,........bb,b ",
      " >,..?....   ,> ",
      " >,....bbbgd ,> ",
      " b,...b  b;  ,b ",
      " >,,,,,,,,,,,,> ",
      " >>b>>b>>b>>b>> ",
      "                "
    ]
  ]
}