{
  "name": "building_office5_floor4_90",
  "refpalette": "deceasedcraft:building_office5/building_office5_floor4_palette_90",
  "xsize": 16,
  "zsize": 16,
  "slices": [
    [
      "                ",
      " aabaabaabaabaa ",
      " acccccccccccca ",
      " bccccccccccccb ",
      " acccccccccccca ",
      " acccccccccccca ",
      " bccccccccccccb ",
      " acccccccccccca ",
      " acccccccccccca ",
      " bccccccccccccb ",
      " ac egcccccccca ",
      " ac dfcccccccca ",
      " bc   ccccccccb ",
      " acccccccccccca ",
      " aabaabaabaabaa ",
      "                "
    ],
    [
      "                ",
      " hhbhhbhhbhhbhh ",
      " h   p       Jh ",
      " bl  u    E   b ",
      " hk  t   AAA  h ",
      " hj pu  yABAF h ",
      " bbbot   ADA  b ",
      " himb   yACAF h ",
      " h  n    ACA  h ",
      " bbbbsx yACAF b ",
      " h    w  A!A  h ",
      " h  drb yABAF h ",
      " b   qb  AAA  b ",
      " h    b      Ih ",
      " hhbhhbhhbhhbhh ",
      "                "
    ],
    [
      "                ",
      " KKbKKbKKbKKbKK ",
      " K   P       WK ",
      " b   R        b ",
      " K   R        K ",
      " K  PR    V   K ",
      " bbbOR   TV   b ",
      " K Lb     V   K ",
      " K  N     VT  K ",
      " bbbbQ    V   b ",
      " K    S  TVT  K ",
      " K  d b   U   K ",
      " b  Mrb       b ",
      " K    b      WK ",
      " KKbKKbKKbKKbKK ",
      "                "
    ],
    [
      "                ",
      " KKbKKbKKbKKbKK ",
      " K   P       3K ",
      " b   R        b ",
      " K   R        K ",
      " K  PR        K ",
      " bbb0R        b ",
      " K Yb         K ",
      " K  b         K ",
      " bbbb1        b ",
      " K    2       K ",
      " K Xd b       K ",
      " b MZ b       b ",
      " K    b      3K ",
      " KKbKKbKKbKKbKK ",
      "                "
    ],
    [
      "                ",
      " KKbKKbKKbKKbKK ",
      " K   7        K ",
      " b   R        b ",
      " K   R        K ",
      " K  7R        K ",
      " bbb6R        b ",
      " K  b         K ",
      " K  b         K ",
      " bbbb8        b ",
      " K 5  9       K ",
      " K 4d b       K ",
      " b    b       b ",
      " K    b       K ",
      " KKbKKbKKbKKbKK ",
      "                "
    ],
    [
      "                ",
      " ##b##b##b##b## ",
      " #$$$$$$$$$$$$# ",
      " b$%%%%%%%%%%$b ",
      " #$%%%%%%%%%%$# ",
      " #$%%%%%%%&%%$# ",
      " b$b%%%%%%%%%$b ",
      " #$ b%%%%%%%%$# ",
      " #$ b%%%%%%%%$# ",
      " b$bb%%%%%%%%$b ",
      " #$4g %%%%^%%$# ",
      " #$ d b%%%%%%$# ",
      " b$   b%%%%%%$b ",
      " #$$$$$$$$$$$$# ",
      " ##b##b##b##b## ",
      "                "
    ]
  ]
}