{
  "name": "building_office5_top",
  "refpalette": "deceasedcraft:building_office5/building_office5_top_palette",
  "xsize": 16,
  "zsize": 16,
  "slices": [
    [
      "                ",
      " aabaabaabaabaa ",
      " acccccccccccca ",
      " bc   ccccccccb ",
      " ac decfcccccca ",
      " ac  gcccccccca ",
      " bccccccccccccb ",
      " acccccccccccca ",
      " acccccccccccca ",
      " bccccccccccccb ",
      " acccccccccccca ",
      " acccccccccccca ",
      " bccccccccccccb ",
      " acccccccccccca ",
      " aabaabaabaabaa ",
      "                "
    ],
    [
      "                ",
      " hhbhhbhhbhhbhh ",
      " hiiiiiiiiiiiih ",
      " bi   i      ib ",
      " hi d ifffjj ih ",
      " hi   k   !j ih ",
      " biiil     f ib ",
      " hi        f ih ",
      " hi        f ih ",
      " bi  fffffff ib ",
      " hi  f   f   ih ",
      " hi  m   m   ih ",
      " bi          ib ",
      " hiiiiiiiiiiiih ",
      " hhbhhbhhbhhbhh ",
      "                "
    ],
    [
      "                ",
      " nnbnnbnnbnnbnn ",
      " niiiiiooooooon ",
      " bi   i      ob ",
      " ni dpi   qq on ",
      " ni r s   qq on ",
      " biiit       ob ",
      " no          on ",
      " no          on ",
      " bo          ob ",
      " no          on ",
      " no          on ",
      " bo          ob ",
      " noooooooooooon ",
      " nnbnnbnnbnnbnn ",
      "                "
    ],
    [
      "                ",
      "                ",
      "  uuuuu         ",
      "  uuuuu         ",
      "  uuuuu    w    ",
      "  uuuuu         ",
      "  uuuu          ",
      "                ",
      "                ",
      "                ",
      "                ",
      "                ",
      "                ",
      "                ",
      "                ",
      "                "
    ],
    [
      "                ",
      "                ",
      "                ",
      "                ",
      "           x    ",
      "                ",
      "                ",
      "                ",
      "                ",
      "                ",
      "                ",
      "                ",
      "                ",
      "                ",
      "                ",
      "                "
    ],
    [
      "                ",
      "                ",
      "                ",
      "                ",
      "           y    ",
      "                ",
      "                ",
      "                ",
      "                ",
      "                ",
      "                ",
      "                ",
      "                ",
      "                ",
      "                ",
      "                "
    ]
  ]
}