{
  "name": "building_office5_floor4",
  "refpalette": "deceasedcraft:building_office5/building_office5_floor4_palette",
  "xsize": 16,
  "zsize": 16,
  "slices": [
    [
      "                ",
      " aabaabaabaabaa ",
      " acccccccccccca ",
      " bc   ccccccccb ",
      " ac decccccccca ",
      " ac fgcccccccca ",
      " bccccccccccccb ",
      " acccccccccccca ",
      " acccccccccccca ",
      " bccccccccccccb ",
      " acccccccccccca ",
      " acccccccccccca ",
      " bccccccccccccb ",
      " acccccccccccca ",
      " aabaabaabaabaa ",
      "                "
    ],
    [
      "                ",
      " hhbhhbhhbhhbhh ",
      " h    b ibjkl h ",
      " b    b mb    b ",
      " h  d bnbop   h ",
      " h qr s  tutuph ",
      " bbbbwx       b ",
      " h            h ",
      " h  y y y y   h ",
      " b AAAAAAAAA  b ",
      " h AB!CCCDBAE h ",
      " h AAAAAAAAA  h ",
      " b  F F F F   b ",
      " hI          Jh ",
      " hhbhhbhhbhhbhh ",
      "                "
    ],
    [
      "                ",
      " KKbKKbKKbKKbKK ",
      " K    b  b    K ",
      " b    b Lb    b ",
      " K Md bNbOP   K ",
      " K r  Q  RRRRPK ",
      " bbbbS        b ",
      " K            K ",
      " K            K ",
      " b   T   T    b ",
      " K  UVVVVVV   K ",
      " K   T T      K ",
      " b            b ",
      " KW          WK ",
      " KKbKKbKKbKKbKK ",
      "                "
    ],
    [
      "                ",
      " KKbKKbKKbKKbKK ",
      " K    b  b    K ",
      " b MX b Yb    b ",
      " K Zd bbb0P   K ",
      " K    1  RRRRPK ",
      " bbbb2        b ",
      " K            K ",
      " K            K ",
      " b            b ",
      " K            K ",
      " K            K ",
      " b            b ",
      " K3          3K ",
      " KKbKKbKKbKKbKK ",
      "                "
    ],
    [
      "                ",
      " KKbKKbKKbKKbKK ",
      " K    b  b    K ",
      " b  45b  b    b ",
      " K  d bbb67   K ",
      " K    8  RRRR7K ",
      " bbbb9        b ",
      " K            K ",
      " K            K ",
      " b            b ",
      " K            K ",
      " K            K ",
      " b            b ",
      " K            K ",
      " KKbKKbKKbKKbKK ",
      "                "
    ],
    [
      "                ",
      " ##b##b##b##b## ",
      " #$$$$$$$$$$$$# ",
      " b$  4b  b%%%$b ",
      " #$ dgbbb%%%%$# ",
      " #$   %%%%%%%$# ",
      " b$bb%%%%%%%%$b ",
      " #$%%%%%%%%%%$# ",
      " #$%%%%%%%%%%$# ",
      " b$%%%%%%%%%%$b ",
      " #$%%^%%%%&%%$# ",
      " #$%%%%%%%%%%$# ",
      " b$%%%%%%%%%%$b ",
      " #$$$$$$$$$$$$# ",
      " ##b##b##b##b## ",
      "                "
    ]
  ]
}