{
  "name": "building_office5_top_270",
  "refpalette": "deceasedcraft:building_office5/building_office5_top_palette_270",
  "xsize": 16,
  "zsize": 16,
  "slices": [
    [
      "                ",
      " aabaabaabaabaa ",
      " acccccccccccca ",
      " bcccccccc   cb ",
      " acccccccc d ca ",
      " accccccccge ca ",
      " bccccccccccccb ",
      " acccccccccfcca ",
      " acccccccccccca ",
      " bccccccccccccb ",
      " acccccccccccca ",
      " acccccccccccca ",
      " bccccccccccccb ",
      " acccccccccccca ",
      " aabaabaabaabaa ",
      "                "
    ],
    [
      "                ",
      " hhbhhbhhbhhbhh ",
      " hiiiiiiiiiiiih ",
      " bi      i   ib ",
      " hi      i d ih ",
      " hi mff  l   ih ",
      " bi   f   kiiib ",
      " hi   f    f ih ",
      " hi   f    f ih ",
      " bi mff    f ib ",
      " hi   f   !j ih ",
      " hi   ffffjj ih ",
      " bi          ib ",
      " hiiiiiiiiiiiih ",
      " hhbhhbhhbhhbhh ",
      "                "
    ],
    [
      "                ",
      " nnbnnbnnbnnbnn ",
      " noooooooiiiiin ",
      " bo      i   ib ",
      " no      ird in ",
      " no      t p in ",
      " bo       siiib ",
      " no          on ",
      " no          on ",
      " bo          ob ",
      " no       qq on ",
      " no       qq on ",
      " bo          ob ",
      " noooooooooooon ",
      " nnbnnbnnbnnbnn ",
      "                "
    ],
    [
      "                ",
      "                ",
      "         uuuuu  ",
      "         uuuuu  ",
      "         uuuuu  ",
      "         uuuuu  ",
      "          uuuu  ",
      "                ",
      "                ",
      "                ",
      "                ",
      "           w    ",
      "                ",
      "                ",
      "                ",
      "                "
    ],
    [
      "                ",
      "                ",
      "                ",
      "                ",
      "                ",
      "                ",
      "                ",
      "                ",
      "                ",
      "                ",
      "                ",
      "           x    ",
      "                ",
      "                ",
      "                ",
      "                "
    ],
    [
      "                ",
      "                ",
      "                ",
      "                ",
      "                ",
      "                ",
      "                ",
      "                ",
      "                ",
      "                ",
      "                ",
      "           y    ",
      "                ",
      "                ",
      "                ",
      "                "
    ]
  ]
}