{
  "name": "building_office5_floor2_180",
  "refpalette": "deceasedcraft:building_office5/building_office5_floor2_palette_180",
  "xsize": 16,
  "zsize": 16,
  "slices": [
    [
      "                ",
      " aabaabaabaabaa ",
      " acccccccccccca ",
      " bccccccccccccb ",
      " acccccccccccca ",
      " acccccccccccca ",
      " bccccccccccccb ",
      " acccccccccccca ",
      " acccccccccccca ",
      " bccccccccccccb ",
      " accccccccgf ca ",
      " acccccccced ca ",
      " bcccccccc   cb ",
      " acccccccccccca ",
      " aabaabaabaabaa ",
      "                "
    ],
    [
      "                ",
      " hhbhhbhhbhhbhh ",
      " hR  QP  QP  Oh ",
      " bN  MN  MN  Mb ",
      " hJ LFJ KFJ KFh ",
      " hJI FJI FJI Fh ",
      " bE  DE  DE  Db ",
      " hB CAB  AB  Ah ",
      " h            h ",
      " b    w  yxbbbb ",
      " h  wu   t sr h ",
      " h qqqqbpb d  h ",
      " b   obn b    b ",
      " hmlkjbi b    h ",
      " hhbhhbhhbhhbhh ",
      "                "
    ],
    [
      "                ",
      " SSbSSbSSbSSbSS ",
      " SV          VS ",
      " b*  89  (*  &b ",
      " S^  %^  %^  %S ",
      " S$  #$  #$  #S ",
      " b9  8   76  5b ",
      " S            S ",
      " S            S ",
      " b        4bbbb ",
      " S       3  s S ",
      " S 210ZbYb dX S ",
      " b    bW b    b ",
      " SVU Tb  b    S ",
      " SSbSSbSSbSSbSS ",
      "                "
    ],
    [
      "                ",
      " SSbSSbSSbSSbSS ",
      " S)          )S ",
      " b            b ",
      " S            S ",
      " S            S ",
      " b            b ",
      " S            S ",
      " S            S ",
      " b        {bbbb ",
      " S       ]    S ",
      " S 2   bbb d[ S ",
      " b    b- b +X b ",
      " S)   b  b    S ",
      " SSbSSbSSbSSbSS ",
      "                "
    ],
    [
      "                ",
      " SSbSSbSSbSSbSS ",
      " S            S ",
      " b            b ",
      " S            S ",
      " S            S ",
      " b            b ",
      " S            S ",
      " S            S ",
      " b        :bbbb ",
      " S       ;    S ",
      " S 2   bbb d  S ",
      " b    b  b|}  b ",
      " S    b  b    S ",
      " SSbSSbSSbSSbSS ",
      "                "
    ],
    [
      "                ",
      " ''b''b''b''b'' ",
      " '<<<<<<<<<<<<' ",
      " b<>>>>>>>>>><b ",
      " '<>>>>>>>>>><' ",
      " '<>>,>>>>.>><' ",
      " b<>>>>>>>>>><b ",
      " '<>>>>>>>>>><' ",
      " '<>>>>>>>>>><' ",
      " b<>>>>>>>>bb<b ",
      " '<>>,>>>>   <' ",
      " '<>>>>bbbgd <' ",
      " b<>>>b! b}  <b ",
      " '<<<<<<<<<<<<' ",
      " ''b''b''b''b'' ",
      "                "
    ]
  ]
}