{
  "name": "building_office5_floor2_270",
  "refpalette": "deceasedcraft:building_office5/building_office5_floor2_palette_270",
  "xsize": 16,
  "zsize": 16,
  "slices": [
    [
      "                ",
      " aabaabaabaabaa ",
      " acccccccccccca ",
      " bcccccccc   cb ",
      " accccccccfd ca ",
      " accccccccge ca ",
      " bccccccccccccb ",
      " acccccccccccca ",
      " acccccccccccca ",
      " bccccccccccccb ",
      " acccccccccccca ",
      " acccccccccccca ",
      " bccccccccccccb ",
      " acccccccccccca ",
      " aabaabaabaabaa ",
      "                "
    ],
    [
      "                ",
      " hhbhhbhhbhhbhh ",
      " hOMFFDA b    h ",
      " b  K    br   b ",
      " h   I   bsd  h ",
      " hPNJJEB x    h ",
      " bQMFFDA ytbbbb ",
      " h  K      p  h ",
      " h   I     bnih ",
      " bPNJJEB w qbbb ",
      " hQMFFDA  uqojh ",
      " h  L  C  wq kh ",
      " b   I     q lb ",
      " hRNJJEB     mh ",
      " hhbhhbhhbhhbhh ",
      "                "
    ],
    [
      "                ",
      " SSbSSbSSbSSbSS ",
      " SV&%#5  b    S ",
      " b       bsX  b ",
      " S       b d  S ",
      " S *^$6  4    S ",
      " b (%#7   3bbbb ",
      " S         Y  S ",
      " S         bW S ",
      " b 9^$     Zbbb ",
      " S 8%#8    0 TS ",
      " S         1  S ",
      " b         2 Ub ",
      " SV*^$9      VS ",
      " SSbSSbSSbSSbSS ",
      "                "
    ],
    [
      "                ",
      " SSbSSbSSbSSbSS ",
      " S)      b    S ",
      " b       b [X b ",
      " S       b d+ S ",
      " S       {    S ",
      " b        ]bbbb ",
      " S         b  S ",
      " S         b- S ",
      " b          bbb ",
      " S            S ",
      " S            S ",
      " b         2  b ",
      " S)          )S ",
      " SSbSSbSSbSSbSS ",
      "                "
    ],
    [
      "                ",
      " SSbSSbSSbSSbSS ",
      " S       b    S ",
      " b       b    b ",
      " S       b d} S ",
      " S       :  | S ",
      " b        ;bbbb ",
      " S         b  S ",
      " S         b  S ",
      " b          bbb ",
      " S            S ",
      " S            S ",
      " b         2  b ",
      " S            S ",
      " SSbSSbSSbSSbSS ",
      "                "
    ],
    [
      "                ",
      " ''b''b''b''b'' ",
      " '<<<<<<<<<<<<' ",
      " b<>>>>>>b   <b ",
      " '<>>>>>>b d <' ",
      " '<>>.>>>> g}<' ",
      " b<>>>>>>>>bb<b ",
      " '<>>>>>>>>b <' ",
      " '<>>>>>>>>b!<' ",
      " b<>>>>>>>>>b<b ",
      " '<>>,>>>>,>><' ",
      " '<>>>>>>>>>><' ",
      " b<>>>>>>>>>><b ",
      " '<<<<<<<<<<<<' ",
      " ''b''b''b''b'' ",
      "                "
    ]
  ]
}