{
  "name": "building_office5_floor3",
  "refpalette": "deceasedcraft:building_office5/building_office5_floor3_palette",
  "xsize": 16,
  "zsize": 16,
  "slices": [
    [
      "                ",
      " aabaabaabaabaa ",
      " acccccccccccca ",
      " bc   ccccccccb ",
      " ac decccccccca ",
      " ac fgcccccccca ",
      " bccccccccccccb ",
      " acccccccccccca ",
      " acccccccccccca ",
      " bccccccccccccb ",
      " acccccccccccca ",
      " acccccccccccca ",
      " bccccccccccccb ",
      " acccccccccccca ",
      " aabaabaabaabaa ",
      "                "
    ],
    [
      "                ",
      " hhbhhbhhbhhbhh ",
      " h    b ibjklmh ",
      " b    b nbo   b ",
      " h  d bpbqqqq h ",
      " h rs t  uw u h ",
      " bbbbxy       b ",
      " h        A   h ",
      " hB  CB  CBD Ch ",
      " bE  FE  FE IFb ",
      " hJ KLJ KLJ KLh ",
      " hJM LJM LJNMLh ",
      " bO  PO  POQ Pb ",
      " hR  ST  ST  Uh ",
      " hhbhhbhhbhhbhh ",
      "                "
    ],
    [
      "                ",
      " VVbVVbVVbVVbVV ",
      " V    b  bWXYZV ",
      " b    b 0b    b ",
      " V 1d b2b34 5 V ",
      " V s  6       V ",
      " bbbb7        b ",
      " V            V ",
      " V            V ",
      " bA  89  #   $b ",
      " VI  %I  %N  %V ",
      " V^  &^  &   &V ",
      " b   *(  )+  *b ",
      " VZ          ZV ",
      " VVbVVbVVbVVbVV ",
      "                "
    ],
    [
      "                ",
      " VVbVVbVVbVVbVV ",
      " V    b  b   -V ",
      " b 1[ b ]b    b ",
      " V {d bbb   5 V ",
      " V    }       V ",
      " bbbb|        b ",
      " V            V ",
      " V            V ",
      " b            b ",
      " V            V ",
      " V            V ",
      " b            b ",
      " V-          -V ",
      " VVbVVbVVbVVbVV ",
      "                "
    ],
    [
      "                ",
      " VVbVVbVVbVVbVV ",
      " V    b  b    V ",
      " b  ;:b  b    b ",
      " V  d bbb   5 V ",
      " V    '       V ",
      " bbbb<        b ",
      " V            V ",
      " V            V ",
      " b            b ",
      " V            V ",
      " V            V ",
      " b            b ",
      " V            V ",
      " VVbVVbVVbVVbVV ",
      "                "
    ],
    [
      "                ",
      " >>b>>b>>b>>b>> ",
      " >,,,,,,,,,,,,> ",
      " b,  ;b  b...,b ",
      " >, dgbbb....,> ",
      " >,   ....?..,> ",
      " b,bb........,b ",
      " >,..........,> ",
      " >,..........,> ",
      " b,..........,b ",
      " >,..?....!..,> ",
      " >,..........,> ",
      " b,..........,b ",
      " >,,,,,,,,,,,,> ",
      " >>b>>b>>b>>b>> ",
      "                "
    ]
  ]
}