{
  "name": "building_office5_ground_270",
  "refpalette": "deceasedcraft:building_office5/building_office5_ground_palette_270",
  "xsize": 16,
  "zsize": 16,
  "slices": [
    [
      "ccbaaaaaaaaaaaaa",
      "ccc=aa=aa=bb=bba",
      "bcccbaaaacccccba",
      "a=cccbaaacdddc=a",
      "aabcccbbbcd!dcba",
      "aaabccccccdddcba",
      "a=aabccccccccc=a",
      "aaaabcceeccbaaaa",
      "aaaabcceeccbaaaa",
      "a=aabccccccbaa=a",
      "aaabccccccccbaaa",
      "aabcccbbbbcccbaa",
      "a=cccbaaaabccc=a",
      "bcccbaaaaaabcccb",
      "ccc=aa=aa=aa=ccc",
      "ccbaaaaaaaaaabcc"
    ],
    [
      "                ",
      "   =gg=  =ff=ff ",
      "     ggggh    f ",
      " =     tphl   = ",
      " g       hmk  f ",
      " gg      o    f ",
      " =g    q  nhhh= ",
      "  gx   rq   ig  ",
      "  gy   ur   jg  ",
      " =g     q    g= ",
      " gg          gg ",
      " g            g ",
      " =     ws     = ",
      "     gggggg     ",
      "   =gg=  =gg=   ",
      "                "
    ],
    [
      "                ",
      "   =  =  =ff=ff ",
      "         h    f ",
      " =       hmA  = ",
      "         h k  f ",
      "         C    f ",
      " =        Bhhh= ",
      "                ",
      "        r       ",
      " =            = ",
      "                ",
      "                ",
      " =            = ",
      "                ",
      "   =  =  =  =   ",
      "                "
    ],
    [
      "                ",
      " DD=DD=DD=DD=DD ",
      " D       h    D ",
      " =       h FA = ",
      " D       h kE D ",
      " D       h    D ",
      " =       Ihhhh= ",
      " D            D ",
      " D            D ",
      " =            = ",
      " D            D ",
      " D            D ",
      " =            = ",
      " D            D ",
      " DD=DD=DD=DD=DD ",
      "                "
    ],
    [
      "                ",
      " JJ=JJ=JJ=JJ=JJ ",
      " JKKKKKKKhKKKKJ ",
      " =K      h   K= ",
      " JK      h kLKJ ",
      " JK      h  MKJ ",
      " =K      Nhhhh= ",
      " JK          KJ ",
      " JK          KJ ",
      " =K          K= ",
      " JK          KJ ",
      " JK          KJ ",
      " =K          K= ",
      " JKKKKKKKKKKKKJ ",
      " JJ=JJ=JJ=JJ=JJ ",
      "                "
    ],
    [
      "                ",
      " OOOOOOOOOOOOOO ",
      " OPPPPPPPPPPPPO ",
      " OPQQQQQQh   PO ",
      " OPQQQQQQh k PO ",
      " OPQQQQQQh RLPO ",
      " OPQQQQQQShhhPO ",
      " OPQQQQQQQQQQPO ",
      " OPQQQQQQQQQQPO ",
      " OPQQQQQQQQQQPO ",
      " OPQQQQQQQQQQPO ",
      " OPQQQQQQQQQQPO ",
      " OPQQQQQQQQQQPO ",
      " OPPPPPPPPPPPPO ",
      " OOOOOOOOOOOOOO ",
      "                "
    ]
  ]
}