{
  "name": "building_office5_floor4_270",
  "refpalette": "deceasedcraft:building_office5/building_office5_floor4_palette_270",
  "xsize": 16,
  "zsize": 16,
  "slices": [
    [
      "                ",
      " aabaabaabaabaa ",
      " acccccccccccca ",
      " bcccccccc   cb ",
      " accccccccfd ca ",
      " accccccccge ca ",
      " bccccccccccccb ",
      " acccccccccccca ",
      " acccccccccccca ",
      " bccccccccccccb ",
      " acccccccccccca ",
      " acccccccccccca ",
      " bccccccccccccb ",
      " acccccccccccca ",
      " aabaabaabaabaa ",
      "                "
    ],
    [
      "                ",
      " hhbhhbhhbhhbhh ",
      " hI      b    h ",
      " b  AAA  bq   b ",
      " h FABAy brd  h ",
      " h  A!A  w    h ",
      " b FACAy xsbbbb ",
      " h  ACA    n  h ",
      " h FACAy   bmih ",
      " b  ADA   tobbb ",
      " h FABAy  up jh ",
      " h  AAA   t  kh ",
      " b   E    u  lb ",
      " hJ       p   h ",
      " hhbhhbhhbhhbhh ",
      "                "
    ],
    [
      "                ",
      " KKbKKbKKbKKbKK ",
      " KW      b    K ",
      " b       brM  b ",
      " K   U   b d  K ",
      " K  TVT  S    K ",
      " b   V    Qbbbb ",
      " K  TV     N  K ",
      " K   V     bL K ",
      " b   VT   RObbb ",
      " K   V    RP  K ",
      " K        R   K ",
      " b        R   b ",
      " KW       P   K ",
      " KKbKKbKKbKKbKK ",
      "                "
    ],
    [
      "                ",
      " KKbKKbKKbKKbKK ",
      " K3      b    K ",
      " b       b ZM b ",
      " K       b dX K ",
      " K       2    K ",
      " b        1bbbb ",
      " K         b  K ",
      " K         bY K ",
      " b        R0bbb ",
      " K        RP  K ",
      " K        R   K ",
      " b        R   b ",
      " K3       P   K ",
      " KKbKKbKKbKKbKK ",
      "                "
    ],
    [
      "                ",
      " KKbKKbKKbKKbKK ",
      " K       b    K ",
      " b       b    b ",
      " K       b d4 K ",
      " K       9  5 K ",
      " b        8bbbb ",
      " K         b  K ",
      " K         b  K ",
      " b        R6bbb ",
      " K        R7  K ",
      " K        R   K ",
      " b        R   b ",
      " K        7   K ",
      " KKbKKbKKbKKbKK ",
      "                "
    ],
    [
      "                ",
      " ##b##b##b##b## ",
      " #$$$$$$$$$$$$# ",
      " b$%%%%%%b   $b ",
      " #$%%%%%%b d $# ",
      " #$%%^%%%% g4$# ",
      " b$%%%%%%%%bb$b ",
      " #$%%%%%%%%b $# ",
      " #$%%%%%%%%b $# ",
      " b$%%%%%%%%%b$b ",
      " #$%%&%%%%%%%$# ",
      " #$%%%%%%%%%%$# ",
      " b$%%%%%%%%%%$b ",
      " #$$$$$$$$$$$$# ",
      " ##b##b##b##b## ",
      "                "
    ]
  ]
}