{
  "name": "building_office5_floor3_90",
  "refpalette": "deceasedcraft:building_office5/building_office5_floor3_palette_90",
  "xsize": 16,
  "zsize": 16,
  "slices": [
    [
      "                ",
      " aabaabaabaabaa ",
      " acccccccccccca ",
      " bccccccccccccb ",
      " acccccccccccca ",
      " acccccccccccca ",
      " bccccccccccccb ",
      " acccccccccccca ",
      " acccccccccccca ",
      " bccccccccccccb ",
      " ac egcccccccca ",
      " ac dfcccccccca ",
      " bc   ccccccccb ",
      " acccccccccccca ",
      " aabaabaabaabaa ",
      "                "
    ],
    [
      "                ",
      " hhbhhbhhbhhbhh ",
      " hm     CFLLPUh ",
      " bl qu   IKM  b ",
      " hk q   D  NQ h ",
      " hjoqw ABEJJOTh ",
      " bbbqu  CFLLPSb ",
      " hinb     K   h ",
      " h  p      M  h ",
      " bbbbty BEJJOTb ",
      " h    x CFLLPSh ",
      " h  dsb   K   h ",
      " b   rb    M  b ",
      " h    b BEJJORh ",
      " hhbhhbhhbhhbhh ",
      "                "
    ],
    [
      "                ",
      " VVbVVbVVbVVbVV ",
      " VZ      $%&*ZV ",
      " bY 5         b ",
      " VX           V ",
      " VW 4     N + V ",
      " bbb3    #%&) b ",
      " V 0b         V ",
      " V  2         V ",
      " bbbb6   9I^( b ",
      " V    7  8%&* V ",
      " V  d b       V ",
      " b  1sb       b ",
      " V    b  AI^ ZV ",
      " VVbVVbVVbVVbVV ",
      "                "
    ],
    [
      "                ",
      " VVbVVbVVbVVbVV ",
      " V-          -V ",
      " b  5         b ",
      " V            V ",
      " V            V ",
      " bbb          b ",
      " V ]b         V ",
      " V  b         V ",
      " bbbb}        b ",
      " V    |       V ",
      " V [d b       V ",
      " b 1{ b       b ",
      " V    b      -V ",
      " VVbVVbVVbVVbVV ",
      "                "
    ],
    [
      "                ",
      " VVbVVbVVbVVbVV ",
      " V            V ",
      " b  5         b ",
      " V            V ",
      " V            V ",
      " bbb          b ",
      " V  b         V ",
      " V  b         V ",
      " bbbb'        b ",
      " V :  <       V ",
      " V ;d b       V ",
      " b    b       b ",
      " V    b       V ",
      " VVbVVbVVbVVbVV ",
      "                "
    ],
    [
      "                ",
      " >>b>>b>>b>>b>> ",
      " >,,,,,,,,,,,,> ",
      " b,..........,b ",
      " >,..........,> ",
      " >,..?....!..,> ",
      " b,b.........,b ",
      " >, b........,> ",
      " >, b........,> ",
      " b,bb........,b ",
      " >,;g ....?..,> ",
      " >, d b......,> ",
      " b,   b......,b ",
      " >,,,,,,,,,,,,> ",
      " >>b>>b>>b>>b>> ",
      "                "
    ]
  ]
}