{
  "name": "building_apartmentsmallabroken_ground_180",
  "refpalette": "deceasedcraft:building_apartmentsmallabroken/building_apartmentsmallabroken_ground_palette_180",
  "xsize": 16,
  "zsize": 16,
  "slices": [
    [
      "aaabaakaaaaaaaaa",
      "aakaakccccccccca",
      "kbiiiiccccccccca",
      "aaihhlcgccccccca",
      "akihjhgfgcccccca",
      "baihhhfgcgcccccb",
      "acccccccgcccccca",
      "accccccfcccccccb",
      "acccccccccccccce",
      "bccccccccccccccb",
      "acccccccccccccca",
      "acccccccccccccca",
      "accccccddccccccb",
      "bccccccddcccccca",
      "bcccccccccccccca",
      "aaaabaaaaaaaabba"
    ],
    [
      "9 Z68ZV 7E      ",
      " 765 4n3sss sss ",
      "V iiVVm 2110  s ",
      "ZYiQ  n S X  Ws ",
      " VU !Q       Ts ",
      "uSR Q Q    PDOs ",
      "Nnmomom      MI ",
      " sL  L          ",
      "Es  y K         ",
      " s JJ        lI ",
      " sBFAw  Em  DCn ",
      " sBxAwmy mp   s ",
      " s xxwn unpt  s ",
      "   r  mq np     ",
      " momoonmnnnnmmm ",
      "                "
    ],
    [
      "                ",
      "      n3ssssss  ",
      "  iUiUn       s ",
      "  i   m       s ",
      "  )           s ",
      "  (         *&s ",
      " nmmmnm      ^I ",
      " s              ",
      " s              ",
      " s           M% ",
      " s       m   $m ",
      " s    m  n#   s ",
      " s    m  n#   s ",
      " s    o  m#     ",
      " nmummmnnnnnnmn ",
      "                "
    ],
    [
      "                ",
      "      n|ssssss  ",
      "  }{iim         ",
      "  U ]Mm       s ",
      "  i   [       s ",
      "  i   +      &s ",
      " nnmnnm      ^% ",
      " s            - ",
      "                ",
      " s           ^% ",
      " s       n   $n ",
      " s    n+mn#   s ",
      " s    n  n#   s ",
      " s    m  n#   s ",
      " nn smnssmnssnn ",
      "                "
    ],
    [
      "                ",
      "      m\u0372|333|3\u0371 ",
      "  i))\u0370m       | ",
      "  {  `n       3 ",
      "  {   m       3 ",
      "  /   m      ?3 ",
      " momnmn      ^% ",
      " |    m      M  ",
      " 3    .      ,  ",
      " |    >      ^% ",
      " |    n  n   <n ",
      " 3    mnnn    3 ",
      " 3    n  n    | ",
      " 3    n  n'   | ",
      " mn:;nn;:nn;;nn ",
      "                "
    ],
    [
      "                ",
      "      mmnmmnnmm ",
      "  iiUUmiiiiiiin ",
      "  i   miiiiiiim ",
      "  i  \u0376niiiiiiin ",
      "  i \u0375Mniiiiiiin ",
      " mnnnnniiiiiiin ",
      " niiiinii\u0374\u0374iiin ",
      " niiiinii\u0374\u0374iiin ",
      " miiiiniiiiiiin ",
      " niiiiniiniiiin ",
      " niiiinnnniiiin ",
      " niiiin\u0373\u0373niiiin ",
      " niiiin\u0373\u0373niiiin ",
      " mmnnnnnnnnnnnn ",
      "                "
    ]
  ]
}