{
  "name": "building_apartmentsmallabroken_ground_270",
  "refpalette": "deceasedcraft:building_apartmentsmallabroken/building_apartmentsmallabroken_ground_palette_270",
  "xsize": 16,
  "zsize": 16,
  "slices": [
    [
      "aaaaababebaabaaa",
      "accccccccccccccb",
      "accccccccccccccb",
      "acccccccccccccca",
      "acccccccccccccca",
      "acccccccccccccca",
      "accccgccccccccca",
      "acccgcgcccccddca",
      "accgfgcfccccddca",
      "kcccgfccccccccca",
      "akilhhccccccccca",
      "aaihjhcccccccccb",
      "baihhhccccccccca",
      "akiiiiccccccccca",
      "aabakaccccccccca",
      "aakaabaaabaaabba"
    ],
    [
      "                ",
      " sssssI  Inss m ",
      " s WTOM  lC   m ",
      " s   D    D   m ",
      "  0  P      t n ",
      " s1X       pppn ",
      "Es1       mmnnn ",
      "7s2S      E u n ",
      " 3         y qm ",
      "Vnmn Qm K  mnmn ",
      "Z4V Q oL  www o ",
      "8 V !Qm yJAAx o ",
      "65iQ  o  JFxxrm ",
      "Z6iiURmL  BB  o ",
      " 7 YVSnssssss m ",
      "9 VZ uN E       "
    ],
    [
      "                ",
      "  ssssI  %mss n ",
      " s   &^  M$   m ",
      " s   *        n ",
      " s            n ",
      " s         ###n ",
      " s        mnnmn ",
      " s            n ",
      " 3            n ",
      " nnm  m    mmom ",
      "  U   n       m ",
      "  i   m       m ",
      "  U   m       u ",
      "  ii)(m       m ",
      "      nsssssssn ",
      "                "
    ],
    [
      "                ",
      "   sss%- %nsssn ",
      " s   &^  ^$   n ",
      " s            s ",
      " s            s ",
      " s         ###n ",
      " s        nnnnm ",
      " s         m  s ",
      " |         +  s ",
      " nmm[+m    nnmn ",
      "  iM  n       m ",
      "  i]  n       s ",
      "  {   m         ",
      "  }Uiin       n ",
      "      ns sssssn ",
      "                "
    ],
    [
      "                ",
      " \u0371|333%  %n3||n ",
      " 3   ?^M,^<   n ",
      " |            ; ",
      " 3            ; ",
      " 3           'n ",
      " 3        nnnnn ",
      " |         n  : ",
      " \u0372         n  ; ",
      " mmnmmnm.>nmnnn ",
      "  \u0370`  m       n ",
      "  )   n       ; ",
      "  )   m       : ",
      "  i{{/o       n ",
      "      m|3||333m ",
      "                "
    ],
    [
      "                ",
      " mnmnnnnnnnnnnn ",
      " miiiiiiiiiiiin ",
      " niiiiiiiiiiiin ",
      " niiiiiiiiiiiin ",
      " miiiii\u0374\u0374iiiiin ",
      " miiiii\u0374\u0374innnnn ",
      " niiiiiiiiin\u0373\u0373n ",
      " miiiiiiiiin\u0373\u0373n ",
      " mmmnnnnnnnnnnn ",
      "  U \u0376Mniiiiiiin ",
      "  U  \u0375niiiiiiin ",
      "  i   niiiiiiin ",
      "  iiiiniiiiiiim ",
      "      mnnmnnnnm ",
      "                "
    ]
  ]
}