{
  "name": "building_apartmentsmallabroken_top_270",
  "refpalette": "deceasedcraft:building_apartmentsmallabroken/building_apartmentsmallabroken_top_palette_270",
  "xsize": 16,
  "zsize": 16,
  "slices": [
    [
      "                ",
      " baaaaaaaaaaaba ",
      " adddddeeddddda ",
      " adddddeeddddda ",
      " bdddddeeddddda ",
      " adddddddddddda ",
      " adddddddddddda ",
      " addddddddddeea ",
      " addddddddddeea ",
      " bddddddddddeea ",
      "  l  fdddddddda ",
      "  m  gdddddddda ",
      "  n jhddddddddb ",
      "  okkidddddddd  ",
      "      aaaabaabc ",
      "                "
    ],
    [
      "                ",
      " pppppppppppApp ",
      " p93 ZpU~pJEBqp ",
      " p# 30p~ pK Crp ",
      " p$ 11p ppL Crp ",
      " A       AM  qp ",
      " A444 W  Q sDsp ",
      " p%   X  ppp tp ",
      " p^752X    F up ",
      " ppApSY RA I wp ",
      "  &   A  A Fppp ",
      "  &   AVSpN  xp ",
      "  i86   TpO  yp ",
      "  iiiip TpP  tp ",
      "      pAppppppp ",
      "                "
    ],
    [
      "                ",
      " '>`>>?>>'p***p ",
      " >    p  pt{-(p ",
      " *\u0371  /A  p    p ",
      " *\u0372   A pp    p ",
      " *\u0372      p;   p ",
      " *\u0372      < }[sp ",
      " *\u0373     ,pAp )p ",
      " >t        F  p ",
      " pppAAR  p    p ",
      "  i   A  A Fppp ",
      "  i   p.Ap    p ",
      "  i\u0370    !p    p ",
      "  \u0374i&np  p:|]+p ",
      "      ppAAp***p ",
      "                "
    ],
    [
      "                ",
      " ?***>?**'p***p ",
      " `   \u0387p  p \u037d\u037b\u0375p ",
      " *\u0389  tp  p    * ",
      " *\u038a   A\u0385pp    * ",
      " *\u038a      p    p ",
      " *\u038a      \u037f }}sp ",
      " *\u038c      App \u0376* ",
      " >       \u0384 F  * ",
      " ApppA   p F \u0377p ",
      "  ie  p  p Fppp ",
      "  \u0374\u0388  A\u0386Ap    * ",
      "  \u038e   p  p    * ",
      "  \u038fii\u0374p  p \u037e\u037c\u037ap ",
      "      A**pp***A ",
      "                "
    ],
    [
      "                ",
      " ?>>>>?>>?p>``p ",
      " `    p  p    p ",
      " `    p  p    \u0390 ",
      " >    ppAp    \u0390 ",
      " >  \u0392    p    p ",
      " `       p }s}p ",
      " >       ppp  \u0390 ",
      " `       p F  \u0391 ",
      " pAApp   p F tp ",
      "  k\u0394\u0393 A  p Fppp ",
      "  &   pppp   t\u0390 ",
      "  &   p  p    \u0390 ",
      "  \u0374\u0395\u038e\u038ep  p    p ",
      "      p``pA`>>A ",
      "                "
    ],
    [
      "                ",
      " ApppAppApppppA ",
      " piiiii\u0396\u0396piiiip ",
      " Aiiiii\u0396\u0396piiiip ",
      " piiiiiiipiiiip ",
      " Aiiiiiiipiiiip ",
      " piiiiiiipiiiip ",
      " piiiiiiipii\u0396\u0396p ",
      " Aiiiiiiipii\u0396\u0396p ",
      " ApApp\u0397iipii\u0396\u0396p ",
      "  i \u0398epiipiiiip ",
      "  i   ppppiiiip ",
      "  \u0374   Aiipiiiip ",
      "  \u0374iiipiipiiiiA ",
      "      AAAAppppp ",
      "                "
    ],
    [
      "                ",
      " abaaaaaaaaaaaa ",
      " adddddeedddddb ",
      " adddddeeddddda ",
      " adddddeeddddda ",
      " adddddddddddda ",
      " bdddddddddddda ",
      " bddddddddddeea ",
      " bddddddddddeea ",
      "  ddddddddddeea ",
      "  \u0374  \u0399dddddddda ",
      "  m  \u039addddddddb ",
      "  n \u039c\u039bdddddddda ",
      "  l\u039dkiddddddddb ",
      "      b aaaabab ",
      "                "
    ],
    [
      "                ",
      " pppppppppppppp ",
      " p9\u03actZp\u03a8tpJB\u039fqp ",
      " p#t 0p wpK\u03a3Crp ",
      " p$ 11A\u03a9ppL Crp ",
      " p      Rp I qp ",
      " p444 W   Is\u03a0sp ",
      " p    X  App  p ",
      " p^752X  \u03a6 \u03a4 up ",
      " ApSAAY  p D wp ",
      "  &   S \u03a7p Fppp ",
      "  &   AIppN  xp ",
      "  \u0374\u03ad\u03ab \u03aa TpO \u039eyp ",
      "   \u0374\u0374ip TpP\u03a5\u03a1\u039ep ",
      "      ApApppppp ",
      "                "
    ],
    [
      "                ",
      " ?``>??>>?p***p ",
      " >   !p  p    p ",
      " *   /p  p\u03af   p ",
      " *    A\u03b3Ap    p ",
      " *       p;   p ",
      "           s\u03aesp ",
      " *      ,ppp )p ",
      " \u03bc       \u03b1 F  p ",
      " pAApA\u03b5  A [  p ",
      "  i   A  p;\u03a4App ",
      "  \u0374\u03b9\u03b7 A pp    p ",
      "  \u03bbf  \u03b6 \u03b2p    p ",
      "   \u03ba\u03b8np  p\u03b0   p ",
      "      A\u03b4AAp***p ",
      "                "
    ],
    [
      "                ",
      " '***>?**'p***p ",
      " \u03bc   \u0387p  p    p ",
      " *    p \u0377p    * ",
      "      pApp    * ",
      " *       A    p ",
      " *       \u0384 sssp ",
      " *       ppp \u0376* ",
      " `       \u0384 F  * ",
      " ApApp   p F \u0377p ",
      "  \u03748  A  p FpAp ",
      "  \u03baf\u03b7 p\u0386Ap    * ",
      "      A  p    * ",
      "   \u03bdi\u0374p  p    p ",
      "      S *pp***p ",
      "                "
    ],
    [
      "                ",
      " '`>>>'>>'p`>>p ",
      " `    A  p    p ",
      " >    p tp    \u0390 ",
      " \u03be    pppp    \u0390 ",
      "    \u0392    p    p ",
      " '       p sssp ",
      " `       App  \u0390 ",
      " >       p F  \u0390 ",
      " SAppA   p F  p ",
      "  \u039d g p  A \u03a4ppp ",
      "  \u03b8 \u03b7 pppp    \u0391 ",
      "      p  p    \u0390 ",
      "   \u0395\u03bf\u038eA  p    p ",
      "      S`>Ap`>\u03be\u037f ",
      "                "
    ],
    [
      "                ",
      " pApppppppppppp ",
      " Aiiiii\u0396\u0396piiiip ",
      " piiiii\u0396\u0396piiiip ",
      " piiiiiiipiiiip ",
      " piiiiiiipiiiip ",
      " Aiiiiiiipiiiip ",
      " Aiiiiiiipii\u0396\u0396p ",
      " piiiiiiipii\u0396\u0396p ",
      " AApAAiiipii\u0396\u0396p ",
      "  i  fAiipiiiip ",
      "  \u0374 \u03b7\u03c2ppppiiiip ",
      "      Aiipiiiip ",
      "    \u03c3i\u03c0iipiiiiA ",
      "      \u03c1SAAApApA ",
      "                "
    ],
    [
      "                ",
      " aababaaaaabbab ",
      " a\u03c9\u03c6\u03c5ddeedddddb ",
      " a\u03ca\u03c5\u03c6\u03c5deeddddda ",
      " a\u03c5ddddeeddddda ",
      " bdd\u03c5ddddddddda ",
      " bddd\u03c7dddddddda ",
      " bdddddddddd\u03c4\u03c4a ",
      " bdddddddddd\u03c4\u03c4a ",
      " cdddddddddd\u03c4\u03c4a ",
      "  i   dddddddda ",
      "  \u039d \u03b7 dddddddda ",
      "    \u03c88\u03c6\u03c5dddddda ",
      "    \u03bd\u0374d\u03c5\u03c5ddddda ",
      "        c cbaac ",
      "                "
    ],
    [
      "                ",
      " pppppppppppppp ",
      " p \u03d2\u03f5\u03f0A\u03e1\u03e1pJ\u03d7\u03cb\u03cbp ",
      " p\u03f6  \u03f1p\u03e1\u03e2AK\u03d8\u03d0\u03ccp ",
      " A \u03f9 \u03f2A\u03e9\u03e3\u03deL \u03d1\u03ccp ",
      " p\u03fb\u03fa    \u03e4\u03df  \u03d2\u03ccp ",
      " A\u03fc\u03f6 \u03f3\u03ee    }\u03d3sp ",
      " A\u03fd\u03f9\u03f6   \u03e5  \u03d9\u03cd\u03cdp ",
      " S^75\u03f4 \u03ea\u03e6\u03e0 R\u03cd\u03cdp ",
      " AAASA\u03e8\u03eb\u03e7A \u03d2\u03cd\u03cdp ",
      "  \u03b8   S\u03ec\u03e8p\u03da\u03a4ASp ",
      "  l \u03f7 A9pp\u03db \u03d4\u03cep ",
      "    \u03f8 \u03ef\u03edTA\u03dc \u03d5\u03cfp ",
      "     \u03baS\u03edIS\u03dd\u039e\u03d6\u03cfp ",
      "      \u03c0SApA\u03c0SAp ",
      "                "
    ],
    [
      "                ",
      " '`?>\u03be?>>?p***p ",
      " ?  \u03f1\u03f0p  p\u0406\u0405\u0402\u03fep ",
      " *    A  A\u0407  \u03ffp ",
      " *    p  A\u0408  \u03ccp ",
      " *           \u0400p ",
      " *\u03fd          sp ",
      " *\u03fd        \u03a4 )p ",
      " ?\u0411\u040f\u040e    \u0409    p ",
      " SpAAS\u040d  \u040a  \u0403 p ",
      "  \u0412   S\u040c\u040bS FpAp ",
      "   \u0410  AtAp  \u03b0\u03d4p ",
      "        tA   \u0401A ",
      "     nS  A\u0404\u0404\u0404\u03d5p ",
      "      \u03c9\u03c0SAS***A ",
      "                "
    ],
    [
      "                ",
      " \u041c **`?**?p***p ",
      " '    p  A \u0417\u0416\u0413p ",
      " *    A  p    * ",
      " *    A\u0419A\u03de    * ",
      " *       \u0418    p ",
      " *\u03fd         }sp ",
      "  \u03fd        A \u0376* ",
      " '\u03fd           * ",
      " AAAAp     \u03a4 \u0414p ",
      "  \u03bbh  A\u041a A FApp ",
      "   \u0410  p\u041bAS   \u0415* ",
      "      A tp   \u0415  ",
      "     \u0374\u03c0  A \u0404\u0404\u0415p ",
      "        tA\u03c0 **S ",
      "                "
    ],
    [
      "                ",
      "   '\u03bc`?>>?p>>>A ",
      "      p  p    p ",
      " ?    p  p    \u0390 ",
      " `    pApp    \u0390 ",
      " >  \u041e    A    p ",
      " `       p }ssp ",
      " '\u03fd      \u0419Ap  \u0390 ",
      " \u03bc       \u0419 \u03a4  \u0390 ",
      " S\u03c0SSA   \u041d \u03a4  p ",
      "  \u03bb\u0394\u041f pR S Fppp ",
      "      AApS    \u0390 ",
      "      At!A   \u0415\u0391 ",
      "     \u03bfS tp \u0404  A ",
      "       \u03be SA?>>\u03c0 ",
      "                "
    ],
    [
      "                ",
      " SAApppppppppAp ",
      " A\u0374\u0374iii\u0396\u0396piiiiA ",
      " Siiiii\u0396\u0396piiiiA ",
      " Aiiiiiiipiiiip ",
      " p\u0374\u0374i\u03ba\u03baiipiiiip ",
      " Ai\u0374\u0421 \u0374iipiiiip ",
      " A\u0374\u03ba\u0420\u0420\u03ba\u03baipii\u0396\u0396p ",
      " S\u03ba\u03c9\u03ba\u0374iiipii\u0396\u0396p ",
      " \u03c1\u0422bAA\u0374iipii\u0396\u0396p ",
      "    \u03988piipiiiip ",
      "      ApppiiiiA ",
      "      AiipiiiiA ",
      "     \u03bdAiipiiiiA ",
      "      \u0419ASAApA\u03c0\u03c9 ",
      "                "
    ],
    [
      "                ",
      "  bbbaaaaaaabab ",
      "  \u03baiii\u03bfiiiiiiib ",
      " b\u0374ddddddddddia ",
      " aid\u0426\u03c5dddddddia ",
      " bi\u03c5\u03c6\u0424\u03c5ddddddia ",
      " ci\u03ca\u0425 \u03ca\u03c5dddddia ",
      "  \u03b8\u03c9\u03c9\u0425\u0423\u03c6dddddia ",
      "  \u0374\u03c9\u03ca\u03c6\u03c6d\u03c5ddddia ",
      "  \u03bb \u03c9dd\u03c5dddddia ",
      "     \u0398\u03c6ddddddia ",
      "      d\u03c5dddddia ",
      "      dddddddib ",
      "     \u03bd\u0374\u0374iiiiii  ",
      "       cbbabbc  ",
      "                "
    ],
    [
      "                ",
      "                ",
      "  ii\u0374\u042f\u038e\u038e\u0429ii&&\u03b8  ",
      "  i    \u042c     \u03b8  ",
      "  \u0374 \u0426\u0426\u0426\u0426\u0426\u0426!\u042b \u0427  ",
      "  i       \u042b\u042b i  ",
      "  \u038e        \u0426 i  ",
      "  \u0395        \u0426 \u0428  ",
      "  \u0431  \u0430     \u0426\u042a\u038e  ",
      "    SAp    \u0426 i  ",
      "           \u0426 &  ",
      "      S    \u0426\u042a&  ",
      "      p    \u0426 \u0427  ",
      "      \u042e\u042d\u03b8&ii\u038e\u0429  ",
      "                ",
      "                "
    ],
    [
      "                ",
      "                ",
      "  i\u038e\u038eiii\u0374iiiii  ",
      "  &          i  ",
      "  &       \u042b\u042b &  ",
      "  \u0427       \u042b\u042b \u03b8  ",
      "  \u0374          \u03b8  ",
      "  \u0374          i  ",
      "  \u03ba          i  ",
      "    bAA      \u0374  ",
      "             i  ",
      "      b      i  ",
      "      S      i  ",
      "       \u0374\u0374\u0374\u03ba\u03b8ii  ",
      "                ",
      "                "
    ],
    [
      "                ",
      "                ",
      "  i\u0374iiii\u038e\u0395\u038ei\u03b8\u0374  ",
      "  i          i  ",
      "  i       \u0432\u0432 i  ",
      "  \u0374       \u0432\u0432 i  ",
      "  \u03b8          \u03b8  ",
      "             \u03b8  ",
      "             \u0428  ",
      "             \u038e  ",
      "             \u0395  ",
      "             i  ",
      "             i  ",
      "        \u0374\u042f\u0395\u03bf\u038ei  ",
      "                ",
      "                "
    ]
  ]
}