{
  "name": "building_apartmentsmallabroken_top_180",
  "refpalette": "deceasedcraft:building_apartmentsmallabroken/building_apartmentsmallabroken_top_palette_180",
  "xsize": 16,
  "zsize": 16,
  "slices": [
    [
      "                ",
      "      baaaabaab ",
      "  onmldddddddda ",
      "  k   dddddddda ",
      "  kj  dddddddda ",
      "  ihgfdddddddda ",
      " adddddddddddda ",
      " adddddddddeeea ",
      " adddddddddeeea ",
      " adddddddddddda ",
      " bdddddddddddda ",
      " adddddddddddda ",
      " addddeeeddddda ",
      " bddddeeedddddb ",
      " c baaaaaaaaaaa ",
      "                "
    ],
    [
      "                ",
      "      pppAApppp ",
      "  ii&&p^%4 $#9p ",
      "  i8  A7 4   3p ",
      "  i6  p5 4 13 p ",
      "  i   S2   10Zp ",
      " pp AAYXXW pppp ",
      " A  V       ~Up ",
      " pTTS R    p ~p ",
      " ppppAA pQApppp ",
      " pPON   p MLKJp ",
      " p   FIFps   Ep ",
      " p   p   D CCBA ",
      " ptyxpwutsqrrqp ",
      " pppppppppppppp ",
      "                "
    ],
    [
      "                ",
      "      p>*****>' ",
      "  \u0374iiipt\u0373\u0372\u0372\u0372\u0371 > ",
      "  i\u0370  p       ` ",
      "  &   A       > ",
      "  n   A     / > ",
      " pp pAR    AAp? ",
      " p  .         > ",
      " A !A   ,  p  > ",
      " ApppAp p<pppp' ",
      " p:     A ;  tp ",
      " *|  F Fp}   {* ",
      " *]  p   [   -* ",
      " *+  p  )s   (* ",
      " pppppppppppppp ",
      "                "
    ],
    [
      "                ",
      "      A>*****`? ",
      "  \u038f\u038e\u0374ip \u038c\u038a\u038a\u038a\u0389 * ",
      "  i \u0388ep       * ",
      "  i   p       * ",
      "  \u0374   A     t\u0387> ",
      " AppAp     App? ",
      " *  \u0386      \u0385  * ",
      " *  A      p  * ",
      " pppppp\u0384A\u037fpppp' ",
      " p      p     p ",
      " *\u037e  FFFp}   \u037d* ",
      " *\u037c  p   }   \u037b* ",
      " *\u037a  p\u0377 \u0376s   \u0375* ",
      " Ap**pp**pp**pp ",
      "                "
    ],
    [
      "                ",
      "      p`>`>>``? ",
      "  \u0374&&kA       > ",
      "  \u0395  \u0394A       > ",
      "  \u038e  \u0393p   \u0392   > ",
      "  \u038e   p       > ",
      " ppppA     ppp? ",
      " `  p      p  > ",
      " `  p      A  > ",
      " ppppppppppppp? ",
      " A      p     p ",
      " `   FFFp}    > ",
      " >   p   s    ` ",
      " >  tpt  }    ` ",
      " Ap\u0390\u0390pp\u0391\u0390pp\u0390\u0390pp ",
      "                "
    ],
    [
      "                ",
      "      AAppApApA ",
      "  \u0374\u0374iipiiiiiiip ",
      "  i   Aiiiiiiip ",
      "  i  \u0398piiiiiiip ",
      "  i  epiiiiiiiA ",
      " ApApp\u0397iiiiiiip ",
      " Aiipiiiiiii\u0396\u0396p ",
      " Aiipiiiiiii\u0396\u0396A ",
      " Appppppppppppp ",
      " piiiiiiiiiiiip ",
      " piiiiiiiiiiiip ",
      " piiii\u0396\u0396\u0396iiiiip ",
      " piiii\u0396\u0396\u0396iiiiip ",
      " pApppppppppppA ",
      "                "
    ],
    [
      "                ",
      "       bbbaaaaa ",
      "  lnm\u0374ddddddddb ",
      "  \u039d   dddddddda ",
      "  k\u039c  dddddddda ",
      "  i\u039b\u039a\u0399dddddddda ",
      " bdddddddddddda ",
      "  dddddddddeeea ",
      " adddddddddeeea ",
      " adddddddddddda ",
      " adddddddddddda ",
      " adddddddddddda ",
      " bddddeeeddddda ",
      " addddeeeddddda ",
      " bbabaaaaaaaaba ",
      "                "
    ],
    [
      "                ",
      "      Apppppppp ",
      "   \u0374&&p^ 4 $#9p ",
      "  \u0374\u03ad  S7 4  t\u03acp ",
      "  \u0374\u03ab  A5 4 1 tp ",
      "  i   A2   10Zp ",
      " Ap\u03aaASYXXW Appp ",
      " p  I      \u03a9 \u03a8p ",
      " ATTp\u03a7    Rpwtp ",
      " pppppp\u03a6A ppppp ",
      " pPON   pI LKJp ",
      " p\u03a5  FD\u03a4psI \u03a3Bp ",
      " p\u03a1\u039e p   \u03a0 CC\u039fp ",
      " p\u039eyxpwu sqrrqp ",
      " pppppppppppppp ",
      "                "
    ],
    [
      "                ",
      "      p\u03bc* ***>? ",
      "   \u03bb\u0374iA       ` ",
      "  \u03baf\u03b9 A       ` ",
      "  \u03b8 \u03b7 p       > ",
      "  n   A     /!? ",
      " Ap\u03b6AA\u03b5    App? ",
      " \u03b4         \u03b3  > ",
      " A \u03b2p   ,  A  > ",
      " AppppA\u03b1p pppp? ",
      " p\u03b0  ;  p ; \u03af p ",
      " *   \u03a4[Fps    * ",
      " *   A   \u03ae    * ",
      " *   p  )s    * ",
      " pppppppppppppp ",
      "                "
    ],
    [
      "                ",
      "      A`*** *\u03bc' ",
      "    \u03ba\u0374p       * ",
      "  \u03bd f8A       * ",
      "  i \u03b7 p       * ",
      "  \u0374   p      \u0387> ",
      " SpApA     ppp? ",
      "    \u0386      A  * ",
      " *  A      p\u0377 * ",
      " pppppp\u0384p\u0384Appp' ",
      " p      p     p ",
      " *   FFFps    * ",
      " *   p   s    * ",
      " *   A\u0377 \u0376s    * ",
      " pp**pp**pp**pp ",
      "                "
    ],
    [
      "                ",
      "      S>`' \u03be>`' ",
      "    \u03b8\u039dA       ` ",
      "  \u0395   p       > ",
      "  \u03bf \u03b7gp   \u0392   > ",
      "  \u038e   A       > ",
      " SAppp     ppA' ",
      " `  p      p  > ",
      " >  p      pt > ",
      " ApppAppAppppp' ",
      " p      p     p ",
      " `   \u03a4FFps    ` ",
      " >   p   s    > ",
      " \u03be   p   s    > ",
      " \u037fp\u0390\u0391pp\u0390\u0390pp\u0390\u0390pp ",
      "                "
    ],
    [
      "                ",
      "      ApAApppAp ",
      "    \u0374iAiiiiiiiA ",
      "      piiiiiiip ",
      "  \u03c3 \u03b7 Aiiiiiiip ",
      "  i \u03c2fAiiiiiiip ",
      " \u03c1\u03c0ApAiiiiiiiip ",
      " Siipiiiiiii\u0396\u0396p ",
      " Aiipiiiiiii\u0396\u0396p ",
      " Appppppppppppp ",
      " Aiiiiiiiiiiiip ",
      " piiiiiiiiiiiip ",
      " Aiiii\u0396\u0396\u0396iiiiip ",
      " piiii\u0396\u0396\u0396iiiiip ",
      " AApppppppppppp ",
      "                "
    ],
    [
      "                ",
      "      cbbbbaaaa ",
      "    \u039diddddd\u03c5\u03ca\u03c9a ",
      "      dddddd\u03c5\u03c6b ",
      "  \u03bd\u03c8\u03b7 dddd\u03c5d\u03c6\u03c5a ",
      "  \u03748  ddd\u03c7dd\u03c5db ",
      "  d\u03c6dddddddddda ",
      "  \u03c5\u03c5dddddddeeea ",
      " c\u03c5ddddddddeeea ",
      "  dddddddddddda ",
      " cdddddddddddda ",
      " bddddddddddddb ",
      " adddd\u03c4\u03c4\u03c4dddddb ",
      " adddd\u03c4\u03c4\u03c4ddddda ",
      " caaaaaaaaaaabb ",
      "                "
    ],
    [
      "                ",
      "      ASAApAppp ",
      "    l\u03b8A^\u03fd\u03fc\u03fb \u03f6 p ",
      "      A7\u03f9\u03f6\u03fa\u03f9 \u03d2p ",
      "   \u03f8\u03f7 S5\u03f6    \u03f5p ",
      "  \u03ba   A\u03f4 \u03f3 \u03f2\u03f1\u03f0p ",
      " \u03c0S\u03efAS\u03e8  \u03ee ApAp ",
      " S\u03ed\u03ed9\u03ec\u03eb\u03ea   \u03e9\u03e1\u03e1p ",
      " AITp\u03e8\u03e7\u03e6\u03e5 \u03e4\u03e3\u03e2\u03e1p ",
      " pSAppA\u03e0  \u03df\u03deApp ",
      " A\u03dd\u03dc\u03db\u03da     LKJp ",
      " \u03c0\u039e  \u03a4\u03d2R\u03d9}  \u03d8\u03d7p ",
      " S\u03d6\u03d5\u03d4A\u03cd\u03cd\u03cd\u03d3\u03d2\u03d1\u03d0\u03cbp ",
      " A\u03cf\u03cf\u03ceS\u03cd\u03cd\u03cds\u03cc\u03cc\u03cc\u03cbp ",
      " pppppppppppppp ",
      "                "
    ],
    [
      "                ",
      "      S?*****?' ",
      "     \u0412p\u0411\u03fd\u03fd    ` ",
      "    \u0410 A\u040f      ? ",
      "      A\u040e     \u03f1> ",
      "  n   S      \u03f0\u03be ",
      " \u03c9S AS\u040d    pAp? ",
      " \u03c0  t\u040c        > ",
      " S tA\u040b        > ",
      " AAApS\u040a\u0409   AAp? ",
      " S\u0404        \u0408\u0407\u0406p ",
      " *\u0404  F  \u03a4    \u0405* ",
      " *\u0404 \u03b0p\u0403      \u0402* ",
      " *\u03d5\u0401\u03d4A  )s\u0400\u03cc\u03ff\u03fe* ",
      " ApAppppppppppp ",
      "                "
    ],
    [
      "                ",
      "      A' ****'\u041c ",
      "     \u03bbA\u03fd\u03fd\u03fd      ",
      "    \u0410hA       * ",
      "      A       * ",
      "  \u0374   p       ` ",
      "  \u03c0ApA     AAp? ",
      "    \u041b\u041a     \u0419  * ",
      " t tA      A  * ",
      " AApSA    \u0418\u03depA? ",
      " \u03c0            p ",
      "  \u0404  F\u03a4 A    \u0417* ",
      " *\u0404  A   }   \u0416* ",
      " *\u0415\u0415\u0415p\u0414 \u0376s   \u0413* ",
      " Sp *pp**pp**pp ",
      "                "
    ],
    [
      "                ",
      "      S\u03bc'`>`?   ",
      "     \u03bb\u03c0 \u03fd       ",
      "     \u0394S       ' ",
      "     \u041fS   \u041e   \u03bc ",
      "  \u03bf   A       ` ",
      "  SAAp     ppp? ",
      " \u03be tAR     A  > ",
      "  t!p      p  > ",
      " SpASS\u041d\u0419\u0419pAppp? ",
      " A      A     p ",
      " ?\u0404  F\u03a4\u03a4p}    > ",
      " >   p   s    > ",
      " > \u0415 p   s    > ",
      " \u03c0A\u0391\u0390pp\u0390\u0390pp\u0390\u0390pA ",
      "                "
    ],
    [
      "                ",
      "      \u03c1SAApASAS ",
      "      \u0422\u03ba\u0374i\u0374ii\u0374A ",
      "      b\u03c9\u03ba\u0374\u0374ii\u0374A ",
      "     \u0398A\u03ba\u0420\u0421iiiip ",
      "  \u03bd  8A\u0374\u0420 \u03baiiip ",
      " \u0419AAAp\u0374i\u03ba\u0374\u03baiiip ",
      " Aiipiii\u03baiii\u0396\u0396p ",
      " Siipiiiiiii\u0396\u0396p ",
      " Appppppppppppp ",
      " Aiiiiiiiiiiiip ",
      " piiiiiiiiiiiip ",
      " Aiiii\u0396\u0396\u0396iiiiip ",
      " \u03c0iiii\u0396\u0396\u0396iiiiiA ",
      " \u03c9AAApppppppAAp ",
      "                "
    ],
    [
      "                ",
      "         cbab   ",
      "      \u03bb\u0374\u03b8iii\u0374\u03bab ",
      "       \u03c9\u03c9\u03ca\u03c5ddib ",
      "      \u03c9\u03ca\u03c9\u0425\u03c6\u0426dib ",
      "  \u03bd  \u0398d\u03c6\u0425 \u0424\u03c5dia ",
      "  \u0374dd\u03c6d\u03c6\u0423\u03ca\u03c5dd\u03bfa ",
      " c\u0374d\u03c5d\u03c5d\u03c6\u03c5dddia ",
      " bidddd\u03c5dddddia ",
      " biddddddddddia ",
      " aiddddddddddia ",
      " biddddddddddia ",
      " biddddddddddib ",
      " ciiiiiiiiiiiia ",
      "   baaaaaaaaabb ",
      "                "
    ],
    [
      "                ",
      "                ",
      "       \u0431\u0395\u038ei\u0374ii  ",
      "             i  ",
      "      S    \u0426 \u0374  ",
      "      A\u0430   \u0426 \u042f  ",
      "  \u042epS p    \u0426 \u038e  ",
      "  \u042d        \u0426\u042c\u038e  ",
      "  \u03b8        \u0426 \u0429  ",
      "  &        \u0426 i  ",
      "  i       \u042b! i  ",
      "  i\u0426\u0426\u0426\u0426\u0426\u0426\u0426\u042b\u042b &  ",
      "  \u038e \u042a  \u042a     &  ",
      "  \u0429\u0427&&i\u038e\u0428ii\u0427\u03b8\u03b8  ",
      "                ",
      "                "
    ],
    [
      "                ",
      "                ",
      "       \u03ba\u0374\u0374\u0427&&i  ",
      "             \u038e  ",
      "      b      \u038e  ",
      "      A      i  ",
      "   Sb A      i  ",
      "  \u0374          i  ",
      "  \u0374          \u0374  ",
      "  \u0374          i  ",
      "  \u03ba       \u042b\u042b i  ",
      "  \u03b8       \u042b\u042b i  ",
      "  i          i  ",
      "  iiii\u0374ii\u03b8\u03b8&ii  ",
      "                ",
      "                "
    ],
    [
      "                ",
      "                ",
      "         \u03b8\u0374iii  ",
      "             \u0374  ",
      "             i  ",
      "             i  ",
      "             i  ",
      "             i  ",
      "  \u0374          \u038e  ",
      "  \u042f          \u0395  ",
      "  \u0395       \u0432\u0432 \u038e  ",
      "  \u03bf       \u0432\u0432 i  ",
      "  \u038e          \u03b8  ",
      "  iii\u0395\u038e\u0428\u03b8\u03b8iii\u0374  ",
      "                ",
      "                "
    ]
  ]
}