{
  "name": "building_apartmentsmallabroken_ground",
  "refpalette": "deceasedcraft:building_apartmentsmallabroken/building_apartmentsmallabroken_ground_palette",
  "xsize": 16,
  "zsize": 16,
  "slices": [
    [
      "abbaaaaaaaabaaaa",
      "accccccccccccccb",
      "accccccddccccccb",
      "bccccccddcccccca",
      "acccccccccccccca",
      "acccccccccccccca",
      "bccccccccccccccb",
      "ecccccccccccccca",
      "bcccccccfcccccca",
      "accccccgccccccca",
      "bcccccgcgfhhhiab",
      "accccccgfghjhika",
      "acccccccgclhhiaa",
      "accccccccciiiibk",
      "accccccccckaakaa",
      "aaaaaaaaakaabaaa"
    ],
    [
      "                ",
      " mmmnnnnmnoomom ",
      "     pn qm  r   ",
      " s  tpnu nwxx s ",
      " s   pm ymwAxBs ",
      " nCD  mE  wAFBs ",
      " Il        JJ s ",
      "         K y  sE",
      "          L  Ls ",
      " IM      momomnN",
      " sODP    Q Q RSu",
      " sT       Q! UV ",
      " sW  X S n  QiYZ",
      " s  0112 mVVii V",
      " sss sss3n4 567 ",
      "      E7 VZ86Z 9"
    ],
    [
      "                ",
      " nmnnnnnnmmmumn ",
      "     #m  o    s ",
      " s   #n  m    s ",
      " s   #n  m    s ",
      " m$   m       s ",
      " %M           s ",
      "              s ",
      "              s ",
      " I^      mnmmmn ",
      " s&*         (  ",
      " s           )  ",
      " s       m   i  ",
      " s       nUiUi  ",
      "  ssssss3n      ",
      "                "
    ],
    [
      "                ",
      " nnssnmssnms nn ",
      " s   #n  m    s ",
      " s   #n  n    s ",
      " s   #nm+n    s ",
      " n$   n       s ",
      " %^           s ",
      "                ",
      " -            s ",
      " %^      mnnmnn ",
      " s&      +   i  ",
      " s       [   i  ",
      " s       mM] U  ",
      "         mii{}  ",
      "  ssssss|n      ",
      "                "
    ],
    [
      "                ",
      " nn;;nn:;nn;:nm ",
      " |   'n  n    3 ",
      " |    n  n    3 ",
      " 3    nnnm    3 ",
      " n<   n  n    | ",
      " %^      >    | ",
      "  ,      .    3 ",
      "  M      m    | ",
      " %^      nmnmom ",
      " 3?      m   /  ",
      " 3       m   {  ",
      " 3       n`  {  ",
      " |       m\u0370))i  ",
      " \u03713|333|\u0372m      ",
      "                "
    ],
    [
      "                ",
      " nnnnnnnnnnnnmm ",
      " niiiin\u0373\u0373niiiin ",
      " niiiin\u0373\u0373niiiin ",
      " niiiinnnniiiin ",
      " niiiiniiniiiin ",
      " niiiiiiiniiiim ",
      " niii\u0374\u0374iiniiiin ",
      " niii\u0374\u0374iiniiiin ",
      " niiiiiiinnnnnm ",
      " niiiiiiinM\u0375 i  ",
      " niiiiiiin\u0376  i  ",
      " miiiiiiim   i  ",
      " niiiiiiimUUii  ",
      " mmnnmmnmm      ",
      "                "
    ]
  ]
}