{
  "name": "building_apartmentsmallabroken_top",
  "refpalette": "deceasedcraft:building_apartmentsmallabroken/building_apartmentsmallabroken_top_palette",
  "xsize": 16,
  "zsize": 16,
  "slices": [
    [
      "                ",
      " aaaaaaaaaaab c ",
      " bdddddeeeddddb ",
      " adddddeeedddda ",
      " adddddddddddda ",
      " addddddddddddb ",
      " adddddddddddda ",
      " aeeeddddddddda ",
      " aeeeddddddddda ",
      " adddddddddddda ",
      " addddddddfghi  ",
      " adddddddd  jk  ",
      " adddddddd   k  ",
      " addddddddlmno  ",
      " baabaaaab      ",
      "                "
    ],
    [
      "                ",
      " pppppppppppppp ",
      " pqrrqstuwpxytp ",
      " ABCC D   p   p ",
      " pE   spFIF   p ",
      " pJKLM p   NOPp ",
      " ppppAQp AApppp ",
      " p~ p    R STTp ",
      " pU~       V  A ",
      " pppp WXXYAA pp ",
      " pZ01   2S   i  ",
      " p 31 4 5p  6i  ",
      " p3   4 7A  8i  ",
      " p9#$ 4%^p&&ii  ",
      " ppppAAppp      ",
      "                "
    ],
    [
      "                ",
      " pppppppppppppp ",
      " *(   s)  p  +* ",
      " *-   [   p  ]* ",
      " *{   }pF F  |* ",
      " pt  ; A     :p ",
      " 'pppp<p pApppA ",
      " >  p  ,   A! A ",
      " >         .  p ",
      " ?pAA    RAp pp ",
      " > /     A   n  ",
      " >       A   &  ",
      " `       p  \u0370i  ",
      " > \u0371\u0372\u0372\u0372\u0373tpiii\u0374  ",
      " '>*****>p      ",
      "                "
    ],
    [
      "                ",
      " pp**pp**pp**pA ",
      " *\u0375   s\u0376 \u0377p  \u037a* ",
      " *\u037b   }   p  \u037c* ",
      " *\u037d   }pFFF  \u037e* ",
      " p     p      p ",
      " 'pppp\u037fA\u0384pppppp ",
      " *  p      A  * ",
      " *  \u0385      \u0386  * ",
      " ?ppA     pAppA ",
      " >\u0387t     A   \u0374  ",
      " *       p   i  ",
      " *       pe\u0388 i  ",
      " * \u0389\u038a\u038a\u038a\u038c pi\u0374\u038e\u038f  ",
      " ?`*****>A      ",
      "                "
    ],
    [
      "                ",
      " pp\u0390\u0390pp\u0390\u0391pp\u0390\u0390pA ",
      " `    }  tpt  > ",
      " `    s   p   > ",
      " >    }pFFF   ` ",
      " p     p      A ",
      " ?ppppppppppppp ",
      " >  A      p  ` ",
      " >  p      p  ` ",
      " ?ppp     Apppp ",
      " >       p   \u038e  ",
      " >   \u0392   p\u0393  \u038e  ",
      " >       A\u0394  \u0395  ",
      " >       Ak&&\u0374  ",
      " ?``>>`>`p      ",
      "                "
    ],
    [
      "                ",
      " ApppppppppppAp ",
      " piiiii\u0396\u0396\u0396iiiip ",
      " piiiii\u0396\u0396\u0396iiiip ",
      " piiiiiiiiiiiip ",
      " piiiiiiiiiiiip ",
      " pppppppppppppA ",
      " A\u0396\u0396iiiiiiipiiA ",
      " p\u0396\u0396iiiiiiipiiA ",
      " piiiiiii\u0397ppApA ",
      " Aiiiiiiipe  i  ",
      " piiiiiiip\u0398  i  ",
      " piiiiiiiA   i  ",
      " piiiiiiipii\u0374\u0374  ",
      " ApApAppAA      ",
      "                "
    ],
    [
      "                ",
      " abaaaaaaaababb ",
      " adddddeeedddda ",
      " adddddeeeddddb ",
      " adddddddddddda ",
      " adddddddddddda ",
      " adddddddddddda ",
      " aeeeddddddddda ",
      " aeeeddddddddd  ",
      " addddddddddddb ",
      " adddddddd\u0399\u039a\u039bi  ",
      " adddddddd  \u039ck  ",
      " adddddddd   \u039d  ",
      " bdddddddd\u0374mnl  ",
      " aaaaabbb       ",
      "                "
    ],
    [
      "                ",
      " pppppppppppppp ",
      " pqrrqs uwpxy\u039ep ",
      " p\u039fCC \u03a0   p \u039e\u03a1p ",
      " pB\u03a3 Isp\u03a4DF  \u03a5p ",
      " pJKL Ip   NOPp ",
      " ppppp A\u03a6pppppp ",
      " ptwpR    \u03a7pTTA ",
      " p\u03a8 \u03a9      I  p ",
      " pppA WXXYSA\u03aapA ",
      " pZ01   2A   i  ",
      " pt 1 4 5A  \u03ab\u0374  ",
      " p\u03act  4 7S  \u03ad\u0374  ",
      " p9#$ 4 ^p&&\u0374   ",
      " ppppppppA      ",
      "                "
    ],
    [
      "                ",
      " pppppppppppppp ",
      " *    s)  p   * ",
      " *    \u03ae   A   * ",
      " *    spF[\u03a4   * ",
      " p \u03af ; p  ;  \u03b0p ",
      " ?pppp p\u03b1AppppA ",
      " >  A  ,   p\u03b2 A ",
      " >  \u03b3         \u03b4 ",
      " ?ppA    \u03b5AA\u03b6pA ",
      " ?!/     A   n  ",
      " >       p \u03b7 \u03b8  ",
      " `       A \u03b9f\u03ba  ",
      " `       Ai\u0374\u03bb   ",
      " ?>*** *\u03bcp      ",
      "                "
    ],
    [
      "                ",
      " pp**pp**pp**pp ",
      " *    s\u0376 \u0377A   * ",
      " *    s   p   * ",
      " *    spFFF   * ",
      " p     p      p ",
      " 'pppA\u0384p\u0384pppppp ",
      " * \u0377p      A  * ",
      " *  A      \u0386    ",
      " ?ppp     ApApS ",
      " >\u0387      p   \u0374  ",
      " *       p \u03b7 i  ",
      " *       A8f \u03bd  ",
      " *       p\u0374\u03ba    ",
      " '\u03bc* ***`A      ",
      "                "
    ],
    [
      "                ",
      " pp\u0390\u0390pp\u0390\u0390pp\u0391\u0390p\u037f ",
      " >    s   p   \u03be ",
      " >    s   p   > ",
      " `    spFF\u03a4   ` ",
      " p     p      p ",
      " 'pppppAppApppA ",
      " > tp      p  > ",
      " >  p      p  ` ",
      " 'App     pppAS ",
      " >       A   \u038e  ",
      " >   \u0392   pg\u03b7 \u03bf  ",
      " >       p   \u0395  ",
      " `       A\u039d\u03b8    ",
      " '`>\u03be '`>S      ",
      "                "
    ],
    [
      "                ",
      " ppppppppppppAA ",
      " piiiii\u0396\u0396\u0396iiiip ",
      " piiiii\u0396\u0396\u0396iiiiA ",
      " piiiiiiiiiiiip ",
      " piiiiiiiiiiiiA ",
      " pppppppppppppA ",
      " p\u0396\u0396iiiiiiipiiA ",
      " p\u0396\u0396iiiiiiipiiS ",
      " piiiiiiiiApA\u03c0\u03c1 ",
      " piiiiiiiAf\u03c2 i  ",
      " piiiiiiiA \u03b7 \u03c3  ",
      " piiiiiiip      ",
      " AiiiiiiiAi\u0374    ",
      " pApppAApA      ",
      "                "
    ],
    [
      "                ",
      " bbaaaaaaaaaaac ",
      " addddd\u03c4\u03c4\u03c4dddda ",
      " bddddd\u03c4\u03c4\u03c4dddda ",
      " bddddddddddddb ",
      " addddddddddddc ",
      " adddddddddddd  ",
      " aeeedddddddd\u03c5c ",
      " aeeeddddddd\u03c5\u03c5  ",
      " adddddddddd\u03c6d  ",
      " bd\u03c5dd\u03c7ddd  8\u0374  ",
      " a\u03c5\u03c6d\u03c5dddd \u03b7\u03c8\u03bd  ",
      " b\u03c6\u03c5dddddd      ",
      " a\u03c9\u03ca\u03c5dddddi\u039d    ",
      " aaaabbbbc      ",
      "                "
    ],
    [
      "                ",
      " pppppppppppppp ",
      " p\u03cb\u03cc\u03cc\u03ccs\u03cd\u03cd\u03cdS\u03ce\u03cf\u03cfA ",
      " p\u03cb\u03d0\u03d1\u03d2\u03d3\u03cd\u03cd\u03cdA\u03d4\u03d5\u03d6S ",
      " p\u03d7\u03d8  }\u03d9R\u03d2\u03a4  \u039e\u03c0 ",
      " pJKL     \u03da\u03db\u03dc\u03ddA ",
      " ppA\u03de\u03df  \u03e0AppASp ",
      " p\u03e1\u03e2\u03e3\u03e4 \u03e5\u03e6\u03e7\u03e8pTIA ",
      " p\u03e1\u03e1\u03e9   \u03ea\u03eb\u03ec9\u03ed\u03edS ",
      " pApA \u03ee  \u03e8SA\u03efS\u03c0 ",
      " p\u03f0\u03f1\u03f2 \u03f3 \u03f4A   \u03ba  ",
      " p\u03f5    \u03f65S \u03f7\u03f8   ",
      " p\u03d2 \u03f9\u03fa\u03f6\u03f97A      ",
      " p \u03f6 \u03fb\u03fc\u03fd^A\u03b8l    ",
      " pppApAASA      ",
      "                "
    ],
    [
      "                ",
      " pppppppppppApA ",
      " *\u03fe\u03ff\u03cc\u0400s)  A\u03d4\u0401\u03d5* ",
      " *\u0402      \u0403p\u03b0 \u0404* ",
      " *\u0405    \u03a4  F  \u0404* ",
      " p\u0406\u0407\u0408        \u0404S ",
      " ?pAA   \u0409\u040aSpAAA ",
      " >        \u040bAt S ",
      " >        \u040ct  \u03c0 ",
      " ?pAp    \u040dSA S\u03c9 ",
      " \u03be\u03f0      S   n  ",
      " >\u03f1     \u040eA      ",
      " ?      \u040fA \u0410    ",
      " `    \u03fd\u03fd\u0411p\u0412     ",
      " '?*****?S      ",
      "                "
    ],
    [
      "                ",
      " pp**pp**pp* pS ",
      " *\u0413   s\u0376 \u0414p\u0415\u0415\u0415* ",
      " *\u0416   }   A  \u0404* ",
      " *\u0417    A \u03a4F  \u0404  ",
      " p            \u03c0 ",
      " ?Ap\u03de\u0418    ASpAA ",
      " *  A      At t ",
      " *  \u0419     \u041a\u041b    ",
      " ?pAA     ApA\u03c0  ",
      " `       p   \u0374  ",
      " *       A      ",
      " *       Ah\u0410    ",
      "      \u03fd\u03fd\u03fdA\u03bb     ",
      " \u041c'**** 'A      ",
      "                "
    ],
    [
      "                ",
      " Ap\u0390\u0390pp\u0390\u0390pp\u0390\u0391A\u03c0 ",
      " >    s   p \u0415 > ",
      " >    s   p   > ",
      " >    }p\u03a4\u03a4F  \u0404? ",
      " p     A      A ",
      " ?pppAp\u0419\u0419\u041dSSApS ",
      " >  p      p!t  ",
      " >  A     RAt \u03be ",
      " ?ppp     pAAS  ",
      " `       A   \u03bf  ",
      " \u03bc   \u041e   S\u041f     ",
      " '       S\u0394     ",
      "       \u03fd \u03c0\u03bb     ",
      "   ?`>`'\u03bcS      ",
      "                "
    ],
    [
      "                ",
      " pAApppppppAAA\u03c9 ",
      " Aiiiii\u0396\u0396\u0396iiii\u03c0 ",
      " piiiii\u0396\u0396\u0396iiiiA ",
      " piiiiiiiiiiiip ",
      " piiiiiiiiiiiiA ",
      " pppppppppppppA ",
      " p\u0396\u0396iiiiiiipiiS ",
      " p\u0396\u0396iii\u03baiiipiiA ",
      " piii\u03ba\u0374\u03bai\u0374pAAA\u0419 ",
      " piii\u03ba \u0420\u0374A8  \u03bd  ",
      " piiii\u0421\u0420\u03baA\u0398     ",
      " A\u0374ii\u0374\u0374\u03ba\u03c9b      ",
      " A\u0374ii\u0374i\u0374\u03ba\u0422      ",
      " SASApAAS\u03c1      ",
      "                "
    ],
    [
      "                ",
      " bbaaaaaaaaab   ",
      " aiiiiiiiiiiiic ",
      " biddddddddddib ",
      " aiddddddddddib ",
      " aiddddddddddia ",
      " aiddddddddddib ",
      " aiddddd\u03c5ddddib ",
      " aiddd\u03c5\u03c6d\u03c5d\u03c5d\u0374c ",
      " a\u03bfdd\u03c5\u03ca\u0423\u03c6d\u03c6dd\u0374  ",
      " aid\u03c5\u0424 \u0425\u03c6d\u0398  \u03bd  ",
      " bid\u0426\u03c6\u0425\u03c9\u03ca\u03c9      ",
      " bidd\u03c5\u03ca\u03c9\u03c9       ",
      " b\u03ba\u0374iii\u03b8\u0374\u03bb      ",
      "   babc         ",
      "                "
    ],
    [
      "                ",
      "                ",
      "  \u03b8\u03b8\u0427ii\u0428\u038ei&&\u0427\u0429  ",
      "  &     \u042a  \u042a \u038e  ",
      "  & \u042b\u042b\u0426\u0426\u0426\u0426\u0426\u0426\u0426i  ",
      "  i !\u042b       i  ",
      "  i \u0426        &  ",
      "  \u0429 \u0426        \u03b8  ",
      "  \u038e\u042c\u0426        \u042d  ",
      "  \u038e \u0426    p Sp\u042e  ",
      "  \u042f \u0426   \u0430A      ",
      "  \u0374 \u0426    S      ",
      "  i             ",
      "  ii\u0374i\u038e\u0395\u0431       ",
      "                ",
      "                "
    ],
    [
      "                ",
      "                ",
      "  ii&\u03b8\u03b8ii\u0374iiii  ",
      "  i          i  ",
      "  i \u042b\u042b       \u03b8  ",
      "  i \u042b\u042b       \u03ba  ",
      "  i          \u0374  ",
      "  \u0374          \u0374  ",
      "  i          \u0374  ",
      "  i      A bS   ",
      "  i      A      ",
      "  \u038e      b      ",
      "  \u038e             ",
      "  i&&\u0427\u0374\u0374\u03ba       ",
      "                ",
      "                "
    ],
    [
      "                ",
      "                ",
      "  \u0374iii\u03b8\u03b8\u0428\u038e\u0395iii  ",
      "  \u03b8          \u038e  ",
      "  i \u0432\u0432       \u03bf  ",
      "  \u038e \u0432\u0432       \u0395  ",
      "  \u0395          \u042f  ",
      "  \u038e          \u0374  ",
      "  i             ",
      "  i             ",
      "  i             ",
      "  i             ",
      "  \u0374             ",
      "  iii\u0374\u03b8         ",
      "                ",
      "                "
    ]
  ]
}