{
  "name": "building_apartmentsmallabroken_top_90",
  "refpalette": "deceasedcraft:building_apartmentsmallabroken/building_apartmentsmallabroken_top_palette_90",
  "xsize": 16,
  "zsize": 16,
  "slices": [
    [
      "                ",
      " cbaabaaaa      ",
      "  ddddddddikko  ",
      " bddddddddhj n  ",
      " addddddddg  m  ",
      " addddddddf  l  ",
      " aeeddddddddddb ",
      " aeedddddddddda ",
      " aeedddddddddda ",
      " adddddddddddda ",
      " adddddddddddda ",
      " adddddeedddddb ",
      " adddddeeddddda ",
      " adddddeeddddda ",
      " abaaaaaaaaaaab ",
      "                "
    ],
    [
      "                ",
      " pppppppAp      ",
      " pt  PpT piiii  ",
      " py  OpT   68i  ",
      " px  NpSVA   &  ",
      " pppF A  A   &  ",
      " pw I AR YSpApp ",
      " pu F    X257^p ",
      " pt ppp  X   %p ",
      " psDs Q  W 444A ",
      " pq  MA       A ",
      " prC Lpp p11 $p ",
      " prC Kp ~p03 #p ",
      " pqBEJp~UpZ 39p ",
      " ppAppppppppppp ",
      "                "
    ],
    [
      "                ",
      " p***pAApp      ",
      " p+]|:p  pn&i\u0374  ",
      " p    p!    \u0370i  ",
      " p    pA.p   i  ",
      " pppF A  A   i  ",
      " p    p  RAAppp ",
      " p  F        t> ",
      " p) pAp,     \u0373* ",
      " ps[} <      \u0372* ",
      " p   ;p      \u0372* ",
      " p    pp A   \u0372* ",
      " p    p  A/  \u0371* ",
      " p(-{tp  p    > ",
      " p***p'>>?>>`>' ",
      "                "
    ],
    [
      "                ",
      " A***pp**A      ",
      " p\u037a\u037c\u037e p  p\u0374ii\u038f  ",
      " *    p  p   \u038e  ",
      " *    pA\u0386A  \u0388\u0374  ",
      " pppF p  p  ei  ",
      " p\u0377 F p   ApppA ",
      " *  F \u0384       > ",
      " *\u0376 ppA      \u038c* ",
      " ps}} \u037f      \u038a* ",
      " p    p      \u038a* ",
      " *    pp\u0385A   \u038a* ",
      " *    p  pt  \u0389* ",
      " p\u0375\u037b\u037d p  p\u0387   ` ",
      " p***p'**?>***? ",
      "                "
    ],
    [
      "                ",
      " A>>`Ap``p      ",
      " p    p  p\u038e\u038e\u0395\u0374  ",
      " \u0390    p  p   &  ",
      " \u0390t   pppp   &  ",
      " pppF p  A \u0393\u0394k  ",
      " pt F p   ppAAp ",
      " \u0391  F p       ` ",
      " \u0390  ppp       > ",
      " p}s} p       ` ",
      " p    p    \u0392  > ",
      " \u0390    pApp    > ",
      " \u0390    p  p    ` ",
      " p    p  p    ` ",
      " p``>p?>>?>>>>? ",
      "                "
    ],
    [
      "                ",
      " pppppAAAA      ",
      " Aiiiipiipiii\u0374  ",
      " piiiipiiA   \u0374  ",
      " piiiipppp   i  ",
      " piiiipiipe\u0398 i  ",
      " p\u0396\u0396iipii\u0397ppApA ",
      " p\u0396\u0396iipiiiiiiiA ",
      " p\u0396\u0396iipiiiiiiip ",
      " piiiipiiiiiiip ",
      " piiiipiiiiiiiA ",
      " piiiipiiiiiiip ",
      " piiiip\u0396\u0396iiiiiA ",
      " piiiip\u0396\u0396iiiiip ",
      " ApppppAppApppA ",
      "                "
    ],
    [
      "                ",
      " babaaaa b      ",
      " bddddddddik\u039dl  ",
      " adddddddd\u039b\u039c n  ",
      " bdddddddd\u039a  m  ",
      " adddddddd\u0399  \u0374  ",
      " aeedddddddddd  ",
      " aeeddddddddddb ",
      " aeeddddddddddb ",
      " addddddddddddb ",
      " adddddddddddda ",
      " adddddeeddddda ",
      " adddddeeddddda ",
      " bdddddeeddddda ",
      " aaaaaaaaaaaaba ",
      "                "
    ],
    [
      "                ",
      " ppppppApA      ",
      " p\u039e\u03a1\u03a5PpT pi\u0374\u0374   ",
      " py\u039e OpT \u03aa \u03ab\u03ad\u0374  ",
      " px  NppIA   &  ",
      " pppF p\u03a7 S   &  ",
      " pw D p  YAASpA ",
      " pu \u03a4 \u03a6  X257^p ",
      " p  ppA  X    p ",
      " ps\u03a0sI   W 444p ",
      " pq I pR      p ",
      " prC Lpp\u03a9A11 $p ",
      " prC\u03a3Kpw p0 t#p ",
      " pq\u039fBJpt\u03a8pZt\u03ac9p ",
      " pppppppppppppp ",
      "                "
    ],
    [
      "                ",
      " p***pAA\u03b4A      ",
      " p   \u03b0p  pn\u03b8\u03ba   ",
      " p    p\u03b2 \u03b6  f\u03bb  ",
      " p    pp A \u03b7\u03b9\u0374  ",
      " ppA\u03a4;p  A   i  ",
      " p  [ A  \u03b5ApAAp ",
      " p  F \u03b1       \u03bc ",
      " p) ppp,      * ",
      " ps\u03aes           ",
      " p   ;p       * ",
      " p    pA\u03b3A    * ",
      " p   \u03afp  p/   * ",
      " p    p  p!   > ",
      " p***p?>>??>``? ",
      "                "
    ],
    [
      "                ",
      " p***pp* S      ",
      " p    p  p\u0374i\u03bd   ",
      " *    p  A      ",
      " *    pA\u0386p \u03b7f\u03ba  ",
      " pApF p  A  8\u0374  ",
      " p\u0377 F p   ppApA ",
      " *  F \u0384       ` ",
      " *\u0376 ppp       * ",
      " psss \u0384       * ",
      " p    A       * ",
      " *    ppAp      ",
      " *    p\u0377 p    * ",
      " p    p  p\u0387   \u03bc ",
      " p***p'**?>***' ",
      "                "
    ],
    [
      "                ",
      " \u037f\u03be>`pA>`S      ",
      " p    p  A\u038e\u03bf\u0395   ",
      " \u0390    p  p      ",
      " \u0391    pppp \u03b7 \u03b8  ",
      " ppp\u03a4 A  p g \u039d  ",
      " p  F p   AppAS ",
      " \u0390  F p       > ",
      " \u0390  ppA       ` ",
      " psss p       ' ",
      " p    p    \u0392    ",
      " \u0390    pppp    \u03be ",
      " \u0390    pt p    > ",
      " p    p  A    ` ",
      " p>>`p'>>'>>>`' ",
      "                "
    ],
    [
      "                ",
      " ApApAAAS\u03c1      ",
      " Aiiiipii\u03c0i\u03c3    ",
      " piiiipiiA      ",
      " piiiipppp\u03c2\u03b7 \u0374  ",
      " piiiipiiAf  i  ",
      " p\u0396\u0396iipiiiAApAA ",
      " p\u0396\u0396iipiiiiiiip ",
      " p\u0396\u0396iipiiiiiiiA ",
      " piiiipiiiiiiiA ",
      " piiiipiiiiiiip ",
      " piiiipiiiiiiip ",
      " piiiip\u0396\u0396iiiiip ",
      " piiiip\u0396\u0396iiiiiA ",
      " ppppppppppppAp ",
      "                "
    ],
    [
      "                ",
      " caabc c        ",
      " addddd\u03c5\u03c5d\u0374\u03bd    ",
      " adddddd\u03c5\u03c68\u03c8    ",
      " adddddddd \u03b7 \u039d  ",
      " adddddddd   i  ",
      " a\u03c4\u03c4ddddddddddc ",
      " a\u03c4\u03c4ddddddddddb ",
      " a\u03c4\u03c4ddddddddddb ",
      " adddddddd\u03c7dddb ",
      " addddddddd\u03c5ddb ",
      " adddddeedddd\u03c5a ",
      " adddddeed\u03c5\u03c6\u03c5\u03caa ",
      " bdddddeedd\u03c5\u03c6\u03c9a ",
      " babbaaaaababaa ",
      "                "
    ],
    [
      "                ",
      " pAS\u03c0ApAS\u03c0      ",
      " p\u03cf\u03d6\u039e\u03ddSI\u03edS\u03ba     ",
      " p\u03cf\u03d5 \u03dcAT\u03ed\u03ef \u03f8    ",
      " p\u03ce\u03d4 \u03dbpp9A \u03f7 l  ",
      " pSA\u03a4\u03dap\u03e8\u03ecS   \u03b8  ",
      " p\u03cd\u03cd\u03d2 A\u03e7\u03eb\u03e8ASAAA ",
      " p\u03cd\u03cdR \u03e0\u03e6\u03ea \u03f457^S ",
      " p\u03cd\u03cd\u03d9  \u03e5   \u03f6\u03f9\u03fdA ",
      " ps\u03d3}    \u03ee\u03f3 \u03f6\u03fcA ",
      " p\u03cc\u03d2  \u03df\u03e4    \u03fa\u03fbp ",
      " p\u03cc\u03d1 L\u03de\u03e3\u03e9A\u03f2 \u03f9 A ",
      " p\u03cc\u03d0\u03d8KA\u03e2\u03e1p\u03f1  \u03f6p ",
      " p\u03cb\u03cb\u03d7Jp\u03e1\u03e1A\u03f0\u03f5\u03d2 p ",
      " pppppppppppppp ",
      "                "
    ],
    [
      "                ",
      " A***SAS\u03c0\u03c9      ",
      " p\u03d5\u0404\u0404\u0404A  Sn     ",
      " A\u0401   At        ",
      " p\u03d4\u03b0  pAtA  \u0410   ",
      " pApF S\u040b\u040cS   \u0412  ",
      " p \u0403  \u040a  \u040dSAApS ",
      " p    \u0409    \u040e\u040f\u0411? ",
      " p) \u03a4        \u03fd* ",
      " ps          \u03fd* ",
      " p\u0400           * ",
      " p\u03cc  \u0408A  p    * ",
      " p\u03ff  \u0407A  A    * ",
      " p\u03fe\u0402\u0405\u0406p  p\u03f0\u03f1  ? ",
      " p***p?>>?\u03be>?`' ",
      "                "
    ],
    [
      "                ",
      " S** \u03c0At        ",
      " p\u0415\u0404\u0404 A  \u03c0\u0374     ",
      "  \u0415   pt A      ",
      " *\u0415   SA\u041bp  \u0410   ",
      " ppAF A \u041aA  h\u03bb  ",
      " p\u0414 \u03a4     pAAAA ",
      " *           \u03fd' ",
      " *\u0376 A        \u03fd  ",
      " ps}         \u03fd* ",
      " p    \u0418       * ",
      " *    \u03deA\u0419A    * ",
      " *    p  A    * ",
      " p\u0413\u0416\u0417 A  p    ' ",
      " p***p?**?`** \u041c ",
      "                "
    ],
    [
      "                ",
      " \u03c0>>?AS \u03be       ",
      " A  \u0404 pt S\u03bf     ",
      " \u0391\u0415   A!tA      ",
      " \u0390    SpAA      ",
      " pppF S Rp \u041f\u0394\u03bb  ",
      " p  \u03a4 \u041d   ASS\u03c0S ",
      " \u0390  \u03a4 \u0419       \u03bc ",
      " \u0390  pA\u0419      \u03fd' ",
      " pss} p       ` ",
      " p    A    \u041e  > ",
      " \u0390    ppAp    ` ",
      " \u0390    p  p    ? ",
      " p    p  p      ",
      " A>>>p?>>?`\u03bc'   ",
      "                "
    ],
    [
      "                ",
      " \u03c9\u03c0ApAASA\u0419      ",
      " AiiiipiiA\u03bd     ",
      " AiiiipiiA      ",
      " AiiiipppA      ",
      " piiiipiip8\u0398    ",
      " p\u0396\u0396iipii\u0374AAb\u0422\u03c1 ",
      " p\u0396\u0396iipiii\u0374\u03ba\u03c9\u03baS ",
      " p\u0396\u0396iipi\u03ba\u03ba\u0420\u0420\u03ba\u0374A ",
      " piiiipii\u0374 \u0421\u0374iA ",
      " piiiipii\u03ba\u03bai\u0374\u0374p ",
      " piiiipiiiiiiiA ",
      " Aiiiip\u0396\u0396iiiiiS ",
      " Aiiiip\u0396\u0396iii\u0374\u0374A ",
      " pApppppppppAAS ",
      "                "
    ],
    [
      "                ",
      "  cbbabbc       ",
      "  iiiiii\u0374\u0374\u03bd     ",
      " biddddddd      ",
      " aiddddd\u03c5d      ",
      " aidddddd\u03c6\u0398     ",
      " aiddddd\u03c5dd\u03c9 \u03bb  ",
      " aidddd\u03c5d\u03c6\u03c6\u03ca\u03c9\u0374  ",
      " aiddddd\u03c6\u0423\u0425\u03c9\u03c9\u03b8  ",
      " aiddddd\u03c5\u03ca \u0425\u03caic ",
      " aidddddd\u03c5\u0424\u03c6\u03c5ib ",
      " aiddddddd\u03c5\u0426dia ",
      " aidddddddddd\u0374b ",
      " biiiiiii\u03bfiii\u03ba  ",
      " babaaaaaaabbb  ",
      "                "
    ],
    [
      "                ",
      "                ",
      "  \u0429\u038eii&\u03b8\u042d\u042e      ",
      "  \u0427 \u0426    p      ",
      "  &\u042a\u0426    S      ",
      "  & \u0426           ",
      "  i \u0426    pAS    ",
      "  \u038e\u042a\u0426     \u0430  \u0431  ",
      "  \u0428 \u0426        \u0395  ",
      "  i \u0426        \u038e  ",
      "  i \u042b\u042b       i  ",
      "  \u0427 \u042b!\u0426\u0426\u0426\u0426\u0426\u0426 \u0374  ",
      "  \u03b8     \u042c    i  ",
      "  \u03b8&&ii\u0429\u038e\u038e\u042f\u0374ii  ",
      "                ",
      "                "
    ],
    [
      "                ",
      "                ",
      "  ii\u03b8\u03ba\u0374\u0374\u0374       ",
      "  i      S      ",
      "  i      b      ",
      "  i             ",
      "  \u0374      AAb    ",
      "  i          \u03ba  ",
      "  i          \u0374  ",
      "  \u03b8          \u0374  ",
      "  \u03b8 \u042b\u042b       \u0427  ",
      "  & \u042b\u042b       &  ",
      "  i          &  ",
      "  iiiii\u0374iii\u038e\u038ei  ",
      "                ",
      "                "
    ],
    [
      "                ",
      "                ",
      "  i\u038e\u03bf\u0395\u042f\u0374        ",
      "  i             ",
      "  i             ",
      "  \u0395             ",
      "  \u038e             ",
      "  \u0428             ",
      "  \u03b8             ",
      "  \u03b8          \u03b8  ",
      "  i \u0432\u0432       \u0374  ",
      "  i \u0432\u0432       i  ",
      "  i          i  ",
      "  \u0374\u03b8i\u038e\u0395\u038eiiii\u0374i  ",
      "                ",
      "                "
    ]
  ]
}