{
  "name": "building_apartmentsmallabroken_ground_90",
  "refpalette": "deceasedcraft:building_apartmentsmallabroken/building_apartmentsmallabroken_ground_palette_90",
  "xsize": 16,
  "zsize": 16,
  "slices": [
    [
      "abbaaabaaabaakaa",
      "acccccccccakabaa",
      "accccccccciiiika",
      "accccccccchhhiab",
      "bccccccccchjhiaa",
      "accccccccchhlika",
      "acccccccccfgccck",
      "acddccccfcgfgcca",
      "acddcccccgcgccca",
      "acccccccccgcccca",
      "acccccccccccccca",
      "acccccccccccccca",
      "acccccccccccccca",
      "bcccccccccccccca",
      "bcccccccccccccca",
      "aaabaabebabaaaaa"
    ],
    [
      "       E Nu ZV 9",
      " m ssssssnSVY 7 ",
      " o  BB  LmRUii6Z",
      " mrxxFJ  o  Qi56",
      " o xAAJy mQ! V 8",
      " o www  Lo Q V4Z",
      " nmnm  K mQ nmnV",
      " mq y         3 ",
      " n u E      S2s7",
      " nnnmm       1sE",
      " nppp       X1s ",
      " n t      P  0  ",
      " m   D    D   s ",
      " m   Cl  MOTW s ",
      " m ssnI  Isssss ",
      "                "
    ],
    [
      "                ",
      " nsssssssn      ",
      " m       m()ii  ",
      " u       m   U  ",
      " m       m   i  ",
      " m       n   U  ",
      " momm    m  mnn ",
      " n            3 ",
      " n            s ",
      " nmnnm        s ",
      " n###         s ",
      " n            s ",
      " n        *   s ",
      " m   $M  ^&   s ",
      " n ssm%  Issss  ",
      "                "
    ],
    [
      "                ",
      " nsssss sn      ",
      " n       niiU}  ",
      "         m   {  ",
      " s       n  ]i  ",
      " m       n  Mi  ",
      " nmnn    m+[mmn ",
      " s  +         | ",
      " s  m         s ",
      " mnnnn        s ",
      " n###         s ",
      " s            s ",
      " s            s ",
      " n   $^  ^&   s ",
      " nsssn% -%sss   ",
      "                "
    ],
    [
      "                ",
      " m333||3|m      ",
      " n       o/{{i  ",
      " :       m   )  ",
      " ;       n   )  ",
      " n       m  `\u0370  ",
      " nnnmn>.mnmmnmm ",
      " ;  n         \u0372 ",
      " :  n         | ",
      " nnnnn        3 ",
      " n'           3 ",
      " ;            3 ",
      " ;            | ",
      " n   <^,M^?   3 ",
      " n||3n%  %333|\u0371 ",
      "                "
    ],
    [
      "                ",
      " mnnnnmnnm      ",
      " miiiiiiiniiii  ",
      " niiiiiiin   i  ",
      " niiiiiiin\u0375  U  ",
      " niiiiiiinM\u0376 U  ",
      " nnnnnnnnnnnmmm ",
      " n\u0373\u0373niiiiiiiiim ",
      " n\u0373\u0373niiiiiiiiin ",
      " nnnnni\u0374\u0374iiiiim ",
      " niiiii\u0374\u0374iiiiim ",
      " niiiiiiiiiiiin ",
      " niiiiiiiiiiiin ",
      " niiiiiiiiiiiim ",
      " nnnnnnnnnnnmnm ",
      "                "
    ]
  ]
}