{
  "name": "multi_courtyardofficetower_10_floor15",
  "refpalette": "deceasedcraft:multi_courtyardofficetower_10/multi_courtyardofficetower_10_floor15_palette",
  "xsize": 16,
  "zsize": 16,
  "slices": [
    [
      "aaaaaaaaaaaaab  ",
      "aaaaaaaaaaaaab  ",
      "aaaaaaaaaaaaab  ",
      "aaacaaaaaaaccccc",
      "aaaaaaaaaaaaaab ",
      "aaaaaaaaaaaaaab ",
      "aaaaaaaaaaaaaab ",
      "aaaaaaaaaaaaaabd",
      "aaaaaaaaaaaaaab ",
      "aaaaaaaaaaaaaab ",
      "aaaaaaaaaaaaaab ",
      "aaacbbbbbbb bbcc",
      "aaac    eff    g",
      "bbbc   hiffc   j",
      "   cbbbbbbbc   j",
      "   c   d   cgjj "
    ],
    [
      "           k j  ",
      "  lm n    opqj  ",
      " llrstu    w g  ",
      " srcxxx    ccccc",
      "  yx AB    C Dg ",
      " EFxD        Ij ",
      "  Jx       K Lj ",
      "           K Mjd",
      "              j ",
      "              j ",
      "           NOPg ",
      " Q cRRRRS  cTTcc",
      "UUVc    W  c   g",
      "jjgc   iX  c   j",
      "   cgjjjjjgc   j",
      "   c   d   cgjj "
    ],
    [
      "             j  ",
      "  Y        ! j  ",
      " YYZ 0       g  ",
      "   c111    ccccc",
      "  21          g ",
      "  31          j ",
      "  41          j ",
      "              jd",
      "              j ",
      "              j ",
      "            56g ",
      "   cRRRRS  c  cc",
      "   c   W7  c   g",
      "jjgc  iX   c   j",
      "   cgjjjjjgc   j",
      "   c   d   cgjj "
    ],
    [
      "             j  ",
      "             j  ",
      "             g  ",
      "   c       ccccc",
      "              g ",
      "              j ",
      "              j ",
      "              jd",
      "              j ",
      "              j ",
      "            89g ",
      "   cRRRRS  c  cc",
      "   cff#7   c   g",
      "jjgcffX    c   j",
      "   cgjjjjjgc   j",
      "   c   d   cgjj "
    ],
    [
      "             j  ",
      "             j  ",
      "             g  ",
      "   c       ccccc",
      "              g ",
      "              j ",
      "              j ",
      "              jd",
      "              j ",
      "              j ",
      "              g ",
      "   cRRRRS  ccccc",
      "   c  e#   c   g",
      "jjgc  $    c   j",
      "   cgjjjjjgc   j",
      "   c   d   cgjj "
    ],
    [
      "%%%c%%%%%%%%%j  ",
      "%^%c%^%%%^%%%j  ",
      "%%%c%%%%%%%%%g  ",
      "cccccccccccccccc",
      "%%%c%%%%%%%%%%g ",
      "%^%c%^%%%^%%%%j ",
      "%%%c%%%%%%%%%%j ",
      "%%%c%%%%%%%%%%jd",
      "%%%c%%%%%%%%%%j ",
      "%^%c%^%%%^%%%%j ",
      "%%%c%%%%%%%%%%g ",
      "%%%cbbbbbbbccccc",
      "%%%c   e#  c   g",
      "jjgc  h$   c   j",
      "   cgjjjjjgc   j",
      "   c   d   cgjj "
    ]
  ]
}