{
  "name": "multi_courtyardofficetower_10_floor5",
  "refpalette": "deceasedcraft:multi_courtyardofficetower_10/multi_courtyardofficetower_10_floor5_palette",
  "xsize": 16,
  "zsize": 16,
  "slices": [
    [
      "aaaaaaaaaaaaab  ",
      "aaaaaaaaaaaaab  ",
      "aaaaaaaaaaaaab  ",
      "aaacaaaaaaaccccc",
      "aaaaaaaaaaaaaab ",
      "aaaaaaaaaaaaaab ",
      "aaaaaaaaaaaaaab ",
      "aaaaaaaaaaaaaabd",
      "aaaaaaaaaaaaaab ",
      "aaaaaaaaaaaaaab ",
      "aaaaaaaaaaaaaab ",
      "aaacbbbbbbb bbcc",
      "aaac    eff    g",
      "bbbc   hiffc   j",
      "   cbbbbbbbc   j",
      "   c   d   cgjj "
    ],
    [
      "           k j  ",
      "  lm n    kopj  ",
      " llqrrs    k g  ",
      " tucwww   xccccc",
      "  ywAAB    CD j ",
      " E wFI J   K  j ",
      "   wL         j ",
      "  EM N       Ojd",
      "              j ",
      "  E E   kPQQ  j ",
      "    RRSTUOOTVWg ",
      "   cXXXXY Zc00cc",
      "112c    3  c   g",
      "jjgc   i45!c   j",
      "   cgjjjjjgc   j",
      "   c   d   cgjj "
    ],
    [
      "             j  ",
      "  O          j  ",
      "   678       g  ",
      " 9 c###    ccccc",
      "   #$%^    &* j ",
      "   #         (j ",
      "   #          j ",
      "             Ojd",
      "              j ",
      "              j ",
      "    )  + -[]{}g ",
      "   cXXXXY  c  cc",
      "   c   3|  c   g",
      "jjgc  i4   c   j",
      "   cgjjjjjgc   j",
      "   c   d   cgjj "
    ],
    [
      "             j  ",
      "             j  ",
      "             g  ",
      "   c       ccccc",
      "              g ",
      "              j ",
      "              j ",
      "              jd",
      "              j ",
      "              j ",
      "            ;:g ",
      "   cXXXXY  c  cc",
      "   cff'|   c   g",
      "jjgcff4    c   j",
      "   cgjjjjjgc   j",
      "   c   d   cgjj "
    ],
    [
      "             j  ",
      "             j  ",
      "             g  ",
      "   c       ccccc",
      "              g ",
      "              j ",
      "              j ",
      "              jd",
      "              j ",
      "              j ",
      "              g ",
      "   cXXXXY  ccccc",
      "   c  e'   c   g",
      "jjgc  <    c   j",
      "   cgjjjjjgc   j",
      "   c   d   cgjj "
    ],
    [
      ">>>c>>>>>>>>>j  ",
      ">,>c>,>>>,>>>j  ",
      ">>>c>>>>>>>>>g  ",
      "cccccccccccccccc",
      ">>>c>>>>>>>>>>g ",
      ">,>c>,>>>,>>>>j ",
      ">>>c>>>>>>>>>>j ",
      ">>>c>>>>>>>>>>jd",
      ">>>c>>>>>>>>>>j ",
      ">,>c>,>>>,>>>>j ",
      ">>>c>>>>>>>>>>g ",
      ">>>cbbbbbbbccccc",
      ">>>c   e'  c   g",
      "jjgc  h<   c   j",
      "   cgjjjjjgc   j",
      "   c   d   cgjj "
    ]
  ]
}