{
  "name": "multi_courtyardofficetower_10_floor12",
  "refpalette": "deceasedcraft:multi_courtyardofficetower_10/multi_courtyardofficetower_10_floor12_palette",
  "xsize": 16,
  "zsize": 16,
  "slices": [
    [
      "                ",
      "                ",
      "                ",
      "   a       aaaaa",
      "                ",
      "                ",
      "                ",
      "                ",
      "                ",
      "                ",
      "         bb     ",
      "   a    cddaaaaa",
      "   a    edda   f",
      "   aghhhhhga i j",
      "   a       a   j",
      "   a       afjj "
    ],
    [
      "                ",
      "                ",
      "                ",
      "   a       aaaaa",
      "                ",
      "                ",
      "                ",
      "                ",
      "                ",
      "                ",
      "        bkk     ",
      "   a   cl  aaaaa",
      "   a       a   f",
      "   aghhhhhga   j",
      "   a       a   j",
      "   a       afjj "
    ],
    [
      "                ",
      "                ",
      "                ",
      "   a       aaaaa",
      "                ",
      "                ",
      "                ",
      "                ",
      "                ",
      "                ",
      "       mk       ",
      "   a  cl   aaaaa",
      "   a       a   f",
      "   aghhhhhga   j",
      "   a       a   j",
      "   a       afjj "
    ],
    [
      "                ",
      "                ",
      "                ",
      "   a       aaaaa",
      "                ",
      "                ",
      "                ",
      "                ",
      "                ",
      "                ",
      "    mmmk        ",
      "   addl    aaaaa",
      "   addn    a   f",
      "   aghhhhhga   j",
      "   a       a   j",
      "   a       afjj "
    ],
    [
      "                ",
      "                ",
      "                ",
      "   a       aaaaa",
      "                ",
      "                ",
      "                ",
      "                ",
      "                ",
      "                ",
      "    kkk         ",
      "   a       aaaaa",
      "   a  en   a   f",
      "   aghhhhhga   j",
      "   a       a   j",
      "   a       afjj "
    ],
    [
      "opoaoooooooo q  ",
      "ppoaoooooooo q  ",
      "oooaoooooooo r  ",
      "aaaaaaaaaaaaaaaa",
      "oooaooooooooo r ",
      "oooaooooooooo q ",
      "oooaooooooooo q ",
      "oooaooooooooo qq",
      "oooaooooooooo q ",
      "oooaooooooooo q ",
      "oooaooooooooo r ",
      "oooa       aaaaa",
      "   a   en  a   f",
      "qqrastttttsa   j",
      "   arqqqqqra   j",
      "   a   q   afjj "
    ]
  ]
}