{
  "name": "multi_courtyardofficetower_10_floor7",
  "refpalette": "deceasedcraft:multi_courtyardofficetower_10/multi_courtyardofficetower_10_floor7_palette",
  "xsize": 16,
  "zsize": 16,
  "slices": [
    [
      "aaaaaaaaaaaaab  ",
      "aaaaaaaaaaaaab  ",
      "aaaaaaaaaaaaab  ",
      "aaacaaaaaaaccccc",
      "aaaaaaaaaaaaaab ",
      "aaaaaaaaaaaaaab ",
      "aaaaaaaaaaaaaab ",
      "aaaaaaaaaaaaaabd",
      "aaaaaaaaaaaaaab ",
      "aaaaaaaaaaaaaab ",
      "aaaaaaaaaaaaaab ",
      "aaacbbbbbbb bbcc",
      "aaac    eff    g",
      "bbbc   hiffc   j",
      "   cbbbbbbbc   j",
      "   c   d   cgjj "
    ],
    [
      "     k     l j  ",
      "  mn      opqj  ",
      " mmrsst    u g  ",
      " wxcyyy    ccccc",
      "  AyBCD    EFIg ",
      "  AyJ        Kj ",
      " LMyN O    O Kj ",
      "           O Pjd",
      "              j ",
      "              j ",
      "           QRSg ",
      " T cUUUUV  cWWcc",
      "XXYc    Z  c   g",
      "jjgc   i0  c   j",
      "   cgjjjjjgc   j",
      "   c   d   cgjj "
    ],
    [
      "             j  ",
      "  12         j  ",
      " 113456      g  ",
      "   c777    ccccc",
      "  87          g ",
      "  97          j ",
      "  #7          j ",
      "              jd",
      "              j ",
      "              j ",
      "            $%g ",
      "   cUUUUV  c  cc",
      "   c   Z^  c   g",
      "jjgc  i0   c   j",
      "   cgjjjjjgc   j",
      "   c   d   cgjj "
    ],
    [
      "             j  ",
      "             j  ",
      "             g  ",
      "   c       ccccc",
      "              g ",
      "              j ",
      "              j ",
      "              jd",
      "              j ",
      "              j ",
      "            &*g ",
      "   cUUUUV  c  cc",
      "   cff(^   c   g",
      "jjgcff0    c   j",
      "   cgjjjjjgc   j",
      "   c   d   cgjj "
    ],
    [
      "             j  ",
      "             j  ",
      "             g  ",
      "   c       ccccc",
      "              g ",
      "              j ",
      "              j ",
      "              jd",
      "              j ",
      "              j ",
      "              g ",
      "   cUUUUV  ccccc",
      "   c  e(   c   g",
      "jjgc  )    c   j",
      "   cgjjjjjgc   j",
      "   c   d   cgjj "
    ],
    [
      "+++c+++++++++j  ",
      "+-+c+-+++-+++j  ",
      "+++c+++++++++g  ",
      "cccccccccccccccc",
      "+++c++++++++++g ",
      "+-+c+-+++-++++j ",
      "+++c++++++++++j ",
      "+++c++++++++++jd",
      "+++c++++++++++j ",
      "+-+c+-+++-++++j ",
      "+++c++++++++++g ",
      "+++cbbbbbbbccccc",
      "+++c   e(  c   g",
      "jjgc  h)   c   j",
      "   cgjjjjjgc   j",
      "   c   d   cgjj "
    ]
  ]
}