{
  "name": "multi_courtyardofficetower_10_floor1",
  "refpalette": "deceasedcraft:multi_courtyardofficetower_10/multi_courtyardofficetower_10_floor1_palette",
  "xsize": 16,
  "zsize": 16,
  "slices": [
    [
      "    aaa         ",
      "     a          ",
      "                ",
      "   b       bbbbb",
      "                ",
      "                ",
      "                ",
      "                ",
      "                ",
      "                ",
      "         cc     ",
      "   b    deebbbbb",
      "   b    feeb   g",
      "   bhiiiiihb   j",
      "   b       b   j",
      "   b       bgjj "
    ],
    [
      "     aa         ",
      "     a          ",
      "                ",
      "   b       bbbbb",
      "                ",
      "                ",
      "                ",
      "                ",
      "                ",
      "                ",
      "        ckk     ",
      "   b   dl  bbbbb",
      "   b       b   g",
      "   bhiiiiihb   j",
      "   b       b   j",
      "   b       bgjj "
    ],
    [
      "     aa         ",
      "                ",
      "                ",
      "   b       bbbbb",
      "                ",
      "                ",
      "                ",
      "                ",
      "                ",
      "                ",
      "       mk       ",
      "   b  dl   bbbbb",
      "   b       b   g",
      "   bhiiiiihb   j",
      "   b       b   j",
      "   b       bgjj "
    ],
    [
      "     a          ",
      "                ",
      "                ",
      "   b       bbbbb",
      "                ",
      "                ",
      "                ",
      "                ",
      "                ",
      "                ",
      "    mmmk        ",
      "   beel    bbbbb",
      "   been    b   g",
      "   bhiiiiihb   j",
      "   b       b   j",
      "   b       bgjj "
    ],
    [
      "                ",
      "                ",
      "                ",
      "   b       bbbbb",
      "                ",
      "                ",
      "                ",
      "                ",
      "                ",
      "                ",
      "    kkk         ",
      "   b       bbbbb",
      "   b  fn   b   g",
      "   bhiiiiihb   j",
      "   b       b   j",
      "   b       bgjj "
    ],
    [
      "oooboooooooo p  ",
      "oooboooooooo p  ",
      "oooboooooooo q  ",
      "bbbbbbbbbbbbbbbb",
      "ooobooooooooo q ",
      "ooobooooooooo p ",
      "ooobooooooooo p ",
      "ooobooooooooo pp",
      "ooobooooooooo p ",
      "ooobooooooooo p ",
      "ooobooooooooo q ",
      "ooob       bbbbb",
      "   b   fn  b   g",
      "ppqbrsssssrb   j",
      "   bqpppppqb   j",
      "   b   p   bgjj "
    ]
  ]
}