{
  "name": "multi_courtyardofficetower_10_floor20",
  "refpalette": "deceasedcraft:multi_courtyardofficetower_10/multi_courtyardofficetower_10_floor20_palette",
  "xsize": 16,
  "zsize": 16,
  "slices": [
    [
      "   abbbbbbbbcd  ",
      "   abbbbbbbbcd  ",
      "   abbbbbbbbce  ",
      "aaafbbbbbbgfffff",
      "bbbbbbbbbbbbbce ",
      "bbbbbbbbbbbbbcd ",
      "bbbbbbbbbbbbbcd ",
      "bbbbbbbbbbbbbcdh",
      "bbbbbbbbbbbbbcd ",
      "bbbbbbbbbbbbbcd ",
      "bbbgbbbbbbbbbce ",
      "bbbfbbbbbbbfcfff",
      "cccfbbbbbbbfccce",
      "ddefcccccccfci d",
      "   fedddddefc  d",
      "   f   h   fedd "
    ],
    [
      "  jkl      mnh  ",
      "  jk      omnh  ",
      "  jkl      pnq  ",
      "rrrf      sfffff",
      "           t nq ",
      "           u nh ",
      "           w nh ",
      "             nhh",
      "             nh ",
      "             nh ",
      " o s         nq ",
      "mmxfyAB yABfCfff",
      "nnnf       f   e",
      "hhqfnnnnnnnfDEFd",
      "   fqhhhhhqfI  d",
      "   f   h   fedd "
    ],
    [
      "                ",
      "           J    ",
      "                ",
      "   f      Kfffff",
      "                ",
      "                ",
      "                ",
      "                ",
      "                ",
      "                ",
      "   K            ",
      "   f       fLfff",
      "   f       f   e",
      "   f       fM  d",
      "   f       f  d ",
      "   f       fed  "
    ],
    [
      "                ",
      "                ",
      "                ",
      "   f      Nfffff",
      "                ",
      "                ",
      "                ",
      "                ",
      "                ",
      "                ",
      "   N        O   ",
      "   f       fffff",
      "   f       f  e ",
      "   f       f  d ",
      "   f       fedd ",
      "   f       f    "
    ],
    [
      "                ",
      "                ",
      "                ",
      "   f      Nfffff",
      "                ",
      "                ",
      "                ",
      "                ",
      "                ",
      "                ",
      "   N            ",
      "   f       fffff",
      "   f       f  e ",
      "   f       f  d ",
      "   f       fed  ",
      "   f       f    "
    ],
    [
      "                ",
      "                ",
      "                ",
      "   f      Pfffff",
      "                ",
      "                ",
      "                ",
      "                ",
      "                ",
      "                ",
      "   P            ",
      "   f       fffff",
      "   f       f e  ",
      "   f       fed  ",
      "   f       f    ",
      "   f       f    "
    ]
  ]
}