{
  "name": "multi_courtyardofficetower_10_base1",
  "refpalette": "deceasedcraft:multi_courtyardofficetower_10/multi_courtyardofficetower_10_base1_palette",
  "xsize": 16,
  "zsize": 16,
  "slices": [
    [
      "aaaaaaaaaaaaaaaa",
      "aaaaaaaaaaaaaaaa",
      "aaaaaaaaaaaaaaaa",
      "aaabaaaaaaabbbba",
      "aaaaaaaaaaaaaaaa",
      "aaaaaaaaaaaaaaaa",
      "aaaaaaaaaaaaaaaa",
      "aaaaaaaaaaaaaaaa",
      "aaaaaaaaaaaaaaaa",
      "aaaaaaaaaaaaaaaa",
      "aaaaaaaaaaaaaaaa",
      "aaabaaaaaaabbbba",
      "aaabaaaaaaabccca",
      "aaabaaaaaaabccca",
      "aaabaaaaaaabccca",
      "aaaaaaaaaaaaaaaa"
    ],
    [
      "dddddddeffeaaaaa",
      "dddddddeffeaaaaa",
      "dddddddeffeaaaaa",
      "dddbdddeffebbbba",
      "dddddddeffeggggg",
      "dddddddeffeggggg",
      "dddddddeffeggggg",
      "eeeeeeeeffeggggg",
      "ffffffffffeggggg",
      "ffffffffffeggggg",
      "eeeeeeeeeeeggggg",
      "aaabhhhhggg ggbg",
      "aaabggggggg    g",
      "aaabgggggggb   g",
      "aaabiiiiiiib   g",
      "aaaaaaaaaaaagggg"
    ],
    [
      "dddddddj  jaaaaa",
      "dddddddj  jaaaaa",
      "dddddddj  jaaaaa",
      "dddbdddj  jbbbba",
      "dddddddj  j kl i",
      "dddddddj       i",
      "dddddddj       i",
      "jjjjjjjm       n",
      "               i",
      "               i",
      "jjjjj      opq i",
      "aaabrrrrs  bttbg",
      "aaabgggg   b   g",
      "aaabgggu   b   g",
      "aaabiiiiiiib   g",
      "aaaaaaaaaaaagggg"
    ],
    [
      "dddddddj  jaaaaa",
      "dddddddj  jaaaaa",
      "dddddddj  jaaaaa",
      "dddbdddj  jbbbba",
      "dddddddj  j    i",
      "dddddddj       i",
      "dddddddj       i",
      "jjjjjjjw       x",
      "               i",
      "               i",
      "jjjjj       yA i",
      "aaabrrrrs  b  bg",
      "aaabgggg   b   g",
      "aaabggu    b   g",
      "aaabiiiiiiib   g",
      "aaaaaaaaaaaagggg"
    ],
    [
      "dddddddj  jaaaaa",
      "dddddddj  jaaaaa",
      "dddddddj  jaaaaa",
      "dddbdddj  jbbbba",
      "dddddddj  j    i",
      "dddddddj       i",
      "dddddddj       i",
      "jjjjjjjB      Ci",
      "               i",
      "               i",
      "jjjjj       DE i",
      "aaabrrrrs  b  bg",
      "aaab  Fg   b   g",
      "aaab       b   g",
      "aaabiiiiiiib   g",
      "aaaaaaaaaaaagggg"
    ],
    [
      "dddddddjIIjaaaaa",
      "dddddddjIIjaaaaa",
      "dddddddjIIjaaaaa",
      "dddbdddjIIjbbbba",
      "dddddddjIIjIIIIi",
      "dddddddjIIjIIIIi",
      "dddddddjIIjIIIIi",
      "jjjjjjjJIIjIIIIi",
      "IIIIIIIIIIjIIIIi",
      "IIIIIIIIIIjIIIIi",
      "jjjjjjjjjjjIIIIi",
      "aaabrrrrs  bbbbg",
      "aaab   FK  b   g",
      "aaab       b   g",
      "aaabiiiiiiib   g",
      "aaaaaaaaaaaagggg"
    ]
  ]
}