{
  "name": "multi_courtyardofficetower_10_floor11",
  "refpalette": "deceasedcraft:multi_courtyardofficetower_10/multi_courtyardofficetower_10_floor11_palette",
  "xsize": 16,
  "zsize": 16,
  "slices": [
    [
      "                ",
      "                ",
      "                ",
      "   a       aaaaa",
      "                ",
      "                ",
      "                ",
      "                ",
      "                ",
      "                ",
      "   b     cc     ",
      "   a    deeaaaaa",
      "   a    feea ggh",
      "   aijjjjjiagggk",
      "   a       agggk",
      "   a       ahkk "
    ],
    [
      "                ",
      "                ",
      "                ",
      "   a      laaaaa",
      "                ",
      "                ",
      "                ",
      "                ",
      "                ",
      "                ",
      "   l    cmm     ",
      "   a   dn  aaaaa",
      "   a       aopqh",
      "   aijjjjjiarstk",
      "   a       ar  k",
      "   a       ahkk "
    ],
    [
      "                ",
      "                ",
      "                ",
      "   a      uaaaaa",
      "                ",
      "                ",
      "                ",
      "                ",
      "                ",
      "                ",
      "   u   wm       ",
      "   a  dn   aaaaa",
      "   a       ax jh",
      "   aijjjjjiar  k",
      "   a       ar  k",
      "   a       ahkk "
    ],
    [
      "                ",
      "                ",
      "                ",
      "   a      yaaaaa",
      "                ",
      "                ",
      "                ",
      "                ",
      "                ",
      "                ",
      "   ywwwm        ",
      "   aeen    aaaaa",
      "   aeeA    a  Bh",
      "   aijjjjjiar  k",
      "   a       ar  k",
      "   a       ahkk "
    ],
    [
      "                ",
      "                ",
      "                ",
      "   a       aaaaa",
      "                ",
      "                ",
      "                ",
      "                ",
      "                ",
      "                ",
      "    mmm         ",
      "   a       aaaaa",
      "   a  fA   aCCCh",
      "   aijjjjjiaCDCk",
      "   a       aCCCk",
      "   a       ahkk "
    ],
    [
      "                ",
      "                ",
      "                ",
      "   a       aaaaa",
      "                ",
      "                ",
      "                ",
      "                ",
      "                ",
      "                ",
      "                ",
      "   a       aaaaa",
      "   a   fA  aEEEh",
      "   aijjjjjiaEFEk",
      "   a       aEEEk",
      "   a       ahkk "
    ]
  ]
}