{
  "name": "multi_courtyardofficetower_10_floor14",
  "refpalette": "deceasedcraft:multi_courtyardofficetower_10/multi_courtyardofficetower_10_floor14_palette",
  "xsize": 16,
  "zsize": 16,
  "slices": [
    [
      "             a  ",
      "             a  ",
      "             b  ",
      "cccdcccccccddddd",
      "   c          b ",
      "   c          a ",
      "   c          a ",
      "   c          ae",
      "   c          a ",
      "   c          a ",
      "   c          b ",
      "   dffffgg ddddd",
      "   d    hiid   b",
      "aabd   jkiid   a",
      "   dbaaaaabd   a",
      "   d   e   dbaa "
    ],
    [
      "             a  ",
      "             a  ",
      "             b  ",
      "cccdcccccccddddd",
      "   c          b ",
      "   c          a ",
      "   c          a ",
      "   c          ae",
      "   c          a ",
      "   c          a ",
      "   c          b ",
      "   dffffgggddddd",
      "   d    l  d   b",
      "aabd   km  d   a",
      "   dbaaaaabd   a",
      "   d   e   dbaa "
    ],
    [
      "             a  ",
      "             a  ",
      "             b  ",
      "cccdcccccccddddd",
      "   c          b ",
      "   c          a ",
      "   c          a ",
      "   c          ae",
      "   c          a ",
      "   c          a ",
      "   c          b ",
      "   dffffgggddddd",
      "   d   ln  d   b",
      "aabd  km   d   a",
      "   dbaaaaabd   a",
      "   d   e   dbaa "
    ],
    [
      "             a  ",
      "             a  ",
      "             b  ",
      "cccdcccccccddddd",
      "   c          b ",
      "   c          a ",
      "   c          a ",
      "   c          ae",
      "   c          a ",
      "   c          a ",
      "   c          b ",
      "   dffffgggddddd",
      "   diion   d   b",
      "aabdiim    d   a",
      "   dbaaaaabd   a",
      "   d   e   dbaa "
    ],
    [
      "             a  ",
      "             a  ",
      "             b  ",
      "cccdcccccccddddd",
      "   c          b ",
      "   c          a ",
      "   c          a ",
      "   c          ae",
      "   c          a ",
      "   c          a ",
      "   c          b ",
      "   dffffgggddddd",
      "   d  ho   d   b",
      "aabd  p    d   a",
      "   dbaaaaabd   a",
      "   d   e   dbaa "
    ],
    [
      "qqqdqqqqqqqqqa  ",
      "qrqdqrqqqrqqqa  ",
      "qqqdqqqqqqqqqb  ",
      "dddddddddddddddd",
      "qqqdqqqqqqqqqqb ",
      "qrqdqrqqqrqqqqa ",
      "qqqdqqqqqqqqqqa ",
      "qqqdqqqqqqqqqqae",
      "qqqdqqqqqqqqqqa ",
      "qrqdqrqqqrqqqqa ",
      "qqqdqqqqqqqqqqb ",
      "qqqdsssssssddddd",
      "qqqd   ho  d   b",
      "aabd  jp   d   a",
      "   dbaaaaabd   a",
      "   d   e   dbaa "
    ]
  ]
}