{
  "name": "multi_courtyardofficetower_10_floor9",
  "refpalette": "deceasedcraft:multi_courtyardofficetower_10/multi_courtyardofficetower_10_floor9_palette",
  "xsize": 16,
  "zsize": 16,
  "slices": [
    [
      "             a  ",
      "             a  ",
      "             b  ",
      "   c       ccccc",
      "              b ",
      "              a ",
      "              a ",
      "              ad",
      "              a ",
      "              a ",
      "              b ",
      "   ceeeeff ccccc",
      "   c    ghhc   b",
      "aabc   ijhhc   a",
      "   cbaaaaabc   a",
      "   c   d   cbaa "
    ],
    [
      "             a  ",
      "             a  ",
      "             b  ",
      "   c       ccccc",
      "              b ",
      "              a ",
      "              a ",
      "              ad",
      "              a ",
      "              a ",
      "              b ",
      "   ceeeefffccccc",
      "   c    k  c   b",
      "aabc   jl  c   a",
      "   cbaaaaabc   a",
      "   c   d   cbaa "
    ],
    [
      "             a  ",
      "             a  ",
      "             b  ",
      "   c       ccccc",
      "              b ",
      "              a ",
      "              a ",
      "              ad",
      "              a ",
      "              a ",
      "              b ",
      "   ceeeefffccccc",
      "   c   km  c   b",
      "aabc  jl   c   a",
      "   cbaaaaabc   a",
      "   c   d   cbaa "
    ],
    [
      "             a  ",
      "             a  ",
      "             b  ",
      "   c       ccccc",
      "              b ",
      "              a ",
      "              a ",
      "              ad",
      "              a ",
      "              a ",
      "              b ",
      "   ceeeefffccccc",
      "   chhnm   c   b",
      "aabchhl    c   a",
      "   cbaaaaabc   a",
      "   c   d   cbaa "
    ],
    [
      "             a  ",
      "             a  ",
      "             b  ",
      "   c       ccccc",
      "              b ",
      "              a ",
      "              a ",
      "              ad",
      "              a ",
      "              a ",
      "              b ",
      "   ceeeefffccccc",
      "   c  on   c   b",
      "aabc  pp   c   a",
      "   cbaaaaabc   a",
      "   c   d   cbaa "
    ],
    [
      "qqqcqqqqqqqqqa  ",
      "qrqcqrqqqrqqqa  ",
      "qqqcqqqqqqqqqb  ",
      "cccccccccccccccc",
      "qqqcqqqqqqqqqqb ",
      "qrqcqrqqqrqqqqa ",
      "qqqcqqqqqqqqqqa ",
      "qqqcqqqqqqqqqqad",
      "qqqcqqqqqqqqqqa ",
      "qrqcqrqqqrqqqqa ",
      "qqqcqqqqqqqqqqb ",
      "qqqcsssssssccccc",
      "qqqc   on  c   b",
      "aabc  ii   c   a",
      "   cbaaaaabc   a",
      "   c   d   cbaa "
    ]
  ]
}