{
  "name": "multi_courtyardofficetower_10_ground",
  "refpalette": "deceasedcraft:multi_courtyardofficetower_10/multi_courtyardofficetower_10_ground_palette",
  "xsize": 16,
  "zsize": 16,
  "slices": [
    [
      "aaaaaabbabbbabaa",
      "aaaaaaabbbaaaaaa",
      "aaaaaababbaaaaaa",
      "aaacaaabbbacccca",
      "aaaaaabbbbaaaaaa",
      "aaaaaaabbabaaaaa",
      "dddddddddddddddd",
      "eeeeeeeeeeeeeeee",
      "ddddddddddddddde",
      "aaaaaaaaaafffffd",
      "aaaaaaaaafffffff",
      "aaacfffffffccccf",
      "aaac    gffc   f",
      "aaachhfffffc   f",
      "aaacaadedffc   f",
      "aaaaaadeedfffffd"
    ],
    [
      "    ij          ",
      "            iii ",
      "ii        i i   ",
      "   ci      cccc ",
      "  i       ii i  ",
      " k  lmn  k  lmn ",
      "                ",
      "                ",
      "                ",
      "                ",
      "   iiiiio       ",
      "  ic   pq  cccc ",
      "   c       c   r",
      " iicstttt sc   u",
      " i c       c   u",
      "i           ruu "
    ],
    [
      "     w          ",
      "            i   ",
      " i              ",
      "   c       cccc ",
      "           i    ",
      "                ",
      "                ",
      "                ",
      "                ",
      "                ",
      "    i  ox       ",
      "  ic  pq   cccc ",
      "   c       c   r",
      " i cyAAAA yc   u",
      "   c       c   u",
      "            ruu "
    ],
    [
      "     B          ",
      "                ",
      "                ",
      "   c       ccccC",
      "                ",
      "                ",
      "                ",
      "                ",
      "                ",
      "                ",
      "    ooox        ",
      "   cffq    ccccC",
      "   cffD    c   r",
      "   cyAAAEFIc   u",
      "   c       c   u",
      "   J       Jruu "
    ],
    [
      "     i          ",
      "                ",
      "i               ",
      "   c       ccccC",
      "                ",
      "                ",
      "                ",
      "                ",
      "                ",
      "                ",
      "    xxx         ",
      "   c       ccccC",
      "   c  gD   c   r",
      "   cyAAAAtyc   u",
      "   c       c   u",
      "   J       Jruu "
    ],
    [
      "    ii          ",
      "                ",
      "i               ",
      "   c       ccccc",
      "                ",
      "                ",
      "                ",
      "                ",
      "                ",
      "                ",
      "                ",
      "   c       ccccc",
      "   c   gD  c   r",
      "   cyAAAAAyc   u",
      "   c       c   u",
      "   c       cruu "
    ]
  ]
}