{
  "name": "multi_courtyardofficetower_10_floor8",
  "refpalette": "deceasedcraft:multi_courtyardofficetower_10/multi_courtyardofficetower_10_floor8_palette",
  "xsize": 16,
  "zsize": 16,
  "slices": [
    [
      "aaaaaaaaaaaaab  ",
      "aaaaaaaaaaaaab  ",
      "aaaaaaaaaaaaab  ",
      "aaacaaaaaaaccccc",
      "aaaaaaaaaaaaaab ",
      "aaaaaaaaaaaaaab ",
      "aaaaaaaaaaaaaab ",
      "aaaaaaaaaaaaaabd",
      "aaaaaaaaaaaaaab ",
      "aaaaaaaaaaaaaab ",
      "aaaaaaaaaaaaaab ",
      "aaacbbbbbbb bbcc",
      "aaac    eff    g",
      "bbbc   hiffc   j",
      "   cbbbbbbbc   j",
      "   c   d   cgjj "
    ],
    [
      "     k   lmn j  ",
      "    opk   qq j  ",
      "     r       g  ",
      " s c      tccccc",
      " u         w xg ",
      " s           yj ",
      " A         B Cj ",
      " s         B Djd",
      " A            j ",
      "              j ",
      "   t       EFIg ",
      "   cJJJJK  cLLcc",
      "  Mc    N  c   g",
      "jjgc   iO  c   j",
      "   cgjjjjjgc   j",
      "   c   d   cgjj "
    ],
    [
      "           P j  ",
      "             j  ",
      "             g  ",
      "   c      Qccccc",
      "              g ",
      "              j ",
      "              j ",
      "              jd",
      "              j ",
      "              j ",
      "   Q        RSg ",
      "   cJJJJK  c  cc",
      "  Tc   NU  c   g",
      "jjgc  iO   c   j",
      "   cgjjjjjgc   j",
      "   c   d   cgjj "
    ],
    [
      "           V j  ",
      "             j  ",
      "             g  ",
      "   c      Wccccc",
      "              g ",
      "              j ",
      "              j ",
      "              jd",
      "              j ",
      "              j ",
      "   W        XYg ",
      "   cJJJJK  c  cc",
      "ZZ0cff1U   c   g",
      "jjgcffO    c   j",
      "   cgjjjjjgc   j",
      "   c   d   cgjj "
    ],
    [
      "             j  ",
      "             j  ",
      "             g  ",
      "   c       ccccc",
      "              g ",
      "              j ",
      "              j ",
      "              jd",
      "              j ",
      "              j ",
      "              g ",
      "   cJJJJK  ccccc",
      "223c  e1   c   g",
      "jjgc  4    c   j",
      "   cgjjjjjgc   j",
      "   c   d   cgjj "
    ],
    [
      "           5 j  ",
      "           5 j  ",
      "           6 g  ",
      "   c       ccccc",
      "              g ",
      "              j ",
      "              j ",
      "              jd",
      "              j ",
      "              j ",
      "              g ",
      "   cJJJJKK ccccc",
      "778c   e1  c   g",
      "jjgc  h4   c   j",
      "   cgjjjjjgc   j",
      "   c   d   cgjj "
    ]
  ]
}