{
  "name": "multi_courtyardofficetower_10_floor4",
  "refpalette": "deceasedcraft:multi_courtyardofficetower_10/multi_courtyardofficetower_10_floor4_palette",
  "xsize": 16,
  "zsize": 16,
  "slices": [
    [
      "aaaaaaaaaaaaab  ",
      "aaaaaaaaaaaaab  ",
      "aaaaaaaaaaaaab  ",
      "aaacaaaaaaaccccc",
      "aaaaaaaaaaaaaab ",
      "aaaaaaaaaaaaaab ",
      "aaaaaaaaaaaaaab ",
      "aaaaaaaaaaaaaabd",
      "aaaaaaaaaaaaaab ",
      "aaaaaaaaaaaaaab ",
      "aaaaaaaaaaaaaab ",
      "aaacbbbbbbb bbcc",
      "aaac    eff    g",
      "bbbc   hiffc   j",
      "   cbbbbbbbc   j",
      "   c   d   cgjj "
    ],
    [
      "           k j  ",
      "  lm n    opqj  ",
      " llrsst    u g  ",
      " wxcyyy    ccccc",
      "  Ay BC    DElg ",
      " FAyE        Ij ",
      "  Jy       K Ij ",
      "           K Ljd",
      "              j ",
      "              j ",
      "           MNOg ",
      " P cQQQQR  cSScc",
      "TTUc    V  c   g",
      "jjgc   iW  c   j",
      "   cgjjjjjgc   j",
      "   c   d   cgjj "
    ],
    [
      "             j  ",
      "  X        ! j  ",
      " XX YZ       g  ",
      " 01c222    ccccc",
      "  12         3g ",
      "  42          j ",
      "  52          j ",
      "              jd",
      "              j ",
      "              j ",
      "            67g ",
      "   cQQQQR  c  cc",
      "   c   V8  c   g",
      "jjgc  iW   c   j",
      "   cgjjjjjgc   j",
      "   c   d   cgjj "
    ],
    [
      "             j  ",
      "             j  ",
      "             g  ",
      "   c       ccccc",
      "             9g ",
      "              j ",
      "              j ",
      "              jd",
      "              j ",
      "              j ",
      "            #$g ",
      "   cQQQQR  c  cc",
      "   cff%8   c   g",
      "jjgcffW    c   j",
      "   cgjjjjjgc   j",
      "   c   d   cgjj "
    ],
    [
      "             j  ",
      "             j  ",
      "             g  ",
      "   c       ccccc",
      "              g ",
      "              j ",
      "              j ",
      "              jd",
      "              j ",
      "              j ",
      "              g ",
      "   cQQQQR  ccccc",
      "   c  e%   c   g",
      "jjgc  ^    c   j",
      "   cgjjjjjgc   j",
      "   c   d   cgjj "
    ],
    [
      "&&&c&&&&&&&&&j  ",
      "&*&c&*&&&*&&&j  ",
      "&&&c&&&&&&&&&g  ",
      "cccccccccccccccc",
      "&&&c&&&&&&&&&&g ",
      "&*&c&*&&&*&&&&j ",
      "&&&c&&&&&&&&&&j ",
      "&&&c&&&&&&&&&&jd",
      "&&&c&&&&&&&&&&j ",
      "&*&c&*&&&*&&&&j ",
      "&&&c&&&&&&&&&&g ",
      "&&&cbbbbbbbccccc",
      "&&&c   e%  c   g",
      "jjgc  h^   c   j",
      "   cgjjjjjgc   j",
      "   c   d   cgjj "
    ]
  ]
}