{
  "name": "multi_courtyardofficetower_10_floor13",
  "refpalette": "deceasedcraft:multi_courtyardofficetower_10/multi_courtyardofficetower_10_floor13_palette",
  "xsize": 16,
  "zsize": 16,
  "slices": [
    [
      "aaaaaaaaaaaabc  ",
      "aaaaaaaaaaaabc  ",
      "aaaaaaaaaaaabd  ",
      "bbbebbbbbbbeeeee",
      "fffbgggggggggbd ",
      "fffbgggggggggbc ",
      "fffbgggggggggbc ",
      "fffbgggggggggbch",
      "fffbgggggggggbc ",
      "fffbgggggggggbc ",
      "fffbgggggggggbd ",
      "fffeiibbbbb bbee",
      "bbbe    jbb    d",
      "ccdebbbbbbbe   c",
      "   edcccccde   c",
      "   e   h   edcc "
    ],
    [
      "             c  ",
      "             c  ",
      "             d  ",
      "klmemmmmmnneeeee",
      "   mo p  qr   d ",
      "   m          c ",
      "   ms t       c ",
      "   mu t       ch",
      "   mw t       c ",
      "   m          c ",
      "   m       xyAd ",
      "BBCeDDDDE  eFFee",
      "BBIe    J  e   d",
      "ccde   KL  e   c",
      "   edcccccde   c",
      "   e   h   edcc "
    ],
    [
      "             c  ",
      "             c  ",
      "             d  ",
      "MNmemmmmm  eeeee",
      "   m!    OP   d ",
      "   m          c ",
      "   m          c ",
      "   m          ch",
      "   m          c ",
      "   m          c ",
      "   m        QRd ",
      " S eDDDDE  e  ee",
      " T e   JU  e   d",
      "ccde  KL   e   c",
      "   edcccccde   c",
      "   e   h   edcc "
    ],
    [
      "             c  ",
      "             c  ",
      "             d  ",
      "mmmemmmmmmmeeeee",
      "   m          d ",
      "  Vm          c ",
      "  Vm          c ",
      "  Vm          ch",
      "  Vm          c ",
      "  Vm          c ",
      "   m        WXd ",
      "   eDDDDE  e  ee",
      "   eYYZU   e   d",
      "ccdeYYL    e   c",
      "   edcccccde   c",
      "   e   h   edcc "
    ],
    [
      "             c  ",
      "             c  ",
      "             d  ",
      "mmmemmmmmmmeeeee",
      "   m          d ",
      "  Vm          c ",
      "  Vm          c ",
      "  Vm          ch",
      "  Vm          c ",
      "  Vm          c ",
      "   m          d ",
      "   eDDDDE  eeeee",
      "   e  0Z   e   d",
      "ccde  1    e   c",
      "   edcccccde   c",
      "   e   h   edcc "
    ],
    [
      "             c  ",
      "             c  ",
      "             d  ",
      "mmmemmmmmmmeeeee",
      "   m          d ",
      "  Vm          c ",
      "  Vm          c ",
      "  Vm          ch",
      "  Vm          c ",
      "  Vm          c ",
      "   m          d ",
      "   eDDDDEE eeeee",
      "   e   0Z  e   d",
      "ccde  21   e   c",
      "   edcccccde   c",
      "   e   h   edcc "
    ]
  ]
}