{
  "name": "multi_courtyardofficetower_10_floor3",
  "refpalette": "deceasedcraft:multi_courtyardofficetower_10/multi_courtyardofficetower_10_floor3_palette",
  "xsize": 16,
  "zsize": 16,
  "slices": [
    [
      "             a  ",
      "           bba  ",
      "             c  ",
      "   deeeeeeeddddd",
      "   e          c ",
      "   e          a ",
      "   e          a ",
      "   e          af",
      "   e          a ",
      "   e          a ",
      "   e          c ",
      "   dgggghh ddddd",
      "   d    ijjd   c",
      "aacd   kljjd   a",
      "   dcaaaaacd   a",
      "   d   f   dcaa "
    ],
    [
      "             a  ",
      "             a  ",
      "             c  ",
      "   deeeeeeeddddd",
      "   e          c ",
      "   e          a ",
      "   e          a ",
      "   e          af",
      "   e          a ",
      "   e          a ",
      "   e          c ",
      "   dgggghhhddddd",
      "   d    m  d   c",
      "aacd   ln  d   a",
      "   dcaaaaacd   a",
      "   d   f   dcaa "
    ],
    [
      "             a  ",
      "             a  ",
      "             c  ",
      "   deeeeeeeddddd",
      "   e          c ",
      "   e          a ",
      "   e          a ",
      "   e          af",
      "   e          a ",
      "   e          a ",
      "   e          c ",
      "   dgggghhhddddd",
      "   d   mo  d   c",
      "aacd  ln   d   a",
      "   dcaaaaacd   a",
      "   d   f   dcaa "
    ],
    [
      "             a  ",
      "             a  ",
      "             c  ",
      "   deeeeeeeddddd",
      "   e          c ",
      "   e          a ",
      "   e          a ",
      "   e          af",
      "   e          a ",
      "   e          a ",
      "   e          c ",
      "   dgggghhhddddd",
      "   djjpo   d   c",
      "aacdjjn    d   a",
      "   dcaaaaacd   a",
      "   d   f   dcaa "
    ],
    [
      "             a  ",
      "             a  ",
      "             c  ",
      "   deeeeeeeddddd",
      "   e          c ",
      "   e          a ",
      "   e          a ",
      "   e          af",
      "   e          a ",
      "   e          a ",
      "   e          c ",
      "   dgggghhhddddd",
      "   d  ip   d   c",
      "aacd  q    d   a",
      "   dcaaaaacd   a",
      "   d   f   dcaa "
    ],
    [
      "rrrdrrrrrrr  a  ",
      "rsrdrsrrrsr  a  ",
      "rrrdrrrrrrr  c  ",
      "dddddddddddddddd",
      "rrrdrrrrrrrrrrc ",
      "rsrdrsrrrsrrrra ",
      "rrrdrrrrrrrrrra ",
      "rrrdrrrrrrrrrraf",
      "rrrdrrrrrrrrrra ",
      "rsrdrsrrrsrrrra ",
      "rrrdrrrrrrrrrrc ",
      "rrrdtttttttddddd",
      "rrrd   ip  d   c",
      "aacd  kq   d   a",
      "   dcaaaaacd   a",
      "   d   f   dcaa "
    ]
  ]
}