{
  "name": "multi_courtyardofficetower_10_floor18",
  "refpalette": "deceasedcraft:multi_courtyardofficetower_10/multi_courtyardofficetower_10_floor18_palette",
  "xsize": 16,
  "zsize": 16,
  "slices": [
    [
      "aaaaaaaaaaaaab  ",
      "aaaaaaaaaaaaab  ",
      "aaaaaaaaaaaaab  ",
      "aaacaaaaaaaccccc",
      "aaaaaaaaaaaaaab ",
      "aaaaaaaaaaaaaab ",
      "aaaaaaaaaaaaaab ",
      "aaaaaaaaaaaaaabd",
      "aaaaaaaaaaaaaab ",
      "aaaaaaaaaaaaaab ",
      "aaaaaaaaaaaaaab ",
      "aaacbbbbbbb bbcc",
      "aaac    eff    g",
      "bbbc   hiiic   j",
      "   cbbbbbbbc   j",
      "   c   d   cgjj "
    ],
    [
      "         kk lj  ",
      "             j  ",
      "         mn og  ",
      "   c    pppccccc",
      "              g ",
      "              j ",
      "              j ",
      "qqqr          jd",
      "   s          j ",
      "   s          j ",
      "   t    u  wxyg ",
      "   cAAAAA  cBBcc",
      "CDEc       c   g",
      "jjgc    hhhc   j",
      "   cgjjjjjgc   j",
      "   c   d   cgjj "
    ],
    [
      "             j  ",
      "             j  ",
      "             g  ",
      "   c    FFFccccc",
      "              g ",
      "              j ",
      "              j ",
      "IJKL          jd",
      "   M          j ",
      "   N          j ",
      "            OPg ",
      "   c       c  cc",
      "QR c       c   g",
      "jjgc       c   j",
      "   cgjjjjjgc   j",
      "   c   d   cgjj "
    ],
    [
      "             j  ",
      "             j  ",
      "             g  ",
      "   c       ccccc",
      "              g ",
      "              j ",
      "              j ",
      "              jd",
      "              j ",
      "              j ",
      "            STg ",
      "   c       c  cc",
      "   c       c   g",
      "jjgc       c   j",
      "   cgjjjjjgc   j",
      "   c   d   cgjj "
    ],
    [
      "             j  ",
      "             j  ",
      "             g  ",
      "   c       ccccc",
      "              g ",
      "              j ",
      "UVUV          j ",
      "WXWXY         jd",
      "              j ",
      "              j ",
      "              g ",
      "   c       ccccc",
      "   c       c   g",
      "jjgc       c   j",
      "   cgjjjjjgc   j",
      "   c   d   cgjj "
    ],
    [
      "             j  ",
      "Z            j  ",
      "Z            g  ",
      "   c       ccccc",
      "              g ",
      "              j ",
      "              j ",
      "0123          jd",
      "              j ",
      "              j ",
      "              g ",
      "   c       ccccc",
      "   c       c   g",
      "jjgc       c   j",
      "   cgjjjjjgc   j",
      "   c   d   cgjj "
    ]
  ]
}