{
  "name": "multi_courtyardofficetower_10_floor16",
  "refpalette": "deceasedcraft:multi_courtyardofficetower_10/multi_courtyardofficetower_10_floor16_palette",
  "xsize": 16,
  "zsize": 16,
  "slices": [
    [
      "aaaaaaaaaaaaab  ",
      "aaaaaaaaaaaaab  ",
      "aaaaaaaaaaaaab  ",
      "aaacaaaaaaaccccc",
      "aaaaaaaaaaaaaab ",
      "aaaaaaaaaaaaaab ",
      "aaaaaaaaaaaaaab ",
      "aaaaaaaaaaaaaabd",
      "aaaaaaaaaaaaaab ",
      "aaaaaaaaaaaaaab ",
      "aaaaaaaaaaaaaab ",
      "aaacbbbbbbb bbcc",
      "aaac    eff    g",
      "bbbc   hiffc   j",
      "   cbbbbbbbc   j",
      "   c   d   cgjj "
    ],
    [
      "     k     l j  ",
      "  mn      opqj  ",
      " mmrstu    w g  ",
      " xrcyyy    ccccc",
      "  AyBCD    EFIg ",
      "J KyL        Mj ",
      "  NyO P    P Mj ",
      "           P Qjd",
      "              j ",
      "              j ",
      "           RSTg ",
      " U cVVVVW  cXXcc",
      "YYZc    0  c   g",
      "jjgc   i1  c   j",
      "   cgjjjjjgc   j",
      "   c   d   cgjj "
    ],
    [
      "             j  ",
      "  23       ! j  ",
      " 22 456      g  ",
      " 78c999    ccccc",
      "  #9          g ",
      "  $9          j ",
      "  89          j ",
      "              jd",
      "              j ",
      "              j ",
      "            %^g ",
      "   cVVVVW  c  cc",
      "   c   0&  c   g",
      "jjgc  i1   c   j",
      "   cgjjjjjgc   j",
      "   c   d   cgjj "
    ],
    [
      "             j  ",
      "             j  ",
      "             g  ",
      "   c       ccccc",
      "              g ",
      "              j ",
      "              j ",
      "              jd",
      "              j ",
      "              j ",
      "            *(g ",
      "   cVVVVW  c  cc",
      "   cff)&   c   g",
      "jjgcff1    c   j",
      "   cgjjjjjgc   j",
      "   c   d   cgjj "
    ],
    [
      "             j  ",
      "             j  ",
      "             g  ",
      "   c       ccccc",
      "              g ",
      "              j ",
      "              j ",
      "              jd",
      "              j ",
      "              j ",
      "              g ",
      "   cVVVVW  ccccc",
      "   c  e)   c   g",
      "jjgc  +    c   j",
      "   cgjjjjjgc   j",
      "   c   d   cgjj "
    ],
    [
      "---c---------j  ",
      "-[-c-[---[---j  ",
      "---c---------g  ",
      "cccccccccccccccc",
      "---c----------g ",
      "-[-c-[---[----j ",
      "---c----------j ",
      "---c----------jd",
      "---c----------j ",
      "-[-c-[---[----j ",
      "---c----------g ",
      "---cbbbbbbbccccc",
      "---c   e)  c   g",
      "jjgc  h+   c   j",
      "   cgjjjjjgc   j",
      "   c   d   cgjj "
    ]
  ]
}