{
  "name": "multi_courtyardofficetower_10_floor19",
  "refpalette": "deceasedcraft:multi_courtyardofficetower_10/multi_courtyardofficetower_10_floor19_palette",
  "xsize": 16,
  "zsize": 16,
  "slices": [
    [
      "abb          c  ",
      "da           c  ",
      "de           f  ",
      "g  h       hhhhh",
      "   i          f ",
      "   j          c ",
      "   j          c ",
      "   k          cl",
      "   j          c ",
      "   j          c ",
      "   m          f ",
      "   h       hhhhh",
      "   h       h   f",
      "ccfh       h n c",
      "   hfcccccfh   c",
      "   h   l   hfcc "
    ],
    [
      " dde         c  ",
      " og          c  ",
      " g           f  ",
      "   h       hhhhh",
      "              f ",
      "              c ",
      "              c ",
      "              cl",
      "              c ",
      "              c ",
      "              f ",
      "   h       hhhhh",
      "   h       h   f",
      "ccfh       h n c",
      "   hfcccccfh   c",
      "   h   l   hfcc "
    ],
    [
      "             c  ",
      "             c  ",
      "             f  ",
      "   h       hhhhh",
      "              f ",
      "              c ",
      "              c ",
      "              cl",
      "              c ",
      "              c ",
      "              f ",
      "   h       hhhhh",
      "   h       h   f",
      "ccfh       h n c",
      "   hfcccccfh   c",
      "   h   l   hfcc "
    ],
    [
      "             c  ",
      "             c  ",
      "             f  ",
      "   h       hhhhh",
      "              f ",
      "              c ",
      "              c ",
      "              cl",
      "              c ",
      "              c ",
      "              f ",
      "   h       hhhhh",
      "   h       h   f",
      "ccfh       h n c",
      "   hfcccccfh   c",
      "   h   l   hfcc "
    ],
    [
      "             c  ",
      "             c  ",
      "             f  ",
      "   h       hhhhh",
      "              f ",
      "              c ",
      "              c ",
      "              cl",
      "              c ",
      "              c ",
      "              f ",
      "   h       hhhhh",
      "   h       h   f",
      "ccfh       h n c",
      "   hfcccccfh   c",
      "   h   l   hfcc "
    ],
    [
      "   hpppppppppc  ",
      "   hpqpppqpppc  ",
      "   hpppppppppf  ",
      "hhhhhhhhhhhhhhhh",
      "ppphppppppppppf ",
      "pqphpqpppqppppc ",
      "ppphppppppppppc ",
      "ppphppppppppppcl",
      "ppphppppppppppc ",
      "pqphpqpppqppppc ",
      "ppphppppppppppf ",
      "ppphppppppphhhhh",
      "ppphppppppph   f",
      "ccfh       h n c",
      "   hfcccccfh   c",
      "   h   l   hfcc "
    ]
  ]
}