{
  "name": "multi_courtyardofficetower_10_floor22",
  "refpalette": "deceasedcraft:multi_courtyardofficetower_10/multi_courtyardofficetower_10_floor22_palette",
  "xsize": 16,
  "zsize": 16,
  "slices": [
    [
      "   a       a    ",
      "   a       a    ",
      "   a       a    ",
      "aaaaaaaaaaaaaaaa",
      "   a       a    ",
      "   a       a    ",
      "   a       a    ",
      "   a       a    ",
      "   a       a    ",
      "   a       a    ",
      "   a       a    ",
      "aaaaaaaaaaaaaaaa",
      "   a       a    ",
      "   a       a    ",
      "   a       a    ",
      "   a       a    "
    ],
    [
      "bbcacbbbbbca    ",
      "bbcacbbbbbca    ",
      "cccaccccccca    ",
      "aaaaaaaaaaaaaaaa",
      "cccaccccccca    ",
      "bbcacbbbbbca    ",
      "bbcacbbbbbca    ",
      "bbcacbbbbbca    ",
      "bbcacbbbbbca    ",
      "bbcacbbbbbca    ",
      "cccaccccccca    ",
      "aaaaaaaaaaaaaaaa",
      "   a       a    ",
      "   a       a    ",
      "   a       a    ",
      "   a       a    "
    ],
    [
      "   a       a    ",
      "   a       a    ",
      "   a       a    ",
      "aaaaaaaaaaaaaaaa",
      "   a       a    ",
      "   a       a    ",
      "   a       a    ",
      "   a       a    ",
      "   a       a    ",
      "   a       a    ",
      "   a       a    ",
      "aaaaaaaaaaaaaaaa",
      "   a       a    ",
      "   a       a    ",
      "   a       a    ",
      "   a       a    "
    ],
    [
      "   a       a    ",
      "   a       a    ",
      "   a       a    ",
      "aaaaaaaaaaaaaaaa",
      "   a       a    ",
      "   a       a    ",
      "   a       a    ",
      "   a       a    ",
      "   a       a    ",
      "   a       a    ",
      "   a       a    ",
      "aaaaaaaaaaaaaaaa",
      "   a       a    ",
      "   a       a    ",
      "   a       a    ",
      "   a       a    "
    ],
    [
      "   a       a    ",
      "   a       a    ",
      "   a       a    ",
      "aaaaaaaaaaaaaaaa",
      "   a       a    ",
      "   a       a    ",
      "   a       a    ",
      "   a       a    ",
      "   a       a    ",
      "   a       a    ",
      "   a       a    ",
      "aaaaaaaaaaaaaaaa",
      "   a       a    ",
      "   a       a    ",
      "   a       a    ",
      "   a       a    "
    ],
    [
      "   a       a    ",
      "   a       a    ",
      "   a       a    ",
      "aaaaaaaaaaaaaaaa",
      "   a       a    ",
      "   a       a    ",
      "   a       a    ",
      "   a       a    ",
      "   a       a    ",
      "   a       a    ",
      "   a       a    ",
      "aaaaaaaaaaaaaaaa",
      "   a       a    ",
      "   a       a    ",
      "   a       a    ",
      "   a       a    "
    ]
  ]
}