{
  "name": "multi_courtyardofficetower_10_top",
  "refpalette": "deceasedcraft:multi_courtyardofficetower_10/multi_courtyardofficetower_10_top_palette",
  "xsize": 16,
  "zsize": 16,
  "slices": [
    [
      "   a       a    ",
      "   a       a    ",
      "   a       a    ",
      "aaaaaaaaaaaaaaaa",
      "   a       a    ",
      "   a       a    ",
      "   a       a    ",
      "   a       a    ",
      "   a       a    ",
      "   a       a    ",
      "   a       a    ",
      "aaaaaaaaaaaaaaaa",
      "   a       a    ",
      "   a       a    ",
      "   a       a    ",
      "   a       a    "
    ],
    [
      "   a       a    ",
      "   a       a    ",
      "   a       a    ",
      "aaaaaaaaaaaaaaaa",
      "   a       a    ",
      "   a       a    ",
      "   a       a    ",
      "   a       a    ",
      "   a       a    ",
      "   a       a    ",
      "   a       a    ",
      "aaaaaaaaaaaaaaaa",
      "   a       a    ",
      "   a       a    ",
      "   a       a    ",
      "   a       a    "
    ],
    [
      "   a       a    ",
      "   a       a    ",
      "   a       a    ",
      "aaaaaaaaaaaaaaaa",
      "   a       a    ",
      "   a       a    ",
      "   a       a    ",
      "   a       a    ",
      "   a       a    ",
      "   a       a    ",
      "   a       a    ",
      "aaaaaaaaaaaaaaaa",
      "   a       a    ",
      "   a       a    ",
      "   a       a    ",
      "   a       a    "
    ],
    [
      "           a    ",
      "           a    ",
      "           a    ",
      "   aaaaaaaaaaaaa",
      "   a       a    ",
      "   a       a    ",
      "   a       a    ",
      "   a       a    ",
      "   a       a    ",
      "   a       a    ",
      "   a       a    ",
      "aaaaaaaaaaaaaaaa",
      "   a       a    ",
      "   a       a    ",
      "   a       a    ",
      "   a       a    "
    ],
    [
      "                ",
      "                ",
      "                ",
      "           aaaaa",
      "           a    ",
      "           a    ",
      "           a    ",
      "           a    ",
      "           a    ",
      "           a    ",
      "           a    ",
      "   aaaaaaaaaaaaa",
      "   a       a    ",
      "   a       a    ",
      "   a       a    ",
      "   a       a    "
    ],
    [
      "                ",
      "                ",
      "                ",
      "                ",
      "                ",
      "                ",
      "                ",
      "                ",
      "                ",
      "                ",
      "                ",
      "           aaaaa",
      "           a    ",
      "           a    ",
      "           a    ",
      "           a    "
    ]
  ]
}