{
  "name": "multi_courtyardofficetower_10_floor2",
  "refpalette": "deceasedcraft:multi_courtyardofficetower_10/multi_courtyardofficetower_10_floor2_palette",
  "xsize": 16,
  "zsize": 16,
  "slices": [
    [
      "aaaaaaaaaaaabc  ",
      "aaaaaaaaaaaabc  ",
      "aaaaaaaaaaaabd  ",
      "aaaebbbbbbbeeeee",
      "aaabfffffffffbd ",
      "aaabfffffffffbc ",
      "aaabfffffffffbc ",
      "aaabfffffffffbcg",
      "aaabfffffffffbc ",
      "aaabfffffffffbc ",
      "aaabfffffffffbd ",
      "aaaebbbbbbb bbee",
      "bbbe    hbb    d",
      "ccdebbbbbbbe   c",
      "   edcccccde   c",
      "   e   g   edcc "
    ],
    [
      "      iii    c  ",
      "             c  ",
      "             d  ",
      "   ejjjjjkkeeeee",
      "l  jm n  op   d ",
      "qr j          c ",
      "s  jt u       c ",
      "   jw u       cg",
      "   jx u       c ",
      "   j          c ",
      "r  j       yABd ",
      "   eCCCCD  eEEee",
      "   e    F  e   d",
      "ccde   IJ  e   c",
      "   edcccccde   c",
      "   e   g   edcc "
    ],
    [
      "      KKL    c  ",
      "           M c  ",
      "             d  ",
      "   ejjjjj  eeeee",
      "   j     NO   d ",
      "   j          c ",
      "   j          c ",
      "   j          cg",
      "   j          c ",
      "   j          c ",
      "   j        PQd ",
      "   eCCCCD  e  ee",
      "   e   FR  e   d",
      "ccde  IJ   e   c",
      "   edcccccde   c",
      "   e   g   edcc "
    ],
    [
      "      LL     c  ",
      "           M c  ",
      "             d  ",
      "   ejjjjjjjeeeee",
      "   j          d ",
      "   j          c ",
      "   j          c ",
      "   j          cg",
      "   j          c ",
      "   j          c ",
      "   j        STd ",
      "   eCCCCD  e  ee",
      "   eUUVR   e   d",
      "ccdeUUJ    e   c",
      "   edcccccde   c",
      "   e   g   edcc "
    ],
    [
      "             c  ",
      "           M c  ",
      "             d  ",
      "   ejjjjjjjeeeee",
      "   j          d ",
      "   j          c ",
      "   j          c ",
      "   j          cg",
      "   j          c ",
      "   j          c ",
      "   j          d ",
      "   eCCCCD  eeeee",
      "   e  WV   e   d",
      "ccde  X    e   c",
      "   edcccccde   c",
      "   e   g   edcc "
    ],
    [
      "             c  ",
      "           YZc  ",
      "             d  ",
      "   ejjjjjjjeeeee",
      "   j          d ",
      "   j          c ",
      "   j          c ",
      "   j          cg",
      "   j          c ",
      "   j          c ",
      "   j          d ",
      "   eCCCCDD eeeee",
      "   e   WV  e   d",
      "ccde  0X   e   c",
      "   edcccccde   c",
      "   e   g   edcc "
    ]
  ]
}