{
  "name": "multi_courtyardofficetower_10_floor10",
  "refpalette": "deceasedcraft:multi_courtyardofficetower_10/multi_courtyardofficetower_10_floor10_palette",
  "xsize": 16,
  "zsize": 16,
  "slices": [
    [
      "aabcbbcccbcbde  ",
      "aabcbbbcbbbcde  ",
      "bbbcbbbbbcbcdf  ",
      "cccgbbcbbchggggg",
      "bbbbbbbccccdddf ",
      "bbbbbbcbcccddde ",
      "bccbbbbbcccddde ",
      "ccbbcbbbbbcdddei",
      "cbbccccbbbcddde ",
      "ccbcccbcbbbddde ",
      "ccchcccccbbdddf ",
      "cbcgddddddd ddgg",
      "dddg    jdd    f",
      "eefgkkdddddg   e",
      "   gfeeeeefg   e",
      "   g   i   gfee "
    ],
    [
      "   l      m ni  ",
      "   l        ni  ",
      "   l        no  ",
      "lllg      pggggg",
      "              o ",
      "              i ",
      "              i ",
      "              ii",
      "              i ",
      "              i ",
      "q  p    r  stuo ",
      "   g   wx  gyygg",
      "nnng       g   f",
      "iiogABBBBBAg   e",
      "   goiiiiiog   e",
      "   g   i   gfee "
    ],
    [
      "                ",
      "                ",
      "                ",
      "   g      Cggggg",
      "                ",
      "                ",
      "                ",
      "                ",
      "                ",
      "                ",
      "   C   rD   EF  ",
      "   g  wx   g  gg",
      "   g       g   f",
      "   gIJJJJJIg   e",
      "   g       g   e",
      "   g       gfee "
    ],
    [
      "                ",
      "                ",
      "                ",
      "   g      lggggg",
      "                ",
      "                ",
      "                ",
      "                ",
      "                ",
      "                ",
      "   lrrrD    rK  ",
      "   gddx    g  gg",
      "   gddL    g   f",
      "   gIJJJJJIg   e",
      "   g       g   e",
      "   g       gfee "
    ],
    [
      "                ",
      "                ",
      "                ",
      "   g      Mggggg",
      "                ",
      "                ",
      "                ",
      "                ",
      "                ",
      "                ",
      "   MDDD         ",
      "   g       ggggg",
      "   g  jL   g   f",
      "   gIJJJJJIg   e",
      "   g       g   e",
      "   g       gfee "
    ],
    [
      "                ",
      "                ",
      "                ",
      "   g      Mggggg",
      "                ",
      "                ",
      "                ",
      "                ",
      "                ",
      "                ",
      "   M            ",
      "   g       ggggg",
      "   g   jL  g   f",
      "   gIJJJJJIg   e",
      "   g       g   e",
      "   g       gfee "
    ]
  ]
}