{
  "name": "multi_courtyardofficetower_10_floor6",
  "refpalette": "deceasedcraft:multi_courtyardofficetower_10/multi_courtyardofficetower_10_floor6_palette",
  "xsize": 16,
  "zsize": 16,
  "slices": [
    [
      "aaaaaaaaaaaaab  ",
      "aaaaaaaaaaaaab  ",
      "aaaaaaaaaaaaab  ",
      "aaacaaaaaaaccccc",
      "aaaaaaaaaaaaaab ",
      "aaaaaaaaaaaaaab ",
      "aaaaaaaaaaaaaab ",
      "aaaaaaaaaaaaaabd",
      "aaaaaaaaaaaaaab ",
      "aaaaaaaaaaaaaab ",
      "aaaaaaaaaaaaaab ",
      "aaacbbbbbbb bbcc",
      "aaac    eff    g",
      "bbbc   hiffc   j",
      "   cbbbbbbbc   j",
      "   c   d   cgjj "
    ],
    [
      "           k j  ",
      "  lm n    opqj  ",
      " llrsst    u g  ",
      " wxcyyy    ccccc",
      " AByCCC    DClg ",
      "  ByE        Fj ",
      "  IyJ      K Fj ",
      "           K Ljd",
      "              j ",
      "              j ",
      "           MNOg ",
      " P cQQQQR  cSScc",
      "TTUc    V  c   g",
      "jjgc   iW  c   j",
      "   cgjjjjjgc   j",
      "   c   d   cgjj "
    ],
    [
      "             j  ",
      "  X        Y j  ",
      " XXZ012      g  ",
      " 33c444    ccccc",
      "  546        7g ",
      "  84          j ",
      "  94          j ",
      "              jd",
      "              j ",
      "              j ",
      "            #$g ",
      "   cQQQQR  c  cc",
      "   c   V%  c   g",
      "jjgc  iW   c   j",
      "   cgjjjjjgc   j",
      "   c   d   cgjj "
    ],
    [
      "             j  ",
      "             j  ",
      "             g  ",
      "   c       ccccc",
      "             ^g ",
      "              j ",
      "              j ",
      "              jd",
      "              j ",
      "              j ",
      "            &*g ",
      "   cQQQQR  c  cc",
      "   cff(%   c   g",
      "jjgcffW    c   j",
      "   cgjjjjjgc   j",
      "   c   d   cgjj "
    ],
    [
      "             j  ",
      "             j  ",
      "             g  ",
      "   c       ccccc",
      "              g ",
      "              j ",
      "              j ",
      "              jd",
      "              j ",
      "              j ",
      "              g ",
      "   cQQQQR  ccccc",
      "   c  e(   c   g",
      "jjgc  )    c   j",
      "   cgjjjjjgc   j",
      "   c   d   cgjj "
    ],
    [
      "+++c+++++++++j  ",
      "+-+c+-+++-+++j  ",
      "+++c+++++++++g  ",
      "cccccccccccccccc",
      "+++c++++++++++g ",
      "+-+c+-+++-++++j ",
      "+++c++++++++++j ",
      "+++c++++++++++jd",
      "+++c++++++++++j ",
      "+-+c+-+++-++++j ",
      "+++c++++++++++g ",
      "+++cbbbbbbbccccc",
      "+++c   e(  c   g",
      "jjgc  h)   c   j",
      "   cgjjjjjgc   j",
      "   c   d   cgjj "
    ]
  ]
}