{
  "name": "multi_courtyardofficetower_10_floor17",
  "refpalette": "deceasedcraft:multi_courtyardofficetower_10/multi_courtyardofficetower_10_floor17_palette",
  "xsize": 16,
  "zsize": 16,
  "slices": [
    [
      "aaaaaaaaaaaaab  ",
      "aaaaaaaaaaaaab  ",
      "aaaaaaaaaaaaab  ",
      "aaacaaaaaaaccccc",
      "aaaaaaaaaaaaaab ",
      "aaaaaaaaaaaaaab ",
      "aaaaaaaaaaaaaab ",
      "aaaaaaaaaaaaaabd",
      "aaaaaaaaaaaaaab ",
      "aaaaaaaaaaaaaab ",
      "aaaaaaaaaaaaaab ",
      "aaacbbbbbbb bbcc",
      "aaac    eff    g",
      "bbbc   hiffc   j",
      "   cbbbbbbbc   j",
      "   c   d   cgjj "
    ],
    [
      "  k        l j  ",
      "m nopqr   stuj  ",
      "wnnxyABC   D g  ",
      " ExcFFF    ccccc",
      "  IF JK   LM Ng ",
      " OPFN        Qj ",
      "  RFS T    U Vj ",
      " W         U Xjd",
      "   Y          j ",
      "T             j ",
      "           Z01g ",
      " 2 c33334  c55cc",
      "667c    8  c   g",
      "jjgc   i9  c   j",
      "   cgjjjjjgc   j",
      "   c   d   cgjj "
    ],
    [
      "             j  ",
      "  #          j  ",
      " ##  $       g  ",
      "   c%%%    ccccc",
      "   %          g ",
      "  ^%          j ",
      "   %          j ",
      "              jd",
      "              j ",
      "              j ",
      "            &*g ",
      "   c33334  c  cc",
      "   c   8(  c   g",
      "jjgc  i9   c   j",
      "   cgjjjjjgc   j",
      "   c   d   cgjj "
    ],
    [
      "             j  ",
      "             j  ",
      "             g  ",
      "   c       ccccc",
      "              g ",
      "              j ",
      "              j ",
      "              jd",
      "              j ",
      "              j ",
      "            )+g ",
      "   c33334  c  cc",
      "   cff-(   c   g",
      "jjgcff9    c   j",
      "   cgjjjjjgc   j",
      "   c   d   cgjj "
    ],
    [
      "             j  ",
      "             j  ",
      "             g  ",
      "   c       ccccc",
      "              g ",
      "              j ",
      "              j ",
      "              jd",
      "              j ",
      "              j ",
      "              g ",
      "   c33334  ccccc",
      "   c  e-   c   g",
      "jjgc  [    c   j",
      "   cgjjjjjgc   j",
      "   c   d   cgjj "
    ],
    [
      "]]]c]]]]]]]]]j  ",
      "]{]c]{]]]{]]]j  ",
      "]]]c]]]]]]]]]g  ",
      "cccccccccccccccc",
      "]]]c]]]]]]]]]]g ",
      "]{]c]{]]]{]]]]j ",
      "]]]c]]]]]]]]]]j ",
      "]]]c]]]]]]]]]]jd",
      "]]]c]]]]]]]]]]j ",
      "]{]c]{]]]{]]]]j ",
      "]]]c]]]]]]]]]]g ",
      "]]]cbbbbbbbccccc",
      "]]]c   e-  c   g",
      "jjgc  h[   c   j",
      "   cgjjjjjgc   j",
      "   c   d   cgjj "
    ]
  ]
}