{
  "name": "multi_laboratory_11_base6",
  "refpalette": "deceasedcraft:multi_laboratory_11/multi_laboratory_11_base6_palette",
  "xsize": 16,
  "zsize": 16,
  "slices": [
    [
      "aaaaaaaaaaaaabcv",
      "aaaaaaaaaaaaabcv",
      "aaaaaaaaaaaaabcv",
      "aaaaaaaaaaaaabcv",
      "aaaaaaaaaaaaabcv",
      "aaaaaaaaaaaaabcv",
      "aaaadaaaaaaaabcv",
      "aaaaaaaaaaaaabcv",
      "aaaaaaaaaaaaabcv",
      "aaaaaaaaaaaaabcv",
      "aaaaaaaaaaaaabcv",
      "aaaaaaaaaaaaabcv",
      "eaaaaaaaaaaaabcv",
      "eaaadaaaaaaaabcv",
      "feaaaaaaaaaaabcv",
      " eaaaaaaaaaaabcv"
    ],
    [
      "             gcv",
      "             bcv",
      "            hbcv",
      "            hbcv",
      " i           bcv",
      "jjjk      llllcv",
      "    d     lm bcv",
      "    n     llllcv",
      "    o        bcv",
      "    o p     hbcv",
      "    o       hbcv",
      "    o        bcv",
      "q   r     llllcv",
      "q   d     lm bcv",
      "fq  s     llllcv",
      " q  o        bcv"
    ],
    [
      "             gcv",
      "            tbcv",
      "           uwbcv",
      "           uwbcv",
      "             bcv",
      "           qllcv",
      "    d     qm bcv",
      "    n      qllcv",
      "    x       tbcv",
      "    y       wbcv",
      "    A      uBbcv",
      "    C       Dbcv",
      "q          qllcv",
      "q   d     qm bcv",
      "fq  C      qllcv",
      " q  n       tbcv"
    ],
    [
      "             gcv",
      "             bcv",
      "             bcv",
      "             bcv",
      "             bcv",
      "           qllcv",
      "    d     qm bcv",
      "    E      qllcv",
      "             bcv",
      "             bcv",
      "    F        bcv",
      "             bcv",
      "q          qllcv",
      "q   d     qm bcv",
      "fq         qllcv",
      " q           bcv"
    ],
    [
      "             gcv",
      "             bcv",
      "            Ibcv",
      "            Ibcv",
      "             bcv",
      "           qllcv",
      "    d     qm bcv",
      "           qllcv",
      "             bcv",
      "            Ibcv",
      "            Ibcv",
      "             bcv",
      "q          qllcv",
      "q   d     qm bcv",
      "fq         qllcv",
      " q           bcv"
    ],
    [
      "             gcv",
      "             bcv",
      "             bcv",
      "            gbcv",
      "             bcv",
      "           qllcv",
      "    d     qm bcv",
      "           qllcv",
      "             bcv",
      "            gbcv",
      "             bcv",
      "             bcv",
      "q          qllcv",
      "q   d     qm bcv",
      "fq         qllcv",
      " q           bcv"
    ]
  ]
}