{
  "name": "multi_laboratory_11_base2",
  "refpalette": "deceasedcraft:multi_laboratory_11/multi_laboratory_11_base2_palette",
  "xsize": 16,
  "zsize": 16,
  "slices": [
    [
      "aaaaaaaaaaaaabcv",
      "aaaaaaaaaaaaabcv",
      "aaaaaaaaaaaaabcv",
      "aaaaaaaaaaaaabcv",
      "aaaaaaaaaaaaabcv",
      "aaaaaaaaaaaaabcv",
      "aaaadaaaaaaaabcv",
      "aaaaaaaaaaaaabcv",
      "aaaaaaaaaaaaabcv",
      "aaaaaaaaaaaaabcv",
      "aaaaaaaaaaaaabcv",
      "aaaaaaaaaaaaabcv",
      "eaaaaaaaaaaaabcv",
      "eaaadaaaaaaaabcv",
      "feaaaaaaaaaaabcv",
      " eaaaaaaaaaaabcv"
    ],
    [
      "    ghijkiiihbcv",
      "    gl  m   ibcv",
      "    gl      ibcv",
      "    g       ibcv",
      "    n      oibcv",
      "    gpqqqqqqhbcv",
      " r fdggggggggbcv",
      "    gs  ss   bcv",
      "    g        bcv",
      "    g t     uucv",
      "    gwwxy  u Acv",
      "    gBBCy ou Acv",
      "DE  gF      uucv",
      "Df  d        bcv",
      "fD  g        bcv",
      " D  I       uucv"
    ],
    [
      "    ghiiii!ihbcv",
      "    J       ibcv",
      "    J       ibcv",
      "    g       ibcv",
      "    K       ibcv",
      "    gL    MNhbcv",
      "   Odggggggggbcv",
      "    g        bcv",
      "    J        bcv",
      "    J       Ducv",
      "    J PQ   D Acv",
      "    JQRS   D Acv",
      "D   g       Ducv",
      "DO  d        bcv",
      "fD  g        bcv",
      " D  I       Ducv"
    ],
    [
      "    ghTTTTTThbcv",
      "    U       Vbcv",
      "    U       Wbcv",
      "    g       Wbcv",
      "    U        bcv",
      "    g       hbcv",
      "   Xdggggggggbcv",
      "    g        bcv",
      "    J        bcv",
      "    J       Ducv",
      "    J      D Acv",
      "    J      D Acv",
      "D   g       Ducv",
      "DX  d        bcv",
      "fD  g        bcv",
      " D  I       Ducv"
    ],
    [
      "    gh      hbcv",
      "    g        bcv",
      "    g        bcv",
      "    g       Ybcv",
      "    g        bcv",
      "    g       hbcv",
      "    dggggggggbcv",
      "    g  Z  Z  bcv",
      "    g        bcv",
      "    g       Ducv",
      "    g      D Acv",
      "    g      D Acv",
      "D   g       Ducv",
      "D   d        bcv",
      "fD  g        bcv",
      " D  g       Ducv"
    ],
    [
      "0000U11111111bcv",
      "0020U13111131bcv",
      "0020U11111111bcv",
      "0020U11111111bcv",
      "0020U13111141bcv",
      "0000U11111111bcv",
      "0000dggggggggbcv",
      "0000U55555555bcv",
      "0000U66666666bcv",
      "0000U66 6676uucv",
      "0000U667667u8Acv",
      "0000U664664u8Acv",
      "D000U6696676uucv",
      "D000d66666666bcv",
      "fD00U66666666bcv",
      " D00U6676676uucv"
    ]
  ]
}