{
  "name": "multi_laboratory_11_base1",
  "refpalette": "deceasedcraft:multi_laboratory_11/multi_laboratory_11_base1_palette",
  "xsize": 16,
  "zsize": 16,
  "slices": [
    [
      "aaaaaaaaaaaaabcv",
      "aaaaaaaaaaaaabcv",
      "aaaaaaaaaaaaabcv",
      "aaaaaaaaaaaaabcv",
      "aaaaaaaaaaaaabcv",
      "aaaaaaaaaaaaabcv",
      "aaaadaaaaaaaabcv",
      "aaaaaaaaaaaaabcv",
      "aaaaaaaaaaaaabcv",
      "aaaaaaaaaaaaabcv",
      "aaaaaaaaaaaaabcv",
      "aaaaaaaaaaaaabcv",
      "eaaaaaaaaaaaabcv",
      "eaaadaaaaaaaabcv",
      "feaaaaaaaaaaabcv",
      " eaaaaaaaaaaabcv"
    ],
    [
      "    ghiijkiihbcv",
      "    g       ibcv",
      "    g       ibcv",
      "    l  iii  mbcv",
      "    g       nbcv",
      "    g       ibcv",
      "   od  iii  ibcv",
      "p   q       hbcv",
      "    q       ibcv",
      "    q  iii  mbcv",
      "    q       nbcv",
      "    qr      !bcv",
      "st  quw    xhbcv",
      "so  dyy    yybcv",
      "os  yA      Bbcv",
      " s  yCD  D  Ebcv"
    ],
    [
      "    ghiiFFiihbcv",
      "    g       ibcv",
      "    g       ibcv",
      "    I  iii  Jbcv",
      "    g       Jbcv",
      "    g       ibcv",
      "   Kd  iii  ibcv",
      "    q       hbcv",
      "    q       ibcv",
      "    q  iii  Jbcv",
      "    q       Jbcv",
      "    q       ibcv",
      "s   q L     hbcv",
      "sK  dyy    yybcv",
      "os  qM      Nbcv",
      " s  q       Nbcv"
    ],
    [
      "    ghOOP OOhbcv",
      "    g       Obcv",
      "    g       Obcv",
      "    g  OOO  Pbcv",
      "    g       Qbcv",
      "    g       Obcv",
      "   Rd  OOO  Obcv",
      "    q       hbcv",
      "    q       Obcv",
      "    q  OOO  Sbcv",
      "    q        bcv",
      "    q       Obcv",
      "s   q       hbcv",
      "sR  dyy    yybcv",
      "os  q       Tbcv",
      " s  q       Tbcv"
    ],
    [
      "    gU      Ubcv",
      "    g        bcv",
      "    g        bcv",
      "    g        bcv",
      "    g        bcv",
      "    g        bcv",
      "    d        bcv",
      "    q       Ubcv",
      "    q        bcv",
      "    q        bcv",
      "    q        bcv",
      "    q        bcv",
      "s   q       Ubcv",
      "s   dyy    yybcv",
      "os  q        bcv",
      " s  q        bcv"
    ],
    [
      "VVVVWVVVVVVVVbcv",
      "VVVVWVXVVVVXVbcv",
      "VVVVWVXVVVVXVbcv",
      "VVVVWVXVVVVYVbcv",
      "VVVVWVXVVVVXVbcv",
      "VVVVWVVVVVVVVbcv",
      "VVVVdVVVVVVVVbcv",
      "VVVVWVVVVVVVVbcv",
      "VVVVWVXVVVVXVbcv",
      "VVVVWVXVVVVXVbcv",
      "VVVVWVXVVVVXVbcv",
      "VVVVWVXVVVVXVbcv",
      "ZVVVWVVVVVVVVbcv",
      "ZVVVdyyyyyyyybcv",
      "0ZVVWVVVVVVVVbcv",
      " ZVVWVXVVVVXVbcv"
    ]
  ]
}