{
  "name": "multi_laboratory_11_ground",
  "refpalette": "deceasedcraft:multi_laboratory_11/multi_laboratory_11_ground_palette",
  "xsize": 16,
  "zsize": 16,
  "slices": [
    [
      "aaaabcccvdeeeezz",
      "aaaabcccveeeeeez",
      "aaaabcccvdezezze",
      "aaaabcccvddeezez",
      "aaaabcccvdedeeez",
      "aaaabcccddeeeezz",
      "aaaabcccvdeeeeee",
      "aaaabcccvddeeeez",
      "aaaabcccvdeeezez",
      "aaaabcccvveeeezz",
      "aaaabcccvvdezeez",
      "aaaabcccvdeeeeee",
      "baaabcccvveeeezz",
      "baaabcccvdeeeezz",
      "bbaabcccvddeeeze",
      "@baabcccvedeeeez"
    ],
    [
      "  f g     hi jk ",
      "    g           ",
      " llfg           ",
      "fll g     hij   ",
      " f  g          k",
      "    g           ",
      "  f b     hjij  ",
      "fll g           ",
      " llfg          k",
      "  f g     hii   ",
      "    g       k  k",
      "    g           ",
      "m   g     hinj  ",
      "m  ob         k ",
      "mm  g           ",
      " m  g     h ij  "
    ],
    [
      "    g           ",
      "    g           ",
      "    g           ",
      "  p g           ",
      "    g           ",
      "    g           ",
      "    b           ",
      "    q           ",
      "    g           ",
      "    g           ",
      "    g           ",
      "    g           ",
      "    q           ",
      "   rb           ",
      "    q           ",
      "    q           "
    ],
    [
      "    g           ",
      "    g           ",
      "    g           ",
      "    g           ",
      "    g           ",
      "    g           ",
      "    b           ",
      "    q           ",
      "    g           ",
      "    g           ",
      "    g           ",
      "    g           ",
      "    q           ",
      "   sb           ",
      "    q           ",
      "    q           "
    ],
    [
      "    g           ",
      "    g           ",
      "    g           ",
      "    g           ",
      "    g           ",
      "    g           ",
      "    b           ",
      "    q           ",
      "    g           ",
      "    g           ",
      "    g           ",
      "    g           ",
      "    q           ",
      "    b           ",
      "    q           ",
      "    q           "
    ],
    [
      "ttttg           ",
      "ttttg           ",
      "ttttg           ",
      "ttttg           ",
      "ttttg           ",
      "ttttg           ",
      "ttttb           ",
      "ttttg           ",
      " tttg           ",
      "  ttg           ",
      "  ttg           ",
      "  ttg           ",
      "   tg           ",
      "   tb           ",
      "   tg           ",
      "   tg           "
    ]
  ]
}