{
  "name": "multi_laboratory_11_base5",
  "refpalette": "deceasedcraft:multi_laboratory_11/multi_laboratory_11_base5_palette",
  "xsize": 16,
  "zsize": 16,
  "slices": [
    [
      "             abv",
      "             cbv",
      "             cbv",
      "            acbv",
      "             cbv",
      "           deebv",
      "    f     dg cbv",
      "           deebv",
      "             cbv",
      "            acbv",
      "             cbv",
      "             cbv",
      "d          deebv",
      "d  !f     dg cbv",
      "hd         deebv",
      " d           cbv"
    ],
    [
      "             abv",
      "             cbv",
      "             cbv",
      "            aabv",
      "             abv",
      "           deebv",
      "    f     dg cbv",
      "           deebv",
      "             cbv",
      "            aabv",
      "             abv",
      "             abv",
      "d          deebv",
      "d   f     dg cbv",
      "hd         deebv",
      " d           abv"
    ],
    [
      "             abv",
      "             cbv",
      "             cbv",
      "            acbv",
      "             cbv",
      "           deebv",
      "    f     dg cbv",
      "           deebv",
      "             cbv",
      "            acbv",
      "             cbv",
      "             cbv",
      "d          deebv",
      "d   f     dg cbv",
      "hd         deebv",
      " d           cbv"
    ],
    [
      "             abv",
      "             cbv",
      "             cbv",
      "            acbv",
      "             cbv",
      "           deebv",
      "    f     dg cbv",
      "           deebv",
      "            acbv",
      "            acbv",
      "            acbv",
      "             cbv",
      "d          deebv",
      "d   f     dg cbv",
      "hd         deebv",
      " d           cbv"
    ],
    [
      "            iabv",
      "             cbv",
      "             cbv",
      "            acbv",
      "             cbv",
      "           deebv",
      "    f     dg cbv",
      "           deebv",
      "             cbv",
      "             cbv",
      "            acbv",
      "             cbv",
      "d          deebv",
      "d   f     dg cbv",
      "hd         deebv",
      " d          icbv"
    ],
    [
      "jjjjjjjjjjjjaabv",
      "jjjjjjjjjjjjacbv",
      "jjjjjjjjjjjjacbv",
      "jjjjjjjjjjjjkcbv",
      "jjjjjjjjjjjjacbv",
      "jjjjjjjjjjeeeebv",
      "jjjjfjjjjjel cbv",
      "jjjjjjjjjjeeeebv",
      "jjjjjjjjjjjjacbv",
      "jjjjjjjjjjjjacbv",
      "jjjjjjjjjjjjkcbv",
      "jjjjjjjjjjjjacbv",
      "djjjjjjjjjeeeebv",
      "djjjfjjjjjel cbv",
      "hdjjjjjjjjeeeebv",
      " djjjjjjjjjjacbv"
    ]
  ]
}