{
  "name": "multi_laboratory_11_base4",
  "refpalette": "deceasedcraft:multi_laboratory_11/multi_laboratory_11_base4_palette",
  "xsize": 16,
  "zsize": 16,
  "slices": [
    [
      "aaaaaaaaaaaaabcv",
      "aaaaaaaaaaaaabcv",
      "aaaaaaaaaaaaabcv",
      "aaaaaaaaaaaaabcv",
      "aaaaaaaaaaaaabcv",
      "aaaaaaaaaaaaabcv",
      "aaaadaaaaaaaabcv",
      "aaaaaaaaaaaaabcv",
      "aaaaaaaaaaaaabcv",
      "aaaaaaaaaaaaabcv",
      "aaaaaaaaaaaaabcv",
      "aaaaaaaaaaaaabcv",
      "eaaaaaaaaaaaabcv",
      "eaaadaaaaaaaabcv",
      "feaaaaaaaaaaabcv",
      " eaaaaaaaaaaabcv"
    ],
    [
      "    ghiiiiiihbcv",
      "    gj      ibcv",
      "    gj      ibcv",
      "    g       ibcv",
      "    k       ibcv",
      "    glmmmmmmhbcv",
      "   fdggggggggbcv",
      "n   goo o o  bcv",
      "    g        bcv",
      "    g  p    qqcv",
      "    grsrt  q ucv",
      "    gwwxt y  ucv",
      "AB  g  C   ~qqcv",
      "Af  dD     E bcv",
      "fA  g        bcv",
      " A  F       qqcv"
    ],
    [
      "    ghiiiiiihbcv",
      "    I       ibcv",
      "    IJ      ibcv",
      "    g       ibcv",
      "    K       ibcv",
      "    gL     Mhbcv",
      "   Ndggggggggbcv",
      "    g        bcv",
      "    I        bcv",
      "    I       Aqcv",
      "    I OP   A ucv",
      "    IOQ      ucv",
      "A   g       Eqcv",
      "AN  d        bcv",
      "fA  g        bcv",
      " A  F       Aqcv"
    ],
    [
      "    ghRRRRRRhbcv",
      "    S       Tbcv",
      "    S       Ubcv",
      "    g       Ubcv",
      "    S       Vbcv",
      "    g       hbcv",
      "   Wdggggggggbcv",
      "    g        bcv",
      "    I        bcv",
      "    I       Aqcv",
      "    I      A ucv",
      "    I      X ucv",
      "A   g       Aqcv",
      "AW  d        bcv",
      "fA  g        bcv",
      " A  F       Aqcv"
    ],
    [
      "    gh      hbcv",
      "    g        bcv",
      "    g        bcv",
      "    g        bcv",
      "    g        bcv",
      "    g       hbcv",
      "    dggggggggbcv",
      "    g  Y  Y  bcv",
      "    g        bcv",
      "    g       Aqcv",
      "    g      A ucv",
      "    g      A ucv",
      "A   g       Aqcv",
      "A   d        bcv",
      "fA  g        bcv",
      " A  g       Aqcv"
    ],
    [
      "ZZZZS00000000bcv",
      "ZZ1ZS020000!0bcv",
      "ZZ1ZS00000000bcv",
      "ZZ1ZS00000000bcv",
      "ZZ1ZS02000020bcv",
      "ZZZZS00000000bcv",
      "ZZZZdggggggggbcv",
      "ZZZZS33333333bcv",
      "ZZZZS44444444bcv",
      "ZZZZS4454454qqcv",
      "ZZZZS445446q7ucv",
      "ZZZZS445445q7ucv",
      "AZZZS4464464qqcv",
      "AZZZd44444444bcv",
      "fAZZS44444444bcv",
      " AZZS4454454qqcv"
    ]
  ]
}