{
  "name": "multi_laboratory_11_base3",
  "refpalette": "deceasedcraft:multi_laboratory_11/multi_laboratory_11_base3_palette",
  "xsize": 16,
  "zsize": 16,
  "slices": [
    [
      "aaaaaaaaaaaaabcv",
      "aaaaaaaaaaaaabcv",
      "aaaaaaaaaaaaabcv",
      "aaaaaaaaaaaaabcv",
      "aaaaaaaaaaaaabcv",
      "aaaaaaaaaaaaabcv",
      "aaaadaaaaaaaabcv",
      "aaaaaaaaaaaaabcv",
      "aaaaaaaaaaaaabcv",
      "aaaaaaaaaaaaabcv",
      "aaaaaaaaaaaaabcv",
      "aaaaaaaaaaaaabcv",
      "eaaaaaaaaaaaabcv",
      "eaaadaaaaaaaabcv",
      "feaaaaaaaaaaabcv",
      " eaaaaaaaaaaabcv"
    ],
    [
      "g   hijjjjjjibcv",
      "k   hl      jbcv",
      "    hl     mjbcv",
      "    h       jbcv",
      "    n       jbcv",
      "    hopopoppibcv",
      "q gfdhhhhhhhhbcv",
      "   rhsss tt  bcv",
      "   uhss      bcv",
      "    hs w    xxcv",
      "  y h AAA  x Bcv",
      "  C h ADD wx Bcv",
      "EF  h IAA   xxcv",
      "Ef  d        bcv",
      "fE  h        bcv",
      " E  J       xxcv"
    ],
    [
      "    hijKjjLjibcv",
      "    MN      jbcv",
      "    M       Obcv",
      "    h       jbcv",
      "    P       Obcv",
      "    hQ    RSibcv",
      "   Tdhhhhhhhhbcv",
      "    h!s      bcv",
      "    M        bcv",
      "    M       Excv",
      "    M UU   E Bcv",
      "    M UU   E Bcv",
      "E   h IVW   Excv",
      "ET  d        bcv",
      "fE  h        bcv",
      " E  J       Excv"
    ],
    [
      "    hiXXXXXXibcv",
      "    Y       mbcv",
      "    Y       Zbcv",
      "    h       Zbcv",
      "    Y        bcv",
      "    h       ibcv",
      "   0dhhhhhhhhbcv",
      "    hs   11  bcv",
      "    M        bcv",
      "    M       Excv",
      "    M 22   E Bcv",
      "    M 22   E Bcv",
      "E   h       Excv",
      "E0  d        bcv",
      "fE  h        bcv",
      " E  J       Excv"
    ],
    [
      "    hi      ibcv",
      "    h        bcv",
      "    h       3bcv",
      "    h        bcv",
      "    h        bcv",
      "    h       ibcv",
      "    dhhhhhhhhbcv",
      "    h  4  4  bcv",
      "    h        bcv",
      "    h       Excv",
      "    h      E Bcv",
      "    h      E Bcv",
      "E   h       Excv",
      "E   d        bcv",
      "fE  h        bcv",
      " E  h       Excv"
    ],
    [
      "5555Y66666666bcv",
      "5555Y67666676bcv",
      "5555Y66666666bcv",
      "5555Y66666666bcv",
      "5555Y67666686bcv",
      "5555Y66666666bcv",
      "5555dhhhhhhhhbcv",
      "5555Y99999999bcv",
      "5555Y########bcv",
      "5555Y##$##%#xxcv",
      "5555Y##%##%x^Bcv",
      "5555Y##$##%x^Bcv",
      "E555Y##%##%#xxcv",
      "E555d########bcv",
      "fE55Y########bcv",
      " E55Y##%##%#xxcv"
    ]
  ]
}