{
  "name": "multi_laboratory_11_base7",
  "refpalette": "deceasedcraft:multi_laboratory_11/multi_laboratory_11_base7_palette",
  "xsize": 16,
  "zsize": 16,
  "slices": [
    [
      "aaaaaaaaaaaaaaav",
      "aaabaaaaaaaaaaav",
      "aaaaaac aaaaaaav",
      "aaaaaaccaaaaaaav",
      "aaaaaaaaaaaaaaav",
      "aaaaaaaaaaaaaaav",
      "aaaaaaaaaaaaaaav",
      "aaaaaaaaaaaaaaav",
      "aaaaaaaaaaaaaaav",
      "aaaaaaaaaaaaaaav",
      "aaaaaaaaaaaaaaav",
      "aaaaaaaaaaaaaaav",
      "daaaaaaaaaaaaaav",
      "daaaaaaaaaaaaaav",
      "ddaaaaaaaaaaaaav",
      "adaaaaaaaaaaaaav"
    ],
    [
      "  eeaaaaaaaaaaav",
      "aeebaaaaaaaaaaav",
      "aaafaaagaaaaaaav",
      "aaaaaaggaaaaaaav",
      "aaaaaaaaaaaaaaav",
      "aaaaaaaaaaaaaaav",
      "aaaaaaaaaaaaaaav",
      "aaaaaaaaaaaaaaav",
      "aaaaaaaaaaaaaaav",
      "aaaaaaaaaaaaaaav",
      "aaaaaaaaaaaaaaav",
      "aaaaaaaaaaaaaaav",
      "aaaaaaaaaaaaaaav",
      "aaaaaaaaaaaaaaav",
      "haaaaaaaaaaaaaav",
      "aaaaaaaaaaaaaaav"
    ],
    [
      "     eaaaaaaaaav",
      "    eaaaaaaaaaav",
      "aa  eafgaaaaaaav",
      "aaaeaeifaaaaaaav",
      "aaaaaaeeaaaaaaav",
      "aaaafagaaaaaaaav",
      "aaaaaaaaaaaaaaav",
      "aaaaaaaaaaaaaaav",
      "aaaaaaaaaaaaaaav",
      "aaaaaaaaaaaaaaav",
      "aaaaaaaaaaaaaaav",
      "aaaaaaaaaaaaaaav",
      "aaaaaaaaaaaaaaav",
      "aaaaaaaaaaaaaaav",
      "haaaaaaaaaaaaaav",
      "baaaaaaaaaaaaaav"
    ],
    [
      "       aaaaaaaav",
      "      egbaaaaaav",
      "aa     iaaaaaaav",
      "aaa      eaaaaav",
      "aaa     aaaaaaav",
      "aaaa  i aaaaaaav",
      "aaaaaafaaaaaaaav",
      "aaaaaaaaaaaaaaav",
      "aaaaaaaaaaaaaaav",
      "aaaaaaaaaaaaaaav",
      "aaaaaaaaaaaaaaav",
      "aaaaaaaaaaaaaaav",
      "aaaaaaaaaaaaaaav",
      "aaaaaaaaaaaaaaav",
      "haaaaaaaaaaaaaav",
      "baaaaaaaaaaaaaav"
    ],
    [
      "aa      aaaaaaav",
      "aa     jifaaaaav",
      "aa       aaaaaav",
      "aaa       aaaaav",
      "aaak     aaaaaav",
      "aaaa   kaaaaaaav",
      "aaaaaaaaaaaaaaav",
      "aaaaaaaaaaaaaaav",
      "aaaaaaaaaaaaaaav",
      "aaaaaaaaaaaaaaav",
      "aaaaaaaaaaaaaaav",
      "aaaaaaaaaaaaaaav",
      "aaaaaaaaaaaaaaav",
      "aaaaaaaaaaaaaaav",
      "haaaaaaaaaaaaaav",
      "eaaaaaaaaaaaaaav"
    ],
    [
      "aaaaaaaaaaaaaaav",
      "aaaaaakaaaaaaaav",
      "aakaakkkkaaaaaav",
      "aaaaakkkkaaaaaav",
      "aaaaakkkaaaaaaav",
      "aaaaaaaaaaaaaaav",
      "aaaaaaaaaaaaaaav",
      "aaaaaaaaaaaaaaav",
      "aaaaaaaaaaaaaaav",
      "aaaaaaaaaaaaaaav",
      "aaaaaaaaaaaaaaav",
      "aaaaaaaaaaaaaaav",
      "aaaaaaaaaaaaaaav",
      "aaaaaaaaaaaaaaav",
      "haaaaaaaaaaaaaav",
      " aaaaaaaaaaaaaav"
    ]
  ]
}