{
  "name": "multi_storageyard_0_ground",
  "refpalette": "deceasedcraft:multi_storageyard_0/multi_storageyard_0_ground_palette",
  "xsize": 16,
  "zsize": 16,
  "slices": [
    [
      "abbzazzzzzzaaabb",
      "azzzzzz=zz===zza",
      "azzzzzzz====z=za",
      "b=zzzzzzzzzzz==b",
      "b=zzzzzzzzzzz==b",
      "b=zzzzz=zzzzz=zz",
      "==zzzzzzzzzzz=za",
      "==zzzzz=zzzzzzaa",
      "a=zzzzz=zzzzz=zz",
      "a=zzzzzzzzzzz==z",
      "zzzzzzz=zzzzz==z",
      "zzzzzzz=zzzzz==z",
      "zzzzzzz=zzzzz==z",
      "zzzzzzzzzzzzz==z",
      "zz====z========z",
      "zz===z========zz"
    ],
    [
      "ccc d   d e  ccc",
      "cddd ee dd  dddc",
      "c fffff ggggg  c",
      "cdhiiih jkkkj  c",
      "cdhlllh jmmmjd  ",
      "cdhiiih jkkkjdde",
      " dhlllh jmmmjd  ",
      "  hiiih jkkkjd  ",
      " dhlllh jmmmj e ",
      "  hiiih jkkkj   ",
      " dhlllh jmmmj   ",
      " dhiiih jkkkj   ",
      "ddhlllh jmmmjd e",
      " dhiiih jkkkjd  ",
      "ednnnnn opqoo   ",
      "     e   rrs    "
    ],
    [
      "ccc          ccc",
      "cdd     d    ddc",
      "c ft tf gt tg  c",
      "c ululu wmxmw  c",
      "cdhyyyh j   j   ",
      "c uyyyu xA! xd  ",
      "  hyyyh j BCjd  ",
      "  uyyDu xE Fx   ",
      "  hDDDh j I j   ",
      "  uDDDu x !Jx   ",
      " dhDDDh jK  j   ",
      "  uDDDu x L x   ",
      " dh  Dh j  Mjd  ",
      " dulNlu wmwmw   ",
      "  nO On orPOo   ",
      "                "
    ],
    [
      "                ",
      "                ",
      "  ft tf gt tg   ",
      "  ululu wmxmw   ",
      "  hyyyh j   j   ",
      "  uyy N x   x   ",
      "  hyy h j   j   ",
      "  N   N x   x   ",
      "  h DDh j   j   ",
      "  N DDu x   x   ",
      "  h DDh j   j   ",
      "  N  Du x   x   ",
      "  h   h j   j   ",
      "  ulNlu wmwmw   ",
      "  nO On oOPOo   ",
      "                "
    ],
    [
      "                ",
      "                ",
      "  ft tf gt tg   ",
      "  ululu wmxmw   ",
      "  hyy h j   j   ",
      "  uy  N x   x   ",
      "  h   h j   j   ",
      "  N   N x   x   ",
      "  h  Dh j   j   ",
      "  N  Du x   x   ",
      "  h   h j   j   ",
      "  N   N x   x   ",
      "  h   h j   j   ",
      "  ulNlu wmwmw   ",
      "  nO On oOPOo   ",
      "                "
    ],
    [
      "                ",
      "                ",
      "  fffff ggggg   ",
      "  hQQQh jRRRj   ",
      "  hlllh jmmmj   ",
      "  hQQQh jRRRj   ",
      "  hlllh jmmmj   ",
      "  hQQQh jRRRj   ",
      "  hlllh jmmmj   ",
      "  hQQQh jRRRj   ",
      "  hlllh jmmmj   ",
      "  hQQQh jRRRj   ",
      "  hlllh jmmmj   ",
      "  hQQQh jRRRj   ",
      "  nnnnn ooooo   ",
      "                "
    ]
  ]
}