{
  "name": "multi_storageyard_0_top",
  "refpalette": "deceasedcraft:multi_storageyard_0/multi_storageyard_0_top_palette",
  "xsize": 16,
  "zsize": 16,
  "slices": [
    [
      "                ",
      "                ",
      "                ",
      "                ",
      "                ",
      "                ",
      "                ",
      "  aaaaa         ",
      "  bcccb         ",
      "  bdddb         ",
      "  bcccb         ",
      "  bdddb         ",
      "  bcccb         ",
      "  bdddb         ",
      "  bcccb         ",
      "  bdddb         "
    ],
    [
      "                ",
      "                ",
      "                ",
      "                ",
      "                ",
      "                ",
      "                ",
      "  ae ea         ",
      "  fdfdf         ",
      "  b   b         ",
      "  f   f         ",
      "  b   b         ",
      "  fg  f         ",
      "  bgghb         ",
      "  fh  i         ",
      "  b  jb         "
    ],
    [
      "                ",
      "                ",
      "                ",
      "                ",
      "                ",
      "                ",
      "                ",
      "  ae ea         ",
      "  fdfdf         ",
      "  b   b         ",
      "  f   f         ",
      "  b   b         ",
      "  fh  i         ",
      "  bh  b         ",
      "  i   i         ",
      "  b   b         "
    ],
    [
      "                ",
      "                ",
      "                ",
      "                ",
      "                ",
      "                ",
      "                ",
      "  ae ea         ",
      "  fdidf         ",
      "  b   b         ",
      "  i   i         ",
      "  b   b         ",
      "  i   i         ",
      "  b   b         ",
      "  i   i         ",
      "  b   b         "
    ],
    [
      "                ",
      "                ",
      "                ",
      "                ",
      "                ",
      "                ",
      "                ",
      "  aaaaa         ",
      "  bkkkb         ",
      "  bdddb         ",
      "  bkkkb         ",
      "  bdddb         ",
      "  bkkkb         ",
      "  bdddb         ",
      "  bkkkb         ",
      "  bdddb         "
    ]
  ]
}