{
  "name": "multi_filmworkstower_23_floor3",
  "refpalette": "deceasedcraft:multi_filmworkstower_23/multi_filmworkstower_23_floor3_palette",
  "xsize": 16,
  "zsize": 16,
  "slices": [
    [
      "            a   ",
      "            a   ",
      "            a   ",
      "            a   ",
      "            a   ",
      "            a   ",
      "     bc     a   ",
      "            a   ",
      "            a   ",
      "aaaaaaaaaaaaa   ",
      "                ",
      "                ",
      "                ",
      "                ",
      "                ",
      "                "
    ],
    [
      "            a   ",
      "            a   ",
      "            a   ",
      "            a   ",
      "            a   ",
      "            a   ",
      "      bcd   a   ",
      "            a   ",
      "            a   ",
      "aaaaaaaaaaaaa   ",
      "                ",
      "                ",
      "                ",
      "                ",
      "                ",
      "                "
    ],
    [
      "eeeeeeeeefgaa   ",
      "eeeeeeeeefgaa   ",
      "eeeeeeeeefgaa   ",
      "eeeeeeeeefgaa   ",
      "eeeeeeeeefgaa   ",
      "eeeeeeeeefgaa   ",
      "fffffffff gaa   ",
      "gggggggggggaa   ",
      "aaaaaaaaaaaaa   ",
      "aaaaaaaaaaaaa   ",
      "                ",
      "                ",
      "                ",
      "                ",
      "                ",
      "                "
    ],
    [
      "hhhhhhhhh       ",
      "iiiiiiiih       ",
      "hhhhhhhhh       ",
      "hhhhhhhhh       ",
      "iiiiiiiih       ",
      "hhhhhhhhh       ",
      "                ",
      "                ",
      "                ",
      "                ",
      "                ",
      "                ",
      "                ",
      "                ",
      "                ",
      "                "
    ],
    [
      "                ",
      "                ",
      "                ",
      "                ",
      "                ",
      "                ",
      "                ",
      "                ",
      "                ",
      "                ",
      "                ",
      "                ",
      "                ",
      "                ",
      "                ",
      "                "
    ],
    [
      "                ",
      "                ",
      "                ",
      "                ",
      "                ",
      "                ",
      "                ",
      "                ",
      "                ",
      "                ",
      "                ",
      "                ",
      "                ",
      "                ",
      "                ",
      "                "
    ]
  ]
}