{
  "name": "multi_filmworkstower_23_base2",
  "refpalette": "deceasedcraft:multi_filmworkstower_23/multi_filmworkstower_23_base2_palette",
  "xsize": 16,
  "zsize": 16,
  "slices": [
    [
      "         abbbbcv",
      "         abbbbcv",
      "         abbbbcv",
      "         abbbbcv",
      "         abbbbcv",
      "         abbbbcv",
      "         abbbbcv",
      "aaaaaaaaaabbbbcv",
      "bbbbbbbbbbbbbbcv",
      "bbbbbbbbbbbbbbcv",
      "bbbbbbbbbbbbbbcv",
      "bbbbbbbbbbbbbbcv",
      "bbbbbbbbbbbbbbcv",
      "cccccccccccccccv",
      "dddddddddddddddv",
      "vvvvvvvvvvvvvvvv"
    ],
    [
      "         a    cv",
      "         a    cv",
      "         a    cv",
      "         a    cv",
      "         a    cv",
      "         a    cv",
      "         aef  cv",
      "aaaaaaaaaa    cv",
      "              cv",
      "              cv",
      "              cv",
      "              cv",
      "              cv",
      "cccccccccccccccv",
      "dddddddddddddddv",
      "vvvvvvvvvvvvvvvv"
    ],
    [
      "         a    cv",
      "         a    cv",
      "         a    cv",
      "         a    cv",
      "         a    cv",
      "         a    cv",
      "         ae   cv",
      "aaaaaaaaaa    cv",
      "              cv",
      "              cv",
      "              cv",
      "              cv",
      "              cv",
      "cccccccccccccccv",
      "dddddddddddddddv",
      "vvvvvvvvvvvvvvvv"
    ],
    [
      "         a    cv",
      "         a    cv",
      "         a    cv",
      "         a    cv",
      "         a    cv",
      "         ag   cv",
      "         ae   cv",
      "aaaaaaaaaa    cv",
      "              cv",
      "              cv",
      "              cv",
      "              cv",
      "              cv",
      "cccccccccccccccv",
      "dddddddddddddddv",
      "vvvvvvvvvvvvvvvv"
    ],
    [
      "         ah   cv",
      "         ah   cv",
      "         ah   cv",
      "         ah   cv",
      "         ah   cv",
      "         ah   cv",
      "         aei  cv",
      "aaaaaaaaaa    cv",
      "              cv",
      "              cv",
      "              cv",
      "              cv",
      "              cv",
      "cccccccccccccccv",
      "dddddddddddddddv",
      "vvvvvvvvvvvvvvvv"
    ],
    [
      "         a    cv",
      "         a    cv",
      "         a    cv",
      "         a    cv",
      "         a    cv",
      "         a    cv",
      "         ae   cv",
      "aaaaaaaaaa    cv",
      "              cv",
      "              cv",
      "              cv",
      "              cv",
      "              cv",
      "cccccccccccccccv",
      "dddddddddddddddv",
      "vvvvvvvvvvvvvvvv"
    ]
  ]
}