{
  "name": "multi_filmworkstower_23_base3",
  "refpalette": "deceasedcraft:multi_filmworkstower_23/multi_filmworkstower_23_base3_palette",
  "xsize": 16,
  "zsize": 16,
  "slices": [
    [
      "aaaaaaaaaaabbbbv",
      "aaaaaaaaaaabbbbv",
      "aaaaaaaaaaabbbbv",
      "aaaaaaaaaaabbbbv",
      "aaaaaaaaaaabbbbv",
      "aaaaaaaaaaabbbbv",
      "aaaaaaaaaaabbbbv",
      "aaaaaaaaaaabbbbv",
      "aaaaaaaaaaabbbbv",
      "bbbbbbbbbbbbbbbv",
      "bbbbbbbbbbbbbbbv",
      "bbbbbbbbbbbbbbbv",
      "bbbbbbbbbbbbbbbv",
      "bbbbbbbbbbbbbbbv",
      "bbbbbbbbbbbbbbbv",
      "vvvvvvvvvvvvvvvv"
    ],
    [
      "cccccccccdabbbbv",
      "cefccccccdabbbbv",
      "ccfccccccdabbbbv",
      "cceccccccdabbbbv",
      "ccfccghccdabbbbv",
      "cccccciccdabbbbv",
      "cccccccccdabbbbv",
      "ddddddddddabbbbv",
      "aaaaaaaaaaabbbbv",
      "bbbbbbbbbbbbbbbv",
      "bbbbbbbbbbbbbbbv",
      "bbbbbbbbbbbbbbbv",
      "bbbbbbbbbbbbbbbv",
      "bbbbbbbbbbbbbbbv",
      "bbbbbbbbbbbbbbbv",
      "vvvvvvvvvvvvvvvv"
    ],
    [
      "    j   jdabbbbv",
      "         dabbbbv",
      "       e dabbbbv",
      "     k   dabbbbv",
      "         dabbbbv",
      "        edabbbbv",
      "  j   lm dabbbbv",
      "ddddddddddabbbbv",
      "aaaaaaaaaaabbbbv",
      "bbbbbbbbbbbbbbbv",
      "bbbbbbbbbbbbbbbv",
      "bbbbbbbbbbbbbbbv",
      "bbbbbbbbbbbbbbbv",
      "bbbbbbbbbbbbbbbv",
      "bbbbbbbbbbbbbbbv",
      "vvvvvvvvvvvvvvvv"
    ],
    [
      "         dabbbbv",
      "         dabbbbv",
      "         dabbbbv",
      "         dabbbbv",
      "         dabbbbv",
      "         dabbbbv",
      "         dabbbbv",
      "ddddddddddabbbbv",
      "aaaaaaaaaaabbbbv",
      "bbbbbbbbbbbbbbbv",
      "bbbbbbbbbbbbbbbv",
      "bbbbbbbbbbbbbbbv",
      "bbbbbbbbbbbbbbbv",
      "bbbbbbbbbbbbbbbv",
      "bbbbbbbbbbbbbbbv",
      "vvvvvvvvvvvvvvvv"
    ],
    [
      "         dabbbbv",
      "         dabbbbv",
      "         dabbbbv",
      "         dabbbbv",
      "         dabbbbv",
      "         dabbbbv",
      "         dabbbbv",
      "ddddddddddabbbbv",
      "aaaaaaaaaaabbbbv",
      "bbbbbbbbbbbbbbbv",
      "bbbbbbbbbbbbbbbv",
      "bbbbbbbbbbbbbbbv",
      "bbbbbbbbbbbbbbbv",
      "bbbbbbbbbbbbbbbv",
      "bbbbbbbbbbbbbbbv",
      "vvvvvvvvvvvvvvvv"
    ],
    [
      "         dabbbbv",
      "         dabbbbv",
      "         dabbbbv",
      "         dabbbbv",
      "         dabbbbv",
      "         dabbbbv",
      "         dabbbbv",
      "ddddddddddabbbbv",
      "aaaaaaaaaaabbbbv",
      "bbbbbbbbbbbbbbbv",
      "bbbbbbbbbbbbbbbv",
      "bbbbbbbbbbbbbbbv",
      "bbbbbbbbbbbbbbbv",
      "bbbbbbbbbbbbbbbv",
      "bbbbbbbbbbbbbbbv",
      "vvvvvvvvvvvvvvvv"
    ]
  ]
}