{
  "name": "multi_filmworkstower_23_floor2",
  "refpalette": "deceasedcraft:multi_filmworkstower_23/multi_filmworkstower_23_floor2_palette",
  "xsize": 16,
  "zsize": 16,
  "slices": [
    [
      "aaaaaaaaaabcd   ",
      "aaaaaaaaaabcd   ",
      "aaaaaaaaaabcd   ",
      "aaaaaaaaaabcd   ",
      "aaaaaaaaaabcd   ",
      "aaaaaaaaaabcd   ",
      "caaaaaaaaabcd   ",
      "bbbbbbbbbbbcd   ",
      "ccccccccccccd   ",
      "ddddddddddddd   ",
      "                ",
      "                ",
      "                ",
      "                ",
      "                ",
      "                "
    ],
    [
      "          efd   ",
      "          efd   ",
      "        g efd   ",
      "     hh i efd   ",
      "        j efd   ",
      "    klllm efd   ",
      "cn        efd   ",
      "eeeeeeeeeeefd   ",
      "ffffffffffffd   ",
      "ddddddddddddd   ",
      "                ",
      "                ",
      "                ",
      "                ",
      "                ",
      "                "
    ],
    [
      "           od   ",
      "           od   ",
      "        p  od   ",
      "           od   ",
      "           od   ",
      "           od   ",
      " qn        od   ",
      "           od   ",
      "ooooooooooood   ",
      "ddddddddddddd   ",
      "                ",
      "                ",
      "                ",
      "                ",
      "                ",
      "                "
    ],
    [
      "           od   ",
      "           od   ",
      "           od   ",
      "           od   ",
      "           od   ",
      "           od   ",
      "  qn       od   ",
      "           od   ",
      "ooooooooooood   ",
      "ddddddddddddd   ",
      "                ",
      "                ",
      "                ",
      "                ",
      "                ",
      "                "
    ],
    [
      "           od   ",
      "            d   ",
      "           od   ",
      "           od   ",
      "           od   ",
      "           od   ",
      "   qn       d   ",
      "           od   ",
      "ooooo oooo od   ",
      "ddddddddddddd   ",
      "                ",
      "                ",
      "                ",
      "                ",
      "                ",
      "                "
    ],
    [
      "           od   ",
      "            d   ",
      "            d   ",
      "            d   ",
      "           od   ",
      "            d   ",
      "    qn      d   ",
      "            d   ",
      "  oo   o   od   ",
      "ddddddddddddd   ",
      "                ",
      "                ",
      "                ",
      "                ",
      "                ",
      "                "
    ]
  ]
}