{
  "name": "multi_filmworkstower_23_base1",
  "refpalette": "deceasedcraft:multi_filmworkstower_23/multi_filmworkstower_23_base1_palette",
  "xsize": 16,
  "zsize": 16,
  "slices": [
    [
      "         a    bv",
      "         a    bv",
      "         a    bv",
      "         a    bv",
      "         a    bv",
      "         a    bv",
      "         ac   bv",
      "aaaaaaaaaa    bv",
      "              bv",
      "              bv",
      "              bv",
      "              bv",
      "              bv",
      "bbbbbbbbbbbbbbbv",
      "dddddddddddddddv",
      "vvvvvvvvvvvvvvvv"
    ],
    [
      "         a    bv",
      "         a    bv",
      "         a    bv",
      "         a    bv",
      "         a    bv",
      "         ae   bv",
      "         acf  bv",
      "aaaaaaaaaa    bv",
      "              bv",
      "              bv",
      "              bv",
      "              bv",
      "              bv",
      "bbbbbbbbbbbbbbbv",
      "dddddddddddddddv",
      "vvvvvvvvvvvvvvvv"
    ],
    [
      "         ag   bv",
      "         ag   bv",
      "         ag   bv",
      "         ag   bv",
      "         ag   bv",
      "         ag   bv",
      "         achhhbv",
      "aaaaaaaaaa    bv",
      "              bv",
      "              bv",
      "              bv",
      "              bv",
      "              bv",
      "bbbbbbbbbbbbbbbv",
      "dddddddddddddddv",
      "vvvvvvvvvvvvvvvv"
    ],
    [
      "   i          bv",
      "   i          bv",
      "   i          bv",
      "   i          bv",
      "   i          bv",
      "              bv",
      "         jck  bv",
      "              bv",
      "              bv",
      "              bv",
      "              bv",
      "              bv",
      "              bv",
      "bbbbbbbbbbbbbbbv",
      "dddddddddddddddv",
      "vvvvvvvvvvvvvvvv"
    ],
    [
      "lmlllmlnopqpppbv",
      "lmlllmlnopqpppbv",
      "lmlllmlnopqpppbv",
      "lrlllrlnopqpppbv",
      "nnnnnnnnopqpppbv",
      "ooooooooopqpppbv",
      "ppppppppppspppbv",
      "ppppppppppppppbv",
      "ppppppppppppppbv",
      "ppppppppppppppbv",
      "ppppppppppppppbv",
      "ppppppppppppppbv",
      "ppppppppppppppbv",
      "bbbbbbbbbbbbbbbv",
      "dddddddddddddddv",
      "vvvvvvvvvvvvvvvv"
    ],
    [
      "ttttttttttttttbv",
      "ttttttttttttttbv",
      "ttttttttttttttbv",
      "ttttttttttttttbv",
      "ttttttttttttttbv",
      "ttttttttttttttbv",
      "ttttttttttttttbv",
      "ttttttttttttttbv",
      "ttttttttttttttbv",
      "ttttttttttttttbv",
      "ttttttttttttttbv",
      "ttttttttttttttbv",
      "ttttttttttttttbv",
      "bbbbbbbbbbbbbbbv",
      "dddddddddddddddv",
      "vvvvvvvvvvvvvvvv"
    ]
  ]
}