{
  "name": "multi_alienresearch_12_base6",
  "refpalette": "deceasedcraft:multi_alienresearch_12/multi_alienresearch_12_base6_palette",
  "xsize": 16,
  "zsize": 16,
  "slices": [
    [
      "vvvvvvvvvvvvvvvv",
      "aaaaaaaaaaaaaaav",
      "aaaaaaaaaaaaaaav",
      "aaaaaaaaaaaaaaav",
      "aaaaaaaaaaaaaaav",
      "aaaaaaaaaaaaaaav",
      "aaaaaaaaaaaaaaav",
      "aaaaaaaaaaaaaaav",
      "aaaaaaaaaaaaaaav",
      "aaaaaaaaaaaaaaav",
      "aaaaaaaaaaabccbv",
      "aaaaaaaaaaab  bv",
      "aaaaaaaaaaab  bv",
      "aaaaaaaaaaab  bv",
      "aaaaaaaaaaab  bv",
      "daaaaaaaaaabeefv"
    ],
    [
      "vvvvvvvvvvvvvvvv",
      "aaaaaaaaaaaaaaav",
      "aaaaaaaaaaaaaaav",
      "aaaaaaaaaaaaaaav",
      "aaaaaaaaaaaaaaav",
      "aaaaaaaaaaaaaaav",
      "aaaaaaaaaaaaaaav",
      "aaaaaaaaaaaaaaav",
      "aaaaaaaaaaaaaaav",
      "aaaaaaaaaaabccgv",
      "aaaaaaaaaaab  bv",
      "aaaaaaaaaaab  bv",
      "aaaaaaaaaaab  bv",
      "aaaaaaaaaaab  bv",
      "aaaaaaaaaaabeebv",
      "daaaaaaaaaaaaaav"
    ],
    [
      "vvvvvvvvvvvvvvvv",
      "aaaaaaaaaaaaaaav",
      "aaaaaaaaaaaaaaav",
      "aaaaaaaaaaaaaaav",
      "aaaaaaaaaaaaaaav",
      "aaaaaaaaaaaaaaav",
      "aaaaaaaaaaaaaaav",
      "aaaaaaaaaaaaaaav",
      "aaaaaaaaaaabccbv",
      "aaaaaaaaaaab  fv",
      "aaaaaaaaaaab  bv",
      "aaaaaaaaaaab  bv",
      "aaaaaaaaaaab  bv",
      "aaaaaaaaaaabeebv",
      "daaaaaaaaaaaaaav",
      "daaaaaaaaaaaaaav"
    ],
    [
      "vvvvvvvvvvvvvvvv",
      "aaaaaaaaaaaaaaav",
      "aaaaaaaaaaaaaaav",
      "aaaaaaaaaaaaaaav",
      "aaaaaaaaaaaaaaav",
      "aaaaaaaaaaaaaaav",
      "aaaaaaaaaaaaaaav",
      "aaaaaaaaaaabccbv",
      "aaaaaaaaaaab  bv",
      "aaaaaaaaaaab  fv",
      "aaaaaaaaaaab  bv",
      "aaaaaaaaaaab  bv",
      "aaaaaaaaaaabeebv",
      "aaaaaaaaaaaaaaav",
      "daaaaaaaaaaaaaav",
      "daaaaaaaaaaaaaav"
    ],
    [
      "vvvvvvvvvvvvvvvv",
      "aaaaaaaaaaaaaaav",
      "aaaaaaaaaaaaaaav",
      "aaaaaaaaaaaaaaav",
      "aaaaaaaaaaaaaaav",
      "aaaaaaaaaaaaaaav",
      "aaaaaaaaaaabccbv",
      "aaaaaaaaaaab  bv",
      "aaaaaaaaaaab  bv",
      "aaaaaaaaaaab  fv",
      "aaaaaaaaaaab  bv",
      "aaaaaaaaaaabeebv",
      "aaaaaaaaaaaaaaav",
      "aaaaaaaaaaaaaaav",
      "daaaaaaaaaaaaaav",
      "daaaaaaaaaaaaaav"
    ],
    [
      "vvvvvvvvvvvvvvvv",
      "aaaaaaaaaaaaaaav",
      "aaaaaaaaaaaaaaav",
      "aaaaaaaaaaaaaaav",
      "aaaaaaaaaaaaaaav",
      "aaaaaaaaaaabccbv",
      "aaaaaaaaaaab  bv",
      "aaaaaaaaaaab  bv",
      "aaaaaaaaaaab  bv",
      "aaaaaaaaaaab  fv",
      "aaaaaaaaaaabeebv",
      "aaaaaaaaaaaaaaav",
      "aaaaaaaaaaaaaaav",
      "aaaaaaaaaaaaaaav",
      "haaaaaaaaaaaaaav",
      "haaaaaaaaaaaaaav"
    ]
  ]
}