{
  "name": "multi_alienresearch_12_base5",
  "refpalette": "deceasedcraft:multi_alienresearch_12/multi_alienresearch_12_base5_palette",
  "xsize": 16,
  "zsize": 16,
  "slices": [
    [
      "vvvvvvvvvvvvvvvv",
      "aaaaaaaaaaaabbbv",
      "aaaaaaaaaaaaccbv",
      "aaaaaaaaaaaaccbv",
      "aaaaaaaaaaabddbv",
      "aaaaaaaaaaab  bv",
      "aaaaaaaaaaab  bv",
      "aaaaaaaaaaab  bv",
      "aaaaaaaaaaab  bv",
      "aaaaaaaaaaabeefv",
      "aaaaaaaaaaaaaaav",
      "aaaaaaaaaaaaaaav",
      "aaaaaaaaaaaaaaav",
      "aaaaaaaaaaaaaaav",
      "gaaaaaaaaaaaaaav",
      "gaaaaaaaaaaaaaav"
    ],
    [
      "vvvvvvvvvvvvvvvv",
      "aaaaaaaaaaahbbbv",
      "aaaaaaaaaaai  bv",
      "aaaaaaaaaaai jfv",
      "aaaaaaaaaaab  bv",
      "aaaaaaaaaaab  bv",
      "aaaaaaaaaaab  bv",
      "aaaaaaaaaaab  bv",
      "aaaaaaaaaaabeebv",
      "aaaaaaaaaaaaaaav",
      "aaaaaaaaaaaaaaav",
      "aaaaaaaaaaaaaaav",
      "aaaaaaaaaaaaaaav",
      "aaaaaaaaaaaaaaav",
      "gaaaaaaaaaaaaaav",
      "gaaaaaaaaaaaaaav"
    ],
    [
      "vvvvvvvvvvvvvvvv",
      "aaaaaaaaaabfbbbv",
      "aaaaaaaaaai   bv",
      "aaaaaaaaaai   fv",
      "aaaaaaaaaabb  bv",
      "aaaaaaaaaaab  bv",
      "aaaaaaaaaaab  bv",
      "aaaaaaaaaaabeebv",
      "aaaaaaaaaaaaaaav",
      "aaaaaaaaaaaaaaav",
      "aaaaaaaaaaaaaaav",
      "aaaaaaaaaaaaaaav",
      "aaaaaaaaaaaaaaav",
      "aaaaaaaaaaaaaaav",
      "kaaaaaaaaaaaaaav",
      "kaaaaaaaaaaaaaav"
    ],
    [
      "vvvvvvvvvvvvvvvv",
      "aaaaaaaaabbfbbbv",
      "aaaaaaaaai    bv",
      "aaaaaaaaai    fv",
      "aaaaaaaaabbb  bv",
      "aaaaaaaaaaab  bv",
      "aaaaaaaaaaabeebv",
      "aaaaaaaaaaaaaaav",
      "aaaaaaaaaaaaaaav",
      "aaaaaaaaaaaaaaav",
      "aaaaaaaaaaaaaaav",
      "aaaaaaaaaaaaaaav",
      "aaaaaaaaaaaaaaav",
      "aaaaaaaaaaaaaaav",
      "kaaaaaaaaaaaaaav",
      "kaaaaaaaaaaaaaav"
    ],
    [
      "vvvvvvvvvvvvvvvv",
      "aaaaaaaabbbfbbbv",
      "aaaaaaaai     bv",
      "aaaaaaaai     fv",
      "aaaaaaaabbbb  bv",
      "aaaaaaaaaaabeebv",
      "aaaaaaaaaaaaaaav",
      "aaaaaaaaaaaaaaav",
      "aaaaaaaaaaaaaaav",
      "aaaaaaaaaaaaaaav",
      "aaaaaaaaaaaaaaav",
      "aaaaaaaaaaaaaaav",
      "aaaaaaaaaaaaaaav",
      "aaaaaaaaaaaaaaav",
      "kaaaaaaaaaaaaaav",
      "kaaaaaaaaaaaaaav"
    ],
    [
      "vvvvvvvvvvvvvvvv",
      "aaaaaaabbbbfbbbv",
      "aaaaaaai      bv",
      "aaaaaaai      fv",
      "aaaaaaabbbbbeebv",
      "aaaaaaaaaaaaaaav",
      "aaaaaaaaaaaaaaav",
      "aaaaaaaaaaaaaaav",
      "aaaaaaaaaaaaaaav",
      "aaaaaaaaaaaaaaav",
      "aaaaaaaaaaaaaaav",
      "aaaaaaaaaaaaaaav",
      "aaaaaaaaaaaaaaav",
      "aaaaaaaaaaaaaaav",
      "aaaaaaaaaaaaaaav",
      "kaaaaaaaaaaaaaav"
    ]
  ]
}