{
  "name": "multi_alienresearch_12_ground",
  "refpalette": "deceasedcraft:multi_alienresearch_12/multi_alienresearch_12_ground_palette",
  "xsize": 16,
  "zsize": 16,
  "slices": [
    [
      "zzzzaazzzzzzazzz",
      "zaazzazzazzzzzzz",
      "azzaazazzzzaazaz",
      "zzazazzzazazzazz",
      "azzazazazazzzzzz",
      "azzzzaazzazazzzz",
      "zzazazzzazazazaz",
      "aazzazabzzzbzazz",
      "bzzabazaazzazbzz",
      "aazzzbazbzazazzz",
      "bazbzazababaaazz",
      "bzabbbabzzabbazz",
      "bbaabbbbzbbbazzz",
      "bbbbbbbzbbbzabaz",
      "bbzbbabbbbabbazz",
      "bbbbbbabbbbbaazz"
    ],
    [
      "c       c     c ",
      "            c   ",
      "     c c        ",
      "ddddddddddddddc ",
      " cc        c d  ",
      "        c   cdc ",
      "     c       d  ",
      "   c     c   d  ",
      "          c cd c",
      "   c   c c   d  ",
      "    ceeee    dc ",
      "    fggggf   d  ",
      "   hgiggigj  d  ",
      "   hgiggigjc d  ",
      "   hgiiiigj  dc ",
      "   hgiggigj  d  "
    ],
    [
      "                ",
      "                ",
      "                ",
      "dddddddddddddd  ",
      "             d  ",
      "             d  ",
      "             d  ",
      "             d  ",
      "             d  ",
      "             d  ",
      "             d  ",
      "             d  ",
      "             d  ",
      "             d  ",
      "             d  ",
      "             d  "
    ],
    [
      "                ",
      "                ",
      "                ",
      "dddddddddddddd  ",
      "             d  ",
      "             d  ",
      "             d  ",
      "             d  ",
      "             d  ",
      "             d  ",
      "                ",
      "                ",
      "             d  ",
      "             d  ",
      "             d  ",
      "             d  "
    ],
    [
      "                ",
      "                ",
      "                ",
      "kkkkkkkkkkkkkk  ",
      "             k  ",
      "             k  ",
      "             k  ",
      "             k  ",
      "             k  ",
      "             k  ",
      "                ",
      "             k  ",
      "             k  ",
      "             k  ",
      "             k  ",
      "             k  "
    ],
    [
      "                ",
      "                ",
      "                ",
      "                ",
      "                ",
      "                ",
      "                ",
      "                ",
      "                ",
      "                ",
      "                ",
      "                ",
      "                ",
      "                ",
      "                ",
      "                "
    ]
  ]
}