{
  "name": "multi_alienresearch_12_base3",
  "refpalette": "deceasedcraft:multi_alienresearch_12/multi_alienresearch_12_base3_palette",
  "xsize": 16,
  "zsize": 16,
  "slices": [
    [
      "vvvvvvvvvvvvvvvv",
      "aaaaabcccccccccv",
      "d    ecccccccccv",
      "d    ecccccccccv",
      "aaaaaacccccccccv",
      "cccccccccccccccv",
      "cccccccccccccccv",
      "cccccccccccccccv",
      "cccccccccccccccv",
      "cccccccccccccccv",
      "cccccccccccccccv",
      "cccccccccccccccv",
      "cccccccccccccccv",
      "cccccccccccccccv",
      "cccccccccccccccv",
      "cccccccccccccccv"
    ],
    [
      "vvvvvvvvvvvvvvvv",
      "aaaaaccccccccccv",
      "    eccccccccccv",
      "    eccccccccccv",
      "aaaaaccccccccccv",
      "cccccccccccccccv",
      "cccccccccccccccv",
      "cccccccccccccccv",
      "cccccccccccccccv",
      "cccccccccccccccv",
      "cccccccccccccccv",
      "cccccccccccccccv",
      "cccccccccccccccv",
      "cccccccccccccccv",
      "cccccccccccccccv",
      "cccccccccccccccv"
    ],
    [
      "vvvvvvvvvvvvvvvv",
      "aaaacccccccccccv",
      "   ecccccccccccv",
      "   ecccccccccccv",
      "aaaacccccccccccv",
      "cccccccccccccccv",
      "cccccccccccccccv",
      "cccccccccccccccv",
      "cccccccccccccccv",
      "cccccccccccccccv",
      "cccccccccccccccv",
      "cccccccccccccccv",
      "cccccccccccccccv",
      "cccccccccccccccv",
      "cccccccccccccccv",
      "cccccccccccccccv"
    ],
    [
      "vvvvvvvvvvvvvvvv",
      "aaaccccccccccccv",
      "  eccccccccccccv",
      "  eccccccccccccv",
      "aaaccccccccccccv",
      "cccccccccccccccv",
      "cccccccccccccccv",
      "cccccccccccccccv",
      "cccccccccccccccv",
      "cccccccccccccccv",
      "cccccccccccccccv",
      "cccccccccccccccv",
      "cccccccccccccccv",
      "cccccccccccccccv",
      "cccccccccccccccv",
      "cccccccccccccccv"
    ],
    [
      "vvvvvvvvvvvvvvvv",
      "aacccccccccccccv",
      " ecccccccccccccv",
      " ecccccccccccccv",
      "aacccccccccccccv",
      "cccccccccccccccv",
      "cccccccccccccccv",
      "cccccccccccccccv",
      "cccccccccccccccv",
      "cccccccccccccccv",
      "cccccccccccccccv",
      "cccccccccccccccv",
      "cccccccccccccccv",
      "cccccccccccccccv",
      "cccccccccccccccv",
      "cccccccccccccccv"
    ],
    [
      "vvvvvvvvvvvvvvvv",
      "accccccccccccccv",
      "eccccccccccccccv",
      "eccccccccccccccv",
      "accccccccccccccv",
      "cccccccccccccccv",
      "cccccccccccccccv",
      "cccccccccccccccv",
      "cccccccccccccccv",
      "cccccccccccccccv",
      "cccccccccccccccv",
      "cccccccccccccccv",
      "cccccccccccccccv",
      "cccccccccccccccv",
      "cccccccccccccccv",
      "cccccccccccccccv"
    ]
  ]
}