{
  "xsize": 16,
  "zsize": 16,
  "refpalette": "lce2:quarry",
  "slices": [
    [
      "~~~~~~~~~~!~!~~'",
      "~~~~~~~~~~!~!~~!",
      "~~~~~~~~~~!~!~~!",
      "~~~~~~~~~~~~!~66",
      "~~~~~~~~~~~~!~~'",
      "~~~~~~~~~~~~!~~~",
      "~~~~~~~~~~~!!!~~",
      "~~~~~~~~~~~!!!~~",
      "~~~~~~~~~~~!!!~~",
      "~~~~~~~~~~~~!~~~",
      "~~~~~~~~~~~~!~~~",
      "~~~~~~~~~~~~!~~~",
      "~~~~~~~~~~~~!~~~",
      "~~~~~~~~~~~~!~~~",
      "~~~~~~~~~~~~!~~~",
      "~~~~~~~~~~~~!~~!"
    ],
    [
      "~~~~~~~~~~~~~~~'",
      "~~~~~~~~~~~~~~~!",
      "~~~~~~~~~~!~~~66",
      "~~~~~~~~~~!~~~~!",
      "~~~~~~~~~~!~~~~~",
      "~~~~~~~~~~~~~~~~",
      "~~~~~~~~~~~~!~~~",
      "~~~~~~~~~~~~!~~~",
      "~~~~~~~~~~~~!~~~",
      "~~~~~~~~~~~~~~~~",
      "~~~~~~~~~~~~~~~~",
      "~~~~~~~~~~~~~~~~",
      "~~~~~~~~~~~~~~~~",
      "~~~~~~~~~~~~~~~~",
      "~~~~~~~~~~~~~~~~",
      "~~~~~~~~~~~~~~~~"
    ],
    [
      "~~~~~~~~~~~~~~!!",
      "~~~~~~~~~~~~~~66",
      "~~~~~~~~~~~~~~66",
      "~~~~~~~~~~~~~~~!",
      "~~~~~~~~~~!~~~~~",
      "~~~~~~~~~~!~~~~~",
      "~~~~~~~~~~!~~~~~",
      "~~~~~~~~~~!~~~~~",
      "~~~~~~~~~~~~~~~~",
      "~~~~~~~~~~~~~~~~",
      "~~~~~~~~~~~~~~~~",
      "~~~~~~~~~~~~~~~~",
      "~~~~~~~~~~~~~~~~",
      "~~~~~~~~~~~~~~~~",
      "~~~~~~~~~~~~~~~~",
      "~~~~~~~~~~~~~~~~"
    ],
    [
      "~~~~~~~~~~~~~~66",
      "~~~~~~~~~~~~~~66",
      "~~~~~~~~~~~~~~!!",
      "~~~~~~~~~~~~~~~~",
      "~~~~~~~~~~~~~~~~",
      "~~~~~~~~~~~~~~''",
      "~~~~~~~~~~~~~~''",
      "~~~~~~~~~~!~~~~~",
      "~~~~~~~~~~!~~~~~",
      "~~~~~~~~~~!~~~~~",
      "~~~~~~~~~~!~~~~~",
      "~~~~~~~~~~~~~~~~",
      "~~~~~~~~~~~~~~~~",
      "~~~~~~~~~~~~~~~~",
      "~~~~~~~~~~~~~~~~",
      "~~~~~~~~~~~~~~~~"
    ],
    [
      "~~~~~~~~~~~~~~66",
      "~~~~~~~~~~~~~~!'",
      "~~~~~~~~~~~~~~!!",
      "~~~~~~~~~~~~~~!!",
      "~~~~~~~~~~~~~~''",
      "~~~~~~~~~~~~~~''",
      "~~~~~~~~~~~~~~~~",
      "~~~~~~~~~~~~~~~~",
      "~~~~~~~~~~~~~~~~",
      "~~~~~~~~~~~~~~~~",
      "~~~~~~~~~~!~~~~~",
      "~~~~~~~~~~!~~~~~",
      "~~~~~~~~~~!~~~~~",
      "~~~~~~~~~~!~~~~~",
      "~~~~~~~~~~~~~~~~",
      "~~~~~~~~~~~~~~~~"
    ],
    [
      "~~~~~~~~~~~~~~~'",
      "~~~~~~~~~~~~~~!'",
      "~~~~~~~~~~~~~~~'",
      "~~~~~~~~~~~~~~!'",
      "~~~~~~~~~~~~~~~'",
      "~~~~~~~~~~~~~~~~",
      "~~~~~~~~~~~~~~~~",
      "~~~~~~~~~~~~~~~~",
      "~~~~~~~~~~~~~~~~",
      "~~~~~~~~~~~~~~~~",
      "~~~~~~~~~~~~~~~~",
      "~~~~~~~~~~~~~~~~",
      "~~~~~~~~~~~~~~~~",
      "~~~~~~~~~~!~~~~~",
      "~~~~~~~~~~!~~~~~",
      "~~~~~~~~~~!~~~~~"
    ]
  ]
}