{
  "name": "multi_polyclinic_1_ground",
  "refpalette": "deceasedcraft:multi_polyclinic_1/multi_polyclinic_1_ground_palette",
  "xsize": 16,
  "zsize": 16,
  "slices": [
    [
      "aaaaaaaaaaaaaaaa",
      "aaaaaaaaaaaaaaaa",
      "bbbbbbbbbbbbbaaa",
      "ccccccccccccccca",
      "ddedddedddeddaaa",
      "fffffffffffddgag",
      "fffffffffffddggg",
      "fffffffffffdddga",
      "ddddddddddddddag",
      "ffdffffdddddddaa",
      "ffdffffdddddddaa",
      "ffdffffdddddddaa",
      "ffdffffdddddddaa",
      "ddddddddddddddaa",
      "ddddddddddddddaa",
      "aaaaaaaaaaaaaaaa"
    ],
    [
      "                ",
      "hhhhhhhhhhhhh   ",
      "iiiiiiiiiiiii   ",
      "jjjjjjjjjjjjjjj ",
      "iihiiihiiihk lm ",
      "no pno pno q    ",
      "           r    ",
      "           q    ",
      "stuuwuuuuxuuu   ",
      "  y    A   Bu   ",
      "  y  CCyDD Eu   ",
      "F I JKLyMNOPu   ",
      "QRy! S T UO u   ",
      "uuuuuuuuuuuuu   ",
      " V  V  V  V     ",
      "                "
    ],
    [
      "                ",
      "                ",
      "WOWOX WOYOZO    ",
      "jjjjjjjjjjjjjjj ",
      "00100010001k    ",
      "           q    ",
      "           2    ",
      "           q    ",
      "34yy5yyyy6yyy   ",
      " 7y    8  9 y   ",
      " #y$   yDD  y   ",
      "  %  ^&y**O(y   ",
      ")+y-   [  O]y   ",
      "yyyyyyyyyyyyy   ",
      " V  V  V  V     ",
      "                "
    ],
    [
      "                ",
      "                ",
      " OZOOO O{O{O    ",
      "jjjjjjjjjjjjjjj ",
      "           k    ",
      "           q    ",
      "           q    ",
      "    }    | q    ",
      ";;yy;yyyy;yyy   ",
      "  y    :   'y   ",
      "  y    yDD  y   ",
      "  <    y>,O y   ",
      "+)y    y UO.y   ",
      "???////yyyyyy   ",
      " V  V  V  V     ",
      "                "
    ],
    [
      "                ",
      "                ",
      "     `     `    ",
      "jjjjjjjjjjjjjjj ",
      "           k    ",
      "           k    ",
      "           k    ",
      "           k    ",
      "yyyyyyyyyyyyy   ",
      "  y    y    y   ",
      "  y    yDD` y   ",
      "  y    y UO y   ",
      "\u0370\u0371y    yU!O\u0372y   ",
      "yyyyyyyyyyyyy   ",
      " V  V  V  V     ",
      "                "
    ],
    [
      "                ",
      "\u0373\u0373\u0373\u0373\u0373\u0373\u0373\u0373\u0373\u0373\u0373\u0373\u0373\u0373  ",
      "\u0374\u0374\u0374\u0374\u0374\u0374\u0374\u0374\u0374\u0374\u0374\u0374\u0374\u0373  ",
      "  \u0374    \u0374    \u0374\u0373  ",
      "\u0375\u0375\u0374\u0375\u0375\u0375\u0375\u0374\u0375\u0375\u0375\u0375\u0374\u0373  ",
      "\u0375\u0375\u0374\u0375\u0375\u0375\u0375\u0374\u0375\u0375\u0375\u0375\u0374\u0373  ",
      "\u0375\u0375\u0374\u0375\u0375\u0375\u0375\u0374\u0375\u0375\u0375\u0375\u0374\u0373  ",
      "\u0375\u0375\u0374\u0375\u0375\u0375\u0375\u0374\u0375\u0375\u0375\u0375\u0374\u0373  ",
      "yyyyyyyyyyyyy\u0373  ",
      "\u0376\u0376y\u0376\u0376\u0376\u0376y\u0376\u0376\u0376\u0376y\u0373  ",
      "\u0376\u0376y\u0376\u0376\u0376\u0376y\u0376\u0376\u0376\u0376y\u0373  ",
      "\u0376\u0376y\u0376\u0376\u0376\u0376y\u0376\u0376\u0376\u0376y\u0373  ",
      "\u0376\u0376y\u0376\u0376\u0376\u0376y\u0377\u037a\u037a\u0377y\u0373  ",
      "yyyyyyyyyyyyy\u0373  ",
      "\u0373\u0373\u0373\u0373\u0373\u0373\u0373\u0373\u0373\u0373\u0373\u0373\u0373\u0373  ",
      "                "
    ]
  ]
}