{
  "name": "multi_terraceplaza_19_base2",
  "refpalette": "deceasedcraft:multi_terraceplaza_19/multi_terraceplaza_19_base2_palette",
  "xsize": 16,
  "zsize": 16,
  "slices": [
    [
      "abccccccccccccba",
      "abccccccccccccba",
      "abccccccccccccba",
      "abccccccccccccba",
      "adccccccccccccda",
      "abccccccccccccba",
      "abccccccccccccba",
      "abccccccccccccba",
      "abccccccccccccba",
      "abccccccccccccba",
      "abccccccccccccba",
      "abccccccccccccba",
      "abccccccccccccba",
      "abccccccccccccba",
      "abccccccccccccba",
      "adccccccccccccda"
    ],
    [
      "efghijiij jkhgfl",
      "efgh ii   iihgfl",
      "efgmn      opgfq",
      " fgh        hgfq",
      "rdgsssstussssgdw",
      " fgx        ygfA",
      "BfgC        ygfA",
      "Bfgx  DEFI  ygfA",
      "Bfg   JEFK  ygfA",
      " fgx  IEFK  ygfA",
      "BfgL  DEFJ  ygfA",
      "Bfgx  JEFI  ygfA",
      "BfgM~       ygfA",
      "NfgO   PP   QgfA",
      "rfggRSggggTSggfw",
      "wdUU  VVVV  UUdw"
    ],
    [
      " fgj   i   jigf ",
      " fg          gf ",
      " fg          gf ",
      " fgh        hgf ",
      "rdgssssWXssssgdw",
      " fg         YgfZ",
      " fg         Ygf0",
      " fg         1gf2",
      " fg    34    gf5",
      " fg    63   7gf8",
      " fg    9    Ygf#",
      " fg     3   4gf2",
      " fg          gf$",
      " fg          gf%",
      "rfgg^&gggg*&ggfw",
      "wd((   )+)  ((dw"
    ],
    [
      " f------------f ",
      " fg[[[[[[[[[[gf ",
      " fg          gf ",
      " fgh        hgf]",
      "rdgssssssssssgdw",
      " fg          gf{",
      " fg          gf}",
      " fg|        |gf ",
      " fg          gf ",
      " fg          gf ",
      " fg|        |gf ",
      " fg          gf;",
      " fg         :gf{",
      " fg|        |gf}",
      "rfggggggggggggfw",
      "wd    ''''    dw"
    ],
    [
      " ffffffffffffff ",
      " ffffffffffffff ",
      " f------------f ",
      " fgh[[[[[[[[hgf ",
      "rdgh<<<<<<<<hgdw",
      " fgh        hgf ",
      " fgh        hgf ",
      " fgh        hgf ",
      " fgh        hgf ",
      " fgh        hgf ",
      " fgh        hgf ",
      " fgh        hgf ",
      " fgh        hgf ",
      " fgh:       hgf ",
      "rfggggggggggggfw",
      "wd            dw"
    ],
    [
      ">,            . ",
      "?f////////////f ",
      ">ffffffffffffff ",
      "?f``ffffffff``f ",
      "rd------------dw",
      ">fg[[[[[[[[[[gf ",
      "?fg          gf ",
      ">fg          gf ",
      "?fg          gf ",
      ">fg          gf ",
      "?fg:         gf ",
      ">fg         :gf ",
      "?fg:        :gf ",
      ">fgh: \u0370\u0371\u0371\u0370  hgf ",
      "rfggggggggggggfw",
      "wd\u0372\u0372\u0372\u0372\u0372\u0372\u0372\u0372\u0372\u0372\u0372\u0372dw"
    ]
  ]
}