{
  "name": "multi_terraceplaza_19_ground",
  "refpalette": "deceasedcraft:multi_terraceplaza_19/multi_terraceplaza_19_ground_palette",
  "xsize": 16,
  "zsize": 16,
  "slices": [
    [
      "ab            ca",
      "ab            ca",
      "db            cd",
      "eb            ce",
      "efg          hfe",
      "ab            ca",
      "ab            ca",
      "ab            ca",
      "ab            ca",
      "ab            ca",
      "ab            ca",
      "ab            ca",
      "ab            ca",
      "ab            ca",
      "ab            ca",
      "ifjjjkkkkkkjjjfi"
    ],
    [
      " l            l ",
      "dl            ld",
      "ml            lm",
      "nl            lo",
      "nf            fo",
      " l            l ",
      " l            l ",
      " l            l ",
      " l            l ",
      " l            l ",
      " l            l ",
      " l            l ",
      " l            l ",
      " l            l ",
      " l            l ",
      "pf            fp"
    ],
    [
      "d              d",
      "mo            nm",
      "n              o",
      "                ",
      " f            f ",
      "                ",
      "                ",
      "                ",
      "                ",
      "                ",
      "                ",
      "                ",
      "                ",
      "                ",
      "                ",
      "pf            fp"
    ],
    [
      "mo            nm",
      "n              o",
      "                ",
      "                ",
      " f            f ",
      "                ",
      "                ",
      "                ",
      "                ",
      "                ",
      "                ",
      "                ",
      "                ",
      "                ",
      "                ",
      "pf            fp"
    ],
    [
      "n              o",
      "                ",
      "                ",
      "                ",
      " f            f ",
      "                ",
      "                ",
      "                ",
      "                ",
      "                ",
      "                ",
      "                ",
      "                ",
      "                ",
      "                ",
      "pf            fp"
    ],
    [
      "                ",
      "                ",
      "                ",
      "                ",
      " f            f ",
      "                ",
      "                ",
      "                ",
      "                ",
      "                ",
      "                ",
      "                ",
      "                ",
      "                ",
      "qqrssssssssssrqq",
      "pfrttttttttttrfp"
    ]
  ]
}