{
  "name": "multi_terraceplaza_19_base1",
  "refpalette": "deceasedcraft:multi_terraceplaza_19/multi_terraceplaza_19_base1_palette",
  "xsize": 16,
  "zsize": 16,
  "slices": [
    [
      "ab            ca",
      "ab            ca",
      "ad            ea",
      "afggfhhhhhhfggfa",
      "ijkkffffffffkkjl",
      "afmmffffffffmmfa",
      "afnnnnnnnnnnnnfa",
      "afoppppppppppofa",
      "afo          ofa",
      "afo          ofa",
      "afo          ofa",
      "afo          ofa",
      "afoq  r  r  qofa",
      "afos qtuut qsofa",
      "ifoooooooooooofl",
      "ljwwwwwwwwwwwwjl"
    ],
    [
      " b            c ",
      " b            c ",
      " b            c ",
      " dhhh      hhhe ",
      "ijxxh      hxxjl",
      " fhhhhhhhhhhhhf ",
      " ffffffffffffff ",
      " ffffffffffffff ",
      " fnnnnnnnnnnnnf ",
      " foppppppppppof ",
      " foq         of ",
      " fo          of ",
      " fo   t  t   of ",
      " fossstyyAsssof ",
      "ifoooooooooooofl",
      "ljwwwwwwwwwwwwjl"
    ],
    [
      " b            c ",
      " b            c ",
      " b            c ",
      " b            c ",
      "ij            jl",
      " b            c ",
      " d            e ",
      " fhhhhhhhhhhhhf ",
      " fBBBBBffffffff ",
      " ffffffffffffff ",
      " fnnnnnnnnnnnnf ",
      " foppppppppppof ",
      " fo   tAAt   of ",
      " foqq!tCCA  qof ",
      "ifoooooooooooofl",
      "ljwwwwwwwwwwwwjl"
    ],
    [
      "D              D",
      "D              D",
      "D              D",
      "D              D",
      "Dj            jD",
      "D              D",
      "Db            cD",
      "Db            cD",
      "DfEEEEEf      eD",
      "DfkkkkkfhhhhhhfD",
      "DffffffffffffffD",
      "DffffffffffffffD",
      "DfnnnnnnnnnnnnfD",
      "DfoppppppppppofD",
      "DfoooooooooooofD",
      "ljwwwwwwwwwwwwjD"
    ],
    [
      "D              D",
      "D              D",
      "D              D",
      "D              D",
      "Dj            jD",
      "D              D",
      "D              D",
      "Db            cD",
      "Db            cD",
      "DbFFFFF       cD",
      "Dd            eD",
      "DfhhhhhhhhhhhhfD",
      "DffffffffffffffD",
      "DffffffffffffnfD",
      "DfnnnnnnnnnnnnfD",
      "ljnnnnnnnnnnnnjD"
    ],
    [
      "mI            ID",
      "mI            ID",
      "mI            ID",
      "mI            ID",
      "Ij            jI",
      "mI            ID",
      "mI            ID",
      "mI            ID",
      "mI            ID",
      "mI            ID",
      "mI            ID",
      "mI            ID",
      "mI            ID",
      "mIhhhhhhhhhhhhID",
      "mIffffffffffffID",
      "IjIIIIIIIIIIIIjI"
    ]
  ]
}