{
  "name": "multi_terraceplaza_19_floor1",
  "refpalette": "deceasedcraft:multi_terraceplaza_19/multi_terraceplaza_19_floor1_palette",
  "xsize": 16,
  "zsize": 16,
  "slices": [
    [
      "                ",
      "                ",
      "                ",
      "                ",
      " a            a ",
      "                ",
      "                ",
      "                ",
      "                ",
      "                ",
      "                ",
      "bbcddddddddddcbb",
      "eecffffffffffcee",
      "ggcffffffffffcgg",
      "hhhhhhhhhhhhhhhh",
      "hhhhhhhhhhhhhhhh"
    ],
    [
      " i            i ",
      " i            i ",
      " i            i ",
      " i            i ",
      "ia            ai",
      "                ",
      "                ",
      "                ",
      "bbcddddddddddcbb",
      "eecffffffffffcee",
      "ggcffffffffffcgg",
      "jj            jj",
      "kk            kk",
      "                ",
      "llllllllllllllll",
      "                "
    ],
    [
      " m            n ",
      " m            n ",
      " m            n ",
      " m            n ",
      " ao          pa ",
      "bbcddddddddddcbb",
      "eecffffffffffcee",
      "ggcffffffffffcgg",
      "jj            jj",
      "kk            kk",
      "                ",
      "                ",
      "                ",
      "                ",
      "                ",
      "                "
    ],
    [
      " q            q ",
      " q            q ",
      "bqcddddddddddcqb",
      "eecffffffffffcee",
      "iacrrrrrrrrrrcai",
      "hhsssssssssssshh",
      "kk            kk",
      "                ",
      "                ",
      "                ",
      "                ",
      "                ",
      "                ",
      "                ",
      "                ",
      "                "
    ],
    [
      "eecffffffffffcee",
      "ggcffffffffffcgg",
      "jj            jj",
      "hhhhhhhhhhhhhhhh",
      "tttttttttttttttt",
      "llllllllllllllll",
      "                ",
      "                ",
      "                ",
      "                ",
      "                ",
      "                ",
      "                ",
      "                ",
      "                ",
      "                "
    ],
    [
      "kk            kk",
      "                ",
      "                ",
      "                ",
      "                ",
      "                ",
      "                ",
      "                ",
      "                ",
      "                ",
      "                ",
      "                ",
      "                ",
      "                ",
      "                ",
      "                "
    ]
  ]
}