{
  "name": "multi_terraceplaza_15_ground",
  "refpalette": "deceasedcraft:multi_terraceplaza_15/multi_terraceplaza_15_ground_palette",
  "xsize": 16,
  "zsize": 16,
  "slices": [
    [
      "abaaaaaaaaaaaaba",
      "aaaaaaaaaaaaaaaa",
      "aaaaaaaaaaaaaaaa",
      "aaaaaaaaaaaaaaaa",
      "aaaaaaaaaaaaaaaa",
      "aaaaaaaaaaaaaaaa",
      "aaaaaaaaaaaaaaaa",
      "aaaaaaaaaaaaaaaa",
      "aaaaaaaaaaaaaaaa",
      "aaaaaaaaaaaaaaaa",
      "aaaaaaaaaaaaaaaa",
      "cbccccccccccccbc",
      "dddddddddddddddd",
      "dddddddddddddddd",
      "dddddddddddddddd",
      "dddddddddddddddd"
    ],
    [
      " b            b ",
      "                ",
      "                ",
      "                ",
      "                ",
      "                ",
      "                ",
      "                ",
      "                ",
      "                ",
      "                ",
      "ebeeefggggfeeebe",
      "      hihi      ",
      "      jjjj      ",
      "                ",
      "                "
    ],
    [
      " b            b ",
      "                ",
      "                ",
      "                ",
      "                ",
      "                ",
      "                ",
      "                ",
      "                ",
      "                ",
      "                ",
      "ebeeef    feeebe",
      "      klkl      ",
      "                ",
      "                ",
      "                "
    ],
    [
      " b            b ",
      "                ",
      "                ",
      "                ",
      "                ",
      "                ",
      "                ",
      "                ",
      "                ",
      "                ",
      "                ",
      "ebeeefmnnmfeeebe",
      "      opoo      ",
      "                ",
      "                ",
      "                "
    ],
    [
      " b            b ",
      "                ",
      "                ",
      "                ",
      "                ",
      "                ",
      "                ",
      "                ",
      "                ",
      "                ",
      "                ",
      "ebeeeffffffeeebe",
      "                ",
      "                ",
      "                ",
      "                "
    ],
    [
      " b            b ",
      "                ",
      "                ",
      "                ",
      "                ",
      "                ",
      "                ",
      "                ",
      "                ",
      "                ",
      "                ",
      "ebeeeeeeeeeeeebe",
      "                ",
      "                ",
      "                ",
      "                "
    ]
  ]
}