{
  "name": "multi_terraceplaza_15_floor2",
  "refpalette": "deceasedcraft:multi_terraceplaza_15/multi_terraceplaza_15_floor2_palette",
  "xsize": 16,
  "zsize": 16,
  "slices": [
    [
      "abaaaaaaaaaaaaba",
      "                ",
      "                ",
      "                ",
      "                ",
      "                ",
      "                ",
      "                ",
      "                ",
      "                ",
      "                ",
      "cb            bc",
      "                ",
      "                ",
      "                ",
      "                "
    ],
    [
      "dbddddddddddddbd",
      " e            e ",
      "                ",
      "                ",
      "                ",
      "                ",
      "                ",
      "                ",
      "                ",
      "                ",
      "                ",
      "fb            bf",
      "                ",
      "                ",
      "                ",
      "                "
    ],
    [
      "gbggggggggggggbg",
      "  h   h h    h  ",
      "                ",
      "                ",
      "                ",
      "                ",
      "                ",
      "                ",
      "                ",
      "                ",
      "                ",
      "fb            bf",
      "                ",
      "                ",
      "                ",
      "                "
    ],
    [
      "ibiiiiiiiiiiiibi",
      "jihh hhhh h hhij",
      "ji            ij",
      "ji            ij",
      "ji            ij",
      "ji            ij",
      "ji            ij",
      "ji            ij",
      "ji            ij",
      "ji            ij",
      "ji            ij",
      "ib            bi",
      "ki            ik",
      "ki            ik",
      "ki            ik",
      "ki            ik"
    ],
    [
      "lbmnnnnnnnnnnobl",
      "lphhhhhhhhhhhhql",
      "lp            ql",
      "lp            ql",
      "lp            ql",
      "lp            ql",
      "lp            ql",
      "lp            ql",
      "lp            ql",
      "lp            ql",
      "lp            ql",
      "rbs          tbr",
      "up            qu",
      "up            qu",
      "up            qu",
      "up            qu"
    ],
    [
      " bhhhhhhhhhhhhb ",
      " whhhhhhhhhhhhw ",
      " w            w ",
      " w            w ",
      " w            w ",
      " w            w ",
      " w            w ",
      " w            w ",
      " w            w ",
      " w            w ",
      " w            w ",
      "cb            bc",
      " w            w ",
      " w            w ",
      " w            w ",
      " w            w "
    ]
  ]
}