{
  "name": "multi_terraceplaza_15_base2",
  "refpalette": "deceasedcraft:multi_terraceplaza_15/multi_terraceplaza_15_base2_palette",
  "xsize": 16,
  "zsize": 16,
  "slices": [
    [
      "HaHHHHHHHHHHHHaH",
      "HHHHHHHHHHHHHHHH",
      "HHHHHHHHHHHHHHHH",
      "HHHHHHHHHHHHHHHH",
      "HHHHHHHHHHHHHHHH",
      "HHHHHHHHHHHHHHHH",
      "HHHHHHHHHHHHHHHH",
      "HHHHHHHHHHHHHHHH",
      "HHHHHHHHHHHHHHHH",
      "bbbbbbbbbbbbbbbb",
      "bbbbbbbbbbbbbbbb",
      "caccccccccccccac",
      "dddddddddddddddd",
      "dddddddddddddddd",
      "dddddddddddddddd",
      "dddddddddddddddd"
    ],
    [
      "eaf gf gf gf gae",
      "e              e",
      "e              e",
      "e              e",
      "e              e",
      "e              e",
      "e              e",
      "e              e",
      "e              e",
      "                ",
      "                ",
      "haiiijkkkkjiiial",
      "      mnmn      ",
      "      oooo      ",
      "                ",
      "                "
    ],
    [
      " a            a ",
      "                ",
      "                ",
      "                ",
      "                ",
      "                ",
      "                ",
      "                ",
      "                ",
      "                ",
      "                ",
      "paiiij    jiiiaq",
      "      rsrs      ",
      "                ",
      "                ",
      "                "
    ],
    [
      " a            a ",
      "                ",
      "                ",
      "                ",
      "                ",
      "                ",
      "                ",
      "                ",
      "                ",
      "                ",
      "                ",
      "taiiijututjiiiau",
      "w     wwxw     w",
      "                ",
      "                ",
      "                "
    ],
    [
      " a            a ",
      "                ",
      "                ",
      "           y    ",
      "                ",
      "                ",
      "                ",
      "                ",
      "    y           ",
      "                ",
      "                ",
      "jaAAAjjjjjjAAAaj",
      "                ",
      "                ",
      "                ",
      "                "
    ],
    [
      "BaBBBBBBBBBBBBaB",
      "CBCCCCCCCCCCCCBC",
      "CBCCCCCCCCCCCCBC",
      "CBCCDCCCCCCDCCBC",
      "CBCCCCCCCCCCCCBC",
      "CBCCCCCCCCCCCCBC",
      "CBCCCCCCCCCCCCBC",
      "CBCCCCCCCCCCCCBC",
      "CBCCDCCCCCCDCCBC",
      "CBCCCCCCCCCCCCBC",
      "CBCCCCCCCCCCCCBC",
      "BaBBBBBBBBBBBBaB",
      "EBEEEEEEEEEEEEBE",
      "EBEEEEEEEEEEEEBE",
      "EBEEEEEEEEEEEEBE",
      "EBEEEEEEEEEEEEBE"
    ]
  ]
}