{
  "name": "multi_terraceplaza_15_floor5",
  "refpalette": "deceasedcraft:multi_terraceplaza_15/multi_terraceplaza_15_floor5_palette",
  "xsize": 16,
  "zsize": 16,
  "slices": [
    [
      " abbbbbbbbbbbba ",
      " b            b ",
      " b            b ",
      "cbcc        ccbc",
      "dbdeffffffffedbd",
      "gggeffffffffeggg",
      "hhe          ehh",
      "hh            hh",
      "ii            ii",
      "jj            jj",
      "                ",
      "                ",
      "                ",
      "                ",
      "                ",
      "                "
    ],
    [
      "kabbbbbbbbbbbbak",
      "dbddddddddddddbd",
      "ggggggeeeegggggg",
      "hhhheelllleehhhh",
      "hhh          hhh",
      "iii          iii",
      "jj            jj",
      "                ",
      "                ",
      "                ",
      "                ",
      "                ",
      "                ",
      "                ",
      "                ",
      "                "
    ],
    [
      "hhhhhhhhhhhhhhhh",
      "hhhhhhhhhhhhhhhh",
      "iiiiii    iiiiii",
      "jjjj        jjjj",
      "                ",
      "                ",
      "                ",
      "                ",
      "                ",
      "                ",
      "                ",
      "                ",
      "                ",
      "                ",
      "                ",
      "                "
    ],
    [
      "                ",
      "                ",
      "                ",
      "                ",
      "                ",
      "                ",
      "                ",
      "                ",
      "                ",
      "                ",
      "                ",
      "                ",
      "                ",
      "                ",
      "                ",
      "                "
    ],
    [
      "                ",
      "                ",
      "                ",
      "                ",
      "                ",
      "                ",
      "                ",
      "                ",
      "                ",
      "                ",
      "                ",
      "                ",
      "                ",
      "                ",
      "                ",
      "                "
    ],
    [
      "                ",
      "                ",
      "                ",
      "                ",
      "                ",
      "                ",
      "                ",
      "                ",
      "                ",
      "                ",
      "                ",
      "                ",
      "                ",
      "                ",
      "                ",
      "                "
    ]
  ]
}