{
  "name": "multi_terraceplaza_15_floor1",
  "refpalette": "deceasedcraft:multi_terraceplaza_15/multi_terraceplaza_15_floor1_palette",
  "xsize": 16,
  "zsize": 16,
  "slices": [
    [
      " a            a ",
      "                ",
      "                ",
      "                ",
      "                ",
      "                ",
      "                ",
      "                ",
      "                ",
      "                ",
      "                ",
      "babbbbbbbbbbbbab",
      "     c c    c   ",
      "                ",
      "                ",
      "                "
    ],
    [
      "daddddddddddddad",
      "edeeeeeeeeeeeede",
      "edeffffffffffede",
      "edefggggggggfede",
      "edefghhhhhhgfede",
      "edefghhhhhhgfede",
      "edefghhhhhhgfede",
      "edefghhhhhhgfede",
      "edefggggggggfede",
      "edeffffffffffede",
      "edeeeeeeeeeeeede",
      "daddddddddddddad",
      "hd c cccc  cc dh",
      "hd            dh",
      "hd            dh",
      "hd            dh"
    ],
    [
      "iaiiiiiiiiiiiiai",
      "jjjjjjjjjjjjjjjj",
      "jjjjjjjjjjjjjjjj",
      "jjjjjjjjjjjjjjjj",
      "jjjkjjlllljjkjjj",
      "jjjkjjlmmljjkjjj",
      "jjjkjjlmmljjkjjj",
      "jjjkjjlllljjkjjj",
      "jjjjjjjjjjjjjjjj",
      "jjjjjjjjjjjjjjjj",
      "jjjjjjjjjjjjjjjj",
      "naoppppppppppqan",
      "rscccccccccccctr",
      "rs            tr",
      "rs            tr",
      "rs            tr"
    ],
    [
      "uauuuuuuuuuuuuau",
      "                ",
      "                ",
      "                ",
      "   w  xyyA  w   ",
      "   B  CDEF  B   ",
      "   B  CEDF  B   ",
      "   I  JKKL  I   ",
      "                ",
      "                ",
      "  MMMMMMMMMMMM  ",
      "NaccccccccccccaN",
      " OccccccccccccO ",
      " O            O ",
      " O            O ",
      " O            O "
    ],
    [
      "PaPPPPPPPPPPPPaP",
      "                ",
      "                ",
      "                ",
      "            Q   ",
      "   R   DS   !   ",
      "   T   SU   V   ",
      "                ",
      "                ",
      "                ",
      "                ",
      "Na            aN",
      "                ",
      "                ",
      "                ",
      "                "
    ],
    [
      "PaPPPPPPPPPPPPaP",
      "                ",
      "                ",
      "                ",
      "                ",
      "       U        ",
      "                ",
      "                ",
      "                ",
      "                ",
      "                ",
      "Na            aN",
      "                ",
      "                ",
      "                ",
      "                "
    ]
  ]
}