{
  "name": "multi_terraceplaza_15_floor4",
  "refpalette": "deceasedcraft:multi_terraceplaza_15/multi_terraceplaza_15_floor4_palette",
  "xsize": 16,
  "zsize": 16,
  "slices": [
    [
      "abccccccccccccba",
      "ac  deedeede  ca",
      "ac            ca",
      "ac            ca",
      "ac            ca",
      "ac            ca",
      "ac            ca",
      "ac            ca",
      "ac            ca",
      "ac            ca",
      "ac            ca",
      "cb            bc",
      "                ",
      "                ",
      "                ",
      "                "
    ],
    [
      "fbccccccccccccb ",
      "gc  deeeeede  c ",
      "gc            c ",
      "gc            c ",
      "hc            c ",
      "ic            c ",
      "ic            c ",
      "jc            c ",
      "kc            c ",
      "lc            c ",
      "lc            c ",
      "cb            bc",
      "                ",
      "                ",
      "                ",
      "                "
    ],
    [
      " bccccccccccccb ",
      " c            c ",
      " c            c ",
      " c            c ",
      "hc            c ",
      "mc            c ",
      "ic            c ",
      " c            c ",
      " c            c ",
      "kc            c ",
      "mc            c ",
      "cb            bc",
      "                ",
      "                ",
      "                ",
      "nnopppppppppponn"
    ],
    [
      " bccccccccccccb ",
      " c            c ",
      " c            c ",
      " c            c ",
      "hc            c ",
      " c            c ",
      " c            c ",
      " c            c ",
      " c            c ",
      " c            c ",
      "qc            c ",
      "cb            bc",
      "nnopppppppppponn",
      "rrossssssssssorr",
      "ttossssssssssott",
      "uu            uu"
    ],
    [
      " bccccccccccccb ",
      " c            c ",
      " c            c ",
      " c            c ",
      "hc            c ",
      " c            c ",
      " c            c ",
      " c            c ",
      " c            c ",
      "ncoppppppppppocn",
      "rcossssssssssocr",
      "wbossssssssssobw",
      "uu            uu",
      "uu            uu",
      "xx            xx",
      "yy            yy"
    ],
    [
      " bccccccccccccb ",
      " c            c ",
      " c            c ",
      " c            c ",
      "hc            c ",
      " c            c ",
      "nc pppppppppp cn",
      "rcossssssssssocr",
      "ttossssssssssott",
      "uu            uu",
      "uu            uu",
      "xx            xx",
      "yy            yy",
      "                ",
      "                ",
      "                "
    ]
  ]
}