{
  "name": "multi_nuclearpowerplant_1_base6",
  "refpalette": "deceasedcraft:multi_nuclearpowerplant_1/multi_nuclearpowerplant_1_base6_palette",
  "xsize": 16,
  "zsize": 16,
  "slices": [
    [
      "vvvvvvvvvvvvvvvv",
      "vvvvvvvvvvvvvvvv",
      "vvvvvvvvvvvvvvvv",
      "vvvvvvvvvvvvvvvv",
      "vvvvvvvvvvvvvvvv",
      "vvvvvvvvvvvvvvvv",
      "vvvvvvvvvvvvvvva",
      "vvvvvvvvvvvvvvab",
      "vvvvvvvvvvvvvvac",
      "vvvvvvvvvvvvva  ",
      "vvvvvvvvvvvvad  ",
      "vvvvvvvvvvvva   ",
      "vvvvvvvvvvva    ",
      "vvvvvvvvvva     ",
      "vvvvvvvvvva     ",
      "vvvvvvvvva      "
    ],
    [
      "veeeeeeeeeeeeeee",
      "veeeeeeeeeeeeeee",
      "veeeeeeeeeeeeeee",
      "veeeeeeeeeeeeeee",
      "veeeeeeeeeeeeeee",
      "veeeeeeeeeeeeeee",
      "veeeeeeeeeeeeeef",
      "veeeeeeeeeeeeef ",
      "veeeeeeeeeeeeef ",
      "veeeeeeeeeeeef  ",
      "veeeeeeeeeeef   ",
      "veeeeeeeeeeef   ",
      "veeeeeeeeeef    ",
      "veeeeeeeeef     ",
      "veeeeeeeeef     ",
      "veeeeeeeef      "
    ],
    [
      "vbbbbbbbbbbbbbbb",
      "vbbbbbbbbbbbbbbb",
      "vbbbbbbbbbbbbbbb",
      "vbbbbbbbbbbbbbbb",
      "vbbbbbbbbbbbbbbb",
      "vbbbbbbbbbbbbbbb",
      "vbbbbbbbbbbbbbbf",
      "vbbbbbbbbbbbbbf ",
      "vbbbbbbbbbbbbbf ",
      "vbbbbbbbbbbbbf  ",
      "vbbbbbbbbbbbf   ",
      "vbbbbbbbbbbbf   ",
      "vbbbbbbbbbbf    ",
      "vbbbbbbbbbf     ",
      "vbbbbbbbbbf     ",
      "vbbbbbbbbf      "
    ],
    [
      "vbbbbbbbbbbbbbbb",
      "vbbbbbbbbbbbbbbb",
      "vbbbbbbbbbbbbbbb",
      "vbbbbbbbbbbbbbbb",
      "vbbbbbbbbbbbbbbb",
      "vbbbbbbbbbbbbbbb",
      "vbbbbbbbbbbbbbbf",
      "vbbbbbbbbbbbbbf ",
      "vbbbbbbbbbbbbbf ",
      "vbbbbbbbbbbbbf  ",
      "vbbbbbbbbbbbf   ",
      "vbbbbbbbbbbbf   ",
      "vbbbbbbbbbbf    ",
      "vbbbbbbbbbf     ",
      "vbbbbbbbbbf     ",
      "vbbbbbbbbf      "
    ],
    [
      "vbbbbbbbbbbbbbbb",
      "vbbbbbbbbbbbbbbb",
      "vbbbbbbbbbbbbbbb",
      "vbbbbbbbbbbbbbbb",
      "vbbbbbbbbbbbbbbb",
      "vbbbbbbbbbbbbbbb",
      "vbbbbbbbbbbbbbbf",
      "vbbbbbbbbbbbbbf ",
      "vbbbbbbbbbbbbbf ",
      "vbbbbbbbbbbbbf  ",
      "vbbbbbbbbbbbf   ",
      "vbbbbbbbbbbbf   ",
      "vbbbbbbbbbbf    ",
      "vbbbbbbbbbf     ",
      "vbbbbbbbbbf     ",
      "vbbbbbbbbf      "
    ],
    [
      "vbbbbbbbbbbbbbbb",
      "vbbbbbbbbbbbbbbb",
      "vbbbbbbbbbbbbbbb",
      "vbbbbbbbbbbbbbbb",
      "vbbbbbbbbbbbbbbb",
      "vbbbbbbbbbbbbbbb",
      "vbbbbbbbbbbbbbbf",
      "vbbbbbbbbbbbbbf ",
      "vbbbbbbbbbbbbbf ",
      "vbbbbbbbbbbbbf  ",
      "vbbbbbbbbbbbf   ",
      "vbbbbbbbbbbbf   ",
      "vbbbbbbbbbbf    ",
      "vbbbbbbbbbf     ",
      "vbbbbbbbbbf     ",
      "vbbbbbbbbf      "
    ]
  ]
}