{
  "name": "multi_nuclearpowerplant_1_base9",
  "refpalette": "deceasedcraft:multi_nuclearpowerplant_1/multi_nuclearpowerplant_1_base9_palette",
  "xsize": 16,
  "zsize": 16,
  "slices": [
    [
      "vaaaaaaaaaaaaaaa",
      "vaaaaaaaaaaaaaaa",
      "vaaaaaaaaaaaaaaa",
      "vaaaaaaaaaaaaaaa",
      "vaaaaaaaaaaaaaaa",
      "vaaabbbbbbbbbbbb",
      "vaaabbcccccccccc",
      "vaaabbcdd       ",
      "vaaabbcd        ",
      "vaaabbc         ",
      "vaaabbc         ",
      "vaaabbc         ",
      "vaaabbceeeee    ",
      "vaaabbfffffee   ",
      "vaaabbfggggfe   ",
      "vaaabbfhgggfe   "
    ],
    [
      "vaaaaaaaaaaaaaaa",
      "vaaaaaaaaaaaaaaa",
      "vaaaaaaaaaaaaaaa",
      "vaaaaaaaaaaaaaaa",
      "vaaaaaaaaaaaaaaa",
      "vaaabbbbbbbbbbbb",
      "vaaabbcccccccccc",
      "vaaabbcdd       ",
      "vaaabbcd        ",
      "vaaabbc         ",
      "vaaabbc         ",
      "vaaabbc         ",
      "vaaabbc         ",
      "vaaabbceeee     ",
      "vaaabbc    e    ",
      "vaaabbci   e    "
    ],
    [
      "vaaaaaaaaaaaaaaa",
      "vaaaaaaaaaaaaaaa",
      "vaaaaaaaaaaaaaaa",
      "vaaaaaaaaaaaaaaa",
      "vaaaaaaaaaaaaaaa",
      "vaaabbbbbbbbbbbb",
      "vaaabbcccccccccc",
      "vaaabbcdd       ",
      "vaaabbcd        ",
      "vaaabbc         ",
      "vaaabbc         ",
      "vaaabbc         ",
      "vaaabbc         ",
      "vaaabbc         ",
      "vaaabbc         ",
      "vaaabbci        "
    ],
    [
      "vaaaaaaaaaaaaaaa",
      "vaaaaaaaaaaaaaaa",
      "vaaaaaaaaaaaaaaa",
      "vaaaaaaaaaaaaaaa",
      "vaaaaaaaaaaaaaaa",
      "vaaabbbbbbbbbbbb",
      "vaaabbcccccccccc",
      "vaaabbcdd       ",
      "vaaabbcdj       ",
      "vaaabbc         ",
      "vaaabbc         ",
      "vaaabbc         ",
      "vaaabbc         ",
      "vaaabbc         ",
      "vaaabbc         ",
      "vaaabbci        "
    ],
    [
      "vaaaaaaaaaaaaaaa",
      "vaaaaaaaaaaaaaaa",
      "vaaaaaaaaaaaaaaa",
      "vaaaaaaaaaaaaaaa",
      "vaaaaaaaaaaaaaaa",
      "vaaabbbbbbbbbbbb",
      "vaaabbcccccccccc",
      "vaaabbcdd       ",
      "vaaabbcdiiiiiiii",
      "vaaabbc i       ",
      "vaaabbc i       ",
      "vaaabbc i       ",
      "vaaabbc i       ",
      "vaaabbc i       ",
      "vaaabbc i       ",
      "vaaabbcii       "
    ],
    [
      "vaaaaaaaaaaaaaaa",
      "vaaaaaaaaaaaaaaa",
      "vaaaaaaaaaaaaaaa",
      "vaaaaaaaaaaaaaaa",
      "vaaaaaaaaaaaaaaa",
      "vaaabbbbbbbbbbbb",
      "vaaabbcccccccccc",
      "vaaabbcdd       ",
      "vaaabbcd        ",
      "vaaabbc         ",
      "vaaabbc         ",
      "vaaabbc         ",
      "vaaabbc         ",
      "vaaabbc         ",
      "vaaabbc         ",
      "vaaabbc         "
    ]
  ]
}