{
  "name": "multi_nuclearpowerplant_1_ground",
  "refpalette": "deceasedcraft:multi_nuclearpowerplant_1/multi_nuclearpowerplant_1_ground_palette",
  "xsize": 16,
  "zsize": 16,
  "slices": [
    [
      "zzzzzzzzzzzazaaz",
      "zazzzzzzzzazazaz",
      "zzzzzzzzzzazzaaa",
      "zzzzzzzazzzaazaa",
      "zzzzazzzzzazzaaa",
      "zzzzzzzzazazaaaa",
      "zzzzzzzazzzaaaaa",
      "zzzzzzzzaaaaaaab",
      "zzazzzaazazaaaab",
      "zzzzzzzzzaaaaabb",
      "zzzzzazaaaaaabbc",
      "zzzazaazaaaaabcc",
      "zzzzzazaaaaabbc ",
      "zazazzzazaabbcc ",
      "zzzazaaaaaabcc  ",
      "zzazazaaaabbc   "
    ],
    [
      "   d de         ",
      "     d     d    ",
      " d ddddd        ",
      "  d      d      ",
      "                ",
      " ddddd          ",
      "   dd   d      f",
      " d   d        gz",
      "    dd  d     hz",
      "   d d       fzz",
      " edd        gzzc",
      "  d         fzcc",
      " dd        fzzcc",
      "    dd    gzzccc",
      " d  d     fzcccc",
      "d        gazccc "
    ],
    [
      "                ",
      "                ",
      "                ",
      "                ",
      "                ",
      "                ",
      "                ",
      "               i",
      "               i",
      "              ii",
      "             iiz",
      "             iaz",
      "            iizz",
      "           iizac",
      "           izzcc",
      "          iiazcc"
    ],
    [
      "                ",
      "                ",
      "                ",
      "                ",
      "                ",
      "                ",
      "                ",
      "               i",
      "               i",
      "              ii",
      "             ii ",
      "             i z",
      "            ii z",
      "           ii  z",
      "           i dzz",
      "          ii zzc"
    ],
    [
      "                ",
      "                ",
      "                ",
      "                ",
      "                ",
      "                ",
      "                ",
      "               j",
      "               j",
      "              j ",
      "             j  ",
      "             j  ",
      "            j   ",
      "           j    ",
      "           j    ",
      "          j    z"
    ],
    [
      "                ",
      "                ",
      "                ",
      "                ",
      "                ",
      "                ",
      "                ",
      "                ",
      "                ",
      "                ",
      "                ",
      "                ",
      "                ",
      "                ",
      "                ",
      "                "
    ]
  ]
}