{
  "name": "multi_nuclearpowerplant_1_base3",
  "refpalette": "deceasedcraft:multi_nuclearpowerplant_1/multi_nuclearpowerplant_1_base3_palette",
  "xsize": 16,
  "zsize": 16,
  "slices": [
    [
      "vaa             ",
      "vaa             ",
      "vaa             ",
      "vaa             ",
      "vaa             ",
      "vaa             ",
      "vaa            b",
      "vaa           bc",
      "vaa           bc",
      "vaa          bcc",
      "vaa         bccc",
      "vaa         bccc",
      "vaa        bcccc",
      "vaa       bccccc",
      "vaa       bccccc",
      "vaa      bccccc "
    ],
    [
      "v d             ",
      "v d             ",
      "v d             ",
      "v d             ",
      "v d             ",
      "v d             ",
      "v d            e",
      "v d           e ",
      "v d           e ",
      "v d          e  ",
      "v d         ef  ",
      "v d         e   ",
      "v d        e    ",
      "v d       e    g",
      "v d       e    h",
      "v d      e    g "
    ],
    [
      "v               ",
      "v               ",
      "v               ",
      "v               ",
      "v               ",
      "v               ",
      "v              e",
      "v             e ",
      "v             e ",
      "v            e  ",
      "v           e   ",
      "v           e   ",
      "v          e    ",
      "v         e     ",
      "v         e     ",
      "v        e      "
    ],
    [
      "v               ",
      "v               ",
      "v               ",
      "v               ",
      "v               ",
      "v               ",
      "v              e",
      "v             e ",
      "v             e ",
      "v            e  ",
      "v           e   ",
      "v           e   ",
      "v          e    ",
      "v         e     ",
      "v         e     ",
      "v        e      "
    ],
    [
      "v               ",
      "v               ",
      "v               ",
      "v               ",
      "v               ",
      "v               ",
      "v              e",
      "v             e ",
      "v             e ",
      "v            e  ",
      "v           e   ",
      "v           e   ",
      "v          e    ",
      "v         e     ",
      "v         e     ",
      "v        e      "
    ],
    [
      "v               ",
      "v               ",
      "v               ",
      "v               ",
      "v               ",
      "v               ",
      "v              e",
      "v             e ",
      "v             e ",
      "v            e  ",
      "v           e   ",
      "v           e   ",
      "v          e    ",
      "v         e     ",
      "v         e     ",
      "v        e      "
    ]
  ]
}