{
  "name": "multi_nuclearpowerplant_1_base11",
  "refpalette": "deceasedcraft:multi_nuclearpowerplant_1/multi_nuclearpowerplant_1_base11_palette",
  "xsize": 16,
  "zsize": 16,
  "slices": [
    [
      "vaaaaaaaaaaaaaaa",
      "vaaaaaaaaaaaaaaa",
      "vaaaaaaaaaaaaaaa",
      "vaaaaaaaaaaaaaaa",
      "vaaaaaaaaaaaaaaa",
      "vaaabbbbbbbbbbbb",
      "vaaabbcccccccccc",
      "vaaabbcdd       ",
      "vaaabbcd        ",
      "vaaabbc         ",
      "vaaabbc         ",
      "vaaabbc         ",
      "vaaabbeeeeee    ",
      "vaaabeeffffee   ",
      "vaaabefggggfe   ",
      "vaaabefggggfe   "
    ],
    [
      "vaaaaaaaaaaaaaaa",
      "vaaaaaaaaaaaaaaa",
      "vaaaaaaaaaaaaaaa",
      "vaaaaaaaaaaaaaaa",
      "vaaaaaaaaaaaaaaa",
      "vaaabbbbbbbbbbbb",
      "vaaabbcccccccccc",
      "vaaabbcdd       ",
      "vaaabbcd        ",
      "vaaabbc         ",
      "vaaabbc         ",
      "vaaabbc         ",
      "vaaabbeeeeee    ",
      "vaaabeeffffee   ",
      "vaaabefggggfe   ",
      "vaaabefggggfe   "
    ],
    [
      "vaaaaaaaaaaaaaaa",
      "vaaaaaaaaaaaaaaa",
      "vaaaaaaaaaaaaaaa",
      "vaaaaaaaaaaaaaaa",
      "vaaaaaaaaaaaaaaa",
      "vaaabbbbbbbbbbbb",
      "vaaabbcccccccccc",
      "vaaabbcdd       ",
      "vaaabbcd        ",
      "vaaabbc         ",
      "vaaabbc         ",
      "vaaabbc         ",
      "vaaabbeeeeee    ",
      "vaaabeeffffee   ",
      "vaaabefggggfe   ",
      "vaaabefggggfe   "
    ],
    [
      "vaaaaaaaaaaaaaaa",
      "vaaaaaaaaaaaaaaa",
      "vaaaaaaaaaaaaaaa",
      "vaaaaaaaaaaaaaaa",
      "vaaaaaaaaaaaaaaa",
      "vaaabbbbbbbbbbbb",
      "vaaabbcccccccccc",
      "vaaabbcdd       ",
      "vaaabbcd        ",
      "vaaabbc         ",
      "vaaabbc         ",
      "vaaabbc         ",
      "vaaabbeeeeee    ",
      "vaaabeeffffee   ",
      "vaaabefggggfe   ",
      "vaaabefggggfe   "
    ],
    [
      "vaaaaaaaaaaaaaaa",
      "vaaaaaaaaaaaaaaa",
      "vaaaaaaaaaaaaaaa",
      "vaaaaaaaaaaaaaaa",
      "vaaaaaaaaaaaaaaa",
      "vaaabbbbbbbbbbbb",
      "vaaabbcccccccccc",
      "vaaabbcdd       ",
      "vaaabbcd        ",
      "vaaabbc         ",
      "vaaabbc         ",
      "vaaabbc         ",
      "vaaabbeeeeee    ",
      "vaaabeeffffee   ",
      "vaaabefhhhhfe   ",
      "vaaabefhhhhfe   "
    ],
    [
      "vaaaaaaaaaaaaaaa",
      "vaaaaaaaaaaaaaaa",
      "vaaaaaaaaaaaaaaa",
      "vaaaaaaaaaaaaaaa",
      "vaaaaaaaaaaaaaaa",
      "vaaabbbbbbbbbbbb",
      "vaaabbcccccccccc",
      "vaaabbcdd       ",
      "vaaabbcd        ",
      "vaaabbc         ",
      "vaaabbc         ",
      "vaaabbc         ",
      "vaaabbeeeeee    ",
      "vaaabeeffffee   ",
      "vaaabefbbbbfe   ",
      "vaaabefbbbbfe   "
    ]
  ]
}