{
  "name": "multi_nuclearpowerplant_1_base10",
  "refpalette": "deceasedcraft:multi_nuclearpowerplant_1/multi_nuclearpowerplant_1_base10_palette",
  "xsize": 16,
  "zsize": 16,
  "slices": [
    [
      "vaaaaaaaaaaaaaaa",
      "vaaaaaaaaaaaaaaa",
      "vaaaaaaaaaaaaaaa",
      "vaaaaaaaaaaaaaaa",
      "vaaaaaaaaaaaaaaa",
      "vaaabbbbbbbbbbbb",
      "vaaabbcccccccccc",
      "vaaabbcdd       ",
      "vaaabbcdeeeeeeee",
      "vaaabbc eeeeeeee",
      "vaaabbc ee      ",
      "vaaabbc ee      ",
      "vaaabbffffff    ",
      "vaaabffbbbbff   ",
      "vaaabfbbbbbbf   ",
      "vaaabfbbbbbbf   "
    ],
    [
      "vaaaaaaaaaaaaaaa",
      "vaaaaaaaaaaaaaaa",
      "vaaaaaaaaaaaaaaa",
      "vaaaaaaaaaaaaaaa",
      "vaaaaaaaaaaaaaaa",
      "vaaabbbbbbbbbbbb",
      "vaaabbcccccccccc",
      "vaaabbcdd       ",
      "vaaabbcdghhhhhhh",
      "vaaabbc i jjjjjj",
      "vaaabbc ik      ",
      "vaaabbc ik      ",
      "vaaabbfflmff    ",
      "vaaabff    ff   ",
      "vaaabf      f   ",
      "vaaabf      f   "
    ],
    [
      "vaaaaaaaaaaaaaaa",
      "vaaaaaaaaaaaaaaa",
      "vaaaaaaaaaaaaaaa",
      "vaaaaaaaaaaaaaaa",
      "vaaaaaaaaaaaaaaa",
      "vaaabbbbbbbbbbbb",
      "vaaabbcccccccccc",
      "vaaabbcdd       ",
      "vaaabbcd        ",
      "vaaabbc         ",
      "vaaabbc         ",
      "vaaabbc   n     ",
      "vaaabbffopff    ",
      "vaaabff    ff   ",
      "vaaabf      f   ",
      "vaaabf      f   "
    ],
    [
      "vaaaaaaaaaaaaaaa",
      "vaaaaaaaaaaaaaaa",
      "vaaaaaaaaaaaaaaa",
      "vaaaaaaaaaaaaaaa",
      "vaaaaaaaaaaaaaaa",
      "vaaabbbbbbbbbbbb",
      "vaaabbcccccccccc",
      "vaaabbcdd       ",
      "vaaabbcd        ",
      "vaaabbc         ",
      "vaaabbc         ",
      "vaaabbc         ",
      "vaaabbffqqff    ",
      "vaaabff    ff   ",
      "vaaabf      f   ",
      "vaaabf      f   "
    ],
    [
      "vaaaaaaaaaaaaaaa",
      "vaaaaaaaaaaaaaaa",
      "vaaaaaaaaaaaaaaa",
      "vaaaaaaaaaaaaaaa",
      "vaaaaaaaaaaaaaaa",
      "vaaabbbbbbbbbbbb",
      "vaaabbcccccccccc",
      "vaaabbcdd       ",
      "vaaabbcd        ",
      "vaaabbc         ",
      "vaaabbc         ",
      "vaaabbc         ",
      "vaaabbffffff    ",
      "vaaabff    ff   ",
      "vaaabf      f   ",
      "vaaabf      f   "
    ],
    [
      "vaaaaaaaaaaaaaaa",
      "vaaaaaaaaaaaaaaa",
      "vaaaaaaaaaaaaaaa",
      "vaaaaaaaaaaaaaaa",
      "vaaaaaaaaaaaaaaa",
      "vaaabbbbbbbbbbbb",
      "vaaabbcccccccccc",
      "vaaabbcdd       ",
      "vaaabbcd        ",
      "vaaabbc         ",
      "vaaabbc         ",
      "vaaabbc         ",
      "vaaabbffffff    ",
      "vaaabff    ff   ",
      "vaaabf      f   ",
      "vaaabf      f   "
    ]
  ]
}