{
  "name": "multi_nuclearpowerplant_1_base1",
  "refpalette": "deceasedcraft:multi_nuclearpowerplant_1/multi_nuclearpowerplant_1_base1_palette",
  "xsize": 16,
  "zsize": 16,
  "slices": [
    [
      "vaaaaaaaaaaaaaaa",
      "vaaaaaaaaaaaaaaa",
      "vaaaaaaaaaaaaaaa",
      "vaaaaaaaaaaaaaaa",
      "vaaaaaaaaaaaaaaa",
      "vaaaaaaaaaaaaaaa",
      "vaaaaaaaaaaaaaab",
      "vaaaaaaaaaaaaabz",
      "vaaaaaaaaaaaaabz",
      "vaaaaaaaaaaaabzc",
      "vaaaaaaaaaaabzcc",
      "vaaaaaaaaaaabzcc",
      "vaaaaaaaaaabzccc",
      "vaaaaaaaaabzcccc",
      "vaaaaaaaaabzcccc",
      "vaaaaaaaabzccccc"
    ],
    [
      "vddddddddddddddd",
      "vddddddddddddddd",
      "vddddddddddddddd",
      "vddddddddddddddd",
      "vddddddddddddddd",
      "vddddddddddddddd",
      "vdddddddddddddde",
      "vdddddddddddddef",
      "vdddddddddddddef",
      "vddddddddddddef ",
      "vdddddddddddef  ",
      "vdddddddddddef  ",
      "vddddddddddef   ",
      "vdddddddddef    ",
      "vdddddddddef    ",
      "vddddddddef     "
    ],
    [
      "vddddddddddddddd",
      "vddddddddddddddd",
      "vddddddddddddddd",
      "vddddddddddddddd",
      "vddddddddddddddd",
      "vddddddddddddddd",
      "vdddddddddddddde",
      "vddddddddddddde ",
      "vddddddddddddde ",
      "vdddddddddddde  ",
      "vddddddddddde   ",
      "vddddddddddde   ",
      "vdddddddddde    ",
      "vddddddddde     ",
      "vddddddddde     ",
      "vdddddddde      "
    ],
    [
      "vddddddddddddddd",
      "vddddddddddddddd",
      "vddddddddddddddd",
      "vddddddddddddddd",
      "vddddddddddddddd",
      "vddddddddddddddd",
      "vdddddddddddddde",
      "vddddddddddddde ",
      "vddddddddddddde ",
      "vdddddddddddde  ",
      "vddddddddddde   ",
      "vddddddddddde   ",
      "vdddddddddde    ",
      "vddddddddde     ",
      "vddddddddde     ",
      "vdddddddde      "
    ],
    [
      "vddddddddddddddd",
      "vddddddddddddddd",
      "vddddddddddddddd",
      "vddddddddddddddd",
      "vddddddddddddddd",
      "vddddddddddddddd",
      "vdddddddddddddde",
      "vddddddddddddde ",
      "vddddddddddddde ",
      "vdddddddddddde  ",
      "vddddddddddde   ",
      "vddddddddddde   ",
      "vdddddddddde    ",
      "vddddddddde     ",
      "vddddddddde     ",
      "vdddddddde      "
    ],
    [
      "vddddddddddddddd",
      "vddddddddddddddd",
      "vddddddddddddddd",
      "vddddddddddddddd",
      "vddddddddddddddd",
      "vddddddddddddddd",
      "vdddddddddddddde",
      "vdddddddddddddeg",
      "vdddddddddddddeg",
      "vddddddddddddegg",
      "vdddddddddddegg ",
      "vdddddddddddeg  ",
      "vddddddddddegg  ",
      "vdddddddddegg   ",
      "vdddddddddeg    ",
      "vddddddddegg    "
    ]
  ]
}