{
  "name": "multi_nuclearpowerplant_1_base2",
  "refpalette": "deceasedcraft:multi_nuclearpowerplant_1/multi_nuclearpowerplant_1_base2_palette",
  "xsize": 16,
  "zsize": 16,
  "slices": [
    [
      "v               ",
      "v               ",
      "v               ",
      "v               ",
      "v               ",
      "v               ",
      "v              a",
      "v             a ",
      "v             a ",
      "v            a  ",
      "v           a   ",
      "v           a   ",
      "v          a    ",
      "v         a     ",
      "v         a     ",
      "v        a      "
    ],
    [
      "v               ",
      "v               ",
      "v               ",
      "v               ",
      "v               ",
      "v               ",
      "v              a",
      "v             a ",
      "v             a ",
      "v            a  ",
      "v           a   ",
      "v           a   ",
      "v          a    ",
      "v         a     ",
      "v         a     ",
      "v        a      "
    ],
    [
      "v               ",
      "v               ",
      "v               ",
      "v               ",
      "v               ",
      "v               ",
      "v              a",
      "v             a ",
      "v             a ",
      "v            a  ",
      "v           a   ",
      "v           a   ",
      "v          a    ",
      "v         a     ",
      "v         a     ",
      "v        a      "
    ],
    [
      "v               ",
      "v               ",
      "v               ",
      "v               ",
      "v               ",
      "v               ",
      "v              a",
      "v             a ",
      "v             a ",
      "v            a  ",
      "v           a   ",
      "v           a   ",
      "v          a    ",
      "v         a     ",
      "v         a     ",
      "v        a      "
    ],
    [
      "v               ",
      "v               ",
      "v               ",
      "v               ",
      "v               ",
      "v               ",
      "v              a",
      "v             a ",
      "v             a ",
      "v            a  ",
      "v           a   ",
      "v           a   ",
      "v          a    ",
      "v         a     ",
      "v         a     ",
      "v        a      "
    ],
    [
      "v               ",
      "v               ",
      "v               ",
      "v               ",
      "v               ",
      "v               ",
      "v              a",
      "v             ab",
      "v             ab",
      "v            abb",
      "v           abbb",
      "v           abbb",
      "v          abbbb",
      "v         abbbbb",
      "v         abbbbb",
      "v        abbbbbb"
    ]
  ]
}