{
  "name": "multi_nuclearpowerplant_1_base7",
  "refpalette": "deceasedcraft:multi_nuclearpowerplant_1/multi_nuclearpowerplant_1_base7_palette",
  "xsize": 16,
  "zsize": 16,
  "slices": [
    [
      "vaaaaaaaaaaaaaaa",
      "vaaaaaaaaaaaaaaa",
      "vaaaaaaaaaaaaaaa",
      "vaaaaaaaaaaaaaaa",
      "vaaaaaaaaaaaaaaa",
      "vaaaaaaaaaaaaaaa",
      "vaaaaaaaaaaaaaab",
      "vaaaaaaaaaaaaabc",
      "vaaaaaaaaaaaaabc",
      "vaaaaaaaaaaaabcc",
      "vaaaaaaaaaaabccc",
      "vaaaaaaaaaaabccc",
      "vaaaaaaaaaabcccc",
      "vaaaaaaaaabccccc",
      "vaaaaaaaaabccccc",
      "vaaaaaaaabcccccc"
    ],
    [
      "vaaaaaaaaaaaaaaa",
      "vaaaaaaaaaaaaaaa",
      "vaaaaaaaaaaaaaaa",
      "vaaaaaaaaaaaaaaa",
      "vaaaaaaaaaaaaaaa",
      "vaaaaaaaaaaaaaaa",
      "vaaaaaaaaaaaaaab",
      "vaaaaaaaaaaaaabc",
      "vaaaaaaaaaaaaabc",
      "vaaaaaaaaaaaabcc",
      "vaaaaaaaaaaabccc",
      "vaaaaaaaaaaabccc",
      "vaaaaaaaaaabcccc",
      "vaaaaaaaaabccccc",
      "vaaaaaaaaabccccc",
      "vaaaaaaaabcccccc"
    ],
    [
      "vaaaaaaaaaaaaaaa",
      "vaaaaaaaaaaaaaaa",
      "vaaaaaaaaaaaaaaa",
      "vaaaaaaaaaaaaaaa",
      "vaaaaaaaaaaaaaaa",
      "vaaaaaaaaaaaaaaa",
      "vaaaaaaaaaaaaaab",
      "vaaaaaaaaaaaaabc",
      "vaaaaaaaaaaaaabc",
      "vaaaaaaaaaaaabcc",
      "vaaaaaaaaaaabccc",
      "vaaaaaaaaaaabccc",
      "vaaaaaaaaaabcccc",
      "vaaaaaaaaabccccc",
      "vaaaaaaaaabccccc",
      "vaaaaaaaabcccccc"
    ],
    [
      "vaaaaaaaaaaaaaaa",
      "vaaaaaaaaaaaaaaa",
      "vaaaaaaaaaaaaaaa",
      "vaaaaaaaaaaaaaaa",
      "vaaaaaaaaaaaaaaa",
      "vaaaaaaaaaaaaaaa",
      "vaaaaaaaaaaaaaab",
      "vaaaaaaaaaaaaabc",
      "vaaaaaaaaaaaaabc",
      "vaaaaaaaaaaaabcc",
      "vaaaaaaaaaaabccc",
      "vaaaaaaaaaaabccc",
      "vaaaaaaaaaabcccc",
      "vaaaaaaaaabccccc",
      "vaaaaaaaaabccccc",
      "vaaaaaaaabcccccc"
    ],
    [
      "vaaaaaaaaaaaaaaa",
      "vaaaaaaaaaaaaaaa",
      "vaaaaaaaaaaaaaaa",
      "vaaaaaaaaaaaaaaa",
      "vaaaaaaaaaaaaaaa",
      "vaaaaaaaaaaaaaaa",
      "vaaaaaaaaaaaaaab",
      "vaaaaaaaaaaaaabc",
      "vaaaaaaaaaaaaabc",
      "vaaaaaaaaaaaabcc",
      "vaaaaaaaaaaabccc",
      "vaaaaaaaaaaabccc",
      "vaaaaaaaaaabcccc",
      "vaaaaaaaaabccccc",
      "vaaaaaaaaabccccc",
      "vaaaaaaaabcccccc"
    ],
    [
      "vddddddddddddddd",
      "vddddddddddddddd",
      "vddddddddddddddd",
      "vddddddddddddddd",
      "vddddddddddddddd",
      "vddddddddddddddd",
      "vddddddddddddddb",
      "vdddddddddddddbc",
      "vdddddddddddddbc",
      "vddddddddddddbcc",
      "vdddddddddddbccc",
      "vdddddddddddbccc",
      "vddddddddddbcccc",
      "vdddddddddbccccc",
      "vdddddddddbccccc",
      "vddddddddbcccccc"
    ]
  ]
}