{
  "name": "multi_nuclearpowerplant_1_base8",
  "refpalette": "deceasedcraft:multi_nuclearpowerplant_1/multi_nuclearpowerplant_1_base8_palette",
  "xsize": 16,
  "zsize": 16,
  "slices": [
    [
      "vaaaaaaaaaaaaaaa",
      "vaaaaaaaaaaaaaaa",
      "vaaaaaaaaaaaaaaa",
      "vaaaaaaaaaaaaaaa",
      "vaaaaaaaaaaaaaaa",
      "vaaabbbbbbbbbbbb",
      "vaaabbcccccccccc",
      "vaaabbcddddddddd",
      "vaaabbcddddddddd",
      "vaaabbcddddddddd",
      "vaaabbcddddddddd",
      "vaaabbcddddddddd",
      "vaaabbcddddddddd",
      "vaaabbcddddddddd",
      "vaaabbcddddddddd",
      "vaaabbcddddddddd"
    ],
    [
      "vaaaaaaaaaaaaaaa",
      "vaaaaaaaaaaaaaaa",
      "vaaaaaaaaaaaaaaa",
      "vaaaaaaaaaaaaaaa",
      "vaaaaaaaaaaaaaaa",
      "vaaabbbbbbbbbbbb",
      "vaaabbbbbbbbbbbe",
      "vaaabbbbbbbbbbef",
      "vaaabbbbbbbbbbef",
      "vaaabbbbbbbbbeff",
      "vaaabbbbbbbbefff",
      "vaaabbbbbbbbefff",
      "vaaabbbbbbbeffff",
      "vaaabbbbbbefffff",
      "vaaabbbbbbefffff",
      "vaaabbbbbeffffff"
    ],
    [
      "vaaaaaaaaaaaaaaa",
      "vaaaaaaaaaaaaaaa",
      "vaaaaaaaaaaaaaaa",
      "vaaaaaaaaaaaaaaa",
      "vaaaaaaaaaaaaaaa",
      "vaaaaaaaaaaaaaaa",
      "vaaaaaaaaaaaaaag",
      "vaaaaaaaaaaaaagh",
      "vaaaaaaaaaaaaagh",
      "vaaaaaaaaaaaaghh",
      "vaaaaaaaaaaaghhh",
      "vaaaaaaaaaaaghhh",
      "vaaaaaaaaaaghhhh",
      "vaaaaaaaaaghhhhh",
      "vaaaaaaaaaghhhhh",
      "vaaaaaaaaghhhhhh"
    ],
    [
      "vaaaaaaaaaaaaaaa",
      "vaaaaaaaaaaaaaaa",
      "vaaaaaaaaaaaaaaa",
      "vaaaaaaaaaaaaaaa",
      "vaaaaaaaaaaaaaaa",
      "vaaaaaaaaaaaaaaa",
      "vaaaaaaaaaaaaaag",
      "vaaaaaaaaaaaaagh",
      "vaaaaaaaaaaaaagh",
      "vaaaaaaaaaaaaghh",
      "vaaaaaaaaaaaghhh",
      "vaaaaaaaaaaaghhh",
      "vaaaaaaaaaaghhhh",
      "vaaaaaaaaaghhhhh",
      "vaaaaaaaaaghhhhh",
      "vaaaaaaaaghhhhhh"
    ],
    [
      "vaaaaaaaaaaaaaaa",
      "vaaaaaaaaaaaaaaa",
      "vaaaaaaaaaaaaaaa",
      "vaaaaaaaaaaaaaaa",
      "vaaaaaaaaaaaaaaa",
      "vaaaaaaaaaaaaaaa",
      "vaaaaaaaaaaaaaag",
      "vaaaaaaaaaaaaagh",
      "vaaaaaaaaaaaaagh",
      "vaaaaaaaaaaaaghh",
      "vaaaaaaaaaaaghhh",
      "vaaaaaaaaaaaghhh",
      "vaaaaaaaaaaghhhh",
      "vaaaaaaaaaghhhhh",
      "vaaaaaaaaaghhhhh",
      "vaaaaaaaaghhhhhh"
    ],
    [
      "vaaaaaaaaaaaaaaa",
      "vaaaaaaaaaaaaaaa",
      "vaaaaaaaaaaaaaaa",
      "vaaaaaaaaaaaaaaa",
      "vaaaaaaaaaaaaaaa",
      "vaaaaaaaaaaaaaaa",
      "vaaaaaaaaaaaaaag",
      "vaaaaaaaaaaaaagh",
      "vaaaaaaaaaaaaagh",
      "vaaaaaaaaaaaaghh",
      "vaaaaaaaaaaaghhh",
      "vaaaaaaaaaaaghhh",
      "vaaaaaaaaaaghhhh",
      "vaaaaaaaaaghhhhh",
      "vaaaaaaaaaghhhhh",
      "vaaaaaaaaghhhhhh"
    ]
  ]
}