{
  "name": "multi_nuclearpowerplant_34_base11",
  "refpalette": "deceasedcraft:multi_nuclearpowerplant_34/multi_nuclearpowerplant_34_base11_palette",
  "xsize": 16,
  "zsize": 16,
  "slices": [
    [
      "aaaaaaaaaaaaabcd",
      "aaaaaaaaaaaaabcd",
      "aaaaaaaaaaaaabcc",
      "aaaaaaaaaaaaaabc",
      "aaaaaaaaaaaaaab=",
      "aaaaaaaaaaaaaaab",
      "aaaaaaaaaaaaaaaa",
      "aaaaaaaaaaaaaaaa",
      "aaaaaaaaaaaaaaaa",
      "aaaaaaaaaaaaaaaa",
      "aaaaaaaaaaaaaaaa",
      "aaaaaaaaaaaaaaaa",
      "aaaaaaaaaaaaaaaa",
      "aaaaaaaaaaaaaaaa",
      "aaaaaaaaaaaaaaaa",
      "vvvvvvvvvvvvvvvv"
    ],
    [
      "aaaaaaaaaaaaabcd",
      "aaaaaaaaaaaaabcd",
      "aaaaaaaaaaaaabcc",
      "aaaaaaaaaaaaaabc",
      "aaaaaaaaaaaaaab=",
      "aaaaaaaaaaaaaaab",
      "aaaaaaaaaaaaaaaa",
      "aaaaaaaaaaaaaaaa",
      "aaaaaaaaaaaaaaaa",
      "aaaaaaaaaaaaaaaa",
      "aaaaaaaaaaaaaaaa",
      "aaaaaaaaaaaaaaaa",
      "aaaaaaaaaaaaaaaa",
      "aaaaaaaaaaaaaaaa",
      "aaaaaaaaaaaaaaaa",
      "vvvvvvvvvvvvvvvv"
    ],
    [
      "aaaaaaaaaaaaabcd",
      "aaaaaaaaaaaaabcd",
      "aaaaaaaaaaaaabcc",
      "aaaaaaaaaaaaaabc",
      "aaaaaaaaaaaaaab=",
      "aaaaaaaaaaaaaaab",
      "aaaaaaaaaaaaaaaa",
      "aaaaaaaaaaaaaaaa",
      "aaaaaaaaaaaaaaaa",
      "aaaaaaaaaaaaaaaa",
      "aaaaaaaaaaaaaaaa",
      "aaaaaaaaaaaaaaaa",
      "aaaaaaaaaaaaaaaa",
      "aaaaaaaaaaaaaaaa",
      "aaaaaaaaaaaaaaaa",
      "vvvvvvvvvvvvvvvv"
    ],
    [
      "aaaaaaaaaaaaabcd",
      "aaaaaaaaaaaaabcd",
      "aaaaaaaaaaaaabcc",
      "aaaaaaaaaaaaaabc",
      "aaaaaaaaaaaaaab=",
      "aaaaaaaaaaaaaaab",
      "aaaaaaaaaaaaaaaa",
      "aaaaaaaaaaaaaaaa",
      "aaaaaaaaaaaaaaaa",
      "aaaaaaaaaaaaaaaa",
      "aaaaaaaaaaaaaaaa",
      "aaaaaaaaaaaaaaaa",
      "aaaaaaaaaaaaaaaa",
      "aaaaaaaaaaaaaaaa",
      "aaaaaaaaaaaaaaaa",
      "vvvvvvvvvvvvvvvv"
    ],
    [
      "aaaaaaaaaaaaabcd",
      "aaaaaaaaaaaaabcd",
      "aaaaaaaaaaaaabcc",
      "aaaaaaaaaaaaaabc",
      "aaaaaaaaaaaaaab=",
      "aaaaaaaaaaaaaaab",
      "aaaaaaaaaaaaaaaa",
      "aaaaaaaaaaaaaaaa",
      "aaaaaaaaaaaaaaaa",
      "aaaaaaaaaaaaaaaa",
      "aaaaaaaaaaaaaaaa",
      "aaaaaaaaaaaaaaaa",
      "aaaaaaaaaaaaaaaa",
      "aaaaaaaaaaaaaaaa",
      "aaaaaaaaaaaaaaaa",
      "vvvvvvvvvvvvvvvv"
    ],
    [
      "aaaaaaaaaaaaabcd",
      "aaaaaaaaaaaaabcd",
      "aaaaaaaaaaaaabcc",
      "aaaaaaaaaaaaaabc",
      "aaaaaaaaaaaaaab=",
      "aaaaaaaaaaaaaaab",
      "aaaaaaaaaaaaaaaa",
      "aaaaaaaaaaaaaaaa",
      "aaaaaaaaaaaaaaaa",
      "aaaaaaaaaaaaaaaa",
      "aaaaaaaaaaaaaaaa",
      "aaaaaaaaaaaaaaaa",
      "aaaaaaaaaaaaaaaa",
      "aaaaaaaaaaaaaaaa",
      "aaaaaaaaaaaaaaaa",
      "vvvvvvvvvvvvvvvv"
    ]
  ]
}