{
  "name": "multi_nuclearpowerplant_34_base6",
  "refpalette": "deceasedcraft:multi_nuclearpowerplant_34/multi_nuclearpowerplant_34_base6_palette",
  "xsize": 16,
  "zsize": 16,
  "slices": [
    [
      "aaa=b       cddd",
      "a==b        cddd",
      "==b         cddd",
      "=b          ccdd",
      "b            ccd",
      "      efffg h cc",
      "      eiddj     ",
      "      eiddj     ",
      "      efffg     ",
      "b           h   ",
      "=bbbbbbbbbbbbbbb",
      "================",
      "kkkkkkkkkkkkkkkk",
      "llllllllllllllll",
      "llllllllllllllll",
      "vvvvvvvvvvvvvvvv"
    ],
    [
      "mmm=b       cddd",
      "m==b        cddd",
      "==b         cddd",
      "=b          ccdd",
      "b            ccd",
      "      efffg h cc",
      "      eiddj     ",
      "      eiddj     ",
      "      efffg     ",
      "b           h   ",
      "=bbbbbbbbbbbbbbb",
      "================",
      "nnnnnnnnnnnnnnnn",
      "llllllllllllllll",
      "llllllllllllllll",
      "vvvvvvvvvvvvvvvv"
    ],
    [
      "   =b       cddd",
      " ==b        cddd",
      "==b         cddd",
      "=b          ccdd",
      "b            ccd",
      "      efffg h cc",
      "      eiddj     ",
      "      eiddj     ",
      "      efffg     ",
      "b           h   ",
      "=bbbbbbbbbbbbbbb",
      "================",
      "nnnnnnnnnnnnnnnn",
      "llllllllllllllll",
      "llllllllllllllll",
      "vvvvvvvvvvvvvvvv"
    ],
    [
      "   =b       cddd",
      " ==b        cddd",
      "==b         cddd",
      "=b          ccdd",
      "b            ccd",
      "      efffg h cc",
      "      eiddj     ",
      "      eiddj     ",
      "      efffg     ",
      "b           h   ",
      "=bbbbbbbbbbbbbbb",
      "================",
      "nnnnnnnnnnnnnnnn",
      "llllllllllllllll",
      "llllllllllllllll",
      "vvvvvvvvvvvvvvvv"
    ],
    [
      "   =b       cddd",
      " ==b        cddd",
      "==b         cddd",
      "=b          ccdd",
      "b            ccd",
      "      efffg h cc",
      "      eiddj     ",
      "      eiddj     ",
      "      efffg     ",
      "b           h   ",
      "=bbbbbbbbbbbbbbb",
      "================",
      "nnnnnnnnnnnnnnnn",
      "llllllllllllllll",
      "llllllllllllllll",
      "vvvvvvvvvvvvvvvv"
    ],
    [
      "   =b       cddd",
      " ==b        cddd",
      "==b         cddd",
      "=b          ccdd",
      "b            ccd",
      "      efffg h cc",
      "      eiddj     ",
      "      eiddj     ",
      "      efffg     ",
      "b           h   ",
      "=bbbbbbbbbbbbbbb",
      "================",
      "nnnnnnnnnnnnnnnn",
      "llllllllllllllll",
      "llllllllllllllll",
      "vvvvvvvvvvvvvvvv"
    ]
  ]
}