{
  "name": "multi_nuclearpowerplant_34_base1",
  "refpalette": "deceasedcraft:multi_nuclearpowerplant_34/multi_nuclearpowerplant_34_base1_palette",
  "xsize": 16,
  "zsize": 16,
  "slices": [
    [
      "aaaaaab=========",
      "aaaaab==========",
      "aaaab===========",
      "aabb============",
      "abc=============",
      "bc==============",
      "c===============",
      "c===============",
      "cc==============",
      "cccccccccccccccc",
      "cccccccccccccccc",
      "cccccccccccccccc",
      "dddddddddddddddd",
      "eeeeeeeeeeeeeeee",
      "eeeeeeeeeeeeeeee",
      "vvvvvvvvvvvvvvvv"
    ],
    [
      "aaaaaabccccccccc",
      "aaaaabcccccccccc",
      "aaaabccccccccccc",
      "aabbcccccccccccc",
      "abcccccccccccccc",
      "bccccccccccccccc",
      "cccccccccccccccc",
      "cccccccccccccccc",
      "cccccccccccccccc",
      "cccccccccccccccc",
      "cccccccccccccccc",
      "cccccccccccccccc",
      "dddddddddddddddd",
      "eeeeeeeeeeeeeeee",
      "eeeeeeeeeeeeeeee",
      "vvvvvvvvvvvvvvvv"
    ],
    [
      "aaaaaabccccccccc",
      "aaaaabcccccccccc",
      "aaaabccccccccccc",
      "aabbcccccccccccc",
      "abcccccccccccccc",
      "bccccccccccccccc",
      "cccccccccccccccc",
      "cccccccccccccccc",
      "cccccccccccccccc",
      "cccccccccccccccc",
      "cccccccccccccccc",
      "cccccccccccccccc",
      "dddddddddddddddd",
      "eeeeeeeeeeeeeeee",
      "eeeeeeeeeeeeeeee",
      "vvvvvvvvvvvvvvvv"
    ],
    [
      "aaaaaabccccccccc",
      "aaaaabcccccccccc",
      "aaaabccccccccccc",
      "aabbcccccccccccc",
      "abcccccccccccccc",
      "bccccccccccccccc",
      "cccccccccccccccc",
      "cccccccccccccccc",
      "cccccccccccccccc",
      "cccccccccccccccc",
      "cccccccccccccccc",
      "cccccccccccccccc",
      "dddddddddddddddd",
      "eeeeeeeeeeeeeeee",
      "eeeeeeeeeeeeeeee",
      "vvvvvvvvvvvvvvvv"
    ],
    [
      "aaaaaabccccccccc",
      "aaaaabcccccccccc",
      "aaaabccccccccccc",
      "aabbcccccccccccc",
      "abcccccccccccccc",
      "bccccccccccccccc",
      "cccccccccccccccc",
      "cccccccccccccccc",
      "cccccccccccccccc",
      "cccccccccccccccc",
      "cccccccccccccccc",
      "cccccccccccccccc",
      "dddddddddddddddd",
      "eeeeeeeeeeeeeeee",
      "eeeeeeeeeeeeeeee",
      "vvvvvvvvvvvvvvvv"
    ],
    [
      "fbaaaabccccccccc",
      "baaaabcccccccccc",
      "aaaabccccccccccc",
      "aabbcccccccccccc",
      "abcccccccccccccc",
      "bcccccccccccccgg",
      "ccccccccccccgggc",
      "ccccccccccgggccc",
      "cccccccggggccccc",
      "cccgggggcccccccc",
      "ggggcccccccccccc",
      "cccccccccccccccc",
      "dddddddddddddddd",
      "cccccccccccccccc",
      "cccccccccccccccc",
      "vvvvvvvvvvvvvvvv"
    ]
  ]
}