{
  "name": "multi_nuclearpowerplant_34_base3",
  "refpalette": "deceasedcraft:multi_nuclearpowerplant_34/multi_nuclearpowerplant_34_base3_palette",
  "xsize": 16,
  "zsize": 16,
  "slices": [
    [
      "aaabcdddd       ",
      "abbcdddd        ",
      "b=cdddd         ",
      "=cdddd          ",
      "cdddd           ",
      "dddde           ",
      "ddddf           ",
      "dddddddddddddddd",
      "dddddddddddddddd",
      "cddddddddddddddd",
      "=ccccccccccccccc",
      "b===============",
      "gggggggggggggggg",
      "hhhhhhhhhhhhhhhh",
      "hhhhhhhhhhhhhhhh",
      "vvvvvvvvvvvvvvvv"
    ],
    [
      "ijjkl   m       ",
      "ikkl   m        ",
      "k=l   m         ",
      "=l   m          ",
      "ln  m           ",
      "                ",
      "                ",
      "    oooooooooooo",
      "                ",
      "lp     p     p  ",
      "=lllllllllllllll",
      "q===============",
      "qqqqqqqqqqqqqqqq",
      "hhhhhhhhhhhhhhhh",
      "hhhhhhhhhhhhhhhh",
      "vvvvvvvvvvvvvvvv"
    ],
    [
      "   kl           ",
      " kkl            ",
      "k=l             ",
      "=l              ",
      "l               ",
      "                ",
      "                ",
      "                ",
      "                ",
      "l               ",
      "=lllllllllllllll",
      "q===============",
      "qqqqqqqqqqqqqqqq",
      "hhhhhhhhhhhhhhhh",
      "hhhhhhhhhhhhhhhh",
      "vvvvvvvvvvvvvvvv"
    ],
    [
      "   kl           ",
      " kkl            ",
      "k=l             ",
      "=l              ",
      "l               ",
      "                ",
      "                ",
      "                ",
      "                ",
      "l               ",
      "=lllllllllllllll",
      "q===============",
      "qqqqqqqqqqqqqqqq",
      "hhhhhhhhhhhhhhhh",
      "hhhhhhhhhhhhhhhh",
      "vvvvvvvvvvvvvvvv"
    ],
    [
      "   kl           ",
      " kkl            ",
      "k=l             ",
      "=l              ",
      "l               ",
      "                ",
      "                ",
      "                ",
      "                ",
      "l               ",
      "=lllllllllllllll",
      "q===============",
      "qqqqqqqqqqqqqqqq",
      "hhhhhhhhhhhhhhhh",
      "hhhhhhhhhhhhhhhh",
      "vvvvvvvvvvvvvvvv"
    ],
    [
      "   kl           ",
      " kkl            ",
      "k=l             ",
      "=l              ",
      "l               ",
      "                ",
      "                ",
      "                ",
      "                ",
      "l               ",
      "=lllllllllllllll",
      "q===============",
      "qqqqqqqqqqqqqqqq",
      "hhhhhhhhhhhhhhhh",
      "hhhhhhhhhhhhhhhh",
      "vvvvvvvvvvvvvvvv"
    ]
  ]
}