{
  "name": "multi_nuclearpowerplant_34_base9",
  "refpalette": "deceasedcraft:multi_nuclearpowerplant_34/multi_nuclearpowerplant_34_base9_palette",
  "xsize": 16,
  "zsize": 16,
  "slices": [
    [
      "aaaaaaaaaaaaab  ",
      "aaaaaaaaaaaaab  ",
      "aaaaaaaaaaaaab  ",
      "aaaaaaaaaaaaaab ",
      "aaaaaaaaaaaaaab ",
      "aaaaaaaaaaaaaaab",
      "aaaaaaaaaaaaaaaa",
      "aaaaaaaaaaaaaaaa",
      "aaaaaaaaaaaaaaaa",
      "aaaaaaaaaaaaaaaa",
      "aaaaaaaaaaaaaaaa",
      "aaaaaaaaaaaaaaaa",
      "aaaaaaaaaaaaaaaa",
      "aaaaaaaaaaaaaaaa",
      "aaaaaaaaaaaaaaaa",
      "vvvvvvvvvvvvvvvv"
    ],
    [
      "aaaaaaaaaaaaab  ",
      "aaaaaaaaaaaaab  ",
      "aaaaaaaaaaaaab  ",
      "aaaaaaaaaaaaaab ",
      "aaaaaaaaaaaaaab ",
      "aaaaaaaaaaaaaaab",
      "aaaaaaaaaaaaaaaa",
      "aaaaaaaaaaaaaaaa",
      "aaaaaaaaaaaaaaaa",
      "aaaaaaaaaaaaaaaa",
      "aaaaaaaaaaaaaaaa",
      "aaaaaaaaaaaaaaaa",
      "aaaaaaaaaaaaaaaa",
      "aaaaaaaaaaaaaaaa",
      "aaaaaaaaaaaaaaaa",
      "vvvvvvvvvvvvvvvv"
    ],
    [
      "aaaaaaaaaaaaab  ",
      "aaaaaaaaaaaaab  ",
      "aaaaaaaaaaaaab  ",
      "aaaaaaaaaaaaaab ",
      "aaaaaaaaaaaaaab ",
      "aaaaaaaaaaaaaaab",
      "aaaaaaaaaaaaaaaa",
      "aaaaaaaaaaaaaaaa",
      "aaaaaaaaaaaaaaaa",
      "aaaaaaaaaaaaaaaa",
      "aaaaaaaaaaaaaaaa",
      "aaaaaaaaaaaaaaaa",
      "aaaaaaaaaaaaaaaa",
      "aaaaaaaaaaaaaaaa",
      "aaaaaaaaaaaaaaaa",
      "vvvvvvvvvvvvvvvv"
    ],
    [
      "ccaaaaaaaaaaab  ",
      "ccaaaaaaaaaaab  ",
      "ccaaaaaaaaaaab  ",
      "ccaaaaaaaaaaaab ",
      "ccaaaaaaaaaaaab ",
      "ccaaaaaaaaaaaaab",
      "ccaaaaaaaaaaaaaa",
      "ccaaaaaaaaaaaaaa",
      "ccaaaaaaaaaaaaaa",
      "ccaaaaaaaaaaaaaa",
      "ccaaaaaaaaaaaaaa",
      "ccaaaaaaaaaaaaaa",
      "ccaaaaaaaaaaaaaa",
      "aaaaaaaaaaaaaaaa",
      "aaaaaaaaaaaaaaaa",
      "vvvvvvvvvvvvvvvv"
    ],
    [
      "dcaaaaaaaaaaab  ",
      "dcaaaaaaaaaaab  ",
      "dcaaaaaaaaaaab  ",
      "dcaaaaaaaaaaaab ",
      "dcaaaaaaaaaaaab ",
      "dcaaaaaaaaaaaaab",
      "dcaaaaaaaaaaaaaa",
      "dcaaaaaaaaaaaaaa",
      "dcaaaaaaaaaaaaaa",
      "dcaaaaaaaaaaaaaa",
      "dcaaaaaaaaaaaaaa",
      "dcaaaaaaaaaaaaaa",
      "ccaaaaaaaaaaaaaa",
      "aaaaaaaaaaaaaaaa",
      "aaaaaaaaaaaaaaaa",
      "vvvvvvvvvvvvvvvv"
    ],
    [
      "ccaaaaaaaaaaab  ",
      "ccaaaaaaaaaaab  ",
      "ccaaaaaaaaaaab  ",
      "ccaaaaaaaaaaaab ",
      "ccaaaaaaaaaaaab ",
      "ccaaaaaaaaaaaaab",
      "ccaaaaaaaaaaaaaa",
      "ccaaaaaaaaaaaaaa",
      "ccaaaaaaaaaaaaaa",
      "ccaaaaaaaaaaaaaa",
      "ccaaaaaaaaaaaaaa",
      "dcaaaaaaaaaaaaaa",
      "ccaaaaaaaaaaaaaa",
      "aaaaaaaaaaaaaaaa",
      "aaaaaaaaaaaaaaaa",
      "vvvvvvvvvvvvvvvv"
    ]
  ]
}