{
  "name": "multi_nuclearpowerplant_34_base7",
  "refpalette": "deceasedcraft:multi_nuclearpowerplant_34/multi_nuclearpowerplant_34_base7_palette",
  "xsize": 16,
  "zsize": 16,
  "slices": [
    [
      "   =a       bccc",
      "  =a        bccc",
      " =a         bccc",
      "=a          bbcc",
      "ad    eeeee  bbc",
      "      fffff g bb",
      "      fffff  h  ",
      "      fffffi j  ",
      "      fffff     ",
      "ak    lllll mk  ",
      "=aaaaaaaaaaaaaaa",
      "n===============",
      "oooooooooooooooo",
      "pppppppppppppppp",
      "pppppppppppppppp",
      "vvvvvvvvvvvvvvvv"
    ],
    [
      "   =a       bccc",
      "  =a        bccc",
      " =a         bccc",
      "=a          bbcc",
      "a            bbc",
      "      qrrrs m bb",
      "tttttturrrs   h ",
      "tttttturrrs   j ",
      "      qrrrs     ",
      "a           m   ",
      "=aaaaaaaaaaaaaaa",
      "n===============",
      "oooooooooooooooo",
      "pppppppppppppppp",
      "pppppppppppppppp",
      "vvvvvvvvvvvvvvvv"
    ],
    [
      "   =a       bwww",
      "  =a        bwww",
      " =a         bwww",
      "=a          bbww",
      "a            bbw",
      "xxxxxxurrrs m bb",
      "wwwwwwwyyyA    h",
      "wwwwwwwyyyA    j",
      "BBBBBBurrrs     ",
      "a           m   ",
      "=aaaaaaaaaaaaaaa",
      "n===============",
      "oooooooooooooooo",
      "pppppppppppppppp",
      "pppppppppppppppp",
      "vvvvvvvvvvvvvvvv"
    ],
    [
      "   =a       bwww",
      "  =a        bwww",
      " =a         bwww",
      "=a          bbww",
      "a            bbw",
      "xxxxxxurrrs m bb",
      "wwwwwwwyyyA     ",
      "wwwwwwwyyyA     ",
      "BBBBBBurrrs     ",
      "a           m   ",
      "=aaaaaaaaaaaaaaa",
      "n===============",
      "oooooooooooooooo",
      "pppppppppppppppp",
      "pppppppppppppppp",
      "vvvvvvvvvvvvvvvv"
    ],
    [
      "   =a       bwww",
      "  =a        bwww",
      " =a         bwww",
      "=a          bbww",
      "a            bbw",
      "      qrrrs m bb",
      "CCCCCCuDwwA     ",
      "CCCCCCuDwwA     ",
      "      qrrrs     ",
      "a           m   ",
      "=aaaaaaaaaaaaaaa",
      "n===============",
      "oooooooooooooooo",
      "pppppppppppppppp",
      "pppppppppppppppp",
      "vvvvvvvvvvvvvvvv"
    ],
    [
      "EEE=a       bwww",
      "EE=a        bwww",
      "E=a         bwww",
      "=a          bbww",
      "a            bbw",
      "      qrrrs m bb",
      "      qDwwA     ",
      "      qDwwA     ",
      "      qrrrs     ",
      "a           m   ",
      "=aaaaaaaaaaaaaaa",
      "n===============",
      "oooooooooooooooo",
      "pppppppppppppppp",
      "pppppppppppppppp",
      "vvvvvvvvvvvvvvvv"
    ]
  ]
}