{
  "name": "multi_nuclearpowerplant_34_base8",
  "refpalette": "deceasedcraft:multi_nuclearpowerplant_34/multi_nuclearpowerplant_34_base8_palette",
  "xsize": 16,
  "zsize": 16,
  "slices": [
    [
      "aaaaaaaaaaaaab  ",
      "aaaaaaaaaaaaab  ",
      "aaaaaaaaaaaaab  ",
      "aaaaaaaaaaaaaab ",
      "aaaaaaaaaaaaaab ",
      "aaaaaaaaaaaaaaab",
      "aaaaaaaaaaaaaaaa",
      "aaaaaaaaaaaaaaaa",
      "aaaaaaaaaaaaaaaa",
      "aaaaaaaaaaaaaaaa",
      "aaaaaaaaaaaaaaaa",
      "caaaaaaaaaaaaaaa",
      "aaaaaaaaaaaaaaaa",
      "dddddddddddddddd",
      "dddddddddddddddd",
      "vvvvvvvvvvvvvvvv"
    ],
    [
      "=============eaa",
      "=============eaa",
      "=============eaa",
      "==============ea",
      "==============ea",
      "===============e",
      "================",
      "================",
      "================",
      "================",
      "================",
      "c===============",
      "eeeeeeeeeeeeeeee",
      "dddddddddddddddd",
      "dddddddddddddddd",
      "vvvvvvvvvvvvvvvv"
    ],
    [
      "dddddddddddddbdd",
      "dddddddddddddbdd",
      "dddddddddddddbdd",
      "ddddddddddddddbd",
      "ddddddddddddddbd",
      "dddddddddddddddb",
      "dddddddddddddddd",
      "dddddddddddddddd",
      "dddddddddddddddd",
      "dddddddddddddddd",
      "aadddddddddddddd",
      "cadddddddddddddd",
      "bbbbbbbbbbbbbbbb",
      "dddddddddddddddd",
      "dddddddddddddddd",
      "vvvvvvvvvvvvvvvv"
    ],
    [
      "dddddddddddddbdd",
      "dddddddddddddbdd",
      "dddddddddddddbdd",
      "ddddddddddddddbd",
      "ddddddddddddddbd",
      "dddddddddddddddb",
      "dddddddddddddddd",
      "dddddddddddddddd",
      "dddddddddddddddd",
      "dddddddddddddddd",
      "aadddddddddddddd",
      "cadddddddddddddd",
      "bbbbbbbbbbbbbbbb",
      "dddddddddddddddd",
      "dddddddddddddddd",
      "vvvvvvvvvvvvvvvv"
    ],
    [
      "==fg============",
      "=fg=============",
      "fg==============",
      "g===============",
      "================",
      "================",
      "================",
      "================",
      "================",
      "================",
      "g===============",
      "cggggggggggggggg",
      "bbbbbbbbbbbbbbbb",
      "dddddddddddddddd",
      "dddddddddddddddd",
      "vvvvvvvvvvvvvvvv"
    ],
    [
      "   =hhhhhhhhhhhh",
      "  =hhhhhhhhhhhhh",
      " =hhhhhhhhhhhhhh",
      "=hhhhhhhhhhhhhhh",
      "hhhhhhhhhhhhhhhh",
      "hhhhhhhhhhhhhhhh",
      "hhhhhhhhhhhhhhhh",
      "hhhhhhhhhhhhhhhh",
      "hhhhhhhhhhhhhhhh",
      "hhhhhhhhhhhhhhhh",
      "=hhhhhhhhhhhhhhh",
      "c===============",
      "bbbbbbbbbbbbbbbb",
      "dddddddddddddddd",
      "dddddddddddddddd",
      "vvvvvvvvvvvvvvvv"
    ]
  ]
}