{
  "name": "multi_nuclearpowerplant_34_base5",
  "refpalette": "deceasedcraft:multi_nuclearpowerplant_34/multi_nuclearpowerplant_34_base5_palette",
  "xsize": 16,
  "zsize": 16,
  "slices": [
    [
      "   =a       bccc",
      " ==a    ddddbeee",
      "==a     d   bccc",
      "=a      d   ffcc",
      "a       d    ffc",
      "      ghhhi j ff",
      "      gkccl     ",
      "      gkccl     ",
      "      ghhhi     ",
      "a           j   ",
      "=aaaaaaaaaaaaaaa",
      "================",
      "mmmmmmmmmmmmmmmm",
      "nnnnnnnnnnnnnnnn",
      "nnnnnnnnnnnnnnnn",
      "vvvvvvvvvvvvvvvv"
    ],
    [
      "   =a   oooobppp",
      " ==a   qcccccccc",
      "==a    qcrssbttt",
      "=a     qcu  ffcc",
      "a      qcu   ffc",
      "      ghchi j ff",
      "      gwwwl     ",
      "      gwwwl     ",
      "      ghhhi     ",
      "a           j   ",
      "=aaaaaaaaaaaaaaa",
      "================",
      "mmmmmmmmmmmmmmmm",
      "nnnnnnnnnnnnnnnn",
      "nnnnnnnnnnnnnnnn",
      "vvvvvvvvvvvvvvvv"
    ],
    [
      "   =a       bccc",
      " ==a    xxxxbyyy",
      "==a     x   bccc",
      "=a      x   ffcc",
      "a       x    ffc",
      "      ghhhi j ff",
      "      ghhhi     ",
      "      ghhhi     ",
      "      ghhhi     ",
      "a           j   ",
      "=aaaaaaaaaaaaaaa",
      "================",
      "mmmmmmmmmmmmmmmm",
      "nnnnnnnnnnnnnnnn",
      "nnnnnnnnnnnnnnnn",
      "vvvvvvvvvvvvvvvv"
    ],
    [
      "   =a       fccc",
      " ==a        fccc",
      "==a         fccc",
      "=a          ffcc",
      "a            ffc",
      "      ghhhi j ff",
      "      ghhhi     ",
      "      ghhhi     ",
      "      ghhhi    A",
      "a           j  B",
      "=aaaaaaaaaaaaaaa",
      "================",
      "mmmmmmmmmmmmmmmm",
      "nnnnnnnnnnnnnnnn",
      "nnnnnnnnnnnnnnnn",
      "vvvvvvvvvvvvvvvv"
    ],
    [
      "   =a       fccc",
      " ==a        fccc",
      "==a         fccc",
      "=a          ffcc",
      "a            ffc",
      "            j ff",
      "                ",
      "                ",
      "              A ",
      "a           j B ",
      "=aaaaaaaaaaaaaaa",
      "================",
      "mmmmmmmmmmmmmmmm",
      "nnnnnnnnnnnnnnnn",
      "nnnnnnnnnnnnnnnn",
      "vvvvvvvvvvvvvvvv"
    ],
    [
      "   =a       fccc",
      " ==a        fccc",
      "==a         fccc",
      "=a          ffcc",
      "a            ffc",
      "           CD ff",
      "           CC   ",
      "           CC   ",
      "           CCA  ",
      "a          CDB  ",
      "=aaaaaaaaaaaaaaa",
      "================",
      "mmmmmmmmmmmmmmmm",
      "nnnnnnnnnnnnnnnn",
      "nnnnnnnnnnnnnnnn",
      "vvvvvvvvvvvvvvvv"
    ]
  ]
}