{
  "name": "multi_nuclearpowerplant_34_base2",
  "refpalette": "deceasedcraft:multi_nuclearpowerplant_34/multi_nuclearpowerplant_34_base2_palette",
  "xsize": 16,
  "zsize": 16,
  "slices": [
    [
      "   ab           ",
      " aab            ",
      "a=b             ",
      "=b              ",
      "b               ",
      "                ",
      "                ",
      "                ",
      "                ",
      "b               ",
      "=bbbbbbbbbbbbbbb",
      "c===============",
      "cccccccccccccccc",
      "dddddddddddddddd",
      "dddddddddddddddd",
      "vvvvvvvvvvvvvvvv"
    ],
    [
      "   ab           ",
      " aab            ",
      "a=b             ",
      "=b              ",
      "b               ",
      "                ",
      "                ",
      "                ",
      "                ",
      "b               ",
      "=bbbbbbbbbbbbbbb",
      "c===============",
      "cccccccccccccccc",
      "dddddddddddddddd",
      "dddddddddddddddd",
      "vvvvvvvvvvvvvvvv"
    ],
    [
      "   ab           ",
      " aab            ",
      "a=b             ",
      "=b              ",
      "b               ",
      "                ",
      "                ",
      "                ",
      "                ",
      "b               ",
      "=bbbbbbbbbbbbbbb",
      "c===============",
      "cccccccccccccccc",
      "dddddddddddddddd",
      "dddddddddddddddd",
      "vvvvvvvvvvvvvvvv"
    ],
    [
      "   abb          ",
      " aabb           ",
      "a=bb            ",
      "=bb             ",
      "bb              ",
      "b               ",
      "e               ",
      "e               ",
      "e               ",
      "bfffffffffffffff",
      "=bbbbbbbbbbbbbbb",
      "c===============",
      "cccccccccccccccc",
      "dddddddddddddddd",
      "dddddddddddddddd",
      "vvvvvvvvvvvvvvvv"
    ],
    [
      "   ghhbi        ",
      " gghhbi         ",
      "ghhhbi          ",
      "hh=bi           ",
      "h=bi            ",
      "=bi             ",
      "bi              ",
      "bi              ",
      "bbiiiiiiiiiiiiii",
      "=bbbbbbbbbbbbbbb",
      "j===============",
      "jjjjjjjjjjjjjjjj",
      "cccccccccccccccc",
      "dddddddddddddddd",
      "dddddddddddddddd",
      "vvvvvvvvvvvvvvvv"
    ],
    [
      "kkkkhh=bbbbbbbbb",
      "kkkhh=bbbbbbbbbb",
      "khhh=bbbbbbbbbbb",
      "hh==bbbbbbbbbbbb",
      "h==bbbbbbbbbbbbb",
      "==bbbbbbbbbbbbbb",
      "=bbbbbbbbbbbbbbb",
      "=bbbbbbbbbbbbbbb",
      "==bbbbbbbbbbbbbb",
      "j===============",
      "jjjjjjjjjjjjjjjj",
      "jjjjjjjjjjjjjjjj",
      "cccccccccccccccc",
      "dddddddddddddddd",
      "dddddddddddddddd",
      "vvvvvvvvvvvvvvvv"
    ]
  ]
}