{
  "name": "multi_nuclearpowerplant_34_base4",
  "refpalette": "deceasedcraft:multi_nuclearpowerplant_34/multi_nuclearpowerplant_34_base4_palette",
  "xsize": 16,
  "zsize": 16,
  "slices": [
    [
      "   =a       bccc",
      " ==a        bccc",
      "==a         bccc",
      "=a          bbcc",
      "a            bbc",
      "          def bb",
      "          g h   ",
      "           ih   ",
      "           i    ",
      "a          jk   ",
      "=aaaaaaaaaaaaaaa",
      "================",
      "llllllllllllllll",
      "mmmmmmmmmmmmmmmm",
      "mmmmmmmmmmmmmmmm",
      "vvvvvvvvvvvvvvvv"
    ],
    [
      "   =a       bccc",
      " ==a        bccc",
      "==a         bccc",
      "=a          bbcc",
      "a            bbc",
      "         d    bb",
      "         g      ",
      "                ",
      "                ",
      "a               ",
      "=aaaaaaaaaaaaaaa",
      "================",
      "llllllllllllllll",
      "mmmmmmmmmmmmmmmm",
      "mmmmmmmmmmmmmmmm",
      "vvvvvvvvvvvvvvvv"
    ],
    [
      "   =a       bccc",
      " ==a        bccc",
      "==a         bccc",
      "=a          bbcc",
      "a            bbc",
      "        d     bb",
      "        g       ",
      "                ",
      "                ",
      "a               ",
      "=aaaaaaaaaaaaaaa",
      "================",
      "llllllllllllllll",
      "mmmmmmmmmmmmmmmm",
      "mmmmmmmmmmmmmmmm",
      "vvvvvvvvvvvvvvvv"
    ],
    [
      "   =a       bccc",
      " ==a        bccc",
      "==a         bccc",
      "=a          bbcc",
      "a            bbc",
      "       d      bb",
      "       g        ",
      "                ",
      "                ",
      "a               ",
      "=aaaaaaaaaaaaaaa",
      "================",
      "llllllllllllllll",
      "mmmmmmmmmmmmmmmm",
      "mmmmmmmmmmmmmmmm",
      "vvvvvvvvvvvvvvvv"
    ],
    [
      "   =a       b   ",
      " ==a        b   ",
      "==a         b   ",
      "=a          bb  ",
      "a            bb ",
      "      d       bb",
      "      g         ",
      "                ",
      "                ",
      "a               ",
      "=aaaaaaaaaaaaaaa",
      "================",
      "llllllllllllllll",
      "mmmmmmmmmmmmmmmm",
      "mmmmmmmmmmmmmmmm",
      "vvvvvvvvvvvvvvvv"
    ],
    [
      "   =a       n   ",
      " ==a        n   ",
      "==a         n   ",
      "=a          nn  ",
      "a            nn ",
      "     d        nn",
      "     g          ",
      "                ",
      "                ",
      "a               ",
      "=aaaaaaaaaaaaaaa",
      "================",
      "llllllllllllllll",
      "mmmmmmmmmmmmmmmm",
      "mmmmmmmmmmmmmmmm",
      "vvvvvvvvvvvvvvvv"
    ]
  ]
}