{
  "name": "multi_nuclearpowerplant_34_ground",
  "refpalette": "deceasedcraft:multi_nuclearpowerplant_34/multi_nuclearpowerplant_34_ground_palette",
  "xsize": 16,
  "zsize": 16,
  "slices": [
    [
      " abcddceeeeeeeee",
      " bcdeceeeeeeeeee",
      "bceeceeeeeeeeeee",
      "eecceeeeeeeeeeee",
      "eceeeeeeeeeeeeee",
      "ceeeeeeeeeeeeeff",
      "eeeeeeeeeeeefffd",
      "eeeeeeeeeefffddd",
      "eeeeeeeffffddddd",
      "eeefffffdddddddd",
      "ffffdddddddddddd",
      "dddddddddddddddd",
      "dddddddddddzzdzz",
      "dddddddddzzddzdz",
      "dddzddzdzzdzzzzd",
      "ddzzzdzddzzzzdzz"
    ],
    [
      "eeeeeeeeezzzzzzz",
      "eeeeeeezzzzzzzzz",
      "eeeeezzzzzzzzzzz",
      "eeezzzzzzzzzzzdz",
      "zzzzzzdzzzzzzzzz",
      "zzzzzzzzzzzzzzzz",
      "zzzzzzzzzzzzzzzg",
      "zzzzzzzzzzdzzhi ",
      "zdzzzzzzzzzhi   ",
      "zdzzzzdzghi     ",
      "zzzzhgii        ",
      "ghii            ",
      "                ",
      "                ",
      "      j         ",
      "  j        jj   "
    ],
    [
      "zzzzzzzzz       ",
      "zzzzzzz   j k j ",
      "zzzzz     j jj  ",
      "zzzzj  zjj jj   ",
      "j    j          ",
      " k  jj  j     ll",
      "     m      lll ",
      " j kjj jj lll   ",
      "     j llll     ",
      "   lllll        ",
      "llll            ",
      "                ",
      "                ",
      "                ",
      "                ",
      "                "
    ],
    [
      "  k j           ",
      "    jj          ",
      "                ",
      "  j             ",
      "                ",
      "              ll",
      "            lll ",
      "          lll   ",
      "       llll     ",
      "   lllll        ",
      "llll            ",
      "                ",
      "                ",
      "                ",
      "                ",
      "                "
    ],
    [
      "                ",
      "                ",
      "                ",
      "                ",
      "                ",
      "               n",
      "             nn ",
      "           nn   ",
      "        nnn     ",
      "    nnnn        ",
      "nnn             ",
      "                ",
      "                ",
      "                ",
      "                ",
      "                "
    ],
    [
      "                ",
      "                ",
      "                ",
      "                ",
      "                ",
      "                ",
      "                ",
      "                ",
      "                ",
      "                ",
      "                ",
      "                ",
      "                ",
      "                ",
      "                ",
      "                "
    ]
  ]
}