{
  "name": "multi_laboratory_5_top",
  "refpalette": "deceasedcraft:multi_laboratory_5/multi_laboratory_5_top_palette",
  "xsize": 16,
  "zsize": 16,
  "slices": [
    [
      "                ",
      "                ",
      "aababaaaababaaba",
      "cccccdccccdccccc",
      "cccccecccceccccc",
      "ffffffffffffffff",
      "g  h g  h g ii g",
      "gjjjjgjjjjgjjjjg",
      "gggggggggggggggg",
      "g    g    g    g",
      "g    g    g    g",
      "g    g    g    g",
      "g    g    g    g",
      "g    g    g    g",
      "g    k    g    g",
      "gggg lggg lgggmg"
    ],
    [
      "                ",
      "                ",
      "aaaaaabaaaaaabaa",
      "                ",
      "                ",
      "noooofoooofoooon",
      "pii  pii  p  iip",
      "pjjjjpjjjjpjjjjp",
      "gppppgppppgppppg",
      "p    p    p    p",
      "p    p    p    p",
      "p    p    p    p",
      "p    p    p    p",
      "p    p    p    p",
      "p    p    p    p",
      "gpqqpgpqqpgpqqpg"
    ],
    [
      "                ",
      "                ",
      "aabaaaabaaaaaaab",
      "                ",
      "                ",
      "noooofoooofoooon",
      "pi iip  h p h ip",
      "pjjjjpjjjjpjjjjp",
      "gppppgppppgppppg",
      "p    p    p    p",
      "p    p    p    p",
      "p    p    p    p",
      "p    p    p    p",
      "p    p    p    p",
      "p    p    p    p",
      "gp  pgp  pgp  pg"
    ],
    [
      "                ",
      "                ",
      "baaaaaaaaaaaaaaa",
      "                ",
      "                ",
      "noooofoooofoooon",
      "p h  p i  p  i p",
      "pjjjjpjjjjpjjjjp",
      "gppppgppppgppppg",
      "p    p    p    p",
      "p    p    p    p",
      "p    p    p    p",
      "p    p    p    p",
      "p    p    p    p",
      "p    p    p    p",
      "gprrpgprrpgprrpg"
    ],
    [
      "                ",
      "                ",
      "aaaaaaaaaaabaaaa",
      "                ",
      "                ",
      "noooofoooofoooon",
      "p    p    p    p",
      "p    p    p    p",
      "gppppgppppgppppg",
      "p    p    p    p",
      "p    p    p    p",
      "p    p    p    p",
      "p    p    p    p",
      "p    p    p    p",
      "p    p    p    p",
      "gppppgppppgppppg"
    ],
    [
      "                ",
      "                ",
      "aaaaaaaaaaaaaaaa",
      "                ",
      "                ",
      "ffffffffffffffff",
      "ssssssssssssssss",
      "ssssssssssssssss",
      "ssssssssssssssss",
      "sttttsttttstttts",
      "ut  tut  tut  tu",
      "sttttsttttstttts",
      "sttttsttttstttts",
      "sttttsttttstttts",
      "sttttsttttstttts",
      "ffffffffffffffff"
    ],
    [
      "                ",
      "                ",
      "aaaaaaaaaaaaaaaa",
      "                ",
      "                ",
      "w xx   xx   xx w",
      "wyAABBBAABBBCDEw",
      "wyAAE y!AE yFFBB",
      "w II   II   II w",
      "wwwwwwwwwwwwwwww",
      "uJ KJuJLJJuJLJJu",
      "wwwwwwwwwwwwwwww",
      "M    M    M    M",
      "NBBBBNBBBBNBBBBN",
      "O    O    O    O",
      "wwwwwwwwwwwwwwww"
    ],
    [
      "                ",
      "                ",
      "aaaaaaaaaaaaaaaa",
      "                ",
      "                ",
      "                ",
      "  PQ   RR    S  ",
      "  PR   RR   SS  ",
      "                ",
      "T              T",
      "                ",
      "T              T",
      "                ",
      "                ",
      "                ",
      "                "
    ]
  ]
}