{
  "name": "multi_laboratory_5_base5",
  "refpalette": "deceasedcraft:multi_laboratory_5/multi_laboratory_5_base5_palette",
  "xsize": 16,
  "zsize": 16,
  "slices": [
    [
      "vvvvvvvvvvvvvvvv",
      "aaaaaaaaaaaaaaaa",
      "bbbbbbbbbbbbbbbb",
      "                ",
      "                ",
      "cccccccccccccccc",
      "c    c    c    c",
      "cd  dcd  dcd  dc",
      "cccccccccccccccc",
      "c    c    c    c",
      "c    c    c    c",
      "c    c    c    c",
      "c    c    c    c",
      "c    c    c    c",
      "c    c    c    c",
      "ceeeeceeeeceeeec"
    ],
    [
      "vvvvvvvvvvvvvvvv",
      "aaaaaaaaaaaaaaaa",
      "bbbbbbbbbbbbbbbb",
      "                ",
      "                ",
      "ceeeeeeeeeeeeeec",
      "e    e    e    e",
      "ed  ded  ded  de",
      "ceeeeceeeeceeeec",
      "e    e    e    e",
      "e    e    e    e",
      "e    e    e    e",
      "e    e    e    e",
      "e    e    e    e",
      "e    e    e    e",
      "ceeeeceeeeceeeec"
    ],
    [
      "vvvvvvvvvvvvvvvv",
      "aaaaaaaaaaaaaaaa",
      "bbbbbbbbbbbbbbbb",
      "                ",
      "                ",
      "ceeeeeeeeeeeeeec",
      "e    e    e    e",
      "ed  ded  ded  de",
      "ceeeeceeeeceeeec",
      "e    e    e    e",
      "e    e    e    e",
      "e    e    e    e",
      "e    e    e    e",
      "e    e    e    e",
      "e    e    e    e",
      "ceeeeceeeeceeeec"
    ],
    [
      "vvvvvvvvvvvvvvvv",
      "aaaaaaaaaaaaaaaa",
      "bbbbbbbbbbbbbbbb",
      "                ",
      "                ",
      "ceeeeeeeeeeeeeec",
      "e    e    e    e",
      "ed  ded  ded  de",
      "ceeeeceeeeceeeec",
      "e    e    e    e",
      "e    e    e    e",
      "e    e    e    e",
      "e    e    e    e",
      "e    e    e    e",
      "e    e    e    e",
      "ceeeeceeeeceeeec"
    ],
    [
      "vvvvvvvvvvvvvvvv",
      "aaaaaaaaaaaaaaaa",
      "bbbbbbbbbbbbbbbb",
      "                ",
      "                ",
      "ceeeeeeeeeeeeeec",
      "e    e    e    e",
      "ed  ded  ded  de",
      "ceeeeceeeeceeeec",
      "e    e    e    e",
      "e    e    e    e",
      "e    e    e    e",
      "e    e    e    e",
      "e    e    e    e",
      "e    e    e    e",
      "ceeeeceeeeceeeec"
    ],
    [
      "vvvvvvvvvvvvvvvv",
      "aaaaaaaaaaaaaaaa",
      "bbbbbbbbbbbbbbbb",
      "                ",
      "                ",
      "ceeeeeeeeeeeeeec",
      "e    e    e    e",
      "ed  ded  ded  de",
      "ceeeeceeeeceeeec",
      "e    e    e    e",
      "e    e    e    e",
      "e    e    e    e",
      "e    e    e    e",
      "e    e    e    e",
      "e    e    e    e",
      "ceeeeceeeeceeeec"
    ]
  ]
}