{
  "name": "multi_laboratory_5_ground",
  "refpalette": "deceasedcraft:multi_laboratory_5/multi_laboratory_5_ground_palette",
  "xsize": 16,
  "zsize": 16,
  "slices": [
    [
      "zzzzzzzzzzzzzzzz",
      "aabaaaazzaaaaaaa",
      "cccccccccccccccc",
      "cccccccccccccccc",
      "cccccccccccccccc",
      "dddddddddddddddd",
      "e    e    f    e",
      "eg  geg  gfg  ge",
      "eeeeeeeeeeeeeeee",
      "e    ehhhhe    e",
      "e    ehhhhe    e",
      "e    ehhhhe    e",
      "e    ehhhhe    e",
      "e    ehhhhe    e",
      "e    ehhh e    e",
      "eeee ieeeeeeeebj"
    ],
    [
      "              kk",
      "       k        ",
      "llllmmmmmmmmmmmm",
      "                ",
      "                ",
      "noooodoooodoooon",
      "f    f    f    f",
      "fppppfppppfppppf",
      "effffeffffeffffe",
      "f    fhqqhf    f",
      "f    fr  sf    f",
      "f    fr  sf    f",
      "f    fr  tf    f",
      "f    fr  sf    f",
      "f    fhuwhf    f",
      "efxxfefxxfefxxfe"
    ],
    [
      "                ",
      "                ",
      "llllmmmmmmmmmmmm",
      "                ",
      "                ",
      "noooodoooodoooon",
      "f y  f A  f  A f",
      "fppppfppppfppppf",
      "effffeffffeffffe",
      "f    fhqqhf    f",
      "f    fr  sf    f",
      "f    fr  sf    f",
      "f    fr  sf    f",
      "f    fr  sf    f",
      "f    fhBChf    f",
      "ef  fef  fef  fe"
    ],
    [
      "                ",
      "                ",
      "llllDDDDEDDDDEDD",
      "                ",
      "                ",
      "noooodoooodoooon",
      "fy A f  yyfyy  f",
      "fppppfppppfppppf",
      "effffeffffeffffe",
      "f    fhqqhf    f",
      "f    fr  sf    f",
      "f    fr  sf    f",
      "f    fr  sf    f",
      "f    fr  sf    f",
      "f    fhqqhf    f",
      "efhhfefhhfefhhfe"
    ],
    [
      "                ",
      "                ",
      "DEEDEDDDDEDDEDDD",
      "FFFF            ",
      "                ",
      "noooodoooodoooon",
      "fyy  f yy f  A f",
      "fppppfppppfppppf",
      "effffeffffeffffe",
      "f    fhqqhf    f",
      "f    frIIsf    f",
      "f    frIIsf    f",
      "f    frIIsf    f",
      "f    frIIsf    f",
      "f    fhqqhf    f",
      "effffeffffeffffe"
    ],
    [
      "                ",
      "                ",
      "DEEDDDDEDDEDDEEE",
      "                ",
      "                ",
      "noooodoooodoooon",
      "f y  f y  f y  f",
      "fppppfppppfppppf",
      "effffeffffeffffe",
      "f    fhhhhf    f",
      "f    fhqqhf    f",
      "f    fhqqhf    f",
      "f    fhqqhf    f",
      "f    fhqqhf    f",
      "f    fhhhhf    f",
      "effffeffffeffffe"
    ]
  ]
}