{
  "name": "multi_laboratory_5_base7",
  "refpalette": "deceasedcraft:multi_laboratory_5/multi_laboratory_5_base7_palette",
  "xsize": 16,
  "zsize": 16,
  "slices": [
    [
      "vvvvvvvvvvvvvvvv",
      "abaaaaaaaaaaaaaa",
      "abcaaaaaaaaaaaaa",
      "baacaabaaaaaaaaa",
      "aaaaaaaaaaaaaaaa",
      "baacacaaaaaaaaab",
      "daeaeeaaaaaaaaaa",
      "aeeeeeaaaaaaaaaa",
      "eeeeaeeaaaaaaaaa",
      "aeaaaaaaaaaaaaaa",
      "aaaaaaaaaaaaaaaa",
      "aaaaaaaaaaaaaaaa",
      "aaaaaaaaaaaaaaaa",
      "aaaaaaaaaaaaaaaa",
      "aaaaaaaaaaaaaaaa",
      "aaaaaaaaaaaaaaaa"
    ],
    [
      "vvvvvvvvvvvvvvvv",
      "aaaaaaaaaaaaaaaa",
      "ffffffffffffffff",
      "   agghiddj  dda",
      "     k       gld",
      "m   hm    md   m",
      "     n a dba ggd",
      "  oo peaaaaaa ga",
      "n  neeeaaaaaaaaa",
      "epeeeeeaaaaaaaaa",
      "eeeeeeeaaaaaaaaa",
      "eeeaaaaaaaaaaaaa",
      "eaaaaaaaaaaaaaaa",
      "aaaaaaaaaaaaadad",
      "aaaaaaaaaaaaaaad",
      "aaaaaaaaaaaaaaaa"
    ],
    [
      "vvvvvvvvvvvvvvvv",
      "aaaaaaaaaaaaaaaa",
      "ffffffffffffffff",
      "     g         q",
      "                ",
      "m    m    m    m",
      "           d  g ",
      " g   nr  daa   d",
      "     pedcaaaaaaa",
      "nnpseeeaaaaatdaa",
      "pseeeeeaaaaactta",
      "eeeeaaaaaaaaduuu",
      "eeaaaaaaaaaaa  d",
      "eaaaaaaaaaaaa   ",
      "aaaaaaaaaaaaaa  ",
      "aaaaaaaaaaaaaaa "
    ],
    [
      "vvvvvvvvvvvvvvvv",
      "aaaaaaaaaaaaaaaa",
      "ffffffffffffffff",
      "                ",
      "                ",
      "m    m    m    m",
      "                ",
      " r    r         ",
      "     w   aaaadaa",
      "  nxneeaaaaayyaa",
      "wxeeeeeaaaaattta",
      "eeaaaaaaaaaauu u",
      "eaaaaaaaaaaaa   ",
      "aaaaaaaaaaaaa   ",
      "aaaaaaaaaaaaaa  ",
      "aaaaaaaaaaaaaaa "
    ],
    [
      "vvvvvvvvvvvvvvvv",
      "aaaaaaaaaaaaaaaa",
      "ffffffffffffffff",
      "                ",
      "                ",
      "m    m    m    m",
      "                ",
      " r    r       rq",
      "     AeB  dd Baa",
      "   eeeeaaaatByaa",
      "AeeeeeeaaaaatBta",
      "eaaaaaaaaaaauuca",
      "aaaaaaaaaaaaaBBa",
      "aaaaaaaaaaaaa Ba",
      "aaaaaaaaaaaaaaaa",
      "aaaaaaaaaaaaaaaa"
    ],
    [
      "vvvvvvvvvvvvvvvv",
      "aaaaaaaaaaaaaaaa",
      "ffffffffffffffff",
      "                ",
      "                ",
      "m    m    m    m",
      "               B",
      "Br  r r       ra",
      "cB  eeeaaBBccaaa",
      "effffeffffaffffa",
      "effffeffffaffffa",
      "affffaffffaffffa",
      "affffaffffaffffa",
      "affffaffffaffffa",
      "affffaffffaffffa",
      "aaaaaaaaaaaaaaaa"
    ]
  ]
}