{
  "name": "multi_laboratory_5_base1",
  "refpalette": "deceasedcraft:multi_laboratory_5/multi_laboratory_5_base1_palette",
  "xsize": 16,
  "zsize": 16,
  "slices": [
    [
      "vvvvvvvvvvvvvvvv",
      "aaaaaaaaaaaaaaaa",
      "bbbbbbbbbbbbbbbb",
      "                ",
      "                ",
      "cccccccccccccccc",
      "c    c    c    c",
      "cd  dcd  dcd  dc",
      "cccccccccccccccc",
      "c    c    c    c",
      "c    c    c    c",
      "c    c    c    c",
      "c    c    c    c",
      "c    c    c    c",
      "c    c    c    c",
      "cccc eccc ecccfg"
    ],
    [
      "vvvvvvvvvvvvvvvv",
      "aaaaaaaaaaaaaaaa",
      "bbbbbbbbbbbbbbbb",
      "                ",
      "                ",
      "chhhhhhhhhhhhhhc",
      "h    h    h    h",
      "hd  dhd  dhd  dh",
      "chhhhchhhhchhhhc",
      "h    h    h    h",
      "h    h    h    h",
      "h    h    h    h",
      "h    h    h    h",
      "h    h    h    h",
      "h    h    h    h",
      "chiihchiihchiihc"
    ],
    [
      "vvvvvvvvvvvvvvvv",
      "aaaaaaaaaaaaaaaa",
      "bbbbbbbbbbbbbbbb",
      "                ",
      "                ",
      "chhhhhhhhhhhhhhc",
      "h    h    h    h",
      "hd  dhd  dhd  dh",
      "chhhhchhhhchhhhc",
      "h    h    h    h",
      "h    h    h    h",
      "h    h    h    h",
      "h    h    h    h",
      "h    h    h    h",
      "h    h    h    h",
      "ch  hch  hch  hc"
    ],
    [
      "vvvvvvvvvvvvvvvv",
      "aaaaaaaaaaaaaaaa",
      "bbbbbbbbbbbbbbbb",
      "                ",
      "                ",
      "chhhhhhhhhhhhhhc",
      "h    h    h    h",
      "hd  dhd  dhd  dh",
      "chhhhchhhhchhhhc",
      "h    h    h    h",
      "h    h    h    h",
      "h    h    h    h",
      "h    h    h    h",
      "h    h    h    h",
      "h    h    h    h",
      "chjjhchjjhchjjhc"
    ],
    [
      "vvvvvvvvvvvvvvvv",
      "aaaaaaaaaaaaaaaa",
      "bbbbbbbbbbbbbbbb",
      "                ",
      "                ",
      "chhhhhhhhhhhhhhc",
      "h    h    h    h",
      "hd  dhd  dhd  dh",
      "chhhhchhhhchhhhc",
      "h    h    h    h",
      "h    h    h    h",
      "h    h    h    h",
      "h    h    h    h",
      "h    h    h    h",
      "h    h    h    h",
      "chhhhchhhhchhhhc"
    ],
    [
      "vvvvvvvvvvvvvvvv",
      "aaaaaaaaaaaaaaaa",
      "bbbbbbbbbbbbbbbb",
      "kkkkkkkkkkkkkkkk",
      "kkkkkkkkkkkkkkkk",
      "chhhhhhhhhhhhhhc",
      "h    h    h    h",
      "h    h    h    h",
      "chhhhchhhhchhhhc",
      "h    h    h    h",
      "h    h    h    h",
      "h    h    h    h",
      "h    h    h    h",
      "h    h    h    h",
      "h    h    h    h",
      "chhhhchhhhchhhhc"
    ]
  ]
}