{
  "name": "multi_laboratory_5_base6",
  "refpalette": "deceasedcraft:multi_laboratory_5/multi_laboratory_5_base6_palette",
  "xsize": 16,
  "zsize": 16,
  "slices": [
    [
      "vvvvvvvvvvvvvvvv",
      "aaaaaaaaaaaaaaaa",
      "bbbbbbbbbbbbbbbb",
      "                ",
      "                ",
      "cccccccccccccccc",
      "c    c    c    c",
      "cd  dcd   c   dc",
      "cccccccccccccccc",
      "ceeeec    ceeeec",
      "ceeeec    ceeeec",
      "cefeec    ceeeec",
      "ceeeec    ceeeec",
      "cegeec    ceeeec",
      "ceeeeh    ceee c",
      "cccc icccjcccc i"
    ],
    [
      "vvvvvvvvvvvvvvvv",
      "aaaaaaaaaaaaaaaa",
      "bbbbbbbbbbbbbbbb",
      "                ",
      "                ",
      "chhhhhhhhhhhhhhc",
      "h    h    h    h",
      "hd  dhd   h   dh",
      "chhhhchhhhchhhhc",
      "hekkeh    hekkeh",
      "hlg mh    hn  mh",
      "hn gmh    hn  mh",
      "hfgeoh    hn  oh",
      "hn  eh    hn  mh",
      "hepqeh    herqeh",
      "chfshchsshchsshc"
    ],
    [
      "vvvvvvvvvvvvvvvv",
      "aaaaaaaaaaaaaaaa",
      "bbbbbbbbbbbbbbbb",
      "                ",
      "                ",
      "chhhhhhhhhhhhhhc",
      "h    h    h    h",
      "hd  dhd   ht  dh",
      "chhhhchhhhchhhhc",
      "hekgeh    hekkeh",
      "h    h    hn  mh",
      "hn  mh    hn  mh",
      "h  guh    hn  mh",
      "hn  mh    hn  mh",
      "hw xeh    heyxeh",
      "ch  hch  hch  hc"
    ],
    [
      "vvvvvvvvvvvvvvvv",
      "aaaaaaaaaaaaaaaa",
      "bbbbbbbbbbbbbbbb",
      "                ",
      "                ",
      "chhhhhhhhhhhhhhc",
      "h    h    h    h",
      "hd  dhd   ht  dh",
      "chhhhchhhhchhhhc",
      "he Aeh    hekkeh",
      "h   mh    hn  mh",
      "h    h    hn  mh",
      "h   mh    hn  mh",
      "hl  mh    hn  mh",
      "h   eh    hekkeh",
      "cheehcheehcheehc"
    ],
    [
      "vvvvvvvvvvvvvvvv",
      "aaaaaaaaaaaaaaaa",
      "bbbbbbbbbbbbbbbb",
      "                ",
      "                ",
      "chhhhhhhhhhhhhhc",
      "h    h    h    h",
      "hd  dhd  dhd  dh",
      "chhhhchhhhchhhhc",
      "heAkeh    hekkeh",
      "hn Bmh    hn Bmh",
      "h    h    hnB mh",
      "h    h    hn Bmh",
      "h   mh    hnBBmh",
      "h  Aeh    hekkeh",
      "chhhhchhhhchhhhc"
    ],
    [
      "vvvvvvvvvvvvvvvv",
      "aaaaaaaaaaaaaaaa",
      "bbbbbbbbbbbbbbbb",
      "                ",
      "                ",
      "chhhhhhhhhhhhhhc",
      "h    h    h    h",
      "hd  dhd  dhd  dh",
      "chhhhchhhhchhhhc",
      "heeeeh    heeeeh",
      "hekkeh    hekkeh",
      "hC Aeh    hekkeh",
      "hC  eh    hekkeh",
      "h  Aeh    hekkeh",
      "h Ceeh    heeeeh",
      "chhhhchhhhchhhhc"
    ]
  ]
}