{
  "name": "multi_laboratory_5_base2",
  "refpalette": "deceasedcraft:multi_laboratory_5/multi_laboratory_5_base2_palette",
  "xsize": 16,
  "zsize": 16,
  "slices": [
    [
      "vvvvvvvvvvvvvvvv",
      "aaaaaaaaaaaaaaaa",
      "bbbbbbbbbbbbbbbb",
      "                ",
      "                ",
      "cccccccccccccccc",
      "c    c    c    c",
      "cd  dcd  dcd  dc",
      "cccccccccccccccc",
      "c    c    c    c",
      "c    c    c    c",
      "c    c    c    c",
      "c    c    c    c",
      "c    c    c    c",
      "c    c    c    c",
      "cccc cccc ecccfc"
    ],
    [
      "vvvvvvvvvvvvvvvv",
      "aaaaaaaaaaaaaaaa",
      "bbbbbbbbbbbbbbbb",
      "                ",
      "                ",
      "cggggggggggggggc",
      "g    g    g    g",
      "gd  dgd  dgd  dg",
      "cggggcggggcggggc",
      "g    g    g    g",
      "g    g    g    g",
      "g    g    g    g",
      "g    g    g    g",
      "g    g    g    g",
      "g    g    g    g",
      "cghhgcghhgcghhgc"
    ],
    [
      "vvvvvvvvvvvvvvvv",
      "aaaaaaaaaaaaaaaa",
      "bbbbbbbbbbbbbbbb",
      "                ",
      "                ",
      "cggggggggggggggc",
      "g    g    g    g",
      "gd  dgd  dgd  dg",
      "cggggcggggcggggc",
      "g    g    g    g",
      "g    g    g    g",
      "g    g    g    g",
      "g    g    g    g",
      "g    g    g    g",
      "g    g    g    g",
      "cg  gcg  gcg  gc"
    ],
    [
      "vvvvvvvvvvvvvvvv",
      "aaaaaaaaaaaaaaaa",
      "bbbbbbbbbbbbbbbb",
      "                ",
      "                ",
      "cggggggggggggggc",
      "g    g    g    g",
      "gd  dgd  dgd  dg",
      "cggggcggggcggggc",
      "g    g    g    g",
      "g    g    g    g",
      "g    g    g    g",
      "g    g    g    g",
      "g    g    g    g",
      "g    g    g    g",
      "cgiigcgiigcgiigc"
    ],
    [
      "vvvvvvvvvvvvvvvv",
      "aaaaaaaaaaaaaaaa",
      "bbbbbbbbbbbbbbbb",
      "                ",
      "                ",
      "cggggggggggggggc",
      "g    g    g    g",
      "gd  dgd  dgd  dg",
      "cggggcggggcggggc",
      "g    g    g    g",
      "g    g    g    g",
      "g    g    g    g",
      "g    g    g    g",
      "g    g    g    g",
      "g    g    g    g",
      "cggggcggggcggggc"
    ],
    [
      "vvvvvvvvvvvvvvvv",
      "aaaaaaaaaaaaaaaa",
      "bbbbbbbbbbbbbbbb",
      "                ",
      "                ",
      "cggggggggggggggc",
      "g    g    g    g",
      "gd  dgd  dgd  dg",
      "cggggcggggcggggc",
      "g    g    g    g",
      "g    g    g    g",
      "g    g    g    g",
      "g    g    g    g",
      "g    g    g    g",
      "g    g    g    g",
      "cggggcggggcggggc"
    ]
  ]
}