{
  "name": "multi_casino_7_floor13",
  "refpalette": "deceasedcraft:multi_casino_7/multi_casino_7_floor13_palette",
  "xsize": 16,
  "zsize": 16,
  "slices": [
    [
      "             ab ",
      "             ab ",
      "             cb ",
      "    ddddefffffb ",
      "    dgh di    j ",
      "    dkl dim     ",
      "    dn  di      ",
      "    eddddim     ",
      "iiiiiiiiii      ",
      "m m m m m       ",
      "                ",
      "                ",
      "                ",
      "                ",
      "                ",
      "                "
    ],
    [
      "             ab ",
      "             ab ",
      "             cb ",
      "    ddddefffffb ",
      "    d   do      ",
      "    dpq mom     ",
      "    drs do      ",
      "    eddddom     ",
      "oooooooooi      ",
      "m m m m m       ",
      "                ",
      "                ",
      "                ",
      "                ",
      "                ",
      "                "
    ],
    [
      "             ab ",
      "             cb ",
      "        efffffb ",
      "    dddd om     ",
      "    d   eo      ",
      "    d t mom     ",
      "    d undo      ",
      "   e edddom     ",
      "oooooooooi      ",
      "m m m m m       ",
      "                ",
      "                ",
      "                ",
      "                ",
      "                ",
      "                "
    ],
    [
      "             cb ",
      "        efffffb ",
      "         o    j ",
      "    dddd om     ",
      "    d   do      ",
      "    d wxeom     ",
      "    d  udo      ",
      "  e  deddom     ",
      "oooooooooi      ",
      "m m m m m       ",
      "                ",
      "                ",
      "                ",
      "                ",
      "                ",
      "                "
    ],
    [
      "             cb ",
      "        efffffb ",
      "         o      ",
      "    dddd om     ",
      "    d  ndo      ",
      "    d yAeom     ",
      "    d   do      ",
      "  e  deddom     ",
      "oooooooooi      ",
      "m m m m m       ",
      "                ",
      "                ",
      "                ",
      "                ",
      "                ",
      "                "
    ],
    [
      "        efffffb ",
      "         om     ",
      "         o      ",
      "    dddd om     ",
      "    dBCAdo      ",
      "    d D dom     ",
      "    d   eo      ",
      "Be   ddedom     ",
      "oooooooooi      ",
      "m m m m m       ",
      "                ",
      "                ",
      "                ",
      "                ",
      "                ",
      "                "
    ]
  ]
}