{
  "name": "multi_casino_7_floor5",
  "refpalette": "deceasedcraft:multi_casino_7/multi_casino_7_floor5_palette",
  "xsize": 16,
  "zsize": 16,
  "slices": [
    [
      "             ab ",
      "             ac ",
      "             ab ",
      "    dddde    ac ",
      "    dfg d    ab ",
      "    dhi d    ac ",
      "    dj  d    ab ",
      "    eddddkkkkac ",
      "aaaaaaaaaaaaaab ",
      "cbcbcbcbcbcbcbc ",
      "                ",
      "                ",
      "                ",
      "                ",
      "                ",
      "                "
    ],
    [
      "             ab ",
      "             ab ",
      "             ab ",
      "    dddde    ac ",
      "    d   d    ab ",
      "    dlm n    ab ",
      "    dop d    ab ",
      "    eddddkkkkac ",
      "aaaaaaaaaaaaaab ",
      "cbbbcbbbcbbbcbb ",
      "                ",
      "                ",
      "                ",
      "                ",
      "                ",
      "                "
    ],
    [
      "             ab ",
      "             ab ",
      "        e    ab ",
      "    dddd     ac ",
      "    d   e    ab ",
      "    d q n    ab ",
      "    d rjd    ab ",
      "   e edddk kkac ",
      "aaaaaaaaaaaaaab ",
      "cbbbcbbbcbbbcbb ",
      "                ",
      "                ",
      "                ",
      "                ",
      "                ",
      "                "
    ],
    [
      "             ab ",
      "        e    ab ",
      "             ab ",
      "    dddd     ac ",
      "    d   d    ab ",
      "    d ste    ab ",
      "    d  rd    ab ",
      "  e  dedd   kac ",
      "aaaaaaaaaaaaaab ",
      "cbbbcbbbcbbbcbb ",
      "                ",
      "                ",
      "                ",
      "                ",
      "                ",
      "                "
    ],
    [
      "             ab ",
      "        e    ab ",
      "             ab ",
      "    dddd     ac ",
      "    d  jd    ab ",
      "    d uwe    ab ",
      "    d   d    ab ",
      "  e  dedd    ac ",
      "aaaaaaaaaaaaaab ",
      "cbbbcbbbcbbbcbb ",
      "                ",
      "                ",
      "                ",
      "                ",
      "                ",
      "                "
    ],
    [
      "        e    ab ",
      "             ab ",
      "             ab ",
      "    dddd     ac ",
      "    dxywd    ab ",
      "    d A d    ab ",
      "    d   e    ab ",
      "xeBBBddedBBBBac ",
      "aaaaaaaaaaaaaab ",
      "cbbbcbbbcbbbcbb ",
      "                ",
      "                ",
      "                ",
      "                ",
      "                ",
      "                "
    ]
  ]
}