{
  "name": "multi_casino_7_base9",
  "refpalette": "deceasedcraft:multi_casino_7/multi_casino_7_base9_palette",
  "xsize": 16,
  "zsize": 16,
  "slices": [
    [
      "aaaaaaaaaaaaaaaa",
      "aaaaaaaaaaaaaaaa",
      "aaaaaaaaaaaaaaaa",
      "aaaaaaaaaaaaaaaa",
      "aaaaabbbaaaaaaaa",
      "aaaaabbbaaaaaaaa",
      "aaaaabbbaaaaaaaa",
      "aaaaaaaaaaaaaaaa",
      "cccccccccccccccc",
      "cccccccccccccccc",
      "cccccccccccccccc",
      "cccccccccccccccc",
      "cccccccccccccccc",
      "cccccccccccccccc",
      "cccccccccccccccc",
      "vvvvvvvvvvvvvvvv"
    ],
    [
      "  @dddddeddddddd",
      " @dddddddddddddd",
      "@ddddddddddddddd",
      "bbbbdddddddddddd",
      "    f   dddddddd",
      "    dg  dddddddd",
      "hiijdkl!dddddddd",
      "bbbbbdddmddddddd",
      "cccccccccccccccc",
      "cccccccccccccccc",
      "cccccccccccccccc",
      "cccccccccccccccc",
      "cccccccccccccccc",
      "cccccccccccccccc",
      "cccccccccccccccc",
      "vvvvvvvvvvvvvvvv"
    ],
    [
      "  @dddddeddddddd",
      " @dddddddddddddd",
      "@ddddddddddddddd",
      "bbbbdddddddddddd",
      "    n   dddddddd",
      "    d o dddddddd",
      "  pjd qrdddddddd",
      "bbbbbdddmddddddd",
      "cccccccccccccccc",
      "cccccccccccccccc",
      "cccccccccccccccc",
      "cccccccccccccccc",
      "cccccccccccccccc",
      "cccccccccccccccc",
      "cccccccccccccccc",
      "vvvvvvvvvvvvvvvv"
    ],
    [
      "  @dddddeddddddd",
      " @dddddddddddddd",
      "@ddddddddddddddd",
      "bbbbdddddddddddd",
      "    st  dddddddd",
      "    d uwdddddddd",
      "   jd  qdddddddd",
      "bbbbbdddmddddddd",
      "cccccccccccccccc",
      "cccccccccccccccc",
      "cccccccccccccccc",
      "cccccccccccccccc",
      "cccccccccccccccc",
      "cccccccccccccccc",
      "cccccccccccccccc",
      "vvvvvvvvvvvvvvvv"
    ],
    [
      "  @ddddddddddddd",
      " @dddddddddddddd",
      "@ddddddddddddddd",
      "bbbbdddddddddddd",
      "    d  rdddddddd",
      "    d xydddddddd",
      "   jd   dddddddd",
      "bbbbbdddmddddddd",
      "cccccccccccccccc",
      "cccccccccccccccc",
      "cccccccccccccccc",
      "cccccccccccccccc",
      "cccccccccccccccc",
      "cccccccccccccccc",
      "cccccccccccccccc",
      "vvvvvvvvvvvvvvvv"
    ],
    [
      "rmAddddddddddddm",
      "rAmdddddddddddmd",
      "Addmdddddddddmdd",
      "bbbbddddddddmddd",
      "aaaad!Bydddmdddd",
      "aaaad C ddmddddd",
      "aaajd   dmdddddd",
      "bbbbbdddmddddddd",
      "cccccccccccccccc",
      "cccccccccccccccc",
      "cccccccccccccccc",
      "cccccccccccccccc",
      "cccccccccccccccc",
      "cccccccccccccccc",
      "cccccccccccccccc",
      "vvvvvvvvvvvvvvvv"
    ]
  ]
}