{
  "name": "multi_casino_7_floor23",
  "refpalette": "deceasedcraft:multi_casino_7/multi_casino_7_floor23_palette",
  "xsize": 16,
  "zsize": 16,
  "slices": [
    [
      "aaaaaaaaab      ",
      "aaaaaaaaabc     ",
      "aaaaaaaaab      ",
      "deeeddddabc     ",
      "deeedfg db      ",
      "deeedhi dbc     ",
      "deeedj  db      ",
      "keeeedddkbc     ",
      "bbbbbbbbbb      ",
      "c c c c c       ",
      "                ",
      "                ",
      "                ",
      "                ",
      "                ",
      "                "
    ],
    [
      "l   mnnnop      ",
      "l   mqqqopc     ",
      "l rsmtttop      ",
      "du uddddwpc     ",
      "d  xd   dp      ",
      "d  xdyA cpc     ",
      "dB CdDE dp      ",
      "kF  Idddkpc     ",
      "pppppppppb      ",
      "c c c c c       ",
      "                ",
      "                ",
      "                ",
      "                ",
      "                ",
      "                "
    ],
    [
      "        Jp      ",
      "K       Lpc     ",
      "  M      p      ",
      "du uddddNpc     ",
      "d   d   dp      ",
      "d   d O cpc     ",
      "d   d Pjdp      ",
      "k   Jdddkpc     ",
      "pppppppppb      ",
      "c c c c c       ",
      "                ",
      "                ",
      "                ",
      "                ",
      "                ",
      "                "
    ],
    [
      "         p      ",
      "         pc     ",
      "         p      ",
      "duuuddddQpc     ",
      "d  Rd   dp      ",
      "d  Sd TUdpc     ",
      "d   d  Pdp      ",
      "k   Vdddkpc     ",
      "pppppppppb      ",
      "c c c c c       ",
      "                ",
      "                ",
      "                ",
      "                ",
      "                ",
      "                "
    ],
    [
      "         p      ",
      "         pc     ",
      "         p      ",
      "duuudddd pc     ",
      "d   d  jdp      ",
      "d   d WXdpc     ",
      "d   d   dp      ",
      "k    dddkpc     ",
      "pppppppppb      ",
      "c c c c c       ",
      "                ",
      "                ",
      "                ",
      "                ",
      "                ",
      "                "
    ],
    [
      "YYYYYYYYZp      ",
      "YYYYYYYYZpc     ",
      "YYYYYYYYZp      ",
      "0010dddd2pc     ",
      "d333d45Xdp      ",
      "d333d 6 dpc     ",
      "d333d   dp      ",
      "k3337dddkpc     ",
      "pppppppppb      ",
      "c c c c c       ",
      "                ",
      "                ",
      "                ",
      "                ",
      "                ",
      "                "
    ]
  ]
}