{
  "name": "multi_casino_7_floor3",
  "refpalette": "deceasedcraft:multi_casino_7/multi_casino_7_floor3_palette",
  "xsize": 16,
  "zsize": 16,
  "slices": [
    [
      "aaaaaaaaa     b ",
      "aaaaaaaaa     b ",
      "aaaaaaaaa     b ",
      "aaaacaacd     e ",
      "aaaacfg c     b ",
      "aaaachi c     b ",
      "aaaacj  c     b ",
      "ccccdcccccccd e ",
      "              b ",
      "ebbbebbbebbbebb ",
      "                ",
      "                ",
      "                ",
      "                ",
      "                ",
      "                "
    ],
    [
      "k  l    m     b ",
      "c  c    m     b ",
      "ccnc    m     b ",
      "    copcd     e ",
      "    c   c     b ",
      "    cqr s     b ",
      " t ucwx c     b ",
      "ccccdcccccccd e ",
      "              b ",
      "ebbbebbbebbbebb ",
      "                ",
      "                ",
      "                ",
      "                ",
      "                ",
      "                "
    ],
    [
      "y  A          b ",
      "c  c          b ",
      "ccBc          b ",
      "    cCpc      e ",
      "    c   d     b ",
      "    c D s     b ",
      " E Fc Ijc     b ",
      "cccccdcccccd  e ",
      "              b ",
      "ebbbebbbebbbebb ",
      "                ",
      "                ",
      "                ",
      "                ",
      "                ",
      "                "
    ],
    [
      "J  J          b ",
      "c  c          b ",
      "ccKc          b ",
      "    cLLc      e ",
      "    c   c     b ",
      "    c MNd     b ",
      "OPOPc  Ic     b ",
      "ccccccdcccd   e ",
      "              b ",
      "ebbbebbbebbbebb ",
      "                ",
      "                ",
      "                ",
      "                ",
      "                ",
      "                "
    ],
    [
      "c  c          b ",
      "c  c          b ",
      "cccc          b ",
      "    cccc      e ",
      "    c  jc     b ",
      "    c QRd     b ",
      "    c   c     b ",
      "ccccccdcccd   e ",
      "              b ",
      "ebbbebbbebbbebb ",
      "                ",
      "                ",
      "                ",
      "                ",
      "                ",
      "                "
    ],
    [
      "m  m          b ",
      "c  c          e ",
      "cccc          b ",
      "   Scccc      e ",
      "   ScTURc     b ",
      "   Sc V c     e ",
      "   Sc   d     b ",
      "cccccccdcd    e ",
      "              b ",
      "ebebebebebebebe ",
      "                ",
      "                ",
      "                ",
      "                ",
      "                ",
      "                "
    ]
  ]
}