{
  "name": "multi_casino_7_floor18",
  "refpalette": "deceasedcraft:multi_casino_7/multi_casino_7_floor18_palette",
  "xsize": 16,
  "zsize": 16,
  "slices": [
    [
      "aaaaaaaabc      ",
      "aaaaaaaabcd     ",
      "aaaaaaaabc      ",
      "eeeeebbebcd     ",
      "ffffegh ec      ",
      "ffffeij ecd     ",
      "ffffek  ec      ",
      "lffffeeelcd     ",
      "cccccccccc      ",
      "d d d d d       ",
      "                ",
      "                ",
      "                ",
      "                ",
      "                ",
      "                "
    ],
    [
      "m  m     n      ",
      "  m      nd     ",
      "opqrs   tn      ",
      "eeeeeuwexnd     ",
      "yAABe   en      ",
      "   CeDE dnd     ",
      "y  FeIJ en      ",
      "lKL Meeelnd     ",
      "nnnnnnnnnc      ",
      "d d d d d       ",
      "                ",
      "                ",
      "                ",
      "                ",
      "                ",
      "                "
    ],
    [
      "         n      ",
      "         nd     ",
      "op NO    n      ",
      "eeeeePweQnd     ",
      "y   e   en      ",
      "    e R dnd     ",
      "y   e Sken      ",
      "lT  Ueeelnd     ",
      "nnnnnnnnnc      ",
      "d d d d d       ",
      "                ",
      "                ",
      "                ",
      "                ",
      "                ",
      "                "
    ],
    [
      "         n      ",
      "         nd     ",
      "opVWO    n      ",
      "eeeeeXXe nd     ",
      "yYZ e   en      ",
      "y   e 01end     ",
      "y   e  Sen      ",
      "l2  3eeelnd     ",
      "nnnnnnnnnc      ",
      "d d d d d       ",
      "                ",
      "                ",
      "                ",
      "                ",
      "                ",
      "                "
    ],
    [
      "         n      ",
      "         nd     ",
      "44  5    n      ",
      "eeeeeeee nd     ",
      "y   e  ken      ",
      "y   e 67end     ",
      "y   e   en      ",
      "l   8eeelnd     ",
      "nnnnnnnnnc      ",
      "d d d d d       ",
      "                ",
      "                ",
      "                ",
      "                ",
      "                ",
      "                "
    ],
    [
      "99999999#n      ",
      "99999999#nd     ",
      "$$$$9999#n      ",
      "%%^%eeee!nd     ",
      "&&&&e*(7en      ",
      "&&&&e ) end     ",
      "&&&&e   en      ",
      "l&&&+eeelnd     ",
      "nnnnnnnnnc      ",
      "d d d d d       ",
      "                ",
      "                ",
      "                ",
      "                ",
      "                ",
      "                "
    ]
  ]
}