{
  "name": "multi_casino_7_floor20",
  "refpalette": "deceasedcraft:multi_casino_7/multi_casino_7_floor20_palette",
  "xsize": 16,
  "zsize": 16,
  "slices": [
    [
      "aaabcaaade      ",
      "aaaaaaaadef     ",
      "aaaaaaaade      ",
      "gggggddgdef     ",
      "hhhhgij ge      ",
      "hhhhgkl gef     ",
      "hhhhgm  ge      ",
      "nhhhhgggnef     ",
      "eeeeeeeeee      ",
      "f f f f f       ",
      "                ",
      "                ",
      "                ",
      "                ",
      "                ",
      "                "
    ],
    [
      "o   p    q      ",
      " o  o    qf     ",
      "rstuw   xq      ",
      "gggggyAgBqf     ",
      "CDDEg   gq      ",
      "   FgIJ fqf     ",
      "C  KgLM gq      ",
      "nNO Pgggnqf     ",
      "qqqqqqqqqe      ",
      "f f f f f       ",
      "                ",
      "                ",
      "                ",
      "                ",
      "                ",
      "                "
    ],
    [
      "    Q    q      ",
      "         qf     ",
      "rsRST    q      ",
      "gggggUAgVqf     ",
      "C   g   gq      ",
      "    g W fqf     ",
      "C   g Xmgq      ",
      "nY  Zgggnqf     ",
      "qqqqqqqqqe      ",
      "f f f f f       ",
      "                ",
      "                ",
      "                ",
      "                ",
      "                ",
      "                "
    ],
    [
      "    0    q      ",
      "         qf     ",
      "rs12T    q      ",
      "ggggg33g4qf     ",
      "C56 g   gq      ",
      "C   g 78gqf     ",
      "C   g  Xgq      ",
      "n9  #gggnqf     ",
      "qqqqqqqqqe      ",
      "f f f f f       ",
      "                ",
      "                ",
      "                ",
      "                ",
      "                ",
      "                "
    ],
    [
      "    0    q      ",
      "         qf     ",
      "$$  %    q      ",
      "gggggggg qf     ",
      "C   g  mgq      ",
      "C   g ^&gqf     ",
      "C   g   gq      ",
      "n   *gggnqf     ",
      "qqqqqqqqqe      ",
      "f f f f f       ",
      "                ",
      "                ",
      "                ",
      "                ",
      "                ",
      "                "
    ],
    [
      "(((()(((+q      ",
      "((((((((+qf     ",
      "----((((+q      ",
      "[[][gggg{qf     ",
      "}}}}g|;&gq      ",
      "}}}}g : gqf     ",
      "}}}}g   gq      ",
      "n}}}'gggnqf     ",
      "qqqqqqqqqe      ",
      "f f f f f       ",
      "                ",
      "                ",
      "                ",
      "                ",
      "                ",
      "                "
    ]
  ]
}