{
  "name": "multi_casino_7_floor26",
  "refpalette": "deceasedcraft:multi_casino_7/multi_casino_7_floor26_palette",
  "xsize": 16,
  "zsize": 16,
  "slices": [
    [
      "         a      ",
      "         ab     ",
      "         a      ",
      "cccccccc ab     ",
      "ddddcef ca      ",
      "ddddcgh cab     ",
      "ddddci  ca      ",
      "jddddcccjab     ",
      "aaaaaaaaaa      ",
      "b b b b b       ",
      "                ",
      "                ",
      "                ",
      "                ",
      "                ",
      "                "
    ],
    [
      "k        l      ",
      "k        lb     ",
      "k        l      ",
      "cccccccc lb     ",
      "kmmnc   cl      ",
      "   ocpq blb     ",
      "k  rcst cl      ",
      "juw xcccjlb     ",
      "llllllllla      ",
      "b b b b b       ",
      "                ",
      "                ",
      "                ",
      "                ",
      "                ",
      "                "
    ],
    [
      "         l      ",
      "         lb     ",
      "         l      ",
      "cccccccc lb     ",
      "k   c   cl      ",
      "    c y blb     ",
      "k   c Aicl      ",
      "jB  Ccccjlb     ",
      "llllllllla      ",
      "b b b b b       ",
      "                ",
      "                ",
      "                ",
      "                ",
      "                ",
      "                "
    ],
    [
      "         l      ",
      "         lb     ",
      "  DEFI   l      ",
      "cccccccc lb     ",
      "kJK c   cl      ",
      "k   c LMclb     ",
      "k   c  Acl      ",
      "jN  Occcjlb     ",
      "llllllllla      ",
      "b b b b b       ",
      "                ",
      "                ",
      "                ",
      "                ",
      "                ",
      "                "
    ],
    [
      "         l      ",
      "         lb     ",
      "  PQRS   l      ",
      "cccccccc lb     ",
      "k   c  icl      ",
      "k   c TUclb     ",
      "k   c   cl      ",
      "j   Vcccjlb     ",
      "llllllllla      ",
      "b b b b b       ",
      "                ",
      "                ",
      "                ",
      "                ",
      "                ",
      "                "
    ],
    [
      "         l      ",
      "         lb     ",
      "  WXYZ   l      ",
      "cccccccc lb     ",
      "c000c12Ucl      ",
      "c000c 3 clb     ",
      "c000c   cl      ",
      "j0004cccjlb     ",
      "llllllllla      ",
      "b b b b b       ",
      "                ",
      "                ",
      "                ",
      "                ",
      "                ",
      "                "
    ]
  ]
}