{
  "name": "multi_casino_7_base5",
  "refpalette": "deceasedcraft:multi_casino_7/multi_casino_7_base5_palette",
  "xsize": 16,
  "zsize": 16,
  "slices": [
    [
      "                ",
      "                ",
      "                ",
      "aaaabbbb        ",
      "ccccbde b       ",
      "ccccbfg b       ",
      "ccchbi  b       ",
      "jjjjjbbbk       ",
      "                ",
      "                ",
      "                ",
      "l  lml  l  lml  ",
      "nnnnnnnnnnnnnnnn",
      "oooooooooooooooo",
      "oooooooooooooooo",
      "vvvvvvvvvvvvvvvv"
    ],
    [
      "                ",
      "                ",
      "                ",
      "ppppbbbb        ",
      "qr !b   b       ",
      "s  tbuw x       ",
      "   hbyA b       ",
      "jjjjjbbbk       ",
      "                ",
      "                ",
      "                ",
      "   lm      lm   ",
      "nnnnnnnnnnnnnnnn",
      "oooooooooooooooo",
      "oooooooooooooooo",
      "vvvvvvvvvvvvvvvv"
    ],
    [
      "                ",
      "                ",
      "                ",
      "BBppbbbb        ",
      "    b   b       ",
      "    b C x       ",
      "   hb Dib       ",
      "jjjjjbbbkE      ",
      "                ",
      "                ",
      "                ",
      "    m       m   ",
      "nnnnnnnnnnnnnnnn",
      "oooooooooooooooo",
      "oooooooooooooooo",
      "vvvvvvvvvvvvvvvv"
    ],
    [
      "                ",
      "                ",
      "                ",
      "FFppbbbb        ",
      "   Ib   b       ",
      "   Ib JKb       ",
      "   hb  Db       ",
      "jjjjjbbbk       ",
      "                ",
      "                ",
      "                ",
      "    m       m   ",
      "nnnnnnnnnnnnnnnn",
      "oooooooooooooooo",
      "oooooooooooooooo",
      "vvvvvvvvvvvvvvvv"
    ],
    [
      "iLiiiiiiiiiiiiiL",
      "iiLiiiiiiiiiiiLi",
      "iiiLiiiiiiiiiLii",
      "ppppbbbbMiiiLiii",
      "   Nb  ibiiLiiii",
      "    b OPbiLiiiii",
      "   hb   bLiiiiii",
      "fffffbbbkiiiMiii",
      "iiiiiiiLiLiiiiii",
      "iiiiiiLiiiLiiiii",
      "iiiiiLiiiiiLiiii",
      "    m       m   ",
      "nnnnnnnnnnnnnnnn",
      "oooooooooooooooo",
      "oooooooooooooooo",
      "vvvvvvvvvvvvvvvv"
    ],
    [
      "dkdddddddddddddk",
      "ddkdddddddddddkd",
      "dddkdddddddddkdd",
      "ddddbbbbQdddkddd",
      "ddddbRSPbddkdddd",
      "ddddb T bdkddddd",
      "dddhb   bkdddddd",
      "dddddbbbkdddQddd",
      "dddddddkdkdddddd",
      "ddddddkdddkddddd",
      "UUUUdkUUUUUkdUUU",
      "VVVVmVVVVVVVmVVV",
      "nnnnnnnnnnnnnnnn",
      "oooooooooooooooo",
      "oooooooooooooooo",
      "vvvvvvvvvvvvvvvv"
    ]
  ]
}