{
  "name": "multi_casino_7_floor9",
  "refpalette": "deceasedcraft:multi_casino_7/multi_casino_7_floor9_palette",
  "xsize": 16,
  "zsize": 16,
  "slices": [
    [
      "                ",
      "             a  ",
      "                ",
      "    bbbbc    de ",
      "    bfg b    he ",
      "    bij b    ke ",
      "    bl  b    ke ",
      "    cbbbbmmmmke ",
      "nnnndhkkkkkkkke ",
      "o opeeeeeeeeeee ",
      "                ",
      "                ",
      "                ",
      "                ",
      "                ",
      "                "
    ],
    [
      "                ",
      "             a  ",
      "                ",
      "    bbbbc    de ",
      "    b   b    he ",
      "    bqr o    ke ",
      "    bst b    ke ",
      "    cbbbbmmmmke ",
      "uuuudhkkkkkkkke ",
      "o o eeeeeeeeeee ",
      "                ",
      "                ",
      "                ",
      "                ",
      "                ",
      "                "
    ],
    [
      "                ",
      "             a  ",
      "        c       ",
      "    bbbbb    de ",
      "    b   c    he ",
      "    b w o    ke ",
      "    b xlb    ke ",
      "   c cbbbm mmke ",
      "uuuuudhkkkkkkke ",
      "o o oeeeeeeeeee ",
      "                ",
      "                ",
      "                ",
      "                ",
      "                ",
      "                "
    ],
    [
      "                ",
      "        c    a  ",
      "                ",
      "    bbbbb    de ",
      "    b   b    he ",
      "    b yAc    ke ",
      "    b  xb    ke ",
      "  c  bcbb   mke ",
      "uuuuuudhkkkkkke ",
      "o o opeeeeeeeee ",
      "                ",
      "                ",
      "                ",
      "                ",
      "                ",
      "                "
    ],
    [
      "                ",
      "        c    a  ",
      "                ",
      "    bbbbb    de ",
      "    b  lb    he ",
      "    b BCc    ke ",
      "    b   b    ke ",
      "  c  bcbb    ke ",
      "uuuuuudhkkkkkke ",
      "o o o eeeeeeeee ",
      "                ",
      "                ",
      "                ",
      "                ",
      "                ",
      "                "
    ],
    [
      "        c       ",
      "             a  ",
      "             de ",
      "    bbbbb    he ",
      "    bDECb    ke ",
      "    b F b    ke ",
      "    b   c    ke ",
      "Dc   bbcbIIIIke ",
      "uuuuuuudhkkkkke ",
      "o o o oeeeeeeee ",
      "                ",
      "                ",
      "                ",
      "                ",
      "                ",
      "                "
    ]
  ]
}