{
  "name": "multi_casino_7_floor8",
  "refpalette": "deceasedcraft:multi_casino_7/multi_casino_7_floor8_palette",
  "xsize": 16,
  "zsize": 16,
  "slices": [
    [
      "  abbbbbbbbbbcd ",
      "   abbbbbbbbbed ",
      "   abbbbbbbbbfd ",
      "   agbbgbbbbbfd ",
      "   aghi gbbbbfd ",
      "   agjk gbbbbfd ",
      "   agl  gbbbbfd ",
      "    mgggneeeefd ",
      "ceffffffffffffd ",
      "ddddddddddddddd ",
      "                ",
      "                ",
      "                ",
      "                ",
      "                ",
      "                "
    ],
    [
      "   o p q    r   ",
      "   sotp u  wrcd ",
      "    oxyA   BCed ",
      "    gDEgFIC Bfd ",
      "    g   gJ BKfd ",
      "    gaL MNwBBfO ",
      "    gPQ gRRRRfd ",
      "     gggnSSSSfd ",
      "ceffffffffffffd ",
      "ddOdddOdddOdddO ",
      "                ",
      "                ",
      "                ",
      "                ",
      "                ",
      "                "
    ],
    [
      "                ",
      "             T  ",
      "     u       cd ",
      "    gUEgV   Wed ",
      "    g   gX B fd ",
      "    g Y MX  Bfd ",
      "    g Zln    fd ",
      "     ggngVVVVfd ",
      "0cefffffffffffd ",
      "Mdddddddddddddd ",
      "                ",
      "                ",
      "                ",
      "                ",
      "                ",
      "                "
    ],
    [
      "                ",
      "             T  ",
      "             cd ",
      "    g11g2    ed ",
      "    g   g    fd ",
      "    g 34n    fd ",
      "    g  Zg    fd ",
      "     gngg5555fd ",
      "00ceffffffffffd ",
      "M6ddddddddddddd ",
      "                ",
      "                ",
      "                ",
      "                ",
      "                ",
      "                "
    ],
    [
      "                ",
      "             T  ",
      "                ",
      "    gggg     cd ",
      "    g  lg    ed ",
      "    g 78n    fd ",
      "    g   g    fd ",
      "     gngg5555fd ",
      "00ceffffffffffd ",
      "M ddddddddddddd ",
      "                ",
      "                ",
      "                ",
      "                ",
      "                ",
      "                "
    ],
    [
      "                ",
      "             T  ",
      "                ",
      "    gggg     cd ",
      "    g9#8n    ed ",
      "    g $ g    fd ",
      "    g   g    fd ",
      "     nggg5555fO ",
      "000cefffffffffd ",
      "M MdOdddOdddOdd ",
      "                ",
      "                ",
      "                ",
      "                ",
      "                ",
      "                "
    ]
  ]
}