{
  "name": "multi_casino_7_floor7",
  "refpalette": "deceasedcraft:multi_casino_7/multi_casino_7_floor7_palette",
  "xsize": 16,
  "zsize": 16,
  "slices": [
    [
      "             ab ",
      "             ab ",
      "             ab ",
      "    ccccd    ab ",
      "    cef c    ab ",
      "    cgh c    ab ",
      "    ci  c    ab ",
      "    dccccjjjjab ",
      "aaaaaaaaaaaaaab ",
      "bbbbbbbbbbbbbbb ",
      "                ",
      "                ",
      "                ",
      "                ",
      "                ",
      "                "
    ],
    [
      "             ab ",
      "             ab ",
      "             ab ",
      "    ccccd    ak ",
      "    c   c    ab ",
      "    clm n    ab ",
      "    cop c    ab ",
      "    dccccjjjjak ",
      "aaaaaaaaaaaaaab ",
      "kbbbkbbbkbbbkbb ",
      "                ",
      "                ",
      "                ",
      "                ",
      "                ",
      "                "
    ],
    [
      "             ab ",
      "             ab ",
      "             ab ",
      "    cccc     ak ",
      "    c   d    ab ",
      "    c q n    ab ",
      "    c ric    ab ",
      "     dcccjjj ak ",
      "aaaaaaaaaaaaaab ",
      "kbbbkbbbkbbbkbb ",
      "                ",
      "                ",
      "                ",
      "                ",
      "                ",
      "                "
    ],
    [
      "             ab ",
      "             ab ",
      "             ab ",
      "    cccc     ak ",
      "    c   c    ab ",
      "    c std    ab ",
      "    c  rc    ab ",
      "     cdccj j ak ",
      "aaaaaaaaaaaaaab ",
      "kbbbkbbbkbbbkbb ",
      "                ",
      "                ",
      "                ",
      "                ",
      "                ",
      "                "
    ],
    [
      "             ab ",
      "             ab ",
      "             ab ",
      "    cccc     ab ",
      "    c  ic    ab ",
      "    c uwd    ab ",
      "    c   c    ab ",
      "     cdcc    ab ",
      "aaaaaaaaaaaaaab ",
      "bbbbbbbbbbbbbbb ",
      "                ",
      "                ",
      "                ",
      "                ",
      "                ",
      "                "
    ],
    [
      "             xb ",
      "             ab ",
      "             ab ",
      "    cccc     ab ",
      "    cyAwc    ab ",
      "    c B c    ab ",
      "    c   d    ab ",
      "     ccdcCCCCab ",
      "xaaaaaaaaaaaaab ",
      "bbbbbbbbbbbbbbb ",
      "                ",
      "                ",
      "                ",
      "                ",
      "                ",
      "                "
    ]
  ]
}