{
  "name": "multi_casino_7_floor15",
  "refpalette": "deceasedcraft:multi_casino_7/multi_casino_7_floor15_palette",
  "xsize": 16,
  "zsize": 16,
  "slices": [
    [
      "         a      ",
      "         ab     ",
      "         a      ",
      "    ccccdab     ",
      "    cef ca      ",
      "    cgh cab     ",
      "    ci  ca      ",
      "    dccccab     ",
      "aaaaaaaaaa      ",
      "b b b b b       ",
      "                ",
      "                ",
      "                ",
      "                ",
      "                ",
      "                "
    ],
    [
      "         j      ",
      "k        jb     ",
      "         j      ",
      "    ccccdjb     ",
      "    c   cj      ",
      "    clm bjb     ",
      "    cno cj      ",
      "    dccccjb     ",
      "jjjjjjjjja      ",
      "b b b b b       ",
      "                ",
      "                ",
      "                ",
      "                ",
      "                ",
      "                "
    ],
    [
      " p       j      ",
      "q        jb     ",
      "         j      ",
      "    cccc jb     ",
      "    c   dj      ",
      "    c r bjb     ",
      "    c sicj      ",
      "     dcccjb     ",
      "jjjjjjjjja      ",
      "b b b b b       ",
      "                ",
      "                ",
      "                ",
      "                ",
      "                ",
      "                "
    ],
    [
      " t       j      ",
      "q        jb     ",
      "         j      ",
      "    cccc jb     ",
      "    c   cj      ",
      "    c uwdjb     ",
      "    c  scj      ",
      "     cdccjb     ",
      "jjjjjjjjja      ",
      "b b b b b       ",
      "                ",
      "                ",
      "                ",
      "                ",
      "                ",
      "                "
    ],
    [
      " tt      j      ",
      "qt       jb     ",
      "         j      ",
      "    cccc jb     ",
      "    c  icj      ",
      "    c xydjb     ",
      "    c   cj      ",
      "     cdccjb     ",
      "jjjjjjjjja      ",
      "b b b b b       ",
      "                ",
      "                ",
      "                ",
      "                ",
      "                ",
      "                "
    ],
    [
      "AABCDDDDEj      ",
      "BBEDDDDDEjb     ",
      "FFDDDDDDEj      ",
      "DDDDccccEjb     ",
      "DDDDcpIycj      ",
      "DDDDc J cjb     ",
      "DDDDc   dj      ",
      "EEEEEccdcjb     ",
      "jjjjjjjjja      ",
      "b b b b b       ",
      "                ",
      "                ",
      "                ",
      "                ",
      "                ",
      "                "
    ]
  ]
}