{
  "name": "multi_casino_7_base4",
  "refpalette": "deceasedcraft:multi_casino_7/multi_casino_7_base4_palette",
  "xsize": 16,
  "zsize": 16,
  "slices": [
    [
      "aaaaaaaaaaaaaaaa",
      "aaaaaaaaaaaaaaaa",
      "aaaaaaaaaaaaaaaa",
      "bbbbcddcaaaaaaaa",
      "bbbbcef caaaaaaa",
      "bbbbcgh caaaaaaa",
      "bbbbci  caaaaaaa",
      "bbbbbcccjaaaaaaa",
      "bbbbbbbbaaaaaaaa",
      "dddddddddddddddd",
      "bbbbbbbbbbbbbbbb",
      "kkkklkkkkkkklkkk",
      "mmmmmmmmmmmmmmmm",
      "nnnnnnnnnnnnnnnn",
      "nnnnnnnnnnnnnnnn",
      "vvvvvvvvvvvvvvvv"
    ],
    [
      "                ",
      "                ",
      "                ",
      "oooocpqcr  ssss ",
      "    c   c stttts",
      "uwxycAB C stttts",
      " wD cEF c IJttJK",
      "xxxxxcccj  LM L ",
      "N               ",
      "L               ",
      "    O       O   ",
      "PPPPlPPPPPPPlPPP",
      "mmmmmmmmmmmmmmmm",
      "nnnnnnnnnnnnnnnn",
      "nnnnnnnnnnnnnnnn",
      "vvvvvvvvvvvvvvvv"
    ],
    [
      "                ",
      "                ",
      "                ",
      "oooocQqcR       ",
      "    c   c       ",
      "SwxTc U C       ",
      " w  c Vic       ",
      "xxxxxcccj       ",
      "                ",
      "                ",
      "                ",
      "PPPPlPPPPPPPlPPP",
      "mmmmmmmmmmmmmmmm",
      "nnnnnnnnnnnnnnnn",
      "nnnnnnnnnnnnnnnn",
      "vvvvvvvvvvvvvvvv"
    ],
    [
      "                ",
      "                ",
      "                ",
      "oooocWWcX       ",
      "    c   c       ",
      "xwxxc YZc       ",
      " w  c  Vc       ",
      "xxxxxcccj       ",
      "                ",
      "                ",
      "                ",
      "PPPPlPPPPPPPlPPP",
      "mmmmmmmmmmmmmmmm",
      "nnnnnnnnnnnnnnnn",
      "nnnnnnnnnnnnnnnn",
      "vvvvvvvvvvvvvvvv"
    ],
    [
      "                ",
      "                ",
      "                ",
      "oooocccc        ",
      "eeeec  ic       ",
      "eeeec 01c       ",
      "ee!ec   c       ",
      "xxxxxcccj       ",
      "                ",
      "                ",
      "                ",
      "PPPPlPPPPPPPlPPP",
      "mmmmmmmmmmmmmmmm",
      "nnnnnnnnnnnnnnnn",
      "nnnnnnnnnnnnnnnn",
      "vvvvvvvvvvvvvvvv"
    ],
    [
      "                ",
      "                ",
      "                ",
      "oooocccc        ",
      "   2c341c       ",
      "  2 c 5 c       ",
      "6666c   c       ",
      "xxxxxcccj       ",
      "                ",
      "                ",
      "                ",
      "P PPlP PP PPlP P",
      "mmmmmmmmmmmmmmmm",
      "nnnnnnnnnnnnnnnn",
      "nnnnnnnnnnnnnnnn",
      "vvvvvvvvvvvvvvvv"
    ]
  ]
}