{
  "name": "multi_casino_7_floor28",
  "refpalette": "deceasedcraft:multi_casino_7/multi_casino_7_floor28_palette",
  "xsize": 16,
  "zsize": 16,
  "slices": [
    [
      "aaaaaaaaab      ",
      "aaaaaaaaabc     ",
      "daaaaaaaab      ",
      "dedefaafabc     ",
      "eddefgh fb      ",
      "eeeefii fbc     ",
      "eeeef   fb      ",
      "jaaakfffjbc     ",
      "llllllllll      ",
      "c c c c c       ",
      "                ",
      "                ",
      "                ",
      "                ",
      "                ",
      "                "
    ],
    [
      "         b      ",
      "         bc     ",
      "         b      ",
      "    fmnf bc     ",
      "    f   fb      ",
      " oo fpp cbc     ",
      "    f   fb      ",
      "j    fffjbc     ",
      "bbbbbbbbbl      ",
      "c c c c c       ",
      "                ",
      "                ",
      "                ",
      "                ",
      "                ",
      "                "
    ],
    [
      "         b      ",
      "         bc     ",
      "         b      ",
      "    fqnf bc     ",
      "    f   fb      ",
      "    f   cbc     ",
      "    f   fb      ",
      "j    fffjbc     ",
      "bbbbbbbbbl      ",
      "c c c c c       ",
      "                ",
      "                ",
      "                ",
      "                ",
      "                ",
      "                "
    ],
    [
      "        j       ",
      "         bc     ",
      "         b      ",
      "    frrf bc     ",
      "    f   fb      ",
      "    f   fbc     ",
      "    f   fb      ",
      "sj   fffjbc     ",
      "bbbbbbbbbl      ",
      "c c c c c       ",
      "                ",
      "                ",
      "                ",
      "                ",
      "                ",
      "                "
    ],
    [
      "                ",
      "        jcc     ",
      "         b      ",
      "    ffff bc     ",
      "    f   fb      ",
      "    f   fbc     ",
      "    f   fb      ",
      "  j  fffjbc     ",
      "bbbbbbbbbl      ",
      "c c c c c       ",
      "                ",
      "                ",
      "                ",
      "                ",
      "                ",
      "                "
    ],
    [
      "                ",
      "                ",
      "    ttttj       ",
      "   uwwwwxbc     ",
      "   uwyyywb      ",
      "   uwyyywbc     ",
      "   uwyyywb      ",
      "   jxwwwjbc     ",
      "bbbbbbbbbl      ",
      "c c c c c       ",
      "                ",
      "                ",
      "                ",
      "                ",
      "                ",
      "                "
    ]
  ]
}