{
  "name": "multi_casino_7_floor10",
  "refpalette": "deceasedcraft:multi_casino_7/multi_casino_7_floor10_palette",
  "xsize": 16,
  "zsize": 16,
  "slices": [
    [
      "aaaaaaaaaaaaa   ",
      "aaaaaaaaaaaaab  ",
      "aaaaaaaaaaaaacd ",
      "aaaaeaaeaaaaafd ",
      "aaaaegh eaaaaid ",
      "aaaaejk eaaaaid ",
      "aaaael  eaaaaid ",
      "maaaaeeemffffid ",
      "nnnnnnnncfiiiid ",
      "o o o opddddddd ",
      "                ",
      "                ",
      "                ",
      "                ",
      "                ",
      "                "
    ],
    [
      "            q   ",
      "r s         tcd ",
      "uuw        xyfd ",
      "uuwAeBCeD  xyid ",
      "uuw e   e  xyid ",
      "E F eIJ o   Kid ",
      "    eLM essssid ",
      "m   DeeemNNNNid ",
      "OOOOOOOOcfiiiid ",
      "o o o o ddddddd ",
      "                ",
      "                ",
      "                ",
      "                ",
      "                ",
      "                "
    ],
    [
      "        m       ",
      "            tcd ",
      "  P         Qfd ",
      "  R eSCeT    id ",
      "  U e   e    id ",
      "    e V o   Kid ",
      "    e Wlm    id ",
      " m  TeemeTTXTid ",
      "OOOOOOOOOcfiiid ",
      "o o o o odddddd ",
      "                ",
      "                ",
      "                ",
      "                ",
      "                ",
      "                "
    ],
    [
      "             cd ",
      "        m   tfd ",
      "            Yid ",
      "    eZZe0   1id ",
      "    e   e   2id ",
      "    e 34m   Kid ",
      "    e  We    id ",
      "  m 0emeeOO  id ",
      "OOOOOOOOOncfiid ",
      "o o o o opddddd ",
      "                ",
      "                ",
      "                ",
      "                ",
      "                ",
      "                "
    ],
    [
      "             cd ",
      "        m    fd ",
      "             id ",
      "    eeee     id ",
      "    e  le    id ",
      "    e 56m   7id ",
      "    e   e    id ",
      "  m  emeeOO  id ",
      "OOOOOOOOOncfiid ",
      "o o o o o ddddd ",
      "                ",
      "                ",
      "                ",
      "                ",
      "                ",
      "                "
    ],
    [
      "             fd ",
      "             id ",
      "        m    id ",
      "    eeee     id ",
      "    e896m    id ",
      "    e # e    id ",
      "    e   e    id ",
      "   m meeeOOO id ",
      "OOOOOOOOOn cfid ",
      "o o o o o  dddd ",
      "                ",
      "                ",
      "                ",
      "                ",
      "                ",
      "                "
    ]
  ]
}