{
  "name": "multi_casino_7_floor21",
  "refpalette": "deceasedcraft:multi_casino_7/multi_casino_7_floor21_palette",
  "xsize": 16,
  "zsize": 16,
  "slices": [
    [
      "aaaaaaaabc      ",
      "aaaaaaaabcd     ",
      "aaaaaaaabc      ",
      "eeeeebbebcd     ",
      "ffffegh ec      ",
      "ffffeij ecd     ",
      "ffffek  ec      ",
      "lffffeeelcd     ",
      "cccccccccc      ",
      "d d d d d       ",
      "                ",
      "                ",
      "                ",
      "                ",
      "                ",
      "                "
    ],
    [
      "mm m     n      ",
      "         nd     ",
      "opqrs   tn      ",
      "eeeeeuwexnd     ",
      "yAABe   en      ",
      "   CeDE dnd     ",
      "y  FeIJ en      ",
      "lKL Meeelnd     ",
      "nnnnnnnnnc      ",
      "d d d d d       ",
      "                ",
      "                ",
      "                ",
      "                ",
      "                ",
      "                "
    ],
    [
      "         n      ",
      "         nd     ",
      "op  N    n      ",
      "eeeeeOwePnd     ",
      "y   e   en      ",
      "    e Q dnd     ",
      "y   e Rken      ",
      "lS  Teeelnd     ",
      "nnnnnnnnnc      ",
      "d d d d d       ",
      "                ",
      "                ",
      "                ",
      "                ",
      "                ",
      "                "
    ],
    [
      "         n      ",
      "         nd     ",
      "opUVN    n      ",
      "eeeeeWWeXnd     ",
      "yYZ e   en      ",
      "y   e 01end     ",
      "y   e  Ren      ",
      "l2  3eeelnd     ",
      "nnnnnnnnnc      ",
      "d d d d d       ",
      "                ",
      "                ",
      "                ",
      "                ",
      "                ",
      "                "
    ],
    [
      "         n      ",
      "         nd     ",
      "45  6    n      ",
      "eeeeeeee nd     ",
      "y   e  ken      ",
      "y   e 78end     ",
      "y   e   en      ",
      "l   9eeelnd     ",
      "nnnnnnnnnc      ",
      "d d d d d       ",
      "                ",
      "                ",
      "                ",
      "                ",
      "                ",
      "                "
    ],
    [
      "########$n      ",
      "########$nd     ",
      "%%%%####$n      ",
      "^^&^eeee*nd     ",
      "((((e)+8en      ",
      "((((e - end     ",
      "((((e   en      ",
      "l(((!eeelnd     ",
      "nnnnnnnnnc      ",
      "d d d d d       ",
      "                ",
      "                ",
      "                ",
      "                ",
      "                ",
      "                "
    ]
  ]
}