{
  "name": "multi_casino_7_floor11",
  "refpalette": "deceasedcraft:multi_casino_7/multi_casino_7_floor11_palette",
  "xsize": 16,
  "zsize": 16,
  "slices": [
    [
      "             ab ",
      "             cb ",
      "             cb ",
      "    dddde    cb ",
      "    dfg d    cb ",
      "    dhi d    cb ",
      "    dj  d    cb ",
      "    eddddkkkkcb ",
      "llllllllll  mab ",
      "n n n n n  obbb ",
      "                ",
      "                ",
      "                ",
      "                ",
      "                ",
      "                "
    ],
    [
      "             cb ",
      "             cb ",
      "             cb ",
      "    dddde    cb ",
      "    d   d    cb ",
      "    dpq n    cb ",
      "    drs d    cb ",
      "    eddddkkkkcb ",
      "kkkkkkkkkl  mab ",
      "n n n n n   bbb ",
      "                ",
      "                ",
      "                ",
      "                ",
      "                ",
      "                "
    ],
    [
      "             cb ",
      "             cb ",
      "             cb ",
      "    dddd     cb ",
      "    d   e    cb ",
      "    d t n    cb ",
      "    d ujd    cb ",
      "     edddkkkkab ",
      "kkkkkkkkkl   mb ",
      "n n n n n    bb ",
      "                ",
      "                ",
      "                ",
      "                ",
      "                ",
      "                "
    ],
    [
      "             cb ",
      "             cb ",
      "             cb ",
      "    dddd     cb ",
      "    d   d    cb ",
      "    d wxe    cb ",
      "    d  ud    cb ",
      "     deddkkkkab ",
      "kkkkkkkkkl   mb ",
      "n n n n n    ob ",
      "                ",
      "                ",
      "                ",
      "                ",
      "                ",
      "                "
    ],
    [
      "             cb ",
      "             cb ",
      "             cb ",
      "    dddd     cb ",
      "    d  jd    cb ",
      "    d yAe    cb ",
      "    d   d    cb ",
      "     deddkkkkab ",
      "kkkkkkkkkl   mb ",
      "n n n n n     b ",
      "                ",
      "                ",
      "                ",
      "                ",
      "                ",
      "                "
    ],
    [
      "             cb ",
      "             cb ",
      "             cb ",
      "    dddd     cb ",
      "    dBCAd    cb ",
      "    d D d    cb ",
      "    d   e    cb ",
      "     ddedkkkkab ",
      "kkkkkkkkkl   mb ",
      "n n n n n       ",
      "                ",
      "                ",
      "                ",
      "                ",
      "                ",
      "                "
    ]
  ]
}