{
  "name": "multi_casino_7_floor16",
  "refpalette": "deceasedcraft:multi_casino_7/multi_casino_7_floor16_palette",
  "xsize": 16,
  "zsize": 16,
  "slices": [
    [
      "aaaaaaaaab      ",
      "aaaaaaaaabc     ",
      "aaaaaaaaab      ",
      "aaaadaadabc     ",
      "aaaadef db      ",
      "aaaadgh dbc     ",
      "aaaadi  db      ",
      "aaaaadddjbc     ",
      "bbbbbbbbbb      ",
      "c c c c c       ",
      "                ",
      "                ",
      "                ",
      "                ",
      "                ",
      "                "
    ],
    [
      "     kkk l      ",
      "m        lc     ",
      "   n     l      ",
      "  kodpqdrlc     ",
      " k sd   dl      ",
      "  ksdtu clc     ",
      "w kxdyA dl      ",
      "   Brdddjlc     ",
      "lllllllllb      ",
      "c c c c c       ",
      "                ",
      "                ",
      "                ",
      "                ",
      "                ",
      "                "
    ],
    [
      "         l      ",
      "         lc     ",
      "   C     l      ",
      "    dDqdElc     ",
      "   !d   dl      ",
      "   Fd n clc     ",
      "    d Iijl      ",
      "   JEddjdlc     ",
      "lllllllllb      ",
      "c c c c c       ",
      "                ",
      "                ",
      "                ",
      "                ",
      "                ",
      "                "
    ],
    [
      "         l      ",
      "         Kc     ",
      "   L     l      ",
      "   MdNNdOKc     ",
      "   Md   dl      ",
      "   Md LPjKc     ",
      "   Md  Idl      ",
      "   QOdjddlc     ",
      "RlRlRlRllb      ",
      "c c c c c       ",
      "                ",
      "                ",
      "                ",
      "                ",
      "                ",
      "                "
    ],
    [
      "         l      ",
      "         Kc     ",
      "         l      ",
      "    dddd Kc     ",
      "   Sd  idl      ",
      "   Td UVjKc     ",
      "    d   dl      ",
      "     djddlc     ",
      "RlRlRlRllb      ",
      "c c c c c       ",
      "                ",
      "                ",
      "                ",
      "                ",
      "                ",
      "                "
    ],
    [
      "         l      ",
      "         Kc     ",
      "         l      ",
      "    dddd Kc     ",
      "    dWXVjl      ",
      "    d Y dKc     ",
      "    d   dl      ",
      "     jdddlc     ",
      "RlRlRlRllb      ",
      "c c c c c       ",
      "                ",
      "                ",
      "                ",
      "                ",
      "                ",
      "                "
    ]
  ]
}