{
  "name": "multi_casino_7_floor17",
  "refpalette": "deceasedcraft:multi_casino_7/multi_casino_7_floor17_palette",
  "xsize": 16,
  "zsize": 16,
  "slices": [
    [
      "         a      ",
      "         bc     ",
      "         a      ",
      "    ddddebc     ",
      "    dfg da      ",
      "    dhi dbc     ",
      "    dj  da      ",
      "    eddddkc     ",
      "lalalalakk      ",
      "c c c c c       ",
      "                ",
      "                ",
      "                ",
      "                ",
      "                ",
      "                "
    ],
    [
      "    m    a      ",
      "    m    bc     ",
      "    m    a      ",
      "    ddddebc     ",
      "    d   da      ",
      "    dno cbc     ",
      "    dpq da      ",
      "    eddddac     ",
      "lalalalaak      ",
      "c c c c c       ",
      "                ",
      "                ",
      "                ",
      "                ",
      "                ",
      "                "
    ],
    [
      "         a      ",
      "         bc     ",
      "        ea      ",
      "    dddd bc     ",
      "    d   ea      ",
      "    d r cbc     ",
      "    d sjda      ",
      "   e edddac     ",
      "lalalalaak      ",
      "c c c c c       ",
      "                ",
      "                ",
      "                ",
      "                ",
      "                ",
      "                "
    ],
    [
      "         a      ",
      "        etc     ",
      "         a      ",
      "    dddd tc     ",
      "    d   da      ",
      "    d uwetc     ",
      "    d  sda      ",
      "  e  deddac     ",
      "xaxaxaxaak      ",
      "c c c c c       ",
      "                ",
      "                ",
      "                ",
      "                ",
      "                ",
      "                "
    ],
    [
      "         a      ",
      "        eac     ",
      "         a      ",
      "    dddd ac     ",
      "    d  jda      ",
      "    d yAeac     ",
      "    d   da      ",
      "  e  deddac     ",
      "aaaaaaaaak      ",
      "c c c c c       ",
      "                ",
      "                ",
      "                ",
      "                ",
      "                ",
      "                "
    ],
    [
      "BBBBBBBBea      ",
      "BBBBBBBBCac     ",
      "BBBBBBBBCa      ",
      "BBBBddddCac     ",
      "BBBBdDEAda      ",
      "BBBBd F dac     ",
      "BBBBd   ea      ",
      "DeCCCddedac     ",
      "aaaaaaaaak      ",
      "c c c c c       ",
      "                ",
      "                ",
      "                ",
      "                ",
      "                ",
      "                "
    ]
  ]
}