{
  "name": "multi_casino_7_floor12",
  "refpalette": "deceasedcraft:multi_casino_7/multi_casino_7_floor12_palette",
  "xsize": 16,
  "zsize": 16,
  "slices": [
    [
      "  abbbbbbbbbbcd ",
      "   abbbbbbbbbcd ",
      "   abbbbbbbbbcd ",
      "   aebbebbbbbcd ",
      "   aefg ebbbbcd ",
      "   aehi ebbbbcd ",
      "   aej  ebbbbkd ",
      "    leeembbbbnd ",
      "oooooooooo    p ",
      "q q q q q       ",
      "                ",
      "                ",
      "                ",
      "                ",
      "                ",
      "                "
    ],
    [
      "   r      s  cd ",
      "   tr      u cd ",
      "    r       wcd ",
      "    exyeA   Bcd ",
      "    e   e   Ccd ",
      "    eaD q    cd ",
      "    eEF e    kd ",
      "     eeemnnnnnd ",
      "IIIIIIIIIo      ",
      "q q q q q       ",
      "                ",
      "                ",
      "                ",
      "                ",
      "                ",
      "                "
    ],
    [
      "             cd ",
      "             cd ",
      "             cd ",
      "    eJyeK    cd ",
      "    e   e    cd ",
      "    e L q    kd ",
      "    e Mjmnnnnnd ",
      "     eemeIq     ",
      "IIIIIIIIIo      ",
      "q q q q q       ",
      "                ",
      "                ",
      "                ",
      "                ",
      "                ",
      "                "
    ],
    [
      "             cd ",
      "             cd ",
      "             cd ",
      "    eNNeO    cd ",
      "    e   e    kd ",
      "    e PQmnnnnnd ",
      "    e  MeI    p ",
      "     emeeIq     ",
      "IIIIIIIIIo      ",
      "q q q q q       ",
      "                ",
      "                ",
      "                ",
      "                ",
      "                ",
      "                "
    ],
    [
      "             cd ",
      "             cd ",
      "             cd ",
      "    eeee     cd ",
      "    e  je    kd ",
      "    e RSmnnnnnd ",
      "    e   eI      ",
      "     emeeIq     ",
      "IIIIIIIIIo      ",
      "q q q q q       ",
      "                ",
      "                ",
      "                ",
      "                ",
      "                ",
      "                "
    ],
    [
      "             cd ",
      "             cd ",
      "             cd ",
      "    eeee     kd ",
      "    eTUSmnnnnnd ",
      "    e V eIq     ",
      "    e   eI      ",
      "     meeeIq     ",
      "IIIIIIIIIo      ",
      "q q q q q       ",
      "                ",
      "                ",
      "                ",
      "                ",
      "                ",
      "                "
    ]
  ]
}