{
  "name": "multi_casino_7_floor19",
  "refpalette": "deceasedcraft:multi_casino_7/multi_casino_7_floor19_palette",
  "xsize": 16,
  "zsize": 16,
  "slices": [
    [
      "aaaaaaaabc      ",
      "aaaaaaaabcd     ",
      "aaaaaaaabc      ",
      "eeeeebbebcd     ",
      "ffffegh ec      ",
      "ffffeij ecd     ",
      "ffffek  ec      ",
      "lffffeeelcd     ",
      "cccccccccc      ",
      "d d d d d       ",
      "                ",
      "                ",
      "                ",
      "                ",
      "                ",
      "                "
    ],
    [
      "mmm      n      ",
      "         nd     ",
      "opqrs   tn      ",
      "eeeeeuwe!nd     ",
      "xyyAe   en      ",
      "   BeCD dnd     ",
      "x  EeFI en      ",
      "lJK !eeelnd     ",
      "nnnnnnnnnc      ",
      "d d d d d       ",
      "                ",
      "                ",
      "                ",
      "                ",
      "                ",
      "                "
    ],
    [
      "         n      ",
      "         nd     ",
      "op LM    n      ",
      "eeeeeNwe nd     ",
      "x   e   en      ",
      "    e O dnd     ",
      "x   e Pken      ",
      "lQ  Reeelnd     ",
      "nnnnnnnnnc      ",
      "d d d d d       ",
      "                ",
      "                ",
      "                ",
      "                ",
      "                ",
      "                "
    ],
    [
      "         n      ",
      "         nd     ",
      "opSTM    n      ",
      "eeeeeUUe nd     ",
      "xVW e   en      ",
      "x   e XYend     ",
      "x   e  Pen      ",
      "lZ  0eeelnd     ",
      "nnnnnnnnnc      ",
      "d d d d d       ",
      "                ",
      "                ",
      "                ",
      "                ",
      "                ",
      "                "
    ],
    [
      "         n      ",
      "         nd     ",
      " L  1    n      ",
      "eeeeeeee nd     ",
      "x   e  ken      ",
      "x   e 23end     ",
      "x   e   en      ",
      "l   4eeelnd     ",
      "nnnnnnnnnc      ",
      "d d d d d       ",
      "                ",
      "                ",
      "                ",
      "                ",
      "                ",
      "                "
    ],
    [
      "555555556n      ",
      "555555556nd     ",
      "777755556n      ",
      "8898eeee#nd     ",
      "$$$$e%^3en      ",
      "$$$$e & end     ",
      "$$$$e   en      ",
      "l$$$#eeelnd     ",
      "nnnnnnnnnc      ",
      "d d d d d       ",
      "                ",
      "                ",
      "                ",
      "                ",
      "                ",
      "                "
    ]
  ]
}