{
  "name": "multi_casino_7_floor27",
  "refpalette": "deceasedcraft:multi_casino_7/multi_casino_7_floor27_palette",
  "xsize": 16,
  "zsize": 16,
  "slices": [
    [
      "         a      ",
      "         ab     ",
      "  cdef   a      ",
      "gggggggg ab     ",
      "ghhhgij ga      ",
      "ghhhgkl bab     ",
      "ghhhgm  ga      ",
      "nhhhhgggnab     ",
      "oooooooooo      ",
      "b b b b b       ",
      "                ",
      "                ",
      "                ",
      "                ",
      "                ",
      "                "
    ],
    [
      "         a      ",
      "         ab     ",
      "         a      ",
      "gggggggg ab     ",
      "gpqrg   ga      ",
      "gst guw bab     ",
      "g  xgyA ga      ",
      "nB  Cgggnab     ",
      "aaaaaaaaao      ",
      "b b b b b       ",
      "                ",
      "                ",
      "                ",
      "                ",
      "                ",
      "                "
    ],
    [
      "         a      ",
      "         ab     ",
      "         a      ",
      "gggggggg ab     ",
      "gDtEg   ga      ",
      "g F g I gab     ",
      "g   g Jmga      ",
      "nK  Cgggnab     ",
      "aaaaaaaaao      ",
      "b b b b b       ",
      "                ",
      "                ",
      "                ",
      "                ",
      "                ",
      "                "
    ],
    [
      "         a      ",
      "         ab     ",
      "         a      ",
      "gggggggg ab     ",
      "gt  g   ga      ",
      "g   g LMgab     ",
      "g   g  Jga      ",
      "n   Cgggnab     ",
      "aaaaaaaaao      ",
      "b b b b b       ",
      "                ",
      "                ",
      "                ",
      "                ",
      "                ",
      "                "
    ],
    [
      "         a      ",
      "         ab     ",
      "         a      ",
      "gggggggg ab     ",
      "g   g  mga      ",
      "g   g NOgab     ",
      "g   g   ga      ",
      "n   Cgggnab     ",
      "aaaaaaaaao      ",
      "b b b b b       ",
      "                ",
      "                ",
      "                ",
      "                ",
      "                ",
      "                "
    ],
    [
      "PPPPPPPPQa      ",
      "PPPPPPPPQab     ",
      "PPPPPPPPQa      ",
      "RRSRgggg!ab     ",
      "TmmmgUVOga      ",
      "Tmmmg W gab     ",
      "Tmmmg   ga      ",
      "nmmmCgggnab     ",
      "aaaaaaaaao      ",
      "b b b b b       ",
      "                ",
      "                ",
      "                ",
      "                ",
      "                ",
      "                "
    ]
  ]
}