{
  "name": "multi_casino_7_floor1",
  "refpalette": "deceasedcraft:multi_casino_7/multi_casino_7_floor1_palette",
  "xsize": 16,
  "zsize": 16,
  "slices": [
    [
      "                ",
      "                ",
      "                ",
      "    aaaab       ",
      "    acd a       ",
      "    aef a       ",
      "    ag  a       ",
      "haaabaaaaaaab   ",
      "                ",
      "      i   i     ",
      "                ",
      "        j       ",
      "                ",
      "      i   i     ",
      "                ",
      "                "
    ],
    [
      "                ",
      "                ",
      "                ",
      "    aaaab       ",
      "    a   a       ",
      "    akl h       ",
      "    amn a       ",
      "aaaabaaaaaaab   ",
      "        i       ",
      "      i   i     ",
      "       ioi      ",
      "     i pj  i    ",
      "       iqi      ",
      "      i   i     ",
      "        i       ",
      "                "
    ],
    [
      "                ",
      "                ",
      "        b       ",
      "    aaaa        ",
      "    a   b       ",
      "    a r h       ",
      "    a sga       ",
      "aaababaaaaab b  ",
      "                ",
      "        i       ",
      "        i       ",
      "      ii ii     ",
      "        i       ",
      "        i       ",
      "                ",
      "                "
    ],
    [
      "                ",
      "        b       ",
      "                ",
      "    aaaa        ",
      "    a   a       ",
      "    a tub       ",
      "    a  sa       ",
      "aabaaabaaab   b ",
      "                ",
      "                ",
      "                ",
      "                ",
      "                ",
      "                ",
      "                ",
      "                "
    ],
    [
      "                ",
      "        b       ",
      "                ",
      "    aaaa        ",
      "    a  ga       ",
      "    a wxb       ",
      "    a   a       ",
      "aabaaabaaab   b ",
      "                ",
      "                ",
      "                ",
      "                ",
      "                ",
      "                ",
      "                ",
      "                "
    ],
    [
      "        b       ",
      "                ",
      "                ",
      "    aaaa        ",
      "    ayAxa       ",
      "    a B a       ",
      "    a   b       ",
      "abaaaaabab     b",
      "                ",
      "                ",
      "                ",
      "                ",
      "                ",
      "                ",
      "                ",
      "                "
    ]
  ]
}