{
  "name": "multi_casino_7_floor14",
  "refpalette": "deceasedcraft:multi_casino_7/multi_casino_7_floor14_palette",
  "xsize": 16,
  "zsize": 16,
  "slices": [
    [
      "aaaaaaaaab    c ",
      "aaaaaaaaabd     ",
      "aaaaaaaaab      ",
      "aaaaeaaeabd     ",
      "aaaaefg eb      ",
      "aaaaehi ebd     ",
      "aaaaej  eb      ",
      "kaaaaeeekbd     ",
      "bbbbbbbbbb      ",
      "d d d d d       ",
      "                ",
      "                ",
      "                ",
      "                ",
      "                ",
      "                "
    ],
    [
      "lm       n      ",
      "         nd     ",
      "         n      ",
      "  opeqresnd     ",
      "  ote   en      ",
      "  oteuw dnd     ",
      "  oxeyA en      ",
      "k   seeeknd     ",
      "nnnnnnnnnb      ",
      "d d d d d       ",
      "                ",
      "                ",
      "                ",
      "                ",
      "                ",
      "                "
    ],
    [
      "        kn      ",
      "         nd     ",
      "         n      ",
      "   BeCreDnd     ",
      "   Ee   en      ",
      "   Fe I dnd     ",
      "    e Jjkn      ",
      " k  Deekend     ",
      "nnnnnnnnnb      ",
      "d d d d d       ",
      "                ",
      "                ",
      "                ",
      "                ",
      "                ",
      "                "
    ],
    [
      "         n      ",
      "        knd     ",
      "         n      ",
      "    eKKeLnd     ",
      "    e   en      ",
      "    e MNknd     ",
      "    e  Jen      ",
      "  k Lekeend     ",
      "nnnnnnnnnb      ",
      "d d d d d       ",
      "                ",
      "                ",
      "                ",
      "                ",
      "                ",
      "                "
    ],
    [
      "         n      ",
      "        knd     ",
      "         n      ",
      "    eeee nd     ",
      "    e  jen      ",
      "    e Olknd     ",
      "    e   en      ",
      "  k  ekeend     ",
      "nnnnnnnnnb      ",
      "d d d d d       ",
      "                ",
      "                ",
      "                ",
      "                ",
      "                ",
      "                "
    ],
    [
      "         n      ",
      "         nd     ",
      "        kn      ",
      "    eeee nd     ",
      "    ePQlkn      ",
      "    e R end     ",
      "    e   en      ",
      "   k keeend     ",
      "nnnnnnnnnb      ",
      "d d d d d       ",
      "                ",
      "                ",
      "                ",
      "                ",
      "                ",
      "                "
    ]
  ]
}