{
  "name": "multi_casino_7_floor2",
  "refpalette": "deceasedcraft:multi_casino_7/multi_casino_7_floor2_palette",
  "xsize": 16,
  "zsize": 16,
  "slices": [
    [
      "       a a      ",
      "      a   a     ",
      "     a     a    ",
      "    abbb    a   ",
      "   abcd b    a  ",
      "  a bef b     a ",
      " a  bg  b      a",
      "abbbbbbba       ",
      "                ",
      "                ",
      "                ",
      "                ",
      "                ",
      "                ",
      "                ",
      "                "
    ],
    [
      "hhhhhhijijihhhhh",
      "hhhhhijihijihhhh",
      "hhhhijihhhijihhh",
      "hhhijbbbhhhijihh",
      "hhijb   bhhhijih",
      "hijibkl mhhhhiji",
      "ijiibno biiiiiij",
      "abbbbbbbajjjjjjj",
      "pppppppppppppppp",
      "pppppppppppppppp",
      "pppppppppppppppp",
      "                ",
      "                ",
      "                ",
      "                ",
      "                "
    ],
    [
      "        a       ",
      "                ",
      "                ",
      "    bbbb        ",
      "    b   b       ",
      "    b q m       ",
      "    b rga       ",
      "babbbbbaba     a",
      "                ",
      "                ",
      "                ",
      "                ",
      "                ",
      "                ",
      "                ",
      "                "
    ],
    [
      "                ",
      "        a       ",
      "                ",
      "    bbbb        ",
      "    b   b       ",
      "    b sta       ",
      "    b  rb       ",
      "bbabbbabbba   a ",
      "                ",
      "                ",
      "                ",
      "                ",
      "                ",
      "                ",
      "                ",
      "                "
    ],
    [
      "                ",
      "        a       ",
      "                ",
      "    bbbb        ",
      "    b  gb       ",
      "    b uwa       ",
      "    b   b       ",
      "bbabbbabbba   a ",
      "                ",
      "                ",
      "                ",
      "                ",
      "                ",
      "                ",
      "                ",
      "                "
    ],
    [
      "              x ",
      "              x ",
      "        a     x ",
      "    bbbb      x ",
      "    byAwa     x ",
      "    b B b     x ",
      "    b   b     x ",
      "bbbababbbbba ax ",
      "              x ",
      "xxxxxxxxxxxxxxx ",
      "                ",
      "                ",
      "                ",
      "                ",
      "                ",
      "                "
    ]
  ]
}