{
  "name": "multi_casino_7_ground",
  "refpalette": "deceasedcraft:multi_casino_7/multi_casino_7_ground_palette",
  "xsize": 16,
  "zsize": 16,
  "slices": [
    [
      "aaaaaaaaaaaaaaaa",
      "aaaaaaaaaaaaaaaa",
      "aaaaaaaaaaaaaaaa",
      "aaaabccbaaaaaaaa",
      "aaaabdeHbaaaaaaa",
      "aaaabfgHbaaaaaaa",
      "aaaabhHHbaaaaaaa",
      "aaaaabbbiaaaaaaa",
      "aaaaaaaaaaaaaaaa",
      "cccccccccccccccc",
      "jjjjjjjjjjjjjjjj",
      "kkkkkkklmlkkkkkk",
      "HHHHHHHlllHHHHHH",
      "HHHHHHHlllHHHHHH",
      "HHHHHHHHHHHHHHHH",
      "HHHHHHHHHHHHHHHH"
    ],
    [
      "                ",
      "                ",
      "                ",
      "    bnobp       ",
      "   qb   b       ",
      "  r bst u       ",
      "wx  byA b  BCD B",
      "uuuubbbbi       ",
      "                ",
      "                ",
      "EEEEEEEFFFEEEEEE",
      "       IJI      ",
      "  K   LIMINO  K ",
      "  P   QIIIR   P ",
      "                ",
      "                "
    ],
    [
      "                ",
      "                ",
      "                ",
      "    bSobT       ",
      "    b   b       ",
      "  ! b U u       ",
      "    b Vhi       ",
      "uuuubbbibi      ",
      "                ",
      "                ",
      "                ",
      "        J       ",
      "        W       ",
      "                ",
      "                ",
      "                "
    ],
    [
      "                ",
      "                ",
      "                ",
      "    bXXbY       ",
      "    b   b       ",
      "    b Z0i       ",
      "    b  Vb       ",
      "uuubbbibbbi     ",
      "                ",
      "                ",
      "                ",
      "        J       ",
      "                ",
      "                ",
      "                ",
      "                "
    ],
    [
      "                ",
      "                ",
      "                ",
      "    bbbb        ",
      "    b  hb       ",
      "    b 12i       ",
      "    b   b       ",
      "uubbbbibbbi     ",
      "                ",
      "                ",
      "                ",
      "        J       ",
      "                ",
      "                ",
      "                ",
      "                "
    ],
    [
      "                ",
      "                ",
      "                ",
      "    bbbb        ",
      "    b342i       ",
      "    b 5 b       ",
      "    b   b       ",
      "uubbbibbbbbi    ",
      "                ",
      "                ",
      "                ",
      "        J       ",
      "                ",
      "                ",
      "                ",
      "                "
    ]
  ]
}