{
  "name": "multi_casino_7_base8",
  "refpalette": "deceasedcraft:multi_casino_7/multi_casino_7_base8_palette",
  "xsize": 16,
  "zsize": 16,
  "slices": [
    [
      "aaaaaaaaaaaaaaaa",
      "aaaaaaaaaaaaaaaa",
      "aaaaaaaaaaaaaaaa",
      "bbbbcddcaaaaaaaa",
      "bbbbcef caaaaaaa",
      "bbbbcgh caaaaaaa",
      "bbbbci  caaaaaaa",
      "bbbbbcccjaaaaaaa",
      "bbbbbbbbaaaaaaaa",
      "dddddddddddddddd",
      "bbbbbbbbbbbbbbbb",
      "kkkklkkkkkkklkkk",
      "mmmmmmmmmmmmmmmm",
      "nnnnnnnnnnnnnnnn",
      "nnnnnnnnnnnnnnnn",
      "vvvvvvvvvvvvvvvv"
    ],
    [
      "                ",
      "                ",
      "                ",
      "oooocpqcr      s",
      "    c   c       ",
      "tuwtcxy A       ",
      " uB cCD c       ",
      "wwwwwcccj      s",
      "EF              ",
      "                ",
      "    I       I   ",
      "JJJJlJJJJJJJlJJJ",
      "mmmmmmmmmmmmmmmm",
      "nnnnnnnnnnnnnnnn",
      "nnnnnnnnnnnnnnnn",
      "vvvvvvvvvvvvvvvv"
    ],
    [
      "                ",
      "                ",
      "                ",
      "oooocKqcL       ",
      "    c   c       ",
      "MuwMc N A       ",
      " u  c Oic       ",
      "wwwwwcccj       ",
      "                ",
      "                ",
      "                ",
      "JJJJlJJJJJJJlJJJ",
      "mmmmmmmmmmmmmmmm",
      "nnnnnnnnnnnnnnnn",
      "nnnnnnnnnnnnnnnn",
      "vvvvvvvvvvvvvvvv"
    ],
    [
      "                ",
      "                ",
      "                ",
      "oooocPPcQ       ",
      "    c   c       ",
      "wuwwc RSc       ",
      " u  c  Oc       ",
      "wwwwwcccj       ",
      "                ",
      "                ",
      "                ",
      "JJJJlJJJJJJJlJJJ",
      "mmmmmmmmmmmmmmmm",
      "nnnnnnnnnnnnnnnn",
      "nnnnnnnnnnnnnnnn",
      "vvvvvvvvvvvvvvvv"
    ],
    [
      "                ",
      "                ",
      "                ",
      "oooocccc        ",
      "eeeec  ic       ",
      "eeeec TUc       ",
      "eeVec   c       ",
      "wwwwwcccj       ",
      "                ",
      "                ",
      "                ",
      "JJJJlJJJJJJJlJJJ",
      "mmmmmmmmmmmmmmmm",
      "nnnnnnnnnnnnnnnn",
      "nnnnnnnnnnnnnnnn",
      "vvvvvvvvvvvvvvvv"
    ],
    [
      "                ",
      "                ",
      "                ",
      "oooocccc        ",
      "   WcXYUc       ",
      "  W c Z c       ",
      "0000c   c       ",
      "wwwwwcccj       ",
      "                ",
      "                ",
      "                ",
      "J JJlJ JJ JJlJ J",
      "mmmmmmmmmmmmmmmm",
      "nnnnnnnnnnnnnnnn",
      "nnnnnnnnnnnnnnnn",
      "vvvvvvvvvvvvvvvv"
    ]
  ]
}