{
  "name": "multi_casino_7_floor4",
  "refpalette": "deceasedcraft:multi_casino_7/multi_casino_7_floor4_palette",
  "xsize": 16,
  "zsize": 16,
  "slices": [
    [
      "aaaaaaaaaaaaa b ",
      "aaaaaaaaaaaaa c ",
      "aaaaaaaaaaaaa b ",
      "aaaadaadaaaaa b ",
      "aaaadef daaaa b ",
      "aaaadgh daaaa c ",
      "aaaadi  daaaa b ",
      "aaaaadddjaaaa b ",
      "              b ",
      "bbcbbbcbbbcbbbc ",
      "                ",
      "                ",
      "                ",
      "                ",
      "                ",
      "                "
    ],
    [
      "         kl lmb ",
      " n        l omc ",
      "pqr   s     tmb ",
      "rrrudwxdy t Amb ",
      "qpr d   d    mb ",
      " B  dCD E    mc ",
      "    dFI dJJJJmb ",
      "y   !dddjKKKKmb ",
      "mmmmmmmmmmmmmmb ",
      "bbcbbbcbbbcbbbc ",
      "                ",
      "                ",
      "                ",
      "                ",
      "                ",
      "                "
    ],
    [
      "             mb ",
      "            !mc ",
      "             mb ",
      "    dLxdM   Nmb ",
      "    d   d    mb ",
      "    d O E    mc ",
      "    d Pij    mb ",
      "M    ddjdMMMMmb ",
      "mmmmmmmmmmmmmmb ",
      "bbcbbbcbbbcbbbc ",
      "                ",
      "                ",
      "                ",
      "                ",
      "                ",
      "                "
    ],
    [
      "            Qmb ",
      "            Rmc ",
      "            Smb ",
      "    dTTdU   Vmb ",
      "    d   d    mb ",
      "    d WXj    mc ",
      "    d  Pd    mb ",
      "U    djddYYYYmb ",
      "mmmmmmmmmmmmmmb ",
      "bbcbbbcbbbcbbbc ",
      "                ",
      "                ",
      "                ",
      "                ",
      "                ",
      "                "
    ],
    [
      "             mb ",
      "             mc ",
      "             mb ",
      "    dddd     mb ",
      "    d  id    mb ",
      "    d Z0j    mc ",
      "    d   d    mb ",
      "     djddYYYYmb ",
      "mmmmmmmmmmmmmmb ",
      "bbcbbbcbbbcbbbc ",
      "                ",
      "                ",
      "                ",
      "                ",
      "                ",
      "                "
    ],
    [
      "             mb ",
      "             mc ",
      "             mb ",
      "    dddd     mb ",
      "    d120j    mb ",
      "    d 3 d    mc ",
      "    d   d    mb ",
      "     jdddYYYYmb ",
      "mmmmmmmmmmmmmmb ",
      "bbcbbbcbbbcbbbc ",
      "                ",
      "                ",
      "                ",
      "                ",
      "                ",
      "                "
    ]
  ]
}