{
  "name": "multi_casino_7_floor24",
  "refpalette": "deceasedcraft:multi_casino_7/multi_casino_7_floor24_palette",
  "xsize": 16,
  "zsize": 16,
  "slices": [
    [
      "aaaaaaaaab      ",
      "aaaaaaaaabc     ",
      "aaaaaaaaab      ",
      "deeedaadabc     ",
      "deeedfg db      ",
      "deeedhi dbc     ",
      "deeedj  db      ",
      "keeeedddkbc     ",
      "bbbbbbbbbb      ",
      "c c c c c       ",
      "                ",
      "                ",
      "                ",
      "                ",
      "                ",
      "                "
    ],
    [
      "         l      ",
      "         lc     ",
      "  m      l      ",
      "dn ndopdqlc     ",
      "d  rd   dl      ",
      "d  rdst clc     ",
      "du wdxy dl      ",
      "kA  Bdddklc     ",
      "lllllllllb      ",
      "c c c c c       ",
      "                ",
      "                ",
      "                ",
      "                ",
      "                ",
      "                "
    ],
    [
      "         l      ",
      "         lc     ",
      "  C      l      ",
      "dn ndDpdElc     ",
      "d   d   dl      ",
      "d   d F clc     ",
      "d   d Ijdl      ",
      "k   Jdddklc     ",
      "lllllllllb      ",
      "c c c c c       ",
      "                ",
      "                ",
      "                ",
      "                ",
      "                ",
      "                "
    ],
    [
      "         l      ",
      "         lc     ",
      "         l      ",
      "dnnndKKdLlc     ",
      "d  Md   dl      ",
      "d  Nd OPdlc     ",
      "d   d  Idl      ",
      "k   Qdddklc     ",
      "lllllllllb      ",
      "c c c c c       ",
      "                ",
      "                ",
      "                ",
      "                ",
      "                ",
      "                "
    ],
    [
      "         l      ",
      "         lc     ",
      "         l      ",
      "dnnndddd lc     ",
      "d   d  jdl      ",
      "d   d RSdlc     ",
      "d   d   dl      ",
      "k   Tdddklc     ",
      "lllllllllb      ",
      "c c c c c       ",
      "                ",
      "                ",
      "                ",
      "                ",
      "                ",
      "                "
    ],
    [
      "UVVVVVVVUl      ",
      "UVVVVVVVUlc     ",
      "UVVVVVVVUl      ",
      "dWXWddddYlc     ",
      "dZZZd01Sdl      ",
      "dZZZd 2 dlc     ",
      "dZZZd   dl      ",
      "kZZZYdddklc     ",
      "lllllllllb      ",
      "c c c c c       ",
      "                ",
      "                ",
      "                ",
      "                ",
      "                ",
      "                "
    ]
  ]
}