{
  "name": "multi_casino_7_floor6",
  "refpalette": "deceasedcraft:multi_casino_7/multi_casino_7_floor6_palette",
  "xsize": 16,
  "zsize": 16,
  "slices": [
    [
      "aaaaaaaaaaaaabc ",
      "aaaaaaaaaaaaabc ",
      "aaaaaaaaaaaaabc ",
      "aaaadaadaaaaabc ",
      "aaaadef daaaabc ",
      "aaaadgh daaaabc ",
      "aaaadi  daaaabc ",
      "jkkkkdddjkkkkbc ",
      "bbbbbbbbbbbbbbc ",
      "ccccccccccccccc ",
      "                ",
      "                ",
      "                ",
      "                ",
      "                ",
      "                "
    ],
    [
      "  l mnop   qrbc ",
      " sppooppt   ubw ",
      " sppppppx   ybc ",
      "  ABdCDdE m Fbc ",
      "  IJd   dK LMbc ",
      "   JdNO PQ RSbw ",
      "  q dTU dllllbc ",
      "j   EdddjVVVVbc ",
      "bbbbbbbbbbbbbbc ",
      "ccwcccwcccwcccw ",
      "                ",
      "                ",
      "                ",
      "                ",
      "                ",
      "                "
    ],
    [
      "        j   Wbc ",
      "    Xm      ubw ",
      "   Y XZ     0bc ",
      "    d1Dd2   3bc ",
      "    d   d4  Lbc ",
      "   Jd r P5  Sbw ",
      "   Jd 6ij    bc ",
      " j  2ddjd2222bc ",
      "bbbbbbbbbbbbbbc ",
      "ccwcccwcccwcccw ",
      "                ",
      "                ",
      "                ",
      "                ",
      "                ",
      "                "
    ],
    [
      "            7bc ",
      "        j   ubw ",
      "    888     9bc ",
      "    d##d$   9bc ",
      "    d   d   9bc ",
      "   Jd 7%j   Sbw ",
      "    d  6d4   bc ",
      "  j $djdd^^^^bc ",
      "bbbbbbbbbbbbbbc ",
      "ccwcccwcccwcccw ",
      "                ",
      "                ",
      "                ",
      "                ",
      "                ",
      "                "
    ],
    [
      "             bc ",
      "        j   &bw ",
      "     8       bc ",
      "    dddd     bc ",
      "    d  id    bc ",
      "    d *(j    bw ",
      "    d   d    bc ",
      "  j  djdd^^^^bc ",
      "bbbbbbbbbbbbbbc ",
      "ccwcccwcccwcccw ",
      "                ",
      "                ",
      "                ",
      "                ",
      "                ",
      "                "
    ],
    [
      "             bc ",
      "             bc ",
      "        j    bc ",
      "    dddd     bc ",
      "    d)+(j    bc ",
      "    d - d    bc ",
      "    d   d    bc ",
      "   j jddd^^^^bc ",
      "bbbbbbbbbbbbbbc ",
      "ccccccccccccccc ",
      "                ",
      "                ",
      "                ",
      "                ",
      "                ",
      "                "
    ]
  ]
}