{
  "name": "multi_casino_7_floor25",
  "refpalette": "deceasedcraft:multi_casino_7/multi_casino_7_floor25_palette",
  "xsize": 16,
  "zsize": 16,
  "slices": [
    [
      "aaaabbbbac      ",
      "aaaabbbbacd     ",
      "aaaabbbbac      ",
      "efffeeeeacd     ",
      "efffegh ec      ",
      "efffeij ecd     ",
      "efffek  ec      ",
      "lffffeeelcd     ",
      "cccccccccc      ",
      "d d d d d       ",
      "                ",
      "                ",
      "                ",
      "                ",
      "                ",
      "                "
    ],
    [
      "   mnnnnbo      ",
      "   mnnnnbod     ",
      "   mnnnnbo      ",
      "ppppeeeeqod     ",
      "rsste   eo      ",
      "rssteuw dod     ",
      "rsstexy eo      ",
      "lAAAqeeelod     ",
      "oooooooooc      ",
      "d d d d d       ",
      "                ",
      "                ",
      "                ",
      "                ",
      "                ",
      "                "
    ],
    [
      "         o      ",
      "         od     ",
      "         o      ",
      "    eeeeBod     ",
      "C   e   eo      ",
      "D   e E dod     ",
      "F   e Ikeo      ",
      "l J Beeelod     ",
      "oooooooooc      ",
      "d d d d d       ",
      "                ",
      "                ",
      "                ",
      "                ",
      "                ",
      "                "
    ],
    [
      "         o      ",
      "         od     ",
      "         o      ",
      "    eeeeKod     ",
      "   Le   eo      ",
      "   Le MNeod     ",
      "    e  Ieo      ",
      "l   Keeelod     ",
      "oooooooooc      ",
      "d d d d d       ",
      "                ",
      "                ",
      "                ",
      "                ",
      "                ",
      "                "
    ],
    [
      "         o      ",
      "         od     ",
      "         o      ",
      "    eeee od     ",
      "    e  keo      ",
      "    e OPeod     ",
      "    e   eo      ",
      "l    eeelod     ",
      "oooooooooc      ",
      "d d d d d       ",
      "                ",
      "                ",
      "                ",
      "                ",
      "                ",
      "                "
    ],
    [
      "         o      ",
      "         od     ",
      "         o      ",
      "eeeeeeee od     ",
      "QQQQeRSPeo      ",
      "QQQQe T eod     ",
      "QQQQe   eo      ",
      "lQQQ!eeelod     ",
      "oooooooooc      ",
      "d d d d d       ",
      "                ",
      "                ",
      "                ",
      "                ",
      "                ",
      "                "
    ]
  ]
}