{
  "name": "multi_casino_7_base6",
  "refpalette": "deceasedcraft:multi_casino_7/multi_casino_7_base6_palette",
  "xsize": 16,
  "zsize": 16,
  "slices": [
    [
      "aaaaaaaaaaaaaaaa",
      "aaaaaaaaaaaaaaaa",
      "aaaaaaaaaaaaaaaa",
      "bbbbcddcaaaaaaaa",
      "bbbbcef caaaaaaa",
      "bbbbcgh caaaaaaa",
      "bbbbci  caaaaaaa",
      "bbbbbcccjaaaaaaa",
      "bbbbbbbbaaaaaaaa",
      "dddddddddddddddd",
      "bbbbbbbbbbbbbbbb",
      "kkkklkkkkkkklkkk",
      "mmmmmmmmmmmmmmmm",
      "nnnnnnnnnnnnnnnn",
      "nnnnnnnnnnnnnnnn",
      "vvvvvvvvvvvvvvvv"
    ],
    [
      "                ",
      "                ",
      "           opo  ",
      "qqqqcrsct uwxwy ",
      "    c   c px xp ",
      "ABCAcDE F uwxwy ",
      "IBJ cKL c  MpM  ",
      "CCCCCcccj       ",
      "N               ",
      "O               ",
      "    P       P   ",
      "QQQQlQQQQQQQlQQQ",
      "mmmmmmmmmmmmmmmm",
      "nnnnnnnnnnnnnnnn",
      "nnnnnnnnnnnnnnnn",
      "vvvvvvvvvvvvvvvv"
    ],
    [
      "                ",
      "                ",
      "                ",
      "qqqqcRscS  TUT  ",
      "    c   c  VWU  ",
      "XBCXc Y F  TVT  ",
      " B  c Zic       ",
      "CCCCCcccj       ",
      "                ",
      "                ",
      "                ",
      "QQQQlQQQQQQQlQQQ",
      "mmmmmmmmmmmmmmmm",
      "nnnnnnnnnnnnnnnn",
      "nnnnnnnnnnnnnnnn",
      "vvvvvvvvvvvvvvvv"
    ],
    [
      "                ",
      "                ",
      "                ",
      "qqqqc00c1       ",
      "    c   c   2   ",
      "CBCCc 34c       ",
      " B  c  Zc       ",
      "CCCCCcccj       ",
      "                ",
      "                ",
      "                ",
      "QQQQlQQQQQQQlQQQ",
      "mmmmmmmmmmmmmmmm",
      "nnnnnnnnnnnnnnnn",
      "nnnnnnnnnnnnnnnn",
      "vvvvvvvvvvvvvvvv"
    ],
    [
      "                ",
      "                ",
      "                ",
      "qqqqcccc        ",
      "eeeec  ic       ",
      "eeeec 56c       ",
      "ee7ec   c       ",
      "CCCCCcccj       ",
      "                ",
      "                ",
      "                ",
      "QQQQlQQQQQQQlQQQ",
      "mmmmmmmmmmmmmmmm",
      "nnnnnnnnnnnnnnnn",
      "nnnnnnnnnnnnnnnn",
      "vvvvvvvvvvvvvvvv"
    ],
    [
      "                ",
      "                ",
      "                ",
      "qqqqcccc        ",
      "   8c9#6c       ",
      "  8 c $ c       ",
      "%%%%c   c       ",
      "CCCCCcccj       ",
      "                ",
      "                ",
      "                ",
      "Q QQlQ QQ QQlQ Q",
      "mmmmmmmmmmmmmmmm",
      "nnnnnnnnnnnnnnnn",
      "nnnnnnnnnnnnnnnn",
      "vvvvvvvvvvvvvvvv"
    ]
  ]
}