{
  "name": "multi_casino_7_base7",
  "refpalette": "deceasedcraft:multi_casino_7/multi_casino_7_base7_palette",
  "xsize": 16,
  "zsize": 16,
  "slices": [
    [
      "                ",
      "                ",
      "                ",
      "aaaabbbb        ",
      "ccccbde b       ",
      "ccccbfg b       ",
      "ccchbi  b       ",
      "jjjjjbbbk       ",
      "                ",
      "                ",
      "                ",
      "l  lml  l  lml  ",
      "nnnnnnnnnnnnnnnn",
      "oooooooooooooooo",
      "oooooooooooooooo",
      "vvvvvvvvvvvvvvvv"
    ],
    [
      "                ",
      "                ",
      "                ",
      "ppppbbbb        ",
      "qr sb   b       ",
      "t  sbuw x       ",
      "   hbyA b       ",
      "jjjjjbbbk       ",
      "                ",
      "                ",
      "                ",
      "   lm      lm   ",
      "nnnnnnnnnnnnnnnn",
      "oooooooooooooooo",
      "oooooooooooooooo",
      "vvvvvvvvvvvvvvvv"
    ],
    [
      "                ",
      "                ",
      "                ",
      "BBppbbbb        ",
      "   Cb   b       ",
      "    b D x       ",
      "   hb Eib       ",
      "jjjjjbbbkF      ",
      "                ",
      "                ",
      "                ",
      "    m       m   ",
      "nnnnnnnnnnnnnnnn",
      "oooooooooooooooo",
      "oooooooooooooooo",
      "vvvvvvvvvvvvvvvv"
    ],
    [
      "                ",
      "                ",
      "                ",
      "IIppbbbb        ",
      "   Jb   b       ",
      "   Jb KLb       ",
      "   hb  Eb       ",
      "jjjjjbbbk       ",
      "                ",
      "                ",
      "                ",
      "    m       m   ",
      "nnnnnnnnnnnnnnnn",
      "oooooooooooooooo",
      "oooooooooooooooo",
      "vvvvvvvvvvvvvvvv"
    ],
    [
      "iMiiiiiiiiiiiiiM",
      "iiMiiiiiiiiiiiMi",
      "iiiMiiiiiiiiiMii",
      "ppppbbbbNiiiMiii",
      "    b  ibiiMiiii",
      "    b OPbiMiiiii",
      "   hb   bMiiiiii",
      "fffffbbbkiiiNiii",
      "iiiiiiiMiMiiiiii",
      "iiiiiiMiiiMiiiii",
      "iiiiiMiiiiiMiiii",
      "    m       m   ",
      "nnnnnnnnnnnnnnnn",
      "oooooooooooooooo",
      "oooooooooooooooo",
      "vvvvvvvvvvvvvvvv"
    ],
    [
      "dkdddddddddddddk",
      "ddkdddddddddddkd",
      "dddkdddddddddkdd",
      "ddddbbbbQdddkddd",
      "ddddbRSPbddkdddd",
      "ddddb T bdkddddd",
      "dddhb   bkdddddd",
      "dddddbbbkdddQddd",
      "dddddddkdkdddddd",
      "ddddddkdddkddddd",
      "UUUUdkUUUUUkdUUU",
      "VVVVmVVVVVVVmVVV",
      "nnnnnnnnnnnnnnnn",
      "oooooooooooooooo",
      "oooooooooooooooo",
      "vvvvvvvvvvvvvvvv"
    ]
  ]
}