{
  "name": "multi_casino_7_base2",
  "refpalette": "deceasedcraft:multi_casino_7/multi_casino_7_base2_palette",
  "xsize": 16,
  "zsize": 16,
  "slices": [
    [
      "aaaaaaaaaaaaaaaa",
      "aaaaaaaaaaaaaaaa",
      "aaaaaaaaaaaaaaaa",
      "bbbbcddcaaaaaaaa",
      "bbbbcef caaaaaaa",
      "bbbbcgh caaaaaaa",
      "bbbbci  caaaaaaa",
      "bbbbbcccjaaaaaaa",
      "bbbbbbbbaaaaaaaa",
      "dddddddddddddddd",
      "bbbbbbbbbbbbbbbb",
      "kkkklkkkkkkklkkk",
      "mmmmmmmmmmmmmmmm",
      "nnnnnnnnnnnnnnnn",
      "nnnnnnnnnnnnnnnn",
      "vvvvvvvvvvvvvvvv"
    ],
    [
      "                ",
      "                ",
      "          o o o ",
      "ppppcqrcs t t t ",
      "    c   c u u u ",
      "wxywcAB C D D D ",
      " xE cFI c J J J ",
      "yyyyycccj o o o ",
      "K               ",
      "L               ",
      "    M       M   ",
      "NNNNlNNNNNNNlNNN",
      "mmmmmmmmmmmmmmmm",
      "nnnnnnnnnnnnnnnn",
      "nnnnnnnnnnnnnnnn",
      "vvvvvvvvvvvvvvvv"
    ],
    [
      "                ",
      "                ",
      "                ",
      "ppppcOrcP Q Q Q ",
      "    c   c RSRSRS",
      "TxyTc U CVRVRVRV",
      " x  c Wic X X X ",
      "yyyyycccj       ",
      "                ",
      "                ",
      "                ",
      "NNNNlNNNNNNNlNNN",
      "mmmmmmmmmmmmmmmm",
      "nnnnnnnnnnnnnnnn",
      "nnnnnnnnnnnnnnnn",
      "vvvvvvvvvvvvvvvv"
    ],
    [
      "                ",
      "                ",
      "                ",
      "ppppcYYcZ       ",
      "    c   c 0 0 0 ",
      "yxyyc 12c 3 3 3 ",
      " x  c  Wc       ",
      "yyyyycccj       ",
      "                ",
      "                ",
      "                ",
      "NNNNlNNNNNNNlNNN",
      "mmmmmmmmmmmmmmmm",
      "nnnnnnnnnnnnnnnn",
      "nnnnnnnnnnnnnnnn",
      "vvvvvvvvvvvvvvvv"
    ],
    [
      "                ",
      "                ",
      "                ",
      "ppppcccc        ",
      "eeeec  ic 4 4 4 ",
      "eeeec 56c 4 4 4 ",
      "ee7ec   c       ",
      "yyyyycccj       ",
      "                ",
      "                ",
      "                ",
      "NNNNlNNNNNNNlNNN",
      "mmmmmmmmmmmmmmmm",
      "nnnnnnnnnnnnnnnn",
      "nnnnnnnnnnnnnnnn",
      "vvvvvvvvvvvvvvvv"
    ],
    [
      "                ",
      "                ",
      "                ",
      "ppppcccc        ",
      "   8c9#6c       ",
      "  8 c $ c       ",
      "%%%%c   c       ",
      "yyyyycccj       ",
      "                ",
      "                ",
      "                ",
      "N NNlN NN NNlN N",
      "mmmmmmmmmmmmmmmm",
      "nnnnnnnnnnnnnnnn",
      "nnnnnnnnnnnnnnnn",
      "vvvvvvvvvvvvvvvv"
    ]
  ]
}