{
  "name": "multi_casino_7_floor22",
  "refpalette": "deceasedcraft:multi_casino_7/multi_casino_7_floor22_palette",
  "xsize": 16,
  "zsize": 16,
  "slices": [
    [
      "aaaaaaaaab      ",
      "aaaaaaaaabc     ",
      "aaaaaaaaab      ",
      "deeedaadabc     ",
      "deeedfg db      ",
      "deeedhi dbc     ",
      "deeedj  db      ",
      "keeeedddkbc     ",
      "bbbbbbbbbb      ",
      "c c c c c       ",
      "                ",
      "                ",
      "                ",
      "                ",
      "                ",
      "                "
    ],
    [
      "  l     mn      ",
      " o      pnc     ",
      "        qn      ",
      "dr rdstdunc     ",
      "d  wd   dn      ",
      "dx wdyA cnc     ",
      "dB CdDE dn      ",
      "kF  Idddknc     ",
      "nnnnnnnnnb      ",
      "c c c c c       ",
      "                ",
      "                ",
      "                ",
      "                ",
      "                ",
      "                "
    ],
    [
      "         n      ",
      "         nc     ",
      "         n      ",
      "d  rdJtdKnc     ",
      "d   d   dn      ",
      "d   d L cnc     ",
      "d   d Mjdn      ",
      "k   Ndddknc     ",
      "nnnnnnnnnb      ",
      "c c c c c       ",
      "                ",
      "                ",
      "                ",
      "                ",
      "                ",
      "                "
    ],
    [
      "         n      ",
      "         nc     ",
      " O       n      ",
      "d rrdPPd nc     ",
      "d  Qd   dn      ",
      "d  Rd STdnc     ",
      "d   d  Mdn      ",
      "k   Udddknc     ",
      "nnnnnnnnnb      ",
      "c c c c c       ",
      "                ",
      "                ",
      "                ",
      "                ",
      "                ",
      "                "
    ],
    [
      "         n      ",
      "         nc     ",
      "         n      ",
      "drrrdddd nc     ",
      "d   d  jdn      ",
      "d   d VWdnc     ",
      "d   d   dn      ",
      "k   Xdddknc     ",
      "nnnnnnnnnb      ",
      "c c c c c       ",
      "                ",
      "                ",
      "                ",
      "                ",
      "                ",
      "                "
    ],
    [
      "YZZZZZZZYn      ",
      "YZZZZZZZYnc     ",
      "YZZZZZZZYn      ",
      "d010dddd2nc     ",
      "d333d45Wdn      ",
      "d333d 6 dnc     ",
      "d333d   dn      ",
      "k333!dddknc     ",
      "nnnnnnnnnb      ",
      "c c c c c       ",
      "                ",
      "                ",
      "                ",
      "                ",
      "                ",
      "                "
    ]
  ]
}