{
  "name": "multi_casino_13_base8",
  "refpalette": "deceasedcraft:multi_casino_13/multi_casino_13_base8_palette",
  "xsize": 16,
  "zsize": 16,
  "slices": [
    [
      "aaaaaaaaaabcdefv",
      "aaaaaaaaaabcdefv",
      "aaaaaaaaaabcdefv",
      "aaaaaaaaaabcgefv",
      "aaaaaaaaaabcdefv",
      "baaaaaaaaabcdefv",
      "baaaaaaaaabcdefv",
      "haaaaaaahabcdefv",
      "baaaaaaaaabcdefv",
      "baaaaaaaaabcdefv",
      "aaaaaaaaaabcdefv",
      "aaaaaaaaaabcgefv",
      "aaaaaaaaaabcdefv",
      "aaaaaaaaaabcdefv",
      "aaaaaaaaaabcdefv",
      "aaaaaaaaaabcdefv"
    ],
    [
      "        i   jefv",
      "        k   jefv",
      "        l   jefv",
      "    mm n   ogefv",
      "    mm p    jefv",
      "q      p    jefv",
      "q   rsst    jefv",
      "h       h   jefv",
      "q           jefv",
      "q           jefv",
      "            jefv",
      "           ogefv",
      "            jefv",
      "            jefv",
      "    u   u   jefv",
      "u  uwu uwu  jefv"
    ],
    [
      "            jefv",
      "        x   jefv",
      "            jefv",
      "            gefv",
      "            jefv",
      "            jefv",
      "            jefv",
      "        h   jefv",
      "            jefv",
      "            jefv",
      "            jefv",
      "            gefv",
      "            jefv",
      "            jefv",
      "            jefv",
      "    y   y   jefv"
    ],
    [
      "            jefv",
      "            jefv",
      "            jefv",
      "            gefv",
      "            jefv",
      "            jefv",
      "            jefv",
      "        h   jefv",
      "            jefv",
      "            jefv",
      "            jefv",
      "            gefv",
      "            jefv",
      "            jefv",
      "            jefv",
      "            jefv"
    ],
    [
      "            jefv",
      "            jefv",
      "            jefv",
      "            gefv",
      "            jefv",
      "            jefv",
      "            jefv",
      "        h   jefv",
      "            jefv",
      "            jefv",
      "            jefv",
      "            gefv",
      "            jefv",
      "            jefv",
      "            jefv",
      "            jefv"
    ],
    [
      "            jefv",
      "            jefv",
      "            jefv",
      "            gefv",
      "            jefv",
      "            jefv",
      "             efv",
      "        h   jefv",
      "            jefv",
      "             efv",
      "            jefv",
      "            gefv",
      "            jefv",
      "            jefv",
      "             efv",
      "            jefv"
    ]
  ]
}