{
  "name": "multi_casino_13_ground",
  "refpalette": "deceasedcraft:multi_casino_13/multi_casino_13_ground_palette",
  "xsize": 16,
  "zsize": 16,
  "slices": [
    [
      "abbbbbbbabbcdHHH",
      "abbbbbbbabbcdHHH",
      "abbbbbbbabbcdHHH",
      "abbbbbbbabbcdHHH",
      "abbbbbbbabbcdHHH",
      "abbbbbbbabbcdHHH",
      "abbbbbbbabbcdHHH",
      "eaaaaaaafaacdHHH",
      "abbbbbbbabbcdHHH",
      "abbbbbbbabbcdHHH",
      "abbbbbbbabbcdHHH",
      "abbbbbbbabbcdHHH",
      "abbbbbbbabbcdHHH",
      "abbbbbbbabbcdHHH",
      "abbbbbbbabbcdHHH",
      "ccccccccccccdHHH"
    ],
    [
      "          gh    ",
      "          gh    ",
      "          gh    ",
      "          gh    ",
      "          gh    ",
      "          gh    ",
      "          gh    ",
      "     ~~ i gh    ",
      "          gh    ",
      "          gh    ",
      "          gh    ",
      "          gh    ",
      "          gh    ",
      "          gh    ",
      "jgggjgggjggh    ",
      "hhhhhhhhhhhh    "
    ],
    [
      "                ",
      "                ",
      "                ",
      "                ",
      "                ",
      "                ",
      "                ",
      "      ~ k       ",
      "                ",
      "                ",
      "                ",
      "                ",
      "                ",
      "                ",
      "l   l   l       ",
      "                "
    ],
    [
      "                ",
      "                ",
      "                ",
      "                ",
      "                ",
      "                ",
      "                ",
      "      ~ g       ",
      "                ",
      "                ",
      "                ",
      "                ",
      "                ",
      "                ",
      "                ",
      "                "
    ],
    [
      "                ",
      "                ",
      "                ",
      "                ",
      "                ",
      "                ",
      "                ",
      "      ~ m       ",
      "                ",
      "                ",
      "                ",
      "                ",
      "                ",
      "                ",
      "                ",
      "                "
    ],
    [
      "                ",
      "                ",
      "                ",
      "                ",
      "                ",
      "                ",
      "                ",
      "      ~ m       ",
      "                ",
      "                ",
      "                ",
      "                ",
      "                ",
      "                ",
      "                ",
      "                "
    ]
  ]
}