{
  "name": "multi_casino_13_base4",
  "refpalette": "deceasedcraft:multi_casino_13/multi_casino_13_base4_palette",
  "xsize": 16,
  "zsize": 16,
  "slices": [
    [
      "aaaaaaaaaabcdefv",
      "aaaaaaaaaabcdefv",
      "aaaaaaaaaabcdefv",
      "aaaaaaaaaabcgefv",
      "aaaaaaaaaabcdefv",
      "baaaaaaaaabcdefv",
      "baaaaaaaaabcdefv",
      "baaaaaaahabcdefv",
      "baaaaaaaaabcdefv",
      "baaaaaaaaabcdefv",
      "aaaaaaaaaabcdefv",
      "aaaaaaaaaabcgefv",
      "aaaaaaaaaabcdefv",
      "aaaaaaaaaabcdefv",
      "aaaaaaaaaabcdefv",
      "aaaaaaaaaabcdefv"
    ],
    [
      "      i     jefv",
      "      k     jefv",
      "      k     jefv",
      "      l    mgefv",
      "    knopk   jefv",
      "q     i     jefv",
      "q     k     jefv",
      "q      rh   jefv",
      "q           jefv",
      "q    kks    jefv",
      "    kttuw   jefv",
      "    ktttx  mgefv",
      "    kttt    jefv",
      "    kttuw   jefv",
      "     kky    jefv",
      "            jefv"
    ],
    [
      "      A     jefv",
      "            jefv",
      "            jefv",
      "      B     gefv",
      "     C D    jefv",
      "      A     jefv",
      "            jefv",
      "        h   jefv",
      "            jefv",
      "            jefv",
      "            jefv",
      "            gefv",
      "            jefv",
      "            jefv",
      "            jefv",
      "            jefv"
    ],
    [
      "      A     jefv",
      "            jefv",
      "            jefv",
      "      B     gefv",
      "     C D    jefv",
      "      A     jefv",
      "            jefv",
      "        h   jefv",
      "            jefv",
      "            jefv",
      "            jefv",
      "            gefv",
      "            jefv",
      "            jefv",
      "            jefv",
      "            jefv"
    ],
    [
      "      E     jefv",
      "            jefv",
      "            jefv",
      "      F     gefv",
      "     IJK    jefv",
      "      E     jefv",
      "            jefv",
      "        h   jefv",
      "            jefv",
      "            jefv",
      "            jefv",
      "            gefv",
      "            jefv",
      "            jefv",
      "            jefv",
      "            jefv"
    ],
    [
      "      L     jefv",
      "            jefv",
      "            jefv",
      "      M     gefv",
      "     N O    jefv",
      "      P     jefv",
      "             efv",
      "        h   jefv",
      "            jefv",
      "             efv",
      "            jefv",
      "            gefv",
      "            jefv",
      "            jefv",
      "             efv",
      "            jefv"
    ]
  ]
}