{
  "name": "multi_casino_13_base2",
  "refpalette": "deceasedcraft:multi_casino_13/multi_casino_13_base2_palette",
  "xsize": 16,
  "zsize": 16,
  "slices": [
    [
      "aaaaaaaaaabcdefv",
      "aaaaaaaaaabcdefv",
      "aaaaaaaaaabcdefv",
      "aaaaaaaaaabcgefv",
      "aaaaaaaaaabcdefv",
      "baaaaaaaaabcdefv",
      "baaaaaaaaabcdefv",
      "baaaaaaahabcdefv",
      "baaaaaaaaabcdefv",
      "baaaaaaaaabcdefv",
      "aaaaaaaaaabcdefv",
      "aaaaaaaaaabcgefv",
      "aaaaaaaaaabcdefv",
      "aaaaaaaaaabcdefv",
      "aaaaaaaaaabcdefv",
      "aaaaaaaaaabcdefv"
    ],
    [
      " i j   kl   mefv",
      "  nop qrl   mefv",
      "   i    s   mefv",
      "      nop  tgefv",
      "   j        mefv",
      "u  op nop   mefv",
      "u  i        mefv",
      "u      wh   mefv",
      "u           mefv",
      "u  xyABCx   mefv",
      "            mefv",
      "   xyABCx  tgefv",
      "            mefv",
      "   xyABCx   mefv",
      "            mefv",
      "   xyABCx   mefv"
    ],
    [
      "            mefv",
      "            mefv",
      "        D   mefv",
      "            gefv",
      "            mefv",
      "            mefv",
      "            mefv",
      "        h   mefv",
      "     E      mefv",
      "    FIIJ    mefv",
      "     EK     mefv",
      "    FIIJ    gefv",
      "     EK     mefv",
      "    FIIJ    mefv",
      "     EK     mefv",
      "    FIIJ    mefv"
    ],
    [
      "        L   mefv",
      "        M   mefv",
      "        N   mefv",
      "            gefv",
      "            mefv",
      "            mefv",
      "            mefv",
      "        h   mefv",
      "            mefv",
      "     OP     mefv",
      "            mefv",
      "     OP     gefv",
      "            mefv",
      "     OP     mefv",
      "            mefv",
      "     OP     mefv"
    ],
    [
      "            mefv",
      "        Q   mefv",
      "            mefv",
      "            gefv",
      "            mefv",
      "            mefv",
      "            mefv",
      "        h   mefv",
      "            mefv",
      "     RR     mefv",
      "            mefv",
      "     RR     gefv",
      "            mefv",
      "     RR     mefv",
      "            mefv",
      "     RR     mefv"
    ],
    [
      "            mefv",
      "        Q   mefv",
      "            mefv",
      "            gefv",
      "            mefv",
      "            mefv",
      "             efv",
      "        h   mefv",
      "            mefv",
      "             efv",
      "            mefv",
      "            gefv",
      "            mefv",
      "            mefv",
      "             efv",
      "            mefv"
    ]
  ]
}