{
  "name": "multi_casino_13_base3",
  "refpalette": "deceasedcraft:multi_casino_13/multi_casino_13_base3_palette",
  "xsize": 16,
  "zsize": 16,
  "slices": [
    [
      "            abcv",
      "             bcv",
      "            abcv",
      "            dbcv",
      "            abcv",
      "             bcv",
      "             bcv",
      "        e    bcv",
      "            abcv",
      "             bcv",
      "             bcv",
      "            dbcv",
      "            abcv",
      "             bcv",
      "             bcv",
      "            abcv"
    ],
    [
      "             bcv",
      "             bcv",
      "             bcv",
      "            dbcv",
      "             bcv",
      "             bcv",
      "             bcv",
      "        e    bcv",
      "             bcv",
      "             bcv",
      "             bcv",
      "            dbcv",
      "             bcv",
      "             bcv",
      "             bcv",
      "             bcv"
    ],
    [
      "             bcv",
      "             bcv",
      "             bcv",
      "            dbcv",
      "             bcv",
      "             bcv",
      "        f    bcv",
      "       ge    bcv",
      "        h    bcv",
      "             bcv",
      "             bcv",
      "            dbcv",
      "             bcv",
      "             bcv",
      "             bcv",
      "             bcv"
    ],
    [
      "             bcv",
      "             bcv",
      "             bcv",
      "            dbcv",
      "             bcv",
      "             bcv",
      "             bcv",
      "        e    bcv",
      "             bcv",
      "             bcv",
      "             bcv",
      "            dbcv",
      "             bcv",
      "             bcv",
      "             bcv",
      "             bcv"
    ],
    [
      "ijiiiiiiiiii bcv",
      "iijiiiiiiiii bcv",
      "iiijiiiiiiii bcv",
      "iiiikiiikiiidbcv",
      "iiiiijiiiiij bcv",
      " iiiiijiiiji bcv",
      " iiiiiijijii bcv",
      " iiikiiieiii bcv",
      " iiiiiijijii bcv",
      " iiiiijiiiji bcv",
      "iiiiijiiiiij bcv",
      "iiiikiiikiiidbcv",
      "iiijiiiiiiii bcv",
      "iijiiiiiiiii bcv",
      "ijiiiiiiiiii bcv",
      "kiiikiiikiii bcv"
    ],
    [
      "lelllllllllmnbcv",
      "llellllllllmnbcv",
      "lllelllllllmnbcv",
      "llllelllollldbcv",
      "lllllelllllenbcv",
      "plllllelllemnbcv",
      "pllllllelelmnbcv",
      "plllolllellmnbcv",
      "pllllllelelmnbcv",
      "plllllelllemnbcv",
      "lllllelllllenbcv",
      "llllelllollldbcv",
      "lllelllllllmnbcv",
      "llellllllllmnbcv",
      "lelllllllllmnbcv",
      "elllolllollmnbcv"
    ]
  ]
}