{
  "name": "multi_casino_13_base5",
  "refpalette": "deceasedcraft:multi_casino_13/multi_casino_13_base5_palette",
  "xsize": 16,
  "zsize": 16,
  "slices": [
    [
      "            abcv",
      "        d    bcv",
      "            abcv",
      "            ebcv",
      "            abcv",
      "             bcv",
      "             bcv",
      "        f    bcv",
      "            abcv",
      "             bcv",
      "             bcv",
      "            ebcv",
      "            abcv",
      "             bcv",
      "             bcv",
      "            abcv"
    ],
    [
      "             bcv",
      "        d    bcv",
      "             bcv",
      "            ebcv",
      "             bcv",
      "             bcv",
      "             bcv",
      "        f    bcv",
      "             bcv",
      "             bcv",
      "             bcv",
      "            ebcv",
      "             bcv",
      "             bcv",
      "             bcv",
      "             bcv"
    ],
    [
      "             bcv",
      "        g    bcv",
      "             bcv",
      "            ebcv",
      "             bcv",
      "             bcv",
      "        h    bcv",
      "       if    bcv",
      "        j    bcv",
      "             bcv",
      "             bcv",
      "            ebcv",
      "             bcv",
      "             bcv",
      "             bcv",
      "             bcv"
    ],
    [
      "             bcv",
      "        k    bcv",
      "             bcv",
      "            ebcv",
      "             bcv",
      "             bcv",
      "             bcv",
      "        f    bcv",
      "             bcv",
      "             bcv",
      "             bcv",
      "            ebcv",
      "             bcv",
      "             bcv",
      "             bcv",
      "             bcv"
    ],
    [
      "lmllllllllll bcv",
      "llmlllllnlll bcv",
      "lllmllllllll bcv",
      "llllolllolllebcv",
      "lllllmlllllm bcv",
      " lllllmlllml bcv",
      " llllllmlmll bcv",
      " lllolllflll bcv",
      " llllllmlmll bcv",
      " lllllmlllml bcv",
      "lllllmlllllm bcv",
      "llllolllolllebcv",
      "lllmllllllll bcv",
      "llmlllllllll bcv",
      "lmllllllllll bcv",
      "olllolllolll bcv"
    ],
    [
      "pfpppppppppqrbcv",
      "ppfppppppppqrbcv",
      "pppfpppppppqrbcv",
      "ppppfpppspppebcv",
      "pppppfpppppfrbcv",
      "tpppppfpppfqrbcv",
      "tppppppfpfpqrbcv",
      "tpppspppfppqrbcv",
      "tppppppfpfpqrbcv",
      "tpppppfpppfqrbcv",
      "pppppfpppppfrbcv",
      "ppppfpppspppebcv",
      "pppfpppppppqrbcv",
      "ppfppppppppqrbcv",
      "pfpppppppppqrbcv",
      "fpppspppsppqrbcv"
    ]
  ]
}