{
  "name": "multi_casino_13_base6",
  "refpalette": "deceasedcraft:multi_casino_13/multi_casino_13_base6_palette",
  "xsize": 16,
  "zsize": 16,
  "slices": [
    [
      "aaaaaaaaaabcdefv",
      "aaaaaaaaaabcdefv",
      "aaaaaaaaaabcdefv",
      "aaaaaaaaaabcgefv",
      "aaaaaaaaaabcdefv",
      "baaaaaaaaabcdefv",
      "baaaaaaaaabcdefv",
      "baaaaaaahabcdefv",
      "baaaaaaaaabcdefv",
      "baaaaaaaaabcdefv",
      "aaaaaaaaaabcdefv",
      "aaaaaaaaaabcgefv",
      "aaaaaaaaaabcdefv",
      "aaaaaaaaaabcdefv",
      "aaaaaaaaaabcdefv",
      "aaaaaaaaaabcdefv"
    ],
    [
      "   i   jk   lefv",
      "  mno pqk   lefv",
      "   r    s   lefv",
      "      mno  tgefv",
      "    i       lefv",
      "u   n mno   lefv",
      "u   r       lefv",
      "u      wh   lefv",
      "u           lefv",
      "u   xyx     lefv",
      "   ABCBD    lefv",
      "   yC Cy   tgefv",
      "   ABCBD    lefv",
      "    EyE     lefv",
      "            lefv",
      "    xyx     lefv"
    ],
    [
      "            lefv",
      "            lefv",
      "        F   lefv",
      "            gefv",
      "            lefv",
      "    I       lefv",
      "            lefv",
      "        h   lefv",
      "            lefv",
      "            lefv",
      "    JKJ     lefv",
      "    KLM     gefv",
      "    JMJ     lefv",
      "            lefv",
      "            lefv",
      "            lefv"
    ],
    [
      "        N   lefv",
      "        O   lefv",
      "        P   lefv",
      "            gefv",
      "            lefv",
      "            lefv",
      "            lefv",
      "        h   lefv",
      "            lefv",
      "            lefv",
      "            lefv",
      "     Q      gefv",
      "            lefv",
      "            lefv",
      "            lefv",
      "            lefv"
    ],
    [
      "        R   lefv",
      "        S   lefv",
      "            lefv",
      "            gefv",
      "            lefv",
      "            lefv",
      "            lefv",
      "        h   lefv",
      "            lefv",
      "            lefv",
      "            lefv",
      "            gefv",
      "            lefv",
      "            lefv",
      "            lefv",
      "            lefv"
    ],
    [
      "            lefv",
      "        S   lefv",
      "            lefv",
      "            gefv",
      "            lefv",
      "            lefv",
      "             efv",
      "        h   lefv",
      "            lefv",
      "             efv",
      "            lefv",
      "            gefv",
      "            lefv",
      "            lefv",
      "             efv",
      "            lefv"
    ]
  ]
}