{
  "name": "multi_casino_13_base7",
  "refpalette": "deceasedcraft:multi_casino_13/multi_casino_13_base7_palette",
  "xsize": 16,
  "zsize": 16,
  "slices": [
    [
      "            abcv",
      "             bcv",
      "            abcv",
      "            dbcv",
      "            abcv",
      "             bcv",
      "             bcv",
      "        e    bcv",
      "            abcv",
      "             bcv",
      "             bcv",
      "            dbcv",
      "            abcv",
      "             bcv",
      "             bcv",
      "            abcv"
    ],
    [
      "             bcv",
      "             bcv",
      "             bcv",
      "            dbcv",
      "             bcv",
      "             bcv",
      "             bcv",
      "        e    bcv",
      "             bcv",
      "             bcv",
      "             bcv",
      "            dbcv",
      "             bcv",
      "             bcv",
      "             bcv",
      "             bcv"
    ],
    [
      "             bcv",
      "             bcv",
      "             bcv",
      "            dbcv",
      "             bcv",
      "             bcv",
      "             bcv",
      "        e    bcv",
      "             bcv",
      "             bcv",
      "             bcv",
      "            dbcv",
      "             bcv",
      "             bcv",
      "             bcv",
      "             bcv"
    ],
    [
      "             bcv",
      "             bcv",
      "             bcv",
      "            dbcv",
      "             bcv",
      "             bcv",
      "             bcv",
      "        e    bcv",
      "             bcv",
      "             bcv",
      "             bcv",
      "            dbcv",
      "             bcv",
      "             bcv",
      "             bcv",
      "             bcv"
    ],
    [
      "fgffffffffff bcv",
      "ffgfffffffff bcv",
      "fffgffffffff bcv",
      "ffffhfffhfffdbcv",
      "fffffgfffffg bcv",
      " fffffgfffgf bcv",
      " ffffffgfgff bcv",
      " fffhfffefff bcv",
      " ffffffgfgff bcv",
      " fffffgfffgf bcv",
      "fffffgfffffg bcv",
      "ffffhfffhfffdbcv",
      "fffgffffffff bcv",
      "ffgfffffffff bcv",
      "fgffffffffff bcv",
      "hfffhfffhfff bcv"
    ],
    [
      "ieiiiiiiiiijkbcv",
      "iieiiiiiiiijkbcv",
      "iiieiiiiiiijkbcv",
      "iiiieiiiliiidbcv",
      "iiiiieiiiiiekbcv",
      "miiiiieiiiejkbcv",
      "miiiiiieieijkbcv",
      "miiiliiieiijkbcv",
      "miiiiiieieijkbcv",
      "miiiiieiiiejkbcv",
      "iiiiieiiiiiekbcv",
      "iiiieiiiliiidbcv",
      "iiieiiiiiiijkbcv",
      "iieiiiiiiiijkbcv",
      "ieiiiiiiiiijkbcv",
      "eiiiliiiliijkbcv"
    ]
  ]
}