{
  "name": "multi_casino_13_base9",
  "refpalette": "deceasedcraft:multi_casino_13/multi_casino_13_base9_palette",
  "xsize": 16,
  "zsize": 16,
  "slices": [
    [
      "aaaaaaaaabbbbbbv",
      "aaaaaaaaabbbbbbv",
      "aaaaaaaaabbbbbbv",
      "aaaaaaaaabbbbbbv",
      "aaaaaaaaabbbbbbv",
      "aaaaaaaaabbbbbbv",
      "aaaaaaaaabbbbbbv",
      "aaaaaaaaabbbbbbv",
      "aaaaaaaaabbbbbbv",
      "aaaaaaaaabbbbbbv",
      "aaaaaaaaabbbbbbv",
      "aaaaaaaaabbbbbbv",
      "aaaaaaaaabbbbbbv",
      "aaaaaaaaabbbbbbv",
      "aaaaaaaaabbbbbbv",
      "aaaaaaaaabbbbbbv"
    ],
    [
      "cccccccccbbbbbbv",
      "cccccccccbbbbbbv",
      "cccccccccbbbbbbv",
      "dccccccccbbbbbbv",
      "cccccccccbbbbbbv",
      "@ccccccccbbbbbbv",
      "@ccccccccbbbbbbv",
      "@dccccccebbbbbbv",
      "@ccccccccbbbbbbv",
      "@ccccccccbbbbbbv",
      "cccccccccbbbbbbv",
      "dccccccccbbbbbbv",
      "cccccccccbbbbbbv",
      "cccccccccbbbbbbv",
      "cccccccccbbbbbbv",
      "cccccccccbbbbbbv"
    ],
    [
      "cccccccccbbbbbbv",
      "cccccccccbbbbbbv",
      "cccccccccbbbbbbv",
      "dccccccccbbbbbbv",
      "cccccccccbbbbbbv",
      "@ccccccccbbbbbbv",
      "@ccccccccbbbbbbv",
      "@dccccccebbbbbbv",
      "@ccccccccbbbbbbv",
      "@ccccccccbbbbbbv",
      "cccccccccbbbbbbv",
      "dccccccccbbbbbbv",
      "cccccccccbbbbbbv",
      "cccccccccbbbbbbv",
      "cccccccccbbbbbbv",
      "cccccccccbbbbbbv"
    ],
    [
      "cccccccccbbbbbbv",
      "cccccccccbbbbbbv",
      "cccccccccbbbbbbv",
      "dccccccccbbbbbbv",
      "cccccccccbbbbbbv",
      "@ccccccccbbbbbbv",
      "@ccccccccbbbbbbv",
      "@dccccccebbbbbbv",
      "@ccccccccbbbbbbv",
      "@ccccccccbbbbbbv",
      "cccccccccbbbbbbv",
      "dccccccccbbbbbbv",
      "cccccccccbbbbbbv",
      "cccccccccbbbbbbv",
      "cccccccccbbbbbbv",
      "cccccccccbbbbbbv"
    ],
    [
      "cccccccccbbbbbbv",
      "cccccccccbbbbbbv",
      "cccccccccbbbbbbv",
      "cccccccccbbbbbbv",
      "cccccccccbbbbbbv",
      "fccccccccbbbbbbv",
      "fccccccccbbbbbbv",
      "fcccccccebbbbbbv",
      "fccccccccbbbbbbv",
      "fccccccccbbbbbbv",
      "cccccccccbbbbbbv",
      "cccccccccbbbbbbv",
      "cccccccccbbbbbbv",
      "cccccccccbbbbbbv",
      "cccccccccbbbbbbv",
      "cccccccccbbbbbbv"
    ],
    [
      "cecccccccbbbbbbv",
      "cceccccccbbbbbbv",
      "cccecccccbbbbbbv",
      "cccceccccbbbbbbv",
      "cccccecccbbbbbbv",
      "fccccceccbbbbbbv",
      "fccccccecbbbbbbv",
      "fcccccccebbbbbbv",
      "fccccccecbbbbbbv",
      "fccccceccbbbbbbv",
      "cccccecccbbbbbbv",
      "cccceccccbbbbbbv",
      "cccecccccbbbbbbv",
      "cceccccccbbbbbbv",
      "cecccccccbbbbbbv",
      "eccccccccbbbbbbv"
    ]
  ]
}