{
  "name": "multi_campsite1_1_floor1",
  "refpalette": "deceasedcraft:multi_campsite1_1/multi_campsite1_1_floor1_palette",
  "xsize": 16,
  "zsize": 16,
  "slices": [
    [
      "abaaaabbbaaaaaaa",
      "aaacaaabbbaaaaaa",
      "aaaaabaabbaaddda",
      "aaaaaaaababbbbba",
      "aaaaaaaabbabbbba",
      "caaaaaabbbaaddda",
      "cccaaaaabaaaaaaa",
      "ccaaaaababaaaaaa",
      "caaaaaaabbaaaaaa",
      "aaaaaababbaaaaaa",
      "aaaaaaadbbdaaaaa",
      "aaaaaaadbbdaaaaa",
      "aaaaaaadbbdaaaaa",
      "caaaaaaaaaaaaaaa",
      "aaaaaaaaaaaaaaaa",
      "aaaaaaaaaaaaaaaa"
    ],
    [
      "cccccccccccccccc",
      "cccccecccccccccc",
      "ccccccccccccfffc",
      "ccccccgcccchiijc",
      "ccccccccccckiijc",
      "ccccccccccccfffc",
      "cccccccccccccccc",
      "cccccccccccccccc",
      "ccccgccccccccccc",
      "cccccccclmcccccc",
      "cncccccoppoccccc",
      "cccccccopqoccccc",
      "cccccccorroccccc",
      "ccgccgccccccccgc",
      "ccccccnccccccccc",
      "ccccccccccsccccc"
    ],
    [
      "cccccccccccccccc",
      "cccccccccccccccc",
      "cccccccccccctttc",
      "cccccccccccuccjc",
      "cccccccccccvccjc",
      "ccccccccccccwwwc",
      "cccccccccccccccc",
      "cccccccccccccccc",
      "cccccccccccccccc",
      "ccccccccxycccccc",
      "czcccccAccBccccc",
      "cccccccAccBccccc",
      "cccccccArrBccccc",
      "cccccccccccccccc",
      "cccccczccccccccc",
      "cccccccccccccccc"
    ],
    [
      "cccccccccccccccc",
      "cccccccccccccccc",
      "cccccccccccccccc",
      "cccccccccccctttc",
      "ccccccccccccwwwc",
      "cccccccccccccccc",
      "cccccccccccccccc",
      "cccccccccccccccc",
      "cccccccccccccccc",
      "cccccccccccccccc",
      "ccccccccABcccccc",
      "ccccccccABcccccc",
      "ccccccccABcccccc",
      "cccccccccccccccc",
      "cccccccccccccccc",
      "cccccccccccccccc"
    ],
    [
      "cccccccccccccccc",
      "cccccccccccccccc",
      "cccccccccccccccc",
      "cccccccccccccccc",
      "cccccccccccccccc",
      "cccccccccccccccc",
      "cccccccccccccccc",
      "cccccccccccccccc",
      "cccccccccccccccc",
      "cccccccccccccccc",
      "cccccccccccccccc",
      "cccccccccccccccc",
      "cccccccccccccccc",
      "cccccccccccccccc",
      "cccccccccccccccc",
      "cccccccccccccccc"
    ],
    [
      "cccccccccccccccc",
      "cccccccccccccccc",
      "cccccccccccccccc",
      "cccccccccccccccc",
      "cccccccccccccccc",
      "cccccccccccccccc",
      "cccccccccccccccc",
      "cccccccccccccccc",
      "cccccccccccccccc",
      "cccccccccccccccc",
      "cccccccccccccccc",
      "cccccccccccccccc",
      "cccccccccccccccc",
      "cccccccccccccccc",
      "cccccccccccccccc",
      "cccccccccccccccc"
    ]
  ]
}