{
  "name": "multi_alienresearch_10_base9",
  "refpalette": "deceasedcraft:multi_alienresearch_10/multi_alienresearch_10_base9_palette",
  "xsize": 16,
  "zsize": 16,
  "slices": [
    [
      "abbbbbbbbbbbbbbb",
      "bbbbbbbbbbbbbbbb",
      "bbbbbbbbbbbbbbbb",
      "bbbbbbbbbbbbbbbb",
      "bbbbbbbbbbbbbbbb",
      "bbbbbbbbbbbbbbbb",
      "bbbbbbbbbbbbbbbb",
      "bbbbbbbbbbbbbbbb",
      "bbbbbbbbbbbbbbbb",
      "bbbbbbbbbbbbbbbb",
      "bbbbbbbbbbbbbbbb",
      "bbbbbbbbbbbbbbbb",
      "bbbbbbbbbbbbbbbb",
      "bbbbbbbbbbbbbbbb",
      "bbbbbbbbbbbbbbbb",
      "bbbbbbbbbbbbbbbb"
    ],
    [
      "caddbbbbbbbbbbbb",
      "aaabbbbbbbbbbbbb",
      "dabbbbbbbbbbbbbb",
      "dbbbbbbbbbbbbbbb",
      "bbbbbbbbbbbbbbbb",
      "bbbbbbbbbbbbbbbb",
      "bbbbbbbbbbbbbbbb",
      "bbbbbbbbbbbbbbbb",
      "bbbbbbbbbbbbbbbb",
      "bbbbbbbbbbbbbbbb",
      "bbbbbbbbbbbbbbbb",
      "bbbbbbbbbbbbbbbb",
      "bbbbbbbbbbbbbbbb",
      "bbbbbbbbbbbbbbbb",
      "bbbbbbbbbbbbbbbb",
      "bbbbbbbbbbbbbbbb"
    ],
    [
      "    ddbbbbbbbbbb",
      " c ddbbbbbbbbbbb",
      "  aadbbbbbbbbbbb",
      " daabbbbbbbbbbbb",
      "dddbbbbbbbbbbbbb",
      "dbbbbbbbbbbbbbbb",
      "bbbbbbbbbbbbbbbb",
      "bbbbbbbbbbbbbbbb",
      "bbbbbbbbbbbbbbbb",
      "bbbbbbbbbbbbbbbb",
      "bbbbbbbbbbbbbbbb",
      "bbbbbbbbbbbbbbbb",
      "bbbbbbbbbbbbbbbb",
      "bbbbbbbbbbbbbbbb",
      "bbbbbbbbbbbbbbbb",
      "bbbbbbbbbbbbbbbb"
    ],
    [
      "      ddbbbbbbbb",
      "     ddbbbbbbbbb",
      "  c  ddbbbbbbbbb",
      "   cadbbbbbbbbbb",
      "   aabbbbbbbbbbb",
      " dddbbbbbbbbbbbb",
      "dddbbbbbbbbbbbbb",
      "dbbbbbbbbbbbbbbb",
      "bbbbbbbbbbbbbbbb",
      "bbbbbbbbbbbbbbbb",
      "bbbbbbbbbbbbbbbb",
      "bbbbbbbbbbbbbbbb",
      "bbbbbbbbbbbbbbbb",
      "bbbbbbbbbbbbbbbb",
      "bbbbbbbbbbbbbbbb",
      "bbbbbbbbbbbbbbbb"
    ],
    [
      "        dbbbbbbb",
      " e     ddbbbbbbb",
      "  c    dbbbbbbbb",
      "   f  ddbbbbbbbb",
      "    cadbbbbbbbbb",
      "    aabbbbbbbbbb",
      "   ddbbbbbbbbbbb",
      " dddbbbbbbbbbbbb",
      "ddbbbbbbbbbbbbbb",
      "bbbbbbbbbbbbbbbb",
      "bbbbbbbbbbbbbbbb",
      "bbbbbbbbbbbbbbbb",
      "bbbbbbbbbbbbbbbb",
      "bbbbbbbbbbbbbbbb",
      "bbbbbbbbbbbbbbbb",
      "bbbbbbbbbbbbbbbb"
    ],
    [
      "c c      dbbbbbb",
      " c       dbbbbbb",
      "c f     dbbbbbbb",
      "        dbbbbbbb",
      "       dbbbbbbbb",
      "     cabbbbbbbbb",
      "     abbbbbbbbbb",
      "    dbbbbbbbbbbb",
      "  ddbbbbbbbbbbbb",
      "ddbbbbbbbbbbbbbb",
      "bbbbbbbbbbbbbbbb",
      "bbbbbbbbbbbbbbbb",
      "bbbbbbbbbbbbbbbb",
      "bbbbbbbbbbbbbbbb",
      "bbbbbbbbbbbbbbbb",
      "bbbbbbbbbbbbbbbb"
    ]
  ]
}