{
  "name": "multi_alienresearch_10_base6",
  "refpalette": "deceasedcraft:multi_alienresearch_10/multi_alienresearch_10_base6_palette",
  "xsize": 16,
  "zsize": 16,
  "slices": [
    [
      "  a             ",
      " a              ",
      "a               ",
      "                ",
      "               a",
      "               a",
      "              ab",
      "              ab",
      "             abb",
      "            abbc",
      "           abbcc",
      "          adbccc",
      "         abbbccc",
      "        abbccccc",
      "      aabbcccccc",
      "    aabbbccccccc"
    ],
    [
      "                ",
      "                ",
      "                ",
      "                ",
      "                ",
      "                ",
      "                ",
      "               e",
      "               e",
      "              e ",
      "             e  ",
      "            e   ",
      "           ee   ",
      "          e    f",
      "         e     g",
      "       ee    hij"
    ],
    [
      "kl              ",
      "l               ",
      "                ",
      "                ",
      "                ",
      "                ",
      "                ",
      "               m",
      "               m",
      "              m ",
      "             m  ",
      "            m   ",
      "           mm   ",
      "          m     ",
      "         m     n",
      "       mm       "
    ],
    [
      " opq            ",
      "opppk           ",
      "pp l            ",
      "qpl             ",
      " k              ",
      "                ",
      "                ",
      "               m",
      "               m",
      "              m ",
      "             m  ",
      "            m   ",
      "           mm   ",
      "          m     ",
      "         m      ",
      "       mm       "
    ],
    [
      "   q  ql        ",
      "    qqr         ",
      "  soplk         ",
      "q oppl          ",
      " qppl           ",
      " qll            ",
      "qtk             ",
      "l              m",
      "               m",
      "              m ",
      "             m  ",
      "            m   ",
      "           mm   ",
      "          m     ",
      "         m      ",
      "       mm       "
    ],
    [
      "   @uu@opw      ",
      "    @@uxw       ",
      "     ooyw       ",
      "@    opw        ",
      "u@  pplw        ",
      "u@ooplw         ",
      "@uoplw          ",
      "oxyww          m",
      "pww            m",
      "w             m ",
      "             m  ",
      "            m   ",
      "           mm   ",
      "          m     ",
      "         m      ",
      "       mm       "
    ]
  ]
}