{
  "name": "multi_alienresearch_10_base7",
  "refpalette": "deceasedcraft:multi_alienresearch_10/multi_alienresearch_10_base7_palette",
  "xsize": 16,
  "zsize": 16,
  "slices": [
    [
      "              ab",
      "              ab",
      "              ab",
      "             abc",
      "             abc",
      "            abcc",
      "           abccc",
      "           abccc",
      "        d abcccc",
      "         aeccccc",
      "        aecccccc",
      "      aabccfffff",
      "     abbcccfghhh",
      "   aabcccccfhhhh",
      "aaabbccccccfhhhh",
      "bbbccccccccfhhhh"
    ],
    [
      "                ",
      "               b",
      "               b",
      "               b",
      "              bc",
      "              bc",
      "             bcc",
      "       a    bccc",
      "        i   bccc",
      "         ajbcccc",
      "         jkccccc",
      "         bcfffff",
      "       bbccfg  l",
      "      bccccf fmf",
      "    bbcccccf n  ",
      " bbbcccccccfof  "
    ],
    [
      "                ",
      "                ",
      "                ",
      "               b",
      "               b",
      "     d        bc",
      "      a       bc",
      "       i     bcc",
      "            bccc",
      "            bccc",
      "          akcccc",
      "          kfffff",
      "        bbcfgp  ",
      "       bcccfqfrf",
      "     bbccccf s  ",
      "   bbccccccf f  "
    ],
    [
      "                ",
      "                ",
      "                ",
      "                ",
      "    d          b",
      "     a         b",
      "              bc",
      "              bc",
      "             bcc",
      "            bccc",
      "          akcccc",
      "          kfffff",
      "         bcfgt  ",
      "        bccfufff",
      "      bbcccf f  ",
      "    bbcccccfwf  "
    ],
    [
      "                ",
      "                ",
      "                ",
      "   a            ",
      "    i           ",
      "               b",
      "               b",
      "              bc",
      "             bcc",
      "            bccc",
      "          a bccc",
      "           kffff",
      "         bbfg   ",
      "        bccf fff",
      "       bcccf f  ",
      "     bbccccf f  "
    ],
    [
      "                ",
      " d              ",
      "  a             ",
      "   i            ",
      "                ",
      "               k",
      "               k",
      "              kc",
      "              kc",
      "             kcc",
      "          a kccc",
      "           kffff",
      "          kfgxxx",
      "         kcfxfff",
      "       kkccfxf  ",
      "     kkccccfxf  "
    ]
  ]
}