{
  "name": "multi_alienresearch_10_base5",
  "refpalette": "deceasedcraft:multi_alienresearch_10/multi_alienresearch_10_base5_palette",
  "xsize": 16,
  "zsize": 16,
  "slices": [
    [
      "ab  cc cdef     ",
      "b     cgeef     ",
      "      cgef      ",
      "     cdeef      ",
      "c   cgeef       ",
      "c  cgeef        ",
      " ccdeee         ",
      "cggeef         h",
      "deeef          h",
      "eeff          h ",
      "ff           h  ",
      "            h   ",
      "           hh   ",
      "          h     ",
      "         h      ",
      "       hh       "
    ],
    [
      " @iiijjjk       ",
      "@liiijjk        ",
      "iimijjjk        ",
      "iiinjjk         ",
      "iijjkk          ",
      "jjjjko          ",
      "jjjk            ",
      "jkk            h",
      "k              h",
      "              h ",
      "             h  ",
      "            h   ",
      "           hh   ",
      "          h     ",
      "         h      ",
      "       hh       "
    ],
    [
      " @              ",
      "@p              ",
      "  p             ",
      "                ",
      "                ",
      "                ",
      "                ",
      "               h",
      "               h",
      "              h ",
      "             h  ",
      "            h   ",
      "           hh   ",
      "          h     ",
      "         h      ",
      "       hh       "
    ],
    [
      "ijq             ",
      "jj              ",
      "q               ",
      "                ",
      "                ",
      "                ",
      "                ",
      "               h",
      "               h",
      "              h ",
      "             h  ",
      "            h   ",
      "           hh   ",
      "          h     ",
      "         h      ",
      "       hh       "
    ],
    [
      "                ",
      "                ",
      "                ",
      "                ",
      "                ",
      "                ",
      "                ",
      "               h",
      "               h",
      "              h ",
      "             h  ",
      "            h   ",
      "           hh   ",
      "          h     ",
      "         h      ",
      "       hh       "
    ],
    [
      "                ",
      "                ",
      "                ",
      "                ",
      "                ",
      "                ",
      "                ",
      "               r",
      "               r",
      "              r ",
      "             r  ",
      "            r   ",
      "           rr   ",
      "          r     ",
      "         r    ss",
      "       rr     s "
    ]
  ]
}