{
  "name": "multi_alienresearch_10_top",
  "refpalette": "deceasedcraft:multi_alienresearch_10/multi_alienresearch_10_top_palette",
  "xsize": 16,
  "zsize": 16,
  "slices": [
    [
      "                ",
      "                ",
      "                ",
      "                ",
      "                ",
      "                ",
      "      ~         ",
      "                ",
      "                ",
      "                ",
      "                ",
      "                ",
      "                ",
      "                ",
      "                ",
      "                "
    ],
    [
      "                ",
      "                ",
      "                ",
      "                ",
      "   !a           ",
      "                ",
      "      ~         ",
      "                ",
      "                ",
      "                ",
      "                ",
      "              a!",
      "                ",
      "                ",
      "                ",
      "                "
    ],
    [
      "                ",
      "                ",
      "                ",
      "                ",
      "   bbb       cdd",
      "                ",
      "      ~         ",
      "                ",
      "                ",
      "                ",
      "                ",
      "   bbb       cdd",
      "                ",
      "                ",
      "                ",
      "                "
    ],
    [
      "           c  ef",
      "           c  ef",
      "           c  gg",
      "           c  ef",
      "   b b    cdddef",
      "           c  hg",
      "      ~    c  ef",
      "           c  ef",
      "           c  gg",
      "           c  ef",
      "           c  ef",
      "   b b    cddd h",
      "           c   f",
      "           c  ef",
      "           c  gg",
      "           c  ef"
    ],
    [
      "           efij ",
      "           efij ",
      "           efg  ",
      "           efij ",
      "dc k k cdddefjj ",
      "           efh  ",
      "      ~    efi  ",
      "           efij ",
      "           efg  ",
      "           efij ",
      "           efij ",
      "dc b b cdddefh  ",
      "           efj  ",
      "           efij ",
      "           efg  ",
      "           efij "
    ],
    [
      "e       efij    ",
      "e       efij    ",
      "        ggij    ",
      "e       efij    ",
      "edddddddefij    ",
      "g       ggij    ",
      "e     ~ efij    ",
      "e       efij    ",
      "g       ggij    ",
      "e       efij    ",
      "e       efi     ",
      "gdddddddggij    ",
      "e       efij    ",
      "e       efij    ",
      "h       ggij    ",
      "e       efij    "
    ],
    [
      " lfffffij       ",
      "jlfffffij       ",
      " hhhghgg        ",
      "jlfffffij       ",
      "jlfffffjj       ",
      " ggggggg        ",
      "jlfffffij       ",
      "jljffffij       ",
      " ghggggg        ",
      "jlfffffjj       ",
      " lfffffij       ",
      " ggggggh        ",
      "jlfffffij       ",
      " lfffffij       ",
      " hgggggg        ",
      "jjfffffij       "
    ],
    [
      "    jj          ",
      "   jj           ",
      "                ",
      "    jj          ",
      "   jjj          ",
      "                ",
      "   jj           ",
      "    jj          ",
      "                ",
      "   jjj          ",
      "   jjj          ",
      "                ",
      "   jjj          ",
      "   j            ",
      "                ",
      "   j j          "
    ]
  ]
}