{
  "name": "multi_alienresearch_10_base8",
  "refpalette": "deceasedcraft:multi_alienresearch_10/multi_alienresearch_10_base8_palette",
  "xsize": 16,
  "zsize": 16,
  "slices": [
    [
      "aaaabbbbbbccdddd",
      "aaaabbbbbbceeeee",
      "aaabbbbbbcceeeee",
      "aabbbbbbbceeeeee",
      "bbbbbbbbcceeeeee",
      "bbbbbfbcceeeeeee",
      "bbbbbbggeeeeeeee",
      "bbbbbcgeeeeeeeee",
      "bbbbcceeeeeeeeee",
      "bbccceeeeeeeeeee",
      "ccceeeeeeeeeeeee",
      "ceeeeeeeeeeddddd",
      "deeeeeeeeeedhiii",
      "deeeeeeeeeediiii",
      "deeeeeeeeeediiii",
      "deeeeeeeeeediiii"
    ],
    [
      "           jcddd",
      "          kceeee",
      "          lceeee",
      "          ceeeee",
      "          ceeeee",
      "         ceeeeee",
      "      f ceeeeeee",
      "       geeeeeeee",
      "      ceeeeeeeee",
      "     ceeeeeeeeee",
      " m!cceeeeeeeeeee",
      "ncceeeeeeeeddddd",
      "ceeeeeeeeeedh! o",
      "deeeeeeeeeed dpd",
      "deeeeeeeeeed q  ",
      "deeeeeeeeeedrd  "
    ],
    [
      "            cddd",
      "            ceee",
      "            ceee",
      "           ceeee",
      "           ceeee",
      "          ceeeee",
      "         ceeeeee",
      "       fgeeeeeee",
      "       ggeeeeeee",
      "      ceeeeeeeee",
      "     ceeeeeeeeee",
      "   cceeeeeeddddd",
      "ccceeeeeeeedhs  ",
      "deeeeeeeeeedtdud",
      "deeeeeeeeeed w  ",
      "deeeeeeeeeed d  "
    ],
    [
      "             cdd",
      "             cee",
      "            ceee",
      "            ceee",
      "            ceee",
      "           ceeee",
      "          ceeeee",
      "         ceeeeee",
      "        fgeeeeee",
      "       cgeeeeeee",
      "      ceeeeeeeee",
      "     ceeeeeddddd",
      "  ccceeeeeedhx  ",
      "cceeeeeeeeedyddd",
      "deeeeeeeeeed d  ",
      "deeeeeeeeeedAd  "
    ],
    [
      "              cd",
      "              ce",
      "             cee",
      "             cee",
      "            ceee",
      "            ceee",
      "           ceeee",
      "          ceeeee",
      "        f ceeeee",
      "         geeeeee",
      "       cceeeeeee",
      "      ceeeeddddd",
      "    cceeeeedh   ",
      "  cceeeeeeed ddd",
      "cceeeeeeeeed d  ",
      "deeeeeeeeeed d  "
    ],
    [
      "               c",
      "              ce",
      "              ce",
      "              ce",
      "             cee",
      "            ceee",
      "            ceee",
      "           ceeee",
      "        f ceeeee",
      "         geeeeee",
      "        ceeeeeee",
      "       ceeeddddd",
      "     cceeeedhBBB",
      "    ceeeeeedBddd",
      " ccceeeeeeedBd  ",
      "ceeeeeeeeeedBd  "
    ]
  ]
}