{
  "name": "multi_alienresearch_10_base4",
  "refpalette": "deceasedcraft:multi_alienresearch_10/multi_alienresearch_10_base4_palette",
  "xsize": 16,
  "zsize": 16,
  "slices": [
    [
      "                ",
      "                ",
      "                ",
      "                ",
      "               a",
      "               a",
      "              ab",
      "              ab",
      "             abb",
      "            abbc",
      "           abbcc",
      "          adbccc",
      "         abbbccc",
      "        abbccccc",
      "      aabbcccccc",
      "    aabbbccccccc"
    ],
    [
      "                ",
      "                ",
      "                ",
      "                ",
      "                ",
      "               b",
      "               b",
      "              be",
      "              be",
      "             bee",
      "          a beee",
      "           beeee",
      "          beeeee",
      "         beeeeee",
      "       bbeeeeeee",
      "     bbeeeeeeeee"
    ],
    [
      "                ",
      "                ",
      "                ",
      "                ",
      "                ",
      "               f",
      "               f",
      "              fe",
      "             fee",
      "            feee",
      "          a feee",
      "           beeee",
      "         ffeeeee",
      "        feeeeeee",
      "       feeeeeeee",
      "     ffeeeeeeeee"
    ],
    [
      "                ",
      "                ",
      "                ",
      "                ",
      "               f",
      "               f",
      "              fe",
      "              fe",
      "             fee",
      "            feee",
      "          abeeee",
      "          beeeee",
      "         feeeeee",
      "        feeeeeee",
      "      ffeeeeeeee",
      "    ffeeeeeeeeee"
    ],
    [
      "                ",
      "                ",
      "                ",
      "               f",
      "               f",
      "              fe",
      "              fe",
      "             fee",
      "            feee",
      "            feee",
      "          abeeee",
      "          beeeee",
      "        ffeeeeee",
      "       feeeeeeee",
      "     ffeeeeeeeee",
      "   ffeeeeeeeeeee"
    ],
    [
      "                ",
      "               f",
      "               f",
      "               f",
      "              fe",
      "              fe",
      "             fee",
      "            feee",
      "        g   feee",
      "         ahfeeee",
      "         hbeeeee",
      "         feeeeee",
      "       ffeeeeeee",
      "      feeeeeeeee",
      "    ffeeeeeeeeee",
      " fffeeeeeeeeeeee"
    ]
  ]
}