{
  "name": "multi_alienresearch_10_base3",
  "refpalette": "deceasedcraft:multi_alienresearch_10/multi_alienresearch_10_base3_palette",
  "xsize": 16,
  "zsize": 16,
  "slices": [
    [
      "    a    b    cd",
      "    e   b     cd",
      "   f    b     cd",
      "  fb   b     cdg",
      "hi  b  b     cdg",
      "     bb     cdgg",
      "     bc    cdggg",
      "   bb  c   cdggg",
      " bb     c cdgggg",
      "b        cjggggg",
      "        cjgggggg",
      "      ccdggggggg",
      "     cddgggggggg",
      "   ccdgggggggggg",
      "cccddggggggggggg",
      "dddggggggggggggg"
    ],
    [
      "               d",
      "              dg",
      "              dg",
      "              dg",
      "             dgg",
      "            dggg",
      "            dggg",
      "           dgggg",
      "        c dggggg",
      "         kgggggg",
      "        dggggggg",
      "       dgggggggg",
      "     ddggggggggg",
      "    dggggggggggg",
      " dddgggggggggggg",
      "dggggggggggggggg"
    ],
    [
      "              dg",
      "              dg",
      "             dgg",
      "             dgg",
      "            dggg",
      "            dggg",
      "           dgggg",
      "          dggggg",
      "        c dggggg",
      "         kgggggg",
      "       ddggggggg",
      "      dggggggggg",
      "    ddgggggggggg",
      "  ddgggggggggggg",
      "ddgggggggggggggg",
      "gggggggggggggggg"
    ],
    [
      "             dgg",
      "             dgg",
      "            dggg",
      "            dggg",
      "            dggg",
      "           dgggg",
      "          dggggg",
      "         dgggggg",
      "        ckgggggg",
      "       dkggggggg",
      "      dggggggggg",
      "     dgggggggggg",
      "  dddggggggggggg",
      "ddgggggggggggggg",
      "gggggggggggggggg",
      "gggggggggggggggg"
    ],
    [
      "            dggg",
      "            dggg",
      "            dggg",
      "           dgggg",
      "           dgggg",
      "          dggggg",
      "         dgggggg",
      "       ckggggggg",
      "       kkggggggg",
      "      dggggggggg",
      "     dgggggggggg",
      "   ddggggggggggg",
      "dddggggggggggggg",
      "gggggggggggggggg",
      "gggggggggggggggg",
      "gggggggggggggggg"
    ],
    [
      "            dggg",
      "           dgggg",
      "           dgggg",
      "          dggggg",
      "          dggggg",
      "         dgggggg",
      "      c dggggggg",
      "       kgggggggg",
      "      dggggggggg",
      "     dgggggggggg",
      "   ddggggggggggg",
      " ddggggggggggggg",
      "dggggggggggggggg",
      "gggggggggggggggg",
      "gggggggggggggggg",
      "gggggggggggggggg"
    ]
  ]
}