{
  "name": "multi_alienresearch_10_base2",
  "refpalette": "deceasedcraft:multi_alienresearch_10/multi_alienresearch_10_base2_palette",
  "xsize": 16,
  "zsize": 16,
  "slices": [
    [
      "a b       ccdddd",
      " b        cddddd",
      "b a      ccddddd",
      "         cdddddd",
      "        ccdddddd",
      "     b ccddddddd",
      "      eedddddddd",
      "     ceddddddddd",
      "    ccdddddddddd",
      "  cccddddddddddd",
      "cccddddddddddddd",
      "cddddddddddddddd",
      "dddddddddddddddd",
      "dddddddddddddddd",
      "dddddddddddddddd",
      "dddddddddddddddd"
    ],
    [
      "         cdddddd",
      " f       cdddddd",
      "  b     cddddddd",
      "   b    cddddddd",
      "    a  cdddddddd",
      "     beddddddddd",
      "     edddddddddd",
      "    cddddddddddd",
      "  ccdddddddddddd",
      "ccdddddddddddddd",
      "dddddddddddddddd",
      "dddddddddddddddd",
      "dddddddddddddddd",
      "dddddddddddddddd",
      "dddddddddddddddd",
      "dddddddddddddddd"
    ],
    [
      "        cddddddd",
      "       ccddddddd",
      "       cdddddddd",
      "   f  ccdddddddd",
      "    becddddddddd",
      "    eedddddddddd",
      "   ccddddddddddd",
      " cccdddddddddddd",
      "ccdddddddddddddd",
      "dddddddddddddddd",
      "dddddddddddddddd",
      "dddddddddddddddd",
      "dddddddddddddddd",
      "dddddddddddddddd",
      "dddddddddddddddd",
      "dddddddddddddddd"
    ],
    [
      "      ccdddddddd",
      "     ccddddddddd",
      "  b  ccddddddddd",
      "   becdddddddddd",
      "   eeddddddddddd",
      " cccdddddddddddd",
      "cccddddddddddddd",
      "cddddddddddddddd",
      "dddddddddddddddd",
      "dddddddddddddddd",
      "dddddddddddddddd",
      "dddddddddddddddd",
      "dddddddddddddddd",
      "dddddddddddddddd",
      "dddddddddddddddd",
      "dddddddddddddddd"
    ],
    [
      "    ccdddddddddd",
      " b ccddddddddddd",
      "  eecddddddddddd",
      " ceedddddddddddd",
      "cccddddddddddddd",
      "cddddddddddddddd",
      "dddddddddddddddd",
      "dddddddddddddddd",
      "dddddddddddddddd",
      "dddddddddddddddd",
      "dddddddddddddddd",
      "dddddddddddddddd",
      "dddddddddddddddd",
      "dddddddddddddddd",
      "dddddddddddddddd",
      "dddddddddddddddd"
    ],
    [
      "beccdddddddddddd",
      "eeeddddddddddddd",
      "cedddddddddddddd",
      "cddddddddddddddd",
      "dddddddddddddddd",
      "dddddddddddddddd",
      "dddddddddddddddd",
      "dddddddddddddddd",
      "dddddddddddddddd",
      "dddddddddddddddd",
      "dddddddddddddddd",
      "dddddddddddddddd",
      "dddddddddddddddd",
      "dddddddddddddddd",
      "dddddddddddddddd",
      "dddddddddddddddd"
    ]
  ]
}