{
  "name": "multi_filmworkstower_10_floor2",
  "refpalette": "deceasedcraft:multi_filmworkstower_10/multi_filmworkstower_10_floor2_palette",
  "xsize": 16,
  "zsize": 16,
  "slices": [
    [
      "                ",
      "                ",
      "                ",
      "                ",
      "                ",
      "                ",
      "aaaaaaaaaaaaaaaa",
      "bbbbbbbbbbbbbbbb",
      "cccccccccccccccc",
      "   ddebfbeeeeeee",
      "   gdeeeeeeeeeee",
      "   hdeeeeeeeeeee",
      "   hdeeeeeeeeeee",
      "   hdeeeeeeeeeee",
      "   hdeeeeeeeeeee",
      "   hdeeeeeeeeeee"
    ],
    [
      "                ",
      "                ",
      "                ",
      "                ",
      "                ",
      "                ",
      "aaaaaaaaaaaaaaaa",
      "iiiiiiiiiiiiiiii",
      "jjjjjjjjjjjjjjjj",
      "     kblbm      ",
      "                ",
      "                ",
      "                ",
      "                ",
      "                ",
      "               n"
    ],
    [
      "                ",
      "                ",
      "                ",
      "                ",
      "                ",
      "                ",
      "aaaaaaaaaaaaaaaa",
      "oooooooooooooooo",
      "                ",
      "    kp q rm  s t",
      "                ",
      "                ",
      "                ",
      "                ",
      "                ",
      "                "
    ],
    [
      "                ",
      "                ",
      "                ",
      "                ",
      "                ",
      "                ",
      "aaaaaaaaaaaaaaaa",
      "oooooooooooooooo",
      "                ",
      "   kp  u  rm w x",
      "                ",
      "                ",
      "                ",
      "                ",
      "                ",
      "                "
    ],
    [
      "                ",
      "                ",
      "                ",
      "                ",
      "                ",
      "                ",
      "aaaaaaaaaaaaaaaa",
      "o  ooooooo oooo ",
      "                ",
      "  kp   u   rmy A",
      "                ",
      "                ",
      "                ",
      "                ",
      "                ",
      "                "
    ],
    [
      "                ",
      "                ",
      "                ",
      "                ",
      "                ",
      "                ",
      "aaaaaaaaaaaaaaaa",
      "     oo oo   oo ",
      "                ",
      " kp    u    rm B",
      "                ",
      "                ",
      "                ",
      "                ",
      "                ",
      "                "
    ]
  ]
}