{
  "name": "multi_filmworkstower_10_ground",
  "refpalette": "deceasedcraft:multi_filmworkstower_10/multi_filmworkstower_10_ground_palette",
  "xsize": 16,
  "zsize": 16,
  "slices": [
    [
      "aaaaaaabccccccdc",
      "aaaaaabdddcddddd",
      "aaaaaabddddddddd",
      "aaaaaabddddddddd",
      "aaaaaabddcdddcdd",
      "aaaaaaabccccdccc",
      "aaaaaaabcccccecc",
      "bfaaaaaabccccccc",
      "bfbfaaaaabbccccc",
      "bfbfbfaaaaabbccc",
      "bfbfbfbfaaaaabbc",
      "bfbfbfbfbfaaaaab",
      "bfbfbfbfbfbfaaaa",
      "bfbfbfbfbfbfbfaa",
      "bfbfbfbfbfbfbfbf",
      "bfbfbfbfbfbfbfbf"
    ],
    [
      "                ",
      "                ",
      "                ",
      "                ",
      "                ",
      "                ",
      "             ghh",
      "                ",
      " h              ",
      " h h            ",
      " h h h          ",
      " h h h h        ",
      " h h h h h      ",
      " h h h h h h    ",
      " h h h h h h h  ",
      " h h h h h h h h"
    ],
    [
      "                ",
      "                ",
      "                ",
      "                ",
      "                ",
      "                ",
      "             i  ",
      "                ",
      "                ",
      "                ",
      "                ",
      "                ",
      "                ",
      "                ",
      "                ",
      "                "
    ],
    [
      "                ",
      "                ",
      "                ",
      "                ",
      "                ",
      "                ",
      "             h  ",
      "                ",
      "                ",
      "               j",
      "                ",
      "                ",
      "                ",
      "                ",
      "                ",
      "                "
    ],
    [
      "                ",
      "                ",
      "                ",
      "                ",
      "                ",
      "                ",
      "             h  ",
      "                ",
      "                ",
      "k             jl",
      "                ",
      "                ",
      "                ",
      "                ",
      "                ",
      "                "
    ],
    [
      "                ",
      "                ",
      "                ",
      "                ",
      "                ",
      "                ",
      "             m  ",
      "                ",
      "                ",
      "nk           jl ",
      "                ",
      "                ",
      "                ",
      "                ",
      "                ",
      "                "
    ]
  ]
}