{
  "name": "multi_filmworkstower_10_base1",
  "refpalette": "deceasedcraft:multi_filmworkstower_10/multi_filmworkstower_10_base1_palette",
  "xsize": 16,
  "zsize": 16,
  "slices": [
    [
      "                ",
      "                ",
      "                ",
      "                ",
      "                ",
      "                ",
      "                ",
      "                ",
      "                ",
      "                ",
      "                ",
      "                ",
      "                ",
      "                ",
      "                ",
      "  a             "
    ],
    [
      "                ",
      "                ",
      "                ",
      "                ",
      "                ",
      "                ",
      "                ",
      "                ",
      "                ",
      "                ",
      "                ",
      "                ",
      "                ",
      "                ",
      "                ",
      "                "
    ],
    [
      "                ",
      "                ",
      "                ",
      "                ",
      "                ",
      "                ",
      "                ",
      "                ",
      "                ",
      "                ",
      "                ",
      "                ",
      "                ",
      "                ",
      "                ",
      "                "
    ],
    [
      "   b   b   b    ",
      "   c   c   c    ",
      "   c   c   c    ",
      "   c   c   c    ",
      "   c   c   c    ",
      "   d   b   d    ",
      "   c   c   c    ",
      "   c   c   c    ",
      "   c   c   c    ",
      "   c   c   c    ",
      "   d   d   d    ",
      "   c   c   c    ",
      "   c   c   c    ",
      "   c   c   c    ",
      "   c   d   c    ",
      "   d   c   d    "
    ],
    [
      "efegefegefegefeg",
      "hihhhihhhihhhihg",
      "hihhhihhhihhhihg",
      "hihhhihhhihhhihg",
      "hihhhihhhihhhihg",
      "efegefegefegefeg",
      "hihhhihhhihhhihg",
      "hihhhihhhihhhihg",
      "hihhhihhhihhhihg",
      "hihhhihhhihhhihg",
      "efegefegefegefeg",
      "hihhhihhhihhhihg",
      "hihhhihhhihhhihg",
      "hihhhihhhihhhihg",
      "hihhhihhhihhhihg",
      "efegefegefegefeg"
    ],
    [
      "jjjjjjjjjjjjjjjj",
      "jjjjjjjjjjjjjjjj",
      "jjjjjjjjjjjjjjjj",
      "jjjjjjjjjjjjjjjj",
      "jjjjjjjjjjjjjjjj",
      "jjjjjjjjjjjjjjjj",
      "jjjjjjjjjjjjjjjj",
      "jjjjjjjjjjjjjjjj",
      "jjjjjjjjjjjjjjjj",
      "jjjjjjjjjjjjjjjj",
      "jjjjjjjjjjjjjjjj",
      "jjjjjjjjjjjjjjjj",
      "jjjjjjjjjjjjjjjj",
      "jjjjjjjjjjjjjjjj",
      "jjjjjjjjjjjjjjjj",
      "jjjjjjjjjjjjjjjj"
    ]
  ]
}