{
  "name": "multi_filmworkstower_10_floor1",
  "refpalette": "deceasedcraft:multi_filmworkstower_10/multi_filmworkstower_10_floor1_palette",
  "xsize": 16,
  "zsize": 16,
  "slices": [
    [
      "                ",
      "                ",
      "                ",
      "                ",
      "                ",
      "                ",
      "                ",
      "                ",
      "                ",
      "aab         cd  ",
      "                ",
      "e               ",
      "                ",
      "                ",
      "e               ",
      "                "
    ],
    [
      "ffgffffgffffgfff",
      "ffgffffgffffgfff",
      "ffgffffgffffgfff",
      "ffgffffgffffgfff",
      "ffgffffgffffgfff",
      "ffgffffgffffgfff",
      "ffgffffgffffgfff",
      "hiiiiiiiiiiiiiii",
      "e               ",
      "aaab       cd   ",
      "e               ",
      "je              ",
      "e               ",
      "e               ",
      "je              ",
      "e               "
    ],
    [
      "kkkkkkkkkkkkkkkk",
      "kkkkkkkkkkkkkkkk",
      "kkkkkkkkkkkkkkkk",
      "kkkkkkkkkkkkkkkk",
      "kkkkkkkkkkkkkkkk",
      "kkkkkkkkkkkkkkkk",
      "kkkkkkkkkkkkkkkk",
      "       l        ",
      "je              ",
      "maaabn o ncd    ",
      "me              ",
      "mjep            ",
      "me              ",
      "me              ",
      "mjep            ",
      "me              "
    ],
    [
      "       q        ",
      "       q        ",
      "       q        ",
      "       q        ",
      "       q        ",
      "       q        ",
      "       q        ",
      "       r        ",
      "jje    s        ",
      " maaaaaaaaabnnnn",
      " te             ",
      " tje            ",
      " te             ",
      " te             ",
      " tje            ",
      " te             "
    ],
    [
      "                ",
      "                ",
      "                ",
      "                ",
      "                ",
      "                ",
      "                ",
      "                ",
      "jjjeu           ",
      " mmaaaaaaaaaaaaa",
      " wmeu           ",
      " xmjju     y    ",
      " xmeu           ",
      " xmeu           ",
      " xmjju     y    ",
      " Ameu           "
    ],
    [
      "                ",
      "                ",
      "                ",
      "                ",
      "                ",
      "                ",
      "                ",
      "BBBBBBBBBBBBBBBB",
      "jjjjjeuuuuuuuuuu",
      "   mjaaaaaaaaaaa",
      "   tj uuuuuuuuuu",
      "   tjjjjjjjjjjjj",
      "   tjeuuuuuuuuuu",
      "   tjeuuuuuuuuuu",
      "   tjjjjjjjjjjjj",
      "   tjeuuuuuuuuuu"
    ]
  ]
}