{
  "name": "multi_filmworkstower_10_base3",
  "refpalette": "deceasedcraft:multi_filmworkstower_10/multi_filmworkstower_10_base3_palette",
  "xsize": 16,
  "zsize": 16,
  "slices": [
    [
      "aaaaaaaaaaaaaaaa",
      "aaaaaaaaaaaaaaaa",
      "aaaaaaaaaaaaaaaa",
      "aaaaaaaaaaaaaaaa",
      "aaaaaaaaaaaaaaaa",
      "aaaaaaaaaaaaaaaa",
      "aaaaaaaaaaaaaaaa",
      "aaaaaaaaaaaaaaaa",
      "aaaaaaaaaaaaaaaa",
      "aaaaaaaaaaaaaaaa",
      "aaaaaaaaaaaaaaaa",
      "aaaaaaaaaaaaaaaa",
      "aaaaaaaaaaaaaaaa",
      "aaaaaaaaaaaaaaaa",
      "aaaaaaaaaaaaaaaa",
      "aaaaaaaaaaaaaaaa"
    ],
    [
      "bbcdddeeeeeebbbb",
      "bbbdddeeeedebbbb",
      "bbbdddeeededbcbb",
      "bbcdddeeeeedefff",
      "bbbdddeeeddeeeed",
      "bbbddeeeeddddeee",
      "bbbbddeeeeddddcb",
      "bbbbeeeeeddeddbb",
      "bbbbeeeeeeeeeebb",
      "bbbddeeeeeeedebg",
      "dddhddeeedeeeebb",
      "fffdhdeeeedddebb",
      "bbchdeeeedddddcb",
      "bbbheieeeedddddd",
      "bbbbeeeeededdhhd",
      "bbbheeeeeeeddhjd"
    ],
    [
      "bbk         lbbb",
      "bbbm        lbbb",
      "gbbn        okbb",
      "bbk            p",
      "gbb            q",
      "bbb             ",
      "bbbr         skg",
      "bbbr        t b ",
      "bbbr          u ",
      "bbb w       t bx",
      "y AB y        C ",
      "D  yE       t b ",
      "bbkFI         kg",
      "JJbK L        M ",
      "JNOP           Q",
      "RSj           TU"
    ],
    [
      "JJk          V  ",
      "  J          C  ",
      "  J          kJJ",
      "JWk             ",
      "                ",
      "  t             ",
      "X             kb",
      "            t b ",
      " YI           Z ",
      "E t         t b ",
      "              0 ",
      "            t b ",
      "bbk           kb",
      "11O             ",
      " AP             ",
      "234           5U"
    ],
    [
      "6Jk          7  ",
      "  J          0  ",
      "  J          kJJ",
      "J8k             ",
      "                ",
      "  t             ",
      "              kb",
      "            t9b ",
      "            t#b ",
      "  t         t#b ",
      "            t#b ",
      "            t$b ",
      "6%k           kb",
      "  ^             ",
      "                ",
      " 34           &*"
    ],
    [
      "JJk          J( ",
      "  J          J) ",
      "  J         +kJJ",
      "JJk         ---[",
      "                ",
      "  t           t ",
      "             %]{",
      "            ]}]|",
      "            ;}]|",
      "  t         ;}]|",
      "            ;}]|",
      "            ]}]|",
      "bbk          %]{",
      " :'           t ",
      "                ",
      " <4           &*"
    ]
  ]
}