{
  "name": "multi_filmworkstower_10_base2",
  "refpalette": "deceasedcraft:multi_filmworkstower_10/multi_filmworkstower_10_base2_palette",
  "xsize": 16,
  "zsize": 16,
  "slices": [
    [
      "aab         cde ",
      "ffg         hde ",
      "ffg         iiij",
      "ffb            k",
      "fff             ",
      "fff             ",
      "fff          lbd",
      "fff         lmd ",
      "fff         lmd ",
      "fff         lmdn",
      "            lod ",
      "pppp        lmd ",
      "ddbc         lbd",
      " qg             ",
      "                ",
      " rs           tu"
    ],
    [
      "ddbc        pppp",
      "wwd         iiii",
      " wd             ",
      " ebh            ",
      "iiii            ",
      "  x          ppy",
      "A x          cbd",
      "  x           d ",
      "  x           B ",
      "xxx           C ",
      "              B ",
      "              d ",
      "Dppp         hbd",
      "dEfc         iiy",
      "                ",
      " usF   I      tu"
    ],
    [
      "pppp            ",
      "  dc            ",
      "  dh            ",
      "iiii            ",
      "                ",
      "               p",
      "             ppd",
      "             cd ",
      "              d ",
      "              d ",
      "              d ",
      "             hd ",
      "             iid",
      "DDJp           i",
      "   E            ",
      " usJ   =      Ku"
    ],
    [
      "                ",
      "pppp            ",
      "iiii            ",
      "                ",
      "                ",
      "                ",
      "                ",
      "             ppp",
      "             cg ",
      "            LLg ",
      "             hg ",
      "             iii",
      "                ",
      "                ",
      "                ",
      " uM    N      Ku"
    ],
    [
      "                ",
      "                ",
      "                ",
      "                ",
      "                ",
      "                ",
      "                ",
      "                ",
      "             ppp",
      "            OPaa",
      "             iii",
      "                ",
      "                ",
      "                ",
      "                ",
      " Ku          QuM"
    ],
    [
      "                ",
      "                ",
      "                ",
      "                ",
      "                ",
      "                ",
      "                ",
      "                ",
      "                ",
      "                ",
      "                ",
      "                ",
      "                ",
      "                ",
      "                ",
      " Ku         RST "
    ]
  ]
}