{
  "name": "multi_thering_20_base1",
  "refpalette": "deceasedcraft:multi_thering_20/multi_thering_20_base1_palette",
  "xsize": 16,
  "zsize": 16,
  "slices": [
    [
      "vvvvvvvvvvvvvvvv",
      "aaaaaaaaaaaaaaav",
      "aaaaaaaaaaaaaaav",
      "aaaaaaaaaaaaaaav",
      "aaaaaaaaaaaaaaav",
      "aaaaaaaaaaaaaaav",
      "aaaaaaaaaaaaaaav",
      "aaaaaaaaaaaaaaav",
      "aaaaaaaaaaaaaaav",
      "aaaaaaaaaaaaaaav",
      "aaaaaaaaaaaaaaav",
      "aaaaaaaaaaaaaaav",
      "aaaaaaaaaaaaaaav",
      "aaaaaaaaaaaaaaav",
      "aaaaaaaaaaaaaaav",
      "baaaaaaaaaaaaaav"
    ],
    [
      "vvvvvvvvvvvvvvvv",
      "aaaaaaaaaaaaaaav",
      "aaaaaaaaaaaaaaav",
      "aaaaaaaaaaaaaaav",
      "aaaaaaaaaaaaaaav",
      "aaaaaaaaaaaaaaav",
      "aaaaaaaaaaaaaaav",
      "aaaaaaaaaaaaaaav",
      "aaaaaaaaaaaaaaav",
      "aaaaaaaaaaaaaaav",
      "aaaaaaaaaaaaaaav",
      "aaaaaaaaaaaaaaav",
      "aaaaaaaaaaaaaaav",
      "aaaaaaaaaaaaaaav",
      "aaaaaaaaaaaaaaav",
      "baaaaaaaaaaaaaav"
    ],
    [
      "vvvvvvvvvvvvvvvv",
      "aaaaaaaaaaaaaaav",
      "aaaaaaaaaaaaaaav",
      "aaaaaaaaaaaaaaav",
      "aaaaaaaaaaaaaaav",
      "aaaaaaaaaaaaaaav",
      "aaaaaaaaaaaaaaav",
      "aaaaaaaaaaaaaaav",
      "aaaaaaaaaaaaaaav",
      "aaaaaaaaaaaaaaav",
      "aaaaaaaaaaaaaaav",
      "aaaaaaaaaaaaaaav",
      "aaaaaaaaaaaaaaav",
      "aaaaaaaaaaaaaaav",
      "aaaaaaaaaaaaaaav",
      "baaaaaaaaaaaaaav"
    ],
    [
      "vvvvvvvvvvvvvvvv",
      "aaaaaaaaaaaaaaav",
      "aaaaaaaaaaaaaaav",
      "aaaaaaaaaaaaaaav",
      "aaaaaaaaaaaaaaav",
      "aaaaaaaaaaaaaaav",
      "aaaaaaaaaaaaaaav",
      "aaaaaaaaaaaaaaav",
      "aaaaaaaaaaaaaaav",
      "aaaaaaaaaaaaaaav",
      "aaaaaaaaaaaaaaav",
      "aaaaaaaaaaaaaaav",
      "aaaaaaaaaaaaaaav",
      "aaaaaaaaaaaaaaav",
      "aaaaaaaaaaaaaaav",
      "baaaaaaaaaaaaaav"
    ],
    [
      "vvvvvvvvvvvvvvvv",
      "aaaaaaaaaaaaaaav",
      "aaaaaaaaaaaaaaav",
      "aaaaaaaaaaaaaaav",
      "aaaaaaaaaaaaaaav",
      "aaaaaaaaaaaaaaav",
      "aaaaaaaaaaaaaaav",
      "aaaaaaaaaaaaaaav",
      "aaaaaaaaaaaaaaav",
      "aaaaaaaaaaaaaaav",
      "aaaaaaaaaaaaaaav",
      "aaaaaaaaaaaaaaav",
      "aaaaaaaaaaaaaaav",
      "aaaaaaaaaaaaaaav",
      "aaaaaaaaaaaaaaav",
      "baaaaaaaaaaaaaav"
    ],
    [
      "vvvvvvvvvvvvvvvv",
      "cccccccccccccccv",
      "cccccccccccccccv",
      "cccccccccccccccv",
      "cccccccccccccccv",
      "cccccccccccccccv",
      "cccccccccccccccv",
      "cccccccccccccccv",
      "cccccccccccccccv",
      "cccccccccccccccv",
      "cccccccccccccccv",
      "cccccccccccccccv",
      "cccccccccccccccv",
      "cccccccccccccccv",
      "cccccccccccccccv",
      "bccccccccccccccv"
    ]
  ]
}