{
  "name": "multi_verticalschool_8_floor30",
  "refpalette": "deceasedcraft:multi_verticalschool_8/multi_verticalschool_8_floor30_palette",
  "xsize": 16,
  "zsize": 16,
  "slices": [
    [
      "abbbbbbbbbbbbbbb",
      "abcccccccccccccc",
      "abcddddddddddddc",
      "abcccccccddddddc",
      "abcddddddcdddddc",
      "abcdddddddcddddc",
      "abcccccccdcdddce",
      "abcddddcdccdddcf",
      "abcccccccdcdddcf",
      "abcdddddddcddddc",
      "abcddddddcdddddc",
      "abcccccccddddddc",
      "abcddddddddddddc",
      "abcccccccccccccc",
      "agggbbbbbbbbbbbb",
      "aaaaaaaaaaaaaaaa"
    ],
    [
      "                ",
      "                ",
      "                ",
      "                ",
      "                ",
      "                ",
      "                ",
      "                ",
      "                ",
      "                ",
      "                ",
      "                ",
      "                ",
      "                ",
      " ggg            ",
      "                "
    ],
    [
      "                ",
      "                ",
      "                ",
      "                ",
      "                ",
      "                ",
      "                ",
      "                ",
      "                ",
      "                ",
      "                ",
      "                ",
      "                ",
      "                ",
      " ggg            ",
      "  h             "
    ],
    [
      "                ",
      "                ",
      "                ",
      "                ",
      "                ",
      "                ",
      "                ",
      "                ",
      "                ",
      "                ",
      "                ",
      "                ",
      "                ",
      "                ",
      " ggg            ",
      "                "
    ],
    [
      "                ",
      "                ",
      "                ",
      "                ",
      "                ",
      "                ",
      "                ",
      " ij             ",
      "                ",
      "                ",
      "                ",
      "                ",
      "                ",
      "                ",
      " ggg            ",
      "                "
    ],
    [
      "                ",
      "                ",
      "                ",
      "                ",
      "                ",
      "                ",
      "  k             ",
      " l!             ",
      "  k             ",
      "                ",
      "                ",
      "                ",
      "                ",
      "                ",
      " ggg            ",
      "                "
    ]
  ]
}