{
  "name": "multi_verticalschool_8_floor18",
  "refpalette": "deceasedcraft:multi_verticalschool_8/multi_verticalschool_8_floor18_palette",
  "xsize": 16,
  "zsize": 16,
  "slices": [
    [
      " abbbbbbb ba    ",
      " c         c    ",
      " c         c    ",
      " a         a    ",
      " c         c    ",
      " c         c    ",
      " c         c    ",
      " c         c    ",
      " c         c    ",
      " c         c    ",
      " a         a    ",
      " c         c    ",
      " c         c    ",
      " a        da    ",
      " eeeaaaaaaaa    ",
      "                "
    ],
    [
      " a         a    ",
      " a         a    ",
      " a         a    ",
      " a         a    ",
      " a         a    ",
      " a         a    ",
      " a         a    ",
      " a         a    ",
      " a         a    ",
      " a         a    ",
      " a         a    ",
      " a         a    ",
      " a         a    ",
      " a        fa    ",
      " eeeaaaaaaaa    ",
      "                "
    ],
    [
      "gahhhhhhhhha    ",
      "gahhhhhhhhha    ",
      "gahihhihhiha    ",
      "gahhhhhhhhha    ",
      "gahhhhhhhhha    ",
      "gahjhhihhiha    ",
      "gahhhhhhhhha    ",
      "gahhhhhhhhha    ",
      "gahjhhihhiha    ",
      "gahhhhhhhhha    ",
      "gahhhhhhhhha    ",
      "gahihhjhhiha    ",
      "gahhhhhhhhha    ",
      "gahhhhhhhhha    ",
      "geeeaaaaaaaa    ",
      "gggggggggggggggg"
    ],
    [
      "klmmmmmmmmmlno  ",
      "klmmmmmmmmmlno  ",
      "klmmmmmmmmmlno  ",
      "klmmmmmmmmmlno  ",
      "klmmmmmmmmmlno  ",
      "klmmmmmmmmmlno  ",
      "klmmmmmmmmmlno  ",
      "klmmmmmmmmmlno  ",
      "klmmmmmmmmmlno  ",
      "klmmmmmmmmmlno  ",
      "klmmmmmmmmmlno  ",
      "klmmmmmmmmmlno  ",
      "klmmmmmmmmmlno  ",
      "klmmmmmmmmmlnooo",
      "keeellllllllnnnn",
      "kkkkkkkkkkkkkkkk"
    ],
    [
      " lppqpppqppl r  ",
      " l         s r  ",
      " l         t r  ",
      " lu uu uu ul r  ",
      " lw xy xy wl r  ",
      " l         l r  ",
      " lu uu uu ul r  ",
      " lw xy xy wl r  ",
      " l         l r  ",
      " lu uu uu ul r  ",
      " lw xy xy wl r  ",
      " l         s r  ",
      " l    A    B r  ",
      " lCDEEEEFIJl  KK",
      " eeellllllll    ",
      "           L    "
    ],
    [
      " apqppppp!qa    ",
      " c         M    ",
      " c         N    ",
      " a         a    ",
      " cO  P Q  Oc    ",
      " c         c    ",
      " c         c    ",
      " cQ QO Q  Pc    ",
      " c         c    ",
      " c         c    ",
      " a  O  PO Qa    ",
      " c         M    ",
      " c         R    ",
      " a !  S   Ta    ",
      " eeeaaaaaaaa    ",
      "                "
    ]
  ]
}