{
  "name": "multi_verticalschool_8_floor8",
  "refpalette": "deceasedcraft:multi_verticalschool_8/multi_verticalschool_8_floor8_palette",
  "xsize": 16,
  "zsize": 16,
  "slices": [
    [
      "abbc      da    ",
      "abbc      e     ",
      "abbf      e     ",
      "abb       da    ",
      "abbf      da    ",
      "abb       da    ",
      "abbf      da    ",
      "abb       da    ",
      "abbf      da    ",
      "abb       da    ",
      "abbf      da    ",
      "abb       da    ",
      "abbf    g da    ",
      "abb     h da    ",
      "aiii      da    ",
      " aaaaaaaaaaaajja"
    ],
    [
      "a       k da  la",
      "a         da  la",
      "af        da  la",
      "a         da  la",
      "af        da  la",
      "a         ma  la",
      "af        ma  la",
      "a         ma  la",
      "af        ma  la",
      "a         ma  la",
      "af        da  la",
      "a         da  la",
      "af        da  la",
      "a         da  la",
      "aiii    n da  la",
      "oaaaaaaaaaaaaaaa"
    ],
    [
      "a      pqrdasabb",
      "a         dasabb",
      "a         dasabb",
      "a         dasabb",
      "a         dasabb",
      "a         tasabb",
      "a         tasabb",
      "a         tasabb",
      "a         tasabb",
      "a         tasabb",
      "a         dasabb",
      "a         dasabb",
      "a         dasabb",
      "a         dasabb",
      "aiii   uqwdasabb",
      "xaaaaaaaaaaaaaaa"
    ],
    [
      "a      yqAdabb  ",
      "a         dabbB ",
      "a         dabb  ",
      "a         dabbB ",
      "a         dabb  ",
      "a         CabbB ",
      "a         CabbD ",
      "a         CabbD ",
      "a         CabbD ",
      "a         CabbbB",
      "a         dabbb ",
      "a         dabbbB",
      "a         dabbb ",
      "a         dabbbB",
      "aiii   E!FdabbbI",
      " aaaaaaaaaaaaaaa"
    ],
    [
      "a      JJJKa    ",
      "a      JJJKaB   ",
      "a      JJJKa    ",
      "a      JJJKaB   ",
      "a      JJJKa    ",
      "a      JJJKaB   ",
      "a      JJJKa    ",
      "a      JJJKa    ",
      "a      JJJKa    ",
      "a      JJJKa B  ",
      "a      JJJKa    ",
      "a      JJJKa B  ",
      "a      JJJKa    ",
      "a      JJJKa B  ",
      "aiii   JJJKaIIII",
      " aaaaaaaaaaaaaaa"
    ],
    [
      "aJJJJJJJL Ma    ",
      "aJJJJJJJL Ma    ",
      "aJJJJJJJL Ma    ",
      "aJJJJJJJL Ma    ",
      "aJJJJJJJL Ma    ",
      "aJJJJJJJL Ma    ",
      "aJJJJJJJL Ma    ",
      "aJJJJJJJL Ma    ",
      "aJJJJJJJL Ma    ",
      "aJJJJJJJL Ma    ",
      "aJJJJJJJL Ma    ",
      "aJJJJJJJL Ma    ",
      "aJJJJJJJL Ma    ",
      "aJJJJJJJL Ma    ",
      "aiiiJJJJL MaIIII",
      "saaaaaaaaaaaaaaa"
    ]
  ]
}