{
  "name": "multi_verticalschool_8_floor14",
  "refpalette": "deceasedcraft:multi_verticalschool_8/multi_verticalschool_8_floor14_palette",
  "xsize": 16,
  "zsize": 16,
  "slices": [
    [
      "abbbccde        ",
      "abbbbcbfg       ",
      "abbbbcb         ",
      "abbbbcb         ",
      "abbbbcb         ",
      "abbbbcb         ",
      "abbbbcb         ",
      "abbbbcb         ",
      "abbbbcb         ",
      "abbbbcb         ",
      "abbbbcb         ",
      "abbbbcb         ",
      "abbbbcbhi       ",
      "abbbccde        ",
      "jkkkjjjjjjjjjjjh",
      "                "
    ],
    [
      "j               ",
      "j      l        ",
      "j mmmmmn        ",
      "j mmmmmn        ",
      "j      n        ",
      "j mmmmmn        ",
      "j mmmmmn        ",
      "j mmmmmn        ",
      "j mmmmmn        ",
      "j      n        ",
      "j mmmmmn        ",
      "j mmmmmn        ",
      "j      o        ",
      "j               ",
      "jkkkjjjjjjjjjjjj",
      "                "
    ],
    [
      "j         p     ",
      "j               ",
      "j               ",
      "j               ",
      "j               ",
      "j               ",
      "j               ",
      "j               ",
      "j               ",
      "j               ",
      "j               ",
      "j               ",
      "j               ",
      "j         q     ",
      "jkkkjjjjjjjjjjjj",
      "                "
    ],
    [
      "j         !     ",
      "j               ",
      "j               ",
      "j               ",
      "j               ",
      "j               ",
      "j               ",
      "j               ",
      "j               ",
      "j               ",
      "j               ",
      "j               ",
      "j               ",
      "j         r     ",
      "jkkkjjjjjjjjjjjj",
      "                "
    ],
    [
      "j         r     ",
      "j               ",
      "j               ",
      "j               ",
      "j               ",
      "j               ",
      "j               ",
      "j               ",
      "j               ",
      "j               ",
      "j               ",
      "j               ",
      "j               ",
      "j         s     ",
      "jkkkjjjjjjjjjjjj",
      "tttttttttttttttt"
    ],
    [
      "j               ",
      "j               ",
      "j               ",
      "j               ",
      "j               ",
      "j               ",
      "j               ",
      "j               ",
      "j               ",
      "j               ",
      "j               ",
      "j               ",
      "j               ",
      "j               ",
      "jkkkjjjjjjjjjjjj",
      "ujjjjjjjjjjjjjjj"
    ]
  ]
}