{
  "name": "multi_verticalschool_8_floor28",
  "refpalette": "deceasedcraft:multi_verticalschool_8/multi_verticalschool_8_floor28_palette",
  "xsize": 16,
  "zsize": 16,
  "slices": [
    [
      "abcccccccccbdddd",
      "abcccccccccbdddd",
      "abcccccccccbdddd",
      "abcccccccccbdddd",
      "abcccccccccbdddd",
      "abcccccccccbdddd",
      "abcccccccccbdddd",
      "abcccccccccbdddd",
      "abcccccccccbdddd",
      "abcccccccccbdddd",
      "abcccccccccbdddd",
      "abcccccccccbdddd",
      "abcccccccccbdddd",
      "abcccccccccbdddd",
      "aeeebbbbbbbbdddd",
      "aaaaaaaaaaaaaaaa"
    ],
    [
      "fbghhhhhhi b    ",
      "fb   j kl  m    ",
      "fbnnkoonnj p    ",
      "fbqr rsqr  b    ",
      "fbtu  wtx  b    ",
      "fby  ABy   b    ",
      "fb         b    ",
      "fb         b    ",
      "fbqx  sq   b    ",
      "fbt  Awtx  b    ",
      "fbyC CByC  b    ",
      "fbDD EEDD  F    ",
      "fb      I  J    ",
      "fbKLMNKLMN b    ",
      "feeebbbbbbbbO  O",
      "PPPPPPPPPPPPPPPP"
    ],
    [
      " QRRRSRSRR Q    ",
      " T         U    ",
      " T         V    ",
      " QWX  YZZ  Q    ",
      " T    Y0   T    ",
      " T1    Z   T    ",
      " T         T    ",
      " T         T    ",
      " T2   3    T    ",
      " T    45   T    ",
      " Q67 89    Q    ",
      " T         #    ",
      " T         $    ",
      " Q% 6^& ^*(Q    ",
      " eeeQQQQQQQQ    ",
      "                "
    ],
    [
      " Q )  k +  Q    ",
      " T         T    ",
      " T         T    ",
      " Q         Q    ",
      " T         T    ",
      " T         T    ",
      " T         T    ",
      " T         T    ",
      " T         T    ",
      " T         T    ",
      " Q         Q    ",
      " T         T    ",
      " T         T    ",
      " Q        -Q    ",
      " eeeQQQQQQQQ    ",
      "                "
    ],
    [
      " Q         Q    ",
      " Q         Q    ",
      " Q         Q    ",
      " Q         Q    ",
      " Q         Q    ",
      " Q         Q    ",
      " Q         Q    ",
      " Q         Q    ",
      " Q         Q    ",
      " Q         Q    ",
      " Q         Q    ",
      " Q         Q    ",
      " Q         Q    ",
      " Q        !Q    ",
      " eeeQQQQQQQQ    ",
      "                "
    ],
    [
      "[Q]]]]]]]]]Q{{{{",
      "[Q]]]]]]]]]Q{{{{",
      "[Q]}]]}]]}]Q{{{{",
      "[Q]]]]]]]]]Q{{{{",
      "[Q]]]]]]]]]Q{||{",
      "[Q];]]}]]}]Q{{{{",
      "[Q]]]]]]]]]Q{{{{",
      "[Q]]]]]]]]]Q{{{{",
      "[Q]}]];]]}]Q{{{{",
      "[Q]]]]]]]]]Q{::{",
      "[Q]]]]]]]]]Q{{{{",
      "[Q]}]]}]]}]Q{{{{",
      "[Q]]]]]]]]]Q{{{{",
      "[Q]]]]]]]]]Q{{{{",
      "[eeeQQQQQQQQ''''",
      "[[[[[[[[[[[[[[[["
    ]
  ]
}