{
  "name": "multi_verticalschool_8_floor26",
  "refpalette": "deceasedcraft:multi_verticalschool_8/multi_verticalschool_8_floor26_palette",
  "xsize": 16,
  "zsize": 16,
  "slices": [
    [
      "abcccccccccbdddd",
      "abcccccccccbdddd",
      "abcccccccccbdddd",
      "abcccccccccbdddd",
      "abcccccccccbdddd",
      "abcccccccccbdddd",
      "abcccccccccbdddd",
      "abcccccccccbdddd",
      "abcccccccccbdddd",
      "abcccccccccbdddd",
      "abcccccccccbdddd",
      "abcccccccccbdddd",
      "abcccccccccbdddd",
      "abcccccccccbdddd",
      "aeeebbbbbbbbdddd",
      "aaaaaaaaaaaaaaaa"
    ],
    [
      "fbghhhhhhi b    ",
      "fb   jk    l    ",
      "fbmm nnmm  o    ",
      "fbpq qrpq  b    ",
      "fbst uwsx  b    ",
      "fby   Ay   b    ",
      "fbB        b    ",
      "fb         b    ",
      "fbp  urp   b    ",
      "fbsC  wst  b    ",
      "fbyD DAyD  b    ",
      "fbEE FFEE  I    ",
      "fb         J    ",
      "fbKLMNLLMN b    ",
      "feeebbbbbbbbO  O",
      "PPPPPPPPPPPPPPPP"
    ],
    [
      " QRSSTSSSS Q    ",
      " U         V    ",
      " U         W    ",
      " QXY  Z01  Q    ",
      " U2   32   U    ",
      " U0    0   U    ",
      " U         U    ",
      " U         U    ",
      " UX   4    U    ",
      " U5   67   U    ",
      " QX  ZZX8  Q    ",
      " U         9    ",
      " U         #    ",
      " Q$ %^  &^*Q    ",
      " eeeQQQQQQQQ    ",
      "                "
    ],
    [
      " Q () k +  Q    ",
      " U         U    ",
      " U         U    ",
      " Q         Q    ",
      " U         U    ",
      " U         U    ",
      " U         U    ",
      " U         U    ",
      " U         U    ",
      " U         U    ",
      " Q         Q    ",
      " U         U    ",
      " U         U    ",
      " Q    !   -Q    ",
      " eeeQQQQQQQQ    ",
      "                "
    ],
    [
      " Q         Q    ",
      " Q         Q    ",
      " Q         Q    ",
      " Q         Q    ",
      " Q         Q    ",
      " Q         Q    ",
      " Q         Q    ",
      " Q         Q    ",
      " Q         Q    ",
      " Q         Q    ",
      " Q         Q    ",
      " Q         Q    ",
      " Q         Q    ",
      " Q        [Q    ",
      " eeeQQQQQQQQ    ",
      "                "
    ],
    [
      "]Q{{{{{{{{{Q}}}}",
      "]Q{{{{{{{{{Q}}}}",
      "]Q{|{{;{{;{Q}}}}",
      "]Q{{{{{{{{{Q}}}}",
      "]Q{{{{{{{{{Q}::}",
      "]Q{;{{|{{|{Q}}}}",
      "]Q{{{{{{{{{Q}}}}",
      "]Q{{{{{{{{{Q}}}}",
      "]Q{;{{;{{;{Q}}}}",
      "]Q{{{{{{{{{Q}::}",
      "]Q{{{{{{{{{Q}}}}",
      "]Q{;{{;{{;{Q}}}}",
      "]Q{{{{{{{{{Q}}}}",
      "]Q{{{{{{{{{Q}}}}",
      "]eeeQQQQQQQQ''''",
      "]]]]]]]]]]]]]]]]"
    ]
  ]
}