{
  "name": "multi_verticalschool_8_floor4",
  "refpalette": "deceasedcraft:multi_verticalschool_8/multi_verticalschool_8_floor4_palette",
  "xsize": 16,
  "zsize": 16,
  "slices": [
    [
      " abbbbbbbbba    ",
      " abbbbbbbbbac   ",
      "  abbbbbbbbad   ",
      "   abbbbbbba    ",
      "    abbbbbba    ",
      "     abbbbbac   ",
      "      abbbbad   ",
      "       abbba    ",
      " ee     abba    ",
      "effe     aa     ",
      "efffe           ",
      "effffe          ",
      "efffffe         ",
      " efffffe        ",
      " gggfffe        ",
      "   eeee         "
    ],
    [
      "                ",
      "                ",
      "                ",
      "                ",
      "                ",
      "                ",
      "                ",
      "                ",
      "                ",
      "  h             ",
      " i              ",
      "  j             ",
      "    i           ",
      "   h  i         ",
      " ggg ih         ",
      "                "
    ],
    [
      "                ",
      "                ",
      "                ",
      "                ",
      "                ",
      "                ",
      "                ",
      "                ",
      "                ",
      "                ",
      "  k             ",
      "  l             ",
      "                ",
      "                ",
      " ggg            ",
      "                "
    ],
    [
      "                ",
      "                ",
      "                ",
      "                ",
      "                ",
      "                ",
      "                ",
      "                ",
      "                ",
      "                ",
      "  k             ",
      " kkk            ",
      "  kk            ",
      "                ",
      " ggg            ",
      "                "
    ],
    [
      "                ",
      "                ",
      "                ",
      "                ",
      "                ",
      "                ",
      "                ",
      "                ",
      "                ",
      "                ",
      "                ",
      "                ",
      "                ",
      "                ",
      " ggg            ",
      "                "
    ],
    [
      "mnnnmnnnmnnnmnno",
      "mnnnmnnnmnnnmnno",
      "mnnnmnnnmnnnmnno",
      "mnnnmnnnmnnnmnno",
      "mnnnmnnnmnnnmnno",
      "mnnnmnnnmnnnmnno",
      "mnnnmnnnmnnnmnno",
      "mnnnmnnnmnnnmnno",
      "mnnnmnnnmnnnmnno",
      "mnnnmnnnmnnnmnno",
      "mnnnmnnnmnnnmnno",
      "mnnnmnnnmnnnmnno",
      "mnnnmnnnmnnnmnno",
      "mnnnmnnnmnnnmnno",
      "mgggmnnnmnnnmnno",
      "mnnnmnnnmnnnmnno"
    ]
  ]
}