{
  "name": "multi_verticalschool_8_floor23",
  "refpalette": "deceasedcraft:multi_verticalschool_8/multi_verticalschool_8_floor23_palette",
  "xsize": 16,
  "zsize": 16,
  "slices": [
    [
      "     aaaa       ",
      "                ",
      "                ",
      "                ",
      "                ",
      "                ",
      "                ",
      "                ",
      "                ",
      "                ",
      "                ",
      "                ",
      "                ",
      "                ",
      " bbb            ",
      "                "
    ],
    [
      "ccdeeeeeeeeeeeee",
      "ccdeeeeeeeeeeeee",
      "ccdeeeeeeeeeeeee",
      "ccdeeeeeeeeeeeee",
      "ccdeeeeeeeeeeeee",
      "ccdeeeeeeeeeeeee",
      "ccdeeeeeeeeeeeee",
      "ccdeeeeeeeeeeeee",
      "ccdeeeeeeeeeeeee",
      "ccdeeeeeeeeeeeee",
      "ccdeeeeeeeeeeeee",
      "ccdeeeeeeeeeeeee",
      "ccdeeeeeeeeeeeee",
      "ccdeeeeeeeeeeeee",
      "cbbbdddddddddddd",
      "cccccccccccccccc"
    ],
    [
      "ffgggggggggggggh",
      "ffgggggggggggggh",
      "ffgggggggggggggh",
      "ffggggggghgggggg",
      "ffiigjgggggggggg",
      "ffhiiigggggigghi",
      "ffiikiihgiihgigh",
      "ffgiiiiiihighiih",
      "ffggiiiiiiiiiihi",
      "ffgigiiiiiiiiggg",
      "ffggiiighiihgggg",
      "ffgggiiigggigggg",
      "ffgggggggggggggg",
      "ffgghggggggggggg",
      "fbbbgggggggggggg",
      "ffgggggggggggggg"
    ],
    [
      "lmnonp npnpnpq  ",
      "lrnpsnonnpnqqq  ",
      "lrps tnpqqqqu   ",
      "lrqqqqqqq  uuu  ",
      "lr   w      uuu ",
      "lm  x        u  ",
      "lr  y           ",
      "lr  A           ",
      "lr              ",
      "lr            u ",
      "lm            uu",
      "lr B           u",
      "lr        qqqqqu",
      "lr     qqqqCCCqq",
      "lbbbqqqqDDDD DDD",
      "lrDoE DE DEDEDDD"
    ],
    [
      "F IIIIIIIIIII   ",
      "F IIIIIIIII     ",
      "F IIIIII        ",
      "F            u  ",
      "F    w      uJ  ",
      "F   K           ",
      "F               ",
      "F   K           ",
      "F               ",
      "F               ",
      "F              J",
      "   l           u",
      "                ",
      "F          III  ",
      "Fbbb    IIIIIIII",
      "F IIIIIIIIIIIIII"
    ],
    [
      "                ",
      "                ",
      "   I            ",
      "                ",
      "    ww      Ju  ",
      "    K       L   ",
      "                ",
      "    K           ",
      "                ",
      "                ",
      "              Lu",
      "   M            ",
      "                ",
      "                ",
      " bbb            ",
      "                "
    ]
  ]
}