{
  "name": "multi_verticalschool_8_floor24",
  "refpalette": "deceasedcraft:multi_verticalschool_8/multi_verticalschool_8_floor24_palette",
  "xsize": 16,
  "zsize": 16,
  "slices": [
    [
      "                ",
      "                ",
      "                ",
      "   a b          ",
      "  acaca      d  ",
      "  aae       df  ",
      "                ",
      "    e           ",
      "                ",
      "               g",
      "              fd",
      "   a            ",
      "                ",
      "                ",
      " hhh            ",
      "     ii         "
    ],
    [
      "                ",
      "    aa          ",
      "    aca         ",
      "     a          ",
      "   a c       f  ",
      "   abaa      fd ",
      "    b        g  ",
      "   aba          ",
      "    a           ",
      "              ff",
      "              d ",
      "                ",
      "                ",
      "                ",
      " hhh            ",
      "     iii        "
    ],
    [
      "                ",
      "                ",
      "     a          ",
      "    aaa         ",
      "    acca        ",
      "    aaaa     d  ",
      "    aa       ff ",
      "  aaa         fd",
      "  aca         fd",
      "   a          d ",
      "                ",
      "                ",
      "                ",
      "                ",
      " hhh            ",
      "      i         "
    ],
    [
      "                ",
      "                ",
      "                ",
      "    aa          ",
      "    aaa         ",
      "    aaa         ",
      "     a          ",
      "                ",
      "   a            ",
      "                ",
      "                ",
      "                ",
      "                ",
      "                ",
      " hhh            ",
      "                "
    ],
    [
      "                ",
      "                ",
      "                ",
      "                ",
      "    aa          ",
      "     a          ",
      "                ",
      "                ",
      "                ",
      "                ",
      "                ",
      "                ",
      "                ",
      "                ",
      " hhh            ",
      "                "
    ],
    [
      "jjjjjjjjjjjjjjjj",
      "jjjjjjjjjjjjjjjj",
      "jjjjjjjjjjjjjjjj",
      "jjjjjjjjjjjjjjjj",
      "jjjjjjjjjjjjjjjj",
      "jjjjjjjjjjjjjjjj",
      "jjjjjjjjjjjjjjjj",
      "jjjjjjjjjjjjjjjj",
      "jjjjjjjjjjjjjjjj",
      "jjjjjjjjjjjjjjjj",
      "jjjjjjjjjjjjjjjj",
      "jjjjjjjjjjjjjjjj",
      "jjjjjjjjjjjjjjjj",
      "jjjjjjjjjjjjjjjj",
      "jhhhjjjjjjjjjjjj",
      "kjjjjjjjjjjjjjjj"
    ]
  ]
}