{
  "name": "multi_verticalschool_8_floor19",
  "refpalette": "deceasedcraft:multi_verticalschool_8/multi_verticalschool_8_floor19_palette",
  "xsize": 16,
  "zsize": 16,
  "slices": [
    [
      " abbcbbbb ba    ",
      " d         d    ",
      " d         d    ",
      " a         a    ",
      " d         d    ",
      " d         d    ",
      " d         d    ",
      " d         d    ",
      " d         d    ",
      " d         d    ",
      " a         a    ",
      " d         d    ",
      " d         d    ",
      " a        ea    ",
      " fffaaaaaaaa    ",
      "                "
    ],
    [
      " a         a    ",
      " a         a    ",
      " a         a    ",
      " a         a    ",
      " a         a    ",
      " a         a    ",
      " a         a    ",
      " a         a    ",
      " a         a    ",
      " a         a    ",
      " a         a    ",
      " a         a    ",
      " a         a    ",
      " a        ga    ",
      " fffaaaaaaaa    ",
      "                "
    ],
    [
      "haiiiiiiiiia    ",
      "haiiiiiiiiia    ",
      "haijiijiijia    ",
      "haiiiiiiiiia    ",
      "haiiiiiiiiia    ",
      "haijiijiikia    ",
      "haiiiiiiiiia    ",
      "haiiiiiiiiia    ",
      "haijiijiikia    ",
      "haiiiiiiiiia    ",
      "haiiiiiiiiia    ",
      "haijiijiijia    ",
      "haiiiiiiiiia    ",
      "haiiiiiiiiia    ",
      "hfffaaaaaaaa    ",
      "hhhhhhhhhhhhhhhh"
    ],
    [
      "lmnnnnnnnnnmop  ",
      "lmnnnnnnnnnmop  ",
      "lmnnnnnnnnnmop  ",
      "lmnnnnnnnnnmop  ",
      "lmnnnnnnnnnmop  ",
      "lmnnnnnnnnnmop  ",
      "lmnnnnnnnnnmop  ",
      "lmnnnnnnnnnmop  ",
      "lmnnnnnnnnnmop  ",
      "lmnnnnnnnnnmop  ",
      "lmnnnnnnnnnmop  ",
      "lmnnnnnnnnnmop  ",
      "lmnnnnnnnnnmop  ",
      "lmnnnnnnnnnmoppp",
      "lfffmmmmmmmmoooo",
      "llllllllllllllll"
    ],
    [
      " mqqqqrqqrqm s  ",
      " m         t s  ",
      " m         u s  ",
      " mw ww ww wm s  ",
      " mx yA yA xm s  ",
      " m    !    m s  ",
      " mw ww ww wm s  ",
      " mx yA yA xm s  ",
      " m         m s  ",
      " mw ww ww wm s  ",
      " mx yA yA xm s  ",
      " m         B s  ",
      " m    C    D s  ",
      " mEEFFFFFIJm  KK",
      " fffmmmmmmmm    ",
      "           L    "
    ],
    [
      " aqqrqqqrqqa    ",
      " d         M    ",
      " d         N    ",
      " a         a    ",
      " dO P  QR Pd    ",
      " d         d    ",
      " d         d    ",
      " dS OP TO Ud    ",
      " d         d    ",
      " d         d    ",
      " aP VQ P  Qa    ",
      " d         W    ",
      " d         X    ",
      " a    Y  Z a    ",
      " fffaaaaaaaa    ",
      "                "
    ]
  ]
}