{
  "name": "multi_verticalschool_8_floor10",
  "refpalette": "deceasedcraft:multi_verticalschool_8/multi_verticalschool_8_floor10_palette",
  "xsize": 16,
  "zsize": 16,
  "slices": [
    [
      "  abc      d e  ",
      "   bcfgf f d e  ",
      "   bc      d    ",
      "   bc      d e  ",
      "   bc      dh i ",
      "   bcfgf f d e  ",
      "   bcj     d e  ",
      "   bc      d e  ",
      "   bc      dh i ",
      "   bcfgf f d e  ",
      "   bc      d k  ",
      "   bc      dlmn ",
      "   bcj     d o  ",
      "   bcfgf f d    ",
      " pppcj     dqrrr",
      " sdddddddddddddd"
    ],
    [
      "    abc   jdt tt",
      "     bcfgf dt tt",
      "     bcj   dtutt",
      "     bc    dt tt",
      "     bc    dt tt",
      "     bcfgf dt tt",
      "     bcj   dt tt",
      "     bc    dt tt",
      "     bc  j dt tt",
      "     bcfgf dt tt",
      "     bc    dt tt",
      "     bc    dtwtt",
      "     bc    dtttt",
      "     bcfgf dqttt",
      " ppp bc j  dxxxx",
      "   sdddddddddddd"
    ],
    [
      "      abcjjd y  ",
      "       bcfgd y  ",
      "       bcj d y  ",
      "       bc  d y  ",
      "       bc  d y  ",
      "       bcfgd y  ",
      "       bc  d y  ",
      "       bcj d y  ",
      "       bcj d y  ",
      "       bcfgd y  ",
      "       bcj d y  ",
      "       bc  d A  ",
      "       bc  d y  ",
      "       bcfgd yj ",
      " ppp   bc  d yj ",
      "     sdddddddddd"
    ],
    [
      "        abcccBCC",
      "         bcccBCC",
      "         bcccBCC",
      "         bcccBCC",
      "         bcccBCC",
      "         bcccBCC",
      "         bcccBCC",
      "         bcccBCC",
      "         bcccBCC",
      "         bcccBCC",
      "         bcccBCC",
      "         bcccBCC",
      "         bcccBCC",
      "         bcccBCC",
      " ppp     bcccBCC",
      "       sddddddCC"
    ],
    [
      "          a     ",
      "                ",
      "                ",
      "                ",
      "                ",
      "                ",
      "                ",
      "                ",
      "                ",
      "                ",
      "                ",
      "                ",
      "                ",
      "                ",
      " ppp            ",
      "         sdddd  "
    ],
    [
      "             D  ",
      "             D  ",
      "             D  ",
      "             D  ",
      "             D  ",
      "             D  ",
      "             D  ",
      "             D  ",
      "             D  ",
      "             D  ",
      "             D  ",
      "             D  ",
      "             D  ",
      "             D  ",
      " ppp         D  ",
      "           sdd  "
    ]
  ]
}