{
  "name": "multi_verticalschool_8_floor11",
  "refpalette": "deceasedcraft:multi_verticalschool_8/multi_verticalschool_8_floor11_palette",
  "xsize": 16,
  "zsize": 16,
  "slices": [
    [
      "             a  ",
      "             a  ",
      "             a  ",
      "             a  ",
      "             a  ",
      "             a  ",
      "             a  ",
      "             a  ",
      "             a  ",
      "             a  ",
      "             a  ",
      "             a  ",
      "             a  ",
      "             a  ",
      " bbb         a  ",
      "             c  "
    ],
    [
      "             a  ",
      "             a  ",
      "             a  ",
      "             a  ",
      "             a  ",
      "             a  ",
      "             a  ",
      "             a  ",
      "             a  ",
      "             a  ",
      "             a  ",
      "             a  ",
      "             a  ",
      "             a  ",
      " bbb         a  ",
      "             c  "
    ],
    [
      "             a  ",
      "             a  ",
      "             a  ",
      "             a  ",
      "             a  ",
      "             a  ",
      "             a  ",
      "             a  ",
      "             a  ",
      "             a  ",
      "             a  ",
      "             a  ",
      "             a  ",
      "             a  ",
      " bbb         a  ",
      "             c  "
    ],
    [
      "            de  ",
      "            de  ",
      "            de  ",
      "            de  ",
      "            de  ",
      "            de  ",
      "            de  ",
      "            de  ",
      "            de  ",
      "            de  ",
      "            de  ",
      "            de  ",
      "            de  ",
      "            de  ",
      " bbb        de  ",
      "            dc  "
    ],
    [
      " f         fghij",
      "            ghij",
      "            ghij",
      "            ghij",
      "            ghij",
      "            ghij",
      "            ghij",
      "            ghij",
      "            ghij",
      "            ghij",
      "            ghij",
      "            ghij",
      "            ghij",
      "            ghij",
      " bbb        ghij",
      "            ghij"
    ],
    [
      " k         klhmn",
      " f         flhmn",
      "            lhmn",
      "            lhmn",
      "            lhmn",
      "            lhmn",
      "            lhmn",
      "            lhmn",
      "            lhmn",
      "            lhmn",
      "            lhmn",
      "            lhmn",
      "            lhmn",
      "            lhmn",
      " bbb        lhmn",
      "            lhmn"
    ]
  ]
}