{
  "name": "multi_verticalschool_8_base1",
  "refpalette": "deceasedcraft:multi_verticalschool_8/multi_verticalschool_8_base1_palette",
  "xsize": 16,
  "zsize": 16,
  "slices": [
    [
      " a     b c a   d",
      "ef         gh da",
      " a         a dda",
      " a         adaa ",
      "aaaaaaaaaaaaa   ",
      "iiiiijjjklm     ",
      "iiiiijjjHno     ",
      "iiiiijjjHno     ",
      "iiiiijjjHno     ",
      "iiiiijjjHno     ",
      "iiiiijjjklm     ",
      "iiiiiaaapppqr   ",
      "iiiiisssttu     ",
      "iiiiisssttu     ",
      "iaaaisssttu     ",
      "iiiiisssttu     "
    ],
    [
      " a         a   d",
      " aw        a  da",
      " a         a dda",
      " a         adaa ",
      "aaaaaaaaaaaaa   ",
      "iijjjklm        ",
      "iijjjHno        ",
      "iijjjHno        ",
      "iijjjHno        ",
      "iijjjHno        ",
      "iijjjklm        ",
      "iiaaapppqr      ",
      "iisssttu        ",
      "iisssttu        ",
      "iaaasttu        ",
      "iisssttu        "
    ],
    [
      " a         a   d",
      " a         a  da",
      " a         a dda",
      " a         adaa ",
      "aaaaaaaaaaaaa   ",
      "jjklm           ",
      "jjHno           ",
      "jjHno           ",
      "jjHno           ",
      "jjHno           ",
      "jjklm           ",
      "aapppqr         ",
      "ssttu           ",
      "ssttu           ",
      "sxxxu           ",
      "ssttu           "
    ],
    [
      " a         a   d",
      " a         a  da",
      " a         a dda",
      " a y     y adaa ",
      "aaaaaaaaaaaaa   ",
      "lm              ",
      "no              ",
      "no              ",
      "no              ",
      "no              ",
      "lm              ",
      "ppqr            ",
      "tu              ",
      "tu              ",
      "txxx            ",
      "tu              "
    ],
    [
      " a        AaBBBd",
      " a        AaBBda",
      " a        AaBdda",
      "AAACAAAAACAadaa ",
      "aaaaaaaaaaaaa   ",
      "                ",
      "                ",
      "                ",
      "                ",
      "                ",
      "                ",
      "r               ",
      "                ",
      "                ",
      " xxxD           ",
      "                "
    ],
    [
      "EaEEEEEEEEEapppF",
      "EaEE!EEEIEEappFa",
      "EaEEEEEEEEEapFFa",
      "EaEEEEEEEEEaFaa ",
      "aaaaaaaaaaaaa   ",
      "                ",
      "                ",
      "                ",
      "                ",
      "                ",
      "                ",
      "                ",
      "                ",
      "                ",
      " xxxJ           ",
      "                "
    ]
  ]
}