{
  "name": "multi_verticalschool_8_floor25",
  "refpalette": "deceasedcraft:multi_verticalschool_8/multi_verticalschool_8_floor25_palette",
  "xsize": 16,
  "zsize": 16,
  "slices": [
    [
      "abcccccccccbdddd",
      "abcccccccccbdddd",
      "abcccccccccbdddd",
      "abcccccccccbdddd",
      "abcccccccccbdddd",
      "abcccccccccbdddd",
      "abcccccccccbdddd",
      "abcccccccccbdddd",
      "abcccccccccbdddd",
      "abcccccccccbdddd",
      "abcccccccccbdddd",
      "abcccccccccbdddd",
      "abcccccccccbdddd",
      "abcccccccccbdddd",
      "aeeebbbbbbbbdddd",
      "aaaaaaaaaaaaaaaa"
    ],
    [
      "fbghhhhhhi b    ",
      "fb j    k  l    ",
      "fbmm nnmm  o    ",
      "fbpq qrpq  b    ",
      "fbst uwst  b    ",
      "fbx   yx   b    ",
      "fb         b    ",
      "fb         b    ",
      "fbp  urpt  b    ",
      "fbst  ws   b    ",
      "fbxA AyxA  b    ",
      "fbBB CCBB  l    ",
      "fb         o    ",
      "fbDDEFDDEF b    ",
      "feeebbbbbbbbI  I",
      "JJJJJJJJJJJJJJJJ"
    ],
    [
      " KLML!LLNL K    ",
      " O         P    ",
      " O         Q    ",
      " KRS  TU   K    ",
      " OV   WX   O    ",
      " OR   Y    O    ",
      " O         O    ",
      " O         O    ",
      " O    Z0   O    ",
      " O    1    O    ",
      " K23  TR4  K    ",
      " O         P    ",
      " O         Q    ",
      " K 526 7 48K    ",
      " eeeKKKKKKKK    ",
      "                "
    ],
    [
      " K    9    K    ",
      " O         O    ",
      " O         O    ",
      " K         K    ",
      " O         O    ",
      " O         O    ",
      " O         O    ",
      " O         O    ",
      " O         O    ",
      " O         O    ",
      " K         K    ",
      " O         O    ",
      " O         O    ",
      " K    #   $K    ",
      " eeeKKKKKKKK    ",
      "                "
    ],
    [
      " K         K    ",
      " K         K    ",
      " K         K    ",
      " K         K    ",
      " K         K    ",
      " K         K    ",
      " K         K    ",
      " K         K    ",
      " K         K    ",
      " K         K    ",
      " K         K    ",
      " K         K    ",
      " K         K    ",
      " K        %K    ",
      " eeeKKKKKKKK    ",
      "                "
    ],
    [
      "^K&&&&&&&&&K****",
      "^K&&&&&&&&&K****",
      "^K&(&&(&&(&K****",
      "^K&&&&&&&&&K****",
      "^K&&&&&&&&&K*))*",
      "^K&(&&(&&(&K****",
      "^K&&&&&&&&&K****",
      "^K&&&&&&&&&K****",
      "^K&(&&(&&+&K****",
      "^K&&&&&&&&&K*))*",
      "^K&&&&&&&&&K****",
      "^K&(&&+&&(&K****",
      "^K&&&&&&&&&K****",
      "^K&&&&&&&&&K****",
      "^eeeKKKKKKKK----",
      "^^^^^^^^^^^^^^^^"
    ]
  ]
}