{
  "name": "multi_verticalschool_8_floor6",
  "refpalette": "deceasedcraft:multi_verticalschool_8/multi_verticalschool_8_floor6_palette",
  "xsize": 16,
  "zsize": 16,
  "slices": [
    [
      " abcbcbcbcbd  ae",
      " f         d  ae",
      " fg       hd  ae",
      " fg       hd  ae",
      " ai  jk lmmd  ae",
      " a      l  d  ae",
      " ai  jk lmmd  ae",
      " ai     l  d  ae",
      " a   jk lmmd  ae",
      " ai     l  d  ae",
      " adnnddddddd  ae",
      " f         d  ae",
      " f         n  ae",
      " f         n  ae",
      " ooodddddddd  ae",
      "  p    q      ae"
    ],
    [
      "rasssssssssdttae",
      "rasssssssssdttae",
      "rasssssssssdttae",
      "rasssssssssdttae",
      "rasssusssssdttae",
      "rasssusssssdttae",
      "rasssusssssdttae",
      "rasssusssssdttae",
      "rasssusssssdttae",
      "rasssusssssdttae",
      "raddddddddddttae",
      "rasssssssssdttae",
      "rasssssssssdttae",
      "rasssssssssdttae",
      "roooddddddddttae",
      "rtttttttttttttae"
    ],
    [
      "eeeeeeeeeeeeeeee",
      "eeeeeeeeeeeeeeee",
      "eeeeeeeeeeeeeeee",
      "eeeeeeeeeeeeeeee",
      "eeeeeeeeeeeeeeee",
      "eeeeeeeeeeeeeeee",
      "eeeeeeeeeeeeeeee",
      "eeeeeeeeeeeeeeee",
      "eeeeeeeeeeeeeeee",
      "eeeeeeeeeeeeeeee",
      "eeeeeeeeeeeeeeee",
      "eeeeeeeeeeeeeeee",
      "eeeeeeeeeeeeeeee",
      "eeeeeeeeeeeeeeee",
      "eoooeeeeeeeeeeee",
      "eeeeeeeeeeeeeeee"
    ],
    [
      "               w",
      "               w",
      "               w",
      "               w",
      "               w",
      "               w",
      "               w",
      "               w",
      "               w",
      "               w",
      "               w",
      "               w",
      "               w",
      "               w",
      " ooo           w",
      "               w"
    ],
    [
      "                ",
      "                ",
      "                ",
      "                ",
      "                ",
      "                ",
      "                ",
      "                ",
      "                ",
      "                ",
      "                ",
      "                ",
      "                ",
      "                ",
      " ooo            ",
      "                "
    ],
    [
      "                ",
      "                ",
      "                ",
      "                ",
      "                ",
      "                ",
      "                ",
      "                ",
      "                ",
      "                ",
      "                ",
      "                ",
      "                ",
      "                ",
      " ooo            ",
      "                "
    ]
  ]
}