{
  "name": "multi_verticalschool_8_floor5",
  "refpalette": "deceasedcraft:multi_verticalschool_8/multi_verticalschool_8_floor5_palette",
  "xsize": 16,
  "zsize": 16,
  "slices": [
    [
      "aaaaaaaaaaaaaabb",
      "aaaaaaaaaaaaaabb",
      "aaaaaaaaaaaaaabb",
      "aaaaaaaaaaaaaabb",
      "aaaaaaaaaaaaaabb",
      "aaaaaaaaaaaaaabb",
      "aaaaaaaaaaaaaabb",
      "aaaaaaaaaaaaaabb",
      "aaaaaaaaaaaaaabb",
      "aaaaaaaaaaaaaabb",
      "aaaaaaaaaaaaaabb",
      "aaaaaaaaaaaaaabb",
      "aaaaaaaaaaaaaabb",
      "aaaaaaaaaaaaaabb",
      "acccaaaaaaaaaabb",
      "aaaaaaaaaaaaaabb"
    ],
    [
      "defe          gb",
      "dfef          gb",
      "defeh      h  gb",
      "d       fij   gb",
      "d             gb",
      "d       fij   gb",
      "d   h      h  gb",
      "d       fij   gb",
      "d             gb",
      "d       fij   gb",
      "d   h      h  gb",
      "d             gb",
      "d             gb",
      "dk            gb",
      "dcccllllllllllgb",
      "              gb"
    ],
    [
      "dmnm          gb",
      "dnmnk         gb",
      "dmnmh      h  gb",
      "d i     nko   gb",
      "dii           gb",
      "d       n o   gb",
      "d   h     kh  gb",
      "d       n o   gb",
      "d             gb",
      "d       n o   gb",
      "d   h   k  h  gb",
      "dk            gb",
      "d             gb",
      "dk k       k  gb",
      "dcccllllllllllgb",
      "  k           gb"
    ],
    [
      "dgppppppppplaaab",
      "dgppppppppplaaab",
      "dgppppppppplaaab",
      "dgppppppppplaaab",
      "dgppppppppplaaab",
      "dgppppppppplaaab",
      "dgppppppppplaaab",
      "dgppppppppplaaab",
      "dgppppppppplaaab",
      "dgppppppppplaaab",
      "dglpplllllllaaab",
      "dgppppppppplaaab",
      "dgppppppppplaaab",
      "dgppppppppplaaab",
      "dcccllllllllaaab",
      "aaaaaaaaaaaaaaab"
    ],
    [
      " g q q q q l  gb",
      " g         l  gb",
      " gr       sl  gb",
      " gr       sl  gb",
      " gt  uw xyyl  gb",
      " gt  u  A Bl  gb",
      " gt  uw xyyl  gb",
      " gt  u  A Bl  gb",
      " gtC uw xyyl  gb",
      " gtD u  A Bl  gb",
      " glE lllllll  gb",
      " g!  uFIIIJl  gb",
      " gK           gb",
      " gL           gb",
      " cccllllllll  gb",
      "  M NOPPPPOQ  gb"
    ],
    [
      " gRqRqRqRqRS  gb",
      " g         S  gb",
      " g         S  gb",
      " g         S  gb",
      " g   T  xyyS  gb",
      " gU  T  V  S  gb",
      " g   T  xyyS  gb",
      " g   T  V  S  gb",
      " gW  T  xyyS  gb",
      " g   TX V  S  gb",
      " gS  SSSSSSS  gb",
      " gY  T     S  gb",
      " g            gb",
      " g  Z         gb",
      " cccSSSSSSSS  gb",
      "  0 121M1313  gb"
    ]
  ]
}