{
  "name": "multi_verticalschool_8_floor31",
  "refpalette": "deceasedcraft:multi_verticalschool_8/multi_verticalschool_8_floor31_palette",
  "xsize": 16,
  "zsize": 16,
  "slices": [
    [
      "                ",
      "                ",
      "                ",
      "                ",
      "                ",
      "                ",
      "  a             ",
      " ba             ",
      "  a             ",
      "                ",
      "                ",
      "                ",
      "                ",
      "                ",
      " ccc            ",
      "                "
    ],
    [
      "  d             ",
      "                ",
      "                ",
      "                ",
      "                ",
      "                ",
      "                ",
      " b              ",
      "                ",
      "                ",
      "                ",
      "                ",
      "                ",
      "       eeee     ",
      " ccc            ",
      "                "
    ],
    [
      "                ",
      "                ",
      "                ",
      "                ",
      "                ",
      "                ",
      "                ",
      " b              ",
      "                ",
      "                ",
      "                ",
      "                ",
      "                ",
      "       ffff     ",
      " ccc   g  g     ",
      "                "
    ],
    [
      "                ",
      "                ",
      "                ",
      "                ",
      "                ",
      "                ",
      "                ",
      " b              ",
      "                ",
      "                ",
      "                ",
      "                ",
      "                ",
      "       h  h     ",
      " ccc   i  i     ",
      "                "
    ],
    [
      "jkkkkkkkkkkkkkkk",
      "jkllllllllmmmmll",
      "jklnnnnnnnnnnnnn",
      "jklnnnnnnnnnnnnn",
      "jklnnnnnnnnnnnnn",
      "jklnnnnnnnnnnnnn",
      "jklnnnnnnnnnnnnn",
      "jolnnnnnnnnnnnnn",
      "jklnnnnnnnnnnnnn",
      "jklnnnnnnnnnnnnn",
      "jkmnnnnnnnnnnnnn",
      "jkmnnnnnnnnnnnnn",
      "jkmnnnnnnnnnnnnn",
      "jkmmmmllllmmmmll",
      "jccckkkokkokkkkk",
      "jjjjjjjjjjjjjjjj"
    ],
    [
      "pcqqqqqqqqqrssss",
      "pcssssssssssssss",
      "pcssssssssssssss",
      "pcssssssssssssss",
      "pcssssssssssssss",
      "pcssssssssssssss",
      "pcssssssssssssss",
      "pcssssssssssssss",
      "pcssssssssssssss",
      "pcssssssssssssss",
      "pcssssssssssssss",
      "pcssssssssssssss",
      "pcssssssssssssss",
      "pcssssssssssssss",
      "pccccccccccccccc",
      "pppppppppppppppp"
    ]
  ]
}