{
  "name": "multi_verticalschool_8_floor15",
  "refpalette": "deceasedcraft:multi_verticalschool_8/multi_verticalschool_8_floor15_palette",
  "xsize": 16,
  "zsize": 16,
  "slices": [
    [
      "abbbbbbbbbbbbbbb",
      "abbbbbbbbbbbbbbb",
      "abb             ",
      "abb             ",
      "abb             ",
      "abb             ",
      "abb             ",
      "abb             ",
      "abb             ",
      "abb             ",
      "abb             ",
      "abb             ",
      "abbbbbbbbbbbbbbb",
      "abbbbbbbbbbbbbbb",
      "acccaaaaaaaaaaaa",
      " aaaaaaaaaaaaaaa"
    ],
    [
      "adeeeeeeeeeeeeee",
      "adfggggggggggggg",
      "adgggggggggggggg",
      "adgggggggggggggg",
      "adgggggggggggggg",
      "adgggggggggggggg",
      "adgggggggggggggg",
      "adgggggggggggggg",
      "adgggggggggggggg",
      "adgggggggggggggg",
      "adgggggggggggggg",
      "adgggggggggggggg",
      "adhggggggggggggg",
      "adeeeeeeeeeeeeee",
      "acccaaaaaaaaaaaa",
      " aaaaaaaaaaaaaaa"
    ],
    [
      "aiiiiiiiiiiiiiii",
      "aiiiiiiiiiiiiiii",
      "aiiiiiiiiiiiiiii",
      "aiiiiiiiiiiiiiii",
      "aiiiiiiiiiiiiiii",
      "aiiiiiiiiiiiiiii",
      "aiiiiiiiiiiiiiii",
      "aiiiiiiiiiiiiiii",
      "aiiiiiiiiiiiiiii",
      "aiiiiiiiiiiiiiii",
      "aiiiiiiiiiiiiiii",
      "aiiiiiiiiiiiiiii",
      "aiiiiiiiiiiiiiii",
      "aiiiiiiiiiiiiiii",
      "accciiiiiiiiiiii",
      "jaaaaaaaaaaaaaaa"
    ],
    [
      "iklllllllllkiiim",
      "iklllllllllkiiim",
      "iklllllllllkiiim",
      "iklllllllllkiiim",
      "nkkkkkkkkkkkiiim",
      "nklllllllllkiiim",
      "nklllllllllkiiim",
      "nklllllllllkiiim",
      "nklllllllllkiiim",
      "nklllllllllkiiim",
      "nklllllllllkiiim",
      "nklllllllllkiiim",
      "nklllllllllkiiii",
      "nklllllllllkiiii",
      "nccckkkkkkkkiiii",
      "ooooooonoooooooo"
    ],
    [
      " kppppqrrstk  un",
      " w      xsyk  un",
      " A        Bk  un",
      " kC  DEDFBBk  un",
      "IkkAJkkkkkkk  un",
      "KkL  M MM Nk  un",
      "IkO       Pk  un",
      "KkQ  RST  Pk  un",
      "KkQ  UVO  Pk  un",
      "KkQ  UVO  Pk  un",
      "KkQ  UVO  Pk  un",
      "IkQ  WXY  Pk  un",
      "KkO       Pk   Z",
      "KkL       Nk    ",
      " ccckkkkkkkk    ",
      "                "
    ],
    [
      " 01111q  2t0   3",
      " 4        50    ",
      " 6         0   K",
      " 0    ED  B0   I",
      " 006700000008  3",
      " 0         0   9",
      " 0#       $%    ",
      " 0   ^&        K",
      " 0*   ()  +-   K",
      " 0*   (        9",
      " 0!   ()  []   {",
      " 0}  |          ",
      " 0;       :'    ",
      " 0         0    ",
      " ccc00000000    ",
      "                "
    ]
  ]
}