{
  "name": "multi_verticalschool_8_floor17",
  "refpalette": "deceasedcraft:multi_verticalschool_8/multi_verticalschool_8_floor17_palette",
  "xsize": 16,
  "zsize": 16,
  "slices": [
    [
      "ab  cccdeeeb    ",
      "ab  fcccfeeb    ",
      "ab    gch eb    ",
      "ab   g i   b    ",
      "ab         b    ",
      "ab         b    ",
      "ab         b    ",
      "ab         b    ",
      "ab         b    ",
      "abjjkjjjkjjb    ",
      "ab  j   j  b    ",
      "ab  j   j  b    ",
      "ab  jlllj  b    ",
      "abmnoccconpb    ",
      "aqqqbbbbbbbb    ",
      " aaaaaaaaaaaaaaa"
    ],
    [
      "ab  grccceeb    ",
      "ab    c   rb    ",
      "ab         b    ",
      "ab         b    ",
      "ab         b    ",
      "ab         b    ",
      "ab         b    ",
      "ab         b    ",
      "ab         b    ",
      "ab         b    ",
      "ab         b    ",
      "ab         b    ",
      "ab   sss   b    ",
      "ab  ottto  b    ",
      "aqqqbbbbbbbb    ",
      " aaaaaaaaaaaaaaa"
    ],
    [
      "ab    ufrgrb    ",
      "ab        rb    ",
      "ab         b    ",
      "ab         b    ",
      "ab         b    ",
      "ab         b    ",
      "ab         b    ",
      "ab         b    ",
      "ab         b    ",
      "ab         b    ",
      "ab         b    ",
      "ab         b    ",
      "ab         b    ",
      "abwwwwwwwwwb    ",
      "aqqqbbbbbbbb    ",
      "xaaaaaaaaaaaaaaa"
    ],
    [
      "yABBBBBBBBBACD  ",
      "yABBBBBBBBBACD  ",
      "yABBBBBBBBBACD  ",
      "yABBBBBBBBBACD  ",
      "yABBBBBBBBBACD  ",
      "yABBBBBBBBBACD  ",
      "yABBBBBBBBBACD  ",
      "yABBBBBBBBBACD  ",
      "yABBBBBBBBBACD  ",
      "yABBBBBBBBBACD  ",
      "yABBBBBBBBBACD  ",
      "yABBBBBBBBBACD  ",
      "yABBBBBBBBBACD  ",
      "yABBBBBBBBBACDDD",
      "yqqqAAAAAAAACCCC",
      "yyyyyyyyyyyyyyyy"
    ],
    [
      " AEFFEIFFFFA J  ",
      " A         K J  ",
      " A         L J  ",
      " AM MM MM MA J  ",
      " AN OP OP NA J  ",
      " A         A J  ",
      " AM MM MM MA J  ",
      " AN OP OP NA J  ",
      " A         A J  ",
      " AM MM MM MA J  ",
      " AN OP OP NA J  ",
      " A         K J  ",
      " A    Q    L J  ",
      " ARRSTTTTUVA  WW",
      " qqqAAAAAAAA    ",
      "           X    "
    ],
    [
      " bFFFFF FEFb    ",
      " Y         Z    ",
      " Y         0    ",
      " b         b    ",
      " Y     1   Y    ",
      " Y         Y    ",
      " Y         Y    ",
      " Y1        Y    ",
      " Y         Y    ",
      " Y         Y    ",
      " b  1     1b    ",
      " Y         Z    ",
      " Y         0    ",
      " b    2  1 b    ",
      " qqqbbbbbbbb    ",
      "                "
    ]
  ]
}