{
  "name": "multi_verticalschool_8_floor7",
  "refpalette": "deceasedcraft:multi_verticalschool_8/multi_verticalschool_8_floor7_palette",
  "xsize": 16,
  "zsize": 16,
  "slices": [
    [
      "                ",
      "                ",
      "                ",
      "                ",
      "                ",
      "                ",
      "                ",
      "                ",
      "                ",
      "                ",
      "                ",
      "                ",
      "                ",
      "                ",
      " aaa            ",
      "                "
    ],
    [
      "                ",
      "                ",
      "                ",
      "                ",
      "                ",
      "                ",
      "                ",
      "                ",
      "                ",
      "                ",
      "                ",
      "                ",
      "                ",
      "                ",
      " aaa            ",
      "                "
    ],
    [
      "bbbbbbbbbbbb    ",
      "bbbbbbbbbbbb    ",
      "bbbbbbbbbbbb    ",
      "bbbbbbbbbbbb    ",
      "bbbbbbbbbbbb    ",
      "bbbbbbbbbbbb    ",
      "bbbbbbbbbbbb    ",
      "bbbbbbbbbbbb    ",
      "bbbbbbbbbbbb    ",
      "bbbbbbbbbbbb    ",
      "bbbbbbbbbbbb    ",
      "bbbbbbbbbbbb    ",
      "bbbbbbbbbbbb    ",
      "bbbbbbbbbbbb    ",
      "baaabbbbbbbb    ",
      "bbbbbbbbbbbbbbbb"
    ],
    [
      "c     dddddceeee",
      "c     dddddceeee",
      "cf fgfdddddceeee",
      "c     dddddceeee",
      "c     dddddceeee",
      "c     dddddceeee",
      "c     dddddceeee",
      "cf fgfdddddceeee",
      "c     dddddceeee",
      "c     dddddceeee",
      "c     dddddceeee",
      "c     dfh fceeee",
      "cf fgfd h  ceeee",
      "c     d   hceeee",
      "caaa  dfhhfceeee",
      "iccccccccccccccc"
    ],
    [
      "c   dddj  kc   l",
      "c   dddj  m    l",
      "cfgfdddj  n    l",
      "c   ddd   kc   l",
      "c   ddd   kc   l",
      "c   ddd   kc   l",
      "c   ddd   kc   l",
      "cfgfddd   kc   l",
      "c   ddd   kc   l",
      "c   ddd   kc   l",
      "c   ddd   kc   l",
      "c   dddjoopc   l",
      "cfgfdddqpppc   l",
      "c   dddqpppc   l",
      "caaadddppppc   l",
      " cccccccccccc  c"
    ],
    [
      "c dddj    kc    ",
      "c dddj    r     ",
      "cfddds    t     ",
      "c ddd     kc    ",
      "c ddds    kc    ",
      "c ddd     kc    ",
      "c ddds    kc    ",
      "cfddd     kc    ",
      "c ddds    kc    ",
      "c ddd     kc    ",
      "c ddds    kc    ",
      "c ddd     kc    ",
      "cfddds uw kc    ",
      "c ddd  uxykc    ",
      "caaad  uABkc    ",
      " cccccccccccc  c"
    ]
  ]
}