{
  "name": "multi_verticalschool_8_floor22",
  "refpalette": "deceasedcraft:multi_verticalschool_8/multi_verticalschool_8_floor22_palette",
  "xsize": 16,
  "zsize": 16,
  "slices": [
    [
      "ab              ",
      "ac              ",
      "ac              ",
      "ab              ",
      "ac              ",
      "ac              ",
      "ab              ",
      "ac              ",
      "ac              ",
      "ab              ",
      "ac  dd          ",
      "ac  dd          ",
      "ab  dde         ",
      "abbbffbbgggggggg",
      "ahhhiiiiiiiiiiii",
      " aaaaaaaaaaaaaaa"
    ],
    [
      "ab              ",
      "ab              ",
      "ab              ",
      "ab              ",
      "ab              ",
      "ab              ",
      "ab              ",
      "ab              ",
      "ab              ",
      "ab              ",
      "abdd            ",
      "abdd            ",
      "abddj           ",
      "abffbbkkkkkkkkkk",
      "ahhhbbbbbbbbbbbb",
      "laaaaaaaaaaaaaaa"
    ],
    [
      "mn   opqr       ",
      "mn              ",
      "mn              ",
      "mn              ",
      "mn              ",
      "mn              ",
      "mn              ",
      "mn              ",
      "mn              ",
      "mn              ",
      "mn              ",
      "mn              ",
      "mne             ",
      "mmmmmmmmmmmmmmmm",
      "shhhmmmmmmmmmmmm",
      "mmmmmmmmmmmmmmmm"
    ],
    [
      " t   uwxy       ",
      "At              ",
      "At              ",
      " t              ",
      " t              ",
      " t              ",
      "At              ",
      "At              ",
      " t              ",
      " t              ",
      "                ",
      "                ",
      "                ",
      " ttttttttttttttt",
      "Bhhh CDEF  CDEF ",
      "                "
    ],
    [
      "     IJKL       ",
      "                ",
      "                ",
      "                ",
      "                ",
      "                ",
      "                ",
      "                ",
      "                ",
      "                ",
      "                ",
      "                ",
      "                ",
      "                ",
      "Mhhh N          ",
      "                "
    ],
    [
      "     OPQR       ",
      "                ",
      "                ",
      "                ",
      "                ",
      "                ",
      "                ",
      "                ",
      "                ",
      "                ",
      "                ",
      "                ",
      "                ",
      "                ",
      "Shhh            ",
      "                "
    ]
  ]
}