{
  "name": "multi_verticalschool_8_floor12",
  "refpalette": "deceasedcraft:multi_verticalschool_8/multi_verticalschool_8_floor12_palette",
  "xsize": 16,
  "zsize": 16,
  "slices": [
    [
      "             ab ",
      " c         c ab ",
      " d         d ab ",
      "             ab ",
      "             ab ",
      "             ab ",
      "             ab ",
      "             ab ",
      "             ab ",
      "             ab ",
      "             ab ",
      "             ab ",
      "             ab ",
      "             ab ",
      " eee         ab ",
      "             ab "
    ],
    [
      "              f ",
      "              f ",
      " c         c  f ",
      " d         d  f ",
      "              f ",
      "              f ",
      "              f ",
      "              f ",
      "              f ",
      "              f ",
      "              f ",
      "                ",
      "                ",
      "              f ",
      " eee          f ",
      "              f "
    ],
    [
      "                ",
      "                ",
      "                ",
      " c         c    ",
      " d         d    ",
      "                ",
      "                ",
      "                ",
      "                ",
      "                ",
      "                ",
      "                ",
      "                ",
      "                ",
      " eee            ",
      "                "
    ],
    [
      "gegggggggggegggh",
      "gegggggggggegggh",
      "gegggggggggegggh",
      "gegggggggggegggh",
      "gegggggggggegggh",
      "gegggggggggegggh",
      "gegggggggggegggh",
      "gegggggggggegggh",
      "gegggggggggegggh",
      "hhhhhhhhhhhhhhhh",
      "                ",
      "                ",
      "                ",
      "                ",
      " eee            ",
      "                "
    ],
    [
      "iiiiiiiiiiiiij a",
      "iiiiiiiiiiiiij a",
      "iiiiiiiiiiiiij a",
      "iiiiiiiiiiiiij a",
      "iiiiiiiiiiiiij a",
      "iiiiiiiiiiiiij a",
      "iiiiiiiiiiiiij a",
      "iiiiiiiiiiiiij a",
      "iiiiiiiiiiiiik a",
      "llllllllllllllla",
      "mmmmmmmmmmmmmmmm",
      "                ",
      "                ",
      "                ",
      " eee            ",
      "                "
    ],
    [
      "  nnnopqr       ",
      "          sj    ",
      "          sj    ",
      " t   u    sj    ",
      " w x y    sj    ",
      " w x y    sj !  ",
      " A   B    sj    ",
      "          sj    ",
      "                ",
      "lllllllllllllll ",
      "                ",
      "                ",
      "                ",
      "                ",
      " eee            ",
      "                "
    ]
  ]
}