{
  "name": "multi_verticalschool_8_floor29",
  "refpalette": "deceasedcraft:multi_verticalschool_8/multi_verticalschool_8_floor29_palette",
  "xsize": 16,
  "zsize": 16,
  "slices": [
    [
      "abcccccccccbdddd",
      "abcccccccccbdddd",
      "abcccccccccbdddd",
      "abcccccccccbdddd",
      "abcccccccccbdddd",
      "abcccccccccbdddd",
      "abcccccccccbdddd",
      "abcccccccccbdddd",
      "abcccccccccbdddd",
      "abcccccccccbdddd",
      "abcccccccccbdddd",
      "abcccccccccbdddd",
      "abcccccccccbdddd",
      "abcccccccccbdddd",
      "aeeebbbbbbbbdddd",
      "aaaaaaaaaaaaaaaa"
    ],
    [
      "fbghhhhhhi b    ",
      "fb         j    ",
      "fbkk llkk  m    ",
      "fbno opno  b    ",
      "fbqr stqr  b    ",
      "fbu   wu   b    ",
      "fb         b    ",
      "fb         b    ",
      "fbn  spn   b    ",
      "fbqr  tqr  b    ",
      "fbux xwux  b    ",
      "fbyy AAyy  j    ",
      "fb         m    ",
      "fbBCDEBBDE b    ",
      "feeebbbbbbbbF  F",
      "IIIIIIIIIIIIIIII"
    ],
    [
      " JKKKKKKKK J    ",
      " L         M    ",
      " L         N    ",
      " J   OO    J    ",
      " L    PQ   L    ",
      " L     R   L    ",
      " L         L    ",
      " L         L    ",
      " LS   T    L    ",
      " LU   VQ   L    ",
      " JWX  Y Z  J    ",
      " L         M    ",
      " L         N    ",
      " J 01Z  Z23J    ",
      " eeeJJJJJJJJ    ",
      "                "
    ],
    [
      " J 4       J    ",
      " L         L    ",
      " L         L    ",
      " J         J    ",
      " L         L    ",
      " L         L    ",
      " L         L    ",
      " L         L    ",
      " L         L    ",
      " L         L    ",
      " J         J    ",
      " L         L    ",
      " L         L    ",
      " J    5   6J    ",
      " eeeJJJJJJJJ    ",
      "                "
    ],
    [
      " J         J    ",
      " J         J    ",
      " J         J    ",
      " J         J    ",
      " J         J    ",
      " J         J    ",
      " J         J    ",
      " J         J    ",
      " J         J    ",
      " J         J    ",
      " J         J    ",
      " J         J    ",
      " J         J    ",
      " J        7J    ",
      " eeeJJJJJJJJ    ",
      "                "
    ],
    [
      "8J999999999J####",
      "8J999999999J####",
      "8J9$99$99$9J####",
      "8J999999999J####",
      "8J999999999J#%%#",
      "8J9$99^99^9J####",
      "8J999999999J####",
      "8J999999999J####",
      "8J9$99^99$9J####",
      "8J999999999J#%%#",
      "8J999999999J####",
      "8J9^99$99$9J####",
      "8J999999999J####",
      "8J999999999J####",
      "8eeeJJJJJJJJ&&&&",
      "8888888888888888"
    ]
  ]
}