{
  "name": "multi_verticalschool_8_floor20",
  "refpalette": "deceasedcraft:multi_verticalschool_8/multi_verticalschool_8_floor20_palette",
  "xsize": 16,
  "zsize": 16,
  "slices": [
    [
      " a bbbbb bba    ",
      " c         c    ",
      " c         c    ",
      " a         a    ",
      " c         c    ",
      " c         c    ",
      " c         c    ",
      " c         c    ",
      " c         c    ",
      " c         c    ",
      " a         a    ",
      " c         c    ",
      " c         c    ",
      " ad       ea    ",
      " fffaaaaaaaa    ",
      "                "
    ],
    [
      " a         a    ",
      " a         a    ",
      " a         a    ",
      " a         a    ",
      " a         a    ",
      " a         a    ",
      " a         a    ",
      " a         a    ",
      " a         a    ",
      " a         a    ",
      " a         a    ",
      " a         a    ",
      " a         a    ",
      " a        ga    ",
      " fffaaaaaaaa    ",
      "                "
    ],
    [
      "haiiiiiiiiia    ",
      "haiiiiiiiiia    ",
      "haijiijiijia    ",
      "haiiiiiiiiia    ",
      "haiiiiiiiiia    ",
      "haijiijiijia    ",
      "haiiiiiiiiia    ",
      "haiiiiiiiiia    ",
      "haijiijiijia    ",
      "haiiiiiiiiia    ",
      "haiiiiiiiiia    ",
      "haijiikiijia    ",
      "haiiiiiiiiia    ",
      "haiiiiiiiiia    ",
      "hfffaaaaaaaa    ",
      "hhhhhhhhhhhhhhhh"
    ],
    [
      "lmnnnnnnnnnmop  ",
      "lmnnnnnnnnnmop  ",
      "lmnnnnnnnnnmop  ",
      "lmnnnnnnnnnmop  ",
      "lmnnnnnnnnnmop  ",
      "lmnnnnnnnnnmop  ",
      "lmnnnnnnnnnmop  ",
      "lmnnnnnnnnnmop  ",
      "lmnnnnnnnnnmop  ",
      "lmnnnnnnnnnmop  ",
      "lmnnnnnnnnnmop  ",
      "lmnnnnnnnnnmop  ",
      "lmnnnnnnnnnmop  ",
      "lmnnnnnnnnnmoppp",
      "lfffmmmmmmmmoooo",
      "llllllllllllllll"
    ],
    [
      " mqqqrqqqrqm s  ",
      " m         t s  ",
      " m         u s  ",
      " mw ww ww wm s  ",
      " mx yA yA xm s  ",
      " m         m s  ",
      " mw ww ww wm s  ",
      " mx yA yA xm s  ",
      " m         m s  ",
      " mw ww ww wm s  ",
      " mx yA yA xm s  ",
      " m         t s  ",
      " m    B    u s  ",
      " mCCDDDDDEFm  II",
      " fffmmmmmmmm    ",
      "           J    "
    ],
    [
      " aqrqqrqqqqa    ",
      " c         K    ",
      " c         L    ",
      " a         a    ",
      " cM  N    Mc    ",
      " c         c    ",
      " c         c    ",
      " cN OM NN Oc    ",
      " c         c    ",
      " c         c    ",
      " aM N   M Na    ",
      " c         K    ",
      " c         L    ",
      " a    P  QRa    ",
      " fffaaaaaaaa    ",
      "                "
    ]
  ]
}