{
  "name": "multi_verticalschool_8_base2",
  "refpalette": "deceasedcraft:multi_verticalschool_8/multi_verticalschool_8_base2_palette",
  "xsize": 16,
  "zsize": 16,
  "slices": [
    [
      "vvvvvvvvvvvvvvvv",
      "vvvvvvvvvvvvvvvv",
      "vvvvvvvvvvvvvvvv",
      "vvvvvvvvvvvvvvvv",
      "vvvvvvvvvvvvvvvv",
      "vvvvvvvvvvvvvvvv",
      "vvvvvvvvvvvvvvvv",
      "vvvvvvvvvvvvvvvv",
      "vvvvvvvvvvvvvvvv",
      "vvvvvvvvvvvvvvvv",
      "vvvvvvvvvvvvvvvv",
      "vvvvvvvvvvvvvvvv",
      "vvvvvvvvvvvvvvvv",
      "vvvvvvvvvvvvvvvv",
      "vvvvvvvvvvvvvvvv",
      "vvvvvvvvvvvvvvvv"
    ],
    [
      "aaaaaaaaaaaaaaaa",
      "aaaaaaaaaaaaaaaa",
      "aaaaaaaaaaaaaaaa",
      "aaaaaaaaaaaaaaaa",
      "aaaaaaaaaaaaaaaa",
      "aaaaaaaaaaaaaaaa",
      "aaaaaaaaaaaaaaaa",
      "aaaaaaaaaaaaaaaa",
      "aaaaaaaaaaaaaaaa",
      "aaaaaaaaaaaaaaaa",
      "aaaaaaaaaaaaaaaa",
      "aaaaaaaaaaaaaaaa",
      "aaaaaaaaaaaaaaaa",
      "aaaaaaaaaaaaaaaa",
      "abbbaaaaaaaaaaaa",
      "aaaaaaaaaaaaaaaa"
    ],
    [
      "aaaaaaaaaaaaaaaa",
      "aaaaaaaaaaaaaaaa",
      "aaaaaaaaaaaaaaaa",
      "aaaaaaaaaaaaaaaa",
      "aaaaaaaaaaaaaaaa",
      "aaaaaaaaaaaaaaaa",
      "aaaaaaaaaaaaaaaa",
      "aaaaaaaaaaaaaaaa",
      "aaaaaaaaaaaaaaaa",
      "aaaaaaaaaaaaaaaa",
      "aaaaaaaaaaaaaaaa",
      "aaaaaaaaaaaaaaaa",
      "aaaaaaaaaaaaaaaa",
      "aaaaaaaaaaaaaaaa",
      "abbbaaaaaaaaaaaa",
      "aaaaaaaaaaaaaaaa"
    ],
    [
      "cbcccccccccbddde",
      "cbcccccccccbddeb",
      "cbcccccccccbdeeb",
      "cbcccccccccbebbf",
      "bbbbbbbbbbbbbaff",
      "aaaaaaaaaaaaaaff",
      "aaaaaaaaaaaaaaff",
      "aaaaaaaaaaaaaaff",
      "aaaaaaaaaaaaaaff",
      "aaaaaaaaaaaaaaff",
      "aaaaaaaaaaaaaaff",
      "aaaaaaaaaaaaaaff",
      "aaaaaaaaaaaaaabf",
      "aaaaaaaaaaaaaagb",
      "abbbaaaaaaaaaagb",
      "aaaaaaaaaaaaaagb"
    ],
    [
      " b         b   e",
      " h         i  eb",
      " b         b eeb",
      "jbkkkl mnmobebbp",
      "bbbbbbbbbbbbbfqr",
      "aaaaaaaaaaafffHr",
      "aaaaaaaaaaafffHr",
      "aaaaaaaaaaafffHr",
      "aaaaaaaaaaafffHr",
      "aaaaaaaaaaafffHr",
      "aaaaaaaaaaafffHr",
      "aaaaaaaaaaabbfqr",
      "aaaaaaaaaaaggbsp",
      "aaaaaaaaaaagggts",
      "abbbaaaaaaagggts",
      "aaaaaaaaaaagggts"
    ],
    [
      " b         b   u",
      " w         x  ub",
      " b         b uub",
      " byAB  mCAmbubb ",
      "bbbbbbbbbbbbbD  ",
      "aaaaaaaafffqpE  ",
      "aaaaaaaafffHrE  ",
      "aaaaaaaafffHrE  ",
      "aaaaaaaafffHrE  ",
      "aaaaaaaafffHrE  ",
      "aaaaaaaafffqpE  ",
      "aaaaaaaabbbssD  ",
      "aaaaaaaagggttsF ",
      "aaaaaaaagggttI J",
      "abbbaaaagggttI J",
      "aaaaaaaagggttI J"
    ]
  ]
}