{
  "name": "multi_verticalschool_8_floor13",
  "refpalette": "deceasedcraft:multi_verticalschool_8/multi_verticalschool_8_floor13_palette",
  "xsize": 16,
  "zsize": 16,
  "slices": [
    [
      "                ",
      "                ",
      "                ",
      "                ",
      "                ",
      "                ",
      "                ",
      "                ",
      "                ",
      "                ",
      "                ",
      "                ",
      "                ",
      "                ",
      " aaa            ",
      "                "
    ],
    [
      "                ",
      "                ",
      "                ",
      "                ",
      "                ",
      "                ",
      "                ",
      "                ",
      "                ",
      "                ",
      "                ",
      "                ",
      "                ",
      "                ",
      " aaa            ",
      "                "
    ],
    [
      "bbbbbbbbbbbbbbbb",
      "bbbbbbbbbbbbbbbb",
      "bbbbbbbbbbbbbbbb",
      "bbbbbbbbbbbbbbbb",
      "bbbbbbbbbbbbbbbb",
      "bbbbbbbbbbbbbbbb",
      "bbbbbbbbbbbbbbbb",
      "bbbbbbbbbbbbbbbb",
      "bbbbbbbbbbbbbbbb",
      "bbbbbbbbbbbbbbbb",
      "bbbbbbbbbbbbbbbb",
      "bbbbbbbbbbbbbbbb",
      "bbbbbbbbbbbbbbbb",
      "bbbbbbbbbbbbbbbb",
      "baaabbbbbbbbbbbb",
      "bbbbbbbbbbbbbbbb"
    ],
    [
      "ccccccdddedddddd",
      "ccccccdddddddddd",
      "ccccccdddddddddd",
      "ccccccdddddddddd",
      "ccccccdddddddddd",
      "ccccccdddddddddd",
      "ccccccdddddddddd",
      "ccccccdddddddddd",
      "ccccccdddddddddd",
      "ccccccdddddddddd",
      "ccccccdddddddddd",
      "ccccccdddddddddd",
      "ccccccdddddddddd",
      "ccccccdddedddddd",
      "faaaffffffffffff",
      "dddddddddddddddd"
    ],
    [
      "g h ee  ij      ",
      "k   le   mn     ",
      "g   oe   pppppp ",
      "g  qoe   pppppp ",
      "g   oe          ",
      "g   oe   pppppp ",
      "g   oe   pppppp ",
      "g   oe   pppppp ",
      "g   oe   pppppp ",
      "g  roe          ",
      "g   oe   pppppp ",
      "g   oe   pppppp ",
      "s   te   uw     ",
      "g x !ey ij      ",
      "faaafffffffffffA",
      "                "
    ],
    [
      "g B Ce ij       ",
      "D   Ee  mn      ",
      "g    @          ",
      "g    @          ",
      "g   F@          ",
      "g    @          ",
      "g    @          ",
      "g   I@          ",
      "g    @          ",
      "g   F@          ",
      "g    @          ",
      "g    @          ",
      "J   Ee  uw      ",
      "g K Le ij       ",
      "faaafffffffffffM",
      "                "
    ]
  ]
}