{
  "name": "multi_verticalschool_8_floor21",
  "refpalette": "deceasedcraft:multi_verticalschool_8/multi_verticalschool_8_floor21_palette",
  "xsize": 16,
  "zsize": 16,
  "slices": [
    [
      " abbb !bb ba    ",
      " c         c    ",
      " c         c    ",
      " a         a    ",
      " c         c    ",
      " c         c    ",
      " c         c    ",
      " c         c    ",
      " c         c    ",
      " c         c    ",
      " a         a    ",
      " c         c    ",
      " c         c    ",
      " a        da    ",
      " eeeaaaaaaaa    ",
      "                "
    ],
    [
      " a         a    ",
      " a         a    ",
      " a         a    ",
      " a         a    ",
      " a         a    ",
      " a         a    ",
      " a         a    ",
      " a         a    ",
      " a         a    ",
      " a         a    ",
      " a         a    ",
      " a         a    ",
      " a         a    ",
      " a        fa    ",
      " eeeaaaaaaaa    ",
      "                "
    ],
    [
      "gahhhhhhhhhaiiii",
      "gahhhhhhhhhaiiii",
      "gahjhhjhhjhaiiii",
      "gahhhhhhhhhaiiii",
      "gahhhhhhhhhaiiii",
      "gahjhhjhhjhaiiii",
      "gahhhhhhhhhaiiii",
      "gahhhhhhhhhaiiii",
      "gahkhhkhhjhaiiii",
      "gahhhhhhhhhaiiii",
      "gahhhhhhhhhaiiii",
      "gahkhhjhhkhaiiii",
      "gahhhhhhhhhaiiii",
      "gahhhhhhhhhaiiii",
      "geeeaaaaaaaallll",
      "gggggggggggggggg"
    ],
    [
      "mnnnnnnnnnnnnnnn",
      "mnnnnnnnnnnnnnnn",
      "mnnnnnnnnnnnnnnn",
      "mnnnnnnnnnnnnnnn",
      "mnnnnnnnnnnnnnnn",
      "mnnnnnnnnnnnnnnn",
      "mnnnnnnnnnnnnnnn",
      "mnnnnnnnnnnnnnnn",
      "mnnnnnnnnnnnnnnn",
      "mnnnnnnnnnnnnnnn",
      "mnnnnnnnnnnnnnnn",
      "mnnnnnnnnnnnnnnn",
      "mnnnnnnnnnnnnnnn",
      "mnnnnnnnnnnnnnnn",
      "meeemmmmmmmmmmmm",
      "mmmmmmmmmmmmmmmm"
    ],
    [
      "op              ",
      "oq              ",
      "oq  r     r     ",
      "opr sr   rs r  r",
      "oq  r  r  r     ",
      "oq           r  ",
      "op    rsr   rsr ",
      "oq     r     r  ",
      "oq              ",
      "op            r ",
      "oq      tt      ",
      "oq      tt      ",
      "op      ttu     ",
      "opppppppwwppxxxx",
      "oeeeyyyyyyyyyyyy",
      "Aooooooooooooooo"
    ],
    [
      "op              ",
      "o!              ",
      "oB              ",
      "op        C     ",
      "oD              ",
      "oC              ",
      "op     E        ",
      "oF              ",
      "oI              ",
      "op              ",
      "oJ    tt        ",
      "oK    tt        ",
      "op    ttu       ",
      "opppppwwppxxxxxx",
      "oeeeyyyyyyyyyyyy",
      " ooooooooooooooo"
    ]
  ]
}