{
  "name": "multi_verticalschool_8_floor9",
  "refpalette": "deceasedcraft:multi_verticalschool_8/multi_verticalschool_8_floor9_palette",
  "xsize": 16,
  "zsize": 16,
  "slices": [
    [
      "abbbccccccca    ",
      "abbbccccccca    ",
      "abbbccccccca    ",
      "abbbccccccca    ",
      "abbbccccccca    ",
      "abbbccccccca    ",
      "abbbccccccca    ",
      "abbbccccccca    ",
      "abbbccccccca    ",
      "abbbccccccca    ",
      "abbbccccccca    ",
      "abbbccccccca    ",
      "abbbccccccca    ",
      "abbbccccccca    ",
      "adddcccccccaeeee",
      "caaaaaaaaaaaaaaa"
    ],
    [
      "afff      ga    ",
      "afhf      ia    ",
      "afff      ia    ",
      "afhf      ia    ",
      "afff      ia    ",
      "afhf     jia    ",
      "afff      ia    ",
      "afhf      ia    ",
      "afff      ia    ",
      "afhf      ia    ",
      "afff      ga    ",
      "afhf       a    ",
      "afff      ka    ",
      "afhf      la    ",
      "adddmm   noaeeee",
      " aaaaaapaaaaaaaa"
    ],
    [
      "a        qra    ",
      "ast        a    ",
      "as        u@    ",
      "asw       x@    ",
      "as         @    ",
      "asy       A@    ",
      "as        B@    ",
      "asy        @    ",
      "as        u@    ",
      "as!        a    ",
      "as         a    ",
      "asC        a    ",
      "as         a    ",
      "asD        a    ",
      "addd E     aeeee",
      " aaaaaaFaaaaaaaa"
    ],
    [
      "a      I  Ja    ",
      "aK         a    ",
      "a          @    ",
      "a          @    ",
      "a          @    ",
      "aK         @    ",
      "a          @    ",
      "a          @    ",
      "a          @    ",
      "aL         a    ",
      "a         Ja    ",
      "a          a    ",
      "a          a    ",
      "aK         a    ",
      "adddM  N   aeeee",
      " aaaaaaaaaaaaaaa"
    ],
    [
      "aOPP      Ja    ",
      "aOPP       a    ",
      "aOPP       a    ",
      "aOPP       a    ",
      "aOPP       a    ",
      "aOPP       a    ",
      "aOPP       a    ",
      "aOPP       a    ",
      "aOPP       a    ",
      "aOPP       a    ",
      "aOPP      Ja    ",
      "aOPP       a    ",
      "aOPP       a    ",
      "aOPP       a    ",
      "addd       aeeee",
      "Qaaaaaaaaaaaaaaa"
    ],
    [
      "RRRRbbbbbbba    ",
      "RRRRbbbbbbba    ",
      "RRRRbbbbbbba    ",
      "RRRRbbbbbbba    ",
      "RRRRbbbbbbba    ",
      "RRRRbbbbbbba    ",
      "RRRRbbbbbbba    ",
      "RRRRbbbbbbba    ",
      "RRRRbbbbbbba    ",
      "RRRRbbbbbbba    ",
      "RRRRbbbbbbba    ",
      "RRRRbbbbbbba S  ",
      "RRRRbbbbbbba    ",
      "RRRRbbbbbbba    ",
      "Rdddbbbbbbbaeeee",
      "Raaaaaaaaaaaaaaa"
    ]
  ]
}