{
  "name": "multi_verticalschool_8_floor27",
  "refpalette": "deceasedcraft:multi_verticalschool_8/multi_verticalschool_8_floor27_palette",
  "xsize": 16,
  "zsize": 16,
  "slices": [
    [
      "abcccccccccbdddd",
      "abcccccccccbdddd",
      "abcccccccccbdddd",
      "abcccccccccbdddd",
      "abcccccccccbdddd",
      "abcccccccccbdddd",
      "abcccccccccbdddd",
      "abcccccccccbdddd",
      "abcccccccccbdddd",
      "abcccccccccbdddd",
      "abcccccccccbdddd",
      "abcccccccccbdddd",
      "abcccccccccbdddd",
      "abcccccccccbdddd",
      "aeeebbbbbbbbdddd",
      "aaaaaaaaaaaaaaaa"
    ],
    [
      "fbghhhhhhi b    ",
      "fb   j     k    ",
      "fbll mmll  n    ",
      "fbop pqop  b    ",
      "fbrs  tr   b    ",
      "fbu  wxus  b    ",
      "fb         b    ",
      "fb         b    ",
      "fbos  qos  b    ",
      "fbr  wtr   b    ",
      "fbuy yxuy  b    ",
      "fbAA BBAA  k    ",
      "fb  C      n    ",
      "fbDDEFIDEF b    ",
      "feeebbbbbbbbJ  J",
      "KKKKKKKKKKKKKKKK"
    ],
    [
      " LMNNONNNN L    ",
      " P         Q    ",
      " P         R    ",
      " LST UVWW  L    ",
      " PX    Y   P    ",
      " P!   Z0   P    ",
      " P         P    ",
      " P         P    ",
      " P0   12   P    ",
      " P3   Z4   P    ",
      " L35  V36  L    ",
      " P         Q    ",
      " P         R    ",
      " L  75!  89L    ",
      " eeeLLLLLLLL    ",
      "                "
    ],
    [
      " L  # $%   L    ",
      " P         P    ",
      " P         P    ",
      " L         L    ",
      " P         P    ",
      " P         P    ",
      " P         P    ",
      " P         P    ",
      " P         P    ",
      " P         P    ",
      " L         L    ",
      " P         P    ",
      " P         P    ",
      " L ^      &L    ",
      " eeeLLLLLLLL    ",
      "                "
    ],
    [
      " L         L    ",
      " L         L    ",
      " L         L    ",
      " L         L    ",
      " L         L    ",
      " L         L    ",
      " L         L    ",
      " L         L    ",
      " L         L    ",
      " L         L    ",
      " L         L    ",
      " L         L    ",
      " L         L    ",
      " L        *L    ",
      " eeeLLLLLLLL    ",
      "                "
    ],
    [
      "(L)))))))))L++++",
      "(L)))))))))L++++",
      "(L)-))-))-)L++++",
      "(L)))))))))L++++",
      "(L)))))))))L+[[+",
      "(L)-))-))-)L++++",
      "(L)))))))))L++++",
      "(L)))))))))L++++",
      "(L)-))-))-)L++++",
      "(L)))))))))L+]]+",
      "(L)))))))))L++++",
      "(L)-))-))-)L++++",
      "(L)))))))))L++++",
      "(L)))))))))L++++",
      "(eeeLLLLLLLL{{{{",
      "(((((((((((((((("
    ]
  ]
}