{
  "name": "multi_verticalschool_8_floor2",
  "refpalette": "deceasedcraft:multi_verticalschool_8/multi_verticalschool_8_floor2_palette",
  "xsize": 16,
  "zsize": 16,
  "slices": [
    [
      "                ",
      "                ",
      "                ",
      "                ",
      "                ",
      "                ",
      "                ",
      "                ",
      "                ",
      "                ",
      "                ",
      "                ",
      "                ",
      "                ",
      " aaa            ",
      "                "
    ],
    [
      "                ",
      "                ",
      "                ",
      "                ",
      "                ",
      "                ",
      "                ",
      "                ",
      "                ",
      "                ",
      "                ",
      "                ",
      "                ",
      "                ",
      " aaa            ",
      "                "
    ],
    [
      "bbbbbbbbbbbbbbbb",
      "bbbbbbbbbbbbbbbb",
      "bbbbbbbbbbbbbbbb",
      "bbbbbbbbbbbbbbbb",
      "bbbbbbbbbbbbbbbb",
      "bbbbbbbbbbbbbbbb",
      "bbbbbbbbbbbbbbbb",
      "bbbbbbbbbbbbbbbb",
      "bbbbbbbbbbbbbbbb",
      "bbbbbbbbbbbbbbbb",
      "bbbbbbbbbbbbbbbb",
      "bbbbbbbbbbbbbbbb",
      "bbbbbbbbbbbbbbbb",
      "bbbbbbbbbbbbbbbb",
      "baaabbbbbbbbbbbb",
      "cbbbbbbbbbbbbbcc"
    ],
    [
      "defffffffffedddd",
      "defffffffffedddd",
      "defffffffffedddd",
      "defffffffffedddd",
      "defffffffffedddd",
      "defffffffffedddd",
      "defffffffffedddd",
      "defffffffffedddd",
      "defffffffffedddd",
      "defffffffffedddd",
      "defffffffffedddd",
      "defffffffffedddd",
      "defffffffffedddd",
      "defffffffffedddd",
      "daaaeeeeeeeedddd",
      "dddddddddddddddd"
    ],
    [
      " ghijjjjjkhg    ",
      " g         g    ",
      " lm       nl    ",
      " g   ooo   g    ",
      " g  poqor  g    ",
      " g   oqo   gs   ",
      " g  poqor  gs   ",
      " g   oqo   gs   ",
      " g  poqor  gs   ",
      " g   oqo   gs   ",
      " g  poqor  g    ",
      " g   ooo   g    ",
      " t    u    t    ",
      " g         g    ",
      " aaagggggtgg    ",
      "                "
    ],
    [
      " gw       wg    ",
      " g         g    ",
      "  x       y     ",
      " g         g    ",
      " g         g    ",
      " g         g    ",
      " g         g    ",
      " g         g    ",
      " g         g    ",
      " g         g    ",
      " g         g    ",
      " g         g    ",
      " t         t    ",
      " g         g    ",
      " aaagggggtgg    ",
      "                "
    ]
  ]
}