{
  "name": "multi_verticalschool_8_floor16",
  "refpalette": "deceasedcraft:multi_verticalschool_8/multi_verticalschool_8_floor16_palette",
  "xsize": 16,
  "zsize": 16,
  "slices": [
    [
      " ab!b     ca    ",
      " a         a    ",
      " a         a    ",
      " a    d    a    ",
      " aaaaaaaaaaa    ",
      " ae        a   f",
      " ag        h    ",
      " ai        h    ",
      " ai        h    ",
      " aj        h   f",
      " ai        h    ",
      " ai        h    ",
      " ae        h    ",
      " ag        a    ",
      " kkkaaaaaaaa    ",
      "                "
    ],
    [
      " l         a    ",
      " l         a    ",
      " l         a    ",
      " l    d    a    ",
      " aaaaaaaaaaa    ",
      " lm        a   n",
      " lo        a    ",
      " l         a    ",
      " l         a    ",
      " ap        a   n",
      " l         a    ",
      " l         a    ",
      " l         a    ",
      " lo        a    ",
      " kkkaaaaaaaa    ",
      "                "
    ],
    [
      " a         a    ",
      " a         a    ",
      " a         a    ",
      " a         a    ",
      " aaaaaaaaaaa    ",
      " a         a   q",
      " a         a    ",
      " a         a    ",
      " a         a    ",
      " ap        a   n",
      " a         a    ",
      " a         a    ",
      " a         a    ",
      " a         a    ",
      " kkkaaaaaaaa    ",
      "                "
    ],
    [
      " a         a    ",
      " a         a    ",
      " a         a    ",
      " a         a    ",
      " aaaaaaaaaaa    ",
      " a         a    ",
      " a         a    ",
      " a         a    ",
      " a         a    ",
      " ap        a   q",
      " a         a    ",
      " a         a    ",
      " a         a    ",
      " a         a    ",
      " kkkaaaaaaaa    ",
      "r               "
    ],
    [
      "rasssssssssa    ",
      "rasssssssssa    ",
      "rasssssssssa    ",
      "rasssssssssa    ",
      "raaaaaaaaaaa    ",
      "rasssssssssa    ",
      "rasssssssssa    ",
      "rasstsssussa    ",
      "rasssssssssa    ",
      "rapssssssssa    ",
      "rasssssssssa    ",
      "rasstssstssa    ",
      "rasssssssssa    ",
      "rasssssssssa    ",
      "rkkkaaaaaaaa    ",
      "rrrrrrrrrrrrrrrr"
    ],
    [
      "waxxxxxxxxxa    ",
      "waxxxxxxxxxa    ",
      "waxxxxxxxxxa    ",
      "waxxxxxxxxxa    ",
      "waxxxxxxxxxa    ",
      "waxxxxxxxxxa    ",
      "waxxxxxxxxxa    ",
      "waxxxxxxxxxa    ",
      "waxxxxxxxxxa    ",
      "wapxxxxxxxxa    ",
      "waxxxxxxxxxa    ",
      "waxxxxxxxxxa    ",
      "waxxxxxxxxxa    ",
      "waxxxxxxxxxa    ",
      "wkkkaaaaaaaa    ",
      "ywwwwwwwwwwwwwww"
    ]
  ]
}