{
  "name": "multi_verticalschool_8_floor3",
  "refpalette": "deceasedcraft:multi_verticalschool_8/multi_verticalschool_8_floor3_palette",
  "xsize": 16,
  "zsize": 16,
  "slices": [
    [
      " ab ccccc ba    ",
      " a         a    ",
      " d         d    ",
      " a         a    ",
      " a         a    ",
      " a         a    ",
      " a         a    ",
      " a         a    ",
      " a         a    ",
      " a         a    ",
      " a         a    ",
      " a         a    ",
      " d         d    ",
      " a         a    ",
      " eeeaaaaadaa    ",
      "                "
    ],
    [
      " a  ccccc  a    ",
      " a         a    ",
      " d         d    ",
      " a         a    ",
      " a         a    ",
      " a         a    ",
      " a         a    ",
      " a         a    ",
      " a         a    ",
      " a         a    ",
      " a         a    ",
      " a         a    ",
      " d         d    ",
      " a         a    ",
      " eeeaaaaadaa    ",
      "                "
    ],
    [
      " a  ccccc  a    ",
      " a         a    ",
      " d         d    ",
      " a    f    a    ",
      " a         a    ",
      " a         a    ",
      " a         a    ",
      " a         a    ",
      " a         a    ",
      " a         a    ",
      " a         a    ",
      " a         a    ",
      " d         d    ",
      " a         a    ",
      " eeeaaaaadaa    ",
      "                "
    ],
    [
      " ghiiiiiiiig    ",
      " giiiiiiiiig    ",
      " giiiijiiiig    ",
      " giiiikiiiig    ",
      " giiiihiiiig    ",
      " giiiiiiiiig    ",
      " giiiiiiiiig    ",
      " giiiiiiiiig    ",
      " giiiiiiiiig    ",
      " giiiiiiiiig    ",
      " giiiiiiiiig    ",
      " giiiiiiiiig    ",
      " giiiiiiiiig    ",
      " gjiiiiiiiig    ",
      " eeegggggggg    ",
      "                "
    ],
    [
      "lgmmmmmmmmmgllll",
      "lgmmmmmmmmmgllll",
      "lgmmmmmmmmmgllll",
      "lgmmmmmmmmmgllll",
      "lgmmmmmmmmmgllln",
      "lgmmmmmmmmmgllll",
      "lgmmmmmmmmmgllll",
      "lgmmmmmmmmmgllll",
      "lgmmmmmmmmmgllll",
      "lgmmmmmmmmmgllln",
      "lgmmmmmmmmmgllll",
      "lgmmmmmmmmmgllll",
      "lgmmmmmmmmmgllll",
      "lgmmmmmmmmmgllll",
      "leeeggggggggllln",
      "llllllllllllllll"
    ],
    [
      "olppppppppplqqqq",
      "olppppppppplqqqq",
      "oqlpppppppplqqqq",
      "ooqlppppppplqqqo",
      "qooqlpppppplqqqo",
      "qoooolppppplqoqq",
      "qqooqolpppplqqqq",
      "qqooooqlppplqqoo",
      "qllqoooolpplqqqo",
      "lpplqqooqllqqqoo",
      "lppplooooqqqqqoo",
      "lpppplqooooqqooo",
      "lppppplqoooooooo",
      "qlppppplqoqooooq",
      "qeeeppplqqooooqq",
      "qqqllllqqooqqqqq"
    ]
  ]
}