{
  "name": "multi_nuclearpowerplant_41_ground",
  "refpalette": "deceasedcraft:multi_nuclearpowerplant_41/multi_nuclearpowerplant_41_ground_palette",
  "xsize": 16,
  "zsize": 16,
  "slices": [
    [
      "aaaaaabbbccccccz",
      "aaaaabbccccccczc",
      "aaabbbcccccczccz",
      "aabbccccccccczcc",
      "bbbccccccczzzccz",
      "bcccccccccczczzc",
      "ccccccczzczzzczc",
      "cccccccccczcczcz",
      "cccczczczzczzzcc",
      "cczcczzczzzczzzz",
      "ccczzzczzczzzczc",
      "zzczcczzzzzzczzz",
      "czzzzczzzzzzzzzc",
      "zzczzzzzzzzzzzzz",
      "zzzzzzzzzzzzzzcz",
      "zzzzczzzzzzzzzzz"
    ],
    [
      "zzzzzzzczd      ",
      "zzzzczzde       ",
      "zczzzzd         ",
      "zzzzfe          ",
      "zzzd       g    ",
      "zde          g  ",
      "e      g    g   ",
      "                ",
      "            g   ",
      "      g         ",
      "    g  gg g     ",
      "g            g  ",
      "      g  h  g   ",
      "    g   g g     ",
      " g        g     ",
      "       gg  gg  g"
    ],
    [
      "      iii       ",
      "  g  ii         ",
      "   iii          ",
      "  ii            ",
      "iii             ",
      "i               ",
      "                ",
      "                ",
      "                ",
      "                ",
      "                ",
      "                ",
      "                ",
      "                ",
      "                ",
      "                "
    ],
    [
      "      iii       ",
      "     ii         ",
      "   iii          ",
      "  ii            ",
      "iii             ",
      "i               ",
      "                ",
      "                ",
      "                ",
      "                ",
      "                ",
      "                ",
      "                ",
      "                ",
      "                ",
      "                "
    ],
    [
      "       jj       ",
      "      j         ",
      "    jj          ",
      "   j            ",
      " jj             ",
      "j               ",
      "                ",
      "                ",
      "                ",
      "                ",
      "                ",
      "                ",
      "                ",
      "                ",
      "                ",
      "                "
    ],
    [
      "                ",
      "                ",
      "                ",
      "                ",
      "                ",
      "                ",
      "                ",
      "                ",
      "                ",
      "                ",
      "                ",
      "                ",
      "                ",
      "                ",
      "                ",
      "                "
    ]
  ]
}