{
  "name": "multi_nuclearpowerplant_41_base9",
  "refpalette": "deceasedcraft:multi_nuclearpowerplant_41/multi_nuclearpowerplant_41_base9_palette",
  "xsize": 16,
  "zsize": 16,
  "slices": [
    [
      "                ",
      "                ",
      "                ",
      "                ",
      "                ",
      "                ",
      "a               ",
      "bac             ",
      "bba       deeed ",
      "bbba      fg  f ",
      "bbbbaa    fh  f ",
      "bbbbbbaaa fi jk ",
      "bbbbbbbbbafffffa",
      "bbbbbbbbbbbbbbbb",
      "bbbbbbbbbbbbbbbb",
      "vvvvvvvvvvvvvvvv"
    ],
    [
      "                ",
      "                ",
      "                ",
      "                ",
      "                ",
      "                ",
      "a               ",
      "bac             ",
      "bba       deeed ",
      "bbba      f   f ",
      "bbbbaa    f   f ",
      "bbbbbbaaa fl  f ",
      "bbbbbbbbbafffffa",
      "bbbbbbbbbbbbbbbb",
      "bbbbbbbbbbbbbbbb",
      "vvvvvvvvvvvvvvvv"
    ],
    [
      "                ",
      "                ",
      "                ",
      "                ",
      "                ",
      "                ",
      "a               ",
      "bac             ",
      "bba       dfffd ",
      "bbba      f m f ",
      "bbbbaa    f   f ",
      "bbbbbbaaa fnopf ",
      "bbbbbbbbbafffffa",
      "bbbbbbbbbbbbbbbb",
      "bbbbbbbbbbbbbbbb",
      "vvvvvvvvvvvvvvvv"
    ],
    [
      "            q   ",
      "            q   ",
      "            q   ",
      "            q   ",
      "            q   ",
      "            q   ",
      "a          rqr  ",
      "bac        rsr  ",
      "bba       dfffd ",
      "bbba      ftttf ",
      "bbbbaa    f   f ",
      "bbbbbbaaa f u f ",
      "bbbbbbbbbafffffa",
      "bbbbbbbbbbbbbbbb",
      "bbbbbbbbbbbbbbbb",
      "vvvvvvvvvvvvvvvv"
    ],
    [
      "    c       c   ",
      "    c       c   ",
      "    c       c   ",
      "    c       c   ",
      "    c       c   ",
      "    c      wcx  ",
      "a   c     wcccy ",
      "baccccccccccAccc",
      "bba       dfffd ",
      "bbba      ftttf ",
      "bbbbaa    f   f ",
      "bbbbbbaaa f u f ",
      "bbbbbbbbbafffffa",
      "bbbbbbbbbbbbbbbb",
      "bbbbbbbbbbbbbbbb",
      "vvvvvvvvvvvvvvvv"
    ],
    [
      "                ",
      "                ",
      "                ",
      "                ",
      "                ",
      "                ",
      "a          cBc  ",
      "bacB       BuB  ",
      "bba       dfffd ",
      "bbba      ftttf ",
      "bbbbaa    f   f ",
      "bbbbbbaaa f u f ",
      "bbbbbbbbbafffffa",
      "bbbbbbbbbbbbbbbb",
      "bbbbbbbbbbbbbbbb",
      "vvvvvvvvvvvvvvvv"
    ]
  ]
}