{
  "name": "multi_nuclearpowerplant_41_base11",
  "refpalette": "deceasedcraft:multi_nuclearpowerplant_41/multi_nuclearpowerplant_41_base11_palette",
  "xsize": 16,
  "zsize": 16,
  "slices": [
    [
      "aaaaaaaaaaaaaaaa",
      "aaaaaaaaaaaaaaaa",
      "baaaaaaaaaaaaabb",
      "bbbbbbbbbbbbbb==",
      "================",
      "================",
      "c===============",
      "dc==============",
      "ddc=============",
      "dddc============",
      "ddddcc==========",
      "ddddddccc=======",
      "dddddddddccccccc",
      "dddddddddddddddd",
      "dddddddddddddddd",
      "vvvvvvvvvvvvvvvv"
    ],
    [
      "aaaaaaaaaaaaaaaa",
      "aaaaaaaaaaaaaaaa",
      "baaaaaaaaaaaaabb",
      "bbbbbbbbbbbbbb==",
      "================",
      "================",
      "c===============",
      "dc==============",
      "ddc=============",
      "dddc============",
      "ddddcc==========",
      "ddddddccc=======",
      "dddddddddccccccc",
      "dddddddddddddddd",
      "dddddddddddddddd",
      "vvvvvvvvvvvvvvvv"
    ],
    [
      "aaaaaaaaaaaaaaaa",
      "aaaaaaaaaaaaaaaa",
      "baaaaaaaaaaaaabb",
      "bbbbbbbbbbbbbb==",
      "================",
      "================",
      "c===============",
      "dc==============",
      "ddc=============",
      "dddc============",
      "ddddcc==========",
      "ddddddccc=======",
      "dddddddddccccccc",
      "dddddddddddddddd",
      "dddddddddddddddd",
      "vvvvvvvvvvvvvvvv"
    ],
    [
      "aaaaaaaaaaaaaaaa",
      "aaaaaaaaaaaaaaaa",
      "baaaaaaaaaaaaabb",
      "bbbbbbbbbbbbbb==",
      "================",
      "================",
      "c===============",
      "dc==============",
      "ddc=============",
      "dddc============",
      "ddddcc==========",
      "ddddddccc=======",
      "dddddddddccccccc",
      "dddddddddddddddd",
      "dddddddddddddddd",
      "vvvvvvvvvvvvvvvv"
    ],
    [
      "aaaaaaaaaaaaaaaa",
      "aaaaaaaaaaaaaaaa",
      "baaaaaaaaaaaaabb",
      "bbbbbbbbbbbbbb==",
      "================",
      "================",
      "c===============",
      "dc==============",
      "ddc=============",
      "dddc============",
      "ddddcc==========",
      "ddddddccc=======",
      "dddddddddccccccc",
      "dddddddddddddddd",
      "dddddddddddddddd",
      "vvvvvvvvvvvvvvvv"
    ],
    [
      "aaaaaaaaaaaaaaaa",
      "aaaaaaaaaaaaaaaa",
      "baaaaaaaaaaaaabb",
      "bbbbbbbbbbbbbb==",
      "================",
      "================",
      "c===============",
      "dc==============",
      "ddc=============",
      "dddc============",
      "ddddcc==========",
      "ddddddccc=======",
      "dddddddddccccccc",
      "dddddddddddddddd",
      "dddddddddddddddd",
      "vvvvvvvvvvvvvvvv"
    ]
  ]
}