{
  "name": "multi_nuclearpowerplant_41_base6",
  "refpalette": "deceasedcraft:multi_nuclearpowerplant_41/multi_nuclearpowerplant_41_base6_palette",
  "xsize": 16,
  "zsize": 16,
  "slices": [
    [
      "aaaaaaaabaaaaaaa",
      "aaaaaaaaaaaaaaaa",
      "aaaaaaaaaaaaaaaa",
      "aaaaaaaaaaaaaaaa",
      "aaaaaaaaaaaaaaac",
      "cccccccccccccccc",
      "   d      e     ",
      "   f      g     ",
      "                ",
      "       h        ",
      "iiiiiiiiiiiiiiii",
      "================",
      "jjjjjjjjjjjjjjjj",
      "kkkkkkkkkkkkkkkk",
      "kkkkkkkkkkkkkkkk",
      "vvvvvvvvvvvvvvvv"
    ],
    [
      "aaaaaaaabaaaaaaa",
      "aaaaaaaaaaaaaaaa",
      "aaaaaaaaaaaaaaaa",
      "aaaaaaaaaaaaaaaa",
      "aaaaaaaaaaaaaaac",
      "cccccccccccccccc",
      "    d    e      ",
      "    f    g      ",
      "                ",
      "       h        ",
      "iiiiiiiiiiiiiiii",
      "================",
      "llllllllllllllll",
      "kkkkkkkkkkkkkkkk",
      "kkkkkkkkkkkkkkkk",
      "vvvvvvvvvvvvvvvv"
    ],
    [
      "aaaaaaaabmaaaaam",
      "aaaaaaaaamaaaaam",
      "aaaaaaaaamaaaaam",
      "aaaaaaaaamaaaaam",
      "aaaaaaaaamaaaaac",
      "cccccccccccccccc",
      "     dnne       ",
      "     fnng       ",
      "      nn        ",
      "      no        ",
      "iiiiiiiiiiiiiiii",
      "================",
      "llllllllllllllll",
      "kkkkkkkkkkkkkkkk",
      "kkkkkkkkkkkkkkkk",
      "vvvvvvvvvvvvvvvv"
    ],
    [
      "aaaaaaaabppppppp",
      "aaaaaaaaaaaaaaaa",
      "aaaaaaaaaaaaaaaa",
      "aaaaaaaaaaaaaaaa",
      "aaaaaaaaaaaaaaac",
      "cccccccccccccccc",
      "      qq        ",
      "                ",
      "     e r        ",
      "     gst        ",
      "iiiiiiiiiiiiiiii",
      "================",
      "llllllllllllllll",
      "kkkkkkkkkkkkkkkk",
      "kkkkkkkkkkkkkkkk",
      "vvvvvvvvvvvvvvvv"
    ],
    [
      "aaaaaaaabbbbbbbb",
      "aaaaaaaaaaaaaaaa",
      "aaaaaaaaaaaaaaaa",
      "aaaaaaaaaaaaaaaa",
      "aaaaaaaaaaaaaaac",
      "cccccccccccccccc",
      "                ",
      "                ",
      "    e           ",
      "    g           ",
      "iiiiiiiiiiiiiiii",
      "================",
      "llllllllllllllll",
      "kkkkkkkkkkkkkkkk",
      "kkkkkkkkkkkkkkkk",
      "vvvvvvvvvvvvvvvv"
    ],
    [
      "aaaaaaaauuuuuuuu",
      "aaaaaaaaaaaaaaaa",
      "aaaaaaaaaaaaaaaa",
      "aaaaaaaaaaaaaaaa",
      "aaaaaaaaaaaaaaac",
      "cccccccccccccccc",
      "                ",
      "                ",
      "   e            ",
      "   g            ",
      "iiiiiiiiiiiiiiii",
      "================",
      "llllllllllllllll",
      "kkkkkkkkkkkkkkkk",
      "kkkkkkkkkkkkkkkk",
      "vvvvvvvvvvvvvvvv"
    ]
  ]
}