{
  "name": "multi_nuclearpowerplant_41_base2",
  "refpalette": "deceasedcraft:multi_nuclearpowerplant_41/multi_nuclearpowerplant_41_base2_palette",
  "xsize": 16,
  "zsize": 16,
  "slices": [
    [
      "                ",
      "                ",
      "                ",
      "                ",
      "                ",
      "                ",
      "                ",
      "                ",
      "                ",
      "            a   ",
      "bbbbbbbbbbbbbbbb",
      "================",
      "cccccccccccccccc",
      "dddddddddddddddd",
      "dddddddddddddddd",
      "vvvvvvvvvvvvvvvv"
    ],
    [
      "        effghefg",
      "         i  h  i",
      "            h   ",
      "           ihi  ",
      "            h   ",
      "            h   ",
      "            j   ",
      "            k   ",
      "            k   ",
      "            k   ",
      "bbbbbbbbbbbbbbbb",
      "================",
      "cccccccccccccccc",
      "dddddddddddddddd",
      "dddddddddddddddd",
      "vvvvvvvvvvvvvvvv"
    ],
    [
      "       lk  mkn  ",
      "        lk  k  k",
      "         lk k kn",
      "          lkkko ",
      "           lko  ",
      "            k   ",
      "            k   ",
      "            p   ",
      "            q   ",
      "            q   ",
      "bbbbbbbbbbbbbbbb",
      "================",
      "cccccccccccccccc",
      "dddddddddddddddd",
      "dddddddddddddddd",
      "vvvvvvvvvvvvvvvv"
    ],
    [
      "                ",
      "                ",
      "                ",
      "                ",
      "                ",
      "            r   ",
      "            k   ",
      "                ",
      "                ",
      "ssssssssssssssss",
      "bbbbbbbbbbbbbbbb",
      "================",
      "cccccccccccccccc",
      "dddddddddddddddd",
      "dddddddddddddddd",
      "vvvvvvvvvvvvvvvv"
    ],
    [
      "                ",
      "                ",
      "                ",
      "                ",
      "                ",
      "                ",
      "            k   ",
      "                ",
      "tttttttttttttttt",
      "bbbbbbbbbbbbbbbb",
      "================",
      "uuuuuuuuuuuuuuuu",
      "cccccccccccccccc",
      "dddddddddddddddd",
      "dddddddddddddddd",
      "vvvvvvvvvvvvvvvv"
    ],
    [
      "bbbbbbbbbbbbbbbb",
      "bbbbbbbbbbbbbbbb",
      "bbbbbbbbbbbbbbbb",
      "bbbbbbbbbbbbbbbb",
      "bbbbbbbbbbbbbbbb",
      "bbbbbbbbbbbbbbbb",
      "bbbbbbbbbbbbbbbb",
      "bbbbbbbbbbbbbbbb",
      "bbbbbbbbbbbbbbbb",
      "================",
      "uuuuuuuuuuuuuuuu",
      "uuuuuuuuuuuuuuuu",
      "cccccccccccccccc",
      "dddddddddddddddd",
      "dddddddddddddddd",
      "vvvvvvvvvvvvvvvv"
    ]
  ]
}