{
  "name": "multi_nuclearpowerplant_41_base7",
  "refpalette": "deceasedcraft:multi_nuclearpowerplant_41/multi_nuclearpowerplant_41_base7_palette",
  "xsize": 16,
  "zsize": 16,
  "slices": [
    [
      "aaaaaaaa aaaaaaa",
      "aaaaaaaaaaaaaaaa",
      "aaaaaaaaaaaaaaaa",
      "aaaaaaaaaaaaaaaa",
      "aaaaaaaaaaaaaaab",
      "bbbbbbbbbbbbbbbb",
      "                ",
      "                ",
      "                ",
      "   c   d c     c",
      "eeeeeeeeeeeeeeee",
      "================",
      "ffffffffffffffff",
      "gggggggggggggggg",
      "gggggggggggggggg",
      "vvvvvvvvvvvvvvvv"
    ],
    [
      "aaaaaaaa@ahhhhha",
      "aaaaaaaaaaaaaaaa",
      "aaaaaaaaaaaaaaaa",
      "aaaaaaaaaaaaaaaa",
      "aaaaaaaaaaaaaaab",
      "bbbbbbbbbbbbbbbb",
      "               i",
      "               j",
      "                ",
      "       d        ",
      "eeeeeeeeeeeeeeee",
      "================",
      "ffffffffffffffff",
      "gggggggggggggggg",
      "gggggggggggggggg",
      "vvvvvvvvvvvvvvvv"
    ],
    [
      "kkkkkkkklkkkkkkk",
      "kkkkkkkkkkkkkkkk",
      "kkkkkkkkkkkkkkkk",
      "kkkkkkkkkkkkkkkk",
      "kkkkkkkkkkkkkkkb",
      "bbbbbbbbbbbbbbbb",
      "              i ",
      "              j ",
      "                ",
      "       d        ",
      "eeeeeeeeeeeeeeee",
      "================",
      "ffffffffffffffff",
      "gggggggggggggggg",
      "gggggggggggggggg",
      "vvvvvvvvvvvvvvvv"
    ],
    [
      "kkkkkkkklkkkkkkk",
      "kkkkkkkkkkkkkkkk",
      "kkkkkkkkkkkkkkkk",
      "kkkkkkkkkkkkkkkk",
      "kkkkkkkkkkkkkkkb",
      "bbbbbbbbbbbbbbbb",
      "m            i  ",
      "n            j  ",
      "                ",
      "       d        ",
      "eeeeeeeeeeeeeeee",
      "================",
      "ffffffffffffffff",
      "gggggggggggggggg",
      "gggggggggggggggg",
      "vvvvvvvvvvvvvvvv"
    ],
    [
      "kkkkkkkklkkkkkkk",
      "kkkkkkkkkkkkkkkk",
      "kkkkkkkkkkkkkkkk",
      "kkkkkkkkkkkkkkkk",
      "kkkkkkkkkkkkkkkb",
      "bbbbbbbbbbbbbbbb",
      " m          i   ",
      " n          j   ",
      "                ",
      "       d        ",
      "eeeeeeeeeeeeeeee",
      "================",
      "ffffffffffffffff",
      "gggggggggggggggg",
      "gggggggggggggggg",
      "vvvvvvvvvvvvvvvv"
    ],
    [
      "kkkkkkkklkkkkkkk",
      "kkkkkkkkkkkkkkkk",
      "kkkkkkkkkkkkkkkk",
      "kkkkkkkkkkkkkkkk",
      "kkkkkkkkkkkkkkkb",
      "bbbbbbbbbbbbbbbb",
      "  m        i    ",
      "  n        j    ",
      "                ",
      "       d        ",
      "eeeeeeeeeeeeeeee",
      "================",
      "ffffffffffffffff",
      "gggggggggggggggg",
      "gggggggggggggggg",
      "vvvvvvvvvvvvvvvv"
    ]
  ]
}