{
  "name": "multi_nuclearpowerplant_41_base5",
  "refpalette": "deceasedcraft:multi_nuclearpowerplant_41/multi_nuclearpowerplant_41_base5_palette",
  "xsize": 16,
  "zsize": 16,
  "slices": [
    [
      "aaaaaaaabccccccc",
      "dddddddaaadaaaaa",
      "aaaaaadaaadaaaaa",
      "aaaaaadddddaaaaa",
      "aaaaaaaaaaaaaaae",
      "eeeeeeeeeeeeeeee",
      "                ",
      "                ",
      "  f             ",
      "  g             ",
      "hhhhhhhhhhhhhhhh",
      "================",
      "iiiiiiiiiiiiiiii",
      "jjjjjjjjjjjjjjjj",
      "jjjjjjjjjjjjjjjj",
      "vvvvvvvvvvvvvvvv"
    ],
    [
      "kkkkkkkabclccccc",
      "aaaaaaamanamaaaa",
      "ooooopapkpamaaaa",
      "aaaaanaaaaamaaaa",
      "aaaaaaoooooaaaae",
      "eeeeeeeeeeeeeeee",
      "                ",
      "                ",
      " f              ",
      " g              ",
      "hhhhhhhhhhhhhhhh",
      "================",
      "iiiiiiiiiiiiiiii",
      "jjjjjjjjjjjjjjjj",
      "jjjjjjjjjjjjjjjj",
      "vvvvvvvvvvvvvvvv"
    ],
    [
      "aaaaaaaabccccccc",
      "qqqqqqqaaaqaaaaa",
      "aaaaaaqaaaqaaaaa",
      "aaaaaaqqqqqaaaaa",
      "aaaaaaaaaaaaaaae",
      "eeeeeeeeeeeeeeee",
      "                ",
      "                ",
      "f               ",
      "g               ",
      "hhhhhhhhhhhhhhhh",
      "================",
      "iiiiiiiiiiiiiiii",
      "jjjjjjjjjjjjjjjj",
      "jjjjjjjjjjjjjjjj",
      "vvvvvvvvvvvvvvvv"
    ],
    [
      "aaaaaaaabccccccc",
      "aaaaaaaaaaaaaaaa",
      "aaaaaaaaaaaaaaaa",
      "aaaaaaaaaaaaaaaa",
      "aaaaaaaaaaaaaaae",
      "eeeeeeeeeeeeeeee",
      "                ",
      "                ",
      "                ",
      "                ",
      "hhhhhhhhhhhhhhhh",
      "================",
      "iiiiiiiiiiiiiiii",
      "jjjjjjjjjjjjjjjj",
      "jjjjjjjjjjjjjjjj",
      "vvvvvvvvvvvvvvvv"
    ],
    [
      "aaaaaaaabccccccc",
      "aaaaaaaaaaaaaaaa",
      "aaaaaaaaaaaaaaaa",
      "aaaaaaaaaaaaaaaa",
      "aaaaaaaaaaaaaaae",
      "eeeeeeeeeeeeeeee",
      "                ",
      "                ",
      "                ",
      "                ",
      "hhhhhhhhhhhhhhhh",
      "================",
      "iiiiiiiiiiiiiiii",
      "jjjjjjjjjjjjjjjj",
      "jjjjjjjjjjjjjjjj",
      "vvvvvvvvvvvvvvvv"
    ],
    [
      "aaaaaaaabcrccccc",
      "aaaaaaaaaaaaaaaa",
      "aaaaaaaaaaaaaaaa",
      "aaaaaaaaaaaaaaaa",
      "aaaaaaaaaaaaaaae",
      "eeeeeeeeeeeeeeee",
      "                ",
      "                ",
      "                ",
      "                ",
      "hhhhhhhhhhhhhhhh",
      "================",
      "iiiiiiiiiiiiiiii",
      "jjjjjjjjjjjjjjjj",
      "jjjjjjjjjjjjjjjj",
      "vvvvvvvvvvvvvvvv"
    ]
  ]
}