{
  "name": "multi_nuclearpowerplant_41_base12",
  "refpalette": "deceasedcraft:multi_nuclearpowerplant_41/multi_nuclearpowerplant_41_base12_palette",
  "xsize": 16,
  "zsize": 16,
  "slices": [
    [
      "aaaaaaaaaaaaaaaa",
      "aaaaaaaaaaaaaaaa",
      "aaaaaaaaaaaaaaaa",
      "aaaaaaaaaaaaaaaa",
      "aaaaaaaaaaaaaaaa",
      "aaaaaaaaaaaaaaaa",
      "aaaaaaaaaaaaaaaa",
      "aaaaaaaaaaaaaaaa",
      "aaaaaaaaaaaaaaaa",
      "aaaaaaaaaaaaaaaa",
      "aaaaaaaaaaaaaaaa",
      "aaaaaaaaaaaaaaaa",
      "aaaaaaaaaaaaaaaa",
      "aaaaaaaaaaaaaaaa",
      "aaaaaaaaaaaaaaaa",
      "vvvvvvvvvvvvvvvv"
    ],
    [
      "bbbbbbbbbbbbbbbb",
      "bbbbbbbbbbbbbbbb",
      "bbbbbbbbbbbbbbbb",
      "bbbbbbbbbbbbbbbb",
      "bbbbbbbbbbbbbbbb",
      "bbbbbbbbbbbbbbbb",
      "bbbbbbbbbbbbbbbb",
      "abbbbbbbbbbbbbbb",
      "aabbbbbbbbbbbbbb",
      "aaabbbbbbbbbbbbb",
      "aaaabbbbbbbbbbbb",
      "aaaaaabbbbbbbbbb",
      "aaaaaaaaabbbbbbb",
      "aaaaaaaaaaaaaaaa",
      "aaaaaaaaaaaaaaaa",
      "vvvvvvvvvvvvvvvv"
    ],
    [
      "================",
      "================",
      "================",
      "================",
      "================",
      "================",
      "c===============",
      "ac==============",
      "aac=============",
      "aaac============",
      "aaaacc==========",
      "aaaaaaccc=======",
      "aaaaaaaaaccccccc",
      "aaaaaaaaaaaaaaaa",
      "aaaaaaaaaaaaaaaa",
      "vvvvvvvvvvvvvvvv"
    ],
    [
      "dddddddddddddddd",
      "dddddddddddddddd",
      "bdddddddddddddbb",
      "bbbbbbbbbbbbbb==",
      "================",
      "================",
      "e===============",
      "ae==============",
      "aae=============",
      "aaae============",
      "aaaaee==========",
      "aaaaaaeee=======",
      "aaaaaaaaaeeeeeee",
      "aaaaaaaaaaaaaaaa",
      "aaaaaaaaaaaaaaaa",
      "vvvvvvvvvvvvvvvv"
    ],
    [
      "ffffffffffffffff",
      "ffffffffffffffff",
      "bfffffffffffffbb",
      "bbbbbbbbbbbbbb==",
      "================",
      "================",
      "e===============",
      "ae==============",
      "aae=============",
      "aaae============",
      "aaaaee==========",
      "aaaaaaeee=======",
      "aaaaaaaaaeeeeeee",
      "aaaaaaaaaaaaaaaa",
      "aaaaaaaaaaaaaaaa",
      "vvvvvvvvvvvvvvvv"
    ],
    [
      "ffffffffffffffff",
      "ffffffffffffffff",
      "bfffffffffffffbb",
      "bbbbbbbbbbbbbb==",
      "================",
      "================",
      "e===============",
      "ae==============",
      "aae=============",
      "aaae============",
      "aaaaee==========",
      "aaaaaaeee=======",
      "aaaaaaaaaeeeeeee",
      "aaaaaaaaaaaaaaaa",
      "aaaaaaaaaaaaaaaa",
      "vvvvvvvvvvvvvvvv"
    ]
  ]
}