{
  "name": "multi_nuclearpowerplant_41_base10",
  "refpalette": "deceasedcraft:multi_nuclearpowerplant_41/multi_nuclearpowerplant_41_base10_palette",
  "xsize": 16,
  "zsize": 16,
  "slices": [
    [
      "                ",
      "                ",
      "a             aa",
      "aaaaaaaaaaaaaabb",
      "bbbbbbbbbbbbbbbc",
      "cccccccccccccccc",
      "deeecccccccccccc",
      "fdgecccccceeeeec",
      "ffdeccccceegggee",
      "fffdccccceg===ge",
      "ffffddccceg===ge",
      "ffffffdddeg===ge",
      "fffffffffddddddd",
      "ffffffffffffffff",
      "ffffffffffffffff",
      "vvvvvvvvvvvvvvvv"
    ],
    [
      "h               ",
      "h               ",
      "h               ",
      "i             jk",
      " kkkkkkkkkkkkk  ",
      "                ",
      "l m             ",
      "fln             ",
      "ffl       opppo ",
      "fffl      p  qp ",
      "ffffll    prstp ",
      "fffffflll u wxpy",
      "ffffffffflpppppl",
      "ffffffffffffffff",
      "ffffffffffffffff",
      "vvvvvvvvvvvvvvvv"
    ],
    [
      "A               ",
      "A               ",
      "A               ",
      "                ",
      "                ",
      "                ",
      "l               ",
      "fln             ",
      "ffl       oBBBo ",
      "fffl      p C p ",
      "ffffll   DpEFIp ",
      "fffffflll J Kxpy",
      "ffffffffflpppppl",
      "ffffffffffffffff",
      "ffffffffffffffff",
      "vvvvvvvvvvvvvvvv"
    ],
    [
      "                ",
      "                ",
      "                ",
      "                ",
      "                ",
      "                ",
      "l               ",
      "fln             ",
      "ffl       oBBBo ",
      "fffl      pqhhp ",
      "ffffll    pLhhp ",
      "fffffflll Mhhhpy",
      "ffffffffflpppppl",
      "ffffffffffffffff",
      "ffffffffffffffff",
      "vvvvvvvvvvvvvvvv"
    ],
    [
      "                ",
      "                ",
      "                ",
      "                ",
      "                ",
      "                ",
      "l               ",
      "fln             ",
      "ffl       oBBBo ",
      "fffl      pNOPp ",
      "ffffll    pQR p ",
      "fffffflll pS TU ",
      "ffffffffflpppppl",
      "ffffffffffffffff",
      "ffffffffffffffff",
      "vvvvvvvvvvvvvvvv"
    ],
    [
      "                ",
      "                ",
      "                ",
      "                ",
      "                ",
      "                ",
      "l               ",
      "fln             ",
      "ffl       oBBBo ",
      "fffl      pV Wp ",
      "ffffll    pQ  pX",
      "fffffflll pY Z  ",
      "ffffffffflpppppl",
      "ffffffffffffffff",
      "ffffffffffffffff",
      "vvvvvvvvvvvvvvvv"
    ]
  ]
}