{
  "name": "multi_nuclearpowerplant_41_base3",
  "refpalette": "deceasedcraft:multi_nuclearpowerplant_41/multi_nuclearpowerplant_41_base3_palette",
  "xsize": 16,
  "zsize": 16,
  "slices": [
    [
      "                ",
      "                ",
      "                ",
      "                ",
      "                ",
      "                ",
      "                ",
      "aaaaaaaaaaaaaaaa",
      "aaaaaaaaaaaaaaaa",
      "aaaaaaaaaaaaaaaa",
      "bbbbbbbbbbbbbbbb",
      "================",
      "cccccccccccccccc",
      "dddddddddddddddd",
      "dddddddddddddddd",
      "vvvvvvvvvvvvvvvv"
    ],
    [
      "                ",
      "                ",
      "                ",
      "                ",
      "                ",
      "                ",
      "                ",
      "eeeeeeeeeeeeeeee",
      "                ",
      "   f     f     f",
      "gggggggggggggggg",
      "================",
      "hhhhhhhhhhhhhhhh",
      "dddddddddddddddd",
      "dddddddddddddddd",
      "vvvvvvvvvvvvvvvv"
    ],
    [
      "                ",
      "                ",
      "                ",
      "                ",
      "                ",
      "                ",
      "                ",
      "                ",
      "                ",
      "                ",
      "gggggggggggggggg",
      "================",
      "hhhhhhhhhhhhhhhh",
      "dddddddddddddddd",
      "dddddddddddddddd",
      "vvvvvvvvvvvvvvvv"
    ],
    [
      "                ",
      "                ",
      "                ",
      "                ",
      "                ",
      "                ",
      "                ",
      "                ",
      "                ",
      "                ",
      "gggggggggggggggg",
      "================",
      "hhhhhhhhhhhhhhhh",
      "dddddddddddddddd",
      "dddddddddddddddd",
      "vvvvvvvvvvvvvvvv"
    ],
    [
      "                ",
      "                ",
      "                ",
      "                ",
      "                ",
      "                ",
      "                ",
      "                ",
      "                ",
      "                ",
      "gggggggggggggggg",
      "================",
      "hhhhhhhhhhhhhhhh",
      "dddddddddddddddd",
      "dddddddddddddddd",
      "vvvvvvvvvvvvvvvv"
    ],
    [
      "                ",
      "                ",
      "                ",
      "                ",
      "                ",
      "                ",
      "                ",
      "                ",
      "                ",
      "                ",
      "gggggggggggggggg",
      "================",
      "hhhhhhhhhhhhhhhh",
      "dddddddddddddddd",
      "dddddddddddddddd",
      "vvvvvvvvvvvvvvvv"
    ]
  ]
}