{
  "name": "multi_nuclearpowerplant_41_base4",
  "refpalette": "deceasedcraft:multi_nuclearpowerplant_41/multi_nuclearpowerplant_41_base4_palette",
  "xsize": 16,
  "zsize": 16,
  "slices": [
    [
      "aaaaaaaabccccccc",
      "aaaaaaaaaaaaaaaa",
      "aaaaaaaaaaaaaaaa",
      "aaaaaaaaaaaaaaaa",
      "aaaaaaaaaaaaaaad",
      "dddddddddddddddd",
      "                ",
      "                ",
      "                ",
      "                ",
      "eeeeeeeeeeeeeeee",
      "================",
      "ffffffffffffffff",
      "gggggggggggggggg",
      "gggggggggggggggg",
      "vvvvvvvvvvvvvvvv"
    ],
    [
      "aaaaaaaabbbbbbbb",
      "aaaaaaaaaaaaaaaa",
      "aaaaaaaaaaaaaaaa",
      "aaaaaaaaaaaaaaaa",
      "aaaaaaaaaaaaaaad",
      "dddddddddddddddd",
      "                ",
      "                ",
      "                ",
      "                ",
      "eeeeeeeeeeeeeeee",
      "================",
      "ffffffffffffffff",
      "gggggggggggggggg",
      "gggggggggggggggg",
      "vvvvvvvvvvvvvvvv"
    ],
    [
      "aaaaaaaaaaaaaaaa",
      "aaaaaaaaaaaaaaaa",
      "aaaaaaaaaaaaaaaa",
      "aaaaaaaaaaaaaaaa",
      "aaaaaaaaaaaaaaad",
      "dddddddddddddddd",
      "                ",
      "                ",
      "                ",
      "                ",
      "eeeeeeeeeeeeeeee",
      "================",
      "ffffffffffffffff",
      "gggggggggggggggg",
      "gggggggggggggggg",
      "vvvvvvvvvvvvvvvv"
    ],
    [
      "aaaaaaaaaaaaaaaa",
      "aaaaaaaaaaaaaaaa",
      "aaaaaaaaaaaaaaaa",
      "aaaaaaaaaaaaaaaa",
      "aaaaaaaaaaaaaaad",
      "dddddddddddddddd",
      "                ",
      "                ",
      "                ",
      "                ",
      "eeeeeeeeeeeeeeee",
      "================",
      "ffffffffffffffff",
      "gggggggggggggggg",
      "gggggggggggggggg",
      "vvvvvvvvvvvvvvvv"
    ],
    [
      "                ",
      "                ",
      "                ",
      "                ",
      "               d",
      "dddddddddddddddd",
      "                ",
      "                ",
      "                ",
      "                ",
      "eeeeeeeeeeeeeeee",
      "================",
      "ffffffffffffffff",
      "gggggggggggggggg",
      "gggggggggggggggg",
      "vvvvvvvvvvvvvvvv"
    ],
    [
      "                ",
      "                ",
      "                ",
      "                ",
      "               h",
      "hhhhhhhhhhhhhhhh",
      "                ",
      "                ",
      "                ",
      "                ",
      "eeeeeeeeeeeeeeee",
      "================",
      "ffffffffffffffff",
      "gggggggggggggggg",
      "gggggggggggggggg",
      "vvvvvvvvvvvvvvvv"
    ]
  ]
}