{
  "name": "multi_nuclearpowerplant_41_base8",
  "refpalette": "deceasedcraft:multi_nuclearpowerplant_41/multi_nuclearpowerplant_41_base8_palette",
  "xsize": 16,
  "zsize": 16,
  "slices": [
    [
      "                ",
      "                ",
      "                ",
      "                ",
      "                ",
      "                ",
      "a          b b  ",
      "cab         d   ",
      "cca       efffe ",
      "ccca      fgggf ",
      "ccccaa    f   f ",
      "ccccccaaa f d f ",
      "cccccccccafffffa",
      "hhhhhhhhhhhhhhhh",
      "hhhhhhhhhhhhhhhh",
      "vvvvvvvvvvvvvvvv"
    ],
    [
      "cccccccccccccccc",
      "cccccccccccccccc",
      "cccccccccccccccc",
      "cccccccccccccccc",
      "cccccccccccccccc",
      "cccccccccccccccc",
      "iccccccccccccccc",
      "=ijccccccccckccc",
      "==iccccccccccccc",
      "===icccccccccccc",
      "====iicccccccccc",
      "======iiiccckccc",
      "iiiiiiiiiiiiiiii",
      "hhhhhhhhhhhhhhhh",
      "hhhhhhhhhhhhhhhh",
      "vvvvvvvvvvvvvvvv"
    ],
    [
      "hhhhhhhhhhhlmlhh",
      "hhhhhhhhhhhlmlhh",
      "hhhhhhhhhhhlmlhh",
      "hhhhhhhhhhhlmlhh",
      "hhhhhhhhhhhlmlhh",
      "hhhhhhhhhhhlmlhh",
      "ahhhhhhhhhhlnlhh",
      "hahhhhhhhhhlolhh",
      "hhahhhhhhhhlnlhh",
      "hhhahhhhhhhlmlhh",
      "hhhhaahhhhhlmlhh",
      "hhhhhhaaahhlolhh",
      "aaaaaaaaaaaaaaaa",
      "hhhhhhhhhhhhhhhh",
      "hhhhhhhhhhhhhhhh",
      "vvvvvvvvvvvvvvvv"
    ],
    [
      "hhhhhhhhhhhhlhhh",
      "hhhhhhhhhhhhlhhh",
      "hhhhhhhhhhhhlhhh",
      "hhhhhhhhhhhhlhhh",
      "hhhhhhhhhhhhlhhh",
      "hhhhhhhhhhhhlhhh",
      "ahhhhhhhhhhhlhhh",
      "hahhhhhhhhhhlhhh",
      "hhahhhhhhhhhlhhh",
      "hhhahhhhhhhhlhhh",
      "hhhhaahhhhhhlhhh",
      "hhhhhhaaahhhlhhh",
      "aaaaaaaaaaaaaaaa",
      "hhhhhhhhhhhhhhhh",
      "hhhhhhhhhhhhhhhh",
      "vvvvvvvvvvvvvvvv"
    ],
    [
      "================",
      "================",
      "================",
      "================",
      "================",
      "================",
      "================",
      "================",
      "================",
      "================",
      "================",
      "pppppppppppppppp",
      "aaaaaaaaaaaaaaaa",
      "hhhhhhhhhhhhhhhh",
      "hhhhhhhhhhhhhhhh",
      "vvvvvvvvvvvvvvvv"
    ],
    [
      "jjjjjjjjjjjjjjjj",
      "jjjjjjjjjjjjjjjj",
      "jjjjjjjjjjjjjjjj",
      "jjjjjjjjjjjjjjjj",
      "jjjjjjjjjjjjjjjj",
      "jjjjjjjjjjjjjjjj",
      "jjjjjjjjjjjjjjjj",
      "jjjjjjjjjjjjjjjj",
      "jjjjjjjjjjjjjjjj",
      "jjjjjjjjjjjjjjjj",
      "jjjjjjjjjjjjjjjj",
      "================",
      "aaaaaaaaaaaaaaaa",
      "hhhhhhhhhhhhhhhh",
      "hhhhhhhhhhhhhhhh",
      "vvvvvvvvvvvvvvvv"
    ]
  ]
}