{
  "name": "multi_gasstation_0_ground",
  "refpalette": "deceasedcraft:multi_gasstation_0/multi_gasstation_0_ground_palette",
  "xsize": 16,
  "zsize": 16,
  "slices": [
    [
      "aaaaaaaaaaaaaaaa",
      "bHHHHHHHHHHcaaaa",
      "HHHHHHHHHHHcaaaa",
      "HHHHHHHHHHHcaaaa",
      "HHHHHHHHHHHcaaaa",
      "HHHHHHHHHHHcaaaa",
      "HHHHHHHHHHHcaaaa",
      "HHHHbHHbbbbbbbaa",
      "HHHHbHHbbbbbbbaa",
      "HHHHbHHbbbbbbbaa",
      "HHHHbHHbbbbbbbaa",
      "HHHHbHHbbbbbbbaa",
      "HHHHbHHbbbbbbbaa",
      "HHHHbHHbbbbbbbaa",
      "HHHHbHHbbbbbbbaa",
      "HHHHbHHbbbbbbbaa"
    ],
    [
      "                ",
      "d      e  fg    ",
      "       h  ig    ",
      "       e  fg    ",
      "       h  ig    ",
      "       e  fg    ",
      "       h  ig    ",
      "    j  kkkkkkk  ",
      "  lmn  k okp k  ",
      "       k qkr k  ",
      "  stj  kukkkwk  ",
      "  lmg  k xxx k  ",
      "       k     k  ",
      "  stj  k     k  ",
      "  lmy  kkAkkkk  ",
      "  B    C  DDDk  "
    ],
    [
      "                ",
      "E               ",
      "                ",
      "                ",
      "                ",
      "                ",
      "                ",
      "    j  kkkkkkk  ",
      "    F  k  k  k  ",
      "       k  k  k  ",
      "    j  kIkkkJk  ",
      "       k     k  ",
      "       k     k  ",
      "    j  k   K k  ",
      "    L  kkMkkkk  ",
      "       C  N  k  "
    ],
    [
      "                ",
      "E               ",
      "                ",
      "                ",
      "                ",
      "                ",
      "                ",
      "    j  OOOOOOO  ",
      "       P  O  P  ",
      "       P  O  P  ",
      "    j  OOOOOOO  ",
      "       O     O  ",
      "       P     P  ",
      "    j  P     P  ",
      "       OOOOOOO  ",
      "       O  QRSP  "
    ],
    [
      "                ",
      "                ",
      "                ",
      "                ",
      "                ",
      "                ",
      "                ",
      "    kT kkkkkkk  ",
      "       kUUkUUk  ",
      "       kUUkUUk  ",
      "    kV kkkkkkk  ",
      "       kUUUUUk  ",
      "       kUUUUUk  ",
      "    kT kUUVUUk  ",
      "       kkkkkkk  ",
      "       k  WX!k  "
    ],
    [
      "                ",
      "                ",
      "                ",
      "                ",
      "                ",
      "                ",
      " YYYYYYYYYYYYYY ",
      " YggbbbbbbbbbbY ",
      " YggbggggggggbY ",
      " YggbggggggggbY ",
      " YggbggggggggbY ",
      " YggbggggggggbY ",
      " YggbggggggggbY ",
      " YggbggggggggbY ",
      " YggbbbbbbbbbbY ",
      " YggbggggggggbY "
    ]
  ]
}