{
  "name": "building_office1b_floor2_180",
  "refpalette": "deceasedcraft:building_office1b/building_office1b_floor2_palette_180",
  "xsize": 16,
  "zsize": 16,
  "slices": [
    [
      "                ",
      " iiiiiiiiiiiiii ",
      " ibbbbbbbbbbbbi ",
      " ibbbbbbbbbbbbi ",
      " idbbbbbddddddi ",
      "  ebbbbbdhg  e  ",
      "  ebbbbbdf   e  ",
      " ccbbbbbbddddcc ",
      "  abbbbbbbbbba  ",
      "  abbbbbbbbbba  ",
      "  abbbbbbbbbba  ",
      "  abbbbbbbbbba  ",
      "  abbbbbbbbbba  ",
      "  aaaaaaaaaaaa  ",
      "                ",
      "                "
    ],
    [
      "                ",
      " FFFFFFFFFFFFFF ",
      " FPO       NMLF ",
      " FK        J  F ",
      " Fd   B dIddddF ",
      "  e B EBd DC e  ",
      "  e   B d    e  ",
      " cc  AAA!ddddcc ",
      "  j pwuyxwu mj  ",
      "  j tsr tsrq j  ",
      "  j  on pon  j  ",
      "  j  lkm lk  j  ",
      "  j          j  ",
      "  jjjjjjjjjjjj  ",
      "                ",
      "                "
    ],
    [
      "                ",
      " FFFFFFFFFFFFFF ",
      " F5        43 F ",
      " F         2  F ",
      " Fd     d1ddddF ",
      "  e   0 d  Dge  ",
      "  e     d    e  ",
      " cc  ZZZZddddcc ",
      "  j  YT  XT  j  ",
      "  j  WU  VU  j  ",
      "  j  TS  RQ  j  ",
      "  j          j  ",
      "  j          j  ",
      "  jjjjjjjjjjjj  ",
      "                ",
      "                "
    ],
    [
      "                ",
      " FF^jjjjjjjj^FF ",
      " F%        4$ F ",
      " F#        9  F ",
      " Fd     ddddddF ",
      "  e     d   fe  ",
      "  e     d  8ge  ",
      " cc  7xR6ddddcc ",
      "  j          j  ",
      "  j          j  ",
      "  j          j  ",
      "  j          j  ",
      "  j          j  ",
      "  jjjjjjjjjjjj  ",
      "                ",
      "                "
    ],
    [
      "                ",
      " FFFFFFFFFFFFFF ",
      " F{        ]^^F ",
      " F[        -^^F ",
      " Fd     ddddddF ",
      "  e     d    e  ",
      "  e     d 8+ e  ",
      " cc)*(**&ddddcc ",
      "  j          j  ",
      "  j          j  ",
      "  j          j  ",
      "  j          j  ",
      "  j          j  ",
      "  jjjjjjjjjjjj  ",
      "                ",
      "                "
    ],
    [
      "                ",
      " FFFFFFFFFFFFFF ",
      " F<}|||||||': F ",
      " F<}|||||||' :F ",
      " Fd}||||ddddddF ",
      "  e}||||d;   e  ",
      "  e}||||d8+  e  ",
      " cc}|||||ddddcc ",
      "  j}||||||||}j  ",
      "  j}||||||||}j  ",
      "  j}||||||||}j  ",
      "  j}||||||||}j  ",
      "  j}}}}}}}}}}j  ",
      "  jjjjjjjjjjjj  ",
      "                ",
      "                "
    ]
  ]
}