{
  "name": "building_office1b_base1_270",
  "refpalette": "deceasedcraft:building_office1b/building_office1b_base1_palette_270",
  "xsize": 16,
  "zsize": 16,
  "slices": [
    [
      "vvvvvvvvvvvvvvvv",
      "vaaaaaaaaaaaaaav",
      "vaaaaaaaaaaaaaav",
      "vaaaaaaaaaaaaaav",
      "vaaaaaaaaaaaaaav",
      "vaaaaaaaaaaaaaav",
      "vaaaaaaaaaaaaaav",
      "vaaaaaaaaaaaaaav",
      "vaaaaaaaaaaaaaav",
      "vaaaaaaaaaaaaaav",
      "vaaaaaaaaaaaaaav",
      "vaaaaaaaaaaaaaav",
      "vaaaaaaaaaaaaaav",
      "vaaaaaaaaaaaaaav",
      "vaaaaaaaaaaaaaav",
      "vvvvvvvvvvvvvvvv"
    ],
    [
      "vvvvvvvvvvvvvvvv",
      "vBBBBbbbbbbbbbbv",
      "vBFFByfffcfffcbv",
      "vB  C t t oi dbv",
      "vB  C  i    d bv",
      "vB  Ct jjjjj  bv",
      "vB  B  rurpk  bv",
      "vB  DA        bv",
      "vB  EA      g bv",
      "vB  B  qqsql  bv",
      "vB  C  mmmmm  bv",
      "vB  C     d   bv",
      "vB  C  xw  n dbv",
      "vBIIBehhhehhhebv",
      "vBJJBbbbbbbbbbbv",
      "vvvvvvvvvvvvvvvv"
    ],
    [
      "vvvvvvvvvvvvvvvv",
      "vBBBBbbbbbbbbbbv",
      "vBFFBVXNo!QNMKbv",
      "vB  C         bv",
      "vB  C    S    bv",
      "vB  C  OOTOO  bv",
      "vB  B         bv",
      "vB  Z         bv",
      "vB  0         bv",
      "vB  B         bv",
      "vB  C  OOTOO  bv",
      "vB  C    U    bv",
      "vB  C         bv",
      "vB 1BY PWVRP Lbv",
      "vB22Bbbbbbbbbbbv",
      "vvvvvvvvvvvvvvvv"
    ],
    [
      "vvvvvvvvvvvvvvvv",
      "vBBBBbbbbbbbbbbv",
      "vBFFB 3  3  3 bv",
      "vB  C         bv",
      "vB  C         bv",
      "vB  C  OOTOO  bv",
      "vB  B    5    bv",
      "vB  B         bv",
      "vB  B         bv",
      "vB  B    6    bv",
      "vB  C  OOTOO  bv",
      "vB  C         bv",
      "vB  C         bv",
      "vB  B 4  4  4 bv",
      "vB77Bbbbbbbbbbbv",
      "vvvvvvvvvvvvvvvv"
    ],
    [
      "vvvvvvvvvvvvvvvv",
      "vBBBBbbbbbbbbbbv",
      "vBFFB898898898bv",
      "vB  C         bv",
      "vB  C         bv",
      "vB  C  OOTOO  bv",
      "vB  C         bv",
      "vB  C         bv",
      "vB  C         bv",
      "vB  C         bv",
      "vB  C  OOTOO  bv",
      "vB  C         bv",
      "vB  C         bv",
      "vB  B8#88#88#8bv",
      "vB77Bbbbbbbbbbbv",
      "vvvvvvvvvvvvvvvv"
    ],
    [
      "vvvvvvvvvvvvvvvv",
      "vBBBBbbbbbbbbbbv",
      "vBFFB$$$$$$$$$bv",
      "vB  B$$$$$$$$$bv",
      "vB  B$$$$$$$$$bv",
      "vB  B$$$$$$$$$bv",
      "vB  B$J$$g$$g$bv",
      "vB  B$J$$g$$g$bv",
      "vB  B$g$$g$$%$bv",
      "vB  B$g$$J$$g$bv",
      "vB  B$$$$$$$$$bv",
      "vB  B$$$$$$$$$bv",
      "vB  B$$$$$$$$$bv",
      "vB^^B$$$$$$$$$bv",
      "vB&&Bbbbbbbbbbbv",
      "vvvvvvvvvvvvvvvv"
    ]
  ]
}