{
  "name": "building_office1b_floor1_180",
  "refpalette": "deceasedcraft:building_office1b/building_office1b_floor1_palette_180",
  "xsize": 16,
  "zsize": 16,
  "slices": [
    [
      "                ",
      " iiiiiiiiiiiiii ",
      " ibbbbbbbbbbbbi ",
      " ibbbbbbbbbbbbi ",
      " idbbbbbddddddi ",
      "  ebbbbbdhg  e  ",
      "  ebbbbbdf   e  ",
      " ccbbbbbbddddcc ",
      "  abbbbbbbbbba  ",
      "  abbbbbbbbbba  ",
      "  abbbbbbbbbba  ",
      "  abbbbbbbbbba  ",
      "  abbbbbbbbbba  ",
      "  aaaaaaaaaaaa  ",
      "                ",
      "                "
    ],
    [
      "                ",
      " CCCCCCCCCCCCCC ",
      " CN        MLKC ",
      " CJ        IFEC ",
      " Cd   y dDddddC ",
      "  e  yByd Ag e  ",
      "  e   y d    e  ",
      " cc  xxxxddddcc ",
      "  j wts uts! j  ",
      "  j  rqp rq pj  ",
      "  j  on  onm j  ",
      "  j  lk  lk  j  ",
      "  j          j  ",
      "  jjjjjjjjjjjj  ",
      "                ",
      "                "
    ],
    [
      "                ",
      " CCCCCCCCCCCCCC ",
      " C2        10 C ",
      " C         Z  C ",
      " Cd     dYddddC ",
      "  e   X d  Age  ",
      "  e     d    e  ",
      " cc  WWWWddddcc ",
      "  j  VU  VU  j  ",
      "  j  TS  TS  j  ",
      "  j  RQ  PO  j  ",
      "  j          j  ",
      "  j          j  ",
      "  jjjjjjjjjjjj  ",
      "                ",
      "                "
    ],
    [
      "                ",
      " CC%jjjjjjjj%CC ",
      " C$        1# C ",
      " C9        8  C ",
      " Cd     ddddddC ",
      "  e     d   fe  ",
      "  e     d  7ge  ",
      " cc  6543ddddcc ",
      "  j          j  ",
      "  j          j  ",
      "  j          j  ",
      "  j          j  ",
      "  j          j  ",
      "  jjjjjjjjjjjj  ",
      "                ",
      "                "
    ],
    [
      "                ",
      " CCCCCCCCCCCCCC ",
      " C]        [%%C ",
      " C-        +%%C ",
      " Cd     ddddddC ",
      "  e     d    e  ",
      "  e     d 7) e  ",
      " cc(&*&&^ddddcc ",
      "  j          j  ",
      "  j          j  ",
      "  j          j  ",
      "  j          j  ",
      "  j          j  ",
      "  jjjjjjjjjjjj  ",
      "                ",
      "                "
    ],
    [
      "                ",
      " CCCCCCCCCCCCCC ",
      " C'{}}}}}}}:; C ",
      " C'{}}}}}}}: ;C ",
      " Cd{}}}}ddddddC ",
      "  e{}}}}d|   e  ",
      "  e{}}}}d7)  e  ",
      " cc{}}}}}ddddcc ",
      "  j{}}}}}}}}{j  ",
      "  j{}}}}}}}}{j  ",
      "  j{}}}}}}}}{j  ",
      "  j{}}}}}}}}{j  ",
      "  j{{{{{{{{{{j  ",
      "  jjjjjjjjjjjj  ",
      "                ",
      "                "
    ]
  ]
}