{
  "name": "building_office1b_floor2",
  "refpalette": "deceasedcraft:building_office1b/building_office1b_floor2_palette",
  "xsize": 16,
  "zsize": 16,
  "slices": [
    [
      "                ",
      "                ",
      "  aaaaaaaaaaaa  ",
      "  abbbbbbbbbba  ",
      "  abbbbbbbbbba  ",
      "  abbbbbbbbbba  ",
      "  abbbbbbbbbba  ",
      "  abbbbbbbbbba  ",
      " ccddddbbbbbbcc ",
      "  e   fdbbbbbe  ",
      "  e  ghdbbbbbe  ",
      " iddddddbbbbbdi ",
      " ibbbbbbbbbbbbi ",
      " ibbbbbbbbbbbbi ",
      " iiiiiiiiiiiiii ",
      "                "
    ],
    [
      "                ",
      "                ",
      "  jjjjjjjjjjjj  ",
      "  j          j  ",
      "  j  kl mkl  j  ",
      "  j  nop no  j  ",
      "  j qrst rst j  ",
      "  jm uwxyuwp j  ",
      " ccdddd!AAA  cc ",
      "  e    d B   e  ",
      "  e CD dBE B e  ",
      " FddddId B   dF ",
      " F  J        KF ",
      " FLMN       OPF ",
      " FFFFFFFFFFFFFF ",
      "                "
    ],
    [
      "                ",
      "                ",
      "  jjjjjjjjjjjj  ",
      "  j          j  ",
      "  j          j  ",
      "  j  QR  ST  j  ",
      "  j  UV  UW  j  ",
      "  j  TX  TY  j  ",
      " ccddddZZZZ  cc ",
      "  e    d     e  ",
      "  egD  d 0   e  ",
      " Fdddd1d     dF ",
      " F  2         F ",
      " F 34        5F ",
      " FFFFFFFFFFFFFF ",
      "                "
    ],
    [
      "                ",
      "                ",
      "  jjjjjjjjjjjj  ",
      "  j          j  ",
      "  j          j  ",
      "  j          j  ",
      "  j          j  ",
      "  j          j  ",
      " ccdddd6Rx7  cc ",
      "  eg8  d     e  ",
      "  ef   d     e  ",
      " Fdddddd     dF ",
      " F  9        #F ",
      " F $4        %F ",
      " FF^jjjjjjjj^FF ",
      "                "
    ],
    [
      "                ",
      "                ",
      "  jjjjjjjjjjjj  ",
      "  j          j  ",
      "  j          j  ",
      "  j          j  ",
      "  j          j  ",
      "  j          j  ",
      " ccdddd&**(*)cc ",
      "  e +8 d     e  ",
      "  e    d     e  ",
      " Fdddddd     dF ",
      " F^^-        [F ",
      " F^^]        {F ",
      " FFFFFFFFFFFFFF ",
      "                "
    ],
    [
      "                ",
      "                ",
      "  jjjjjjjjjjjj  ",
      "  j}}}}}}}}}}j  ",
      "  j}||||||||}j  ",
      "  j}||||||||}j  ",
      "  j}||||||||}j  ",
      "  j}||||||||}j  ",
      " ccdddd|||||}cc ",
      "  e  +8d||||}e  ",
      "  e   ;d||||}e  ",
      " Fdddddd||||}dF ",
      " F: '|||||||}<F ",
      " F :'|||||||}<F ",
      " FFFFFFFFFFFFFF ",
      "                "
    ]
  ]
}