{
  "name": "building_office1b_base1_90",
  "refpalette": "deceasedcraft:building_office1b/building_office1b_base1_palette_90",
  "xsize": 16,
  "zsize": 16,
  "slices": [
    [
      "vvvvvvvvvvvvvvvv",
      "vaaaaaaaaaaaaaav",
      "vaaaaaaaaaaaaaav",
      "vaaaaaaaaaaaaaav",
      "vaaaaaaaaaaaaaav",
      "vaaaaaaaaaaaaaav",
      "vaaaaaaaaaaaaaav",
      "vaaaaaaaaaaaaaav",
      "vaaaaaaaaaaaaaav",
      "vaaaaaaaaaaaaaav",
      "vaaaaaaaaaaaaaav",
      "vaaaaaaaaaaaaaav",
      "vaaaaaaaaaaaaaav",
      "vaaaaaaaaaaaaaav",
      "vaaaaaaaaaaaaaav",
      "vvvvvvvvvvvvvvvv"
    ],
    [
      "vvvvvvvvvvvvvvvv",
      "vbbbbbbbbbbBJJBv",
      "vbehhhehhheBIIBv",
      "vbd n  wx  C  Bv",
      "vb   d     C  Bv",
      "vb  mmmmm  C  Bv",
      "vb  lqsqq  B  Bv",
      "vb g      AE  Bv",
      "vb        AD  Bv",
      "vb  kprur  B  Bv",
      "vb  jjjjj tC  Bv",
      "vb d    i  C  Bv",
      "vbd io t t C  Bv",
      "vbcfffcfffyBFFBv",
      "vbbbbbbbbbbBBBBv",
      "vvvvvvvvvvvvvvvv"
    ],
    [
      "vvvvvvvvvvvvvvvv",
      "vbbbbbbbbbbB22Bv",
      "vbL PRVWP YB1 Bv",
      "vb         C  Bv",
      "vb    U    C  Bv",
      "vb  OOTOO  C  Bv",
      "vb         B  Bv",
      "vb         0  Bv",
      "vb         Z  Bv",
      "vb         B  Bv",
      "vb  OOTOO  C  Bv",
      "vb    S    C  Bv",
      "vb         C  Bv",
      "vbKMNQ!oNXVBFFBv",
      "vbbbbbbbbbbBBBBv",
      "vvvvvvvvvvvvvvvv"
    ],
    [
      "vvvvvvvvvvvvvvvv",
      "vbbbbbbbbbbB77Bv",
      "vb 4  4  4 B  Bv",
      "vb         C  Bv",
      "vb         C  Bv",
      "vb  OOTOO  C  Bv",
      "vb    6    B  Bv",
      "vb         B  Bv",
      "vb         B  Bv",
      "vb    5    B  Bv",
      "vb  OOTOO  C  Bv",
      "vb         C  Bv",
      "vb         C  Bv",
      "vb 3  3  3 BFFBv",
      "vbbbbbbbbbbBBBBv",
      "vvvvvvvvvvvvvvvv"
    ],
    [
      "vvvvvvvvvvvvvvvv",
      "vbbbbbbbbbbB77Bv",
      "vb8#88#88#8B  Bv",
      "vb         C  Bv",
      "vb         C  Bv",
      "vb  OOTOO  C  Bv",
      "vb         C  Bv",
      "vb         C  Bv",
      "vb         C  Bv",
      "vb         C  Bv",
      "vb  OOTOO  C  Bv",
      "vb         C  Bv",
      "vb         C  Bv",
      "vb898898898BFFBv",
      "vbbbbbbbbbbBBBBv",
      "vvvvvvvvvvvvvvvv"
    ],
    [
      "vvvvvvvvvvvvvvvv",
      "vbbbbbbbbbbB&&Bv",
      "vb$$$$$$$$$B^^Bv",
      "vb$$$$$$$$$B  Bv",
      "vb$$$$$$$$$B  Bv",
      "vb$$$$$$$$$B  Bv",
      "vb$g$$J$$g$B  Bv",
      "vb$%$$g$$g$B  Bv",
      "vb$g$$g$$J$B  Bv",
      "vb$g$$g$$J$B  Bv",
      "vb$$$$$$$$$B  Bv",
      "vb$$$$$$$$$B  Bv",
      "vb$$$$$$$$$B  Bv",
      "vb$$$$$$$$$BFFBv",
      "vbbbbbbbbbbBBBBv",
      "vvvvvvvvvvvvvvvv"
    ]
  ]
}