{
  "name": "building_office1b_floor3_90",
  "refpalette": "deceasedcraft:building_office1b/building_office1b_floor3_palette_90",
  "xsize": 16,
  "zsize": 16,
  "slices": [
    [
      "                ",
      "        c  iiii ",
      "  aaaaaaceedbbi ",
      "  abbbbbbbbbbbi ",
      "  abbbbbbbbbbbi ",
      "  abbbbbbbbbbbi ",
      "  abbbbbbbbbbbi ",
      "  abbbbbbbbbbbi ",
      "  abbbbbbdddbbi ",
      "  abbbbbdfhdbbi ",
      "  abbbbbd gdbbi ",
      "  abbbbbd  dbbi ",
      "  abbbbbd  dbbi ",
      "  aaaaaaceedbbi ",
      "        c  iiii ",
      "                "
    ],
    [
      "                ",
      "        c  yyyy ",
      "  jjjjjjceedEKy ",
      "  j     d     y ",
      "  j o   t     y ",
      "  j nn  s     y ",
      "  jlnnq d     y ",
      "  j nn  duxB  y ",
      "  jlnnq dddd  y ",
      "  j nn  d  A  y ",
      "  jlnnq d wd  y ",
      "  j     d gdDJy ",
      "  jkmmprd  d Iy ",
      "  jjjjjjceedCFy ",
      "        c  yyyy ",
      "                "
    ],
    [
      "                ",
      "        c  yyyy ",
      "  jjjjjjceedZZy ",
      "  j     d     y ",
      "  j     W     y ",
      "  j PS  V     y ",
      "  j MR  d     y ",
      "  j     d!    y ",
      "  j OM  dddd  y ",
      "  j N   d  X  y ",
      "  j MM  d  d  y ",
      "  j     d wdY1y ",
      "  j LQTUd gd 0y ",
      "  jjjjjjceed  y ",
      "        c  yyyy ",
      "                "
    ],
    [
      "                ",
      "        c  yyyy ",
      "  jjjjjjceedZZy ",
      "  j     d     7 ",
      "  j     3     j ",
      "  j     3     j ",
      "  j     d     j ",
      "  j     d     j ",
      "  j     dddd  j ",
      "  j     d  d  j ",
      "  j     d  d  j ",
      "  j     d4 d51j ",
      "  j    2dgfd 67 ",
      "  jjjjjjceed  y ",
      "        c  yyyy ",
      "                "
    ],
    [
      "                ",
      "        c  yyyy ",
      "  jjjjjjceed#%y ",
      "  j     d     y ",
      "  j     d     y ",
      "  j     d     y ",
      "  j     d     y ",
      "  j     d     y ",
      "  j     dddd  y ",
      "  j     d  d  y ",
      "  j     d4 d  y ",
      "  j     d8 d9$y ",
      "  j     d  d77y ",
      "  jjjjjjceed77y ",
      "        c  yyyy ",
      "                "
    ],
    [
      "                ",
      "        c  yyyy ",
      "  jjjjjjceed**y ",
      "  j^^^^^d^^^^^y ",
      "  j^&&&*d&&&&&y ",
      "  j^&&&*d&&&&&y ",
      "  j^&&&*d&&&&&y ",
      "  j^&&&*d&&&&&y ",
      "  j^&&&*dddd&&y ",
      "  j^&&&*d4(d&&y ",
      "  j^&&&*d8 d&&y ",
      "  j^&&&*d  d++y ",
      "  j^^^^^d  d )y ",
      "  jjjjjjceed) y ",
      "        c  yyyy ",
      "                "
    ]
  ]
}