{
  "name": "building_office1b_ground_180",
  "refpalette": "deceasedcraft:building_office1b/building_office1b_ground_palette_180",
  "xsize": 16,
  "zsize": 16,
  "slices": [
    [
      "aaaaaaaaaaaaaaaa",
      "abbbbbbbbbbbbbba",
      "abdbbbbbbbbbbeba",
      "abdbbbbbbbbbbeba",
      "abdbbbbbddddddba",
      "abdbbbbbdbbbbdba",
      "abdbbbbbdbbbbdba",
      "abdbbbbb!dddddba",
      "abcbbbbbbbbbbcba",
      "abcbbbbbbbbbbcba",
      "abcbbbbbbbbbbcba",
      "abcbbbbbbbbbbcba",
      "abcbbbbbbbbbbcba",
      "abccccccccccccba",
      "abbbbbbbbbbbbbba",
      "aaaaaaaaaaaaaaaa"
    ],
    [
      "                ",
      " uuuuuuuuuuuuuu ",
      " D          CBu ",
      " A          yxu ",
      " udq    dwddddu ",
      "  r     d ts r  ",
      "  r     d    r  ",
      " fdq    qdddddf ",
      "  gpon  k    g  ",
      "  g     km   g  ",
      " fglll  k    gf ",
      "  g     k    g  ",
      "  gjih       g  ",
      " fggggggggggggf ",
      "   f  f  f  f   ",
      "                "
    ],
    [
      "                ",
      " uuuuuuuuuuuuuu ",
      " N          L u ",
      " M          L u ",
      " udJ    dKddddu ",
      "  r     d  tsr  ",
      "  r     d    r  ",
      " fdJ    Jdddddf ",
      "  g     I    g  ",
      "  g          g  ",
      " fg     F    gf ",
      "  g     E    g  ",
      "  g          g  ",
      " fggggggggggggf ",
      "   f  f  f  f   ",
      "                "
    ],
    [
      "                ",
      " uuUggggggggUuu ",
      " T          L u ",
      " S          L u ",
      " udO    ddddddu ",
      "  r    Rd   Qr  ",
      "  r     d  Psr  ",
      " fdO    Odddddf ",
      "  g          g  ",
      "  g          g  ",
      " fg          gf ",
      "  g          g  ",
      "  g          g  ",
      " fggggggggggggf ",
      "   f  f  f  f   ",
      "                "
    ],
    [
      "                ",
      " uuuuuuuuuuuuuu ",
      " u          L u ",
      " u          ! u ",
      " ud     ddddddu ",
      "  r     d    r  ",
      "  r     d PV r  ",
      " fd      dddddf ",
      "  g          g  ",
      "  g          g  ",
      " fg          gf ",
      "  g          g  ",
      "  g          g  ",
      " fggggggggggggf ",
      "   f  f  f  f   ",
      "                "
    ],
    [
      "                ",
      " uuuuuuuuuuuuuu ",
      " u0XYYYYYYYYL u ",
      " u0XYYYYYYYYL u ",
      " udXYYYYddddddu ",
      "  rXYYYYdZ   r  ",
      "  rXYYYYdPV  r  ",
      " WWXYYYYYddddWW ",
      " WWXYYYYYYYYXWW ",
      " WWXYYYYYYYYXWW ",
      " WWXYYYYYYYYXWW ",
      " WWXYYYYYYYYXWW ",
      " WWXXXXXXXXXXWW ",
      " WWWWWWWWWWWWWW ",
      " WWWWWWWWWWWWWW ",
      "                "
    ]
  ]
}