{
  "name": "building_office1b_floor3",
  "refpalette": "deceasedcraft:building_office1b/building_office1b_floor3_palette",
  "xsize": 16,
  "zsize": 16,
  "slices": [
    [
      "                ",
      "                ",
      "  aaaaaaaaaaaa  ",
      "  abbbbbbbbbba  ",
      "  abbbbbbbbbba  ",
      "  abbbbbbbbbba  ",
      "  abbbbbbbbbba  ",
      "  abbbbbbbbbba  ",
      " ccddddbbbbbbcc ",
      "  e   fdbbbbbe  ",
      "  e  ghdbbbbbe  ",
      " iddddddbbbbbdi ",
      " ibbbbbbbbbbbbi ",
      " ibbbbbbbbbbbbi ",
      " iiiiiiiiiiiiii ",
      "                "
    ],
    [
      "                ",
      "                ",
      "  jjjjjjjjjjjj  ",
      "  jk l l l   j  ",
      "  jm nnnnnno j  ",
      "  jm nnnnnn  j  ",
      "  jp q q q   j  ",
      "  jr         j  ",
      " ccdddddddstdcc ",
      "  e    du    e  ",
      "  e gw dx    e  ",
      " yddddAdB    dy ",
      " yC D        Ey ",
      " yFIJ        Ky ",
      " yyyyyyyyyyyyyy ",
      "                "
    ],
    [
      "                ",
      "                ",
      "  jjjjjjjjjjjj  ",
      "  j          j  ",
      "  jL MNO MP  j  ",
      "  jQ M M RS  j  ",
      "  jT         j  ",
      "  jU         j  ",
      " ccdddddddVWdcc ",
      "  e    d!    e  ",
      "  egw  d     e  ",
      " yddddXd     dy ",
      " y  Y        Zy ",
      " y 01        Zy ",
      " yyyyyyyyyyyyyy ",
      "                "
    ],
    [
      "                ",
      "                ",
      "  jjjjjjjjjjjj  ",
      "  j          j  ",
      "  j          j  ",
      "  j          j  ",
      "  j          j  ",
      "  j2         j  ",
      " ccddddddd33dcc ",
      "  eg4  d     e  ",
      "  ef   d     e  ",
      " ydddddd     dy ",
      " y  5        Zy ",
      " y 61        Zy ",
      " yy7jjjjjjjj7yy ",
      "                "
    ],
    [
      "                ",
      "                ",
      "  jjjjjjjjjjjj  ",
      "  j          j  ",
      "  j          j  ",
      "  j          j  ",
      "  j          j  ",
      "  j          j  ",
      " ccddddddddddcc ",
      "  e 84 d     e  ",
      "  e    d     e  ",
      " ydddddd     dy ",
      " y779        #y ",
      " y77$        %y ",
      " yyyyyyyyyyyyyy ",
      "                "
    ],
    [
      "                ",
      "                ",
      "  jjjjjjjjjjjj  ",
      "  j^^^^^^^^^^j  ",
      "  j^&&&&&&&&^j  ",
      "  j^&&&&&&&&^j  ",
      "  j^&&&&&&&&^j  ",
      "  j^********^j  ",
      " ccddddddddddcc ",
      "  e  84d&&&&^e  ",
      "  e   (d&&&&^e  ",
      " ydddddd&&&&^dy ",
      " y) +&&&&&&&^*y ",
      " y )+&&&&&&&^*y ",
      " yyyyyyyyyyyyyy ",
      "                "
    ]
  ]
}