{
  "name": "building_office1b_ground_270",
  "refpalette": "deceasedcraft:building_office1b/building_office1b_ground_palette_270",
  "xsize": 16,
  "zsize": 16,
  "slices": [
    [
      "aaaaaaaaaaaaaaaa",
      "abbbbbbbbbbbbbba",
      "abeeddddccccccba",
      "abbbdbbdbbbbbcba",
      "abbbdbbdbbbbbcba",
      "abbbdbbdbbbbbcba",
      "abbbdbbdbbbbbcba",
      "abbbddd!bbbbbcba",
      "abbbbbbbbbbbbcba",
      "abbbbbbbbbbbbcba",
      "abbbbbbbbbbbbcba",
      "abbbbbbbbbbbbcba",
      "abbbbbbbbbbbbcba",
      "abddddddccccccba",
      "abbbbbbbbbbbbbba",
      "aaaaaaaaaaaaaaaa"
    ],
    [
      "                ",
      " uuuu  f  f  f  ",
      " uBxdrrdgggggg  ",
      " uCyd  d     gf ",
      " u  ds d     g  ",
      " u  dt d     g  ",
      " u  w  d m   gf ",
      " u  dddqkkkk g  ",
      " u           g  ",
      " u           gf ",
      " u      n l hg  ",
      " u      o l ig  ",
      " u  q  qp l jgf ",
      " u  drrdgggggg  ",
      " uDAu  f  f  f  ",
      "                "
    ],
    [
      "                ",
      " uuuu  f  f  f  ",
      " u  drrdgggggg  ",
      " uLLds d     gf ",
      " u  dt d     g  ",
      " u  d  d     g  ",
      " u  K  d     gf ",
      " u  dddJI FE g  ",
      " u           g  ",
      " u           gf ",
      " u           g  ",
      " u           g  ",
      " u  J  J     gf ",
      " u  drrdgggggg  ",
      " uNMu  f  f  f  ",
      "                "
    ],
    [
      "                ",
      " uuuu  f  f  f  ",
      " u  drrdgggggg  ",
      " ULLdQsd     gf ",
      " g  d Pd     g  ",
      " g  d  d     g  ",
      " g  d  d     gf ",
      " g  dddO     g  ",
      " g   R       g  ",
      " g           gf ",
      " g           g  ",
      " g           g  ",
      " U  O  O     gf ",
      " u  drrdgggggg  ",
      " uTSu  f  f  f  ",
      "                "
    ],
    [
      "                ",
      " uuuu  f  f  f  ",
      " u  drrdgggggg  ",
      " uL!d  d     gf ",
      " u  d Vd     g  ",
      " u  d Pd     g  ",
      " u  d  d     gf ",
      " u  ddd      g  ",
      " u           g  ",
      " u           gf ",
      " u           g  ",
      " u           g  ",
      " u           gf ",
      " u  drrdgggggg  ",
      " uuuu  f  f  f  ",
      "                "
    ],
    [
      "                ",
      " uuuu  WWWWWWWW ",
      " u  drrWWWWWWWW ",
      " uLLd  dXXXXXWW ",
      " uYYd  dYYYYXWW ",
      " uYYd VdYYYYXWW ",
      " uYYdZPdYYYYXWW ",
      " uYYdddYYYYYXWW ",
      " uYYYYYYYYYYXWW ",
      " uYYYYYYYYYYXWW ",
      " uYYYYYYYYYYXWW ",
      " uYYYYYYYYYYXWW ",
      " uXXXXXXXXXXXWW ",
      " u00drrWWWWWWWW ",
      " uuuu  WWWWWWWW ",
      "                "
    ]
  ]
}