{
  "name": "building_office1b_top_90",
  "refpalette": "deceasedcraft:building_office1b/building_office1b_top_palette_90",
  "xsize": 16,
  "zsize": 16,
  "slices": [
    [
      "                ",
      "        c  iiii ",
      "  aaaaaaceedbbi ",
      "  abbbbbbbbbbbi ",
      "  abbbbbbbbbbbi ",
      "  abbbbbbbbbbbi ",
      "  abbbbbbbbbbbi ",
      "  abbbbbbbbbbbi ",
      "  abbbbbbdddbbi ",
      "  abbbbbdfhdbbi ",
      "  abbbbbd gdbbi ",
      "  abbbbbd  dbbi ",
      "  abbbbbd  dbbi ",
      "  aaaaaaceedbbi ",
      "        c  iiii ",
      "                "
    ],
    [
      "                ",
      "        c  xxxx ",
      "  jjjjjjceedKMx ",
      "  j       wC  x ",
      "  jl p t  wC  x ",
      "  jk p s  wBJ x ",
      "  j        AI x ",
      "  j           x ",
      "  j nnnnnddd  x ",
      "  j moqrd  y  x ",
      "  j     d ud  x ",
      "  j     d  dFLx ",
      "  j     d  dEEx ",
      "  jjjjjjceedDDx ",
      "        c  xxxx ",
      "                "
    ],
    [
      "                ",
      "        c  xxxx ",
      "  N N N ceedXYx ",
      "              x ",
      "           U  x ",
      "              x ",
      "              x ",
      "              x ",
      "    OPQRSddd  x ",
      "       !d  T  x ",
      "        d  d  x ",
      "        d  d  x ",
      "        d  dWWx ",
      "  N N N ceedVVx ",
      "        c  xxxx ",
      "                "
    ],
    [
      "                ",
      "        c  xxxx ",
      "  N N N ceed23x ",
      "           1  4 ",
      "           0  5 ",
      "           0  5 ",
      "           0  5 ",
      "           Z  5 ",
      "         ddd  5 ",
      "        d  d  5 ",
      "        d  d  5 ",
      "        d  d  5 ",
      "        d  dWW4 ",
      "  N N N ceed  x ",
      "        c  xxxx ",
      "                "
    ],
    [
      "                ",
      "        c  xxxx ",
      "  N N N cddd88x ",
      "        dddd77x ",
      "        dddd77x ",
      "     6  dddd77x ",
      "        dddd77x ",
      "        dddd77x ",
      "        dddd77x ",
      "        dddd77x ",
      "     6  dddd77x ",
      "        dddd77x ",
      "        dddd77x ",
      "  N N N cddd77x ",
      "        c  xxxx ",
      "                "
    ],
    [
      "                ",
      "        c  xxxx ",
      "  999999c  %%%x ",
      "  9fffff#  %%%x ",
      "  9fffff#  %%%x ",
      "  9fffff$  %%%x ",
      "  9fffff#  %%%x ",
      "  9fffff#  %%%x ",
      "  9fffff#  %%%x ",
      "  9fffff#  %%%x ",
      "  9fffff$  %%%x ",
      "  9fffff#  %%%x ",
      "  9fffff#  %%%x ",
      "  999999c  %%%x ",
      "        c  xxxx ",
      "                "
    ]
  ]
}