{
  "name": "building_office1b_floor2_270",
  "refpalette": "deceasedcraft:building_office1b/building_office1b_floor2_palette_270",
  "xsize": 16,
  "zsize": 16,
  "slices": [
    [
      "                ",
      " iiii  c        ",
      " ibbdeecaaaaaa  ",
      " ibbd  dbbbbba  ",
      " ibbd  dbbbbba  ",
      " ibbdg dbbbbba  ",
      " ibbdhfdbbbbba  ",
      " ibbdddbbbbbba  ",
      " ibbbbbbbbbbba  ",
      " ibbbbbbbbbbba  ",
      " ibbbbbbbbbbba  ",
      " ibbbbbbbbbbba  ",
      " ibbbbbbbbbbba  ",
      " ibbdeecaaaaaa  ",
      " iiii  c        ",
      "                "
    ],
    [
      "                ",
      " FFFF  c        ",
      " FL deecjjjjjj  ",
      " FM d  dm    j  ",
      " FNJdC d q   j  ",
      " F  dD durnk j  ",
      " F  I  dwsol j  ",
      " F  ddd!xtp  j  ",
      " F   B Ay  m j  ",
      " F  BEBAurnk j  ",
      " F     Awsol j  ",
      " F   B  pt   j  ",
      " FO          j  ",
      " FPKdeecjjjjjj  ",
      " FFFF  c        ",
      "                "
    ],
    [
      "                ",
      " FFFF  c        ",
      " F  deecjjjjjj  ",
      " F3 dg d     j  ",
      " F42dD d     j  ",
      " F  d  dTUQ  j  ",
      " F  1  dXVR  j  ",
      " F  dddZ     j  ",
      " F     Z     j  ",
      " F   0 ZTUS  j  ",
      " F     ZYWT  j  ",
      " F           j  ",
      " F           j  ",
      " F5 deecjjjjjj  ",
      " FFFF  c        ",
      "                "
    ],
    [
      "                ",
      " FFFF  c        ",
      " F  deecjjjjjj  ",
      " ^$ dfgd     j  ",
      " j49d 8d     j  ",
      " j  d  d     j  ",
      " j  d  d     j  ",
      " j  ddd6     j  ",
      " j     R     j  ",
      " j     x     j  ",
      " j     7     j  ",
      " j           j  ",
      " ^           j  ",
      " F%#deecjjjjjj  ",
      " FFFF  c        ",
      "                "
    ],
    [
      "                ",
      " FFFF  c        ",
      " F^^deecjjjjjj  ",
      " F^^d  d     j  ",
      " F]-d +d     j  ",
      " F  d 8d     j  ",
      " F  d  d     j  ",
      " F  ddd&     j  ",
      " F     *     j  ",
      " F     *     j  ",
      " F     (     j  ",
      " F     *     j  ",
      " F     )     j  ",
      " F{[deecjjjjjj  ",
      " FFFF  c        ",
      "                "
    ],
    [
      "                ",
      " FFFF  c        ",
      " F :deecjjjjjj  ",
      " F: d  d}}}}}j  ",
      " F''d  d||||}j  ",
      " F||d +d||||}j  ",
      " F||d;8d||||}j  ",
      " F||ddd|||||}j  ",
      " F||||||||||}j  ",
      " F||||||||||}j  ",
      " F||||||||||}j  ",
      " F||||||||||}j  ",
      " F}}}}}}}}}}}j  ",
      " F<<deecjjjjjj  ",
      " FFFF  c        ",
      "                "
    ]
  ]
}