{
  "name": "building_office1b_floor2_90",
  "refpalette": "deceasedcraft:building_office1b/building_office1b_floor2_palette_90",
  "xsize": 16,
  "zsize": 16,
  "slices": [
    [
      "                ",
      "        c  iiii ",
      "  aaaaaaceedbbi ",
      "  abbbbbbbbbbbi ",
      "  abbbbbbbbbbbi ",
      "  abbbbbbbbbbbi ",
      "  abbbbbbbbbbbi ",
      "  abbbbbbbbbbbi ",
      "  abbbbbbdddbbi ",
      "  abbbbbdfhdbbi ",
      "  abbbbbd gdbbi ",
      "  abbbbbd  dbbi ",
      "  abbbbbd  dbbi ",
      "  aaaaaaceedbbi ",
      "        c  iiii ",
      "                "
    ],
    [
      "                ",
      "        c  FFFF ",
      "  jjjjjjceedKPF ",
      "  j          OF ",
      "  j   tp  B   F ",
      "  j loswA     F ",
      "  j knruABEB  F ",
      "  j m  yA B   F ",
      "  j  ptx!ddd  F ",
      "  j loswd  I  F ",
      "  j knrud Dd  F ",
      "  j   q d CdJNF ",
      "  j    md  d MF ",
      "  jjjjjjceed LF ",
      "        c  FFFF ",
      "                "
    ],
    [
      "                ",
      "        c  FFFF ",
      "  jjjjjjceed 5F ",
      "  j           F ",
      "  j           F ",
      "  j  TWYZ     F ",
      "  j  SUTZ 0   F ",
      "  j     Z     F ",
      "  j     Zddd  F ",
      "  j  RVXd  1  F ",
      "  j  QUTd  d  F ",
      "  j     d Dd24F ",
      "  j     d gd 3F ",
      "  jjjjjjceed  F ",
      "        c  FFFF ",
      "                "
    ],
    [
      "                ",
      "        c  FFFF ",
      "  jjjjjjceed#%F ",
      "  j           ^ ",
      "  j           j ",
      "  j     7     j ",
      "  j     x     j ",
      "  j     R     j ",
      "  j     6ddd  j ",
      "  j     d  d  j ",
      "  j     d  d  j ",
      "  j     d8 d94j ",
      "  j     dgfd $^ ",
      "  jjjjjjceed  F ",
      "        c  FFFF ",
      "                "
    ],
    [
      "                ",
      "        c  FFFF ",
      "  jjjjjjceed[{F ",
      "  j     )     F ",
      "  j     *     F ",
      "  j     (     F ",
      "  j     *     F ",
      "  j     *     F ",
      "  j     &ddd  F ",
      "  j     d  d  F ",
      "  j     d8 d  F ",
      "  j     d+ d-]F ",
      "  j     d  d^^F ",
      "  jjjjjjceed^^F ",
      "        c  FFFF ",
      "                "
    ],
    [
      "                ",
      "        c  FFFF ",
      "  jjjjjjceed<<F ",
      "  j}}}}}}}}}}}F ",
      "  j}||||||||||F ",
      "  j}||||||||||F ",
      "  j}||||||||||F ",
      "  j}||||||||||F ",
      "  j}|||||ddd||F ",
      "  j}||||d8;d||F ",
      "  j}||||d+ d||F ",
      "  j}||||d  d''F ",
      "  j}}}}}d  d :F ",
      "  jjjjjjceed: F ",
      "        c  FFFF ",
      "                "
    ]
  ]
}