{
  "name": "building_office1b_floor1_90",
  "refpalette": "deceasedcraft:building_office1b/building_office1b_floor1_palette_90",
  "xsize": 16,
  "zsize": 16,
  "slices": [
    [
      "                ",
      "        c  iiii ",
      "  aaaaaaceedbbi ",
      "  abbbbbbbbbbbi ",
      "  abbbbbbbbbbbi ",
      "  abbbbbbbbbbbi ",
      "  abbbbbbbbbbbi ",
      "  abbbbbbbbbbbi ",
      "  abbbbbbdddbbi ",
      "  abbbbbdfhdbbi ",
      "  abbbbbd gdbbi ",
      "  abbbbbd  dbbi ",
      "  abbbbbd  dbbi ",
      "  aaaaaaceedbbi ",
      "        c  iiii ",
      "                "
    ],
    [
      "                ",
      "        c  CCCC ",
      "  jjjjjjceedJNC ",
      "  j           C ",
      "  j    w      C ",
      "  j lortx y   C ",
      "  j knqsxyBy  C ",
      "  j   p x y   C ",
      "  j    uxddd  C ",
      "  j lortd  D  C ",
      "  j knqsd Ad  C ",
      "  j  m !d gdIMC ",
      "  j   p d  dFLC ",
      "  jjjjjjceedEKC ",
      "        c  CCCC ",
      "                "
    ],
    [
      "                ",
      "        c  CCCC ",
      "  jjjjjjceed 2C ",
      "  j           C ",
      "  j           C ",
      "  j  RTVW     C ",
      "  j  QSUW X   C ",
      "  j     W     C ",
      "  j     Wddd  C ",
      "  j  PTVd  Y  C ",
      "  j  OSUd  d  C ",
      "  j     d AdZ1C ",
      "  j     d gd 0C ",
      "  jjjjjjceed  C ",
      "        c  CCCC ",
      "                "
    ],
    [
      "                ",
      "        c  CCCC ",
      "  jjjjjjceed9$C ",
      "  j           % ",
      "  j           j ",
      "  j     6     j ",
      "  j     5     j ",
      "  j     4     j ",
      "  j     3ddd  j ",
      "  j     d  d  j ",
      "  j     d  d  j ",
      "  j     d7 d81j ",
      "  j     dgfd #% ",
      "  jjjjjjceed  C ",
      "        c  CCCC ",
      "                "
    ],
    [
      "                ",
      "        c  CCCC ",
      "  jjjjjjceed-]C ",
      "  j     (     C ",
      "  j     &     C ",
      "  j     *     C ",
      "  j     &     C ",
      "  j     &     C ",
      "  j     ^ddd  C ",
      "  j     d  d  C ",
      "  j     d7 d  C ",
      "  j     d) d+[C ",
      "  j     d  d%%C ",
      "  jjjjjjceed%%C ",
      "        c  CCCC ",
      "                "
    ],
    [
      "                ",
      "        c  CCCC ",
      "  jjjjjjceed''C ",
      "  j{{{{{{{{{{{C ",
      "  j{}}}}}}}}}}C ",
      "  j{}}}}}}}}}}C ",
      "  j{}}}}}}}}}}C ",
      "  j{}}}}}}}}}}C ",
      "  j{}}}}}ddd}}C ",
      "  j{}}}}d7|d}}C ",
      "  j{}}}}d) d}}C ",
      "  j{}}}}d  d::C ",
      "  j{{{{{d  d ;C ",
      "  jjjjjjceed; C ",
      "        c  CCCC ",
      "                "
    ]
  ]
}