{
  "name": "building_office1b_floor1",
  "refpalette": "deceasedcraft:building_office1b/building_office1b_floor1_palette",
  "xsize": 16,
  "zsize": 16,
  "slices": [
    [
      "                ",
      "                ",
      "  aaaaaaaaaaaa  ",
      "  abbbbbbbbbba  ",
      "  abbbbbbbbbba  ",
      "  abbbbbbbbbba  ",
      "  abbbbbbbbbba  ",
      "  abbbbbbbbbba  ",
      " ccddddbbbbbbcc ",
      "  e   fdbbbbbe  ",
      "  e  ghdbbbbbe  ",
      " iddddddbbbbbdi ",
      " ibbbbbbbbbbbbi ",
      " ibbbbbbbbbbbbi ",
      " iiiiiiiiiiiiii ",
      "                "
    ],
    [
      "                ",
      "                ",
      "  jjjjjjjjjjjj  ",
      "  j          j  ",
      "  j  kl  kl  j  ",
      "  j mno  no  j  ",
      "  jp qr pqr  j  ",
      "  j !stu stw j  ",
      " ccddddxxxx  cc ",
      "  e    d y   e  ",
      "  e gA dyBy  e  ",
      " CddddDd y   dC ",
      " CEFI        JC ",
      " CKLM        NC ",
      " CCCCCCCCCCCCCC ",
      "                "
    ],
    [
      "                ",
      "                ",
      "  jjjjjjjjjjjj  ",
      "  j          j  ",
      "  j          j  ",
      "  j  OP  QR  j  ",
      "  j  ST  ST  j  ",
      "  j  UV  UV  j  ",
      " ccddddWWWW  cc ",
      "  e    d     e  ",
      "  egA  d X   e  ",
      " CddddYd     dC ",
      " C  Z         C ",
      " C 01        2C ",
      " CCCCCCCCCCCCCC ",
      "                "
    ],
    [
      "                ",
      "                ",
      "  jjjjjjjjjjjj  ",
      "  j          j  ",
      "  j          j  ",
      "  j          j  ",
      "  j          j  ",
      "  j          j  ",
      " ccdddd3456  cc ",
      "  eg7  d     e  ",
      "  ef   d     e  ",
      " Cdddddd     dC ",
      " C  8        9C ",
      " C #1        $C ",
      " CC%jjjjjjjj%CC ",
      "                "
    ],
    [
      "                ",
      "                ",
      "  jjjjjjjjjjjj  ",
      "  j          j  ",
      "  j          j  ",
      "  j          j  ",
      "  j          j  ",
      "  j          j  ",
      " ccdddd^&&*&(cc ",
      "  e )7 d     e  ",
      "  e    d     e  ",
      " Cdddddd     dC ",
      " C%%+        -C ",
      " C%%[        ]C ",
      " CCCCCCCCCCCCCC ",
      "                "
    ],
    [
      "                ",
      "                ",
      "  jjjjjjjjjjjj  ",
      "  j{{{{{{{{{{j  ",
      "  j{}}}}}}}}{j  ",
      "  j{}}}}}}}}{j  ",
      "  j{}}}}}}}}{j  ",
      "  j{}}}}}}}}{j  ",
      " ccdddd}}}}}{cc ",
      "  e  )7d}}}}{e  ",
      "  e   |d}}}}{e  ",
      " Cdddddd}}}}{dC ",
      " C; :}}}}}}}{'C ",
      " C ;:}}}}}}}{'C ",
      " CCCCCCCCCCCCCC ",
      "                "
    ]
  ]
}