{
  "name": "building_office1b_base1",
  "refpalette": "deceasedcraft:building_office1b/building_office1b_base1_palette",
  "xsize": 16,
  "zsize": 16,
  "slices": [
    [
      "vvvvvvvvvvvvvvvv",
      "vaaaaaaaaaaaaaav",
      "vaaaaaaaaaaaaaav",
      "vaaaaaaaaaaaaaav",
      "vaaaaaaaaaaaaaav",
      "vaaaaaaaaaaaaaav",
      "vaaaaaaaaaaaaaav",
      "vaaaaaaaaaaaaaav",
      "vaaaaaaaaaaaaaav",
      "vaaaaaaaaaaaaaav",
      "vaaaaaaaaaaaaaav",
      "vaaaaaaaaaaaaaav",
      "vaaaaaaaaaaaaaav",
      "vaaaaaaaaaaaaaav",
      "vaaaaaaaaaaaaaav",
      "vvvvvvvvvvvvvvvv"
    ],
    [
      "vvvvvvvvvvvvvvvv",
      "vbbbbbbbbbbbbbbv",
      "vbcd        debv",
      "vbf d   g    hbv",
      "vbfi jk  lm nhbv",
      "vbfo jp  qmd hbv",
      "vbc  jr  sm  ebv",
      "vbft ju  qm whbv",
      "vbf ijr  qm xhbv",
      "vbft         hbv",
      "vby  t AA    ebv",
      "vBBCCCBDEBCCCBBv",
      "vBF          IJv",
      "vBF          IJv",
      "vBBBBBBBBBBBBBBv",
      "vvvvvvvvvvvvvvvv"
    ],
    [
      "vvvvvvvvvvvvvvvv",
      "vbbbbbbbbbbbbbbv",
      "vbK          Lbv",
      "vbM           bv",
      "vbN  O    O  Pbv",
      "vbQ  O    O  Rbv",
      "vb! ST    TU Vbv",
      "vbo  O    O  Wbv",
      "vbN  O    O  Pbv",
      "vbX           bv",
      "vbV          Ybv",
      "vBBCCCBZ0BCCCBBv",
      "vBF          12v",
      "vBF           2v",
      "vBBBBBBBBBBBBBBv",
      "vvvvvvvvvvvvvvvv"
    ],
    [
      "vvvvvvvvvvvvvvvv",
      "vbbbbbbbbbbbbbbv",
      "vb            bv",
      "vb3          4bv",
      "vb   O    O   bv",
      "vb   O    O   bv",
      "vb3  T5  6T  4bv",
      "vb   O    O   bv",
      "vb   O    O   bv",
      "vb3          4bv",
      "vb            bv",
      "vBBCCCBBBBCCCBBv",
      "vBF           7v",
      "vBF           7v",
      "vBBBBBBBBBBBBBBv",
      "vvvvvvvvvvvvvvvv"
    ],
    [
      "vvvvvvvvvvvvvvvv",
      "vbbbbbbbbbbbbbbv",
      "vb8          8bv",
      "vb9          #bv",
      "vb8  O    O  8bv",
      "vb8  O    O  8bv",
      "vb9  T    T  #bv",
      "vb8  O    O  8bv",
      "vb8  O    O  8bv",
      "vb9          #bv",
      "vb8          8bv",
      "vBBCCCCCCCCCCBBv",
      "vBF           7v",
      "vBF           7v",
      "vBBBBBBBBBBBBBBv",
      "vvvvvvvvvvvvvvvv"
    ],
    [
      "vvvvvvvvvvvvvvvv",
      "vbbbbbbbbbbbbbbv",
      "vb$$$$$$$$$$$$bv",
      "vb$$$$gg%g$$$$bv",
      "vb$$$$$$$$$$$$bv",
      "vb$$$$$$$$$$$$bv",
      "vb$$$$gggJ$$$$bv",
      "vb$$$$$$$$$$$$bv",
      "vb$$$$$$$$$$$$bv",
      "vb$$$$JJgg$$$$bv",
      "vb$$$$$$$$$$$$bv",
      "vBBBBBBBBBBBBBBv",
      "vBF          ^&v",
      "vBF          ^&v",
      "vBBBBBBBBBBBBBBv",
      "vvvvvvvvvvvvvvvv"
    ]
  ]
}