{
  "name": "building_office1b_top",
  "refpalette": "deceasedcraft:building_office1b/building_office1b_top_palette",
  "xsize": 16,
  "zsize": 16,
  "slices": [
    [
      "                ",
      "                ",
      "  aaaaaaaaaaaa  ",
      "  abbbbbbbbbba  ",
      "  abbbbbbbbbba  ",
      "  abbbbbbbbbba  ",
      "  abbbbbbbbbba  ",
      "  abbbbbbbbbba  ",
      " ccddddbbbbbbcc ",
      "  e   fdbbbbbe  ",
      "  e  ghdbbbbbe  ",
      " iddddddbbbbbdi ",
      " ibbbbbbbbbbbbi ",
      " ibbbbbbbbbbbbi ",
      " iiiiiiiiiiiiii ",
      "                "
    ],
    [
      "                ",
      "                ",
      "  jjjjjjjjjjjj  ",
      "  j       kl j  ",
      "  j   mn     j  ",
      "  j   on  pp j  ",
      "  j   qn     j  ",
      "  j   rn  st j  ",
      " ccddddn     cc ",
      "  e    d     e  ",
      "  e  u d  wwwe  ",
      " xddddyd ABCCdx ",
      " xDEF    IJ  Kx ",
      " xDEL        Mx ",
      " xxxxxxxxxxxxxx ",
      "                "
    ],
    [
      "                ",
      "                ",
      "  N          N  ",
      "                ",
      "  N    O     N  ",
      "       P        ",
      "  N    Q     N  ",
      "      !R        ",
      " ccddddS     cc ",
      "  e    d     e  ",
      "  e    d     e  ",
      " xddddTd   U dx ",
      " xVW         Xx ",
      " xVW         Yx ",
      " xxxxxxxxxxxxxx ",
      "                "
    ],
    [
      "                ",
      "                ",
      "  N          N  ",
      "                ",
      "  N          N  ",
      "                ",
      "  N          N  ",
      "                ",
      " ccdddd      cc ",
      "  e    d     e  ",
      "  e    d     e  ",
      " xddddddZ0001dx ",
      " x W         2x ",
      " x W         3x ",
      " xx4555555554xx ",
      "                "
    ],
    [
      "                ",
      "                ",
      "  N          N  ",
      "                ",
      "  N          N  ",
      "     6    6     ",
      "  N          N  ",
      "                ",
      " ccddddddddddcc ",
      "  dddddddddddd  ",
      "  dddddddddddd  ",
      " xddddddddddddx ",
      " x777777777778x ",
      " x777777777778x ",
      " xxxxxxxxxxxxxx ",
      "                "
    ],
    [
      "                ",
      "                ",
      "  999999999999  ",
      "  9ffffffffff9  ",
      "  9ffffffffff9  ",
      "  9ffffffffff9  ",
      "  9ffffffffff9  ",
      "  9ffffffffff9  ",
      " cc##$####$##cc ",
      "                ",
      "                ",
      " x%%%%%%%%%%%%x ",
      " x%%%%%%%%%%%%x ",
      " x%%%%%%%%%%%%x ",
      " xxxxxxxxxxxxxx ",
      "                "
    ]
  ]
}