{
  "name": "building_office1b_top_270",
  "refpalette": "deceasedcraft:building_office1b/building_office1b_top_palette_270",
  "xsize": 16,
  "zsize": 16,
  "slices": [
    [
      "                ",
      " iiii  c        ",
      " ibbdeecaaaaaa  ",
      " ibbd  dbbbbba  ",
      " ibbd  dbbbbba  ",
      " ibbdg dbbbbba  ",
      " ibbdhfdbbbbba  ",
      " ibbdddbbbbbba  ",
      " ibbbbbbbbbbba  ",
      " ibbbbbbbbbbba  ",
      " ibbbbbbbbbbba  ",
      " ibbbbbbbbbbba  ",
      " ibbbbbbbbbbba  ",
      " ibbdeecaaaaaa  ",
      " iiii  c        ",
      "                "
    ],
    [
      "                ",
      " xxxx  c        ",
      " xDDdeecjjjjjj  ",
      " xEEd  d     j  ",
      " xLFd  d     j  ",
      " x  du d     j  ",
      " x  y  drqom j  ",
      " x  dddnnnnn j  ",
      " x           j  ",
      " x IA        j  ",
      " x JBw  s p kj  ",
      " x  Cw  t p lj  ",
      " x  Cw       j  ",
      " xMKdeecjjjjjj  ",
      " xxxx  c        ",
      "                "
    ],
    [
      "                ",
      " xxxx  c        ",
      " xVVdeec N N N  ",
      " xWWd  d        ",
      " x  d  d        ",
      " x  d  d        ",
      " x  T  d!       ",
      " x  dddSRQPO    ",
      " x              ",
      " x              ",
      " x              ",
      " x  U           ",
      " x              ",
      " xYXdeec N N N  ",
      " xxxx  c        ",
      "                "
    ],
    [
      "                ",
      " xxxx  c        ",
      " x  deec N N N  ",
      " 4WWd  d        ",
      " 5  d  d        ",
      " 5  d  d        ",
      " 5  d  d        ",
      " 5  ddd         ",
      " 5  Z           ",
      " 5  0           ",
      " 5  0           ",
      " 5  0           ",
      " 4  1           ",
      " x32deec N N N  ",
      " xxxx  c        ",
      "                "
    ],
    [
      "                ",
      " xxxx  c        ",
      " x77dddc N N N  ",
      " x77dddd        ",
      " x77dddd        ",
      " x77dddd  6     ",
      " x77dddd        ",
      " x77dddd        ",
      " x77dddd        ",
      " x77dddd        ",
      " x77dddd  6     ",
      " x77dddd        ",
      " x77dddd        ",
      " x88dddc N N N  ",
      " xxxx  c        ",
      "                "
    ],
    [
      "                ",
      " xxxx  c        ",
      " x%%%  c999999  ",
      " x%%%  #fffff9  ",
      " x%%%  #fffff9  ",
      " x%%%  $fffff9  ",
      " x%%%  #fffff9  ",
      " x%%%  #fffff9  ",
      " x%%%  #fffff9  ",
      " x%%%  #fffff9  ",
      " x%%%  $fffff9  ",
      " x%%%  #fffff9  ",
      " x%%%  #fffff9  ",
      " x%%%  c999999  ",
      " xxxx  c        ",
      "                "
    ]
  ]
}