{
  "name": "building_office1b_floor1_270",
  "refpalette": "deceasedcraft:building_office1b/building_office1b_floor1_palette_270",
  "xsize": 16,
  "zsize": 16,
  "slices": [
    [
      "                ",
      " iiii  c        ",
      " ibbdeecaaaaaa  ",
      " ibbd  dbbbbba  ",
      " ibbd  dbbbbba  ",
      " ibbdg dbbbbba  ",
      " ibbdhfdbbbbba  ",
      " ibbdddbbbbbba  ",
      " ibbbbbbbbbbba  ",
      " ibbbbbbbbbbba  ",
      " ibbbbbbbbbbba  ",
      " ibbbbbbbbbbba  ",
      " ibbbbbbbbbbba  ",
      " ibbdeecaaaaaa  ",
      " iiii  c        ",
      "                "
    ],
    [
      "                ",
      " CCCC  c        ",
      " CKEdeecjjjjjj  ",
      " CLFd  d p   j  ",
      " CMIdg d! m  j  ",
      " C  dA dsqnk j  ",
      " C  D  dtrol j  ",
      " C  dddxu    j  ",
      " C   y x p   j  ",
      " C  yByxsqnk j  ",
      " C   y xtrol j  ",
      " C      w    j  ",
      " C           j  ",
      " CNJdeecjjjjjj  ",
      " CCCC  c        ",
      "                "
    ],
    [
      "                ",
      " CCCC  c        ",
      " C  deecjjjjjj  ",
      " C0 dg d     j  ",
      " C1ZdA d     j  ",
      " C  d  dUSO  j  ",
      " C  Y  dVTP  j  ",
      " C  dddW     j  ",
      " C     W     j  ",
      " C   X WUSQ  j  ",
      " C     WVTR  j  ",
      " C           j  ",
      " C           j  ",
      " C2 deecjjjjjj  ",
      " CCCC  c        ",
      "                "
    ],
    [
      "                ",
      " CCCC  c        ",
      " C  deecjjjjjj  ",
      " %# dfgd     j  ",
      " j18d 7d     j  ",
      " j  d  d     j  ",
      " j  d  d     j  ",
      " j  ddd3     j  ",
      " j     4     j  ",
      " j     5     j  ",
      " j     6     j  ",
      " j           j  ",
      " %           j  ",
      " C$9deecjjjjjj  ",
      " CCCC  c        ",
      "                "
    ],
    [
      "                ",
      " CCCC  c        ",
      " C%%deecjjjjjj  ",
      " C%%d  d     j  ",
      " C[+d )d     j  ",
      " C  d 7d     j  ",
      " C  d  d     j  ",
      " C  ddd^     j  ",
      " C     &     j  ",
      " C     &     j  ",
      " C     *     j  ",
      " C     &     j  ",
      " C     (     j  ",
      " C]-deecjjjjjj  ",
      " CCCC  c        ",
      "                "
    ],
    [
      "                ",
      " CCCC  c        ",
      " C ;deecjjjjjj  ",
      " C; d  d{{{{{j  ",
      " C::d  d}}}}{j  ",
      " C}}d )d}}}}{j  ",
      " C}}d|7d}}}}{j  ",
      " C}}ddd}}}}}{j  ",
      " C}}}}}}}}}}{j  ",
      " C}}}}}}}}}}{j  ",
      " C}}}}}}}}}}{j  ",
      " C}}}}}}}}}}{j  ",
      " C{{{{{{{{{{{j  ",
      " C''deecjjjjjj  ",
      " CCCC  c        ",
      "                "
    ]
  ]
}