{
  "name": "building_office1b_ground_90",
  "refpalette": "deceasedcraft:building_office1b/building_office1b_ground_palette_90",
  "xsize": 16,
  "zsize": 16,
  "slices": [
    [
      "aaaaaaaaaaaaaaaa",
      "abbbbbbbbbbbbbba",
      "abccccccddddddba",
      "abcbbbbbbbbbbbba",
      "abcbbbbbbbbbbbba",
      "abcbbbbbbbbbbbba",
      "abcbbbbbbbbbbbba",
      "abcbbbbbbbbbbbba",
      "abcbbbbb!dddbbba",
      "abcbbbbbdbbdbbba",
      "abcbbbbbdbbdbbba",
      "abcbbbbbdbbdbbba",
      "abcbbbbbdbbdbbba",
      "abccccccddddeeba",
      "abbbbbbbbbbbbbba",
      "aaaaaaaaaaaaaaaa"
    ],
    [
      "                ",
      "  f  f  f  uADu ",
      "  ggggggdrrd  u ",
      " fgj l pq  q  u ",
      "  gi l o      u ",
      "  gh l n      u ",
      " fg           u ",
      "  g           u ",
      "  g kkkkqddd  u ",
      " fg   m d  w  u ",
      "  g     d td  u ",
      "  g     d sd  u ",
      " fg     d  dyCu ",
      "  ggggggdrrdxBu ",
      "  f  f  f  uuuu ",
      "                "
    ],
    [
      "                ",
      "  f  f  f  uMNu ",
      "  ggggggdrrd  u ",
      " fg     J  J  u ",
      "  g           u ",
      "  g           u ",
      " fg           u ",
      "  g           u ",
      "  g EF IJddd  u ",
      " fg     d  K  u ",
      "  g     d  d  u ",
      "  g     d td  u ",
      " fg     d sdLLu ",
      "  ggggggdrrd  u ",
      "  f  f  f  uuuu ",
      "                "
    ],
    [
      "                ",
      "  f  f  f  uSTu ",
      "  ggggggdrrd  u ",
      " fg     O  O  U ",
      "  g           g ",
      "  g           g ",
      " fg           g ",
      "  g       R   g ",
      "  g     Oddd  g ",
      " fg     d  d  g ",
      "  g     d  d  g ",
      "  g     dP d  g ",
      " fg     dsQdLLU ",
      "  ggggggdrrd  u ",
      "  f  f  f  uuuu ",
      "                "
    ],
    [
      "                ",
      "  f  f  f  uuuu ",
      "  ggggggdrrd  u ",
      " fg           u ",
      "  g           u ",
      "  g           u ",
      " fg           u ",
      "  g           u ",
      "  g      ddd  u ",
      " fg     d  d  u ",
      "  g     dP d  u ",
      "  g     dV d  u ",
      " fg     d  d!Lu ",
      "  ggggggdrrd  u ",
      "  f  f  f  uuuu ",
      "                "
    ],
    [
      "                ",
      " WWWWWWWW  uuuu ",
      " WWWWWWWWrrd00u ",
      " WWXXXXXXXXXXXu ",
      " WWXYYYYYYYYYYu ",
      " WWXYYYYYYYYYYu ",
      " WWXYYYYYYYYYYu ",
      " WWXYYYYYYYYYYu ",
      " WWXYYYYYdddYYu ",
      " WWXYYYYdPZdYYu ",
      " WWXYYYYdV dYYu ",
      " WWXYYYYd  dYYu ",
      " WWXXXXXd  dLLu ",
      " WWWWWWWWrrd  u ",
      " WWWWWWWW  uuuu ",
      "                "
    ]
  ]
}