{
  "name": "building_office1b_ground",
  "refpalette": "deceasedcraft:building_office1b/building_office1b_ground_palette",
  "xsize": 16,
  "zsize": 16,
  "slices": [
    [
      "aaaaaaaaaaaaaaaa",
      "abbbbbbbbbbbbbba",
      "abccccccccccccba",
      "abcbbbbbbbbbbcba",
      "abcbbbbbbbbbbcba",
      "abcbbbbbbbbbbcba",
      "abcbbbbbbbbbbcba",
      "abcbbbbbbbbbbcba",
      "abddddd!bbbbbdba",
      "abdbbbbdbbbbbdba",
      "abdbbbbdbbbbbdba",
      "abddddddbbbbbdba",
      "abebbbbbbbbbbdba",
      "abebbbbbbbbbbdba",
      "abbbbbbbbbbbbbba",
      "aaaaaaaaaaaaaaaa"
    ],
    [
      "                ",
      "   f  f  f  f   ",
      " fggggggggggggf ",
      "  g       hijg  ",
      "  g    k     g  ",
      " fg    k  lllgf ",
      "  g   mk     g  ",
      "  g    k  nopg  ",
      " fdddddq    qdf ",
      "  r    d     r  ",
      "  r st d     r  ",
      " uddddwd    qdu ",
      " uxy          A ",
      " uBC          D ",
      " uuuuuuuuuuuuuu ",
      "                "
    ],
    [
      "                ",
      "   f  f  f  f   ",
      " fggggggggggggf ",
      "  g          g  ",
      "  g    E     g  ",
      " fg    F     gf ",
      "  g          g  ",
      "  g    I     g  ",
      " fdddddJ    Jdf ",
      "  r    d     r  ",
      "  rst  d     r  ",
      " uddddKd    Jdu ",
      " u L          M ",
      " u L          N ",
      " uuuuuuuuuuuuuu ",
      "                "
    ],
    [
      "                ",
      "   f  f  f  f   ",
      " fggggggggggggf ",
      "  g          g  ",
      "  g          g  ",
      " fg          gf ",
      "  g          g  ",
      "  g          g  ",
      " fdddddO    Odf ",
      "  rsP  d     r  ",
      "  rQ   dR    r  ",
      " udddddd    Odu ",
      " u L          S ",
      " u L          T ",
      " uuUggggggggUuu ",
      "                "
    ],
    [
      "                ",
      "   f  f  f  f   ",
      " fggggggggggggf ",
      "  g          g  ",
      "  g          g  ",
      " fg          gf ",
      "  g          g  ",
      "  g          g  ",
      " fddddd      df ",
      "  r VP d     r  ",
      "  r    d     r  ",
      " udddddd     du ",
      " u !          u ",
      " u L          u ",
      " uuuuuuuuuuuuuu ",
      "                "
    ],
    [
      "                ",
      " WWWWWWWWWWWWWW ",
      " WWWWWWWWWWWWWW ",
      " WWXXXXXXXXXXWW ",
      " WWXYYYYYYYYXWW ",
      " WWXYYYYYYYYXWW ",
      " WWXYYYYYYYYXWW ",
      " WWXYYYYYYYYXWW ",
      " WWddddYYYYYXWW ",
      "  r  VPdYYYYXr  ",
      "  r   ZdYYYYXr  ",
      " uddddddYYYYXdu ",
      " u LYYYYYYYYX0u ",
      " u LYYYYYYYYX0u ",
      " uuuuuuuuuuuuuu ",
      "                "
    ]
  ]
}