{
  "name": "building_office1b_top_180",
  "refpalette": "deceasedcraft:building_office1b/building_office1b_top_palette_180",
  "xsize": 16,
  "zsize": 16,
  "slices": [
    [
      "                ",
      " iiiiiiiiiiiiii ",
      " ibbbbbbbbbbbbi ",
      " ibbbbbbbbbbbbi ",
      " idbbbbbddddddi ",
      "  ebbbbbdhg  e  ",
      "  ebbbbbdf   e  ",
      " ccbbbbbbddddcc ",
      "  abbbbbbbbbba  ",
      "  abbbbbbbbbba  ",
      "  abbbbbbbbbba  ",
      "  abbbbbbbbbba  ",
      "  abbbbbbbbbba  ",
      "  aaaaaaaaaaaa  ",
      "                ",
      "                "
    ],
    [
      "                ",
      " xxxxxxxxxxxxxx ",
      " xM        LEDx ",
      " xK  JI    FEDx ",
      " xdCCBA dyddddx ",
      "  ewww  d u  e  ",
      "  e     d    e  ",
      " cc     nddddcc ",
      "  j ts  nr   j  ",
      "  j     nq   j  ",
      "  j pp  no   j  ",
      "  j     nm   j  ",
      "  j lk       j  ",
      "  jjjjjjjjjjjj  ",
      "                ",
      "                "
    ],
    [
      "                ",
      " xxxxxxxxxxxxxx ",
      " xY         WVx ",
      " xX         WVx ",
      " xd U   dTddddx ",
      "  e     d    e  ",
      "  e     d    e  ",
      " cc     Sddddcc ",
      "        R!      ",
      "  N     Q    N  ",
      "        P       ",
      "  N     O    N  ",
      "                ",
      "  N          N  ",
      "                ",
      "                "
    ],
    [
      "                ",
      " xx4555555554xx ",
      " x3         W x ",
      " x2         W x ",
      " xd1000Zddddddx ",
      "  e     d    e  ",
      "  e     d    e  ",
      " cc      ddddcc ",
      "                ",
      "  N          N  ",
      "                ",
      "  N          N  ",
      "                ",
      "  N          N  ",
      "                ",
      "                "
    ],
    [
      "                ",
      " xxxxxxxxxxxxxx ",
      " x877777777777x ",
      " x877777777777x ",
      " xddddddddddddx ",
      "  dddddddddddd  ",
      "  dddddddddddd  ",
      " ccddddddddddcc ",
      "                ",
      "  N          N  ",
      "     6    6     ",
      "  N          N  ",
      "                ",
      "  N          N  ",
      "                ",
      "                "
    ],
    [
      "                ",
      " xxxxxxxxxxxxxx ",
      " x%%%%%%%%%%%%x ",
      " x%%%%%%%%%%%%x ",
      " x%%%%%%%%%%%%x ",
      "                ",
      "                ",
      " cc##$####$##cc ",
      "  9ffffffffff9  ",
      "  9ffffffffff9  ",
      "  9ffffffffff9  ",
      "  9ffffffffff9  ",
      "  9ffffffffff9  ",
      "  999999999999  ",
      "                ",
      "                "
    ]
  ]
}