{
  "name": "building_office1b_base1_180",
  "refpalette": "deceasedcraft:building_office1b/building_office1b_base1_palette_180",
  "xsize": 16,
  "zsize": 16,
  "slices": [
    [
      "vvvvvvvvvvvvvvvv",
      "vaaaaaaaaaaaaaav",
      "vaaaaaaaaaaaaaav",
      "vaaaaaaaaaaaaaav",
      "vaaaaaaaaaaaaaav",
      "vaaaaaaaaaaaaaav",
      "vaaaaaaaaaaaaaav",
      "vaaaaaaaaaaaaaav",
      "vaaaaaaaaaaaaaav",
      "vaaaaaaaaaaaaaav",
      "vaaaaaaaaaaaaaav",
      "vaaaaaaaaaaaaaav",
      "vaaaaaaaaaaaaaav",
      "vaaaaaaaaaaaaaav",
      "vaaaaaaaaaaaaaav",
      "vvvvvvvvvvvvvvvv"
    ],
    [
      "vvvvvvvvvvvvvvvv",
      "vBBBBBBBBBBBBBBv",
      "vJI          FBv",
      "vJI          FBv",
      "vBBCCCBEDBCCCBBv",
      "vbe    AA t  ybv",
      "vbh         tfbv",
      "vbhx mq  rji fbv",
      "vbhw mq  uj tfbv",
      "vbe  ms  rj  cbv",
      "vbh dmq  pj ofbv",
      "vbhn ml  kj ifbv",
      "vbh    g   d fbv",
      "vbed        dcbv",
      "vbbbbbbbbbbbbbbv",
      "vvvvvvvvvvvvvvvv"
    ],
    [
      "vvvvvvvvvvvvvvvv",
      "vBBBBBBBBBBBBBBv",
      "v2           FBv",
      "v21          FBv",
      "vBBCCCB0ZBCCCBBv",
      "vbY          Vbv",
      "vb           Xbv",
      "vbP  O    O  Nbv",
      "vbW  O    O  obv",
      "vbV UT    TS !bv",
      "vbR  O    O  Qbv",
      "vbP  O    O  Nbv",
      "vb           Mbv",
      "vbL          Kbv",
      "vbbbbbbbbbbbbbbv",
      "vvvvvvvvvvvvvvvv"
    ],
    [
      "vvvvvvvvvvvvvvvv",
      "vBBBBBBBBBBBBBBv",
      "v7           FBv",
      "v7           FBv",
      "vBBCCCBBBBCCCBBv",
      "vb            bv",
      "vb4          3bv",
      "vb   O    O   bv",
      "vb   O    O   bv",
      "vb4  T6  5T  3bv",
      "vb   O    O   bv",
      "vb   O    O   bv",
      "vb4          3bv",
      "vb            bv",
      "vbbbbbbbbbbbbbbv",
      "vvvvvvvvvvvvvvvv"
    ],
    [
      "vvvvvvvvvvvvvvvv",
      "vBBBBBBBBBBBBBBv",
      "v7           FBv",
      "v7           FBv",
      "vBBCCCCCCCCCCBBv",
      "vb8          8bv",
      "vb#          9bv",
      "vb8  O    O  8bv",
      "vb8  O    O  8bv",
      "vb#  T    T  9bv",
      "vb8  O    O  8bv",
      "vb8  O    O  8bv",
      "vb#          9bv",
      "vb8          8bv",
      "vbbbbbbbbbbbbbbv",
      "vvvvvvvvvvvvvvvv"
    ],
    [
      "vvvvvvvvvvvvvvvv",
      "vBBBBBBBBBBBBBBv",
      "v&^          FBv",
      "v&^          FBv",
      "vBBBBBBBBBBBBBBv",
      "vb$$$$$$$$$$$$bv",
      "vb$$$$ggJJ$$$$bv",
      "vb$$$$$$$$$$$$bv",
      "vb$$$$$$$$$$$$bv",
      "vb$$$$Jggg$$$$bv",
      "vb$$$$$$$$$$$$bv",
      "vb$$$$$$$$$$$$bv",
      "vb$$$$g%gg$$$$bv",
      "vb$$$$$$$$$$$$bv",
      "vbbbbbbbbbbbbbbv",
      "vvvvvvvvvvvvvvvv"
    ]
  ]
}