{
  "name": "building_office1b_floor3_180",
  "refpalette": "deceasedcraft:building_office1b/building_office1b_floor3_palette_180",
  "xsize": 16,
  "zsize": 16,
  "slices": [
    [
      "                ",
      " iiiiiiiiiiiiii ",
      " ibbbbbbbbbbbbi ",
      " ibbbbbbbbbbbbi ",
      " idbbbbbddddddi ",
      "  ebbbbbdhg  e  ",
      "  ebbbbbdf   e  ",
      " ccbbbbbbddddcc ",
      "  abbbbbbbbbba  ",
      "  abbbbbbbbbba  ",
      "  abbbbbbbbbba  ",
      "  abbbbbbbbbba  ",
      "  abbbbbbbbbba  ",
      "  aaaaaaaaaaaa  ",
      "                ",
      "                "
    ],
    [
      "                ",
      " yyyyyyyyyyyyyy ",
      " yK        JIFy ",
      " yE        D Cy ",
      " yd    BdAddddy ",
      "  e    xd wg e  ",
      "  e    ud    e  ",
      " ccdtsdddddddcc ",
      "  j         rj  ",
      "  j   q q q pj  ",
      "  j  nnnnnn mj  ",
      "  j onnnnnn mj  ",
      "  j   l l l kj  ",
      "  jjjjjjjjjjjj  ",
      "                ",
      "                "
    ],
    [
      "                ",
      " yyyyyyyyyyyyyy ",
      " yZ        10 y ",
      " yZ        Y  y ",
      " yd     dXddddy ",
      "  e     d  wge  ",
      "  e    !d    e  ",
      " ccdWVdddddddcc ",
      "  j         Uj  ",
      "  j         Tj  ",
      "  j  SR M M Qj  ",
      "  j  PM ONM Lj  ",
      "  j          j  ",
      "  jjjjjjjjjjjj  ",
      "                ",
      "                "
    ],
    [
      "                ",
      " yy7jjjjjjjj7yy ",
      " yZ        16 y ",
      " yZ        5  y ",
      " yd     ddddddy ",
      "  e     d   fe  ",
      "  e     d  4ge  ",
      " ccd33dddddddcc ",
      "  j         2j  ",
      "  j          j  ",
      "  j          j  ",
      "  j          j  ",
      "  j          j  ",
      "  jjjjjjjjjjjj  ",
      "                ",
      "                "
    ],
    [
      "                ",
      " yyyyyyyyyyyyyy ",
      " y%        $77y ",
      " y#        977y ",
      " yd     ddddddy ",
      "  e     d    e  ",
      "  e     d 48 e  ",
      " ccddddddddddcc ",
      "  j          j  ",
      "  j          j  ",
      "  j          j  ",
      "  j          j  ",
      "  j          j  ",
      "  jjjjjjjjjjjj  ",
      "                ",
      "                "
    ],
    [
      "                ",
      " yyyyyyyyyyyyyy ",
      " y*^&&&&&&&+) y ",
      " y*^&&&&&&&+ )y ",
      " yd^&&&&ddddddy ",
      "  e^&&&&d(   e  ",
      "  e^&&&&d48  e  ",
      " ccddddddddddcc ",
      "  j^********^j  ",
      "  j^&&&&&&&&^j  ",
      "  j^&&&&&&&&^j  ",
      "  j^&&&&&&&&^j  ",
      "  j^^^^^^^^^^j  ",
      "  jjjjjjjjjjjj  ",
      "                ",
      "                "
    ]
  ]
}