{
  "name": "building_office1b_floor3_270",
  "refpalette": "deceasedcraft:building_office1b/building_office1b_floor3_palette_270",
  "xsize": 16,
  "zsize": 16,
  "slices": [
    [
      "                ",
      " iiii  c        ",
      " ibbdeecaaaaaa  ",
      " ibbd  dbbbbba  ",
      " ibbd  dbbbbba  ",
      " ibbdg dbbbbba  ",
      " ibbdhfdbbbbba  ",
      " ibbdddbbbbbba  ",
      " ibbbbbbbbbbba  ",
      " ibbbbbbbbbbba  ",
      " ibbbbbbbbbbba  ",
      " ibbbbbbbbbbba  ",
      " ibbbbbbbbbbba  ",
      " ibbdeecaaaaaa  ",
      " iiii  c        ",
      "                "
    ],
    [
      "                ",
      " yyyy  c        ",
      " yFCdeecjjjjjj  ",
      " yI d  drpmmkj  ",
      " yJDdg d     j  ",
      " y  dw d qnnlj  ",
      " y  A  d  nn j  ",
      " y  dddd qnnlj  ",
      " y  Bxud  nn j  ",
      " y     d qnnlj  ",
      " y     s  nn j  ",
      " y     t   o j  ",
      " y     d     j  ",
      " yKEdeecjjjjjj  ",
      " yyyy  c        ",
      "                "
    ],
    [
      "                ",
      " yyyy  c        ",
      " y  deecjjjjjj  ",
      " y0 dg dUTQL j  ",
      " y1Ydw d     j  ",
      " y  d  d  MM j  ",
      " y  X  d   N j  ",
      " y  dddd  MO j  ",
      " y    !d     j  ",
      " y     d  RM j  ",
      " y     V  SP j  ",
      " y     W     j  ",
      " y     d     j  ",
      " yZZdeecjjjjjj  ",
      " yyyy  c        ",
      "                "
    ],
    [
      "                ",
      " yyyy  c        ",
      " y  deecjjjjjj  ",
      " 76 dfgd2    j  ",
      " j15d 4d     j  ",
      " j  d  d     j  ",
      " j  d  d     j  ",
      " j  dddd     j  ",
      " j     d     j  ",
      " j     d     j  ",
      " j     3     j  ",
      " j     3     j  ",
      " 7     d     j  ",
      " yZZdeecjjjjjj  ",
      " yyyy  c        ",
      "                "
    ],
    [
      "                ",
      " yyyy  c        ",
      " y77deecjjjjjj  ",
      " y77d  d     j  ",
      " y$9d 8d     j  ",
      " y  d 4d     j  ",
      " y  d  d     j  ",
      " y  dddd     j  ",
      " y     d     j  ",
      " y     d     j  ",
      " y     d     j  ",
      " y     d     j  ",
      " y     d     j  ",
      " y%#deecjjjjjj  ",
      " yyyy  c        ",
      "                "
    ],
    [
      "                ",
      " yyyy  c        ",
      " y )deecjjjjjj  ",
      " y) d  d^^^^^j  ",
      " y++d  d*&&&^j  ",
      " y&&d 8d*&&&^j  ",
      " y&&d(4d*&&&^j  ",
      " y&&dddd*&&&^j  ",
      " y&&&&&d*&&&^j  ",
      " y&&&&&d*&&&^j  ",
      " y&&&&&d*&&&^j  ",
      " y&&&&&d*&&&^j  ",
      " y^^^^^d^^^^^j  ",
      " y**deecjjjjjj  ",
      " yyyy  c        ",
      "                "
    ]
  ]
}