{
  "name": "multi_nuclearpowerplant_22_base3",
  "refpalette": "deceasedcraft:multi_nuclearpowerplant_22/multi_nuclearpowerplant_22_base3_palette",
  "xsize": 16,
  "zsize": 16,
  "slices": [
    [
      "   aabcccccccccc",
      "    aabccccccccc",
      "     aabcccccccc",
      "      aabccccccc",
      "       aabcccccc",
      "        adbccccc",
      "         aabcccc",
      "          abcccc",
      "          aabccc",
      "           aabcc",
      "            abcc",
      "            aabc",
      "             abc",
      "             aab",
      "              ab",
      "              ab"
    ],
    [
      "     e          ",
      "      e         ",
      "       e        ",
      "        e       ",
      "         e      ",
      "         fe     ",
      "           e    ",
      "           e    ",
      "            e   ",
      "             e  ",
      "             e  ",
      "              e ",
      "              e ",
      "               e",
      "               e",
      "               e"
    ],
    [
      "     e          ",
      "      e         ",
      "       e        ",
      "        e       ",
      "         e      ",
      "         fe     ",
      "           e    ",
      "           e    ",
      "            e   ",
      "             e  ",
      "             e  ",
      "              e ",
      "              e ",
      "               e",
      "               e",
      "               e"
    ],
    [
      "     e          ",
      "      e         ",
      "       e        ",
      "        e       ",
      "         e      ",
      "         fe     ",
      "           e    ",
      "           e    ",
      "            e   ",
      "             e  ",
      "             e  ",
      "              e ",
      "              e ",
      "               e",
      "               e",
      "               e"
    ],
    [
      "     e          ",
      "      e         ",
      "       e        ",
      "        e       ",
      "         e      ",
      "         fe     ",
      "           e    ",
      "           e    ",
      "            e   ",
      "             e  ",
      "             e  ",
      "              e ",
      "              e ",
      "               e",
      "               e",
      "               e"
    ],
    [
      "     e          ",
      "      e         ",
      "       e        ",
      "        e       ",
      "         e      ",
      "         fe     ",
      "           e    ",
      "           e    ",
      "            e   ",
      "             e  ",
      "             e  ",
      "              e ",
      "              e ",
      "               e",
      "               e",
      "               e"
    ]
  ]
}