{
  "name": "multi_nuclearpowerplant_22_base12",
  "refpalette": "deceasedcraft:multi_nuclearpowerplant_22/multi_nuclearpowerplant_22_base12_palette",
  "xsize": 16,
  "zsize": 16,
  "slices": [
    [
      "aaaaaaaaaaaaaaaa",
      "aaaaaaaaaaaaaaaa",
      "aaaaaaaaaaaaaaaa",
      "aaaaaaaaaaaaaaaa",
      "aaaaaaaaaaaaaaaa",
      "aaaaaaaaaaaaaaaa",
      "aaaaaaaaaaaaaaaa",
      "aaaaaaaaaaaaaaaa",
      "aaaaaaaaaaaaaaaa",
      "aaaaaaaaaaaaaaaa",
      "aaaaaaaaaaaaaaaa",
      "aaaaaaaaaaaaaaaa",
      "aaaaaaaaaaaaaaaa",
      "aaaaaaaaaaaaaaaa",
      "aaaaaaaaaaaaaaaa",
      "aaaaaaaaaaaaaaaa"
    ],
    [
      "aaaaaaaaaaaaaaaa",
      "aaaaaaaaaaaaaaaa",
      "aaaaaaaaaaaaaaaa",
      "aaaaaaaaaaaaaaaa",
      "aaaaaaaaaaaaaaaa",
      "bbbbbbbbbbbbbbbb",
      "bbbbbbbbbbbbbbbb",
      "bbbbbbbbbbbbbbbb",
      "bbbbbbbbbbbbbbbb",
      "bbbbbbbbbbbbbbbb",
      "bbbbbbbbbbbbbbbb",
      "bbbbbbbbbbbbbbbb",
      "bbbbbbbbbbbbbbbb",
      "bbbbbbbbbbbbbbbb",
      "bbbbbbbbbbbbbbbb",
      "bbbbbbbbbbbbbbbb"
    ],
    [
      "aaaaaaaaaaaaaaaa",
      "aaaaaaaaaaaaaaaa",
      "aaaaaaaaaaaaaaaa",
      "aaaaaaaaaaaaaaaa",
      "aaaaaaaaaaaaaaaa",
      "cbbbccbbbbbbbbbb",
      "cdddccdddddddddd",
      "cefecceggggggggg",
      "cefecceggggggggg",
      "eeeeeeeggggggggg",
      "gggggggggggggggg",
      "gggggggggggggggg",
      "gggggggggggggggg",
      "gggggggggggggggg",
      "gggggggggggggggg",
      "gggggggggggggggg"
    ],
    [
      "aaaaaaaaaaaaaaaa",
      "aaaaaaaaaaaaaaaa",
      "aaaaaaaaaaaaaaaa",
      "aaaaaaaaaaaaaaaa",
      "aaaaaaaaaaaaaaaa",
      "cbbbccbbbbbbbbbb",
      "hdddhhdddddddddd",
      "ijkliijmm no    ",
      "pj lppj         ",
      "                ",
      "                ",
      "                ",
      "                ",
      "                ",
      "               q",
      "              rs"
    ],
    [
      "aaaaaaaaaaaaaaaa",
      "aaaaaaaaaaaaaaaa",
      "aaaaaaaaaaaaaaaa",
      "aaaaaaaaaaaaaaaa",
      "aaaaaaaaaaaaaaaa",
      "cbbbccbbbbbbbbbb",
      "tdddutdddddddddd",
      "ijwlxijmm   o   ",
      "fj llfj         ",
      "y    y          ",
      "                ",
      "                ",
      "                ",
      "                ",
      "              q ",
      "             rsA"
    ],
    [
      "aaaaaaaaaaaaaaaa",
      "aaaaaaaaaaaaaaaa",
      "aaaaaaaaaaaaaaaa",
      "aaaaaaaaaaaaaaaa",
      "aaaaaaaaaaaaaaaa",
      "cbbbccbbbbbbbbbb",
      "tdddutdddddddddd",
      "ij lxijmm    o  ",
      "Bj llBj         ",
      "                ",
      "                ",
      "                ",
      "                ",
      "                ",
      "             q  ",
      "            rsA "
    ]
  ]
}