{
  "name": "multi_nuclearpowerplant_22_base11",
  "refpalette": "deceasedcraft:multi_nuclearpowerplant_22/multi_nuclearpowerplant_22_base11_palette",
  "xsize": 16,
  "zsize": 16,
  "slices": [
    [
      "aaaaaaaaaaaaaaaa",
      "aaaaaaaaaaaaaaaa",
      "aaaaaaaaaaaaaaaa",
      "aaaaaaaaaaaaaaaa",
      "aaaaaaaaaaaaaaaa",
      "bcccbbcccccccccc",
      "deeefdeeeeeeeeee",
      "ghijkghll     m ",
      "nh jjnh         ",
      "o    o          ",
      "                ",
      "                ",
      "                ",
      "                ",
      "            p   ",
      "           qrs  "
    ],
    [
      "aaaaaaaaaaaaaaaa",
      "aaaaaaaaaaaaaaaa",
      "aaaaaaaaaaaaaaaa",
      "aaaaaaaaaaaaaaaa",
      "aaaaaaaaaaaaaaaa",
      "bcccbbcccccccccc",
      "teeeuueeeeeeeeee",
      "wh jxwhll      m",
      "wh jwwh         ",
      "                ",
      "                ",
      "                ",
      "                ",
      "                ",
      "           p    ",
      "          qrs   "
    ],
    [
      "aaaaaaaaaaaaaaaa",
      "aaaaaaaaaaaaaaaa",
      "aaaaaaaaaaaaaaaa",
      "aaaaaaaaaaaaaaaa",
      "aaaaaaaaaaaaaaaa",
      "cccccccccccccccc",
      "eeeeeeeeeeeeeeee",
      "    y  ll       ",
      "                ",
      "                ",
      "                ",
      "                ",
      "                ",
      "                ",
      "          p     ",
      "          rs    "
    ],
    [
      "aaaaaaaaaaaaaaaa",
      "aaaaaaaaaaaaaaaa",
      "aaaaaaaaaaaaaaaa",
      "aaaaaaaaaaaaaaaa",
      "aaaaaaaaaaaaaaaa",
      "cccccccccccccccc",
      "eeeeeeeeeeeeeeee",
      "    A  ll       ",
      "                ",
      "                ",
      "                ",
      "                ",
      "                ",
      "                ",
      "         p      ",
      "         rs     "
    ],
    [
      "aaaaaaaaaaaaaaaa",
      "aaaaaaaaaaaaaaaa",
      "aaaaaaaaaaaaaaaa",
      "aaaaaaaaaaaaaaaa",
      "aaaaaaaaaaaaaaaa",
      "cccccccccccccccc",
      "eeeeeeeeeeeeeeee",
      "AAA A  ll       ",
      "                ",
      "                ",
      "                ",
      "                ",
      "                ",
      "                ",
      "ppppppppp       ",
      "BBBBBBBBBs      "
    ],
    [
      "aaaaaaaaaaaaaaaa",
      "aaaaaaaaaaaaaaaa",
      "aaaaaaaaaaaaaaaa",
      "aaaaaaaaaaaaaaaa",
      "aaaaaaaaaaaaaaaa",
      "cccccccccccccccc",
      "eeeeeeeeeeeeeeee",
      "  A A  ll       ",
      "                ",
      "                ",
      "                ",
      "                ",
      "                ",
      "                ",
      "                ",
      "sssssssss       "
    ]
  ]
}