{
  "name": "multi_nuclearpowerplant_22_ground",
  "refpalette": "deceasedcraft:multi_nuclearpowerplant_22/multi_nuclearpowerplant_22_ground_palette",
  "xsize": 16,
  "zsize": 16,
  "slices": [
    [
      "                ",
      "                ",
      "                ",
      "                ",
      "                ",
      "                ",
      "                ",
      "                ",
      "                ",
      "                ",
      "                ",
      "                ",
      "                ",
      "                ",
      "                ",
      "                "
    ],
    [
      "     aaaaaaaaaaa",
      "        aaaaaaaa",
      "           aaaaa",
      "            aaaa",
      "              aa",
      "               a",
      "                ",
      "                ",
      "                ",
      "                ",
      "                ",
      "                ",
      "                ",
      "                ",
      "                ",
      "                "
    ],
    [
      "aaaaaaaaazzzzzzb",
      "aaaaaaaaaaazzzzz",
      "aaaaaaaaaaaaazzz",
      "aaaaaaaaaaaaaaaz",
      "aaaaaaaaaaaaaaaa",
      "  aaaaaaaaaaaaaa",
      "     aaaaaaaaaaa",
      "       aaaaaaaaa",
      "        aaaaaaaa",
      "         aaaaaaa",
      "          aaaaaa",
      "           aaaaa",
      "            aaaa",
      "             aaa",
      "             aaa",
      "              aa"
    ],
    [
      "zzzzzzzzzc      ",
      "zzzzzzzzzzz     ",
      "zzzzzzzzzzzzzz  ",
      "zzzzzzbzzzzzzzz ",
      "aaazzzzzzzzzzzzz",
      "aaaaaazzzzzzzzzz",
      "aaaaaaaazzzzzzzz",
      "aaaaaaaaazzzzzzz",
      "aaaaaaaaaazzzzzz",
      "aaaaaaaaaaazzzzz",
      "aaaaaaaaaaaazzzz",
      "  aaaaaaaaaaazzz",
      "   aaaaaaaaaaazz",
      "    aaaaaaaaaazz",
      "     aaaaaaaaaaz",
      "      aaaaaaaaaz"
    ],
    [
      "                ",
      "    c c         ",
      "                ",
      "  z       c     ",
      "zzzz            ",
      "zzzzzzz   dc c  ",
      "zzzzzzzzc    cc ",
      "zzzzzzzzzc   c  ",
      "zzzzzzzzzzzc    ",
      "azzzzzzzzzzz    ",
      "aaazzzzzzzzzc   ",
      "aaaazzzzzzzzz   ",
      "aaaaazzzzzzzzzcc",
      "aaaaaazzzbzzzzz ",
      "aaaaaaazzzzzzzzz",
      "aaaaaaaazzzzzzz "
    ],
    [
      "                ",
      "                ",
      "                ",
      "  c             ",
      "                ",
      "c  c            ",
      " d              ",
      "  c    c        ",
      "                ",
      "z z             ",
      "zzzb            ",
      "zzzzz c         ",
      "zzzzzc       c  ",
      "zzzzzz       c  ",
      "zzzzzzzc c      ",
      "zzzzzzzz   cdc  "
    ]
  ]
}