{
  "name": "multi_nuclearpowerplant_22_base2",
  "refpalette": "deceasedcraft:multi_nuclearpowerplant_22/multi_nuclearpowerplant_22_base2_palette",
  "xsize": 16,
  "zsize": 16,
  "slices": [
    [
      "     a          ",
      "      a         ",
      "       a        ",
      "        a       ",
      "         a      ",
      "         ba     ",
      "           a    ",
      "           a    ",
      "            a   ",
      "             a  ",
      "             a  ",
      "              a ",
      "              a ",
      "               a",
      "               a",
      "               a"
    ],
    [
      "     a          ",
      "      a         ",
      "       a        ",
      "        a       ",
      "         a      ",
      "         ba     ",
      "           a    ",
      "           a    ",
      "            a   ",
      "             a  ",
      "             a  ",
      "              a ",
      "              a ",
      "               a",
      "               a",
      "               a"
    ],
    [
      "     a          ",
      "      a         ",
      "       a        ",
      "        a       ",
      "         a      ",
      "         ba     ",
      "           a    ",
      "           a    ",
      "            a   ",
      "             a  ",
      "             a  ",
      "              a ",
      "              a ",
      "               a",
      "               a",
      "               a"
    ],
    [
      "     a          ",
      "      a         ",
      "       a        ",
      "        a       ",
      "         a      ",
      "         ba     ",
      "           a    ",
      "           a    ",
      "            a   ",
      "             a  ",
      "             a  ",
      "              a ",
      "              a ",
      "               a",
      "               a",
      "               a"
    ],
    [
      "   ccd          ",
      "    ccd         ",
      "     ccd        ",
      "      ccd       ",
      "       ccd      ",
      "        ccd     ",
      "         ccd    ",
      "          cd    ",
      "          ccd   ",
      "           ccd  ",
      "            cd  ",
      "            ccd ",
      "             cd ",
      "             ccd",
      "              cd",
      "              cd"
    ],
    [
      "eeeccffffggfffgg",
      "eeeeccffffffffff",
      "eeeeeccfffffffff",
      "eeeeeeccffffffff",
      "eeeeeeeccfffffff",
      "eeeeeeeeccfffggg",
      " eeeeeeeeccfffff",
      "  eeeeeeeecfffff",
      "    eeeeeeccffff",
      "     eeeeeeccfff",
      "      eeeeeecfff",
      "       eeeeeccff",
      "       eeeeeecff",
      "        eeeeeccf",
      "         eeeeecf",
      "          eeeecf"
    ]
  ]
}