{
  "name": "multi_nuclearpowerplant_22_base6",
  "refpalette": "deceasedcraft:multi_nuclearpowerplant_22/multi_nuclearpowerplant_22_base6_palette",
  "xsize": 16,
  "zsize": 16,
  "slices": [
    [
      "aaaaaaaaaaaaaaaa",
      "aaaaaaaaaaaaaaaa",
      "aaaaaaaaaaaaaaaa",
      "aaaaaaaaaaaaaaaa",
      "aaaaaaaaaaaaaaaa",
      "aaaaaaaaabaaaaaa",
      "aaaaaaaaaaaaaaaa",
      "aaaaaaaaaaaaaaaa",
      "aaaaaaaaaaaaaaaa",
      "aaaaaaaaaaaaaaaa",
      "aaaaaaaaaaaaaaaa",
      "aaaaaaaaaaaaaaaa",
      "aaaaaaaaaaaaaaaa",
      "aaaaaaaaaaaaaaaa",
      "aaaaaaaaaaaaaaaa",
      "aaaaaaaaaaaaaaaa"
    ],
    [
      "          cddddd",
      "          cddddd",
      "          cddddd",
      "          cddddd",
      "          cddddd",
      "        efcddddd",
      "          cddddd",
      "          cddddd",
      "          cddddd",
      "          cddddd",
      "          cddddd",
      "           ggggg",
      "                ",
      "                ",
      "                ",
      "                "
    ],
    [
      "           h h h",
      "            i   ",
      "           h h h",
      "                ",
      "           h h h",
      "         f  i   ",
      "           h h h",
      "                ",
      "           h h h",
      "            i   ",
      "           h h h",
      "                ",
      "                ",
      "                ",
      "                ",
      "                "
    ],
    [
      "           iii i",
      "          ji iki",
      "           iii i",
      "                ",
      "           iii i",
      "         fli imi",
      "           iii i",
      "                ",
      "           iii i",
      "          ni ioi",
      "           iii i",
      "                ",
      "                ",
      "                ",
      "                ",
      "                "
    ],
    [
      "           iii i",
      "           i i i",
      "           iii i",
      "                ",
      "           iii i",
      "         f i i i",
      "           iii i",
      "                ",
      "           iii i",
      "           i i i",
      "           iii i",
      "                ",
      "                ",
      "                ",
      "                ",
      "                "
    ],
    [
      "           iii i",
      "           i i i",
      "           iii i",
      "                ",
      "           iii i",
      "         f i i i",
      "           iii i",
      "                ",
      "           iii i",
      "           i i i",
      "           iii i",
      "                ",
      "                ",
      "                ",
      "                ",
      "                "
    ]
  ]
}