{
  "name": "multi_nuclearpowerplant_22_base1",
  "refpalette": "deceasedcraft:multi_nuclearpowerplant_22/multi_nuclearpowerplant_22_base1_palette",
  "xsize": 16,
  "zsize": 16,
  "slices": [
    [
      "aaaaaaaaaabbbbbb",
      "aaaaaaaaaabbbbbb",
      "aaaaaaaaaaabbbbb",
      "aaaaaaaaaaabbbbb",
      "aaaaaaaaaaaabbbb",
      "aaaaaaaaaaaabbbb",
      "caaaaaaaaaaaabbb",
      "ccaaaaaaaaaaabbb",
      " cccaaaaaaaaabbb",
      "   ccaaaaaaaaabb",
      "    ccaaaaaaaabb",
      "     ccaaaaaaaab",
      "      caaaaaaaab",
      "      ccaaaaaaab",
      "       ccaaaaaaa",
      "        ccaaaaaa"
    ],
    [
      "          dabbbb",
      "          dabbbb",
      "           dabbb",
      "           dabbb",
      "            dabb",
      "            dabb",
      "e            dab",
      "ee           dab",
      " eee         dfa",
      "   ee         da",
      "    ee        df",
      "     ee        d",
      "      e        d",
      "      ee       d",
      "       ee       ",
      "        ee      "
    ],
    [
      "            abbb",
      "            dabb",
      "             dab",
      "             dfa",
      "              da",
      "              df",
      "               d",
      "               d",
      "                ",
      "                ",
      "                ",
      "                ",
      "                ",
      "                ",
      "                ",
      "                "
    ],
    [
      "             dab",
      "              da",
      "               d",
      "                ",
      "                ",
      "                ",
      "                ",
      "                ",
      "                ",
      "                ",
      "                ",
      "                ",
      "                ",
      "                ",
      "                ",
      "                "
    ],
    [
      "               d",
      "                ",
      "                ",
      "                ",
      "                ",
      "                ",
      "                ",
      "                ",
      "                ",
      "                ",
      "                ",
      "                ",
      "                ",
      "                ",
      "                ",
      "                "
    ],
    [
      "                ",
      "                ",
      "                ",
      "                ",
      "                ",
      "                ",
      "                ",
      "                ",
      "                ",
      "                ",
      "                ",
      "                ",
      "                ",
      "                ",
      "                ",
      "                "
    ]
  ]
}