{
  "name": "multi_residentiale_1_ground",
  "refpalette": "deceasedcraft:multi_residentiale_1/multi_residentiale_1_ground_palette",
  "xsize": 16,
  "zsize": 16,
  "slices": [
    [
      "abbbacaddbdcbbbb",
      "abbbdbbddacbbbbb",
      "abbbbbdcdcdcbbbb",
      "abbbdcbdaccdbbbb",
      "abeeeeeeeeeeeebb",
      "eeeeeeeeeeeeeebb",
      "eeeeeffffffeeebb",
      "eeeeeffffffeeebb",
      "eeeeeffffffeeebb",
      "eeeeeffffffeeebb",
      "eeeeeeeeeeeeeebb",
      "abeeeeeeeeeeeebb",
      "abbbbbbbbbbbbbbb",
      "bbbbbbbbbbbbbbbb",
      "abbbbbbbbbbbbbbb",
      "abbaaaaabaaaaaba"
    ],
    [
      "  gh     ij hg g",
      "  ghj i    ihg g",
      "  gh  j     hg g",
      "  gh       jhg g",
      " kvvvvvlmvvvvv g",
      "k v        nov g",
      "            pv g",
      "            qv g",
      "            rv g",
      " k          sv g",
      "t v      uwxyv g",
      "  vvvvvvvvvvvv g",
      "               g",
      "               g",
      "               g",
      "                "
    ],
    [
      "   A        A   ",
      "   A        A   ",
      "   A        A   ",
      "   A        A   ",
      "  vvvvvBCvvvvv  ",
      "  v         ov  ",
      "  D         Ev  ",
      "  D         Fv  ",
      "  D         Iv  ",
      "  D          v  ",
      "  v         Jv  ",
      "  vvvvvvvvvvvv  ",
      "                ",
      "                ",
      "                ",
      "                "
    ],
    [
      "  KL        LM  ",
      "  KL        LM  ",
      "  KL        LM  ",
      "  KL   NN   LM  ",
      "  vvvvvvvvvvvv  ",
      "  v          v  ",
      "  D          v  ",
      "  D          v  ",
      "  D          v  ",
      "  D        O v  ",
      "  v        PJv  ",
      "  vvQQQvvQQQvv  ",
      "                ",
      "                ",
      "                ",
      "                "
    ],
    [
      "   KRRRRRRRRM   ",
      "   KRRRRRRRRM   ",
      "   KRRRRRRRRM   ",
      "   KRRRRRRRRM   ",
      "  vvvvvvvvvvvv  ",
      "  v          v  ",
      "  vS T    T  v  ",
      "  vS         v  ",
      "  vS         v  ",
      "  vS T    U  v  ",
      "  v         Jv  ",
      "  vvvvvvvvvvvv  ",
      "                ",
      "                ",
      "                ",
      "                "
    ],
    [
      "    KVW XYVM    ",
      "    KVWZ 0VM    ",
      "    KVW  1VM    ",
      "    K222222M    ",
      "  vvvvvvvvvvvv  ",
      "  v3333333333v  ",
      "  v3333333333v  ",
      "  v3333333333v  ",
      "  v3333333333v  ",
      "  v3333333333v  ",
      "  v3333333333v  ",
      "  vvvvvvvvvvvv  ",
      "                ",
      "                ",
      "                ",
      "                "
    ]
  ]
}