{
  "name": "multi_laboratory_12_base4",
  "refpalette": "deceasedcraft:multi_laboratory_12/multi_laboratory_12_base4_palette",
  "xsize": 16,
  "zsize": 16,
  "slices": [
    [
      " abbbbbbbbbbbcdv",
      " abbbbbbbbbbbcdv",
      " abbbbbbbbbbbcdv",
      "eabbbbbbbbbbbcdv",
      "abbbfbbbbbbbbcdv",
      "abbbbbbbbbbbbcdv",
      "bbbbbbbbbbbbbcdv",
      "bbbbbbbbbbbbbcdv",
      "bbbbbbbbbbbbbcdv",
      "bbbbbbbbbbbbbcdv",
      "bbbbbbbbbbbbbcdv",
      "bbbbfbbbbbbbbcdv",
      "bbbbbbbbbbbbbcdv",
      "bbbbbbbbbbbbbcdv",
      "bbbbbbbbbbbbbcdv",
      "bbbbbbbbbbbbbcdv"
    ],
    [
      " g  h      ijkdv",
      " g  l      ijkdv",
      " g  m     nijkdv",
      "eg  o      ijkdv",
      "ge  f      ijkdv",
      "gp  o q   rijkdv",
      "    osstu  ijkdv",
      "    owwxu nijkdv",
      "    o  y  r iidv",
      "    o A      cdv",
      "    oBCDEDC  cdv",
      "   efoooooooocdv",
      "    oFFF FFI!cdv",
      "    m        cdv",
      "    J      qKcdv",
      "    L     r Kcdv"
    ],
    [
      " g  M      gjkdv",
      " g  N      gjkdv",
      " g  m      gjkdv",
      "eg  o      gjkdv",
      "gO  f      gjkdv",
      "g   o      gjkdv",
      "    PQR    gjkdv",
      "    P QS   gjkdv",
      "    P       gidv",
      "    P        cdv",
      "    o        cdv",
      "   Ofoooooooocdv",
      "    o        cdv",
      "    m        cdv",
      "    T        cdv",
      "    U       Vcdv"
    ],
    [
      " g  m      gjkdv",
      " g  m      gjkdv",
      " g  m      gjkdv",
      "eg  o      gjkdv",
      "gW  f      gjkdv",
      "g   o      gjkdv",
      "    P      gjkdv",
      "    P      gjkdv",
      "    P       gidv",
      "    P        cdv",
      "    o        cdv",
      "   Wfoooooooocdv",
      "    o        cdv",
      "    m        cdv",
      "    m        cdv",
      "    m        cdv"
    ],
    [
      " g  o      gXkdv",
      " g  o      gXkdv",
      " g  o      gXkdv",
      "eg  o      gXkdv",
      "g   f      gXkdv",
      "g   o      gXkdv",
      "    o      gXkdv",
      "    o      gXkdv",
      "    o       gidv",
      "    o        cdv",
      "    o  Y  Z  cdv",
      "    foooooooocdv",
      "    o        cdv",
      "    o       0cdv",
      "    o        cdv",
      "    o        cdv"
    ],
    [
      " g112334334i5kdv",
      " g112334334i!kdv",
      " g112334336i5kdv",
      "eg112333333i5kdv",
      "g111f333333i5kdv",
      "g1112334334i5kdv",
      "11112334334i5kdv",
      "11112337334i5kdv",
      "111123373343iidv",
      "1111233333333cdv",
      "1111288888888cdv",
      "1111foooooooocdv",
      "1111283333338cdv",
      "1191283333338cdv",
      "1191283433438cdv",
      "1191283633638cdv"
    ]
  ]
}