{
  "name": "multi_laboratory_12_base6",
  "refpalette": "deceasedcraft:multi_laboratory_12/multi_laboratory_12_base6_palette",
  "xsize": 16,
  "zsize": 16,
  "slices": [
    [
      " abbbbbbbbbbbcdv",
      " abbbbbbbbbbbcdv",
      " abbbbbbbbbbbcdv",
      "eabbbbbbbbbbbcdv",
      "abbbfbbbbbbbbcdv",
      "abbbbbbbbbbbbcdv",
      "bbbbbbbbbbbbbcdv",
      "bbbbbbbbbbbbbcdv",
      "bbbbbbbbbgbbbcdv",
      "bbbbbbbbbb bbcdv",
      "bbbbbgbbbbbbbcdv",
      "bbbbfhgbbgbbbcdv",
      "bbbbbbbbhgbbbcdv",
      "bbbbbbbbgggbbcdv",
      "bbbbbbbbhbggbcdv",
      "bbbbgbghggbbbcdv"
    ],
    [
      " i  j       kcdv",
      " i  jl      kcdv",
      " i  j        cdv",
      "ei  m     nnnndv",
      "i   f     no cdv",
      "i   p     nnnndv",
      "    jq       cdv",
      "    j       kcdv",
      "    j    rr kcdv",
      "    j     rggcdv",
      " q st     nnnndv",
      "u wxfy A hnBCcdv",
      "DE   l   Fgnnndv",
      "        r Ihhcdv",
      "  J      A rkcdv",
      "J      r F rhcdv"
    ],
    [
      " i  K      LMcdv",
      " i         LMcdv",
      " i          Ncdv",
      "ei         inndv",
      "i   f     io cdv",
      "i          inndv",
      "            Ocdv",
      "    K      LMcdv",
      "    P       Qcdv",
      "           rgcdv",
      "    R     hgnndv",
      "    f     gBCcdv",
      "            nndv",
      "          rrhcdv",
      "             cdv",
      "            Fcdv"
    ],
    [
      " i           cdv",
      " i           cdv",
      " i           cdv",
      "ei         inndv",
      "i   f     io cdv",
      "i          inndv",
      "             cdv",
      "             cdv",
      "             cdv",
      "            Fcdv",
      "          hinndv",
      "    f     iBCcdv",
      "           Snndv",
      "             cdv",
      "             cdv",
      "             cdv"
    ],
    [
      " i          Tcdv",
      " i          Tcdv",
      " i           cdv",
      "ei         inndv",
      "i   f     io cdv",
      "i          inndv",
      "             cdv",
      "            Tcdv",
      "            Tcdv",
      "             cdv",
      "          rinndv",
      "    f     iBCcdv",
      "           inndv",
      "             cdv",
      "            Tcdv",
      "            Tcdv"
    ],
    [
      " i          Ucdv",
      " i           cdv",
      " i           cdv",
      "ei         inndv",
      "i   f     io cdv",
      "i          inndv",
      "             cdv",
      "             cdv",
      "            Ucdv",
      "             cdv",
      "           inndv",
      "    f     iBCcdv",
      "           inndv",
      "             cdv",
      "            Ucdv",
      "             cdv"
    ]
  ]
}