{
  "name": "multi_laboratory_12_base3",
  "refpalette": "deceasedcraft:multi_laboratory_12/multi_laboratory_12_base3_palette",
  "xsize": 16,
  "zsize": 16,
  "slices": [
    [
      " abbbbbbbbbbbcdv",
      " abbbbbbbbbbbcdv",
      " abbbbbbbbbbbcdv",
      "eabbbbbbbbbbbcdv",
      "abbbfbbbbbbbbcdv",
      "abbbbbbbbbbbbcdv",
      "bbbbbbbbbbbbbcdv",
      "bbbbbbbbbbbbbcdv",
      "bbbbbbbbbbbbbcdv",
      "bbbbbbbbbbbbbcdv",
      "bbbbbbbbbbbbbcdv",
      "bbbbfbbbbbbbbcdv",
      "bbbbbbbbbbbbbcdv",
      "bbbbbbbbbbbbbcdv",
      "bbbbbbbbbbbbbcdv",
      "bbbbbbbbbbbbbcdv"
    ],
    [
      " g  h      ijkdv",
      " g  l     mijkdv",
      " g  n       iidv",
      "ego pq     r cdv",
      "ges fq     t cdv",
      "guw p        cdv",
      " x  p       ycdv",
      "  A p BBCBB ycdv",
      "    p DDDDD  cdv",
      "   rp BBEBB  cdv",
      "F IJp        cdv",
      "   efppppppppcdv",
      "    pKK K  LLcdv",
      "    n       Mcdv",
      "    h      NOcdv",
      " P  l       Ocdv"
    ],
    [
      " g  Q      gjkdv",
      " g  R      gjkdv",
      " g  n       gidv",
      "eg  pS       cdv",
      "gT  f        cdv",
      "g   p        cdv",
      "    U        cdv",
      "    U VVCVV  cdv",
      "    U VV VV  cdv",
      "    U   E W  cdv",
      "    p   X    cdv",
      "   Tfppppppppcdv",
      "    p        cdv",
      "    n        cdv",
      "    Q       Ycdv",
      "    R       Zcdv"
    ],
    [
      " g  n      gjkdv",
      " g  n      gjkdv",
      " g  n       gidv",
      "eg  p        cdv",
      "g   f        cdv",
      "g   p        cdv",
      "    U       0cdv",
      "    U VV VV 0cdv",
      "    U VV VV  cdv",
      "    U        cdv",
      "    p        cdv",
      "   1fppppppppcdv",
      "    p        cdv",
      "    n        cdv",
      "    n        cdv",
      "    n        cdv"
    ],
    [
      " g  p      g2kdv",
      " g  p      g2kdv",
      " g  p       gidv",
      "eg  p        cdv",
      "g   f        cdv",
      "g   p        cdv",
      "    p        cdv",
      "    p        cdv",
      "    p        cdv",
      "    p        cdv",
      "    p  3  4  cdv",
      "    fppppppppcdv",
      "    p        cdv",
      "    p       5cdv",
      "    p        cdv",
      "    p        cdv"
    ],
    [
      " g667889889i#kdv",
      " g66788988$i#kdv",
      " g6678898898iidv",
      "eg66788888888cdv",
      "g666f88888888cdv",
      "g666788988988cdv",
      "6666788988$88cdv",
      "6666788988988cdv",
      "6666788988988cdv",
      "6666788888888cdv",
      "66667%%%%%%%!cdv",
      "6666fppppppppcdv",
      "66667%888888%cdv",
      "66^67%888888%cdv",
      "66^67%898898%cdv",
      "66^67%8&8898%cdv"
    ]
  ]
}