{
  "name": "multi_laboratory_12_base2",
  "refpalette": "deceasedcraft:multi_laboratory_12/multi_laboratory_12_base2_palette",
  "xsize": 16,
  "zsize": 16,
  "slices": [
    [
      " abbbbbbbbbbbcdv",
      " abbbbbbbbbbbcdv",
      " abbbbbbbbbbbcdv",
      "eabbbbbbbbbbbcdv",
      "abbbfbbbbbbbbcdv",
      "abbbbbbbbbbbbcdv",
      "bbbbbbbbbbbbbcdv",
      "bbbbbbbbbbbbbcdv",
      "bbbbbbbbbbbbbcdv",
      "bbbbbbbbbbbbbcdv",
      "bbbbbbbbbbbbbcdv",
      "bbbbfbbbbbbbbcdv",
      "bbbbbbbbbbbbbcdv",
      "bbbbbbbbbbbbbcdv",
      "bbbbbbbbbbbbbcdv",
      "bbbbbbbbbbbbbcdv"
    ],
    [
      " g  h      ijkdv",
      " g  l     mijkdv",
      " g  n       iidv",
      "eg  o        cdv",
      "ge  f        cdv",
      "gp  o q     iidv",
      "    orrst  i kdv",
      "    ouuwt  i kdv",
      "    o x   y iidv",
      "    o        cdv",
      "    o!ABBCB  cdv",
      "D  efoooooooocdv",
      "    o       Ecdv",
      "    n        cdv",
      "    F       Icdv",
      " J  K      LIcdv"
    ],
    [
      " g  M      gjkdv",
      " g  N      gjkdv",
      " g  n       gidv",
      "eg  o        cdv",
      "gO  f        cdv",
      "g   o       gidv",
      "    P QR   g kdv",
      "    PR S   g kdv",
      "    P       gidv",
      "    P        cdv",
      "    o        cdv",
      "   Ofoooooooocdv",
      "    o        cdv",
      "    n        cdv",
      "    T       Ucdv",
      "    V       Wcdv"
    ],
    [
      " g  n      gjkdv",
      " g  n      gjkdv",
      " g  n       gidv",
      "eg  o        cdv",
      "gX  f        cdv",
      "g   o       gidv",
      "    P      g kdv",
      "    P      g kdv",
      "    P       gidv",
      "    P        cdv",
      "    o        cdv",
      "   Xfoooooooocdv",
      "    o        cdv",
      "    n        cdv",
      "    n        cdv",
      "    n        cdv"
    ],
    [
      " g  o      gYkdv",
      " g  o      gYkdv",
      " g  o       gidv",
      "eg  o        cdv",
      "g   f        cdv",
      "g   o       gidv",
      "    o      g kdv",
      "    o      g kdv",
      "    o       gidv",
      "    o        cdv",
      "    o  Z  0  cdv",
      "    foooooooocdv",
      "    o        cdv",
      "    o       1cdv",
      "    o        cdv",
      "    o        cdv"
    ],
    [
      " g223445445i6kdv",
      " g223445447i6kdv",
      " g2234454454iidv",
      "eg22344444444cdv",
      "g222f44444444cdv",
      "g22234474474iidv",
      "22223445445i6kdv",
      "22223445445i6kdv",
      "222234454474iidv",
      "2222344444444cdv",
      "2222388888888cdv",
      "2222foooooooocdv",
      "2222384444448cdv",
      "2292384444448cdv",
      "2292384544548cdv",
      "2292384744548cdv"
    ]
  ]
}