{
  "name": "multi_laboratory_12_ground",
  "refpalette": "deceasedcraft:multi_laboratory_12/multi_laboratory_12_ground_palette",
  "xsize": 16,
  "zsize": 16,
  "slices": [
    [
      "@abbacccvdeeeeez",
      "@abbacccvdeezeez",
      "@abbacccvdeeezzz",
      "aabbacccvdeeezez",
      "abbbacccdveeeeee",
      "abbbacccvdezeeez",
      "bbbbacccvvdeeezz",
      "bbbbacccvdeezeze",
      "bbbbacccvdeeeeze",
      "bbbbacccveeeeeez",
      "bbbbacccvdeeezzz",
      "bbbbacccddedeeez",
      "bbbbacccvdeeeeez",
      "bbbbacccvdeeeezz",
      "bbbbacccvvdeeeze",
      "bbbbacccvdeeeeez"
    ],
    [
      " f  g           ",
      " f  g          h",
      " f  g     ijjh  ",
      "ff  g           ",
      "f  ka           ",
      "f   g     j il  ",
      "    g          h",
      "   mn           ",
      "  mog     ij j  ",
      "kmp g           ",
      "mop g        h  ",
      "p p a     jjql  ",
      "p p g          h",
      "p p g           ",
      "p p g     iqjl  ",
      "    g           "
    ],
    [
      "    r           ",
      "    r           ",
      "    r           ",
      "    r           ",
      "   sa           ",
      "    r           ",
      "    g           ",
      "   mn           ",
      "  mog           ",
      "smp g           ",
      "mop r           ",
      "p p a           ",
      "p p g           ",
      "p p g           ",
      "p p g           ",
      "    g           "
    ],
    [
      "    r           ",
      "    r           ",
      "    r           ",
      "    r           ",
      "   ta           ",
      "    r           ",
      "    g           ",
      "   mn           ",
      "  mog           ",
      "tmp g           ",
      "mop r           ",
      "pup a           ",
      "p p g           ",
      "p p g           ",
      "p p g           ",
      "    g           "
    ],
    [
      "    r           ",
      "    r           ",
      "    r           ",
      "    r           ",
      "    a           ",
      "    r           ",
      "    g           ",
      "   mn           ",
      "  mog           ",
      " muog           ",
      "mouor           ",
      " o oa           ",
      " owog           ",
      " o og           ",
      "uoxog           ",
      "y y g           "
    ],
    [
      "   Ag           ",
      "   Ag           ",
      "   Ag           ",
      "   Ag           ",
      "   Aa           ",
      "   Ag           ",
      "   Ag           ",
      "   mn           ",
      "  mAg           ",
      " mAAg           ",
      "mAAAg           ",
      "AAAAa           ",
      "ABBAg           ",
      "ABBAg           ",
      "AAAAg           ",
      "AAAAg           "
    ]
  ]
}