{
  "name": "multi_laboratory_12_base5",
  "refpalette": "deceasedcraft:multi_laboratory_12/multi_laboratory_12_base5_palette",
  "xsize": 16,
  "zsize": 16,
  "slices": [
    [
      " a          bcdv",
      " a           cdv",
      " a           cdv",
      "ea         affdv",
      "a   g     ah cdv",
      "a          affdv",
      "             cdv",
      "             cdv",
      "            bcdv",
      "             cdv",
      "           affdv",
      "   ig     ajkcdv",
      "           affdv",
      "             cdv",
      "            lcdv",
      "            mcdv"
    ],
    [
      " a          bbdv",
      " a           cdv",
      " a           cdv",
      "ea         affdv",
      "a   g     ah cdv",
      "a          affdv",
      "             cdv",
      "             cdv",
      "            bcdv",
      "            bcdv",
      "           affdv",
      "    g     ajkcdv",
      "           affdv",
      "             ldv",
      "            nldv",
      "            lcdv"
    ],
    [
      " a          bcdv",
      " a           cdv",
      " a           cdv",
      "ea         affdv",
      "a   g     ah cdv",
      "a          affdv",
      "             cdv",
      "             cdv",
      "            bcdv",
      "             cdv",
      "           affdv",
      "    g     ajkcdv",
      "           affdv",
      "             cdv",
      "            ocdv",
      "            lcdv"
    ],
    [
      " a          bcdv",
      " a          bcdv",
      " a          bcdv",
      "ea         affdv",
      "a   g     ah cdv",
      "a          affdv",
      "             bdv",
      "             bdv",
      "            bbdv",
      "             cdv",
      "           affdv",
      "    g     ajkcdv",
      "           affdv",
      "             cdv",
      "             cdv",
      "            lcdv"
    ],
    [
      " a          bcdv",
      " a           cdv",
      " a           cdv",
      "ea         affdv",
      "a   g     ah cdv",
      "a          affdv",
      "             cdv",
      "             cdv",
      "            bcdv",
      "             cdv",
      "           affdv",
      "    g     ajkcdv",
      "           affdv",
      "             cdv",
      "             cdv",
      "            ncdv"
    ],
    [
      " appppppppppqcdv",
      " appppppppppbcdv",
      " appppppppppbcdv",
      "eappppppppffffdv",
      "apppgpppppfr cdv",
      "apppppppppffffdv",
      "ppppppppppppbcdv",
      "ppppppppppppbcdv",
      "ppppppppppppqcdv",
      "ppppppppppppbcdv",
      "ppppppppppffffdv",
      "ppppgpppppfskcdv",
      "ppppppppppffffdv",
      "ppppppppppppbcdv",
      "pppppppppppplcdv",
      "ppppppppppppncdv"
    ]
  ]
}