{
  "name": "multi_laboratory_12_base1",
  "refpalette": "deceasedcraft:multi_laboratory_12/multi_laboratory_12_base1_palette",
  "xsize": 16,
  "zsize": 16,
  "slices": [
    [
      " abbbbbbbbbbbcdv",
      " abbbbbbbbbbbcdv",
      " abbbbbbbbbbbcdv",
      "eabbbbbbbbbbbcdv",
      "abbbfbbbbbbbbcdv",
      "abbbbbbbbbbbbcdv",
      "bbbbbbbbbbbbbcdv",
      "bbbbbbbbbbbbbcdv",
      "bbbbbbbbbbbbbcdv",
      "bbbbbbbbbbbbbcdv",
      "bbbbbbbbbbbbbcdv",
      "bbbbfbbbbbbbbcdv",
      "bbbbbbbbbbbbbcdv",
      "bbbbbbbbbbbbbcdv",
      "bbbbbbbbbbbbbcdv",
      "bbbbbbbbbbbbbcdv"
    ],
    [
      " g  hi  jk lmcdv",
      " g  hin oo  mcdv",
      " g  hi  pq lmcdv",
      "rg  hsn l   tcdv",
      "gr  fhh    h!cdv",
      "gu  w r    rxcdv",
      "    wyy      cdv",
      "    wA   BCD cdv",
      "    wA   BEEEcdv",
      "    wA       cdv",
      "    wA   BCF cdv",
      "   rfAF  BEEEcdv",
      "    IAJ      cdv",
      "    IKK  BCD cdv",
      "    L    BEEEcdv",
      "    M        cdv"
    ],
    [
      " g  w       Ncdv",
      " g  w        cdv",
      " g  w        cdv",
      "rg  wO       cdv",
      "gP  fhh    hhcdv",
      "g   w P    P cdv",
      "    w        cdv",
      "    w        cdv",
      "    w      Q cdv",
      "    w        cdv",
      "    wR       cdv",
      "   PfS     Q cdv",
      "    IT       cdv",
      "    I        cdv",
      "    U      VWcdv",
      "    X        cdv"
    ],
    [
      " g  w       Ycdv",
      " g  w       Ycdv",
      " g  w       Ycdv",
      "rg  w       Ycdv",
      "gZ  fhh    hhcdv",
      "g   w Z    Z cdv",
      "    w        cdv",
      "    w        cdv",
      "    w        cdv",
      "    w        cdv",
      "    w        cdv",
      "   Zf        cdv",
      "    I        cdv",
      "    I        cdv",
      "    I        cdv",
      "    I        cdv"
    ],
    [
      " g  w        cdv",
      " g  w        cdv",
      " g  w        cdv",
      "rg  w        cdv",
      "g   fhh    hhcdv",
      "g   w        cdv",
      "    w        cdv",
      "    w        cdv",
      "    w        cdv",
      "    w        cdv",
      "    w        cdv",
      "    f        cdv",
      "    I        cdv",
      "    I        cdv",
      "    I        cdv",
      "    I        cdv"
    ],
    [
      " 011213111131cdv",
      " 011213111131cdv",
      " 011213111131cdv",
      "4011211111111cdv",
      "0111fhhhhhhhhcdv",
      "0111211111111cdv",
      "1111213111131cdv",
      "1111213111131cdv",
      "1111213111131cdv",
      "1111213111131cdv",
      "1111211111111cdv",
      "1111f11111111cdv",
      "1111211111111cdv",
      "1111213111131cdv",
      "1111213111131cdv",
      "1111213111151cdv"
    ]
  ]
}