{
  "name": "multi_thering_10_base1",
  "refpalette": "deceasedcraft:multi_thering_10/multi_thering_10_base1_palette",
  "xsize": 16,
  "zsize": 16,
  "slices": [
    [
      "vvvvvvvvvvvvvvvv",
      "aaaaaaaaaaaaaaaa",
      "bbbbbbbbbbbbbbbb",
      "                ",
      "                ",
      "                ",
      "                ",
      "                ",
      "                ",
      "                ",
      "                ",
      "                ",
      "                ",
      "   c  d  d  d   ",
      "                ",
      "effffffffffffffe"
    ],
    [
      "vvvvvvvvvvvvvvvv",
      "aaaaaaaaaaaaaaaa",
      "gghghhiiiijjjkkk",
      "ggg h hiijij jkk",
      "                ",
      "                ",
      "                ",
      "    l      l    ",
      "              l ",
      "  l    l        ",
      "                ",
      "                ",
      "                ",
      "                ",
      "                ",
      "effffffffffffffe"
    ],
    [
      "vvvvvvvvvvvvvvvv",
      "aaaaaaaaaaaaaaaa",
      "bbbbbbbbbbbbbbbb",
      "                ",
      "                ",
      "                ",
      "                ",
      "  l m  l  lm l  ",
      " l            m ",
      "  ml l m l  l l ",
      "                ",
      "                ",
      "                ",
      "                ",
      "                ",
      "effffffffffffffe"
    ],
    [
      "vvvvvvvvvvvvvvvv",
      "aaaaaaaaaaaaaaaa",
      "                ",
      "                ",
      "                ",
      "                ",
      "                ",
      " lmlml mllmmlm  ",
      " m            m ",
      " lmmlmlmlm lm m ",
      "                ",
      "                ",
      "                ",
      "                ",
      "                ",
      "effffffffffffffe"
    ],
    [
      "vvvvvvvvvvvvvvvv",
      "aaaaaaaaaaaaaaaa",
      "                ",
      "                ",
      "                ",
      "                ",
      "                ",
      " mmmmmlmmmmmmml ",
      " m            m ",
      " mmmmmmmmmlmmlm ",
      "                ",
      "                ",
      "                ",
      "                ",
      "                ",
      "effffffffffffffe"
    ],
    [
      "vvvvvvvvvvvvvvvv",
      "aaaaaaaaaaaaaaaa",
      "nnnnnnnnnnnnnnnn",
      "nnnnnnnnnnnnnnnn",
      "nnnnnnnnnnnnnnnn",
      "nnnnnnnnnnnnnnnn",
      "oooooooooooooooo",
      "oppppppppppppppo",
      "oppppppppppppppo",
      "oppppppppppppppo",
      "oooooooooooooooo",
      "nnnnnnnnnnnnnnnn",
      "nnnnnnnnnnnnnnnn",
      "nnnnnnnnnnnnnnnn",
      "nnnnnnnnnnnnnnnn",
      "effffffffffffffe"
    ]
  ]
}