{
  "name": "multi_thering_10_floor7",
  "refpalette": "deceasedcraft:multi_thering_10/multi_thering_10_floor7_palette",
  "xsize": 16,
  "zsize": 16,
  "slices": [
    [
      "                ",
      "                ",
      "                ",
      "  aaaaaaaaaaaa  ",
      "aabbbbbbbbbbbbaa",
      "bbccccccccccccbb",
      "cccccccccccccccc",
      "cccccccccccccccc",
      "ccbbbbbbbbbbbbcc",
      "bbb def  def bbb",
      "                ",
      "                ",
      "                ",
      "                ",
      "                ",
      "g              g"
    ],
    [
      "                ",
      "                ",
      "                ",
      "                ",
      "  hhhhhhhhhhhh  ",
      "hhiiiiiiiiiiiihh",
      "iijkjjj j jjkjii",
      "jllllllllllllllj",
      "ll            ll",
      "                ",
      "                ",
      "                ",
      "                ",
      "                ",
      "                ",
      "g              g"
    ],
    [
      "                ",
      "                ",
      "                ",
      "                ",
      "                ",
      "  iiiiiiiiiiii  ",
      "ii            ii",
      "                ",
      "                ",
      "                ",
      "                ",
      "                ",
      "                ",
      "                ",
      "                ",
      "g              g"
    ],
    [
      "                ",
      "                ",
      "                ",
      "                ",
      "                ",
      "                ",
      "                ",
      "                ",
      "                ",
      "                ",
      "                ",
      "                ",
      "                ",
      "                ",
      "                ",
      "g              g"
    ],
    [
      "                ",
      "                ",
      "                ",
      "                ",
      "                ",
      "                ",
      "                ",
      "                ",
      "                ",
      "                ",
      "                ",
      "                ",
      "                ",
      "                ",
      "                ",
      "g              g"
    ],
    [
      "                ",
      "                ",
      "                ",
      "                ",
      "                ",
      "                ",
      "                ",
      "                ",
      "                ",
      "                ",
      "                ",
      "                ",
      "                ",
      "                ",
      "                ",
      "g              g"
    ]
  ]
}