{
  "name": "multi_thering_10_floor6",
  "refpalette": "deceasedcraft:multi_thering_10/multi_thering_10_floor6_palette",
  "xsize": 16,
  "zsize": 16,
  "slices": [
    [
      "                ",
      "                ",
      "                ",
      "                ",
      "                ",
      "                ",
      "                ",
      "                ",
      "                ",
      "                ",
      "                ",
      "                ",
      "                ",
      "                ",
      "                ",
      "a              a"
    ],
    [
      "                ",
      "                ",
      "                ",
      "                ",
      "                ",
      "                ",
      "                ",
      "                ",
      "                ",
      "                ",
      "                ",
      "                ",
      "                ",
      "                ",
      "                ",
      "a              a"
    ],
    [
      "                ",
      "                ",
      "                ",
      "                ",
      "                ",
      "                ",
      "                ",
      "                ",
      "                ",
      "                ",
      "                ",
      "                ",
      "                ",
      "                ",
      "                ",
      "a              a"
    ],
    [
      "                ",
      "                ",
      "                ",
      "                ",
      "                ",
      "                ",
      "                ",
      "                ",
      "                ",
      "                ",
      "                ",
      "                ",
      "                ",
      "                ",
      "                ",
      "a              a"
    ],
    [
      "                ",
      "                ",
      "                ",
      "                ",
      "                ",
      "                ",
      "                ",
      "  bbbbbbbbbbbb  ",
      "bbccccccccccccbb",
      "cccccccccccccccc",
      "cccccccccccccccc",
      "cccccccccccccccc",
      "cccccccccccccccc",
      "cccccccccccccccc",
      "cccccccccccccccc",
      "acccccccccccccca"
    ],
    [
      "                ",
      "                ",
      "                ",
      "                ",
      "                ",
      "  bbbbbbbbbbbb  ",
      "bbcbccccccccbcbb",
      "cccdccccccccdccc",
      "cccccccccccccccc",
      "ccceffffffffeccc",
      "ffffffffffffffff",
      "ghgggggggghggggh",
      "gggggggggggggggg",
      "gghghhggggggghhh",
      "hhhhggggggghgghg",
      "ahhhgggggggghhha"
    ]
  ]
}