{
  "name": "multi_thering_10_base2",
  "refpalette": "deceasedcraft:multi_thering_10/multi_thering_10_base2_palette",
  "xsize": 16,
  "zsize": 16,
  "slices": [
    [
      "vvvvvvvvvvvvvvvv",
      "aaaaaaaaaaaaaaaa",
      "aaaaaaaaaaaaaaaa",
      "aaaaaaaaaaaaaaaa",
      "aaaaaaaaaaaaaaaa",
      "aaaaaaaaaaaaaaaa",
      "aaaaaaaaaaaaaaaa",
      "aaaaaaaaaaaaaaaa",
      "aaaaaaaaaaaaaaaa",
      "aaaaaaaaaaaaaaaa",
      "aaaaaaaaaaaaaaaa",
      "aaaaaaaaaaaaaaaa",
      "aaaaaaaaaaaaaaaa",
      "aaaaaaaaaaaaaaaa",
      "aaaaaaaaaaaaaaaa",
      "baaaaaaaaaaaaaab"
    ],
    [
      "vvvvvvvvvvvvvvvv",
      "aaaaaaaaaaaaaaaa",
      "aaaaaaaaaaaaaaaa",
      "aaaaaaaaaaaaaaaa",
      "aaaaaaaaaaaaaaaa",
      "aaaaaaaaaaaaaaaa",
      "aaaaaaaaaaaaaaaa",
      "aaaaaaaaaaaaaaaa",
      "aaaaaaaaaaaaaaaa",
      "aaaaaaaaaaaaaaaa",
      "aaaaaaaaaaaaaaaa",
      "aaaaaaaaaaaaaaaa",
      "aaaaaaaaaaaaaaaa",
      "aaaaaaaaaaaaaaaa",
      "aaaaaaaaaaaaaaaa",
      "baaaaaaaaaaaaaab"
    ],
    [
      "vvvvvvvvvvvvvvvv",
      "cccccccccccccccc",
      "cccccccccccccccc",
      "cccccccccccccccc",
      "cccccccccccccccc",
      "cccccccccccccccc",
      "cccccccccccccccc",
      "cccccccccccccccc",
      "cccccccccccccccc",
      "cccccccccccccccc",
      "cccccccccccccccc",
      "cccccccccccccccc",
      "cccccccccccccccc",
      "cccccccccccccccc",
      "cccccccccccccccc",
      "bccccccccccccccb"
    ],
    [
      "vvvvvvvvvvvvvvvv",
      "dddddddddddddddd",
      "eeeeeeeeeeeeeeee",
      "eeeeeeeeeeeeeeee",
      "eeeeeeeeeeeeeeee",
      "eeeeeeeeeeeeeeee",
      "eeeeeeeeeeeeeeee",
      "effffffffffffffe",
      "effffffffffffffe",
      "effffffffffffffe",
      "eeeeeeeeeeeeeeee",
      "eeeeeeeeeeeeeeee",
      "eeeeeeeeeeeeeeee",
      "eeeeeeeeeeeeeeee",
      "eeeeeeeeeeeeeeee",
      "dddddddddddddddd"
    ],
    [
      "vvvvvvvvvvvvvvvv",
      "dddddddddddddddd",
      "          !    g",
      "                ",
      "                ",
      "                ",
      "                ",
      " hhhhhhhhhhhhhh ",
      " hiiiiiiiiiiiih ",
      " hhhhhhhhhhhhhh ",
      "                ",
      "                ",
      "                ",
      "   j  j  j  j   ",
      "                ",
      "kllllllllllllllk"
    ],
    [
      "vvvvvvvvvvvvvvvv",
      "dddddddddddddddd",
      "mmmnnonoooppqpqq",
      "mmnmnno oop pqq ",
      "                ",
      "                ",
      "                ",
      "                ",
      "  rsssssssssst  ",
      "                ",
      "                ",
      "                ",
      "                ",
      "   u  w  x  y   ",
      "                ",
      "kllllllllllllllk"
    ]
  ]
}