{
  "name": "multi_thering_10_ground",
  "refpalette": "deceasedcraft:multi_thering_10/multi_thering_10_ground_palette",
  "xsize": 16,
  "zsize": 16,
  "slices": [
    [
      "aaaaaaaaaaaaaaaa",
      "HHHHHHHHHHHHHHHH",
      "HHHHHHHHHHHHHHHH",
      "HHHaaaaaaaaaaaaa",
      "HHaHHHHHHHHHHHHb",
      "HHaHHHHHHHHHHHHb",
      "HHaHHHHHHHHHHHHb",
      "HHaHHHHHHHHHHHHb",
      "HHHaaaaaaaaaaaaa",
      "HHHHHHHHHHHHHHHH",
      "HHHHHHHHHHHHHHHH",
      "aaaaaaaaaaaaaaaa",
      "cccccccccccccccc",
      "dddddddddddddddd",
      "dddddddddddddddd",
      "eeeeeeeeeeeeeeee"
    ],
    [
      "                ",
      "                ",
      "                ",
      "                ",
      "   fgfgfgfgfgfgh",
      "               h",
      "               h",
      "   ijijijijijijh",
      "                ",
      "       k        ",
      "                ",
      "                ",
      "                ",
      "                ",
      " llllllllllllll ",
      "mhhhhhhhhhhhhhhm"
    ],
    [
      "                ",
      "                ",
      "                ",
      "                ",
      "                ",
      "                ",
      "                ",
      "                ",
      "                ",
      "                ",
      "                ",
      "                ",
      "                ",
      "                ",
      "                ",
      "mnnnnnnnnnnnnnnm"
    ],
    [
      "                ",
      "                ",
      "                ",
      "                ",
      "                ",
      "                ",
      "               o",
      "                ",
      "                ",
      "                ",
      "                ",
      "                ",
      "                ",
      "                ",
      "                ",
      "m              m"
    ],
    [
      "                ",
      "                ",
      "                ",
      "                ",
      "                ",
      "                ",
      "               p",
      "                ",
      "                ",
      "                ",
      "                ",
      "                ",
      "                ",
      "                ",
      "                ",
      "m              m"
    ],
    [
      "                ",
      "                ",
      "                ",
      "                ",
      "                ",
      "                ",
      "               p",
      "                ",
      "                ",
      "                ",
      "                ",
      "                ",
      "                ",
      "                ",
      "                ",
      "m              m"
    ]
  ]
}