{
  "name": "multi_cafe_0_ground",
  "refpalette": "deceasedcraft:multi_cafe_0/multi_cafe_0_ground_palette",
  "xsize": 16,
  "zsize": 16,
  "slices": [
    [
      "aaaaaaaaaaaaaaaa",
      "aaaaaaaaaaaaaaaa",
      "aabbbbbbbbbbbbbb",
      "aabbbbbbbbbbbbbb",
      "aabbcccccccccccc",
      "aabbcdddddddcddd",
      "aabbcdddddddaddd",
      "aabbcdddddddaddd",
      "aabbcdddddddaddd",
      "aabbcdddddddcddd",
      "aabbcdddddddaddd",
      "aabbcdddddddaddd",
      "aabbcdddddddaddd",
      "aabbcdddddddcddd",
      "aabbcdddddddcddd",
      "aabbcddddddddddd"
    ],
    [
      " ef f gf hff  ij",
      "fjfhjgi   igehjg",
      "ie              ",
      "ef              ",
      "jh  ckkkkcllmlll",
      "g   noooop  m   ",
      "f   noooop  q rs",
      " e  noooop      ",
      "hg  noooop  t   ",
      "j   coooop  m rs",
      "e   noooop      ",
      " i  noooop  t   ",
      "jh  noooop  q rs",
      " f  uoooop  m   ",
      "f   poooop  m   ",
      "    poooop      "
    ],
    [
      "                ",
      "                ",
      "                ",
      "                ",
      "    lllllll m   ",
      "    l       m   ",
      "    lw w    x  y",
      "    lABC        ",
      "    lD D    E   ",
      "    l       m   ",
      "    lw w        ",
      "    lABC    E   ",
      "    lD D    x  F",
      "    I       m   ",
      "            m   ",
      "                "
    ],
    [
      "                ",
      "                ",
      "                ",
      "                ",
      "            m   ",
      "            m   ",
      "                ",
      "       F        ",
      "                ",
      "            m   ",
      "                ",
      "       J        ",
      "                ",
      "            m   ",
      "            m   ",
      "                "
    ],
    [
      "                ",
      "                ",
      "                ",
      "                ",
      "            m   ",
      "            m   ",
      "                ",
      "                ",
      "                ",
      "            m   ",
      "                ",
      "                ",
      "                ",
      "            m   ",
      "            m   ",
      "                "
    ],
    [
      "                ",
      "                ",
      "                ",
      "                ",
      "            m   ",
      "            m   ",
      "                ",
      "                ",
      "                ",
      "            m   ",
      "                ",
      "                ",
      "                ",
      "            m   ",
      "            m   ",
      "                "
    ]
  ]
}