{
  "name": "multi_nuclearpowerplant_33_base4",
  "refpalette": "deceasedcraft:multi_nuclearpowerplant_33/multi_nuclearpowerplant_33_base4_palette",
  "xsize": 16,
  "zsize": 16,
  "slices": [
    [
      "                ",
      "                ",
      "                ",
      "                ",
      "               =",
      "              =a",
      "             =a ",
      "            =a  ",
      "           =a   ",
      "          =a    ",
      "         =a     ",
      "        =a      ",
      "       =a      b",
      "      =a      bb",
      "     =a      bbc",
      "    =a      bbcc"
    ],
    [
      "                ",
      "                ",
      "                ",
      "                ",
      "               =",
      "              =a",
      "             =a ",
      "            =a  ",
      "           =a   ",
      "          =a    ",
      "         =a     ",
      "        =a      ",
      "       =a      b",
      "      =a      bb",
      "     =a      bbc",
      "    =a      bbcc"
    ],
    [
      "                ",
      "                ",
      "                ",
      "                ",
      "               =",
      "              =a",
      "             =a ",
      "            =a  ",
      "           =a   ",
      "          =a    ",
      "         =a     ",
      "        =a      ",
      "       =a      b",
      "      =a      bb",
      "     =a      bbc",
      "    =a      bbcc"
    ],
    [
      "                ",
      "                ",
      "                ",
      "                ",
      "               =",
      "              =a",
      "             =a ",
      "            =a  ",
      "           =a   ",
      "          =a    ",
      "         =a     ",
      "        =a      ",
      "       =a      b",
      "      =a      bb",
      "     =a      bbc",
      "    =a      bbcc"
    ],
    [
      "                ",
      "                ",
      "                ",
      "                ",
      "               =",
      "              =a",
      "             =a ",
      "            =a  ",
      "           =a   ",
      "          =a    ",
      "         =a     ",
      "        =a      ",
      "       =a      b",
      "      =a      bb",
      "     =a      bb ",
      "    =a      bb  "
    ],
    [
      "                ",
      "                ",
      "                ",
      "                ",
      "               =",
      "              =a",
      "             =a ",
      "            =a  ",
      "           =a   ",
      "          =a    ",
      "         =a     ",
      "        =a      ",
      "       =a      d",
      "      =a      dd",
      "     =a      dd ",
      "    =a      dd  "
    ]
  ]
}