{
  "name": "multi_nuclearpowerplant_33_base1",
  "refpalette": "deceasedcraft:multi_nuclearpowerplant_33/multi_nuclearpowerplant_33_base1_palette",
  "xsize": 16,
  "zsize": 16,
  "slices": [
    [
      "aaaaaaaaaaaaaaaa",
      "aaaaaaaaaaaaaaaa",
      "aaaaaaaaaaaaaaaa",
      "aaaaaaaaaaaaaaaa",
      "aaaaaaaaaaaaaaaa",
      "aaaaaaaaaaaaaaaa",
      "aaaaaaaaaaaaaaab",
      "aaaaaaaaaaaaaabc",
      "aaaaaaaaaaaaabc=",
      "aaaaaaaaaaaaab==",
      "aaaaaaaaaaaab===",
      "aaaaaaaaaaab====",
      "aaaaaaaaaab=====",
      "aaaaaaaaab======",
      "aaaaaaaab=======",
      "aaaaaaab========"
    ],
    [
      "dbaaaaaaaaaaaaaa",
      "dbaaaaaaaaaaaaaa",
      "ebaaaaaaaaaaaaaa",
      "baaaaaaaaaaaaaaa",
      "baaaaaaaaaaaaaaa",
      "baaaaaaaaaaaaaaa",
      "aaaaaaaaaaaaaaab",
      "aaaaaaaaaaaaaabc",
      "aaaaaaaaaaaaabcc",
      "aaaaaaaaaaaaabcc",
      "aaaaaaaaaaaabccc",
      "aaaaaaaaaaabcccc",
      "aaaaaaaaaabccccc",
      "aaaaaaaaabcccccc",
      "aaaaaaaabccccccc",
      "aaaaaaabcccccccc"
    ],
    [
      "  debaaaaaaaaaaa",
      "  debaaaaaaaaaaa",
      "  dbaaaaaaaaaaaa",
      " debaaaaaaaaaaaa",
      " debaaaaaaaaaaaa",
      " dbaaaaaaaaaaaaa",
      "debaaaaaaaaaaaab",
      "dbaaaaaaaaaaaabc",
      "ebaaaaaaaaaaabcc",
      "baaaaaaaaaaaabcc",
      "baaaaaaaaaaabccc",
      "aaaaaaaaaaabcccc",
      "aaaaaaaaaabccccc",
      "aaaaaaaaabcccccc",
      "aaaaaaaabccccccc",
      "aaaaaaabcccccccc"
    ],
    [
      "     debaaaaaaaa",
      "     dbaaaaaaaaa",
      "    debaaaaaaaaa",
      "    debaaaaaaaaa",
      "    dbaaaaaaaaaa",
      "   debaaaaaaaaaa",
      "   dbaaaaaaaaaab",
      "  debaaaaaaaaabc",
      "  dbaaaaaaaaabcc",
      " debaaaaaaaaabcc",
      " dbaaaaaaaaabccc",
      "dbaaaaaaaaabcccc",
      "dbaaaaaaaabccccc",
      "baaaaaaaabcccccc",
      "aaaaaaaabccccccc",
      "aaaaaaabcccccccc"
    ],
    [
      "        dbaaaaaa",
      "       debaaaaaa",
      "       debaaaaaa",
      "       dbaaaaaaa",
      "      debaaaaaaa",
      "      dbaaaaaaaa",
      "     debaaaaaaab",
      "     dbaaaaaaabc",
      "    dbaaaaaaabcc",
      "    dbaaaaaaabcc",
      "   dbaaaaaaabccc",
      "  dbaaaaaaabcccc",
      "  dbaaaaaabccccc",
      " dbaaaaaabcccccc",
      "dbaaaaaabccccccc",
      "baaaaaabcccccccc"
    ],
    [
      "          debaaa",
      "          debaaa",
      "          dbaaaa",
      "         debaaaa",
      "         dbaaaaa",
      "        debaaaaa",
      "        dbaaaaab",
      "       dbaaaaabc",
      "      debaaaabcc",
      "      dbaaaaabcc",
      "     dbaaaaabccc",
      "    debaaaabcccc",
      "    dbaaaabccccc",
      "   dbaaaabcccccc",
      "  dbaaaabccccccc",
      " dbaaaabcccccccc"
    ]
  ]
}