{
  "name": "multi_nuclearpowerplant_33_base11",
  "refpalette": "deceasedcraft:multi_nuclearpowerplant_33/multi_nuclearpowerplant_33_base11_palette",
  "xsize": 16,
  "zsize": 16,
  "slices": [
    [
      "           abcdd",
      "           abcdd",
      "           abedd",
      "         f abcdd",
      "           abcdd",
      "         f abcdd",
      "           abcdd",
      "           abcdd",
      "       gg  abcdd",
      "aaaaaaaaaaaabcdd",
      "ccccccccccccbeee",
      "hhhhhhhhhhhcbe i",
      "hhhhhhhhhhhcbe i",
      "hhhhhhhhhhhcbe i",
      "hhhhhhhhhhhcbeee",
      "hhhhhhhhhhhhbcdd"
    ],
    [
      "           abcdd",
      "           abcdd",
      "           abedd",
      "         ffabcdd",
      "         f abcdd",
      "         ffabcdd",
      "           abcdd",
      "           abcdd",
      "j      gg  abcdd",
      "aaaaaaaaaaaabcdd",
      "ccccccccccccbeee",
      "hhhhhhhhhhhcbe i",
      "hhhhhhhhhhhcbe i",
      "hhhhhhhhhhhcbe i",
      "hhhhhhhhhhhcbeee",
      "hhhhhhhhhhhhbcdd"
    ],
    [
      "           abcdd",
      "           abcdd",
      "           abedd",
      "         ffabcdd",
      "         f abcdd",
      "         ffabcdd",
      "           abcdd",
      "           abcdd",
      "kl     gg  abcdd",
      "aaaaaaaaaaaabcdd",
      "cccccccccccceeee",
      "hhhhhhhhhhhceeem",
      "hhhhhhhhhhhceeen",
      "hhhhhhhhhhhceeeo",
      "hhhhhhhhhhhceeee",
      "hhhhhhhhhhhhbcdd"
    ],
    [
      "           abcdd",
      "           abcdd",
      "           abedd",
      "         ppppqdd",
      "         prppqdd",
      "         ppppqdd",
      "           abcdd",
      "           abcdd",
      "  l    gg  abcdd",
      "aaaaaaaaaaaabcdd",
      "cccccccccccceeee",
      "hhhhhhhhhhhe   s",
      "hhhhhhhhhhhe   s",
      "hhhhhhhhhhhe   s",
      "hhhhhhhhhhhceeee",
      "hhhhhhhhhhhhbcdd"
    ],
    [
      "           abcdd",
      "           abcdd",
      "           abedd",
      "         ppppqdd",
      "         tddddud",
      "         ppppqdd",
      "           abcdd",
      "           abcdd",
      "   l   gg  abcdd",
      "aaaaaaaaaaaabcdd",
      "ccccccccccccecww",
      "hhhhhhhhhhhceeee",
      "hhhhhhhhhhhceeee",
      "hhhhhhhhhhhceeee",
      "hhhhhhhhhhhcecxx",
      "hhhhhhhhhhhhbcdd"
    ],
    [
      "           abcdd",
      "           abcdd",
      "           abedd",
      "         ppppqdd",
      "         tdppqdd",
      "         ppppqdd",
      "           abcdd",
      "           abcdd",
      "    l  gg  abcdd",
      "aaaaaaaaaaaabcdd",
      "ccccccccccccbcdd",
      "hhhhhhhhhhhcbcdd",
      "hhhhhhhhhhhcbedd",
      "hhhhhhhhhhhcbcdd",
      "hhhhhhhhhhhcbcdd",
      "hhhhhhhhhhhhbcdd"
    ]
  ]
}