{
  "name": "multi_nuclearpowerplant_33_base2",
  "refpalette": "deceasedcraft:multi_nuclearpowerplant_33/multi_nuclearpowerplant_33_base2_palette",
  "xsize": 16,
  "zsize": 16,
  "slices": [
    [
      "                ",
      "               a",
      "               a",
      "              a ",
      "              a=",
      "             a=b",
      "            a=b ",
      "           a=b  ",
      "           ab   ",
      "          ab    ",
      "         ab     ",
      "        ab      ",
      "       ab       ",
      "      ab        ",
      "     ab         ",
      "    ab          "
    ],
    [
      "                ",
      "               a",
      "               a",
      "              a ",
      "              a=",
      "             a=b",
      "            a=b ",
      "           a=b  ",
      "           ab   ",
      "          ab    ",
      "         ab     ",
      "        ab      ",
      "       abccccccc",
      "      ab        ",
      "     ab         ",
      "    ab          "
    ],
    [
      "                ",
      "               a",
      "               a",
      "              a ",
      "              a=",
      "             a=b",
      "            a=b ",
      "           a=b  ",
      "           ab   ",
      "          ab    ",
      "         ab     ",
      "        ab      ",
      "       abddddddd",
      "      ab        ",
      "     ab         ",
      "    ab          "
    ],
    [
      "                ",
      "               a",
      "               a",
      "              a ",
      "              a=",
      "             a=b",
      "            a=bb",
      "           a=bb ",
      "           abb  ",
      "          abb   ",
      "         abb    ",
      "        abb     ",
      "       abb      ",
      "      abb       ",
      "     abb        ",
      "    abb         "
    ],
    [
      "                ",
      "               e",
      "               e",
      "              ef",
      "              ef",
      "             eff",
      "            eff=",
      "           eff=b",
      "           ef=bg",
      "          effbg ",
      "         effbg  ",
      "        effbg   ",
      "       effbg    ",
      "      effbg     ",
      "     effbg      ",
      "    effbg       "
    ],
    [
      "hhhhhhhhhhhhhhhh",
      "hhhhhhhhhhhhhhhh",
      "hhhhhhhhhhhhhhhh",
      "hhhhhhhhhhhhhhhf",
      "hiiihhhhiiihhhhf",
      "hhhhhhhhhhhhhhff",
      "hhhhhhhhhhhhhff=",
      "hhhhhhhhhhhhff==",
      "hhhhhhhhhhhhf==b",
      "hhhhhhhhhhhff=bb",
      "hhhhiiihhhff=bbb",
      "hhhhhhhhhff=bbbb",
      "hhhhhhhhff=bbbbb",
      "hhhhhhhff=bbbbbb",
      "hhhhhhff=bbbbbbb",
      "ihhhhff=bbbbbbbb"
    ]
  ]
}