{
  "name": "multi_nuclearpowerplant_33_base9",
  "refpalette": "deceasedcraft:multi_nuclearpowerplant_33/multi_nuclearpowerplant_33_base9_palette",
  "xsize": 16,
  "zsize": 16,
  "slices": [
    [
      "           ab   ",
      "           ab   ",
      "           abc  ",
      "         dddb   ",
      "         efdb   ",
      "         dddb   ",
      "            b   ",
      "            b   ",
      "       gg   b   ",
      "aaaaaaaaaaaab   ",
      "hhhhhhhhhhhhb   ",
      "iiiiiiiiiiihb   ",
      "iiiiiiiiiiihbc  ",
      "iiiiiiiiiiihb   ",
      "iiiiiiiiiiihb   ",
      "iiiiiiiiiiiib   "
    ],
    [
      "           ab   ",
      "           ab   ",
      "           abc  ",
      "         dddb   ",
      "         efdb   ",
      "         dddb   ",
      "            b   ",
      "            b   ",
      "       gg   b   ",
      "aaaaaaaaaaaab   ",
      "hhhhhhhhhhhhb   ",
      "iiiiiiiiiiihb   ",
      "iiiiiiiiiiihbc  ",
      "iiiiiiiiiiihb   ",
      "iiiiiiiiiiihb   ",
      "iiiiiiiiiiiib   "
    ],
    [
      "           ab   ",
      "           ab   ",
      "           abc  ",
      "         dddb   ",
      "         efdb   ",
      "         dddb   ",
      "            b   ",
      "            b   ",
      "       gg   b   ",
      "aaaaaaaaaaaab   ",
      "hhhhhhhhhhhhb   ",
      "iiiiiiiiiiihb   ",
      "iiiiiiiiiiihbc  ",
      "iiiiiiiiiiihb   ",
      "iiiiiiiiiiihb   ",
      "iiiiiiiiiiiib   "
    ],
    [
      "           ab   ",
      "           ab   ",
      "           abcjk",
      "         dddb   ",
      "         efdb   ",
      "         dddb   ",
      "            b   ",
      "       ll   b   ",
      "       gg   b   ",
      "aaaaaaaaaaaab   ",
      "hhhhhhhhhhhhb   ",
      "hhiiiiiiiiihb   ",
      "hhiiiiiiiiihbc  ",
      "hhiiiiiiiiihb   ",
      "hhiiiiiiiiihb   ",
      "hhiiiiiiiiiib   "
    ],
    [
      "           ab   ",
      "           ab   ",
      "           abccc",
      "         dddb   ",
      "         efdb   ",
      "         dddb   ",
      "            b   ",
      "mmmmmmmmmmmmno  ",
      "m      gg   b   ",
      "maaaaaaaaaaab   ",
      "mhhhhhhhhhhhb   ",
      "mhiiiiiiiiihb   ",
      "mhiiiiiiiiihbccc",
      "mhiiiiiiiiihb   ",
      "mhiiiiiiiiihb   ",
      "mhiiiiiiiiiib   "
    ],
    [
      "           ab   ",
      "           ab   ",
      "           abcp ",
      "         dddb   ",
      "         dfdb   ",
      "         dddb   ",
      "            b   ",
      "            b   ",
      "       gg   b   ",
      "aaaaaaaaaaaab   ",
      "hhhhhhhhhhhhb   ",
      "hhiiiiiiiiihb   ",
      "hhiiiiiiiiihbcp ",
      "hhiiiiiiiiihb   ",
      "hhiiiiiiiiihb   ",
      "hhiiiiiiiiiib   "
    ]
  ]
}