{
  "name": "multi_nuclearpowerplant_33_base12",
  "refpalette": "deceasedcraft:multi_nuclearpowerplant_33/multi_nuclearpowerplant_33_base12_palette",
  "xsize": 16,
  "zsize": 16,
  "slices": [
    [
      "aaaaaaaaaaaaaaaa",
      "aaaaaaaaaaaaaaaa",
      "aaaaaaaaaaaaaaaa",
      "aaaaaaaaaaaaaaaa",
      "aaaaaaaaaaaaaaaa",
      "aaaaaaaaaaaaaaaa",
      "aaaaaaaaaaaaaaaa",
      "aaaaaaaaaaaaaaaa",
      "aaaaaaaaaaaaaaaa",
      "aaaaaaaaaaaaaaaa",
      "aaaaaaaaaaaaaaaa",
      "aaaaaaaaaaaaaaaa",
      "aaaaaaaaaaaaaaaa",
      "aaaaaaaaaaaaaaaa",
      "aaaaaaaaaaaaaaaa",
      "aaaaaaaaaaaaaaaa"
    ],
    [
      "bbbbbbbbbbbbbbbb",
      "bbbbbbbbbbbbbbbb",
      "bbbbbbbbbbbbbbbb",
      "bbbbbbbbbbbbbbbb",
      "bbbbbbbbbbbbbbbb",
      "bbbbbbbbbbbbbbbb",
      "bbbbbbbbbbbbbbbb",
      "bbbbbbbbbbbbbbbb",
      "bbbbbbbbbbbbbbbb",
      "bbbbbbbbbbbbbbbb",
      "bbbbbbbbbbbbbbbb",
      "aaaaaaaaaaabbbbb",
      "aaaaaaaaaaabbbbb",
      "aaaaaaaaaaabbbbb",
      "aaaaaaaaaaabbbbb",
      "aaaaaaaaaaaabbbb"
    ],
    [
      "cccccccccccde===",
      "cccccccccccde===",
      "ccccccccffffe===",
      "ccccccccffffe===",
      "ccccccccffgfe===",
      "ccccccccffffe===",
      "ccccccccffffe===",
      "cccccccccccde===",
      "cccccccccccde===",
      "dddddddddddde===",
      "bbbbbbbbbbbbe===",
      "aaaaaaaaaaabe===",
      "aaaaaaaaaaabe===",
      "aaaaaaaaaaabe===",
      "aaaaaaaaaaabe===",
      "aaaaaaaaaaaae==="
    ],
    [
      "           dhbii",
      "j          dhbii",
      "           dhbii",
      "         k dhbii",
      "           dhbii",
      "         k dhbii",
      "           dhbii",
      "           dhbii",
      "       ll  dhbii",
      "ddddddddddddhbii",
      "bbbbbbbbbbbbhbii",
      "aaaaaaaaaaabhbmm",
      "aaaaaaaaaaabhbmm",
      "aaaaaaaaaaabhbmm",
      "aaaaaaaaaaabhbii",
      "aaaaaaaaaaaahbii"
    ],
    [
      "           dhbnn",
      "           dhbnn",
      "           dhmnn",
      "         o dhbnn",
      "          pdhbnn",
      "         o dhbnn",
      "           dhbnn",
      "           dhbnn",
      "       ll  dhbnn",
      "ddddddddddddhbnn",
      "bbbbbbbbbbbbhmmm",
      "aaaaaaaaaaabhm  ",
      "aaaaaaaaaaabhmqr",
      "aaaaaaaaaaabhm  ",
      "aaaaaaaaaaabhmmm",
      "aaaaaaaaaaaahbnn"
    ],
    [
      "           dhbnn",
      "           dhbnn",
      "           dhmnn",
      "         osdhbnn",
      "          tdhbnn",
      "         oudhbnn",
      "           dhbnn",
      "           dhbnn",
      "       ll  dhbnn",
      "ddddddddddddhbnn",
      "bbbbbbbbbbbbhmmm",
      "aaaaaaaaaaabhm w",
      "aaaaaaaaaaabhm w",
      "aaaaaaaaaaabhm w",
      "aaaaaaaaaaabhmmm",
      "aaaaaaaaaaaahbnn"
    ]
  ]
}