{
  "name": "multi_nuclearpowerplant_33_base7",
  "refpalette": "deceasedcraft:multi_nuclearpowerplant_33/multi_nuclearpowerplant_33_base7_palette",
  "xsize": 16,
  "zsize": 16,
  "slices": [
    [
      "                ",
      "                ",
      "                ",
      "                ",
      "               =",
      "aa aaa aaa    =b",
      " aca a a a   =b ",
      "aa aaa aaa  =b  ",
      "           =bd  ",
      "aa aaa    =b    ",
      " aea a   =b     ",
      "aa aaa  =b      ",
      "       =b      f",
      "aa    =b      ff",
      " a   =b      ffg",
      "aa  =b      ffgg"
    ],
    [
      "                ",
      "                ",
      "                ",
      "                ",
      "               =",
      "aa aaa aaa    =b",
      " a a a a a   =b ",
      "aa aaa aaa  =b  ",
      "           =b   ",
      "aa aaa    =b    ",
      " a a a   =b     ",
      "aa aaa  =b      ",
      "       =b      f",
      "aa    =b      ff",
      " a   =b      ffg",
      "aa  =b      ffgg"
    ],
    [
      "                ",
      "                ",
      "                ",
      "                ",
      "               =",
      "aa aaa aaa    =b",
      " a a a a a   =b ",
      "aa aaa aaa  =b  ",
      "           =b   ",
      "aa aaa    =b    ",
      " a a a   =b     ",
      "aa aaa  =b      ",
      "       =b      f",
      "aa    =b      ff",
      " a   =b      ffh",
      "aa  =b      ffhh"
    ],
    [
      "                ",
      "                ",
      "                ",
      "                ",
      "               =",
      "aa aaa aaa    =b",
      "aa aaa aaa   =b ",
      "aa aaa aaa  =b  ",
      "           =b   ",
      "aa aaa    =b    ",
      "aa aaa   =b     ",
      "aa aaa  =b      ",
      "       =b      f",
      "aa    =b      ff",
      "aa   =b      ffh",
      "aa  =b      ffhh"
    ],
    [
      "                ",
      "                ",
      "                ",
      "                ",
      "               =",
      "              =b",
      "             =b ",
      "            =b  ",
      "           =b   ",
      "          =b    ",
      "         =b     ",
      "        =b      ",
      "       =b      f",
      "      =b      ff",
      "     =b      ffh",
      "    =b      ffhh"
    ],
    [
      "iiiiiiiiiiiiiiii",
      "iiiiiiiiiiiiiiii",
      "iiiiiiiiiiiiiiii",
      "iiiiiiiiiiiiiiii",
      "iiiiiiiiiiiiiii=",
      "iiiiiiiiiiiiii=b",
      "iiiiiiiiiiiii=b ",
      "iiiiiiiiiiii=b  ",
      "iiiiiiiiiii=b   ",
      "iiiiiiiiii=b    ",
      "iiiiiiiii=b     ",
      "iiiiiiii=b      ",
      "iiiiiii=b      f",
      "iiiiii=b      ff",
      "iiiii=b      ffh",
      "iiii=b      ffhh"
    ]
  ]
}