{
  "name": "multi_nuclearpowerplant_33_base3",
  "refpalette": "deceasedcraft:multi_nuclearpowerplant_33/multi_nuclearpowerplant_33_base3_palette",
  "xsize": 16,
  "zsize": 16,
  "slices": [
    [
      "aaaaaaaaaaaaaaaa",
      "aaaaaaaaaaaaaaab",
      "aaaaaaaaaaaaaaab",
      "aaaaaaaaaaaaaab ",
      "aaaaaaaaaaaaaab=",
      "aaaaaaaaaaaaab=c",
      "aaaaaaaaaaaab=cd",
      "aaaaaaaaaaab=cdd",
      "aaaaaaaaaaabcddd",
      "aaaaaaaaaabcdddd",
      "aaaaaaaaabcdddd ",
      "aaaaaaaabcdddd  ",
      "aaaaaaabcdddd   ",
      "aaaaaabcdddd    ",
      "aaaaabcdddd     ",
      "aaaabcdddd      "
    ],
    [
      "    ef          ",
      "     g         h",
      "         i    jh",
      "      i kkkkkkh ",
      "       j  l mnh=",
      "        j   oh=p",
      "      qqqqqqh=p ",
      "    qqrrrrrh=p  ",
      "   qrrrrrrrhps  ",
      "  qrrrrrrrhp   t",
      " qrrrrrrrhp   t ",
      " qrrrrrrhp   t  ",
      "qrrrrrrhp   t   ",
      "qrrr!rhp   t    ",
      "qrrrrhps  t     ",
      "qrrrhp   t      "
    ],
    [
      "    uf          ",
      "     g         h",
      "               h",
      "        wjxyABh ",
      "              h=",
      "            Ch=p",
      "            h=p ",
      "           h=p  ",
      "      D EF hp   ",
      "     I    hp    ",
      "      DJ hp     ",
      "   E    hp      ",
      "  K L  hp       ",
      "    I hp        ",
      "  E  hp         ",
      "    hp          "
    ],
    [
      "    uf          ",
      "     g         h",
      "               h",
      "              h ",
      "              h=",
      "            Mh=p",
      "            h=p ",
      "           h=p  ",
      "           hp   ",
      "          hp    ",
      "         hp     ",
      "        hp      ",
      "       hp       ",
      "      hp        ",
      "     hp         ",
      "    hp          "
    ],
    [
      "    NO          ",
      "               h",
      "               h",
      "              h ",
      "              h=",
      "             h=p",
      "            h=p ",
      "           h=p  ",
      "           hp   ",
      "          hp    ",
      "         hp     ",
      "        hp      ",
      "       hp       ",
      "      hp        ",
      "     hp         ",
      "    hp          "
    ],
    [
      "                ",
      "               h",
      "               h",
      "              h ",
      "              h=",
      "             h=p",
      "            h=p ",
      "           h=p  ",
      "           hp   ",
      "          hp    ",
      "         hp     ",
      "        hp      ",
      "       hp       ",
      "      hp        ",
      "     hp         ",
      "    hp          "
    ]
  ]
}