{
  "name": "multi_nuclearpowerplant_33_base5",
  "refpalette": "deceasedcraft:multi_nuclearpowerplant_33/multi_nuclearpowerplant_33_base5_palette",
  "xsize": 16,
  "zsize": 16,
  "slices": [
    [
      "                ",
      "                ",
      "                ",
      "                ",
      "               =",
      "aa aaa aaa    =b",
      " a a a a a   =b ",
      "aa aaa aaa  =b  ",
      "           =b   ",
      "aa aaa    =b    ",
      " a a a   =b     ",
      "aa aaa  =b      ",
      "       =b      c",
      "aa    =b      cc",
      " a   =b      ccd",
      "aa  =b      ccdd"
    ],
    [
      "                ",
      "                ",
      "                ",
      "                ",
      "               =",
      "aa aaa aaa    =b",
      " a a a a a   =b ",
      "aa aaa aaa  =b  ",
      "           =b   ",
      "aa aaa    =b    ",
      " a a a   =b     ",
      "aa aaa  =b      ",
      "       =b      c",
      "aa    =b      cc",
      " a   =b      ccd",
      "aa  =b      ccdd"
    ],
    [
      "                ",
      "                ",
      "                ",
      "                ",
      "               =",
      "aa aaa aaa    =b",
      "aa aaa aaa   =b ",
      "aa aaa aaa  =b  ",
      "           =b   ",
      "aa aaa    =b    ",
      "aa aaa   =b     ",
      "aa aaa  =b      ",
      "       =b      c",
      "aa    =b      cc",
      "aa   =b      ccd",
      "aa  =b      ccdd"
    ],
    [
      "                ",
      "                ",
      "                ",
      "                ",
      "               =",
      "              =b",
      "             =b ",
      "            =b  ",
      "           =b   ",
      "          =b    ",
      "         =b     ",
      "        =b      ",
      "       =b      c",
      "      =b      cc",
      "     =b      ccd",
      "    =b      ccdd"
    ],
    [
      "                ",
      "                ",
      "                ",
      "                ",
      "               =",
      "              =b",
      "             =b ",
      "            =b  ",
      "           =b   ",
      "          =b    ",
      "         =b     ",
      "        =b      ",
      "       =b      c",
      "      =b      cc",
      "     =b      ccd",
      "    =b      ccdd"
    ],
    [
      "                ",
      "                ",
      "                ",
      "                ",
      "               =",
      "              =b",
      "             =b ",
      "            =b  ",
      "           =b   ",
      "          =b    ",
      "         =b     ",
      "        =b      ",
      "       =b      c",
      "      =b      cc",
      "     =b      ccd",
      "    =b      ccdd"
    ]
  ]
}