{
  "name": "multi_nuclearpowerplant_33_base6",
  "refpalette": "deceasedcraft:multi_nuclearpowerplant_33/multi_nuclearpowerplant_33_base6_palette",
  "xsize": 16,
  "zsize": 16,
  "slices": [
    [
      "aaaaaaaaaaaaaaaa",
      "aaaaaaaaaaaaaaaa",
      "aaaaaaaaaaaaaaaa",
      "aaaaaaaaaaaaaaaa",
      "aaaaaaaaaaaaaaa=",
      "aaaaaaaaaaaaaa=b",
      "aaaaaaaaaaaaa=b ",
      "aaaaaaaaaaaa=b  ",
      "aaaaaaaaaaa=b   ",
      "aaaaaaaaaa=b    ",
      "aaaaaaaaa=b     ",
      "aaaaaaaa=b      ",
      "aaaaaaa=b      c",
      "aaaaaa=b      cc",
      "aaaaa=b      ccd",
      "aaaa=b      ccdd"
    ],
    [
      "                ",
      "                ",
      "                ",
      "                ",
      "eeeeeeeeeeeeeef=",
      "gggggggggggggg=b",
      "ggggggggggggg=b ",
      "gggggggggggg=b  ",
      "ggggggggggg=b   ",
      "gggggggggg=b    ",
      "ggggggggg=b     ",
      "gggggggg=b      ",
      "ggggggg=b      c",
      "gggggg=b      cc",
      "ggggg=b      ccd",
      "gggg=b      ccdd"
    ],
    [
      "                ",
      "                ",
      "                ",
      "                ",
      "               =",
      " h h h h h    =b",
      "i   i   i    =b ",
      " h h h h h  =b  ",
      "           =b   ",
      " h h h    =b    ",
      "i   i    =b     ",
      " h h h  =b      ",
      "       =b      c",
      " h    =b      cc",
      "i   !=b      ccd",
      " h  =b      ccjj"
    ],
    [
      "                ",
      "                ",
      "                ",
      "                ",
      "               =",
      "ii iii iii    =b",
      " iki ili i   =b ",
      "ii iii iii  =b  ",
      "           =b   ",
      "ii iii    =b    ",
      " imi i   =b     ",
      "ii iii  =b      ",
      "       =b      c",
      "ii    =b      cc",
      " i   =b      ccd",
      "ii  =b      ccdd"
    ],
    [
      "                ",
      "                ",
      "                ",
      "                ",
      "               =",
      "ii iii iii    =b",
      " i i i i i   =b ",
      "ii iii iii  =b  ",
      "           =b   ",
      "ii iii    =b    ",
      " i i i   =b     ",
      "ii iii  =b      ",
      "       =b      c",
      "ii    =b      cc",
      " i   =b      ccd",
      "ii  =b      ccdd"
    ],
    [
      "                ",
      "                ",
      "                ",
      "                ",
      "               =",
      "ii iii iii    =b",
      " i i i i i   =b ",
      "ii iii iii  =b  ",
      "           =b   ",
      "ii iii    =b    ",
      " i i i   =b     ",
      "ii iii  =b      ",
      "       =b      c",
      "ii    =b      cc",
      " i   =b      ccd",
      "ii  =b      ccdd"
    ]
  ]
}