{
  "name": "multi_nuclearpowerplant_33_ground",
  "refpalette": "deceasedcraft:multi_nuclearpowerplant_33/multi_nuclearpowerplant_33_ground_palette",
  "xsize": 16,
  "zsize": 16,
  "slices": [
    [
      "             abc",
      "             acd",
      "            abcd",
      "            acdd",
      "           abcdd",
      "          eacddd",
      "          acdddc",
      "         abcddcf",
      "         acddcff",
      "        acdddcff",
      "       abcddcfff",
      "       acddcffff",
      "      acddcfffff",
      "     acddcffffff",
      "    acddcfffffff",
      "   acddcffffffff"
    ],
    [
      "      ffffffffff",
      "      ffffffffff",
      "     fffffffffff",
      "     fffffffffff",
      "    ffffffffffff",
      "   fffffffffffff",
      "   fffffffffffff",
      "  ffffffffffffff",
      " fffffffffffffff",
      "ffffffffffffffff",
      "fffffffffffffffz",
      "ffffffffffffffzz",
      "fffffffffffffzzz",
      "ffffffffffffzzzz",
      "fffffffffffzzzzz",
      "ffffffffffzzzzzz"
    ],
    [
      "fffffffzzzzzzzzz",
      "fffffffzzzzzzzzz",
      "fffffffzzzzzzzzz",
      "ffffffzzzzzzzzzz",
      "ffffffzzzdzzzzzz",
      "fffffzzzzzzzzzzz",
      "ffffzzzzzzzzzzzz",
      "ffffzzzzzzzzzzzz",
      "fffzzzddzzzzzdzz",
      "ffzzzzzzzzzzzzzz",
      "fzzzzzzzzzzzzzz ",
      "zzzzzzzzzzzzzzg ",
      "zzzzzzzzzzzzzzh ",
      "zzzzzzzzzzzzg  g",
      "zzzzzzzzzzz  i  ",
      "zzzzzzzzzzzg  g "
    ],
    [
      "zzzzzzz  g  h   ",
      "zzzzzzz      g  ",
      "zzzzzzz   g   g ",
      "zzzzzz          ",
      "zzzzzz     g  gg",
      "zzzzz g    g g  ",
      "zzdzz           ",
      "zzzzg   gggh  i ",
      "zzzz     gg     ",
      "zzg z g  i      ",
      "z  g   g g g    ",
      "  g  g  g g     ",
      "g g   g g       ",
      "  g gh     g    ",
      "g g    gg       ",
      "    g           "
    ],
    [
      " g g  g         ",
      "    gg          ",
      "g g  gg         ",
      "   g g          ",
      "     i          ",
      "                ",
      "                ",
      "g               ",
      "                ",
      "                ",
      "                ",
      "                ",
      "                ",
      "                ",
      "                ",
      "                "
    ],
    [
      "                ",
      "                ",
      "                ",
      "                ",
      "                ",
      "                ",
      "                ",
      "                ",
      "                ",
      "                ",
      "                ",
      "                ",
      "                ",
      "                ",
      "                ",
      "                "
    ]
  ]
}