{
  "name": "multi_nuclearpowerplant_33_base8",
  "refpalette": "deceasedcraft:multi_nuclearpowerplant_33/multi_nuclearpowerplant_33_base8_palette",
  "xsize": 16,
  "zsize": 16,
  "slices": [
    [
      "aaaaaaaaab cd   ",
      "aaaaaaaaab cd   ",
      "aaaaaaaaab cde  ",
      "aaaaaaaaafffd   ",
      "aaaaaaaaafgfd   ",
      "aaaaaaaaafffd   ",
      "aaaaaaaaaaaad   ",
      "aaaaaaaaaaaad   ",
      "aaaaaaaaaaaad   ",
      "ccccccccccccd   ",
      "hhhhhhhhhhhhd   ",
      "hhhhhhhhhhhhd   ",
      "hhhhhhhhhhhhde  ",
      "hhhhhhhhhhhhd   ",
      "hhhhhhhhhhhhd   ",
      "hhhhhhhhhhhhd   "
    ],
    [
      "=========fifjhhh",
      "=========fifjhhh",
      "=========fifjkhh",
      "=========fffjhhh",
      "=========fgfjhhh",
      "=========fffjhhh",
      "============jhhh",
      "============jhhh",
      "============jhhh",
      "============jhhh",
      "===========hhhhh",
      "===========hhhhh",
      "===========hhkhh",
      "===========hhhhh",
      "===========hhhhh",
      "============jhhh"
    ],
    [
      "lllllllllfgfdlll",
      "lllllllllfgfdlll",
      "lllllllllfgfdlll",
      "lllllllllfgfdlll",
      "lllllllllfgfdlll",
      "lllllllllfffdlll",
      "lllllllllllldlll",
      "lllllllllllldlll",
      "lllllllllllldlll",
      "lllllllllllldlll",
      "lllllllllllhmmmn",
      "lllllllllllopppq",
      "lllllllllllopppq",
      "lllllllllllopppq",
      "lllllllllllhmmmr",
      "lllllllllllldlll"
    ],
    [
      "lllllllllfffdlll",
      "lllllllllfffdlll",
      "lllllllllfffdlll",
      "lllllllllfffdlll",
      "lllllllllfffdlll",
      "lllllllllfffdlll",
      "lllllllllllldlll",
      "lllllllllllldlll",
      "lllllllllllldlll",
      "lllllllllllldlll",
      "lllllllllllhhhhh",
      "lllllllllllhhhhh",
      "lllllllllllhhhhh",
      "lllllllllllhhhhh",
      "lllllllllllhhhhh",
      "lllllllllllldlll"
    ],
    [
      "jjjjjjjjjjjjjjjj",
      "jjjjjjjjjjjjjjjj",
      "jjjjjjjjjjjjjjjj",
      "sssssssssssjjjjj",
      "===========sjjjt",
      "===========sjjt=",
      "===========sjt==",
      "===========st===",
      "==========st====",
      "=========st=====",
      "========st======",
      "=======st=======",
      "======st========",
      "=====st=========",
      "====st==========",
      "===st==========="
    ],
    [
      "                ",
      "                ",
      "                ",
      "                ",
      "               =",
      " u u u u u    =k",
      "w   w   w    =kk",
      " u u u u u  =kkk",
      "           =kkkk",
      " u u u    =kkkkk",
      "w   w    =kkkkkk",
      " u u u  =kkkkkkk",
      "       =kkkkkkkk",
      " u    =kkkkkkkkk",
      "w    =kkkkkkkkkk",
      " u  =kkkkkkkkkkk"
    ]
  ]
}