{
  "name": "multi_nuclearpowerplant_33_base10",
  "refpalette": "deceasedcraft:multi_nuclearpowerplant_33/multi_nuclearpowerplant_33_base10_palette",
  "xsize": 16,
  "zsize": 16,
  "slices": [
    [
      "           abc  ",
      "           abc  ",
      "          dabe  ",
      "         fgfbc  ",
      "         hifbc  ",
      "         fffbc  ",
      "jjjjjjjjjjjabc  ",
      "jjjjjjjjjjjabc  ",
      "     kjlljjabc  ",
      "aaaaaaaaaaaabc  ",
      "mmmmmmmmmmmmbc  ",
      "nnnnnnnnnnnmbc  ",
      "nnnnnnnnnnnmbe  ",
      "nnnnnnnnnnnmbc  ",
      "nnnnnnnnnnnmbc  ",
      "nnnnnnnnnnnnbc  "
    ],
    [
      "           ao   ",
      "           ao   ",
      "           aopq ",
      "         fffo   ",
      "         hifo   ",
      "rrrrrrrrrfffo   ",
      "           so   ",
      "rrrrrr     sottt",
      "       ll uso   ",
      "aaaaaaaaaaaao   ",
      "mmmmmmmmmmmmo   ",
      "nnnnnnnnnnnmo   ",
      "nnnnnnnnnnnmopq ",
      "nnnnnnnnnnnmo   ",
      "nnnnnnnnnnnmo   ",
      "nnnnnnnnnnnno   "
    ],
    [
      "           ao   ",
      "           ao   ",
      "           aop  ",
      "         fffo   ",
      "         hifo   ",
      "         fffo   ",
      "            o   ",
      "            wxxx",
      "       ll   o   ",
      "aaaaaaaaaaaao   ",
      "mmmmmmmmmmmmo   ",
      "nnnnnnnnnnnmo   ",
      "nnnnnnnnnnnmop  ",
      "nnnnnnnnnnnmo   ",
      "nnnnnnnnnnnmo   ",
      "nnnnnnnnnnnno   "
    ],
    [
      "           ao   ",
      "           ao   ",
      "           aop  ",
      "         fffo   ",
      "         hifo   ",
      "         fffo   ",
      "            o   ",
      "            y   ",
      "       ll   o   ",
      "aaaaaaaaaaaao   ",
      "mmmmmmmmmmmmo   ",
      "nnnnnnnnnnnmo   ",
      "nnnnnnnnnnnmop  ",
      "nnnnnnnnnnnmo   ",
      "nnnnnnnnnnnmo   ",
      "nnnnnnnnnnnno   "
    ],
    [
      "           ao   ",
      "           ao   ",
      "          daop  ",
      "         fgfo   ",
      "         hifo   ",
      "         fffo   ",
      "            o   ",
      "           Ab   ",
      "       ll   o   ",
      "aaaaaaaaaaaao   ",
      "mmmmmmmmmmmmo   ",
      "nnnnnnnnnnnmo   ",
      "nnnnnnnnnnnmop  ",
      "nnnnnnnnnnnmo   ",
      "nnnnnnnnnnnmo   ",
      "nnnnnnnnnnnno   "
    ],
    [
      "           ao   ",
      "           ao   ",
      "           aop  ",
      "         fffo   ",
      "         hifo   ",
      "         fffo   ",
      "            o   ",
      "            o   ",
      "       ll   o   ",
      "aaaaaaaaaaaao   ",
      "mmmmmmmmmmmmo   ",
      "nnnnnnnnnnnmo   ",
      "nnnnnnnnnnnmop  ",
      "nnnnnnnnnnnmo   ",
      "nnnnnnnnnnnmo   ",
      "nnnnnnnnnnnno   "
    ]
  ]
}