{
  "name": "multi_filmworkstower_0_base2",
  "refpalette": "deceasedcraft:multi_filmworkstower_0/multi_filmworkstower_0_base2_palette",
  "xsize": 16,
  "zsize": 16,
  "slices": [
    [
      "vvvvvvvvvvvvvvvv",
      "vaaaaaaaaaaaaaaa",
      "vaaabbbbbccccccc",
      "vaaabddddeeeeeee",
      "vaaabddddeeeeeee",
      "vaaabfdddeeeeeee",
      "vaaabfdddeeeeeee",
      "vaaabfdddeeeeeee",
      "vaaabddddeeeeeee",
      "vaaabfdddeeeeeee",
      "vaaabfdddeeeeeee",
      "vaaabfdddeeeeeee",
      "vaaabddddeeeeeee",
      "vaaabddddeeeeeee",
      "vaaabddddeeeeeee",
      "vaaabbbbbbbbbbbb"
    ],
    [
      "vvvvvvvvvvvvvvvv",
      "vaaaaaaaaaaaaaaa",
      "vaaabbbbbccccccc",
      "vaaabgh  ijjjk  ",
      "vaaablh  ijjjk  ",
      "vaaabmhn ijjjk  ",
      "vaaabmh  ijjjk  ",
      "vaaabmh  ijjjk  ",
      "vaaablh  ijjjk  ",
      "vaaaboh  ijjjk  ",
      "vaaaboh  ijjjk  ",
      "vaaaboh  ijjjj  ",
      "vaaabph  ijjjj  ",
      "vaaabqh  ijjjj  ",
      "vaaabrh sijjjj  ",
      "vaaabbbbbbbbbbbb"
    ],
    [
      "vvvvvvvvvvvvvvvv",
      "vaaaaaaaaaaaaaaa",
      "vaaabbbbbccccccc",
      "vaaabt   ijjk   ",
      "vaaabu   ijjk   ",
      "vaaab    ijjk   ",
      "vaaab    ijjk   ",
      "vaaab    ijjk   ",
      "vaaabw   ijjk   ",
      "vaaab    ijjk   ",
      "vaaab    ijjk   ",
      "vaaab    ijjkx  ",
      "vaaaby   ijjkA  ",
      "vaaab    ijjjA  ",
      "vaaab   BijjjC  ",
      "vaaabbbbbbbbbbbb"
    ],
    [
      "vvvvvvvvvvvvvvvv",
      "vaaaaaaaaaaaaaaa",
      "vaaabbbbbccccccc",
      "vaaab    ijk    ",
      "vaaab   Dijk    ",
      "vaaab    ijk    ",
      "vaaab   Eijk    ",
      "vaaab   Fijk    ",
      "vaaab   Dijk    ",
      "vaaab   Iijj    ",
      "vaaab    ijj    ",
      "vaaab   Jijj    ",
      "vaaab   Dijj    ",
      "vaaab    ijjx   ",
      "vaaab   sijjC   ",
      "vaaabbbbbbbbbbbb"
    ],
    [
      "vvvvvvvvvvvvvvvv",
      "vaaaaaaaaaaaaaaa",
      "vaaabbbbbccccccc",
      "vaaab    ik     ",
      "vaaabK  Lik     ",
      "vaaab   Lik     ",
      "vaaab   Lik     ",
      "vaaab   Lik     ",
      "vaaabK  Lik     ",
      "vaaab   Likx    ",
      "vaaab   LikA    ",
      "vaaab   LijA    ",
      "vaaabK  LijA    ",
      "vaaab    ijA    ",
      "vaaab  MBijC    ",
      "vaaabbbbbbbbbbbb"
    ],
    [
      "vvvvvvvvvvvvvvvv",
      "vaaaaaaaaaaaaaaa",
      "vaaabbbbbccccccc",
      "vaaabNNNNk      ",
      "vaaabNNNNk      ",
      "vaaabNNNNk      ",
      "vaaabNNNNk      ",
      "vaaabNNNNj      ",
      "vaaabNNNNj      ",
      "vaaabNNNNj      ",
      "vaaabNNNNj      ",
      "vaaabNNNNjx     ",
      "vaaabNNNNjA     ",
      "vaaabNNNNjA     ",
      "vaaabOPQBjC     ",
      "vaaabbbbbbbbbbbb"
    ]
  ]
}