{
  "name": "multi_filmworkstower_0_base1",
  "refpalette": "deceasedcraft:multi_filmworkstower_0/multi_filmworkstower_0_base1_palette",
  "xsize": 16,
  "zsize": 16,
  "slices": [
    [
      "vvvvvvvvvvvvvvvv",
      "vaaaaaaaaaaaaaaa",
      "vaaabbbbbbbbbbbb",
      "vaaabcccd       ",
      "vaaabcccd       ",
      "vaaabcccd       ",
      "vaaabcccd       ",
      "vaaabcccde      ",
      "vaaabcccdf      ",
      "vaaabcccgf      ",
      "vaaabcccgf      ",
      "vaaabcccgf      ",
      "vaaabcccgf      ",
      "vaaabcccgf      ",
      "vaaabccchi      ",
      "vaaajjjjjjjjjjjj"
    ],
    [
      "vvvvvvvvvvvvvvvv",
      "vaaaaaaaaaaaaaaa",
      "vaaabbbbbbbbbbbb",
      "vaaab           ",
      "vaaab           ",
      "vaaab           ",
      "vaaab           ",
      "vaaab           ",
      "vaaab           ",
      "vaaab   kl      ",
      "vaaab   kl      ",
      "vaaab   kl      ",
      "vaaab   kl      ",
      "vaaab   kl      ",
      "vaaab   kl      ",
      "vaaajjjjjjjjjjjj"
    ],
    [
      "vvvvvvvvvvvvvvvv",
      "vaaaaaaaaaaaaaaa",
      "vaaabbbbbbbbbbbb",
      "vaaab           ",
      "vaaab           ",
      "vaaab           ",
      "vaaab           ",
      "vaaab           ",
      "vaaab           ",
      "vaaab    kl     ",
      "vaaab    kl     ",
      "vaaab    kl     ",
      "vaaab    kl     ",
      "vaaab    kl     ",
      "vaaab    kl     ",
      "vaaajjjjjjjjjjjj"
    ],
    [
      "vvvvvvvvvvvvvvvv",
      "vaaaaaaaaaaaaaaa",
      "vaaabbbbbbbbbbbb",
      "vaaab           ",
      "vaaab           ",
      "vaaab           ",
      "vaaab           ",
      "vaaab           ",
      "vaaab           ",
      "vaaab     kl    ",
      "vaaab     kl    ",
      "vaaab     kl    ",
      "vaaab     kl    ",
      "vaaab     kl    ",
      "vaaab     kl    ",
      "vaaajjjjjjjjjjjj"
    ],
    [
      "vvvvvvvvvvvvvvvv",
      "vaaaaaaaaaaaaaaa",
      "vaaabbbbbbbbbbbb",
      "vaaab         mm",
      "vaaab         mm",
      "vaaab         mm",
      "vaaab         mm",
      "vaaab         mm",
      "vaaab         mm",
      "vaaab      kl mm",
      "vaaab      kl mm",
      "vaaab      kl mm",
      "vaaab      kl mm",
      "vaaab      kl mm",
      "vaaab      kl mm",
      "vaaajjjjjjjjjjjj"
    ],
    [
      "vvvvvvvvvvvvvvvv",
      "vaaaaaaaaaaaaaaa",
      "vaaabbbbbbbbbbbb",
      "vaaabnnnnnnnncjj",
      "vaaabnnnnnnnncjj",
      "vaaabnnnnnnnncjj",
      "vaaabnnnnnnnncjj",
      "vaaabnnnnnnnncjj",
      "vaaabnnnnnnnncjj",
      "vaaab       kcjj",
      "vaaab       kcjj",
      "vaaab       kcjj",
      "vaaab       kcjj",
      "vaaab       kcjj",
      "vaaab       kcjj",
      "vaaa jjjjjjjjjjj"
    ]
  ]
}