{
  "name": "multi_filmworkstower_0_ground",
  "refpalette": "deceasedcraft:multi_filmworkstower_0/multi_filmworkstower_0_ground_palette",
  "xsize": 16,
  "zsize": 16,
  "slices": [
    [
      "aaaaaaaaaaaaaaaa",
      "aaaaaaaaaaaaaaaa",
      "aaaaaaaaaaaaaaaa",
      "aaaaaaaaaaaaaaaa",
      "aaaaaaaaaaaaaaaa",
      "aaaaaaaaaaaaaaaa",
      "aaaabbbbbbbbbbbb",
      "aaaabcccccccccdd",
      "aaaabeeeeeeeeedd",
      "aaaab        edd",
      "aaaab        edd",
      "aaaab        edd",
      "aaaab        edd",
      "aaaab        edd",
      "aaaab        edd",
      "aaaab fffffffedd"
    ],
    [
      "                ",
      "                ",
      "                ",
      "                ",
      "                ",
      "                ",
      "     ggggggggggg",
      "     g          ",
      "     g          ",
      "     g          ",
      "     g          ",
      "     g          ",
      "     g          ",
      "     g          ",
      "     g          ",
      "     h          "
    ],
    [
      "                ",
      "                ",
      "                ",
      "                ",
      "                ",
      "                ",
      "      gggggggggg",
      "      g         ",
      "      g         ",
      "      g         ",
      "      g         ",
      "      g         ",
      "      g         ",
      "      g         ",
      "      g         ",
      "      h         "
    ],
    [
      "                ",
      "                ",
      "                ",
      "                ",
      "                ",
      "                ",
      "       ggggggggg",
      "       g        ",
      "       g        ",
      "       g        ",
      "       g        ",
      "       g        ",
      "       g        ",
      "       g        ",
      "       g        ",
      "       h        "
    ],
    [
      "                ",
      "                ",
      "                ",
      "                ",
      "                ",
      "                ",
      "        gggggggg",
      "        g       ",
      "        g       ",
      "        g       ",
      "        g       ",
      "        g       ",
      "        g       ",
      "        g       ",
      "        g       ",
      "        h       "
    ],
    [
      "                ",
      "                ",
      "                ",
      "                ",
      "                ",
      "                ",
      "         ggggggg",
      "         g      ",
      "         g      ",
      "         g      ",
      "         g      ",
      "         g      ",
      "         g      ",
      "         g      ",
      "         g      ",
      "         h      "
    ]
  ]
}