{
  "name": "multi_officethefirst_1_floor6",
  "refpalette": "deceasedcraft:multi_officethefirst_1/multi_officethefirst_1_floor6_palette",
  "xsize": 16,
  "zsize": 16,
  "slices": [
    [
      "     abccdcccccc",
      "     abbbbbbbdbb",
      "     abeeeeeeeee",
      "     abeeeeeeeee",
      "     abeeeeeeeee",
      "     abeeeeeeeee",
      "     abeeeeeeeee",
      "     abeeeddd dd",
      "    fgd ddddd  h",
      "    fi   bddddhh",
      "    fj   bdddddd",
      "    k    bbbbbbb",
      "    fffff       ",
      "          l  mno",
      "                ",
      "                "
    ],
    [
      "      pq r   g  ",
      "      sssssssdtu",
      "      s        w",
      "      s   xxx   ",
      "      s  yABBC  ",
      "      s  DE     ",
      "      s  DF  I u",
      "      sI JbKbdLM",
      "    fgbbNbF ObP ",
      "    fi   bF  bQ ",
      "    fR   bSTUbss",
      "    k    bbbbbbb",
      "    fffff       ",
      "          lmVV  ",
      "                ",
      "                "
    ],
    [
      "         r   g  ",
      "      WWWWWWWdtX",
      "      W         ",
      "      W         ",
      "      W   Y     ",
      "      W         ",
      "      W   Z  0 X",
      "      W1  b2bdL ",
      "    fgbb3b4 5bQ ",
      "    fi   b   bQ ",
      "    fR   b  6bWW",
      "    k    bb78888",
      "    fffff 9     ",
      "         #lV    ",
      "                ",
      "                "
    ],
    [
      "         r   g  ",
      "      WWWWWWWdtt",
      "      W         ",
      "      W         ",
      "      W         ",
      "      W         ",
      "      W        $",
      "      W   b%bdL^",
      "    fgbb%b& *bQ ",
      "    fi   b&  bQ ",
      "    fR   b&  bWW",
      "    f    bbbbbbb",
      "    fffff       ",
      "          l(VV  ",
      "                ",
      "                "
    ],
    [
      "         r   ggg",
      "      WWWWWWWddd",
      "      W         ",
      "      W         ",
      "      W         ",
      "      W         ",
      "      W         ",
      "      W   bbbdLL",
      "    fgbbbb   bQ ",
      "    fi   b   bQ ",
      "    fR   b)  bWW",
      "    f    bbbbbbb",
      "    fffff       ",
      "          l  (n+",
      "                ",
      "                "
    ],
    [
      "         r      ",
      "      ssssssssss",
      "      s---------",
      "      s---------",
      "      s-[----[--",
      "      s---------",
      "      s---------",
      "      s]]]bbbddd",
      "    fgbbbb{{{b}}",
      "    fi   b{{{b}}",
      "    fR   b{{{bss",
      "    f    bbbbbbb",
      "    fffff       ",
      "          l    V",
      "                ",
      "                "
    ]
  ]
}