{
  "name": "multi_officethefirst_1_floor7",
  "refpalette": "deceasedcraft:multi_officethefirst_1/multi_officethefirst_1_floor7_palette",
  "xsize": 16,
  "zsize": 16,
  "slices": [
    [
      "     aaaabaaaaaa",
      "     acccccccccc",
      "     acddddddddd",
      "     acddddddddd",
      "     acddddddddd",
      "     acddddddddd",
      "     acddddddddd",
      "     acdddeee ee",
      "    fgcdddeee   ",
      "    fhiiddeeec  ",
      "    fjcccccccccc",
      "    fklmfaaaaaaa",
      "    fffff       ",
      "          n  opq",
      "                ",
      "                "
    ],
    [
      "         b      ",
      "      rrrrrrrrrr",
      "      r       st",
      "      r uw    st",
      "      rxy AB    ",
      "      r Cw BD   ",
      "      rEF IB J K",
      "      rLM ccceNO",
      "    fgr   P Qc  ",
      "    ferRSTc Uc  ",
      "    ferrrrrrrrrr",
      "    fVVV        ",
      "                ",
      "          noWW  ",
      "                ",
      "                "
    ],
    [
      "         b      ",
      "      XXXXXXXXXX",
      "      X       YZ",
      "      X       0 ",
      "      X 1  2    ",
      "      X 3  2    ",
      "      X 4  2 5 6",
      "      X   ccceN ",
      "    fgX   78 c  ",
      "    fVX9  c #c  ",
      "      XXXXXXXXXX",
      "                ",
      "                ",
      "          nW    ",
      "                ",
      "                "
    ],
    [
      "         b      ",
      "      XXXXXXXXXX",
      "      X         ",
      "      X         ",
      "      X    2    ",
      "      X    2    ",
      "      X    2   $",
      "      X   ccceN%",
      "      X   ^ &c  ",
      "      X*  c (c  ",
      "      XXXXXXXXXX",
      "                ",
      "                ",
      "          nq    ",
      "                ",
      "                "
    ],
    [
      "         b      ",
      "      XXXXXXXXXX",
      "      X         ",
      "      X         ",
      "      X    )    ",
      "      X    )    ",
      "      X    )    ",
      "      X   ccceNN",
      "      X   c  c  ",
      "      X*  c  c  ",
      "      XXXXXXXXXX",
      "                ",
      "                ",
      "          n     ",
      "                ",
      "                "
    ],
    [
      "         b      ",
      "      rrrrrrrrrr",
      "      r+++++++++",
      "      r+++++++++",
      "      r+-++++-++",
      "      r+++++++++",
      "      r+++++++++",
      "      r   ccceee",
      "      r [ cttc  ",
      "      r   cttc  ",
      "      rrrrrrrrrr",
      "                ",
      "                ",
      "          ]     ",
      "                ",
      "                "
    ]
  ]
}