{
  "name": "multi_officethefirst_1_floor3",
  "refpalette": "deceasedcraft:multi_officethefirst_1/multi_officethefirst_1_floor3_palette",
  "xsize": 16,
  "zsize": 16,
  "slices": [
    [
      "     abccdcccccc",
      "     abccccccccc",
      "     abccccccccc",
      "     abccccccccc",
      "     abccccccccc",
      "     abccccccccc",
      "     abccccccccc",
      "     abccccccccc",
      "    efd ddddcccc",
      "    eg   bddcccc",
      "    eh   bddcccc",
      "    i    bbbbbbb",
      "    eeeee       ",
      "          j  klm",
      "                ",
      "                "
    ],
    [
      "      no p  qo  ",
      "      nr    sr  ",
      "      nt    ut  ",
      "      nwx yABw  ",
      "      noC   DEFI",
      "      n!   JKo  ",
      "      nr    sr  ",
      "      nL        ",
      "    efbbMbNbO   ",
      "    eg   b P    ",
      "    eQ   bRbSTUU",
      "    i    bbbbbbb",
      "    eeeee       ",
      "          jkll  ",
      "                ",
      "                "
    ],
    [
      "      V  p  WX  ",
      "      V         ",
      "      V         ",
      "      VW     W  ",
      "      VY    ZY  ",
      "      V0        ",
      "      V         ",
      "      V1        ",
      "    efbb2b3b4   ",
      "    eg   b 5    ",
      "    eQ   b6b7  8",
      "    9    bb#$$$$",
      "    eeeee %     ",
      "         ^jl    ",
      "                ",
      "                "
    ],
    [
      "      V  p      ",
      "      V         ",
      "      V         ",
      "      V         ",
      "      V         ",
      "      V         ",
      "      V         ",
      "      V         ",
      "    efbb&b&b*   ",
      "    eg   b b    ",
      "    eQ   b(b)+)+",
      "    i    bbbbbbb",
      "    eeeee       ",
      "          j-ll  ",
      "                ",
      "                "
    ],
    [
      "      V  p      ",
      "      V         ",
      "      V         ",
      "      V         ",
      "      V         ",
      "      V         ",
      "      V         ",
      "      V   [     ",
      "    efbbbbbb    ",
      "    eg   b b    ",
      "    eQ   b b]]]]",
      "    i    bbbbbbb",
      "    eeeee       ",
      "          j  -{}",
      "                ",
      "                "
    ],
    [
      "      n|;d|||;||",
      "      n|||||||||",
      "      n|||||||||",
      "      n|||||||||",
      "      n|||||||||",
      "      n|;||||;||",
      "      n|||||||||",
      "      n|||||||||",
      "    efbbbbbb::::",
      "    eg   b'b::::",
      "    eQ   b'b<<<<",
      "    i    bbbbbbb",
      "    eeeee       ",
      "          j    l",
      "                ",
      "                "
    ]
  ]
}