{
  "name": "multi_officethefirst_1_floor2",
  "refpalette": "deceasedcraft:multi_officethefirst_1/multi_officethefirst_1_floor2_palette",
  "xsize": 16,
  "zsize": 16,
  "slices": [
    [
      "     abccdcccccc",
      "     abccccccccc",
      "     abccccccccc",
      "     abccccccccc",
      "     abccccccccc",
      "     abccccccccc",
      "    efbccccccccc",
      "    edbccccccccc",
      "    edd dddbgggg",
      "    eh   bdb    ",
      "    ei   bdbjjjj",
      "    e    bbg    ",
      "    eeeee       ",
      "          k     ",
      "                ",
      "                "
    ],
    [
      "      l  m n  n ",
      "      l    o  o ",
      "      l  nppqqpp",
      "      l  rpsssss",
      "      l  tppuupp",
      "      l    w  w ",
      "    e l    t  t ",
      "    exly        ",
      "    edbbAbBbCCCC",
      "    eh   b b    ",
      "    eD   bEbjjjj",
      "    e    bbg    ",
      "    eeeee       ",
      "          kF    ",
      "                ",
      "                "
    ],
    [
      "      j  m      ",
      "      j         ",
      "      j         ",
      "      j   I     ",
      "      j   J     ",
      "      j         ",
      "      j         ",
      "    efjK        ",
      "    edbbLbMb    ",
      "    eh   b bNNNN",
      "    eD   bObbbbb",
      "    e    bbggggg",
      "    eeeee P     ",
      "         QkR    ",
      "                ",
      "                "
    ],
    [
      "      j  m      ",
      "      j         ",
      "      j         ",
      "      j         ",
      "      j         ",
      "      j         ",
      "      j         ",
      "    efj         ",
      "    edbbSbSb    ",
      "    eh   b bNNTT",
      "    eD   bUbbbbb",
      "    C    bbbbbbb",
      "    eeeee       ",
      "          kVRR  ",
      "                ",
      "                "
    ],
    [
      "      j  m      ",
      "      j         ",
      "      j         ",
      "      j         ",
      "      j         ",
      "      j         ",
      "      j         ",
      "    efj   W     ",
      "    edbbbbbb    ",
      "    eh   b bNNXX",
      "    eD   b bbbbb",
      "    C    bbbbbbb",
      "    eeeee       ",
      "          k  VYF",
      "                ",
      "                "
    ],
    [
      "      lZZdZZZZZZ",
      "      lZZZZZZZZZ",
      "      lZZZZ00000",
      "      lZZZZ00000",
      "      lZZZZ00000",
      "      lZZZZZZZZZ",
      "      lZZZZZZZZZ",
      "    e lZZZZZZZZZ",
      "    exbbbbbb1111",
      "    eh   b2b3333",
      "    eD   b2bbbbb",
      "    C    bbbbbbb",
      "    eeeee       ",
      "          k    R",
      "                ",
      "                "
    ]
  ]
}