{
  "name": "multi_officethefirst_1_floor12",
  "refpalette": "deceasedcraft:multi_officethefirst_1/multi_officethefirst_1_floor12_palette",
  "xsize": 16,
  "zsize": 16,
  "slices": [
    [
      "     aaaabaaaaaa",
      "     acccccccccc",
      "     ac         ",
      "     ac         ",
      "     ac         ",
      "     ac         ",
      "     ac       de",
      "     ac   cccfff",
      "     ac   cggc  ",
      "     ac   c gc  ",
      "     acccccccccc",
      "     aaaaaaaaaaa",
      "                ",
      "                ",
      "                ",
      "                "
    ],
    [
      "         b      ",
      "      hhhhhhhhhh",
      "      h         ",
      "      h         ",
      "      h         ",
      "      h         ",
      "      h       ij",
      "      h   cccfff",
      "      h   cklc  ",
      "      h   c lc  ",
      "      hhhhhhhhhh",
      "                ",
      "                ",
      "                ",
      "                ",
      "                "
    ],
    [
      "         b      ",
      "      mmmmmmmmmm",
      "      m         ",
      "      m         ",
      "      m         ",
      "      m         ",
      "      m       no",
      "      m   cccfff",
      "      m   c pc  ",
      "      m   c pc  ",
      "      mmmmmmmmmm",
      "                ",
      "                ",
      "                ",
      "                ",
      "                "
    ],
    [
      "         b      ",
      "      mmmmmmmmmm",
      "      m         ",
      "      m         ",
      "      m         ",
      "      m         ",
      "      m       qr",
      "      m   cccfff",
      "      m   c kc  ",
      "      m   c  c  ",
      "      mmmmmmmmmm",
      "                ",
      "                ",
      "                ",
      "                ",
      "                "
    ],
    [
      "         b      ",
      "      mmmmmmmmmm",
      "      m         ",
      "      m         ",
      "      m         ",
      "      m         ",
      "      m         ",
      "      m   cccfff",
      "      m   c  c  ",
      "      m   c  c  ",
      "      mmmmmmmmmm",
      "                ",
      "                ",
      "                ",
      "                ",
      "                "
    ],
    [
      "         b      ",
      "      hhhhhhhhhh",
      "      hsssssssss",
      "      hsssssssss",
      "      hstssssuss",
      "      hsssssssss",
      "      hsssssssss",
      "      hwwwcccfff",
      "      hwwwcwwc  ",
      "      hwwwcwwc  ",
      "      hhhhhhhhhh",
      "                ",
      "                ",
      "                ",
      "                ",
      "                "
    ]
  ]
}