{
  "name": "multi_officethefirst_1_base3",
  "refpalette": "deceasedcraft:multi_officethefirst_1/multi_officethefirst_1_base3_palette",
  "xsize": 16,
  "zsize": 16,
  "slices": [
    [
      "va    ba cccd   ",
      "va    baefffg   ",
      "va    bahhhh    ",
      "va    ba        ",
      "va    ba        ",
      "va    ba        ",
      "va    ba        ",
      "vaaaaaaa      ii",
      "va  a  a     ijk",
      "va  al a     ikk",
      "va  a  a     ikk",
      "va  aaaa     imk",
      "va    na      ii",
      "va     a  o     ",
      "vaaaaaaaaaaaaaaa",
      "vvvvvvvvvvvvvvvv"
    ],
    [
      "va    pa qqqd   ",
      "va    parss!f   ",
      "va    ptuuuw    ",
      "va    pa        ",
      "va    pa        ",
      "va    pa        ",
      "va   x a        ",
      "vaaaaaaa      ii",
      "va  a  a     iyk",
      "va  al a     ijk",
      "va  a  a     ikk",
      "va  aaaa     ijk",
      "va     a      ii",
      "va     a  o     ",
      "vaaaaaaaaaaaaaaa",
      "vvvvvvvvvvvvvvvv"
    ],
    [
      "va     a qqqd   ",
      "va     aABCDf   ",
      "va     E        ",
      "va     a        ",
      "va     a        ",
      "va     a        ",
      "va  x  a        ",
      "vaaaaaaa      ii",
      "va  a  a     ikk",
      "va  al a     ikk",
      "va  a  a     ikk",
      "va  aaaa     ikk",
      "va     a      ii",
      "va    na  o     ",
      "vaaaaaaaaaaaaaaa",
      "vvvvvvvvvvvvvvvv"
    ],
    [
      "vab    a qqqd   ",
      "vab    aABCDf   ",
      "vab   Fa        ",
      "vab    a        ",
      "vab    a        ",
      "vab    a        ",
      "vabx   a        ",
      "vaaaaaaa      ii",
      "va  a  a     iyk",
      "va  al a     ikk",
      "va  a  a    Iikk",
      "va  aaaa   Joikk",
      "va    na  JoK ii",
      "van    a  oL    ",
      "vaaaaaaaaaaaaaaa",
      "vvvvvvvvvvvvvvvv"
    ],
    [
      "vaM    a qqqd   ",
      "vaM    aACBDf   ",
      "vaM    a        ",
      "vaM    a        ",
      "vaM    a        ",
      "vaM    a        ",
      "va     a        ",
      "vaaaaaaa      ii",
      "va  a  a     ikk",
      "va  al a     ikk",
      "va  a  a     ikk",
      "va  aaaa     ikk",
      "va    na      ii",
      "va     a  o     ",
      "vaaaaaaaaaaaaaaa",
      "vvvvvvvvvvvvvvvv"
    ],
    [
      "va     aNqqqd   ",
      "va     aOCCDf   ",
      "va     aN       ",
      "va     aN       ",
      "va     aN       ",
      "va     aN       ",
      "va     aN       ",
      "vaaaaaaaN     ii",
      "van a  aN    ijk",
      "va  al aN   Pikk",
      "va  a  aNNNNQRkk",
      "va  aaaa     ikk",
      "va     a      ii",
      "va     a  o     ",
      "vaaaaaaaaaaaaaaa",
      "vvvvvvvvvvvvvvvv"
    ]
  ]
}