{
  "name": "multi_officethefirst_1_base1",
  "refpalette": "deceasedcraft:multi_officethefirst_1/multi_officethefirst_1_base1_palette",
  "xsize": 16,
  "zsize": 16,
  "slices": [
    [
      "va    ba cccd   ",
      "va    ba!eeef   ",
      "va    ba        ",
      "va    ba        ",
      "va    ba        ",
      "va    ba        ",
      "va    bagggggggg",
      "vaaaaaaa      hh",
      "va ia  a     hjk",
      "va  al a     hkk",
      "vai a  a     hkj",
      "va  aaaa     hjk",
      "va    ia      hh",
      "vaii  ia  m     ",
      "vaaaaaaaaaaaaaaa",
      "vvvvvvvvvvvvvvvv"
    ],
    [
      "va    na        ",
      "va    nao       ",
      "va    na        ",
      "va    na        ",
      "va    na        ",
      "va    na        ",
      "va    npqqqqqqqr",
      "vaaaaaaa      hs",
      "va  a  a     h  ",
      "va  al a     h  ",
      "va  a  a     h  ",
      "va  aaaa     h  ",
      "vai  i a      hh",
      "vai  iia  m     ",
      "vaaaaaaaaaaaaaaa",
      "vvvvvvvvvvvvvvvv"
    ],
    [
      "va     a        ",
      "va     a        ",
      "va     a        ",
      "va     a        ",
      "va     a        ",
      "va     a        ",
      "va     t        ",
      "vaaaaaaa      hu",
      "va  a  a     h  ",
      "vai al a     h  ",
      "va  a  a     h  ",
      "va  aaaa     h  ",
      "va   iia      hh",
      "va  i  a  m     ",
      "vaaaaaaaaaaaaaaa",
      "vvvvvvvvvvvvvvvv"
    ],
    [
      "va     a        ",
      "va     a        ",
      "va     a        ",
      "va     a        ",
      "va     a        ",
      "va     a        ",
      "va    wa       x",
      "vaaaaaaa      yy",
      "vaiia  a     y  ",
      "vaiial a    Ay  ",
      "vai a  a    Ay  ",
      "vai aaaa     y  ",
      "va iiiia      yy",
      "vaiii ia  m    B",
      "vaaaaaaaaaaaaaaa",
      "vvvvvvvvvvvvvvvv"
    ],
    [
      "vaCCDCCaCCCCCCCC",
      "vaCCCCCaCCCCCCCC",
      "vaCCCCCaCCDDCCCD",
      "vaCCCCCaCCEDCCCD",
      "vaCCECCaCCCCCCCC",
      "vaCCCCCaCCCCCCCC",
      "vaCCCCCaCCCCCCCC",
      "vaaaaaaaCCCCCCFF",
      "vaCCa  aCCCCCFII",
      "vaCCal aCCDDCFII",
      "vaCCa  aCCDDCFII",
      "vaCCaaaaCCCCCFII",
      "vaCCCCCaCCCCCCFF",
      "vaCCCCCaCCmCCCCC",
      "vaaaaaaaaaaaaaaa",
      "vvvvvvvvvvvvvvvv"
    ],
    [
      "vJJJJJJJJJJJJJJJ",
      "vJJJJJJJJJJJJJJJ",
      "vJJJJJJJJJJJJJJJ",
      "vJJJJJJJJJJJJJJJ",
      "vJJJJJJJJJJJJJJJ",
      "vJJJJJJJJJJJJJJJ",
      "vJJJJJJJJJJJJJJJ",
      "vJJJJJJJJJJJJJJJ",
      "vJJJJJJJJJJJJJJJ",
      "vJJJJlJJJJJJJJJJ",
      "vJJJJJJJJJJJJJJJ",
      "vJJJJJJJJJJJJJJJ",
      "vJJJJJJJJJJJJJJJ",
      "vJJJJJJJJJmJJJJJ",
      "vJJJJJJJJJJJJJJJ",
      "vvvvvvvvvvvvvvvv"
    ]
  ]
}