{
  "name": "multi_officethefirst_1_floor10",
  "refpalette": "deceasedcraft:multi_officethefirst_1/multi_officethefirst_1_floor10_palette",
  "xsize": 16,
  "zsize": 16,
  "slices": [
    [
      "     aaaabaaaaaa",
      "     acccccccccc",
      "     acddddddddd",
      "     acddddddddd",
      "     acddddddddd",
      "     acddddddddd",
      "     acddddddddd",
      "     acdddeee ee",
      "     acdddeee   ",
      "     acdddeeec  ",
      "     acccccccccc",
      "     aaaaaaaaaaa",
      "                ",
      "                ",
      "                ",
      "                "
    ],
    [
      "         b      ",
      "      ffffffffff",
      "      fgh iji  k",
      "      f   ljlmn ",
      "      f  oojoo  ",
      "      f    p    ",
      "      f      q r",
      "      fs  cccetu",
      "      fw  x yc  ",
      "      f A c Bc  ",
      "      ffffffffff",
      "                ",
      "                ",
      "                ",
      "                ",
      "                "
    ],
    [
      "         b      ",
      "      CCCCCCCCCC",
      "      CD  EFI  J",
      "      C   KFL   ",
      "      C  M FNO  ",
      "      C         ",
      "      C      P Q",
      "      C   cccet ",
      "      C   R  c  ",
      "      C ! c Sc  ",
      "      CCCCCCCCCC",
      "                ",
      "                ",
      "                ",
      "                ",
      "                "
    ],
    [
      "         b      ",
      "      CCCCCCCCCC",
      "      C         ",
      "      C         ",
      "      C         ",
      "      C         ",
      "      C        T",
      "      C   cccetU",
      "      C   V Wc  ",
      "      C   c Xc  ",
      "      CCCCCCCCCC",
      "                ",
      "                ",
      "                ",
      "                ",
      "                "
    ],
    [
      "         b      ",
      "      CCCCCCCCCC",
      "      C         ",
      "      C         ",
      "      C         ",
      "      C         ",
      "      C         ",
      "      C   cccett",
      "      C   c  c  ",
      "      C   c  c  ",
      "      CCCCCCCCCC",
      "                ",
      "                ",
      "                ",
      "                ",
      "                "
    ],
    [
      "         b      ",
      "      ffffffffff",
      "      fYYYYYYYYY",
      "      fYYYYYYYYY",
      "      fYZYYYYZYY",
      "      fYYYYYYYYY",
      "      fYYYYYYYYY",
      "      f   ccceee",
      "      f   cllc  ",
      "      f   cllc  ",
      "      ffffffffff",
      "                ",
      "                ",
      "                ",
      "                ",
      "                "
    ]
  ]
}