{
  "name": "multi_officethefirst_1_top",
  "refpalette": "deceasedcraft:multi_officethefirst_1/multi_officethefirst_1_top_palette",
  "xsize": 16,
  "zsize": 16,
  "slices": [
    [
      "     aaaaaaaaaaa",
      "     abbbbbbbbbb",
      "     abccccccccc",
      "     abccccccccc",
      "     abccccccccc",
      "     abccccccccc",
      "     abccccccccc",
      "     abcdddddddd",
      "     abcdddddb  ",
      "     abcdddddb  ",
      "     abbbbbbbbbb",
      "     aaaaaaaaaaa",
      "                ",
      "                ",
      "                ",
      "                "
    ],
    [
      "                ",
      "      eeeeeeeeee",
      "      e         ",
      "      e   fgggh ",
      "      e   fgggh ",
      "      e    iji  ",
      "      e    i i  ",
      "      e bbbbbbbb",
      "      e k       ",
      "      e bl      ",
      "      eemmmmmmmm",
      "                ",
      "                ",
      "                ",
      "                ",
      "                "
    ],
    [
      "                ",
      "                ",
      "                ",
      "          fgggh ",
      "          fg!gh ",
      "                ",
      "                ",
      "        bbbbbbbb",
      "        n   o   ",
      "        b       ",
      "        mpqqqpmm",
      "                ",
      "                ",
      "                ",
      "                ",
      "                "
    ],
    [
      "                ",
      "                ",
      "                ",
      "           rss  ",
      "           rrs  ",
      "                ",
      "                ",
      "        bbbbbbbb",
      "        t uu u  ",
      "        b   wxyA",
      "        mmmmmmmm",
      "                ",
      "                ",
      "                ",
      "                ",
      "                "
    ],
    [
      "                ",
      "                ",
      "                ",
      "                ",
      "                ",
      "                ",
      "       aaaaaaaaa",
      "       aBBBBBBBB",
      "       aBCCCCCCC",
      "       aBCCCCCCC",
      "       aDDDDDDDD",
      "                ",
      "                ",
      "                ",
      "                ",
      "                "
    ],
    [
      "                ",
      "                ",
      "                ",
      "                ",
      "                ",
      "                ",
      "                ",
      "                ",
      "                ",
      "                ",
      "                ",
      "                ",
      "                ",
      "                ",
      "                ",
      "                "
    ]
  ]
}