{
  "name": "multi_officethefirst_1_ground",
  "refpalette": "deceasedcraft:multi_officethefirst_1/multi_officethefirst_1_ground_palette",
  "xsize": 16,
  "zsize": 16,
  "slices": [
    [
      "HHabcdaeedeeeeee",
      "HHabcdaeeeeeeeee",
      "HHabcdaeeeeeeeee",
      "HHabcdaeeeeeeeee",
      "HHabcdaeeeeeeeee",
      "HHabcdaeeeeeeeee",
      "HHabcdaeeeeeeeee",
      "HHabcdaeeeeeeeee",
      "HHabcdd ddddeeee",
      "HHabcfg gaddeeee",
      "HHabchgggaddeeee",
      "HHabc gggaaaaaaa",
      "HHabcccccbijjjjj",
      "HHabbbbbbbkjjjjj",
      "HHabbbbbbbijjjjj",
      "HHabbbbbbbijjjjj"
    ],
    [
      "    cdl  m nn o ",
      "    cdlpp  qqqqq",
      "    cdlpr     s ",
      "    cdlpr       ",
      "    cdlpr       ",
      "    cdlpp       ",
      "    cdl         ",
      "    cdlt        ",
      "    cdaauawa xyA",
      "    cfBC a a D E",
      "    cFB  aIaJJKE",
      "    c B  aaL   M",
      "    ccccc       ",
      "          N     ",
      "                ",
      "                "
    ],
    [
      "    cdJ  m      ",
      "    cdJ       OP",
      "    cdJ         ",
      "    cdJ         ",
      "    cdJ         ",
      "    cdJ         ",
      "    cdJ         ",
      "    cdJQ        ",
      "    cdaaRaSa xT ",
      "    cfB  a a   U",
      "    cFB  aVaJJKU",
      "    c W  aaL    ",
      "    ccccc X     ",
      "          N     ",
      "                ",
      "                "
    ],
    [
      "    cYJ  m      ",
      "    cdJ         ",
      "    cdJ         ",
      "    cdJ         ",
      "    cdJ         ",
      "    cdJ         ",
      "    cdJ         ",
      "    cdJ         ",
      "    cdaaZaZa    ",
      "    cfB  a a    ",
      "    cFB  aVaJJKK",
      "    c 0  aaL    ",
      "    ccccc       ",
      "          N     ",
      "                ",
      "                "
    ],
    [
      "    c J  m      ",
      "    c1J         ",
      "    cYJ         ",
      "    cdJ         ",
      "    cdJ         ",
      "    cdJ         ",
      "    cdJ         ",
      "    cdJ         ",
      "    cdaaaaaa    ",
      "    cfB  a a    ",
      "    cFB2 aVaJJJJ",
      "    c B  aaL    ",
      "    ccccc       ",
      "          N     ",
      "                ",
      "                "
    ],
    [
      "      l  m      ",
      "      l         ",
      "    c l         ",
      "    cYl         ",
      "    cdl         ",
      "    cdl         ",
      "    cdl         ",
      "    cdl         ",
      "    cdaaaaaa    ",
      "    cf333a a    ",
      "    cF333aVaJJJJ",
      "    c 333aaL    ",
      "    ccccc       ",
      "          N     ",
      "                ",
      "                "
    ]
  ]
}