{
  "name": "multi_officethefirst_1_floor4",
  "refpalette": "deceasedcraft:multi_officethefirst_1/multi_officethefirst_1_floor4_palette",
  "xsize": 16,
  "zsize": 16,
  "slices": [
    [
      "     abccdcccccc",
      "     abccccccccc",
      "     abccccccccc",
      "     abccccccccc",
      "     abccccccccc",
      "     abccccccccc",
      "     abccccccccc",
      "     abccccccccc",
      "    efd ddddcccc",
      "    eg   bddcccc",
      "    eh   bddcccc",
      "    i    bbbbbbb",
      "    eeeee       ",
      "          j  klm",
      "                ",
      "                "
    ],
    [
      "      no p  qr  ",
      "      ns    ts  ",
      "      nu    wx  ",
      "      nyA BCDy  ",
      "      nEF   IEJK",
      "      nr   Lqr  ",
      "      ns    ts  ",
      "      nM        ",
      "    efbbNbObP   ",
      "    eg   bQR    ",
      "    eS   bTbUVWW",
      "    i    bbbbbbb",
      "    eeeee       ",
      "          jkXX  ",
      "                ",
      "                "
    ],
    [
      "      Y  p   Z  ",
      "      Y         ",
      "      Y         ",
      "      Y0     0  ",
      "      Y1    21  ",
      "      Y         ",
      "      Y         ",
      "      Y3        ",
      "    efbb4b5b6   ",
      "    eg   b 7    ",
      "    eS   b8b  9#",
      "    $    bb%^^^^",
      "    eeeee &     ",
      "         *jX    ",
      "                ",
      "                "
    ],
    [
      "      Y  p      ",
      "      Y         ",
      "      Y         ",
      "      Y         ",
      "      Y         ",
      "      Y         ",
      "      Y         ",
      "      Y         ",
      "    efbb(b(b)   ",
      "    eg   b b    ",
      "    eS   b+b-[-[",
      "    i    bbbbbbb",
      "    eeeee       ",
      "          j]XX  ",
      "                ",
      "                "
    ],
    [
      "      Y  p      ",
      "      Y         ",
      "      Y         ",
      "      Y         ",
      "      Y         ",
      "      Y         ",
      "      Y         ",
      "      Y   {     ",
      "    efbbbbbb    ",
      "    eg   bQb    ",
      "    eS   b!b}}}}",
      "    i    bbbbbbb",
      "    eeeee       ",
      "          j  ]l|",
      "                ",
      "                "
    ],
    [
      "      n;:d;;;';;",
      "      n;;;;;;;;;",
      "      n;;;;;;;;;",
      "      n;;;;;;;;;",
      "      n;;;;;;;;;",
      "      n;:;;;;:;;",
      "      n;;;;;;;;;",
      "      n;;;;;;;;;",
      "    efbbbbbb<<<<",
      "    eg   b>b<<<<",
      "    eS   b>b,,,,",
      "    i    bbbbbbb",
      "    eeeee       ",
      "          j    X",
      "                ",
      "                "
    ]
  ]
}