{
  "name": "multi_officethefirst_1_floor9",
  "refpalette": "deceasedcraft:multi_officethefirst_1/multi_officethefirst_1_floor9_palette",
  "xsize": 16,
  "zsize": 16,
  "slices": [
    [
      "     aaaabaaaaaa",
      "     acccccccccc",
      "     acddddddddd",
      "     acddddddddd",
      "     acddddddddd",
      "     acddddddddd",
      "     acddddddddd",
      "     acdddeee ee",
      "     acdddeee   ",
      "     acdddeeec  ",
      "     acccccccccc",
      "     aaaaaaaaaaa",
      "                ",
      "                ",
      "                ",
      "                "
    ],
    [
      "         b      ",
      "      ffffffffff",
      "      fg  h!hi j",
      "      f klmnm   ",
      "      f  oonoo  ",
      "      f    p    ",
      "      f      q r",
      "      fs  cccetu",
      "      fw  x yc  ",
      "      f ABc Cc  ",
      "      ffffffffff",
      "                ",
      "                ",
      "                ",
      "                ",
      "                "
    ],
    [
      "         b      ",
      "      DDDDDDDDDD",
      "      DE  FIJ  K",
      "      D   LE    ",
      "      D   MENO  ",
      "      D         ",
      "      D      P Q",
      "      D   cccet ",
      "      D   RS c  ",
      "      D   c Tc  ",
      "      DDDDDDDDDD",
      "                ",
      "                ",
      "                ",
      "                ",
      "                "
    ],
    [
      "         b      ",
      "      DDDDDDDDDD",
      "      DU        ",
      "      D         ",
      "      D         ",
      "      D         ",
      "      D        V",
      "      D   cccetW",
      "      D   X Yc  ",
      "      D   c Zc  ",
      "      DDDDDDDDDD",
      "                ",
      "                ",
      "                ",
      "                ",
      "                "
    ],
    [
      "         b      ",
      "      DDDDDDDDDD",
      "      D         ",
      "      D         ",
      "      D         ",
      "      D         ",
      "      D         ",
      "      D   cccett",
      "      D   c  c  ",
      "      D   c  c  ",
      "      DDDDDDDDDD",
      "                ",
      "                ",
      "                ",
      "                ",
      "                "
    ],
    [
      "         b      ",
      "      ffffffffff",
      "      f000000000",
      "      f000000000",
      "      f010000100",
      "      f000000000",
      "      f000000000",
      "      f   ccceee",
      "      f   cmmc  ",
      "      f   cmmc  ",
      "      ffffffffff",
      "                ",
      "                ",
      "                ",
      "                ",
      "                "
    ]
  ]
}