{
  "name": "multi_officethefirst_1_floor5",
  "refpalette": "deceasedcraft:multi_officethefirst_1/multi_officethefirst_1_floor5_palette",
  "xsize": 16,
  "zsize": 16,
  "slices": [
    [
      "     abccdcccccc",
      "     abccccccccc",
      "     abccccccccc",
      "     abccccccccc",
      "     abccccccccc",
      "     abccccccccc",
      "     abccccccccc",
      "     abccccccccc",
      "    efd ddddcccc",
      "    eg   bddcccc",
      "    eh   bddcccc",
      "    i    bbbbbbb",
      "    eeeee       ",
      "          j  klm",
      "                ",
      "                "
    ],
    [
      "      no p qro  ",
      "      ns    ts  ",
      "      nu    wu  ",
      "      nxq   yx  ",
      "      nABCDEFA  ",
      "      no    roBC",
      "      ns    ts  ",
      "      nI        ",
      "    efbbJbKbL   ",
      "    eg   b M    ",
      "    eN   bObPQRR",
      "    i    bbbbbbb",
      "    eeeee       ",
      "          jkSS  ",
      "                ",
      "                "
    ],
    [
      "      T  p      ",
      "      T         ",
      "      T         ",
      "      TU     V  ",
      "      TW    XU  ",
      "      T     VW  ",
      "      T         ",
      "      TY        ",
      "    efbbZb0b1   ",
      "    eg   b 2    ",
      "    eN   b3b4 56",
      "    7    bb89999",
      "    eeeee #     ",
      "         $jS    ",
      "                ",
      "                "
    ],
    [
      "      T  p      ",
      "      T         ",
      "      T         ",
      "      T         ",
      "      T         ",
      "      T         ",
      "      T         ",
      "      T         ",
      "    efbb%b%b^   ",
      "    eg   b b    ",
      "    eN   b&b*(*(",
      "    i    bbbbbbb",
      "    eeeee       ",
      "          j)SS  ",
      "                ",
      "                "
    ],
    [
      "      T  p      ",
      "      T         ",
      "      T         ",
      "      T         ",
      "      T         ",
      "      T         ",
      "      T         ",
      "      T   +     ",
      "    efbbbbbb    ",
      "    eg   b b    ",
      "    eN   b b----",
      "    i    bbbbbbb",
      "    eeeee       ",
      "          j  )l[",
      "                ",
      "                "
    ],
    [
      "      n]{d]]]{]]",
      "      n]]]]]]]]]",
      "      n]]]]]]]]]",
      "      n]]]]]]]]]",
      "      n]]]]]]]]]",
      "      n]}]]]]{]]",
      "      n]]]]]]]]]",
      "      n]]]]]]]]]",
      "    efbbbbbb||||",
      "    eg   b;b||||",
      "    eN   b;b::::",
      "    i    bbbbbbb",
      "    eeeee       ",
      "          j    S",
      "                ",
      "                "
    ]
  ]
}