{
  "name": "multi_officethefirst_1_floor1",
  "refpalette": "deceasedcraft:multi_officethefirst_1/multi_officethefirst_1_floor1_palette",
  "xsize": 16,
  "zsize": 16,
  "slices": [
    [
      "     ab  c      ",
      "     ab         ",
      "     ab         ",
      "    dab         ",
      "    deb         ",
      "    dfb         ",
      "    dfb         ",
      "    dfb         ",
      "    dfbbbbbb    ",
      "    dg   b b    ",
      "    dh   bibjjjj",
      "    d    bbk    ",
      "    ddddd       ",
      "          l     ",
      "                ",
      "                "
    ],
    [
      "      m  c      ",
      "      m         ",
      "      m         ",
      "      m         ",
      "    d m         ",
      "    dem         ",
      "    dfm         ",
      "    dfm         ",
      "    dfbbbbbb    ",
      "    dg   b b    ",
      "    dh   bnbjjjj",
      "    d    bbk    ",
      "    ddddd       ",
      "          l     ",
      "                ",
      "                "
    ],
    [
      "      j  c      ",
      "      j         ",
      "      j         ",
      "      j         ",
      "    d j         ",
      "    doj         ",
      "    dfj         ",
      "    dfj         ",
      "    dfbbbbbb    ",
      "    dg   b b    ",
      "    dh   bnbjjjj",
      "    d    bbk    ",
      "    ddddd p     ",
      "          l     ",
      "                ",
      "                "
    ],
    [
      "      j  c      ",
      "      j         ",
      "      j         ",
      "      j         ",
      "      j         ",
      "    doj         ",
      "    dfj         ",
      "    dfj         ",
      "    dfbbbbbb    ",
      "    dg   b b    ",
      "    dh   bnbjjjj",
      "    d    bbk    ",
      "    ddddd       ",
      "          l     ",
      "                ",
      "                "
    ],
    [
      "      j  c      ",
      "      j         ",
      "      j         ",
      "      j         ",
      "      j         ",
      "    d j         ",
      "    dej         ",
      "    dfj         ",
      "    dfbbbbbb    ",
      "    dg   b b    ",
      "    dh   bqbjjjj",
      "    d    bbk    ",
      "    ddddd       ",
      "          l     ",
      "                ",
      "                "
    ],
    [
      "      mrrfrrrrrr",
      "      mrsrrsrrsr",
      "      mrsrrsrrsr",
      "      mrsrrsrrsr",
      "      mrsrrsrrsr",
      "      mrsrrsrrsr",
      "    domrsrrsrrsr",
      "    dfmrrrrrrrrr",
      "    dfbbbbbb    ",
      "    dg   btb    ",
      "    dh   btbjjjj",
      "    d    bbk    ",
      "    ddddd       ",
      "          l     ",
      "                ",
      "                "
    ]
  ]
}