{
  "name": "multi_officethefirst_1_floor11",
  "refpalette": "deceasedcraft:multi_officethefirst_1/multi_officethefirst_1_floor11_palette",
  "xsize": 16,
  "zsize": 16,
  "slices": [
    [
      "     aaaabaaaaaa",
      "     acccccccccc",
      "     acddddddddd",
      "     acddddddddd",
      "     acddddddddd",
      "     acddddddddd",
      "     acddddddddd",
      "     acdddeee ee",
      "     acdddeee   ",
      "     acdddeeec  ",
      "     acccccccccc",
      "     aaaaaaaaaaa",
      "                ",
      "                ",
      "                ",
      "                "
    ],
    [
      "         b      ",
      "      ffffffffff",
      "      fghi ihi j",
      "      f         ",
      "      f         ",
      "      f      k  ",
      "      f  llllm n",
      "      f  occcepq",
      "      f   r sc  ",
      "      f  tc uc  ",
      "      ffffffffff",
      "                ",
      "                ",
      "                ",
      "                ",
      "                "
    ],
    [
      "         b      ",
      "      wwwwwwwwww",
      "      wxy   A  B",
      "      w         ",
      "      w         ",
      "      w         ",
      "      w  CDEFI J",
      "      w  occcep ",
      "      w   K  c  ",
      "      w   c Lc  ",
      "      wwwwwwwwww",
      "                ",
      "                ",
      "                ",
      "                ",
      "                "
    ],
    [
      "         b      ",
      "      wwwwwwwwww",
      "      wM        ",
      "      w         ",
      "      w         ",
      "      w         ",
      "      w  F  F  N",
      "      w  occcepO",
      "      w   P Qc  ",
      "      w   c Rc  ",
      "      wwwwwwwwww",
      "                ",
      "                ",
      "                ",
      "                ",
      "                "
    ],
    [
      "         b      ",
      "      wwwwwwwwww",
      "      wM        ",
      "      w         ",
      "      w         ",
      "      w         ",
      "      w  FSFC   ",
      "      w  occcepp",
      "      w   c  c  ",
      "      w   c  c  ",
      "      wwwwwwwwww",
      "                ",
      "                ",
      "                ",
      "                ",
      "                "
    ],
    [
      "         b      ",
      "      ffffffffff",
      "      f         ",
      "      f         ",
      "      f         ",
      "      f         ",
      "      f    T    ",
      "      f   ccceee",
      "      f   cUUc  ",
      "      f   cVUc  ",
      "      ffffffffff",
      "                ",
      "                ",
      "                ",
      "                ",
      "                "
    ]
  ]
}