{
  "name": "multi_officethefirst_1_floor8",
  "refpalette": "deceasedcraft:multi_officethefirst_1/multi_officethefirst_1_floor8_palette",
  "xsize": 16,
  "zsize": 16,
  "slices": [
    [
      "     aaaabaaaaaa",
      "     acccccccccc",
      "     acddddddddd",
      "     acddddddddd",
      "     acddddddddd",
      "     acddddddddd",
      "     acddddddddd",
      "     acdddeee ee",
      "     acdddeee   ",
      "     acdddeeec  ",
      "     acccccccccc",
      "     aaaaaaaaaaa",
      "                ",
      "                ",
      "                ",
      "                "
    ],
    [
      "         b      ",
      "      ffffffffff",
      "      fghijkj  l",
      "      f   mkmno ",
      "      f  ppkpp  ",
      "      f    q    ",
      "      f      r s",
      "      ft  ccceuw",
      "      fx  y Ac  ",
      "      fBCDc Ec  ",
      "      ffffffffff",
      "                ",
      "                ",
      "                ",
      "                ",
      "                "
    ],
    [
      "         b      ",
      "      FFFFFFFFFF",
      "      FI  JIK   ",
      "      F   LIM   ",
      "      F  NOIP   ",
      "      F         ",
      "      F      Q R",
      "      F   ccceu ",
      "      F   S Tc  ",
      "      FU  c Vc  ",
      "      FFFFFFFFFF",
      "                ",
      "                ",
      "                ",
      "                ",
      "                "
    ],
    [
      "         b      ",
      "      FFFFFFFFFF",
      "      FW       X",
      "      F         ",
      "      F         ",
      "      F         ",
      "      F        Y",
      "      F   ccceuZ",
      "      F   0 1c  ",
      "      F   cT!c  ",
      "      FFFFFFFFFF",
      "                ",
      "                ",
      "                ",
      "                ",
      "                "
    ],
    [
      "         b      ",
      "      FFFFFFFFFF",
      "      F         ",
      "      F         ",
      "      F         ",
      "      F         ",
      "      F         ",
      "      F   ccceuu",
      "      F   c  c  ",
      "      F   c Tc  ",
      "      FFFFFFFFFF",
      "                ",
      "                ",
      "                ",
      "                ",
      "                "
    ],
    [
      "         b      ",
      "      ffffffffff",
      "      f222222222",
      "      f222222222",
      "      f232222422",
      "      f222222222",
      "      f222222222",
      "      f   ccceee",
      "      f   cmmc  ",
      "      f   cmmc  ",
      "      ffffffffff",
      "                ",
      "                ",
      "                ",
      "                ",
      "                "
    ]
  ]
}