{
  "name": "multi_officethefirst_1_base4",
  "refpalette": "deceasedcraft:multi_officethefirst_1/multi_officethefirst_1_base4_palette",
  "xsize": 16,
  "zsize": 16,
  "slices": [
    [
      "vabbbbbabbbbbbbb",
      "vabbbbbabbbbbbbb",
      "vabbbbbabbbbbbbb",
      "vabbbbbabbbbbbbb",
      "vabbbbbbbbbbbbbb",
      "vabbbbbbbbbbbbbb",
      "vabbbbbabbbbbbbb",
      "vaabaaaabbbbbbcc",
      "vabbabbbbbbbbcdd",
      "vabbabbbbbbbbcdd",
      "vabbabbbbbbbbcdd",
      "vabbaaaabbbbbcdd",
      "vabbbbbabbbbbbcc",
      "vabbbbbabbbbbbbb",
      "vaaaaaaaaaaaaaaa",
      "vvvvvvvvvvvvvvvv"
    ],
    [
      "vaef gha iiij   ",
      "vaek  halmmno   ",
      "vae   da        ",
      "vae    a        ",
      "vaef   p        ",
      "vaq    r        ",
      "vas    a       t",
      "vaauaaaa      ww",
      "vax ay  A    wBC",
      "vax aD  E   FwII",
      "vax aJ  K   FwIC",
      "vaL aaaa     wCI",
      "vaM  NOa      ww",
      "vaP NQ a  R    S",
      "vaaaaaaaaaaaaaaa",
      "vvvvvvvvvvvvvvvv"
    ],
    [
      "vaT   Ua iiiV   ",
      "vaW   XaYZ01o   ",
      "vaW   2a        ",
      "vaW    a        ",
      "vaT    3        ",
      "vaW    4        ",
      "vaW    a        ",
      "vaauaaaa      55",
      "va  a6  7    5BI",
      "va8 aD  E    5II",
      "va  a9  #    5II",
      "va8 aaaa     5II",
      "va     a      55",
      "vaN   Na  R     ",
      "vaaaaaaaaaaaaaaa",
      "vvvvvvvvvvvvvvvv"
    ],
    [
      "va     a iiiV   ",
      "va     aY0Z1o   ",
      "va     a        ",
      "vaf    a        ",
      "va     $        ",
      "va     $        ",
      "va     a        ",
      "vaaaaaaa      55",
      "va  a   E    5CI",
      "va  a%  E    5II",
      "va  a   E   ^5II",
      "va  aaaa   &R5II",
      "va     a  &R* 55",
      "va     a  R*    ",
      "vaaaaaaaaaaaaaaa",
      "vvvvvvvvvvvvvvvv"
    ],
    [
      "va     a iiiV   ",
      "va     aY0Z1o   ",
      "va     a        ",
      "va     a        ",
      "va     $        ",
      "va     $        ",
      "va     a        ",
      "vaaaaaaa      55",
      "va  a   E    5II",
      "va  a%  E    5II",
      "va  a   E    5II",
      "va  aaaa     5BI",
      "va     a      55",
      "va     a  R     ",
      "vaaaaaaaaaaaaaaa",
      "vvvvvvvvvvvvvvvv"
    ],
    [
      "va     a(iiiV   ",
      "va     a)001o   ",
      "va     a(       ",
      "va     a(       ",
      "va     a(       ",
      "va     a(       ",
      "va     a(       ",
      "vaaaaaaa(     55",
      "va  a  a(    5II",
      "va  a% a(   +5II",
      "va  a  a((((-[II",
      "va  aaaa     5BI",
      "va   N a      55",
      "vaN N  a  R     ",
      "vaaaaaaaaaaaaaaa",
      "vvvvvvvvvvvvvvvv"
    ]
  ]
}