{
  "name": "multi_officethefirst_1_base2",
  "refpalette": "deceasedcraft:multi_officethefirst_1/multi_officethefirst_1_base2_palette",
  "xsize": 16,
  "zsize": 16,
  "slices": [
    [
      "va    ba ccde   ",
      "va    bafgggh   ",
      "va    baiiii    ",
      "va    ba        ",
      "va    ba        ",
      "va    ba        ",
      "va    ba        ",
      "vaaaaaaa      jj",
      "va  a  a     jkl",
      "va  am a     jnn",
      "va  a  a     jkn",
      "va  aaaa     jkn",
      "vao    a      jj",
      "vao   oa  p     ",
      "vaaaaaaaaaaaaaaa",
      "vvvvvvvvvvvvvvvv"
    ],
    [
      "va    qa rrre   ",
      "va    qasttug   ",
      "va    qwxxxy    ",
      "va    qa        ",
      "va    qa        ",
      "va    qa        ",
      "va   A a        ",
      "vaaaaaaa      jj",
      "va  a  a     jnn",
      "va  am a     jnn",
      "va  a  a     jnn",
      "va  aaaa     jnn",
      "va     a      jj",
      "va     a  p     ",
      "vaaaaaaaaaaaaaaa",
      "vvvvvvvvvvvvvvvv"
    ],
    [
      "va     a rrre   ",
      "va     aBCDEg   ",
      "va     F        ",
      "va     a        ",
      "va     a        ",
      "va     a        ",
      "va  A  a        ",
      "vaaaaaaa      jj",
      "va oa  a     jkn",
      "va  am a     jnn",
      "va  a  a     jnn",
      "va  aaaa     jnn",
      "va     a      jj",
      "va o   a  p     ",
      "vaaaaaaaaaaaaaaa",
      "vvvvvvvvvvvvvvvv"
    ],
    [
      "vab    a rrre   ",
      "vab    aBCCEg   ",
      "vab   Ia        ",
      "vab    a        ",
      "vab    a        ",
      "vab    a        ",
      "vabA   a        ",
      "vaaaaaaa      jj",
      "va  a  a     jln",
      "va  am a     jnn",
      "va  a  a    Jjnn",
      "va  aaaa   Kpjnl",
      "vao o oa  KpL jj",
      "vao o  a  pL    ",
      "vaaaaaaaaaaaaaaa",
      "vvvvvvvvvvvvvvvv"
    ],
    [
      "vaM    a rrre   ",
      "vaM    aBDCEg   ",
      "vaM    a        ",
      "vaM    a        ",
      "vaM    a        ",
      "vaM    a        ",
      "va     a        ",
      "vaaaaaaa      jj",
      "va  a  a     jnn",
      "va  am a     jnn",
      "va  a  a     jnn",
      "va  aaaa     jln",
      "va   o a      jj",
      "va   ooa  p     ",
      "vaaaaaaaaaaaaaaa",
      "vvvvvvvvvvvvvvvv"
    ],
    [
      "va     aNrrre   ",
      "va     aOCDEg   ",
      "va     aN       ",
      "va     aN       ",
      "va     aN       ",
      "va     aN       ",
      "va     aN       ",
      "vaaaaaaaN     jj",
      "vao a  aN    jkn",
      "va  am aN   Pjln",
      "va  a  aNNNNQRnn",
      "va  aaaa     jSn",
      "va     a      jj",
      "vao o  a  p     ",
      "vaaaaaaaaaaaaaaa",
      "vvvvvvvvvvvvvvvv"
    ]
  ]
}