{
  "name": "multi_nuclearpowerplant_27_base6",
  "refpalette": "deceasedcraft:multi_nuclearpowerplant_27/multi_nuclearpowerplant_27_base6_palette",
  "xsize": 16,
  "zsize": 16,
  "slices": [
    [
      "aaaaaaaaaaaaaaaa",
      "aaaaaaaaaaaaaaaa",
      "aaaaaaaaaaaaaaaa",
      "aaaaaaaaaaaaaa==",
      "aaaaaaaaaaaa====",
      "aaaaaaaaaaa====b",
      "aaaaaaaa=======b",
      "aaaaaa==aaaaaa=b",
      "aaaac=aaaaaaaa=b",
      "aaaaaaaaaaaaaa==",
      "aaaaaaaaaaaaaa==",
      "daaaaaaaaaaaaa==",
      "ddddc=aaaaaaaa=d",
      "eeee====afaaaa=e",
      "eeee===========e",
      "vvvvvvvvvvvvvvvv"
    ],
    [
      "          ghhhhh",
      "          ghhhhh",
      "          ghhhhh",
      "          ghhh==",
      "          gh====",
      "          i====b",
      "        =======b",
      "      ==aaaaaa=b",
      "    c=jakkkkkk=b",
      "    lmjaknnnnn==",
      "    opjaknnnnn==",
      "q   lmjaknnnnn==",
      "eqqqc=jakkkkkk=q",
      "eeee====afaaaa=e",
      "eeee===========e",
      "vvvvvvvvvvvvvvvv"
    ],
    [
      "                ",
      "           r r  ",
      "            s   ",
      "           r r==",
      "            ====",
      "           ====b",
      "        =======b",
      "      ==      =b",
      "    c=        =b",
      "    lm   ttttt==",
      "     u   ttttt==",
      "q   lm   ttttt==",
      "eqqqc=        =q",
      "eeee==== f    =e",
      "eeee===========e",
      "vvvvvvvvvvvvvvvv"
    ],
    [
      "                ",
      "           sss  ",
      "          ws s  ",
      "           sss==",
      "            ====",
      "           ====b",
      "        =======b",
      "      ==      =b",
      "    c=        =b",
      "    lm   xttty==",
      "    AB   Cxxxy==",
      "q   lm   xttty==",
      "eqqqc=        =q",
      "eeee==== f    =e",
      "eeee===========e",
      "vvvvvvvvvvvvvvvv"
    ],
    [
      "                ",
      "           sss  ",
      "           s s  ",
      "           sss==",
      "            ====",
      "           ====b",
      "        =======b",
      "      ==      =b",
      "    c=        =b",
      "    lm   CDDDy==",
      "    lm  ECDDDy==",
      "q   lm   CDFDy==",
      "eqqqc=        =q",
      "eeee==== f    =e",
      "eeee===========e",
      "vvvvvvvvvvvvvvvv"
    ],
    [
      "                ",
      "           sss  ",
      "           s s  ",
      "           sss==",
      "            ====",
      "           ====b",
      "        =======b",
      "      ==      =b",
      "    c=        =b",
      "    lm     D y==",
      "    lm    DDDy==",
      "q   lm     DIy==",
      "eqqqc=      f =q",
      "eeee==== f  f =e",
      "eeee===========e",
      "vvvvvvvvvvvvvvvv"
    ]
  ]
}