{
  "name": "multi_nuclearpowerplant_27_base7",
  "refpalette": "deceasedcraft:multi_nuclearpowerplant_27/multi_nuclearpowerplant_27_base7_palette",
  "xsize": 16,
  "zsize": 16,
  "slices": [
    [
      "                ",
      "           aaa  ",
      "          ba a  ",
      "           aaa  ",
      "               =",
      "c      c      =d",
      "              =d",
      "              =d",
      "e      e      =d",
      "               =",
      "               =",
      "                ",
      "ffffffffffffffff",
      "gggggggggggggggg",
      "gggggggggggggggg",
      "vvvvvvvvvvvvvvvv"
    ],
    [
      "                ",
      "           aaa  ",
      "           a a  ",
      "           aaa  ",
      "               =",
      "c      c      hi",
      "jjjjjjjjjjjjjjhi",
      "jjjjjjjjjjjjjjhi",
      "e      e      hi",
      "               =",
      "               =",
      "                ",
      "ffffffffffffffff",
      "gggggggggggggggg",
      "gggggggggggggggg",
      "vvvvvvvvvvvvvvvv"
    ],
    [
      "                ",
      "           aaa  ",
      "           a a  ",
      "           aaa  ",
      "               =",
      "kkkkkkkkkkkkkkhi",
      "llllllllllllllll",
      "llllllllllllllll",
      "mmmmmmmmmmmmmmhi",
      "               =",
      "               =",
      "                ",
      "ffffffffffffffff",
      "gggggggggggggggg",
      "gggggggggggggggg",
      "vvvvvvvvvvvvvvvv"
    ],
    [
      "                ",
      "           aaa  ",
      "           aaa  ",
      "           aaa  ",
      "               =",
      "kkkkkkkkkkkkkkhi",
      "llllllllllllllll",
      "llllllllllllllll",
      "mmmmmmmmmmmmmmhi",
      "               =",
      "               =",
      "                ",
      "ffffffffffffffff",
      "gggggggggggggggg",
      "gggggggggggggggg",
      "vvvvvvvvvvvvvvvv"
    ],
    [
      "                ",
      "                ",
      "                ",
      "                ",
      "               =",
      "              hi",
      "nnnnnnnnnnnnnnhi",
      "nnnnnnnnnnnnnnhi",
      "              hi",
      "               =",
      "               =",
      "                ",
      "ffffffffffffffff",
      "gggggggggggggggg",
      "gggggggggggggggg",
      "vvvvvvvvvvvvvvvv"
    ],
    [
      "oooooooooooooooo",
      "oooooooooooooooo",
      "oooooooooooooooo",
      "oooooooooooooooo",
      "ooooooooooooooo=",
      "oooooooooooooo=d",
      "oooooooooooooo=d",
      "oooooooooooooo=d",
      "oooooooooooooo=d",
      "ooooooooooooooo=",
      "ooooooooooooooo=",
      "pppppppppppppppp",
      "fffffffffpffffff",
      "gggg=====p=====g",
      "gggg===========g",
      "vvvvvvvvvvvvvvvv"
    ]
  ]
}