{
  "name": "multi_nuclearpowerplant_27_base2",
  "refpalette": "deceasedcraft:multi_nuclearpowerplant_27/multi_nuclearpowerplant_27_base2_palette",
  "xsize": 16,
  "zsize": 16,
  "slices": [
    [
      "    a           ",
      "   a            ",
      " aa             ",
      "a             bb",
      "            bb==",
      "           bcd=e",
      "        bbb fg=e",
      "      bb      =e",
      "  bbbbbh  i   =e",
      "bbb    h      h=",
      "       jjjjjjjh=",
      "              hh",
      "hhhhhhhhhhhhhhhh",
      "kkkkkkkkkikkik=l",
      "kkkkkkkkkkkkkk=l",
      "vvvvvvvvvvvvvvvv"
    ],
    [
      "    a           ",
      "   a            ",
      " aa             ",
      "a             bb",
      "            bb==",
      "           bmn=e",
      "        bbb op=e",
      "      bb      =e",
      "  bbbbqq  i   =e",
      "bbqqqqqq      h=",
      "qqqqqqqqqqqqqqh=",
      "qqqqqqqqqqqqqqhh",
      "hhhhhhhhhhhhhhhh",
      "kkkkkkkkkikkik=l",
      "kkkkkkkkkkkkkk=l",
      "vvvvvvvvvvvvvvvv"
    ],
    [
      "    a           ",
      "   a            ",
      " aa             ",
      "a             bb",
      "            bb==",
      "         r bst=e",
      "        bbb uw=e",
      "      bb      =e",
      "  bbbbiiiii   =e",
      "bb    i       h=",
      "      i       h=",
      "h     i       hh",
      "khhhhhihhhhhhhhh",
      "kkkkkkikkikkik=l",
      "kkkkkkkkkkkkkk=l",
      "vvvvvvvvvvvvvvvv"
    ],
    [
      "    a           ",
      "   a            ",
      " aa             ",
      "a             bb",
      "            bb==",
      "           b  =e",
      "        bbb   =e",
      "      bb      =e",
      "  bbbb        =e",
      "bb            h=",
      "              h=",
      "h             hh",
      "khhhhhhhhhhhhhhh",
      "iiiiiiikkikkik=l",
      "kkkkkkkkkkkkkk=l",
      "vvvvvvvvvvvvvvvv"
    ],
    [
      "  xxy           ",
      "xxxy            ",
      "xyy             ",
      "y             yy",
      "            yyxx",
      "           yxxx=",
      "        yyyxxkk=",
      "      yyxxxxkkk=",
      "  yyyyxxxkkkkkk=",
      "yyxxxxxkkkkkkkkk",
      "xxxkkkkkkkkkkkkk",
      "hkkkkkkkkkkkkkkk",
      "khhhhhhhhhhhhhhh",
      "kkkkkkikkikkik=l",
      "kkkkkkkkkkkkkk=l",
      "vvvvvvvvvvvvvvvv"
    ],
    [
      "AAxxBBBBBBBBBBBB",
      "xxxBBBBBBBBBBBBB",
      "xBBBBBBBBBBBBBBB",
      "BBBBBBBCCCCBBBBB",
      "BBBBBBBBBBBBBBxx",
      "BBBBBBBBBBBBxxxk",
      "CCCCBBBBBBBxxkkk",
      "BBBBBBBBxxxxkkkk",
      "BBBBBBxxxkkkkkkk",
      "BBxxxxxkkkkkkkkk",
      "xxxkkkkkkkkkkkkk",
      "hkkkkkkkkkkkkkkk",
      "khhhhhhhhhhhhhhh",
      "kkkkkkikkikkik=l",
      "kkkkkkkkkkkkkk=l",
      "vvvvvvvvvvvvvvvv"
    ]
  ]
}