{
  "name": "multi_nuclearpowerplant_27_base3",
  "refpalette": "deceasedcraft:multi_nuclearpowerplant_27/multi_nuclearpowerplant_27_base3_palette",
  "xsize": 16,
  "zsize": 16,
  "slices": [
    [
      "  aabccccccccccc",
      "aaabcccccccccccc",
      "abbccccccccccccc",
      "bcccccccccccccbb",
      "ccccccccccccbb==",
      "cccccccccccbbb=d",
      "ccccccccbbbbbb=d",
      "ccccccbbbbbbbb=d",
      "ccbbbbbbbbbbbb=d",
      "bbbbbbbbbbbbbbb=",
      "bbbbbbbbbbbbbbb=",
      "bbbbbbbbbbbbbbbb",
      "eeeeeeeeeeeeeeee",
      "fffffffffgffgf=h",
      "ffffffffffffff=h",
      "vvvvvvvvvvvvvvvv"
    ],
    [
      "    i           ",
      "   i        j   ",
      " ii        kl mn",
      "i         o o pp",
      "         q  pp==",
      "        rssppp=t",
      "       upppppp=t",
      " w xxxpp  p  p=t",
      "  pppppy AyBCy=t",
      "  pDDEEy FyIJyy=",
      "       KLKMKNKy=",
      "           k  yy",
      "yyyyyyyyyyyyyyyy",
      "fffffffffgffgf=h",
      "ffffffffffffff=h",
      "vvvvvvvvvvvvvvvv"
    ],
    [
      "    i           ",
      "   i            ",
      " ii         O  P",
      "i             pp",
      "            pp==",
      "           ppp=t",
      "        pppppp=t",
      "      pp QpR p=t",
      "  pppppy  y  y=t",
      "  pSTTUy  y  yy=",
      "       KVKWKXKy=",
      "              yy",
      "yyyyyyyyyyyyyyyy",
      "fffffffffgffgf=h",
      "ffffffffffffff=h",
      "vvvvvvvvvvvvvvvv"
    ],
    [
      "    i           ",
      "   i            ",
      " ii            Y",
      "i             pp",
      "            pp==",
      "           ppp=t",
      "        pppppp=t",
      "      pp Zp0 p=t",
      "  pppppy  y  y=t",
      "  p1223y  y  yy=",
      "       K4K K4Ky=",
      "              yy",
      "yyyyyyyyyyyyyyyy",
      "fffffffffgffgf=h",
      "ffffffffffffff=h",
      "vvvvvvvvvvvvvvvv"
    ],
    [
      "    i           ",
      "   i            ",
      " ii             ",
      "i             pp",
      "            pp==",
      "           ppp=t",
      "        pppppp=t",
      "      pp  p  p=t",
      "  pppppy  5  y=t",
      "  p    y  y  yy=",
      "       KKKKKKKy=",
      "              yy",
      "yyyyyyyyyyyyyyyy",
      "fffffffffgffgf=h",
      "ffffffffffffff=h",
      "vvvvvvvvvvvvvvvv"
    ],
    [
      "    i           ",
      "   i            ",
      " ii             ",
      "i             pp",
      "            pp==",
      "           p66=t",
      "        ppp 66=t",
      "      pp666666=t",
      "  pppppy66g666=t",
      "ppp    y666666y=",
      "       KKKKKKKy=",
      "              yy",
      "yyyyyyyyyyyyyyyy",
      "fffffffffgffgf=h",
      "ffffffffffffff=h",
      "vvvvvvvvvvvvvvvv"
    ]
  ]
}