{
  "name": "multi_nuclearpowerplant_27_base1",
  "refpalette": "deceasedcraft:multi_nuclearpowerplant_27/multi_nuclearpowerplant_27_base1_palette",
  "xsize": 16,
  "zsize": 16,
  "slices": [
    [
      "aaaaaaaaabbbbbbb",
      "aaaaaaaabbbbbbbb",
      "aaaaaaaabbbbbbbb",
      "aaaaaaabbbbbbbbb",
      "aaaaaabbbbbbbbbb",
      "aaaaabbbbbbbbbba",
      "aaaabbbbbbbbbaac",
      "aaabbbbbbbbbaccc",
      "aabbbbbbbaaacccc",
      "bbbbbbbaaccccccc",
      "bbbaaaaccccccccc",
      "daaccccccccccccc",
      "eddddddddddddddd",
      "eeeeecfccfccfc=g",
      "eeeeeccccccccc=g",
      "vvvvvvvvvvvvvvvv"
    ],
    [
      "         habbbbb",
      "        habbbbbb",
      "        abbbbbbb",
      "       abbbbbbbb",
      "      habbbbbbbb",
      "     aabbbbbbbba",
      "    abbbbbbbbaac",
      "   abbbbbbbbaccc",
      " aabbbbbbaaacccc",
      "abbbbbbaaccccccc",
      "bbbaaaaccccccccc",
      "daaccccccccccccc",
      "cddddddddddddddd",
      "ccccccfccfccfc=g",
      "cccccccccccccc=g",
      "vvvvvvvvvvvvvvvv"
    ],
    [
      "           habbb",
      "          habbbb",
      "         habbbbb",
      "        habbbbbb",
      "        abbbbbbb",
      "       abbbbbbba",
      "     aabbbbbbaac",
      "    abbbbbbbaccc",
      "  aabbbbbaaacccc",
      "aabbbbbaaccccccc",
      "bbbaaaaccccccccc",
      "daaccccccccccccc",
      "cddddddddddddddd",
      "ccccccfccfccfc=g",
      "cccccccccccccc=g",
      "vvvvvvvvvvvvvvvv"
    ],
    [
      "             hab",
      "            habb",
      "           habbb",
      "          habbbb",
      "         aabbbbb",
      "        abbbbbba",
      "       abbbbbaac",
      "     aabbbbbaccc",
      "   aabbbbaaacccc",
      " aabbbbaaccccccc",
      "abbaaaaccccccccc",
      "daaccccccccccccc",
      "cddddddddddddddd",
      "ccccccfccfccfc=g",
      "cccccccccccccc=g",
      "vvvvvvvvvvvvvvvv"
    ],
    [
      "               a",
      "              ab",
      "             abb",
      "            abbb",
      "           abbbb",
      "         aabbbba",
      "        abbbbaac",
      "      aabbbbaccc",
      "    aabbbaaacccc",
      " aaabbbaaccccccc",
      "abbaaaaccccccccc",
      "daaccccccccccccc",
      "cddddddddddddddd",
      "ccccccfccfccfc=g",
      "cccccccccccccc=g",
      "vvvvvvvvvvvvvvvv"
    ],
    [
      "                ",
      "               h",
      "              ha",
      "             hab",
      "            aabb",
      "           abbba",
      "         aabbaac",
      "       aabbbaccc",
      "     aabbaaacccc",
      "  aaabbaaccccccc",
      "iibaaaacccccccii",
      "diiiiiiiiiiiiiic",
      "cddddddddddddddd",
      "ccccccfccfccfc=c",
      "cccccccccccccc=c",
      "vvvvvvvvvvvvvvvv"
    ]
  ]
}