{
  "name": "multi_nuclearpowerplant_27_ground",
  "refpalette": "deceasedcraft:multi_nuclearpowerplant_27/multi_nuclearpowerplant_27_ground_palette",
  "xsize": 16,
  "zsize": 16,
  "slices": [
    [
      "                ",
      "                ",
      "                ",
      "               a",
      "           aaaaa",
      "     baaaaaaaaac",
      "aaaaaaaaaaaaacca",
      "aaaaaaaaaaaacaaa",
      "aaaaaaaaacccaaaa",
      "aaaaaaaccaaaaaaa",
      "ddaccccaaaaaaadd",
      "edddddddddddddde",
      "eeeeeeeeeeeeeeee",
      "eeeeeeeeeeeeeeee",
      "eeeeeeeeeeeeeeee",
      "ezeeeeeeeeeeezez"
    ],
    [
      "aaaaaaaaaaaaaaaa",
      "aaaaaaaaaaaaaaaa",
      "aaaaaaaaaaaaaaaa",
      "aaaaaaaaaaaaaaaa",
      "aaaaaaaaaaaaaaaa",
      "aaaaaaaaaaaazzzz",
      "aaaaaaazzzzzzzzz",
      "zzzzzzzzzzzzzzzz",
      "zzzzzzzzzezzzzez",
      "zzzzzzzzzzzezzzz",
      "zzeezzzezzzzzezz",
      "fzzzzzzzzzzzzzzf",
      " gggggggggggggg ",
      "                ",
      "                ",
      "                "
    ],
    [
      "aaaaaazzzzzzzzzz",
      "azzzzzzzzzzzzzze",
      "zzzzzzzzzzzzzzzz",
      "zzzzzzzzzzzzzzzz",
      "zzzezzezzzzzzzzz",
      "zzzzzzzzzzzzh   ",
      "ezzzzzzzz    z h",
      "ihz          h  ",
      "  hhhhh   h h  h",
      "      h  h  h   ",
      "jj   hh    i  jj",
      " jjjjjjjjjjjjjj ",
      "                ",
      "                ",
      "                ",
      "                "
    ],
    [
      "ezzzzzz  i      ",
      "zz hz       h h ",
      "     h     hkh  ",
      "   h h h k   h  ",
      "  i     ih  h  h",
      "  h hh          ",
      "     h          ",
      "                ",
      "                ",
      "                ",
      "jj            jj",
      " jjjjjjjjjjjjjj ",
      "                ",
      "                ",
      "                ",
      "                "
    ],
    [
      "   h            ",
      "                ",
      "                ",
      "                ",
      "                ",
      "                ",
      "                ",
      "                ",
      "                ",
      "                ",
      "l              l",
      " llllllllllllll ",
      "                ",
      "                ",
      "                ",
      "                "
    ],
    [
      "                ",
      "                ",
      "                ",
      "                ",
      "                ",
      "                ",
      "                ",
      "                ",
      "                ",
      "                ",
      "                ",
      "                ",
      "                ",
      "                ",
      "                ",
      "                "
    ]
  ]
}