{
  "name": "multi_nuclearpowerplant_27_base5",
  "refpalette": "deceasedcraft:multi_nuclearpowerplant_27/multi_nuclearpowerplant_27_base5_palette",
  "xsize": 16,
  "zsize": 16,
  "slices": [
    [
      "                ",
      "           aaa  ",
      "           a a  ",
      "           aaa==",
      "            ====",
      "           ====b",
      "        =======b",
      "      ==      =b",
      "    c=        =b",
      "    de        ==",
      "     e        ==",
      "f   de        ==",
      "gfffc=        =f",
      "gggg==== h  h =g",
      "gggg===========g",
      "vvvvvvvvvvvvvvvv"
    ],
    [
      "                ",
      "           aaa  ",
      "           a a  ",
      "           aaa==",
      "            ====",
      "           ====b",
      "        =======b",
      "      ==      =b",
      "    c=        =b",
      "    de        ==",
      "     e        ==",
      "f   de        ==",
      "gfffc=        =f",
      "gggg==== h  h =g",
      "gggg===========g",
      "vvvvvvvvvvvvvvvv"
    ],
    [
      "                ",
      "           aaa  ",
      "           aaa  ",
      "           aaa==",
      "            ====",
      "           ====b",
      "        =======b",
      "      ==      =b",
      "    c=        =b",
      "    de        ==",
      "     e        ==",
      "f   de        ==",
      "gfffc=        =f",
      "gggg==== h  h =g",
      "gggg===========g",
      "vvvvvvvvvvvvvvvv"
    ],
    [
      "                ",
      "                ",
      "                ",
      "              ==",
      "            ====",
      "           ====b",
      "        =======b",
      "      ==      =b",
      "    c=        =b",
      "    de        ==",
      "     e        ==",
      "f   de        ==",
      "gfffc=        =f",
      "gggg==== h  h =g",
      "gggg===========g",
      "vvvvvvvvvvvvvvvv"
    ],
    [
      "                ",
      "                ",
      "                ",
      "              ==",
      "            ====",
      "           ====b",
      "        =======b",
      "      ==      =b",
      "    c=        =b",
      "    de        ==",
      "    de        ==",
      "f   de        ==",
      "gfffc=        =f",
      "gggg==== h  h =g",
      "gggg===========g",
      "vvvvvvvvvvvvvvvv"
    ],
    [
      "                ",
      "                ",
      "                ",
      "              ==",
      "            ====",
      "           ====b",
      "        =======b",
      "      ==      =b",
      "    c=        =b",
      "    de        ==",
      "    de        ==",
      "f   de        ==",
      "gfffc=        =f",
      "gggg==== h  h =g",
      "gggg===========g",
      "vvvvvvvvvvvvvvvv"
    ]
  ]
}