{
  "name": "multi_nuclearpowerplant_27_base4",
  "refpalette": "deceasedcraft:multi_nuclearpowerplant_27/multi_nuclearpowerplant_27_base4_palette",
  "xsize": 16,
  "zsize": 16,
  "slices": [
    [
      "                ",
      "                ",
      "                ",
      "              ==",
      "            ====",
      "           ====a",
      "        =======a",
      "      ==      =a",
      "    b=        =a",
      "    cd        ==",
      "     d        ==",
      "e   cd        ==",
      "feeeb=        =e",
      "ffff==== g  g =f",
      "ffff===========f",
      "vvvvvvvvvvvvvvvv"
    ],
    [
      "                ",
      "                ",
      "                ",
      "              ==",
      "            ====",
      "           ====a",
      "        =======a",
      "      ==      =a",
      "    b=        =a",
      "    cd        ==",
      "     d        ==",
      "e   cd        ==",
      "feeeb=        =e",
      "ffff==== g  g =f",
      "ffff===========f",
      "vvvvvvvvvvvvvvvv"
    ],
    [
      "                ",
      "                ",
      "                ",
      "              ==",
      "            ====",
      "           ====a",
      "        =======a",
      "      ==      =a",
      "    b=        =a",
      "    cd        ==",
      "     d        ==",
      "e   cd        ==",
      "feeeb=        =e",
      "ffff==== g  g =f",
      "ffff===========f",
      "vvvvvvvvvvvvvvvv"
    ],
    [
      "                ",
      "                ",
      "                ",
      "              ==",
      "            ====",
      "           ====a",
      "        =======a",
      "      ==      =a",
      "    b=        =a",
      "    cd        ==",
      "     d        ==",
      "e   cd        ==",
      "feeeb=        =e",
      "ffff==== g  g =f",
      "ffff===========f",
      "vvvvvvvvvvvvvvvv"
    ],
    [
      "                ",
      "                ",
      "                ",
      "              ==",
      "            ====",
      "           ====a",
      "        =======a",
      "      ==      =a",
      "    b=        =a",
      "    cd        ==",
      "    cd        ==",
      "e   cd        ==",
      "feeeb=        =e",
      "ffff==== g  g =f",
      "ffff===========f",
      "vvvvvvvvvvvvvvvv"
    ],
    [
      "  hh            ",
      "hhh             ",
      "h               ",
      "              ==",
      "            ====",
      "           ====a",
      "        =======a",
      "      ==iiiiii=a",
      "    b=iiiiiiii=a",
      "    ciiiiiiiii==",
      "    ciiiiiiiii==",
      "e   ciiiiiiiii==",
      "ieeeb=iiiiiiii=e",
      "iiii====igiigi=f",
      "iiii===========f",
      "vvvvvvvvvvvvvvvv"
    ]
  ]
}