{
  "name": "building_warehouseb_ground_270",
  "refpalette": "deceasedcraft:building_warehouseb/building_warehouseb_ground_palette_270",
  "xsize": 16,
  "zsize": 16,
  "slices": [
    [
      "azzzzazzzzzaazzz",
      "aaaaazaazzaazaaa",
      "zzaaaaaaaaaaaaaz",
      "zaaaaaaaaaaaaaza",
      "zdbbbddbdbbddbbz",
      "zbbbbbbbbbbbbbbz",
      "zbbbbbbcccccccbz",
      "zbbbbbbcccccccbz",
      "zdbbbbbcccccccbz",
      "zbbbbbbcccccccbz",
      "zbbbbbbcccccccbz",
      "zbbbbbbcccccccbz",
      "zdbbbbbcccccccbz",
      "zdbbbdbcccccccbz",
      "zbbbdbbbbbbbbbbz",
      "zzzzzzzzzzzzzzzz"
    ],
    [
      "  e e  e  e     ",
      "     e      e   ",
      "e               ",
      "                ",
      "               e",
      "  fg  ggnnnnngf ",
      "  ggxxgu     hge",
      "e gBy gt   p !g ",
      "  fAA      l ige",
      "  C      h m jg ",
      "e D      s m kg ",
      "e glplp  p q lge",
      "e gfxxg  l   mf ",
      "  fg  fw t ro!g ",
      "      ffggfgffge",
      " e  e  e e    e "
    ],
    [
      "                ",
      "                ",
      "                ",
      "                ",
      "                ",
      "  gg  fgnnnnngg ",
      "  ffxxgt      g ",
      "  fB  g      pf ",
      "  gIF      h ig ",
      "  J           x ",
      "  K           x ",
      "  gp         kf ",
      "  ggxxg      mg ",
      "  gf  gw E   hf ",
      "      fggfggggg ",
      "                "
    ],
    [
      "                ",
      "                ",
      "                ",
      "                ",
      "                ",
      "  gg  gfnnnnnff ",
      "  ggxxf       g ",
      "  f   g       g ",
      "  gM  L       g ",
      "  N   L       g ",
      "  N   L       g ",
      "  f   L       g ",
      "  ggxxf       g ",
      "  gf  gw      f ",
      "      gggfggfgf ",
      "                "
    ],
    [
      "                ",
      "                ",
      "                ",
      "                ",
      " OOOOOOOOOOOOO  ",
      " OggQQfgfgggggg ",
      " OggPPgPPPPPPPg ",
      " Og   f       g ",
      " OgR  gN      f ",
      " Og   gN M  M g ",
      " Og   gN M  M g ",
      " OgR  gN      g ",
      " OggPPg       g ",
      " OggOOgw      f ",
      " OOOOOgggggfggg ",
      "                "
    ],
    [
      "                ",
      "                ",
      "                ",
      "                ",
      "                ",
      "  VVVVfggfgggfg ",
      "  VVVVgSSSSSSSg ",
      "  VVVVgSSSSSSSg ",
      "  VVVVgSSSSSSSg ",
      "  VVVVgSSUSSTSg ",
      "  VVVVgSSUSSTSf ",
      "  VVVVgSSSSSSSg ",
      "  VVVVgSSSSSSSg ",
      "  VVVVgwSSSSSSg ",
      "      gfggggggg ",
      "                "
    ]
  ]
}