{
  "name": "building_warehouseb_ground_180",
  "refpalette": "deceasedcraft:building_warehouseb/building_warehouseb_ground_palette_180",
  "xsize": 16,
  "zsize": 16,
  "slices": [
    [
      "zzzzzzzzzzzzzzaa",
      "zbddbbbdbbbdazaz",
      "zbbbbbbbbbbbaaaz",
      "zbbbbbbbbbbbaaaz",
      "zdbbbbbbbbbbaaaz",
      "zbdbbbbbbbbdaaza",
      "zbbbbbbbbbbdaaaz",
      "zbccccccccbbaaaz",
      "zbccccccccbdaazz",
      "zbccccccccbbaazz",
      "zbccccccccbbaaaz",
      "zbccccccccbdaaaa",
      "zbccccccccbdaaza",
      "zbccccccccbbaaaz",
      "zbbbbbbbbbbbzaaz",
      "zzzzzzzzzzzzazaz"
    ],
    [
      "   eee  e    e  ",
      "e               ",
      "  fggDCfggf    e",
      "  gfl  ABgg     ",
      "e  xp  Ayx     e",
      "   xl    x    e ",
      " ffgp   ggg     ",
      "efw     tug    e",
      " g        n     ",
      "egtlpsh   n     ",
      " f        n    e",
      " gr qmmlp n     ",
      " fo       n   e ",
      " f!mlkji!hg     ",
      "eggfggggggf     ",
      " e  e  e e e    "
    ],
    [
      "                ",
      "                ",
      "  gggKJgffg     ",
      "  fgp  IBfg     ",
      "   x   F x      ",
      "   x     x      ",
      " fgg    ggf     ",
      " gw      tg     ",
      " g        n     ",
      " fE       n     ",
      " g        n     ",
      " g     h  n     ",
      " g        n     ",
      " ghmk  ip g     ",
      " gfgfxxgfgg     ",
      "                "
    ],
    [
      "                ",
      "                ",
      "  ggfNNgfgg     ",
      "  fg   M gg     ",
      "   x     x      ",
      "   x     x      ",
      " ggfLLLLgfg     ",
      " gw       f     ",
      " g        n     ",
      " f        n     ",
      " g        n     ",
      " g        n     ",
      " f        n     ",
      " g        f     ",
      " ffgggggggf     ",
      "                "
    ],
    [
      "                ",
      " OOOOOOOOOOO    ",
      " OgggggggggO    ",
      " OggR  R ggO    ",
      " OOP     PQO    ",
      " OOP     PQO    ",
      " gggggggfgfO    ",
      " gw NNNN PgO    ",
      " g       PfO    ",
      " g   MM  PgO    ",
      " g       PgO    ",
      " f       PgO    ",
      " g   MM  PgO    ",
      " g       PgO    ",
      " gfggggfggg     ",
      "                "
    ],
    [
      "                ",
      "                ",
      "  VVVVVVVVV     ",
      "  VVVVVVVVV     ",
      "  VVVVVVVVV     ",
      "  VVVVVVVVV     ",
      " gggggggggf     ",
      " fwSSSSSSSg     ",
      " gSSSSSSSSg     ",
      " gSSSUUSSSf     ",
      " gSSSSSSSSg     ",
      " gSSSSSSSSg     ",
      " gSSSTTSSSg     ",
      " gSSSSSSSSf     ",
      " ggggfggggg     ",
      "                "
    ]
  ]
}