{
  "name": "building_warehouseb_ground_90",
  "refpalette": "deceasedcraft:building_warehouseb/building_warehouseb_ground_palette_90",
  "xsize": 16,
  "zsize": 16,
  "slices": [
    [
      "zzzzzzzzzzzzzzzz",
      "zbbbbbbbbbbdbbbz",
      "zbcccccccbdbbbdz",
      "zbcccccccbbbbbdz",
      "zbcccccccbbbbbbz",
      "zbcccccccbbbbbbz",
      "zbcccccccbbbbbbz",
      "zbcccccccbbbbbdz",
      "zbcccccccbbbbbbz",
      "zbcccccccbbbbbbz",
      "zbbbbbbbbbbbbbbz",
      "zbbddbbdbddbbbdz",
      "azaaaaaaaaaaaaaz",
      "zaaaaaaaaaaaaazz",
      "aaazaazzaazaaaaa",
      "zzzaazzzzzazzzza"
    ],
    [
      " e    e e  e  e ",
      "egffgfggff      ",
      " g!or t wf  gf  ",
      " fm   l  gxxfg e",
      "egl q p  plplg e",
      " gk m s      D e",
      " gj m h      C  ",
      "egi l      AAf  ",
      " g! p   tg yBg e",
      "egh     ugxxgg  ",
      " fgnnnnngg  gf  ",
      "e               ",
      "                ",
      "               e",
      "   e      e     ",
      "     e  e  e e  "
    ],
    [
      "                ",
      " gggggfggf      ",
      " fh   E wg  fg  ",
      " gm      gxxgg  ",
      " fk         pg  ",
      " x           K  ",
      " x           J  ",
      " gi h      FIg  ",
      " fp      g  Bf  ",
      " g      tgxxff  ",
      " ggnnnnngf  gg  ",
      "                ",
      "                ",
      "                ",
      "                ",
      "                "
    ],
    [
      "                ",
      " fgfggfggg      ",
      " f      wg  fg  ",
      " g       fxxgg  ",
      " g       L   f  ",
      " g       L   N  ",
      " g       L   N  ",
      " g       L  Mg  ",
      " g       g   f  ",
      " g       fxxgg  ",
      " ffnnnnnfg  gg  ",
      "                ",
      "                ",
      "                ",
      "                ",
      "                "
    ],
    [
      "                ",
      " gggfgggggOOOOO ",
      " f      wgOOggO ",
      " g       gPPggO ",
      " g      Ng  RgO ",
      " g M  M Ng   gO ",
      " g M  M Ng   gO ",
      " f      Ng  RgO ",
      " g       f   gO ",
      " gPPPPPPPgPPggO ",
      " ggggggfgfQQggO ",
      "  OOOOOOOOOOOOO ",
      "                ",
      "                ",
      "                ",
      "                "
    ],
    [
      "                ",
      " gggggggfg      ",
      " gSSSSSSwgVVVV  ",
      " gSSSSSSSgVVVV  ",
      " gSSSSSSSgVVVV  ",
      " fSTSSUSSgVVVV  ",
      " gSTSSUSSgVVVV  ",
      " gSSSSSSSgVVVV  ",
      " gSSSSSSSgVVVV  ",
      " gSSSSSSSgVVVV  ",
      " gfgggfggfVVVV  ",
      "                ",
      "                ",
      "                ",
      "                ",
      "                "
    ]
  ]
}