{
  "name": "building_warehouseb_ground",
  "refpalette": "deceasedcraft:building_warehouseb/building_warehouseb_ground_palette",
  "xsize": 16,
  "zsize": 16,
  "slices": [
    [
      "zazazzzzzzzzzzzz",
      "zaazbbbbbbbbbbbz",
      "zaaabbccccccccbz",
      "azaadbccccccccbz",
      "aaaadbccccccccbz",
      "zaaabbccccccccbz",
      "zzaabbccccccccbz",
      "zzaadbccccccccbz",
      "zaaabbccccccccbz",
      "zaaadbbbbbbbbbbz",
      "azaadbbbbbbbbdbz",
      "zaaabbbbbbbbbbdz",
      "zaaabbbbbbbbbbbz",
      "zaaabbbbbbbbbbbz",
      "zazadbbbdbbbddbz",
      "aazzzzzzzzzzzzzz"
    ],
    [
      "    e e e  e  e ",
      "     fggggggfgge",
      "     gh!ijklm!f ",
      " e   n       of ",
      "     n plmmq rg ",
      "e    n        f ",
      "     n   hspltge",
      "     n        g ",
      "e    gut     wfe",
      "     ggg   pgff ",
      " e    x    lx   ",
      "e     xyA  px  e",
      "     ggBA  lfg  ",
      "e    fggfCDggf  ",
      "               e",
      "  e    e  eee   "
    ],
    [
      "                ",
      "     ggfgxxfgfg ",
      "     g pi  kmhg ",
      "     n        g ",
      "     n  h     g ",
      "     n        g ",
      "     n       Ef ",
      "     n        g ",
      "     gt      wg ",
      "     fgg    ggf ",
      "      x     x   ",
      "      x F   x   ",
      "     gfBI  pgf  ",
      "     gffgJKggg  ",
      "                ",
      "                "
    ],
    [
      "                ",
      "     fgggggggff ",
      "     f        g ",
      "     n        f ",
      "     n        g ",
      "     n        g ",
      "     n        f ",
      "     n        g ",
      "     f       wg ",
      "     gfgLLLLfgg ",
      "      x     x   ",
      "      x     x   ",
      "     gg M   gf  ",
      "     ggfgNNfgg  ",
      "                ",
      "                "
    ],
    [
      "                ",
      "     gggfggggfg ",
      "    OgP       g ",
      "    OgP  MM   g ",
      "    OgP       f ",
      "    OgP       g ",
      "    OgP  MM   g ",
      "    OfP       g ",
      "    OgP NNNN wg ",
      "    Ofgfggggggg ",
      "    OQP     POO ",
      "    OQP     POO ",
      "    Ogg R  RggO ",
      "    OgggggggggO ",
      "    OOOOOOOOOOO ",
      "                "
    ],
    [
      "                ",
      "     gggggfgggg ",
      "     fSSSSSSSSg ",
      "     gSSSTTSSSg ",
      "     gSSSSSSSSg ",
      "     gSSSSSSSSg ",
      "     fSSSUUSSSg ",
      "     gSSSSSSSSg ",
      "     gSSSSSSSwf ",
      "     fggggggggg ",
      "     VVVVVVVVV  ",
      "     VVVVVVVVV  ",
      "     VVVVVVVVV  ",
      "     VVVVVVVVV  ",
      "                ",
      "                "
    ]
  ]
}