{
  "name": "multi_nuclearpowerplant_16_base3",
  "refpalette": "deceasedcraft:multi_nuclearpowerplant_16/multi_nuclearpowerplant_16_base3_palette",
  "xsize": 16,
  "zsize": 16,
  "slices": [
    [
      "                ",
      "                ",
      "                ",
      "                ",
      "                ",
      "                ",
      "                ",
      "                ",
      "                ",
      "    aaaaaaaa    ",
      " aaaa======aaaa ",
      "aa===      ===aa",
      "a==          ==a",
      "=              =",
      "                ",
      "                "
    ],
    [
      "                ",
      "                ",
      "                ",
      "                ",
      "                ",
      "                ",
      "                ",
      "                ",
      "                ",
      "    aaaaaaaa    ",
      " aaaa======aaaa ",
      "aa===      ===aa",
      "a==          ==a",
      "=              =",
      "                ",
      "                "
    ],
    [
      "                ",
      "                ",
      "                ",
      "                ",
      "                ",
      "                ",
      "                ",
      "                ",
      "                ",
      "     bbbbbb     ",
      "  bbaaaaaaaabb  ",
      "caaaa======aaaac",
      "aaa==      ==aaa",
      "a==          ==a",
      "=              =",
      "                "
    ],
    [
      "                ",
      "                ",
      "                ",
      "                ",
      "                ",
      "                ",
      "                ",
      "                ",
      "                ",
      "     bbbbbb     ",
      "  bbaaaaaaaabb  ",
      "caaaa======aaaac",
      "aaa==      ==aaa",
      "a==          ==a",
      "=              =",
      "                "
    ],
    [
      "                ",
      "                ",
      "                ",
      "                ",
      "                ",
      "                ",
      "                ",
      "                ",
      "                ",
      "     bbbbbb     ",
      "   baaaaaaaab   ",
      " aaaa======aaaa ",
      "aaa==      ==aaa",
      "a==          ==a",
      "=              =",
      "                "
    ],
    [
      "                ",
      "                ",
      "                ",
      "                ",
      "                ",
      "                ",
      "                ",
      "                ",
      "                ",
      "     bbbbbb     ",
      "   baaaaaaaab   ",
      " caaa======aaac ",
      "aaa==      ==aaa",
      "a==          ==a",
      "=              =",
      "                "
    ]
  ]
}