{
  "name": "multi_nuclearpowerplant_16_top",
  "refpalette": "deceasedcraft:multi_nuclearpowerplant_16/multi_nuclearpowerplant_16_top_palette",
  "xsize": 16,
  "zsize": 16,
  "slices": [
    [
      "aaabbbbbbbbbbbbb",
      "bbbb            ",
      "b               ",
      "                ",
      "                ",
      "                ",
      "                ",
      "                ",
      "                ",
      "                ",
      "                ",
      "     cccccc     ",
      "  ddeeeeeeeedd  ",
      "ddeeee====eeeedd",
      "eee===    ===eee",
      "ee=          =ee"
    ],
    [
      "zzzbbbbbffff    ",
      "bbbb            ",
      "b               ",
      "                ",
      "                ",
      "                ",
      "                ",
      "                ",
      "                ",
      "                ",
      "                ",
      "     cccccc     ",
      "  ddeeeeeeeedd  ",
      "ddeeee====eeeedd",
      "eee===    ===eee",
      "ee=          =ee"
    ],
    [
      "   f            ",
      "ffff            ",
      "f               ",
      "                ",
      "                ",
      "                ",
      "                ",
      "                ",
      "                ",
      "                ",
      "                ",
      "      cccc      ",
      "   deeeeeeeed   ",
      " deeee====eeeed ",
      "eee===    ===eee",
      "ee=          =ee"
    ],
    [
      "                ",
      "                ",
      "                ",
      "                ",
      "                ",
      "                ",
      "                ",
      "                ",
      "                ",
      "                ",
      "                ",
      "      cccc      ",
      "   ddeeeeeedd   ",
      " deeee====eeeed ",
      "dee===    ===eed",
      "ee=          =ee"
    ],
    [
      "                ",
      "                ",
      "                ",
      "                ",
      "                ",
      "                ",
      "                ",
      "                ",
      "                ",
      "                ",
      "                ",
      "                ",
      "    deeeeeed    ",
      "  eeee====eeee  ",
      "dee===    ===eed",
      "ee=          =ee"
    ],
    [
      "                ",
      "                ",
      "                ",
      "                ",
      "                ",
      "                ",
      "                ",
      "                ",
      "                ",
      "                ",
      "                ",
      "                ",
      "    deeeeeed    ",
      "  eeee====eeee  ",
      "dee===    ===eed",
      "ee=          =ee"
    ],
    [
      "                ",
      "                ",
      "                ",
      "                ",
      "                ",
      "                ",
      "                ",
      "                ",
      "                ",
      "                ",
      "                ",
      "                ",
      "    deeeeeed    ",
      "  eeee====eeee  ",
      "dee===    ===eed",
      "ee=          =ee"
    ],
    [
      "                ",
      "                ",
      "                ",
      "                ",
      "                ",
      "                ",
      "                ",
      "                ",
      "                ",
      "                ",
      "                ",
      "                ",
      "    deeeeeed    ",
      "  eeee====eeee  ",
      "dee===    ===eed",
      "ee=          =ee"
    ],
    [
      "                ",
      "                ",
      "                ",
      "                ",
      "                ",
      "                ",
      "                ",
      "                ",
      "                ",
      "                ",
      "                ",
      "                ",
      "     eeeeee     ",
      "  eeee====eeee  ",
      " ee===    ===ee ",
      "ee=          =ee"
    ],
    [
      "                ",
      "                ",
      "                ",
      "                ",
      "                ",
      "                ",
      "                ",
      "                ",
      "                ",
      "                ",
      "                ",
      "                ",
      "     eeeeee     ",
      "  eeee====eeee  ",
      " ee===    ===ee ",
      "ee=          =ee"
    ],
    [
      "                ",
      "                ",
      "                ",
      "                ",
      "                ",
      "                ",
      "                ",
      "                ",
      "                ",
      "                ",
      "                ",
      "                ",
      "     eeeeee     ",
      "  eeee====eeee  ",
      " ee===    ===ee ",
      "ee=          =ee"
    ],
    [
      "                ",
      "                ",
      "                ",
      "                ",
      "                ",
      "                ",
      "                ",
      "                ",
      "                ",
      "                ",
      "                ",
      "                ",
      "     eeeeee     ",
      "  eeee====eeee  ",
      " ee===    ===ee ",
      "ee=          =ee"
    ],
    [
      "                ",
      "                ",
      "                ",
      "                ",
      "                ",
      "                ",
      "                ",
      "                ",
      "                ",
      "                ",
      "                ",
      "                ",
      "     eeeeee     ",
      "  eeee====eeee  ",
      " ee===    ===ee ",
      "ee=          =ee"
    ],
    [
      "                ",
      "                ",
      "                ",
      "                ",
      "                ",
      "                ",
      "                ",
      "                ",
      "                ",
      "                ",
      "                ",
      "                ",
      "     eeeeee     ",
      "  eeee====eeee  ",
      " ee===    ===ee ",
      "ee=          =ee"
    ],
    [
      "                ",
      "                ",
      "                ",
      "                ",
      "                ",
      "                ",
      "                ",
      "                ",
      "                ",
      "                ",
      "                ",
      "                ",
      "     eeeeee     ",
      "  eeee====eeee  ",
      " ee===    ===ee ",
      "ee=          =ee"
    ],
    [
      "                ",
      "                ",
      "                ",
      "                ",
      "                ",
      "                ",
      "                ",
      "                ",
      "                ",
      "                ",
      "                ",
      "                ",
      "    deeeeeed    ",
      "  eeee====eeee  ",
      "dee===    ===eed",
      "ee=          =ee"
    ],
    [
      "                ",
      "                ",
      "                ",
      "                ",
      "                ",
      "                ",
      "                ",
      "                ",
      "                ",
      "                ",
      "                ",
      "                ",
      "    deeeeeed    ",
      "  eeee====eeee  ",
      "dee===    ===eed",
      "ee=          =ee"
    ],
    [
      "                ",
      "                ",
      "                ",
      "                ",
      "                ",
      "                ",
      "                ",
      "                ",
      "                ",
      "                ",
      "                ",
      "                ",
      "    eeeeeeee    ",
      "  eeee====eeee  ",
      "eee===    ===eee",
      "ee=          =ee"
    ],
    [
      "                ",
      "                ",
      "                ",
      "                ",
      "                ",
      "                ",
      "                ",
      "                ",
      "                ",
      "                ",
      "                ",
      "     cccccc     ",
      "   ceeeeeeeec   ",
      " ceeee====eeeec ",
      "eee===    ===eee",
      "ee=          =ee"
    ],
    [
      "                ",
      "                ",
      "                ",
      "                ",
      "                ",
      "                ",
      "                ",
      "                ",
      "                ",
      "                ",
      "                ",
      "     cccccc     ",
      "   ceeeeeeeec   ",
      " ceeee====eeeec ",
      "eee===    ===eee",
      "ee=          =ee"
    ],
    [
      "                ",
      "                ",
      "                ",
      "                ",
      "                ",
      "                ",
      "                ",
      "                ",
      "                ",
      "                ",
      "                ",
      "    eeeeeeee    ",
      "  eeeggggggeee  ",
      "eeeggg    gggeee",
      "egg          gge",
      "gg            gg"
    ]
  ]
}