{
  "name": "multi_nuclearpowerplant_16_base4",
  "refpalette": "deceasedcraft:multi_nuclearpowerplant_16/multi_nuclearpowerplant_16_base4_palette",
  "xsize": 16,
  "zsize": 16,
  "slices": [
    [
      "                ",
      "                ",
      "                ",
      "                ",
      "                ",
      "                ",
      "                ",
      "     aaaaaa     ",
      "  aabbbbbbbbaa  ",
      "abbbb======bbbba",
      "bb===cccccc===bb",
      "==  deeeeeef  ==",
      "=   deghhgef   =",
      "    def  def    ",
      "    def  def    ",
      "ccccgegccgegcccc"
    ],
    [
      "                ",
      "                ",
      "                ",
      "                ",
      "                ",
      "                ",
      "                ",
      "     aaaaaa     ",
      "  aabbbbbbbbaa  ",
      "abbbb======bbbba",
      "bb===      ===bb",
      "==            ==",
      "=              =",
      "                ",
      "                ",
      "                "
    ],
    [
      "                ",
      "                ",
      "                ",
      "                ",
      "                ",
      "                ",
      "                ",
      "                ",
      "    bbbbbbbb    ",
      " bbbb======bbbb ",
      "bb===      ===bb",
      "==            ==",
      "=              =",
      "                ",
      "                ",
      "                "
    ],
    [
      "                ",
      "                ",
      "                ",
      "                ",
      "                ",
      "                ",
      "                ",
      "                ",
      "     aaaaaa     ",
      "  aabbbbbbbbaa  ",
      "ibbbb======bbbbi",
      "bb===      ===bb",
      "b==          ==b",
      "=              =",
      "                ",
      "                "
    ],
    [
      "                ",
      "                ",
      "                ",
      "                ",
      "                ",
      "                ",
      "                ",
      "                ",
      "     aaaaaa     ",
      "  aabbbbbbbbaa  ",
      "ibbbb======bbbbi",
      "bb===      ===bb",
      "b==          ==b",
      "=              =",
      "                ",
      "                "
    ],
    [
      "                ",
      "                ",
      "                ",
      "                ",
      "                ",
      "                ",
      "                ",
      "                ",
      "     aaaaaa     ",
      "  aabbbbbbbbaa  ",
      "ibbbb======bbbbi",
      "bb===      ===bb",
      "b==          ==b",
      "=              =",
      "                ",
      "                "
    ]
  ]
}