{
  "name": "multi_nuclearpowerplant_16_base8",
  "refpalette": "deceasedcraft:multi_nuclearpowerplant_16/multi_nuclearpowerplant_16_base8_palette",
  "xsize": 16,
  "zsize": 16,
  "slices": [
    [
      "aaaaaaaaaaaaaaaa",
      "aaaaaaaaaaaaaaaa",
      "aaaaaaaaaaaaaaaa",
      "aaaabbbbbbbbaaaa",
      "abbbccccccccbbba",
      "bccc========cccb",
      "c==============c",
      "====dddddddd====",
      "=ddd e    e ddd=",
      "d    e    e    d",
      "e    e    e    e",
      "fggggfggggfggggf",
      "e    e    e    e",
      "e    e    e    e",
      "e    e    e    e",
      "e    e    e    e"
    ],
    [
      "================",
      "================",
      "================",
      "======hhhh======",
      "====iiiiiiii====",
      "=iiiddddddddiii=",
      "iddddjjjjjjddddi",
      "ddjjjjjjjjjjjjdd",
      "jjjjjjjjjjjjjjjj",
      "jjjjjjjjjjjjjjjj",
      "jjjjjjjjjjjjjjjj",
      "jjjjjjjjjjjjjjjj",
      "jjjjjjjjjjjjjjjj",
      "jjjjjjjjjjjjjjjj",
      "jjjjjjjjjjjjjjjj",
      "jjjjjjjjjjjjjjjj"
    ],
    [
      "kkkkkkkkkkkkkkkk",
      "kkkkkkkkkkkkkkkk",
      "kkkkkkkkkkkkkkkk",
      "kkkkkkhllhkkkkkk",
      "kkkkmmmmmmmmkkkk",
      "kmmmddddddddmmmk",
      "mddddllllllddddm",
      "ddlllllllllllldd",
      "llllllllllllllll",
      "llllllllllllllll",
      "llllllllllllllll",
      "llllllllllllllll",
      "llllllllllllllll",
      "llllllllllllllll",
      "llllllllllllllll",
      "llllllllllllllll"
    ],
    [
      "kkkkkkkkkkkkkkkk",
      "kkkkkkkkkkkkkkkk",
      "kkkkkkkkkkkkkkkk",
      "kkkkkkhhhhkkkkkk",
      "kkkkmmmmmmmmkkkk",
      "kmmmddddddddmmmk",
      "mddddllllllddddm",
      "ddlllllllllllldd",
      "llllllllllllllll",
      "llllllllllllllll",
      "llllllllllllllll",
      "llllllllllllllll",
      "llllllllllllllll",
      "llllllllllllllll",
      "llllllllllllllll",
      "llllllllllllllll"
    ],
    [
      "nnnnnnnnnnnnnnnn",
      "nnnnnnnnnnnnnnnn",
      "nnnnnnnnnnnnnnnn",
      "nnnoooooooooonnn",
      "ooooiiiiiiiioooo",
      "oiiiddddddddiiio",
      "iddddllllllddddi",
      "ddlllllllllllldd",
      "llllllllllllllll",
      "llllllllllllllll",
      "llllllllllllllll",
      "llllllllllllllll",
      "llllllllllllllll",
      "llllllllllllllll",
      "llllllllllllllll",
      "llllllllllllllll"
    ],
    [
      "                ",
      "                ",
      "                ",
      "                ",
      "    mmmmmmmm    ",
      " mmmddddddddmmm ",
      "mddddllllllddddm",
      "ddlllllllllllldd",
      "llllllllllllllll",
      "llllllllllllllll",
      "llllllllllllllll",
      "llllllllllllllll",
      "llllllllllllllll",
      "llllllllllllllll",
      "llllllllllllllll",
      "llllllllllllllll"
    ]
  ]
}