{
  "name": "multi_nuclearpowerplant_16_base7",
  "refpalette": "deceasedcraft:multi_nuclearpowerplant_16/multi_nuclearpowerplant_16_base7_palette",
  "xsize": 16,
  "zsize": 16,
  "slices": [
    [
      "                ",
      "                ",
      "                ",
      "                ",
      "    aaaaaaaa    ",
      " aaabbbbbbbbaaa ",
      "abbbbccccccbbbba",
      "bbccccccccccccbb",
      "cccccccccccccccc",
      "cccccccccccccccc",
      "cccccccccccccccc",
      "cccccccccccccccc",
      "cccccccccccccccc",
      "cccccccccccccccc",
      "cccccccccccccccc",
      "cccccccccccccccc"
    ],
    [
      "       dd       ",
      "       dd       ",
      "       dd       ",
      "       dd       ",
      "    aaeeeeaa    ",
      " aaabbbbbbbbaaa ",
      "abbbbccccccbbbba",
      "bbccccccccccccbb",
      "cccccccccccccccc",
      "cccccccccccccccc",
      "cccccccccccccccc",
      "cccccccccccccccc",
      "cccccccccccccccc",
      "cccccccccccccccc",
      "cccccccccccccccc",
      "cccccccccccccccc"
    ],
    [
      "      fccg      ",
      "      fccg      ",
      "      fccg      ",
      "      fccg      ",
      "    aaecceaa    ",
      " aaabbbccbbbaaa ",
      "abbbbccccccbbbba",
      "bbccccccccccccbb",
      "cccccccccccccccc",
      "cccccccccccccccc",
      "cccccccccccccccc",
      "cccccccccccccccc",
      "cccccccccccccccc",
      "cccccccccccccccc",
      "cccccccccccccccc",
      "cccccccccccccccc"
    ],
    [
      "      fccg      ",
      "      fccg      ",
      "      fccg      ",
      "      fccg      ",
      "    aaecceaa    ",
      " aaabbbccbbbaaa ",
      "abbbbccccccbbbba",
      "bbccccccccccccbb",
      "cccccccccccccccc",
      "cccccccccccccccc",
      "cccccccccccccccc",
      "cccccccccccccccc",
      "cccccccccccccccc",
      "cccccccccccccccc",
      "cccccccccccccccc",
      "cccccccccccccccc"
    ],
    [
      "       hh       ",
      "       hh       ",
      "       hh       ",
      "       hh       ",
      "    aaeeeeaa    ",
      " aaabbbbbbbbaaa ",
      "abbbbccccccbbbba",
      "bbciccccccccccbb",
      "jccccccccccccccc",
      "cicccccccccccccc",
      "cccccccccccccccc",
      "cccccccccccccccc",
      "cccccccccccccccc",
      "cccccccccccccccc",
      "cccccccccccccccc",
      "cccccccccccccccc"
    ],
    [
      "kkkkk      kkkkk",
      "kkkkk      kkkkk",
      "kkkkk      kkkkk",
      "kkkllllllllllkkk",
      "lllm        mlll",
      "l   bbbbbbbb   l",
      " bbbb      bbbb ",
      "bb            bb",
      "                ",
      "                ",
      "                ",
      "                ",
      "                ",
      "                ",
      "                ",
      "                "
    ]
  ]
}