{
  "name": "multi_nuclearpowerplant_16_base12",
  "refpalette": "deceasedcraft:multi_nuclearpowerplant_16/multi_nuclearpowerplant_16_base12_palette",
  "xsize": 16,
  "zsize": 16,
  "slices": [
    [
      "aaaaaaaaaaaaaaaa",
      "aaaaaaaaaaaaaaaa",
      "aaaaaaaaaaaaaaaa",
      "aaaaaaaaaaaaaaaa",
      "aaaaaaaaaaaaaaaa",
      "aaaaaaaaaaaaaaaa",
      "aaaaaaaaaaaaaaaa",
      "aaaaaaaaaaaaaaaa",
      "aaaaaaaaaaaaaaaa",
      "aaaaaaaaaaaaaaaa",
      "aaaaaaaaaaaaaaaa",
      "aaaaaaaaaaaaaaaa",
      "aaaaaaaaaaaaaaaa",
      "aaaaaaaaaaaaaaaa",
      "aaaaaaaaaaaaaaaa",
      "aaaaaaaaaaaaaaaa"
    ],
    [
      "bbbbbbbbbbbbbbbb",
      "bbbbbbbbbbbbbbbb",
      "bbbbbbbbbbbbbbbb",
      "bbbbbbbbbbbbbbbb",
      "bbbbbbbbbbbbbbbb",
      "bbbbbbbbbbbbbbbb",
      "bbbbbbbbbbbbbbbb",
      "bbbbbbbbbbbbbbbb",
      "bbbbbbbbbbbbbbbb",
      "bbbbbbbbbbbbbbbb",
      "bbbbbbbbbbbbbbbb",
      "bbbbbbbbbbbbbbbb",
      "bbbbbbbbbbbbbbbb",
      "bbbbbbbbbbbbbbbb",
      "bbbbbbbbbbbbbbbb",
      "bbbbbbbbbbbbbbbb"
    ],
    [
      "cccccccccccccccc",
      "cccccccccccccccc",
      "cccccccccccccccc",
      "cccccccccccccccc",
      "cccccccccccccccc",
      "cccccccccccccccc",
      "cccccccccccccccc",
      "cccccccccccccccc",
      "cccccccccccccccc",
      "cccccccccccccccc",
      "cccccccccccccccc",
      "cccccccccccccccc",
      "cccccccccccccccc",
      "cccccccccccccccc",
      "cccccccccccccccc",
      "cccccccccccccccc"
    ],
    [
      "                ",
      "de    fdde    fd",
      "                ",
      "                ",
      "                ",
      "dggggggddggggggd",
      "hhhhhhihhhhhhhhh",
      "iiiiiiiiiiiiiiii",
      "hihhhhhhhhhhhhhh",
      "djjjjjjddjjjjjjd",
      "                ",
      "                ",
      "                ",
      "de    fdde    fd",
      "                ",
      "                "
    ],
    [
      "                ",
      "d      dd      d",
      "       dd       ",
      "       dd       ",
      "       dd       ",
      "dk    lddk    ld",
      "               m",
      "               n",
      "               m",
      "dk    lddk    ld",
      "       dd       ",
      "       dd       ",
      "       dd       ",
      "dk    lddk    ld",
      "                ",
      "                "
    ],
    [
      "                ",
      "d      dd      d",
      "                ",
      "                ",
      "                ",
      "dddddddddddddddd",
      "               o",
      "               o",
      "               o",
      "dddddddddddddddd",
      "                ",
      "                ",
      "pqqqqqqppqqqqqqp",
      "dddddddddddddddd",
      "rqqqqqqrrqqqqqqr",
      "                "
    ]
  ]
}