{
  "name": "multi_nuclearpowerplant_16_base5",
  "refpalette": "deceasedcraft:multi_nuclearpowerplant_16/multi_nuclearpowerplant_16_base5_palette",
  "xsize": 16,
  "zsize": 16,
  "slices": [
    [
      "                ",
      "                ",
      "                ",
      "                ",
      "                ",
      "                ",
      "      =  =      ",
      "   =        =   ",
      "=              =",
      "                ",
      "                ",
      "                ",
      "                ",
      "                ",
      "                ",
      "                "
    ],
    [
      "                ",
      "                ",
      "                ",
      "                ",
      "                ",
      "                ",
      "                ",
      "     ab  ab     ",
      "   ab      ab   ",
      "b              a",
      "                ",
      "                ",
      "                ",
      "                ",
      "                ",
      "                "
    ],
    [
      "                ",
      "                ",
      "                ",
      "                ",
      "                ",
      "                ",
      "                ",
      "     =    =     ",
      "    =      =    ",
      "                ",
      "                ",
      "                ",
      "                ",
      "                ",
      "                ",
      "                "
    ],
    [
      "                ",
      "                ",
      "                ",
      "                ",
      "                ",
      "                ",
      "    cccccccc    ",
      " cccc=dddd=cccc ",
      "ccdd=eeeeee=ddcc",
      "ddeeeffffffeeedd",
      "eeffffffffffffee",
      "ffffffffffffffff",
      "ffffffffffffffff",
      "ffffffffffffffff",
      "ffffffffffffffff",
      "ffffffffffffffff"
    ],
    [
      "                ",
      "                ",
      "                ",
      "                ",
      "                ",
      "                ",
      "     gggggg     ",
      "  gghhhhhhhhgg  ",
      "ghhhh======hhhhg",
      "hh===      ===hh",
      "==            ==",
      "                ",
      "                ",
      "                ",
      "                ",
      "                "
    ],
    [
      "                ",
      "                ",
      "                ",
      "                ",
      "                ",
      "                ",
      "                ",
      "    hhhhhhhh    ",
      " hhhh======hhhh ",
      "hh===      ===hh",
      "==   i    i   ==",
      "    j~kllm~n    ",
      "     o    o     ",
      "     l    l     ",
      "     l    l     ",
      "i    p    p    i"
    ]
  ]
}