{
  "name": "multi_nuclearpowerplant_16_ground",
  "refpalette": "deceasedcraft:multi_nuclearpowerplant_16/multi_nuclearpowerplant_16_ground_palette",
  "xsize": 16,
  "zsize": 16,
  "slices": [
    [
      "                ",
      "                ",
      "                ",
      "                ",
      "                ",
      "                ",
      "                ",
      "                ",
      "                ",
      "                ",
      "                ",
      "    aaaaaaaa    ",
      "  aaa======aaa  ",
      "aaa===    ===aaa",
      "a==          ==a",
      "==            =="
    ],
    [
      "                ",
      "                ",
      "                ",
      "                ",
      "                ",
      "                ",
      "                ",
      "                ",
      "                ",
      "                ",
      "                ",
      "    aaaaaaaa    ",
      "  aaa======aaa  ",
      "aaa===    ===aaa",
      "a==          ==a",
      "==            =="
    ],
    [
      "                ",
      "                ",
      "                ",
      "                ",
      "                ",
      "                ",
      "                ",
      "                ",
      "                ",
      "                ",
      "                ",
      "    aaaaaaaa    ",
      "  aaa======aaa  ",
      "aaa===    ===aaa",
      "a==          ==a",
      "==            =="
    ],
    [
      "                ",
      "                ",
      "                ",
      "                ",
      "                ",
      "                ",
      "                ",
      "                ",
      "                ",
      "                ",
      "                ",
      "    aaaaaaaa    ",
      "  aaa======aaa  ",
      "aaa===    ===aaa",
      "a==          ==a",
      "==            =="
    ],
    [
      "             b  ",
      "                ",
      "                ",
      "                ",
      "                ",
      "                ",
      "                ",
      "                ",
      "                ",
      "                ",
      "                ",
      "    aaaaaaaa    ",
      "  aaa======aaa  ",
      "aaa===    ===aaa",
      "a==          ==a",
      "==            =="
    ],
    [
      "        cccccccc",
      " b              ",
      "                ",
      "                ",
      "                ",
      "                ",
      "                ",
      "                ",
      "                ",
      "                ",
      "                ",
      "     dddddd     ",
      "  eeaaaaaaaaee  ",
      "eeaaaa====aaaaee",
      "aaa===    ===aaa",
      "aa=          =aa"
    ]
  ]
}