{
  "name": "multi_nuclearpowerplant_16_base2",
  "refpalette": "deceasedcraft:multi_nuclearpowerplant_16/multi_nuclearpowerplant_16_base2_palette",
  "xsize": 16,
  "zsize": 16,
  "slices": [
    [
      "                ",
      "                ",
      "                ",
      "                ",
      "                ",
      "                ",
      "                ",
      "                ",
      "                ",
      "     aaaaaa     ",
      "   abbbbbbbba   ",
      " cbbb======bbbc ",
      "bbb==      ==bbb",
      "b==          ==b",
      "=              =",
      "                "
    ],
    [
      "                ",
      "                ",
      "                ",
      "                ",
      "                ",
      "                ",
      "                ",
      "                ",
      "                ",
      "                ",
      "    bbbbbbbb    ",
      " cbbb======bbbc ",
      "bbb==      ==bbb",
      "b==          ==b",
      "=              =",
      "                "
    ],
    [
      "                ",
      "                ",
      "                ",
      "                ",
      "                ",
      "                ",
      "                ",
      "                ",
      "                ",
      "                ",
      "    bbbbbbbb    ",
      "  bbb======bbb  ",
      "bbb==      ==bbb",
      "b==          ==b",
      "=              =",
      "                "
    ],
    [
      "                ",
      "                ",
      "                ",
      "                ",
      "                ",
      "                ",
      "                ",
      "                ",
      "                ",
      "                ",
      "    bbbbbbbb    ",
      "  bbb======bbb  ",
      "bbb==      ==bbb",
      "b==          ==b",
      "=              =",
      "                "
    ],
    [
      "                ",
      "                ",
      "                ",
      "                ",
      "                ",
      "                ",
      "                ",
      "                ",
      "                ",
      "                ",
      "     aaaaaa     ",
      "   abbbbbbbba   ",
      " abbb======bbba ",
      "bbb===    ===bbb",
      "b==          ==b",
      "==            =="
    ],
    [
      "                ",
      "                ",
      "                ",
      "                ",
      "                ",
      "                ",
      "                ",
      "                ",
      "                ",
      "                ",
      "     aaaaaa     ",
      "   abbbbbbbba   ",
      " abbb======bbba ",
      "bbb===    ===bbb",
      "b==          ==b",
      "==            =="
    ]
  ]
}