{
  "name": "multi_nuclearpowerplant_25_base8",
  "refpalette": "deceasedcraft:multi_nuclearpowerplant_25/multi_nuclearpowerplant_25_base8_palette",
  "xsize": 16,
  "zsize": 16,
  "slices": [
    [
      "    a b==cdeeeee",
      "    ab==cdeeeeee",
      "    ab==cdeeeeee",
      "    b==cdeeeeeee",
      "fffb==cdeeeeeeee",
      " bb==cdeeeeeeeee",
      "b===cdeeeeeeeeee",
      "===cdeeeeeeeeeee",
      "=ccdeeeeeeeeeeee",
      "cddeeeeeeeeeeeee",
      "deeeeeeeeeeeeeee",
      "eeeeeeeeeeeeeeee",
      "eeeeeeeeeeeeeeee",
      "eeeeeeeeeeeeeeee",
      "eeeeeeeeeeeeeeee",
      "eeeeeeeeeeeeeeee"
    ],
    [
      "gggggggbbh======",
      "gggggggbh=======",
      "ggggggbbh=======",
      "gggggbbh========",
      "ggggbbh=========",
      "gggbbh==========",
      "ggbbh===========",
      "bbbh============",
      "bhh=============",
      "h===============",
      "================",
      "================",
      "================",
      "================",
      "================",
      "================"
    ],
    [
      "iiiiiiibbjkkkkkk",
      "iiiiiiibjkkkkkkk",
      "iiiiiibbjkkkkkkk",
      "iiiiibbjkkkkkkkk",
      "iiiibbjkkkkkkkkk",
      "iiibbjkkkkkkkkkk",
      "iibbjkkkkkkkkkkk",
      "bbbjkkkkkkkkkkkk",
      "bjjkkkkkkkkkkkkk",
      "jkkkkkkkkkkkkkkk",
      "kkkkkkkkkkkkkkkk",
      "kkkkkkkkkkkkkkkk",
      "kkkkkkkkkkkkkkkk",
      "kkkkkkkkkkkkkkkk",
      "kkkkkkkkkkkkkkkk",
      "kkkkkkkkkkkkkkkk"
    ],
    [
      "iiiiiiibbjkkkkkk",
      "iiiiiiibjkkkkkkk",
      "iiiiiibbjkkkkkkk",
      "iiiiibbjkkkkkkkk",
      "iiiibbjkkkkkkkkk",
      "iiibbjkkkkkkkkkk",
      "iibbjkkkkkkkkkkk",
      "bbbjkkkkkkkkkkkk",
      "bjjkkkkkkkkkkkkk",
      "jkkkkkkkkkkkkkkk",
      "kkkkkkkkkkkkkkkk",
      "kkkkkkkkkkkkkkkk",
      "kkkkkkkkkkkkkkkk",
      "kkkkkkkkkkkkkkkk",
      "kkkkkkkkkkkkkkkk",
      "kkkkkkkkkkkkkkkk"
    ],
    [
      "iiiiiiibbhlmmmmm",
      "iiiiiiibhllmmmmm",
      "iiiiiibbhlmmmmmm",
      "iiiiibbhllmmmmmm",
      "iiiibbhllmmmmmmm",
      "iiibbhllmmmmmmmm",
      "iibbhllmmmmmmmmm",
      "bbbhllmmmmmmmmmm",
      "bhhllmmmmmmmmmmm",
      "hlllmmmmmmmmmmmm",
      "llmmmmmmmmmmmmmm",
      "mmmmmmmmmmmmmmmm",
      "mmmmmmmmmmmmmmmm",
      "mmmmmmmmmmmmmmmm",
      "mmmmmmmmmmmmmmmm",
      "mmmmmmmmmmmmmmmm"
    ],
    [
      "iiiiiiibbj      ",
      "iiiiiiibj       ",
      "iiiiiibbj       ",
      "iiiiibbj        ",
      "iiiibbj         ",
      "iiibbj          ",
      "iibbj           ",
      "bbbj            ",
      "bjj             ",
      "j               ",
      "                ",
      "                ",
      "                ",
      "                ",
      "                ",
      "                "
    ]
  ]
}