{
  "name": "multi_nuclearpowerplant_25_base12",
  "refpalette": "deceasedcraft:multi_nuclearpowerplant_25/multi_nuclearpowerplant_25_base12_palette",
  "xsize": 16,
  "zsize": 16,
  "slices": [
    [
      "aaaaaaaaaaaaaaaa",
      "aaaaaaaaaaaaaaaa",
      "aaaaaaaaaaaaaaaa",
      "aaaaaaaaaaaaaaaa",
      "aaaaaaaaaaaaaaaa",
      "aaaaaaaaaaaaaaaa",
      "aaaaaaaaaaaaaaaa",
      "aaaaaaaaaaaaaaaa",
      "aaaaaaaaaaaaaaaa",
      "aaaaaaaaaaaaaaaa",
      "aaaaaaaaaaaaaaaa",
      "aaaaaaaaaaaaaaaa",
      "aaaaaaaaaaaaaaaa",
      "aaaaaaaaaaaaaaaa",
      "aaaaaaaaaaaaaaaa",
      "aaaaaaaaaaaaaaaa"
    ],
    [
      "bbbbbbbbbbbbbbbb",
      "bbbbbbbbbbbbbbbb",
      "bbbbbbbbbbbbbbbb",
      "bbbbbbbbbbbbbbbb",
      "bbbbbbbbbbbbbbbb",
      "bbbbbbbbbbbbbbbb",
      "bbbbbbbbbbbbbbbb",
      "bbbbbbbbbbbbbbbb",
      "bbbbbbbbbbbbbbbb",
      "bbbbbbbbbbbbbbbb",
      "bbbbbbbbbbbbbbbb",
      "bbbbbbbbbbbbbbbb",
      "bbbbbbbbbbbbbbbb",
      "bbbbbbbbbbbbbbbb",
      "bbbbbbbbbbbbbbbb",
      "bbbbbbbbbbbbbbbb"
    ],
    [
      "cccccccccccccccc",
      "cccccccccccccccc",
      "cccccccccccccccc",
      "cccccccccccccccc",
      "cccccccccccccccc",
      "cccccccccccccccc",
      "cccccccccccccccc",
      "cccccccccccccccc",
      "cccccccccccccccc",
      "cccccccccccccccc",
      "cccccccccccccccc",
      "cccccccccccccccc",
      "cccccccccccccccc",
      "cccccccccccccccc",
      "cccccccccccccccc",
      "cccccccccccccccc"
    ],
    [
      "                ",
      "                ",
      "de   fdghde     ",
      "                ",
      "                ",
      "                ",
      "diiiiiiddj      ",
      "klkkkklllm      ",
      "lllllllllm      ",
      "kkkkkllklm      ",
      "dnnnnnnddo      ",
      "                ",
      "                ",
      "      p         ",
      "de   fdghde    q",
      "              hr"
    ],
    [
      "                ",
      "                ",
      "dg   hdddd      ",
      "       dd       ",
      "       dd       ",
      "       dd       ",
      "dg    hdd       ",
      "                ",
      "                ",
      "                ",
      "dg    hdd       ",
      "       dd       ",
      "       dd       ",
      "       dd       ",
      "d     dddd    qs",
      "             hr "
    ],
    [
      "                ",
      "tuuuuu          ",
      "ddddddd  d      ",
      "wuuuuu   d      ",
      "         d      ",
      "         d      ",
      "dddddddddd      ",
      "         d      ",
      "         d      ",
      "         d      ",
      "dddddddddd      ",
      "         d      ",
      "         d      ",
      "         d      ",
      "d     d  d   qs ",
      "            hr  "
    ]
  ]
}