{
  "name": "multi_nuclearpowerplant_25_base7",
  "refpalette": "deceasedcraft:multi_nuclearpowerplant_25/multi_nuclearpowerplant_25_base7_palette",
  "xsize": 16,
  "zsize": 16,
  "slices": [
    [
      "aaaaaaabbc      ",
      "aaaaaaabc       ",
      "aaaaaabbc       ",
      "aaaaabbc        ",
      "aaaabbc         ",
      "aaabbc          ",
      "aabbc           ",
      "bbbc            ",
      "bcc             ",
      "c               ",
      "                ",
      "                ",
      "                ",
      "                ",
      "                ",
      "                "
    ],
    [
      "aaaaaaabbc      ",
      "aaaaaaabc       ",
      "aaaaaabbc       ",
      "aaaaabbc        ",
      "aaaabbc         ",
      "aaabbc          ",
      "aabbc           ",
      "bbbc            ",
      "bcc             ",
      "c               ",
      "                ",
      "                ",
      "                ",
      "                ",
      "                ",
      "                "
    ],
    [
      "aaaaaaabbc      ",
      "aaaaaaabc       ",
      "aaaaaaddc       ",
      "aaaaadd         ",
      "aaaadd          ",
      "aaadd           ",
      "aadd            ",
      "bbd             ",
      "bcc             ",
      "c               ",
      "                ",
      "                ",
      "                ",
      "                ",
      "                ",
      "                "
    ],
    [
      "aaaaaaabbc      ",
      "aaaaaaabc       ",
      "aaaaaaddc       ",
      "aaaaadd         ",
      "aaaadd          ",
      "aaadd           ",
      "aadd            ",
      "bbd             ",
      "bcc             ",
      "c               ",
      "                ",
      "                ",
      "                ",
      "                ",
      "                ",
      "                "
    ],
    [
      "aaaaaaabbc      ",
      "aaaaaaabc       ",
      "aaaaaabbc       ",
      "aaaaabbc        ",
      "aaaabbc         ",
      "aaabbc          ",
      "aabbc           ",
      "bbbc            ",
      "bcc             ",
      "c               ",
      "                ",
      "                ",
      "                ",
      "                ",
      "                ",
      "                "
    ],
    [
      "       bb efffff",
      "       b eefffff",
      "      bb effffff",
      "     bb geffffff",
      "    bb eefffffff",
      "   bb eeffffffff",
      "  bb eefffffffff",
      "bbb eeffffffffff",
      "b  gefffffffffff",
      " eeeffffffffffff",
      "eeffffffffffffff",
      "ffffffffffffffff",
      "ffffffffffffffff",
      "ffffffffffffffff",
      "ffffffffffffffff",
      "ffffffffffffffff"
    ]
  ]
}