{
  "name": "multi_nuclearpowerplant_25_base6",
  "refpalette": "deceasedcraft:multi_nuclearpowerplant_25/multi_nuclearpowerplant_25_base6_palette",
  "xsize": 16,
  "zsize": 16,
  "slices": [
    [
      "         abccccc",
      "        abbccccc",
      "        abcccccc",
      "       abbcccccc",
      "      abbccccccc",
      "     abbcccccccc",
      "    abbccccccccc",
      "   abbcccccccccc",
      " aabbccccccccccc",
      "abbbcccccccccccc",
      "bbcccccccccccccc",
      "cccccccccccccccc",
      "cccccccccccccccc",
      "cccccccccccccccc",
      "cccccccccccccccc",
      "cccccccccccccccc"
    ],
    [
      "       dde      ",
      "       de       ",
      "      dde       ",
      "     dde        ",
      "    dde         ",
      "   dde          ",
      "  dde           ",
      "ddde            ",
      "dee             ",
      "e               ",
      "                ",
      "                ",
      "                ",
      "               f",
      "                ",
      "                "
    ],
    [
      "       ==       ",
      "       =        ",
      "      ==        ",
      "     ==         ",
      "    ==          ",
      "   ==           ",
      "  ==            ",
      "===             ",
      "=               ",
      "                ",
      "                ",
      "                ",
      "                ",
      "                ",
      "                ",
      "                "
    ],
    [
      "                ",
      "                ",
      "                ",
      "                ",
      "     =          ",
      "    =           ",
      "                ",
      "                ",
      "                ",
      "                ",
      "                ",
      "                ",
      "                ",
      "                ",
      "                ",
      "                "
    ],
    [
      "                ",
      "                ",
      "                ",
      "     g          ",
      "     h          ",
      "   ij           ",
      "                ",
      "                ",
      "                ",
      "                ",
      "                ",
      "                ",
      "                ",
      "                ",
      "                ",
      "                "
    ],
    [
      "                ",
      "                ",
      "                ",
      "     =          ",
      "                ",
      "   =            ",
      "                ",
      "                ",
      "                ",
      "                ",
      "                ",
      "                ",
      "                ",
      "                ",
      "                ",
      "                "
    ]
  ]
}