{
  "name": "building_processingunita_ground",
  "refpalette": "deceasedcraft:building_processingunita/building_processingunita_ground_palette",
  "xsize": 16,
  "zsize": 16,
  "slices": [
    [
      "aazzzzzzzzzzzzzz",
      "aaazzzzzzzzzzzzz",
      "aazbbbbbbbbbbbzz",
      "aaabbbbbbbbbbbzz",
      "zaabbbbbbbbbbbzz",
      "aaabbbbbbbbbbbzz",
      "aaabbbbbbbbbbbzz",
      "azabbbbbbbbbbbzz",
      "aaabbbbbbbbcbbzz",
      "aaabbbbbbbbbbbzz",
      "zaabbbbbbbbcbbzz",
      "zaabbbbbbbbbbbzz",
      "aaabbbbbbbbbbbzz",
      "aazbbbbbbbbbbbzz",
      "aazzzzzzzzzzzzzz",
      "aaazzzzzzzzzzzzz"
    ],
    [
      "    d  e   d d d",
      "      d     f d ",
      "   ggggggggggg  ",
      "   gh!i hjklhg d",
      "    mmm nj   g  ",
      "        opqppg  ",
      "           rsgd ",
      "           tsg  ",
      "          uwsg  ",
      "          uwsg  ",
      "          uxsg d",
      "    sssssyABsgd ",
      "   ghCDEhFIIhg  ",
      "   gggggggggggd ",
      "   dd ddd dJ    ",
      "    Kdd dJdd  e "
    ],
    [
      "                ",
      "            f   ",
      "   ggggggggggg  ",
      "   ghmm hj  hg  ",
      "   L m   j   g  ",
      "   L    MpNppg  ",
      "   L       Osg  ",
      "   L       Psg  ",
      "   L        sg  ",
      "   L        sg  ",
      "   L        sg  ",
      "   L    QR Ssg  ",
      "   gh   hIIIhg  ",
      "   ggggggggggg  ",
      "                ",
      "                "
    ],
    [
      "                ",
      "            T   ",
      "   ggggggggggg  ",
      "   gh   hj  hg  ",
      "   L U   j   g  ",
      "   L     ppppg  ",
      "   L        sg  ",
      "   L        sg  ",
      "   L       Vsg  ",
      "   L       Wsg  ",
      "   L       Xsg  ",
      "   L     YYZZg  ",
      "   gh0 1hIIIhg  ",
      "   ggggggggggg  ",
      "                ",
      "                "
    ],
    [
      "                ",
      "                ",
      "   gg234g234gg  ",
      "   gh555h555hg  ",
      "  6g7    j   g  ",
      "  6g7    ppppg  ",
      "  6g7        g  ",
      "  6g7        g  ",
      "  6g  8      g  ",
      "  6g        9g  ",
      "  6g         g  ",
      "  6g         g  ",
      "   gh555h555hg  ",
      "   gg234g234gg  ",
      "                ",
      "                "
    ],
    [
      "                ",
      "                ",
      "   ###########  ",
      "   g$$$$$$$$$g  ",
      "   g%   %   %g  ",
      "   g555555555g  ",
      "   g         g  ",
      "   g         g  ",
      "   g  ^   ^  g  ",
      "   g         g  ",
      "   g555555555g  ",
      "   g&   &   &g  ",
      "   g$$$$$$$$$g  ",
      "   ###########  ",
      "                ",
      "                "
    ]
  ]
}