{
  "name": "building_processingunita_ground_180",
  "refpalette": "deceasedcraft:building_processingunita/building_processingunita_ground_palette_180",
  "xsize": 16,
  "zsize": 16,
  "slices": [
    [
      "zzzzzzzzzzzzzaaa",
      "zzzzzzzzzzzzzzaa",
      "zzbbbbbbbbbbbzaa",
      "zzbbbbbbbbbbbaaa",
      "zzbbbbbbbbbbbaaz",
      "zzbbcbbbbbbbbaaz",
      "zzbbbbbbbbbbbaaa",
      "zzbbcbbbbbbbbaaa",
      "zzbbbbbbbbbbbaza",
      "zzbbbbbbbbbbbaaa",
      "zzbbbbbbbbbbbaaa",
      "zzbbbbbbbbbbbaaz",
      "zzbbbbbbbbbbbaaa",
      "zzbbbbbbbbbbbzaa",
      "zzzzzzzzzzzzzaaa",
      "zzzzzzzzzzzzzzaa"
    ],
    [
      " e  ddJd ddK    ",
      "    Jd ddd dd   ",
      " dggggggggggg   ",
      "  ghIIFhEDChg   ",
      " dgsBAysssss    ",
      "d gsxu          ",
      "  gswu          ",
      "  gswu          ",
      "  gst           ",
      " dgsr           ",
      "  gppqpo        ",
      "  g   jn mmm    ",
      "d ghlkjh i!hg   ",
      "  ggggggggggg   ",
      " d f     d      ",
      "d d d   e  d    "
    ],
    [
      "                ",
      "                ",
      "  ggggggggggg   ",
      "  ghIIIh   hg   ",
      "  gsS RQ    L   ",
      "  gs        L   ",
      "  gs        L   ",
      "  gs        L   ",
      "  gsP       L   ",
      "  gsO       L   ",
      "  gppNpM    L   ",
      "  g   j   m L   ",
      "  gh  jh mmhg   ",
      "  ggggggggggg   ",
      "   f            ",
      "                "
    ],
    [
      "                ",
      "                ",
      "  ggggggggggg   ",
      "  ghIIIh1 0hg   ",
      "  gZZYY     L   ",
      "  gsX       L   ",
      "  gsW       L   ",
      "  gsV       L   ",
      "  gs        L   ",
      "  gs        L   ",
      "  gpppp     L   ",
      "  g   j   U L   ",
      "  gh  jh   hg   ",
      "  ggggggggggg   ",
      "   T            ",
      "                "
    ],
    [
      "                ",
      "                ",
      "  gg432g432gg   ",
      "  gh555h555hg   ",
      "  g         g6  ",
      "  g         g6  ",
      "  g9        g6  ",
      "  g      8  g6  ",
      "  g        7g6  ",
      "  g        7g6  ",
      "  gpppp    7g6  ",
      "  g   j    7g6  ",
      "  gh555h555hg   ",
      "  gg432g432gg   ",
      "                ",
      "                "
    ],
    [
      "                ",
      "                ",
      "  ###########   ",
      "  g$$$$$$$$$g   ",
      "  g&   &   &g   ",
      "  g555555555g   ",
      "  g         g   ",
      "  g  ^   ^  g   ",
      "  g         g   ",
      "  g         g   ",
      "  g555555555g   ",
      "  g%   %   %g   ",
      "  g$$$$$$$$$g   ",
      "  ###########   ",
      "                ",
      "                "
    ]
  ]
}