{
  "name": "building_processingunita_ground_270",
  "refpalette": "deceasedcraft:building_processingunita/building_processingunita_ground_palette_270",
  "xsize": 16,
  "zsize": 16,
  "slices": [
    [
      "aaaazzaaaaazaaaa",
      "aaaaaaaazaaaaaaa",
      "azzaaaaaaaaaazaz",
      "zzbbbbbbbbbbbbzz",
      "zzbbbbbbbbbbbbzz",
      "zzbbbbbbbbbbbbzz",
      "zzbbbbbbbbbbbbzz",
      "zzbbbbbbbbbbbbzz",
      "zzbbbbbbbbbbbbzz",
      "zzbbbbbbbbbbbbzz",
      "zzbbbbbbbbbbbbzz",
      "zzbbbcbcbbbbbbzz",
      "zzbbbbbbbbbbbbzz",
      "zzbbbbbbbbbbbbzz",
      "zzzzzzzzzzzzzzzz",
      "zzzzzzzzzzzzzzzz"
    ],
    [
      "                ",
      "                ",
      "                ",
      " dgg        gg  ",
      "Kdghs      mhg d",
      "d gCs      m!g  ",
      "ddgDs      migd ",
      " dgEs        g e",
      "ddghs     onhg  ",
      "J gFy     pjjg  ",
      "ddgIAuuu  q kg  ",
      "dJgIBxwwtrp lg d",
      "  ghssssssp hgf ",
      "  gggggggggggg d",
      "e d d    d    d ",
      "     d      d  d"
    ],
    [
      "                ",
      "                ",
      "                ",
      "  ggLLLLLLLLgg  ",
      "  gh        hg  ",
      "  g        mmg  ",
      "  g         mg  ",
      "  g          g  ",
      "  ghQ     M hg  ",
      "  gIR     pjjg  ",
      "  gI      N  g  ",
      "  gIS   POp  g  ",
      "  ghssssssp hgf ",
      "  gggggggggggg  ",
      "                ",
      "                "
    ],
    [
      "                ",
      "                ",
      "                ",
      "  ggLLLLLLLLgg  ",
      "  gh        hg  ",
      "  g0       U g  ",
      "  g          g  ",
      "  g1         g  ",
      "  gh        hg  ",
      "  gIY     pjjg  ",
      "  gIY     p  g  ",
      "  gIZXWV  p  g  ",
      "  ghZsssssp hgT ",
      "  gggggggggggg  ",
      "                ",
      "                "
    ],
    [
      "                ",
      "                ",
      "    66666666    ",
      "  gggggggggggg  ",
      "  gh    7777hg  ",
      "  25        52  ",
      "  35   8    53  ",
      "  45        54  ",
      "  gh        hg  ",
      "  25      pj52  ",
      "  35      p 53  ",
      "  45      p 54  ",
      "  gh  9   p hg  ",
      "  gggggggggggg  ",
      "                ",
      "                "
    ],
    [
      "                ",
      "                ",
      "                ",
      "  #gggggggggg#  ",
      "  #$&5    5%$#  ",
      "  #$ 5    5 $#  ",
      "  #$ 5 ^  5 $#  ",
      "  #$ 5    5 $#  ",
      "  #$&5    5%$#  ",
      "  #$ 5    5 $#  ",
      "  #$ 5 ^  5 $#  ",
      "  #$ 5    5 $#  ",
      "  #$&5    5%$#  ",
      "  #gggggggggg#  ",
      "                ",
      "                "
    ]
  ]
}