{
  "name": "building_processingunita_ground_90",
  "refpalette": "deceasedcraft:building_processingunita/building_processingunita_ground_palette_90",
  "xsize": 16,
  "zsize": 16,
  "slices": [
    [
      "zzzzzzzzzzzzzzzz",
      "zzzzzzzzzzzzzzzz",
      "zzbbbbbbbbbbbbzz",
      "zzbbbbbbbbbbbbzz",
      "zzbbbbbbcbcbbbzz",
      "zzbbbbbbbbbbbbzz",
      "zzbbbbbbbbbbbbzz",
      "zzbbbbbbbbbbbbzz",
      "zzbbbbbbbbbbbbzz",
      "zzbbbbbbbbbbbbzz",
      "zzbbbbbbbbbbbbzz",
      "zzbbbbbbbbbbbbzz",
      "zzbbbbbbbbbbbbzz",
      "zazaaaaaaaaaazza",
      "aaaaaaazaaaaaaaa",
      "aaaazaaaaazzaaaa"
    ],
    [
      "d  d      d     ",
      " d    d    d d e",
      "d gggggggggggg  ",
      " fgh psssssshg  ",
      "d gl prtwwxBIgJd",
      "  gk q  uuuAIgdd",
      "  gjjp     yFg J",
      "  ghno     shgdd",
      "e g        sEgd ",
      " dgim      sDgdd",
      "  g!m      sCg d",
      "d ghm      shgdK",
      "  gg        ggd ",
      "                ",
      "                ",
      "                "
    ],
    [
      "                ",
      "                ",
      "  gggggggggggg  ",
      " fgh psssssshg  ",
      "  g  pOP   SIg  ",
      "  g  N      Ig  ",
      "  gjjp     RIg  ",
      "  gh M     Qhg  ",
      "  g          g  ",
      "  gm         g  ",
      "  gmm        g  ",
      "  gh        hg  ",
      "  ggLLLLLLLLgg  ",
      "                ",
      "                ",
      "                "
    ],
    [
      "                ",
      "                ",
      "  gggggggggggg  ",
      " Tgh psssssZhg  ",
      "  g  p  VWXZIg  ",
      "  g  p     YIg  ",
      "  gjjp     YIg  ",
      "  gh        hg  ",
      "  g         1g  ",
      "  g          g  ",
      "  g U       0g  ",
      "  gh        hg  ",
      "  ggLLLLLLLLgg  ",
      "                ",
      "                ",
      "                "
    ],
    [
      "                ",
      "                ",
      "  gggggggggggg  ",
      "  gh p   9  hg  ",
      "  45 p      54  ",
      "  35 p      53  ",
      "  25jp      52  ",
      "  gh        hg  ",
      "  45        54  ",
      "  35    8   53  ",
      "  25        52  ",
      "  gh7777    hg  ",
      "  gggggggggggg  ",
      "    66666666    ",
      "                ",
      "                "
    ],
    [
      "                ",
      "                ",
      "  #gggggggggg#  ",
      "  #$%5    5&$#  ",
      "  #$ 5    5 $#  ",
      "  #$ 5  ^ 5 $#  ",
      "  #$ 5    5 $#  ",
      "  #$%5    5&$#  ",
      "  #$ 5    5 $#  ",
      "  #$ 5  ^ 5 $#  ",
      "  #$ 5    5 $#  ",
      "  #$%5    5&$#  ",
      "  #gggggggggg#  ",
      "                ",
      "                ",
      "                "
    ]
  ]
}