{
  "name": "multi_polyclinic_0_ground",
  "refpalette": "deceasedcraft:multi_polyclinic_0/multi_polyclinic_0_ground_palette",
  "xsize": 16,
  "zsize": 16,
  "slices": [
    [
      "aaaaaaaaaaaaaaaa",
      "aaaaaaaaaaaaaaaa",
      "aaaaaaaaabbbbbbb",
      "aaaaccdccccccccc",
      "eaaaaaaaffgfffgf",
      "aaaeaeeeffhhhhhh",
      "aeaaeaeeffhhhhhh",
      "aaffffffffhhhhhh",
      "aaffffffffffffff",
      "aafffffffhhhhfhh",
      "aafffffffhhhhfhh",
      "aafffffffhhhhfhh",
      "aafffffffhhhhfhh",
      "aaffffffffffffff",
      "aaffffffffffffff",
      "aaaaaaaaaaaaaaaa"
    ],
    [
      "                ",
      "         iiiiiii",
      "         jjjjjjj",
      "    kklkkkkkkkkk",
      "    mnmm oijjjij",
      "         p qrs q",
      "         t      ",
      "         p      ",
      "   uuuuuuuuwuuxy",
      "   u A  B   jC  ",
      "   u DEFC I  C  ",
      "   u DFJCKLM N  ",
      "   uOPQRC SM CTU",
      "   uuuuuuuuuuuuu",
      "        V  V  V ",
      "                "
    ],
    [
      "                ",
      "                ",
      "          WXXXXX",
      "    klllkkkkkkkk",
      "         oYZZZYZ",
      "         p      ",
      "         0      ",
      "         p      ",
      "   CCCCCCCC1CC2 ",
      "   C    3   4C  ",
      "   C F  C   5C6 ",
      "   C 7  C 8  9  ",
      "   C   #C $  C%%",
      "   CCCCCCCCCCCCC",
      "        V  V  V ",
      "                "
    ],
    [
      "                ",
      "                ",
      "          ^XX&XX",
      "    kklkkkkkkkkk",
      "         o      ",
      "         p      ",
      "         p      ",
      "         p *    ",
      "   CCCCCCCC(CC((",
      "   C    )    C  ",
      "   C    C    C  ",
      "   C    C    +  ",
      "   C    C    C%-",
      "   CCCCCC[[[[]]]",
      "        V  V  V ",
      "                "
    ],
    [
      "                ",
      "                ",
      "         {     {",
      "    kkkkkkkkkkkk",
      "         o      ",
      "         o      ",
      "         o      ",
      "         o      ",
      "   CCCCCCCCCCCCC",
      "   C}}}}C    C  ",
      "   C}||}C    C  ",
      "   C}||}C    C  ",
      "   C}}}}C    C;;",
      "   CCCCCCCCCCCCC",
      "        V  V  V ",
      "                "
    ],
    [
      "                ",
      "       :::::::::",
      "       :''''''''",
      "       :'    '  ",
      "       :'<<<<'<<",
      "       :'<<<<'<<",
      "       :'<<<<'<<",
      "       :'<<<<'<<",
      "   CCCCCCCCCCCCC",
      "   C>>>>C>>>>C>>",
      "   C,>>>C>>>>C>>",
      "   C,>>>C>>>>C>>",
      "   C>>>>C>>>>C>>",
      "   CCCCCCCCCCCCC",
      "       :::::::::",
      "                "
    ]
  ]
}