{
  "name": "multi_terraceplaza_30_floor1",
  "refpalette": "deceasedcraft:multi_terraceplaza_30/multi_terraceplaza_30_floor1_palette",
  "xsize": 16,
  "zsize": 16,
  "slices": [
    [
      " a  bc  de      ",
      " a  bc  fe      ",
      " a  bc  fe      ",
      " a gbc  fe      ",
      "aa hbc  de      ",
      " a  bc  fe      ",
      " a  bc  de      ",
      " a  bc  fe      ",
      "aaaaic  fe      ",
      "j   kc  de      ",
      "j   kc  de      ",
      "j   kc  fe      ",
      "j   kc  de      ",
      "j   kc  fe      ",
      "j   kc  fe      ",
      "jaaakc  de      "
    ],
    [
      "la  mno de      ",
      "la  mno fe      ",
      "la gmno fe      ",
      "la hmno fe      ",
      "aa  mno de      ",
      " a  mno fe      ",
      " a  mno de      ",
      " a  mno fe      ",
      "mmmmipqqfe      ",
      "llllmno de      ",
      "llrlmno de      ",
      "llllmno fe      ",
      "llllmno de      ",
      "llrlmno fe      ",
      "llllmno fe      ",
      "llllmno de      "
    ],
    [
      "sattuw  de      ",
      "stttuw  fe      ",
      "saxhuw  fe      ",
      "sa  uw  fe      ",
      "ya  uw  de      ",
      " a  uw  fe      ",
      " a  uw  de      ",
      " a  uw  fe      ",
      "aaaaiA  fe      ",
      "BCCCuw  de      ",
      "BCCCuw  de      ",
      "BCCCuw  fe      ",
      "BCCCuw  de      ",
      "BCCCuw  fe      ",
      "BCCCuw  fe      ",
      "BCCCuw  de      "
    ],
    [
      "Da  aw  de      ",
      " E  aw  fe      ",
      " FI aw  fe      ",
      "Dax aw  fe      ",
      "Ja  aw  de      ",
      " a  aw  fe      ",
      " a  aw  de      ",
      " a  aw  fe      ",
      "aaaai   fe      ",
      "KoLLMw  de      ",
      "No  Mw  de      ",
      " o  Mw  fe      ",
      "Oo  Mw  de      ",
      "Po  Mw  fe      ",
      "Qo  Mw  fe      ",
      "!aRaMw  de      "
    ],
    [
      " a  S   de      ",
      " T  Sw  fe      ",
      " F  S   fe      ",
      " aI S   fe      ",
      "Uax aw  de      ",
      " a  Sw  fe      ",
      " a  S   de      ",
      " a  a   fe      ",
      "aaaai   fe      ",
      "V WXMw  de      ",
      "V   Mw  de      ",
      "V   M   fe      ",
      "V   Mw  de      ",
      "V   M   fe      ",
      "V   Mw  fe      ",
      "@aYaMw  de      "
    ],
    [
      " a  a   de      ",
      " F  a   fe      ",
      " F  a   fe      ",
      " a  a   fe      ",
      "FaI a   de      ",
      " ax a   fe      ",
      " a  a   de      ",
      " a  a   fe      ",
      "aaaai   fe      ",
      "    M   de      ",
      "    M   de      ",
      "    M   fe      ",
      "    M   de      ",
      "    M   fe      ",
      "    M   fe      ",
      "Za0aM   de      "
    ]
  ]
}