{
  "name": "multi_terraceplaza_30_floor3",
  "refpalette": "deceasedcraft:multi_terraceplaza_30/multi_terraceplaza_30_floor3_palette",
  "xsize": 16,
  "zsize": 16,
  "slices": [
    [
      " a  bc  de      ",
      " f  b   ge      ",
      " h  b   ge      ",
      " a  bc  ge      ",
      "ia  ac  de      ",
      " a  b   ge      ",
      " a  b   de      ",
      " a  ac  ge      ",
      "aaaaj   ge      ",
      "     c  de      ",
      "     c  de      ",
      " k      ge      ",
      "l       de      ",
      "m    c  ge      ",
      "n       ge      ",
      "o    c  de      "
    ],
    [
      " a  a   de      ",
      " h  a   ge      ",
      " h  a   ge      ",
      " a  a   ge      ",
      "ha  a   de      ",
      " a  a   ge      ",
      " a  a   de      ",
      " a  a   ge      ",
      "aaaaj   ge      ",
      "        de      ",
      "        de      ",
      "        ge      ",
      "p       de      ",
      "        ge      ",
      "        ge      ",
      "        de      "
    ],
    [
      " a  a   de      ",
      " a  a   ge      ",
      " a  a   ge      ",
      " a  a   ge      ",
      "aa  a   de      ",
      " a  a   ge      ",
      " a  a   de      ",
      " a  a   ge      ",
      "aaaaj   ge      ",
      "        de      ",
      "        de      ",
      "        ge      ",
      "        de      ",
      "        ge      ",
      "        ge      ",
      "        de      "
    ],
    [
      " a  a   de      ",
      " a  a   ge      ",
      " a  a   ge      ",
      " a  a   ge      ",
      "aa  a   de      ",
      " a  a   ge      ",
      " a  a   de      ",
      " a  a   ge      ",
      "aaaaj   ge      ",
      "        de      ",
      "        de      ",
      "        ge      ",
      "        de      ",
      "        ge      ",
      "qqqqqrssge      ",
      "ttttuwssde      "
    ],
    [
      " a  a   de      ",
      " a  a   ge      ",
      " a  a   ge      ",
      " a  a   ge      ",
      "aa  a   de      ",
      " a  a   ge      ",
      " a  a   de      ",
      " a  a   ge      ",
      "aaaaj   ge      ",
      "        de      ",
      "        de      ",
      "qqqqqrssge      ",
      "ttttuwssde      ",
      "xxxxxyssge      ",
      "AAAAAy  ge      ",
      "    By  de      "
    ],
    [
      "CaDDa   de      ",
      "CaDDa   ge      ",
      "CaDDa   ge      ",
      "CaDDa   ge      ",
      "aaDDa   de      ",
      " aDDa   ge      ",
      " aDDa   de      ",
      " aDDa   ge      ",
      "EEEEjrssge      ",
      "uuuuuwssde      ",
      "xxxxxyssde      ",
      "AAAAAy  ge      ",
      "    By  de      ",
      "     F  ge      ",
      "     I  ge      ",
      "                "
    ]
  ]
}