{
  "name": "multi_terraceplaza_30_floor2",
  "refpalette": "deceasedcraft:multi_terraceplaza_30/multi_terraceplaza_30_floor2_palette",
  "xsize": 16,
  "zsize": 16,
  "slices": [
    [
      " a  a   bc      ",
      " a  a   dc      ",
      " a  a   dc      ",
      " a  a   dc      ",
      "aa  a   bc      ",
      " aefa   dc      ",
      " agga   bc      ",
      " agga   dc      ",
      "aaaah   dc      ",
      "    i   bc      ",
      "    i   bc      ",
      "    i   dc      ",
      "    i   bc      ",
      "    i   dc      ",
      "    i   dc      ",
      " aaai   bc      "
    ],
    [
      " a  j   bc      ",
      " a  j   dc      ",
      " a  j   dc      ",
      " a  j   dc      ",
      "aa fj   bc      ",
      " a kj   dc      ",
      " a  j   bc      ",
      " a  j   dc      ",
      "aaaah   dc      ",
      "l   m   bc      ",
      "    m   bc      ",
      "    m   dc      ",
      "    m   bc      ",
      "    m   dc      ",
      "    m   dc      ",
      " aaam   bc      "
    ],
    [
      " a  jn  bc      ",
      " a  jn  dc      ",
      " a  jn  dc      ",
      " a fjn  dc      ",
      "aa kjn  bc      ",
      " a  jn  dc      ",
      " a  jn  bc      ",
      " a  jn  dc      ",
      "aaaahn  dc      ",
      "    on  bc      ",
      "    on  bc      ",
      " p  on  dc      ",
      "q   on  bc      ",
      "    on  dc      ",
      "    on  dc      ",
      "qaaaon  bc      "
    ],
    [
      "ra  stu bc      ",
      "ra  stu dc      ",
      "ra fstu dc      ",
      "ra kstu dc      ",
      "aa  stu bc      ",
      " a  stu dc      ",
      " a  stu bc      ",
      " a  stu dc      ",
      "sssshwxxdc      ",
      "rrrrstu bc      ",
      "rrrrstu bc      ",
      "yrrrstu dc      ",
      "qyrrstu bc      ",
      "Ayrrstu dc      ",
      "Ayrrstu dc      ",
      "qyrrstu bc      "
    ],
    [
      "BaggCD  bc      ",
      "BgggCD  dc      ",
      "BaEkCD  dc      ",
      "Ba  CD  dc      ",
      "Fa  CD  bc      ",
      " a  CD  dc      ",
      " a  CD  bc      ",
      " a  CD  dc      ",
      "aaaahI  dc      ",
      "JJJJCD  bc      ",
      "JJJJCD  bc      ",
      "JJJJCD  dc      ",
      "JJJJCD  bc      ",
      "JJJJCD  dc      ",
      "JJJJCD  dc      ",
      "JJJJCD  bc      "
    ],
    [
      "Ka  aD  bc      ",
      " L  aD  dc      ",
      " M  aD  dc      ",
      "Ka  aD  dc      ",
      "Na  aD  bc      ",
      " a  aD  dc      ",
      " a  aD  bc      ",
      " a  aD  dc      ",
      "aaaah   dc      ",
      "     D  bc      ",
      "     D  bc      ",
      "OO   D  dc      ",
      "=O   D  bc      ",
      "PO   D  dc      ",
      "=O   D  dc      ",
      "=O   D  bc      "
    ]
  ]
}