{
  "name": "multi_terraceplaza_30_base1",
  "refpalette": "deceasedcraft:multi_terraceplaza_30/multi_terraceplaza_30_base1_palette",
  "xsize": 16,
  "zsize": 16,
  "slices": [
    [
      "abccb     dbeeev",
      "acccbd     beeev",
      "abccb     dbeeev",
      "abfgbd    dbeeev",
      "hb  bd     beeev",
      " b  b!     beeev",
      " b  bd    dbeeev",
      " b  bi    ibeeev",
      "bbbbjbbbbbbbeeev",
      "    b      beeev",
      "    b      beeev",
      "    b      beeev",
      "    b      beeev",
      "    b      beeev",
      "    b      beeev",
      "    b      beeev"
    ],
    [
      "kb  b      beeev",
      " l  b      beeev",
      " m  b      beeev",
      "kbn b      beeev",
      "obf b      beeev",
      " b  b      beeev",
      " b  b      beeev",
      " b  bi    ibeeev",
      "bbbbjbbbbbbbeeev",
      "    b      beeev",
      "    b      beeev",
      "    b      beeev",
      "    b      beeev",
      "    b      beeev",
      "    b      beeev",
      "    b      beeev"
    ],
    [
      " b  b      beeev",
      " p  b      beeev",
      " m  b      beeev",
      " b  b      beeev",
      "qbn b      beeev",
      " bf b      beeev",
      " b  b      beeev",
      " b  bi    ibeeev",
      "bbbbjbbbbbbbeeev",
      "    b      beeev",
      "    b      beeev",
      "    b      beeev",
      "    b      beeev",
      "    b      beeev",
      "    b      beeev",
      "    b      beeev"
    ],
    [
      " b  brrrrrrbeeev",
      " m  brrrrrrbeeev",
      " m  brrrrrrbeeev",
      " b  brrrrrrbeeev",
      "mb  brrrrrrbeeev",
      " bnsbrrrrrtbeeev",
      " bccbrrrrrrbeeev",
      " bccbrrrrrrbeeev",
      "bbbbjbbbbbbbeeev",
      "mmmmbrrrrrrbeeev",
      " uumbrrrrrtbeeev",
      " uumbrrrrrrbeeev",
      " uumbrrrrrrbeeev",
      " uumbrrrrrrbeeev",
      " uumbrrrrrrbeeev",
      " uumbrrrrrrbeeev"
    ],
    [
      " b  beeeeewbeeev",
      " b  beeeeewbeeev",
      " b  beeeeewbeeev",
      " b  beeeeewbeeev",
      "bb sbeeeeewbeeev",
      " b gbeeeeewbeeev",
      " b  beeeeewbeeev",
      " b  beeeeewbeeev",
      "bbbbjbbbbbwbeeev",
      "mmmmbeeeeewbeeev",
      "xxymbeeeeewbeeev",
      "xxymbeeeeewbeeev",
      "xxymbeeeeewbeeev",
      "xxymbeeeeewbeeev",
      "xxymbeeeeewbeeev",
      "xxymbeeeeewbeeev"
    ],
    [
      "Ab  BCeeeeebeeev",
      "Ab  BCeeeeebeeev",
      "Ab  BCeeeeebeeev",
      "Ab sBCeeeeebeeev",
      "bb gBCeeeeebeeev",
      " b  BCeeeeebeeev",
      " b  BCeeeeebeeev",
      " b  BCeeeeebeeev",
      "BBBBjDeebbbbeeev",
      "mmmmBCeeeeebeeev",
      "EEFmBCeeeeebeeev",
      "EEFmBCeeeeebeeev",
      "EEFmBCeeeeebeeev",
      "EEFmBCeeeeebeeev",
      "EEFmBCeeeeebeeev",
      "EEFmBCeeeeebeeev"
    ]
  ]
}