{
  "name": "multi_terraceplaza_30_base2",
  "refpalette": "deceasedcraft:multi_terraceplaza_30/multi_terraceplaza_30_base2_palette",
  "xsize": 16,
  "zsize": 16,
  "slices": [
    [
      "abccbccccccbdddv",
      "acccbccccccbdddv",
      "abccbccccccbdddv",
      "abccbccccccbdddv",
      "ebccbccccccbdddv",
      "fbccbccccccbdddv",
      "fbccbccccccbdddv",
      "fbccbccccccbdddv",
      "bbbbgbbccbbbdddv",
      "hhhhbccccccbdddv",
      "hhhhbccccccbdddv",
      "hhhhcccccccbdddv",
      "hhhhcccccccbdddv",
      "hhhhbccccccbdddv",
      "hhhhbccccccbdddv",
      "hhhhbccccccbdddv"
    ],
    [
      "ib  bj    jbdddv",
      " k  bj    jbdddv",
      " lm bj    jbdddv",
      "ibn bj    jbdddv",
      "obp bj    jbdddv",
      "qb mbj    jbdddv",
      " bm bj    jbdddv",
      "rb!mbs    sbdddv",
      "bbbbgbbtubbbdddv",
      "   wb     wbdddv",
      "   wb     wbdddv",
      "    x    ywbdddv",
      "    A     wbdddv",
      "   wb     wbdddv",
      "BC wb    Dwbdddv",
      "E  wb F   wbdddv"
    ],
    [
      " b  bI    !bdddv",
      " J  b     Ibdddv",
      " l  bI    Kbdddv",
      " b  bL     bdddv",
      "Mbn b     Ibdddv",
      " bp bI     bdddv",
      " b  bI    Ibdddv",
      "rbm bs    sbdddv",
      "bbbbgbbNObbbdddv",
      "    b      bdddv",
      "    bP    Qbdddv",
      "    R     Sbdddv",
      "    T     Ubdddv",
      "    b     Vbdddv",
      "    b     Sbdddv",
      "W   bX    Ybdddv"
    ],
    [
      " b  bj    jbdddv",
      " l  bj    jbdddv",
      " l  bj    jbdddv",
      " b  bj    jbdddv",
      "lb mbj    jbdddv",
      " bnZbj    jbdddv",
      " bccbj    jbdddv",
      "rbccbs    sbdddv",
      "bbbbgbb00bbbdddv",
      "    b      bdddv",
      "    b     Ubdddv",
      "    l     Vbdddv",
      "    l     Sbdddv",
      "    b     1bdddv",
      "    b     Ybdddv",
      "    b     Ubdddv"
    ],
    [
      " b  bI     bdddv",
      " b  b2    3bdddv",
      " b  b     Ibdddv",
      " b  bI    Ibdddv",
      "bb Zb      bdddv",
      "4b 5bI    Ibdddv",
      " b  bI    Ibdddv",
      "rb  bs    sbdddv",
      "bbbbgbbbbbbbdddv",
      "    b      bdddv",
      "    b     Sbdddv",
      "    b     1bdddv",
      "    b     Ybdddv",
      "    b     Qbdddv",
      "    b     Qbdddv",
      "    b     Sbdddv"
    ],
    [
      "6b  7j    jbdddv",
      "6b  7j    jbdddv",
      "6b  7j    jbdddv",
      "6b Z7j    jbdddv",
      "bb 57j    jbdddv",
      "cb  7j    jbdddv",
      "cb  7j    jbdddv",
      "cb  7s    sbdddv",
      "bbbbgbbbbbbbdddv",
      "    b      bdddv",
      "    b      bdddv",
      "    b      bdddv",
      "    b      bdddv",
      "    b      bdddv",
      "    b      bdddv",
      "    b      bdddv"
    ]
  ]
}