{
  "name": "multi_terraceplaza_30_ground",
  "refpalette": "deceasedcraft:multi_terraceplaza_30/multi_terraceplaza_30_ground_palette",
  "xsize": 16,
  "zsize": 16,
  "slices": [
    [
      "abccdeffghijkHHH",
      "acccdeffghijkHHH",
      "ablcdeffghijkHHH",
      "ab mdeffghijkHHH",
      "nb  deffghijkHHH",
      " b  deffghijkHHH",
      " b  deffghiokHHH",
      " b  deffghijkHHH",
      "bbbbpqrfghijkHHH",
      "ssssdeffghijkHHH",
      "ssssdeffghiokHHH",
      "ssssdeffghijkHHH",
      "ssssdeffghijkHHH",
      "ssssdeffghijkHHH",
      "ssssdeffghijkHHH",
      "ssssdeffghijkHHH"
    ],
    [
      "tb  be  u wx    ",
      " y  be  u wx    ",
      " AB be  u wx    ",
      "tbl be  u wx    ",
      "Cb  be  u wx    ",
      " b  be  u wx    ",
      " b  be  u wD    ",
      " b  be  u wE    ",
      "bbbbp   F IE    ",
      "J  K e  u wE    ",
      "JL K e  u wD    ",
      "J  K e  u wx    ",
      "M  N e  u wx    ",
      "   J e  u wx    ",
      "O  P e  u wx    ",
      " bQb e  u wx    "
    ],
    [
      " b  ue  RSw     ",
      " T  u   USw     ",
      " A  u   USw     ",
      " bB ue  USw     ",
      "Vbl be  RSw     ",
      " b  u   USw     ",
      " b  ue  RSwW    ",
      " b  b   US      ",
      "bbbbp   USX     ",
      "YZ 0 e  RS      ",
      "1    e  RSwW    ",
      "Y  2    USw     ",
      "M    e  RSw     ",
      "        USw     ",
      "        USw     ",
      " b3b e  RSw     "
    ],
    [
      " b  b   RS      ",
      " A  b   US      ",
      " A  b   US      ",
      " b  b   US      ",
      "AbB b   RS      ",
      " bl b   US      ",
      " b  b   RS      ",
      " b  b   US      ",
      "bbbbp   USx     ",
      "4       RS      ",
      "4       RS      ",
      "4       US      ",
      "4       RS      ",
      "4       US      ",
      "4       US      ",
      "4b5b    RS      "
    ],
    [
      " b  b   RS      ",
      " b  b   US      ",
      " b  b   US      ",
      " b  b   US      ",
      "bb  b   RS      ",
      " bB6b   US      ",
      " bccb   RS      ",
      " bccb   US      ",
      "bbbbp   USx     ",
      "4       RS      ",
      "4       RS      ",
      "4       US      ",
      "4       RS      ",
      "4       US      ",
      "4       US      ",
      "4bbb    RS      "
    ],
    [
      " b  7   RS      ",
      " b  7   US      ",
      " b  7   US      ",
      " b  7   US      ",
      "bb 67   RS      ",
      " b m7   US      ",
      " b  7   RS      ",
      " b  7   US      ",
      "bbbbp   US      ",
      "4   8   RS      ",
      "4   8   RS      ",
      "4   8   US      ",
      "4   8   RS      ",
      "4   8   US      ",
      "4   8   US      ",
      "4bbb8   RS      "
    ]
  ]
}