{
  "name": "multi_terraceplaza_30_floor4",
  "refpalette": "deceasedcraft:multi_terraceplaza_30/multi_terraceplaza_30_floor4_palette",
  "xsize": 16,
  "zsize": 16,
  "slices": [
    [
      "abbbc   de      ",
      "fbbbc   ge      ",
      "fbbbc   ge      ",
      "abbbc   ge      ",
      "bbbbc   de      ",
      " bbbchiige      ",
      " bbbcjiide      ",
      " bbbckiige      ",
      "kkkkkk  ge      ",
      "kkkkkk  de      ",
      "     l  de      ",
      "     m  ge      ",
      "                ",
      "                ",
      "                ",
      "                "
    ],
    [
      "    c   de      ",
      "    c   ge      ",
      "   nchiige      ",
      "   ncjiige      ",
      "    ckiide      ",
      "   nck  ge      ",
      "hhhhkk  de      ",
      "llllll  ge      ",
      "mmmmmm  ge      ",
      "                ",
      "                ",
      "                ",
      "                ",
      "                ",
      "                ",
      "                "
    ],
    [
      "    cjiide      ",
      "   nckiige      ",
      "   nck  ge      ",
      "hhhhkk  ge      ",
      "llllll  de      ",
      "mmmmmm  ge      ",
      "                ",
      "                ",
      "                ",
      "                ",
      "                ",
      "                ",
      "                ",
      "                ",
      "                ",
      "                "
    ],
    [
      "hhhhkk  de      ",
      "llllll  ge      ",
      "mmmmmm  ge      ",
      "                ",
      "                ",
      "                ",
      "                ",
      "                ",
      "                ",
      "                ",
      "                ",
      "                ",
      "                ",
      "                ",
      "                ",
      "                "
    ],
    [
      "                ",
      "                ",
      "                ",
      "                ",
      "                ",
      "                ",
      "                ",
      "                ",
      "                ",
      "                ",
      "                ",
      "                ",
      "                ",
      "                ",
      "                ",
      "                "
    ],
    [
      "                ",
      "                ",
      "                ",
      "                ",
      "                ",
      "                ",
      "                ",
      "                ",
      "                ",
      "                ",
      "                ",
      "                ",
      "                ",
      "                ",
      "                ",
      "                "
    ]
  ]
}