{
  "name": "multi_thering_22_floor6",
  "refpalette": "deceasedcraft:multi_thering_22/multi_thering_22_floor6_palette",
  "xsize": 16,
  "zsize": 16,
  "slices": [
    [
      "a               ",
      "                ",
      "                ",
      "                ",
      "                ",
      "                ",
      "                ",
      "                ",
      "                ",
      "                ",
      "                ",
      "                ",
      "                ",
      "                ",
      "                ",
      "a               "
    ],
    [
      "a               ",
      "                ",
      "                ",
      "                ",
      "                ",
      "                ",
      "                ",
      "                ",
      "                ",
      "                ",
      "                ",
      "                ",
      "                ",
      "                ",
      "                ",
      "a               "
    ],
    [
      "a               ",
      "                ",
      "                ",
      "                ",
      "                ",
      "                ",
      "                ",
      "                ",
      "                ",
      "                ",
      "                ",
      "                ",
      "                ",
      "                ",
      "                ",
      "a               "
    ],
    [
      "a               ",
      "                ",
      "                ",
      "                ",
      "                ",
      "                ",
      "                ",
      "                ",
      "                ",
      "                ",
      "                ",
      "                ",
      "                ",
      "                ",
      "                ",
      "a               "
    ],
    [
      "abbbbbbc        ",
      "bbbbbbbc        ",
      "bbbbbbbbc       ",
      "bbbbbbbbc       ",
      "bbbbbbbbc       ",
      "bbbbbbbbc       ",
      "bbbbbbbbc       ",
      "bbbbbbbbc       ",
      "bbbbbbbbc       ",
      "bbbbbbbbc       ",
      "bbbbbbbbc       ",
      "bbbbbbbbc       ",
      "bbbbbbbbc       ",
      "bbbbbbbbc       ",
      "bbbbbbbc        ",
      "bbbbbbbc        "
    ],
    [
      "addeefbbbc      ",
      "dddeefbbbc      ",
      "dedeefbbbbc     ",
      "deddefgbhcc     ",
      "dddeeffbbbc     ",
      "dddeeffbbbc     ",
      "dddeeffbbbc     ",
      "dddedffbbbc     ",
      "ddeeeffbbbc     ",
      "dddeeffbbbc     ",
      "dddeeffbbbc     ",
      "ddeeeffbbbc     ",
      "dddeef!bhcc     ",
      "ddeedfbbbbc     ",
      "ddeeefbbbc      ",
      "ddeedfbbbc      "
    ]
  ]
}