{
  "name": "multi_thering_22_ground",
  "refpalette": "deceasedcraft:multi_thering_22/multi_thering_22_ground_palette",
  "xsize": 16,
  "zsize": 16,
  "slices": [
    [
      "abbbbbbcdcbbaeee",
      "abbbbbbcdcbbaeee",
      "abbbbbbcdcbbaeee",
      "abbbbbbcdcbbaeee",
      "abbbebbcdcbbaeee",
      "abbbbbbcdcbbaeee",
      "abbbbbbcdcbbaeee",
      "abbbbbbcdcbbaeee",
      "abbbbbbcdcbbaeee",
      "abbbbbbcdcbbaeee",
      "abbbbbbcdcbbaeee",
      "abbbebbcdcbbaeee",
      "abbbbbbcdcbbaeee",
      "abbbbbbcdcbbaeee",
      "bbbbbbbcdcbbaeee",
      "abbbbbbcdcbbaeee"
    ],
    [
      "f      ghg   i  ",
      "       ghg   i  ",
      "       ghg   i  ",
      "       ghg   i  ",
      "    j  ghg  ki  ",
      "       ghg   i  ",
      "       ghg  li  ",
      "       ghg  mi  ",
      "       ghg  mi  ",
      "       ghg  ni  ",
      "       ghg   i  ",
      "    j  ghg  ki  ",
      "       ghg   i  ",
      "       ghg   i  ",
      "       ghg   i  ",
      "f      ghg   i  "
    ],
    [
      "f               ",
      "                ",
      "                ",
      "                ",
      "    o       p   ",
      "                ",
      "                ",
      "                ",
      "                ",
      "                ",
      "                ",
      "    o       p   ",
      "                ",
      "                ",
      "                ",
      "f               "
    ],
    [
      "f               ",
      "                ",
      "                ",
      "                ",
      "    i           ",
      "                ",
      "                ",
      "                ",
      "                ",
      "                ",
      "                ",
      "    i           ",
      "                ",
      "                ",
      "                ",
      "f               "
    ],
    [
      "f               ",
      "                ",
      "                ",
      "                ",
      "    i           ",
      "                ",
      "                ",
      "                ",
      "                ",
      "                ",
      "                ",
      "    i           ",
      "                ",
      "                ",
      "                ",
      "f               "
    ],
    [
      "f               ",
      "                ",
      "                ",
      "                ",
      "    i           ",
      "                ",
      "                ",
      "                ",
      "                ",
      "                ",
      "                ",
      "    i           ",
      "                ",
      "                ",
      "                ",
      "f               "
    ]
  ]
}