{
  "name": "multi_thering_22_floor7",
  "refpalette": "deceasedcraft:multi_thering_22/multi_thering_22_floor7_palette",
  "xsize": 16,
  "zsize": 16,
  "slices": [
    [
      "a     bcccbd    ",
      "      bcccbd    ",
      "      bbcccbd   ",
      "       bcccbd   ",
      "      ebcccbd   ",
      "      fbcccbd   ",
      "      gbcccbd   ",
      "       bcccbd   ",
      "       bcccbd   ",
      "      ebcccbd   ",
      "      fbcccbd   ",
      "h     gbcccbd   ",
      "       bcccbd   ",
      "      bbcccbd   ",
      "      bcccbd    ",
      "      bcccbd    "
    ],
    [
      "a      ijkl     ",
      "       iikl     ",
      "        ijkl    ",
      "        ijkl    ",
      "        i kl    ",
      "        ijkl    ",
      "        ijkl    ",
      "        ijkl    ",
      "        ijkl    ",
      "        i kl    ",
      "        imkl    ",
      "n       ijkl    ",
      "        ijkl    ",
      "        imkl    ",
      "       iikl     ",
      "       ijkl     "
    ],
    [
      "a        k      ",
      "         k      ",
      "          k     ",
      "          k     ",
      "          k     ",
      "          k     ",
      "          k     ",
      "          k     ",
      "          k     ",
      "          k     ",
      "          k     ",
      "k         k     ",
      "          k     ",
      "          k     ",
      "         k      ",
      "         k      "
    ],
    [
      "a               ",
      "                ",
      "                ",
      "                ",
      "                ",
      "                ",
      "                ",
      "                ",
      "                ",
      "                ",
      "                ",
      "k               ",
      "                ",
      "                ",
      "                ",
      "                "
    ],
    [
      "a               ",
      "                ",
      "                ",
      "                ",
      "                ",
      "                ",
      "                ",
      "                ",
      "                ",
      "                ",
      "                ",
      "k               ",
      "                ",
      "                ",
      "                ",
      "                "
    ],
    [
      "a               ",
      "                ",
      "                ",
      "                ",
      "                ",
      "                ",
      "                ",
      "                ",
      "                ",
      "                ",
      "                ",
      "o               ",
      "                ",
      "                ",
      "                ",
      "                "
    ]
  ]
}