{
  "name": "building_wastelandgasstation_ground_270",
  "refpalette": "deceasedcraft:building_wastelandgasstation/building_wastelandgasstation_ground_palette_270",
  "xsize": 16,
  "zsize": 16,
  "slices": [
    [
      "zzzzzzzzzzzzzzzz",
      "zzzzzzzzzzeeezzz",
      "zbbbbbbbbbbbbbbz",
      "zbbbbbbbbbbbbbbz",
      "zbbbbbbbbbbbbbbz",
      "zbbbbbbbbbbbbbbz",
      "zbddddbbbbddddbz",
      "zaccaacccccazaaz",
      "zzacccaccaaccazz",
      "zazacccacacccaaa",
      "zaaccccccccczaaz",
      "zbddddbbbbddddbz",
      "zzacacccccccccca",
      "zzzacccccccccaaz",
      "zacaacaaaccaaazz",
      "zdaaaaaaaaaaaaaz"
    ],
    [
      "ffggf g fggggggf",
      "ghhhhhhhhhhhhhhf",
      "ghDDxrCywwqpmkhg",
      " hgl          hg",
      "gg          l gf",
      "f     l   r   gf",
      "   E shAxhs n  f",
      " t   rl   t  li ",
      "f             f ",
      " uf  j  l u   j ",
      "     l          ",
      "   F shBxhs o  f",
      "f l  i  rktl  i ",
      "        l       ",
      " u   j    u   f ",
      " I              "
    ],
    [
      "  g        g  g ",
      "ghhhhhhhhhhhhhh ",
      " h            hg",
      " h            h ",
      "                ",
      "                ",
      "      J  J      ",
      "                ",
      "                ",
      "                ",
      "                ",
      "      J KJ      ",
      "                ",
      "                ",
      "                ",
      " I              "
    ],
    [
      "                ",
      " JJJJJJJJJJJJJJ ",
      " J            J ",
      " J            J ",
      "                ",
      "                ",
      "      L  L      ",
      "                ",
      "                ",
      "                ",
      "                ",
      "      L  L      ",
      "                ",
      "                ",
      "                ",
      " M              "
    ],
    [
      "                ",
      " L LL  LL  LL L ",
      "                ",
      " L   N    N   L ",
      "     N    N     ",
      "                ",
      "      h  h      ",
      "                ",
      "                ",
      "                ",
      "                ",
      "      L  L      ",
      "                ",
      "                ",
      "                ",
      "                "
    ],
    [
      "                ",
      " OOOOOOOOOOOOOO ",
      " OssssssssssssO ",
      " OssssssssssssO ",
      " PQQQQQQQQQQQQP ",
      " PQSSQQSSQQSSQP ",
      " PQSSQQSSQQSSQP ",
      "  RRRRRRRRRRRR  ",
      "  R  NR  RN  R  ",
      "  R  NR  RN  R  ",
      "                ",
      "      h  h      ",
      "                ",
      "                ",
      "                ",
      "                "
    ]
  ]
}