{
  "name": "building_wastelandgasstation_ground",
  "refpalette": "deceasedcraft:building_wastelandgasstation/building_wastelandgasstation_ground_palette",
  "xsize": 16,
  "zsize": 16,
  "slices": [
    [
      "zzzzzzzzzazzazzz",
      "zzbbbbbazaabcaza",
      "zzbbbbdaaaadcaaa",
      "zebbbbdzcczdccaa",
      "zebbbbdacccdccaa",
      "zebbbbdcaccdccca",
      "zzbbbbbcaacbccca",
      "zzbbbbbccccbccaa",
      "zzbbbbbccacbccaa",
      "zzbbbbbcaccbccaa",
      "zzbbbbdacccdccca",
      "zzbbbbdacccdacaa",
      "zzbbbbdccacdcaaa",
      "zzbbbbdcazadazca",
      "zzbbbbbazaabzzad",
      "zzzzzzzzzzzzzzzz"
    ],
    [
      "ffggfff    f    ",
      "ghhhgg ifj  i f ",
      "ghk    l        ",
      "ghm l n    o    ",
      "ghp         l   ",
      "ghq  rst u st u ",
      "ghw   h    hk   ",
      "fhw   x  l xrl  ",
      " hy   A    B    ",
      "ghC  lhl   h    ",
      " hr   sr jlsi j ",
      "fhx             ",
      "ghDl  E    F    ",
      "ghDg     f  l   ",
      "fhhhg  t u    uI",
      "fgg gf  f   f   "
    ],
    [
      "  g             ",
      "ghhh            ",
      " h              ",
      " h              ",
      "gh              ",
      " h              ",
      " h    J    J    ",
      " h         K    ",
      " h              ",
      " h    J    J    ",
      " h              ",
      " h              ",
      " h              ",
      "gh              ",
      " hhh           I",
      " g              "
    ],
    [
      "                ",
      " JJJ            ",
      " J              ",
      " J              ",
      " J              ",
      " J              ",
      " J    L    L    ",
      " J              ",
      " J              ",
      " J    L    L    ",
      " J              ",
      " J              ",
      " J              ",
      " J              ",
      " JJJ           M",
      "                "
    ],
    [
      "                ",
      " L L            ",
      "                ",
      " L              ",
      " L              ",
      "   NN           ",
      "      h    L    ",
      " L              ",
      " L              ",
      "      h    L    ",
      "   NN           ",
      " L              ",
      " L              ",
      "                ",
      " L L            ",
      "                "
    ],
    [
      "                ",
      " OOOPPP         ",
      " OssQQQRRR      ",
      " OssQSSR        ",
      " OssQSSR        ",
      " OssQQQRNN      ",
      " OssQQQRRR h    ",
      " OssQSSR        ",
      " OssQSSR        ",
      " OssQQQRRR h    ",
      " OssQQQRNN      ",
      " OssQSSR        ",
      " OssQSSR        ",
      " OssQQQRRR      ",
      " OOOPPP         ",
      "                "
    ]
  ]
}