{
  "name": "building_wastelandgasstation_ground_90",
  "refpalette": "deceasedcraft:building_wastelandgasstation/building_wastelandgasstation_ground_palette_90",
  "xsize": 16,
  "zsize": 16,
  "slices": [
    [
      "zaaaaaaaaaaaaadz",
      "zzaaaccaaacaacaz",
      "zaacccccccccazzz",
      "accccccccccacazz",
      "zbddddbbbbddddbz",
      "zaazcccccccccaaz",
      "aaacccacacccazaz",
      "zzaccaaccacccazz",
      "zaazacccccaaccaz",
      "zbddddbbbbddddbz",
      "zbbbbbbbbbbbbbbz",
      "zbbbbbbbbbbbbbbz",
      "zbbbbbbbbbbbbbbz",
      "zbbbbbbbbbbbbbbz",
      "zzzeeezzzzzzzzzz",
      "zzzzzzzzzzzzzzzz"
    ],
    [
      "              I ",
      " f   u    j   u ",
      "       l        ",
      " i  ltkr  i  l f",
      "f  o shxBhs F   ",
      "          l     ",
      " j   u l  j  fu ",
      " f             f",
      " il  t   lr   t ",
      "f  n shxAhs E   ",
      "fg   r   l     f",
      "fg l          gg",
      "gh          lgh ",
      "ghkmpqwwyCrxDDhg",
      "fhhhhhhhhhhhhhhg",
      "fggggggf g fggff"
    ],
    [
      "              I ",
      "                ",
      "                ",
      "                ",
      "      JK J      ",
      "                ",
      "                ",
      "                ",
      "                ",
      "      J  J      ",
      "                ",
      "                ",
      " h            h ",
      "gh            h ",
      " hhhhhhhhhhhhhhg",
      " g  g        g  "
    ],
    [
      "              M ",
      "                ",
      "                ",
      "                ",
      "      L  L      ",
      "                ",
      "                ",
      "                ",
      "                ",
      "      L  L      ",
      "                ",
      "                ",
      " J            J ",
      " J            J ",
      " JJJJJJJJJJJJJJ ",
      "                "
    ],
    [
      "                ",
      "                ",
      "                ",
      "                ",
      "      L  L      ",
      "                ",
      "                ",
      "                ",
      "                ",
      "      h  h      ",
      "                ",
      "     N    N     ",
      " L   N    N   L ",
      "                ",
      " L LL  LL  LL L ",
      "                "
    ],
    [
      "                ",
      "                ",
      "                ",
      "                ",
      "      h  h      ",
      "                ",
      "  R  NR  RN  R  ",
      "  R  NR  RN  R  ",
      "  RRRRRRRRRRRR  ",
      " PQSSQQSSQQSSQP ",
      " PQSSQQSSQQSSQP ",
      " PQQQQQQQQQQQQP ",
      " OssssssssssssO ",
      " OssssssssssssO ",
      " OOOOOOOOOOOOOO ",
      "                "
    ]
  ]
}