{
  "name": "building_wastelandgasstation_ground_180",
  "refpalette": "deceasedcraft:building_wastelandgasstation/building_wastelandgasstation_ground_palette_180",
  "xsize": 16,
  "zsize": 16,
  "slices": [
    [
      "zzzzzzzzzzzzzzzz",
      "dazzbaazabbbbbzz",
      "aczadazacdbbbbzz",
      "aaacdcaccdbbbbzz",
      "aacadcccadbbbbzz",
      "acccdcccadbbbbzz",
      "aaccbccacbbbbbzz",
      "aaccbcaccbbbbbzz",
      "aaccbccccbbbbbzz",
      "acccbcaacbbbbbzz",
      "acccdccacdbbbbez",
      "aaccdcccadbbbbez",
      "aaccdzcczdbbbbez",
      "aaacdaaaadbbbbzz",
      "azacbaazabbbbbzz",
      "zzzazzazzzzzzzzz"
    ],
    [
      "   f   f  fg ggf",
      "Iu    u t  ghhhf",
      "   l  f     gDhg",
      "    F    E  lDhg",
      "             xhf",
      " j islj rs   rh ",
      "    h   lhl  Chg",
      "    B    A   yh ",
      "  lrx l  x   whf",
      "   kh    h   whg",
      " u ts u tsr  qhg",
      "   l         phg",
      "    o    n l mhg",
      "        l    khg",
      " f i  jfi gghhhg",
      "    f    fffggff"
    ],
    [
      "              g ",
      "I           hhh ",
      "              hg",
      "              h ",
      "              h ",
      "              h ",
      "    J    J    h ",
      "              h ",
      "    K         h ",
      "    J    J    h ",
      "              h ",
      "              hg",
      "              h ",
      "              h ",
      "            hhhg",
      "             g  "
    ],
    [
      "                ",
      "M           JJJ ",
      "              J ",
      "              J ",
      "              J ",
      "              J ",
      "    L    L    J ",
      "              J ",
      "              J ",
      "    L    L    J ",
      "              J ",
      "              J ",
      "              J ",
      "              J ",
      "            JJJ ",
      "                "
    ],
    [
      "                ",
      "            L L ",
      "                ",
      "              L ",
      "              L ",
      "           NN   ",
      "    L    h      ",
      "              L ",
      "              L ",
      "    L    h      ",
      "           NN   ",
      "              L ",
      "              L ",
      "                ",
      "            L L ",
      "                "
    ],
    [
      "                ",
      "         PPPOOO ",
      "      RRRQQQssO ",
      "        RSSQssO ",
      "        RSSQssO ",
      "      NNRQQQssO ",
      "    h RRRQQQssO ",
      "        RSSQssO ",
      "        RSSQssO ",
      "    h RRRQQQssO ",
      "      NNRQQQssO ",
      "        RSSQssO ",
      "        RSSQssO ",
      "      RRRQQQssO ",
      "         PPPOOO ",
      "                "
    ]
  ]
}