{
  "name": "multi_alienresearch_5_base2",
  "refpalette": "deceasedcraft:multi_alienresearch_5/multi_alienresearch_5_base2_palette",
  "xsize": 16,
  "zsize": 16,
  "slices": [
    [
      "       aaaaaaa  ",
      "     aa   b   aa",
      "  b a     b     ",
      "   a    cddde   ",
      "  a b ce     ce ",
      " a   f         f",
      " a  g           ",
      "a   h           ",
      "a  g            ",
      "a  i            ",
      "abbi            ",
      "a  i            ",
      "a  h            ",
      "a   g           ",
      " a  h           ",
      " a   f         f"
    ],
    [
      "b         j     ",
      " a              ",
      "  a             ",
      "   j            ",
      "                ",
      "     k          ",
      "                ",
      "                ",
      "                ",
      "                ",
      "j               ",
      "                ",
      "                ",
      "                ",
      "                ",
      "                "
    ],
    [
      "a               ",
      " j              ",
      "                ",
      "                ",
      "                ",
      "                ",
      "                ",
      "                ",
      "                ",
      "                ",
      "                ",
      "                ",
      "                ",
      "                ",
      "                ",
      "                "
    ],
    [
      "ll              ",
      "la              ",
      "  a             ",
      "                ",
      "                ",
      "                ",
      "                ",
      "                ",
      "                ",
      "                ",
      "                ",
      "                ",
      "                ",
      "                ",
      "                ",
      "                "
    ],
    [
      "mmnnnn    a    n",
      "mlln      a     ",
      "nll             ",
      "nn a            ",
      "n               ",
      "n               ",
      "                ",
      "                ",
      "                ",
      "                ",
      "aa              ",
      "                ",
      "                ",
      "                ",
      "                ",
      "n               "
    ],
    [
      "mmmmmmnnnlllnnnm",
      "mmmmnnnnnlllnnnn",
      "mmmlnnn   a   nn",
      "mmllln    a    n",
      "mnnla   aaaaa   ",
      "mnnn a a     a a",
      "nnn   a       a ",
      "nn   a         a",
      "nn  a           ",
      "ll  a           ",
      "llaaa           ",
      "ll  a           ",
      "nn  a           ",
      "nn   a         a",
      "nnn   a       a ",
      "mnnn a a     a a"
    ]
  ]
}