{
  "name": "multi_alienresearch_5_base5",
  "refpalette": "deceasedcraft:multi_alienresearch_5/multi_alienresearch_5_base5_palette",
  "xsize": 16,
  "zsize": 16,
  "slices": [
    [
      "a   a     a     ",
      "     a bbbbbbb a",
      "     bbcccccccbb",
      "    bccccccccccc",
      "a  bcccccccccccc",
      " abccccccccccccc",
      "  bcccccdddddccc",
      " bcccccdd e dfcc",
      " bccccggh   hffc",
      " bccccg   e   fc",
      "abccccge eie efc",
      " bccccg   e   fc",
      " bccccggh   hffc",
      " bcccccgj e jjcc",
      "  bcccccjjjjjccc",
      " abccccccccccccc"
    ],
    [
      "k  ll     mnnnnn",
      "opl    @q@@@q@nn",
      "onrs t@uwxyxwu@t",
      "nnnm@           ",
      "nnn@            ",
      "nnt             ",
      "nn@             ",
      "n@u             ",
      "nqw     h   h   ",
      "n@x      e e    ",
      "m@A       e     ",
      "n@x      e e    ",
      "nqw     h   h   ",
      "n@u             ",
      "nn@             ",
      "nnt             "
    ],
    [
      "          B     ",
      "       @@@@@@@  ",
      "  B  @@C     C@@",
      " D B@           ",
      "   @            ",
      "  @             ",
      "  @             ",
      " @C             ",
      " @      hE Eh   ",
      " @      E   E   ",
      "B@              ",
      " @      E   E   ",
      " @      hE Eh   ",
      " @C             ",
      "  @             ",
      "  @             "
    ],
    [
      "                ",
      "       lllFlll  ",
      "     ll   l   ll",
      " I  l     l     ",
      "   ll           ",
      "  l  l         J",
      "  l             ",
      " l              ",
      " l      hKLMh   ",
      " l      N   N   ",
      " Fll    O   O   ",
      " l      P   P   ",
      " l      hKLMh   ",
      " l              ",
      "  l             ",
      "  l  J         J"
    ],
    [
      "   QQ           ",
      "  Q             ",
      "                ",
      "                ",
      "        RRRRR   ",
      "      RR  R  RR ",
      "     RR   R   oo",
      "     R R lll ooo",
      "    R   F   nooo",
      "    R  l   Jnnoo",
      "    RRRl  JJnnoo",
      "    R  l JJJnnoo",
      "    R   nnnnnooo",
      "     R oonnnoooo",
      "     Roooooooooo",
      "      ooooooooo "
    ],
    [
      " ooJJnnnnn      ",
      "  Jnnnn         ",
      "   nn           ",
      "                ",
      "                ",
      "                ",
      "                ",
      "                ",
      "                ",
      "S           D   ",
      "                ",
      "                ",
      "                ",
      "                ",
      "                ",
      "                "
    ]
  ]
}