{
  "name": "multi_alienresearch_5_base6",
  "refpalette": "deceasedcraft:multi_alienresearch_5/multi_alienresearch_5_base6_palette",
  "xsize": 16,
  "zsize": 16,
  "slices": [
    [
      "       aaaaaaa  ",
      "     aa       aa",
      "    a           ",
      "   a            ",
      "  a             ",
      " a              ",
      " a              ",
      "a               ",
      "a       ~       ",
      "a               ",
      "a               ",
      "a               ",
      "a               ",
      "a               ",
      " a              ",
      " a              "
    ],
    [
      "                ",
      "                ",
      "                ",
      "                ",
      "                ",
      "                ",
      "                ",
      "        bbcbb   ",
      "       bbcbcbb  ",
      "       bc   cb  ",
      "       cb   bc  ",
      "       bc   cb  ",
      "       bbcbcbb  ",
      "        bbcbb   ",
      "                ",
      "                "
    ],
    [
      "                ",
      "       ddefedd  ",
      "     efeeefeeefe",
      "    defefffffefe",
      "   deeffgggggffe",
      "  eeefgghhhhhggf",
      "  fffgghiiiiihgg",
      " deefghiijkjilhg",
      " defghmmj   jllh",
      " eefghmj     jlh",
      " fffghmk     klh",
      " eefghmj     jlh",
      " defghmmj   jllh",
      " deefghmnjkjnnhg",
      "  fffgghnnnnnhgg",
      "  eeefgghhhhhggf"
    ],
    [
      "   e opppoqopppo",
      "  dpo orrstsrro ",
      " d ppotu wxw uto",
      "epppr           ",
      " opr            ",
      "o o             ",
      "pot             ",
      "pru      yyy    ",
      "pr      ABCDA   ",
      "oEF    IJ   JK  ",
      "LtM    IN   NK  ",
      "oEF    IO   OK  ",
      "pr      ABCDA   ",
      "pru      PPP    ",
      "pot             ",
      "o o             "
    ],
    [
      "dppo o   oqo   o",
      "ppr o o   t   o ",
      "prk  ot   Q   to",
      "o               ",
      " o              ",
      "o o             ",
      " ot             ",
      "                ",
      "        AR RA   ",
      "o       R   R   ",
      "Lt              ",
      "o       R   R   ",
      "        AR RA   ",
      "                ",
      " ot             ",
      "o o             "
    ],
    [
      "p  @S@   @S@   @",
      "    @S@   t   @S",
      "     @t       t@",
      "@               ",
      "S@              ",
      "@S@             ",
      " @t             ",
      "                ",
      "        A   A   ",
      "@        T T    ",
      "St        T     ",
      "@        T T    ",
      "        A   A   ",
      "                ",
      " @t             ",
      "@S@             "
    ]
  ]
}