{
  "name": "multi_alienresearch_5_base9",
  "refpalette": "deceasedcraft:multi_alienresearch_5/multi_alienresearch_5_base9_palette",
  "xsize": 16,
  "zsize": 16,
  "slices": [
    [
      "aaaaaaaaaaaaaaaa",
      "aaaaaaaaaaaaaaaa",
      "aaaaaaabbcccbbaa",
      "aaaaaabbcccccbba",
      "aaaaccccccdccccc",
      "aaaacccc     ccc",
      "aaabccd   e   dc",
      "aabbcc f  g  f c",
      "aabcc     h     ",
      "aaccc     h     ",
      "aaccd    ijkl!  ",
      "aaccc     h     ",
      "aabcc     h     ",
      "aabbcc f  g  f c",
      "aaabccd   e   dc",
      "aaaacccc     ccc"
    ],
    [
      "aaaaaabbbcccbbba",
      "aaaabbbbbcccbbbb",
      "aaacbbb   m   bb",
      "aacccb    m    b",
      "abbcm   mmmmm   ",
      "abbb m m     m m",
      "bbb   m       m ",
      "bb   m f  n  f m",
      "bb  m           ",
      "cc  m           ",
      "ccmmm           ",
      "cc  m           ",
      "bb  m           ",
      "bb   m f  n  f m",
      "bbb   m       m ",
      "abbb m m     m m"
    ],
    [
      "aabbbb    m    b",
      "accb      m     ",
      "bcc             ",
      "bb m            ",
      "b               ",
      "b               ",
      "                ",
      "       f  n  f  ",
      "                ",
      "                ",
      "mm              ",
      "                ",
      "                ",
      "       f  n  f  ",
      "                ",
      "b               "
    ],
    [
      "cc              ",
      "cm              ",
      "  m             ",
      "                ",
      "                ",
      "                ",
      "                ",
      "       f  n  f  ",
      "                ",
      "                ",
      "                ",
      "                ",
      "                ",
      "       f  n  f  ",
      "                ",
      "                "
    ],
    [
      "m         o     ",
      " p              ",
      "  m             ",
      "   o            ",
      "                ",
      "                ",
      "                ",
      "       f  q  f  ",
      "                ",
      "                ",
      "o               ",
      "                ",
      "                ",
      "       f  q  f  ",
      "                ",
      "                "
    ],
    [
      "      rmmmmmmmr ",
      "     mm   m   mm",
      "  p m     m     ",
      "   m      m     ",
      "  m m   mmmmm   ",
      " m   m m     m m",
      "rm    m       m ",
      "m    misltuklsim",
      "m   m    w      ",
      "m   m           ",
      "mmmmm           ",
      "m   m           ",
      "m   m    x      ",
      "m    misltuklsim",
      "rm    m       m ",
      " m   m m     m m"
    ]
  ]
}