{
  "name": "multi_alienresearch_5_base4",
  "refpalette": "deceasedcraft:multi_alienresearch_5/multi_alienresearch_5_base4_palette",
  "xsize": 16,
  "zsize": 16,
  "slices": [
    [
      "   a            ",
      "                ",
      "                ",
      "                ",
      "                ",
      "                ",
      "                ",
      "                ",
      "                ",
      "            b   ",
      "                ",
      "                ",
      "                ",
      "                ",
      "                ",
      "                "
    ],
    [
      "                ",
      "                ",
      "                ",
      "                ",
      "                ",
      "                ",
      "                ",
      "                ",
      "                ",
      "                ",
      "                ",
      "                ",
      "                ",
      "                ",
      "                ",
      "                "
    ],
    [
      "                ",
      "       ccddddd  ",
      "     dd       dd",
      "    c           ",
      "   cd           ",
      "  c             ",
      "  c             ",
      " c              ",
      " c              ",
      " c              ",
      " c              ",
      " c              ",
      " c              ",
      " e              ",
      "  f             ",
      "  f             "
    ],
    [
      "       ggghggg  ",
      "     gghhhhhhhgg",
      "    ghhhiiiiihhh",
      "   hhhiijjjjjiih",
      "  ghiijjeeeeejji",
      " ghhijff     ee ",
      " ghijfe         ",
      "ghhijf   eee    ",
      "ghije   e       ",
      "ghijf  f        ",
      "hhijf  f        ",
      "ghijf  f        ",
      "ghijf           ",
      "ghhijf          ",
      " ghijf          ",
      " ghhi           "
    ],
    [
      "                ",
      "                ",
      "                ",
      "          a     ",
      "        hhhhh   ",
      "      hhhhhhhhh ",
      "     hhhhhhhhh  ",
      "     hhhhjjjh   ",
      "    hhhhjiii    ",
      "    hhhjijj     ",
      "   ahhhjij      ",
      "    hhhji       ",
      "    hhhh        ",
      "     hh         ",
      "     h          ",
      "                "
    ],
    [
      "                ",
      "                ",
      "                ",
      "                ",
      "                ",
      "                ",
      "                ",
      "                ",
      "                ",
      "                ",
      "                ",
      "                ",
      "                ",
      "                ",
      "                ",
      "      k         "
    ]
  ]
}