{
  "name": "multi_alienresearch_5_base8",
  "refpalette": "deceasedcraft:multi_alienresearch_5/multi_alienresearch_5_base8_palette",
  "xsize": 16,
  "zsize": 16,
  "slices": [
    [
      "  aaabbbbbbbbbbb",
      " aabbbbbbbbbbbbb",
      "aabbbbbbbbbbbbbb",
      "abbbbbbbbbbbbbbb",
      "abbbbbbcccccccbb",
      "bbbbbbcc     ccb",
      "bbbbbcc ddddd cc",
      "bbbbcc dd   dd c",
      "bbbbc dd     dd ",
      "bbbbc d       d ",
      "bbbbc d       d ",
      "bbbbc d       d ",
      "bbbbc dd     dd ",
      "bbbbcc dd   dd c",
      "bbbbbcc ddddd cc",
      "bbbbbbcc     ccb"
    ],
    [
      "  aaa           ",
      " aa    e    f   ",
      "aa   ghij   gklj",
      "a               ",
      "a      m nnn m  ",
      "  o     ppppp   ",
      "  q    prrrrrp  ",
      " fs m prrrrrrrp ",
      "  t  prrrrrrrrrp",
      "    uprrrrrrrrrp",
      "    uprrrrrrrrrp",
      "    uprrrrrrrrrp",
      "  o  prrrrrrrrrp",
      "f w m prrrrrrrp ",
      "  x    prrrrrp  ",
      "  t     ppppp   "
    ],
    [
      "                ",
      "                ",
      "      yA      ! ",
      "                ",
      "                ",
      "        aa aa   ",
      "       aa   aa  ",
      "  B   aa C  Daa ",
      "     aaE~    Faa",
      "     a I       a",
      "                ",
      "     aJ      K a",
      "     aaL     Maa",
      "  N   aa     aa ",
      "       aa   aa  ",
      "        aa aa   "
    ],
    [
      "                ",
      "                ",
      "                ",
      "                ",
      "                ",
      "                ",
      "                ",
      "                ",
      "             N  ",
      "                ",
      "                ",
      "                ",
      "                ",
      "                ",
      "                ",
      "                "
    ],
    [
      "                ",
      "                ",
      "                ",
      "                ",
      "                ",
      "                ",
      "                ",
      "                ",
      "        ~       ",
      "                ",
      "                ",
      "                ",
      "                ",
      "                ",
      "                ",
      "                "
    ],
    [
      "                ",
      "                ",
      "                ",
      "                ",
      "                ",
      "                ",
      "                ",
      "                ",
      "                ",
      "                ",
      "                ",
      "                ",
      "                ",
      "                ",
      "                ",
      "                "
    ]
  ]
}