{
  "name": "multi_alienresearch_5_ground",
  "refpalette": "deceasedcraft:multi_alienresearch_5/multi_alienresearch_5_ground_palette",
  "xsize": 16,
  "zsize": 16,
  "slices": [
    [
      "abvazaaabaaaaaav",
      "avaaaaavvaavavba",
      "aaaavaaaaaaaaaaa",
      "vzavavavvazavvza",
      "aavvavzvzvvvvvav",
      "vbvvvvvvvvavvbvv",
      "vvvzvvvvvvvvvvvv",
      "vvvvvavvzvvvavvz",
      "vvbvvvvvvvbvvvvv",
      "azvvvvvvvvvvvzvv",
      "vvvvzavzvvvvvzvv",
      "zazvazvvazvvvvvv",
      "cccccccccccccccc",
      "zdezdefghgzzgfhh",
      "ddeeedczghzghzgg",
      "zzeeeechghggghhz"
    ],
    [
      "                ",
      "                ",
      "                ",
      " i              ",
      "                ",
      "                ",
      "                ",
      "                ",
      "                ",
      "                ",
      "    i           ",
      "i        i      ",
      "jjjjjjj   klllll",
      "immi  noppppon  ",
      "q      i  i  i  ",
      " r  q   qs     r"
    ],
    [
      "                ",
      "                ",
      "                ",
      "                ",
      "                ",
      "                ",
      "                ",
      "                ",
      "                ",
      "                ",
      "                ",
      "                ",
      "tutt tt   klllll",
      "      noppppon  ",
      "                ",
      "                "
    ],
    [
      "                ",
      "                ",
      "                ",
      "                ",
      "                ",
      "                ",
      "                ",
      "                ",
      "                ",
      "                ",
      "                ",
      "                ",
      "  ttutt   klllll",
      "      noppppon  ",
      "                ",
      "                "
    ],
    [
      "                ",
      "                ",
      "                ",
      "                ",
      "                ",
      "                ",
      "                ",
      "                ",
      "                ",
      "                ",
      "                ",
      "                ",
      "  ttutw   klllll",
      "      noppppon  ",
      "                ",
      "                "
    ],
    [
      "                ",
      "                ",
      "                ",
      "                ",
      "                ",
      "                ",
      "                ",
      "                ",
      "                ",
      "                ",
      "                ",
      "                ",
      " wttttw   klllll",
      "nnx   noppppon  ",
      "                ",
      "                "
    ]
  ]
}