{
  "name": "multi_militarybase_4_base1",
  "refpalette": "deceasedcraft:multi_militarybase_4/multi_militarybase_4_base1_palette",
  "xsize": 16,
  "zsize": 16,
  "slices": [
    [
      "vvvvvvvvvvvvvvvv",
      "avaaaaaaavaaaavv",
      "abaaaaaaabaaaavv",
      "abaaaaaaabaaaavv",
      "abaaaaacabaaaavv",
      "bvbbbbbbbvbbbvvv",
      "abaaaaaaabaaaavv",
      "abaaaaaaabaaaavv",
      "abaaaaaaabaaaavv",
      "dveaaaaacbaaaavv",
      "fbffaaaaabaaaavv",
      "fbfgfaaaabaaaavv",
      "fbfffcaaabaaaavv",
      "bvbbbbbbbvbbbvvv",
      " bfgfaaaaaaaaavv",
      " bfffaaaaaaaaavv"
    ],
    [
      "vvvvvvvvvvvvvvvv",
      " vhijkl!mvnnnnvv",
      " o     pmq  nnvv",
      " rs   t     nnvv",
      " o       qn  nvv",
      " v       vuuuvvv",
      " o      wqxxxyvv",
      " rs      qx  Avv",
      " o B CD  q   EFv",
      " ve          EFv",
      "      IJ qK  EFv",
      "  L   MNLqOs Pvv",
      "       L qOs Qvv",
      "Rv      Bvuuuvvv",
      " R       LSTSTvv",
      " R   LIJ      vv"
    ],
    [
      "vvvvvvvvvvvvvvvv",
      " v     tmv nnnvv",
      "        Uq   nvv",
      " V            vv",
      "         q    vv",
      " v       vuuuvvv",
      "         qxx  vv",
      " V       q    vv",
      "         q    Fv",
      " v            Fv",
      "         q    Fv",
      "      D  qW   vv",
      "         qW   vv",
      " v      Xvuuuvvv",
      "          SSSSvv",
      "              vv"
    ],
    [
      "vvvvvvvvvvvvvvvv",
      " v       v  nnvv",
      "         q   Yvv",
      "         q    vv",
      "         q    vv",
      " v       vuuuvvv",
      "         qx   vv",
      "         q    vv",
      "         q    Fv",
      " v       q    Fv",
      "         q    Fv",
      "         q    vv",
      "         q    vv",
      " v       vuuuvvv",
      "          SZZSvv",
      "              vv"
    ],
    [
      "vvvvvvvvvvvvvvvv",
      " v       v   Yvv",
      " R       q   Yvv",
      " R       q    vv",
      " R       q    vv",
      " vRRRRRRRvuuuvvv",
      " R       R    vv",
      " R       R    vv",
      " R       R   0Fv",
      " v       R   0Fv",
      "         R   0Fv",
      "         R    vv",
      "         R    vv",
      "1v       vuuuvvv",
      " 1            vv",
      " 1            vv"
    ],
    [
      "vvvvvvvvvvvvvvvv",
      "2v2222222v2222vv",
      "3b3333333b3332vv",
      "3b3333333b3332vv",
      "3b3333333b3332vv",
      "b4bbbbbbbvbbbvvv",
      "3b3333333b3332vv",
      "3b3333333b3332vv",
      "3b3333333b333!vv",
      "3v3333333b3332vv",
      "3b3333333b3332vv",
      "3b3333333b3332vv",
      "3b3333333b3332vv",
      "bvbbbbbbbvbbbvv5",
      "6b333333333332vv",
      "6b333333333332vv"
    ]
  ]
}