{
  "name": "multi_militarybase_4_base3",
  "refpalette": "deceasedcraft:multi_militarybase_4/multi_militarybase_4_base3_palette",
  "xsize": 16,
  "zsize": 16,
  "slices": [
    [
      "vvvvvvvvvvvvvvvv",
      " vaaaaaaavaaaavv",
      " baaaaaaabaaaavv",
      " baaaaaaabaaaavv",
      " baaaaaaabaaaavv",
      " vbbbbbbbvbbbvvv",
      " bcccaaaabaaaavv",
      " bcccaaaabaaaavv",
      " bcccaaaabaaaavv",
      " vdccaaaabaaaavv",
      " bcccaaaabaaaavv",
      " bcccaaaabaaaavv",
      "ebcccaaaabaaaavv",
      " vbbbbbbbvbbbvvv",
      " bcccaaaaaaaaavv",
      " bcccaaaaaaaaavv"
    ],
    [
      "vvvvvvvvvvvvvvvv",
      " vf ghi fvjjjjvv",
      " k      lmj  jvv",
      " k  nnn lmo  jvv",
      " k      pmj qjvv",
      " v       vmrmvvv",
      " k       st tuvv",
      " k       s    vv",
      " kw   xy   A  vv",
      " vwB    C D  tvv",
      " kB          uvv",
      " kEF  I  s   tvv",
      " kJ      s!tutvv",
      " v       vmmmvvv",
      " k   KLK KLK Mvv",
      " k          N!vv"
    ],
    [
      "vvvvvvvvvvvvvvvv",
      " vf     fvjqqqvv",
      "         mo  jvv",
      "         mo  ovv",
      "         mj  jvv",
      " v       vmOmvvv",
      "         s  t vv",
      "         s    vv",
      "              vv",
      " v            vv",
      "             tvv",
      "         s    vv",
      "         s   tvv",
      " v       vmmmvvv",
      "              vv",
      "              vv"
    ],
    [
      "vvvvvvvvvvvvvvvv",
      " v      !vj ojvv",
      "         m   qvv",
      "         mo   vv",
      "         m   qvv",
      " v       vmmmvvv",
      "         s    vv",
      "         s    vv",
      "         s    vv",
      " vP      s    vv",
      "         s    vv",
      "         s    vv",
      "         s    vv",
      " v       vmmmvvv",
      "             Qvv",
      "              vv"
    ],
    [
      "vvvvvvvvvvvvvvvv",
      " v       vo  qvv",
      " R       m    vv",
      " R       m    vv",
      " R       m    vv",
      " vkkkkkkkvmmmvvv",
      " R       k    vv",
      " R       k    vv",
      " R       k    vv",
      " vP      k    vv",
      " R       k    vv",
      " R       k    vv",
      " R       k    vv",
      "Rv       vmmmvvv",
      " R            vv",
      " R            vv"
    ],
    [
      "vvvvvvvvvvvvvvvv",
      "SvSSSSSSSvSSSSvv",
      "TbTTTTTTTbTTTSvv",
      "TbTTTTTTTbTTTSvv",
      "TbTTTTTTTbTTTSvv",
      "Tvbbbbbbbvbbbvvv",
      "TbTTTTTTTbTTTSvv",
      "TbTTTTTTTbTTTSvv",
      "TbTTTTTTTbTTTSvv",
      "TvPTTTTTTbTTTSvv",
      "TbTTTTTTTbTTTSvv",
      "TbTTTTTTTbTTTSvv",
      "TbTTTTTTTbTTTSvv",
      "Uvbbbbbbbvbbbvvv",
      " UTTTTTTTTTTTSvv",
      " UTTTTTTTTTTTSvv"
    ]
  ]
}