{
  "name": "multi_militarybase_4_ground",
  "refpalette": "deceasedcraft:multi_militarybase_4/multi_militarybase_4_ground_palette",
  "xsize": 16,
  "zsize": 16,
  "slices": [
    [
      "zzzzzzzzzzzzzzzz",
      "aaaaaaaaaaaaaaaz",
      "bzzzzzbzzzzbbbaz",
      "bbzbbzzbzbzzbbaz",
      "cdebfffbfffzzzaz",
      "eghbbbbbbbbzzbaz",
      "cdcbbbbbbbbbzzaz",
      "hcbfffffbffbzzaz",
      "bbcbbbbbbbbbbzaz",
      "bbbbbbbbbbbbbbaz",
      "bbfbfffffffbzzaz",
      "bbbibbbbbbbbbzaz",
      "bbbbbbbbbbbbzzaz",
      "bbbbfffffbfbzbjk",
      "bbbbbbbbbbbbbzdd",
      "lbbbbbbbbbbbbzam"
    ],
    [
      "                ",
      "aaaaaaaaaaaaaaa ",
      "  n n o n n  oa ",
      " mc           a ",
      "m  c         na ",
      "   mpdpppdp n a ",
      "   mpqqqqqp   a ",
      "    pqqqqqp  na ",
      " r spdpppdp   a ",
      "   t        uoa ",
      "  wx       r  a ",
      "yA   B      rsa ",
      "       pdpppdpem",
      "       pqqqqqpm ",
      "       pqqqqqp C",
      "       pdpppdpe "
    ],
    [
      "                ",
      "aaaaaaaaaaaaaaa ",
      "      o      oa ",
      "      D       a ",
      "       E      a ",
      "   FIJK LJLM  a ",
      "    N OPQRS   a ",
      "    N OPQTU   a ",
      "   FVWL LWKM  a ",
      "       X    uoa ",
      "              a ",
      "          Y   e ",
      "      Z010 234  ",
      "       5 678 j  ",
      "       9R6 8 #  ",
      "      Z2$0 0%^# "
    ],
    [
      "                ",
      "aaaaaaaaaaaaaaa ",
      "      o      oa ",
      "      D       a ",
      "      &       a ",
      "     *( ))KM  a ",
      "    +-(   [   a ",
      "    ]-(   {   a ",
      "     }( ))LM  a ",
      "      |   ; uoa ",
      "              a ",
      "       :   '  a ",
      "      Z0<< (> , ",
      "       .    ?/  ",
      "       `    ?   ",
      "      Z0<< (\u0370   "
    ],
    [
      "                ",
      "aaaaaaaaaaaaaaa ",
      "      o      oa ",
      "      D       a ",
      "       \u0371      a ",
      "      +-]     a ",
      "      ]QL++   a ",
      "      +QL]+   a ",
      "      +-+     a ",
      "       \u0372    uoa ",
      "              a ",
      "          \u0371   a ",
      "         \u0373?\u0373  a ",
      "       \u0373\u037326\u0373  a ",
      "       \u0374\u037306\u0373  a ",
      "         \u0373?\u0374  a "
    ],
    [
      "                ",
      "\u0375\u0375\u0375\u0375\u0375\u0376\u0377\u0375\u0375\u0375\u0375\u0375\u0375\u037a\u037a ",
      "\u037b\u037b\u037b\u037b\u037b\u037b\u037c\u037b\u037b\u037b\u037b\u037b\u037b\u037c\u037a ",
      "      D      \u037b\u037d ",
      "             \u037b\u037d ",
      "             \u037b\u037d ",
      "             \u037b\u037d ",
      "             \u037b\u037d ",
      "             \u037b\u037d ",
      "            u\u037c\u0377 ",
      "             \u037b\u037d ",
      "             \u037b\u037d ",
      "             \u037b\u037d ",
      "           ~ \u037b\u037d ",
      "             \u037b\u037e ",
      "             \u037b\u037d "
    ]
  ]
}