{
  "name": "multi_militarybase_4_base4",
  "refpalette": "deceasedcraft:multi_militarybase_4/multi_militarybase_4_base4_palette",
  "xsize": 16,
  "zsize": 16,
  "slices": [
    [
      "vvvvvvvvvvvvvvvv",
      "avaaaaaaavaaaavv",
      "abaaaaaaabaaaavv",
      "abaaaaaaabaaaavv",
      "abaaaaaaabaaaavv",
      "bvbbbbbbbvbbbvvv",
      "abaaaaaaabaaaavv",
      "abaaaaaaabaaaavv",
      "abaaaaaaabaaaavv",
      "avaaaaaaabaaaavv",
      "abaaaaaaabaaaavv",
      "abaaaaaaabaaaavv",
      "abaaaaaaabaaaavv",
      "bvbbbbbbbbbbbvvv",
      "cbddddddddddddvv",
      "cbddddddddddddvv"
    ],
    [
      "vvvvvvvvvvvvvvvv",
      "evfffffffvghghvv",
      "eijklmnlop   qvv",
      "ei           hvv",
      "ei       p   qvv",
      "ev       vrrrvvv",
      "ei          sfvv",
      "ei          tfvv",
      "ui  wxw     nfvv",
      "uvy xAx     Bfvv",
      " i  wxw     nfvv",
      " C          Dfvv",
      " i          Efvv",
      "ev           vvv",
      "F             vv",
      "              vv"
    ],
    [
      "vvvvvvvvvvvvvvvv",
      "IvJnKnlLJv M !vv",
      " i       p    vv",
      " i           Nvv",
      "Oi       p    vv",
      "ev       vrrrvvv",
      "ei           Dvv",
      "ei           Pvv",
      "ui           Qvv",
      " vy          nvv",
      " i           Qvv",
      " C           Rvv",
      " i           Dvv",
      "ev           vvv",
      "n             vv",
      "             Svv"
    ],
    [
      "vvvvvvvvvvvvvvvv",
      " v       v    vv",
      " i       p    vv",
      " i       p    vv",
      " i       p    vv",
      "Tv       vrrrvvv",
      "Ui            vv",
      "Oi            vv",
      "ei            vv",
      "evy           vv",
      "Vi            vv",
      " i            vv",
      "Wi            vv",
      "ev           vvv",
      "              vv",
      "              vv"
    ],
    [
      "vvvvvvvvvvvvvvvv",
      " v       v    vv",
      " i       p    vv",
      " i       p    vv",
      " i       p    vv",
      " vXXXXXXXvrrrvvv",
      " i       X    vv",
      " i       X    vv",
      " i       X    vv",
      " vy      X    vv",
      "Oi       X    vv",
      "ei       X    vv",
      "ei       X    vv",
      "evXXXXXXXXXXXvvv",
      "              vv",
      "              vv"
    ],
    [
      "vvvvvvvvvvvvvvvv",
      " vYYYYYYYvYYYYvv",
      " ZYYYYYYYbYYYYvv",
      " ZYYYYYYYbYYYYvv",
      " ZYYYYYYYbYYYYvv",
      " vbbbbbbbbbbbvvv",
      " ZYYYYYYYbYYYYvv",
      " ZYYYYYYYbYYYYvv",
      " ZYYYYYYYbYYYYvv",
      " vyYYYYYYbYYYYvv",
      " ZYYYYYYYbYYYYvv",
      " ZYYYYYYYbYYYYvv",
      "UZYYYYYYYbYYYYvv",
      "Ovbbbbbbbbbbbvvv",
      "VZYYYYYYYYYYYYvv",
      "0ZYYYYYYYYYYYYvv"
    ]
  ]
}