{
  "name": "multi_militarybase_4_base2",
  "refpalette": "deceasedcraft:multi_militarybase_4/multi_militarybase_4_base2_palette",
  "xsize": 16,
  "zsize": 16,
  "slices": [
    [
      "vvvvvvvvvvvvvvvv",
      "avaaaaaaavaaaavv",
      "abaaaaaaabaaaavv",
      "abaaaaaaabaaaavv",
      "abaaaaaaabaaaavv",
      "bvbbbbbbbvbbbvvv",
      "abaaaaaacbaaaavv",
      "abaaadeeabaaaavv",
      "abaaafdcabaaaavv",
      "gvhaeefdabaaaavv",
      "ibiejdaaabaaaavv",
      "ibieiaaaabaaaavv",
      "ibiiiaaaabaaaavv",
      "bvbbbbbbbvbbbvvv",
      " biiiaaaaaaaaavv",
      " biiiaaaaaaaaavv"
    ],
    [
      "vvvvvvvvvvvvvvvv",
      " vk k k kvlmlmvv",
      "nop p p po   mvv",
      "qor r r r    svv",
      "to       o   svv",
      "uvuuuwuuuvo ovvv",
      " x  yA   B CDEvv",
      "FI  f    B    vv",
      "        JB CDEvv",
      "uvh     KL    vv",
      "         B CDEvv",
      "         B    vv",
      "     M   B CDEvv",
      "Nv  KO   vooovvv",
      " N  P     QRS vv",
      " N           Tvv"
    ],
    [
      "vvvvvvvvvvvvvvvv",
      " vk k k kv U mvv",
      " op p p po   Vvv",
      " or r r r     vv",
      " o       o    vv",
      "uvuuuWuuuvo ovvv",
      "         B CDEvv",
      "         B    vv",
      "         B CDEvv",
      "uvh      X    vv",
      "         B CDEvv",
      "         B    vv",
      "         B CDEvv",
      " vY      vooovvv",
      "              vv",
      "              vv"
    ],
    [
      "vvvvvvvvvvvvvvvv",
      " v       v    vv",
      " o       o    vv",
      " o       o    vv",
      " o       o    vv",
      "uvuuuuuuuvooovvv",
      "         B    vv",
      "         B    vv",
      "         B    vv",
      "uvh      B    vv",
      "         B    vv",
      "         B    vv",
      "         B    vv",
      " v       vooovvv",
      "              vv",
      "              vv"
    ],
    [
      "vvvvvvvvvvvvvvvv",
      " v       v    vv",
      " o       o    vv",
      " o       o    vv",
      " o       o    vv",
      "uvNNNNNNNvooovvv",
      " N       N    vv",
      " N       N    vv",
      " N       N    vv",
      "Nvh      N    vv",
      "         N    vv",
      "         N    vv",
      "         N    vv",
      "Zv       vooovvv",
      " Z            vv",
      " Z            vv"
    ],
    [
      "vvvvvvvvvvvvvvvv",
      "0v0000000v0000vv",
      "1b1111111b1110vv",
      "1b1111111b1110vv",
      "1b1111111b1110vv",
      "bvbbbbbbbvbbbvvv",
      "1b1111111b111!vv",
      "1b1111111b1110vv",
      "1b1111111b1110vv",
      "1vh111111b1110vv",
      "1b1111111b1110vv",
      "1b1111111b1110vv",
      "1b1111111b1110vv",
      "2vbbbbbbbvbbbvvv",
      " 2111111111110vv",
      " 2111111111110vv"
    ]
  ]
}