{
  "name": "building_residentialc_ground",
  "refpalette": "deceasedcraft:building_residentialc/building_residentialc_ground_palette",
  "xsize": 16,
  "zsize": 16,
  "slices": [
    [
      "abbaaaaabaaaaaaa",
      "abbbbbbbbbbbbbbb",
      "abccccccccccccbb",
      "abcddddddeeefbbb",
      "abcddddddeeefbbb",
      "abcddddddeeefbbb",
      "abcddddddeeefbbb",
      "aacddddddeeefbbb",
      "aacddddddeeefbbb",
      "abcddddddeeefbbb",
      "abcddddddeeefbbb",
      "bbcddddddeeefbbb",
      "abcddddddeeefbbb",
      "abccccccccccccbb",
      "abbbbbbbbbbbbbbb",
      "aaaaabaaabbabaaa"
    ],
    [
      "                ",
      "               g",
      "  hhiihiihiihh g",
      "  j  kl mn ofg g",
      "  jp ql mn ofg g",
      "  jr sl  t ufg g",
      " wh   x    yfg g",
      "  A   x    Bfg g",
      "  C        Dfg g",
      "  h        Efg g",
      "  j      FFFfg g",
      "  jI     J Kfg g",
      "  jLM N  OPQfg g",
      "  hhRRhRRhRRhh g",
      "               g",
      "                "
    ],
    [
      "                ",
      "                ",
      "  hhSShSShSShh  ",
      "  S   T  U  f   ",
      "  S  VT     f   ",
      "  S  WT    Xf   ",
      "  hY  x     f   ",
      "  Z   x     0   ",
      "  1         0   ",
      "  h        2f   ",
      "  S      FFFf   ",
      "  S      3  f   ",
      "  S45N   O  f   ",
      "  hhSShSSh66hh  ",
      "                ",
      "                "
    ],
    [
      "                ",
      "                ",
      "  hhhhhhhhhhhh  ",
      "  S   T     f7  ",
      "  S   T     f7  ",
      "  S   T     f7  ",
      "  h   x     f7  ",
      "  S   x     07  ",
      "  S     8   07  ",
      "  h         f7  ",
      "  S      FFFf7  ",
      "  S 9    O  f7  ",
      "  S      O  f7  ",
      "  hhhhhhhhhhhh  ",
      "                ",
      "                "
    ],
    [
      "                ",
      " ############## ",
      " RhhhhhhhhhhhhR ",
      "  hdddddddddf$  ",
      "  hdddddddddf$  ",
      "  hdddddddddf$  ",
      "  hdddddddddf$  ",
      "  hdddddddddf   ",
      "  hdddddddddf   ",
      "  hdddddddddf$  ",
      "  hd9  dddddf$  ",
      "  hd   dddddf$  ",
      "  hd   dddddf$  ",
      " ihhhhhhhhhhhhi ",
      " %%%%%%%%%%%%%% ",
      "                "
    ],
    [
      "                ",
      "                ",
      " ############## ",
      " R$fhhhhhhhhf$R ",
      "  $f$$$$$$$$f$  ",
      "  $f^&&* ()+f$  ",
      "  $f-[[-]({}f$  ",
      "   f----)( |f   ",
      "   f        f   ",
      "  $f ;; ::::f$  ",
      "  $f  '< >,>f$  ",
      "  $f  '    .f$  ",
      " i$f  ? /`! f$i ",
      " %%%%%%%%%%%%%% ",
      "                ",
      "                "
    ]
  ]
}