{
  "name": "building_residentialc_ground_180",
  "refpalette": "deceasedcraft:building_residentialc/building_residentialc_ground_palette_180",
  "xsize": 16,
  "zsize": 16,
  "slices": [
    [
      "aaababbaaabaaaaa",
      "bbbbbbbbbbbbbbba",
      "bbccccccccccccba",
      "bbbfeeeddddddcba",
      "bbbfeeeddddddcbb",
      "bbbfeeeddddddcba",
      "bbbfeeeddddddcba",
      "bbbfeeeddddddcaa",
      "bbbfeeeddddddcaa",
      "bbbfeeeddddddcba",
      "bbbfeeeddddddcba",
      "bbbfeeeddddddcba",
      "bbbfeeeddddddcba",
      "bbccccccccccccba",
      "bbbbbbbbbbbbbbba",
      "aaaaaaabaaaaabba"
    ],
    [
      "                ",
      "g               ",
      "g hhRRhRRhRRhh  ",
      "g gfQPO  N MLj  ",
      "g gfK J     Ij  ",
      "g gfFFF      j  ",
      "g gfE        h  ",
      "g gfD        C  ",
      "g gfB    x   A  ",
      "g gfy    x   hw ",
      "g gfu t  ls rj  ",
      "g gfo nm lq pj  ",
      "g gfo nm lk  j  ",
      "g hhiihiihiihh  ",
      "g               ",
      "                "
    ],
    [
      "                ",
      "                ",
      "  hh66hSShSShh  ",
      "   f  O   N54S  ",
      "   f  3      S  ",
      "   fFFF      S  ",
      "   f2        h  ",
      "   0         1  ",
      "   0     x   Z  ",
      "   f     x  Yh  ",
      "   fX    TW  S  ",
      "   f     TV  S  ",
      "   f  U  T   S  ",
      "  hhSShSShSShh  ",
      "                ",
      "                "
    ],
    [
      "                ",
      "                ",
      "  hhhhhhhhhhhh  ",
      "  7f  O      S  ",
      "  7f  O    9 S  ",
      "  7fFFF      S  ",
      "  7f         h  ",
      "  70   8     S  ",
      "  70     x   S  ",
      "  7f     x   h  ",
      "  7f     T   S  ",
      "  7f     T   S  ",
      "  7f     T   S  ",
      "  hhhhhhhhhhhh  ",
      "                ",
      "                "
    ],
    [
      "                ",
      " %%%%%%%%%%%%%% ",
      " ihhhhhhhhhhhhi ",
      "  $fddddd   dh  ",
      "  $fddddd   dh  ",
      "  $fddddd  9dh  ",
      "  $fdddddddddh  ",
      "   fdddddddddh  ",
      "   fdddddddddh  ",
      "  $fdddddddddh  ",
      "  $fdddddddddh  ",
      "  $fdddddddddh  ",
      "  $fdddddddddh  ",
      " RhhhhhhhhhhhhR ",
      " ############## ",
      "                "
    ],
    [
      "                ",
      "                ",
      " %%%%%%%%%%%%%% ",
      " i$f !`/ ?  f$i ",
      "  $f.    '  f$  ",
      "  $f>,> <'  f$  ",
      "  $f:::: ;; f$  ",
      "   f        f   ",
      "   f| ()----f   ",
      "  $f}{(]-[[-f$  ",
      "  $f+)( *&&^f$  ",
      "  $f$$$$$$$$f$  ",
      " R$fhhhhhhhhf$R ",
      " ############## ",
      "                ",
      "                "
    ]
  ]
}