{
  "name": "building_residentialc_floor1_90",
  "refpalette": "deceasedcraft:building_residentialc/building_residentialc_floor1_palette_90",
  "xsize": 16,
  "zsize": 16,
  "slices": [
    [
      "                ",
      "   ab      pr   ",
      "   accc  cccr   ",
      "   adddjjdddr   ",
      "   ae    m  r   ",
      "   ae    m  r   ",
      "   aehik m  r   ",
      "   ae    m  r   ",
      "   aeg    o r   ",
      "   ae     nqr   ",
      "   ae       r   ",
      "   aef   l  r   ",
      "   adddjjdddr   ",
      "   accc  cccr   ",
      "   ab      pr   ",
      "                "
    ],
    [
      "                ",
      "    ab    pr    ",
      "    accBBccr    ",
      "    addjjddr    ",
      "    abA  m r    ",
      "   txby  m r    ",
      "    eb   m r    ",
      "    w    m r    ",
      "    w    m r    ",
      "    eb    qr    ",
      "   sub     r    ",
      "    ab     r    ",
      "    addjjddr    ",
      "    accBBccr    ",
      "    ab    pr    ",
      "                "
    ],
    [
      "                ",
      "     ab  pr     ",
      "     accccr     ",
      "     addddr     ",
      "     ab  pr     ",
      "     ab  pr     ",
      "   ttxb  pr     ",
      "    eCb  pr     ",
      "    eCb  pr     ",
      "   ssub  pr     ",
      "     ab  pr     ",
      "     ab  pr     ",
      "     addddr     ",
      "     accccr     ",
      "     ab  pr     ",
      "                "
    ],
    [
      "                ",
      "      abpr      ",
      "      accr      ",
      "      addr      ",
      "      a  r      ",
      "      a  r      ",
      "      aF r      ",
      "   tttE  r      ",
      "   sssD  r      ",
      "      aF r      ",
      "      a  r      ",
      "      a  r      ",
      "      addr      ",
      "      accr      ",
      "      abpr      ",
      "                "
    ],
    [
      "                ",
      "       ar       ",
      "       ar       ",
      "       ar       ",
      "       ar       ",
      "       ar       ",
      "       ar       ",
      "       ar       ",
      "       ar       ",
      "       ar       ",
      "       ar       ",
      "       ar       ",
      "       ar       ",
      "       ar       ",
      "       ar       ",
      "                "
    ],
    [
      "                ",
      "                ",
      "                ",
      "                ",
      "                ",
      "                ",
      "                ",
      "       ~~       ",
      "        ~       ",
      "                ",
      "                ",
      "                ",
      "                ",
      "                ",
      "                ",
      "                "
    ]
  ]
}