{
  "name": "building_residentialc_ground_270",
  "refpalette": "deceasedcraft:building_residentialc/building_residentialc_ground_palette_270",
  "xsize": 16,
  "zsize": 16,
  "slices": [
    [
      "aaaabaaaaaaaaaaa",
      "abbbbbbaabbbbbbb",
      "abccccccccccccbb",
      "abcddddddddddcba",
      "abcddddddddddcba",
      "bbcddddddddddcba",
      "abcddddddddddcba",
      "abcddddddddddcba",
      "abcddddddddddcbb",
      "bbceeeeeeeeeecba",
      "bbceeeeeeeeeecba",
      "abceeeeeeeeeecba",
      "bbcffffffffffcba",
      "abcbbbbbbbbbbcba",
      "abbbbbbbbbbbbbba",
      "abbbbbbbbbbbbbba"
    ],
    [
      "                ",
      "         w      ",
      "  hjjjhCAhjjjh  ",
      "  hLI     rp h  ",
      "  RM         i  ",
      "  R       sqki  ",
      "  hN    xxlllh  ",
      "  R          i  ",
      "  R        mmi  ",
      "  hOJF    tnnh  ",
      "  RP F       i  ",
      "  RQKFEDByuooi  ",
      "  hffffffffffh  ",
      "  hggggggggggh  ",
      "                ",
      " gggggggggggggg "
    ],
    [
      "                ",
      "                ",
      "  hSSSh1ZhSSSh  ",
      "  h4     Y   h  ",
      "  S5         S  ",
      "  SN      WV S  ",
      "  h     xxTTTh  ",
      "  S          S  ",
      "  S          S  ",
      "  hO3F      Uh  ",
      "  6  F       S  ",
      "  6  F2   X  S  ",
      "  hffff00ffffh  ",
      "  h          h  ",
      "                ",
      "                "
    ],
    [
      "                ",
      "                ",
      "  hSSShSShSSSh  ",
      "  h          h  ",
      "  h 9        h  ",
      "  h          h  ",
      "  h     xxTTTh  ",
      "  h          h  ",
      "  h    8     h  ",
      "  hOOF       h  ",
      "  h  F       h  ",
      "  h  F       h  ",
      "  hffff00ffffh  ",
      "  h7777777777h  ",
      "                ",
      "                "
    ],
    [
      "                ",
      " %i          R# ",
      " %hhhhhhhhhhhh# ",
      " %hddddddddddh# ",
      " %h  9dddddddh# ",
      " %h   dddddddh# ",
      " %h   dddddddh# ",
      " %hddddddddddh# ",
      " %hddddddddddh# ",
      " %hddddddddddh# ",
      " %hddddddddddh# ",
      " %hddddddddddh# ",
      " %hffffffffffh# ",
      " %h$$$$  $$$$h# ",
      " %i          R# ",
      "                "
    ],
    [
      "                ",
      "  %i        R#  ",
      "  %$$$$  $$$$#  ",
      "  %ffffffffff#  ",
      "  %     --^$h#  ",
      "  %   ; -[&$h#  ",
      "  %?''; -[&$h#  ",
      "  %  <  --*$h#  ",
      "  %/  : )] $h#  ",
      "  %` >: ((($h#  ",
      "  %! ,:  {)$h#  ",
      "  % .>: |}+$h#  ",
      "  %ffffffffff#  ",
      "  %$$$$  $$$$#  ",
      "  %i        R#  ",
      "                "
    ]
  ]
}