{
  "name": "building_residentialc_floor1_270",
  "refpalette": "deceasedcraft:building_residentialc/building_residentialc_floor1_palette_270",
  "xsize": 16,
  "zsize": 16,
  "slices": [
    [
      "                ",
      "   rp      ba   ",
      "   rccc  ccca   ",
      "   rdddjjddda   ",
      "   r  l   fea   ",
      "   r       ea   ",
      "   rqn     ea   ",
      "   r o    gea   ",
      "   r  m    ea   ",
      "   r  m kihea   ",
      "   r  m    ea   ",
      "   r  m    ea   ",
      "   rdddjjddda   ",
      "   rccc  ccca   ",
      "   rp      ba   ",
      "                "
    ],
    [
      "                ",
      "    rp    ba    ",
      "    rccBBcca    ",
      "    rddjjdda    ",
      "    r     ba    ",
      "    r     bus   ",
      "    rq    be    ",
      "    r m    w    ",
      "    r m    w    ",
      "    r m   be    ",
      "    r m  ybxt   ",
      "    r m  Aba    ",
      "    rddjjdda    ",
      "    rccBBcca    ",
      "    rp    ba    ",
      "                "
    ],
    [
      "                ",
      "     rp  ba     ",
      "     rcccca     ",
      "     rdddda     ",
      "     rp  ba     ",
      "     rp  ba     ",
      "     rp  buss   ",
      "     rp  bCe    ",
      "     rp  bCe    ",
      "     rp  bxtt   ",
      "     rp  ba     ",
      "     rp  ba     ",
      "     rdddda     ",
      "     rcccca     ",
      "     rp  ba     ",
      "                "
    ],
    [
      "                ",
      "      rpba      ",
      "      rcca      ",
      "      rdda      ",
      "      r  a      ",
      "      r  a      ",
      "      r Fa      ",
      "      r  Dsss   ",
      "      r  Ettt   ",
      "      r Fa      ",
      "      r  a      ",
      "      r  a      ",
      "      rdda      ",
      "      rcca      ",
      "      rpba      ",
      "                "
    ],
    [
      "                ",
      "       ra       ",
      "       ra       ",
      "       ra       ",
      "       ra       ",
      "       ra       ",
      "       ra       ",
      "       ra       ",
      "       ra       ",
      "       ra       ",
      "       ra       ",
      "       ra       ",
      "       ra       ",
      "       ra       ",
      "       ra       ",
      "                "
    ],
    [
      "                ",
      "                ",
      "                ",
      "                ",
      "                ",
      "                ",
      "                ",
      "       ~        ",
      "       ~~       ",
      "                ",
      "                ",
      "                ",
      "                ",
      "                ",
      "                ",
      "                "
    ]
  ]
}