{
  "name": "building_residentialc_floor1_180",
  "refpalette": "deceasedcraft:building_residentialc/building_residentialc_floor1_palette_180",
  "xsize": 16,
  "zsize": 16,
  "slices": [
    [
      "                ",
      "                ",
      "                ",
      " rrrrrrrrrrrrrr ",
      " pcd     q  dcp ",
      "  cd    on  dc  ",
      "  cdmmmm   ldc  ",
      "   j        j   ",
      "   j  k     j   ",
      "  cd  i     dc  ",
      "  cd  h g  fdc  ",
      " bcdeeeeeeeedcb ",
      " aaaaaaaaaaaaaa ",
      "                ",
      "                ",
      "                "
    ],
    [
      "                ",
      "                ",
      "                ",
      "                ",
      " rrrrrrrrrrrrrr ",
      " pcd     q  dcp ",
      "  cdmmmmm   dc  ",
      "  Bj        jB  ",
      "  Bj        jB  ",
      "  cdAy      dc  ",
      " bcdbbb  bbbdcb ",
      " aaaaxewweuaaaa ",
      "     t    s     ",
      "                ",
      "                ",
      "                "
    ],
    [
      "                ",
      "                ",
      "                ",
      "                ",
      "                ",
      " rrrrrrrrrrrrrr ",
      " pcdppppppppdcp ",
      "  cd        dc  ",
      "  cd        dc  ",
      " bcdbbbbbbbbdcb ",
      " aaaaaxCCuaaaaa ",
      "      tees      ",
      "      t  s      ",
      "                ",
      "                ",
      "                "
    ],
    [
      "                ",
      "                ",
      "                ",
      "                ",
      "                ",
      "                ",
      " rrrrrrrrrrrrrr ",
      " pcd        dcp ",
      " bcd  F  F  dcb ",
      " aaaaaaEDaaaaaa ",
      "       ts       ",
      "       ts       ",
      "       ts       ",
      "                ",
      "                ",
      "                "
    ],
    [
      "                ",
      "                ",
      "                ",
      "                ",
      "                ",
      "                ",
      "                ",
      " rrrrrrrrrrrrrr ",
      " aaaaaaaaaaaaaa ",
      "                ",
      "                ",
      "                ",
      "                ",
      "                ",
      "                ",
      "                "
    ],
    [
      "                ",
      "                ",
      "                ",
      "                ",
      "                ",
      "                ",
      "                ",
      "       ~~       ",
      "       ~        ",
      "                ",
      "                ",
      "                ",
      "                ",
      "                ",
      "                ",
      "                "
    ]
  ]
}