{
  "name": "building_residentialc_ground_90",
  "refpalette": "deceasedcraft:building_residentialc/building_residentialc_ground_palette_90",
  "xsize": 16,
  "zsize": 16,
  "slices": [
    [
      "abbbbbbbbbbbbbba",
      "abbbbbbbbbbbbbba",
      "abcbbbbbbbbbbcba",
      "abcffffffffffcbb",
      "abceeeeeeeeeecba",
      "abceeeeeeeeeecbb",
      "abceeeeeeeeeecbb",
      "bbcddddddddddcba",
      "abcddddddddddcba",
      "abcddddddddddcba",
      "abcddddddddddcbb",
      "abcddddddddddcba",
      "abcddddddddddcba",
      "bbccccccccccccba",
      "bbbbbbbaabbbbbba",
      "aaaaaaaaaaabaaaa"
    ],
    [
      " gggggggggggggg ",
      "                ",
      "  hggggggggggh  ",
      "  hffffffffffh  ",
      "  ioouyBDEFKQR  ",
      "  i       F PR  ",
      "  hnnt    FJOh  ",
      "  imm        R  ",
      "  i          R  ",
      "  hlllxx    Nh  ",
      "  ikqs       R  ",
      "  i         MR  ",
      "  h pr     ILh  ",
      "  hjjjhAChjjjh  ",
      "      w         ",
      "                "
    ],
    [
      "                ",
      "                ",
      "  h          h  ",
      "  hffff00ffffh  ",
      "  S  X   2F  6  ",
      "  S       F  6  ",
      "  hU      F3Oh  ",
      "  S          S  ",
      "  S          S  ",
      "  hTTTxx     h  ",
      "  S VW      NS  ",
      "  S         5S  ",
      "  h   Y     4h  ",
      "  hSSShZ1hSSSh  ",
      "                ",
      "                "
    ],
    [
      "                ",
      "                ",
      "  h7777777777h  ",
      "  hffff00ffffh  ",
      "  h       F  h  ",
      "  h       F  h  ",
      "  h       FOOh  ",
      "  h     8    h  ",
      "  h          h  ",
      "  hTTTxx     h  ",
      "  h          h  ",
      "  h        9 h  ",
      "  h          h  ",
      "  hSSShSShSSSh  ",
      "                ",
      "                "
    ],
    [
      "                ",
      " #R          i% ",
      " #h$$$$  $$$$h% ",
      " #hffffffffffh% ",
      " #hddddddddddh% ",
      " #hddddddddddh% ",
      " #hddddddddddh% ",
      " #hddddddddddh% ",
      " #hddddddddddh% ",
      " #hddddddd   h% ",
      " #hddddddd   h% ",
      " #hddddddd9  h% ",
      " #hddddddddddh% ",
      " #hhhhhhhhhhhh% ",
      " #R          i% ",
      "                "
    ],
    [
      "                ",
      "  #R        i%  ",
      "  #$$$$  $$$$%  ",
      "  #ffffffffff%  ",
      "  #h$+}| :>. %  ",
      "  #h$){  :, !%  ",
      "  #h$((( :> `%  ",
      "  #h$ ]) :  /%  ",
      "  #h$*--  <  %  ",
      "  #h$&[- ;''?%  ",
      "  #h$&[- ;   %  ",
      "  #h$^--     %  ",
      "  #ffffffffff%  ",
      "  #$$$$  $$$$%  ",
      "  #R        i%  ",
      "                "
    ]
  ]
}