{
  "name": "building_residentialc_floor1",
  "refpalette": "deceasedcraft:building_residentialc/building_residentialc_floor1_palette",
  "xsize": 16,
  "zsize": 16,
  "slices": [
    [
      "                ",
      "                ",
      "                ",
      " aaaaaaaaaaaaaa ",
      " bcdeeeeeeeedcb ",
      "  cdf  g h  dc  ",
      "  cd     i  dc  ",
      "   j     k  j   ",
      "   j        j   ",
      "  cdl   mmmmdc  ",
      "  cd  no    dc  ",
      " pcd  q     dcp ",
      " rrrrrrrrrrrrrr ",
      "                ",
      "                ",
      "                "
    ],
    [
      "                ",
      "                ",
      "                ",
      "     s    t     ",
      " aaaauewwexaaaa ",
      " bcdbbb  bbbdcb ",
      "  cd      yAdc  ",
      "  Bj        jB  ",
      "  Bj        jB  ",
      "  cd   mmmmmdc  ",
      " pcd  q     dcp ",
      " rrrrrrrrrrrrrr ",
      "                ",
      "                ",
      "                ",
      "                "
    ],
    [
      "                ",
      "                ",
      "                ",
      "      s  t      ",
      "      seet      ",
      " aaaaauCCxaaaaa ",
      " bcdbbbbbbbbdcb ",
      "  cd        dc  ",
      "  cd        dc  ",
      " pcdppppppppdcp ",
      " rrrrrrrrrrrrrr ",
      "                ",
      "                ",
      "                ",
      "                ",
      "                "
    ],
    [
      "                ",
      "                ",
      "                ",
      "       st       ",
      "       st       ",
      "       st       ",
      " aaaaaaDEaaaaaa ",
      " bcd  F  F  dcb ",
      " pcd        dcp ",
      " rrrrrrrrrrrrrr ",
      "                ",
      "                ",
      "                ",
      "                ",
      "                ",
      "                "
    ],
    [
      "                ",
      "                ",
      "                ",
      "                ",
      "                ",
      "                ",
      "                ",
      " aaaaaaaaaaaaaa ",
      " rrrrrrrrrrrrrr ",
      "                ",
      "                ",
      "                ",
      "                ",
      "                ",
      "                ",
      "                "
    ],
    [
      "                ",
      "                ",
      "                ",
      "                ",
      "                ",
      "                ",
      "                ",
      "        ~       ",
      "       ~~       ",
      "                ",
      "                ",
      "                ",
      "                ",
      "                ",
      "                ",
      "                "
    ]
  ]
}