{
  "name": "building_hoteld_floor2",
  "refpalette": "deceasedcraft:building_hoteld/building_hoteld_floor2_palette",
  "xsize": 16,
  "zsize": 16,
  "slices": [
    [
      "                ",
      " a=====b   c==a ",
      " =dddddeeeeedd= ",
      " =dffggggggggd= ",
      " =dffgggggggdeh ",
      " =dffggggggg e  ",
      " =dffggggggg e  ",
      " heggggggggg e  ",
      "  eggggggggg e  ",
      "  eggggggggg e  ",
      " iegfggggggg e  ",
      " =dffggggdjddei ",
      " =dffggggjjk  = ",
      " =dddeeeejl   = ",
      " a===b  c=====a ",
      "                "
    ],
    [
      "                ",
      " a=====b   c==a ",
      " =dddddeeeeedd= ",
      " =dmnopqr   sd= ",
      " =dt uwwwxdydeh ",
      " =d  oAAwd  Be  ",
      " =dCDoEEFd  Be  ",
      " heddddddd  Be  ",
      "  eI JpKLd  Be  ",
      "  ex     M  Be  ",
      " iedNowwwd  Be  ",
      " =d  oAwAdOddei ",
      " =dPQoEFEo Rk = ",
      " =dddeeeeo    = ",
      " a===b  c=====a ",
      "                "
    ],
    [
      "                ",
      " a=====b   c==a ",
      " =dddddeeeeedd= ",
      " =d  oST    Ud= ",
      " =d  V    dWdeh ",
      " =dXYo   d   e  ",
      " =d  o  Zd   e  ",
      " heddddddd   e  ",
      "  e01 !23d   e  ",
      "  e      4   e  ",
      " ied5o   d   e  ",
      " =dX o   d6ddei ",
      " =d  o 7 o  Rk= ",
      " =dddeeeeo   8= ",
      " a===b  c=====a ",
      "                "
    ],
    [
      "                ",
      " a=====b   c==a ",
      " =dddddeeeeedd= ",
      " =d  o      9d= ",
      " =d# o    d$deh ",
      " =d% o   d   e  ",
      " =d  o   d^  e  ",
      " heddddddd   e  ",
      "  e      d   e  ",
      "  e      &   e  ",
      " ied$o   d   e  ",
      " =d% o   d*ddei ",
      " =d (o   o   )= ",
      " =dddeeeeo  +j= ",
      " a===b  c=====a ",
      "                "
    ],
    [
      "                ",
      " a=====b   c==a ",
      " =dddddeeeeedd= ",
      " =d  o       d= ",
      " =d  o    dddeh ",
      " =d  o   d   e  ",
      " =d  o   d   e  ",
      " heddddddd   e  ",
      "  e      d   e  ",
      "  e      d   e  ",
      " ieddo   d   e  ",
      " =d  o   ddddei ",
      " =d  o   o    = ",
      " =dddeeeeo +l = ",
      " a===b  c=====a ",
      "                "
    ],
    [
      "                ",
      " a=====b   c==a ",
      " =dddddeeeeedd= ",
      " =d----------d= ",
      " =d-------dddeh ",
      " =d------d   e  ",
      " =d------d [ e  ",
      " heddddddd   e  ",
      "  e------d   e  ",
      "  e------d [ e  ",
      " iedd----d   e  ",
      " =d------ddddei ",
      " =d------o    = ",
      " =dddeeeeo+l  = ",
      " a===b  c=====a ",
      "                "
    ]
  ]
}