{
  "name": "building_hoteld_floor2_180",
  "refpalette": "deceasedcraft:building_hoteld/building_hoteld_floor2_palette_180",
  "xsize": 16,
  "zsize": 16,
  "slices": [
    [
      "                ",
      " a=====c  b===a ",
      " =   ljeeeeddd= ",
      " =  kjjggggffd= ",
      " ieddjdggggffd= ",
      "  e gggggggfgei ",
      "  e ggggggggge  ",
      "  e ggggggggge  ",
      "  e gggggggggeh ",
      "  e gggggggffd= ",
      "  e gggggggffd= ",
      " hedgggggggffd= ",
      " =dggggggggffd= ",
      " =ddeeeeeddddd= ",
      " a==c   b=====a ",
      "                "
    ],
    [
      "                ",
      " a=====c  b===a ",
      " =    oeeeeddd= ",
      " = kR oEFEoQPd= ",
      " ieddOdAwAo  d= ",
      "  eB  dwwwoNdei ",
      "  eB  M     xe  ",
      "  eB  dLKpJ Ie  ",
      "  eB  dddddddeh ",
      "  eB  dFEEoDCd= ",
      "  eB  dwAAo  d= ",
      " hedydxwwwu td= ",
      " =ds   rqponmd= ",
      " =ddeeeeeddddd= ",
      " a==c   b=====a ",
      "                "
    ],
    [
      "                ",
      " a=====c  b===a ",
      " =8   oeeeeddd= ",
      " =kR  o 7 o  d= ",
      " iedd6d   o Xd= ",
      "  e   d   o5dei ",
      "  e   4      e  ",
      "  e   d32! 10e  ",
      "  e   dddddddeh ",
      "  e   dZ  o  d= ",
      "  e   d   oYXd= ",
      " hedWd    V  d= ",
      " =dU    TSo  d= ",
      " =ddeeeeeddddd= ",
      " a==c   b=====a ",
      "                "
    ],
    [
      "                ",
      " a=====c  b===a ",
      " =j+  oeeeeddd= ",
      " =)   o   o( d= ",
      " iedd*d   o %d= ",
      "  e   d   o$dei ",
      "  e   &      e  ",
      "  e   d      e  ",
      "  e   dddddddeh ",
      "  e  ^d   o  d= ",
      "  e   d   o %d= ",
      " hed$d    o #d= ",
      " =d9      o  d= ",
      " =ddeeeeeddddd= ",
      " a==c   b=====a ",
      "                "
    ],
    [
      "                ",
      " a=====c  b===a ",
      " = l+ oeeeeddd= ",
      " =    o   o  d= ",
      " iedddd   o  d= ",
      "  e   d   oddei ",
      "  e   d      e  ",
      "  e   d      e  ",
      "  e   dddddddeh ",
      "  e   d   o  d= ",
      "  e   d   o  d= ",
      " heddd    o  d= ",
      " =d       o  d= ",
      " =ddeeeeeddddd= ",
      " a==c   b=====a ",
      "                "
    ],
    [
      "                ",
      " a=====c  b===a ",
      " =  l+oeeeeddd= ",
      " =    o------d= ",
      " iedddd------d= ",
      "  e   d----ddei ",
      "  e [ d------e  ",
      "  e   d------e  ",
      "  e   dddddddeh ",
      "  e [ d------d= ",
      "  e   d------d= ",
      " heddd-------d= ",
      " =d----------d= ",
      " =ddeeeeeddddd= ",
      " a==c   b=====a ",
      "                "
    ]
  ]
}