{
  "name": "building_hoteld_floor1",
  "refpalette": "deceasedcraft:building_hoteld/building_hoteld_floor1_palette",
  "xsize": 16,
  "zsize": 16,
  "slices": [
    [
      "                ",
      " a=====b   c==a ",
      " =dddddeeeeedd= ",
      " =dffggggggggd= ",
      " =dffgggggggdeh ",
      " =dffggggggg e  ",
      " =dffggggggg e  ",
      " heggggggggg e  ",
      "  eggggggggg e  ",
      "  eggggggggg e  ",
      " iegfggggggg e  ",
      " =dffggggjjddei ",
      " =dffggggjjk  = ",
      " =dddeeeejl   = ",
      " a===b  c=====a ",
      "                "
    ],
    [
      "                ",
      " a=====b   c==a ",
      " =dddddeeeeedd= ",
      " =dmnopqr   sd= ",
      " =dt uwwwxdydeh ",
      " =d  oAAwd  Be  ",
      " =dCDoEEFd  Be  ",
      " heddddddd  Be  ",
      "  eI JpKLd  Be  ",
      "  ex     M  Be  ",
      " iedNowwwd  Be  ",
      " =d OoAwAdPddei ",
      " =dQRoEFEo Sk = ",
      " =dddeeeeo    = ",
      " a===b  c=====a ",
      "                "
    ],
    [
      "                ",
      " a=====b   c==a ",
      " =dddddeeeeedd= ",
      " =d  oTU    Vd= ",
      " =d  W    dXdeh ",
      " =dYZo   d   e  ",
      " =d  o  0d   e  ",
      " heddddddd   e  ",
      "  e12  34d   e  ",
      "  e      5   e  ",
      " ied6o   d   e  ",
      " =dY o   d7ddei ",
      " =d  o 0 o  Sk= ",
      " =dddeeeeo   8= ",
      " a===b  c=====a ",
      "                "
    ],
    [
      "                ",
      " a=====b   c==a ",
      " =dddddeeeeedd= ",
      " =d  o      9d= ",
      " =d# o    d$deh ",
      " =d% o   d   e  ",
      " =d  o   d^  e  ",
      " heddddddd   e  ",
      "  e      d   e  ",
      "  e      &   e  ",
      " ied$o   d   e  ",
      " =d% o   d*ddei ",
      " =d (o   o   )= ",
      " =dddeeeeo  +j= ",
      " a===b  c=====a ",
      "                "
    ],
    [
      "                ",
      " a=====b   c==a ",
      " =dddddeeeeedd= ",
      " =d  o       d= ",
      " =d  o    dddeh ",
      " =d  o   d   e  ",
      " =d  o   d   e  ",
      " heddddddd   e  ",
      "  e      d   e  ",
      "  e      d   e  ",
      " ieddo   d   e  ",
      " =d  o   ddddei ",
      " =d !o   o    = ",
      " =dddeeeeo +l = ",
      " a===b  c=====a ",
      "                "
    ],
    [
      "                ",
      " a=====b   c==a ",
      " =dddddeeeeedd= ",
      " =d---------!d= ",
      " =d-------dddeh ",
      " =d------d   e  ",
      " =d------d [ e  ",
      " heddddddd   e  ",
      "  e------d   e  ",
      "  e------d [ e  ",
      " iedd----d   e  ",
      " =d------ddddei ",
      " =d------o    = ",
      " =dddeeeeo+l  = ",
      " a===b  c=====a ",
      "                "
    ]
  ]
}