{
  "name": "building_hoteld_ground_90",
  "refpalette": "deceasedcraft:building_hoteld/building_hoteld_ground_palette_90",
  "xsize": 16,
  "zsize": 16,
  "slices": [
    [
      "aaaaaaaaaaaaaaaa",
      "ab==aaaaaaaa==ba",
      "a=dddddddddd  =a",
      "a=dfdeeddddd  =a",
      "acdeeeedddddh =a",
      "acdeeeedddddgi=a",
      "acdeeeedddddgg=a",
      "acdeeeedddddddca",
      "acdeeeedddddddca",
      "a=deeeedddddddca",
      "a=deeeedddddddca",
      "a=deeeeddddddd=a",
      "a=deeeeddddddd=a",
      "a=dddddddddddd=a",
      "ab=====cccc===ba",
      "aaaaaaaaaaaaaaaa"
    ],
    [
      "                ",
      " b==t y  y I==b ",
      " =llmmgCEgmm  = ",
      " =lrlqx  x lh = ",
      " kmqqqq    KL = ",
      "  mqqqq    K  = ",
      "  mqqqq    K M= ",
      "  mqqwq      mk ",
      " jmqqqq      m  ",
      " =lpquq      m  ",
      " =loquq  F F mj ",
      " =loqqqBDDDDDl= ",
      " =lnsqxA  J  l= ",
      " =lllllmmmmlll= ",
      " b=====t  I===b ",
      "                "
    ],
    [
      "                ",
      " b==t y  y I==b ",
      " =llmmgPQgmmgS= ",
      " =l l O  O lL = ",
      " km        R  = ",
      "  m        R  = ",
      "  m        R M= ",
      "  m          mk ",
      " jm          m  ",
      " =l          m  ",
      " =l          mj ",
      " =l          l= ",
      " =l   N      l= ",
      " =lllllmmmmlll= ",
      " b=====t  I===b ",
      "                "
    ],
    [
      "                ",
      " b==t yyyy I==b ",
      " =llmmggggmmVg= ",
      " =l l      l W= ",
      " km        R  = ",
      "  m        R  = ",
      "  m        R M= ",
      "  m          mk ",
      " jm          m  ",
      " =l          m  ",
      " =lU         mj ",
      " =lT         l= ",
      " =l          l= ",
      " =lllllmmmmlll= ",
      " b=====t  I===b ",
      "                "
    ],
    [
      "                ",
      " b==t      I==b ",
      " =llmmmmmmmm  = ",
      " =l l      l i= ",
      " km        X W= ",
      "  m        X  = ",
      "  m        X M= ",
      "  m          mk ",
      " jm          m  ",
      " =l          m  ",
      " =l          mj ",
      " =l          l= ",
      " =l          l= ",
      " =lllllmmmmlll= ",
      " b=====t  I===b ",
      "                "
    ],
    [
      "                ",
      " b==t      I==b ",
      " =llmmmmmmmm  = ",
      " =lZl      l  = ",
      " kmYYYYYYYYl i= ",
      "  mYYYYYYYYl W= ",
      "  mYYYYYYYYlll= ",
      "  mYYYYYYYYYYmk ",
      " jmYYYYYYYYYYm  ",
      " =lYYYYYYYYYYm  ",
      " =lYYYYYYYYYYmj ",
      " =lYYYYYYYYYYl= ",
      " =lYYYYYYYYYYl= ",
      " =lllllmmmmlll= ",
      " b=====t  I===b ",
      "                "
    ]
  ]
}