{
  "name": "building_hoteld_ground_270",
  "refpalette": "deceasedcraft:building_hoteld/building_hoteld_ground_palette_270",
  "xsize": 16,
  "zsize": 16,
  "slices": [
    [
      "aaaaaaaaaaaaaaaa",
      "ab===cccc=====ba",
      "a=dddddddddddd=a",
      "a=dddddddeeeed=a",
      "a=dddddddeeeed=a",
      "acdddddddeeeed=a",
      "acdddddddeeeed=a",
      "acdddddddeeeedca",
      "acdddddddeeeedca",
      "a=ggdddddeeeedca",
      "a=igdddddeeeedca",
      "a= hdddddeeeedca",
      "a=  dddddeedfd=a",
      "a=  dddddddddd=a",
      "ab==aaaaaaaa==ba",
      "aaaaaaaaaaaaaaaa"
    ],
    [
      "                ",
      " b===I  t=====b ",
      " =lllmmmmlllll= ",
      " =l  J  Axqsnl= ",
      " =lDDDDDBqqqol= ",
      " jm F F  quqol= ",
      "  m      quqpl= ",
      "  m      qqqqmj ",
      " km      qwqqm  ",
      " =M K    qqqqm  ",
      " =  K    qqqqm  ",
      " = LK    qqqqmk ",
      " = hl x  xqlrl= ",
      " =  mmgECgmmll= ",
      " b==I y  y t==b ",
      "                "
    ],
    [
      "                ",
      " b===I  t=====b ",
      " =lllmmmmlllll= ",
      " =l      N   l= ",
      " =l          l= ",
      " jm          l= ",
      "  m          l= ",
      "  m          mj ",
      " km          m  ",
      " =M R        m  ",
      " =  R        m  ",
      " =  R        mk ",
      " = Ll O  O l l= ",
      " =SgmmgQPgmmll= ",
      " b==I y  y t==b ",
      "                "
    ],
    [
      "                ",
      " b===I  t=====b ",
      " =lllmmmmlllll= ",
      " =l          l= ",
      " =l         Tl= ",
      " jm         Ul= ",
      "  m          l= ",
      "  m          mj ",
      " km          m  ",
      " =M R        m  ",
      " =  R        m  ",
      " =  R        mk ",
      " =W l      l l= ",
      " =gVmmggggmmll= ",
      " b==I yyyy t==b ",
      "                "
    ],
    [
      "                ",
      " b===I  t=====b ",
      " =lllmmmmlllll= ",
      " =l          l= ",
      " =l          l= ",
      " jm          l= ",
      "  m          l= ",
      "  m          mj ",
      " km          m  ",
      " =M X        m  ",
      " =  X        m  ",
      " =W X        mk ",
      " =i l      l l= ",
      " =  mmmmmmmmll= ",
      " b==I      t==b ",
      "                "
    ],
    [
      "                ",
      " b===I  t=====b ",
      " =lllmmmmlllll= ",
      " =lYYYYYYYYYYl= ",
      " =lYYYYYYYYYYl= ",
      " jmYYYYYYYYYYl= ",
      "  mYYYYYYYYYYl= ",
      "  mYYYYYYYYYYmj ",
      " kmYYYYYYYYYYm  ",
      " =lllYYYYYYYYm  ",
      " =W lYYYYYYYYm  ",
      " =i lYYYYYYYYmk ",
      " =  l      lZl= ",
      " =  mmmmmmmmll= ",
      " b==I      t==b ",
      "                "
    ]
  ]
}