{
  "name": "building_hoteld_top_90",
  "refpalette": "deceasedcraft:building_hoteld/building_hoteld_top_palette_90",
  "xsize": 16,
  "zsize": 16,
  "slices": [
    [
      "                ",
      " a==g      h==a ",
      " =eeeeeeeeee  = ",
      " =edd      d  = ",
      " cefffffffffk = ",
      "  efffffffffjl= ",
      "  efffffffffjj= ",
      "  effffffffffec ",
      " beffffffffffe  ",
      " =dffffffffffe  ",
      " =dffffffffffeb ",
      " =dfffffffiiid= ",
      " =dffffffffiii= ",
      " =dddddeeeedii= ",
      " a=====g  h===a ",
      "                "
    ],
    [
      "                ",
      "           h==a ",
      "  eeeeeeeeee  = ",
      "  edduuuuuudk = ",
      "  enn      EJ = ",
      "  e  t  t  E  = ",
      "  e psypsy E D= ",
      "  e  r  r    ec ",
      " be         Ie  ",
      " =d   rA    Ie  ",
      " =d  qxq  DDDeb ",
      " =d m w   C  d= ",
      " =dmommm Bd  L= ",
      " =dddddeeeedFK= ",
      " a=====g  h===a ",
      "                "
    ],
    [
      "                ",
      "           h==a ",
      "  eeeeeeeeeek1= ",
      "  eE       dJ = ",
      "  e        Y  = ",
      "  e PSUPSU Y  = ",
      "  e  R  R  Y D= ",
      "  e          ec ",
      " be          e  ",
      " =dO         e  ",
      " =dN QTQ  DDDeb ",
      " =dM  w   VX0d= ",
      " =d  m    dW  = ",
      " =dddddeeeedZK= ",
      " a=====g  h===a ",
      "                "
    ],
    [
      "                ",
      "           h==a ",
      "  eeeeeeeeee5j= ",
      "  eY       d 8= ",
      "  e        Y  = ",
      "  e        Y  = ",
      "  e        Y D= ",
      "  e          ec ",
      " be          e  ",
      " =d          e  ",
      " =d       DDDeb ",
      " =d       2 4d= ",
      " =d       d3 7= ",
      " =dddddeeeedA6= ",
      " a=====g  h===a ",
      "                "
    ],
    [
      "                ",
      "           h==a ",
      "  eeeeeeeeee  = ",
      "  eY       d l= ",
      "  e        Y 8= ",
      "  e        Y  = ",
      "  e        Y D= ",
      "  e          ec ",
      " be          e  ",
      " =d          e  ",
      " =d       DDDeb ",
      " =d       d  d= ",
      " =d       d  d= ",
      " =dddddeeeeddd= ",
      " a=====g  h===a ",
      "                "
    ],
    [
      "                ",
      "           h==a ",
      "  eeeeeeeeee  = ",
      "  eY       d  = ",
      "  e        Y l= ",
      "  e        Y 8= ",
      "  e        Y D= ",
      "  e          ec ",
      " be          e  ",
      " =d          e  ",
      " =d       DDDeb ",
      " =d       d99d= ",
      " =d       d99d= ",
      " =dddddeeeeddd= ",
      " a=====g  h===a ",
      "                "
    ],
    [
      "                ",
      "           h==a ",
      "  eeeeeeeeee  = ",
      "  eY       d  = ",
      "  e        Yk = ",
      "  e        Yjl= ",
      "  e        Yjj= ",
      "  e     DDdddec ",
      " be DDddddddde  ",
      " =ddddddddddde  ",
      " =dddddddddddeb ",
      " =ddddddddddde= ",
      " =ddddddddddde= ",
      " =dddddeeeeeee= ",
      " a=====g  h===a ",
      "                "
    ],
    [
      "                ",
      "           h==a ",
      "  eeeeeeeeee  = ",
      "  eY       dk = ",
      "  e        YJ = ",
      "  e        Y  = ",
      "  e        Y D= ",
      "  e     uu&# ec ",
      " be uu&#! ^  e  ",
      " =d#^ ^ % %  e  ",
      " =d % % % % Ie  ",
      " =d % %     Ie  ",
      " =dE$$$     Ee  ",
      " =dddddeeeeeee  ",
      " a=====g        ",
      "                "
    ],
    [
      "                ",
      "           h==a ",
      "  eeeeeeeeeek1= ",
      "  eY       dJ = ",
      "  e        Y  = ",
      "  e        Y  = ",
      "  e        Y D= ",
      "  e          ec ",
      " be          e  ",
      " =dO         e  ",
      " =dN         e  ",
      " =dM         e  ",
      " =dY        Ye  ",
      " =dddddeeeeeee  ",
      " a=====g        ",
      "                "
    ],
    [
      "                ",
      "           h==a ",
      "  eeeeeeeeee5j= ",
      "  eY       d 8= ",
      "  e        Y  = ",
      "  e        Y  = ",
      "  e        Y D= ",
      "  e          ec ",
      " be          e  ",
      " =e          e  ",
      " =e          e  ",
      " =e          e  ",
      " =eY        Ye  ",
      " =eeeeeeeeeeee  ",
      " a=====g        ",
      "                "
    ],
    [
      "                ",
      "           h==a ",
      "  eeeeeeeeee  = ",
      "  e*       d l= ",
      "  e        * 8= ",
      "  e        Y  = ",
      "  e        Y D= ",
      "  e          ec ",
      "  e          e  ",
      "  e          e  ",
      "  e          e  ",
      "  e          e  ",
      "  e*        *e  ",
      "  eeeeeeeeeeee  ",
      "                ",
      "                "
    ],
    [
      "                ",
      "           h==a ",
      "  eeeeeeeeee  = ",
      "  e((((((((d  = ",
      "  e()))))))d l= ",
      "  e()))))))d 8= ",
      "  e()))))))dDD= ",
      "  e())))))))(ec ",
      "  e())))))))(e  ",
      "  e())))))))(e  ",
      "  e())))))))(e  ",
      "  e())))))))(e  ",
      "  e((((((((((e  ",
      "  eeeeeeeeeeee  ",
      "                ",
      "                "
    ],
    [
      "                ",
      "           h==a ",
      "  eeeeeeeeee  = ",
      "  eddddddddd, = ",
      "  ed]}:ddddd> = ",
      "  ed--;ddddd<l= ",
      "  ed[-;dddddjj= ",
      "  ed[-;ddddddec ",
      "  ed[-;dddddde  ",
      "  ed[-;dddddde  ",
      "  ed--;dddddde  ",
      "  ed+{|dddd'de  ",
      "  edddddddddde  ",
      "  eeeeeeeeeeee  ",
      "                ",
      "                "
    ],
    [
      "                ",
      "           h==a ",
      "  eeeeeeeeee  = ",
      "  eE    `\u0374\u0376\u0377Y = ",
      "  e     /\u0374\u0376\u0377  = ",
      "  e     /\u0374\u0376\u0377\u037b = ",
      "  e     /\u0375    = ",
      "  e     ?\u0374\u0374 \u0374ec ",
      "  e      \u0373\u0373  e  ",
      "  e      \u0372\u0372\u0372 e  ",
      "  e     .\u0371\u0371\u0371\u037ae  ",
      "  e     .\u0371\u0371!\u037ae  ",
      "  eE     \u0370\u0370\u0370Ee  ",
      "  eeeeeeeeeeee  ",
      "                ",
      "                "
    ],
    [
      "                ",
      "           h==a ",
      "  eeeeeeeeee  = ",
      "  eY    `\u0374  Y = ",
      "  e     /\u0374    = ",
      "  e     /\u0374    = ",
      "  e     /\u037d    = ",
      "  e     ?\u0374\u0374 \u0374ec ",
      "  e      \u037c\u037c  e  ",
      "  e          e  ",
      "  e          e  ",
      "  e          e  ",
      "  eY        Ye  ",
      "  eeeeeeeeeeee  ",
      "                ",
      "                "
    ],
    [
      "                ",
      "           h==a ",
      "  eeeeeeeeeeee= ",
      "  eY    \u037e\u0374  Ye= ",
      "  e     \u037e\u0374   e= ",
      "  e     \u037e\u0374   e= ",
      "  e     \u037e\u0374   e= ",
      "  e     \u037e\u0374\u0374\u037f\u0374ec ",
      "  e      \u037c\u037c  e  ",
      "  e          e  ",
      "  e          e  ",
      "  e          e  ",
      "  eY        Ye  ",
      "  eeeeeeeeeeee  ",
      "                ",
      "                "
    ],
    [
      "                ",
      "                ",
      "  eeeeeeeeeeee  ",
      "  eY        Ye  ",
      "  e          e  ",
      "  e          e  ",
      "  e          e  ",
      "  e          e  ",
      "  e    \u0384     e  ",
      "  e          e  ",
      "  e          e  ",
      "  e          e  ",
      "  eY        Ye  ",
      "  eeeeeeeeeeee  ",
      "                ",
      "                "
    ],
    [
      "                ",
      "                ",
      "  eeeeeeeeeeee  ",
      "  eY        Ye  ",
      "  e          e  ",
      "  e          e  ",
      "  e          e  ",
      "  e          e  ",
      "  e    \u0385     e  ",
      "  e          e  ",
      "  e          e  ",
      "  e          e  ",
      "  eY        Ye  ",
      "  eeeeeeeeeeee  ",
      "                ",
      "                "
    ],
    [
      "                ",
      "                ",
      "  eeeeeeeeeeee  ",
      "  eY        Ye  ",
      "  e          e  ",
      "  e          e  ",
      "  e          e  ",
      "  e     \u0384    e  ",
      "  e    \u0385     e  ",
      "  e          e  ",
      "  e          e  ",
      "  e          e  ",
      "  eY        Ye  ",
      "  eeeeeeeeeeee  ",
      "                ",
      "                "
    ],
    [
      "                ",
      "                ",
      "  eeeeeeeeeeee  ",
      "  eY        Ye  ",
      "  e          e  ",
      "  e          e  ",
      "  e          e  ",
      "  e    \u0384\u0385    e  ",
      "  e    \u0385     e  ",
      "  e          e  ",
      "  e          e  ",
      "  e          e  ",
      "  eY        Ye  ",
      "  eeeeeeeeeeee  ",
      "                ",
      "                "
    ],
    [
      "                ",
      "                ",
      "  eeeeeeeeeeee  ",
      "  eY        Ye  ",
      "  e          e  ",
      "  e          e  ",
      "  e   \u0386\u0386\u0386\u0386   e  ",
      "  e   \u0386\u0385\u0385\u0386   e  ",
      "  e   \u0386\u0385\u0384\u0386   e  ",
      "  e   \u0386\u0386\u0386\u0386   e  ",
      "  e          e  ",
      "  e          e  ",
      "  eY        Ye  ",
      "  eeeeeeeeeeee  ",
      "                ",
      "                "
    ],
    [
      "                ",
      "                ",
      "  eeeeeeeeeeee  ",
      "  e*        *e  ",
      "  e          e  ",
      "  e  \u0386\u0386\u0386\u0386\u0386\u0386  e  ",
      "  e  \u0386\u0386\u0386\u0386\u0386\u0386  e  ",
      "  e  \u0386\u0386\u0387\u0387\u0386\u0386  e  ",
      "  e  \u0386\u0386\u0387\u0387\u0386\u0386  e  ",
      "  e  \u0386\u0386\u0386\u0386\u0386\u0386  e  ",
      "  e  \u0386\u0386\u0386\u0386\u0386\u0386  e  ",
      "  e          e  ",
      "  e*        *e  ",
      "  eeeeeeeeeeee  ",
      "                ",
      "                "
    ],
    [
      "                ",
      "                ",
      "  eeeeeeeeeeee  ",
      "  e\u0388\u0388\u0388\u0388\u0388\u0388\u0388\u0388\u0388\u0388e  ",
      "  e\u0388eeeeeeee\u0388e  ",
      "  e\u0388e\u0388\u0388\u0388\u0388\u0388\u0388e\u0388e  ",
      "  e\u0388e\u0388\u0389\u0389\u0389\u0389\u0388e\u0388e  ",
      "  e\u0388e\u0388\u0389\u038a\u038a\u0389\u0388e\u0388e  ",
      "  e\u0388e\u0388\u0389\u038a\u038a\u0389\u0388e\u0388e  ",
      "  e\u0388e\u0388\u0389\u0389\u0389\u0389\u0388e\u0388e  ",
      "  e\u0388e\u0388\u0388\u0388\u0388\u0388\u0388e\u0388e  ",
      "  e\u0388eeeeeeee\u0388e  ",
      "  e\u0388\u0388\u0388\u0388\u0388\u0388\u0388\u0388\u0388\u0388e  ",
      "  eeeeeeeeeeee  ",
      "                ",
      "                "
    ],
    [
      "                ",
      "                ",
      "                ",
      "                ",
      "                ",
      "                ",
      "      \u038c\u038c\u038c\u038c      ",
      "      \u038c\u038e\u038e\u038c      ",
      "      \u038c\u038e\u038e\u038c      ",
      "      \u038c\u038c\u038c\u038c      ",
      "                ",
      "                ",
      "                ",
      "                ",
      "                ",
      "                "
    ]
  ]
}