{
  "name": "building_hoteld_floor1_180",
  "refpalette": "deceasedcraft:building_hoteld/building_hoteld_floor1_palette_180",
  "xsize": 16,
  "zsize": 16,
  "slices": [
    [
      "                ",
      " a=====c  b===a ",
      " =   ljeeeeddd= ",
      " =  kjjggggffd= ",
      " ieddjjggggffd= ",
      "  e gggggggfgei ",
      "  e ggggggggge  ",
      "  e ggggggggge  ",
      "  e gggggggggeh ",
      "  e gggggggffd= ",
      "  e gggggggffd= ",
      " hedgggggggffd= ",
      " =dggggggggffd= ",
      " =ddeeeeeddddd= ",
      " a==c   b=====a ",
      "                "
    ],
    [
      "                ",
      " a=====c  b===a ",
      " =    oeeeeddd= ",
      " = kS oEFEoRQd= ",
      " ieddPdAwAoO d= ",
      "  eB  dwwwoNdei ",
      "  eB  M     xe  ",
      "  eB  dLKpJ Ie  ",
      "  eB  dddddddeh ",
      "  eB  dFEEoDCd= ",
      "  eB  dwAAo  d= ",
      " hedydxwwwu td= ",
      " =ds   rqponmd= ",
      " =ddeeeeeddddd= ",
      " a==c   b=====a ",
      "                "
    ],
    [
      "                ",
      " a=====c  b===a ",
      " =8   oeeeeddd= ",
      " =kS  o 0 o  d= ",
      " iedd7d   o Yd= ",
      "  e   d   o6dei ",
      "  e   5      e  ",
      "  e   d43  21e  ",
      "  e   dddddddeh ",
      "  e   d0  o  d= ",
      "  e   d   oZYd= ",
      " hedXd    W  d= ",
      " =dV    UTo  d= ",
      " =ddeeeeeddddd= ",
      " a==c   b=====a ",
      "                "
    ],
    [
      "                ",
      " a=====c  b===a ",
      " =j+  oeeeeddd= ",
      " =)   o   o( d= ",
      " iedd*d   o %d= ",
      "  e   d   o$dei ",
      "  e   &      e  ",
      "  e   d      e  ",
      "  e   dddddddeh ",
      "  e  ^d   o  d= ",
      "  e   d   o %d= ",
      " hed$d    o #d= ",
      " =d9      o  d= ",
      " =ddeeeeeddddd= ",
      " a==c   b=====a ",
      "                "
    ],
    [
      "                ",
      " a=====c  b===a ",
      " = l+ oeeeeddd= ",
      " =    o   o! d= ",
      " iedddd   o  d= ",
      "  e   d   oddei ",
      "  e   d      e  ",
      "  e   d      e  ",
      "  e   dddddddeh ",
      "  e   d   o  d= ",
      "  e   d   o  d= ",
      " heddd    o  d= ",
      " =d       o  d= ",
      " =ddeeeeeddddd= ",
      " a==c   b=====a ",
      "                "
    ],
    [
      "                ",
      " a=====c  b===a ",
      " =  l+oeeeeddd= ",
      " =    o------d= ",
      " iedddd------d= ",
      "  e   d----ddei ",
      "  e [ d------e  ",
      "  e   d------e  ",
      "  e   dddddddeh ",
      "  e [ d------d= ",
      "  e   d------d= ",
      " heddd-------d= ",
      " =d!---------d= ",
      " =ddeeeeeddddd= ",
      " a==c   b=====a ",
      "                "
    ]
  ]
}