{
  "name": "building_hoteld_base1_90",
  "refpalette": "deceasedcraft:building_hoteld/building_hoteld_base1_palette_90",
  "xsize": 16,
  "zsize": 16,
  "slices": [
    [
      "vvvvvvvvvvvvvvvv",
      "v===cdfg h k===v",
      "v=         imm=v",
      "v=         j!nov",
      "va         imm=v",
      "va         ilm=v",
      "va         i m=v",
      "va            av",
      "va            av",
      "v=            av",
      "v=            av",
      "v=            =v",
      "v=  b e       =v",
      "v=            =v",
      "v======aaaa====v",
      "vvvvvvvvvvvvvvvv"
    ],
    [
      "vvvvvvvvvvvvvvvv",
      "v===dcpqqqqr===v",
      "v=         imm=v",
      "v=         imm=v",
      "va         ilm=v",
      "va         i m=v",
      "va         i m=v",
      "va            av",
      "va            av",
      "v=            av",
      "v=            av",
      "v=            =v",
      "v=            =v",
      "v=           !=v",
      "v======aaaa====v",
      "vvvvvvvvvvvvvvvv"
    ],
    [
      "vvvvvvvvvvvvvvvv",
      "v===tuwxwxwx===v",
      "v=s        imm=v",
      "v=         ilm=v",
      "va         i m=v",
      "v          i m=v",
      "va         i m=v",
      "va            av",
      "va            av",
      "v=            av",
      "v=            av",
      "v=            =v",
      "v=            =v",
      "v=           y=v",
      "v======a aa====v",
      "vvvvvvvvvvvvvvvv"
    ],
    [
      "vvvvvvvvvvvvvvvv",
      "v===        ===v",
      "v=y        iAm=v",
      "v=         i m=v",
      "va         i m=v",
      "v          i m=v",
      "v          i m=v",
      "va            av",
      "v             av",
      "v=             v",
      "v=            av",
      "v=            =v",
      "v=            =v",
      "v=s          y=v",
      "v======  a ====v",
      "vvvvvvvvvvvvvvvv"
    ],
    [
      "vvvvvvvvvvvvvvvv",
      "v===        ===v",
      "v=y        E  =v",
      "v=         E F=v",
      "v          E m=v",
      "v          E m=v",
      "v     BBBB E m=v",
      "v     BCDB     v",
      "v     BCDB     v",
      "v=    BBBB     v",
      "v=             v",
      "v=            =v",
      "v=            =v",
      "v=y          y=v",
      "v======    ====v",
      "vvvvvvvvvvvvvvvv"
    ],
    [
      "vvvvvvvvvvvvvvvv",
      "v===MNPMNPMN===v",
      "v=LLLLLLLLLL  =v",
      "v=LLLLLLLLLL  =v",
      "vJLLLLLLLLLL F=v",
      "vILLLLLLLLLLSm=v",
      "vKLLLLLOOLLLmm=v",
      "vJLLLLOQROLLLLJv",
      "vILLLLOQQOLLLLIv",
      "v=LLLLLOOLLLLLJv",
      "v=LLLLLLLLLLLLIv",
      "v=LLLLLLLLLLLL=v",
      "v=LLLLLLLLLLLL=v",
      "v=LLLLLLLLLLLL=v",
      "v======MNMN====v",
      "vvvvvvvvvvvvvvvv"
    ]
  ]
}