{
  "name": "building_hoteld_base2",
  "refpalette": "deceasedcraft:building_hoteld/building_hoteld_base2_palette",
  "xsize": 16,
  "zsize": 16,
  "slices": [
    [
      "vvvvvvvvvvvvvvvv",
      "vaaaaaaaaaaaaaav",
      "vaaaaaaaaaaaaaav",
      "vaaaaaaaaaaaaaav",
      "vaaaaaaaaaaaaaav",
      "vaaaaaaaaaaaaaav",
      "vaaaaaaaaaaaaaav",
      "vaaaaaaaaaaaaaav",
      "vaaaaaaaaaaaaaav",
      "vaaaaaaaaaaaaaav",
      "vaaaaaaaaaaaaaav",
      "vaaaaaaaaaaaaaav",
      "vaaaaaaaaaaaaaav",
      "vaaaaaaaaaaaaaav",
      "vaaaaaaaaaaaaaav",
      "vvvvvvvvvvvvvvvv"
    ],
    [
      "vvvvvvvvvvvvvvvv",
      "v======aaaaa===v",
      "v=aaaaaaaaaaaa=v",
      "v=aaaaaaaaaaaa=v",
      "v=aaaaaaaaaaaaav",
      "v=aaabbbbbcaaaav",
      "v=aaadaaaacaaaav",
      "vaaaadaaaacaaaav",
      "vaaaadaaaacaaaav",
      "vaaaadaaaacaaaav",
      "vaaaadeeeecaaaav",
      "v=aaaaaaafffaaav",
      "v=aaaaaaag h a=v",
      "v=aaaaaaafij  =v",
      "v====aaaa=== ==v",
      "vvvvvvvvvvvvvvvv"
    ],
    [
      "vvvvvvvvvvvvvvvv",
      "v======kkkkk===v",
      "v=aaaaaaaaaaaa=v",
      "v=aaaaaaaaaaaa=v",
      "v=aaaaaaaaaaaaav",
      "v=aaallllllaaaav",
      "v=aaalaaaalaaaav",
      "vkaaalaaaalaaaav",
      "vkaaalaaaalaaaav",
      "vkaaalaaaalaaaav",
      "vkaaallllllaaaav",
      "v=aaaaaaaaaaaaav",
      "v=aaaaaaaaaa a=v",
      "v=aaaaaaaaa m =v",
      "v====kkkk=== ==v",
      "vvvvvvvvvvvvvvvv"
    ],
    [
      "vvvvvvvvvvvvvvvv",
      "v======nnnnn===v",
      "v=oooooooooooo=v",
      "v=oooooooooooo=v",
      "v=ooooooooooooov",
      "v=oooppppppoooov",
      "v=ooopoooopoooov",
      "vnooopoooopoooov",
      "vnooopoooopoooov",
      "vnooopoooopoooov",
      "vnoooppppppoooov",
      "v=ooooooooooooov",
      "v=oooooooaaaaa=v",
      "v=oooooooaaaqa=v",
      "v====nnnn===a==v",
      "vvvvvvvvvvvvvvvv"
    ],
    [
      "vvvvvvvvvvvvvvvv",
      "v======rrrrr===v",
      "v=oooooooooooo=v",
      "v=oooooooooooo=v",
      "v=oossssssssootv",
      "v=oossssssssoouv",
      "v=oossssssssooov",
      "vroossssssssooov",
      "vroossssssssooov",
      "vroossssssssooov",
      "vroossssssssooov",
      "v=oossssssssooov",
      "v=oooooooaaaaa=v",
      "v=oooooooaaafa=v",
      "v====rrrr===f==v",
      "vvvvvvvvvvvvvvvv"
    ],
    [
      "vvvvvvvvvvvvvvvv",
      "v======rrrrr===v",
      "v=  wx   y    =v",
      "v=   A   BC DE=v",
      "v= F        I Jv",
      "v= K       LI Mv",
      "v= K       LI Nv",
      "vr         LI Nv",
      "vr        L I Nv",
      "vr          I Iv",
      "vrOB       LI Pv",
      "v= Q     RRRIRIv",
      "v=       Saaaa=v",
      "v=  OBC  aaaaa=v",
      "v====rrrr===T==v",
      "vvvvvvvvvvvvvvvv"
    ]
  ]
}