{
  "name": "building_hoteld_floor1_270",
  "refpalette": "deceasedcraft:building_hoteld/building_hoteld_floor1_palette_270",
  "xsize": 16,
  "zsize": 16,
  "slices": [
    [
      "                ",
      " a===i  h=====a ",
      " =dddeeeeddddd= ",
      " =dffggggffffd= ",
      " =dfffgggffffd= ",
      " beggggggggggd= ",
      "  eggggggggggd= ",
      "  eggggggggggeb ",
      " cegggggggggge  ",
      " =jjjgggggggge  ",
      " =ljjgggggggge  ",
      " = kdggggggggec ",
      " =  d      dgd= ",
      " =  eeeeeeeedd= ",
      " a==i      h==a ",
      "                "
    ],
    [
      "                ",
      " a===i  h=====a ",
      " =dddeeeeddddd= ",
      " =dQ dxIdC tmd= ",
      " =dRON  dD  nd= ",
      " beooo Jdoouod= ",
      "  eEAw pdEAwpd= ",
      "  eFww KdEAwqeb ",
      " ceEAw LdFwwre  ",
      " =ooddMddddx e  ",
      " =  P      d e  ",
      " = Sd      y ec ",
      " = kdBBBBBBdsd= ",
      " =  eeeeeeeedd= ",
      " a==i      h==a ",
      "                "
    ],
    [
      "                ",
      " a===i  h=====a ",
      " =dddeeeeddddd= ",
      " =d Yd 1d Y  d= ",
      " =d  6 2d Z  d= ",
      " beooo  dooWod= ",
      "  e     d   Td= ",
      "  e0   3d   Ueb ",
      " ce    4d0   e  ",
      " =oodd5dddd  e  ",
      " =  7      d e  ",
      " =  d      X ec ",
      " = Sd      dVd= ",
      " =8keeeeeeeedd= ",
      " a==i      h==a ",
      "                "
    ],
    [
      "                ",
      " a===i  h=====a ",
      " =dddeeeeddddd= ",
      " =d %d  d %# d= ",
      " =d( $  d    d= ",
      " beooo  dooood= ",
      "  e     d    d= ",
      "  e     d    eb ",
      " ce     d    e  ",
      " =oodd&dddd  e  ",
      " =  *    ^ d e  ",
      " =  d      $ ec ",
      " =+ d      d9d= ",
      " =j)eeeeeeeedd= ",
      " a==i      h==a ",
      "                "
    ],
    [
      "                ",
      " a===i  h=====a ",
      " =dddeeeeddddd= ",
      " =d  d  d    d= ",
      " =d! d  d    d= ",
      " beooo  dooood= ",
      "  e     d    d= ",
      "  e     d    eb ",
      " ce     d    e  ",
      " =ooddddddd  e  ",
      " =  d      d e  ",
      " =+ d      d ec ",
      " =l d      d d= ",
      " =  eeeeeeeedd= ",
      " a==i      h==a ",
      "                "
    ],
    [
      "                ",
      " a===i  h=====a ",
      " =dddeeeeddddd= ",
      " =d--d--d----d= ",
      " =d--d--d----d= ",
      " be-----d----d= ",
      "  e-----d----d= ",
      "  e-----d----eb ",
      " ce-----d----e  ",
      " =ooddddddd--e  ",
      " =+ d      d-e  ",
      " =l d [  [ d-ec ",
      " =  d      d!d= ",
      " =  eeeeeeeedd= ",
      " a==i      h==a ",
      "                "
    ]
  ]
}