{
  "name": "building_hoteld_ground_180",
  "refpalette": "deceasedcraft:building_hoteld/building_hoteld_ground_palette_180",
  "xsize": 16,
  "zsize": 16,
  "slices": [
    [
      "aaaaaaaaaaaaaaaa",
      "ab=====cccc===ba",
      "a=   igddddddd=a",
      "a=  hggddddddd=a",
      "aadddddddddddd=a",
      "aaddddddddddddca",
      "aaddddddddddddca",
      "aaddddddddddddca",
      "aaddddddddddddca",
      "aadeeeeeeeeeed=a",
      "aadeeeeeeeeeed=a",
      "aaddeeeeeeeeed=a",
      "a=dfeeeeeeeeed=a",
      "a=dddddddddddd=a",
      "ab==ccccc=====ba",
      "aaaaaaaaaaaaaaaa"
    ],
    [
      "                ",
      " b=====k  j===b ",
      " =    Mmmmmlll= ",
      " = hL      D l= ",
      " ImlKKK   FD l= ",
      "  m        DJmI ",
      " ygx      FD m  ",
      "  E        D m  ",
      "  C        BAmt ",
      " ygxqqqqqqqqxl= ",
      "  mqqqqwquuqql= ",
      " tmlqqqqqqqqsl= ",
      " =lrqqqqqpoonl= ",
      " =llmmmmmlllll= ",
      " b==k   j=====b ",
      "                "
    ],
    [
      "                ",
      " b=====k  j===b ",
      " =S   Mmmmmlll= ",
      " =gL         l= ",
      " ImlRRR      l= ",
      "  m          mI ",
      " ygO         m  ",
      "  Q          m  ",
      "  P          mt ",
      " ygO        Nl= ",
      "  m          l= ",
      " tml         l= ",
      " =l          l= ",
      " =llmmmmmlllll= ",
      " b==k   j=====b ",
      "                "
    ],
    [
      "                ",
      " b=====k  j===b ",
      " =gW  Mmmmmlll= ",
      " =V          l= ",
      " ImlRRR      l= ",
      "  m          mI ",
      " yg          m  ",
      " yg          m  ",
      " yg          mt ",
      " yg          l= ",
      "  m          l= ",
      " tml         l= ",
      " =l       UT l= ",
      " =llmmmmmlllll= ",
      " b==k   j=====b ",
      "                "
    ],
    [
      "                ",
      " b=====k  j===b ",
      " = iW Mmmmmlll= ",
      " =           l= ",
      " ImlXXX      l= ",
      "  m          mI ",
      "  m          m  ",
      "  m          m  ",
      "  m          mt ",
      "  m          l= ",
      "  m          l= ",
      " tml         l= ",
      " =l          l= ",
      " =llmmmmmlllll= ",
      " b==k   j=====b ",
      "                "
    ],
    [
      "                ",
      " b=====k  j===b ",
      " =  iWlmmmmlll= ",
      " =    lYYYYYYl= ",
      " ImllllYYYYYYl= ",
      "  m YYYYYYYYYmI ",
      "  m YYYYYYYYYm  ",
      "  m YYYYYYYYYm  ",
      "  m YYYYYYYYYmt ",
      "  m YYYYYYYYYl= ",
      "  m YYYYYYYYYl= ",
      " tmlYYYYYYYYYl= ",
      " =lZYYYYYYYYYl= ",
      " =llmmmmmlllll= ",
      " b==k   j=====b ",
      "                "
    ]
  ]
}