{
  "name": "building_hoteld_floor3",
  "refpalette": "deceasedcraft:building_hoteld/building_hoteld_floor3_palette",
  "xsize": 16,
  "zsize": 16,
  "slices": [
    [
      "                ",
      " a=====b   c==a ",
      " =dddddeeeeedd= ",
      " =d!fggggggggd= ",
      " =dffgggggggdeh ",
      " =dffggggggg e  ",
      " =dffggggggg e  ",
      " hegfggggggg e  ",
      "  eggggggggg e  ",
      "  eggggggggg e  ",
      " ieggggggggg e  ",
      " =dggggggdjddei ",
      " =dggggggjjk  = ",
      " =dddeeeejl   = ",
      " a===b  c=====a ",
      "                "
    ],
    [
      "                ",
      " a=====b   c==a ",
      " =dddddeeeeedd= ",
      " =dmno      pd= ",
      " =d  oqrstdudeh ",
      " =dw x yyd  Ae  ",
      " =dB oCDDd  Ae  ",
      " hedEdxddd  Ae  ",
      "  e      d  Ae  ",
      "  eF yyyId  Ae  ",
      " ieJ yKLMd  Ae  ",
      " =dJ yKLMdNddei ",
      " =dOPyyyIo Qk = ",
      " =dddeeeeo    = ",
      " a===b  c=====a ",
      "                "
    ],
    [
      "                ",
      " a=====b   c==a ",
      " =dddddeeeeedd= ",
      " =d  o      pd= ",
      " =dR o   SdTdeh ",
      " =d  U   d   e  ",
      " =d  o   d   e  ",
      " hedVdUddd   e  ",
      "  e  W   d   e  ",
      "  e     Xd   e  ",
      " ieY     d   e  ",
      " =dZ     d0ddei ",
      " =d12    o  Qk= ",
      " =dddeeeeo   3= ",
      " a===b  c=====a ",
      "                "
    ],
    [
      "                ",
      " a=====b   c==a ",
      " =dddddeeeeedd= ",
      " =d  o      pd= ",
      " =d4 o   5d6deh ",
      " =d7 o   d   e  ",
      " =d  o   d   e  ",
      " hed8d8ddd9  e  ",
      "  e      d#  e  ",
      "  e      d   e  ",
      " ie      d   e  ",
      " =d$     d%ddei ",
      " =d^2    o   &= ",
      " =dddeeeeo  *j= ",
      " a===b  c=====a ",
      "                "
    ],
    [
      "                ",
      " a=====b   c==a ",
      " =dddddeeeeedd= ",
      " =d  o       d= ",
      " =d  o   (dddeh ",
      " =d  o   d   e  ",
      " =d  o   d   e  ",
      " heddddddd   e  ",
      "  e      d   e  ",
      "  e      d   e  ",
      " ie      d   e  ",
      " =d)     ddddei ",
      " =d!+    o    = ",
      " =dddeeeeo *l = ",
      " a===b  c=====a ",
      "                "
    ],
    [
      "                ",
      " a=====b   c==a ",
      " =dddddeeeeedd= ",
      " =d----------d= ",
      " =d-------dddeh ",
      " =d------d   e  ",
      " =d------d [ e  ",
      " heddddddd   e  ",
      "  e------d   e  ",
      "  e------d [ e  ",
      " ie------d   e  ",
      " =d------ddddei ",
      " =d------o    = ",
      " =dddeeeeo*l  = ",
      " a===b  c=====a ",
      "                "
    ]
  ]
}