{
  "name": "building_hoteld_base1_180",
  "refpalette": "deceasedcraft:building_hoteld/building_hoteld_base1_palette_180",
  "xsize": 16,
  "zsize": 16,
  "slices": [
    [
      "vvvvvvvvvvvvvvvv",
      "v==o===aaaa====v",
      "v=mnmmm       =v",
      "v=m!ml        =v",
      "vkijiii       =v",
      "v             av",
      "vh            av",
      "v             av",
      "vg            av",
      "vf          e =v",
      "vd            =v",
      "vc          b =v",
      "v=            =v",
      "v=            =v",
      "v===aaaaa======v",
      "vvvvvvvvvvvvvvvv"
    ],
    [
      "vvvvvvvvvvvvvvvv",
      "v======aaaa====v",
      "v=mmmmm      !=v",
      "v=mml         =v",
      "vriiiii       =v",
      "vq            av",
      "vq            av",
      "vq            av",
      "vq            av",
      "vp            =v",
      "vc            =v",
      "vd            =v",
      "v=            =v",
      "v=            =v",
      "v===aaaaa======v",
      "vvvvvvvvvvvvvvvv"
    ],
    [
      "vvvvvvvvvvvvvvvv",
      "v======aaaa====v",
      "v=mmmmm      y=v",
      "v=ml          =v",
      "vxiiiii       =v",
      "vw            av",
      "vx            av",
      "vw             v",
      "vx            av",
      "vw            =v",
      "vu            =v",
      "vt            =v",
      "v=            =v",
      "v=s           =v",
      "v===a aaa======v",
      "vvvvvvvvvvvvvvvv"
    ],
    [
      "vvvvvvvvvvvvvvvv",
      "v======aa a====v",
      "v=mmmmm      y=v",
      "v=A           =v",
      "v iiiii       =v",
      "v              v",
      "v             av",
      "v              v",
      "v              v",
      "v             =v",
      "v             =v",
      "v             =v",
      "v=            =v",
      "v=y          s=v",
      "v===a  a ======v",
      "vvvvvvvvvvvvvvvv"
    ],
    [
      "vvvvvvvvvvvvvvvv",
      "v======    ====v",
      "v= Fmmm      y=v",
      "v=            =v",
      "v EEEEE       =v",
      "v              v",
      "v     BBBB     v",
      "v     BDDB     v",
      "v     BCCB     v",
      "v     BBBB    =v",
      "v             =v",
      "v             =v",
      "v=            =v",
      "v=y          y=v",
      "v===     ======v",
      "vvvvvvvvvvvvvvvv"
    ],
    [
      "vvvvvvvvvvvvvvvv",
      "v======JIJI====v",
      "v=  FmmLLLLLLL=v",
      "v=   SmLLLLLLL=v",
      "vNLLLLLLLLLLLL=v",
      "vMLLLLLLLLLLLLNv",
      "vPLLLLLOOLLLLLMv",
      "vNLLLLORQOLLLLNv",
      "vMLLLLOQQOLLLLMv",
      "vPLLLLLOOLLLLL=v",
      "vNLLLLLLLLLLLL=v",
      "vMLLLLLLLLLLLL=v",
      "v=LLLLLLLLLLLL=v",
      "v=LLLLLLLLLLLL=v",
      "v===JIKJI======v",
      "vvvvvvvvvvvvvvvv"
    ]
  ]
}