{
  "name": "building_hoteld_base2_90",
  "refpalette": "deceasedcraft:building_hoteld/building_hoteld_base2_palette_90",
  "xsize": 16,
  "zsize": 16,
  "slices": [
    [
      "vvvvvvvvvvvvvvvv",
      "vaaaaaaaaaaaaaav",
      "vaaaaaaaaaaaaaav",
      "vaaaaaaaaaaaaaav",
      "vaaaaaaaaaaaaaav",
      "vaaaaaaaaaaaaaav",
      "vaaaaaaaaaaaaaav",
      "vaaaaaaaaaaaaaav",
      "vaaaaaaaaaaaaaav",
      "vaaaaaaaaaaaaaav",
      "vaaaaaaaaaaaaaav",
      "vaaaaaaaaaaaaaav",
      "vaaaaaaaaaaaaaav",
      "vaaaaaaaaaaaaaav",
      "vaaaaaaaaaaaaaav",
      "vvvvvvvvvvvvvvvv"
    ],
    [
      "vvvvvvvvvvvvvvvv",
      "v===aaaaaaaa===v",
      "v=aaaaaaaaaaa =v",
      "v=aaaaaaaaaa   v",
      "vaaaaaaaaaafhj=v",
      "vaaaaccccccf i=v",
      "vaaaabaaaaefgf=v",
      "vaaaabaaaaeaaaav",
      "vaaaabaaaaeaaaav",
      "v=aaabaaaaeaaaav",
      "v=aaabdddddaaaav",
      "v=aaaaaaaaaaaa=v",
      "v=aaaaaaaaaaaa=v",
      "v=aaaaaaaaaaaa=v",
      "v======aaaa====v",
      "vvvvvvvvvvvvvvvv"
    ],
    [
      "vvvvvvvvvvvvvvvv",
      "v===aaaaaaaa===v",
      "v=aaaaaaaaaaa =v",
      "v=aaaaaaaaaa m v",
      "vkaaaaaaaaaaa =v",
      "vkaaallllllaaa=v",
      "vkaaalaaaalaaa=v",
      "vkaaalaaaalaaakv",
      "vkaaalaaaalaaakv",
      "v=aaalaaaalaaakv",
      "v=aaallllllaaakv",
      "v=aaaaaaaaaaaa=v",
      "v=aaaaaaaaaaaa=v",
      "v=aaaaaaaaaaaa=v",
      "v======kkkk====v",
      "vvvvvvvvvvvvvvvv"
    ],
    [
      "vvvvvvvvvvvvvvvv",
      "v===oooooooo===v",
      "v=ooooooooooaa=v",
      "v=ooooooooooaqav",
      "vnooooooooooaa=v",
      "vnoooppppppoaa=v",
      "vnooopoooopoaa=v",
      "vnooopoooopooonv",
      "vnooopoooopooonv",
      "v=ooopoooopooonv",
      "v=oooppppppooonv",
      "v=oooooooooooo=v",
      "v=oooooooooooo=v",
      "v=oooooooooooo=v",
      "v======nnnn====v",
      "vvvvvvvvvvvvvvvv"
    ],
    [
      "vvvvvvvvvvvvvvvv",
      "v===tuoooooo===v",
      "v=ooooooooooaa=v",
      "v=ooooooooooaffv",
      "vroossssssssaa=v",
      "vroossssssssaa=v",
      "vroossssssssaa=v",
      "vroossssssssoorv",
      "vroossssssssoorv",
      "v=oossssssssoorv",
      "v=oossssssssoorv",
      "v=oossssssssoo=v",
      "v=oooooooooooo=v",
      "v=oooooooooooo=v",
      "v======rrrr====v",
      "vvvvvvvvvvvvvvvv"
    ],
    [
      "vvvvvvvvvvvvvvvv",
      "v===JMNNNIPI===v",
      "v= E       Raa=v",
      "v= DIIIIIIIIaaTv",
      "vr   LLL  LRaa=v",
      "vr C    L  Raa=v",
      "vryB       RSa=v",
      "vr            rv",
      "vr            rv",
      "v=           Crv",
      "v=xA         Brv",
      "v=w          O=v",
      "v=  FKK   BQ  =v",
      "v=        O   =v",
      "v======rrrr====v",
      "vvvvvvvvvvvvvvvv"
    ]
  ]
}