{
  "name": "building_hoteld_top_180",
  "refpalette": "deceasedcraft:building_hoteld/building_hoteld_top_palette_180",
  "xsize": 16,
  "zsize": 16,
  "slices": [
    [
      "                ",
      " a=====c  b===a ",
      " =   ljeeeedii= ",
      " =  kjjffffiii= ",
      " hedfffffffiid= ",
      "  e fffffffifeh ",
      "  e fffffffffe  ",
      "  e fffffffffe  ",
      "  e fffffffffeg ",
      "  e fffffffffd= ",
      "  e fffffffffd= ",
      " gedfffffffffd= ",
      " =edfffffffffd= ",
      " =eeeeeeeddddd= ",
      " a==c   b=====a ",
      "                "
    ],
    [
      "                ",
      " a=====c  b===a ",
      " =    DeeeedLK= ",
      " = kJ   IID  F= ",
      " hedEEE   D  d= ",
      "  eu      DCdeh ",
      "  eu  y     Be  ",
      "  eu tsr     e  ",
      "  eu  p  Aq meg ",
      "  eu  y  rxwmd= ",
      "  eu tsr  q md= ",
      "  edn p    mod= ",
      "  edn       md= ",
      "  eeeeeeeddddd= ",
      "        b=====a ",
      "                "
    ],
    [
      "                ",
      " a=====c  b===a ",
      " =1   Deeeed K= ",
      " =kJ      D0 Z= ",
      " hedYYY   DXWd= ",
      "  e       DVdeh ",
      "  e  U       e  ",
      "  e  SR      e  ",
      "  e  P    Q  eg ",
      "  e  U    Tw d= ",
      "  e  SR   Q md= ",
      "  e  P       d= ",
      "  eE     ONM d= ",
      "  eeeeeeeddddd= ",
      "        b=====a ",
      "                "
    ],
    [
      "                ",
      " a=====c  b===a ",
      " =j8  Deeeed76= ",
      " =5       D4 A= ",
      " hedYYY   D 3d= ",
      "  e       D2deh ",
      "  e          e  ",
      "  e          e  ",
      "  e          eg ",
      "  e          d= ",
      "  e          d= ",
      "  e          d= ",
      "  eY         d= ",
      "  eeeeeeeddddd= ",
      "        b=====a ",
      "                "
    ],
    [
      "                ",
      " a=====c  b===a ",
      " = l8 Deeeeddd= ",
      " =        D  d= ",
      " hedYYY   D  d= ",
      "  e       Dddeh ",
      "  e          e  ",
      "  e          e  ",
      "  e          eg ",
      "  e          d= ",
      "  e          d= ",
      "  e          d= ",
      "  eY         d= ",
      "  eeeeeeeddddd= ",
      "        b=====a ",
      "                "
    ],
    [
      "                ",
      " a=====c  b===a ",
      " =  l8Deeeeddd= ",
      " =        D99d= ",
      " hedYYY   D99d= ",
      "  e       Dddeh ",
      "  e          e  ",
      "  e          e  ",
      "  e          eg ",
      "  e          d= ",
      "  e          d= ",
      "  e          d= ",
      "  eY         d= ",
      "  eeeeeeeddddd= ",
      "        b=====a ",
      "                "
    ],
    [
      "                ",
      " a=====c  b===a ",
      " =   ljeeeeeee= ",
      " =  kjjdddddde= ",
      " hedYYYdddddde= ",
      "  e    ddddddeh ",
      "  e    Dddddde  ",
      "  e    Dddddde  ",
      "  e     dddddeg ",
      "  e     dddddd= ",
      "  e     Dddddd= ",
      "  e     Dddddd= ",
      "  eY     ddddd= ",
      "  eeeeeeeddddd= ",
      "        b=====a ",
      "                "
    ],
    [
      "                ",
      " a=====c        ",
      " =    Deeeeeee  ",
      " = kJ     IIEe  ",
      " hedYYY#     e  ",
      "  e    &^%%  e  ",
      "  e    u     e  ",
      "  e    u!%%  e  ",
      "  e     #    eg ",
      "  e     &^%%$d= ",
      "  e     u   $d= ",
      "  e     u^%%$d= ",
      "  eY     #  Ed= ",
      "  eeeeeeeddddd= ",
      "        b=====a ",
      "                "
    ],
    [
      "                ",
      " a=====c        ",
      " =1   Deeeeeee  ",
      " =kJ        Ye  ",
      " hedYYY      e  ",
      "  e          e  ",
      "  e          e  ",
      "  e          e  ",
      "  e          eg ",
      "  e          d= ",
      "  e          d= ",
      "  e          d= ",
      "  eY     ONMYd= ",
      "  eeeeeeeddddd= ",
      "        b=====a ",
      "                "
    ],
    [
      "                ",
      " a=====c        ",
      " =j8  Deeeeeee  ",
      " =5         Ye  ",
      " hedYYY      e  ",
      "  e          e  ",
      "  e          e  ",
      "  e          e  ",
      "  e          eg ",
      "  e          e= ",
      "  e          e= ",
      "  e          e= ",
      "  eY        Ye= ",
      "  eeeeeeeeeeee= ",
      "        b=====a ",
      "                "
    ],
    [
      "                ",
      " a=====c        ",
      " = l8 Deeeeeee  ",
      " =          *e  ",
      " hed*YY      e  ",
      "  e          e  ",
      "  e          e  ",
      "  e          e  ",
      "  e          e  ",
      "  e          e  ",
      "  e          e  ",
      "  e          e  ",
      "  e*        *e  ",
      "  eeeeeeeeeeee  ",
      "                ",
      "                "
    ],
    [
      "                ",
      " a=====c        ",
      " =  l8Deeeeeee  ",
      " =    D((((((e  ",
      " hedddd)))))(e  ",
      "  e())))))))(e  ",
      "  e())))))))(e  ",
      "  e())))))))(e  ",
      "  e())))))))(e  ",
      "  e())))))))(e  ",
      "  e())))))))(e  ",
      "  e())))))))(e  ",
      "  e((((((((((e  ",
      "  eeeeeeeeeeee  ",
      "                ",
      "                "
    ],
    [
      "                ",
      " a=====c        ",
      " =   ljeeeeeee  ",
      " = ,><jdddddde  ",
      " hedddddddd'de  ",
      "  edddddddddde  ",
      "  edddddddddde  ",
      "  edddddddddde  ",
      "  edddddddddde  ",
      "  ed:;;;;;;|de  ",
      "  ed}------{de  ",
      "  ed]-[[[[-+de  ",
      "  edddddddddde  ",
      "  eeeeeeeeeeee  ",
      "                ",
      "                "
    ],
    [
      "                ",
      " a=====c        ",
      " =     eeeeeee  ",
      " = Y \u037b \u0374  \u037a\u037aEe  ",
      " he\u0377\u0377\u0377   \u0372\u0371!\u0370e  ",
      "  e\u0376\u0376\u0376 \u0374\u0373\u0372\u0371\u0371\u0370e  ",
      "  e\u0374\u0374\u0374\u0375\u0374\u0373\u0372\u0371\u0371\u0370e  ",
      "  e`///?  .. e  ",
      "  e          e  ",
      "  e          e  ",
      "  e          e  ",
      "  e          e  ",
      "  eE        Ee  ",
      "  eeeeeeeeeeee  ",
      "                ",
      "                "
    ],
    [
      "                ",
      " a=====c        ",
      " =     eeeeeee  ",
      " = Y   \u0374    Ye  ",
      " he          e  ",
      "  e    \u0374\u037c    e  ",
      "  e\u0374\u0374\u0374\u037d\u0374\u037c    e  ",
      "  e`///?     e  ",
      "  e          e  ",
      "  e          e  ",
      "  e          e  ",
      "  e          e  ",
      "  eY        Ye  ",
      "  eeeeeeeeeeee  ",
      "                ",
      "                "
    ],
    [
      "                ",
      " a=====c        ",
      " =eeeeeeeeeeee  ",
      " =eY   \u0374    Ye  ",
      " he    \u037f     e  ",
      "  e    \u0374\u037c    e  ",
      "  e\u0374\u0374\u0374\u0374\u0374\u037c    e  ",
      "  e\u037e\u037e\u037e\u037e\u037e     e  ",
      "  e          e  ",
      "  e          e  ",
      "  e          e  ",
      "  e          e  ",
      "  eY        Ye  ",
      "  eeeeeeeeeeee  ",
      "                ",
      "                "
    ],
    [
      "                ",
      "                ",
      "  eeeeeeeeeeee  ",
      "  eY        Ye  ",
      "  e          e  ",
      "  e          e  ",
      "  e          e  ",
      "  e          e  ",
      "  e     \u0384    e  ",
      "  e          e  ",
      "  e          e  ",
      "  e          e  ",
      "  eY        Ye  ",
      "  eeeeeeeeeeee  ",
      "                ",
      "                "
    ],
    [
      "                ",
      "                ",
      "  eeeeeeeeeeee  ",
      "  eY        Ye  ",
      "  e          e  ",
      "  e          e  ",
      "  e          e  ",
      "  e          e  ",
      "  e     \u0385    e  ",
      "  e          e  ",
      "  e          e  ",
      "  e          e  ",
      "  eY        Ye  ",
      "  eeeeeeeeeeee  ",
      "                ",
      "                "
    ],
    [
      "                ",
      "                ",
      "  eeeeeeeeeeee  ",
      "  eY        Ye  ",
      "  e          e  ",
      "  e          e  ",
      "  e          e  ",
      "  e    \u0384     e  ",
      "  e     \u0385    e  ",
      "  e          e  ",
      "  e          e  ",
      "  e          e  ",
      "  eY        Ye  ",
      "  eeeeeeeeeeee  ",
      "                ",
      "                "
    ],
    [
      "                ",
      "                ",
      "  eeeeeeeeeeee  ",
      "  eY        Ye  ",
      "  e          e  ",
      "  e          e  ",
      "  e          e  ",
      "  e    \u0385     e  ",
      "  e    \u0384\u0385    e  ",
      "  e          e  ",
      "  e          e  ",
      "  e          e  ",
      "  eY        Ye  ",
      "  eeeeeeeeeeee  ",
      "                ",
      "                "
    ],
    [
      "                ",
      "                ",
      "  eeeeeeeeeeee  ",
      "  eY        Ye  ",
      "  e          e  ",
      "  e          e  ",
      "  e   \u0386\u0386\u0386\u0386   e  ",
      "  e   \u0386\u0385\u0384\u0386   e  ",
      "  e   \u0386\u0385\u0385\u0386   e  ",
      "  e   \u0386\u0386\u0386\u0386   e  ",
      "  e          e  ",
      "  e          e  ",
      "  eY        Ye  ",
      "  eeeeeeeeeeee  ",
      "                ",
      "                "
    ],
    [
      "                ",
      "                ",
      "  eeeeeeeeeeee  ",
      "  e*        *e  ",
      "  e          e  ",
      "  e  \u0386\u0386\u0386\u0386\u0386\u0386  e  ",
      "  e  \u0386\u0386\u0386\u0386\u0386\u0386  e  ",
      "  e  \u0386\u0386\u0387\u0387\u0386\u0386  e  ",
      "  e  \u0386\u0386\u0387\u0387\u0386\u0386  e  ",
      "  e  \u0386\u0386\u0386\u0386\u0386\u0386  e  ",
      "  e  \u0386\u0386\u0386\u0386\u0386\u0386  e  ",
      "  e          e  ",
      "  e*        *e  ",
      "  eeeeeeeeeeee  ",
      "                ",
      "                "
    ],
    [
      "                ",
      "                ",
      "  eeeeeeeeeeee  ",
      "  e\u0388\u0388\u0388\u0388\u0388\u0388\u0388\u0388\u0388\u0388e  ",
      "  e\u0388eeeeeeee\u0388e  ",
      "  e\u0388e\u0388\u0388\u0388\u0388\u0388\u0388e\u0388e  ",
      "  e\u0388e\u0388\u0389\u0389\u0389\u0389\u0388e\u0388e  ",
      "  e\u0388e\u0388\u0389\u038a\u038a\u0389\u0388e\u0388e  ",
      "  e\u0388e\u0388\u0389\u038a\u038a\u0389\u0388e\u0388e  ",
      "  e\u0388e\u0388\u0389\u0389\u0389\u0389\u0388e\u0388e  ",
      "  e\u0388e\u0388\u0388\u0388\u0388\u0388\u0388e\u0388e  ",
      "  e\u0388eeeeeeee\u0388e  ",
      "  e\u0388\u0388\u0388\u0388\u0388\u0388\u0388\u0388\u0388\u0388e  ",
      "  eeeeeeeeeeee  ",
      "                ",
      "                "
    ],
    [
      "                ",
      "                ",
      "                ",
      "                ",
      "                ",
      "                ",
      "      \u038c\u038c\u038c\u038c      ",
      "      \u038c\u038e\u038e\u038c      ",
      "      \u038c\u038e\u038e\u038c      ",
      "      \u038c\u038c\u038c\u038c      ",
      "                ",
      "                ",
      "                ",
      "                ",
      "                ",
      "                "
    ]
  ]
}