{
  "name": "building_hoteld_top",
  "refpalette": "deceasedcraft:building_hoteld/building_hoteld_top_palette",
  "xsize": 16,
  "zsize": 16,
  "slices": [
    [
      "                ",
      " a=====b   c==a ",
      " =dddddeeeeeee= ",
      " =dfffffffffde= ",
      " =dfffffffffdeg ",
      " =dfffffffff e  ",
      " =dfffffffff e  ",
      " gefffffffff e  ",
      "  efffffffff e  ",
      "  efffffffff e  ",
      " hefifffffff e  ",
      " =diifffffffdeh ",
      " =iiiffffjjk  = ",
      " =iideeeejl   = ",
      " a===b  c=====a ",
      "                "
    ],
    [
      "                ",
      " a=====b        ",
      " =dddddeeeeeee  ",
      " =dm       nde  ",
      " =dom    p nde  ",
      " =dm q  rst ue  ",
      " =dmwxr  y  ue  ",
      " gem qA  p  ue  ",
      "  e     rst ue  ",
      "  eB     y  ue  ",
      " hedCD      ue  ",
      " =d  D   EEEdeh ",
      " =F  DII   Jk = ",
      " =KLdeeeeD    = ",
      " a===b  c=====a ",
      "                "
    ],
    [
      "                ",
      " a=====b        ",
      " =dddddeeeeeee  ",
      " =d MNO     Ee  ",
      " =d       P  e  ",
      " =dm Q   RS  e  ",
      " =d wT    U  e  ",
      " ge  Q    P  e  ",
      "  e      RS  e  ",
      "  e       U  e  ",
      " hedVD       e  ",
      " =dWXD   YYYdeh ",
      " =Z 0D      Jk= ",
      " =K deeeeD   1= ",
      " a===b  c=====a ",
      "                "
    ],
    [
      "                ",
      " a=====b        ",
      " =dddddeeeeeee  ",
      " =d         Ye  ",
      " =d          e  ",
      " =d          e  ",
      " =d          e  ",
      " ge          e  ",
      "  e          e  ",
      "  e          e  ",
      " hed2D       e  ",
      " =d3 D   YYYdeh ",
      " =A 4D       5= ",
      " =67deeeeD  8j= ",
      " a===b  c=====a ",
      "                "
    ],
    [
      "                ",
      " a=====b        ",
      " =dddddeeeeeee  ",
      " =d         Ye  ",
      " =d          e  ",
      " =d          e  ",
      " =d          e  ",
      " ge          e  ",
      "  e          e  ",
      "  e          e  ",
      " heddD       e  ",
      " =d  D   YYYdeh ",
      " =d  D        = ",
      " =dddeeeeD 8l = ",
      " a===b  c=====a ",
      "                "
    ],
    [
      "                ",
      " a=====b        ",
      " =dddddeeeeeee  ",
      " =d         Ye  ",
      " =d          e  ",
      " =d          e  ",
      " =d          e  ",
      " ge          e  ",
      "  e          e  ",
      "  e          e  ",
      " heddD       e  ",
      " =d99D   YYYdeh ",
      " =d99D        = ",
      " =dddeeeeD8l  = ",
      " a===b  c=====a ",
      "                "
    ],
    [
      "                ",
      " a=====b        ",
      " =dddddeeeeeee  ",
      " =ddddd     Ye  ",
      " =dddddD     e  ",
      " =dddddD     e  ",
      " =dddddd     e  ",
      " geddddd     e  ",
      "  edddddD    e  ",
      "  edddddD    e  ",
      " hedddddd    e  ",
      " =eddddddYYYdeh ",
      " =eddddddjjk  = ",
      " =eeeeeeejl   = ",
      " a===b  c=====a ",
      "                "
    ],
    [
      "                ",
      " a=====b        ",
      " =dddddeeeeeee  ",
      " =dE  #     Ye  ",
      " =d$%%^u     e  ",
      " =d$   u     e  ",
      " =d$%%^&     e  ",
      " ge    #     e  ",
      "  e  %%!u    e  ",
      "  e     u    e  ",
      "  e  %%^&    e  ",
      "  e     #YYYdeh ",
      "  eEII     Jk = ",
      "  eeeeeeeD    = ",
      "        c=====a ",
      "                "
    ],
    [
      "                ",
      " a=====b        ",
      " =dddddeeeeeee  ",
      " =dYMNO     Ye  ",
      " =d          e  ",
      " =d          e  ",
      " =d          e  ",
      " ge          e  ",
      "  e          e  ",
      "  e          e  ",
      "  e          e  ",
      "  e      YYYdeh ",
      "  eY        Jk= ",
      "  eeeeeeeD   1= ",
      "        c=====a ",
      "                "
    ],
    [
      "                ",
      " a=====b        ",
      " =eeeeeeeeeeee  ",
      " =eY        Ye  ",
      " =e          e  ",
      " =e          e  ",
      " =e          e  ",
      " ge          e  ",
      "  e          e  ",
      "  e          e  ",
      "  e          e  ",
      "  e      YYYdeh ",
      "  eY         5= ",
      "  eeeeeeeD  8j= ",
      "        c=====a ",
      "                "
    ],
    [
      "                ",
      "                ",
      "  eeeeeeeeeeee  ",
      "  e*        *e  ",
      "  e          e  ",
      "  e          e  ",
      "  e          e  ",
      "  e          e  ",
      "  e          e  ",
      "  e          e  ",
      "  e          e  ",
      "  e      YY*deh ",
      "  e*          = ",
      "  eeeeeeeD 8l = ",
      "        c=====a ",
      "                "
    ],
    [
      "                ",
      "                ",
      "  eeeeeeeeeeee  ",
      "  e((((((((((e  ",
      "  e())))))))(e  ",
      "  e())))))))(e  ",
      "  e())))))))(e  ",
      "  e())))))))(e  ",
      "  e())))))))(e  ",
      "  e())))))))(e  ",
      "  e())))))))(e  ",
      "  e()))))ddddeh ",
      "  e((((((D    = ",
      "  eeeeeeeD8l  = ",
      "        c=====a ",
      "                "
    ],
    [
      "                ",
      "                ",
      "  eeeeeeeeeeee  ",
      "  edddddddddde  ",
      "  ed+-[[[[-]de  ",
      "  ed{------}de  ",
      "  ed|;;;;;;:de  ",
      "  edddddddddde  ",
      "  edddddddddde  ",
      "  edddddddddde  ",
      "  edddddddddde  ",
      "  ed'ddddddddeh ",
      "  eddddddj<>, = ",
      "  eeeeeeejl   = ",
      "        c=====a ",
      "                "
    ],
    [
      "                ",
      "                ",
      "  eeeeeeeeeeee  ",
      "  eE        Ee  ",
      "  e          e  ",
      "  e          e  ",
      "  e          e  ",
      "  e          e  ",
      "  e ..  ?///`e  ",
      "  e\u0370\u0371\u0371\u0372\u0373\u0374\u0375\u0374\u0374\u0374e  ",
      "  e\u0370\u0371\u0371\u0372\u0373\u0374 \u0376\u0376\u0376e  ",
      "  e\u0370!\u0371\u0372   \u0377\u0377\u0377eh ",
      "  eE\u037a\u037a  \u0374 \u037b Y = ",
      "  eeeeeee     = ",
      "        c=====a ",
      "                "
    ],
    [
      "                ",
      "                ",
      "  eeeeeeeeeeee  ",
      "  eY        Ye  ",
      "  e          e  ",
      "  e          e  ",
      "  e          e  ",
      "  e          e  ",
      "  e     ?///`e  ",
      "  e    \u037c\u0374\u037d\u0374\u0374\u0374e  ",
      "  e    \u037c\u0374    e  ",
      "  e          eh ",
      "  eY    \u0374   Y = ",
      "  eeeeeee     = ",
      "        c=====a ",
      "                "
    ],
    [
      "                ",
      "                ",
      "  eeeeeeeeeeee  ",
      "  eY        Ye  ",
      "  e          e  ",
      "  e          e  ",
      "  e          e  ",
      "  e          e  ",
      "  e     \u037e\u037e\u037e\u037e\u037ee  ",
      "  e    \u037c\u0374\u0374\u0374\u0374\u0374e  ",
      "  e    \u037c\u0374    e  ",
      "  e     \u037f    eh ",
      "  eY    \u0374   Ye= ",
      "  eeeeeeeeeeee= ",
      "        c=====a ",
      "                "
    ],
    [
      "                ",
      "                ",
      "  eeeeeeeeeeee  ",
      "  eY        Ye  ",
      "  e          e  ",
      "  e          e  ",
      "  e          e  ",
      "  e    \u0384     e  ",
      "  e          e  ",
      "  e          e  ",
      "  e          e  ",
      "  e          e  ",
      "  eY        Ye  ",
      "  eeeeeeeeeeee  ",
      "                ",
      "                "
    ],
    [
      "                ",
      "                ",
      "  eeeeeeeeeeee  ",
      "  eY        Ye  ",
      "  e          e  ",
      "  e          e  ",
      "  e          e  ",
      "  e    \u0385     e  ",
      "  e          e  ",
      "  e          e  ",
      "  e          e  ",
      "  e          e  ",
      "  eY        Ye  ",
      "  eeeeeeeeeeee  ",
      "                ",
      "                "
    ],
    [
      "                ",
      "                ",
      "  eeeeeeeeeeee  ",
      "  eY        Ye  ",
      "  e          e  ",
      "  e          e  ",
      "  e          e  ",
      "  e    \u0385     e  ",
      "  e     \u0384    e  ",
      "  e          e  ",
      "  e          e  ",
      "  e          e  ",
      "  eY        Ye  ",
      "  eeeeeeeeeeee  ",
      "                ",
      "                "
    ],
    [
      "                ",
      "                ",
      "  eeeeeeeeeeee  ",
      "  eY        Ye  ",
      "  e          e  ",
      "  e          e  ",
      "  e          e  ",
      "  e    \u0385\u0384    e  ",
      "  e     \u0385    e  ",
      "  e          e  ",
      "  e          e  ",
      "  e          e  ",
      "  eY        Ye  ",
      "  eeeeeeeeeeee  ",
      "                ",
      "                "
    ],
    [
      "                ",
      "                ",
      "  eeeeeeeeeeee  ",
      "  eY        Ye  ",
      "  e          e  ",
      "  e          e  ",
      "  e   \u0386\u0386\u0386\u0386   e  ",
      "  e   \u0386\u0385\u0385\u0386   e  ",
      "  e   \u0386\u0384\u0385\u0386   e  ",
      "  e   \u0386\u0386\u0386\u0386   e  ",
      "  e          e  ",
      "  e          e  ",
      "  eY        Ye  ",
      "  eeeeeeeeeeee  ",
      "                ",
      "                "
    ],
    [
      "                ",
      "                ",
      "  eeeeeeeeeeee  ",
      "  e*        *e  ",
      "  e          e  ",
      "  e  \u0386\u0386\u0386\u0386\u0386\u0386  e  ",
      "  e  \u0386\u0386\u0386\u0386\u0386\u0386  e  ",
      "  e  \u0386\u0386\u0387\u0387\u0386\u0386  e  ",
      "  e  \u0386\u0386\u0387\u0387\u0386\u0386  e  ",
      "  e  \u0386\u0386\u0386\u0386\u0386\u0386  e  ",
      "  e  \u0386\u0386\u0386\u0386\u0386\u0386  e  ",
      "  e          e  ",
      "  e*        *e  ",
      "  eeeeeeeeeeee  ",
      "                ",
      "                "
    ],
    [
      "                ",
      "                ",
      "  eeeeeeeeeeee  ",
      "  e\u0388\u0388\u0388\u0388\u0388\u0388\u0388\u0388\u0388\u0388e  ",
      "  e\u0388eeeeeeee\u0388e  ",
      "  e\u0388e\u0388\u0388\u0388\u0388\u0388\u0388e\u0388e  ",
      "  e\u0388e\u0388\u0389\u0389\u0389\u0389\u0388e\u0388e  ",
      "  e\u0388e\u0388\u0389\u038a\u038a\u0389\u0388e\u0388e  ",
      "  e\u0388e\u0388\u0389\u038a\u038a\u0389\u0388e\u0388e  ",
      "  e\u0388e\u0388\u0389\u0389\u0389\u0389\u0388e\u0388e  ",
      "  e\u0388e\u0388\u0388\u0388\u0388\u0388\u0388e\u0388e  ",
      "  e\u0388eeeeeeee\u0388e  ",
      "  e\u0388\u0388\u0388\u0388\u0388\u0388\u0388\u0388\u0388\u0388e  ",
      "  eeeeeeeeeeee  ",
      "                ",
      "                "
    ],
    [
      "                ",
      "                ",
      "                ",
      "                ",
      "                ",
      "                ",
      "      \u038c\u038c\u038c\u038c      ",
      "      \u038c\u038e\u038e\u038c      ",
      "      \u038c\u038e\u038e\u038c      ",
      "      \u038c\u038c\u038c\u038c      ",
      "                ",
      "                ",
      "                ",
      "                ",
      "                ",
      "                "
    ]
  ]
}