{
  "name": "building_hoteld_ground",
  "refpalette": "deceasedcraft:building_hoteld/building_hoteld_ground_palette",
  "xsize": 16,
  "zsize": 16,
  "slices": [
    [
      "aaaaaaaaaaaaaaaa",
      "ab=====ccccc==ba",
      "a=dddddddddddd=a",
      "a=deeeeeeeeefd=a",
      "a=deeeeeeeeeddaa",
      "a=deeeeeeeeeedaa",
      "a=deeeeeeeeeedaa",
      "acddddddddddddaa",
      "acddddddddddddaa",
      "acddddddddddddaa",
      "acddddddddddddaa",
      "a=ddddddddddddaa",
      "a=dddddddggh  =a",
      "a=dddddddgi   =a",
      "ab===cccc=====ba",
      "aaaaaaaaaaaaaaaa"
    ],
    [
      "                ",
      " b=====j   k==b ",
      " =lllllmmmmmll= ",
      " =lnoopqqqqqrl= ",
      " =lsqqqqqqqqlmt ",
      " =lqquuqwqqqqm  ",
      " =lxqqqqqqqqxgy ",
      " tmAB        C  ",
      "  m D        E  ",
      "  m DF      xgy ",
      " ImJD        m  ",
      " =l DF   KKKlmI ",
      " =l D      Lh = ",
      " =lllmmmmM    = ",
      " b===j  k=====b ",
      "                "
    ],
    [
      "                ",
      " b=====j   k==b ",
      " =lllllmmmmmll= ",
      " =l          l= ",
      " =l         lmt ",
      " =l          m  ",
      " =lN        Ogy ",
      " tm          P  ",
      "  m          Q  ",
      "  m         Ogy ",
      " Im          m  ",
      " =l      RRRlmI ",
      " =l         Lg= ",
      " =lllmmmmM   S= ",
      " b===j  k=====b ",
      "                "
    ],
    [
      "                ",
      " b=====j   k==b ",
      " =lllllmmmmmll= ",
      " =l TU       l= ",
      " =l         lmt ",
      " =l          m  ",
      " =l          gy ",
      " tm          gy ",
      "  m          gy ",
      "  m          gy ",
      " Im          m  ",
      " =l      RRRlmI ",
      " =l          V= ",
      " =lllmmmmM  Wg= ",
      " b===j  k=====b ",
      "                "
    ],
    [
      "                ",
      " b=====j   k==b ",
      " =lllllmmmmmll= ",
      " =l          l= ",
      " =l         lmt ",
      " =l          m  ",
      " =l          m  ",
      " tm          m  ",
      "  m          m  ",
      "  m          m  ",
      " Im          m  ",
      " =l      XXXlmI ",
      " =l           = ",
      " =lllmmmmM Wi = ",
      " b===j  k=====b ",
      "                "
    ],
    [
      "                ",
      " b=====j   k==b ",
      " =lllllmmmmmll= ",
      " =lYYYYYYYYYZl= ",
      " =lYYYYYYYYYlmt ",
      " =lYYYYYYYYY m  ",
      " =lYYYYYYYYY m  ",
      " tmYYYYYYYYY m  ",
      "  mYYYYYYYYY m  ",
      "  mYYYYYYYYY m  ",
      " ImYYYYYYYYY m  ",
      " =lYYYYYYllllmI ",
      " =lYYYYYYl    = ",
      " =lllmmmmlWi  = ",
      " b===j  k=====b ",
      "                "
    ]
  ]
}