{
  "name": "building_hoteld_base1",
  "refpalette": "deceasedcraft:building_hoteld/building_hoteld_base1_palette",
  "xsize": 16,
  "zsize": 16,
  "slices": [
    [
      "vvvvvvvvvvvvvvvv",
      "v======aaaaa===v",
      "v=            =v",
      "v=            =v",
      "v= b          cv",
      "v=            dv",
      "v= e          fv",
      "va            gv",
      "va             v",
      "va            hv",
      "va             v",
      "v=       iiijikv",
      "v=        lm!m=v",
      "v=       mmmnm=v",
      "v====aaaa===o==v",
      "vvvvvvvvvvvvvvvv"
    ],
    [
      "vvvvvvvvvvvvvvvv",
      "v======aaaaa===v",
      "v=            =v",
      "v=            =v",
      "v=            dv",
      "v=            cv",
      "v=            pv",
      "va            qv",
      "va            qv",
      "va            qv",
      "va            qv",
      "v=       iiiiirv",
      "v=         lmm=v",
      "v=!      mmmmm=v",
      "v====aaaa======v",
      "vvvvvvvvvvvvvvvv"
    ],
    [
      "vvvvvvvvvvvvvvvv",
      "v======aaa a===v",
      "v=           s=v",
      "v=            =v",
      "v=            tv",
      "v=            uv",
      "v=            wv",
      "va            xv",
      "v             wv",
      "va            xv",
      "va            wv",
      "v=       iiiiixv",
      "v=          lm=v",
      "v=y      mmmmm=v",
      "v====aaaa======v",
      "vvvvvvvvvvvvvvvv"
    ],
    [
      "vvvvvvvvvvvvvvvv",
      "v====== a  a===v",
      "v=s          y=v",
      "v=            =v",
      "v=             v",
      "v=             v",
      "v=             v",
      "v              v",
      "v              v",
      "va             v",
      "v              v",
      "v=       iiiii v",
      "v=           A=v",
      "v=y      mmmmm=v",
      "v====a aa======v",
      "vvvvvvvvvvvvvvvv"
    ],
    [
      "vvvvvvvvvvvvvvvv",
      "v======     ===v",
      "v=y          y=v",
      "v=            =v",
      "v=             v",
      "v=             v",
      "v=    BBBB     v",
      "v     BCCB     v",
      "v     BDDB     v",
      "v     BBBB     v",
      "v              v",
      "v=       EEEEE v",
      "v=            =v",
      "v=y      mmmF =v",
      "v====    ======v",
      "vvvvvvvvvvvvvvvv"
    ],
    [
      "vvvvvvvvvvvvvvvv",
      "v======IJKIJ===v",
      "v=LLLLLLLLLLLL=v",
      "v=LLLLLLLLLLLL=v",
      "v=LLLLLLLLLLLLMv",
      "v=LLLLLLLLLLLLNv",
      "v=LLLLLOOLLLLLPv",
      "vMLLLLOQQOLLLLMv",
      "vNLLLLOQROLLLLNv",
      "vMLLLLLOOLLLLLPv",
      "vNLLLLLLLLLLLLMv",
      "v=LLLLLLLLLLLLNv",
      "v=LLLLLLLmS   =v",
      "v=LLLLLLLmmF  =v",
      "v====IJIJ======v",
      "vvvvvvvvvvvvvvvv"
    ]
  ]
}