{
  "name": "building_hoteld_floor3_90",
  "refpalette": "deceasedcraft:building_hoteld/building_hoteld_floor3_palette_90",
  "xsize": 16,
  "zsize": 16,
  "slices": [
    [
      "                ",
      " a==h      i==a ",
      " =ddeeeeeeee  = ",
      " =dgd      d  = ",
      " ceggggggggdk = ",
      "  eggggggggjjl= ",
      "  eggggggggdjj= ",
      "  eggggggggggec ",
      " begggggggggge  ",
      " =dgggggggggge  ",
      " =dggggggggggeb ",
      " =dfffffgggggd= ",
      " =d!fffggggggd= ",
      " =dddddeeeeddd= ",
      " a=====h  i===a ",
      "                "
    ],
    [
      "                ",
      " a==h      i==a ",
      " =ddeeeeeeee  = ",
      " =dpdAAAAAAdk = ",
      " ce u      dQ = ",
      "  e d      N  = ",
      "  e tdddddddoo= ",
      "  e syDd IMMIec ",
      " be ryDd yLLye  ",
      " =d q Cx yKKye  ",
      " =dooxod yyyyeb ",
      " =dn   E    Pd= ",
      " =dm wBd FJJOd= ",
      " =dddddeeeeddd= ",
      " a=====h  i===a ",
      "                "
    ],
    [
      "                ",
      " a==h      i==a ",
      " =ddeeeeeeeek3= ",
      " =dpd      dQ = ",
      " ce T      d  = ",
      "  e d      0  = ",
      "  e Sdddddddoo= ",
      "  e    d X   ec ",
      " be    d     e  ",
      " =d    U     e  ",
      " =dooUodW    eb ",
      " =d    V    2d= ",
      " =d R  d  YZ1d= ",
      " =dddddeeeeddd= ",
      " a=====h  i===a ",
      "                "
    ],
    [
      "                ",
      " a==h      i==a ",
      " =ddeeeeeeee&j= ",
      " =dpd      d *= ",
      " ce 6      d  = ",
      "  e d  9#  %  = ",
      "  e 5dddddddoo= ",
      "  e    d     ec ",
      " be    d     e  ",
      " =d    8     e  ",
      " =dooood     eb ",
      " =d    8    2d= ",
      " =d 47 d   $^d= ",
      " =dddddeeeeddd= ",
      " a=====h  i===a ",
      "                "
    ],
    [
      "                ",
      " a==h      i==a ",
      " =ddeeeeeeee  = ",
      " =d d      d l= ",
      " ce d      d *= ",
      "  e d      d  = ",
      "  e (dddddddoo= ",
      "  e    d     ec ",
      " be    d     e  ",
      " =d    d     e  ",
      " =dooood     eb ",
      " =d    d    +d= ",
      " =d    d   )!d= ",
      " =dddddeeeeddd= ",
      " a=====h  i===a ",
      "                "
    ],
    [
      "                ",
      " a==h      i==a ",
      " =ddeeeeeeee  = ",
      " =d-d      d  = ",
      " ce-d [  [ d l= ",
      "  e-d      d *= ",
      "  e--dddddddoo= ",
      "  e----d-----ec ",
      " be----d-----e  ",
      " =d----d-----e  ",
      " =d----d-----eb ",
      " =d----d-----d= ",
      " =d----d-----d= ",
      " =dddddeeeeddd= ",
      " a=====h  i===a ",
      "                "
    ]
  ]
}