{
  "name": "building_hoteld_floor1_90",
  "refpalette": "deceasedcraft:building_hoteld/building_hoteld_floor1_palette_90",
  "xsize": 16,
  "zsize": 16,
  "slices": [
    [
      "                ",
      " a==h      i==a ",
      " =ddeeeeeeee  = ",
      " =dgd      d  = ",
      " ceggggggggdk = ",
      "  eggggggggjjl= ",
      "  eggggggggjjj= ",
      "  eggggggggggec ",
      " begggggggggge  ",
      " =dgggggggggge  ",
      " =dggggggggggeb ",
      " =dffffgggfffd= ",
      " =dffffggggffd= ",
      " =dddddeeeeddd= ",
      " a=====h  i===a ",
      "                "
    ],
    [
      "                ",
      " a==h      i==a ",
      " =ddeeeeeeee  = ",
      " =dsdBBBBBBdk = ",
      " ce y      dS = ",
      "  e d      P  = ",
      "  e xddddMddoo= ",
      "  erwwFdL wAEec ",
      " beqwAEdK wwFe  ",
      " =dpwAEdp wAEe  ",
      " =douoodJ oooeb ",
      " =dn  Dd  NORd= ",
      " =dmt CdIxd Qd= ",
      " =dddddeeeeddd= ",
      " a=====h  i===a ",
      "                "
    ],
    [
      "                ",
      " a==h      i==a ",
      " =ddeeeeeeeek8= ",
      " =dVd      dS = ",
      " ce X      d  = ",
      "  e d      7  = ",
      "  e  dddd5ddoo= ",
      "  e   0d4    ec ",
      " beU   d3   0e  ",
      " =dT   d     e  ",
      " =doWood  oooeb ",
      " =d  Z d2 6  d= ",
      " =d  Y d1 dY d= ",
      " =dddddeeeeddd= ",
      " a=====h  i===a ",
      "                "
    ],
    [
      "                ",
      " a==h      i==a ",
      " =ddeeeeeeee)j= ",
      " =d9d      d += ",
      " ce $      d  = ",
      "  e d ^    *  = ",
      "  e  dddd&ddoo= ",
      "  e    d     ec ",
      " be    d     e  ",
      " =d    d     e  ",
      " =dooood  oooeb ",
      " =d    d  $ (d= ",
      " =d #% d  d% d= ",
      " =dddddeeeeddd= ",
      " a=====h  i===a ",
      "                "
    ],
    [
      "                ",
      " a==h      i==a ",
      " =ddeeeeeeee  = ",
      " =d d      d l= ",
      " ce d      d += ",
      "  e d      d  = ",
      "  e  dddddddoo= ",
      "  e    d     ec ",
      " be    d     e  ",
      " =d    d     e  ",
      " =dooood  oooeb ",
      " =d    d  d !d= ",
      " =d    d  d  d= ",
      " =dddddeeeeddd= ",
      " a=====h  i===a ",
      "                "
    ],
    [
      "                ",
      " a==h      i==a ",
      " =ddeeeeeeee  = ",
      " =d!d      d  = ",
      " ce-d [  [ d l= ",
      "  e-d      d += ",
      "  e--dddddddoo= ",
      "  e----d-----ec ",
      " be----d-----e  ",
      " =d----d-----e  ",
      " =d----d-----eb ",
      " =d----d--d--d= ",
      " =d----d--d--d= ",
      " =dddddeeeeddd= ",
      " a=====h  i===a ",
      "                "
    ]
  ]
}