{
  "name": "building_hoteld_floor2_270",
  "refpalette": "deceasedcraft:building_hoteld/building_hoteld_floor2_palette_270",
  "xsize": 16,
  "zsize": 16,
  "slices": [
    [
      "                ",
      " a===i  h=====a ",
      " =dddeeeeddddd= ",
      " =dffggggffffd= ",
      " =dfffgggffffd= ",
      " beggggggggggd= ",
      "  eggggggggggd= ",
      "  eggggggggggeb ",
      " cegggggggggge  ",
      " =jjdgggggggge  ",
      " =ljjgggggggge  ",
      " = kdggggggggec ",
      " =  d      dgd= ",
      " =  eeeeeeeedd= ",
      " a==i      h==a ",
      "                "
    ],
    [
      "                ",
      " a===i  h=====a ",
      " =dddeeeeddddd= ",
      " =dP dxIdC tmd= ",
      " =dQ N  dD  nd= ",
      " beooo Jdoouod= ",
      "  eEAw pdEAwpd= ",
      "  eFww KdEAwqeb ",
      " ceEAw LdFwwre  ",
      " =ooddMddddx e  ",
      " =  O      d e  ",
      " = Rd      y ec ",
      " = kdBBBBBBdsd= ",
      " =  eeeeeeeedd= ",
      " a==i      h==a ",
      "                "
    ],
    [
      "                ",
      " a===i  h=====a ",
      " =dddeeeeddddd= ",
      " =d Xd 0d X  d= ",
      " =d  5 1d Y  d= ",
      " beooo  dooVod= ",
      "  e    !d   Sd= ",
      "  e7   2d   Teb ",
      " ce    3dZ   e  ",
      " =oodd4dddd  e  ",
      " =  6      d e  ",
      " =  d      W ec ",
      " = Rd      dUd= ",
      " =8keeeeeeeedd= ",
      " a==i      h==a ",
      "                "
    ],
    [
      "                ",
      " a===i  h=====a ",
      " =dddeeeeddddd= ",
      " =d %d  d %# d= ",
      " =d( $  d    d= ",
      " beooo  dooood= ",
      "  e     d    d= ",
      "  e     d    eb ",
      " ce     d    e  ",
      " =oodd&dddd  e  ",
      " =  *    ^ d e  ",
      " =  d      $ ec ",
      " =+ d      d9d= ",
      " =j)eeeeeeeedd= ",
      " a==i      h==a ",
      "                "
    ],
    [
      "                ",
      " a===i  h=====a ",
      " =dddeeeeddddd= ",
      " =d  d  d    d= ",
      " =d  d  d    d= ",
      " beooo  dooood= ",
      "  e     d    d= ",
      "  e     d    eb ",
      " ce     d    e  ",
      " =ooddddddd  e  ",
      " =  d      d e  ",
      " =+ d      d ec ",
      " =l d      d d= ",
      " =  eeeeeeeedd= ",
      " a==i      h==a ",
      "                "
    ],
    [
      "                ",
      " a===i  h=====a ",
      " =dddeeeeddddd= ",
      " =d--d--d----d= ",
      " =d--d--d----d= ",
      " be-----d----d= ",
      "  e-----d----d= ",
      "  e-----d----eb ",
      " ce-----d----e  ",
      " =ooddddddd--e  ",
      " =+ d      d-e  ",
      " =l d [  [ d-ec ",
      " =  d      d-d= ",
      " =  eeeeeeeedd= ",
      " a==i      h==a ",
      "                "
    ]
  ]
}