{
  "name": "building_hoteld_floor3_270",
  "refpalette": "deceasedcraft:building_hoteld/building_hoteld_floor3_palette_270",
  "xsize": 16,
  "zsize": 16,
  "slices": [
    [
      "                ",
      " a===i  h=====a ",
      " =dddeeeeddddd= ",
      " =dggggggfff!d= ",
      " =dgggggfffffd= ",
      " beggggggggggd= ",
      "  eggggggggggd= ",
      "  eggggggggggeb ",
      " cegggggggggge  ",
      " =jjdgggggggge  ",
      " =ljjgggggggge  ",
      " = kdggggggggec ",
      " =  d      dgd= ",
      " =  eeeeeeeedd= ",
      " a==i      h==a ",
      "                "
    ],
    [
      "                ",
      " a===i  h=====a ",
      " =dddeeeeddddd= ",
      " =dOJJF dBw md= ",
      " =dP    E   nd= ",
      " beyyyy doxood= ",
      "  eyKKy xC q d= ",
      "  eyLLy dDyr eb ",
      " ceIMMI dDys e  ",
      " =oodddddddt e  ",
      " =  N      d e  ",
      " = Qd      u ec ",
      " = kdAAAAAAdpd= ",
      " =  eeeeeeeedd= ",
      " a==i      h==a ",
      "                "
    ],
    [
      "                ",
      " a===i  h=====a ",
      " =dddeeeeddddd= ",
      " =d1ZY  d  R d= ",
      " =d2    V    d= ",
      " be    WdoUood= ",
      "  e     U    d= ",
      "  e     d    eb ",
      " ce   X d    e  ",
      " =oodddddddS e  ",
      " =  0      d e  ",
      " =  d      T ec ",
      " = Qd      dpd= ",
      " =3keeeeeeeedd= ",
      " a==i      h==a ",
      "                "
    ],
    [
      "                ",
      " a===i  h=====a ",
      " =dddeeeeddddd= ",
      " =d^$   d 74 d= ",
      " =d2    8    d= ",
      " be     dooood= ",
      "  e     8    d= ",
      "  e     d    eb ",
      " ce     d    e  ",
      " =ooddddddd5 e  ",
      " =  %  #9  d e  ",
      " =  d      6 ec ",
      " =* d      dpd= ",
      " =j&eeeeeeeedd= ",
      " a==i      h==a ",
      "                "
    ],
    [
      "                ",
      " a===i  h=====a ",
      " =dddeeeeddddd= ",
      " =d!)   d    d= ",
      " =d+    d    d= ",
      " be     dooood= ",
      "  e     d    d= ",
      "  e     d    eb ",
      " ce     d    e  ",
      " =ooddddddd( e  ",
      " =  d      d e  ",
      " =* d      d ec ",
      " =l d      d d= ",
      " =  eeeeeeeedd= ",
      " a==i      h==a ",
      "                "
    ],
    [
      "                ",
      " a===i  h=====a ",
      " =dddeeeeddddd= ",
      " =d-----d----d= ",
      " =d-----d----d= ",
      " be-----d----d= ",
      "  e-----d----d= ",
      "  e-----d----eb ",
      " ce-----d----e  ",
      " =ooddddddd--e  ",
      " =* d      d-e  ",
      " =l d [  [ d-ec ",
      " =  d      d-d= ",
      " =  eeeeeeeedd= ",
      " a==i      h==a ",
      "                "
    ]
  ]
}