{
  "name": "building_hoteld_top_270",
  "refpalette": "deceasedcraft:building_hoteld/building_hoteld_top_palette_270",
  "xsize": 16,
  "zsize": 16,
  "slices": [
    [
      "                ",
      " a===h  g=====a ",
      " =iideeeeddddd= ",
      " =iiiffffffffd= ",
      " =diiifffffffd= ",
      " beffffffffffd= ",
      "  effffffffffd= ",
      "  effffffffffeb ",
      " ceffffffffffe  ",
      " =jjfffffffffe  ",
      " =ljfffffffffe  ",
      " = kfffffffffec ",
      " =  d      dde= ",
      " =  eeeeeeeeee= ",
      " a==h      g==a ",
      "                "
    ],
    [
      "                ",
      " a===h  g=====a ",
      " =KFdeeeeddddd= ",
      " =L  dB mmmomd= ",
      " =d  C   w m d= ",
      " beDDD  qxq  d= ",
      "  eI    Ar   d= ",
      "  eI         eb ",
      " ce    r  r  e  ",
      " =D E yspysp e  ",
      " =  E  t  t  e  ",
      " = JE      nne  ",
      " = kduuuuuudde  ",
      " =  eeeeeeeeee  ",
      " a==h           ",
      "                "
    ],
    [
      "                ",
      " a===h  g=====a ",
      " =KZdeeeeddddd= ",
      " =  Wd    m  d= ",
      " =d0XV   w  Md= ",
      " beDDD  QTQ Nd= ",
      "  e         Od= ",
      "  e          eb ",
      " ce          e  ",
      " =D Y  R  R  e  ",
      " =  Y USPUSP e  ",
      " =  Y        e  ",
      " = Jd       Ee  ",
      " =1keeeeeeeeee  ",
      " a==h           ",
      "                "
    ],
    [
      "                ",
      " a===h  g=====a ",
      " =6Adeeeeddddd= ",
      " =7 3d       d= ",
      " =d4 2       d= ",
      " beDDD       d= ",
      "  e          d= ",
      "  e          eb ",
      " ce          e  ",
      " =D Y        e  ",
      " =  Y        e  ",
      " =  Y        e  ",
      " =8 d       Ye  ",
      " =j5eeeeeeeeee  ",
      " a==h           ",
      "                "
    ],
    [
      "                ",
      " a===h  g=====a ",
      " =dddeeeeddddd= ",
      " =d  d       d= ",
      " =d  d       d= ",
      " beDDD       d= ",
      "  e          d= ",
      "  e          eb ",
      " ce          e  ",
      " =D Y        e  ",
      " =  Y        e  ",
      " =8 Y        e  ",
      " =l d       Ye  ",
      " =  eeeeeeeeee  ",
      " a==h           ",
      "                "
    ],
    [
      "                ",
      " a===h  g=====a ",
      " =dddeeeeddddd= ",
      " =d99d       d= ",
      " =d99d       d= ",
      " beDDD       d= ",
      "  e          d= ",
      "  e          eb ",
      " ce          e  ",
      " =D Y        e  ",
      " =8 Y        e  ",
      " =l Y        e  ",
      " =  d       Ye  ",
      " =  eeeeeeeeee  ",
      " a==h           ",
      "                "
    ],
    [
      "                ",
      " a===h  g=====a ",
      " =eeeeeeeddddd= ",
      " =eddddddddddd= ",
      " =eddddddddddd= ",
      " beddddddddddd= ",
      "  eddddddddddd= ",
      "  edddddddDD eb ",
      " cedddDD     e  ",
      " =jjY        e  ",
      " =ljY        e  ",
      " = kY        e  ",
      " =  d       Ye  ",
      " =  eeeeeeeeee  ",
      " a==h           ",
      "                "
    ],
    [
      "                ",
      "        g=====a ",
      "  eeeeeeeddddd= ",
      "  eE     $$$Ed= ",
      "  eI     % % d= ",
      "  eI % % % % d= ",
      "  e  % % ^ ^#d= ",
      "  e  ^ !#&uu eb ",
      " ce #&uu     e  ",
      " =D Y        e  ",
      " =  Y        e  ",
      " = JY        e  ",
      " = kd       Ye  ",
      " =  eeeeeeeeee  ",
      " a==h           ",
      "                "
    ],
    [
      "                ",
      "        g=====a ",
      "  eeeeeeeddddd= ",
      "  eY        Yd= ",
      "  e         Md= ",
      "  e         Nd= ",
      "  e         Od= ",
      "  e          eb ",
      " ce          e  ",
      " =D Y        e  ",
      " =  Y        e  ",
      " =  Y        e  ",
      " = Jd       Ye  ",
      " =1keeeeeeeeee  ",
      " a==h           ",
      "                "
    ],
    [
      "                ",
      "        g=====a ",
      "  eeeeeeeeeeee= ",
      "  eY        Ye= ",
      "  e          e= ",
      "  e          e= ",
      "  e          e= ",
      "  e          eb ",
      " ce          e  ",
      " =D Y        e  ",
      " =  Y        e  ",
      " =  Y        e  ",
      " =8 d       Ye  ",
      " =j5eeeeeeeeee  ",
      " a==h           ",
      "                "
    ],
    [
      "                ",
      "                ",
      "  eeeeeeeeeeee  ",
      "  e*        *e  ",
      "  e          e  ",
      "  e          e  ",
      "  e          e  ",
      "  e          e  ",
      " ce          e  ",
      " =D Y        e  ",
      " =  Y        e  ",
      " =8 *        e  ",
      " =l d       *e  ",
      " =  eeeeeeeeee  ",
      " a==h           ",
      "                "
    ],
    [
      "                ",
      "                ",
      "  eeeeeeeeeeee  ",
      "  e((((((((((e  ",
      "  e())))))))(e  ",
      "  e())))))))(e  ",
      "  e())))))))(e  ",
      "  e())))))))(e  ",
      " ce())))))))(e  ",
      " =DDd)))))))(e  ",
      " =8 d)))))))(e  ",
      " =l d)))))))(e  ",
      " =  d((((((((e  ",
      " =  eeeeeeeeee  ",
      " a==h           ",
      "                "
    ],
    [
      "                ",
      "                ",
      "  eeeeeeeeeeee  ",
      "  edddddddddde  ",
      "  ed'dddd|{+de  ",
      "  edddddd;--de  ",
      "  edddddd;-[de  ",
      "  edddddd;-[de  ",
      " cedddddd;-[de  ",
      " =jjddddd;-[de  ",
      " =l<ddddd;--de  ",
      " = >ddddd:}]de  ",
      " = ,ddddddddde  ",
      " =  eeeeeeeeee  ",
      " a==h           ",
      "                "
    ],
    [
      "                ",
      "                ",
      "  eeeeeeeeeeee  ",
      "  eE\u0370\u0370\u0370     Ee  ",
      "  e\u037a!\u0371\u0371.     e  ",
      "  e\u037a\u0371\u0371\u0371.     e  ",
      "  e \u0372\u0372\u0372      e  ",
      "  e  \u0373\u0373      e  ",
      " ce\u0374 \u0374\u0374?     e  ",
      " =    \u0375/     e  ",
      " = \u037b\u0377\u0376\u0374/     e  ",
      " =  \u0377\u0376\u0374/     e  ",
      " = Y\u0377\u0376\u0374`    Ee  ",
      " =  eeeeeeeeee  ",
      " a==h           ",
      "                "
    ],
    [
      "                ",
      "                ",
      "  eeeeeeeeeeee  ",
      "  eY        Ye  ",
      "  e          e  ",
      "  e          e  ",
      "  e          e  ",
      "  e  \u037c\u037c      e  ",
      " ce\u0374 \u0374\u0374?     e  ",
      " =    \u037d/     e  ",
      " =    \u0374/     e  ",
      " =    \u0374/     e  ",
      " = Y  \u0374`    Ye  ",
      " =  eeeeeeeeee  ",
      " a==h           ",
      "                "
    ],
    [
      "                ",
      "                ",
      "  eeeeeeeeeeee  ",
      "  eY        Ye  ",
      "  e          e  ",
      "  e          e  ",
      "  e          e  ",
      "  e  \u037c\u037c      e  ",
      " ce\u0374\u037f\u0374\u0374\u037e     e  ",
      " =e   \u0374\u037e     e  ",
      " =e   \u0374\u037e     e  ",
      " =e   \u0374\u037e     e  ",
      " =eY  \u0374\u037e    Ye  ",
      " =eeeeeeeeeeee  ",
      " a==h           ",
      "                "
    ],
    [
      "                ",
      "                ",
      "  eeeeeeeeeeee  ",
      "  eY        Ye  ",
      "  e          e  ",
      "  e          e  ",
      "  e          e  ",
      "  e     \u0384    e  ",
      "  e          e  ",
      "  e          e  ",
      "  e          e  ",
      "  e          e  ",
      "  eY        Ye  ",
      "  eeeeeeeeeeee  ",
      "                ",
      "                "
    ],
    [
      "                ",
      "                ",
      "  eeeeeeeeeeee  ",
      "  eY        Ye  ",
      "  e          e  ",
      "  e          e  ",
      "  e          e  ",
      "  e     \u0385    e  ",
      "  e          e  ",
      "  e          e  ",
      "  e          e  ",
      "  e          e  ",
      "  eY        Ye  ",
      "  eeeeeeeeeeee  ",
      "                ",
      "                "
    ],
    [
      "                ",
      "                ",
      "  eeeeeeeeeeee  ",
      "  eY        Ye  ",
      "  e          e  ",
      "  e          e  ",
      "  e          e  ",
      "  e     \u0385    e  ",
      "  e    \u0384     e  ",
      "  e          e  ",
      "  e          e  ",
      "  e          e  ",
      "  eY        Ye  ",
      "  eeeeeeeeeeee  ",
      "                ",
      "                "
    ],
    [
      "                ",
      "                ",
      "  eeeeeeeeeeee  ",
      "  eY        Ye  ",
      "  e          e  ",
      "  e          e  ",
      "  e          e  ",
      "  e     \u0385    e  ",
      "  e    \u0385\u0384    e  ",
      "  e          e  ",
      "  e          e  ",
      "  e          e  ",
      "  eY        Ye  ",
      "  eeeeeeeeeeee  ",
      "                ",
      "                "
    ],
    [
      "                ",
      "                ",
      "  eeeeeeeeeeee  ",
      "  eY        Ye  ",
      "  e          e  ",
      "  e          e  ",
      "  e   \u0386\u0386\u0386\u0386   e  ",
      "  e   \u0386\u0384\u0385\u0386   e  ",
      "  e   \u0386\u0385\u0385\u0386   e  ",
      "  e   \u0386\u0386\u0386\u0386   e  ",
      "  e          e  ",
      "  e          e  ",
      "  eY        Ye  ",
      "  eeeeeeeeeeee  ",
      "                ",
      "                "
    ],
    [
      "                ",
      "                ",
      "  eeeeeeeeeeee  ",
      "  e*        *e  ",
      "  e          e  ",
      "  e  \u0386\u0386\u0386\u0386\u0386\u0386  e  ",
      "  e  \u0386\u0386\u0386\u0386\u0386\u0386  e  ",
      "  e  \u0386\u0386\u0387\u0387\u0386\u0386  e  ",
      "  e  \u0386\u0386\u0387\u0387\u0386\u0386  e  ",
      "  e  \u0386\u0386\u0386\u0386\u0386\u0386  e  ",
      "  e  \u0386\u0386\u0386\u0386\u0386\u0386  e  ",
      "  e          e  ",
      "  e*        *e  ",
      "  eeeeeeeeeeee  ",
      "                ",
      "                "
    ],
    [
      "                ",
      "                ",
      "  eeeeeeeeeeee  ",
      "  e\u0388\u0388\u0388\u0388\u0388\u0388\u0388\u0388\u0388\u0388e  ",
      "  e\u0388eeeeeeee\u0388e  ",
      "  e\u0388e\u0388\u0388\u0388\u0388\u0388\u0388e\u0388e  ",
      "  e\u0388e\u0388\u0389\u0389\u0389\u0389\u0388e\u0388e  ",
      "  e\u0388e\u0388\u0389\u038a\u038a\u0389\u0388e\u0388e  ",
      "  e\u0388e\u0388\u0389\u038a\u038a\u0389\u0388e\u0388e  ",
      "  e\u0388e\u0388\u0389\u0389\u0389\u0389\u0388e\u0388e  ",
      "  e\u0388e\u0388\u0388\u0388\u0388\u0388\u0388e\u0388e  ",
      "  e\u0388eeeeeeee\u0388e  ",
      "  e\u0388\u0388\u0388\u0388\u0388\u0388\u0388\u0388\u0388\u0388e  ",
      "  eeeeeeeeeeee  ",
      "                ",
      "                "
    ],
    [
      "                ",
      "                ",
      "                ",
      "                ",
      "                ",
      "                ",
      "      \u038c\u038c\u038c\u038c      ",
      "      \u038c\u038e\u038e\u038c      ",
      "      \u038c\u038e\u038e\u038c      ",
      "      \u038c\u038c\u038c\u038c      ",
      "                ",
      "                ",
      "                ",
      "                ",
      "                ",
      "                "
    ]
  ]
}