{
  "name": "building_hoteld_base2_180",
  "refpalette": "deceasedcraft:building_hoteld/building_hoteld_base2_palette_180",
  "xsize": 16,
  "zsize": 16,
  "slices": [
    [
      "vvvvvvvvvvvvvvvv",
      "vaaaaaaaaaaaaaav",
      "vaaaaaaaaaaaaaav",
      "vaaaaaaaaaaaaaav",
      "vaaaaaaaaaaaaaav",
      "vaaaaaaaaaaaaaav",
      "vaaaaaaaaaaaaaav",
      "vaaaaaaaaaaaaaav",
      "vaaaaaaaaaaaaaav",
      "vaaaaaaaaaaaaaav",
      "vaaaaaaaaaaaaaav",
      "vaaaaaaaaaaaaaav",
      "vaaaaaaaaaaaaaav",
      "vaaaaaaaaaaaaaav",
      "vaaaaaaaaaaaaaav",
      "vvvvvvvvvvvvvvvv"
    ],
    [
      "vvvvvvvvvvvvvvvv",
      "v== ===aaaa====v",
      "v=  jifaaaaaaa=v",
      "v=a h gaaaaaaa=v",
      "vaaafffaaaaaaa=v",
      "vaaaaceeeedaaaav",
      "vaaaacaaaadaaaav",
      "vaaaacaaaadaaaav",
      "vaaaacaaaadaaaav",
      "vaaaacaaaadaaa=v",
      "vaaaacbbbbbaaa=v",
      "vaaaaaaaaaaaaa=v",
      "v=aaaaaaaaaaaa=v",
      "v=aaaaaaaaaaaa=v",
      "v===aaaaa======v",
      "vvvvvvvvvvvvvvvv"
    ],
    [
      "vvvvvvvvvvvvvvvv",
      "v== ===kkkk====v",
      "v= m aaaaaaaaa=v",
      "v=a aaaaaaaaaa=v",
      "vaaaaaaaaaaaaa=v",
      "vaaaallllllaaakv",
      "vaaaalaaaalaaakv",
      "vaaaalaaaalaaakv",
      "vaaaalaaaalaaakv",
      "vaaaalaaaalaaa=v",
      "vaaaallllllaaa=v",
      "vaaaaaaaaaaaaa=v",
      "v=aaaaaaaaaaaa=v",
      "v=aaaaaaaaaaaa=v",
      "v===kkkkk======v",
      "vvvvvvvvvvvvvvvv"
    ],
    [
      "vvvvvvvvvvvvvvvv",
      "v==a===nnnn====v",
      "v=aqaaaooooooo=v",
      "v=aaaaaooooooo=v",
      "vooooooooooooo=v",
      "vooooppppppooonv",
      "voooopoooopooonv",
      "voooopoooopooonv",
      "voooopoooopooonv",
      "voooopoooopooo=v",
      "vooooppppppooo=v",
      "vooooooooooooo=v",
      "v=oooooooooooo=v",
      "v=oooooooooooo=v",
      "v===nnnnn======v",
      "vvvvvvvvvvvvvvvv"
    ],
    [
      "vvvvvvvvvvvvvvvv",
      "v==f===rrrr====v",
      "v=afaaaooooooo=v",
      "v=aaaaaooooooo=v",
      "vooossssssssoo=v",
      "vooossssssssoorv",
      "vooossssssssoorv",
      "vooossssssssoorv",
      "vooossssssssoorv",
      "vooossssssssoo=v",
      "vuoossssssssoo=v",
      "vtoossssssssoo=v",
      "v=oooooooooooo=v",
      "v=oooooooooooo=v",
      "v===rrrrr======v",
      "vvvvvvvvvvvvvvvv"
    ],
    [
      "vvvvvvvvvvvvvvvv",
      "v==T===rrrr====v",
      "v=aaaaa  CBO  =v",
      "v=aaaaS       =v",
      "vIRIRRR     Q =v",
      "vP IL       BOrv",
      "vI I          rv",
      "vN I L        rv",
      "vN IL         rv",
      "vN IL       K =v",
      "vM IL       K =v",
      "vJ I        F =v",
      "v=ED CB   A   =v",
      "v=    y   xw  =v",
      "v===rrrrr======v",
      "vvvvvvvvvvvvvvvv"
    ]
  ]
}