{
  "name": "building_hoteld_base1_270",
  "refpalette": "deceasedcraft:building_hoteld/building_hoteld_base1_palette_270",
  "xsize": 16,
  "zsize": 16,
  "slices": [
    [
      "vvvvvvvvvvvvvvvv",
      "v====aaaa======v",
      "v=            =v",
      "v=       e b  =v",
      "v=            =v",
      "va            =v",
      "va            =v",
      "va            av",
      "va            av",
      "v=m i         av",
      "v=mli         av",
      "v=mmi         av",
      "von!j         =v",
      "v=mmi         =v",
      "v===k h gfdc===v",
      "vvvvvvvvvvvvvvvv"
    ],
    [
      "vvvvvvvvvvvvvvvv",
      "v====aaaa======v",
      "v=!           =v",
      "v=            =v",
      "v=            =v",
      "va            =v",
      "va            =v",
      "va            av",
      "va            av",
      "v=m i         av",
      "v=m i         av",
      "v=mli         av",
      "v=mmi         =v",
      "v=mmi         =v",
      "v===rqqqqpcd===v",
      "vvvvvvvvvvvvvvvv"
    ],
    [
      "vvvvvvvvvvvvvvvv",
      "v====aa a======v",
      "v=y           =v",
      "v=            =v",
      "v=            =v",
      "va            =v",
      "va            =v",
      "va            av",
      "va            av",
      "v=m i         av",
      "v=m i          v",
      "v=m i         av",
      "v=mli         =v",
      "v=mmi        s=v",
      "v===xwxwxwut===v",
      "vvvvvvvvvvvvvvvv"
    ],
    [
      "vvvvvvvvvvvvvvvv",
      "v==== a  ======v",
      "v=y          s=v",
      "v=            =v",
      "v=            =v",
      "va            =v",
      "v             =v",
      "va             v",
      "va            av",
      "v=m i          v",
      "v=m i          v",
      "v=m i         av",
      "v=m i         =v",
      "v=mAi        y=v",
      "v===        ===v",
      "vvvvvvvvvvvvvvvv"
    ],
    [
      "vvvvvvvvvvvvvvvv",
      "v====    ======v",
      "v=y          y=v",
      "v=            =v",
      "v=            =v",
      "v             =v",
      "v     BBBB    =v",
      "v     BDCB     v",
      "v     BDCB     v",
      "v=m E BBBB     v",
      "v=m E          v",
      "v=m E          v",
      "v=F E         =v",
      "v=  E        y=v",
      "v===        ===v",
      "vvvvvvvvvvvvvvvv"
    ],
    [
      "vvvvvvvvvvvvvvvv",
      "v====NMNM======v",
      "v=LLLLLLLLLLLL=v",
      "v=LLLLLLLLLLLL=v",
      "v=LLLLLLLLLLLL=v",
      "vILLLLLLLLLLLL=v",
      "vJLLLLLOOLLLLL=v",
      "vILLLLOQQOLLLLIv",
      "vJLLLLORQOLLLLJv",
      "v=mmLLLOOLLLLLKv",
      "v=mSLLLLLLLLLLIv",
      "v=F LLLLLLLLLLJv",
      "v=  LLLLLLLLLL=v",
      "v=  LLLLLLLLLL=v",
      "v===NMPNMPNM===v",
      "vvvvvvvvvvvvvvvv"
    ]
  ]
}