{
  "name": "building_hoteld_floor2_90",
  "refpalette": "deceasedcraft:building_hoteld/building_hoteld_floor2_palette_90",
  "xsize": 16,
  "zsize": 16,
  "slices": [
    [
      "                ",
      " a==h      i==a ",
      " =ddeeeeeeee  = ",
      " =dgd      d  = ",
      " ceggggggggdk = ",
      "  eggggggggjjl= ",
      "  eggggggggdjj= ",
      "  eggggggggggec ",
      " begggggggggge  ",
      " =dgggggggggge  ",
      " =dggggggggggeb ",
      " =dffffgggfffd= ",
      " =dffffggggffd= ",
      " =dddddeeeeddd= ",
      " a=====h  i===a ",
      "                "
    ],
    [
      "                ",
      " a==h      i==a ",
      " =ddeeeeeeee  = ",
      " =dsdBBBBBBdk = ",
      " ce y      dR = ",
      "  e d      O  = ",
      "  e xddddMddoo= ",
      "  erwwFdL wAEec ",
      " beqwAEdK wwFe  ",
      " =dpwAEdp wAEe  ",
      " =douoodJ oooeb ",
      " =dn  Dd  N Qd= ",
      " =dmt CdIxd Pd= ",
      " =dddddeeeeddd= ",
      " a=====h  i===a ",
      "                "
    ],
    [
      "                ",
      " a==h      i==a ",
      " =ddeeeeeeeek8= ",
      " =dUd      dR = ",
      " ce W      d  = ",
      "  e d      6  = ",
      "  e  dddd4ddoo= ",
      "  e   Zd3    ec ",
      " beT   d2   7e  ",
      " =dS   d!    e  ",
      " =doVood  oooeb ",
      " =d  Y d1 5  d= ",
      " =d  X d0 dX d= ",
      " =dddddeeeeddd= ",
      " a=====h  i===a ",
      "                "
    ],
    [
      "                ",
      " a==h      i==a ",
      " =ddeeeeeeee)j= ",
      " =d9d      d += ",
      " ce $      d  = ",
      "  e d ^    *  = ",
      "  e  dddd&ddoo= ",
      "  e    d     ec ",
      " be    d     e  ",
      " =d    d     e  ",
      " =dooood  oooeb ",
      " =d    d  $ (d= ",
      " =d #% d  d% d= ",
      " =dddddeeeeddd= ",
      " a=====h  i===a ",
      "                "
    ],
    [
      "                ",
      " a==h      i==a ",
      " =ddeeeeeeee  = ",
      " =d d      d l= ",
      " ce d      d += ",
      "  e d      d  = ",
      "  e  dddddddoo= ",
      "  e    d     ec ",
      " be    d     e  ",
      " =d    d     e  ",
      " =dooood  oooeb ",
      " =d    d  d  d= ",
      " =d    d  d  d= ",
      " =dddddeeeeddd= ",
      " a=====h  i===a ",
      "                "
    ],
    [
      "                ",
      " a==h      i==a ",
      " =ddeeeeeeee  = ",
      " =d-d      d  = ",
      " ce-d [  [ d l= ",
      "  e-d      d += ",
      "  e--dddddddoo= ",
      "  e----d-----ec ",
      " be----d-----e  ",
      " =d----d-----e  ",
      " =d----d-----eb ",
      " =d----d--d--d= ",
      " =d----d--d--d= ",
      " =dddddeeeeddd= ",
      " a=====h  i===a ",
      "                "
    ]
  ]
}