{
  "name": "building_hoteld_floor3_180",
  "refpalette": "deceasedcraft:building_hoteld/building_hoteld_floor3_palette_180",
  "xsize": 16,
  "zsize": 16,
  "slices": [
    [
      "                ",
      " a=====c  b===a ",
      " =   ljeeeeddd= ",
      " =  kjjggggggd= ",
      " ieddjdggggggd= ",
      "  e gggggggggei ",
      "  e ggggggggge  ",
      "  e ggggggggge  ",
      "  e gggggggfgeh ",
      "  e gggggggffd= ",
      "  e gggggggffd= ",
      " hedgggggggffd= ",
      " =dggggggggf!d= ",
      " =ddeeeeeddddd= ",
      " a==c   b=====a ",
      "                "
    ],
    [
      "                ",
      " a=====c  b===a ",
      " =    oeeeeddd= ",
      " = kQ oIyyyPOd= ",
      " ieddNdMLKy Jd= ",
      "  eA  dMLKy Jei ",
      "  eA  dIyyy Fe  ",
      "  eA  d      e  ",
      "  eA  dddxdEdeh ",
      "  eA  dDDCo Bd= ",
      "  eA  dyy x wd= ",
      " hedudtsrqo  d= ",
      " =dp      onmd= ",
      " =ddeeeeeddddd= ",
      " a==c   b=====a ",
      "                "
    ],
    [
      "                ",
      " a=====c  b===a ",
      " =3   oeeeeddd= ",
      " =kQ  o    21d= ",
      " iedd0d     Zd= ",
      "  e   d     Yei ",
      "  e   dX     e  ",
      "  e   d   W  e  ",
      "  e   dddUdVdeh ",
      "  e   d   o  d= ",
      "  e   d   U  d= ",
      " hedTdS   o Rd= ",
      " =dp      o  d= ",
      " =ddeeeeeddddd= ",
      " a==c   b=====a ",
      "                "
    ],
    [
      "                ",
      " a=====c  b===a ",
      " =j*  oeeeeddd= ",
      " =&   o    2^d= ",
      " iedd%d     $d= ",
      "  e   d      ei ",
      "  e   d      e  ",
      "  e  #d      e  ",
      "  e  9ddd8d8deh ",
      "  e   d   o  d= ",
      "  e   d   o 7d= ",
      " hed6d5   o 4d= ",
      " =dp      o  d= ",
      " =ddeeeeeddddd= ",
      " a==c   b=====a ",
      "                "
    ],
    [
      "                ",
      " a=====c  b===a ",
      " = l* oeeeeddd= ",
      " =    o    +!d= ",
      " iedddd     )d= ",
      "  e   d      ei ",
      "  e   d      e  ",
      "  e   d      e  ",
      "  e   dddddddeh ",
      "  e   d   o  d= ",
      "  e   d   o  d= ",
      " heddd(   o  d= ",
      " =d       o  d= ",
      " =ddeeeeeddddd= ",
      " a==c   b=====a ",
      "                "
    ],
    [
      "                ",
      " a=====c  b===a ",
      " =  l*oeeeeddd= ",
      " =    o------d= ",
      " iedddd------d= ",
      "  e   d------ei ",
      "  e [ d------e  ",
      "  e   d------e  ",
      "  e   dddddddeh ",
      "  e [ d------d= ",
      "  e   d------d= ",
      " heddd-------d= ",
      " =d----------d= ",
      " =ddeeeeeddddd= ",
      " a==c   b=====a ",
      "                "
    ]
  ]
}