{
  "name": "building_hoteld_base2_270",
  "refpalette": "deceasedcraft:building_hoteld/building_hoteld_base2_palette_270",
  "xsize": 16,
  "zsize": 16,
  "slices": [
    [
      "vvvvvvvvvvvvvvvv",
      "vaaaaaaaaaaaaaav",
      "vaaaaaaaaaaaaaav",
      "vaaaaaaaaaaaaaav",
      "vaaaaaaaaaaaaaav",
      "vaaaaaaaaaaaaaav",
      "vaaaaaaaaaaaaaav",
      "vaaaaaaaaaaaaaav",
      "vaaaaaaaaaaaaaav",
      "vaaaaaaaaaaaaaav",
      "vaaaaaaaaaaaaaav",
      "vaaaaaaaaaaaaaav",
      "vaaaaaaaaaaaaaav",
      "vaaaaaaaaaaaaaav",
      "vaaaaaaaaaaaaaav",
      "vvvvvvvvvvvvvvvv"
    ],
    [
      "vvvvvvvvvvvvvvvv",
      "v====aaaa======v",
      "v=aaaaaaaaaaaa=v",
      "v=aaaaaaaaaaaa=v",
      "v=aaaaaaaaaaaa=v",
      "vaaaadddddbaaa=v",
      "vaaaaeaaaabaaa=v",
      "vaaaaeaaaabaaaav",
      "vaaaaeaaaabaaaav",
      "v=fgfeaaaabaaaav",
      "v=i fccccccaaaav",
      "v=jhfaaaaaaaaaav",
      "v   aaaaaaaaaa=v",
      "v= aaaaaaaaaaa=v",
      "v===aaaaaaaa===v",
      "vvvvvvvvvvvvvvvv"
    ],
    [
      "vvvvvvvvvvvvvvvv",
      "v====kkkk======v",
      "v=aaaaaaaaaaaa=v",
      "v=aaaaaaaaaaaa=v",
      "v=aaaaaaaaaaaa=v",
      "vkaaallllllaaa=v",
      "vkaaalaaaalaaa=v",
      "vkaaalaaaalaaakv",
      "vkaaalaaaalaaakv",
      "v=aaalaaaalaaakv",
      "v=aaallllllaaakv",
      "v= aaaaaaaaaaakv",
      "v m aaaaaaaaaa=v",
      "v= aaaaaaaaaaa=v",
      "v===aaaaaaaa===v",
      "vvvvvvvvvvvvvvvv"
    ],
    [
      "vvvvvvvvvvvvvvvv",
      "v====nnnn======v",
      "v=oooooooooooo=v",
      "v=oooooooooooo=v",
      "v=oooooooooooo=v",
      "vnoooppppppooo=v",
      "vnooopoooopooo=v",
      "vnooopoooopooonv",
      "vnooopoooopooonv",
      "v=aaopoooopooonv",
      "v=aaoppppppooonv",
      "v=aaoooooooooonv",
      "vaqaoooooooooo=v",
      "v=aaoooooooooo=v",
      "v===oooooooo===v",
      "vvvvvvvvvvvvvvvv"
    ],
    [
      "vvvvvvvvvvvvvvvv",
      "v====rrrr======v",
      "v=oooooooooooo=v",
      "v=oooooooooooo=v",
      "v=oossssssssoo=v",
      "vroossssssssoo=v",
      "vroossssssssoo=v",
      "vroossssssssoorv",
      "vroossssssssoorv",
      "v=aassssssssoorv",
      "v=aassssssssoorv",
      "v=aassssssssoorv",
      "vffaoooooooooo=v",
      "v=aaoooooooooo=v",
      "v===oooooout===v",
      "vvvvvvvvvvvvvvvv"
    ],
    [
      "vvvvvvvvvvvvvvvv",
      "v====rrrr======v",
      "v=   O        =v",
      "v=  QB   KKF  =v",
      "v=O          w=v",
      "vrB         Ax=v",
      "vrC           =v",
      "vr            rv",
      "vr            rv",
      "v=aSR       Byrv",
      "v=aaR  L    C rv",
      "v=aaRL  LLL   rv",
      "vTaaIIIIIIIID =v",
      "v=aaR       E =v",
      "v===IPINNNMJ===v",
      "vvvvvvvvvvvvvvvv"
    ]
  ]
}