{
  "name": "multi_sunkenmonumentpark_0_ground",
  "refpalette": "deceasedcraft:multi_sunkenmonumentpark_0/multi_sunkenmonumentpark_0_ground_palette",
  "xsize": 16,
  "zsize": 16,
  "slices": [
    [
      "aaaaaaaaaaaaaaaa",
      "abaaaaaaaaaaaaaa",
      "aaaacccccccccccc",
      "aaaccccccccccccc",
      "aaccccccdddddddd",
      "aaccccdd        ",
      "aacccd      e   ",
      "aacccd   e      ",
      "aaccdff g    h  ",
      "aaccd           ",
      "aaccd  f   i  hh",
      "aaccd e     h   ",
      "aaccd           ",
      "aaccd      h    ",
      "aaccd e  i    j ",
      "aaccd           "
    ],
    [
      "                ",
      "             f  ",
      "       e  f f   ",
      "     g f e   g  ",
      "      f         ",
      "    e           ",
      "   g        h   ",
      "         h      ",
      "   e    i    j  ",
      "   f            ",
      "           h  jj",
      "   e  h     j   ",
      "  e             ",
      "           j    ",
      "   e  h  h    j ",
      "  f             "
    ],
    [
      "                ",
      "                ",
      "       h        ",
      "     i   h   i  ",
      "                ",
      "    h           ",
      "   i        j   ",
      "         j      ",
      "   h    h    j  ",
      "                ",
      "           j  jj",
      "   h  j     j   ",
      "  h             ",
      "           j    ",
      "   h  j  j    j ",
      "                "
    ],
    [
      "                ",
      "                ",
      "       j        ",
      "     h   j   h  ",
      "                ",
      "    j           ",
      "   h        j   ",
      "         j      ",
      "   j    j    k  ",
      "                ",
      "           j  jk",
      "   j  j         ",
      "  j             ",
      "           k    ",
      "   j  j  j    k ",
      "                "
    ],
    [
      "                ",
      "                ",
      "       j        ",
      "     j   j   j  ",
      "                ",
      "    j           ",
      "   j        k   ",
      "         k      ",
      "   j    j       ",
      "                ",
      "           k  k ",
      "   j  k         ",
      "  j             ",
      "                ",
      "   j     k      ",
      "                "
    ],
    [
      "                ",
      "                ",
      "       k        ",
      "     j   k   j  ",
      "                ",
      "                ",
      "   j            ",
      "                ",
      "   k    k       ",
      "                ",
      "                ",
      "   j            ",
      "  k             ",
      "                ",
      "   k            ",
      "                "
    ]
  ]
}