{
  "name": "multi_sunkenmonumentpark_0_base1",
  "refpalette": "deceasedcraft:multi_sunkenmonumentpark_0/multi_sunkenmonumentpark_0_base1_palette",
  "xsize": 16,
  "zsize": 16,
  "slices": [
    [
      "vvvvvvvvvvvvvvvv",
      "vaaaaaaaaaaaaaaa",
      "vaaaaaaaaaaaaaaa",
      "vaaaaaaaaaaaaaaa",
      "vaaaaaaaaaaaaaaa",
      "vaaaaaaaaaaaaaaa",
      "vaaaaaaaaaaaaaaa",
      "vaaaaaaaaaaaaaaa",
      "vaaaaaaaaaaaaaaa",
      "vaaaaaaaaaaaaaaa",
      "vaaaaaaaaaaaaaaa",
      "vaaaaaaaaaaaaaaa",
      "vaaaaaaaaaaaaaaa",
      "vaaaaaaaaaaaaaaa",
      "vaaaaaaaaaaaaaaa",
      "vaaaaaaaaaaaaaaa"
    ],
    [
      "vvvvvvvvvvvvvvvv",
      "vaaaaaaaaaaaaaaa",
      "vaaaaaaaaaaaaaaa",
      "vaaaaaaaaaaaaaaa",
      "vaaaaaaaaaaaaaaa",
      "vaaaaaaaaaaaaaaa",
      "vaaaaaaaaaaaaaaa",
      "vaaaaaaaaaaaaaaa",
      "vaaaaaaaaaaaaaaa",
      "vaaaaaaaaaaaaaaa",
      "vaaaaaaaaaaaaaaa",
      "vaaaaaaaaaaaaaaa",
      "vaaaaaaaaaaaaaaa",
      "vaaaaaaaaaaaaaaa",
      "vaaaaaaaaaaaaaaa",
      "vaaaaaaaaaaaaaaa"
    ],
    [
      "vvvvvvvvvvvvvvvv",
      "vaaaaaaaaaaaaaaa",
      "vaaaaaaaaaaaaaaa",
      "vaaaaaaaaaaaaaaa",
      "vaaaaaaaaaaaaaaa",
      "vaaaaaaaaaaaaaaa",
      "vaaaaaaaaaaaaaaa",
      "vaaaaaaaaaaaaaaa",
      "vaaaaaaaaaaaaaaa",
      "vaaaaaaaaaaaaaaa",
      "vaaaaaaaaaaaaaaa",
      "vaaaaaaaaaaaaaaa",
      "vaaaaaaaaaaaaaaa",
      "vaaaaaaaaaaaaaaa",
      "vaaaaaaaaaaaaaaa",
      "vaaaaaaaaaaaaaaa"
    ],
    [
      "vvvvvvvvvvvvvvvv",
      "vaaaaaaaaaaaaaaa",
      "vaaaaaaaaaaaaaaa",
      "vaaaaaaaaaaaaaaa",
      "vaaaaaaaaaaaaaaa",
      "vaaaaaaaaaaaaaaa",
      "vaaaaaaaaaaaaaaa",
      "vaaaaaaaaaaaaaaa",
      "vaaaaaaaaaaaaaaa",
      "vaaaaaaaaaaaaaaa",
      "vaaaaaaaaaaaaaaa",
      "vaaaaaaaaaaaaaab",
      "vaaaaaaaaaaaaabb",
      "vaaaaaaaaaaaabbb",
      "vaaaaaaaaaaabbbb",
      "vaaaaaaaaaabbbbb"
    ],
    [
      "vvvvvvvvvvvvvvvv",
      "v               ",
      "v               ",
      "v               ",
      "v               ",
      "v               ",
      "v               ",
      "v            bbb",
      "v          bbbbb",
      "v        bbbbbbb",
      "v        bbbbbbb",
      "v       bbbbbbbc",
      "v       bbbbbbc ",
      "v      bbbbbbc  ",
      "v      bbbbbc d ",
      "v      bbbbc    "
    ],
    [
      "vvvvvvvvvvvvvvvv",
      "v               ",
      "v               ",
      "v               ",
      "v       bbbbbbbb",
      "v     bbbbbbbbbb",
      "v    bbbbbbbbbbb",
      "v    bbbbbbbbccc",
      "v   bbbbbbbccd e",
      "v   bbbbbcc     ",
      "v   bbbbbc f  dd",
      "v   bbbbc e d   ",
      "v   bbbbc e     ",
      "v   bbbc e d    ",
      "v   bbbc f    g ",
      "v   bbbc  e     "
    ]
  ]
}