{
  "name": "multi_casino_5_base8",
  "refpalette": "deceasedcraft:multi_casino_5/multi_casino_5_base8_palette",
  "xsize": 16,
  "zsize": 16,
  "slices": [
    [
      "aaaaaaabbccccccc",
      "aaaaaabbcccccccc",
      "aaaaaabccccccccc",
      "aaaaabbccccccccc",
      "aaaabbcccccccccc",
      "aabbbccccccccccc",
      "abbccccccccdcccc",
      "bbcccccceccfcccc",
      "cccccccccccgcccc",
      "cccccccccccccccc",
      "cccccccdh!cccccc",
      "cccccccccccccccc",
      "cccccccccccccccc",
      "cccccccccccccccc",
      "cccccccccccccccc",
      "ccccccbbbbbccccc"
    ],
    [
      "aaaaai     j   k",
      "aaaaii    lmn   ",
      "aaaii      o    ",
      "aaii            ",
      "iii     pqrs    ",
      "i       ttuw    ",
      "           xy  A",
      "     BC e  Dy  E",
      "     FC    Iy  J",
      "  j  KL   Mw    ",
      " lmn sNOPQNs    ",
      "  o    y y      ",
      "        y       ",
      "R               ",
      "ST              ",
      "k         U     "
    ],
    [
      "                ",
      "           V    ",
      "                ",
      "                ",
      "                ",
      "           W    ",
      "        X       ",
      "       YeZ 0    ",
      "        1  2    ",
      "                ",
      "  3   4567      ",
      "                ",
      "                ",
      "                ",
      "8               ",
      "          U     "
    ],
    [
      "                ",
      "                ",
      "                ",
      "                ",
      "                ",
      "                ",
      "        9       ",
      "       #e$      ",
      "        %       ",
      "                ",
      "                ",
      "                ",
      "                ",
      "                ",
      "                ",
      "                "
    ],
    [
      "                ",
      "                ",
      "                ",
      "                ",
      "                ",
      "                ",
      "                ",
      "       ^e&      ",
      "        *       ",
      "                ",
      "                ",
      "                ",
      "                ",
      "                ",
      "                ",
      "                "
    ],
    [
      "                ",
      "                ",
      "                ",
      "                ",
      "                ",
      "                ",
      "                ",
      "        e       ",
      "                ",
      "                ",
      "                ",
      "                ",
      "                ",
      "                ",
      "                ",
      "                "
    ]
  ]
}