{
  "name": "multi_casino_5_base3",
  "refpalette": "deceasedcraft:multi_casino_5/multi_casino_5_base3_palette",
  "xsize": 16,
  "zsize": 16,
  "slices": [
    [
      "                ",
      "                ",
      "                ",
      "                ",
      "                ",
      "                ",
      "                ",
      "        a       ",
      "                ",
      "                ",
      "                ",
      "                ",
      "                ",
      "                ",
      "                ",
      "                "
    ],
    [
      "                ",
      "                ",
      "                ",
      "                ",
      "                ",
      "                ",
      "                ",
      "        a       ",
      "                ",
      "                ",
      "                ",
      "                ",
      "                ",
      "                ",
      "                ",
      "                "
    ],
    [
      "                ",
      "                ",
      "                ",
      "                ",
      "                ",
      "                ",
      "        b       ",
      "       cad      ",
      "        e       ",
      "                ",
      "                ",
      "                ",
      "                ",
      "                ",
      "                ",
      "                "
    ],
    [
      "                ",
      "                ",
      "                ",
      "                ",
      "                ",
      "                ",
      "                ",
      "        a       ",
      "                ",
      "                ",
      "                ",
      "                ",
      "                ",
      "                ",
      "                ",
      "                "
    ],
    [
      "fgfffffffffffffg",
      "ffgfffffffffffgf",
      "fffgfffffffffgff",
      "hfffhfffhfffhfff",
      "fffffgfffffgffff",
      "ffffffgfffgfffff",
      "fffffffgfgffffff",
      "hfffhfffafffhfff",
      "fffffffgfgffffff",
      "ffffffgfffgfffff",
      "fffffgfffffgffff",
      "hfffhfffhfffhfff",
      "fffgfffffffffgff",
      "ffgfffffffffffgf",
      "fgfffffffffffffg",
      "hfffff  i  fffff"
    ],
    [
      "jajjjjjjjjjjjjja",
      "jjajjjjjjjjjjjaj",
      "jjjajjjjjjjjjajj",
      "kjjjajjjkjjjajjj",
      "jjjjjajjjjjajjjj",
      "jjjjjjajjjajjjjj",
      "jjjjjjjajajjjjjj",
      "kjjjkjjjajjjkjjj",
      "jjjjjjjajajjjjjj",
      "jjjjjjajjjajjjjj",
      "jjjjjajjjjjajjjj",
      "kjjjajjjkjjjajjj",
      "jjjajjjjjjjjjajj",
      "jjajjjjjjjjjjjaj",
      "jajjjjjjjjjjjjja",
      "ajjjjjllllljjjjj"
    ]
  ]
}