{
  "name": "multi_casino_5_base7",
  "refpalette": "deceasedcraft:multi_casino_5/multi_casino_5_base7_palette",
  "xsize": 16,
  "zsize": 16,
  "slices": [
    [
      "                ",
      "                ",
      "                ",
      "                ",
      "                ",
      "                ",
      "                ",
      "        a       ",
      "                ",
      "                ",
      "                ",
      "                ",
      "                ",
      "                ",
      "                ",
      "                "
    ],
    [
      " b              ",
      "                ",
      "                ",
      "                ",
      "                ",
      "                ",
      "                ",
      "        a       ",
      "                ",
      "                ",
      "                ",
      "                ",
      "                ",
      "                ",
      "                ",
      "                "
    ],
    [
      " c              ",
      "                ",
      "                ",
      "b               ",
      "                ",
      "                ",
      "        d       ",
      "       eaf      ",
      "        g       ",
      "                ",
      "                ",
      "                ",
      "                ",
      "                ",
      "                ",
      "                "
    ],
    [
      "cc              ",
      "                ",
      "                ",
      "c               ",
      "                ",
      "                ",
      "                ",
      "        a       ",
      "                ",
      "                ",
      "                ",
      "                ",
      "                ",
      "                ",
      "                ",
      "                "
    ],
    [
      " h    ijjjjjjjji",
      "  k  iijjjjjjjij",
      "   k ijjjjjjjijj",
      "c   lijjmjjjmjjj",
      "c iiiijjjjjijjjj",
      "iiijjjijjjijjjjj",
      "jjjjjjjijijjjjjj",
      "mjjjmjjjajjjmjjj",
      "jjjjjjjijijjjjjj",
      "jjjjjjijjjijjjjj",
      "jjjjjijjjjjijjjj",
      "mjjjmjjjmjjjmjjj",
      "jjjijjjjjjjjjijj",
      "jjijjjjjjjjjjjij",
      "jijjjjjjjjjjjjji",
      "mjjjjjjjljjjjjjj"
    ],
    [
      "nannnhoooooooooa",
      "nnannoooooooooao",
      "nnnanooooooooaoo",
      "hnnnaooohoooaooo",
      "hhoooaoooooaoooo",
      "ooooooaoooaooooo",
      "oooooooaoaoooooo",
      "hooohoooaooohooo",
      "oooooooaoaoooooo",
      "ooooooaoooaooooo",
      "oooooaoooooaoooo",
      "hoooaooohoooaooo",
      "oooaoooooooooaoo",
      "ooaoooooooooooao",
      "oaoooooooooooooa",
      "aooooopppppooooo"
    ]
  ]
}