{
  "name": "multi_casino_5_base9",
  "refpalette": "deceasedcraft:multi_casino_5/multi_casino_5_base9_palette",
  "xsize": 16,
  "zsize": 16,
  "slices": [
    [
      "aaaaaaaaaaaaaaaa",
      "aaaaaaaaaaaaaaaa",
      "aaaaaaaaaaaaaaaa",
      "aaaaaaaaaaaaaaaa",
      "aaaaaaaaaaaaaaaa",
      "aaaaaaaaaaaaaaaa",
      "aaaaaaaaaaaaaaaa",
      "aaaaaaaaaaaaaaaa",
      "aaaaaaaaaaaaaaaa",
      "aaaaaaaaaaaaaaaa",
      "aaaaaaaaaaaaaaaa",
      "aaaaaaaaaaaaaaaa",
      "aaaaaaaaaaaaaaaa",
      "aaaaaaaaaaaaaaaa",
      "aaaaaaaaaaaaaaaa",
      "aaaaaaaaaaaaaaaa"
    ],
    [
      "bbbbbbbbbccccccc",
      "bbbbbbbbcccccccc",
      "bbbbbbbccccccccc",
      "bbbbbbbccccccccc",
      "bbbbbbcccccccccc",
      "bbbbbccccccccccc",
      "bbbccccccccccccc",
      "bbccccccdcccccce",
      "cccccccccccccccc",
      "cccccccccccccccc",
      "cccccccccccccccc",
      "cccccccccccccccc",
      "cccccccccccccccc",
      "ccccccccccccccc@",
      "cccccccceccccc@ ",
      "ccccec@@@@@ce@  "
    ],
    [
      "bbbbbbbbbccccccc",
      "bbbbbbbbcccccccc",
      "bbbbbbbccccccccc",
      "bbbbbbbccccccccc",
      "bbbbbbcccccccccc",
      "bbbbbccccccccccc",
      "bbbccccccccccccc",
      "bbccccccdcccccce",
      "cccccccccccccccc",
      "cccccccccccccccc",
      "cccccccccccccccc",
      "cccccccccccccccc",
      "cccccccccccccccc",
      "ccccccccccccccc@",
      "cccccccceccccc@ ",
      "ccccec@@@@@ce@  "
    ],
    [
      "bbbbbbbbbccccccc",
      "bbbbbbbbcccccccc",
      "bbbbbbbccccccccc",
      "bbbbbbbccccccccc",
      "bbbbbbcccccccccc",
      "bbbbbccccccccccc",
      "bbbccccccccccccc",
      "bbccccccdcccccce",
      "cccccccccccccccc",
      "cccccccccccccccc",
      "cccccccccccccccc",
      "cccccccccccccccc",
      "cccccccccccccccc",
      "ccccccccccccccc@",
      "cccccccceccccc@ ",
      "ccccec@@@@@ce@  "
    ],
    [
      "bbbbbbbbbccccccc",
      "bbbbbbbbcccccccc",
      "bbbbbbbccccccccc",
      "bbbbbbbccccccccc",
      "bbbbbbcccccccccc",
      "bbbbbccccccccccc",
      "bbbccccccccccccc",
      "bbccccccdccccccc",
      "cccccccccccccccc",
      "cccccccccccccccc",
      "cccccccccccccccc",
      "cccccccccccccccc",
      "cccccccccccccccc",
      "ccccccccccccccc@",
      "cccccccccccccc@ ",
      "ccccccfffffce@  "
    ],
    [
      "bdbbbbbbbccccccd",
      "bbdbbbbbccccccdc",
      "bbbdbbbccccccdcc",
      "bbbbdbbcccccdccc",
      "bbbbbdcccccdcccc",
      "bbbbbcdcccdccccc",
      "bbbccccdcdcccccc",
      "bbccccccdccccccc",
      "cccccccdcdcccccc",
      "ccccccdcccdccccc",
      "cccccdcccccdcccc",
      "ccccdcccccccdccc",
      "cccdcccccccccdcc",
      "ccdcccccccccccdf",
      "cdccccccccccccfd",
      "dcccccfffffccfgg"
    ]
  ]
}