{
  "name": "multi_casino_5_floor2",
  "refpalette": "deceasedcraft:multi_casino_5/multi_casino_5_floor2_palette",
  "xsize": 16,
  "zsize": 16,
  "slices": [
    [
      "       a a      ",
      "      a   a     ",
      "     a     a    ",
      "    a       a   ",
      "   a         a  ",
      "  a           a ",
      " a             a",
      "a               ",
      " a ~           a",
      "  a           a ",
      "   a         a  ",
      "    a       a   ",
      "     a     a    ",
      "      a   a     ",
      "       a a      ",
      "      bcacb     "
    ],
    [
      "dddddddededddddd",
      "ddddddedddeddddd",
      "dddddedddddedddd",
      "ddddedddddddeddd",
      "dddedddddddddedd",
      "ddeddddddddddded",
      "eeddddddddddddde",
      "feddddddddddddde",
      "efedddddddddddef",
      "defedddddddddefe",
      "ddefedddddddefed",
      "dddefedddddefedd",
      "ddddefedddefeddd",
      "dddddefedefedddd",
      "ddddddefefeddddd",
      "ddddeeffaffeeddd"
    ],
    [
      "                ",
      "                ",
      "                ",
      "                ",
      "                ",
      "                ",
      "                ",
      "        ~       ",
      "   ~            ",
      "                ",
      "                ",
      "                ",
      "                ",
      "                ",
      "                ",
      "      ggggg     "
    ],
    [
      "                ",
      "                ",
      "                ",
      "                ",
      "                ",
      "                ",
      "                ",
      "        ~       ",
      "   ~            ",
      "                ",
      "                ",
      "                ",
      "                ",
      "                ",
      "                ",
      "                "
    ],
    [
      "                ",
      "                ",
      "                ",
      "                ",
      "                ",
      "                ",
      "                ",
      "        ~       ",
      "   ~            ",
      "                ",
      "                ",
      "                ",
      "                ",
      "                ",
      "                ",
      "                "
    ],
    [
      "                ",
      "                ",
      "                ",
      "                ",
      "                ",
      "                ",
      "                ",
      "        ~       ",
      "   ~            ",
      "                ",
      "                ",
      "                ",
      "                ",
      "                ",
      "                ",
      "                "
    ]
  ]
}