{
  "name": "multi_casino_5_base4",
  "refpalette": "deceasedcraft:multi_casino_5/multi_casino_5_base4_palette",
  "xsize": 16,
  "zsize": 16,
  "slices": [
    [
      "aaaaaaaaaaaaaaaa",
      "aaaaaaaaaaaaaaaa",
      "aaaaaaaaaaaaaaaa",
      "aaaaaaaaaaaaaaaa",
      "aaaaaaaaaaaaaaaa",
      "aaaaaaaaaaaaaaaa",
      "aaaaaaaaaaabaaaa",
      "aaaaaaaacaa aaaa",
      "aaaaaaaaaaadaaaa",
      "aaaaaaaaaaaaaaaa",
      "aaaaaaabefaaaaaa",
      "aaaaaaaaaaaaaaaa",
      "aaaaaaaaaaaaaaaa",
      "aaaaaaaaaaaaaaaa",
      "aaaaaaaaaaaaaaaa",
      "aaaaaagaaagaaaaa"
    ],
    [
      "  hhhhh   hhhhh ",
      "ihhjjjhk lhj!jhk",
      "hhj mnn   nnmnn ",
      "hhjo            ",
      "hhjk    pqrs    ",
      "ihhk    ttuw    ",
      "  n        xy  A",
      "     BC c  Dy  E",
      "  F  IC    Jy  K",
      "ihhk LM   Nw    ",
      "hhjk sOPQROs    ",
      "hhjo   yyy      ",
      "hhjk            ",
      "ihhk            ",
      "  n             ",
      "      S   S     "
    ],
    [
      "                ",
      "    TU      VW  ",
      "  X             ",
      "  Y             ",
      "  Z             ",
      "           0    ",
      "           1    ",
      "        c       ",
      "           2    ",
      "                ",
      "  W   344       ",
      "  5             ",
      "  6             ",
      "                ",
      "                ",
      "          S     "
    ],
    [
      "                ",
      "                ",
      "                ",
      "                ",
      "                ",
      "                ",
      "        7       ",
      "       8c9      ",
      "        #       ",
      "                ",
      "                ",
      "                ",
      "                ",
      "                ",
      "                ",
      "                "
    ],
    [
      "                ",
      "                ",
      "                ",
      "                ",
      "                ",
      "                ",
      "        $       ",
      "        c%      ",
      "        ^       ",
      "                ",
      "                ",
      "                ",
      "                ",
      "                ",
      "                ",
      "                "
    ],
    [
      "                ",
      "                ",
      "                ",
      "                ",
      "                ",
      "                ",
      "                ",
      "        c       ",
      "                ",
      "                ",
      "                ",
      "                ",
      "                ",
      "                ",
      "                ",
      "                "
    ]
  ]
}