{
  "name": "multi_casino_5_ground",
  "refpalette": "deceasedcraft:multi_casino_5/multi_casino_5_ground_palette",
  "xsize": 16,
  "zsize": 16,
  "slices": [
    [
      "abbbbbbbabbcHHHH",
      "abbbbbbbabbcHHHH",
      "abbbbbbbabbcHHHH",
      "abbbbbbbabbcHHHH",
      "ccccccccccccHHHH",
      "dddddddddddcHHHH",
      "eeeeeeeeeedcHHHH",
      "eeeeeeeefedcHHHH",
      "eeeeeeeeeedcHHHH",
      "eeeeeeeeeedcHHHH",
      "eeeeeeeeeedccHHH",
      "eeeeeeeeeeedcHHH",
      "eeeeeeeeeeedcHHH",
      "eeeeeeeeeeedccHH",
      "eeeeeeeeeeeedccH",
      "eeeeeedeeeeeddcH"
    ],
    [
      "          ghi  j",
      "          ghi  j",
      "          ghi  j",
      "          khi  j",
      "hhhhhhhhhhhhi  j",
      "           hi  j",
      "           hi  j",
      "   ~    f  hi  j",
      "lm nlm     hi  j",
      "           hop j",
      "           hhi q",
      "            hi  ",
      "            hop ",
      "            hhop",
      "             hhi",
      "      r       ho"
    ],
    [
      "                ",
      "                ",
      "                ",
      "          s     ",
      "                ",
      "                ",
      "        f       ",
      "       ftf      ",
      "   ~    f       ",
      "                ",
      "                ",
      "                ",
      "                ",
      "                ",
      "                ",
      "                "
    ],
    [
      "                ",
      "                ",
      "                ",
      "                ",
      "                ",
      "        f       ",
      "                ",
      "      f   f     ",
      "   ~            ",
      "        f       ",
      "                ",
      "                ",
      "                ",
      "                ",
      "                ",
      "                "
    ],
    [
      "                ",
      "                ",
      "                ",
      "                ",
      "                ",
      "        f       ",
      "                ",
      "      f   f     ",
      "   ~            ",
      "        f       ",
      "                ",
      "                ",
      "                ",
      "                ",
      "                ",
      "                "
    ],
    [
      "                ",
      "                ",
      "                ",
      "                ",
      "        f       ",
      "                ",
      "                ",
      "     f     f    ",
      "   ~            ",
      "                ",
      "        f       ",
      "                ",
      "                ",
      "                ",
      "                ",
      "                "
    ]
  ]
}