{
  "name": "multi_casino_5_base1",
  "refpalette": "deceasedcraft:multi_casino_5/multi_casino_5_base1_palette",
  "xsize": 16,
  "zsize": 16,
  "slices": [
    [
      "                ",
      "                ",
      "                ",
      "                ",
      "                ",
      "       aaa      ",
      "      b c d     ",
      "      befgd     ",
      "      b h d     ",
      "       iii      ",
      "                ",
      "                ",
      "                ",
      "                ",
      "                ",
      "                "
    ],
    [
      "                ",
      "                ",
      "                ",
      "                ",
      "                ",
      "                ",
      "                ",
      "        f       ",
      "                ",
      "                ",
      "                ",
      "                ",
      "                ",
      "                ",
      "                ",
      "                "
    ],
    [
      "                ",
      "                ",
      "                ",
      "                ",
      "                ",
      "                ",
      "        j       ",
      "       kfl      ",
      "        m       ",
      "                ",
      "                ",
      "                ",
      "                ",
      "                ",
      "                ",
      "                "
    ],
    [
      "                ",
      "                ",
      "                ",
      "                ",
      "                ",
      "                ",
      "                ",
      "        f       ",
      "                ",
      "                ",
      "                ",
      "                ",
      "                ",
      "                ",
      "                ",
      "                "
    ],
    [
      "nonnnnnnnnnnnnno",
      "nnonnnnnnnnnnnon",
      "nnnonnnnnnnnnonn",
      "pnnnpnnnpnnnpnnn",
      "nnnnnonnnnnonnnn",
      "nnnnnnonnnonnnnn",
      "nnnnnnnononnnnnn",
      "pnnnpnnnfnnnpnnn",
      "nnnnnnnononnnnnn",
      "nnnnnnonnnonnnnn",
      "nnnnnonnnnnonnnn",
      "pnnnpnnnpnnnpnnn",
      "nnnonnnnnnnnnonn",
      "nnonnnnnnnnnnnon",
      "nonnnnnnnnnnnnno",
      "pnnnnn  q  nnnnn"
    ],
    [
      "rfrrrrrrrrrrrrrf",
      "rrfrrrrrrrrrrrfr",
      "rrrfrrrrrrrrrfrr",
      "srrrfrrrsrrrfrrr",
      "rrrrrfrrrrrfrrrr",
      "rrrrrrfrrrfrrrrr",
      "rrrrrrrfrfrrrrrr",
      "srrrsrrrfrrrsrrr",
      "rrrrrrrfrfrrrrrr",
      "rrrrrrfrrrfrrrrr",
      "rrrrrfrrrrrfrrrr",
      "srrrfrrrsrrrfrrr",
      "rrrfrrrrrrrrrfrr",
      "rrfrrrrrrrrrrrfr",
      "rfrrrrrrrrrrrrrf",
      "frrrrrtttttrrrrr"
    ]
  ]
}