{
  "name": "multi_casino_5_base2",
  "refpalette": "deceasedcraft:multi_casino_5/multi_casino_5_base2_palette",
  "xsize": 16,
  "zsize": 16,
  "slices": [
    [
      "aaaaaaaaaaaaaaaa",
      "aaaaaaaaaaaaaaaa",
      "aaaaaaaaaaaaaaaa",
      "aaaaaaaaaaaaaaaa",
      "aaaaaaaaaaaaaaaa",
      "aaaaaaaaaaaaaaaa",
      "aaaaaaaaaaaaaaaa",
      "aaaaaaaabaaaaaaa",
      "aaaaaaaaaaaaaaaa",
      "aaaaaaaaaaaaaaaa",
      "aaaaaaaaaaaaaaaa",
      "aaaaaaaaaaaaaaaa",
      "aaaaaaaaaaaaaaaa",
      "aaaaaaaaaaaaaaaa",
      "aaaaaaaaaaaaaaaa",
      "aaaaaacaaacaaaaa"
    ],
    [
      " ddddddddd      ",
      "edddd  f        ",
      "dddg  hhhh      ",
      "ddd  ijjjjk     ",
      "dd  ijjjljk     ",
      "dd mjjj nop     ",
      "ddgmjjq   r    s",
      "dd mjlt bu     w",
      "dd mjj  k      x",
      "    uuyA        ",
      "                ",
      "                ",
      "                ",
      "                ",
      "                ",
      "      B   B     "
    ],
    [
      "  C   D EF      ",
      " E IF           ",
      "DJ              ",
      "K L             ",
      " J              ",
      "DI              ",
      "M               ",
      "NC      b       ",
      "                ",
      "                ",
      "                ",
      "                ",
      "                ",
      "                ",
      "                ",
      "          B     "
    ],
    [
      "                ",
      "                ",
      "                ",
      "                ",
      "                ",
      "                ",
      "                ",
      "        b       ",
      "                ",
      "                ",
      "                ",
      "                ",
      "                ",
      "                ",
      "                ",
      "                "
    ],
    [
      "                ",
      "                ",
      "                ",
      "                ",
      "                ",
      "                ",
      "                ",
      "        b       ",
      "                ",
      "                ",
      "                ",
      "                ",
      "                ",
      "                ",
      "                ",
      "                "
    ],
    [
      "                ",
      "                ",
      "                ",
      "                ",
      "                ",
      "                ",
      "                ",
      "        b       ",
      "                ",
      "                ",
      "                ",
      "                ",
      "                ",
      "                ",
      "                ",
      "                "
    ]
  ]
}