{
  "name": "multi_casino_15_base4",
  "refpalette": "deceasedcraft:multi_casino_15/multi_casino_15_base4_palette",
  "xsize": 16,
  "zsize": 16,
  "slices": [
    [
      "aaaaaaaaaabcdefv",
      "aaaaaaaaaabcdefv",
      "aaaaaaaaaabcdefv",
      "aaaaaaaaaabcgefv",
      "aaaaaaaaaabcdefv",
      "aaaaaaaaaabcdefv",
      "aaaaaaaaaabcdefv",
      "aaaaaaaahabcdefv",
      "aaaaaaaaaabcdefv",
      "bbbbbbbbbbbcdefv",
      "ccccccccccccdefv",
      "ddddgdddddddgefv",
      "eeeeeeeeeeeeeefv",
      "fffffffffffffffv",
      "fffffffffffffffv",
      "vvvvvvvvvvvvvvvv"
    ],
    [
      "     iij    kefv",
      "    illmn   kefv",
      "   illlmn   kefv",
      "  illllo   pgefv",
      " illll      kefv",
      " illl q     kefv",
      " rmmn       kefv",
      "  oo    h   kefv",
      "            kefv",
      "            kefv",
      "    s       kefv",
      "kkkkgkkkkkkkgefv",
      "eeeeeeeeeeeeeefv",
      "fffffffffffffffv",
      "fffffffffffffffv",
      "vvvvvvvvvvvvvvvv"
    ],
    [
      "            kefv",
      "            kefv",
      "            kefv",
      "            gefv",
      "            kefv",
      "            kefv",
      "            kefv",
      "        h   kefv",
      "            kefv",
      "            kefv",
      "            kefv",
      "kkkkgkkkkkkkgefv",
      "eeeeeeeeeeeeeefv",
      "fffffffffffffffv",
      "fffffffffffffffv",
      "vvvvvvvvvvvvvvvv"
    ],
    [
      "            kefv",
      "            kefv",
      "            kefv",
      "            gefv",
      "            kefv",
      "            kefv",
      "            kefv",
      "        h   kefv",
      "            kefv",
      "            kefv",
      "            kefv",
      "kkkkgkkkkkkkgefv",
      "eeeeeeeeeeeeeefv",
      "fffffffffffffffv",
      "fffffffffffffffv",
      "vvvvvvvvvvvvvvvv"
    ],
    [
      "            kefv",
      "            kefv",
      "            kefv",
      "            gefv",
      "            kefv",
      "            kefv",
      "            kefv",
      "        h   kefv",
      "            kefv",
      "            kefv",
      "            kefv",
      "kkkkgkkkkkkkgefv",
      "eeeeeeeeeeeeeefv",
      "fffffffffffffffv",
      "fffffffffffffffv",
      "vvvvvvvvvvvvvvvv"
    ],
    [
      "            kefv",
      "             efv",
      "            kefv",
      "            gefv",
      "            kefv",
      "            kefv",
      "            kefv",
      "        h   kefv",
      "            kefv",
      "            kefv",
      "            kefv",
      "kkkkgkkkk kkgefv",
      "eeeeeeeeeeeeeefv",
      "fffffffffffffffv",
      "fffffffffffffffv",
      "vvvvvvvvvvvvvvvv"
    ]
  ]
}