{
  "name": "multi_casino_15_base7",
  "refpalette": "deceasedcraft:multi_casino_15/multi_casino_15_base7_palette",
  "xsize": 16,
  "zsize": 16,
  "slices": [
    [
      "             abv",
      "             abv",
      "            cabv",
      "            dabv",
      "            cabv",
      "             abv",
      "            cabv",
      "        e   cabv",
      "             abv",
      "            cabv",
      "            cabv",
      "c ccdcc c  cdabv",
      "aaaaaaaaaaaaaabv",
      "bbbbbbbbbbbbbbbv",
      "bbbbbbbbbbbbbbbv",
      "vvvvvvvvvvvvvvvv"
    ],
    [
      " f           abv",
      "             abv",
      "             abv",
      "            dabv",
      "             abv",
      "             abv",
      "             abv",
      "        e   cabv",
      "             abv",
      "             abv",
      "            cabv",
      "   cdc      dabv",
      "aaaaaaaaaaaaaabv",
      "bbbbbbbbbbbbbbbv",
      "bbbbbbbbbbbbbbbv",
      "vvvvvvvvvvvvvvvv"
    ],
    [
      " g           abv",
      "             abv",
      "             abv",
      "f           dabv",
      "             abv",
      "             abv",
      "             abv",
      "        e    abv",
      "             abv",
      "             abv",
      "             abv",
      "    d       dabv",
      "aaaaaaaaaaaaaabv",
      "bbbbbbbbbbbbbbbv",
      "bbbbbbbbbbbbbbbv",
      "vvvvvvvvvvvvvvvv"
    ],
    [
      "gg           abv",
      "             abv",
      "             abv",
      "g           dabv",
      "             abv",
      "             abv",
      "             abv",
      "        e    abv",
      "             abv",
      "             abv",
      "             abv",
      "    d       dabv",
      "aaaaaaaaaaaaaabv",
      "bbbbbbbbbbbbbbbv",
      "bbbbbbbbbbbbbbbv",
      "vvvvvvvvvvvvvvvv"
    ],
    [
      "hi    jhhhhh abv",
      "  k  jjhhhhh abv",
      "   k jhhhhhh abv",
      "g   ljhhmhhhdabv",
      "g jjjjhhhhhj abv",
      "jjjhhhjhhhjh abv",
      "hhhhhhhjhjhh abv",
      "mhhhmhhhehhh abv",
      "hhhhhhhhhjhh abv",
      "hhhhhhhhhhjh abv",
      "hhhhhhhhhhhj abv",
      "    d       dabv",
      "aaaaaaaaaaaaaabv",
      "bbbbbbbbbbbbbbbv",
      "bbbbbbbbbbbbbbbv",
      "vvvvvvvvvvvvvvvv"
    ],
    [
      "neoooinnnnnpqabv",
      "ooeoonnnnnnpqabv",
      "oooeonnnnnnpqabv",
      "ioooennnonnndabv",
      "iinnnennnnneqabv",
      "nnnnnnennnepqabv",
      "nnnnnnnenenpqabv",
      "onnnonnnennpqabv",
      "nnnnnnnenenpqabv",
      "nnnnnnennnepqabv",
      "ppppnepppppeqabv",
      "rrrrdrrrrrrrdabv",
      "aaaaaaaaaaaaaabv",
      "bbbbbbbbbbbbbbbv",
      "bbbbbbbbbbbbbbbv",
      "vvvvvvvvvvvvvvvv"
    ]
  ]
}