{
  "name": "multi_casino_15_base5",
  "refpalette": "deceasedcraft:multi_casino_15/multi_casino_15_base5_palette",
  "xsize": 16,
  "zsize": 16,
  "slices": [
    [
      "             abv",
      "             abv",
      "            cabv",
      "            dabv",
      "            cabv",
      "             abv",
      "            cabv",
      "        e   cabv",
      "             abv",
      "            cabv",
      "            cabv",
      "c ccdcc c  cdabv",
      "aaaaaaaaaaaaaabv",
      "bbbbbbbbbbbbbbbv",
      "bbbbbbbbbbbbbbbv",
      "vvvvvvvvvvvvvvvv"
    ],
    [
      "             abv",
      "             abv",
      "             abv",
      "            dabv",
      "             abv",
      "             abv",
      "             abv",
      "        e   cabv",
      "             abv",
      "             abv",
      "            cabv",
      "   cdc      dabv",
      "aaaaaaaaaaaaaabv",
      "bbbbbbbbbbbbbbbv",
      "bbbbbbbbbbbbbbbv",
      "vvvvvvvvvvvvvvvv"
    ],
    [
      "             abv",
      "             abv",
      "             abv",
      "            dabv",
      "             abv",
      "             abv",
      "        f    abv",
      "       ge    abv",
      "             abv",
      "             abv",
      "             abv",
      "    d       dabv",
      "aaaaaaaaaaaaaabv",
      "bbbbbbbbbbbbbbbv",
      "bbbbbbbbbbbbbbbv",
      "vvvvvvvvvvvvvvvv"
    ],
    [
      "             abv",
      "             abv",
      "             abv",
      "            dabv",
      "             abv",
      "             abv",
      "             abv",
      "        e    abv",
      "             abv",
      "             abv",
      "             abv",
      "    d       dabv",
      "aaaaaaaaaaaaaabv",
      "bbbbbbbbbbbbbbbv",
      "bbbbbbbbbbbbbbbv",
      "vvvvvvvvvvvvvvvv"
    ],
    [
      "hihhhhhhhhhh abv",
      "hhihhhhhhhhh abv",
      "hhhihhhhhhhh abv",
      "jhhhjhhhjhhhdabv",
      "hhhhhihhhhhi abv",
      "hhhhhhihhhih abv",
      "hhhhhhhihihh abv",
      "jhhhjhhhehhh abv",
      "hhhhhhhhhihh abv",
      "hhhhhhhhhhih abv",
      "hhhhhhhhhhhi abv",
      "    d       dabv",
      "aaaaaaaaaaaaaabv",
      "bbbbbbbbbbbbbbbv",
      "bbbbbbbbbbbbbbbv",
      "vvvvvvvvvvvvvvvv"
    ],
    [
      "kekkkkkkkkklmabv",
      "kkekkkkkkkklmabv",
      "kkkekkkkkkklmabv",
      "nkkkekkknkkkdabv",
      "kkkkkekkkkkemabv",
      "kkkkkkekkkelmabv",
      "kkkkkkkekeklmabv",
      "nkkknkkkekklmabv",
      "kkkkkkkekeklmabv",
      "kkkkkkekkkelmabv",
      "llllkelllllemabv",
      "oooodooooooodabv",
      "aaaaaaaaaaaaaabv",
      "bbbbbbbbbbbbbbbv",
      "bbbbbbbbbbbbbbbv",
      "vvvvvvvvvvvvvvvv"
    ]
  ]
}