{
  "name": "multi_casino_15_ground",
  "refpalette": "deceasedcraft:multi_casino_15/multi_casino_15_ground_palette",
  "xsize": 16,
  "zsize": 16,
  "slices": [
    [
      "abbbbbbbabbcdHHH",
      "abeeeeeeeeefdHHH",
      "abeeeeeeeeefdHHH",
      "abeeeeeeeeefdHHH",
      "abeeeeeeeeefdHHH",
      "abeeeeeeeeefdHHH",
      "abbbbbbbabbcdHHH",
      "gaaaaaaahaacdHHH",
      "abbbbbbbabbcdHHH",
      "abbbbbbbabbcdHHH",
      "ccccccccccccdHHH",
      "dddddddbibddHHHH",
      "HHHHHHHbbbHHHHHH",
      "HHHHHHHbbbHHHHHH",
      "HHHHHHHHHHHHHHHH",
      "HHHHHHHHHHHHHHHH"
    ],
    [
      "           j    ",
      "    kllkm  n    ",
      "   opqqprs n    ",
      "   tuwx cy n    ",
      "   opAAprB n    ",
      "    CDDCE  n    ",
      "           j    ",
      "     ~~ F  j    ",
      "          Ij    ",
      "IIIIIIIIIIIj    ",
      "jjjjjjjJJJjj    ",
      "       KLK      ",
      "  M   NKOK      ",
      "  P   QKKK      ",
      "                ",
      "                "
    ],
    [
      "                ",
      "      R         ",
      "   STUUVVW      ",
      "   SX UWYW      ",
      "   STUUVVW      ",
      "      Z         ",
      "                ",
      "      ~ 0       ",
      "                ",
      "                ",
      "                ",
      "        L       ",
      "        1       ",
      "                ",
      "                ",
      "                "
    ],
    [
      "                ",
      "                ",
      "                ",
      "   2W34         ",
      "                ",
      "                ",
      "                ",
      "      ~ I       ",
      "                ",
      "                ",
      "                ",
      "        L       ",
      "                ",
      "                ",
      "                ",
      "                "
    ],
    [
      "                ",
      "                ",
      "                ",
      "                ",
      "                ",
      "                ",
      "                ",
      "      ~ 5       ",
      "                ",
      "                ",
      "                ",
      "        L       ",
      "                ",
      "                ",
      "                ",
      "                "
    ],
    [
      "                ",
      "                ",
      "                ",
      "                ",
      "                ",
      "                ",
      "                ",
      "      ~ 5       ",
      "                ",
      "                ",
      "                ",
      "        L       ",
      "                ",
      "                ",
      "                ",
      "                "
    ]
  ]
}