{
  "name": "multi_casino_15_base9",
  "refpalette": "deceasedcraft:multi_casino_15/multi_casino_15_base9_palette",
  "xsize": 16,
  "zsize": 16,
  "slices": [
    [
      "aaaaaaaaabbbbbbv",
      "aaaaaaaaabbbbbbv",
      "aaaaaaaaabbbbbbv",
      "aaaaaaaaabbbbbbv",
      "aaaaaaaaabbbbbbv",
      "aaaaaaaaabbbbbbv",
      "aaaaaaaaabbbbbbv",
      "aaaaaaaaabbbbbbv",
      "bbbbbbbbbbbbbbbv",
      "bbbbbbbbbbbbbbbv",
      "bbbbbbbbbbbbbbbv",
      "bbbbbbbbbbbbbbbv",
      "bbbbbbbbbbbbbbbv",
      "bbbbbbbbbbbbbbbv",
      "bbbbbbbbbbbbbbbv",
      "vvvvvvvvvvvvvvvv"
    ],
    [
      "bbbbbbbbbbbbbbbv",
      "bbbbbbbbbbbbbbbv",
      "bbbbbbbbbbbbbbbv",
      "bbbbbbbbbbbbbbbv",
      "bbbbbbbbbbbbbbbv",
      "bbbbbbbbbbbbbbbv",
      "bbbbbbbbbbbbbbbv",
      "bbbbbbbbcbbbbbbv",
      "bbbbbbbbbbbbbbbv",
      "bbbbbbbbbbbbbbbv",
      "bbbbbbbbbbbbbbbv",
      "bbbbbbbbbbbbbbbv",
      "bbbbbbbbbbbbbbbv",
      "bbbbbbbbbbbbbbbv",
      "bbbbbbbbbbbbbbbv",
      "vvvvvvvvvvvvvvvv"
    ],
    [
      "bbbbbbbbbbbbbbbv",
      "bbbbbbbbbbbbbbbv",
      "bbbbbbbbbbbbbbbv",
      "bbbbbbbbbbbbbbbv",
      "bbbbbbbbbbbbbbbv",
      "bbbbbbbbbbbbbbbv",
      "bbbbbbbbbbbbbbbv",
      "bbbbbbbbcbbbbbbv",
      "bbbbbbbbbbbbbbbv",
      "bbbbbbbbbbbbbbbv",
      "bbbbbbbbbbbbbbbv",
      "bbbbbbbbbbbbbbbv",
      "bbbbbbbbbbbbbbbv",
      "bbbbbbbbbbbbbbbv",
      "bbbbbbbbbbbbbbbv",
      "vvvvvvvvvvvvvvvv"
    ],
    [
      "bbbbbbbbbbbbbbbv",
      "bbbbbbbbbbbbbbbv",
      "bbbbbbbbbbbbbbbv",
      "bbbbbbbbbbbbbbbv",
      "bbbbbbbbbbbbbbbv",
      "bbbbbbbbbbbbbbbv",
      "bbbbbbbbbbbbbbbv",
      "bbbbbbbbcbbbbbbv",
      "bbbbbbbbbbbbbbbv",
      "bbbbbbbbbbbbbbbv",
      "bbbbbbbbbbbbbbbv",
      "bbbbbbbbbbbbbbbv",
      "bbbbbbbbbbbbbbbv",
      "bbbbbbbbbbbbbbbv",
      "bbbbbbbbbbbbbbbv",
      "vvvvvvvvvvvvvvvv"
    ],
    [
      "bbbbbbbbbbbbbbbv",
      "bbbbbbbbbbbbbbbv",
      "bbbbbbbbbbbbbbbv",
      "bbbbbbbbbbbbbbbv",
      "bbbbbbbbbbbbbbbv",
      "bbbbbbbbbbbbbbbv",
      "bbbbbbbbbbbbbbbv",
      "bbbbbbbbcbbbbbbv",
      "bbbbbbbbbbbbbbbv",
      "bbbbbbbbbbbbbbbv",
      "bbbbbbbbbbbbbbbv",
      "bbbbbbbbbbbbbbbv",
      "bbbbbbbbbbbbbbbv",
      "bbbbbbbbbbbbbbbv",
      "bbbbbbbbbbbbbbbv",
      "vvvvvvvvvvvvvvvv"
    ],
    [
      "bcbbbbbbbbbbbbbv",
      "bbcbbbbbbbbbbbbv",
      "bbbcbbbbbbbbbbbv",
      "bbbbcbbbbbbbbbbv",
      "bbbbbcbbbbbbbbbv",
      "bbbbbbcbbbbbbbbv",
      "bbbbbbbcbbbbbbbv",
      "bbbbbbbbcbbbbbbv",
      "bbbbbbbbbbbbbbbv",
      "bbbbbbbbbbbbbbbv",
      "bbbbbbbbbbbbbbbv",
      "bbbbbbbbbbbbbbbv",
      "bbbbbbbbbbbbbbbv",
      "bbbbbbbbbbbbbbbv",
      "bbbbbbbbbbbbbbbv",
      "vvvvvvvvvvvvvvvv"
    ]
  ]
}