{
  "name": "multi_casino_15_base6",
  "refpalette": "deceasedcraft:multi_casino_15/multi_casino_15_base6_palette",
  "xsize": 16,
  "zsize": 16,
  "slices": [
    [
      "aaaaaaaaaabcdefv",
      "aaaaaaaaaabcdefv",
      "aaaaaaaaaabcdefv",
      "aaaaaaaaaabcgefv",
      "aaaaaaaaaabcdefv",
      "aaaaaaaaaabcdefv",
      "aaaaaaaaaabcdefv",
      "aaaaaaaahabcdefv",
      "aaaaaaaaaabcdefv",
      "bbbbbbbbbbbcdefv",
      "ccccccccccccdefv",
      "ddddgdddddddgefv",
      "eeeeeeeeeeeeeefv",
      "fffffffffffffffv",
      "fffffffffffffffv",
      "vvvvvvvvvvvvvvvv"
    ],
    [
      "            iefv",
      "   jkj      iefv",
      "  lmnmo     iefv",
      "o kn!nk    pgefv",
      "k lmnmo     iefv",
      "o  qkq      iefv",
      "            iefv",
      "        h   iefv",
      "            iefv",
      "            iefv",
      "    r       iefv",
      "iiiigiiiiiiigefv",
      "eeeeeeeeeeeeeefv",
      "fffffffffffffffv",
      "fffffffffffffffv",
      "vvvvvvvvvvvvvvvv"
    ],
    [
      "            iefv",
      "            iefv",
      "   stu      iefv",
      "   twt      gefv",
      "   stu      iefv",
      "            iefv",
      "            iefv",
      "        h   iefv",
      "            iefv",
      "            iefv",
      "            iefv",
      "iiiigiiiiiiigefv",
      "eeeeeeeeeeeeeefv",
      "fffffffffffffffv",
      "fffffffffffffffv",
      "vvvvvvvvvvvvvvvv"
    ],
    [
      "            iefv",
      "            iefv",
      "            iefv",
      "    x       gefv",
      "            iefv",
      "            iefv",
      "            iefv",
      "        h   iefv",
      "            iefv",
      "            iefv",
      "            iefv",
      "iiiigiiiiiiigefv",
      "eeeeeeeeeeeeeefv",
      "fffffffffffffffv",
      "fffffffffffffffv",
      "vvvvvvvvvvvvvvvv"
    ],
    [
      "            iefv",
      "            iefv",
      "            iefv",
      "            gefv",
      "            iefv",
      "            iefv",
      "            iefv",
      "        h   iefv",
      "            iefv",
      "            iefv",
      "            iefv",
      "iiiigiiiiiiigefv",
      "eeeeeeeeeeeeeefv",
      "fffffffffffffffv",
      "fffffffffffffffv",
      "vvvvvvvvvvvvvvvv"
    ],
    [
      "            iefv",
      "             efv",
      "            iefv",
      "            gefv",
      "            iefv",
      "            iefv",
      "            iefv",
      "        h   iefv",
      "            iefv",
      "            iefv",
      "            iefv",
      "iiiigiiii iigefv",
      "eeeeeeeeeeeeeefv",
      "fffffffffffffffv",
      "fffffffffffffffv",
      "vvvvvvvvvvvvvvvv"
    ]
  ]
}