{
  "name": "multi_casino_15_base3",
  "refpalette": "deceasedcraft:multi_casino_15/multi_casino_15_base3_palette",
  "xsize": 16,
  "zsize": 16,
  "slices": [
    [
      "             abv",
      "             abv",
      "            cabv",
      "            dabv",
      "            cabv",
      "       eee   abv",
      "      f g   cabv",
      "      fhi   cabv",
      "      f      abv",
      "            cabv",
      "            cabv",
      "c ccdcc c  cdabv",
      "aaaaaaaaaaaaaabv",
      "bbbbbbbbbbbbbbbv",
      "bbbbbbbbbbbbbbbv",
      "vvvvvvvvvvvvvvvv"
    ],
    [
      "             abv",
      "             abv",
      "             abv",
      "            dabv",
      "             abv",
      "             abv",
      "             abv",
      "        i   cabv",
      "             abv",
      "             abv",
      "            cabv",
      "   cdc      dabv",
      "aaaaaaaaaaaaaabv",
      "bbbbbbbbbbbbbbbv",
      "bbbbbbbbbbbbbbbv",
      "vvvvvvvvvvvvvvvv"
    ],
    [
      "             abv",
      "             abv",
      "             abv",
      "            dabv",
      "             abv",
      "             abv",
      "        j    abv",
      "       ki    abv",
      "             abv",
      "             abv",
      "             abv",
      "    d       dabv",
      "aaaaaaaaaaaaaabv",
      "bbbbbbbbbbbbbbbv",
      "bbbbbbbbbbbbbbbv",
      "vvvvvvvvvvvvvvvv"
    ],
    [
      "             abv",
      "             abv",
      "             abv",
      "            dabv",
      "             abv",
      "             abv",
      "             abv",
      "        i    abv",
      "             abv",
      "             abv",
      "             abv",
      "    d       dabv",
      "aaaaaaaaaaaaaabv",
      "bbbbbbbbbbbbbbbv",
      "bbbbbbbbbbbbbbbv",
      "vvvvvvvvvvvvvvvv"
    ],
    [
      "lmllllllllll abv",
      "llmlllllllll abv",
      "lllmllllllll abv",
      "nlllnlllnllldabv",
      "lllllmlllllm abv",
      "llllllmlllml abv",
      "lllllllmlmll abv",
      "nlllnlllilll abv",
      "lllllllllmll abv",
      "llllllllllml abv",
      "lllllllllllm abv",
      "    d       dabv",
      "aaaaaaaaaaaaaabv",
      "bbbbbbbbbbbbbbbv",
      "bbbbbbbbbbbbbbbv",
      "vvvvvvvvvvvvvvvv"
    ],
    [
      "oiooooooooopqabv",
      "ooioooooooopqabv",
      "oooiooooooopqabv",
      "roooiooorooodabv",
      "oooooioooooiqabv",
      "ooooooioooipqabv",
      "oooooooioiopqabv",
      "roooroooioopqabv",
      "oooooooioiopqabv",
      "ooooooioooipqabv",
      "ppppoipppppiqabv",
      "ssssdsssssssdabv",
      "aaaaaaaaaaaaaabv",
      "bbbbbbbbbbbbbbbv",
      "bbbbbbbbbbbbbbbv",
      "vvvvvvvvvvvvvvvv"
    ]
  ]
}