{
  "name": "multi_casino_15_base8",
  "refpalette": "deceasedcraft:multi_casino_15/multi_casino_15_base8_palette",
  "xsize": 16,
  "zsize": 16,
  "slices": [
    [
      "aaaaaaaaaabcdefv",
      "aaaaaaaaaabcdefv",
      "aaaaaaaaaabcdefv",
      "aaaaaaaaaabcgefv",
      "aaaaaaaaaabcdefv",
      "aaaaaaaaaabcdefv",
      "aaaaaaaaaabcdefv",
      "aaaaaaaahabcdefv",
      "aaaaaaaaaabcdefv",
      "bbbbbbbbbbbcdefv",
      "ccccccccccccdefv",
      "ddddgdddddddgefv",
      "eeeeeeeeeeeeeefv",
      "fffffffffffffffv",
      "fffffffffffffffv",
      "vvvvvvvvvvvvvvvv"
    ],
    [
      "aaaaaaaaai  jefv",
      "aaaaaaaaai  jefv",
      "aaaaaaaaak  jefv",
      "aaaaaaaaa  lgefv",
      "aaaaaaaaa   jefv",
      "aaaaaaaaa   jefv",
      "aaaaaaaaa   jefv",
      "aaaaaaaah   jefv",
      "mmmn        jefv",
      "            jefv",
      "    o       jefv",
      "jjjjgjjjjjjjgefv",
      "eeeeeeeeeeeeeefv",
      "fffffffffffffffv",
      "fffffffffffffffv",
      "vvvvvvvvvvvvvvvv"
    ],
    [
      "            jefv",
      "            jefv",
      "            jefv",
      "            gefv",
      "            jefv",
      "            jefv",
      "            jefv",
      "        h   jefv",
      "            jefv",
      "            jefv",
      "            jefv",
      "jjjjgjjjjjjjgefv",
      "eeeeeeeeeeeeeefv",
      "fffffffffffffffv",
      "fffffffffffffffv",
      "vvvvvvvvvvvvvvvv"
    ],
    [
      "            jefv",
      "            jefv",
      "            jefv",
      "            gefv",
      "            jefv",
      "            jefv",
      "            jefv",
      "        h   jefv",
      "            jefv",
      "            jefv",
      "            jefv",
      "jjjjgjjjjjjjgefv",
      "eeeeeeeeeeeeeefv",
      "fffffffffffffffv",
      "fffffffffffffffv",
      "vvvvvvvvvvvvvvvv"
    ],
    [
      "            jefv",
      "            jefv",
      "            jefv",
      "            gefv",
      "            jefv",
      "            jefv",
      "            jefv",
      "        h   jefv",
      "            jefv",
      "            jefv",
      "            jefv",
      "jjjjgjjjjjjjgefv",
      "eeeeeeeeeeeeeefv",
      "fffffffffffffffv",
      "fffffffffffffffv",
      "vvvvvvvvvvvvvvvv"
    ],
    [
      "            jefv",
      "             efv",
      "            jefv",
      "            gefv",
      "            jefv",
      "            jefv",
      "            jefv",
      "        h   jefv",
      "            jefv",
      "            jefv",
      "            jefv",
      "jjjjgjjjj jjgefv",
      "eeeeeeeeeeeeeefv",
      "fffffffffffffffv",
      "fffffffffffffffv",
      "vvvvvvvvvvvvvvvv"
    ]
  ]
}