{
  "name": "multi_casino_15_base2",
  "refpalette": "deceasedcraft:multi_casino_15/multi_casino_15_base2_palette",
  "xsize": 16,
  "zsize": 16,
  "slices": [
    [
      "aaaaaaaaaabcdefv",
      "aaaaaaaaaabcdefv",
      "aaaaaaaaaabcdefv",
      "aaaaaaaaaabcgefv",
      "aaaaaaaaaabcdefv",
      "aaaaaaaaaabcdefv",
      "aaaaaaaaaabcdefv",
      "aaaaaaaahabcdefv",
      "aaaaaaaaaabcdefv",
      "bbbbbbbbbbbcdefv",
      "ccccccccccccdefv",
      "ddddgdddddddgefv",
      "eeeeeeeeeeeeeefv",
      "fffffffffffffffv",
      "fffffffffffffffv",
      "vvvvvvvvvvvvvvvv"
    ],
    [
      "      i     jefv",
      "      k     jefv",
      "     k      jefv",
      "k    l     mgefv",
      "l  knopk    jefv",
      "opk  i      jefv",
      "i    k      jefv",
      "k       h   jefv",
      "            jefv",
      "            jefv",
      "    q       jefv",
      "jjjjgjjjjjjjgefv",
      "eeeeeeeeeeeeeefv",
      "fffffffffffffffv",
      "fffffffffffffffv",
      "vvvvvvvvvvvvvvvv"
    ],
    [
      "      r     jefv",
      "            jefv",
      "            jefv",
      "     s      gefv",
      "s   tuw     jefv",
      "uw   r      jefv",
      "r           jefv",
      "        h   jefv",
      "            jefv",
      "            jefv",
      "            jefv",
      "jjjjgjjjjjjjgefv",
      "eeeeeeeeeeeeeefv",
      "fffffffffffffffv",
      "fffffffffffffffv",
      "vvvvvvvvvvvvvvvv"
    ],
    [
      "      x     jefv",
      "            jefv",
      "            jefv",
      "     y      gefv",
      "y   AuB     jefv",
      "uB   x      jefv",
      "x           jefv",
      "        h   jefv",
      "            jefv",
      "            jefv",
      "            jefv",
      "jjjjgjjjjjjjgefv",
      "eeeeeeeeeeeeeefv",
      "fffffffffffffffv",
      "fffffffffffffffv",
      "vvvvvvvvvvvvvvvv"
    ],
    [
      "      C     jefv",
      "            jefv",
      "            jefv",
      "     D      gefv",
      "D   E F     jefv",
      " F   C      jefv",
      "C           jefv",
      "        h   jefv",
      "            jefv",
      "            jefv",
      "            jefv",
      "jjjjgjjjjjjjgefv",
      "eeeeeeeeeeeeeefv",
      "fffffffffffffffv",
      "fffffffffffffffv",
      "vvvvvvvvvvvvvvvv"
    ],
    [
      "            jefv",
      "             efv",
      "            jefv",
      "            gefv",
      "     I      jefv",
      "I           jefv",
      "            jefv",
      "        h   jefv",
      "            jefv",
      "            jefv",
      "            jefv",
      "jjjjgjjjj jjgefv",
      "eeeeeeeeeeeeeefv",
      "fffffffffffffffv",
      "fffffffffffffffv",
      "vvvvvvvvvvvvvvvv"
    ]
  ]
}