{
  "name": "multi_communitycenter_7_floor1",
  "refpalette": "deceasedcraft:multi_communitycenter_7/multi_communitycenter_7_floor1_palette",
  "xsize": 16,
  "zsize": 16,
  "slices": [
    [
      "a  b       a c  ",
      "a d eeebe  a c  ",
      "ab   b   b afc  ",
      "a  ee eeg  afc  ",
      "a b  e   b a c  ",
      "a e eee d  a c  ",
      "a  b   e b a c  ",
      "a          afc  ",
      "a          afc  ",
      "a          a c  ",
      "a          a c  ",
      "ahhh       a c  ",
      "iiiiii   jkafc  ",
      "llllli   mnafc  ",
      "lllllih    a c  ",
      "lllllih  ooa c  "
    ],
    [
      "                ",
      "                ",
      "            f   ",
      "            f   ",
      "                ",
      "                ",
      "                ",
      "            f   ",
      "            f   ",
      "                ",
      "                ",
      "                ",
      "            f   ",
      "            f   ",
      "                ",
      "                "
    ],
    [
      "                ",
      "                ",
      "            f   ",
      "            f   ",
      "                ",
      "                ",
      "                ",
      "            f   ",
      "            f   ",
      "                ",
      "                ",
      "                ",
      "            f   ",
      "            f   ",
      "                ",
      "                "
    ],
    [
      "                ",
      "                ",
      "            p   ",
      "            p   ",
      "                ",
      "                ",
      "                ",
      "            p   ",
      "            p   ",
      "                ",
      "                ",
      "                ",
      "            p   ",
      "            p   ",
      "                ",
      "                "
    ],
    [
      "qqqqqqqqqqqqrss ",
      "qqqqqqqqqqqqrss ",
      "qqqqqqqqqqqqrss ",
      "qqqqqqqqqqqqrss ",
      "qqqqqqqqqqqqrss ",
      "qqqqqqqqqqqqrss ",
      "qqqqqqqqqqqqrss ",
      "qqqqqqqqqqqqrss ",
      "qqqqqqqqqqqqrss ",
      "qqqqqqqqqqqqrss ",
      "qqqqqqqqqqqqrss ",
      "qqqqqqqqqqqqrss ",
      "qqqqqqqqqqqqrss ",
      "qqqqqqqqqqqqrss ",
      "qqqqqqqqqqqqrss ",
      "qqqqqqqqqqqqrss "
    ],
    [
      "                ",
      "                ",
      "                ",
      "                ",
      "                ",
      "                ",
      "                ",
      "                ",
      "      ~         ",
      "                ",
      "                ",
      "                ",
      "                ",
      "                ",
      "                ",
      "                "
    ]
  ]
}