{
  "name": "multi_communitycenter_7_ground",
  "refpalette": "deceasedcraft:multi_communitycenter_7/multi_communitycenter_7_ground_palette",
  "xsize": 16,
  "zsize": 16,
  "slices": [
    [
      "aaab    baaaaacd",
      "aaab    baaaaacd",
      "aaab    baaaaacd",
      "aaabeeeebaaaaacd",
      "aaabbbbbbaaaaacd",
      "aaaaaaaaaaaaaacd",
      "aaaaaaaaaaaaaacd",
      "aaaaaaaaaaaaaacd",
      "aaaaaaaaaaaaaacd",
      "aaaaaaaaaaaaaacd",
      "aaaaaaaaaaaaaacd",
      "aaaaaaaaaaaaaacd",
      "ffffffaaaaaaaacd",
      "ggggggaaaaaaaacd",
      "ggggggaaaaaaaacd",
      "ggggggaaaaaaaacd"
    ],
    [
      "  hi    ih   jk ",
      " lmi    im  nop ",
      " qmi    im rrop ",
      " smiiiiiim t op ",
      "  hmmmmmmh  njk ",
      "   uwwxyA    op ",
      "        B  rrop ",
      "        A  t op ",
      "  CD E   hFFFjk ",
      "   I E  A n nop ",
      "   J  E B rrrop ",
      "   K!E  A t top ",
      "LMNNNN   hFFFjk ",
      "  A  N  A n nop ",
      "  O PN  B rrrop ",
      "  AQQN  A t top "
    ],
    [
      "  h      h   j  ",
      "  m      m   o  ",
      "  m      m  !o  ",
      "  m      m   o  ",
      "  hmmmmmmh   j  ",
      "     RSTA    o  ",
      "        U  V o  ",
      "        A    o  ",
      "    W    hXXXj  ",
      "    W   A    o  ",
      "    W   U   Yo  ",
      "    W   A    o  ",
      "Z0NNNN   hXXXj  ",
      "  A  N  A    o  ",
      "  1  N  U   2o  ",
      "  AQQN  A    o  "
    ],
    [
      "  h      h   j  ",
      "  m      m   3  ",
      "  m      m   3  ",
      "  m      m   3  ",
      "  hmmmmmmh   j  ",
      "   45556A    3  ",
      "        A    3  ",
      "        A    3  ",
      "         hFFFj  ",
      "        A    3  ",
      "        A    3  ",
      "        A    3  ",
      "NNNNNN   hFFFj  ",
      "  A77N  A    3  ",
      "  A77N  A    3  ",
      "  A88N  A    3  "
    ],
    [
      "  h      h   j  ",
      "  m      m   o  ",
      "  m      m   o  ",
      "  m      m   o  ",
      " 9hmmmmmmh9  j  ",
      "   #####A    o  ",
      "        A    o  ",
      "        A    o  ",
      "  $     9hFFFj  ",
      "        A    o  ",
      "        A    o  ",
      "        A    o  ",
      "NNNNNN   hFFFj  ",
      "   %^N  A    o  ",
      "    ^N  A    o  ",
      "   %%N  A    o  "
    ],
    [
      "aaaaaaaaaaaaa&  ",
      "aaaaaaaaaaaaa&  ",
      "aaaaaaaaaaaaa&  ",
      "aaaaaaaaaaaaa&  ",
      "aaaaaaaaaaaaaj  ",
      "aaaaaaaaaaaaa&  ",
      "aaaaaaaaaaaaa&  ",
      "aaaaaaaaaaaaa&  ",
      "aaaaaaaaaaaaa&  ",
      "aaaaaaaaaaaaa&  ",
      "aaaaaaaaaaaaa&  ",
      "aaaaaaaaaaaaa&  ",
      "NNNNNNaaaaaaaj  ",
      "bbbbbNaaaaaaa&  ",
      "bbbbbNaaaaaaa&  ",
      "bbbbbNaaaaaaa&  "
    ]
  ]
}