{
  "name": "building_policeoffice1_floor3",
  "refpalette": "deceasedcraft:building_policeoffice1/building_policeoffice1_floor3_palette",
  "xsize": 16,
  "zsize": 16,
  "slices": [
    [
      "                ",
      "  aaaaaaaaaa    ",
      "  abbbbbbbba    ",
      "  abbbbbbbba    ",
      "  abbbbbbbba    ",
      "  abbbbbbbba    ",
      "  abbbbbbbba    ",
      "  abbbbbbbba    ",
      "  abbbbbbbba    ",
      "  abbbbbbbba    ",
      "  abbbbbbbba    ",
      " cdefebbcccccgc ",
      " cfffebbh     c ",
      " cfffebi      c ",
      " ccjccjccjccjcc ",
      "                "
    ],
    [
      "                ",
      "  akkkkkkkkk    ",
      "  a        k    ",
      "  a   l l  k    ",
      "  a mnoop  k    ",
      "  a  qrrst k    ",
      "  a mqrrs  k    ",
      "  a  uwwxt k    ",
      "  a  y y   k    ",
      "  a        k    ",
      "  aA    ABBa    ",
      " cdeCeDEcccccFc ",
      " cIJ e        c ",
      " cKLMe Ni     c ",
      " ccjccjccjccjcc ",
      "                "
    ],
    [
      "                ",
      "  akkkkkkkkk    ",
      "  a        k    ",
      "  a        k    ",
      "  a  OP Q  k    ",
      "  a     P  k    ",
      "  a  P     k    ",
      "  a  R PS  k    ",
      "  a        k    ",
      "  a        k    ",
      "  aT    T Ua    ",
      " cdeVeWXcccccFc ",
      " cY  e        c ",
      " cZL e  Ni    c ",
      " ccjccjccjccjcc ",
      "                "
    ],
    [
      "                ",
      "  akkkkkkkkk    ",
      "  a        k    ",
      "  0        k    ",
      "  0   11   k    ",
      "  0  2334  k    ",
      "  g  2334  k    ",
      "  0   55   k    ",
      "  0        k    ",
      "  0        k    ",
      "  a      67a    ",
      " cde8e99cccccFc ",
      " c#  !    $$  c ",
      " c %^e   Ni$  c ",
      " ccjccjccjccjcc ",
      "                "
    ],
    [
      "                ",
      "  akkkkkkkkk    ",
      "  a        k    ",
      "  a        k    ",
      "  a        k    ",
      "  a   &&   k    ",
      "  a   &&   k    ",
      "  a        k    ",
      "  a        k    ",
      "  a        k    ",
      "  a        a    ",
      " cdeee**cccccFc ",
      " c())e   +h - c ",
      " c())e      - c ",
      " ccjccjccjccjcc ",
      "                "
    ],
    [
      "                ",
      "  a[[[[[[[[[    ",
      "  a]]]]]]]][    ",
      "  a]]]]]]]][    ",
      "  a]]]]]]]][    ",
      "  a]]]]]]]][    ",
      "  a]]]]]]]][    ",
      "  a]]]]]]]][    ",
      "  a]]]]]]]][    ",
      "  a]]]]]]]][    ",
      "  a]]]]]]]]a    ",
      " cdeee{{cccccFc ",
      " cd}ee  +h    c ",
      " cdd}e        c ",
      " cc|ccjccjccjcc ",
      "   ;            "
    ]
  ]
}