{
  "name": "building_policeoffice1_top_270",
  "refpalette": "deceasedcraft:building_policeoffice1/building_policeoffice1_top_palette_270",
  "xsize": 16,
  "zsize": 16,
  "slices": [
    [
      "                ",
      " cccc           ",
      " cbbdaaaaaaaaaa ",
      " jbbdbbbbbbbbba ",
      " cbbdbbbbbbbbba ",
      " cffcbbbbbbbbba ",
      " jffbbbbbbbbbba ",
      " cifbbbbbbbbbba ",
      " c gcbbbbbbbbba ",
      " j  cbbbbbbbbba ",
      " c  cbbbbbbbbba ",
      " c  caaaaaaaaaa ",
      " j  c           ",
      " c  e           ",
      " chhc           ",
      "                "
    ],
    [
      "                ",
      " cccc           ",
      " cu!caaaaaaaaaa ",
      " j  c  q   nn a ",
      " cwtddddddd oka ",
      " c  c   dl pp a ",
      " j  r   d lnnla ",
      " cx s   ddd!oka ",
      " c  c     lpp a ",
      " j  c        ma ",
      " c  c         a ",
      " c  caaaaaaaaaa ",
      " j  c           ",
      " c  e           ",
      " cccc           ",
      "                "
    ],
    [
      "                ",
      " cccc           ",
      " cIIc CBDCBBBBy ",
      " j Jc      nn A ",
      " cLtc      oo   ",
      " c  c      pp A ",
      " j  E      nn A ",
      " c  F      oo A ",
      " c  c      pp q ",
      " j  c         A ",
      " c  c         A ",
      " c  cCCC CC CCy ",
      " j  c           ",
      " c  e           ",
      " cKKc           ",
      "                "
    ],
    [
      "                ",
      " cccc           ",
      " cOOc           ",
      " j  c           ",
      " cttc      y    ",
      " cP c           ",
      " j  N           ",
      " c  N      yM   ",
      " c  c           ",
      " j  c           ",
      " c  c           ",
      " c  c           ",
      " j  c           ",
      " c  e           ",
      " cKKc           ",
      "                "
    ],
    [
      "                ",
      " cccc           ",
      " cRRc           ",
      " c lc           ",
      " cttc      Q    ",
      " cSSc           ",
      " cSSc           ",
      " cSSc      Q    ",
      " cSSc           ",
      " cSSc           ",
      " cSSc           ",
      " cSSc           ",
      " cSSc           ",
      " cTTc           ",
      " cccc           ",
      "                "
    ],
    [
      "                ",
      " cccc           ",
      " cccc           ",
      " cccc      U    ",
      " cccc      UU   ",
      " cccc           ",
      " cccc           ",
      " cccc      UU   ",
      " cccc      U    ",
      " cccc           ",
      " cccc           ",
      " cccc           ",
      " cccc           ",
      " cccc           ",
      " cccc           ",
      "                "
    ]
  ]
}