{
  "name": "building_policeoffice1_floor1_270",
  "refpalette": "deceasedcraft:building_policeoffice1/building_policeoffice1_floor1_palette_270",
  "xsize": 16,
  "zsize": 16,
  "slices": [
    [
      "                ",
      " cccc           ",
      " cffdaaaaaaaaaa ",
      " jffebbbbbbbbba ",
      " cfffbbbbbbbbba ",
      " ceeebbbbbbbbba ",
      " jbbbbbbbbbbbba ",
      " cibbbbbbbbbbba ",
      " c hcbbbbbbbbba ",
      " j  cbbbbbbbbba ",
      " c  cbbbbbbbbba ",
      " c  caaaaaaaaaa ",
      " j  c           ",
      " c  g           ",
      " cccc           ",
      "                "
    ],
    [
      "                ",
      " cccc           ",
      " cFEdaaaaaaaaaa ",
      " jI ewBAyws   k ",
      " cJ C     t m k ",
      " ceee    xuqnlk ",
      " j        ooo k ",
      " cK           k ",
      " ci c p  p  p k ",
      " j  crnlrnlrnlk ",
      " c  coo oo oo k ",
      " c  cakkkkkkkkk ",
      " j  c           ",
      " c  D           ",
      " cccc           ",
      "                "
    ],
    [
      "                ",
      " cccc           ",
      " cXWdaaaaaaaaaa ",
      " jI eR TSRP   k ",
      " c  V     Q   k ",
      " ceee      NL k ",
      " j            k ",
      " c            k ",
      " cK c         k ",
      " ji cUM OM OM k ",
      " c  c         k ",
      " c  cakkkkkkkkk ",
      " j  c           ",
      " c  D           ",
      " cccc           ",
      "                "
    ],
    [
      "                ",
      " cccc           ",
      " c51daYYYgYYYaa ",
      " j6 e         k ",
      " c720         k ",
      " ce3e         k ",
      " j            k ",
      " c            k ",
      " c  c         k ",
      " jK cZ        k ",
      " ci4c         k ",
      " c44cakkkkkkkkk ",
      " j  c           ",
      " c  D           ",
      " cccc           ",
      "                "
    ],
    [
      "                ",
      " cccc           ",
      " c88daaaaaaaaaa ",
      " j99e         k ",
      " c99e         k ",
      " ceee         k ",
      " j            k ",
      " c            k ",
      " c  c         k ",
      " j #c         k ",
      " c hc         k ",
      " c  cakkkkkkkkk ",
      " j$$c           ",
      " c  D           ",
      " cccc           ",
      "                "
    ],
    [
      "                ",
      " cccc           ",
      " cdddaaaaaaaaaa ",
      "-+d)e^^^^^^^^^% ",
      " c) e^^^^^^^^^% ",
      " ceee^^^^^^^^^% ",
      " j  (^*^^*^^&^% ",
      " c  (^!^^*^^*^% ",
      " c #c^^^^^^^^^% ",
      " j hc^^^^^^^^^% ",
      " c  c^^^^^^^^^% ",
      " c  ca%%%%%%%%% ",
      " j  c           ",
      " c  D           ",
      " cccc           ",
      "                "
    ]
  ]
}