{
  "name": "building_policeoffice1_floor1_90",
  "refpalette": "deceasedcraft:building_policeoffice1/building_policeoffice1_floor1_palette_90",
  "xsize": 16,
  "zsize": 16,
  "slices": [
    [
      "                ",
      "           cccc ",
      "           g  c ",
      "           c  j ",
      " aaaaaaaaaac  c ",
      " abbbbbbbbbc  c ",
      " abbbbbbbbbc  j ",
      " abbbbbbbbbch c ",
      " abbbbbbbbbbbic ",
      " abbbbbbbbbbbbj ",
      " abbbbbbbbbeeec ",
      " abbbbbbbbbfffc ",
      " abbbbbbbbbeffj ",
      " aaaaaaaaaadffc ",
      "           cccc ",
      "                "
    ],
    [
      "                ",
      "           cccc ",
      "           D  c ",
      "           c  j ",
      " kkkkkkkkkac  c ",
      " k oo oo ooc  c ",
      " klnrlnrlnrc  j ",
      " k p  p  p c ic ",
      " k           Kc ",
      " k ooo        j ",
      " klnqux    eeec ",
      " k m t     C Jc ",
      " k   swyABwe Ij ",
      " aaaaaaaaaadEFc ",
      "           cccc ",
      "                "
    ],
    [
      "                ",
      "           cccc ",
      "           D  c ",
      "           c  j ",
      " kkkkkkkkkac  c ",
      " k         c  c ",
      " k MO MO MUc ij ",
      " k         c Kc ",
      " k            c ",
      " k            j ",
      " k LN      eeec ",
      " k   Q     V  c ",
      " k   PRST Re Ij ",
      " aaaaaaaaaadWXc ",
      "           cccc ",
      "                "
    ],
    [
      "                ",
      "           cccc ",
      "           D  c ",
      "           c  j ",
      " kkkkkkkkkac44c ",
      " k         c4ic ",
      " k        Zc Kj ",
      " k         c  c ",
      " k            c ",
      " k            j ",
      " k         e3ec ",
      " k         027c ",
      " k         e 6j ",
      " aaYYYgYYYad15c ",
      "           cccc ",
      "                "
    ],
    [
      "                ",
      "           cccc ",
      "           D  c ",
      "           c$$j ",
      " kkkkkkkkkac  c ",
      " k         ch c ",
      " k         c# j ",
      " k         c  c ",
      " k            c ",
      " k            j ",
      " k         eeec ",
      " k         e99c ",
      " k         e99j ",
      " aaaaaaaaaad88c ",
      "           cccc ",
      "                "
    ],
    [
      "                ",
      "           cccc ",
      "           D  c ",
      "           c  j ",
      " %%%%%%%%%ac  c ",
      " %^^^^^^^^^c  c ",
      " %^^^^^^^^^ch j ",
      " %^^^^^^^^^c# c ",
      " %^*^^*^^!^(  c ",
      " %^&^^*^^*^(  j ",
      " %^^^^^^^^^eeec ",
      " %^^^^^^^^^e )c ",
      " %^^^^^^^^^e)d+-",
      " aaaaaaaaaadddc ",
      "           cccc ",
      "                "
    ]
  ]
}