{
  "name": "building_policeoffice1_floor3_90",
  "refpalette": "deceasedcraft:building_policeoffice1/building_policeoffice1_floor3_palette_90",
  "xsize": 16,
  "zsize": 16,
  "slices": [
    [
      "                ",
      "           cccc ",
      "           g  c ",
      "           c  j ",
      " aaaaaaaaaac  c ",
      " abbbbbbbbbc  c ",
      " abbbbbbbbbc  j ",
      " abbbbbbbbbch c ",
      " abbbbbbbbbbbic ",
      " abbbbbbbbbbbbj ",
      " abbbbbbbbbeeec ",
      " abbbbbbbbbfffc ",
      " abbbbbbbbbeffj ",
      " aaaaaaaaaadffc ",
      "           cccc ",
      "                "
    ],
    [
      "                ",
      "           cccc ",
      "           F  c ",
      "           c  j ",
      " kkkkkkkkkac  c ",
      " k        Bc  c ",
      " k   t t  Bc  j ",
      " k lpssx  Ac ic ",
      " k  orrwy  E Nc ",
      " k lorrw   D  j ",
      " k  nqquy  eeec ",
      " k  m m    C Mc ",
      " k        AeJLj ",
      " aaaaaaaaaadIKc ",
      "           cccc ",
      "                "
    ],
    [
      "                ",
      "           cccc ",
      "           F  c ",
      "           c  j ",
      " kkkkkkkkkac  c ",
      " k        Uc  c ",
      " k         c ij ",
      " k  QP S  Tc Nc ",
      " k     P   X  c ",
      " k  P      W  j ",
      " k  O PR   eeec ",
      " k         V  c ",
      " k        Te Lj ",
      " aaaaaaaaaadYZc ",
      "           cccc ",
      "                "
    ],
    [
      "                ",
      "           cccc ",
      "           F  c ",
      "           c  j ",
      " kkkkkkkkkac$$c ",
      " k        7c$ic ",
      " k        6c Nj ",
      " k   44    c  c ",
      " k  1335   9  c ",
      " k  1335   9  j ",
      " k   22    e!ec ",
      " k         8 ^c ",
      " k         e %j ",
      " aa000g000ad# c ",
      "           cccc ",
      "                "
    ],
    [
      "                ",
      "           cccc ",
      "           F  c ",
      "           c--j ",
      " kkkkkkkkkac  c ",
      " k         ch c ",
      " k         c+ j ",
      " k         c  c ",
      " k   &&    *  c ",
      " k   &&    *  j ",
      " k         eeec ",
      " k         e))c ",
      " k         e))j ",
      " aaaaaaaaaad((c ",
      "           cccc ",
      "                "
    ],
    [
      "                ",
      "           cccc ",
      "           F  c ",
      "           c  j ",
      " [[[[[[[[[ac  c ",
      " []]]]]]]]]c  c ",
      " []]]]]]]]]ch j ",
      " []]]]]]]]]c+ c ",
      " []]]]]]]]]{  c ",
      " []]]]]]]]]{  j ",
      " []]]]]]]]]eeec ",
      " []]]]]]]]]ee}c ",
      " []]]]]]]]]e}d|;",
      " aaaaaaaaaadddc ",
      "           cccc ",
      "                "
    ]
  ]
}