{
  "name": "building_policeoffice1_top",
  "refpalette": "deceasedcraft:building_policeoffice1/building_policeoffice1_top_palette",
  "xsize": 16,
  "zsize": 16,
  "slices": [
    [
      "                ",
      "  aaaaaaaaaa    ",
      "  abbbbbbbba    ",
      "  abbbbbbbba    ",
      "  abbbbbbbba    ",
      "  abbbbbbbba    ",
      "  abbbbbbbba    ",
      "  abbbbbbbba    ",
      "  abbbbbbbba    ",
      "  abbbbbbbba    ",
      "  abbbbbbbba    ",
      " cdddcbbcccccec ",
      " cbbbfffg     h ",
      " cbbbffi      h ",
      " ccjccjccjccjcc ",
      "                "
    ],
    [
      "                ",
      "  aaaaaaaaaa    ",
      "  a k lk m a    ",
      "  anopnop  a    ",
      "  an pn!p  a    ",
      "  a d ldl  a    ",
      "  a dl d   a    ",
      "  a dddd   a    ",
      "  aqd      a    ",
      "  a d      a    ",
      "  a d      a    ",
      " cccdcrscccccec ",
      " c! t         c ",
      " cu w  x      c ",
      " ccjccjccjccjcc ",
      "                "
    ],
    [
      "                ",
      "  yA AAAqAAy    ",
      "  B        C    ",
      "  Bnopnop  C    ",
      "  Bnopnop       ",
      "  B        C    ",
      "  C        C    ",
      "  D             ",
      "  B        C    ",
      "  C        C    ",
      "           C    ",
      " cccccEFcccccec ",
      " cIJt         K ",
      " cI L         K ",
      " ccjccjccjccjcc ",
      "                "
    ],
    [
      "                ",
      "                ",
      "                ",
      "       M        ",
      "    y  y        ",
      "                ",
      "                ",
      "                ",
      "                ",
      "                ",
      "                ",
      " cccccNNcccccec ",
      " cO t         K ",
      " cO tP        K ",
      " ccjccjccjccjcc ",
      "                "
    ],
    [
      "                ",
      "                ",
      "                ",
      "                ",
      "    Q  Q        ",
      "                ",
      "                ",
      "                ",
      "                ",
      "                ",
      "                ",
      " cccccccccccccc ",
      " cRltSSSSSSSSTc ",
      " cR tSSSSSSSSTc ",
      " cccccccccccccc ",
      "                "
    ],
    [
      "                ",
      "                ",
      "                ",
      "    U  U        ",
      "   UU  UU       ",
      "                ",
      "                ",
      "                ",
      "                ",
      "                ",
      "                ",
      " cccccccccccccc ",
      " cccccccccccccc ",
      " cccccccccccccc ",
      " cccccccccccccc ",
      "                "
    ]
  ]
}