{
  "name": "building_policeoffice1_floor2_180",
  "refpalette": "deceasedcraft:building_policeoffice1/building_policeoffice1_floor2_palette_180",
  "xsize": 16,
  "zsize": 16,
  "slices": [
    [
      "                ",
      " ccjccjccjccjcc ",
      " c      ibefffc ",
      " c     hbbefffc ",
      " cgcccccbbefedc ",
      "    abbbbbbbba  ",
      "    abbbbbbbba  ",
      "    abbbbbbbba  ",
      "    abbbbbbbba  ",
      "    abbbbbbbba  ",
      "    abbbbbbbba  ",
      "    abbbbbbbba  ",
      "    abbbbbbbba  ",
      "    abbbbbbbba  ",
      "    aaaaaaaaaa  ",
      "                "
    ],
    [
      "                ",
      " ccjccjccjccjcc ",
      " c     iK eJIFc ",
      " c        e  Ec ",
      " cDccccc  eCedc ",
      "    a       wa  ",
      "    kou     Ba  ",
      "    kopq    Aa  ",
      "    kon     ya  ",
      "    k l   x wa  ",
      "    kou  otsra  ",
      "    kopq op  a  ",
      "    kon  onm a  ",
      "    k l   l  a  ",
      "    kkkkkkkkka  ",
      "                "
    ],
    [
      "                ",
      " ccjccjccjccjcc ",
      " c    iK  e IVc ",
      " c        e  Uc ",
      " cDccccc  eTedc ",
      "    a S     Qa  ",
      "    k P      a  ",
      "    k N      a  ",
      "    k       Ra  ",
      "    k       Qa  ",
      "    k P    O a  ",
      "    k N   M  a  ",
      "    k     L  a  ",
      "    k        a  ",
      "    kkkkkkkkka  ",
      "                "
    ],
    [
      "                ",
      " ccjccjccjccjcc ",
      " c  0iK   e321c ",
      " c  00    Z  !c ",
      " cDccccc  eYedc ",
      "    a X      a  ",
      "    k        W  ",
      "    k        W  ",
      "    k        W  ",
      "    k        g  ",
      "    k        W  ",
      "    k        W  ",
      "    k        W  ",
      "    k        a  ",
      "    kkkkkkkkka  ",
      "                "
    ],
    [
      "                ",
      " ccjccjccjccjcc ",
      " c 7      e554c ",
      " c 7 h6   e554c ",
      " cDccccc  eeedc ",
      "    a        a  ",
      "    k        a  ",
      "    k        a  ",
      "    k        a  ",
      "    k        a  ",
      "    k        a  ",
      "    k        a  ",
      "    k        a  ",
      "    k        a  ",
      "    kkkkkkkkka  ",
      "                "
    ],
    [
      "            *   ",
      " ccjccjccjcc&cc ",
      " c        e^ddc ",
      " c    h6  e ^dc ",
      " cDccccc%%eeedc ",
      "    a99999999a  ",
      "    8999$#999a  ",
      "    899999999a  ",
      "    899999999a  ",
      "    8999##999a  ",
      "    899999999a  ",
      "    899999999a  ",
      "    8999##999a  ",
      "    899999999a  ",
      "    888888888a  ",
      "                "
    ]
  ]
}