{
  "name": "building_policeoffice1_floor2_90",
  "refpalette": "deceasedcraft:building_policeoffice1/building_policeoffice1_floor2_palette_90",
  "xsize": 16,
  "zsize": 16,
  "slices": [
    [
      "                ",
      "           cccc ",
      "           g  c ",
      "           c  j ",
      " aaaaaaaaaac  c ",
      " abbbbbbbbbc  c ",
      " abbbbbbbbbc  j ",
      " abbbbbbbbbch c ",
      " abbbbbbbbbbbic ",
      " abbbbbbbbbbbbj ",
      " abbbbbbbbbeeec ",
      " abbbbbbbbbfffc ",
      " abbbbbbbbbeffj ",
      " aaaaaaaaaadffc ",
      "           cccc ",
      "                "
    ],
    [
      "                ",
      "           cccc ",
      "           D  c ",
      "           c  j ",
      " kkkkkkkkkac  c ",
      " k ooo ooo c  c ",
      " klnpulnpu c  j ",
      " k  q   q  c ic ",
      " k           Kc ",
      " k ooo        j ",
      " klnptx    eeec ",
      " k m s     C Jc ",
      " k   rwyABwe Ij ",
      " aaaaaaaaaadEFc ",
      "           cccc ",
      "                "
    ],
    [
      "                ",
      "           cccc ",
      "           D  c ",
      "           c  j ",
      " kkkkkkkkkac  c ",
      " k         c  c ",
      " k  NP  NPSc ij ",
      " k         c Kc ",
      " k            c ",
      " k            j ",
      " k LM      eeec ",
      " k   O     T  c ",
      " k    QR  Qe Ij ",
      " aaaaaaaaaadUVc ",
      "           cccc ",
      "                "
    ],
    [
      "                ",
      "           cccc ",
      "           D  c ",
      "           c  j ",
      " kkkkkkkkkac00c ",
      " k         c0ic ",
      " k        Xc Kj ",
      " k         c  c ",
      " k            c ",
      " k            j ",
      " k         eZec ",
      " k         Y 3c ",
      " k         e 2j ",
      " aaWWWgWWWad!1c ",
      "           cccc ",
      "                "
    ],
    [
      "                ",
      "           cccc ",
      "           D  c ",
      "           c77j ",
      " kkkkkkkkkac  c ",
      " k         ch c ",
      " k         c6 j ",
      " k         c  c ",
      " k            c ",
      " k            j ",
      " k         eeec ",
      " k         e55c ",
      " k         e55j ",
      " aaaaaaaaaad44c ",
      "           cccc ",
      "                "
    ],
    [
      "                ",
      "           cccc ",
      "           D  c ",
      "           c  j ",
      " 888888888ac  c ",
      " 8999999999c  c ",
      " 8999999999ch j ",
      " 8999999999c6 c ",
      " 89#99#99$9%  c ",
      " 89#99#99#9%  j ",
      " 8999999999eeec ",
      " 8999999999e ^c ",
      " 8999999999e^d&*",
      " aaaaaaaaaadddc ",
      "           cccc ",
      "                "
    ]
  ]
}