{
  "name": "building_policeoffice1_top_90",
  "refpalette": "deceasedcraft:building_policeoffice1/building_policeoffice1_top_palette_90",
  "xsize": 16,
  "zsize": 16,
  "slices": [
    [
      "                ",
      "           chhc ",
      "           e  c ",
      "           c  j ",
      " aaaaaaaaaac  c ",
      " abbbbbbbbbc  c ",
      " abbbbbbbbbc  j ",
      " abbbbbbbbbcg c ",
      " abbbbbbbbbbfic ",
      " abbbbbbbbbbffj ",
      " abbbbbbbbbcffc ",
      " abbbbbbbbbdbbc ",
      " abbbbbbbbbdbbj ",
      " aaaaaaaaaadbbc ",
      "           cccc ",
      "                "
    ],
    [
      "                ",
      "           cccc ",
      "           e  c ",
      "           c  j ",
      " aaaaaaaaaac  c ",
      " a         c  c ",
      " am        c  j ",
      " a ppl     c  c ",
      " ako!ddd   s xc ",
      " alnnl d   r  j ",
      " a pp ld   c  c ",
      " ako dddddddtwc ",
      " a nn   q  c  j ",
      " aaaaaaaaaac!uc ",
      "           cccc ",
      "                "
    ],
    [
      "                ",
      "           cKKc ",
      "           e  c ",
      "           c  j ",
      " yCC CC CCCc  c ",
      " A         c  c ",
      " A         c  j ",
      " q pp      c  c ",
      " A oo      F  c ",
      " A nn      E  j ",
      " A pp      c  c ",
      "   oo      ctLc ",
      " A nn      cJ j ",
      " yBBBBCDBC cIIc ",
      "           cccc ",
      "                "
    ],
    [
      "                ",
      "           cKKc ",
      "           e  c ",
      "           c  j ",
      "           c  c ",
      "           c  c ",
      "           c  j ",
      "           c  c ",
      "   My      N  c ",
      "           N  j ",
      "           c Pc ",
      "    y      cttc ",
      "           c  j ",
      "           cOOc ",
      "           cccc ",
      "                "
    ],
    [
      "                ",
      "           cccc ",
      "           cTTc ",
      "           cSSc ",
      "           cSSc ",
      "           cSSc ",
      "           cSSc ",
      "           cSSc ",
      "    Q      cSSc ",
      "           cSSc ",
      "           cSSc ",
      "    Q      cttc ",
      "           cl c ",
      "           cRRc ",
      "           cccc ",
      "                "
    ],
    [
      "                ",
      "           cccc ",
      "           cccc ",
      "           cccc ",
      "           cccc ",
      "           cccc ",
      "           cccc ",
      "    U      cccc ",
      "   UU      cccc ",
      "           cccc ",
      "           cccc ",
      "   UU      cccc ",
      "    U      cccc ",
      "           cccc ",
      "           cccc ",
      "                "
    ]
  ]
}