{
  "name": "building_policeoffice1_base2_90",
  "refpalette": "deceasedcraft:building_policeoffice1/building_policeoffice1_base2_palette_90",
  "xsize": 16,
  "zsize": 16,
  "slices": [
    [
      "vvvvvvvvvvvvvvvv",
      "vaaaaaaaaaaaaaav",
      "vaaaaaaaaaaaaaav",
      "vaaaaaaaaaaaaaav",
      "vaaaaaaaaaaaaaav",
      "vaaaaaaaaaaaaaav",
      "vaaaaaaaaaaaaaav",
      "vaaaaaaaaaaaaaav",
      "vaaaaaaaaaaaaaav",
      "vaaaaaaaaaaaaaav",
      "vaaaaaaaaaaaaaav",
      "vaaaaaaaaaaaaaav",
      "vaaaaaaaaaaaaaav",
      "vaaaaaaaaaaaaaav",
      "vaaaaaaaaaaaaaav",
      "vvvvvvvvvvvvvvvv"
    ],
    [
      "vvvvvvvvvvvvvvvv",
      "vaaaaaaaaaaaaaav",
      "vaaaaaaaaaaaaaav",
      "vaaaaaaaaaaaaaav",
      "vaaaaaaaaaaaaaav",
      "vaaaaaaaaaaaaaav",
      "vaaaaaaaaaaaaaav",
      "vaaaaaaaaaaaaaav",
      "vaaaaaaaaaaaaaav",
      "vaaaaaaaaaaaaaav",
      "vaaaaaaaaaaaaaav",
      "vaaaaaaaaaaaaaav",
      "vaaaaaaaaaaaaaav",
      "vaaaaaaaaaaaaaav",
      "vaaaaaaaaaaaaaav",
      "vvvvvvvvvvvvvvvv"
    ],
    [
      "vvvvvvvvvvvvvvvv",
      "vaaaaaaaaaaaaaav",
      "vaaaaaaaaaaaaaav",
      "vaaaaaaaaaaaaaav",
      "vaaaaaaaaaaaaaav",
      "vaaaaaaaaaaaaaav",
      "vaaaaaaaaaaaaaav",
      "vaaaaaaaaaaaaaav",
      "vaaaaaaaaaaaaaav",
      "vaaaaaaaaaaaaaav",
      "vaaaaaaaaaaaaaav",
      "vaaaaaaaaaaaaaav",
      "vaaaaaaaaaaaaaav",
      "vaaaaaaaaaaaaaav",
      "vaaaaaaaaaaaaaav",
      "vvvvvvvvvvvvvvvv"
    ],
    [
      "vvvvvvvvvvvvvvvv",
      "vbbbbbbbbbbddddv",
      "vbcccccccccdffdv",
      "vbcccccccccdffdv",
      "vbcccccccccdffdv",
      "vbcccccccccdgcdv",
      "vbddddddddddgcdv",
      "vbcccccbeeedgcdv",
      "vbcccccbeeedgcdv",
      "vbcccccbeeedgcdv",
      "vbcccccccccdgcdv",
      "vbcccccccccdfcdv",
      "vbcccccccccdccdv",
      "vbcccccccccdccdv",
      "vbbbbbbbbbbddddv",
      "vvvvvvvvvvvvvvvv"
    ],
    [
      "vvvvvvvvvvvvvvvv",
      "vbbbbbbbbbbddddv",
      "vbm  m  m  I Ldv",
      "vbmr w  w Cd Ldv",
      "vblq     CBdffdv",
      "vbklu    BB@Jcdv",
      "vbddddddddddJcdv",
      "vb ppp b  EdJcdv",
      "vbj    b  DdJcdv",
      "vb     byA dJcdv",
      "vi  t   x x@Jcdv",
      "vh ooo     dfcdv",
      "vi nnn     d Kdv",
      "vh  s      F  dv",
      "vbbbbbbbbbbddddv",
      "vvvvvvvvvvvvvvvv"
    ],
    [
      "vvvvvvvvvvvvvvvv",
      "vbbbbbbbbbbddddv",
      "vbw  m  U  Y 0dv",
      "vbm  w  m  d Zdv",
      "vbq       Bdffdv",
      "vbOr      W@Jcdv",
      "vbddSdddddddJcdv",
      "vb  R  b   dJcdv",
      "vN     b   dJcdv",
      "vb     bTV dJcdv",
      "vM      x x@Jcdv",
      "vM P       dfKdv",
      "vM  Q      d  dv",
      "vM         X  dv",
      "vbbbbbbbbbbddddv",
      "vvvvvvvvvvvvvvvv"
    ]
  ]
}