{
  "name": "building_policeoffice1_base1_90",
  "refpalette": "deceasedcraft:building_policeoffice1/building_policeoffice1_base1_palette_90",
  "xsize": 16,
  "zsize": 16,
  "slices": [
    [
      "vvvvvvvvvvvvvvvv",
      "vaaaaaaaaaaccccv",
      "va         j  cv",
      "va         c ocv",
      "va         ckkcv",
      "va         @lncv",
      "vace!gcccccclncv",
      "va dfd a   clncv",
      "va     a   clncv",
      "va     a   clncv",
      "vb      hhh@lmcv",
      "vb         ck cv",
      "vb         c  cv",
      "vb        ij  cv",
      "vaaaaaaaaaaccccv",
      "vvvvvvvvvvvvvvvv"
    ],
    [
      "vvvvvvvvvvvvvvvv",
      "vaaaaaaaaaaccccv",
      "va         c  cv",
      "va         c rcv",
      "va         ckkcv",
      "va         @lncv",
      "vaccpccccccclncv",
      "va  d  aq  clncv",
      "va     a   clncv",
      "va     a   clmcv",
      "vb      hhhcl cv",
      "vb         ck cv",
      "vb         c  cv",
      "vb         c  cv",
      "vaaaaaaaaaaccccv",
      "vvvvvvvvvvvvvvvv"
    ],
    [
      "vvvvvvvvvvvvvvvv",
      "vaaaaaaaaaaccccv",
      "va         c  cv",
      "va         c  cv",
      "va         ckkcv",
      "va         @lncv",
      "vacccccccccclncv",
      "va     aq  clncv",
      "va     aq  clmcv",
      "va     a   cl cv",
      "vb      hhhcl cv",
      "vb         ck cv",
      "vb         c  cv",
      "vb         c  cv",
      "vaaaaaaaaaaccccv",
      "vvvvvvvvvvvvvvvv"
    ],
    [
      "vvvvvvvvvvvvvvvv",
      "vaaaaaaaaaaccccv",
      "va         c  cv",
      "va         c  cv",
      "va         ckkcv",
      "va         @lncv",
      "vacccccccccclncv",
      "va     a!q clmcv",
      "va sss aq  cl cv",
      "va sss aq qcl cv",
      "va sss ahhhcl cv",
      "va sss a   ck cv",
      "va sss a   c  cv",
      "va     a t c  cv",
      "vaaaaaaaaaaccccv",
      "vvvvvvvvvvvvvvvv"
    ],
    [
      "vvvvvvvvvvvvvvvv",
      "vaaaaaaaaaaccccv",
      "va         c  cv",
      "va         c  cv",
      "va         ckkcv",
      "va         @lncv",
      "vacccccccccclmcv",
      "vauuuuuawwwcl cv",
      "vauuuuuawwwcl cv",
      "vauuuuuawwwcl cv",
      "vauuuuuawwwcl cv",
      "vauuuuuawwwck cv",
      "vauuuuuawwwc  cv",
      "vauuuuuawxwc  cv",
      "vaaaaaaaaaaccccv",
      "vvvvvvvvvvvvvvvv"
    ],
    [
      "vvvvvvvvvvvvvvvv",
      "vaaaaaaaaaaccccv",
      "vauuuuuuuuuckkcv",
      "vauuuuuuuuuckkcv",
      "vauuuuuuuuuckkcv",
      "vauuuuyuuuuckmcv",
      "vawwwwywwwwck cv",
      "vaqq  yaq qck cv",
      "va    ya  qck cv",
      "va    ya   ckAcv",
      "va   qyaq  ckncv",
      "va  qqya   ckncv",
      "vaq qqya  qcnncv",
      "vayyyyyyyyycnncv",
      "vaaaaaaaaaaccccv",
      "vvvvvvvvvvvvvvvv"
    ]
  ]
}