{
  "name": "building_policeoffice1_base2_180",
  "refpalette": "deceasedcraft:building_policeoffice1/building_policeoffice1_base2_palette_180",
  "xsize": 16,
  "zsize": 16,
  "slices": [
    [
      "vvvvvvvvvvvvvvvv",
      "vaaaaaaaaaaaaaav",
      "vaaaaaaaaaaaaaav",
      "vaaaaaaaaaaaaaav",
      "vaaaaaaaaaaaaaav",
      "vaaaaaaaaaaaaaav",
      "vaaaaaaaaaaaaaav",
      "vaaaaaaaaaaaaaav",
      "vaaaaaaaaaaaaaav",
      "vaaaaaaaaaaaaaav",
      "vaaaaaaaaaaaaaav",
      "vaaaaaaaaaaaaaav",
      "vaaaaaaaaaaaaaav",
      "vaaaaaaaaaaaaaav",
      "vaaaaaaaaaaaaaav",
      "vvvvvvvvvvvvvvvv"
    ],
    [
      "vvvvvvvvvvvvvvvv",
      "vaaaaaaaaaaaaaav",
      "vaaaaaaaaaaaaaav",
      "vaaaaaaaaaaaaaav",
      "vaaaaaaaaaaaaaav",
      "vaaaaaaaaaaaaaav",
      "vaaaaaaaaaaaaaav",
      "vaaaaaaaaaaaaaav",
      "vaaaaaaaaaaaaaav",
      "vaaaaaaaaaaaaaav",
      "vaaaaaaaaaaaaaav",
      "vaaaaaaaaaaaaaav",
      "vaaaaaaaaaaaaaav",
      "vaaaaaaaaaaaaaav",
      "vaaaaaaaaaaaaaav",
      "vvvvvvvvvvvvvvvv"
    ],
    [
      "vvvvvvvvvvvvvvvv",
      "vaaaaaaaaaaaaaav",
      "vaaaaaaaaaaaaaav",
      "vaaaaaaaaaaaaaav",
      "vaaaaaaaaaaaaaav",
      "vaaaaaaaaaaaaaav",
      "vaaaaaaaaaaaaaav",
      "vaaaaaaaaaaaaaav",
      "vaaaaaaaaaaaaaav",
      "vaaaaaaaaaaaaaav",
      "vaaaaaaaaaaaaaav",
      "vaaaaaaaaaaaaaav",
      "vaaaaaaaaaaaaaav",
      "vaaaaaaaaaaaaaav",
      "vaaaaaaaaaaaaaav",
      "vvvvvvvvvvvvvvvv"
    ],
    [
      "vvvvvvvvvvvvvvvv",
      "vddddddddddddddv",
      "vdfffcccccccccdv",
      "vdfffggggggfccdv",
      "vddddddddddddddv",
      "vbccccdeeeccccbv",
      "vbccccdeeeccccbv",
      "vbccccdeeeccccbv",
      "vbccccdbbbccccbv",
      "vbccccdcccccccbv",
      "vbccccdcccccccbv",
      "vbccccdcccccccbv",
      "vbccccdcccccccbv",
      "vbccccdcccccccbv",
      "vbbbbbbbbbbbbbbv",
      "vvvvvvvvvvvvvvvv"
    ],
    [
      "vvvvvvvvvvvvvvvv",
      "vddddddddddddddv",
      "vdLLfcccccccK dv",
      "vd  fJJJJJJf  dv",
      "vdIdd@dddd@ddFdv",
      "vb CBBdED x   bv",
      "vb  CBd  A    bv",
      "vbmw  d  yx   bv",
      "vb    dbbb    bv",
      "vb    d       bv",
      "vbmw  dp   on bv",
      "vb   udp  tonsbv",
      "vb rqldp   on bv",
      "vbmmlkd j     bv",
      "vbbbbbbbbbihihbv",
      "vvvvvvvvvvvvvvvv"
    ],
    [
      "vvvvvvvvvvvvvvvv",
      "vddddddddddddddv",
      "vd0ZfccccccK  dv",
      "vd  fJJJJJJf  dv",
      "vdYdd@dddd@ddXdv",
      "vb  BWd   x   bv",
      "vb    d  V    bv",
      "vbUm  d  Tx   bv",
      "vb    dbbb    bv",
      "vb    d       bv",
      "vbmw  d       bv",
      "vb    SR    Q bv",
      "vb   rd    P  bv",
      "vbwmqOd       bv",
      "vbbbbbbbNbMMMMbv",
      "vvvvvvvvvvvvvvvv"
    ]
  ]
}