{
  "name": "building_policeoffice1_ground_180",
  "refpalette": "deceasedcraft:building_policeoffice1/building_policeoffice1_ground_palette_180",
  "xsize": 16,
  "zsize": 16,
  "slices": [
    [
      "aaaaaaaaaaaaaaaa",
      "affffffffffffffa",
      "afi!k   jddhhhfa",
      "afiidddddddhhhfa",
      "afcfffffddchcgfa",
      "eaaacddddddddcaa",
      "aeeecddddddddcaa",
      "eaeecddddddddcaa",
      "aaaacddddddddcaa",
      "HHbacddddddddcaa",
      "HHbacddddddddcaa",
      "HHbacddddddddcaa",
      "HHbacddddddddcaa",
      "HHbacddddddddcaa",
      "HHbaccccccccccaa",
      "HHbaaaaaaaaaaaaa"
    ],
    [
      "                ",
      " ffOffOffOffOff ",
      " fNI   jk cMLKf ",
      " fJI      c  Ff ",
      " fEfffffDCcBcgf ",
      "    r       ncl ",
      "    A       ycl ",
      "    x       wcl ",
      "    r       ucl ",
      "    r        cl ",
      "    r  t  t  cl ",
      "    r ssssss cl ",
      "    r  q  q  cl ",
      "    cn pppponcl ",
      "    ccmccccmccl ",
      "                "
    ],
    [
      "                ",
      " ffOffOffOffOff ",
      " f0   jk  c LZf ",
      " f        cY Xf ",
      " fEfffWfVUcTcgf ",
      "    r       Qc  ",
      "    S        c  ",
      "    R        c  ",
      "    r        c  ",
      "    r        c  ",
      "    r        c  ",
      "    r        c  ",
      "    r        c  ",
      "    cQ pppp Qc  ",
      "    ccPccccPcc  ",
      "                "
    ],
    [
      "                ",
      " ffOffOffOffOff ",
      " f  7jk   c#98f ",
      " f  77    65 4f ",
      " fEfffff33c2cgf ",
      "    r       Qc  ",
      "    r        P  ",
      "    r        P  ",
      "    r        P  ",
      "    r        1  ",
      "    r        P  ",
      "    r        P  ",
      "    r        P  ",
      "    cQ p  p Qc  ",
      "    ccPccccPcc  ",
      "                "
    ],
    [
      "                ",
      " ffOffOffOffOff ",
      " f I      c&&^f ",
      " f I (*   c&&^f ",
      " fEfffff%%cccgf ",
      "    c  $     c  ",
      "    c        c  ",
      "    c        c  ",
      "    c        c  ",
      "    c        c  ",
      "    c        c  ",
      "    c        c  ",
      "    c        c  ",
      "    c  pppp  c  ",
      "    cccccccccc  ",
      "                "
    ],
    [
      "            |   ",
      " ffOffOffOff}ff ",
      " f        c{ggf ",
      " f    (*  c {gf ",
      " fEfffff]]cccgf ",
      "    )++++++++)  ",
      "    )++++++++)  ",
      "    )++--[[++)  ",
      "    )++++++++)  ",
      "    )++++++++)  ",
      "    )++++++++)  ",
      "    )++[[--++)  ",
      "    )++++++++)  ",
      "    )++++++++)  ",
      "    ))))))))))  ",
      "                "
    ]
  ]
}