{
  "name": "building_policeoffice1_floor3_270",
  "refpalette": "deceasedcraft:building_policeoffice1/building_policeoffice1_floor3_palette_270",
  "xsize": 16,
  "zsize": 16,
  "slices": [
    [
      "                ",
      " cccc           ",
      " cffdaaaaaaaaaa ",
      " jffebbbbbbbbba ",
      " cfffbbbbbbbbba ",
      " ceeebbbbbbbbba ",
      " jbbbbbbbbbbbba ",
      " cibbbbbbbbbbba ",
      " c hcbbbbbbbbba ",
      " j  cbbbbbbbbba ",
      " c  cbbbbbbbbba ",
      " c  caaaaaaaaaa ",
      " j  c           ",
      " c  g           ",
      " cccc           ",
      "                "
    ],
    [
      "                ",
      " cccc           ",
      " cKIdaaaaaaaaaa ",
      " jLJeA        k ",
      " cM C    m m  k ",
      " ceee  yuqqn  k ",
      " j  D   wrrol k ",
      " cN E  ywrro  k ",
      " ci cA  xsspl k ",
      " j  cB  t t   k ",
      " c  cB        k ",
      " c  cakkkkkkkkk ",
      " j  c           ",
      " c  F           ",
      " cccc           ",
      "                "
    ],
    [
      "                ",
      " cccc           ",
      " cZYdaaaaaaaaaa ",
      " jL eT        k ",
      " c  V         k ",
      " ceee   RP O  k ",
      " j  W      P  k ",
      " c  X   P     k ",
      " cN cT  S PQ  k ",
      " ji c         k ",
      " c  cU        k ",
      " c  cakkkkkkkkk ",
      " j  c           ",
      " c  F           ",
      " cccc           ",
      "                "
    ],
    [
      "                ",
      " cccc           ",
      " c #da000g000aa ",
      " j% e         k ",
      " c^ 8         k ",
      " ce!e    22   k ",
      " j  9   5331  k ",
      " c  9   5331  k ",
      " c  c    44   k ",
      " jN c6        k ",
      " ci$c7        k ",
      " c$$cakkkkkkkkk ",
      " j  c           ",
      " c  F           ",
      " cccc           ",
      "                "
    ],
    [
      "                ",
      " cccc           ",
      " c((daaaaaaaaaa ",
      " j))e         k ",
      " c))e         k ",
      " ceee         k ",
      " j  *    &&   k ",
      " c  *    &&   k ",
      " c  c         k ",
      " j +c         k ",
      " c hc         k ",
      " c  cakkkkkkkkk ",
      " j--c           ",
      " c  F           ",
      " cccc           ",
      "                "
    ],
    [
      "                ",
      " cccc           ",
      " cdddaaaaaaaaaa ",
      ";|d}e]]]]]]]]][ ",
      " c}ee]]]]]]]]][ ",
      " ceee]]]]]]]]][ ",
      " j  {]]]]]]]]][ ",
      " c  {]]]]]]]]][ ",
      " c +c]]]]]]]]][ ",
      " j hc]]]]]]]]][ ",
      " c  c]]]]]]]]][ ",
      " c  ca[[[[[[[[[ ",
      " j  c           ",
      " c  F           ",
      " cccc           ",
      "                "
    ]
  ]
}