{
  "name": "building_policeoffice1_top_180",
  "refpalette": "deceasedcraft:building_policeoffice1/building_policeoffice1_top_palette_180",
  "xsize": 16,
  "zsize": 16,
  "slices": [
    [
      "                ",
      " ccjccjccjccjcc ",
      " h      iffbbbc ",
      " h     gfffbbbc ",
      " cecccccbbcdddc ",
      "    abbbbbbbba  ",
      "    abbbbbbbba  ",
      "    abbbbbbbba  ",
      "    abbbbbbbba  ",
      "    abbbbbbbba  ",
      "    abbbbbbbba  ",
      "    abbbbbbbba  ",
      "    abbbbbbbba  ",
      "    abbbbbbbba  ",
      "    aaaaaaaaaa  ",
      "                "
    ],
    [
      "                ",
      " ccjccjccjccjcc ",
      " c      x  w uc ",
      " c         t !c ",
      " cecccccsrcdccc ",
      "    a      d a  ",
      "    a      d a  ",
      "    a      dqa  ",
      "    a   dddd a  ",
      "    a   d ld a  ",
      "    a  ldl d a  ",
      "    a  p!np na  ",
      "    a  ponpona  ",
      "    a m kl k a  ",
      "    aaaaaaaaaa  ",
      "                "
    ],
    [
      "                ",
      " ccjccjccjccjcc ",
      " K         L Ic ",
      " K         tJIc ",
      " cecccccFEccccc ",
      "    C           ",
      "    C        C  ",
      "    C        B  ",
      "             D  ",
      "    C        C  ",
      "    C        B  ",
      "       ponponB  ",
      "    C  ponponB  ",
      "    C        B  ",
      "    yAAqAAA Ay  ",
      "                "
    ],
    [
      "                ",
      " ccjccjccjccjcc ",
      " K        Pt Oc ",
      " K         t Oc ",
      " cecccccNNccccc ",
      "                ",
      "                ",
      "                ",
      "                ",
      "                ",
      "                ",
      "        y  y    ",
      "        M       ",
      "                ",
      "                ",
      "                "
    ],
    [
      "                ",
      " cccccccccccccc ",
      " cTSSSSSSSSt Rc ",
      " cTSSSSSSSStlRc ",
      " cccccccccccccc ",
      "                ",
      "                ",
      "                ",
      "                ",
      "                ",
      "                ",
      "        Q  Q    ",
      "                ",
      "                ",
      "                ",
      "                "
    ],
    [
      "                ",
      " cccccccccccccc ",
      " cccccccccccccc ",
      " cccccccccccccc ",
      " cccccccccccccc ",
      "                ",
      "                ",
      "                ",
      "                ",
      "                ",
      "                ",
      "       UU  UU   ",
      "        U  U    ",
      "                ",
      "                ",
      "                "
    ]
  ]
}