{
  "name": "building_policeoffice1_ground_90",
  "refpalette": "deceasedcraft:building_policeoffice1/building_policeoffice1_ground_palette_90",
  "xsize": 16,
  "zsize": 16,
  "slices": [
    [
      "HHHHHHHaeaeaaaaa",
      "HHHHHHHaaeaffffa",
      "bbbbbbbaeeaciifa",
      "aaaaaaaaeeafi!fa",
      "accccccccccfdkfa",
      "acdddddddddfd fa",
      "acdddddddddfd fa",
      "acdddddddddfd fa",
      "acdddddddddddjfa",
      "acddddddddddddfa",
      "acdddddddddcddfa",
      "acdddddddddhhhfa",
      "acdddddddddchhfa",
      "accccccccccghhfa",
      "aaaaaaaaaaaffffa",
      "aaaaaaaaaaaaaaaa"
    ],
    [
      "                ",
      "           ffff ",
      "           EJNf ",
      "           fIIO ",
      " ccrrrrrxArf  f ",
      " cn        f  f ",
      " m  s      f  O ",
      " cpqst     f jf ",
      " cp s      D kf ",
      " cp s      C  O ",
      " cpqst     cccf ",
      " mo s      B Mf ",
      " cn    uwync LO ",
      " ccccccccccgFKf ",
      " llllllllllffff ",
      "                "
    ],
    [
      "                ",
      "           ffff ",
      "           E 0f ",
      "           f  O ",
      " ccrrrrrRSrf  f ",
      " cQ        f  f ",
      " P         W jO ",
      " cp        f kf ",
      " cp        V  f ",
      " cp        U  O ",
      " cp        cccf ",
      " P         TY f ",
      " cQ       Qc LO ",
      " ccccccccccgXZf ",
      "           ffff ",
      "                "
    ],
    [
      "                ",
      "           ffff ",
      "           E  f ",
      "           f  O ",
      " ccrrrrrrrrf77f ",
      " cQ        f7jf ",
      " P         f kO ",
      " cp        f  f ",
      " c         3  f ",
      " c         3  O ",
      " cp        c6cf ",
      " P         25#f ",
      " cQ       Qc 9O ",
      " ccPPP1PPPcg48f ",
      "           ffff ",
      "                "
    ],
    [
      "                ",
      "           ffff ",
      "           E  f ",
      "           fIIO ",
      " ccccccccccf  f ",
      " c         f( f ",
      " c         f* O ",
      " cp       $f  f ",
      " cp        %  f ",
      " cp        %  O ",
      " cp        cccf ",
      " c         c&&f ",
      " c         c&&O ",
      " ccccccccccg^^f ",
      "           ffff ",
      "                "
    ],
    [
      "                ",
      "           ffff ",
      "           E  f ",
      "           f  O ",
      " ))))))))))f  f ",
      " )+++++++++f  f ",
      " )+++++++++f( O ",
      " )++[+++-++f* f ",
      " )++[+++-++]  f ",
      " )++-+++[++]  O ",
      " )++-+++[++cccf ",
      " )+++++++++c {f ",
      " )+++++++++c{g}|",
      " ))))))))))gggf ",
      "           ffff ",
      "                "
    ]
  ]
}