{
  "name": "building_policeoffice1_base1",
  "refpalette": "deceasedcraft:building_policeoffice1/building_policeoffice1_base1_palette",
  "xsize": 16,
  "zsize": 16,
  "slices": [
    [
      "vvvvvvvvvvvvvvvv",
      "vabbbbaaaaaaaaav",
      "va       c    av",
      "va      de    av",
      "va      f!    av",
      "va      dg    av",
      "va       c    av",
      "va    aaac    av",
      "va   h   c    av",
      "va   h   c    av",
      "vai  h   c    av",
      "vcjcc@cccc@ccjcv",
      "vc  kllllllk  cv",
      "vc   mnnnnnko cv",
      "vccccccccccccccv",
      "vvvvvvvvvvvvvvvv"
    ],
    [
      "vvvvvvvvvvvvvvvv",
      "vabbbbaaaaaaaaav",
      "va       c    av",
      "va       c    av",
      "va      dp    av",
      "va       c    av",
      "va       c    av",
      "va    aaac    av",
      "va   h  qc    av",
      "va   h   c    av",
      "va   h   c    av",
      "vccccccccc@ccccv",
      "vc  kllllllk  cv",
      "vc    mnnnnkr cv",
      "vccccccccccccccv",
      "vvvvvvvvvvvvvvvv"
    ],
    [
      "vvvvvvvvvvvvvvvv",
      "vabbbbaaaaaaaaav",
      "va       c    av",
      "va       c    av",
      "va       c    av",
      "va       c    av",
      "va       c    av",
      "va    aaac    av",
      "va   h qqc    av",
      "va   h   c    av",
      "va   h   c    av",
      "vccccccccc@ccccv",
      "vc  kllllllk  cv",
      "vc     mnnnk  cv",
      "vccccccccccccccv",
      "vvvvvvvvvvvvvvvv"
    ],
    [
      "vvvvvvvvvvvvvvvv",
      "vaaaaaaaaaaaaaav",
      "va       c    av",
      "va sssss c    av",
      "va sssss c    av",
      "va sssss c    av",
      "va       c    av",
      "vaaaaaaaac    av",
      "va   hqq!c    av",
      "vat  h  qc    av",
      "va   hq  c    av",
      "vccccccccc@ccccv",
      "vc  kllllllk  cv",
      "vc      mnnk  cv",
      "vccccccccccccccv",
      "vvvvvvvvvvvvvvvv"
    ],
    [
      "vvvvvvvvvvvvvvvv",
      "vaaaaaaaaaaaaaav",
      "vauuuuuuuc    av",
      "vauuuuuuuc    av",
      "vauuuuuuuc    av",
      "vauuuuuuuc    av",
      "vauuuuuuuc    av",
      "vaaaaaaaac    av",
      "vawwwwwwwc    av",
      "vaxwwwwwwc    av",
      "vawwwwwwwc    av",
      "vccccccccc@ccccv",
      "vc  kllllllk  cv",
      "vc       mnk  cv",
      "vccccccccccccccv",
      "vvvvvvvvvvvvvvvv"
    ],
    [
      "vvvvvvvvvvvvvvvv",
      "vaaaaaaaaaaaaaav",
      "vayq    qwuuuuav",
      "vay     qwuuuuav",
      "vayqq    wuuuuav",
      "vayqqq   wuuuuav",
      "vayyyyyyyyyuuuav",
      "vayaaaaaawuuuuav",
      "vay  q  qwuuuuav",
      "vay      wuuuuav",
      "vayq   qqwuuuuav",
      "vccccccccccccccv",
      "vcnnkkkkkkkkkkcv",
      "vcnnnnA   mkkkcv",
      "vccccccccccccccv",
      "vvvvvvvvvvvvvvvv"
    ]
  ]
}