{
  "name": "building_policeoffice1_ground",
  "refpalette": "deceasedcraft:building_policeoffice1/building_policeoffice1_ground_palette",
  "xsize": 16,
  "zsize": 16,
  "slices": [
    [
      "aaaaaaaaaaaaabHH",
      "aaccccccccccabHH",
      "aacddddddddcabHH",
      "aacddddddddcabHH",
      "aacddddddddcabHH",
      "aacddddddddcabHH",
      "aacddddddddcabHH",
      "aacddddddddcaaaa",
      "aacddddddddceeae",
      "aacddddddddceeea",
      "aacddddddddcaaae",
      "afgchcddfffffcfa",
      "afhhhdddddddiifa",
      "afhhhddj   k!ifa",
      "affffffffffffffa",
      "aaaaaaaaaaaaaaaa"
    ],
    [
      "                ",
      " lccmccccmcc    ",
      " lcnopppp nc    ",
      " lc  q  q  r    ",
      " lc ssssss r    ",
      " lc  t  t  r    ",
      " lc        r    ",
      " lcu       r    ",
      " lcw       x    ",
      " lcy       A    ",
      " lcn       r    ",
      " fgcBcCDfffffEf ",
      " fF  c      IJf ",
      " fKLMc kj   INf ",
      " ffOffOffOffOff ",
      "                "
    ],
    [
      "                ",
      "  ccPccccPcc    ",
      "  cQ pppp Qc    ",
      "  c        r    ",
      "  c        r    ",
      "  c        r    ",
      "  c        r    ",
      "  c        r    ",
      "  c        R    ",
      "  c        S    ",
      "  cQ       r    ",
      " fgcTcUVfWfffEf ",
      " fX Yc        f ",
      " fZL c  kj   0f ",
      " ffOffOffOffOff ",
      "                "
    ],
    [
      "                ",
      "  ccPccccPcc    ",
      "  cQ p  p Qc    ",
      "  P        r    ",
      "  P        r    ",
      "  P        r    ",
      "  1        r    ",
      "  P        r    ",
      "  P        r    ",
      "  P        r    ",
      "  cQ       r    ",
      " fgc2c33fffffEf ",
      " f4 56    77  f ",
      " f89#c   kj7  f ",
      " ffOffOffOffOff ",
      "                "
    ],
    [
      "                ",
      "  cccccccccc    ",
      "  c  pppp  c    ",
      "  c        c    ",
      "  c        c    ",
      "  c        c    ",
      "  c        c    ",
      "  c        c    ",
      "  c        c    ",
      "  c        c    ",
      "  c     $  c    ",
      " fgccc%%fffffEf ",
      " f^&&c   *( I f ",
      " f^&&c      I f ",
      " ffOffOffOffOff ",
      "                "
    ],
    [
      "                ",
      "  ))))))))))    ",
      "  )++++++++)    ",
      "  )++++++++)    ",
      "  )++--[[++)    ",
      "  )++++++++)    ",
      "  )++++++++)    ",
      "  )++++++++)    ",
      "  )++[[--++)    ",
      "  )++++++++)    ",
      "  )++++++++)    ",
      " fgccc]]fffffEf ",
      " fg{ c  *(    f ",
      " fgg{c        f ",
      " ff}ffOffOffOff ",
      "   |            "
    ]
  ]
}