{
  "name": "building_policeoffice1_floor3_180",
  "refpalette": "deceasedcraft:building_policeoffice1/building_policeoffice1_floor3_palette_180",
  "xsize": 16,
  "zsize": 16,
  "slices": [
    [
      "                ",
      " ccjccjccjccjcc ",
      " c      ibefffc ",
      " c     hbbefffc ",
      " cgcccccbbefedc ",
      "    abbbbbbbba  ",
      "    abbbbbbbba  ",
      "    abbbbbbbba  ",
      "    abbbbbbbba  ",
      "    abbbbbbbba  ",
      "    abbbbbbbba  ",
      "    abbbbbbbba  ",
      "    abbbbbbbba  ",
      "    abbbbbbbba  ",
      "    aaaaaaaaaa  ",
      "                "
    ],
    [
      "                ",
      " ccjccjccjccjcc ",
      " c     iN eMLKc ",
      " c        e JIc ",
      " cFcccccEDeCedc ",
      "    aBBA    Aa  ",
      "    k        a  ",
      "    k   y y  a  ",
      "    k txwwu  a  ",
      "    k  srrqm a  ",
      "    k tsrrq  a  ",
      "    k  poonm a  ",
      "    k  l l   a  ",
      "    k        a  ",
      "    kkkkkkkkka  ",
      "                "
    ],
    [
      "                ",
      " ccjccjccjccjcc ",
      " c    iN  e LZc ",
      " c        e  Yc ",
      " cFcccccXWeVedc ",
      "    aU T    Ta  ",
      "    k        a  ",
      "    k        a  ",
      "    k  SP R  a  ",
      "    k     P  a  ",
      "    k  P     a  ",
      "    k  Q PO  a  ",
      "    k        a  ",
      "    k        a  ",
      "    kkkkkkkkka  ",
      "                "
    ],
    [
      "                ",
      " ccjccjccjccjcc ",
      " c  $iN   e^% c ",
      " c  $$    !  #c ",
      " cFccccc99e8edc ",
      "    a76      a  ",
      "    k        0  ",
      "    k        0  ",
      "    k   55   0  ",
      "    k  4332  g  ",
      "    k  4332  0  ",
      "    k   11   0  ",
      "    k        0  ",
      "    k        a  ",
      "    kkkkkkkkka  ",
      "                "
    ],
    [
      "                ",
      " ccjccjccjccjcc ",
      " c -      e))(c ",
      " c - h+   e))(c ",
      " cFccccc**eeedc ",
      "    a        a  ",
      "    k        a  ",
      "    k        a  ",
      "    k        a  ",
      "    k   &&   a  ",
      "    k   &&   a  ",
      "    k        a  ",
      "    k        a  ",
      "    k        a  ",
      "    kkkkkkkkka  ",
      "                "
    ],
    [
      "            ;   ",
      " ccjccjccjcc|cc ",
      " c        e}ddc ",
      " c    h+  ee}dc ",
      " cFccccc{{eeedc ",
      "    a]]]]]]]]a  ",
      "    []]]]]]]]a  ",
      "    []]]]]]]]a  ",
      "    []]]]]]]]a  ",
      "    []]]]]]]]a  ",
      "    []]]]]]]]a  ",
      "    []]]]]]]]a  ",
      "    []]]]]]]]a  ",
      "    []]]]]]]]a  ",
      "    [[[[[[[[[a  ",
      "                "
    ]
  ]
}