{
  "name": "building_policeoffice1_ground_270",
  "refpalette": "deceasedcraft:building_policeoffice1/building_policeoffice1_ground_palette_270",
  "xsize": 16,
  "zsize": 16,
  "slices": [
    [
      "aaaaaaaaaaaaaaaa",
      "affffaaaaaaaaaaa",
      "afhhgcccccccccca",
      "afhhcdddddddddca",
      "afhhhdddddddddca",
      "afddcdddddddddca",
      "afddddddddddddca",
      "afjdddddddddddca",
      "af dfdddddddddca",
      "af dfdddddddddca",
      "af dfdddddddddca",
      "afkdfcccccccccca",
      "af!ifaeeaaaaaaaa",
      "afiicaeeabbbbbbb",
      "affffaeaaHHHHHHH",
      "aaaaaeaeaHHHHHHH"
    ],
    [
      "                ",
      " ffffllllllllll ",
      " fKFgcccccccccc ",
      " OL cnywu    nc ",
      " fM B      s om ",
      " fccc     tsqpc ",
      " O  C      s pc ",
      " fk D      s pc ",
      " fj f     tsqpc ",
      " O  f      s  m ",
      " f  f        nc ",
      " f  frAxrrrrrcc ",
      " OIIf           ",
      " fNJE           ",
      " ffff           ",
      "                "
    ],
    [
      "                ",
      " ffff           ",
      " fZXgcccccccccc ",
      " OL cQ       Qc ",
      " f YT         P ",
      " fccc        pc ",
      " O  U        pc ",
      " f  V        pc ",
      " fk f        pc ",
      " Oj W         P ",
      " f  f        Qc ",
      " f  frSRrrrrrcc ",
      " O  f           ",
      " f0 E           ",
      " ffff           ",
      "                "
    ],
    [
      "                ",
      " ffff           ",
      " f84gcPPP1PPPcc ",
      " O9 cQ       Qc ",
      " f#52         P ",
      " fc6c        pc ",
      " O  3         c ",
      " f  3         c ",
      " f  f        pc ",
      " Ok f         P ",
      " fj7f        Qc ",
      " f77frrrrrrrrcc ",
      " O  f           ",
      " f  E           ",
      " ffff           ",
      "                "
    ],
    [
      "                ",
      " ffff           ",
      " f^^gcccccccccc ",
      " O&&c         c ",
      " f&&c         c ",
      " fccc        pc ",
      " O  %        pc ",
      " f  %        pc ",
      " f  f$       pc ",
      " O *f         c ",
      " f (f         c ",
      " f  fcccccccccc ",
      " OIIf           ",
      " f  E           ",
      " ffff           ",
      "                "
    ],
    [
      "                ",
      " ffff           ",
      " fggg)))))))))) ",
      "|}g{c+++++++++) ",
      " f{ c+++++++++) ",
      " fccc++[+++-++) ",
      " O  ]++[+++-++) ",
      " f  ]++-+++[++) ",
      " f *f++-+++[++) ",
      " O (f+++++++++) ",
      " f  f+++++++++) ",
      " f  f)))))))))) ",
      " O  f           ",
      " f  E           ",
      " ffff           ",
      "                "
    ]
  ]
}