{
  "name": "building_policeoffice1_floor1",
  "refpalette": "deceasedcraft:building_policeoffice1/building_policeoffice1_floor1_palette",
  "xsize": 16,
  "zsize": 16,
  "slices": [
    [
      "                ",
      "  aaaaaaaaaa    ",
      "  abbbbbbbba    ",
      "  abbbbbbbba    ",
      "  abbbbbbbba    ",
      "  abbbbbbbba    ",
      "  abbbbbbbba    ",
      "  abbbbbbbba    ",
      "  abbbbbbbba    ",
      "  abbbbbbbba    ",
      "  abbbbbbbba    ",
      " cdefebbcccccgc ",
      " cfffebbh     c ",
      " cfffebi      c ",
      " ccjccjccjccjcc ",
      "                "
    ],
    [
      "                ",
      "  akkkkkkkkk    ",
      "  a  l   l k    ",
      "  a mno pnok    ",
      "  a  qo  rok    ",
      "  astuo  l k    ",
      "  aw x  pnok    ",
      "  ay     rok    ",
      "  aA     l k    ",
      "  aB    pnok    ",
      "  aw     roa    ",
      " cdeCe  cccccDc ",
      " cE  e        c ",
      " cFIJe Ki     c ",
      " ccjccjccjccjcc ",
      "                "
    ],
    [
      "                ",
      "  akkkkkkkkk    ",
      "  a        k    ",
      "  a  L   M k    ",
      "  a  N   O k    ",
      "  aPQ      k    ",
      "  aR     M k    ",
      "  aS     O k    ",
      "  aT       k    ",
      "  a      M k    ",
      "  aR     U a    ",
      " cdeVe  cccccDc ",
      " cW  e        c ",
      " cXI e  Ki    c ",
      " ccjccjccjccjcc ",
      "                "
    ],
    [
      "                ",
      "  akkkkkkkkk    ",
      "  a        k    ",
      "  Y        k    ",
      "  Y        k    ",
      "  Y        k    ",
      "  g        k    ",
      "  Y        k    ",
      "  Y        k    ",
      "  Y        k    ",
      "  a      Z a    ",
      " cde0e  cccccDc ",
      " c1 23    44  c ",
      " c567e   Ki4  c ",
      " ccjccjccjccjcc ",
      "                "
    ],
    [
      "                ",
      "  akkkkkkkkk    ",
      "  a        k    ",
      "  a        k    ",
      "  a        k    ",
      "  a        k    ",
      "  a        k    ",
      "  a        k    ",
      "  a        k    ",
      "  a        k    ",
      "  a        a    ",
      " cdeee  cccccDc ",
      " c899e   #h $ c ",
      " c899e      $ c ",
      " ccjccjccjccjcc ",
      "                "
    ],
    [
      "                ",
      "  a%%%%%%%%%    ",
      "  a^^^^^^^^%    ",
      "  a^^^&*^^^%    ",
      "  a^^^^^^^^%    ",
      "  a^^^^^^^^%    ",
      "  a^^^**^^^%    ",
      "  a^^^^^^^^%    ",
      "  a^^^^^^^^%    ",
      "  a^^^*!^^^%    ",
      "  a^^^^^^^^a    ",
      " cdeee((cccccDc ",
      " cd) e  #h    c ",
      " cdd)e        c ",
      " cc+ccjccjccjcc ",
      "   -            "
    ]
  ]
}