{
  "name": "building_policeoffice1_base2_270",
  "refpalette": "deceasedcraft:building_policeoffice1/building_policeoffice1_base2_palette_270",
  "xsize": 16,
  "zsize": 16,
  "slices": [
    [
      "vvvvvvvvvvvvvvvv",
      "vaaaaaaaaaaaaaav",
      "vaaaaaaaaaaaaaav",
      "vaaaaaaaaaaaaaav",
      "vaaaaaaaaaaaaaav",
      "vaaaaaaaaaaaaaav",
      "vaaaaaaaaaaaaaav",
      "vaaaaaaaaaaaaaav",
      "vaaaaaaaaaaaaaav",
      "vaaaaaaaaaaaaaav",
      "vaaaaaaaaaaaaaav",
      "vaaaaaaaaaaaaaav",
      "vaaaaaaaaaaaaaav",
      "vaaaaaaaaaaaaaav",
      "vaaaaaaaaaaaaaav",
      "vvvvvvvvvvvvvvvv"
    ],
    [
      "vvvvvvvvvvvvvvvv",
      "vaaaaaaaaaaaaaav",
      "vaaaaaaaaaaaaaav",
      "vaaaaaaaaaaaaaav",
      "vaaaaaaaaaaaaaav",
      "vaaaaaaaaaaaaaav",
      "vaaaaaaaaaaaaaav",
      "vaaaaaaaaaaaaaav",
      "vaaaaaaaaaaaaaav",
      "vaaaaaaaaaaaaaav",
      "vaaaaaaaaaaaaaav",
      "vaaaaaaaaaaaaaav",
      "vaaaaaaaaaaaaaav",
      "vaaaaaaaaaaaaaav",
      "vaaaaaaaaaaaaaav",
      "vvvvvvvvvvvvvvvv"
    ],
    [
      "vvvvvvvvvvvvvvvv",
      "vaaaaaaaaaaaaaav",
      "vaaaaaaaaaaaaaav",
      "vaaaaaaaaaaaaaav",
      "vaaaaaaaaaaaaaav",
      "vaaaaaaaaaaaaaav",
      "vaaaaaaaaaaaaaav",
      "vaaaaaaaaaaaaaav",
      "vaaaaaaaaaaaaaav",
      "vaaaaaaaaaaaaaav",
      "vaaaaaaaaaaaaaav",
      "vaaaaaaaaaaaaaav",
      "vaaaaaaaaaaaaaav",
      "vaaaaaaaaaaaaaav",
      "vaaaaaaaaaaaaaav",
      "vvvvvvvvvvvvvvvv"
    ],
    [
      "vvvvvvvvvvvvvvvv",
      "vddddbbbbbbbbbbv",
      "vdccdcccccccccbv",
      "vdccdcccccccccbv",
      "vdcfdcccccccccbv",
      "vdcgdcccccccccbv",
      "vdcgdeeebcccccbv",
      "vdcgdeeebcccccbv",
      "vdcgdeeebcccccbv",
      "vdcgddddddddddbv",
      "vdcgdcccccccccbv",
      "vdffdcccccccccbv",
      "vdffdcccccccccbv",
      "vdffdcccccccccbv",
      "vddddbbbbbbbbbbv",
      "vvvvvvvvvvvvvvvv"
    ],
    [
      "vvvvvvvvvvvvvvvv",
      "vddddbbbbbbbbbbv",
      "vd  F      s  hv",
      "vdK d     nnn iv",
      "vdcfd     ooo hv",
      "vdcJ@x x   t  iv",
      "vdcJd Ayb     bv",
      "vdcJdD  b    jbv",
      "vdcJdE  b ppp bv",
      "vdcJddddddddddbv",
      "vdcJ@BB    ulkbv",
      "vdffdBC     qlbv",
      "vdL dC w  w rmbv",
      "vdL I  m  m  mbv",
      "vddddbbbbbbbbbbv",
      "vvvvvvvvvvvvvvvv"
    ],
    [
      "vvvvvvvvvvvvvvvv",
      "vddddbbbbbbbbbbv",
      "vd  X         Mv",
      "vd  d      Q  Mv",
      "vdKfd       P Mv",
      "vdcJ@x x      Mv",
      "vdcJd VTb     bv",
      "vdcJd   b     Nv",
      "vdcJd   b  R  bv",
      "vdcJdddddddSddbv",
      "vdcJ@W      rObv",
      "vdffdB       qbv",
      "vdZ d  m  w  mbv",
      "vd0 Y  U  m  wbv",
      "vddddbbbbbbbbbbv",
      "vvvvvvvvvvvvvvvv"
    ]
  ]
}