{
  "name": "building_policeoffice1_floor2_270",
  "refpalette": "deceasedcraft:building_policeoffice1/building_policeoffice1_floor2_palette_270",
  "xsize": 16,
  "zsize": 16,
  "slices": [
    [
      "                ",
      " cccc           ",
      " cffdaaaaaaaaaa ",
      " jffebbbbbbbbba ",
      " cfffbbbbbbbbba ",
      " ceeebbbbbbbbba ",
      " jbbbbbbbbbbbba ",
      " cibbbbbbbbbbba ",
      " c hcbbbbbbbbba ",
      " j  cbbbbbbbbba ",
      " c  cbbbbbbbbba ",
      " c  caaaaaaaaaa ",
      " j  c           ",
      " c  g           ",
      " cccc           ",
      "                "
    ],
    [
      "                ",
      " cccc           ",
      " cFEdaaaaaaaaaa ",
      " jI ewBAywr   k ",
      " cJ C     s m k ",
      " ceee    xtpnlk ",
      " j        ooo k ",
      " cK           k ",
      " ci c  q   q  k ",
      " j  c upnlupnlk ",
      " c  c ooo ooo k ",
      " c  cakkkkkkkkk ",
      " j  c           ",
      " c  D           ",
      " cccc           ",
      "                "
    ],
    [
      "                ",
      " cccc           ",
      " cVUdaaaaaaaaaa ",
      " jI eQ  RQ    k ",
      " c  T     O   k ",
      " ceee      ML k ",
      " j            k ",
      " c            k ",
      " cK c         k ",
      " ji cSPN  PN  k ",
      " c  c         k ",
      " c  cakkkkkkkkk ",
      " j  c           ",
      " c  D           ",
      " cccc           ",
      "                "
    ],
    [
      "                ",
      " cccc           ",
      " c1!daWWWgWWWaa ",
      " j2 e         k ",
      " c3 Y         k ",
      " ceZe         k ",
      " j            k ",
      " c            k ",
      " c  c         k ",
      " jK cX        k ",
      " ci0c         k ",
      " c00cakkkkkkkkk ",
      " j  c           ",
      " c  D           ",
      " cccc           ",
      "                "
    ],
    [
      "                ",
      " cccc           ",
      " c44daaaaaaaaaa ",
      " j55e         k ",
      " c55e         k ",
      " ceee         k ",
      " j            k ",
      " c            k ",
      " c  c         k ",
      " j 6c         k ",
      " c hc         k ",
      " c  cakkkkkkkkk ",
      " j77c           ",
      " c  D           ",
      " cccc           ",
      "                "
    ],
    [
      "                ",
      " cccc           ",
      " cdddaaaaaaaaaa ",
      "*&d^e9999999998 ",
      " c^ e9999999998 ",
      " ceee9999999998 ",
      " j  %9#99#99#98 ",
      " c  %9$99#99#98 ",
      " c 6c9999999998 ",
      " j hc9999999998 ",
      " c  c9999999998 ",
      " c  ca888888888 ",
      " j  c           ",
      " c  D           ",
      " cccc           ",
      "                "
    ]
  ]
}