{
  "name": "building_policeoffice1_floor2",
  "refpalette": "deceasedcraft:building_policeoffice1/building_policeoffice1_floor2_palette",
  "xsize": 16,
  "zsize": 16,
  "slices": [
    [
      "                ",
      "  aaaaaaaaaa    ",
      "  abbbbbbbba    ",
      "  abbbbbbbba    ",
      "  abbbbbbbba    ",
      "  abbbbbbbba    ",
      "  abbbbbbbba    ",
      "  abbbbbbbba    ",
      "  abbbbbbbba    ",
      "  abbbbbbbba    ",
      "  abbbbbbbba    ",
      " cdefebbcccccgc ",
      " cfffebbh     c ",
      " cfffebi      c ",
      " ccjccjccjccjcc ",
      "                "
    ],
    [
      "                ",
      "  akkkkkkkkk    ",
      "  a  l   l k    ",
      "  a mno  nok    ",
      "  a  po qpok    ",
      "  arsto  uok    ",
      "  aw x   l k    ",
      "  ay     nok    ",
      "  aA    qpok    ",
      "  aB     uok    ",
      "  aw       a    ",
      " cdeCe  cccccDc ",
      " cE  e        c ",
      " cFIJe Ki     c ",
      " ccjccjccjccjcc ",
      "                "
    ],
    [
      "                ",
      "  akkkkkkkkk    ",
      "  a        k    ",
      "  a  L     k    ",
      "  a  M   N k    ",
      "  a O    P k    ",
      "  aQ       k    ",
      "  aR       k    ",
      "  a      N k    ",
      "  a      P k    ",
      "  aQ     S a    ",
      " cdeTe  cccccDc ",
      " cU  e        c ",
      " cVI e  Ki    c ",
      " ccjccjccjccjcc ",
      "                "
    ],
    [
      "                ",
      "  akkkkkkkkk    ",
      "  a        k    ",
      "  W        k    ",
      "  W        k    ",
      "  W        k    ",
      "  g        k    ",
      "  W        k    ",
      "  W        k    ",
      "  W        k    ",
      "  a      X a    ",
      " cdeYe  cccccDc ",
      " c!  Z    00  c ",
      " c123e   Ki0  c ",
      " ccjccjccjccjcc ",
      "                "
    ],
    [
      "                ",
      "  akkkkkkkkk    ",
      "  a        k    ",
      "  a        k    ",
      "  a        k    ",
      "  a        k    ",
      "  a        k    ",
      "  a        k    ",
      "  a        k    ",
      "  a        k    ",
      "  a        a    ",
      " cdeee  cccccDc ",
      " c455e   6h 7 c ",
      " c455e      7 c ",
      " ccjccjccjccjcc ",
      "                "
    ],
    [
      "                ",
      "  a888888888    ",
      "  a999999998    ",
      "  a999##9998    ",
      "  a999999998    ",
      "  a999999998    ",
      "  a999##9998    ",
      "  a999999998    ",
      "  a999999998    ",
      "  a999#$9998    ",
      "  a99999999a    ",
      " cdeee%%cccccDc ",
      " cd^ e  6h    c ",
      " cdd^e        c ",
      " cc&ccjccjccjcc ",
      "   *            "
    ]
  ]
}