{
  "name": "building_policeoffice1_base1_270",
  "refpalette": "deceasedcraft:building_policeoffice1/building_policeoffice1_base1_palette_270",
  "xsize": 16,
  "zsize": 16,
  "slices": [
    [
      "vvvvvvvvvvvvvvvv",
      "vccccaaaaaaaaaav",
      "vc  ji        bv",
      "vc  c         bv",
      "vc kc         bv",
      "vcml@hhh      bv",
      "vcnlc   a     av",
      "vcnlc   a     av",
      "vcnlc   a dfd av",
      "vcnlccccccg!ecav",
      "vcnl@         av",
      "vckkc         av",
      "vco c         av",
      "vc  j         av",
      "vccccaaaaaaaaaav",
      "vvvvvvvvvvvvvvvv"
    ],
    [
      "vvvvvvvvvvvvvvvv",
      "vccccaaaaaaaaaav",
      "vc  c         bv",
      "vc  c         bv",
      "vc kc         bv",
      "vc lchhh      bv",
      "vcmlc   a     av",
      "vcnlc   a     av",
      "vcnlc  qa  d  av",
      "vcnlcccccccpccav",
      "vcnl@         av",
      "vckkc         av",
      "vcr c         av",
      "vc  c         av",
      "vccccaaaaaaaaaav",
      "vvvvvvvvvvvvvvvv"
    ],
    [
      "vvvvvvvvvvvvvvvv",
      "vccccaaaaaaaaaav",
      "vc  c         bv",
      "vc  c         bv",
      "vc kc         bv",
      "vc lchhh      bv",
      "vc lc   a     av",
      "vcmlc  qa     av",
      "vcnlc  qa     av",
      "vcnlccccccccccav",
      "vcnl@         av",
      "vckkc         av",
      "vc  c         av",
      "vc  c         av",
      "vccccaaaaaaaaaav",
      "vvvvvvvvvvvvvvvv"
    ],
    [
      "vvvvvvvvvvvvvvvv",
      "vccccaaaaaaaaaav",
      "vc  c t a     av",
      "vc  c   a sss av",
      "vc kc   a sss av",
      "vc lchhha sss av",
      "vc lcq qa sss av",
      "vc lc  qa sss av",
      "vcmlc q!a     av",
      "vcnlccccccccccav",
      "vcnl@         av",
      "vckkc         av",
      "vc  c         av",
      "vc  c         av",
      "vccccaaaaaaaaaav",
      "vvvvvvvvvvvvvvvv"
    ],
    [
      "vvvvvvvvvvvvvvvv",
      "vccccaaaaaaaaaav",
      "vc  cwxwauuuuuav",
      "vc  cwwwauuuuuav",
      "vc kcwwwauuuuuav",
      "vc lcwwwauuuuuav",
      "vc lcwwwauuuuuav",
      "vc lcwwwauuuuuav",
      "vc lcwwwauuuuuav",
      "vcmlccccccccccav",
      "vcnl@         av",
      "vckkc         av",
      "vc  c         av",
      "vc  c         av",
      "vccccaaaaaaaaaav",
      "vvvvvvvvvvvvvvvv"
    ],
    [
      "vvvvvvvvvvvvvvvv",
      "vccccaaaaaaaaaav",
      "vcnncyyyyyyyyyav",
      "vcnncq  ayqq qav",
      "vcnkc   ayqq  av",
      "vcnkc  qayq   av",
      "vcAkc   ay    av",
      "vc kcq  ay    av",
      "vc kcq qay  qqav",
      "vc kcwwwwywwwwav",
      "vcmkcuuuuyuuuuav",
      "vckkcuuuuuuuuuav",
      "vckkcuuuuuuuuuav",
      "vckkcuuuuuuuuuav",
      "vccccaaaaaaaaaav",
      "vvvvvvvvvvvvvvvv"
    ]
  ]
}