{
  "name": "building_policeoffice1_floor1_180",
  "refpalette": "deceasedcraft:building_policeoffice1/building_policeoffice1_floor1_palette_180",
  "xsize": 16,
  "zsize": 16,
  "slices": [
    [
      "                ",
      " ccjccjccjccjcc ",
      " c      ibefffc ",
      " c     hbbefffc ",
      " cgcccccbbefedc ",
      "    abbbbbbbba  ",
      "    abbbbbbbba  ",
      "    abbbbbbbba  ",
      "    abbbbbbbba  ",
      "    abbbbbbbba  ",
      "    abbbbbbbba  ",
      "    abbbbbbbba  ",
      "    abbbbbbbba  ",
      "    abbbbbbbba  ",
      "    aaaaaaaaaa  ",
      "                "
    ],
    [
      "                ",
      " ccjccjccjccjcc ",
      " c     iK eJIFc ",
      " c        e  Ec ",
      " cDccccc  eCedc ",
      "    aor     wa  ",
      "    konp    Ba  ",
      "    k l     Aa  ",
      "    kor     ya  ",
      "    konp  x wa  ",
      "    k l  outsa  ",
      "    kor  oq  a  ",
      "    konp onm a  ",
      "    k l   l  a  ",
      "    kkkkkkkkka  ",
      "                "
    ],
    [
      "                ",
      " ccjccjccjccjcc ",
      " c    iK  e IXc ",
      " c        e  Wc ",
      " cDccccc  eVedc ",
      "    a U     Ra  ",
      "    k M      a  ",
      "    k       Ta  ",
      "    k O     Sa  ",
      "    k M     Ra  ",
      "    k      QPa  ",
      "    k O   N  a  ",
      "    k M   L  a  ",
      "    k        a  ",
      "    kkkkkkkkka  ",
      "                "
    ],
    [
      "                ",
      " ccjccjccjccjcc ",
      " c  4iK   e765c ",
      " c  44    32 1c ",
      " cDccccc  e0edc ",
      "    a Z      a  ",
      "    k        Y  ",
      "    k        Y  ",
      "    k        Y  ",
      "    k        g  ",
      "    k        Y  ",
      "    k        Y  ",
      "    k        Y  ",
      "    k        a  ",
      "    kkkkkkkkka  ",
      "                "
    ],
    [
      "                ",
      " ccjccjccjccjcc ",
      " c $      e998c ",
      " c $ h#   e998c ",
      " cDccccc  eeedc ",
      "    a        a  ",
      "    k        a  ",
      "    k        a  ",
      "    k        a  ",
      "    k        a  ",
      "    k        a  ",
      "    k        a  ",
      "    k        a  ",
      "    k        a  ",
      "    kkkkkkkkka  ",
      "                "
    ],
    [
      "            -   ",
      " ccjccjccjcc+cc ",
      " c        e)ddc ",
      " c    h#  e )dc ",
      " cDccccc((eeedc ",
      "    a^^^^^^^^a  ",
      "    %^^^!*^^^a  ",
      "    %^^^^^^^^a  ",
      "    %^^^^^^^^a  ",
      "    %^^^**^^^a  ",
      "    %^^^^^^^^a  ",
      "    %^^^^^^^^a  ",
      "    %^^^*&^^^a  ",
      "    %^^^^^^^^a  ",
      "    %%%%%%%%%a  ",
      "                "
    ]
  ]
}