{
  "name": "building_policeoffice1_base1_180",
  "refpalette": "deceasedcraft:building_policeoffice1/building_policeoffice1_base1_palette_180",
  "xsize": 16,
  "zsize": 16,
  "slices": [
    [
      "vvvvvvvvvvvvvvvv",
      "vccccccccccccccv",
      "vc oknnnnnm   cv",
      "vc  kllllllk  cv",
      "vcjcc@cccc@ccjcv",
      "va    c   h  iav",
      "va    c   h   av",
      "va    c   h   av",
      "va    caaa    av",
      "va    c       av",
      "va    gd      av",
      "va    !f      av",
      "va    ed      av",
      "va    c       av",
      "vaaaaaaaaabbbbav",
      "vvvvvvvvvvvvvvvv"
    ],
    [
      "vvvvvvvvvvvvvvvv",
      "vccccccccccccccv",
      "vc rknnnnm    cv",
      "vc  kllllllk  cv",
      "vcccc@cccccccccv",
      "va    c   h   av",
      "va    c   h   av",
      "va    cq  h   av",
      "va    caaa    av",
      "va    c       av",
      "va    c       av",
      "va    pd      av",
      "va    c       av",
      "va    c       av",
      "vaaaaaaaaabbbbav",
      "vvvvvvvvvvvvvvvv"
    ],
    [
      "vvvvvvvvvvvvvvvv",
      "vccccccccccccccv",
      "vc  knnnm     cv",
      "vc  kllllllk  cv",
      "vcccc@cccccccccv",
      "va    c   h   av",
      "va    c   h   av",
      "va    cqq h   av",
      "va    caaa    av",
      "va    c       av",
      "va    c       av",
      "va    c       av",
      "va    c       av",
      "va    c       av",
      "vaaaaaaaaabbbbav",
      "vvvvvvvvvvvvvvvv"
    ],
    [
      "vvvvvvvvvvvvvvvv",
      "vccccccccccccccv",
      "vc  knnm      cv",
      "vc  kllllllk  cv",
      "vcccc@cccccccccv",
      "va    c  qh   av",
      "va    cq  h  tav",
      "va    c!qqh   av",
      "va    caaaaaaaav",
      "va    c       av",
      "va    c sssss av",
      "va    c sssss av",
      "va    c sssss av",
      "va    c       av",
      "vaaaaaaaaaaaaaav",
      "vvvvvvvvvvvvvvvv"
    ],
    [
      "vvvvvvvvvvvvvvvv",
      "vccccccccccccccv",
      "vc  knm       cv",
      "vc  kllllllk  cv",
      "vcccc@cccccccccv",
      "va    cwwwwwwwav",
      "va    cwwwwwwxav",
      "va    cwwwwwwwav",
      "va    caaaaaaaav",
      "va    cuuuuuuuav",
      "va    cuuuuuuuav",
      "va    cuuuuuuuav",
      "va    cuuuuuuuav",
      "va    cuuuuuuuav",
      "vaaaaaaaaaaaaaav",
      "vvvvvvvvvvvvvvvv"
    ],
    [
      "vvvvvvvvvvvvvvvv",
      "vccccccccccccccv",
      "vckkkm   Annnncv",
      "vckkkkkkkkkknncv",
      "vccccccccccccccv",
      "vauuuuwqq   qyav",
      "vauuuuw      yav",
      "vauuuuwq  q  yav",
      "vauuuuwaaaaaayav",
      "vauuuyyyyyyyyyav",
      "vauuuuw   qqqyav",
      "vauuuuw    qqyav",
      "vauuuuwq     yav",
      "vauuuuwq    qyav",
      "vaaaaaaaaaaaaaav",
      "vvvvvvvvvvvvvvvv"
    ]
  ]
}