{
  "name": "building_policeoffice1_base2",
  "refpalette": "deceasedcraft:building_policeoffice1/building_policeoffice1_base2_palette",
  "xsize": 16,
  "zsize": 16,
  "slices": [
    [
      "vvvvvvvvvvvvvvvv",
      "vaaaaaaaaaaaaaav",
      "vaaaaaaaaaaaaaav",
      "vaaaaaaaaaaaaaav",
      "vaaaaaaaaaaaaaav",
      "vaaaaaaaaaaaaaav",
      "vaaaaaaaaaaaaaav",
      "vaaaaaaaaaaaaaav",
      "vaaaaaaaaaaaaaav",
      "vaaaaaaaaaaaaaav",
      "vaaaaaaaaaaaaaav",
      "vaaaaaaaaaaaaaav",
      "vaaaaaaaaaaaaaav",
      "vaaaaaaaaaaaaaav",
      "vaaaaaaaaaaaaaav",
      "vvvvvvvvvvvvvvvv"
    ],
    [
      "vvvvvvvvvvvvvvvv",
      "vaaaaaaaaaaaaaav",
      "vaaaaaaaaaaaaaav",
      "vaaaaaaaaaaaaaav",
      "vaaaaaaaaaaaaaav",
      "vaaaaaaaaaaaaaav",
      "vaaaaaaaaaaaaaav",
      "vaaaaaaaaaaaaaav",
      "vaaaaaaaaaaaaaav",
      "vaaaaaaaaaaaaaav",
      "vaaaaaaaaaaaaaav",
      "vaaaaaaaaaaaaaav",
      "vaaaaaaaaaaaaaav",
      "vaaaaaaaaaaaaaav",
      "vaaaaaaaaaaaaaav",
      "vvvvvvvvvvvvvvvv"
    ],
    [
      "vvvvvvvvvvvvvvvv",
      "vaaaaaaaaaaaaaav",
      "vaaaaaaaaaaaaaav",
      "vaaaaaaaaaaaaaav",
      "vaaaaaaaaaaaaaav",
      "vaaaaaaaaaaaaaav",
      "vaaaaaaaaaaaaaav",
      "vaaaaaaaaaaaaaav",
      "vaaaaaaaaaaaaaav",
      "vaaaaaaaaaaaaaav",
      "vaaaaaaaaaaaaaav",
      "vaaaaaaaaaaaaaav",
      "vaaaaaaaaaaaaaav",
      "vaaaaaaaaaaaaaav",
      "vaaaaaaaaaaaaaav",
      "vvvvvvvvvvvvvvvv"
    ],
    [
      "vvvvvvvvvvvvvvvv",
      "vbbbbbbbbbbbbbbv",
      "vbcccccccdccccbv",
      "vbcccccccdccccbv",
      "vbcccccccdccccbv",
      "vbcccccccdccccbv",
      "vbcccccccdccccbv",
      "vbccccbbbdccccbv",
      "vbcccceeedccccbv",
      "vbcccceeedccccbv",
      "vbcccceeedccccbv",
      "vddddddddddddddv",
      "vdccfggggggfffdv",
      "vdcccccccccfffdv",
      "vddddddddddddddv",
      "vvvvvvvvvvvvvvvv"
    ],
    [
      "vvvvvvvvvvvvvvvv",
      "vbhihibbbbbbbbbv",
      "vb     j dklmmbv",
      "vb no   pdlqr bv",
      "vbsnot  pdu   bv",
      "vb no   pd  wmbv",
      "vb       d    bv",
      "vb    bbbd    bv",
      "vb   xy  d  wmbv",
      "vb    A  dBC  bv",
      "vb   x DEdBBC bv",
      "vdFdd@dddd@ddIdv",
      "vd  fJJJJJJf  dv",
      "vd KcccccccfLLdv",
      "vddddddddddddddv",
      "vvvvvvvvvvvvvvvv"
    ],
    [
      "vvvvvvvvvvvvvvvv",
      "vbMMMMbNbbbbbbbv",
      "vb       dOqmwbv",
      "vb  P    dr   bv",
      "vb Q    RS    bv",
      "vb       d  wmbv",
      "vb       d    bv",
      "vb    bbbd    bv",
      "vb   xT  d  mUbv",
      "vb    V  d    bv",
      "vb   x   dWB  bv",
      "vdXdd@dddd@ddYdv",
      "vd  fJJJJJJf  dv",
      "vd  KccccccfZ0dv",
      "vddddddddddddddv",
      "vvvvvvvvvvvvvvvv"
    ]
  ]
}