{
  "name": "multi_flatmedium_1_floor3",
  "refpalette": "deceasedcraft:multi_flatmedium_1/multi_flatmedium_1_floor3_palette",
  "xsize": 16,
  "zsize": 16,
  "slices": [
    [
      " abbavvvvvvcccd ",
      " abbavvvvvvcccd ",
      " evaaaavvvvecca ",
      " avvvvavvvvcccd ",
      " afvvvavvvvcccd ",
      " avvvvavvvvcccd ",
      " avvvvavvvvcccd ",
      " avfvvavvvvcccd ",
      " avvvvavvvvcccd ",
      " avvvfvvvvvcccd ",
      " avvvvavvvvcccd ",
      " eaaavvvvvvecca ",
      " abbavvvvvvcccd ",
      " abbvvvvvvvcccd ",
      " abbavvvvvvcccd ",
      " aaaavvvvvvcccd "
    ],
    [
      " g ha     ij  a ",
      " a kalmnno a  a ",
      " epaaaaqqq e  a ",
      " a rssat  ua  a ",
      " g  wxay ABa  C ",
      " gD   aE  Fa  a ",
      " aI JKaL  Ma  N ",
      " aO PQaR AMa  N ",
      " g  JKaS  Ta  a ",
      " g D  U   Va  a ",
      " aWXYYaZA 0a  a ",
      " eaaar11121e  a ",
      " a34a     5a  a ",
      " g  6 77  8a  a ",
      " g  a 99  #a  a ",
      " aaaa$ss$ssa  a "
    ],
    [
      " %  a      ^    ",
      " a  a&*    a(   ",
      " e)aaaa   +e  - ",
      " a r[[a]   a    ",
      " %{ }|a;  :%    ",
      " %'   a<  >%    ",
      " a    a   ,a    ",
      " a   +a.   a    ",
      " %{   a?  :%    ",
      " %'   /   >%    ",
      " a`\u0370YYa    a    ",
      " eaaar111\u03711e  - ",
      " a  a     +a    ",
      " %  \u0372     :%    ",
      " % \u0373a     >%    ",
      " a\u0374\u0374a\u0374\u0374\u0374\u0374[[a    "
    ],
    [
      " %  a      \u0375    ",
      " a \u0376a      a    ",
      " e1aaaa    e  - ",
      " a \u0377[[a\u037a   a    ",
      " %\u037b   a\u037c  \u037d%    ",
      " %\u037e   a\u037f  \u0384%    ",
      " a    a\u037c   a    ",
      " a    a\u037f   a    ",
      " %\u037b   a\u0385  \u037d%    ",
      " %\u037e   \u0386   \u0384%    ",
      " a   !a    a    ",
      " eaaar11111e  - ",
      " a \u0387a      a    ",
      " %  \u0388     \u037d%    ",
      " % \u0389a     \u0384%    ",
      " aaaa\u0374\u0374\u0374\u0374[[a    "
    ],
    [
      " a\u038a\u038aa \u038c  \u038e a    ",
      " a\u038a\u038aa      a    ",
      " eaaaaa\u038f   e  - ",
      " a   \u0390a\u038f   a    ",
      " a    a\u038f   a    ",
      " a    a\u038f \u0391 a    ",
      " a    a\u038f   a    ",
      " a    a\u038f   a    ",
      " a    a\u038f   a    ",
      " a    a\u038f \u0391 a    ",
      " a\u0390   a\u038f   a    ",
      " eaaa\u0392\u0392\u0392\u0392\u0392\u0392e  - ",
      " a\u038a\u038aa      a    ",
      " a\u038a\u038aa      a    ",
      " a\u038a\u038aa      a    ",
      " aaaa\u0393\u0393\u0393\u0393\u0393\u0393a    "
    ],
    [
      " \u0394c ccccccc\u0394  \u0395 ",
      " \u0394c ccccccc\u0394  \u0395 ",
      " eccccccccce  e ",
      " \u0394ccccccccc\u0394  \u0395 ",
      " \u0394ccccccccc\u0394  \u0395 ",
      " \u0394ccccccccc\u0394  \u0395 ",
      " \u0394ccccccccc\u0394  \u0395 ",
      " \u0394ccccccccc\u0394  \u0395 ",
      " \u0394ccccccccc\u0394  \u0395 ",
      " \u0394ccccccccc\u0394  \u0395 ",
      " \u0394ccccccccc\u0394  \u0395 ",
      " eccccccccce  e ",
      " \u0394c ccccccc\u0394  \u0395 ",
      " \u0394c ccccccc\u0394  \u0395 ",
      " \u0394c\u0396ccccccc\u0394  \u0395 ",
      " \u0394ccccccccc\u0394  \u0395 "
    ]
  ]
}