{
  "name": "multi_flatmedium_1_floor5",
  "refpalette": "deceasedcraft:multi_flatmedium_1/multi_flatmedium_1_floor5_palette",
  "xsize": 16,
  "zsize": 16,
  "slices": [
    [
      " abbavvvvvvcccd ",
      " abbavvvvvvcccd ",
      " evaaaavvvvecca ",
      " avvvvavvvvcccd ",
      " avvvvavvvvcccd ",
      " avvvvavvvvcccd ",
      " avvvvavvvvcccd ",
      " avvvvavvvvcccd ",
      " avvvvavvvvcccd ",
      " avvvvvvvvvcccd ",
      " avvvvavvvvcccd ",
      " eaaavvvvvvecca ",
      " abbavvvvvvcccd ",
      " abbvvvvvvvcccd ",
      " abbavvvvvvcccd ",
      " aaaavvvvvvcccd "
    ],
    [
      " f ga      h  a ",
      " a iajkllm a  a ",
      " enaaaaooo e  a ",
      " a pqqar  sa  a ",
      " f  tuaw  xa  a ",
      " f    ay  Aa  a ",
      " a  BCaD  Ea  a ",
      " a   FaI  Ea  a ",
      " f  BCaJ  Ka  a ",
      " f    L   Ma  a ",
      " aNOqqa    a  a ",
      " eaaapPPPQPe  a ",
      " aRSa     Ta  a ",
      " f  U VV  Wa  a ",
      " f  a XX  Ya  a ",
      " aaaaZqqZqqa  a "
    ],
    [
      " 0  a      1    ",
      " a  a      a2   ",
      " e3aaaa   4e  5 ",
      " a p66a7   a    ",
      " 08   a   90    ",
      " 0#   a   $0    ",
      " a    a    a    ",
      " a   4a%   a    ",
      " 08   a^  90    ",
      " 0#   &   $0    ",
      " a  66a    a    ",
      " eaaapPPP*Pe  5 ",
      " a  a     4a    ",
      " 0  (     90    ",
      " 0 )a     $0    ",
      " a++a++++66a    "
    ],
    [
      " 0  a      -    ",
      " a [a      a    ",
      " ePaaaa    e  5 ",
      " a p66a]   a    ",
      " 0{   a}  |0    ",
      " 0;   a:  '0    ",
      " a    a}   a    ",
      " a    a:   a    ",
      " 0{   a<  |0    ",
      " 0;   >   '0    ",
      " a  66a    a    ",
      " eaaapPPPPPe  5 ",
      " a ,a      a    ",
      " 0  .     |0    ",
      " 0 ?a     '0    ",
      " aaaa++++66a    "
    ],
    [
      " a//a `  \u0370 a    ",
      " a//a      a    ",
      " eaaaaa\u0371   e  5 ",
      " a    a\u0371   a    ",
      " a    a\u0371   a    ",
      " a    a\u0371 \u0372 a    ",
      " a    a\u0371   a    ",
      " a    a\u0371   a    ",
      " a    a\u0371   a    ",
      " a    a\u0371 \u0372 a    ",
      " a    a\u0371   a    ",
      " eaaa\u0373\u0373\u0373\u0373\u0373\u0373e  5 ",
      " a//a      a    ",
      " a//a      a    ",
      " a//a      a    ",
      " aaaa\u0374\u0374\u0374\u0374\u0374\u0374a    "
    ],
    [
      " \u0375c ccccccc\u0375  \u0376 ",
      " \u0375c ccccccc\u0375  \u0376 ",
      " eccccccccce  e ",
      " \u0375ccccccccc\u0375  \u0376 ",
      " \u0375ccccccccc\u0375  \u0376 ",
      " \u0375ccccccccc\u0375  \u0376 ",
      " \u0375ccccccccc\u0375  \u0376 ",
      " \u0375ccccccccc\u0375  \u0376 ",
      " \u0375ccccccccc\u0375  \u0376 ",
      " \u0375ccccccccc\u0375  \u0376 ",
      " \u0375ccccccccc\u0375  \u0376 ",
      " eccccccccce  e ",
      " \u0375c ccccccc\u0375  \u0376 ",
      " \u0375c ccccccc\u0375  \u0376 ",
      " \u0375c\u0377ccccccc\u0375  \u0376 ",
      " \u0375ccccccccc\u0375  \u0376 "
    ]
  ]
}