{
  "name": "multi_flatmedium_1_top",
  "refpalette": "deceasedcraft:multi_flatmedium_1/multi_flatmedium_1_top_palette",
  "xsize": 16,
  "zsize": 16,
  "slices": [
    [
      " abbavvvcvcddde ",
      " abbavvvvvvddde ",
      " fvaaaavvgvfdda ",
      " avvvvavggcddde ",
      " avvvvahhijddde ",
      " avvvvahihgkdde ",
      " avcvvahhjhdkde ",
      " avvvvavlvvddde ",
      " mvvcvavvvvddde ",
      " nhvcvvvcvvddde ",
      " ovvvvacvvvddde ",
      " faaavvvvvvfdda ",
      " abbavvcvvvddde ",
      " abbvvvvvcvddde ",
      " abbavvvcvvddde ",
      " aaaavvvvvvddde "
    ],
    [
      " p qa      rs a ",
      " a tauwxxy a  a ",
      " fAaaaaB   fCDa ",
      " a EFFaI  JoK a ",
      " p   haj  lhLCa ",
      " p  MNah    OPa ",
      " aQ RSag T j  a ",
      " mQ  UaV  WnX a ",
      " Y   Za0 12o Ca ",
      " 3    4  15n  a ",
      " M67FFa    8C9a ",
      " 8aaaE###$#f  a ",
      " a%^a     &a* a ",
      " p  ( ))  +a- a ",
      " p  a [[  ]o{ M ",
      " aaaa}FF}FFn  M "
    ],
    [
      " |  a      ;  : ",
      " a  a      a'   ",
      " f<aaaa   >f  , ",
      " a E..a?   n    ",
      " |/  !a    |    ",
      " |`  \u0370a         ",
      " 8    a         ",
      " n   \u0371a\u0372   n  - ",
      " \u0373    a\u0374  \u0375|    ",
      "      \u0376   \u0377|    ",
      " \u037a 6..a    a    ",
      " ohaaE###\u037b#f  , ",
      " a  a     !n    ",
      " |  \u037c     \u0375|    ",
      " | \u037da     \u0377|    ",
      " a\u037e\u037ea\u037e\u037e\u037e\u037e..a    "
    ],
    [
      " |  a      \u037f    ",
      " a \u0384a      8    ",
      " f#aaaa    f  , ",
      " a \u0385..a\u0386        ",
      " |\u0387   a\u0388        ",
      " |\u0389   a\u038a        ",
      " 8    a\u0388        ",
      " Y    a\u038a        ",
      "      a\u038c  \u038e|    ",
      "      \u038f   \u0390|    ",
      "    ..a    8    ",
      "   haE#####f  , ",
      " 8 \u0391a      8    ",
      " |  \u0392     \u038e|    ",
      " | \u0393a     \u0390|    ",
      " aaaa\u037e\u037e\u037e\u037e..a    "
    ],
    [
      " a\u0394\u0394a \u0395  \u0396 8    ",
      " a\u0394\u0394a      a    ",
      " faaaaa\u0397   f  , ",
      " a    a\u0397   \u0398    ",
      " a    a\u0397        ",
      " a    a\u0397        ",
      " a    a\u0397        ",
      " a    a\u0397   8    ",
      " Y    a\u0397   n    ",
      " \u0399    a\u0397 \u039a a    ",
      " \u0399\u0398   a\u0397   a    ",
      " \u039b\u039c\u039da\u039e\u039e\u039e\u039e\u039e\u039ef  , ",
      " a\u0394\u0394a      a    ",
      " a\u0394\u0394a      a    ",
      " a\u0394\u0394a      8    ",
      " aaaa\u039f\u039f\u039f\u039f\u039f\u039fa    "
    ],
    [
      " Dd dddddddD  \u03a0 ",
      " Dd dddddddD  \u03a0 ",
      " fdddddddddf  f ",
      " Ddddddd7ddD  \u03a0 ",
      " Dddddddd77M  \u03a0 ",
      " Ddddddd777   \u03a0 ",
      " Ddddddd7ddM  \u03a0 ",
      " Dddddddd7dD  \u03a0 ",
      " MdddddddddD  \u03a0 ",
      " MdddddddddD  \u03a0 ",
      " MdddddddddD  \u03a0 ",
      " fdddddddddf  f ",
      " Dd dddddddD  \u03a0 ",
      " Dd dddddddD  \u03a0 ",
      " Dd\u03a1dddddddD  \u03a0 ",
      " DdddddddddD  \u03a0 "
    ],
    [
      " addd\u03a3\u03a3\u03a3\u03a3\u03a3\u03a3ddda ",
      " addd\u03a3\u03a3\u03a3\u03a3\u03a3\u03a3ddda ",
      " addd\u03a3\u03a3\u03a3\u03a3\u03a3\u03a3\u03a4dda ",
      " addd\u03a3\u03a3\u03a3\u03a3\u03a3\u03a3ddda ",
      " addd\u03a3\u03a3\u03a3\u03a3\u03a3\u03a3ddda ",
      " addd\u03a3\u03a3\u03a3\u03a3\u03a3\u03a3ddda ",
      " addd\u03a3\u03a3\u03a3\u03a3\u03a3\u03a3ddda ",
      " addd\u03a3\u03a3\u03a3\u03a3\u03a3\u03a3ddda ",
      " addd\u03a3\u03a3\u03a3\u03a3\u03a3\u03a3ddda ",
      " addd\u03a3\u03a3\u03a3\u03a3\u03a3\u03a3ddda ",
      " addd\u03a3\u03a3\u03a3\u03a3\u03a3\u03a3ddda ",
      " addd\u03a3\u03a3\u03a3\u03a3\u03a3\u03a3\u03a4dda ",
      " addd\u03a3\u03a3\u03a3\u03a3\u03a3\u03a3ddda ",
      " addd\u03a3\u03a3\u03a3\u03a3\u03a3\u03a3ddda ",
      " addd\u03a3\u03a3\u03a3\u03a3\u03a3\u03a3ddda ",
      " addd\u03a3\u03a3\u03a3\u03a3\u03a3\u03a3ddda "
    ],
    [
      " p            p ",
      " p            p ",
      " ,       \u03a5\u03a6\u03a4  , ",
      " p   \u03a7\u03a8       p ",
      " p   \u03a8\u03a9\u03a8      p ",
      " p    \u03a8  \u03a5\u03a6   p ",
      " p            p ",
      " p            p ",
      " p    \u03a8  \u03a5\u03a6   p ",
      " p   \u03a8\u03a9\u03a8      p ",
      " p   \u03a7\u03a8       p ",
      " ,       \u03a5\u03a6\u03a4  , ",
      " p            p ",
      " p            p ",
      " p            p ",
      " p            p "
    ],
    [
      "         \u03a4      ",
      "         \u03a4      ",
      " \u03aa       !\u03a4\u03a4  \u03aa ",
      "      \u03a7  \u03a4      ",
      "      \u03ab\u03a9 \u03a4      ",
      "      \u03a9  \u03a4      ",
      "         \u03a4      ",
      "         \u03a4      ",
      "     \u03a9\u03a9\u03a9 \u03a4      ",
      "     \u03a9S\u03a9 \u03a4      ",
      "      \u03a9\u03a9 \u03a4      ",
      " \u03aa       \u03a4\u03a4\u03a4  \u03aa ",
      "                ",
      "                ",
      "                ",
      "                "
    ],
    [
      "                ",
      "                ",
      "                ",
      "                ",
      "                ",
      "                ",
      "                ",
      "                ",
      "      \u03a9\u03a9        ",
      "     \u03a9S\u03a9        ",
      "      \u03a9\u03a9        ",
      "                ",
      "                ",
      "                ",
      "                ",
      "                "
    ],
    [
      "                ",
      "                ",
      "                ",
      "                ",
      "                ",
      "                ",
      "                ",
      "                ",
      "      \u03a7         ",
      "       \u03a9        ",
      "       \u03a9        ",
      "                ",
      "                ",
      "                ",
      "                ",
      "                "
    ]
  ]
}