{
  "name": "multi_flatmedium_1_ground",
  "refpalette": "deceasedcraft:multi_flatmedium_1/multi_flatmedium_1_ground_palette",
  "xsize": 16,
  "zsize": 16,
  "slices": [
    [
      "aabbbbcbbcbbbbaa",
      "aabbbbbbbbbbbbaa",
      "adbbbdbbbbdbbbda",
      "aabbbbbbbbbbbbaa",
      "aabbbbbbbcbbbbaa",
      "aabbbcbbbbbbbbaa",
      "aabbbbbbbbbbbbaa",
      "aabbbbbbbbbbbbaa",
      "aabbbefbbebbbbaa",
      "aabbbbebbbbbbbaa",
      "aabbbbbbbbbbbbaa",
      "adbbbdbbbbdbbbda",
      "aabbbebbbbbbbbaa",
      "aabbbbbbbbbbbbaa",
      "aabbbbbbbbbbbbaa",
      "aabbbbbbbbbbbbaa"
    ],
    [
      " gh ij ki  k  g ",
      " gl m  nm on  g ",
      " p  qpqqqqpq  p ",
      " g  i  ki  k  g ",
      " g  m rnm  n  g ",
      "    i skituk sg ",
      "    mw nmx n  g ",
      " g yixAki  k    ",
      " gx m  nm  ns g ",
      " g  i  ki Bk  g ",
      " g  m  nm  n  g ",
      " p  qpq qqpq  p ",
      " g  i  ki Ck  g ",
      " g  m  nmD n  g ",
      " g  iE ki Fk  g ",
      " g sm  nm Inx g "
    ],
    [
      "                ",
      "                ",
      " J   J    J   J ",
      "                ",
      "                ",
      "                ",
      "                ",
      "                ",
      "                ",
      "                ",
      "                ",
      " J   J    J   J ",
      "                ",
      "                ",
      "                ",
      "                "
    ],
    [
      "                ",
      "                ",
      " J   J    J   J ",
      "                ",
      "                ",
      "                ",
      "                ",
      "                ",
      "                ",
      "                ",
      "                ",
      " J   J    J   J ",
      "                ",
      "                ",
      "                ",
      "                "
    ],
    [
      " K   K    K   K ",
      " K   K    K   K ",
      " JKKKJKKKKJKKKJ ",
      " K   K    K   K ",
      " K   K    K   K ",
      " K   K    K   K ",
      " K   K    K   K ",
      " K   K    K   K ",
      " K   K    K   K ",
      " K   K    K   K ",
      " K   K    K   K ",
      " JKKKJKKKKJKKKJ ",
      " K   K    K   K ",
      " K   K    K   K ",
      " K   K    K   K ",
      " K   K    K   K "
    ],
    [
      " LbbbbbbbbbbbbL ",
      " LbbbbbbbbbbbbL ",
      " LbbbbbbbbbbbbL ",
      " LbbbbbbbbbbbbL ",
      " LbbbbbbbbbbbbL ",
      " LbbbbbbbbbbbbL ",
      " LbbbbbbbbbbbbL ",
      " LbbbbbbbbbbbbL ",
      " LbbbbbbbbbbbbL ",
      " LbbbbbbbbbbbbL ",
      " LbbbbbbbbbbbbL ",
      " LbbbbbbbbbbbbL ",
      " LbbbbbbbbbbbbL ",
      " LbbbbbbbbbbbbL ",
      " LbbbbbbbbbbbbL ",
      " LbbbbbbbbbbbbL "
    ]
  ]
}