{
  "name": "multi_flatmedium_1_floor4",
  "refpalette": "deceasedcraft:multi_flatmedium_1/multi_flatmedium_1_floor4_palette",
  "xsize": 16,
  "zsize": 16,
  "slices": [
    [
      " abbavvvvvvcccd ",
      " abbavvvvvvcccd ",
      " evaaaavvvvecca ",
      " avvvvavvvvcccd ",
      " avvvvavvvvcccd ",
      " avvvvavvvvcccd ",
      " avvvvavvvvcccd ",
      " avvvvavvvvcccd ",
      " avvvvavvvvcccd ",
      " avvvvvvvvvcccd ",
      " avvvvavvvvcccd ",
      " eaaavvvvvvecca ",
      " abbavvvvvvcccd ",
      " abbvvvvvvvcccd ",
      " abbavvvvvvcccd ",
      " aaaavvvvvvcccd "
    ],
    [
      " f ga      h  a ",
      " a iajkllm a  a ",
      " enaaaaooo e  a ",
      " a pqqar  sa  a ",
      " f  tuaw  xa  a ",
      " f y  aA  Ba  a ",
      " aC  DaE  Fa  a ",
      " a   IaJ  Fa  a ",
      " fK  !aL  Ma  a ",
      " f    N   Oa  a ",
      " aPQqqaR  Sa  a ",
      " eaaapTTTUTe  a ",
      " aVWa     Xa  a ",
      " f  Y ZZ o0a  a ",
      " f  a 11  2a  a ",
      " aaaa3qq3qqa  a "
    ],
    [
      " 4  a      5    ",
      " a  a  678 a9   ",
      " e#aaaa   $e  % ",
      " a ^&&a*   a    ",
      " 4( )+a-  [4    ",
      " 4]   a{  }4    ",
      " a    a   |a    ",
      " a   $a;   a    ",
      " 4(   a:  [4    ",
      " 4]   '   }4    ",
      " a<>,.a   !a    ",
      " eaaapTTT?Te  % ",
      " a  a     /a    ",
      " 4  `     \u03704    ",
      " 4 \u0371a\u0372    \u03734    ",
      " a\u0374\u0374a\u0374\u0374\u0374\u0374&&a    "
    ],
    [
      " 4  a      \u0375    ",
      " a \u0376a      a    ",
      " eTaaaa    e  % ",
      " a  \u0377\u0377a\u037a   a    ",
      " 4\u037b   a\u037c  \u037d4    ",
      " 4\u037e   a\u037f  \u03844    ",
      " a    a\u037c   a    ",
      " a    a\u037f   a    ",
      " 4\u037b   a\u0385  \u037d4    ",
      " 4\u037e   \u0386   \u03844    ",
      " a    a    a    ",
      " eaaapTTTTTe  % ",
      " a \u0387a      a    ",
      " 4  \u0388     \u03894    ",
      " 4 \u038aa     \u038c4    ",
      " aaaa\u0374\u0374\u0374\u0374&&a    "
    ],
    [
      " a\u038e\u038ea \u038f  \u0390 a    ",
      " a\u038e\u038ea      a    ",
      " eaaaaa\u0391   e  % ",
      " a    a\u0391   a    ",
      " a    a\u0391   a    ",
      " a    a\u0391 \u0392 a    ",
      " a    a\u0391   a    ",
      " a    a\u0391   a    ",
      " a    a\u0391   a    ",
      " a    a\u0391 \u0392 a    ",
      " a    a\u0391   a    ",
      " eaaa\u0393\u0393\u0393\u0393\u0393\u0393e  % ",
      " a\u038e\u038ea      a    ",
      " a\u038e\u038ea      a    ",
      " a\u038e\u038ea      a    ",
      " aaaa\u0394\u0394\u0394\u0394\u0394\u0394a    "
    ],
    [
      " \u0395c ccccccc\u0395  \u0396 ",
      " \u0395c ccccccc\u0395  \u0396 ",
      " eccccccccce  e ",
      " \u0395ccccccccc\u0395  \u0396 ",
      " \u0395ccccccccc\u0395  \u0396 ",
      " \u0395ccccccccc\u0395  \u0396 ",
      " \u0395ccccccccc\u0395  \u0396 ",
      " \u0395ccccccccc\u0395  \u0396 ",
      " \u0395ccccccccc\u0395  \u0396 ",
      " \u0395ccccccccc\u0395  \u0396 ",
      " \u0395ccccccccc\u0395  \u0396 ",
      " eccccccccce  e ",
      " \u0395c ccccccc\u0395  \u0396 ",
      " \u0395c ccccccc\u0395  \u0396 ",
      " \u0395c\u0397ccccccc\u0395  \u0396 ",
      " \u0395ccccccccc\u0395  \u0396 "
    ]
  ]
}