{
  "name": "multi_flatmedium_1_floor2",
  "refpalette": "deceasedcraft:multi_flatmedium_1/multi_flatmedium_1_floor2_palette",
  "xsize": 16,
  "zsize": 16,
  "slices": [
    [
      " abbavvvvvvcccd ",
      " abbavvvvvvcccd ",
      " evaavavvvvecca ",
      " avvvvavvvvcccd ",
      " avvvvavvvvcccd ",
      " avvvvavvvvcccd ",
      " avvvvavvvvcccd ",
      " avvvvavvvvcccd ",
      " avfvvavvvvcccd ",
      " afvfvavvvvcccd ",
      " avvvvavfvvcccd ",
      " evaavavvvvecca ",
      " abbafvvvfvcccd ",
      " abbavvfvvvcccd ",
      " abbavvvvvvcccd ",
      " aaaavvvfvvcccd "
    ],
    [
      " g ha      i  a ",
      " a ja  klm a  a ",
      " enaaoap q e  a ",
      " a    !r   a  a ",
      " g ss at   a  a ",
      " g uu a  q a  a ",
      " awxxwayyAAa  a ",
      " axxxxaxxxxa  a ",
      " gB  CaCD  E  a ",
      " g    aC   i  a ",
      " a    a  F a  a ",
      " eIaaJaB   e  a ",
      " a ja   K  a  a ",
      " g ha L    a  a ",
      " g !a    MBa  a ",
      " aaaaNNNNNNa  a "
    ],
    [
      " O  a      P    ",
      " a  a  QRS aT   ",
      " eUaaVaW  Xe  Y ",
      " a   XaZ   a    ",
      " O    a   0O    ",
      " O    a   1O    ",
      " aNNNNaNNNNa    ",
      " a2222a2222a    ",
      " O    aC   3    ",
      " O    a    P    ",
      " a   Xa    aT   ",
      " e4aa5a   Xe  Y ",
      " a  a      a    ",
      " O  a     0O    ",
      " O  a     1O    ",
      " aNNaNNNNNNa    "
    ],
    [
      " O  a      6    ",
      " a 7a  8   a    ",
      " e2aa2a    e  Y ",
      " a    a    a    ",
      " O    a   9O    ",
      " O    a   #O    ",
      " aNNNNa$%$%a    ",
      " a2222a2222a    ",
      " O    a!   6    ",
      " O    a    6    ",
      " a B  a    a    ",
      " eNaaNa    e  Y ",
      " a  a      a    ",
      " O  a     9O    ",
      " OB a     #O    ",
      " aaaaNNNNNNa    "
    ],
    [
      " a^^a &  * a    ",
      " a^^a      a    ",
      " eaaaaa((((e  Y ",
      " a    a    a    ",
      " a *  a  ) a    ",
      " a    a    a    ",
      " a++++a++++a    ",
      " a((((a((((a    ",
      " aB  Ba    a    ",
      " a *  a  *Ba    ",
      " a    aB   a    ",
      " eaaaaa++++e  Y ",
      " a^^aB     a    ",
      " a^^a &  ) a    ",
      " a^^aB    Ba    ",
      " aaaa++++++a    "
    ],
    [
      " -c ccccccc-  [ ",
      " -c ccccccc-  [ ",
      " eccccccccce  e ",
      " -ccccccccc-  [ ",
      " -ccccccccc-  [ ",
      " -ccccccccc-  [ ",
      " -ccccccccc-  [ ",
      " -ccccccccc-  [ ",
      " -ccccccccc-  [ ",
      " -ccccccccc-  [ ",
      " -ccccccccc-  [ ",
      " eccccccccce  e ",
      " -c ccccccc-  [ ",
      " -c ccccccc-  [ ",
      " -c]ccccccc-  [ ",
      " -ccccccccc-  [ "
    ]
  ]
}