{
  "name": "multi_flatmedium_1_floor1",
  "refpalette": "deceasedcraft:multi_flatmedium_1/multi_flatmedium_1_floor1_palette",
  "xsize": 16,
  "zsize": 16,
  "slices": [
    [
      " abbavvvcvvddde ",
      " abbacvvvvcddde ",
      " fvaavavvvvfdda ",
      " avvvvavvvcddde ",
      " avvvvavvccddde ",
      " avvvvavcvvddde ",
      " avvvvavvvvddde ",
      " avvvvavvvvddde ",
      " avvvvavvvvddde ",
      " avvvvavcvvddde ",
      " avvccagvcvddde ",
      " fvaacghhccfdda ",
      " abbavhhigvddde ",
      " abbavghhcvddde ",
      " abbavcgccvddde ",
      " aaaavvvcvvddde "
    ],
    [
      " j ka lm nop  a ",
      " a qa rsst a  a ",
      " fuaawaxyyAfm a ",
      " aBC  aDEF a  a ",
      " I J  aKLMNa  a ",
      " j O  aPQRSa  T ",
      " a!UU!aVWWWa  X ",
      " YZUUZaUUUUa  X ",
      " j    T012 34 T ",
      " j  m5X6 78p 4a ",
      " a    m  6 a  a ",
      " f9aYi   6 fm a ",
      " a qT6   46a  a ",
      " j kY6   #$a  a ",
      " j !aP  6y%a  a ",
      " aaaa^WW&&&a  a "
    ],
    [
      " *  a      (    ",
      " a  a )+-[ a]   ",
      " f{aa}a|  ;f  I ",
      " a   ;a:   a    ",
      " *    a'  <*    ",
      "     >a   ,*    ",
      " T&&&&a&&&&a    ",
      "  ....a????a    ",
      "      X    /    ",
      "           (    ",
      " `         a]   ",
      " f\u0370a\u0371     ;f  I ",
      " a  \u0371      a    ",
      " *  \u0371     <*    ",
      " * \u0372T     ,*    ",
      " a&&a&&&&&&a    "
    ],
    [
      " *  a      \u0373    ",
      " a \u0374a      a    ",
      " f.aa.a\u0375   f  I ",
      " a    a\u0376   a    ",
      " *    a   \u0377*    ",
      "      a   \u037a*    ",
      " Y&&&&a\u037b\u037c\u037b\u037ca    ",
      "  ....a????a    ",
      "           \u0373    ",
      "           \u0373    ",
      " \u037d         a    ",
      " f&a\u037e      f  I ",
      " a \u0374Y      a    ",
      " *  \u0371     \u0377     ",
      " * \u037fa     \u037a*    ",
      " aaaa\u037b\u037b\u037b&&&a    "
    ],
    [
      " a\u0384\u0384a \u0385  \u0386 a    ",
      " a\u0384\u0384a      a    ",
      " faaaaa\u0387\u0387\u0387\u0387f  I ",
      " a    a    a    ",
      " a \u0386  a  \u0388 a    ",
      " T    a    a    ",
      " T\u0389\u0389\u0389\u0389a\u0389\u0389\u0389\u0389a    ",
      " \u038a\u0387\u0387\u0387\u0387a\u0387\u0387\u0387\u0387a    ",
      "      \u038c    a    ",
      " \u038a \u0386     \u0386 a    ",
      " Y         a    ",
      " faaa\u037e   \u0389\u0389f  I ",
      " a\u0384\u0384a      a    ",
      " a\u0384\u0384a \u0385  \u0388 a    ",
      " a\u0384\u0384a      a    ",
      " aaaa\u0389\u0389\u0389\u0389\u0389\u0389a    "
    ],
    [
      " \u038ed ddddddd\u038e  \u038f ",
      " \u038ed ddddddd\u038e  \u038f ",
      " fdddddddddf  f ",
      " \u038eddddddddd\u038e  \u038f ",
      " \u038eddddddddd\u038e  \u038f ",
      " \u038eddddddddd\u038e  \u038f ",
      " \u038eddddddddd\u038e  \u038f ",
      " \u038eddddddddd\u038e  \u038f ",
      " \u038eddddddddd\u038e  \u038f ",
      " \u038eddddddddd\u038e  \u038f ",
      " \u038eddddddddd\u038e  \u038f ",
      " fdddddddddf  f ",
      " \u038ed ddddddd\u038e  \u038f ",
      " \u038ed ddddddd\u038e  \u038f ",
      " \u038ed\u0390ddddddd\u038e  \u038f ",
      " \u038eddddddddd\u038e  \u038f "
    ]
  ]
}