{
  "name": "multi_sunkenmonumentpark_10_base1",
  "refpalette": "deceasedcraft:multi_sunkenmonumentpark_10/multi_sunkenmonumentpark_10_base1_palette",
  "xsize": 16,
  "zsize": 16,
  "slices": [
    [
      "aaaaaaaabbbbbbbb",
      "aaaaaaaabbbbbbbb",
      "aaaaaaaabbbbbbbb",
      "aaaaaaabbbbbbbbb",
      "aaaaaaabbbbbbbbb",
      "aaaaaabbbbbbbbbb",
      "aaaaabbbbbbbbbbb",
      "aaabbbbbbbbbbbbb",
      "bbbbbbbbbbbbbbbb",
      "bbbbbbbbbbbbbbbb",
      "bbbbbbbbbbbbbbbb",
      "bbbbbbbbbbbbbbbb",
      "bbbbbbbbbbbbbbbb",
      "bbbbbbbbbbbbbbbb",
      "bbbbbbbbbbbbbbbb",
      "bbbbbbbbbbbbbbbb"
    ],
    [
      "ccccccdd=eeeeeea",
      "ccccccdd=eeeeeea",
      "cccccddd=eeeefea",
      "cccccdd=eeeeeeea",
      "ccccddd=eeeeeeab",
      "ccdddd=eeeeeeeab",
      "ddddd=eeeeeeeeab",
      "ddd==eeeeeefeabb",
      "===eeeeeeeeeeabb",
      "eeeeeeeeeeeeabbb",
      "eeeeeeeeeeeabbbb",
      "eeeeeee!eeabbbbb",
      "eeeeeeeeeabbbbbb",
      "eefeeeeaabbbbbbb",
      "eeeeaaabbbbbbbbb",
      "aaaabbbbbbbbbbbb"
    ],
    [
      "cccccc  g     hi",
      "cccccc  g     hi",
      "ccccc   g    j k",
      "ccccc  g       k",
      "cccc   g    l km",
      "cc    g     n km",
      "     g        km",
      "   gg      j kmm",
      "ggg          kmm",
      "            kmmm",
      "           kmmmm",
      "       j  kmmmmm",
      "    op   kmmmmmm",
      "  j    kkmmmmmmm",
      "hh  kkkmmmmmmmmm",
      "qqkkmmmmmmmmmmmb"
    ],
    [
      "cccccc          ",
      "cccccc          ",
      "ccccc        r  ",
      "ccccc           ",
      "cccc            ",
      "cc              ",
      "                ",
      "           r    ",
      "                ",
      "              s ",
      "               t",
      "       r        ",
      "           u  s ",
      "  r           sk",
      "          s su k",
      "          u  kkm"
    ],
    [
      "wwwwxx          ",
      "wwwwxx          ",
      "wwwxx        y  ",
      "wwxxx           ",
      "xxxx            ",
      "xx              ",
      "                ",
      "           y    ",
      "                ",
      "                ",
      "               A",
      "       y        ",
      "           r    ",
      "  y             ",
      "             r  ",
      "          r     "
    ],
    [
      "                ",
      "  a B           ",
      " C           y  ",
      "DE B            ",
      " B              ",
      "                ",
      "                ",
      "           y    ",
      "                ",
      "                ",
      "               r",
      "       y        ",
      "           y    ",
      "  y             ",
      "             y  ",
      "          y     "
    ]
  ]
}