{
  "name": "multi_sunkenmonumentpark_10_ground",
  "refpalette": "deceasedcraft:multi_sunkenmonumentpark_10/multi_sunkenmonumentpark_10_ground_palette",
  "xsize": 16,
  "zsize": 16,
  "slices": [
    [
      "                ",
      "  a             ",
      "bc              ",
      "bb              ",
      "                ",
      "                ",
      "                ",
      "                ",
      "                ",
      "                ",
      "               d",
      "                ",
      "           d    ",
      "                ",
      "             d  ",
      "          d     "
    ],
    [
      "eef           gg",
      "ffa           gg",
      "bc           hgg",
      "bb            gg",
      "             ggg",
      "             ggg",
      "            gggg",
      "           hgggg",
      "           ggggg",
      "          gggg  ",
      "         gggg  d",
      "       igggg    ",
      "      ggggg     ",
      "  j gggggg      ",
      "ggggggggg    k  ",
      "ggggggggg k     "
    ],
    [
      "ccl          mnn",
      "ocl          mnn",
      " cp          mnn",
      "bb           mnn",
      "            mnnn",
      "            mnnn",
      "           mnnnn",
      "           mnnnn",
      "          mnnnmm",
      "         mnnnm  ",
      "        mnnnm  k",
      "      mmnnnm    ",
      "    mmnnnnm     ",
      "mmmmnnnnnm      ",
      "nnnnnnnnm       ",
      "nnnnnnnnm       "
    ],
    [
      "cqrs         t  ",
      "ours         t  ",
      "uuw          t  ",
      "             t  ",
      "            x   ",
      "            t   ",
      "           x    ",
      "           t    ",
      "          x   yA",
      "         x   A  ",
      "        x   A   ",
      "      xB   A    ",
      "    xB    A     ",
      "BBBB     A      ",
      "        C       ",
      "        A       "
    ],
    [
      "c cs            ",
      "  cs            ",
      "  D             ",
      "                ",
      "                ",
      "                ",
      "                ",
      "                ",
      "                ",
      "                ",
      "                ",
      "                ",
      "                ",
      "                ",
      "                ",
      "                "
    ],
    [
      "cso             ",
      "                ",
      "                ",
      "                ",
      "                ",
      "                ",
      "                ",
      "                ",
      "                ",
      "                ",
      "                ",
      "                ",
      "                ",
      "                ",
      "                ",
      "                "
    ]
  ]
}