{
  "name": "multi_terraceplaza_27_base1",
  "refpalette": "deceasedcraft:multi_terraceplaza_27/multi_terraceplaza_27_base1_palette",
  "xsize": 16,
  "zsize": 16,
  "slices": [
    [
      "a               ",
      "a               ",
      "a               ",
      "a               ",
      "a               ",
      "a               ",
      "a               ",
      "a               ",
      "a               ",
      "a               ",
      "     b cddcdcded",
      "ffffffffffffffff",
      "fggggggggggggggg",
      "hhhhhhhhhhhhhhhh",
      "iiiiiiiiiiiiiiii",
      "vvvvvvvvvvvvvvvv"
    ],
    [
      "a               ",
      "a               ",
      "a               ",
      "a               ",
      "a               ",
      "a               ",
      "a               ",
      "a               ",
      "a               ",
      "a               ",
      "     j kddldkdkd",
      "ffffffffffffffff",
      "f     m     m   ",
      "hhhhhhhhhhhhhhhh",
      "iiiiiiiiiiiiiiii",
      "vvvvvvvvvvvvvvvv"
    ],
    [
      "an              ",
      "an              ",
      "an              ",
      "an              ",
      "an              ",
      "an              ",
      "an              ",
      "an              ",
      "an              ",
      "an              ",
      "                ",
      "ffffffffffffffff",
      "oooooooooooooooo",
      "hhhhhhhhhhhhhhhh",
      "iiiiiiiiiiiiiiii",
      "vvvvvvvvvvvvvvvv"
    ],
    [
      "aaaaaaaaaaaaaaaa",
      "aaaaaaaaaaaaaaaa",
      "aaaaaaaaaaaaaaaa",
      "aaaaaaaaaaaaaaaa",
      "aaaaaaaaaaaaaaaa",
      "aaaaaaaaaaaaaaaa",
      "aaaaaaaaaaaaaaaa",
      "aaaaaaaaaaaaaaaa",
      "aaaaaaaaaaaaaaaa",
      "aaaaaaaaaaaaaaaa",
      "pppppppppppppppp",
      "ffffffffffffffff",
      "iiiiiiiiiiiiiiii",
      "hhhhhhhhhhhhhhhh",
      "iiiiiiiiiiiiiiii",
      "vvvvvvvvvvvvvvvv"
    ],
    [
      "ooooooqoooooqooo",
      "iiiiiiiiiiiiiiii",
      "iiiiiiiiiiiiiiii",
      "iiiiiiiiiiiiiiii",
      "iiiiiiiiiiiiiiii",
      "iiiiiiiiiiiiiiii",
      "iiiiiiiiiiiiiiii",
      "iiiiiiiiiiiiiiii",
      "rrrrrrrrrrrrrrrr",
      "srsrrssrrrrsrrrs",
      "rrssrrrsrrrrssrr",
      "rrrrrrrrrrrrrrrr",
      "rrrrrrrrrrrrrrrr",
      "hhhhhhhhhhhhhhhh",
      "iiiiiiiiiiiiiiii",
      "vvvvvvvvvvvvvvvv"
    ],
    [
      "iiiiiiiiiiiiiiii",
      "iiiiiiiiiiiiiiii",
      "iiiiiiiiiiiiiiii",
      "iiiiiiiiiiiiiiii",
      "iiiiiiiiiiiiiiii",
      "irrrrrrrrrrrrrrr",
      "rrrrrrrrrrrrrrrr",
      "rrrrrrrrrrrrrrrr",
      "rtttttt    ttttt",
      "                ",
      "    u    u    u ",
      "wxyABwxyABwxyABw",
      "rrrrrrrrrrrrrrrr",
      "CCCCCCCCCCCCCCCC",
      "iiiiiiiiiiiiiiii",
      "vvvvvvvvvvvvvvvv"
    ]
  ]
}