{
  "name": "multi_terraceplaza_27_base2",
  "refpalette": "deceasedcraft:multi_terraceplaza_27/multi_terraceplaza_27_base2_palette",
  "xsize": 16,
  "zsize": 16,
  "slices": [
    [
      "aaaaaaaaaaaaaaaa",
      "aaaaaaaaaaaaaaaa",
      "aaaaaaaaaaaaaaaa",
      "aaaaaaaaaaaaaaaa",
      "aaaaaaaaaaaaaaaa",
      "aaaaaaaaaaaaaaaa",
      "aaaaaaaaaaaaaaaa",
      "aaaaaaaaaaaaaaaa",
      "aaaaaaaaaaaaaaaa",
      "aaaaaaaaaaaaaaaa",
      "aaaaaaaaaaaaaaaa",
      "aaaaaaaaaaaaaaaa",
      "aaaaaaaaaaaaaaaa",
      "bbbbbbbbbbbbbbbb",
      "cccccccccccccccc",
      "vvvvvvvvvvvvvvvv"
    ],
    [
      "d    effgffgh   ",
      "i               ",
      "i               ",
      "i               ",
      "i    j j j j    ",
      "i               ",
      "i               ",
      "i               ",
      "i     k k k k   ",
      "d               ",
      "                ",
      "l            m m",
      "lnnnnnnnnnnnnooo",
      "bbbbbbbbbbbbbbbb",
      "cccccccccccccccc",
      "vvvvvvvvvvvvvvvv"
    ],
    [
      "d    epqpqgph   ",
      "                ",
      "                ",
      "                ",
      "                ",
      "                ",
      "                ",
      "                ",
      "                ",
      "d               ",
      "                ",
      "l               ",
      "lr  s    t    mu",
      "bbbbbbbbbbbbbbbb",
      "cccccccccccccccc",
      "vvvvvvvvvvvvvvvv"
    ],
    [
      "d    ewgwgwwh   ",
      "                ",
      "                ",
      "                ",
      "                ",
      "                ",
      "                ",
      "                ",
      "                ",
      "d               ",
      "                ",
      "l               ",
      "lxx!x x xxx x   ",
      "bbbbbbbbbbbbbbbb",
      "cccccccccccccccc",
      "vvvvvvvvvvvvvvvv"
    ],
    [
      "d               ",
      "                ",
      "                ",
      "                ",
      "                ",
      "                ",
      "                ",
      "                ",
      "                ",
      "d               ",
      "                ",
      "l               ",
      "l               ",
      "bbbbbbbbbbbbbbbb",
      "cccccccccccccccc",
      "vvvvvvvvvvvvvvvv"
    ],
    [
      "d        y      ",
      "d               ",
      "d               ",
      "d               ",
      "d               ",
      "d               ",
      "d               ",
      "d               ",
      "d               ",
      "d               ",
      "                ",
      "llllllllllllllll",
      "l               ",
      "bbbbbbbbbbbbbbbb",
      "cccccccccccccccc",
      "vvvvvvvvvvvvvvvv"
    ]
  ]
}