{
  "name": "multi_terraceplaza_27_ground",
  "refpalette": "deceasedcraft:multi_terraceplaza_27/multi_terraceplaza_27_ground_palette",
  "xsize": 16,
  "zsize": 16,
  "slices": [
    [
      "aaaaaaaaaaaaaaaa",
      "aaaaaaaaaaaaaaaa",
      "aaabbbbbbbbbbbbb",
      "abbbcccccccccccc",
      "bbcccccccccccccc",
      "bccccddd     ddd",
      "                ",
      "                ",
      "                ",
      "                ",
      "                ",
      "    e    e    e ",
      "ffff!fffffffffgf",
      "bbbbbbbbbbbbbbbb",
      "aaaaaaaaaaaaaaaa",
      "aaaaaaaaaaaaaaaa"
    ],
    [
      "                ",
      "                ",
      "                ",
      "                ",
      "h               ",
      "i               ",
      "                ",
      "                ",
      "                ",
      "                ",
      "                ",
      "    j    j    j ",
      "                ",
      "iiiikiiiiiiiiiki",
      "                ",
      "                "
    ],
    [
      "                ",
      "                ",
      "                ",
      "                ",
      "                ",
      "                ",
      "                ",
      "                ",
      "                ",
      "                ",
      "                ",
      "    j    j    j ",
      "                ",
      "                ",
      "                ",
      "                "
    ],
    [
      "                ",
      "                ",
      "                ",
      "                ",
      "                ",
      "                ",
      "                ",
      "                ",
      "                ",
      "                ",
      "                ",
      "                ",
      "                ",
      "                ",
      "                ",
      "                "
    ],
    [
      "                ",
      "                ",
      "                ",
      "                ",
      "                ",
      "                ",
      "                ",
      "                ",
      "                ",
      "                ",
      "                ",
      "                ",
      "                ",
      "                ",
      "                ",
      "                "
    ],
    [
      "llllllllmnolllll",
      "llllllllmpolllll",
      "llllllllmqolllll",
      "lllllllllrllllll",
      "                ",
      "                ",
      "                ",
      "                ",
      "                ",
      "                ",
      "                ",
      "                ",
      "                ",
      "                ",
      "                ",
      "                "
    ]
  ]
}