{
  "name": "multi_terraceplaza_23_ground",
  "refpalette": "deceasedcraft:multi_terraceplaza_23/multi_terraceplaza_23_ground_palette",
  "xsize": 16,
  "zsize": 16,
  "slices": [
    [
      "aaaaaaaaabcccccc",
      "aaaaaaaaabcccccc",
      "aaaaaaaaabcccccc",
      "aaaaaaaaabcccccc",
      "aaaaaaaaad bbd b",
      "aaaaaaaaaefffe  ",
      "aaaaaaaaaefffe  ",
      "aaaaaaaaaefffe  ",
      "aaaaaaaaageeeeee",
      "aaaaaaaaabhhhhhh",
      "aaaaaaaaabhhhhhh",
      "aaaaaaaaabhhhhhh",
      "aaaaaaaaabhhhhhh",
      "aaaaaaaaabhhhhhh",
      "aaaaaaaaabhhhhhh",
      "aaaaaaaaabhhhhhh"
    ],
    [
      "         ijkk jk",
      "                ",
      "                ",
      "         lmkk mk",
      "        noepqeep",
      "         ersse  ",
      "         et  e  ",
      " l       etuue  ",
      "now      geeeeee",
      " i       x      ",
      "         x     y",
      "         AB     ",
      "          B CD  ",
      "          B CD  ",
      "          B CD  ",
      "  E       B CD  "
    ],
    [
      "                ",
      "                ",
      "                ",
      "                ",
      "         FeIJeeI",
      "         eK  e  ",
      "         et  e  ",
      "         etuue  ",
      " F       geeeeee",
      "         x      ",
      "         x      ",
      "         AB     ",
      "          B LM  ",
      "          B NM  ",
      "          B LO  ",
      "          B LM  "
    ],
    [
      "                ",
      "                ",
      "                ",
      "                ",
      "         PeQQeeQ",
      "         et  e  ",
      "         et  e  ",
      "         etuue  ",
      " R       geeeeee",
      "         x      ",
      "         x      ",
      "         AB     ",
      "          B ST  ",
      "          B U   ",
      "          B TU  ",
      "          B  V  "
    ],
    [
      "                ",
      "                ",
      "                ",
      "                ",
      "          eeeeee",
      "         etWWe  ",
      "         et  e  ",
      "         etuue  ",
      " R       geeeeee",
      "         x      ",
      "         x      ",
      "         AB     ",
      "          B     ",
      "          B     ",
      "          B     ",
      "          B     "
    ],
    [
      "         e      ",
      "         e      ",
      "         e      ",
      "         e      ",
      "         eeeeeee",
      "         ettte  ",
      "         ettte  ",
      "         ettte  ",
      "         geeeeee",
      "         Q      ",
      "         Q      ",
      "        XQY     ",
      "        XQY     ",
      "        XQY     ",
      "        XQY     ",
      "        XQY     "
    ]
  ]
}