{
  "name": "multi_terraceplaza_23_floor4",
  "refpalette": "deceasedcraft:multi_terraceplaza_23/multi_terraceplaza_23_floor4_palette",
  "xsize": 16,
  "zsize": 16,
  "slices": [
    [
      "         abc!dec",
      "         affffff",
      "         affffff",
      "         abcg ec",
      "         ahihhhi",
      "jjjjjjjjja k h k",
      "llllllllla m h m",
      "nnnnnnnnna o h o",
      "pppppppppppppppp",
      "pppppppppppppppp",
      "                ",
      "                ",
      "                ",
      "                ",
      "                ",
      "                "
    ],
    [
      "         a      ",
      "         a      ",
      "jjjjjjjjja      ",
      "llllllllla      ",
      "nnnnnnnnna      ",
      "pppppppppa      ",
      "ppppppppppqqqqqq",
      "rrrrrrrrrrrrrrrr",
      "ssssssssssssssss",
      "                ",
      "                ",
      "                ",
      "                ",
      "                ",
      "                ",
      "                "
    ],
    [
      "llllllllla      ",
      "nnnnnnnnna      ",
      "pppppppppa      ",
      "ppppppppppqqqqqq",
      "rrrrrrrrrrrrrrrr",
      "ssssssssssssssss",
      "                ",
      "                ",
      "                ",
      "                ",
      "                ",
      "                ",
      "                ",
      "                ",
      "                ",
      "                "
    ],
    [
      "ppppppppppqqqqqq",
      "rrrrrrrrrrrrrrrr",
      "ssssssssssssssss",
      "                ",
      "                ",
      "                ",
      "                ",
      "                ",
      "                ",
      "                ",
      "                ",
      "                ",
      "                ",
      "                ",
      "                ",
      "                "
    ],
    [
      "                ",
      "                ",
      "                ",
      "                ",
      "                ",
      "                ",
      "                ",
      "                ",
      "                ",
      "                ",
      "                ",
      "                ",
      "                ",
      "                ",
      "                ",
      "                "
    ],
    [
      "                ",
      "                ",
      "                ",
      "                ",
      "                ",
      "                ",
      "                ",
      "                ",
      "                ",
      "                ",
      "                ",
      "                ",
      "                ",
      "                ",
      "                ",
      "                "
    ]
  ]
}