{
  "name": "multi_terraceplaza_23_floor1",
  "refpalette": "deceasedcraft:multi_terraceplaza_23/multi_terraceplaza_23_floor1_palette",
  "xsize": 16,
  "zsize": 16,
  "slices": [
    [
      "         a      ",
      "         a     b",
      "         a      ",
      "         a      ",
      "         aaaaaaa",
      "         a   a  ",
      "         a   a  ",
      "         a   a  ",
      "         caaaaaa",
      "         d      ",
      "         d      ",
      "         d      ",
      "         d      ",
      "         d      ",
      "         d      ",
      "         d      "
    ],
    [
      "eeeeeeeeefgggggg",
      "eeeeeeeeefghgggh",
      "eeeeeeeeefghgggh",
      "eeeeeeeeefgggggg",
      "eeeeeeeeefaaaaaa",
      "eeeeeeeeef   a  ",
      "eeeeeeeeef   a  ",
      "eeeeeeeeef   a  ",
      "fffffffffcffffff",
      "eeeeeeeeefgggggg",
      "eeeeeeeeefgiggig",
      "eeeeeeeeefgggggg",
      "eeeeeeeeefgggggg",
      "eeeeeeeeefgiggig",
      "eeeeeeeeefgggggg",
      "eeeeeeeeefgggggg"
    ],
    [
      "jjjjjjjjjkllllll",
      "jjjjjjjjjkllllll",
      "jjjjjjjjjkllllll",
      "jjjjjjjjjkllllll",
      "jjjjjjjjjm kkm k",
      "jjnjjjjjja   a  ",
      "jjnjjjjjja   a  ",
      "jjnjjjjjja   a  ",
      "jjnjjjjjjcaaaaaa",
      "jjnjjjjjjkoooooo",
      "jjjjjjjjjkoooooo",
      "jjjjjjjjjkoooooo",
      "jjjjjjjjjkoooooo",
      "jjjjjjjjjkoooooo",
      "jjjjjjjjjkoooooo",
      "jjjjjjjjjkoooooo"
    ],
    [
      "         pqrr qr",
      "                ",
      "                ",
      "         strr tr",
      "  u     wxayAaay",
      " uB      a   a  ",
      " CB      a   a  ",
      " nB      a   a  ",
      "wxD      caaaaaa",
      " n       EFIJJKL",
      " nM      E N   L",
      "         O P QQL",
      "               L",
      "               L",
      "               L",
      "              RL"
    ],
    [
      "                ",
      "                ",
      "                ",
      "                ",
      "         SaTUaaT",
      "         a   a  ",
      "         a   a  ",
      "         a   a  ",
      " S       caaaaaa",
      " V       EW     ",
      " X       E      ",
      "         O Y    ",
      "                ",
      "                ",
      "                ",
      "                "
    ],
    [
      "                ",
      "                ",
      "                ",
      "                ",
      "         Zaddaad",
      "         a   a  ",
      "         a   a  ",
      "         a   a  ",
      " W       caaaaaa",
      "         EW     ",
      "         E      ",
      "         O      ",
      "                ",
      "                ",
      "                ",
      "                "
    ]
  ]
}