{
  "name": "multi_terraceplaza_23_base1",
  "refpalette": "deceasedcraft:multi_terraceplaza_23/multi_terraceplaza_23_base1_palette",
  "xsize": 16,
  "zsize": 16,
  "slices": [
    [
      "aaaaaaaaabcccccc",
      "aaaaaaaaabcccccc",
      "aaaaaaaaabcccccc",
      "aaaaaaaaabcccccc",
      "aaaaaaaaad bbd b",
      "aaaaaaaaae   e  ",
      "aaafggaaae   e  ",
      "aaa!aaaaae   e  ",
      "hhhhhhhhhieeeeee",
      "                ",
      "                ",
      "                ",
      "                ",
      "                ",
      "                ",
      "                "
    ],
    [
      "         jkll kl",
      "                ",
      "                ",
      "         mnll nl",
      "        ogepqeep",
      "         e   e  ",
      " rs ttu  e   e  ",
      " wwwxu   e   e  ",
      "yyyyyyyyyieeeeee",
      "                ",
      "                ",
      "                ",
      "                ",
      "                ",
      "                ",
      "                "
    ],
    [
      "                ",
      "                ",
      "                ",
      "                ",
      "         teABeeA",
      "         e   e  ",
      "         e   e  ",
      " CD      e   e  ",
      "         ieeeeee",
      "                ",
      "                ",
      "                ",
      "                ",
      "                ",
      "                ",
      "                "
    ],
    [
      "                ",
      "                ",
      "                ",
      "                ",
      "         EeFFeeF",
      "         e   e  ",
      "         e   e  ",
      "         e   e  ",
      "         ieeeeee",
      "FFFFFFFFFFFFFFFF",
      "II              ",
      "II              ",
      "II              ",
      "II              ",
      "II              ",
      "II              "
    ],
    [
      "         J      ",
      "         J     K",
      "         J      ",
      "         J      ",
      "         Jeeeeee",
      "         e   e  ",
      "         e   e  ",
      "         e   e  ",
      "         ieeeeee",
      "FFFFFFFFFFFFFFFF",
      "LMMMMMMMMMMMMMMM",
      "LMMMMMMMMMMMMMMM",
      "LMMMMMMMMMMMMMMM",
      "LMMMMMMMMMMMMMMM",
      "LMMMMMMMMMMMMMMM",
      "LMMMMMMMMMMMMMMM"
    ],
    [
      "NNNNNNNNNOPPPPPP",
      "NNNNNNNNNOPQPPPQ",
      "NNNNNNNNNOPQPPPQ",
      "NNNNNNNNNOPPPPPP",
      "NNNNNNNNNOeeeeee",
      "NNNNNNNNNO   e  ",
      "NNNNNNNNNO   e  ",
      "NNNNNNNNNO   e  ",
      "OOOOOOOOOiOOOOOO",
      "FFFFFFFFFOFFFFFF",
      "RSSSSSSSSOSSSSSS",
      "RSSSSSSSSOSSSSSS",
      "RSSSSSSSSOSSSSSS",
      "RSSSSSSSSOSSSSSS",
      "RSSSSSSSSOSSSSSS",
      "RSSSSSSSSOSSSSSS"
    ]
  ]
}