{
  "name": "multi_terraceplaza_23_floor3",
  "refpalette": "deceasedcraft:multi_terraceplaza_23/multi_terraceplaza_23_floor3_palette",
  "xsize": 16,
  "zsize": 16,
  "slices": [
    [
      "                ",
      "                ",
      "                ",
      "                ",
      "         abcdbbc",
      "         b   b  ",
      "         b   b  ",
      "         b   b  ",
      " a       ebbbbbb",
      "                ",
      "                ",
      "             f  ",
      "              gh",
      "              i ",
      "              j ",
      "              kl"
    ],
    [
      "                ",
      "                ",
      "                ",
      "                ",
      "         mbnnbbn",
      "         b   b  ",
      "         b   b  ",
      "         b   b  ",
      " o       ebbbbbb",
      "                ",
      "                ",
      "                ",
      "              ll",
      "                ",
      "                ",
      "                "
    ],
    [
      "                ",
      "                ",
      "                ",
      "                ",
      "          bbbbbb",
      "         b   b  ",
      "         b   b  ",
      "         b   b  ",
      " o       ebbbbbb",
      "                ",
      "                ",
      "                ",
      "                ",
      "                ",
      "                ",
      "                "
    ],
    [
      "         b      ",
      "         b      ",
      "         b      ",
      "         b      ",
      "         bbbbbbb",
      "         b   b  ",
      "         b   b  ",
      "         b   b  ",
      "         ebbbbbb",
      "                ",
      "                ",
      "                ",
      "                ",
      "                ",
      "pppppppppppppppp",
      "qqqqqqqqqqrrrrrr"
    ],
    [
      "         b      ",
      "         b      ",
      "         b s    ",
      "         b      ",
      "         bbbbbbb",
      "         b   b  ",
      "         b   b  ",
      "         b   b  ",
      "         ebbbbbb",
      "                ",
      "                ",
      "pppppppppppppppp",
      "qqqqqqqqqqrrrrrr",
      "tttttttttttttttt",
      "uuuuuuuuuuuuuuuu",
      "wwwwwwwwww      "
    ],
    [
      "         bxxxxxx",
      "         bxyxxxy",
      "         bxyxxxy",
      "         bxxxxxx",
      "         bbbbbbb",
      "         b   b  ",
      "         b   b  ",
      "         b   b  ",
      "AAAAAAAAAeAAAAAA",
      "qqqqqqqqqqqqqqqq",
      "tttttttttttttttt",
      "uuuuuuuuuuuuuuuu",
      "wwwwwwwwww      ",
      "                ",
      "                ",
      "                "
    ]
  ]
}