{
  "name": "multi_terraceplaza_23_base2",
  "refpalette": "deceasedcraft:multi_terraceplaza_23/multi_terraceplaza_23_base2_palette",
  "xsize": 16,
  "zsize": 16,
  "slices": [
    [
      "aaaaaaaaabcccccc",
      "aaaaaaaaabcccccc",
      "aaaaaaaaabcccccc",
      "aaaaaaaaabcccccc",
      "aaaaaaaaad bbd b",
      "aaaaaaaaae   eff",
      "aaaaaaaaae   eff",
      "aaaaaaaaae   eff",
      "bbbbbbbbbgeeeeee",
      "hhhhhhhhhhhhhhhh",
      "hhhhhhhhhhhhhhhh",
      "hhhhhhhhhhhhhhhh",
      "hhhhhhhhhhhhhhhh",
      "hhhhhhhhhhhhhhhh",
      "hhhhhhhhhhhhhhhh",
      "hhhhhhhhhhhhhhhh"
    ],
    [
      "         ijkk jk",
      "                ",
      "                ",
      "         lmkk mk",
      "        noepqeep",
      "         e   ers",
      "         e   et ",
      "         e   etu",
      "wx yA xwwgeeeeee",
      "                ",
      "                ",
      "                ",
      "                ",
      "                ",
      " BC DE FB BC DE ",
      "  I DE J   I DE "
    ],
    [
      "                ",
      "                ",
      "                ",
      "                ",
      "         KeLMeeL",
      "         e   eN ",
      "         e   et ",
      "         e   etu",
      "wx yA xwwgeeeeee",
      "                ",
      "                ",
      "                ",
      "                ",
      "                ",
      "                ",
      "  O    P   O    "
    ],
    [
      "                ",
      "                ",
      "                ",
      "                ",
      "         QeRReeR",
      "         e   et ",
      "         e   et ",
      "         e   etu",
      "wx    xwwgeeeeee",
      "                ",
      "                ",
      "                ",
      "                ",
      "                ",
      "                ",
      "                "
    ],
    [
      "         S      ",
      "         S T    ",
      "         S T    ",
      "         S      ",
      "         Seeeeee",
      "         e   etU",
      "         e   et ",
      "         e   etu",
      "wxV  Vxwwgeeeeee",
      "         W      ",
      "                ",
      "                ",
      "                ",
      "                ",
      "                ",
      "                "
    ],
    [
      "XXXXXXXXXYZZZZZZ",
      "XXXXXXXXXYZfZZZf",
      "XXXXXXXXXYZfZZZf",
      "XXXXXXXXXYZZZZZZ",
      "XXXXXXXXXYeeeeee",
      "XXXXXXXXXY   ett",
      "XXXXXXXXXY   ett",
      "XXXXXXXXXY   ett",
      "YYYYYYYYYgeeeeee",
      " 000000         ",
      "                ",
      "                ",
      "                ",
      "                ",
      "                ",
      "                "
    ]
  ]
}