{
  "name": "multi_terraceplaza_23_floor2",
  "refpalette": "deceasedcraft:multi_terraceplaza_23/multi_terraceplaza_23_floor2_palette",
  "xsize": 16,
  "zsize": 16,
  "slices": [
    [
      "                ",
      "                ",
      "                ",
      "                ",
      "          aaaaaa",
      "         a   a  ",
      "         a   a  ",
      "         a   a  ",
      " b       caaaaaa",
      "         d      ",
      "         d      ",
      "         e      ",
      "                ",
      "                ",
      "                ",
      "                "
    ],
    [
      "         a      ",
      "         a      ",
      "         a      ",
      "         a      ",
      "         aaaaaaa",
      "         a   a  ",
      "         a   a  ",
      "         a   a  ",
      "         caaaaaa",
      "         f      ",
      "         f      ",
      "        gfh     ",
      "        ifh     ",
      "        jfh   k ",
      "        jfh     ",
      "        ifh     "
    ],
    [
      "         a      ",
      "         a     l",
      "         a     l",
      "         a      ",
      "         aaaaaaa",
      "         a   a  ",
      "         a   a  ",
      "         a   a  ",
      "         caaaaaa",
      "         f      ",
      "         f      ",
      "         f  m   ",
      "         f   k  ",
      "         f    k ",
      "         f     k",
      "         f   k  "
    ],
    [
      "nnnnnnnnnopppppp",
      "nnnnnnnnnopqpppq",
      "nnnnnnnnnopqpppq",
      "nnnnnnnnnopppppp",
      "nnnnnnnnnoaaaaaa",
      "nnnnnnnnno   a  ",
      "nnnnnnnnno   a  ",
      "nnnnnnnnno   a  ",
      "ooooooooocoooooo",
      "nnnnnnnnnopppppp",
      "nnnnnnnnnopppppp",
      "nnnnnnnnnoppprrr",
      "nnnnnnnnnopprkss",
      "nnnnnnnnnopprskk",
      "nnnnnnnnnopprskk",
      "nnnnnnnnnopprkss"
    ],
    [
      "tttttttttuwwwwww",
      "tttttttttuwwwwww",
      "tttttttttuwwwwww",
      "tttttttttuwwwwww",
      "tttttttttx uux u",
      "ttytttttta   a  ",
      "ttytttttta   a  ",
      "ttytttttta   a  ",
      "ttyttttttcaaaaaa",
      "ttyttttttuAAAAAA",
      "ttyttttttuAAAAAA",
      "ttyttttttuAAAAAA",
      "tttttttttuAAAAAA",
      "tttttttttuAAAAAA",
      "tttttttttuAAAAAA",
      "tttttttttuAAAAAB"
    ],
    [
      "         CDEE DE",
      "                ",
      "                ",
      "         FIEE IE",
      "  J     KLaMNaaM",
      " JO      a   a  ",
      " PO      a   a  ",
      " yO      a   a  ",
      "KLQ      caaaaaa",
      " yO             ",
      " RO             ",
      " JO          SSS",
      "  J          S==",
      "             STU",
      "             S=V",
      "             S=W"
    ]
  ]
}