{
  "name": "multi_cabin1_0_floor1",
  "refpalette": "deceasedcraft:multi_cabin1_0/multi_cabin1_0_floor1_palette",
  "xsize": 16,
  "zsize": 16,
  "slices": [
    [
      "abbbbbbbbbbbbaab",
      "babbaaaaabbbbaaa",
      "baaaaccaaaabbbab",
      "aaaacccccaaabbba",
      "aaacccccccaaabbb",
      "aaacccccccccaabb",
      "aaaccccccccccaab",
      "aacccccccccccaab",
      "aaccccccccccccab",
      "baccccccccccccaa",
      "baccccccccccccaa",
      "baccccccccccccaa",
      "aacccccccccccaaa",
      "aacccccccccccaab",
      "aaaccccccccccaaa",
      "aaacccccccccccaa"
    ],
    [
      "bbbbbbbbbbbbbbbb",
      "bbbbbbbbbbbbbbdb",
      "bbbbbaabbbbbbbbb",
      "bbbbaaaaabbbbbbb",
      "bdbaaacccabbbbbb",
      "bbbaaccccaaabbbb",
      "bbbacccccccaabbb",
      "bbaaccccccccabbb",
      "bbaeecccccceeabb",
      "bbaaacccccccaabb",
      "bbaaacccccccaabb",
      "bbaaccccccccaabb",
      "bbaaccccccccabbb",
      "bbaacccccccaabbb",
      "bbbaaccccccaabbb",
      "bbbaacccccccaabb"
    ],
    [
      "bbbbbbbbbbbbbbbb",
      "bbbbbbbbbbbbbbfb",
      "bbbbbbbbbbbbbbbb",
      "bbbbbbbbbbbbbbbb",
      "bfbbbbaaabbbbbbb",
      "bbbbbagaabbbbbbb",
      "bbbbaaccaaabbbbb",
      "bbbbacccccaabbbb",
      "bbbeecccccceebbb",
      "bbbbbcccccccbbbb",
      "bbbbbccccccabbbb",
      "bbbbaccccccabbbb",
      "bbbbaaccccaabbbb",
      "bbbbaaccccabbbbb",
      "bbbbbaccccabbbbb",
      "bbbbbaacccaabbbb"
    ],
    [
      "bbbbbbbbbbbbbbbb",
      "bbbbbbbbbbbbbbbb",
      "bbbbbbbbbbbbbbbb",
      "bbbbbbbbbbbbbbbb",
      "bbbbbbbbbbbbbbbb",
      "bbbbbbbbbbbbbbbb",
      "bbbbbbagbbbbbbbb",
      "bbbbbagagabbbbbb",
      "bbbbbaagagabbbbb",
      "bbbhhaaggaahhbbb",
      "bbbiiccjjcciibbb",
      "bbbbbckjjkcbbbbb",
      "bbbbbbccccbbbbbb",
      "bbbbbbccccbbbbbb",
      "bbbbbbaaaabbbbbb",
      "bbbbbbbaaabbbbbb"
    ],
    [
      "bbbbbbbbbbbbbbbb",
      "bbbbbbbbbbbbbbbb",
      "bbbbbbbbbbbbbbbb",
      "bbbbbbbbbbbbbbbb",
      "bbbbbbbbbbbbbbbb",
      "bbbbbbbbbbbbbbbb",
      "bbbbbbbbbbbbbbbb",
      "bbbbbbbbbbbbbbbb",
      "bbbbbbbbbbbbbbbb",
      "bbbbbbbbbbbbbbbb",
      "bbbbbllmnllbbbbb",
      "bbbhhlobbolhhbbb",
      "bbbiiljppjliibbb",
      "bbbiiljjjjliibbb",
      "bbbbblqqqqlbbbbb",
      "bbbbblqqqqlbbbbb"
    ],
    [
      "bbbbbbbbbbbbbbbb",
      "bbbbbbbbbbbbbbbb",
      "bbbbbbbbbbbbbbbb",
      "bbbbbbbbbbbbbbbb",
      "bbbbbbbbbbbbbbbb",
      "bbbbbbbbbbbbbbbb",
      "bbbbbbbbbbbbbbbb",
      "bbbbbbbbbbbbbbbb",
      "bbbbbbbbbbbbbbbb",
      "bbbbbbbbbbbbbbbb",
      "bbbbbllrsllbbbbb",
      "bbbbblobbolbbbbb",
      "bbbbbltbbtlbbbbb",
      "bbbbblbbbblbbbbb",
      "bbbhhlubbulhhbbb",
      "bbbhhlvbbwlhhbbb"
    ]
  ]
}