{
  "name": "multi_cabin1_0_top",
  "refpalette": "deceasedcraft:multi_cabin1_0/multi_cabin1_0_top_palette",
  "xsize": 16,
  "zsize": 16,
  "slices": [
    [
      "aaaaaaaaaaaaaaaa",
      "aaaaaaaaaaaaaaaa",
      "aaaaaaaaaaaaaaaa",
      "aaaaaaaaaaaaaaaa",
      "aaaaaaaaaaaaaaaa",
      "aaaaaaaaaaaaaaaa",
      "aaaaaaaaaaaaaaaa",
      "aaaaaaaaaaaaaaaa",
      "aaaaaaaaaaaaaaaa",
      "aaaaaaaaaaaaaaaa",
      "aaaaabbccbbaaaaa",
      "aaaaabdaadbaaaaa",
      "aaaaabaaaabaaaaa",
      "aaaaabaaaabaaaaa",
      "aaaaabaaaabaaaaa",
      "aaaaabeaafbaaaaa"
    ],
    [
      "aaaaaaaaaaaaaaaa",
      "aaaaaaaaaaaaaaaa",
      "aaaaaaaaaaaaaaaa",
      "aaaaaaaaaaaaaaaa",
      "aaaaaaaaaaaaaaaa",
      "aaaaaaaaaaaaaaaa",
      "aaaaaaaaaaaaaaaa",
      "aaaaaggggggaaaaa",
      "aaaaaghhhhgaaaaa",
      "aaaaaghhhhgaaaaa",
      "aaaaagdggdgaaaaa",
      "aaaaagaaaagaaaaa",
      "aaaaagaaaagaaaaa",
      "aaaaagaaaagaaaaa",
      "aaaaagaaaagaaaaa",
      "aaaaagaaaagaaaaa"
    ],
    [
      "aaaaaaaaaaaaaaaa",
      "aaaaaaaaaaaaaaaa",
      "aaaaaaaaaaaaaaaa",
      "aaaaaaaaaaaaaaaa",
      "aaaaaaaaaaaaaaaa",
      "aaaaaaaaaaaaaaaa",
      "aaaaaaaaaaaaaaaa",
      "aaaaaggggggaaaaa",
      "aaaaagijjigaaaaa",
      "aaaaagakkagaaaaa",
      "aaaaagallagaaaaa",
      "aaaaagaaaagaaaaa",
      "aaaaagaaaagaaaaa",
      "aaaaagaaaagaaaaa",
      "aaaaagaaaagaaaaa",
      "aaaaagaaaagaaaaa"
    ],
    [
      "aaaaaaaaaaaaaaaa",
      "aaaaaaaaaaaaaaaa",
      "aaaaaaaaaaaaaaaa",
      "aaaaaaaaaaaaaaaa",
      "aaaaaaaaaaaaaaaa",
      "aaaaaaaaaaaaaaaa",
      "aaaaaaaaaaaaaaaa",
      "aaaaagmmmmgaaaaa",
      "aaaaagaaangaaaaa",
      "aaaaagaaaagaaaaa",
      "aaaaagaaaagaaaaa",
      "aaaaagllllgaaaaa",
      "aaaaopqqqqpoaaaa",
      "aaaaopqqqqpoaaaa",
      "aaaaopqqqqpoaaaa",
      "aaaaraqqqqaraaaa"
    ],
    [
      "aaaaaaaaaaaaaaaa",
      "aaaaaaaaaaaaaaaa",
      "aaaaaaaaaaaaaaaa",
      "aaaaaaaaaaaaaaaa",
      "aaaaaaaaaaaaaaaa",
      "aaaaaaaaaaaaaaaa",
      "aaaaooooooooaaaa",
      "aaaaoppppppoaaaa",
      "aaaaopqqqqpoaaaa",
      "aaaaraqqqqaraaaa",
      "aaaaraqqqqaraaaa",
      "aaaaraqqqqaraaaa",
      "aaaaaaaaaaaaaaaa",
      "aaaaaaaaaaaaaaaa",
      "aaaaaaaaaaaaaaaa",
      "aaaaaaaaaaaaaaaa"
    ],
    [
      "aaaaaaaaaaaaaaaa",
      "aaaaaaaaaaaaaaaa",
      "aaaaaaaaaaaaaaaa",
      "aaaaaaaaaaaaaaaa",
      "aaaaaaaaaaaaaaaa",
      "aaaaaaaaaaaaaaaa",
      "aaaaaaaaaaaaaaaa",
      "aaaaaaaaaaaaaaaa",
      "aaaaaaaaaaaaaaaa",
      "aaaaaaaaaaaaaaaa",
      "aaaaaaaaaaaaaaaa",
      "aaaaaaaaaaaaaaaa",
      "aaaaaaaaaaaaaaaa",
      "aaaaaaaaaaaaaaaa",
      "aaaaaaaaaaaaaaaa",
      "aaaaaaaaaaaaaaaa"
    ]
  ]
}