{
  "name": "multi_hospital_4_base4",
  "refpalette": "deceasedcraft:multi_hospital_4/multi_hospital_4_base4_palette",
  "xsize": 16,
  "zsize": 16,
  "slices": [
    [
      "vvvvvvvvvvvvvvvv",
      "aaaaaaaaaaaaaaav",
      "aaaaaaaaaaaaaaav",
      "aaaaaaaaaaaaaaav",
      "aaaaaaaaaaaaaaav",
      "aaaaaaaaaaaaaaav",
      "aaaaaaaaaaaaaaav",
      "baaaaaaaaaaaaaav",
      "baaaaaaaaaaaaaav",
      "baaaaaaaaaaaaaav",
      "baaaaaaaaaaaaaav",
      "baaaaaaaaaaaaaav",
      "baaaaaaaaaaaaaav",
      "baaaaaaaaaaaaaav",
      "baaaaaaaaaaaaaav",
      "baaaaaaaaaaaaaav"
    ],
    [
      "vvvvvvvvvvvvvvvv",
      "aaaaaaaaaaaaaaav",
      "aaaaaaaaaaaaaaav",
      "cccaaaaaaaaaaaav",
      "cccaaaaaaaaaaaav",
      "cccaaaaaaaaaaaav",
      "cccaaaaaaaaaaaav",
      "baaaaaaaaaaaaaav",
      "baaaaaaaaaaaaaav",
      "baaaaaaaaaaaaaav",
      "baaaaaaaaaaaaaav",
      "baaaaaaaaaaaaaav",
      "baaaaaaaaaaaaaav",
      "baaaaaaaaaaaaaav",
      "baaaaaaaaaaaaaav",
      "baaaaaaaaaaaaaav"
    ],
    [
      "vvvvvvvvvvvvvvvv",
      "aaaaaaaaaaaaaaav",
      "aaaaaaaaaaaaaaav",
      "cccaaaaaaaaaaaav",
      "ddcaaaaaaaaaaaav",
      "cccaaaaaaaaaaaav",
      "cccaaaaaaaaaaaav",
      "baaaaaaaaaaaaaav",
      "baaaaaaaaaaaaaav",
      "baaaaaaaaaaaaaav",
      "baaaaaaaaaaaaaav",
      "baaaaaaaaaaaaaav",
      "baaaaaaaaaaaaaav",
      "baaaaaaaaaaaaaav",
      "baaaaaaaaaaaaaav",
      "baaaaaaaaaaaaaav"
    ],
    [
      "vvvvvvvvvvvvvvvv",
      "aaaaaaaaaaaaaaav",
      "aaaaaaaaaaaaaaav",
      "cccaaaaaaaaaaaav",
      "edcaaaaaaaaaaaav",
      "cccaaaaaaaaaaaav",
      "cccaaaaaaaaaaaav",
      "baaaaaaaaaaaaaav",
      "baaaaaaaaaaaaaav",
      "baaaaaaaaaaaaaav",
      "baaaaaaaaaaaaaav",
      "baaaaaaaaaaaaaav",
      "baaaaaaaaaaaaaav",
      "baaaaaaaaaaaaaav",
      "baaaaaaaaaaaaaav",
      "baaaaaaaaaaaaaav"
    ],
    [
      "vvvvvvvvvvvvvvvv",
      "aaaaaaaaaaaaaaav",
      "aaaaaaaaaaaaaaav",
      "cccaaaaaaaaaaaav",
      "c caaaaaaaaaaaav",
      "cccaaaaaaaaaaaav",
      "cccaaaaaaaaaaaav",
      "bccaaaaaaaaaaaav",
      "bccaaaaaaaaaaaav",
      "bccaaaaaaaaaaaav",
      "bccaaaaaaaaaaaav",
      "bccaaaaaaaaaaaav",
      "bccaaaaaaaaaaaav",
      "bccaaaaaaaaaaaav",
      "bccaaaaaaaaaaaav",
      "bccaaaaaaaaaaaav"
    ],
    [
      "vvvvvvvvvvvvvvvv",
      "aaaaaaaaaaaaaaav",
      "aaaaaaaaaaaaaaav",
      "cccaaaaaaaaaaaav",
      "cdcaaaaaaaaaaaav",
      "cdcaaaaaaaaaaaav",
      "cdcaaaaaaaaaaaav",
      "bdcaaaaaaaaaaaav",
      "bdcaaaaaaaaaaaav",
      "bdcaaaaaaaaaaaav",
      "bdcaaaaaaaaaaaav",
      "bdcaaaaaaaaaaaav",
      "bdcaaaaaaaaaaaav",
      "bdcaaaaaaaaaaaav",
      "bdcaaaaaaaaaaaav",
      "bdcaaaaaaaaaaaav"
    ]
  ]
}