{
  "name": "multi_hospital_4_ground",
  "refpalette": "deceasedcraft:multi_hospital_4/multi_hospital_4_ground_palette",
  "xsize": 16,
  "zsize": 16,
  "slices": [
    [
      "abHHHHHHHHHHbaaa",
      "HbHHHHHHHHHHbaca",
      "HbHHHHHHHHHHbaaa",
      "bHHHHHHHHHHHHbbb",
      "HHHHHHHHHHHHHHHH",
      "HHHHHHHHHHHHHHHH",
      "HHHHHHHHHHHHHHHH",
      "bHHHHHHHHHHHHbbb",
      "abbbbbbbbbbbbaaa",
      "ddddddddddddddaa",
      "effffffffffffdaa",
      "eggggggggggggdaa",
      "ehhhhhhhhhhhhiaa",
      "e            jaa",
      "e       kkk  jaa",
      "d  kkk lmkmn jaa"
    ],
    [
      "                ",
      "o             p ",
      "q               ",
      " rsssssssssst   ",
      " uwwwwwwwwwwx   ",
      " uwwwwwwwwwwx   ",
      " uwwwwwwwwwwx   ",
      " yAAAAAAAAAAB   ",
      "              C ",
      "D             E ",
      "e             E ",
      "e             E ",
      "eFFFFFFFFFFFFiE ",
      "e       DID  JE ",
      "e  DID  KLK  JE ",
      "M  KLK  NOP  JE "
    ],
    [
      "                ",
      "              Q ",
      "                ",
      "                ",
      "                ",
      "                ",
      "                ",
      "                ",
      "                ",
      "                ",
      "e               ",
      "e               ",
      "eFFFFFFFFFFFFi  ",
      "e            J  ",
      "e       RRR  J  ",
      "M  RRR STTTU J  "
    ],
    [
      "                ",
      "              V ",
      "                ",
      "                ",
      "                ",
      "                ",
      "                ",
      "                ",
      "                ",
      "                ",
      "e               ",
      "e               ",
      "eFFFFFFFFFFFFi  ",
      "e            J  ",
      "e            M  ",
      "M       WXW  M  "
    ],
    [
      "                ",
      "              EY",
      "                ",
      "                ",
      "                ",
      "                ",
      "                ",
      "                ",
      "                ",
      "                ",
      "e               ",
      "e               ",
      "eFFFFFFFFFFFFi  ",
      "e            J  ",
      "e            M  ",
      "M            M  "
    ],
    [
      "              E ",
      "             YEE",
      "              Y ",
      "                ",
      "                ",
      "                ",
      "Z               ",
      "Z               ",
      "Z               ",
      "Z               ",
      "e               ",
      "e               ",
      "eFFFFFFFFFFFFi  ",
      "e            J  ",
      "e            J  ",
      "e            J  "
    ]
  ]
}