{
  "name": "multi_hospital_4_base2",
  "refpalette": "deceasedcraft:multi_hospital_4/multi_hospital_4_base2_palette",
  "xsize": 16,
  "zsize": 16,
  "slices": [
    [
      "vvvvvvvvvvvvvvvv",
      "aaaaaaaaaaaaaaav",
      "aaaaaaaaaaaaaaav",
      "aaaaaaaaaaaaaaav",
      "aaaaaaaaaaaaaaav",
      "aaaaaaaaaaaaaaav",
      "aaaaaaaaaaaaaaav",
      "baaaaaaaaaaaaaav",
      "baaaaaaaaaaaaaav",
      "baaaaaaaaaaaaaav",
      "baaaaaaaaaaaaaav",
      "cddaaaaaaaaaaaav",
      "cddaaaaaaaaaaaav",
      "cddaaaaaaaaaaaav",
      "cddaaaaaaaaaaaav",
      "cddaaaaaaaaaaaav"
    ],
    [
      "vvvvvvvvvvvvvvvv",
      "aaaaaaaaaaaaaaav",
      "aaaaaaaaaaaaaaav",
      "aaaaaaaaaaaaaaav",
      "aaaaaaaaaaaaaaav",
      "aaaaaaaaaaaaaaav",
      "aaaaaaaaaaaaaaav",
      "baaaaaaaaaaaaaav",
      "baaaaaaaaaaaaaav",
      "baaaaaaaaaaaaaav",
      "baaaaaaaaaaaaaav",
      "cddaaaaaaaaaaaav",
      "cddaaaaaaaaaaaav",
      "cddaaaaaaaaaaaav",
      "cddaaaaaaaaaaaav",
      "cddaaaaaaaaaaaav"
    ],
    [
      "vvvvvvvvvvvvvvvv",
      "ebbbbbbbbbbbbbfv",
      "ebbbbbbbbbbbbbfv",
      "ebbbbbbbbbbbbbfv",
      "ebbbbbbbbbbbbbfv",
      "ebbbbbbbbbbbbbfv",
      "ebbbbbbbbbbbbbfv",
      "bbbbbbbbbbbbbbfv",
      "bbbbbbbbbbbbbbfv",
      "bbbbbbbbbbbbbbfv",
      "bbbbbbbbbbbbbbfv",
      "bbbbbbbbbbbbbbfv",
      "bbbbbbbbbbbbbbfv",
      "bbbbbbbbbbbbbbfv",
      "bbbbbbbbbbbbbbfv",
      "bbbbbbbbbbbbbbfv"
    ],
    [
      "vvvvvvvvvvvvvvvv",
      "ebbbbbbbbbbbbbfv",
      "efgggggggggggffv",
      "ehggggggggggghfv",
      "efgggggggggggffv",
      "efgggggggggggffv",
      "eigggggggggggifv",
      "bfgggggggggggffv",
      "bfgggggggggggffv",
      "bhggggggggggghfv",
      "bfgggggggggggffv",
      "bbbgggggggggbbfv",
      "bfgggggggggggffv",
      "bhggggggggggghfv",
      "bfigggggggggiffv",
      "bfigggggggggiffv"
    ],
    [
      "vvvvvvvvvvvvvvvv",
      "ebbbbbbbbbbbbbfv",
      "ef  jkkkkkl  ffv",
      "em  jkkkkkl   cv",
      "ef  jkkkkkl  ffv",
      "ef  jkkkkkl  ffv",
      "ei   n o     ifv",
      "bf     p     ffv",
      "bf           ffv",
      "bm            cv",
      "bf    qqq    ffv",
      "bbbr  qqq srbbfv",
      "bft   qqq   uffv",
      "bm          w xv",
      "bfy         Affv",
      "bfy         Affv"
    ],
    [
      "vvvvvvvvvvvvvvvv",
      "bbbbbb   bbbbbfv",
      "ef  jB C Bl  ffv",
      "bm  jB D Bl   cv",
      "bf  jB D Bl  ffv",
      "bf  jB E Bl  ffv",
      "bi   F I J   ifv",
      "bf     C     ffv",
      "bf           ffv",
      "bm            cv",
      "bf           ffv",
      "bbbK      LKbbfv",
      "bf           ffv",
      "bm            cv",
      "bfM         Nffv",
      "bfM         Offv"
    ]
  ]
}