{
  "name": "multi_hospital_4_base1",
  "refpalette": "deceasedcraft:multi_hospital_4/multi_hospital_4_base1_palette",
  "xsize": 16,
  "zsize": 16,
  "slices": [
    [
      "vvvvvvvvvvvvvvvv",
      "aaaaaa   aaaaabv",
      "cb  de   ef  bbv",
      "cg  de   ef   hv",
      "cb  de   ef  bbv",
      "cb  de   ef  bbv",
      "ci           ibv",
      "cb           bbv",
      "cb           bbv",
      "cg            jv",
      "cb           bbv",
      "caak       kaabv",
      "cb           bbv",
      "cg            jv",
      "cb           bbv",
      "cb           bbv"
    ],
    [
      "vvvvvvvvvvvvvvvv",
      "aaaaaaaaaaaaaabv",
      "lb   meeem   bbv",
      " n   meeem    jv",
      " b   meeem   bbv",
      "ob   meeem   bbv",
      "ai           ibv",
      "pb           bbv",
      " b           bbv",
      " n            jv",
      "lb    qqq    bbv",
      "aaakr qqq  kaabv",
      "lb    qqq    bbv",
      " n            jv",
      " b           bbv",
      "ob           bbv"
    ],
    [
      "vvvvvvvvvvvvvvvv",
      "aaaaaaaaaaaaaabv",
      " b           bbv",
      " n            jv",
      " b           bbv",
      "sb           bbv",
      "ai           ibv",
      "tb           bbv",
      " b           bbv",
      " n            jv",
      " b     u     bbv",
      "aaawx yAB  waabv",
      " b     C     bbv",
      " n            jv",
      " b           bbv",
      "Db           bbv"
    ],
    [
      "vvvvvvvvvvvvvvvv",
      "aaaaaaaaaaaaaabv",
      "Eb           bbv",
      " n            hv",
      " b           bbv",
      " b           bbv",
      "ai           ibv",
      " b           bbv",
      " b           bbv",
      " n            jv",
      "Eb           bbv",
      "aaaaaaaaaaaaaabv",
      "Eb           bbv",
      " n            jv",
      " b           bbv",
      " b           bbv"
    ],
    [
      "vvvvvvvvvvvvvvvv",
      "aaaaaaaaaaaaaabv",
      "ebeeeeeeeeeeebbv",
      "eeeeeeeeeeeeeebv",
      "ebeeeeeeeeeeebbv",
      "ebeeeeeeeeeeebbv",
      "aieeeeeeeeeeeibv",
      "ebeeeeeeeeeeebbv",
      "ebeeeeeeeeeeebbv",
      "eeeeeeeeeeeeeebv",
      "ebeeeeeeeeeeebbv",
      "aaaaaaaaaaaaaabv",
      "ebeeeeeeeeeeebbv",
      "eeeeeeeeeeeeeebv",
      "ebeeeeeeeeeeebbv",
      "ebeeeeeeeeeeebbv"
    ],
    [
      "vvvvvvvvvvvvvvvv",
      "aaaaaaaaaaaaaabv",
      "FbFFFFFFFFFFFbbv",
      "FbFFFFFFFFFFFbbv",
      "FbFFFFFFFFFFFbbv",
      "FbFFFFFFFFFFFbbv",
      "aiFFFFFFFFFFFibv",
      "FbFFFFFFFFFFFbbv",
      "FbFFFFFFFFFFFbbv",
      "FbFFFFFFFFFFFbbv",
      "FbFFFFFFFFFFFbbv",
      "aaaaaaaaaaaaaabv",
      "FIIIIIIIIIIIIbbv",
      "FFFFFFFFFFFFFbbv",
      "FFFFFFFFFFFFFbbv",
      "FFFFFFFFFFFFFbbv"
    ]
  ]
}