{
  "name": "multi_hospital_4_base3",
  "refpalette": "deceasedcraft:multi_hospital_4/multi_hospital_4_base3_palette",
  "xsize": 16,
  "zsize": 16,
  "slices": [
    [
      "vvvvvvvvvvvvvvvv",
      "aaaaaaaaaaaaaaav",
      "aaaaaaaaaaaaaaav",
      "bbbaaaaaaaaaaaav",
      "b baaaaaaaaaaaav",
      "b baaaaaaaaaaaav",
      "b baaaaaaaaaaaav",
      "c baaaaaaaaaaaav",
      "c baaaaaaaaaaaav",
      "c baaaaaaaaaaaav",
      "c baaaaaaaaaaaav",
      "c baaaaaaaaaaaav",
      "cdbaaaaaaaaaaaav",
      "cebaaaaaaaaaaaav",
      "cfbaaaaaaaaaaaav",
      "cebaaaaaaaaaaaav"
    ],
    [
      "vvvvvvvvvvvvvvvv",
      "aaaaaaaaaaaaaaav",
      "aaaaaaaaaaaaaaav",
      "bbbaaaaaaaaaaaav",
      "bbbaaaaaaaaaaaav",
      "bbbaaaaaaaaaaaav",
      "bbbaaaaaaaaaaaav",
      "cbbaaaaaaaaaaaav",
      "cbbaaaaaaaaaaaav",
      "cbbaaaaaaaaaaaav",
      "cbbaaaaaaaaaaaav",
      "cbbaaaaaaaaaaaav",
      "cbbaaaaaaaaaaaav",
      "cebaaaaaaaaaaaav",
      "e baaaaaaaaaaaav",
      "cebaaaaaaaaaaaav"
    ],
    [
      "vvvvvvvvvvvvvvvv",
      "aaaaaaaaaaaaaaav",
      "aaaaaaaaaaaaaaav",
      "bbbaaaaaaaaaaaav",
      "bbbaaaaaaaaaaaav",
      "bbbaaaaaaaaaaaav",
      "bbbaaaaaaaaaaaav",
      "cbbaaaaaaaaaaaav",
      "cbbaaaaaaaaaaaav",
      "cbbaaaaaaaaaaaav",
      "cbbaaaaaaaaaaaav",
      "cbbaaaaaaaaaaaav",
      "cbbaaaaaaaaaaaav",
      "cebaaaaaaaaaaaav",
      "g baaaaaaaaaaaav",
      "cebaaaaaaaaaaaav"
    ],
    [
      "vvvvvvvvvvvvvvvv",
      "aaaaaaaaaaaaaaav",
      "aaaaaaaaaaaaaaav",
      "aaaaaaaaaaaaaaav",
      "aaaaaaaaaaaaaaav",
      "aaaaaaaaaaaaaaav",
      "aaaaaaaaaaaaaaav",
      "caaaaaaaaaaaaaav",
      "caaaaaaaaaaaaaav",
      "caaaaaaaaaaaaaav",
      "caaaaaaaaaaaaaav",
      "cbbaaaaaaaaaaaav",
      "cbbaaaaaaaaaaaav",
      "cebaaaaaaaaaaaav",
      "cebaaaaaaaaaaaav",
      "cebaaaaaaaaaaaav"
    ],
    [
      "vvvvvvvvvvvvvvvv",
      "aaaaaaaaaaaaaaav",
      "aaaaaaaaaaaaaaav",
      "aaaaaaaaaaaaaaav",
      "aaaaaaaaaaaaaaav",
      "aaaaaaaaaaaaaaav",
      "aaaaaaaaaaaaaaav",
      "caaaaaaaaaaaaaav",
      "caaaaaaaaaaaaaav",
      "caaaaaaaaaaaaaav",
      "caaaaaaaaaaaaaav",
      "hbbaaaaaaaaaaaav",
      "hbbaaaaaaaaaaaav",
      "hbbaaaaaaaaaaaav",
      "hbbaaaaaaaaaaaav",
      "hbbaaaaaaaaaaaav"
    ],
    [
      "vvvvvvvvvvvvvvvv",
      "aaaaaaaaaaaaaaav",
      "aaaaaaaaaaaaaaav",
      "aaaaaaaaaaaaaaav",
      "aaaaaaaaaaaaaaav",
      "aaaaaaaaaaaaaaav",
      "aaaaaaaaaaaaaaav",
      "caaaaaaaaaaaaaav",
      "caaaaaaaaaaaaaav",
      "caaaaaaaaaaaaaav",
      "caaaaaaaaaaaaaav",
      "hbbaaaaaaaaaaaav",
      "hbbaaaaaaaaaaaav",
      "hbbaaaaaaaaaaaav",
      "hbbaaaaaaaaaaaav",
      "hbbaaaaaaaaaaaav"
    ]
  ]
}