{
  "name": "multi_nuclearpowerplant_8_base2",
  "refpalette": "deceasedcraft:multi_nuclearpowerplant_8/multi_nuclearpowerplant_8_base2_palette",
  "xsize": 16,
  "zsize": 16,
  "slices": [
    [
      "     a          ",
      "    a           ",
      "   a            ",
      "  a             ",
      " a              ",
      "a               ",
      "                ",
      "                ",
      "                ",
      "                ",
      "                ",
      "                ",
      "                ",
      "                ",
      "                ",
      "                "
    ],
    [
      "     a          ",
      "    a           ",
      "   a            ",
      "  a             ",
      " a              ",
      "a               ",
      "                ",
      "                ",
      "                ",
      "                ",
      "                ",
      "                ",
      "                ",
      "                ",
      "                ",
      "                "
    ],
    [
      "     a          ",
      "    a           ",
      "   a            ",
      "  a             ",
      " a              ",
      "a               ",
      "                ",
      "                ",
      "                ",
      "                ",
      "                ",
      "                ",
      "                ",
      "                ",
      "                ",
      "                "
    ],
    [
      "     a          ",
      "    a           ",
      "   a            ",
      "  a             ",
      " a              ",
      "a               ",
      "                ",
      "                ",
      "                ",
      "                ",
      "                ",
      "                ",
      "                ",
      "                ",
      "                ",
      "                "
    ],
    [
      "     a          ",
      "    a           ",
      "   a            ",
      "  a             ",
      " a              ",
      "a               ",
      "                ",
      "                ",
      "                ",
      "                ",
      "                ",
      "                ",
      "                ",
      "                ",
      "                ",
      "                "
    ],
    [
      "     abbbbbbbbbb",
      "    abbbbbbbbbbb",
      "   abbbbbbbbbbbb",
      "  abbbbbbbbbbbbb",
      " abbbbbbbbbbbbbb",
      "abbbbbbbbbbbbbbb",
      "bbbbbbbbbbbbbbb ",
      "bbbbbbbbbbbbbb  ",
      "bbbbbbbbbbbb    ",
      "bbbbbbbbbbb     ",
      "bbbbbbbbbb      ",
      "bbbbbbbbb       ",
      "bbbbbbbbb       ",
      "bbbbbbbb        ",
      "bbbbbbb         ",
      "bbbbbb          "
    ]
  ]
}