{
  "name": "multi_nuclearpowerplant_8_base8",
  "refpalette": "deceasedcraft:multi_nuclearpowerplant_8/multi_nuclearpowerplant_8_base8_palette",
  "xsize": 16,
  "zsize": 16,
  "slices": [
    [
      "aaaaabbbbbbbbbbb",
      "aaaabbbbbbbbbbbb",
      "aaabbbbbbbbbbbbb",
      "aabbbbbbbbbbbbbb",
      "abbbbbbbbbbbbbbb",
      "bbbbbbbbbbbbbbbb",
      "cccccccccccccccc",
      "dddddddddddddddd",
      "dddddddddddddddd",
      "dddddddddddddddd",
      "dddddddddddddddd",
      "dddddddddddddddd",
      "dddddddddddddddd",
      "dddddddddddddddd",
      "dddddddddddddddd",
      "dddddddddddddddd"
    ],
    [
      "aaaaaeffe=======",
      "aaaaefffe=======",
      "aaaefffe========",
      "aaeffffe========",
      "aeffffe=========",
      "efffffe=========",
      "fffffe==========",
      "fffffe==========",
      "fffffe==========",
      "ffffe===========",
      "ffffe===========",
      "ffffe===========",
      "fffe============",
      "fffe============",
      "fffe============",
      "fffe============"
    ],
    [
      "aaaaaghhgaaaaaaa",
      "aaaaghhhgaaaaaaa",
      "aaaghhhgaaaaaaaa",
      "aaghhhhgaaaaaaaa",
      "aghhhhgaaaaaaaaa",
      "ghhhhhgaaaaaaaaa",
      "hhhhhgaaaaaaaaaa",
      "hhhhhgaaaaaaaaaa",
      "hhhhhgaaaaaaaaaa",
      "hhhhgaaaaaaaaaaa",
      "hhhhgaaaaaaaaaaa",
      "hhhhgaaaaaaaaaaa",
      "hhhgaaaaaaaaaaaa",
      "hhhgaaaaaaaaaaaa",
      "hhhgaaaaaaaaaaaa",
      "hhhgaaaaaaaaaaaa"
    ],
    [
      "aaaaaghhgaaaaaaa",
      "aaaaghhhgaaaaaaa",
      "aaaghhhgaaaaaaaa",
      "aaghhhhgaaaaaaaa",
      "aghhhhgaaaaaaaaa",
      "ghhhhhgaaaaaaaaa",
      "hhhhhgaaaaaaaaaa",
      "hhhhhgaaaaaaaaaa",
      "hhhhhgaaaaaaaaaa",
      "hhhhgaaaaaaaaaaa",
      "hhhhgaaaaaaaaaaa",
      "hhhhgaaaaaaaaaaa",
      "hhhgaaaaaaaaaaaa",
      "hhhgaaaaaaaaaaaa",
      "hhhgaaaaaaaaaaaa",
      "hhhgaaaaaaaaaaaa"
    ],
    [
      "aaaaaghhgeeeeeee",
      "aaaaghhhgeeeeeee",
      "aaaghhhgeeeeeeee",
      "aaghhhhgeeeeeeee",
      "aghhhhgeeeeeeeee",
      "ghhhhhgeeeeeeeee",
      "hhhhhgeeeeeeeeee",
      "hhhhhgeeeeeeeeee",
      "hhhhhgeeeeeeeeee",
      "hhhhgeeeeeeeeeee",
      "hhhhgeeeeeeeeeee",
      "hhhhgeeeeeeeeeee",
      "hhhgeeeeeeeeeeee",
      "hhhgeeeeeeeeeeee",
      "hhhgeeeeeeeeeeee",
      "hhhgeeeeeeeeeeee"
    ],
    [
      "aaaaaghhg       ",
      "aaaaghhhg       ",
      "aaaghhhg        ",
      "aaghhhhg        ",
      "aghhhhg         ",
      "ghhhhhg         ",
      "hhhhhg          ",
      "hhhhhg          ",
      "hhhhhg          ",
      "hhhhg           ",
      "hhhhg           ",
      "hhhhg           ",
      "hhhg            ",
      "hhhg            ",
      "hhhg            ",
      "hhhg            "
    ]
  ]
}