{
  "name": "multi_nuclearpowerplant_8_ground",
  "refpalette": "deceasedcraft:multi_nuclearpowerplant_8/multi_nuclearpowerplant_8_ground_palette",
  "xsize": 16,
  "zsize": 16,
  "slices": [
    [
      "azaaaabbcccc    ",
      "aaaaabbcccc     ",
      "aaaabbccc       ",
      "aaabbccc        ",
      "aabbccc         ",
      "abbccc          ",
      "bbccc           ",
      "bccc            ",
      "ccc             ",
      "cc              ",
      "c               ",
      "                ",
      "                ",
      "                ",
      "                ",
      "                "
    ],
    [
      "     dzazccccccc",
      "    dazzcccccccc",
      "   dzzzccccccc  ",
      "  dzzzcccccc    ",
      " eaazccccc      ",
      "ezzzcccc        ",
      "zzzcccc         ",
      "zzcccc          ",
      "zcccc           ",
      "cccc            ",
      "ccc             ",
      "cc              ",
      "cc              ",
      "c               ",
      "                ",
      "                "
    ],
    [
      "      ff azzzzzz",
      "     ff zzzzzccc",
      "    ff zzzzccccc",
      "   ff azzccccccc",
      "  ffgzzccccccccc",
      " ff zzccccccccc ",
      "ff zzccccccc    ",
      "f zzcccccc      ",
      " azccccc        ",
      "zzccccc         ",
      "zccccc          ",
      "zcccc           ",
      "cccc            ",
      "ccc             ",
      "cc              ",
      "c               "
    ],
    [
      "      ff     z g",
      "     ff    gazzz",
      "    ff   g zzzzz",
      "   ff   gzzzzzzz",
      "  ff   zzzzzzzcc",
      " ff   zzzazccccc",
      "ff  zzzzzccccccc",
      "f   zzzccccccccc",
      "   zzzccccccccc ",
      "  zzzcccccccc   ",
      " zzzccccccc     ",
      " zzcccccc       ",
      "zzcccccc        ",
      "zcccccc         ",
      "ccccc           ",
      "cccc            "
    ],
    [
      "      h         ",
      "     h        g ",
      "    h      gg   ",
      "   i        j   ",
      "  k        l  zz",
      " k      g  zzzzz",
      "k      gaazzzazz",
      "     ggzzzzzzzcc",
      "      zzzzzzcccc",
      "     zzzzzcccccc",
      "   zzzzzcccccccc",
      "  azzzzccccccccc",
      "  zzzzcccccccc  ",
      "gzzzcccccccc    ",
      "zzzccccccc      ",
      "zzcccccc        "
    ],
    [
      "                ",
      "                ",
      "                ",
      "                ",
      "               g",
      "                ",
      "              gj",
      "              zz",
      "       g  glzzzz",
      "     g z zzzzzzz",
      "    j  zazzzzzzz",
      "     gzzzzzzzccc",
      "  gg zzzzzzccccc",
      " gj zzzzzccccccc",
      "  zzzzzccccccccc",
      " azzzccccccccc  "
    ]
  ]
}