{
  "name": "multi_nuclearpowerplant_8_base7",
  "refpalette": "deceasedcraft:multi_nuclearpowerplant_8/multi_nuclearpowerplant_8_base7_palette",
  "xsize": 16,
  "zsize": 16,
  "slices": [
    [
      "aaaaabccb       ",
      "aaaabcccb       ",
      "aaabcccb        ",
      "aabccccb        ",
      "abccccb         ",
      "bcccccb         ",
      "cccccb          ",
      "cccccb          ",
      "cccccb          ",
      "ccccb           ",
      "ccccb           ",
      "ccccb           ",
      "cccb            ",
      "cccb            ",
      "cccb            ",
      "cccb            "
    ],
    [
      "aaaaabccb       ",
      "aaaabcccb       ",
      "aaabcccb        ",
      "aabccccb        ",
      "abccccb         ",
      "bcccccb         ",
      "cccccb          ",
      "cccccb          ",
      "cccccb          ",
      "ccccb           ",
      "ccccb           ",
      "ccccb           ",
      "cccb            ",
      "cccb            ",
      "cccb            ",
      "cccb            "
    ],
    [
      "aaaaabccb       ",
      "aaaabcccb       ",
      "aaabcccb        ",
      "aabccccb        ",
      "abccccb         ",
      "bcccccb         ",
      "cccccb          ",
      "cccccb          ",
      "cccccb          ",
      "ccccb           ",
      "ccccb           ",
      "ccccb           ",
      "cccb            ",
      "cccb            ",
      "cccb            ",
      "cccb            "
    ],
    [
      "aaaaabccb       ",
      "aaaabcccb       ",
      "aaabcccb        ",
      "aabccccb        ",
      "abccccb         ",
      "bcccccb         ",
      "cccccb          ",
      "cccccb          ",
      "cccccb          ",
      "ccccb           ",
      "ccccb           ",
      "ccccb           ",
      "cccb            ",
      "cccb            ",
      "cccb            ",
      "cccb            "
    ],
    [
      "aaaaabccb       ",
      "aaaabcccb       ",
      "aaabcccb        ",
      "aabccccb        ",
      "abccccb         ",
      "bcccccb         ",
      "cccccb          ",
      "cccccb          ",
      "cccccb          ",
      "ccccb           ",
      "ccccb           ",
      "ccccb           ",
      "cccb            ",
      "cccb            ",
      "cccb            ",
      "cccb            "
    ],
    [
      "dddddbccbeeeeeee",
      "ddddbcccbeeeeeee",
      "dddbcccbeeeeeeee",
      "ddbccccbeeeeeeee",
      "dbccccbeeeeeeeee",
      "bcccccbeeeeeeeee",
      "cccccbeeeeeeeeee",
      "cccccbeeeeeeeeee",
      "cccccbeeeeeeeeee",
      "ccccbeeeeeeeeeee",
      "ccccbeeeeeeeeeee",
      "ccccbeeeeeeeeeee",
      "cccbeeeeeeeeeeee",
      "cccbeeeeeeeeeeee",
      "cccbeeeeeeeeeeee",
      "cccbeeeeeeeeeeee"
    ]
  ]
}