{
  "name": "multi_nuclearpowerplant_8_base1",
  "refpalette": "deceasedcraft:multi_nuclearpowerplant_8/multi_nuclearpowerplant_8_base1_palette",
  "xsize": 16,
  "zsize": 16,
  "slices": [
    [
      "aaaaabzccccccccc",
      "aaaabzcccccccccc",
      "aaabzccccccccccc",
      "aabzcccccccccccc",
      "abzccccccccccccc",
      "bzcccccccccccccc",
      "zccccccccccccccd",
      "ccccccccccccccdd",
      "ccccccccccccddd ",
      "cccccccccccdd   ",
      "ccccccccccdd    ",
      "cccccccccdd     ",
      "cccccccccd      ",
      "ccccccccdd      ",
      "cccccccdd       ",
      "ccccccdd        "
    ],
    [
      "eeeeefg         ",
      "eeeefg          ",
      "eeefg           ",
      "eefg            ",
      "efg             ",
      "fg              ",
      "g              h",
      "              hh",
      "            hhh ",
      "           hh   ",
      "          hh    ",
      "         hh     ",
      "         h      ",
      "        hh      ",
      "       hh       ",
      "      hh        "
    ],
    [
      "eeeeef          ",
      "eeeef           ",
      "eeef            ",
      "eef             ",
      "ef              ",
      "f               ",
      "                ",
      "                ",
      "                ",
      "                ",
      "                ",
      "                ",
      "                ",
      "                ",
      "                ",
      "                "
    ],
    [
      "eeeeef          ",
      "eeeef           ",
      "eeef            ",
      "eef             ",
      "ef              ",
      "f               ",
      "                ",
      "                ",
      "                ",
      "                ",
      "                ",
      "                ",
      "                ",
      "                ",
      "                ",
      "                "
    ],
    [
      "eeeeef          ",
      "eeeef           ",
      "eeef            ",
      "eefi            ",
      "ef              ",
      "f               ",
      "                ",
      "                ",
      "                ",
      "                ",
      "                ",
      "                ",
      "                ",
      "                ",
      "                ",
      "                "
    ],
    [
      "eeeeefdd        ",
      "eeeefdd         ",
      "eeefdd          ",
      "eefdd           ",
      "efdd            ",
      "fdd             ",
      "dd              ",
      "d               ",
      "                ",
      "                ",
      "                ",
      "                ",
      "                ",
      "                ",
      "                ",
      "                "
    ]
  ]
}