{
  "name": "multi_nuclearpowerplant_8_base6",
  "refpalette": "deceasedcraft:multi_nuclearpowerplant_8/multi_nuclearpowerplant_8_base6_palette",
  "xsize": 16,
  "zsize": 16,
  "slices": [
    [
      "vvvvvabcaadddddd",
      "vvvvaec addddddd",
      "vvvabc aaddddddd",
      "vvaec  adddddddd",
      "vabc  aadddddddd",
      "aec   addddddddd",
      "bc   aaddddddddd",
      "c    adddddddddd",
      "     adddddddddd",
      "    aadddddddddd",
      "    addddddddddd",
      "    addddddddddd",
      "   aaddddddddddd",
      "   adddddddddddd",
      "   adddddddddddd",
      "   adddddddddddd"
    ],
    [
      "fffffg  hh      ",
      "ffffg   h       ",
      "fffg   hh       ",
      "ffg    h        ",
      "fg    hh        ",
      "g     h         ",
      "     hh         ",
      "     h          ",
      "     h          ",
      "    hh          ",
      "    h           ",
      "    h           ",
      "   hh           ",
      "   hi           ",
      "   hj           ",
      "   hk           "
    ],
    [
      "eeeeeg          ",
      "eeeeg           ",
      "eeeg            ",
      "eeg             ",
      "eg              ",
      "g               ",
      "                ",
      "                ",
      "                ",
      "                ",
      "                ",
      "                ",
      "                ",
      "                ",
      "                ",
      "                "
    ],
    [
      "eeeeeg          ",
      "eeeeg           ",
      "eeeg            ",
      "eeg             ",
      "eg              ",
      "g               ",
      "                ",
      "                ",
      "                ",
      "                ",
      "                ",
      "                ",
      "                ",
      "                ",
      "                ",
      "                "
    ],
    [
      "eeeeeg          ",
      "eeeeg           ",
      "eeeg            ",
      "eeg             ",
      "eg              ",
      "g               ",
      "                ",
      "                ",
      "                ",
      "                ",
      "                ",
      "                ",
      "                ",
      "                ",
      "                ",
      "                "
    ],
    [
      "eeeeeg          ",
      "eeeeg           ",
      "eeeg            ",
      "eeg             ",
      "eg              ",
      "g               ",
      "                ",
      "                ",
      "                ",
      "                ",
      "                ",
      "                ",
      "                ",
      "                ",
      "                ",
      "                "
    ]
  ]
}