{
  "name": "multi_nuclearpowerplant_48_base12",
  "refpalette": "deceasedcraft:multi_nuclearpowerplant_48/multi_nuclearpowerplant_48_base12_palette",
  "xsize": 16,
  "zsize": 16,
  "slices": [
    [
      "aaaaaaaaaaaaaaav",
      "aaaaaaaaaaaaaaav",
      "aaaaaaaaaaaaaaav",
      "aaaaaaaaaaaaaaav",
      "aaaaaaaaaaaaaaav",
      "aaaaaaaaaaaaaaav",
      "aaaaaaaaaaaaaaav",
      "aaaaaaaaaaaaaaav",
      "aaaaaaaaaaaaaaav",
      "aaaaaaaaaaaaaaav",
      "aaaaaaaaaaaaaaav",
      "aaaaaaaaaaaaaaav",
      "aaaaaaaaaaaaaaav",
      "aaaaaaaaaaaaaaav",
      "aaaaaaaaaaaaaaav",
      "vvvvvvvvvvvvvvvv"
    ],
    [
      "bbbbbbbbbbbbaaav",
      "bbbbbbbbbbbbaaav",
      "bbbbbbbbbbbbaaav",
      "bbbbbbbbbbbaaaav",
      "bbbbbbbbbbbaaaav",
      "bbbbbbbbbbaaaaav",
      "bbbbbbbbbaaaaaav",
      "bbbbbbbbaaaaaaav",
      "bbbbbbbaaaaaaaav",
      "bbbbbbaaaaaaaaav",
      "bbbbbaaaaaaaaaav",
      "bbbaaaaaaaaaaaav",
      "aaaaaaaaaaaaaaav",
      "aaaaaaaaaaaaaaav",
      "aaaaaaaaaaaaaaav",
      "vvvvvvvvvvvvvvvv"
    ],
    [
      "===========caaav",
      "===========caaav",
      "===========caaav",
      "==========caaaav",
      "==========caaaav",
      "=========caaaaav",
      "========caaaaaav",
      "=======caaaaaaav",
      "======caaaaaaaav",
      "=====caaaaaaaaav",
      "===ccaaaaaaaaaav",
      "cccaaaaaaaaaaaav",
      "aaaaaaaaaaaaaaav",
      "aaaaaaaaaaaaaaav",
      "aaaaaaaaaaaaaaav",
      "vvvvvvvvvvvvvvvv"
    ],
    [
      "db=========eaaav",
      "bb=========eaaav",
      "===========eaaav",
      "==========eaaaav",
      "==========eaaaav",
      "=========eaaaaav",
      "========eaaaaaav",
      "=======eaaaaaaav",
      "======eaaaaaaaav",
      "=====eaaaaaaaaav",
      "===eeaaaaaaaaaav",
      "eeeaaaaaaaaaaaav",
      "aaaaaaaaaaaaaaav",
      "aaaaaaaaaaaaaaav",
      "aaaaaaaaaaaaaaav",
      "vvvvvvvvvvvvvvvv"
    ],
    [
      "fb=========eaaav",
      "bb=========eaaav",
      "===========eaaav",
      "==========eaaaav",
      "==========eaaaav",
      "=========eaaaaav",
      "========eaaaaaav",
      "=======eaaaaaaav",
      "======eaaaaaaaav",
      "=====eaaaaaaaaav",
      "===eeaaaaaaaaaav",
      "eeeaaaaaaaaaaaav",
      "aaaaaaaaaaaaaaav",
      "aaaaaaaaaaaaaaav",
      "aaaaaaaaaaaaaaav",
      "vvvvvvvvvvvvvvvv"
    ],
    [
      "fb=========eaaav",
      "bb=========eaaav",
      "===========eaaav",
      "==========eaaaav",
      "==========eaaaav",
      "=========eaaaaav",
      "========eaaaaaav",
      "=======eaaaaaaav",
      "======eaaaaaaaav",
      "=====eaaaaaaaaav",
      "===eeaaaaaaaaaav",
      "eeeaaaaaaaaaaaav",
      "aaaaaaaaaaaaaaav",
      "aaaaaaaaaaaaaaav",
      "aaaaaaaaaaaaaaav",
      "vvvvvvvvvvvvvvvv"
    ]
  ]
}