{
  "name": "multi_nuclearpowerplant_48_base4",
  "refpalette": "deceasedcraft:multi_nuclearpowerplant_48/multi_nuclearpowerplant_48_base4_palette",
  "xsize": 16,
  "zsize": 16,
  "slices": [
    [
      "abbbc    d=efffv",
      "bbbcc    d=efffv",
      "bbcc     d=efffv",
      "bcc     d=effffv",
      "cc      d=effffv",
      "       d=efffffv",
      "      d=effffffv",
      "     d=efffffffv",
      "   dd=effffffffv",
      "ddd==efffffffffv",
      "===eeffffffffffv",
      "eeeffffffffffffv",
      "fffffffffffffffv",
      "fffffffffffffffv",
      "fffffffffffffffv",
      "vvvvvvvvvvvvvvvv"
    ],
    [
      "abbbc    d=efffv",
      "bbbcc    d=efffv",
      "bbcc     d=efffv",
      "bcc     d=effffv",
      "cc      d=effffv",
      "       d=efffffv",
      "      d=effffffv",
      "     d=efffffffv",
      "   dd=effffffffv",
      "ddd==efffffffffv",
      "===eeffffffffffv",
      "eeeffffffffffffv",
      "fffffffffffffffv",
      "fffffffffffffffv",
      "fffffffffffffffv",
      "vvvvvvvvvvvvvvvv"
    ],
    [
      "bbbbc    d=efffv",
      "bbbcc    d=efffv",
      "bbcc     d=efffv",
      "bcc     d=effffv",
      "cc      d=effffv",
      "       d=efffffv",
      "      d=effffffv",
      "     d=efffffffv",
      "   dd=effffffffv",
      "ddd==efffffffffv",
      "===eeffffffffffv",
      "eeeffffffffffffv",
      "fffffffffffffffv",
      "fffffffffffffffv",
      "fffffffffffffffv",
      "vvvvvvvvvvvvvvvv"
    ],
    [
      "bbbbc    d=efffv",
      "bbbcc    d=efffv",
      "bbcc     d=efffv",
      "bcc     d=effffv",
      "cc      d=effffv",
      "       d=efffffv",
      "      d=effffffv",
      "     d=efffffffv",
      "   dd=effffffffv",
      "ddd==efffffffffv",
      "===eeffffffffffv",
      "eeeffffffffffffv",
      "fffffffffffffffv",
      "fffffffffffffffv",
      "fffffffffffffffv",
      "vvvvvvvvvvvvvvvv"
    ],
    [
      "    c    d=efffv",
      "   cc    d=efffv",
      "  cc     d=efffv",
      " cc     d=effffv",
      "cc      d=effffv",
      "       d=efffffv",
      "      d=effffffv",
      "     d=efffffffv",
      "   dd=effffffffv",
      "ddd==efffffffffv",
      "===eeffffffffffv",
      "eeeffffffffffffv",
      "fffffffffffffffv",
      "fffffffffffffffv",
      "fffffffffffffffv",
      "vvvvvvvvvvvvvvvv"
    ],
    [
      "    g    d=efffv",
      "   gg    d=efffv",
      "  gg     d=efffv",
      " gg     d=effffv",
      "gg      d=effffv",
      "       d=efffffv",
      "      d=effffffv",
      "     d=efffffffv",
      "   dd=effffffffv",
      "ddd==efffffffffv",
      "===eeffffffffffv",
      "eeeffffffffffffv",
      "fffffffffffffffv",
      "fffffffffffffffv",
      "fffffffffffffffv",
      "vvvvvvvvvvvvvvvv"
    ]
  ]
}