{
  "name": "multi_nuclearpowerplant_48_base11",
  "refpalette": "deceasedcraft:multi_nuclearpowerplant_48/multi_nuclearpowerplant_48_base11_palette",
  "xsize": 16,
  "zsize": 16,
  "slices": [
    [
      "ab=========cdddv",
      "bb=========cdddv",
      "===========cdddv",
      "==========cddddv",
      "==========cddddv",
      "=========cdddddv",
      "========cddddddv",
      "=======cdddddddv",
      "======cddddddddv",
      "=====cdddddddddv",
      "===ccddddddddddv",
      "cccddddddddddddv",
      "dddddddddddddddv",
      "dddddddddddddddv",
      "dddddddddddddddv",
      "vvvvvvvvvvvvvvvv"
    ],
    [
      "ab=========cdddv",
      "bb=========cdddv",
      "===========cdddv",
      "==========cddddv",
      "==========cddddv",
      "=========cdddddv",
      "========cddddddv",
      "=======cdddddddv",
      "======cddddddddv",
      "=====cdddddddddv",
      "===ccddddddddddv",
      "cccddddddddddddv",
      "dddddddddddddddv",
      "dddddddddddddddv",
      "dddddddddddddddv",
      "vvvvvvvvvvvvvvvv"
    ],
    [
      "ab=========cdddv",
      "bb=========cdddv",
      "===========cdddv",
      "==========cddddv",
      "==========cddddv",
      "=========cdddddv",
      "========cddddddv",
      "=======cdddddddv",
      "======cddddddddv",
      "=====cdddddddddv",
      "===ccddddddddddv",
      "cccddddddddddddv",
      "dddddddddddddddv",
      "dddddddddddddddv",
      "dddddddddddddddv",
      "vvvvvvvvvvvvvvvv"
    ],
    [
      "ab=========cdddv",
      "bb=========cdddv",
      "===========cdddv",
      "==========cddddv",
      "==========cddddv",
      "=========cdddddv",
      "========cddddddv",
      "=======cdddddddv",
      "======cddddddddv",
      "=====cdddddddddv",
      "===ccddddddddddv",
      "cccddddddddddddv",
      "dddddddddddddddv",
      "dddddddddddddddv",
      "dddddddddddddddv",
      "vvvvvvvvvvvvvvvv"
    ],
    [
      "ab=========cdddv",
      "bb=========cdddv",
      "===========cdddv",
      "==========cddddv",
      "==========cddddv",
      "=========cdddddv",
      "========cddddddv",
      "=======cdddddddv",
      "======cddddddddv",
      "=====cdddddddddv",
      "===ccddddddddddv",
      "cccddddddddddddv",
      "dddddddddddddddv",
      "dddddddddddddddv",
      "dddddddddddddddv",
      "vvvvvvvvvvvvvvvv"
    ],
    [
      "ab=========cdddv",
      "bb=========cdddv",
      "===========cdddv",
      "==========cddddv",
      "==========cddddv",
      "=========cdddddv",
      "========cddddddv",
      "=======cdddddddv",
      "======cddddddddv",
      "=====cdddddddddv",
      "===ccddddddddddv",
      "cccddddddddddddv",
      "dddddddddddddddv",
      "dddddddddddddddv",
      "dddddddddddddddv",
      "vvvvvvvvvvvvvvvv"
    ]
  ]
}