{
  "name": "multi_nuclearpowerplant_48_base9",
  "refpalette": "deceasedcraft:multi_nuclearpowerplant_48/multi_nuclearpowerplant_48_base9_palette",
  "xsize": 16,
  "zsize": 16,
  "slices": [
    [
      "           abbbv",
      "           abbbv",
      "           abbbv",
      "          abbbbv",
      "          abbbbv",
      "         abbbbbv",
      "        abbbbbbv",
      "      cabbbbbbbv",
      "      abbbbbbbbv",
      "     abbbbbbbbbv",
      "   aabbbbbbbbbbv",
      "aaabbbbbbbbbbbbv",
      "bbbbbbbbbbbbbbbv",
      "bbbbbbbbbbbbbbbv",
      "bbbbbbbbbbbbbbbv",
      "vvvvvvvvvvvvvvvv"
    ],
    [
      "           abbbv",
      "           abbbv",
      "           abbbv",
      "          abbbbv",
      "          abbbbv",
      "         abbbbbv",
      "        abbbbbbv",
      "      cabbbbbbbv",
      "      abbbbbbbbv",
      "     abbbbbbbbbv",
      "   aabbbbbbbbbbv",
      "aaabbbbbbbbbbbbv",
      "bbbbbbbbbbbbbbbv",
      "bbbbbbbbbbbbbbbv",
      "bbbbbbbbbbbbbbbv",
      "vvvvvvvvvvvvvvvv"
    ],
    [
      "           abbbv",
      "           abbbv",
      "           abbbv",
      "          abbbbv",
      "          abbbbv",
      "         abbbbbv",
      "        abbbbbbv",
      "      cabbbbbbbv",
      "      abbbbbbbbv",
      "     abbbbbbbbbv",
      "   aabbbbbbbbbbv",
      "aaabbbbbbbbbbbbv",
      "bbbbbbbbbbbbbbbv",
      "bbbbbbbbbbbbbbbv",
      "bbbbbbbbbbbbbbbv",
      "vvvvvvvvvvvvvvvv"
    ],
    [
      "           abbbv",
      "           abbbv",
      "           abbbv",
      "          abbbbv",
      "          abbbbv",
      "         abbbbbv",
      "        abbbbbbv",
      "      cabbbbbbbv",
      "      abbbbbbbbv",
      "     abbbbbbbbbv",
      "   aabbbbbbbbbbv",
      "aaabbbbbbbbbbbbv",
      "bbbbbbbbbbbbbbbv",
      "bbbbbbbbbbbbbbbv",
      "bbbbbbbbbbbbbbbv",
      "vvvvvvvvvvvvvvvv"
    ],
    [
      "    c      abbbv",
      "    c      abbbv",
      "    c      abbbv",
      "    c     abbbbv",
      "    c     abbbbv",
      "    c    abbbbbv",
      "    c   abbbbbbv",
      "cccccccabbbbbbbv",
      "      abbbbbbbbv",
      "     abbbbbbbbbv",
      "   aabbbbbbbbbbv",
      "aaabbbbbbbbbbbbv",
      "bbbbbbbbbbbbbbbv",
      "bbbbbbbbbbbbbbbv",
      "bbbbbbbbbbbbbbbv",
      "vvvvvvvvvvvvvvvv"
    ],
    [
      "           abbbv",
      "           abbbv",
      "           abbbv",
      "          abbbbv",
      "          abbbbv",
      "         abbbbbv",
      "        abbbbbbv",
      "     dcabbbbbbbv",
      "      abbbbbbbbv",
      "     abbbbbbbbbv",
      "   aabbbbbbbbbbv",
      "aaabbbbbbbbbbbbv",
      "bbbbbbbbbbbbbbbv",
      "bbbbbbbbbbbbbbbv",
      "bbbbbbbbbbbbbbbv",
      "vvvvvvvvvvvvvvvv"
    ]
  ]
}