{
  "name": "multi_nuclearpowerplant_48_base10",
  "refpalette": "deceasedcraft:multi_nuclearpowerplant_48/multi_nuclearpowerplant_48_base10_palette",
  "xsize": 16,
  "zsize": 16,
  "slices": [
    [
      " abbcccccccdeeev",
      "aabccccccccdeeev",
      "bbbccccccccdeeev",
      "bcccccccccdeeeev",
      "ccccccccccdeeeev",
      "cccccccccdeeeeev",
      "cccccfffdeeeeeev",
      "cccccfgdeeeeeeev",
      "cccccfdeeeeeeeev",
      "cccccdeeeeeeeeev",
      "cccddeeeeeeeeeev",
      "dddeeeeeeeeeeeev",
      "eeeeeeeeeeeeeeev",
      "eeeeeeeeeeeeeeev",
      "eeeeeeeeeeeeeeev",
      "vvvvvvvvvvvvvvvv"
    ],
    [
      "  h        ieeev",
      "  j        ieeev",
      "hk         ieeev",
      "          ieeeev",
      "          ieeeev",
      "         ieeeeev",
      "      l ieeeeeev",
      "      mieeeeeeev",
      "      ieeeeeeeev",
      "     ieeeeeeeeev",
      "   iieeeeeeeeeev",
      "iiieeeeeeeeeeeev",
      "eeeeeeeeeeeeeeev",
      "eeeeeeeeeeeeeeev",
      "eeeeeeeeeeeeeeev",
      "vvvvvvvvvvvvvvvv"
    ],
    [
      "           ieeev",
      "           ieeev",
      "           ieeev",
      "          ieeeev",
      "          ieeeev",
      "         ieeeeev",
      "        ieeeeeev",
      "      mieeeeeeev",
      "      ieeeeeeeev",
      "     ieeeeeeeeev",
      "   iieeeeeeeeeev",
      "iiieeeeeeeeeeeev",
      "eeeeeeeeeeeeeeev",
      "eeeeeeeeeeeeeeev",
      "eeeeeeeeeeeeeeev",
      "vvvvvvvvvvvvvvvv"
    ],
    [
      "           ieeev",
      "           ieeev",
      "           ieeev",
      "          ieeeev",
      "          ieeeev",
      "         ieeeeev",
      "        ieeeeeev",
      "      mieeeeeeev",
      "      ieeeeeeeev",
      "     ieeeeeeeeev",
      "   iieeeeeeeeeev",
      "iiieeeeeeeeeeeev",
      "eeeeeeeeeeeeeeev",
      "eeeeeeeeeeeeeeev",
      "eeeeeeeeeeeeeeev",
      "vvvvvvvvvvvvvvvv"
    ],
    [
      "           ieeev",
      "           ieeev",
      "           ieeev",
      "          ieeeev",
      "          ieeeev",
      "         ieeeeev",
      "        ieeeeeev",
      "      mieeeeeeev",
      "      ieeeeeeeev",
      "     ieeeeeeeeev",
      "   iieeeeeeeeeev",
      "iiieeeeeeeeeeeev",
      "eeeeeeeeeeeeeeev",
      "eeeeeeeeeeeeeeev",
      "eeeeeeeeeeeeeeev",
      "vvvvvvvvvvvvvvvv"
    ],
    [
      "           ieeev",
      "           ieeev",
      "           ieeev",
      "          ieeeev",
      "          ieeeev",
      "         ieeeeev",
      "        ieeeeeev",
      "      mieeeeeeev",
      "      ieeeeeeeev",
      "     ieeeeeeeeev",
      "   iieeeeeeeeeev",
      "iiieeeeeeeeeeeev",
      "eeeeeeeeeeeeeeev",
      "eeeeeeeeeeeeeeev",
      "eeeeeeeeeeeeeeev",
      "vvvvvvvvvvvvvvvv"
    ]
  ]
}