{
  "name": "multi_nuclearpowerplant_48_base3",
  "refpalette": "deceasedcraft:multi_nuclearpowerplant_48/multi_nuclearpowerplant_48_base3_palette",
  "xsize": 16,
  "zsize": 16,
  "slices": [
    [
      "       aab=cdddv",
      "      aaab=cdddv",
      "      aaab=cdddv",
      "     aaab=cddddv",
      "    aaaab=cddddv",
      "   aaaab=cdddddv",
      " aaaaab=cddddddv",
      "aaaaab=cdddddddv",
      "aaabb=cddddddddv",
      "bbb==cdddddddddv",
      "===ccddddddddddv",
      "cccddddddddddddv",
      "dddddddddddddddv",
      "dddddddddddddddv",
      "dddddddddddddddv",
      "vvvvvvvvvvvvvvvv"
    ],
    [
      "       e f=gdddv",
      "      h  f=gdddv",
      "      e  f=gdddv",
      "     h  f=gddddv",
      "    h  if=gddddv",
      "   h   f=gdddddv",
      " hj   f=gddddddv",
      "j   kf=gdddddddv",
      "   ff=gddddddddv",
      "fff==gdddddddddv",
      "===ggddddddddddv",
      "gggddddddddddddv",
      "dddddddddddddddv",
      "dddddddddddddddv",
      "dddddddddddddddv",
      "vvvvvvvvvvvvvvvv"
    ],
    [
      "         f=gdddv",
      "         f=gdddv",
      "         f=gdddv",
      "        f=gddddv",
      "        f=gddddv",
      "       f=gdddddv",
      "      f=gddddddv",
      "     f=gdddddddv",
      "   ff=gddddddddv",
      "fff==gdddddddddv",
      "===ggddddddddddv",
      "gggddddddddddddv",
      "dddddddddddddddv",
      "dddddddddddddddv",
      "dddddddddddddddv",
      "vvvvvvvvvvvvvvvv"
    ],
    [
      "         f=gdddv",
      "         f=gdddv",
      "         f=gdddv",
      "        f=gddddv",
      "        f=gddddv",
      "       f=gdddddv",
      "      f=gddddddv",
      "     f=gdddddddv",
      "   ff=gddddddddv",
      "fff==gdddddddddv",
      "===ggddddddddddv",
      "gggddddddddddddv",
      "dddddddddddddddv",
      "dddddddddddddddv",
      "dddddddddddddddv",
      "vvvvvvvvvvvvvvvv"
    ],
    [
      "         f=gdddv",
      "         f=gdddv",
      "         f=gdddv",
      "        f=gddddv",
      "        f=gddddv",
      "       f=gdddddv",
      "      f=gddddddv",
      "     f=gdddddddv",
      "   ff=gddddddddv",
      "fff==gdddddddddv",
      "===ggddddddddddv",
      "gggddddddddddddv",
      "dddddddddddddddv",
      "dddddddddddddddv",
      "dddddddddddddddv",
      "vvvvvvvvvvvvvvvv"
    ],
    [
      "         f=gdddv",
      "         f=gdddv",
      "         f=gdddv",
      "        f=gddddv",
      "        f=gddddv",
      "       f=gdddddv",
      "      f=gddddddv",
      "     f=gdddddddv",
      "   ff=gddddddddv",
      "fff==gdddddddddv",
      "===ggddddddddddv",
      "gggddddddddddddv",
      "dddddddddddddddv",
      "dddddddddddddddv",
      "dddddddddddddddv",
      "vvvvvvvvvvvvvvvv"
    ]
  ]
}