{
  "name": "multi_nuclearpowerplant_48_base2",
  "refpalette": "deceasedcraft:multi_nuclearpowerplant_48/multi_nuclearpowerplant_48_base2_palette",
  "xsize": 16,
  "zsize": 16,
  "slices": [
    [
      "         a=bcccv",
      "         a=bcccv",
      "         a=bcccv",
      "        a=bccccv",
      "        a=bccccv",
      "       a=bcccccv",
      "      a=bccccccv",
      "     a=bcccccccv",
      "   aa=bccccccccv",
      "aaa==bcccccccccv",
      "===bbccccccccccv",
      "bbbccccccccccccv",
      "cccccccccccccccv",
      "cccccccccccccccv",
      "cccccccccccccccv",
      "vvvvvvvvvvvvvvvv"
    ],
    [
      "d        a=bcccv",
      "         a=bcccv",
      "         a=bcccv",
      "        a=bccccv",
      "        a=bccccv",
      "       a=bcccccv",
      "      a=bccccccv",
      "     a=bcccccccv",
      "   aa=bccccccccv",
      "aaa==bcccccccccv",
      "===bbccccccccccv",
      "bbbccccccccccccv",
      "cccccccccccccccv",
      "cccccccccccccccv",
      "cccccccccccccccv",
      "vvvvvvvvvvvvvvvv"
    ],
    [
      "ef       a=bcccv",
      "f        a=bcccv",
      "         a=bcccv",
      "        a=bccccv",
      "        a=bccccv",
      "       a=bcccccv",
      "      a=bccccccv",
      "     a=bcccccccv",
      "   aa=bccccccccv",
      "aaa==bcccccccccv",
      "===bbccccccccccv",
      "bbbccccccccccccv",
      "cccccccccccccccv",
      "cccccccccccccccv",
      "cccccccccccccccv",
      "vvvvvvvvvvvvvvvv"
    ],
    [
      "         a=bcccv",
      "        ga=bcccv",
      "        ga=bcccv",
      "        a=bccccv",
      "       a==bccccv",
      "      aa=bcccccv",
      "     aa=bccccccv",
      "    aa=bcccccccv",
      " hha==bccccccccv",
      "aaa==bcccccccccv",
      "===bbccccccccccv",
      "bbbccccccccccccv",
      "cccccccccccccccv",
      "cccccccccccccccv",
      "cccccccccccccccv",
      "vvvvvvvvvvvvvvvv"
    ],
    [
      "       ia=jbcccv",
      "       ia=jbcccv",
      "      iaa=jbcccv",
      "      ia=jbccccv",
      "     ia=jjbccccv",
      "    ia==jbcccccv",
      "  iia==jbccccccv",
      "iiaa==jbcccccccv",
      "aaa=jjbccccccccv",
      "===jjbcccccccccv",
      "jjjbbccccccccccv",
      "bbbccccccccccccv",
      "cccccccccccccccv",
      "cccccccccccccccv",
      "cccccccccccccccv",
      "vvvvvvvvvvvvvvvv"
    ],
    [
      "aaaaaaaa=jjbcccv",
      "aaaaaaaa=jjbcccv",
      "aaaaaaa==jjbcccv",
      "aaaaaaa=jjbccccv",
      "aaaaaa=jjjbccccv",
      "aaaaa=jjjbcccccv",
      "aaaa=jjjbccccccv",
      "aa==jjjbcccccccv",
      "===jjjbccccccccv",
      "jjjjjbcccccccccv",
      "jjjbbccccccccccv",
      "bbbccccccccccccv",
      "cccccccccccccccv",
      "cccccccccccccccv",
      "cccccccccccccccv",
      "vvvvvvvvvvvvvvvv"
    ]
  ]
}