{
  "name": "multi_nuclearpowerplant_48_base6",
  "refpalette": "deceasedcraft:multi_nuclearpowerplant_48/multi_nuclearpowerplant_48_base6_palette",
  "xsize": 16,
  "zsize": 16,
  "slices": [
    [
      "abbbc    d=efffv",
      "bbbcc    d=efffv",
      "bbcc     d=efffv",
      "bcc     d=effffv",
      "cc      d=effffv",
      "       d=efffffv",
      "      d=effffffv",
      "     d=efffffffv",
      "   dd=effffffffv",
      "ddd==efffffffffv",
      "===eeffffffffffv",
      "eeeffffffffffffv",
      "fffffffffffffffv",
      "fffffffffffffffv",
      "fffffffffffffffv",
      "vvvvvvvvvvvvvvvv"
    ],
    [
      "abbbc    d=gfffv",
      "bbbcc    d=gfffv",
      "bbcc     d=gfffv",
      "bcc     d=gffffv",
      "cc      d=gffffv",
      "       d=gfffffv",
      "      d=gffffffv",
      "     d=gfffffffv",
      "   dd=gffffffffv",
      "ddd==gfffffffffv",
      "===ggffffffffffv",
      "gggffffffffffffv",
      "fffffffffffffffv",
      "fffffffffffffffv",
      "fffffffffffffffv",
      "vvvvvvvvvvvvvvvv"
    ],
    [
      "abbbc    d=gfffv",
      "bbbcc    d=gfffv",
      "bbcc     d=gfffv",
      "bcc     d=gffffv",
      "cc      d=gffffv",
      "       d=gfffffv",
      "      d=gffffffv",
      "     d=gfffffffv",
      "   dd=gffffffffv",
      "ddd==gfffffffffv",
      "===ggffffffffffv",
      "gggffffffffffffv",
      "fffffffffffffffv",
      "fffffffffffffffv",
      "fffffffffffffffv",
      "vvvvvvvvvvvvvvvv"
    ],
    [
      "abbbc    d=gfffv",
      "bbbcc    d=gfffv",
      "bbcc     d=gfffv",
      "bcc     d=gffffv",
      "cc      d=gffffv",
      "       d=gfffffv",
      "      d=gffffffv",
      "     d=gfffffffv",
      "   dd=gffffffffv",
      "ddd==gfffffffffv",
      "===ggffffffffffv",
      "gggffffffffffffv",
      "fffffffffffffffv",
      "fffffffffffffffv",
      "fffffffffffffffv",
      "vvvvvvvvvvvvvvvv"
    ],
    [
      "abbbc    d=gfffv",
      "bbbcc    d=gfffv",
      "bbcc     d=gfffv",
      "bcc     d=gffffv",
      "cc      d=gffffv",
      "       d=gfffffv",
      "      d=gffffffv",
      "     d=gfffffffv",
      "   dd=gffffffffv",
      "ddd==gfffffffffv",
      "===ggffffffffffv",
      "gggffffffffffffv",
      "fffffffffffffffv",
      "fffffffffffffffv",
      "fffffffffffffffv",
      "vvvvvvvvvvvvvvvv"
    ],
    [
      "hbbbc    d=gfffv",
      "bbbcc    d=gfffv",
      "bbcc     d=gfffv",
      "bcc     d=gffffv",
      "cc      d=gffffv",
      "       d=gfffffv",
      "      d=gffffffv",
      "     d=gfffffffv",
      "   dd=gffffffffv",
      "ddd==gfffffffffv",
      "===ggffffffffffv",
      "gggffffffffffffv",
      "fffffffffffffffv",
      "fffffffffffffffv",
      "fffffffffffffffv",
      "vvvvvvvvvvvvvvvv"
    ]
  ]
}