{
  "name": "multi_nuclearpowerplant_48_base8",
  "refpalette": "deceasedcraft:multi_nuclearpowerplant_48/multi_nuclearpowerplant_48_base8_palette",
  "xsize": 16,
  "zsize": 16,
  "slices": [
    [
      "           abbbv",
      "           abbbv",
      "           abbbv",
      "          abbbbv",
      "          abbbbv",
      "         abbbbbv",
      "        abbbbbbv",
      "      cabbbbbbbv",
      "      abbbbbbbbv",
      "     abbbbbbbbbv",
      "   aabbbbbbbbbbv",
      "aaabbbbbbbbbbbbv",
      "bbbbbbbbbbbbbbbv",
      "bbbbbbbbbbbbbbbv",
      "bbbbbbbbbbbbbbbv",
      "vvvvvvvvvvvvvvvv"
    ],
    [
      "dddddddddddebbbv",
      "dddddddddddebbbv",
      "dddddddddddebbbv",
      "ddddddddddebbbbv",
      "ddddddddddebbbbv",
      "dddddddddebbbbbv",
      "ddddddddebbbbbbv",
      "ddddddfebbbbbbbv",
      "ddddddebbbbbbbbv",
      "dddddebbbbbbbbbv",
      "dddeebbbbbbbbbbv",
      "eeebbbbbbbbbbbbv",
      "bbbbbbbbbbbbbbbv",
      "bbbbbbbbbbbbbbbv",
      "bbbbbbbbbbbbbbbv",
      "vvvvvvvvvvvvvvvv"
    ],
    [
      "bbbbbbbbbbbabbbv",
      "bbbbbbbbbbbabbbv",
      "bbbbbbbbbbbabbbv",
      "bbbbbbbbbbabbbbv",
      "bbbbbbbbbbabbbbv",
      "bbbbbbbbbabbbbbv",
      "bbbbbbbbabbbbbbv",
      "bbbbbbbabbbbbbbv",
      "bbbbbbabbbbbbbbv",
      "bbbbbabbbbbbbbbv",
      "bbbaabbbbbbbbbbv",
      "aaabbbbbbbbbbbbv",
      "bbbbbbbbbbbbbbbv",
      "bbbbbbbbbbbbbbbv",
      "bbbbbbbbbbbbbbbv",
      "vvvvvvvvvvvvvvvv"
    ],
    [
      "bbbbbbbbbbbabbbv",
      "bbbbbbbbbbbabbbv",
      "bbbbbbbbbbbabbbv",
      "bbbbbbbbbbabbbbv",
      "bbbbbbbbbbabbbbv",
      "bbbbbbbbbabbbbbv",
      "bbbbbbbbabbbbbbv",
      "bbbbbbbabbbbbbbv",
      "bbbbbbabbbbbbbbv",
      "bbbbbabbbbbbbbbv",
      "bbbaabbbbbbbbbbv",
      "aaabbbbbbbbbbbbv",
      "bbbbbbbbbbbbbbbv",
      "bbbbbbbbbbbbbbbv",
      "bbbbbbbbbbbbbbbv",
      "vvvvvvvvvvvvvvvv"
    ],
    [
      "==========gebbbv",
      "==========gebbbv",
      "==========gebbbv",
      "=========gebbbbv",
      "=========gebbbbv",
      "========gebbbbbv",
      "=======gebbbbbbv",
      "======gebbbbbbbv",
      "=====gebbbbbbbbv",
      "===ggebbbbbbbbbv",
      "gggeebbbbbbbbbbv",
      "eeebbbbbbbbbbbbv",
      "bbbbbbbbbbbbbbbv",
      "bbbbbbbbbbbbbbbv",
      "bbbbbbbbbbbbbbbv",
      "vvvvvvvvvvvvvvvv"
    ],
    [
      "ffffffffff=abbbv",
      "ffffffffff=abbbv",
      "ffffffffff=abbbv",
      "fffffffff=abbbbv",
      "fffffffff=abbbbv",
      "ffffffff=abbbbbv",
      "fffffff=abbbbbbv",
      "ffffff=abbbbbbbv",
      "fffff=abbbbbbbbv",
      "fff==abbbbbbbbbv",
      "===aabbbbbbbbbbv",
      "aaabbbbbbbbbbbbv",
      "bbbbbbbbbbbbbbbv",
      "bbbbbbbbbbbbbbbv",
      "bbbbbbbbbbbbbbbv",
      "vvvvvvvvvvvvvvvv"
    ]
  ]
}