{
  "name": "multi_nuclearpowerplant_48_base7",
  "refpalette": "deceasedcraft:multi_nuclearpowerplant_48/multi_nuclearpowerplant_48_base7_palette",
  "xsize": 16,
  "zsize": 16,
  "slices": [
    [
      " aaab    c=deeev",
      "aaabb    c=deeev",
      "aabb     c=deeev",
      "abb     c=deeeev",
      "bb      c=deeeev",
      "       c=deeeeev",
      "f     c=deeeeeev",
      "g   hc=deeeeeeev",
      "   cc=deeeeeeeev",
      "ccc==deeeeeeeeev",
      "===ddeeeeeeeeeev",
      "dddeeeeeeeeeeeev",
      "eeeeeeeeeeeeeeev",
      "eeeeeeeeeeeeeeev",
      "eeeeeeeeeeeeeeev",
      "vvvvvvvvvvvvvvvv"
    ],
    [
      "@aaab    c=deeev",
      "aaabb    c=deeev",
      "aabb     c=deeev",
      "abb     c=deeeev",
      "bb      c=deeeev",
      "       c=deeeeev",
      "      c=deeeeeev",
      "     c=deeeeeeev",
      "   cc=deeeeeeeev",
      "ccc==deeeeeeeeev",
      "===ddeeeeeeeeeev",
      "dddeeeeeeeeeeeev",
      "eeeeeeeeeeeeeeev",
      "eeeeeeeeeeeeeeev",
      "eeeeeeeeeeeeeeev",
      "vvvvvvvvvvvvvvvv"
    ],
    [
      "ijjjb    c=deeev",
      "jjjbb    c=deeev",
      "jjbb     c=deeev",
      "jbb     c=deeeev",
      "bb      c=deeeev",
      "       c=deeeeev",
      "      c=deeeeeev",
      "     c=deeeeeeev",
      "   cc=deeeeeeeev",
      "ccc==deeeeeeeeev",
      "===ddeeeeeeeeeev",
      "dddeeeeeeeeeeeev",
      "eeeeeeeeeeeeeeev",
      "eeeeeeeeeeeeeeev",
      "eeeeeeeeeeeeeeev",
      "vvvvvvvvvvvvvvvv"
    ],
    [
      "ijjjb    c=deeev",
      "jjjbb    c=deeev",
      "jjbb     c=deeev",
      "jbb     c=deeeev",
      "bb      c=deeeev",
      "       c=deeeeev",
      "      c=deeeeeev",
      "     c=deeeeeeev",
      "   cc=deeeeeeeev",
      "ccc==deeeeeeeeev",
      "===ddeeeeeeeeeev",
      "dddeeeeeeeeeeeev",
      "eeeeeeeeeeeeeeev",
      "eeeeeeeeeeeeeeev",
      "eeeeeeeeeeeeeeev",
      "vvvvvvvvvvvvvvvv"
    ],
    [
      "ijjjb    c=deeev",
      "jjjbb    c=deeev",
      "jjbb     c=deeev",
      "jbb     c=deeeev",
      "bb      c=deeeev",
      "       c=deeeeev",
      "      c=deeeeeev",
      "     c=deeeeeeev",
      "   cc=deeeeeeeev",
      "ccc==deeeeeeeeev",
      "===ddeeeeeeeeeev",
      "dddeeeeeeeeeeeev",
      "eeeeeeeeeeeeeeev",
      "eeeeeeeeeeeeeeev",
      "eeeeeeeeeeeeeeev",
      "vvvvvvvvvvvvvvvv"
    ],
    [
      "ijjjb    c=deeev",
      "jjjbb    c=deeev",
      "jjbb     c=deeev",
      "jbb     c=deeeev",
      "bb      c=deeeev",
      "       c=deeeeev",
      "      c=deeeeeev",
      "     c=deeeeeeev",
      "   cc=deeeeeeeev",
      "ccc==deeeeeeeeev",
      "===ddeeeeeeeeeev",
      "dddeeeeeeeeeeeev",
      "eeeeeeeeeeeeeeev",
      "eeeeeeeeeeeeeeev",
      "eeeeeeeeeeeeeeev",
      "vvvvvvvvvvvvvvvv"
    ]
  ]
}