{
  "name": "multi_nuclearpowerplant_48_base5",
  "refpalette": "deceasedcraft:multi_nuclearpowerplant_48/multi_nuclearpowerplant_48_base5_palette",
  "xsize": 16,
  "zsize": 16,
  "slices": [
    [
      "abbbc    d=efffv",
      "bbbcc    d=efffv",
      "bbcc     d=efffv",
      "bcc     d=effffv",
      "cc      d=effffv",
      "       d=efffffv",
      "      d=effffffv",
      "     d=efffffffv",
      "   dd=effffffffv",
      "ddd==efffffffffv",
      "===eeffffffffffv",
      "eeeffffffffffffv",
      "fffffffffffffffv",
      "fffffffffffffffv",
      "fffffffffffffffv",
      "vvvvvvvvvvvvvvvv"
    ],
    [
      "abbbc    d=efffv",
      "bbbcc    d=efffv",
      "bbcc     d=efffv",
      "bcc     d=effffv",
      "cc      d=effffv",
      "       d=efffffv",
      "      d=effffffv",
      "     d=efffffffv",
      "   dd=effffffffv",
      "ddd==efffffffffv",
      "===eeffffffffffv",
      "eeeffffffffffffv",
      "fffffffffffffffv",
      "fffffffffffffffv",
      "fffffffffffffffv",
      "vvvvvvvvvvvvvvvv"
    ],
    [
      "abbbc    d=efffv",
      "bbbcc    d=efffv",
      "bbcc     d=efffv",
      "bcc     d=effffv",
      "cc      d=effffv",
      "       d=efffffv",
      "      d=effffffv",
      "     d=efffffffv",
      "   dd=effffffffv",
      "ddd==efffffffffv",
      "===eeffffffffffv",
      "eeeffffffffffffv",
      "fffffffffffffffv",
      "fffffffffffffffv",
      "fffffffffffffffv",
      "vvvvvvvvvvvvvvvv"
    ],
    [
      "abbbc    d=efffv",
      "bbbcc    d=efffv",
      "bbcc     d=efffv",
      "bcc     d=effffv",
      "cc      d=effffv",
      "       d=efffffv",
      "      d=effffffv",
      "     d=efffffffv",
      "   dd=effffffffv",
      "ddd==efffffffffv",
      "===eeffffffffffv",
      "eeeffffffffffffv",
      "fffffffffffffffv",
      "fffffffffffffffv",
      "fffffffffffffffv",
      "vvvvvvvvvvvvvvvv"
    ],
    [
      "abbbc    d=efffv",
      "bbbcc    d=efffv",
      "bbcc     d=efffv",
      "bcc     d=effffv",
      "cc      d=effffv",
      "       d=efffffv",
      "      d=effffffv",
      "     d=efffffffv",
      "   dd=effffffffv",
      "ddd==efffffffffv",
      "===eeffffffffffv",
      "eeeffffffffffffv",
      "fffffffffffffffv",
      "fffffffffffffffv",
      "fffffffffffffffv",
      "vvvvvvvvvvvvvvvv"
    ],
    [
      "abbbc    d=efffv",
      "bbbcc    d=efffv",
      "bbcc     d=efffv",
      "bcc     d=effffv",
      "cc      d=effffv",
      "       d=efffffv",
      "      d=effffffv",
      "     d=efffffffv",
      "   dd=effffffffv",
      "ddd==efffffffffv",
      "===eeffffffffffv",
      "eeeffffffffffffv",
      "fffffffffffffffv",
      "fffffffffffffffv",
      "fffffffffffffffv",
      "vvvvvvvvvvvvvvvv"
    ]
  ]
}