{
  "name": "multi_nuclearpowerplant_48_base1",
  "refpalette": "deceasedcraft:multi_nuclearpowerplant_48/multi_nuclearpowerplant_48_base1_palette",
  "xsize": 16,
  "zsize": 16,
  "slices": [
    [
      "========aaabcccv",
      "========aaabcccv",
      "=======aaaabcccv",
      "=======aaabccccv",
      "======aaaabccccv",
      "=====aaaabcccccv",
      "====aaaabccccccv",
      "==aaaaabcccccccv",
      "aaaaaabccccccccv",
      "aaaaabcccccccccv",
      "aaabbccccccccccv",
      "bbbccccccccccccv",
      "cccccccccccccccv",
      "cccccccccccccccv",
      "cccccccccccccccv",
      "vvvvvvvvvvvvvvvv"
    ],
    [
      "aaaaaaaaaaabcccv",
      "aaaaaaaaaaabcccv",
      "aaaaaaaaaaabcccv",
      "aaaaaaaaaabccccv",
      "aaaaaaaaaabccccv",
      "aaaaaaaaabcccccv",
      "aaaaaaaabccccccv",
      "aaaaaaabcccccccv",
      "aaaaaabccccccccv",
      "aaaaabcccccccccv",
      "aaabbccccccccccv",
      "bbbccccccccccccv",
      "cccccccccccccccv",
      "cccccccccccccccv",
      "cccccccccccccccv",
      "vvvvvvvvvvvvvvvv"
    ],
    [
      "aaaaaaaaaaabcccv",
      "aaaaaaaaaaabcccv",
      "aaaaaaaaaaabcccv",
      "aaaaaaaaaabccccv",
      "aaaaaaaaaabccccv",
      "aaaaaaaaabcccccv",
      "aaaaaaaabccccccv",
      "aaaaaaabcccccccv",
      "aaaaaabccccccccv",
      "aaaaabcccccccccv",
      "aaabbccccccccccv",
      "bbbccccccccccccv",
      "cccccccccccccccv",
      "cccccccccccccccv",
      "cccccccccccccccv",
      "vvvvvvvvvvvvvvvv"
    ],
    [
      "aaaaaaaaaaabcccv",
      "aaaaaaaaaaabcccv",
      "aaaaaaaaaaabcccv",
      "aaaaaaaaaabccccv",
      "aaaaaaaaaabccccv",
      "aaaaaaaaabcccccv",
      "aaaaaaaabccccccv",
      "aaaaaaabcccccccv",
      "aaaaaabccccccccv",
      "aaaaabcccccccccv",
      "aaabbccccccccccv",
      "bbbccccccccccccv",
      "cccccccccccccccv",
      "cccccccccccccccv",
      "cccccccccccccccv",
      "vvvvvvvvvvvvvvvv"
    ],
    [
      "aaaaaaaaaaabcccv",
      "aaaaaaaaaaabcccv",
      "aaaaaaaaaaabcccv",
      "aaaaaaaaaabccccv",
      "aaaaaaaaaabccccv",
      "aaaaaaaaabcccccv",
      "aaaaaaaabccccccv",
      "aaaaaaabcccccccv",
      "aaaaaabccccccccv",
      "aaaaabcccccccccv",
      "aaabbccccccccccv",
      "bbbccccccccccccv",
      "cccccccccccccccv",
      "cccccccccccccccv",
      "cccccccccccccccv",
      "vvvvvvvvvvvvvvvv"
    ],
    [
      "aaaaaaaaaaabaaav",
      "aaaaaaaaaaabaaav",
      "aaaaaaaaaaabaaav",
      "aaaaaaaaaabaaaav",
      "aaaaaaaaaabaaaav",
      "aaaaaaaaabaaaaav",
      "aaaaaaaabaaaaaav",
      "aaaaaaabaaaaaaav",
      "aaaaaabaaaaaaaav",
      "aaaaabaaaaaaaaav",
      "aaabbaaaaaaaaaav",
      "bbbaaaaaaaaaaaav",
      "aaaaaaaaaaaaaaav",
      "aaaaaaaaaaaaaaav",
      "aaaaaaaaaaaaaaav",
      "vvvvvvvvvvvvvvvv"
    ]
  ]
}