{
  "name": "multi_thering_17_base2",
  "refpalette": "deceasedcraft:multi_thering_17/multi_thering_17_base2_palette",
  "xsize": 16,
  "zsize": 16,
  "slices": [
    [
      "aaaaaaaaaaaaaaab",
      "aaaaaaaaaaaaaaaa",
      "aaaaaaaaaaaaaaaa",
      "aaaaaaaaaaaaaaaa",
      "aaaaaaaaaaaaaaaa",
      "aaaaaaaaaaaaaaaa",
      "aaaaaaaaaaaaaaaa",
      "aaaaaaaaaaaaaaaa",
      "aaaaaaaaaaaaaaaa",
      "aaaaaaaaaaaaaaaa",
      "aaaaaaaaaaaaaaaa",
      "aaaaaaaaaaaaaaaa",
      "aaaaaaaaaaaaaaaa",
      "aaaaaaaaaaaaaaaa",
      "aaaaaaaaaaaaaaaa",
      "aaaaaaaaaaaaaaab"
    ],
    [
      "aaaaaaaaaaaaaaab",
      "aaaaaaaaaaaaaaaa",
      "aaaaaaaaaaaaaaaa",
      "aaaaaaaaaaaaaaaa",
      "aaaaaaaaaaaaaaaa",
      "aaaaaaaaaaaaaaaa",
      "aaaaaaaaaaaaaaaa",
      "aaaaaaaaaaaaaaaa",
      "aaaaaaaaaaaaaaaa",
      "aaaaaaaaaaaaaaaa",
      "aaaaaaaaaaaaaaaa",
      "aaaaaaaaaaaaaaaa",
      "aaaaaaaaaaaaaaaa",
      "aaaaaaaaaaaaaaaa",
      "aaaaaaaaaaaaaaaa",
      "aaaaaaaaaaaaaaab"
    ],
    [
      "aaaaaaaaaaaaaaab",
      "aaaaaaaaaaaaaaaa",
      "aaaaaaaaaaaaaaaa",
      "aaaaaaaaaaaaaaaa",
      "aaaaaaaaaaaaaaaa",
      "aaaaaaaaaaaaaaaa",
      "aaaaaaaaaaaaaaaa",
      "aaaaaaaaaaaaaaaa",
      "aaaaaaaaaaaaaaaa",
      "aaaaaaaaaaaaaaaa",
      "aaaaaaaaaaaaaaaa",
      "aaaaaaaaaaaaaaaa",
      "aaaaaaaaaaaaaaaa",
      "aaaaaaaaaaaaaaaa",
      "aaaaaaaaaaaaaaaa",
      "aaaaaaaaaaaaaaab"
    ],
    [
      "ccaaaaaaaaaaaaab",
      "ccaaaaaaaaaaaaaa",
      "ccaaaaaaaaaaaaaa",
      "ccaaaaaaaaaaaaaa",
      "ccaaaaaaaaaaaaaa",
      "caaaaaaaaaaaaaaa",
      "caaaaaaaaaaaaaaa",
      "caaaaaaaaaaaaaaa",
      "aaaaaaaaaaaaaaaa",
      "aaaaaaaaaaaaaaaa",
      "aaaaaaaaaaaaaaaa",
      "aaaaaaaaaaaaaaaa",
      "aaaaaaaaaaaaaaaa",
      "aaaaaaaaaaaaaaaa",
      "aaaaaaaaaaaaaaaa",
      "aaaaaaaaaaaaaaab"
    ],
    [
      "deccaaaaaaaaaaab",
      "deccaaaaaaaaaaaa",
      "eeccaaaaaaaaaaaa",
      "eeccaaaaaaaaaaaa",
      "eeccaaaaaaaaaaaa",
      "ecccaaaaaaaaaaaa",
      "eccaaaaaaaaaaaaa",
      "eccaaaaaaaaaaaaa",
      "cccaaaaaaaaaaaaa",
      "ccaaaaaaaaaaaaaa",
      "ccaaaaaaaaaaaaaa",
      "caaaaaaaaaaaaaaa",
      "caaaaaaaaaaaaaaa",
      "aaaaaaaaaaaaaaaa",
      "aaaaaaaaaaaaaaaa",
      "aaaaaaaaaaaaaaab"
    ],
    [
      "fedeccaaaaaaaaab",
      "fedeccaaaaaaaaaa",
      " edeccaaaaaaaaaa",
      " eeeccaaaaaaaaaa",
      " geeccaaaaaaaaaa",
      "ggeeccaaaaaaaaaa",
      "geecccaaaaaaaaaa",
      "geeccaaaaaaaaaaa",
      "geeccaaaaaaaaaaa",
      "eecccaaaaaaaaaaa",
      "eeccaaaaaaaaaaaa",
      "ecccaaaaaaaaaaaa",
      "eccaaaaaaaaaaaaa",
      "cccaaaaaaaaaaaaa",
      "ccaaaaaaaaaaaaaa",
      "caaaaaaaaaaaaaab"
    ]
  ]
}