{
  "name": "multi_thering_17_base1",
  "refpalette": "deceasedcraft:multi_thering_17/multi_thering_17_base1_palette",
  "xsize": 16,
  "zsize": 16,
  "slices": [
    [
      " abcdceefffffffg",
      "  bcdceeffffffff",
      "  bccceeffffffff",
      "   hcceeffffffff",
      "   hcceeffffffff",
      "   hcceeffffffff",
      "  hhcceeffffffff",
      "  hcceeeffffffff",
      "  hcceefffffffff",
      " hhcceefffffffff",
      " hcceeefffffffff",
      "hhcceeefffffffff",
      "hcceeeffffffffff",
      "hcceeeffffffffff",
      "cceeefffffffffff",
      "ceeefffffffffffg"
    ],
    [
      "    bcdceefffffg",
      "    bcdceeffffff",
      "     cdceeffffff",
      "     cdceeffffff",
      "     ccceeffffff",
      "     hcceeffffff",
      "     hcceeffffff",
      "    hhcceeffffff",
      "    hcceeeffffff",
      "    hcceeeffffff",
      "   hhcceefffffff",
      "   hccceefffffff",
      "  hhcceeefffffff",
      "  hccceeffffffff",
      " hhcceeeffffffff",
      "hhcceeeffffffffg"
    ],
    [
      "     abcdceefffg",
      "      bcdceeffff",
      "      bcdceeffff",
      "      bcdceeffff",
      "       cdceeffff",
      "       ccceeffff",
      "       hcceeffff",
      "       hcceeffff",
      "      hhcceeffff",
      "      hccceeffff",
      "      hcceeeffff",
      "      hcceefffff",
      "     hhcceefffff",
      "     hcceeefffff",
      "    hhcceeffffff",
      "   hhcceeefffffg"
    ],
    [
      "        bcdceefg",
      "        bcdceeff",
      "        bcdceeff",
      "        bcdceeff",
      "        bccceeff",
      "         hcceeff",
      "         hcceeff",
      "         hcceeff",
      "         hcceeff",
      "         hcceeff",
      "        hhcceeff",
      "        hcceeeff",
      "        hcceefff",
      "       hhcceefff",
      "       hcceeefff",
      "      hhcceefffg"
    ],
    [
      "         abcdceg",
      "          bcdcee",
      "          bcdcee",
      "          bcdcee",
      "           cdcee",
      "           cdcee",
      "           cccee",
      "           hccee",
      "           hccee",
      "           hccee",
      "           hccee",
      "          hhccee",
      "          hcceee",
      "          hcceef",
      "         hhcceef",
      "         hcceeeg"
    ],
    [
      "            bcdg",
      "            bcdc",
      "            bcdc",
      "            bcdc",
      "            bcdc",
      "            bcdc",
      "             cdc",
      "             ccc",
      "             hcc",
      "             hcc",
      "             hcc",
      "             hcc",
      "            hhcc",
      "            hcce",
      "            hcce",
      "           hhccg"
    ]
  ]
}