{
  "name": "multi_nuclearpowerplant_44_base7",
  "refpalette": "deceasedcraft:multi_nuclearpowerplant_44/multi_nuclearpowerplant_44_base7_palette",
  "xsize": 16,
  "zsize": 16,
  "slices": [
    [
      "aaaaab    c=deev",
      "aaaabb    c=deev",
      "aaabb     c=deev",
      "bbbb     c=fdeev",
      "         c=gdeev",
      "        c=h diiv",
      "       c=  jd  v",
      "     cc=   kl  v",
      "ccccc==    mn  v",
      "=====      jd  v",
      "o          pd  v",
      "q           d  v",
      "            d  v",
      "rrr         d  v",
      "rsr         d  v",
      "rrr         d  v"
    ],
    [
      "aaaaab    c=deev",
      "aaaabb    c=deev",
      "aaabb     c=deev",
      "bbbb     c=pdeev",
      "         c=tdeev",
      "        c= udiiv",
      "       c=   d  v",
      "     cc=    w  v",
      "ccccc==     w  v",
      "=====       d  v",
      "           pd  v",
      "            d  v",
      "            d  v",
      "rrr         d  v",
      "xyx         d  v",
      "rAr         d  v"
    ],
    [
      "     b    c=deev",
      "    bb    c=deev",
      "   bb     c=deev",
      "bbbb     c=pdeev",
      "         c==deev",
      "        c=  diiv",
      "       c=   d  v",
      "     cc=    d  v",
      "ccccc==     d  v",
      "=====       d  v",
      "           pd  v",
      "            d  v",
      "            d  v",
      "rrr         d  v",
      "x x         d  v",
      "rrr         d  v"
    ],
    [
      "     b    c=deev",
      "    bb    c=deev",
      "   bb     c=deev",
      "bbbb     c=pdeev",
      "         c==deev",
      "        c=  diiv",
      "       c=   d  v",
      "     cc=    d  v",
      "ccccc==     d  v",
      "=====       d  v",
      "           pd  v",
      "            d  v",
      "            d  v",
      "rrr         d  v",
      "x x         d  v",
      "rrr         d  v"
    ],
    [
      "     b    c=deev",
      "    bb    c=deev",
      "   bb     c=deev",
      "bbbb     c=pdeev",
      "         c==deev",
      "        c=  diiv",
      "       c=   d  v",
      "     cc=    d  v",
      "ccccc==     d  v",
      "=====       d  v",
      "           pd  v",
      "           pd  v",
      "           pd  v",
      "rrr        pd  v",
      "x x        pd  v",
      "rrr        pd  v"
    ],
    [
      "     b    c=deev",
      "    bb    c=deev",
      "   bb     c=deev",
      "bbbb     c=pdeev",
      "         c==deev",
      "        c=  diiv",
      "       c=   diiv",
      "     cc=    diiv",
      "ccccc==     diiv",
      "=====       diiv",
      "            diiv",
      "            diiv",
      "            diiv",
      "rrr         diiv",
      "x x         diiv",
      "rrr         diiv"
    ]
  ]
}