{
  "name": "multi_nuclearpowerplant_44_base6",
  "refpalette": "deceasedcraft:multi_nuclearpowerplant_44/multi_nuclearpowerplant_44_base6_palette",
  "xsize": 16,
  "zsize": 16,
  "slices": [
    [
      "     a    b=cddv",
      "    aa    b=cddv",
      "   aa     b=cddv",
      "aaaa     b=ecddv",
      "         b==cddv",
      "        b=  cddv",
      "       b=   cddv",
      "     bb=    cddv",
      "bbbbb==     cddv",
      "=====       cddv",
      "            cddv",
      "            cddv",
      "            cddv",
      "fff         cddv",
      "g g         cddv",
      "fff         cddv"
    ],
    [
      "     a    b=hddv",
      "    aa    b=hddv",
      "   aa     b=hddv",
      "aaaa     b=ehddv",
      "         b==hddv",
      "        b=  hddv",
      "       b=   hddv",
      "     bb=    hddv",
      "bbbbb==     hddv",
      "=====       hddv",
      "            hddv",
      "            hddv",
      "            hddv",
      "fff         hddv",
      "g g         hddv",
      "fff         hddv"
    ],
    [
      "     a    b=hddv",
      "    aa    b=hddv",
      "   aa     b=hddv",
      "aaaa     b=ehddv",
      "         b==hddv",
      "        b=  hddv",
      "       b=   hddv",
      "     bb=    hddv",
      "bbbbb==     hddv",
      "=====       hddv",
      "            hddv",
      "ii          hddv",
      " i          hddv",
      "fff         hddv",
      "g g         hddv",
      "fff         hddv"
    ],
    [
      "     a    b=hddv",
      "    aa    b=hddv",
      "   aa     b=hddv",
      "aaaa     b=ehddv",
      "         b==hddv",
      "        b=  hddv",
      "       b=   hddv",
      "     bb=    hddv",
      "bbbbb==     hddv",
      "=====       hddv",
      "jj          hddv",
      "  k         hddv",
      "l k         hddv",
      "f f         hddv",
      "gmg         hddv",
      "fff         hddv"
    ],
    [
      "     a    b=hddv",
      "    aa    b=hddv",
      "   aa     b=hddv",
      "aaaa     b=ehddv",
      "         b==hddv",
      "        b=  hddv",
      "       b=   hddv",
      "     bb=    hddv",
      "bbbbb==     hddv",
      "=====       hddv",
      "            hddv",
      "nn          hddv",
      " n          hddv",
      "fff         hddv",
      "g g         hddv",
      "fff         hddv"
    ],
    [
      "     a    b=hddv",
      "    aa    b=hddv",
      "   aa     b=hddv",
      "aaaa     b=ehddv",
      "         b==hddv",
      "        b=  hddv",
      "       b=   hddv",
      "     bb=    hddv",
      "bbbbb==     hddv",
      "=====       hddv",
      "            hddv",
      "            hddv",
      "            hddv",
      "fff         hddv",
      "g g         hddv",
      "fff         hddv"
    ]
  ]
}