{
  "name": "multi_nuclearpowerplant_44_base11",
  "refpalette": "deceasedcraft:multi_nuclearpowerplant_44/multi_nuclearpowerplant_44_base11_palette",
  "xsize": 16,
  "zsize": 16,
  "slices": [
    [
      "abcd========effv",
      "cccd========effv",
      "agcd========effv",
      "bhcd========effv",
      "cccd========effv",
      "ghcd========effv",
      "ibcd========effv",
      "cccd========effv",
      "agcd========effv",
      "bhcd========effv",
      "cccd========effv",
      "ghcd========effv",
      "abcd========effv",
      "cccd========effv",
      "agcd========effv",
      "bhcd========effv"
    ],
    [
      "bhcd========effv",
      "cccd========effv",
      "ghcd========effv",
      "abcd========effv",
      "cccd========effv",
      "agcd========effv",
      "bhcd========effv",
      "cccd========effv",
      "ghcd========effv",
      "abcd========effv",
      "cccd========effv",
      "agcd========effv",
      "bhcd========effv",
      "cccd========effv",
      "ghcd========effv",
      "abcd========effv"
    ],
    [
      "abcd========effv",
      "cccd========effv",
      "agcd========effv",
      "bhcd========effv",
      "cccd========effv",
      "cccd========effv",
      "cccd========effv",
      "cccd========effv",
      "agcd========effv",
      "bhcd========effv",
      "cccd========effv",
      "ghcd========effv",
      "abcd========effv",
      "cccd========effv",
      "cccd========effv",
      "cccd========effv"
    ],
    [
      "cccd========effv",
      "cccd========effv",
      "cccd========effv",
      "cccd========effv",
      "cccd========effv",
      "cccd========effv",
      "cccd========effv",
      "cccd========effv",
      "cccd========effv",
      "cccd========effv",
      "cccd========effv",
      "cccd========effv",
      "cccd========effv",
      "cccd========effv",
      "cccd========effv",
      "cccd========effv"
    ],
    [
      "cccd========effv",
      "cccd========effv",
      "cccd========effv",
      "cccd========effv",
      "cccd========effv",
      "cccd========effv",
      "cccd========effv",
      "cccd========effv",
      "cccd========effv",
      "cccd========effv",
      "cccd========effv",
      "cccd========effv",
      "cccd========effv",
      "cccd========effv",
      "cccd========effv",
      "cccd========effv"
    ],
    [
      "cccd========effv",
      "cccd========effv",
      "cccd========effv",
      "cccd========effv",
      "cccd========effv",
      "cccd========effv",
      "cccd========effv",
      "cccd========effv",
      "cccd========effv",
      "cccd========effv",
      "cccd========effv",
      "cccd========effv",
      "cccd========effv",
      "cccd========effv",
      "cccd========effv",
      "cccd========effv"
    ]
  ]
}