{
  "name": "multi_nuclearpowerplant_44_base9",
  "refpalette": "deceasedcraft:multi_nuclearpowerplant_44/multi_nuclearpowerplant_44_base9_palette",
  "xsize": 16,
  "zsize": 16,
  "slices": [
    [
      "            abbv",
      "            abbv",
      "            abbv",
      "            abbv",
      "            abbv",
      "            abbv",
      "            abbv",
      "          c abbv",
      "    deeeeeedabbv",
      "    f       abbv",
      "    f       abbv",
      "    f       abbv",
      "    f       abbv",
      "    f       abbv",
      "    f       abbv",
      "    f       abbv"
    ],
    [
      "           gabbv",
      "           gabbv",
      "           gabbv",
      "           gabbv",
      "           gabbv",
      "           gabbv",
      "           gabbv",
      "           gabbv",
      "    deeeeeedabbv",
      "    f       abbv",
      "    f       abbv",
      "    f       abbv",
      "    f       abbv",
      "    f       abbv",
      "    f       abbv",
      "    f       abbv"
    ],
    [
      "            abbv",
      "          hiabbv",
      "          hjabbv",
      "          hiabbv",
      "          hiabbv",
      "          h abbv",
      "          hiabbv",
      "          ckabbv",
      "    deeeeeedabbv",
      "    f       abbv",
      "    f       abbv",
      "    f       abbv",
      "    f       abbv",
      "    f       abbv",
      "    f       abbv",
      "    f       allv"
    ],
    [
      "            abbv",
      "            abbv",
      "            abbv",
      "            abbv",
      "            abbv",
      "            abbv",
      "            abbv",
      "          c abbv",
      "mmmndeeeeeedabbv",
      "    f       abbv",
      "    f       abbv",
      "    f       abbv",
      "    f       abbv",
      "    f       abbv",
      "    f       allv",
      "    f       aoov"
    ],
    [
      "    p       abbv",
      "    p       abbv",
      "    p       abbv",
      "    p       abbv",
      "    p       abbv",
      "    p       abbv",
      "    p       abbv",
      "    p       abbv",
      "ppppddddddddabbv",
      "    d       abbv",
      "    d       abbv",
      "    d       abbv",
      "    d       abbv",
      "    d       allv",
      "    d       aoov",
      "    d       aqqv"
    ],
    [
      "            abbv",
      "            abbv",
      "            abbv",
      "            abbv",
      "            abbv",
      "            abbv",
      "            abbv",
      "    r       abbv",
      "   sdeeeeeedabbv",
      "    etttttttabbv",
      "    euttttttabbv",
      "    etttttttabbv",
      "    etttttttallv",
      "    etttttttaoov",
      "    etttttttaqqv",
      "    ettttttta  v"
    ]
  ]
}