{
  "name": "multi_nuclearpowerplant_44_base4",
  "refpalette": "deceasedcraft:multi_nuclearpowerplant_44/multi_nuclearpowerplant_44_base4_palette",
  "xsize": 16,
  "zsize": 16,
  "slices": [
    [
      " a   b    c=deev",
      " a  bb    c=deev",
      " a bb     c=deev",
      "fffb     c=gdeev",
      " a       c==deev",
      " a      c=  deev",
      " a     c=   deev",
      " a   cc=    deev",
      "hhhcc==     deev",
      "iii==       deev",
      " a          deev",
      " a          deev",
      " a          deev",
      " a          deev",
      " a          deev",
      " a          deev"
    ],
    [
      "     b    c=deev",
      "    bb    c=deev",
      "   bb     c=deev",
      "bbbb     c=gdeev",
      "         c==deev",
      "        c=  deev",
      "       c=   deev",
      "     cc=    deev",
      "ccccc==     deev",
      "=====       deev",
      "            deev",
      "            deev",
      "            deev",
      "            deev",
      "            deev",
      "            deev"
    ],
    [
      "     b    c=deev",
      "    bb    c=deev",
      "   bb     c=deev",
      "bbbb     c=gdeev",
      "         c==deev",
      "        c=  deev",
      "       c=   deev",
      "     cc=    deev",
      "ccccc==     deev",
      "=====       deev",
      "            deev",
      "            deev",
      "            deev",
      "            deev",
      "            deev",
      "            deev"
    ],
    [
      "     b    c=deev",
      "    bb    c=deev",
      "   bb     c=deev",
      "bbbb     c=gdeev",
      "         c==deev",
      "        c=  deev",
      "       c=   deev",
      "     cc=    deev",
      "ccccc==     deev",
      "=====       deev",
      "            deev",
      "            deev",
      "            deev",
      "            deev",
      "            deev",
      "            deev"
    ],
    [
      "     b    c=deev",
      "    bb    c=deev",
      "   bb     c=deev",
      "bbbb     c=gdeev",
      "         c==deev",
      "        c=  deev",
      "       c=   deev",
      "     cc=    deev",
      "ccccc==     deev",
      "=====       deev",
      "            deev",
      "jjjj        deev",
      "            deev",
      "            deev",
      "            deev",
      "            deev"
    ],
    [
      "     k    c=deev",
      "    kk    c=deev",
      "   kk     c=deev",
      "kkkk     c=gdeev",
      "         c==deev",
      "        c=  deev",
      "       c=   deev",
      "     cc=    deev",
      "ccccc==     deev",
      "=====       deev",
      "            deev",
      "l l         deev",
      "            deev",
      "            deev",
      "            deev",
      "            deev"
    ]
  ]
}