{
  "name": "multi_nuclearpowerplant_44_base3",
  "refpalette": "deceasedcraft:multi_nuclearpowerplant_44/multi_nuclearpowerplant_44_base3_palette",
  "xsize": 16,
  "zsize": 16,
  "slices": [
    [
      "       aaab=cddv",
      "       aaab=cddv",
      "       aaabecddv",
      "      aaabefcddv",
      "     aaaabegcddv",
      "aaaaaaaabeggcddv",
      "aaaaaaabegggcddv",
      "aaaaabbeggggcddv",
      "bbbbb==eggggcddv",
      "=====hheggggcddv",
      "hhhhhhheggggcddv",
      "hhhhhhheggggcddv",
      "hhhhhhheggggcddv",
      "hhhhhhheggggcddv",
      "hhhhhhheggggcddv",
      "hhhhhhheggggcddv"
    ],
    [
      "       i  j=kddv",
      "       i  j=kddv",
      "       i  j=kddv",
      "      l  j=fkddv",
      "     l   j==kddv",
      "mmmmm   j=n kddv",
      "       j=n  kddv",
      " o   jj=n   kddv",
      "jpjjj===n qqkddv",
      "=r===jj=n stkddv",
      "jjjjjjj=n uwkddv",
      "jjjjjjj=n xykddv",
      "jjjjjjj=n qqkddv",
      "jjjjjjj=n stkddv",
      "jjjjjjj=n uwkddv",
      "jjjjjjj=n xykddv"
    ],
    [
      "          j=kddv",
      "          j=kddv",
      "          j=kddv",
      "         j=fkddv",
      "         j==kddv",
      "        j=n kddv",
      "       j=n  kddv",
      "     jj=n   kddv",
      "j jjj===n qqkddv",
      "= ===Aj=n Btkddv",
      "CDCCCEj=n uwkddv",
      "      j=n xykddv",
      "   FI J=n qqkddv",
      "   KILJ=n Btkddv",
      "   KI J=n uwkddv",
      "M  CI !=n xykddv"
    ],
    [
      "          j=kddv",
      "          j=kddv",
      "          j=kddv",
      "         j=fkddv",
      "         j==kddv",
      "        j=n kddv",
      "       j=n  kddv",
      "     jj=n   kddv",
      "j jjj===n qqkddv",
      "= ===Nj=n OPkddv",
      "CQCCCEj=n uwkddv",
      "      j=n xykddv",
      "   F   =n qqkddv",
      "   R  S=n OPkddv",
      "   R   =n uwkddv",
      "   C   =n xykddv"
    ],
    [
      "          j=kddv",
      "          j=kddv",
      "          j=kddv",
      "         j=fkddv",
      "         j==kddv",
      "        j=n kddv",
      "       j=n  kddv",
      "     jj=n   kddv",
      "jTjjj===n qqkddv",
      "=!===Nj=n uukddv",
      "CUCCCEj=n ufkddv",
      "   V  j=n xxkddv",
      "   F  W=n qqkddv",
      "   X  W=n uukddv",
      "   X  W=n ufkddv",
      "   C  W=n xxkddv"
    ],
    [
      "          j=kddv",
      "          j=kddv",
      "          j=kddv",
      "         j=fkddv",
      "         j==kddv",
      "        j=n kddv",
      "       j=n  kddv",
      "     jj=n   kddv",
      "jjjjj===n   kddv",
      "=====fj=n   kddv",
      "CCCjCEj=n  fkddv",
      "   j  j=n   kddv",
      "   j  j=n   kddv",
      "   j  j=n   kddv",
      "   j  j=n  fkddv",
      "   j  j=n   kddv"
    ]
  ]
}