{
  "name": "multi_nuclearpowerplant_44_base1",
  "refpalette": "deceasedcraft:multi_nuclearpowerplant_44/multi_nuclearpowerplant_44_base1_palette",
  "xsize": 16,
  "zsize": 16,
  "slices": [
    [
      "=========aaabccv",
      "=========aaabccv",
      "========aaddbccv",
      "========aadebccv",
      "=======aadd=bccv",
      "======aaad==bccv",
      "====aaaad=f bccv",
      "aaaaaadd=f  bccv",
      "ddddddddf ggbccv",
      "!hijkjidf lmbccv",
      "nnoopoqdf rsbccv",
      "tttttttdf u bccv",
      "w x    df ggbccv",
      "y      df ABbccv",
      " CDDE  df rsbccv",
      "   F   df uIbccv"
    ],
    [
      "aaaaaaaaaaaabccv",
      "aaaaaaaaaaaabccv",
      "aaaaaaaaaaddbccv",
      "aaaaaaaaaadebccv",
      "aaaaaaaaadd=bccv",
      "aaaaaaaaad==bccv",
      "aaaaaaaad=f bccv",
      "aaaaaadd=f  bccv",
      "ddddddddf ggbccv",
      "JKiLMLidf rrbccv",
      "N OP  Qdf rebccv",
      "       df uubccv",
      "      Rdf ggbccv",
      "       df rrbccv",
      " STU  Vdf rebccv",
      "       df uubccv"
    ],
    [
      "aaaaaaaaaaaabccv",
      "aaaaaaaaaaaabccv",
      "aaaaaaaaaaddbccv",
      "aaaaaaaaaadebccv",
      "aaaaaaaaadd=bccv",
      "aaaaaaaaad==bccv",
      "aaaaaaaad=f bccv",
      "aaaaaadd=f  bccv",
      "ddddddddf   bccv",
      "JWiXWYidf   bccv",
      "Z 0   1df  ebccv",
      "       df   bccv",
      "      Rdf   bccv",
      "       df   bccv",
      "       df  ebccv",
      "       df   bccv"
    ],
    [
      "aaaaaaaaaaaabccv",
      "aaaaaaaaaaaabccv",
      "aaaaaaaaaaddbccv",
      "aaaaaaaaaadebccv",
      "aaaaaaaaadd=bccv",
      "aaaaaaaaad==bccv",
      "aaaaaaaad=f bccv",
      "aaaaaadd=f  bccv",
      "ddddddddf   bccv",
      "iiiiiiidf   bccv",
      "2222222df  ebccv",
      "       df  ebccv",
      "       df  ebccv",
      "       df  ebccv",
      "       df  ebccv",
      "       df  ebccv"
    ],
    [
      "aaaaaaaaaaaabccv",
      "aaaaaaaaaaaabccv",
      "aaaaaaaaaaddbccv",
      "aaaaaaaaaadebccv",
      "aaaaaaaaaddabccv",
      "aaaaaaaaadaabccv",
      "aaaaaaaadaaabccv",
      "aaaaaaddaaaabccv",
      "ddddddddaaaabccv",
      "3333333daaaabccv",
      "4444444daaaabccv",
      "       daaaabccv",
      "       daaaabccv",
      "       daaaabccv",
      "       daaaabccv",
      "       daaaabccv"
    ],
    [
      "aaaaa5aaaaaabaav",
      "aaaaa55aaaaabaav",
      "aaaaaa5aaaaabaav",
      "aaaaaa55aaaebaav",
      "aaaaaaa5aaaabaav",
      "aaaaaaa55aaabaav",
      "aaaaaaaa5aaabaav",
      "aaaaaadd5aaabaav",
      "dddddddd55aabaav",
      "eeeeee6ee5aabaav",
      "7777777de5aabaav",
      "7777777de5aabaav",
      "7877877de55abaav",
      "7877877de 5abaav",
      "7877877de 5abaav",
      "7877877de 5abaav"
    ]
  ]
}