{
  "name": "multi_nuclearpowerplant_44_base2",
  "refpalette": "deceasedcraft:multi_nuclearpowerplant_44/multi_nuclearpowerplant_44_base2_palette",
  "xsize": 16,
  "zsize": 16,
  "slices": [
    [
      "          a=bccv",
      "          a=bccv",
      "          a=bccv",
      "         a=dbccv",
      "         a==bccv",
      "        a=e bccv",
      "       a=e  bccv",
      " f   aa=e   bccv",
      "aaaaa===e   bccv",
      "=====da=e   bccv",
      "gggagha=e  dbccv",
      "   a  a=e  dbccv",
      "   a  a=e  dbccv",
      "   a  a=e  dbccv",
      "   a  a=e  dbccv",
      "   a  a=e  dbccv"
    ],
    [
      "          a=bccv",
      "          a=bccv",
      "          a=bccv",
      "         a=dbccv",
      "         a==bccv",
      "        a=e bccv",
      "       a=e  bccv",
      "     aa=e   bccv",
      "aaaaa===e   bccv",
      "=====da=e   bccv",
      "gggagha=e   bccv",
      "iiia  a=e   bccv",
      "iiia  a=e   bccv",
      "iiia  a=e   bccv",
      "iiia  a=e   bccv",
      "iiia  a=e   bccv"
    ],
    [
      "          a=bccv",
      "          a=bccv",
      "          a=bccv",
      "         a=dbccv",
      "         a==bccv",
      "        a=e bccv",
      "       a=e  bccv",
      "     aa=e   bccv",
      "aaaaa===e   bccv",
      "=====da=e   bccv",
      "gggagha=e   bccv",
      "ddda  a=e   bccv",
      "ddda  a=e   bccv",
      "ddda  a=e   bccv",
      "ddda  a=e   bccv",
      "ddda  a=e   bccv"
    ],
    [
      "         ja=bccv",
      "         ja=bccv",
      "         a==bccv",
      "         a=dbccv",
      "        a==kbccv",
      "       aa=kkbccv",
      "      aa=kkkbccv",
      "llllaa==kkkkbccv",
      "aaaa====kkkkbccv",
      "=====da=kkkkbccv",
      "aaaaaaa=kkkkbccv",
      "aaaaaaa=kkkkbccv",
      "adaaaaa=kkkkbccv",
      "aaaaaaa=kkkkbccv",
      "aaaaaaa=kkkkbccv",
      "adaaaaa=kkkkbccv"
    ],
    [
      "        ma=kbccv",
      "        ma=kbccv",
      "       ma=nnbccv",
      "       ma=ndbccv",
      "      ma=nnobccv",
      "    mma==noobccv",
      "mmmmaa==nooobccv",
      "aaaa==nnoooobccv",
      "====nnnnoooobccv",
      "dddddddnoooobccv",
      " d    dnoooobccv",
      " d     noooobccv",
      " d     noooobccv",
      " d     noooobccv",
      " d     noooobccv",
      " d     noooobccv"
    ],
    [
      "aaaaaaaaa=kkbccv",
      "aaaaaaaaa=kkbccv",
      "aaaaaaaa=kppbccv",
      "aaaaaaaa=kpdbccv",
      "aaaaaaa=kpp=bccv",
      "aaaaaa=kkp==bccv",
      "aaaa==kkp=e bccv",
      "====kkpp=e qbccv",
      "pppppppperssbccv",
      "tttttttpe uwbccv",
      "ttttttxpeyABbccv",
      "tttttttpeCDEbccv",
      "tttttttpe ssbccv",
      "tttttttpe FIbccv",
      "tttttttpe A!bccv",
      "tttttttpe DEbccv"
    ]
  ]
}