{
  "name": "multi_nuclearpowerplant_44_ground",
  "refpalette": "deceasedcraft:multi_nuclearpowerplant_44/multi_nuclearpowerplant_44_ground_palette",
  "xsize": 16,
  "zsize": 16,
  "slices": [
    [
      "abbbbcdddddddzdz",
      "bbbbbccddddzdzzz",
      "bbbbbbcdddddddzz",
      "bbbbbbccdddddzdz",
      "bbbbbbbcddddddzz",
      "bbbbbbbccddddzdz",
      "bbbbbbbbcdddddzd",
      "bbbbbbbbcddddddz",
      "bbbbbbbbccdddddd",
      "bbbbbbbbbcddddzd",
      "bbbbbbbbbcdddddz",
      "bbbbbbbbbcdddddd",
      "bbbbbbbbbccddddz",
      "bbbbbbbbbbcddddz",
      "bbbbbbbbbbcddddd",
      "bbbbbbbbbbcddddz"
    ],
    [
      "  zzzze         ",
      "bzzfzzzg     h  ",
      "zzzzzdzi        ",
      "zzzzzzzzg       ",
      "bzzzzzzze       ",
      "zzzzzzzdzg     h",
      "zzzzzzzzze      ",
      "zzzzzzzdzi      ",
      "zzzzzdzzzzg     ",
      "zzzzzzzzzzg     ",
      "zzzzzzzzzze     ",
      "zzzzzzzdzze     ",
      "zzzzzzzzdzzg    ",
      "zzzzzzdzdzzg    ",
      "zzzzzzzzzzze    ",
      "zzzzzzzzzdde    "
    ],
    [
      "  b  j          ",
      "     jj         ",
      "f     j         ",
      "    b jj        ",
      "       j        ",
      "       jj       ",
      "        j       ",
      "        j       ",
      " f      jj      ",
      "        hj      ",
      "     h   j      ",
      "    h    j      ",
      "         jj     ",
      "         hj     ",
      "   hh     j     ",
      "       h  j     "
    ],
    [
      "     j          ",
      "     jj         ",
      "      j         ",
      "      jj        ",
      "       j        ",
      "       jj       ",
      "        j       ",
      "        j       ",
      "        jj      ",
      "         j      ",
      "         j      ",
      "         j      ",
      "         jj     ",
      "          j     ",
      "          j     ",
      "          j     "
    ],
    [
      "                ",
      "      k         ",
      "                ",
      "       l        ",
      "       l        ",
      "        l       ",
      "        l       ",
      "        l       ",
      "         l      ",
      "         l      ",
      "         l      ",
      "         l      ",
      "          l     ",
      "          l     ",
      "          l     ",
      "          l     "
    ],
    [
      "                ",
      "                ",
      "                ",
      "                ",
      "                ",
      "                ",
      "                ",
      "                ",
      "                ",
      "                ",
      "                ",
      "                ",
      "                ",
      "                ",
      "                ",
      "                "
    ]
  ]
}