{
  "name": "multi_nuclearpowerplant_44_base10",
  "refpalette": "deceasedcraft:multi_nuclearpowerplant_44/multi_nuclearpowerplant_44_base10_palette",
  "xsize": 16,
  "zsize": 16,
  "slices": [
    [
      "   abcccccccdeev",
      "   abcccccccdeev",
      "   abcccccccdeev",
      "   abcccccccdeev",
      "   abcccccccdeev",
      "   abcccccccdeev",
      "   abcccccccdeev",
      "   abcccccccdeev",
      "   abcccccccdeev",
      "   abcccccccdeev",
      "   abcccccccdeev",
      "   abcccccccdeev",
      "   abcccccccdeev",
      "   abcccccccdeev",
      "   abcccccccdeev",
      "   abcccccccdeev"
    ],
    [
      "    f    g hieev",
      "    f  j   hieev",
      "    f      hieev",
      "    f      hieev",
      "    f      hieev",
      "    f      hieev",
      "    f      hieev",
      "    f      hieev",
      "    kllmnllkieev",
      "    o       ieev",
      "    o    p qieev",
      "    o    p qieev",
      "    o    p qieev",
      "    o       ieev",
      "    o    p qieev",
      "    o    p qieev"
    ],
    [
      "          rsieev",
      "          rtieev",
      "          rtieev",
      "          rtieev",
      "          r ieev",
      "          ruieev",
      "          rtieev",
      "          wxieev",
      "    kllyAllkieev",
      "    o B  B Cieev",
      "    o       ieev",
      "    o       ieev",
      "    o       ieev",
      "    o      Cieev",
      "    o      Dieev",
      "    o       ieev"
    ],
    [
      "            ieev",
      "            ieev",
      "            ieev",
      "            ieev",
      "            ieev",
      "            ieev",
      "            ieev",
      "          w ieev",
      "    kllEEllkieev",
      "    o       ieev",
      "    o       ieev",
      "    o      Fieev",
      "    o      Iieev",
      "    o       ieev",
      "    o      Jieev",
      "    o      Jieev"
    ],
    [
      "           hieev",
      "           hieev",
      "           hieev",
      "           hieev",
      "           hieev",
      "           hieev",
      "           hieev",
      "           hieev",
      "    kllllllkieev",
      "    o       ieev",
      "    o       ieev",
      "    o       ieev",
      "    o       ieev",
      "    o       ieev",
      "    o       ieev",
      "    o       ieev"
    ],
    [
      "          rtieev",
      "          rtieev",
      "          r ieev",
      "          rKieev",
      "          r ieev",
      "          ruieev",
      "          r!ieev",
      "          wxieev",
      "    kllllllkieev",
      "    o       ieev",
      "    o       ieev",
      "    o       ieev",
      "    o       ieev",
      "    o       ieev",
      "    o       ieev",
      "    o       ieev"
    ]
  ]
}