{
  "name": "multi_nuclearpowerplant_44_base8",
  "refpalette": "deceasedcraft:multi_nuclearpowerplant_44/multi_nuclearpowerplant_44_base8_palette",
  "xsize": 16,
  "zsize": 16,
  "slices": [
    [
      "            abbv",
      "            abbv",
      "            abbv",
      "            abbv",
      "            abbv",
      "            abbv",
      "            abbv",
      "            abbv",
      "    cddddddcabbv",
      "    d       abbv",
      "    deeeeeeeabbv",
      "    de      affv",
      "    de      aggv",
      "    de      ahhv",
      "    de      a  v",
      "    de      a  v"
    ],
    [
      "ffffffffffffibbv",
      "ffffffffffffibbv",
      "ffffffffffffibbv",
      "ffffffffffffibbv",
      "ffffffffffffibbv",
      "ffffffffffffibbv",
      "ffffffffffffibbv",
      "ffffffffffffibbv",
      "fffffffffffjibbv",
      "ffffffffffffibbv",
      "fffffffffffeiffv",
      "ffffffffffffiggv",
      "ffffffffffffihhv",
      "ffffffffffffi  v",
      "ffffffffffffi  v",
      "ffffffffffffi  v"
    ],
    [
      "bbbbbbbbbbbbabbv",
      "bbbbbbbbbbbbabbv",
      "bbbbbbbbbbbbabbv",
      "bbbbbbbbbbbbabbv",
      "bbbbbbbbbbbbabbv",
      "bbbbbbbbbbbbaffv",
      "bbbbbbbbbbbbaffv",
      "bbbbbbbbbbbbaffv",
      "bbbbbbbbbbbbaffv",
      "bbbbbbbbbbffaffv",
      "bbbbbbbbbbfeaggv",
      "bbbbbbbbbbffahhv",
      "bbbbbbbbbbbba  v",
      "bbbbbbbbbbbba  v",
      "bbbbbbbbbbbba  v",
      "bbbbbbbbbbbba  v"
    ],
    [
      "bbbbbbbbbbbbabbv",
      "bbbbbbbbbbbbabbv",
      "bbbbbbbbbbbbabbv",
      "bbbbbbbbbbbbabbv",
      "bbbbbbbbbbbbabbv",
      "bbbbbbbbbbbbaffv",
      "bbbbbbbbbbbbakkv",
      "bbbbbbbbbbbbaffv",
      "bbbbbbbbbbbbaffv",
      "bbbbbbbbbbffaggv",
      "bbbbbbbbbbfeahhv",
      "bbbbbbbbbbffa  v",
      "bbbbbbbbbbbba  v",
      "bbbbbbbbbbbba  v",
      "bbbbbbbbbbbba  v",
      "bbbbbbbbbbbba  v"
    ],
    [
      "===========gabbv",
      "===========gabbv",
      "===========gabbv",
      "==========giabbv",
      "==========giabbv",
      "=========giiaffv",
      "========giiiallv",
      "=======giiiiiggv",
      "=====ggiiiiiiggv",
      "gggggiiiiiiiahhv",
      "iiiiiiiiiiiea  v",
      "mmmmmiiiiiiia  v",
      "nnnnmiiiiiiia  v",
      "fffnmiiiiiiia  v",
      "fffnmiiiiiiia  v",
      "fffnmiiiiiiia  v"
    ],
    [
      "jjjjjjjjjjj=abbv",
      "jjjjjjjjjjj=abbv",
      "jjjjjjjjjjj=abbv",
      "jjjjjjjjjj=oabbv",
      "jjjjjjjjjj=pabbv",
      "jjjjjjjjj=  affv",
      "jjjjjjjj=   a  v",
      "jjjjjjj=   qr  v",
      "jjjjj==    st  v",
      "=====       a  v",
      " uw        ea  v",
      " xy         a  v",
      "            a  v",
      "AAA         a  v",
      "A A         a  v",
      "AAA         a  v"
    ]
  ]
}