{
  "name": "multi_nuclearpowerplant_44_base5",
  "refpalette": "deceasedcraft:multi_nuclearpowerplant_44/multi_nuclearpowerplant_44_base5_palette",
  "xsize": 16,
  "zsize": 16,
  "slices": [
    [
      " a   b    c=deev",
      " a  bb    c=deev",
      " a bb     c=deev",
      "fffb     c=gdeev",
      " a       c==deev",
      " a      c=  deev",
      " a     c=   deev",
      " a   cc=    deev",
      "hhhcc==     deev",
      "iii==       deev",
      " a          deev",
      " a          deev",
      " a          deev",
      "jjj         deev",
      "k k         deev",
      "jjj         deev"
    ],
    [
      "l m  b    c=deev",
      "l m bb    c=deev",
      "l mbb     c=deev",
      "f fb     c=gdeev",
      "l m      c==deev",
      "l m     c=  deev",
      "l m    c=   deev",
      "l m  cc=    deev",
      "h hcc==     deev",
      "i i==       deev",
      "l m         deev",
      "l m         deev",
      "l m         deev",
      "j j         deev",
      "knk         deev",
      "jjj         deev"
    ],
    [
      " o   b    c=deev",
      " o  bb    c=deev",
      " o bb     c=deev",
      "fffb     c=gdeev",
      " o       c==deev",
      " o      c=  deev",
      " o     c=   deev",
      " o   cc=    deev",
      "hhhcc==     deev",
      "iii==       deev",
      " o          deev",
      " o          deev",
      " o          deev",
      "jjj         deev",
      "jpj         deev",
      "jjj         deev"
    ],
    [
      "     b    c=deev",
      "    bb    c=deev",
      "   bb     c=deev",
      "bbbb     c=gdeev",
      "         c==deev",
      "        c=  deev",
      "       c=   deev",
      "     cc=    deev",
      "ccccc==     deev",
      "=====       deev",
      "            deev",
      "            deev",
      "            deev",
      "qqq         deev",
      "qrq         deev",
      "qqq         deev"
    ],
    [
      " a   b    c=deev",
      " a  bb    c=deev",
      " a bb     c=deev",
      "fffb     c=gdeev",
      " a       c==deev",
      " a      c=  deev",
      " a     c=   deev",
      " a   cc=    deev",
      "hhhcc==     deev",
      "iii==       deev",
      " a          deev",
      " a          deev",
      " a          deev",
      " a          deev",
      " a          deev",
      " a          deev"
    ],
    [
      "l m  b    c=deev",
      "l m bb    c=deev",
      "l mbb     c=deev",
      "f fb     c=gdeev",
      "l m      c==deev",
      "l m     c=  deev",
      "l m    c=   deev",
      "l m  cc=    deev",
      "h hcc==     deev",
      "i i==       deev",
      "l m         deev",
      "l m         deev",
      "l m         deev",
      "l m         deev",
      "l m         deev",
      "l m         deev"
    ]
  ]
}