{
  "name": "multi_nuclearpowerplant_44_base12",
  "refpalette": "deceasedcraft:multi_nuclearpowerplant_44/multi_nuclearpowerplant_44_base12_palette",
  "xsize": 16,
  "zsize": 16,
  "slices": [
    [
      "aaaaaaaaaaaaaaav",
      "aaaaaaaaaaaaaaav",
      "aaaaaaaaaaaaaaav",
      "aaaaaaaaaaaaaaav",
      "aaaaaaaaaaaaaaav",
      "aaaaaaaaaaaaaaav",
      "aaaaaaaaaaaaaaav",
      "aaaaaaaaaaaaaaav",
      "aaaaaaaaaaaaaaav",
      "aaaaaaaaaaaaaaav",
      "aaaaaaaaaaaaaaav",
      "aaaaaaaaaaaaaaav",
      "aaaaaaaaaaaaaaav",
      "aaaaaaaaaaaaaaav",
      "aaaaaaaaaaaaaaav",
      "aaaaaaaaaaaaaaav"
    ],
    [
      "bbbbbbbbbbbbbaav",
      "bbbbbbbbbbbbbaav",
      "bbbbbbbbbbbbbaav",
      "bbbbbbbbbbbbbaav",
      "bbbbbbbbbbbbbaav",
      "bbbbbbbbbbbbbaav",
      "bbbbbbbbbbbbbaav",
      "bbbbbbbbbbbbbaav",
      "bbbbbbbbbbbbbaav",
      "bbbbbbbbbbbbbaav",
      "bbbbbbbbbbbbbaav",
      "bbbbbbbbbbbbbaav",
      "bbbbbbbbbbbbbaav",
      "bbbbbbbbbbbbbaav",
      "bbbbbbbbbbbbbaav",
      "bbbbbbbbbbbbbaav"
    ],
    [
      "============caav",
      "============caav",
      "============caav",
      "============caav",
      "============caav",
      "============caav",
      "============caav",
      "============caav",
      "============caav",
      "============caav",
      "============caav",
      "============caav",
      "============caav",
      "============caav",
      "============caav",
      "============caav"
    ],
    [
      "dddb========eaav",
      "dddb========eaav",
      "dddb========eaav",
      "dddb========eaav",
      "dddb========eaav",
      "dddb========eaav",
      "dddb========eaav",
      "dddb========eaav",
      "dddb========eaav",
      "dddb========eaav",
      "dddb========eaav",
      "dddb========eaav",
      "dddb========eaav",
      "dddb========eaav",
      "dddb========eaav",
      "dddb========eaav"
    ],
    [
      "ffgb========eaav",
      "gggb========eaav",
      "ffgb========eaav",
      "ffgb========eaav",
      "gggb========eaav",
      "ffgb========eaav",
      "ffgb========eaav",
      "gggb========eaav",
      "ffgb========eaav",
      "ffgb========eaav",
      "gggb========eaav",
      "ffgb========eaav",
      "ffgb========eaav",
      "gggb========eaav",
      "ffgb========eaav",
      "ffgb========eaav"
    ],
    [
      "higb========eaav",
      "gggb========eaav",
      "jigb========eaav",
      "khgb========eaav",
      "gggb========eaav",
      "kjgb========eaav",
      "higb========eaav",
      "gggb========eaav",
      "jigb========eaav",
      "khgb========eaav",
      "gggb========eaav",
      "kjgb========eaav",
      "higb========eaav",
      "gggb========eaav",
      "jigb========eaav",
      "khgb========eaav"
    ]
  ]
}