{
  "name": "multi_nuclearpowerplant_42_base8",
  "refpalette": "deceasedcraft:multi_nuclearpowerplant_42/multi_nuclearpowerplant_42_base8_palette",
  "xsize": 16,
  "zsize": 16,
  "slices": [
    [
      "vvvvvvvvvvvvvvvv",
      "aaaaaaaaaaaaaaav",
      "aaaaaaaaaaaaaaav",
      "aaaaaaaaaaaaaaav",
      "bbbaaaaaaaaaaaav",
      "   bbaaaaaaaaaav",
      "     baaaaaaaaav",
      "      baaaaaaaav",
      "      cbaaaaaaav",
      "        baaaaaav",
      "         baaaaav",
      "          baaaav",
      "          baaaav",
      "           baaav",
      "           baaav",
      "           baaav"
    ],
    [
      "vvvvvvvvvvvvvvvv",
      "aaaaaaaaaaaaaaav",
      "aaaaaaaaaaaaaaav",
      "aaaaaaaaaaaaaaav",
      "dddaaaaaaaaaaaav",
      "eeeddaaaaaaaaaav",
      "eeeeedaaaaaaaaav",
      "eeeeeedaaaaaaaav",
      "eeeeeefdaaaaaaav",
      "eeeeeeeedaaaaaav",
      "eeeeeeeeedaaaaav",
      "eeeeeeeeeedaaaav",
      "eeeeeeeeeedaaaav",
      "eeeeeeeeeeedaaav",
      "eeeeeeeeeeedaaav",
      "eeeeeeeeeeedaaav"
    ],
    [
      "vvvvvvvvvvvvvvvv",
      "aaaaaaaaaaaaaaav",
      "aaaaaaaaaaaaaaav",
      "aaaaaaaaaaaaaaav",
      "bbbaaaaaaaaaaaav",
      "aaabbaaaaaaaaaav",
      "aaaaabaaaaaaaaav",
      "aaaaaabaaaaaaaav",
      "aaaaaaabaaaaaaav",
      "aaaaaaaabaaaaaav",
      "aaaaaaaaabaaaaav",
      "aaaaaaaaaabaaaav",
      "aaaaaaaaaabaaaav",
      "aaaaaaaaaaabaaav",
      "aaaaaaaaaaabaaav",
      "aaaaaaaaaaabaaav"
    ],
    [
      "vvvvvvvvvvvvvvvv",
      "aaaaaaaaaaaaaaav",
      "aaaaaaaaaaaaaaav",
      "aaaaaaaaaaaaaaav",
      "bbbaaaaaaaaaaaav",
      "aaabbaaaaaaaaaav",
      "aaaaabaaaaaaaaav",
      "aaaaaabaaaaaaaav",
      "aaaaaaabaaaaaaav",
      "aaaaaaaabaaaaaav",
      "aaaaaaaaabaaaaav",
      "aaaaaaaaaabaaaav",
      "aaaaaaaaaabaaaav",
      "aaaaaaaaaaabaaav",
      "aaaaaaaaaaabaaav",
      "aaaaaaaaaaabaaav"
    ],
    [
      "vvvvvvvvvvvvvvvv",
      "aaaaaaaaaaaaaaav",
      "aaaaaaaaaaaaaaav",
      "aaaaaaaaaaaaaaav",
      "dddaaaaaaaaaaaav",
      "gggddaaaaaaaaaav",
      "===ggdaaaaaaaaav",
      "=====gdaaaaaaaav",
      "======gdaaaaaaav",
      "=======gdaaaaaav",
      "========gdaaaaav",
      "=========gdaaaav",
      "=========gdaaaav",
      "==========gdaaav",
      "==========gdaaav",
      "==========gdaaav"
    ],
    [
      "vvvvvvvvvvvvvvvv",
      "aaaaaaaaaaaaaaav",
      "aaaaaaaaaaaaaaav",
      "aaaaaaaaaaaaaaav",
      "bbbaaaaaaaaaaaav",
      "===bbaaaaaaaaaav",
      "fff==baaaaaaaaav",
      "fffff=baaaaaaaav",
      "ffffff=baaaaaaav",
      "fffffff=baaaaaav",
      "ffffffff=baaaaav",
      "fffffffff=baaaav",
      "fffffffff=baaaav",
      "ffffffffff=baaav",
      "ffffffffff=baaav",
      "ffffffffff=baaav"
    ]
  ]
}