{
  "name": "multi_nuclearpowerplant_42_base5",
  "refpalette": "deceasedcraft:multi_nuclearpowerplant_42/multi_nuclearpowerplant_42_base5_palette",
  "xsize": 16,
  "zsize": 16,
  "slices": [
    [
      "vvvvvvvvvvvvvvvv",
      "aaaaaaaaaaaaaaav",
      "aaaaaaaaaaaaaaav",
      "aaaaaaaaaaaaaaav",
      "bbbaaaaaaaaaaaav",
      "===bbaaaaaaaaaav",
      "ccc==baaaaaaaaav",
      "   cc=baaaaaaaav",
      "     c=baaaaaaav",
      "      c=baaaaaav",
      "       c=baaaaav",
      "dd      c=baaaav",
      " dd     c=baaaav",
      "  dd     c=baaav",
      "   dd    c=baaav",
      "e   d    c=baaav"
    ],
    [
      "vvvvvvvvvvvvvvvv",
      "aaaaaaaaaaaaaaav",
      "aaaaaaaaaaaaaaav",
      "aaaaaaaaaaaaaaav",
      "bbbaaaaaaaaaaaav",
      "===bbaaaaaaaaaav",
      "ccc==baaaaaaaaav",
      "   cc=baaaaaaaav",
      "     c=baaaaaaav",
      "      c=baaaaaav",
      "       c=baaaaav",
      "dd      c=baaaav",
      " dd     c=baaaav",
      "  dd     c=baaav",
      "   dd    c=baaav",
      "e   d    c=baaav"
    ],
    [
      "vvvvvvvvvvvvvvvv",
      "aaaaaaaaaaaaaaav",
      "aaaaaaaaaaaaaaav",
      "aaaaaaaaaaaaaaav",
      "bbbaaaaaaaaaaaav",
      "===bbaaaaaaaaaav",
      "ccc==baaaaaaaaav",
      "   cc=baaaaaaaav",
      "     c=baaaaaaav",
      "      c=baaaaaav",
      "       c=baaaaav",
      "dd      c=baaaav",
      " dd     c=baaaav",
      "  dd     c=baaav",
      "   dd    c=baaav",
      "e   d    c=baaav"
    ],
    [
      "vvvvvvvvvvvvvvvv",
      "aaaaaaaaaaaaaaav",
      "aaaaaaaaaaaaaaav",
      "aaaaaaaaaaaaaaav",
      "bbbaaaaaaaaaaaav",
      "===bbaaaaaaaaaav",
      "ccc==baaaaaaaaav",
      "   cc=baaaaaaaav",
      "     c=baaaaaaav",
      "      c=baaaaaav",
      "       c=baaaaav",
      "dd      c=baaaav",
      " dd     c=baaaav",
      "  dd     c=baaav",
      "   dd    c=baaav",
      "e   d    c=baaav"
    ],
    [
      "vvvvvvvvvvvvvvvv",
      "aaaaaaaaaaaaaaav",
      "aaaaaaaaaaaaaaav",
      "aaaaaaaaaaaaaaav",
      "bbbaaaaaaaaaaaav",
      "===bbaaaaaaaaaav",
      "ccc==baaaaaaaaav",
      "   cc=baaaaaaaav",
      "     c=baaaaaaav",
      "      c=baaaaaav",
      "       c=baaaaav",
      "dd      c=baaaav",
      " dd     c=baaaav",
      "  fd     c=baaav",
      "   dd    c=baaav",
      "e   d    c=baaav"
    ],
    [
      "vvvvvvvvvvvvvvvv",
      "aaaaaaaaaaaaaaav",
      "aaaaaaaaaaaaaaav",
      "aaaaaaaaaaaaaaav",
      "bbbaaaaaaaaaaaav",
      "===bbaaaaaaaaaav",
      "ccc==baaaaaaaaav",
      "   cc=baaaaaaaav",
      "     c=baaaaaaav",
      "      c=baaaaaav",
      "       c=baaaaav",
      "fd      c=baaaav",
      " dd     c=baaaav",
      "  dd     c=baaav",
      "   dd    c=baaav",
      "e   d    c=baaav"
    ]
  ]
}