{
  "name": "multi_nuclearpowerplant_42_base2",
  "refpalette": "deceasedcraft:multi_nuclearpowerplant_42/multi_nuclearpowerplant_42_base2_palette",
  "xsize": 16,
  "zsize": 16,
  "slices": [
    [
      "vvvvvvvvvvvvvvvv",
      "aaaaaaaaaaaaaaav",
      "aaaaaaaaaaaaaaav",
      "aaaaaaaaaaaaaaav",
      "bbbaaaaaaaaaaaav",
      "===bbaaaaaaaaaav",
      "ccc==baaaaaaaaav",
      "   cc=baaaaaaaav",
      "     c=baaaaaaav",
      "      c=baaaaaav",
      "       c=baaaaav",
      "        c=baaaav",
      "        c=baaaav",
      "         c=baaav",
      "         c=baaav",
      "         c=baaav"
    ],
    [
      "vvvvvvvvvvvvvvvv",
      "aaaaaaaaaaaaaaav",
      "aaaaaaaaaaaaaaav",
      "aaaaaaaaaaaaaaav",
      "bbbaaaaaaaaaaaav",
      "===bbaaaaaaaaaav",
      "ccc==baaaaaaaaav",
      "   cc=baaaaaaaav",
      "     c=baaaaaaav",
      "      c=baaaaaav",
      "       c=baaaaav",
      "        c=baaaav",
      "        c=baaaav",
      "         c=baaav",
      "         c=baaav",
      "         c=baaav"
    ],
    [
      "vvvvvvvvvvvvvvvv",
      "aaaaaaaaaaaaaaav",
      "aaaaaaaaaaaaaaav",
      "aaaaaaaaaaaaaaav",
      "bbbaaaaaaaaaaaav",
      "===bbaaaaaaaaaav",
      "ccc==baaaaaaaaav",
      "   cc=baaaaaaaav",
      "     c=baaaaaaav",
      "      c=baaaaaav",
      "       c=baaaaav",
      "        c=baaaav",
      "        c=baaaav",
      "         c=baaav",
      "d        c=baaav",
      "ed       c=baaav"
    ],
    [
      "vvvvvvvvvvvvvvvv",
      "aaaaaaaaaaaaaaav",
      "aaaaaaaaaaaaaaav",
      "aaaaaaaaaaaaaaav",
      "bbbaaaaaaaaaaaav",
      "===bbaaaaaaaaaav",
      "ccc==baaaaaaaaav",
      " ffc==baaaaaaaav",
      "    cc=baaaaaaav",
      "     cc=baaaaaav",
      "      cc=baaaaav",
      "       c==baaaav",
      "        c=baaaav",
      "        gc=baaav",
      "        gc=baaav",
      "         c=baaav"
    ],
    [
      "vvvvvvvvvvvvvvvv",
      "aaaaaaaaaaaaaaav",
      "aaaaaaaaaaaaaaav",
      "aaaaaaaaaaaaaaav",
      "bbbaaaaaaaaaaaav",
      "hhhbbaaaaaaaaaav",
      "===hhbaaaaaaaaav",
      "ccc=hhbaaaaaaaav",
      "iicc==hbaaaaaaav",
      "  iic==hbaaaaaav",
      "    ic==hbaaaaav",
      "     ic=hhbaaaav",
      "      ic=hbaaaav",
      "      icc=hbaaav",
      "       ic=hbaaav",
      "       ic=hbaaav"
    ],
    [
      "vvvvvvvvvvvvvvvv",
      "aaaaaaaaaaaaaaav",
      "aaaaaaaaaaaaaaav",
      "aaaaaaaaaaaaaaav",
      "bbbaaaaaaaaaaaav",
      "hhhbbaaaaaaaaaav",
      "hhhhhbaaaaaaaaav",
      "===hhhbaaaaaaaav",
      "cc==hhhbaaaaaaav",
      "cccc=hhhbaaaaaav",
      "ccccc=hhhbaaaaav",
      "cccccc=hhhbaaaav",
      "ccccccc=hhbaaaav",
      "ccccccc==hhbaaav",
      "cccccccc=hhbaaav",
      "jccccccc=hhbaaav"
    ]
  ]
}