{
  "name": "multi_nuclearpowerplant_42_base6",
  "refpalette": "deceasedcraft:multi_nuclearpowerplant_42/multi_nuclearpowerplant_42_base6_palette",
  "xsize": 16,
  "zsize": 16,
  "slices": [
    [
      "vvvvvvvvvvvvvvvv",
      "aaaaaaaaaaaaaaav",
      "aaaaaaaaaaaaaaav",
      "aaaaaaaaaaaaaaav",
      "bbbaaaaaaaaaaaav",
      "===bbaaaaaaaaaav",
      "ccc==baaaaaaaaav",
      "   cc=baaaaaaaav",
      "     c=baaaaaaav",
      "      c=baaaaaav",
      "       c=baaaaav",
      "dd      c=baaaav",
      " dd     c=baaaav",
      "  dd     c=baaav",
      "   dd    c=baaav",
      "e   d    c=baaav"
    ],
    [
      "vvvvvvvvvvvvvvvv",
      "aaaaaaaaaaaaaaav",
      "aaaaaaaaaaaaaaav",
      "aaaaaaaaaaaaaaav",
      "fffaaaaaaaaaaaav",
      "===ffaaaaaaaaaav",
      "ccc==faaaaaaaaav",
      "   cc=faaaaaaaav",
      "     c=faaaaaaav",
      "      c=faaaaaav",
      "       c=faaaaav",
      "dd      c=faaaav",
      " dd     c=faaaav",
      "  dd     c=faaav",
      "   dd    c=faaav",
      "e   d    c=faaav"
    ],
    [
      "vvvvvvvvvvvvvvvv",
      "aaaaaaaaaaaaaaav",
      "aaaaaaaaaaaaaaav",
      "aaaaaaaaaaaaaaav",
      "fffaaaaaaaaaaaav",
      "===ffaaaaaaaaaav",
      "ccc==faaaaaaaaav",
      "   cc=faaaaaaaav",
      "     c=faaaaaaav",
      "      c=faaaaaav",
      "       c=faaaaav",
      "dd      c=faaaav",
      " dd     c=faaaav",
      "  gd     c=faaav",
      "   dd    c=faaav",
      "e   d    c=faaav"
    ],
    [
      "vvvvvvvvvvvvvvvv",
      "aaaaaaaaaaaaaaav",
      "aaaaaaaaaaaaaaav",
      "aaaaaaaaaaaaaaav",
      "fffaaaaaaaaaaaav",
      "===ffaaaaaaaaaav",
      "ccc==faaaaaaaaav",
      "   cc=faaaaaaaav",
      "     c=faaaaaaav",
      "      c=faaaaaav",
      "       c=faaaaav",
      "dd      c=faaaav",
      " dd     c=faaaav",
      "  dd     c=faaav",
      "   dd    c=faaav",
      "e   d    c=faaav"
    ],
    [
      "vvvvvvvvvvvvvvvv",
      "aaaaaaaaaaaaaaav",
      "aaaaaaaaaaaaaaav",
      "aaaaaaaaaaaaaaav",
      "fffaaaaaaaaaaaav",
      "===ffaaaaaaaaaav",
      "ccc==faaaaaaaaav",
      "   cc=faaaaaaaav",
      "     c=faaaaaaav",
      "      c=faaaaaav",
      "       c=faaaaav",
      "dd      c=faaaav",
      " dd     c=faaaav",
      "  dd     c=faaav",
      "   dd    c=faaav",
      "e   d    c=faaav"
    ],
    [
      "vvvvvvvvvvvvvvvv",
      "aaaaaaaaaaaaaaav",
      "aaaaaaaaaaaaaaav",
      "aaaaaaaaaaaaaaav",
      "fffaaaaaaaaaaaav",
      "===ffaaaaaaaaaav",
      "ccc==faaaaaaaaav",
      "   cc=faaaaaaaav",
      "     c=faaaaaaav",
      "      c=faaaaaav",
      "       c=faaaaav",
      "dd      c=faaaav",
      " dd     c=faaaav",
      "  dd     c=faaav",
      "   dd    c=faaav",
      "h   d    c=faaav"
    ]
  ]
}