{
  "name": "multi_nuclearpowerplant_42_base12",
  "refpalette": "deceasedcraft:multi_nuclearpowerplant_42/multi_nuclearpowerplant_42_base12_palette",
  "xsize": 16,
  "zsize": 16,
  "slices": [
    [
      "vvvvvvvvvvvvvvvv",
      "aaaaaaaaaaaaaaav",
      "aaaaaaaaaaaaaaav",
      "aaaaaaaaaaaaaaav",
      "aaaaaaaaaaaaaaav",
      "aaaaaaaaaaaaaaav",
      "aaaaaaaaaaaaaaav",
      "aaaaaaaaaaaaaaav",
      "aaaaaaaaaaaaaaav",
      "aaaaaaaaaaaaaaav",
      "aaaaaaaaaaaaaaav",
      "aaaaaaaaaaaaaaav",
      "aaaaaaaaaaaaaaav",
      "aaaaaaaaaaaaaaav",
      "aaaaaaaaaaaaaaav",
      "aaaaaaaaaaaaaaav"
    ],
    [
      "vvvvvvvvvvvvvvvv",
      "aaaaaaaaaaaaaaav",
      "aaaaaaaaaaaaaaav",
      "aaaaaaaaaaaaaaav",
      "bbbaaaaaaaaaaaav",
      "bbbbbaaaaaaaaaav",
      "bbbbbbaaaaaaaaav",
      "bbbbbbbaaaaaaaav",
      "bbbbbbbbaaaaaaav",
      "bbbbbbbbbaaaaaav",
      "bbbbbbbbbbaaaaav",
      "bbbbbbbbbbbaaaav",
      "bbbbbbbbbbbaaaav",
      "bbbbbbbbbbbbaaav",
      "bbbbbbbbbbbbaaav",
      "bbbbbbbbbbbbaaav"
    ],
    [
      "vvvvvvvvvvvvvvvv",
      "aaaaaaaaaaaaaaav",
      "aaaaaaaaaaaaaaav",
      "aaaaaaaaaaaaaaav",
      "cccaaaaaaaaaaaav",
      "===ccaaaaaaaaaav",
      "=====caaaaaaaaav",
      "======caaaaaaaav",
      "=======caaaaaaav",
      "========caaaaaav",
      "=========caaaaav",
      "==========caaaav",
      "==========caaaav",
      "===========caaav",
      "===========caaav",
      "===========caaav"
    ],
    [
      "vvvvvvvvvvvvvvvv",
      "aaaaaaaaaaaaaaav",
      "aaaaaaaaaaaaaaav",
      "aaaaaaaaaaaaaaav",
      "dddaaaaaaaaaaaav",
      "===ddaaaaaaaaaav",
      "=====daaaaaaaaav",
      "======daaaaaaaav",
      "=======daaaaaaav",
      "========daaaaaav",
      "=========daaaaav",
      "==========daaaav",
      "==========daaaav",
      "===========daaav",
      "bb=========daaav",
      "eb=========daaav"
    ],
    [
      "vvvvvvvvvvvvvvvv",
      "aaaaaaaaaaaaaaav",
      "aaaaaaaaaaaaaaav",
      "aaaaaaaaaaaaaaav",
      "dddaaaaaaaaaaaav",
      "===ddaaaaaaaaaav",
      "=====daaaaaaaaav",
      "======daaaaaaaav",
      "=======daaaaaaav",
      "========daaaaaav",
      "=========daaaaav",
      "==========daaaav",
      "==========daaaav",
      "===========daaav",
      "bb=========daaav",
      "fb=========daaav"
    ],
    [
      "vvvvvvvvvvvvvvvv",
      "aaaaaaaaaaaaaaav",
      "aaaaaaaaaaaaaaav",
      "aaaaaaaaaaaaaaav",
      "dddaaaaaaaaaaaav",
      "===ddaaaaaaaaaav",
      "=====daaaaaaaaav",
      "======daaaaaaaav",
      "=======daaaaaaav",
      "========daaaaaav",
      "=========daaaaav",
      "==========daaaav",
      "==========daaaav",
      "===========daaav",
      "bb=========daaav",
      "fb=========daaav"
    ]
  ]
}