{
  "name": "multi_nuclearpowerplant_42_base1",
  "refpalette": "deceasedcraft:multi_nuclearpowerplant_42/multi_nuclearpowerplant_42_base1_palette",
  "xsize": 16,
  "zsize": 16,
  "slices": [
    [
      "vvvvvvvvvvvvvvvv",
      "aaaaaaaaaaaaaaav",
      "aaaaaaaaaaaaaaav",
      "aaaaaaaaaaaaaaav",
      "bbbaaaaaaaaaaaav",
      "cccbbaaaaaaaaaav",
      "cccccbaaaaaaaaav",
      "ccccccbaaaaaaaav",
      "==cccccbaaaaaaav",
      "====ccccbaaaaaav",
      "=====ccccbaaaaav",
      "======ccccbaaaav",
      "=======cccbaaaav",
      "=======ccccbaaav",
      "========cccbaaav",
      "d=======cccbaaav"
    ],
    [
      "vvvvvvvvvvvvvvvv",
      "aaaaaaaaaaaaaaav",
      "aaaaaaaaaaaaaaav",
      "aaaaaaaaaaaaaaav",
      "bbbaaaaaaaaaaaav",
      "cccbbaaaaaaaaaav",
      "cccccbaaaaaaaaav",
      "ccccccbaaaaaaaav",
      "cccccccbaaaaaaav",
      "ccccccccbaaaaaav",
      "cccccccccbaaaaav",
      "ccccccccccbaaaav",
      "ccccccccccbaaaav",
      "cccccccccccbaaav",
      "cccccccccccbaaav",
      "eccccccccccbaaav"
    ],
    [
      "vvvvvvvvvvvvvvvv",
      "aaaaaaaaaaaaaaav",
      "aaaaaaaaaaaaaaav",
      "aaaaaaaaaaaaaaav",
      "bbbaaaaaaaaaaaav",
      "cccbbaaaaaaaaaav",
      "cccccbaaaaaaaaav",
      "ccccccbaaaaaaaav",
      "cccccccbaaaaaaav",
      "ccccccccbaaaaaav",
      "cccccccccbaaaaav",
      "ccccccccccbaaaav",
      "ccccccccccbaaaav",
      "eccccccccccbaaav",
      "eecccccccccbaaav",
      "fecccccccccbaaav"
    ],
    [
      "vvvvvvvvvvvvvvvv",
      "aaaaaaaaaaaaaaav",
      "aaaaaaaaaaaaaaav",
      "aaaaaaaaaaaaaaav",
      "bbbaaaaaaaaaaaav",
      "cccbbaaaaaaaaaav",
      "cccccbaaaaaaaaav",
      "ccccccbaaaaaaaav",
      "cccccccbaaaaaaav",
      "ccccccccbaaaaaav",
      "cccccccccbaaaaav",
      "ccccccccccbaaaav",
      "ccccccccccbaaaav",
      "cccccccccccbaaav",
      "fecccccccccbaaav",
      "gfcccccccccbaaav"
    ],
    [
      "vvvvvvvvvvvvvvvv",
      "aaaaaaaaaaaaaaav",
      "aaaaaaaaaaaaaaav",
      "aaaaaaaaaaaaaaav",
      "bbbaaaaaaaaaaaav",
      "cccbbaaaaaaaaaav",
      "cccccbaaaaaaaaav",
      "ccccccbaaaaaaaav",
      "cccccccbaaaaaaav",
      "ccccccccbaaaaaav",
      "cccccccccbaaaaav",
      "ccccccccccbaaaav",
      "ccccccccccbaaaav",
      "cccccccccccbaaav",
      " hcccccccccbaaav",
      "  fccccccccbaaav"
    ],
    [
      "vvvvvvvvvvvvvvvv",
      "cccccccccccccccv",
      "cccccccccccccccv",
      "cccccccccccccccv",
      "bbbccccccccccccv",
      "cccbbccccccccccv",
      "cccccbcccccccccv",
      "ccccccbccccccccv",
      "cccccccbcccccccv",
      "ccccccccbccccccv",
      "cccccccccbcccccv",
      "ccccccccccbccccv",
      "zcccccccccbccccv",
      " fcccccccccbcccv",
      "  fccccccccbcccv",
      "   ccccccccbcccv"
    ]
  ]
}