{
  "name": "multi_nuclearpowerplant_42_base7",
  "refpalette": "deceasedcraft:multi_nuclearpowerplant_42/multi_nuclearpowerplant_42_base7_palette",
  "xsize": 16,
  "zsize": 16,
  "slices": [
    [
      "vvvvvvvvvvvvvvvv",
      "aaaaaaaaaaaaaaav",
      "aaaaaaaaaaaaaaav",
      "aaaaaaaaaaaaaaav",
      "bbbaaaaaaaaaaaav",
      "===bbaaaaaaaaaav",
      "ccc==baaaaaaaaav",
      "   cc=baaaaaaaav",
      "d   ec=baaaaaaav",
      "f     c=baaaaaav",
      "       c=baaaaav",
      "gg      c=baaaav",
      "hgg     c=baaaav",
      "hhgg     c=baaav",
      "hhhgg    c=baaav",
      " hhhg    c=baaav"
    ],
    [
      "vvvvvvvvvvvvvvvv",
      "aaaaaaaaaaaaaaav",
      "aaaaaaaaaaaaaaav",
      "aaaaaaaaaaaaaaav",
      "bbbaaaaaaaaaaaav",
      "===bbaaaaaaaaaav",
      "ccc==baaaaaaaaav",
      "   cc=baaaaaaaav",
      "     c=baaaaaaav",
      "      c=baaaaaav",
      "       c=baaaaav",
      "gg      c=baaaav",
      "ijg     c=baaaav",
      "iigg     c=baaav",
      "ihhgj    c=baaav",
      "@hiij    c=baaav"
    ],
    [
      "vvvvvvvvvvvvvvvv",
      "aaaaaaaaaaaaaaav",
      "aaaaaaaaaaaaaaav",
      "aaaaaaaaaaaaaaav",
      "bbbaaaaaaaaaaaav",
      "===bbaaaaaaaaaav",
      "ccc==baaaaaaaaav",
      "   cc=baaaaaaaav",
      "     c=baaaaaaav",
      "      c=baaaaaav",
      "       c=baaaaav",
      "gg      c=baaaav",
      " jg     c=baaaav",
      "  jg     c=baaav",
      "   jg    c=baaav",
      "k   j    c=baaav"
    ],
    [
      "vvvvvvvvvvvvvvvv",
      "aaaaaaaaaaaaaaav",
      "aaaaaaaaaaaaaaav",
      "aaaaaaaaaaaaaaav",
      "bbbaaaaaaaaaaaav",
      "===bbaaaaaaaaaav",
      "ccc==baaaaaaaaav",
      "   cc=baaaaaaaav",
      "     c=baaaaaaav",
      "      c=baaaaaav",
      "       c=baaaaav",
      "gg      c=baaaav",
      " jg     c=baaaav",
      "  jg     c=baaav",
      "   gg    c=baaav",
      "k   j    c=baaav"
    ],
    [
      "vvvvvvvvvvvvvvvv",
      "aaaaaaaaaaaaaaav",
      "aaaaaaaaaaaaaaav",
      "aaaaaaaaaaaaaaav",
      "bbbaaaaaaaaaaaav",
      "===bbaaaaaaaaaav",
      "ccc==baaaaaaaaav",
      "   cc=baaaaaaaav",
      "     c=baaaaaaav",
      "      c=baaaaaav",
      "       c=baaaaav",
      "gg      c=baaaav",
      " jg     c=baaaav",
      "  gg     c=baaav",
      "   gg    c=baaav",
      "k   g    c=baaav"
    ],
    [
      "vvvvvvvvvvvvvvvv",
      "aaaaaaaaaaaaaaav",
      "aaaaaaaaaaaaaaav",
      "aaaaaaaaaaaaaaav",
      "bbbaaaaaaaaaaaav",
      "===bbaaaaaaaaaav",
      "ccc==baaaaaaaaav",
      "   cc=baaaaaaaav",
      "     c=baaaaaaav",
      "      c=baaaaaav",
      "       c=baaaaav",
      "gg      c=baaaav",
      " gg     c=baaaav",
      "  gg     c=baaav",
      "   gg    c=baaav",
      "k   g    c=baaav"
    ]
  ]
}