{
  "name": "multi_nuclearpowerplant_42_base4",
  "refpalette": "deceasedcraft:multi_nuclearpowerplant_42/multi_nuclearpowerplant_42_base4_palette",
  "xsize": 16,
  "zsize": 16,
  "slices": [
    [
      "vvvvvvvvvvvvvvvv",
      "aaaaaaaaaaaaaaav",
      "aaaaaaaaaaaaaaav",
      "aaaaaaaaaaaaaaav",
      "bbbaaaaaaaaaaaav",
      "===bbaaaaaaaaaav",
      "ccc==baaaaaaaaav",
      "   cc=baaaaaaaav",
      "     c=baaaaaaav",
      "      c=baaaaaav",
      "       c=baaaaav",
      "dd      c=baaaav",
      " dd     c=baaaav",
      "  ed     c=baaav",
      "   dd    c=baaav",
      "f   d    c=baaav"
    ],
    [
      "vvvvvvvvvvvvvvvv",
      "aaaaaaaaaaaaaaav",
      "aaaaaaaaaaaaaaav",
      "aaaaaaaaaaaaaaav",
      "bbbaaaaaaaaaaaav",
      "===bbaaaaaaaaaav",
      "ccc==baaaaaaaaav",
      "   cc=baaaaaaaav",
      "     c=baaaaaaav",
      "      c=baaaaaav",
      "       c=baaaaav",
      "dd      c=baaaav",
      " dd     c=baaaav",
      "  ed     c=baaav",
      "   dd    c=baaav",
      "f   d    c=baaav"
    ],
    [
      "vvvvvvvvvvvvvvvv",
      "aaaaaaaaaaaaaaav",
      "aaaaaaaaaaaaaaav",
      "aaaaaaaaaaaaaaav",
      "bbbaaaaaaaaaaaav",
      "===bbaaaaaaaaaav",
      "ccc==baaaaaaaaav",
      "   cc=baaaaaaaav",
      "     c=baaaaaaav",
      "      c=baaaaaav",
      "       c=baaaaav",
      "dd      c=baaaav",
      " dd     c=baaaav",
      "  ed     c=baaav",
      "   ed    c=baaav",
      "    d    c=baaav"
    ],
    [
      "vvvvvvvvvvvvvvvv",
      "aaaaaaaaaaaaaaav",
      "aaaaaaaaaaaaaaav",
      "aaaaaaaaaaaaaaav",
      "bbbaaaaaaaaaaaav",
      "===bbaaaaaaaaaav",
      "ccc==baaaaaaaaav",
      "   cc=baaaaaaaav",
      "     c=baaaaaaav",
      "      c=baaaaaav",
      "       c=baaaaav",
      "dd      c=baaaav",
      " ee     c=baaaav",
      "  gd     c=baaav",
      "   ee    c=baaav",
      "    d    c=baaav"
    ],
    [
      "vvvvvvvvvvvvvvvv",
      "aaaaaaaaaaaaaaav",
      "aaaaaaaaaaaaaaav",
      "aaaaaaaaaaaaaaav",
      "bbbaaaaaaaaaaaav",
      "===bbaaaaaaaaaav",
      "ccc==baaaaaaaaav",
      "   cc=baaaaaaaav",
      "     c=baaaaaaav",
      "      c=baaaaaav",
      "       c=baaaaav",
      "dd      c=baaaav",
      " ee     c=baaaav",
      "  gd     c=baaav",
      "   ed    c=baaav",
      "    d    c=baaav"
    ],
    [
      "vvvvvvvvvvvvvvvv",
      "aaaaaaaaaaaaaaav",
      "aaaaaaaaaaaaaaav",
      "aaaaaaaaaaaaaaav",
      "bbbaaaaaaaaaaaav",
      "===bbaaaaaaaaaav",
      "ccc==baaaaaaaaav",
      "   cc=baaaaaaaav",
      "     c=baaaaaaav",
      "      c=baaaaaav",
      "       c=baaaaav",
      "hh      c=baaaav",
      "        c=baaaav",
      "   h     c=baaav",
      "    h    c=baaav",
      "    h    c=baaav"
    ]
  ]
}