{
  "name": "multi_nuclearpowerplant_42_base3",
  "refpalette": "deceasedcraft:multi_nuclearpowerplant_42/multi_nuclearpowerplant_42_base3_palette",
  "xsize": 16,
  "zsize": 16,
  "slices": [
    [
      "vvvvvvvvvvvvvvvv",
      "aaaaaaaaaaaaaaav",
      "aaaaaaaaaaaaaaav",
      "aaaaaaaaaaaaaaav",
      "bbbaaaaaaaaaaaav",
      "===bbaaaaaaaaaav",
      "ccc==baaaaaaaaav",
      "dddcc=baaaaaaaav",
      "dddddc=baaaaaaav",
      " dddddc=baaaaaav",
      "   ddddc=baaaaav",
      "    ddddc=baaaav",
      "     dddc=baaaav",
      "      dddc=baaav",
      "      dddc=baaav",
      "       ddc=baaav"
    ],
    [
      "vvvvvvvvvvvvvvvv",
      "aaaaaaaaaaaaaaav",
      "aaaaaaaaaaaaaaav",
      "aaaaaaaaaaaaaaav",
      "eeeaaaaaaaaaaaav",
      "===eeaaaaaaaaaav",
      "fff==eaaaaaaaaav",
      "   ff=eaaaaaaaav",
      "g    f=eaaaaaaav",
      " hg   f=eaaaaaav",
      "   h   f=eaaaaav",
      "    h   f=eaaaav",
      "     h  f=eaaaav",
      "      i  f=eaaav",
      "      h  f=eaaav",
      "       i f=eaaav"
    ],
    [
      "vvvvvvvvvvvvvvvv",
      "aaaaaaaaaaaaaaav",
      "aaaaaaaaaaaaaaav",
      "aaaaaaaaaaaaaaav",
      "eeeaaaaaaaaaaaav",
      "===eeaaaaaaaaaav",
      "fff==eaaaaaaaaav",
      "   ff=eaaaaaaaav",
      "     f=eaaaaaaav",
      "      f=eaaaaaav",
      "       f=eaaaaav",
      "        f=eaaaav",
      "        f=eaaaav",
      "         f=eaaav",
      "         f=eaaav",
      "         f=eaaav"
    ],
    [
      "vvvvvvvvvvvvvvvv",
      "aaaaaaaaaaaaaaav",
      "aaaaaaaaaaaaaaav",
      "aaaaaaaaaaaaaaav",
      "eeeaaaaaaaaaaaav",
      "===eeaaaaaaaaaav",
      "fff==eaaaaaaaaav",
      "   ff=eaaaaaaaav",
      "     f=eaaaaaaav",
      "      f=eaaaaaav",
      "       f=eaaaaav",
      "        f=eaaaav",
      "        f=eaaaav",
      "         f=eaaav",
      "         f=eaaav",
      "         f=eaaav"
    ],
    [
      "vvvvvvvvvvvvvvvv",
      "aaaaaaaaaaaaaaav",
      "aaaaaaaaaaaaaaav",
      "aaaaaaaaaaaaaaav",
      "eeeaaaaaaaaaaaav",
      "===eeaaaaaaaaaav",
      "fff==eaaaaaaaaav",
      "   ff=eaaaaaaaav",
      "     f=eaaaaaaav",
      "      f=eaaaaaav",
      "       f=eaaaaav",
      "        f=eaaaav",
      "        f=eaaaav",
      "         f=eaaav",
      "         f=eaaav",
      "         f=eaaav"
    ],
    [
      "vvvvvvvvvvvvvvvv",
      "aaaaaaaaaaaaaaav",
      "aaaaaaaaaaaaaaav",
      "aaaaaaaaaaaaaaav",
      "eeeaaaaaaaaaaaav",
      "===eeaaaaaaaaaav",
      "fff==eaaaaaaaaav",
      "   ff=eaaaaaaaav",
      "     f=eaaaaaaav",
      "      f=eaaaaaav",
      "       f=eaaaaav",
      "        f=eaaaav",
      "        f=eaaaav",
      "         f=eaaav",
      "         f=eaaav",
      "         f=eaaav"
    ]
  ]
}