{
  "name": "multi_nuclearpowerplant_42_base11",
  "refpalette": "deceasedcraft:multi_nuclearpowerplant_42/multi_nuclearpowerplant_42_base11_palette",
  "xsize": 16,
  "zsize": 16,
  "slices": [
    [
      "vvvvvvvvvvvvvvvv",
      "aaaaaaaaaaaaaaav",
      "aaaaaaaaaaaaaaav",
      "aaaaaaaaaaaaaaav",
      "bbbaaaaaaaaaaaav",
      "===bbaaaaaaaaaav",
      "=====baaaaaaaaav",
      "======baaaaaaaav",
      "=======baaaaaaav",
      "========baaaaaav",
      "=========baaaaav",
      "==========baaaav",
      "==========baaaav",
      "===========baaav",
      "cc=========baaav",
      "dc=========baaav"
    ],
    [
      "vvvvvvvvvvvvvvvv",
      "aaaaaaaaaaaaaaav",
      "aaaaaaaaaaaaaaav",
      "aaaaaaaaaaaaaaav",
      "bbbaaaaaaaaaaaav",
      "===bbaaaaaaaaaav",
      "=====baaaaaaaaav",
      "======baaaaaaaav",
      "=======baaaaaaav",
      "========baaaaaav",
      "=========baaaaav",
      "==========baaaav",
      "==========baaaav",
      "===========baaav",
      "cc=========baaav",
      "dc=========baaav"
    ],
    [
      "vvvvvvvvvvvvvvvv",
      "aaaaaaaaaaaaaaav",
      "aaaaaaaaaaaaaaav",
      "aaaaaaaaaaaaaaav",
      "bbbaaaaaaaaaaaav",
      "===bbaaaaaaaaaav",
      "=====baaaaaaaaav",
      "======baaaaaaaav",
      "=======baaaaaaav",
      "========baaaaaav",
      "=========baaaaav",
      "==========baaaav",
      "==========baaaav",
      "===========baaav",
      "cc=========baaav",
      "dc=========baaav"
    ],
    [
      "vvvvvvvvvvvvvvvv",
      "aaaaaaaaaaaaaaav",
      "aaaaaaaaaaaaaaav",
      "aaaaaaaaaaaaaaav",
      "bbbaaaaaaaaaaaav",
      "===bbaaaaaaaaaav",
      "=====baaaaaaaaav",
      "======baaaaaaaav",
      "=======baaaaaaav",
      "========baaaaaav",
      "=========baaaaav",
      "==========baaaav",
      "==========baaaav",
      "===========baaav",
      "cc=========baaav",
      "dc=========baaav"
    ],
    [
      "vvvvvvvvvvvvvvvv",
      "aaaaaaaaaaaaaaav",
      "aaaaaaaaaaaaaaav",
      "aaaaaaaaaaaaaaav",
      "bbbaaaaaaaaaaaav",
      "===bbaaaaaaaaaav",
      "=====baaaaaaaaav",
      "======baaaaaaaav",
      "=======baaaaaaav",
      "========baaaaaav",
      "=========baaaaav",
      "==========baaaav",
      "==========baaaav",
      "===========baaav",
      "cc=========baaav",
      "dc=========baaav"
    ],
    [
      "vvvvvvvvvvvvvvvv",
      "aaaaaaaaaaaaaaav",
      "aaaaaaaaaaaaaaav",
      "aaaaaaaaaaaaaaav",
      "bbbaaaaaaaaaaaav",
      "===bbaaaaaaaaaav",
      "=====baaaaaaaaav",
      "======baaaaaaaav",
      "=======baaaaaaav",
      "========baaaaaav",
      "=========baaaaav",
      "==========baaaav",
      "==========baaaav",
      "===========baaav",
      "cc=========baaav",
      "dc=========baaav"
    ]
  ]
}