{
  "name": "multi_nuclearpowerplant_42_base10",
  "refpalette": "deceasedcraft:multi_nuclearpowerplant_42/multi_nuclearpowerplant_42_base10_palette",
  "xsize": 16,
  "zsize": 16,
  "slices": [
    [
      "vvvvvvvvvvvvvvvv",
      "aaaaaaaaaaaaaaav",
      "aaaaaaaaaaaaaaav",
      "aaaaaaaaaaaaaaav",
      "bbbaaaaaaaaaaaav",
      "cccbbaaaaaaaaaav",
      "cccccbaaaaaaaaav",
      "cccccdbaaaaaaaav",
      "cccccdebaaaaaaav",
      "cccccdddbaaaaaav",
      "cccccccccbaaaaav",
      "ccccccccccbaaaav",
      "fcccccccccbaaaav",
      "fffccccccccbaaav",
      "ggfccccccccbaaav",
      " gffcccccccbaaav"
    ],
    [
      "vvvvvvvvvvvvvvvv",
      "aaaaaaaaaaaaaaav",
      "aaaaaaaaaaaaaaav",
      "aaaaaaaaaaaaaaav",
      "hhhaaaaaaaaaaaav",
      "   hhaaaaaaaaaav",
      "     haaaaaaaaav",
      "      haaaaaaaav",
      "      ihaaaaaaav",
      "      j haaaaaav",
      "         haaaaav",
      "          haaaav",
      "          haaaav",
      "kl         haaav",
      "  m        haaav",
      "  k        haaav"
    ],
    [
      "vvvvvvvvvvvvvvvv",
      "aaaaaaaaaaaaaaav",
      "aaaaaaaaaaaaaaav",
      "aaaaaaaaaaaaaaav",
      "hhhaaaaaaaaaaaav",
      "   hhaaaaaaaaaav",
      "     haaaaaaaaav",
      "      haaaaaaaav",
      "      ihaaaaaaav",
      "        haaaaaav",
      "         haaaaav",
      "          haaaav",
      "          haaaav",
      "           haaav",
      "           haaav",
      "           haaav"
    ],
    [
      "vvvvvvvvvvvvvvvv",
      "aaaaaaaaaaaaaaav",
      "aaaaaaaaaaaaaaav",
      "aaaaaaaaaaaaaaav",
      "hhhaaaaaaaaaaaav",
      "   hhaaaaaaaaaav",
      "     haaaaaaaaav",
      "      haaaaaaaav",
      "      ihaaaaaaav",
      "        haaaaaav",
      "         haaaaav",
      "          haaaav",
      "          haaaav",
      "           haaav",
      "           haaav",
      "           haaav"
    ],
    [
      "vvvvvvvvvvvvvvvv",
      "aaaaaaaaaaaaaaav",
      "aaaaaaaaaaaaaaav",
      "aaaaaaaaaaaaaaav",
      "hhhaaaaaaaaaaaav",
      "   hhaaaaaaaaaav",
      "     haaaaaaaaav",
      "      haaaaaaaav",
      "      ihaaaaaaav",
      "        haaaaaav",
      "         haaaaav",
      "          haaaav",
      "          haaaav",
      "           haaav",
      "           haaav",
      "           haaav"
    ],
    [
      "vvvvvvvvvvvvvvvv",
      "aaaaaaaaaaaaaaav",
      "aaaaaaaaaaaaaaav",
      "aaaaaaaaaaaaaaav",
      "hhhaaaaaaaaaaaav",
      "   hhaaaaaaaaaav",
      "     haaaaaaaaav",
      "      haaaaaaaav",
      "      ihaaaaaaav",
      "        haaaaaav",
      "         haaaaav",
      "          haaaav",
      "          haaaav",
      "           haaav",
      "           haaav",
      "           haaav"
    ]
  ]
}