{
  "name": "multi_nuclearpowerplant_42_base9",
  "refpalette": "deceasedcraft:multi_nuclearpowerplant_42/multi_nuclearpowerplant_42_base9_palette",
  "xsize": 16,
  "zsize": 16,
  "slices": [
    [
      "vvvvvvvvvvvvvvvv",
      "aaaaaaaaaaaaaaav",
      "aaaaaaaaaaaaaaav",
      "aaaaaaaaaaaaaaav",
      "bbbaaaaaaaaaaaav",
      "   bbaaaaaaaaaav",
      "     baaaaaaaaav",
      "      baaaaaaaav",
      "      cbaaaaaaav",
      "        baaaaaav",
      "         baaaaav",
      "          baaaav",
      "          baaaav",
      "           baaav",
      "           baaav",
      "           baaav"
    ],
    [
      "vvvvvvvvvvvvvvvv",
      "aaaaaaaaaaaaaaav",
      "aaaaaaaaaaaaaaav",
      "aaaaaaaaaaaaaaav",
      "bbbaaaaaaaaaaaav",
      "   bbaaaaaaaaaav",
      "     baaaaaaaaav",
      "      baaaaaaaav",
      "      cbaaaaaaav",
      "        baaaaaav",
      "         baaaaav",
      "          baaaav",
      "          baaaav",
      "           baaav",
      "           baaav",
      "           baaav"
    ],
    [
      "vvvvvvvvvvvvvvvv",
      "aaaaaaaaaaaaaaav",
      "aaaaaaaaaaaaaaav",
      "aaaaaaaaaaaaaaav",
      "bbbaaaaaaaaaaaav",
      "   bbaaaaaaaaaav",
      "     baaaaaaaaav",
      "      baaaaaaaav",
      "      cbaaaaaaav",
      "        baaaaaav",
      "         baaaaav",
      "          baaaav",
      "          baaaav",
      "           baaav",
      "           baaav",
      "           baaav"
    ],
    [
      "vvvvvvvvvvvvvvvv",
      "aaaaaaaaaaaaaaav",
      "aaaaaaaaaaaaaaav",
      "aaaaaaaaaaaaaaav",
      "bbbaaaaaaaaaaaav",
      "   bbaaaaaaaaaav",
      "     baaaaaaaaav",
      "      baaaaaaaav",
      "      cbaaaaaaav",
      "        baaaaaav",
      "         baaaaav",
      "          baaaav",
      "          baaaav",
      "           baaav",
      "           baaav",
      "           baaav"
    ],
    [
      "vvvvvvvvvvvvvvvv",
      "aaaaaaaaaaaaaaav",
      "aaaaaaaaaaaaaaav",
      "aaaaaaaaaaaaaaav",
      "bbbaaaaaaaaaaaav",
      "   bbaaaaaaaaaav",
      "     baaaaaaaaav",
      "      baaaaaaaav",
      "cccccccbaaaaaaav",
      "    c   baaaaaav",
      "    c    baaaaav",
      "    c     baaaav",
      "    c     baaaav",
      "    c      baaav",
      "    c      baaav",
      "    c      baaav"
    ],
    [
      "vvvvvvvvvvvvvvvv",
      "aaaaaaaaaaaaaaav",
      "aaaaaaaaaaaaaaav",
      "aaaaaaaaaaaaaaav",
      "bbbaaaaaaaaaaaav",
      "   bbaaaaaaaaaav",
      "     baaaaaaaaav",
      "      baaaaaaaav",
      "     dcbaaaaaaav",
      "        baaaaaav",
      "         baaaaav",
      "          baaaav",
      "          baaaav",
      "           baaav",
      "           baaav",
      "           baaav"
    ]
  ]
}