{
  "name": "multi_laboratory_1_base7",
  "refpalette": "deceasedcraft:multi_laboratory_1/multi_laboratory_1_base7_palette",
  "xsize": 16,
  "zsize": 16,
  "slices": [
    [
      "vaaaaabbbcaaacaa",
      "vaaaaabbbaaaacaa",
      "vaaaaabaaaaaacaa",
      "vaaaaaaaaaaaacaa",
      "vaaaaabaabaaacaa",
      "vaaaaabaaaaaacaa",
      "vaaaaaaaaaaaacaa",
      "vaaaaaaaaaaaacaa",
      "vaaaaaaaaaaaacaa",
      "vaaaaaaaabaaacaa",
      "vaaaaaaaaaaaacaa",
      "vaaaaaaaaaaaacaa",
      "vaaaaaaaaaaaacad",
      "vaaaaaaaaaaaccad",
      "vaaaaaaaaaaaaadd",
      "vaaaaaaaaaaaaada"
    ],
    [
      "vaaaabe fggaaaaa",
      "vaaaab  hgaaaaaa",
      "vaaaai  caaaaaaa",
      "vaaaah  baaaaaaa",
      "vaaaaa   haaaaaa",
      "vaaaaae  iaaaaaa",
      "vaaaaai   caaaaa",
      "vaaaaaah   iacaa",
      "vaaaaaaae  igbaa",
      "vaaaaaaab iaggaa",
      "vaaaaaaaaaagggaa",
      "vaaaaaaaaaaaggaa",
      "vaaaaaaaaaaaa aa",
      "vaaaaaaaaaaaaaaa",
      "vaaaaaaaaaaaaaaj",
      "vaaaaaaaaaaaaaaa"
    ],
    [
      "vaaaaf  egggaaaa",
      "vaaaaa  hgaaaaaa",
      "vaaaa   aaaaaaaa",
      "vaaaah  baaaaaaa",
      "vaaaa    haaaaaa",
      "vaaaai    kaaaaa",
      "vaaaak     aaaaa",
      "vaaaaaah    haaa",
      "vaaaaaaa     fba",
      "vaaaaaaab    iih",
      "vaaaaaaaaahiiggi",
      "vaaaaaaaaaagkcaa",
      "vaaaaaaaaaaagbba",
      "vaaaaaaaaaaaaaba",
      "vaaaaaaaaaaaaaaj",
      "vaaaaaaaaaaaaaaa"
    ],
    [
      "vaaaae  laggaaaa",
      "vaaaaa  aaaaaaaa",
      "vaaaac  baaaaaaa",
      "vaaaah  baaaaaaa",
      "vaaaa   lhaaaaaa",
      "vaaaa    gaaaaaa",
      "vaaaaa   laaaaaa",
      "vaaaaaah    haaa",
      "vaaaaaaaa    eba",
      "vaaaaaaaaa     h",
      "vaaaaaaaaah     ",
      "vaaaaaaaaaaa    ",
      "vaaaaaaaaaaaae  ",
      "vaaaaaaaaaaaabb ",
      "vaaaaaaaaaaaaaaj",
      "vaaaaaaaaaaaaaag"
    ],
    [
      "vaaaaa laaaaaaaa",
      "vaaaaaaaaaaaaaaa",
      "vaaaaaalaaaaaaaa",
      "vaaaaallaaaaaaaa",
      "vaaaaka aaaaaaaa",
      "vaaaaaaaaaaaaaaa",
      "vaaaaaaaaaaaaaaa",
      "vaaaaaaalaa haaa",
      "vaaaaaaaaal   ca",
      "vaaaaaaaaa     h",
      "vaaaaaaaaaaa    ",
      "vaaaaaaaaaaaa   ",
      "vaaaaaaaaaaaag  ",
      "vaaaaaaaaaaaaab ",
      "vaaaaaaaaaaaaaaj",
      "vaaaaaaaaaaaaaa "
    ],
    [
      "vaaaaaaaaaaaaaaa",
      "vaaaaaaaaaaaaaaa",
      "vaaaaaaaaaaaaaaa",
      "vaaaaaaaaaaaaaaa",
      "vaaaaaaaaaaaaaaa",
      "vaaaaaaaaaaaaaaa",
      "vaaaaaaaaaaaaaaa",
      "vaaaaaaaaaaaagaa",
      "vaaaaaaaaaaaacca",
      "vaaaaaaaaaaallla",
      "vaaaaaaaaaaaalll",
      "vaaaaaaaaaaaalll",
      "vaaaaaaaaaaaagml",
      "vaaaaaaaaaaaaga ",
      "vaaaaaaaaaaaaaaj",
      "vaaaaaaaaaaaaaa "
    ]
  ]
}