{
  "name": "multi_laboratory_1_base6",
  "refpalette": "deceasedcraft:multi_laboratory_1/multi_laboratory_1_base6_palette",
  "xsize": 16,
  "zsize": 16,
  "slices": [
    [
      "vabccccccccccccc",
      "vabccccccccccccc",
      "vabccccccccccccc",
      "vabccccccccccccc",
      "vabccccccccccccc",
      "vabccccccccccccc",
      "vabccccccccdcccc",
      "vabccccccccccccc",
      "vabccccccccccccc",
      "vabccccccccccccc",
      "vabccccccccccccc",
      "vabccccccccccccc",
      "vabcccccccccccce",
      "vabccccccccdccce",
      "vabcccccccccccef",
      "vabccccccccccce "
    ],
    [
      "vag             ",
      "vab             ",
      "vabh            ",
      "vabh          i ",
      "vab             ",
      "vajjjj      klll",
      "vab mj     d    ",
      "vajjjj     !    ",
      "vab        n    ",
      "vabh     o n    ",
      "vabh       n    ",
      "vab        n    ",
      "vajjjj     p   q",
      "vab mj     d   q",
      "vajjjj     r  qf",
      "vab        n  q "
    ],
    [
      "vag             ",
      "vab             ",
      "vabst           ",
      "vabut           ",
      "vabw            ",
      "vajjq        x  ",
      "vab mq     d    ",
      "vajjq           ",
      "vaby       A    ",
      "vabut      B    ",
      "vabst      C    ",
      "vabw            ",
      "vajjq          q",
      "vab mq     d   q",
      "vajjq      x  qf",
      "vaby       A  q "
    ],
    [
      "vag             ",
      "vab             ",
      "vab             ",
      "vab             ",
      "vab             ",
      "vajjq           ",
      "vab mq     d    ",
      "vajjq           ",
      "vab             ",
      "vab             ",
      "vab             ",
      "vab             ",
      "vajjq          q",
      "vab mq     d   q",
      "vajjq      D  qf",
      "vab           q "
    ],
    [
      "vag             ",
      "vab             ",
      "vabE            ",
      "vabE            ",
      "vab             ",
      "vajjq           ",
      "vab mq     d    ",
      "vajjq           ",
      "vab             ",
      "vabE            ",
      "vabE            ",
      "vab             ",
      "vajjq          q",
      "vab mq     d   q",
      "vajjq         qf",
      "vab           q "
    ],
    [
      "vag             ",
      "vab             ",
      "vabg            ",
      "vab             ",
      "vab             ",
      "vajjq           ",
      "vab mq     d    ",
      "vajjq           ",
      "vab             ",
      "vabg            ",
      "vab             ",
      "vab             ",
      "vajjq          q",
      "vab mq     d   q",
      "vajjq         qf",
      "vab           q "
    ]
  ]
}