{
  "name": "multi_laboratory_1_ground",
  "refpalette": "deceasedcraft:multi_laboratory_1/multi_laboratory_1_ground_palette",
  "xsize": 16,
  "zsize": 16,
  "slices": [
    [
      "azazaabvcccdeeee",
      "zazazabbcccdeeee",
      "zazaazbvcccdeeee",
      "zzzzaabvcccdeeee",
      "zzzazaavcccdeeee",
      "azazaabvcccdeeee",
      "zzzaaavvcccdeeee",
      "zzazzabvcccdeeee",
      "zazzabbbcccdeeee",
      "azazzabvcccdeeee",
      "zzzzaaavcccdeeee",
      "zzzaaaavcccdeeee",
      "azzazzbbcccdeeed",
      "zzazazbvcccdeeed",
      "zzzazabvcccdeedd",
      "zaaazabvcccdeed@"
    ],
    [
      "        f  g    ",
      "h h     f  g i  ",
      "     h  f  gijj ",
      "h k     f  g jji",
      " l      f  g    ",
      "        f  g    ",
      "hh      f  d i  ",
      "   h    f  g jj ",
      "h       f  gijji",
      "   h    f  g    ",
      "        f  g i  ",
      " k      f  g    ",
      "    h   f  g   m",
      "        f  dn  m",
      "h l     o  g  mm",
      "    h   o  g  m "
    ],
    [
      "        f  g    ",
      "        f  g    ",
      "        f  g    ",
      "  ~     f  g p  ",
      "        f  g    ",
      "        f  g    ",
      "        f  d    ",
      "        f  q    ",
      "        f  g  r ",
      "        s  g    ",
      "        f  g    ",
      " ~      f  g    ",
      "        f  q    ",
      "        s  dt   ",
      "        u  q    ",
      "        u  q    "
    ],
    [
      "        s  g    ",
      "        w  g    ",
      "        w  g    ",
      "        w  g    ",
      "        w  g    ",
      "        w  g    ",
      "        s  d    ",
      "        w  q    ",
      "        s  g    ",
      "        s  g    ",
      "        s  g    ",
      "        w  g    ",
      "        w  q    ",
      "        w  dx   ",
      "        u  q    ",
      "        u  q    "
    ],
    [
      "        w  g    ",
      "        w  g    ",
      "        w  g    ",
      "        w  g    ",
      "        s  g    ",
      "        w  g    ",
      "        w  d    ",
      "        w  q    ",
      "        w  g    ",
      "        s  g    ",
      "        w  g    ",
      "        s  g    ",
      "        w  q    ",
      "        s  d    ",
      "        u  q    ",
      "        u  q    "
    ],
    [
      "        w  gyyyy",
      "        s  gyyyy",
      "        s  gyyyy",
      "        w  gyyyy",
      "        w  gyyyy",
      "        s  gyyyy",
      "        w  dyyyy",
      "        w  gyyyy",
      "        w  gyyy ",
      "        w  gyy  ",
      "        w  gyy  ",
      "        w  gyy  ",
      "        s  gy   ",
      "        s  dy   ",
      "        u  gy   ",
      "        u  gy   "
    ]
  ]
}