{
  "name": "multi_laboratory_1_base3",
  "refpalette": "deceasedcraft:multi_laboratory_1/multi_laboratory_1_base3_palette",
  "xsize": 16,
  "zsize": 16,
  "slices": [
    [
      "vabccccccccccccc",
      "vabccccccccccccc",
      "vabccccccccccccc",
      "vabccccccccccccc",
      "vabccccccccccccc",
      "vabccccccccccccc",
      "vabccccccccdcccc",
      "vabccccccccccccc",
      "vabccccccccccccc",
      "vabccccccccccccc",
      "vabccccccccccccc",
      "vabccccccccccccc",
      "vabcccccccccccce",
      "vabccccccccdccce",
      "vabcccccccccccef",
      "vabccccccccccce "
    ],
    [
      "vabghhh!higj    ",
      "vabh     klj m  ",
      "vabn   k   j o  ",
      "vabnk     mj    ",
      "vabh    p qr    ",
      "vabg       j    ",
      "vabjjjjjjjjdf  s",
      "vabtu w xuyj  AB",
      "vab        j   C",
      "vabD EFFI  j    ",
      "vabJ K  LM j    ",
      "vabJNK  L  j    ",
      "vabO PQQR  j  ST",
      "vab    U   d  fT",
      "vab        j  Tf",
      "vabD   w   V  T "
    ],
    [
      "vabghhihWhgj    ",
      "vabX       Y    ",
      "vabh       Y    ",
      "vabh       j    ",
      "vabh       Z    ",
      "vabg 00000 j    ",
      "vabjjjjjjjjd1   ",
      "vab        j    ",
      "vab        Y    ",
      "vab   23   Y    ",
      "vab  4  5  Y    ",
      "vab  6     Y    ",
      "vab   78   j   T",
      "vab        d  1T",
      "vab        j  Tf",
      "vab        V  T "
    ],
    [
      "vabg999999gj    ",
      "vab#       $    ",
      "vab%       $    ",
      "vab^       j    ",
      "vab        $    ",
      "vabg  & *  j    ",
      "vabjjjjjjjjd(   ",
      "vab        j    ",
      "vab        Y    ",
      "vab        Y    ",
      "vab        Y    ",
      "vab        Y    ",
      "vab        j   T",
      "vab        d  (T",
      "vab        j  Tf",
      "vab        V  T "
    ],
    [
      "vabg      gj    ",
      "vab        j    ",
      "vab        j    ",
      "vab        j    ",
      "vab        j    ",
      "vabg       j    ",
      "vabjjjjjjjjd    ",
      "vab        j    ",
      "vab        j    ",
      "vab        j    ",
      "vab        j    ",
      "vab        j    ",
      "vab        j   T",
      "vab        d   T",
      "vab        j  Tf",
      "vab        j  T "
    ],
    [
      "vabg))))))g$++++",
      "vab)-))))-)$++++",
      "vab))))))))$++++",
      "vab))))))))$++++",
      "vab)-))))-)$++++",
      "vabg)))))))$++++",
      "vabjjjjjjjjd++++",
      "vab[[[[[[[[$++++",
      "vab[[[[[[[[$++++",
      "vab[[]]{}[[$++++",
      "vab[[][[][[$++++",
      "vab[[}[[}[[$++++",
      "vab[[]}]][[$+++T",
      "vab[[[[[[[[d+++T",
      "vab[[[[[[[[$++Tf",
      "vab[[}[[}[[$++T "
    ]
  ]
}