{
  "name": "multi_laboratory_1_base5",
  "refpalette": "deceasedcraft:multi_laboratory_1/multi_laboratory_1_base5_palette",
  "xsize": 16,
  "zsize": 16,
  "slices": [
    [
      "vab             ",
      "vac             ",
      "vacb            ",
      "vac             ",
      "vac             ",
      "vadde           ",
      "vac fe     g    ",
      "vadde           ",
      "vach            ",
      "vacb            ",
      "vac             ",
      "vac             ",
      "vadde          e",
      "vac fe     gi  e",
      "vadde         ej",
      "vac           e "
    ],
    [
      "vab             ",
      "vac             ",
      "vabb            ",
      "vab             ",
      "vab             ",
      "vadde           ",
      "vac fe     g    ",
      "vadde           ",
      "vacb            ",
      "vacb            ",
      "vac             ",
      "vac             ",
      "vadde          e",
      "vac fe     g   e",
      "vadde         ej",
      "vac           e "
    ],
    [
      "vab             ",
      "vac             ",
      "vacb            ",
      "vac             ",
      "vac             ",
      "vadde           ",
      "vac fe     g    ",
      "vadde           ",
      "vac             ",
      "vabb            ",
      "vab             ",
      "vab             ",
      "vadde          e",
      "vac fe     g   e",
      "vadde         ej",
      "vacb          e "
    ],
    [
      "vab             ",
      "vac             ",
      "vacb            ",
      "vach            ",
      "vac             ",
      "vadde           ",
      "vac fe     g    ",
      "vadde           ",
      "vac             ",
      "vacb            ",
      "vach            ",
      "vac             ",
      "vadde          e",
      "vac fe     g   e",
      "vadde         ej",
      "vac           e "
    ],
    [
      "vab             ",
      "vac             ",
      "vacb            ",
      "vach            ",
      "vach            ",
      "vadde           ",
      "vac fe     g    ",
      "vadde           ",
      "vach            ",
      "vacb            ",
      "vach            ",
      "vac             ",
      "vadde          e",
      "vac fe     g   e",
      "vadde         ej",
      "vac           e "
    ],
    [
      "vabbkkkkkkkkkkkk",
      "vacbkkkkkkkkkkkk",
      "vaclkkkkkkkkkkkk",
      "vacbkkkkkkkkkkkk",
      "vacbkkkkkkkkkkkk",
      "vaddddkkkkkkkkkk",
      "vac mdkkkkkgkkkk",
      "vaddddkkkkkkkkkk",
      "vacbkkkkkkkkkkkk",
      "vaclkkkkkkkkkkkk",
      "vacbkkkkkkkkkkkk",
      "vacbkkkkkkkkkkkk",
      "vaddddkkkkkkkkke",
      "vac mdkkkkkgkkke",
      "vaddddkkkkkkkkej",
      "vacbkkkkkkkkkke "
    ]
  ]
}