{
  "name": "multi_laboratory_1_base1",
  "refpalette": "deceasedcraft:multi_laboratory_1/multi_laboratory_1_base1_palette",
  "xsize": 16,
  "zsize": 16,
  "slices": [
    [
      "vabccccccccccccc",
      "vabccccccccccccc",
      "vabccccccccccccc",
      "vabccccccccccccc",
      "vabccccccccccccc",
      "vabccccccccccccc",
      "vabccccccccdcccc",
      "vabccccccccccccc",
      "vabccccccccccccc",
      "vabccccccccccccc",
      "vabccccccccccccc",
      "vabccccccccccccc",
      "vabcccccccccccce",
      "vabccccccccdccce",
      "vabcccccccccccef",
      "vabccccccccccce "
    ],
    [
      "vabghhiiii j    ",
      "vabgk   l  j    ",
      "vabm       j    ",
      "vabgn      o    ",
      "vabp       j    ",
      "vabp  qqq  j    ",
      "vabp rstuw dx   ",
      "vabp rsyuw A    ",
      "vabg rBttw A    ",
      "vabg rCtDw A    ",
      "vabm rCtDw A    ",
      "vabg  EEE  A    ",
      "vabgF    IJA  KL",
      "vabMMMMNMMMd  xL",
      "vabg    iOPM  Lx",
      "vabm     lQM  L "
    ],
    [
      "vabk  RSTS j    ",
      "vabU       j    ",
      "vabU       j    ",
      "vabV       W    ",
      "vabX       j    ",
      "vabY       j    ",
      "vabZ  0 1  d2   ",
      "vab3  0    A    ",
      "vab4       A    ",
      "vab5  6 7  A    ",
      "vabU       A    ",
      "vabU       A    ",
      "vabU       A   L",
      "vabMMMM8MMMd  2L",
      "vabU    9T A  Lx",
      "vabU       A  L "
    ],
    [
      "vab#$$     j    ",
      "vab%       j    ",
      "vabX       j    ",
      "vab        j    ",
      "vab        j    ",
      "vab^       j    ",
      "vab#       d&   ",
      "vab*       A    ",
      "vab        A    ",
      "vab        A    ",
      "vab(       A    ",
      "vab#       A    ",
      "vab!       A   L",
      "vabMMMMMMMMd  &L",
      "vab        A  Lx",
      "vab#       A  L "
    ],
    [
      "vab        j    ",
      "vab        j    ",
      "vab        j    ",
      "vab        j    ",
      "vab        j    ",
      "vab        j    ",
      "vab   ) )  d    ",
      "vab        A    ",
      "vab        A    ",
      "vab        A    ",
      "vab   + +  A    ",
      "vab        A    ",
      "vab        A   L",
      "vabMMMMMMMMd   L",
      "vab        A  Lx",
      "vab        A  L "
    ],
    [
      "vab--------[----",
      "vab--]---]-[----",
      "vab--{---]-[----",
      "vab--]---]-[----",
      "vab--]---]-[----",
      "vab--------[----",
      "vab---}}}--d----",
      "vab---|}|--[----",
      "vab--]---;-[----",
      "vab--]|}|;-[----",
      "vab--]}}};-[----",
      "vab--]---;-[----",
      "vab--------[---:",
      "vab''''''''d---:",
      "vab--------[--:<",
      "vab--]---]-[--: "
    ]
  ]
}