{
  "name": "multi_laboratory_1_base2",
  "refpalette": "deceasedcraft:multi_laboratory_1/multi_laboratory_1_base2_palette",
  "xsize": 16,
  "zsize": 16,
  "slices": [
    [
      "vabccccccccccccc",
      "vabccccccccccccc",
      "vabccccccccccccc",
      "vabccccccccccccc",
      "vabccccccccccccc",
      "vabccccccccccccc",
      "vabccccccccdcccc",
      "vabccccccccccccc",
      "vabccccccccccccc",
      "vabccccccccccccc",
      "vabccccccccccccc",
      "vabccccccccccccc",
      "vabcccccccccccce",
      "vabccccccccdccce",
      "vabcccccccccccef",
      "vabccccccccccce "
    ],
    [
      "vabghhhhhhgi    ",
      "vabh      ji    ",
      "vabh      ki    ",
      "vabh       i    ",
      "vabh     l m    ",
      "vabgnooonnni    ",
      "vabiiiiiiiidf p ",
      "vabkqrrrrski    ",
      "vab  t     i    ",
      "vabu       i    ",
      "vabu  w l  i    ",
      "vabxqyyyys i    ",
      "vabAqrrrrs i  BC",
      "vab   D    d  fC",
      "vab        i  Cf",
      "vabx  w    E  C "
    ],
    [
      "vabghhhhhhgi    ",
      "vabh       F    ",
      "vabh       F    ",
      "vabh       i    ",
      "vabh       I    ",
      "vabgn   Jo i    ",
      "vabiiiiiiiidK   ",
      "vab   LMN  i    ",
      "vab        F    ",
      "vab        F    ",
      "vab        F    ",
      "vab   OPQ  F    ",
      "vab  R L   i   C",
      "vab        d  KC",
      "vab        i  Cf",
      "vab        E  C "
    ],
    [
      "vabgSSSSSSgi    ",
      "vabT       U    ",
      "vabV       U    ",
      "vabW       i    ",
      "vabX       U    ",
      "vabg       i    ",
      "vabiiiiiiiidY   ",
      "vab        i    ",
      "vab        F    ",
      "vab        F    ",
      "vab        F    ",
      "vab        F    ",
      "vab        i   C",
      "vab        d  YC",
      "vab        i  Cf",
      "vab        E  C "
    ],
    [
      "vabg      gi    ",
      "vab !      i    ",
      "vab        i    ",
      "vabZ       i    ",
      "vab        i    ",
      "vabg       i    ",
      "vabiiiiiiiid    ",
      "vab        i    ",
      "vab        i    ",
      "vab        i    ",
      "vab        i    ",
      "vab        i    ",
      "vab        i   C",
      "vab        d   C",
      "vab        i  Cf",
      "vab        i  C "
    ],
    [
      "vabg000000gU1111",
      "vab02000030U1411",
      "vab00000000U1411",
      "vab00000000U1411",
      "vab03000020U1411",
      "vabg0000000U1111",
      "vabiiiiiiiid1111",
      "vab55555555U1111",
      "vab55555555U1111",
      "vab55655455U1111",
      "vab55655255U1111",
      "vab55455455U1111",
      "vab55255655U111C",
      "vab55555555d111C",
      "vab55555555U11Cf",
      "vab55455655U11C "
    ]
  ]
}