{
  "name": "multi_laboratory_1_base4",
  "refpalette": "deceasedcraft:multi_laboratory_1/multi_laboratory_1_base4_palette",
  "xsize": 16,
  "zsize": 16,
  "slices": [
    [
      "vabccccccccccccc",
      "vabccccccccccccc",
      "vabccccccccccccc",
      "vabccccccccccccc",
      "vabccccccccccccc",
      "vabccccccccccccc",
      "vabccccccccdcccc",
      "vabccccccccccccc",
      "vabccccccccccccc",
      "vabccccccccccccc",
      "vabcc!cccccccccc",
      "vabccccccccccccc",
      "vabcccccccccccce",
      "vabccccccccdccce",
      "vabcccccccccccef",
      "vabccccccccccce "
    ],
    [
      "vabghhhhhhgi    ",
      "vabjk    l i    ",
      "vabh       i    ",
      "vabhk      i    ",
      "vabh       m    ",
      "vabgno npnqi    ",
      "vabiiiiiiiidf   ",
      "vabrstttturi    ",
      "vabw  x    i    ",
      "vaby l     i    ",
      "vab  A B   i    ",
      "vabC DDDD  i    ",
      "vabC tttt  i  EF",
      "vab    x   d  fF",
      "vab        i  Ff",
      "vaby lI    J  F "
    ],
    [
      "vabghhhhhhgi    ",
      "vabh       K    ",
      "vabL       K    ",
      "vabL       i    ",
      "vabh       M    ",
      "vabg       i    ",
      "vabiiiiiiiidN   ",
      "vab   OPQ  i    ",
      "vab        K    ",
      "vab        K    ",
      "vab        K    ",
      "vab   RSl  K    ",
      "vab  Q O   i   F",
      "vab        d  NF",
      "vab        i  Ff",
      "vab        J  F "
    ],
    [
      "vabgTTTTTTgi    ",
      "vab        U    ",
      "vabV       U    ",
      "vabW       i    ",
      "vab        U    ",
      "vabg       i    ",
      "vabiiiiiiiidX   ",
      "vab        i    ",
      "vab        K    ",
      "vab        K    ",
      "vab        K    ",
      "vab        K    ",
      "vab        i   F",
      "vab        d  XF",
      "vab        i  Ff",
      "vab        J  F "
    ],
    [
      "vabg      gi    ",
      "vab        i    ",
      "vab        i    ",
      "vabY       i    ",
      "vab        i    ",
      "vabg       i    ",
      "vabiiiiiiiid    ",
      "vab        i    ",
      "vab        i    ",
      "vab        i    ",
      "vab        i    ",
      "vab        i    ",
      "vab        i   F",
      "vab        d   F",
      "vab        i  Ff",
      "vab        i  F "
    ],
    [
      "vabgZZZZZZgU0000",
      "vabZ1ZZZZ2ZU0300",
      "vabZZZZZZZZU0300",
      "vabZZZZZZZZU0300",
      "vabZ1ZZZZ1ZU0300",
      "vabgZZZZZZZU0000",
      "vabiiiiiiiid0000",
      "vab44444444U0000",
      "vab44444444U0000",
      "vab44244544U0000",
      "vab44244544U0000",
      "vab44544244U0000",
      "vab44544544U000F",
      "vab44444444d000F",
      "vab44444444U00Ff",
      "vab44244544U00F "
    ]
  ]
}