{
  "xsize": 16,
  "zsize": 16,
  "refpalette": "lce2:rails",
  "slices": [
    [
      "yyyyyyyyyyyyyyyy",
      "yyyyyyyyyyyyyyyy",
      "yyyyyyyyyyyyyyyy",
      "yyyyyyyyyyyyyyyy",
      "yyyyyyyyyyyyyyyy",
      "yyyyyyyyyyyyyyyy",
      "yyyyyyyyyyyyyyyy",
      "yyyyyyyyyyyyyyyy",
      "yyyyyyyyyyyyyyyy",
      "yyyyyyyyyyyyyyyy",
      "yyyyyyyyyyyyyyyy",
      "yyyyyyyyyyyyyyyy",
      "yyyyyyyyyyyyyyyy",
      "yyyyyyyyyyyyyyyy",
      "yyyyyyyyyyyyyyyy",
      "yyyyyyyyyyyyyyyy"
    ],
    [
      "yyyyyyyyyyyyyyyy",
      "~~~~~~~~~~~~~~~~",
      "~~~~~~~~~~~~~~~~",
      "~~~~~~~~~~~~~~~~",
      "~~~~~~~~~~~~~~~~",
      "eeeeeeefeeeeeeee",
      "~~~~~~~g~~~~~~~~",
      "eeeeeeefeeeeeeee",
      "~~~~~~~g~~~~~~~~",
      "eeeeeeefeeeeeeee",
      "~~~~~~~~~~~~~~~~",
      "~~~~~~~~~~~~~~~~",
      "~~~~~~~~~~~~~~~~",
      "~~~~~~~~~~~~~~~~",
      "~~~~~~~~~~~~~~~~",
      "yyyyyyyyyyyyyyyy"
    ],
    [
      "yyyyyyyyyyyyyyyy",
      "~~~~~~~~~~~~~~~~",
      "~~~~~~~~~~~~~~~~",
      "~~~~~~~~~~~~~~~~",
      "~~~~~~~~~~~~~~~~",
      "~~~~~~~~~~~~~~~~",
      "~~~~~~~~~~~~~~~~",
      "~~~~~~~~~~~~~~~~",
      "~~~~~~~~~~~~~~~~",
      "~~~~~~~~~~~~~~~~",
      "~~~~~~~~~~~~~~~~",
      "~~~~~~~~~~~~~~~~",
      "~~~~~~~~~~~~~~~~",
      "~~~~~~~~~~~~~~~~",
      "~~~~~~~~~~~~~~~~",
      "yyyyyyyyyyyyyyyy"
    ],
    [
      "yyyyyyyyyyyyyyyy",
      "~~~~~~~~~~~~~~~~",
      "~~~~~~~~~~~~~~~~",
      "~~~~~~~~~~~~~~~~",
      "~~~~~~~~~~~~~~~~",
      "~~~~~~~~~~~~~~~~",
      "~~~~~~~~~~~~~~~~",
      "~~~~~~~~~~~~~~~~",
      "~~~~~~~~~~~~~~~~",
      "~~~~~~~~~~~~~~~~",
      "~~~~~~~~~~~~~~~~",
      "~~~~~~~~~~~~~~~~",
      "~~~~~~~~~~~~~~~~",
      "~~~~~~~~~~~~~~~~",
      "~~~~~~~~~~~~~~~~",
      "yyyyyyyyyyyyyyyy"
    ],
    [
      "yyyyyyyyyyyyyyyy",
      "~~~~~~~~~~~~~~~~",
      "~~~~~~~~~~~~~~~~",
      "~~~~~~~~~~~~~~~~",
      "~~~~~~~~~~~~~~~~",
      "~~~~~~~~~~~~~~~~",
      "~~~~~~~~~~~~~~~~",
      "~~~~~~~~~~~~~~~~",
      "~~~~~~~~~~~~~~~~",
      "~~~~~~~~~~~~~~~~",
      "~~~~~~~~~~~~~~~~",
      "~~~~~~~~~~~~~~~~",
      "~~~~~~~~~~~~~~~~",
      "~~~~~~~~~~~~~~~~",
      "~~~~~~~~~~~~~~~~",
      "yyyyyyyyyyyyyyyy"
    ],
    [
      "yyyyyyyyyyyyyyyy",
      "~~~~~~~~~~~~~~~~",
      "~~~~~~~~~~~~~~~~",
      "~~~~~~~~~~~~~~~~",
      "~~~~~~~~~~~~~~~~",
      "~~~~~~~~~~~~~~~~",
      "~~~~~~~~~~~~~~~~",
      "~~~~~~~~~~~~~~~~",
      "~~~~~~~~~~~~~~~~",
      "~~~~~~~~~~~~~~~~",
      "~~~~~~~~~~~~~~~~",
      "~~~~~~~~~~~~~~~~",
      "~~~~~~~~~~~~~~~~",
      "~~~~~~~~~~~~~~~~",
      "~~~~~~~~~~~~~~~~",
      "yyyyyyyyyyyyyyyy"
    ],
    [
      "yyyyyyyyyyyyyyyy",
      "~~~~~~~~~~~~~~~~",
      "~~~~~~~~~~~~~~~~",
      "~~~~~~~~~~~~~~~~",
      "~~~~~~~~~~~~~~~~",
      "~~~~~~~~~~~~~~~~",
      "~~~~~~~~~~~~~~~~",
      "~~~~~~~~~~~~~~~~",
      "~~~~~~~~~~~~~~~~",
      "~~~~~~~~~~~~~~~~",
      "~~~~~~~~~~~~~~~~",
      "~~~~~~~~~~~~~~~~",
      "~~~~~~~~~~~~~~~~",
      "~~~~~~~~~~~~~~~~",
      "~~~~~~~~~~~~~~~~",
      "yyyyyyyyyyyyyyyy"
    ],
    [
      "yyyyyyyyyyyyyyyy",
      "~~~~~~~~~~~~~~~~",
      "~~~~~~~~~~~~~~~~",
      "~~~~~~~~~~~~~~~~",
      "~~~~~~~~~~~~~~~~",
      "~~~~~~~~~~~~~~~~",
      "~~~~~~~~~~~~~~~~",
      "~~~~~~~~~~~~~~~~",
      "~~~~~~~~~~~~~~~~",
      "~~~~~~~~~~~~~~~~",
      "~~~~~~~~~~~~~~~~",
      "~~~~~~~~~~~~~~~~",
      "~~~~~~~~~~~~~~~~",
      "~~~~~~~~~~~~~~~~",
      "~~~~~~~~~~~~~~~~",
      "yyyyyyyyyyyyyyyy"
    ],
    [
      "yyyyyyyyyyyyyyyy",
      "yyyyyyyyyyyyyyyy",
      "yyyyyyyyyyyyyyyy",
      "yyyyyyyyyyyyyyyy",
      "yyyyyyyyyyyyyyyy",
      "yyyyyyyyyyyyyyyy",
      "yyyyyyyyyyyyyyyy",
      "yyyyyyyyyyyyyyyy",
      "yyyyyyyyyyyyyyyy",
      "yyyyyyyyyyyyyyyy",
      "yyyyyyyyyyyyyyyy",
      "yyyyyyyyyyyyyyyy",
      "yyyyyyyyyyyyyyyy",
      "yyyyyyyyyyyyyyyy",
      "yyyyyyyyyyyyyyyy",
      "yyyyyyyyyyyyyyyy"
    ]
  ]
}