{
  "name": "multi_terraceplaza_0_base1",
  "refpalette": "deceasedcraft:multi_terraceplaza_0/multi_terraceplaza_0_base1_palette",
  "xsize": 16,
  "zsize": 16,
  "slices": [
    [
      "vvvvvvvvvvvvvvvv",
      "vaaabbbbbbbbbbbb",
      "vaacbddddddddddd",
      "vaaabddddddddddd",
      "vaaabddHHHHHHHHH",
      "vaaabddHHHHeHHHH",
      "vaaabddHHHHHHHHH",
      "vaaabddHHHHHHHHH",
      "vaaabddHHHHHHHHH",
      "vaaabddHHHHHHHHH",
      "vaaabddHHHHHHHHH",
      "vaaabddHHHHHHHHH",
      "vaaabddHHHHHHHHH",
      "vaaabddHHHHHHHHH",
      "vaaabddHHHHHHHHH",
      "vaaabddHHHHHHHHH"
    ],
    [
      "vvvvvvvvvvvvvvvv",
      "vaaabbbbbbbbbbbb",
      "vaacb           ",
      "vaaab           ",
      "vaaab  fgfghfgfg",
      "vaaab      e    ",
      "vaaab      h    ",
      "vaaab  ijij ijij",
      "vaaab           ",
      "vaaab           ",
      "vaaab           ",
      "vaaab           ",
      "vaaab       fgfg",
      "vaaab      h    ",
      "vaaab      h k  ",
      "vaaab      hijij"
    ],
    [
      "vvvvvvvvvvvvvvvv",
      "vaaabbbbbbbbbbbb",
      "vaacb           ",
      "vaaab           ",
      "vaaab           ",
      "vaaab      e    ",
      "vaaab           ",
      "vaaab           ",
      "vaaab           ",
      "vaaab           ",
      "vaaab           ",
      "vaaab           ",
      "vaaab           ",
      "vaaab           ",
      "vaaab           ",
      "vaaab           "
    ],
    [
      "vvvvvvvvvvvvvvvv",
      "vaaabbbbbbbbbbbb",
      "vaacb           ",
      "vaaab           ",
      "vaaab           ",
      "vaaab      e    ",
      "vaaab           ",
      "vaaab           ",
      "vaaab           ",
      "vaaab           ",
      "vaaab           ",
      "vaaab           ",
      "vaaab           ",
      "vaaab           ",
      "vaaab           ",
      "vaaab           "
    ],
    [
      "vvvvvvvvvvvvvvvv",
      "vaaabbbbbbbbbbbb",
      "vaacccccccclcccc",
      "vaaabmmmmmmmmmmm",
      "vaaabmmmmmmmmmmm",
      "vaaabmmmmmmemmmm",
      "vaaab           ",
      "vaaab           ",
      "vaaab   n     n ",
      "vaaab           ",
      "vaaab           ",
      "vaaab           ",
      "vaaab           ",
      "vaaab         n ",
      "vaaab           ",
      "vaaab           "
    ],
    [
      "vvvvvvvvvvvvvvvv",
      "vaaabbbbbbbbbbbb",
      "vaaaboooooopoooo",
      "vaaaboooooopqqqq",
      "vaaaboooooopqq q",
      "vaaabooooooepppp",
      "vaaaboooooopoooo",
      "vaaaboooooopoooo",
      "vaaaboooroopooro",
      "vaaaboooooopoooo",
      "vaaaboooooopoooo",
      "vaaaboooooopoooo",
      "vaaaboooooopoooo",
      "vaaaboooroopooro",
      "vaaaboooooopoooo",
      "vaaaboooooopoooo"
    ]
  ]
}