{
  "name": "multi_terraceplaza_0_base2",
  "refpalette": "deceasedcraft:multi_terraceplaza_0/multi_terraceplaza_0_base2_palette",
  "xsize": 16,
  "zsize": 16,
  "slices": [
    [
      "vvvvvvvvvvvvvvvv",
      "vaaabbbbbbbbbbbb",
      "vaaabccccccccccc",
      "vaaabccccccccccc",
      "vaaabccHHHHHHHHH",
      "vaaabccHHHHdHHHH",
      "vaaabccHHHHHHHHH",
      "vaaabccHHHHHHHHH",
      "vaaabccHHHHHHHHH",
      "vaaabccHHHHHHHHH",
      "vaaabccHHHHHHHHH",
      "vaaabccHHHHHHHHH",
      "vaaabccHHHHHHHHH",
      "vaaabccHHHHHHHHH",
      "vaaabccHHHHHHHHH",
      "vaaabccHHHHHHHHH"
    ],
    [
      "vvvvvvvvvvvvvvvv",
      "vaaabbbbbbbbbbbb",
      "vaaab           ",
      "vaaab           ",
      "vaaab  efefgefef",
      "vaaab      d    ",
      "vaaab     hg    ",
      "vaaab  ijij ijij",
      "vaaab           ",
      "vaaab           ",
      "vaaab           ",
      "vaaab           ",
      "vaaab       efef",
      "vaaab      g    ",
      "vaaab      g    ",
      "vaaab      gijij"
    ],
    [
      "vvvvvvvvvvvvvvvv",
      "vaaabbbbbbbbbbbb",
      "vaaab           ",
      "vaaab           ",
      "vaaab           ",
      "vaaab      d    ",
      "vaaab           ",
      "vaaab           ",
      "vaaab           ",
      "vaaab           ",
      "vaaab           ",
      "vaaab           ",
      "vaaab           ",
      "vaaab           ",
      "vaaab           ",
      "vaaab           "
    ],
    [
      "vvvvvvvvvvvvvvvv",
      "vaaabbbbbbbbbbbb",
      "vaaab           ",
      "vaaab           ",
      "vaaab           ",
      "vaaab      d    ",
      "vaaab           ",
      "vaaab           ",
      "vaaab           ",
      "vaaab           ",
      "vaaab           ",
      "vaaab           ",
      "vaaab           ",
      "vaaab           ",
      "vaaab           ",
      "vaaab           "
    ],
    [
      "vvvvvvvvvvvvvvvv",
      "vaaabbbbbbbbbbbb",
      "vaakkkkkkkkkkkkk",
      "vaaablllllllllll",
      "vaaablllllllllll",
      "vaaablllllldllll",
      "vaaab           ",
      "vaaab           ",
      "vaaab           ",
      "vaaab           ",
      "vaaab           ",
      "vaaab           ",
      "vaaab           ",
      "vaaab           ",
      "vaaab           ",
      "vaaab           "
    ],
    [
      "vvvvvvvvvvvvvvvv",
      "vaaabbbbbbbbbbbb",
      "vaakbmmmmmmmmmmm",
      "vaaabmmmmmmmmmmm",
      "vaaabmmmmmmmmmmm",
      "vaaabmmmmmmdnnnn",
      "vaaabmmmmmmnmmmm",
      "vaaabmmmmmmnmmmm",
      "vaaabmmmommnmmom",
      "vaaabmmmmmmnmmmm",
      "vaaabmmmmmmnmmmm",
      "vaaabmmmmmmnmmmm",
      "vaaabmmmmmmnmmmm",
      "vaaabmmm!mmnmmom",
      "vaaabmmmmmmnmmmm",
      "vaaabmmmmmmnmmmm"
    ]
  ]
}