{
  "name": "multi_terraceplaza_0_floor2",
  "refpalette": "deceasedcraft:multi_terraceplaza_0/multi_terraceplaza_0_floor2_palette",
  "xsize": 16,
  "zsize": 16,
  "slices": [
    [
      "                ",
      "                ",
      "                ",
      "                ",
      "                ",
      "       a   b    ",
      "       a        ",
      "       a        ",
      "      cd        ",
      "      ce        ",
      "      ce        ",
      "      cd        ",
      "      cd        ",
      "      ce        ",
      "      cd        ",
      "      ce        "
    ],
    [
      "                ",
      "                ",
      "                ",
      "       a        ",
      "       a        ",
      "       a   bffff",
      "      cd   g    ",
      "      ce   g    ",
      "      cd   g    ",
      "      ce   g    ",
      "      ce   g    ",
      "      cd   g    ",
      "      cd   g    ",
      "      ce   g    ",
      "      cd   g    ",
      "      ce   g    "
    ],
    [
      "                ",
      "       aaaaaaaaa",
      "       a        ",
      "       a        ",
      "      ce   h    ",
      "      ce  ibjjjj",
      "      cd  kgllll",
      "      ce  kmnooo",
      "      cd  kmnppp",
      "      ce  kmnppp",
      "      ce  kmnppp",
      "      cd  kmnppp",
      "      cd  kmnppp",
      "      ce  kmnppp",
      "      cd  kmnqqq",
      "      ce  kgrrrr"
    ],
    [
      "       ccccccccc",
      "      ceededdeed",
      "      cdssstssss",
      "      cessstssss",
      "      cessgugggg",
      "      cewwubxxxx",
      "      cdssgxyyyy",
      "      cessgxyyyy",
      "      cdssgxyyyy",
      "      cessgxyyyy",
      "      cessgxyyyy",
      "      cdssgxyyyy",
      "      cdssgxyyyy",
      "      cessgxyyyy",
      "      cdssgxyyyy",
      "      cessgxyyyy"
    ],
    [
      "       ccccccccc",
      "      ceededdeed",
      "      cdAAAAAAAA",
      "      ceAAAAAAAA",
      "      ceAAAAAAAA",
      "      ceAAAbAAAA",
      "      cdAAAAAAAA",
      "      ceABBBAAAA",
      "      cdABBBAAAA",
      "      ceABBBAAAA",
      "      ceABBBAAAA",
      "      cdABBBAAAA",
      "      cdABBBAAAA",
      "      ceABBBAAAA",
      "      cdABBBAAAB",
      "      ceAAAAAAAB"
    ],
    [
      "       ccccccccc",
      "      ceededdeed",
      "      cd        ",
      "      ce        ",
      "      ce        ",
      "      ceCDDb   E",
      "      cd       E",
      "      ce       E",
      "      cd  F     ",
      "      ce  I     ",
      "      ce        ",
      "      cd  J     ",
      "      cd  K     ",
      "      ce  L     ",
      "      cd        ",
      "      ce        "
    ]
  ]
}