{
  "name": "multi_terraceplaza_0_floor3",
  "refpalette": "deceasedcraft:multi_terraceplaza_0/multi_terraceplaza_0_floor3_palette",
  "xsize": 16,
  "zsize": 16,
  "slices": [
    [
      "       aaaaaaaaa",
      "      abbcbccbbc",
      "      ac        ",
      "      ab        ",
      "      ab        ",
      "      abd  e   f",
      "      acghhi   f",
      "      ab       f",
      "      ac        ",
      "      ab        ",
      "      ab        ",
      "      ac        ",
      "      ac        ",
      "      ab        ",
      "      ac        ",
      "      ab        "
    ],
    [
      "       aaaaaaaaa",
      "      abbcbccbbc",
      "      ac        ",
      "      ab        ",
      "      ab        ",
      "      ab   e   f",
      "      acd  j   f",
      "      abghhi   f",
      "      ac        ",
      "      ab        ",
      "      ab        ",
      "      ac        ",
      "      ac        ",
      "      ab        ",
      "      ac        ",
      "      ab        "
    ],
    [
      "       aaaaaaaaa",
      "      abbcbccbbc",
      "      ac        ",
      "      ab        ",
      "      ab        ",
      "      ab   e   f",
      "      ac       f",
      "      abd  j   f",
      "      acghhi    ",
      "      ab        ",
      "      ab        ",
      "      ac        ",
      "      ac        ",
      "      ab        ",
      "      ac        ",
      "      ab        "
    ],
    [
      "       aaaaaaaaa",
      "      abbcbccbbc",
      "      ac        ",
      "      ab        ",
      "      ab        ",
      "      ab   e   k",
      "      ac       k",
      "      ab       k",
      "      acd  j    ",
      "      abghhi    ",
      "      ab        ",
      "      ac        ",
      "      ac        ",
      "      ab        ",
      "      ac        ",
      "      ab        "
    ],
    [
      "       aaaaaaaaa",
      "      abbcbccbbc",
      "      ac        ",
      "      ab        ",
      "      ab        ",
      "      ab   e    ",
      "      ac        ",
      "      ab        ",
      "      ac        ",
      "      abd  j    ",
      "      abghhi    ",
      "      ac        ",
      "      ac        ",
      "      ab        ",
      "      ac        ",
      "      ab        "
    ],
    [
      "       aaaaaaaaa",
      "      abbcbccbbc",
      "      ac        ",
      "      ab        ",
      "      ab        ",
      "      ab   e    ",
      "      ac        ",
      "      ab        ",
      "      ac        ",
      "      ab        ",
      "      abd  j    ",
      "      acghhi    ",
      "      ac        ",
      "      ab        ",
      "      ac        ",
      "      ab        "
    ]
  ]
}