{
  "name": "multi_terraceplaza_0_floor4",
  "refpalette": "deceasedcraft:multi_terraceplaza_0/multi_terraceplaza_0_floor4_palette",
  "xsize": 16,
  "zsize": 16,
  "slices": [
    [
      "       aaaaaaaaa",
      "      abbcbccbbc",
      "      ac        ",
      "      ab        ",
      "      ab        ",
      "      ab   d    ",
      "      ac        ",
      "      ab        ",
      "      ac        ",
      "      ab        ",
      "      ab        ",
      "      ace  f    ",
      "      acghhi    ",
      "      ab jjjjjjj",
      "      ac jjjjjjj",
      "      ab jjjjjjj"
    ],
    [
      "       aaaaaaaaa",
      "      abbcbccbbc",
      "      ac        ",
      "      ab        ",
      "      ab        ",
      "      ab   d    ",
      "      ac        ",
      "      ab        ",
      "      ac        ",
      "      ab        ",
      "      ab        ",
      "      ac        ",
      "      ace  f    ",
      "      abe  kkkkk",
      "      ace       ",
      "      abe       "
    ],
    [
      "       aaaaaaaaa",
      "      abbcbccbbc",
      "      ac        ",
      "      ab        ",
      "      ab        ",
      "      ab   d    ",
      "      ac        ",
      "      ab        ",
      "      ac        ",
      "      ab        ",
      "      ab        ",
      "      ac        ",
      "      ac        ",
      "      ab        ",
      "      ac        ",
      "      ab        "
    ],
    [
      "       aaaaaaaaa",
      "      abbcbccbbc",
      "      ac        ",
      "      ab        ",
      "      ab        ",
      "      ab   d    ",
      "      ac        ",
      "      ab        ",
      "      ac        ",
      "      ab        ",
      "      ab        ",
      "      ac        ",
      "      ac        ",
      "      ab        ",
      "      ac        ",
      "      ab        "
    ],
    [
      "       aaaaaaaaa",
      "      abbcbccbbc",
      "      ac        ",
      "      ab        ",
      "      ab        ",
      "      ab   d    ",
      "      ac        ",
      "      ab        ",
      "      ac        ",
      "      ab        ",
      "      ab        ",
      "      ac        ",
      "      ac        ",
      "      ab        ",
      "      ac        ",
      "      ab        "
    ],
    [
      "       aaaaaaaaa",
      "      abbcbccbbc",
      "      ac        ",
      "      ab        ",
      "      ab        ",
      "      ab   d    ",
      "      ac        ",
      "      ab        ",
      "      ac        ",
      "      ab        ",
      "      ab        ",
      "      ac        ",
      "      ac        ",
      "      ab        ",
      "      ac        ",
      "      ab   l    "
    ]
  ]
}