{
  "name": "multi_terraceplaza_0_floor5",
  "refpalette": "deceasedcraft:multi_terraceplaza_0/multi_terraceplaza_0_floor5_palette",
  "xsize": 16,
  "zsize": 16,
  "slices": [
    [
      "       aaaaaaaaa",
      "      abbcbccbbc",
      "      ac        ",
      "      ab        ",
      "      ab        ",
      "      ab   d    ",
      "      ac        ",
      "      ab        ",
      "      ac        ",
      "      ab        ",
      "      ab        ",
      "      ac        ",
      "      ac        ",
      "      ab        ",
      "      ac        ",
      "      ab        "
    ],
    [
      "       aaaaaaaaa",
      "      abbcbccbbc",
      "      aceeeeeeee",
      "      abeeeeeeee",
      "      abeeffffff",
      "      abeefdgggg",
      "      aceefhhhhh",
      "      abeefh    ",
      "      aceefh    ",
      "      abeefhhhhh",
      "      abeefhhhhh",
      "      aceefhhhhh",
      "      aceefhhhhh",
      "      abeefh    ",
      "      aceefh    ",
      "      abeefhhhhh"
    ],
    [
      "       aaaaaaaaa",
      "      abbcbccbbc",
      "      ac        ",
      "      ab        ",
      "      ab  iiiiii",
      "      ab  iiiiii",
      "      ac  iiiiii",
      "      ab  ii@@@@",
      "      ac  ii@@@@",
      "      ab  iiiiii",
      "      ab  iiiiii",
      "      ac  iiiiii",
      "      ac  iiiiii",
      "      ab  ii@@@@",
      "      ac  ii@@@@",
      "      ab  iiiiii"
    ],
    [
      "       aaaaaaaaa",
      "      abbcbccbbc",
      "      ac        ",
      "      ab        ",
      "      ab        ",
      "      ab        ",
      "      ac        ",
      "      ab        ",
      "      ac        ",
      "      ab        ",
      "      ab        ",
      "      ac        ",
      "      ac        ",
      "      ab        ",
      "      ac        ",
      "      ab        "
    ],
    [
      "                ",
      "                ",
      "                ",
      "                ",
      "                ",
      "                ",
      "                ",
      "                ",
      "                ",
      "                ",
      "                ",
      "                ",
      "                ",
      "                ",
      "                ",
      "                "
    ],
    [
      "                ",
      "                ",
      "                ",
      "                ",
      "                ",
      "                ",
      "                ",
      "                ",
      "                ",
      "                ",
      "                ",
      "                ",
      "                ",
      "                ",
      "                ",
      "                "
    ]
  ]
}