{
  "name": "multi_terraceplaza_0_ground",
  "refpalette": "deceasedcraft:multi_terraceplaza_0/multi_terraceplaza_0_ground_palette",
  "xsize": 16,
  "zsize": 16,
  "slices": [
    [
      "HHHaaaaaaaaaaaaa",
      "HHHaaaaaaaaaaaaa",
      "HHHbcdeeffeeeeee",
      "HHHbgddeffehhhhh",
      "HHHbggddffehhhih",
      "HHHHbggcffejhhhh",
      "HHHHbgggffeeeeee",
      "HHHHHbbbbbbbbbbb",
      "HHHHHHHHHHHHHHHH",
      "HHHHHHHHHHHHHHHH",
      "HHHHHHHHHHHHHHHH",
      "HHHHHHHHHHHHHHHH",
      "HHHHHHHHHHHHHHHH",
      "HHHHHbbbbbbHHHHH",
      "HHHHbgggffgbHHHb",
      "HHHHbggcffcbHHHb"
    ],
    [
      "                ",
      "                ",
      "    kl          ",
      "    mln         ",
      "    mmll      o ",
      "     mmk   j    ",
      "                ",
      "        pp      ",
      "        pp      ",
      "        pp      ",
      "      q pp q    ",
      "        pp      ",
      "        pp      ",
      "        pp      ",
      "                ",
      "     mmk  k  r  "
    ],
    [
      "                ",
      "                ",
      "                ",
      "      o         ",
      "                ",
      "           j    ",
      "                ",
      "                ",
      "                ",
      "                ",
      "                ",
      "                ",
      "                ",
      "                ",
      "                ",
      "       s  st    "
    ],
    [
      "                ",
      "                ",
      "                ",
      "      u         ",
      "                ",
      "           j    ",
      "                ",
      "                ",
      "                ",
      "                ",
      "                ",
      "                ",
      "                ",
      "                ",
      "                ",
      "                "
    ],
    [
      "                ",
      "                ",
      "                ",
      "      u         ",
      "                ",
      "           j    ",
      "                ",
      "                ",
      "                ",
      "                ",
      "                ",
      "                ",
      "                ",
      "                ",
      "                ",
      "                "
    ],
    [
      "                ",
      "                ",
      "                ",
      "                ",
      "                ",
      "           j    ",
      "                ",
      "                ",
      "                ",
      "                ",
      "                ",
      "                ",
      "                ",
      "                ",
      "                ",
      "                "
    ]
  ]
}