{
  "name": "multi_communitycenter_5_base1",
  "refpalette": "deceasedcraft:multi_communitycenter_5/multi_communitycenter_5_base1_palette",
  "xsize": 16,
  "zsize": 16,
  "slices": [
    [
      "HHHHHHHHHHHHHHHH",
      "HHHHHHHHHHHHHHHH",
      "HHHHHHHHHHHHHHHH",
      "HHHHHHHHHHHHHHHH",
      "HHHHHHHHHHHHHHHH",
      "HHHHHHHHHHHHHHHH",
      "HHHHHHHHHHHHHHHH",
      "HHHHHHHHHHHHHHaa",
      "HHHHHHHHHHHHHHab",
      "HHHHHHHHHHHHHHab",
      "HHHHHHHHHHHHHHaa",
      "HHHHHHHHHHHHHHHH",
      "HHHHHHHHHHHHHHHH",
      "HHHHHHHHHHHHHHHH",
      "HHHHHHHHHHHHHHHH",
      "vvvvvvvvvvvvvvvv"
    ],
    [
      "    c    c    c ",
      "dede dede dede d",
      "                ",
      "                ",
      "                ",
      "                ",
      "fgfg fgfg fgfg  ",
      "    c    c    ch",
      "              ij",
      "dede dede dedeij",
      "iiiiiiiiiiiiiiik",
      "iiiiiiiiiiiiiiii",
      "iiiiiiiiiiiiiiii",
      "iiiiiiiiiiiiiiii",
      "iiiiiiiiiiiiiiii",
      "vvvvvvvvvvvvvvvv"
    ],
    [
      "    c    c    c ",
      "                ",
      "                ",
      "                ",
      "                ",
      "                ",
      "                ",
      "    c    c    ch",
      "              ij",
      "              ij",
      "iiiiiiiiiiiiiiik",
      "iiiiiiiiiiiiiiii",
      "iiiiiiiiiiiiiiii",
      "iiiiiiiiiiiiiiii",
      "iiiiiiiiiiiiiiii",
      "vvvvvvvvvvvvvvvv"
    ],
    [
      "    c    c    c ",
      "                ",
      "                ",
      "                ",
      "                ",
      "                ",
      "                ",
      "    c    c    ch",
      "              ij",
      "              ij",
      "iiiiiiiiiiiiiiik",
      "iiiiiiiiiiiiiiii",
      "iiiiiiiiiiiiiiii",
      "iiiiiiiiiiiiiiii",
      "iiiiiiiiiiiiiiii",
      "vvvvvvvvvvvvvvvv"
    ],
    [
      "llllcllllcllllcl",
      "    c    c    c ",
      "    c    c    c ",
      "    c    c    c ",
      "    c    c    c ",
      "    c    c    c ",
      "    c    c    c ",
      "llllcllllcllllcc",
      "    c    c    cj",
      "    c    c    cj",
      "iiiiiiiiiiiiiiak",
      "iiiiiiiiiiiiiiii",
      "iiiiiiiiiiiiiiii",
      "iiiiiiiiiiiiiiii",
      "iiiiiiiiiiiiiiii",
      "vvvvvvvvvvvvvvvv"
    ],
    [
      "iiiiiiiiiiiiiiii",
      "iiiiiiiiiiiiiiii",
      "iiiiiiiiiiiiiiii",
      "iiiiiiiiiiiiiiii",
      "iiiiiiiiiiiiiiii",
      "iiiiiiiiiiiiiiii",
      "iiiiiiiiiiiiiiii",
      "iiiiiiiiiiiiiiii",
      "iiiiiiiiiiiiiiij",
      "iiiiiiiiiiiiiiij",
      "iiiiiiiiiiiiiiik",
      "iiiiiiiiiiiiiiii",
      "iiiiiiiiiiiiiiii",
      "iiiiiiiiiiiiiiii",
      "iiiiiiiiiiiiiiii",
      "vvvvvvvvvvvvvvvv"
    ]
  ]
}