{
  "name": "multi_communitycenter_5_ground",
  "refpalette": "deceasedcraft:multi_communitycenter_5/multi_communitycenter_5_ground_palette",
  "xsize": 16,
  "zsize": 16,
  "slices": [
    [
      "aabcccbaaaaaaaab",
      "aaabbbbaaaddaaab",
      "aaaaaaaaaddddaab",
      "aaaaaaaaaddddaae",
      "baaaaaaaaaddaaae",
      "fbbaaaaaaaaaaaaa",
      "fffbbbaaaaaaaaaa",
      "fffffbbbbbbbbbbg",
      "fffffahhhhhhhhhg",
      "fffffahhhhhhhhhg",
      "fffffahhhhhhhhhg",
      "aafffahhhhhhhhhg",
      "iaaaaahhhhhhhhhg",
      "iiiiaaaaaaaaaaag",
      "iiiiiiiiiiiiiiii",
      "iiiiiiiiiiiiiiii"
    ],
    [
      "  jklmn        n",
      "   jopp   qq   p",
      "         qrrq  p",
      "         qrrq   ",
      "          qq    ",
      "               s",
      "   npp          ",
      " t   pnu uwwuunp",
      " t  tpxy  AA AAp",
      " t  tpBC       p",
      "    ppDD  AA AAp",
      "EE  Fp I       p",
      " EEEEp J  AA AAp",
      "    EEEEEEEEEEEE",
      "                ",
      "                "
    ],
    [
      "  j   n        n",
      "   jopp        p",
      "          KK   p",
      "          KK    ",
      "                ",
      "                ",
      "   npp          ",
      " L   pnu uwwuunp",
      " L  MpNN   O PQp",
      " L  Mp N       p",
      "    LpDD  R  STp",
      "uu   pUV       p",
      " EEuup J  WQ TXp",
      "    uuuEEuuuEEuu",
      "                ",
      "                "
    ],
    [
      "  j   n Y    Y n",
      "   jopp        p",
      "               p",
      "                ",
      "                ",
      "                ",
      "   npp          ",
      " Z  0pnu uwwuunp",
      " Z  1p         p",
      " Z  Zp         p",
      "    2pDD       p",
      "uu   p3J       p",
      " EEuup J       p",
      "    uuuEEuuuEEuu",
      "                ",
      "                "
    ],
    [
      "  n   n 4Y  Y4 n",
      "   nopp        p",
      "               p",
      "                ",
      "n               ",
      " nn             ",
      "   npp          ",
      "    0pnnnnnnnnnp",
      "    0p         p",
      "     p         p",
      "     p         p",
      "EE   p         p",
      " EEEEp         p",
      "    EEEEEEEEEEEE",
      "                ",
      "                "
    ],
    [
      "  pp55p644 Y446p",
      "   pppp66666666p",
      "      pppppppppp",
      "      7        7",
      "p     7        7",
      "ppp   7        7",
      "55pppp7        7",
      "55555ppppppppppp",
      "55555p555555555p",
      "55555p555555555p",
      "55555p555555555p",
      "EE555p555555555p",
      " EEEEp555555555p",
      "    EEEEEEEEEEEE",
      "                ",
      "                "
    ]
  ]
}