{
  "name": "multi_nuclearpowerplant_3_base5",
  "refpalette": "deceasedcraft:multi_nuclearpowerplant_3/multi_nuclearpowerplant_3_base5_palette",
  "xsize": 16,
  "zsize": 16,
  "slices": [
    [
      "vaabc           ",
      "vaac            ",
      "vaac            ",
      "vaac            ",
      "vaac            ",
      "vaac            ",
      "vaac            ",
      "vaac            ",
      "vaac            ",
      "vaac            ",
      "vaac            ",
      "vaac            ",
      "vaac            ",
      "vaac            ",
      "vaac            ",
      "vaabc           "
    ],
    [
      "vaabc    de     ",
      "vaac            ",
      "vaac            ",
      "vaac            ",
      "vaac            ",
      "vaac            ",
      "vaac            ",
      "vaac            ",
      "vaac            ",
      "vaac            ",
      "vaac            ",
      "vaac            ",
      "vaac            ",
      "vaac            ",
      "vaac            ",
      "vaabc    fg     "
    ],
    [
      "vaabc           ",
      "vaac     de     ",
      "vaac            ",
      "vaac            ",
      "vaac            ",
      "vaac            ",
      "vaac            ",
      "vaac            ",
      "vaac            ",
      "vaac            ",
      "vaac            ",
      "vaac            ",
      "vaac            ",
      "vaac            ",
      "vaac     fg     ",
      "vaabc           "
    ],
    [
      "vaabc           ",
      "vaac            ",
      "vaac     de     ",
      "vaac            ",
      "vaac            ",
      "vaac            ",
      "vaac            ",
      "vaac            ",
      "vaac            ",
      "vaac            ",
      "vaac            ",
      "vaac            ",
      "vaac            ",
      "vaac     fg     ",
      "vaac            ",
      "vaabc           "
    ],
    [
      "vaabc           ",
      "vaac            ",
      "vaac            ",
      "vaac     de     ",
      "vaac            ",
      "vaac            ",
      "vaac            ",
      "vaac            ",
      "vaac            ",
      "vaac            ",
      "vaac            ",
      "vaac            ",
      "vaac     fg     ",
      "vaac            ",
      "vaac            ",
      "vaabc           "
    ],
    [
      "vaabc           ",
      "vaac            ",
      "vaac            ",
      "vaac            ",
      "vaac     de     ",
      "vaac            ",
      "vaac            ",
      "vaac            ",
      "vaac            ",
      "vaac            ",
      "vaac            ",
      "vaac     fg     ",
      "vaac            ",
      "vaac            ",
      "vaac            ",
      "vaabc           "
    ]
  ]
}