{
  "name": "multi_nuclearpowerplant_3_base12",
  "refpalette": "deceasedcraft:multi_nuclearpowerplant_3/multi_nuclearpowerplant_3_base12_palette",
  "xsize": 16,
  "zsize": 16,
  "slices": [
    [
      "vaaaaaaaaaaaaaaa",
      "vaaaaaaaaaaaaaaa",
      "vaaaaaaaaaaaaaaa",
      "vaaaaaaaaaaaaaaa",
      "vaaaaaaaaaaaaaaa",
      "vaaaaaaaaaaaaaaa",
      "vaaaaaaaaaaaaaaa",
      "vaaaaaaaaaaaaaaa",
      "vaaaaaaaaaaaaaaa",
      "vaaaaaaaaaaaaaaa",
      "vaaaaaaaaaaaaaaa",
      "vaaaaaaaaaaaaaaa",
      "vaaaaaaaaaaaaaaa",
      "vaaaaaaaaaaaaaaa",
      "vaaaaaaaaaaaaaaa",
      "vaaaaaaaaaaaaaaa"
    ],
    [
      "vaaabbbbbbbbbbbb",
      "vaaabbbbbbbbbbbb",
      "vaaabbbbbbbbbbbb",
      "vaaabbbbbbbbbbbb",
      "vaaabbbbbbbbbbbb",
      "vbbbbbbbbbbbbbbb",
      "vbbbbbbbbbbbbbbb",
      "vbbbbbbbbbbbbbbb",
      "vbbbbbbbbbbbbbbb",
      "vbbbbbbbbbbbbbbb",
      "vbbbbbbbbbbbbbbb",
      "vaaabbbbbbbbbbbb",
      "vaaabbbbbbbbbbbb",
      "vaaabbbbbbbbbbbb",
      "vaaabbbbbbbbbbbb",
      "vaaabbbbbbbbbbbb"
    ],
    [
      "vaaabcddddddceee",
      "vaaabcddddddcbbb",
      "vaaabcddddddcbbb",
      "vaaabcddddddcbbb",
      "vbbbbccccccccbbb",
      "vffffffffffffbbb",
      "vffffffffffffbbb",
      "vffffffffffffbbb",
      "vffffffffffffbbb",
      "vffffffffffffbbb",
      "vffffffffffffbbb",
      "vbbbbccccccccbbb",
      "vaaabcddddddcbbb",
      "vaaabcddddddcbbb",
      "vaaabcddddddcbbb",
      "vaaabcddddddcggg"
    ],
    [
      "vaaabh      hiii",
      "vaaabh      hbbb",
      "vaaabh      hbbb",
      "vbbbbhjjjjjjhbbk",
      "vffffffffffffbbk",
      "vffffffffffflbkk",
      "v mmnnnoooopqkkk",
      "v mmnnnoooorqkkk",
      "v mmnnnoooopqkkk",
      "v mmnnnoooorqkkk",
      "vffffffffffflbkk",
      "vffffffffffffbbk",
      "vbbbbhjjjjjjhbbk",
      "vaaabh      hbbb",
      "vaaabh      hbbb",
      "vaaabh      hsss"
    ],
    [
      "vaaabh     t@iii",
      "vaaabh     thbbb",
      "vaaabh     thbbb",
      "vbbbbhjjjjjthbbb",
      "vffffffffffufbb ",
      "v mmnnnoooorwb  ",
      "v mmnnnoooo     ",
      "v mmnnnoooo     ",
      "v mmnnnoooo     ",
      "v mmnnnoooo     ",
      "v mmnnnoooopxb  ",
      "vffffffffffyfbb ",
      "vbbbbhjjjjjAhbbb",
      "vaaabh     Ahbbb",
      "vaaabh     Ahbbb",
      "vaaabh     A@sss"
    ],
    [
      "vaaabh     t@iii",
      "vaaabh     thbbb",
      "vaaabh     thbbb",
      "vbbbbhjjjjjthbbb",
      "vffffffffffufbb ",
      "v mmnnnoooopwb  ",
      "v mmnnnoooo     ",
      "v mmnnnoooo     ",
      "v mmnnnoooo     ",
      "v mmnnnoooo     ",
      "v mmnnnoooopxb  ",
      "vffffffffffyfbb ",
      "vbbbbhjjjjjAhbbb",
      "vaaabh     Ahbbb",
      "vaaabh     Ahbbb",
      "vaaabh     A@sss"
    ]
  ]
}