{
  "name": "multi_nuclearpowerplant_3_base10",
  "refpalette": "deceasedcraft:multi_nuclearpowerplant_3/multi_nuclearpowerplant_3_base10_palette",
  "xsize": 16,
  "zsize": 16,
  "slices": [
    [
      "vaaabcd     c   ",
      "vaaabcd     c   ",
      "vaaabcd     c   ",
      "vaaabcd     c   ",
      "vaaabce    fc   ",
      "vaaabcd     c   ",
      "vaaabcd     c   ",
      "vaaabcd     c   ",
      "vaaabcd     c   ",
      "vaaabcd     c   ",
      "vaaabcd     c   ",
      "vaaabce    fc   ",
      "vaaabcd     c   ",
      "vaaabcd     c   ",
      "vaaabcd     c   ",
      "vaaabcd     c   "
    ],
    [
      "vaaabcg     c   ",
      "vaaabcg     c   ",
      "vaaabcg     c   ",
      "vaaabcg     c   ",
      "vaaabcg    fc   ",
      "vaaabcg     c   ",
      "vaaabcg     h   ",
      "vaaabcg     h   ",
      "vaaabcg     h   ",
      "vaaabcg     h   ",
      "vaaabcg     c   ",
      "vaaabcg    fc   ",
      "vaaabcg     c   ",
      "vaaabcg     c   ",
      "vaaabcg     c   ",
      "vaaabcg     c   "
    ],
    [
      "vaaabc      c   ",
      "vaaabc      c   ",
      "vaaabc      c   ",
      "vaaabc      c   ",
      "vaaabc     fc   ",
      "vaaabc      c   ",
      "vaaabc      c   ",
      "vaaabc      c   ",
      "vaaabc      c   ",
      "vaaabc      h   ",
      "vaaabc      c   ",
      "vaaabc     fc   ",
      "vaaabc      c   ",
      "vaaabc      c   ",
      "vaaabc      c   ",
      "vaaabc      c   "
    ],
    [
      "vaaabc      c   ",
      "vaaabc      c   ",
      "vaaabc      c   ",
      "vaaabc      c   ",
      "vaaabc     fc   ",
      "vaaabc      c   ",
      "vaaabc      c   ",
      "vaaabc      c   ",
      "vaaabc      c   ",
      "vaaabc      h   ",
      "vaaabc      c   ",
      "vaaabc     fc   ",
      "vaaabc      c   ",
      "vaaabc      c   ",
      "vaaabc      c   ",
      "vaaabc      c   "
    ],
    [
      "vaaabc      c   ",
      "vaaabc      c   ",
      "vaaabc      c   ",
      "vaaabc      c   ",
      "vaaabc fffffc   ",
      "vaaabc      c   ",
      "vaaabc      h   ",
      "vaaabc      h   ",
      "vaaabc      h   ",
      "vaaabc      c   ",
      "vaaabc      c   ",
      "vaaabc fffffc   ",
      "vaaabc      c   ",
      "vaaabc      c   ",
      "vaaabc      c   ",
      "vaaabc      c   "
    ],
    [
      "vaaabc      c   ",
      "vaaabc      c   ",
      "vaaabc      c   ",
      "vaaabc      c   ",
      "vaaabc f    c   ",
      "vaaabc      c   ",
      "vaaabc      c   ",
      "vaaabc      c   ",
      "vaaabc      c   ",
      "vaaabc      c   ",
      "vaaabc      c   ",
      "vaaabc f    c   ",
      "vaaabc      c   ",
      "vaaabc      c   ",
      "vaaabc      c   ",
      "vaaabc      c   "
    ]
  ]
}