{
  "name": "multi_nuclearpowerplant_3_base2",
  "refpalette": "deceasedcraft:multi_nuclearpowerplant_3/multi_nuclearpowerplant_3_base2_palette",
  "xsize": 16,
  "zsize": 16,
  "slices": [
    [
      "v   a           ",
      "v  a            ",
      "v  a            ",
      "v  a            ",
      "v  a            ",
      "v  a bc         ",
      "v  a dddd       ",
      "v  a dddd       ",
      "v  a dddd       ",
      "v  a dddd       ",
      "v  a ef         ",
      "v  a            ",
      "v  a            ",
      "v  a            ",
      "v  a            ",
      "v   a           "
    ],
    [
      "v   a           ",
      "v  a            ",
      "v  a            ",
      "v  a            ",
      "v  a            ",
      "v  a   ef       ",
      "v  a g  h       ",
      "v  a g  h       ",
      "v  a g  h       ",
      "v  a g  h       ",
      "v  a   bc       ",
      "v  a            ",
      "v  a            ",
      "v  a            ",
      "v  a            ",
      "v   a           "
    ],
    [
      "v   a           ",
      "v  a            ",
      "v  a            ",
      "v  a            ",
      "v  a   ef       ",
      "v  a            ",
      "v  a            ",
      "v  a            ",
      "v  a            ",
      "v  a            ",
      "v  a            ",
      "v  a   bc       ",
      "v  a            ",
      "v  a            ",
      "v  a            ",
      "v   a           "
    ],
    [
      "v   a           ",
      "v  a            ",
      "v  a            ",
      "v  a   ef       ",
      "v  a            ",
      "v  a            ",
      "v  a            ",
      "v  a            ",
      "v  a            ",
      "v  a            ",
      "v  a            ",
      "v  a            ",
      "v  a   bc       ",
      "v  a            ",
      "v  a            ",
      "v   a           "
    ],
    [
      "v   a           ",
      "v  a            ",
      "v  a   ef       ",
      "v  a            ",
      "v  a            ",
      "v  a            ",
      "v  a            ",
      "v  a            ",
      "v  a            ",
      "v  a            ",
      "v  a            ",
      "v  a            ",
      "v  a            ",
      "v  a   bc       ",
      "v  a            ",
      "v   a           "
    ],
    [
      "v   a    iiiiiii",
      "v  a   ejiiiiiii",
      "v  a     iiiiiii",
      "v  a     iiiiiii",
      "v  a     iiiiiii",
      "v  a     iiiiiii",
      "v  a     iiiiiii",
      "v  a     iiiiiii",
      "v  a     iiiiiii",
      "v  a     iiiiiii",
      "v  a     iiiiiii",
      "v  a     iiiiiii",
      "v  a     iiiiiii",
      "v  a     iiiiiii",
      "v  a   bciiiiiii",
      "v   a    iiiiiii"
    ]
  ]
}