{
  "name": "multi_nuclearpowerplant_3_base11",
  "refpalette": "deceasedcraft:multi_nuclearpowerplant_3/multi_nuclearpowerplant_3_base11_palette",
  "xsize": 16,
  "zsize": 16,
  "slices": [
    [
      "vaaabc     d@eee",
      "vaaabc     dcbbb",
      "vaaabc     dcbbb",
      "vbbbbcfffffdcbbb",
      "vgggggggggghgbb ",
      "v iijjjkkkklmb  ",
      "v iijjjkkkk     ",
      "v iijjjkkkk     ",
      "v iijjjkkkk     ",
      "v iijjjkkkk     ",
      "v iijjjkkkklnb  ",
      "vggggggggggogbb ",
      "vbbbbcfffffpcbbb",
      "vaaabc     pcbbb",
      "vaaabc     pcbbb",
      "vaaabc     p@qqq"
    ],
    [
      "vaaabc     d@eee",
      "vaaabc     dcbbb",
      "vaaabc     dcbbb",
      "vbbbbcfffffdcbbb",
      "vgggggggggghgbb ",
      "v iijjjkkkkrmb  ",
      "v iijjjkkkk     ",
      "v iijjjkkkk     ",
      "v iijjjkkkk     ",
      "v iijjjkkkk     ",
      "v iijjjkkkkrnb  ",
      "vggggggggggogbb ",
      "vbbbbcfffffpcbbb",
      "vaaabc     pcbbb",
      "vaaabc     pcbbb",
      "vaaabc     p@qqq"
    ],
    [
      "vaaabc      ceee",
      "vaaabc      cbbb",
      "vaaabc      cbbb",
      "vbbbbcfffffscbbb",
      "vggggggggggggbbb",
      "vgggggggggggtbbb",
      "v iijjjkkkkrubbb",
      "v iijjjkkkkrubbb",
      "v iijjjkkkkrubbb",
      "v iijjjkkkklubbb",
      "vgggggggggggtbbb",
      "vggggggggggggbbb",
      "vbbbbcfffffwcbbb",
      "vaaabc      cbbb",
      "vaaabc      cbbb",
      "vaaabc      cqqq"
    ],
    [
      "vaaabc      c   ",
      "vaaabc      cbbb",
      "vaaabc      cbbb",
      "vaaabc      cbbb",
      "vbbbbcxffffycbbb",
      "vggggggggggggbbb",
      "vggggggggggggbbb",
      "vggggggggggggbbb",
      "vggggggggggggbbb",
      "vggggggggggggbbb",
      "vggggggggggggbbb",
      "vbbbbcxffffycbbb",
      "vaaabc      cbbb",
      "vaaabc      cbbb",
      "vaaabc      cbbb",
      "vaaabc      c   "
    ],
    [
      "vaaabc      c   ",
      "vaaabc      c   ",
      "vaaabc      cAAA",
      "vaaabc      cAAA",
      "vaaabcB    ycAAA",
      "vbbbbcffffffcAAA",
      "vbbbbcffffffcAAA",
      "vbbbbcffffffcAAA",
      "vbbbbcffffffcAAA",
      "vbbbbcffffffcAAA",
      "vbbbbcffffffcAAA",
      "vaaabcB    ycAAA",
      "vaaabc      cAAA",
      "vaaabc      cAAA",
      "vaaabc      c   ",
      "vaaabc      c   "
    ],
    [
      "vaaabc      c   ",
      "vaaabc      c   ",
      "vaaabc      c   ",
      "vaaabc      c   ",
      "vaaabcB    yc   ",
      "vaaabc      c   ",
      "vaaabc      c   ",
      "vaaabc      c   ",
      "vaaabc      c   ",
      "vaaabc      c   ",
      "vaaabc      c   ",
      "vaaabcB    yc   ",
      "vaaabc      c   ",
      "vaaabc      c   ",
      "vaaabc      c   ",
      "vaaabc      c   "
    ]
  ]
}