{
  "name": "multi_nuclearpowerplant_3_base6",
  "refpalette": "deceasedcraft:multi_nuclearpowerplant_3/multi_nuclearpowerplant_3_base6_palette",
  "xsize": 16,
  "zsize": 16,
  "slices": [
    [
      "vvvva           ",
      "vvva            ",
      "vvvab           ",
      "vvvacb          ",
      "vvvab           ",
      "vvvab           ",
      "vvvacb          ",
      "vvvab           ",
      "vvvab           ",
      "vvvacb          ",
      "vvvab           ",
      "vvvab           ",
      "vvvacb          ",
      "vvvab           ",
      "vvva            ",
      "vvvva           "
    ],
    [
      "vddde           ",
      "vdde            ",
      "vdde            ",
      "vdde            ",
      "vdde            ",
      "vdde            ",
      "vdde            ",
      "vdde            ",
      "vdde            ",
      "vdde            ",
      "vdde            ",
      "vdde            ",
      "vdde            ",
      "vdde            ",
      "vdde            ",
      "vddde           "
    ],
    [
      "vccfe           ",
      "vcce            ",
      "vcce            ",
      "vcce            ",
      "vcce            ",
      "vcce            ",
      "vcce            ",
      "vcce            ",
      "vcce            ",
      "vcce            ",
      "vcce            ",
      "vcce            ",
      "vcce            ",
      "vcce            ",
      "vcce            ",
      "vccfe           "
    ],
    [
      "vccge           ",
      "vcce            ",
      "vcce            ",
      "vcce            ",
      "vcce            ",
      "vcce            ",
      "vcce            ",
      "vcce            ",
      "vcce            ",
      "vcce            ",
      "vcce            ",
      "vcce            ",
      "vcce            ",
      "vcce            ",
      "vcce            ",
      "vccge           "
    ],
    [
      "vccge           ",
      "vcce            ",
      "vcce            ",
      "vcce            ",
      "vcce            ",
      "vcce            ",
      "vcce            ",
      "vcce            ",
      "vcce            ",
      "vcce            ",
      "vcce            ",
      "vcce            ",
      "vcce            ",
      "vcce            ",
      "vcce            ",
      "vccge           "
    ],
    [
      "vccge           ",
      "vcce            ",
      "vcce            ",
      "vcce            ",
      "vcce            ",
      "vcce            ",
      "vcce            ",
      "vcce            ",
      "vcce            ",
      "vcce            ",
      "vcce            ",
      "vcce            ",
      "vcce            ",
      "vcce            ",
      "vcce            ",
      "vccge           "
    ]
  ]
}