{
  "name": "multi_nuclearpowerplant_3_base9",
  "refpalette": "deceasedcraft:multi_nuclearpowerplant_3/multi_nuclearpowerplant_3_base9_palette",
  "xsize": 16,
  "zsize": 16,
  "slices": [
    [
      "vaaabbcddddce   ",
      "vaaabbcddddce   ",
      "vaaabbcddddce   ",
      "vaaabbcddddce   ",
      "vaaabbcfdddce   ",
      "vaaabbcddddce   ",
      "vaaabbcddddce   ",
      "vaaabbcddddce   ",
      "vaaabbcddddce   ",
      "vaaabbcddddce   ",
      "vaaabbcddddce   ",
      "vaaabbcfdddce   ",
      "vaaabbcddddce   ",
      "vaaabbcddddce   ",
      "vaaabbcddddce   ",
      "vaaabbcddddce   "
    ],
    [
      "vaaabbg    e    ",
      "vaaabbg    e    ",
      "vaaabbg    e    ",
      "vaaabbg    e    ",
      "vaaabbgf   e    ",
      "vaaabbg    e    ",
      "vaaabbg    e    ",
      "vaaabbg    e    ",
      "vaaabbg    e    ",
      "vaaabbg    e    ",
      "vaaabbg    e    ",
      "vaaabbgf   e    ",
      "vaaabbg    e    ",
      "vaaabbg    e    ",
      "vaaabbg    e    ",
      "vaaabbg    e    "
    ],
    [
      "vaaabbg         ",
      "vaaabbg         ",
      "vaaabbg         ",
      "vaaabbg         ",
      "vaaabbgf        ",
      "vaaabbg         ",
      "vaaabbg         ",
      "vaaabbg         ",
      "vaaabbg         ",
      "vaaabbg         ",
      "vaaabbg         ",
      "vaaabbgf        ",
      "vaaabbg         ",
      "vaaabbg         ",
      "vaaabbg         ",
      "vaaabbg         "
    ],
    [
      "vaaabbg         ",
      "vaaabbg         ",
      "vaaabbg         ",
      "vaaabbg         ",
      "vaaabbgf        ",
      "vaaabbg         ",
      "vaaabbg         ",
      "vaaabbg         ",
      "vaaabbg         ",
      "vaaabbg         ",
      "vaaabbg         ",
      "vaaabbgf        ",
      "vaaabbg         ",
      "vaaabbg         ",
      "vaaabbg         ",
      "vaaabbg         "
    ],
    [
      "vaaabbg f       ",
      "vaaabbg f       ",
      "vaaabbg f       ",
      "vaaabbg f       ",
      "vaaabbgff       ",
      "vaaabbg f       ",
      "vaaabbg f       ",
      "vaaabbg f       ",
      "vaaabbg f       ",
      "vaaabbg f       ",
      "vaaabbg f       ",
      "vaaabbgff       ",
      "vaaabbg f       ",
      "vaaabbg f       ",
      "vaaabbg f       ",
      "vaaabbg f       "
    ],
    [
      "vaaabbg         ",
      "vaaabbg         ",
      "vaaabbg         ",
      "vaaabbg         ",
      "vaaabbg         ",
      "vaaabbg         ",
      "vaaabbg         ",
      "vaaabbg         ",
      "vaaabbg         ",
      "vaaabbg         ",
      "vaaabbg         ",
      "vaaabbg         ",
      "vaaabbg         ",
      "vaaabbg         ",
      "vaaabbg         ",
      "vaaabbg         "
    ]
  ]
}