{
  "name": "multi_nuclearpowerplant_3_base7",
  "refpalette": "deceasedcraft:multi_nuclearpowerplant_3/multi_nuclearpowerplant_3_base7_palette",
  "xsize": 16,
  "zsize": 16,
  "slices": [
    [
      "vaaabccccccccccc",
      "vaabcccccccccccc",
      "vaabcccccccccccc",
      "vaabcccccccccccc",
      "vaabcccccccccccc",
      "vaabcccccccccccc",
      "vaabcccccccccccc",
      "vaabcccccccccccc",
      "vaabcccccccccccc",
      "vaabcccccccccccc",
      "vaabcccccccccccc",
      "vaabcccccccccccc",
      "vaabcccccccccccc",
      "vaabcccccccccccc",
      "vaabcccccccccccc",
      "vaaabccccccccccc"
    ],
    [
      "vaaabccccccccccc",
      "vaabcccccccccccc",
      "vaabcccccccccccc",
      "vaabcccccccccccc",
      "vaabcccccccccccc",
      "vaabcccccccccccc",
      "vaabcccccccccccc",
      "vaabcccccccccccc",
      "vaabcccccccccccc",
      "vaabcccccccccccc",
      "vaabcccccccccccc",
      "vaabcccccccccccc",
      "vaabcccccccccccc",
      "vaabcccccccccccc",
      "vaabcccccccccccc",
      "vaaabccccccccccc"
    ],
    [
      "vaaabccccccccccc",
      "vaabcccccccccccc",
      "vaabcccccccccccc",
      "vaabcccccccccccc",
      "vaabcccccccccccc",
      "vaabcccccccccccc",
      "vaabcccccccccccc",
      "vaabcccccccccccc",
      "vaabcccccccccccc",
      "vaabcccccccccccc",
      "vaabcccccccccccc",
      "vaabcccccccccccc",
      "vaabcccccccccccc",
      "vaabcccccccccccc",
      "vaabcccccccccccc",
      "vaaabccccccccccc"
    ],
    [
      "vaaabccccccccccc",
      "vaabcccccccccccc",
      "vaabcccccccccccc",
      "vaabcccccccccccc",
      "vaabcccccccccccc",
      "vaabcccccccccccc",
      "vaabcccccccccccc",
      "vaabcccccccccccc",
      "vaabcccccccccccc",
      "vaabcccccccccccc",
      "vaabcccccccccccc",
      "vaabcccccccccccc",
      "vaabcccccccccccc",
      "vaabcccccccccccc",
      "vaabcccccccccccc",
      "vaaabccccccccccc"
    ],
    [
      "vaaabccccccccccc",
      "vaabcccccccccccc",
      "vaabcccccccccccc",
      "vaabcccccccccccc",
      "vaabcccccccccccc",
      "vaabcccccccccccc",
      "vaabcccccccccccc",
      "vaabcccccccccccc",
      "vaabcccccccccccc",
      "vaabcccccccccccc",
      "vaabcccccccccccc",
      "vaabcccccccccccc",
      "vaabcccccccccccc",
      "vaabcccccccccccc",
      "vaabcccccccccccc",
      "vaaabccccccccccc"
    ],
    [
      "vdddbccccccccccc",
      "vddbcccccccccccc",
      "vddbcccccccccccc",
      "vddbcccccccccccc",
      "vddbcccccccccccc",
      "vddbcccccccccccc",
      "vddbcccccccccccc",
      "vddbcccccccccccc",
      "vddbcccccccccccc",
      "vddbcccccccccccc",
      "vddbcccccccccccc",
      "vddbcccccccccccc",
      "vddbcccccccccccc",
      "vddbcccccccccccc",
      "vddbcccccccccccc",
      "vdddbccccccccccc"
    ]
  ]
}