{
  "name": "multi_nuclearpowerplant_3_base8",
  "refpalette": "deceasedcraft:multi_nuclearpowerplant_3/multi_nuclearpowerplant_3_base8_palette",
  "xsize": 16,
  "zsize": 16,
  "slices": [
    [
      "vaaabbcddddddddd",
      "vaaabbcddddddddd",
      "vaaabbcddddddddd",
      "vaaabbcddddddddd",
      "vaaabbcddddddddd",
      "vaaabbcddddddddd",
      "vaaabbcddddddddd",
      "vaaabbcddddddddd",
      "vaaabbcddddddddd",
      "vaaabbcddddddddd",
      "vaaabbcddddddddd",
      "vaaabbcddddddddd",
      "vaaabbcddddddddd",
      "vaaabbcddddddddd",
      "vaaabbcddddddddd",
      "vaaabbcddddddddd"
    ],
    [
      "vaaaefffffffffff",
      "vaaeffffffffffff",
      "vaaeffffffffffff",
      "vaaeffffffffffff",
      "vaaeffffffffffff",
      "vaaeffffffffffff",
      "vaaeffffffffffff",
      "vaaeffffffffffff",
      "vaaeffffffffffff",
      "vaaeffffffffffff",
      "vaaeffffffffffff",
      "vaaeffffffffffff",
      "vaaeffffffffffff",
      "vaaeffffffffffff",
      "vaaeffffffffffff",
      "vaaaefffffffffff"
    ],
    [
      "vaaaghhhhhhhhhhh",
      "vaaghhhhhhhhhhhh",
      "vaaghhhhhhhhhhhh",
      "vaaghhhhhhhhhhhh",
      "vaaghhhhhhhhhhhh",
      "vaaghhhhhhhhhhhh",
      "vaaghhhhhhhhhhhh",
      "vaaghhhhhhhhhhhh",
      "vaaghhhhhhhhhhhh",
      "vaaghhhhhhhhhhhh",
      "vaaghhhhhhhhhhhh",
      "vaaghhhhhhhhhhhh",
      "vaaghhhhhhhhhhhh",
      "vaaghhhhhhhhhhhh",
      "vaaghhhhhhhhhhhh",
      "vaaaghhhhhhhhhhh"
    ],
    [
      "vaaaghhhhhhhhhhh",
      "vaaghhhhhhhhhhhh",
      "vaaghhhhhhhhhhhh",
      "vaaghhhhhhhhhhhh",
      "vaaghhhhhhhhhhhh",
      "vaaghhhhhhhhhhhh",
      "vaaghhhhhhhhhhhh",
      "vaaghhhhhhhhhhhh",
      "vaaghhhhhhhhhhhh",
      "vaaghhhhhhhhhhhh",
      "vaaghhhhhhhhhhhh",
      "vaaghhhhhhhhhhhh",
      "vaaghhhhhhhhhhhh",
      "vaaghhhhhhhhhhhh",
      "vaaghhhhhhhhhhhh",
      "vaaaghhhhhhhhhhh"
    ],
    [
      "vaaaghhhhhhhhhhh",
      "vaaghhhhhhhhhhhh",
      "vaaghhhhhhhhhhhh",
      "vaaghhhhhhhhhhhh",
      "vaaghhhhhhhhhhhh",
      "vaaghhhhhhhhhhhh",
      "vaaghhhhhhhhhhhh",
      "vaaghhhhhhhhhhhh",
      "vaaghhhhhhhhhhhh",
      "vaaghhhhhhhhhhhh",
      "vaaghhhhhhhhhhhh",
      "vaaghhhhhhhhhhhh",
      "vaaghhhhhhhhhhhh",
      "vaaghhhhhhhhhhhh",
      "vaaghhhhhhhhhhhh",
      "vaaaghhhhhhhhhhh"
    ],
    [
      "vaaaghhhhhhhhhhh",
      "vaaghhhhhhhhhhhh",
      "vaaghhhhhhhhhhhh",
      "vaaghhhhhhhhhhhh",
      "vaaghhhhhhhhhhhh",
      "vaaghhhhhhhhhhhh",
      "vaaghhhhhhhhhhhh",
      "vaaghhhhhhhhhhhh",
      "vaaghhhhhhhhhhhh",
      "vaaghhhhhhhhhhhh",
      "vaaghhhhhhhhhhhh",
      "vaaghhhhhhhhhhhh",
      "vaaghhhhhhhhhhhh",
      "vaaghhhhhhhhhhhh",
      "vaaghhhhhhhhhhhh",
      "vaaaghhhhhhhhhhh"
    ]
  ]
}