{
  "name": "multi_nuclearpowerplant_3_base3",
  "refpalette": "deceasedcraft:multi_nuclearpowerplant_3/multi_nuclearpowerplant_3_base3_palette",
  "xsize": 16,
  "zsize": 16,
  "slices": [
    [
      "vaa b  cd       ",
      "vaab            ",
      "vaab            ",
      "vaab            ",
      "vaab            ",
      "vaab            ",
      "vaab            ",
      "vaab            ",
      "vaab            ",
      "vaab            ",
      "vaab            ",
      "vaab            ",
      "vaab            ",
      "vaab            ",
      "vaab            ",
      "vaa b  ef       "
    ],
    [
      "v g hef         ",
      "v gh            ",
      "v gh            ",
      "v gh            ",
      "v gh            ",
      "v gh            ",
      "v gh            ",
      "v gh            ",
      "v gh            ",
      "v gh            ",
      "v gh            ",
      "v gh            ",
      "v gh            ",
      "v gh            ",
      "v gh            ",
      "v g hcd         "
    ],
    [
      "v   h           ",
      "v  h ef         ",
      "v  h            ",
      "v  h            ",
      "v  h            ",
      "v  h            ",
      "v  h            ",
      "v  h            ",
      "v  h            ",
      "v  h            ",
      "v  h            ",
      "v  h            ",
      "v  h            ",
      "v  h            ",
      "v  h cd         ",
      "v   h           "
    ],
    [
      "v   h           ",
      "v  h            ",
      "v  h ef         ",
      "v  h            ",
      "v  h            ",
      "v  h            ",
      "v  h            ",
      "v  h            ",
      "v  h            ",
      "v  h            ",
      "v  h            ",
      "v  h            ",
      "v  h            ",
      "v  h cd         ",
      "v  h            ",
      "v   h           "
    ],
    [
      "v   h           ",
      "v  h            ",
      "v  h            ",
      "v  h ef         ",
      "v  h            ",
      "v  h            ",
      "v  h            ",
      "v  h            ",
      "v  h            ",
      "v  h            ",
      "v  h            ",
      "v  h            ",
      "v  h cd         ",
      "v  h            ",
      "v  h            ",
      "v   h           "
    ],
    [
      "v   h           ",
      "v  h            ",
      "v  h            ",
      "v  h            ",
      "v  h ef         ",
      "v  h            ",
      "v  h            ",
      "v  h            ",
      "v  h            ",
      "v  h            ",
      "v  h            ",
      "v  h cd         ",
      "v  h            ",
      "v  h            ",
      "v  h            ",
      "v   h           "
    ]
  ]
}