{
  "name": "multi_nuclearpowerplant_3_ground",
  "refpalette": "deceasedcraft:multi_nuclearpowerplant_3/multi_nuclearpowerplant_3_ground_palette",
  "xsize": 16,
  "zsize": 16,
  "slices": [
    [
      "zaaaabc         ",
      "aaaabbc         ",
      "aaaabcc         ",
      "aaaabc          ",
      "aaaabc          ",
      "aaaabc          ",
      "aaaabc          ",
      "aaaabc          ",
      "aaaabc          ",
      "aaaabc          ",
      "aaaabc          ",
      "aaaabc          ",
      "aaaabc          ",
      "aaaabcc         ",
      "aaaabbc         ",
      "zaaaabc         "
    ],
    [
      "    dzcc        ",
      "   ezzcc        ",
      "   ezccc        ",
      "   eaccc        ",
      "   ezccc        ",
      "   ezcc         ",
      "   eacc         ",
      "   ezcc         ",
      "   ezcc         ",
      "   ezcc         ",
      "   ezcc         ",
      "   ezccc        ",
      "   ezccc        ",
      "   ezccc        ",
      "   ezzcc        ",
      "f   gzcc        "
    ],
    [
      "     hzccc      ",
      "    hhzcc       ",
      "    hzzcc       ",
      "    hzzcc       ",
      "    haccc       ",
      "    haccc       ",
      "    hzccc       ",
      "    hzccc       ",
      "    hzccc       ",
      "    hzccc       ",
      "    hzccc       ",
      "    haccc       ",
      "    hzzcc       ",
      "    hzzcc       ",
      "    hhacc       ",
      "     hzccc      "
    ],
    [
      "     h zccc     ",
      "    hh zccc     ",
      "    hfzaccc     ",
      "    hf zcc      ",
      "    h zzcc      ",
      "    h zzcc      ",
      "    hizzcc      ",
      "    h zzcc      ",
      "    h azcc      ",
      "    h zzcc      ",
      "    h zzcc      ",
      "    h zzcc      ",
      "    hfzzcc      ",
      "    h  zccc     ",
      "    hh zccc     ",
      "     hfzccc     "
    ],
    [
      "     j fzacc    ",
      "    j  fzacc    ",
      "    j   zccc    ",
      "    j  fzccc    ",
      "    j fkzccc    ",
      "    j f zcc     ",
      "    j   zcc     ",
      "    j  fzcc     ",
      "    j   zcc     ",
      "    j ffzcc     ",
      "    j fzzcc     ",
      "    j  kzccc    ",
      "    j   zccc    ",
      "    j   zccc    ",
      "    j   zzcc    ",
      "     j fzzcc    "
    ],
    [
      "        i accc  ",
      "        f zcc   ",
      "        fzzcc   ",
      "         zzcc   ",
      "         zccc   ",
      "        zzccc   ",
      "         zccc   ",
      "         accc   ",
      "        izccc   ",
      "         zccc   ",
      "       ffzccc   ",
      "         zccc   ",
      "        fzzcc   ",
      "        fzzcc   ",
      "        fkzcc   ",
      "        i zccc  "
    ]
  ]
}