{
  "name": "multi_nuclearpowerplant_3_base4",
  "refpalette": "deceasedcraft:multi_nuclearpowerplant_3/multi_nuclearpowerplant_3_base4_palette",
  "xsize": 16,
  "zsize": 16,
  "slices": [
    [
      "vaaab           ",
      "vaab            ",
      "vaab            ",
      "vaab            ",
      "vaab            ",
      "vaab     cd     ",
      "vaab   eeee     ",
      "vaab   eeee     ",
      "vaab   eeee     ",
      "vaab   eeee     ",
      "vaab     fg     ",
      "vaab            ",
      "vaab            ",
      "vaab            ",
      "vaab            ",
      "vaaab           "
    ],
    [
      "vaaab           ",
      "vaab            ",
      "vaab            ",
      "vaab            ",
      "vaab            ",
      "vaab   fg       ",
      "vaab   h  i     ",
      "vaab   h  i     ",
      "vaab   h  i     ",
      "vaab   h  i     ",
      "vaab   cd       ",
      "vaab            ",
      "vaab            ",
      "vaab            ",
      "vaab            ",
      "vaaab           "
    ],
    [
      "vaaab           ",
      "vaab            ",
      "vaab            ",
      "vaab            ",
      "vaab   fg       ",
      "vaab            ",
      "vaab            ",
      "vaab            ",
      "vaab            ",
      "vaab            ",
      "vaab            ",
      "vaab   cd       ",
      "vaab            ",
      "vaab            ",
      "vaab            ",
      "vaaab           "
    ],
    [
      "vaaab           ",
      "vaab            ",
      "vaab            ",
      "vaab   fg       ",
      "vaab            ",
      "vaab            ",
      "vaab            ",
      "vaab            ",
      "vaab            ",
      "vaab            ",
      "vaab            ",
      "vaab            ",
      "vaab   cd       ",
      "vaab            ",
      "vaab            ",
      "vaaab           "
    ],
    [
      "vaaab           ",
      "vaab            ",
      "vaab   fg       ",
      "vaab            ",
      "vaab            ",
      "vaab            ",
      "vaab            ",
      "vaab            ",
      "vaab            ",
      "vaab            ",
      "vaab            ",
      "vaab            ",
      "vaab            ",
      "vaab   cd       ",
      "vaab            ",
      "vaaab           "
    ],
    [
      "vaaab           ",
      "vaab   fg       ",
      "vaab            ",
      "vaa~            ",
      "vaa~            ",
      "vaa~            ",
      "vaa~            ",
      "vaa~            ",
      "vaa~            ",
      "vaa~            ",
      "vaa~            ",
      "vaa~            ",
      "vaa~            ",
      "vaab            ",
      "vaab   cd       ",
      "vaaab           "
    ]
  ]
}