{
  "name": "multi_nuclearpowerplant_3_base1",
  "refpalette": "deceasedcraft:multi_nuclearpowerplant_3/multi_nuclearpowerplant_3_base1_palette",
  "xsize": 16,
  "zsize": 16,
  "slices": [
    [
      "vaaab  cdeeeeeee",
      "vaab     eeeeeee",
      "vaab     eeeeeee",
      "vaab     eeeeeee",
      "vaab     eeeeeee",
      "vaab     eeeeeee",
      "vaab     eeeeeee",
      "vaab     eeeeeee",
      "vaab     eeeeeee",
      "vaab     eeeeeee",
      "vaab     eeeeeee",
      "vaab     eeeeeee",
      "vaab     eeeeeee",
      "vaab     eeeeeee",
      "vaab     eeeeeee",
      "vaaab  fgeeeeeee"
    ],
    [
      "vhhhi    j      ",
      "vhhi     j      ",
      "vhhi     j      ",
      "vhhi     j      ",
      "vhhi     j      ",
      "vhhi     j      ",
      "vhhi     j      ",
      "vhhi     j      ",
      "vhhi     j      ",
      "vhhi     j      ",
      "vhhi     j      ",
      "vhhi     j      ",
      "vhhi     j      ",
      "vhhi     j      ",
      "vhhi     j      ",
      "vhhhi    j      "
    ],
    [
      "vhhhi           ",
      "vhhi            ",
      "vhhi            ",
      "vhhi            ",
      "vhhi            ",
      "vhhi            ",
      "vhhi            ",
      "vhhi            ",
      "vhhi            ",
      "vhhi            ",
      "vhhi            ",
      "vhhi            ",
      "vhhi            ",
      "vhhi            ",
      "vhhi            ",
      "vhhhi           "
    ],
    [
      "vhhhi           ",
      "vhhi            ",
      "vhhi            ",
      "vhhi            ",
      "vhhi            ",
      "vhhi            ",
      "vhhi            ",
      "vhhi            ",
      "vhhi            ",
      "vhhi            ",
      "vhhi            ",
      "vhhi            ",
      "vhhi            ",
      "vhhi            ",
      "vhhi            ",
      "vhhhi           "
    ],
    [
      "vhhhi           ",
      "vhhi            ",
      "vhhi            ",
      "vhhi            ",
      "vhhi            ",
      "vhhi            ",
      "vhhi            ",
      "vhhi            ",
      "vhhi            ",
      "vhhi            ",
      "vhhi            ",
      "vhhi            ",
      "vhhi            ",
      "vhhi            ",
      "vhhi            ",
      "vhhhi           "
    ],
    [
      "vhhhik          ",
      "vhhikk          ",
      "vhhik           ",
      "vhhik           ",
      "vhhik           ",
      "vhhik           ",
      "vhhik           ",
      "vhhik           ",
      "vhhik           ",
      "vhhik           ",
      "vhhik           ",
      "vhhik           ",
      "vhhik           ",
      "vhhik           ",
      "vhhikk          ",
      "vhhhik          "
    ]
  ]
}