{
  "name": "multi_nuclearpowerplant_3_top",
  "refpalette": "deceasedcraft:multi_nuclearpowerplant_3/multi_nuclearpowerplant_3_top_palette",
  "xsize": 16,
  "zsize": 16,
  "slices": [
    [
      "           zaaa ",
      "          bzaaa ",
      "           zaa  ",
      "           zaa  ",
      "          zzaa  ",
      "          zzaa  ",
      "          zzaa  ",
      "         czzaa  ",
      "          zzaa  ",
      "          zzaa  ",
      "          zzaa  ",
      "         bzzaa  ",
      "         bdzaa  ",
      "         bbzaa  ",
      "           zaaa ",
      "          bzaaa "
    ],
    [
      "           bzzaa",
      "            zaaa",
      "            zaaa",
      "           bzaa ",
      "            daa ",
      "           ezaa ",
      "           bzaa ",
      "           zzaa ",
      "          bbzaa ",
      "          b zaa ",
      "            zaa ",
      "          bczaa ",
      "            zaa ",
      "            zaaa",
      "            zaaa",
      "           bzzaa"
    ],
    [
      "            ezza",
      "            bzza",
      "             zaa",
      "            zzaa",
      "             zaa",
      "             zaa",
      "             zaa",
      "             zaa",
      "             zaa",
      "            bzaa",
      "             zaa",
      "            bzaa",
      "             zaa",
      "             daa",
      "             zza",
      "            bbza"
    ],
    [
      "               z",
      "              dz",
      "              zz",
      "             bzz",
      "             czz",
      "              zz",
      "             bzz",
      "             ezz",
      "             bzz",
      "             bzz",
      "             bzz",
      "             zzz",
      "             czz",
      "              zz",
      "              cz",
      "               z"
    ],
    [
      "                ",
      "                ",
      "               b",
      "              b ",
      "              b ",
      "                ",
      "              b ",
      "                ",
      "                ",
      "              bc",
      "                ",
      "               b",
      "              b ",
      "                ",
      "                ",
      "               e"
    ]
  ]
}