{
  "name": "multi_workshop_1_floor2",
  "refpalette": "deceasedcraft:multi_workshop_1/multi_workshop_1_floor2_palette",
  "xsize": 16,
  "zsize": 16,
  "slices": [
    [
      " abbbbbbbbbbbba ",
      " abbbbbbbbbbbba ",
      " acaaacaaacbbbc ",
      "        dHeeeef ",
      "        dHeeeef ",
      "        dHeeeef ",
      "            eef ",
      "            eef ",
      "            eef ",
      "  g   g   gfffg ",
      "                ",
      "                ",
      "                ",
      "                ",
      "                ",
      "                "
    ],
    [
      " ah i jkjl    m ",
      " anooopkpk    a ",
      " acaaacaaacqqqc ",
      "      rHe     r ",
      "      rHe     r ",
      "      rHe     r ",
      "      r       r ",
      "      r       r ",
      "      r       r ",
      "  g   grrrgrrrg ",
      "                ",
      "                ",
      "                ",
      "                ",
      "                ",
      "                "
    ],
    [
      " m sts        m ",
      " guo!o  k     a ",
      " acaaacaaacqqqc ",
      "   ddHe         ",
      "   ddHe         ",
      "   ddHe         ",
      "   dddw         ",
      "   dddw         ",
      "   dddw         ",
      "  g   g   g   g ",
      "                ",
      "                ",
      "                ",
      "                ",
      "                ",
      "                "
    ],
    [
      " a            m ",
      " a            a ",
      " acaaacaaacqqqc ",
      "  fee           ",
      "  fee           ",
      "  fee           ",
      "  feeeeHd       ",
      "  feeeeHd       ",
      "  feeeeHd       ",
      "  gfffgfffg   g ",
      "                ",
      "                ",
      "                ",
      "                ",
      "                ",
      "                "
    ],
    [
      " a            x ",
      " a        y   a ",
      " acaaacaaacAAAc ",
      "  r       r     ",
      "  r       r     ",
      "  r       r     ",
      "  r     eHr     ",
      "  r     eHr     ",
      "  r     eHr     ",
      "  grrrgrrrg   g ",
      "                ",
      "                ",
      "                ",
      "                ",
      "                ",
      "                "
    ],
    [
      " arrrrrrrrrrrra ",
      " aBCBBBCBBDBBBa ",
      " acEffcEffgaaac ",
      "          wddd  ",
      "          wddd  ",
      "          wddd  ",
      "          eHdd  ",
      "          eHdd  ",
      "          eHdd  ",
      "  g   g   g   g ",
      "                ",
      "                ",
      "                ",
      "                ",
      "                ",
      "                "
    ]
  ]
}