{
  "name": "multi_workshop_1_floor3",
  "refpalette": "deceasedcraft:multi_workshop_1/multi_workshop_1_floor3_palette",
  "xsize": 16,
  "zsize": 16,
  "slices": [
    [
      " abbbbbbbbbbbba ",
      " abbbbbbbbbbbba ",
      " acaaacaaacbbbc ",
      "        dHeeeef ",
      "        dHeeeef ",
      "        dHeeeef ",
      "            eef ",
      "            eef ",
      "            eef ",
      "  g   g   gfffg ",
      "                ",
      "                ",
      "                ",
      "                ",
      "                ",
      "                "
    ],
    [
      " ahij kl  j   m ",
      " anokkpqqqr   a ",
      " acaaacaaac   c ",
      "      sHe     s ",
      "      sHe     s ",
      "      sHe     s ",
      "      s       s ",
      "      s       s ",
      "      s       s ",
      "  g   gsssgsssg ",
      "                ",
      "                ",
      "                ",
      "                ",
      "                ",
      "                "
    ],
    [
      " m            m ",
      " go k         a ",
      " acaaacaaactttc ",
      "   ddHe         ",
      "   ddHe         ",
      "   ddHe         ",
      "   dddu         ",
      "   dddu         ",
      "   dddu         ",
      "  g   g   g   g ",
      "                ",
      "                ",
      "                ",
      "                ",
      "                ",
      "                "
    ],
    [
      " a            m ",
      " a     wxw    a ",
      " acaaacaaactttc ",
      "  fee           ",
      "  fee           ",
      "  fee           ",
      "  feeeeHd       ",
      "  feeeeHd       ",
      "  feeeeHd       ",
      "  gfffgfffg   g ",
      "                ",
      "                ",
      "                ",
      "                ",
      "                ",
      "                "
    ],
    [
      " a            y ",
      " a        A   a ",
      " acaaacaaacBBBc ",
      "  s       s     ",
      "  s       s     ",
      "  s       s     ",
      "  s     eHs     ",
      "  s     eHs     ",
      "  s     eHs     ",
      "  gsssgsssg   g ",
      "                ",
      "                ",
      "                ",
      "                ",
      "                ",
      "                "
    ],
    [
      " assssssssssssa ",
      " aCDCCCDCCECCCa ",
      " acFffcIffgaaac ",
      "          uddd  ",
      "          uddd  ",
      "          uddd  ",
      "          eHdd  ",
      "          eHdd  ",
      "          eHdd  ",
      "  g   g   g   g ",
      "                ",
      "                ",
      "                ",
      "                ",
      "                ",
      "                "
    ]
  ]
}