{
  "name": "multi_workshop_1_ground",
  "refpalette": "deceasedcraft:multi_workshop_1/multi_workshop_1_ground_palette",
  "xsize": 16,
  "zsize": 16,
  "slices": [
    [
      "abcddddddddddc=e",
      "abccccccccccccbe",
      "abd===dbbbdbbbde",
      "HH=fffg       ee",
      "HH=fffg       ee",
      "HH=fffg       ee",
      "HHveeeeeeeehhhee",
      "HHveiiiiiiehhhee",
      "HHveiiiiiiehhhee",
      "HHeeeeeeeeeeeeee",
      "HHHHHHHHHHHHHHHe",
      "HHHHHHHHHHHHHHHe",
      "eHHHHHHHHHHHHHHe",
      "eHHHHHHHHHHHHHHe",
      "eHHHHHHHHHHHHHHe",
      "eeeeeeeeeeeeeeee"
    ],
    [
      " b            jk",
      " bl   mnnnopppbk",
      " bd   dbbbdbbbdk",
      "  q           rk",
      "  q           rk",
      "  q           rk",
      "  sHt         rk",
      "  sHtu   u    rk",
      "  sHt  u      rk",
      "  e   errrerrrek",
      "               k",
      "               k",
      "kwxwxwx  wxwxwxk",
      "k           y  k",
      "kABABAB  ABABABk",
      "kkkkkkkkkkkkkkkk"
    ],
    [
      " j            j ",
      " eC      D   Eb ",
      " bdFFFdbbbdbbbd ",
      "                ",
      "                ",
      "                ",
      "    sHI         ",
      "    sHI         ",
      "    sHI         ",
      "  e   e   e   e ",
      "                ",
      "                ",
      "                ",
      "                ",
      "                ",
      "                "
    ],
    [
      " b            j ",
      " b            b ",
      " bdFFFdbbbdbbbd ",
      "                ",
      "                ",
      "                ",
      "      sHt       ",
      "      sHt       ",
      "      sHt       ",
      "  eJJJeJJJe   e ",
      "                ",
      "                ",
      "                ",
      "                ",
      "                ",
      "                "
    ],
    [
      " b            k ",
      " b KKK    L   b ",
      " bdbbbdbbbdbbbd ",
      "  r       r     ",
      "  r       r     ",
      "  r       r     ",
      "  r     sHr     ",
      "  r     sHr     ",
      "  r     sHr     ",
      "  errrerrre   e ",
      "                ",
      "                ",
      "                ",
      "                ",
      "                ",
      "                "
    ],
    [
      " brrrrrrrrrrrrb ",
      " bMNMMMNMMOMMMb ",
      " bdPJJdPJJebbbd ",
      "          Ittt  ",
      "          Ittt  ",
      "          Ittt  ",
      "          sHtt  ",
      "          sHtt  ",
      "          sHtt  ",
      "  e   e   e   e ",
      "                ",
      "                ",
      "                ",
      "                ",
      "                ",
      "                "
    ]
  ]
}