{
  "name": "multi_workshop_1_base1",
  "refpalette": "deceasedcraft:multi_workshop_1/multi_workshop_1_base1_palette",
  "xsize": 16,
  "zsize": 16,
  "slices": [
    [
      "va            av",
      "va       bbb  av",
      "va    acaaaaacav",
      "va   adddeeedddv",
      "va   afddddddddv",
      "va   afddddddddv",
      "va   afddddddddv",
      "va   afddddddddv",
      "va   afddddddddv",
      "va   agghggghggv",
      "va   aaaaaa=i=av",
      "va        jkkkav",
      "va        jkkkav",
      "va        jkkkav",
      "vaaaaaaaaaaaaaav",
      "vvvvvvvvvvvvvvvv"
    ],
    [
      "va            av",
      "va     l bmb lav",
      "va    aaaaaaaaav",
      "va   annnnnnnnav",
      "va   annnnnnnnav",
      "va   annnnnnnnav",
      "va   annnnnnnnav",
      "va   annnnnnnnav",
      "va   annnna=i=av",
      "va   annnnakkkav",
      "va   aaaaaajjjav",
      "va            av",
      "va            av",
      "va            av",
      "vvaaaaaaaaaaaaav",
      "vvvvvvvvvvvvvvvv"
    ],
    [
      "va            av",
      "va       bbb  av",
      "va    aaaaaaaaav",
      "va   annnnnnnnav",
      "va   annnnnnnnav",
      "va   annnnnnnnav",
      "va   annnna=i=av",
      "va   annnnakkkav",
      "va   annnnajjjav",
      "va   annnna   av",
      "va   aaaaaa   av",
      "va            av",
      "va            av",
      "va            av",
      "vvaaaaaaaaaaaaav",
      "vvvvvvvvvvvvvvvv"
    ],
    [
      "va            av",
      "va        o   av",
      "va    aaaaaaaaav",
      "va   annnn=kkkav",
      "va   annnnikkkav",
      "va   annnn=kkkav",
      "va   annnnajjjav",
      "va   annnna   av",
      "va   annnna   av",
      "va   annnna   av",
      "va   aaaaaa   av",
      "va            av",
      "va            av",
      "va            av",
      "vvaaaaaaaaaaaaav",
      "vvvvvvvvvvvvvvvv"
    ],
    [
      "vappppppppppppav",
      "vappppppppppppav",
      "vappppaaaaaaaaav",
      "vapppann=kj   av",
      "vapppannikj   av",
      "vapppann=kj   av",
      "vapppannaaa   av",
      "vapppannnna   av",
      "vapppannnna   av",
      "vapppannnna   av",
      "vadddaaaaaa   av",
      "va            av",
      "va            av",
      "va            av",
      "vvaaaaaaaaaaaaav",
      "vvvvvvvvvvvvvvvv"
    ],
    [
      "vappppppppppppav",
      "vappppppppppppav",
      "vapppaaaaaaaaaav",
      "vapppa=kj     av",
      "vapppaikj     av",
      "vapppa=kj     av",
      "vapppaaaaaa   av",
      "vapppannnna   av",
      "vapppannnna   av",
      "vapppannnna   av",
      "vapppaaaaaadddav",
      "vappppppppppppav",
      "vappppppppppppav",
      "vappppppppppppav",
      "vvaaaaaaaaaaaaav",
      "vvvvvvvvvvvvvvvv"
    ]
  ]
}