{
  "name": "multi_workshop_1_floor1",
  "refpalette": "deceasedcraft:multi_workshop_1/multi_workshop_1_floor1_palette",
  "xsize": 16,
  "zsize": 16,
  "slices": [
    [
      " abbbbbbbbbbbba ",
      " abbbbbbbbbbbba ",
      " acaaacaaacbbbc ",
      "        dHeeeef ",
      "        dHeeeef ",
      "        dHeeeef ",
      "            eef ",
      "            eef ",
      "            eef ",
      "  g   g   gfffg ",
      "                ",
      "                ",
      "                ",
      "                ",
      "                ",
      "                "
    ],
    [
      " ahij  k      l ",
      " a!mnopqrr j  a ",
      " acaaacaaac   c ",
      "      sHe     s ",
      "      sHe     s ",
      "      sHe     s ",
      "      s       s ",
      "      s       s ",
      "      s       s ",
      "  g   gsssgsssg ",
      "                ",
      "                ",
      "                ",
      "                ",
      "                ",
      "                "
    ],
    [
      " l            l ",
      " gt    ur     a ",
      " acaaacaaac   c ",
      "   ddHe         ",
      "   ddHe         ",
      "   ddHe         ",
      "   dddw         ",
      "   dddw         ",
      "   dddw         ",
      "  g   g   g   g ",
      "                ",
      "                ",
      "                ",
      "                ",
      "                ",
      "                "
    ],
    [
      " a            l ",
      " a      r     a ",
      " acaaacaaacxxxc ",
      "  fee           ",
      "  fee           ",
      "  fee           ",
      "  feeeeHd       ",
      "  feeeeHd       ",
      "  feeeeHd       ",
      "  gfffgfffg   g ",
      "                ",
      "                ",
      "                ",
      "                ",
      "                ",
      "                "
    ],
    [
      " a            y ",
      " a        A   a ",
      " acaaacaaacBBBc ",
      "  s       s     ",
      "  s       s     ",
      "  s       s     ",
      "  s     eHs     ",
      "  s     eHs     ",
      "  s     eHs     ",
      "  gsssgsssg   g ",
      "                ",
      "                ",
      "                ",
      "                ",
      "                ",
      "                "
    ],
    [
      " assssssssssssa ",
      " aCDCCCDCCECCCa ",
      " acFffcFffgaaac ",
      "          wddd  ",
      "          wddd  ",
      "          wddd  ",
      "          eHdd  ",
      "          eHdd  ",
      "          eHdd  ",
      "  g   g   g   g ",
      "                ",
      "                ",
      "                ",
      "                ",
      "                ",
      "                "
    ]
  ]
}