{
  "name": "multi_workshop_1_base2",
  "refpalette": "deceasedcraft:multi_workshop_1/multi_workshop_1_base2_palette",
  "xsize": 16,
  "zsize": 16,
  "slices": [
    [
      "vaaaaaaaaaaaaaav",
      "vaaaaaaaaaaaaaav",
      "vaaaaaaaaaaaaaav",
      "vaaaaaaaaaaaaaav",
      "vaaaaaaaaaaaaaav",
      "vaaaaaaaaaaaaaav",
      "vaaaaaaaaaaaaaav",
      "vaaaaaaaaaaaaaav",
      "vaaaaaaaaaaaaaav",
      "vaaaaaaaaaaaaaav",
      "vaaaaaaaaaaaaaav",
      "vaaaaaaaaaaaaaav",
      "vaaaaaaaaaaaaaav",
      "vaaaaaaaaaaaaaav",
      "vaaaaaaaaaaaaaav",
      "vvvvvvvvvvvvvvvv"
    ],
    [
      "vaaaaaaaaaaaaaav",
      "vaaaaaaaaaaaaaav",
      "vaaaaaaaaaaaaaav",
      "vaaaaaaaaaaaaaav",
      "vaaaaaaaaaaaaaav",
      "vaaaaaaaaaaaaaav",
      "vaaaaaaaaaaaaaav",
      "vaaaaaaaaaaaaaav",
      "vaaaaaaaaaaaaaav",
      "vaaaaaaaaaaaaaav",
      "vaaaaaaaaaaaaaav",
      "vaaaaaaaaaaaaaav",
      "vaaaaaaaaaaaaaav",
      "vaaaaaaaaaaaaaav",
      "vaaaaaaaaaaaaaav",
      "vvvvvvvvvvvvvvvv"
    ],
    [
      "vbccccccdddddcbv",
      "vbccccccccccccbv",
      "vbccccbebbbbbebv",
      "vbcccbececececev",
      "vbcccecececececv",
      "vbccceececececev",
      "vbcccecececececv",
      "vbccceececececev",
      "vbcccecececececv",
      "vbcccbececececev",
      "vbeeebbbbbbbbbbv",
      "vbaaaaaaaaaaaabv",
      "vbaaaaaaaaaaaabv",
      "vbaaaaaaaaaaaabv",
      "vbbbbbbbbbbbbbbv",
      "vvvvvvvvvvvvvvvv"
    ],
    [
      "vb            bv",
      "vb       fgh  bv",
      "vb   ibjbbbbbjbv",
      "vb   bk lmmmn ov",
      "vb   p        qv",
      "vb   p        rv",
      "vb   p        rv",
      "vb   p      s rv",
      "vb   p        tv",
      "vb   buwxyABxCDv",
      "vbEEEbbbbbbbbbbv",
      "vbFFFI=aaaaaaabv",
      "vbFFFIJaaaaaaabv",
      "vbFFFI=aaaaaaabv",
      "vbbbbbbbbbbbbbbv",
      "vvvvvvvvvvvvvvvv"
    ],
    [
      "vb            bv",
      "vb            bv",
      "vb   Kbjbbbbbjbv",
      "vb   bL       Mv",
      "vb   p         v",
      "vb   p        Nv",
      "vb   p        Nv",
      "vb   p        Nv",
      "vb   p        Ov",
      "vb   b  PQRSP Dv",
      "vb   bbbbbbbbbbv",
      "vb    FI=aaaaabv",
      "vb    FIJaaaaabv",
      "vb    FI=aaaaabv",
      "vbbbbbbbbbbbbbbv",
      "vvvvvvvvvvvvvvvv"
    ],
    [
      "vb            bv",
      "vb       T T  bv",
      "vb   Ubjbbbbbjbv",
      "vb   b  VWXYZ  v",
      "vb   p         v",
      "vb   p         v",
      "vb   p         v",
      "vb   p         v",
      "vb   p         v",
      "vb   b    0   Dv",
      "vb   bbbbbbbbbbv",
      "vb      FI=aaabv",
      "vb      FIJaaabv",
      "vb      FI=aaabv",
      "vbbbbbbbbbbbbbbv",
      "vvvvvvvvvvvvvvvv"
    ]
  ]
}