{
  "name": "multi_workshop_1_top",
  "refpalette": "deceasedcraft:multi_workshop_1/multi_workshop_1_top_palette",
  "xsize": 16,
  "zsize": 16,
  "slices": [
    [
      " abbbbbbbbbbbba ",
      " abbbbbbbbbbbba ",
      " acaaacaaacbbbc ",
      "          deeed ",
      "          deeed ",
      "          deeed ",
      "            eed ",
      "            eed ",
      "            eed ",
      "  f   f   fdddf ",
      "                ",
      "                ",
      "                ",
      "                ",
      "                ",
      "                "
    ],
    [
      " a    ghi     j ",
      " akll!mn  o   a ",
      " acaaacaaacpppc ",
      "      q       q ",
      "      q       q ",
      "      q       q ",
      "      q       q ",
      "      q       q ",
      "      q       q ",
      "  f   fqqqfqqqf ",
      "                ",
      "                ",
      "                ",
      "                ",
      "                ",
      "                "
    ],
    [
      " j            j ",
      " f llllr  s   a ",
      " acaaacaaacpppc ",
      "                ",
      "                ",
      "                ",
      "                ",
      "                ",
      "                ",
      "  f   f   f   f ",
      "                ",
      "                ",
      "                ",
      "                ",
      "                ",
      "                "
    ],
    [
      " a            j ",
      " a tu w x y   a ",
      " acaaacaaacpppc ",
      "  d             ",
      "  d             ",
      "  d             ",
      "  d             ",
      "  d             ",
      "  d             ",
      "  fdddfdddf   f ",
      "                ",
      "                ",
      "                ",
      "                ",
      "                ",
      "                "
    ],
    [
      " a            A ",
      " a      B     a ",
      " acaaacaaacCCCc ",
      "  q       q     ",
      "  q       q     ",
      "  q       q     ",
      "  q       q     ",
      "  q       q     ",
      "  q       q     ",
      "  fqqqfqqqf   f ",
      "                ",
      "                ",
      "                ",
      "                ",
      "                ",
      "                "
    ],
    [
      " a            a ",
      " a      D     a ",
      " acaaacaaacaaac ",
      "                ",
      "                ",
      "                ",
      "                ",
      "                ",
      "                ",
      "  f   f   f   f ",
      "                ",
      "                ",
      "                ",
      "                ",
      "                ",
      "                "
    ],
    [
      " a    f   f   f ",
      " aE   f   f   f ",
      " afaaafaaafaaaf ",
      "  f   f   f   f ",
      "  f   f   f   f ",
      "  f   f   f   f ",
      "  f   f   f   f ",
      "  f   f   f   f ",
      "  f   f   f   f ",
      "  f   f   f   f ",
      "                ",
      "                ",
      "                ",
      "                ",
      "                ",
      "                "
    ],
    [
      " aFFFFIFFFIFFFa ",
      " aFFFFIFFFIFFFa ",
      " aaaaaaaaaaaaaa ",
      "                ",
      "                ",
      "                ",
      "                ",
      "                ",
      "                ",
      "                ",
      "                ",
      "                ",
      "                ",
      "                ",
      "                ",
      "                "
    ],
    [
      " a            a ",
      " a            a ",
      " aaaaaaaaaaaaaa ",
      "                ",
      "                ",
      "                ",
      "                ",
      "                ",
      "                ",
      "                ",
      "                ",
      "                ",
      "                ",
      "                ",
      "                ",
      "                "
    ]
  ]
}