{
  "name": "multi_verticalschool_1_floor20",
  "refpalette": "deceasedcraft:multi_verticalschool_1/multi_verticalschool_1_floor20_palette",
  "xsize": 16,
  "zsize": 16,
  "slices": [
    [
      "             a  ",
      "             a  ",
      "             a  ",
      "             a  ",
      "             a  ",
      "             ab ",
      "             a  ",
      "             a  ",
      "             ab ",
      "             a  ",
      "             a  ",
      "             a  ",
      "             a  ",
      "             a  ",
      "             a  ",
      "             a  "
    ],
    [
      "             a  ",
      "             a  ",
      "             a  ",
      "             a  ",
      "             a  ",
      "             a  ",
      "             a  ",
      "             a  ",
      "             a  ",
      "             a  ",
      "             a  ",
      "             a  ",
      "             a  ",
      "             a  ",
      "             a  ",
      "             a  "
    ],
    [
      "            cadd",
      "            cadd",
      "            cadd",
      "            cadd",
      "            cadd",
      "            cadd",
      "            cadd",
      "            cadd",
      "            cadd",
      "            cadd",
      "            cadd",
      "            cadd",
      "            cadd",
      "            cadd",
      "            cadd",
      "            cadd"
    ],
    [
      "            efgg",
      "            efgg",
      "            efgg",
      "            efgg",
      "            efgg",
      "            efgg",
      "            efgg",
      "            efgg",
      "            efgg",
      "            efgg",
      "            efgg",
      "            efgg",
      "            efhh",
      "            efhh",
      "            efhh",
      "            efhh"
    ],
    [
      "            ifjk",
      "            ifjl",
      "            ifml",
      "            ifjk",
      "            ifjk",
      "            ifmk",
      "            ifjk",
      "            ifjk",
      "            ifml",
      "            ifjk",
      "            ifjk",
      "            ifnn",
      "            if  ",
      "            if  ",
      "            if  ",
      "            if  "
    ],
    [
      "             a  ",
      "             a  ",
      "             ao ",
      "             a  ",
      "             a  ",
      "             ao ",
      "             a  ",
      "             a  ",
      "             ao ",
      "             a  ",
      "             a  ",
      "             a  ",
      "             a  ",
      "             a  ",
      "             a  ",
      "             a  "
    ]
  ]
}