{
  "name": "multi_verticalschool_1_base2",
  "refpalette": "deceasedcraft:multi_verticalschool_1/multi_verticalschool_1_base2_palette",
  "xsize": 16,
  "zsize": 16,
  "slices": [
    [
      "vvvvvvvvvvvvvvvv",
      "vvvvvvvvvvvvvvvv",
      "vvvvvvvvvvvvvvvv",
      "vvvvvvvvvvvvvvvv",
      "vvvvvvvvvvvvvvvv",
      "vvvvvvvvvvvvvvvv",
      "vvvvvvvvvvvvvvvv",
      "vvvvvvvvvvvvvvvv",
      "vvvvvvvvvvvvvvvv",
      "vvvvvvvvvvvvvvvv",
      "vvvvvvvvvvvvvvvv",
      "vvvvvvvvvvvvvvvv",
      "vvvvvvvvvvvvvvvv",
      "vvvvvvvvvvvvvvvv",
      "vvvvvvvvvvvvvvvv",
      "vvvvvvvvvvvvvvvv"
    ],
    [
      "vaaaaaaaaaaaaaaa",
      "vaaaaaaaaaaaaaaa",
      "vaaaaaaaaaaaaaaa",
      "vaaaaaaaaaaaaaaa",
      "vaaaaaaaaaaaaaaa",
      "vaaaaaaaaaaaaaaa",
      "vaaaaaaaaaaaaaaa",
      "vaaaaaaaaaaaaaaa",
      "vaaaaaaaaaaaaaaa",
      "vaaaaaaaaaaaaaaa",
      "vaaaaaaaaaaaaaaa",
      "vaaaaaaaaaaaaaaa",
      "vaaaaaaaaaaaaaaa",
      "vaaaaaaaaaaaaaaa",
      "vaaaaaaaaaaaaaaa",
      "vaaaaaaaaaaaaaaa"
    ],
    [
      "vaaaaaaaaaaaaaaa",
      "vaaaaaaaaaaaaaaa",
      "vaaaaaaaaaaaaaaa",
      "vaaaaaaaaaaaaaaa",
      "vaaaaaaaaaaaaaaa",
      "vaaaaaaaaaaaaaaa",
      "vaaaaaaaaaaaaaaa",
      "vaaaaaaaaaaaaaaa",
      "vaaaaaaaaaaaaaaa",
      "vaaaaaaaaaaaaaaa",
      "vaaaaaaaaaaaaaaa",
      "vaaaaaaaaaaaaaaa",
      "vaaaaaaaaaaaaaaa",
      "vaaaaaaaaaaaaaaa",
      "vaaaaaaaaaaaaaaa",
      "vaaaaaaaaaaaaaaa"
    ],
    [
      "vbbbbcdeeeeeeeee",
      "vbbbbcdeeeeeeeee",
      "vbbbbcdeeeeeeeee",
      "vbbbbcdeeeeeeeee",
      "vbbbbcdeeeeeeeee",
      "vbbbbcdeeeeeeeee",
      "vbbbbcdeeeeeeeee",
      "vbbbbcdeeeeeeeee",
      "vbbbbcffffffffff",
      "vbbbbcdeeeeeeeee",
      "vbbbbcdeeeeeeeee",
      "vbbbbcdeeeeeeeee",
      "vbbbbcdeeeeeeeee",
      "vbbbbcdeeeeeeeee",
      "vbbbbcdeeeeeeeee",
      "vbbbbcdeeeeeeeee"
    ],
    [
      "v    cghhhhhhhhh",
      "v    cghhhhhhhhh",
      "v   icghhhhhhhhh",
      "v    cghhhhhhhhh",
      "v    cghhhhhhhhh",
      "v    cghhhhhhhhh",
      "v    cghhhhhhhhh",
      "v    cghhhhhhhhh",
      "v    cfjkkkkkkkk",
      "v    cdllll     ",
      "v   icdmno      ",
      "v    cd         ",
      "v    cdppp      ",
      "v    cd       qr",
      "v    cdstu      ",
      "v    cdllll     "
    ],
    [
      "v    cg         ",
      "v    cg         ",
      "v    cg       ww",
      "v    cg        x",
      "v    cg        x",
      "v    cg         ",
      "v    cg         ",
      "v    cg         ",
      "v    cfy        ",
      "v    cABBBB     ",
      "v    cA         ",
      "v    cA         ",
      "v    cA         ",
      "v    cA         ",
      "v    cA         ",
      "v    cABBBB     "
    ]
  ]
}