{
  "name": "multi_verticalschool_1_floor4",
  "refpalette": "deceasedcraft:multi_verticalschool_1/multi_verticalschool_1_floor4_palette",
  "xsize": 16,
  "zsize": 16,
  "slices": [
    [
      "             aab",
      "             abb",
      "             ab ",
      "             ab ",
      "             ab ",
      "             ab ",
      "             ab ",
      "             ab ",
      "             ab ",
      "             ab ",
      "             ab ",
      "             ab ",
      "             ab ",
      "             ab ",
      "             ab ",
      "             ab "
    ],
    [
      "               c",
      "              cc",
      "              c ",
      "              c ",
      "              c ",
      "              c ",
      "                ",
      "              c ",
      "                ",
      "              c ",
      "              c ",
      "              c ",
      "              c ",
      "              c ",
      "              c ",
      "              c "
    ],
    [
      "                ",
      "                ",
      "                ",
      "                ",
      "                ",
      "                ",
      "                ",
      "                ",
      "                ",
      "                ",
      "                ",
      "                ",
      "                ",
      "                ",
      "                ",
      "                "
    ],
    [
      "                ",
      "                ",
      "                ",
      "                ",
      "                ",
      "                ",
      "                ",
      "                ",
      "                ",
      "                ",
      "                ",
      "                ",
      "                ",
      "                ",
      "                ",
      "                "
    ],
    [
      "                ",
      "                ",
      "                ",
      "                ",
      "                ",
      "                ",
      "                ",
      "                ",
      "                ",
      "                ",
      "                ",
      "                ",
      "                ",
      "                ",
      "                ",
      "                "
    ],
    [
      "     deefeeefeee",
      "     deefeeefeee",
      "     deefeeefeee",
      "     deefeeefeee",
      "     deefeeefeee",
      "     deefeeefeee",
      "     deefeeefeee",
      "     deefeeefeee",
      "     deefeeefeee",
      "     deefeeefeee",
      "     deefeeefeee",
      "     deefeeefeee",
      "     deefeeefeee",
      "     deefeeefeee",
      "     deefeeefeee",
      "     deefeeefeee"
    ]
  ]
}