{
  "name": "multi_verticalschool_1_floor25",
  "refpalette": "deceasedcraft:multi_verticalschool_1/multi_verticalschool_1_floor25_palette",
  "xsize": 16,
  "zsize": 16,
  "slices": [
    [
      "            abcc",
      "            abcc",
      "            abcc",
      "            abcc",
      "            abcc",
      "            abcc",
      "            abcc",
      "            abcc",
      "            abcc",
      "            abcc",
      "            abcc",
      "            abcc",
      "            abcc",
      "            abcc",
      "            abcc",
      "            abcc"
    ],
    [
      "            dbef",
      "            dbef",
      "            dbef",
      "            dbef",
      "            dbef",
      "            dbef",
      "            db f",
      "            dbef",
      "            dbef",
      "            dbef",
      "            dbef",
      "            dbef",
      "            dbef",
      "            dbef",
      "            dbef",
      "            dbef"
    ],
    [
      "             g h",
      "             g h",
      "             g h",
      "             g h",
      "             g h",
      "             g h",
      "             g h",
      "             g h",
      "             g h",
      "             g h",
      "             g h",
      "             g h",
      "             g h",
      "             g h",
      "             g h",
      "             g h"
    ],
    [
      "             g  ",
      "             g  ",
      "             g  ",
      "             g  ",
      "             g  ",
      "             g  ",
      "             g  ",
      "             g  ",
      "             g  ",
      "             g  ",
      "             g  ",
      "             g  ",
      "             g  ",
      "             g  ",
      "             g  ",
      "             g  "
    ],
    [
      "             g  ",
      "             g  ",
      "             g  ",
      "             g  ",
      "             g  ",
      "             g  ",
      "             g  ",
      "             g  ",
      "             g  ",
      "             g  ",
      "             g  ",
      "             g  ",
      "             g  ",
      "             g  ",
      "             g  ",
      "             g  "
    ],
    [
      "            igjj",
      "            igjj",
      "            igjj",
      "            igjj",
      "            igjj",
      "            igjj",
      "            igjj",
      "            igjj",
      "            igjj",
      "            igjj",
      "            igjj",
      "            igjj",
      "            igjj",
      "            igjj",
      "            igjj",
      "            igjj"
    ]
  ]
}