{
  "name": "multi_verticalschool_1_floor22",
  "refpalette": "deceasedcraft:multi_verticalschool_1/multi_verticalschool_1_floor22_palette",
  "xsize": 16,
  "zsize": 16,
  "slices": [
    [
      "                ",
      "                ",
      "                ",
      "                ",
      "                ",
      "                ",
      "                ",
      "                ",
      "                ",
      "                ",
      "                ",
      "                ",
      "                ",
      "                ",
      "                ",
      "                "
    ],
    [
      "           abbcb",
      "           abbcb",
      "           abbcb",
      "           abbcb",
      "           abbcb",
      "           abbcb",
      "           abbcb",
      "           abbcb",
      "           abbcb",
      "           abbcb",
      "           abbcb",
      "           abbcb",
      "           abbcb",
      "           abbcb",
      "           abbcb",
      "           abbcb"
    ],
    [
      "           deeee",
      "           deeee",
      "           deeee",
      "           deeee",
      "           deeee",
      "           deeee",
      "           deeee",
      "           deeee",
      "           deeee",
      "           deeee",
      "           deeee",
      "           deeee",
      "           deeee",
      "           deeee",
      "           deeee",
      "           deeee"
    ],
    [
      "           df   ",
      "           dg   ",
      "           df   ",
      "           df   ",
      "           df   ",
      "           df   ",
      "           df   ",
      "           df   ",
      "           df   ",
      "           df   ",
      "           df   ",
      "           df   ",
      "           df   ",
      "           df   ",
      "           df   ",
      "           df   "
    ],
    [
      "           df   ",
      "           dh   ",
      "           df   ",
      "           df   ",
      "           df   ",
      "           df   ",
      "           df   ",
      "           df   ",
      "           df   ",
      "           df   ",
      "           df   ",
      "           df   ",
      "           df   ",
      "           df   ",
      "           df   ",
      "           df   "
    ],
    [
      "           df   ",
      "           di   ",
      "           df   ",
      "           df   ",
      "           df   ",
      "           df   ",
      "           df   ",
      "           df   ",
      "           df   ",
      "           df   ",
      "           df   ",
      "           df   ",
      "           df   ",
      "           df   ",
      "           df   ",
      "           df   "
    ]
  ]
}