{
  "name": "multi_verticalschool_1_floor14",
  "refpalette": "deceasedcraft:multi_verticalschool_1/multi_verticalschool_1_floor14_palette",
  "xsize": 16,
  "zsize": 16,
  "slices": [
    [
      "     ab         ",
      "     abcddcccccc",
      "     ab   e fg  ",
      "     ab         ",
      "     ab         ",
      "     ab   e  gg ",
      "     ab    h    ",
      "     ab   e g g ",
      "     ab         ",
      "     ab         ",
      "     ab   e  gg ",
      "     abciicccccc",
      "     ab         ",
      "     ab         ",
      "     ab         ",
      "     ab         "
    ],
    [
      "     ab         ",
      "     abccccccccc",
      "     ab   ejjjjj",
      "     ab         ",
      "     ab         ",
      "     ab   ejjjjj",
      "     ab    h    ",
      "     ab   ejjjjj",
      "     ab         ",
      "     ab         ",
      "     ab   ejjjjj",
      "     abccccccccc",
      "     ab         ",
      "     ab         ",
      "     ab         ",
      "     ab         "
    ],
    [
      "     ab         ",
      "     abccccccccc",
      "     ab   eg  gg",
      "     ab         ",
      "     ab         ",
      "     ab   e gg g",
      "     ab    h    ",
      "     ab   eg  gg",
      "     ab         ",
      "     ab         ",
      "     ab   e gkgg",
      "     abccccccccc",
      "     ab         ",
      "     ab         ",
      "     ab         ",
      "     ab         "
    ],
    [
      "     ab         ",
      "     abccccccccc",
      "     ab   e     ",
      "     ab         ",
      "     ab         ",
      "     ab   e     ",
      "     ab    hllll",
      "     ab   e     ",
      "     ab         ",
      "     ab         ",
      "     ab   e     ",
      "     abccccccccc",
      "     ab         ",
      "     ab         ",
      "     ab         ",
      "     ab         "
    ],
    [
      "     abmmmmmmmmm",
      "     abccccccccc",
      "     abnnnnnnnnn",
      "     abnnnnnnnnn",
      "     abnnnnnnnnn",
      "     abnnnnnnnnn",
      "     abnnnnonnnn",
      "     abnnnnnnnnn",
      "     abnnnnnnnnn",
      "     abnnnnnnnnn",
      "     abnnnnnnnnn",
      "     abccccccccc",
      "     abpqqqqqqqq",
      "     abpqqqqqqqq",
      "     abpqqqqqqqq",
      "     abpqqqqqqqq"
    ],
    [
      "     abbrsssssss",
      "     abbrsssssss",
      "     abbrsssssss",
      "     abbrsssssss",
      "     abbrsssssss",
      "     abbrsssssss",
      "     abbrsssssss",
      "     abbrsssssss",
      "     abbrsssssss",
      "     abbrsssssss",
      "     abbrsssssss",
      "     abbrsssssss",
      "     abbrsssssss",
      "     abbrsssssss",
      "     abbrsssssss",
      "     abbrsssssss"
    ]
  ]
}