{
  "name": "multi_verticalschool_1_floor29",
  "refpalette": "deceasedcraft:multi_verticalschool_1/multi_verticalschool_1_floor29_palette",
  "xsize": 16,
  "zsize": 16,
  "slices": [
    [
      "            abcc",
      "            abcc",
      "            abcc",
      "            abcc",
      "            abcc",
      "            abcc",
      "            abcc",
      "            abcc",
      "            abcc",
      "            abcc",
      "            abcc",
      "            abcc",
      "            abcc",
      "            abcc",
      "            abcc",
      "            abcc"
    ],
    [
      "            dbef",
      "            dbef",
      "            dbef",
      "            db f",
      "            dbgf",
      "            dbef",
      "            dbef",
      "            dbgf",
      "            dbef",
      "            dbef",
      "            dbef",
      "            dbef",
      "            db f",
      "            dbgf",
      "            dbgf",
      "            dbef"
    ],
    [
      "             h  ",
      "             h i",
      "             h i",
      "             h i",
      "             h i",
      "             h i",
      "             h  ",
      "             h i",
      "             h i",
      "             h i",
      "             h i",
      "             h i",
      "             h i",
      "             h i",
      "             h i",
      "             h i"
    ],
    [
      "             h  ",
      "             h  ",
      "             h  ",
      "             h  ",
      "             h  ",
      "             h  ",
      "             h  ",
      "             h  ",
      "             h  ",
      "             h  ",
      "             h  ",
      "             h  ",
      "             h  ",
      "             h  ",
      "             h  ",
      "             h  "
    ],
    [
      "             h  ",
      "             h  ",
      "             h  ",
      "             h  ",
      "             h  ",
      "             h  ",
      "             h  ",
      "             h  ",
      "             h  ",
      "             h  ",
      "             h  ",
      "             h  ",
      "             h  ",
      "             h  ",
      "             h  ",
      "             h  "
    ],
    [
      "            jhkk",
      "            jhkk",
      "            jhkk",
      "            jhkk",
      "            jhkk",
      "            jhkk",
      "            jhkk",
      "            jhkk",
      "            jhkk",
      "            jhkk",
      "            jhkk",
      "            jhkk",
      "            jhkk",
      "            jhkk",
      "            jhkk",
      "            jhkk"
    ]
  ]
}