{
  "name": "multi_verticalschool_1_floor26",
  "refpalette": "deceasedcraft:multi_verticalschool_1/multi_verticalschool_1_floor26_palette",
  "xsize": 16,
  "zsize": 16,
  "slices": [
    [
      "            abcc",
      "            abcc",
      "            abcc",
      "            abcc",
      "            abcc",
      "            abcc",
      "            abcc",
      "            abcc",
      "            abcc",
      "            abcc",
      "            abcc",
      "            abcc",
      "            abcc",
      "            abcc",
      "            abcc",
      "            abcc"
    ],
    [
      "            dbef",
      "            dbgf",
      "            dbgf",
      "            dbgf",
      "            db h",
      "            db f",
      "            dbgf",
      "            dbef",
      "            dbgf",
      "            dbgh",
      "            dbgf",
      "            db f",
      "            dbgf",
      "            dbgf",
      "            dbgf",
      "            dbgf"
    ],
    [
      "             i j",
      "             i j",
      "             i j",
      "             i j",
      "             i  ",
      "             i j",
      "             i j",
      "             i j",
      "             i  ",
      "             i  ",
      "             i j",
      "             i j",
      "             i j",
      "             i j",
      "             i j",
      "             i j"
    ],
    [
      "             i  ",
      "             i  ",
      "             i  ",
      "             i  ",
      "             i  ",
      "             i  ",
      "             i  ",
      "             i  ",
      "             i  ",
      "             i  ",
      "             i  ",
      "             i  ",
      "             i  ",
      "             i  ",
      "             i  ",
      "             i  "
    ],
    [
      "             i  ",
      "             i  ",
      "             i  ",
      "             i  ",
      "             i  ",
      "             i  ",
      "             i  ",
      "             i  ",
      "             i  ",
      "             i  ",
      "             i  ",
      "             i  ",
      "             i  ",
      "             i  ",
      "             i  ",
      "             i  "
    ],
    [
      "            kill",
      "            kill",
      "            kill",
      "            kill",
      "            kill",
      "            kill",
      "            kill",
      "            kill",
      "            kill",
      "            kill",
      "            kill",
      "            kill",
      "            kill",
      "            kill",
      "            kill",
      "            kill"
    ]
  ]
}