{
  "name": "multi_verticalschool_1_floor17",
  "refpalette": "deceasedcraft:multi_verticalschool_1/multi_verticalschool_1_floor17_palette",
  "xsize": 16,
  "zsize": 16,
  "slices": [
    [
      "                ",
      "                ",
      "                ",
      "                ",
      "                ",
      "                ",
      "                ",
      "                ",
      "                ",
      "                ",
      "                ",
      "                ",
      "                ",
      "                ",
      "                ",
      "                "
    ],
    [
      "                ",
      "                ",
      "                ",
      "                ",
      "                ",
      "                ",
      "                ",
      "                ",
      "                ",
      "                ",
      "                ",
      "                ",
      "                ",
      "                ",
      "                ",
      "                "
    ],
    [
      "            a bb",
      "            a bc",
      "            a bc",
      "            a bc",
      "            a bc",
      "            a bc",
      "            a bc",
      "            a bc",
      "            a bc",
      "            a bc",
      "            a bc",
      "            a bc",
      "            a bc",
      "            a bc",
      "            a bc",
      "            a bc"
    ],
    [
      "            deff",
      "            deff",
      "            deff",
      "            deff",
      "            deff",
      "            deff",
      "            deff",
      "            deff",
      "            deff",
      "            deff",
      "            deff",
      "            deff",
      "            degg",
      "            degg",
      "            degg",
      "            degg"
    ],
    [
      "            heij",
      "            heij",
      "            hekj",
      "            heij",
      "            heij",
      "            hekj",
      "            heij",
      "            heil",
      "            hekj",
      "            heil",
      "            heij",
      "            hemm",
      "            he  ",
      "            he  ",
      "            he  ",
      "            he  "
    ],
    [
      "             n  ",
      "             n  ",
      "             no ",
      "             n  ",
      "             n  ",
      "             no ",
      "             n  ",
      "             n  ",
      "             no ",
      "             n  ",
      "             n  ",
      "             n  ",
      "             n  ",
      "             n  ",
      "             n  ",
      "             n  "
    ]
  ]
}