{
  "name": "multi_verticalschool_1_ground",
  "refpalette": "deceasedcraft:multi_verticalschool_1/multi_verticalschool_1_ground_palette",
  "xsize": 16,
  "zsize": 16,
  "slices": [
    [
      "HHHHabccbbbbbdee",
      "HHHHabccbbbbbd  ",
      "HHHHabccbbbbbd  ",
      "HHHHabccbbbbbbe ",
      "HHHHabccbbbbbbe ",
      "HHHHabccbbbbbbbe",
      "HHHHabccbbbbbbbb",
      "HHHHabccbbbbbbbb",
      "HHHHabccbbbbbbbb",
      "HHHHabccbbbbbbbb",
      "HHHHabccbbbbbbbb",
      "HHHHabcccccccccc",
      "HHHHabcccccccccc",
      "HHHHabcccfffffff",
      "HHHHabccfccccccc",
      "HHHHabcfcccccccc"
    ],
    [
      "       ghhhhhhii",
      "       ghhhhhhii",
      "       ghhhhhhii",
      "       ghhhhhhhj",
      "       ghhhhhhhj",
      "       ghhhhhhhh",
      "       ghhhhhhhh",
      "       ghhhhhhhh",
      "       ghhhhhhhh",
      "       ghhhhhhhh",
      "       ghhhhhhhh",
      "       ggggggggg",
      "                ",
      "         kkkkkkk",
      "        k       ",
      "       k        "
    ],
    [
      "       lbbmmmmmm",
      "       lbbmmmbjj",
      "       lbbmmmbnn",
      "       lbbmmmbb ",
      "       lbbmmmmb ",
      "       lbbmmmmbb",
      "       lbbmmmmmm",
      "       lbbmmmmmm",
      "       lbbmmmmmm",
      "       lbbmmmmmm",
      "       lbbbbbbbb",
      "       lllllllll",
      "                ",
      "                ",
      "                ",
      "                "
    ],
    [
      "       lbfm     ",
      "       lbfm  o  ",
      "       lbfm  o  ",
      "       lbfm  oo ",
      "       lbfm   o ",
      "       lbfm   oo",
      "       lbfm     ",
      "       lbfm     ",
      "       lbfm     ",
      "       lbfmp    ",
      "       lbbbbbbbb",
      "       lllllllll",
      "                ",
      "                ",
      "                ",
      "                "
    ],
    [
      "       lbq      ",
      "       lbr      ",
      "       lb       ",
      "       lbr      ",
      "       lbr      ",
      "       lbq      ",
      "       lb       ",
      "       lb       ",
      "       lbq      ",
      "       lbr s    ",
      "       lbbbbbbbb",
      "       lllllllll",
      "                ",
      "                ",
      "                ",
      "                "
    ],
    [
      "       lbs      ",
      "       lb       ",
      "       lb       ",
      "       lb       ",
      "       lb       ",
      "       lbs      ",
      "       lb       ",
      "       lb       ",
      "       lbs      ",
      "       lb  t    ",
      "       lbbbbbbbb",
      "       lllllllll",
      "                ",
      "                ",
      "                ",
      "                "
    ]
  ]
}