{
  "name": "multi_verticalschool_1_floor3",
  "refpalette": "deceasedcraft:multi_verticalschool_1/multi_verticalschool_1_floor3_palette",
  "xsize": 16,
  "zsize": 16,
  "slices": [
    [
      "             a  ",
      "             a  ",
      "             a  ",
      "             a  ",
      "             a  ",
      "             a  ",
      "             a  ",
      "             a  ",
      "             a  ",
      "             a  ",
      "             a  ",
      "             a  ",
      "             a  ",
      "             a  ",
      "             a  ",
      "             a  "
    ],
    [
      "             a  ",
      "             a  ",
      "             a  ",
      "             a  ",
      "             a  ",
      "             a  ",
      "             a  ",
      "             a  ",
      "             a  ",
      "             a  ",
      "             a  ",
      "             a  ",
      "             a  ",
      "             a  ",
      "             a  ",
      "             a  "
    ],
    [
      "             a  ",
      "             a  ",
      "             a  ",
      "             a  ",
      "             a  ",
      "             a  ",
      "             a  ",
      "             a  ",
      "             a  ",
      "             a  ",
      "             a  ",
      "             a  ",
      "             a  ",
      "             a  ",
      "             a  ",
      "             a  "
    ],
    [
      "            ba  ",
      "            ba  ",
      "            ba  ",
      "            ba  ",
      "            ba  ",
      "            ba  ",
      "            ba  ",
      "            ba  ",
      "            ba  ",
      "            ba  ",
      "            ba  ",
      "            ba  ",
      "            ba  ",
      "            ba  ",
      "            ba  ",
      "            ba  "
    ],
    [
      "            cdee",
      "            cdef",
      "            cdee",
      "            cdee",
      "            cdee",
      "            cdee",
      "            cdef",
      "            cdee",
      "            cdee",
      "            cdee",
      "            cdee",
      "            cdef",
      "            cdee",
      "            cdee",
      "            cdee",
      "            cdee"
    ],
    [
      "            gddh",
      "            gdhh",
      "            gdhi",
      "            gdhi",
      "            gdhi",
      "            gdhi",
      "            gdhi",
      "            gdhi",
      "            gdhi",
      "            gdhi",
      "            gdhi",
      "            gdhj",
      "            gdhi",
      "            gdhj",
      "            gdhj",
      "            gdhj"
    ]
  ]
}