{
  "name": "multi_verticalschool_1_floor13",
  "refpalette": "deceasedcraft:multi_verticalschool_1/multi_verticalschool_1_floor13_palette",
  "xsize": 16,
  "zsize": 16,
  "slices": [
    [
      "                ",
      "                ",
      "                ",
      "                ",
      "                ",
      "                ",
      "                ",
      "                ",
      "                ",
      "                ",
      "                ",
      "                ",
      "                ",
      "                ",
      "                ",
      "                "
    ],
    [
      "                ",
      "                ",
      "                ",
      "                ",
      "                ",
      "                ",
      "                ",
      "                ",
      "                ",
      "                ",
      "                ",
      "                ",
      "                ",
      "                ",
      "                ",
      "                "
    ],
    [
      "      a bcbbbbbb",
      "      a bcbbbbbb",
      "      a bcbbbbbb",
      "      a bcbbbbbb",
      "      a bcbbbbbb",
      "      a bcbbbbbb",
      "      a bcbbbbbb",
      "      a bcbbbbbb",
      "      a bcbbbbbb",
      "      a bcbbbbbb",
      "      a bcbbbbbb",
      "      a bcbbbbbb",
      "      a bcbbbbbb",
      "      a bcbbbbbb",
      "      a bcbbbbbb",
      "      a bcbbbbbb"
    ],
    [
      "     defffffffff",
      "     defgggggggg",
      "     defffffffff",
      "     defffffffff",
      "     defffffffff",
      "     defffffffff",
      "     defffffffff",
      "     defffffffff",
      "     defffffffff",
      "     defffffffff",
      "     defffffffff",
      "     defgggggggg",
      "     defhhhhhhhh",
      "     defhhhhhhhh",
      "     defhhhhhhhh",
      "     defhhhhhhhh"
    ],
    [
      "     de      iii",
      "     degjkgggggg",
      "     de   lm mm ",
      "     de         ",
      "     de         ",
      "     de   lm mmm",
      "     de    noooo",
      "     de   lmmm m",
      "     de         ",
      "     de         ",
      "     de   lm  mm",
      "     degpqgggggg",
      "     de         ",
      "     de         ",
      "     de         ",
      "     de         "
    ],
    [
      "     der  r  s t",
      "     deguwgggggg",
      "     de   lxxxxx",
      "     de         ",
      "     de         ",
      "     dy   lxxxxx",
      "     dy    n    ",
      "     dy   lxxxxx",
      "     de         ",
      "     de         ",
      "     de   lxxxxx",
      "     degABgggggg",
      "     deC  C     ",
      "     dy         ",
      "     dy         ",
      "     de         "
    ]
  ]
}