{
  "name": "multi_verticalschool_1_base1",
  "refpalette": "deceasedcraft:multi_verticalschool_1/multi_verticalschool_1_base1_palette",
  "xsize": 16,
  "zsize": 16,
  "slices": [
    [
      "v    ab       cc",
      "v    ab      dee",
      "v    ab      dff",
      "v    ab       gh",
      "v    ab        h",
      "v    ab        g",
      "v    ab         ",
      "v    ab         ",
      "v    aij        ",
      "v    ak         ",
      "v    ak         ",
      "v    ak         ",
      "v    akl        ",
      "v    ak         ",
      "v    ak         ",
      "v    ak         "
    ],
    [
      "v    ab      dff",
      "v    ab      d  ",
      "v    ab         ",
      "v    ab         ",
      "v    ab         ",
      "v    ab         ",
      "v    ab         ",
      "v    ab         ",
      "v    aij        ",
      "v    ak         ",
      "v    ak         ",
      "v    ak         ",
      "v    akm        ",
      "v    ak         ",
      "v    ak         ",
      "v    ak         "
    ],
    [
      "v    ab         ",
      "v    ab         ",
      "v    ab         ",
      "v    ab         ",
      "v    ab         ",
      "v    ab         ",
      "v    ab         ",
      "v    ab         ",
      "v    aij        ",
      "v    ak         ",
      "v    ak         ",
      "v    ak         ",
      "v    ak         ",
      "v    ak         ",
      "v    ak         ",
      "v    ak         "
    ],
    [
      "v    ab         ",
      "v    ab         ",
      "v    ab         ",
      "v    ab         ",
      "v    ab         ",
      "v    ab         ",
      "v    ab         ",
      "v    ab         ",
      "v    aij        ",
      "v    ak         ",
      "v    ak         ",
      "v    ak         ",
      "v    ak         ",
      "v    ak         ",
      "v    ak         ",
      "v    ak         "
    ],
    [
      "v    abn        ",
      "v    abn        ",
      "v    abn        ",
      "v    abn        ",
      "v    abn        ",
      "v    abnn       ",
      "v    abnnn      ",
      "v    abnnnnnnnnn",
      "v    aiiiiiiiiii",
      "v    akooooooooo",
      "v    akooooooooo",
      "v    akopoooooop",
      "v    akopoooooop",
      "v    akopoooooop",
      "v    akooooooooo",
      "v    akooooooooo"
    ],
    [
      "veeeeaqrs       ",
      "veeeeaqrs       ",
      "veeeeaqrs       ",
      "veeeeaqrs       ",
      "veeeeaqrss      ",
      "veeeeaqrrss     ",
      "veeeeaqtrrssssss",
      "veeeeaqttrrrrrrr",
      "veeeeaiiiiiiiiii",
      "veeeeaquuuuuuuuu",
      "veeeeaquuuuuuuuu",
      "veeeeaquuuuuuuuu",
      "veeeeaquuuuuuuuu",
      "veeeeaquuuuuuuuu",
      "veeeeaquuuuuuuuu",
      "veeeeaquuuuuuuuu"
    ]
  ]
}