{
  "name": "multi_verticalschool_1_floor27",
  "refpalette": "deceasedcraft:multi_verticalschool_1/multi_verticalschool_1_floor27_palette",
  "xsize": 16,
  "zsize": 16,
  "slices": [
    [
      "            abcc",
      "            abcc",
      "            abcc",
      "            abcc",
      "            abcc",
      "            abcc",
      "            abcc",
      "            abcc",
      "            abcc",
      "            abcc",
      "            abcc",
      "            abcc",
      "            abcc",
      "            abcc",
      "            abcc",
      "            abcc"
    ],
    [
      "            dbef",
      "            db f",
      "            dbef",
      "            dbef",
      "            dbef",
      "            dbef",
      "            dbef",
      "            dbef",
      "            dbef",
      "            dbef",
      "            dbeg",
      "            dbeg",
      "            dbhf",
      "            dbef",
      "            dbhf",
      "            dbef"
    ],
    [
      "             i j",
      "             i  ",
      "             i j",
      "             i  ",
      "             i j",
      "             i j",
      "             i j",
      "             i j",
      "             i j",
      "             i j",
      "             i  ",
      "             i  ",
      "             i j",
      "             i  ",
      "             i j",
      "             i j"
    ],
    [
      "             i  ",
      "             i  ",
      "             i  ",
      "             i  ",
      "             i  ",
      "             i  ",
      "             i  ",
      "             i  ",
      "             i  ",
      "             i  ",
      "             i  ",
      "             i  ",
      "             i  ",
      "             i  ",
      "             i  ",
      "             i  "
    ],
    [
      "             i  ",
      "             i  ",
      "             i  ",
      "             i  ",
      "             i  ",
      "             i  ",
      "             i  ",
      "             i  ",
      "             i  ",
      "             i  ",
      "             i  ",
      "             i  ",
      "             i  ",
      "             i  ",
      "             i  ",
      "             i  "
    ],
    [
      "            kill",
      "            kill",
      "            kill",
      "            kill",
      "            kill",
      "            kill",
      "            kill",
      "            kill",
      "            kill",
      "            kill",
      "            kill",
      "            kill",
      "            kill",
      "            kill",
      "            kill",
      "            kill"
    ]
  ]
}