{
  "name": "multi_verticalschool_1_floor5",
  "refpalette": "deceasedcraft:multi_verticalschool_1/multi_verticalschool_1_floor5_palette",
  "xsize": 16,
  "zsize": 16,
  "slices": [
    [
      "     aabbbbbbbbb",
      "     aabbbbbbbbb",
      "     aabbbbbbbbb",
      "     aabbbbbbbbb",
      "     aabbbbbbbbb",
      "     aabbbbbbbbb",
      "     aabbbbbbbbb",
      "     aabbbbbbbbb",
      "     aabbbbbbbbb",
      "     aabbbbbbbbb",
      "     aabbbbbbbbb",
      "     aabbbbbbbbb",
      "     aabbbbbbbbb",
      "     aabbbbbbbbb",
      "     aabbbbbbbbb",
      "     aabbbbbbbbb"
    ],
    [
      "     ac         ",
      "     adddddddddd",
      "     adddddddddd",
      "     addedededed",
      "     addedededed",
      "     addedededed",
      "     addedededed",
      "     addedededed",
      "     addedededed",
      "     addedededed",
      "     addedededed",
      "     addedededed",
      "     addedededed",
      "     addedededed",
      "     addedededed",
      "     addedededed"
    ],
    [
      "     acf        ",
      "     adddddddddd",
      "     adggggggggg",
      "     adggggggggg",
      "     adggggggggg",
      "     adggggggggg",
      "     adhgggggggi",
      "     adggggggggg",
      "     adggggggggg",
      "     adggggggggg",
      "     adggggggggg",
      "     adhgggggggi",
      "     adggggggggg",
      "     adggggggggg",
      "     adggggggggg",
      "     adggggggggg"
    ],
    [
      "     abbbbbbbbbb",
      "     adddddddddd",
      "     adgjgjgjgjg",
      "     adggggggggg",
      "     adggggggggg",
      "     adggggggggg",
      "     adggggggggg",
      "     adggggggggg",
      "     adggggggggg",
      "     adggggggggg",
      "     adggggggggg",
      "     adggggggggg",
      "     adggggggggg",
      "     adggggggggg",
      "     adggggggggg",
      "     adggggggggg"
    ],
    [
      "     a  k k k k ",
      "     a          ",
      "     a          ",
      "     a          ",
      "     a          ",
      "     a          ",
      "     a          ",
      "     a          ",
      "     a          ",
      "     a          ",
      "     a          ",
      "     a          ",
      "     a          ",
      "     a          ",
      "     a          ",
      "     a          "
    ],
    [
      "     a      !   ",
      "     a          ",
      "     a          ",
      "     a          ",
      "     a          ",
      "     a          ",
      "     a          ",
      "     a          ",
      "     a          ",
      "     a          ",
      "     a          ",
      "     a          ",
      "     a          ",
      "     a          ",
      "     a          ",
      "     a          "
    ]
  ]
}