{
  "name": "multi_verticalschool_1_floor15",
  "refpalette": "deceasedcraft:multi_verticalschool_1/multi_verticalschool_1_floor15_palette",
  "xsize": 16,
  "zsize": 16,
  "slices": [
    [
      "        a       ",
      "        a       ",
      "        a       ",
      "        abc     ",
      "        a       ",
      "        a       ",
      "        a       ",
      "        a       ",
      "        bbc     ",
      "        b       ",
      "        a       ",
      "        a       ",
      "        a       ",
      "        abd     ",
      "        a       ",
      "        a       "
    ],
    [
      "                ",
      "                ",
      "                ",
      "         a      ",
      "                ",
      "                ",
      "                ",
      "        ~       ",
      "         a      ",
      "                ",
      "                ",
      "                ",
      "                ",
      "         a      ",
      "                ",
      "                "
    ],
    [
      "            e ff",
      "            e fg",
      "            e fg",
      "         h  e fg",
      "            e fg",
      "            e fg",
      "            e fg",
      "            e fg",
      "         h  e fg",
      "            e fg",
      "            e fg",
      "            e fg",
      "            e fg",
      "         h  e fg",
      "            e fg",
      "            e fg"
    ],
    [
      "            ijkk",
      "            ijkk",
      "            ijkk",
      "        hhh ijkk",
      "         h  ijlk",
      "            ijkk",
      "            ijkl",
      "            ijkk",
      "        hhh ijkk",
      "            ijlk",
      "            ijkk",
      "            ijkk",
      "         h  ijmm",
      "         h  ijmm",
      "         h  ijmm",
      "            ijmm"
    ],
    [
      "            nj  ",
      "            nj  ",
      "         h  nj  ",
      "         hh nj  ",
      "         h  nj  ",
      "            nj  ",
      "            nj  ",
      "         h  nj  ",
      "        hhh nj  ",
      "         h  nj  ",
      "            nj  ",
      "            nj  ",
      "         h  nj  ",
      "        hhh nj  ",
      "         h  nj  ",
      "            nj  "
    ],
    [
      "             o  ",
      "             o  ",
      "         h   o  ",
      "         hh  o  ",
      "             o  ",
      "             o  ",
      "             o  ",
      "         h   o  ",
      "         hh  o  ",
      "             o  ",
      "             o  ",
      "             o  ",
      "         h   o  ",
      "         hh  o  ",
      "             o  ",
      "             o  "
    ]
  ]
}