{
  "name": "multi_verticalschool_1_floor19",
  "refpalette": "deceasedcraft:multi_verticalschool_1/multi_verticalschool_1_floor19_palette",
  "xsize": 16,
  "zsize": 16,
  "slices": [
    [
      "             a  ",
      "             a  ",
      "             ab ",
      "             a  ",
      "             a  ",
      "             ab ",
      "             a  ",
      "             a  ",
      "             ab ",
      "             a  ",
      "             a  ",
      "             a  ",
      "             a  ",
      "             a  ",
      "             a  ",
      "             a  "
    ],
    [
      "             a  ",
      "             a  ",
      "             a  ",
      "             a  ",
      "             a  ",
      "             a  ",
      "             a  ",
      "             a  ",
      "             a  ",
      "             a  ",
      "             a  ",
      "             a  ",
      "             a  ",
      "             a  ",
      "             a  ",
      "             a  "
    ],
    [
      "            cadd",
      "            cadd",
      "            cadd",
      "            cadd",
      "            cadd",
      "            cadd",
      "            cadd",
      "            cadd",
      "            cadd",
      "            cadd",
      "            cadd",
      "            cadd",
      "            cadd",
      "            cadd",
      "            cadd",
      "            cadd"
    ],
    [
      "            efgg",
      "            efgg",
      "            efgg",
      "            efgg",
      "            efgg",
      "            efgg",
      "            efgg",
      "            efgg",
      "            efgg",
      "            efgg",
      "            efgg",
      "            efgg",
      "            efhh",
      "            efhh",
      "            efhh",
      "            efhh"
    ],
    [
      "            ifjk",
      "            ifjk",
      "            iflk",
      "            ifjk",
      "            ifjk",
      "            iflk",
      "            ifjk",
      "            ifjm",
      "            iflk",
      "            ifjk",
      "            ifjk",
      "            ifnn",
      "            if  ",
      "            if  ",
      "            if  ",
      "            if  "
    ],
    [
      "             a  ",
      "             a  ",
      "             ao ",
      "             a  ",
      "             a  ",
      "             ao ",
      "             a  ",
      "             a  ",
      "             ao ",
      "             a  ",
      "             a  ",
      "             a  ",
      "             a  ",
      "             a  ",
      "             a  ",
      "             a  "
    ]
  ]
}