{
  "name": "multi_nuclearpowerplant_0_base1",
  "refpalette": "deceasedcraft:multi_nuclearpowerplant_0/multi_nuclearpowerplant_0_base1_palette",
  "xsize": 16,
  "zsize": 16,
  "slices": [
    [
      "vvvvvvvvvvvvvvvv",
      "v               ",
      "v               ",
      "v               ",
      "vaaaaaaaaaaaaaaa",
      "vvvvvvvvvvvvvvvv",
      "vbbbbbbbbbbbbbbb",
      "vbbbbbbbbbbbbbbb",
      "vbbbbbbbbbbbbbbb",
      "vbbbbbbbbbbbbbbb",
      "vbbbbbbbbbbbbbbb",
      "vbbbbbbbbbbbbbbb",
      "vbbbbbbbbbbbbbbb",
      "vbbbbbbbbbbbbbbb",
      "vbbbbbbbbbbbbbbb",
      "vbbbbbbbbbbbbbbb"
    ],
    [
      "vvvvvvvvvvvvvvvv",
      "v               ",
      "v               ",
      "v               ",
      "v               ",
      "vvvvvvvvvvvvvvvv",
      "vccccccccccccccc",
      "vccccccccccccccc",
      "vccccccccccccccc",
      "vccccccccccccccc",
      "vccccccccccccccc",
      "vccccccccccccccc",
      "vccccccccccccccc",
      "vccccccccccccccc",
      "vccccccccccccccc",
      "vccccccccccccccc"
    ],
    [
      "vvvvvvvvvvvvvvvv",
      "v               ",
      "v               ",
      "v               ",
      "v               ",
      "vvvvvvvvvvvvvvvv",
      "vccccccccccccccc",
      "vccccccccccccccc",
      "vccccccccccccccc",
      "vccccccccccccccc",
      "vccccccccccccccc",
      "vccccccccccccccc",
      "vccccccccccccccc",
      "vccccccccccccccc",
      "vccccccccccccccc",
      "vccccccccccccccc"
    ],
    [
      "vvvvvvvvvvvvvvvv",
      "v               ",
      "v               ",
      "v               ",
      "v               ",
      "vvvvvvvvvvvvvvvv",
      "vccccccccccccccc",
      "vccccccccccccccc",
      "vccccccccccccccc",
      "vccccccccccccccc",
      "vccccccccccccccc",
      "vccccccccccccccc",
      "vccccccccccccccc",
      "vccccccccccccccc",
      "vccccccccccccccc",
      "vccccccccccccccc"
    ],
    [
      "vvvvvvvvvvvvvvvv",
      "v               ",
      "v               ",
      "v               ",
      "v               ",
      "vvvvvvvvvvvvvvvv",
      "vccccccccccccccc",
      "vccccccccccccccc",
      "vccccccccccccccc",
      "vccccccccccccccc",
      "vccccccccccccccc",
      "vccccccccccccccc",
      "vccccccccccccccc",
      "vccccccccccccccc",
      "vccccccccccccccc",
      "vccccccccccccccc"
    ],
    [
      "vvvvvvvvvvvvvvvv",
      "vddddddddddddddd",
      "vddddddddddddddd",
      "vddddddddddddddd",
      "vddddddddddddddd",
      "vvvvvvvvvvvvvvvv",
      "vccccccccccccccc",
      "vccccccccccccccc",
      "vccccccccccccccc",
      "vccccccccccccccc",
      "vccccccccccccccc",
      "vccccccccccccccc",
      "vccccccccccccccc",
      "vccccccccccccccc",
      "vccccccccccccccc",
      "vccccccccccccccc"
    ]
  ]
}