{
  "name": "multi_nuclearpowerplant_0_base3",
  "refpalette": "deceasedcraft:multi_nuclearpowerplant_0/multi_nuclearpowerplant_0_base3_palette",
  "xsize": 16,
  "zsize": 16,
  "slices": [
    [
      "vvvvvvvvvvvvvvvv",
      "vaa             ",
      "vaa             ",
      "vbb             ",
      "vbb             ",
      "vbb             ",
      "vbb             ",
      "vbbbbbbbbbbbbbbb",
      "vbbbbbbbbbbbbbbb",
      "vbb             ",
      "vbb             ",
      "vbb             ",
      "vbb             ",
      "vbb             ",
      "vbb             ",
      "vbb             "
    ],
    [
      "vvvvvvvvvvvvvvvv",
      "vccda           ",
      "vccda           ",
      "veeda           ",
      "vfg             ",
      "vfg             ",
      "vhg             ",
      "v  iiiiiiiiiiiii",
      "v  jjjjjjjjjjjjj",
      "v g             ",
      "v g             ",
      "v g             ",
      "v g             ",
      "v g             ",
      "v g             ",
      "v g             "
    ],
    [
      "vvvvvvvvvvvvvvvv",
      "v k cda         ",
      "v   cda         ",
      "v  ddda         ",
      "v               ",
      "v               ",
      "v               ",
      "v               ",
      "v               ",
      "v               ",
      "v               ",
      "v               ",
      "v               ",
      "v               ",
      "v               ",
      "v               "
    ],
    [
      "vvvvvvvvvvvvvvvv",
      "v     cda       ",
      "v     cda       ",
      "v   cddda       ",
      "v               ",
      "v               ",
      "v               ",
      "v               ",
      "v               ",
      "v               ",
      "v               ",
      "v               ",
      "v               ",
      "v               ",
      "v               ",
      "v               "
    ],
    [
      "vvvvvvvvvvvvvvvv",
      "v       cda     ",
      "v       cda     ",
      "v     cddda     ",
      "v               ",
      "v               ",
      "v               ",
      "v               ",
      "v               ",
      "v               ",
      "v               ",
      "v               ",
      "v               ",
      "v               ",
      "v               ",
      "v               "
    ],
    [
      "vvvvvvvvvvvvvvvv",
      "v         cda   ",
      "v         cda   ",
      "v       cddda   ",
      "v               ",
      "v               ",
      "v               ",
      "v               ",
      "v               ",
      "v               ",
      "v               ",
      "v               ",
      "v               ",
      "v               ",
      "v               ",
      "v               "
    ]
  ]
}