{
  "name": "scattered_foodtruck_1_floor1",
  "refpalette": "deceasedcraft:scattered_foodtruck_1/scattered_foodtruck_1_floor1_palette",
  "xsize": 16,
  "zsize": 16,
  "slices": [
    [
      "aaaaaaaaaaaaaabb",
      "aaacaacdaaaaaaab",
      "aacdcaaaaccaaaab",
      "aaccccdaccaadaaa",
      "aadccccccccaaaaa",
      "acaccccccdaeaaaa",
      "aaaaccffgggdacaa",
      "aaacccfffggcdaaa",
      "adadhcffgggcaaaa",
      "ahdahhfggggcaaaa",
      "hahhadfggggdaaaa",
      "aadaacgfgggacaaa",
      "aaaaaagggggacaaa",
      "aaaadeaacdaeaaaa",
      "aaadaaaaaaaaaaba",
      "aaaaaadaaaaaabbb"
    ],
    [
      "bbbbbbbbbbbbbbbb",
      "bbbbbbbbbbbbbbbb",
      "bbbibbbbbbjbbkbb",
      "bbklbmbbnllbbbbb",
      "bbbnllklopqbbbbb",
      "bkbborqlblksbbbb",
      "bbbblntuuvvlbkbb",
      "bbbbwltxmyvwbkbb",
      "bbbbbbtbzbtjbbbb",
      "bbbbbbAbbBvsbbbb",
      "bbbbbCnbbDvjbbbb",
      "bbbbbltmjCEbobbb",
      "bbbbbbEEbvEklbbb",
      "bbbbkFbblwGFbbbb",
      "bkbbbbbbbbbbbbbb",
      "bbbbbblbbbbkbbbb"
    ],
    [
      "bbbbbbbbbbbbbbbb",
      "bbbbbbbbbbbbbbbb",
      "bbbibbbbbbbbbbbb",
      "bbbbbbbbbbbbbbbb",
      "bbbbbbbbbbbbbbbb",
      "bbbbbrbbbbbrbbbb",
      "bbbbbbHHmbumbbbb",
      "bbbbbbIbbbtbbbbb",
      "bbbbbbtbbbEbbbbb",
      "bbbbbbJbbbtsbbbb",
      "bbbbbbbbbKvbbbbb",
      "bbbbbbIbbbtbbbbb",
      "bbbbbbvvImEbbbbb",
      "bbbbbFbbbbbFbbbb",
      "bbbbbbbbbbbbbbbb",
      "bbbbbbbbbbbbbbbb"
    ],
    [
      "bbbbbbbbbbbbbbbb",
      "bbbbbbbbbbbbbbbb",
      "bbbbbbbbbbbbbbbb",
      "bbbbbbbbbbbbbbbb",
      "bbbbbbbbbbbbbbbb",
      "bbbbbrmbbbmrbbbb",
      "bbbbbmtuHmHmbbbb",
      "bbbbbmtLLMtmbbbb",
      "bbbbbbtLLmtmbbbb",
      "bbbbbbtLLbvsbbbb",
      "bbbbbbbLLbtbbbbb",
      "bbbbbbtMLbvbbbbb",
      "bbbbbbvHvHvbbbbb",
      "bbbbbsbbbmmFbbbb",
      "bbbbbbbbbbbbbbbb",
      "bbbbbbbbbbbbbbbb"
    ],
    [
      "bbbbbbbbbbbbbbbb",
      "bbbbbbbbbbbbbbbb",
      "bbbbbbbbbbbbbbbb",
      "bbbbbbbbbbbbbbbb",
      "bbbbppppbbpppbbb",
      "bbbbbrNNNNNrObbb",
      "bbbbbPjCwbxQbbbb",
      "bbbbbPRCSbnQbbbb",
      "bbbbbPjbCbbQbbbb",
      "bbbbbPRqSbbQbbbb",
      "bbbbbPTbjbbQbbbb",
      "bbbbbQmCbbnUbbbb",
      "bbbbbQTzbyzUbbbb",
      "bbbbVsWWWWXFVbbb",
      "bbbbYZYZZYYYYbbb",
      "bbbbbbbbbbbbbbbb"
    ],
    [
      "bbbbbbbbbbbbbbbb",
      "bbbbbbbbbbbbbbbb",
      "bbbbbbbbbbbbbbbb",
      "bbbbbbbbbbbbbbbb",
      "bbbbbbbbbbbbbbbb",
      "bbbbpKKKKmKKpbbb",
      "bbbbOumbbbmvObbb",
      "bbbbbtbbbbbbbbbb",
      "bbbbbtbbbbbvbbbb",
      "bbbbbrjbbbbsbbbb",
      "bbbbbtbbbbbvbbbb",
      "bbbbbtbbbbbvbbbb",
      "bbbb0tmbbbmEVbbb",
      "bbbbZ1111112Ybbb",
      "bbbbbbbbbbbbbbbb",
      "bbbbbbbbbbbbbbbb"
    ]
  ]
}