{
  "name": "multi_terraceplaza_21_ground",
  "refpalette": "deceasedcraft:multi_terraceplaza_21/multi_terraceplaza_21_ground_palette",
  "xsize": 16,
  "zsize": 16,
  "slices": [
    [
      "aaaaaaaaaaaaaaaa",
      "aaaaaaaaaaaaaaaa",
      "bbbbbbbbbbbbbbbb",
      "cccccccccccccccc",
      "cdccccdcccccdccc",
      "cccccccccecccccc",
      "bbbbbbbbbbbbbbbb",
      "ffffffffffffffff",
      "HHHHHHHHHHHHHHHH",
      "HHHHHHHHHHHHHHHH",
      "HHHHHHHHHHHHHHHH",
      "HHHHHHHHHHHHHHHH",
      "HHHHHHHHHHHHHHHH",
      "ffffffffffffffff",
      "aagggggggggggggf",
      "aggggggggggggggg"
    ],
    [
      "                ",
      "                ",
      "                ",
      "                ",
      " h    h     h   ",
      "         e      ",
      "                ",
      "                ",
      "                ",
      "                ",
      "i    i    i    i",
      "                ",
      "                ",
      "                ",
      "  jjjjjjjjjjjjj ",
      " jjkkk kkk kkkjj"
    ],
    [
      "                ",
      "                ",
      "                ",
      "                ",
      "                ",
      "         e      ",
      "                ",
      "                ",
      "                ",
      "                ",
      "                ",
      "                ",
      "                ",
      "                ",
      "                ",
      "   lll lll lll  "
    ],
    [
      "                ",
      "                ",
      "                ",
      "                ",
      "                ",
      "         e      ",
      "                ",
      "                ",
      "                ",
      "                ",
      "                ",
      "                ",
      "                ",
      "                ",
      "                ",
      "                "
    ],
    [
      "                ",
      "                ",
      "                ",
      "                ",
      "                ",
      "         e      ",
      "                ",
      "                ",
      "                ",
      "                ",
      "                ",
      "                ",
      "                ",
      "                ",
      "                ",
      "                "
    ],
    [
      "                ",
      "                ",
      "                ",
      "                ",
      "                ",
      "         e      ",
      "                ",
      "                ",
      "                ",
      "                ",
      "                ",
      "                ",
      "                ",
      "                ",
      "                ",
      "                "
    ]
  ]
}