{
  "name": "multi_terraceplaza_21_floor2",
  "refpalette": "deceasedcraft:multi_terraceplaza_21/multi_terraceplaza_21_floor2_palette",
  "xsize": 16,
  "zsize": 16,
  "slices": [
    [
      "                ",
      "                ",
      "                ",
      "                ",
      "                ",
      "         a      ",
      "                ",
      "                ",
      "                ",
      "                ",
      "                ",
      "                ",
      "                ",
      "                ",
      "                ",
      "                "
    ],
    [
      "                ",
      "                ",
      "                ",
      "                ",
      "                ",
      "bbbbbbbbbabbbbbb",
      "        cdc     ",
      "        cdc     ",
      "        cdc     ",
      "        cdc     ",
      "        cdc     ",
      "        cdc     ",
      "        cdc     ",
      "        cdc     ",
      "        cdc     ",
      "        cdc     "
    ],
    [
      "                ",
      "eeeeeeeeeeeeeeee",
      "                ",
      "                ",
      "         f      ",
      "gggggggggagggggg",
      "hhhhhhhhcichhhhh",
      "jkkkkkkjliljmmmm",
      "jnnnnnnjliljnnnn",
      "jnnnnnnjliljnnnn",
      "jnnnnnnjliljnnnn",
      "jnnnnnnjliljnnnn",
      "jnnnnnnjliljnnnn",
      "jnnnnnnjliljnnnn",
      "jmmmmmmjliljkkkk",
      "oooooooocicooooo"
    ],
    [
      "pppppppppppppppp",
      "qrqqrrqrqqrqqqrq",
      "ssssssssstssssss",
      "ssssssssstssssss",
      "cccccccccucccccc",
      "wwwwwwwwwawwwwww",
      "xxxxxxxxxwxxxxxx",
      "xxxxxxxxxwxxxxxx",
      "xxxxxxxxxwxxxxxx",
      "xxxxxxxxxwxxxxxx",
      "xxxxxxxxxwxxxxxx",
      "xxxxxxxxxwxxxxxx",
      "xxxxxxxxxwxxxxxx",
      "xxxxxxxxxwxxxxxx",
      "xxxxxxxxxwxxxxxx",
      "xxxxxxxxxwxxxxxx"
    ],
    [
      "pppppppppppppppp",
      "qrqqrrqrqqrqqqrq",
      "yyyyyyyyyyyyyyyy",
      "yyyyyyyyyyyyyyyy",
      "yyyyyyyyyyyyyyyy",
      "AAAAAAAAAaAAAAAA",
      "AAAAAAAAAAAAAAAA",
      "AAAAAAAAAAAAAAAA",
      "AAAAAAAAAAAAAAAA",
      "AAAAAAAAAAAAAAAA",
      "AAAAAAAAAAAAAAAA",
      "AAAAAAAAAAAAAAAA",
      "AAAAAAAAAAAAAAAA",
      "AAAAAAAAAAAAAAAA",
      "BBBBBBBBBBBBBBBB",
      "BBBBBBBBBBBBBBBB"
    ],
    [
      "CpCCppCppppppppp",
      "qrqqrrqrqqrqqqrq",
      "                ",
      "                ",
      "                ",
      "         a      ",
      " D E FI  J K L M",
      "        NO      ",
      "         P Q R S",
      " TU V W         ",
      "           X Y Z",
      "        01      ",
      " 2  34   5 6 7 8",
      " 9#$!%^ &*      ",
      "((((((((((((((((",
      ")        (++++++"
    ]
  ]
}