{
  "name": "multi_terraceplaza_21_floor3",
  "refpalette": "deceasedcraft:multi_terraceplaza_21/multi_terraceplaza_21_floor3_palette",
  "xsize": 16,
  "zsize": 16,
  "slices": [
    [
      "abbabaabbbbbbbbb",
      "cdccddcdccdcccdc",
      "                ",
      "                ",
      "                ",
      "         e      ",
      "                ",
      "         f      ",
      "         g      ",
      "                ",
      "                ",
      "         h      ",
      "         i      ",
      " jkl mn  o      ",
      "pppppppppppqprps",
      "t        puuuuuu"
    ],
    [
      "bbbabaabbbbbbbbb",
      "cdccddcdccdcccdc",
      "                ",
      "                ",
      "                ",
      "         e      ",
      "                ",
      "                ",
      "                ",
      "                ",
      "                ",
      "                ",
      "                ",
      " jwl            ",
      "pppppppppppxpxpx",
      "y        puuuuuu"
    ],
    [
      "bbbbbbbbbbbbbbbb",
      "cdccddcdccdcccdc",
      "                ",
      "                ",
      "                ",
      "         e      ",
      "                ",
      "                ",
      "                ",
      "                ",
      "                ",
      "                ",
      "                ",
      "                ",
      "pppppppppppppppp",
      "p        puuuuuu"
    ],
    [
      "bbbbbbbbbbbbbbbb",
      "cdccddcdccdcccdc",
      "                ",
      "                ",
      "                ",
      "         e      ",
      "                ",
      "                ",
      "                ",
      "                ",
      "                ",
      "                ",
      "                ",
      "                ",
      "pppppppppppApBpC",
      "p        puuuuuu"
    ],
    [
      "bDDbDDDDDbbbDDbb",
      "cdccddcdccdcccdc",
      "                ",
      "                ",
      "                ",
      "         e      ",
      "                ",
      "                ",
      "                ",
      "                ",
      "                ",
      "                ",
      "                ",
      "                ",
      "pppppppppppxpxpx",
      "p        puuuuuu"
    ],
    [
      "DDbbbbDDbbbDDbbb",
      "cdccddcdccdcccdc",
      "                ",
      "                ",
      "                ",
      "         e      ",
      "         E      ",
      "                ",
      "                ",
      "                ",
      "                ",
      "                ",
      "                ",
      "                ",
      "pppppppppppppppp",
      "pFFFFFFFFFFFFFFF"
    ]
  ]
}