{
  "name": "multi_terraceplaza_21_floor5",
  "refpalette": "deceasedcraft:multi_terraceplaza_21/multi_terraceplaza_21_floor5_palette",
  "xsize": 16,
  "zsize": 16,
  "slices": [
    [
      "aaaaaaaaaaaaaaaa",
      "bcbbccbcbbcbbbcb",
      "                ",
      "                ",
      "                ",
      "         d      ",
      "                ",
      "                ",
      "                ",
      "                ",
      "                ",
      "                ",
      "                ",
      "                ",
      "                ",
      "                "
    ],
    [
      "aaaaaaaaaaaaaaaa",
      "bcbbccbcbbcbbbcb",
      "eeeeeeeeeeeeeeee",
      "eeeeeeeeeeeeeeee",
      "ffffffffffffffff",
      "gggggggggdgggggg",
      "hhhhhhhhhhhhhhhh",
      "                ",
      "                ",
      "hhhhhhhhhhhhhhhh",
      "hhhhhhhhhhhhhhhh",
      "hhhhhhhhhhhhhhhh",
      "hhhhhhhhhhhhhhhh",
      "                ",
      "                ",
      "hhhhhhhhhhhhhhhh"
    ],
    [
      "aaaaaaaaaaaaaaaa",
      "bcbbccbcbbcbbbcb",
      "                ",
      "                ",
      "iiiiiiiiiiiiiiii",
      "iiiiiiiiiiiiiiii",
      "iiiiiiiiiiiiiiii",
      "@@@@@@@@@@@@@@@@",
      "@@@@@@@@@@@@@@@@",
      "iiiiiiiiiiiiiiii",
      "iiiiiiiiiiiiiiii",
      "iiiiiiiiiiiiiiii",
      "iiiiiiiiiiiiiiii",
      "@@@@@@@@@@@@@@@@",
      "@@@@@@@@@@@@@@@@",
      "iiiiiiiiiiiiiiii"
    ],
    [
      "aaaaaaaaaaaaaaaa",
      "bcbbccbcbbcbbbcb",
      "                ",
      "                ",
      "                ",
      "                ",
      "                ",
      "                ",
      "                ",
      "                ",
      "                ",
      "                ",
      "                ",
      "                ",
      "                ",
      "                "
    ],
    [
      "                ",
      "                ",
      "                ",
      "                ",
      "                ",
      "                ",
      "                ",
      "                ",
      "                ",
      "                ",
      "                ",
      "                ",
      "                ",
      "                ",
      "                ",
      "                "
    ],
    [
      "                ",
      "                ",
      "                ",
      "                ",
      "                ",
      "                ",
      "                ",
      "                ",
      "                ",
      "                ",
      "                ",
      "                ",
      "                ",
      "                ",
      "                ",
      "                "
    ]
  ]
}