{
  "name": "multi_terraceplaza_21part2_floor3",
  "refpalette": "deceasedcraft:multi_terraceplaza_21/multi_terraceplaza_21part2_floor3_palette",
  "xsize": 16,
  "zsize": 16,
  "slices": [
    [
      "abbabaabbbbbbbbb",
      "                ",
      "                ",
      "                ",
      "                ",
      "                ",
      "                ",
      "                ",
      "                ",
      "                ",
      "                ",
      "                ",
      "                ",
      "                ",
      "ccccccccccc c c ",
      "         c      "
    ],
    [
      "bbbabaabbbbbbbbb",
      "                ",
      "                ",
      "                ",
      "                ",
      "                ",
      "                ",
      "                ",
      "                ",
      "                ",
      "                ",
      "                ",
      "                ",
      "                ",
      "ccccccccccc c c ",
      "d        c      "
    ],
    [
      "bbbbbbbbbbbbbbbb",
      "                ",
      "                ",
      "                ",
      "                ",
      "                ",
      "                ",
      "                ",
      "                ",
      "                ",
      "                ",
      "                ",
      "                ",
      "                ",
      "cccccccccccccccc",
      "c        c      "
    ],
    [
      "bbbbbbbbbbbbbbbb",
      "                ",
      "                ",
      "                ",
      "                ",
      "                ",
      "                ",
      "                ",
      "                ",
      "                ",
      "                ",
      "                ",
      "                ",
      "                ",
      "ccccccccccc c c ",
      "c        c      "
    ],
    [
      "beebeeeeebbbeebb",
      "                ",
      "                ",
      "                ",
      "                ",
      "                ",
      "                ",
      "                ",
      "                ",
      "                ",
      "                ",
      "                ",
      "                ",
      "                ",
      "ccccccccccc c c ",
      "c        c      "
    ],
    [
      "eebbbbeebbbeebbb",
      "                ",
      "                ",
      "                ",
      "                ",
      "                ",
      "                ",
      "                ",
      "                ",
      "                ",
      "                ",
      "                ",
      "                ",
      "                ",
      "cccccccccccccccc",
      "c               "
    ]
  ]
}