{
  "name": "multi_terraceplaza_21_base2",
  "refpalette": "deceasedcraft:multi_terraceplaza_21/multi_terraceplaza_21_base2_palette",
  "xsize": 16,
  "zsize": 16,
  "slices": [
    [
      "vvvvvvvvvvvvvvvv",
      "aaaaaaaaaaaaaaaa",
      "bbbbbbbbbbbbbbbb",
      "bbbbbbbbbbbbbbbb",
      "HHHHHHHHHHHHHHHH",
      "HHHHHHHHHcHHHHHH",
      "HHHHHHHHHHHHHHHH",
      "HHHHHHHHHHHHHHHH",
      "HHHHHHHHHHHHHHHH",
      "HHHHHHHHHHHHHHHH",
      "HHHHHHHHHHHHHHHH",
      "HHHHHHHHHHHHHHHH",
      "HHHHHHHHHHHHHHHH",
      "HHHHHHHHHHHHHHHH",
      "HHHHHHHHHHHHHHHH",
      "HHHHHHHHHHHHHHHH"
    ],
    [
      "vvvvvvvvvvvvvvvv",
      "aaaaaaaaaaaaaaaa",
      "                ",
      "                ",
      "defefefefgefefef",
      "d        c      ",
      "d        g h    ",
      "dijijijij ijijij",
      "d               ",
      "d               ",
      "d               ",
      "d               ",
      "defefefef f efef",
      "d        g      ",
      "d     k  g      ",
      "dijijijijgjjijij"
    ],
    [
      "vvvvvvvvvvvvvvvv",
      "aaaaaaaaaaaaaaaa",
      "                ",
      "                ",
      "                ",
      "         c      ",
      "                ",
      "                ",
      "                ",
      "                ",
      "                ",
      "                ",
      "                ",
      "                ",
      "                ",
      "                "
    ],
    [
      "vvvvvvvvvvvvvvvv",
      "aaaaaaaaaaaaaaaa",
      "                ",
      "                ",
      "                ",
      "         c      ",
      "                ",
      "                ",
      "                ",
      "                ",
      "                ",
      "                ",
      "                ",
      "                ",
      "                ",
      "                "
    ],
    [
      "vvvvvvvvvvvvvvvv",
      "aaaaaaaaaaaaaaaa",
      "llllllllllllllll",
      "mmmmmmmmmmmmmmmm",
      "mmmmmmmmmmmmmmmm",
      "mmmmmmmmmcmmmmmm",
      "                ",
      "                ",
      " n              ",
      "                ",
      "                ",
      "                ",
      "                ",
      "            n   ",
      "                ",
      "                "
    ],
    [
      "vvvvvvvvvvvvvvvv",
      "aaaaaaaaaaaaaaaa",
      "oooooooooooooooo",
      "oooooooooooooooo",
      "oooooooooooooooo",
      "pppppppppcpppppp",
      "oooooooooooooooo",
      "oooooooooooooooo",
      "oqooooqoooooqooo",
      "oooooooooooooooo",
      "oooooooooooooooo",
      "oooooooooooooooo",
      "oooooooooooooooo",
      "oqooooqoooooqooo",
      "oooooooooooooooo",
      "oooooooooooooooo"
    ]
  ]
}