{
  "name": "multi_terraceplaza_21_base1",
  "refpalette": "deceasedcraft:multi_terraceplaza_21/multi_terraceplaza_21_base1_palette",
  "xsize": 16,
  "zsize": 16,
  "slices": [
    [
      "vvvvvvvvvvvvvvvv",
      "aaaaaaaaaaaaaaaa",
      "bbbbbbbbbbbbbbbb",
      "bbbbbbbbbbbbbbbb",
      "HHHHHHHHHHHHHHHH",
      "HHHHHHHHHcHHHHHH",
      "HHHHHHHHHHHHHHHH",
      "HHHHHHHHHHHHHHHH",
      "HHHHHHHHHHHHHHHH",
      "HHHHHHHHHHHHHHHH",
      "HHHHHHHHHHHHHHHH",
      "HHHHHHHHHHHHHHHH",
      "HHHHHHHHHHHHHHHH",
      "HHHHHHHHHHHHHHHH",
      "HHHHHHHHHHHHHHHH",
      "HHHHHHHHHHHHHHHH"
    ],
    [
      "vvvvvvvvvvvvvvvv",
      "aaaaaaaaaaaaaaaa",
      "                ",
      "                ",
      "defefefefgefefef",
      "d        c      ",
      "d        g     h",
      "dijijijij ijijij",
      "d               ",
      "d               ",
      "d               ",
      "d               ",
      "defefefef efefef",
      "d        g      ",
      "d   k    g      ",
      "dijijijijgijijij"
    ],
    [
      "vvvvvvvvvvvvvvvv",
      "aaaaaaaaaaaaaaaa",
      "                ",
      "                ",
      "                ",
      "         c      ",
      "                ",
      "                ",
      "                ",
      "                ",
      "                ",
      "                ",
      "                ",
      "                ",
      "                ",
      "                "
    ],
    [
      "vvvvvvvvvvvvvvvv",
      "aaaaaaaaaaaaaaaa",
      "                ",
      "                ",
      "                ",
      "         c      ",
      "                ",
      "                ",
      "                ",
      "                ",
      "                ",
      "                ",
      "                ",
      "                ",
      "                ",
      "                "
    ],
    [
      "vvvvvvvvvvvvvvvv",
      "aaaaaaaaaaaaaaaa",
      "lllllllllmllllll",
      "nnnnnnnnnnnnnnnn",
      "nnnnnnnnnnnnnnnn",
      "nnnnnnnnncnnnnnn",
      "                ",
      "                ",
      "      o         ",
      "                ",
      "                ",
      "                ",
      "                ",
      " o              ",
      "                ",
      "                "
    ],
    [
      "vvvvvvvvvvvvvvvv",
      "aaaaaaaaaaaaaaaa",
      "pppppppppqpppppp",
      "rrrrrrrrrqrrrrrr",
      "r rrrr rrqrr rrr",
      "qqqqqqqqqcqqqqqq",
      "pppppppppppppppp",
      "pppppppppppppppp",
      "psppppspppppsppp",
      "pppppppppppppppp",
      "pppppppppppppppp",
      "pppppppppppppppp",
      "pppppppppppppppp",
      "psppppspppppsppp",
      "pppppppppppppppp",
      "pppppppppppppppp"
    ]
  ]
}