{
  "name": "multi_terraceplaza_21_floor4",
  "refpalette": "deceasedcraft:multi_terraceplaza_21/multi_terraceplaza_21_floor4_palette",
  "xsize": 16,
  "zsize": 16,
  "slices": [
    [
      "aabbaaaabbbaabbb",
      "cdccddcdccdcccdc",
      "                ",
      "                ",
      "                ",
      "         e      ",
      "                ",
      "                ",
      "                ",
      "                ",
      "                ",
      "                ",
      "                ",
      "ffffffffffffffff",
      "ffffffffffffffff",
      "fggggggggggggggg"
    ],
    [
      "abbbbaabbbaabbbb",
      "cdccddcdccdcccdc",
      "                ",
      "                ",
      "                ",
      "         e      ",
      "                ",
      "                ",
      "                ",
      "                ",
      "                ",
      "                ",
      "                ",
      "hhhhhhhhhhhhhhhh",
      "                ",
      "                "
    ],
    [
      "abaaaaabaaaaaabb",
      "cdccddcdccdcccdc",
      "                ",
      "                ",
      "                ",
      "         e      ",
      "                ",
      "                ",
      "                ",
      "                ",
      "                ",
      "                ",
      "                ",
      "                ",
      "                ",
      "                "
    ],
    [
      "bbbbbbbbbbbbbbbb",
      "cdccddcdccdcccdc",
      "                ",
      "                ",
      "                ",
      "         e      ",
      "                ",
      "                ",
      "                ",
      "                ",
      "                ",
      "                ",
      "                ",
      "                ",
      "                ",
      "                "
    ],
    [
      "bbbbbbbbbbbbbbbb",
      "cdccddcdccdcccdc",
      "                ",
      "                ",
      "                ",
      "         e      ",
      "                ",
      "                ",
      "                ",
      "                ",
      "                ",
      "                ",
      "                ",
      "                ",
      "                ",
      "                "
    ],
    [
      "bbbbbbbbbbbbbbbb",
      "cdccddcdccdcccdc",
      "                ",
      "                ",
      "                ",
      "         e      ",
      "                ",
      "                ",
      "                ",
      "                ",
      "                ",
      "                ",
      "                ",
      "                ",
      "                ",
      "                "
    ]
  ]
}