{
  "name": "multi_hospital_2_base2",
  "refpalette": "deceasedcraft:multi_hospital_2/multi_hospital_2_base2_palette",
  "xsize": 16,
  "zsize": 16,
  "slices": [
    [
      "vvvvvvvvvvvvvvvv",
      "aaaaaaaaaaaaaaaa",
      "aaaaaaaaaaaaaaaa",
      "aaaaaaaaaaaaaaaa",
      "aaaaaaaaaaaaaaaa",
      "bbbaaaaaaaaaaaaa",
      "  caaaaaaaaaaaaa",
      "  dddddddddddddd",
      "  efbbbbbbbbbbbb",
      "   @           b",
      "   g           b",
      "   g           h",
      "   g           h",
      "   g           h",
      "   g           h",
      "   g           h"
    ],
    [
      "vvvvvvvvvvvvvvvv",
      "aaaaaaaaaaaaaaaa",
      "aaaaaaaaaaaaaaaa",
      "aaaaaaaaaaaaaaaa",
      "aaaaaaaaaaaaaaaa",
      "bbbaaaaaaaaaaaaa",
      "  caaaaaaaaaaaaa",
      "  dddddddddddddd",
      "  efbbbbbbbbbbbb",
      "   @           b",
      "   g           b",
      "   g           i",
      "   g           i",
      "   g           i",
      "   g     j     i",
      "   g           i"
    ],
    [
      "vvvvvvvvvvvvvvvv",
      "aaaaaaaaaaaaaaaa",
      "aaaaaaaaaaaaaaaa",
      "aaaaaaaaaaaaaaaa",
      "aaaaaaaaaaaaaaaa",
      "bbbaaaaaaaaaaaaa",
      "  caaaaaaaaaaaaa",
      "  dddddddddddddd",
      "  efbbbbbbbbbbbb",
      "   @           b",
      "   @           b",
      "   @           b",
      "   @           b",
      "   @           b",
      "   @     k     b",
      "   @           b"
    ],
    [
      "vvvvvvvvvvvvvvvv",
      "aaaaaaaaaaaaaaaa",
      "aaaaaaaaaaaaaaaa",
      "aaaaaaaaaaaaaaaa",
      "aaaaaaaaaaaaaaaa",
      "bbbaaaaaaaaaaaaa",
      "  caaaaaaaaaaaaa",
      "  dddddddddddddd",
      "  efbbbbbbbbbbbb",
      "  efbbbbbbbbbbbb",
      "  efbbbbbbbbbbbb",
      "  efbbbbbbbbbbbb",
      "  efbbbbbbbbbbbb",
      "  efbbbbbbbbbbbb",
      "  efbbbbblbbbbbb",
      "  efbbbbbbbbbbbb"
    ],
    [
      "vvvvvvvvvvvvvvvv",
      "mmmnnnnnnnnnnnnn",
      "mmmnnnnnnnnnnnnn",
      "mmmnnnnnnnnnnnnn",
      "mmmnnnnnnnnnnnnn",
      "mmmnnnnnnnnnnnnn",
      "mmmnnnnnnnnnnnnn",
      "mmdddddddddddddd",
      "mmmodddddddddddd",
      "mmmodddddddddddd",
      "mmmodddddddddddd",
      "mmmodddddddddddd",
      "mmmodddddddddddd",
      "mmmodddddddddddd",
      "mmmodddddddddddd",
      "mmmodddddddddddd"
    ],
    [
      "vvvvvvvvvvvvvvvv",
      "nnndddddnnnndddd",
      "nnnnnnnnnnnnnnnn",
      "nnnnnnnnnnnnnnnn",
      "nnnnnnnnnnnnnnnn",
      "nnnnnnnnnnnnnnnn",
      "nnndddddnnnnnnnn",
      "nnnnnnpqnnnnnnnn",
      "nnnnnnpqnnnnnnnn",
      "nnnnnnpqnnnnnnnn",
      "nnnnnnpqnnnnnnnn",
      "nnnnnnpqnnnnnnnn",
      "nnnnnnpqnnnnnnnn",
      "nnnnnnpqnnnnnnnn",
      "nnnnnnpqnnnnnnnn",
      "nnnnnnpqnnnnnnnn"
    ]
  ]
}