{
  "name": "multi_hospital_2_base1",
  "refpalette": "deceasedcraft:multi_hospital_2/multi_hospital_2_base1_palette",
  "xsize": 16,
  "zsize": 16,
  "slices": [
    [
      "vvvvvvvvvvvvvvvv",
      "   aaaaabbbbaaaa",
      "       cbbbbbbbb",
      "      debbbbbbbb",
      "      ffbbbbbbbb",
      "      ffbbbbbbbb",
      "   aaaaabbbbbbbb",
      "    ghijbbbbbbbb",
      "   kkbilbbbbbbbb",
      "     hijbbbbbbbb",
      "    ghijbbbbbbbb",
      "   kkbi bbbbbbbb",
      "     hijbbbbbbbb",
      "    mhilbbbbbbbb",
      "   kkbijbbbbbbbb",
      "     hijbbbbbbbb"
    ],
    [
      "vvvvvvvvvvvvvvvv",
      "   aaaaannnnaaaa",
      "             o  ",
      "             p  ",
      "             o q",
      "             orr",
      "   aaaaa    aaaa",
      "     his     ott",
      "   uwbi      o x",
      "     his     y  ",
      "     hi      o  ",
      "    wbA     aaaa",
      "     hi      o  ",
      "     hi      B  ",
      "    wbi      o C",
      "     his     orr"
    ],
    [
      "vvvvvvvvvvvvvvvv",
      "   aaaaannnnaaaa",
      "             o  ",
      "             D  ",
      "             oE ",
      "             oFI",
      "   aaaaa    aaaa",
      "     hi      oJK",
      "     bi      oE ",
      "     hi      L  ",
      "     hA      o  ",
      "     bA     aaaa",
      "     hA      o  ",
      "     hi      M  ",
      "     bi      o  ",
      "     hi      oNO"
    ],
    [
      "vvvvvvvvvvvvvvvv",
      "   aaaaannnnaaaa",
      "             o  ",
      "            PQ  ",
      "             o  ",
      "             o  ",
      "   aaaaa    aaaa",
      "     hi      o  ",
      "     bi      o  ",
      "     hi     RQ  ",
      "     hi      o  ",
      "     bA     aaaa",
      "     hi      o  ",
      "     hi     PQ  ",
      "     bi      o  ",
      "     hi      o! "
    ],
    [
      "vvvvvvvvvvvvvvvv",
      "SSSaaaaannnnaaaa",
      "bbbbbb       oTT",
      "SSSSSb       oTT",
      "SSSSSb       oTT",
      "bbbbbb       oTT",
      "SSSaaaaa    aaaa",
      "SSSSSbiU     oTT",
      "bbbbbbiU     oTT",
      "SSSSSbiU     oTT",
      "SSSSSbiU     oTT",
      "bbbbbbiU    aaaa",
      "SSSSSbiU     oTT",
      "SSSSSbiU     oTT",
      "bbbbbbiU     oTT",
      "SSSSSbiU     oTT"
    ],
    [
      "vvvvvvvvvvvvvvvv",
      "VVVaaaaaVVVVaaaa",
      "VVVVVbVVVVVVVVVV",
      "VVVVVbVVVVVVVVVV",
      "VVVVVbVVVVVVVVVV",
      "VVVVVbVVVVVVVVVV",
      "VVVaaaaaVVVVaaaa",
      "VVVVVbiVVVVVVVVV",
      "VVVVVbiVVVVVVVVV",
      "VVVVVbiVVVVVVVVV",
      "VVVVVbiVVVVVVVVV",
      "VVVVVbiVVVVVaaaa",
      "VVVVVbiVVVVVVVVV",
      "VVVVVbiVVVVVVVVV",
      "VVVVVbiVVVVVVVVV",
      "VVVVVbiVVVVVVVVV"
    ]
  ]
}