{
  "name": "multi_hospital_2_base4",
  "refpalette": "deceasedcraft:multi_hospital_2/multi_hospital_2_base4_palette",
  "xsize": 16,
  "zsize": 16,
  "slices": [
    [
      "vvvvvvvvvvvvvvvv",
      "aaaaaaaaaaaaaaaa",
      "aaaaaaaaaaaaaaaa",
      "aaaaaaaaaaaaaaaa",
      "aaaaaaaaaaaaaaaa",
      "bbbaaaaaaaaaaaaa",
      "  caaaaaaaaaaaaa",
      "  dddddddddddddd",
      "    e           ",
      "    e           ",
      "    e           ",
      "    e           ",
      "    e           ",
      "    e           ",
      "    e           ",
      "    e           "
    ],
    [
      "vvvvvvvvvvvvvvvv",
      "aaaaaaaaaaaaaaaa",
      "aaaaaaaaaaaaaaaa",
      "aaaaaaaaaaffffff",
      "aaaaaaaaaaffffff",
      "bbbaaaaaaaffffff",
      "  caaaaaaaffffff",
      "  dddddddddddddd",
      "    e           ",
      "    e          g",
      "    e           ",
      "    e           ",
      "    e           ",
      "    e           ",
      "    e          g",
      "    e           "
    ],
    [
      "vvvvvvvvvvvvvvvv",
      "aaaaaaaaaaaaaaaa",
      "aaaaaaaaaaaaaaaa",
      "aaaaaaaaaaffffff",
      "aaaaaaaaaafhhhhh",
      "bbbaaaaaaafhhffi",
      "  caaaaaaafhhffi",
      "  dddddddddddddi",
      "    e          i",
      "    e         jk",
      "    e          i",
      "    e          i",
      "    e          i",
      "    e          i",
      "    e     l   jk",
      "    e          i"
    ],
    [
      "vvvvvvvvvvvvvvvv",
      "aaaaaaaaaaaaaaaa",
      "aaaaaaaaaaaaaaaa",
      "aaaaaaaaaaffffff",
      "aaaaaaaaaaf     ",
      "bbbaaaaaaafmmffi",
      "  caaaaaaafnnfff",
      "  ddddddddd  ddd",
      "   offffffffffff",
      "   offffffffffff",
      "   offffffffffff",
      "   offffffffffff",
      "   offffffffffff",
      "   offffffffffff",
      "   offffffpfffff",
      "   offffffffffff"
    ],
    [
      "vvvvvvvvvvvvvvvv",
      "aaaaaaaaaaaaaaaa",
      "aaaqqqqqqqqqqqqa",
      "aaaqqqqqqqqqqqqf",
      "aaaqqqqqqqqqqqqf",
      "bbbrrrrrrrrrrrqi",
      "sstrrrrrrrrrrrqf",
      "ssdddddddddrrddd",
      "  uwxxxxxxxxxxxx",
      "  uwxxxxxxxxxxyx",
      "  uwxxxxxxxxxxyx",
      "  uwxyyyyyxxxxyx",
      "  uwxyyyyyxxxxyx",
      "  uwxxxxxxxxxxyx",
      "  uwxxxxxxxxxxyx",
      "  uwxxxxxxxxxxyx"
    ],
    [
      "vvvvvvvvvvvvvvvv",
      "aaaaaaaaaaaaaaaa",
      "aaaqqqqqqqqqqqqa",
      "aaaqABBBBBBBBAqf",
      "aaaqqCCCCCCCCqqf",
      "bbbq         Dqi",
      "  EF         Iqf",
      "JJdddddddddKKddd",
      "  uwbbbbbbLMNLbb",
      "   @  O       Pb",
      "   @  Q QQR   Pb",
      "   @ SSSSS    Tb",
      "   @ UVWVU    Xb",
      "   @     Y    Tb",
      "   @          Pb",
      "   @          Tb"
    ]
  ]
}