{
  "name": "multi_hospital_2_top",
  "refpalette": "deceasedcraft:multi_hospital_2/multi_hospital_2_top_palette",
  "xsize": 16,
  "zsize": 16,
  "slices": [
    [
      "                ",
      "                ",
      "                ",
      "                ",
      "                ",
      "      abbbbbbbbb",
      "      abccccdddd",
      "      abcddddddd",
      "      abcddddddd",
      "      abcddddddd",
      "      abcddddddd",
      "bbbbbbbbcddddddd",
      "eeeeeeeecddddddd",
      "ddffffffdddddddd",
      "ddffffffdddddddd",
      "ddffffffdddddddd"
    ],
    [
      "                ",
      "                ",
      "                ",
      "                ",
      "                ",
      "                ",
      "        gggghhhh",
      "        g   iiii",
      "        g   ijkl",
      "        g   i m ",
      "        g   n   ",
      " oo oo og   iiii",
      "eeeeeeeeg   ippq",
      " rs  t u    w   ",
      "x s yA BC   iD  ",
      "  s EF BI   i JK"
    ],
    [
      "                ",
      "                ",
      "                ",
      "                ",
      "                ",
      "                ",
      "        gggghhLh",
      "        g   bb b",
      "        g   bMNO",
      "        g   bP  ",
      "        g   Q   ",
      " oo oo og   bbbb",
      "ReeReeReg   b S ",
      "  T UV W    X   ",
      "  T  Y a    b   ",
      "  T Z  a    g0  "
    ],
    [
      "                ",
      "                ",
      "                ",
      "                ",
      "                ",
      "                ",
      "        gggghLLL",
      "        g   b   ",
      "        g   b   ",
      "        g   b   ",
      "        g  12   ",
      " oo oo og   bbbb",
      "ReeReeReg   b 3 ",
      "  T 45 6   72   ",
      "  T  8 a    b   ",
      "  T 9  a    g#  "
    ],
    [
      "                ",
      "                ",
      "                ",
      "                ",
      "                ",
      "                ",
      "        gggghhLh",
      "        g   bb b",
      "        g   b   ",
      "        g   b   ",
      "        g   b   ",
      " oo oo og   bbbb",
      "ReeReeReg   b   ",
      "  $%^$%^    b   ",
      "  $&^$&^    b   ",
      "  $&^$&^    b   "
    ],
    [
      "                ",
      "                ",
      "                ",
      "                ",
      "                ",
      "                ",
      "        gggghhhh",
      "        g   bbbb",
      "        g   b   ",
      "        g   b   ",
      "        g   b   ",
      " oo oo og   bbbb",
      "eeeeeeeeg   b   ",
      "***(**(a    b   ",
      "))T+---a    b   ",
      "))T[---a    b   "
    ],
    [
      "                ",
      "                ",
      "                ",
      "                ",
      "                ",
      "      abbbbbbbbb",
      "      abcccc]]]]",
      "      abc]]]]]]]",
      "      abc]]]]]]]",
      "      abc]]]]]]]",
      "      abc]]]]]]]",
      "bbbbbbbbc]]]]]]]",
      "]]]]]]]]c]]]]]]]",
      "{{{{{*{{c]]]]]]]",
      "{{{{{{{{c]]]]]]]",
      "{{{{}}}{c]]]]]]]"
    ],
    [
      "                ",
      "                ",
      "                ",
      "                ",
      "                ",
      "                ",
      "        {{{{{{{{",
      "        {       ",
      "        {       ",
      "        {       ",
      "        {       ",
      "       o{o o o o",
      "{{{{{{{{||||||||",
      "     *  |       ",
      "    ;*; |      :",
      "   '< <>|       "
    ],
    [
      "                ",
      "                ",
      "                ",
      "                ",
      "                ",
      "                ",
      "                ",
      "                ",
      "                ",
      "                ",
      "                ",
      "       o o o o o",
      "        ||||||||",
      "        |       ",
      "        |       ",
      "    ,., |       "
    ],
    [
      "                ",
      "                ",
      "                ",
      "                ",
      "                ",
      "                ",
      "                ",
      "                ",
      "                ",
      "                ",
      "                ",
      "       o o o o o",
      "        ||||||||",
      "        |       ",
      "        |       ",
      "        |       "
    ],
    [
      "                ",
      "                ",
      "                ",
      "                ",
      "                ",
      "                ",
      "                ",
      "                ",
      "                ",
      "                ",
      "                ",
      "       o o o o o",
      "        ||||||||",
      "        |       ",
      "        |       ",
      "        |       "
    ],
    [
      "                ",
      "                ",
      "                ",
      "                ",
      "                ",
      "                ",
      "                ",
      "                ",
      "                ",
      "                ",
      "      {{{{{{{{{{",
      "      {}}}}}}}}}",
      "      {}cccccccc",
      "      {}c]]]]]]]",
      "      {}c]]]]]]]",
      "      {}c]]]]]]]"
    ],
    [
      "                ",
      "                ",
      "                ",
      "                ",
      "                ",
      "                ",
      "                ",
      "                ",
      "                ",
      "                ",
      "      ??????????",
      "      ?         ",
      "      ? ????????",
      "      ? ????????",
      "      ? ????????",
      "      ? ????????"
    ]
  ]
}