{
  "name": "multi_hospital_2_floor1",
  "refpalette": "deceasedcraft:multi_hospital_2/multi_hospital_2_floor1_palette",
  "xsize": 16,
  "zsize": 16,
  "slices": [
    [
      "                ",
      "                ",
      " a              ",
      "bc              ",
      "db              ",
      "dc              ",
      "db              ",
      "dc              ",
      "deeeeeeeeeeeeee ",
      "dddddddddddddde ",
      "dddddddddddddde ",
      "dddddddddddddde ",
      "dddddddddddddde ",
      "dddddddddddddde ",
      "dddddddddddddde ",
      "dddddddddddddde "
    ],
    [
      "                ",
      "                ",
      " a              ",
      "ff              ",
      " f              ",
      "gf              ",
      "hf              ",
      "if              ",
      "jeeeeeeeeeeeeee ",
      " klm nopqr stuw ",
      " k    o  r xyu  ",
      " klm  oA B   uw ",
      " CCCCDCCCr xyuw ",
      "         E   u  ",
      " FFFFIFFFr xyuw ",
      " klm  olm    uw "
    ],
    [
      "                ",
      "                ",
      " a              ",
      "ff              ",
      " f              ",
      " f              ",
      " f              ",
      " f              ",
      "jeeeeeeeeeeeeee ",
      "JK    L  M   uw ",
      " K    L  M   j  ",
      " K    L  N   uw ",
      " OOOOPOOOM   uw ",
      "         Q   j  ",
      " RRRRSRRRM   uw ",
      " K    L      uw "
    ],
    [
      "                ",
      "                ",
      " a              ",
      "ff              ",
      " f              ",
      " f              ",
      " f              ",
      " f              ",
      "jeecceecceeccee ",
      " K    L  M   uw ",
      " K    L  M   j  ",
      " K    L  M   uw ",
      " OOOOOOOOM   uw ",
      "         M   j  ",
      " RRRRRRRRM   uw ",
      " K    L      uw "
    ],
    [
      "                ",
      "                ",
      " a              ",
      "ff              ",
      " f              ",
      " f              ",
      " f              ",
      " f              ",
      "jeeeeeeeeeeeeee ",
      " K    L  M   uw ",
      " K    L  M   j  ",
      " K    L  M   uw ",
      " OOOOOOOOM   uw ",
      " T   T   M   j  ",
      " RRRRRRRRM   uw ",
      " K    L      uw "
    ],
    [
      "                ",
      "                ",
      " a              ",
      "ff              ",
      " f              ",
      " f              ",
      " f              ",
      " f              ",
      "jeeeeeeeeeeeeee ",
      " uUUUuUUUuUUUuw ",
      " uUUUuUUUuUUUu  ",
      " uUUUuUUUuUUUuw ",
      " uUUUuUUUuUUUuw ",
      " uUUUuUUUuUUUu  ",
      " uUUUuUUUuUUUuw ",
      " uUUUuUUUuUUUuw "
    ]
  ]
}