{
  "name": "multi_hospital_2_base3",
  "refpalette": "deceasedcraft:multi_hospital_2/multi_hospital_2_base3_palette",
  "xsize": 16,
  "zsize": 16,
  "slices": [
    [
      "vvvvvvvvvvvvvvvv",
      "aaaaaaaaaaaaaaaa",
      "aaabbbbbbbbbbbba",
      "aaabcddddddddcbe",
      "aaabbffffffffbbe",
      "gggb          bh",
      "   i          be",
      "  jjjjjjjjj  jjj",
      "  klggggggmnomgg",
      "   @pq r      sg",
      "   t          ug",
      "   t wxyxx    Ag",
      "   t BC DE     g",
      "   t          Fg",
      "   t          Ig",
      "   t           g"
    ],
    [
      "vvvvvvvvvvvvvvvv",
      "aaaaaaaaaaaaaaaa",
      "aaabbbbbbbbbbbba",
      "aaabbbbbbbbbbbbe",
      "aaabbbbbbbbbbbbe",
      "gggb  J    J Kbh",
      "  LM          be",
      "  jjjjjjjjjNNjjj",
      "  klggggggmOOmgg",
      "   @           g",
      "   tP          g",
      "   t           g",
      "   t          Qg",
      "   t           g",
      "   t           g",
      "   t           g"
    ],
    [
      "vvvvvvvvvvvvvvvv",
      "aaaaaaaaaaaaaaaa",
      "aaabbbbbbbbbbbba",
      "aaabbbbbbbbbbbbe",
      "aaabbbbbbbbbbbbe",
      "ggghRhhhhhhhhRhh",
      "  Sb       K Kbe",
      "  jjjjjjjjjjjjjj",
      "  klggggggmmmmgg",
      "   @           g",
      "   t           g",
      "   tP          g",
      "   t           g",
      "   t           g",
      "   t          Tg",
      "   t           g"
    ],
    [
      "vvvvvvvvvvvvvvvv",
      "aaaaaaaaaaaaaaaa",
      "aaaUUUUUUUUUUUUa",
      "aaaUUUUUUUUUUUUa",
      "aaaUUUUUUUUUUUUa",
      "gggUUUUUUUUUUUUa",
      "  SUUUUUUUUUUUUa",
      "  jjjjjjjjjjjjjj",
      "  klgVVVVVgggggg",
      "   @ WWWWW     g",
      "   t WWWWW     g",
      "   t WWWWW     g",
      "   tPWWWWW     g",
      "   tpWWWWW     g",
      "   tpWWWWW     g",
      "   tpWWWWW     g"
    ],
    [
      "vvvvvvvvvvvvvvvv",
      "aaaaaaaaaaaaaaaa",
      "aaaaaaaaaaaaaaaa",
      "aaaaaaaaaaaaaaaa",
      "aaaaaaaaaaaaaaaa",
      "gggaaaaaaaaaaaaa",
      "  Saaaaaaaaaaaaa",
      "  jjjjjjjjjjjjjj",
      "  klgggggggggggg",
      "   @ X    Y    g",
      "   t X  Z Y    g",
      "   t X 010Y    2",
      "   t X3450Y    2",
      "   t   450Y    2",
      "   t  3450Y    2",
      "   t   4!0Y    2"
    ],
    [
      "vvvvvvvvvvvvvvvv",
      "aaaaaaaaaaaaaaaa",
      "aaaaaaaaaaaaaaaa",
      "aaaaaaaaaaaaaaaa",
      "aaaaaaaaaaaaaaaa",
      "gggaaaaaaaaaaaaa",
      "  Saaaaaaaaaaaaa",
      "  jjjjjjjjjjjjjj",
      "  klgggggggggggg",
      "   @           g",
      "   t           g",
      "   t   678     9",
      "   t           9",
      "   t   #E      9",
      "   t   $       9",
      "   t   %       9"
    ]
  ]
}