{
  "name": "multi_hospital_2_ground",
  "refpalette": "deceasedcraft:multi_hospital_2/multi_hospital_2_ground_palette",
  "xsize": 16,
  "zsize": 16,
  "slices": [
    [
      "aaaaaaaaaaaaaaaa",
      "HHHHHHHHHHHHHHHH",
      "HHHHHHHHHHHHHHHH",
      "bbbbbbbbbbbbbbbb",
      "HHHHHHHHHHHHHHHH",
      "HHHHHHHHHHHHHHHH",
      "HHHHHHHHHHHHHHHH",
      "bbbbbbbbbbbbbbbb",
      "aaaaaaaaaabbbbba",
      "cccccccccaccccca",
      "ddddddddeccccccc",
      "ddddddddeccccccc",
      "cccccccceccccccc",
      "ffffffffeggggggg",
      "ggggcccceggggggg",
      "ggggccccgggggggg"
    ],
    [
      "                ",
      "hi  hij hi  hi  ",
      "kl  kl  klm kl  ",
      "                ",
      "                ",
      "                ",
      "                ",
      "                ",
      "nnnnnnnnno     o",
      "ppppppppqn     n",
      "        er     s",
      "tttttttteuw   wu",
      "xxxxxxxxey     y",
      "ffffffffer     s",
      "   ABBBBe       ",
      "C  A DEA     FIJ"
    ],
    [
      "                ",
      "                ",
      "                ",
      "                ",
      "                ",
      "                ",
      "                ",
      "                ",
      "                ",
      "                ",
      "        eK     K",
      "        euw   wu",
      "LAMAN   ey     y",
      "ffffffffeK     K",
      "   ABBOBe       ",
      "   A P A        "
    ],
    [
      "                ",
      "                ",
      "                ",
      "                ",
      "                ",
      "                ",
      "                ",
      "                ",
      "                ",
      "                ",
      "        eQ     Q",
      "        euw   wu",
      "NANAA   ey     y",
      "ffffffffeQ     Q",
      "   ABBBBe       ",
      "   A  RA        "
    ],
    [
      "                ",
      "                ",
      "                ",
      "                ",
      "                ",
      "                ",
      "                ",
      "                ",
      "                ",
      "                ",
      "        e       ",
      "        euwwwwwu",
      "  S   S ey     y",
      "ffffffffe       ",
      "   ABBBBe       ",
      "   A  TA  UU  U "
    ],
    [
      "                ",
      "                ",
      "                ",
      "                ",
      "                ",
      "                ",
      "        VVVVVVVV",
      "        VVVVVVVV",
      "        VVVVVVVV",
      "        VVVVVVVV",
      "        eVVVVVVV",
      "WWWWWWWWeXXXXXXX",
      "YYYYYYYYeyyyyyyy",
      "ZZZZ0ZZZeZZZZZZZ",
      "ZZZZ1ZZZeZZZZZZZ",
      "ZZZZ1ZZZZZ22Z22Z"
    ]
  ]
}