{
  "name": "multi_militarybase_0_ground",
  "refpalette": "deceasedcraft:multi_militarybase_0/multi_militarybase_0_ground_palette",
  "xsize": 16,
  "zsize": 16,
  "slices": [
    [
      "zzzzzzzzzzzzzzzz",
      "zaaaaaaaaaaaaaaa",
      "zabzzbzbbzbzzzzz",
      "zazzzzbbbbzbbbbb",
      "zazbzzzbcccccccc",
      "zazzzzbbcddddddd",
      "zazzzzbzcedddddd",
      "zazzzzzbc dddddd",
      "zazzbzzbc dddddd",
      "zabbzzbbc dddccc",
      "zazzzzzfcddddccc",
      "zazbzzbzcddddccc",
      "zazzzzzbcddddccc",
      "gabzzbhbcccccccc",
      "ijbbbkzbbbbkbbbb",
      "ijbbbbbbbbbbbbbb"
    ],
    [
      "                ",
      " aaaaaaaaaaaaaaa",
      " al m m lm m m m",
      " a  m   n       ",
      " am  op qqqqqqqq",
      " a   m  q   r  s",
      " a mm   q     ot",
      " a m m  q uw    ",
      " a    m q    xy ",
      " alA m  q  t qq ",
      " am B m q    qC ",
      " am DE  qFIJKqL ",
      " a   M  qNNNNq  ",
      "Oa      qqqqqq  ",
      "PQtwR  rST      ",
      "  O UoT V  W    "
    ],
    [
      "                ",
      " aaaaaaaaaaaaaaa",
      " al     l       ",
      " a      n       ",
      " a      XYYYYXXX",
      " a      X       ",
      " a      Y       ",
      " a      Y       ",
      " a      X    x  ",
      " alA    X    XX ",
      " a      Y    X  ",
      " a      Y    Y  ",
      " a      XZ01 X  ",
      " a      XXYYXX  ",
      " O              ",
      "                "
    ],
    [
      "                ",
      " aaaaaaaaaaaaaaa",
      " al     l       ",
      " a      n2222   ",
      " a      XXXXXXXX",
      " a     2X       ",
      " a     2X       ",
      " a     2X       ",
      " a     2X    x  ",
      " alA   2X    XXX",
      " a     2X    X  ",
      " a     2X    Y  ",
      " a     2X    X  ",
      " a      XXYYXX  ",
      "                ",
      "                "
    ],
    [
      "                ",
      " aaaaaaaaaaaaaaa",
      " al     l       ",
      " a      n       ",
      " a      X3333XXX",
      " a      X44444  ",
      " a      34      ",
      " a      34      ",
      " a      X4   x44",
      " alA    X4   XX3",
      " a      34   X  ",
      " a      34   X  ",
      " a      X4   X  ",
      " a      XXXXXX  ",
      "                ",
      "                "
    ],
    [
      "                ",
      " 556666676666666",
      " 589999989999999",
      " O9     n       ",
      " O9     qqqqqqqq",
      " O9     q#####  ",
      " O9     q#######",
      " O9     q#######",
      " $9     q####x##",
      "%^8A    q####qqq",
      " O9     q####q  ",
      " O      q####q  ",
      " O      q####q  ",
      " O      q####q  ",
      "        q&&&&q  ",
      "        q&&&&q  "
    ]
  ]
}