{
  "name": "multi_militarybase_0_base3",
  "refpalette": "deceasedcraft:multi_militarybase_0/multi_militarybase_0_base3_palette",
  "xsize": 16,
  "zsize": 16,
  "slices": [
    [
      "vvvvvvvvvvvvvvvv",
      "vaaaavaaavaaav  ",
      "vaaaabaaabaaab  ",
      "vaaaabaaabaaab  ",
      "vaaaabaaabaaab  ",
      "vvbbbvbbbvbbbv  ",
      "vaaaaaaacbdddb  ",
      "vaaaaaaaabdddb  ",
      "vaaaaaaaebdddb  ",
      "vaccafaaebddgv  ",
      "vacaaaaafbdddb  ",
      "vaaaaaaaabdddb  ",
      "vaaaaaaccbdddb  ",
      "vvaaaaaacbbbbvh ",
      "vaaaaaaaabdddbi ",
      "vaaaaaaaabdddbj "
    ],
    [
      "vvvvvvvvvvvvvvvv",
      "vk klvmmmvnonv  ",
      "vpq  r s r   t  ",
      "vpq      u   t  ",
      "vpq      r   t  ",
      "vvwwwvwwwv   v  ",
      "vx           t  ",
      "v  yyy       t  ",
      "vx AAA       t  ",
      "vB          Cv  ",
      "vB  DEF    I t  ",
      "vB xJKLs     t  ",
      "vB  JKL      t  ",
      "vv xJKLs     v  ",
      "vM  JKL      t  ",
      "vM xJKLs     t  "
    ],
    [
      "vvvvvvvvvvvvvvvv",
      "vN  kvOPQvnonv  ",
      "vR   r   r   S  ",
      "v        T   U  ",
      "vR       r   U  ",
      "vvwwwvwwwv   v  ",
      "v            h  ",
      "v            U  ",
      "v            U  ",
      "v           Cv  ",
      "vV   WX      U  ",
      "v   Y        h  ",
      "vZ    0         ",
      "vv    Y      1  ",
      "v2              ",
      "v3    X         "
    ],
    [
      "vvvvvvvvvvvvvvvv",
      "v    v   vnonv  ",
      "v    r   r   S  ",
      "v        r      ",
      "v        r      ",
      "vvwwwvwwwv   v  ",
      "v               ",
      "v               ",
      "v               ",
      "v           Cv  ",
      "v               ",
      "v               ",
      "v               ",
      "vv              ",
      "v               ",
      "v               "
    ],
    [
      "vvvvvvvvvvvvvvvv",
      "v    v   v   v  ",
      "v    r   r   w  ",
      "v    r   r   w  ",
      "v    r   r   w  ",
      "vvwwwvwwwvtttv  ",
      "v        t   w  ",
      "v        t   w  ",
      "v        t   w  ",
      "v        t  Cv  ",
      "v        t   w  ",
      "v        t   w  ",
      "v        t   w  ",
      "vv       t   vww",
      "v        t   w  ",
      "v        t   w  "
    ],
    [
      "vvvvvvvvvvvvvvvv",
      "v4444v444v444v44",
      "v4555b555b555b55",
      "v4555b555b555b56",
      "v4555b555b555b55",
      "vvbbbvbbbvbbbv55",
      "v45555555b555b55",
      "v45555555b555b56",
      "v45555555b555b55",
      "v45555555b55Cv55",
      "v45555555b555b55",
      "v45555555b555b56",
      "v45555555b555b55",
      "vv5555555b555v77",
      "v45555555b5557  ",
      "v45555555b5557  "
    ]
  ]
}