{
  "name": "multi_militarybase_0_base2",
  "refpalette": "deceasedcraft:multi_militarybase_0/multi_militarybase_0_base2_palette",
  "xsize": 16,
  "zsize": 16,
  "slices": [
    [
      "vvvvvvvvvvvvvvvv",
      "vaaaavaaaaaaavaa",
      "vaaaabaaaaaaabaa",
      "vaaaabaaaaaaabaa",
      "vaaaabaaaaaaabaa",
      "vvbbbvbbbbbbbvbb",
      "vaaaabaacaaaabaa",
      "vaaaabaaaaaaabaa",
      "vaaaabaaaaaaabaa",
      "vaaaabaaaaacdvee",
      "vaaaabaaaaaffbff",
      "vaaaabaaaafffbff",
      "vaaaabacaafffbff",
      "vvbbbvbbbbbbbvbb",
      "vaaaaaaaaafffb  ",
      "vaaaacaaaafffb  "
    ],
    [
      "vvvvvvvvvvvvvvvv",
      "vghghvij k  iv!i",
      "vl mjno    jon o",
      "vl p q rp   sn s",
      "vg t nu    wxnyA",
      "vvnBnvCCCDCCCvCC",
      "vEFI J          ",
      "v    JA         ",
      "vEFI JK LA  MN g",
      "v    O  P  QRvCS",
      "vEFI J TUP  Q V ",
      "v    JPWX u   Y ",
      "vEFI J  k       ",
      "vvnnnv       vZZ",
      "v0100   P23  Z  ",
      "v4    P5   6 Z  "
    ],
    [
      "vvvvvvvvvvvvvvvv",
      "v!   v      iv i",
      "v    n      on o",
      "v    7      sn s",
      "v8   n 9     n  ",
      "vvn#nvCCC$CCCvCC",
      "vEFI J          ",
      "v    J          ",
      "vEFI J          ",
      "v    %      RvCS",
      "vEFI J  ^       ",
      "v    J  4       ",
      "vEFI J          ",
      "vvnnnv       v  ",
      "v0!10           ",
      "v               "
    ],
    [
      "vvvvvvvvvvvvvvvv",
      "v    v       v  ",
      "v    n       n  ",
      "v    n       n  ",
      "v    n       n  ",
      "vvnnnvCCCCCCCvCC",
      "v    J          ",
      "v    J          ",
      "v    J          ",
      "v    J      RvCC",
      "v    J          ",
      "v    J          ",
      "v    J          ",
      "vvnnnv       v  ",
      "v&000           ",
      "v               "
    ],
    [
      "vvvvvvvvvvvvvvvv",
      "v    v       v  ",
      "v    n       n  ",
      "v    n       n  ",
      "v    n       n  ",
      "vvnnnvZZZZZZZvCC",
      "v    Z       Z  ",
      "v    Z       Z  ",
      "v    Z       Z  ",
      "v    Z      RvZZ",
      "v    Z          ",
      "v    Z          ",
      "v    Z          ",
      "vvnnnv       v**",
      "v            *  ",
      "v            *  "
    ],
    [
      "vvvvvvvvvvvvvvvv",
      "v((((v(((((((v((",
      "v()))b)))))))b))",
      "v()))b)))))))b))",
      "v()))b)))))))b))",
      "vvbbbvbbbbbbbvbb",
      "v()))b)))))))b))",
      "v()))b)))))))b))",
      "v()))b)))))))b))",
      "v()))b))))))Rv))",
      "v()))b)))))))b))",
      "v()))b)))))))b))",
      "v()))b)))))))b))",
      "vvbbbvbbbbbbbv++",
      "v()))))))))))+  ",
      "v()))))))))))+  "
    ]
  ]
}