{
  "name": "multi_militarybase_0_base4",
  "refpalette": "deceasedcraft:multi_militarybase_0/multi_militarybase_0_base4_palette",
  "xsize": 16,
  "zsize": 16,
  "slices": [
    [
      "vvvvvvvvvvvvvvvv",
      "vaaaavaaaaaaavaa",
      "vaaaabaaaaaaabaa",
      "vaaaabaaaaaaabaa",
      "vaaaabaaaaaaabaa",
      "vvbbbvbbbbbbbvbb",
      "vaaaabaaaaaaabaa",
      "vaaaabaaaaaaabaa",
      "vaaaabaaaaaaabaa",
      "vaaaabaaaaaaavaa",
      "vaaaabaaaaaaabaa",
      "vaaaabaaaaaaabaa",
      "vaaaabaaaaaaabaa",
      "vvbbbbbbbbbbbvbb",
      "vccccccccccccbdd",
      "vccccccccccccbdd"
    ],
    [
      "vvvvvvvvvvvvvvvv",
      "veeffvgggggggvhh",
      "veff ijklmkjknhh",
      "vo           nhh",
      "vop qi      rnhh",
      "vvsssvt    uwvhh",
      "v!xuyA     BCnhh",
      "vgDB        qnhh",
      "vgE     FIF  nJJ",
      "vgk   KqLtM Nv O",
      "vgP     FQF  n  ",
      "vgR          S  ",
      "vgE         Tn  ",
      "vv          Tvhh",
      "vUV           kW",
      "v XY            "
    ],
    [
      "vvvvvvvvvvvvvvvv",
      "vof  vZ0Zk1m2v33",
      "vo   i       n  ",
      "v            n  ",
      "v    i       n44",
      "vvsssv       vhh",
      "v5           nhh",
      "vk           nhh",
      "vE      6    n  ",
      "v7      8   Nv  ",
      "vE           n  ",
      "v9           S  ",
      "vk           n  ",
      "vv           vhh",
      "v               ",
      "v#$             "
    ],
    [
      "vvvvvvvvvvvvvvvv",
      "v    v       v %",
      "v    i       n  ",
      "v    i       n  ",
      "v    i       n  ",
      "vvsssv       v  ",
      "v            n  ",
      "v            n44",
      "v            nhh",
      "v           Nvhh",
      "v            n^^",
      "v            n  ",
      "v            n&&",
      "vv           vhh",
      "v               ",
      "v               "
    ],
    [
      "vvvvvvvvvvvvvvvv",
      "v    v       v  ",
      "v    i       n  ",
      "v    i       n  ",
      "v    i       n  ",
      "vvsssv*******v  ",
      "v    *       n  ",
      "v    *       n  ",
      "v    *       n  ",
      "v    *      Nv  ",
      "v    *       n44",
      "v    *       nhh",
      "v    *       nhh",
      "vv***********vhh",
      "v               ",
      "v               "
    ],
    [
      "vvvvvvvvvvvvvvvv",
      "v((((v(((((((v  ",
      "v((((b((((((()  ",
      "v((((b((((((()  ",
      "v((((b((((((()  ",
      "vvbbbvbbbbbbbv  ",
      "v((((b((((((()  ",
      "v((((b((((((()  ",
      "v((((b((((((()  ",
      "v((((b((((((Nv  ",
      "v((((b((((((()+ ",
      "v((((b((((((()+ ",
      "v((((b((((((()+ ",
      "vvbbbbbbbbbbbv44",
      "v(((((((((((()^^",
      "v(((((((((((()--"
    ]
  ]
}