{
  "name": "multi_militarybase_0_base1",
  "refpalette": "deceasedcraft:multi_militarybase_0/multi_militarybase_0_base1_palette",
  "xsize": 16,
  "zsize": 16,
  "slices": [
    [
      "vvvvvvvvvvvvvvvv",
      "vaaaavaaaaaaavaa",
      "vaaaabaaaaaaabaa",
      "vaaaabaaaaaaabaa",
      "vaaaabaaaaaaabaa",
      "vvbbbvbbbbbbbvbb",
      "vaaaabaaaaaaabaa",
      "vaaaabaaaaaaabaa",
      "vaaaabaaaaaaabaa",
      "vaaaabaaaaaacvdd",
      "vaaaabaaaaaeebee",
      "vaaaabafaaeeebee",
      "vaaaabaagaeeebee",
      "vvbbbvbbbbbbbvbb",
      "vaaaaaaaaaeeeb  ",
      "vaaaaaaaaaeeeb  "
    ],
    [
      "vvvvvvvvvvvvvvvv",
      "vhhiivj j j jv  ",
      "vhiiklm m m mlno",
      "vhi   p p p pln ",
      "viq il       lno",
      "vvlllvrrrsrrrv  ",
      "v! tuw xy    lno",
      "v A yw B C DElnF",
      "vIJy w      Klno",
      "v A Bw  BL  cv  ",
      "vM y w  N y K   ",
      "v A  w   O P    ",
      "vQ   w      D   ",
      "vvl  v     RSvTT",
      "vU y         T  ",
      "vUJ  B   V   T  "
    ],
    [
      "vvvvvvvvvvvvvvvv",
      "viiqqvj j j jv  ",
      "vqq  lm m m mlWF",
      "vX    p p p plY ",
      "vqk  l       ln!",
      "vvlllvrrrZrrrv  ",
      "v    w       lYo",
      "v    w       ln ",
      "v    w       lno",
      "v    w   L   v  ",
      "v0   w   O      ",
      "v    w          ",
      "v    w          ",
      "vvl  v       v  ",
      "vU              ",
      "vU              "
    ],
    [
      "vvvvvvvvvvvvvvvv",
      "vqqkkv       v  ",
      "vqk  l       l  ",
      "v    l       l  ",
      "vk   l       lY ",
      "vvlllvrrrrrrrv  ",
      "v    w       l  ",
      "v    w       lW ",
      "v    w   1   lYF",
      "v    w   O   v  ",
      "v    w          ",
      "v    w          ",
      "v    w          ",
      "vvl  v       v  ",
      "vU              ",
      "v2              "
    ],
    [
      "vvvvvvvvvvvvvvvv",
      "vk  kv       v  ",
      "v    l       l  ",
      "v    l       l  ",
      "vk   l       l  ",
      "vvlllvTTTTTTTv  ",
      "v    T       l  ",
      "v    T       l  ",
      "v    T   O   l  ",
      "v    T       v  ",
      "v    T          ",
      "v    T          ",
      "v    T          ",
      "vvlllv       vww",
      "v            w  ",
      "v            w  "
    ],
    [
      "vvvvvvvvvvvvvvvv",
      "v3333v3333333v33",
      "v3444b4444444b44",
      "v3444b4444444b44",
      "v3444b4444444b44",
      "vvbbbvbbbbbbbvbb",
      "v3444b444 444b44",
      "v3444b444O 44b44",
      "v3444b444  44b44",
      "v3444b444 444v44",
      "v3444b444 444b44",
      "v3444b4444444b44",
      "v3444b4444444b44",
      "vvbbbvbbbbbbbvbb",
      "v344444444444b55",
      "v344444444444b55"
    ]
  ]
}