{
  "name": "multi_sunkenmonumentpark_6_base1",
  "refpalette": "deceasedcraft:multi_sunkenmonumentpark_6/multi_sunkenmonumentpark_6_base1_palette",
  "xsize": 16,
  "zsize": 16,
  "slices": [
    [
      "aaaaaaaabbbbbbbb",
      "aaaaaaaabbbbbbbb",
      "aaaaaaaabbbbbbbb",
      "aaaaaaaaabbbbbbb",
      "aaaaaaaaabbbbbbb",
      "aaaaaaaaaabbbbbb",
      "aaaaaaaaaaabbbbb",
      "aaaaaaaaaaaaabbb",
      "aaaaaaaaaaaaaaaa",
      "aaaaaaaaaaaaaaaa",
      "aaaaaaaaaaaaaaaa",
      "aaaaaaaaaaaaaaaa",
      "aaaaaaaaaaaaaaaa",
      "aaaaaaaaaaaaaaaa",
      "aaaaaaaaaaaaaaaa",
      "aaaaaaaaaaaaaaaa"
    ],
    [
      "bcccccc=ddeeeeee",
      "bcccccc=ddeeeeee",
      "bcfcccc=dddeeeee",
      "bccccccc=ddeeeee",
      "abcccccc=dddeeee",
      "abccccccc=ddddee",
      "abcccccccc=ddddd",
      "aabcfcccccc==ddd",
      "aabcccccccccc===",
      "aaabcccccccccccc",
      "aaaabccccccccccc",
      "aaaaabccfccccccc",
      "aaaaaabccccccccc",
      "aaaaaaabbccccfcc",
      "aaaaaaaaabbbcccc",
      "aaaaaaaaaaaabbbb"
    ],
    [
      "gh     i  eeeeee",
      "gh     i  eeeeee",
      "j k    i   eeeee",
      "j       i  eeeee",
      "lj m    i   eeee",
      "lj n     i    ee",
      "lj        i     ",
      "llj o      ii   ",
      "llj          iii",
      "lllj            ",
      "llllj           ",
      "lllllj  o       ",
      "llllllj   pq    ",
      "llllllljj    o  ",
      "llllllllljjj  hh",
      "allllllllllljjrr"
    ],
    [
      "          eeeeee",
      "          eeeeee",
      "  s        eeeee",
      "           eeeee",
      "            eeee",
      "              ee",
      "                ",
      "    s           ",
      "                ",
      "                ",
      "t               ",
      "  t     s       ",
      " u              ",
      "j  u t       s  ",
      "j w  u          ",
      "ljj t           "
    ],
    [
      "          xxyyyy",
      "          xxyyyy",
      "  A        xxyyy",
      "           xxxyy",
      "            xxxx",
      "              xx",
      "                ",
      "    A           ",
      "                ",
      "                ",
      "s               ",
      "  s     A       ",
      "                ",
      "     s       A  ",
      "  B             ",
      "    s           "
    ],
    [
      "                ",
      "           C b  ",
      "  A           D ",
      "            E FI",
      "              E ",
      "                ",
      "                ",
      "    A           ",
      "                ",
      "                ",
      "A               ",
      "  A     A       ",
      "                ",
      "     A       A  ",
      "  s             ",
      "    A           "
    ]
  ]
}