{
  "name": "multi_sunkenmonumentpark_6_ground",
  "refpalette": "deceasedcraft:multi_sunkenmonumentpark_6/multi_sunkenmonumentpark_6_ground_palette",
  "xsize": 16,
  "zsize": 16,
  "slices": [
    [
      "                ",
      "           a b  ",
      "              cd",
      "              dd",
      "                ",
      "                ",
      "                ",
      "                ",
      "                ",
      "                ",
      "e               ",
      "  e             ",
      "                ",
      "     e          ",
      "  e             ",
      "    e           "
    ],
    [
      "ff           ghh",
      "ff         i jgg",
      "ffk           cd",
      "ff            dd",
      "fff             ",
      "fff             ",
      "ffff            ",
      "ffffk           ",
      "fffff           ",
      "  ffff          ",
      "e  ffff         ",
      "  l ffffk       ",
      "     fffff      ",
      "      ffffff k  ",
      "  e    fffffffff",
      "    l  fffffffff"
    ],
    [
      "mmn          jcc",
      "mmn        i jco",
      "mmn          pc ",
      "mmn           dd",
      "mmmn            ",
      "mmmn            ",
      "mmmmn           ",
      "mmmmn           ",
      "nnmmmn          ",
      "  nmmmn         ",
      "   nmmmn        ",
      "    nmmmnn      ",
      "     nmmmmnn    ",
      "      nmmmmmnnnn",
      "  l    nmmmmmmmm",
      "       nmmmmmmmm"
    ],
    [
      "  q          rsc",
      "  q        i rto",
      "  q          utt",
      "  q             ",
      "   w            ",
      "   q            ",
      "    w           ",
      "    q           ",
      "xy   w          ",
      "  x   w         ",
      "   x   w        ",
      "    x   Aw      ",
      "     x    Aw    ",
      "      x     AAAA",
      "       B        ",
      "       x        "
    ],
    [
      "           C   c",
      "           i    ",
      "                ",
      "                ",
      "                ",
      "                ",
      "                ",
      "                ",
      "                ",
      "                ",
      "                ",
      "                ",
      "                ",
      "                ",
      "                ",
      "                "
    ],
    [
      "          DEd Dc",
      "           i    ",
      "                ",
      "                ",
      "                ",
      "                ",
      "                ",
      "                ",
      "                ",
      "                ",
      "                ",
      "                ",
      "                ",
      "                ",
      "                ",
      "                "
    ]
  ]
}