{
  "name": "multi_sunkenmonumentpark_2_ground",
  "refpalette": "deceasedcraft:multi_sunkenmonumentpark_2/multi_sunkenmonumentpark_2_ground_palette",
  "xsize": 16,
  "zsize": 16,
  "slices": [
    [
      "aaaabc          ",
      "aaaabc          ",
      "dddddeeeefg     ",
      "dddddeeeeeg     ",
      "eeeeeeeeeegg    ",
      "eeehi    efg    ",
      "eehhi           ",
      "eehhi           ",
      "eehhi j  k      ",
      "eehhil       k  ",
      "eehhi j         ",
      "eehhi           ",
      "eehhi   k   m   ",
      "eehhijj  k      ",
      "eehhi           ",
      "eehhi j  k   m  "
    ],
    [
      "              gg",
      "              gg",
      "     nnndddeeegg",
      "     nnndddeeegg",
      "   oooeeeddeeeeg",
      "         eeeeeeg",
      "            eeeg",
      "  j            g",
      "         m      ",
      "     k       m  ",
      "   j            ",
      " j              ",
      "   l    m   m   ",
      "         m      ",
      "                ",
      "         m   m  "
    ],
    [
      "              ed",
      "              ed",
      "           nnndd",
      "           nnndd",
      "      ooo  nnndd",
      "         poonndd",
      "            eeed",
      "               e",
      "         m      ",
      "     m       m  ",
      "                ",
      "                ",
      "   k    m   q   ",
      "         m      ",
      "                ",
      "         m   q  "
    ],
    [
      "             rs ",
      "             r  ",
      "                ",
      "                ",
      "                ",
      "                ",
      "            poo ",
      "               p",
      "         m      ",
      "     m       q  ",
      "                ",
      "                ",
      "   m    q       ",
      "         m      ",
      "                ",
      "         q      "
    ],
    [
      "                ",
      "                ",
      "                ",
      "                ",
      "                ",
      "                ",
      "                ",
      "                ",
      "         q      ",
      "                ",
      "                ",
      "                ",
      "   m            ",
      "         q      ",
      "                ",
      "                "
    ],
    [
      "                ",
      "                ",
      "                ",
      "                ",
      "                ",
      "                ",
      "                ",
      "                ",
      "                ",
      "                ",
      "                ",
      "                ",
      "   q            ",
      "                ",
      "                ",
      "                "
    ]
  ]
}