{
  "name": "multi_sunkenmonumentpark_2_base1",
  "refpalette": "deceasedcraft:multi_sunkenmonumentpark_2/multi_sunkenmonumentpark_2_base1_palette",
  "xsize": 16,
  "zsize": 16,
  "slices": [
    [
      "vaaaaaaaaaaaaaaa",
      "vaaaaaaaaaaaaaaa",
      "vaaaaaaaaaaaaaaa",
      "vaaaaaaaaaaaaaaa",
      "vaaaaaaaaaaaaaaa",
      "vaaaaaaaaaaaaaaa",
      "vaaaaaaaaaaaaaaa",
      "vaaaaaaaaaaaaaaa",
      "vaaaaaaaaaaaaaaa",
      "vaaaaaaaaaaaaaaa",
      "vaaaaaaaaaaaaaaa",
      "vaaaaaaaaaaaaaaa",
      "vaaaaaaaaaaaaaaa",
      "vaaaaaaaaaaaaaaa",
      "vaaaaaaaaaaaaaaa",
      "vaaaaaaaaaaaaaaa"
    ],
    [
      "vaaaaaaaaaaaaaaa",
      "vaaaaaaaaaaaaaaa",
      "vaaaaaaaaaaaaaaa",
      "vaaaaaaaaaaaaaaa",
      "vaaaaaaaaaaaaaaa",
      "vaaaaaaaaaaaaaaa",
      "vaaaaaaaaaaaaaaa",
      "vaaaaaaaaaaaaaaa",
      "vaaaaaaaaaaaaaaa",
      "vaaaaaaaaaaaaaaa",
      "vaaaaaaaaaaaaaaa",
      "vaaaaaaaaaaaaaaa",
      "vaaaaaaaaaaaaaaa",
      "vaaaaaaaaaaaaaaa",
      "vaaaaaaaaaaaaaaa",
      "vaaaaaaaaaaaaaaa"
    ],
    [
      "vaaaaaaaaaaaabbb",
      "vaaaaaaaaaaaabbb",
      "vaaaaaaaaaaaaccc",
      "vaaaaaaaaaaaaccc",
      "vaaaaaaaaaaaaccc",
      "vaaaaaaaaaaaaccc",
      "vaaaaaaaaaaaaccc",
      "vaaaaaaaaaaaaccc",
      "vaaaaaaaaaaaaccc",
      "vaaaaaaaaaaaaacc",
      "vaaaaaaaaaaaaacc",
      "vaaaaaaaaaaaaacc",
      "vaaaaaaaaaaaaaac",
      "vaaaaaaaaaaaaaaa",
      "vaaaaaaaaaaaaaaa",
      "vaaaaaaaaaaaaaaa"
    ],
    [
      "vdddddaaaabbbef ",
      "vdddddaaaabbbef ",
      "vdddddaaaacccg  ",
      "vdddddaaaacccg  ",
      "vdddddaaaacccg  ",
      "vaaaaaaaaacccg  ",
      "vaaaaaaaaacccg h",
      "vaaaaaaaaacccg  ",
      "vaaaaaaaaacccg h",
      "vaaaaaaaaaccccgh",
      "vaaaaaaaaaccccg ",
      "vaaaaaaaaaccccg ",
      "vaaaaaaaaacccccg",
      "vaaaaaaaaacccccc",
      "vaaaaaaaaaaccccc",
      "vaaaaaaaaaaccccc"
    ],
    [
      "vddddddbbbef    ",
      "vddddddbbbef    ",
      "vddddddcccg     ",
      "vddddddcccg     ",
      "vddddddcccg     ",
      "vaaaaaacccg     ",
      "vaaaaaacccg     ",
      "vaaaaaacccgh    ",
      "vaaaaaacccg     ",
      "vaaaaaacccg  i  ",
      "vaaaaaacccg     ",
      "vaaaaaacccg h   ",
      "vaaaaaacccg j   ",
      "vaaaaaacccg     ",
      "vaaaaaaccccg  h ",
      "vaaaaaaccccg j h"
    ],
    [
      "vdddbbbef       ",
      "vdddbbbef       ",
      "vddddddd        ",
      "vdddddddk       ",
      "vdddddddl       ",
      "vaaacccg        ",
      "vaaacccg        ",
      "vaaacccg h      ",
      "vaaacccg j      ",
      "vaaacccg     m  ",
      "vaaacccg        ",
      "vaaacccg h      ",
      "vaaacccgj   n   ",
      "vaaacccg j      ",
      "vaaacccg        ",
      "vaaacccg j   n  "
    ]
  ]
}