{
  "name": "multi_oasiscondo_11_floor9",
  "refpalette": "deceasedcraft:multi_oasiscondo_11/multi_oasiscondo_11_floor9_palette",
  "xsize": 16,
  "zsize": 16,
  "slices": [
    [
      "aaaaaaaaaaabbcdd",
      "eeeeeeeeeeeeecff",
      "geeeeeeeggggecff",
      "geeeeeeeggggecff",
      "geeeeeeeggggecff",
      "geeeceeeggggecff",
      "eeeeeeeeeeeeh he",
      "                ",
      "                ",
      "                ",
      "                ",
      "                ",
      "                ",
      "                ",
      "                ",
      "                "
    ],
    [
      "iijjjjjiijjbbc  ",
      "kl mmm kl   nco ",
      "         pq nco ",
      " rssssst    nco ",
      "            nco ",
      "   ucw   xy Aco ",
      "AAAAAAAAAAAAA BC",
      "              BB",
      "              BD",
      "                ",
      "                ",
      "                ",
      "                ",
      "                ",
      "                ",
      "                "
    ],
    [
      "  jjjjj  jjbbc  ",
      "EF     EF   IcJ ",
      "            KcJ ",
      " LMMMMMN    OcJ ",
      "            PcJ ",
      "    c!      AcJ ",
      "AAAAAAAAAAAAA B ",
      "              BB",
      "              BQ",
      "                ",
      "                ",
      "                ",
      "                ",
      "                ",
      "                ",
      "                "
    ],
    [
      "jjjjjjjjjjjbbc  ",
      "             cJ ",
      "            RcJ ",
      " SMMMMMT    Rc  ",
      "             cJ ",
      "    c       AcJ ",
      "AAAAAAAAAAAAA B ",
      "              BB",
      "              B ",
      "                ",
      "                ",
      "                ",
      "                ",
      "                ",
      "                ",
      "                "
    ],
    [
      "bbbbbbbbbbbbbc  ",
      "            Rc  ",
      "            RcJ ",
      "             c  ",
      "             c  ",
      "    c       AcJ ",
      "AAAAAAAAAAAAA B ",
      "              BB",
      "              B ",
      "                ",
      "                ",
      "                ",
      "                ",
      "                ",
      "                ",
      "                "
    ],
    [
      "bbbbbbbbbbbbbcUU",
      "UUUUUUUUUUUUUcUU",
      "UUUUUUUUUUUUUcUU",
      "UUUUUUUUUUUUUcUU",
      "UUUUUUUUUUUUUcUU",
      "UUUUcUUUUUUUAcUU",
      "AAAAAAAAAAAAA BB",
      "              BB",
      "              BB",
      "                ",
      "                ",
      "                ",
      "                ",
      "                ",
      "                ",
      "                "
    ]
  ]
}