{
  "name": "multi_oasiscondo_11_base3",
  "refpalette": "deceasedcraft:multi_oasiscondo_11/multi_oasiscondo_11_base3_palette",
  "xsize": 16,
  "zsize": 16,
  "slices": [
    [
      "              va",
      "              vb",
      "              v ",
      "              v ",
      "              v ",
      "    c        cvc",
      "              v ",
      "              v ",
      "              v ",
      "              v ",
      "              d ",
      "              d ",
      "              d ",
      "              d ",
      "              d ",
      "vvvvvvvvvvvvvvvv"
    ],
    [
      "              v ",
      "              v ",
      "              v ",
      "              v ",
      "              v ",
      "    c        cvc",
      "              v ",
      "              v ",
      "              v ",
      "              v ",
      "              v ",
      "              v ",
      "              v ",
      "              v ",
      "              v ",
      "vvvvvvvvvvvvvvvv"
    ],
    [
      "              v ",
      "              v ",
      "              v ",
      "              v ",
      "              v ",
      "    c        cvc",
      "              v ",
      "              v ",
      "              v ",
      "              v ",
      "              v ",
      "              v ",
      "              v ",
      "              v ",
      "              v ",
      "vvvvvvvvvvvvvvvv"
    ],
    [
      "              v ",
      "              v ",
      "              v ",
      "              v ",
      "              v ",
      "    c        cvc",
      "              v ",
      "              v ",
      "              v ",
      "              v ",
      "              v ",
      "              v ",
      "              v ",
      "              v ",
      "              v ",
      "vvvvvvvvvvvvvvvv"
    ],
    [
      "              v ",
      "              v ",
      "              v ",
      "              v ",
      "              v ",
      "    c        cvc",
      "              v ",
      "              v ",
      "              v ",
      "              v ",
      "              v ",
      "              v ",
      "              v ",
      "              v ",
      "              v ",
      "vvvvvvvvvvvvvvvv"
    ],
    [
      "eeeefeeeeeeeefvf",
      "eeeefeeeeeeeefvf",
      "eeeefeeeeeeeefvf",
      "eeeefeeeeeeeefvf",
      "eeeefeeeeeeeefvf",
      "ffffgffffffffgfg",
      "eeeefeeeeeeeefvf",
      "eeeefeeeeeeeefvf",
      "eeeefeeeeeeeefvf",
      "eeeefeeeeeeeefvf",
      "eeeefeeeeeeeefvf",
      "eeeefeeeeeeeefvf",
      "eeeefeeeeeeeefvf",
      "eeeefeeeeeeeefvf",
      "eeeefeeeeeeeefvf",
      "vvvvvvvvvvvvvvvv"
    ]
  ]
}