{
  "name": "multi_oasiscondo_11_floor7",
  "refpalette": "deceasedcraft:multi_oasiscondo_11/multi_oasiscondo_11_floor7_palette",
  "xsize": 16,
  "zsize": 16,
  "slices": [
    [
      "aaaabaaaaaaaacad",
      "bbbbbbbbbbbbbcbb",
      "bbbbbbbbbbbbbcbb",
      "bbbbbbbbbbbbbcbb",
      "bbbbbbbbbbbbbcbb",
      "bbbbbbbbbbbbbcbb",
      "bbbbbbbbbbbbe eb",
      "                ",
      "                ",
      "                ",
      "                ",
      "                ",
      "                ",
      "                ",
      "                ",
      "                "
    ],
    [
      "aaaaaaaaaaaaacaf",
      "    g  h i jkcl ",
      "    mmmmmn okcmm",
      "   pq rsrn okct ",
      "aaaan  u nwokcxy",
      "AAB n    nCDEct ",
      "FI gJKLMNnOPa aQ",
      "aRRaRaaRRSTRU Ua",
      "                ",
      "                ",
      "                ",
      "                ",
      "                ",
      "                ",
      "                ",
      "                "
    ],
    [
      "aaaaaaaaaaaaacaV",
      "         W XYcZ ",
      "    mmmmmn  Ycmm",
      "    0 1 2n 3Yc4 ",
      "aaaan    n 56c  ",
      "A  7n    n 89c# ",
      "$   % ^ &n  R R ",
      "****(******T) UR",
      "                ",
      "                ",
      "                ",
      "                ",
      "                ",
      "                ",
      "                ",
      "                "
    ],
    [
      "aaaaaaaaaaaaaca+",
      "        -[  6c] ",
      "    mmmmmn  {cmm",
      "    }    n  Yc  ",
      "aaaan    n  {c  ",
      "g  |n    n  ;c  ",
      ":   '    n ^S a ",
      "****(******T< Ua",
      "                ",
      "                ",
      "                ",
      "                ",
      "                ",
      "                ",
      "                ",
      "                "
    ],
    [
      "aaaaaaaaaaaaacaa",
      "         n  Yc  ",
      "    mmmmmn> Ycmm",
      ">  >n    n  {c  ",
      "aaaan ,  n  Yc ,",
      "....n    n> {c  ",
      "....n    n  S R ",
      "****(******T) )a",
      "                ",
      "                ",
      "                ",
      "                ",
      "                ",
      "                ",
      "                ",
      "                "
    ],
    [
      "aaaaaaaaaaaaacaa",
      "?????????????c??",
      "?????????????c??",
      "?????????????c??",
      "?????????????c??",
      "    ?????????c??",
      "  / ????????R a?",
      "RaaaRRaaRaRR` )a",
      "                ",
      "                ",
      "                ",
      "                ",
      "                ",
      "                ",
      "                ",
      "                "
    ]
  ]
}