{
  "name": "multi_oasiscondo_11_top",
  "refpalette": "deceasedcraft:multi_oasiscondo_11/multi_oasiscondo_11_top_palette",
  "xsize": 16,
  "zsize": 16,
  "slices": [
    [
      "abbbbbaaaaaabcde",
      "ffffbff!ghgffcde",
      "ffffbffffffffcde",
      "ffffbffffffffcde",
      "fffffffffffffcii",
      "ffffcffffffffcff",
      "ffffffffffffj jf",
      "                ",
      "                ",
      "                ",
      "                ",
      "                ",
      "                ",
      "                ",
      "                ",
      "                "
    ],
    [
      "kbbbbblllllmbc n",
      " opqbrstuuw xc n",
      " ypAb       Bc n",
      " CDEb       Bc n",
      "    k       xcii",
      "FIF c JKKKKLMcNN",
      "MMMMMMMMMMMMM ON",
      "              OO",
      "              OO",
      "                ",
      "                ",
      "                ",
      "                ",
      "                ",
      "                ",
      "                "
    ],
    [
      "Pbbbbb  QRS bc n",
      " ToAbU V     c n",
      " WDXb       Yc n",
      "    b       Yc n",
      "    P       Zcii",
      "    c 001112Mc33",
      "MMMMMMMMMMMMM O3",
      "              OO",
      "              O4",
      "                ",
      "                ",
      "                ",
      "                ",
      "                ",
      "                ",
      "                "
    ],
    [
      "5bbbbb666666bc7 ",
      "   8b       9c##",
      "  $ b       9c##",
      "    b       9c  ",
      "    %       9c  ",
      "    c      ^Mc &",
      "MMMMMMMMMMMMM O ",
      "              OO",
      "              OM",
      "                ",
      "                ",
      "                ",
      "                ",
      "                ",
      "                ",
      "                "
    ],
    [
      "bbbbbbbbbbbbbc *",
      "    b       (c )",
      "    b       Rc+-",
      "    b       [c  ",
      "    b       ]c  ",
      "    c       Mc  ",
      "MMMMMMMMMMMMM O ",
      "              OO",
      "              OM",
      "                ",
      "                ",
      "                ",
      "                ",
      "                ",
      "                ",
      "                "
    ],
    [
      "bbbbbbbbbbbbbc  ",
      "{{{{b{{{{{{{{c  ",
      "{{{{b{{{{{{{{c  ",
      "{{{{b{{{{{{{{c  ",
      "{{{{b{{{{{{{{c  ",
      "    c       Mc  ",
      "MMMMMMMMMMMMM O ",
      "              OO",
      "              O ",
      "                ",
      "                ",
      "                ",
      "                ",
      "                ",
      "                ",
      "                "
    ],
    [
      "aaaaaaaaaaabbc  ",
      "fffffffffffffc  ",
      "fffffffffffffc  ",
      "fffffffffffffc  ",
      "fffffffffffffc  ",
      "}}}}c}}}}}}}Mc  ",
      "MMMMMMMMMMMMM O ",
      "              OO",
      "              O ",
      "                ",
      "                ",
      "                ",
      "                ",
      "                ",
      "                ",
      "                "
    ],
    [
      "   |||    |bbc  ",
      "   ;;;       c  ",
      "     : '  '  c  ",
      "< <   >,.>,. c  ",
      "<?</`  \u0370  \u0370  c  ",
      "\u0371?\u0371/c       Mc  ",
      "MMMMMMMMMMMMM O ",
      "              OO",
      "              O ",
      "                ",
      "                ",
      "                ",
      "                ",
      "                ",
      "                ",
      "                "
    ],
    [
      "   |||    |bbc  ",
      "            \u0372c  ",
      "            \u0373c  ",
      "       \u0374  \u0374 \u0373c  ",
      "      \u0375\u0376\u0377\u0375\u0376\u0377\u037ac  ",
      "    c       Mc  ",
      "MMMMMMMMMMMMM O ",
      "              OO",
      "              O ",
      "                ",
      "                ",
      "                ",
      "                ",
      "                ",
      "                ",
      "                "
    ],
    [
      "|||||||||||bbc  ",
      "             c  ",
      "             c  ",
      "             c  ",
      "             c  ",
      "    c       Mc  ",
      "MMMMMMMMMMMMM O ",
      "              OO",
      "              O ",
      "                ",
      "                ",
      "                ",
      "                ",
      "                ",
      "                ",
      "                "
    ],
    [
      "bbbbbbbbbbbbbc  ",
      "             c  ",
      "             c  ",
      "             c  ",
      "             c  ",
      "    c       Mc  ",
      "MMMMMMMMMMMMM O ",
      "              OO",
      "              O ",
      "                ",
      "                ",
      "                ",
      "                ",
      "                ",
      "                ",
      "                "
    ],
    [
      "bbbbbbbbbbbbbc{{",
      "{{{{{{{{{{{{{c{{",
      "{{{{{{{{{{{{{c{{",
      "{{{{{{{{{{{{{c{{",
      "{{{{{{{{{{{{{c{{",
      "{{{{c{{{{{{{Mc{{",
      "MMMMMMMMMMMMM OO",
      "              OO",
      "              OO",
      "                ",
      "                ",
      "                ",
      "                ",
      "                ",
      "                ",
      "                "
    ],
    [
      "bbbbbaaaaaaaaaaa",
      "aaaaaaaaaaaaaaaa",
      "aaaaaaaaaaaaaaaa",
      "aaaaaaaaaaaaaaaa",
      "aaaaaaaaaaaaaaaa",
      "\u037b\u037b\u037b\u037b\u037b\u037b\u037b\u037b\u037b\u037b\u037b\u037b\u037b\u037b\u037b\u037b",
      "ffffffffffffj jf",
      "                ",
      "                ",
      "                ",
      "                ",
      "                ",
      "                ",
      "                ",
      "                ",
      "                "
    ],
    [
      "bbbbb        \u037c\u037d\u037c",
      "    \u037e        \u037e  ",
      "\u037f\u037f\u037f\u037f\u037f\u037f\u037f\u037f\u037f\u037f\u037f\u037f\u037f\u037f\u037f\u037f",
      "    \u0384        \u0384  ",
      "    \u0385        \u0385  ",
      "\u0386\u0386\u0386\u0386\u0386\u0386\u0386\u0386\u0386\u0386\u0386\u0386\u0386\u0386\u0386\u0386",
      "                ",
      "                ",
      "                ",
      "                ",
      "                ",
      "                ",
      "                ",
      "                ",
      "                ",
      "                "
    ],
    [
      "bb\u037fbb           ",
      "  \u037f             ",
      "  \u037f             ",
      "                ",
      "                ",
      "\u0386\u0386\u0386\u0386\u0386\u0386\u0386\u0386\u0386\u0386\u0386\u0386\u0386\u0386\u0386\u0386",
      "                ",
      "                ",
      "                ",
      "                ",
      "                ",
      "                ",
      "                ",
      "                ",
      "                ",
      "                "
    ],
    [
      "bbbbb           ",
      "                ",
      "                ",
      "                ",
      "                ",
      "                ",
      "                ",
      "                ",
      "                ",
      "                ",
      "                ",
      "                ",
      "                ",
      "                ",
      "                ",
      "                "
    ]
  ]
}