{
  "name": "multi_oasiscondo_11_base4",
  "refpalette": "deceasedcraft:multi_oasiscondo_11/multi_oasiscondo_11_base4_palette",
  "xsize": 16,
  "zsize": 16,
  "slices": [
    [
      "aaaaaaaaaaaaaaaa",
      "aaaaaaaaaaaaaaaa",
      "aaaaaaaaaaaaaaaa",
      "aaaaaaaaaaaaaaaa",
      "aaaaaaaaaaaaaaaa",
      "aaaaaaaaaaaaaaaa",
      "aaaaaaaaaaaaaaaa",
      "aaaaaaaaaaaaaaaa",
      "aaaaaaaaaaaaaaaa",
      "aaaaaaaaaaaaaaaa",
      "aaaaaaaaaaaaaaaa",
      "aaaaaaaaaaaaaaaa",
      "aaaaaaaaaaaaaaaa",
      "aaaaaaaaaaaaaaaa",
      "aaaaaaaaaaaaaaaa",
      "vvvvvvvvvvvvvvvv"
    ],
    [
      "aaaaaaaaaaaaaaaa",
      "aaaaaaaaaaaaaaaa",
      "aaaaaaaaaaaaaaaa",
      "aaaaaaaaaaaaaaaa",
      "aaaaaaaaaaaaaaaa",
      "aaaabaaaaaaaabab",
      "aaaaaaaaaaaaaaaa",
      "aaaaaaaaaaaaaaaa",
      "aaaaaaaaaaaaaaaa",
      "aaaaaaaaaaaaaaaa",
      "aaaaaaaaaaaaaaaa",
      "aaaaaaaaaaaaaaaa",
      "aaaaaaaaaaaaaaaa",
      "aaaaaaaaaaaaaaaa",
      "aaaaaaaaaaaaaaaa",
      "vvvvvvvvvvvvvvvv"
    ],
    [
      "cccccHHHHHccccva",
      "HHHHHHHHHHccccva",
      "HHHHHHHHHHccccva",
      "HHHHHHHHHHccccva",
      "HHHHcHHHHHccccva",
      "HHHHbHHHHHcccbvb",
      "HHHHcHHHHHccccva",
      "HHHHcHHHHHccccva",
      "HHHHcHHHHHHcccvd",
      "HHHHcHHHHHHcccvd",
      "HHHHcHHHHHHHcccc",
      "HHHHcHHHHHHHHccc",
      "HHHHHHHHHHHHHHHH",
      "HHHHHHHHHHHHHHHH",
      "HHHHHHHHHHHHHHHH",
      "vvvvvvvvvvvvvvvv"
    ],
    [
      "           ef va",
      "           ef va",
      "           ef va",
      "           ef va",
      "ghghigh    ef va",
      "    b      efbvb",
      "    i      ef vd",
      "jkjkijk    lf vd",
      "ghghigh     m vc",
      "    i       n vo",
      "    i         pp",
      "jkjkijk         ",
      "                ",
      "                ",
      "                ",
      "vvvvvvvvvvvvvvvv"
    ],
    [
      "              va",
      "              va",
      "              vd",
      "              vd",
      "              vd",
      "    b        bvb",
      "              vo",
      "              vp",
      "              v ",
      "              v ",
      "                ",
      "                ",
      "                ",
      "                ",
      "                ",
      "vvvvvvvvvvvvvvvv"
    ],
    [
      "              vd",
      "              vd",
      "              vc",
      "              vo",
      "              vp",
      "    b        bvb",
      "              v ",
      "              v ",
      "              v ",
      "              v ",
      "                ",
      "                ",
      "                ",
      "                ",
      "                ",
      "vvvvvvvvvvvvvvvv"
    ]
  ]
}