{
  "name": "multi_oasiscondo_11_floor8",
  "refpalette": "deceasedcraft:multi_oasiscondo_11/multi_oasiscondo_11_floor8_palette",
  "xsize": 16,
  "zsize": 16,
  "slices": [
    [
      "aaaabaaaaaaaacad",
      "bbbbbbbbbbbbbcbb",
      "bbbbbbbbbbbbbcbb",
      "bbbbbbbbbbbbbcbb",
      "bbbbbbbbbbbbbcbb",
      "bbbbbbbbbbbbbcbb",
      "bbbbbbbbbbbbe eb",
      "                ",
      "                ",
      "                ",
      "                ",
      "                ",
      "                ",
      "                ",
      "                ",
      "                "
    ],
    [
      "aaaaaaaaaaaaacaf",
      " ghh!hhhijkkjcl ",
      " m      n oo cpp",
      " g   q  n   rcs ",
      "aapptuw     xcyA",
      "  BCDEFIiq JKcs ",
      "L  MaN OiPQRS aT",
      "aaaaaaSSaaSaU Va",
      "                ",
      "                ",
      "                ",
      "                ",
      "                ",
      "                ",
      "                ",
      "                "
    ],
    [
      "aaaaaaaaaaaaacaW",
      " ghhhhXhiY  Zc0 ",
      " 1      n    cpp",
      " g2     n    c3 ",
      "aappp45      c  ",
      " 6 7a8 9i  # c  ",
      "$   a   i   a S%",
      "^^^^&^^^^^^SU Ua",
      "                ",
      "                ",
      "                ",
      "                ",
      "                ",
      "                ",
      "                ",
      "                "
    ],
    [
      "aaaaaaaaaaaaaca*",
      " g( )X+(i -[ c] ",
      " {      n    cpp",
      " g      n   }c  ",
      "aappp|;:    'c  ",
      "   <a> ,i    c  ",
      ".   a   i   S a ",
      "^^^^&^^^^^^aV Ua",
      "                ",
      "                ",
      "                ",
      "                ",
      "                ",
      "                ",
      "                ",
      "                "
    ],
    [
      "aaaaaaaaaaaaacaa",
      " g      i    c  ",
      "?g ?  ? i /  cpp",
      " g      i    c  ",
      "aappppppi    c /",
      "```\u0370aO `i ?  c  ",
      "``` a```i   a a ",
      "^^^^&^^^^^^aU Va",
      "                ",
      "                ",
      "                ",
      "                ",
      "                ",
      "                ",
      "                ",
      "                "
    ],
    [
      "aaaaaaaaaaaaacaa",
      "\u0371\u0371\u0371\u0371\u0371\u0371\u0371\u0371\u0371\u0371\u0371\u0371\u0371c\u0371\u0371",
      "\u0371\u0371\u0371\u0371\u0371\u0371\u0371\u0371\u0371\u0371\u0371\u0371\u0371c\u0371\u0371",
      "\u0371\u0371\u0371\u0371\u0371\u0371\u0371\u0371\u0371\u0371\u0371\u0371\u0371c\u0371\u0371",
      "\u0371\u0371\u0371\u0371\u0371\u0371\u0371\u0371\u0371\u0371\u0371\u0371\u0371c\u0371\u0371",
      "   \u0371\u0371!O \u0371\u0371\u0371\u0371\u0371c\u0371\u0371",
      "  \u0372\u0371\u0371\u0371  \u0371\u0371\u0371\u0371a S\u0371",
      "aaaSaSSSaaaaV US",
      "                ",
      "                ",
      "                ",
      "                ",
      "                ",
      "                ",
      "                ",
      "                "
    ]
  ]
}