{
  "name": "multi_oasiscondo_11_floor4",
  "refpalette": "deceasedcraft:multi_oasiscondo_11/multi_oasiscondo_11_floor4_palette",
  "xsize": 16,
  "zsize": 16,
  "slices": [
    [
      "aaaabacaaaaaabac",
      "ddddbddddddddbdd",
      "ddddbddddddddbdd",
      "ddddbddddddddbdd",
      "ddddbddddddddbdd",
      "ddddbddddddddbdd",
      "ddde edddddde ed",
      "                ",
      "                ",
      "                ",
      "                ",
      "                ",
      "                ",
      "                ",
      "                ",
      "                "
    ],
    [
      "aaaabafaaaaaabag",
      " hhhb!ijklam bn ",
      "    boopqrastboo",
      " uwxby   AaBCby ",
      "aaaabDEFIJaKabLM",
      "  NOby  PQRqSby ",
      "T Ca UV   FxU aW",
      "aaaX UUYYYYUU Xa",
      "     UZZZZZZU   ",
      "                ",
      "                ",
      "                ",
      "                ",
      "                ",
      "                ",
      "                "
    ],
    [
      "aaaaba0aaaaaaba1",
      "    bi   2a34b5 ",
      "    boop 6a  boo",
      "   7b8   9aBBb# ",
      "aaaab    $a%ab  ",
      " ^ &b*   2  Sb( ",
      "   a U     )U +-",
      "[[+X UU    UU X+",
      "     U]]]]]]U   ",
      "                ",
      "                ",
      "                ",
      "                ",
      "                ",
      "                ",
      "                "
    ],
    [
      "aaaaba{aaaaaaba{",
      "    b}   |a;:b} ",
      "    boop 'a  boo",
      "    b    <aBBb  ",
      "aaaab     a>ab  ",
      "   ,b       .b  ",
      "?  a U      U a ",
      "[[a/ UU` ` UU /a",
      "     U      U   ",
      "                ",
      "                ",
      "                ",
      "                ",
      "                ",
      "                ",
      "                "
    ],
    [
      "aaaabaaaaaaaabaa",
      "    b    \u0370a\u0371\u0371b  ",
      "  \u0372 boop  a\u0371\u0371boo",
      "    b    \u0373a\u0371\u0371b  ",
      "aaaab  \u0374  aaab \u0374",
      "\u0371\u0371\u0371\u0372b       \u0372b  ",
      "\u0371\u0371\u0371a U      U a ",
      "[[aX UU\u0375\u0375\u0375\u0375UU Xa",
      "     U      U   ",
      "                ",
      "                ",
      "                ",
      "                ",
      "                ",
      "                ",
      "                "
    ],
    [
      "aaaabaaaaaaaabaa",
      "\u0376\u0376\u0376\u0376b\u0376\u0376\u0376\u0376\u0376\u0376 \u0377b\u0376\u0376",
      "\u0376\u0376\u0376\u0376b\u0376\u0376\u0376\u0376\u0376\u0376  b\u0376\u0376",
      "\u0376\u0376\u0376\u0376b\u0376\u0376\u0376\u0376\u0376\u0376  b\u0376\u0376",
      "\u0376\u0376\u0376\u0376b\u0376\u0376\u0376\u0376\u0376\u0376\u0376\u0376b\u0376\u0376",
      "   \u0376b\u0376\u0376\u0376\u0376\u0376\u0376\u0376\u0376b\u0376\u0376",
      "  \u0377+ U\u0376\u0376\u0376\u0376\u0376\u0376U a\u0376",
      "+aaX UUUUUUUU /a",
      "     UUUUUUUU   ",
      "                ",
      "                ",
      "                ",
      "                ",
      "                ",
      "                ",
      "                "
    ]
  ]
}