{
  "name": "multi_oasiscondo_11_floor11",
  "refpalette": "deceasedcraft:multi_oasiscondo_11/multi_oasiscondo_11_floor11_palette",
  "xsize": 16,
  "zsize": 16,
  "slices": [
    [
      "aabbcaaaaaaaaaaa",
      "ddddceeeeeeeeeee",
      "fgddceeeeeeheeee",
      " iddceeeeeeeeeee",
      " iddceeeeeeeeeee",
      "jkddceeeeeeeecee",
      "dddl ldddddddddd",
      "                ",
      "                ",
      "                ",
      "                ",
      "                ",
      "                ",
      "                ",
      "                ",
      "                "
    ],
    [
      "mnbbc           ",
      "   oc           ",
      "   pc  q   r    ",
      "   pc     sts  u",
      "   pc wtw  s  wt",
      "   xc  w     c w",
      "   b yAAAAAAAAAA",
      "BbbC yyAAAAAAAAA",
      "     yDDDDDDDDDD",
      "                ",
      "                ",
      "                ",
      "                ",
      "                ",
      "                ",
      "                "
    ],
    [
      "Enbbc           ",
      "   Fc           ",
      "    c           ",
      "    c           ",
      "   Ic           ",
      "   Jc        c  ",
      "   b y          ",
      "KKbL yy         ",
      "     yMMMMMMMMMM",
      "                ",
      "                ",
      "                ",
      "                ",
      "                ",
      "                ",
      "                "
    ],
    [
      "nnbbc           ",
      "    c           ",
      "    c           ",
      "    c           ",
      "    c           ",
      "    c        c  ",
      "   b y          ",
      "KKbC yy         ",
      "     y          ",
      "                ",
      "                ",
      "                ",
      "                ",
      "                ",
      "                ",
      "                "
    ],
    [
      "bbbbc           ",
      "    c           ",
      "    c           ",
      "    c           ",
      "    c           ",
      "    c        c  ",
      "   b y          ",
      "KKbC yyNNNNNNNNN",
      "     y          ",
      "                ",
      "                ",
      "                ",
      "                ",
      "                ",
      "                ",
      "                "
    ],
    [
      "bbbbcOOOOOOOOOOO",
      "PPPPcOOOOOOOOOOO",
      "PPPPcOOOOOOOOOOO",
      "PPPPcOOOOOOOOOOO",
      "PPPPcOOOOOOOOOOO",
      "PPPPcOOOOOOOOcOO",
      "PPPb yyyyyyyyyyy",
      "BbbC yyyyyyyyyyy",
      "     yyyyyyyyyyy",
      "                ",
      "                ",
      "                ",
      "                ",
      "                ",
      "                ",
      "                "
    ]
  ]
}