{
  "name": "multi_oasiscondo_11_floor10",
  "refpalette": "deceasedcraft:multi_oasiscondo_11/multi_oasiscondo_11_floor10_palette",
  "xsize": 16,
  "zsize": 16,
  "slices": [
    [
      "aaaaaaaaaaaaabcc",
      "dddddddddddddbee",
      "fdfddddffdfddbee",
      "dfffffffdfffdbee",
      "fffddfdddddfdbee",
      "dfddbddfdddddbee",
      "eeeeeeeeeeeeg ge",
      "                ",
      "                ",
      "                ",
      "                ",
      "                ",
      "                ",
      "                ",
      "                ",
      "                "
    ],
    [
      "             bhi",
      " j jjklj m j bn ",
      "   j m     jjbop",
      "             bo ",
      "    l   j k jbop",
      "   mbjl jmj  bq ",
      "rrrrrrrrrrrrs t ",
      "rrrrrrrrrrrss ut",
      "wwwwwwwwwwwws   ",
      "                ",
      "                ",
      "                ",
      "                ",
      "                ",
      "                ",
      "                "
    ],
    [
      "             bhx",
      "   j y       bA ",
      "           j bB ",
      "             bC ",
      "          y  bB ",
      "    b   j    bC ",
      "            s t ",
      "           ss uD",
      "EEEEEEEEEEEEs   ",
      "                ",
      "                ",
      "                ",
      "                ",
      "                ",
      "                ",
      "                "
    ],
    [
      "             bhh",
      "     j       b  ",
      "             b  ",
      "             b  ",
      "          l  b  ",
      "    b        b  ",
      "            s t ",
      "           ss ut",
      "            s   ",
      "                ",
      "                ",
      "                ",
      "                ",
      "                ",
      "                ",
      "                "
    ],
    [
      "             btt",
      "     j       b  ",
      "             b  ",
      "             b  ",
      "             b  ",
      "    b        b  ",
      "            s t ",
      "FFFFFFFFFFFss It",
      "            s   ",
      "                ",
      "                ",
      "                ",
      "                ",
      "                ",
      "                ",
      "                "
    ],
    [
      "JJJJJJJJJJJJJbtt",
      "JJJJJJJJJJJJJbKK",
      "JJJJJJJJJJJJJbKK",
      "JJJJJJJJJJJJJbKK",
      "JJJJJJJJJJJJJbKK",
      "JJJJbJJJJJJJJbKK",
      "sssssssssssss DK",
      "sssssssssssss ut",
      "sssssssssssss   ",
      "                ",
      "                ",
      "                ",
      "                ",
      "                ",
      "                ",
      "                "
    ]
  ]
}