{
  "name": "multi_oasiscondo_11_floor6",
  "refpalette": "deceasedcraft:multi_oasiscondo_11/multi_oasiscondo_11_floor6_palette",
  "xsize": 16,
  "zsize": 16,
  "slices": [
    [
      "aaaabaaaaaaaacad",
      "bbbbbbbbbbbbbcbb",
      "bbbbbbbbbbbbbcbb",
      "bbbbbbbbbbbbbcbb",
      "bbbbbbbbbbbbbcbb",
      "bbbbbbbbbbbbbcbb",
      "bbbbbbbbbbbbe eb",
      "                ",
      "                ",
      "                ",
      "                ",
      "                ",
      "                ",
      "                ",
      "                ",
      "                "
    ],
    [
      "aaaaaaaaaaaaacaf",
      " ggghijjklmmncop",
      "    q    r   cst",
      " uwxh    lsyacA ",
      "aaaah BBClDEFcIJ",
      " KDLh MM lNOFcPQ",
      "R  ShTUUTlVWa XY",
      "aaaXaXXZ0XZX1 1X",
      "                ",
      "                ",
      "                ",
      "                ",
      "                ",
      "                ",
      "                ",
      "                "
    ],
    [
      "aaaaaaaaaaaaaca2",
      "    h 3 4lmm5cp ",
      "    6    7 8 c9 ",
      "    h    ls#ac  ",
      "aaaah    l   c  ",
      "   $h    l   cT ",
      "    h% C!l ^a Z&",
      "****(******X) )a",
      "                ",
      "                ",
      "                ",
      "                ",
      "                ",
      "                ",
      "                ",
      "                "
    ],
    [
      "aaaaaaaaaaaaaca+",
      "    h    l-[ac] ",
      "    {    }  ac9|",
      "    h    ls;ac  ",
      "aaaah    l  :c  ",
      "   'h    l  <c> ",
      ",   h   Cl .a X ",
      "****(******a) ?a",
      "                ",
      "                ",
      "                ",
      "                ",
      "                ",
      "                ",
      "                ",
      "                "
    ],
    [
      "aaaaaaaaaaaaacaa",
      "    h    l//ac  ",
      "  ` h\u0370  \u0371l \u0371acs9",
      "    h    lssac  ",
      "aaaah    l\u0372\u0372\u0372c `",
      "\u0372\u0372\u0372\u0373h\u0370  \u0370l\u0372\u0372\u0372c  ",
      "\u0372\u0372\u0372 h    l \u0370X Z ",
      "****(******a) ?X",
      "                ",
      "                ",
      "                ",
      "                ",
      "                ",
      "                ",
      "                ",
      "                "
    ],
    [
      "aaaaaaaaaaaaacaa",
      "\u0374\u0374\u0374\u0374\u0374\u0374\u0374\u0374\u0374\u0374\u0374\u0374\u0374c\u0374\u0374",
      "\u0374\u0374\u0374\u0374\u0374\u0374\u0374\u0374\u0374\u0374\u0374\u0374\u0374c\u0374\u0374",
      "\u0374\u0374\u0374\u0374\u0374\u0374\u0374\u0374\u0374\u0374\u0374\u0374\u0374c\u0374\u0374",
      "\u0374\u0374\u0374\u0374\u0374\u0374\u0374\u0374\u0374\u0374   c\u0374\u0374",
      "   \u0374\u0374\u0374\u0374\u0374\u0374\u0374  \u0375c\u0374\u0374",
      "  \u0375\u0374\u0374\u0374\u0374\u0374\u0374\u0374\u0374\u0374X X\u0374",
      "aaXaaaXaXaaX? )a",
      "                ",
      "                ",
      "                ",
      "                ",
      "                ",
      "                ",
      "                ",
      "                "
    ]
  ]
}