{
  "name": "multi_oasiscondo_11_base1",
  "refpalette": "deceasedcraft:multi_oasiscondo_11/multi_oasiscondo_11_base1_palette",
  "xsize": 16,
  "zsize": 16,
  "slices": [
    [
      "aaaaaHHHHHHHaaaH",
      "HHHHHHHHHHHHHHHH",
      "HHHHHHHHHHHHHHHH",
      "HHHHHHHHHHHHHHHH",
      "HHHHaHHHHHHHHaHH",
      "HHHHbHHHHHHHHbHH",
      "HHHHaHHHHHHHHaHH",
      "HHHHaHHHHHHHHaHH",
      "HHHHaHHHHHHHHaHH",
      "HHHHaHHHHHHHHaHH",
      "HHHHaHHHHHHHHaHH",
      "HHHHaHHHHHHHHaHH",
      "HHHHHHHHHHHHHHHH",
      "HHHHHHHHHHHHHHHH",
      "HHHHHHHHHHHHHHHH",
      "vvvvvvvvvvvvvvvv"
    ],
    [
      "                ",
      "                ",
      "                ",
      "                ",
      "cdcdecdcdcdcdecd",
      "    b        b  ",
      " f  e        e  ",
      "ghgheghghghghegh",
      "cdcdecdcdcdcdecd",
      "    e    i   e  ",
      "    e        e  ",
      "ghgheghghghghegh",
      "                ",
      "                ",
      "                ",
      "vvvvvvvvvvvvvvvv"
    ],
    [
      "                ",
      "                ",
      "                ",
      "                ",
      "                ",
      "    b        b  ",
      "                ",
      "                ",
      "                ",
      "                ",
      "                ",
      "                ",
      "                ",
      "                ",
      "                ",
      "vvvvvvvvvvvvvvvv"
    ],
    [
      "                ",
      "                ",
      "                ",
      "                ",
      "                ",
      "    b        b  ",
      "                ",
      "                ",
      "                ",
      "                ",
      "                ",
      "                ",
      "                ",
      "                ",
      "                ",
      "vvvvvvvvvvvvvvvv"
    ],
    [
      "                ",
      "                ",
      "                ",
      "                ",
      "                ",
      "    b        b  ",
      "                ",
      "                ",
      "                ",
      "                ",
      "                ",
      "                ",
      "                ",
      "                ",
      "                ",
      "vvvvvvvvvvvvvvvv"
    ],
    [
      "jjjjkjjjjjjjjkjj",
      "jjjjkjjjjjjjjkjj",
      "jjjjkjjjjjjjjkjj",
      "jjjjkjjjjjjjjkjj",
      "jjjjkjjjjjjjjkjj",
      "kkkklkkkkkkkklkk",
      "jjjjkjjjjjjjjkjj",
      "jjjjkjjjjjjjjkjj",
      "jjjjkjjjjjjjjkjj",
      "jjjjkjjjjjjjjkjj",
      "jjjjkjjjjjjjjkjj",
      "jjjjkjjjjjjjjkjj",
      "jjjjkjjjjjjjjkjj",
      "jjjjkjjjjjjjjkjj",
      "jjjjkjjjjjjjjkjj",
      "vvvvvvvvvvvvvvvv"
    ]
  ]
}