{
  "name": "multi_oasiscondo_11_floor3",
  "refpalette": "deceasedcraft:multi_oasiscondo_11/multi_oasiscondo_11_floor3_palette",
  "xsize": 16,
  "zsize": 16,
  "slices": [
    [
      "aaaabacaaaaaabac",
      "ddddbddddddddbdd",
      "ddddbddddddddbdd",
      "ddddbddddddddbdd",
      "ddddbddddddddbdd",
      "ddddbddddddddbdd",
      "ddde edddddde ed",
      "                ",
      "                ",
      "                ",
      "                ",
      "                ",
      "                ",
      "                ",
      "                ",
      "                "
    ],
    [
      "aaaabafaaaaaabaf",
      " ghibj k   lmbj ",
      "   nbo  p qrsbtt",
      " uwxbyA B CDmbo ",
      "aaaabyA EaaaabFI",
      " J Kbo  LM   bo ",
      "NOPa aQREN!Pa aS",
      "TaaU UaaTVVTW Ua",
      "                ",
      "                ",
      "                ",
      "                ",
      "                ",
      "                ",
      "                ",
      "                "
    ],
    [
      "aaaabaXaaaaaabaX",
      "    bY     Z b0 ",
      "    b      1 btt",
      " 23 b      4 b5 ",
      "aaaab   Eaaaab  ",
      "   6b7  899 6b# ",
      "   a a  E M T T$",
      "%%TU UT%%%%T^ UT",
      "                ",
      "                ",
      "                ",
      "                ",
      "                ",
      "                ",
      "                ",
      "                "
    ],
    [
      "aaaaba&aaaaaaba&",
      "    b*     ( b* ",
      "    b      ) btt",
      "    b      + b  ",
      "aaaab   Eaaaab  ",
      "   -b   [   -b  ",
      "]  a a  E]  T V ",
      "%%aU Wa%%%%aW Wa",
      "                ",
      "                ",
      "                ",
      "                ",
      "                ",
      "                ",
      "                ",
      "                "
    ],
    [
      "aaaabaaaaaaaabaa",
      "    b      {}b  ",
      "  | b      {}btt",
      "    b      {}b  ",
      "aaaab ; Eaaaab ;",
      ":::|b   E:::|b  ",
      ":::T T  E:::T T ",
      "%%aW Ua%%%%TU Wa",
      "                ",
      "                ",
      "                ",
      "                ",
      "                ",
      "                ",
      "                ",
      "                "
    ],
    [
      "aaaabaaaaaaaabaa",
      "''''b'''''''<b''",
      "''''b'''''''<b''",
      "''''b'''''''<b''",
      "''''b''''''''b''",
      "   'b''''   'b''",
      "  >T a'''  >a a'",
      "TaaU UaTaaTaU Ua",
      "                ",
      "                ",
      "                ",
      "                ",
      "                ",
      "                ",
      "                ",
      "                "
    ]
  ]
}