{
  "name": "multi_oasiscondo_11_ground",
  "refpalette": "deceasedcraft:multi_oasiscondo_11/multi_oasiscondo_11_ground_palette",
  "xsize": 16,
  "zsize": 16,
  "slices": [
    [
      "aaaaaaaaaaaaabcc",
      "aaaaaaaaaaaaabcc",
      "cccaaaaaaaaaabcc",
      "cccaaaaaaaaaabcc",
      "cccaaaaaaaaaabcc",
      "aaadedaaaaaadedc",
      "dddddddddddddddd",
      "ffffffffffffffff",
      "ggggffffffffffff",
      "gggggffffffffhff",
      "ggggggffffffffff",
      "ggggggffffffffff",
      "ggggggffffffffff",
      "gggggffffffffhff",
      "ggggffffffffffff",
      "ffffffffffffffff"
    ],
    [
      "               i",
      "                ",
      "                ",
      "j               ",
      "    k        k  ",
      "lm nen  op  nen ",
      "nnnnqnnrssrnnqnn",
      "                ",
      "tttt            ",
      "uuuut        w  ",
      "xxxxut       y  ",
      "xxxxut       y  ",
      "xxxxut       y  ",
      "uuuut        w  ",
      "tttt            ",
      "                "
    ],
    [
      "                ",
      "                ",
      "                ",
      "                ",
      "    A        A  ",
      "   nen  BC  nen ",
      "nnnn nnr  rnn nn",
      "                ",
      "                ",
      "             D  ",
      "                ",
      "                ",
      "                ",
      "             D  ",
      "                ",
      "                "
    ],
    [
      "                ",
      "                ",
      "                ",
      "                ",
      "    E        F  ",
      "   nen  II  nen ",
      "nnnn nnrJJrnn nn",
      "                ",
      "                ",
      "             K  ",
      "                ",
      "                ",
      "                ",
      "             K  ",
      "                ",
      "                "
    ],
    [
      "                ",
      "                ",
      "                ",
      "                ",
      "                ",
      "   nen      nen ",
      "nnnn nnrrrrnn nn",
      "                ",
      "                ",
      "             K  ",
      "                ",
      "                ",
      "                ",
      "             K  ",
      "                ",
      "                "
    ],
    [
      "                ",
      "                ",
      "                ",
      "                ",
      "                ",
      "   nen      nen ",
      "nnnn nnnnnnnn nn",
      "                ",
      "                ",
      "             L  ",
      "                ",
      "                ",
      "                ",
      "             L  ",
      "                ",
      "                "
    ]
  ]
}