{
  "name": "multi_oasiscondo_11_floor1",
  "refpalette": "deceasedcraft:multi_oasiscondo_11/multi_oasiscondo_11_floor1_palette",
  "xsize": 16,
  "zsize": 16,
  "slices": [
    [
      "                ",
      "                ",
      "                ",
      "                ",
      "                ",
      "   aba      aba ",
      "aaaa aaaaaaaa aa",
      "                ",
      "                ",
      "                ",
      "                ",
      "                ",
      "                ",
      "                ",
      "                ",
      "                "
    ],
    [
      "                ",
      "       c c      ",
      "                ",
      "      c c  c    ",
      "                ",
      "   aba      aba ",
      "aaaa aaaaaaaa aa",
      "                ",
      "                ",
      "                ",
      "                ",
      "                ",
      "                ",
      "                ",
      "                ",
      "                "
    ],
    [
      "                ",
      "      cdcdc     ",
      "                ",
      "      dcdc d    ",
      "                ",
      "   aba      aba ",
      "aaaa aaaaaaaa aa",
      "                ",
      "                ",
      "                ",
      "                ",
      "                ",
      "                ",
      "                ",
      "                ",
      "                "
    ],
    [
      "                ",
      "      dddddc    ",
      "                ",
      "      ddddcd    ",
      "                ",
      "   aba      aba ",
      "aaaa aaaaaaaa aa",
      "                ",
      "                ",
      "                ",
      "                ",
      "                ",
      "                ",
      "                ",
      "                ",
      "                "
    ],
    [
      "      eeeeee    ",
      "     edddddde   ",
      "     effffffe   ",
      "     edddddde   ",
      "      eeeeee    ",
      "   aba      aba ",
      "aaaa aaaaaaaa aa",
      "                ",
      "                ",
      "                ",
      "                ",
      "                ",
      "                ",
      "                ",
      "                ",
      "                "
    ],
    [
      "gggggggggggggggg",
      "gggggghhhhhhgggg",
      "gggggghhhhhhgggg",
      "gggggghhhhhhgggg",
      "gggggggggggggggg",
      "gggibiggggggibig",
      "iiiiiiiiiiiiiiii",
      "iiiiiiiiiiiiiiii",
      "iiiiiiiiiiiiiiii",
      "                ",
      "                ",
      "                ",
      "                ",
      "                ",
      "                ",
      "                "
    ]
  ]
}