{
  "name": "multi_oasiscondo_11_base2",
  "refpalette": "deceasedcraft:multi_oasiscondo_11/multi_oasiscondo_11_base2_palette",
  "xsize": 16,
  "zsize": 16,
  "slices": [
    [
      "aaaaaHHHHHHHaaaH",
      "HHHHHHHHHHHHHHHH",
      "HHHHHHHHHHHHHHHH",
      "HHHHHHHHHHHHHHHH",
      "HHHHaHHHHHHHHaHH",
      "HHHHbHHHHHHHHbHH",
      "HHHHaHHHHHHHHaHH",
      "HHHHaHHHHHHHHaHH",
      "HHHHaHHHHHHHHaHH",
      "HHHHaHHHHHHHHaHH",
      "HHHHaHHHHHHHHaHH",
      "HHHHaHHHHHHHHaHH",
      "HHHHHHHHHHHHHHHH",
      "HHHHHHHHHHHHHHHH",
      "HHHHHHHHHHHHHHHH",
      "vvvvvvvvvvvvvvvv"
    ],
    [
      "                ",
      "                ",
      "                ",
      "                ",
      "cdcdecdcdcdcdecd",
      "    b        b  ",
      "    e        e  ",
      "fgfgefgfgfgfgefg",
      "cdcdecdcdcdcdecd",
      "    e        e  ",
      "    e        e  ",
      "fgfgefgfgfgfgefg",
      "                ",
      "                ",
      "                ",
      "vvvvvvvvvvvvvvvv"
    ],
    [
      "                ",
      "                ",
      "                ",
      "                ",
      "                ",
      "    b        b  ",
      "                ",
      "                ",
      "                ",
      "                ",
      "                ",
      "                ",
      "                ",
      "                ",
      "                ",
      "vvvvvvvvvvvvvvvv"
    ],
    [
      "                ",
      "                ",
      "                ",
      "                ",
      "                ",
      "    b        b  ",
      "                ",
      "                ",
      "                ",
      "                ",
      "                ",
      "                ",
      "                ",
      "                ",
      "                ",
      "vvvvvvvvvvvvvvvv"
    ],
    [
      "                ",
      "                ",
      "                ",
      "                ",
      "                ",
      "    b        b  ",
      "                ",
      "                ",
      "                ",
      "                ",
      "                ",
      "                ",
      "                ",
      "                ",
      "                ",
      "vvvvvvvvvvvvvvvv"
    ],
    [
      "hhhhihhhhhhhhihh",
      "hhhhihhhhhhhhihh",
      "hhhhihhhhhhhhihh",
      "hhhhihhhhhhhhihh",
      "hhhhihhhhhhhhihh",
      "iiiijiiiiiiiijii",
      "hhhhihhhhhhhhihh",
      "hhhhihhhhhhhhihh",
      "hhhhihhhhhhhhihh",
      "hhhhihhhhhhhhihh",
      "hhhhihhhhhhhhihh",
      "hhhhihhhhhhhhihh",
      "hhhhihhhhhhhhihh",
      "hhhhihhhhhhhhihh",
      "hhhhihhhhhhhhihh",
      "vvvvvvvvvvvvvvvv"
    ]
  ]
}