{
  "name": "multi_oasiscondo_11_floor5",
  "refpalette": "deceasedcraft:multi_oasiscondo_11/multi_oasiscondo_11_floor5_palette",
  "xsize": 16,
  "zsize": 16,
  "slices": [
    [
      "aaaabacaaaaaabac",
      "ddddbddddddddbdd",
      "ddddbddddddddbdd",
      "ddddbddddddddbdd",
      "ddddbddddddddbdd",
      "ddddbddddddddbdd",
      "ddde edddddde ed",
      "                ",
      "                ",
      "                ",
      "                ",
      "                ",
      "                ",
      "                ",
      "                ",
      "                "
    ],
    [
      "aaaabafaaaaaabaf",
      "g  hbii!jkalmbn ",
      "g opbqqrisatubqq",
      " w xby A Ba CbDE",
      "aaaabFI  JaKabL ",
      " MNOby P QR Sb  ",
      "TUCV WXY   ZW a0",
      "1V12 WW3333WW 41",
      "     W555555W   ",
      "                ",
      "                ",
      "                ",
      "                ",
      "                ",
      "                ",
      "                "
    ],
    [
      "aaaaba6aaaaaaba6",
      "7   bi j  a89b# ",
      "    bqqr $a  bqq",
      "    b%^  &a  b *",
      "aaaab(   )a+ab  ",
      "   -b[   ]  Sb{ ",
      "}  1 W|    ;W a:",
      "''1< WW   >WW 2a",
      "     W,,,,,,W   ",
      "                ",
      "                ",
      "                ",
      "                ",
      "                ",
      "                ",
      "                "
    ],
    [
      "aaaaba.aaaaaaba.",
      "7   b?   /a`\u0370b? ",
      "7   bqqr \u0371a  bqq",
      "7   b    \u0372a  b  ",
      "aaaab    \u0373a\u0374ab  ",
      "   \u0375b(      \u0376b  ",
      "\u0377  1 W(     W 1 ",
      "''12 WW > >WW 4a",
      "     W      W   ",
      "                ",
      "                ",
      "                ",
      "                ",
      "                ",
      "                ",
      "                "
    ],
    [
      "aaaabaaaaaaaabaa",
      "j   b    \u037aa\u037b\u037bb  ",
      "7j! bqqr \u037ca\u037b\u037bbqq",
      "j   b(^  \u037da\u037b\u037bb  ",
      "aaaab  \u037e  aaab \u037e",
      "\u037b\u037b\u037b\u037fb       \u0384b  ",
      "\u037b\u037b\u037b1 W      W a ",
      "''14 WW\u0385\u0385\u0385\u0385WW 41",
      "     W      W   ",
      "                ",
      "                ",
      "                ",
      "                ",
      "                ",
      "                ",
      "                "
    ],
    [
      "aaaabaaaaaaaabaa",
      "\u0386\u0386\u0386\u0386b\u0386\u0386\u0386\u0386\u0386\u0386 \u0387b\u0386\u0386",
      "\u0386\u0386\u0386\u0386b\u0386\u0386\u0386\u0386\u0386\u0386  b\u0386\u0386",
      "\u0386\u0386\u0386\u0386b\u0386\u0386\u0386\u0386\u0386\u0386  b\u0386\u0386",
      "\u0386\u0386\u0386\u0386b\u0386\u0386\u0386\u0386\u0386\u0386\u0386\u0386b\u0386\u0386",
      "   \u0386b\u0386\u0386\u0386\u0386\u0386\u0386\u0386\u0386b\u0386\u0386",
      "  \u0387a W\u0386\u0386\u0386\u0386\u0386\u0386W a\u0386",
      "a1a2 WWWWWWWW 4a",
      "     WWWWWWWW   ",
      "                ",
      "                ",
      "                ",
      "                ",
      "                ",
      "                ",
      "                "
    ]
  ]
}