{
  "name": "multi_oasiscondo_11_floor2",
  "refpalette": "deceasedcraft:multi_oasiscondo_11/multi_oasiscondo_11_floor2_palette",
  "xsize": 16,
  "zsize": 16,
  "slices": [
    [
      "aaaabacaaaaaabac",
      "deeebddddddddbdd",
      "deeebddddddddbdd",
      "deeebddddddddbdd",
      "ddddbffddddddbdd",
      "ddddbddddddddbdd",
      "dddg gddddddg gd",
      "                ",
      "                ",
      "                ",
      "                ",
      "                ",
      "                ",
      "                ",
      "                ",
      "                "
    ],
    [
      "aaaabahaaaaaabai",
      "  j bk    lmnbk ",
      " jojbpppp    bpp",
      "  j bqrst uwxby ",
      "aaaabAB CaaaabAB",
      "  DEby  F  IIby ",
      "J KL aMNCJ Ka aO",
      "aaaP PaLLaaaP Pa",
      "                ",
      "                ",
      "                ",
      "                ",
      "                ",
      "                ",
      "                ",
      "                "
    ],
    [
      "aaaabaQaaaaaabaR",
      "    bS    TU bV ",
      "    bpppp    bpp",
      "    b   W   XbY ",
      "aaaab   Caaaab  ",
      "   Zb0  1   Zb2 ",
      "   a L3 C   a L ",
      "44a5 5a4444LP Pa",
      "                ",
      "                ",
      "                ",
      "                ",
      "                ",
      "                ",
      "                ",
      "                "
    ],
    [
      "aaaaba6aaaaaaba6",
      "    b7    89#b7 ",
      "    bpppp    bpp",
      "    b   $%   b  ",
      "aaaab   Caaaab  ",
      "   ^b   $   ^b  ",
      "&  a a* C&  a a ",
      "44L5 Pa4444aP 5a",
      "                ",
      "                ",
      "                ",
      "                ",
      "                ",
      "                ",
      "                ",
      "                "
    ],
    [
      "aaaabaaaaaaaabaa",
      "    b (     )b  ",
      "  + bpppp  + bpp",
      "    b   C    b  ",
      "aaaab   Caaaab -",
      "[[[+b   C[[[!b  ",
      "[[[L a  C[[[a a ",
      "44aP Pa4444a5 Pa",
      "                ",
      "                ",
      "                ",
      "                ",
      "                ",
      "                ",
      "                ",
      "                "
    ],
    [
      "aaaabaaaaaaaabaa",
      "]]]]b]]]]]]]]b]]",
      "]]]]b]]]]]]]]b]]",
      "]]]]b]]]]]]]]b]]",
      "]]]]b]]]]]]]]b]]",
      "   ]b]]]]   ]b]]",
      "  {a a]]]  {L a]",
      "aaLP 5aLaaaaP PL",
      "                ",
      "                ",
      "                ",
      "                ",
      "                ",
      "                ",
      "                ",
      "                "
    ]
  ]
}