{
  "name": "multi_thering_12_base2",
  "refpalette": "deceasedcraft:multi_thering_12/multi_thering_12_base2_palette",
  "xsize": 16,
  "zsize": 16,
  "slices": [
    [
      "aaaaaaaaaaaaaaaa",
      "aaaaaaaaaaaaaaaa",
      "aaaaaaaaaaaaaaaa",
      "aaaaaaaaaaaaaaaa",
      "aaaaaaaaaaaaaaaa",
      "aaaaaaaaaaaaaaaa",
      "aaaaaaaaaaaaaaaa",
      "aaaaaaaaaaaaaaaa",
      "aaaaaaaaaaaaaaaa",
      "aaaaaaaaaaaaaaaa",
      "aaaaaaaaaaaaaaaa",
      "aaaaaaaaaaaaaaaa",
      "aaaaaaaaaaaaaaaa",
      "aaaaaaaaaaaaaaaa",
      "aaaaaaaaaaaaaaaa",
      "aaaaaaaaaaaaaaaa"
    ],
    [
      "aaaaaaaaaaaaaaaa",
      "aaaaaaaaaaaaaaaa",
      "aaaaaaaaaaaaaaaa",
      "aaaaaaaaaaaaaaaa",
      "aaaaaaaaaaaaaaaa",
      "aaaaaaaaaaaaaaaa",
      "aaaaaaaaaaaaaaaa",
      "aaaaaaaaaaaaaaaa",
      "aaaaaaaaaaaaaaaa",
      "aaaaaaaaaaaaaaaa",
      "aaaaaaaaaaaaaaaa",
      "aaaaaaaaaaaaaaaa",
      "aaaaaaaaaaaaaaaa",
      "aaaaaaaaaaaaaaaa",
      "aaaaaaaaaaaaaaaa",
      "aaaaaaaaaaaaaaaa"
    ],
    [
      "bbbbbbbbbbbbbbbb",
      "bbbbbbbbbbbbbbbb",
      "bbbbbbbbbbbbbbbb",
      "bbbbbbbbbbbbbbbb",
      "bbbbbbbbbbbbbbba",
      "bbbbbbbbbbbbbbba",
      "bbbbbbbbbbbbbbba",
      "bbbbbbbbbbbbbbaa",
      "bbbbbbbbbbbbbbaa",
      "bbbbbbbbbbbbbaaa",
      "bbbbbbbbbbbbaaaa",
      "bbbbbbbbbbbaaaaa",
      "bbbbbbbbbbaaaaaa",
      "bbbbbbbbbaaaaaaa",
      "bbbbbbbaaaaaaaaa",
      "bbbbaaaaaaaaaaaa"
    ],
    [
      "cddddddddddddddc",
      "dddddddddddddddd",
      "dddddddddddddddd",
      "dddddddddddddddd",
      "dddddddddddddddb",
      "dddddddddddddddb",
      "dddddddddddddddb",
      "ddddddddddddddbb",
      "ddddddddddddddbb",
      "dddddddddddddbbb",
      "ddddddddddddbbba",
      "dddddddddddbbbaa",
      "ddddddddddbbbbaa",
      "dddddddddbbbbaaa",
      "dddddddbbbbaaaaa",
      "cdddbbbbbbaaaaaa"
    ],
    [
      "e              e",
      "               d",
      "               d",
      "               f",
      "              ff",
      "              fd",
      "              fd",
      "             ffd",
      "             fdd",
      "            ffdd",
      "           ffddb",
      "          ffddbb",
      "         ffdddbb",
      "       fffdddbbb",
      "    ffffdddbbbba",
      "eddffdddddbbbbaa"
    ],
    [
      "e              e",
      "                ",
      "                ",
      "                ",
      "                ",
      "                ",
      "                ",
      "                ",
      "               f",
      "               f",
      "              ff",
      "             ffd",
      "             fdd",
      "           fffdd",
      "          ffdddb",
      "e       fffdddbb"
    ]
  ]
}