{
  "name": "multi_officethefirst_2_base3",
  "refpalette": "deceasedcraft:multi_officethefirst_2/multi_officethefirst_2_base3_palette",
  "xsize": 16,
  "zsize": 16,
  "slices": [
    [
      "vvvvvvvvvvvvvvvv",
      "abaaaaaaaaaaaaav",
      "   cdddeafg   av",
      "    hhhhaf    av",
      "   ijkk af    av",
      "   cdddeaf    av",
      "    hhhhaf    av",
      "   ikkk af    av",
      "   cdddlaf    av",
      "    hhhhaf    av",
      "   ikjj af    av",
      "   cdddlaf    av",
      "    hhhhaf    av",
      "   ijjj af    av",
      "   cdddeaf    av",
      "    hhhhaf    av"
    ],
    [
      "vvvvvvvvvvvvvvvv",
      "abaaaaaaaaaaaaav",
      "   dmnnoa     av",
      "    pqqqrs    av",
      "   ittt as    av",
      "   dmnnoas    av",
      "    pqqqrs    av",
      "   ittt as    av",
      "   dmnnoas    av",
      "    pqqqus    av",
      "   ittt as    av",
      "   dmnnoas    av",
      "    pqqqrs    av",
      "   ittt as    av",
      "   dmnnoas    av",
      "    pqqqrs    av"
    ],
    [
      "vvvvvvvvvvvvvvvv",
      "abaaaaaaaaaaaaav",
      "   dwxxya     av",
      "    A   B     av",
      "   ittt a     av",
      "   dCxDya     av",
      "        B     av",
      "   ittt a     av",
      "   dCxxya     av",
      "        E     av",
      "   ittt a     av",
      "   dCxxya     av",
      "        B     av",
      "   ittt a     av",
      "   dCxxya     av",
      "        B     av"
    ],
    [
      "vvvvvvvvvvvvvvvv",
      "abaaaaaaaaaaaaav",
      "   dCxxya    fav",
      "        aF   fav",
      "   ittt a    fav",
      "   dC!Dya    fav",
      "        aF   fav",
      "   ittt a    fav",
      "   dCxxya    fav",
      "        aI   fav",
      "   ittt a    fav",
      "   dCDxya    fav",
      "        aF   fav",
      "   ittt a    fav",
      "   dJxxya    fav",
      "    A   aF   fav"
    ],
    [
      "vvvvvvvvvvvvvvvv",
      "abaaaaaaaaaaaaav",
      "   dCxxya   g av",
      "        a    Kav",
      "   ittt a    Kav",
      "   dCDxya    Kav",
      "        a    Kav",
      "   ittt a    Kav",
      "   dCxxya    Kav",
      "        a    Kav",
      "   ittt a    Kav",
      "   dCxxya    Kav",
      "        a    Kav",
      "   ittt a    Kav",
      "   dCxxya    Kav",
      "        a    Kav"
    ],
    [
      "vvvvvvvvvvvvvvvv",
      "abaaaaaaaaaaaaav",
      "   dCxDLa  g  av",
      "       Ma     av",
      "   itttMa     av",
      "   dCxxLa     av",
      "       Ma     av",
      "   itttMa     av",
      "   dNxxLa     av",
      "    A  Ma     av",
      "   itttMa     av",
      "   dCxxLa     av",
      "       Ma     av",
      "   itttMa     av",
      "   dCxDLa     av",
      "       Ma     av"
    ]
  ]
}