{
  "name": "multi_officethefirst_2_base1",
  "refpalette": "deceasedcraft:multi_officethefirst_2/multi_officethefirst_2_base1_palette",
  "xsize": 16,
  "zsize": 16,
  "slices": [
    [
      "vvvvvvvvvvvvvvvv",
      "abaaaaaaaaaaaaav",
      "   cdddeafg   av",
      "        af    av",
      "   hiii af    av",
      "   cdddeaf    av",
      "        af    av",
      "   hjjj af    av",
      "   cddd!af    av",
      "        af    av",
      "   hijj af    av",
      "   cdddeaf    av",
      "        af    av",
      "   hjji af    av",
      "   cdddeaf    av",
      "        af    av"
    ],
    [
      "vvvvvvvvvvvvvvvv",
      "baaaaaaaaaaaaaav",
      "       ka     av",
      "        al    av",
      "        al    av",
      "       kal    av",
      "        al    av",
      "        al    av",
      "        al    av",
      "        al    av",
      "        al    av",
      "       kal    av",
      "        al    av",
      "        al    av",
      "       kal    av",
      "        al    av"
    ],
    [
      "vvvvvvvvvvvvvvvv",
      "aaaaaaaaaaaaaaav",
      "        a     av",
      "        a     av",
      "        a     av",
      "        a     av",
      "        a     av",
      "        a     av",
      "        a     av",
      "        a     av",
      "        a     av",
      "        a     av",
      "        a     av",
      "        a     av",
      "        a     av",
      "        a     av"
    ],
    [
      "vvvvvvvvvvvvvvvv",
      "aaaaaaaaaaaaaaav",
      "        a     av",
      "        a     av",
      "        a     av",
      "        a     av",
      "        a     av",
      "        a     av",
      "        a     av",
      "        a     av",
      "        a     av",
      "        a     av",
      "        a     av",
      "        a     av",
      "        a     av",
      "        a     av"
    ],
    [
      "vvvvvvvvvvvvvvvv",
      "aaaaaaaaaaaaaaav",
      "mmmmmmmmammmmmav",
      "mmmmmmmmammmmmav",
      "nmmmnommammommav",
      "ommmoommammmmmav",
      "mmmmmmmmammmmmav",
      "mmmmmmmmammmmmav",
      "mmmmmmmmammnmmav",
      "mmmmmmmmammmmmav",
      "mmmmmmmmammmmmav",
      "ommmoommammmmmav",
      "ommmoommammnmmav",
      "mmmmmmmmammmmmav",
      "mmmmmmmmammmmmav",
      "mmmmmmmmammmmmav"
    ],
    [
      "vvvvvvvvvvvvvvvv",
      "pppppppppppppppv",
      "pppppppppppppppv",
      "pppppppppppppppv",
      "pppppppppppppppv",
      "qqqqqqqqqqqppppv",
      "rrrrrrrrrrpppppv",
      "rrrrrrrrrrpppppv",
      "rrrrrrrrrrpppppv",
      "rrrrrrrrrrpppppv",
      "pppppppppppppppv",
      "pppppppppppppppv",
      "pppppppppppppppv",
      "pppppppppppppppv",
      "pppppppppppppppv",
      "pppppppppppppppv"
    ]
  ]
}