{
  "name": "multi_officethefirst_2_base4",
  "refpalette": "deceasedcraft:multi_officethefirst_2/multi_officethefirst_2_base4_palette",
  "xsize": 16,
  "zsize": 16,
  "slices": [
    [
      "vvvvvvvvvvvvvvvv",
      "aaaaaaaaaaaaaaav",
      "bbbbbbbbabbbbbav",
      "bbbbbbbbabbbbbav",
      "bbbbbbbbabbbbbav",
      "bbbbbbbbabbbbbav",
      "bbbbbbbbabbbbbav",
      "bbbbbbbbabbbbbav",
      "bbbbbbbbabbbbbav",
      "bbbbbbbbabbbbbav",
      "bbbbbbbbabbbbbav",
      "bbbbbbbbabbbbbav",
      "bbbbbbbbabbbbbav",
      "bbbbbbbbabbbbbav",
      "bbbbbbbbabbbbbav",
      "bbbbbbbbabbbbbav"
    ],
    [
      "vvvvvvvvvvvvvvvv",
      "aaaaaaaaaaaaaaav",
      "   cdeefag   hav",
      "        a i  jav",
      "   klll a    jav",
      "   cdeefa    mav",
      "        an o mav",
      "   klll ap   mav",
      "   cdeefaqr  mav",
      "        aq  omav",
      "   klll ap   mav",
      "   cdeefas o mav",
      "        at  umav",
      "   klll at   mav",
      "   cdeefaw   mav",
      "        ap  umav"
    ],
    [
      "vvvvvvvvvvvvvvvv",
      "aaaaaaaaaaaaaaav",
      "   cxyABa    Cav",
      "        a  i Cav",
      "   Dlll a    Cav",
      "   cxyyBa    Cav",
      "        a    Cav",
      "   Dlll aE   Fav",
      "   cxyyBaI   Cav",
      "        aJ   Cav",
      "   Dlll a    Kav",
      "   cxAyBa    Cav",
      "        a    Fav",
      "   Dlll a    Cav",
      "   cxyyBa    Cav",
      "        a    !av"
    ],
    [
      "vvvvvvvvvvvvvvvv",
      "Laaaaaaaaaaaaaav",
      "   cxyyBa    Mav",
      "        a   iMav",
      "   Dlll a     av",
      "   cxyyBa    uav",
      "        a     av",
      "   Dlll a     av",
      "   cxyyBa     av",
      "        a     av",
      "   Dlll a     av",
      "   cxyyBa     av",
      "        aN    av",
      "   Dlll a     av",
      "   cxyABa     av",
      "        a    oav"
    ],
    [
      "vvvvvvvvvvvvvvvv",
      "aLaaaaaaaaaaaaav",
      "   cOyABa   P av",
      "    Q   a    Rav",
      "   Dlll a     av",
      "   cxyyBa     av",
      "        a     av",
      "   Dlll a     av",
      "   cxyyBa     av",
      "        a     av",
      "   Dlll a     av",
      "   cxyyBa     av",
      "        a     av",
      "   Dlll a     av",
      "   cxyyBa     av",
      "        a     av"
    ],
    [
      "vvvvvvvvvvvvvvvv",
      "aaaaaaaaaaaaaaav",
      "   cxyySa  P  av",
      "       Ta     av",
      "   DlllTa     av",
      "   cxyySa     av",
      "       Ta     av",
      "   DlllTa     av",
      "   cxAySa     av",
      "       Ta     av",
      "   DlllTa     av",
      "   cxyySa     av",
      "       Ta     av",
      "   DlllTa     av",
      "   cxAySa     av",
      "       Ta     av"
    ]
  ]
}