{
  "name": "multi_officethefirst_2_ground",
  "refpalette": "deceasedcraft:multi_officethefirst_2/multi_officethefirst_2_ground_palette",
  "xsize": 16,
  "zsize": 16,
  "slices": [
    [
      "HHHHHHHHHHHHHHHH",
      "HHHHHHHHHHHHHHHH",
      "aaaaaaaaaaaaaHHH",
      "bbbbbbbbbbbbbaHH",
      "ccdccccdccccbaHH",
      "eefeeeefeeecbaHH",
      "ggggggggggecbaHH",
      "ggggggggggecbaHH",
      "ggggggggggecbaHH",
      "ggggggggggecbaHH",
      "eeeeeeeeeeecbaHH",
      "hhhhhhhhhhecbaHH",
      "eeeeeeeeeeecbaHH",
      "aaaaaaaaaaecbaHH",
      "iiiiiiiiiaecbaHH",
      "iiiiiiiiiaecbaHH"
    ],
    [
      "                ",
      "                ",
      "                ",
      "                ",
      "cccccccccccc    ",
      "jjjjjjjjjjjc    ",
      "          jc    ",
      "          jc    ",
      "          jc    ",
      "          kc    ",
      "llllllllllec    ",
      "hhhhhhhhhhec    ",
      "mmmmmmmmmmec    ",
      "ffffffffffec    ",
      "        nfec    ",
      " l       fec    "
    ],
    [
      "                ",
      "                ",
      "                ",
      "                ",
      "                ",
      "                ",
      "                ",
      "                ",
      "                ",
      "           c    ",
      "          jc    ",
      "oooooooooojc    ",
      "          jc    ",
      "ppppppppppkc    ",
      "        opec    ",
      "         pec    "
    ],
    [
      "                ",
      "                ",
      "                ",
      "                ",
      "                ",
      "                ",
      "                ",
      "                ",
      "                ",
      "                ",
      "                ",
      "                ",
      "                ",
      "pppppppppp c    ",
      "        qpjc    ",
      "         pjc    "
    ],
    [
      "                ",
      "                ",
      "                ",
      "                ",
      "                ",
      "                ",
      "                ",
      "                ",
      "                ",
      "                ",
      "                ",
      "                ",
      "                ",
      "pppppppppp      ",
      "         p      ",
      "         p      "
    ],
    [
      "                ",
      "                ",
      "                ",
      "                ",
      "                ",
      "                ",
      "                ",
      "                ",
      "                ",
      "                ",
      "                ",
      "                ",
      "                ",
      "ffffffffff      ",
      "r        f      ",
      "ss       f      "
    ]
  ]
}