{
  "name": "multi_officethefirst_2_base2",
  "refpalette": "deceasedcraft:multi_officethefirst_2/multi_officethefirst_2_base2_palette",
  "xsize": 16,
  "zsize": 16,
  "slices": [
    [
      "vvvvvvvvvvvvvvvv",
      "abaaaaaaaaaaaaav",
      "   cdddeafg   av",
      "    hhhhaf    av",
      "   ijjj af    av",
      "   cdddkaf    av",
      "    hhhhaf    av",
      "   illj af    av",
      "   cdddeaf    av",
      "    hhhhaf    av",
      "   ijll af    av",
      "   cdddkaf    av",
      "    hhhhaf    av",
      "   illl af    av",
      "   cdddeaf    av",
      "    hhhhaf    av"
    ],
    [
      "vvvvvvvvvvvvvvvv",
      "abaaaaaaaaaaaaav",
      "   dmnnoa     av",
      "    pqqqrs    av",
      "   ittt as    av",
      "   dmnnoas    av",
      "    pqqqrs    av",
      "   ittt as    av",
      "   dmnnoas    av",
      "    pqqqrs    av",
      "   ittt as    av",
      "   dmnnoas    av",
      "    pqqqrs    av",
      "   ittt as    av",
      "   dmnnoas    av",
      "    pqqqrs    av"
    ],
    [
      "vvvvvvvvvvvvvvvv",
      "abaaaaaaaaaaaaav",
      "   duwwxa     av",
      "        y     av",
      "   ittt a     av",
      "   duwwxa     av",
      "        y     av",
      "   ittt a     av",
      "   duAwxa     av",
      "        y     av",
      "   ittt a     av",
      "   dBwAxa     av",
      "    C   y     av",
      "   ittt a     av",
      "   duwwxa     av",
      "        y     av"
    ],
    [
      "vvvvvvvvvvvvvvvv",
      "abaaaaaaaaaaaaav",
      "   duAwxa    fav",
      "        aD   fav",
      "   ittt a    fav",
      "   duwAxa    fav",
      "        aD   fav",
      "   ittt a    fav",
      "   duwwxa    fav",
      "        aD   fav",
      "   ittt a    fav",
      "   d!Awxa    fav",
      "        aD   fav",
      "   ittt a    fav",
      "   duwAxa    fav",
      "        a!   fav"
    ],
    [
      "vvvvvvvvvvvvvvvv",
      "abaaaaaaaaaaaaav",
      "   d!Awxa   g av",
      "        a    Eav",
      "   ittt a    Eav",
      "   duwAxa    Eav",
      "        a    Eav",
      "   ittt a    Eav",
      "   duwwxa    Eav",
      "        a    Eav",
      "   ittt a    Eav",
      "   duAwxa    Eav",
      "        a    Eav",
      "   ittt a    Eav",
      "   duwAxa    Eav",
      "        a    Eav"
    ],
    [
      "vvvvvvvvvvvvvvvv",
      "aaaaaaaaaaaaaaav",
      "   duwwFa  g  av",
      "       Ia     av",
      "   itttIa     av",
      "   duAwFa     av",
      "       Ia     av",
      "   itttIa     av",
      "   duwAFa     av",
      "       Ia     av",
      "   itttIa     av",
      "   duwwFa     av",
      "       Ia     av",
      "   itttIa     av",
      "   duwwFa     av",
      "       Ia     av"
    ]
  ]
}