{
  "name": "multi_thering_13_base1",
  "refpalette": "deceasedcraft:multi_thering_13/multi_thering_13_base1_palette",
  "xsize": 16,
  "zsize": 16,
  "slices": [
    [
      "           aaabb",
      "c        aaabbbd",
      "eee   aaaabbbbdd",
      "bbbaaaabbbbbdddd",
      "ffbbbbbbbbdddddg",
      "bbbbbbbdddddddgg",
      "ddddddddddddgggg",
      "ddddddddgggggggg",
      "gggggggggggggggg",
      "gggggggggggggggg",
      "gggggggggggggggg",
      "gggggggggggggggg",
      "gggggggggggggggg",
      "gggggggggggggggg",
      "gggggggggggggggg",
      "hggggggggggggggh"
    ],
    [
      "               a",
      "              aa",
      "            aaab",
      "          aaabbb",
      "ee     aaaabbbbd",
      "bbbbbaaabbbbbbdd",
      "ffffbbbbbbbbdddd",
      "bbbbbbbbdddddddg",
      "dddddddddddddggg",
      "ddddddddddgggggg",
      "gggggggggggggggg",
      "gggggggggggggggg",
      "gggggggggggggggg",
      "gggggggggggggggg",
      "gggggggggggggggg",
      "hggggggggggggggh"
    ],
    [
      "                ",
      "                ",
      "                ",
      "               a",
      "              aa",
      "c           aaab",
      "eeee    aaaaabbb",
      "bbbbbbbaabbbbbbd",
      "ffffffbbbbbbbddd",
      "bbbbbbbbbbdddddd",
      "ddddddddddddddgg",
      "dddddddddddggggg",
      "gggggggggggggggg",
      "gggggggggggggggg",
      "gggggggggggggggg",
      "hggggggggggggggh"
    ],
    [
      "                ",
      "                ",
      "                ",
      "                ",
      "                ",
      "                ",
      "               a",
      "             aaa",
      "eeeeee    aaaabb",
      "bbbbbbaaaaabbbbb",
      "fffffbbbbbbbbbdd",
      "bbbbbbbbbbbddddd",
      "dddddddddddddddg",
      "ddddddddddddgggg",
      "gggggggggggggggg",
      "hggggggggggggggh"
    ],
    [
      "                ",
      "                ",
      "                ",
      "                ",
      "                ",
      "                ",
      "                ",
      "                ",
      "                ",
      "c             aa",
      "eeeee      aaaab",
      "bbbbbbbbbaaabbbb",
      "ffffffffbbbbbbbd",
      "bbbbbbbbbbbbdddd",
      "dddddddddddddddd",
      "hddddddddddddggh"
    ],
    [
      "                ",
      "                ",
      "                ",
      "                ",
      "                ",
      "                ",
      "                ",
      "                ",
      "                ",
      "                ",
      "                ",
      "               a",
      "eeeeeeee    aaaa",
      "bbbbbbbbaaaaabbb",
      "fffffffbbbbbbbbb",
      "hbbbbbbbbbbbbddh"
    ]
  ]
}