{
  "name": "building_hardwarestorecedamaged_ground_180",
  "refpalette": "deceasedcraft:building_hardwarestorecedamaged/building_hardwarestorecedamaged_ground_palette_180",
  "xsize": 16,
  "zsize": 16,
  "slices": [
    [
      "aaaaaaaaaaaaaaaa",
      "adddddddddddddda",
      "adddddddddddddda",
      "adddddddddddddda",
      "adddddddddddddda",
      "adddddddddddddda",
      "acccdccdddddddda",
      "acccccccddddddda",
      "acccccccddddddda",
      "acccccccddddddda",
      "acccccccddddddda",
      "acccccccddddddda",
      "acccccccddbbddda",
      "accHHHccabbbbaaa",
      "aaHHHHHaabbbbaaa",
      "aaHHHHHaabbbbaaa"
    ],
    [
      "                ",
      " gggggggggggggg ",
      " gmlllllmllmllg ",
      " glVXWUU VU Ulg ",
      " glT wS    E lg ",
      " glRP Q wPO  mg ",
      " eeeNfee sM Jlg ",
      " e wL  f CKjJlg ",
      " eIF EDeC   rlg ",
      " eB A  e swyrlg ",
      "xe w ute s  rlg ",
      " e q  pellonmlg ",
      " fk  jieggh ggg ",
      " ef   ee        ",
      "                ",
      "                "
    ],
    [
      "                ",
      " YZZZ90ZZZZZZZY ",
      " ZmllllmllmlllZ ",
      " ZlV  U      lZ ",
      " Zm          mZ ",
      " Zl          lZ ",
      " eee eef    8lZ ",
      " f2 762e     mZ ",
      " e2   2e     lZ ",
      " e2   2e     mZ ",
      " e2   2e 5   mZ ",
      " e2   2fll43llZ ",
      " e2   2eZ1  0ZY ",
      " ee   ef        ",
      "                ",
      "                "
    ],
    [
      "                ",
      " Y%%%Z9%%%%%%%Y ",
      " %lm((ml{l((lm% ",
      " $l          m% ",
      " %l          (% ",
      " %l          (% ",
      " fef]eee     l% ",
      " eI [ -e     l% ",
      " +)    f     (% ",
      " bI   *e      % ",
      " u     e     m% ",
      "      keml& ml$ ",
      " eI   ^e%Z  1$Y ",
      " ee###ef        ",
      "                ",
      "                "
    ],
    [
      "                ",
      " Y%%%%Z%%%%%%%Y ",
      " %lll{llllllll% ",
      " >{  <<<<<<  l% ",
      " %l          l% ",
      " %l          l% ",
      " eeeefee     l% ",
      " e     e     l% ",
      " :     e'    m% ",
      " :     f     l% ",
      "       e     l% ",
      " :     em{lllm; ",
      " e ||| e%%}} 1Y ",
      " ee###ee        ",
      "                ",
      "                "
    ],
    [
      "                ",
      " Y$$$$$$$$$$$$Y ",
      " $llmmlllllllm$ ",
      " 0m  ,,,,,,  l$ ",
      " $l          m$ ",
      " $m          m$ ",
      " efeeeee     l$ ",
      " e     e     l$ ",
      " e     e     l$ ",
      " e     e     l$ ",
      " e     f     l$ ",
      " e     ellllm{0 ",
      " f     e$$001 Y ",
      " eeeefee        ",
      "                ",
      "                "
    ]
  ]
}