{
  "name": "building_hardwarestorecedamaged_ground_270",
  "refpalette": "deceasedcraft:building_hardwarestorecedamaged/building_hardwarestorecedamaged_ground_palette_270",
  "xsize": 16,
  "zsize": 16,
  "slices": [
    [
      "aaaaaaaaaaaaaaaa",
      "addddddddddddaaa",
      "addddddddddddaaa",
      "addddddddddddbbb",
      "adddddddddddbbbb",
      "adddddddddddbbbb",
      "addddddddddddbbb",
      "addddddddddddaaa",
      "addddddcccccccaa",
      "adddddccccccccHH",
      "adddddcccccccHHH",
      "addddddccccccHHH",
      "adddddcccccccHHH",
      "adddddccccccccHH",
      "adddddccccccccaa",
      "aaaaaaaaaaaaaaaa"
    ],
    [
      "                ",
      " gggggggggggg   ",
      " glllmllllllg   ",
      " glU  JJrrrmg   ",
      " gm E  j y n    ",
      " glU OMK w oh   ",
      " glV PsC sslg   ",
      " gm  w  C  lg   ",
      " glU  efeeeeee  ",
      " glUSQe D tpie  ",
      " glWw f E u j   ",
      " glX PNL A      ",
      " glVTRewF wq    ",
      " gmllle IB  kf  ",
      " gggggeeeeeefe  ",
      "          x     "
    ],
    [
      "                ",
      " YZZZZZZZZZZY   ",
      " ZllmllmlmmlZ   ",
      " Zl   8    l0   ",
      " Zl        3    ",
      " Zm        4    ",
      " Zl       5l1   ",
      " Zl        lZ   ",
      " Zm   feeeefef  ",
      " 0lU  e222222e  ",
      " 9l   e6        ",
      " Zl    7        ",
      " ZlV  e         ",
      " Zmlmle222222e  ",
      " YZZZZefeeeeee  ",
      "                "
    ],
    [
      "                ",
      " Y%%%%%%%%%$Y   ",
      " %mm((ll( ml$   ",
      " %l        m1   ",
      " %(             ",
      " %(        &    ",
      " %l        lZ   ",
      " %{        m%   ",
      " %l   eefeeeef  ",
      " 9m   e- * k^e  ",
      " Z(   e      #  ",
      " %(   ][     #  ",
      " %m   f      #  ",
      " %lllleI)I  Ie  ",
      " Y%$%%fe+bu ee  ",
      "                "
    ],
    [
      "                ",
      " Y%%%%%%%%%;Y   ",
      " %llllllmllm1   ",
      " %l        l    ",
      " %l        l}   ",
      " %l<       l}   ",
      " %l<       {%   ",
      " %l<    '  m%   ",
      " %l<  eeefeeee  ",
      " Zl<  e      e  ",
      " %{<  f     |#  ",
      " %l   e     |#  ",
      " %l   e     |#  ",
      " %l{lle      e  ",
      " Y%>%%ee:: :ee  ",
      "                "
    ],
    [
      "                ",
      " Y$$$$$$$$$0Y   ",
      " $mlmmlllll{    ",
      " $l        m1   ",
      " $l        l0   ",
      " $l,       l0   ",
      " $l,       l$   ",
      " $l,       l$   ",
      " $l,  eeeefeee  ",
      " $l,  e      e  ",
      " $m,  e      f  ",
      " $m   e      e  ",
      " $l   e      e  ",
      " $lmlmf      e  ",
      " Y$0$$eeeeeefe  ",
      "                "
    ]
  ]
}