{
  "name": "building_hardwarestorecedamaged_ground_90",
  "refpalette": "deceasedcraft:building_hardwarestorecedamaged/building_hardwarestorecedamaged_ground_palette_90",
  "xsize": 16,
  "zsize": 16,
  "slices": [
    [
      "aaaaaaaaaaaaaaaa",
      "aaccccccccddddda",
      "HHccccccccddddda",
      "HHHcccccccddddda",
      "HHHccccccdddddda",
      "HHHcccccccddddda",
      "HHccccccccddddda",
      "aacccccccdddddda",
      "aaadddddddddddda",
      "bbbdddddddddddda",
      "bbbbddddddddddda",
      "bbbbddddddddddda",
      "bbbdddddddddddda",
      "aaadddddddddddda",
      "aaadddddddddddda",
      "aaaaaaaaaaaaaaaa"
    ],
    [
      "     x          ",
      "  efeeeeeeggggg ",
      "  fk  BI elllmg ",
      "    qw FweRTVlg ",
      "      A LNP Xlg ",
      "   j u E f wWlg ",
      "  eipt D eQSUlg ",
      "  eeeeeefe  Ulg ",
      "   gl  C  w  mg ",
      "   glss CsP Vlg ",
      "   ho w KMO Ulg ",
      "    n y j  E mg ",
      "   gmrrrJJ  Ulg ",
      "   gllllllmlllg ",
      "   gggggggggggg ",
      "                "
    ],
    [
      "                ",
      "  eeeeeefeZZZZY ",
      "  e222222elmlmZ ",
      "         e  VlZ ",
      "        7    lZ ",
      "        6e   l9 ",
      "  e222222e  Ul0 ",
      "  fefeeeef   mZ ",
      "   Zl        lZ ",
      "   1l5       lZ ",
      "    4        mZ ",
      "    3        lZ ",
      "   0l    8   lZ ",
      "   ZlmmlmllmllZ ",
      "   YZZZZZZZZZZY ",
      "                "
    ],
    [
      "                ",
      "  ee ub+ef%%$%Y ",
      "  eI  I)Iellll% ",
      "  #      f   m% ",
      "  #     []   (% ",
      "  #      e   (Z ",
      "  e^k * -e   m9 ",
      "  feeeefee   l% ",
      "   %m        {% ",
      "   Zl        l% ",
      "    &        (% ",
      "             (% ",
      "   1m        l% ",
      "   $lm (ll((mm% ",
      "   Y$%%%%%%%%%Y ",
      "                "
    ],
    [
      "                ",
      "  ee: ::ee%%>%Y ",
      "  e      ell{l% ",
      "  #|     e   l% ",
      "  #|     e   l% ",
      "  #|     f  <{% ",
      "  e      e  <lZ ",
      "  eeeefeee  <l% ",
      "   %m  '    <l% ",
      "   %{       <l% ",
      "   }l       <l% ",
      "   }l        l% ",
      "    l        l% ",
      "   1mllmllllll% ",
      "   Y;%%%%%%%%%Y ",
      "                "
    ],
    [
      "                ",
      "  efeeeeee$$0$Y ",
      "  e      fmlml$ ",
      "  e      e   l$ ",
      "  e      e   m$ ",
      "  f      e  ,m$ ",
      "  e      e  ,l$ ",
      "  eeefeeee  ,l$ ",
      "   $l       ,l$ ",
      "   $l       ,l$ ",
      "   0l       ,l$ ",
      "   0l        l$ ",
      "   1m        l$ ",
      "    {lllllmmlm$ ",
      "   Y0$$$$$$$$$Y ",
      "                "
    ]
  ]
}