{
  "name": "building_hardwarestorecedamaged_ground",
  "refpalette": "deceasedcraft:building_hardwarestorecedamaged/building_hardwarestorecedamaged_ground_palette",
  "xsize": 16,
  "zsize": 16,
  "slices": [
    [
      "aaabbbbaaHHHHHaa",
      "aaabbbbaaHHHHHaa",
      "aaabbbbaccHHHcca",
      "adddbbddccccccca",
      "adddddddccccccca",
      "adddddddccccccca",
      "adddddddccccccca",
      "adddddddccccccca",
      "adddddddccccccca",
      "addddddddccdccca",
      "adddddddddddddda",
      "adddddddddddddda",
      "adddddddddddddda",
      "adddddddddddddda",
      "adddddddddddddda",
      "aaaaaaaaaaaaaaaa"
    ],
    [
      "                ",
      "                ",
      "        ee   fe ",
      " ggg hggeij  kf ",
      " glmnollep  q e ",
      " glr  s etu w ex",
      " glryws e  A Be ",
      " glr   CeDE FIe ",
      " glJjKC f  Lw e ",
      " glJ Ms eefNeee ",
      " gm  OPw Q PRlg ",
      " gl E    Sw Tlg ",
      " glU UV UUWXVlg ",
      " gllmllmlllllmg ",
      " gggggggggggggg ",
      "                "
    ],
    [
      "                ",
      "                ",
      "        fe   ee ",
      " YZ0  1Ze2   2e ",
      " Zll34llf2   2e ",
      " Zm   5 e2   2e ",
      " Zm     e2   2e ",
      " Zl     e2   2e ",
      " Zm     e267 2f ",
      " Zl8    fee eee ",
      " Zl          lZ ",
      " Zm          mZ ",
      " Zl      U  VlZ ",
      " ZlllmllmllllmZ ",
      " YZZZZZZZ09ZZZY ",
      "                "
    ],
    [
      "                ",
      "                ",
      "        fe###ee ",
      " Y$1  Z%e^   Ie ",
      " $lm &lmek      ",
      " %m     e     u ",
      " %      e*   Ib ",
      " %(     f    )+ ",
      " %l     e- [ Ie ",
      " %l     eee]fef ",
      " %(          l% ",
      " %(          l% ",
      " %m          l$ ",
      " %ml((l{lm((ml% ",
      " Y%%%%%%%9Z%%%Y ",
      "                "
    ],
    [
      "                ",
      "                ",
      "        ee###ee ",
      " Y1 }}%%e ||| e ",
      " ;mlll{me     : ",
      " %l     e       ",
      " %l     f     : ",
      " %m    'e     : ",
      " %l     e     e ",
      " %l     eefeeee ",
      " %l          l% ",
      " %l          l% ",
      " %l  <<<<<<  {> ",
      " %llllllll{lll% ",
      " Y%%%%%%%Z%%%%Y ",
      "                "
    ],
    [
      "                ",
      "                ",
      "        eefeeee ",
      " Y 100$$e     f ",
      " 0{mlllle     e ",
      " $l     f     e ",
      " $l     e     e ",
      " $l     e     e ",
      " $l     e     e ",
      " $l     eeeeefe ",
      " $m          m$ ",
      " $m          l$ ",
      " $l  ,,,,,,  m0 ",
      " $mlllllllmmll$ ",
      " Y$$$$$$$$$$$$Y ",
      "                "
    ]
  ]
}