{
  "name": "scattered_treehouse_1_floor1",
  "refpalette": "deceasedcraft:scattered_treehouse_1/scattered_treehouse_1_floor1_palette",
  "xsize": 16,
  "zsize": 16,
  "slices": [
    [
      "aaaaaaaaaaaaaaaa",
      "aaaaaaaaaaaaaaaa",
      "aaaaaaaaaaaaaaaa",
      "aaaaaaaaaaaaaaaa",
      "aaaaaaaaaaaaaaaa",
      "aabbaaaacacdcaaa",
      "abbbaaaadccddaaa",
      "abbbaaaeaccccaaa",
      "abbbaaafccccaaaa",
      "abaaafafgccccaaa",
      "aaaaaafadcccdaaa",
      "aaaaaffacdcdcaaa",
      "aaaaafafccccaaaa",
      "aaaffaaadcdcdaaa",
      "aaaaafaaaaaaaaaa",
      "aafaaaaaaaaaaaaa"
    ],
    [
      "hhhhhhhhhhhhhhhh",
      "hhhhhhhhhhhhhhhh",
      "hhhhhhhhhhhhhhhh",
      "hhhhhhhhhhhhhhhh",
      "hhhhhhhiiiiiiihh",
      "hhjkhhhihhhhhihh",
      "hjjklhhihhhhhihh",
      "hjjkmhhehhhhhihh",
      "hjjknhophhhhhihh",
      "hjqrhhhhihhhhihh",
      "hhlhhhhhhhhhhihh",
      "hhhhhhhhhhhhhihh",
      "hhhhhhhhhhhhhihh",
      "hhhhhhhhhhhhhihh",
      "hhhhhhhiiiiiiihh",
      "hhhhhhhhhhhhhhhh"
    ],
    [
      "hhhhhhhhhhhhhhhh",
      "hhhhhhhhhhhhhhhh",
      "hhhhhhhhhhhhhhhh",
      "hhhhhhhhhhhhhhhh",
      "hhhhhhhhhhhhhhhh",
      "hhhhhhhhhhhhhhhh",
      "hhjhhhhihhhhhhhh",
      "hhjhhhheshhhhhhh",
      "hhjhhhhphhhhhhhh",
      "hhhhhhhhihhhhhhh",
      "hhhhhhhhhhhhhhhh",
      "hhhhhhhhhhhhhhhh",
      "hhhhhhhhhhhhhhhh",
      "hhhhhhhhhhhhhhhh",
      "hhhhhhhhhhhhhhhh",
      "hhhhhhhhhhhhhhhh"
    ],
    [
      "hhhhhhhhhhhhhhhh",
      "hhhhhhhhhhhhhhhh",
      "hhhhhhhhhhhhhhhh",
      "hhhhhhhhhhhhhhhh",
      "hhhhhhhhhhhhhhhh",
      "hhhhhhhhhhhhhhhh",
      "hhhhhhhittthhhhh",
      "hhhhhhueuvthhhhh",
      "hhhhhhhpttthhhhh",
      "hhhhhhhhihhhhhhh",
      "hhhhhhhhhhhhhhhh",
      "hhhhhhhhhhhhhhhh",
      "hhhhhhhhhhhhhhhh",
      "hhhhhhhhhhhhhhhh",
      "hhhhhhhhhhhhhhhh",
      "hhhhhhhhhhhhhhhh"
    ],
    [
      "hhhhhhhhhhhhhhhh",
      "hhhhhhhhhhhhhhhh",
      "hhhhhhhhhhhhhhhh",
      "hhhhhhhhhhhhhhhh",
      "hhhhhhhhhhhhhhhh",
      "hhhhhhhwwwwhhhhh",
      "hhhhhttxhiyzhhhh",
      "hhhhhvsehhAzhhhh",
      "hhhhhttpBiyzhhhh",
      "hhhhhhhhiCChhhhh",
      "hhhhhhhhhhhhhhhh",
      "hhhhhhhhhhhhhhhh",
      "hhhhhhhhhhhhhhhh",
      "hhhhhhhhhhhhhhhh",
      "hhhhhhhhhhhhhhhh",
      "hhhhhhhhhhhhhhhh"
    ],
    [
      "hhhhhhhhhhhhhhhh",
      "hhhhhhhhhhhhhhhh",
      "hhhhhhhhhhhhhhhh",
      "hhhhhhhhhhhhhhhh",
      "hhhhhhhhhhhhhhhh",
      "hhhhhwwwhhhhhhhh",
      "hhhhDihhhihhhhhh",
      "hhhhDEhehhhhhhhh",
      "hhhhDihpFihhhhhh",
      "hhhhhCChihhhhhhh",
      "hhhhhhhhhhhhhhhh",
      "hhhhhhhhhhhhhhhh",
      "hhhhhhhhhhhhhhhh",
      "hhhhhhhhhhhhhhhh",
      "hhhhhhhhhhhhhhhh",
      "hhhhhhhhhhhhhhhh"
    ]
  ]
}