{
  "name": "scattered_treehouse_1_floor3",
  "refpalette": "deceasedcraft:scattered_treehouse_1/scattered_treehouse_1_floor3_palette",
  "xsize": 16,
  "zsize": 16,
  "slices": [
    [
      "aaaaaaaaaaaaaaaa",
      "aaaaaaaaaaaaaaaa",
      "aaaaaaabbbaaaaaa",
      "aaaaaabbbbbaaaaa",
      "aaaaaabbbbbbbbaa",
      "aaaaaabbbbbbbbba",
      "aaaaaaabbbbbbbba",
      "aaaaaabcbdbbbbba",
      "aaaaaaabdaabbbaa",
      "aaaabaaabbbaaaaa",
      "aaabbbabbbbbaaaa",
      "aaaabaabbbbbaaaa",
      "aaaaaaabbbbbaaaa",
      "aaaaaaaabbbaaaaa",
      "aaaaaaaaaaaaaaaa",
      "aaaaaaaaaaaaaaaa"
    ],
    [
      "aaaaaaaaaaaaaaaa",
      "aaaaaaaaaaaaaaaa",
      "aaaaaaaaaaaaaaaa",
      "aaaaaaaabaaaaaaa",
      "aaaaaaabbbabbbaa",
      "aaaaaabbbabbbbba",
      "aaaaabbbbbbbbbba",
      "aaaaabbbbbbbbbba",
      "aaaaabbbbbabbbaa",
      "aaaaaabbbbbaaaaa",
      "aaaaaaabbbbbaaaa",
      "aaaaaaabbbbbaaaa",
      "aaaaaaabbbbbaaaa",
      "aaaaaaaabbbaaaaa",
      "aaaaaaaaaaaaaaaa",
      "aaaaaaaaaaaaaaaa"
    ],
    [
      "aaaaaaaaaaaaaaaa",
      "aaaaaaaaaaaaaaaa",
      "aaaaaaaaaaaaaaaa",
      "aaaaaaaaaaaaaaaa",
      "aaaaaaaaaaabbbaa",
      "aaaaaabbbabbbbba",
      "aaaaabbbbbbbbbba",
      "aaaaabbbbbbbbbba",
      "aaaaabbbbbabbbaa",
      "aaaaaabbbaaaaaaa",
      "aaaaaaaaabaaaaaa",
      "aaaaaaaabbbaaaaa",
      "aaaaaaaaabaaaaaa",
      "aaaaaaaaaaaaaaaa",
      "aaaaaaaaaaaaaaaa",
      "aaaaaaaaaaaaaaaa"
    ],
    [
      "aaaaaaaaaaaaaaaa",
      "aaaaaaaaaaaaaaaa",
      "aaaaaaaaaaaaaaaa",
      "aaaaaaaaaaaaaaaa",
      "aaaaaaaaaaaaaaaa",
      "aaaaaabbbaaabaaa",
      "aaaaabbbbbabbbaa",
      "aaaaabbbbbaabaaa",
      "aaaaabbbbbaaaaaa",
      "aaaaaabbbaaaaaaa",
      "aaaaaaaaaaaaaaaa",
      "aaaaaaaaaaaaaaaa",
      "aaaaaaaaaaaaaaaa",
      "aaaaaaaaaaaaaaaa",
      "aaaaaaaaaaaaaaaa",
      "aaaaaaaaaaaaaaaa"
    ],
    [
      "aaaaaaaaaaaaaaaa",
      "aaaaaaaaaaaaaaaa",
      "aaaaaaaaaaaaaaaa",
      "aaaaaaaaaaaaaaaa",
      "aaaaaaaaaaaaaaaa",
      "aaaaaaaaaaaaaaaa",
      "aaaaaaabaaaaaaaa",
      "aaaaaabbbaaaaaaa",
      "aaaaaaabaaaaaaaa",
      "aaaaaaaaaaaaaaaa",
      "aaaaaaaaaaaaaaaa",
      "aaaaaaaaaaaaaaaa",
      "aaaaaaaaaaaaaaaa",
      "aaaaaaaaaaaaaaaa",
      "aaaaaaaaaaaaaaaa",
      "aaaaaaaaaaaaaaaa"
    ],
    [
      "aaaaaaaaaaaaaaaa",
      "aaaaaaaaaaaaaaaa",
      "aaaaaaaaaaaaaaaa",
      "aaaaaaaaaaaaaaaa",
      "aaaaaaaaaaaaaaaa",
      "aaaaaaaaaaaaaaaa",
      "aaaaaaaaaaaaaaaa",
      "aaaaaaaaaaaaaaaa",
      "aaaaaaaaaaaaaaaa",
      "aaaaaaaaaaaaaaaa",
      "aaaaaaaaaaaaaaaa",
      "aaaaaaaaaaaaaaaa",
      "aaaaaaaaaaaaaaaa",
      "aaaaaaaaaaaaaaaa",
      "aaaaaaaaaaaaaaaa",
      "aaaaaaaaaaaaaaaa"
    ]
  ]
}