{
  "name": "scattered_treehouse_1_floor2",
  "refpalette": "deceasedcraft:scattered_treehouse_1/scattered_treehouse_1_floor2_palette",
  "xsize": 16,
  "zsize": 16,
  "slices": [
    [
      "aaaaaaaaaaaaaaaa",
      "aaaaaaaaaaaaaaaa",
      "aaaaaaaaaaaaaaaa",
      "aaaaaaaaaaaaaaaa",
      "aaaaaaaaaaaaaaaa",
      "aaaaaaaaaaaaaaaa",
      "aaaaabaacdeeaaaa",
      "aaaaaaafdgccaaaa",
      "aaaaabahiiiiaaaa",
      "aaaaaaaabaaaaaaa",
      "aaaaaaaaaaaaaaaa",
      "aaaaaaaaaaaaaaaa",
      "aaaaaaaaaaaaaaaa",
      "aaaaaaaaaaaaaaaa",
      "aaaaaaaaaaaaaaaa",
      "aaaaaaaaaaaaaaaa"
    ],
    [
      "aaaaaaaaaaaaaaaa",
      "aaaaaaaaaaaaaaaa",
      "aaaaaaaaaaaaaaaa",
      "aaaaaaaaaaaaaaaa",
      "aaaaaaaaaaaaaaaa",
      "aaaaaaaaaajaaaaa",
      "aaaaeeeeajdjaaaa",
      "aaaaccgfkkkkaaaa",
      "aaaaiidhaaaaaaaa",
      "aaaaadaabaaaaaaa",
      "aaaaaaaaaaaaaaaa",
      "aaaaaaaaaaaaaaaa",
      "aaaaaaaaaaaaaaaa",
      "aaaaaaaaaaaaaaaa",
      "aaaaaaaaaaaaaaaa",
      "aaaaaaaaaaaaaaaa"
    ],
    [
      "aaaaaaaaaaaaaaaa",
      "aaaaaaaaaaaaaaaa",
      "aaaaaaaaaaaaaaaa",
      "aaaaaaaaaaaaaaaa",
      "aaaaaaaaajjjaaaa",
      "aaaaaaaaljjjjaaa",
      "aaaaaaaljjjjjaaa",
      "aaaakkkfjjjjjaaa",
      "aaaaaaahajjjaaaa",
      "aaaajaaabaaaaaaa",
      "aaajdjaaaaaaaaaa",
      "aaaajaaaaaaaaaaa",
      "aaaaaaaaaaaaaaaa",
      "aaaaaaaaaaaaaaaa",
      "aaaaaaaaaaaaaaaa",
      "aaaaaaaaaaaaaaaa"
    ],
    [
      "aaaaaaaaaaaaaaaa",
      "aaaaaaaaaaaaaaaa",
      "aaaaaaaaaaaaaaaa",
      "aaaaaaaajaaaaaaa",
      "aaaaaaajljjjaaaa",
      "aaaaaaaajjjjjaaa",
      "aaaaaaaamjjjjaaa",
      "aaaaaaafdjjjjaaa",
      "aaajjjahdjjjaaaa",
      "aajjjjjalaaaaaaa",
      "aajjjjjaaaaaaaaa",
      "aajjjjjaaaaaaaaa",
      "aaajjjaaaaaaaaaa",
      "aaaaaaaaaaaaaaaa",
      "aaaaaaaaaaaaaaaa",
      "aaaaaaaaaaaaaaaa"
    ],
    [
      "aaaaaaaaaaaaaaaa",
      "aaaaaaaaaaaaaaaa",
      "aaaaaaajjjaaaaaa",
      "aaaaaajjjjjaaaaa",
      "aaaaaajjjjjjaaaa",
      "aaaaaajjjjjjjaaa",
      "aaaaaaanojdjjaaa",
      "aaaaaaafpdjjjaaa",
      "aaajjjaqajjjaaaa",
      "aajjjjjaraaaaaaa",
      "aajjjjjaalaaaaaa",
      "aajjjjjajljaaaaa",
      "aaajjjaaajaaaaaa",
      "aaaaaaaaaaaaaaaa",
      "aaaaaaaaaaaaaaaa",
      "aaaaaaaaaaaaaaaa"
    ],
    [
      "aaaaaaaaaaaaaaaa",
      "aaaaaaaaaaaaaaaa",
      "aaaaaaajjjaaaaaa",
      "aaaaaajjjjjaaaaa",
      "aaaaaajjjjjaaaaa",
      "aaaaaajjjjjajaaa",
      "aaaaaaansjjddjaa",
      "aaaaaaafaajajaaa",
      "aaajjjaaasaaaaaa",
      "aajjjjjajjjaaaaa",
      "aajjjjjjjjjjaaaa",
      "aajjjjjjjjjjaaaa",
      "aaajjjajjjjjaaaa",
      "aaaaaaaajjjaaaaa",
      "aaaaaaaaaaaaaaaa",
      "aaaaaaaaaaaaaaaa"
    ]
  ]
}