{
  "name": "multi_filmworkstower_6_ground",
  "refpalette": "deceasedcraft:multi_filmworkstower_6/multi_filmworkstower_6_ground_palette",
  "xsize": 16,
  "zsize": 16,
  "slices": [
    [
      "aaaaaaaabccccddd",
      "aaaaaaaabddddddd",
      "aaaaaaaabddddddd",
      "aaaaaaaabddddddd",
      "aaaaaaaabddddddd",
      "aaaaaaaabccccddd",
      "aaaaaaaabcccccef",
      "aaaaaaaabbccccef",
      "aaaaaaaaabccccef",
      "aaaaaaaaabbbb ef",
      "aaaaaaaaag    ef",
      "aaaaaaaaahg   ef",
      "aaaaaaaaag    ef",
      "aaaaaaaaag    ef",
      "aaaaaaaaahg   ef",
      "aaaaaaaaag    ef"
    ],
    [
      "        i       ",
      "        i       ",
      "       jk       ",
      "       lk       ",
      "        i       ",
      "        i       ",
      "        mnnn    ",
      "      opppqnn  r",
      "         mg nn r",
      "         sbbbt r",
      "         ag    r",
      "         ahg   r",
      "         sg    r",
      "         ug    r",
      "         uhg   r",
      "         ug    r"
    ],
    [
      "        i       ",
      "        i       ",
      "       w        ",
      "       x        ",
      "        i       ",
      "        i       ",
      "        m       ",
      "     opppppq    ",
      "         ymg    ",
      "         ssbbbt ",
      "         Asg    ",
      "         Bshg   ",
      "         ssg    ",
      "          ug    ",
      "          uhg   ",
      "          ug    "
    ],
    [
      "        i       ",
      "        i       ",
      "       C        ",
      "       C        ",
      "        i       ",
      "        i       ",
      "        mD      ",
      "    opppppppq   ",
      "          ymg   ",
      "           sbbbt",
      "           ag   ",
      "           ahgE ",
      "           ag   ",
      "           sg   ",
      "           uhgE ",
      "           ug   "
    ],
    [
      "        i       ",
      "        i       ",
      "        i       ",
      "        i       ",
      "        i       ",
      "        i       ",
      "        mF      ",
      "   opppppppppq  ",
      "           ymg  ",
      "           ssbbb",
      "           Asg  ",
      "           Ishg ",
      "           Bsg  ",
      "           ssg  ",
      "            uhg ",
      "            ug  "
    ],
    [
      "        i       ",
      "        i       ",
      "        i       ",
      "        i       ",
      "        i       ",
      "        i       ",
      "        mJ      ",
      "  opppppppppppq ",
      "            ymg ",
      "             sbb",
      "             ag ",
      "             ahg",
      "             ag ",
      "             ag ",
      "             shg",
      "             ug "
    ]
  ]
}