{
  "name": "multi_filmworkstower_6_base3",
  "refpalette": "deceasedcraft:multi_filmworkstower_6/multi_filmworkstower_6_base3_palette",
  "xsize": 16,
  "zsize": 16,
  "slices": [
    [
      "aaaaaaaaaaaabbbb",
      "aaaaaaaaaaaabbbb",
      "aaaaaaaaaaaabbbb",
      "aaaaaaaaaaaabbbb",
      "aaaaaaaaaaaabbbb",
      "aaaaaaaaaaaabbbb",
      "aaaaaaaaaaaabbbb",
      "aaaaaaaaaaaabbbb",
      "aaaaaaaaaaaabbbb",
      "abbbbbaaaaaabbbb",
      "aaaaaaaaaaaabbbb",
      "aaaaaaaaaaaabbbb",
      "aaaaaaaaaaaabbbb",
      "aaaaaaaaaaaabbbb",
      "aaaaaaaaaaaabbbb",
      "aaaaaaaaaaaabbbb"
    ],
    [
      "aaaaaaaaaaaabcdd",
      "aaaaaaaaaaaabcdd",
      "aaaaaaaaaaaabcdd",
      "aaaaaaaaaaaabcdd",
      "aaaaaaaaaaaabcdd",
      "aaaaaaaaaaaabcdd",
      "aaaaaaaaaaaabcdd",
      "aaaaaaaaaaaabcdd",
      "aaaaaaaaaaaabcdd",
      "abbbbbaaaaaabcdd",
      "aaaaaaaaaaaabcee",
      "aaaaaaaaaaaabcff",
      "aaaaaaaaaaaabcgd",
      "aaaaaaaaaaaabcdd",
      "aaaaaaaaaaaabcdd",
      "aaaaaaaaaaaabcdd"
    ],
    [
      "aaaaaaaaaaaabcdd",
      "aaaaaaaaaaaabcdd",
      "aaaaaaaaaaaabcdh",
      "aaaaaaaaaaaabcdh",
      "aaaaaaaaaaaabcdd",
      "aaaaaaaaaaaabcdd",
      "aaaaaaaaaaaabch ",
      "aaaaaaaaaaaabchd",
      "aaaaaaaaaaaabcdd",
      "abbbbbaaaaaabcdd",
      "aaaaaaaaaaaabc  ",
      "aaaaaaaaaaaabc  ",
      "aaaaaaaaaaaabcid",
      "aaaaaaaaaaaabcdj",
      "aaaaaaaaaaaabcdj",
      "aaaaaaaaaaaabcdj"
    ],
    [
      "aaaaaaaaaaaabcjj",
      "aaaaaaaaaaaabck ",
      "aaaaaaaaaaaabcl ",
      "aaaaaaaaaaaabc m",
      "aaaaaaaaaaaabc i",
      "aaaaaaaaaaaabc d",
      "aaaaaaaaaaaabcdn",
      "aaaaaaaaaaaabop ",
      "aaaaaaaaaaaabop ",
      "abbbbbaaaaaabch ",
      "aaaaaaaaaaaabc  ",
      "aaaaaaaaaaaabc  ",
      "aaaaaaaaaaaabcid",
      "aaaaaaaaaaaabcdq",
      "aaaaaaaaaaaabcdr",
      "aaaaaaaaaaaabcd "
    ],
    [
      "aaaaaaaaaaaabjsj",
      "aaaaaaaaaaaabc  ",
      "aaaaaaaaaaaabct ",
      "aaaaaaaaaaaabc m",
      "aaaaaaaaaaaabc i",
      "aaaaaaaaaaaabc d",
      "aaaaaaaaaaaabcdu",
      "aaaaaaaaaaaabw  ",
      "aaaaaaaaaaaabw  ",
      "abbbbbaaaaaabdx ",
      "aaaaaaaaaaaabc  ",
      "aaaaaaaaaaaabc  ",
      "aaaaaaaaaaaabciy",
      "aaaaaaaaaaaabcd ",
      "aaaaaaaaaaaabcs ",
      "aaaaaaaaaaaabcd "
    ],
    [
      "aaaaaaaaaaaabcjj",
      "aaaaaaaaaaaabc  ",
      "aaaaaaaaaaaabc  ",
      "aaaaaaaaaaaabc m",
      "aaaaaaaaaaaabc i",
      "aaaaaaaaaaaabc d",
      "aaaaaaaaaaaabcdA",
      "aaaaaaaaaaaabcd ",
      "aaaaaaaaaaaabcd ",
      "abbbbbaaaaaabcd ",
      "aaaaaaaaaaaabc  ",
      "aaaaaaaaaaaabc  ",
      "aaaaaaaaaaaabcih",
      "aaaaaaaaaaaabcd ",
      "aaaaaaaaaaaabch ",
      "aaaaaaaaaaaabch "
    ]
  ]
}