{
  "name": "multi_filmworkstower_6_floor3",
  "refpalette": "deceasedcraft:multi_filmworkstower_6/multi_filmworkstower_6_floor3_palette",
  "xsize": 16,
  "zsize": 16,
  "slices": [
    [
      "                ",
      "                ",
      "                ",
      "                ",
      "                ",
      "                ",
      "      aaaaaaaaaa",
      "      a         ",
      "      b         ",
      "      c         ",
      "     de         ",
      "    dfe         ",
      "     de         ",
      "     de         ",
      "    dfe         ",
      "     de         "
    ],
    [
      "                ",
      "                ",
      "                ",
      "                ",
      "                ",
      "                ",
      "       aaaaaaaaa",
      "       aa       ",
      "       bb       ",
      "       cc     gh",
      "      dij       ",
      "     dfij       ",
      "      dij       ",
      "      dij       ",
      "     dfij       ",
      "      dij       "
    ],
    [
      "                ",
      "                ",
      "                ",
      "                ",
      "                ",
      "                ",
      "         aaaaaaa",
      "         aaaaaaa",
      "         bbbbbbb",
      "         cccc cc",
      "       kfijjjjjj",
      "      dffijjjjjj",
      "       kfijjjjjj",
      "       kfijjjjjj",
      "      dffijjjjjj",
      "       kfijjjjjj"
    ],
    [
      "                ",
      "                ",
      "                ",
      "                ",
      "                ",
      "                ",
      "                ",
      "                ",
      "                ",
      "                ",
      "         kkkkkkk",
      "       kffffffff",
      "         kkkkkkk",
      "         kkkkkkk",
      "       kffffffff",
      "         kkkkkkk"
    ],
    [
      "                ",
      "                ",
      "                ",
      "                ",
      "                ",
      "                ",
      "                ",
      "                ",
      "                ",
      "                ",
      "                ",
      "                ",
      "                ",
      "                ",
      "                ",
      "                "
    ],
    [
      "                ",
      "                ",
      "                ",
      "                ",
      "                ",
      "                ",
      "                ",
      "                ",
      "                ",
      "                ",
      "                ",
      "                ",
      "                ",
      "                ",
      "                ",
      "                "
    ]
  ]
}