{
  "name": "multi_filmworkstower_6_floor2",
  "refpalette": "deceasedcraft:multi_filmworkstower_6/multi_filmworkstower_6_floor2_palette",
  "xsize": 16,
  "zsize": 16,
  "slices": [
    [
      "                ",
      "                ",
      "                ",
      "                ",
      "                ",
      "                ",
      "aaaaaaaaaaaaaaaa",
      "abbbbbbbbbbbbbbb",
      "cddddddddddddddd",
      "e               ",
      "f               ",
      "f               ",
      "f               ",
      "f               ",
      "f               ",
      "f               "
    ],
    [
      "                ",
      "                ",
      "                ",
      "                ",
      "                ",
      "                ",
      " aaaaaaaaaaaaaaa",
      " agggggggggggggg",
      " chhhhhhhhhhhhhh",
      " e              ",
      "if              ",
      "jf              ",
      "if              ",
      "if              ",
      "jf              ",
      "if              "
    ],
    [
      "                ",
      "                ",
      "                ",
      "                ",
      "                ",
      "                ",
      "  aaaaaaaaaaaaaa",
      "  akkkkkkkkkkkkk",
      "  c             ",
      "  e             ",
      " if             ",
      "ijf             ",
      " if             ",
      " if             ",
      "ijf             ",
      " if             "
    ],
    [
      "                ",
      "                ",
      "                ",
      "                ",
      "                ",
      "                ",
      "   aaaaaaaaaaaaa",
      "   akkkkkkkkkkkk",
      "   c            ",
      "   e            ",
      "  if            ",
      " ijf            ",
      "  if            ",
      "  if            ",
      " ijf            ",
      "  if            "
    ],
    [
      "                ",
      "                ",
      "                ",
      "                ",
      "                ",
      "                ",
      "    aaaaaaaaaaaa",
      "    a kk kkkk kk",
      "    c           ",
      "    e           ",
      "   if           ",
      "  ijf           ",
      "   if           ",
      "   if           ",
      "  ijf           ",
      "   if           "
    ],
    [
      "                ",
      "                ",
      "                ",
      "                ",
      "                ",
      "                ",
      "     aaaaaaaaaaa",
      "     a    kkk kk",
      "     c          ",
      "     e          ",
      "    if          ",
      "   ijf          ",
      "    if          ",
      "    if          ",
      "   ijf          ",
      "    if          "
    ]
  ]
}