{
  "name": "multi_filmworkstower_6_base1",
  "refpalette": "deceasedcraft:multi_filmworkstower_6/multi_filmworkstower_6_base1_palette",
  "xsize": 16,
  "zsize": 16,
  "slices": [
    [
      "   a         b  ",
      "   a         b  ",
      "   a         b  ",
      "   a         b  ",
      "   a         b  ",
      "   a         b  ",
      "   a         b  ",
      "   a         b  ",
      "   a         b  ",
      "ccccccccc   db  ",
      "   a         b  ",
      "   a         b  ",
      "   a         b  ",
      "   a         b  ",
      "   a         b  ",
      "   a         b  "
    ],
    [
      "   a         b  ",
      "   a         b  ",
      "   a         b  ",
      "   a         b  ",
      "   a         b  ",
      "   a         b  ",
      "   a         b  ",
      "   a         b  ",
      "   a        eb  ",
      "cccccccccf gdb  ",
      "   a        hb  ",
      "   a         b  ",
      "   a         b  ",
      "   a         b  ",
      "   a         b  ",
      "   a         b  "
    ],
    [
      "   a        ib  ",
      "   a        ib  ",
      "   a        ib  ",
      "   a        ib  ",
      "   a        ib  ",
      "   a        ib  ",
      "   a        ib  ",
      "   a        ib  ",
      "   a        ib  ",
      "ccccccccccjjdb  ",
      "   a        ib  ",
      "   a        ib  ",
      "   a        ib  ",
      "   a        ib  ",
      "   a        ib  ",
      "   a        ib  "
    ],
    [
      "   a            ",
      "   a            ",
      "   a            ",
      "   a            ",
      "   a            ",
      "   a            ",
      "   a            ",
      "   a            ",
      "   a            ",
      "ccccccccccfkdl  ",
      "   a            ",
      "   a            ",
      "   a            ",
      "   a            ",
      "   a            ",
      "   a            "
    ],
    [
      "mmmnoooooooopoqr",
      "mmmnoooooooopoqr",
      "mmmnoooooooopoqr",
      "mmmnoooooooopoqr",
      "mmmnoooooooopoqr",
      "mmmnoooooooopoqr",
      "mmmnoooooooopoqr",
      "mmmnoooooooopoqr",
      "mmmnoooooooopoqr",
      "cccccccccccosoqr",
      "mmmnoooooooopoqr",
      "mmmnoooooooopoqr",
      "mmmnoooooooopoqr",
      "mmmnoooooooopoqr",
      "mmmnoooooooopoqr",
      "mmmnoooooooopoqr"
    ],
    [
      "cccccccccccccccc",
      "cccccccccccccccc",
      "cccccccccccccccc",
      "cccccccccccccccc",
      "cccccccccccccccc",
      "cccccccccccccccc",
      "cccccccccccccccc",
      "cccccccccccccccc",
      "cccccccccccccccc",
      "ccccccccccccc cc",
      "cccccccccccccccc",
      "cccccccccccccccc",
      "cccccccccccccccc",
      "cccccccccccccccc",
      "cccccccccccccccc",
      "cccccccccccccccc"
    ]
  ]
}