{
  "name": "multi_filmworkstower_6_floor1",
  "refpalette": "deceasedcraft:multi_filmworkstower_6/multi_filmworkstower_6_floor1_palette",
  "xsize": 16,
  "zsize": 16,
  "slices": [
    [
      "        a       ",
      "        a       ",
      "        a       ",
      "        a       ",
      "        a       ",
      "        a       ",
      "        b       ",
      " cddddddddddddde",
      "             fbg",
      "             hhi",
      "             jhg",
      "             khl",
      "             khg",
      "             mhg",
      "             hhl",
      "              ng"
    ],
    [
      "ooopooooboooopoo",
      "ooopooooboooopoo",
      "ooopooooboooopoo",
      "ooopooooboooopoo",
      "ooopooooboooopoo",
      "ooopooooboooopoo",
      "ooopooooboooopoo",
      "dddddddddddddddd",
      "              fb",
      "               h",
      "               q",
      "               q",
      "               q",
      "               q",
      "               q",
      "               h"
    ],
    [
      "rrrrrrrrrrrrrrrr",
      "rrrrrrrrrrrrrrrr",
      "rrrrrrrrrrrrrrrr",
      "rrrrrrrrrrrrrrrr",
      "rrrrrrrrrrrrrrrr",
      "rrrrrrrrrrrrrrrr",
      "rrrrrrrrrrrrrrrr",
      "                ",
      "llllllllllllllll",
      "               h",
      "               j",
      "               k",
      "               k",
      "               k",
      "               m",
      "               h"
    ],
    [
      "                ",
      "                ",
      "                ",
      "                ",
      "                ",
      "                ",
      "                ",
      "                ",
      "llllllllllllllll",
      "                ",
      "                ",
      "                ",
      "                ",
      "                ",
      "                ",
      "                "
    ],
    [
      "                ",
      "                ",
      "                ",
      "                ",
      "                ",
      "                ",
      "                ",
      "s               ",
      "llllllllllllllll",
      "                ",
      "                ",
      "                ",
      "                ",
      "                ",
      "                ",
      "                "
    ],
    [
      "                ",
      "                ",
      "                ",
      "                ",
      "                ",
      "                ",
      "                ",
      "ssssssssssssssss",
      "llllllllllllllll",
      "                ",
      "                ",
      "                ",
      "                ",
      "                ",
      "                ",
      "                "
    ]
  ]
}