{
  "name": "multi_filmworkstower_6_base2",
  "refpalette": "deceasedcraft:multi_filmworkstower_6/multi_filmworkstower_6_base2_palette",
  "xsize": 16,
  "zsize": 16,
  "slices": [
    [
      "aaaaaaaaaaaaabcc",
      "aaaaaaaaaaaaabdd",
      "aaaaaaaaaaaaabdd",
      "aaaaaaaaaaaaabde",
      "aaaaaaaaaaaaabdd",
      "aaaaaaaaaaaaabfd",
      "aaaaaaaaaaaaabdg",
      "aaaaaaaaaaaaabff",
      "aaaaaaaaaaaaabdd",
      "hhhhhhaaaaaaabfd",
      "aaaaaaaaaaaaab  ",
      "aaaaaaaaaaaaabii",
      "aaaaaaaaaaaaabjk",
      "aaaaaaaaaaaaabl ",
      "aaaaaaaaaaaaabl ",
      "aaaaaaaaaaaaabl "
    ],
    [
      "             bkk",
      "             b  ",
      "             b  ",
      "m            bno",
      "             bpp",
      "             b q",
      "             brs",
      "             b t",
      "uw           b  ",
      "hhhhhhx    yAbBB",
      "CDEF         b  ",
      "   F         b  ",
      "   F         bii",
      "   F         bdk",
      "   F         bd ",
      "   F         bdI"
    ],
    [
      "   F         bii",
      "   F         b  ",
      "   F         b  ",
      "   F         bpp",
      "   F         b  ",
      "   F         b  ",
      "   F         b  ",
      "   F         b  ",
      "   F         b  ",
      "hhhhhhh     Ab  ",
      "JKLM         b  ",
      "   M         b  ",
      "   M         b  ",
      "   M         bii",
      "   M         bkI",
      "   M         bpN"
    ],
    [
      "   M         b  ",
      "   M         bii",
      "   M         bpp",
      "   M         b  ",
      "   M         b  ",
      "   M         b  ",
      "   M         b  ",
      "   M         b  ",
      "   M        Ob  ",
      "hhhhhhhx    Ab  ",
      "   M        Pb  ",
      "   M         b  ",
      "   M         b  ",
      "   M         b  ",
      "   M         b Q",
      "   M         b  "
    ],
    [
      "   M        Rb  ",
      "   M        Rb  ",
      "   M        Rb  ",
      "   M        Rb  ",
      "   M        Rb  ",
      "   M        Rb  ",
      "   M        Rb  ",
      "   M        Rb  ",
      "   M        Rb  ",
      "hhhhhhhh   SAb  ",
      "   M        Rb  ",
      "   M        Rb  ",
      "   M        Rb  ",
      "   M        Rb  ",
      "   M        Rb  ",
      "   M        Rb  "
    ],
    [
      "   M         b  ",
      "   M         b  ",
      "   M         b  ",
      "   M         b  ",
      "   M         b  ",
      "   M         b  ",
      "   M         b  ",
      "   M         b  ",
      "   M         b  ",
      "hhhhhhhhx   Ab  ",
      "   M         b  ",
      "   M         b  ",
      "   M         b  ",
      "   M         b  ",
      "   M         b  ",
      "   M         b  "
    ]
  ]
}