{
  "name": "multi_casino_8_base7",
  "refpalette": "deceasedcraft:multi_casino_8/multi_casino_8_base7_palette",
  "xsize": 16,
  "zsize": 16,
  "slices": [
    [
      "vvvvvvvvvvvvvvvv",
      "aaaaaaaaaaaaaaaa",
      "bbbbbbbbbbbbbbbb",
      "c ccdc  c  cdcc ",
      "                ",
      "                ",
      "                ",
      "        e       ",
      "                ",
      "                ",
      "                ",
      "                ",
      "                ",
      "                ",
      "                ",
      "                "
    ],
    [
      "vvvvvvvvvvvvvvvv",
      "aaaaaaaaaaaaaaaa",
      "bbbbbbbbbbbbbbbb",
      "c  cd      cdc  ",
      "                ",
      "                ",
      "                ",
      "        e       ",
      "                ",
      "                ",
      "                ",
      "                ",
      "                ",
      "                ",
      "                ",
      "                "
    ],
    [
      "vvvvvvvvvvvvvvvv",
      "aaaaaaaaaaaaaaaa",
      "bbbbbbbbbbbbbbbb",
      "    d       d   ",
      "                ",
      "                ",
      "                ",
      "        e       ",
      "                ",
      "                ",
      "                ",
      "                ",
      "                ",
      "                ",
      "                ",
      "                "
    ],
    [
      "vvvvvvvvvvvvvvvv",
      "aaaaaaaaaaaaaaaa",
      "bbbbbbbbbbbbbbbb",
      "    d       d   ",
      "                ",
      "                ",
      "                ",
      "        e       ",
      "                ",
      "                ",
      "                ",
      "                ",
      "                ",
      "                ",
      "                ",
      "                "
    ],
    [
      "vvvvvvvvvvvvvvvv",
      "aaaaaaaaaaaaaaaa",
      "bbbbbbbbbbbbbbbb",
      "    d       d   ",
      "fffffgfffffgffff",
      "ffffffgfffgfffff",
      "fffffffgfgffffff",
      "hfffhfffefffhfff",
      "fffffffgfgffffff",
      "ffffffgfffgfffff",
      "fffffgfffffgffff",
      "hfffhfffhfffhfff",
      "fffgfffffffffgff",
      "ffgfffffffffffgf",
      "fgfffffffffffffg",
      "hfffff     fffff"
    ],
    [
      "vvvvvvvvvvvvvvvv",
      "aaaaaaaaaaaaaaaa",
      "bbbbbbbbbbbbbbbb",
      "iiiidiiiiiiidiii",
      "jjjjkejjjjjekjjj",
      "kkkkkkekkkekkkkk",
      "kkkkkkkekekkkkkk",
      "lkkklkkkekkklkkk",
      "kkkkkkkekekkkkkk",
      "kkkkkkekkkekkkkk",
      "kkkkkekkkkkekkkk",
      "lkkkekkklkkkekkk",
      "kkkekkkkkkkkkekk",
      "kkekkkkkkkkkkkek",
      "kekkkkkkkkkkkkke",
      "ekkkkkmmmmmkkkkk"
    ]
  ]
}