{
  "name": "multi_casino_8_base6",
  "refpalette": "deceasedcraft:multi_casino_8/multi_casino_8_base6_palette",
  "xsize": 16,
  "zsize": 16,
  "slices": [
    [
      "vvvvvvvvvvvvvvvv",
      "aaaaaaaaaaaaaaaa",
      "bbbbbbbbbbbbbbbb",
      "ccccdcccccccdccc",
      "eeeeeeeeeeeeeeee",
      "ffffffffffffffff",
      "gggggggggggggggg",
      "gggggggghggggggg",
      "gggggggggggggggg",
      "gggggggggggggggg",
      "gggggggggggggggg",
      "gggggggggggggggg",
      "gggggggggggggggg",
      "gggggggggggggggg",
      "gggggggggggggggg",
      "ggggggfffffggggg"
    ],
    [
      "vvvvvvvvvvvvvvvv",
      "aaaaaaaaaaaaaaaa",
      "bbbbbbbbbbbbbbbb",
      "iiiidiiiiiiidiii",
      "    j       j   ",
      "                ",
      "                ",
      "        h k klmm",
      "nnnn    o p p qr",
      "stuswww   x x y ",
      "ssssw!w         ",
      "sutswww  ApB  k ",
      "nnnn         ApB",
      "              x ",
      "                ",
      "      CCCCC     "
    ],
    [
      "vvvvvvvvvvvvvvvv",
      "aaaaaaaaaaaaaaaa",
      "bbbbbbbbbbbbbbbb",
      "iiiidiiiiiiidiii",
      "                ",
      "                ",
      "                ",
      "        h    D E",
      "          F I   ",
      "    J           ",
      "     K          ",
      "    L           ",
      "                ",
      "                ",
      "                ",
      "                "
    ],
    [
      "vvvvvvvvvvvvvvvv",
      "aaaaaaaaaaaaaaaa",
      "bbbbbbbbbbbbbbbb",
      "iiiidiiiiiiidiii",
      "                ",
      "                ",
      "                ",
      "        h    MNO",
      "                ",
      "                ",
      "                ",
      "                ",
      "                ",
      "                ",
      "                ",
      "                "
    ],
    [
      "vvvvvvvvvvvvvvvv",
      "aaaaaaaaaaaaaaaa",
      "bbbbbbbbbbbbbbbb",
      "iiiidiiiiiiidiii",
      "                ",
      "                ",
      "                ",
      "        h     P ",
      "                ",
      "                ",
      "                ",
      "                ",
      "                ",
      "                ",
      "                ",
      "                "
    ],
    [
      "vvvvvvvvvvvvvvvv",
      "aaaaaaaaaaaaaaaa",
      "bbbbbbbbbbbbbbbb",
      "iiiidii ii idiii",
      "                ",
      "                ",
      "                ",
      "        h     P ",
      "                ",
      "                ",
      "                ",
      "                ",
      "                ",
      "                ",
      "                ",
      "                "
    ]
  ]
}