{
  "name": "multi_casino_8_ground",
  "refpalette": "deceasedcraft:multi_casino_8/multi_casino_8_ground_palette",
  "xsize": 16,
  "zsize": 16,
  "slices": [
    [
      "HHHHHHHHHHHHHHHH",
      "HHHHHHHHHHHHHHHH",
      "HHHHHHHHHHHHHHHH",
      "aaaaaaaaaaaaaaaa",
      "bbbbbbbbbbbbbbbb",
      "bcccccccdccccccc",
      "bcccccccdccccccc",
      "bdddddddeddddddd",
      "bcccccccdccccccc",
      "bcccccccdccccccc",
      "bcccccccdccccccc",
      "bcccccccdccccccc",
      "bcccccccdccccccc",
      "bcccccccdccccccc",
      "bcccccccdccccccc",
      "bdddddddfddddddd"
    ],
    [
      "                ",
      "                ",
      "                ",
      "                ",
      "gggggggggggggggg",
      "ghhhhhhhhhhhhhhh",
      "gh              ",
      "gi      j       ",
      "gh              ",
      "gh      ~       ",
      "gh      ~       ",
      "gi              ",
      "gh              ",
      "gh              ",
      "gh              ",
      "gi              "
    ],
    [
      "                ",
      "                ",
      "                ",
      "                ",
      "                ",
      "                ",
      "                ",
      " k      l       ",
      "                ",
      "        ~       ",
      "                ",
      " k              ",
      "                ",
      "                ",
      "                ",
      " k              "
    ],
    [
      "                ",
      "                ",
      "                ",
      "                ",
      "                ",
      "                ",
      "                ",
      "        h       ",
      "                ",
      "        ~       ",
      "                ",
      "                ",
      "                ",
      "                ",
      "                ",
      "                "
    ],
    [
      "                ",
      "                ",
      "                ",
      "                ",
      "                ",
      "                ",
      "                ",
      "        m       ",
      "                ",
      "        ~       ",
      "                ",
      "                ",
      "                ",
      "                ",
      "                ",
      "                "
    ],
    [
      "                ",
      "                ",
      "                ",
      "                ",
      "                ",
      "                ",
      "                ",
      "        m       ",
      "                ",
      "        ~       ",
      "                ",
      "                ",
      "                ",
      "                ",
      "                ",
      "                "
    ]
  ]
}