{
  "name": "multi_casino_8_base3",
  "refpalette": "deceasedcraft:multi_casino_8/multi_casino_8_base3_palette",
  "xsize": 16,
  "zsize": 16,
  "slices": [
    [
      "vvvvvvvvvvvvvvvv",
      "aaaaaaaaaaaaaaaa",
      "bbbbbbbbbbbbbbbb",
      "c ccdc  c  cdcc ",
      "                ",
      "                ",
      "                ",
      "        e       ",
      "                ",
      "                ",
      "                ",
      "                ",
      "                ",
      "                ",
      "                ",
      "                "
    ],
    [
      "vvvvvvvvvvvvvvvv",
      "aaaaaaaaaaaaaaaa",
      "bbbbbbbbbbbbbbbb",
      "c  cd      cdc  ",
      "                ",
      "                ",
      "                ",
      "        e       ",
      "                ",
      "                ",
      "                ",
      "                ",
      "                ",
      "                ",
      "                ",
      "                "
    ],
    [
      "vvvvvvvvvvvvvvvv",
      "aaaaaaaaaaaaaaaa",
      "bbbbbbbbbbbbbbbb",
      "    d       d   ",
      "                ",
      "                ",
      "                ",
      "       feg      ",
      "        h       ",
      "                ",
      "                ",
      "                ",
      "                ",
      "                ",
      "                ",
      "                "
    ],
    [
      "vvvvvvvvvvvvvvvv",
      "aaaaaaaaaaaaaaaa",
      "bbbbbbbbbbbbbbbb",
      "    d       d   ",
      "                ",
      "                ",
      "                ",
      "        e       ",
      "                ",
      "                ",
      "                ",
      "                ",
      "                ",
      "                ",
      "                ",
      "                "
    ],
    [
      "vvvvvvvvvvvvvvvv",
      "aaaaaaaaaaaaaaaa",
      "bbbbbbbbbbbbbbbb",
      "    d       d   ",
      "iiiiijiiiiijiiii",
      "iiiiiijiiijiiiii",
      "iiiiiiijijiiiiii",
      "kiiikiiieiiikiii",
      "iiiiiiijijiiiiii",
      "iiiiiijiiijiiiii",
      "iiiiijiiiiijiiii",
      "kiiikiiikiiikiii",
      "iiijiiiiiiiiijii",
      "iijiiiiiiiiiiiji",
      "ijiiiiiiiiiiiiij",
      "kiiiii     iiiii"
    ],
    [
      "vvvvvvvvvvvvvvvv",
      "aaaaaaaaaaaaaaaa",
      "bbbbbbbbbbbbbbbb",
      "lllldllllllldlll",
      "mmmmnemmmmmenmmm",
      "nnnnnnennnennnnn",
      "nnnnnnnenennnnnn",
      "onnnonnnennnonnn",
      "nnnnnnnenennnnnn",
      "nnnnnnennnennnnn",
      "nnnnnennnnnennnn",
      "onnnennnonnnennn",
      "nnnennnnnnnnnenn",
      "nnennnnnnnnnnnen",
      "nennnnnnnnnnnnne",
      "ennnnnpppppnnnnn"
    ]
  ]
}