{
  "name": "multi_casino_8_base5",
  "refpalette": "deceasedcraft:multi_casino_8/multi_casino_8_base5_palette",
  "xsize": 16,
  "zsize": 16,
  "slices": [
    [
      "vvvvvvvvvvvvvvvv",
      "aaaaaaaaaaaaaaaa",
      "bbbbbbbbbbbbbbbb",
      "c ccdc  c  cdcc ",
      "                ",
      "                ",
      "                ",
      "        e     f ",
      "                ",
      "                ",
      "                ",
      "                ",
      "                ",
      "                ",
      "                ",
      "                "
    ],
    [
      "vvvvvvvvvvvvvvvv",
      "aaaaaaaaaaaaaaaa",
      "bbbbbbbbbbbbbbbb",
      "c  cd      cdc  ",
      "                ",
      "                ",
      "                ",
      "        e     f ",
      "                ",
      "                ",
      "                ",
      "                ",
      "                ",
      "                ",
      "                ",
      "                "
    ],
    [
      "vvvvvvvvvvvvvvvv",
      "aaaaaaaaaaaaaaaa",
      "bbbbbbbbbbbbbbbb",
      "    d       d   ",
      "                ",
      "                ",
      "                ",
      "       geh    i ",
      "        j       ",
      "                ",
      "                ",
      "                ",
      "                ",
      "                ",
      "                ",
      "                "
    ],
    [
      "vvvvvvvvvvvvvvvv",
      "aaaaaaaaaaaaaaaa",
      "bbbbbbbbbbbbbbbb",
      "    d       d   ",
      "                ",
      "                ",
      "                ",
      "        e     k ",
      "                ",
      "                ",
      "                ",
      "                ",
      "                ",
      "                ",
      "                ",
      "                "
    ],
    [
      "vvvvvvvvvvvvvvvv",
      "aaaaaaaaaaaaaaaa",
      "bbbbbbbbbbbbbbbb",
      "    d       d   ",
      "lllllmlllllmllll",
      "llllllmlllmlllll",
      "lllllllmlmllllll",
      "nlllnlllelllnlol",
      "lllllllmlmllllll",
      "llllllmlllmlllll",
      "lllllmlllllmllll",
      "nlllnlllnlllnlll",
      "lllmlllllllllmll",
      "llmlllllllllllml",
      "lmlllllllllllllm",
      "nlllll     lllll"
    ],
    [
      "vvvvvvvvvvvvvvvv",
      "aaaaaaaaaaaaaaaa",
      "bbbbbbbbbbbbbbbb",
      "ppppdpppppppdppp",
      "qqqqreqqqqqerqqq",
      "rrrrrrerrrerrrrr",
      "rrrrrrrererrrrrr",
      "srrrsrrrerrrsrrr",
      "rrrrrrrererrrrrr",
      "rrrrrrerrrerrrrr",
      "rrrrrerrrrrerrrr",
      "srrrerrrsrrrerrr",
      "rrrerrrrrrrrrerr",
      "rrerrrrrrrrrrrer",
      "rerrrrrrrrrrrrre",
      "errrrrtttttrrrrr"
    ]
  ]
}