{
  "name": "multi_nuclearpowerplant_47_base2",
  "refpalette": "deceasedcraft:multi_nuclearpowerplant_47/multi_nuclearpowerplant_47_base2_palette",
  "xsize": 16,
  "zsize": 16,
  "slices": [
    [
      "          a=bccv",
      "          a=bccv",
      "          a=bccv",
      "          a=bccv",
      "          a=bccv",
      "          a=bccv",
      "          a=bccv",
      "          a=bccv",
      "          a=bccv",
      "          a=bccv",
      "          a=bccv",
      "          a=bccv",
      "         da=bccv",
      "          a=bccv",
      "          a=bccv",
      "          a=bccv"
    ],
    [
      "          a=bccv",
      "          a=bccv",
      "          a=bccv",
      "          a=bccv",
      "          a=bccv",
      "          a=bccv",
      "          a=bccv",
      "          a=bccv",
      "e         a=bccv",
      "fg        a=bccv",
      "h         a=bccv",
      "i  g      a=bccv",
      "jjjjjjkllla=bccv",
      "f  g      a=bccv",
      "h         a=bccv",
      "hg        a=bccv"
    ],
    [
      "          a=bccv",
      "          a=bccv",
      "          a=bccv",
      "          a=bccv",
      "          a=bccv",
      "          a=bccv",
      "          a=bccv",
      "m         a=bccv",
      "lm        a=bccv",
      " ln       a=bccv",
      "  ln      a=bccv",
      "m  ln     a=bccv",
      "llllllloppa=bccv",
      "q  lr     a=bccv",
      "  lq      a=bccv",
      " lr       a=bccv"
    ],
    [
      "         sa=bccv",
      "         sa=bccv",
      "         sa=bccv",
      "         sa=bccv",
      "         sa=bccv",
      "         sa=bccv",
      "         sa=bccv",
      "         sa=bccv",
      "         sa=bccv",
      "         sa=bccv",
      "         sa=bccv",
      "         sa=bccv",
      "     tl  sa=bccv",
      "         sa=bccv",
      "         sa=bccv",
      "         sa=bccv"
    ],
    [
      "        ua=wbccv",
      "        ua=wbccv",
      "        ua=wbccv",
      "        ua=wbccv",
      "        ua=wbccv",
      "        ua=wbccv",
      "        ua=wbccv",
      "        ua=wbccv",
      "        ua=wbccv",
      "        ua=wbccv",
      "        ua=wbccv",
      "        ua=wbccv",
      "      l ua=wbccv",
      "        ua=wbccv",
      "        ua=wbccv",
      "        ua=wbccv"
    ],
    [
      "aaaaaaaaa=wwbccv",
      "aaaaaaaaa=wwbccv",
      "aaaaaaaaa=wwbccv",
      "aaaaaaaaa=wwbccv",
      "aaaaaaaaa=wwbccv",
      "aaaaaaaaa=wwbccv",
      "aaaaaaaaa=wwbccv",
      "aaaaaaaaa=wwbccv",
      "aaaaaaaaa=wwbccv",
      "aaaaaaaaa=wwbccv",
      "aaaaaaaaa=wwbccv",
      "aaaaaaaaa=wwbccv",
      "aaaaaaaaa=wwbccv",
      "aaaaaaaaa=wwbccv",
      "aaaaaaaaa=wwbccv",
      "aaaaaaaaa=wwbccv"
    ]
  ]
}