{
  "name": "multi_nuclearpowerplant_47_base4",
  "refpalette": "deceasedcraft:multi_nuclearpowerplant_47/multi_nuclearpowerplant_47_base4_palette",
  "xsize": 16,
  "zsize": 16,
  "slices": [
    [
      "abaaac    d=effv",
      "abaaac    d=effv",
      "abaaac    d=effv",
      "abaaac    d=effv",
      "abaaac    d=effv",
      "abaaac    d=effv",
      "abbbac    d=effv",
      "aaabac    d=effv",
      "gaabac    d=effv",
      "haabac    d=effv",
      "hbbbac    d=effv",
      "haaaac    d=effv",
      "haaaac    d=effv",
      "haaaac    d=effv",
      "haaaac    d=effv",
      "haaacc    d=effv"
    ],
    [
      "aaaaac    d=effv",
      "aaaaac    d=effv",
      "aaaaac    d=effv",
      "aaaaac    d=effv",
      "aaaaac    d=effv",
      "aaaaac    d=effv",
      "aaaaac    d=effv",
      "aaaaac    d=effv",
      "gaaaac    d=effv",
      "gaaaac    d=effv",
      "gaaaac    d=effv",
      "gaaaac    d=effv",
      "gaaaac    d=effv",
      "gaaaac    d=effv",
      "gaaaac    d=effv",
      "gaaacc    d=effv"
    ],
    [
      "aaaaac    d=effv",
      "aaaaac    d=effv",
      "aaaaac    d=effv",
      "aaaaac    d=effv",
      "aaaaac    d=effv",
      "aaaaac    d=effv",
      "aaaaac    d=effv",
      "aaaaac    d=effv",
      "aaaaac    d=effv",
      "aaaaac    d=effv",
      "aaaaac    d=effv",
      "aaaaac    d=effv",
      "aaaaac    d=effv",
      "aaaaac    d=effv",
      "aaaaac    d=effv",
      "aaaacc    d=effv"
    ],
    [
      "aaaaac    d=effv",
      "aaaaac    d=effv",
      "aaaaac    d=effv",
      "aaaaac    d=effv",
      "aaaaac    d=effv",
      "aaaaac    d=effv",
      "aaaaac    d=effv",
      "aaaaac    d=effv",
      "aaaaac    d=effv",
      "aaaaac    d=effv",
      "aaaaac    d=effv",
      "aaaaac    d=effv",
      "aaaaac    d=effv",
      "aaaaac    d=effv",
      "aaaaac    d=effv",
      "aaaacc    d=effv"
    ],
    [
      "     c    d=effv",
      "     c    d=effv",
      "     c    d=effv",
      "     c    d=effv",
      "     c    d=effv",
      "     c    d=effv",
      "     c    d=effv",
      "     c    d=effv",
      "     c    d=effv",
      "     c    d=effv",
      "     c    d=effv",
      "     c    d=effv",
      "     c    d=effv",
      "     c    d=effv",
      "     c    d=effv",
      "    cc    d=effv"
    ],
    [
      "     i    d=effv",
      "     i    d=effv",
      "     i    d=effv",
      "     i    d=effv",
      "     i    d=effv",
      "     i    d=effv",
      "     i    d=effv",
      "     i    d=effv",
      "     i    d=effv",
      "     i    d=effv",
      "     i    d=effv",
      "     i    d=effv",
      "     i    d=effv",
      "     i    d=effv",
      "     i    d=effv",
      "    ii    d=effv"
    ]
  ]
}