{
  "name": "multi_nuclearpowerplant_47_base5",
  "refpalette": "deceasedcraft:multi_nuclearpowerplant_47/multi_nuclearpowerplant_47_base5_palette",
  "xsize": 16,
  "zsize": 16,
  "slices": [
    [
      "abaaac    d=effv",
      "abaaac    d=effv",
      "abaaac    d=effv",
      "abaaac    d=effv",
      "abaaac    d=effv",
      "abaaac    d=effv",
      "abbbac    d=effv",
      "aaabac    d=effv",
      "gaabac    d=effv",
      "haabac    d=effv",
      "hbbbac    d=effv",
      "haaaac    d=effv",
      "haaaac    d=effv",
      "haaaac    d=effv",
      "haaaac    d=effv",
      "haaacc    d=effv"
    ],
    [
      "iajaac    d=effv",
      "iajaac    d=effv",
      "iajaac    d=effv",
      "iajaac    d=effv",
      "iajaac    d=effv",
      "iaklac    d=effv",
      "iaaajc    d=effv",
      "amkajc    d=effv",
      "gaiajc    d=effv",
      "hlkajc    d=effv",
      "naaajc    d=effv",
      "hmmmac    d=effv",
      "haaaac    d=effv",
      "haaaac    d=effv",
      "haaaac    d=effv",
      "haaacc    d=effv"
    ],
    [
      "aoaaac    d=effv",
      "aoaaac    d=effv",
      "aoaaac    d=effv",
      "aoaaac    d=effv",
      "aoaaac    d=effv",
      "aoaaac    d=effv",
      "aoooac    d=effv",
      "aaaoac    d=effv",
      "gaaoac    d=effv",
      "haaoac    d=effv",
      "hoooac    d=effv",
      "haaaac    d=effv",
      "haaaac    d=effv",
      "haaaac    d=effv",
      "haaaac    d=effv",
      "haaacc    d=effv"
    ],
    [
      "aaaaac    d=effv",
      "aaaaac    d=effv",
      "aaaaac    d=effv",
      "aaaaac    d=effv",
      "aaaaac    d=effv",
      "aaaaac    d=effv",
      "aaaaac    d=effv",
      "aaaaac    d=effv",
      "gaaaac    d=effv",
      "haaaac    d=effv",
      "haaaac    d=effv",
      "haaaac    d=effv",
      "haaaac    d=effv",
      "haaaac    d=effv",
      "haaaac    d=effv",
      "haaacc    d=effv"
    ],
    [
      "abaaac    d=effv",
      "abaaac    d=effv",
      "abaaac    d=effv",
      "abaaac    d=effv",
      "abaaac    d=effv",
      "abaaac    d=effv",
      "abbbac    d=effv",
      "aaabac    d=effv",
      "gaabac    d=effv",
      "haabac    d=effv",
      "hbbbac    d=effv",
      "haaaac    d=effv",
      "haaaac    d=effv",
      "haaaac    d=effv",
      "haaaac    d=effv",
      "haaacc    d=effv"
    ],
    [
      "iajaac    d=effv",
      "iajaac    d=effv",
      "iajaac    d=effv",
      "iajaac    d=effv",
      "iajaac    d=effv",
      "iaklac    d=effv",
      "iaaajc    d=effv",
      "amkajc    d=effv",
      "gaiajc    d=effv",
      "hlkajc    d=effv",
      "paaajc    d=effv",
      "hmmmac    d=effv",
      "haaaac    d=effv",
      "haaaac    d=effv",
      "haaaac    d=effv",
      "haaacc    d=effv"
    ]
  ]
}