{
  "name": "multi_nuclearpowerplant_47_base9",
  "refpalette": "deceasedcraft:multi_nuclearpowerplant_47/multi_nuclearpowerplant_47_base9_palette",
  "xsize": 16,
  "zsize": 16,
  "slices": [
    [
      "            abbv",
      "            abbv",
      "           cabbv",
      "            abbv",
      "            abbv",
      "            abbv",
      "            abbv",
      "            abbv",
      "            abbv",
      "            abbv",
      "            abbv",
      "            abbv",
      "           cabbv",
      "            abbv",
      "            abbv",
      "            abbv"
    ],
    [
      "           dabbv",
      "           dabbv",
      "           cabbv",
      "          edabbv",
      "          fdabbv",
      "          fdabbv",
      "          fdabbv",
      "          fdabbv",
      "          fdabbv",
      "          fdabbv",
      "          fdabbv",
      "          fdabbv",
      "           cabbv",
      "            abbv",
      "            abbv",
      "            abbv"
    ],
    [
      "          fgabbv",
      "          fhabbv",
      "           cabbv",
      "          eiabbv",
      "            abbv",
      "            abbv",
      "            abbv",
      "            abbv",
      "            abbv",
      "            abbv",
      "            abbv",
      "            abbv",
      "           cabbv",
      "            abbv",
      "            abbv",
      "            abbv"
    ],
    [
      "            abbv",
      "            abbv",
      "jjjjjjjjjjkcabbv",
      "            abbv",
      "            abbv",
      "            abbv",
      "            abbv",
      "            abbv",
      "            abbv",
      "            abbv",
      "            abbv",
      "            abbv",
      "jjjjjjjjjjkcabbv",
      "            abbv",
      "            abbv",
      "            abbv"
    ],
    [
      "    c       abbv",
      "    c       abbv",
      "ccccccccccccabbv",
      "    c       abbv",
      "    c       abbv",
      "    c       abbv",
      "    c       abbv",
      "    c       abbv",
      "    c       abbv",
      "    c       abbv",
      "    c       abbv",
      "    c       abbv",
      "ccccccccccccabbv",
      "    c       abbv",
      "    c       abbv",
      "    c       abbv"
    ],
    [
      "            abbv",
      "    l       abbv",
      "   mcn    ocabbv",
      "    p       abbv",
      "            abbv",
      "            abbv",
      "            abbv",
      "            abbv",
      "            abbv",
      "            abbv",
      "            abbv",
      "    l       abbv",
      "   mcn    ocabbv",
      "    p       abbv",
      "            abbv",
      "            abbv"
    ]
  ]
}