{
  "name": "multi_nuclearpowerplant_47_base6",
  "refpalette": "deceasedcraft:multi_nuclearpowerplant_47/multi_nuclearpowerplant_47_base6_palette",
  "xsize": 16,
  "zsize": 16,
  "slices": [
    [
      "aaaaab    c=deev",
      "aaaaab    c=deev",
      "aaaaab    c=deev",
      "aaaaab    c=deev",
      "aaaaab    c=deev",
      "aaaaab    c=deev",
      "aaaaab    c=deev",
      "aaaaab    c=deev",
      "faaaab    c=deev",
      "aaaaab    c=deev",
      "aaaaab    c=deev",
      "aaaaab    c=deev",
      "aaaaab    c=deev",
      "aaaaab    c=deev",
      "aaaaab    c=deev",
      "aaaabb    c=deev"
    ],
    [
      "aaaaab    c=geev",
      "aaaaab    c=geev",
      "aaaaab    c=geev",
      "aaaaab    c=geev",
      "aaaaab    c=geev",
      "aaaaab    c=geev",
      "aaaaab    c=geev",
      "aaaaab    c=geev",
      "faaaab    c=geev",
      "aaaaab    c=geev",
      "aaaaab    c=geev",
      "aaaaab    c=geev",
      "aaaaab    c=geev",
      "aaaaab    c=geev",
      "aaaaab    c=geev",
      "aaaabb    c=geev"
    ],
    [
      "aaaaab    c=geev",
      "aaaaab    c=geev",
      "aaaaab    c=geev",
      "aaaaab    c=geev",
      "aaaaab    c=geev",
      "aaaaab    c=geev",
      "aaaaab    c=geev",
      "aaaaab    c=geev",
      "faaaab    c=geev",
      "hhhhhb    c=geev",
      "aaaaab    c=geev",
      "aaaaab    c=geev",
      "aaaaab    c=geev",
      "aaaaab    c=geev",
      "aaaaab    c=geev",
      "hhhhbb    c=geev"
    ],
    [
      "aaaaab    c=geev",
      "aaaaab    c=geev",
      "aaaaab    c=geev",
      "aaaaab    c=geev",
      "aaaaab    c=geev",
      "aaaaab    c=geev",
      "aaaaab    c=geev",
      "aaaaab    c=geev",
      "faaaab    c=geev",
      "iaaaab    c=geev",
      "iaaaab    c=geev",
      "iaaaab    c=geev",
      "iaaaab    c=geev",
      "iaaaab    c=geev",
      "iaaaab    c=geev",
      "iaaabb    c=geev"
    ],
    [
      "aaaaab    c=geev",
      "aaaaab    c=geev",
      "aaaaab    c=geev",
      "aaaaab    c=geev",
      "aaaaab    c=geev",
      "aaaaab    c=geev",
      "aaaaab    c=geev",
      "aaaaab    c=geev",
      "faaaab    c=geev",
      "faaaab    c=geev",
      "faaaab    c=geev",
      "faaaab    c=geev",
      "faaaab    c=geev",
      "faaaab    c=geev",
      "faaaab    c=geev",
      "faaabb    c=geev"
    ],
    [
      "aaaaab    c=geev",
      "aaaaab    c=geev",
      "aaaaab    c=geev",
      "aaaaab    c=geev",
      "aaaaab    c=geev",
      "aaaaab    c=geev",
      "aaaaab    c=geev",
      "aaaaab    c=geev",
      "jaaaab    c=geev",
      "jaaaab    c=geev",
      "jaaaab    c=geev",
      "jaaaab    c=geev",
      "jaaaab    c=geev",
      "jaaaab    c=geev",
      "jaaaab    c=geev",
      "jaaabb    c=geev"
    ]
  ]
}