{
  "name": "multi_nuclearpowerplant_47_base10",
  "refpalette": "deceasedcraft:multi_nuclearpowerplant_47/multi_nuclearpowerplant_47_base10_palette",
  "xsize": 16,
  "zsize": 16,
  "slices": [
    [
      "   abcccccccdeev",
      "   abcccccffdeev",
      "   abcccccfgdeev",
      "   abcccccffdeev",
      "   abcccccccdeev",
      "   abcccccccdeev",
      "   abcccccccdeev",
      "   abcccccccdeev",
      "   abcccccccdeev",
      "   abcccccccdeev",
      "   abcccccccdeev",
      "   abcccccffdeev",
      "   abcccccfgdeev",
      "   abcccccffdeev",
      "  abbcccccccdeev",
      "  abccccccccdeev"
    ],
    [
      "    h     ijkeev",
      "    h     ijkeev",
      "    h     lmkeev",
      "    h     njkeev",
      "    h     ijkeev",
      "    h     ijkeev",
      "    h     ijkeev",
      "jjjo      ijkeev",
      "    h     ijkeev",
      "    h     ijkeev",
      "    h     ijkeev",
      "    h     ijkeev",
      "    h     lmkeev",
      "    h       keev",
      "   p        keev",
      "   h        keev"
    ],
    [
      "            keev",
      "            keev",
      "           mkeev",
      "          nqkeev",
      "            keev",
      "            keev",
      "            keev",
      "rrr         keev",
      "            keev",
      "            keev",
      "            keev",
      "            keev",
      "           mkeev",
      "            keev",
      "            keev",
      "            keev"
    ],
    [
      "            keev",
      "            keev",
      "           mkeev",
      "            keev",
      "            keev",
      "            keev",
      "            keev",
      "            keev",
      "            keev",
      "            keev",
      "            keev",
      "            keev",
      "           mkeev",
      "            keev",
      "            keev",
      "            keev"
    ],
    [
      "          ijkeev",
      "          ijkeev",
      "           mkeev",
      "          njkeev",
      "          ijkeev",
      "          ijkeev",
      "          ijkeev",
      "          ijkeev",
      "          ijkeev",
      "          ijkeev",
      "          ijkeev",
      "          ijkeev",
      "           mkeev",
      "            keev",
      "            keev",
      "            keev"
    ],
    [
      "            keev",
      "            keev",
      "           mkeev",
      "          nqkeev",
      "            keev",
      "            keev",
      "            keev",
      "           !keev",
      "            keev",
      "            keev",
      "            keev",
      "            keev",
      "           mkeev",
      "            keev",
      "            keev",
      "            keev"
    ]
  ]
}