{
  "name": "multi_nuclearpowerplant_47_base11",
  "refpalette": "deceasedcraft:multi_nuclearpowerplant_47/multi_nuclearpowerplant_47_base11_palette",
  "xsize": 16,
  "zsize": 16,
  "slices": [
    [
      "abcd========effv",
      "cccd========effv",
      "agcd========effv",
      "bhcd========effv",
      "cccd========effv",
      "ghcd========effv",
      "abcd========effv",
      "cccd========effv",
      "cccd========effv",
      "cccd========effv",
      "cccd========effv",
      "cccd========effv",
      "cccd========effv",
      "cccd========effv",
      "ccd=========effv",
      "ccd=========effv"
    ],
    [
      "cccd========effv",
      "cccd========effv",
      "cccd========effv",
      "cccd========effv",
      "cccd========effv",
      "cccd========effv",
      "cccd========effv",
      "cccd========effv",
      "cccd========effv",
      "cccd========effv",
      "cccd========effv",
      "cccd========effv",
      "cccd========effv",
      "cccd========effv",
      "ccd=========effv",
      "ccd=========effv"
    ],
    [
      "cccd========effv",
      "cccd========effv",
      "cccd========effv",
      "cccd========effv",
      "cccd========effv",
      "cccd========effv",
      "cccd========effv",
      "cccd========effv",
      "cccd========effv",
      "cccd========effv",
      "cccd========effv",
      "cccd========effv",
      "cccd========effv",
      "cccd========effv",
      "ccd=========effv",
      "ccd=========effv"
    ],
    [
      "cccd========effv",
      "cccd========effv",
      "cccd========effv",
      "cccd========effv",
      "cccd========effv",
      "cccd========effv",
      "cccd========effv",
      "cccd========effv",
      "cccd========effv",
      "cccd========effv",
      "cccd========effv",
      "cccd========effv",
      "cccd========effv",
      "cccd========effv",
      "ccd=========effv",
      "ccd=========effv"
    ],
    [
      "cccd========effv",
      "cccd========effv",
      "cccd========effv",
      "cccd========effv",
      "cccd========effv",
      "cccd========effv",
      "cccd========effv",
      "cccd========effv",
      "cccd========effv",
      "cccd========effv",
      "cccd========effv",
      "cccd========effv",
      "cccd========effv",
      "cccd========effv",
      "ccd=========effv",
      "ccd=========effv"
    ],
    [
      "cccd========effv",
      "cccd========effv",
      "cccd========effv",
      "cccd========effv",
      "cccd========effv",
      "cccd========effv",
      "cccd========effv",
      "cccd========effv",
      "cccd========effv",
      "cccd========effv",
      "cccd========effv",
      "cccd========effv",
      "cccd========effv",
      "cccd========effv",
      "ccd=========effv",
      "ccd=========effv"
    ]
  ]
}