{
  "name": "multi_nuclearpowerplant_47_base12",
  "refpalette": "deceasedcraft:multi_nuclearpowerplant_47/multi_nuclearpowerplant_47_base12_palette",
  "xsize": 16,
  "zsize": 16,
  "slices": [
    [
      "aaaaaaaaaaaaaaav",
      "aaaaaaaaaaaaaaav",
      "aaaaaaaaaaaaaaav",
      "aaaaaaaaaaaaaaav",
      "aaaaaaaaaaaaaaav",
      "aaaaaaaaaaaaaaav",
      "aaaaaaaaaaaaaaav",
      "aaaaaaaaaaaaaaav",
      "aaaaaaaaaaaaaaav",
      "aaaaaaaaaaaaaaav",
      "aaaaaaaaaaaaaaav",
      "aaaaaaaaaaaaaaav",
      "aaaaaaaaaaaaaaav",
      "aaaaaaaaaaaaaaav",
      "aaaaaaaaaaaaaaav",
      "aaaaaaaaaaaaaaav"
    ],
    [
      "bbbbbbbbbbbbbaav",
      "bbbbbbbbbbbbbaav",
      "bbbbbbbbbbbbbaav",
      "bbbbbbbbbbbbbaav",
      "bbbbbbbbbbbbbaav",
      "bbbbbbbbbbbbbaav",
      "bbbbbbbbbbbbbaav",
      "bbbbbbbbbbbbbaav",
      "bbbbbbbbbbbbbaav",
      "bbbbbbbbbbbbbaav",
      "bbbbbbbbbbbbbaav",
      "bbbbbbbbbbbbbaav",
      "bbbbbbbbbbbbbaav",
      "bbbbbbbbbbbbbaav",
      "bbbbbbbbbbbbbaav",
      "bbbbbbbbbbbbbaav"
    ],
    [
      "============caav",
      "============caav",
      "============caav",
      "============caav",
      "============caav",
      "============caav",
      "============caav",
      "============caav",
      "============caav",
      "============caav",
      "============caav",
      "============caav",
      "============caav",
      "============caav",
      "============caav",
      "============caav"
    ],
    [
      "dddb========eaav",
      "dddb========eaav",
      "dddb========eaav",
      "dddb========eaav",
      "dddb========eaav",
      "dddb========eaav",
      "dddb========eaav",
      "dddb========eaav",
      "dddb========eaav",
      "dddb========eaav",
      "dddb========eaav",
      "dddb========eaav",
      "dddb========eaav",
      "dddb========eaav",
      "ddb=========eaav",
      "ddb=========eaav"
    ],
    [
      "ffgb========eaav",
      "gggb========eaav",
      "ffgb========eaav",
      "ffgb========eaav",
      "gggb========eaav",
      "ffgb========eaav",
      "ffgb========eaav",
      "gggb========eaav",
      "gggb========eaav",
      "gggb========eaav",
      "gggb========eaav",
      "gggb========eaav",
      "gggb========eaav",
      "gggb========eaav",
      "ggb=========eaav",
      "ggb=========eaav"
    ],
    [
      "higb========eaav",
      "gggb========eaav",
      "jigb========eaav",
      "khgb========eaav",
      "gggb========eaav",
      "kjgb========eaav",
      "higb========eaav",
      "gggb========eaav",
      "gggb========eaav",
      "gggb========eaav",
      "gggb========eaav",
      "gggb========eaav",
      "gggb========eaav",
      "gggb========eaav",
      "ggb=========eaav",
      "ggb=========eaav"
    ]
  ]
}