{
  "name": "multi_nuclearpowerplant_47_base1",
  "refpalette": "deceasedcraft:multi_nuclearpowerplant_47/multi_nuclearpowerplant_47_base1_palette",
  "xsize": 16,
  "zsize": 16,
  "slices": [
    [
      "=========aaabccv",
      "=========aaabccv",
      "=========aaabccv",
      "=========aaabccv",
      "=========aaabccv",
      "=========aaabccv",
      "=========aaabccv",
      "=========aaabccv",
      "=========aaabccv",
      "=========aaabccv",
      "=========aaabccv",
      "=========aaabccv",
      "=========aaabccv",
      "=========aaabccv",
      "=========aaabccv",
      "=========aaabccv"
    ],
    [
      "aaaaaaaaaaaabccv",
      "aaaaaaaaaaaabccv",
      "aaaaaaaaaaaabccv",
      "aaaaaaaaaaaabccv",
      "aaaaaaaaaaaabccv",
      "aaaaaaaaaaaabccv",
      "aaaaaaaaaaaabccv",
      "aaaaaaaaaaaabccv",
      "aaaaaaaaaaaabccv",
      "aaaaaaaaaaaabccv",
      "aaaaaaaaaaaabccv",
      "aaaaaaaaaaaabccv",
      "aaaaaaaaaaaabccv",
      "aaaaaaaaaaaabccv",
      "aaaaaaaaaaaabccv",
      "aaaaaaaaaaaabccv"
    ],
    [
      "aaaaaaaaaaaabccv",
      "aaaaaaaaaaaabccv",
      "aaaaaaaaaaaabccv",
      "aaaaaaaaaaaabccv",
      "aaaaaaaaaaaabccv",
      "aaaaaaaaaaaabccv",
      "aaaaaaaaaaaabccv",
      "aaaaaaaaaaaabccv",
      "aaaaaaaaaaaabccv",
      "aaaaaaaaaaaabccv",
      "aaaaaaaaaaaabccv",
      "aaaaaaaaaaaabccv",
      "aaaaaaaaaaaabccv",
      "aaaaaaaaaaaabccv",
      "aaaaaaaaaaaabccv",
      "aaaaaaaaaaaabccv"
    ],
    [
      "aaaaaaaaaaaabccv",
      "aaaaaaaaaaaabccv",
      "aaaaaaaaaaaabccv",
      "aaaaaaaaaaaabccv",
      "aaaaaaaaaaaabccv",
      "aaaaaaaaaaaabccv",
      "aaaaaaaaaaaabccv",
      "aaaaaaaaaaaabccv",
      "aaaaaaaaaaaabccv",
      "aaaaaaaaaaaabccv",
      "aaaaaaaaaaaabccv",
      "aaaaaaaaaaaabccv",
      "aaaaaaaaaaaabccv",
      "aaaaaaaaaaaabccv",
      "aaaaaaaaaaaabccv",
      "aaaaaaaaaaaabccv"
    ],
    [
      "aaaaaaaaaaaabccv",
      "aaaaaaaaaaaabccv",
      "aaaaaaaaaaaabccv",
      "aaaaaaaaaaaabccv",
      "aaaaaaaaaaaabccv",
      "aaaaaaaaaaaabccv",
      "aaaaaaaaaaaabccv",
      "aaaaaaaaaaaabccv",
      "aaaaaaaaaaaabccv",
      "aaaaaaaaaaaabccv",
      "aaaaaaaaaaaabccv",
      "aaaaaaaaaaaabccv",
      "aaaaaaaaaaaabccv",
      "aaaaaaaaaaaabccv",
      "aaaaaaaaaaaabccv",
      "aaaaaaaaaaaabccv"
    ],
    [
      "aaaaddaaaaaabaav",
      "aaaadaaaaaaabaav",
      "aaaddaaaaaaabaav",
      "aaddaaaaaaaabaav",
      "aadaaaaaaaaabaav",
      "addaaaaaaaaabaav",
      "ddaaaaaaaaaabaav",
      "daaaaaaaaaaabaav",
      "daaaaaaaaaaabaav",
      "aaaaaaaaaaaabaav",
      "aaaaaaaaaaaabaav",
      "aaaaaaaaaaaabaav",
      "aaaaaaaaaaaabaav",
      "aaaaaaaaaaaabaav",
      "aaaaaaaaaaaabaav",
      "aaaaaaaaaaaabaav"
    ]
  ]
}