{
  "name": "multi_nuclearpowerplant_47_ground",
  "refpalette": "deceasedcraft:multi_nuclearpowerplant_47/multi_nuclearpowerplant_47_ground_palette",
  "xsize": 16,
  "zsize": 16,
  "slices": [
    [
      "aaaabbccccczzccz",
      "aaaabcccccccczzz",
      "aaabbcccczczczzz",
      "aabbccczcczczczz",
      "aabccccczzczzzzz",
      "abbcccccczczzzzz",
      "bbccccczczzczczz",
      "bcccczcczcczzzzz",
      "bccccczccczzzzzz",
      "ccccccczzczczzzz",
      "ccczczccczzzzzzz",
      "cccccczczczzzczz",
      "ccczzczzzczczzzz",
      "czccczzcczzzzzzz",
      "cczzcczzczczzczz",
      "czczzccccczczzcz"
    ],
    [
      "zzzzczd        e",
      "zzzzzf          ",
      "czzczd          ",
      "zzzzg         e ",
      "zzzg        eee ",
      "zzzd            ",
      "zzg             ",
      "zg             e",
      "zd         ee   ",
      "f               ",
      "              ee",
      "      e         ",
      "   e    e   ee  ",
      "      e        e",
      "           ee   ",
      "          e e  e"
    ],
    [
      "    hh          ",
      "    h           ",
      " e hh           ",
      "  hh            ",
      "  h             ",
      " hh             ",
      "hh              ",
      "h               ",
      "h               ",
      "                ",
      "                ",
      "                ",
      "                ",
      "                ",
      "                ",
      "                "
    ],
    [
      "    hh          ",
      "    h           ",
      "   hh           ",
      "  hh            ",
      "  h             ",
      " hh             ",
      "hh              ",
      "h               ",
      "h               ",
      "                ",
      "                ",
      "                ",
      "                ",
      "                ",
      "                ",
      "                "
    ],
    [
      "     i          ",
      "    i           ",
      "    i           ",
      "   i            ",
      "  i             ",
      "  i             ",
      " i              ",
      "i               ",
      "i               ",
      "                ",
      "                ",
      "                ",
      "                ",
      "                ",
      "                ",
      "                "
    ],
    [
      "                ",
      "                ",
      "                ",
      "                ",
      "                ",
      "                ",
      "                ",
      "                ",
      "                ",
      "                ",
      "                ",
      "                ",
      "                ",
      "                ",
      "                ",
      "                "
    ]
  ]
}