{
  "name": "multi_nuclearpowerplant_47_base3",
  "refpalette": "deceasedcraft:multi_nuclearpowerplant_47/multi_nuclearpowerplant_47_base3_palette",
  "xsize": 16,
  "zsize": 16,
  "slices": [
    [
      "       aaab=cddv",
      "       aaab=cddv",
      "       aaab=cddv",
      "       aaab=cddv",
      "       aaab=cddv",
      "       aaab=cddv",
      "       aaab=cddv",
      "       aaab=cddv",
      "       aaab=cddv",
      "       aaab=cddv",
      "       aaab=cddv",
      "       aaab=cddv",
      "       aaab=cddv",
      "       aaab=cddv",
      "       aaab=cddv",
      "       aaab=cddv"
    ],
    [
      "       e  f=gddv",
      "       e  f=gddv",
      "       e  f=gddv",
      "       e hf=gddv",
      "       e  f=gddv",
      "       e  f=gddv",
      "       e  f=gddv",
      "       e  f=gddv",
      "       e  f=gddv",
      "       e hf=gddv",
      "       e  f=gddv",
      "       e  f=gddv",
      "       e  f=gddv",
      "       e  f=gddv",
      "       e  f=gddv",
      "       e hf=gddv"
    ],
    [
      "          f=gddv",
      "          f=gddv",
      "          f=gddv",
      "          f=gddv",
      "          f=gddv",
      "          f=gddv",
      "          f=gddv",
      "          f=gddv",
      "          f=gddv",
      "          f=gddv",
      "          f=gddv",
      "          f=gddv",
      "          f=gddv",
      "          f=gddv",
      "          f=gddv",
      "          f=gddv"
    ],
    [
      "          f=gddv",
      "          f=gddv",
      "          f=gddv",
      "          f=gddv",
      "          f=gddv",
      "          f=gddv",
      "          f=gddv",
      "          f=gddv",
      "          f=gddv",
      "          f=gddv",
      "          f=gddv",
      "          f=gddv",
      "          f=gddv",
      "          f=gddv",
      "          f=gddv",
      "          f=gddv"
    ],
    [
      "          f=gddv",
      "          f=gddv",
      "          f=gddv",
      "          f=gddv",
      "          f=gddv",
      "          f=gddv",
      "          f=gddv",
      "          f=gddv",
      "          f=gddv",
      "          f=gddv",
      "          f=gddv",
      "          f=gddv",
      "          f=gddv",
      "          f=gddv",
      "          f=gddv",
      "          f=gddv"
    ],
    [
      "          f=gddv",
      "          f=gddv",
      "          f=gddv",
      "          f=gddv",
      "          f=gddv",
      "          f=gddv",
      "          f=gddv",
      "          f=gddv",
      "          f=gddv",
      "          f=gddv",
      "          f=gddv",
      "          f=gddv",
      "          f=gddv",
      "          f=gddv",
      "          f=gddv",
      "          f=gddv"
    ]
  ]
}