{
  "name": "multi_nuclearpowerplant_47_base7",
  "refpalette": "deceasedcraft:multi_nuclearpowerplant_47/multi_nuclearpowerplant_47_base7_palette",
  "xsize": 16,
  "zsize": 16,
  "slices": [
    [
      "aaaaab    c=deev",
      "aaaaab    c=deev",
      "aaaaab    c=deev",
      "aaaaab   fc=deev",
      "aaaaab    c=deev",
      "aaaaab    c=deev",
      "aaaaab    c=deev",
      "aaaaab    c=deev",
      " aaaab    c=deev",
      "aaaaab    c=deev",
      "aaaaab    c=deev",
      "aaaaab    c=deev",
      "aaaaab    c=deev",
      "aaaaab    c=deev",
      "aaaaab    c=deev",
      "aaaabb   fc=deev"
    ],
    [
      "aaaaab    c=deev",
      "aaaaab    c=deev",
      "aaaaab    c=deev",
      "aaaaab    c=deev",
      "aaaaab    c=deev",
      "aaaaab    c=deev",
      "aaaaab    c=deev",
      "aaaaab    c=deev",
      "@aaaab    c=deev",
      "aaaaab    c=deev",
      "gaaaab    c=deev",
      "gaaaab    c=deev",
      "gaaaab    c=deev",
      "gaaaab    c=deev",
      "gaaaab    c=deev",
      "aaaabb    c=deev"
    ],
    [
      "hhhhhb    c=deev",
      "hhhhhb    c=deev",
      "hhhhhb    c=deev",
      "hhhhhb    c=deev",
      "hhhhhb    c=deev",
      "hhhhhb    c=deev",
      "hhhhhb    c=deev",
      "hhhhhb    c=deev",
      "ihhhhb    c=deev",
      "hhhhhb    c=deev",
      "hhhhhb    c=deev",
      "hhhhhb    c=deev",
      "hhhhhb    c=deev",
      "hhhhhb    c=deev",
      "hhhhhb    c=deev",
      "hhhhbb    c=deev"
    ],
    [
      "hhhhhb    c=deev",
      "hhhhhb    c=deev",
      "hhhhhb    c=deev",
      "hhhhhb    c=deev",
      "hhhhhb    c=deev",
      "hhhhhb    c=deev",
      "hhhhhb    c=deev",
      "hhhhhb    c=deev",
      "ihhhhb    c=deev",
      "hhhhhb    c=deev",
      "hhhhhb    c=deev",
      "hhhhhb    c=deev",
      "hhhhhb    c=deev",
      "hhhhhb    c=deev",
      "hhhhhb    c=deev",
      "hhhhbb    c=deev"
    ],
    [
      "hhhhhb    c=deev",
      "hhhhhb    c=deev",
      "hhhhhb    c=deev",
      "hhhhhb    c=deev",
      "hhhhhb    c=deev",
      "hhhhhb    c=deev",
      "hhhhhb    c=deev",
      "hhhhhb    c=deev",
      "ihhhhb    c=deev",
      "hhhhhb    c=deev",
      "hhhhhb    c=deev",
      "hhhhhb    c=deev",
      "hhhhhb    c=deev",
      "hhhhhb    c=deev",
      "hhhhhb    c=deev",
      "hhhhbb    c=deev"
    ],
    [
      "hhhhhb    c=deev",
      "hhhhhb    c=deev",
      "hhhhhb    c=deev",
      "hhhhhb    c=deev",
      "hhhhhb    c=deev",
      "hhhhhb    c=deev",
      "hhhhhb    c=deev",
      "hhhhhb    c=deev",
      "ihhhhb    c=deev",
      "hhhhhb    c=deev",
      "hhhhhb    c=deev",
      "hhhhhb    c=deev",
      "hhhhhb    c=deev",
      "hhhhhb    c=deev",
      "hhhhhb    c=deev",
      "hhhhbb    c=deev"
    ]
  ]
}