{
  "name": "multi_communitycenter_6_floor1",
  "refpalette": "deceasedcraft:multi_communitycenter_6/multi_communitycenter_6_floor1_palette",
  "xsize": 16,
  "zsize": 16,
  "slices": [
    [
      "                ",
      "                ",
      "                ",
      "                ",
      "                ",
      "                ",
      "                ",
      "                ",
      "aaaaaaaaaaaaaa  ",
      "b    bb    bba  ",
      "cccccccccccc a  ",
      "c  dd      c a  ",
      "c  effffe  c a  ",
      "c  effffe  cba  ",
      "c  effffe  cba  ",
      "c          c a  "
    ],
    [
      "                ",
      "                ",
      "                ",
      "                ",
      "                ",
      "                ",
      "                ",
      "                ",
      "                ",
      "b    bb    bb   ",
      "                ",
      "                ",
      "    dd          ",
      "     d      b   ",
      "     g      b   ",
      "                "
    ],
    [
      "                ",
      "                ",
      "                ",
      "                ",
      "                ",
      "                ",
      "                ",
      "                ",
      "                ",
      "b    bb    bb   ",
      "                ",
      "                ",
      "                ",
      "            b   ",
      "            b   ",
      "                "
    ],
    [
      "                ",
      "                ",
      "                ",
      "                ",
      "                ",
      "                ",
      "                ",
      "                ",
      "                ",
      "h    hh    hh   ",
      "                ",
      "                ",
      "                ",
      "            h   ",
      "            h   ",
      "                "
    ],
    [
      "                ",
      "                ",
      "                ",
      "                ",
      "                ",
      "                ",
      "                ",
      "iiiiiiiiiiiiiii ",
      "iiiiiiiiiiiiiii ",
      "jjjjjjjjjjjjjii ",
      "kkkkkkkkkkkkjii ",
      "kkkkkkkkkkkkjii ",
      "kkkkkkkkkkkkjii ",
      "kkkkkkkkkkkkjii ",
      "kkkkkkkkkkkkjii ",
      "kkkkkkkkkkkkjii "
    ],
    [
      "                ",
      "                ",
      "                ",
      "                ",
      "                ",
      "                ",
      "                ",
      "                ",
      "                ",
      "                ",
      "                ",
      "      ~         ",
      "                ",
      "                ",
      "                ",
      "                "
    ]
  ]
}