{
  "name": "multi_communitycenter_6_ground",
  "refpalette": "deceasedcraft:multi_communitycenter_6/multi_communitycenter_6_ground_palette",
  "xsize": 16,
  "zsize": 16,
  "slices": [
    [
      "aaaaaaaaaaaaaaaa",
      "aaaaabbbbbbbbbbb",
      "ccccbHHHHHHHHHHH",
      "cccbHHHHHHHHHHHH",
      "cccbHHHHHHHHHHHH",
      "cccbHHHHHHHHHHHH",
      "cccbHHHHbbbbbbbb",
      "cccbddddbcccccca",
      "eeebffffbeeeeeca",
      "eeeb    beeeeeca",
      "eeeb    beeeeeca",
      "eeeb    beeeeeca",
      "eeeb    beeeeeca",
      "eeeb    beeeeeca",
      "eeeb    beeeeeca",
      "eeeb    beeeeeca"
    ],
    [
      "                ",
      "     ggggggggggg",
      "hhhhg           ",
      "h ig            ",
      "jjig            ",
      " ijg            ",
      "i ig    gggggggg",
      "ijig    ghhhhh  ",
      "kklg    glkkklm ",
      " nog    go  pqh ",
      " rog    go ssqh ",
      " tog    go   qh ",
      "  ug    gu w lm ",
      " nog    go  xqh ",
      " rog    go ssqh ",
      " tog    go w qh "
    ],
    [
      "                ",
      "                ",
      "                ",
      "  y             ",
      "AAy             ",
      " yA             ",
      "y y             ",
      "yAy             ",
      "kkl      lkkkl  ",
      "  o      o   q  ",
      "  o      o B q  ",
      "  o      o   q  ",
      "  u      u   l  ",
      "  o      o   q  ",
      "  o      o   q  ",
      "  o      o   q  "
    ],
    [
      "                ",
      "                ",
      "                ",
      "                ",
      "                ",
      "                ",
      "                ",
      "                ",
      "kkl      lkkkl  ",
      "  o      o   k  ",
      "  o      o   k  ",
      "  o      o   k  ",
      "  u      u   l  ",
      "  o      o   k  ",
      "  o      o   k  ",
      "  o      o   k  "
    ],
    [
      "                ",
      "                ",
      "                ",
      "                ",
      "                ",
      "                ",
      "                ",
      "                ",
      "CClCCCCCClCCCl  ",
      "  o      o   q  ",
      "  o      o   q  ",
      "  o      o   q  ",
      "  u      uD  l  ",
      "  o      o   q  ",
      "  o      o   q  ",
      "  o      o   q  "
    ],
    [
      "                ",
      "                ",
      "                ",
      "                ",
      "                ",
      "                ",
      "                ",
      "                ",
      "EElEEEEEElEEEE  ",
      "eeeeeeeeeeeeeE  ",
      "eeeeeeeeeeeeeE  ",
      "eeeeeeeeeeeeeE  ",
      "eeeeeeeeeeeeel  ",
      "eeeeeeeeeeeeeE  ",
      "eeeeeeeeeeeeeE  ",
      "eeeeeeeeeeeeeE  "
    ]
  ]
}