{
  "name": "multi_communitycenter_6_base1",
  "refpalette": "deceasedcraft:multi_communitycenter_6/multi_communitycenter_6_base1_palette",
  "xsize": 16,
  "zsize": 16,
  "slices": [
    [
      "vvvvvvvvvvvvvvvv",
      "HHHHHHHHHHHHHHHv",
      "HHHHHHHHHHHHHHHv",
      "HHHHHHHHHHHHHHHv",
      "HHHHHHHHHHHHHHHv",
      "HHHHHHHHHHHHHHHv",
      "HHHHHHHHHHHHHHHv",
      "HHHHHHHHHHHHHHHv",
      "HHHHHHHHHHHHHHHv",
      "HHHHHHHHHHHHHHHv",
      "HHHHHHHHHHHHHHHv",
      "HHHHHHHHHHHHHHHv",
      "HHHHHHHHHHHHHHHv",
      "HHHHHHHHHHHHHHHv",
      "HHHHHHHHHHHHHHHv",
      "HHHHHHHHHHHHHHHv"
    ],
    [
      "vvvvvvvvvvvvvvvv",
      "aaaaaaaaaaaaaaav",
      "aaaaaaaaaaaaaaav",
      "aaaaaaaaaaaaaaav",
      "aaaaaaaaaaaaaaav",
      "aaaaaaaaaaaaaaav",
      "bcb cbcbdcbcb!av",
      "   d          av",
      "   e    e    eav",
      "fgf gfgf gfgf av",
      "              av",
      "              av",
      "              av",
      "              av",
      "bcb   dd      av",
      "   eHhhHe    eav"
    ],
    [
      "vvvvvvvvvvvvvvvv",
      "aaaaaaaaaaaaaaav",
      "aaaaaaaaaaaaaaav",
      "aaaaaaaaaaaaaaav",
      "aaaaaaaaaaaaaaav",
      "aaaaaaaaaaaaaaav",
      "              av",
      "              av",
      "   e    e    eav",
      "              av",
      "              av",
      "              av",
      "              av",
      "              av",
      "             dav",
      "   eHhhHe    eav"
    ],
    [
      "vvvvvvvvvvvvvvvv",
      "aaaaaaaaaaaaaaav",
      "aaaaaaaaaaaaaaav",
      "aaaaaaaaaaaaaaav",
      "aaaaaaaaaaaaaaav",
      "aaaaaaaaaaaaaaav",
      "   d         dav",
      "        d    dav",
      "   e    e    eav",
      "        d     av",
      "             dav",
      "              av",
      "              av",
      "             dav",
      "    d   d    dav",
      "   eHHHHe    eav"
    ],
    [
      "vvvvvvvvvvvvvvvv",
      "aaaaaaaaaaaaaaav",
      "aaaaaaaaaaaaaaav",
      "aaaaaaaaaaaaaaav",
      "aaaaaaaaaaaaaaav",
      "aaaaaaaaaaaaaaav",
      "d de d ded  deav",
      "  ded   e    eav",
      "iiieiiiieiiiieav",
      "   ed  de   deav",
      "   e    e    eav",
      "   ed dde    eav",
      "  deHHHHe   deav",
      "   ejjjje    eav",
      "  dekkkke d deav",
      "iiie    eiiiieav"
    ],
    [
      "vvvvvvvvvvvvvvvv",
      "aaaaaaaaaaaaaaav",
      "aaaaaaaaaaaaaaav",
      "aaaaaaaaaaaaaaav",
      "aaaaaaaaaaaaaaav",
      "aaaaaaaaaaaaaaav",
      "aaaaaaaaaaaaaaav",
      "aaaeaaaaaaaaaaav",
      "aaaeHHHHeaaaaaav",
      "aaahHHHHhaaaaaav",
      "aaahjjjjhaaaaaav",
      "aaahkkkkhaaaaaav",
      "aaah    haaaaaav",
      "aaah    haaaaaav",
      "aaah    haaaaaav",
      "aaah    haaaaaav"
    ]
  ]
}