{
  "name": "multi_cafe_1_ground",
  "refpalette": "deceasedcraft:multi_cafe_1/multi_cafe_1_ground_palette",
  "xsize": 16,
  "zsize": 16,
  "slices": [
    [
      "aabbcddddddddddd",
      "aabbcdddddddcddd",
      "aabbcdddddddcddd",
      "aabbcdddddddaddd",
      "aabbcdddddddaddd",
      "aabbcdddddddaddd",
      "aabbcdddddddcddd",
      "aabbcdddddddaddd",
      "aabbcdddddddaddd",
      "aabbcdddddddaddd",
      "aabbcdddddddcddd",
      "aabbcccccccccccc",
      "aabbbbbbbbbbbbbb",
      "aabbbbbbbbbbbbbb",
      "aaaaaaaaaaaaaaaa",
      "aaaaaaaaaaaaaaaa"
    ],
    [
      "    effffe      ",
      "g   effffe  h   ",
      " g  iffffe  h   ",
      "jk  lffffe  m no",
      " g  lffffe  p   ",
      "kq  lffffe  m   ",
      "rg  cffffe  h no",
      "sk  lffffe      ",
      " k  lffffe  p   ",
      "q   lffffe  m no",
      "rk  lffffe  h   ",
      "j   cttttcuuhuuu",
      "sq              ",
      "kr              ",
      "g  sk sgrsj r k ",
      " krk rk k q kgqg"
    ],
    [
      "                ",
      "            h   ",
      "    w       h   ",
      "    ux x    y   ",
      "    uABC    D   ",
      "    uE E    y   ",
      "    u       h  F",
      "    ux x        ",
      "    uABC    D   ",
      "    uE E    y   ",
      "    u       h   ",
      "    uuuuuuu h   ",
      "                ",
      "                ",
      "                ",
      "                "
    ],
    [
      "                ",
      "            h   ",
      "            h   ",
      "                ",
      "       I        ",
      "                ",
      "            h   ",
      "                ",
      "     I          ",
      "                ",
      "            h   ",
      "            h   ",
      "                ",
      "                ",
      "                ",
      "                "
    ],
    [
      "                ",
      "            h   ",
      "            h   ",
      "                ",
      "                ",
      "                ",
      "            h   ",
      "                ",
      "                ",
      "                ",
      "            h   ",
      "            h   ",
      "                ",
      "                ",
      "                ",
      "                "
    ],
    [
      "                ",
      "            h   ",
      "            h   ",
      "                ",
      "                ",
      "                ",
      "            h   ",
      "                ",
      "                ",
      "                ",
      "            h   ",
      "            h   ",
      "                ",
      "                ",
      "                ",
      "                "
    ]
  ]
}