{
  "name": "multi_sunkenmonumentpark_14_base1",
  "refpalette": "deceasedcraft:multi_sunkenmonumentpark_14/multi_sunkenmonumentpark_14_base1_palette",
  "xsize": 16,
  "zsize": 16,
  "slices": [
    [
      "aaaaaaaaaaaaaaav",
      "aaaaaaaaaaaaaaav",
      "aaaaaaaaaaaaaaav",
      "aaaaaaaaaaaaaaav",
      "aaaaaaaaaaaaaaav",
      "aaaaaaaaaaaaaaav",
      "aaaaaaaaaaaaaaav",
      "aaaaaaaaaaaaaaav",
      "aaaaaaaaaaaaaaav",
      "aaaaaaaaaaaaaaav",
      "aaaaaaaaaaaaaaav",
      "aaaaaaaaaaaaaaav",
      "aaaaaaaaaaaaaaav",
      "aaaaaaaaaaaaaaav",
      "aaaaaaaaaaaaaaav",
      "aaaaaaaaaaaaaaav"
    ],
    [
      "aaaaaaaaaaaaaaav",
      "aaaaaaaaaaaaaaav",
      "aaaaaaaaaaaaaaav",
      "aaaaaaaaaaaaaaav",
      "aaaaaaaaaaaaaaav",
      "aaaaaaaaaaaaaaav",
      "aaaaaaaaaaaaaaav",
      "aaaaaaaaaaaaaaav",
      "aaaaaaaaaaaaaaav",
      "aaaaaaaaaaaaaaav",
      "aaaaaaaaaaaaaaav",
      "aaaaaaaaaaaaaaav",
      "aaaaaaaaaaaaaaav",
      "aaaaaaaaaaaaaaav",
      "aaaaaaaaaaaaaaav",
      "aaaaaaaaaaaaaaav"
    ],
    [
      "bbbaaaaaaaaaaaav",
      "bbbaaaaaaaaaaaav",
      "cccaaaaaaaaaaaav",
      "cccaaaaaaaaaaaav",
      "cccaaaaaaaaaaaav",
      "cccaaaaaaaaaaaav",
      "cccaaaaaaaaaaaav",
      "cccaaaaaaaaaaaav",
      "cccaaaaaaaaaaaav",
      "ccaaaaaaaaaaaaav",
      "ccaaaaaaaaaaaaav",
      "ccaaaaaaaaaaaaav",
      "caaaaaaaaaaaaaav",
      "aaaaaaaaaaaaaaav",
      "aaaaaaaaaaaaaaav",
      "aaaaaaaaaaaaaaav"
    ],
    [
      " debbbaaaafffffv",
      " debbbaaaafffffv",
      "  gcccaaaafffffv",
      "  gcccaaaafffffv",
      "h gcccaaaafffffv",
      "  gcccaaaaaaaaav",
      " hgcccaaaaaaaaav",
      "h gcccaaaaaaaaav",
      "  gcccaaaaaaaaav",
      " gccccaaaaaaaaav",
      " gccccaaaaaaaaav",
      " gccccaaaaaaaaav",
      "gcccccaaaaaaaaav",
      "ccccccaaaaaaaaav",
      "cccccaaaaaaaaaav",
      "cccccaaaaaaaaaav"
    ],
    [
      "    debbbffffffv",
      "    debbbffffffv",
      "     gcccffffffv",
      "     gcccffffffv",
      "     gcccffffffv",
      "     gccc      v",
      "    hgccc      v",
      "   i gccc      v",
      "     gccc      v",
      "     gccc      v",
      "   i gccc      v",
      "     gccc      v",
      "   h gccc      v",
      "h    gccc      v",
      "  i gcccc      v",
      "i   gcccc      v"
    ],
    [
      "       debbbfffv",
      "       debbbfffv",
      "        fffffffv",
      "       jfffffffv",
      "       kfffffffv",
      "       hgccc   v",
      "        gccc   v",
      "   l  i gccc   v",
      "       mgccc   v",
      "      h gccc   v",
      "   l    gccc   v",
      "        gccc   v",
      "   h   hgccc   v",
      "      h gccc   v",
      "  l     gccc   v",
      "l     i gccc   v"
    ]
  ]
}