{
  "name": "multi_sunkenmonumentpark_14_ground",
  "refpalette": "deceasedcraft:multi_sunkenmonumentpark_14/multi_sunkenmonumentpark_14_ground_palette",
  "xsize": 16,
  "zsize": 16,
  "slices": [
    [
      "          abcccc",
      "          abcccc",
      "     deffffggggg",
      "     dfffffggggg",
      "    ddffffffffff",
      "    def    hifff",
      "          jhiiff",
      "   k  l    hiiff",
      "       m   hiiff",
      "         jnhiiff",
      "   k       hiiff",
      "           hiiff",
      "          nhiiff",
      "           hiiff",
      "  k        hiiff",
      "k     l    hiiff"
    ],
    [
      "dd              ",
      "dd              ",
      "ddfffgggooo     ",
      "ddfffgggooo     ",
      "dffffggfffppp   ",
      "dffffff         ",
      "dfff        j   ",
      "d  k  k      n  ",
      "       l        ",
      "          l j   ",
      "   k        n   ",
      "             qj ",
      "          l     ",
      "                ",
      "  k         nj  ",
      "k     k         "
    ],
    [
      "gf              ",
      "gf              ",
      "ggooo           ",
      "ggooo           ",
      "ggooo  ppp      ",
      "ggooppr         ",
      "gfff            ",
      "f  s  k      l  ",
      "       k        ",
      "          k     ",
      "   k        l   ",
      "             m  ",
      "          k     ",
      "                ",
      "            l   ",
      "s     k         "
    ],
    [
      " tu             ",
      "  u             ",
      "                ",
      "                ",
      "                ",
      "                ",
      " ppr            ",
      "r     s      k  ",
      "       k        ",
      "          k     ",
      "   s        k   ",
      "             l  ",
      "          k     ",
      "                ",
      "            k   ",
      "      k         "
    ],
    [
      "                ",
      "                ",
      "                ",
      "                ",
      "                ",
      "                ",
      "                ",
      "             k  ",
      "       s        ",
      "                ",
      "            k   ",
      "             k  ",
      "          s     ",
      "                ",
      "            k   ",
      "      s         "
    ],
    [
      "                ",
      "                ",
      "                ",
      "                ",
      "                ",
      "                ",
      "                ",
      "             s  ",
      "                ",
      "                ",
      "            s   ",
      "             k  ",
      "                ",
      "                ",
      "            s   ",
      "                "
    ]
  ]
}