{
  "name": "multi_sunkenmonumentpark_12_ground",
  "refpalette": "deceasedcraft:multi_sunkenmonumentpark_12/multi_sunkenmonumentpark_12_ground_palette",
  "xsize": 16,
  "zsize": 16,
  "slices": [
    [
      "aaaaaaaaaaaaaaaa",
      "aaaaaaaaaaaaaaba",
      "ccccccccccccaaaa",
      "cccccccccccccaaa",
      "ddddddddccccccaa",
      "        ddccccaa",
      "  e  fe   dcccaa",
      "      g e dcccaa",
      "      g    dccaa",
      "h      ee  dccaa",
      " h     g egdccaa",
      "   h i     dccaa",
      "        gg dccaa",
      "j    h    edccaa",
      " j         dccaa",
      "j        gfdccaa"
    ],
    [
      "                ",
      " g   g          ",
      " e   e gg g     ",
      "   e     e      ",
      "           f    ",
      "            e   ",
      "  h  ih      g  ",
      "        h       ",
      "             g  ",
      "j      hh    e  ",
      " j       h      ",
      "   j h          ",
      "                ",
      "j    j    h e   ",
      " j              ",
      "j         i  e  "
    ],
    [
      "                ",
      "                ",
      " h   h          ",
      "   h     h      ",
      "           i    ",
      "            h   ",
      "  j  hj         ",
      "        j       ",
      "                ",
      "j      jj    h  ",
      " j       j      ",
      "   j j          ",
      "                ",
      "k    j    j h   ",
      " k              ",
      "j         h  h  "
    ],
    [
      "                ",
      "                ",
      " j   j          ",
      "   j     j      ",
      "           h    ",
      "            j   ",
      "  j  jj         ",
      "        j       ",
      "                ",
      "k      jj    j  ",
      " k       j      ",
      "   k j          ",
      "                ",
      "     k    j j   ",
      "                ",
      "k         j  j  "
    ],
    [
      "                ",
      "                ",
      " j   j          ",
      "   j     j      ",
      "           j    ",
      "            j   ",
      "  k  jk         ",
      "        k       ",
      "                ",
      "       kk    j  ",
      " j       k      ",
      "     k          ",
      "                ",
      "          k j   ",
      "                ",
      "          j  j  "
    ],
    [
      "                ",
      "                ",
      " k   j          ",
      "   k     k      ",
      "           j    ",
      "            k   ",
      "                ",
      "                ",
      "                ",
      "             j  ",
      " j              ",
      "                ",
      "                ",
      "            k   ",
      "                ",
      "          k  k  "
    ]
  ]
}