{
  "name": "multi_sunkenmonumentpark_12_base1",
  "refpalette": "deceasedcraft:multi_sunkenmonumentpark_12/multi_sunkenmonumentpark_12_base1_palette",
  "xsize": 16,
  "zsize": 16,
  "slices": [
    [
      "vvvvvvvvvvvvvvvv",
      "aaaaaaaaaaaaaaav",
      "aaaaaaaaaaaaaaav",
      "aaaaaaaaaaaaaaav",
      "aaaaaaaaaaaaaaav",
      "aaaaaaaaaaaaaaav",
      "aaaaaaaaaaaaaaav",
      "aaaaaaaaaaaaaaav",
      "aaaaaaaaaaaaaaav",
      "aaaaaaaaaaaaaaav",
      "aaaaaaaaaaaaaaav",
      "aaaaaaaaaaaaaaav",
      "aaaaaaaaaaaaaaav",
      "aaaaaaaaaaaaaaav",
      "aaaaaaaaaaaaaaav",
      "aaaaaaaaaaaaaaav"
    ],
    [
      "vvvvvvvvvvvvvvvv",
      "aaaaaaaaaaaaaaav",
      "aaaaaaaaaaaaaaav",
      "aaaaaaaaaaaaaaav",
      "aaaaaaaaaaaaaaav",
      "aaaaaaaaaaaaaaav",
      "aaaaaaaaaaaaaaav",
      "aaaaaaaaaaaaaaav",
      "aaaaaaaaaaaaaaav",
      "aaaaaaaaaaaaaaav",
      "aaaaaaaaaaaaaaav",
      "aaaaaaaaaaaaaaav",
      "aaaaaaaaaaaaaaav",
      "aaaaaaaaaaaaaaav",
      "aaaaaaaaaaaaaaav",
      "aaaaaaaaaaaaaaav"
    ],
    [
      "vvvvvvvvvvvvvvvv",
      "aaaaaaaaaaaaaaav",
      "aaaaaaaaaaaaaaav",
      "aaaaaaaaaaaaaaav",
      "aaaaaaaaaaaaaaav",
      "aaaaaaaaaaaaaaav",
      "aaaaaaaaaaaaaaav",
      "aaaaaaaaaaaaaaav",
      "aaaaaaaaaaaaaaav",
      "aaaaaaaaaaaaaaav",
      "aaaaaaaaaaaaaaav",
      "aaaaaaaaaaaaaaav",
      "aaaaaaaaaaaaaaav",
      "aaaaaaaaaaaaaaav",
      "aaaaaaaaaaaaaaav",
      "aaaaaaaaaaaaaaav"
    ],
    [
      "vvvvvvvvvvvvvvvv",
      "aaaaaaaaaaaaaaav",
      "aaaaaaaaaaaaaaav",
      "aaaaaaaaaaaaaaav",
      "aaaaaaaaaaaaaaav",
      "aaaaaaaaaaaaaaav",
      "aaaaaaaaaaaaaaav",
      "aaaaaaaaaaaaaaav",
      "aaaaaaaaaaaaaaav",
      "aaaaaaaaaaaaaaav",
      "aaaaaaaaaaaaaaav",
      "baaaaaaaaaaaaaav",
      "bbaaaaaaaaaaaaav",
      "bbbaaaaaaaaaaaav",
      "bbbbaaaaaaaaaaav",
      "bbbbbaaaaaaaaaav"
    ],
    [
      "vvvvvvvvvvvvvvvv",
      "               v",
      "               v",
      "               v",
      "               v",
      "               v",
      "               v",
      "bbb            v",
      "bbbbb          v",
      "bbbbbbb        v",
      "bbbbbbb        v",
      "cbbbbbbb       v",
      " cbbbbbb       v",
      "d cbbbbbb      v",
      " d cbbbbb      v",
      "d   cbbbb      v"
    ],
    [
      "vvvvvvvvvvvvvvvv",
      "               v",
      "               v",
      "               v",
      "bbbbbbbb       v",
      "bbbbbbbbbb     v",
      "bbbbbbbbbbb    v",
      "cccbbbbbbbb    v",
      "  eccbbbbbbb   v",
      "d    ccbbbbb   v",
      " d    cbbbbb   v",
      "   d f cbbbb   v",
      "       cbbbb   v",
      "g    d  cbbb   v",
      " g   ee cbbb   v",
      "g       cbbb   v"
    ]
  ]
}