{
  "name": "multi_pumpjack_2_ground",
  "refpalette": "deceasedcraft:multi_pumpjack_2/multi_pumpjack_2_ground_palette",
  "xsize": 16,
  "zsize": 16,
  "slices": [
    [
      "zzzzzzzzzzzzzzzz",
      "zzzzzzzzzzzzzzzz",
      "zzzzzzzzzzzzzzzz",
      "zzzzzzzzzzzzzzzz",
      "zzzz=======zzzzz",
      "zzzz=======zzzzz",
      "z!zz=======zzzzz",
      "zzzz=======zzzzz",
      "zzzz=======zzzzz",
      "zzzz=======zzzzz",
      "zzzz=======zzzzz",
      "zzzzzzzzzzzzzzzz",
      "zzzzzzzzzzzzzzzz",
      "zzzzzzzzzzzzzzzz",
      "zzzzzzzzzzzzzzzz",
      "zzzzzzzzzzzzzzzz"
    ],
    [
      " a        a a   ",
      "b   a a a     a ",
      "bcccbcccbcccb   ",
      "d e  f      c a ",
      "dgghiii jkl c   ",
      "dhmni    ol c a ",
      "dh   e      ba  ",
      "di       p  c   ",
      "dk        q c a ",
      "dr f      e c a ",
      "d    s~t    b   ",
      "d uw   x    ca  ",
      "d y         c   ",
      "d   AB   r  c a ",
      "d           b   ",
      "d      r  CCDe a"
    ],
    [
      "                ",
      "b               ",
      "bEEEbEEEbEEEb   ",
      "            E   ",
      " FFii    I  E   ",
      " mJ         E   ",
      "            b   ",
      " o          E   ",
      "            E   ",
      "            E   ",
      "      ~     b   ",
      "            E   ",
      "            E   ",
      "            E   ",
      "            b   ",
      "            E   "
    ],
    [
      "                ",
      "b               ",
      "bEEEbE EbEEEb   ",
      "            E   ",
      "            E   ",
      "            E   ",
      "            b   ",
      "            E   ",
      "            E   ",
      "            E   ",
      "      ~     b   ",
      "            E   ",
      "            E   ",
      "            E   ",
      "            b   ",
      "                "
    ],
    [
      "                ",
      "b               ",
      "b   K   K   K   ",
      "                ",
      "                ",
      "                ",
      "            K   ",
      "                ",
      "                ",
      "                ",
      "            K   ",
      "                ",
      "                ",
      "                ",
      "            K   ",
      "                "
    ],
    [
      "                ",
      "b               ",
      "b               ",
      "                ",
      "                ",
      "                ",
      "                ",
      "                ",
      "                ",
      "                ",
      "      ~         ",
      "                ",
      "                ",
      "                ",
      "                ",
      "                "
    ]
  ]
}