{
  "name": "multi_cabin3_1_floor1",
  "refpalette": "deceasedcraft:multi_cabin3_1/multi_cabin3_1_floor1_palette",
  "xsize": 16,
  "zsize": 16,
  "slices": [
    [
      "aaaaaaaaaaaaaaaa",
      "baaaaaaaaaaaaaaa",
      "bacaaaacaaaacaaa",
      "ddddddddddddaaaa",
      "eeeeeeeeeeedaaaa",
      "eeeeeeeeeeedaaaa",
      "ddddddddddddaaaa",
      "bacfffacaaaacaaa",
      "abaaaaaaaaaaaaaa",
      "bbbaaaaaaaaaaaaa",
      "bbaaaaaaaaaaaaaa",
      "baaaaaaaaaaaaaaa",
      "baaaaaaaaaaaaaaa",
      "aafaaaafaaaafaaa",
      "aaaaaaaaaaaaaaaa",
      "aaaaaaaaaaaaaaaa"
    ],
    [
      "gggggggggggggggg",
      "gggggggggggggggg",
      "ghchhhhchhhhcggg",
      "ijkjjjjljjjjgggg",
      "ggggggggmnojgggg",
      "ggggggggmnojgggg",
      "pjqjjjjrjjjjgggg",
      "ghcsttucggggcggg",
      "ggvgggggggggvggg",
      "ggwgggggggggvggg",
      "ggvgggggggggvggg",
      "gxvgggggggggvggg",
      "gyvgggggggggvggg",
      "vvcvvvvcvvvvcggg",
      "gggggggggggggggg",
      "gggggggggggggggg"
    ],
    [
      "gggggggggggggggg",
      "gggggggggzzABBgg",
      "ggcggggcgzzABBgg",
      "CjDjEEjgFFFGBBgg",
      "gggggggggHHGBBgg",
      "gggggggggHHGBBgg",
      "IjgjEEjJFFFGBBgg",
      "ggcggggcgzzABBgg",
      "gggggggggzzABBgg",
      "gggggggggggggggg",
      "gggggggggggggggg",
      "gggggggggggggggg",
      "gggggggggggggggg",
      "ggKggggKggggKggg",
      "gggggggggggggggg",
      "gggggggggggggggg"
    ],
    [
      "gggggggggggggggg",
      "ggggzzABBggggggg",
      "ggcgzzABBggggggg",
      "jjDFLLGMMggggggg",
      "ggggHHGMMggggggg",
      "ggggHHGMMggggggg",
      "jjJFNNGMMggggggg",
      "ggcgzzABBggggggg",
      "ggggzzABBggggggg",
      "gggggggggggggggg",
      "gggggggggggggggg",
      "gggggggggggggggg",
      "gggggggggggggggg",
      "gggggggggggggggg",
      "gggggggggggggggg",
      "gggggggggggggggg"
    ],
    [
      "gggggggggggggggg",
      "zABBgggggggggggg",
      "zABBgggggggggggg",
      "FGMMgggggggggggg",
      "HGMMgggggggggggg",
      "HGMMgggggggggggg",
      "FGMMgggggggggggg",
      "zABBgggggggggggg",
      "zABBgggggggggggg",
      "gggggggggggggggg",
      "gggggggggggggggg",
      "gggggggggggggggg",
      "gggggggggggggggg",
      "gggggggggggggggg",
      "gggggggggggggggg",
      "gggggggggggggggg"
    ],
    [
      "gggggggggggggggg",
      "gggggggggggggggg",
      "gggggggggggggggg",
      "gggggggggggggggg",
      "gggggggggggggggg",
      "gggggggggggggggg",
      "gggggggggggggggg",
      "gggggggggggggggg",
      "gggggggggggggggg",
      "gggggggggggggggg",
      "gggggggggggggggg",
      "gggggggggggggggg",
      "gggggggggggggggg",
      "gggggggggggggggg",
      "gggggggggggggggg",
      "gggggggggggggggg"
    ]
  ]
}