{
  "name": "multi_verticalschool_13_floor7",
  "refpalette": "deceasedcraft:multi_verticalschool_13/multi_verticalschool_13_floor7_palette",
  "xsize": 16,
  "zsize": 16,
  "slices": [
    [
      "                ",
      "                ",
      "                ",
      "                ",
      "                ",
      "                ",
      "                ",
      "                ",
      "                ",
      "                ",
      "                ",
      "                ",
      "                ",
      "                ",
      "            aaa ",
      "                "
    ],
    [
      "                ",
      "                ",
      "                ",
      "                ",
      "                ",
      "                ",
      "                ",
      "                ",
      "                ",
      "                ",
      "                ",
      "                ",
      "                ",
      "                ",
      "            aaa ",
      "                "
    ],
    [
      "        bbbbbbbb",
      "        bbbbbbbb",
      "        bbbbbbbb",
      "        bbbbbbbb",
      "        bbbbbbbb",
      "        bbbbbbbb",
      "        bbbbbbbb",
      "        bbbbbbbb",
      "        bbbbbbbb",
      "        bbbbbbbb",
      "        bbbbbbbb",
      "        bbbbbbbb",
      "        bbbbbbbb",
      "        bbbbbbbb",
      "        bbbbaaab",
      "bbbbbbbbbbbbbbbb"
    ],
    [
      "      bccccccccc",
      "      bccccccccc",
      "      bccccccccc",
      "      bccccccccc",
      "      bccccccccc",
      "      bccccccccc",
      "      bccccccccc",
      "      bccccccccc",
      "      bccccccccc",
      "      bccccccccc",
      "      bccccccccc",
      "      bccccccccc",
      "      bccccccccc",
      "      bccccccccc",
      "      bcccccaaac",
      "cccccccccccccccd"
    ],
    [
      "    bceeed  fdcc",
      "    bceeed   dcg",
      "    bceeed   dcg",
      "    bceeedhijdcg",
      "    bceeed   dcg",
      "    bceeed   dcc",
      "    bceeed  fdcc",
      "    bceeedhijdcc",
      "    bceeeed fdcc",
      "    bceeeeedddcc",
      "    bceeeeeeeegk",
      "    bceeeeeeeegk",
      "    bceeeeeeeecc",
      "    bceeeccccccc",
      "    bcccccccaaac",
      "ccccccccccccccc "
    ],
    [
      "  bcee   dddddgc",
      "  bcee   dddddlm",
      "  bceen  dddddl ",
      "  bceen  dddddlo",
      "  bceen  dddddl ",
      "  bceep  dddddgc",
      "  bceee  dddddgk",
      "  bceee  dddddgc",
      "  bceee  qqdddgc",
      "  bceee    dddgc",
      "  bceee       r ",
      "  bceee       s ",
      "  bceee ttttttgc",
      "  bceeettu w  gc",
      "  bcccc     aaac",
      "ccccccccccccccc "
    ]
  ]
}