{
  "name": "multi_verticalschool_13_floor25",
  "refpalette": "deceasedcraft:multi_verticalschool_13/multi_verticalschool_13_floor25_palette",
  "xsize": 16,
  "zsize": 16,
  "slices": [
    [
      "abbbbbbbbbbbbbac",
      "abbbbbbbbbbbbbac",
      "abbbbbbbbbbbbbac",
      "abbbbbbbbbbbbbac",
      "abbbbbbbbbbbbbac",
      "abbbbbbbbbbbbbac",
      "abbbbbbbbbbbbbac",
      "abbbbbbbbbbbbbac",
      "abbbbbbbbbbbbbac",
      "abbbbbbbbbbbbbac",
      "abbbbbbbbbbbbbac",
      "abbbbbbbbbbbbbac",
      "abbbbbbbbbbbbbac",
      "abbbbbbbbbbbbbac",
      "aaaaaaaaaaaadddc",
      "cccccccccccccccc"
    ],
    [
      "a          effag",
      "h   ij   ij   ag",
      "k  lmn  lmn   ag",
      "ao  pqr  pqr  ag",
      "as lpq  lpq   ag",
      "at  pqr  pqr  ag",
      "aq lpq  lpq   ag",
      "aq  pqr  pqr  ag",
      "at lpq  lpq   ag",
      "au  wxr  wxr  ag",
      "ay  yy   yy   ag",
      "h           o ag",
      "k          AnBag",
      "a          Cu ag",
      "aaaaaaaaaaaadddg",
      "DDDDDDDDDDDDDDDD"
    ],
    [
      "E          eFFE ",
      "I             E ",
      "J   KL   KL   M ",
      "E   NO   NO   M ",
      "E   KL   !L   M ",
      "M   NO   NO   M ",
      "M   KL   KL   E ",
      "M   NO   NO   E ",
      "M   KL   KL   M ",
      "EP  NO   NO   M ",
      "E             M ",
      "I             M ",
      "J           Q E ",
      "E     RRR   S E ",
      "EEEEEEEEEEEEddd ",
      "                "
    ],
    [
      "E          eTUE ",
      "M             E ",
      "M             M ",
      "E             M ",
      "E             M ",
      "M             M ",
      "M             E ",
      "M             E ",
      "M             M ",
      "E             M ",
      "E             M ",
      "M             M ",
      "M             E ",
      "EV    RRR     E ",
      "EEEEEEEEEEEEddd ",
      "                "
    ],
    [
      "E            WE ",
      "E             E ",
      "E             E ",
      "E             E ",
      "E             E ",
      "E             E ",
      "E             E ",
      "E             E ",
      "E      X      E ",
      "E             E ",
      "E             E ",
      "E             E ",
      "E             E ",
      "EY            E ",
      "EEEEEEEEEEEEddd ",
      "                "
    ],
    [
      "EZZZZZZZZZZZZZE0",
      "EZZZZZZZZZZZZZE0",
      "EZZ111ZZZ111ZZE0",
      "EZZZZZZZZZZZZZE0",
      "EZZZZZZZZZZZZZE0",
      "EZZ111ZZZ111ZZE0",
      "EZZZZZZZZZZZZZE0",
      "EZZZZZZZZZZZZZE0",
      "EZZ111ZZZ111ZZE0",
      "EZZZZZZZZZZZZZE0",
      "EZZZZZZZZZZZZZE0",
      "EZZ111ZZZ111ZZE0",
      "EZZZZZZZZZZZZZE0",
      "EZZZZZZZZZZZZZE0",
      "EEEEEEEEEEEEddd0",
      "0000000000000000"
    ]
  ]
}