{
  "name": "multi_verticalschool_13_floor22",
  "refpalette": "deceasedcraft:multi_verticalschool_13/multi_verticalschool_13_floor22_palette",
  "xsize": 16,
  "zsize": 16,
  "slices": [
    [
      "             abc",
      "             abc",
      "             abc",
      "             abc",
      "             abc",
      "             abc",
      "             abc",
      "             abc",
      "             abc",
      "             abc",
      "             abc",
      "             abc",
      "             abc",
      "aaaaaaaaaaaaabbc",
      "bbbbbbbbbbbbdddc",
      "ccccccccccccccc "
    ],
    [
      "             efc",
      "             efc",
      "             efc",
      "             efc",
      "             efc",
      "             efc",
      "             efc",
      "             efc",
      "             efc",
      "             efc",
      "             efc",
      "             efc",
      "             efc",
      "eeeeeeeeeeeeefac",
      "ffffffffffffdddc",
      "cccccccccccccccg"
    ],
    [
      "             hhh",
      "             hhh",
      "             hhh",
      "             hhh",
      "             hhh",
      "             hhh",
      "             hhh",
      "             hhh",
      "             hhh",
      "             hhh",
      "             hhh",
      "             hhh",
      "             hhh",
      "hhhhhhhhhhhhhhhh",
      "hhhhhhhhhhhhdddi",
      "hhhhhhhhhhhhhhhh"
    ],
    [
      "             j  ",
      "             j k",
      "             j k",
      "             j  ",
      "             j  ",
      "             j  ",
      "             j l",
      "             j l",
      "             j  ",
      "             j  ",
      "             j  ",
      "             j l",
      "             j l",
      "jjjjjjjjjjjjjj  ",
      " mnop qmnop dddr",
      "                "
    ],
    [
      "                ",
      "                ",
      "                ",
      "                ",
      "                ",
      "                ",
      "                ",
      "                ",
      "                ",
      "                ",
      "                ",
      "                ",
      "                ",
      "                ",
      "    s     t dddu",
      "                "
    ],
    [
      "                ",
      "                ",
      "                ",
      "                ",
      "                ",
      "                ",
      "                ",
      "                ",
      "                ",
      "                ",
      "                ",
      "                ",
      "                ",
      "                ",
      "            dddw",
      "                "
    ]
  ]
}