{
  "name": "multi_verticalschool_13_floor9",
  "refpalette": "deceasedcraft:multi_verticalschool_13/multi_verticalschool_13_floor9_palette",
  "xsize": 16,
  "zsize": 16,
  "slices": [
    [
      "           a  bc",
      "           a  bc",
      "           adebc",
      "           a  bc",
      "           a  bc",
      "              bc",
      "              bc",
      "             fbc",
      "             gbc",
      "             hbc",
      "              bc",
      "              bc",
      "        iiiiiibc",
      "  iiiiiiij k  bc",
      "iiij k      lllc",
      "cccccccccccccccm"
    ],
    [
      "           a  bc",
      "           a  bc",
      "           anobc",
      "           a  bc",
      "           a  bc",
      "              bc",
      "              bc",
      "             pbc",
      "             gbc",
      "             qbc",
      "              bc",
      "              bc",
      "        iiiiiibc",
      "  iiiiiiij k  bc",
      "iiij k      lllc",
      "ccccccccccccccc "
    ],
    [
      "           a  bc",
      "           a  bc",
      "           a  bc",
      "           a  bc",
      "           a  bc",
      "              bc",
      "              bc",
      "              bc",
      "             rbc",
      "              bc",
      "              bc",
      "              bc",
      "        iiiiiibc",
      "  iiiiiiij k  bc",
      "iiij k      lllc",
      "ccccccccccccccc "
    ],
    [
      "              bc",
      "              bc",
      "              bc",
      "              bc",
      "              bc",
      "              bc",
      "              bc",
      "              bc",
      "              bc",
      "              bc",
      "              bc",
      "              bc",
      "        iiiiiibc",
      "  iiiiiiij k  bc",
      "iiij k      lllc",
      "ccccccccccccccc "
    ],
    [
      "              bc",
      "              bc",
      "              bc",
      "              bc",
      "              bc",
      "              bc",
      "              bc",
      "              bc",
      "              bc",
      "              bc",
      "              bc",
      "              bc",
      "        iiiiiibc",
      "  iiiiiiij k  bc",
      "iiij k      lllc",
      "cccccccccccccccs"
    ],
    [
      "        ttttttbc",
      "        ttttttbc",
      "        ttttttbc",
      "        ttttttbc",
      "        ttttttbc",
      "        ttttttbc",
      "        ttttttbc",
      "        ttttttbc",
      "        ttttttbc",
      "        ttttttbc",
      "        ttttttbc",
      "        ttttttbc",
      "        uwwwwwbc",
      "  iiiiiiij k  bc",
      "iiij k      lllc",
      "cccccccccccccccx"
    ]
  ]
}