{
  "name": "multi_verticalschool_13_floor3",
  "refpalette": "deceasedcraft:multi_verticalschool_13/multi_verticalschool_13_floor3_palette",
  "xsize": 16,
  "zsize": 16,
  "slices": [
    [
      "   aaaaa   aaaaa",
      "                ",
      "               b",
      "              b ",
      "             b  ",
      "            b   ",
      "           b    ",
      "          b     ",
      "         b      ",
      "        b       ",
      "       b        ",
      "      b         ",
      "     b          ",
      "    b           ",
      "   b        ccc ",
      "  b             "
    ],
    [
      "                ",
      "                ",
      "               b",
      "              b ",
      "             b  ",
      "            b   ",
      "           b    ",
      "          b     ",
      "         b      ",
      "        b       ",
      "       b        ",
      "      b         ",
      "     b          ",
      "    b           ",
      "   b        ccc ",
      "  b             "
    ],
    [
      "                ",
      "                ",
      "               b",
      "              b ",
      "             b  ",
      "            b   ",
      "           b    ",
      "          b     ",
      "         b      ",
      "        b       ",
      "       b        ",
      "      b         ",
      "     b          ",
      "    b           ",
      "   b        ccc ",
      "  b             "
    ],
    [
      "                ",
      "                ",
      "               b",
      "              bd",
      "             bdd",
      "            bddd",
      "           bdddd",
      "          bddddd",
      "         bdddddd",
      "        bddddddd",
      "       bdddddddd",
      "      bddddddddd",
      "     bdddddddddd",
      "    bddddddddddd",
      "   bddddddddcccd",
      "  bdddddddddddde"
    ],
    [
      "ffffffffffffffff",
      "ffffffffffffffff",
      "fffffffffffffffg",
      "ffffffffffffffgh",
      "fffifffifffifghh",
      "ffffffffffffghhh",
      "fffffffffffghhhj",
      "ffffffffffghhhhj",
      "fffffffffghhhhgj",
      "fffiffffghhhhhjj",
      "fffffffghhhhhjjj",
      "ffffffghhhhhjjjj",
      "fffffghhhhhjjjjj",
      "ffffghhhhhjjjj!j",
      "fffghhhhgjjjcccj",
      "ffghhhjjjjjjjjjj"
    ],
    [
      "jkjkkkkkkkkjjjjl",
      "jjkkkkkkkkjjjjll",
      "jjkkkkkkkkjkjlll",
      "jkkkkkkkkjjjlljl",
      "kkkkkkkkkjjlljjl",
      "kkkkkkkjjjlljjll",
      "kkkkkkjjjlljjjlm",
      "kkkkkjkklljjjlln",
      "kkkkjjjlljjjjlop",
      "kkkjjjlljjjjllmp",
      "kkjkjlljjjjllmpp",
      "kjjjlljjjjllnpp ",
      "kjjlljjjjllmppqp",
      "jjlljjjlllnpp  q",
      "jlljjlllon qcccp",
      "llllllnmqpppp pq"
    ]
  ]
}