{
  "name": "multi_verticalschool_13_floor30",
  "refpalette": "deceasedcraft:multi_verticalschool_13/multi_verticalschool_13_floor30_palette",
  "xsize": 16,
  "zsize": 16,
  "slices": [
    [
      "aaaaaaaaaaaaaaab",
      "ccccccccccccccab",
      "cddddddddddddcab",
      "cddddddcccccccab",
      "cdddddcddddddcab",
      "cddddcdddddddcab",
      "ecdddcdcccccccab",
      "ecdddccdcddddcab",
      "fcdddcdcccccccab",
      "cddddcdddddddcab",
      "cdddddcddddddcab",
      "cddddddcccccccab",
      "cddddddddddddcab",
      "ccccccccccccccab",
      "aaaaaaaaaaaagggb",
      "bbbbbbbbbbbbbbbb"
    ],
    [
      "                ",
      "                ",
      "                ",
      "                ",
      "                ",
      "                ",
      "                ",
      "                ",
      "                ",
      "                ",
      "                ",
      "                ",
      "                ",
      "                ",
      "            ggg ",
      "              h "
    ],
    [
      "                ",
      "                ",
      "                ",
      "                ",
      "                ",
      "                ",
      "                ",
      "                ",
      "                ",
      "                ",
      "                ",
      "                ",
      "                ",
      "                ",
      "            ggg ",
      "             i  "
    ],
    [
      "                ",
      "                ",
      "                ",
      "                ",
      "                ",
      "                ",
      "                ",
      "                ",
      "                ",
      "                ",
      "                ",
      "                ",
      "                ",
      "                ",
      "            ggg ",
      "                "
    ],
    [
      "                ",
      "                ",
      "                ",
      "                ",
      "                ",
      "                ",
      "                ",
      "             jk ",
      "                ",
      "                ",
      "                ",
      "                ",
      "                ",
      "                ",
      "            ggg ",
      "                "
    ],
    [
      "                ",
      "                ",
      "                ",
      "                ",
      "                ",
      "                ",
      "             l  ",
      "             mn ",
      "             l  ",
      "                ",
      "                ",
      "                ",
      "                ",
      "                ",
      "            ggg ",
      "                "
    ]
  ]
}