{
  "name": "multi_verticalschool_13_floor15",
  "refpalette": "deceasedcraft:multi_verticalschool_13/multi_verticalschool_13_floor15_palette",
  "xsize": 16,
  "zsize": 16,
  "slices": [
    [
      "aaaaaaaaaaaaaabc",
      "aaaaaaaaaaaaaabc",
      "             abc",
      "             abc",
      "             abc",
      "             abc",
      "             abc",
      "             abc",
      "             abc",
      "             abc",
      "             abc",
      "             abc",
      "aaaaaaaaaaaaaabc",
      "aaaaaaaaaaaaaabc",
      "ccccccccccccdddc",
      "ccccccccccccccc "
    ],
    [
      "eeeeeeeeeeeeeefc",
      "ggggggggggggggfc",
      "ggggggggggggggfc",
      "ggggggggggggggfc",
      "ggggggggggggggfc",
      "ggggggggggggggfc",
      "ggggggggggggggfc",
      "ggggggggggggggfc",
      "ggggggggggggggfc",
      "ggggggggggggggfc",
      "ggggggggggggggfc",
      "ggggggggggggggfc",
      "ggggggggggggggfc",
      "eeeeeeeeeeeeeefc",
      "ccccccccccccdddc",
      "ccccccccccccccc "
    ],
    [
      "hhhhhhhhhhhhhhhc",
      "hhhhhhhhhhhhhhhc",
      "hhhhhhhhhhhhhhhc",
      "hhhhhhhhhhhhhhhc",
      "hhhhhhhhhhhhhhhc",
      "hhhhhhhhhhhhhhhc",
      "hhhhhhhhhhhhhhhc",
      "hhhhhhhhhhhhhhhc",
      "hhhhhhhhhhhhhhhc",
      "hhhhhhhhhhhhhhhc",
      "hhhhhhhhhhhhhhhc",
      "hhhhhhhhhhhhhhhc",
      "hhhhhhhhhhhhhhhc",
      "hhhhhhhhhhhhhhhc",
      "hhhhhhhhhhhhdddc",
      "ccccccccccccccci"
    ],
    [
      "jhhhhhhhhhhhhhhk",
      "jhhhhhhhhhhhhhhk",
      "jhhhhhhhhhhhhhhk",
      "jhhhhhhhhhhhhhhk",
      "jhhhhhhhhhhhhhhk",
      "jhhhhhhhhhhhhhhl",
      "jhhhhhhhhhhhhhhm",
      "jhhhhhhhhhhhhhhm",
      "jhhhhhhhhhhhhhhl",
      "jhhhhhhhhhhhhhhk",
      "jhhhhhhhhhhhhhhk",
      "jhhhhhhhhhhhhhhk",
      "hhhhhhhhhhhhhhhk",
      "hhhhhhhhhhhhhhhk",
      "hhhhhhhhhhhhdddk",
      "mmmmmmmmmmlmmlmm"
    ],
    [
      "lnopo       pppq",
      "lnopo       oooq",
      "ln      r      q",
      "ln     spt  oooq",
      "ln      u   pppq",
      "lnopo       ooow",
      "lnopo   r       ",
      "lnopo  spt      ",
      "lnopo   u   ooox",
      "lnopo       pppq",
      "ln          oooq",
      "ln      r      q",
      "y      spt  oooq",
      "        u   pppq",
      "            ddd ",
      "                "
    ],
    [
      "A  B         C D",
      "E              D",
      "F              D",
      "               D",
      "A            IJD",
      "A               ",
      "K  L            ",
      "F  M    N       ",
      "                ",
      "K  O         PQD",
      "               D",
      "A              D",
      "               D",
      "             R D",
      "            ddd ",
      "                "
    ]
  ]
}