{
  "name": "multi_verticalschool_13_floor28",
  "refpalette": "deceasedcraft:multi_verticalschool_13/multi_verticalschool_13_floor28_palette",
  "xsize": 16,
  "zsize": 16,
  "slices": [
    [
      "abbbbbbbbbbbbbac",
      "abbbbbbbbbbbbbac",
      "abbbbbbbbbbbbbac",
      "abbbbbbbbbbbbbac",
      "abbbbbbbbbbbbbac",
      "abbbbbbbbbbbbbac",
      "abbbbbbbbbbbbbac",
      "abbbbbbbbbbbbbac",
      "abbbbbbbbbbbbbac",
      "abbbbbbbbbbbbbac",
      "abbbbbbbbbbbbbac",
      "abbbbbbbbbbbbbac",
      "abbbbbbbbbbbbbac",
      "abbbbbbbbbbbbbac",
      "aaaaaaaaaaaadddc",
      "cccccccccccccccc"
    ],
    [
      "a           eeaf",
      "g           heaf",
      "i             af",
      "a    jk k    laf",
      "a     m n     af",
      "ao  kp q rk   af",
      "as     t      af",
      "au  w  t  x   af",
      "ay  kp A Bk   af",
      "a     C D     af",
      "a     k kw    af",
      "g             af",
      "i             af",
      "aEF   IJK   EFaf",
      "aaaaaaaaaaaadddf",
      "LLLLLLLLLLLLLLLL"
    ],
    [
      "M  NO N NO N !M ",
      "P             M ",
      "Q             R ",
      "M             R ",
      "M             R ",
      "R      S      R ",
      "R      T      M ",
      "R      U      M ",
      "R      V      R ",
      "M             R ",
      "M             R ",
      "P             R ",
      "Q             M ",
      "M W X YZ  0 12M ",
      "MMMMMMMMMMMMddd ",
      "                "
    ],
    [
      "M  34 5 64 7 hM ",
      "R             M ",
      "R             R ",
      "M             R ",
      "M             R ",
      "R             R ",
      "R             M ",
      "R             M ",
      "R             R ",
      "M             R ",
      "M             R ",
      "R             R ",
      "R             M ",
      "M8  9     9   M ",
      "MMMMMMMMMMMMddd ",
      "                "
    ],
    [
      "M             M ",
      "M             M ",
      "M             M ",
      "M             M ",
      "M             M ",
      "M             M ",
      "M             M ",
      "M             M ",
      "M             M ",
      "M             M ",
      "M             M ",
      "M             M ",
      "M             M ",
      "M#  $     $   M ",
      "MMMMMMMMMMMMddd ",
      "                "
    ],
    [
      "M%%%%%%%%%%%%%M^",
      "M%%%%%%%%%%%%%M^",
      "M%%&&&%%%&&&%%M^",
      "M%%%%%%%%%%%%%M^",
      "M%%%%%%%%%%%%%M^",
      "M%%&&&%%%&&&%%M^",
      "M%%%%%%%%%%%%%M^",
      "M%%%%%%%%%%%%%M^",
      "M%%&**%%%*&&%%M^",
      "M%%%%%%%%%%%%%M^",
      "M%%%%%%%%%%%%%M^",
      "M%%&&*%%%&&&%%M^",
      "M%%%%%%%%%%%%%M^",
      "M%%%%%%%%%%%%%M^",
      "MMMMMMMMMMMMddd^",
      "^^^^^^^^^^^^^^^^"
    ]
  ]
}