{
  "name": "multi_verticalschool_13_floor23",
  "refpalette": "deceasedcraft:multi_verticalschool_13/multi_verticalschool_13_floor23_palette",
  "xsize": 16,
  "zsize": 16,
  "slices": [
    [
      "                ",
      "                ",
      "                ",
      "                ",
      "                ",
      "                ",
      "                ",
      "                ",
      "                ",
      "                ",
      "                ",
      "                ",
      "                ",
      "                ",
      "            aaa ",
      "                "
    ],
    [
      "bbbbbbbbbbbbbcdd",
      "bbbbbbbbbbbbbcdd",
      "bbbbbbbbbbbbbcdd",
      "bbbbbbbbbbbbbcdd",
      "bbbbbbbbbbbbbcdd",
      "bbbbbbbbbbbbbcdd",
      "bbbbbbbbbbbbbcdd",
      "bbbbbbbbbbbbbcdd",
      "bbbbbbbbbbbbbcdd",
      "bbbbbbbbbbbbbcdd",
      "bbbbbbbbbbbbbcdd",
      "bbbbbbbbbbbbbcdd",
      "bbbbbbbbbbbbbcdd",
      "bbbbbbbbbbbbbcdd",
      "ccccccccccccaaad",
      "dddddddddddddddd"
    ],
    [
      "eeeeeeefgghhhifj",
      "eeeeeeeffgkiiifj",
      "eeeeeeeefggllifj",
      "eeeeeeeeffgkiifj",
      "eeeeeeeeefggmifj",
      "eeeeeeeeeffgkifj",
      "neeeeeeeeefggifj",
      "eeeeeeeeeeffgkfj",
      "eeeeeeeeeeefggfj",
      "oneeeeeeeeeffgfj",
      "ooeeeeeeeeeefgfj",
      "ooeeeeeeeeeefffj",
      "oooeeeeeeeeeeffj",
      "oooeeeeeeeeeeffj",
      "oooeeeeeeeeeaaaj",
      "ooooeeeeeeeeeejj"
    ],
    [
      "       p      qr",
      "       s      qr",
      "              qr",
      "              qr",
      "              qr",
      "         tu   qr",
      "          p   qr",
      "          s   qr",
      "              qr",
      "              qr",
      "w             qr",
      "w           tuqr",
      "             pqr",
      "x            sqr",
      "xx          aaar",
      "yxx           Ar"
    ],
    [
      "               B",
      "                ",
      "               B",
      "               B",
      "               B",
      "         C     B",
      "               B",
      "               B",
      "                ",
      "               B",
      "               B",
      "            CD B",
      "               B",
      "               B",
      "            aaaB",
      "E              B"
    ],
    [
      "                ",
      "                ",
      "                ",
      "                ",
      "                ",
      "         F      ",
      "                ",
      "                ",
      "                ",
      "                ",
      "                ",
      "            F   ",
      "                ",
      "                ",
      "            aaa ",
      "                "
    ]
  ]
}