{
  "name": "multi_verticalschool_13_floor21",
  "refpalette": "deceasedcraft:multi_verticalschool_13/multi_verticalschool_13_floor21_palette",
  "xsize": 16,
  "zsize": 16,
  "slices": [
    [
      "    abbbbb bb a ",
      "    c         c ",
      "    c         c ",
      "    a         a ",
      "    c         c ",
      "    c         c ",
      "    c         c ",
      "    c         c ",
      "    c         c ",
      "    c         c ",
      "    a         a ",
      "    c         c ",
      "    c         c ",
      "    ad        a ",
      "    aaaaaaaaeee ",
      "                "
    ],
    [
      "    a         a ",
      "    a         a ",
      "    a         a ",
      "    a         a ",
      "    a         a ",
      "    a         a ",
      "    a         a ",
      "    a         a ",
      "    a         a ",
      "    a         a ",
      "    a         a ",
      "    a         a ",
      "    a         a ",
      "    a!        a ",
      "    aaaaaaaaeee ",
      "                "
    ],
    [
      "ffffagggggggggah",
      "ffffagggggggggah",
      "ffffagiggjggigah",
      "ffffagggggggggah",
      "ffffagggggggggah",
      "ffffagjggiggigah",
      "ffffagggggggggah",
      "ffffagggggggggah",
      "ffffagjggjggjgah",
      "ffffagggggggggah",
      "ffffagggggggggah",
      "ffffagjggjggjgah",
      "ffffagggggggggah",
      "ffffagggggggggah",
      "kkkkaaaaaaaaeeeh",
      "hhhhhhhhhhhhhhhh"
    ],
    [
      "llllllllllllllmm",
      "llllllllllllllmm",
      "llllllllllllllmm",
      "llllllllllllllmm",
      "llllllllllllllmm",
      "llllllllllllllmm",
      "llllllllllllllmm",
      "llllllllllllllmm",
      "llllllllllllllmm",
      "llllllllllllllmm",
      "llllllllllllllmm",
      "llllllllllllllmm",
      "llllllllllllllmm",
      "llllllllllllllmm",
      "mmmmmmmmmmmmeeem",
      "mmmmmmmmmmmmmmmm"
    ],
    [
      "             nop",
      "q   r r r r  nop",
      "    stttttu  nop",
      "wq  xxxxxxx  nop",
      "q   yAAAAAB  nop",
      "     C C C   nop",
      "             nop",
      "     r r r   nop",
      "q   stttttu  nop",
      "wq  xxxxxxx  nop",
      "q   yAAAAAB  nop",
      "     C C C   nop",
      "             nop",
      "nnnnnnnnnnnnnoop",
      "ooooooooooooeeep",
      "pppppppppppppppD"
    ],
    [
      "             nop",
      "             nop",
      "    E F  I   nop",
      "J   KKKKKKK  nop",
      "     LMLNLO  nop",
      "             nop",
      "             nop",
      "             nop",
      "    PQMQNQ   nop",
      "E   KKKKKKK  nop",
      "     LMLNLR  nop",
      "             nop",
      "             nop",
      "nnnnnnnnnnnnnoop",
      "ooooooooooooeeep",
      "ppppppppppppppp "
    ]
  ]
}