{
  "name": "multi_verticalschool_13_floor19",
  "refpalette": "deceasedcraft:multi_verticalschool_13/multi_verticalschool_13_floor19_palette",
  "xsize": 16,
  "zsize": 16,
  "slices": [
    [
      "    abbbbb bbba ",
      "    c         c ",
      "    c         c ",
      "    a         a ",
      "    c         c ",
      "    c         c ",
      "    c         c ",
      "    c         c ",
      "    c         c ",
      "    c         c ",
      "    a         a ",
      "    c         c ",
      "    c         c ",
      "    ad        a ",
      "    aaaaaaaaeee ",
      "                "
    ],
    [
      "    a         a ",
      "    a         a ",
      "    a         a ",
      "    a         a ",
      "    a         a ",
      "    a         a ",
      "    a         a ",
      "    a         a ",
      "    a         a ",
      "    a         a ",
      "    a         a ",
      "    a         a ",
      "    a         a ",
      "    af        a ",
      "    aaaaaaaaeee ",
      "                "
    ],
    [
      "    agggggggggah",
      "    agggggggggah",
      "    agiggjggigah",
      "    agggggggggah",
      "    agggggggggah",
      "    agiggiggigah",
      "    agggggggggah",
      "    agggggggggah",
      "    agjggiggigah",
      "    agggggggggah",
      "    agggggggggah",
      "    agiggiggjgah",
      "    agggggggggah",
      "    agggggggggah",
      "    aaaaaaaaeeeh",
      "hhhhhhhhhhhhhhhh"
    ],
    [
      "  klmnnnnnnnnnmo",
      "  klmnnnnnnnnnmo",
      "  klmnnnnnnnnnmo",
      "  klmnnnnnnnnnmo",
      "  klmnnnnnnnnnmo",
      "  klmnnnnnnnnnmo",
      "  klmnnnnnnnnnmo",
      "  klmnnnnnnnnnmo",
      "  klmnnnnnnnnnmo",
      "  klmnnnnnnnnnmo",
      "  klmnnnnnnnnnmo",
      "  klmnnnnnnnnnmo",
      "  klmnnnnnnnnnmo",
      "kkklmnnnnnnnnnmo",
      "llllmmmmmmmmeeeo",
      "oooooooooooooooo"
    ],
    [
      "  p mqqqqrqqsqm ",
      "  p t         m ",
      "  p u        wm ",
      "  p mw ww ww  m ",
      "  p mx yA yA xm ",
      "  p m         m ",
      "  p mw ww ww wm ",
      "  p mx yA yA xm ",
      "  p m         m ",
      "  p mw ww ww wm ",
      "  p mx yA yA xm ",
      "  p t         m ",
      "  p B    C    m ",
      "DD  mEFIIIIIJJm ",
      "    mmmmmmmmeee ",
      "    K           "
    ],
    [
      "    aqqssq!sqqa ",
      "    L         c ",
      "    M         c ",
      "    a         a ",
      "    cN NO PQ Nc ",
      "    c         c ",
      "    c         c ",
      "    cR  N SO Pc ",
      "    c         c ",
      "    c         c ",
      "    aO P  NN Sa ",
      "    L         c ",
      "    T         c ",
      "    aU!  V  W a ",
      "    aaaaaaaaeee ",
      "                "
    ]
  ]
}