{
  "name": "multi_verticalschool_13_floor26",
  "refpalette": "deceasedcraft:multi_verticalschool_13/multi_verticalschool_13_floor26_palette",
  "xsize": 16,
  "zsize": 16,
  "slices": [
    [
      "abbbbbbbbbbbbbac",
      "abbbbbbbbbbbbbac",
      "abbbbbbbbbbbbbac",
      "abbbbbbbbbbbbbac",
      "abbbbbbbbbbbbbac",
      "abbbbbbbbbbbbbac",
      "abbbbbbbbbbbbbac",
      "abbbbbbbbbbbbbac",
      "abbbbbbbbbbbbbac",
      "abbbbbbbbbbbbbac",
      "abbbbbbbbbbbbbac",
      "abbbbbbbbbbbbbac",
      "abbbbbbbbbbbbbac",
      "abbbbbbbbbbbbbac",
      "aaaaaaaaaaaadddc",
      "cccccccccccccccc"
    ],
    [
      "a          effag",
      "h   ij   ij   ag",
      "k  lmn  lmn   ag",
      "ao  pqr  pqr  ag",
      "as lpq  lpq   ag",
      "at  pqr  pqr  ag",
      "aq lpq  lpq   ag",
      "aq  pqr  pqr  ag",
      "at lpq  lpq   ag",
      "au  wxr  wxr  ag",
      "ay  yy   yy   ag",
      "A           o ag",
      "k          BnCag",
      "a          Du!ag",
      "aaaaaaaaaaaadddg",
      "EEEEEEEEEEEEEEEE"
    ],
    [
      "F          eIIF ",
      "J             F ",
      "K   LM   LM   N ",
      "F   OP   OP   N ",
      "F   LM   LM   N ",
      "N   OP   OP   N ",
      "NQ  LM   LM   F ",
      "N   OP   OP   F ",
      "N   LM   LM   N ",
      "F   OP   OP   N ",
      "F             N ",
      "R             N ",
      "K           S F ",
      "F     TTT     F ",
      "FFFFFFFFFFFFddd ",
      "                "
    ],
    [
      "F          UV!F ",
      "N             F ",
      "N             N ",
      "F             N ",
      "F             N ",
      "N             N ",
      "N             F ",
      "N             F ",
      "N             N ",
      "F             N ",
      "F             N ",
      "N             N ",
      "N             F ",
      "FW    TTT     F ",
      "FFFFFFFFFFFFddd ",
      "                "
    ],
    [
      "F             F ",
      "F             F ",
      "F             F ",
      "F             F ",
      "F             F ",
      "F             F ",
      "F             F ",
      "F             F ",
      "F      X      F ",
      "F             F ",
      "F             F ",
      "F             F ",
      "F             F ",
      "FY            F ",
      "FFFFFFFFFFFFddd ",
      "                "
    ],
    [
      "FZZZZZZZZZZZZZF0",
      "FZZZZZZZZZZZZZF0",
      "FZZ111ZZZ111ZZF0",
      "FZZZZZZZZZZZZZF0",
      "FZZZZZZZZZZZZZF0",
      "FZZ111ZZZ111ZZF0",
      "FZZZZZZZZZZZZZF0",
      "FZZZZZZZZZZZZZF0",
      "FZZ111ZZZ111ZZF0",
      "FZZZZZZZZZZZZZF0",
      "FZZZZZZZZZZZZZF0",
      "FZZ111ZZZ111ZZF0",
      "FZZZZZZZZZZZZZF0",
      "FZZZZZZZZZZZZZF0",
      "FFFFFFFFFFFFddd0",
      "0000000000000000"
    ]
  ]
}