{
  "name": "multi_verticalschool_13_floor18",
  "refpalette": "deceasedcraft:multi_verticalschool_13/multi_verticalschool_13_floor18_palette",
  "xsize": 16,
  "zsize": 16,
  "slices": [
    [
      "    abbcd ebbba ",
      "    f         f ",
      "    f         f ",
      "    a         a ",
      "    f         f ",
      "    f         f ",
      "    f         f ",
      "    f         f ",
      "    f         f ",
      "    f         f ",
      "    a         a ",
      "    f         f ",
      "    f         f ",
      "    ag        a ",
      "    aaaaaaaahhh ",
      "                "
    ],
    [
      "    a         a ",
      "    a    ij   a ",
      "    a   iiij  a ",
      "    a     i   a ",
      "    a         a ",
      "    a         a ",
      "    a         a ",
      "    a         a ",
      "    a         a ",
      "    a         a ",
      "    a         a ",
      "    a         a ",
      "    a         a ",
      "    ak        a ",
      "    aaaaaaaahhh ",
      "                "
    ],
    [
      "    alllmnolllap",
      "    allliiinllap",
      "    alqmii!ijlap",
      "    alllmniinlap",
      "    alllllonllap",
      "    alqllqllqlap",
      "    alllllllllap",
      "    alllllllllap",
      "    alrllrllqlap",
      "    alllllllllap",
      "    alllllllllap",
      "    alqllqllqlap",
      "    alllllllllap",
      "    alllllllllap",
      "    aaaaaaaahhhp",
      "pppppppppppppppp"
    ],
    [
      "  stuwwwwwwwwwux",
      "  stuwwwwwiiwwux",
      "  stuwwwwiy iwux",
      "  stuwwwwi  inux",
      "  stuwwwwwoiiiuA",
      "  stuwwwwwwwoijB",
      "  stuwwwwwwwwwuB",
      "  stuwwwwwwwwwux",
      "  stuwwwwwwwwwux",
      "  stuwwwwwwwwwux",
      "  stuwwwwwwwwwux",
      "  stuwwwwwwwwwux",
      "  stuwwwwwwwwwux",
      "ssstuwwwwwwwwwux",
      "ttttuuuuuuuuhhhx",
      "xxxxxxxxxxxxxxxx"
    ],
    [
      "  C uDEDDFIDDEu ",
      "  C JKLMNO  PQu ",
      "  C R    S  eTu ",
      "  C uKUP    IPu ",
      "  C uVKWc  X  n ",
      "  C uYZ0Q  O X  ",
      "  C uK1LLKL   i ",
      "  C uV Z2 Z2K u ",
      "  C uL      3Vu ",
      "  C u  LL4LL Lu ",
      "  C uV Z2 Z2 Vu ",
      "  C 5         u ",
      "  C R    6    u ",
      "77  u89#####$$u ",
      "    uuuuuuuuhhh ",
      "    %           "
    ],
    [
      "    aDDDED DEDa ",
      "    ^  O      f ",
      "    &         f ",
      "    a         a ",
      "    f         f ",
      "    f  O        ",
      "    f         f ",
      "    f* Y   (  f ",
      "    f         f ",
      "    f         f ",
      "    a3  * 14  a ",
      "    )         f ",
      "    &         f ",
      "    a +  -    a ",
      "    aaaaaaaahhh ",
      "                "
    ]
  ]
}