{
  "name": "multi_verticalschool_13_floor20",
  "refpalette": "deceasedcraft:multi_verticalschool_13/multi_verticalschool_13_floor20_palette",
  "xsize": 16,
  "zsize": 16,
  "slices": [
    [
      "    abbbbb bbba ",
      "    c         c ",
      "    c         c ",
      "    a         a ",
      "    c         c ",
      "    c         c ",
      "    c         c ",
      "    c         c ",
      "    c         c ",
      "    c         c ",
      "    a         a ",
      "    c         c ",
      "    c         c ",
      "    ad        a ",
      "    aaaaaaaaeee ",
      "                "
    ],
    [
      "    a         a ",
      "    a         a ",
      "    a         a ",
      "    a         a ",
      "    a         a ",
      "    a         a ",
      "    a         a ",
      "    a         a ",
      "    a         a ",
      "    a         a ",
      "    a         a ",
      "    a         a ",
      "    a         a ",
      "    af        a ",
      "    aaaaaaaaeee ",
      "                "
    ],
    [
      "    agggggggggah",
      "    agggggggggah",
      "    agiggiggigah",
      "    agggggggggah",
      "    agggggggggah",
      "    agiggiggigah",
      "    agggggggggah",
      "    agggggggggah",
      "    agiggiggigah",
      "    agggggggggah",
      "    agggggggggah",
      "    agiggiggigah",
      "    agggggggggah",
      "    agggggggggah",
      "    aaaaaaaaeeeh",
      "hhhhhhhhhhhhhhhh"
    ],
    [
      "  jklmmmmmmmmmln",
      "  jklmmmmmmmmmln",
      "  jklmmmmmmmmmln",
      "  jklmmmmmmmmmln",
      "  jklmmmmmmmmmln",
      "  jklmmmmmmmmmln",
      "  jklmmmmmmmmmln",
      "  jklmmmmmmmmmln",
      "  jklmmmmmmmmmln",
      "  jklmmmmmmmmmln",
      "  jklmmmmmmmmmln",
      "  jklmmmmmmmmmln",
      "  jklmmmmmmmmmln",
      "jjjklmmmmmmmmmln",
      "kkkklllllllleeen",
      "nnnnnnnnnnnnnnnn"
    ],
    [
      "  o lpq!pqppppl ",
      "  o r         l ",
      "  o s        tl ",
      "  o lt tt tt  l ",
      "  o lu wx wx ul ",
      "  o l         l ",
      "  o lt tt tt tl ",
      "  o lu wx wx ul ",
      "  o l         l ",
      "  o lt tt tt tl ",
      "  o lu wx wx ul ",
      "  o y         l ",
      "  o s    A  B l ",
      "CC  lDEFFFIJKKl ",
      "    lllllllleee ",
      "    L           "
    ],
    [
      "    appppMppqNa ",
      "    O         c ",
      "    P         c ",
      "    a         a ",
      "    c         c ",
      "    c         c ",
      "    c         c ",
      "    c         c ",
      "    c         c ",
      "    c         c ",
      "    a        Qa ",
      "    R         c ",
      "    P         c ",
      "    aS   T    a ",
      "    aaaaaaaaeee ",
      "                "
    ]
  ]
}