{
  "name": "multi_verticalschool_13_floor11",
  "refpalette": "deceasedcraft:multi_verticalschool_13/multi_verticalschool_13_floor11_palette",
  "xsize": 16,
  "zsize": 16,
  "slices": [
    [
      "                ",
      "                ",
      "                ",
      "               a",
      "                ",
      "                ",
      "                ",
      "                ",
      "                ",
      "                ",
      "                ",
      "                ",
      "                ",
      "             b  ",
      "            ccc ",
      "             d  "
    ],
    [
      "                ",
      "                ",
      "                ",
      "               a",
      "                ",
      "                ",
      "                ",
      "                ",
      "                ",
      "                ",
      "                ",
      "                ",
      "                ",
      "             e  ",
      "            ccc ",
      "             e  "
    ],
    [
      "         fff    ",
      "         agg    ",
      "          gg    ",
      "               a",
      "                ",
      "                ",
      "                ",
      "                ",
      "                ",
      "                ",
      "                ",
      "                ",
      "                ",
      "             h  ",
      "            ccc ",
      "             i  "
    ],
    [
      "        j   kl  ",
      "         ammfg  ",
      "         jmmfg  ",
      "          nafg a",
      "                ",
      "                ",
      "                ",
      "                ",
      "                ",
      "                ",
      "                ",
      "                ",
      "                ",
      "                ",
      "            ccc ",
      "                "
    ],
    [
      "oooppppo    qq  ",
      "oooooooo r   mfg",
      "ooooooooo    mfg",
      "oooooooooo r mfr",
      "ooooooooooo nn  ",
      "oooooooooooooooo",
      "oooooooooooooooo",
      "oooppppooooooooo",
      "ooopoopooooooooo",
      "oooppppooooooooo",
      "oooooooooooooooo",
      "oooooooooooooooo",
      "oooooooooooooooo",
      "oooooooooooooooo",
      "ooooooooooooccco",
      "oooooooooooooooo"
    ],
    [
      "ssssttttu    qqf",
      "ssssttttuu     m",
      "sssstttttu     m",
      "sssstttttuuu   u",
      "ssssttttwtwuuuuu",
      "ssssttttttwwwwtw",
      "sssstttttttwwwww",
      "sssstttttwtwtwwt",
      "ssssttttttttwwww",
      "sssstttttttwwxyw",
      "ssssttttttttwxww",
      "sssstttttttwwxww",
      "tssssttttttwyxwt",
      "tsssstttttwtwxyw",
      "tsssssttttttccct",
      "ttsssssttttttttt"
    ]
  ]
}