{
  "name": "multi_verticalschool_13_floor10",
  "refpalette": "deceasedcraft:multi_verticalschool_13/multi_verticalschool_13_floor10_palette",
  "xsize": 16,
  "zsize": 16,
  "slices": [
    [
      "  aaaaaaab c  de",
      "  aaaaaaab c fde",
      "  aaaaaaab c  de",
      "  aaaaaaab c  de",
      "  aaaaaaab c  de",
      "  aaaaaaab c  de",
      "  aaaaaaab c  de",
      "  aaaaaaab c  de",
      "  aaaaaaab c  de",
      "  aaaaaaab c  de",
      "  aaaaaaab c  de",
      "  aaaaaaab c  de",
      "  aaaaaaab c  de",
      "  ghhhhhhb c  de",
      "iiib c     cjjje",
      "eeeeeeeeeeeeeee "
    ],
    [
      "aaab c     eeeee",
      "aaab c     ceeee",
      "aaab c        de",
      "aaab c        de",
      "aaab c        de",
      "aaab c     c  de",
      "aaab c        de",
      "aaab c        de",
      "aaab c     f  de",
      "aaab c     c  de",
      "aaab c        de",
      "aaab c        de",
      "aaab c     f  de",
      "aaab c     c  de",
      "hhhb c     fjjje",
      "eeeeeeeeeeeeeee "
    ],
    [
      "        kkkellle",
      "        kkkceeee",
      "    fc  fkkkkkde",
      "          kkkkde",
      "           kkkde",
      "           c  de",
      "              de",
      "              de",
      "f    c        de",
      "           c  de",
      "              de",
      "           f  de",
      "           f  de",
      "     f     cf de",
      "f    c     fjjje",
      "eeeeeeeeeeeeeeem"
    ],
    [
      "nnnnnnnneoopqrst",
      "nnnnnnnneeoouuuw",
      "nnnnnnnnneoowwww",
      "nnnnnnnnnneewwwe",
      "nnnnnnnnnnneeeee",
      "nnnnnnnnnnnnnnnn",
      "nnnnnnnnnnnnnnnn",
      "nnnnnnnnnnnnnnnn",
      "nnnnnnnnnnnnnnnn",
      "nnnnnnnnnnnnnnnn",
      "nnnnnnnnnnnnnnnn",
      "nnnnnnnnnnnnnnnn",
      "nnnnnnnnnnnnnnnn",
      "nnnnnnnnnnnnnnnn",
      "nnnnnnnnnnnnjjjn",
      "nnxxxxxxnnnnnnnn"
    ],
    [
      "          y     ",
      "    A      y    ",
      "                ",
      "               B",
      "                ",
      "                ",
      "    CD          ",
      "                ",
      "    EF          ",
      "                ",
      "    IJ          ",
      "                ",
      "                ",
      "                ",
      "            jjj ",
      "                "
    ],
    [
      "                ",
      "                ",
      "                ",
      "               B",
      "                ",
      "                ",
      "                ",
      "                ",
      "                ",
      "                ",
      "                ",
      "                ",
      "                ",
      "                ",
      "            jjj ",
      "                "
    ]
  ]
}