{
  "name": "multi_verticalschool_13_floor31",
  "refpalette": "deceasedcraft:multi_verticalschool_13/multi_verticalschool_13_floor31_palette",
  "xsize": 16,
  "zsize": 16,
  "slices": [
    [
      "                ",
      "                ",
      "                ",
      "                ",
      "                ",
      "                ",
      "             a  ",
      "             ab ",
      "             a  ",
      "                ",
      "                ",
      "                ",
      "                ",
      "                ",
      "            ccc ",
      "                "
    ],
    [
      "          d     ",
      "                ",
      "                ",
      "                ",
      "                ",
      "                ",
      "                ",
      "              b ",
      "                ",
      "                ",
      "                ",
      "                ",
      "                ",
      "     eeee       ",
      "            ccc ",
      "                "
    ],
    [
      "                ",
      "                ",
      "                ",
      "                ",
      "                ",
      "                ",
      "                ",
      "              b ",
      "                ",
      "                ",
      "                ",
      "                ",
      "                ",
      "     ffff       ",
      "     g  g   ccc ",
      "                "
    ],
    [
      "                ",
      "                ",
      "                ",
      "                ",
      "                ",
      "                ",
      "                ",
      "              b ",
      "                ",
      "                ",
      "                ",
      "                ",
      "                ",
      "     h  h       ",
      "     i  i   ccc ",
      "                "
    ],
    [
      "jjjjjjjjjjjjjjjk",
      "llllllllllmmmmjk",
      "nnnnnnnnnnnnnmjk",
      "nnnnnnnnnnnnnmjk",
      "nnnnnnnnnnnnnmjk",
      "nnnnnnnnnnnnnmjk",
      "nnnnnnnnnnnnnmjk",
      "nnnnnnnnnnnnnmok",
      "nnnnnnnnnnnnnmjk",
      "nnnnnnnnnnnnnmjk",
      "nnnnnnnnnnnnnljk",
      "nnnnnnnnnnnnnljk",
      "nnnnnnnnnnnnnljk",
      "llmmmmmmmmlllljk",
      "jjjjjojjojjjccck",
      "kkkkkkkkkkkkkkkk"
    ],
    [
      "ppppppppppppppcq",
      "ppppppppppppppcq",
      "ppppppppppppppcq",
      "ppppppppppppppcq",
      "ppppppppppppppcq",
      "ppppppppppppppcq",
      "ppppppppppppppcq",
      "ppppppppppppppcq",
      "ppppppppppppppcq",
      "ppppppppppppppcq",
      "ppppppppppppppcq",
      "ppppppppppppppcq",
      "ppppppppppppppcq",
      "ppppppppppppppcq",
      "cccccccccccccccq",
      "qqqqqqqqqqqqqqqq"
    ]
  ]
}