{
  "name": "multi_verticalschool_13_floor2",
  "refpalette": "deceasedcraft:multi_verticalschool_13/multi_verticalschool_13_floor2_palette",
  "xsize": 16,
  "zsize": 16,
  "slices": [
    [
      "                ",
      "                ",
      "                ",
      "                ",
      "                ",
      "                ",
      "                ",
      "                ",
      "                ",
      "                ",
      "                ",
      "                ",
      "                ",
      "                ",
      "            aaa ",
      "                "
    ],
    [
      "                ",
      "                ",
      "                ",
      "                ",
      "                ",
      "                ",
      "                ",
      "                ",
      "                ",
      "                ",
      "                ",
      "                ",
      "                ",
      "                ",
      "            aaa ",
      "                "
    ],
    [
      "bbbbbbbbbbbbbbcb",
      "bbbbbbbbbbbbbcbb",
      "bbbbbbbbbbbbcbb ",
      "bbbbbbbbbbbcbb d",
      "bbbbbbbbbbcbb d ",
      "bbbbbbbbbcbb d  ",
      "bbbbbbbbcbb d   ",
      "bbbbbbbcbb d    ",
      "bbbbbbcbb d     ",
      "bbbbbcbb d      ",
      "bbbbcbb d       ",
      "bbbcbb d        ",
      "bbcbb d         ",
      "bcbb d          ",
      "cbb d       aaa ",
      "bb d            "
    ],
    [
      "eeeeeeeeeeeeeeee",
      "eeeeeeeeeeeeeeee",
      "eeeeeeeeeeeeeeef",
      "eeeeeeeeeeeeeefg",
      "eeeeeeeeeeeeefg ",
      "eeeeeeeeeeeefg  ",
      "eeeeeeeeeeefg   ",
      "eeeeeeeeeefg    ",
      "eeeeeeeeefg     ",
      "eeeeeeeefg      ",
      "eeeeeeefg       ",
      "eeeeeefg        ",
      "eeeeefg         ",
      "eeeefg          ",
      "eeefg       aaa ",
      "eefg            "
    ],
    [
      "   hiiih   hjklh",
      "    mno         ",
      "    pnq        f",
      "   rpnqs      ft",
      "    pnq      ft ",
      "    unw     ft  ",
      "    xxx    ft   ",
      "          ft    ",
      "         ft     ",
      "        ft      ",
      "       ft       ",
      "      ft        ",
      "     ft         ",
      "    ft          ",
      "   ft       aaa ",
      "  ft            "
    ],
    [
      "   hhhhh   hxxxh",
      "     y          ",
      "     yA        B",
      "    CyD       B ",
      "    Ey       B  ",
      "     y      B   ",
      "           B    ",
      "          B     ",
      "         B      ",
      "        B       ",
      "       B        ",
      "      B         ",
      "     B          ",
      "    B           ",
      "   B        aaa ",
      "  B             "
    ]
  ]
}