{
  "name": "multi_verticalschool_13_floor27",
  "refpalette": "deceasedcraft:multi_verticalschool_13/multi_verticalschool_13_floor27_palette",
  "xsize": 16,
  "zsize": 16,
  "slices": [
    [
      "abbbbbbbbbbbbbac",
      "abbbbbbbbbbbbbac",
      "abbbbbbbbbbbbbac",
      "abbbbbbbbbbbbbac",
      "abbbbbbbbbbbbbac",
      "abbbbbbbbbbbbbac",
      "abbbbbbbbbbbbbac",
      "abbbbbbbbbbbbbac",
      "abbbbbbbbbbbbbac",
      "abbbbbbbbbbbbbac",
      "abbbbbbbbbbbbbac",
      "abbbbbbbbbbbbbac",
      "abbbbbbbbbbbbbac",
      "abbbbbbbbbbbbbac",
      "aaaaaaaaaaaadddc",
      "cccccccccccccccc"
    ],
    [
      "a      efghhgiaj",
      "k          l  aj",
      "m       l    laj",
      "a      nooooooaj",
      "ap     nqrssrqaj",
      "at      ul  ulaj",
      "aw       x   yaj",
      "aAB        CDEaj",
      "aFB     IlJ l aj",
      "aFB    nKoLLoKaj",
      "aMB    nrrrrrraj",
      "aNB      l l laj",
      "aw            aj",
      "aO     PQRSSRTaj",
      "aaaaaaaaaaaadddj",
      "UUUUUUUUUUUUUUUU"
    ],
    [
      "V       WXYYX!V ",
      "Z             V ",
      "0             1 ",
      "V        2 2321 ",
      "V4       5   61 ",
      "V             1 ",
      "1             V ",
      "1             V ",
      "V             1 ",
      "V4       7  8I1 ",
      "V       69#9$91 ",
      "1             1 ",
      "1             V ",
      "V       %^& * V ",
      "VVVVVVVVVVVVddd ",
      "                "
    ],
    [
      "V       ())))+V ",
      "1             V ",
      "1             1 ",
      "V             1 ",
      "V-            1 ",
      "V             1 ",
      "1             V ",
      "1             V ",
      "V             1 ",
      "V-            1 ",
      "V             1 ",
      "1             1 ",
      "1             V ",
      "V       []]]]{V ",
      "VVVVVVVVVVVVddd ",
      "                "
    ],
    [
      "V       }|}|}|V ",
      "V       ;     V ",
      "V       ;     V ",
      "V       ;     V ",
      "V       ;     V ",
      "V       ;     V ",
      "V       ;     V ",
      "V       ;     V ",
      "V       ;     V ",
      "V       ;     V ",
      "V       ;     V ",
      "V       ;     V ",
      "V       ;     V ",
      "V       :':':'V ",
      "VVVVVVVVVVVVddd ",
      "                "
    ],
    [
      "V<<<<<<<>>>>>>V,",
      "V<<<<<<<>>>>>>V,",
      "V<<...<<>>>>>>V,",
      "V<<<<<<<>>..>>V,",
      "V<<<<<<<>>..>>V,",
      "V<<???<<>>..>>V,",
      "V<<<<<<<>>..>>V,",
      "V<<<<<<<>>??>>V,",
      "V<<...<<>>??>>V,",
      "V<<<<<<<>>..>>V,",
      "V<<<<<<<>>??>>V,",
      "V<<...<<>>>>>>V,",
      "V<<<<<<<>>>>>>V,",
      "V<<<<<<<>>>>>>V,",
      "VVVVVVVVVVVVddd,",
      ",,,,,,,,,,,,,,,,"
    ]
  ]
}