{
  "name": "multi_verticalschool_13_floor29",
  "refpalette": "deceasedcraft:multi_verticalschool_13/multi_verticalschool_13_floor29_palette",
  "xsize": 16,
  "zsize": 16,
  "slices": [
    [
      "abbbbbbbbbbbbbac",
      "abbbbbbbbbbbbbac",
      "abbbbbbbbbbbbbac",
      "abbbbbbbbbbbbbac",
      "abbbbbbbbbbbbbac",
      "abbbbbbbbbbbbbac",
      "abbbbbbbbbbbbbac",
      "abbbbbbbbbbbbbac",
      "abbbbbbbbbbbbbac",
      "abbbbbbbbbbbbbac",
      "abbbbbbbbbbbbbac",
      "abbbbbbbbbbbbbac",
      "abbbbbbbbbbbbbac",
      "abbbbbbbbbbbbbac",
      "aaaaaaaaaaaadddc",
      "cccccccccccccccc"
    ],
    [
      "a             ae",
      "f             ae",
      "g           hiae",
      "a           j ae",
      "a             ae",
      "ak          hlae",
      "am   hnh h    ae",
      "ak   o p p  q ae",
      "am          hiae",
      "a    rh hn  r ae",
      "a     p p     ae",
      "s           hiae",
      "t  hi  !  u   ae",
      "a  r       h  ae",
      "aaaaaaaaaaaaddde",
      "wwwwwwwwwwwwwwww"
    ],
    [
      "x  y A B C D  x ",
      "E             x ",
      "F             I ",
      "x             I ",
      "x             I ",
      "IJ            I ",
      "I             x ",
      "IK            x ",
      "IL            I ",
      "x    M      N I ",
      "x             I ",
      "O             I ",
      "P      Q      x ",
      "x      R      x ",
      "xxxxxxxxxxxxddd ",
      "                "
    ],
    [
      "x  S       !  x ",
      "I             x ",
      "I             I ",
      "x             I ",
      "x             I ",
      "I             I ",
      "I             x ",
      "I             x ",
      "I             I ",
      "x             I ",
      "x             I ",
      "I             I ",
      "I             x ",
      "xT            x ",
      "xxxxxxxxxxxxddd ",
      "                "
    ],
    [
      "x  U U U U U  x ",
      "x             x ",
      "x             x ",
      "x             x ",
      "x             x ",
      "x             x ",
      "x             x ",
      "x             x ",
      "x             x ",
      "x             x ",
      "x             x ",
      "x             x ",
      "x             x ",
      "xV            x ",
      "xxxxxxxxxxxxddd ",
      "                "
    ],
    [
      "xWWWWWWWWWWWWWxX",
      "xWWWWWWWWWWWWWxX",
      "xWWYYYWWWYYYWWxX",
      "xWWWWWWWWWWWWWxX",
      "xWWWWWWWWWWWWWxX",
      "xWWYYYWWWYYYWWxX",
      "xWWWWWWWWWWWWWxX",
      "xWWWWWWWWWWWWWxX",
      "xWWYYYWWWYYYWWxX",
      "xWWWWWWWWWWWWWxX",
      "xWWWWWWWWWWWWWxX",
      "xWWYYYWWWYYYWWxX",
      "xWWWWWWWWWWWWWxX",
      "xWWWWWWWWWWWWWxX",
      "xxxxxxxxxxxxdddX",
      "XXXXXXXXXXXXXXXX"
    ]
  ]
}