{
  "name": "multi_verticalschool_13_floor8",
  "refpalette": "deceasedcraft:multi_verticalschool_13/multi_verticalschool_13_floor8_palette",
  "xsize": 16,
  "zsize": 16,
  "slices": [
    [
      "abcc          db",
      "abcce         df",
      "abcc          dg",
      "abcch         dg",
      "abcch         di",
      "abcch         db",
      "abccc         j ",
      "abccck        db",
      "abccc         db",
      "abccck        db",
      "abccc         l ",
      "abccck        m ",
      "abccc   nnnnnndb",
      "abcccnnnno p  db",
      "abbbbp      qqqb",
      "bbbbbbbbbbbbbbb "
    ],
    [
      "cc            db",
      "cck           db",
      "cc            db",
      "cck           db",
      "cch           db",
      "cch           db",
      "cch           r ",
      "ccck          db",
      "ccc           db",
      "ccck          db",
      "ccc           st",
      "ccck          st",
      "ccc     nnnnnndb",
      "cccnnnnnno p  db",
      "ccco p      qqqb",
      "bbbbbbbbbbbbbbbu"
    ],
    [
      "              db",
      "k             db",
      "              db",
      "k             db",
      "              db",
      "h             db",
      "h             db",
      "h             db",
      "ck            db",
      "c             db",
      "ck            db",
      "c             db",
      "ck      nnnnnndb",
      "c nnnnnnno p  db",
      "cnno p      qqqb",
      "bbbbbbbbbbbbbbbw"
    ],
    [
      "           x  db",
      "           x  db",
      "           x  db",
      "           x  db",
      "           x  db",
      "              db",
      "              db",
      "              db",
      "              db",
      "              db",
      "              db",
      "              db",
      "        nnnnnndb",
      "  nnnnnnno p  db",
      "nnno p      qqqb",
      "bbbbbbbbbbbbbbb "
    ],
    [
      "           x  db",
      "           x  db",
      "           xyAdb",
      "           x  db",
      "           x  db",
      "              db",
      "              db",
      "              db",
      "             Bdb",
      "              db",
      "              db",
      "              db",
      "        nnnnnndb",
      "  nnnnnnno p  db",
      "nnno p      qqqb",
      "bbbbbbbbbbbbbbb "
    ],
    [
      "           x  db",
      "           x  db",
      "           xCDdb",
      "           x  db",
      "           x  db",
      "              db",
      "              db",
      "             Edb",
      "             Fdb",
      "             Idb",
      "              db",
      "              db",
      "        nnnnnndb",
      "  nnnnnnno p  db",
      "nnno p      qqqb",
      "bbbbbbbbbbbbbbbJ"
    ]
  ]
}