{
  "name": "multi_verticalschool_13_floor17",
  "refpalette": "deceasedcraft:multi_verticalschool_13/multi_verticalschool_13_floor17_palette",
  "xsize": 16,
  "zsize": 16,
  "slices": [
    [
      "               a",
      "               a",
      "               a",
      "               a",
      "       b       a",
      "               a",
      "               a",
      "               a",
      "               a",
      "       b       a",
      "               a",
      "               a",
      "               a",
      "               a",
      "            ccca",
      "aaaaaaaaaaaaaaa "
    ],
    [
      "               a",
      "               a",
      "               a",
      "               a",
      "       b       a",
      "               a",
      "               a",
      "               a",
      "               a",
      "       b       a",
      "               a",
      "               a",
      "               a",
      "               a",
      "            ccca",
      "aaaaaaaaaaaaaaa "
    ],
    [
      "    ddddddddddda",
      "    ddddddddddda",
      "    ddddddddddda",
      "    ddddddddddda",
      "    dddeddddddda",
      "    ddddddddddda",
      "    ddddddddddda",
      "    ddddddddddda",
      "    ddddddddddda",
      "    dddeddddddda",
      "    ddddddddddda",
      "    ddddddddddda",
      "    ddddddddddda",
      "    ddddddddddda",
      "    ddddddddccca",
      "aaaaaaaaaaaaaaaf"
    ],
    [
      "  ghijjjjjjjjjik",
      "  ghijjjjjjjjjik",
      "  ghijjjjjjjjjik",
      "  ghijjjjjjjjjik",
      "  ghijjjjjjjjjik",
      "  ghijjjjjjjjjik",
      "  ghijjjjjjjjjik",
      "  ghijjjjjjjjjik",
      "  ghijjjjjjjjjik",
      "  ghijjjjjjjjjik",
      "  ghijjjjjjjjjik",
      "  ghijjjjjjjjjik",
      "  ghijjjjjjjjjik",
      "ggghijjjjjjjjjik",
      "hhhhiiiiiiiiccck",
      "kkkkkkkkkkkkkkkk"
    ],
    [
      "  l immmnmmmomi ",
      "  l p      q ri ",
      "  l s         i ",
      "  l irt  u  q i ",
      "  l iw xy xy wi ",
      "  l i         i ",
      "  l ir rr rr ri ",
      "  l iw xy xy wi ",
      "  l i         i ",
      "  l ir rr rr ri ",
      "  l iw xy xy wi ",
      "  l A         i ",
      "  l s    B    i ",
      "CC  iDEFFFFFIIi ",
      "    iiiiiiiiccc ",
      "    J           "
    ],
    [
      "    KmnmmLmmmnK ",
      "    M         N ",
      "    O         N ",
      "    K         K ",
      "    N  PQ  R  N ",
      "    N         N ",
      "    N         N ",
      "    NQ  P P  PN ",
      "    N         N ",
      "    N         N ",
      "    K  SQ  P TK ",
      "    U         N ",
      "    O         N ",
      "    KVW  X  Y K ",
      "    KKKKKKKKccc ",
      "                "
    ]
  ]
}