{
  "name": "multi_convenientstore_0_ground",
  "refpalette": "deceasedcraft:multi_convenientstore_0/multi_convenientstore_0_ground_palette",
  "xsize": 16,
  "zsize": 16,
  "slices": [
    [
      "abHHbcaaaaaaaaaa",
      "abHHbcaaaaaaaaaa",
      "abHHbccccccccccc",
      "abHHbbHHHHHHHHHH",
      "abHHbbHHHHHHHHHH",
      "abHHbbHHHHHHHHHH",
      "abHHHbHHHHHHHHHH",
      "abHHHHHHHHHHHHHH",
      "abHHHHHHHHHHHHHH",
      "abHHHHHHHHHHHHHH",
      "abHHbbbbbbbbbbbb",
      "abHHbccccccccccc",
      "abHHbccccccccccc",
      "abHHbccccccccccc",
      "abHHbccccccccccc",
      "abHHbccccccccccc"
    ],
    [
      "     defffffffff",
      "     deeeeeeeeee",
      "     ddddddddddd",
      "g     hihihihihi",
      "                ",
      "                ",
      "      jkjkjkjkjk",
      "g         l     ",
      "    m           ",
      "      no        ",
      "         p      ",
      "g    ddddddddddd",
      "     dcccccccccc",
      "     dcccccccccc",
      "     dcccccccccc",
      "g    dccqqqqqqqq"
    ],
    [
      "                ",
      "                ",
      "                ",
      "r               ",
      "                ",
      "                ",
      "                ",
      "r               ",
      "                ",
      "                ",
      "                ",
      "r               ",
      "       s   t    ",
      "        t su wxx",
      "      pu onuuyAB",
      "r      uCD  E FF"
    ],
    [
      "                ",
      "                ",
      "                ",
      "f               ",
      "                ",
      "                ",
      "                ",
      "f               ",
      "                ",
      "                ",
      "                ",
      "f               ",
      "                ",
      "             w  ",
      "      uu   uuyIJ",
      "f      u        "
    ],
    [
      "                ",
      "                ",
      "                ",
      "f               ",
      "                ",
      "                ",
      "                ",
      "f               ",
      "                ",
      "                ",
      "                ",
      "f               ",
      "                ",
      "             KLL",
      "          uuuyyy",
      "f      u        "
    ],
    [
      "                ",
      "                ",
      "                ",
      "M               ",
      "                ",
      "                ",
      "                ",
      "f               ",
      "                ",
      "                ",
      "                ",
      "M               ",
      "                ",
      "          N  O  ",
      "       uuuuuuuuu",
      "       u        "
    ]
  ]
}