{
  "name": "multi_nuclearpowerplant_17_base9",
  "refpalette": "deceasedcraft:multi_nuclearpowerplant_17/multi_nuclearpowerplant_17_base9_palette",
  "xsize": 16,
  "zsize": 16,
  "slices": [
    [
      "                ",
      "                ",
      "                ",
      "                ",
      "                ",
      "                ",
      "                ",
      "                ",
      "                ",
      "                ",
      "                ",
      "   aa           ",
      "   aa           ",
      "   aa           ",
      "   aa           ",
      "   aa           "
    ],
    [
      "                ",
      "                ",
      "                ",
      "                ",
      "                ",
      "                ",
      "                ",
      "                ",
      "                ",
      "                ",
      "                ",
      "                ",
      "                ",
      "                ",
      "                ",
      "                "
    ],
    [
      "                ",
      "                ",
      "                ",
      "                ",
      "                ",
      "                ",
      "                ",
      "                ",
      "                ",
      "                ",
      "                ",
      "                ",
      "                ",
      "                ",
      "                ",
      "                "
    ],
    [
      "bbbbbbbbbbbbbbbb",
      "bbbbbbbbbbbbbbbb",
      "bbbbbbbbbbbbbbbb",
      "bbbbbbbbbbbbbbbb",
      "bbbbbbbbbbbbbbbb",
      "bbbbbbbbbbbbbbbb",
      "bbbbbbbbbbbbbbbb",
      "bbbbbbbbbbbbbbbb",
      "bbbbbbbbbbbbbbbb",
      "bbbbbbbbbbbbbbbb",
      "bbbbbbbbbbbbbbbb",
      "bbbbbbbbbbbbbbbb",
      "bbbbbbbbbbbbbbbb",
      "bbbbbbbbbbbbbbbb",
      "bbbbbbbbbbbbbbbb",
      "bbbbbbbbbbbbbbbb"
    ],
    [
      "cd  ecd  ecd  ec",
      "f    f    f    f",
      "                ",
      "                ",
      "g    g    g    g",
      "cd  ecd  ecd  ec",
      "f    f    f    f",
      "                ",
      "                ",
      "g    g    g    g",
      "cd  ecd  ecd  ec",
      "f    f    f    f",
      "                ",
      "                ",
      "g    g    g    g",
      "cd  ecd  ecd  ec"
    ],
    [
      "c    c    c    c",
      "                ",
      "                ",
      "                ",
      "                ",
      "c    c    c    c",
      "                ",
      "                ",
      "                ",
      "                ",
      "c    c    c    c",
      "                ",
      "                ",
      "                ",
      "                ",
      "c    c    c    c"
    ]
  ]
}