{
  "name": "multi_nuclearpowerplant_17_base11",
  "refpalette": "deceasedcraft:multi_nuclearpowerplant_17/multi_nuclearpowerplant_17_base11_palette",
  "xsize": 16,
  "zsize": 16,
  "slices": [
    [
      "a      aa      a",
      "bccccccbbccccccb",
      "b      bb      b",
      "                ",
      "                ",
      "                ",
      "                ",
      "                ",
      "                ",
      "                ",
      "                ",
      "                ",
      "                ",
      "b      bb      b",
      "bccccccbbccccccb",
      "d      dd      d"
    ],
    [
      "a      aa      a",
      "bccccccbbccccccb",
      "b      bb      b",
      "                ",
      "                ",
      "                ",
      "                ",
      "                ",
      "                ",
      "                ",
      "                ",
      "                ",
      "                ",
      "b      bb      b",
      "bccccccbbccccccb",
      "d      dd      d"
    ],
    [
      "a      aa      a",
      "bccccccbbccccccb",
      "effffffeeffffffe",
      "b      bb      b",
      "b      bb      b",
      "b      bb      b",
      "b      bb      b",
      "b      bb      b",
      "b      bb      b",
      "b      bb      b",
      "b      bb      b",
      "b      bb      b",
      "b      bb      b",
      "effffffeeffffffe",
      "bccccccbbccccccb",
      "d      dd      d"
    ],
    [
      "                ",
      "b      bb      b",
      "bccccccbbccccccb",
      "bccccccbbccccccb",
      "bccccccbbccccccb",
      "bggggggbbggggggb",
      "bccccccbbccccccb",
      "bccccccbbccccccb",
      "bccccccbbccccccb",
      "bccccccbbccccccb",
      "bggggggbbggggggb",
      "b      bb      b",
      "b      bb      b",
      "b      bb      b",
      "b      bb      b",
      "                "
    ],
    [
      "                ",
      "                ",
      "h      hh      h",
      "h      hh      h",
      "h      hh      h",
      "h      hh      h",
      "h      hh      h",
      "h      hh      h",
      "h      hh      h",
      "h      hh      h",
      "h      hh      h",
      "h      hh      h",
      "h      hh      h",
      "h      hh      h",
      "                ",
      "                "
    ],
    [
      "                ",
      "                ",
      "                ",
      "                ",
      "                ",
      "                ",
      "                ",
      "                ",
      "                ",
      "                ",
      "                ",
      "                ",
      "                ",
      "                ",
      "                ",
      "                "
    ]
  ]
}