{
  "name": "multi_policeapartment_1_floor1",
  "refpalette": "deceasedcraft:multi_policeapartment_1/multi_policeapartment_1_floor1_palette",
  "xsize": 16,
  "zsize": 16,
  "slices": [
    [
      "                ",
      "                ",
      "                ",
      "                ",
      "                ",
      "          a a   ",
      "        bcdedccc",
      "        c     c ",
      "        c     fg",
      "        c     ch",
      "        c     ch",
      "        c     fg",
      "        c     ci",
      "        bcdedccc",
      "          j j   ",
      "                "
    ],
    [
      "  klllllllllllll",
      "  klllllllllllll",
      "  klllllllllllll",
      "  klllllllllllll",
      "  klllllllllllll",
      "  kkkkkkkkkkkkkk",
      "        bcdmdccc",
      "        c     c ",
      "        c     fg",
      "        c     ch",
      "        c     ch",
      "        c     fg",
      "        c     c ",
      "        bcdmdccc",
      "          j j   ",
      "                "
    ],
    [
      "                ",
      "                ",
      "                ",
      "                ",
      "                ",
      "          a a   ",
      "        bcdmdccc",
      "        c     c ",
      "        c     fg",
      "        c     ch",
      "        c     ch",
      "        c     fg",
      "        c     c ",
      "        bcdmdccn",
      "          j j   ",
      "                "
    ],
    [
      "                ",
      "                ",
      "                ",
      "                ",
      "                ",
      "          a a   ",
      "        bcdmdccc",
      "        c     c ",
      "        c     fg",
      "        c     ch",
      "        c     ch",
      "        c     fg",
      "        c     c ",
      "        bcdmdccc",
      "          j j   ",
      "                "
    ],
    [
      "                ",
      "                ",
      "                ",
      "                ",
      "                ",
      "          a a   ",
      "        bcdmdccc",
      "        c     co",
      "        c     fo",
      "        c     co",
      "        c     co",
      "        c     fo",
      "        c     co",
      "        bcdmdccc",
      "          j j   ",
      "                "
    ],
    [
      "                ",
      "                ",
      "                ",
      "                ",
      "                ",
      "          a a   ",
      "        bcdmdccc",
      "        c     cp",
      "        c     fp",
      "        c     cp",
      "        c     cp",
      "        c     fp",
      "        c     cp",
      "        bcdmdccc",
      "          j j   ",
      "                "
    ]
  ]
}