{
  "name": "multi_policeapartment_1_ground",
  "refpalette": "deceasedcraft:multi_policeapartment_1/multi_policeapartment_1_ground_palette",
  "xsize": 16,
  "zsize": 16,
  "slices": [
    [
      "HHHHHHHHHHHHHHHH",
      "HHHHHHHHHHHHHHHH",
      "HHHHHHHHHHHHHHHH",
      "HHHHHHHHHHHHHHHH",
      "HHHHHHHHHHHHHHHH",
      "aaaaaaaaaaaaaaaa",
      "bbbbbbbbbcdedccf",
      "bbbbbbbbc     gh",
      "bbbbbbbbc     ih",
      "bbbbbbbbc     hh",
      "bbbbbbbbc     hh",
      "bbbbbbbbc     hh",
      "bbbbbbbbc     hh",
      "bbbbbbbbbcdedccc",
      "bbbbbbbbbbbbbbbb",
      "bbbbbbbbbbbbbbbb"
    ],
    [
      "                ",
      "                ",
      "                ",
      "                ",
      "                ",
      "          j j  k",
      "        lcdmdccn",
      "        c     co",
      "        c     np",
      "        c     qr",
      "        c     qs",
      "        c     n ",
      "        c     ct",
      "        lcdmdccc",
      "          u u   ",
      "                "
    ],
    [
      "                ",
      "                ",
      "                ",
      "                ",
      "                ",
      "          j j  k",
      "        lcdmdccn",
      "        c     co",
      "        c     n ",
      "        c      w",
      "        c      x",
      "        c     n ",
      "        c     ct",
      "        lcdmdccc",
      "          u u   ",
      "                "
    ],
    [
      "                ",
      "                ",
      "                ",
      "                ",
      "                ",
      "          j j  k",
      "        lcdmdccn",
      "        c     co",
      "        c     n ",
      "        c     yA",
      "        c     yA",
      "        c     n ",
      "        c     ct",
      "        lcdmdccc",
      "          u u   ",
      "                "
    ],
    [
      "                ",
      "                ",
      "                ",
      "                ",
      "                ",
      "          j j  B",
      "        lcdmdccn",
      "        c     co",
      "        c     nC",
      "        c     cA",
      "        c     cA",
      "        c     nD",
      "        c     cE",
      "        lcdmdccc",
      "          u u   ",
      "                "
    ],
    [
      "                ",
      "                ",
      "                ",
      "                ",
      "                ",
      "          j j   ",
      "        lcdmdccc",
      "        c     c ",
      "        c     nF",
      "        c     cA",
      "        c     cA",
      "        c     nF",
      "        c     cI",
      "        lcdmdccc",
      "          u u   ",
      "                "
    ]
  ]
}