{
  "name": "multi_policeapartment_1_floor3",
  "refpalette": "deceasedcraft:multi_policeapartment_1/multi_policeapartment_1_floor3_palette",
  "xsize": 16,
  "zsize": 16,
  "slices": [
    [
      "              ab",
      "              ab",
      "              ab",
      "              ab",
      "              ab",
      "          c c ab",
      "        defgfeeb",
      "        e     hb",
      "        e     ib",
      "        e     bb",
      "        e     bb",
      "        e     bb",
      "        e     bb",
      "        defgfeee",
      "          j j   ",
      "                "
    ],
    [
      "              kl",
      "              kl",
      "              kl",
      "              kl",
      "              kl",
      "          c c km",
      "        defnfeem",
      "        e     e ",
      "        e     op",
      "        e     qr",
      "        e     qs",
      "        e     o ",
      "        e     e ",
      "        defnfeee",
      "          j j   ",
      "                "
    ],
    [
      "                ",
      "                ",
      "                ",
      "                ",
      "                ",
      "          c c  m",
      "        defnfeem",
      "        e     e ",
      "        e     o ",
      "        e      t",
      "        e      u",
      "        e     o ",
      "        e     e ",
      "        defnfeew",
      "          j j   ",
      "                "
    ],
    [
      "                ",
      "                ",
      "                ",
      "                ",
      "                ",
      "          c c  x",
      "        defnfeex",
      "        e     e ",
      "        e     oy",
      "        e     AB",
      "        e     AB",
      "        e     oC",
      "        e     e ",
      "        defnfeee",
      "          j j   ",
      "                "
    ],
    [
      "                ",
      "                ",
      "                ",
      "                ",
      "                ",
      "          c c   ",
      "        defnfeee",
      "        e     e ",
      "        e     oD",
      "        e     eB",
      "        e     eB",
      "        e     oD",
      "        e     e ",
      "        defnfeee",
      "          j j   ",
      "                "
    ],
    [
      "                ",
      "                ",
      "                ",
      "                ",
      "                ",
      "          c c   ",
      "        defnfeee",
      "        e     e ",
      "        e     oD",
      "        e     eB",
      "        e     eB",
      "        e     oD",
      "        e     e ",
      "        defnfeee",
      "          j j   ",
      "                "
    ]
  ]
}