{
  "name": "multi_policeapartment_1_base1",
  "refpalette": "deceasedcraft:multi_policeapartment_1/multi_policeapartment_1_base1_palette",
  "xsize": 16,
  "zsize": 16,
  "slices": [
    [
      "vaaaaaaaaaaaaaaa",
      "vaaaaaaaaaaaaaaa",
      "vaaaaaaaaaaaaaaa",
      "vaaaaaaaaaaaaaaa",
      "vaaaaaaaaaaaaaaa",
      "vaaaaaaaaaaaaaaa",
      "vaaaaaaabbbbbbbb",
      "vaaaaaaabccdccdd",
      "vaaaaaaabccccccd",
      "vaaaaaaabccccccc",
      "vaaaaaaabccccccc",
      "vaaaaaaabccccccd",
      "vaaaaaaabccccdcc",
      "vaaaaaaabbbbbbbb",
      "vaaaaaaaaaaaaaaa",
      "vvvvvvvvvvvvvvvv"
    ],
    [
      "vaaaaaaaaaaaaaaa",
      "vaaaaaaaaaaaaaaa",
      "vaaaaaaaaaaaaaaa",
      "vaaaaaaaaaaaaaaa",
      "vaaaaaaaaaaaaaaa",
      "vaaaaaaaaaaaaaaa",
      "vaaaaaaabaeeddad",
      "vaaaaaaafg    hd",
      "vaaaaaaafi jkhk ",
      "vaaaaaaafi bllll",
      "vaaaaaaafi bmmmm",
      "vaaaaaaafi  n nh",
      "vaaaaaaafoh     ",
      "vaaaaaaabbaeadea",
      "vaaaaaaaaaaaaaaa",
      "vvvvvvvvvvvvvvvv"
    ],
    [
      "vaaaaaaaaaaaaaaa",
      "vaaaaaaaaaaaaaaa",
      "vaaaaaaaaaaaaaaa",
      "vaaaaaaaaaaaaaaa",
      "vaaaaaaaaaaaaaaa",
      "vaaaaaaaaaaaaaaa",
      "vaaaaaaabbaeaaad",
      "vaaaaaaabp      ",
      "vaaaaaaaqr      ",
      "vaaaaaaaq   h s ",
      "vaaaaaaaq   tuw ",
      "vaaaaaaaqw      ",
      "vaaaaaaabx  h   ",
      "vaaaaaaabbaebaeb",
      "vaaaaaaaaaaaaaaa",
      "vvvvvvvvvvvvvvvv"
    ],
    [
      "vaaaaaaaaaaaaaaa",
      "vaaaaaaaaaaaaaaa",
      "vaaaaaaaaaaaaaaa",
      "vaaaaaaaaaaaaaaa",
      "vaaaaaaaaaaaaaaa",
      "vaaaaaaaaaaaaaaa",
      "vaaaaaaabbbbbaba",
      "vaaaaaaabh      ",
      "vaaaaaaay       ",
      "vaaaaaaay       ",
      "vaaaaaaay       ",
      "vaaaaaaay       ",
      "vaaaaaaab       ",
      "vaaaaaaabbbbbabb",
      "vaaaaaaaaaaaaaaa",
      "vvvvvvvvvvvvvvvv"
    ],
    [
      "vaaaaaaaaaaaaaaa",
      "vaaaaaaaaaaaaaaa",
      "vaaaaaaaaaaaaaaa",
      "vaaaaaaaaaaaaaaa",
      "vaaaaaaaaaaaaaaa",
      "vaaaaaaaaaaaaaaa",
      "vaaaaaaabbbbbbba",
      "vaaaaaaabh hh   ",
      "vaaaaaaab       ",
      "vaaaaaaabh    h!",
      "vaaaaaaab      h",
      "vaaaaaaabh      ",
      "vaaaaaaabh      ",
      "vaaaaaaabbbbbbbb",
      "vaaaaaaaaaaaaaaa",
      "vvvvvvvvvvvvvvvv"
    ],
    [
      "vaaaaaaaaaaaaaaa",
      "vaaaaaaaaaaaaaaa",
      "vaaaaaaaaaaaaaaa",
      "vaaaaaaaaaaaaaaa",
      "vaaaaaaaaaaaaaaa",
      "vaaaaaaaaaaaaaaa",
      "vaaaaaaabbbbbbbb",
      "vaaaaaaabbbbbbbb",
      "vaaaaaaabbbbbbbb",
      "vaaaaaaabbbbbbbb",
      "vaaaaaaabbbbbbbb",
      "vaaaaaaabbbbbbbb",
      "vaaaaaaabbbbbbbb",
      "vaaaaaaabbbbbbbb",
      "vaaaaaaaaaaaaaaa",
      "vvvvvvvvvvvvvvvv"
    ]
  ]
}