{
  "name": "multi_policeapartment_1_top",
  "refpalette": "deceasedcraft:multi_policeapartment_1/multi_policeapartment_1_top_palette",
  "xsize": 16,
  "zsize": 16,
  "slices": [
    [
      "              ab",
      "              ab",
      "              ab",
      "              ab",
      "              ab",
      "          c c ab",
      "        defgfeeb",
      "        ehhihhjb",
      "        ekkkklmb",
      "        ekkkkkbb",
      "        ekkkkkbb",
      "        ekkkkkbb",
      "        ehhihhbb",
      "        defgfeee",
      "          n n   ",
      "                "
    ],
    [
      "              op",
      "              oq",
      "              o ",
      "              op",
      "              or",
      "          c c os",
      "        deftfees",
      "        ehhuhhe ",
      "        es   wxy",
      "        es    AB",
      "        es    AC",
      "        es   Dx ",
      "        ehhuhheE",
      "        deftfeee",
      "          n n   ",
      "                "
    ],
    [
      "                ",
      "                ",
      "                ",
      "                ",
      "                ",
      "          c c  s",
      "        deftfees",
      "        ehh hhe ",
      "        es   Dx ",
      "        eF     I",
      "        eF     J",
      "        es   Dx ",
      "        ehh hheE",
      "        deftfeeK",
      "          n n   ",
      "                "
    ],
    [
      "                ",
      "                ",
      "                ",
      "                ",
      "                ",
      "          c c  L",
      "        deftfeeL",
      "        ehh hhe ",
      "        es   DxM",
      "        eF    NO",
      "        eF    NO",
      "        es   Dx!",
      "        ehh hheE",
      "        deftfeee",
      "          n n   ",
      "                "
    ],
    [
      "                ",
      "                ",
      "                ",
      "                ",
      "                ",
      "          c c   ",
      "        deftfeee",
      "        ehh hhe ",
      "        es   DxP",
      "        es   DeO",
      "        es   DeO",
      "        es   DxP",
      "        ehh hheE",
      "        deftfeee",
      "          n n   ",
      "                "
    ],
    [
      "                ",
      "                ",
      "                ",
      "                ",
      "                ",
      "          c c   ",
      "        deftfeee",
      "        ekkkkke ",
      "        ekkkkkxP",
      "        ekkkkkeO",
      "        ekkkkkeO",
      "        ekkkkkxP",
      "        ekkkkkeE",
      "        deftfeee",
      "          n n   ",
      "                "
    ],
    [
      "                ",
      "                ",
      "                ",
      "                ",
      "                ",
      "          c c   ",
      "        defgfeee",
      "        eQRSTQeb",
      "        eQ U Qbb",
      "        eQ V Qbb",
      "        eQ W Qbb",
      "        eQ U Qbb",
      "        eQXSYQeE",
      "        defgfeee",
      "          n n   ",
      "                "
    ],
    [
      "                ",
      "                ",
      "                ",
      "                ",
      "                ",
      "          c c   ",
      "        defgfeee",
      "        eZ    e0",
      "        e1    e ",
      "        e      2",
      "        e      3",
      "        e4    e ",
      "        eZ    e5",
      "        defgfeee",
      "          n n   ",
      "                "
    ],
    [
      "                ",
      "                ",
      "                ",
      "                ",
      "                ",
      "          c c   ",
      "        defgfeee",
      "        eZ6666e7",
      "        eZ6666e8",
      "        eZ6666 9",
      "        eZ6666 #",
      "        eZ6666e8",
      "        eZ6666e ",
      "        defgfeee",
      "          n n   ",
      "                "
    ],
    [
      "                ",
      "                ",
      "                ",
      "                ",
      "                ",
      "          c c   ",
      "         $fgf$$$",
      "        %^fgf&&&",
      "        %&fgf&&&",
      "        %&fgf&&&",
      "        %&fgf&&&",
      "        %&fgf&&&",
      "        %^fgf&&&",
      "         *fgf***",
      "          n n   ",
      "                "
    ],
    [
      "                ",
      "                ",
      "                ",
      "                ",
      "                ",
      "                ",
      "          ( (   ",
      "         )( (   ",
      "          ( (   ",
      "          ( (   ",
      "          ( (   ",
      "          ( (   ",
      "         )( (   ",
      "          ( (   ",
      "                ",
      "                "
    ]
  ]
}