{
  "name": "multi_thering_15_base1",
  "refpalette": "deceasedcraft:multi_thering_15/multi_thering_15_base1_palette",
  "xsize": 16,
  "zsize": 16,
  "slices": [
    [
      "vvvvvvvvvvvvvvvv",
      "aaaaaaaaaaaaaaaa",
      "bcbddddddddddbca",
      "               a",
      "               a",
      "               a",
      "               a",
      "               a",
      "               a",
      "               a",
      "               a",
      "               a",
      "               a",
      "               a",
      "               a",
      "e fgghhhiijjjk a"
    ],
    [
      "vvvvvvvvvvvvvvvv",
      "aaaaaaaaaaaaaaaa",
      "b bllmlmmmnnnb a",
      "   ll mmmn nn  a",
      "               a",
      "               a",
      "               a",
      "               a",
      "               a",
      "               a",
      "               a",
      "               a",
      "               a",
      "               a",
      "               a",
      "e  oooooooooo  a"
    ],
    [
      "vvvvvvvvvvvvvvvv",
      "aaaaaaaaaaaaaaaa",
      "d dddddddddddd a",
      "               a",
      "               a",
      "               a",
      "               a",
      "               a",
      "               a",
      "               a",
      "               a",
      "               a",
      "               a",
      "               a",
      "               a",
      "e              a"
    ],
    [
      "vvvvvvvvvvvvvvvv",
      "aaaaaaaaaaaaaaaa",
      "               a",
      "               a",
      "               a",
      "               a",
      "               a",
      "               a",
      "               a",
      "               a",
      "               a",
      "               a",
      "               a",
      "               a",
      "               a",
      "e              a"
    ],
    [
      "vvvvvvvvvvvvvvvv",
      "aaaaaaaaaaaaaaaa",
      "               a",
      "               a",
      "               a",
      "               a",
      "               a",
      "               a",
      "               a",
      "               a",
      "               a",
      "               a",
      "               a",
      "               a",
      "               a",
      "e              a"
    ],
    [
      "vvvvvvvvvvvvvvvv",
      "aaaaaaaaaaaaaaaa",
      "pppppppppppppppa",
      "pppppppppppppppa",
      "pppppppppppppppa",
      "pppppppppppppppa",
      "pppppppppppppppa",
      "pppppppppppppppa",
      "pppppppppppppppa",
      "pppppppppppppppa",
      "pppppppppppppppa",
      "pppppppppppppppa",
      "pppppppppppppppa",
      "pppppppppppppppa",
      "pppppppppppppppa",
      "eqqqqqqqqqqqqqqa"
    ]
  ]
}