{
  "name": "multi_thering_15_base2",
  "refpalette": "deceasedcraft:multi_thering_15/multi_thering_15_base2_palette",
  "xsize": 16,
  "zsize": 16,
  "slices": [
    [
      "vvvvvvvvvvvvvvvv",
      "aaaaaaaaaaaaaaaa",
      "aaaaaaaaaaaaaaaa",
      "aaaaaaaaaaaaaaaa",
      "aaaaaaaaaaaaaaaa",
      "aaaaaaaaaaaaaaaa",
      "aaaaaaaaaaaaaaaa",
      "aaaaaaaaaaaaaaaa",
      "aaaaaaaaaaaaaaaa",
      "aaaaaaaaaaaaaaaa",
      "aaaaaaaaaaaaaaaa",
      "aaaaaaaaaaaaaaaa",
      "aaaaaaaaaaaaaaaa",
      "aaaaaaaaaaaaaaaa",
      "aaaaaaaaaaaaaaaa",
      "baaaaaaaaaaaaaaa"
    ],
    [
      "vvvvvvvvvvvvvvvv",
      "aaaaaaaaaaaaaaaa",
      "aaaaaaaaaaaaaaaa",
      "aaaaaaaaaaaaaaaa",
      "aaaaaaaaaaaaaaaa",
      "aaaaaaaaaaaaaaaa",
      "aaaaaaaaaaaaaaaa",
      "aaaaaaaaaaaaaaaa",
      "aaaaaaaaaaaaaaaa",
      "aaaaaaaaaaaaaaaa",
      "aaaaaaaaaaaaaaaa",
      "aaaaaaaaaaaaaaaa",
      "aaaaaaaaaaaaaaaa",
      "aaaaaaaaaaaaaaaa",
      "aaaaaaaaaaaaaaaa",
      "baaaaaaaaaaaaaaa"
    ],
    [
      "vvvvvvvvvvvvvvvv",
      "cccccccccccccccc",
      "cccccccccccccccc",
      "cccccccccccccccc",
      "cccccccccccccccc",
      "cccccccccccccccc",
      "cccccccccccccccc",
      "cccccccccccccccc",
      "cccccccccccccccc",
      "cccccccccccccccc",
      "cccccccccccccccc",
      "cccccccccccccccc",
      "cccccccccccccccc",
      "cccccccccccccccc",
      "cccccccccccccccc",
      "bccccccccccccccc"
    ],
    [
      "vvvvvvvvvvvvvvvv",
      "dddddddddddddddd",
      "eeeeeeeeeeeeeeed",
      "eeeeeeeeeeeeeeed",
      "eeeeeeeeeeeeeeed",
      "eeeffffffffffeed",
      "eeeffffffffffeed",
      "eeeeeeeeeeeeeeed",
      "eeeeeeeeeeeeeeed",
      "eeeeeeeeeeeeeeed",
      "eeeffffffffffeed",
      "eeeffffffffffeed",
      "eeeeeeeeeeeeeeed",
      "eeeeeeeeeeeeeeed",
      "eeeeeeeeeeeeeeed",
      "deeffffffffffeed"
    ],
    [
      "vvvvvvvvvvvvvvvv",
      "dddddddddddddddd",
      "ghg        !ighd",
      "               d",
      "               d",
      "   jjjjjjjjjj  d",
      "   jjjjjjjjjj  d",
      "               d",
      "               d",
      "               d",
      "   jjjjjjjjjj  d",
      "   jjjjjjjjjj  d",
      "               d",
      "               d",
      "               d",
      "k  lmlmmnnnoo  d"
    ],
    [
      "vvvvvvvvvvvvvvvv",
      "dddddddddddddddd",
      "gpgqqqrrrsrssgpd",
      "   qqrr rrsss  d",
      "               d",
      "   tuututtuuu  d",
      "   wxwwwxwwxx  d",
      "              yd",
      "              Ad",
      "              Bd",
      "   CCCDDDEDEE  d",
      "   FFIFFIIJIJ  d",
      "               d",
      "               d",
      "               d",
      "k y          K d"
    ]
  ]
}