{
  "name": "multi_thering_15_floor7",
  "refpalette": "deceasedcraft:multi_thering_15/multi_thering_15_floor7_palette",
  "xsize": 16,
  "zsize": 16,
  "slices": [
    [
      "                ",
      "                ",
      "                ",
      "                ",
      "aa              ",
      "bbaaa           ",
      "ccbbbaaa        ",
      "cccccbbaaa      ",
      "cccccccbbaa     ",
      "bbcccccccbbaa   ",
      " bbbcccccccbba  ",
      "   bbbbcccccbbaa",
      "     dbbccccccba",
      "       bbbcccccb",
      "        dbbccccc",
      "e       d bbbccc"
    ],
    [
      "                ",
      "                ",
      "                ",
      "                ",
      "                ",
      "ff              ",
      "ggfff           ",
      "hhgggff         ",
      "iiihhggff       ",
      "  iiihhggff     ",
      "    iiiijggff   ",
      "       iihhgff  ",
      "     k  iiihggf ",
      "          iihjgf",
      "        k  iiihg",
      "e       k    iih"
    ],
    [
      "                ",
      "                ",
      "                ",
      "                ",
      "                ",
      "                ",
      "gg              ",
      "  ggg           ",
      "     gg         ",
      "       gg       ",
      "         gg     ",
      "           g    ",
      "     g      gg  ",
      "              g ",
      "        g      g",
      "e       g       "
    ],
    [
      "                ",
      "                ",
      "                ",
      "                ",
      "                ",
      "                ",
      "                ",
      "                ",
      "                ",
      "                ",
      "                ",
      "                ",
      "     g          ",
      "                ",
      "        g       ",
      "e       g       "
    ],
    [
      "                ",
      "                ",
      "                ",
      "                ",
      "                ",
      "                ",
      "                ",
      "                ",
      "                ",
      "                ",
      "                ",
      "                ",
      "     l          ",
      "                ",
      "        g       ",
      "e       l       "
    ],
    [
      "                ",
      "                ",
      "                ",
      "                ",
      "                ",
      "                ",
      "                ",
      "                ",
      "                ",
      "                ",
      "                ",
      "                ",
      "                ",
      "                ",
      "        l       ",
      "e               "
    ]
  ]
}