{
  "name": "multi_thering_15_ground",
  "refpalette": "deceasedcraft:multi_thering_15/multi_thering_15_ground_palette",
  "xsize": 16,
  "zsize": 16,
  "slices": [
    [
      "aaaaaaaaaaaaaaaa",
      "HHHHHHHHHHHHHHHH",
      "HHHHHHHHHHHHHHHH",
      "aaaaaaaaaaaaaaaa",
      "bbHHHHHHHHHHHHbb",
      "bbHHHHHHHHHHHHbb",
      "bbHHHHHHHHHHHHbb",
      "bbHHHHHHHHHHHHbb",
      "aaaaaaaaaaaaaaaa",
      "HHHHHHHHHHHHHHHH",
      "HHHHHHHHHHHHHHHH",
      "aaaaaaaaaaaaaaaa",
      "cccccccccccccccc",
      "dddddddddddddddd",
      "dddddddddddddddd",
      "eccccccccccccccc"
    ],
    [
      "                ",
      "                ",
      "                ",
      "                ",
      " fghghghghghghf ",
      " f    i       fj",
      "jf            f ",
      " fklklklklklklf ",
      "                ",
      "                ",
      "                ",
      "                ",
      "                ",
      "                ",
      "                ",
      "m               "
    ],
    [
      "                ",
      "                ",
      "                ",
      "                ",
      "                ",
      "               f",
      "f               ",
      "                ",
      "                ",
      "                ",
      "                ",
      "                ",
      "                ",
      "                ",
      "                ",
      "m               "
    ],
    [
      "                ",
      "                ",
      "                ",
      "                ",
      "                ",
      "               n",
      "n               ",
      "                ",
      "                ",
      "                ",
      "                ",
      "                ",
      "                ",
      "                ",
      "                ",
      "m               "
    ],
    [
      "                ",
      "                ",
      "                ",
      "                ",
      "               n",
      "n             nn",
      "nn             o",
      "o               ",
      "                ",
      "                ",
      "                ",
      "                ",
      "                ",
      "                ",
      "                ",
      "m               "
    ],
    [
      "                ",
      "                ",
      "                ",
      "                ",
      "               n",
      "n             on",
      "n              n",
      "n               ",
      "                ",
      "                ",
      "                ",
      "                ",
      "                ",
      "                ",
      "                ",
      "m               "
    ]
  ]
}