{
  "name": "building_hardwarestorece_ground",
  "refpalette": "deceasedcraft:building_hardwarestorece/building_hardwarestorece_ground_palette",
  "xsize": 16,
  "zsize": 16,
  "slices": [
    [
      "aaabbbbaaHHHHHaa",
      "aaabbbbaaHHHHHaa",
      "aaabbbbaccHHHcca",
      "adddbbddccccccca",
      "adddddddccccccca",
      "adddddddccccccca",
      "adddddddccccccca",
      "adddddddccccccca",
      "adddddddccccccca",
      "addddddddccdccca",
      "adddddddddddddda",
      "adddddddddddddda",
      "adddddddddddddda",
      "adddddddddddddda",
      "adddddddddddddda",
      "aaaaaaaaaaaaaaaa"
    ],
    [
      "                ",
      "                ",
      "        eefffee ",
      " ggghhggei   je ",
      " gkklmkken   oe ",
      " gkp  q er   se ",
      " gkp  q et u  e ",
      " gkp  q ew   xe ",
      " gky  q eA B Ce ",
      " gky  q eeeDeee ",
      " gk          kg ",
      " gk          kg ",
      " gkEFIEIFFEFEkg ",
      " gkkkkkkkkkkkkg ",
      " gggggggggggggg ",
      "                "
    ],
    [
      "                ",
      "                ",
      "        eefffee ",
      " JKK  KKeL   Le ",
      " KkkMNkkeL   Le ",
      " Kk     eL   Le ",
      " Kk     eL O Le ",
      " Kk     eL   Le ",
      " KkP  Q eLRS Le ",
      " KkT  U eee eee ",
      " Kk          kK ",
      " Kk          kK ",
      " KkIVEIEIIIIEkK ",
      " KkkkkkkkkkkkkK ",
      " JKKKKKKKKKKKKJ ",
      "                "
    ],
    [
      "                ",
      "                ",
      "        eefffee ",
      " JWW  WWeX    e ",
      " WkkYYkkej   xb ",
      " Wk     eZ   j0 ",
      " W1     e2   3b ",
      " W1     e4   50 ",
      " Wk     e6 7 xe ",
      " Wk     eee8eee ",
      " W1          kW ",
      " W1          kW ",
      " Wk          kW ",
      " Wkk11kkkk11kkW ",
      " JWWWWWWWWWWWWJ ",
      "                "
    ],
    [
      "                ",
      "                ",
      "        eefffee ",
      " JWW99WWe ### e ",
      " Wkkkkkke     $ ",
      " Wk     e     $ ",
      " Wk     e     $ ",
      " Wk    %e     $ ",
      " Wk     e     e ",
      " Wk     eeeeeee ",
      " Wk          kW ",
      " Wk          kW ",
      " Wk  ^^^^^^  kW ",
      " WkkkkkkkkkkkkW ",
      " JWWWWWWWWWWWWJ ",
      "                "
    ],
    [
      "                ",
      "                ",
      "        eeeeeee ",
      " J&&**&&e     e ",
      " &kkkkkke     e ",
      " &k     e     e ",
      " &k     e     e ",
      " &k     e     e ",
      " &k     e     e ",
      " &k     eeeeeee ",
      " &k          k& ",
      " &k          k& ",
      " &k  ((((((  k& ",
      " &kkkkkkkkkkkk& ",
      " J&&&&&&&&&&&&J ",
      "                "
    ]
  ]
}