{
  "name": "building_hardwarestorece_ground_90",
  "refpalette": "deceasedcraft:building_hardwarestorece/building_hardwarestorece_ground_palette_90",
  "xsize": 16,
  "zsize": 16,
  "slices": [
    [
      "aaaaaaaaaaaaaaaa",
      "aaccccccccddddda",
      "HHccccccccddddda",
      "HHHcccccccddddda",
      "HHHccccccdddddda",
      "HHHcccccccddddda",
      "HHccccccccddddda",
      "aacccccccdddddda",
      "aaadddddddddddda",
      "bbbdddddddddddda",
      "bbbbddddddddddda",
      "bbbbddddddddddda",
      "bbbdddddddddddda",
      "aaadddddddddddda",
      "aaadddddddddddda",
      "aaaaaaaaaaaaaaaa"
    ],
    [
      "                ",
      "  eeeeeeeeggggg ",
      "  ejos xCekkkkg ",
      "  f      e  Ekg ",
      "  f   u BD  Fkg ",
      "  f      e  Ekg ",
      "  einrtwAe  Fkg ",
      "  eeeeeeee  Fkg ",
      "   gk       Ikg ",
      "   gkqqqqq  Ekg ",
      "   hm       Ikg ",
      "   hl       Fkg ",
      "   gkpppyy  Ekg ",
      "   gkkkkkkkkkkg ",
      "   gggggggggggg ",
      "                "
    ],
    [
      "                ",
      "  eeeeeeeeKKKKJ ",
      "  eLLLLLLekkkkK ",
      "  f      e  EkK ",
      "  f   O S   IkK ",
      "  f     Re  IkK ",
      "  eLLLLLLe  IkK ",
      "  eeeeeeee  IkK ",
      "   Kk       EkK ",
      "   Kk   QU  IkK ",
      "    N       EkK ",
      "    M       VkK ",
      "   Kk   PT  IkK ",
      "   KkkkkkkkkkkK ",
      "   JKKKKKKKKKKJ ",
      "                "
    ],
    [
      "                ",
      "  eeb0b0eeWWWWJ ",
      "  e xj35xekkkkW ",
      "  f      e   kW ",
      "  f     78   1W ",
      "  f      e   1W ",
      "  eXjZ246e   kW ",
      "  eeeeeeee   kW ",
      "   Wk        kW ",
      "   Wk        kW ",
      "    Y        1W ",
      "    Y        1W ",
      "   Wk        kW ",
      "   Wkk11kk11kkW ",
      "   JWWWWWWWWWWJ ",
      "                "
    ],
    [
      "                ",
      "  ee$$$$eeWWWWJ ",
      "  e      ekkkkW ",
      "  f#     e   kW ",
      "  f#     e   kW ",
      "  f#     e  ^kW ",
      "  e      e  ^kW ",
      "  eeeeeeee  ^kW ",
      "   Wk  %    ^kW ",
      "   Wk       ^kW ",
      "   9k       ^kW ",
      "   9k        kW ",
      "   Wk        kW ",
      "   WkkkkkkkkkkW ",
      "   JWWWWWWWWWWJ ",
      "                "
    ],
    [
      "                ",
      "  eeeeeeee&&&&J ",
      "  e      ekkkk& ",
      "  e      e   k& ",
      "  e      e   k& ",
      "  e      e  (k& ",
      "  e      e  (k& ",
      "  eeeeeeee  (k& ",
      "   &k       (k& ",
      "   &k       (k& ",
      "   *k       (k& ",
      "   *k        k& ",
      "   &k        k& ",
      "   &kkkkkkkkkk& ",
      "   J&&&&&&&&&&J ",
      "                "
    ]
  ]
}