{
  "name": "building_hardwarestorece_ground_270",
  "refpalette": "deceasedcraft:building_hardwarestorece/building_hardwarestorece_ground_palette_270",
  "xsize": 16,
  "zsize": 16,
  "slices": [
    [
      "aaaaaaaaaaaaaaaa",
      "addddddddddddaaa",
      "addddddddddddaaa",
      "addddddddddddbbb",
      "adddddddddddbbbb",
      "adddddddddddbbbb",
      "addddddddddddbbb",
      "addddddddddddaaa",
      "addddddcccccccaa",
      "adddddccccccccHH",
      "adddddcccccccHHH",
      "addddddccccccHHH",
      "adddddcccccccHHH",
      "adddddccccccccHH",
      "adddddccccccccaa",
      "aaaaaaaaaaaaaaaa"
    ],
    [
      "                ",
      " gggggggggggg   ",
      " gkkkkkkkkkkg   ",
      " gkE  yypppkg   ",
      " gkF       lh   ",
      " gkI       mh   ",
      " gkE  qqqqqkg   ",
      " gkI       kg   ",
      " gkF  eeeeeeee  ",
      " gkF  eAwtrnie  ",
      " gkE  e      f  ",
      " gkF  DB u   f  ",
      " gkE  e      f  ",
      " gkkkkeCx soje  ",
      " gggggeeeeeeee  ",
      "                "
    ],
    [
      "                ",
      " JKKKKKKKKKKJ   ",
      " KkkkkkkkkkkK   ",
      " KkI  TP   kK   ",
      " KkV       M    ",
      " KkE       N    ",
      " KkI  UQ   kK   ",
      " KkE       kK   ",
      " KkI  eeeeeeee  ",
      " KkI  eLLLLLLe  ",
      " KkI  eR     f  ",
      " KkI   S O   f  ",
      " KkE  e      f  ",
      " KkkkkeLLLLLLe  ",
      " JKKKKeeeeeeee  ",
      "                "
    ],
    [
      "                ",
      " JWWWWWWWWWWJ   ",
      " Wkk11kk11kkW   ",
      " Wk        kW   ",
      " W1        Y    ",
      " W1        Y    ",
      " Wk        kW   ",
      " Wk        kW   ",
      " Wk   eeeeeeee  ",
      " Wk   e642ZjXe  ",
      " W1   e      f  ",
      " W1   87     f  ",
      " Wk   e      f  ",
      " Wkkkkex53jx e  ",
      " JWWWWee0b0bee  ",
      "                "
    ],
    [
      "                ",
      " JWWWWWWWWWWJ   ",
      " WkkkkkkkkkkW   ",
      " Wk        kW   ",
      " Wk        k9   ",
      " Wk^       k9   ",
      " Wk^       kW   ",
      " Wk^    %  kW   ",
      " Wk^  eeeeeeee  ",
      " Wk^  e      e  ",
      " Wk^  e     #f  ",
      " Wk   e     #f  ",
      " Wk   e     #f  ",
      " Wkkkke      e  ",
      " JWWWWee$$$$ee  ",
      "                "
    ],
    [
      "                ",
      " J&&&&&&&&&&J   ",
      " &kkkkkkkkkk&   ",
      " &k        k&   ",
      " &k        k*   ",
      " &k(       k*   ",
      " &k(       k&   ",
      " &k(       k&   ",
      " &k(  eeeeeeee  ",
      " &k(  e      e  ",
      " &k(  e      e  ",
      " &k   e      e  ",
      " &k   e      e  ",
      " &kkkke      e  ",
      " J&&&&eeeeeeee  ",
      "                "
    ]
  ]
}