{
  "name": "building_hardwarestorece_ground_180",
  "refpalette": "deceasedcraft:building_hardwarestorece/building_hardwarestorece_ground_palette_180",
  "xsize": 16,
  "zsize": 16,
  "slices": [
    [
      "aaaaaaaaaaaaaaaa",
      "adddddddddddddda",
      "adddddddddddddda",
      "adddddddddddddda",
      "adddddddddddddda",
      "adddddddddddddda",
      "acccdccdddddddda",
      "acccccccddddddda",
      "acccccccddddddda",
      "acccccccddddddda",
      "acccccccddddddda",
      "acccccccddddddda",
      "acccccccddbbddda",
      "accHHHccabbbbaaa",
      "aaHHHHHaabbbbaaa",
      "aaHHHHHaabbbbaaa"
    ],
    [
      "                ",
      " gggggggggggggg ",
      " gkkkkkkkkkkkkg ",
      " gkEFEFFIEIFEkg ",
      " gk          kg ",
      " gk          kg ",
      " eeeDeee q  ykg ",
      " eC B Ae q  ykg ",
      " ex   we q  pkg ",
      " e  u te q  pkg ",
      " es   re q  pkg ",
      " eo   nekkmlkkg ",
      " ej   iegghhggg ",
      " eefffee        ",
      "                ",
      "                "
    ],
    [
      "                ",
      " JKKKKKKKKKKKKJ ",
      " KkkkkkkkkkkkkK ",
      " KkEIIIIEIEVIkK ",
      " Kk          kK ",
      " Kk          kK ",
      " eee eee U  TkK ",
      " eL SRLe Q  PkK ",
      " eL   Le     kK ",
      " eL O Le     kK ",
      " eL   Le     kK ",
      " eL   LekkNMkkK ",
      " eL   LeKK  KKJ ",
      " eefffee        ",
      "                ",
      "                "
    ],
    [
      "                ",
      " JWWWWWWWWWWWWJ ",
      " Wkk11kkkk11kkW ",
      " Wk          kW ",
      " Wk          1W ",
      " Wk          1W ",
      " eee8eee     kW ",
      " ex 7 6e     kW ",
      " 05   4e     1W ",
      " b3   2e     1W ",
      " 0j   Ze     kW ",
      " bx   jekkYYkkW ",
      " e    XeWW  WWJ ",
      " eefffee        ",
      "                ",
      "                "
    ],
    [
      "                ",
      " JWWWWWWWWWWWWJ ",
      " WkkkkkkkkkkkkW ",
      " Wk  ^^^^^^  kW ",
      " Wk          kW ",
      " Wk          kW ",
      " eeeeeee     kW ",
      " e     e     kW ",
      " $     e%    kW ",
      " $     e     kW ",
      " $     e     kW ",
      " $     ekkkkkkW ",
      " e ### eWW99WWJ ",
      " eefffee        ",
      "                ",
      "                "
    ],
    [
      "                ",
      " J&&&&&&&&&&&&J ",
      " &kkkkkkkkkkkk& ",
      " &k  ((((((  k& ",
      " &k          k& ",
      " &k          k& ",
      " eeeeeee     k& ",
      " e     e     k& ",
      " e     e     k& ",
      " e     e     k& ",
      " e     e     k& ",
      " e     ekkkkkk& ",
      " e     e&&**&&J ",
      " eeeeeee        ",
      "                ",
      "                "
    ]
  ]
}