{
  "name": "multi_cabin2_1_floor1",
  "refpalette": "deceasedcraft:multi_cabin2_1/multi_cabin2_1_floor1_palette",
  "xsize": 16,
  "zsize": 16,
  "slices": [
    [
      "aaabcdeeeedcaaaa",
      "aaabcdeeeedcaaaa",
      "aaabcdeeeedcaaaa",
      "aaabcdeeeedcaaaa",
      "aaabcdeeeedcaaaa",
      "aaabcdeeeedcaaaa",
      "aaabcdeeeedcaaaa",
      "aaabcdeeeedcaaaa",
      "aaabcdeeeedcaaaa",
      "aaabcdeeeedcaaaa",
      "aaabcddddddcaaaa",
      "aaaaccccccccaaaa",
      "aaaaaaaaaaaaaaaa",
      "aaaaaaaaaaaaaaaa",
      "aaaaaaaaaaaaaaaa",
      "aaaaaaaaaaaaaaaa"
    ],
    [
      "fghffifffjkgffff",
      "fghfflfffmkgffff",
      "fghfnlfffokgffff",
      "fghfplfffqkgffff",
      "fghfflfffqkgfffr",
      "fghffiffstkgffff",
      "fghfflffuvkgffff",
      "fghfnlfffwkgffff",
      "fghfplfffxkgfrff",
      "fghfflffffkgffff",
      "fghffyllllkgffff",
      "fgggggggggggffff",
      "ffffffffffffffff",
      "fffffrffrfffffrf",
      "ffrffffffffrffff",
      "ffffffffffffffff"
    ],
    [
      "fffffifffzkfffff",
      "ffffflfffflfffff",
      "ffffflfffflfffff",
      "ffffflfffflfffff",
      "ffffflfffflffffA",
      "fffffiffffkfffff",
      "ffffflfffBlfffff",
      "ffffflfffflfffff",
      "ffffflfffflffAff",
      "ffffflfffflfffff",
      "fffffyllllkfffff",
      "ffffffffffffffff",
      "ffffffffffffffff",
      "fffffAffAfffffAf",
      "ffAffffffffAffff",
      "ffffffffffffffff"
    ],
    [
      "fffffiffffkfffff",
      "ffffflffffkfffff",
      "ffffflffffkfffff",
      "ffffflffffkfffff",
      "ffffflffffkfffff",
      "fffffiffffkfffff",
      "ffffflffffkfffff",
      "ffffflffffkfffff",
      "ffffflffffkfffff",
      "ffffflffffkfffff",
      "fffffyllllkfffff",
      "ffffffffffffffff",
      "ffffffffffffffff",
      "ffffffffffffffff",
      "ffffffffffffffff",
      "ffffffffffffffff"
    ],
    [
      "fffffCDDDDEfffff",
      "fffffCDDDDEfffff",
      "fffffCDDDDEfffff",
      "fffffCDDDDEfffff",
      "fffffCDDDDEfffff",
      "fffffCDDDDEfffff",
      "fffffCDDDDEfffff",
      "fffffCDDDDEfffff",
      "fffffCDDDDEfffff",
      "fffffCDDDDEfffff",
      "fffffFGGGGHfffff",
      "ffffffffffffffff",
      "ffffffffffffffff",
      "ffffffffffffffff",
      "ffffffffffffffff",
      "ffffffffffffffff"
    ],
    [
      "ffffIkJJJJkIffff",
      "ffffIkJJJJkIffff",
      "ffffIkJJJJkIffff",
      "ffffIkJJJJkIffff",
      "ffffIkJJJJkIffff",
      "ffffIkJJJJkIffff",
      "ffffIkJJJJkIffff",
      "ffffIkJJJJkIffff",
      "ffffIkKKKKkIffff",
      "ffffIkaaaakIffff",
      "ffffIkkkkkkIffff",
      "ffffIIIIIIIIffff",
      "ffffffffffffffff",
      "ffffffffffffffff",
      "ffffffffffffffff",
      "ffffffffffffffff"
    ]
  ]
}