{
  "name": "multi_cabin2_1part2_floor1",
  "refpalette": "deceasedcraft:multi_cabin2_1/multi_cabin2_1part2_floor1_palette",
  "xsize": 16,
  "zsize": 16,
  "slices": [
    [
      "aaaaaaaaaaaaaaaa",
      "aaaaaaaaaaaaaaaa",
      "aaaaaaaaaaaaaaaa",
      "aaaaaaaaaaaaaaaa",
      "aaaaaaaaaaaaaaaa",
      "aaaaaaaaaaaaaaaa",
      "aaaaaaaaaaaaaaaa",
      "aaaaaaaaaaaaaaaa",
      "aaaaaaaaaaaaaaaa",
      "aaaaaaaaaaaaaaaa",
      "aaaaaaaaaaaaaaaa",
      "aaaaaaaaaaaaaaaa",
      "aaaaaaaaaaaaaaaa",
      "aaaaaaaaaaaaaaaa",
      "aaaaaaaaaaaaaaaa",
      "aaaaaaaaaaaaaaaa"
    ],
    [
      "aaaaabaaaaaaaaaa",
      "aaaaacaaaaaaaaaa",
      "aaaaacaaaaaaaaaa",
      "aaaaacaaaaaaaaaa",
      "aaaaacaaaaaaaaaa",
      "aaaaabaaaaaaaaaa",
      "aaaaacaaaaaaaaaa",
      "aaaaacaaaaaaaaaa",
      "aaaaacaaaaaaaaaa",
      "aaaaacaaaaaaaaaa",
      "aaaaadccccaaaaaa",
      "aaaaaaaaaaaaaaaa",
      "aaaaaaaaaaaaaaaa",
      "aaaaaaaaaaaaaaaa",
      "aaaaaaaaaaaaaaaa",
      "aaaaaaaaaaaaaaaa"
    ],
    [
      "aaaaabaaaaaaaaaa",
      "aaaaacaaaacaaaaa",
      "aaaaacaaaacaaaaa",
      "aaaaacaaaacaaaaa",
      "aaaaacaaaacaaaaa",
      "aaaaabaaaaaaaaaa",
      "aaaaacaaaecaaaaa",
      "aaaaacaaaacaaaaa",
      "aaaaacaaaacaaaaa",
      "aaaaacaaaacaaaaa",
      "aaaaadccccaaaaaa",
      "aaaaaaaaaaaaaaaa",
      "aaaaaaaaaaaaaaaa",
      "aaaaaaaaaaaaaaaa",
      "aaaaaaaaaaaaaaaa",
      "aaaaaaaaaaaaaaaa"
    ],
    [
      "aaaaabaaaaaaaaaa",
      "aaaaacaaaaaaaaaa",
      "aaaaacaaaaaaaaaa",
      "aaaaacaaaaaaaaaa",
      "aaaaacaaaaaaaaaa",
      "aaaaabaaaaaaaaaa",
      "aaaaacaaaaaaaaaa",
      "aaaaacaaaaaaaaaa",
      "aaaaacaaaaaaaaaa",
      "aaaaacaaaaaaaaaa",
      "aaaaadccccaaaaaa",
      "aaaaaaaaaaaaaaaa",
      "aaaaaaaaaaaaaaaa",
      "aaaaaaaaaaaaaaaa",
      "aaaaaaaaaaaaaaaa",
      "aaaaaaaaaaaaaaaa"
    ],
    [
      "aaaaaaaaaaaaaaaa",
      "aaaaaaaaaaaaaaaa",
      "aaaaaaaaaaaaaaaa",
      "aaaaaaaaaaaaaaaa",
      "aaaaaaaaaaaaaaaa",
      "aaaaaaaaaaaaaaaa",
      "aaaaaaaaaaaaaaaa",
      "aaaaaaaaaaaaaaaa",
      "aaaaaaaaaaaaaaaa",
      "aaaaaaaaaaaaaaaa",
      "aaaaaaaaaaaaaaaa",
      "aaaaaaaaaaaaaaaa",
      "aaaaaaaaaaaaaaaa",
      "aaaaaaaaaaaaaaaa",
      "aaaaaaaaaaaaaaaa",
      "aaaaaaaaaaaaaaaa"
    ],
    [
      "aaaaaaaaaaaaaaaa",
      "aaaaaaaaaaaaaaaa",
      "aaaaaaaaaaaaaaaa",
      "aaaaaaaaaaaaaaaa",
      "aaaaaaaaaaaaaaaa",
      "aaaaaaaaaaaaaaaa",
      "aaaaaaaaaaaaaaaa",
      "aaaaaaaaaaaaaaaa",
      "aaaaaaaaaaaaaaaa",
      "aaaaaaaaaaaaaaaa",
      "aaaaaaaaaaaaaaaa",
      "aaaaaaaaaaaaaaaa",
      "aaaaaaaaaaaaaaaa",
      "aaaaaaaaaaaaaaaa",
      "aaaaaaaaaaaaaaaa",
      "aaaaaaaaaaaaaaaa"
    ]
  ]
}