{
  "name": "multi_cabin1_1_floor1",
  "refpalette": "deceasedcraft:multi_cabin1_1/multi_cabin1_1_floor1_palette",
  "xsize": 16,
  "zsize": 16,
  "slices": [
    [
      "abbcccccccccccbb",
      "abbcccccccccccbb",
      "abbcccccccccbbbb",
      "aabbccccccccbbba",
      "aabbbccccccbbbba",
      "aabbbbdbbdbbbbba",
      "aaabbbbbbbbbbbaa",
      "aaabbbbbbbbbbbaa",
      "aaaabbbbbbbbbaaa",
      "aaaaaabbbbbbaaaa",
      "aaaaaaaaaaaaaaaa",
      "aaaaaaaaaaaaaaaa",
      "aaaaaaaaaaaaaaaa",
      "aaaaaaaaaaaaaaaa",
      "aaaaaaaaaaaaaaaa",
      "aaaaaaaaaaaaaaaa"
    ],
    [
      "aaabccccccccbbaa",
      "aaabcccccccbbbaa",
      "aaabbccccccbaaaa",
      "aaaabbccccbbaaaa",
      "aaaaabbbbbbaaaaa",
      "aaaaaaeaaeaaaaaa",
      "aaaaaaaaaaaaaaaa",
      "aaaaaaaaaaaaaaaa",
      "aaaaaaaaaaaaaaaa",
      "aaaaaaaaaaaaaaaa",
      "aaaaaaaaaaaaaaaa",
      "aaaaaaaaaaaaaaaa",
      "aaaaaaaaaaaaaaaa",
      "aaaaaaaaaaaaaaaa",
      "aaaaaaaaaaaaaaaa",
      "aaaaaaaaaaaaaaaa"
    ],
    [
      "aaaabbbbbbbbaaaa",
      "aaaabbbbbbbaaaaa",
      "aaaaabbbbbbaaaaa",
      "aaaaaabbbbaaaaaa",
      "aaaaaaaaaaaaaaaa",
      "aaaaaaeaaeaaaaaa",
      "aaaaaaaaaaaaaaaa",
      "aaaaaaaaaaaaaaaa",
      "aaaaaaaaaaaaaaaa",
      "aaaaaaaaaaaaaaaa",
      "aaaaaaaaaaaaaaaa",
      "aaaaaaaaaaaaaaaa",
      "aaaaaaaaaaaaaaaa",
      "aaaaaaaaaaaaaaaa",
      "aaaaaaaaaaaaaaaa",
      "aaaaaaaaaaaaaaaa"
    ],
    [
      "aaaaaaaaaaaaaaaa",
      "aaaaaaaaaaaaaaaa",
      "aaaaaaaaaaaaaaaa",
      "aaaaaaaaaaaaaaaa",
      "aaaaaaaaaaaaaaaa",
      "aaaaaaeaaeaaaaaa",
      "aaaaaaaaaaaaaaaa",
      "aaaaaaaaaaaaaaaa",
      "aaaaaaaaaaaaaaaa",
      "aaaaaaaaaaaaaaaa",
      "aaaaaaaaaaaaaaaa",
      "aaaaaaaaaaaaaaaa",
      "aaaaaaaaaaaaaaaa",
      "aaaaaaaaaaaaaaaa",
      "aaaaaaaaaaaaaaaa",
      "aaaaaaaaaaaaaaaa"
    ],
    [
      "aaaaafggggfaaaaa",
      "aaaaafggggfaaaaa",
      "aaaaafggggfaaaaa",
      "aaaaafggggfaaaaa",
      "aaaaafggggfaaaaa",
      "aaaaafhgghfaaaaa",
      "aaaaafggggfaaaaa",
      "aaaaafggggfaaaaa",
      "aaaaafggggfaaaaa",
      "aaaaaffffffaaaaa",
      "aaaaaaaaaaaaaaaa",
      "aaaaaaaaaaaaaaaa",
      "aaaaaaaaaaaaaaaa",
      "aaaaaaaaaaaaaaaa",
      "aaaaaaaaaaaaaaaa",
      "aaaaaaaaaaaaaaaa"
    ],
    [
      "aaaiifjaakfiiaaa",
      "aaaiifjaalfiiaaa",
      "aaaaafmaamfaaaaa",
      "aaaaafnaaofaaaaa",
      "aaaaafmppmfaaaaa",
      "aaaaafqpprfaaaaa",
      "aaaaafqpprfaaaaa",
      "aaaaafspptfaaaaa",
      "aaaaafuuuufaaaaa",
      "aaaaaffffffaaaaa",
      "aaaaaaaaaaaaaaaa",
      "aaaaaaaaaaaaaaaa",
      "aaaaaaaaaaaaaaaa",
      "aaaaaaaaaaaaaaaa",
      "aaaaaaaaaaaaaaaa",
      "aaaaaaaaaaaaaaaa"
    ]
  ]
}