{
  "name": "multi_cabin1_1_top",
  "refpalette": "deceasedcraft:multi_cabin1_1/multi_cabin1_1_top_palette",
  "xsize": 16,
  "zsize": 16,
  "slices": [
    [
      "aaaaabcaadbaaaaa",
      "aaaaabcaadbaaaaa",
      "aaaeebaaaabeeaaa",
      "aaaeebaaaabeeaaa",
      "aaaeebfaagbeeaaa",
      "aaahhbaaaabhhaaa",
      "aaahhbaaaabhhaaa",
      "aaahhbiaajbhhaaa",
      "aaaaabkkkkbaaaaa",
      "aaaaabbbbbbaaaaa",
      "aaaaaaaaaaaaaaaa",
      "aaaaaaaaaaaaaaaa",
      "aaaaaaaaaaaaaaaa",
      "aaaaaaaaaaaaaaaa",
      "aaaaaaaaaaaaaaaa",
      "aaaaaaaaaaaaaaaa"
    ],
    [
      "aaaaalaaaalaaaaa",
      "aaaaalaaaalaaaaa",
      "aaaaalaaaalaaaaa",
      "aaaaalaaaalaaaaa",
      "aaaaalaaaalaaaaa",
      "aaaaalaaaalaaaaa",
      "aaaaalaaaalaaaaa",
      "aaaaalmmmmlaaaaa",
      "aaaenopppponeaaa",
      "aaaenooooooneaaa",
      "aaaennnnnnnneaaa",
      "aaaeeeeeeeeeeaaa",
      "aaaaaaaaaaaaaaaa",
      "aaaaaaaaaaaaaaaa",
      "aaaaaaaaaaaaaaaa",
      "aaaaaaaaaaaaaaaa"
    ],
    [
      "aaaaalaaaalaaaaa",
      "aaaaalmmmmlaaaaa",
      "aaaahoqqqqohaaaa",
      "aaaahoqqqqohaaaa",
      "aaaahoqqqqohaaaa",
      "aaaaeaqqqqaeaaaa",
      "aaaaeaqqqqaeaaaa",
      "aaaaeaqqqqaeaaaa",
      "aaaaaaaaaaaaaaaa",
      "aaaaaaaaaaaaaaaa",
      "aaaaaaaaaaaaaaaa",
      "aaaaaaaaaaaaaaaa",
      "aaaaaaaaaaaaaaaa",
      "aaaaaaaaaaaaaaaa",
      "aaaaaaaaaaaaaaaa",
      "aaaaaaaaaaaaaaaa"
    ],
    [
      "aaaaeaqqqqaeaaaa",
      "aaaaeaqqqqaeaaaa",
      "aaaaaaaaaaaaaaaa",
      "aaaaaaaaaaaaaaaa",
      "aaaaaaaaaaaaaaaa",
      "aaaaaaaaaaaaaaaa",
      "aaaaaaaaaaaaaaaa",
      "aaaaaaaaaaaaaaaa",
      "aaaaaaaaaaaaaaaa",
      "aaaaaaaaaaaaaaaa",
      "aaaaaaaaaaaaaaaa",
      "aaaaaaaaaaaaaaaa",
      "aaaaaaaaaaaaaaaa",
      "aaaaaaaaaaaaaaaa",
      "aaaaaaaaaaaaaaaa",
      "aaaaaaaaaaaaaaaa"
    ],
    [
      "aaaaaaaaaaaaaaaa",
      "aaaaaaaaaaaaaaaa",
      "aaaaaaaaaaaaaaaa",
      "aaaaaaaaaaaaaaaa",
      "aaaaaaaaaaaaaaaa",
      "aaaaaaaaaaaaaaaa",
      "aaaaaaaaaaaaaaaa",
      "aaaaaaaaaaaaaaaa",
      "aaaaaaaaaaaaaaaa",
      "aaaaaaaaaaaaaaaa",
      "aaaaaaaaaaaaaaaa",
      "aaaaaaaaaaaaaaaa",
      "aaaaaaaaaaaaaaaa",
      "aaaaaaaaaaaaaaaa",
      "aaaaaaaaaaaaaaaa",
      "aaaaaaaaaaaaaaaa"
    ],
    [
      "aaaaaaaaaaaaaaaa",
      "aaaaaaaaaaaaaaaa",
      "aaaaaaaaaaaaaaaa",
      "aaaaaaaaaaaaaaaa",
      "aaaaaaaaaaaaaaaa",
      "aaaaaaaaaaaaaaaa",
      "aaaaaaaaaaaaaaaa",
      "aaaaaaaaaaaaaaaa",
      "aaaaaaaaaaaaaaaa",
      "aaaaaaaaaaaaaaaa",
      "aaaaaaaaaaaaaaaa",
      "aaaaaaaaaaaaaaaa",
      "aaaaaaaaaaaaaaaa",
      "aaaaaaaaaaaaaaaa",
      "aaaaaaaaaaaaaaaa",
      "aaaaaaaaaaaaaaaa"
    ]
  ]
}