{
  "name": "multi_thering_21_floor7",
  "refpalette": "deceasedcraft:multi_thering_21/multi_thering_21_floor7_palette",
  "xsize": 16,
  "zsize": 16,
  "slices": [
    [
      "aabcc           ",
      "aaabc           ",
      "aaaabc          ",
      "baaabbc         ",
      "baaaabc         ",
      "bbaaaabc        ",
      "dbbaaabcc       ",
      "e baaaabc       ",
      " ebbaaabcc      ",
      "   bbaaabc      ",
      "  d baaabc      ",
      "    baaaabc     ",
      "   ebbaaabc     ",
      "     baaabc     ",
      "     bbaaabc    ",
      "f     baaabc    "
    ],
    [
      "ghi             ",
      "jghi            ",
      "jjghi           ",
      " jghii          ",
      " jjghi          ",
      "  jjkhi         ",
      "l  jghi         ",
      "m  jjghi        ",
      " m  jjhi        ",
      "     jghi       ",
      "  l  jghi       ",
      "     jj hi      ",
      "   m  jghi      ",
      "      jjhi      ",
      "       jghi     ",
      "f      jghi     "
    ],
    [
      " h              ",
      "  h             ",
      "   h            ",
      "   h            ",
      "    h           ",
      "     h          ",
      "m    h          ",
      "h     h         ",
      " h    h         ",
      "       h        ",
      "  m    h        ",
      "        h       ",
      "   h    h       ",
      "        h       ",
      "         h      ",
      "f        h      "
    ],
    [
      "                ",
      "                ",
      "                ",
      "                ",
      "                ",
      "                ",
      "h               ",
      "h               ",
      " h              ",
      "                ",
      "  h             ",
      "                ",
      "   h            ",
      "                ",
      "                ",
      "f               "
    ],
    [
      "                ",
      "                ",
      "                ",
      "                ",
      "                ",
      "                ",
      "h               ",
      "n               ",
      " n              ",
      "                ",
      "  h             ",
      "                ",
      "   n            ",
      "                ",
      "                ",
      "f               "
    ],
    [
      "                ",
      "                ",
      "                ",
      "                ",
      "                ",
      "                ",
      "n               ",
      "                ",
      "                ",
      "                ",
      "  n             ",
      "                ",
      "                ",
      "                ",
      "                ",
      "f               "
    ]
  ]
}