{
  "name": "multi_thering_21_ground",
  "refpalette": "deceasedcraft:multi_thering_21/multi_thering_21_ground_palette",
  "xsize": 16,
  "zsize": 16,
  "slices": [
    [
      "abbbbbbbbbbbbacc",
      "abbbbbbbbbbbaccc",
      "abbbbbbbbbbbaccc",
      "abbbbbbbbbbbaccc",
      "abbbbbbbbbbbaccc",
      "abbbbbbbbbbbaccc",
      "abbbcbbbbbbbaccc",
      "abbbbbbbbbbbaccc",
      "abbbbbbbbbbbaccc",
      "abbbbbbbbbbbaccc",
      "abbbbbbbbbbbaccc",
      "abbbbbbbbbbbaccc",
      "abbbbbbbbbbbaccc",
      "abbbcbbbbbbbaccc",
      "abbbbbbbddbbaccc",
      "abbbbbbdedbbaccc"
    ],
    [
      "             fgg",
      "             g  ",
      "             g  ",
      "             g  ",
      "             g  ",
      "             g  ",
      "    h       fg  ",
      "             g  ",
      "            ig  ",
      "            jg  ",
      "            jg  ",
      "            kg  ",
      "             g  ",
      "    h       fg  ",
      "        ll   g  ",
      "m      lnl   g  "
    ],
    [
      "             o  ",
      "                ",
      "                ",
      "                ",
      "                ",
      "                ",
      "    p       o   ",
      "                ",
      "                ",
      "                ",
      "                ",
      "                ",
      "                ",
      "    p       o   ",
      "                ",
      "m               "
    ],
    [
      "                ",
      "                ",
      "                ",
      "                ",
      "                ",
      "                ",
      "    g           ",
      "                ",
      "                ",
      "                ",
      "                ",
      "                ",
      "                ",
      "    g           ",
      "                ",
      "m               "
    ],
    [
      "                ",
      "                ",
      "                ",
      "                ",
      "                ",
      "                ",
      "    g           ",
      "                ",
      "                ",
      "                ",
      "                ",
      "                ",
      "                ",
      "    g           ",
      "                ",
      "m               "
    ],
    [
      "                ",
      "                ",
      "                ",
      "                ",
      "                ",
      "                ",
      "    g           ",
      "                ",
      "                ",
      "                ",
      "                ",
      "                ",
      "                ",
      "    g           ",
      "                ",
      "m               "
    ]
  ]
}