{
  "name": "multi_thering_21_floor16",
  "refpalette": "deceasedcraft:multi_thering_21/multi_thering_21_floor16_palette",
  "xsize": 16,
  "zsize": 16,
  "slices": [
    [
      "aaaaaaaaaaa     ",
      "bbbbbbbbbba     ",
      "bbbbbbbbbba     ",
      "bbbbbbbbbba     ",
      "bbbbbbbbbba     ",
      "bbbbbbbbbba     ",
      "bbbbbbbbbba     ",
      "bbbbbbbbbba     ",
      "aaaaaaaaaaa     ",
      "                ",
      "                ",
      "                ",
      "                ",
      "                ",
      "                ",
      "                "
    ],
    [
      "cccccccccccd    ",
      "cccccccccced    ",
      "cccccccccced    ",
      "cccccccccced    ",
      "cccccccccced    ",
      "cccccccccced    ",
      "cccccccfcced    ",
      "cccccccccced    ",
      "cccccccccced    ",
      "gggggggggggd    ",
      "                ",
      "                ",
      "                ",
      "                ",
      "                ",
      "                "
    ],
    [
      "ccchcccchccd    ",
      "iiiiiiiiij      ",
      "iiiiiiiiij      ",
      "iiiiiiiiij      ",
      "iiiiiiiiij      ",
      "iiiiiiiiij      ",
      "iiiiiiiiij      ",
      "iiiiiiiiij      ",
      "jjjjjjjjjj      ",
      "                ",
      "                ",
      "                ",
      "                ",
      "                ",
      "                ",
      "                "
    ],
    [
      "cccccccccccd    ",
      "iiiiiiiiij      ",
      "iiiiiiiiij      ",
      "iiiiiiiiij      ",
      "iiiiiiiiij      ",
      "iiiiiiiiij      ",
      "iiiiiiiiij      ",
      "iiiiiiiiij      ",
      "jjjjjjjjjj      ",
      "                ",
      "                ",
      "                ",
      "                ",
      "                ",
      "                ",
      "                "
    ],
    [
      "kkklkkkkl       ",
      "                ",
      "                ",
      "                ",
      "                ",
      "                ",
      "                ",
      "                ",
      "                ",
      "                ",
      "                ",
      "                ",
      "                ",
      "                ",
      "                ",
      "                "
    ],
    [
      "                ",
      "                ",
      "                ",
      "                ",
      "                ",
      "                ",
      "                ",
      "                ",
      "                ",
      "                ",
      "                ",
      "                ",
      "                ",
      "                ",
      "                ",
      "                "
    ]
  ]
}