{
  "name": "multi_nuclearpowerplant_43_base5",
  "refpalette": "deceasedcraft:multi_nuclearpowerplant_43/multi_nuclearpowerplant_43_base5_palette",
  "xsize": 16,
  "zsize": 16,
  "slices": [
    [
      "a   bb    c=deev",
      "a    b    c=deev",
      "a    b    c=deev",
      "a    b    c=deev",
      "a    b    c=deev",
      "afff b    c=deev",
      "a  f b    c=deev",
      "g  f b    c=deev",
      "   f b    c=deev",
      " fff b    c=deev",
      " f   b    c=deev",
      " f   b    c=deev",
      " f   b    c=deev",
      " f   b    c=deev",
      " f   b    c=deev",
      " f   b    c=deev"
    ],
    [
      "a   bb    c=deev",
      "a    b    c=deev",
      "a    b    c=deev",
      "a    b    c=deev",
      "ahhh b    c=deev",
      "i   jb    c=deev",
      "akl jb    c=deev",
      "g m jb    c=deev",
      " hl jb    c=deev",
      "m   jb    c=deev",
      "m lk b    c=deev",
      "m j  b    c=deev",
      "m j  b    c=deev",
      "m j  b    c=deev",
      "m j  b    c=deev",
      "m j  b    c=deev"
    ],
    [
      "a   bb    c=deev",
      "a    b    c=deev",
      "a    b    c=deev",
      "a    b    c=deev",
      "a    b    c=deev",
      "annn b    c=deev",
      "a  n b    c=deev",
      "g  n b    c=deev",
      "   n b    c=deev",
      " nnn b    c=deev",
      " n   b    c=deev",
      " n   b    c=deev",
      " n   b    c=deev",
      " n   b    c=deev",
      " n   b    c=deev",
      " n   b    c=deev"
    ],
    [
      "a   bb    c=deev",
      "     b    c=deev",
      "a    b    c=deev",
      "a    b    c=deev",
      "a    b    c=deev",
      "a    b    c=deev",
      "a    b    c=deev",
      "g    b    c=deev",
      "     b    c=deev",
      "     b    c=deev",
      "     b    c=deev",
      "     b    c=deev",
      "     b    c=deev",
      "     b    c=deev",
      "     b    c=deev",
      "     b    c=deev"
    ],
    [
      "a   bb    c=deev",
      "     b    c=deev",
      "     b    c=deev",
      "a    b    c=deev",
      "a    b    c=deev",
      "afff b    c=deev",
      "a  f b    c=deev",
      "g  f b    c=deev",
      "   f b    c=deev",
      " fff b    c=deev",
      " f   b    c=deev",
      " f   b    c=deev",
      " f   b    c=deev",
      " f   b    c=deev",
      " f   b    c=deev",
      " f   b    c=deev"
    ],
    [
      "a   bo    c=deev",
      "a    b    c=deev",
      "a    b    c=deev",
      "a    b    c=deev",
      "ahhh b    c=deev",
      "p   jb    c=deev",
      "akl jb    c=deev",
      "q m jb    c=deev",
      " hl jb    c=deev",
      "m   jb    c=deev",
      "m lk b    c=deev",
      "m j  b    c=deev",
      "m j  b    c=deev",
      "m j  b    c=deev",
      "m j  b    c=deev",
      "m j  b    c=deev"
    ]
  ]
}