{
  "name": "multi_nuclearpowerplant_43_base6",
  "refpalette": "deceasedcraft:multi_nuclearpowerplant_43/multi_nuclearpowerplant_43_base6_palette",
  "xsize": 16,
  "zsize": 16,
  "slices": [
    [
      "    aa    b=cddv",
      "     e    b=cddv",
      "     a    b=cddv",
      "     a    b=cddv",
      "     a    b=cddv",
      "     a    b=cddv",
      "     a    b=cddv",
      "f    a    b=cddv",
      "     a    b=cddv",
      "     a    b=cddv",
      "     a    b=cddv",
      "     a    b=cddv",
      "     a    b=cddv",
      "     a    b=cddv",
      "     a    b=cddv",
      "     a    b=cddv"
    ],
    [
      "    aa    b=gddv",
      "     a    b=gddv",
      "     a    b=gddv",
      "     a    b=gddv",
      "     a    b=gddv",
      "     a    b=gddv",
      "     a    b=gddv",
      "f    a    b=gddv",
      "     a    b=gddv",
      "     a    b=gddv",
      "     a    b=gddv",
      "     a    b=gddv",
      "     a    b=gddv",
      "     a    b=gddv",
      "     a    b=gddv",
      "     a    b=gddv"
    ],
    [
      "hhhhaa    b=gddv",
      "     a    b=gddv",
      "     a    b=gddv",
      "     a    b=gddv",
      "     a    b=gddv",
      "     a    b=gddv",
      "hhhhha    b=gddv",
      "f    a    b=gddv",
      "     a    b=gddv",
      "     a    b=gddv",
      "     a    b=gddv",
      "     a    b=gddv",
      "     a    b=gddv",
      "     a    b=gddv",
      "     a    b=gddv",
      "     a    b=gddv"
    ],
    [
      "i   aa    b=gddv",
      "i    a    b=gddv",
      "i    a    b=gddv",
      "i    a    b=gddv",
      "i    a    b=gddv",
      "i    a    b=gddv",
      "i    a    b=gddv",
      "f    a    b=gddv",
      "     a    b=gddv",
      "     a    b=gddv",
      "     a    b=gddv",
      "     a    b=gddv",
      "     a    b=gddv",
      "     a    b=gddv",
      "     a    b=gddv",
      "     a    b=gddv"
    ],
    [
      "f   aa    b=gddv",
      "f    a    b=gddv",
      "f    a    b=gddv",
      "f    a    b=gddv",
      "f    a    b=gddv",
      "f    a    b=gddv",
      "f    a    b=gddv",
      "f    a    b=gddv",
      "     a    b=gddv",
      "     a    b=gddv",
      "     a    b=gddv",
      "     a    b=gddv",
      "     a    b=gddv",
      "     a    b=gddv",
      "     a    b=gddv",
      "     a    b=gddv"
    ],
    [
      "j   aa    b=gddv",
      "j    a    b=gddv",
      "j    a    b=gddv",
      "j    a    b=gddv",
      "j    a    b=gddv",
      "j    a    b=gddv",
      "j    a    b=gddv",
      "j    a    b=gddv",
      "     a    b=gddv",
      "     a    b=gddv",
      "     a    b=gddv",
      "     a    b=gddv",
      "     a    b=gddv",
      "     a    b=gddv",
      "     a    b=gddv",
      "     a    b=gddv"
    ]
  ]
}