{
  "name": "multi_nuclearpowerplant_43_base1",
  "refpalette": "deceasedcraft:multi_nuclearpowerplant_43/multi_nuclearpowerplant_43_base1_palette",
  "xsize": 16,
  "zsize": 16,
  "slices": [
    [
      "a========bbbcddv",
      "e========bbbcddv",
      "e========bbbcddv",
      "fa=======bbbcddv",
      "fe=======bbbcddv",
      "fea======bbbcddv",
      "ea=======bbbcddv",
      "e========bbbcddv",
      "fa=======bbbcddv",
      "=========bbbcddv",
      "=========bbbcddv",
      "=========bbbcddv",
      "=========bbbcddv",
      "=========bbbcddv",
      "=========bbbcddv",
      "=========bbbcddv"
    ],
    [
      "gbbbbbbbbbbbcddv",
      "ggbbbbbbbbbbcddv",
      " ggbbbbbbbbbcddv",
      " ggbbbbbbbbbcddv",
      " hbbbbbbbbbbcddv",
      " hgbbbbbbbbbcddv",
      " gbbbbbbbbbbcddv",
      "hgbbbbbbbbbbcddv",
      "ihbbbbbbbbbbcddv",
      "gbbbbbbbbbbbcddv",
      "bbbbbbbbbbbbcddv",
      "bbbbbbbbbbbbcddv",
      "bbbbbbbbbbbbcddv",
      "bbbbbbbbbbbbcddv",
      "bbbbbbbbbbbbcddv",
      "bbbbbbbbbbbbcddv"
    ],
    [
      " hbbbbbbbbbbcddv",
      " igbbbbbbbbbcddv",
      " hgbbbbbbbbbcddv",
      "  hgbbbbbbbbcddv",
      "  igbbbbbbbbcddv",
      "  hgbbbbbbbbcddv",
      "  gbbbbbbbbbcddv",
      "  gbbbbbbbbbcddv",
      " hbbbbbbbbbbcddv",
      " ggbbbbbbbbbcddv",
      "ggbbbbbbbbbbcddv",
      "bbbbbbbbbbbbcddv",
      "bbbbbbbbbbbbcddv",
      "bbbbbbbbbbbbcddv",
      "bbbbbbbbbbbbcddv",
      "bbbbbbbbbbbbcddv"
    ],
    [
      "  hgbbbbbbbbcddv",
      "  hgbbbbbbbbcddv",
      "   gbbbbbbbbcddv",
      "    bbbbbbbbcddv",
      "   gbbbbbbbbcddv",
      "   gbbbbbbbbcddv",
      "   bbbbbbbbbcddv",
      "  hgbbbbbbbbcddv",
      "  hgbbbbbbbbcddv",
      "  hbbbbbbbbbcddv",
      " hgbbbbbbbbbcddv",
      "ggbbbbbbbbbbcddv",
      "bbbbbbbbbbbbcddv",
      "bbbbbbbbbbbbcddv",
      "bbbbbbbbbbbbcddv",
      "bbbbbbbbbbbbcddv"
    ],
    [
      "  jhbbbbbbbbcddv",
      "   zgbbbbbbbcddv",
      "    hbbbbbbbcddv",
      "    igbbbbbbcddv",
      "   khbbbbbbbcddv",
      "    bbbbbbbbcddv",
      "    gbbbbbbbcddv",
      "   kbbbbbbbbcddv",
      "   hgbbbbbbbcddv",
      "   hbbbbbbbbcddv",
      "  gbbbbbbbbbcddv",
      " ibbbbbbbbbbcddv",
      "igbbbbbbbbbbcddv",
      "bbbbbbbbbbbbcddv",
      "bbbbbbbbbbbbcddv",
      "bbbbbbbbbbbbcddv"
    ],
    [
      "    bbbbbbbbcbbv",
      "    kbbbbbbbcbbv",
      "     hbbbbbbcbbv",
      "      bbbbbbcbbv",
      "     zhbbbbbcbbv",
      "      bbbbbbcbbv",
      "     ibbbbbbcbbv",
      "     hbbbbbbcbbv",
      "     bbbbbbbcbbv",
      "    ibbbbbbbcbbv",
      "    hbbbbbbbcbbv",
      "  hbbbbbbbbbcbbv",
      " hllbbbbbbbbcbbv",
      "hbbllbbbbbbbcbbv",
      "hgbblbbbbbbbcbbv",
      "bbbbllbbbbbbcbbv"
    ]
  ]
}