{
  "name": "multi_nuclearpowerplant_43_ground",
  "refpalette": "deceasedcraft:multi_nuclearpowerplant_43/multi_nuclearpowerplant_43_ground_palette",
  "xsize": 16,
  "zsize": 16,
  "slices": [
    [
      "      zzzzzzzzzz",
      "      zzzzzzzzzz",
      "      azzzzzzzzz",
      "       zbzbzzzzb",
      "       zzzczzzzz",
      "       czzzzbzzz",
      "       dzzbzzzzz",
      "      dbzbzzzzzz",
      "     dzcbbzbzzzz",
      "      bbzzbzzzbz",
      "     abbbbzbzzzz",
      "   d bbzbzbbzzzz",
      "  eebbbbbbbbzbzz",
      "  ceebbbbbbzbbzz",
      "  aaebbbbbbbzzzz",
      "daaaeebbbbzbzbzz"
    ],
    [
      "       a        ",
      "                ",
      "            c   ",
      "                ",
      "                ",
      "                ",
      "                ",
      "          d     ",
      "                ",
      "         a      ",
      "               f",
      "                ",
      "   gh    c      ",
      "    zia     a   ",
      "   zzh          ",
      " z bzzi         "
    ],
    [
      "                ",
      "                ",
      "                ",
      "                ",
      "                ",
      "                ",
      "                ",
      "                ",
      "                ",
      "                ",
      "                ",
      "                ",
      "                ",
      "   gg           ",
      "    g           ",
      "    gg          "
    ],
    [
      "                ",
      "                ",
      "                ",
      "                ",
      "                ",
      "                ",
      "                ",
      "                ",
      "                ",
      "                ",
      "                ",
      "                ",
      "   g            ",
      "   gg           ",
      "    g           ",
      "    gg          "
    ],
    [
      "                ",
      "                ",
      "                ",
      "                ",
      "                ",
      "                ",
      "                ",
      "                ",
      "                ",
      "                ",
      "                ",
      "                ",
      "   j            ",
      "    j           ",
      "    j           ",
      "                "
    ],
    [
      "                ",
      "                ",
      "                ",
      "                ",
      "                ",
      "                ",
      "                ",
      "                ",
      "                ",
      "                ",
      "                ",
      "                ",
      "                ",
      "                ",
      "                ",
      "                "
    ]
  ]
}