{
  "name": "multi_nuclearpowerplant_43_base7",
  "refpalette": "deceasedcraft:multi_nuclearpowerplant_43/multi_nuclearpowerplant_43_base7_palette",
  "xsize": 16,
  "zsize": 16,
  "slices": [
    [
      "aaaabb    c=deev",
      "aaaaab    c=deev",
      "aaaaab    c=deev",
      "aaaaab    c=deev",
      "aaaaab    c=deev",
      "aaaaab    c=deev",
      "aaaaab    c=deev",
      " aaaab    c=deev",
      "aaaaab    c=deev",
      "aaaaab    c=deev",
      "aaaaab    c=deev",
      "aaaaab    c=deev",
      "aaaaab    c=deev",
      "aaaaab    c=deev",
      "aaaaab    c=deev",
      "aaaaab    c=deev"
    ],
    [
      "ffaabb    c=deev",
      "ffffab    c=deev",
      "fffffg    c=deev",
      "fafafb    c=deev",
      "fffaag    c=deev",
      "ffafab    c=deev",
      "ffaafb    c=deev",
      "@afaab    c=deev",
      "ffafab    c=deev",
      "ffafab    c=deev",
      "affaab    c=deev",
      "fafafb    c=deev",
      "aaaaab    c=deev",
      "aaaafb    c=deev",
      "faaaab    c=deev",
      "aaaaab    c=deev"
    ],
    [
      "    bb    c=deev",
      "     b    c=deev",
      "     g    c=deev",
      "     g    c=deev",
      "     g    c=deev",
      "     b    c=deev",
      "     g    c=deev",
      "h    b    c=deev",
      "     g    c=deev",
      "     b    c=deev",
      "     b    c=deev",
      "     g    c=deev",
      "     b    c=deev",
      "     b    c=deev",
      "     b    c=deev",
      "     b    c=deev"
    ],
    [
      "    bb    c=deev",
      "     b    c=deev",
      "     b    c=deev",
      "     g    c=deev",
      "     g    c=deev",
      "     g    c=deev",
      "     g    c=deev",
      "h    b    c=deev",
      "     b    c=deev",
      "     b    c=deev",
      "     b    c=deev",
      "     b    c=deev",
      "     b    c=deev",
      "     b    c=deev",
      "     b    c=deev",
      "     b    c=deev"
    ],
    [
      "    bb    c=deev",
      "     b    c=deev",
      "     b    c=deev",
      "     g    c=deev",
      "     b    c=deev",
      "     g    c=deev",
      "     b    c=deev",
      "h    b    c=deev",
      "     b    c=deev",
      "     b    c=deev",
      "     b    c=deev",
      "     b    c=deev",
      "     b    c=deev",
      "     b    c=deev",
      "     b    c=deev",
      "     b    c=deev"
    ],
    [
      "    bb    c=deev",
      "     b    c=deev",
      "     b    c=deev",
      "     b    c=deev",
      "     b    c=deev",
      "     g    c=deev",
      "     b    c=deev",
      "h    g    c=deev",
      "     b    c=deev",
      "     b    c=deev",
      "     b    c=deev",
      "     b    c=deev",
      "     b    c=deev",
      "     b    c=deev",
      "     b    c=deev",
      "     b    c=deev"
    ]
  ]
}