{
  "name": "multi_nuclearpowerplant_43_base4",
  "refpalette": "deceasedcraft:multi_nuclearpowerplant_43/multi_nuclearpowerplant_43_base4_palette",
  "xsize": 16,
  "zsize": 16,
  "slices": [
    [
      "a   bc    d=effv",
      "a    c    d=effv",
      "a    c    d=effv",
      "a    c    d=effv",
      "a    b    d=effv",
      "aggg c    d=effv",
      "a  g c    d=effv",
      "h  g c    d=effv",
      "   g c    d=effv",
      " ggg c    d=effv",
      " g   c    d=effv",
      " g   c    d=effv",
      " g   c    d=effv",
      " g   c    d=effv",
      " g   c    d=effv",
      " g   c    d=effv"
    ],
    [
      "h   cc    d=effv",
      "h    c    d=effv",
      "i    c    d=effv",
      "i    c    d=effv",
      "i    b    d=effv",
      "i    c    d=effv",
      "h    c    d=effv",
      "h    c    d=effv",
      "     c    d=effv",
      "     c    d=effv",
      "     c    d=effv",
      "     c    d=effv",
      "     c    d=effv",
      "     c    d=effv",
      "     c    d=effv",
      "     c    d=effv"
    ],
    [
      "    cb    d=effv",
      "     c    d=effv",
      "     c    d=effv",
      "     b    d=effv",
      "     b    d=effv",
      "     b    d=effv",
      "     c    d=effv",
      "     c    d=effv",
      "     c    d=effv",
      "     c    d=effv",
      "     c    d=effv",
      "     c    d=effv",
      "     c    d=effv",
      "     c    d=effv",
      "     c    d=effv",
      "     c    d=effv"
    ],
    [
      "    bb    d=effv",
      "     c    d=effv",
      "     c    d=effv",
      "     b    d=effv",
      "     j    d=effv",
      "     c    d=effv",
      "     c    d=effv",
      "     b    d=effv",
      "     c    d=effv",
      "     c    d=effv",
      "     c    d=effv",
      "     c    d=effv",
      "     c    d=effv",
      "     c    d=effv",
      "     c    d=effv",
      "     c    d=effv"
    ],
    [
      "    cc    d=effv",
      "     c    d=effv",
      "     b    d=effv",
      "     j    d=effv",
      "     j    d=effv",
      "     b    d=effv",
      "     c    d=effv",
      "     c    d=effv",
      "     c    d=effv",
      "     b    d=effv",
      "     c    d=effv",
      "     c    d=effv",
      "     c    d=effv",
      "     c    d=effv",
      "     c    d=effv",
      "     c    d=effv"
    ],
    [
      "    kk    d=effv",
      "     k    d=effv",
      "          d=effv",
      "          d=effv",
      "          d=effv",
      "          d=effv",
      "     k    d=effv",
      "     k    d=effv",
      "     k    d=effv",
      "          d=effv",
      "     k    d=effv",
      "     k    d=effv",
      "     k    d=effv",
      "     k    d=effv",
      "     k    d=effv",
      "     k    d=effv"
    ]
  ]
}