{
  "name": "multi_nuclearpowerplant_43_base9",
  "refpalette": "deceasedcraft:multi_nuclearpowerplant_43/multi_nuclearpowerplant_43_base9_palette",
  "xsize": 16,
  "zsize": 16,
  "slices": [
    [
      "            abbv",
      "            abbv",
      "            abbv",
      "           cabbv",
      "            abbv",
      "            abbv",
      "            abbv",
      "            abbv",
      "            abbv",
      "            abbv",
      "            abbv",
      "            abbv",
      "          d abbv",
      "           cabbv",
      "            abbv",
      "            abbv"
    ],
    [
      "            abbv",
      "            abbv",
      "            abbv",
      "           cabbv",
      "           eabbv",
      "           eabbv",
      "           eabbv",
      "           eabbv",
      "           eabbv",
      "           eabbv",
      "           eabbv",
      "           eabbv",
      "           eabbv",
      "           cabbv",
      "           eabbv",
      "           eabbv"
    ],
    [
      "            abbv",
      "            abbv",
      "            abbv",
      "           cabbv",
      "          fgabbv",
      "          fhabbv",
      "          fgabbv",
      "          fhabbv",
      "          f abbv",
      "          fgabbv",
      "          fgabbv",
      "          fgabbv",
      "          diabbv",
      "           cabbv",
      "          fhabbv",
      "          jgabbv"
    ],
    [
      "            abbv",
      "            abbv",
      "            abbv",
      "kkkkkkkkkklcabbv",
      "            abbv",
      "            abbv",
      "            abbv",
      "            abbv",
      "            abbv",
      "            abbv",
      "            abbv",
      "            abbv",
      "          d abbv",
      "kkkkkkkkkklcabbv",
      "            abbv",
      "            abbv"
    ],
    [
      "    c       abbv",
      "    c       abbv",
      "    c       abbv",
      "ccccccccccccabbv",
      "    c       abbv",
      "    c       abbv",
      "    c       abbv",
      "    c       abbv",
      "    c       abbv",
      "    c       abbv",
      "    c       abbv",
      "    c       abbv",
      "    c       abbv",
      "ccccccccccccabbv",
      "    c       abbv",
      "    c       abbv"
    ],
    [
      "            abbv",
      "            abbv",
      "    m       abbv",
      "   nco    pcabbv",
      "    q       abbv",
      "            abbv",
      "            abbv",
      "            abbv",
      "            abbv",
      "            abbv",
      "            abbv",
      "            abbv",
      "    m       abbv",
      "   nco    pcabbv",
      "    q       abbv",
      "            abbv"
    ]
  ]
}