{
  "name": "multi_nuclearpowerplant_43_base2",
  "refpalette": "deceasedcraft:multi_nuclearpowerplant_43/multi_nuclearpowerplant_43_base2_palette",
  "xsize": 16,
  "zsize": 16,
  "slices": [
    [
      "          a=bccv",
      "          a=bccv",
      "          a=bccv",
      "         da=bccv",
      "          a=bccv",
      "          a=bccv",
      "          a=bccv",
      "          a=bccv",
      "          a=bccv",
      "          a=bccv",
      "          a=bccv",
      "          a=bccv",
      "          a=bccv",
      "          a=bccv",
      "          a=bccv",
      "          a=bccv"
    ],
    [
      "          a=bccv",
      "          a=bccv",
      "          a=bccv",
      "   efghiiia=bccv",
      "          a=bccv",
      "          a=bccv",
      "          a=bccv",
      "          a=bccv",
      "          a=bccv",
      "          a=bccv",
      "          a=bccv",
      "          a=bccv",
      "          a=bccv",
      "          a=bccv",
      "          a=bccv",
      "          a=bccv"
    ],
    [
      " ij       a=bccv",
      "  ik      a=bccv",
      "   ij     a=bccv",
      "llmiiiinooa=bccv",
      "   ip     a=bccv",
      "  ip      a=bccv",
      "  p       a=bccv",
      "          a=bccv",
      "          a=bccv",
      "          a=bccv",
      "          a=bccv",
      "          a=bccv",
      "          a=bccv",
      "          a=bccv",
      "          a=bccv",
      "          a=bccv"
    ],
    [
      "         qa=bccv",
      "         qa=bccv",
      "         qa=bccv",
      "     ri  qa=bccv",
      "         qa=bccv",
      "         qa=bccv",
      "         qa=bccv",
      "         qa=bccv",
      "         qa=bccv",
      "         qa=bccv",
      "         qa=bccv",
      "         qa=bccv",
      "         qa=bccv",
      "         qa=bccv",
      "         qa=bccv",
      "         qa=bccv"
    ],
    [
      "        sa=tbccv",
      "        sa=tbccv",
      "        sa=tbccv",
      "      i sa=tbccv",
      "        sa=tbccv",
      "        sa=tbccv",
      "        sa=tbccv",
      "        sa=tbccv",
      "        sa=tbccv",
      "        sa=tbccv",
      "        sa=tbccv",
      "        sa=tbccv",
      "        sa=tbccv",
      "        sa=tbccv",
      "        sa=tbccv",
      "        sa=tbccv"
    ],
    [
      "uuwaaaaaa=ttbccv",
      "luluaaaaa=ttbccv",
      " uwuaaaaa=ttbccv",
      " luuaaaaa=ttbccv",
      " luaaaaaa=ttbccv",
      "luuaaaaaa=ttbccv",
      " uwaaaaaa=ttbccv",
      " luuaaaaa=ttbccv",
      "luwuaaaaa=ttbccv",
      "lwwaaaaaa=ttbccv",
      "luaaaaaaa=ttbccv",
      "wluaaaaaa=ttbccv",
      "wuaaaaaaa=ttbccv",
      "uaaaaaaaa=ttbccv",
      "aaaaaaaaa=ttbccv",
      "aaaaaaaaa=ttbccv"
    ]
  ]
}