{
  "name": "multi_nuclearpowerplant_43_base8",
  "refpalette": "deceasedcraft:multi_nuclearpowerplant_43/multi_nuclearpowerplant_43_base8_palette",
  "xsize": 16,
  "zsize": 16,
  "slices": [
    [
      "            abbv",
      "            abbv",
      "            abbv",
      "    c      cabbv",
      "            abbv",
      "            abbv",
      "            abbv",
      "            abbv",
      "            abbv",
      "            abbv",
      "            abbv",
      "            abbv",
      "            abbv",
      "    c      cabbv",
      "            abbv",
      "            abbv"
    ],
    [
      "ddddddddddddebbv",
      "ddddddddddddebbv",
      "ddddddddddddebbv",
      "dddddddddddfebbv",
      "ddddddddddddebbv",
      "ddddddddddddebbv",
      "ddddddddddddebbv",
      "ddddddddddddebbv",
      "ddddddddddddebbv",
      "ddddddddddddebbv",
      "ddddddddddddebbv",
      "ddddddddddddebbv",
      "ddddddddddddebbv",
      "dddddddddddfebbv",
      "ddddddddddddebbv",
      "ddddddddddddebbv"
    ],
    [
      "bbbbbbbbbbbbabbv",
      "bbbbbbbbbbbbabbv",
      "bbbbbbbbbbbbabbv",
      "bbbbbbbbbbbbabbv",
      "bbbbbbbbbbbbabbv",
      "bbbbbbbbbbbbabbv",
      "bbbbbbbbbbbbabbv",
      "bbbbbbbbbbbbabbv",
      "bbbbbbbbbbbbabbv",
      "bbbbbbbbbbbbabbv",
      "bbbbbbbbbbbbabbv",
      "bbbbbbbbbbbbabbv",
      "bbbbbbbbbbbbabbv",
      "bbbbbbbbbbbbabbv",
      "bbbbbbbbbbbbabbv",
      "bbbbbbbbbbbbabbv"
    ],
    [
      "bbbbbbbbbbbbabbv",
      "bbbbbbbbbbbbabbv",
      "bbbbbbbbbbbbabbv",
      "bbbbbbbbbbbbabbv",
      "bbbbbbbbbbbbabbv",
      "bbbbbbbbbbbbabbv",
      "bbbbbbbbbbbbabbv",
      "bbbbbbbbbbbbabbv",
      "bbbbbbbbbbbbabbv",
      "bbbbbbbbbbbbabbv",
      "bbbbbbbbbbbbabbv",
      "bbbbbbbbbbbbabbv",
      "bbbbbbbbbbbbabbv",
      "bbbbbbbbbbbbabbv",
      "bbbbbbbbbbbbabbv",
      "bbbbbbbbbbbbabbv"
    ],
    [
      "===========gabbv",
      "===========gabbv",
      "===========gabbv",
      "===========gabbv",
      "===========gabbv",
      "===========gabbv",
      "===========gabbv",
      "===========gabbv",
      "===========gabbv",
      "===========gabbv",
      "===========gabbv",
      "===========gabbv",
      "===========gabbv",
      "===========gabbv",
      "===========gabbv",
      "===========gabbv"
    ],
    [
      "fffffffffff=abbv",
      "fffffffffff=abbv",
      "fffffffffff=abbv",
      "fffffffffff=abbv",
      "fffffffffff=abbv",
      "fffffffffff=abbv",
      "fffffffffff=abbv",
      "fffffffffff=abbv",
      "fffffffffff=abbv",
      "fffffffffff=abbv",
      "fffffffffff=abbv",
      "fffffffffff=abbv",
      "fffffffffff=abbv",
      "fffffffffff=abbv",
      "fffffffffff=abbv",
      "fffffffffff=abbv"
    ]
  ]
}