{
  "name": "multi_nuclearpowerplant_43_base11",
  "refpalette": "deceasedcraft:multi_nuclearpowerplant_43/multi_nuclearpowerplant_43_base11_palette",
  "xsize": 16,
  "zsize": 16,
  "slices": [
    [
      "aab=========cddv",
      "aab=========cddv",
      "aaab========cddv",
      "aaab========cddv",
      "aaab========cddv",
      "aaab========cddv",
      "aaab========cddv",
      "aaab========cddv",
      "aaab========cddv",
      "efab========cddv",
      "ghab========cddv",
      "aaab========cddv",
      "efab========cddv",
      "ghab========cddv",
      "aaab========cddv",
      "fhab========cddv"
    ],
    [
      "aab=========cddv",
      "aab=========cddv",
      "aaab========cddv",
      "aaab========cddv",
      "aaab========cddv",
      "aaab========cddv",
      "aaab========cddv",
      "aaab========cddv",
      "aaab========cddv",
      "fhab========cddv",
      "egab========cddv",
      "aaab========cddv",
      "fhab========cddv",
      "egab========cddv",
      "aaab========cddv",
      "efab========cddv"
    ],
    [
      "aab=========cddv",
      "aab=========cddv",
      "aaab========cddv",
      "aaab========cddv",
      "aaab========cddv",
      "aaab========cddv",
      "aaab========cddv",
      "aaab========cddv",
      "aaab========cddv",
      "fhab========cddv",
      "egab========cddv",
      "aaab========cddv",
      "efab========cddv",
      "ghab========cddv",
      "aaab========cddv",
      "fhab========cddv"
    ],
    [
      "aab=========cddv",
      "aab=========cddv",
      "aaab========cddv",
      "aaab========cddv",
      "aaab========cddv",
      "aaab========cddv",
      "aaab========cddv",
      "aaab========cddv",
      "aaab========cddv",
      "aaab========cddv",
      "aaab========cddv",
      "aaab========cddv",
      "aaab========cddv",
      "aaab========cddv",
      "aaab========cddv",
      "aaab========cddv"
    ],
    [
      "aab=========cddv",
      "aab=========cddv",
      "aaab========cddv",
      "aaab========cddv",
      "aaab========cddv",
      "aaab========cddv",
      "aaab========cddv",
      "aaab========cddv",
      "aaab========cddv",
      "aaab========cddv",
      "aaab========cddv",
      "aaab========cddv",
      "aaab========cddv",
      "aaab========cddv",
      "aaab========cddv",
      "aaab========cddv"
    ],
    [
      "aab=========cddv",
      "aab=========cddv",
      "aaab========cddv",
      "aaab========cddv",
      "aaab========cddv",
      "aaab========cddv",
      "aaab========cddv",
      "aaab========cddv",
      "aaab========cddv",
      "aaab========cddv",
      "aaab========cddv",
      "aaab========cddv",
      "aaab========cddv",
      "aaab========cddv",
      "aaab========cddv",
      "aaab========cddv"
    ]
  ]
}