{
  "name": "multi_nuclearpowerplant_43_base10",
  "refpalette": "deceasedcraft:multi_nuclearpowerplant_43/multi_nuclearpowerplant_43_base10_palette",
  "xsize": 16,
  "zsize": 16,
  "slices": [
    [
      "  abccccccccdeev",
      "  abbcccccccdeev",
      "   abcccccffdeev",
      "   abcccccfgdeev",
      "   abcccccffdeev",
      "   abcccccccdeev",
      "   abcccccccdeev",
      "   abcccccccdeev",
      "   abcccccccdeev",
      "   hbcccccccdeev",
      "   hbcccccccdeev",
      "   hbcccccccdeev",
      "   hbcccccffdeev",
      "   hbcccccfgdeev",
      "   hbcccccffdeev",
      "   hbcccccccdeev"
    ],
    [
      "   i        jeev",
      "   k        jeev",
      "    i       jeev",
      "    i     lmjeev",
      "    i      njeev",
      "    i      njeev",
      "    i      njeev",
      "    i      njeev",
      "nnno       njeev",
      "    i      njeev",
      "    i      njeev",
      "    i      njeev",
      "    i      njeev",
      "    i     lmjeev",
      "    i      njeev",
      "    i p    njeev"
    ],
    [
      "            jeev",
      "            jeev",
      "            jeev",
      "           mjeev",
      "          qrjeev",
      "          qsjeev",
      "          qtjeev",
      "          qsjeev",
      "uuu       qrjeev",
      "          qsjeev",
      "          qwjeev",
      "          qsjeev",
      "          xyjeev",
      "           mjeev",
      "          qrjeev",
      "          qsjeev"
    ],
    [
      "            jeev",
      "            jeev",
      "            jeev",
      "           mjeev",
      "            jeev",
      "            jeev",
      "            jeev",
      "            jeev",
      "            jeev",
      "            jeev",
      "            jeev",
      "            jeev",
      "          x jeev",
      "           mjeev",
      "            jeev",
      "            jeev"
    ],
    [
      "            jeev",
      "            jeev",
      "            jeev",
      "           mjeev",
      "           njeev",
      "           njeev",
      "           njeev",
      "           njeev",
      "           njeev",
      "           njeev",
      "           njeev",
      "           njeev",
      "           njeev",
      "           mjeev",
      "           njeev",
      "           njeev"
    ],
    [
      "            jeev",
      "            jeev",
      "            jeev",
      "           mjeev",
      "          qsjeev",
      "          qAjeev",
      "          qrjeev",
      "          qsjeev",
      "          qsjeev",
      "          qsjeev",
      "          qsjeev",
      "          qsjeev",
      "          xyjeev",
      "           mjeev",
      "          qsjeev",
      "          q jeev"
    ]
  ]
}