{
  "name": "multi_nuclearpowerplant_43_base12",
  "refpalette": "deceasedcraft:multi_nuclearpowerplant_43/multi_nuclearpowerplant_43_base12_palette",
  "xsize": 16,
  "zsize": 16,
  "slices": [
    [
      "aaaaaaaaaaaaaaav",
      "aaaaaaaaaaaaaaav",
      "aaaaaaaaaaaaaaav",
      "aaaaaaaaaaaaaaav",
      "aaaaaaaaaaaaaaav",
      "aaaaaaaaaaaaaaav",
      "aaaaaaaaaaaaaaav",
      "aaaaaaaaaaaaaaav",
      "aaaaaaaaaaaaaaav",
      "aaaaaaaaaaaaaaav",
      "aaaaaaaaaaaaaaav",
      "aaaaaaaaaaaaaaav",
      "aaaaaaaaaaaaaaav",
      "aaaaaaaaaaaaaaav",
      "aaaaaaaaaaaaaaav",
      "aaaaaaaaaaaaaaav"
    ],
    [
      "bbbbbbbbbbbbbaav",
      "bbbbbbbbbbbbbaav",
      "bbbbbbbbbbbbbaav",
      "bbbbbbbbbbbbbaav",
      "bbbbbbbbbbbbbaav",
      "bbbbbbbbbbbbbaav",
      "bbbbbbbbbbbbbaav",
      "bbbbbbbbbbbbbaav",
      "bbbbbbbbbbbbbaav",
      "bbbbbbbbbbbbbaav",
      "bbbbbbbbbbbbbaav",
      "bbbbbbbbbbbbbaav",
      "bbbbbbbbbbbbbaav",
      "bbbbbbbbbbbbbaav",
      "bbbbbbbbbbbbbaav",
      "bbbbbbbbbbbbbaav"
    ],
    [
      "============caav",
      "============caav",
      "============caav",
      "============caav",
      "============caav",
      "============caav",
      "============caav",
      "============caav",
      "============caav",
      "============caav",
      "============caav",
      "============caav",
      "============caav",
      "============caav",
      "============caav",
      "============caav"
    ],
    [
      "ddb=========eaav",
      "ddb=========eaav",
      "dddb========eaav",
      "dddb========eaav",
      "dddb========eaav",
      "dddb========eaav",
      "dddb========eaav",
      "dddb========eaav",
      "dddb========eaav",
      "dddb========eaav",
      "dddb========eaav",
      "dddb========eaav",
      "dddb========eaav",
      "dddb========eaav",
      "dddb========eaav",
      "dddb========eaav"
    ],
    [
      "ffb=========eaav",
      "ffb=========eaav",
      "fffb========eaav",
      "fffb========eaav",
      "fffb========eaav",
      "fffb========eaav",
      "fffb========eaav",
      "fffb========eaav",
      "fffb========eaav",
      "ggfb========eaav",
      "ggfb========eaav",
      "fffb========eaav",
      "ggfb========eaav",
      "ggfb========eaav",
      "fffb========eaav",
      "ggfb========eaav"
    ],
    [
      "ffb=========eaav",
      "ffb=========eaav",
      "fffb========eaav",
      "fffb========eaav",
      "fffb========eaav",
      "fffb========eaav",
      "fffb========eaav",
      "fffb========eaav",
      "fffb========eaav",
      "hifb========eaav",
      "jkfb========eaav",
      "fffb========eaav",
      "hifb========eaav",
      "jkfb========eaav",
      "fffb========eaav",
      "jhfb========eaav"
    ]
  ]
}