{
  "name": "multi_laboratory_3_base4",
  "refpalette": "deceasedcraft:multi_laboratory_3/multi_laboratory_3_base4_palette",
  "xsize": 16,
  "zsize": 16,
  "slices": [
    [
      "vabccccccccccccc",
      "vabccccccccccccc",
      "vbbccccccccdcccc",
      "vbbccccccccccccc",
      "vbbccccccccccccc",
      "vbbccccccccccccc",
      "vbbccccccccccccc",
      "vbbccccccccccccc",
      "vbbccccccccccccc",
      "vbbccccccccdcccc",
      "vbbccccccccccccc",
      "vbbccccccccccccc",
      "vbbccccccccccccc",
      "vbbccccccccccccc",
      "vbbccccccccccccc",
      "vbbccccccccccccc"
    ],
    [
      "vabe f     g  h ",
      "vabii      j klm",
      "vbb       nd  l ",
      "vbbo      pj    ",
      "vbbqr   f nj fl ",
      "vbbp s    pjt  s",
      "vbbo      uj    ",
      "vbbqrf    uj    ",
      "vbbw   x yuj    ",
      "vbbAB    uAdjjjj",
      "vbbAq    CAjD   ",
      "vbbAE    FAj    ",
      "vbbAE    FAj    ",
      "vbbAo    IAj  JK",
      "vbbAqLMM uAj   u",
      "vbbAAAAAAAAj   N"
    ],
    [
      "vab        g  O ",
      "vabP       j    ",
      "vbb        d    ",
      "vbb       pj    ",
      "vbbQ       R    ",
      "vbbp       R    ",
      "vbbS      TR    ",
      "vbbQ      kR    ",
      "vbb        j    ",
      "vbbA     UAdjRRR",
      "vbbA     VAj    ",
      "vbbA      AW    ",
      "vbbA      AW    ",
      "vbbA     XAW   Y",
      "vbbA     ZAW    ",
      "vbbAAAAAAAAj    "
    ],
    [
      "vab        g    ",
      "vab        j    ",
      "vbb        d    ",
      "vbb        j    ",
      "vbb        R    ",
      "vbb        R    ",
      "vbb        R    ",
      "vbb        R    ",
      "vbb        j    ",
      "vbbA      AdjRRR",
      "vbbW      Aj    ",
      "vbbW     0A1    ",
      "vbbW     0A1    ",
      "vbbW      A1    ",
      "vbbA  22  A1    ",
      "vbbAAAAAAAAj    "
    ],
    [
      "vab        j    ",
      "vab        j    ",
      "vbb        d    ",
      "vbb        j    ",
      "vbb        j    ",
      "vbb        j    ",
      "vbb        j    ",
      "vbb        j    ",
      "vbb        j    ",
      "vbbA      Adjjjj",
      "vbb1      Aj    ",
      "vbb1      Aj    ",
      "vbb1      Aj    ",
      "vbb1      Aj    ",
      "vbbA      Aj    ",
      "vbbAAAAAAAAj    "
    ],
    [
      "vab3343353367877",
      "vab3343353367777",
      "vab33333333d7777",
      "vab3333333367777",
      "vab3353343367477",
      "vab3343353367877",
      "vab3353343367877",
      "vab3343353367977",
      "vab3333333367777",
      "vabA999999Ad####",
      "vabA9    9A63333",
      "vabA9$  $9A63333",
      "vabA9    9A63333",
      "vabA9    9A63355",
      "vabA999999A63353",
      "vabAAAAAAAA63393"
    ]
  ]
}