{
  "name": "multi_laboratory_3_base6",
  "refpalette": "deceasedcraft:multi_laboratory_3/multi_laboratory_3_base6_palette",
  "xsize": 16,
  "zsize": 16,
  "slices": [
    [
      "vabccccccccccccc",
      "vabccccccccccccc",
      "vbcccccccccdeeee",
      "vbfffffffffccccc",
      "vbffffbbbbfccccc",
      "vbffffbg bfccccc",
      "vbffffbg bfccccc",
      "vbffffbbbbfccccc",
      "vbfffffffffccccc",
      "vbhiiiiiiiidcccc",
      "vbjjjjcccccccc!c",
      "vbjjjjcccccccccc",
      "vbjjjjcccccccccc",
      "vbjjjjcccccccccc",
      "vbjjjjcccccccccc",
      "vbjjjjcccccccccc"
    ],
    [
      "vab             ",
      "vak             ",
      "vdllllllllldmmmm",
      "vb     nn  l    ",
      "vbo   pppp l    ",
      "vb   qpg prl    ",
      "vb   qpg prl    ",
      "vbo   pppp l    ",
      "vb st  uu  l wx ",
      "vdy  ydyyyyd  x ",
      "vb AB l    lC x ",
      "vbD   E    l    ",
      "vbF   l    l    ",
      "vbFI  l    l    ",
      "vb    l    l    ",
      "vbJKKJl    l  x "
    ],
    [
      "vab             ",
      "vak             ",
      "vdllllllllldLLLL",
      "vb         M    ",
      "vb         M    ",
      "vb     NN  M    ",
      "vb     OO  M    ",
      "vb         M    ",
      "vb PQ      M    ",
      "vdy  ydyyyyd  R ",
      "vb ST l    M    ",
      "vb    U    M    ",
      "vb    l    M    ",
      "vbV  Wl    M    ",
      "vb    l    M    ",
      "vbX   l    M  Y "
    ],
    [
      "vab             ",
      "vak             ",
      "vdllllllllldLLLL",
      "vb         M    ",
      "vb         M    ",
      "vb         M    ",
      "vb         M    ",
      "vb         M    ",
      "vb         M    ",
      "vdyyyydyyyyd    ",
      "vb    l    M    ",
      "vb    Z    M    ",
      "vb    l    M    ",
      "vb    l    M    ",
      "vb    l    M    ",
      "vb    l    M    "
    ],
    [
      "vab             ",
      "vak             ",
      "vdllllllllldLLLL",
      "vb         M    ",
      "vb         M    ",
      "vb         M    ",
      "vb         M    ",
      "vb         M    ",
      "vb         M    ",
      "vdyyyydyyyyd    ",
      "vb    l    M    ",
      "vb    l    M    ",
      "vb    l    M    ",
      "vb    l    M    ",
      "vb    l    M    ",
      "vb    l    M    "
    ],
    [
      "vab             ",
      "vak             ",
      "vdllllllllldLLLL",
      "vb         M    ",
      "vb         M    ",
      "vb         M    ",
      "vb         M    ",
      "vb         M    ",
      "vb         M    ",
      "vdyyyydyyyyd    ",
      "vb0000l    M    ",
      "vb0000l    M    ",
      "vb0000l    M    ",
      "vb0000l    M    ",
      "vb000 l    M    ",
      "vb0000l    M    "
    ]
  ]
}