{
  "name": "multi_laboratory_3_ground",
  "refpalette": "deceasedcraft:multi_laboratory_3/multi_laboratory_3_ground_palette",
  "xsize": 16,
  "zsize": 16,
  "slices": [
    [
      "zaazzavvbbbcdddd",
      "zzzaaaevbbbcdddd",
      "zazzzaevbbbcdddd",
      "zzzzaaaebbbcdddd",
      "azzazzavbbbcdddd",
      "zzaaaaevbbbcdddd",
      "zazfaaevbbbcdddd",
      "zzfazaavbbbcdddd",
      "azzaaaevbbbcdddd",
      "zzzazeeebbbcdddd",
      "zazzaaevbbbcdddd",
      "zzzazaevbbbcdddd",
      "zzaaaaeebbbcdddd",
      "zzzazaavbbbcdddd",
      "azazazvvbbbcdddd",
      "zzzazzevbbbcdddd"
    ],
    [
      "g   h   i  j klm",
      " g      i  j    ",
      "g  g    i  cn o ",
      "g g     i  j    ",
      " h      i  pqqqq",
      "gr h    s  jtuuu",
      "g wf r     pxuyA",
      " www       pqqqq",
      " w B       j    ",
      "    g      c   C",
      "           j  DE",
      "g          j FI!",
      "g          j  IJ",
      "  f g      j  IJ",
      "           j FIJ",
      "     g     j  KL"
    ],
    [
      "        i  j    ",
      "        i  j    ",
      "        i  c    ",
      "        M  N    ",
      "        i  pqOOO",
      "        i  j  u ",
      "        s  j P  ",
      "  w        pqqqq",
      "           N    ",
      "           c    ",
      "           j    ",
      "           j  Q ",
      "           j    ",
      "  ~        j    ",
      "           j    ",
      "           j    "
    ],
    [
      "        M  j    ",
      "        M  j    ",
      "        R  c    ",
      "        M  N    ",
      "        M  pqSSS",
      "        M  jP   ",
      "        i  j    ",
      "  w     s  pqqqq",
      "           N    ",
      "           c    ",
      "           j    ",
      "           j    ",
      "           j    ",
      "           j    ",
      "           j    ",
      "           j    "
    ],
    [
      "        R  j    ",
      "        R  j    ",
      "        M  c    ",
      "        R  N    ",
      "        R  pqqqq",
      "        M  jP   ",
      "        R  j    ",
      "        i  pqqqq",
      "        s  N    ",
      "           c    ",
      "           j    ",
      "           j    ",
      "           j    ",
      "           j    ",
      "           j    ",
      "           j    "
    ],
    [
      "        R  jTUUU",
      "        R  jTUUU",
      "        R  cTTTT",
      "        R  jTTTT",
      "        M  pqqqq",
      "        M  j P  ",
      "        M  jP   ",
      "        M  pqqqq",
      "        i  jTTTT",
      "        s  cTTTT",
      "           jTUUU",
      "           jTUUU",
      "           jTTTT",
      "           jTTTT",
      "           jTUUU",
      "           jTUUU"
    ]
  ]
}