{
  "name": "multi_laboratory_3_base3",
  "refpalette": "deceasedcraft:multi_laboratory_3/multi_laboratory_3_base3_palette",
  "xsize": 16,
  "zsize": 16,
  "slices": [
    [
      "vabccccccccccccc",
      "vabccccccccccdcc",
      "vabccccccccecccc",
      "vabccccccccccccc",
      "vabcccccccccfccc",
      "vabccccccccccccc",
      "vabccccccccccccc",
      "vabccccccccccccc",
      "vabgghhhhhhccccc",
      "vabccccccccecccc",
      "vabccccccccccccc",
      "vabccccccccccccc",
      "vabccccccccccccc",
      "vabccccccccccccc",
      "vabccccccccccccc",
      "vabccccccccccccc"
    ],
    [
      "vabi j     k  l ",
      "vab m n    o  l ",
      "vabp  q    e rl ",
      "vabstutwxyAo Bl ",
      "vabCC  DtDDo  l ",
      "vabEFEF    o IJK",
      "vabEE EL M o  N ",
      "vabEEOEEPLLo  Q ",
      "vab  RREESLoMT  ",
      "vabUV LE LUeoooo",
      "vabUW XE YUoZ   ",
      "vabU0 XXE1Uo    ",
      "vabU0 XXE2Uo    ",
      "vabU0 XEEEUo  34",
      "vabU56EEE Uo   7",
      "vabUUUUUUUUo   8"
    ],
    [
      "vab        k    ",
      "vab        o    ",
      "vab9       e    ",
      "vab        o  # ",
      "vab$j      %    ",
      "vabL L          ",
      "vabLL L    %    ",
      "vabE ^LLL  %    ",
      "vabEERR L& o    ",
      "vabU      Ueo%%%",
      "vabU  LL* Uo    ",
      "vabU(  E  U)    ",
      "vabU(     U)    ",
      "vabU     EU)    ",
      "vabU+   EEU)    ",
      "vabUUUUUUUUo    "
    ],
    [
      "vab        k    ",
      "vab        o    ",
      "vab        e    ",
      "vab        o    ",
      "vab        %    ",
      "vab        %    ",
      "vab        %    ",
      "vabL - [   %    ",
      "vabERRRR R o    ",
      "vabU      Ueo%%%",
      "vabU ]  - Uo    ",
      "vabU      U{    ",
      "vabU   }  U{    ",
      "vabU      U{    ",
      "vabU    E|U{    ",
      "vabUUUUUUUUo    "
    ],
    [
      "vab        o    ",
      "vab        o    ",
      "vab        e    ",
      "vab        o    ",
      "vab        o    ",
      "vab        o    ",
      "vab   EE   o    ",
      "vab  ||EE  o    ",
      "vabEEEE||E o    ",
      "vabUE|E|| Ueoooo",
      "vabUE;||E Uo    ",
      "vabUE|||E Uo    ",
      "vabU  |;E Uo    ",
      "vabU :    Uo    ",
      "vabU ' EEEUo    ",
      "vabUUUUUUUUo    "
    ],
    [
      "vab<<><<><<,.?..",
      "vab<</<<><<,....",
      "vab<<<<<<<<e....",
      "vab<<<<<<<<,....",
      "vab<<><<`<<,. ..",
      "vab<</<<><<,./..",
      "vab<<`<</<<,.?..",
      "vab<<><<><<,.?..",
      "vab<<<<<<<<,....",
      "vabU``````Ue\u0370\u0370\u0370\u0370",
      "vabU`\u0371\u0372\u0373\u0374`U,<<<<",
      "vabU`\u0372\u0373\u0374\u0375`U,<<<<",
      "vabU`\u0372\u0374\u0371\u0376`U,<<<<",
      "vabU`\u0371\u0372\u0374\u0377`U,<<>>",
      "vabU``````U,<<><",
      "vabUUUUUUUU,<<><"
    ]
  ]
}