{
  "name": "multi_laboratory_3_base1",
  "refpalette": "deceasedcraft:multi_laboratory_3/multi_laboratory_3_base1_palette",
  "xsize": 16,
  "zsize": 16,
  "slices": [
    [
      "vabccccccccccccc",
      "vabccccccccccccc",
      "vabccccccccdcccc",
      "vabcccccccccceee",
      "vabcccccccccceee",
      "vabcccccccccceee",
      "vabcccccccccceee",
      "vabcccccccccceee",
      "vabccccccccccc!c",
      "vabccccccccdcccc",
      "vabccccccccccccc",
      "vabccccccccccccc",
      "vabccccccccccccc",
      "vabccccccccccccc",
      "vabccccccccccccc",
      "vabccccccccccccc"
    ],
    [
      "vabf       g    ",
      "vabf hiiij g    ",
      "vabkkkkkkkkdl   ",
      "vabm  noppqk    ",
      "vabm  rpsoqkt   ",
      "vabuw rxxxqk  y ",
      "vabA       k BC ",
      "vabD wE    k  y ",
      "vabkiiF IJIkl  K",
      "vabkkkkLkkkdkkkk",
      "vabD     MMN OOy",
      "vabDw      N y  ",
      "vabD  w w  N    ",
      "vabA hPFPj N    ",
      "vabD hQRQj N    ",
      "vabu  w S  N    "
    ],
    [
      "vabT       g    ",
      "vabU   VW  g    ",
      "vabkkkkkkkkdX   ",
      "vab   Y    N    ",
      "vab        N    ",
      "vabZ       N    ",
      "vabZ       N    ",
      "vabZ       N    ",
      "vabk01   J NX   ",
      "vabkkkk2kkkdk333",
      "vab4    5  N 6  ",
      "vab7       N    ",
      "vabE       N    ",
      "vab        N    ",
      "vab8   9   N    ",
      "vab4       N    "
    ],
    [
      "vab        g    ",
      "vab        g    ",
      "vabkkkkkkkkd#   ",
      "vab$  n    N    ",
      "vab$       N    ",
      "vab%       N    ",
      "vab        N    ",
      "vab^       N    ",
      "vab$    $$$N#   ",
      "vabkkkkkkkkdk&&&",
      "vab!       N    ",
      "vabW       N    ",
      "vab        N    ",
      "vab        N    ",
      "vab        N    ",
      "vab*       N    "
    ],
    [
      "vab        g    ",
      "vab        g    ",
      "vabkkkkkkkkd    ",
      "vab   n    N    ",
      "vab        N    ",
      "vab        N    ",
      "vab        N    ",
      "vab        N    ",
      "vab        N    ",
      "vabkkkkkkkkdk(((",
      "vab        N    ",
      "vab        N    ",
      "vab        N    ",
      "vab        N    ",
      "vab        N    ",
      "vab        N    "
    ],
    [
      "vab))+)))-)[))))",
      "vab))))))))[))))",
      "vab]]]kkkkkd))))",
      "vab)))n))))[))))",
      "vab))-)))-)[))))",
      "vab))+)))-)[))))",
      "vab))-)))-)[))))",
      "vab))-)))-)[))))",
      "vab))))))))[))))",
      "vab]]]kkkkkdkkkk",
      "vab))))))))[))))",
      "vab))-)))-)[))))",
      "vab))-)))-)[))))",
      "vab))-)))-)[))))",
      "vab))-)))-)[))))",
      "vab))))))))[))))"
    ]
  ]
}