{
  "name": "multi_laboratory_3_base5",
  "refpalette": "deceasedcraft:multi_laboratory_3/multi_laboratory_3_base5_palette",
  "xsize": 16,
  "zsize": 16,
  "slices": [
    [
      "vab             ",
      "vac             ",
      "vdeeeeeeeeedffff",
      "vb         g    ",
      "vb         g    ",
      "vb         g    ",
      "vb         g    ",
      "vb         g    ",
      "vb         g    ",
      "vdddddddddddh   ",
      "vbiiiid    g    ",
      "vbiiiid    g    ",
      "vbiiiid    g    ",
      "vbiiiid    g    ",
      "vbiii d    g    ",
      "vbiiiid    g    "
    ],
    [
      "vab             ",
      "vac             ",
      "vdeeeeeeeeedffff",
      "vb         g    ",
      "vb         g    ",
      "vb         g    ",
      "vb         g    ",
      "vb         g    ",
      "vb         g    ",
      "vdjjjjeeeeed    ",
      "vb    e    g    ",
      "vbk  le    g    ",
      "vbm   e    g    ",
      "vbk   e    g    ",
      "vb    e    g    ",
      "vbnnn e    g    "
    ],
    [
      "vab             ",
      "vac             ",
      "vdeeeeeeeeedffff",
      "vb         g    ",
      "vb         g    ",
      "vb         g    ",
      "vb         g    ",
      "vb         g    ",
      "vb         g    ",
      "vdjjjjeeeeed    ",
      "vb    e    g    ",
      "vb    e    g    ",
      "vbo   e    g    ",
      "vb   pe    g    ",
      "vb    e    g    ",
      "vbq   e    g    "
    ],
    [
      "vab             ",
      "vac             ",
      "vdeeeeeeeeedffff",
      "vb         g    ",
      "vb         g    ",
      "vb         g    ",
      "vb         g    ",
      "vb         g    ",
      "vb         g    ",
      "vdjjjjeeeeed    ",
      "vb    e    g    ",
      "vb    e    g    ",
      "vb    e    g    ",
      "vb    e    g    ",
      "vb    e    g    ",
      "vbr s e    g    "
    ],
    [
      "vab             ",
      "vac             ",
      "vdeeeeeeeeedtttt",
      "vb         e    ",
      "vb         e    ",
      "vb         e    ",
      "vb         e    ",
      "vb         e    ",
      "vb         e    ",
      "vdjjjjeeeeed    ",
      "vb    e    e    ",
      "vb    e    e    ",
      "vb    e    e    ",
      "vb    e    e    ",
      "vb    e    e    ",
      "vb    e    e    "
    ],
    [
      "vabcuuuuuuuuuuuu",
      "vaccuuuuuuuuuuuu",
      "vdeeeeeeeeedwwww",
      "vbxxxxxxxxxexxxx",
      "vbxxxxxxxxxexxxx",
      "vbxxyyyyyxxexxxx",
      "vbxxyyyyyxxexxxx",
      "vbxxxxxxxxxexxxx",
      "vbxxxxxxxxxexxxx",
      "vdAAAAeeeeeexxxx",
      "vbuuuuexxxxexxxx",
      "vbuuuuexxxxexxxx",
      "vbuuuuexyBxexxxx",
      "vbuuuuexyBxexxxx",
      "vbuuuuexxxxexxxx",
      "vbuuuuexxxxexxxx"
    ]
  ]
}