{
  "name": "multi_laboratory_3_base2",
  "refpalette": "deceasedcraft:multi_laboratory_3/multi_laboratory_3_base2_palette",
  "xsize": 16,
  "zsize": 16,
  "slices": [
    [
      "vabccccccccccccc",
      "vab!cccccccccccc",
      "vabccccccccdcccc",
      "vabccccccccccccc",
      "vabccccccccccccc",
      "vabccccccccccccc",
      "vabccccccccccccc",
      "vabccccccccccccc",
      "vabeeffffffccccc",
      "vabccccccccdcccc",
      "vabccccccccccccc",
      "vabccccccccccccc",
      "vabccccccccccccc",
      "vabccccccccccccc",
      "vabccccccccccccc",
      "vabccccccccccccc"
    ],
    [
      "vabg       h  i ",
      "vabjjk     l  im",
      "vab       nd  i ",
      "vabop     nl  i ",
      "vabjj    qrl  is",
      "vabt u    wl  x ",
      "vab   y k  l    ",
      "vab  ABB   l    ",
      "vab CDDDDE l    ",
      "vabF      Fdllll",
      "vabFI JJ KFlI   ",
      "vabFL JJ MFl    ",
      "vabFL JJ NFl    ",
      "vabFL JJO Fl  BP",
      "vabFQ     Fl   R",
      "vabFFFFFFFFl   S"
    ],
    [
      "vab        h    ",
      "vabT       l  U ",
      "vabV       d  W ",
      "vab        l  U ",
      "vabT       X    ",
      "vabV       X    ",
      "vab        X    ",
      "vab   YZ   X    ",
      "vab 0DDDD1 l    ",
      "vabF      FdlXXX",
      "vabF      Fl    ",
      "vabF2     F3    ",
      "vabF2     F3    ",
      "vabF      F3  45",
      "vabF      F3   6",
      "vabFFFFFFFFl    "
    ],
    [
      "vab        h    ",
      "vab        l    ",
      "vab        d    ",
      "vab        l    ",
      "vab        X    ",
      "vab        X    ",
      "vab        X    ",
      "vab        X    ",
      "vab DDDDDD l    ",
      "vabF      FdlXXX",
      "vabF 7    Fl    ",
      "vabF      F8    ",
      "vabF   9  F8    ",
      "vabF      F8    ",
      "vabF      F8    ",
      "vabFFFFFFFFl    "
    ],
    [
      "vab        l    ",
      "vab        l    ",
      "vab        d    ",
      "vab        l    ",
      "vab        l    ",
      "vab        l    ",
      "vab        l    ",
      "vab        l    ",
      "vab DDDDDD l    ",
      "vabF      Fdllll",
      "vabF #    Fl    ",
      "vabF      Fl    ",
      "vabF   #  Fl    ",
      "vabF $    Fl    ",
      "vabF %  % Fl    ",
      "vabFFFFFFFFl    "
    ],
    [
      "vab^^&^^&^^*()((",
      "vab^^+^^&^^*((((",
      "vab^^^^^^^^d((((",
      "vab^^^^^^^^*((((",
      "vab^^&^^&^^*()((",
      "vab^^+^^&^^*()((",
      "vab^^&^^+^^*()((",
      "vab^^&^^&^^*(-((",
      "vab^^^^^^^^*((((",
      "vabF------Fd[[[[",
      "vabF-]{}|-F*^^^^",
      "vabF-{}|;-F*^^^^",
      "vabF-{|]:-F*^^^^",
      "vabF-]{|'-F*^^))",
      "vabF------F*^^)^",
      "vabFFFFFFFF*^^)^"
    ]
  ]
}