{
  "name": "multi_laboratory_3_top",
  "refpalette": "deceasedcraft:multi_laboratory_3/multi_laboratory_3_top_palette",
  "xsize": 16,
  "zsize": 16,
  "slices": [
    [
      "        abbczzde",
      "        abbczzde",
      "        afgcddee",
      "        abbceeee",
      "        abbceeee",
      "        hbbceeee",
      "        abbceeee",
      "        abbceeee",
      "        hbbceeee",
      "        ifgceeee",
      "        jbbceeee",
      "        kbbceeee",
      "        kbbceeee",
      "        kbbceeee",
      "        kbbceeee",
      "        kbbceeee"
    ],
    [
      "        a  lmno ",
      "        a  l mo ",
      "        h  p o  ",
      "        a  l    ",
      "        a  l    ",
      "        a  l    ",
      "        a  l    ",
      "        h  lq   ",
      "        a  lr   ",
      "        a  st   ",
      "        i  l    ",
      "        i  l    ",
      "        h  lq   ",
      "        i  lr   ",
      "        i  lt   ",
      "        i  l    "
    ],
    [
      "        a       ",
      "        a       ",
      "        a       ",
      "        a       ",
      "        a       ",
      "        a       ",
      "        a       ",
      "        a       ",
      "        a       ",
      "        h  s    ",
      "        a       ",
      "        h       ",
      "        a       ",
      "        a   u   ",
      "        a       ",
      "        h       "
    ],
    [
      "        h       ",
      "        a       ",
      "        a       ",
      "        a       ",
      "        a       ",
      "        h       ",
      "        a       ",
      "        a       ",
      "        a       ",
      "        a  s    ",
      "        h       ",
      "        a       ",
      "        a       ",
      "        a       ",
      "        h       ",
      "        a       "
    ],
    [
      "        a       ",
      "        a       ",
      "        a       ",
      "        a       ",
      "        a       ",
      "        a       ",
      "        a       ",
      "        a       ",
      "        a       ",
      "        a  s    ",
      "        a       ",
      "        a       ",
      "        a       ",
      "        a       ",
      "        a       ",
      "        a       "
    ],
    [
      "        a       ",
      "        a       ",
      "        a       ",
      "        a      f",
      "        a     ff",
      "        a    ff ",
      "        a    f  ",
      "        a   ff  ",
      "        a   f   ",
      "        a  cf   ",
      "        a  f    ",
      "        a  f    ",
      "        a  f    ",
      "        a  f    ",
      "        a  f    ",
      "        a  f    "
    ],
    [
      "        w       ",
      "        w       ",
      "        w       ",
      "        a      c",
      "        a     cc",
      "        a    ccx",
      "        a    cxx",
      "        a   ccxx",
      "        a   cxxx",
      "        afgccxxx",
      "        a  cxxxx",
      "        a  cxxxx",
      "        h  cxxxx",
      "        a  cxxxx",
      "        a  cxxxx",
      "        a  cxxxx"
    ],
    [
      "                ",
      "                ",
      "                ",
      "               l",
      "              ls",
      "             ll ",
      "        w    ly ",
      "        w   ll  ",
      "        w   l   ",
      "        a  sl   ",
      "        a  l    ",
      "        a  lA   ",
      "        a  lB   ",
      "        a  lC   ",
      "        a  ly   ",
      "        a  l    "
    ],
    [
      "                ",
      "                ",
      "                ",
      "                ",
      "                ",
      "                ",
      "              D ",
      "                ",
      "                ",
      "                ",
      "                ",
      "                ",
      "        w       ",
      "        w       ",
      "        w   E   ",
      "        a       "
    ]
  ]
}