{
  "name": "scattered_cabin_2_floor1",
  "refpalette": "deceasedcraft:scattered_cabin_2/scattered_cabin_2_floor1_palette",
  "xsize": 16,
  "zsize": 16,
  "slices": [
    [
      "abcbbacabbcbcbbb",
      "bdddddddddddddda",
      "bddddddddddddddc",
      "bddddddddddddddb",
      "ceeeeeeedddddddb",
      "cfegeeeeeeeeeeec",
      "befeeeeeeeeeeeec",
      "aeeeefeeeeeeeeeb",
      "bfefeeeeeeeeeeeb",
      "beeeefeeeeeeeeeb",
      "beeeeeeeeeeeeeea",
      "cddeeeeeeeeeeeea",
      "bdddeeeeeeeeeeec",
      "cdddeeeeeeeeeeeb",
      "adddeeeeeeeeeeeb",
      "bbbbcbaccbbcbabc"
    ],
    [
      "hiiiiiiiiiiiiiih",
      "iiiiiiiiiiiiiiii",
      "iiiiijiiiiiiiiii",
      "iiiiiiiiiijiiiii",
      "iiiiiiiiiiiiiiii",
      "iiikiiiiiiiiiiii",
      "iiiiiiiiiiiiiiii",
      "iiiiiiiliimiliii",
      "iiiiiiinooooniii",
      "iiiiiiipiiiqoiii",
      "iiiiiiiriiisoiii",
      "iitiiiioiiiuoiii",
      "iviiiiiowiiuoiii",
      "ittiiiioxyooniii",
      "iivtiiinoonliiii",
      "hiiiiiiiiiiiiiiz"
    ],
    [
      "iiiiiiiiiiiiiiii",
      "iiiiiiiiiiiiiiii",
      "iiiiiAiiiiiiiiii",
      "iiiiiiiiiiAiiiii",
      "iiiiiiiiiiiiiiii",
      "iiiiiiiiiiiiiiii",
      "iiiiiiiiiiiiiiii",
      "iiiiiiiliimiliii",
      "iiiiiiinooooniii",
      "iiiiiiiBiiiioiii",
      "iiiiiiiCiiiiDiii",
      "iiiiiiioiiiiDiii",
      "iiiiiiiDiiiioiii",
      "iiiiiiiDiiooniii",
      "iiiiiiinoonliiii",
      "iiiiiiiiiiiiiiii"
    ],
    [
      "iiiiiiiiiiiiiiii",
      "iiiiiiiiiiiiiiii",
      "iiiiiiiiiiiiiiii",
      "iiiiiiiiiiiiiiii",
      "iiiiiiiiiiiiiiii",
      "iiiiiiiiiiiiiiii",
      "iiiiiiiiiiiiiiii",
      "iiiiiiiliimiliii",
      "iiiiiiinooooniii",
      "iiiiiiioiiiioiii",
      "iiiiiiioiiEioiii",
      "iiiiiiioiiiioiii",
      "iiiiiiioiiiioiii",
      "iiiiiiioiiooniii",
      "iiiiiiinoonliiii",
      "iiiiiiiiiiiiiiii"
    ],
    [
      "iiiiiiiiiiiiiiii",
      "iiiiiiiiiiiiiiii",
      "iiiiiiiiiiiiiiii",
      "iiiiiiiiiiiiiiii",
      "iiiiiiiiiiiiiiii",
      "iiiiiiiiiiiiiiii",
      "iiiiiiFGGGFFGGii",
      "iiiiiiGGFGGGGGii",
      "iiiiiiGGGGGGGFii",
      "iiiiiiFGFGGGFGii",
      "iiiiiiFGGHFGGGii",
      "iiiiiiGFGHHGGGii",
      "iiiiiiGGHGGFGGii",
      "iiiiiiGGGGFGGFii",
      "iiiiiiGFFGGGGGii",
      "iiiiiiGGGGGGFiii"
    ],
    [
      "iiiiiiiiiiiiiiii",
      "iiiiiiiiiiiiiiii",
      "iiiiiiiiiiiiiiii",
      "iiiiiiiiiiiiiiii",
      "iiiiiiiiiiiiiiii",
      "iiiiiiiiiiiiiiii",
      "iiiiiiiiiiiiiiii",
      "iiiiiiiiiiiiiiii",
      "iiiiiiiiiiiiiiii",
      "iiiiiiiiiiiiiiii",
      "iiiiiiiiiiiiiiii",
      "iiiiiiiiiiiiiiii",
      "iiiiiiiiiiiiiiii",
      "iiiiiiiiiiiiiiii",
      "iiiiiiiiiiiiiiii",
      "iiiiiiiiiiiiiiii"
    ]
  ]
}