{
  "name": "multi_policeapartment_2_top",
  "refpalette": "deceasedcraft:multi_policeapartment_2/multi_policeapartment_2_top_palette",
  "xsize": 16,
  "zsize": 16,
  "slices": [
    [
      "                ",
      "                ",
      "aaaaaaaaaaaaaaaa",
      "bcccccaddddbcccc",
      "acccccaddddacccc",
      "accceccddddacccc",
      "acccccaaaaaacccc",
      "accfcgcccccacccc",
      "acghiccccccacccc",
      "accgfjcccccacccc",
      "!aaaaaaakaalaaaa",
      "kkkkkkkkkkkkkkkk",
      "kkkkkkkkkkkkkkkk",
      "kkaaaaaaaaaaaaaa",
      "kkm             ",
      "kkm             "
    ],
    [
      "                ",
      "                ",
      "aaaaaaaaaaaaaaaa",
      "nop qra stunw xy",
      "aABCDEaF   aA   ",
      "aIJ  KL M  aIN  ",
      "aOP  QaaaaaaORS ",
      "aT    UVWXYaTS  ",
      "aAZ0     1 a23 S",
      "aI4  5    6a2789",
      "#aaaaaaa$aa#aaaa",
      "    %      q^ % ",
      "  &&&&K&&&&&^*&&",
      " ()++++++)+++)++",
      " (-             ",
      " (-             "
    ],
    [
      "                ",
      "                ",
      "aaaaaaaaaaaaaaaa",
      "n[]  {a   un}   ",
      "a|    a    a|   ",
      "a|    ; M: a|   ",
      "a     aaaaaa'   ",
      "a<    U!  >a,   ",
      "a.         a?   ",
      "a| /       a `\u0370\u0370",
      "#aa\u0371 \u0371aa\u0372aa#aa\u0371\u0371",
      "            \u0373   ",
      "            E   ",
      "  \u0374      \u0374  \u0375\u0374  ",
      "                ",
      "                "
    ],
    [
      "                ",
      "                ",
      "aa\u0371\u0371\u0371\u0376\u0374\u0371\u0371\u0371aaa\u0371\u0371\u0371",
      "b\u0377]  Ra\u037a\u037a\u037au\u037b    ",
      "a|    a\u037c  \u037da|   ",
      "a\u037e    u  \u037f\u0384a|   ",
      "a\u0385    aaaaaa\u0385   ",
      "a\u0386    U\u0387\u0388\u0387\u0388a\u0386   ",
      "a|         a\u0389   ",
      "a\u038a \u038c       a\u038e   ",
      "#aa\u0376\u0374 aa\u038faa#aa\u0376\u0376",
      "                ",
      "                ",
      "  \u0374      \u0374   \u0374  ",
      "                ",
      "                "
    ],
    [
      "                ",
      "                ",
      "aaaaaaaaaaaaaaaa",
      "b\u0390\u0391  4a   u\u037b\u0390   ",
      "au    a    au   ",
      "au    a    au   ",
      "au    aaaaaau   ",
      "au    u    au   ",
      "au         au   ",
      "au         au   ",
      "#aaaaaaaaaa#aaaa",
      "                ",
      "                ",
      "  \u0374      \u0374   \u0374  ",
      "                ",
      "                "
    ],
    [
      "                ",
      "                ",
      "\u0374\u0376\u0376\u0376\u0376\u0376\u0376\u0376\u0376\u0376\u0376\u0376\u0376\u0376\u0376\u0376",
      "b\u0392\u0392\u0392\u0392\u0392\u0392\u0392\u0392\u0392\u0392S\u0392\u0392\u0392\u0392",
      "\u0392\u0392\u0392\u0392\u0392\u0392\u0392\u0392\u0392\u0392\u0392\u0392\u0392\u0392\u0392\u0392",
      "\u0392\u0392\u0392\u0392\u0392\u0392\u0392\u0392\u0392\u0392\u0392\u0392\u0392\u0392\u0392\u0392",
      "\u0392\u0392\u0392\u0392\u0392\u0392\u0392\u0392\u0392\u0392\u0392\u0392\u0392\u0392\u0392\u0392",
      "\u0392\u0392\u0392\u0392\u0392\u0392\u0392\u0392\u0392\u0392\u0392\u0392\u0392\u0392\u0392\u0392",
      "\u0392\u0392\u0392\u0392\u0392\u0392\u0392\u0392\u0392\u0392\u0392\u0392\u0392\u0392\u0392\u0392",
      "\u0392\u0392\u0392\u0392\u0392\u0392\u0392\u0392\u0392\u0392\u0392\u0392\u0392\u0392\u0392\u0392",
      "\u0393\u0393\u0393\u0393\u0393\u0393\u0393\u0393\u0393\u0393\u0393\u0393\u0393\u0393\u0393\u0393",
      "                ",
      "                ",
      "\u0376\u0376\u0376\u0376\u0376\u0376\u0376\u0376\u0376\u0376\u0376\u0376\u0376\u0376\u0376\u0376",
      "                ",
      "                "
    ],
    [
      "                ",
      "                ",
      "aaaaaaaaaaaaaaaa",
      "bdddddddddd\u0394dddd",
      "ddddddddd\u0395dddddd",
      "ddddddddddddd\u0396\u0396d",
      "ddddddddddddd\u0396\u0396d",
      "ddddddddddddd\u0396\u0396d",
      "ddddddddd\u0395dddddd",
      "dddddddddddddddd",
      "aaaaaaaaaaaaaaaa",
      "kkkkkkkkkkkkkkkk",
      "kkkkkkkkkkkkkkkk",
      "aaaaaaaaaaaaaaaa",
      "                ",
      "                "
    ],
    [
      "                ",
      "                ",
      "\u0397\u0397\u0397\u0397\u0397\u0397\u0397\u0397\u0397\u0397\u0397\u0397\u0397\u0397\u0397\u0397",
      "\u0398          \u0398    ",
      "   \u0399\u0399\u0399\u0399  \u039a      ",
      "   \u0399\u0399\u0399\u0399  \u039a  \u039b\u0396\u0396\u039c",
      "   \u0399\u0399\u0399\u0399  \u039a\u039a\u039a\u039a\u0396\u0396\u039a",
      "   \u0399\u0399\u0399\u0399  \u039a  \u039b\u0396\u0396\u039c",
      "   \u0399\u0399\u0399\u0399  \u039a      ",
      "                ",
      "\u0397\u0397\u0397\u0397\u0397\u0397\u0397\u0397\u0397\u0397\u0397\u0397\u0397\u0397\u0397\u0397",
      "                ",
      "                ",
      "                ",
      "                ",
      "                "
    ],
    [
      "                ",
      "                ",
      "                ",
      "                ",
      "                ",
      "            \u039b\u0396\u0396\u039c",
      "            \u039b\u0396\u0396\u039c",
      "            \u039b\u0396\u0396\u039c",
      "                ",
      "                ",
      "                ",
      "                ",
      "                ",
      "                ",
      "                ",
      "                "
    ],
    [
      "                ",
      "                ",
      "                ",
      "                ",
      "                ",
      "             \u0397  ",
      "                ",
      "                ",
      "                ",
      "                ",
      "                ",
      "                ",
      "                ",
      "                ",
      "                ",
      "                "
    ],
    [
      "                ",
      "                ",
      "                ",
      "                ",
      "                ",
      "             \u039d  ",
      "                ",
      "                ",
      "                ",
      "                ",
      "                ",
      "                ",
      "                ",
      "                ",
      "                ",
      "                "
    ],
    [
      "                ",
      "                ",
      "                ",
      "                ",
      "                ",
      "             \u039d\u039d ",
      "             \u039d  ",
      "                ",
      "                ",
      "                ",
      "                ",
      "                ",
      "                ",
      "                ",
      "                ",
      "                "
    ]
  ]
}