{
  "name": "multi_policeapartment_2_floor4",
  "refpalette": "deceasedcraft:multi_policeapartment_2/multi_policeapartment_2_floor4_palette",
  "xsize": 16,
  "zsize": 16,
  "slices": [
    [
      "                ",
      "                ",
      "aaaaaaaaaaaaaaaa",
      "bcccccaddddbcccc",
      "acccccaddddacccc",
      "accccccddddacccc",
      "acccccaaaaaacccc",
      "accccccccccacccc",
      "accccccccccacccc",
      "accccccccccacccc",
      "eaaaaaaafaa!aaaa",
      "ffffffffffffffff",
      "ffffffffffffffff",
      "ffaaaaaaaaaaaaaa",
      "ffg             ",
      "ffg             "
    ],
    [
      "                ",
      "                ",
      "aaaaaaaaaaaaaaaa",
      "hijkklamnophijlk",
      "aq rr as   aq  r",
      "at uu w x  at  u",
      "ay    aaaaaay   ",
      "aAB   CDEFIaAB  ",
      "aq         aq   ",
      "at JJJ    KatLJJ",
      "MaaaaaaaNaaMaaaa",
      "                ",
      "  OOOOOOOOOOOOOO",
      " PQRRRRRRQRRRQRR",
      " PS             ",
      " PS             "
    ],
    [
      "                ",
      "                ",
      "aaaaaaaaaaaaaaaa",
      "hTU  VaW  phTUX ",
      "aY    a   ZaY   ",
      "aY    0 x1ZaY   ",
      "a2    aaaaaa3   ",
      "a4    C 5 6a4   ",
      "aY         aY   ",
      "aY 789     aY 78",
      "Maa###aa$aaMaa##",
      "                ",
      "                ",
      "  %      %   %  ",
      "                ",
      "                "
    ],
    [
      "                ",
      "                ",
      "aa###^%###aaa###",
      "b&U   a***pb&U  ",
      "aY    a(  )aY   ",
      "aY    p  +-aY   ",
      "a[    aaaaaa[   ",
      "a]    C{}{}a]   ",
      "aY         aY   ",
      "aY |;:     aY |;",
      "Maa^^^aa'aaMaa^^",
      "                ",
      "                ",
      "  %      %   %  ",
      "                ",
      "                "
    ],
    [
      "                ",
      "                ",
      "aaaaaaaaaaaaaaaa",
      "b<>   a   pb<>  ",
      "ap    a   ,ap   ",
      "ap    a   .ap   ",
      "ap    aaaaaap   ",
      "ap    p  ? ap   ",
      "ap         ap   ",
      "ap         ap   ",
      "MaaaaaaaaaaMaaaa",
      "                ",
      "                ",
      "  %      %   %  ",
      "                ",
      "                "
    ],
    [
      "                ",
      "                ",
      "%^^^^^^^^^^%^^^^",
      "b//////////b////",
      "////////////////",
      "////////////////",
      "////////////////",
      "////////////////",
      "////////////////",
      "////////////////",
      "````````````````",
      "                ",
      "                ",
      "^^^^^^^^^^^^^^^^",
      "                ",
      "                "
    ]
  ]
}