{
  "name": "multi_policeapartment_2_floor3",
  "refpalette": "deceasedcraft:multi_policeapartment_2/multi_policeapartment_2_floor3_palette",
  "xsize": 16,
  "zsize": 16,
  "slices": [
    [
      "                ",
      "                ",
      "aaaaaaaaaaaaaaaa",
      "bcccccaddddbcccc",
      "acccccaddddacccc",
      "accccccddddacccc",
      "acccccaaaaaacccc",
      "accccccccccacccc",
      "accccccccccacccc",
      "accccccccccacccc",
      "eaaaaaaafaagaaaa",
      "ffffffffffffffff",
      "ffffffffffffffff",
      "ffaaaaaaaaaaaaaa",
      "ffh             ",
      "ffh             "
    ],
    [
      "                ",
      "                ",
      "aaaaaaaaaaaaaaaa",
      "ijkllma nop!qkml",
      "ar sstau   ar  s",
      "aw xx y A  aw  x",
      "aB    aaaaaaB   ",
      "aCD   EFIJKaCL  ",
      "ar         ar   ",
      "aw MMM    Naw MM",
      "OaaaaaaaPaaOaaaa",
      "                ",
      "  QQQQQQQQQQQQQQ",
      " RSTTTTTTSTTTSTT",
      " RU             ",
      " RU             "
    ],
    [
      "                ",
      "                ",
      "aaaaaaaaaaaaaaaa",
      "iVW  !a   ptXWY ",
      "aZ    a   0aZ   ",
      "aZ    1 A2 aZ   ",
      "a3    aaaaaa4   ",
      "a5    E 6 7a5   ",
      "aZ         aZ   ",
      "aZ 89#     aZ 89",
      "Oaa$$$aa%aaOaa$$",
      "                ",
      "                ",
      "  ^      ^   ^  ",
      "                ",
      "                "
    ],
    [
      "                ",
      "                ",
      "aa$$$&^$$$aaa$$$",
      "b*W   a(((pb*W  ",
      "aZ    a)  +aZ   ",
      "aZ    p  -[aZ   ",
      "a]    aaaaaa]   ",
      "a{    E}|}|a{   ",
      "aZ         aZ   ",
      "aZ ;:'     aZ ;:",
      "Oaa&&&aa<aaOaa&&",
      "                ",
      "                ",
      "  ^      ^   ^  ",
      "                ",
      "                "
    ],
    [
      "                ",
      "                ",
      "aaaaaaaaaaaaaaaa",
      "b>,   a   pb>,  ",
      "ap    a   .ap   ",
      "ap    a   ?ap   ",
      "ap    aaaaaap   ",
      "ap    p/`  ap   ",
      "ap         ap   ",
      "ap         ap   ",
      "OaaaaaaaaaaOaaaa",
      "                ",
      "                ",
      "  ^      ^   ^  ",
      "                ",
      "                "
    ],
    [
      "                ",
      "                ",
      "^&&&&&&&&&&^&&&&",
      "b\u0370\u0370\u0370\u0370\u0370\u0370\u0370\u0370\u0370\u0370b\u0370\u0370\u0370\u0370",
      "\u0370\u0370\u0370\u0370\u0370\u0370\u0370\u0370\u0370\u0370\u0370\u0370\u0370\u0370\u0370\u0370",
      "\u0370\u0370\u0370\u0370\u0370\u0370\u0370\u0370\u0370\u0370\u0370\u0370\u0370\u0370\u0370\u0370",
      "\u0370\u0370\u0370\u0370\u0370\u0370\u0370\u0370\u0370\u0370\u0370\u0370\u0370\u0370\u0370\u0370",
      "\u0370\u0370\u0370\u0370\u0370\u0370\u0370\u0370\u0370\u0370\u0370\u0370\u0370\u0370\u0370\u0370",
      "\u0370\u0370\u0370\u0370\u0370\u0370\u0370\u0370\u0370\u0370\u0370\u0370\u0370\u0370\u0370\u0370",
      "\u0370\u0370\u0370\u0370\u0370\u0370\u0370\u0370\u0370\u0370\u0370\u0370\u0370\u0370\u0370\u0370",
      "\u0371\u0371\u0371\u0371\u0371\u0371\u0371\u0371\u0371\u0371\u0371\u0371\u0371\u0371\u0371\u0371",
      "                ",
      "                ",
      "&&&&&&&&&&&&&&&&",
      "                ",
      "                "
    ]
  ]
}