{
  "name": "multi_policeapartment_2_floor1",
  "refpalette": "deceasedcraft:multi_policeapartment_2/multi_policeapartment_2_floor1_palette",
  "xsize": 16,
  "zsize": 16,
  "slices": [
    [
      "                ",
      "                ",
      "aaaaaaaaaaaaaaaa",
      "bc        dbc   ",
      "e          e    ",
      "                ",
      "                ",
      "                ",
      "                ",
      "                ",
      "                ",
      "                ",
      " ffffffffff ffff",
      "aaaaaaaaaaaaaaaa",
      "                ",
      "                "
    ],
    [
      "                ",
      "                ",
      "aaaaaaaaaaaaaaaa",
      "bggggggggggbgggg",
      "gggggggggggggggg",
      "gg  hh    ggg  h",
      "gg        ggg   ",
      "ggh       ggg   ",
      "ggh       ggg   ",
      "ggh       gggh  ",
      "gghh  hh  ggghh ",
      "gggggggggggggggg",
      "iggggggggggigggg",
      "aaaaaaaaaaaaaaaa",
      "jjjjjjjjjjjjjjjj",
      "kkkkkkkkkkkkkkkk"
    ],
    [
      "                ",
      "                ",
      "aaaaaaaaaaaaaaaa",
      "bllllllllllbllll",
      "mmmmnnnnmmmmmmmn",
      "mnnnnnnnnnnmnnnn",
      "mnnoooooonnmnnoo",
      "mnnoooooonnmnnoo",
      "mnnoooooonnmnnoo",
      "mnnoooooonnmnnoo",
      "mnnnnnnnnnnmnnnn",
      "mnnnnnnnnnnmnnnn",
      "pnnnnnnnnnnpnnnn",
      "aaaaaaaaaaaaaaaa",
      "                ",
      "                "
    ],
    [
      "                ",
      "                ",
      "aaaaaaaaaaaaaaaa",
      "bllllllllllbllll",
      "  qm    m   q m ",
      "                ",
      "                ",
      "                ",
      "                ",
      "                ",
      "                ",
      "q               ",
      "mmmmmmmmmmmmmmmm",
      "aaaaaaaaaaaaaaaa",
      "                ",
      "                "
    ],
    [
      "                ",
      "                ",
      "rrrrrrrrrrrrrrrr",
      "bllsllllsllbllsl",
      "t  m    mq t  m ",
      "                ",
      "                ",
      "           q    ",
      "                ",
      "                ",
      "                ",
      "u          u   q",
      "wllllllllllwllll",
      "rrrrrrrrrrrrrrrr",
      "                ",
      "                "
    ],
    [
      "                ",
      "                ",
      "xyyyyyyyyyyxyyyy",
      "bwwwwwwwwwwbwwww",
      "wAAAAAAAAAAwAAAA",
      "wAAAAAAAAAAwAAAA",
      "wAAAAAAAAAAwAAAA",
      "wAAAAAAAAAAwAAAA",
      "wAAAAAAAAAAwAAAA",
      "wAAAAAAAAAAwAAAA",
      "wAAAAAAAAAAwAAAA",
      "wAAAAAAAAAAwAAAA",
      "wwwwwwwwwwwwwwww",
      "yyyyyyyyyyyyyyyy",
      "                ",
      "                "
    ]
  ]
}