{
  "name": "multi_policeapartment_2_floor2",
  "refpalette": "deceasedcraft:multi_policeapartment_2/multi_policeapartment_2_floor2_palette",
  "xsize": 16,
  "zsize": 16,
  "slices": [
    [
      "                ",
      "                ",
      "aaaaaaaaaaaaaaaa",
      "bcccccaddddbcccc",
      "acccccaddddacccc",
      "accccccddddacccc",
      "acccccaaaaaacccc",
      "acccccccccca!ccc",
      "accccccccccacccc",
      "accccccccccacccc",
      "eaaaaaaafaaeaaaa",
      "ffffffffffffffff",
      "ffffffffffffffff",
      "ffaaaaaaaaaaaaaa",
      "ffg             ",
      "ffg             "
    ],
    [
      "                ",
      "                ",
      "aaaaaaaaaaaaaaaa",
      "hijkklamnophijlk",
      "aq rr as   aq  r",
      "at uu w x  aty u",
      "aA    aaaaaaA   ",
      "aBC   DEFIJaBK  ",
      "aq         aq   ",
      "at LLL    Mat LL",
      "NaaaaaaaOaaNaaaa",
      "                ",
      "  PPPPPPPPPPPPPP",
      " QRSSSSSSRSSSRSS",
      " QT             ",
      " QT             "
    ],
    [
      "                ",
      "                ",
      "aaaaaaaaaaaaaaaa",
      "hUV  WaX  phUVY ",
      "aZ    a   0aZ   ",
      "aZ    1 x20aZ   ",
      "a3    aaaaaa4   ",
      "a4    567 8a    ",
      "aZ         aZ   ",
      "aZ 9#$     aZ %^",
      "Naa&&&aa*aaNaa&&",
      "                ",
      "                ",
      "  (      (   (  ",
      "                ",
      "                "
    ],
    [
      "                ",
      "                ",
      "aa&&&)(&&&aaa&&&",
      "bKV   a+++pb-V  ",
      "aZ    a[  ]aZ   ",
      "aZ    p  {}aZ   ",
      "a|    aaaaaa|   ",
      "a;    D:':'a;   ",
      "aZ         aZ   ",
      "aZ <>,     aZ .?",
      "Naa)))aa/aaNaa))",
      "                ",
      "                ",
      "  (      (   (  ",
      "                ",
      "                "
    ],
    [
      "                ",
      "                ",
      "aaaaaaaaaaaaaaaa",
      "b!`   a   pb\u0370`  ",
      "apK   a   \u0371ap   ",
      "ap    a   \u0372ap   ",
      "ap    aaaaaap   ",
      "ap    p \u0373  ap   ",
      "ap         ap   ",
      "ap         ap   ",
      "NaaaaaaaaaaNaaaa",
      "                ",
      "                ",
      "  (      (   (  ",
      "                ",
      "                "
    ],
    [
      "                ",
      "                ",
      "))))))))))))))))",
      "b\u0374\u0374\u0374\u0374\u0374\u0374\u0374\u0374\u0374\u0374b\u0374\u0374\u0374\u0374",
      "\u0374\u0374\u0374\u0374\u0374\u0374\u0374\u0374\u0374\u0374\u0374\u0374\u0374\u0374\u0374\u0374",
      "\u0374\u0374\u0374\u0374\u0374\u0374\u0374\u0374\u0374\u0374\u0374\u0374\u0374\u0374\u0374\u0374",
      "\u0374\u0374\u0374\u0374\u0374\u0374\u0374\u0374\u0374\u0374\u0374\u0374\u0374\u0374\u0374\u0374",
      "\u0374\u0374\u0374\u0374\u0374\u0374\u0374\u0374\u0374\u0374\u0374\u0374\u0374\u0374\u0374\u0374",
      "\u0374\u0374\u0374\u0374\u0374\u0374\u0374\u0374\u0374\u0374\u0374\u0374\u0374\u0374\u0374\u0374",
      "\u0374\u0374\u0374\u0374\u0374\u0374\u0374\u0374\u0374\u0374\u0374\u0374\u0374\u0374\u0374\u0374",
      "\u0375\u0375\u0375\u0375\u0375\u0375\u0375\u0375\u0375\u0375\u0375\u0375\u0375\u0375\u0375\u0375",
      "                ",
      "                ",
      "))))))))))))))))",
      "                ",
      "                "
    ]
  ]
}