{
  "name": "multi_policeapartment_2_ground",
  "refpalette": "deceasedcraft:multi_policeapartment_2/multi_policeapartment_2_ground_palette",
  "xsize": 16,
  "zsize": 16,
  "slices": [
    [
      "aaaaaaaaaaaaaaaa",
      "aaaaaaaaaaaaaaaa",
      "bbbbbbbbbbbbbbbb",
      "cccccccccccccccc",
      "cccccccccccccccc",
      "cccccccccccccccc",
      "cccccccccccccccc",
      "cccccccccccccccc",
      "cccccccccccccccc",
      "cccccccccccccccc",
      "cccccccccccccccc",
      "cccccccccccccccc",
      "cccccccccccccccc",
      "bddddddddddbdddd",
      "effffffffffeffff",
      "HHHHHHHHHHHHHHHH"
    ],
    [
      "                ",
      "                ",
      "bbbbbbbbbbbbbbbb",
      " g        h g   ",
      "       iji      ",
      "  k l mnonp  k l",
      "  q r st!tu  q r",
      "      wtxty     ",
      "       ABA      ",
      "  C D mnEnp  C D",
      "  F I  AJA   F I",
      "       KLK      ",
      "            MMMM",
      "bN        ObN   ",
      "P          P    ",
      "                "
    ],
    [
      "                ",
      "                ",
      "bbbbbbbbbbbbbbbb",
      "Qg     R ShQg   ",
      "       TTT      ",
      "       UAU      ",
      "      stVtu     ",
      "       @@@      ",
      "       WWW      ",
      "       XWX      ",
      "       XXX      ",
      "                ",
      " MMMMMMMMMMYZZZZ",
      "bN        ObN   ",
      "           0    ",
      "                "
    ],
    [
      "                ",
      "                ",
      "bbbbbbbbbbbbbbbb",
      "1g        h1g   ",
      "                ",
      "        X       ",
      "                ",
      "       2X3      ",
      "                ",
      "                ",
      "                ",
      "                ",
      " ZZZZZZZZZZ ZZZZ",
      "bN        ObN   ",
      "4               ",
      "                "
    ],
    [
      "                ",
      "                ",
      "bbbbbbbbbbbbbbbb",
      "1g        h1g   ",
      "                ",
      "                ",
      "                ",
      "                ",
      "                ",
      "                ",
      "                ",
      "                ",
      " ZZZZZZZZZZ ZZZZ",
      "bN        ObN   ",
      "5          5    ",
      "                "
    ],
    [
      "                ",
      "                ",
      "bbbbbbbbbbbbbbbb",
      "1g        h1g   ",
      "                ",
      "                ",
      "                ",
      "                ",
      "                ",
      "                ",
      "                ",
      "                ",
      " ZZZZZZZZZZ ZZZZ",
      "b6777777778b6777",
      "                ",
      "                "
    ]
  ]
}