{
  "name": "building_restaurantsushi_ground_90",
  "refpalette": "deceasedcraft:building_restaurantsushi/building_restaurantsushi_ground_palette_90",
  "xsize": 16,
  "zsize": 16,
  "slices": [
    [
      "aaaaaaaaaaaaaaaa",
      "acccccccccccccca",
      "acddddddddddddca",
      "acdhheieieihhdca",
      "acdhheiggeihhdca",
      "acdffggffggffdca",
      "acdeiffeiffeidca",
      "acdeieieieieidca",
      "acdggeiggeiggdca",
      "acdffggffggffdca",
      "acdeiffeiffeidca",
      "abddddddddddddba",
      "aabcccbbbbcccbaa",
      "aaaaaaabbaaaaaaa",
      "aaaaaaabbaaaaaaa",
      "aaaaaaabbaaaaaaa"
    ],
    [
      "                ",
      " kkkkxxxxxxkkkk ",
      " knnkkkkkkkk Mk ",
      " knqr BDD!Kk Lk ",
      " kkkk      kCkk ",
      " lm  wAAAAJ  ml ",
      " lm  ummmmI  ml ",
      " lm  tyyyyF  ml ",
      " lm  ssssss  ml ",
      " lm          ml ",
      " kmp pkCEkp pmk ",
      " jmmmmm  mmmmmj ",
      "  mooom  mooom  ",
      "                ",
      "                ",
      "                "
    ],
    [
      "                ",
      " kkkkRRRRRRkkkk ",
      " kQSkkkkkkkk  k ",
      " kP T  0246k  k ",
      " kkkk      kYkk ",
      "  m   XZ 3   m  ",
      "  O  VVVVV5  O  ",
      "  O  UWWWWW  O  ",
      "  O          O  ",
      "  m          m  ",
      " km   kY1k   mk ",
      " NmOOOm  mOOOmN ",
      "  mRRRm  mRRRm  ",
      "                ",
      "                ",
      "                "
    ],
    [
      "                ",
      " kOOkRRRRRRkOOk ",
      " k8 kkkkkkkk  k ",
      " k7 k  ^^ 4k )k ",
      " kkkk      kkkk ",
      " RmQ        (mR ",
      " Rm9 $$$$$$ *mR ",
      " Rm9 ###### *mR ",
      " Rm9        *mR ",
      " RmP        &mR ",
      " km   kkkk   mk ",
      " NmOOOm  mOOOmN ",
      "  mRRRm%%mRRRm  ",
      "                ",
      "                ",
      "                "
    ],
    [
      "                ",
      " k++k++++++k++k ",
      " k  kkkkkkkk  k ",
      " k  k      k  k ",
      " kkkk      kkkk ",
      " +m[        ]m+ ",
      " +m[        ]m+ ",
      " +m[        ]m+ ",
      " +m[        ]m+ ",
      " +m[        ]m+ ",
      " kmkkkkkkkkkkmk ",
      "  mkkkm  mkkkm  ",
      "  m+++m%%m+++m  ",
      "  -   -  -   -  ",
      "                ",
      "                "
    ],
    [
      "                ",
      " kkkk}}}}}}kkkk ",
      " k||kkkkkkkk||k ",
      " k||k}}}}}}k||k ",
      " k}}}}}}}}}}}}k ",
      " km;;:;;;;:;;mk ",
      " km;;:;;;;:;;mk ",
      " km;;:;;;;:;;mk ",
      " km;;:;;;;:;;mk ",
      " km;;:;;;;:;;mk ",
      " km}}}}}}}}}}mk ",
      " {{{{{{{{{{{{{{ ",
      " {{{{{{{{{{{{{{ ",
      " {{{{{{{{{{{{{{ ",
      " {{{{{{{{{{{{{{ ",
      "                "
    ]
  ]
}