{
  "name": "building_restaurantsushi_ground",
  "refpalette": "deceasedcraft:building_restaurantsushi/building_restaurantsushi_ground_palette",
  "xsize": 16,
  "zsize": 16,
  "slices": [
    [
      "aaaaaaaaaaaaaaaa",
      "aaaabcccccccccca",
      "aaabddddddddddca",
      "aaacdefgeefhhdca",
      "aaacdifgiifhhdca",
      "aaacdfgeefgeedca",
      "aaabdfgiifgiidca",
      "bbbbdefgeefgedca",
      "bbbbdifgiifgidca",
      "aaabdfgeefgeedca",
      "aaacdfgiifgiidca",
      "aaacdefgeefhhdca",
      "aaacdifgiifhhdca",
      "aaabddddddddddca",
      "aaaabcccccccccca",
      "aaaaaaaaaaaaaaaa"
    ],
    [
      "                ",
      "    jklllllkkkk ",
      "   mmmmmmmmknnk ",
      "   omp     kqnk ",
      "   om      krkk ",
      "   omp stuw  kx ",
      "   mmk symA Bkx ",
      "     C symA Dkx ",
      "     E symA Dkx ",
      "   mmk symA !kx ",
      "   omp sFIJ Kkx ",
      "   om      kkkk ",
      "   omp     C  k ",
      "   mmmmmmmmkLMk ",
      "    jklllllkkkk ",
      "                "
    ],
    [
      "                ",
      "    Nk     kkkk ",
      "   mmmmOOOmkPQk ",
      "   RO      k Sk ",
      "   RO      kTkk ",
      "   RO   UV   kR ",
      "   mmk  WVX  kR ",
      "     Y  WVZ 0kR ",
      "     1  WV  2kR ",
      "   mmk  WV3 4kR ",
      "   RO   W5  6kR ",
      "   RO      kkkk ",
      "   RO      Y  k ",
      "   mmmmOOOmk  k ",
      "    Nk     kkkk ",
      "                "
    ],
    [
      "                ",
      "    NkRRRRRkkkk ",
      "   mmmmmmmmk78O ",
      "   RO P999Qk  O ",
      "   RO      kkkk ",
      "   RO   #$   kR ",
      "   mmk  #$   kR ",
      "   % k  #$  ^kR ",
      "   % k  #$  ^kR ",
      "   mmk  #$   kR ",
      "   RO   #$  4kR ",
      "   RO      kkkk ",
      "   RO &***(k  O ",
      "   mmmmmmmmk) O ",
      "    NkRRRRRkkkk ",
      "                "
    ],
    [
      "                ",
      "     k+++++kkkk ",
      "  -mmmmmmmmk  + ",
      "   +kk[[[[[k  + ",
      "   +kk     kkkk ",
      "   +kk       k+ ",
      "  -mmk       k+ ",
      "   % k       k+ ",
      "   % k       k+ ",
      "  -mmk       k+ ",
      "   +kk       k+ ",
      "   +kk     kkkk ",
      "   +kk]]]]]k  + ",
      "  -mmmmmmmmk  + ",
      "     k+++++kkkk ",
      "                "
    ],
    [
      "                ",
      " {{{{kkkkkkkkkk ",
      " {{{{mmmmmm}||k ",
      " {{{{};;;;;}||k ",
      " {{{{};;;;;}kkk ",
      " {{{{}:::::}}k} ",
      " {{{{};;;;;}}k} ",
      " {{{{};;;;;}}k} ",
      " {{{{};;;;;}}k} ",
      " {{{{};;;;;}}k} ",
      " {{{{}:::::}}k} ",
      " {{{{};;;;;}kkk ",
      " {{{{};;;;;}||k ",
      " {{{{mmmmmm}||k ",
      " {{{{kkkkkkkkkk ",
      "                "
    ]
  ]
}