{
  "name": "building_restaurantsushi_ground_270",
  "refpalette": "deceasedcraft:building_restaurantsushi/building_restaurantsushi_ground_palette_270",
  "xsize": 16,
  "zsize": 16,
  "slices": [
    [
      "aaaaaaabbaaaaaaa",
      "aaaaaaabbaaaaaaa",
      "aaaaaaabbaaaaaaa",
      "aabcccbbbbcccbaa",
      "abddddddddddddba",
      "acdieffieffiedca",
      "acdffggffggffdca",
      "acdggieggieggdca",
      "acdieieieieiedca",
      "acdieffieffiedca",
      "acdffggffggffdca",
      "acdhhieggiehhdca",
      "acdhhieieiehhdca",
      "acddddddddddddca",
      "acccccccccccccca",
      "aaaaaaaaaaaaaaaa"
    ],
    [
      "                ",
      "                ",
      "                ",
      "  mooom  mooom  ",
      " jmmmmm  mmmmmj ",
      " kmp pkECkp pmk ",
      " lm          ml ",
      " lm  ssssss  ml ",
      " lm  Fyyyyt  ml ",
      " lm  Immmmu  ml ",
      " lm  JAAAAw  ml ",
      " kkCk      kkkk ",
      " kL kK!DDB rqnk ",
      " kM kkkkkkkknnk ",
      " kkkkxxxxxxkkkk ",
      "                "
    ],
    [
      "                ",
      "                ",
      "                ",
      "  mRRRm  mRRRm  ",
      " NmOOOm  mOOOmN ",
      " km   k1Yk   mk ",
      "  m          m  ",
      "  O          O  ",
      "  O  WWWWWU  O  ",
      "  O  5VVVVV  O  ",
      "  m   3 ZX   m  ",
      " kkYk      kkkk ",
      " k  k6420  T Pk ",
      " k  kkkkkkkkSQk ",
      " kkkkRRRRRRkkkk ",
      "                "
    ],
    [
      "                ",
      "                ",
      "                ",
      "  mRRRm%%mRRRm  ",
      " NmOOOm  mOOOmN ",
      " km   kkkk   mk ",
      " Rm&        PmR ",
      " Rm*        9mR ",
      " Rm* ###### 9mR ",
      " Rm* $$$$$$ 9mR ",
      " Rm(        QmR ",
      " kkkk      kkkk ",
      " k) k4 ^^  k 7k ",
      " k  kkkkkkkk 8k ",
      " kOOkRRRRRRkOOk ",
      "                "
    ],
    [
      "                ",
      "                ",
      "  -   -  -   -  ",
      "  m+++m%%m+++m  ",
      "  mkkkm  mkkkm  ",
      " kmkkkkkkkkkkmk ",
      " +m]        [m+ ",
      " +m]        [m+ ",
      " +m]        [m+ ",
      " +m]        [m+ ",
      " +m]        [m+ ",
      " kkkk      kkkk ",
      " k  k      k  k ",
      " k  kkkkkkkk  k ",
      " k++k++++++k++k ",
      "                "
    ],
    [
      "                ",
      " {{{{{{{{{{{{{{ ",
      " {{{{{{{{{{{{{{ ",
      " {{{{{{{{{{{{{{ ",
      " {{{{{{{{{{{{{{ ",
      " km}}}}}}}}}}mk ",
      " km;;:;;;;:;;mk ",
      " km;;:;;;;:;;mk ",
      " km;;:;;;;:;;mk ",
      " km;;:;;;;:;;mk ",
      " km;;:;;;;:;;mk ",
      " k}}}}}}}}}}}}k ",
      " k||k}}}}}}k||k ",
      " k||kkkkkkkk||k ",
      " kkkk}}}}}}kkkk ",
      "                "
    ]
  ]
}