{
  "name": "building_restaurantsushi_ground_180",
  "refpalette": "deceasedcraft:building_restaurantsushi/building_restaurantsushi_ground_palette_180",
  "xsize": 16,
  "zsize": 16,
  "slices": [
    [
      "aaaaaaaaaaaaaaaa",
      "accccccccccbaaaa",
      "acddddddddddbaaa",
      "acdhhfiigfidcaaa",
      "acdhhfeegfedcaaa",
      "acdiigfiigfdcaaa",
      "acdeegfeegfdbaaa",
      "acdigfiigfidbbbb",
      "acdegfeegfedbbbb",
      "acdiigfiigfdbaaa",
      "acdeegfeegfdcaaa",
      "acdhhfiigfidcaaa",
      "acdhhfeegfedcaaa",
      "acddddddddddbaaa",
      "accccccccccbaaaa",
      "aaaaaaaaaaaaaaaa"
    ],
    [
      "                ",
      " kkkklllllkj    ",
      " kMLkmmmmmmmm   ",
      " k  C     pmo   ",
      " kkkk      mo   ",
      " xkK JIFs pmo   ",
      " xk! Amys kmm   ",
      " xkD Amys E     ",
      " xkD Amys C     ",
      " xkB Amys kmm   ",
      " xk  wuts pmo   ",
      " kkrk      mo   ",
      " knqk     pmo   ",
      " knnkmmmmmmmm   ",
      " kkkklllllkj    ",
      "                "
    ],
    [
      "                ",
      " kkkk     kN    ",
      " k  kmOOOmmmm   ",
      " k  Y      OR   ",
      " kkkk      OR   ",
      " Rk6  5W   OR   ",
      " Rk4 3VW  kmm   ",
      " Rk2  VW  1     ",
      " Rk0 ZVW  Y     ",
      " Rk  XVW  kmm   ",
      " Rk   VU   OR   ",
      " kkTk      OR   ",
      " kS k      OR   ",
      " kQPkmOOOmmmm   ",
      " kkkk     kN    ",
      "                "
    ],
    [
      "                ",
      " kkkkRRRRRkN    ",
      " O )kmmmmmmmm   ",
      " O  k(***& OR   ",
      " kkkk      OR   ",
      " Rk4  $#   OR   ",
      " Rk   $#  kmm   ",
      " Rk^  $#  k %   ",
      " Rk^  $#  k %   ",
      " Rk   $#  kmm   ",
      " Rk   $#   OR   ",
      " kkkk      OR   ",
      " O  kQ999P OR   ",
      " O87kmmmmmmmm   ",
      " kkkkRRRRRkN    ",
      "                "
    ],
    [
      "                ",
      " kkkk+++++k     ",
      " +  kmmmmmmmm-  ",
      " +  k]]]]]kk+   ",
      " kkkk     kk+   ",
      " +k       kk+   ",
      " +k       kmm-  ",
      " +k       k %   ",
      " +k       k %   ",
      " +k       kmm-  ",
      " +k       kk+   ",
      " kkkk     kk+   ",
      " +  k[[[[[kk+   ",
      " +  kmmmmmmmm-  ",
      " kkkk+++++k     ",
      "                "
    ],
    [
      "                ",
      " kkkkkkkkkk{{{{ ",
      " k||}mmmmmm{{{{ ",
      " k||};;;;;}{{{{ ",
      " kkk};;;;;}{{{{ ",
      " }k}}:::::}{{{{ ",
      " }k}};;;;;}{{{{ ",
      " }k}};;;;;}{{{{ ",
      " }k}};;;;;}{{{{ ",
      " }k}};;;;;}{{{{ ",
      " }k}}:::::}{{{{ ",
      " kkk};;;;;}{{{{ ",
      " k||};;;;;}{{{{ ",
      " k||}mmmmmm{{{{ ",
      " kkkkkkkkkk{{{{ ",
      "                "
    ]
  ]
}