{
  "name": "multi_militaryradiocamp_1_ground",
  "refpalette": "deceasedcraft:multi_militaryradiocamp_1/multi_militaryradiocamp_1_ground_palette",
  "xsize": 16,
  "zsize": 16,
  "slices": [
    [
      "aazaazzzzzzzzzzz",
      "abbbzzzczzcczzzz",
      "zczbcccccdzccdzz",
      "dzzbcccccc=ccz=z",
      "czzbccccccczzzzz",
      "=czbccccccc=zczz",
      "cczbccccccccdzzz",
      "c=zbcccccccczz=z",
      "d=zbccccccccczzz",
      "czzbcccccccccczz",
      "ccccccccccccdzzz",
      "cccccccccccc=zzz",
      "ccccc=ccccc=zzzz",
      "z=cccz=cc=zdzz=z",
      "zabbzzzczzzcczzz",
      "zzaaazzzzzzzzzzz"
    ],
    [
      "         ee     ",
      "ffghii jhhiij i ",
      "  f    iik    l ",
      "m f nnnop    qr ",
      " sf tnto      u ",
      " wg nnn       x ",
      "mkf nnny      x ",
      "  f nnnAB     x ",
      "  f tnt       l ",
      "  gCnnnoC     l ",
      "  m          CD ",
      "  m          xDj",
      "             x  ",
      "  moEFIJii  Kkr ",
      "ffguLLLM jNNLLM ",
      "                "
    ],
    [
      "                ",
      "ffg             ",
      "  f OPO         ",
      "m f QRS         ",
      "  f TUV         ",
      "  g WWV         ",
      "m f VXWY        ",
      "  fZV0W1 ~      ",
      "  f T 2         ",
      "  g W3V         ",
      "  m 4 4         ",
      "                ",
      "                ",
      "  m   5         ",
      "ffg             ",
      "                "
    ],
    [
      "                ",
      "667             ",
      "  8             ",
      "9 8  #          ",
      "# 8 $9%         ",
      "# 7 ^&^         ",
      "9 8*V W(        ",
      "  8 ^ ^  ~      ",
      "  8 W W         ",
      "  7 W)V         ",
      "    4 4         ",
      "                ",
      "                ",
      "                ",
      "++7             ",
      "                "
    ],
    [
      "                ",
      "                ",
      "                ",
      "                ",
      "                ",
      "    9##         ",
      "    ##9         ",
      "   -[#[] ~      ",
      "     9          ",
      "     9          ",
      "                ",
      "                ",
      "                ",
      "                ",
      "                ",
      "                "
    ],
    [
      "                ",
      "                ",
      "                ",
      "                ",
      "                ",
      "                ",
      "                ",
      "         ~      ",
      "                ",
      "                ",
      "                ",
      "                ",
      "                ",
      "                ",
      "                ",
      "                "
    ]
  ]
}