{
  "name": "building_residentiald_floor2_180",
  "refpalette": "deceasedcraft:building_residentiald/building_residentiald_floor2_palette_180",
  "xsize": 16,
  "zsize": 16,
  "slices": [
    [
      "                ",
      "                ",
      "  abbbbaffffff  ",
      "  an   agjjjjf  ",
      "  b         jf  ",
      "  b         jf  ",
      "  bm l   k  jf  ",
      "  aiii  h   gf  ",
      "  ae        aa  ",
      "  b       d  b  ",
      "  b          b  ",
      "  b          b  ",
      "  bc         b  ",
      "  aabbbaabbbaa  ",
      "                ",
      "                "
    ],
    [
      "                ",
      " AC    wB       ",
      " Aaabbaauuuuuu  ",
      " Aa    auyyyyu  ",
      " Aa    wuyyyyu  ",
      " Aa    wuyyyyu  ",
      " Aa  l wuyyyyu  ",
      " xaiii wuuuuuut ",
      " qa s  rqqqqaaq ",
      "  a          a  ",
      "  b          b  ",
      "  b          b  ",
      "  a          a  ",
      " paaaaaaaaaaaap ",
      " oooooooooooooo ",
      "                "
    ],
    [
      "                ",
      "  AC  wB        ",
      "  AaaaaB        ",
      "  AC  wB        ",
      "  AC  wB        ",
      "  AC  wB        ",
      "  AC  wB        ",
      "  AEEEEB        ",
      " txEEEEDttttttt ",
      " qaqqqqqqqqqqaq ",
      "  a          a  ",
      "  a          a  ",
      " pappppppppppap ",
      " oooooooooooooo ",
      "                ",
      "                "
    ],
    [
      "                ",
      "   ACwB         ",
      "   AaaB         ",
      "   ANMB         ",
      "   A  B         ",
      "   AL B         ",
      "   AKJB         ",
      "   A  B         ",
      "   AIFB         ",
      " ttxEEDtttttttt ",
      " qaqqqqqqqqqqaq ",
      " pappppppppppap ",
      " oooooooooooooo ",
      "                ",
      "                ",
      "                "
    ],
    [
      "                ",
      "    AB          ",
      "    AB          ",
      "    AB          ",
      "    AB          ",
      "    AB          ",
      "    AB          ",
      "    AB          ",
      "    AB          ",
      "    AB          ",
      " tttxOttttttttt ",
      " oooooooooooooo ",
      "                ",
      "                ",
      "                ",
      "                "
    ],
    [
      "~               ",
      "                ",
      "                ",
      "                ",
      "                ",
      "                ",
      "                ",
      "                ",
      "                ",
      "                ",
      "                ",
      "                ",
      "                ",
      "                ",
      "                ",
      "                "
    ]
  ]
}