{
  "name": "building_residentiald_floor1_270",
  "refpalette": "deceasedcraft:building_residentiald/building_residentiald_floor1_palette_270",
  "xsize": 16,
  "zsize": 16,
  "slices": [
    [
      "                ",
      "                ",
      "  ffffffabbbba  ",
      "  fggkkga    a  ",
      "  fg         b  ",
      "  fk         b  ",
      "  fk  l      b  ",
      "  fg   h     a  ",
      "  aa         a  ",
      "  b    i     b  ",
      "  b    jc    b  ",
      "  b    jd    b  ",
      "  bn  mje    a  ",
      "  aabbbaabbbba  ",
      "                ",
      "                "
    ],
    [
      "                ",
      " oo          oo ",
      " oqqqfffaaaaaao ",
      " oqggggga    ao ",
      " oqg         ao ",
      " oqg         ao ",
      " oqg  l      ao ",
      " oqg   l     ao ",
      " oaa         ao ",
      " oa    i     ao ",
      " oa    j     ao ",
      " oa    j     ao ",
      " oa   pj     ao ",
      " oaaaaaaaaaaaao ",
      " oo          oo ",
      "                "
    ],
    [
      "                ",
      "  rAto    otsr  ",
      "  rAtqqqaaatsr  ",
      "  rAtggga otsr  ",
      "  rAto    otsr  ",
      "  rAto  u otsr  ",
      "  rAtoll  otsr  ",
      "  rAto l  otsr  ",
      "  rAto    otsr  ",
      "  rAto x  otsr  ",
      "  rAto t  otsr  ",
      "  rAto tw otsr  ",
      "  rAtoyt  otsr  ",
      "  rAtaaaaaatsr  ",
      "  rAto    otsr  ",
      "                "
    ],
    [
      "                ",
      "     rAttsr     ",
      "     rAttsr     ",
      "     rAttsr     ",
      "     rAttsr     ",
      "     rAttsr     ",
      "     rAttsr     ",
      "     rAttsr     ",
      "     rAttsr     ",
      "     rAttsr     ",
      "     rAttsr     ",
      "     rAttsr     ",
      "     rAttsr     ",
      "     rAttsr     ",
      "     rAttsr     ",
      "                "
    ],
    [
      "                ",
      "                ",
      "                ",
      "                ",
      "                ",
      "                ",
      "                ",
      "                ",
      "                ",
      "                ",
      "                ",
      "                ",
      "                ",
      "                ",
      "                ",
      "~               "
    ],
    [
      "                ",
      "                ",
      "                ",
      "                ",
      "                ",
      "                ",
      "                ",
      "                ",
      "                ",
      "                ",
      "                ",
      "                ",
      "                ",
      "                ",
      "                ",
      "~               "
    ]
  ]
}