{
  "name": "building_residentiald_floor2_270",
  "refpalette": "deceasedcraft:building_residentiald/building_residentiald_floor2_palette_270",
  "xsize": 16,
  "zsize": 16,
  "slices": [
    [
      "                ",
      "                ",
      "  ffffffabbbba  ",
      "  fjjjjga    a  ",
      "  fj         b  ",
      "  fj     d   b  ",
      "  fj  k      b  ",
      "  fg   h     a  ",
      "  aa         a  ",
      "  b          b  ",
      "  b   li     b  ",
      "  b    i     b  ",
      "  bn  mie   ca  ",
      "  aabbbaabbbba  ",
      "                ",
      "                "
    ],
    [
      "                ",
      "       tq    po ",
      "  uuuuuuaabbaao ",
      "  uyyyyua    ao ",
      "  uyyyyuq    ao ",
      "  uyyyyuq    ao ",
      "  uyyyyuq    ao ",
      " Buuuuuuq    ao ",
      " waawwwwr    ao ",
      "  a          ao ",
      "  b   li     ao ",
      "  b    is    ao ",
      "  a    i     ao ",
      " Caaaaaaaabbaao ",
      " AAAAAAxq    po ",
      "                "
    ],
    [
      "                ",
      "        tq  po  ",
      "        taaaao  ",
      "        tq  po  ",
      "        tq  po  ",
      "        tq  po  ",
      "        tq  po  ",
      "        tq  po  ",
      " BBBBBBBDq  po  ",
      " wawwwwEEq  po  ",
      "  a    EEq  po  ",
      "  a    EEq  po  ",
      " CaCCCCEEq  po  ",
      " AAAAAAAxaaaao  ",
      "        tq  po  ",
      "                "
    ],
    [
      "                ",
      "         tqpo   ",
      "         taao   ",
      "         tqpo   ",
      "         tqpo   ",
      "         tqpo   ",
      "         tqpo   ",
      "         tqpo   ",
      "         tqpo   ",
      " BBBBBBBBDqpo   ",
      " waM  J FEqpo   ",
      " CaN LK IEqpo   ",
      " AAAAAAAAxqpo   ",
      "         taao   ",
      "         tqpo   ",
      "                "
    ],
    [
      "                ",
      "          to    ",
      "          to    ",
      "          to    ",
      "          to    ",
      "          to    ",
      "          to    ",
      "          to    ",
      "          to    ",
      "          to    ",
      " BBBBBBBBBOo    ",
      " AAAAAAAAAxo    ",
      "          to    ",
      "          to    ",
      "          to    ",
      "                "
    ],
    [
      "                ",
      "                ",
      "                ",
      "                ",
      "                ",
      "                ",
      "                ",
      "                ",
      "                ",
      "                ",
      "                ",
      "                ",
      "                ",
      "                ",
      "                ",
      "~               "
    ]
  ]
}