{
  "name": "building_residentiald_ground_180",
  "refpalette": "deceasedcraft:building_residentiald/building_residentiald_ground_palette_180",
  "xsize": 16,
  "zsize": 16,
  "slices": [
    [
      "aaaaaaaaaaaaaaaa",
      "bbbbbbbbbbbbbbba",
      "bbccccccbbbbbbba",
      "bbcddddceeeeebba",
      "bbcdddddffffebba",
      "bbcdddddffffebba",
      "bbcdddddffffebba",
      "bbcdddddffffebba",
      "bbcdddddddddccba",
      "bbcddddddddddcba",
      "bbcddddddddddcaa",
      "bbcddddddddddcaa",
      "bbcddddddddddcba",
      "bbccccccccccccba",
      "bbbbbbbbbbbbbbba",
      "aaaaaaaaaaaaaaaa"
    ],
    [
      "                ",
      "g               ",
      "g hjOOjhgggggg  ",
      "g h   Nheeeeeg  ",
      "g hM  EhLKJIeg  ",
      "g hF  Eh    eg  ",
      "g h   Dh    eg  ",
      "g hC   A   Beg  ",
      "g hw   A yxxhh  ",
      "g hw      uu j  ",
      "g hsts       r  ",
      "g hq mp      o  ",
      "g hn m!l k   ji ",
      "g hhhhhhhhhhhh  ",
      "g               ",
      "                "
    ],
    [
      "                ",
      "                ",
      "  hjOOjh        ",
      "  h    heXXee   ",
      "  O   3h2 10e   ",
      "  O   Zh    X   ",
      "  O   Yh    X   ",
      "  h    A    e   ",
      "  hW   A VU hh  ",
      "  OT         j  ",
      "  hsSs       R  ",
      "  P  m       Q  ",
      "  h  m  k    j  ",
      "  hhPhOhhOOOhh  ",
      "                ",
      "                "
    ],
    [
      "                ",
      "                ",
      "  hj88jh777777  ",
      "  h    heeeee7  ",
      "  6    h    e7  ",
      "  6    h    e7  ",
      "  6    h    e7  ",
      "  h    A    e7  ",
      "  h    A    hh  ",
      "  6          j  ",
      "  hsss       5  ",
      "  6  m       5  ",
      "  h  m k     j  ",
      "  hh4h4hh444hh  ",
      "                ",
      "                "
    ],
    [
      "                ",
      "                ",
      "  hhhhhh999999  ",
      "  hddddh%%%%$9  ",
      "  hddddd    #9  ",
      "  hddddd    #9  ",
      "  hddddd    #9  ",
      "  hddddd    #9  ",
      "  hdddddddddhh  ",
      "  hddddddddddh  ",
      "  hddddddddddh  ",
      "  hddddddddddh  ",
      "  hdddk   dddh  ",
      "  hhhhhhhhhhhh  ",
      "                ",
      "                "
    ],
    [
      "                ",
      "                ",
      "  hOOOOh;;;;;;  ",
      "  h ,, heeeee;  ",
      "  6?., ]    e;  ",
      "  6?., ]    e;  ",
      "  6-,, ] >  e;  ",
      "  h<'':]    e;  ",
      "  h|}{ ]]]]]hh  ",
      "  O [     -+)O  ",
      "  O          O  ",
      "  O   ((((   O  ",
      "  O       *&^O  ",
      "  hh444hh444hh  ",
      "                ",
      "                "
    ]
  ]
}