{
  "name": "building_residentiald_floor2_90",
  "refpalette": "deceasedcraft:building_residentiald/building_residentiald_floor2_palette_90",
  "xsize": 16,
  "zsize": 16,
  "slices": [
    [
      "                ",
      "                ",
      "  abbbbaabbbaa  ",
      "  ac   eim  nb  ",
      "  b     i    b  ",
      "  b     il   b  ",
      "  b          b  ",
      "  a         aa  ",
      "  a     h   gf  ",
      "  b      k  jf  ",
      "  b   d     jf  ",
      "  b         jf  ",
      "  a    agjjjjf  ",
      "  abbbbaffffff  ",
      "                ",
      "                "
    ],
    [
      "                ",
      " op    qxAAAAAA ",
      " oaabbaaaaaaaaC ",
      " oa     i    a  ",
      " oa    si    b  ",
      " oa     il   b  ",
      " oa          a  ",
      " oa    rwwwwaaw ",
      " oa    quuuuuuB ",
      " oa    quyyyyu  ",
      " oa    quyyyyu  ",
      " oa    quyyyyu  ",
      " oa    auyyyyu  ",
      " oaabbaauuuuuu  ",
      " op    qt       ",
      "                "
    ],
    [
      "                ",
      "  op  qt        ",
      "  oaaaaxAAAAAAA ",
      "  op  qEECCCCaC ",
      "  op  qEE    a  ",
      "  op  qEE    a  ",
      "  op  qEEwwwwaw ",
      "  op  qDBBBBBBB ",
      "  op  qt        ",
      "  op  qt        ",
      "  op  qt        ",
      "  op  qt        ",
      "  op  qt        ",
      "  oaaaat        ",
      "  op  qt        ",
      "                "
    ],
    [
      "                ",
      "   opqt         ",
      "   oaat         ",
      "   opqxAAAAAAAA ",
      "   opqEI KL NaC ",
      "   opqEF J  Maw ",
      "   opqDBBBBBBBB ",
      "   opqt         ",
      "   opqt         ",
      "   opqt         ",
      "   opqt         ",
      "   opqt         ",
      "   opqt         ",
      "   oaat         ",
      "   opqt         ",
      "                "
    ],
    [
      "                ",
      "    ot          ",
      "    ot          ",
      "    ot          ",
      "    oxAAAAAAAAA ",
      "    oOBBBBBBBBB ",
      "    ot          ",
      "    ot          ",
      "    ot          ",
      "    ot          ",
      "    ot          ",
      "    ot          ",
      "    ot          ",
      "    ot          ",
      "    ot          ",
      "                "
    ],
    [
      "               ~",
      "                ",
      "                ",
      "                ",
      "                ",
      "                ",
      "                ",
      "                ",
      "                ",
      "                ",
      "                ",
      "                ",
      "                ",
      "                ",
      "                ",
      "                "
    ]
  ]
}