{
  "name": "building_residentiald_ground",
  "refpalette": "deceasedcraft:building_residentiald/building_residentiald_ground_palette",
  "xsize": 16,
  "zsize": 16,
  "slices": [
    [
      "aaaaaaaaaaaaaaaa",
      "abbbbbbbbbbbbbbb",
      "abccccccccccccbb",
      "abcddddddddddcbb",
      "aacddddddddddcbb",
      "aacddddddddddcbb",
      "abcddddddddddcbb",
      "abccdddddddddcbb",
      "abbeffffdddddcbb",
      "abbeffffdddddcbb",
      "abbeffffdddddcbb",
      "abbeffffdddddcbb",
      "abbeeeeecddddcbb",
      "abbbbbbbccccccbb",
      "abbbbbbbbbbbbbbb",
      "aaaaaaaaaaaaaaaa"
    ],
    [
      "                ",
      "               g",
      "  hhhhhhhhhhhh g",
      " ij   k l!m nh g",
      "  o      pm qh g",
      "  r       stsh g",
      "  j uu      wh g",
      "  hhxxy A   wh g",
      "  geB   A   Ch g",
      "  ge    hD   h g",
      "  ge    hE  Fh g",
      "  geIJKLhE  Mh g",
      "  geeeeehN   h g",
      "  gggggghjOOjh g",
      "               g",
      "                "
    ],
    [
      "                ",
      "                ",
      "  hhOOOhhOhPhh  ",
      "  j    k  m  h  ",
      "  Q       m  P  ",
      "  R       sSsh  ",
      "  j         TO  ",
      "  hh UV A   Wh  ",
      "   e    A    h  ",
      "   X    hY   O  ",
      "   X    hZ   O  ",
      "   e01 2h3   O  ",
      "   eeXXeh    h  ",
      "        hjOOjh  ",
      "                ",
      "                "
    ],
    [
      "                ",
      "                ",
      "  hh444hh4h4hh  ",
      "  j     k m  h  ",
      "  5       m  6  ",
      "  5       sssh  ",
      "  j          6  ",
      "  hh    A    h  ",
      "  7e    A    h  ",
      "  7e    h    6  ",
      "  7e    h    6  ",
      "  7e    h    6  ",
      "  7eeeeeh    h  ",
      "  777777hj88jh  ",
      "                ",
      "                "
    ],
    [
      "                ",
      "                ",
      "  hhhhhhhhhhhh  ",
      "  hddd   kdddh  ",
      "  hddddddddddh  ",
      "  hddddddddddh  ",
      "  hddddddddddh  ",
      "  hhdddddddddh  ",
      "  9#    dddddh  ",
      "  9#    dddddh  ",
      "  9#    dddddh  ",
      "  9#    dddddh  ",
      "  9$%%%%hddddh  ",
      "  999999hhhhhh  ",
      "                ",
      "                "
    ],
    [
      "                ",
      "                ",
      "  hh444hh444hh  ",
      "  O^&*       O  ",
      "  O   ((((   O  ",
      "  O          O  ",
      "  O)+-     [ O  ",
      "  hh]]]]] {}|h  ",
      "  ;e    ]:''<h  ",
      "  ;e  > ] ,,-6  ",
      "  ;e    ] ,.?6  ",
      "  ;e    ] ,.?6  ",
      "  ;eeeeeh ,, h  ",
      "  ;;;;;;hOOOOh  ",
      "                ",
      "                "
    ]
  ]
}