{
  "name": "building_residentiald_floor1_90",
  "refpalette": "deceasedcraft:building_residentiald/building_residentiald_floor1_palette_90",
  "xsize": 16,
  "zsize": 16,
  "slices": [
    [
      "                ",
      "                ",
      "  abbbbaabbbaa  ",
      "  a    ejm  nb  ",
      "  b    dj    b  ",
      "  b    cj    b  ",
      "  b     i    b  ",
      "  a         aa  ",
      "  a     h   gf  ",
      "  b      l  kf  ",
      "  b         kf  ",
      "  b         gf  ",
      "  a    agkkggf  ",
      "  abbbbaffffff  ",
      "                ",
      "                "
    ],
    [
      "                ",
      " oo          oo ",
      " oaaaaaaaaaaaao ",
      " oa     jp   ao ",
      " oa     j    ao ",
      " oa     j    ao ",
      " oa     i    ao ",
      " oa         aao ",
      " oa     l   gqo ",
      " oa      l  gqo ",
      " oa         gqo ",
      " oa         gqo ",
      " oa    agggggqo ",
      " oaaaaaafffqqqo ",
      " oo          oo ",
      "                "
    ],
    [
      "                ",
      "  rsto    otAr  ",
      "  rstaaaaaatAr  ",
      "  rsto  tyotAr  ",
      "  rsto wt otAr  ",
      "  rsto  t otAr  ",
      "  rsto  x otAr  ",
      "  rsto    otAr  ",
      "  rsto  l otAr  ",
      "  rsto  llotAr  ",
      "  rsto u  otAr  ",
      "  rsto    otAr  ",
      "  rsto agggtAr  ",
      "  rstaaaqqqtAr  ",
      "  rsto    otAr  ",
      "                "
    ],
    [
      "                ",
      "     rsttAr     ",
      "     rsttAr     ",
      "     rsttAr     ",
      "     rsttAr     ",
      "     rsttAr     ",
      "     rsttAr     ",
      "     rsttAr     ",
      "     rsttAr     ",
      "     rsttAr     ",
      "     rsttAr     ",
      "     rsttAr     ",
      "     rsttAr     ",
      "     rsttAr     ",
      "     rsttAr     ",
      "                "
    ],
    [
      "               ~",
      "                ",
      "                ",
      "                ",
      "                ",
      "                ",
      "                ",
      "                ",
      "                ",
      "                ",
      "                ",
      "                ",
      "                ",
      "                ",
      "                ",
      "                "
    ],
    [
      "               ~",
      "                ",
      "                ",
      "                ",
      "                ",
      "                ",
      "                ",
      "                ",
      "                ",
      "                ",
      "                ",
      "                ",
      "                ",
      "                ",
      "                ",
      "                "
    ]
  ]
}