{
  "name": "building_residentiald_ground_90",
  "refpalette": "deceasedcraft:building_residentiald/building_residentiald_ground_palette_90",
  "xsize": 16,
  "zsize": 16,
  "slices": [
    [
      "abbbbbbbbbbbbbba",
      "abbbbbbbbbbbbbba",
      "abccccccccccccba",
      "abcddddddddddcba",
      "abcddddddddddcba",
      "abcddddddddddcba",
      "abcddddddddddcba",
      "abcdddddddddccba",
      "abcdddddffffebba",
      "abcdddddffffebba",
      "abcdddddffffebba",
      "abcdddddffffebba",
      "abcddddceeeeebba",
      "abccccccbbbbbbba",
      "abbbaabbbbbbbbba",
      "aaaaaaaaaaaaaaaa"
    ],
    [
      " gggggggggggggg ",
      "                ",
      "  hhhhhhhhhhhh  ",
      "  hnqswwC FM j  ",
      "  h  t       O  ",
      "  hmms       O  ",
      "  h!p    DEENj  ",
      "  hl   AAhhhhh  ",
      "  h        Leg  ",
      "  hk   y   Keg  ",
      "  h   ux   Jeg  ",
      "  h   uxB  Ieg  ",
      "  h    heeeeeg  ",
      "  hjorjhgggggg  ",
      "   i            ",
      "                "
    ],
    [
      "                ",
      "                ",
      "  hhPhOhhOOOhh  ",
      "  h  sTW     j  ",
      "  P  S       O  ",
      "  hmms       O  ",
      "  O      YZ3 j  ",
      "  h    AAhhhhh  ",
      "  hk       2e   ",
      "  O    V    X   ",
      "  O    U   1X   ",
      "  O        0e   ",
      "  h    heXXee   ",
      "  hjQRjh        ",
      "                ",
      "                "
    ],
    [
      "                ",
      "                ",
      "  hh6h6hh666hh  ",
      "  h  s       j  ",
      "  4  s       8  ",
      "  hmms       8  ",
      "  4          j  ",
      "  hk   AAhhhhh  ",
      "  h         e7  ",
      "  4         e7  ",
      "  4         e7  ",
      "  4         e7  ",
      "  h    heeeee7  ",
      "  hj55jh777777  ",
      "                ",
      "                "
    ],
    [
      "                ",
      "                ",
      "  hhhhhhhhhhhh  ",
      "  hddddddddddh  ",
      "  hddddddddddh  ",
      "  hddddddddddh  ",
      "  hkdddddddddh  ",
      "  h ddddddddhh  ",
      "  h dddd    %9  ",
      "  h dddd    %9  ",
      "  hddddd    %9  ",
      "  hddddd    %9  ",
      "  hddddh####$9  ",
      "  hhhhhh999999  ",
      "                ",
      "                "
    ],
    [
      "                ",
      "                ",
      "  hOOOOhh666hh  ",
      "  h    |<-?? O  ",
      "  4   [}',..,O  ",
      "  4    {',,,,O  ",
      "  4 (   :    O  ",
      "  h (  ]]]]]hh  ",
      "  h (  ]    e;  ",
      "  4 (  ] >  e;  ",
      "  4*  -]    e;  ",
      "  4&  +]    e;  ",
      "  h^  )heeeee;  ",
      "  hOOOOh;;;;;;  ",
      "                ",
      "                "
    ]
  ]
}