{
  "name": "building_residentiald_floor1_180",
  "refpalette": "deceasedcraft:building_residentiald/building_residentiald_floor1_palette_180",
  "xsize": 16,
  "zsize": 16,
  "slices": [
    [
      "                ",
      "                ",
      "  abbbbaffffff  ",
      "  an   agkkggf  ",
      "  b         gf  ",
      "  b         kf  ",
      "  bm     l  kf  ",
      "  ajjji h   gf  ",
      "  aedc      aa  ",
      "  b          b  ",
      "  b          b  ",
      "  b          b  ",
      "  b          b  ",
      "  aabbbaabbbaa  ",
      "                ",
      "                "
    ],
    [
      "                ",
      " oooooooooooooo ",
      " oaaaaaaqqqqqqo ",
      "  a    agggggq  ",
      "  a         gq  ",
      "  a         gf  ",
      "  ap     l  gf  ",
      "  ajjji l   gf  ",
      "  a         aa  ",
      "  a          a  ",
      "  a          a  ",
      "  a          a  ",
      "  a          a  ",
      " oaaaaaaaaaaaao ",
      " oooooooooooooo ",
      "                "
    ],
    [
      "                ",
      "                ",
      " rrrrrrrrrrrrrr ",
      " AAAAAAAAAAAAAA ",
      " tttttttttttttt ",
      " oaooooooooogqo ",
      "  ay     l  gq  ",
      "  atttx ll  gq  ",
      "  a w     u aa  ",
      "  a          a  ",
      " oaooooooooooao ",
      " tttttttttttttt ",
      " ssssssssssssss ",
      " rrrrrrrrrrrrrr ",
      "                ",
      "                "
    ],
    [
      "                ",
      "                ",
      "                ",
      "                ",
      "                ",
      " rrrrrrrrrrrrrr ",
      " AAAAAAAAAAAAAA ",
      " tttttttttttttt ",
      " tttttttttttttt ",
      " ssssssssssssss ",
      " rrrrrrrrrrrrrr ",
      "                ",
      "                ",
      "                ",
      "                ",
      "                "
    ],
    [
      "~               ",
      "                ",
      "                ",
      "                ",
      "                ",
      "                ",
      "                ",
      "                ",
      "                ",
      "                ",
      "                ",
      "                ",
      "                ",
      "                ",
      "                ",
      "                "
    ],
    [
      "~               ",
      "                ",
      "                ",
      "                ",
      "                ",
      "                ",
      "                ",
      "                ",
      "                ",
      "                ",
      "                ",
      "                ",
      "                ",
      "                ",
      "                ",
      "                "
    ]
  ]
}