{
  "name": "building_residentiald_floor2",
  "refpalette": "deceasedcraft:building_residentiald/building_residentiald_floor2_palette",
  "xsize": 16,
  "zsize": 16,
  "slices": [
    [
      "                ",
      "                ",
      "  aabbbaabbbaa  ",
      "  b         cb  ",
      "  b          b  ",
      "  b          b  ",
      "  b  d       b  ",
      "  aa        ea  ",
      "  fg   h  iiia  ",
      "  fj  k   l mb  ",
      "  fj         b  ",
      "  fj         b  ",
      "  fjjjjga   na  ",
      "  ffffffabbbba  ",
      "                ",
      "                "
    ],
    [
      "                ",
      " oooooooooooooo ",
      " paaaaaaaaaaaap ",
      "  a          a  ",
      "  b          b  ",
      "  b          b  ",
      "  a          a  ",
      " qaaqqqqr  s aq ",
      " tuuuuuuw iiiax ",
      "  uyyyyuw l  aA ",
      "  uyyyyuw    aA ",
      "  uyyyyuw    aA ",
      "  uyyyyua    aA ",
      "  uuuuuuaabbaaA ",
      "       Bw    CA ",
      "                "
    ],
    [
      "                ",
      "                ",
      " oooooooooooooo ",
      " pappppppppppap ",
      "  a          a  ",
      "  a          a  ",
      " qaqqqqqqqqqqaq ",
      " tttttttDEEEExt ",
      "        BEEEEA  ",
      "        Bw  CA  ",
      "        Bw  CA  ",
      "        Bw  CA  ",
      "        Bw  CA  ",
      "        BaaaaA  ",
      "        Bw  CA  ",
      "                "
    ],
    [
      "                ",
      "                ",
      "                ",
      " oooooooooooooo ",
      " pappppppppppap ",
      " qaqqqqqqqqqqaq ",
      " ttttttttDEExtt ",
      "         BFIA   ",
      "         B  A   ",
      "         BJKA   ",
      "         B LA   ",
      "         B  A   ",
      "         BMNA   ",
      "         BaaA   ",
      "         BwCA   ",
      "                "
    ],
    [
      "                ",
      "                ",
      "                ",
      "                ",
      " oooooooooooooo ",
      " tttttttttOxttt ",
      "          BA    ",
      "          BA    ",
      "          BA    ",
      "          BA    ",
      "          BA    ",
      "          BA    ",
      "          BA    ",
      "          BA    ",
      "          BA    ",
      "                "
    ],
    [
      "                ",
      "                ",
      "                ",
      "                ",
      "                ",
      "                ",
      "                ",
      "                ",
      "                ",
      "                ",
      "                ",
      "                ",
      "                ",
      "                ",
      "                ",
      "               ~"
    ]
  ]
}