{
  "name": "building_residentiald_ground_270",
  "refpalette": "deceasedcraft:building_residentiald/building_residentiald_ground_palette_270",
  "xsize": 16,
  "zsize": 16,
  "slices": [
    [
      "aaaaaaaaaaaaaaaa",
      "abbbbbbbbbaabbba",
      "abbbbbbbccccccba",
      "abbeeeeecddddcba",
      "abbeffffdddddcba",
      "abbeffffdddddcba",
      "abbeffffdddddcba",
      "abbeffffdddddcba",
      "abccdddddddddcba",
      "abcddddddddddcba",
      "abcddddddddddcba",
      "abcddddddddddcba",
      "abcddddddddddcba",
      "abccccccccccccba",
      "abbbbbbbbbbbbbba",
      "abbbbbbbbbbbbbba"
    ],
    [
      "                ",
      "            i   ",
      "  gggggghjrojh  ",
      "  geeeeeh    h  ",
      "  geI  Bxu   h  ",
      "  geJ   xu   h  ",
      "  geK   y   kh  ",
      "  geL        h  ",
      "  hhhhhAA   lh  ",
      "  jNEED    p!h  ",
      "  O       smmh  ",
      "  O       t  h  ",
      "  j MF Cwwsqnh  ",
      "  hhhhhhhhhhhh  ",
      "                ",
      " gggggggggggggg "
    ],
    [
      "                ",
      "                ",
      "        hjRQjh  ",
      "   eeXXeh    h  ",
      "   e0        O  ",
      "   X1   U    O  ",
      "   X    V    O  ",
      "   e2       kh  ",
      "  hhhhhAA    h  ",
      "  j 3ZY      O  ",
      "  O       smmh  ",
      "  O       S  P  ",
      "  j     WTs  h  ",
      "  hhOOOhhOhPhh  ",
      "                ",
      "                "
    ],
    [
      "                ",
      "                ",
      "  777777hj55jh  ",
      "  7eeeeeh    h  ",
      "  7e         4  ",
      "  7e         4  ",
      "  7e         4  ",
      "  7e         h  ",
      "  hhhhhAA   kh  ",
      "  j          4  ",
      "  8       smmh  ",
      "  8       s  4  ",
      "  j       s  h  ",
      "  hh666hh6h6hh  ",
      "                ",
      "                "
    ],
    [
      "                ",
      "                ",
      "  999999hhhhhh  ",
      "  9$####hddddh  ",
      "  9%    dddddh  ",
      "  9%    dddddh  ",
      "  9%    dddd h  ",
      "  9%    dddd h  ",
      "  hhdddddddd h  ",
      "  hdddddddddkh  ",
      "  hddddddddddh  ",
      "  hddddddddddh  ",
      "  hddddddddddh  ",
      "  hhhhhhhhhhhh  ",
      "                ",
      "                "
    ],
    [
      "                ",
      "                ",
      "  ;;;;;;hOOOOh  ",
      "  ;eeeeeh)  ^h  ",
      "  ;e    ]+  &4  ",
      "  ;e    ]-  *4  ",
      "  ;e  > ]  ( 4  ",
      "  ;e    ]  ( h  ",
      "  hh]]]]]  ( h  ",
      "  O    :   ( 4  ",
      "  O,,,,'{    4  ",
      "  O,..,'}[   4  ",
      "  O ??-<|    h  ",
      "  hh666hhOOOOh  ",
      "                ",
      "                "
    ]
  ]
}