{
  "name": "building_residentiald_floor1",
  "refpalette": "deceasedcraft:building_residentiald/building_residentiald_floor1_palette",
  "xsize": 16,
  "zsize": 16,
  "slices": [
    [
      "                ",
      "                ",
      "  aabbbaabbbaa  ",
      "  b          b  ",
      "  b          b  ",
      "  b          b  ",
      "  b          b  ",
      "  aa      cdea  ",
      "  fg   h ijjja  ",
      "  fk  l     mb  ",
      "  fk         b  ",
      "  fg         b  ",
      "  fggkkga   na  ",
      "  ffffffabbbba  ",
      "                ",
      "                "
    ],
    [
      "                ",
      " oooooooooooooo ",
      " oaaaaaaaaaaaao ",
      "  a          a  ",
      "  a          a  ",
      "  a          a  ",
      "  a          a  ",
      "  aa         a  ",
      "  fg   l ijjja  ",
      "  fg  l     pa  ",
      "  fg         a  ",
      "  qg         a  ",
      "  qggggga    a  ",
      " oqqqqqqaaaaaao ",
      " oooooooooooooo ",
      "                "
    ],
    [
      "                ",
      "                ",
      " rrrrrrrrrrrrrr ",
      " ssssssssssssss ",
      " tttttttttttttt ",
      " oaooooooooooao ",
      "  a          a  ",
      "  aa u     w a  ",
      "  qg  ll xttta  ",
      "  qg  l     ya  ",
      " oqgoooooooooao ",
      " tttttttttttttt ",
      " AAAAAAAAAAAAAA ",
      " rrrrrrrrrrrrrr ",
      "                ",
      "                "
    ],
    [
      "                ",
      "                ",
      "                ",
      "                ",
      "                ",
      " rrrrrrrrrrrrrr ",
      " ssssssssssssss ",
      " tttttttttttttt ",
      " tttttttttttttt ",
      " AAAAAAAAAAAAAA ",
      " rrrrrrrrrrrrrr ",
      "                ",
      "                ",
      "                ",
      "                ",
      "                "
    ],
    [
      "                ",
      "                ",
      "                ",
      "                ",
      "                ",
      "                ",
      "                ",
      "                ",
      "                ",
      "                ",
      "                ",
      "                ",
      "                ",
      "                ",
      "                ",
      "               ~"
    ],
    [
      "                ",
      "                ",
      "                ",
      "                ",
      "                ",
      "                ",
      "                ",
      "                ",
      "                ",
      "                ",
      "                ",
      "                ",
      "                ",
      "                ",
      "                ",
      "               ~"
    ]
  ]
}