{
  "name": "building_flowershop_ground_180",
  "refpalette": "deceasedcraft:building_flowershop/building_flowershop_ground_palette_180",
  "xsize": 16,
  "zsize": 16,
  "slices": [
    [
      "iiiiiiiiiiiiiiii",
      "iiiiiiiiiiiiiiii",
      "iiiiiiiiiiiiiiii",
      "acddcdiiiidddcda",
      "adcddciiiidcddca",
      "adbbbbiiiibbbbca",
      "acbbbbbbbbbbbbda",
      "acbeeeeeeeeeebda",
      "adbeeeeeeeeeebca",
      "acbeeeeeeeeeebda",
      "adbeeeeeeeeeebda",
      "abbeeggggggeebba",
      "abeeeggghggeeeba",
      "abeeeffffffeeeba",
      "abbbbdddddcbbbba",
      "aaaaaaaaaaaaaaaa"
    ],
    [
      "                ",
      "                ",
      " RRRRR    RRRRR ",
      " QDDDP    QDDDP ",
      " uuuuu    uuuuu ",
      " uwwww    wwwwu ",
      " uwOKpLNMLpKJwu ",
      " uw I      AFwu ",
      " uw E      ADwu ",
      " uw C BBBB Aywu ",
      " uw x        wu ",
      " jjtjkp q kjsjj ",
      " jr jpqkpqpj oj ",
      " j!njmmmmmmj lj ",
      " jjjjkkkkkkjjjj ",
      "                "
    ],
    [
      "                ",
      "                ",
      "                ",
      " <':;|    }{][- ",
      " +8108    +0818 ",
      " 8wwww    wwww0 ",
      " )w(KpL*&LpK^w8 ",
      " 1w %       $w# ",
      " 0w         9w8 ",
      " 8w 7 6543  2w1 ",
      " 0w          w0 ",
      " jjZjW    WjYjj ",
      " jX j  W   j  j ",
      " jVUjmmmmmmj Tj ",
      " jjjjSSSSSSjjjj ",
      "                "
    ],
    [
      "                ",
      "                ",
      "                ",
      "                ",
      "                ",
      "  wwww    wwww  ",
      "  w KpLLLLpK w  ",
      "  >          >  ",
      "  >          >  ",
      "  >          >  ",
      "  w          w  ",
      " jjjjW    Wjjjj ",
      " j  j  W   j /j ",
      " j?.jmmmmmmj ,j ",
      " j>>j      j>>j ",
      "                "
    ],
    [
      "                ",
      " \u0374\u0374\u0374\u0374\u0374\u0374\u0374\u0374\u0374\u0374\u0374\u0374\u0374\u0374 ",
      " \u0374\u0374\u0374\u0374\u0374\u0374\u0374\u0374\u0374\u0374\u0374\u0374\u0374\u0374 ",
      " \u0374\u0374\u0374\u0374\u0374\u0374\u0374\u0374\u0374\u0374\u0374\u0374\u0374\u0374 ",
      " \u0374\u0374\u0374\u0375\u0374\u0374\u0374\u0374\u0374\u0374\u0375\u0374\u0374\u0374 ",
      "  wwwwwwwwwwww  ",
      "  w\u0373KppppppK\u0371w  ",
      "  w\u0373\u0372\u0372\u0372\u0372\u0372\u0372\u0372\u0372\u0371w  ",
      "  w\u0373\u0372\u0372\u0372\u0372\u0372\u0372\u0372\u0372\u0371w  ",
      "  w\u0373\u0372\u0372\u0372\u0372\u0372\u0372\u0372\u0372\u0371w  ",
      "  w\u0373\u0372\u0372\u0372\u0372\u0372\u0372\u0372\u0372\u0371w  ",
      " jjjj\u0370     jjjj ",
      " j  j      j  j ",
      " j  jmmmmmmj  j ",
      " j``j      j``j ",
      "                "
    ],
    [
      "                ",
      "    \u0385      \u0385    ",
      "    \u0377      \u0377    ",
      "    \u0377      \u0377    ",
      "    \u0377      \u0377    ",
      "  \u037d\u037d\u0377\u037d\u037d\u037d\u037d\u037d\u037d\u0377\u037d\u037d  ",
      "  \u037d\u0384\u0377\u037f\u037f\u037f\u037f\u037f\u037f\u0377\u037e\u037d  ",
      "  \u037d\u0384\u0377\u037f\u037f\u037f\u037f\u037f\u037f\u0377\u037e\u037d  ",
      "  \u037d\u0384\u0377\u037f\u037f\u037f\u037f\u037f\u037f\u0377\u037e\u037d  ",
      "  \u037d\u0384\u0377\u037f\u037f\u037f\u037f\u037f\u037f\u0377\u037e\u037d  ",
      "  \u037d\u0384\u0377\u037f\u037f\u037f\u037f\u037f\u037f\u0377\u037e\u037d  ",
      " jjj\u0377\u037a\u037a\u037a\u037a\u037a\u037a\u0377jjj ",
      " j\u0376\u0376\u0377\u037c\u037b\u037c\u037b\u037c\u037b\u0377\u0376\u0376j ",
      " j\u0376\u0376\u0377\u037a\u037a\u037a\u037a\u037a\u037a\u0377\u0376\u0376j ",
      " jjjjjjjjjjjjjj ",
      "                "
    ]
  ]
}