{
  "name": "building_flowershop_ground",
  "refpalette": "deceasedcraft:building_flowershop/building_flowershop_ground_palette",
  "xsize": 16,
  "zsize": 16,
  "slices": [
    [
      "aaaaaaaaaaaaaaaa",
      "abbbbcdddddbbbba",
      "abeeeffffffeeeba",
      "abeeegghgggeeeba",
      "abbeeggggggeebba",
      "adbeeeeeeeeeebda",
      "adbeeeeeeeeeebca",
      "acbeeeeeeeeeebda",
      "adbeeeeeeeeeebca",
      "adbbbbbbbbbbbbca",
      "acbbbbiiiibbbbda",
      "acddcdiiiicddcda",
      "adcdddiiiidcddca",
      "iiiiiiiiiiiiiiii",
      "iiiiiiiiiiiiiiii",
      "iiiiiiiiiiiiiiii"
    ],
    [
      "                ",
      " jjjjkkkkkkjjjj ",
      " jl jmmmmmmjn!j ",
      " jo jpqpkqpj rj ",
      " jjsjk q pkjtjj ",
      " uw        x wu ",
      " uwyA BBBB C wu ",
      " uwDA      E wu ",
      " uwFA      I wu ",
      " uwJKpLMNLpKOwu ",
      " uwwww    wwwwu ",
      " uuuuu    uuuuu ",
      " PDDDQ    PDDDQ ",
      " RRRRR    RRRRR ",
      "                ",
      "                "
    ],
    [
      "                ",
      " jjjjSSSSSSjjjj ",
      " jT jmmmmmmjUVj ",
      " j  j   W  j Xj ",
      " jjYjW    WjZjj ",
      " 0w          w0 ",
      " 1w2  3456 7 w8 ",
      " 8w9         w0 ",
      " #w$       % w1 ",
      " 8w^KpL&*LpK(w) ",
      " 0wwww    wwww8 ",
      " 8180+    8018+ ",
      " -[]{}    |;:'< ",
      "                ",
      "                ",
      "                "
    ],
    [
      "                ",
      " j>>j      j>>j ",
      " j, jmmmmmmj.?j ",
      " j/ j   W  j  j ",
      " jjjjW    Wjjjj ",
      "  w          w  ",
      "  >          >  ",
      "  >          >  ",
      "  >          >  ",
      "  w KpLLLLpK w  ",
      "  wwww    wwww  ",
      "                ",
      "                ",
      "                ",
      "                ",
      "                "
    ],
    [
      "                ",
      " j``j      j``j ",
      " j  jmmmmmmj  j ",
      " j  j      j  j ",
      " jjjj     \u0370jjjj ",
      "  w\u0371\u0372\u0372\u0372\u0372\u0372\u0372\u0372\u0372\u0373w  ",
      "  w\u0371\u0372\u0372\u0372\u0372\u0372\u0372\u0372\u0372\u0373w  ",
      "  w\u0371\u0372\u0372\u0372\u0372\u0372\u0372\u0372\u0372\u0373w  ",
      "  w\u0371\u0372\u0372\u0372\u0372\u0372\u0372\u0372\u0372\u0373w  ",
      "  w\u0371KppppppK\u0373w  ",
      "  wwwwwwwwwwww  ",
      " \u0374\u0374\u0374\u0375\u0374\u0374\u0374\u0374\u0374\u0374\u0375\u0374\u0374\u0374 ",
      " \u0374\u0374\u0374\u0374\u0374\u0374\u0374\u0374\u0374\u0374\u0374\u0374\u0374\u0374 ",
      " \u0374\u0374\u0374\u0374\u0374\u0374\u0374\u0374\u0374\u0374\u0374\u0374\u0374\u0374 ",
      " \u0374\u0374\u0374\u0374\u0374\u0374\u0374\u0374\u0374\u0374\u0374\u0374\u0374\u0374 ",
      "                "
    ],
    [
      "                ",
      " jjjjjjjjjjjjjj ",
      " j\u0376\u0376\u0377\u037a\u037a\u037a\u037a\u037a\u037a\u0377\u0376\u0376j ",
      " j\u0376\u0376\u0377\u037b\u037c\u037b\u037c\u037b\u037c\u0377\u0376\u0376j ",
      " jjj\u0377\u037a\u037a\u037a\u037a\u037a\u037a\u0377jjj ",
      "  \u037d\u037e\u0377\u037f\u037f\u037f\u037f\u037f\u037f\u0377\u0384\u037d  ",
      "  \u037d\u037e\u0377\u037f\u037f\u037f\u037f\u037f\u037f\u0377\u0384\u037d  ",
      "  \u037d\u037e\u0377\u037f\u037f\u037f\u037f\u037f\u037f\u0377\u0384\u037d  ",
      "  \u037d\u037e\u0377\u037f\u037f\u037f\u037f\u037f\u037f\u0377\u0384\u037d  ",
      "  \u037d\u037e\u0377\u037f\u037f\u037f\u037f\u037f\u037f\u0377\u0384\u037d  ",
      "  \u037d\u037d\u0377\u037d\u037d\u037d\u037d\u037d\u037d\u0377\u037d\u037d  ",
      "    \u0377      \u0377    ",
      "    \u0377      \u0377    ",
      "    \u0377      \u0377    ",
      "    \u0385      \u0385    ",
      "                "
    ]
  ]
}