{
  "name": "building_flowershop_ground_270",
  "refpalette": "deceasedcraft:building_flowershop/building_flowershop_ground_palette_270",
  "xsize": 16,
  "zsize": 16,
  "slices": [
    [
      "iiiaaaaaaaaaaaaa",
      "iiidccddcddbbbba",
      "iiicdbbbbbbbeeba",
      "iiiddbbeeeeeeeba",
      "iiidcbbeeeeeeeba",
      "iiiddbbeeeeggfca",
      "iiiiiibeeeeggfda",
      "iiiiiibeeeeghfda",
      "iiiiiibeeeeggfda",
      "iiiiiibeeeeggfda",
      "iiidcbbeeeeggfda",
      "iiicdbbeeeeeeeba",
      "iiiddbbeeeeeeeba",
      "iiidcbbbbbbbeeba",
      "iiicddccdcdbbbba",
      "iiiaaaaaaaaaaaaa"
    ],
    [
      "                ",
      "  RPuuuuuuujjjj ",
      "  RDuwwwwwwjolj ",
      "  RDuwJFDy s  j ",
      "  RDuwKAAA jjjj ",
      "  RQuwp    kpmk ",
      "      L  B  qmk ",
      "      M  B qpmk ",
      "      N  B  kmk ",
      "      L  B pqmk ",
      "  RPuwp    kpmk ",
      "  RDuwKIECxjjjj ",
      "  RDuwO    t nj ",
      "  RDuwwwwwwjr!j ",
      "  RQuuuuuuujjjj ",
      "                "
    ],
    [
      "                ",
      "   -808#810jjjj ",
      "   [1wwwwwwj Tj ",
      "   ]8w^$92 Y  j ",
      "   {0wK    jjjj ",
      "   }+wp    W mS ",
      "      L  3   mS ",
      "      &  4   mS ",
      "      *  5  WmS ",
      "      L  6   mS ",
      "   |8wp    W mS ",
      "   ;0wK% 7 jjjj ",
      "   :1w(    Z Uj ",
      "   '8wwwwwwjXVj ",
      "   <+8)1080jjjj ",
      "                "
    ],
    [
      "                ",
      "           jjjj ",
      "     ww>>>wj/,> ",
      "     w     j  > ",
      "     wK    jjjj ",
      "     wp    W m  ",
      "      L      m  ",
      "      L      m  ",
      "      L     Wm  ",
      "      L      m  ",
      "     wp    W m  ",
      "     wK    jjjj ",
      "     w     j .> ",
      "     ww>>>wj ?> ",
      "           jjjj ",
      "                "
    ],
    [
      "                ",
      " \u0374\u0374\u0374\u0374      jjjj ",
      " \u0374\u0374\u0374\u0374wwwwwwj  ` ",
      " \u0374\u0374\u0374\u0374w\u0371\u0371\u0371\u0371\u0371j  ` ",
      " \u0374\u0374\u0374\u0375wK\u0372\u0372\u0372\u0372jjjj ",
      " \u0374\u0374\u0374\u0374wp\u0372\u0372\u0372\u0372  m  ",
      " \u0374\u0374\u0374\u0374wp\u0372\u0372\u0372\u0372  m  ",
      " \u0374\u0374\u0374\u0374wp\u0372\u0372\u0372\u0372  m  ",
      " \u0374\u0374\u0374\u0374wp\u0372\u0372\u0372\u0372  m  ",
      " \u0374\u0374\u0374\u0374wp\u0372\u0372\u0372\u0372  m  ",
      " \u0374\u0374\u0374\u0374wp\u0372\u0372\u0372\u0372\u0370 m  ",
      " \u0374\u0374\u0374\u0375wK\u0372\u0372\u0372\u0372jjjj ",
      " \u0374\u0374\u0374\u0374w\u0373\u0373\u0373\u0373\u0373j  ` ",
      " \u0374\u0374\u0374\u0374wwwwwwj  ` ",
      " \u0374\u0374\u0374\u0374      jjjj ",
      "                "
    ],
    [
      "                ",
      "           jjjj ",
      "     \u037d\u037d\u037d\u037d\u037d\u037dj\u0376\u0376j ",
      "     \u037d\u037e\u037e\u037e\u037e\u037ej\u0376\u0376j ",
      " \u0385\u0377\u0377\u0377\u0377\u0377\u0377\u0377\u0377\u0377\u0377\u0377\u0377j ",
      "     \u037d\u037f\u037f\u037f\u037f\u037f\u037a\u037b\u037aj ",
      "     \u037d\u037f\u037f\u037f\u037f\u037f\u037a\u037c\u037aj ",
      "     \u037d\u037f\u037f\u037f\u037f\u037f\u037a\u037b\u037aj ",
      "     \u037d\u037f\u037f\u037f\u037f\u037f\u037a\u037c\u037aj ",
      "     \u037d\u037f\u037f\u037f\u037f\u037f\u037a\u037b\u037aj ",
      "     \u037d\u037f\u037f\u037f\u037f\u037f\u037a\u037c\u037aj ",
      " \u0385\u0377\u0377\u0377\u0377\u0377\u0377\u0377\u0377\u0377\u0377\u0377\u0377j ",
      "     \u037d\u0384\u0384\u0384\u0384\u0384j\u0376\u0376j ",
      "     \u037d\u037d\u037d\u037d\u037d\u037dj\u0376\u0376j ",
      "           jjjj ",
      "                "
    ]
  ]
}