{
  "name": "building_flowershop_ground_90",
  "refpalette": "deceasedcraft:building_flowershop/building_flowershop_ground_palette_90",
  "xsize": 16,
  "zsize": 16,
  "slices": [
    [
      "aaaaaaaaaaaaaiii",
      "abbbbdcdccddciii",
      "abeebbbbbbbcdiii",
      "abeeeeeeebbddiii",
      "abeeeeeeebbdciii",
      "adfggeeeebbcdiii",
      "adfggeeeebiiiiii",
      "adfggeeeebiiiiii",
      "adfhgeeeebiiiiii",
      "adfggeeeebiiiiii",
      "acfggeeeebbddiii",
      "abeeeeeeebbcdiii",
      "abeeeeeeebbddiii",
      "abeebbbbbbbdciii",
      "abbbbddcddccdiii",
      "aaaaaaaaaaaaaiii"
    ],
    [
      "                ",
      " jjjjuuuuuuuQR  ",
      " j!rjwwwwwwuDR  ",
      " jn t    OwuDR  ",
      " jjjjxCEIKwuDR  ",
      " kmpk    pwuPR  ",
      " kmqp B  L      ",
      " kmk  B  N      ",
      " kmpq B  M      ",
      " kmq  B  L      ",
      " kmpk    pwuQR  ",
      " jjjj AAAKwuDR  ",
      " j  s yDFJwuDR  ",
      " jlojwwwwwwuDR  ",
      " jjjjuuuuuuuPR  ",
      "                "
    ],
    [
      "                ",
      " jjjj0801)8+<   ",
      " jVXjwwwwww8'   ",
      " jU Z    (w1:   ",
      " jjjj 7 %Kw0;   ",
      " Sm W    pw8|   ",
      " Sm   6  L      ",
      " SmW  5  *      ",
      " Sm   4  &      ",
      " Sm   3  L      ",
      " Sm W    pw+}   ",
      " jjjj    Kw0{   ",
      " j  Y 29$^w8]   ",
      " jT jwwwwww1[   ",
      " jjjj018#808-   ",
      "                "
    ],
    [
      "                ",
      " jjjj           ",
      " >? jw>>>ww     ",
      " >. j     w     ",
      " jjjj    Kw     ",
      "  m W    pw     ",
      "  m      L      ",
      "  mW     L      ",
      "  m      L      ",
      "  m      L      ",
      "  m W    pw     ",
      " jjjj    Kw     ",
      " >  j     w     ",
      " >,/jw>>>ww     ",
      " jjjj           ",
      "                "
    ],
    [
      "                ",
      " jjjj      \u0374\u0374\u0374\u0374 ",
      " `  jwwwwww\u0374\u0374\u0374\u0374 ",
      " `  j\u0373\u0373\u0373\u0373\u0373w\u0374\u0374\u0374\u0374 ",
      " jjjj\u0372\u0372\u0372\u0372Kw\u0375\u0374\u0374\u0374 ",
      "  m \u0370\u0372\u0372\u0372\u0372pw\u0374\u0374\u0374\u0374 ",
      "  m  \u0372\u0372\u0372\u0372pw\u0374\u0374\u0374\u0374 ",
      "  m  \u0372\u0372\u0372\u0372pw\u0374\u0374\u0374\u0374 ",
      "  m  \u0372\u0372\u0372\u0372pw\u0374\u0374\u0374\u0374 ",
      "  m  \u0372\u0372\u0372\u0372pw\u0374\u0374\u0374\u0374 ",
      "  m  \u0372\u0372\u0372\u0372pw\u0374\u0374\u0374\u0374 ",
      " jjjj\u0372\u0372\u0372\u0372Kw\u0375\u0374\u0374\u0374 ",
      " `  j\u0371\u0371\u0371\u0371\u0371w\u0374\u0374\u0374\u0374 ",
      " `  jwwwwww\u0374\u0374\u0374\u0374 ",
      " jjjj      \u0374\u0374\u0374\u0374 ",
      "                "
    ],
    [
      "                ",
      " jjjj           ",
      " j\u0376\u0376j\u037d\u037d\u037d\u037d\u037d\u037d     ",
      " j\u0376\u0376j\u0384\u0384\u0384\u0384\u0384\u037d     ",
      " j\u0377\u0377\u0377\u0377\u0377\u0377\u0377\u0377\u0377\u0377\u0377\u0377\u0385 ",
      " j\u037a\u037c\u037a\u037f\u037f\u037f\u037f\u037f\u037d     ",
      " j\u037a\u037b\u037a\u037f\u037f\u037f\u037f\u037f\u037d     ",
      " j\u037a\u037c\u037a\u037f\u037f\u037f\u037f\u037f\u037d     ",
      " j\u037a\u037b\u037a\u037f\u037f\u037f\u037f\u037f\u037d     ",
      " j\u037a\u037c\u037a\u037f\u037f\u037f\u037f\u037f\u037d     ",
      " j\u037a\u037b\u037a\u037f\u037f\u037f\u037f\u037f\u037d     ",
      " j\u0377\u0377\u0377\u0377\u0377\u0377\u0377\u0377\u0377\u0377\u0377\u0377\u0385 ",
      " j\u0376\u0376j\u037e\u037e\u037e\u037e\u037e\u037d     ",
      " j\u0376\u0376j\u037d\u037d\u037d\u037d\u037d\u037d     ",
      " jjjj           ",
      "                "
    ]
  ]
}