{
  "name": "multi_oasiscondo_4_floor8",
  "refpalette": "deceasedcraft:multi_oasiscondo_4/multi_oasiscondo_4_floor8_palette",
  "xsize": 16,
  "zsize": 16,
  "slices": [
    [
      "                ",
      "                ",
      "                ",
      "                ",
      "                ",
      "                ",
      "                ",
      "                ",
      "                ",
      "ab baaaaaaaaaaaa",
      "aacaaaaaaaaaaaaa",
      "aacaaaaaaaaaaaaa",
      "aacaaaaaaaaaaaaa",
      "aacaaaaaaaaaaaaa",
      "aacaaaaaaaaaaaaa",
      "deceeeeeeeeaeeee"
    ],
    [
      "                ",
      "                ",
      "                ",
      "                ",
      "                ",
      "                ",
      "                ",
      "                ",
      "ef fegeggghghhge",
      "ig gjklmn oepq r",
      " sct  umwxyABCxy",
      "DEcF     IJKLLee",
      " scM   N  u OPQ ",
      "LLc RR N      S ",
      " TcUVVUmWWWWWWQ ",
      "Xeceeeeeeeeeeeee"
    ],
    [
      "                ",
      "                ",
      "                ",
      "                ",
      "                ",
      "                ",
      "                ",
      "                ",
      "gf YeZZZZZZ0ZZZZ",
      " e e12 m3  e   4",
      " 5c    m6 789  #",
      "  c      $ LLLee",
      " %c    N    ^ Q ",
      "LLc    N      & ",
      " *c   (mWWWWWWQ ",
      ")eceeeeeeeeeeeee"
    ],
    [
      "                ",
      "                ",
      "                ",
      "                ",
      "                ",
      "                ",
      "                ",
      "                ",
      "ef YgZZZZZZ0ZZZZ",
      " g e   m   e   +",
      "  c    m- [e]  #",
      "  c     {}|LLLee",
      "  c    N      Q ",
      "LLc    N      ; ",
      " :c    m '< >,Q ",
      ".eceeeeeeeeeeeee"
    ],
    [
      "                ",
      "                ",
      "                ",
      "                ",
      "                ",
      "                ",
      "                ",
      "                ",
      "gf feZZZZZZ0ZZZZ",
      " g e   m???e ???",
      "  c  / m???e/???",
      "` c    mLLLLLLee",
      "  c    m      Q ",
      "LLc  ` m /  \u0370 Q/",
      "  c    m \u0371  \u0372 Q ",
      "eeceeeeeeeeeeeee"
    ],
    [
      "                ",
      "                ",
      "                ",
      "                ",
      "                ",
      "                ",
      "                ",
      "                ",
      "eY Yeeegeeeegeee",
      "\u0373e g\u0373\u0373\u0373\u0373  \u0373\u0373\u0373\u0374  ",
      "\u0373\u0373c\u0373\u0373\u0373\u0373\u0373  \u0374\u0373\u0373   ",
      "\u0373\u0373c\u0373\u0373\u0373\u0373\u0373\u0373\u0373\u0373\u0373\u0373\u0373\u0373\u0373",
      "\u0373\u0373c\u0373\u0373\u0373\u0373\u0373\u0373\u0373\u0373\u0373\u0373\u0373\u0373\u0373",
      "\u0373\u0373c\u0373\u0373\u0373\u0373\u0373\u0373\u0373\u0373\u0373\u0373\u0373\u0373\u0373",
      "\u0373\u0373c\u0373\u0373\u0373\u0373\u0373\u0373\u0373\u0373\u0373\u0373\u0373\u0373\u0373",
      "eeceeeeeeeeeeeee"
    ]
  ]
}