{
  "name": "multi_oasiscondo_4_floor11",
  "refpalette": "deceasedcraft:multi_oasiscondo_4/multi_oasiscondo_4_floor11_palette",
  "xsize": 16,
  "zsize": 16,
  "slices": [
    [
      "                ",
      "                ",
      "                ",
      "                ",
      "                ",
      "                ",
      "                ",
      "                ",
      "                ",
      "aaaaaaaaaab baaa",
      "ccdccccccccdaaaa",
      "cccccccccccdaaaa",
      "cccccccccccdaaaa",
      "eccccccccccdaaaa",
      "cccccccccccdaaaa",
      "fffffffffffdggff"
    ],
    [
      "                ",
      "                ",
      "                ",
      "                ",
      "                ",
      "                ",
      "                ",
      "hhhhhhhhhhi     ",
      "jjjjjjjjjii kggg",
      "jjjjjjjjjji glmm",
      "  d        d    ",
      "    n   oo dp q ",
      "r  stn ot  du q ",
      "tr  s   o  dw q ",
      "r          d    ",
      "           dggxy"
    ],
    [
      "                ",
      "                ",
      "                ",
      "                ",
      "                ",
      "                ",
      "                ",
      "AAAAAAAAAAi     ",
      "         ii kBCC",
      "          i gD  ",
      "  d        d    ",
      "           d    ",
      "           d    ",
      "           d    ",
      "           d    ",
      "           dggxE"
    ],
    [
      "                ",
      "                ",
      "                ",
      "                ",
      "                ",
      "                ",
      "                ",
      "          i     ",
      "         ii kgCC",
      "          i g   ",
      "  d        d    ",
      "           d    ",
      "           d    ",
      "           d    ",
      "           d    ",
      "           dggxx"
    ],
    [
      "                ",
      "                ",
      "                ",
      "                ",
      "                ",
      "                ",
      "                ",
      "          i     ",
      "FFFFFFFFFii IgCC",
      "          i g   ",
      "  d        d    ",
      "           d    ",
      "           d    ",
      "           d    ",
      "           d    ",
      "           dgggg"
    ],
    [
      "                ",
      "                ",
      "                ",
      "                ",
      "                ",
      "                ",
      "                ",
      "iiiiiiiiiii     ",
      "iiiiiiiiiii kgBg",
      "iiiiiiiiiii BJJJ",
      "KKdKKKKKKKKdJJJJ",
      "KKKKKKKKKKKdJJJJ",
      "KKKKKKKKKKKdJJJJ",
      "KKKKKKKKKKKdJJJJ",
      "KKKKKKKKKKKdJJJJ",
      "KKKKKKKKKKKdgggg"
    ]
  ]
}