{
  "name": "multi_oasiscondo_4_floor9",
  "refpalette": "deceasedcraft:multi_oasiscondo_4/multi_oasiscondo_4_floor9_palette",
  "xsize": 16,
  "zsize": 16,
  "slices": [
    [
      "                ",
      "                ",
      "                ",
      "                ",
      "                ",
      "                ",
      "                ",
      "                ",
      "                ",
      "ab baaaaaaaaaaaa",
      "ccdaaeaaeaaeaaea",
      "ccdaafaaeaafaaea",
      "ccdae@eaeae@eaea",
      "ccdaaaaaaaaaaaaa",
      "ccdaaaaaaaaaaaaa",
      "ggdeehhhhhhhhhhh"
    ],
    [
      "                ",
      "                ",
      "                ",
      "                ",
      "                ",
      "                ",
      "                ",
      "ij              ",
      "jj              ",
      "kj lllllllllllll",
      " mdlneope qdoper",
      " mdrset eruet ew",
      " md exe e exe e ",
      " mdy   A y   B y",
      " md    CD     CD",
      "  deeEEFFEEEEEFF"
    ],
    [
      "                ",
      "                ",
      "                ",
      "                ",
      "                ",
      "                ",
      "                ",
      "Ij              ",
      "jj              ",
      " j lllllllllllll",
      " JdlKeL e  dM e ",
      " Jd NeO e Pe  e ",
      " Jd exe e exe e ",
      " JdQ   R Q   S Q",
      " Jd    TU     TU",
      "  deeEE  EEEEE  "
    ],
    [
      "                ",
      "                ",
      "                ",
      "                ",
      "                ",
      "                ",
      "                ",
      " j              ",
      "jj              ",
      " j lllllllllllll",
      " Jdl e  e  d  e ",
      "  d VeW e Xe! e ",
      " JdYexeYeYexeYeY",
      " Jd             ",
      "  d             ",
      "  deeEEEEEEEEEEE"
    ],
    [
      "                ",
      "                ",
      "                ",
      "                ",
      "                ",
      "                ",
      "                ",
      " j              ",
      "jj              ",
      " j lllllllllllll",
      "  dl e  e  d  e ",
      "  d  e  e  e  e ",
      "  deeeeeeeeeeeee",
      "  d             ",
      "  d             ",
      "  deeeeeeeeeeeee"
    ],
    [
      "                ",
      "                ",
      "                ",
      "                ",
      "                ",
      "                ",
      "                ",
      "jj              ",
      "jj              ",
      "jj lllllllllllll",
      "ZZdlZeZZeZZdZZeZ",
      "ZZdZZeZZeZZeZZeZ",
      "ZZdeeeeeeeeeeeee",
      "ZZdZZZZZZZZZZZZZ",
      "ZZdZZZZZZZZZZZZZ",
      "ZZdeeeeeeeeeeeee"
    ]
  ]
}