{
  "name": "multi_oasiscondo_4_floor3",
  "refpalette": "deceasedcraft:multi_oasiscondo_4/multi_oasiscondo_4_floor3_palette",
  "xsize": 16,
  "zsize": 16,
  "slices": [
    [
      "                ",
      "                ",
      "                ",
      "                ",
      "                ",
      "                ",
      "                ",
      "                ",
      "                ",
      "ab baaaaaab baaa",
      "aacaaaaaaaacaaaa",
      "aacaaaaaaaacaaaa",
      "aacaaaaaaaacaaaa",
      "aacaaaaaaaacaaaa",
      "aacaaaaaaaacaaaa",
      "deceeeeeedeceeee"
    ],
    [
      "                ",
      "                ",
      "                ",
      "                ",
      "                ",
      "                ",
      "                ",
      "                ",
      "ef fegeeeef hgig",
      "je ek lmnoe ekpl",
      " qcr   s  qctu  ",
      "wxceeeem wxceeee",
      " qcy   A  qcB   ",
      "CCcyD  CCCCc D  ",
      " EcFIJ    EcFIJ ",
      "KeceeeeeeLeceeee"
    ],
    [
      "                ",
      "                ",
      "                ",
      "                ",
      "                ",
      "                ",
      "                ",
      "                ",
      "ef heMMMMef hgMM",
      "Ne e  Om oe e   ",
      " PcQ RRS  TcQ   ",
      "  ceeeem   ceeee",
      " Uc   VW   cX   ",
      "CCcY   CCCCc    ",
      "VZc 01    2c345 ",
      "6eceeeeee7eceeee"
    ],
    [
      "                ",
      "                ",
      "                ",
      "                ",
      "                ",
      "                ",
      "                ",
      "                ",
      "ef fgMMMMef heMM",
      " e e  8m 9e e  8",
      "  c#   $   c#   ",
      "  ceeeem   ceeee",
      "  c  V!$   c    ",
      "CCc    CCCCc    ",
      "!%c       %c^&* ",
      "(eceeeeee(eceeee"
    ],
    [
      "                ",
      "                ",
      "                ",
      "                ",
      "                ",
      "                ",
      "                ",
      "                ",
      "eh feMMMMef feMM",
      " e e)))m  e e)))",
      "  c+)))m   c+)))",
      "- ceeeem - ceeee",
      "  c V Vm   c    ",
      "CCc +  CCCCc [  ",
      "V c        c ]{ ",
      "eeceeeeeeeeceeee"
    ],
    [
      "                ",
      "                ",
      "                ",
      "                ",
      "                ",
      "                ",
      "                ",
      "                ",
      "gh heeeeeeh hege",
      "}e e|  }}}e e|  ",
      "}}c}   }}}}c}   ",
      "}}c}}}}}}}}c}}}}",
      "}}c}}}}}}}}c}}}}",
      "}}c}}}}}}}}c}}}}",
      "}}c}}}}}}}}c};}}",
      "eeceeeeeeeeceeee"
    ]
  ]
}