{
  "name": "multi_oasiscondo_4_base1",
  "refpalette": "deceasedcraft:multi_oasiscondo_4/multi_oasiscondo_4_base1_palette",
  "xsize": 16,
  "zsize": 16,
  "slices": [
    [
      "vvvvvvvvvvvvvvvv",
      "HHHHHHHHHHHHHHHH",
      "HHHHHHHHHHHHHHHH",
      "HHHHHHHHHHHHHHHH",
      "HHaHHHHHHHHaHHHH",
      "HHaHHHHHHHHaHHHH",
      "HHaHHHHHHHHaHHHH",
      "HHaHHHHHHHHaHHHH",
      "HHaHHHHHHHHaHHHH",
      "HHaHHHHHHHHaHHHH",
      "HHbHHHHHHHHbHHHH",
      "HHaHHHHHHHHaHHHH",
      "HHHHHHHHHHHHHHHH",
      "HHHHHHHHHHHHHHHH",
      "HHHHHHHHHHHHHHHH",
      "aaaHHHHHHHHaHHHH"
    ],
    [
      "vvvvvvvvvvvvvvvv",
      "                ",
      "                ",
      "                ",
      "cdecdcdcdcdecdcd",
      "  e        e    ",
      "  e    f   e    ",
      "gheghghghgheghgh",
      "cdecdcdcdcdecdcd",
      "  e        e    ",
      "  b        b    ",
      "gheghghghgheghgh",
      "                ",
      "                ",
      "                ",
      "  ec  dc  dec  d"
    ],
    [
      "vvvvvvvvvvvvvvvv",
      "                ",
      "                ",
      "                ",
      "                ",
      "                ",
      "                ",
      "                ",
      "                ",
      "                ",
      "  b        b    ",
      "                ",
      "                ",
      "                ",
      "                ",
      "                "
    ],
    [
      "vvvvvvvvvvvvvvvv",
      "                ",
      "                ",
      "                ",
      "                ",
      "                ",
      "                ",
      "                ",
      "                ",
      "                ",
      "  b        b    ",
      "                ",
      "                ",
      "                ",
      "                ",
      "                "
    ],
    [
      "vvvvvvvvvvvvvvvv",
      "                ",
      "                ",
      "                ",
      "                ",
      "                ",
      "                ",
      "                ",
      "                ",
      "                ",
      "  b        b    ",
      "                ",
      "                ",
      "                ",
      "                ",
      "                "
    ],
    [
      "vvvvvvvvvvvvvvvv",
      "iijiiiiiiiijiiii",
      "iijiiiiiiiijiiii",
      "iijiiiiiiiijiiii",
      "iijiiiiiiiijiiii",
      "iijiiiiiiiijiiii",
      "iijiiiiiiiijiiii",
      "iijiiiiiiiijiiii",
      "iijiiiiiiiijiiii",
      "iijiiiiiiiijiiii",
      "jjkjjjjjjjjkjjjj",
      "iijiiiiiiiijiiii",
      "iijiiiiiiiijiiii",
      "iijiiiiiiiijiiii",
      "iijiiiiiiiijiiii",
      "iijiiiiiiiijiiii"
    ]
  ]
}