{
  "name": "multi_oasiscondo_4_floor1",
  "refpalette": "deceasedcraft:multi_oasiscondo_4/multi_oasiscondo_4_floor1_palette",
  "xsize": 16,
  "zsize": 16,
  "slices": [
    [
      "                ",
      "                ",
      "                ",
      "                ",
      "                ",
      "                ",
      "                ",
      "                ",
      "ab ba           ",
      " a accccccc cccc",
      "  d       cdc   ",
      "  d             ",
      "  de            ",
      "  df            ",
      "  dg            ",
      "  d             "
    ],
    [
      "                ",
      "                ",
      "                ",
      "                ",
      "                ",
      "                ",
      "                ",
      "                ",
      "ab ba           ",
      " a accccccc cccc",
      "  d       cdc   ",
      "  d             ",
      "  d          h h",
      "  di            ",
      "  d            h",
      "  d             "
    ],
    [
      "                ",
      "                ",
      "                ",
      "                ",
      "                ",
      "                ",
      "                ",
      "                ",
      "ab ba           ",
      " a accccccc cccc",
      "  d       cdc   ",
      "  d             ",
      "  d          jhj",
      "  dk            ",
      "  d          h j",
      "  d             "
    ],
    [
      "                ",
      "                ",
      "                ",
      "                ",
      "                ",
      "                ",
      "                ",
      "                ",
      "ab ba           ",
      " a accccccc cccc",
      "  d       cdc   ",
      "  d             ",
      "  d          jjj",
      "  d             ",
      "  d          jhj",
      "  d             "
    ],
    [
      "                ",
      "                ",
      "                ",
      "                ",
      "                ",
      "                ",
      "                ",
      "                ",
      "ab ba           ",
      "la accccccc cccc",
      "  d       cdc   ",
      "  d          mmm",
      "  d         mjjj",
      "  d         mnnn",
      "  d         mjjj",
      "  d          mmm"
    ],
    [
      "                ",
      "                ",
      "                ",
      "                ",
      "                ",
      "                ",
      "                ",
      "                ",
      "ab baaaaaaaaaaaa",
      "aa aaaaaaaaaaaaa",
      "oodoooooooadaooo",
      "oodooooooooooooo",
      "oodooooooooooppp",
      "oodooooooooooppp",
      "oodooooooooooppp",
      "oodooooooooooooo"
    ]
  ]
}