{
  "name": "multi_oasiscondo_4_floor10",
  "refpalette": "deceasedcraft:multi_oasiscondo_4/multi_oasiscondo_4_floor10_palette",
  "xsize": 16,
  "zsize": 16,
  "slices": [
    [
      "                ",
      "                ",
      "                ",
      "                ",
      "                ",
      "                ",
      "                ",
      "                ",
      "                ",
      "ab baaaaaaaaaaaa",
      "aacdddddeddcdedd",
      "aacdddeedeeeddde",
      "aacdeeedddedeede",
      "aacddedddddddeee",
      "aacddddddddddded",
      "ffcggggggggggggg"
    ],
    [
      "                ",
      "                ",
      "                ",
      "                ",
      "                ",
      "                ",
      "                ",
      "   hiiiiiiiiiiii",
      "jk hhlllllllllll",
      "mj hllllllllllll",
      "noc pqrq   cq r ",
      "nscqtu        w ",
      "nscq   qq  t    ",
      "nxc w t  wq     ",
      " ycA q wq q  w  ",
      "BCc             "
    ],
    [
      "                ",
      "                ",
      "                ",
      "                ",
      "                ",
      "                ",
      "                ",
      "   hDDDDDDDDDDDD",
      "jk hh           ",
      "Ej h            ",
      " Fcq w     c    ",
      "  c q           ",
      " Ic     q  A    ",
      "  c   q         ",
      "  c  A          ",
      "JCc             "
    ],
    [
      "                ",
      "                ",
      "                ",
      "                ",
      "                ",
      "                ",
      "                ",
      "   h            ",
      "jK hh           ",
      "Ej h            ",
      "  c        c    ",
      "  c q           ",
      "  c             ",
      "  c   A         ",
      "  c             ",
      "CCc             "
    ],
    [
      "                ",
      "                ",
      "                ",
      "                ",
      "                ",
      "                ",
      "                ",
      "   h            ",
      "jK hhLLLLLLLLLLL",
      "Ej h            ",
      "  c        c    ",
      "  c A           ",
      "  c             ",
      "  c             ",
      "  c             ",
      "jjc             "
    ],
    [
      "                ",
      "                ",
      "                ",
      "                ",
      "                ",
      "                ",
      "                ",
      "   hhhhhhhhhhhhh",
      "jk hhhhhhhhhhhhh",
      "MN hhhhhhhhhhhhh",
      "MMcOOOOOOOOcOOOO",
      "MMcOOOOOOOOOOOOO",
      "MMcOOOOOOOOOOOOO",
      "MMcOOOOOOOOOOOOO",
      "MMcOOOOOOOOOOOOO",
      "jjcOOOOOOOOOOOOO"
    ]
  ]
}