{
  "name": "multi_oasiscondo_4_top",
  "refpalette": "deceasedcraft:multi_oasiscondo_4/multi_oasiscondo_4_top_palette",
  "xsize": 16,
  "zsize": 16,
  "slices": [
    [
      "                ",
      "                ",
      "                ",
      "                ",
      "                ",
      "                ",
      "                ",
      "                ",
      "                ",
      "aaaaaaaaaab baaa",
      "ccdccccccccdaaaa",
      "cccccccccccdaaaa",
      "cccccccccccdaaaa",
      "cccccccccccdaaaa",
      "cccccccccccdaaaa",
      "cccccccccccdaaee"
    ],
    [
      "                ",
      "                ",
      "                ",
      "                ",
      "                ",
      "                ",
      "                ",
      "ffffffffffg     ",
      "hhhhhhhhhgg ieee",
      "hhhhhhhhhhg e   ",
      "jkdljjjjjkmdn op",
      " q qq rs qmdn o ",
      "      q t md  op",
      "       u  mdn o ",
      "          mdn op",
      "          md  ee"
    ],
    [
      "                ",
      "                ",
      "                ",
      "                ",
      "                ",
      "                ",
      "                ",
      "wwwwwwwwwwg     ",
      "         gg iexx",
      "          g e   ",
      " ydAB  C  Dd    ",
      "          Dd  E ",
      "          Dd    ",
      "          Dd    ",
      "          Dd    ",
      "          Dd  ee"
    ],
    [
      "                ",
      "                ",
      "                ",
      "                ",
      "                ",
      "                ",
      "                ",
      "          g     ",
      "         gg iexx",
      "          g e   ",
      "  d        d  FI",
      "           d    ",
      "           d  JI",
      "           d  F ",
      "           d   I",
      "           dKKee"
    ],
    [
      "                ",
      "                ",
      "                ",
      "                ",
      "                ",
      "                ",
      "                ",
      "          g     ",
      "         gg iexx",
      "          g e   ",
      "  d        d   L",
      "           d    ",
      "           d   L",
      "           d    ",
      "           d   L",
      "           deeee"
    ],
    [
      "                ",
      "                ",
      "                ",
      "                ",
      "                ",
      "                ",
      "                ",
      "          g     ",
      "         gg ieee",
      "  M       g eNNN",
      "  d        dNNNN",
      "           dNNNN",
      "           dNNNN",
      "           dNNNN",
      "           dNNNN",
      "           deeee"
    ],
    [
      "                ",
      "                ",
      "                ",
      "                ",
      "                ",
      "                ",
      "                ",
      "          g     ",
      "         gg     ",
      "  O       g baaa",
      "  d        daaaa",
      "           daaaa",
      "           daaaa",
      "           daaaa",
      "           daaaa",
      "      x    deeee"
    ],
    [
      "                ",
      "                ",
      "                ",
      "                ",
      "                ",
      "                ",
      "                ",
      "          g     ",
      "         gg ieee",
      "  P       g eQR ",
      "  d        dS T ",
      "           dUUR ",
      "           dS T ",
      "           dUUR ",
      "           dS T ",
      "           deeee"
    ],
    [
      "                ",
      "                ",
      "                ",
      "                ",
      "                ",
      "                ",
      "                ",
      "          g     ",
      "         gg iexx",
      "          g e R ",
      "  d        d  V ",
      "           dUUR ",
      "           d  V ",
      "           dUUR ",
      "           d  V ",
      "           deeee"
    ],
    [
      "                ",
      "                ",
      "                ",
      "                ",
      "                ",
      "                ",
      "                ",
      "          g     ",
      "         gg iexx",
      "          g eWR ",
      "  d        d  R ",
      "           dUUR ",
      "           d  R ",
      "           dUUR ",
      "           d  R ",
      "           deeee"
    ],
    [
      "                ",
      "                ",
      "                ",
      "                ",
      "                ",
      "                ",
      "                ",
      "          g     ",
      "XXXXXXXXXgg iexx",
      "          g eYR ",
      "  d        dYYR ",
      "           dYYR ",
      "           dYYR ",
      "           dYYR ",
      "           dYYR ",
      "           deeee"
    ],
    [
      "                ",
      "                ",
      "                ",
      "                ",
      "                ",
      "                ",
      "                ",
      "ggggggggggg     ",
      "ggggggggggg ieee",
      "ggggggggggg e NN",
      "ZZdZZZZZZZZd0 NN",
      "ZZZZZZZZZZZd  NN",
      "ZZZZZZZZZZZd0 NN",
      "ZZZZZZZZZZZd  NN",
      "ZZZZZZZZZZZd0 NN",
      "ZZZZZZZZZZZdeeee"
    ],
    [
      "                ",
      "                ",
      "                ",
      "                ",
      "                ",
      "                ",
      "                ",
      "                ",
      "                ",
      "aaaaaaaaaab baaa",
      "1111111111111111",
      "2222222222222222",
      "2222222222222222",
      "2222222222222222",
      "2222222222222222",
      "2222222222222222"
    ],
    [
      "                ",
      "                ",
      "                ",
      "                ",
      "                ",
      "                ",
      "                ",
      "                ",
      "                ",
      "                ",
      "3333333333333333",
      "  4        4    ",
      "  5        5    ",
      "6666666666666666",
      "  7        7    ",
      "898             "
    ],
    [
      "                ",
      "                ",
      "                ",
      "                ",
      "                ",
      "                ",
      "                ",
      "                ",
      "                ",
      "                ",
      "3333333333333333",
      "                ",
      "                ",
      "                ",
      "                ",
      "                "
    ]
  ]
}