{
  "name": "multi_oasiscondo_4_ground",
  "refpalette": "deceasedcraft:multi_oasiscondo_4/multi_oasiscondo_4_ground_palette",
  "xsize": 16,
  "zsize": 16,
  "slices": [
    [
      "abbbbbbbbbbbbbbb",
      "abbbbbbbbbbbbbbb",
      "abcbbbbbbbbbbbbb",
      "abbbbbbbbbaaaaaa",
      "abbbbbbbbbaddddd",
      "abbbbbbbbbaaaaaa",
      "abcbbbbbbbbbbbbb",
      "abbbbbbbbbbbbbbb",
      "ebbbebbbbbbbbbbb",
      "feaeaaaaaaaaaaaa",
      "ffghhhhhhhagahhh",
      "ffghiiiiiihhhhhh",
      "jfghiiiiiihhhhhh",
      "jfghiiiiiihhhhhh",
      "jfghiiiiiihhhhhh",
      "jfghiiiiiihhhhhh"
    ],
    [
      "                ",
      "                ",
      "  k             ",
      "  l       mnnnnn",
      "  l       nooooo",
      "  l       mnnnnn",
      "  k             ",
      "                ",
      "ep pe           ",
      " eqerrrrrrrqrrns",
      "  g tuwwxtrgr  y",
      "  g        A    ",
      "  gB  CC        ",
      "  gD            ",
      "  gE            ",
      "  gt            "
    ],
    [
      "                ",
      "                ",
      "  F             ",
      "                ",
      "                ",
      "                ",
      "  F             ",
      "                ",
      "ep pe           ",
      " e errrrrrr rrn ",
      "  g      Irgr  J",
      "  g        K    ",
      "  g             ",
      "  g             ",
      "  g             ",
      "  g             "
    ],
    [
      "                ",
      "                ",
      "  L             ",
      "                ",
      "                ",
      "                ",
      "  L             ",
      "                ",
      "ep pe           ",
      " e errrrrrr rrnM",
      "  g       rgr  N",
      "  g        O    ",
      "  g             ",
      "  g             ",
      "  g             ",
      "  g             "
    ],
    [
      "                ",
      "                ",
      "  L             ",
      "                ",
      "                ",
      "                ",
      "  L             ",
      "                ",
      "ep pe           ",
      " e errrrrrr rrnn",
      "  g       rgr   ",
      "  g             ",
      "  gP            ",
      "  gQ            ",
      "  gR            ",
      "  g             "
    ],
    [
      "                ",
      "                ",
      "  S             ",
      "                ",
      "                ",
      "                ",
      "  S             ",
      "                ",
      "ep pe           ",
      " e errrrrrr rrrr",
      "  g       rgr   ",
      "  g             ",
      "  gT            ",
      "  gU            ",
      "  gV            ",
      "  g             "
    ]
  ]
}