{
  "name": "multi_oasiscondo_4_base3",
  "refpalette": "deceasedcraft:multi_oasiscondo_4/multi_oasiscondo_4_base3_palette",
  "xsize": 16,
  "zsize": 16,
  "slices": [
    [
      "vvvvvvvvvvvvvvvv",
      "                ",
      "                ",
      "                ",
      "                ",
      "                ",
      "                ",
      "                ",
      "                ",
      "                ",
      "  a        a    ",
      "                ",
      "                ",
      "                ",
      "                ",
      "                "
    ],
    [
      "vvvvvvvvvvvvvvvv",
      "                ",
      "                ",
      "                ",
      "                ",
      "                ",
      "                ",
      "                ",
      "                ",
      "                ",
      "  a        a    ",
      "                ",
      "                ",
      "                ",
      "                ",
      "                "
    ],
    [
      "vvvvvvvvvvvvvvvv",
      "                ",
      "                ",
      "                ",
      "                ",
      "                ",
      "                ",
      "                ",
      "                ",
      "                ",
      "  a        a    ",
      "                ",
      "                ",
      "                ",
      "                ",
      "                "
    ],
    [
      "vvvvvvvvvvvvvvvv",
      "                ",
      "                ",
      "                ",
      "                ",
      "                ",
      "                ",
      "                ",
      "                ",
      "                ",
      "  a        a    ",
      "                ",
      "                ",
      "                ",
      "                ",
      "                "
    ],
    [
      "vvvvvvvvvvvvvvvv",
      "                ",
      "                ",
      "                ",
      "                ",
      "                ",
      "                ",
      "                ",
      "                ",
      "                ",
      "  a        a    ",
      "                ",
      "                ",
      "                ",
      "                ",
      "                "
    ],
    [
      "vvvvvvvvvvvvvvvv",
      "bbcbbbbbbbbcbbbb",
      "bbcbbbbbbbbcbbbb",
      "bbcbbbbbbbbcbbbb",
      "bbcbbbbbbbbcbbbb",
      "bbcbbbbbbbbcbbbb",
      "bbcbbbbbbbbcbbbb",
      "bbcbbbbbbbbcbbbb",
      "bbcbbbbbbbbcbbbb",
      "bbcbbbbbbbbcbbbb",
      "ccdccccccccdcccc",
      "bbcbbbbbbbbcbbbb",
      "bbcbbbbbbbbcbbbb",
      "bbcbbbbbbbbcbbbb",
      "bbcbbbbbbbbcbbbb",
      "bbcbbbbbbbbcbbbb"
    ]
  ]
}