{
  "name": "multi_oasiscondo_4_floor2",
  "refpalette": "deceasedcraft:multi_oasiscondo_4/multi_oasiscondo_4_floor2_palette",
  "xsize": 16,
  "zsize": 16,
  "slices": [
    [
      "                ",
      "                ",
      "                ",
      "                ",
      "                ",
      "                ",
      "                ",
      "                ",
      "                ",
      "ab baaaaaab baaa",
      "aacaaaaaaaacaaaa",
      "aacaaaaaaaacaaaa",
      "aacaaaaaaaacaaaa",
      "aacadaaaaaacaaaa",
      "aacaaaaaaaacaaaa",
      "efcffffffefcffff"
    ],
    [
      "                ",
      "                ",
      "                ",
      "                ",
      "                ",
      "                ",
      "                ",
      "                ",
      "fg hfiffffh hfff",
      "jf fk lmnof pk l",
      " qcrst uw qcrst ",
      "xycffffm ABcffff",
      " qc    C  qc    ",
      "DDc E  DDDDc    ",
      " Fc       IcJKL ",
      "MfcffffffMfcffff"
    ],
    [
      "                ",
      "                ",
      "                ",
      "                ",
      "                ",
      "                ",
      "                ",
      "                ",
      "ig hfNNNNfg hfNN",
      "Of f  Pm of i  Q",
      "  cR S T  UcR   ",
      " Vcffffm W cffff",
      " Xc    Y  Zc000 ",
      "DDc    DDDDc    ",
      " 1c       2c    ",
      "3fcffffff3fcffff"
    ],
    [
      "                ",
      "                ",
      "                ",
      "                ",
      "                ",
      "                ",
      "                ",
      "                ",
      "fh hfNNNNig hfNN",
      " f f  4m 5f f  4",
      "  c6   7   c6   ",
      "  cffffm WWcffff",
      "  c    7   c899#",
      "DDc    DDDDc    ",
      " $c       $c    ",
      "%fcffffff%fcffff"
    ],
    [
      "                ",
      "                ",
      "                ",
      "                ",
      "                ",
      "                ",
      "                ",
      "                ",
      "fh gfNNNNfh hfNN",
      " f f^^^m  f f^^^",
      "  c&^^^m W c&^^^",
      "* cffffmW! cffff",
      "  c    m   c((()",
      "DDc +  DDDDc -  ",
      "  c        c    ",
      "ffcffffffffcffff"
    ],
    [
      "                ",
      "                ",
      "                ",
      "                ",
      "                ",
      "                ",
      "                ",
      "                ",
      "fh gffffffh gfff",
      "[f f]  [[[i f]  ",
      "[[c[   [[[[c[   ",
      "[[c[[[[[[[[c[[[[",
      "[[c[[[[[[[[c[[[[",
      "[[c[[[[[[[[c[[[[",
      "[[c[[[[[[[[c[[[[",
      "ffcffffffffcffff"
    ]
  ]
}