{
  "name": "multi_oasiscondo_4_floor6",
  "refpalette": "deceasedcraft:multi_oasiscondo_4/multi_oasiscondo_4_floor6_palette",
  "xsize": 16,
  "zsize": 16,
  "slices": [
    [
      "                ",
      "                ",
      "                ",
      "                ",
      "                ",
      "                ",
      "                ",
      "                ",
      "                ",
      "ab baaaaaaaaaaaa",
      "aacaaaaaaaaaaaaa",
      "aacaaaaaaaaaaaaa",
      "aacaaaaaaaaaaaaa",
      "aacaaaaaaaaaaaaa",
      "aacaaaaaaaaaaaaa",
      "deceeeeeeeeaeeee"
    ],
    [
      "                ",
      "                ",
      "                ",
      "                ",
      "                ",
      "                ",
      "                ",
      "                ",
      "fg geeefeffhfeee",
      "ie fjklmnnmop  q",
      " rcs  l tt o    ",
      "uwcsxyl AA oeeee",
      " BceCDl    oEFI ",
      "DDc!J K    L    ",
      " McNOOlPQQRoSSS ",
      "Teceeeeeeeeeeeee"
    ],
    [
      "                ",
      "                ",
      "                ",
      "                ",
      "                ",
      "                ",
      "                ",
      "                ",
      "eU UfVVVVVVWVVVV",
      "Xe eY lZ  Xo   0",
      " rc1  l    oY23 ",
      "uwc   l    oeeee",
      " Bce4Dl    o5   ",
      "DDc 6 7    8    ",
      " 9c#OOl $J%o    ",
      "^eceeeeeeeeeeeee"
    ],
    [
      "                ",
      "                ",
      "                ",
      "                ",
      "                ",
      "                ",
      "                ",
      "                ",
      "eg geVVVVVVWVVVV",
      " f e& l    o   *",
      "  c(  l    o&   ",
      "  c)  l    oeeee",
      " +ce-Dl    o    ",
      "DDce  [    ]    ",
      " {ce}}l J  o    ",
      "|eceeeeeeeeeeeee"
    ],
    [
      "                ",
      "                ",
      "                ",
      "                ",
      "                ",
      "                ",
      "                ",
      "                ",
      "eU UeVVVVVVWVVVV",
      " h e; l    o :::",
      "  c:::l;  ;o':::",
      "< c:::l    oeeee",
      "  ceDDl    o    ",
      "DDce' l'  ;o <  ",
      "  ce>>l    o    ",
      "eeceeeeeeeeeeeee"
    ],
    [
      "                ",
      "                ",
      "                ",
      "                ",
      "                ",
      "                ",
      "                ",
      "                ",
      "eU ,fffeeeeeeeee",
      ".h f.........?  ",
      "..c?  .......   ",
      "..c   ..........",
      "..c.............",
      "..c.............",
      "..c.............",
      "eeceeeeeeeeeeeee"
    ]
  ]
}