{
  "name": "multi_oasiscondo_4_floor7",
  "refpalette": "deceasedcraft:multi_oasiscondo_4/multi_oasiscondo_4_floor7_palette",
  "xsize": 16,
  "zsize": 16,
  "slices": [
    [
      "                ",
      "                ",
      "                ",
      "                ",
      "                ",
      "                ",
      "                ",
      "                ",
      "                ",
      "ab baaaaaaaaaaaa",
      "aacaaaaaaaaaaaaa",
      "aacaaaaaaaaaaaaa",
      "aacaaaaaaaaaaaaa",
      "aacaaaaaaaaaaaaa",
      "aacaaaaaaaaaaaaa",
      "deceeeeeeeeaeeee"
    ],
    [
      "                ",
      "                ",
      "                ",
      "                ",
      "                ",
      "                ",
      "                ",
      "                ",
      "fg geeeefeeeeeff",
      "he ei jklhmn   o",
      " pc!qrj s  j tu!",
      "wxcyq jA   jeeee",
      " pcyq jBCD E    ",
      "FFcyq jFFFFF    ",
      " IcyJKL         ",
      "Meceeeeeeeeeeeee"
    ],
    [
      "                ",
      "                ",
      "                ",
      "                ",
      "                ",
      "                ",
      "                ",
      "                ",
      "fg gfNNNNNNONNNN",
      "Pe eQ jRS  T    ",
      " UcVW j    jX  K",
      "  cVY jA   jeeee",
      " ZcV0 jBCD12 34 ",
      "FFcVK jFFFFF    ",
      " 5cV6 7         ",
      "8eceeeeeeeeeeeee"
    ],
    [
      "                ",
      "                ",
      "                ",
      "                ",
      "                ",
      "                ",
      "                ",
      "                ",
      "e9 9eNNNNNNONNNN",
      " e e  j    #   $",
      "  cV  j    j%   ",
      "  cV  j    jeeee",
      "  cV  j  ^ & *( ",
      "FFcV  jFFFFF    ",
      " )cV  &         ",
      "+eceeeeeeeeeeeee"
    ],
    [
      "                ",
      "                ",
      "                ",
      "                ",
      "                ",
      "                ",
      "                ",
      "                ",
      "eg 9fNNNNNNONNNN",
      " f f  j    j----",
      "  cV [j    j----",
      "] cV  j  ] jeeee",
      "  cV  j    j[  [",
      "FFcV {jFFFFF    ",
      "  cV  j{        ",
      "eeceeeeeeeeeeeee"
    ],
    [
      "                ",
      "                ",
      "                ",
      "                ",
      "                ",
      "                ",
      "                ",
      "                ",
      "f9 9eefeeeffeefe",
      "}e e}}}}}}}}}|  ",
      "}}c}}}}}}}}}}   ",
      "}}c}}}}}}}}}}}}}",
      "}}c}}}}}}}}}}}}}",
      "}}c}}}}}}}}}}}}}",
      "}}c}}}}}}}}}}}}}",
      "eeceeeeeeeeeeeee"
    ]
  ]
}