{
  "name": "multi_oasiscondo_4_floor5",
  "refpalette": "deceasedcraft:multi_oasiscondo_4/multi_oasiscondo_4_floor5_palette",
  "xsize": 16,
  "zsize": 16,
  "slices": [
    [
      "                ",
      "                ",
      "                ",
      "                ",
      "                ",
      "                ",
      "                ",
      "                ",
      "                ",
      "ab baaaaaab baaa",
      "aacaaaaaaaacaaaa",
      "aacaaaaaaaacaaaa",
      "aacaaaaaaaacaaaa",
      "aacaaaaaaaacaaaa",
      "aacadaaaaaacaaaa",
      "efcffffffefcffff"
    ],
    [
      "                ",
      "                ",
      "                ",
      "                ",
      "                ",
      "                ",
      "                ",
      "   ghhhhhhg     ",
      "fi ggjjjjgg kffl",
      "mf g      g lnop",
      "qrcs  tuw xcyA  ",
      "BCcfDfEEEFIcffff",
      " rcn fJKJ LcMN  ",
      "OOcPQf R  Sc T  ",
      " UcVWfw   UcXYZ0",
      "1fcffffff1fcffff"
    ],
    [
      "                ",
      "                ",
      "                ",
      "                ",
      "                ",
      "                ",
      "                ",
      "   g222222g     ",
      "f3 gg 4 4gg kf55",
      "mf g      g 6   ",
      " 7cs    8 9cA#  ",
      "  cf$fmmm%^cffff",
      " &c  f* ( )c    ",
      "OOc +f    Sc    ",
      " -c[!f]    c{}| ",
      ";fcffffff;fcffff"
    ],
    [
      "                ",
      "                ",
      "                ",
      "                ",
      "                ",
      "                ",
      "                ",
      "   g      g     ",
      "li gg4444gg 3l55",
      "ml g      g f  :",
      "  c'       c<   ",
      "! cf>fmmm% cffff",
      "  c  f     c    ",
      "OOc  f    Sc    ",
      " ,c.?f    ,c/// ",
      "`fcffffff`fcffff"
    ],
    [
      "                ",
      "                ",
      "                ",
      "                ",
      "                ",
      "                ",
      "                ",
      "   g      g     ",
      "f3 gg\u0370\u0370\u0370\u0370gg if55",
      "9l g      g l\u0371\u0371\u0371",
      "  c\u0372      \u0373c\u0372\u0371\u0371\u0371",
      "\u0374 cfffmmm\u0375\u0373cffff",
      "  c\u0371\u0371f    \u0373c    ",
      "OOc\u0371\u0371f \u0376  Sc \u0377  ",
      "  c\u0371\u0371f     c|\u037a0 ",
      "ffcffffffffcffff"
    ],
    [
      "                ",
      "                ",
      "                ",
      "                ",
      "                ",
      "                ",
      "                ",
      "   gggggggg     ",
      "f3 gggggggg 3lff",
      "\u037bf g\u037b\u037b\u037b\u037b\u037b\u037bg f\u037c  ",
      "\u037b\u037bc\u037b\u037b\u037b\u037b\u037b\u037b\u037b\u037bc\u037b   ",
      "\u037b\u037bc\u037b\u037b\u037b\u037b\u037b\u037b\u037b\u037bc\u037b\u037b\u037b\u037b",
      "\u037b\u037bc  \u037b\u037b\u037b\u037b\u037b\u037bc\u037b\u037b\u037b\u037b",
      "\u037b\u037bc  \u037b\u037b\u037b\u037b\u037b\u037bc\u037b\u037b\u037b\u037b",
      "\u037b\u037bc\u037c \u037b\u037b\u037b\u037b\u037b\u037bc\u037b\u037b\u037b\u037b",
      "ffcffffffffcffff"
    ]
  ]
}