{
  "name": "multi_oasiscondo_4_base2",
  "refpalette": "deceasedcraft:multi_oasiscondo_4/multi_oasiscondo_4_base2_palette",
  "xsize": 16,
  "zsize": 16,
  "slices": [
    [
      "vvvvvvvvvvvvvvvv",
      "HHHHHHHHHHHHHHHH",
      "HHHHHHHHHHHHHHHH",
      "HHHHHHHHHHHHHHHH",
      "HHaHHHHHHHHaHHHH",
      "HHaHHHHHHHHaHHHH",
      "HHaHHHHHHHHaHHHH",
      "HHaHHHHHHHHaHHHH",
      "HHaHHHHHHHHaHHHH",
      "HHaHHHHHHHHaHHHH",
      "HHbHHHHHHHHbHHHH",
      "HHaHHHHHHHHaHHHH",
      "HHHHHHHHHHHHHHHH",
      "HHHHHHHHHHHHHHHH",
      "HHHHHHHHHHHHHHHH",
      "aaaHHHHHHHHaHHHH"
    ],
    [
      "vvvvvvvvvvvvvvvv",
      "                ",
      "                ",
      "                ",
      "cdecdcdcdcdecdcd",
      "  e        e    ",
      "  e        e    ",
      "fgefgfgfgfgefgfg",
      "cdecdcdcdcdecdcd",
      "  e        e    ",
      "  b        b    ",
      "fgefgfgfgfgefgfg",
      "                ",
      "                ",
      "                ",
      "  ec  dc  dec  d"
    ],
    [
      "vvvvvvvvvvvvvvvv",
      "                ",
      "                ",
      "                ",
      "                ",
      "                ",
      "                ",
      "                ",
      "                ",
      "                ",
      "  b        b    ",
      "                ",
      "                ",
      "                ",
      "                ",
      "                "
    ],
    [
      "vvvvvvvvvvvvvvvv",
      "                ",
      "                ",
      "                ",
      "                ",
      "                ",
      "                ",
      "                ",
      "                ",
      "                ",
      "  b        b    ",
      "                ",
      "                ",
      "                ",
      "                ",
      "                "
    ],
    [
      "vvvvvvvvvvvvvvvv",
      "                ",
      "                ",
      "                ",
      "                ",
      "                ",
      "                ",
      "                ",
      "                ",
      "                ",
      "  b        b    ",
      "                ",
      "                ",
      "                ",
      "                ",
      "                "
    ],
    [
      "vvvvvvvvvvvvvvvv",
      "hhihhhhhhhhihhhh",
      "hhihhhhhhhhihhhh",
      "hhihhhhhhhhihhhh",
      "hhihhhhhhhhihhhh",
      "hhihhhhhhhhihhhh",
      "hhihhhhhhhhihhhh",
      "hhihhhhhhhhihhhh",
      "hhihhhhhhhhihhhh",
      "hhihhhhhhhhihhhh",
      "iijiiiiiiiijiiii",
      "hhihhhhhhhhihhhh",
      "hhihhhhhhhhihhhh",
      "hhihhhhhhhhihhhh",
      "hhihhhhhhhhihhhh",
      "hhihhhhhhhhihhhh"
    ]
  ]
}