{
  "name": "multi_oasiscondo_4_floor4",
  "refpalette": "deceasedcraft:multi_oasiscondo_4/multi_oasiscondo_4_floor4_palette",
  "xsize": 16,
  "zsize": 16,
  "slices": [
    [
      "                ",
      "                ",
      "                ",
      "                ",
      "                ",
      "                ",
      "                ",
      "                ",
      "                ",
      "ab baaaaaab baaa",
      "aacaaaaaaaacaaaa",
      "aacaaaaaaaacaaaa",
      "aacaaaaaaaacaaaa",
      "aacaaaaaaaacaaaa",
      "aacaaaaaaaacaaaa",
      "deceeeeeedeceeee"
    ],
    [
      "                ",
      "                ",
      "                ",
      "                ",
      "                ",
      "                ",
      "                ",
      "   fggggggf     ",
      "eh ffiiiiff heee",
      "je fk lmnof ep q",
      " rcs tu w rcxyA ",
      "BCceDeE  FIceeee",
      " rcp eJ   rcKLM ",
      "NNcOPeQ RNNc    ",
      " ScTUeV   ScWXY ",
      "ZeceeeeeeZeceeee"
    ],
    [
      "                ",
      "                ",
      "                ",
      "                ",
      "                ",
      "                ",
      "                ",
      "   f000000f     ",
      "e1 ff2   ff he33",
      " 4 f      f e   ",
      " 5cs  6    c7   ",
      "  ce8e9    ceeee",
      " #c  e$    c    ",
      "NNc  e% RNNc    ",
      " ^c&*e    (c ) +",
      "-eceeeeee-eceeee"
    ],
    [
      "                ",
      "                ",
      "                ",
      "                ",
      "                ",
      "                ",
      "                ",
      "   f      f     ",
      "e[ ff22  ff he33",
      " 4 f      f e  ]",
      "  c{       c}   ",
      "  ce|e     ceeee",
      "  c  e;    c    ",
      "NNc  e: RNNc    ",
      " 'c<+e>   'c,.?$",
      "/eceeeeee/eceeee"
    ],
    [
      "                ",
      "                ",
      "                ",
      "                ",
      "                ",
      "                ",
      "                ",
      "   f      f     ",
      "e1 ff````ff 1e33",
      " e f      f e\u0370\u0370\u0370",
      "  c\u0371       c\u0371\u0370\u0370\u0370",
      "\u0372 ceee  \u0372  ceeee",
      "  c\u0370\u0370e\u0373    c    ",
      "NNc\u0370\u0370e\u0374 RNNc \u0375  ",
      "  c\u0370\u0370e\u0376    c\u0377 \u037a\u0373",
      "eeceeeeeeeeceeee"
    ],
    [
      "                ",
      "                ",
      "                ",
      "                ",
      "                ",
      "                ",
      "                ",
      "   ffffffff     ",
      "4h ffffffff 14ee",
      "\u037be f\u037b\u037b\u037b\u037b\u037b\u037bf e\u037c  ",
      "\u037b\u037bc\u037b\u037b\u037b\u037b\u037b\u037b\u037b\u037bc\u037b   ",
      "\u037b\u037bc\u037b\u037b\u037b\u037b\u037b\u037b\u037b\u037bc\u037b\u037b\u037b\u037b",
      "\u037b\u037bc  \u037b\u037b\u037b\u037b\u037b\u037bc\u037b\u037b\u037b\u037b",
      "\u037b\u037bc  \u037b\u037b\u037b\u037b\u037b\u037bc\u037b\u037b\u037b\u037b",
      "\u037b\u037bc\u037c \u037b\u037b\u037b\u037b\u037b\u037bc\u037b\u037b\u037b\u037b",
      "eeceeeeeeeeceeee"
    ]
  ]
}