{
  "name": "multi_nuclearpowerplant_36_base11",
  "refpalette": "deceasedcraft:multi_nuclearpowerplant_36/multi_nuclearpowerplant_36_base11_palette",
  "xsize": 16,
  "zsize": 16,
  "slices": [
    [
      "aaaaaaaaaaaaaaaa",
      "bbbbbbcaaaaaaaaa",
      "ddeaaaaaaaaaaaaa",
      "ddeaaaaaaaaaaaaa",
      "ddeaaaaaaaaaaaaa",
      "bbbbbbfaaaaaaaaa",
      "aaaaaaaaaaaaaaaa",
      "aaaaaaaaaaaaaaaa",
      "gaaaaaaaaaaaaaaa",
      "ahiajhahiakhahia",
      "ajlaliajlaliajla",
      "aaaaaaaaaaaaaaaa",
      "ahiajhahiajhahia",
      "ajlaliajlaliajla",
      "aaaaaaaaaaaaaaaa",
      "ajhahiajhahiajha"
    ],
    [
      "aaaaaaaaaaaaaaaa",
      "bbbbbbcaaaaaaaaa",
      "ddeaaaaaaaaaaaaa",
      "ddeaaaaaaaaaaaaa",
      "ddeaaaaaaaaaaaaa",
      "bbbbbbfaaaaaaaaa",
      "aaaaaaaaaaaaaaaa",
      "aaaaaaaaaaaaaaaa",
      "gaaaaaaaaaaaaaaa",
      "ajhahiajhahiajha",
      "almajlaliajlalia",
      "aaaaaaaaaaaaaaaa",
      "ajha!iajhahiajha",
      "aliajnaliajlalia",
      "aaaaaaaaaaaaaaaa",
      "ahiajhahiajhahia"
    ],
    [
      "aaaaaaaaaaaaaaaa",
      "bbbbbbcaaaaaaaaa",
      "bbbaaabaaaaaaaaa",
      "bbbaaabaaaaaaaaa",
      "bbbaaabaaaaaaaaa",
      "bbbbbbfaaaaaaaaa",
      "aaaaaaaaaaaaaaaa",
      "aaaaaaaaaaaaaaaa",
      "gaaaaaaaaaaaaaaa",
      "ahiahiahiajhahia",
      "amlajlajlaliajla",
      "aaaaaaaaaaaaaaaa",
      "ahiajhahiajhaaaa",
      "ajlaliajlaliaaaa",
      "aaaaaaaaaaaaaaaa",
      "ajhahiajhahiaoha"
    ],
    [
      "aaaaaaaaaaaaaaaa",
      "bbbbbbcaaaaaaaaa",
      "ddpqqqbaaaaaaaaa",
      "ddpqqqbaaaaaaaaa",
      "ddpqqqbaaaaaaaaa",
      "bbbbbbfaaaaaaaaa",
      "aaaaaaaaaaaaaaaa",
      "aaaaaaaaaaaaaaaa",
      "gaaaaaaaaaaaaaaa",
      "aaaaaaaaaaaaaaaa",
      "aaaaaaaaaaaaaaaa",
      "aaaaaaaaaaaaaaaa",
      "aaaaaaaaaaaaaaaa",
      "aaaaaaaaaaaaaaaa",
      "aaaaaaaaaaaaaaaa",
      "aaaaaaaaaaaaaaaa"
    ],
    [
      "aaaaaaaaaaaaaaaa",
      "cccbbbcaaaaaaaaa",
      "bbraaabaaaaaaaaa",
      "bbraaabaaaaaaaaa",
      "bbraaabaaaaaaaaa",
      "fffbbbfaaaaaaaaa",
      "aaaaaaaaaaaaaaaa",
      "aaaaaaaaaaaaaaaa",
      "gaaaaaaaaaaaaaaa",
      "aaaaaaaaaaaaaaaa",
      "aaaaaaaaaaaaaaaa",
      "aaaaaaaaaaaaaaaa",
      "aaaaaaaaaaaaaaaa",
      "aaaaaaaaaaaaaaaa",
      "aaaaaaaaaaaaaaaa",
      "aaaaaaaaaaaaaaaa"
    ],
    [
      "aaaaaaaaaaaaaaaa",
      "aacbbbcaaaaaaaaa",
      "aabaaabaaaaaaaaa",
      "aabaaabaaaaaaaaa",
      "aabaaabaaaaaaaaa",
      "aafbbbfaaaaaaaaa",
      "aaaaaaaaaaaaaaaa",
      "aaaaaaaaaaaaaaaa",
      "gaaaaaaaaaaaaaaa",
      "aaaaaaaaaaaaaaaa",
      "aaaaaaaaaaaaaaaa",
      "aaaaaaaaaaaaaaaa",
      "aaaaaaaaaaaaaaaa",
      "aaaaaaaaaaaaaaaa",
      "aaaaaaaaaaaaaaaa",
      "aaaaaaaaaaaaaaaa"
    ]
  ]
}