{
  "name": "multi_nuclearpowerplant_36_base1",
  "refpalette": "deceasedcraft:multi_nuclearpowerplant_36/multi_nuclearpowerplant_36_base1_palette",
  "xsize": 16,
  "zsize": 16,
  "slices": [
    [
      "===abcc        c",
      "===caa         a",
      "===ac          c",
      "==bac           ",
      "==add           ",
      "==bc            ",
      "===cc          c",
      "===aac         c",
      "===bcc         a",
      "e===aac     ccab",
      "fe==baccc cccaa=",
      "fee===aaccaacb==",
      "gfee==bcaab=b===",
      "gfeee==b========",
      "ggfeee==========",
      "ggfeeee========="
    ],
    [
      "eeehhi          ",
      "eehj            ",
      "eeeh            ",
      "eeh             ",
      "eh              ",
      "ehj             ",
      "heh             ",
      "ehej            ",
      "eeeh            ",
      "eeehj          j",
      "feehhj       jhe",
      "feeeehjj   ijjhe",
      "gfeeeehijj jhhee",
      "gfeeeeehehhheeee",
      "ggfeeeeeeeheeeee",
      "ggfeeeeeeeeeeeee"
    ],
    [
      "ehhi            ",
      "ehe             ",
      "ehi             ",
      "ej              ",
      "ei              ",
      "hj              ",
      "hj              ",
      "ehi             ",
      "ehe             ",
      "eehj            ",
      "feeei         jj",
      "feeeji        jh",
      "gfeehhj     jhhe",
      "gfeeeeeehjiiheee",
      "ggfeeeeeehhhheee",
      "ggfeeeeeeeeeheee"
    ],
    [
      "eej             ",
      "eh              ",
      "hj              ",
      "h               ",
      "j               ",
      "e               ",
      "h               ",
      "ej              ",
      "eh              ",
      "eej             ",
      "feej            ",
      "feej           j",
      "gfehj        jhh",
      "gfehehhj    jhee",
      "ggfeeeehjhjhheee",
      "ggfeeeeeeeeeeeee"
    ],
    [
      "ej              ",
      "jk              ",
      "                ",
      "                ",
      "                ",
      "i               ",
      "j               ",
      "h               ",
      "ej              ",
      "ehi             ",
      "fei             ",
      "feh             ",
      "gfei           j",
      "gfhjji        jh",
      "ggfeeeehi  jehee",
      "ggfeeeeehjjeeeee"
    ],
    [
      "                ",
      "                ",
      "                ",
      "                ",
      "                ",
      "                ",
      "                ",
      "z               ",
      "j               ",
      "e               ",
      "fh              ",
      "fej             ",
      "gfe             ",
      "gfez            ",
      "ggfeijz      ije",
      "ggfeheej   hhjee"
    ]
  ]
}