{
  "name": "multi_nuclearpowerplant_36_base5",
  "refpalette": "deceasedcraft:multi_nuclearpowerplant_36/multi_nuclearpowerplant_36_base5_palette",
  "xsize": 16,
  "zsize": 16,
  "slices": [
    [
      "        abcbcbcb",
      "   ddd  acbcbcbc",
      "  d   d abcbcbcb",
      "e d   d acbcbcbc",
      "eed     abcbcbcb",
      " eed    acbcbcbc",
      "  ee    abcbcbcb",
      "   ee   faaaaaaa",
      "    eg          ",
      "     eg         ",
      "      ee        ",
      "d      eg       ",
      "=d      ee      ",
      " =d      eg     ",
      "  =d      ee    ",
      "   =d      ee   "
    ],
    [
      "        abcbcbcb",
      "   ddd  acbchcbc",
      "  d   d ahchchcb",
      "e d     achihcbc",
      "eed     abcbchcb",
      " eed    achjbcbc",
      "  ee    ajkbcbcb",
      "   ee   la aaaaa",
      "    eg          ",
      "     eh         ",
      "      eg        ",
      "d      ee       ",
      "=d      eg      ",
      " =d      ee     ",
      "  =d      ee    ",
      "   =d      ee   "
    ],
    [
      "        abcbkhcb",
      "   ddd  acbjmjbc",
      "  d   d ahjjkhcb",
      "e d     akj jcbc",
      "eed     abkhjncb",
      " eedd   akhmhkhc",
      "  ee      khchcb",
      "   eg   l  a aaa",
      "    ee          ",
      "     eh         ",
      "      ee        ",
      "d      eg       ",
      "=d      eg      ",
      " =d      ee     ",
      "  =d      eg    ",
      "   =d      ee   "
    ],
    [
      "        ahcbjhcb",
      "   ooo  acpq jbk",
      "  o      hmjrhkb",
      "e o     aj~ jjbc",
      "eeo     ahjjstqb",
      " eeooo   jh qmhc",
      "  eg      jhcukb",
      "   ee   l    aa ",
      "    eg          ",
      "     eh         ",
      "      eg        ",
      "d      eh       ",
      "=d      eg      ",
      " =d      ee     ",
      "  =d      ee    ",
      "   =d      ee   "
    ],
    [
      "        ahjbkhch",
      "        akwj khj",
      "         hj  jmj",
      "e        k    jc",
      "ee      a kj  jb",
      " ee       j hjbc",
      "  eg        kwkh",
      "   eg        a  ",
      "    eh          ",
      "     eh         ",
      "      eh        ",
      "d      eh       ",
      "=d      eh      ",
      " =d      eg     ",
      "  =d      ee    ",
      "   =d      ee   "
    ],
    [
      "        ahjkjhkh",
      "         j    hr",
      "               h",
      "e              j",
      "eg            kb",
      " eg          jbc",
      "  eg        j ch",
      "   eh           ",
      "    eh          ",
      "     eh         ",
      "      eg        ",
      "d      gh       ",
      "=d      eh      ",
      " =d      eg     ",
      "  =d      ee    ",
      "   =d      eg   "
    ]
  ]
}