{
  "name": "multi_nuclearpowerplant_36_base9",
  "refpalette": "deceasedcraft:multi_nuclearpowerplant_36/multi_nuclearpowerplant_36_base9_palette",
  "xsize": 16,
  "zsize": 16,
  "slices": [
    [
      "                ",
      "  abbba         ",
      "  bcccb         ",
      "  bcccb         ",
      "  bcccb         ",
      "  dbbbd         ",
      "                ",
      "                ",
      "                ",
      "                ",
      "                ",
      "                ",
      "                ",
      "                ",
      "                ",
      "                "
    ],
    [
      "                ",
      "  abbba         ",
      "  bcccb         ",
      "  bcccb         ",
      "  bcccb         ",
      "  dbbbd         ",
      "                ",
      "                ",
      "                ",
      "                ",
      "                ",
      "                ",
      "                ",
      "                ",
      "                ",
      "                "
    ],
    [
      "                ",
      "  abbba         ",
      "  bcccb         ",
      "  bcccb         ",
      "  bcccb         ",
      "  dbbbd         ",
      "                ",
      "                ",
      "                ",
      "                ",
      "                ",
      "                ",
      "                ",
      "                ",
      "                ",
      "                "
    ],
    [
      "            e   ",
      "  abbba     e   ",
      "  bcccb    fef  ",
      "  bcccbghhhiejhh",
      "  bcccb    fef  ",
      "  dbbbd     e   ",
      "    k       e   ",
      "    e       e   ",
      "    e       e   ",
      "    e       e   ",
      "    e       e   ",
      "    e       e   ",
      "    l      fef  ",
      "hhhhhhhhhhhiejhh",
      "    m      fef  ",
      "    e       e   "
    ],
    [
      "    n       n   ",
      "  abbba    onp  ",
      "  bcccb   qnnnp ",
      "nnbcccbnnnnnrnnn",
      "  bcccb   snnnt ",
      "  dbbbd    unt  ",
      "    n       n   ",
      "    n       n   ",
      "    n       n   ",
      "    n       n   ",
      "    n       n   ",
      "    n      onp  ",
      "    n     onnnp ",
      "nnnnnnnnnnnnrnnn",
      "    n     unnnt ",
      "    n      snw  "
    ],
    [
      "                ",
      "  abbba         ",
      "  bcccb    nxn  ",
      "  bcccb    xyx  ",
      "  bcccb    nxn  ",
      "  dbbbd         ",
      "                ",
      "                ",
      "                ",
      "                ",
      "                ",
      "                ",
      "    A      nxn  ",
      "   BnC     xyx  ",
      "    D      nxn  ",
      "                "
    ]
  ]
}