{
  "name": "multi_nuclearpowerplant_36_base6",
  "refpalette": "deceasedcraft:multi_nuclearpowerplant_36/multi_nuclearpowerplant_36_base6_palette",
  "xsize": 16,
  "zsize": 16,
  "slices": [
    [
      "         a     a",
      "   bbb          ",
      "  b   b         ",
      "c b   b         ",
      "ccb   b         ",
      " ccbbb          ",
      "  cc     a     a",
      "   cc   d       ",
      "    cc          ",
      "     cc         ",
      "      cc        ",
      "b      cc       ",
      "=b      cc      ",
      "e=b      fc     ",
      "ee=b      cc    ",
      "eee=b      cc   "
    ],
    [
      "         a     a",
      "   bbb          ",
      "  b   b         ",
      "c b   b         ",
      "ccb   b         ",
      " ccbbb          ",
      "  cc     a     a",
      "   cc   d       ",
      "    cc          ",
      "     cc         ",
      "      cc        ",
      "b      cc       ",
      "=b      cc      ",
      " =b      cc     ",
      "  =b      cc    ",
      "   =b      cc   "
    ],
    [
      "ggggggggga     a",
      "   bbb          ",
      "  b   b         ",
      "c b   b         ",
      "ccb   b         ",
      " ccbbb          ",
      "  ccggggga     a",
      "   cc   dh     h",
      "    cc   h     h",
      "     cc  h     h",
      "      cc h     h",
      "b      cch     h",
      "=b      cc     h",
      " =b      cc    h",
      "  =b      cc   h",
      "   =b      cc  h"
    ],
    [
      "        hiiii ii",
      "   bbb  hi     i",
      "  b   b hi    ii",
      "c b   b hii    i",
      "ccb   b h    i i",
      " ccbbb  hi  iiii",
      "  cc    hii iiii",
      "   cc   dggggggg",
      "    cc          ",
      "     cc         ",
      "      cc        ",
      "b      cc       ",
      "=b      cc      ",
      " =b      cc     ",
      "  =b      cc    ",
      "   =b      cc   "
    ],
    [
      "        djkjkjkj",
      "   bbb  dkj jkjk",
      "  b   b djkjkjkj",
      "c b   b dkjkj jk",
      "ccb     dj j jkj",
      " ccbbb  dkjkjkjk",
      "  cc    djkjkjkj",
      "   cc   dddddddd",
      "    cc          ",
      "     cf         ",
      "      cc        ",
      "b      cc       ",
      "=b      cc      ",
      " =b      cc     ",
      "  =b      cc    ",
      "   =b      cc   "
    ],
    [
      "        llllllll",
      "   bbb  llllllll",
      "  b   b llllllll",
      "c b   b llllllll",
      "ccb     llllllll",
      " ccb b  llllllll",
      "  cc    llllllll",
      "   cc   llllllll",
      "    cc          ",
      "     cf         ",
      "      cc        ",
      "b      cf       ",
      "=b      cc      ",
      " =b      cc     ",
      "  =b      cc    ",
      "   =b      cc   "
    ]
  ]
}