{
  "name": "multi_nuclearpowerplant_36_base7",
  "refpalette": "deceasedcraft:multi_nuclearpowerplant_36/multi_nuclearpowerplant_36_base7_palette",
  "xsize": 16,
  "zsize": 16,
  "slices": [
    [
      "aaaaaaaaaaaabaaa",
      "aaacccaaaaaaaaba",
      "aac   caaaabbbaa",
      "dac   caaabbbbba",
      "ddc   caaaabbbaa",
      " ddcccaaababbbba",
      "  ddaaaaaaaabbaa",
      "   ddaaa aaaaaaa",
      "    ddaaaaaaaaaa",
      "     ddaaaaaaaaa",
      "      ddaaaaaaaa",
      "c      ddaaaaaaa",
      "=c      ddaaaaaa",
      " =c      ddaaaaa",
      "  =c      ddaaaa",
      "   =c      ddaaa"
    ],
    [
      "aabaabbbaebbbbbe",
      "aaacccabbbbbbbbb",
      "aac   cabbbbbbbb",
      "dac   cbbbbbbbbb",
      "ddc   cbbbbbbbbb",
      " ddcccabbbbbbbbb",
      "  ddbabbbebbbbbe",
      "   ddaab@abbbbbb",
      "    ddbaabbbbbba",
      "     ddbbbabbabb",
      "      ddbaababbb",
      "c      fdbaabaaa",
      "=c      ddaaaaab",
      " =c      ddabaaa",
      "  =c      ddaaaa",
      "   =c      ddbaa"
    ],
    [
      "g   h    e     e",
      "   ccc          ",
      "  c   c         ",
      "d c   cc        ",
      "ddc   c         ",
      " ddccch         ",
      "  fd     e     e",
      "   dd i j       ",
      "    dd          ",
      "     df      cc ",
      "      dfk lm  c ",
      "c      df c     ",
      "=c      ff k l  ",
      " =c      dfh    ",
      "  =c      dd    ",
      "   =c      df   "
    ],
    [
      "         e     e",
      "   ccc          ",
      "  c   c         ",
      "d c   c         ",
      "ddc   c         ",
      " ddccc          ",
      "  dd     e     e",
      "   df   j       ",
      "    ff          ",
      "     df         ",
      "      ff        ",
      "c      df       ",
      "=c      fd      ",
      " =c      ffh    ",
      "  =c      dd    ",
      "   =c      dd   "
    ],
    [
      "         e     e",
      "   ccc          ",
      "  c   c         ",
      "d c   c         ",
      "ddc   c         ",
      " ddccc          ",
      "  dd     e     e",
      "   dd   j       ",
      "    ff          ",
      "     dd         ",
      "      df        ",
      "c      ff       ",
      "=c      fd      ",
      " =c      df     ",
      "  =c      dd    ",
      "   =c      dd   "
    ],
    [
      "         e     e",
      "   ccc          ",
      "  c   c         ",
      "d c   c         ",
      "ddc   c         ",
      " ddccc          ",
      "  dd     e     e",
      "   dd   j       ",
      "    dd          ",
      "     dd         ",
      "      dd        ",
      "c      ff       ",
      "=c      dd      ",
      "n=c      fd     ",
      "nn=c      dd    ",
      "nnn=c      fd   "
    ]
  ]
}