{
  "name": "multi_nuclearpowerplant_36_base12",
  "refpalette": "deceasedcraft:multi_nuclearpowerplant_36/multi_nuclearpowerplant_36_base12_palette",
  "xsize": 16,
  "zsize": 16,
  "slices": [
    [
      "aaaaaaaaaaaaaaaa",
      "aaaaaaaaaaaaaaaa",
      "aaaaaaaaaaaaaaaa",
      "aaaaaaaaaaaaaaaa",
      "aaaaaaaaaaaaaaaa",
      "aaaaaaaaaaaaaaaa",
      "aaaaaaaaaaaaaaaa",
      "aaaaaaaaaaaaaaaa",
      "aaaaaaaaaaaaaaaa",
      "aaaaaaaaaaaaaaaa",
      "aaaaaaaaaaaaaaaa",
      "aaaaaaaaaaaaaaaa",
      "aaaaaaaaaaaaaaaa",
      "aaaaaaaaaaaaaaaa",
      "aaaaaaaaaaaaaaaa",
      "aaaaaaaaaaaaaaaa"
    ],
    [
      "bbbbbbbbbbbbbbbb",
      "bbbbbbbbbbbbbbbb",
      "bbbbbbbbbbbbbbbb",
      "bbbbbbbbbbbbbbbb",
      "bbbbbbbbbbbbbbbb",
      "bbbbbbbbbbbbbbbb",
      "bbbbbbbbbbbbbbbb",
      "bbbbbbbbbbbbbbbb",
      "bbbbbbbbbbbbbbbb",
      "bbbbbbbbbbbbbbbb",
      "bbbbbbbbbbbbbbbb",
      "bbbbbbbbbbbbbbbb",
      "bbbbbbbbbbbbbbbb",
      "bbbbbbbbbbbbbbbb",
      "bbbbbbbbbbbbbbbb",
      "bbbbbbbbbbbbbbbb"
    ],
    [
      "================",
      "================",
      "================",
      "================",
      "================",
      "================",
      "================",
      "================",
      "================",
      "================",
      "================",
      "================",
      "================",
      "================",
      "================",
      "================"
    ],
    [
      "cccccccccccccccc",
      "cccccccccccccccc",
      "ddddddeccccccccc",
      "ddddddeccccccccc",
      "ddddddeccccccccc",
      "cccccccccccccccc",
      "cccccccccccccccc",
      "cccccccccccccccc",
      "cccccccccccccccc",
      "cccccccccccccccc",
      "cccccccccccccccc",
      "cccccccccccccccc",
      "cccccccccccccccc",
      "cccccccccccccccc",
      "cccccccccccccccc",
      "cccccccccccccccc"
    ],
    [
      "ffffffffffffffff",
      "ddddddgfffffffff",
      "hijdddffffffffff",
      "kljdddffffffffff",
      "mijdddffffffffff",
      "ddddddnfffffffff",
      "ffffffffffffffff",
      "ffffffffffffffff",
      "offfffffffffffff",
      "fppfppfppfppfppf",
      "fppfppfppfppfppf",
      "ffffffffffffffff",
      "fppfppfppfppfppf",
      "fppfppfppfppfppf",
      "ffffffffffffffff",
      "fppfppfppfppfppf"
    ],
    [
      "ffffffffffffffff",
      "ddddddgfffffffff",
      "qqrfffffffffffff",
      "qqrfffffffffffff",
      "qqrfffffffffffff",
      "ddddddnfffffffff",
      "ffffffffffffffff",
      "ffffffffffffffff",
      "offfffffffffffff",
      "fstftufstftufstf",
      "fwufswfwufswfwuf",
      "ffffffffffffffff",
      "fstftufstftufstf",
      "fwufswfwufswfwuf",
      "ffffffffffffffff",
      "ftufstftufstftuf"
    ]
  ]
}