{
  "name": "multi_nuclearpowerplant_36_base10",
  "refpalette": "deceasedcraft:multi_nuclearpowerplant_36/multi_nuclearpowerplant_36_base10_palette",
  "xsize": 16,
  "zsize": 16,
  "slices": [
    [
      "                ",
      "  abbba         ",
      "  bcccb         ",
      "  bcccb         ",
      "  bcccb         ",
      "  dbbbd         ",
      "                ",
      "                ",
      "e               ",
      "                ",
      "                ",
      "                ",
      "                ",
      "                ",
      "                ",
      "                "
    ],
    [
      "f               ",
      "f abbba         ",
      "f bcccb         ",
      "f bcccb         ",
      "f bcccb         ",
      "f dbbbd         ",
      "f               ",
      "f               ",
      "gfffffffffffffff",
      "f               ",
      "f               ",
      "f               ",
      "f               ",
      "f               ",
      "f               ",
      "f               "
    ],
    [
      "h               ",
      "h abbba         ",
      "h bcccb         ",
      "ijbcccb         ",
      "h bcccb         ",
      "h dbbbd         ",
      "h               ",
      "h               ",
      " kkkkkkkkkkkkkkk",
      "h               ",
      "h               ",
      "h               ",
      "h               ",
      "h               ",
      "h               ",
      "h               "
    ],
    [
      "                ",
      "  abbba         ",
      "  bcccb         ",
      "  lcccb         ",
      "  bcccb         ",
      "  dbbbd         ",
      "                ",
      "                ",
      "                ",
      "                ",
      "                ",
      "                ",
      "                ",
      "                ",
      "                ",
      "                "
    ],
    [
      "                ",
      "  abbba         ",
      "  bcccb         ",
      " mncccb         ",
      "  bcccb         ",
      "  dbbbd         ",
      "                ",
      "                ",
      "                ",
      "                ",
      "                ",
      "                ",
      "                ",
      "                ",
      "                ",
      "                "
    ],
    [
      "                ",
      "  abbba         ",
      "  bcccb         ",
      " opcccb         ",
      "  bcccb         ",
      "  dbbbd         ",
      "                ",
      "                ",
      "                ",
      "                ",
      "                ",
      "                ",
      "                ",
      "                ",
      "                ",
      "                "
    ]
  ]
}