{
  "name": "multi_nuclearpowerplant_36_base2",
  "refpalette": "deceasedcraft:multi_nuclearpowerplant_36/multi_nuclearpowerplant_36_base2_palette",
  "xsize": 16,
  "zsize": 16,
  "slices": [
    [
      "                ",
      "                ",
      "                ",
      "                ",
      "                ",
      "                ",
      "                ",
      "                ",
      "                ",
      "                ",
      "                ",
      "a               ",
      "=a              ",
      " =a             ",
      "  =a            ",
      "b  =a           "
    ],
    [
      "                ",
      "                ",
      "                ",
      "c               ",
      "                ",
      "                ",
      "                ",
      "                ",
      "                ",
      "                ",
      "                ",
      "a           d   ",
      "=a          d   ",
      " =a         e   ",
      "  =a        f   ",
      "b  =a       f   "
    ],
    [
      "                ",
      "                ",
      "                ",
      "                ",
      "                ",
      "                ",
      "                ",
      "                ",
      "                ",
      "                ",
      "            c   ",
      "a          gh   ",
      "=a          f   ",
      " =a         f   ",
      "  =a        i   ",
      "b  =a       j   "
    ],
    [
      "                ",
      "                ",
      "                ",
      "                ",
      "                ",
      "                ",
      "                ",
      "                ",
      "                ",
      "                ",
      "a               ",
      "aa              ",
      "=aa         k   ",
      " =aa        f   ",
      "  =aa           ",
      "b l=aa          "
    ],
    [
      "                ",
      "                ",
      "                ",
      "                ",
      "                ",
      "                ",
      "                ",
      "                ",
      "m               ",
      "am              ",
      "=am             ",
      "==am            ",
      "n==am           ",
      "no==am      f   ",
      "nn ==am         ",
      "pn  ==am        "
    ],
    [
      "aqqhqccr       c",
      "qchqc         s ",
      "hqhcc           ",
      "aqcc            ",
      "hqc             ",
      "aqqc            ",
      "ahcc            ",
      "aqcqc           ",
      "aahqc           ",
      "=aahcc         c",
      "o=aaqqcc     ccq",
      "ot=aqcqqcc ccqcq",
      "not=aqhqqccqahqh",
      "nott=aaqchqaaqch",
      "nnott=aaqahaahqa",
      "unottt=aaaaaaaqa"
    ]
  ]
}