{
  "name": "multi_nuclearpowerplant_36_base8",
  "refpalette": "deceasedcraft:multi_nuclearpowerplant_36/multi_nuclearpowerplant_36_base8_palette",
  "xsize": 16,
  "zsize": 16,
  "slices": [
    [
      "                ",
      "  abbba         ",
      "  bcccb    d d  ",
      "  bcccb     e   ",
      "  bcccb    d d  ",
      "  fbbbf         ",
      "                ",
      "                ",
      "                ",
      "                ",
      "                ",
      "                ",
      "           d d  ",
      "    d       e   ",
      "           d d  ",
      "                "
    ],
    [
      "gggggggggggggggg",
      "gggbbbgggggggggg",
      "ggbcccbggggggggg",
      "ggbcccbggggghggg",
      "ggbcccbggggggggg",
      "gggbbbgggggggggg",
      "gggggggggggggggg",
      "gggggggggggggggg",
      "gggggggggggggggg",
      "gggggggggggggggg",
      "gggggggggggggggg",
      "gggggggggggggggg",
      "gggggggggggggggg",
      "gggggggggggghggg",
      "gggggggggggggggg",
      "gggggggggggggggg"
    ],
    [
      "iiiiiiiiiiijkjii",
      "llllllmiiiijkjii",
      "nnopppqiiiijrjii",
      "nnopppqiiiijsjii",
      "nnopppqiiiijrjii",
      "llllllmiiiijkjii",
      "iiiiiiiiiiijkjii",
      "iiiiiiiiiiijkjii",
      "iiiiiiiiiiijkjii",
      "iiiiiiiiiiijkjii",
      "iiiiiiiiiiijkjii",
      "iiiiiiiiiiijkjii",
      "iiiiiiiiiiijrjii",
      "iiiiiiiiiiijsjii",
      "iiiiiiiiiiijrjii",
      "iiiiiiiiiiijkjii"
    ],
    [
      "iiiiiiiiiiiijiii",
      "gggbbbiiiiiijiii",
      "ggt   biiiiijiii",
      "ggt   biiiiijiii",
      "ggt   biiiiijiii",
      "gggbbbiiiiiijiii",
      "iiiiiiiiiiiijiii",
      "iiiiiiiiiiiijiii",
      "iiiiiiiiiiiijiii",
      "iiiiiiiiiiiijiii",
      "iiiiiiiiiiiijiii",
      "iiiiiiiiiiiijiii",
      "iiiiiiiiiiiijiii",
      "iiiiiiiiiiiijiii",
      "iiiiiiiiiiiijiii",
      "iiiiiiiiiiiijiii"
    ],
    [
      "================",
      "===bbb==========",
      "==b   b=========",
      "==b   b=========",
      "==b   b=========",
      "===bbb==========",
      "================",
      "================",
      "================",
      "================",
      "================",
      "================",
      "u===============",
      "wu==============",
      "wwu=============",
      "wwwu============"
    ],
    [
      "bbbbbbbbbbbbbbbb",
      "bbbbbbbbbbbbbbbb",
      "bbb   bbbbbbbbbb",
      "bbb   bbbbbbbbbb",
      "bbb   bbbbbbbbbb",
      "bbbbbbbbbbbbbbbb",
      "bbbbbbbbbbbbbbbb",
      "bbbbbbbbbbbbbbbb",
      "bbbbbbbbbbbbbbbb",
      "bbbbbbbbbbbbbbbb",
      "bbbbbbbbbbbbbbbb",
      "bbbbbbbbbbbbbbbb",
      "=bbbbbbbbbbbbbbb",
      " =bbbbbbbbbbbbbb",
      "  =bbbbbbbbbbbbb",
      "   =bbbbbbbbbbbb"
    ]
  ]
}