{
  "name": "multi_nuclearpowerplant_9_base8",
  "refpalette": "deceasedcraft:multi_nuclearpowerplant_9/multi_nuclearpowerplant_9_base8_palette",
  "xsize": 16,
  "zsize": 16,
  "slices": [
    [
      "aaaaaaaaaaaaaaaa",
      "aaaaaaaaaaaaaaaa",
      "aaaaaaaaaaaaaaaa",
      "aaaaaaaaaaaaaaaa",
      "aaaaaaaaaaaaaaaa",
      "aaaaaaaaaaaaaaab",
      "aaaaaaaaaaaaabbc",
      "aaaaaaaaaaaabcc=",
      "aaaaaaaaaaabc===",
      "aaaaaaaaaabc===d",
      "aaaaaaaaabc==dd ",
      "aaaaaaaabc==deee",
      "aaaaaaabc==d    ",
      "aaaaaabc==df    ",
      "aaaaaabc==df    ",
      "aaaaabc==d f    "
    ],
    [
      "ggh=============",
      "ggh=============",
      "ggh=============",
      "ggh=============",
      "ggh=============",
      "ggh=============",
      "gh=============i",
      "gh===========iid",
      "gh==========iddd",
      "gh=========iddgg",
      "gh========iddggg",
      "gh=======iddgggg",
      "gh======iddggggg",
      "h======iddgggggg",
      "h======idggggggg",
      "h=====iddggggggg"
    ],
    [
      "jjklllllllllllll",
      "jjklllllllllllll",
      "jjklllllllllllll",
      "jjklllllllllllll",
      "jjklllllllllllll",
      "jjklllllllllllll",
      "jklllllllllllllm",
      "jklllllllllllmmd",
      "jkllllllllllmddd",
      "jklllllllllmddjj",
      "jkllllllllmddjjj",
      "jklllllllmddjjjj",
      "jkllllllmddjjjjj",
      "kllllllmddjjjjjj",
      "kllllllmdjjjjjjj",
      "klllllmddjjjjjjj"
    ],
    [
      "jjklllllllllllll",
      "jjklllllllllllll",
      "jjklllllllllllll",
      "jjklllllllllllll",
      "jjklllllllllllll",
      "jjklllllllllllll",
      "jklllllllllllllm",
      "jklllllllllllmmd",
      "jkllllllllllmddd",
      "jklllllllllmddjj",
      "jkllllllllmddjjj",
      "jklllllllmddjjjj",
      "jkllllllmddjjjjj",
      "kllllllmddjjjjjj",
      "kllllllmdjjjjjjj",
      "klllllmddjjjjjjj"
    ],
    [
      "jjkhhhhhhhhhhhhh",
      "jjkhhhhhhhhhhhhh",
      "jjkhhhhhhhhhhhhh",
      "jjkhhhhhhhhhhhhh",
      "jjkhhhhhhhhhhhhh",
      "jjkhhhhhhhhhhhnn",
      "jkhhhhhhhhhhnnni",
      "jkhhhhhhhhhnniid",
      "jkhhhhhhhhnniddd",
      "jkhhhhhhhnniddjj",
      "jkhhhhhhnniddjjj",
      "jkhhhhhnniddjjjj",
      "jkhhhhnniddjjjjj",
      "khhhhhniddjjjjjj",
      "khhhhnnidjjjjjjj",
      "khhhhniddjjjjjjj"
    ],
    [
      "jjk             ",
      "jjk             ",
      "jjk             ",
      "jjk             ",
      "jjk             ",
      "jjk             ",
      "jk             m",
      "jk           mmd",
      "jk          mddd",
      "jk         mddjj",
      "jk        mddjjj",
      "jk       mddjjjj",
      "jk      mddjjjjj",
      "k      mddjjjjjj",
      "k      mdjjjjjjj",
      "k     mddjjjjjjj"
    ]
  ]
}