{
  "name": "multi_nuclearpowerplant_9_base12",
  "refpalette": "deceasedcraft:multi_nuclearpowerplant_9/multi_nuclearpowerplant_9_base12_palette",
  "xsize": 16,
  "zsize": 16,
  "slices": [
    [
      "aaaaaaaaaaaaaaaa",
      "aaaaaaaaaaaaaaaa",
      "aaaaaaaaaaaaaaaa",
      "aaaaaaaaaaaaaaaa",
      "aaaaaaaaaaaaaaaa",
      "aaaaaaaaaaaaaaaa",
      "aaaaaaaaaaaaaaaa",
      "aaaaaaaaaaaaaaaa",
      "aaaaaaaaaaaaaaaa",
      "aaaaaaaaaaaaaaaa",
      "aaaaaaaaaaaaaaaa",
      "aaaaaaaaaaaaaaaa",
      "aaaaaaaaaaaaaaaa",
      "aaaaaaaaaaaaaaaa",
      "aaaaaaaaaaaaaaaa",
      "aaaaaaaaaaaaaaaa"
    ],
    [
      "bbbbbbbbbbbbbbbb",
      "bbbbbbbbbbbbbbbb",
      "bbbbbbbbbbbbbbbb",
      "bbbbbbbbbbbbbbbb",
      "bbbbbbbbbbbbbbbb",
      "bbbbbbbbbbbbbbbb",
      "bbbbbbbbbbbbbbbb",
      "bbbbbbbbbbbbbbbb",
      "bbbbbbbbbbbbbbbb",
      "bbbbbbbbbbbbbbbb",
      "bbbbbbbbbbbbbbbb",
      "bbbbbbbbbbbbbbbb",
      "bbbbbbbbbbbbbbbb",
      "bbbbbbbbbbbbbbbb",
      "bbbbbbbbbbbbbbbb",
      "bbbbbbbbbbbbbbbb"
    ],
    [
      "cccccccccccccccc",
      "cccccccccccccccc",
      "cccccccccccccccc",
      "cccccccccccccccc",
      "cccccccccccccccc",
      "cccccccccccccccc",
      "cccccccccccccccc",
      "cccccccccccccccc",
      "cccccccccccccccc",
      "cccccccccccccccc",
      "cccccccccccccccc",
      "cccccccccccccccc",
      "cccccccccccccccc",
      "cccccccccccccccc",
      "cccccccccccccccc",
      "cccccccccccccccc"
    ],
    [
      "                ",
      "     defgeh   de",
      "                ",
      "                ",
      "                ",
      "      ieejjjjjje",
      "      klmlmmmmmm",
      "      klllllllll",
      "      kllmmmmmmm",
      "      neeooooooe",
      "                ",
      "                ",
      "                ",
      "     defgeh   de",
      "                ",
      "                "
    ],
    [
      "                ",
      "      eeee     e",
      "       ee       ",
      "       ee       ",
      "       ee       ",
      "       eef    ge",
      "                ",
      "                ",
      "                ",
      "       eef    ge",
      "       ee       ",
      "       ee       ",
      "       ee       ",
      "      eeeef   ge",
      "                ",
      "                "
    ],
    [
      "                ",
      "      e  e     e",
      "      e         ",
      "      e         ",
      "      e         ",
      "      eeeeeeeeee",
      "      e         ",
      "      e         ",
      "      e         ",
      "      eeeeeeeeee",
      "      e         ",
      "      e         ",
      "      e   pppppq",
      "      e  eeeeeee",
      "          pppppr",
      "                "
    ]
  ]
}