{
  "name": "multi_nuclearpowerplant_9_base6",
  "refpalette": "deceasedcraft:multi_nuclearpowerplant_9/multi_nuclearpowerplant_9_base6_palette",
  "xsize": 16,
  "zsize": 16,
  "slices": [
    [
      "  aabbbbbbbbbbbb",
      "  abbbbbbbbbbbbb",
      "  abbbbbbbbbbbbb",
      "  abbbbbbbbbbbbb",
      "  abbbbbbbbbbbbb",
      "  abbbbbbbbbbbcc",
      " aabbbbbbbbbcccd",
      " abbbbbbbbbccdd ",
      " abbbbbbbbccd   ",
      " abbbbbbbccd    ",
      " abbbbbbccd     ",
      " abbbbbccd      ",
      " abbbbccd       ",
      "aabbbbcd        ",
      "abbbbccd        ",
      "abbbbcd         "
    ],
    [
      "  ee            ",
      "  e             ",
      "  e             ",
      "  e             ",
      "  e             ",
      "  e             ",
      " ee            f",
      " e           ffg",
      " eh         fggg",
      " ei        fgg  ",
      " ej       fgg   ",
      " e       fgg    ",
      " ek     fgg     ",
      "lm     fgg      ",
      "n      fg       ",
      "o     fgg       "
    ],
    [
      "                ",
      "                ",
      "                ",
      "                ",
      "                ",
      "                ",
      "                ",
      "               =",
      "             ===",
      "            ==  ",
      "           ==   ",
      "          ==    ",
      "         ==     ",
      "        ==      ",
      "        =       ",
      "       ==       "
    ],
    [
      "                ",
      "                ",
      "                ",
      "                ",
      "                ",
      "                ",
      "                ",
      "                ",
      "                ",
      "                ",
      "           =    ",
      "          =     ",
      "                ",
      "                ",
      "                ",
      "                "
    ],
    [
      "                ",
      "                ",
      "                ",
      "                ",
      "                ",
      "                ",
      "                ",
      "                ",
      "                ",
      "                ",
      "           pq   ",
      "          r     ",
      "          s     ",
      "                ",
      "                ",
      "                "
    ],
    [
      "                ",
      "                ",
      "                ",
      "                ",
      "                ",
      "                ",
      "                ",
      "                ",
      "                ",
      "                ",
      "            =   ",
      "                ",
      "          =     ",
      "                ",
      "                ",
      "                "
    ]
  ]
}