{
  "name": "multi_nuclearpowerplant_9_base7",
  "refpalette": "deceasedcraft:multi_nuclearpowerplant_9/multi_nuclearpowerplant_9_base7_palette",
  "xsize": 16,
  "zsize": 16,
  "slices": [
    [
      "aab             ",
      "aab             ",
      "aab             ",
      "aab             ",
      "aab             ",
      "aab             ",
      "ab             c",
      "ab           ccd",
      "ab          cddd",
      "ab         cddaa",
      "ab        cddaaa",
      "ab       cddaaaa",
      "ab      cddaaaaa",
      "b      cddaaaaaa",
      "b      cdaaaaaaa",
      "b     cddaaaaaaa"
    ],
    [
      "aab             ",
      "aab             ",
      "aab             ",
      "aab             ",
      "aab             ",
      "aab             ",
      "ab             c",
      "ab           ccd",
      "ab          cddd",
      "ab         cddaa",
      "ab        cddaaa",
      "ab       cddaaaa",
      "ab      cddaaaaa",
      "b      cddaaaaaa",
      "b      cdaaaaaaa",
      "b     cddaaaaaaa"
    ],
    [
      "aab             ",
      "aab             ",
      "aab             ",
      "aab             ",
      "aab             ",
      "aab             ",
      "ab             c",
      "ab           ccd",
      "ab           edd",
      "ab          eeaa",
      "ab         eeaaa",
      "ab        eeaaaa",
      "ab       eeaaaaa",
      "b      ceeaaaaaa",
      "b      cdaaaaaaa",
      "b     cddaaaaaaa"
    ],
    [
      "aab             ",
      "aab             ",
      "aab             ",
      "aab             ",
      "aab             ",
      "aab             ",
      "ab             c",
      "ab           ccd",
      "ab           edd",
      "ab          eeaa",
      "ab         eeaaa",
      "ab        eeaaaa",
      "ab       eeaaaaa",
      "b      ceeaaaaaa",
      "b      cdaaaaaaa",
      "b     cddaaaaaaa"
    ],
    [
      "aab             ",
      "aab             ",
      "aab             ",
      "aab             ",
      "aab             ",
      "aab             ",
      "ab             c",
      "ab           ccd",
      "ab          cddd",
      "ab         cddfa",
      "ab        cddaaa",
      "ab       cddgaaa",
      "ab      cddggaaa",
      "b      cddgagfaa",
      "b      cdffaaaaa",
      "b     cddaaaagaa"
    ],
    [
      "aabhhhhhhhhhhhhh",
      "aabhhhhhhhhhhhhh",
      "aabhhhhhhhhhhhhh",
      "aabhhhhhhhhhhhhh",
      "aabhhhhhhhhhhhhh",
      "aabhhhhhhhhhhhii",
      "abhhhhhhhhhhiii ",
      "abhhhhhhhhhij  d",
      "abhhhhhhhhii ddd",
      "abhhhhhhhii dd  ",
      "abhhhhhhii dd   ",
      "abhhhhhii dd    ",
      "abhhhhij dd     ",
      "bhhhhhi dd      ",
      "bhhhhii d       ",
      "bhhhhi dd       "
    ]
  ]
}