{
  "name": "building_hotelb_top_270",
  "refpalette": "deceasedcraft:building_hotelb/building_hotelb_top_palette_270",
  "xsize": 16,
  "zsize": 16,
  "slices": [
    [
      "                ",
      " aa aa aa aa aa ",
      " abbbbbbbbbbbba ",
      "  b   cccccccb  ",
      " ab dffdddddcba ",
      " ab gffdddddcba ",
      "  bcffeeeeddcb  ",
      " abcddeeeeddcba ",
      " abcddeeeeddcba ",
      "  bcddeeeeddcb  ",
      " abcddddddddcba ",
      " abcddddddddcba ",
      "  bccccccccccb  ",
      " abbbbbbbbbbbba ",
      " aa aa aa aa aa ",
      "                "
    ],
    [
      "                ",
      " aa aa aa aa aa ",
      " abbbbbbbbbbbba ",
      "  b   cccccccb  ",
      " ab k ffffhhcba ",
      " ab  jffffhhcba ",
      "  bcffffffddcb  ",
      " abcfffiifddcba ",
      " abcfffiifddcba ",
      "  bcffffffddcb  ",
      " abcddddddddcba ",
      " abcddddddddcba ",
      "  bccccccccccb  ",
      " abbbbbbbbbbbba ",
      " aa aa aa aa aa ",
      "                "
    ],
    [
      "                ",
      " aa aa aa aa aa ",
      " abbbbbbbbbbbba ",
      "  b   cccccccb  ",
      " ab k r   n!cba ",
      " ab   s  ollcba ",
      "  bcwu    fmcb  ",
      " abcx  qp fmcba ",
      " abcx  qp fmcba ",
      "  bc      fmcb  ",
      " abcfffffffmcba ",
      " abcmmtmmmmmcba ",
      "  bccccccccccb  ",
      " abbbbbbbbbbbba ",
      " aa aa aa aa aa ",
      "                "
    ],
    [
      "                ",
      "  a aa aa aa aa ",
      " abbbbbbbbbbbba ",
      "  bJJJcccccccb  ",
      " abJk rDDDAycba ",
      " abJ  F  ollcba ",
      "  bcwK    Bfcb  ",
      " abc      Cfcba ",
      " abc       fcba ",
      "  bc      Cfcb  ",
      " abc LIE E fcba ",
      " abcffffffffcba ",
      "  bccccccccccb  ",
      " abbbbbbbbbbbba ",
      "  a aa aa aa aa ",
      "                "
    ],
    [
      "                ",
      "     a aa aa aa ",
      "     bbbbbbbbba ",
      "   ccccccccccb  ",
      "   cffP  o Mcba ",
      "   cfPQ  ollcba ",
      "   cPS     Ccb  ",
      "   c       Ncba ",
      "   c       Ccba ",
      "   c        cb  ",
      "   c       Ccba ",
      "   cCIRBE EOcba ",
      "   ccccccccccb  ",
      "     bbbbbbbbba ",
      "     a aa aa aa ",
      "                "
    ],
    [
      "                ",
      "        a aa aa ",
      "        bbbbbba ",
      "   WVccccccccb  ",
      "   X jfUPoTTcba ",
      "   cjfUP oTTcba ",
      "   cfUP     cb  ",
      "   cUP      cba ",
      "   cP       cba ",
      "   c        cb  ",
      "   c        cba ",
      "   c        cba ",
      "   ccccccccccb  ",
      "        bbbbbba ",
      "        a aa aa ",
      "                "
    ],
    [
      "                ",
      "           a aa ",
      "           bbba ",
      "      WVcccccb  ",
      "        jfP cba ",
      "       jfP  cba ",
      "   W  jfP  Ycb  ",
      "   X jfP    cba ",
      "   cjfP     cba ",
      "   cfP     Ycb  ",
      "   cP       cba ",
      "   c  0  Z  cba ",
      "   ccccccccccb  ",
      "           bbba ",
      "           a aa ",
      "                "
    ],
    [
      "                ",
      "                ",
      "                ",
      "         WVcc   ",
      "          jUc   ",
      "         jUPc   ",
      "        jUPPc   ",
      "       jUPPPc   ",
      "      jUPPP c   ",
      "   W jUPPP Pc   ",
      "   XjUPPP PPc   ",
      "   cUPPP PPPc   ",
      "   cccccccccc   ",
      "                ",
      "                ",
      "                "
    ],
    [
      "                ",
      "                ",
      "                ",
      "            W   ",
      "            X   ",
      "            c   ",
      "           jc   ",
      "          jfc   ",
      "         jfUc   ",
      "        jfUfc   ",
      "       jfUffc   ",
      "      jfUfffc   ",
      "   WVcccccccc   ",
      "                ",
      "                ",
      "                "
    ],
    [
      "                ",
      "                ",
      "                ",
      "                ",
      "                ",
      "                ",
      "            W   ",
      "            X   ",
      "            c   ",
      "           jc   ",
      "          jfc   ",
      "         jffc   ",
      "      WVccccc   ",
      "                ",
      "                ",
      "                "
    ],
    [
      "                ",
      "                ",
      "                ",
      "                ",
      "                ",
      "                ",
      "                ",
      "                ",
      "                ",
      "            W   ",
      "            X   ",
      "           jc   ",
      "         WVcc   ",
      "                ",
      "                ",
      "                "
    ],
    [
      "                ",
      "                ",
      "                ",
      "                ",
      "                ",
      "                ",
      "                ",
      "                ",
      "                ",
      "                ",
      "                ",
      "                ",
      "            W   ",
      "                ",
      "                ",
      "                "
    ]
  ]
}