{
  "name": "building_hotelb_floor2_90",
  "refpalette": "deceasedcraft:building_hotelb/building_hotelb_floor2_palette_90",
  "xsize": 16,
  "zsize": 16,
  "slices": [
    [
      "                ",
      " aa aa aa aa aa ",
      " abbbbbbbbbbbba ",
      "  bccccccccccb  ",
      " abcf  jdeedcba ",
      " abc  hjjggecba ",
      "  bc   ggggecb  ",
      " abc   iiggecba ",
      " abc   igggecba ",
      "  bceggggggecb  ",
      " abceggggggeiba ",
      " abcdeeeeeediba ",
      "  bccccccciiib  ",
      " abbbbbbbbbbbba ",
      " aa aa aa aa aa ",
      "                "
    ],
    [
      "                ",
      " aa aa aa aa aa ",
      " abbbbbbbbbbbba ",
      "  bccccccccccb  ",
      " abcf   r xfcba ",
      " abc    r wCcba ",
      "  bc   q  w cb  ",
      " abc   q sw cba ",
      " abchhhq  wBcba ",
      "  bclnnn sw cb  ",
      " abcknnn  uAEba ",
      " abcfmop   fDba ",
      "  bcccccccty!b  ",
      " abbbbbbbbbbbba ",
      " aa aa aa aa aa ",
      "                "
    ],
    [
      "                ",
      " aa aa aa aa aa ",
      " abbbbbbbbbbbba ",
      "  bccccccccccb  ",
      " abcf     Lfcba ",
      " abc        cba ",
      "  bc      K cb  ",
      " abc      J cba ",
      " abc        cba ",
      "  bcI       cb  ",
      " abcF        ba ",
      " abcf      f ba ",
      "  bccccccc Myb  ",
      " abbbbbbbbbbbba ",
      " aa aa aa aa aa ",
      "                "
    ],
    [
      "                ",
      " aa aa aa aa aa ",
      " abbbbbbbbbbbba ",
      "  bccccccccccb  ",
      " abcf  OP  fcba ",
      " abc        cba ",
      "  bc        cb  ",
      " abc        cba ",
      " abc   N    cba ",
      "  bc        cb  ",
      " abc         ba ",
      " abcf      fQba ",
      "  bccccccc  Mb  ",
      " abbbbbbbbbbbba ",
      " aa aa aa aa aa ",
      "                "
    ],
    [
      "                ",
      " aa aa aa aa aa ",
      " abbbbbbbbbbbba ",
      "  bRSccccccccb  ",
      " abRf      fcba ",
      " abR        cba ",
      "  bR        cb  ",
      " abR   N    cba ",
      " abR   N    cba ",
      "  bR        cb  ",
      " abR        Qba ",
      " abRf      fTba ",
      "  bRRRRRRc   b  ",
      " abbbbbbbbbbbba ",
      " aa aa aa aa aa ",
      "                "
    ],
    [
      "                ",
      " aa aa aa aa aa ",
      " abbbbbbbbbbbba ",
      "  b WWRScccccb  ",
      " abUfiiiiiifcba ",
      " abUiXXXXXXicba ",
      "  bUiXXXXXXicb  ",
      " abUiXXNYXXicba ",
      " abUiXXYNXXicba ",
      "  bUiXXXXXXicb  ",
      " abUiXXXXXXZTba ",
      " abUfiiiiiif ba ",
      "  b VVVVVc   b  ",
      " abbbbbbbbbbbba ",
      " aa aa aa aa aa ",
      "                "
    ]
  ]
}