{
  "name": "building_hotelb_top_180",
  "refpalette": "deceasedcraft:building_hotelb/building_hotelb_top_palette_180",
  "xsize": 16,
  "zsize": 16,
  "slices": [
    [
      "                ",
      " aa aa aa aa aa ",
      " abbbbbbbbbbbba ",
      "  bccccccc   b  ",
      " abcdddddfgd ba ",
      " abcdddddfff ba ",
      "  bcddeeeeffcb  ",
      " abcddeeeeddcba ",
      " abcddeeeeddcba ",
      "  bcddeeeeddcb  ",
      " abcddddddddcba ",
      " abcddddddddcba ",
      "  bccccccccccb  ",
      " abbbbbbbbbbbba ",
      " aa aa aa aa aa ",
      "                "
    ],
    [
      "                ",
      " aa aa aa aa aa ",
      " abbbbbbbbbbbba ",
      "  bccccccc   b  ",
      " abcddffff k ba ",
      " abcddffffj  ba ",
      "  bcddffffffcb  ",
      " abcddfiifffcba ",
      " abcddfiifffcba ",
      "  bcddffffffcb  ",
      " abcddddddhhcba ",
      " abcddddddhhcba ",
      "  bccccccccccb  ",
      " abbbbbbbbbbbba ",
      " aa aa aa aa aa ",
      "                "
    ],
    [
      "                ",
      " aa aa aa aa aa ",
      " abbbbbbbbbbbba ",
      "  bccccccc   b  ",
      " abcmf xxw k ba ",
      " abcmf   u   ba ",
      "  bctf    srcb  ",
      " abcmf qq   cba ",
      " abcmf pp   cba ",
      "  bcmf    o cb  ",
      " abcmffffflncba ",
      " abcmmmmmml!cba ",
      "  bccccccccccb  ",
      " abbbbbbbbbbbba ",
      " aa aa aa aa aa ",
      "                "
    ],
    [
      "                ",
      "  a aa aa aa a  ",
      " abbbbbbbbbbbba ",
      "  bcccccccJJJb  ",
      " abcf    w kJba ",
      " abcfL   K  Jba ",
      "  bcfI    Frcb  ",
      " abcfE     Dcba ",
      " abcf      Dcba ",
      "  bcfE    oDcb  ",
      " abcf C CBlAcba ",
      " abcfffffflycba ",
      "  bccccccccccb  ",
      " abbbbbbbbbbbba ",
      " aa aa aa aa aa ",
      "                "
    ],
    [
      "                ",
      "                ",
      "                ",
      "   cccccccccc   ",
      "   cC    Pffc   ",
      " abcI    SPfcba ",
      "  bcR     QPcb  ",
      " abcB       cba ",
      " abcE       cba ",
      "  bc      oocb  ",
      " abcE     l cba ",
      " abcOC CNClMcba ",
      "  bccccccccccb  ",
      " abbbbbbbbbbbba ",
      " aa aa aa aa aa ",
      "                "
    ],
    [
      "                ",
      "                ",
      "                ",
      "   ccccccccXW   ",
      "   c   PUfj V   ",
      "   c    PUfjc   ",
      "   c     PUfc   ",
      "   c      PUc   ",
      " abc       Pcba ",
      "  bc      oocb  ",
      " abc      TTcba ",
      " abc      TTcba ",
      "  bccccccccccb  ",
      " abbbbbbbbbbbba ",
      " aa aa aa aa aa ",
      "                "
    ],
    [
      "                ",
      "                ",
      "                ",
      "   cccccXW      ",
      "   c Pfj        ",
      "   c  Pfj       ",
      "   c0  Pfj  W   ",
      "   c    Pfj V   ",
      "   c     Pfjc   ",
      "   cZ     Pfc   ",
      "   c       Pc   ",
      " abc  Y  Y  cba ",
      "  bccccccccccb  ",
      " abbbbbbbbbbbba ",
      " aa aa aa aa aa ",
      "                "
    ],
    [
      "                ",
      "                ",
      "                ",
      "   ccXW         ",
      "   cUj          ",
      "   cPUj         ",
      "   cPPUj        ",
      "   cPPPUj       ",
      "   c PPPUj      ",
      "   cP PPPUj W   ",
      "   cPP PPPUjV   ",
      "   cPPP PPPUc   ",
      "   cccccccccc   ",
      "                ",
      "                ",
      "                "
    ],
    [
      "                ",
      "                ",
      "                ",
      "   W            ",
      "   V            ",
      "   c            ",
      "   cj           ",
      "   cfj          ",
      "   cUfj         ",
      "   cfUfj        ",
      "   cffUfj       ",
      "   cfffUfj      ",
      "   ccccccccXW   ",
      "                ",
      "                ",
      "                "
    ],
    [
      "                ",
      "                ",
      "                ",
      "                ",
      "                ",
      "                ",
      "   W            ",
      "   V            ",
      "   c            ",
      "   cj           ",
      "   cfj          ",
      "   cffj         ",
      "   cccccXW      ",
      "                ",
      "                ",
      "                "
    ],
    [
      "                ",
      "                ",
      "                ",
      "                ",
      "                ",
      "                ",
      "                ",
      "                ",
      "                ",
      "   W            ",
      "   V            ",
      "   cj           ",
      "   ccXW         ",
      "                ",
      "                ",
      "                "
    ],
    [
      "                ",
      "                ",
      "                ",
      "                ",
      "                ",
      "                ",
      "                ",
      "                ",
      "                ",
      "                ",
      "                ",
      "                ",
      "   W            ",
      "                ",
      "                ",
      "                "
    ]
  ]
}