{
  "name": "building_hotelb_floor3_180",
  "refpalette": "deceasedcraft:building_hotelb/building_hotelb_floor3_palette_180",
  "xsize": 16,
  "zsize": 16,
  "slices": [
    [
      "                ",
      " aa aa aa aa aa ",
      " abbbbbbbbbbbba ",
      "  bggggggg   b  ",
      " abgdjjjjgkd ba ",
      " abgjjjjjghhiba ",
      "  bggfgfggghgb  ",
      " abceffffffecba ",
      " abceffffffecba ",
      "  bceffffffecb  ",
      " abceffffffecba ",
      " abcdeeeeeedcba ",
      "  bccccccccccb  ",
      " abbbbbbbbbbbba ",
      " aa aa aa aa aa ",
      "                "
    ],
    [
      "                ",
      " aa aa aa aa aa ",
      " abbbbbbbbbbbba ",
      "  bggggggg   b  ",
      " abg210ZYg sXba ",
      " abgW V Ug  Tba ",
      "  bggSgRgQgPgb  ",
      " abDCCON    Kba ",
      " abJICrM Ly Kba ",
      "  bJICrF Ey rb  ",
      " abDCCrB Ay xba ",
      " abws ut   srba ",
      "  bqp nomnm lb  ",
      " abbbbbbbbbbbba ",
      " aa aa aa aa aa ",
      "                "
    ],
    [
      "                ",
      " aa aa aa aa aa ",
      " abbbbbbbbbbbba ",
      "  bggggggg  Xb  ",
      " ab]|  }!g s{ba ",
      " ab]    Zg   ba ",
      "  bgg[g-g+g)gb  ",
      " ab(  O*     ba ",
      " ab   #     &ba ",
      "  b   #^    %b  ",
      " ab$  #9     ba ",
      " ab s 87   s6ba ",
      "  b   5o 4  3b  ",
      " abbbbbbbbbbbba ",
      " aa aa aa aa aa ",
      "                "
    ],
    [
      "                ",
      " aa aa aa aa aa ",
      " abbbbbbbbbbbba ",
      "  bgg\u0370\u0370\u0370gg `{b  ",
      " abg/   ?g s ba ",
      " abg    .g   ba ",
      "  bgg,g,g>g<gb  ",
      " ab   O'     ba ",
      " ab   #      ba ",
      "  b   #      b  ",
      " ab   #      ba ",
      " ab s :;   s ba ",
      "  b    o    !b  ",
      " abbbbbbbbbbbba ",
      " aa aa aa aa aa ",
      "                "
    ],
    [
      "                ",
      " aa aa aa aa aa ",
      " abbbbbbbbbbbba ",
      "  bggggggg`\u0375 b  ",
      " abg     g s ba ",
      " abg     g   ba ",
      "  bggggggggggb  ",
      " ab\u0373        \u0372ba ",
      " ab\u0373  \u0374     \u0372ba ",
      "  b\u0373        \u0372b  ",
      " ab\u0373        \u0372ba ",
      " ab\u0373s      s\u0372ba ",
      "  b \u0371\u0371\u0371\u0371\u0371\u0371\u0371\u0371 b  ",
      " abbbbbbbbbbbba ",
      " aa aa aa aa aa ",
      "                "
    ],
    [
      "                ",
      " aa aa aa aa aa ",
      " abbbbbbbbbbbba ",
      "  bggggggg\u0375  b  ",
      " abg\u037a\u037a\u037a\u037a\u037ag\u037bs ba ",
      " abg\u037a\u037a\u037a\u037a\u037agcc ba ",
      "  bggggggggggb  ",
      " abgh\u0377\u0377\u0377\u0377\u0377\u0377hgba ",
      " abgh\u0377\u0377\u0377\u0377\u0377\u0377hgba ",
      "  bgh\u0377\u0377\u0377\u0377\u0377\u0377hgb  ",
      " abgh\u0377\u0377\u0377\u0377\u0377\u0377hgba ",
      " abg\u0376hhhhhh\u0376gba ",
      "  bggggggggggb  ",
      " abbbbbbbbbbbba ",
      " aa aa aa aa aa ",
      "                "
    ]
  ]
}