{
  "name": "building_hotelb_top",
  "refpalette": "deceasedcraft:building_hotelb/building_hotelb_top_palette",
  "xsize": 16,
  "zsize": 16,
  "slices": [
    [
      "                ",
      " aa aa aa aa aa ",
      " abbbbbbbbbbbba ",
      "  bccccccccccb  ",
      " abcddddddddcba ",
      " abcddddddddcba ",
      "  bcddeeeeddcb  ",
      " abcddeeeeddcba ",
      " abcddeeeeddcba ",
      "  bcffeeeeddcb  ",
      " ab fffdddddcba ",
      " ab dgfdddddcba ",
      "  b   cccccccb  ",
      " abbbbbbbbbbbba ",
      " aa aa aa aa aa ",
      "                "
    ],
    [
      "                ",
      " aa aa aa aa aa ",
      " abbbbbbbbbbbba ",
      "  bccccccccccb  ",
      " abchhddddddcba ",
      " abchhddddddcba ",
      "  bcffffffddcb  ",
      " abcfffiifddcba ",
      " abcfffiifddcba ",
      "  bcffffffddcb  ",
      " ab  jffffddcba ",
      " ab k ffffddcba ",
      "  b   cccccccb  ",
      " abbbbbbbbbbbba ",
      " aa aa aa aa aa ",
      "                "
    ],
    [
      "                ",
      " aa aa aa aa aa ",
      " abbbbbbbbbbbba ",
      "  bccccccccccb  ",
      " abc!lmmmmmmcba ",
      " abcnlfffffmcba ",
      "  bc o    fmcb  ",
      " abc   pp fmcba ",
      " abc   qq fmcba ",
      "  bcrs    ftcb  ",
      " ab   u   fmcba ",
      " ab k wxx fmcba ",
      "  b   cccccccb  ",
      " abbbbbbbbbbbba ",
      " aa aa aa aa aa ",
      "                "
    ],
    [
      "                ",
      " aa aa aa aa aa ",
      " abbbbbbbbbbbba ",
      "  bccccccccccb  ",
      " abcylffffffcba ",
      " abcAlBC C fcba ",
      "  bcDo    Efcb  ",
      " abcD      fcba ",
      " abcD     Efcba ",
      "  bcrF    Ifcb  ",
      " abJ  K   Lfcba ",
      " abJk w    fcba ",
      "  bJJJcccccccb  ",
      " abbbbbbbbbbbba ",
      "  a aa aa aa a  ",
      "                "
    ],
    [
      "                ",
      " aa aa aa aa aa ",
      " abbbbbbbbbbbba ",
      "  bccccccccccb  ",
      " abcMlCNC COcba ",
      " abc l     Ecba ",
      "  bcoo      cb  ",
      " abc       Ecba ",
      " abc       Bcba ",
      "  bcPQ     Rcb  ",
      " abcfPS    Icba ",
      "   cffP    Cc   ",
      "   cccccccccc   ",
      "                ",
      "                ",
      "                "
    ],
    [
      "                ",
      " aa aa aa aa aa ",
      " abbbbbbbbbbbba ",
      "  bccccccccccb  ",
      " abcTT      cba ",
      " abcTT      cba ",
      "  bcoo      cb  ",
      " abcP       cba ",
      "   cUP      c   ",
      "   cfUP     c   ",
      "   cjfUP    c   ",
      "   V jfUP   c   ",
      "   WXcccccccc   ",
      "                ",
      "                ",
      "                "
    ],
    [
      "                ",
      " aa aa aa aa aa ",
      " abbbbbbbbbbbba ",
      "  bccccccccccb  ",
      " abc  Y  Y  cba ",
      "   cP       c   ",
      "   cfP     Zc   ",
      "   cjfP     c   ",
      "   V jfP    c   ",
      "   W  jfP  0c   ",
      "       jfP  c   ",
      "        jfP c   ",
      "      WXccccc   ",
      "                ",
      "                ",
      "                "
    ],
    [
      "                ",
      "                ",
      "                ",
      "   cccccccccc   ",
      "   cUPPP PPPc   ",
      "   VjUPPP PPc   ",
      "   W jUPPP Pc   ",
      "      jUPPP c   ",
      "       jUPPPc   ",
      "        jUPPc   ",
      "         jUPc   ",
      "          jUc   ",
      "         WXcc   ",
      "                ",
      "                ",
      "                "
    ],
    [
      "                ",
      "                ",
      "                ",
      "   WXcccccccc   ",
      "      jfUfffc   ",
      "       jfUffc   ",
      "        jfUfc   ",
      "         jfUc   ",
      "          jfc   ",
      "           jc   ",
      "            c   ",
      "            V   ",
      "            W   ",
      "                ",
      "                ",
      "                "
    ],
    [
      "                ",
      "                ",
      "                ",
      "      WXccccc   ",
      "         jffc   ",
      "          jfc   ",
      "           jc   ",
      "            c   ",
      "            V   ",
      "            W   ",
      "                ",
      "                ",
      "                ",
      "                ",
      "                ",
      "                "
    ],
    [
      "                ",
      "                ",
      "                ",
      "         WXcc   ",
      "           jc   ",
      "            V   ",
      "            W   ",
      "                ",
      "                ",
      "                ",
      "                ",
      "                ",
      "                ",
      "                ",
      "                ",
      "                "
    ],
    [
      "                ",
      "                ",
      "                ",
      "            W   ",
      "                ",
      "                ",
      "                ",
      "                ",
      "                ",
      "                ",
      "                ",
      "                ",
      "                ",
      "                ",
      "                ",
      "                "
    ]
  ]
}