{
  "name": "building_hotelbpart2_floor4_180",
  "refpalette": "deceasedcraft:building_hotelb/building_hotelbpart2_floor4_palette_180",
  "xsize": 16,
  "zsize": 16,
  "slices": [
    [
      "                ",
      " aa aa aa aa aa ",
      " a            a ",
      "                ",
      " a            a ",
      " a            a ",
      "                ",
      " a            a ",
      " a            a ",
      "                ",
      " a            a ",
      " a            a ",
      "                ",
      " a            a ",
      " aa aa aa aa aa ",
      "                "
    ],
    [
      "                ",
      " aa aa aa aa aa ",
      " a            a ",
      "                ",
      " a         b  a ",
      " a            a ",
      "                ",
      " a            a ",
      " a  cc        a ",
      "    c           ",
      " a  c         a ",
      " a  bc     b  a ",
      "                ",
      " a            a ",
      " aa aa aa aa aa ",
      "                "
    ],
    [
      "                ",
      " aa aa aa aa aa ",
      " a            a ",
      "                ",
      " a         b  a ",
      " a            a ",
      "                ",
      " a            a ",
      " a            a ",
      "                ",
      " a            a ",
      " a  b      b  a ",
      "                ",
      " a            a ",
      " aa aa aa aa aa ",
      "                "
    ],
    [
      "                ",
      " aa aa aa aa aa ",
      " a            a ",
      "                ",
      " a         b  a ",
      " a            a ",
      "                ",
      " a            a ",
      " a            a ",
      "                ",
      " a            a ",
      " a  b      b  a ",
      "                ",
      " a            a ",
      " aa aa aa aa aa ",
      "                "
    ],
    [
      "                ",
      " aa aa aa aa aa ",
      " a            a ",
      "                ",
      " a         b  a ",
      " a            a ",
      "                ",
      " a            a ",
      " a            a ",
      "                ",
      " a            a ",
      " a  b      b  a ",
      "                ",
      " a            a ",
      " aa aa aa aa aa ",
      "                "
    ],
    [
      "                ",
      " aa aa aa aa aa ",
      " a            a ",
      "                ",
      " a         b  a ",
      " a            a ",
      "                ",
      " a            a ",
      " a            a ",
      "                ",
      " a            a ",
      " a  d      d  a ",
      "                ",
      " a            a ",
      " aa aa aa aa aa ",
      "                "
    ]
  ]
}