{
  "name": "building_hotelbpart2_floor1",
  "refpalette": "deceasedcraft:building_hotelb/building_hotelbpart2_floor1_palette",
  "xsize": 16,
  "zsize": 16,
  "slices": [
    [
      "                ",
      " aa aa aa aa aa ",
      " a            a ",
      "                ",
      " a  b      b  a ",
      " a  cc        a ",
      "     cc         ",
      " a            a ",
      " a            a ",
      "         c      ",
      " a       cc   a ",
      " a  b     cb  a ",
      "                ",
      "                ",
      "                ",
      "                "
    ],
    [
      "                ",
      " aa aa aa aa aa ",
      " a            a ",
      "                ",
      " a  b         a ",
      " a            a ",
      "                ",
      " a            a ",
      " a            a ",
      "                ",
      " a            a ",
      " a  b      b  a ",
      "                ",
      " a            a ",
      " aa aa aa aa aa ",
      "                "
    ],
    [
      "                ",
      " aa aa aa aa aa ",
      " a            a ",
      "                ",
      " a  b      b  a ",
      " a            a ",
      "                ",
      " a            a ",
      " a            a ",
      "                ",
      " a            a ",
      " a  b      b  a ",
      "                ",
      " a            a ",
      " aa aa aa aa aa ",
      "                "
    ],
    [
      "                ",
      " aa aa aa aa aa ",
      " a            a ",
      "                ",
      " a  b      b  a ",
      " a            a ",
      "                ",
      " a            a ",
      " a            a ",
      "                ",
      " a            a ",
      " a  b      b  a ",
      "                ",
      " a            a ",
      " aa aa aa aa aa ",
      "                "
    ],
    [
      "                ",
      " aa aa aa aa aa ",
      " a            a ",
      "                ",
      " a  b      b  a ",
      " a            a ",
      "                ",
      " a            a ",
      " a            a ",
      "                ",
      " a            a ",
      " a  b      b  a ",
      "                ",
      " a            a ",
      " aa aa aa aa aa ",
      "                "
    ],
    [
      "                ",
      " aa aa aa aa aa ",
      " a            a ",
      "                ",
      " a  b      b  a ",
      " a            a ",
      "                ",
      " a            a ",
      " a            a ",
      "                ",
      " a            a ",
      " a  b      b  a ",
      "                ",
      " a            a ",
      " aa aa aa aa aa ",
      "                "
    ]
  ]
}