{
  "name": "building_hotelb_floor2_270",
  "refpalette": "deceasedcraft:building_hotelb/building_hotelb_floor2_palette_270",
  "xsize": 16,
  "zsize": 16,
  "slices": [
    [
      "                ",
      " aa aa aa aa aa ",
      " abbbbbbbbbbbba ",
      "  biiicccccccb  ",
      " abideeeeeedcba ",
      " abieggggggecba ",
      "  bceggggggecb  ",
      " abcegggi   cba ",
      " abceggii   cba ",
      "  bcegggg   cb  ",
      " abceggjjh  cba ",
      " abcdeedj  fcba ",
      "  bccccccccccb  ",
      " abbbbbbbbbbbba ",
      " aa aa aa aa aa ",
      "                "
    ],
    [
      "                ",
      " aa aa aa aa aa ",
      " abbbbbbbbbbbba ",
      "  b!ytcccccccb  ",
      " abDf   pomfcba ",
      " abEAu  nnnkcba ",
      "  bc ws nnnlcb  ",
      " abcBw  qhhhcba ",
      " abc ws q   cba ",
      "  bc w  q   cb  ",
      " abcCw r    cba ",
      " abcfx r   fcba ",
      "  bccccccccccb  ",
      " abbbbbbbbbbbba ",
      " aa aa aa aa aa ",
      "                "
    ],
    [
      "                ",
      " aa aa aa aa aa ",
      " abbbbbbbbbbbba ",
      "  byM cccccccb  ",
      " ab f      fcba ",
      " ab        Fcba ",
      "  bc       Icb  ",
      " abc        cba ",
      " abc J      cba ",
      "  bc K      cb  ",
      " abc        cba ",
      " abcfL     fcba ",
      "  bccccccccccb  ",
      " abbbbbbbbbbbba ",
      " aa aa aa aa aa ",
      "                "
    ],
    [
      "                ",
      " aa aa aa aa aa ",
      " abbbbbbbbbbbba ",
      "  bM  cccccccb  ",
      " abQf      fcba ",
      " ab         cba ",
      "  bc        cb  ",
      " abc    N   cba ",
      " abc        cba ",
      "  bc        cb  ",
      " abc        cba ",
      " abcf  PO  fcba ",
      "  bccccccccccb  ",
      " abbbbbbbbbbbba ",
      " aa aa aa aa aa ",
      "                "
    ],
    [
      "                ",
      " aa aa aa aa aa ",
      " abbbbbbbbbbbba ",
      "  b   cRRRRRRb  ",
      " abTf      fRba ",
      " abQ        Rba ",
      "  bc        Rb  ",
      " abc    N   Rba ",
      " abc    N   Rba ",
      "  bc        Rb  ",
      " abc        Rba ",
      " abcf      fRba ",
      "  bccccccccSRb  ",
      " abbbbbbbbbbbba ",
      " aa aa aa aa aa ",
      "                "
    ],
    [
      "                ",
      " aa aa aa aa aa ",
      " abbbbbbbbbbbba ",
      "  b   cVVVVV b  ",
      " ab fiiiiiifUba ",
      " abTZXXXXXXiUba ",
      "  bciXXXXXXiUb  ",
      " abciXXNYXXiUba ",
      " abciXXYNXXiUba ",
      "  bciXXXXXXiUb  ",
      " abciXXXXXXiUba ",
      " abcfiiiiiifUba ",
      "  bcccccSRWW b  ",
      " abbbbbbbbbbbba ",
      " aa aa aa aa aa ",
      "                "
    ]
  ]
}