{
  "name": "building_hotelb_floor3_270",
  "refpalette": "deceasedcraft:building_hotelb/building_hotelb_floor3_palette_270",
  "xsize": 16,
  "zsize": 16,
  "slices": [
    [
      "                ",
      " aa aa aa aa aa ",
      " abbbbbbbbbbbba ",
      "  b  igccccccb  ",
      " ab dhheeeedcba ",
      " ab khgffffecba ",
      "  bggggffffecb  ",
      " abgjjgffffecba ",
      " abgjjfffffecba ",
      "  bgjjgffffecb  ",
      " abgjjfffffecba ",
      " abgdjgeeeedcba ",
      "  bggggccccccb  ",
      " abbbbbbbbbbbba ",
      " aa aa aa aa aa ",
      "                "
    ],
    [
      "                ",
      " aa aa aa aa aa ",
      " abbbbbbbbbbbba ",
      "  b XTgKKrxrlb  ",
      " ab s P    s ba ",
      " ab   g yyy mba ",
      "  bgggQ LEA nb  ",
      " abgYUg     mba ",
      " abgZ RNMFBtoba ",
      "  bg0VgOrrrunb  ",
      " abg1 SCCCC  ba ",
      " abg2WgCIICspba ",
      "  bggggDJJDwqb  ",
      " abbbbbbbbbbbba ",
      " aa aa aa aa aa ",
      "                "
    ],
    [
      "                ",
      " aa aa aa aa aa ",
      " abbbbbbbbbbbba ",
      "  bX{ g &% 63b  ",
      " ab s )    s ba ",
      " ab   g      ba ",
      "  bggg+     4b  ",
      " abg!Zg      ba ",
      " abg} -* ^97oba ",
      "  bg  gO###85b  ",
      " abg  [      ba ",
      " abg| g    s ba ",
      "  bg]]g(  $  b  ",
      " abbbbbbbbbbbba ",
      " aa aa aa aa aa ",
      "                "
    ],
    [
      "                ",
      " aa aa aa aa aa ",
      " abbbbbbbbbbbba ",
      "  b{  g     !b  ",
      " ab`s <    s ba ",
      " ab   g      ba ",
      "  bggg>      b  ",
      " abg?.g      ba ",
      " ab\u0370  ,'   ;oba ",
      "  b\u0370  gO###: b  ",
      " ab\u0370  ,      ba ",
      " abg/ g    s ba ",
      "  bgggg      b  ",
      " abbbbbbbbbbbba ",
      " aa aa aa aa aa ",
      "                "
    ],
    [
      "                ",
      " aa aa aa aa aa ",
      " abbbbbbbbbbbba ",
      "  b   g\u0372\u0372\u0372\u0372\u0372 b  ",
      " ab\u0375s g    s\u0371ba ",
      " ab`  g     \u0371ba ",
      "  bgggg     \u0371b  ",
      " abg  g     \u0371ba ",
      " abg  g     \u0371ba ",
      "  bg  g \u0374   \u0371b  ",
      " abg  g     \u0371ba ",
      " abg  g    s\u0371ba ",
      "  bgggg\u0373\u0373\u0373\u0373\u0373 b  ",
      " abbbbbbbbbbbba ",
      " aa aa aa aa aa ",
      "                "
    ],
    [
      "                ",
      " aa aa aa aa aa ",
      " abbbbbbbbbbbba ",
      "  b   gggggggb  ",
      " ab scghhhh\u0376gba ",
      " ab\u0375\u037bcg\u0377\u0377\u0377\u0377hgba ",
      "  bgggg\u0377\u0377\u0377\u0377hgb  ",
      " abg\u037a\u037ag\u0377\u0377\u0377\u0377hgba ",
      " abg\u037a\u037ag\u0377\u0377\u0377\u0377hgba ",
      "  bg\u037a\u037ag\u0377\u0377\u0377\u0377hgb  ",
      " abg\u037a\u037ag\u0377\u0377\u0377\u0377hgba ",
      " abg\u037a\u037aghhhh\u0376gba ",
      "  bggggggggggb  ",
      " abbbbbbbbbbbba ",
      " aa aa aa aa aa ",
      "                "
    ]
  ]
}