{
  "name": "building_hotelb_floor1",
  "refpalette": "deceasedcraft:building_hotelb/building_hotelb_floor1_palette",
  "xsize": 16,
  "zsize": 16,
  "slices": [
    [
      "                ",
      " aa aa aa aa aa ",
      " abbbbbbbbbbbba ",
      "  b     cd   b  ",
      " ab e  fghie ba ",
      " abjkklgghii ba ",
      "  bm kk n    b  ",
      " abo         ba ",
      " ab          ba ",
      "  b  j   k   b  ",
      " ab pmq  kk  ba ",
      " ab eo    ke ba ",
      " rb     pmq  br ",
      " sbbbbbbbbbbbbs ",
      " tttttttttttttt ",
      "                "
    ],
    [
      "                ",
      " aa aa aa aa aa ",
      " abbbbbbbbbbbba ",
      "  b     ccc  b  ",
      " ab e  u  gf ba ",
      " ab      wggxba ",
      "  by      hhdb  ",
      " ab       ii ba ",
      " ab       i  ba ",
      "  b          b  ",
      " ab  A       ba ",
      " ab e      e ba ",
      "  b      B   b  ",
      " abbbbbbbbbbbba ",
      " aa aa aa aa aa ",
      "                "
    ],
    [
      "                ",
      " aa aa aa aa aa ",
      " abbbbbbbbbbbba ",
      "  b         Cb  ",
      " ab e      e ba ",
      " ab          ba ",
      "  b       D xb  ",
      " ab    iihggxba ",
      " ab     ihgf ba ",
      "  b      dE  b  ",
      " ab          ba ",
      " ab e      e ba ",
      "  b          b  ",
      " abbbbbbbbbbbba ",
      " aa aa aa aa aa ",
      "                "
    ],
    [
      "                ",
      " aa aa aa aa aa ",
      " abbbbbbbbbbbba ",
      "  b      CFIIb  ",
      " ab e   i  eIba ",
      " ab    ii   Jba ",
      "  b   dhh   Cb  ",
      " ab   lggK   ba ",
      " ab    fg  u ba ",
      "  b     EEE  b  ",
      " ab          ba ",
      " ab e      e ba ",
      "  b          b  ",
      " abbbbbbbbbbbba ",
      " aa aa aa aa aa ",
      "                "
    ],
    [
      "                ",
      " aa aa aa aa aa ",
      " abbbbbbbbbbbba ",
      "  b   CFIIIIIb  ",
      " ab e  fghieIba ",
      " ab   lgghiiIba ",
      "  b   l n   Ib  ",
      " ab   l     Iba ",
      " ab    u    Jba ",
      "  b         Cb  ",
      " ab          ba ",
      " ab e      e ba ",
      "  b          b  ",
      " abbbbbbbbbbbba ",
      " aa aa aa aa aa ",
      "                "
    ],
    [
      "                ",
      " aa aa aa aa aa ",
      " abbbbbbbbbbbba ",
      "  bCFIIIIIIIIb  ",
      " abCe  u  geIba ",
      " abC     wggIba ",
      "  bC      hhIb  ",
      " abC      iiIba ",
      " abC      i Iba ",
      "  bC        Ib  ",
      " abC        Iba ",
      " abCe      eJba ",
      "  bCCCCCCCCCCb  ",
      " abbbbbbbbbbbba ",
      " aa aa aa aa aa ",
      "                "
    ]
  ]
}