{
  "name": "building_hotelb_floor5_270",
  "refpalette": "deceasedcraft:building_hotelb/building_hotelb_floor5_palette_270",
  "xsize": 16,
  "zsize": 16,
  "slices": [
    [
      "                ",
      " aa aa aa aa aa ",
      " abbbbbbbbbbbba ",
      "  b  igccccccb  ",
      " ab dhheeeedcba ",
      " ab khgffffecba ",
      "  bggggffffecb  ",
      " abgjjgffffecba ",
      " abgjjfffffecba ",
      "  bgjjgffffecb  ",
      " abgjjgffffecba ",
      " abgdjgeeeedcba ",
      "  bggggccccccb  ",
      " abbbbbbbbbbbba ",
      " aa aa aa aa aa ",
      "                "
    ],
    [
      "                ",
      " aa aa aa aa aa ",
      " abbbbbbbbbbbba ",
      "  b OLg      b  ",
      " ab p I !xup ba ",
      " ab   g  Bwq ba ",
      "  bgggJ  Bwq b  ",
      " abgPMgFDCw  ba ",
      " abg  K Exxrlba ",
      "  bgQ g syysmb  ",
      " abg  g tAAtnba ",
      " abgRNg tttpoba ",
      "  bgggg      b  ",
      " abbbbbbbbbbbba ",
      " aa aa aa aa aa ",
      "                "
    ],
    [
      "                ",
      " aa aa aa aa aa ",
      " abbbbbbbbbbbba ",
      "  bO8 g      b  ",
      " ab p 1  Y p ba ",
      " ab   g      ba ",
      "  bggg2      b  ",
      " abg94g0Z W  ba ",
      " abg# 3 EXXUSba ",
      "  bg 5g m  VTb  ",
      " abg 6g      ba ",
      " abg  g    p ba ",
      "  bg77g      b  ",
      " abbbbbbbbbbbba ",
      " aa aa aa aa aa ",
      "                "
    ],
    [
      "                ",
      " aa aa aa aa aa ",
      " abbbbbbbbbbbba ",
      "  b8  g      b  ",
      " ab|p +    p ba ",
      " ab   g      ba ",
      "  bggg-      b  ",
      " abg}]g)*    ba ",
      " ab;  [ (XX^$ba ",
      "  b;  g %  &%b  ",
      " ab; {g      ba ",
      " abg  g    p ba ",
      "  bgggg      b  ",
      " abbbbbbbbbbbba ",
      " aa aa aa aa aa ",
      "                "
    ],
    [
      "                ",
      " aa aa aa aa aa ",
      " abbbbbbbbbbbba ",
      "  b   g''''' b  ",
      " ab,p g    p:ba ",
      " ab|  g     :ba ",
      "  bgggg     :b  ",
      " abg  g     :ba ",
      " abg  g    <:ba ",
      "  bg  g     :b  ",
      " abg  g     :ba ",
      " abg  g    p:ba ",
      "  bgggg>>>>> b  ",
      " abbbbbbbbbbbba ",
      " aa aa aa aa aa ",
      "                "
    ],
    [
      "                ",
      " aa aa aa aa aa ",
      " abbbbbbbbbbbba ",
      "  b   gggggggb  ",
      " ab pcghhhh.gba ",
      " ab,`cg????hgba ",
      "  bgggg????hgb  ",
      " abg//g????hgba ",
      " abg//g????hgba ",
      "  bg//g????hgb  ",
      " abg//g????hgba ",
      " abg//ghhhh.gba ",
      "  bggggggggggb  ",
      " abbbbbbbbbbbba ",
      " aa aa aa aa aa ",
      "                "
    ]
  ]
}