{
  "name": "building_hotelb_ground_270",
  "refpalette": "deceasedcraft:building_hotelb/building_hotelb_ground_palette_270",
  "xsize": 16,
  "zsize": 16,
  "slices": [
    [
      "aaaaaaaaaaaaaaaa",
      "abbbbbbbbbbbbbba",
      "abccccccccccccba",
      "abcddddddddddcba",
      "abcdeffffffedcba",
      "abcdffffffffdcba",
      "aagdffffffffdcba",
      "aahdffffffffdcba",
      "aahdffffffffdcba",
      "aagdffffffffdcba",
      "abcdffffffffdcba",
      "abcdeffffffedcba",
      "abcddddddddddcba",
      "abccccccccccccba",
      "abbbbbbbbbbbbbba",
      "aaaaaaaaaaaaaaaa"
    ],
    [
      "                ",
      " bbbbbbbbbbbbbb ",
      " bjjjjjjjjjjjib ",
      " bjL JFC   lkib ",
      " bj m      mkib ",
      " bj  DDD s  kib ",
      " QO     wt  kib ",
      "  PM    xfffkib ",
      "  PN    xfffkib ",
      " RO     y fnkib ",
      " bjEEEEEA qokib ",
      " bj!m     rmkib ",
      " bjoIKIBBuppdib ",
      " bjjjjjjjjjjjib ",
      " bbbbbbbbbbbbbb ",
      "                "
    ],
    [
      "                ",
      " bbbbbbbbbbbbbS ",
      " bjjjjjjjjiiiTS ",
      " bj7    lkdddTS ",
      " bj m      mdTS ",
      " bj         dTS ",
      " QO      ww dTS ",
      "   8      xedTS ",
      "   9     XxxdTS ",
      " RO       ffdTS ",
      " bj 53 0  VUdTS ",
      " bj m     WmdTS ",
      " bjo6421ZYdddTS ",
      " bjjjjjjjjiiiTS ",
      " bbbbbbbbbbbbbS ",
      "                "
    ],
    [
      "                ",
      " bbbbbbbbbbS$## ",
      " bjjjjjiiiTTTT# ",
      " bj] lkddddddT  ",
      " bj m      m T# ",
      " bj          T# ",
      " }O          T  ",
      " |O        ^ T# ",
      " |O         %T# ",
      " ;O       * %T  ",
      " bj{--+))fxx%T# ",
      " bj m   )fxm T# ",
      " bj [lkddd(& T  ",
      " bjjjjjiiiTTTT# ",
      " bbbbbbbbbbS$## ",
      "                "
    ],
    [
      "                ",
      " bbbbbbbS$## ## ",
      " bjjiiiTTTTTTT# ",
      " bjkdddddddddT  ",
      " bjlm      m T# ",
      " bjl         T# ",
      " bjl         T  ",
      " bjl    )    T# ",
      " bjl   ))    T# ",
      " bjl  tff    T  ",
      " bjl  :xxy   T# ",
      " bjlm  ex  m T# ",
      " bjkddd(&    T  ",
      " bjjiiiTTTTTTT# ",
      " bbbbbbbS$## ## ",
      "                "
    ],
    [
      "                ",
      " bbbbS$## ## ## ",
      " biiTTTTTTTTTT# ",
      " biddddddddddT  ",
      " bideffffffe T# ",
      " bidfffffff  T# ",
      " bidffffff   T  ",
      " bidffffxf)  T# ",
      " bidfffxxf)) T# ",
      " bidfff '    T  ",
      " bidff:      T# ",
      " bide  ^   m T# ",
      " bid(&       T  ",
      " biiTTTTTTTTTT# ",
      " bbbbS$## ## ## ",
      "                "
    ]
  ]
}