{
  "name": "building_hotelb_floor1_270",
  "refpalette": "deceasedcraft:building_hotelb/building_hotelb_floor1_palette_270",
  "xsize": 16,
  "zsize": 16,
  "slices": [
    [
      "                ",
      " tsraa aa aa aa ",
      " tbbbbbbbbbbbba ",
      " tb     omj  b  ",
      " tb ep    ke ba ",
      " tb omj  kk  ba ",
      " tb  q   kl  b  ",
      " tb       gf ba ",
      " tbp     nggcba ",
      " tbm kk   hhdb  ",
      " tbqkk    ii ba ",
      " tb e     ie ba ",
      " tb          b  ",
      " tbbbbbbbbbbbba ",
      " tsraa aa aa aa ",
      "                "
    ],
    [
      "                ",
      " aa aa aa aa aa ",
      " abbbbbbbbbbbba ",
      "  b      y   b  ",
      " ab e      e ba ",
      " ab  A       ba ",
      "  b          b  ",
      " ab        u ba ",
      " ab         cba ",
      "  bB      w cb  ",
      " ab    iihggcba ",
      " ab e   ihgf ba ",
      "  b      dx  b  ",
      " abbbbbbbbbbbba ",
      " aa aa aa aa aa ",
      "                "
    ],
    [
      "                ",
      " aa aa aa aa aa ",
      " abbbbbbbbbbbba ",
      "  b          b  ",
      " ab e      e ba ",
      " ab          ba ",
      "  b          b  ",
      " ab     i    ba ",
      " ab    ii    ba ",
      "  b   dhh    b  ",
      " ab   EggD   ba ",
      " ab e  fg  e ba ",
      "  b     xx  Cb  ",
      " abbbbbbbbbbbba ",
      " aa aa aa aa aa ",
      "                "
    ],
    [
      "                ",
      " aa aa aa aa aa ",
      " abbbbbbbbbbbba ",
      "  b          b  ",
      " ab e      e ba ",
      " ab          ba ",
      "  b     ld   b  ",
      " ab    fghi  ba ",
      " ab   Egghii ba ",
      "  b   E K   Cb  ",
      " ab   E     Fba ",
      " ab e  u   eIba ",
      "  b      CJIIb  ",
      " abbbbbbbbbbbba ",
      " aa aa aa aa aa ",
      "                "
    ],
    [
      "                ",
      " aa aa aa aa aa ",
      " abbbbbbbbbbbba ",
      "  b          b  ",
      " ab e      e ba ",
      " ab          ba ",
      "  b     lll Cb  ",
      " ab    u  gfFba ",
      " ab      nggIba ",
      "  b       hhIb  ",
      " ab       iiIba ",
      " ab e     ieIba ",
      "  b   CJIIIIIb  ",
      " abbbbbbbbbbbba ",
      " aa aa aa aa aa ",
      "                "
    ],
    [
      "                ",
      " aa aa aa aa aa ",
      " abbbbbbbbbbbba ",
      "  bCCCCCCCCCCb  ",
      " abCe      eFba ",
      " abC        Iba ",
      "  bC        Ib  ",
      " abC       uIba ",
      " abC        Iba ",
      "  bC      w Ib  ",
      " abC   iihggIba ",
      " abCe   ihgeIba ",
      "  bCJIIIIIIIIb  ",
      " abbbbbbbbbbbba ",
      " aa aa aa aa aa ",
      "                "
    ]
  ]
}