{
  "name": "building_hotelb_floor5_180",
  "refpalette": "deceasedcraft:building_hotelb/building_hotelb_floor5_palette_180",
  "xsize": 16,
  "zsize": 16,
  "slices": [
    [
      "                ",
      " aa aa aa aa aa ",
      " abbbbbbbbbbbba ",
      "  bggggggg   b  ",
      " abgdjjjjgkd ba ",
      " abgjjjjjghhiba ",
      "  bggggfggghgb  ",
      " abceffffffecba ",
      " abceffffffecba ",
      "  bceffffffecb  ",
      " abceffffffecba ",
      " abcdeeeeeedcba ",
      "  bccccccccccb  ",
      " abbbbbbbbbbbba ",
      " aa aa aa aa aa ",
      "                "
    ],
    [
      "                ",
      " aa aa aa aa aa ",
      " abbbbbbbbbbbba ",
      "  bggggggg   b  ",
      " abgR Q Pg pOba ",
      " abgN   Mg  Lba ",
      "  bggggKgJgIgb  ",
      " ab     F    ba ",
      " ab ttsED  ! ba ",
      "  b tAyxCBBx b  ",
      " ab tAyxwwwu ba ",
      " ab ptsr qqp ba ",
      "  b onml     b  ",
      " abbbbbbbbbbbba ",
      " aa aa aa aa aa ",
      "                "
    ],
    [
      "                ",
      " aa aa aa aa aa ",
      " abbbbbbbbbbbba ",
      "  bggggggg  Ob  ",
      " ab7   #9g p8ba ",
      " ab7 65 4g   ba ",
      "  bgggg3g2g1gb  ",
      " ab     0    ba ",
      " ab   mEZ    ba ",
      "  b    X   Y b  ",
      " ab    XW    ba ",
      " ab p VU   p ba ",
      "  b   TS     b  ",
      " abbbbbbbbbbbba ",
      " aa aa aa aa aa ",
      "                "
    ],
    [
      "                ",
      " aa aa aa aa aa ",
      " abbbbbbbbbbbba ",
      "  bgg;;;gg |8b  ",
      " abg    }g p ba ",
      " abg {  ]g   ba ",
      "  bgggg[g-g+gb  ",
      " ab     )    ba ",
      " ab   %(*    ba ",
      "  b    X     b  ",
      " ab    X     ba ",
      " ab p &^   p ba ",
      "  b   %$     b  ",
      " abbbbbbbbbbbba ",
      " aa aa aa aa aa ",
      "                "
    ],
    [
      "                ",
      " aa aa aa aa aa ",
      " abbbbbbbbbbbba ",
      "  bggggggg|, b  ",
      " abg     g p ba ",
      " abg     g   ba ",
      "  bggggggggggb  ",
      " ab>        'ba ",
      " ab>        'ba ",
      "  b>        'b  ",
      " ab>        'ba ",
      " ab>p  <   p'ba ",
      "  b :::::::: b  ",
      " abbbbbbbbbbbba ",
      " aa aa aa aa aa ",
      "                "
    ],
    [
      "                ",
      " aa aa aa aa aa ",
      " abbbbbbbbbbbba ",
      "  bggggggg,  b  ",
      " abg/////g`p ba ",
      " abg/////gcc ba ",
      "  bggggggggggb  ",
      " abgh??????hgba ",
      " abgh??????hgba ",
      "  bgh??????hgb  ",
      " abgh??????hgba ",
      " abg.hhhhhh.gba ",
      "  bggggggggggb  ",
      " abbbbbbbbbbbba ",
      " aa aa aa aa aa ",
      "                "
    ]
  ]
}