{
  "name": "building_hotelb_ground_180",
  "refpalette": "deceasedcraft:building_hotelb/building_hotelb_ground_palette_180",
  "xsize": 16,
  "zsize": 16,
  "slices": [
    [
      "aaaaaaaaaaaaaaaa",
      "abbbbbaaaabbbbba",
      "abccccghhgccccba",
      "abcddddddddddcba",
      "abcdeffffffedcba",
      "abcdffffffffdcba",
      "abcdffffffffdcba",
      "abcdffffffffdcba",
      "abcdffffffffdcba",
      "abcdffffffffdcba",
      "abcdffffffffdcba",
      "abcdeffffffedcba",
      "abcddddddddddcba",
      "abccccccccccccba",
      "abbbbbbbbbbbbbba",
      "aaaaaaaaaaaaaaaa"
    ],
    [
      "                ",
      " bbbbbR  Qbbbbb ",
      " bjjjjOPPOjjjjb ",
      " bjo!E NM   Ljb ",
      " bjImE     m jb ",
      " bjK E    D Jjb ",
      " bjI E    D Fjb ",
      " bjB E    D Cjb ",
      " bjB Ayxxw   jb ",
      " bju   ffts  jb ",
      " bjprqfff    jb ",
      " bjpmonff  mljb ",
      " bjdkkkkkkkkkjb ",
      " biiiiiiiiiiiib ",
      " bbbbbbbbbbbbbb ",
      "                "
    ],
    [
      "                ",
      " bbbbbR  Qbbbbb ",
      " bjjjjO  Ojjjjb ",
      " bjo   98   7jb ",
      " bj6m5     m jb ",
      " bj4 3       jb ",
      " bj2         jb ",
      " bj1 0       jb ",
      " bjZ        ljb ",
      " bjY   X w  kjb ",
      " bidWVfxxw  dib ",
      " bidmUfxe  mdib ",
      " biddddddddddib ",
      " bTTTTTTTTTTTTb ",
      " SSSSSSSSSSSSSS ",
      "                "
    ],
    [
      "                ",
      " bbbbb;||}bbbbb ",
      " bjjjjOOOOjjjjb ",
      " bj  {      ]jb ",
      " bj[m-     m jb ",
      " bjl -      ljb ",
      " bjk +      kjb ",
      " bid )      dib ",
      " bid))      dib ",
      " bidff      dib ",
      " bT(xx*     dTb ",
      " ST&mx  ^  mdTS ",
      " $T  %%%    dT$ ",
      " #TTTTTTTTTTTT# ",
      " ## ## ## ## ## ",
      "                "
    ],
    [
      "                ",
      " bbbbbbbbbbbbbb ",
      " bjjjjjjjjjjjjb ",
      " bjkllllllllkjb ",
      " bidm      mdib ",
      " bid        dib ",
      " bid :t     dib ",
      " bT(exf)    dTb ",
      " ST&xxf))   dTS ",
      " $T  y      dT$ ",
      " #T         dT# ",
      " #T m      mdT# ",
      "  T         dT  ",
      " #TTTTTTTTTTTT# ",
      " ## ## ## ## ## ",
      "                "
    ],
    [
      "                ",
      " bbbbbbbbbbbbbb ",
      " biiiiiiiiiiiib ",
      " biddddddddddib ",
      " bT(effffffedTb ",
      " ST& fffffffdTS ",
      " $T  :ffffffdT$ ",
      " #T ^  xffffdT# ",
      " #T   'xxfffdT# ",
      "  T    fffffdT  ",
      " #T    )) ffdT# ",
      " #T m  )   edT# ",
      "  T         dT  ",
      " #TTTTTTTTTTTT# ",
      " ## ## ## ## ## ",
      "                "
    ]
  ]
}