{
  "name": "building_hotelbpart2_floor1_270",
  "refpalette": "deceasedcraft:building_hotelb/building_hotelbpart2_floor1_palette_270",
  "xsize": 16,
  "zsize": 16,
  "slices": [
    [
      "                ",
      "    aa aa aa aa ",
      "              a ",
      "                ",
      "    b     cb  a ",
      "         cc   a ",
      "         c      ",
      "              a ",
      "              a ",
      "     cc         ",
      "    cc        a ",
      "    b      b  a ",
      "                ",
      "              a ",
      "    aa aa aa aa ",
      "                "
    ],
    [
      "                ",
      " aa aa aa aa aa ",
      " a            a ",
      "                ",
      " a  b      b  a ",
      " a            a ",
      "                ",
      " a            a ",
      " a            a ",
      "                ",
      " a            a ",
      " a  b         a ",
      "                ",
      " a            a ",
      " aa aa aa aa aa ",
      "                "
    ],
    [
      "                ",
      " aa aa aa aa aa ",
      " a            a ",
      "                ",
      " a  b      b  a ",
      " a            a ",
      "                ",
      " a            a ",
      " a            a ",
      "                ",
      " a            a ",
      " a  b      b  a ",
      "                ",
      " a            a ",
      " aa aa aa aa aa ",
      "                "
    ],
    [
      "                ",
      " aa aa aa aa aa ",
      " a            a ",
      "                ",
      " a  b      b  a ",
      " a            a ",
      "                ",
      " a            a ",
      " a            a ",
      "                ",
      " a            a ",
      " a  b      b  a ",
      "                ",
      " a            a ",
      " aa aa aa aa aa ",
      "                "
    ],
    [
      "                ",
      " aa aa aa aa aa ",
      " a            a ",
      "                ",
      " a  b      b  a ",
      " a            a ",
      "                ",
      " a            a ",
      " a            a ",
      "                ",
      " a            a ",
      " a  b      b  a ",
      "                ",
      " a            a ",
      " aa aa aa aa aa ",
      "                "
    ],
    [
      "                ",
      " aa aa aa aa aa ",
      " a            a ",
      "                ",
      " a  b      b  a ",
      " a            a ",
      "                ",
      " a            a ",
      " a            a ",
      "                ",
      " a            a ",
      " a  b      b  a ",
      "                ",
      " a            a ",
      " aa aa aa aa aa ",
      "                "
    ]
  ]
}