{
  "name": "building_hotelb_ground_90",
  "refpalette": "deceasedcraft:building_hotelb/building_hotelb_ground_palette_90",
  "xsize": 16,
  "zsize": 16,
  "slices": [
    [
      "aaaaaaaaaaaaaaaa",
      "abbbbbbbbbbbbbba",
      "abccccccccccccba",
      "abcddddddddddcba",
      "abcdeffffffedcba",
      "abcdffffffffdcba",
      "abcdffffffffdgaa",
      "abcdffffffffdhaa",
      "abcdffffffffdhaa",
      "abcdffffffffdgaa",
      "abcdffffffffdcba",
      "abcdeffffffedcba",
      "abcddddddddddcba",
      "abccccccccccccba",
      "abbbbbbbbbbbbbba",
      "aaaaaaaaaaaaaaaa"
    ],
    [
      "                ",
      " bbbbbbbbbbbbbb ",
      " bijjjjjjjjjjjb ",
      " bidppuBBIKIojb ",
      " bikmr     m!jb ",
      " bikoq AEEEEEjb ",
      " biknf y     OR ",
      " bikfffx    NP  ",
      " bikfffx    MP  ",
      " bik  tw     OQ ",
      " bik  s DDD  jb ",
      " bikm      m jb ",
      " bikl   CFJ Ljb ",
      " bijjjjjjjjjjjb ",
      " bbbbbbbbbbbbbb ",
      "                "
    ],
    [
      "                ",
      " Sbbbbbbbbbbbbb ",
      " STiiijjjjjjjjb ",
      " STdddYZ1246ojb ",
      " STdmW     m jb ",
      " STdUV  0 35 jb ",
      " STdff       OR ",
      " STdxxX     9   ",
      " STdex      8   ",
      " STd ww      OQ ",
      " STd         jb ",
      " STdm      m jb ",
      " STdddkl    7jb ",
      " STiiijjjjjjjjb ",
      " Sbbbbbbbbbbbbb ",
      "                "
    ],
    [
      "                ",
      " ##$Sbbbbbbbbbb ",
      " #TTTTiiijjjjjb ",
      "  T &(dddkl[ jb ",
      " #T mxf)   m jb ",
      " #T%xxf))+--{jb ",
      "  T% *       O; ",
      " #T%         O| ",
      " #T ^        O| ",
      "  T          O} ",
      " #T          jb ",
      " #T m      m jb ",
      "  Tddddddkl ]jb ",
      " #TTTTiiijjjjjb ",
      " ##$Sbbbbbbbbbb ",
      "                "
    ],
    [
      "                ",
      " ## ##$Sbbbbbbb ",
      " #TTTTTTTiiijjb ",
      "  T    &(dddkjb ",
      " #T m  xe  mljb ",
      " #T   yxx:  ljb ",
      "  T    fft  ljb ",
      " #T    ))   ljb ",
      " #T    )    ljb ",
      "  T         ljb ",
      " #T         ljb ",
      " #T m      mljb ",
      "  Tdddddddddkjb ",
      " #TTTTTTTiiijjb ",
      " ## ##$Sbbbbbbb ",
      "                "
    ],
    [
      "                ",
      " ## ## ##$Sbbbb ",
      " #TTTTTTTTTTiib ",
      "  T       &(dib ",
      " #T m   ^  edib ",
      " #T      :ffdib ",
      "  T    ' fffdib ",
      " #T ))fxxfffdib ",
      " #T  )fxffffdib ",
      "  T   ffffffdib ",
      " #T  fffffffdib ",
      " #T effffffedib ",
      "  Tddddddddddib ",
      " #TTTTTTTTTTiib ",
      " ## ## ##$Sbbbb ",
      "                "
    ]
  ]
}