{
  "name": "building_hotelb_ground",
  "refpalette": "deceasedcraft:building_hotelb/building_hotelb_ground_palette",
  "xsize": 16,
  "zsize": 16,
  "slices": [
    [
      "aaaaaaaaaaaaaaaa",
      "abbbbbbbbbbbbbba",
      "abccccccccccccba",
      "abcddddddddddcba",
      "abcdeffffffedcba",
      "abcdffffffffdcba",
      "abcdffffffffdcba",
      "abcdffffffffdcba",
      "abcdffffffffdcba",
      "abcdffffffffdcba",
      "abcdffffffffdcba",
      "abcdeffffffedcba",
      "abcddddddddddcba",
      "abccccghhgccccba",
      "abbbbbaaaabbbbba",
      "aaaaaaaaaaaaaaaa"
    ],
    [
      "                ",
      " bbbbbbbbbbbbbb ",
      " biiiiiiiiiiiib ",
      " bjkkkkkkkkkdjb ",
      " bjlm  ffnompjb ",
      " bj    fffqrpjb ",
      " bj  stff   ujb ",
      " bj   wxxyA Bjb ",
      " bjC D    E Bjb ",
      " bjF D    E Ijb ",
      " bjJ D    E Kjb ",
      " bj m     EmIjb ",
      " bjL   MN E!ojb ",
      " bjjjjOPPOjjjjb ",
      " bbbbbQ  Rbbbbb ",
      "                "
    ],
    [
      "                ",
      " SSSSSSSSSSSSSS ",
      " bTTTTTTTTTTTTb ",
      " biddddddddddib ",
      " bidm  exfUmdib ",
      " bid  wxxfVWdib ",
      " bjk  w X   Yjb ",
      " bjl        Zjb ",
      " bj       0 1jb ",
      " bj         2jb ",
      " bj       3 4jb ",
      " bj m     5m6jb ",
      " bj7   89   ojb ",
      " bjjjjO  Ojjjjb ",
      " bbbbbQ  Rbbbbb ",
      "                "
    ],
    [
      "                ",
      " ## ## ## ## ## ",
      " #TTTTTTTTTTTT# ",
      " $Td    %%%  T$ ",
      " STdm  ^  xm&TS ",
      " bTd     *xx(Tb ",
      " bid      ffdib ",
      " bid      ))dib ",
      " bid      ) dib ",
      " bjk      + kjb ",
      " bjl      - ljb ",
      " bj m     -m[jb ",
      " bj]      {  jb ",
      " bjjjjOOOOjjjjb ",
      " bbbbb}||;bbbbb ",
      "                "
    ],
    [
      "                ",
      " ## ## ## ## ## ",
      " #TTTTTTTTTTTT# ",
      "  Td         T  ",
      " #Tdm      m T# ",
      " #Td         T# ",
      " $Td      y  T$ ",
      " STd   ))fxx&TS ",
      " bTd    )fxe(Tb ",
      " bid     t: dib ",
      " bid        dib ",
      " bidm      mdib ",
      " bjkllllllllkjb ",
      " bjjjjjjjjjjjjb ",
      " bbbbbbbbbbbbbb ",
      "                "
    ],
    [
      "                ",
      " ## ## ## ## ## ",
      " #TTTTTTTTTTTT# ",
      "  Td         T  ",
      " #Tde   )  m T# ",
      " #Tdff ))    T# ",
      "  Tdfffff    T  ",
      " #Tdfffxx'   T# ",
      " #Tdffffx  ^ T# ",
      " $Tdffffff:  T$ ",
      " STdfffffff &TS ",
      " bTdeffffffe(Tb ",
      " biddddddddddib ",
      " biiiiiiiiiiiib ",
      " bbbbbbbbbbbbbb ",
      "                "
    ]
  ]
}