{
  "name": "building_hotelb_floor4_270",
  "refpalette": "deceasedcraft:building_hotelb/building_hotelb_floor4_palette_270",
  "xsize": 16,
  "zsize": 16,
  "slices": [
    [
      "                ",
      " aa aa aa aa aa ",
      " abbbbbbbbbbbba ",
      "  b  igccccccb  ",
      " ab dhheeeedcba ",
      " ab khgffffecba ",
      "  bggggffffecb  ",
      " abgjjgffffecba ",
      " abgjjfffffecba ",
      "  bgjjgffffecb  ",
      " abgjjgffffecba ",
      " abgdjgeeeedcba ",
      "  bggggccccccb  ",
      " abbbbbbbbbbbba ",
      " aa aa aa aa aa ",
      "                "
    ],
    [
      "                ",
      " aa aa aa aa aa ",
      " abbbbbbbbbbbba ",
      "  b QMg      b  ",
      " ab o J Dxuo ba ",
      " ab   g  Bwp ba ",
      "  bgggK  Bwp b  ",
      " abgRNgIECw  ba ",
      " abg! L Fxxqlba ",
      "  bgSOg ryyrmb  ",
      " abg  g sAAs ba ",
      " abgTPg ssso ba ",
      "  bgggg    tnb  ",
      " abbbbbbbbbbbba ",
      " aa aa aa aa aa ",
      "                "
    ],
    [
      "                ",
      " aa aa aa aa aa ",
      " abbbbbbbbbbbba ",
      "  bQ9 g      b  ",
      " ab o 5  2 o ba ",
      " ab   g   Y  ba ",
      "  bggg!   Z  b  ",
      " abg# g43 0  ba ",
      " abg$ 6 F11WUba ",
      "  bg  g V  XVb  ",
      " abg 7g      ba ",
      " abg  g    o ba ",
      "  bg88g      b  ",
      " abbbbbbbbbbbba ",
      " aa aa aa aa aa ",
      "                "
    ],
    [
      "                ",
      " aa aa aa aa aa ",
      " abbbbbbbbbbbba ",
      "  b9  g      b  ",
      " ab}o +    o ba ",
      " ab   g      ba ",
      "  bggg       b  ",
      " abg{[g)(    ba ",
      " ab|  - F11&%ba ",
      "  b|  g ^  *^b  ",
      " ab| ]g      ba ",
      " abg  g    o ba ",
      "  bgggg      b  ",
      " abbbbbbbbbbbba ",
      " aa aa aa aa aa ",
      "                "
    ],
    [
      "                ",
      " aa aa aa aa aa ",
      " abbbbbbbbbbbba ",
      "  b   g::::: b  ",
      " ab<o g    o;ba ",
      " ab}  g     ;ba ",
      "  bgggg     ;b  ",
      " abg  g     ;ba ",
      " abg  g     ;ba ",
      "  bg  g     ;b  ",
      " abg  g     ;ba ",
      " abg  g    o;ba ",
      "  bgggg''''' b  ",
      " abbbbbbbbbbbba ",
      " aa aa aa aa aa ",
      "                "
    ],
    [
      "                ",
      " aa aa aa aa aa ",
      " abbbbbbbbbbbba ",
      "  b   gggggggb  ",
      " ab ocghhhh>gba ",
      " ab<?cg,,,,hgba ",
      "  bgggg,,,,hgb  ",
      " abg..g,,,,hgba ",
      " abg..g,,,,hgba ",
      "  bg..g,,,,hgb  ",
      " abg..g,,,,hgba ",
      " abg..ghhhh>gba ",
      "  bggggggggggb  ",
      " abbbbbbbbbbbba ",
      " aa aa aa aa aa ",
      "                "
    ]
  ]
}