{
  "name": "building_hotelbpart2_floor3_270",
  "refpalette": "deceasedcraft:building_hotelb/building_hotelbpart2_floor3_palette_270",
  "xsize": 16,
  "zsize": 16,
  "slices": [
    [
      "                ",
      " aa aa aa aa aa ",
      " a            a ",
      "                ",
      " a            a ",
      " a            a ",
      "                ",
      " a            a ",
      " a            a ",
      "                ",
      " a            a ",
      " a            a ",
      "                ",
      " a            a ",
      " aa aa aa aa aa ",
      "                "
    ],
    [
      "                ",
      " aa aa aa aa aa ",
      " a            a ",
      "                ",
      " a  b      b  a ",
      " a            a ",
      "                ",
      " a            a ",
      " a            a ",
      "                ",
      " a     cccc   a ",
      " a     c  cb  a ",
      "                ",
      " a            a ",
      " aa aa aa aa aa ",
      "                "
    ],
    [
      "                ",
      " aa aa aa aa aa ",
      " a            a ",
      "                ",
      " a  b      b  a ",
      " a            a ",
      "                ",
      " a            a ",
      " a            a ",
      "                ",
      " a            a ",
      " a         b  a ",
      "                ",
      " a            a ",
      " aa aa aa aa aa ",
      "                "
    ],
    [
      "                ",
      " aa aa aa aa aa ",
      " a            a ",
      "                ",
      " a  b      b  a ",
      " a            a ",
      "      d         ",
      " a            a ",
      " a            a ",
      "                ",
      " a            a ",
      " a         b  a ",
      "                ",
      " a            a ",
      " aa aa aa aa aa ",
      "                "
    ],
    [
      "                ",
      " aa aa aa aa aa ",
      " a            a ",
      "                ",
      " a  b      b  a ",
      " a            a ",
      "                ",
      " a            a ",
      " a            a ",
      "                ",
      " a            a ",
      " a         b  a ",
      "                ",
      " a            a ",
      " aa aa aa aa aa ",
      "                "
    ],
    [
      "                ",
      " aa aa aa aa aa ",
      " a            a ",
      "                ",
      " a  b      e  a ",
      " a            a ",
      "                ",
      " a            a ",
      " a            a ",
      "                ",
      " a            a ",
      " a         e  a ",
      "                ",
      " a            a ",
      " aa aa aa aa aa ",
      "                "
    ]
  ]
}