{
  "name": "building_hotelb_floor4",
  "refpalette": "deceasedcraft:building_hotelb/building_hotelb_floor4_palette",
  "xsize": 16,
  "zsize": 16,
  "slices": [
    [
      "                ",
      " aa aa aa aa aa ",
      " abbbbbbbbbbbba ",
      "  bccccccccccb  ",
      " abcdeeeeeedcba ",
      " abceffffffecba ",
      "  bceffffffecb  ",
      " abceffffffecba ",
      " abceffffffecba ",
      "  bghgggfggggb  ",
      " abihhgjjjjjgba ",
      " ab dkgjjjjdgba ",
      "  b   gggggggb  ",
      " abbbbbbbbbbbba ",
      " aa aa aa aa aa ",
      "                "
    ],
    [
      "                ",
      " aa aa aa aa aa ",
      " abbbbbbbbbbbba ",
      "  b     lm  nb  ",
      " ab opp qrsotba ",
      " ab uwwwxyAs ba ",
      "  b xBBCxyAs b  ",
      " ab D  EFrss ba ",
      " ab    I     ba ",
      "  bgJgKgLggggb  ",
      " abM  gN O Pgba ",
      " abQo gR!S Tgba ",
      "  b   gggggggb  ",
      " abbbbbbbbbbbba ",
      " aa aa aa aa aa ",
      "                "
    ],
    [
      "                ",
      " aa aa aa aa aa ",
      " abbbbbbbbbbbba ",
      "  b     UV   b  ",
      " ab o   WX o ba ",
      " ab  YZ01    ba ",
      "  b 2   1    b  ",
      " ab    3FV   ba ",
      " ab    4     ba ",
      "  bg5g!g6ggggb  ",
      " ab   g   7 8ba ",
      " ab9o g#$   8ba ",
      "  bQ  gggggggb  ",
      " abbbbbbbbbbbba ",
      " aa aa aa aa aa ",
      "                "
    ],
    [
      "                ",
      " aa aa aa aa aa ",
      " abbbbbbbbbbbba ",
      "  b     %^   b  ",
      " ab o   &* o ba ",
      " ab     1    ba ",
      "  b     1    b  ",
      " ab    (F^   ba ",
      " ab    )     ba ",
      "  bg+g g-ggggb  ",
      " ab   g[  ] gba ",
      " ab o g{    gba ",
      "  b9} gg|||ggb  ",
      " abbbbbbbbbbbba ",
      " aa aa aa aa aa ",
      "                "
    ],
    [
      "                ",
      " aa aa aa aa aa ",
      " abbbbbbbbbbbba ",
      "  b ;;;;;;;; b  ",
      " ab:o      o'ba ",
      " ab:        'ba ",
      "  b:        'b  ",
      " ab:        'ba ",
      " ab:        'ba ",
      "  bggggggggggb  ",
      " ab   g     gba ",
      " ab o g     gba ",
      "  b <}gggggggb  ",
      " abbbbbbbbbbbba ",
      " aa aa aa aa aa ",
      "                "
    ],
    [
      "                ",
      " aa aa aa aa aa ",
      " abbbbbbbbbbbba ",
      "  bggggggggggb  ",
      " abg>hhhhhh>gba ",
      " abgh,,,,,,hgba ",
      "  bgh,,,,,,hgb  ",
      " abgh,,,,,,hgba ",
      " abgh,,,,,,hgba ",
      "  bggggggggggb  ",
      " ab ccg.....gba ",
      " ab o?g.....gba ",
      "  b  <gggggggb  ",
      " abbbbbbbbbbbba ",
      " aa aa aa aa aa ",
      "                "
    ]
  ]
}