{
  "name": "building_hotelb_floor1_180",
  "refpalette": "deceasedcraft:building_hotelb/building_hotelb_floor1_palette_180",
  "xsize": 16,
  "zsize": 16,
  "slices": [
    [
      "                ",
      " tttttttttttttt ",
      " sbbbbbbbbbbbbs ",
      " rb  qmp     br ",
      " ab ek    oe ba ",
      " ab  kk  qmp ba ",
      "  b   k   j  b  ",
      " ab          ba ",
      " ab         oba ",
      "  b    n kk mb  ",
      " ab iihgglkkjba ",
      " ab eihgf  e ba ",
      "  b   dc     b  ",
      " abbbbbbbbbbbba ",
      " aa aa aa aa aa ",
      "                "
    ],
    [
      "                ",
      " aa aa aa aa aa ",
      " abbbbbbbbbbbba ",
      "  b   B      b  ",
      " ab e      e ba ",
      " ab       A  ba ",
      "  b          b  ",
      " ab  i       ba ",
      " ab ii       ba ",
      "  bdhh      yb  ",
      " abxggw      ba ",
      " ab fg  u  e ba ",
      "  b  ccc     b  ",
      " abbbbbbbbbbbba ",
      " aa aa aa aa aa ",
      "                "
    ],
    [
      "                ",
      " aa aa aa aa aa ",
      " abbbbbbbbbbbba ",
      "  b          b  ",
      " ab e      e ba ",
      " ab          ba ",
      "  b  Ed      b  ",
      " ab fghi     ba ",
      " abxgghii    ba ",
      "  bx D       b  ",
      " ab          ba ",
      " ab e      e ba ",
      "  bC         b  ",
      " abbbbbbbbbbbba ",
      " aa aa aa aa aa ",
      "                "
    ],
    [
      "                ",
      " aa aa aa aa aa ",
      " abbbbbbbbbbbba ",
      "  b          b  ",
      " ab e      e ba ",
      " ab          ba ",
      "  b  EEE     b  ",
      " ab u  gf    ba ",
      " ab   Kggl   ba ",
      "  bC   hhd   b  ",
      " abJ   ii    ba ",
      " abIe  i   e ba ",
      "  bIIFC      b  ",
      " abbbbbbbbbbbba ",
      " aa aa aa aa aa ",
      "                "
    ],
    [
      "                ",
      " aa aa aa aa aa ",
      " abbbbbbbbbbbba ",
      "  b          b  ",
      " ab e      e ba ",
      " ab          ba ",
      "  bC         b  ",
      " abJ    u    ba ",
      " abI     l   ba ",
      "  bI   n l   b  ",
      " abIiihggl   ba ",
      " abIeihgf  e ba ",
      "  bIIIIIFC   b  ",
      " abbbbbbbbbbbba ",
      " aa aa aa aa aa ",
      "                "
    ],
    [
      "                ",
      " aa aa aa aa aa ",
      " abbbbbbbbbbbba ",
      "  bCCCCCCCCCCb  ",
      " abJe      eCba ",
      " abI        Cba ",
      "  bI        Cb  ",
      " abI i      Cba ",
      " abIii      Cba ",
      "  bIhh      Cb  ",
      " abIggw     Cba ",
      " abIeg  u  eCba ",
      "  bIIIIIIIIFCb  ",
      " abbbbbbbbbbbba ",
      " aa aa aa aa aa ",
      "                "
    ]
  ]
}