{
  "name": "building_hotelb_floor2",
  "refpalette": "deceasedcraft:building_hotelb/building_hotelb_floor2_palette",
  "xsize": 16,
  "zsize": 16,
  "slices": [
    [
      "                ",
      " aa aa aa aa aa ",
      " abbbbbbbbbbbba ",
      "  bccccccccccb  ",
      " abcdee    fcba ",
      " abcegg     cba ",
      "  bcegg   h cb  ",
      " abceggiigjjcba ",
      " abcegggigjdcba ",
      "  bceggggggecb  ",
      " abieggggggecba ",
      " abideeeeeedcba ",
      "  biiicccccccb  ",
      " abbbbbbbbbbbba ",
      " aa aa aa aa aa ",
      "                "
    ],
    [
      "                ",
      " aa aa aa aa aa ",
      " abbbbbbbbbbbba ",
      "  bccccccccccb  ",
      " abcfklh   fcba ",
      " abcmnnh    cba ",
      "  bconnh    cb  ",
      " abcpnnqqq  cba ",
      " abc      rrcba ",
      "  bc  s s   cb  ",
      " abt uwwwwwxcba ",
      " abyfA B  Cfcba ",
      "  b!DEcccccccb  ",
      " abbbbbbbbbbbba ",
      " aa aa aa aa aa ",
      "                "
    ],
    [
      "                ",
      " aa aa aa aa aa ",
      " abbbbbbbbbbbba ",
      "  bccccccccccb  ",
      " abcfFI    fcba ",
      " abc        cba ",
      "  bc        cb  ",
      " abc        cba ",
      " abc        cba ",
      "  bc        cb  ",
      " ab     JK Lcba ",
      " abMf      fcba ",
      "  by  cccccccb  ",
      " abbbbbbbbbbbba ",
      " aa aa aa aa aa ",
      "                "
    ],
    [
      "                ",
      " aa aa aa aa aa ",
      " abbbbbbbbbbbba ",
      "  bccccccccccb  ",
      " abcf      fcba ",
      " abc        cba ",
      "  bc        cb  ",
      " abc   N   Ocba ",
      " abc       Pcba ",
      "  bc        cb  ",
      " ab         cba ",
      " ab f      fcba ",
      "  bMQ cccccccb  ",
      " abbbbbbbbbbbba ",
      " aa aa aa aa aa ",
      "                "
    ],
    [
      "                ",
      " aa aa aa aa aa ",
      " abbbbbbbbbbbba ",
      "  bRRRRRRRRRRb  ",
      " abRf      fSba ",
      " abR        cba ",
      "  bR        cb  ",
      " abR   NN   cba ",
      " abR        cba ",
      "  bc        cb  ",
      " ab         cba ",
      " ab f      fcba ",
      "  b TQcccccccb  ",
      " abbbbbbbbbbbba ",
      " aa aa aa aa aa ",
      "                "
    ],
    [
      "                ",
      " aa aa aa aa aa ",
      " abbbbbbbbbbbba ",
      "  b UUUUUUUU b  ",
      " abVfiiiiiifWba ",
      " abViXXXXXXiWba ",
      "  bViXXXXXXiRb  ",
      " abViXXYNXXiSba ",
      " abViXXNYXXicba ",
      "  bciXXXXXXicb  ",
      " ab iXXXXXXicba ",
      " ab fZiiiiifcba ",
      "  b  Tcccccccb  ",
      " abbbbbbbbbbbba ",
      " aa aa aa aa aa ",
      "                "
    ]
  ]
}