{
  "name": "building_hotelb_floor5",
  "refpalette": "deceasedcraft:building_hotelb/building_hotelb_floor5_palette",
  "xsize": 16,
  "zsize": 16,
  "slices": [
    [
      "                ",
      " aa aa aa aa aa ",
      " abbbbbbbbbbbba ",
      "  bccccccccccb  ",
      " abcdeeeeeedcba ",
      " abceffffffecba ",
      "  bceffffffecb  ",
      " abceffffffecba ",
      " abceffffffecba ",
      "  bghgggfggggb  ",
      " abihhgjjjjjgba ",
      " ab dkgjjjjdgba ",
      "  b   gggggggb  ",
      " abbbbbbbbbbbba ",
      " aa aa aa aa aa ",
      "                "
    ],
    [
      "                ",
      " aa aa aa aa aa ",
      " abbbbbbbbbbbba ",
      "  b     lmno b  ",
      " ab pqq rstp ba ",
      " ab uwwwxyAt ba ",
      "  b xBBCxyAt b  ",
      " ab !  DEstt ba ",
      " ab    F     ba ",
      "  bgIgJgKggggb  ",
      " abL  gM   Ngba ",
      " abOp gP Q Rgba ",
      "  b   gggggggb  ",
      " abbbbbbbbbbbba ",
      " aa aa aa aa aa ",
      "                "
    ],
    [
      "                ",
      " aa aa aa aa aa ",
      " abbbbbbbbbbbba ",
      "  b     ST   b  ",
      " ab p   UV p ba ",
      " ab    WX    ba ",
      "  b Y   X    b  ",
      " ab    ZEm   ba ",
      " ab    0     ba ",
      "  bg1g2g3ggggb  ",
      " ab   g4 56 7ba ",
      " ab8p g9#   7ba ",
      "  bO  gggggggb  ",
      " abbbbbbbbbbbba ",
      " aa aa aa aa aa ",
      "                "
    ],
    [
      "                ",
      " aa aa aa aa aa ",
      " abbbbbbbbbbbba ",
      "  b     $%   b  ",
      " ab p   ^& p ba ",
      " ab     X    ba ",
      "  b     X    b  ",
      " ab    *(%   ba ",
      " ab    )     ba ",
      "  bg+g-g[ggggb  ",
      " ab   g]  { gba ",
      " ab p g}    gba ",
      "  b8| gg;;;ggb  ",
      " abbbbbbbbbbbba ",
      " aa aa aa aa aa ",
      "                "
    ],
    [
      "                ",
      " aa aa aa aa aa ",
      " abbbbbbbbbbbba ",
      "  b :::::::: b  ",
      " ab'p   <  p>ba ",
      " ab'        >ba ",
      "  b'        >b  ",
      " ab'        >ba ",
      " ab'        >ba ",
      "  bggggggggggb  ",
      " ab   g     gba ",
      " ab p g     gba ",
      "  b ,|gggggggb  ",
      " abbbbbbbbbbbba ",
      " aa aa aa aa aa ",
      "                "
    ],
    [
      "                ",
      " aa aa aa aa aa ",
      " abbbbbbbbbbbba ",
      "  bggggggggggb  ",
      " abg.hhhhhh.gba ",
      " abgh??????hgba ",
      "  bgh??????hgb  ",
      " abgh??????hgba ",
      " abgh??????hgba ",
      "  bggggggggggb  ",
      " ab ccg/////gba ",
      " ab p`g/////gba ",
      "  b  ,gggggggb  ",
      " abbbbbbbbbbbba ",
      " aa aa aa aa aa ",
      "                "
    ]
  ]
}