{
  "name": "building_hotelb_floor3",
  "refpalette": "deceasedcraft:building_hotelb/building_hotelb_floor3_palette",
  "xsize": 16,
  "zsize": 16,
  "slices": [
    [
      "                ",
      " aa aa aa aa aa ",
      " abbbbbbbbbbbba ",
      "  bccccccccccb  ",
      " abcdeeeeeedcba ",
      " abceffffffecba ",
      "  bceffffffecb  ",
      " abceffffffecba ",
      " abceffffffecba ",
      "  bghgggfgfggb  ",
      " abihhgjjjjjgba ",
      " ab dkgjjjjdgba ",
      "  b   gggggggb  ",
      " abbbbbbbbbbbba ",
      " aa aa aa aa aa ",
      "                "
    ],
    [
      "                ",
      " aa aa aa aa aa ",
      " abbbbbbbbbbbba ",
      "  bl mnmon pqb  ",
      " abrs   tu swba ",
      " abx yA BrCCDba ",
      "  br yE FrCIJb  ",
      " abK yL MrCIJba ",
      " abK    NOCCDba ",
      "  bgPgQgRgSggb  ",
      " abT  gU V Wgba ",
      " abXs gYZ012gba ",
      "  b   gggggggb  ",
      " abbbbbbbbbbbba ",
      " aa aa aa aa aa ",
      "                "
    ],
    [
      "                ",
      " aa aa aa aa aa ",
      " abbbbbbbbbbbba ",
      "  b3  4 o5   b  ",
      " ab6s   78 s ba ",
      " ab     9#  $ba ",
      "  b%    ^#   b  ",
      " ab&     #   ba ",
      " ab     *O  (ba ",
      "  bg)g+g-g[ggb  ",
      " ab   gZ    ]ba ",
      " ab{s g!}  |]ba ",
      "  bX  gggggggb  ",
      " abbbbbbbbbbbba ",
      " aa aa aa aa aa ",
      "                "
    ],
    [
      "                ",
      " aa aa aa aa aa ",
      " abbbbbbbbbbbba ",
      "  b!    o    b  ",
      " ab s   ;: s ba ",
      " ab      #   ba ",
      "  b      #   b  ",
      " ab      #   ba ",
      " ab     'O   ba ",
      "  bg<g>g,g,ggb  ",
      " ab   g.    gba ",
      " ab s g?   /gba ",
      "  b{` gg\u0370\u0370\u0370ggb  ",
      " abbbbbbbbbbbba ",
      " aa aa aa aa aa ",
      "                "
    ],
    [
      "                ",
      " aa aa aa aa aa ",
      " abbbbbbbbbbbba ",
      "  b \u0371\u0371\u0371\u0371\u0371\u0371\u0371\u0371 b  ",
      " ab\u0372s      s\u0373ba ",
      " ab\u0372        \u0373ba ",
      "  b\u0372        \u0373b  ",
      " ab\u0372     \u0374  \u0373ba ",
      " ab\u0372        \u0373ba ",
      "  bggggggggggb  ",
      " ab   g     gba ",
      " ab s g     gba ",
      "  b \u0375`gggggggb  ",
      " abbbbbbbbbbbba ",
      " aa aa aa aa aa ",
      "                "
    ],
    [
      "                ",
      " aa aa aa aa aa ",
      " abbbbbbbbbbbba ",
      "  bggggggggggb  ",
      " abg\u0376hhhhhh\u0376gba ",
      " abgh\u0377\u0377\u0377\u0377\u0377\u0377hgba ",
      "  bgh\u0377\u0377\u0377\u0377\u0377\u0377hgb  ",
      " abgh\u0377\u0377\u0377\u0377\u0377\u0377hgba ",
      " abgh\u0377\u0377\u0377\u0377\u0377\u0377hgba ",
      "  bggggggggggb  ",
      " ab ccg\u037a\u037a\u037a\u037a\u037agba ",
      " ab s\u037bg\u037a\u037a\u037a\u037a\u037agba ",
      "  b  \u0375gggggggb  ",
      " abbbbbbbbbbbba ",
      " aa aa aa aa aa ",
      "                "
    ]
  ]
}