{
  "name": "building_hotelb_floor3_90",
  "refpalette": "deceasedcraft:building_hotelb/building_hotelb_floor3_palette_90",
  "xsize": 16,
  "zsize": 16,
  "slices": [
    [
      "                ",
      " aa aa aa aa aa ",
      " abbbbbbbbbbbba ",
      "  bccccccggggb  ",
      " abcdeeeegjdgba ",
      " abcefffffjjgba ",
      "  bceffffgjjgb  ",
      " abcefffffjjgba ",
      " abceffffgjjgba ",
      "  bceffffggggb  ",
      " abceffffghk ba ",
      " abcdeeeehhd ba ",
      "  bccccccgi  b  ",
      " abbbbbbbbbbbba ",
      " aa aa aa aa aa ",
      "                "
    ],
    [
      "                ",
      " aa aa aa aa aa ",
      " abbbbbbbbbbbba ",
      "  bqwDJJDggggb  ",
      " abpsCIICgW2gba ",
      " ab  CCCCS 1gba ",
      "  bnurrrOgV0gb  ",
      " abotBFMNR Zgba ",
      " abm     gUYgba ",
      "  bn AEL Qgggb  ",
      " abm yyy g   ba ",
      " ab s    P s ba ",
      "  blrxrKKgTX b  ",
      " abbbbbbbbbbbba ",
      " aa aa aa aa aa ",
      "                "
    ],
    [
      "                ",
      " aa aa aa aa aa ",
      " abbbbbbbbbbbba ",
      "  b  $  (g]]gb  ",
      " ab s    g |gba ",
      " ab      [  gba ",
      "  b58###Og  gb  ",
      " abo79^ *- }gba ",
      " ab      gZ!gba ",
      "  b4     +gggb  ",
      " ab      g   ba ",
      " ab s    ) s ba ",
      "  b36 %& g {Xb  ",
      " abbbbbbbbbbbba ",
      " aa aa aa aa aa ",
      "                "
    ],
    [
      "                ",
      " aa aa aa aa aa ",
      " abbbbbbbbbbbba ",
      "  b      ggggb  ",
      " ab s    g /gba ",
      " ab      ,  \u0370ba ",
      "  b :###Og  \u0370b  ",
      " abo;   ',  \u0370ba ",
      " ab      g.?gba ",
      "  b      >gggb  ",
      " ab      g   ba ",
      " ab s    < s`ba ",
      "  b!     g  {b  ",
      " abbbbbbbbbbbba ",
      " aa aa aa aa aa ",
      "                "
    ],
    [
      "                ",
      " aa aa aa aa aa ",
      " abbbbbbbbbbbba ",
      "  b \u0373\u0373\u0373\u0373\u0373ggggb  ",
      " ab\u0371s    g  gba ",
      " ab\u0371     g  gba ",
      "  b\u0371   \u0374 g  gb  ",
      " ab\u0371     g  gba ",
      " ab\u0371     g  gba ",
      "  b\u0371     ggggb  ",
      " ab\u0371     g  `ba ",
      " ab\u0371s    g s\u0375ba ",
      "  b \u0372\u0372\u0372\u0372\u0372g   b  ",
      " abbbbbbbbbbbba ",
      " aa aa aa aa aa ",
      "                "
    ],
    [
      "                ",
      " aa aa aa aa aa ",
      " abbbbbbbbbbbba ",
      "  bggggggggggb  ",
      " abg\u0376hhhhg\u037a\u037agba ",
      " abgh\u0377\u0377\u0377\u0377g\u037a\u037agba ",
      "  bgh\u0377\u0377\u0377\u0377g\u037a\u037agb  ",
      " abgh\u0377\u0377\u0377\u0377g\u037a\u037agba ",
      " abgh\u0377\u0377\u0377\u0377g\u037a\u037agba ",
      "  bgh\u0377\u0377\u0377\u0377ggggb  ",
      " abgh\u0377\u0377\u0377\u0377gc\u037b\u0375ba ",
      " abg\u0376hhhhgcs ba ",
      "  bggggggg   b  ",
      " abbbbbbbbbbbba ",
      " aa aa aa aa aa ",
      "                "
    ]
  ]
}