{
  "name": "building_hotelb_top_90",
  "refpalette": "deceasedcraft:building_hotelb/building_hotelb_top_palette_90",
  "xsize": 16,
  "zsize": 16,
  "slices": [
    [
      "                ",
      " aa aa aa aa aa ",
      " abbbbbbbbbbbba ",
      "  bccccccccccb  ",
      " abcddddddddcba ",
      " abcddddddddcba ",
      "  bcddeeeeddcb  ",
      " abcddeeeeddcba ",
      " abcddeeeeddcba ",
      "  bcddeeeeffcb  ",
      " abcdddddffg ba ",
      " abcdddddffd ba ",
      "  bccccccc   b  ",
      " abbbbbbbbbbbba ",
      " aa aa aa aa aa ",
      "                "
    ],
    [
      "                ",
      " aa aa aa aa aa ",
      " abbbbbbbbbbbba ",
      "  bccccccccccb  ",
      " abcddddddddcba ",
      " abcddddddddcba ",
      "  bcddffffffcb  ",
      " abcddfiifffcba ",
      " abcddfiifffcba ",
      "  bcddffffffcb  ",
      " abchhffffj  ba ",
      " abchhffff k ba ",
      "  bccccccc   b  ",
      " abbbbbbbbbbbba ",
      " aa aa aa aa aa ",
      "                "
    ],
    [
      "                ",
      " aa aa aa aa aa ",
      " abbbbbbbbbbbba ",
      "  bccccccccccb  ",
      " abcmmmmmtmmcba ",
      " abcmfffffffcba ",
      "  bcmf      cb  ",
      " abcmf pq  xcba ",
      " abcmf pq  xcba ",
      "  bcmf    uwcb  ",
      " abcllo  s   ba ",
      " abc!n   r k ba ",
      "  bccccccc   b  ",
      " abbbbbbbbbbbba ",
      " aa aa aa aa aa ",
      "                "
    ],
    [
      "                ",
      " aa aa aa aa a  ",
      " abbbbbbbbbbbba ",
      "  bccccccccccb  ",
      " abcffffffffcba ",
      " abcf E EIL cba ",
      "  bcfC      cb  ",
      " abcf       cba ",
      " abcfC      cba ",
      "  bcfB    Kwcb  ",
      " abcllo  F  Jba ",
      " abcyADDDr kJba ",
      "  bcccccccJJJb  ",
      " abbbbbbbbbbbba ",
      " aa aa aa aa a  ",
      "                "
    ],
    [
      "                ",
      " aa aa aa a     ",
      " abbbbbbbbb     ",
      "  bcccccccccc   ",
      " abcOE EBRICc   ",
      " abcC       c   ",
      "  bc        c   ",
      " abcC       c   ",
      " abcN       c   ",
      "  bcC     SPc   ",
      " abcllo  QPfc   ",
      " abcM o  Pffc   ",
      "  bcccccccccc   ",
      " abbbbbbbbb     ",
      " aa aa aa a     ",
      "                "
    ],
    [
      "                ",
      " aa aa a        ",
      " abbbbbb        ",
      "  bcccccccccc   ",
      " abc        c   ",
      " abc        c   ",
      "  bc        c   ",
      " abc       Pc   ",
      " abc      PUc   ",
      "  bc     PUfc   ",
      " abcTTo PUfjc   ",
      " abcTToPUfj X   ",
      "  bccccccccVW   ",
      " abbbbbb        ",
      " aa aa a        ",
      "                "
    ],
    [
      "                ",
      " aa a           ",
      " abbb           ",
      "  bcccccccccc   ",
      " abc  Z  0  c   ",
      " abc       Pc   ",
      "  bcY     Pfc   ",
      " abc     Pfjc   ",
      " abc    Pfj X   ",
      "  bcY  Pfj  W   ",
      " abc  Pfj       ",
      " abc Pfj        ",
      "  bcccccVW      ",
      " abbb           ",
      " aa a           ",
      "                "
    ],
    [
      "                ",
      "                ",
      "                ",
      "   cccccccccc   ",
      "   cPPP PPPUc   ",
      "   cPP PPPUjX   ",
      "   cP PPPUj W   ",
      "   c PPPUj      ",
      "   cPPPUj       ",
      "   cPPUj        ",
      "   cPUj         ",
      "   cUj          ",
      "   ccVW         ",
      "                ",
      "                ",
      "                "
    ],
    [
      "                ",
      "                ",
      "                ",
      "   ccccccccVW   ",
      "   cfffUfj      ",
      "   cffUfj       ",
      "   cfUfj        ",
      "   cUfj         ",
      "   cfj          ",
      "   cj           ",
      "   c            ",
      "   X            ",
      "   W            ",
      "                ",
      "                ",
      "                "
    ],
    [
      "                ",
      "                ",
      "                ",
      "   cccccVW      ",
      "   cffj         ",
      "   cfj          ",
      "   cj           ",
      "   c            ",
      "   X            ",
      "   W            ",
      "                ",
      "                ",
      "                ",
      "                ",
      "                ",
      "                "
    ],
    [
      "                ",
      "                ",
      "                ",
      "   ccVW         ",
      "   cj           ",
      "   X            ",
      "   W            ",
      "                ",
      "                ",
      "                ",
      "                ",
      "                ",
      "                ",
      "                ",
      "                ",
      "                "
    ],
    [
      "                ",
      "                ",
      "                ",
      "   W            ",
      "                ",
      "                ",
      "                ",
      "                ",
      "                ",
      "                ",
      "                ",
      "                ",
      "                ",
      "                ",
      "                ",
      "                "
    ]
  ]
}