{
  "name": "building_hotelb_floor1_90",
  "refpalette": "deceasedcraft:building_hotelb/building_hotelb_floor1_palette_90",
  "xsize": 16,
  "zsize": 16,
  "slices": [
    [
      "                ",
      " aa aa aa aarst ",
      " abbbbbbbbbbbbt ",
      "  b          bt ",
      " ab ei     e bt ",
      " ab ii    kkqbt ",
      "  bdhh   kk mbt ",
      " abcggn     pbt ",
      " ab fg       bt ",
      "  b  lk   q  bt ",
      " ab  kk  jmo bt ",
      " ab ek    pe bt ",
      "  b  jmo     bt ",
      " abbbbbbbbbbbbt ",
      " aa aa aa aarst ",
      "                "
    ],
    [
      "                ",
      " aa aa aa aa aa ",
      " abbbbbbbbbbbba ",
      "  b  xd      b  ",
      " ab fghi   e ba ",
      " abcgghii    ba ",
      "  bc w      Bb  ",
      " abc         ba ",
      " ab u        ba ",
      "  b          b  ",
      " ab       A  ba ",
      " ab e      e ba ",
      "  b   y      b  ",
      " abbbbbbbbbbbba ",
      " aa aa aa aa aa ",
      "                "
    ],
    [
      "                ",
      " aa aa aa aa aa ",
      " abbbbbbbbbbbba ",
      "  bC  xx     b  ",
      " ab e  gf  e ba ",
      " ab   DggE   ba ",
      "  b    hhd   b  ",
      " ab    ii    ba ",
      " ab    i     ba ",
      "  b          b  ",
      " ab          ba ",
      " ab e      e ba ",
      "  b          b  ",
      " abbbbbbbbbbbba ",
      " aa aa aa aa aa ",
      "                "
    ],
    [
      "                ",
      " aa aa aa aa aa ",
      " abbbbbbbbbbbba ",
      "  bIIJC      b  ",
      " abIe   u  e ba ",
      " abF     E   ba ",
      "  bC   K E   b  ",
      " ab iihggE   ba ",
      " ab  ihgf    ba ",
      "  b   dl     b  ",
      " ab          ba ",
      " ab e      e ba ",
      "  b          b  ",
      " abbbbbbbbbbbba ",
      " aa aa aa aa aa ",
      "                "
    ],
    [
      "                ",
      " aa aa aa aa aa ",
      " abbbbbbbbbbbba ",
      "  bIIIIIJC   b  ",
      " abIei     e ba ",
      " abIii       ba ",
      "  bIhh       b  ",
      " abIggn      ba ",
      " abFfg  u    ba ",
      "  bC lll     b  ",
      " ab          ba ",
      " ab e      e ba ",
      "  b          b  ",
      " abbbbbbbbbbbba ",
      " aa aa aa aa aa ",
      "                "
    ],
    [
      "                ",
      " aa aa aa aa aa ",
      " abbbbbbbbbbbba ",
      "  bIIIIIIIIJCb  ",
      " abIeghi   eCba ",
      " abIgghii   Cba ",
      "  bI w      Cb  ",
      " abI        Cba ",
      " abIu       Cba ",
      "  bI        Cb  ",
      " abI        Cba ",
      " abFe      eCba ",
      "  bCCCCCCCCCCb  ",
      " abbbbbbbbbbbba ",
      " aa aa aa aa aa ",
      "                "
    ]
  ]
}