{
  "name": "building_hotelb_floor4_180",
  "refpalette": "deceasedcraft:building_hotelb/building_hotelb_floor4_palette_180",
  "xsize": 16,
  "zsize": 16,
  "slices": [
    [
      "                ",
      " aa aa aa aa aa ",
      " abbbbbbbbbbbba ",
      "  bggggggg   b  ",
      " abgdjjjjgkd ba ",
      " abgjjjjjghhiba ",
      "  bggggfggghgb  ",
      " abceffffffecba ",
      " abceffffffecba ",
      "  bceffffffecb  ",
      " abceffffffecba ",
      " abcdeeeeeedcba ",
      "  bccccccccccb  ",
      " abbbbbbbbbbbba ",
      " aa aa aa aa aa ",
      "                "
    ],
    [
      "                ",
      " aa aa aa aa aa ",
      " abbbbbbbbbbbba ",
      "  bggggggg   b  ",
      " abgT S!Rg oQba ",
      " abgP O Ng  Mba ",
      "  bggggLgKgJgb  ",
      " ab     I    ba ",
      " ab ssrFE  D ba ",
      "  b sAyxCBBx b  ",
      " ab sAyxwwwu ba ",
      " abtosrq ppo ba ",
      "  bn  ml     b  ",
      " abbbbbbbbbbbba ",
      " aa aa aa aa aa ",
      "                "
    ],
    [
      "                ",
      " aa aa aa aa aa ",
      " abbbbbbbbbbbba ",
      "  bggggggg  Qb  ",
      " ab8   $#g o9ba ",
      " ab8 7   g   ba ",
      "  bgggg6g!g5gb  ",
      " ab     4    ba ",
      " ab   VF3    ba ",
      "  b    1   2 b  ",
      " ab    10ZY  ba ",
      " ab o XW   o ba ",
      "  b   VU     b  ",
      " abbbbbbbbbbbba ",
      " aa aa aa aa aa ",
      "                "
    ],
    [
      "                ",
      " aa aa aa aa aa ",
      " abbbbbbbbbbbba ",
      "  bgg|||gg }9b  ",
      " abg    {g o ba ",
      " abg ]  [g   ba ",
      "  bgggg-g g+gb  ",
      " ab     )    ba ",
      " ab   ^F(    ba ",
      "  b    1     b  ",
      " ab    1     ba ",
      " ab o *&   o ba ",
      "  b   ^%     b  ",
      " abbbbbbbbbbbba ",
      " aa aa aa aa aa ",
      "                "
    ],
    [
      "                ",
      " aa aa aa aa aa ",
      " abbbbbbbbbbbba ",
      "  bggggggg}< b  ",
      " abg     g o ba ",
      " abg     g   ba ",
      "  bggggggggggb  ",
      " ab'        :ba ",
      " ab'        :ba ",
      "  b'        :b  ",
      " ab'        :ba ",
      " ab'o      o:ba ",
      "  b ;;;;;;;; b  ",
      " abbbbbbbbbbbba ",
      " aa aa aa aa aa ",
      "                "
    ],
    [
      "                ",
      " aa aa aa aa aa ",
      " abbbbbbbbbbbba ",
      "  bggggggg<  b  ",
      " abg.....g?o ba ",
      " abg.....gcc ba ",
      "  bggggggggggb  ",
      " abgh,,,,,,hgba ",
      " abgh,,,,,,hgba ",
      "  bgh,,,,,,hgb  ",
      " abgh,,,,,,hgba ",
      " abg>hhhhhh>gba ",
      "  bggggggggggb  ",
      " abbbbbbbbbbbba ",
      " aa aa aa aa aa ",
      "                "
    ]
  ]
}