{
  "name": "building_hotelb_floor4_90",
  "refpalette": "deceasedcraft:building_hotelb/building_hotelb_floor4_palette_90",
  "xsize": 16,
  "zsize": 16,
  "slices": [
    [
      "                ",
      " aa aa aa aa aa ",
      " abbbbbbbbbbbba ",
      "  bccccccggggb  ",
      " abcdeeeegjdgba ",
      " abceffffgjjgba ",
      "  bceffffgjjgb  ",
      " abcefffffjjgba ",
      " abceffffgjjgba ",
      "  bceffffggggb  ",
      " abceffffghk ba ",
      " abcdeeeehhd ba ",
      "  bccccccgi  b  ",
      " abbbbbbbbbbbba ",
      " aa aa aa aa aa ",
      "                "
    ],
    [
      "                ",
      " aa aa aa aa aa ",
      " abbbbbbbbbbbba ",
      "  bnt    ggggb  ",
      " ab osss gPTgba ",
      " ab sAAs g  gba ",
      "  bmryyr gOSgb  ",
      " ablqxxF L !gba ",
      " ab  wCEIgNRgba ",
      "  b pwB  Kgggb  ",
      " ab pwB  g   ba ",
      " ab ouxD J o ba ",
      "  b      gMQ b  ",
      " abbbbbbbbbbbba ",
      " aa aa aa aa aa ",
      "                "
    ],
    [
      "                ",
      " aa aa aa aa aa ",
      " abbbbbbbbbbbba ",
      "  b      g88gb  ",
      " ab o    g  gba ",
      " ab      g7 gba ",
      "  bVX  V g  gb  ",
      " abUW11F 6 $gba ",
      " ab  0 34g #gba ",
      "  b  Z   !gggb  ",
      " ab  Y   g   ba ",
      " ab o 2  5 o ba ",
      "  b      g 9Qb  ",
      " abbbbbbbbbbbba ",
      " aa aa aa aa aa ",
      "                "
    ],
    [
      "                ",
      " aa aa aa aa aa ",
      " abbbbbbbbbbbba ",
      "  b      ggggb  ",
      " ab o    g  gba ",
      " ab      g] |ba ",
      "  b^*  ^ g  |b  ",
      " ab%&11F -  |ba ",
      " ab    ()g[{gba ",
      "  b       gggb  ",
      " ab      g   ba ",
      " ab o    + o}ba ",
      "  b      g  9b  ",
      " abbbbbbbbbbbba ",
      " aa aa aa aa aa ",
      "                "
    ],
    [
      "                ",
      " aa aa aa aa aa ",
      " abbbbbbbbbbbba ",
      "  b '''''ggggb  ",
      " ab;o    g  gba ",
      " ab;     g  gba ",
      "  b;     g  gb  ",
      " ab;     g  gba ",
      " ab;     g  gba ",
      "  b;     ggggb  ",
      " ab;     g  }ba ",
      " ab;o    g o<ba ",
      "  b :::::g   b  ",
      " abbbbbbbbbbbba ",
      " aa aa aa aa aa ",
      "                "
    ],
    [
      "                ",
      " aa aa aa aa aa ",
      " abbbbbbbbbbbba ",
      "  bggggggggggb  ",
      " abg>hhhhg..gba ",
      " abgh,,,,g..gba ",
      "  bgh,,,,g..gb  ",
      " abgh,,,,g..gba ",
      " abgh,,,,g..gba ",
      "  bgh,,,,ggggb  ",
      " abgh,,,,gc?<ba ",
      " abg>hhhhgco ba ",
      "  bggggggg   b  ",
      " abbbbbbbbbbbba ",
      " aa aa aa aa aa ",
      "                "
    ]
  ]
}