{
  "name": "building_hotelb_floor2_180",
  "refpalette": "deceasedcraft:building_hotelb/building_hotelb_floor2_palette_180",
  "xsize": 16,
  "zsize": 16,
  "slices": [
    [
      "                ",
      " aa aa aa aa aa ",
      " abbbbbbbbbbbba ",
      "  bccccccciiib  ",
      " abcdeeeeeediba ",
      " abceggggggeiba ",
      "  bceggggggecb  ",
      " abcdjgigggecba ",
      " abcjjgiiggecba ",
      "  bc h   ggecb  ",
      " abc     ggecba ",
      " abcf    eedcba ",
      "  bccccccccccb  ",
      " abbbbbbbbbbbba ",
      " aa aa aa aa aa ",
      "                "
    ],
    [
      "                ",
      " aa aa aa aa aa ",
      " abbbbbbbbbbbba ",
      "  bcccccccED!b  ",
      " abcfC  B Afyba ",
      " abcxwwwwwu tba ",
      "  bc   s s  cb  ",
      " abcrr      cba ",
      " abc  qqqnnpcba ",
      "  bc    hnnocb  ",
      " abc    hnnmcba ",
      " abcf   hlkfcba ",
      "  bccccccccccb  ",
      " abbbbbbbbbbbba ",
      " aa aa aa aa aa ",
      "                "
    ],
    [
      "                ",
      " aa aa aa aa aa ",
      " abbbbbbbbbbbba ",
      "  bccccccc  yb  ",
      " abcf      fMba ",
      " abcL KJ     ba ",
      "  bc        cb  ",
      " abc        cba ",
      " abc        cba ",
      "  bc        cb  ",
      " abc        cba ",
      " abcf    IFfcba ",
      "  bccccccccccb  ",
      " abbbbbbbbbbbba ",
      " aa aa aa aa aa ",
      "                "
    ],
    [
      "                ",
      " aa aa aa aa aa ",
      " abbbbbbbbbbbba ",
      "  bccccccc QMb  ",
      " abcf      f ba ",
      " abc         ba ",
      "  bc        cb  ",
      " abcP       cba ",
      " abcO   N   cba ",
      "  bc        cb  ",
      " abc        cba ",
      " abcf      fcba ",
      "  bccccccccccb  ",
      " abbbbbbbbbbbba ",
      " aa aa aa aa aa ",
      "                "
    ],
    [
      "                ",
      " aa aa aa aa aa ",
      " abbbbbbbbbbbba ",
      "  bcccccccQT b  ",
      " abcf      f ba ",
      " abc         ba ",
      "  bc        cb  ",
      " abc        Rba ",
      " abc   NN   Rba ",
      "  bc        Rb  ",
      " abc        Rba ",
      " abSf      fRba ",
      "  bRRRRRRRRRRb  ",
      " abbbbbbbbbbbba ",
      " aa aa aa aa aa ",
      "                "
    ],
    [
      "                ",
      " aa aa aa aa aa ",
      " abbbbbbbbbbbba ",
      "  bcccccccT  b  ",
      " abcfiiiiiZf ba ",
      " abciXXXXXXi ba ",
      "  bciXXXXXXicb  ",
      " abciXXYNXXiVba ",
      " abSiXXNYXXiVba ",
      "  bRiXXXXXXiVb  ",
      " abWiXXXXXXiVba ",
      " abWfiiiiiifVba ",
      "  b UUUUUUUU b  ",
      " abbbbbbbbbbbba ",
      " aa aa aa aa aa ",
      "                "
    ]
  ]
}