{
  "name": "building_hotelb_floor5_90",
  "refpalette": "deceasedcraft:building_hotelb/building_hotelb_floor5_palette_90",
  "xsize": 16,
  "zsize": 16,
  "slices": [
    [
      "                ",
      " aa aa aa aa aa ",
      " abbbbbbbbbbbba ",
      "  bccccccggggb  ",
      " abcdeeeegjdgba ",
      " abceffffgjjgba ",
      "  bceffffgjjgb  ",
      " abcefffffjjgba ",
      " abceffffgjjgba ",
      "  bceffffggggb  ",
      " abceffffghk ba ",
      " abcdeeeehhd ba ",
      "  bccccccgi  b  ",
      " abbbbbbbbbbbba ",
      " aa aa aa aa aa ",
      "                "
    ],
    [
      "                ",
      " aa aa aa aa aa ",
      " abbbbbbbbbbbba ",
      "  b      ggggb  ",
      " abopttt gNRgba ",
      " abntAAt g  gba ",
      "  bmsyys g Qgb  ",
      " ablrxxE K  gba ",
      " ab  wCDFgMPgba ",
      "  b qwB  Jgggb  ",
      " ab qwB  g   ba ",
      " ab pux! I p ba ",
      "  b      gLO b  ",
      " abbbbbbbbbbbba ",
      " aa aa aa aa aa ",
      "                "
    ],
    [
      "                ",
      " aa aa aa aa aa ",
      " abbbbbbbbbbbba ",
      "  b      g77gb  ",
      " ab p    g  gba ",
      " ab      g6 gba ",
      "  bTV  m g5 gb  ",
      " abSUXXE 3 #gba ",
      " ab  W Z0g49gba ",
      "  b      2gggb  ",
      " ab      g   ba ",
      " ab p Y  1 p ba ",
      "  b      g 8Ob  ",
      " abbbbbbbbbbbba ",
      " aa aa aa aa aa ",
      "                "
    ],
    [
      "                ",
      " aa aa aa aa aa ",
      " abbbbbbbbbbbba ",
      "  b      ggggb  ",
      " ab p    g  gba ",
      " ab      g{ ;ba ",
      "  b%&  % g  ;b  ",
      " ab$^XX( [  ;ba ",
      " ab    *)g]}gba ",
      "  b      -gggb  ",
      " ab      g   ba ",
      " ab p    + p|ba ",
      "  b      g  8b  ",
      " abbbbbbbbbbbba ",
      " aa aa aa aa aa ",
      "                "
    ],
    [
      "                ",
      " aa aa aa aa aa ",
      " abbbbbbbbbbbba ",
      "  b >>>>>ggggb  ",
      " ab:p    g  gba ",
      " ab:     g  gba ",
      "  b:     g  gb  ",
      " ab:<    g  gba ",
      " ab:     g  gba ",
      "  b:     ggggb  ",
      " ab:     g  |ba ",
      " ab:p    g p,ba ",
      "  b '''''g   b  ",
      " abbbbbbbbbbbba ",
      " aa aa aa aa aa ",
      "                "
    ],
    [
      "                ",
      " aa aa aa aa aa ",
      " abbbbbbbbbbbba ",
      "  bggggggggggb  ",
      " abg.hhhhg//gba ",
      " abgh????g//gba ",
      "  bgh????g//gb  ",
      " abgh????g//gba ",
      " abgh????g//gba ",
      "  bgh????ggggb  ",
      " abgh????gc`,ba ",
      " abg.hhhhgcp ba ",
      "  bggggggg   b  ",
      " abbbbbbbbbbbba ",
      " aa aa aa aa aa ",
      "                "
    ]
  ]
}