{
  "name": "multi_courtyardofficetower_9_floor9",
  "refpalette": "deceasedcraft:multi_courtyardofficetower_9/multi_courtyardofficetower_9_floor9_palette",
  "xsize": 16,
  "zsize": 16,
  "slices": [
    [
      "           a    ",
      "           a    ",
      "           b    ",
      "   c       ccccc",
      "            b   ",
      "            a   ",
      "            a   ",
      "            ad  ",
      "            a   ",
      "            a   ",
      "            b   ",
      "   c       ccccc",
      "             b  ",
      "             a  ",
      "             a  ",
      "             ad "
    ],
    [
      "           a    ",
      "           a    ",
      "           b    ",
      "   c       ccccc",
      "            b   ",
      "            a   ",
      "            a   ",
      "            ad  ",
      "            a   ",
      "            a   ",
      "            b   ",
      "   c       ccccc",
      "             b  ",
      "             a  ",
      "             a  ",
      "             ad "
    ],
    [
      "           a    ",
      "           a    ",
      "           b    ",
      "   c       ccccc",
      "            b   ",
      "            a   ",
      "            a   ",
      "            ad  ",
      "            a   ",
      "            a   ",
      "            b   ",
      "   c       ccccc",
      "             b  ",
      "             a  ",
      "             a  ",
      "             ad "
    ],
    [
      "           a    ",
      "           a    ",
      "           b    ",
      "   c       ccccc",
      "            b   ",
      "            a   ",
      "            a   ",
      "            ad  ",
      "            a   ",
      "            a   ",
      "            b   ",
      "   c       ccccc",
      "             b  ",
      "             a  ",
      "             a  ",
      "             ad "
    ],
    [
      "           a    ",
      "           a    ",
      "           b    ",
      "   c       ccccc",
      "            b   ",
      "            a   ",
      "            a   ",
      "            ad  ",
      "            a   ",
      "            a   ",
      "            b   ",
      "   c       ccccc",
      "             b  ",
      "             a  ",
      "             a  ",
      "             ad "
    ],
    [
      "eeeceeeeeeea    ",
      "efecefeeefea    ",
      "eeeceeeeeeeb    ",
      "cccccccccccccccc",
      "eeeceeeeeeeeb   ",
      "efecefeeefeea   ",
      "eeeceeeeeeeea   ",
      "eeeceeeeeeeead  ",
      "eeeceeeeeeeea   ",
      "efecefeeefeea   ",
      "eeeceeeeeeeeb   ",
      "eeeceeeeeeeccccc",
      "eeeceeeeeeeeeb  ",
      "efecefeeefeeea  ",
      "eeeceeeeeeeeea  ",
      "eeeceeeeeeeeead "
    ]
  ]
}