{
  "name": "multi_courtyardofficetower_9_floor7",
  "refpalette": "deceasedcraft:multi_courtyardofficetower_9/multi_courtyardofficetower_9_floor7_palette",
  "xsize": 16,
  "zsize": 16,
  "slices": [
    [
      "aaabcccccccb    ",
      "aaabcccccccb    ",
      "aaabcccccccb    ",
      "aaadbbbbbbbddddd",
      "aaaaaaaaaaaab   ",
      "aaaaaaaaaaaab   ",
      "aaaaaaaaaaaab   ",
      "aaaaaaaaaaaabe  ",
      "aaaaaaaaaaaab   ",
      "aaaaaaaaaaaab   ",
      "aaaaaaaaaaaab   ",
      "aaadaaaaaaaddddd",
      "aaaaaaaaaaaaab  ",
      "aaaaaaaaaaaaab  ",
      "aaaaaaaaaaaaab  ",
      "aaaaaaaaaaaaabe "
    ],
    [
      "   fghaij  k    ",
      "   fla  j  k    ",
      " m faln o  p    ",
      " qrdfffffstddddd",
      " urwxxy    Ap   ",
      "  rB       Ck   ",
      "     D     Ak   ",
      "           Eke  ",
      "           Ek   ",
      "  rBF     IAk   ",
      " mrJKKL    Mp   ",
      " qrdlll    ddddd",
      " urwxxy    N p  ",
      "  rB D    OPQk  ",
      "           R k  ",
      "             ke "
    ],
    [
      "   f Sa j  k    ",
      "   fTaU j  k    ",
      "   faV  W  p    ",
      "  XdfffffYZddddd",
      "  X0 12     p   ",
      "  X         k   ",
      "            k   ",
      "            ke  ",
      "           3k   ",
      "  X4       5k   ",
      "  X6789    #p   ",
      "  Xd$$$    ddddd",
      "  X%^1&      p  ",
      "  X        * k  ",
      "             k  ",
      "             ke "
    ],
    [
      "   f  a j  k    ",
      "   f(a  j  k    ",
      "   fa)  j  p    ",
      "   dfffff+-ddddd",
      "            p   ",
      "            k   ",
      "            k   ",
      "            ke  ",
      "            k   ",
      "            k   ",
      "           [p   ",
      "   d       ddddd",
      "             p  ",
      "             k  ",
      "             k  ",
      "             ke "
    ],
    [
      "   f]]a j  k    ",
      "   f{a] j  k    ",
      "   fa!] j  p    ",
      "   dfffffffddddd",
      "            p   ",
      "            k   ",
      "            k   ",
      "            ke  ",
      "            k   ",
      "            k   ",
      "            p   ",
      "   d       ddddd",
      "             p  ",
      "             k  ",
      "             k  ",
      "             ke "
    ],
    [
      "}}}d|||||||k    ",
      "};}d|||||||k    ",
      "}}}d|||||||p    ",
      "dddddddddddddddd",
      "}}}d}}}}}}}}p   ",
      "};}d};}}};}}k   ",
      "}}}d}}}}}}}}k   ",
      "}}}d}}}}}}}}ke  ",
      "}}}d}}}}}}}}k   ",
      "};}d};}}};}}k   ",
      "}}}d}}}}}}}}p   ",
      "}}}d}}}}}}}ddddd",
      "}}}d}}}}}}}}}p  ",
      "};}d};}}};}}}k  ",
      "}}}d}}}}}}}}}k  ",
      "}}}d}}}}}}}}}ke "
    ]
  ]
}