{
  "name": "multi_courtyardofficetower_9_floor2",
  "refpalette": "deceasedcraft:multi_courtyardofficetower_9/multi_courtyardofficetower_9_floor2_palette",
  "xsize": 16,
  "zsize": 16,
  "slices": [
    [
      "aaaabcccccde    ",
      "aaaaabccccde    ",
      "aaaaaabbccdf    ",
      "aaagaaaabbaggggg",
      "aaaaaaaaaaadf   ",
      "aaaaaaaaaaade   ",
      "aaaaaaaaaaade   ",
      "aaaaaaaaaaadeh  ",
      "aaaaaaaaaaade   ",
      "aaaaaaaaaaade   ",
      "aaaaaaaaaaadf   ",
      "aaagaaaaaaaggggg",
      "aaaaaaaaaaaadf  ",
      "aaaaaaaaaaaade  ",
      "aaaaaaaaaaaade  ",
      "aaaaaaaaaaaadeh "
    ],
    [
      "         i e    ",
      "        j  e    ",
      "           f    ",
      "   gklk   mggggg",
      "   m  n     f   ",
      "   o pnq    e   ",
      "  ro  n     e   ",
      "  so  n     eh  ",
      "  to  n     e   ",
      "   o pnq    e   ",
      "   m  n     f   ",
      "   guwu    ggggg",
      "             f  ",
      "             e  ",
      "      xxx    e  ",
      "      xyx    eh "
    ],
    [
      "           e    ",
      "           e    ",
      "           f    ",
      "   g      Aggggg",
      "   A        f   ",
      "   o        e   ",
      "   o        e   ",
      "   o        eh  ",
      "   o        e   ",
      "   o        e   ",
      "   A        f   ",
      "   g       ggggg",
      "             f  ",
      "           B e  ",
      "      CCD    e  ",
      "      DEC  B eh "
    ],
    [
      "           e    ",
      "           e    ",
      "           f    ",
      "   g      Fggggg",
      "   F        f   ",
      "   o        e   ",
      "   o        e   ",
      "   o        eh  ",
      "   o        e   ",
      "   o        e   ",
      "   F        f   ",
      "   g       ggggg",
      "             f  ",
      "           B e  ",
      "      CDC    e  ",
      "        D  B eh "
    ],
    [
      "           e    ",
      "           e    ",
      "           f    ",
      "   g       ggggg",
      "   F        f   ",
      "   o        e   ",
      "   oI       e   ",
      "  JoI       eh  ",
      "   oK       e   ",
      "   o        e   ",
      "   F        f   ",
      "   g       ggggg",
      "             f  ",
      "           B e  ",
      "             e  ",
      "           B eh "
    ],
    [
      "           e    ",
      "           e    ",
      "           f    ",
      "   g       ggggg",
      "   L        f   ",
      "   o        e   ",
      "   oM       e   ",
      "  NoM       eh  ",
      "   oO       e   ",
      "   o        e   ",
      "   F        f   ",
      "   g       ggggg",
      "             f  ",
      "           NPe  ",
      "             e  ",
      "           NPeh "
    ]
  ]
}