{
  "name": "multi_courtyardofficetower_9_floor3",
  "refpalette": "deceasedcraft:multi_courtyardofficetower_9/multi_courtyardofficetower_9_floor3_palette",
  "xsize": 16,
  "zsize": 16,
  "slices": [
    [
      "           a    ",
      "           a    ",
      "           b    ",
      "   c       ccccc",
      "            b   ",
      "   d        a   ",
      "   de       a   ",
      "  fde       ag  ",
      "   dh       a   ",
      "   d        a   ",
      "            b   ",
      "   c       ccccc",
      "             b  ",
      "           ffa  ",
      "             a  ",
      "           ffag "
    ],
    [
      "           a    ",
      "           a    ",
      "           b    ",
      "   c       ccccc",
      "            b   ",
      "   d        a   ",
      "   d        a   ",
      "   d        ag  ",
      "   d        a   ",
      "   d        a   ",
      "            b   ",
      "   c       ccccc",
      "             b  ",
      "             a  ",
      "             a  ",
      "             ag "
    ],
    [
      "           a    ",
      "           a    ",
      "           b    ",
      "   c       ccccc",
      "            b   ",
      "   d        a   ",
      "   d        a   ",
      "   d        ag  ",
      "   d        a   ",
      "   d        a   ",
      "            b   ",
      "   c       ccccc",
      "             b  ",
      "             a  ",
      "             a  ",
      "             ag "
    ],
    [
      "           a    ",
      "           a    ",
      "           b    ",
      "   c       ccccc",
      "            b   ",
      "   i        a   ",
      "            a   ",
      "            ag  ",
      "            a   ",
      "   i        a   ",
      "            b   ",
      "   c       ccccc",
      "             b  ",
      "             a  ",
      "             a  ",
      "             ag "
    ],
    [
      "           a    ",
      "           a    ",
      "           b    ",
      "   c       ccccc",
      "   j        b   ",
      "   k        a   ",
      "   l        a   ",
      "   l        ag  ",
      "   l        a   ",
      "   k        a   ",
      "   m        b   ",
      "   c       ccccc",
      "             b  ",
      "             a  ",
      "             a  ",
      "             ag "
    ],
    [
      "nnncnnnnnnna    ",
      "noncnonnnona    ",
      "nnncnnnnnnnb    ",
      "cccccccccccccccc",
      "nnncnnnnnnn b   ",
      "noncnonnnon a   ",
      "nnncnnnnnnn a   ",
      "nnncnnnnnnn ag  ",
      "nnncnnnnnnn a   ",
      "noncnonnnon a   ",
      "nnncnnnnnnn b   ",
      "nnncnnnnnnnccccc",
      "nnncnnnnnnn  b  ",
      "noncnonnnon  a  ",
      "nnncnnnnnnn  a  ",
      "nnncnnnnnnn  ag "
    ]
  ]
}