{
  "name": "multi_courtyardofficetower_9_floor17",
  "refpalette": "deceasedcraft:multi_courtyardofficetower_9/multi_courtyardofficetower_9_floor17_palette",
  "xsize": 16,
  "zsize": 16,
  "slices": [
    [
      "aaabcccccccb    ",
      "aaabcccccccb    ",
      "aaabcccccccb    ",
      "aaadbbbbbbbddddd",
      "aaaaaaaaaaaab   ",
      "aaaaaaaaaaaab   ",
      "aaaaaaaaaaaab   ",
      "aaaaaaaaaaaabe  ",
      "aaaaaaaaaaaab   ",
      "aaaaaaaaaaaab   ",
      "aaaaaaaaaaaab   ",
      "aaadaaaaaaaddddd",
      "aaaaaaaaaaaaab  ",
      "aaaaaaaaaaaaab  ",
      "aaaaaaaaaaaaab  ",
      "aaaaaaaaaaaaabe "
    ],
    [
      "   fg ahi  j    ",
      "  kfla  i  j    ",
      " mkfalnop  q    ",
      " rkdfffffstddddd",
      " ukwxyA B  Cq   ",
      "D kE FIB  DJj   ",
      "  K    D BLCj   ",
      " KM      N Oje  ",
      "M  KP     KOj   ",
      "Q kR STUVWLCj   ",
      " mkwXYZ  L 0q   ",
      " rkdlll  V1ddddd",
      " ukwxyA     1q  ",
      "  k2  T    34j  ",
      "   T F    5  j  ",
      "6    T   V   je "
    ],
    [
      "   f 7a i  j    ",
      "  8f9a# i  j    ",
      "  8fa$  %  q    ",
      "  8dfffff^&ddddd",
      "  8  *      q   ",
      "  8         j   ",
      "            j   ",
      "           Kje  ",
      "            j   ",
      "  8U        j   ",
      "  8() +    -q   ",
      "  8d[[[    ddddd",
      "  8 D]M      q  ",
      "  8{         j  ",
      "             j  ",
      "             je "
    ],
    [
      "   f  a i  j    ",
      "   f}a  i  j    ",
      "   fa|  i  q    ",
      "   dfffff;:ddddd",
      "            q   ",
      "            j   ",
      "            j   ",
      "            je  ",
      "            j   ",
      "            j   ",
      "           !q   ",
      "   d       ddddd",
      "             q  ",
      "             j  ",
      "             j  ",
      "             je "
    ],
    [
      "   f''a i  j    ",
      "   f<a' i  j    ",
      "   fa<' i  q    ",
      "   dfffffffddddd",
      "            q   ",
      "            j   ",
      "            j   ",
      "            je  ",
      "            j   ",
      "            j   ",
      "            q   ",
      "   d       ddddd",
      "             q  ",
      "             j  ",
      "             j  ",
      "             je "
    ],
    [
      ">>>d,,,,,,,j    ",
      ">.>d,,,,,,,j    ",
      ">>>d,,,,,,,q    ",
      "dddddddddddddddd",
      ">>>d>>>>>>>>q   ",
      ">.>d>.>>>.>>j   ",
      ">>>d>>>>>>>>j   ",
      ">>>d>>>>>>>>je  ",
      ">>>d>>>>>>>>j   ",
      ">.>d>.>>>.>>j   ",
      ">>>d>>>>>>>>q   ",
      ">>>d>>>>>>>ddddd",
      ">>>d>>>>>>>>>q  ",
      ">.>d>.>>>.>>>j  ",
      ">>>d>>>>>>>>>j  ",
      ">>>d>>>>>>>>>je "
    ]
  ]
}