{
  "name": "multi_courtyardofficetower_9_floor8",
  "refpalette": "deceasedcraft:multi_courtyardofficetower_9/multi_courtyardofficetower_9_floor8_palette",
  "xsize": 16,
  "zsize": 16,
  "slices": [
    [
      "aaaabccccccd    ",
      "aaaaabcccccd    ",
      "aaaaaabbcccd    ",
      "aaaeaaaabbbeeeee",
      "aaaaaaaaaaaad   ",
      "aaaaaaaaaaaad   ",
      "aaaaaaaaaaaad   ",
      "aaaaaaaaaaaadf  ",
      "aaaaaaaaaaaad   ",
      "aaaaaaaaaaaad   ",
      "aaaaaaaaaaaad   ",
      "aaaeaaaaaaaeeeee",
      "aaaaaaaaaaaaad  ",
      "aaaaaaaaaaaaad  ",
      "aaaaaaaaaaaaad  ",
      "aaaaaaaaaaaaadf "
    ],
    [
      "           g    ",
      "         h g    ",
      "           i    ",
      "   e       eeeee",
      "           ji   ",
      "     kkkkk lg   ",
      "    mnnnnnolg   ",
      "    mnnnnnopgf  ",
      "    mnnnnnopg   ",
      "   q rrrrr pg   ",
      "   sq      ji   ",
      "   e      teeeee",
      "     u   wxy i  ",
      "   A BC   DE g  ",
      "     F   wDy g  ",
      "          DI gf "
    ],
    [
      "           g    ",
      "           g    ",
      "           i    ",
      "   e       eeeee",
      "           !i   ",
      "           Jg   ",
      "           Jg   ",
      "           Kgf  ",
      "           Kg   ",
      "           Kg   ",
      "            i   ",
      "   e      Leeeee",
      "           M i  ",
      "             g  ",
      "          N  g  ",
      "             gf "
    ],
    [
      "           g    ",
      "           g    ",
      "           i    ",
      "   e       eeeee",
      "            i   ",
      "           Kg   ",
      "           Kg   ",
      "           Ogf  ",
      "           Og   ",
      "           Og   ",
      "            i   ",
      "   e      Peeeee",
      "           Q i  ",
      "           R g  ",
      "           Q g  ",
      "           R gf "
    ],
    [
      "           g    ",
      "           g    ",
      "           i    ",
      "   e       eeeee",
      "            i   ",
      "           Og   ",
      "           Og   ",
      "            gf  ",
      "            g   ",
      "            g   ",
      "            i   ",
      "   e       eeeee",
      "           S i  ",
      "           T g  ",
      "           U g  ",
      "           p gf "
    ],
    [
      "           g    ",
      "           g    ",
      "           i    ",
      "   e       eeeee",
      "            i   ",
      "            g   ",
      "            g   ",
      "            gf  ",
      "            g   ",
      "            g   ",
      "            i   ",
      "   e       eeeee",
      "           V i  ",
      "           W g  ",
      "           W g  ",
      "           X gf "
    ]
  ]
}