{
  "name": "multi_courtyardofficetower_9_floor20",
  "refpalette": "deceasedcraft:multi_courtyardofficetower_9/multi_courtyardofficetower_9_floor20_palette",
  "xsize": 16,
  "zsize": 16,
  "slices": [
    [
      "aaaaaaaaaabc    ",
      "aaaaaaaaaabc    ",
      "aaaaaaaaaabd    ",
      "eeefaaaaaagfffff",
      "   eaaaaaaabd   ",
      "   eaaaaaaabc   ",
      "   eaaaaaaabc   ",
      "   eaaaaaaabch  ",
      "   eaaaaaaabc   ",
      "   eaaaaaaabc   ",
      "   eaaaaaaabd   ",
      "   eaaaaaagfffff",
      "   eaaaaaaaabd  ",
      "   eaaaaaaaabc  ",
      "   eaaaaaaaabc  ",
      "   eaaaaaaaabch "
    ],
    [
      "iij k     lh    ",
      "       m  lh    ",
      "      nop lq    ",
      "rrrf   k  sfffff",
      "  tuw      lq   ",
      "  tu    m  lh   ",
      "  tuw  nop lh   ",
      "  tu    k  lhh  ",
      "  tuw      lh   ",
      "  tu       lh   ",
      "  tuw      lq   ",
      "  t       sfffff",
      "  tuw      xlq  ",
      "  tu      yAlh  ",
      "  tuw      Alh  ",
      "  tu      yAlhh "
    ],
    [
      "                ",
      "                ",
      "       B        ",
      "   f      Cfffff",
      "                ",
      "                ",
      "        D       ",
      "                ",
      "                ",
      "                ",
      "                ",
      "          Cfffff",
      "                ",
      "           E    ",
      "                ",
      "           F    "
    ],
    [
      "                ",
      "                ",
      "                ",
      "   f      Ifffff",
      "                ",
      "                ",
      "                ",
      "                ",
      "                ",
      "                ",
      "                ",
      "          Ifffff",
      "                ",
      "                ",
      "                ",
      "                "
    ],
    [
      "                ",
      "                ",
      "                ",
      "   f      Ifffff",
      "                ",
      "                ",
      "                ",
      "                ",
      "                ",
      "                ",
      "                ",
      "          Ifffff",
      "                ",
      "                ",
      "                ",
      "                "
    ],
    [
      "                ",
      "                ",
      "                ",
      "   f      Jfffff",
      "                ",
      "                ",
      "                ",
      "                ",
      "                ",
      "                ",
      "                ",
      "          Jfffff",
      "                ",
      "                ",
      "                ",
      "                "
    ]
  ]
}