{
  "name": "multi_courtyardofficetower_9_floor13",
  "refpalette": "deceasedcraft:multi_courtyardofficetower_9/multi_courtyardofficetower_9_floor13_palette",
  "xsize": 16,
  "zsize": 16,
  "slices": [
    [
      "aaabccccccbd    ",
      "aaabccccccbd    ",
      "aaabccccccbe    ",
      "aaafbbbbbbbfffff",
      "aaaaaaaaaaabe   ",
      "aaaaaaaaaaabd   ",
      "aaaaaaaaaaabd   ",
      "aaaaaaaaaaabdg  ",
      "aaaaaaaaaaabd   ",
      "aaaaaaaaaaabd   ",
      "aaaaaaaaaaabe   ",
      "aaaaaaaaaaafffff",
      "aaaaaaaaaaaabe  ",
      "aaaaaaaaaaaabd  ",
      "aaaaaaaaaaaabd  ",
      "aaaaaaaaaaaabdg "
    ],
    [
      "   hijklm  d    ",
      "   hnko m  d    ",
      "   hknp q  e    ",
      "   fhhhhhrsfffff",
      "            e   ",
      "     t      d   ",
      "    uwx     d   ",
      "     y   t  dg  ",
      "        uwx d   ",
      "         y  d   ",
      "            e   ",
      "   fABBBBBAfffff",
      "             e  ",
      "     C   C   d  ",
      "    DDDDDDD  d  ",
      "     E   E   dg "
    ],
    [
      "   h Fk m  d    ",
      "   hIkJ m  d    ",
      "   hkK  L  e    ",
      "   fhhhhhMNfffff",
      "            e   ",
      "            d   ",
      "            d   ",
      "            dg  ",
      "            d   ",
      "            d   ",
      "            e   ",
      "   fOBBBBBOfffff",
      "             e  ",
      "             d  ",
      "             d  ",
      "             dg "
    ],
    [
      "   h  k m  d    ",
      "   hPk  m  d    ",
      "   hkQ  m  e    ",
      "   fhhhhhRSfffff",
      "            e   ",
      "            d   ",
      "            d   ",
      "            dg  ",
      "            d   ",
      "            d   ",
      "            e   ",
      "   fTBBBBBTfffff",
      "             e  ",
      "             d  ",
      "             d  ",
      "             dg "
    ],
    [
      "   hUUk m  d    ",
      "   hVkU m  d    ",
      "   hkVU m  e    ",
      "   fhhhhhhhfffff",
      "            e   ",
      "            d   ",
      "            d   ",
      "            dg  ",
      "            d   ",
      "            d   ",
      "            e   ",
      "   fTBBBBBTfffff",
      "      WXX    e  ",
      "             d  ",
      "             d  ",
      "             dg "
    ],
    [
      "   hYYYYYYYd    ",
      "   hYYYYYYYd    ",
      "   hYYYYYYYe    ",
      "   fhhhhhhhfffff",
      "            e   ",
      "            d   ",
      "            d   ",
      "            dg  ",
      "            d   ",
      "            d   ",
      "            e   ",
      "   f BBBBB fffff",
      "      Z00    e  ",
      "             d  ",
      "             d  ",
      "             dg "
    ]
  ]
}