{
  "name": "multi_courtyardofficetower_9_floor22",
  "refpalette": "deceasedcraft:multi_courtyardofficetower_9/multi_courtyardofficetower_9_floor22_palette",
  "xsize": 16,
  "zsize": 16,
  "slices": [
    [
      "   a       a    ",
      "   a       a    ",
      "   a       a    ",
      "aaaaaaaaaaaaaaaa",
      "   a       a    ",
      "   a       a    ",
      "   a       a    ",
      "   a       a    ",
      "   a       a    ",
      "   a       a    ",
      "   a       a    ",
      "aaaaaaaaaaaaaaaa",
      "   a       a    ",
      "   a       a    ",
      "   a       a    ",
      "   a       a    "
    ],
    [
      "bbcacbbbbbca    ",
      "bbcacbbbbbca    ",
      "cccaccccccca    ",
      "aaaaaaaaaaaaaaaa",
      "cccaccccccca    ",
      "bbcacbbbbbca    ",
      "bbcacbbbbbca    ",
      "bbcacbbbbbca    ",
      "bbcacbbbbbca    ",
      "bbcacbbbbbca    ",
      "cccaccccccca    ",
      "aaaaaaaaaaaaaaaa",
      "cccaccccccca    ",
      "bbcacbbbbbca    ",
      "bbcacbbbbbca    ",
      "bbcacbbbbbca    "
    ],
    [
      "   a       a    ",
      "   a       a    ",
      "   a       a    ",
      "aaaaaaaaaaaaaaaa",
      "   a       a    ",
      "   a       a    ",
      "   a       a    ",
      "   a       a    ",
      "   a       a    ",
      "   a       a    ",
      "   a       a    ",
      "aaaaaaaaaaaaaaaa",
      "   a       a    ",
      "   a       a    ",
      "   a       a    ",
      "   a       a    "
    ],
    [
      "   a       a    ",
      "   a       a    ",
      "   a       a    ",
      "aaaaaaaaaaaaaaaa",
      "   a       a    ",
      "   a       a    ",
      "   a       a    ",
      "   a       a    ",
      "   a       a    ",
      "   a       a    ",
      "   a       a    ",
      "aaaaaaaaaaaaaaaa",
      "   a       a    ",
      "   a       a    ",
      "   a       a    ",
      "   a       a    "
    ],
    [
      "   a       a    ",
      "   a       a    ",
      "   a       a    ",
      "aaaaaaaaaaaaaaaa",
      "   a       a    ",
      "   a       a    ",
      "   a       a    ",
      "   a       a    ",
      "   a       a    ",
      "   a       a    ",
      "   a       a    ",
      "aaaaaaaaaaaaaaaa",
      "   a       a    ",
      "   a       a    ",
      "   a       a    ",
      "   a       a    "
    ],
    [
      "   a       a    ",
      "   a       a    ",
      "   a       a    ",
      "aaaaaaaaaaaaaaaa",
      "   a       a    ",
      "   a       a    ",
      "   a       a    ",
      "   a       a    ",
      "   a       a    ",
      "   a       a    ",
      "   a       a    ",
      "aaaaaaaaaaaaaaaa",
      "   a       a    ",
      "   a       a    ",
      "   a       a    ",
      "   a       a    "
    ]
  ]
}