{
  "name": "multi_courtyardofficetower_9_floor19",
  "refpalette": "deceasedcraft:multi_courtyardofficetower_9/multi_courtyardofficetower_9_floor19_palette",
  "xsize": 16,
  "zsize": 16,
  "slices": [
    [
      "   abbbbbbcd    ",
      "   abbbbbbcd    ",
      "   abbbbbbce    ",
      "   faaaaaaafffff",
      "            e   ",
      "            d   ",
      "            d   ",
      "            dg  ",
      "            d   ",
      "            d   ",
      "            e   ",
      "   f       fffff",
      "             e  ",
      "             d  ",
      "             d  ",
      "             dg "
    ],
    [
      "   a  hhh  d    ",
      "   a       d    ",
      "   a       e    ",
      "   faaaaaaafffff",
      "            e   ",
      "            d   ",
      "            d   ",
      "            dg  ",
      "            d   ",
      "            d   ",
      "            e   ",
      "   f       fffff",
      "             e  ",
      "             d  ",
      " ii          d  ",
      "jkk          dg "
    ],
    [
      "   a  lml  d    ",
      "   a       d    ",
      "   a       e    ",
      "   faaaaaaafffff",
      "            e   ",
      "            d   ",
      "            d   ",
      "            dg  ",
      "            d   ",
      "            d   ",
      "            e   ",
      "   f       fffff",
      "i            e  ",
      "ikj          d  ",
      "knno         d  ",
      "p  o         dg "
    ],
    [
      "   a  qrq  d    ",
      "   a       d    ",
      "   a       e    ",
      "   faaaaaaafffff",
      "            e   ",
      "            d   ",
      "            d   ",
      "            dg  ",
      "            d   ",
      "            d   ",
      "            e   ",
      "j  f       fffff",
      "no           e  ",
      "nso          d  ",
      "             d  ",
      "s            dg "
    ],
    [
      "   a  tut  d    ",
      "   a       d    ",
      "   a       e    ",
      "   faaaaaaafffff",
      "            e   ",
      "            d   ",
      "            d   ",
      "            dg  ",
      "            d   ",
      "            d   ",
      "            e   ",
      "   f       fffff",
      "             e  ",
      "             d  ",
      "             d  ",
      "             dg "
    ],
    [
      "wwwfwwwwwwwd    ",
      "wxwfwwwwwwwd    ",
      "wwwfwwwwwwwe    ",
      "ffffffffffffffff",
      "   fwwwwwwwwe   ",
      "   fwxwwwxwwd   ",
      "   fwwwwwwwwd   ",
      "   fwwwwwwwwdg  ",
      "   fwwwwwwwwd   ",
      "   fwxwwwxwwd   ",
      "   fwwwwwwwwe   ",
      "  yfwwwwwwwfffff",
      "   fwwwwwwwwwe  ",
      "   fwxwwwxwwwd  ",
      "   fwwwwwwwwwd  ",
      "   fwwwwwwwwwdg "
    ]
  ]
}