{
  "name": "multi_courtyardofficetower_9_floor10",
  "refpalette": "deceasedcraft:multi_courtyardofficetower_9/multi_courtyardofficetower_9_floor10_palette",
  "xsize": 16,
  "zsize": 16,
  "slices": [
    [
      "aabcbbbbccde    ",
      "aabcbbbcccde    ",
      "aabcbbbbccdf    ",
      "aabgbbbccchggggg",
      "aabcbbcccccdf   ",
      "aabcbbbccccde   ",
      "aabcbbcbcbcde   ",
      "aabcbbbbbbcdei  ",
      "aabcbbbbbccde   ",
      "aabcbbbcbcbde   ",
      "aabcbbcccccdf   ",
      "aabgbbcccchggggg",
      "aabcbbbccbccdf  ",
      "aabcbbcbcbbcde  ",
      "aabcbbbcbcccde  ",
      "aabcbbcccccbdei "
    ],
    [
      "   j      ki    ",
      "   j      ki    ",
      "   j      kl    ",
      "   g      !ggggg",
      "   j       kl   ",
      "   j       ki   ",
      "   j      mki   ",
      "   n      okii  ",
      "   j      pki   ",
      "   j       ki   ",
      "   j       kl   ",
      "   g      qggggg",
      "   j        kl  ",
      "   j        ki  ",
      "   j      r ki  ",
      "   j      s kii "
    ],
    [
      "                ",
      "                ",
      "                ",
      "   g      tggggg",
      "                ",
      "                ",
      "                ",
      "                ",
      "                ",
      "                ",
      "                ",
      "   g      tggggg",
      "                ",
      "                ",
      "                ",
      "                "
    ],
    [
      "                ",
      "                ",
      "                ",
      "   g      jggggg",
      "                ",
      "                ",
      "                ",
      "                ",
      "                ",
      "                ",
      "                ",
      "   g      jggggg",
      "                ",
      "                ",
      "                ",
      "                "
    ],
    [
      "                ",
      "                ",
      "                ",
      "   g      uggggg",
      "                ",
      "                ",
      "                ",
      "                ",
      "                ",
      "                ",
      "                ",
      "   g      uggggg",
      "                ",
      "                ",
      "                ",
      "                "
    ],
    [
      "                ",
      "                ",
      "                ",
      "   g      uggggg",
      "                ",
      "                ",
      "                ",
      "                ",
      "                ",
      "                ",
      "                ",
      "   g      uggggg",
      "                ",
      "                ",
      "                ",
      "                "
    ]
  ]
}