{
  "name": "multi_courtyardofficetower_9_floor5",
  "refpalette": "deceasedcraft:multi_courtyardofficetower_9/multi_courtyardofficetower_9_floor5_palette",
  "xsize": 16,
  "zsize": 16,
  "slices": [
    [
      "aaabcccccccb    ",
      "aaabcccccccb    ",
      "aaabcccccccb    ",
      "aaadbbbbbbbddddd",
      "aaaaaaaaaaaab   ",
      "aaaaaaaaaaaab   ",
      "aaaaaaaaaaaab   ",
      "aaaaaaaaaaaabe  ",
      "aaaaaaaaaaaab   ",
      "aaaaaaaaaaaab   ",
      "aaaaaaaaaaaab   ",
      "aaadaaaaaaaddddd",
      "aaaaaaaaaaaaab  ",
      "aaaaaaaaaaaaab  ",
      "aaaaaaaaaaaaab  ",
      "aaaaaaaaaaaaabe "
    ],
    [
      " f ghiajk  l    ",
      "  mgnao k  l    ",
      " pmganq r  s    ",
      " tmdggggguwddddd",
      " xmyAABC   Ds   ",
      "  mE  FIJ KLl   ",
      "  MNf      Dl   ",
      "       O   Ple  ",
      "   OQR K S Pl   ",
      "  mE  TUV  Dl   ",
      " pmWXXY Z  0s   ",
      " tmdnnnI  Jddddd",
      " xmyAAB    1 s  ",
      "  mE     2 34l  ",
      "     T    1  l  ",
      "S            le "
    ],
    [
      "   g 5a k  l    ",
      "  6g7a8 k  l    ",
      "  6ga   9  s    ",
      "  6dggggg#$ddddd",
      "  6 R %    ^s   ",
      "  6&        l   ",
      "           Kl   ",
      "            le  ",
      "            l   ",
      "  6*       (l   ",
      "  6)+R     -s   ",
      "  6d[[[    ddddd",
      "  6f]{}      s  ",
      "  6          l  ",
      "             l  ",
      "             le "
    ],
    [
      "   g  a k  l    ",
      "   g|a  k  l    ",
      "   ga;  k  s    ",
      "   dggggg:'ddddd",
      "            s   ",
      "            l   ",
      "            l   ",
      "            le  ",
      "            l   ",
      "            l   ",
      "           <s   ",
      "   d       ddddd",
      "             s  ",
      "             l  ",
      "             l  ",
      "             le "
    ],
    [
      "   g>>a k  l    ",
      "   g,a> k  l    ",
      "   ga,> k  s    ",
      "   dgggggggddddd",
      "            s   ",
      "            l   ",
      "            l   ",
      "            le  ",
      "            l   ",
      "            l   ",
      "            s   ",
      "   d       ddddd",
      "             s  ",
      "             l  ",
      "             l  ",
      "             le "
    ],
    [
      "...d???????l    ",
      "./.d???????l    ",
      "...d???????s    ",
      "dddddddddddddddd",
      "...d........s   ",
      "./.d./.../..l   ",
      "...d........l   ",
      "...d........le  ",
      "...d........l   ",
      "./.d./.../..l   ",
      "...d........s   ",
      "...d.......ddddd",
      "...d.........s  ",
      "./.d./.../...l  ",
      "...d.........l  ",
      "...d.........le "
    ]
  ]
}