{
  "name": "multi_courtyardofficetower_9_ground",
  "refpalette": "deceasedcraft:multi_courtyardofficetower_9/multi_courtyardofficetower_9_ground_palette",
  "xsize": 16,
  "zsize": 16,
  "slices": [
    [
      "aaaaaabbbaaaaaaa",
      "caaaabbabaaaaaaa",
      "dcaaaabbbaaaaaaa",
      "dcaeaabbaaaeeeea",
      "ddcaababbbaaaaaa",
      "cdcaaaabbabaaaaa",
      "cdcccccccccccccc",
      "cddddddddddddddd",
      "cdcccccccccccccc",
      "cdcaaabbbaaaaaaa",
      "ddcaaabbaaaaaaaa",
      "dcaeababaaaeeeea",
      "dcaaaabbbbaaaaaa",
      "caaaaaabbabaaaaa",
      "aaaaaabbabbbbaaa",
      "aaaaaabbbbbbbbaa"
    ],
    [
      " fg          g  ",
      "  g       gg gg ",
      "    g          g",
      "  he      geeeeg",
      "                ",
      "    ijk  h  ijk ",
      "                ",
      "                ",
      "                ",
      "                ",
      "        g  ggggg",
      "  he      geeee ",
      "     g    g g   ",
      "  g          g g",
      " g g         g  ",
      " g   g        g "
    ],
    [
      " l              ",
      "  g             ",
      "                ",
      "   e       eeee ",
      "                ",
      "                ",
      "                ",
      "                ",
      "                ",
      "                ",
      "                ",
      "   e       eeee ",
      "            g   ",
      "  g             ",
      "             g  ",
      "                "
    ],
    [
      " m              ",
      "                ",
      "                ",
      "   e       eeeen",
      "                ",
      "                ",
      "                ",
      "                ",
      "                ",
      "                ",
      "                ",
      "   e       eeeen",
      "                ",
      "                ",
      "                ",
      "                "
    ],
    [
      " g              ",
      "                ",
      "                ",
      "   e       eeeen",
      "                ",
      "                ",
      "                ",
      "                ",
      "                ",
      "                ",
      "                ",
      "   e       eeeen",
      "                ",
      "                ",
      "                ",
      "                "
    ],
    [
      " g              ",
      " g              ",
      "                ",
      "   e       eeeee",
      "                ",
      "                ",
      "                ",
      "                ",
      "                ",
      "                ",
      "                ",
      "   e       eeeee",
      "                ",
      "                ",
      "                ",
      "     g          "
    ]
  ]
}