{
  "name": "multi_courtyardofficetower_9_floor1",
  "refpalette": "deceasedcraft:multi_courtyardofficetower_9/multi_courtyardofficetower_9_floor1_palette",
  "xsize": 16,
  "zsize": 16,
  "slices": [
    [
      "aaa             ",
      " a             a",
      "                ",
      "   b       bbbbb",
      "                ",
      "                ",
      "                ",
      "                ",
      "                ",
      "                ",
      "                ",
      "   b       bbbbb",
      "                ",
      "                ",
      "                ",
      "    aa          "
    ],
    [
      "caa             ",
      " a             a",
      "               a",
      "   b       bbbbb",
      "                ",
      "                ",
      "                ",
      "                ",
      "                ",
      "                ",
      "                ",
      "   b       bbbbb",
      "                ",
      "                ",
      "                ",
      "     aa         "
    ],
    [
      " a              ",
      "               a",
      "                ",
      "   b       bbbbb",
      "                ",
      "                ",
      "                ",
      "                ",
      "                ",
      "                ",
      "                ",
      "   b       bbbbb",
      "                ",
      "                ",
      "                ",
      "                "
    ],
    [
      " c              ",
      "                ",
      "                ",
      "   b       bbbbb",
      "                ",
      "                ",
      "                ",
      "                ",
      "                ",
      "                ",
      "                ",
      "   b       bbbbb",
      "                ",
      "                ",
      "                ",
      "                "
    ],
    [
      "                ",
      "                ",
      "                ",
      "   b       bbbbb",
      "                ",
      "                ",
      "                ",
      "                ",
      "                ",
      "                ",
      "                ",
      "   b       bbbbb",
      "                ",
      "                ",
      "                ",
      "                "
    ],
    [
      "dddbdddddd e    ",
      "dddbdddddd e    ",
      "dddbdddddd f    ",
      "bbbbbbbbbbbbbbbb",
      "dddbddddddd f   ",
      "dddbddddddd e   ",
      "dddbddddddd e   ",
      "dddbddddddd ee  ",
      "dddbddddddd e   ",
      "dddbddddddd e   ",
      "dddbddddddd f   ",
      "dddbdddddddbbbbb",
      "dddbdddddddd f  ",
      "dddbdddddddd e  ",
      "dddbdddddddd e  ",
      "dddbdddddddd ee "
    ]
  ]
}