{
  "name": "multi_courtyardofficetower_9_floor12",
  "refpalette": "deceasedcraft:multi_courtyardofficetower_9/multi_courtyardofficetower_9_floor12_palette",
  "xsize": 16,
  "zsize": 16,
  "slices": [
    [
      "                ",
      "                ",
      "                ",
      "   a       aaaaa",
      "                ",
      "                ",
      "                ",
      "                ",
      "                ",
      "                ",
      "                ",
      "   a       aaaaa",
      "                ",
      "                ",
      "                ",
      "                "
    ],
    [
      "                ",
      "                ",
      "                ",
      "   a       aaaaa",
      "                ",
      "                ",
      "                ",
      "                ",
      "                ",
      "                ",
      "                ",
      "   a       aaaaa",
      "                ",
      "                ",
      "                ",
      "                "
    ],
    [
      "                ",
      "                ",
      "                ",
      "   a       aaaaa",
      "                ",
      "                ",
      "                ",
      "                ",
      "                ",
      "                ",
      "                ",
      "   a       aaaaa",
      "                ",
      "                ",
      "                ",
      "                "
    ],
    [
      "                ",
      "                ",
      "                ",
      "   a       aaaaa",
      "                ",
      "                ",
      "                ",
      "                ",
      "                ",
      "                ",
      "                ",
      "   a       aaaaa",
      "                ",
      "                ",
      "                ",
      "                "
    ],
    [
      "                ",
      "                ",
      "                ",
      "   a       aaaaa",
      "                ",
      "                ",
      "                ",
      "                ",
      "                ",
      "                ",
      "                ",
      "   a       aaaaa",
      "                ",
      "                ",
      "                ",
      "                "
    ],
    [
      "bbbabbbbbb c    ",
      "bbbabbbbbb c    ",
      "bbbabbbbbb d    ",
      "aaaaaaaaaaaaaaaa",
      "bbbabbbbbbb d   ",
      "eebabbbbbbb c   ",
      "bebabbbbbbb c   ",
      "bebabbbbbbb cc  ",
      "bebabbbbbbb c   ",
      "bebabbbbbbb c   ",
      "bebabbbbbbb d   ",
      "bebabbbbbbbaaaaa",
      "bebabbbbbbbb d  ",
      "bebabbbbbbbb c  ",
      "bebabbbbbbbb c  ",
      "bebabbbbbbbb cc "
    ]
  ]
}