{
  "name": "multi_courtyardofficetower_9_floor16",
  "refpalette": "deceasedcraft:multi_courtyardofficetower_9/multi_courtyardofficetower_9_floor16_palette",
  "xsize": 16,
  "zsize": 16,
  "slices": [
    [
      "aaabcccccccb    ",
      "aaabcccccccb    ",
      "aaabcccccccb    ",
      "aaadbbbbbbbddddd",
      "aaaaaaaaaaaab   ",
      "aaaaaaaaaaaab   ",
      "aaaaaaaaaaaab   ",
      "aaaaaaaaaaaabe  ",
      "aaaaaaaaaaaab   ",
      "aaaaaaaaaaaab   ",
      "aaaaaaaaaaaab   ",
      "aaadaaaaaaaddddd",
      "aaaaaaaaaaaaab  ",
      "aaaaaaaaaaaaab  ",
      "aaaaaaaaaaaaab  ",
      "aaaaaaaaaaaaabe "
    ],
    [
      "   fghaij  k    ",
      "   fla  j  k    ",
      " m faln o  p    ",
      " qrdfffffstddddd",
      " urwxyA    Bp   ",
      "  rC D     Ek   ",
      "           Bk   ",
      "           Fke  ",
      "           Fk   ",
      "  rCI      Bk   ",
      " mrwJKL    Mp   ",
      " qrdlll    ddddd",
      " urwxyA    N p  ",
      "  rC D    NONk  ",
      "           N k  ",
      "             ke "
    ],
    [
      "   f Pa j  k    ",
      "   fQaR j  k    ",
      "   faS  T  p    ",
      "  UdfffffVWddddd",
      "  UXYZ0    1p   ",
      "  U2        k   ",
      "           3k   ",
      "            ke  ",
      "            k   ",
      "  U4       5k   ",
      "  U6789    #p   ",
      "  Ud$$$    ddddd",
      "  U%^&*      p  ",
      "  U(       3 k  ",
      "             k  ",
      "             ke "
    ],
    [
      "   f  a j  k    ",
      "   f)a  j  k    ",
      "   fa+  j  p    ",
      "   dfffff-[ddddd",
      "            p   ",
      "            k   ",
      "            k   ",
      "            ke  ",
      "            k   ",
      "            k   ",
      "            p   ",
      "   d       ddddd",
      "             p  ",
      "             k  ",
      "             k  ",
      "             ke "
    ],
    [
      "   f]]a j  k    ",
      "   f{a] j  k    ",
      "   fa{] j  p    ",
      "   dfffffffddddd",
      "            p   ",
      "            k   ",
      "            k   ",
      "            ke  ",
      "            k   ",
      "            k   ",
      "            p   ",
      "   d       ddddd",
      "             p  ",
      "             k  ",
      "             k  ",
      "             ke "
    ],
    [
      "}}}d|||||||k    ",
      "};}d|||||||k    ",
      "}}}d|||||||p    ",
      "dddddddddddddddd",
      "}}}d}}}}}}}}p   ",
      "};}d};}}};}}k   ",
      "}}}d}}}}}}}}k   ",
      "}}}d}}}}}}}}ke  ",
      "}}}d}}}}}}}}k   ",
      "};}d};}}};}}k   ",
      "}}}d}}}}}}}}p   ",
      "}}}d}}}}}}}ddddd",
      "}}}d}}}}}}}}}p  ",
      "};}d};}}};}}}k  ",
      "}}}d}}}}}}}}}k  ",
      "}}}d}}}}}}}}}ke "
    ]
  ]
}