{
  "name": "multi_courtyardofficetower_9_floor4",
  "refpalette": "deceasedcraft:multi_courtyardofficetower_9/multi_courtyardofficetower_9_floor4_palette",
  "xsize": 16,
  "zsize": 16,
  "slices": [
    [
      "aaabcccccccb    ",
      "aaabcccccccb    ",
      "aaabcccccccb    ",
      "aaadbbbbbbbddddd",
      "aaaaaaaaaaaab   ",
      "aaaaaaaaaaaab   ",
      "aaaaaaaaaaaab   ",
      "aaaaaaaaaaaabe  ",
      "aaaaaaaaaaaab   ",
      "aaaaaaaaaaaab   ",
      "aaaaaaaaaaaab   ",
      "aaadaaaaaaaddddd",
      "aaaaaaaaaaaaab  ",
      "aaaaaaaaaaaaab  ",
      "aaaaaaaaaaaaab  ",
      "aaaaaaaaaaaaabe "
    ],
    [
      "   fghaij  k    ",
      "  lfma  j  k    ",
      " nlfamo p  q    ",
      " rldfffffstddddd",
      " ulwxxy    Aq   ",
      "  lB C     Dk   ",
      "           Ak   ",
      "           Eke  ",
      "           Ek   ",
      "  lBF      Ak   ",
      " nlIJJK    Lq   ",
      " rldmmm    ddddd",
      " ulwxxy    M q  ",
      "  lB      NOPk  ",
      "     C     Q k  ",
      "             ke "
    ],
    [
      "   f Ra j  k    ",
      "  SfTaU j  k    ",
      "  SfaV  W  q    ",
      "  SdfffffXYddddd",
      "  SZ012     q   ",
      "  S3        k   ",
      "           4k   ",
      "           5ke  ",
      "           6k   ",
      "  S7       8k   ",
      "  S9#$     %q   ",
      "  Sd^^^    ddddd",
      "  S&*1(      q  ",
      "  S)       5 k  ",
      "             k  ",
      "             ke "
    ],
    [
      "   f  a j  k    ",
      "   f+a  j  k    ",
      "   fa-  j  q    ",
      "   dfffff[]ddddd",
      "            q   ",
      "            k   ",
      "            k   ",
      "            ke  ",
      "            k   ",
      "            k   ",
      "           {q   ",
      "   d       ddddd",
      "             q  ",
      "             k  ",
      "             k  ",
      "             ke "
    ],
    [
      "   f}}a j  k    ",
      "   f a} j  k    ",
      "   fa|} j  q    ",
      "   dfffffffddddd",
      "            q   ",
      "            k   ",
      "            k   ",
      "            ke  ",
      "            k   ",
      "            k   ",
      "            q   ",
      "   d       ddddd",
      "             q  ",
      "             k  ",
      "             k  ",
      "             ke "
    ],
    [
      ";;;d:::::::k    ",
      ";';d:::::::k    ",
      ";;;d:::::::q    ",
      "dddddddddddddddd",
      ";;;d;;;;;;;;q   ",
      ";';d;';;;';;k   ",
      ";;;d;;;;;;;;k   ",
      ";;;d;;;;;;;;ke  ",
      ";;;d;;;;;;;;k   ",
      ";';d;';;;';;k   ",
      ";;;d;;;;;;;;q   ",
      ";;;d;;;;;;;ddddd",
      ";;;d;;;;;;;;;q  ",
      ";';d;';;;';;;k  ",
      ";;;d;;;;;;;;;k  ",
      ";;;d;;;;;;;;;ke "
    ]
  ]
}