{
  "name": "multi_courtyardofficetower_9_floor14",
  "refpalette": "deceasedcraft:multi_courtyardofficetower_9/multi_courtyardofficetower_9_floor14_palette",
  "xsize": 16,
  "zsize": 16,
  "slices": [
    [
      "   abbbbbbcd    ",
      "   abbbbbbcd    ",
      "   abbbbbbce    ",
      "   faaaaaaafffff",
      "            e   ",
      "            d   ",
      "            d   ",
      "            dg  ",
      "            d   ",
      "            d   ",
      "            e   ",
      "   f hhhhh fffff",
      "      ijj    e  ",
      "             d  ",
      "             d  ",
      "             dg "
    ],
    [
      "   a  kkk  d    ",
      "   a       d    ",
      "   a       e    ",
      "   faaaaaaafffff",
      "            e   ",
      "            d   ",
      "            d   ",
      "            dg  ",
      "            d   ",
      "            d   ",
      "            e   ",
      "   f hhhhh fffff",
      "             e  ",
      "             d  ",
      "             d  ",
      "             dg "
    ],
    [
      "   a  lml  d    ",
      "   a       d    ",
      "   a       e    ",
      "   faaaaaaafffff",
      "            e   ",
      "            d   ",
      "            d   ",
      "            dg  ",
      "            d   ",
      "            d   ",
      "            e   ",
      "   f hhhhh fffff",
      "             e  ",
      "             d  ",
      "             d  ",
      "             dg "
    ],
    [
      "   a  non  d    ",
      "   a       d    ",
      "   a       e    ",
      "   faaaaaaafffff",
      "            e   ",
      "            d   ",
      "            d   ",
      "            dg  ",
      "            d   ",
      "            d   ",
      "            e   ",
      "   f p   p fffff",
      "             e  ",
      "             d  ",
      "             d  ",
      "             dg "
    ],
    [
      "   a       d    ",
      "   a       d    ",
      "   a       e    ",
      "   faaaaaaafffff",
      "            e   ",
      "            d   ",
      "            d   ",
      "            dg  ",
      "            d   ",
      "            d   ",
      "            e   ",
      "   fqrsssrtfffff",
      "             e  ",
      "             d  ",
      "             d  ",
      "             dg "
    ],
    [
      "uuufuuuuuuud    ",
      "uwufuuuuuuud    ",
      "uuufuuuuuuue    ",
      "ffffffffffffffff",
      "uuufuuuuuuuue   ",
      "uwufuwuuuwuud   ",
      "uuufuuuuuuuud   ",
      "uuufuuuuuuuudg  ",
      "uuufuuuuuuuud   ",
      "uwufuwuuuwuud   ",
      "uuufuuuuuuuue   ",
      "uuufuuuuuuufffff",
      "uuufuuuuuuuuue  ",
      "uwufuwuuuwuuud  ",
      "uuufuuuuuuuuud  ",
      "uuufuuuuuuuuudg "
    ]
  ]
}