{
  "name": "multi_courtyardofficetower_9_floor15",
  "refpalette": "deceasedcraft:multi_courtyardofficetower_9/multi_courtyardofficetower_9_floor15_palette",
  "xsize": 16,
  "zsize": 16,
  "slices": [
    [
      "aaabcccccccb    ",
      "aaabcccccccb    ",
      "aaabcccccccb    ",
      "aaadbbbbbbbddddd",
      "aaaaaaaaaaaab   ",
      "aaaaaaaaaaaab   ",
      "aaaaaaaaaaaab   ",
      "aaaaaaaaaaaabe  ",
      "aaaaaaaaaaaab   ",
      "aaaaaaaaaaaab   ",
      "aaaaaaaaaaaab   ",
      "aaadaaaaaaaddddd",
      "aaaaaaaaaaaaab  ",
      "aaaaaaaaaaaaab  ",
      "aaaaaaaaaaaaab  ",
      "aaaaaaaaaaaaabe "
    ],
    [
      "   fg ahi  j    ",
      "  kf!al i  j    ",
      " mkfano p  q    ",
      " rkdfffffstddddd",
      " ukwxyA    Bq   ",
      "  kC D     Ej   ",
      "           Bj   ",
      "           Fje  ",
      "           Fj   ",
      "  kIJ      Bj   ",
      " mkwCKL    Mq   ",
      " rkdnnn    ddddd",
      " ukwyNA    O q  ",
      "  kC      PQRj  ",
      "     D     S j  ",
      "             je "
    ],
    [
      "   f Ta i  j    ",
      "  Uf aV i  j    ",
      "  Ufa   W  q    ",
      "  UdfffffXYddddd",
      "  UZ012    3q   ",
      "  UZ        j   ",
      "            j   ",
      "            je  ",
      "           4j   ",
      "  U        5j   ",
      "  U6 78    9q   ",
      "  Ud###    ddddd",
      "  U$%1^      q  ",
      "  U&       * j  ",
      "             j  ",
      "             je "
    ],
    [
      "   f  a i  j    ",
      "   f(a  i  j    ",
      "   fa)  i  q    ",
      "   dfffff+-ddddd",
      "            q   ",
      "            j   ",
      "            j   ",
      "            je  ",
      "            j   ",
      "            j   ",
      "            q   ",
      "   d       ddddd",
      "             q  ",
      "             j  ",
      "             j  ",
      "             je "
    ],
    [
      "   f[[a i  j    ",
      "   f a[ i  j    ",
      "   fa [ i  q    ",
      "   dfffffffddddd",
      "            q   ",
      "            j   ",
      "            j   ",
      "            je  ",
      "            j   ",
      "            j   ",
      "            q   ",
      "   d       ddddd",
      "             q  ",
      "             j  ",
      "             j  ",
      "             je "
    ],
    [
      "]]]d{{{{{{{j    ",
      "]}]d{{{{{{{j    ",
      "]]]d{{{{{{{q    ",
      "dddddddddddddddd",
      "]]]d]]]]]]]]q   ",
      "]}]d]}]]]}]]j   ",
      "]]]d]]]]]]]]j   ",
      "]]]d]]]]]]]]je  ",
      "]]]d]]]]]]]]j   ",
      "]}]d]}]]]}]]j   ",
      "]]]d]]]]]]]]q   ",
      "]]]d]]]]]]]ddddd",
      "]]]d]]]]]]]]]q  ",
      "]}]d]}]]]}]]]j  ",
      "]]]d]]]]]]]]]j  ",
      "]]]d]]]]]]]]]je "
    ]
  ]
}