{
  "name": "multi_courtyardofficetower_9_base1",
  "refpalette": "deceasedcraft:multi_courtyardofficetower_9/multi_courtyardofficetower_9_base1_palette",
  "xsize": 16,
  "zsize": 16,
  "slices": [
    [
      "aaaaaaaaaaaaaaaa",
      "aaaaaaaaaaaaaaaa",
      "aaaaaaaaaaaaaaaa",
      "aaabaaaaaaabbbba",
      "aaaaaaaaaaaaaaaa",
      "aaaaaaaaaaaaaaaa",
      "aaaaaaaaaaaaaaaa",
      "aaaaaaaaaaaaaaaa",
      "aaaaaaaaaaaaaaaa",
      "aaaaaaaaaaaaaaaa",
      "aaaaaaaaaaaaaaaa",
      "aaabaaaaaaabbbba",
      "aaaaaaaaaaaaaaaa",
      "aaaaaaaaaaaaaaaa",
      "aaaaaaaaaaaaaaaa",
      "aaaaaaaaaaaaaaaa"
    ],
    [
      "cccccccdeedaaaaa",
      "cccccccdeedaaaaa",
      "cccccccdeedaaaaa",
      "cccbcccdeedbbbba",
      "cccccccdeedaaaaa",
      "cccccccdeedaaaaa",
      "cccccccdeedaaaaa",
      "cccccccdeedaaaaa",
      "cccccccdeedaaaaa",
      "cccccccdeedaaaaa",
      "cccccccdeedaaaaa",
      "cccbcccdeedbbbba",
      "cccccccdeedaaaaa",
      "cccccccdeedaaaaa",
      "cccccccdeedaaaaa",
      "cccccccdeedaaaaa"
    ],
    [
      "cccccccf  faaaaa",
      "cccccccf  faaaaa",
      "cccccccf  faaaaa",
      "cccbcccf  fbbbba",
      "cccccccf  faaaaa",
      "cccccccf  faaaaa",
      "cccccccf  faaaaa",
      "cccccccf  faaaaa",
      "cccccccf  faaaaa",
      "cccccccf  faaaaa",
      "cccccccf  faaaaa",
      "cccbcccf  fbbbba",
      "cccccccf  faaaaa",
      "cccccccf  faaaaa",
      "cccccccf  faaaaa",
      "cccccccf  faaaaa"
    ],
    [
      "cccccccf  faaaaa",
      "cccccccf  faaaaa",
      "cccccccf  faaaaa",
      "cccbcccf  fbbbba",
      "cccccccf  faaaaa",
      "cccccccf  faaaaa",
      "cccccccf  faaaaa",
      "cccccccf  faaaaa",
      "cccccccf  faaaaa",
      "cccccccf  faaaaa",
      "cccccccf  faaaaa",
      "cccbcccf  fbbbba",
      "cccccccf  faaaaa",
      "cccccccf  faaaaa",
      "cccccccf  faaaaa",
      "cccccccf  faaaaa"
    ],
    [
      "cccccccf  faaaaa",
      "cccccccf  faaaaa",
      "cccccccf  faaaaa",
      "cccbcccf  fbbbba",
      "cccccccf  faaaaa",
      "cccccccf  faaaaa",
      "cccccccf  faaaaa",
      "cccccccf  faaaaa",
      "cccccccf  faaaaa",
      "cccccccf  faaaaa",
      "cccccccf  faaaaa",
      "cccbcccf  fbbbba",
      "cccccccf  faaaaa",
      "cccccccf  faaaaa",
      "cccccccf  faaaaa",
      "cccccccf  faaaaa"
    ],
    [
      "cccccccfggfaaaaa",
      "cccccccfggfaaaaa",
      "cccccccfggfaaaaa",
      "cccbcccfggfbbbba",
      "cccccccfggfaaaaa",
      "cccccccfggfaaaaa",
      "cccccccfggfaaaaa",
      "cccccccfggfaaaaa",
      "cccccccfggfaaaaa",
      "cccccccfggfaaaaa",
      "cccccccfggfaaaaa",
      "cccbcccfggfbbbba",
      "cccccccfggfaaaaa",
      "cccccccfggfaaaaa",
      "cccccccfggfaaaaa",
      "cccccccfggfaaaaa"
    ]
  ]
}