{
  "name": "multi_courtyardofficetower_9_floor6",
  "refpalette": "deceasedcraft:multi_courtyardofficetower_9/multi_courtyardofficetower_9_floor6_palette",
  "xsize": 16,
  "zsize": 16,
  "slices": [
    [
      "aaabcccccccb    ",
      "aaabcccccccb    ",
      "aaabcccccccb    ",
      "aaadbbbbbbbddddd",
      "aaaaaaaaaaaab   ",
      "aaaaaaaaaaaab   ",
      "aaaaaaaaaaaab   ",
      "aaaaaaaaaaaabe  ",
      "aaaaaaaaaaaab   ",
      "aaaaaaaaaaaab   ",
      "aaaaaaaaaaaab   ",
      "aaadaaaaaaaddddd",
      "aaaaaaaaaaaaab  ",
      "aaaaaaaaaaaaab  ",
      "aaaaaaaaaaaaab  ",
      "aaaaaaaaaaaaabe "
    ],
    [
      "   fghaij  k    ",
      "   flam j  k    ",
      " n falo p  q    ",
      " rsdffffftuddddd",
      " wsxyyA    Bq   ",
      "  sC D     Ek   ",
      "           Bk   ",
      "           Fke  ",
      "           Fk   ",
      "  sCI      Bk   ",
      " nsJKKL    Mq   ",
      " rsdlll    ddddd",
      " wsxyyA    N q  ",
      "  sC      OPQk  ",
      "     D     R k  ",
      "             ke "
    ],
    [
      "   f Sa j  k    ",
      "   fTaU j  k    ",
      "   faV  W  q    ",
      "  XdfffffYZddddd",
      "  X  01     q   ",
      "  X2        k   ",
      "            k   ",
      "            ke  ",
      "            k   ",
      "  X3       4k   ",
      "  X5678    9q   ",
      "  Xd###    ddddd",
      "  X$%0^      q  ",
      "  X$       % k  ",
      "             k  ",
      "             ke "
    ],
    [
      "   f  a j  k    ",
      "   f&a  j  k    ",
      "   fa*  j  q    ",
      "   dfffff()ddddd",
      "            q   ",
      "            k   ",
      "            k   ",
      "            ke  ",
      "            k   ",
      "            k   ",
      "            q   ",
      "   d       ddddd",
      "             q  ",
      "             k  ",
      "             k  ",
      "             ke "
    ],
    [
      "   f++a j  k    ",
      "   f-a+ j  k    ",
      "   fa-+ j  q    ",
      "   dfffffffddddd",
      "            q   ",
      "            k   ",
      "            k   ",
      "            ke  ",
      "            k   ",
      "            k   ",
      "            q   ",
      "   d       ddddd",
      "             q  ",
      "             k  ",
      "             k  ",
      "             ke "
    ],
    [
      "[[[d]]]]]]]k    ",
      "[{[d]]]]]]]k    ",
      "[[[d]]]]]]]q    ",
      "dddddddddddddddd",
      "[[[d[[[[[[[[q   ",
      "[{[d[{[[[{[[k   ",
      "[[[d[[[[[[[[k   ",
      "[[[d[[[[[[[[ke  ",
      "[[[d[[[[[[[[k   ",
      "[{[d[{[[[{[[k   ",
      "[[[d[[[[[[[[q   ",
      "[[[d[[[[[[[ddddd",
      "[[[d[[[[[[[[[q  ",
      "[{[d[{[[[{[[[k  ",
      "[[[d[[[[[[[[[k  ",
      "[[[d[[[[[[[[[ke "
    ]
  ]
}