{
  "name": "multi_courtyardofficetower_9_floor18",
  "refpalette": "deceasedcraft:multi_courtyardofficetower_9/multi_courtyardofficetower_9_floor18_palette",
  "xsize": 16,
  "zsize": 16,
  "slices": [
    [
      "aaabcccccccb    ",
      "aaabcccccccb    ",
      "aaabcccccccb    ",
      "aaadbbbbbbbddddd",
      "aaaaaaaaaaaab   ",
      "aaaaaaaaaaaab   ",
      "aaaaaaaaaaaab   ",
      "aaaaaaaaaaaabe  ",
      "aaaaaaaaaaaab   ",
      "aaaaaaaaaaaab   ",
      "aaaaaaaaaaaab   ",
      "aaadaaaaaaaddddd",
      "fffaaaaaaaaaab  ",
      "fffaaaaaaaaaab  ",
      "aaaaaaaaaaaaab  ",
      "aaaaaaaaaaaaabe "
    ],
    [
      "   ghijkl  m    ",
      "   gnjo l  m    ",
      "   gjnpqr  s    ",
      "   dgggggtuddddd",
      "            s   ",
      "            m   ",
      "            m   ",
      "            me  ",
      "            m   ",
      "            m   ",
      "            s   ",
      "w  d    xxxddddd",
      "y        AB Cs  ",
      "y            m  ",
      "D        EE Fm  ",
      "         EE Ime "
    ],
    [
      "   g Jj l  m    ",
      "   gKjL l  m    ",
      "   gjM  N  s    ",
      "   dgggggOPddddd",
      "            s   ",
      "            m   ",
      "            m   ",
      "            me  ",
      "            m   ",
      "            m   ",
      "            s   ",
      "   d    QQQddddd",
      "            Rs  ",
      "             m  ",
      "             m  ",
      "             me "
    ],
    [
      "   g  j l  m    ",
      "   gSj  l  m    ",
      "   gjT  l  s    ",
      "   dgggggUVddddd",
      "            s   ",
      "            m   ",
      "            m   ",
      "            me  ",
      "            m   ",
      "            m   ",
      "            s   ",
      "   d       ddddd",
      "             s  ",
      "             m  ",
      "             m  ",
      "             me "
    ],
    [
      "   gWWj l  m    ",
      "   gXjW l  m    ",
      "   gjXW l  s    ",
      "   dgggggggddddd",
      "            s   ",
      "            m   ",
      "            m   ",
      "            me  ",
      "            m   ",
      "            m   ",
      "            s   ",
      "   d       ddddd",
      "             s  ",
      "             m  ",
      "             m  ",
      "             me "
    ],
    [
      "   gYYYYYYYm    ",
      "   gYYYYYYYm    ",
      "   gYYYYYYYs    ",
      "   dgggggggddddd",
      "            s   ",
      "            m   ",
      "            m   ",
      "            me  ",
      "            m   ",
      "            m   ",
      "            s   ",
      "   d       ddddd",
      "             s  ",
      "             m  ",
      "             m  ",
      "             me "
    ]
  ]
}