{
  "name": "multi_thering_5_floor7",
  "refpalette": "deceasedcraft:multi_thering_5/multi_thering_5_floor7_palette",
  "xsize": 16,
  "zsize": 16,
  "slices": [
    [
      "                ",
      "                ",
      "                ",
      "                ",
      "              aa",
      "           aaabb",
      "        aaabbbcc",
      "      aaabbccccc",
      "     aabbccccccc",
      "   aabbcccccccbb",
      "  abbcccccccbbb ",
      "aabbcccccbbbb   ",
      "abccccccbb  d   ",
      "bcccccbbb d     ",
      "cccccbb e       ",
      "cccbbbed       f"
    ],
    [
      "                ",
      "                ",
      "                ",
      "                ",
      "                ",
      "              gg",
      "           ggghh",
      "         gghhhii",
      "       gghhjikkk",
      "     gghhjikkk  ",
      "   gghhikkkk    ",
      "  gghiikk       ",
      " ghhikkk    l   ",
      "ghijkk    l     ",
      "hikkk   m       ",
      "ikk   ml       f"
    ],
    [
      "                ",
      "                ",
      "                ",
      "                ",
      "                ",
      "                ",
      "              hh",
      "           hhh  ",
      "         hh     ",
      "       hh       ",
      "     hh         ",
      "    h           ",
      "  hh        h   ",
      " h        h     ",
      "h       l       ",
      "      lh       f"
    ],
    [
      "                ",
      "                ",
      "                ",
      "                ",
      "                ",
      "                ",
      "                ",
      "                ",
      "                ",
      "                ",
      "                ",
      "                ",
      "            h   ",
      "          h     ",
      "        h       ",
      "      hh       f"
    ],
    [
      "                ",
      "                ",
      "                ",
      "                ",
      "                ",
      "                ",
      "                ",
      "                ",
      "                ",
      "                ",
      "                ",
      "                ",
      "            h   ",
      "          n     ",
      "        h       ",
      "      hn       f"
    ],
    [
      "                ",
      "                ",
      "                ",
      "                ",
      "                ",
      "                ",
      "                ",
      "                ",
      "                ",
      "                ",
      "                ",
      "                ",
      "            n   ",
      "                ",
      "        n       ",
      "      n        f"
    ]
  ]
}