{
  "name": "multi_thering_5_base2",
  "refpalette": "deceasedcraft:multi_thering_5/multi_thering_5_base2_palette",
  "xsize": 16,
  "zsize": 16,
  "slices": [
    [
      "vvvvvvvvvvvvvvvv",
      "aaaaaaaaaaaaaaaa",
      "aaaaaaaaaaaaaaaa",
      "aaaaaaaaaaaaaaaa",
      "aaaaaaaaaaaaaaaa",
      "aaaaaaaaaaaaaaaa",
      "aaaaaaaaaaaaaaaa",
      "aaaaaaaaaaaaaaaa",
      "aaaaaaaaaaaaaaaa",
      "aaaaaaaaaaaaaaaa",
      "aaaaaaaaaaaaaaaa",
      "aaaaaaaaaaaaaaaa",
      "aaaaaaaaaaaaaaaa",
      "aaaaaaaaaaaaaaaa",
      "aaaaaaaaaaaaaaaa",
      "aaaaaaaaaaaaaaab"
    ],
    [
      "vvvvvvvvvvvvvvvv",
      "aaaaaaaaaaaaaaaa",
      "aaaaaaaaaaaaaaaa",
      "aaaaaaaaaaaaaaaa",
      "aaaaaaaaaaaaaaaa",
      "aaaaaaaaaaaaaaaa",
      "aaaaaaaaaaaaaaaa",
      "aaaaaaaaaaaaaaaa",
      "aaaaaaaaaaaaaaaa",
      "aaaaaaaaaaaaaaaa",
      "aaaaaaaaaaaaaaaa",
      "aaaaaaaaaaaaaaaa",
      "aaaaaaaaaaaaaaaa",
      "aaaaaaaaaaaaaaaa",
      "aaaaaaaaaaaaaaaa",
      "aaaaaaaaaaaaaaab"
    ],
    [
      "vvvvvvvvvvvvvvvv",
      "cccccccccccccccc",
      "cccccccccccccccc",
      "cccccccccccccccc",
      "cccccccccccccccc",
      "cccccccccccccccc",
      "cccccccccccccccc",
      "cccccccccccccccc",
      "cccccccccccccccc",
      "cccccccccccccccc",
      "cccccccccccccccc",
      "cccccccccccccccc",
      "cccccccccccccccc",
      "cccccccccccccccc",
      "cccccccccccccccc",
      "cccccccccccccccb"
    ],
    [
      "vvvvvvvvvvvvvvvv",
      "dddddddddddddddd",
      "deeeeeeeeeeeeeee",
      "feeeeeeeeeeeeeee",
      "deeeeeeeeeeeeeee",
      "deeeeeeeeeeeeeee",
      "deeeeeeeeeeeeeee",
      "deeeeeeeeeeeeeee",
      "deeeeeeeeeeeeeee",
      "deeeeeeeeeeeeeee",
      "deeeeeeeeeeeeeee",
      "deeeeeeeeeeeeeee",
      "deeeeeeeeeeeeeee",
      "feeeeeeeeeeeeeee",
      "deeeeeeeeeeeeeee",
      "deeggggggggggeed"
    ],
    [
      "vvvvvvvvvvvvvvvv",
      "dddddddddddddddd",
      "dh        ijklmn",
      "o               ",
      "dpqd            ",
      "dr s     tuwxy  ",
      "dr s     ABCDE  ",
      "dr s            ",
      "dr s            ",
      "dr s            ",
      "dr s     tuwxy  ",
      "dr s     ABCDE  ",
      "dFId            ",
      "J               ",
      "d               ",
      "d  KKKKKKKKKK  L"
    ],
    [
      "vvvvvvvvvvvvvvvv",
      "dddddddddddddddd",
      "dM   NOP  ijk Mn",
      "                ",
      "d               ",
      "dQ R     tSTUy  ",
      "dV W     AXYZE  ",
      "dV              ",
      "dV              ",
      "dV 0            ",
      "dV W     tSTUy  ",
      "d1 2     AXYZE  ",
      "d               ",
      "                ",
      "d  3343445545   ",
      "d 67888888889# L"
    ]
  ]
}