{
  "name": "multi_pumpjack_0_ground",
  "refpalette": "deceasedcraft:multi_pumpjack_0/multi_pumpjack_0_ground_palette",
  "xsize": 16,
  "zsize": 16,
  "slices": [
    [
      "zzzzzzzzzzzzzzzz",
      "zzzzzzzzzzzzzzzz",
      "zzzzzzzzzzzzzzzz",
      "zzzzzaazzzzzzzzz",
      "zzzzzaazzzzzzzzz",
      "zzzzzzzzzzzzzzzz",
      "zzzzzzzzzzzzzzzz",
      "zzzzaaaaazzzzzzz",
      "zzzzaaaaazzzzzzz",
      "zzzzzzzzzzzzzzzz",
      "zzzzzzzzzzzzzzzz",
      "zzzzzzzzzzzzzzzz",
      "zzzzzzzzzzzzzzzz",
      "zzzzzzzzzzzzzzzz",
      "zzzzzzzzzzzzzzzz",
      "zzzzzzzzzzzzzzzz"
    ],
    [
      " b   b    b b  b",
      "  cc    b    b c",
      " bcddddddddddddd",
      " b deeeeeeeeeeed",
      "   deeeeeeeeeeed",
      "  bdeeeeeceeeeed",
      "   deeeeeeeeeeed",
      "  bdeeeeeeeeeeed",
      "   d!eeeeeeeeeed",
      " b deeeeeeeeeeed",
      "   dffffffeeeeed",
      "b  dffffffeeeeed",
      "   dffffffeeeeed",
      "  bdffffffeeeeed",
      "   dffffffeeeeed",
      " b dfffffceeeeed"
    ],
    [
      "                ",
      "  cc           c",
      "  cddddddddddddd",
      "   dghhhgdijk!ld",
      "   dm    di   no",
      "   d     p    qr",
      "   d     ds   qr",
      "   dtdtdud    wr",
      "   dxdxdxd    yr",
      "   ddddddo     o",
      "   dABCDCdEF    ",
      "   dIJ   dKLM NO",
      "   dP   Qdw     ",
      "   dR   Sdy     ",
      "   dTUU Udy   Vo",
      "   d     W    Xd"
    ],
    [
      "                ",
      "  cc           c",
      "  cddddddddddddd",
      "   dY   Zdi  kld",
      "   d     di    o",
      "   d     0     r",
      "   d     d     r",
      "   d1d1d2d3   yr",
      "   d4d4d4d3    r",
      "   ddddddo     o",
      "   d56 7 d3     ",
      "   d     8      ",
      "   d9    8      ",
      "   dT    d      ",
      "   d  # $d     o",
      "   d     %     d"
    ],
    [
      "                ",
      "  cc           c",
      "  cdd^^^ddd^^^dd",
      "   d & & di   ld",
      "   ^     di    o",
      "   ^     d     r",
      "   ^     d     r",
      "   d * * d     r",
      "   d *&* d     r",
      "   ddddddo     o",
      "   d((***d     r",
      "   d9    )     r",
      "   ^T    )     r",
      "   ^     d     r",
      "   ^     d     o",
      "   d     d     d"
    ],
    [
      "                ",
      "  cc           c",
      "  cddddddddddddd",
      "   d+++++di   ld",
      "   d-----d[    o",
      "   d-----d     o",
      "   d-----d     o",
      "   d-----d     o",
      "   d+++++d[    o",
      "   ddddooo     o",
      "   d+++++d[    o",
      "   dT----d]]   o",
      "   d ----d]]   o",
      "   d ----d]]   o",
      "   d ----d]]   o",
      "   d ----d]]]]]d"
    ]
  ]
}