{
  "name": "multi_pumpjack_0_top",
  "refpalette": "deceasedcraft:multi_pumpjack_0/multi_pumpjack_0_top_palette",
  "xsize": 16,
  "zsize": 16,
  "slices": [
    [
      "                ",
      "  aa           a",
      "  abbbbbbbbbbbbb",
      "   bc deeb    fb",
      "   bc    b     g",
      "   bc h  b     g",
      "   bijkl b     g",
      "   b!    b     g",
      "   bmn   b     g",
      "   bbbopqo     b",
      "   b     b     g",
      "   b r  sbtu   g",
      "   b r  wb x   g",
      "   b r  yb x   g",
      "   b r  Ab x   g",
      "   b r   B  tttb"
    ],
    [
      "                ",
      "  aaCCCCCCCCCCCa",
      "  abbbbbbbbbbbbb",
      "  CbD  Eeb    fb",
      "  CbF    I     b",
      "  CbJ    I     b",
      "  Cb  K  b     b",
      "  Cb     b     b",
      "  CbL    b     b",
      "  CbIIoMNo     b",
      "  Cb     b     b",
      "  Cb     I     b",
      "  Cb     I     b",
      "  Cb     b     b",
      "  Cb     b     b",
      "  Cb     O     b"
    ],
    [
      "                ",
      "  aa           a",
      "  abbbbbbbbbbbbb",
      "   bP Q  bR   fb",
      "   b     S    fb",
      "   b     S  T fb",
      "   b     b  T fb",
      "   b     b    Ub",
      "   bV Q  b    fb",
      "   bSSobbo  T fb",
      "   b  Q  b  T fb",
      "   b     S    fb",
      "   b     S    Ub",
      "   b     b  T fb",
      "   b     b  T fb",
      "   b     bR  ffb"
    ],
    [
      "                ",
      "  aaaaaaaaaaaaaa",
      "  aaaaaaaabbbbbb",
      "  aaWXXXXabbbbbb",
      "  aaYYYYYabbbbbb",
      "  aaYYYYYabbbbbb",
      "  aaYYYYYabbbbbb",
      "  aaYYYYYabbbbbb",
      "  aaXXXXXabbbbbb",
      "  aaaaaaaabbbbbb",
      "  aaXXXXXabbbbbb",
      "  aaYYYYYabbbbbb",
      "  aaYYYYYabbbbbb",
      "  aaYYYYYabbbbbb",
      "  aaYYYYYabbbbbb",
      "  aaYYYYYabbbbbb"
    ],
    [
      " ZZZZZZZZZZZZZZZ",
      " ZZZZZZZZZZZZZZZ",
      " ZZaaaaaaa    ff",
      " ZZa0fbbba    ff",
      " ZZabbbbba      ",
      " ZZabbbbba    ff",
      " ZZabbbbba    ff",
      " ZZabbbbba      ",
      " ZZabbbbba      ",
      " ZZabbbbba      ",
      " ZZabbbbba      ",
      " ZZabbbbba      ",
      " ZZabbbbba      ",
      " ZZabbbbba      ",
      " ZZabbbbba      ",
      " ZZabbbbba      "
    ],
    [
      "                ",
      "                ",
      "               P",
      "    W1          ",
      "    P           ",
      "               P",
      "                ",
      "                ",
      "                ",
      "    fff2        ",
      "    ff32        ",
      "                ",
      "                ",
      "    fff2        ",
      "    ff32        ",
      "                "
    ],
    [
      "                ",
      "                ",
      "                ",
      "    WP          ",
      "    P           ",
      "                ",
      "                ",
      "                ",
      "                ",
      "    ff4         ",
      "    ff          ",
      "                ",
      "                ",
      "    ff4         ",
      "    ff          ",
      "                "
    ],
    [
      "                ",
      "                ",
      "                ",
      "    PP          ",
      "                ",
      "                ",
      "                ",
      "                ",
      "                ",
      "                ",
      "                ",
      "                ",
      "                ",
      "                ",
      "                ",
      "                "
    ],
    [
      "                ",
      "                ",
      "                ",
      "    PP          ",
      "                ",
      "                ",
      "                ",
      "                ",
      "                ",
      "                ",
      "                ",
      "                ",
      "                ",
      "                ",
      "                ",
      "                "
    ],
    [
      "                ",
      "                ",
      "                ",
      "     P          ",
      "                ",
      "                ",
      "                ",
      "                ",
      "                ",
      "                ",
      "                ",
      "                ",
      "                ",
      "                ",
      "                ",
      "                "
    ],
    [
      "                ",
      "                ",
      "                ",
      "     P          ",
      "                ",
      "                ",
      "                ",
      "                ",
      "                ",
      "                ",
      "                ",
      "                ",
      "                ",
      "                ",
      "                ",
      "                "
    ]
  ]
}