{
  "name": "multi_pumpjack_3_ground",
  "refpalette": "deceasedcraft:multi_pumpjack_3/multi_pumpjack_3_ground_palette",
  "xsize": 16,
  "zsize": 16,
  "slices": [
    [
      "zzzzzzzzzzzzzzzz",
      "zzzz===z===zzzzz",
      "zzzz===z===zzzzz",
      "zzzz===z===!zzzz",
      "zzza===z===zzzzz",
      "zzbz===z===zzzzz",
      "zzbb===z===zzzzz",
      "zzaba==z===zzzzz",
      "zzzba==z===zzzzz",
      "zzzz===z===zzzzz",
      "zzzzzzzzzzzzzzzz",
      "zzzzzzzzzzzzzzzz",
      "zccczczczcczcczz",
      "czccczccczcczzcz",
      "ccccccczzzzzcczz",
      "zzzzzzzzzzzzzzzz"
    ],
    [
      "d         e fe  ",
      "d    g h g  ij  ",
      "kl   m     kd n ",
      "ol   l     ki   ",
      "pq   l  m mrf n ",
      "s   tmu     f   ",
      "w           d n ",
      "w           f   ",
      "         x  f n ",
      " wwyg A  AoBi   ",
      "diiidfifdiiidn  ",
      "      n         ",
      "    n         n ",
      "         n      ",
      "               n",
      " n        n     "
    ],
    [
      "d               ",
      "d           C   ",
      "k          kd   ",
      "            C   ",
      "D       E E C   ",
      "            C   ",
      "            d   ",
      "            C   ",
      "            C   ",
      " EE         C   ",
      "dCCCdCCCdCCCd   ",
      "                ",
      "                ",
      "                ",
      "                ",
      "                "
    ],
    [
      "d               ",
      "d           C   ",
      "            d   ",
      "            C   ",
      "        E E C   ",
      "            C   ",
      "            d   ",
      "            C   ",
      "            C   ",
      " EE         C   ",
      "dCCCdCCCdCCCd   ",
      "                ",
      "                ",
      "                ",
      "                ",
      "                "
    ],
    [
      "d               ",
      "d        F      ",
      "         l  I   ",
      "         l      ",
      "        tmu     ",
      "         l      ",
      "         l  I   ",
      "         l      ",
      "         l      ",
      "         J      ",
      "I   I   I   I   ",
      "                ",
      "                ",
      "                ",
      "                ",
      "                "
    ],
    [
      "d               ",
      "d               ",
      "                ",
      "                ",
      "                ",
      "                ",
      "                ",
      "                ",
      "                ",
      "                ",
      "                ",
      "                ",
      "                ",
      "                ",
      "                ",
      "                "
    ]
  ]
}