{
  "name": "multi_laboratory_14_base2",
  "refpalette": "deceasedcraft:multi_laboratory_14/multi_laboratory_14_base2_palette",
  "xsize": 16,
  "zsize": 16,
  "slices": [
    [
      "aaaabaaaaaaaacdv",
      "aaaaaaaaaaaaacdv",
      "aaaaaaaaaaaaacdv",
      "aaaaaaaaaaaaacdv",
      "aaaaaaaaaaaaacdv",
      "aaaaaaaaaaaaacdv",
      "aaaaaaaaaaaaacdv",
      "aaaabaaaaaaaacdv",
      "aaaaaeeeeeeeecdv",
      "aaaaaeeeeeeeecdv",
      "aaaaaeeeeeeeecdv",
      "aaaaaeeeeeeeecdv",
      "aa!aa!eeeeeeecdv",
      "ccccccccccccccdv",
      "dddddddddddddddv",
      "vvvvvvvvvvvvvvvv"
    ],
    [
      "f   bggggggggcdv",
      "f   g        cdv",
      "h   g i jj k cdv",
      "lm  g        cdv",
      "    g   no p cdv",
      "    q      r cdv",
      "    gsssssssscdv",
      "    bggggggggcdv",
      "    gmmttttmmcdv",
      "    u        cdv",
      "    gwxyxwxwxcdv",
      "    g A A A Acdv",
      " BBCgDADADADAcdv",
      "ccccccccccccccdv",
      "dddddddddddddddv",
      "vvvvvvvvvvvvvvvv"
    ],
    [
      "    bggEEEEggcdv",
      "    g        cdv",
      "F   g        cdv",
      "I   g        cdv",
      "    g        cdv",
      "    J        cdv",
      "    gKL   M Kcdv",
      "    bggggggggcdv",
      "    gK      Kcdv",
      "    N        cdv",
      "    gOxPxOxOxcdv",
      "    g A A A Acdv",
      "    g A A A Acdv",
      "ccccccccccccccdv",
      "dddddddddddddddv",
      "vvvvvvvvvvvvvvvv"
    ],
    [
      "    bggQQQQggcdv",
      "   RgS      Scdv",
      "   Tg        cdv",
      "    g        cdv",
      "    g        cdv",
      "    U        cdv",
      "    g        cdv",
      "    bggggggggcdv",
      "    g VWWWWX cdv",
      "    g        cdv",
      "    gxxxxxxxxcdv",
      "    g A A A Acdv",
      "    g A A A Acdv",
      "ccccccccccccccdv",
      "dddddddddddddddv",
      "vvvvvvvvvvvvvvvv"
    ],
    [
      "    bggggggggcdv",
      "    gS      Scdv",
      "    g        cdv",
      "    g        cdv",
      "    g        cdv",
      "    g        cdv",
      "    g        cdv",
      "    bggggggggcdv",
      "    gYYYYYYYYcdv",
      "    gYYYYYYYYcdv",
      "    gYYYYYYYYcdv",
      "    gYYYYYYYYcdv",
      "    gZYZYZYZYcdv",
      "ccccccccccccccdv",
      "dddddddddddddddv",
      "vvvvvvvvvvvvvvvv"
    ],
    [
      "0 00bggggggggcdv",
      "0100U22222222cdv",
      "0100U23222232cdv",
      "4400U22222222cdv",
      "0000U22222222cdv",
      "0000U25222212cdv",
      "0000U22222222cdv",
      "ggggbggggggggcdv",
      "6666g77777777cdv",
      "6686g7 7 7 7ccdv",
      "6686g7 7 7 7ccdv",
      "6686g7 7 7 7ccdv",
      "6666g7 7 7 7ccdv",
      "ccccccccccccccdv",
      "dddddddddddddddv",
      "vvvvvvvvvvvvvvvv"
    ]
  ]
}