{
  "name": "multi_laboratory_14_ground",
  "refpalette": "deceasedcraft:multi_laboratory_14/multi_laboratory_14_ground_palette",
  "xsize": 16,
  "zsize": 16,
  "slices": [
    [
      "aaaabcccvvddddzd",
      "aaaabcccvvdddzdz",
      "aaaabcccvedzdddd",
      "ffffbcccvedddddz",
      "ffffbcccveedddzz",
      "ffffbcccveeddddz",
      "ffffbcccveddzdzz",
      "ffffbcccevdddzdz",
      "ffffbcccvededdzz",
      "ffffbcccveddddzz",
      "bbbbbcccvdzdddzz",
      "cccccccvvedddzzd",
      "cccccccevedzzzzz",
      "ccccceeeeddzzdzz",
      "ddzddddddzdzzzzz",
      "dzzzzzdzzzzzzzzz"
    ],
    [
      "g   b  h   ij   ",
      "    k  h        ",
      "llllm  h   n    ",
      "opopk  h       n",
      "o o k  h      n ",
      "qrqrk  h        ",
      "    k  h       n",
      "s   b  h     n  ",
      "t   k  h        ",
      "s  um  h      n ",
      "kbkmm  h        ",
      "      h      n  ",
      "     hh    n n  ",
      "hhhhh       n n ",
      "         n      ",
      "  n        n n  "
    ],
    [
      "    b  w        ",
      "    x  h        ",
      "llllm  h        ",
      "o o k  h        ",
      "o o k  w        ",
      "qyqyk  h        ",
      "    A  h        ",
      "    b  w        ",
      "    k  w        ",
      "   Bk  h        ",
      "Abkkm  h        ",
      "      h         ",
      "     hh         ",
      "hwhhh           ",
      "                ",
      "                "
    ],
    [
      "    b  w        ",
      "    x  C        ",
      "llllm  C        ",
      "o o k  w        ",
      "o o k  w        ",
      "qqqqk  w        ",
      "    A  C        ",
      "    b  w        ",
      "D   k  w        ",
      "   Ek  w        ",
      "Abkkm  C        ",
      "      C         ",
      "     ww         ",
      "wwwCw           ",
      "                ",
      "                "
    ],
    [
      "    b  C        ",
      "    x  w        ",
      "llllm  w        ",
      "o o k  C        ",
      "o o k  w        ",
      "qqqqk  w        ",
      "    A  w        ",
      "    b  C        ",
      "    k  w        ",
      "    k  C        ",
      "Abkkm  w        ",
      "      C         ",
      "     Cw         ",
      "CwwwC           ",
      "                ",
      "                "
    ],
    [
      "FFFFb  C        ",
      "FFFFk  C        ",
      "llllm  w        ",
      "IIIIk  C        ",
      "JIJIk  C        ",
      "IIIIk  C        ",
      "IIJIk  C        ",
      "IIIIb  w        ",
      "JIJIk  w        ",
      "IIIIk  C        ",
      "kbkkm  C        ",
      "      C         ",
      "     wC         ",
      "wwwCw           ",
      "                ",
      "                "
    ]
  ]
}