{
  "name": "multi_laboratory_14_base4",
  "refpalette": "deceasedcraft:multi_laboratory_14/multi_laboratory_14_base4_palette",
  "xsize": 16,
  "zsize": 16,
  "slices": [
    [
      "aaaabaaaaaaaaccv",
      "aaaaaaaaaaaaaccv",
      "aaaaaaaaaaaaaccv",
      "aaaaaaaaaaaaaccv",
      "aaaaaaaaaaaaaccv",
      "aaaaaaaaaaaaaccv",
      "aaaaaaaaaaaa!ccv",
      "aaaabaaaaaaaaccv",
      "aaaaaddddddddccv",
      "aaaaaddddddddccv",
      "aaaaaddddddddccv",
      "aaaaaddddddddccv",
      "aaaaaddddddddccv",
      "cccccccccccccccv",
      "eeeecccccccccccv",
      "vvvvvvvvvvvvvvvv"
    ],
    [
      "fg  bhhhhhhhhccv",
      "f   hijjklm nccv",
      "o   hjp     qccv",
      "rs  hj   tt uccv",
      "    hw   tt uccv",
      "    x       yccv",
      "    h    AB nccv",
      "    bhhhhhhhhccv",
      "    hssCCCCssccv",
      "    D        ccv",
      "    hEFEFEFEFccv",
      "    h I I I Iccv",
      "JKKLhMIMIMIMIccv",
      "cccccccccccccccv",
      "eeeecccccccccccv",
      "vvvvvvvvvvvvvvvv"
    ],
    [
      "    bhhhhhhhhccv",
      "    hiNjk   Occv",
      "P   hj       ccv",
      "    hj       ccv",
      "    hw       ccv",
      "    Q        ccv",
      "    h       Occv",
      "    bhhhhhhhhccv",
      "    hO      Occv",
      "    R        ccv",
      "    hSFSFSFSFccv",
      "    h I I I Iccv",
      "    h I I I Iccv",
      "cccccccccccccccv",
      "eeeecccccccccccv",
      "vvvvvvvvvvvvvvvv"
    ],
    [
      "    bhhhhhhhhccv",
      "    hiT     Uccv",
      "   Vhp       ccv",
      "   Wh        ccv",
      "    h        ccv",
      "    X        ccv",
      "    h       Uccv",
      "    bhhhhhhhhccv",
      "    h YZZZZ0 ccv",
      "    h        ccv",
      "    hFFFFFFFFccv",
      "    h I I I Iccv",
      "    h I I I Iccv",
      "cccccccccccccccv",
      "eeeecccccccccccv",
      "vvvvvvvvvvvvvvvv"
    ],
    [
      "    bhhhhhhhhccv",
      "    hi       ccv",
      "    h        ccv",
      "    h        ccv",
      "    h        ccv",
      "    h        ccv",
      "    h        ccv",
      "    bhhhhhhhhccv",
      "    h11111111ccv",
      "    h11111111ccv",
      "    h11111111ccv",
      "    h11111111ccv",
      "    h21!12121ccv",
      "cccccccccccccccv",
      "eeeecccccccccccv",
      "vvvvvvvvvvvvvvvv"
    ],
    [
      "3433bhhhhhhhhcev",
      "3433X55555555cev",
      "3633X57555575cev",
      "6633X55555555cev",
      "3333X55555555cev",
      "3333X57555575cev",
      "3333X55555555cev",
      "hhhhbhhhhhhhhcev",
      "8888h99999999cev",
      "8868h9 9 9 9ccev",
      "8848h9 9 9 9ccev",
      "8848h9 9 9 9ccev",
      "8888h9 9 9 9ccev",
      "ccccccccccccccev",
      "eeeeeeeeeeeeeeev",
      "vvvvvvvvvvvvvvvv"
    ]
  ]
}