{
  "name": "multi_laboratory_14_base5",
  "refpalette": "deceasedcraft:multi_laboratory_14/multi_laboratory_14_base5_palette",
  "xsize": 16,
  "zsize": 16,
  "slices": [
    [
      "   ab   cdc   ev",
      "    f   d d   gv",
      "    h  id dj  gv",
      "    h   d d   gv",
      "    h   cdc   gv",
      "    h   k k   gv",
      "    h   ldl   gv",
      "   mb   n n   ev",
      "    o     p   gv",
      "    o         gv",
      "    q         gv",
      "    q         gv",
      "    o         gv",
      "rrrro         gv",
      "ssssrgggggggggrv",
      "vvvvvvvvvvvvvvvv"
    ],
    [
      "    b         ev",
      "    h         gv",
      "    h   t t   gv",
      "    h     u   gv",
      "    h         gv",
      "    h         gv",
      "    h         gv",
      "    b         ev",
      "    o         gv",
      "    o         gv",
      "    q         gv",
      "    q         gv",
      "    o         gv",
      "rrrro         gv",
      "ssssrgggggggggrv",
      "vvvvvvvvvvvvvvvv"
    ],
    [
      "    b         ev",
      "    h         gv",
      "    h         gv",
      "    h         gv",
      "    h         gv",
      "    h         gv",
      "    h         gv",
      "    b         ev",
      "    o         gv",
      "    o         gv",
      "    q         gv",
      "    q         gv",
      "    o         gv",
      "rrrro         gv",
      "ssssrgggggggggrv",
      "vvvvvvvvvvvvvvvv"
    ],
    [
      "    b         ev",
      "    h         gv",
      "    h         gv",
      "    h         gv",
      "    h         gv",
      "    h         gv",
      "    h         gv",
      "    b         ev",
      "    o         gv",
      "    o         gv",
      "    q         gv",
      "    q         gv",
      "    o         gv",
      "rrrro         gv",
      "ssssrgggggggggrv",
      "vvvvvvvvvvvvvvvv"
    ],
    [
      "    b         ev",
      "    o         gv",
      "    o         gv",
      "    o         gv",
      "    o         gv",
      "    o         gv",
      "    o         gv",
      "    b         ev",
      "    o         gv",
      "    o         gv",
      "    o         gv",
      "    o         gv",
      "    o         gv",
      "rrrro         gv",
      "ssssrgggggggggrv",
      "vvvvvvvvvvvvvvvv"
    ],
    [
      "eeeeoeeeeeeeeerv",
      "eeeeoeeeeeeeeerv",
      "eeeeoeeeeeeeeerv",
      "eeeeoeewxxxweerv",
      "eeeeoeewxxxweerv",
      "eeeeoeeeeeeeeerv",
      "eeeeoeeeeeeeeerv",
      "eeeeoeeeeeeeeerv",
      "eeeeoeeeeeeeeerv",
      "eeeeoeeeeeeeeerv",
      "eeeeoeexwxxxeerv",
      "eeeeoeexwxxxeerv",
      "eeeeoeeeeeeeeerv",
      "rrrroeeeeeeeeerv",
      "ssssrrrrrrrrrrrv",
      "vvvvvvvvvvvvvvvv"
    ]
  ]
}