{
  "name": "multi_laboratory_14_top",
  "refpalette": "deceasedcraft:multi_laboratory_14/multi_laboratory_14_top_palette",
  "xsize": 16,
  "zsize": 16,
  "slices": [
    [
      "aaaabcde        ",
      "aaaabffe        ",
      "aaaabffe        ",
      "aaaabffe        ",
      "aaaabffe        ",
      "aaaabffg        ",
      "aaaabffe        ",
      "aaaabcdg        ",
      "aaaab!fe        ",
      "aaaabffe        ",
      "bbbbbffg        ",
      "hihhhhg         ",
      "hdhhhee         ",
      "eeeee           ",
      "                ",
      "                "
    ],
    [
      "    j  e        ",
      "   kl  g        ",
      "   ml  e        ",
      "   nl  e        ",
      "    l  e        ",
      "    l  e        ",
      "    l  e        ",
      "op qj  e        ",
      " r sl  e        ",
      " r  l  e        ",
      "ljlll  e        ",
      "      e         ",
      "     eg         ",
      "egeee           ",
      "                ",
      "                "
    ],
    [
      "    j  g        ",
      "       e        ",
      "       e        ",
      "       g        ",
      "       e        ",
      "       e        ",
      "       e        ",
      " t uj  e        ",
      "       e        ",
      "       g        ",
      " j     e        ",
      "      e         ",
      "     ee         ",
      "geeeg           ",
      "                ",
      "                "
    ],
    [
      "    j  e        ",
      "       e        ",
      "       e        ",
      "       e        ",
      "       e        ",
      "       e        ",
      "       g        ",
      "   wj  e        ",
      "       e        ",
      "       e        ",
      " j     e        ",
      "      e         ",
      "     eg         ",
      "eeeee           ",
      "                ",
      "                "
    ],
    [
      "    j  e        ",
      "       e        ",
      "       e        ",
      "       e        ",
      "       e        ",
      "       e        ",
      "       e        ",
      "    j  e        ",
      "       e        ",
      "       e        ",
      " j     e        ",
      "      e         ",
      "     ee         ",
      "eeeee           ",
      "                ",
      "                "
    ],
    [
      "    b  e        ",
      "    d  e        ",
      "    d  e        ",
      "    d  e        ",
      "    d  e        ",
      "    d  e        ",
      "    d  e        ",
      "    b  e        ",
      "    d  e        ",
      "    d  e        ",
      "dbddd  e        ",
      "      e         ",
      "     ee         ",
      "eeeeg           ",
      "                ",
      "                "
    ],
    [
      "xxxxbcde        ",
      "xxxxb  e        ",
      "xxxxb  e        ",
      "xxxxb  e        ",
      "xxxxb  e        ",
      "xxxxb  e        ",
      "xxxxb  e        ",
      "xxxxbcde        ",
      "xxxxb  e        ",
      "xxxxb  e        ",
      "bbbbb  e        ",
      "yi    e         ",
      "yd   ee         ",
      "eeeee           ",
      "                ",
      "                "
    ],
    [
      "    A  e        ",
      "    l  e        ",
      "    l  e        ",
      "   Bl  e        ",
      "   Cl  e        ",
      "   Dl  e        ",
      "   ql  e        ",
      "    A  e        ",
      "    l  e        ",
      "    l  e        ",
      " jlll  e        ",
      " l    e         ",
      " l   ee         ",
      "eeeee           ",
      "                ",
      "                "
    ],
    [
      "       e        ",
      "       e        ",
      "       e        ",
      "       e        ",
      "       e        ",
      "       e        ",
      "   E   e        ",
      "       e        ",
      "       e        ",
      "       e        ",
      "       e        ",
      "      e         ",
      "     ee         ",
      "eeeee           ",
      "                ",
      "                "
    ],
    [
      "                ",
      "                ",
      "       F        ",
      "       F        ",
      "       F        ",
      "       e        ",
      "       e        ",
      "       e        ",
      "       e        ",
      "       e        ",
      "       e        ",
      "      e         ",
      "     ee         ",
      "eeeee           ",
      "                ",
      "                "
    ],
    [
      "                ",
      "                ",
      "                ",
      "                ",
      "                ",
      "                ",
      "                ",
      "                ",
      "       F        ",
      "       F        ",
      "       F        ",
      "      e         ",
      "     ee         ",
      "eeeee           ",
      "                ",
      "                "
    ]
  ]
}