{
  "name": "multi_laboratory_14_base7",
  "refpalette": "deceasedcraft:multi_laboratory_14/multi_laboratory_14_base7_palette",
  "xsize": 16,
  "zsize": 16,
  "slices": [
    [
      "aaaaaaaaaaaaaaav",
      "aaaaaaaaaaaaaaav",
      "aaaaaaaaaaaaaaav",
      "aaaaaaaaaaaaaaav",
      "aaaaaaaaaaaaaaav",
      "aaaaaaaaaaaaaaav",
      "aaaaaaaaaaaaaaav",
      "aaaaaaaaaaaaaaav",
      "aaaaaaaaaaaaaaav",
      "aaaaaaaaaaaaaaav",
      "aaaaaaaaaaaaaaav",
      "aaaaaaaaaaaaaaav",
      "aaaaaaaaaaaaaaav",
      "aaaaaaaaaaaaaaav",
      "aaaaaaaaaaaaaaav",
      "vvvvvvvvvvvvvvvv"
    ],
    [
      "aaaaaaaaaaaaaaav",
      "aaaaaaaaaaaaaaav",
      "aaaaaaaaaaaaaaav",
      "aaaaaaaaaaaaaaav",
      "aaaaaaaaaaaaaaav",
      "aaaaaaaaaaaaaaav",
      "aaaaaaaaaaaaaaav",
      "aaaaaaaaaaaaaaav",
      "aaaaaaaaaaaaaaav",
      "aaaaaaaaaaaaaaav",
      "aaaaaaaaaaaaaaav",
      "aaaaaaaaaaaaaaav",
      "aaaaaaaaaaaaaaav",
      "aaaaaaaaaaaaaaav",
      "aaaaaaaaaaaaaaav",
      "vvvvvvvvvvvvvvvv"
    ],
    [
      "aaaaaaaaaaaaaaav",
      "aaaaaaaaaaaaaaav",
      "aaaaaaaaaaaaaaav",
      "aaaaaaaaaaaaaaav",
      "aaaaaaaaaaaaaaav",
      "aaaaaaaaaaaaaaav",
      "aaaaaaaaaaaaaaav",
      "aaaaaaaaaaaaaaav",
      "aaaaaaaaaaaaaaav",
      "aaaaaaaaaaaaaaav",
      "aaaaaaaaaaaaaaav",
      "aaaaaaaaaaaaaaav",
      "aaaaaaaaaaaaaaav",
      "aaaaaaaaaaaaaaav",
      "aaaaaaaaaaaaaaav",
      "vvvvvvvvvvvvvvvv"
    ],
    [
      "aaaaaaaaaaaaaaav",
      "aaaaaaaaaaaaaaav",
      "aaaaaaaaaaaaaaav",
      "aaaaaaaaaaaaaaav",
      "aaaaaaaaaaaaaaav",
      "aaaaaaaaaaaaaaav",
      "aaaaaaaaaaaaaaav",
      "aaaaaaaaaaaaaaav",
      "aaaaaaaaaaaaaaav",
      "aaaaaaaaaaaaaaav",
      "aaaaaaaaaaaaaaav",
      "aaaaaaaaaaaaaaav",
      "aaaaaaaaaaaaaaav",
      "aaaaaaaaaaaaaaav",
      "aaaaaaaaaaaaaaav",
      "vvvvvvvvvvvvvvvv"
    ],
    [
      "aaaaaaaaaaaaaaav",
      "aaaaaaaaaaaaaaav",
      "aaaaaaaaaaaaaaav",
      "aaaaaaaaaaaaaaav",
      "aaaaaaaaaaaaaaav",
      "aaaaaaaaaaaaaaav",
      "aaaaaaaaaaaaaaav",
      "aaaaaaaaaaaaaaav",
      "aaaaaaaaaaaaaaav",
      "aaaaaaaaaaaaaaav",
      "aaaaaaaaaaaaaaav",
      "aaaaaaaaaaaaaaav",
      "aaaaaaaaaaaaaaav",
      "aaaaaaaaaaaaaaav",
      "aaaaaaaaaaaaaaav",
      "vvvvvvvvvvvvvvvv"
    ],
    [
      "aaaaaaaaaaaaaaav",
      "aaaaaaaaaaaaaaav",
      "aaaaaaaaaaaaaaav",
      "aaaaaaaaaaaaaaav",
      "aaaaaaaaaaaaaaav",
      "aaaaaaaaaaaaaaav",
      "aaaaaaaaaaaaaaav",
      "aaaaaaaaaaaaaaav",
      "aaaaaaaaaaaaaaav",
      "aaaaaaaaaaaaaaav",
      "aaaaaaaaaaaaaaav",
      "aaaaaaaaaaaaaaav",
      "aaaaaaaaaaaaaaav",
      "aaaaaaaaaaaaaaav",
      "aaaaaaaaaaaaaaav",
      "vvvvvvvvvvvvvvvv"
    ]
  ]
}