{
  "name": "multi_laboratory_14_base1",
  "refpalette": "deceasedcraft:multi_laboratory_14/multi_laboratory_14_base1_palette",
  "xsize": 16,
  "zsize": 16,
  "slices": [
    [
      "aaaabaaaaaaaacdv",
      "aaaaaaaaaaaaacdv",
      "aaaaaaaaaaaaacdv",
      "aaaaaaaaaaaaacdv",
      "aaaaaaaaaaaaacdv",
      "aaaaaaaaaaaaacdv",
      "aaaaaaaaaaaaacdv",
      "aaaabaaaaaaaacdv",
      "aaaaaeeeeeeeecdv",
      "aaaaaeeeeeeeecdv",
      "aaaaaeeeeeeeecdv",
      "aaaaaeeeeeeeecdv",
      "aaaaaee!eeeeecdv",
      "ccccccccccccccdv",
      "dddddddddddddddv",
      "vvvvvvvvvvvvvvvv"
    ],
    [
      "    b       fcdv",
      "    g   h   fcdv",
      "    g ijjjk lcdv",
      "    m       ncdv",
      "    g ioook lcdv",
      "    g  p q  ncdv",
      "    g      rscdv",
      "t   buuuuuuuucdv",
      "w   uooxxxxoocdv",
      "w   y        cdv",
      "w   uABABCBABcdv",
      "w   u D D D Dcdv",
      "!wwtuEDEDEDEDcdv",
      "ccccccccccccccdv",
      "dddddddddddddddv",
      "vvvvvvvvvvvvvvvv"
    ],
    [
      "    b        cdv",
      "    g        cdv",
      "    g  F I  Jcdv",
      "    K        cdv",
      "    g  L     cdv",
      "    g       Mcdv",
      "    g N     Jcdv",
      "O   buuuuuuuucdv",
      "    uP      Pcdv",
      "    Q        cdv",
      "    uRBRBSBRBcdv",
      "T   u D D D Dcdv",
      "OUVOu D D D Dcdv",
      "ccccccccccccccdv",
      "dddddddddddddddv",
      "vvvvvvvvvvvvvvvv"
    ],
    [
      "    b        cdv",
      "    g        cdv",
      "    g       Wcdv",
      "    g       Wcdv",
      "    g        cdv",
      "    g       Wcdv",
      "    g       Wcdv",
      "P   buuuuuuuucdv",
      "    u XYYYYZ cdv",
      "    u        cdv",
      "    uBBBBBBBBcdv",
      "    u D D D Dcdv",
      "P0 Pu D D D Dcdv",
      "ccccccccccccccdv",
      "dddddddddddddddv",
      "vvvvvvvvvvvvvvvv"
    ],
    [
      "    b        cdv",
      "    g        cdv",
      "    g        cdv",
      "    g       1cdv",
      "    g        cdv",
      "    g       2cdv",
      "    g       !cdv",
      "    buuuuuuuucdv",
      "    u33333333cdv",
      "    u33333333cdv",
      "    u33333333cdv",
      "    u33333333cdv",
      "    u43434343cdv",
      "ccccccccccccccdv",
      "dddddddddddddddv",
      "vvvvvvvvvvvvvvvv"
    ],
    [
      "5555b55555555cdv",
      "5555655555555cdv",
      "5555657555755cdv",
      "5555657555755cdv",
      "5555657555755cdv",
      "5555657555755cdv",
      "5555655555555cdv",
      "5555buuuuuuuucdv",
      "5555u88888888cdv",
      "5555u8 8 8 8ccdv",
      "5555u8 8 8 8ccdv",
      "5555u8 8 8 8ccdv",
      "5555u8 8 8 8ccdv",
      "ccccccccccccccdv",
      "dddddddddddddddv",
      "vvvvvvvvvvvvvvvv"
    ]
  ]
}