{
  "name": "multi_laboratory_14_base6",
  "refpalette": "deceasedcraft:multi_laboratory_14/multi_laboratory_14_base6_palette",
  "xsize": 16,
  "zsize": 16,
  "slices": [
    [
      "aaaabacdddddcaev",
      " aaaaacdddddcaev",
      "aaaaaacdddddcaev",
      "aaaaaacdddddcaev",
      "aaaaaacdddddcaev",
      "aaaaaacdddddcaev",
      "aaaaaacdddddcaev",
      "aaaabacdddddcaev",
      "aaaaaacccccccaev",
      "aaaaaaaaaaaaaaev",
      "aaaaaaaaaaaaaaev",
      "aaaaaaaaaaaaaaev",
      "aaaaaaaaaaaaaaev",
      "eeeeeaaaaaaaaaev",
      "ffffeeeeeeeeeeev",
      "vvvvvvvvvvvvvvvv"
    ],
    [
      "ghijb         dv",
      " k lm         nv",
      "g   m    o    nv",
      "p   m         nv",
      "    m  q   q  nv",
      "    m         nv",
      "   gm         nv",
      "  ggb         dv",
      "    m         nv",
      "    m         nv",
      "    r  s      nv",
      "    t         nv",
      "    m        unv",
      "eeeemwwxxyABx!nv",
      "ffffennnnnnnnnev",
      "vvvvvvvvvvvvvvvv"
    ],
    [
      "    b         dv",
      "    C         nv",
      "    C         nv",
      "    C         nv",
      "    C  qD Eq  nv",
      "    C         nv",
      "    C         nv",
      "  FIb         dv",
      "    m         nv",
      "    m         nv",
      "    J         nv",
      "    K         nv",
      "    m         nv",
      "eeeem         nv",
      "ffffennnnnnnnnev",
      "vvvvvvvvvvvvvvvv"
    ],
    [
      "    b         dv",
      "    C         nv",
      "    C   L L   nv",
      "    C         nv",
      "    C  EqqqD  nv",
      "    C         nv",
      "    C         nv",
      "   Mb         dv",
      "    m         nv",
      "    m         nv",
      "    N         nv",
      "    N         nv",
      "    m         nv",
      "eeeem         nv",
      "ffffennnnnnnnnev",
      "vvvvvvvvvvvvvvvv"
    ],
    [
      "   Ob   PQP   dv",
      "        Q Q   nv",
      "    C  RQ QS  nv",
      "    C   QTQ   nv",
      "    C   PQP   nv",
      "    C   U U   nv",
      "    C   VQV   nv",
      "    b   W W   dv",
      "    m   X     nv",
      "    m         nv",
      "    N         nv",
      "    N         nv",
      "    m         nv",
      "eeeem         nv",
      "ffffennnnnnnnnev",
      "vvvvvvvvvvvvvvvv"
    ],
    [
      "   Yb   QVQ   dv",
      "    C   ZVZ   nv",
      "    l  RZUZS  nv",
      "    C   ZVZ   nv",
      "    C   QPQ   nv",
      "    C    0    nv",
      "    C   QWQ   nv",
      "    b    X    dv",
      "    m         nv",
      "    m         nv",
      "    N         nv",
      "    N         nv",
      "    m         nv",
      "eeeem         nv",
      "ffffennnnnnnnnev",
      "vvvvvvvvvvvvvvvv"
    ]
  ]
}