{
  "name": "multi_laboratory_14_base3",
  "refpalette": "deceasedcraft:multi_laboratory_14/multi_laboratory_14_base3_palette",
  "xsize": 16,
  "zsize": 16,
  "slices": [
    [
      "aaaabaaaaaaaacdv",
      "aaaaaaaaaaaaacdv",
      "aaeaaaaaaaaaacdv",
      "aaaaaaaaaaaaacdv",
      "aaafaaaaaaaaacdv",
      "aghaaaaaaaaaacdv",
      "aagaaaaaaaaaacdv",
      "aaaabaaaaaaaacdv",
      "aafaai!iiiiiicdv",
      "aajgafiiiiiffcdv",
      "aagaaiiiiifficdv",
      "aaaaaiiiiiiiicdv",
      "aaaaaiiii!iiicdv",
      "ccccccccccccccdv",
      "dddddddddddddddv",
      "vvvvvvvvvvvvvvvv"
    ],
    [
      "k   bllllllllcdv",
      "km nlopq rstocdv",
      "  uwlx     yAcdv",
      "B  ClDEFI   Jcdv",
      "    lK LM   Ncdv",
      "    OPmQ RSTUcdv",
      "   VlWWXXYYXZcdv",
      "   0bllllllllcdv",
      "   1l22333322cdv",
      "    f       4cdv",
      "   5lf6768676cdv",
      "    l 9 9 9e9cdv",
      "   #l$9$9$9e9cdv",
      "ccccccccccccccdv",
      "dddddddddddddddv",
      "vvvvvvvvvvvvvvvv"
    ],
    [
      "    bllllllllcdv",
      "    l%      %cdv",
      "    l        cdv",
      "    l        cdv",
      "    l^       cdv",
      "    &^ *     cdv",
      "    lWWX(XXXZcdv",
      "    bllllllllcdv",
      "   fl%      %cdv",
      "             cdv",
      "    l 6)6+6)6cdv",
      "    l 9 9 9-9cdv",
      "    l 9 9 9e9cdv",
      "ccccccccccccccdv",
      "dddddddddddddddv",
      "vvvvvvvvvvvvvvvv"
    ],
    [
      "    bllllllllcdv",
      "    l[      [cdv",
      "    l        cdv",
      "    l^       cdv",
      "    l        cdv",
      "    ]        cdv",
      "    l {  S} Zcdv",
      " |  bllllllllcdv",
      "   fl ;::::' cdv",
      "    l        cdv",
      "    l66666666cdv",
      "    l 9 9 9<9cdv",
      "    l 9 9-9efcdv",
      "ccccccccccccccdv",
      "dddddddddddddddv",
      "vvvvvvvvvvvvvvvv"
    ],
    [
      "    bllllllllcdv",
      "    l        cdv",
      "    l        cdv",
      "  > l        cdv",
      "    l        cdv",
      "    l        cdv",
      "    l       Zcdv",
      " < fbllllllllcdv",
      "    l,,,,,,,,cdv",
      "    l,,,,,,,,cdv",
      "    l,,,,,,,,cdv",
      "    l,,,,,,e-cdv",
      "    l.,.,f,eecdv",
      "ccccccccccccccdv",
      "dddddddddddddddv",
      "vvvvvvvvvvvvvvvv"
    ],
    [
      "?/??bllllllllcdv",
      "?`??]\u0370\u0370\u0370\u0370\u0370\u0370\u0370\u0370cdv",
      "?`??]\u0370\u0371\u0370\u0370\u0370\u0370\u0372\u0370cdv",
      "\u0373/f?]\u0370\u0370\u0370\u0370\u0370\u0370\u0370\u0370cdv",
      "??f?]\u0370\u0370\u0370\u0370\u0370\u0370\u0370\u0370cdv",
      "?f??]\u0370`\u0370\u0370\u0370\u0370\u0371\u0370cdv",
      "??ff]\u0370\u0370\u0370\u0370\u0370\u0370\u0370\u0370cdv",
      "lffebllllllllcdv",
      "\u0374\u0374\u0374\u0374l\u0375\u0375\u0375eeff\u0375cdv",
      "\u0374\u0374/\u0374l\u0375 \u0375 e f cdv",
      "\u0374\u0374/\u0374l\u0375 \u0375 f f cdv",
      "\u0374\u0374/\u0374l\u0375 \u0375 f efcdv",
      "\u0374\u0374\u0374\u0374l\u0375 \u0375 f e\u0376cdv",
      "ccccccccccccccdv",
      "dddddddddddddddv",
      "vvvvvvvvvvvvvvvv"
    ]
  ]
}