{
  "name": "multi_convenientstore_3_top",
  "refpalette": "deceasedcraft:multi_convenientstore_3/multi_convenientstore_3_top_palette",
  "xsize": 16,
  "zsize": 16,
  "slices": [
    [
      "      abbbc     ",
      "      abbbc     ",
      "      abbbc     ",
      "      abbbc     ",
      "ddddddbbbbc     ",
      "beeeeeebbbc     ",
      "b     fbbbc     ",
      "bbbbbbbbbbc     ",
      "bbbbbbbbbbc     ",
      "bbbb!bbbbgc     ",
      "ccccccccccc     ",
      "                ",
      "                ",
      "                ",
      "                ",
      "                "
    ],
    [
      "      h  ic     ",
      "     hh jkc     ",
      "      l  mc     ",
      "      h noc     ",
      "hhhhhhh  pc     ",
      "eqqqqqq  ic     ",
      "errrrrr  kc     ",
      "  s t    mc     ",
      " t    su oc     ",
      "wwwxyAwwxBc     ",
      "ccccccccccc     ",
      "                ",
      "                ",
      "                ",
      "                ",
      "                "
    ],
    [
      "          C     ",
      "          C     ",
      "          C     ",
      "          c     ",
      "          c     ",
      "DEEEEEE   C     ",
      "D        FC     ",
      "          C     ",
      "          c     ",
      "IJK  Lt MNc     ",
      "ccCCccCCccc     ",
      "                ",
      "                ",
      "                ",
      "                ",
      "                "
    ],
    [
      "          b     ",
      "          b     ",
      "          b     ",
      "          c     ",
      "          c     ",
      "DOOOOOO   b     ",
      "D         b     ",
      "          b     ",
      "          c     ",
      "          c     ",
      "ccbbccbbccc     ",
      "                ",
      "                ",
      "                ",
      "                ",
      "                "
    ],
    [
      "PPPPPPPPPPc     ",
      "PPPPPPPPPPc     ",
      "PPPPPPPPPPc     ",
      "PPPPPPPPPPc     ",
      "PPPPPPPPPPc     ",
      "PPPPPPPPPPc     ",
      "PPPPPPPPPPc     ",
      "PPPPPPPPPPc     ",
      "PPPPPPPPPPc     ",
      "PPPPPPPPPPc     ",
      "ccccccccccc     ",
      "                ",
      "                ",
      "                ",
      "                ",
      "                "
    ],
    [
      "          Q     ",
      "          Q     ",
      "          Q     ",
      "          Q     ",
      "          Q     ",
      "          Q     ",
      "          Q     ",
      "          Q     ",
      "          Q     ",
      "          Q     ",
      "QQQQQQQQQQQ     ",
      "                ",
      "                ",
      "                ",
      "                ",
      "                "
    ]
  ]
}