{
  "name": "multi_convenientstore_3_floor1",
  "refpalette": "deceasedcraft:multi_convenientstore_3/multi_convenientstore_3_floor1_palette",
  "xsize": 16,
  "zsize": 16,
  "slices": [
    [
      "aaaaaaaaabac    ",
      "      de   c    ",
      "       e   c    ",
      "       efffc    ",
      "       efffc    ",
      "ggggggghfffc    ",
      "fffffffffffc    ",
      "fffffffffffc    ",
      "ff    iffffc    ",
      "fffffffffffc    ",
      "fffffffffffc    ",
      "fffffffffffc    ",
      "cccccccccccc    ",
      "      j         ",
      "                ",
      "                "
    ],
    [
      "aaaaaaaaabac    ",
      "       k   c    ",
      "       k   c    ",
      "       kkkkc    ",
      "       k  lc    ",
      "kkkkkkkk m c    ",
      "nm lnm l o c    ",
      "           c    ",
      " k       p c    ",
      " kkkkkk  m c    ",
      "           c    ",
      "qrstqr   orc    ",
      "cccccccccccc    ",
      "      u         ",
      "                ",
      "                "
    ],
    [
      "aaaaaaaaaaac    ",
      "           c    ",
      "           c    ",
      "           b    ",
      "           b    ",
      "           b    ",
      "           c    ",
      "           b    ",
      "           b    ",
      "           b    ",
      "           c    ",
      "wxyw x    xc    ",
      "bccbbccbbccc    ",
      "                ",
      "                ",
      "                "
    ],
    [
      "aaaaaaaaaaac    ",
      "           c    ",
      "           c    ",
      "           c    ",
      "           c    ",
      "           c    ",
      "           c    ",
      "           c    ",
      "           c    ",
      "           c    ",
      "           c    ",
      "           c    ",
      "cccccccccccc    ",
      "      j         ",
      "                ",
      "                "
    ],
    [
      "AAAAAAAAAAAc    ",
      "AAAAAAAAAAAc    ",
      "AAAAAAAAAAAc    ",
      "AAAAAAAAAAAc    ",
      "AAAAAAAAAAAc    ",
      "AAAAAAAAAAAc    ",
      "AAAAAAAAAAAc    ",
      "AAAAAAAAAAAc    ",
      "AAAAAAAAAAAc    ",
      "AAAAAAAAAAAc    ",
      "AAAAAAAAAAAc    ",
      "AAAAAAAAAAAc    ",
      "cccccccccccc    ",
      "                ",
      "                ",
      "                "
    ],
    [
      "                ",
      "                ",
      "                ",
      "                ",
      "                ",
      "                ",
      "                ",
      "                ",
      "                ",
      "                ",
      "                ",
      "                ",
      "                ",
      "                ",
      "                ",
      "                "
    ]
  ]
}