{
  "name": "multi_convenientstore_3_ground",
  "refpalette": "deceasedcraft:multi_convenientstore_3/multi_convenientstore_3_ground_palette",
  "xsize": 16,
  "zsize": 16,
  "slices": [
    [
      "aaaaaaaaaaabHHba",
      "aaaaaaaaaaabHHba",
      "aaaaaaaaaaabHHba",
      "aaaaaaaaaaabHHba",
      "aaaaaaaaaaabHHba",
      "aaaaaaaaaaabHHba",
      "aaaaaaaaaaabHHba",
      "aaaaaaaaaaabHHba",
      "aaaaaaaaaaabHHba",
      "aaaaaaaaaaabHHba",
      "aaaaaaaaaaabHHba",
      "bbbbbbbbbbbHHHba",
      "HHHHHHHHHHHHHHba",
      "HHHHHHHHHHHHHHba",
      "bbbbbbbbbbbbbbba",
      "aaaaaaaaaaaaaaaa"
    ],
    [
      "ccccccccccadeedf",
      "ccccccccccadeedf",
      "ccccccccccabHHbf",
      "ccccccccccabHHbf",
      "ccccccccccabHHbf",
      "ccccccccccabHHbf",
      "ccccccccccabHHbf",
      "ccccccccccabHHbf",
      "ccccccccccabHHbf",
      "ccccccc!ccabHHbf",
      "aaaaaaaaaaabHHbf",
      "bbbbbbbbbbbHHHbf",
      "HHHHHHHHHHHHHHbf",
      "HHHHHHHHHHHHHbbf",
      "bbbbbbbbbbbbbbbf",
      "ffffffffffffffff"
    ],
    [
      "      g  hi     ",
      " jk  lg mni    o",
      " pppppg  qi    o",
      " krstug  wi    o",
      "xyAABCD   i  E o",
      "xFFFFIF J K    o",
      "x L FMFN OK    o",
      "    PQRST K    o",
      "UVWXYZR012i    o",
      "XX!XY3R4TSi    o",
      "iiiiiiiiiii    o",
      " 4             o",
      "               o",
      "               o",
      "               o",
      "oooooooooooooooo"
    ],
    [
      "      g  56     ",
      "      g  76     ",
      "  89# g  $6     ",
      "     %g  ^i     ",
      "x&*&* (   i     ",
      "xFFFF)F   K     ",
      "x  LF+F   K     ",
      "    - R[J K     ",
      "    Y R]  i     ",
      "W{}WY R |]i     ",
      "iiiiiiiiiii     ",
      "                ",
      "                ",
      "                ",
      "                ",
      "                "
    ],
    [
      "      g  ;6     ",
      "      g  :6     ",
      "      g  '6     ",
      "      g   i     ",
      "x*&<> g   i     ",
      "xFFFF,F   K     ",
      "x   .?F   K     ",
      "    Y/R   K     ",
      "    Y R   i     ",
      "    Y R4  i     ",
      "iiiiiiiiiii     ",
      "                ",
      "                ",
      "                ",
      "                ",
      "                "
    ],
    [
      "      g   c     ",
      "      g   c     ",
      "      g   c     ",
      "      g   i     ",
      "`\u0370\u0370\u0370\u0370\u0370g   i     ",
      "`FFFFFF  \u0371c     ",
      "`    .F  \u0371c     ",
      "    FFF  \u0371c     ",
      "    FFF4 4i     ",
      "\u0372\u0373\u0373\u0372\u0373\u0372\u0373\u0373\u0372\u0373i     ",
      "\u0373ii\u0373i\u0374ii\u0374ii     ",
      "\u0373\u0373\u0373\u0373 \u0375  \u0376       ",
      "                ",
      "                ",
      "                ",
      "                "
    ]
  ]
}