{
  "xsize": 16,
  "zsize": 16,
  "refpalette": "lce2:factory",
  "slices": [
    [
      "          &     ",
      " OVVVVVVVVO&    ",
      " V        V     ",
      " V        V     ",
      " V        V     ",
      " V        V     ",
      " V        V     ",
      " V        V     ",
      " V        V     ",
      " V        V     ",
      " V        V     ",
      " O       &O&    ",
      " V       &V&    ",
      " V        V     ",
      " V        V     ",
      " V        V     "
    ],
    [
      "          &     ",
      " OVVVVVVVVO&    ",
      " V        V     ",
      " V        V     ",
      "&V&       V     ",
      " V        V     ",
      " V        V     ",
      " V        V     ",
      " V        V     ",
      " V        V     ",
      " V        V     ",
      " O        O     ",
      " V       &V&    ",
      " V        V     ",
      " V        V     ",
      " V        V     "
    ],
    [
      "          &     ",
      " OVVVVVVVVO&    ",
      " V       &V&    ",
      " V        V     ",
      "&V&       V     ",
      " V        V     ",
      " V        V     ",
      " V        V     ",
      " V        V     ",
      " V        V     ",
      " V        V     ",
      " O        O     ",
      " V       &V&    ",
      " V        V     ",
      " V        V     ",
      " V        V     "
    ],
    [
      "                ",
      " OVVVVVVVVO     ",
      " V       &V&    ",
      " V        V     ",
      "&V&       V     ",
      " V        V     ",
      " V        V     ",
      " V        V     ",
      " V        V     ",
      " V        V     ",
      " V        V     ",
      " O        O     ",
      " V       &V&    ",
      " V        V     ",
      " V        V     ",
      " V        V     "
    ],
    [
      "                ",
      " OOOOOOOOOO     ",
      " OVVVVVVVVO&    ",
      " OVVVVVVVVO     ",
      "&OVVVVVVVVO     ",
      "&OVVVVVVVVO     ",
      "&OVVVVVVVVO     ",
      " OVVVVVVVVO     ",
      " OVVVVVVVVO     ",
      " OVVVVVVVVO     ",
      " OVVVVVVVVO     ",
      " OOOOOOOOOO     ",
      " OVVVVVVVVO&    ",
      " OVVVVVVVVO&    ",
      " OVVVVVVVVO     ",
      " OVVVVVVVVO     "
    ],
    [
      "                ",
      " !        !     ",
      "         &&&    ",
      "          &     ",
      " &              ",
      "&!&       !     ",
      "&&&             ",
      " &              ",
      "                ",
      " !        !     ",
      "                ",
      "                ",
      "          &     ",
      " !       &!&    ",
      "          &     ",
      "                "
    ]
  ]
}