{
  "xsize": 16,
  "zsize": 16,
  "refpalette": "lce2:factory",
  "slices": [
    [
      "vvvvvvvvvvvvvvvv",
      "vvvvvvvvvvvvvvvv",
      "vvvvvvvvvvvvvvvv",
      "vvvvvvvvvvvvvvvv",
      "vvvvvvvvvvvvvvvv",
      "vvvvvvvvvvvvvvvv",
      "vvvvvvvvvvvvvvvv",
      "vvvvvvvvvvvvvvvv",
      "vvvvvvvvvvvvvvvv",
      "vvvvvvvvvvvvvvvv",
      "vvvvvvvvvvvvvvvv",
      "vvvvvvvvvvvvvvvv",
      "vvvvvvvvvvvvvvvv",
      "vvvvvvvvvvvvvvvv",
      "vvvvvvvvvvvvvvvv",
      "vvvvvvvvvvvvvvvv"
    ],
    [
      "                ",
      "                ",
      "                ",
      "          &     ",
      "       !  !     ",
      "                ",
      "    &!      !   ",
      "                ",
      "                ",
      "     !      !&  ",
      "            &   ",
      "       !  !     ",
      "      &         ",
      "                ",
      "                ",
      "                "
    ],
    [
      "                ",
      "                ",
      "                ",
      "          &     ",
      "       !  !     ",
      "                ",
      "    &!      !   ",
      "                ",
      "                ",
      "     !      !&  ",
      "                ",
      "       !  !     ",
      "      &         ",
      "                ",
      "                ",
      "                "
    ],
    [
      "                ",
      "                ",
      "         &      ",
      "       !!!!     ",
      "      !!!!!!    ",
      "    &!!!!!!!!   ",
      "    !!!!!!!!!   ",
      "    !!!!!!!!!   ",
      "    !!!!!!!!!&  ",
      "    !!!!!!!!!   ",
      "     !!!!!!!!   ",
      "      !! !!!    ",
      "      &  !!     ",
      "                ",
      "                ",
      "                "
    ],
    [
      "                ",
      "                ",
      "                ",
      "        &&      ",
      "       !!!!     ",
      "     &!    !    ",
      "     !      !   ",
      "     !      !&  ",
      "     !   &  !   ",
      "     !   &  !   ",
      "        && !    ",
      "      &!!!!     ",
      "                ",
      "                ",
      "                ",
      "                "
    ],
    [
      "                ",
      "                ",
      "                ",
      "        &       ",
      "       !!!!     ",
      "      !    !    ",
      "     !      !   ",
      "     !      !&  ",
      "     !      !   ",
      "     !      !   ",
      "      ! &  !    ",
      "      &!!!!     ",
      "                ",
      "                ",
      "                ",
      "                "
    ]
  ]
}