{
  "xsize": 16,
  "zsize": 16,
  "refpalette": "lce2:factory",
  "slices": [
    [
      "vvvvvvvvvvvvvvvv",
      "vvvvvvvvvvvvvvvv",
      "vvvvvvvvvvvvvvvv",
      "vvvvvvvvvvvvvvvv",
      "vvvvvvvvvvvvvvvv",
      "vvvvvvvvvvvvvvvv",
      "vvvvvvvvvvvvvvvv",
      "vvvvvvvvvvvvvvvv",
      "vvvvvvvvvvvvvvvv",
      "vvvvvvvvvvvvvvvv",
      "vvvvvvvvvvvvvvvv",
      "vvvvvvvvvvvvvvvv",
      "vvvvvvvvvvvvvvvv",
      "vvvvvvvvvvvvvvvv",
      "vvvvvvvvvvvvvvvv",
      "vvvvvvvvvvvvvvvv"
    ],
    [
      "          &     ",
      "                ",
      " !        !     ",
      "                ",
      "                ",
      "                ",
      " !        !     ",
      "                ",
      "                ",
      "               &",
      " !        ! &&&&",
      " &       &&&&   ",
      "&&&       &     ",
      "&&&             ",
      " !        !     ",
      "                "
    ],
    [
      "          &     ",
      "                ",
      " !!!!!!!!!!     ",
      "                ",
      "                ",
      "                ",
      " !!!!!!!!!!     ",
      "                ",
      "                ",
      "          &     ",
      " !!!!!!!!!!&    ",
      "&&&      &&&    ",
      "&&&       &     ",
      " &              ",
      " !!!!!!!!!!     ",
      "                "
    ],
    [
      " OVVVVVVVVO     ",
      " OVVVVVVVVO     ",
      " OVVVVVVVVO     ",
      " OVVVVVVVVO     ",
      " OVVVVVVVVO     ",
      " OVVVVVVVVO     ",
      " OVVVVVVVVO     ",
      " OVVVVVVVVO     ",
      " OVVVVVVVVO     ",
      " OVVVVVVVVO     ",
      " OVVVVVVVVO&    ",
      "&OVVVVVVVVO     ",
      " OVVVVVVVVO     ",
      " OVVVVVVVVO     ",
      " OOOOOOOOOO     ",
      "                "
    ],
    [
      " V        V     ",
      " V        V     ",
      " V        V     ",
      " V        V     ",
      " O        O     ",
      " V        V     ",
      " V        V     ",
      " V        V     ",
      " V        V     ",
      " V        V     ",
      "&V&      &V&    ",
      "&V&       V     ",
      " V        V     ",
      " V        V     ",
      " OVVVVVVVVO     ",
      "                "
    ],
    [
      " V        V     ",
      " V        V     ",
      " V        V     ",
      " V        V     ",
      " O        O     ",
      " V        V     ",
      " V        V     ",
      " V        V     ",
      " V        V     ",
      "&V&       V     ",
      "&V&      &V&    ",
      " V        V     ",
      " V        V     ",
      " V        V     ",
      " OVVVVVVVVO     ",
      "                "
    ]
  ]
}