{
  "name": "multi_courtyardofficetower_3_ground",
  "refpalette": "deceasedcraft:multi_courtyardofficetower_3/multi_courtyardofficetower_3_ground_palette",
  "xsize": 16,
  "zsize": 16,
  "slices": [
    [
      "aaaaaaaaaabccbaa",
      "aaaaaaaaabccbaaa",
      "aaaaaaaabccbaaaa",
      "aaaaaaabccbaaaaa",
      "aaaaaabccbaaaaaa",
      "aaaaabccbaaaaaaa",
      "aaaabccbaaaaaaaa",
      "aaabccbaaaaaaaaa",
      "aabccbaaaaaaaaaa",
      "abccbaaaaaaaaaaa",
      "bccbaaaaaaaaaaaa",
      "ccbaaaaaaaaaaaaa",
      "cbaaaaaaaaaaaaaa",
      "baaaaaaaaaaaaaaa",
      "aaaaaaaaaaaaaaaa",
      "aaaaaaaaaaaaaaaa"
    ],
    [
      " d    dd        ",
      "     e          ",
      " ed             ",
      "               d",
      "  ed          de",
      "d        f  d   ",
      "                ",
      "          dddddd",
      " f      ddd     ",
      "      ddd       ",
      "     dd     e  e",
      "    dd    d d d ",
      "   dd         d ",
      "  dd  e   e  e  ",
      " dd     e d   d ",
      "dd  d           "
    ],
    [
      "                ",
      "     g          ",
      " g              ",
      "                ",
      "  g            g",
      "                ",
      "                ",
      "                ",
      "                ",
      "                ",
      "            g  g",
      "                ",
      "                ",
      "      g   g  g  ",
      "        g       ",
      "                "
    ],
    [
      "                ",
      "     d          ",
      " d              ",
      "                ",
      "  d            d",
      "                ",
      "                ",
      "                ",
      "                ",
      "                ",
      "            d  d",
      "                ",
      "                ",
      "      d   d  d  ",
      "        d       ",
      "                "
    ],
    [
      "                ",
      "     d          ",
      " d              ",
      "                ",
      "  d            h",
      "                ",
      "                ",
      "                ",
      "                ",
      "                ",
      "            d  d",
      "                ",
      "                ",
      "      d   d  d  ",
      "        d       ",
      "                "
    ],
    [
      "                ",
      "     d          ",
      " d              ",
      "                ",
      "  d             ",
      "                ",
      "                ",
      "                ",
      "                ",
      "                ",
      "            d  d",
      "                ",
      "                ",
      "      d   d  d  ",
      "        d       ",
      "                "
    ]
  ]
}