{
  "name": "multi_alienresearch_4_base7",
  "refpalette": "deceasedcraft:multi_alienresearch_4/multi_alienresearch_4_base7_palette",
  "xsize": 16,
  "zsize": 16,
  "slices": [
    [
      "vvvvvvvvvvvvvvvv",
      "aaaaaaaaaaaaaaaa",
      "aaaaaaaaaaaaaaaa",
      "aaaaaaaaaaaaaaaa",
      "aaaaaabbbcdcbbba",
      "aabbbbeeeeeeeeeb",
      "bbeeee    f    e",
      "ee              ",
      "                ",
      "                ",
      "                ",
      "                ",
      "                ",
      "                ",
      "                ",
      "                "
    ],
    [
      "vvvvvvvvvvvvvvvv",
      "aaaaaaaaaaaaaaaa",
      "aaaaaaaaaaaaaaaa",
      "aaaaaaaaaaaaaaaa",
      "aaaabbbbbcccbbbb",
      "abbb      e     ",
      "b         g     ",
      "          e     ",
      "          f     ",
      "                ",
      "                ",
      "                ",
      "                ",
      "                ",
      "                ",
      "                "
    ],
    [
      "vvvvvvvvvvvvvvvv",
      "aaaaaaaaaaaaaaaa",
      "aaaaaaaaaaaaaaaa",
      "aaaaaabbbcccbbba",
      "aabbbb    e    b",
      "bb              ",
      "                ",
      "                ",
      "          g     ",
      "          e     ",
      "          f     ",
      "                ",
      "                ",
      "                ",
      "                ",
      "                "
    ],
    [
      "vvvvvvvvvvvvvvvv",
      "aaaaaaaaaaaaaaaa",
      "aaaaaaaaaaaaaaaa",
      "aaaabbbbbcccbbbb",
      "abbb      e     ",
      "b               ",
      "                ",
      "                ",
      "                ",
      "                ",
      "          g     ",
      "          e     ",
      "          f     ",
      "                ",
      "                ",
      "                "
    ],
    [
      "vvvvvvvvvvvvvvvv",
      "aaaaaaaaaaaaaaaa",
      "aaaaaaabbcccbbaa",
      "aaabbbb   e   bb",
      "bbb             ",
      "                ",
      "                ",
      "                ",
      "                ",
      "                ",
      "                ",
      "                ",
      "          g     ",
      "          e     ",
      "          f     ",
      "                "
    ],
    [
      "vvvvvvvvvvvvvvvv",
      "aaaaaaaaaaaaaaaa",
      "aaaaaabbcccccbba",
      "aabbbb    e    b",
      "bb              ",
      "                ",
      "                ",
      "                ",
      "                ",
      "                ",
      "                ",
      "                ",
      "                ",
      "                ",
      "          g     ",
      "          e     "
    ]
  ]
}