{
  "name": "multi_alienresearch_4_ground",
  "refpalette": "deceasedcraft:multi_alienresearch_4/multi_alienresearch_4_ground_palette",
  "xsize": 16,
  "zsize": 16,
  "slices": [
    [
      "zzazzzzzzzzzzzaz",
      "azzzzazazzzzazaz",
      "zzazazzzazaazaza",
      "zazzzaazzazzazaz",
      "zazzazzazzzzzzaa",
      "azazzazazazazzza",
      "zzzzzaazazabzzaa",
      "zzaabazaabzaaazz",
      "zzzazzaazabzbaba",
      "bzazaazazzaazaaa",
      "bbabzbabzbzbabab",
      "zbbbbzbzbbaazaba",
      "azbbbbbbbbbbbbbb",
      "bbbbabbbbbabbbbb",
      "zbbzbbzbbbbzbabb",
      "bbbbbbbzbbvbbbbz"
    ],
    [
      "                ",
      "   c      c     ",
      "     cc       c ",
      "dddddddddddddddd",
      "  c  c      c   ",
      " c  c   c     c ",
      "                ",
      " c              ",
      "  c     c       ",
      "                ",
      "                ",
      "     c          ",
      "                ",
      "                ",
      "                ",
      "                "
    ],
    [
      "                ",
      "                ",
      "                ",
      "dddddddddddddddd",
      "                ",
      "                ",
      "                ",
      "                ",
      "                ",
      "                ",
      "                ",
      "                ",
      "                ",
      "                ",
      "                ",
      "                "
    ],
    [
      "                ",
      "                ",
      "                ",
      "dddddddddddddddd",
      "                ",
      "                ",
      "                ",
      "                ",
      "                ",
      "                ",
      "                ",
      "                ",
      "                ",
      "                ",
      "                ",
      "                "
    ],
    [
      "                ",
      "                ",
      "                ",
      "eeeeeeeeeeeeeeee",
      "                ",
      "                ",
      "                ",
      "                ",
      "                ",
      "                ",
      "                ",
      "                ",
      "                ",
      "                ",
      "                ",
      "                "
    ],
    [
      "                ",
      "                ",
      "                ",
      "                ",
      "                ",
      "                ",
      "                ",
      "                ",
      "                ",
      "                ",
      "                ",
      "                ",
      "                ",
      "                ",
      "                ",
      "                "
    ]
  ]
}