{
  "name": "multi_alienresearch_4_base5",
  "refpalette": "deceasedcraft:multi_alienresearch_4/multi_alienresearch_4_base5_palette",
  "xsize": 16,
  "zsize": 16,
  "slices": [
    [
      "vvvvvvvvvvvvvvvv",
      "aaaaabbbbbbbbbbb",
      "aabbc d ed dd d ",
      "bbfff           ",
      "ff              ",
      "                ",
      "                ",
      "                ",
      "                ",
      "      ggghhhggg ",
      "   ggghhhhhhhhhg",
      " gghhhhijjijjihh",
      "ghhhijjkkkkkkkjj",
      "hhjjkkk   k   kk",
      "hikk      k     ",
      "jk  k     k     "
    ],
    [
      "vvvvvvvvvvvvvvvv",
      "aaaaabbbbbbbbbbb",
      "aabbb lm   nm d ",
      "bb  f           ",
      "                ",
      "                ",
      "                ",
      "                ",
      "                ",
      "                ",
      "          o     ",
      "       ppppppp  ",
      "    ppp   pqqqpp",
      "  pp      pqqqqq",
      " p     rrrstttqq",
      "p    rr  uwttttt"
    ],
    [
      "vvvvvvvvvvvvvvvv",
      "aaaaabbbbbbbbbbb",
      "aaxbb           ",
      "xx  f           ",
      "                ",
      "                ",
      "                ",
      "                ",
      "                ",
      "                ",
      "                ",
      "                ",
      "                ",
      "                ",
      "           y    ",
      "          A     "
    ],
    [
      "vvvvvvvvvvvvvvvv",
      "aaaaaabbbbbbbbba",
      "aaxxbb         b",
      "xx   f         f",
      "                ",
      "                ",
      "                ",
      "                ",
      "                ",
      "                ",
      "                ",
      "                ",
      "                ",
      "                ",
      "          BCDE  ",
      "                "
    ],
    [
      "vvvvvvvvvvvvvvvv",
      "aaaaaaabbbbbbbaa",
      "aaaxbbb       bb",
      "xxx  ff       ff",
      "                ",
      "                ",
      "                ",
      "                ",
      "                ",
      "                ",
      "                ",
      "                ",
      "                ",
      "                ",
      "       FFF I    ",
      "     FF         "
    ],
    [
      "vvvvvvvvvvvvvvvv",
      "aaaaaaaabbbbbaaa",
      "aaaaxbbb     bbb",
      "axxx  ff     ff ",
      "x               ",
      "                ",
      "                ",
      "                ",
      "                ",
      "                ",
      "                ",
      "                ",
      "       qqq      ",
      "    qqqqqq      ",
      "  qqqqqhhh J    ",
      " qqqqhhttt      "
    ]
  ]
}