{
  "name": "multi_alienresearch_4_base6",
  "refpalette": "deceasedcraft:multi_alienresearch_4/multi_alienresearch_4_base6_palette",
  "xsize": 16,
  "zsize": 16,
  "slices": [
    [
      "vvvvvvvvvvvvvvvv",
      "aaaaaaaaaaaaaaaa",
      "aaaabbccccdccccb",
      "abbb    eeeee   ",
      "b               ",
      "                ",
      "                ",
      "                ",
      "                ",
      "                ",
      "                ",
      "                ",
      "                ",
      "                ",
      "                ",
      "                "
    ],
    [
      "vvvvvvvvvvvvvvvv",
      "aaaaaaaacccccaaa",
      "aaaabccc     ccc",
      "abbb  ee     ee ",
      "b               ",
      "                ",
      "                ",
      "                ",
      "                ",
      "                ",
      "                ",
      "                ",
      "                ",
      "                ",
      "                ",
      "                "
    ],
    [
      "vvvvvvvvvvvvvvvv",
      "aaaaaaacccccccaa",
      "aaabccc       cc",
      "bbb  ee       ee",
      "                ",
      "                ",
      "                ",
      "                ",
      "                ",
      "                ",
      "                ",
      "                ",
      "                ",
      "                ",
      "                ",
      "                "
    ],
    [
      "vvvvvvvvvvvvvvvv",
      "aaaaaaccccccccca",
      "aabbcc         c",
      "bb   e         e",
      "                ",
      "                ",
      "                ",
      "                ",
      "                ",
      "                ",
      "                ",
      "                ",
      "                ",
      "                ",
      "       ffg gff  ",
      "     gf hi ih fg"
    ],
    [
      "vvvvvvvvvvvvvvvv",
      "aaaaaccccccccccc",
      "aabcc           ",
      "bb  e           ",
      "                ",
      "                ",
      "                ",
      "                ",
      "                ",
      "                ",
      "                ",
      "                ",
      "       ffgjgff  ",
      "    fffhhi ihhff",
      "  gjihhkki ikkhh",
      " ffi ikl i i lki"
    ],
    [
      "vvvvvvvvvvvvvvvv",
      "aaaaaccccccccccc",
      "aaccc mn   no p ",
      "cc  e           ",
      "                ",
      "                ",
      "                ",
      "                ",
      "                ",
      "                ",
      "      qqqqqqqqq ",
      "    qqfhhrsrhhfq",
      "  qqhhhkk@t@kkhh",
      "qqsrkkk  @t@  kk",
      "fhkt@    @t@    ",
      "hkk@t@   @t@   @"
    ]
  ]
}