{
  "name": "multi_alienresearch_4_base3",
  "refpalette": "deceasedcraft:multi_alienresearch_4/multi_alienresearch_4_base3_palette",
  "xsize": 16,
  "zsize": 16,
  "slices": [
    [
      "vvvvvvvvvvvvvvvv",
      "aaaaabbbbbbbbbbb",
      "aaaaabcccccccccc",
      "aaaaabcccccccccc",
      "aaaaabddddeddddb",
      "aaffffgggggggggf",
      "ffgggghhhhhhhhhg",
      "gghhhhhhhhhhhhhh",
      "hhhhhhhhhhhhhhhh",
      "hhhhhhhhhhhhhhhh",
      "hhhhhhdddddddddh",
      "hhhhdddiiidiiidd",
      "hhddiii   j   ii",
      "ddii      j     ",
      "di     klllllm  ",
      "i    km       km"
    ],
    [
      "vvvvvvvvvvvvvvvv",
      "aaaaabbbbbnbbbbb",
      "aaaaab    o     ",
      "aaaaab          ",
      "aaaaabp   q   pb",
      "aaaafffd ddd dff",
      "afff o  r g s  o",
      "f               ",
      "tt              ",
      "t        uwx    ",
      "      yAAAAAAAy ",
      "   BAA         A",
      "  AA            ",
      "AA              ",
      "           C    ",
      "                "
    ],
    [
      "vvvvvvvvvvvvvvvv",
      "aaaaabbbbbnbbbbb",
      "aaaaab          ",
      "aaaaab          ",
      "aaaaab         b",
      "aaaaabDd ddd dDb",
      "aaaffff E g F ff",
      "aff             ",
      "f               ",
      "t         I     ",
      "      yAAAAAAAy ",
      "    AA         A",
      "  AA            ",
      "AA              ",
      "                ",
      "                "
    ],
    [
      "vvvvvvvvvvvvvvvv",
      "aaaaabbbbbnbbbbb",
      "aaaaab          ",
      "aaaaab          ",
      "aaaaab         b",
      "aaaaabJdidddidJb",
      "aaaaaffdddddddff",
      "aaaff     g     ",
      "fff             ",
      "                ",
      "      yAAAAAAAy ",
      "    AA         A",
      "  AA            ",
      "AA              ",
      "                ",
      "                "
    ],
    [
      "vvvvvvvvvvvvvvvv",
      "aaaaabbbbbnbbbbb",
      "aaaaab          ",
      "aaaaab          ",
      "aaaaab         b",
      "aaaaab KKKKKKK b",
      "aaaaabbbbbbbbbbb",
      "aaaaaffffdddffff",
      "aafff     g     ",
      "ff              ",
      "      yAAAAAAAy ",
      "    AA         A",
      "  AA            ",
      "AA              ",
      "                ",
      "                "
    ],
    [
      "vvvvvvvvvvvvvvvv",
      "aaaaabbbbbnbbbbb",
      "aaaaab          ",
      "aaaaab          ",
      "aaaaab         b",
      "aaaaab    L    b",
      "aaaaabbbbbbbbbbb",
      "aaaaaaaaaaaaaaaa",
      "aaaafffffdddffff",
      "aaff      g     ",
      "ff    AMMMMMMMA ",
      "    MM         M",
      "  MM            ",
      "MM              ",
      "                ",
      "                "
    ]
  ]
}