{
  "name": "multi_oasiscondo_0_floor9",
  "refpalette": "deceasedcraft:multi_oasiscondo_0/multi_oasiscondo_0_floor9_palette",
  "xsize": 16,
  "zsize": 16,
  "slices": [
    [
      "                ",
      "                ",
      "                ",
      "                ",
      "                ",
      "                ",
      "                ",
      "                ",
      "                ",
      "           aabbb",
      "          cdddde",
      "         fddddde",
      "         fddddde",
      "         bddddde",
      "         bddddde",
      "         bddddde"
    ],
    [
      "                ",
      "                ",
      "                ",
      "                ",
      "                ",
      "                ",
      "                ",
      "            ghhh",
      "          ghhiii",
      "         ggiiiii",
      "        ggc     ",
      "        ji   k  ",
      "       gji l mk ",
      "       jii   k  ",
      "       jii      ",
      "       jii  n   "
    ],
    [
      "                ",
      "                ",
      "                ",
      "                ",
      "                ",
      "                ",
      "                ",
      "            oooo",
      "          ooo   ",
      "         oo     ",
      "        ooc     ",
      "        o       ",
      "       oo       ",
      "       o        ",
      "       o        ",
      "       o        "
    ],
    [
      "                ",
      "                ",
      "                ",
      "                ",
      "                ",
      "                ",
      "                ",
      "                ",
      "                ",
      "                ",
      "          c     ",
      "                ",
      "                ",
      "                ",
      "                ",
      "                "
    ],
    [
      "                ",
      "                ",
      "                ",
      "                ",
      "                ",
      "                ",
      "                ",
      "                ",
      "            pppp",
      "           pq   ",
      "          c     ",
      "         r      ",
      "        rs      ",
      "        r       ",
      "        r       ",
      "        r       "
    ],
    [
      "                ",
      "                ",
      "                ",
      "                ",
      "                ",
      "                ",
      "                ",
      "            gggg",
      "          gggggg",
      "         ggggggg",
      "        ggcttttt",
      "        ggtttttt",
      "       gggtttttt",
      "       gggtttttt",
      "       gggtttttt",
      "       gggtttttt"
    ]
  ]
}