{
  "name": "multi_oasiscondo_0_floor2",
  "refpalette": "deceasedcraft:multi_oasiscondo_0/multi_oasiscondo_0_floor2_palette",
  "xsize": 16,
  "zsize": 16,
  "slices": [
    [
      "                ",
      "                ",
      "                ",
      "                ",
      "                ",
      "                ",
      "                ",
      "                ",
      "                ",
      "           aabbb",
      "          cbbbbb",
      "         dbbbbbb",
      "         dbbbbbb",
      "         bbbbbbb",
      "         bbbbbbb",
      "         bbbbbbe"
    ],
    [
      "                ",
      "                ",
      "                ",
      "                ",
      "                ",
      "                ",
      "                ",
      "                ",
      "            feeg",
      "           eheij",
      "          cklmno",
      "         epq mn ",
      "        rgs tuwx",
      "        geyyAyyB",
      "        eCD  EFI",
      "        gJD KLMe"
    ],
    [
      "                ",
      "                ",
      "                ",
      "                ",
      "                ",
      "                ",
      "                ",
      "                ",
      "             NNN",
      "           gNNnO",
      "          cP Qn ",
      "         eR  Sn ",
      "         NTxxUVx",
      "        NNyyWyyX",
      "        N       ",
      "        N      e"
    ],
    [
      "                ",
      "                ",
      "                ",
      "                ",
      "                ",
      "                ",
      "                ",
      "                ",
      "             NNN",
      "           gNNn ",
      "          cYZ0n ",
      "         e1  2n ",
      "         N  x 3x",
      "        NNyy4yy4",
      "        N       ",
      "        N      e"
    ],
    [
      "                ",
      "                ",
      "                ",
      "                ",
      "                ",
      "                ",
      "                ",
      "                ",
      "             NNN",
      "           eNNn ",
      "          c555n ",
      "         g6555n ",
      "         N 555n ",
      "        NNyyyyyy",
      "        N      7",
      "        N 8  9 e"
    ],
    [
      "                ",
      "                ",
      "                ",
      "                ",
      "                ",
      "                ",
      "                ",
      "                ",
      "            #eee",
      "           eee$$",
      "          c%  $$",
      "         e$   $$",
      "        re$   $$",
      "        ee$$$$$$",
      "        g$$$$$$$",
      "        e$$$$$$e"
    ]
  ]
}