{
  "name": "multi_oasiscondo_0_floor4",
  "refpalette": "deceasedcraft:multi_oasiscondo_0/multi_oasiscondo_0_floor4_palette",
  "xsize": 16,
  "zsize": 16,
  "slices": [
    [
      "                ",
      "                ",
      "                ",
      "                ",
      "                ",
      "                ",
      "                ",
      "                ",
      "                ",
      "           aabbb",
      "          cbbbbb",
      "         dbbbbbb",
      "         dbbbbbb",
      "         bbbbbbb",
      "         bbbbbbb",
      "         bbbbbbe"
    ],
    [
      "                ",
      "                ",
      "                ",
      "                ",
      "                ",
      "                ",
      "                ",
      "                ",
      "            feeg",
      "           eeehi",
      "          cj  k ",
      "         e   lm ",
      "        neeeoep ",
      "        eeqr  st",
      "        e    uu ",
      "        ewxy wxe"
    ],
    [
      "                ",
      "                ",
      "                ",
      "                ",
      "                ",
      "                ",
      "                ",
      "                ",
      "             AAA",
      "           eAAh ",
      "          c   B ",
      "         gC  Dh ",
      "         AeeEeh ",
      "        AA    sF",
      "        A       ",
      "        AIJ  K e"
    ],
    [
      "                ",
      "                ",
      "                ",
      "                ",
      "                ",
      "                ",
      "                ",
      "                ",
      "             AAA",
      "           eAAh ",
      "          c   L ",
      "         eM  Nh ",
      "         AeeOeh ",
      "        AA    sP",
      "        A       ",
      "        A      e"
    ],
    [
      "                ",
      "                ",
      "                ",
      "                ",
      "                ",
      "                ",
      "                ",
      "                ",
      "             AAA",
      "           gAAh ",
      "          cQQQh ",
      "         eRQQQh ",
      "         Aeeeeh ",
      "        AA    ss",
      "        A       ",
      "        A S  T e"
    ],
    [
      "                ",
      "                ",
      "                ",
      "                ",
      "                ",
      "                ",
      "                ",
      "                ",
      "            feee",
      "           eeeUU",
      "          cV  UU",
      "         gU   UU",
      "        neUUUUUU",
      "        eeUUUUUU",
      "        gUUUUUUU",
      "        eUUUUUUe"
    ]
  ]
}