{
  "name": "multi_oasiscondo_0_floor7",
  "refpalette": "deceasedcraft:multi_oasiscondo_0/multi_oasiscondo_0_floor7_palette",
  "xsize": 16,
  "zsize": 16,
  "slices": [
    [
      "                ",
      "                ",
      "                ",
      "                ",
      "                ",
      "                ",
      "                ",
      "                ",
      "                ",
      "           aabbb",
      "          cbbbbb",
      "         dbbbbbb",
      "         dbbbbbb",
      "         bbbbbbb",
      "         bbbbbbb",
      "         bbbbbbe"
    ],
    [
      "                ",
      "                ",
      "                ",
      "                ",
      "                ",
      "                ",
      "                ",
      "                ",
      "            fghe",
      "           iiijk",
      "          clmnop",
      "         hqrmno ",
      "        shtmmmuw",
      "        eexxyxxA",
      "        hBC  D  ",
      "        eEC FIJe"
    ],
    [
      "                ",
      "                ",
      "                ",
      "                ",
      "                ",
      "                ",
      "                ",
      "                ",
      "             KKK",
      "           gKKo ",
      "          c  Lo ",
      "         iM  No ",
      "         K  O P ",
      "        KKxxQxxR",
      "        KS      ",
      "        K    TUe"
    ],
    [
      "                ",
      "                ",
      "                ",
      "                ",
      "                ",
      "                ",
      "                ",
      "                ",
      "             KKK",
      "           iKKoV",
      "          c  Wo ",
      "         hX  Yo ",
      "         K    Z ",
      "        KKxx0xx0",
      "        K       ",
      "        K      e"
    ],
    [
      "                ",
      "                ",
      "                ",
      "                ",
      "                ",
      "                ",
      "                ",
      "                ",
      "             KKK",
      "           eKKo ",
      "          c 11o ",
      "         e2 11o ",
      "         K 311o ",
      "        KKxxxxxx",
      "        K       ",
      "        K 4  5 e"
    ],
    [
      "                ",
      "                ",
      "                ",
      "                ",
      "                ",
      "                ",
      "                ",
      "                ",
      "            fhee",
      "           ehe66",
      "          c77 66",
      "         e6   66",
      "        8e6   66",
      "        he666666",
      "        h6666666",
      "        e666666e"
    ]
  ]
}