{
  "name": "multi_oasiscondo_0_base1",
  "refpalette": "deceasedcraft:multi_oasiscondo_0/multi_oasiscondo_0_base1_palette",
  "xsize": 16,
  "zsize": 16,
  "slices": [
    [
      "vvvvvvvvvvvvvvvv",
      "vaaaaaaaavbbHHHH",
      "vaaaaaaaavbbHHHH",
      "vaaaaaaaavbbHHHH",
      "vaaaaaaaavbbHHHH",
      "vaaaaaaaavbbHHHH",
      "vaaaaaaaavbbHHHH",
      "vaaaaaaaavbbHHHH",
      "vaaaaaaaavbbHHHH",
      "vvvvvvvvvvbbHHHH",
      "vbbbbbbbbbcbHHHH",
      "vbbbbbbbbbbHHHHH",
      "vHHHHHHHHHHHHHHH",
      "vHHHHHHHHHHHHHHH",
      "vHHHHHHHHHHHHHHH",
      "vHHHHHHHHHHHHHHH"
    ],
    [
      "vvvvvvvvvvvvvvvv",
      "vaaaaaaaav      ",
      "vaaaaaaaav      ",
      "vaaaaaaaav      ",
      "vaaaaaaaav      ",
      "vaaaaaaaav      ",
      "vaaaaaaaav      ",
      "vaaaaaaaav      ",
      "vaaaaaaaav      ",
      "vvvvvvvvvv      ",
      "v         c     ",
      "vdddd           ",
      "ve  f           ",
      "vg  h           ",
      "ve  f           ",
      "vg  h           "
    ],
    [
      "vvvvvvvvvvvvvvvv",
      "vaaaaaaaav      ",
      "vaaaaaaaav      ",
      "vaaaaaaaav      ",
      "vaaaaaaaav      ",
      "vaaaaaaaav      ",
      "vaaaaaaaav      ",
      "vaaaaaaaav      ",
      "vaaaaaaaav      ",
      "vvvvvvvvvv      ",
      "v         c     ",
      "v               ",
      "v               ",
      "v               ",
      "v               ",
      "v               "
    ],
    [
      "vvvvvvvvvvvvvvvv",
      "vaaaaaaaav      ",
      "vaaaaaaaav      ",
      "vaaaaaaaav      ",
      "vaaaaaaaav      ",
      "vaaaaaaaav      ",
      "vaaaaaaaav      ",
      "vaaaaaaaav      ",
      "vaaaaaaaav      ",
      "vvvvvvvvvv      ",
      "v         c     ",
      "v               ",
      "v               ",
      "v               ",
      "v               ",
      "v               "
    ],
    [
      "vvvvvvvvvvvvvvvv",
      "vaaaaaaaav      ",
      "vaaaaaaaav      ",
      "vaaaaaaaav      ",
      "vaaaaaaaav      ",
      "vaaaaaaaav      ",
      "vaaaaaaaav      ",
      "vaaaaaaaav      ",
      "vaaaaaaaav      ",
      "vvvvvvvvvv      ",
      "v         c     ",
      "v               ",
      "v               ",
      "v               ",
      "v               ",
      "v               "
    ],
    [
      "vvvvvvvvvvvvvvvv",
      "vaaaaaaaavijjjjj",
      "vaaaaaaaavijjjjj",
      "vaaaaaaaavijjjjj",
      "vaaaaaaaavijjjjj",
      "vaaaaaaaavijjjjj",
      "vaaaaaaaavijjjjj",
      "vaaaaaaaavijjjjj",
      "vaaaaaaaavijjjjj",
      "vvvvvvvvvvijjjjj",
      "viiiiiiiiikiiiii",
      "vjjjjjjjjjijjjjj",
      "vjjjjjjjjjijjjjj",
      "vjjjjjjjjjijjjjj",
      "vjjjjjjjjjijjjjj",
      "vjjjjjjjjjijjjjj"
    ]
  ]
}