{
  "name": "multi_oasiscondo_0_floor8",
  "refpalette": "deceasedcraft:multi_oasiscondo_0/multi_oasiscondo_0_floor8_palette",
  "xsize": 16,
  "zsize": 16,
  "slices": [
    [
      "                ",
      "                ",
      "                ",
      "                ",
      "                ",
      "                ",
      "                ",
      "                ",
      "                ",
      "           aabbb",
      "          cbbbbb",
      "         dbbbbbb",
      "         dbbbbbb",
      "         bbbbbbb",
      "         bbbbbbb",
      "         bbbbbbe"
    ],
    [
      "                ",
      "                ",
      "                ",
      "                ",
      "                ",
      "                ",
      "                ",
      "                ",
      "            fege",
      "           geehi",
      "          cj klm",
      "         en  kl ",
      "        oep   q ",
      "        gerrsrrt",
      "        euw     ",
      "        exw yABe"
    ],
    [
      "                ",
      "                ",
      "                ",
      "                ",
      "                ",
      "                ",
      "                ",
      "                ",
      "             CCC",
      "           gCClD",
      "          c  El ",
      "         eF  Il ",
      "         C J  K ",
      "        CCrrLrrM",
      "        C       ",
      "        CN   OPe"
    ],
    [
      "                ",
      "                ",
      "                ",
      "                ",
      "                ",
      "                ",
      "                ",
      "                ",
      "             CCC",
      "           eCCl ",
      "          c  Ql ",
      "         gR  Sl ",
      "         C    T ",
      "        CCrrUrrU",
      "        C       ",
      "        C      e"
    ],
    [
      "                ",
      "                ",
      "                ",
      "                ",
      "                ",
      "                ",
      "                ",
      "                ",
      "             CCC",
      "           gCCl ",
      "          cVVVl ",
      "         e!VVVl ",
      "         C VVVl ",
      "        CCrrrrrr",
      "        C       ",
      "        C W  X e"
    ],
    [
      "                ",
      "                ",
      "                ",
      "                ",
      "                ",
      "                ",
      "                ",
      "                ",
      "            fgee",
      "           eeeYY",
      "          cZ  YY",
      "         eY   YY",
      "        0eY   YY",
      "        geYYYYYY",
      "        eYYYYYYY",
      "        gYYYYYYe"
    ]
  ]
}