{
  "name": "multi_oasiscondo_0_floor11",
  "refpalette": "deceasedcraft:multi_oasiscondo_0/multi_oasiscondo_0_floor11_palette",
  "xsize": 16,
  "zsize": 16,
  "slices": [
    [
      "                ",
      "                ",
      "                ",
      "                ",
      "                ",
      "                ",
      "                ",
      "                ",
      "                ",
      "           aabbb",
      "          cddddd",
      "         edddddd",
      "         edddddd",
      "         bdddddd",
      "         bdddddd",
      "         bffffff"
    ],
    [
      "                ",
      "                ",
      "                ",
      "                ",
      "                ",
      "                ",
      "                ",
      "            ghhh",
      "          ghhiii",
      "         ggiiiii",
      "        ggc j   ",
      "        ki      ",
      "       gki jlm  ",
      "       kii  m  n",
      "       kii      ",
      "       kii      "
    ],
    [
      "                ",
      "                ",
      "                ",
      "                ",
      "                ",
      "                ",
      "                ",
      "            oooo",
      "          ooo   ",
      "         oo     ",
      "        ooc     ",
      "        o       ",
      "       oo       ",
      "       o        ",
      "       o        ",
      "       o        "
    ],
    [
      "                ",
      "                ",
      "                ",
      "                ",
      "                ",
      "                ",
      "                ",
      "                ",
      "                ",
      "                ",
      "          c     ",
      "                ",
      "                ",
      "                ",
      "                ",
      "                "
    ],
    [
      "                ",
      "                ",
      "                ",
      "                ",
      "                ",
      "                ",
      "                ",
      "                ",
      "            pppp",
      "           pq   ",
      "          c     ",
      "         r      ",
      "        rs      ",
      "        r       ",
      "        r       ",
      "        r       "
    ],
    [
      "                ",
      "                ",
      "                ",
      "                ",
      "                ",
      "                ",
      "                ",
      "            gggg",
      "          gggggg",
      "         ggggggg",
      "        ggcttttt",
      "        ggtttttt",
      "       gggtttttt",
      "       gggtttttt",
      "       gggtttttt",
      "       gggtttttt"
    ]
  ]
}