{
  "name": "multi_oasiscondo_0_floor3",
  "refpalette": "deceasedcraft:multi_oasiscondo_0/multi_oasiscondo_0_floor3_palette",
  "xsize": 16,
  "zsize": 16,
  "slices": [
    [
      "                ",
      "                ",
      "                ",
      "                ",
      "                ",
      "                ",
      "                ",
      "                ",
      "                ",
      "           aabbb",
      "          cbbbbb",
      "         dbbbbbb",
      "         dbbbbbb",
      "         bbbbbbb",
      "         bbbbbbb",
      "         bbbbbbe"
    ],
    [
      "                ",
      "                ",
      "                ",
      "                ",
      "                ",
      "                ",
      "                ",
      "                ",
      "            feeg",
      "           eeehi",
      "          cj klm",
      "         gn  kl ",
      "        ogpq  r ",
      "        eesstssu",
      "        ewx  y  ",
      "        gAx BCDe"
    ],
    [
      "                ",
      "                ",
      "                ",
      "                ",
      "                ",
      "                ",
      "                ",
      "                ",
      "             EEE",
      "           eEElF",
      "          c  Il ",
      "         eJ  Kl ",
      "         E    L ",
      "        EEssMssN",
      "        E       ",
      "        E    OPe"
    ],
    [
      "                ",
      "                ",
      "                ",
      "                ",
      "                ",
      "                ",
      "                ",
      "                ",
      "             EEE",
      "           eEEl ",
      "          c  Ql ",
      "         eR  Sl ",
      "         E    T ",
      "        EEssUssU",
      "        E       ",
      "        E      e"
    ],
    [
      "                ",
      "                ",
      "                ",
      "                ",
      "                ",
      "                ",
      "                ",
      "                ",
      "             EEE",
      "           eEEl ",
      "          cVVVl ",
      "         gWVVVl ",
      "         E VVVl ",
      "        EEssssss",
      "        E       ",
      "        E X  Y e"
    ],
    [
      "                ",
      "                ",
      "                ",
      "                ",
      "                ",
      "                ",
      "                ",
      "                ",
      "            Zeee",
      "           gee00",
      "          c1  00",
      "         e0   00",
      "        2e0   00",
      "        ge000000",
      "        e0000000",
      "        e000000e"
    ]
  ]
}