{
  "name": "multi_oasiscondo_0_base3",
  "refpalette": "deceasedcraft:multi_oasiscondo_0/multi_oasiscondo_0_base3_palette",
  "xsize": 16,
  "zsize": 16,
  "slices": [
    [
      "vvvvvvvvvvvvvvvv",
      "vaaaaaaaav      ",
      "vaaaaaaaav      ",
      "vaaaaaaaav      ",
      "vaaaaaaaav      ",
      "vaaaaaaaav      ",
      "vaaaaaaaav      ",
      "vaaaaaaaav      ",
      "vaaaaaaaav      ",
      "vvvvvvvvvv      ",
      "v         b     ",
      "v               ",
      "v               ",
      "v               ",
      "v               ",
      "v               "
    ],
    [
      "vvvvvvvvvvvvvvvv",
      "vaaaaaaaav      ",
      "vaaaaaaaav      ",
      "vaaaaaaaav      ",
      "vaaaaaaaav      ",
      "vaaaaaaaav      ",
      "vaaaaaaaav      ",
      "vaaaaaaaav      ",
      "vaaaaaaaav      ",
      "vvvvvvvvvv      ",
      "v         b     ",
      "v               ",
      "v               ",
      "v               ",
      "v               ",
      "v               "
    ],
    [
      "vvvvvvvvvvvvvvvv",
      "vaaaaaaaav      ",
      "vaaaaaaaav      ",
      "vaaaaaaaav      ",
      "vaaaaaaaav      ",
      "vaaaaaaaav      ",
      "vaaaaaaaav      ",
      "vaaaaaaaav      ",
      "vaaaaaaaav      ",
      "vvvvvvvvvv      ",
      "v         b     ",
      "v               ",
      "v               ",
      "v               ",
      "v               ",
      "v               "
    ],
    [
      "vvvvvvvvvvvvvvvv",
      "vaaaaaaaav      ",
      "vaaaaaaaav      ",
      "vaaaaaaaav      ",
      "vaaaaaaaav      ",
      "vaaaaaaaav      ",
      "vaaaaaaaav      ",
      "vaaaaaaaav      ",
      "vaaaaaaaav      ",
      "vvvvvvvvvv      ",
      "v         b     ",
      "v               ",
      "v               ",
      "v               ",
      "v               ",
      "v               "
    ],
    [
      "vvvvvvvvvvvvvvvv",
      "vaaaaaaaav      ",
      "vaaaaaaaav      ",
      "vaaaaaaaav      ",
      "vaaaaaaaav      ",
      "vaaaaaaaav      ",
      "vaaaaaaaav      ",
      "vaaaaaaaav      ",
      "vaaaaaaaav      ",
      "vvvvvvvvvv      ",
      "v         b     ",
      "v               ",
      "v               ",
      "v               ",
      "v               ",
      "v               "
    ],
    [
      "vvvvvvvvvvvvvvvv",
      "vaaaaaaaavcddddd",
      "vaaaaaaaavcddddd",
      "vaaaaaaaavcddddd",
      "vaaaaaaaavcddddd",
      "vaaaaaaaavcddddd",
      "vaaaaaaaavcddddd",
      "vaaaaaaaavcddddd",
      "vaaaaaaaavcddddd",
      "vvvvvvvvvvcddddd",
      "vccccccccceccccc",
      "vdddddddddcddddd",
      "vdddddddddcddddd",
      "vdddddddddcddddd",
      "vdddddddddcddddd",
      "vdddddddddcddddd"
    ]
  ]
}