{
  "name": "multi_oasiscondo_0_floor6",
  "refpalette": "deceasedcraft:multi_oasiscondo_0/multi_oasiscondo_0_floor6_palette",
  "xsize": 16,
  "zsize": 16,
  "slices": [
    [
      "                ",
      "                ",
      "                ",
      "                ",
      "                ",
      "                ",
      "                ",
      "                ",
      "                ",
      "           aabbb",
      "          cbbbbb",
      "         d!ebbbb",
      "         dbbbbbb",
      "         bbbbbbb",
      "         bbbbbbb",
      "         bbbbbbf"
    ],
    [
      "                ",
      "                ",
      "                ",
      "                ",
      "                ",
      "                ",
      "                ",
      "                ",
      "            gfff",
      "           hffij",
      "          ck lmn",
      "         op  lm ",
      "        qhr   s ",
      "        hfttuttw",
      "        fxy  yy ",
      "        fA  BCDf"
    ],
    [
      "                ",
      "                ",
      "                ",
      "                ",
      "                ",
      "                ",
      "                ",
      "                ",
      "             EEE",
      "           hEEmF",
      "          c  Im ",
      "         oJ  Km ",
      "         E L  M ",
      "        EEttNttO",
      "        E       ",
      "        E   PQRf"
    ],
    [
      "                ",
      "                ",
      "                ",
      "                ",
      "                ",
      "                ",
      "                ",
      "                ",
      "             EEE",
      "           fEEm ",
      "          c  Sm ",
      "         hT  Um ",
      "         E    V ",
      "        EEttWttW",
      "        E       ",
      "        E      f"
    ],
    [
      "                ",
      "                ",
      "                ",
      "                ",
      "                ",
      "                ",
      "                ",
      "                ",
      "             EEE",
      "           hEEm ",
      "          cXXXm ",
      "         fYXXXm ",
      "         E XXXm ",
      "        EEtttttt",
      "        E       ",
      "        E Z  0 f"
    ],
    [
      "                ",
      "                ",
      "                ",
      "                ",
      "                ",
      "                ",
      "                ",
      "                ",
      "            gfhh",
      "           fhf11",
      "          c2  11",
      "         h1   11",
      "        3f1   11",
      "        ff111111",
      "        f1111111",
      "        h111111f"
    ]
  ]
}