{
  "name": "multi_oasiscondo_0_floor5",
  "refpalette": "deceasedcraft:multi_oasiscondo_0/multi_oasiscondo_0_floor5_palette",
  "xsize": 16,
  "zsize": 16,
  "slices": [
    [
      "                ",
      "                ",
      "                ",
      "                ",
      "                ",
      "                ",
      "                ",
      "                ",
      "                ",
      "           aabbb",
      "          cbbbbb",
      "         dbbbbbb",
      "         dbbbbbb",
      "         bbbbbbb",
      "         bbbbbbb",
      "         bbbbbbe"
    ],
    [
      "                ",
      "                ",
      "                ",
      "                ",
      "                ",
      "                ",
      "                ",
      "                ",
      "            fege",
      "           geehi",
      "          cj klm",
      "         gn  kl ",
      "        oep   q ",
      "        eerrsrrt",
      "        guw     ",
      "        gxw yABe"
    ],
    [
      "                ",
      "                ",
      "                ",
      "                ",
      "                ",
      "                ",
      "                ",
      "                ",
      "             CCC",
      "           eCClD",
      "          c   l ",
      "         eE  Fl ",
      "         C    I ",
      "        CCrrJrrK",
      "        CL      ",
      "        C   M  e"
    ],
    [
      "                ",
      "                ",
      "                ",
      "                ",
      "                ",
      "                ",
      "                ",
      "                ",
      "             CCC",
      "           eCCl ",
      "          c  Nl ",
      "         gO  Pl ",
      "         C    Q ",
      "        CCrrRrrR",
      "        C       ",
      "        C      e"
    ],
    [
      "                ",
      "                ",
      "                ",
      "                ",
      "                ",
      "                ",
      "                ",
      "                ",
      "             CCC",
      "           gCCl ",
      "          cSSSl ",
      "         eTSSSl ",
      "         C SSSl ",
      "        CCrrrrrr",
      "        C       ",
      "        C U  V e"
    ],
    [
      "                ",
      "                ",
      "                ",
      "                ",
      "                ",
      "                ",
      "                ",
      "                ",
      "            Wegg",
      "           egeXX",
      "          cY  XX",
      "         eX   XX",
      "        oeX   XX",
      "        geXXXXXX",
      "        eXXXXXXX",
      "        gXXXXXXe"
    ]
  ]
}