{
  "name": "multi_oasiscondo_0_base4",
  "refpalette": "deceasedcraft:multi_oasiscondo_0/multi_oasiscondo_0_base4_palette",
  "xsize": 16,
  "zsize": 16,
  "slices": [
    [
      "vvvvvvvvvvvvvvvv",
      "vaaaaaaaaaaaaaaa",
      "vaaaaaaaaaaaaaaa",
      "vaaaaaaaaaaaaaaa",
      "vaaaaaaaaaaaaaaa",
      "vaaaaaaaaaaaaaaa",
      "vaaaaaaaaaaaaaaa",
      "vaaaaaaaaaaaaaaa",
      "vaaaaaaaaaaaaaaa",
      "vaaaaaaaaaaaaaaa",
      "vaaaaaaaaaaaaaaa",
      "vaaaaaaaaaaaaaaa",
      "vaaaaaaaaaaaaaaa",
      "vaaaaaaaaaaaaaaa",
      "vaaaaaaaaaaaaaaa",
      "vaaaaaaaaaaaaaaa"
    ],
    [
      "vvvvvvvvvvvvvvvv",
      "vaaaaaaaaaaaaaaa",
      "vaaaaaaaaaaaaaaa",
      "vaaaaaaaaaaaaaaa",
      "vaaaaaaaaaaaaaaa",
      "vaaaaaaaaaaaaaaa",
      "vaaaaaaaaaaaaaaa",
      "vaaaaaaaaaaaaaaa",
      "vaaaaaaaaaaaaaaa",
      "vaaaaaaaaaaaaaaa",
      "vaaaaaaaaabaaaaa",
      "vaaaaaaaaaaaaaaa",
      "vaaaaaaaaaaaaaaa",
      "vaaaaaaaaaaaaaaa",
      "vaaaaaaaaaaaaaaa",
      "vaaaaaaaaaaaaaaa"
    ],
    [
      "vvvvvvvvvvvvvvvv",
      "vaaaaaaaavccHHHH",
      "vaaaaaaaavccHHHH",
      "vaaaaaaaavccHHHH",
      "vaaaaaaaavccHHHH",
      "vaaaaaaaavccHHHH",
      "vaaaaaaaavccHHHH",
      "vaaaaaaaavccHHHH",
      "vaaaaaaaavccHHHH",
      "vvvvvvvvvvccHHHH",
      "vcccccccccbcHHHH",
      "vccccccccccHHHHH",
      "vHHHHHHHHHHHHHHH",
      "vHHHHHHHHHHHHHHH",
      "vHHHHHHHHHHHHHHH",
      "vHHHHccccccccccc"
    ],
    [
      "vvvvvvvvvvvvvvvv",
      "vaaaaaaaav      ",
      "vaaaaaaaav      ",
      "vaaaaaaaav      ",
      "vaaaaaaaav      ",
      "vaaaaaaaav      ",
      "vaaaaaaaav      ",
      "vaaaaaaaav      ",
      "vaaaaaaaav      ",
      "vvvvvvvvvv      ",
      "v         b     ",
      "v               ",
      "v               ",
      "v               ",
      "v               ",
      "v               "
    ],
    [
      "vvvvvvvvvvvvvvvv",
      "vaaaaaaaav      ",
      "vaaaaaaaav      ",
      "vaaaaaaaav      ",
      "vaaaaaaaav      ",
      "vaaaaaaaav      ",
      "vaaaaaaaav      ",
      "vaaaaaaaav      ",
      "vaaaaaaaav      ",
      "vvvvvvvvvv      ",
      "v         b     ",
      "v               ",
      "v               ",
      "v               ",
      "v               ",
      "v               "
    ],
    [
      "vvvvvvvvvvvvvvvv",
      "vaaaaaaaav      ",
      "vaaaaaaaav      ",
      "vaaaaaaaav      ",
      "vaaaaaaaav      ",
      "vaaaaaaaav      ",
      "vaaaaaaaav      ",
      "vaaaaaaaav      ",
      "vaaaaaaaav      ",
      "vvvvvvvvvv      ",
      "v         b     ",
      "v               ",
      "v               ",
      "v               ",
      "v               ",
      "v               "
    ]
  ]
}