{
  "name": "multi_filmworkstower_2_base1",
  "refpalette": "deceasedcraft:multi_filmworkstower_2/multi_filmworkstower_2_base1_palette",
  "xsize": 16,
  "zsize": 16,
  "slices": [
    [
      "vaaavb          ",
      "vaaavb          ",
      "vaaavb          ",
      "vaaavb          ",
      "vaaavb          ",
      "vaaavb          ",
      "vaaavc          ",
      "vaaade          ",
      "vaaad           ",
      "vaaaffffffffffff",
      "vaaagggggggg    ",
      "vaaag           ",
      "vaaag           ",
      "vaaag           ",
      "vaaag           ",
      "vaaag           "
    ],
    [
      "vaaadc          ",
      "vaaadc          ",
      "vaaadc          ",
      "vaaadc          ",
      "vaaadc          ",
      "vaaadc          ",
      "vaaade          ",
      "vaaad           ",
      "vaaad           ",
      "vaaaffffffffffff",
      "vaaagggggggg    ",
      "vaaag           ",
      "vaaag           ",
      "vaaag           ",
      "vaaag           ",
      "vaaag           "
    ],
    [
      "vaaad           ",
      "vaaad           ",
      "vaaad           ",
      "vaaad           ",
      "vaaadh          ",
      "vaaadi          ",
      "vaaad           ",
      "vaaad           ",
      "vaaad           ",
      "vaaaffffffffffff",
      "vaaagggggggg    ",
      "vaaag           ",
      "vaaag           ",
      "vaaag           ",
      "vaaag           ",
      "vaaag           "
    ],
    [
      "vaaad           ",
      "vaaad           ",
      "vaaad           ",
      "vaaad           ",
      "vaaad           ",
      "vaaad           ",
      "vaaad           ",
      "vaaad           ",
      "vaaad           ",
      "vaaaffffffffffff",
      "vaaagggggggg    ",
      "vaaag           ",
      "vaaag           ",
      "vaaag           ",
      "vaaag           ",
      "vaaag           "
    ],
    [
      "vaaafjjjjjjjjjjj",
      "vaaafjjjjjjjjjjj",
      "vaaafjjjjjjjjjjj",
      "vaaafjjjjjjjjjjj",
      "vaaafjjjjjjjjjjj",
      "vaaafjjjjjjjjjjj",
      "vaaafjjjjjjjjjjj",
      "vaaafjjjjjjjjjjj",
      "vaaafjjjjjjjjjjj",
      "vaaaffffffffffff",
      "vaaafjjjjjjjjjjj",
      "vaaafjjjjjjjjjjj",
      "vaaafjjjjjjjjjjj",
      "vaaafjjjjjjjjjjj",
      "vaaafjjjjjjjjjjj",
      "vaaafjjjjjjjjjjj"
    ],
    [
      "vaaaffffffffffff",
      "vaaaffffffffffff",
      "vaaaffffffffffff",
      "vaaaffffffffffff",
      "vaaaffffffffffff",
      "vaaaffffffffffff",
      "vaaaffffffffffff",
      "vaaaffffffffffff",
      "vaaaffffffffffff",
      "vaaaf ffffffffff",
      "vaaaffffffffffff",
      "vaaaffffffffffff",
      "vaaaffffffffffff",
      "vaaaffffffffffff",
      "vaaaffffffffffff",
      "vaaaffffffffffff"
    ]
  ]
}