{
  "name": "multi_filmworkstower_2_base2",
  "refpalette": "deceasedcraft:multi_filmworkstower_2/multi_filmworkstower_2_base2_palette",
  "xsize": 16,
  "zsize": 16,
  "slices": [
    [
      "vaaabccccccccccc",
      "vaaabccccccccccc",
      "vaaabccccccccccc",
      "vaaabccccccccccc",
      "vaaabccccccccccc",
      "vaaabccccccccccc",
      "vaaabccccccccccc",
      "vaaabccccccccccc",
      "vaaabccccccccccc",
      "vaaabbbbbbbbbbbb",
      "vaaabccccccccccc",
      "vaaabccccccccccc",
      "vaaabccccccccccc",
      "vaaabccccccccccc",
      "vaaabccccccccccc",
      "vaaabccccccccccc"
    ],
    [
      "vaaavde         ",
      "vaaavde         ",
      "vaaavde        f",
      "vaaavde         ",
      "vaaavde         ",
      "vaaavde         ",
      "vaaavge    h    ",
      "vaaai           ",
      "vaaai        jkl",
      "vaaabbbbbbbbbbbb",
      "vaaammmmmmmm   n",
      "vaaamooooooo  p ",
      "vaaamooooooo  p ",
      "vaaamooooooo  p ",
      "vaaamooooooo  q ",
      "vaaamooooooo  p "
    ],
    [
      "vaaar           ",
      "vaaad           ",
      "vaaads          ",
      "vaaadt          ",
      "vaaavu          ",
      "vaaavw          ",
      "vaaavg          ",
      "vaaai           ",
      "vaaai           ",
      "vaaabbbbbbbbbbbb",
      "vaaammmmmmmm    ",
      "vaaam  x  y     ",
      "vaaamyx  A x    ",
      "vaaamA          ",
      "vaaamoy !     f ",
      "vaaamo          "
    ],
    [
      "vaaad           ",
      "vaaadB          ",
      "vaaaCD          ",
      "vaaad           ",
      "vaaadE          ",
      "vaaadF          ",
      "vaaavg          ",
      "vaaai           ",
      "vaaai           ",
      "vaaabbbbbbbbbbbb",
      "vaaammmmmmmm    ",
      "vaaam           ",
      "vaaam           ",
      "vaaam           ",
      "vaaam           ",
      "vaaam           "
    ],
    [
      "vaaad           ",
      "vaaadI          ",
      "vaaadJ          ",
      "vaaad           ",
      "vaaadK          ",
      "vaaadL          ",
      "vaaavg          ",
      "vaaai           ",
      "vaaai           ",
      "vaaabbbbbbbbbbbb",
      "vaaammmmmmmm    ",
      "vaaam           ",
      "vaaam           ",
      "vaaam           ",
      "vaaam           ",
      "vaaam     M     "
    ],
    [
      "vaaad           ",
      "vaaad           ",
      "vaaad           ",
      "vaaad           ",
      "vaaadK          ",
      "vaaadL          ",
      "vaaavg          ",
      "vaaaiN          ",
      "vaaaiO          ",
      "vaaabbbbbbbbbbbb",
      "vaaammmmmmmm    ",
      "vaaam           ",
      "vaaam           ",
      "vaaam           ",
      "vaaam           ",
      "vaaam           "
    ]
  ]
}