{
  "name": "multi_filmworkstower_2_ground",
  "refpalette": "deceasedcraft:multi_filmworkstower_2/multi_filmworkstower_2_ground_palette",
  "xsize": 16,
  "zsize": 16,
  "slices": [
    [
      "aaaabccccccccccc",
      "aaaabccccccccccc",
      "aaaabccccccccccc",
      "aaaabccccccccccc",
      "aaaabccccccccccc",
      "aaaabccccccccccc",
      "aaaabccccccccccc",
      "aaaabccccccccccc",
      "aaaabccccccccccc",
      "aaaab ddddddddcc",
      "aaaabdeee  eedcc",
      "aaafbd g   g dcc",
      "aaaabd       dcc",
      "aaaabde     edcc",
      "aaafbdeg   g dcc",
      "aaaabd     e dcc"
    ],
    [
      "     h     i    ",
      "     h    jik   ",
      "     h     i    ",
      "     h     i    ",
      "     h    jik   ",
      "     h     i    ",
      "     h     l    ",
      "     h          ",
      "     hmn        ",
      "     opppppppp  ",
      "    qdrrrrrrrp  ",
      "   qfdrrrrrrrp  ",
      "    qdrrrrrrrp  ",
      "    qdrrrrrrrp  ",
      "   qfdrrrrrrrp  ",
      "    qdrrrrrrrp  "
    ],
    [
      "      h         ",
      "      h    s    ",
      "      h    t    ",
      "      h         ",
      "      h    u    ",
      "      h    t    ",
      "      h    w    ",
      "      h         ",
      "      hmn       ",
      "      o         ",
      "     qx         ",
      "    qfx         ",
      "     qx         ",
      "     qx         ",
      "    qfx         ",
      "     qx         "
    ],
    [
      "       h        ",
      "       h        ",
      "       h        ",
      "       h        ",
      "       h        ",
      "       h        ",
      "       h   y    ",
      "       h        ",
      "       hmn      ",
      "       o        ",
      "      qx        ",
      "     qfx        ",
      "      qx        ",
      "      qx        ",
      "     qfx        ",
      "      qx        "
    ],
    [
      "        h       ",
      "        h       ",
      "        h       ",
      "        h       ",
      "        h       ",
      "        h       ",
      "        h  y    ",
      "        h       ",
      "        hmn     ",
      "        o       ",
      "       qx       ",
      "      qfx       ",
      "       qx       ",
      "       qx       ",
      "      qfx       ",
      "       qx       "
    ],
    [
      "         h      ",
      "         h      ",
      "         h      ",
      "         h      ",
      "         h      ",
      "         h      ",
      "         h A    ",
      "         h      ",
      "         hmn    ",
      "         o      ",
      "        qx      ",
      "       qfx      ",
      "        qx      ",
      "        qx      ",
      "       qfx      ",
      "        qx      "
    ]
  ]
}