{
  "name": "multi_filmworkstower_2_floor1",
  "refpalette": "deceasedcraft:multi_filmworkstower_2/multi_filmworkstower_2_floor1_palette",
  "xsize": 16,
  "zsize": 16,
  "slices": [
    [
      "          ab    ",
      "          ac    ",
      "          ad    ",
      "          ac    ",
      "          ad    ",
      "          ae    ",
      "          af    ",
      "          ab    ",
      "          agh   ",
      "          i     ",
      "         jk     ",
      "        jlk     ",
      "         jk     ",
      "         jk     ",
      "        jlk     ",
      "         jk     "
    ],
    [
      "           mnnon",
      "           mnnon",
      "           mnnon",
      "           mnnon",
      "           mnnon",
      "           mnnon",
      "           mnnon",
      "           mpppp",
      "           agh  ",
      "           i    ",
      "          jk    ",
      "         jlk    ",
      "          jk    ",
      "          jk  q ",
      "         jlk  q ",
      "          jk  q "
    ],
    [
      "            mrrr",
      "            mrrr",
      "            mrrr",
      "            mrrr",
      "            mrrr",
      "            mrrr",
      "            mrrr",
      "            mss ",
      "            aggg",
      "            i   ",
      "           jk   ",
      "          jlk   ",
      "           jk   ",
      "           jk q ",
      "          jlk q ",
      "           jk q "
    ],
    [
      "                ",
      "                ",
      "                ",
      "                ",
      "                ",
      "                ",
      "             m  ",
      "             mss",
      "             agg",
      "             i  ",
      "            jk  ",
      "           jlk  ",
      "            jk  ",
      "            jkq ",
      "           jlkq ",
      "            jkq "
    ],
    [
      "                ",
      "                ",
      "                ",
      "                ",
      "                ",
      "                ",
      "              m ",
      "              ms",
      "              ag",
      "              i ",
      "             jk ",
      "            jlk ",
      "             jk ",
      "             jt ",
      "            jlt ",
      "             jt "
    ],
    [
      "                ",
      "                ",
      "                ",
      "                ",
      "                ",
      "                ",
      "               m",
      "               m",
      "               a",
      "               i",
      "              jk",
      "             jlk",
      "              jk",
      "              jk",
      "             jlk",
      "              jk"
    ]
  ]
}