{
  "name": "multi_laboratory_13_base5",
  "refpalette": "deceasedcraft:multi_laboratory_13/multi_laboratory_13_base5_palette",
  "xsize": 16,
  "zsize": 16,
  "slices": [
    [
      "             abv",
      "             cbv",
      "ddddefffffffffev",
      "    g         hv",
      "    g         hv",
      "    g         hv",
      "    g         hv",
      "    g         hv",
      "    g         hv",
      "   ie         jv",
      "    g    k    hv",
      "    g   klk   hv",
      "    g   l l   hv",
      "    g   m m   hv",
      "    g   mnm   hv",
      "    g   m m   hv"
    ],
    [
      "             abv",
      "             cbv",
      "ddddefffffffffev",
      "    g         hv",
      "    g         hv",
      "    g         hv",
      "    g         hv",
      "    g         hv",
      "    g         hv",
      "    e         jv",
      "    g         hv",
      "    g    o    hv",
      "    g         hv",
      "    g         hv",
      "    g         hv",
      "    g         hv"
    ],
    [
      "             abv",
      "             cbv",
      "ddddefffffffffev",
      "    g         hv",
      "    g         hv",
      "    g         hv",
      "    g         hv",
      "    g         hv",
      "    g         hv",
      "    e         jv",
      "    g         hv",
      "    g         hv",
      "    g         hv",
      "    g         hv",
      "    g         hv",
      "    g         hv"
    ],
    [
      "            pabv",
      "             cbv",
      "ddddefffffffffev",
      "    g         hv",
      "    g         hv",
      "    g         hv",
      "    g         hv",
      "    g         hv",
      "    g         hv",
      "    e         jv",
      "    g         hv",
      "    g         hv",
      "    g         hv",
      "    g         hv",
      "    g         hv",
      "    g         hv"
    ],
    [
      "            qabv",
      "             cbv",
      "rrrrerrrrrrrrrev",
      "    s         hv",
      "    s         hv",
      "    s         hv",
      "    s         hv",
      "    s         hv",
      "    s         hv",
      "    e         jv",
      "    s         hv",
      "    s         hv",
      "    s         hv",
      "    s         hv",
      "    s         hv",
      "    s         hv"
    ],
    [
      "ttttttttttttuabv",
      "ttttttttttttucbv",
      "wwwwewwwwwwwwwav",
      "jjjjsjjjjjjjjjav",
      "jjjjsjjjjjjjjjav",
      "jjjjsjjxyxyyjjav",
      "jjjjsjjxyxyyjjav",
      "jjjjsjjjjjjjjjav",
      "jjjjsjjjjjjjjjav",
      "jjjjsjjjjjjjjjav",
      "jjjjsjjjjjjjjjav",
      "jjjjsjjjjjjjjjav",
      "jjjjsjjxxxyxjjav",
      "jjjjsjjxxxyxjjav",
      "jjjjsjjjjjjjjjav",
      "jjjjsjjjjjjjjjav"
    ]
  ]
}