{
  "name": "multi_laboratory_13_base3",
  "refpalette": "deceasedcraft:multi_laboratory_13/multi_laboratory_13_base3_palette",
  "xsize": 16,
  "zsize": 16,
  "slices": [
    [
      "aaaaaaaaaaaaabcv",
      "aaaaaaaaaaaaabcv",
      "aaaadaaaaaaaabcv",
      "aaaaaaaaaaaaabcv",
      "aaaaaaaaaaaaabcv",
      "aaaaaaaaaaaaabcv",
      "aaaaaaaaaaaaabcv",
      "aaaaaaaaaaaaabcv",
      "aaaaaaaaaaaaabcv",
      "aaaadaaaaaaaabcv",
      "aaaaaaaaaaaaabcv",
      "aaaaaaaaaaaaabcv",
      "aaaaaaaaaaaaabcv",
      "aaaaaaaaaaaaabcv",
      "aaaaaaaaaaaaabcv",
      "aaaaaaaaaaaaabcv"
    ],
    [
      "ef  g     h ibcv",
      " f  jk    l ibcv",
      " f  dmn     obcv",
      "pf  jq      obcv",
      " f  jq h  h ibcv",
      " r  j       ibcv",
      "    j     lsibcv",
      "    j  l    ibcv",
      "    jk      tbcv",
      "jjjjdun wxy  bcv",
      "   AjB  xxy  bcv",
      "    jBB yyy  bcv",
      "    jBBl     bcv",
      "CD  jB       bcv",
      "E   j!BF  F  bcv",
      "I   jBB     Jbcv"
    ],
    [
      "    g        bcv",
      " K  jk      Kbcv",
      " L  dmM     Nbcv",
      "    j        bcv",
      "    O       Pbcv",
      "    O       Kbcv",
      "    O       Kbcv",
      "    O       Pbcv",
      "    jk       bcv",
      "OOOjduM ww   bcv",
      "    jB  QRR  bcv",
      "    SB  TRR  bcv",
      "    SB       bcv",
      "    SB       bcv",
      "    S        bcv",
      "    jB       bcv"
    ],
    [
      "    g        bcv",
      "    j        bcv",
      "    dU       bcv",
      "    j        bcv",
      "    O        bcv",
      "    O        bcv",
      "    O        bcv",
      "    O        bcv",
      "    j        bcv",
      "OOOjdU   V   bcv",
      "    j    w   bcv",
      "    WB       bcv",
      "    WB       bcv",
      "    W        bcv",
      "    W        bcv",
      "    jB       bcv"
    ],
    [
      "    j        bcv",
      "    j        bcv",
      "    dU       bcv",
      "    j       Xbcv",
      "    j        bcv",
      "    j        bcv",
      "    j        bcv",
      "    j        bcv",
      "    j        bcv",
      "jjjjdU       bcv",
      "    j        bcv",
      "    j        bcv",
      "    j        bcv",
      "    j        bcv",
      "    j        bcv",
      "    j        bcv"
    ],
    [
      "YYZY0U121131Ubcv",
      "YYYY0U121131Ubcv",
      "YYYYdU111111Ubcv",
      "YYYY0U111111Ubcv",
      "YYZY0U131131Ubcv",
      "YYZY0U121121Ubcv",
      "YYZY0U131131Ubcv",
      "YYZY0U131121Ubcv",
      "YYYY0U111111Ubcv",
      "4444dU111111Ubcv",
      "11110U121121Ubcv",
      "11110U121121Ubcv",
      "11110U131121Ubcv",
      "22110U121121Ubcv",
      "12110U111111Ubcv",
      "12110U111111Ubcv"
    ]
  ]
}