{
  "name": "multi_laboratory_13_ground",
  "refpalette": "deceasedcraft:multi_laboratory_13/multi_laboratory_13_ground_palette",
  "xsize": 16,
  "zsize": 16,
  "slices": [
    [
      "aaaabcccvvzddddz",
      "aaaabcccvedddzzz",
      "aaaabcccvedddddz",
      "aaaabcccvdddddzd",
      "aaaabcccveedddzz",
      "aaaabcccvedddddz",
      "aaaabcccveddzzdz",
      "aaaabcccveedddzd",
      "aaaabcccveeddddz",
      "aaaabcccvededdzd",
      "aaaabcccvvddddzd",
      "aaaabccceeddddzz",
      "aaaabcccvddddddz",
      "aaaabcccveddzdzz",
      "aaaabcccvedddddz",
      "aaaabcccveedddzz"
    ],
    [
      " f  g           ",
      "hh  g     ijj k ",
      "hh lb           ",
      " m  g           ",
      "nnnno     ijpq k",
      "rrr!o           ",
      "  rsg       k   ",
      "nnnno     ijj   ",
      "    g           ",
      "t   b         k ",
      "uw  g     ijpq  ",
      "bxy g           ",
      "bx  g           ",
      "bx  g  A  iq j k",
      "bxy g  B        ",
      "CD  g  B      k "
    ],
    [
      "    g           ",
      "    g           ",
      "    b           ",
      "    E           ",
      "nnnno           ",
      "F r g           ",
      "  s g           ",
      "nnnno           ",
      "    E           ",
      "    b           ",
      "    g           ",
      "    g           ",
      "    g  A        ",
      "    g  B        ",
      " I  g  B        ",
      "J   g  B        "
    ],
    [
      "    g           ",
      "    g           ",
      "    b           ",
      "    E           ",
      "nnnno           ",
      "  F g           ",
      "    g           ",
      "nnnno           ",
      "    E           ",
      "    b           ",
      "    g           ",
      "    g  A        ",
      "    g  B        ",
      "    g  K        ",
      "    g  K        ",
      "    g  L        "
    ],
    [
      "    g           ",
      "    g           ",
      "    b           ",
      "    E           ",
      "nnnno           ",
      "    g           ",
      "    g           ",
      "nnnno           ",
      "    E           ",
      "    b           ",
      "    g  A        ",
      "    g  B        ",
      "    g  L        ",
      "    g  L        ",
      "    g  L        ",
      "    g  K        "
    ],
    [
      "MNMOg           ",
      "MNMOg           ",
      "OOOOb           ",
      "OOOOg           ",
      "nnnno           ",
      "MMMOg           ",
      "MMMOg           ",
      "nnnno           ",
      "OOOOg           ",
      "OOOOb  A        ",
      "NMMOg  B        ",
      "NMMOg  K        ",
      "OOOOg  L        ",
      "OOOOg  K        ",
      "NMNOg  K        ",
      "NMNOg  L        "
    ]
  ]
}