{
  "name": "multi_laboratory_13_base2",
  "refpalette": "deceasedcraft:multi_laboratory_13/multi_laboratory_13_base2_palette",
  "xsize": 16,
  "zsize": 16,
  "slices": [
    [
      "aaaaaaaaaaaaabcv",
      "aaaaaaaaaaaaabcv",
      "aaaadaaaaaaaabcv",
      "aaaaaaaaaaaaabcv",
      "aaaaaaaaaaaaabcv",
      "aaaaaaaaaaaaabcv",
      "aaaaaaaaaaaaabcv",
      "aaaaaaaaaaaaabcv",
      "aaaaaeeeeeeeebcv",
      "aaaadaaaaaaaabcv",
      "aaaaaaaaaaaaabcv",
      "aaaaaaaaaaaaabcv",
      "aaaaaaaaaaaaabcv",
      "aaaaaaaaaaaaabcv",
      "aaaaaaaaaaaaabcv",
      "aaaaaaaaaaaaabcv"
    ],
    [
      " f  g     h ibcv",
      "jf  kl    m ibcv",
      " f  dno     pbcv",
      " f  kq      pbcv",
      "rf  kq h  m ibcv",
      " s  k       ibcv",
      "    k      tibcv",
      "    k       ibcv",
      "    k       ubcv",
      "kkkkdw  xx  wbcv",
      "   ykw AAAA wbcv",
      "    kwBACCADwbcv",
      "    kwBAEEADwbcv",
      "FI  kw AAAA wbcv",
      "J   kw  KK  wbcv",
      "L   kwwwwwwwwbcv"
    ],
    [
      "    g        bcv",
      " M  kl      Nbcv",
      "    dnO      bcv",
      "    k        bcv",
      " M  P       Nbcv",
      "    P       Qbcv",
      "    P       Mbcv",
      "    P       Nbcv",
      "    k        bcv",
      "PPPkdw      wbcv",
      "    kw  RR  wbcv",
      "    Sw R  R wbcv",
      "    S  RTUR  bcv",
      "V   Sw  RR  wbcv",
      "W   Sw      wbcv",
      "    kw!wwwwwwbcv"
    ],
    [
      "    g        bcv",
      "    k        bcv",
      "    dX       bcv",
      "    k        bcv",
      "    P        bcv",
      "    P        bcv",
      "    P        bcv",
      "    P        bcv",
      "    k        bcv",
      "PPPkdw      wbcv",
      "    kw  RR  wbcv",
      "    Yw R  R wbcv",
      "    Yw RZ R wbcv",
      "    Yw  RR  wbcv",
      "    Yw      wbcv",
      "    kwww wwwwbcv"
    ],
    [
      "    k        bcv",
      "    k        bcv",
      "    dX       bcv",
      "    k       0bcv",
      "    k        bcv",
      "    k        bcv",
      "    k        bcv",
      "    k        bcv",
      "    k        bcv",
      "kkkkdw      wbcv",
      "    kw  RR  wbcv",
      "    kw R  R wbcv",
      "    kw RZUR wbcv",
      "    kw  RR  wbcv",
      "    kw       bcv",
      "    kwwwwwwwwbcv"
    ],
    [
      "11 12X343353Xbcv",
      "11112X343353Xbcv",
      "1111dX333333Xbcv",
      "11112X333333Xbcv",
      "11612X353353Xbcv",
      "11612X343343Xbcv",
      "11612X343343Xbcv",
      "11612X343373Xbcv",
      "11112X333333Xbcv",
      "8888dw      wbcv",
      "33332w  RR  wbcv",
      "33332w R 9R wbcv",
      "33332w RCCR wbcv",
      "66332w  RR  wbcv",
      "36332w      wbcv",
      "37332wwwwwwwwbcv"
    ]
  ]
}