{
  "name": "multi_laboratory_13_base6",
  "refpalette": "deceasedcraft:multi_laboratory_13/multi_laboratory_13_base6_palette",
  "xsize": 16,
  "zsize": 16,
  "slices": [
    [
      "aaab ababaaaacdv",
      "aaaaaabaaaaaacdv",
      "eebefeeeeeeeegcv",
      "aaaaaaaaaaaaaacv",
      "abbhaaaaaaaaaacv",
      "abaaaaaaaaaaaacv",
      "abaaaaaaaaaaaacv",
      "aaabaaaaaaaaaacv",
      "aaaaaaeeeeeeeacv",
      "a!aafaeiiiiieacv",
      "aaaaaaeiiiiieacv",
      "aaaaaaeiiiiieacv",
      "aaaaaaeiiiiieacv",
      "aaaaaaeiiiiieacv",
      "aaaaaaeiiiiieacv",
      "a!aaaaeiiiiieacv"
    ],
    [
      "   j kbb    lcdv",
      " m bbb       ndv",
      "  obfooooooooofv",
      "  bkp        qrv",
      "s ltp   u u  qrv",
      " jb p wxyyyxABrv",
      "  bbp         rv",
      "  k p  C   C  rv",
      "t k p         rv",
      "kDE f        Fiv",
      "bI  p         rv",
      "bb  p         rv",
      " b  p  J   J  rv",
      "b  up         rv",
      "b   p         rv",
      "bDK p         rv"
    ],
    [
      "     ll      cdv",
      "  Llj        ndv",
      "  LkfMMMMMMMMMfv",
      "  bbN         rv",
      "   lN         rv",
      "   lN  OP P   rv",
      "    N         rv",
      "    N         rv",
      "ll  N         rv",
      "l   f         iv",
      "l   N         rv",
      "    N         rv",
      " l  N  JQ RJ  rv",
      "j   N         rv",
      "    N         rv",
      "l   S         rv"
    ],
    [
      "             cdv",
      "             ndv",
      "   bfMMMMMMMMMfv",
      "   bN        Trv",
      "    N         rv",
      "    N         rv",
      "    N         rv",
      "    N         rv",
      "    N         rv",
      "    f         iv",
      "    N         rv",
      "    N    U    rv",
      "    N  RJJJQ  rv",
      "    N         rv",
      "    N         rv",
      "    N         rv"
    ],
    [
      "             cdv",
      "             ndv",
      "   bfMMMMMMMMMfv",
      "   tN         rv",
      "    N         rv",
      "    N         rv",
      "    N         rv",
      "    N         rv",
      "    N         rv",
      "    f         iv",
      "    N    V    rv",
      "    N   VWV   rv",
      "    N   WXW   rv",
      "    N   YYY   rv",
      "    N   YXY   rv",
      "    N   Y Y   rv"
    ],
    [
      "             cdv",
      "   L         ndv",
      " LbbfMMMMMMMMMfv",
      "   lN         rv",
      "    N         rv",
      "    N         rv",
      "    N         rv",
      "    N         rv",
      "    N    V    rv",
      "    f    W    iv",
      "    N   VZV   rv",
      "    N  0W1W2  rv",
      "    N   XWX   rv",
      "    N    Y    rv",
      "    N    X    rv",
      "    N    1    rv"
    ]
  ]
}