{
  "name": "multi_laboratory_13_base4",
  "refpalette": "deceasedcraft:multi_laboratory_13/multi_laboratory_13_base4_palette",
  "xsize": 16,
  "zsize": 16,
  "slices": [
    [
      "aaaaaaaaaaaaabcv",
      "aaaaaaaaaaaaabcv",
      "aaaadaaaaaaaabbv",
      "aaaaaaaaaaaaabbv",
      "aaaaaaaaaaaaabbv",
      "aaaaaaaaaaaaabbv",
      "aaaaaaaaaaaaabbv",
      "aaaaaaaaaaaaabbv",
      "aaaaaeeeeeeeebbv",
      "aaaadffffffffbbv",
      "aaaaafghhhhifbbv",
      "aaaaafhhhghgfbbv",
      "aaaaafghhhggfbbv",
      "aaaaafhghgggfbbv",
      "aaaaafhhhghgfbbv",
      "aaaaaffffffffbbv"
    ],
    [
      " j  k       lbcv",
      "  m no      pbcv",
      "q   drs     pbbv",
      " j  nt      pbbv",
      " uw nx y  wABbbv",
      " Cw nx      Bbbv",
      "y   nD     ABbbv",
      "    nx      Bbbv",
      "    n       Ebbv",
      "nnnnd@@@@@@@@bbv",
      "   Fnh I IJKgbbv",
      "    ngILIMIMhbbv",
      "    nhMILLMIgbbv",
      "NO  ngI IMI gbbv",
      "P   ngg gI ggbbv",
      "Q   nfgghhggfbbv"
    ],
    [
      "    k       Rbcv",
      "    no      pbcv",
      "    d!S     Tbbv",
      "    n       obbv",
      " U  V      AWbbv",
      "    V      AWbbv",
      "    V      A!bbv",
      "    V      AWbbv",
      "    n       Ebbv",
      "VVVnd@@@@@@@@bbv",
      "    nh      hbbv",
      "    Xh      gbbv",
      "    Xg      gbbv",
      "Y   Xg      hbbv",
      "Z   Xhg     gbbv",
      "    nfhihghgfbbv"
    ],
    [
      "    k        bcv",
      "    n       pbcv",
      "    dp       bbv",
      "    n        bbv",
      "    V        bbv",
      "    V        bbv",
      "    V        bbv",
      "    V        bbv",
      "    n        bbv",
      "VVVnd@@@@@@@@bbv",
      "    nh      ibbv",
      "    0i      hbbv",
      "    0h      hbbv",
      "    0h      gbbv",
      "    0g      hbbv",
      "    nfhhhhggfbbv"
    ],
    [
      "    n        bcv",
      "    n       pbcv",
      "    dp       bbv",
      "    n1       bbv",
      "    n2       bbv",
      "    n3       bbv",
      "    n4       bbv",
      "    n5       bbv",
      "    n6       bbv",
      "nnnnd@@@@@@@@bbv",
      "    ng      hbbv",
      "    nh      gbbv",
      "    ng      hbbv",
      "    nh      hbbv",
      "    nh      gbbv",
      "    nfhhihhhfbbv"
    ],
    [
      "77 78p9#99#9pbcv",
      "77778p9#99#9pbcv",
      "7777dp999999pbcv",
      "77778p999999pbcv",
      "77$78p9$99$9%bcv",
      "77$78p9#99#9%bcv",
      "77^78p9#99#9%bcv",
      "77^78p9#99#9%bcv",
      "77778p999999pbcv",
      "&&&&dp@@@@@@pbcv",
      "99998hhihhihhbcv",
      "99998hhhhihhhbcv",
      "99998hhhhhhhhbcv",
      "#*998hhhihhhhbcv",
      "9#998hiihhhhhbcv",
      "9#998fhhhhhhfbcv"
    ]
  ]
}