{
  "name": "multi_laboratory_13_top",
  "refpalette": "deceasedcraft:multi_laboratory_13/multi_laboratory_13_top_palette",
  "xsize": 16,
  "zsize": 16,
  "slices": [
    [
      "abzzcdde        ",
      "abzzcdde        ",
      "aabbcfge        ",
      "aaaacdde        ",
      "aaaacdde        ",
      "aaaacdde        ",
      "aaaacdde        ",
      "aaaacdde        ",
      "aaaacddh        ",
      "aaaacfgi        ",
      "aaaacddj        ",
      "aaaacddj        ",
      "aaaacddj        ",
      "aaaacddj        ",
      "aaaacddj        ",
      "aaaacddj        "
    ],
    [
      "  k l  m        ",
      " nool  i        ",
      "  nnp  i        ",
      "    l  i        ",
      "    l  i        ",
      "    l  i        ",
      "    l  m        ",
      "   ql  i        ",
      "   rl  i        ",
      "   st  j        ",
      "    l  j        ",
      "    l  j        ",
      "   ql  j        ",
      "   rl  j        ",
      "   sl  m        ",
      "    l  j        "
    ],
    [
      "       j        ",
      "       j        ",
      "       j        ",
      "       j        ",
      "       m        ",
      "       j        ",
      "       j        ",
      "       j        ",
      "   u   j        ",
      "    t  j        ",
      "       j        ",
      "       m        ",
      "       j        ",
      "       j        ",
      "       j        ",
      "       j        "
    ],
    [
      "       j        ",
      "       j        ",
      "       j        ",
      "       j        ",
      "       j        ",
      "       j        ",
      "       j        ",
      "       m        ",
      "       j        ",
      "    t  j        ",
      "       j        ",
      "       j        ",
      "       j        ",
      "       j        ",
      "       j        ",
      "       j        "
    ],
    [
      "       j        ",
      "       j        ",
      "       j        ",
      "       j        ",
      "       j        ",
      "       j        ",
      "       j        ",
      "       j        ",
      "       j        ",
      "    t  m        ",
      "       j        ",
      "       j        ",
      "       j        ",
      "       j        ",
      "       j        ",
      "       j        "
    ],
    [
      "       j        ",
      "       j        ",
      "       j        ",
      "g      j        ",
      "gg     j        ",
      " gg    j        ",
      "  g    j        ",
      "  gg   j        ",
      "   g   j        ",
      "   gc  j        ",
      "    g  j        ",
      "    g  j        ",
      "    g  j        ",
      "    g  j        ",
      "    g  j        ",
      "    g  j        "
    ],
    [
      "       w        ",
      "       w        ",
      "       w        ",
      "c      j        ",
      "cc     j        ",
      "xcc    j        ",
      "xxc    j        ",
      "xxcc   j        ",
      "xxxc   j        ",
      "xxxccfgj        ",
      "xxxxc  j        ",
      "xxxxc  j        ",
      "xxxxc  j        ",
      "xxxxc  j        ",
      "xxxxc  j        ",
      "xxxxc  j        "
    ],
    [
      "                ",
      "                ",
      "                ",
      "l               ",
      "tl              ",
      " ll             ",
      " yl    w        ",
      "  ll   w        ",
      "   l   w        ",
      "   lt  j        ",
      "    l  j        ",
      "   Al  j        ",
      "   Bl  j        ",
      "   Cl  j        ",
      "   yl  j        ",
      "    l  j        "
    ],
    [
      "                ",
      "                ",
      "                ",
      "                ",
      "                ",
      "                ",
      " !              ",
      "                ",
      "                ",
      "                ",
      "                ",
      "                ",
      "       w        ",
      "       w        ",
      "   D   w        ",
      "       j        "
    ]
  ]
}