{
  "name": "multi_laboratory_13_base1",
  "refpalette": "deceasedcraft:multi_laboratory_13/multi_laboratory_13_base1_palette",
  "xsize": 16,
  "zsize": 16,
  "slices": [
    [
      "aaaaaaaaaaaaabcv",
      "aaaaaaaaaaaaabcv",
      "aaaadaaaaaaaabcv",
      "eeeaaaaaaaaaabcv",
      "eeeaaaaaaaaaabcv",
      "eeeaaaaaaaaaabcv",
      "eeeaaaaaaaaaabcv",
      "eeeaaaaaaaaaabcv",
      "aaa!aaaaaaaaabcv",
      "aaaadaaaaaaaabcv",
      "aaaaaaaaaaaaabcv",
      "aaaaaaaaaaaaabcv",
      "aaaaaaaaaaaaabcv",
      "aaaaaaaaaaaaabcv",
      "aaaaaaaaaaaaabcv",
      "aaaaaaaaaaaaabcv"
    ],
    [
      "    fg hijk lbcv",
      "    fmmmijmmmbcv",
      "   ndoooooooobcv",
      "    o       pbcv",
      "   qo  r r  sbcv",
      "  t o  uwx  pbcv",
      " yA o  BCD  Ebcv",
      " t  o  F F  Ebcv",
      "   no   I   !bcv",
      "oooodooo oooobcv",
      "t   J   K   pbcv",
      "   LJ  M M  pbcv",
      "    J jNNNi sbcv",
      "    J       pbcv",
      "    J jOOOi sbcv",
      "    J  P    pbcv"
    ],
    [
      "    f        bcv",
      "    fQRS   TUbcv",
      "   Vdoooooooobcv",
      "    J       Wbcv",
      "    J        bcv",
      "    J    X   bcv",
      "    J   X    bcv",
      "    J        bcv",
      "   VJ Q Y   Zbcv",
      "000odooo oooobcv",
      "    J   1   2bcv",
      "    J        bcv",
      "    J    3   bcv",
      "    J        bcv",
      "    J       4bcv",
      "    J       5bcv"
    ],
    [
      "    f        bcv",
      "    f        bcv",
      "   6doooooooobcv",
      "    J        bcv",
      "    J        bcv",
      "    J        bcv",
      "    J        bcv",
      "    J        bcv",
      "   6J        bcv",
      "777odoooooooobcv",
      "    J        bcv",
      "    J       8bcv",
      "    J       8bcv",
      "    J        bcv",
      "    J        bcv",
      "    J        bcv"
    ],
    [
      "    f        bcv",
      "    f        bcv",
      "    doooooooobcv",
      "    J        bcv",
      "    J        bcv",
      "    J        bcv",
      "    J        bcv",
      "    J        bcv",
      "    J        bcv",
      "999odoooooooobcv",
      "    J        bcv",
      "    J        bcv",
      "    J       #bcv",
      "    J        bcv",
      "    J        bcv",
      "    J        bcv"
    ],
    [
      "$$$$%$^$$$$&$bcv",
      "$$$$%$$$$$$$$bcv",
      "$$$$doooooooobcv",
      "$$$$%$$$$$$$$bcv",
      "$$$$%$^$$$^$$bcv",
      "$$$$%$^$$$^$$bcv",
      "$$$$%$^$$$^$$bcv",
      "$$$$%$^$$$^$$bcv",
      "$$$$%$$$$$$$$bcv",
      "oooodoooooooobcv",
      "$$$$%$$$$$$$$bcv",
      "$$$$%$&$$$^$$bcv",
      "$$$$%$^$$$^$$bcv",
      "$$$$%$^$$$^$$bcv",
      "$$$$%$^$$$^$$bcv",
      "$$$$%$$$$$$$$bcv"
    ]
  ]
}