{
  "name": "building_factorya_top",
  "refpalette": "deceasedcraft:building_factorya/building_factorya_top_palette",
  "xsize": 16,
  "zsize": 16,
  "slices": [
    [
      "                ",
      "   abbbbbbbbbba ",
      "   cdddddddddde ",
      "   cd      ffde ",
      "   cd        ge ",
      "   cd        gh ",
      "   cd        gh ",
      "   cd        ge ",
      "   cd       ide ",
      "   cd       !gh ",
      "   cd        gh ",
      "   cd       jde ",
      "   cd        ge ",
      "   cdddddddddde ",
      "   akkkkkkkkkka ",
      "                "
    ],
    [
      "                ",
      "  llmm        a ",
      "  llnnnnnnnnnn  ",
      "  lldooo   ppn  ",
      "  lldooo   qrn  ",
      "  llds      tnh ",
      "  lldsuwxww tnh ",
      "  lldooo    tn  ",
      "  lldooo    yn  ",
      "  lldsuwAww tnh ",
      "  llds      tnh ",
      "  lldooo    Bn  ",
      "  lldooo     n  ",
      "  llCCnnnnnnnn  ",
      "  llmm        a ",
      "                "
    ],
    [
      "                ",
      "      llmm    a ",
      "      llCCnnnn  ",
      "        ooo  n  ",
      "        oooDDn  ",
      "      EEdddssnh ",
      "      EEdddDDnh ",
      "        ooo  n  ",
      "        ooo Fn  ",
      "      EEdddDDnh ",
      "      EEdddssnh ",
      "        oooDDn  ",
      "        oooo n  ",
      "      llCCnnnn  ",
      "      llmm    a ",
      "                "
    ],
    [
      "                ",
      "          llmma ",
      "          llCCe ",
      "           Edde ",
      "           Edde ",
      "           hhhh ",
      "           hhhh ",
      "           Edde ",
      "           Edde ",
      "           hhhh ",
      "           hhhh ",
      "           Edde ",
      "           Edde ",
      "          llCCe ",
      "          llmma ",
      "                "
    ],
    [
      "                ",
      "              ll",
      "              ll",
      "              ll",
      "              ll",
      "            IJll",
      "            Khll",
      "              ll",
      "              ll",
      "            IJll",
      "            Khll",
      "              ll",
      "              ll",
      "              ll",
      "              ll",
      "                "
    ]
  ]
}