{
  "name": "building_factorya_ground_270",
  "refpalette": "deceasedcraft:building_factorya/building_factorya_ground_palette_270",
  "xsize": 16,
  "zsize": 16,
  "slices": [
    [
      "zzzzzzzzzzz=zzzz",
      "zzzzz=z==z=zzzzz",
      "zzzzzz==z===zzzz",
      "zzzzzzz=====zzzz",
      "zzz==vvvv====zzz",
      "zzz==========zzz",
      "zzz==========zzz",
      "zzz==========zzz",
      "zzzaaaaaaaaaazzz",
      "zzz==========zzz",
      "zzz=======bbbzzz",
      "zzzbcb==c=bbbzzz",
      "zzzbdb====bbbzzz",
      "zzzzzzzzzzzzzzzz",
      "zzzzzzzzzzzzzzzz",
      "zzzzzzzzzzzzzzzz"
    ],
    [
      "                ",
      "e e         e e ",
      " ef ee        fe",
      "egfff e     efg ",
      " fhhottttohlhhff",
      "e h!y    pn ihf ",
      " fhy     q  ihfe",
      "efh          h  ",
      " fhA         he ",
      " ehCA    r  jh e",
      "ffhC     sk kh  ",
      " fhw w     m hf ",
      "  hDBxbbu k khff",
      "efhhhhhhhhhhhhfe",
      "eghhhgghhgghhhg ",
      " ff egg fggf  e "
    ],
    [
      "                ",
      "                ",
      "                ",
      " gff         fg ",
      "  hhottttohIhhf ",
      "  Ey     LK iEf ",
      "  E          E  ",
      " fE          E  ",
      " fh          h  ",
      "  hA       JFh  ",
      " fE      Mmmmh  ",
      "  EwRwO   m mh  ",
      "  ES QPN  mmmh  ",
      "  hhhhhhhhhhhhf ",
      " ghhhgghhgghhhg ",
      "     gg  gg     "
    ],
    [
      "                ",
      "                ",
      "                ",
      " g            g ",
      "  hhottttohThhf ",
      "  E          E  ",
      "  E          E  ",
      "  E          E  ",
      "  h          h  ",
      "  h          h  ",
      "  E    X Ummmh  ",
      "  Ew w s Vm mh  ",
      "  E Z  YWVmmmh  ",
      "  hhhhhhUUhhhh  ",
      " ghhhgghhgghhhg ",
      "     gg  gg     "
    ],
    [
      "                ",
      "                ",
      "                ",
      " g   4444     g ",
      "  hhoooooohhhh  ",
      "  0  5555    0  ",
      "  0          0  ",
      "  0          0  ",
      "  h          h  ",
      "  h          h  ",
      "  0    7  mmmh  ",
      "  *#^##8  m mh  ",
      "  *$&$ Y  mmmh  ",
      "  hhh%9963hhhh  ",
      " g111221122111g ",
      "     11  11     "
    ],
    [
      "                ",
      "                ",
      "                ",
      " g            g ",
      "  hh((((((hhhh  ",
      "  (          (  ",
      "  (          (  ",
      "  (          (  ",
      "  h          h  ",
      "  h          h  ",
      "  h       mmmh  ",
      "  h+++++  mmmh  ",
      "  h[-QbY) mmmh  ",
      "  hhhhhhhhhhhh  ",
      " g   22  22   g ",
      "                "
    ]
  ]
}