{
  "name": "building_factorya_ground",
  "refpalette": "deceasedcraft:building_factorya/building_factorya_ground_palette",
  "xsize": 16,
  "zsize": 16,
  "slices": [
    [
      "zzzzzzzzzzzzzzzz",
      "zzzzzzzzzzzzzzzz",
      "zzzzzzzzzzzzzzzz",
      "zzzz====a=bbbzzz",
      "=z======a=bbbzzz",
      "z=======a=bbbzzz",
      "zz======a====zzz",
      "z=z=v===a==c=zzz",
      "z===v===a====zzz",
      "zz=zv===a====zzz",
      "z=zzv===a==bbzzz",
      "zzzz====a==cdzzz",
      "zzzz====a==bbzzz",
      "zzzzzzzzzzzzzzzz",
      "zzzzzzzzzzzzzzzz",
      "zzzzzzzzzzzzzzzz"
    ],
    [
      "  e f e  e  fe  ",
      " efgfff e  fffge",
      "   fhhhhhhhhhhh ",
      " e ehii  jk khh ",
      "    l      m hhf",
      "    hn    k khgg",
      "    opq  rs  hgg",
      "    t       uhhf",
      "    t       bhh ",
      "   et       bhgg",
      "  e t      wxhgg",
      "  efoy   A  Bhhe",
      "   fh!y ACCwDhh ",
      " effhhhhhhhhhhhf",
      "  egf fffeff fgf",
      " e e e e  f  ee "
    ],
    [
      "                ",
      "   gff       fg ",
      "   fhEEEhhhhhhh ",
      "    hi   Fmmmhh ",
      "    I    Jm mhh ",
      "    hK    mmmhgg",
      "    oL    M  hgg",
      "    t        hh ",
      "    t       Nhh ",
      "    t      OPhgg",
      "    t      wQhgg",
      "    o      R hh ",
      "   fhy   A wShh ",
      "   fhEEEhhEEEhh ",
      "   g   ff f   g ",
      "                "
    ],
    [
      "                ",
      "   gf         g ",
      "    hEEEhhhhhhh ",
      "    h     mmmhh ",
      "    T     m mhh ",
      "    h     mmmhgg",
      "    o     UVVUgg",
      "    t       WUh ",
      "    t     XsYhh ",
      "    t        hgg",
      "    t      w hgg",
      "    o       Zhh ",
      "    h      w hh ",
      "    hEEEhhEEEhh ",
      "   g          g ",
      "                "
    ],
    [
      "                ",
      "   g          g ",
      "    h000hhhhhh1 ",
      "    h     mmmh1 ",
      "    h     m mh1 ",
      "    h     mmmh21",
      "    o        321",
      "   4o5       61 ",
      "   4o5    78Y91 ",
      "   4o5     # 921",
      "   4o5     #$%21",
      "    o      ^&h1 ",
      "    h      #$h1 ",
      "    h000hh0**h1 ",
      "   g          g ",
      "                "
    ],
    [
      "                ",
      "   g          g ",
      "    h(((hhhhhh  ",
      "    h     mmmh  ",
      "    h     mmmh  ",
      "    h     mmmh2 ",
      "    (        h2 ",
      "    (       )h  ",
      "    (      +Yh  ",
      "    (      +bh2 ",
      "    (      +Qh2 ",
      "    (      +-h  ",
      "    h      +[h  ",
      "    h(((hhhhhh  ",
      "   g          g ",
      "                "
    ]
  ]
}