{
  "name": "building_factorya_ground_90",
  "refpalette": "deceasedcraft:building_factorya/building_factorya_ground_palette_90",
  "xsize": 16,
  "zsize": 16,
  "slices": [
    [
      "zzzzzzzzzzzzzzzz",
      "zzzzzzzzzzzzzzzz",
      "zzzzzzzzzzzzzzzz",
      "zzzbbb====bdbzzz",
      "zzzbbb=c==bcbzzz",
      "zzzbbb=======zzz",
      "zzz==========zzz",
      "zzzaaaaaaaaaazzz",
      "zzz==========zzz",
      "zzz==========zzz",
      "zzz==========zzz",
      "zzz====vvvv==zzz",
      "zzzz=====zzzzzzz",
      "zzzz===z==zzzzzz",
      "zzzzz=z==z=zzzzz",
      "zzzz=zzzzzzzzzzz"
    ],
    [
      " e  fggf gge ff ",
      " ghhhgghhgghhhge",
      "efhhhhhhhhhhhhfe",
      "ffhk k ubbxBDh  ",
      " fh m     w whf ",
      "  hk ks     Chff",
      "e hj  r    AChe ",
      " eh         Ahf ",
      "  h          hfe",
      "efhi  q     yhf ",
      " fhi np    y!h e",
      "ffhhlhottttohhf ",
      " gfe     e fffge",
      "ef        ee fe ",
      " e e         e e",
      "                "
    ],
    [
      "     gg  gg     ",
      " ghhhgghhgghhhg ",
      " fhhhhhhhhhhhh  ",
      "  hmmm  NPQ SE  ",
      "  hm m   OwRwE  ",
      "  hmmmM      Ef ",
      "  hFJ       Ah  ",
      "  h          hf ",
      "  E          Ef ",
      "  E          E  ",
      " fEi KL     yE  ",
      " fhhIhottttohh  ",
      " gf         ffg ",
      "                ",
      "                ",
      "                "
    ],
    [
      "     gg  gg     ",
      " ghhhgghhgghhhg ",
      "  hhhhUUhhhhhh  ",
      "  hmmmVWY  Z E  ",
      "  hm mV s w wE  ",
      "  hmmmU X    E  ",
      "  h          h  ",
      "  h          h  ",
      "  E          E  ",
      "  E          E  ",
      "  E          E  ",
      " fhhThottttohh  ",
      " g            g ",
      "                ",
      "                ",
      "                "
    ],
    [
      "     11  11     ",
      " g111221122111g ",
      "  hhhh3699%hhh  ",
      "  hmmm  Y $&$*  ",
      "  hm m  8##^#*  ",
      "  hmmm  7    0  ",
      "  h          h  ",
      "  h          h  ",
      "  0          0  ",
      "  0          0  ",
      "  0    5555  0  ",
      "  hhhhoooooohh  ",
      " g     4444   g ",
      "                ",
      "                ",
      "                "
    ],
    [
      "                ",
      " g   22  22   g ",
      "  hhhhhhhhhhhh  ",
      "  hmmm )YbQ-[h  ",
      "  hmmm  +++++h  ",
      "  hmmm       h  ",
      "  h          h  ",
      "  h          h  ",
      "  (          (  ",
      "  (          (  ",
      "  (          (  ",
      "  hhhh((((((hh  ",
      " g            g ",
      "                ",
      "                ",
      "                "
    ]
  ]
}