{
  "name": "building_factorya_top_270",
  "refpalette": "deceasedcraft:building_factorya/building_factorya_top_palette_270",
  "xsize": 16,
  "zsize": 16,
  "slices": [
    [
      "                ",
      "                ",
      "                ",
      " acccccccccccca ",
      " kddddddddddddb ",
      " kd          db ",
      " kd          db ",
      " kd          db ",
      " kd          db ",
      " kd          db ",
      " kd          db ",
      " kd         fdb ",
      " kd j !i    fdb ",
      " kdgdggdggggddb ",
      " aeeehheehheeea ",
      "                "
    ],
    [
      "                ",
      "                ",
      " llllllllllllll ",
      " llllllllllllll ",
      " mCddddddddddnm ",
      " mCoossoossoonm ",
      "  noo uoou oon  ",
      "  noo woow oon  ",
      "  n   A  x   n  ",
      "  n   w  w   n  ",
      "  n   w  w   n  ",
      "  n        qpn  ",
      "  n Bttytttrpn  ",
      "  nnnnnnnnnnnn  ",
      " a   hh  hh   a ",
      "                "
    ],
    [
      "                ",
      "                ",
      "                ",
      "                ",
      "                ",
      "                ",
      " ll  EE  EE  ll ",
      " ll  EE  EE  ll ",
      " mCooddooddooCm ",
      " mCooddooddooCm ",
      "  nooddooddoon  ",
      "  noDsD  DsD n  ",
      "  n DsDF DsD n  ",
      "  nnnnnnnnnnnn  ",
      " a   hh  hh   a ",
      "                "
    ],
    [
      "                ",
      "                ",
      "                ",
      "                ",
      "                ",
      "                ",
      "                ",
      "                ",
      "                ",
      "                ",
      " ll          ll ",
      " llEEhhEEhhEEll ",
      " mCddhhddhhddCm ",
      " mCddhhddhhddCm ",
      " aeeehheehheeea ",
      "                "
    ],
    [
      "                ",
      "                ",
      "                ",
      "                ",
      "                ",
      "                ",
      "                ",
      "                ",
      "                ",
      "                ",
      "                ",
      "                ",
      "     KI  KI     ",
      "     hJ  hJ     ",
      " llllllllllllll ",
      " llllllllllllll "
    ]
  ]
}