{
  "name": "building_factorya_top_180",
  "refpalette": "deceasedcraft:building_factorya/building_factorya_top_palette_180",
  "xsize": 16,
  "zsize": 16,
  "slices": [
    [
      "                ",
      " akkkkkkkkkka   ",
      " eddddddddddc   ",
      " eg        dc   ",
      " edj       dc   ",
      " hg        dc   ",
      " hg!       dc   ",
      " edi       dc   ",
      " eg        dc   ",
      " hg        dc   ",
      " hg        dc   ",
      " eg        dc   ",
      " edff      dc   ",
      " eddddddddddc   ",
      " abbbbbbbbbba   ",
      "                "
    ],
    [
      "                ",
      " a        mmll  ",
      "  nnnnnnnnCCll  ",
      "  n     ooodll  ",
      "  nB    ooodll  ",
      " hnt      sdll  ",
      " hnt wwAwusdll  ",
      "  ny    ooodll  ",
      "  nt    ooodll  ",
      " hnt wwxwusdll  ",
      " hnt      sdll  ",
      "  nrq   ooodll  ",
      "  npp   ooodll  ",
      "  nnnnnnnnnnll  ",
      " a        mmll  ",
      "                "
    ],
    [
      "                ",
      " a    mmll      ",
      "  nnnnCCll      ",
      "  n oooo        ",
      "  nDDooo        ",
      " hnssdddEE      ",
      " hnDDdddEE      ",
      "  nF ooo        ",
      "  n  ooo        ",
      " hnDDdddEE      ",
      " hnssdddEE      ",
      "  nDDooo        ",
      "  n  ooo        ",
      "  nnnnCCll      ",
      " a    mmll      ",
      "                "
    ],
    [
      "                ",
      " ammll          ",
      " eCCll          ",
      " eddE           ",
      " eddE           ",
      " hhhh           ",
      " hhhh           ",
      " eddE           ",
      " eddE           ",
      " hhhh           ",
      " hhhh           ",
      " eddE           ",
      " eddE           ",
      " eCCll          ",
      " ammll          ",
      "                "
    ],
    [
      "                ",
      "ll              ",
      "ll              ",
      "ll              ",
      "ll              ",
      "llhK            ",
      "llJI            ",
      "ll              ",
      "ll              ",
      "llhK            ",
      "llJI            ",
      "ll              ",
      "ll              ",
      "ll              ",
      "ll              ",
      "                "
    ]
  ]
}