{
  "name": "building_factorya_ground_180",
  "refpalette": "deceasedcraft:building_factorya/building_factorya_ground_palette_180",
  "xsize": 16,
  "zsize": 16,
  "slices": [
    [
      "zzzzzzzzzzzzzzzz",
      "zzzzzzzzzzzzzzzz",
      "zzzzzzzzzzzzzzzz",
      "zzzbb==a====zzzz",
      "zzzdc==a====zzzz",
      "zzzbb==a===vzz=z",
      "zzz====a===vz=zz",
      "zzz====a===v===z",
      "zzz=c==a===v=z=z",
      "zzz====a======zz",
      "zzzbbb=a=======z",
      "zzzbbb=a======z=",
      "zzzbbb=a====zzzz",
      "zzzzzzzzzzzzzzzz",
      "zzzzzzzzzzzzzzzz",
      "zzzzzzzzzzzzzzzz"
    ],
    [
      " ee  f  e e e e ",
      "fgf ffefff fge  ",
      "fhhhhhhhhhhhffe ",
      " hhDwCCA y!hf   ",
      "ehhB  A   yofe  ",
      "gghxw      t e  ",
      "gghb       te   ",
      " hhb       t    ",
      "fhhu       t    ",
      "ggh  sr  qpo    ",
      "gghk k    nh    ",
      "fhh m      l    ",
      " hhk kj  iihe e ",
      " hhhhhhhhhhhf   ",
      "egfff  e fffgfe ",
      "  ef  e  e f e  "
    ],
    [
      "                ",
      " g   f ff   g   ",
      " hhEEEhhEEEhf   ",
      " hhSw A   yhf   ",
      " hh R      o    ",
      "gghQw      t    ",
      "gghPO      t    ",
      " hhN       t    ",
      " hh        t    ",
      "ggh  M    Lo    ",
      "gghmmm    Kh    ",
      " hhm mJ    I    ",
      " hhmmmF   ih    ",
      " hhhhhhhEEEhf   ",
      " gf       ffg   ",
      "                "
    ],
    [
      "                ",
      " g          g   ",
      " hhEEEhhEEEh    ",
      " hh w      h    ",
      " hhZ       o    ",
      "ggh w      t    ",
      "ggh        t    ",
      " hhYsX     t    ",
      " hUW       t    ",
      "ggUVVU     o    ",
      "gghmmm     h    ",
      " hhm m     T    ",
      " hhmmm     h    ",
      " hhhhhhhEEEh    ",
      " g         fg   ",
      "                "
    ],
    [
      "                ",
      " g          g   ",
      " 1h**0hh000h    ",
      " 1h$#      h    ",
      " 1h&^      o    ",
      "12%$#     5o4   ",
      "129 #     5o4   ",
      " 19Y87    5o4   ",
      " 16       5o4   ",
      "123        o    ",
      "12hmmm     h    ",
      " 1hm m     h    ",
      " 1hmmm     h    ",
      " 1hhhhhh000h    ",
      " g          g   ",
      "                "
    ],
    [
      "                ",
      " g          g   ",
      "  hhhhhh(((h    ",
      "  h[+      h    ",
      "  h-+      (    ",
      " 2hQ+      (    ",
      " 2hb+      (    ",
      "  hY+      (    ",
      "  h)       (    ",
      " 2h        (    ",
      " 2hmmm     h    ",
      "  hmmm     h    ",
      "  hmmm     h    ",
      "  hhhhhh(((h    ",
      " g          g   ",
      "                "
    ]
  ]
}