{
  "name": "building_factorya_top_90",
  "refpalette": "deceasedcraft:building_factorya/building_factorya_top_palette_90",
  "xsize": 16,
  "zsize": 16,
  "slices": [
    [
      "                ",
      " aeeehheehheeea ",
      " bddggggdggdgdk ",
      " bdf    i! j dk ",
      " bdf         dk ",
      " bd          dk ",
      " bd          dk ",
      " bd          dk ",
      " bd          dk ",
      " bd          dk ",
      " bd          dk ",
      " bddddddddddddk ",
      " acccccccccccca ",
      "                ",
      "                ",
      "                "
    ],
    [
      "                ",
      " a   hh  hh   a ",
      "  nnnnnnnnnnnn  ",
      "  nprtttyttB n  ",
      "  npq        n  ",
      "  n   w  w   n  ",
      "  n   w  w   n  ",
      "  n   x  A   n  ",
      "  noo woow oon  ",
      "  noo uoou oon  ",
      " mnoossoossooCm ",
      " mnddddddddddCm ",
      " llllllllllllll ",
      " llllllllllllll ",
      "                ",
      "                "
    ],
    [
      "                ",
      " a   hh  hh   a ",
      "  nnnnnnnnnnnn  ",
      "  n DsD FDsD n  ",
      "  n DsD  DsDon  ",
      "  nooddooddoon  ",
      " mCooddooddooCm ",
      " mCooddooddooCm ",
      " ll  EE  EE  ll ",
      " ll  EE  EE  ll ",
      "                ",
      "                ",
      "                ",
      "                ",
      "                ",
      "                "
    ],
    [
      "                ",
      " aeeehheehheeea ",
      " mCddhhddhhddCm ",
      " mCddhhddhhddCm ",
      " llEEhhEEhhEEll ",
      " ll          ll ",
      "                ",
      "                ",
      "                ",
      "                ",
      "                ",
      "                ",
      "                ",
      "                ",
      "                ",
      "                "
    ],
    [
      " llllllllllllll ",
      " llllllllllllll ",
      "     Jh  Jh     ",
      "     IK  IK     ",
      "                ",
      "                ",
      "                ",
      "                ",
      "                ",
      "                ",
      "                ",
      "                ",
      "                ",
      "                ",
      "                ",
      "                "
    ]
  ]
}