{
  "name": "multi_pumpjack_1_top",
  "refpalette": "deceasedcraft:multi_pumpjack_1/multi_pumpjack_1_top_palette",
  "xsize": 16,
  "zsize": 16,
  "slices": [
    [
      "  abcdefgb    hb",
      "  abiiiiiiiiiiii",
      "   ij    j    ji",
      "   ik    k    ki",
      "   il    m    mi",
      "   im    m    mi",
      "   ik    k    ki",
      "   ij    j    ji",
      "   ij    j    ji",
      "   innnnnnnnnnni",
      "   ibbbbbbbbbbbi",
      "   opppppppppppo",
      "   ooooooooooooo",
      "                ",
      "                ",
      "                "
    ],
    [
      "  abqrs tb    hb",
      "  abiiiiiiiiiiii",
      "   iuuwuuuuuwuui",
      "   iu    r    ui",
      "   iu         ui",
      "   iunnnnnnnnnux",
      "   iunnnnnnnnnux",
      "   opppppppppppo",
      "   opppppppppppo",
      "                ",
      "                ",
      "                ",
      "                ",
      "                ",
      "                ",
      "                "
    ],
    [
      "  abyAAAAbuuuuhb",
      "  abbbbbbbbbbbib",
      "   iiiiiiiiiiiii",
      "   opppppppppppo",
      "   opppppppppppo",
      "    u         u ",
      "    w         w ",
      "                ",
      "         ~      ",
      "                ",
      "                ",
      "                ",
      "                ",
      "                ",
      "                ",
      "                "
    ],
    [
      "  aaBBBBBabbbbCb",
      "  aaaaaaaaaaaaaa",
      "                ",
      "                ",
      "                ",
      "    D         D ",
      "                ",
      "                ",
      "         ~      ",
      "                ",
      "                ",
      "                ",
      "                ",
      "                ",
      "                ",
      "                "
    ],
    [
      " ooaaaaaaa      ",
      " ooooooooooooooo",
      " ooooooooooooooo",
      "                ",
      "                ",
      "                ",
      "                ",
      "                ",
      "         ~      ",
      "                ",
      "                ",
      "                ",
      "                ",
      "                ",
      "                ",
      "                "
    ],
    [
      "                ",
      "                ",
      "                ",
      "                ",
      "                ",
      "                ",
      "                ",
      "                ",
      "         ~      ",
      "                ",
      "                ",
      "                ",
      "                ",
      "                ",
      "                ",
      "                "
    ],
    [
      "                ",
      "                ",
      "                ",
      "                ",
      "                ",
      "                ",
      "                ",
      "                ",
      "         ~      ",
      "                ",
      "                ",
      "                ",
      "                ",
      "                ",
      "                ",
      "                "
    ],
    [
      "                ",
      "                ",
      "                ",
      "                ",
      "                ",
      "                ",
      "                ",
      "                ",
      "         ~      ",
      "                ",
      "                ",
      "                ",
      "                ",
      "                ",
      "                ",
      "                "
    ],
    [
      "                ",
      "                ",
      "                ",
      "                ",
      "                ",
      "                ",
      "                ",
      "                ",
      "         ~      ",
      "                ",
      "                ",
      "                ",
      "                ",
      "                ",
      "                ",
      "                "
    ],
    [
      "                ",
      "                ",
      "                ",
      "                ",
      "                ",
      "                ",
      "                ",
      "                ",
      "         ~      ",
      "                ",
      "                ",
      "                ",
      "                ",
      "                ",
      "                ",
      "                "
    ]
  ]
}