{
  "name": "multi_pumpjack_1_ground",
  "refpalette": "deceasedcraft:multi_pumpjack_1/multi_pumpjack_1_ground_palette",
  "xsize": 16,
  "zsize": 16,
  "slices": [
    [
      "zzzzzzzzzzzzzzzz",
      "zzzzzzzzzzzzzzzz",
      "zzzzaaaaaaaaaaaz",
      "zzzzaaaaaaaaaaaz",
      "zzzzabcccccccbbz",
      "zzzzabbaabbabbaz",
      "zzzzbbbaaaaaabaz",
      "zzzzbbaaaaaaabaz",
      "zzzzabbbbaaaabbz",
      "zzzzaaabbbaabbbz",
      "zzzzzddddzddddzz",
      "zezzzeeeezeeeezz",
      "zzezeeezeezezeze",
      "zeeezeeeeeeeezee",
      "zzzzzeezzezezezz",
      "zzzzzzzezzzzzzzz"
    ],
    [
      "  fghhhhhhiiiiig",
      " jfggggggggggggg",
      "   giiiiiiiiiiig",
      "   gkkiiiiiiikkg",
      "   gl          g",
      "j  gm         ng",
      "   g          og",
      " j gp         qg",
      "   gn         rg",
      "   g!ostu    wxg",
      " jjfyAAAAy    yf",
      "               j",
      "          j     ",
      "                ",
      "    j   j       ",
      "               j"
    ],
    [
      "  fg     g    Bg",
      "  fgyggggygCDgyy",
      "   g   EFEE    g",
      "   g           g",
      "   I           I",
      "   I          pI",
      "   I           I",
      "   I           I",
      "   I          Jg",
      "   gK   L     Mg",
      "   fyAAAAy    yf",
      "                ",
      "                ",
      "                ",
      "                ",
      "                "
    ],
    [
      "  fg     g     g",
      "  fgygNNgygOPgyy",
      "   g           g",
      "   g           g",
      "   I           I",
      "   I           I",
      "   I           I",
      "   I           I",
      "   I           g",
      "   g           g",
      "   fyAAAAyAAAAyf",
      "                ",
      "                ",
      "                ",
      "                ",
      "                "
    ],
    [
      "  fg  Q  g     g",
      "  fgygRRgyggggyy",
      "   g           g",
      "   g           g",
      "   R           R",
      "   R           R",
      "   R           R",
      "   R           R",
      "   R           g",
      "   g           g",
      "   fyyyyyyyyyyyf",
      "     SSSS SSSS  ",
      "                ",
      "                ",
      "                ",
      "                "
    ],
    [
      "  fgTTTTTgUUUUUg",
      "  fgyggggyggggyy",
      "   g           g",
      "   g           g",
      "   g           g",
      "   g           g",
      "   g           g",
      "   g           g",
      "   g           g",
      "   g           g",
      "   fgVVVVgVVVVgf",
      "                ",
      "                ",
      "                ",
      "                ",
      "                "
    ]
  ]
}