{
  "name": "multi_nuclearpowerplant_23_base12",
  "refpalette": "deceasedcraft:multi_nuclearpowerplant_23/multi_nuclearpowerplant_23_base12_palette",
  "xsize": 16,
  "zsize": 16,
  "slices": [
    [
      "aaaaaaaaaaaaaaaa",
      "aaaaaaaaaaaaaaaa",
      "aaaaaaaaaaaaaaaa",
      "aaaaaaaaaaaaaaaa",
      "aaaaaaaaaaaaaaaa",
      "aaaaaaaaaaaaaaaa",
      "aaaaaaaaaaaaaaaa",
      "aaaaaaaaaaaaaaaa",
      "aaaaaaaaaaaaaaaa",
      "aaaaaaaaaaaaaaaa",
      "aaaaaaaaaaaaaaaa",
      "aaaaaaaaaaaaaaaa",
      "aaaaaaaaaaaaaaaa",
      "aaaaaaaaaaaaaaaa",
      "aaaaaaaaaaaaaaaa",
      "aaaaaaaaaaaaaaaa"
    ],
    [
      "bbbbbbbbbbbbbbbb",
      "bbbbbbbbbbbbbbbb",
      "bbbbbbbbbbbbbbbb",
      "bbbbbbbbbbbbbbbb",
      "bbbbbbbbbbbbbbbb",
      "bbbbbbbbbbbbbbbb",
      "bbbbbbbbbbbbbbbb",
      "bbbbbbbbbbbbbbbb",
      "bbbbbbbbbbbbbbbb",
      "bbbbbbbbbbbbbbbb",
      "bbbbbbbbbbbbbbbb",
      "bbbbbbbbbbbbbbbb",
      "bbbbbbbbbbbbbbbb",
      "bbbbbbbbbbbbbbbb",
      "bbbbbbbbbbbbbbbb",
      "bbbbbbbbbbbbbbbb"
    ],
    [
      "cccccccccccccccc",
      "cccccccccccccccc",
      "cccccccccccccccc",
      "cccccccccccccccc",
      "cccccccccccccccc",
      "cccccccccccccccc",
      "cccccccccccccccc",
      "cccccccccccccccc",
      "cccccccccccccccc",
      "cccccccccccccccc",
      "cccccccccccccccc",
      "cccccccccccccccc",
      "cccccccccccccccc",
      "cccccccccccccccc",
      "cccccccccccccccc",
      "cccccccccccccccc"
    ],
    [
      "              de",
      "fg   hfidfg    j",
      "      k         ",
      "                ",
      "                ",
      "fllllllffm      ",
      "nnnnnnnoop      ",
      "ooooooooop      ",
      "nnnnnnnnop      ",
      "fqqqqqqffr      ",
      "                ",
      "                ",
      "                ",
      "fg   hfidfg     ",
      "                ",
      "                "
    ],
    [
      "             des",
      "f     ffff    j ",
      "       ff       ",
      "       ff       ",
      "       ff       ",
      "fi    dff       ",
      "ttu             ",
      "wxy             ",
      " Au             ",
      "fi    dff       ",
      "       ff       ",
      "       ff       ",
      "       ff       ",
      "fi   dffff      ",
      "                ",
      "                "
    ],
    [
      "            des ",
      "f     f  f   j  ",
      "         f      ",
      "         f      ",
      "         f      ",
      "ffffffffff      ",
      "BBB      f      ",
      "CCB      f      ",
      "BBB      f      ",
      "ffffffffff      ",
      "         f      ",
      "         f      ",
      "DEEEEE   f      ",
      "fffffff  f      ",
      "FEEEEE          ",
      "                "
    ]
  ]
}