{
  "name": "multi_nuclearpowerplant_23_base7",
  "refpalette": "deceasedcraft:multi_nuclearpowerplant_23/multi_nuclearpowerplant_23_base7_palette",
  "xsize": 16,
  "zsize": 16,
  "slices": [
    [
      "                ",
      "                ",
      "                ",
      "                ",
      "                ",
      "                ",
      "a               ",
      "baa             ",
      "bbba            ",
      "ccbba           ",
      "cccbba          ",
      "ccccbba         ",
      "cccccbba        ",
      "ccccccbba       ",
      "cccccccba       ",
      "cccccccbba      "
    ],
    [
      "                ",
      "                ",
      "                ",
      "                ",
      "                ",
      "                ",
      "a               ",
      "baa             ",
      "bbba            ",
      "ccbba           ",
      "cccbba          ",
      "ccccbba         ",
      "cccccbba        ",
      "ccccccbba       ",
      "cccccccba       ",
      "cccccccbba      "
    ],
    [
      "                ",
      "                ",
      "                ",
      "                ",
      "                ",
      "                ",
      "a               ",
      "baa             ",
      "bbd             ",
      "ccdd            ",
      "cccdd           ",
      "ccccdd          ",
      "cccccdd         ",
      "ccccccdda       ",
      "cccccccba       ",
      "cccccccbba      "
    ],
    [
      "                ",
      "                ",
      "                ",
      "                ",
      "                ",
      "                ",
      "a               ",
      "baa             ",
      "bbd             ",
      "ccdd            ",
      "cccdd           ",
      "ccccdd          ",
      "cccccdd         ",
      "ccccccdda       ",
      "cccccccba       ",
      "cccccccbba      "
    ],
    [
      "                ",
      "                ",
      "                ",
      "                ",
      "                ",
      "                ",
      "a               ",
      "baa             ",
      "bbba            ",
      "ccbba           ",
      "cccbba          ",
      "ccccbba         ",
      "cccccbba        ",
      "ccccccbba       ",
      "cccccccba       ",
      "cccccccbba      "
    ],
    [
      "eeeeeeeeeeeeeeee",
      "eeeeeeeeeeeeeeee",
      "eeeeeeeeeeeeeeee",
      "eeeeeeeeeeeeeeee",
      "eeeeeeeeeeeeeeee",
      "ffeeeeeeeeeeeeee",
      " fffeeeeeeeeeeee",
      "b  gfeeeeeeeeeee",
      "bbb ffeeeeeeeeee",
      "  bb ffeeeeeeeee",
      "   bb ffeeeeeeee",
      "    bb ffeeeeeee",
      "     bb gfeeeeee",
      "      bb feeeeee",
      "       b ffeeeee",
      "       bb feeeee"
    ]
  ]
}