{
  "name": "multi_nuclearpowerplant_23_base8",
  "refpalette": "deceasedcraft:multi_nuclearpowerplant_23/multi_nuclearpowerplant_23_base8_palette",
  "xsize": 16,
  "zsize": 16,
  "slices": [
    [
      "aaaaaaaaaaaaaaaa",
      "aaaaaaaaaaaaaaaa",
      "aaaaaaaaaaaaaaaa",
      "aaaaaaaaaaaaaaaa",
      "aaaaaaaaaaaaaaaa",
      "baaaaaaaaaaaaaaa",
      "cbbaaaaaaaaaaaaa",
      "=ccbaaaaaaaaaaaa",
      "===cbaaaaaaaaaaa",
      "d===cbaaaaaaaaaa",
      " dd==cbaaaaaaaaa",
      "eeed==cbaaaaaaaa",
      "    d==cbaaaaaaa",
      "    fd==cbaaaaaa",
      "    fd==cbaaaaaa",
      "    f d==cbaaaaa"
    ],
    [
      "================",
      "================",
      "================",
      "================",
      "================",
      "================",
      "g===============",
      "dgg=============",
      "dddg============",
      "hhddg===========",
      "hhhddg==========",
      "hhhhddg=========",
      "hhhhhddg========",
      "hhhhhhddg=======",
      "hhhhhhhdg=======",
      "hhhhhhhddg======"
    ],
    [
      "iiiiiiiiiiiiiiii",
      "iiiiiiiiiiiiiiii",
      "iiiiiiiiiiiiiiii",
      "iiiiiiiiiiiiiiii",
      "iiiiiiiiiiiiiiii",
      "iiiiiiiiiiiiiiii",
      "jiiiiiiiiiiiiiii",
      "djjiiiiiiiiiiiii",
      "dddjiiiiiiiiiiii",
      "kkddjiiiiiiiiiii",
      "kkkddjiiiiiiiiii",
      "kkkkddjiiiiiiiii",
      "kkkkkddjiiiiiiii",
      "kkkkkkddjiiiiiii",
      "kkkkkkkdjiiiiiii",
      "kkkkkkkddjiiiiii"
    ],
    [
      "iiiiiiiiiiiiiiii",
      "iiiiiiiiiiiiiiii",
      "iiiiiiiiiiiiiiii",
      "iiiiiiiiiiiiiiii",
      "iiiiiiiiiiiiiiii",
      "iiiiiiiiiiiiiiii",
      "jiiiiiiiiiiiiiii",
      "djjiiiiiiiiiiiii",
      "dddjiiiiiiiiiiii",
      "kkddjiiiiiiiiiii",
      "kkkddjiiiiiiiiii",
      "kkkkddjiiiiiiiii",
      "kkkkkddjiiiiiiii",
      "kkkkkkddjiiiiiii",
      "kkkkkkkdjiiiiiii",
      "kkkkkkkddjiiiiii"
    ],
    [
      "llllllllllllllll",
      "llllllllllllllll",
      "llllllllllllllll",
      "llllllllllllllll",
      "llllllllllllllll",
      "mmllllllllllllll",
      "gmmmllllllllllll",
      "dggmmlllllllllll",
      "dddgmmllllllllll",
      "kkddgmmlllllllll",
      "kkkddgmmllllllll",
      "kkkkddgmmlllllll",
      "kkkkkddgmmllllll",
      "kkkkkkddgmllllll",
      "kkkkkkkdgmmlllll",
      "kkkkkkkddgmlllll"
    ],
    [
      "                ",
      "                ",
      "                ",
      "                ",
      "                ",
      "                ",
      "j               ",
      "djj             ",
      "dddj            ",
      "kkddj           ",
      "kkkddj          ",
      "kkkkddj         ",
      "kkkkkddj        ",
      "kkkkkkddj       ",
      "kkkkkkkdj       ",
      "kkkkkkkddj      "
    ]
  ]
}