{
  "name": "multi_nuclearpowerplant_23_base11",
  "refpalette": "deceasedcraft:multi_nuclearpowerplant_23/multi_nuclearpowerplant_23_base11_palette",
  "xsize": 16,
  "zsize": 16,
  "slices": [
    [
      "           abc  ",
      "d     d  d  e   ",
      "                ",
      "                ",
      "                ",
      "fff             ",
      "gg              ",
      "hhi             ",
      "                ",
      "fff             ",
      "                ",
      "                ",
      "jjjjjj          ",
      "jjjjjjd  d      ",
      "jjjjjj          ",
      "                "
    ],
    [
      "          abc   ",
      "dk    d  d e    ",
      "                ",
      "                ",
      "                ",
      "ll              ",
      "mm              ",
      "nn              ",
      "                ",
      "                ",
      "                ",
      "                ",
      "oooo            ",
      "oooo  d  d      ",
      "oooo            ",
      "                "
    ],
    [
      "          bc    ",
      "ddddddd  de     ",
      "                ",
      "                ",
      "ll              ",
      "mm              ",
      "pp              ",
      "                ",
      "                ",
      "                ",
      "                ",
      "                ",
      "                ",
      "      d  d      ",
      "                ",
      "                "
    ],
    [
      "q        bc     ",
      "d     dkad      ",
      "                ",
      "ll              ",
      "mm              ",
      "pp              ",
      "                ",
      "                ",
      "                ",
      "                ",
      "                ",
      "                ",
      "                ",
      "r     dkad      ",
      "                ",
      "                "
    ],
    [
      "sssssssss       ",
      "dtuuuwdssd      ",
      "xx    yssA      ",
      " B    CssA      ",
      "pp    CssA      ",
      "      CssA      ",
      "      CssA      ",
      "      CssA      ",
      "      CssA      ",
      "      CssA      ",
      "      CssA      ",
      "      CssA      ",
      "      DssA      ",
      "      dEEd      ",
      "       EE       ",
      "       EE       "
    ],
    [
      "                ",
      "dtuuuwd  d      ",
      "      y  F      ",
      "hh    C  F      ",
      "II    C  F      ",
      "      C  F      ",
      "      C  F      ",
      "      C  F      ",
      "      C  F      ",
      "      C  F      ",
      "      C  F      ",
      "      C  F      ",
      "      D  F      ",
      " r    d  d      ",
      "      J  J      ",
      "      J  J      "
    ]
  ]
}