{
  "name": "multi_nuclearpowerplant_23_base6",
  "refpalette": "deceasedcraft:multi_nuclearpowerplant_23/multi_nuclearpowerplant_23_base6_palette",
  "xsize": 16,
  "zsize": 16,
  "slices": [
    [
      "aaaaaaaaaaaaaaaa",
      "aaaaaaaaaaaaaaaa",
      "aaaaaaaaaaaaaaaa",
      "aaaaaaaaaaaaaaaa",
      "aaaaaaaaaaaaaaaa",
      "bbaaaaaaaaaaaaaa",
      "cbbbaaaaaaaaaaaa",
      " ccbbaaaaaaaaaaa",
      "   cbbaaaaaaaaaa",
      "    cbbaaaaaaaaa",
      "     cbbaaaaaaaa",
      "      cbbaaaaaaa",
      "       cbbaaaaaa",
      "        cbaaaaaa",
      "        cbbaaaaa",
      "         cbaaaaa"
    ],
    [
      "                ",
      "                ",
      "                ",
      "               d",
      "                ",
      "                ",
      "e               ",
      "fee             ",
      "fffe            ",
      "  ffe           ",
      "   ffe          ",
      "    ffe         ",
      "     ffe        ",
      "      ffe       ",
      "       fe       ",
      "       ffe      "
    ],
    [
      "                ",
      "                ",
      "                ",
      "                ",
      "                ",
      "                ",
      "                ",
      "=               ",
      "===             ",
      "  ==            ",
      "   ==           ",
      "    ==          ",
      "     ==         ",
      "      ==        ",
      "       =        ",
      "       ==       "
    ],
    [
      "                ",
      "                ",
      "                ",
      "                ",
      "                ",
      "                ",
      "                ",
      "                ",
      "                ",
      "                ",
      "    =           ",
      "     =          ",
      "                ",
      "                ",
      "                ",
      "                "
    ],
    [
      "                ",
      "                ",
      "                ",
      "                ",
      "                ",
      "                ",
      "                ",
      "                ",
      "                ",
      "                ",
      "   gh           ",
      "     i          ",
      "     j          ",
      "                ",
      "                ",
      "                "
    ],
    [
      "                ",
      "                ",
      "                ",
      "                ",
      "                ",
      "                ",
      "                ",
      "                ",
      "                ",
      "                ",
      "   =            ",
      "                ",
      "     =          ",
      "                ",
      "                ",
      "                "
    ]
  ]
}