{
  "name": "multi_courtyardofficetower_2_base1",
  "refpalette": "deceasedcraft:multi_courtyardofficetower_2/multi_courtyardofficetower_2_base1_palette",
  "xsize": 16,
  "zsize": 16,
  "slices": [
    [
      "vvvvvvvvvvvvaaaa",
      "vvvvvvvvvvvvaaaa",
      "vvvvvvvvvvvvaaaa",
      "vvvvvvvvbbbbaaaa",
      "vvvvvvvvvvvvaaaa",
      "vvvvvvvvvvvvaaaa",
      "vvvvvvvvvvvvaaaa",
      "vvvvvvvvvvvvaaaa",
      "vvvvvvvvvvvvaaaa",
      "vvvvvvvvvvvvaaaa",
      "vvvvvvvvvvvvaaaa",
      "vvvvvvvvbbbbvaaa",
      "vvvvvvvvvvvbvaaa",
      "vvvvvvvvvvvbvaaa",
      "vvvvvvvvvvvbvaaa",
      "vvvvvvvvvvvvvvvv"
    ],
    [
      "vcHHHHccccccdeee",
      "vcHHHHccccccdeee",
      "vcHHHHccccccdeee",
      "vcHHHHccbbbbdeee",
      "vcHHHHccccccdeee",
      "vcHHHHccccccdeee",
      "vcHHHHccccccdeee",
      "vcHHHHccccccdddd",
      "vcHHHHccccccdfff",
      "vcHHHHccccccdfff",
      "vcHHHHccccccdddd",
      "vcHHHHccbbbbvaaa",
      "vcHHHHcvaaabvaaa",
      "vcHHHHccvaabvaaa",
      "vcHHHHHccvabvaaa",
      "vcHHHHHHccvvvvvv"
    ],
    [
      "v      g  hijeee",
      "v          ijeee",
      "v      k  lijeee",
      "v       bbbbjeee",
      "v      g  hijeee",
      "v        m ijeee",
      "v      k  lijeee",
      "v          ijjjj",
      "v               ",
      "v               ",
      "v          ijjjj",
      "v       bbbbvaaa",
      "v      vaaabvaaa",
      "v       vaabvaaa",
      "v        vabvaaa",
      "v         vvvvvv"
    ],
    [
      "v           jeee",
      "v           jeee",
      "v           jeee",
      "v       bbbbjeee",
      "v           jeee",
      "v           jeee",
      "v           jeee",
      "v           jjjj",
      "v               ",
      "v               ",
      "v           jjjj",
      "v       bbbbvaaa",
      "v      vaaabvaaa",
      "v       vaabvaaa",
      "v        vabvaaa",
      "v         vvvvvv"
    ],
    [
      "v           jeee",
      "v           jeee",
      "v           jeee",
      "v       bbbbjeee",
      "v           jeee",
      "v           jeee",
      "v           jeee",
      "v           jjjj",
      "v               ",
      "v               ",
      "v           jjjj",
      "v       bbbbvaaa",
      "v      vaaabvaaa",
      "v       vaabvaaa",
      "v        vabvaaa",
      "v         vvvvvv"
    ],
    [
      "vnnnnnnnnnnnjeee",
      "vnnnnnnnnnnnjeee",
      "vnnnnnnnnnnnjeee",
      "vnnnnnnobbbbjeee",
      "vnnnnnnnnnnnjeee",
      "vnnnnnnnnnnnjeee",
      "vnnnnnnnnnnnjeee",
      "vnnnnnnnnnnnjjjj",
      "vnnnnnnnnnnnjnnn",
      "vnnnnnnnnnnnjnnn",
      "vnnnnnnnnnnnjjjj",
      "vnnnnnnobbbbvaaa",
      "vnnnnnnvaaabvaaa",
      "vnnnnnnnvaabvaaa",
      "vnnnnnnnnvabvaaa",
      "vnnnnnnnnnvvvvvv"
    ]
  ]
}