{
  "name": "multi_courtyardofficetower_2_floor4",
  "refpalette": "deceasedcraft:multi_courtyardofficetower_2/multi_courtyardofficetower_2_floor4_palette",
  "xsize": 16,
  "zsize": 16,
  "slices": [
    [
      "           abbbb",
      "           abbbb",
      "           abbbb",
      "        ccccbbbb",
      "           abbbb",
      "           abbbb",
      "           abbbb",
      "          dabbbb",
      "           abbbb",
      "           abbbb",
      "           abbbb",
      "        ccccaaaa",
      "           c   d",
      "           c    ",
      "           c    ",
      "                "
    ],
    [
      "           e    ",
      "           e    ",
      "           fg   ",
      "        cccch   ",
      "           fg   ",
      "           e    ",
      "           e    ",
      "          de    ",
      "           ei   ",
      "           ej   ",
      "           fklm ",
      "        ccccfeee",
      "           c   d",
      "           c    ",
      "           c    ",
      "                "
    ],
    [
      "           e    ",
      "           e    ",
      "           f    ",
      "        ccccn   ",
      "           f    ",
      "           e    ",
      "           e    ",
      "          de    ",
      "           e    ",
      "           e    ",
      "           f    ",
      "        ccccfeee",
      "           c   d",
      "           c    ",
      "           c    ",
      "                "
    ],
    [
      "           e    ",
      "           e    ",
      "           f    ",
      "        cccc    ",
      "           f    ",
      "           e    ",
      "           e    ",
      "          de    ",
      "           e    ",
      "           e    ",
      "           f    ",
      "        ccccfeee",
      "           c   d",
      "           c    ",
      "           c    ",
      "                "
    ],
    [
      "           e    ",
      "           e    ",
      "           f    ",
      "        cccco   ",
      "           f    ",
      "           e    ",
      "           e    ",
      "          de    ",
      "           e    ",
      "           e    ",
      "           f    ",
      "        ccccfeee",
      "           c   d",
      "           c    ",
      "           c    ",
      "                "
    ],
    [
      "           epppp",
      "           epqpp",
      "           fpppp",
      "        cccccccc",
      "           fpppp",
      "           epqpp",
      "           epppp",
      "          depppp",
      "           epppp",
      "           epqpp",
      "           fpppp",
      "        ccccfeee",
      "           c   d",
      "           c    ",
      "           c    ",
      "                "
    ]
  ]
}