{
  "name": "multi_courtyardofficetower_2_floor19",
  "refpalette": "deceasedcraft:multi_courtyardofficetower_2/multi_courtyardofficetower_2_floor19_palette",
  "xsize": 16,
  "zsize": 16,
  "slices": [
    [
      "           a    ",
      "           a    ",
      "           b    ",
      "        cccc    ",
      "           b    ",
      "           a    ",
      "           a    ",
      "          da  e ",
      "           a eee",
      "           a  e ",
      "           b    ",
      "        ccccbaaa",
      "           c   d",
      "           c    ",
      "           c    ",
      "                "
    ],
    [
      "           a    ",
      "           a    ",
      "           b    ",
      "        cccc    ",
      "           b    ",
      "           a    ",
      "           a    ",
      "          da    ",
      "           a ee ",
      "           a  e ",
      "           b    ",
      "        ccccbaaa",
      "           c   d",
      "           c    ",
      "           c    ",
      "                "
    ],
    [
      "           a    ",
      "           a    ",
      "           b    ",
      "        cccc    ",
      "           b    ",
      "           a    ",
      "           a    ",
      "          da    ",
      "           a  e ",
      "           a    ",
      "           b    ",
      "        ccccbaaa",
      "           c   d",
      "           c    ",
      "           c    ",
      "                "
    ],
    [
      "           a    ",
      "           a    ",
      "           b    ",
      "        cccc    ",
      "           b    ",
      "           a    ",
      "           a    ",
      "          da    ",
      "           a    ",
      "           a    ",
      "           b    ",
      "        ccccbaaa",
      "           c   d",
      "           c    ",
      "           c    ",
      "                "
    ],
    [
      "           a    ",
      "           a    ",
      "           b    ",
      "        cccc    ",
      "           b    ",
      "           a    ",
      "           a    ",
      "          da    ",
      "           a    ",
      "           a    ",
      "           b    ",
      "        ccccbaaa",
      "           c   d",
      "           c    ",
      "           c    ",
      "                "
    ],
    [
      "           affff",
      "           afgff",
      "           bffff",
      "        cccccccc",
      "           bffff",
      "           afgff",
      "           affff",
      "          daffff",
      "           affff",
      "           afgff",
      "           bffff",
      "        ccccbaaa",
      "           c   d",
      "           c    ",
      "           c    ",
      "                "
    ]
  ]
}