{
  "name": "multi_courtyardofficetower_2_floor2",
  "refpalette": "deceasedcraft:multi_courtyardofficetower_2/multi_courtyardofficetower_2_floor2_palette",
  "xsize": 16,
  "zsize": 16,
  "slices": [
    [
      "           abccc",
      "           abccc",
      "           dbccc",
      "        eeeebccc",
      "           dbccc",
      "           abccc",
      "           abccc",
      "          fabccc",
      "           abccc",
      "           abccc",
      "           dbbbb",
      "        eeeedaaa",
      "           e   f",
      "           e    ",
      "           e    ",
      "                "
    ],
    [
      "           a    ",
      "           a    ",
      "           d    ",
      "        eeee    ",
      "           d    ",
      "           a    ",
      "           a   g",
      "          fa  hi",
      "           a   j",
      "           a    ",
      "           d    ",
      "        eeeedaaa",
      "           e   f",
      "           e    ",
      "           e    ",
      "                "
    ],
    [
      "           a    ",
      "           a    ",
      "           d    ",
      "        eeee    ",
      "           d    ",
      "           a    ",
      "           a    ",
      "          fa    ",
      "           a    ",
      "           a    ",
      "           d    ",
      "        eeeedaaa",
      "           e   f",
      "           e    ",
      "           e    ",
      "                "
    ],
    [
      "           a    ",
      "           a    ",
      "           d    ",
      "        eeee    ",
      "           d    ",
      "           a    ",
      "           a    ",
      "          fa    ",
      "           a    ",
      "           a    ",
      "           d    ",
      "        eeeedaaa",
      "           e   f",
      "           e    ",
      "           e    ",
      "                "
    ],
    [
      "           a    ",
      "           a    ",
      "           d    ",
      "        eeee    ",
      "           d    ",
      "           a    ",
      "           a    ",
      "          fa    ",
      "           a    ",
      "           a    ",
      "           d    ",
      "        eeeedaaa",
      "           e   f",
      "           e    ",
      "           e    ",
      "                "
    ],
    [
      "           a    ",
      "           a    ",
      "           d    ",
      "        eeee    ",
      "           d    ",
      "           a    ",
      "           a    ",
      "          fa    ",
      "           a    ",
      "           a    ",
      "           d    ",
      "        eeeedaaa",
      "           e   f",
      "           e    ",
      "           e    ",
      "                "
    ]
  ]
}