{
  "name": "multi_courtyardofficetower_2_floor8",
  "refpalette": "deceasedcraft:multi_courtyardofficetower_2/multi_courtyardofficetower_2_floor8_palette",
  "xsize": 16,
  "zsize": 16,
  "slices": [
    [
      "           abbbb",
      "           abbbb",
      "           abbbb",
      "        ccccdddb",
      "           aeeed",
      "           aeeee",
      "           aeeee",
      "          faeeee",
      "           aeeee",
      "           aeeee",
      "           aeeee",
      "        ccccaaaa",
      "           c   f",
      "           c    ",
      "           c    ",
      "                "
    ],
    [
      "           g    ",
      "           g    ",
      "           h    ",
      "        cccc    ",
      "           h    ",
      "           g i  ",
      "           g    ",
      "          fgj   ",
      "           g    ",
      "           g    ",
      "           h  k ",
      "        cccchggg",
      "           c   f",
      "           c    ",
      "           c    ",
      "                "
    ],
    [
      "           g    ",
      "           g    ",
      "           h    ",
      "        cccc    ",
      "           h    ",
      "           g    ",
      "           g    ",
      "          fg    ",
      "           g    ",
      "           g    ",
      "           h    ",
      "        cccchggg",
      "           c   f",
      "           c    ",
      "           c    ",
      "                "
    ],
    [
      "           g    ",
      "           g    ",
      "           h    ",
      "        cccc    ",
      "           h    ",
      "           g    ",
      "           g    ",
      "          fg    ",
      "           g    ",
      "           g    ",
      "           h    ",
      "        cccchggg",
      "           c   f",
      "           c    ",
      "           c    ",
      "                "
    ],
    [
      "           g    ",
      "           g    ",
      "           h    ",
      "        cccc    ",
      "           h    ",
      "           g    ",
      "           g    ",
      "          fg    ",
      "           g    ",
      "           g    ",
      "           h    ",
      "        cccchggg",
      "           c   f",
      "           c    ",
      "           c    ",
      "                "
    ],
    [
      "           g    ",
      "           g    ",
      "           h    ",
      "        cccc    ",
      "           h    ",
      "           g    ",
      "           g    ",
      "          fg    ",
      "           g    ",
      "           g    ",
      "           h    ",
      "        cccchggg",
      "           c   f",
      "           c    ",
      "           c    ",
      "                "
    ]
  ]
}