{
  "name": "multi_courtyardofficetower_2_floor16",
  "refpalette": "deceasedcraft:multi_courtyardofficetower_2/multi_courtyardofficetower_2_floor16_palette",
  "xsize": 16,
  "zsize": 16,
  "slices": [
    [
      "           abbbb",
      "           abbbb",
      "           abbbb",
      "        ccccaaaa",
      "           adddd",
      "           adddd",
      "           adddd",
      "          eadddd",
      "           adddd",
      "           adddd",
      "           adddd",
      "        ccccaaaa",
      "           c   e",
      "           c    ",
      "           c    ",
      "                "
    ],
    [
      "           f    ",
      "           f    ",
      "           ghhhh",
      "        cccciiii",
      "           gjkl ",
      "           f    ",
      "           f    ",
      "          ef  m ",
      "           f nop",
      "           f  op",
      "           gqrs ",
      "        ccccgfff",
      "           c   e",
      "           c    ",
      "           c    ",
      "                "
    ],
    [
      "           f    ",
      "           f    ",
      "           ghhhh",
      "        cccciiii",
      "           g!tu ",
      "           f    ",
      "           f    ",
      "          ef    ",
      "           f  w ",
      "           f  x ",
      "           gyA  ",
      "        ccccgfff",
      "           c   e",
      "           c    ",
      "           c    ",
      "                "
    ],
    [
      "           f    ",
      "           f    ",
      "           g    ",
      "        cccciiii",
      "           g   B",
      "           f    ",
      "           f    ",
      "          ef    ",
      "           f    ",
      "           f    ",
      "           g    ",
      "        ccccgfff",
      "           c   e",
      "           c    ",
      "           c    ",
      "                "
    ],
    [
      "           f    ",
      "           f    ",
      "           g    ",
      "        cccciiii",
      "           g    ",
      "           f    ",
      "           f    ",
      "          ef    ",
      "           f    ",
      "           f    ",
      "           g    ",
      "        ccccgfff",
      "           c   e",
      "           c    ",
      "           c    ",
      "                "
    ],
    [
      "           fCCCC",
      "           fCDCC",
      "           gCCCC",
      "        cccccccc",
      "           gCCCC",
      "           fCDCC",
      "           fCCCC",
      "          efCCCC",
      "           fCCCC",
      "           fCDCC",
      "           gCCCC",
      "        ccccgfff",
      "           c   e",
      "           c    ",
      "           c    ",
      "                "
    ]
  ]
}