{
  "name": "multi_courtyardofficetower_2_floor3",
  "refpalette": "deceasedcraft:multi_courtyardofficetower_2/multi_courtyardofficetower_2_floor3_palette",
  "xsize": 16,
  "zsize": 16,
  "slices": [
    [
      "           a    ",
      "           a    ",
      "           b    ",
      "        cccc    ",
      "           b    ",
      "           a    ",
      "           a    ",
      "          da    ",
      "           a    ",
      "           a    ",
      "           b    ",
      "        ccccbaaa",
      "           c   d",
      "           c    ",
      "           c    ",
      "                "
    ],
    [
      "           a    ",
      "           a    ",
      "           b    ",
      "        cccc    ",
      "           b    ",
      "           a    ",
      "           a    ",
      "          da    ",
      "           a    ",
      "           a    ",
      "           b    ",
      "        ccccbaaa",
      "           c   d",
      "           c    ",
      "           c    ",
      "                "
    ],
    [
      "           a    ",
      "           a    ",
      "           b    ",
      "        cccc    ",
      "           b    ",
      "           a    ",
      "           a    ",
      "          da    ",
      "           a    ",
      "           a    ",
      "           b    ",
      "        ccccbaaa",
      "           c   d",
      "           c    ",
      "           c    ",
      "                "
    ],
    [
      "           a    ",
      "           a    ",
      "           b    ",
      "        cccc    ",
      "           b    ",
      "           a    ",
      "           a    ",
      "          da    ",
      "           a    ",
      "           a    ",
      "           b    ",
      "        ccccbaaa",
      "           c   d",
      "           c    ",
      "           c    ",
      "                "
    ],
    [
      "           a    ",
      "           a    ",
      "           b    ",
      "        cccc    ",
      "           b    ",
      "           a    ",
      "           a    ",
      "          da    ",
      "           a    ",
      "           a    ",
      "           b    ",
      "        ccccbaaa",
      "           c   d",
      "           c    ",
      "           c    ",
      "                "
    ],
    [
      "           aeeee",
      "           aefee",
      "           beeee",
      "        cccccccc",
      "           beeee",
      "           aefee",
      "           aeeee",
      "          daeeee",
      "           aeeee",
      "           aefee",
      "           beeee",
      "        ccccbaaa",
      "           c   d",
      "           c    ",
      "           c    ",
      "                "
    ]
  ]
}