{
  "name": "multi_courtyardofficetower_2_floor5",
  "refpalette": "deceasedcraft:multi_courtyardofficetower_2/multi_courtyardofficetower_2_floor5_palette",
  "xsize": 16,
  "zsize": 16,
  "slices": [
    [
      "           abbbb",
      "           abbbb",
      "           abbbb",
      "        ccccbbbb",
      "           abbbb",
      "           abbbb",
      "           abbbb",
      "          dabbbb",
      "           abbbb",
      "           abbbb",
      "           abbbb",
      "        ccccaaaa",
      "           c   d",
      "           c    ",
      "           c    ",
      "                "
    ],
    [
      "           e f  ",
      "           e    ",
      "           gh   ",
      "        cccci  j",
      "           ghk  ",
      "           e   k",
      "           e    ",
      "          de    ",
      "           el  m",
      "           en   ",
      "           gopq ",
      "        ccccgeee",
      "           c   d",
      "           c    ",
      "           c    ",
      "                "
    ],
    [
      "           e    ",
      "           e    ",
      "           g    ",
      "        cccc    ",
      "           g    ",
      "           e    ",
      "           e    ",
      "          de    ",
      "           e    ",
      "           e    ",
      "           g    ",
      "        ccccgeee",
      "           c   d",
      "           c    ",
      "           c    ",
      "                "
    ],
    [
      "           e    ",
      "           e    ",
      "           g    ",
      "        cccc    ",
      "           g    ",
      "           e    ",
      "           e    ",
      "          de    ",
      "           e    ",
      "           e    ",
      "           g    ",
      "        ccccgeee",
      "           c   d",
      "           c    ",
      "           c    ",
      "                "
    ],
    [
      "           e    ",
      "           e    ",
      "           g    ",
      "        cccc    ",
      "           g    ",
      "           e    ",
      "           e    ",
      "          de    ",
      "           e    ",
      "           e    ",
      "           g    ",
      "        ccccgeee",
      "           c   d",
      "           c    ",
      "           c    ",
      "                "
    ],
    [
      "           errrr",
      "           ersrr",
      "           grrrr",
      "        cccccccc",
      "           grrrr",
      "           ersrr",
      "           errrr",
      "          derrrr",
      "           errrr",
      "           ersrr",
      "           grrrr",
      "        ccccgeee",
      "           c   d",
      "           c    ",
      "           c    ",
      "                "
    ]
  ]
}