{
  "name": "multi_courtyardofficetower_2_floor22",
  "refpalette": "deceasedcraft:multi_courtyardofficetower_2/multi_courtyardofficetower_2_floor22_palette",
  "xsize": 16,
  "zsize": 16,
  "slices": [
    [
      "           a    ",
      "           a    ",
      "           a    ",
      "        aaaaaaaa",
      "           a    ",
      "           a    ",
      "           a    ",
      "           a    ",
      "           a    ",
      "           a    ",
      "           a    ",
      "        aaaaaaaa",
      "           a    ",
      "           a    ",
      "           a    ",
      "                "
    ],
    [
      "           abccc",
      "           abccc",
      "           abbbb",
      "        aaaaaaaa",
      "           abbbb",
      "           abccc",
      "           abccc",
      "           abccc",
      "           abccc",
      "           abccc",
      "           abbbb",
      "        aaaaaaaa",
      "           a    ",
      "           a    ",
      "           a    ",
      "                "
    ],
    [
      "           a    ",
      "           a    ",
      "           a    ",
      "        aaaaaaaa",
      "           a    ",
      "           a    ",
      "           a    ",
      "           a    ",
      "           a    ",
      "           a    ",
      "           a    ",
      "        aaaaaaaa",
      "           a    ",
      "           a    ",
      "           a    ",
      "                "
    ],
    [
      "           a    ",
      "           a    ",
      "           a    ",
      "        aaaaaaaa",
      "           a    ",
      "           a    ",
      "           a    ",
      "           a    ",
      "           a    ",
      "           a    ",
      "           a    ",
      "        aaaaaaaa",
      "           a    ",
      "           a    ",
      "           a    ",
      "                "
    ],
    [
      "           a    ",
      "           a    ",
      "           a    ",
      "        aaaaaaaa",
      "           a    ",
      "           a    ",
      "           a    ",
      "           a    ",
      "           a    ",
      "           a    ",
      "           a    ",
      "        aaaaaaaa",
      "           a    ",
      "           a    ",
      "           a    ",
      "                "
    ],
    [
      "           a    ",
      "           a    ",
      "           a    ",
      "        aaaaaaaa",
      "           a    ",
      "           a    ",
      "           a    ",
      "           a    ",
      "           a    ",
      "           a    ",
      "           a    ",
      "        aaaaaaaa",
      "           a    ",
      "           a    ",
      "           a    ",
      "                "
    ]
  ]
}