{
  "name": "multi_courtyardofficetower_2_floor15",
  "refpalette": "deceasedcraft:multi_courtyardofficetower_2/multi_courtyardofficetower_2_floor15_palette",
  "xsize": 16,
  "zsize": 16,
  "slices": [
    [
      "           abbbb",
      "           abbbb",
      "           abbbb",
      "        ccccaaaa",
      "           adddd",
      "           adddd",
      "           adddd",
      "          eadddd",
      "           adddd",
      "           adddd",
      "           adddd",
      "        ccccaaaa",
      "           c   e",
      "           c    ",
      "           c    ",
      "                "
    ],
    [
      "           f    ",
      "           f    ",
      "           ghhhi",
      "        ccccjjjj",
      "           gklm ",
      "           f    ",
      "           f    ",
      "          ef  n ",
      "           f opq",
      "           f  pq",
      "           grst ",
      "        ccccgfff",
      "           c   e",
      "           c    ",
      "           c    ",
      "                "
    ],
    [
      "           f    ",
      "           f    ",
      "           guuu ",
      "        ccccjjjj",
      "           gwxy ",
      "           f    ",
      "           f    ",
      "          ef  A ",
      "           f  B ",
      "           f  C ",
      "           g DE ",
      "        ccccgfff",
      "           c   e",
      "           c    ",
      "           c    ",
      "                "
    ],
    [
      "           f    ",
      "           f    ",
      "           g    ",
      "        ccccjjjj",
      "           g   F",
      "           f    ",
      "           f    ",
      "          ef    ",
      "           f    ",
      "           f    ",
      "           g    ",
      "        ccccgfff",
      "           c   e",
      "           c    ",
      "           c    ",
      "                "
    ],
    [
      "           f    ",
      "           f    ",
      "           g    ",
      "        ccccjjjj",
      "           g    ",
      "           f    ",
      "           f    ",
      "          ef    ",
      "           f    ",
      "           f    ",
      "           g    ",
      "        ccccgfff",
      "           c   e",
      "           c    ",
      "           c    ",
      "                "
    ],
    [
      "           fIIII",
      "           fIJII",
      "           gIIII",
      "        cccccccc",
      "           gIIII",
      "           fIJII",
      "           fIIII",
      "          efIIII",
      "           fIIII",
      "           fIJII",
      "           gIIII",
      "        ccccgfff",
      "           c   e",
      "           c    ",
      "           c    ",
      "                "
    ]
  ]
}