{
  "name": "multi_courtyardofficetower_2_floor13",
  "refpalette": "deceasedcraft:multi_courtyardofficetower_2/multi_courtyardofficetower_2_floor13_palette",
  "xsize": 16,
  "zsize": 16,
  "slices": [
    [
      "           abccc",
      "           abccc",
      "           dbccc",
      "        eeeebbbb",
      "           dbfff",
      "           abfff",
      "           abfff",
      "          gabfff",
      "           abfff",
      "           abfff",
      "           dbbbb",
      "        eeeedaaa",
      "           e   g",
      "           e    ",
      "           e    ",
      "                "
    ],
    [
      "           a    ",
      "           a    ",
      "           d    ",
      "        eeeehijh",
      "           d    ",
      "           a    ",
      "           a    ",
      "          ga    ",
      "           a    ",
      "           a    ",
      "           d    ",
      "        eeeedaaa",
      "           e   g",
      "           e    ",
      "           e    ",
      "                "
    ],
    [
      "           a    ",
      "           a    ",
      "           d    ",
      "        eeeehklh",
      "           d    ",
      "           a    ",
      "           a    ",
      "          ga    ",
      "           a    ",
      "           a    ",
      "           d    ",
      "        eeeedaaa",
      "           e   g",
      "           e    ",
      "           e    ",
      "                "
    ],
    [
      "           a    ",
      "           a    ",
      "           d    ",
      "        eeeehhhh",
      "           d    ",
      "           a    ",
      "           a    ",
      "          ga    ",
      "           a    ",
      "           a    ",
      "           d    ",
      "        eeeedaaa",
      "           e   g",
      "           e    ",
      "           e    ",
      "                "
    ],
    [
      "           a    ",
      "           a    ",
      "           d    ",
      "        eeeehhhh",
      "           d    ",
      "           a    ",
      "           a    ",
      "          ga    ",
      "           a    ",
      "           a    ",
      "           d    ",
      "        eeeedaaa",
      "           e   g",
      "           e    ",
      "           e    ",
      "                "
    ],
    [
      "           a    ",
      "           a    ",
      "           d    ",
      "        eeeehhhh",
      "           d    ",
      "           a    ",
      "           a    ",
      "          ga    ",
      "           a    ",
      "           a    ",
      "           d    ",
      "        eeeedaaa",
      "           e   g",
      "           e    ",
      "           e    ",
      "                "
    ]
  ]
}