{
  "name": "multi_courtyardofficetower_2_floor18",
  "refpalette": "deceasedcraft:multi_courtyardofficetower_2/multi_courtyardofficetower_2_floor18_palette",
  "xsize": 16,
  "zsize": 16,
  "slices": [
    [
      "           abbbb",
      "           abbbb",
      "           abbbb",
      "        ccccbbbb",
      "           adddd",
      "           adddd",
      "           adddd",
      "          eadddd",
      "           adddd",
      "           adddd",
      "           adddd",
      "        ccccaaaa",
      "           c   e",
      "           c    ",
      "           c    ",
      "                "
    ],
    [
      "           f    ",
      "           f    ",
      "           g    ",
      "        cccc    ",
      "           ghhhh",
      "           f i i",
      "           f j  ",
      "          efj   ",
      "           f  kj",
      "           fj j ",
      "           gj! j",
      "        ccccgfff",
      "           c   e",
      "           c    ",
      "           c    ",
      "                "
    ],
    [
      "           f    ",
      "           f    ",
      "           g    ",
      "        cccc    ",
      "           g    ",
      "           f    ",
      "           f    ",
      "          ef    ",
      "           f  h ",
      "           f    ",
      "           g    ",
      "        ccccgfff",
      "           c   e",
      "           c    ",
      "           c    ",
      "                "
    ],
    [
      "           f    ",
      "           f    ",
      "           g    ",
      "        cccc    ",
      "           g    ",
      "           f    ",
      "           f    ",
      "          ef    ",
      "           f  j ",
      "           f    ",
      "           g    ",
      "        ccccgfff",
      "           c   e",
      "           c    ",
      "           c    ",
      "                "
    ],
    [
      "           f    ",
      "           f    ",
      "           g    ",
      "        cccc    ",
      "           g    ",
      "           f    ",
      "           f  j ",
      "          ef jj ",
      "           f jjj",
      "           f    ",
      "           g    ",
      "        ccccgfff",
      "           c   e",
      "           c    ",
      "           c    ",
      "                "
    ],
    [
      "           f    ",
      "           f    ",
      "           g    ",
      "        cccc    ",
      "           g    ",
      "           f    ",
      "           f    ",
      "          ef  j ",
      "           fjjjj",
      "           f jj ",
      "           g    ",
      "        ccccgfff",
      "           c   e",
      "           c    ",
      "           c    ",
      "                "
    ]
  ]
}