{
  "name": "multi_courtyardofficetower_2_floor14",
  "refpalette": "deceasedcraft:multi_courtyardofficetower_2/multi_courtyardofficetower_2_floor14_palette",
  "xsize": 16,
  "zsize": 16,
  "slices": [
    [
      "           a    ",
      "           a    ",
      "           b    ",
      "        ccccdddd",
      "           b    ",
      "           a    ",
      "           a    ",
      "          ea    ",
      "           a    ",
      "           a    ",
      "           b    ",
      "        ccccbaaa",
      "           c   e",
      "           c    ",
      "           c    ",
      "                "
    ],
    [
      "           a    ",
      "           a    ",
      "           b    ",
      "        ccccdddd",
      "           b    ",
      "           a    ",
      "           a    ",
      "          ea    ",
      "           a    ",
      "           a    ",
      "           b    ",
      "        ccccbaaa",
      "           c   e",
      "           c    ",
      "           c    ",
      "                "
    ],
    [
      "           a    ",
      "           a    ",
      "           b    ",
      "        ccccdddd",
      "           b    ",
      "           a    ",
      "           a    ",
      "          ea    ",
      "           a    ",
      "           a    ",
      "           b    ",
      "        ccccbaaa",
      "           c   e",
      "           c    ",
      "           c    ",
      "                "
    ],
    [
      "           a    ",
      "           a    ",
      "           b    ",
      "        ccccdddd",
      "           b    ",
      "           a    ",
      "           a    ",
      "          ea    ",
      "           a    ",
      "           a    ",
      "           b    ",
      "        ccccbaaa",
      "           c   e",
      "           c    ",
      "           c    ",
      "                "
    ],
    [
      "           a    ",
      "           a    ",
      "           b    ",
      "        ccccdddd",
      "           b    ",
      "           a    ",
      "           a    ",
      "          ea    ",
      "           a    ",
      "           a    ",
      "           b    ",
      "        ccccbaaa",
      "           c   e",
      "           c    ",
      "           c    ",
      "                "
    ],
    [
      "           affff",
      "           afgff",
      "           bffff",
      "        cccccccc",
      "           bffff",
      "           afgff",
      "           affff",
      "          eaffff",
      "           affff",
      "           afgff",
      "           bffff",
      "        ccccbaaa",
      "           c   e",
      "           c    ",
      "           c    ",
      "                "
    ]
  ]
}