{
  "name": "multi_courtyardofficetower_2_ground",
  "refpalette": "deceasedcraft:multi_courtyardofficetower_2/multi_courtyardofficetower_2_ground_palette",
  "xsize": 16,
  "zsize": 16,
  "slices": [
    [
      "aaaaaaaaabcdeffa",
      "aaaaaaaaabcdgfff",
      "aaaaaaaaabbbafff",
      "aaaaaaaahhhhaffa",
      "aaaaaaaaaaaaaffa",
      "aaaaaaaaaaaafffa",
      "aaaaaaaaaaaaafff",
      "aaaaaaaaaaaaafff",
      "aaaaaaaaaaaafffa",
      "aaaaaaaaaaaafaff",
      "aaaaaaaaaaaaafff",
      "aaaaaaaahhhhaafi",
      "aaaaaaaaaaahafij",
      "aaaaaaaaaaahaijj",
      "aaaaaaaaaaahijji",
      "aaaaaaaaaaaijjia"
    ],
    [
      "kk      ld      ",
      "   k    ld      ",
      "    km  lddd    ",
      "        hhhh   n",
      "         kk     ",
      " m k    km      ",
      "  k  m    kk    ",
      "       kk       ",
      "  k m     k     ",
      "         k      ",
      "  k    k kk     ",
      "k m k   hhhhk   ",
      "        kk hm   ",
      "   k       h    ",
      "  mk m km  h    ",
      " k             n"
    ],
    [
      "                ",
      "                ",
      "     l          ",
      "        hhhh    ",
      "          k     ",
      " l       l      ",
      "     l     k    ",
      "                ",
      "    l           ",
      "         k      ",
      "         k      ",
      "  l     hhhh    ",
      "           hl   ",
      "           h    ",
      "  l  l  l  h    ",
      "                "
    ],
    [
      "                ",
      "                ",
      "     k          ",
      "        hhhh    ",
      "                ",
      " k      ok      ",
      "     k         p",
      "              pp",
      "    k         pp",
      "              pp",
      "               p",
      "  k     hhhh    ",
      "           hk   ",
      "           h    ",
      "  k  k  k  h    ",
      "                "
    ],
    [
      "                ",
      "                ",
      "     k          ",
      "        hhhh    ",
      "                ",
      " k      kko     ",
      "     k   k      ",
      "                ",
      "    k          p",
      "                ",
      "                ",
      "  k     hhhh    ",
      "           hk   ",
      "           h    ",
      "  k  k  k  h    ",
      "                "
    ],
    [
      "                ",
      "                ",
      "     k          ",
      "        hhhh    ",
      "         k      ",
      " k      kkk     ",
      "     k   k     p",
      "              pp",
      "    k         pp",
      "              pp",
      "               p",
      "  k     hhhh    ",
      "           ho   ",
      "           h    ",
      "  k  k  k  h    ",
      "                "
    ]
  ]
}