{
  "name": "multi_courtyardofficetower_2_floor6",
  "refpalette": "deceasedcraft:multi_courtyardofficetower_2/multi_courtyardofficetower_2_floor6_palette",
  "xsize": 16,
  "zsize": 16,
  "slices": [
    [
      "           abbbb",
      "           abbbb",
      "           abbbb",
      "        ccccbbbb",
      "           abbbb",
      "           abbbb",
      "           abbbb",
      "          daeebb",
      "           affeb",
      "           afffe",
      "           afffe",
      "        ccccaaaa",
      "           c   d",
      "           c    ",
      "           c    ",
      "                "
    ],
    [
      "           g    ",
      "           g    ",
      "           hi   ",
      "        ccccj   ",
      "           hi   ",
      "           g    ",
      "           g    ",
      "          dg    ",
      "           gk   ",
      "           g    ",
      "           hlm  ",
      "        cccchggg",
      "           c   d",
      "           c    ",
      "           c    ",
      "                "
    ],
    [
      "           g    ",
      "           g    ",
      "           h    ",
      "        ccccn   ",
      "           h    ",
      "           g    ",
      "           g    ",
      "          dg    ",
      "           g    ",
      "           g    ",
      "           h    ",
      "        cccchggg",
      "           c   d",
      "           c    ",
      "           c    ",
      "                "
    ],
    [
      "           g    ",
      "           g    ",
      "           h    ",
      "        cccc    ",
      "           h    ",
      "           g    ",
      "           g    ",
      "          dg    ",
      "           g    ",
      "           g    ",
      "           h    ",
      "        cccchggg",
      "           c   d",
      "           c    ",
      "           c    ",
      "                "
    ],
    [
      "           g    ",
      "           g    ",
      "           h    ",
      "        cccco   ",
      "           h    ",
      "           g    ",
      "           g    ",
      "          dg    ",
      "           g    ",
      "           g    ",
      "           h    ",
      "        cccchggg",
      "           c   d",
      "           c    ",
      "           c    ",
      "                "
    ],
    [
      "           gpppp",
      "           gpqpp",
      "           hpppp",
      "        cccccccc",
      "           hpppp",
      "           gpqpp",
      "           gpppp",
      "          dgpppp",
      "           gpppp",
      "           gpqpp",
      "           hpppp",
      "        cccchggg",
      "           c   d",
      "           c    ",
      "           c    ",
      "                "
    ]
  ]
}