{
  "name": "multi_courtyardofficetower_2_floor17",
  "refpalette": "deceasedcraft:multi_courtyardofficetower_2/multi_courtyardofficetower_2_floor17_palette",
  "xsize": 16,
  "zsize": 16,
  "slices": [
    [
      "           abbbb",
      "           abbbb",
      "           abbbb",
      "        ccccaaaa",
      "           adddd",
      "           adddd",
      "           adddd",
      "          eadddd",
      "           adddd",
      "           adddd",
      "           adddd",
      "        ccccaaaa",
      "           c   e",
      "           c    ",
      "           c    ",
      "                "
    ],
    [
      "           f  g ",
      "           f  h ",
      "           ijjjk",
      "        ccccllll",
      "           imno ",
      "           f    ",
      "           f    ",
      "          ef  p ",
      "           f qrs",
      "           f  rs",
      "           ituw ",
      "        ccccifff",
      "           c   e",
      "           c    ",
      "           c    ",
      "                "
    ],
    [
      "           f    ",
      "           f    ",
      "           ijj  ",
      "        ccccllll",
      "           ixy  ",
      "           f    ",
      "           f    ",
      "          ef  A ",
      "           f  B ",
      "           f    ",
      "           iCDC ",
      "        ccccifff",
      "           c   e",
      "           c    ",
      "           c    ",
      "                "
    ],
    [
      "           f    ",
      "           f    ",
      "           i    ",
      "        ccccllll",
      "           i   E",
      "           f    ",
      "           f    ",
      "          ef    ",
      "           f    ",
      "           f    ",
      "           i    ",
      "        ccccifff",
      "           c   e",
      "           c    ",
      "           c    ",
      "                "
    ],
    [
      "           f    ",
      "           f    ",
      "           i    ",
      "        ccccllll",
      "           i    ",
      "           f    ",
      "           f    ",
      "          ef    ",
      "           f    ",
      "           f    ",
      "           i    ",
      "        ccccifff",
      "           c   e",
      "           c    ",
      "           c    ",
      "                "
    ],
    [
      "           fFFFF",
      "           fFIFF",
      "           iFFFF",
      "        cccccccc",
      "           iFFFF",
      "           fFIFF",
      "           fFFFF",
      "          efFFFF",
      "           fFFFF",
      "           fFIFF",
      "           iFFFF",
      "        ccccifff",
      "           c   e",
      "           c    ",
      "           c    ",
      "                "
    ]
  ]
}