{
  "name": "multi_courtyardofficetower_2_floor7",
  "refpalette": "deceasedcraft:multi_courtyardofficetower_2/multi_courtyardofficetower_2_floor7_palette",
  "xsize": 16,
  "zsize": 16,
  "slices": [
    [
      "           abbbb",
      "           abbbb",
      "           abbbb",
      "        ccccbbbb",
      "           abbbb",
      "           abbbb",
      "           abbbb",
      "          daeebb",
      "           affeb",
      "           afffe",
      "           afffe",
      "        ccccaaaa",
      "           c   d",
      "           c    ",
      "           c    ",
      "                "
    ],
    [
      "           g    ",
      "           g    ",
      "           hi   ",
      "        ccccj   ",
      "           hi   ",
      "           g    ",
      "           g    ",
      "          dg    ",
      "           gk   ",
      "           g  l ",
      "           hm   ",
      "        cccchggg",
      "           c   d",
      "           c    ",
      "           c    ",
      "                "
    ],
    [
      "           g    ",
      "           g    ",
      "           h    ",
      "        cccc    ",
      "           h    ",
      "           g    ",
      "           g    ",
      "          dg    ",
      "           g    ",
      "           g    ",
      "           h    ",
      "        cccchggg",
      "           c   d",
      "           c    ",
      "           c    ",
      "                "
    ],
    [
      "           g    ",
      "           g    ",
      "           h    ",
      "        cccc    ",
      "           h    ",
      "           g    ",
      "           g    ",
      "          dg    ",
      "           g    ",
      "           g    ",
      "           h    ",
      "        cccchggg",
      "           c   d",
      "           c    ",
      "           c    ",
      "                "
    ],
    [
      "           g    ",
      "           g    ",
      "           h    ",
      "        cccc    ",
      "           h    ",
      "           g    ",
      "           g    ",
      "          dg    ",
      "           g    ",
      "           g    ",
      "           h    ",
      "        cccchggg",
      "           c   d",
      "           c    ",
      "           c    ",
      "                "
    ],
    [
      "           gnnnn",
      "           gnonn",
      "           hnnnn",
      "        cccccccc",
      "           hnnnn",
      "           gnonn",
      "           gnnnn",
      "          dgnnnn",
      "           gnnnn",
      "           gnonn",
      "           hnnnn",
      "        cccchggg",
      "           c   d",
      "           c    ",
      "           c    ",
      "                "
    ]
  ]
}