{
  "name": "building_apartmentsmalla_ground_270",
  "refpalette": "deceasedcraft:building_apartmentsmalla/building_apartmentsmalla_ground_palette_270",
  "xsize": 16,
  "zsize": 16,
  "slices": [
    [
      "aaaaadaddaaaaaaa",
      "abbbbbbbbbbbbbba",
      "abbbbbbbbbbbbbba",
      "abbbbbbbbbbbbbba",
      "abbbbbbbbbbbbbba",
      "abbbbbbbbbbbbbba",
      "abbbbbbbbbbbbbba",
      "abbbbbbbbbbbccba",
      "abbbbbbbbbbbccba",
      "abbbbbbbbbbbbbba",
      "aaecccbbbbbbbbba",
      "aaecccbbbbbbbbba",
      "aaecccbbbbbbbbba",
      "aaeeeebbbbbbbbba",
      "aaaaaabbbbbbbbba",
      "aaaaaaaaaaaaaaaa"
    ],
    [
      "                ",
      " gggggwEBwfgggf ",
      " g QMKxCCxshhhf ",
      " g   t    t   f ",
      " gR         m f ",
      " gS N    yuiiif ",
      " gS N  FD fffff ",
      " gT        fnjf ",
      " V         r kf ",
      " fffOLf    ffff ",
      "  U   fI  ooo f ",
      "  U   fJ Ap!plf ",
      "  ecP fJ Appplf ",
      "  eeeefI  qqq f ",
      "      fgggggggf ",
      "                "
    ],
    [
      "                ",
      " gggggw21wfgggf ",
      " g   3x  xY   f ",
      " g   Z    Z   f ",
      " g            f ",
      " g        0WWWf ",
      " g        fffff ",
      " g         f  f ",
      " V         X  f ",
      " fff64f    ffff ",
      "  e   f       f ",
      "  e7  f       f ",
      "  eP  f       f ",
      "  eeU5f       f ",
      "      fgggggggf ",
      "                "
    ],
    [
      "                ",
      " gggggw%%wfgggf ",
      " g   3x  xY   f ",
      " g   $    $   g ",
      " g            g ",
      " g         W8Wf ",
      " g        fffff ",
      " g         f9 g ",
      " V         #  g ",
      " fff^^f    ffff ",
      "  ec  f       f ",
      "  e&  f       g ",
      "  *   f       g ",
      "  (eeef       f ",
      "      fgggggggf ",
      "                "
    ],
    [
      "                ",
      " wVVVVw  wfVVVf ",
      " V   [xxxx-   f ",
      " V            ) ",
      " V            ) ",
      " V           +f ",
      " V        fffff ",
      " V         f  ) ",
      " V         f  ) ",
      " ffffffffffffff ",
      "  {&] f       f ",
      "  U   f       ) ",
      "  U   f       ) ",
      "  e***f       f ",
      "      fVVVVVVVf ",
      "                "
    ],
    [
      "                ",
      " ffffffffffffff ",
      " feeeeeeeeeeeef ",
      " feeeeeeeeeeeef ",
      " feeeeeeeeeeeef ",
      " feeeeeDDeeeeef ",
      " feeeee;|efffff ",
      " feeeeeeeeef}}f ",
      " feeeeeeeeef}}f ",
      " ffffffffffffff ",
      "  e :cfeeeeeeef ",
      "  e   feeeeeeef ",
      "  e   feeeeeeef ",
      "  eeeefeeeeeeef ",
      "      fffffffff ",
      "                "
    ]
  ]
}