{
  "name": "building_apartmentsmalla_floor3_270",
  "refpalette": "deceasedcraft:building_apartmentsmalla/building_apartmentsmalla_floor3_palette_270",
  "xsize": 16,
  "zsize": 16,
  "slices": [
    [
      "                ",
      " aaaaaaaaaaaaaa ",
      " abbbbbccbbbbba ",
      " abbbbbccbbbbba ",
      " abbbbbccbbbbba ",
      " abbbbbbbbbbbba ",
      " abbbbbbbbbbbba ",
      " abbbbbbbbbbcca ",
      " abbbbbbbbbbcca ",
      " abbbbbbbbbbcca ",
      "  e  dbbbbbbbba ",
      "  i  cbbbbbbbba ",
      "  jhfcbbbbbbbba ",
      "  kggebbbbbbbba ",
      "      aaaaaaaaa ",
      "                "
    ],
    [
      "                ",
      " llllllllllllll ",
      " l8  YlOMlB  ml ",
      " l96 ZlPqlCxtnl ",
      " l# 00lQllD tnl ",
      " l       lE  ml ",
      " l333 T  K ouol ",
      " l    UR lll !l ",
      " l$741VR L ywpl ",
      " lllllW  l u ql ",
      "  %   l  l ylll ",
      "  %  2lSllF  rl ",
      "  ec5 X NlI  sl ",
      "  eeeel NlJA  l ",
      "      lllllllll ",
      "                "
    ],
    [
      "                ",
      " :>>>::>>:l^^^l ",
      " >   !l  l{[)&l ",
      " ^\u0377  \u0372l  l}   l ",
      " ^\u037a 6\u0373l/ll    l ",
      " ^\u037a      l|   l ",
      " ^\u037a      ' o+ol ",
      " ^\u037b     ,lll *l ",
      " > \u0375\u0374    < y  l ",
      " lllll\u0370  l +  l ",
      "  e   l  l|ylll ",
      "  e\u0376  l`ll    l ",
      "  e5  \u0371 .l;   l ",
      "  ee%jl ?l ]-(l ",
      "      lllll^^^l ",
      "                "
    ],
    [
      "                ",
      " :^^^>:^^:l^^^l ",
      " >   \u038cl  l \u0386\u0384\u037cl ",
      " ^\u038f   l \u037el    ^ ",
      " ^\u0390   l\u0389ll    ^ ",
      " ^\u0390      l    l ",
      " ^\u0390      \u0388 oool ",
      " ^\u0391      lll \u037d^ ",
      " >       \u0388 y  ^ ",
      " lllll   l y \u037el ",
      "  ec  l  l ylll ",
      "  e\u038e  l\u038all    ^ ",
      "  \u0392   l  l    ^ ",
      "  \u0393eeel  l \u0387\u0385\u037fl ",
      "      l^^ll^^^l ",
      "                "
    ],
    [
      "                ",
      " :>>>>:>>:l>>>l ",
      " >    l  l    l ",
      " >    l  l    \u0394 ",
      " >    llll    \u0394 ",
      " >  \u0395    l    l ",
      " >       l oool ",
      " >       lll  \u0394 ",
      " >       l y  \u0394 ",
      " lllll   l y  l ",
      "  g\u038e\u0396 l  l ylll ",
      "  %   llll    \u0394 ",
      "  %   l  l    \u0394 ",
      "  e\u0392\u0392\u0392l  l    l ",
      "      l>>ll>>>l ",
      "                "
    ],
    [
      "                ",
      " llllllllllllll ",
      " leeeee\u0397\u0397leeeel ",
      " leeeee\u0397\u0397leeeel ",
      " leeeeeeeleeeel ",
      " leeeeeeeleeeel ",
      " leeeeeeeleeeel ",
      " leeeeeeelee\u0397\u0397l ",
      " leeeeeeelee\u0397\u0397l ",
      " lllll\u0398eelee\u0397\u0397l ",
      "  e dcleeleeeel ",
      "  e   lllleeeel ",
      "  e   leeleeeel ",
      "  eeeeleeleeeel ",
      "      lllllllll ",
      "                "
    ]
  ]
}