{
  "name": "building_apartmentsmalla_floor3_90",
  "refpalette": "deceasedcraft:building_apartmentsmalla/building_apartmentsmalla_floor3_palette_90",
  "xsize": 16,
  "zsize": 16,
  "slices": [
    [
      "                ",
      " aaaaaaaaa      ",
      " abbbbbbbbeggk  ",
      " abbbbbbbbcfhj  ",
      " abbbbbbbbc  i  ",
      " abbbbbbbbd  e  ",
      " accbbbbbbbbbba ",
      " accbbbbbbbbbba ",
      " accbbbbbbbbbba ",
      " abbbbbbbbbbbba ",
      " abbbbbbbbbbbba ",
      " abbbbbccbbbbba ",
      " abbbbbccbbbbba ",
      " abbbbbccbbbbba ",
      " aaaaaaaaaaaaaa ",
      "                "
    ],
    [
      "                ",
      " lllllllll      ",
      " l  AJlN leeee  ",
      " ls  IlN X 5ce  ",
      " lr  FllSl2  %  ",
      " llly l  l   %  ",
      " lq u l  Wlllll ",
      " lpwy L RV147$l ",
      " l! lll RU    l ",
      " louo K  T 333l ",
      " lm  El       l ",
      " lnt DllQl00 #l ",
      " lntxClqPlZ 69l ",
      " lm  BlMOlY  8l ",
      " llllllllllllll ",
      "                "
    ],
    [
      "                ",
      " l^^^lllll      ",
      " l(-] l? lj%ee  ",
      " l   ;l. \u0371  5e  ",
      " l    ll`l  \u0376e  ",
      " llly|l  l   e  ",
      " l  + l  \u0370lllll ",
      " l  y <    \u0374\u0375 > ",
      " l* lll,     \u037b^ ",
      " lo+o '      \u037a^ ",
      " l   |l      \u037a^ ",
      " l    ll/l\u03736 \u037a^ ",
      " l   }l  l\u0372  \u0377^ ",
      " l&)[{l  l!   > ",
      " l^^^l:>>::>>>: ",
      "                "
    ],
    [
      "                ",
      " l^^^ll^^l      ",
      " l\u037f\u0385\u0387 l  leee\u0393  ",
      " ^    l  l   \u0392  ",
      " ^    ll\u038al  \u038ee  ",
      " llly l  l  ce  ",
      " l\u037e y l   lllll ",
      " ^  y \u0388       > ",
      " ^\u037d lll      \u0391^ ",
      " looo \u0388      \u0390^ ",
      " l    l      \u0390^ ",
      " ^    ll\u0389l   \u0390^ ",
      " ^    l\u037e l   \u038f^ ",
      " l\u037c\u0384\u0386 l  l\u038c   > ",
      " l^^^l:^^:>^^^: ",
      "                "
    ],
    [
      "                ",
      " l>>>ll>>l      ",
      " l    l  l\u0392\u0392\u0392e  ",
      " \u0394    l  l   %  ",
      " \u0394    llll   %  ",
      " llly l  l \u0396\u038eg  ",
      " l  y l   lllll ",
      " \u0394  y l       > ",
      " \u0394  lll       > ",
      " looo l       > ",
      " l    l    \u0395  > ",
      " \u0394    llll    > ",
      " \u0394    l  l    > ",
      " l    l  l    > ",
      " l>>>l:>>:>>>>: ",
      "                "
    ],
    [
      "                ",
      " lllllllll      ",
      " leeeeleeleeee  ",
      " leeeeleel   e  ",
      " leeeellll   e  ",
      " leeeeleelcd e  ",
      " l\u0397\u0397eelee\u0398lllll ",
      " l\u0397\u0397eeleeeeeeel ",
      " l\u0397\u0397eeleeeeeeel ",
      " leeeeleeeeeeel ",
      " leeeeleeeeeeel ",
      " leeeeleeeeeeel ",
      " leeeel\u0397\u0397eeeeel ",
      " leeeel\u0397\u0397eeeeel ",
      " llllllllllllll ",
      "                "
    ]
  ]
}