{
  "name": "building_apartmentsmalla_floor2_270",
  "refpalette": "deceasedcraft:building_apartmentsmalla/building_apartmentsmalla_floor2_palette_270",
  "xsize": 16,
  "zsize": 16,
  "slices": [
    [
      "                ",
      " aaaaaaaaaaaaaa ",
      " abbbbbccbbbbba ",
      " abbbbbccbbbbba ",
      " abbbbbccbbbbba ",
      " abbbbbbbbbbbba ",
      " abbbbbbbbbbbba ",
      " abbbbbbbbbbcca ",
      " abbbbbbbbbbcca ",
      " abbbbbbbbbbcca ",
      "  e  dbbbbbbbba ",
      "  i  cbbbbbbbba ",
      "  jhfcbbbbbbbba ",
      "  kggebbbbbbbba ",
      "      aaaaaaaaa ",
      "                "
    ],
    [
      "                ",
      " llllllllllllll ",
      " l7  YlROlDy ml ",
      " l8  Zl qlE unl ",
      " l9 00lSllF unl ",
      " l       lI  ml ",
      " l333 U  M owol ",
      " l    VP lll  l ",
      " l#641V PN Axpl ",
      " lllllW  l B ql ",
      "  $   l  l Alll ",
      "  $  2lTllJ  rl ",
      "  ec5 X QlKC sl ",
      "  eeeel QlL  tl ",
      "      lllllllll ",
      "                "
    ],
    [
      "                ",
      " <....<..<l%%%l ",
      " .   \u0374l  l{-(^l ",
      " %\u037d  \u0375l  l}   l ",
      " %\u037e \u0377\u0376l`ll|   l ",
      " %\u037e      l;   l ",
      " %\u037e      > o)ol ",
      " %\u037f   \u0371 ?lll &l ",
      " . \u037b\u037a    , A  l ",
      " lllll\u0372  l [  l ",
      "  e   l  l:Alll ",
      "  e\u037c  l\u0370ll    l ",
      "  e5  \u0373 /l    l ",
      "  ee$jl  l']+*l ",
      "      lllll%%%l ",
      "                "
    ],
    [
      "                ",
      " <%%%.<%%<l%%%l ",
      " .   \u0392l  l \u038c\u0389\u0384l ",
      " %\u0394   l \u0387l    % ",
      " %\u0395   l\u0390ll    % ",
      " %\u0395      l   \u0385l ",
      " %\u0395      \u038f oool ",
      " %\u0396      lll \u0386% ",
      " .       \u038f A  % ",
      " lllll   l A \u0387l ",
      "  ec  l  l Alll ",
      "  e\u0393  l\u0391ll    % ",
      "  \u0397   l  l    % ",
      "  \u0398eeel  l \u038e\u038a\u0388l ",
      "      l%%ll%%%l ",
      "                "
    ],
    [
      "                ",
      " <....<..<l...l ",
      " .    l  l    l ",
      " .    l  l    \u0399 ",
      " .    llll    \u0399 ",
      " .  \u039a    l    l ",
      " .       l oool ",
      " .       lll  \u0399 ",
      " .       l A  \u0399 ",
      " lllll   l A  l ",
      "  g\u0393\u039b l  l Alll ",
      "  $   llll    \u0399 ",
      "  $   l  l    \u0399 ",
      "  e\u0397\u0397\u0397l  l    l ",
      "      l..ll...l ",
      "                "
    ],
    [
      "                ",
      " llllllllllllll ",
      " leeeee\u039c\u039cleeeel ",
      " leeeee\u039c\u039cleeeel ",
      " leeeeeeeleeeel ",
      " leeeeeeeleeeel ",
      " leeeeeeeleeeel ",
      " leeeeeeelee\u039c\u039cl ",
      " leeeeeeelee\u039c\u039cl ",
      " lllll!eelee\u039c\u039cl ",
      "  e dcleeleeeel ",
      "  e   lllleeeel ",
      "  e   leeleeeel ",
      "  eeeeleeleeeel ",
      "      lllllllll ",
      "                "
    ]
  ]
}