{
  "name": "building_apartmentsmalla_floor2_90",
  "refpalette": "deceasedcraft:building_apartmentsmalla/building_apartmentsmalla_floor2_palette_90",
  "xsize": 16,
  "zsize": 16,
  "slices": [
    [
      "                ",
      " aaaaaaaaa      ",
      " abbbbbbbbeggk  ",
      " abbbbbbbbcfhj  ",
      " abbbbbbbbc  i  ",
      " abbbbbbbbd  e  ",
      " accbbbbbbbbbba ",
      " accbbbbbbbbbba ",
      " accbbbbbbbbbba ",
      " abbbbbbbbbbbba ",
      " abbbbbbbbbbbba ",
      " abbbbbccbbbbba ",
      " abbbbbccbbbbba ",
      " abbbbbccbbbbba ",
      " aaaaaaaaaaaaaa ",
      "                "
    ],
    [
      "                ",
      " lllllllll      ",
      " lt  LlQ leeee  ",
      " ls CKlQ X 5ce  ",
      " lr  JllTl2  $  ",
      " lllA l  l   $  ",
      " lq B l  Wlllll ",
      " lpxA NP V146#l ",
      " l  lll PV    l ",
      " lowo M  U 333l ",
      " lm  Il       l ",
      " lnu FllSl00 9l ",
      " lnu Elq lZ  8l ",
      " lm yDlORlY  7l ",
      " llllllllllllll ",
      "                "
    ],
    [
      "                ",
      " l%%%lllll      ",
      " l*+]'l  lj$ee  ",
      " l    l/ \u0373  5e  ",
      " l    ll\u0370l  \u037ce  ",
      " lllA:l  l   e  ",
      " l  [ l  \u0372lllll ",
      " l  A ,    \u037a\u037b . ",
      " l& lll? \u0371   \u037f% ",
      " lo)o >      \u037e% ",
      " l   ;l      \u037e% ",
      " l   |ll`l\u0376\u0377 \u037e% ",
      " l   }l  l\u0375  \u037d% ",
      " l^(-{l  l\u0374   . ",
      " l%%%l<..<....< ",
      "                "
    ],
    [
      "                ",
      " l%%%ll%%l      ",
      " l\u0388\u038a\u038e l  leee\u0398  ",
      " %    l  l   \u0397  ",
      " %    ll\u0391l  \u0393e  ",
      " lllA l  l  ce  ",
      " l\u0387 A l   lllll ",
      " %  A \u038f       . ",
      " %\u0386 lll      \u0396% ",
      " looo \u038f      \u0395% ",
      " l\u0385   l      \u0395% ",
      " %    ll\u0390l   \u0395% ",
      " %    l\u0387 l   \u0394% ",
      " l\u0384\u0389\u038c l  l\u0392   . ",
      " l%%%l<%%<.%%%< ",
      "                "
    ],
    [
      "                ",
      " l...ll..l      ",
      " l    l  l\u0397\u0397\u0397e  ",
      " \u0399    l  l   $  ",
      " \u0399    llll   $  ",
      " lllA l  l \u039b\u0393g  ",
      " l  A l   lllll ",
      " \u0399  A l       . ",
      " \u0399  lll       . ",
      " looo l       . ",
      " l    l    \u039a  . ",
      " \u0399    llll    . ",
      " \u0399    l  l    . ",
      " l    l  l    . ",
      " l...l<..<....< ",
      "                "
    ],
    [
      "                ",
      " lllllllll      ",
      " leeeeleeleeee  ",
      " leeeeleel   e  ",
      " leeeellll   e  ",
      " leeeeleelcd e  ",
      " l\u039c\u039ceelee!lllll ",
      " l\u039c\u039ceeleeeeeeel ",
      " l\u039c\u039ceeleeeeeeel ",
      " leeeeleeeeeeel ",
      " leeeeleeeeeeel ",
      " leeeeleeeeeeel ",
      " leeeel\u039c\u039ceeeeel ",
      " leeeel\u039c\u039ceeeeel ",
      " llllllllllllll ",
      "                "
    ]
  ]
}