{
  "name": "building_apartmentsmalla_floor1",
  "refpalette": "deceasedcraft:building_apartmentsmalla/building_apartmentsmalla_floor1_palette",
  "xsize": 16,
  "zsize": 16,
  "slices": [
    [
      "                ",
      " aaaaaaaaaaaaaa ",
      " abbbbbcccbbbba ",
      " abbbbbcccbbbba ",
      " abbbbbbbbbbbba ",
      " abbbbbbbbbbbba ",
      " abbbbbbbbbbbba ",
      " acccbbbbbbbbba ",
      " acccbbbbbbbbba ",
      " abbbbbbbbbbbba ",
      " abbbbbbbbdcce  ",
      " abbbbbbbb  fg  ",
      " abbbbbbbb  !g  ",
      " abbbbbbbbehij  ",
      " aaaaaaaaa      ",
      "                "
    ],
    [
      "                ",
      " kkkkkkkkkkkkkk ",
      " klmmln opkqr k ",
      " k ss t u k   k ",
      " k w  nkxyx w k ",
      " kABCD k   EFIk ",
      " kkkkkJkKkkkkkk ",
      " kLpk      kMMk ",
      " kN O  PP  Q  k ",
      " kkkk RSSTkkUkk ",
      " kVWX   Yk Z e  ",
      " k  X 0 1k  2e  ",
      " k    0 3k  ce  ",
      " k456 0 7k88ee  ",
      " kkkkkkkkk      ",
      "                "
    ],
    [
      "                ",
      " kkkkkkkkkkkkkk ",
      " 9#   n$  k  %9 ",
      " 9^   &   k  *9 ",
      " 9(   nkx)x  +9 ",
      " k-[ ] k  { }!k ",
      " |kkkk;k:kkkkkk ",
      " '  k  <   k> k ",
      " '  ,      .  k ",
      " |kkk ?//`kk\u0370kk ",
      " '\u0371\u0372\u0373    k   i  ",
      " '  \u0374    k   8  ",
      " '      \u0375k \u03762e  ",
      " ' \u0377\u037a\u037a\u037a\u037b keeee  ",
      " |'99999'k      ",
      "                "
    ],
    [
      "                ",
      " kk99kk99kk99kk ",
      " 9\u037c   n\u037d \u037ek  \u037f9 ",
      " 9\u0384   n   k  \u03859 ",
      " 9\u0386   nkxxx  \u03879 ",
      " k     k      k ",
      " |kkkk\u0388k\u0388kkkkkk ",
      " 9 \u037ek      k  9 ",
      " 9  \u0389      \u038a  9 ",
      " |kkk     kkkkk ",
      " '\u038c\u038e     k   e  ",
      " 9       k   e  ",
      " 9       kc\u038f e  ",
      " 9 \u0390\u0391\u0391\u0391\u0392 kee\u0393\u0394  ",
      " |'99999'k      ",
      "                "
    ],
    [
      "                ",
      " kk\u0395\u0395kk\u0395\u0395kk\u0395\u0395kk ",
      " '    n   k   ' ",
      " '    n   k   ' ",
      " '    nkxxx   ' ",
      " k     k      k ",
      " |kkkkkkkkkkkkk ",
      " '  k      k  ' ",
      " '  k      k  ' ",
      " |kkk     kkkkk ",
      " '       k   \u0393  ",
      " '   \u0396   k\u0397  \u0393  ",
      " '       k\u038f  \u0393  ",
      " '       kg88e  ",
      " |'''''''k      ",
      "                "
    ],
    [
      "                ",
      " kkkkkkkkkkkkkk ",
      " keeeee\u0398\u0398\u0398eeeek ",
      " keeeee\u0398\u0398\u0398eeeek ",
      " keeeeeeeeeeeek ",
      " keeeeeeeeeeeek ",
      " kkkkkkkkkkkkkk ",
      " k\u0398\u0398eeeeeeekeek ",
      " k\u0398\u0398eeeeeeekeek ",
      " keeeeeee\u0399kkkkk ",
      " keeeeeeekc  e  ",
      " keeeeeeekd  e  ",
      " keeeeeeek   e  ",
      " keeeeeeekeeee  ",
      " kkkkkkkkk      ",
      "                "
    ]
  ]
}