{
  "name": "building_apartmentsmalla_floor3_180",
  "refpalette": "deceasedcraft:building_apartmentsmalla/building_apartmentsmalla_floor3_palette_180",
  "xsize": 16,
  "zsize": 16,
  "slices": [
    [
      "                ",
      "      aaaaaaaaa ",
      "  kjiebbbbbbbba ",
      "  gh  bbbbbbbba ",
      "  gf  bbbbbbbba ",
      "  eccdbbbbbbbba ",
      " abbbbbbbbbbbba ",
      " abbbbbbbbbccca ",
      " abbbbbbbbbccca ",
      " abbbbbbbbbbbba ",
      " abbbbbbbbbbbba ",
      " abbbbbbbbbbbba ",
      " abbbbcccbbbbba ",
      " abbbbcccbbbbba ",
      " aaaaaaaaaaaaaa ",
      "                "
    ],
    [
      "                ",
      "      lllllllll ",
      "  ee%%l$ 3 #98l ",
      "  ec  l7 3  6 l ",
      "  e5  l4 3 0  l ",
      "  e 2 l1   0ZYl ",
      " llXllWVUT llll ",
      " l  S  RR  QPOl ",
      " lNNl      lqMl ",
      " llllllLlKlllll ",
      " lJIF   l EDCBl ",
      " lA  yuylo  x l ",
      " l   l w u tt l ",
      " l srlqp!omnnml ",
      " llllllllllllll ",
      "                "
    ],
    [
      "                ",
      "      l>^^^^^>: ",
      "  eeeel \u037b\u037a\u037a\u037a\u0377 > ",
      "  e5\u0376 l\u0375      > ",
      "  %   l\u0374   6  > ",
      "  j   l    \u0373\u0372!: ",
      " ll\u0371ll\u0370    lll: ",
      " l  `      /  > ",
      " l?.l   ,  l  > ",
      " llllll<l'llll: ",
      " l ; |  l | }{l ",
      " ^]  y+ylo   [^ ",
      " ^-  l   +   )^ ",
      " ^(  l  *o   &^ ",
      " llllllllllllll ",
      "                "
    ],
    [
      "                ",
      "      l>^^^^^>: ",
      "  \u0393\u0392eel \u0391\u0390\u0390\u0390\u038f ^ ",
      "  e \u038ecl       ^ ",
      "  e   l       ^ ",
      "  e   l      \u038c> ",
      " lllll     lll: ",
      " ^  \u038a      \u0389  ^ ",
      " ^  l      l\u037e ^ ",
      " llllll\u0388l\u0388llll: ",
      " l      l     l ",
      " ^\u0387  yyylo   \u0386^ ",
      " ^\u0385  l   o   \u0384^ ",
      " ^\u037f  l\u037e \u037do   \u037c^ ",
      " ll^^ll^^ll^^ll ",
      "                "
    ],
    [
      "                ",
      "      l>>>>>>>: ",
      "  e%%gl       > ",
      "  \u0392  \u038el       > ",
      "  \u0392  \u0396l   \u0395   > ",
      "  \u0392   l       > ",
      " lllll     lll: ",
      " >  l      l  > ",
      " >  l      l  > ",
      " lllllllllllll: ",
      " l      l     l ",
      " >   yyylo    > ",
      " >   l   o    > ",
      " >   l   o    > ",
      " ll\u0394\u0394ll\u0394\u0394ll\u0394\u0394ll ",
      "                "
    ],
    [
      "                ",
      "      lllllllll ",
      "  eeeeleeeeeeel ",
      "  e   leeeeeeel ",
      "  e  dleeeeeeel ",
      "  e  cleeeeeeel ",
      " lllll\u0398eeeeeeel ",
      " leeleeeeeee\u0397\u0397l ",
      " leeleeeeeee\u0397\u0397l ",
      " llllllllllllll ",
      " leeeeeeeeeeeel ",
      " leeeeeeeeeeeel ",
      " leeee\u0397\u0397\u0397eeeeel ",
      " leeee\u0397\u0397\u0397eeeeel ",
      " llllllllllllll ",
      "                "
    ]
  ]
}