{
  "name": "building_apartmentsmalla_top_180",
  "refpalette": "deceasedcraft:building_apartmentsmalla/building_apartmentsmalla_top_palette_180",
  "xsize": 16,
  "zsize": 16,
  "slices": [
    [
      "                ",
      "      aaaaaaaaa ",
      "  ihgbbbbbbbbba ",
      "  f   cccccccba ",
      "  f   cccccecba ",
      "  b  dcccccccba ",
      " abccccccccccba ",
      " abccccccccccba ",
      " abccccccccccba ",
      " abccccccccccba ",
      " abccccccccccba ",
      " abccccccccccba ",
      " abccccccccccba ",
      " abbbbbbbbbbbba ",
      " aaaaaaaaaaaaaa ",
      "                "
    ],
    [
      "                ",
      "                ",
      "  bbjjbymmbbbb  ",
      "  b   tp     b  ",
      "  b   tx   e b  ",
      "  b   txp  e w  ",
      "  bttutp   e m  ",
      "  s        erm  ",
      "  j        epn  ",
      "  j       pe b  ",
      "  b       q!pb  ",
      "  beeeeeeeqqpj  ",
      "  m o po     j  ",
      "  nkjjbmlbbkjj  ",
      "                ",
      "                "
    ],
    [
      "                ",
      "                ",
      "  bbbbbbbbkjjb  ",
      "  b   t      m  ",
      "  j   tD     m  ",
      "  h C tB     b  ",
      "  bttAt      b  ",
      "  b          b  ",
      "  b          b  ",
      "  b          b  ",
      "  b       qqpb  ",
      "  b       qq b  ",
      "  b          b  ",
      "  bbbbbbbjjjbb  ",
      "                ",
      "                "
    ],
    [
      "                ",
      "                ",
      "  bbbbbmmbbbbb  ",
      "  bIIII      b  ",
      "  bIIIIp     b  ",
      "  bIIII      b  ",
      "  bIIII      b  ",
      "  b          b  ",
      "  b          m  ",
      "  w          m  ",
      "  m       EF m  ",
      "  m       EE b  ",
      "  m          b  ",
      "  bbbmmlbbbbbb  ",
      "                ",
      "                "
    ],
    [
      "                ",
      "                ",
      "                ",
      "                ",
      "                ",
      "                ",
      "                ",
      "                ",
      "                ",
      "                ",
      "                ",
      "                ",
      "                ",
      "                ",
      "                ",
      "                "
    ],
    [
      "                ",
      "                ",
      "                ",
      "                ",
      "                ",
      "                ",
      "                ",
      "                ",
      "                ",
      "                ",
      "                ",
      "                ",
      "                ",
      "                ",
      "                ",
      "                "
    ]
  ]
}