{
  "name": "building_apartmentsmalla_ground_180",
  "refpalette": "deceasedcraft:building_apartmentsmalla/building_apartmentsmalla_ground_palette_180",
  "xsize": 16,
  "zsize": 16,
  "slices": [
    [
      "aaaaaaaaaaaaaaaa",
      "aaaaaabbbbbbbbba",
      "aaeeeebbbbbbbbba",
      "aaecccbbbbbbbbba",
      "aaecccbbbbbbbbba",
      "aaecccbbbbbbbbbd",
      "abbbbbbbbbbbbbba",
      "abbbbbbbbbbbbbbd",
      "abbbbbbbbbbbbbbd",
      "abbbbbbbbbbbbbba",
      "abbbbbbbbbbbbbba",
      "abbbbbbbbbbbbbba",
      "abbbbbbccbbbbbba",
      "abbbbbbccbbbbbba",
      "abbbbbbbbbbbbbba",
      "aaaaaaaaaaaaaaaa"
    ],
    [
      "                ",
      "      fVggggggg ",
      "  eeUUf TSSR  g ",
      "  ec  f      Qg ",
      "  eP  O  NN  Mg ",
      "  e   L     tKg ",
      " ffffff      xw ",
      " gIJJI   F   CE ",
      " g       D   CB ",
      " g AA     y  xw ",
      " gqppo   fu tsf ",
      " gqp!ofrffi  hg ",
      " gqppof nfim hg ",
      " g ll fkjfi  hg ",
      " ffffffffffffff ",
      "                "
    ],
    [
      "                ",
      "      fVggggggg ",
      "  eeeef       g ",
      "  eP7 f       g ",
      "  U   6       g ",
      "  5   4     Z3g ",
      " ffffff      xw ",
      " g            2 ",
      " g            1 ",
      " g           xw ",
      " g       f0 ZYf ",
      " g    fXffW   g ",
      " g    f  fW   g ",
      " g    f  fW   g ",
      " ffffffffffffff ",
      "                "
    ],
    [
      "                ",
      "      fVggggggg ",
      "  (*eef       g ",
      "  e &cf       g ",
      "  e   ^       g ",
      "  e   ^     $3g ",
      " ffffff      xw ",
      " g            % ",
      " g            % ",
      " g           xw ",
      " g       f  $Yf ",
      " g    f#ffW   g ",
      " g    f 9f8   g ",
      " g    f  fW   g ",
      " ffggffggffggff ",
      "                "
    ],
    [
      "                ",
      "      fVVVVVVVw ",
      "  eUU{f       V ",
      "  *  &f       V ",
      "  *  ]f       V ",
      "  *   f      [V ",
      " ffffff      xw ",
      " V    f      x  ",
      " V    f      x  ",
      " V    f      xw ",
      " V    f  f   -f ",
      " V    ffff    V ",
      " V    f  f    V ",
      " V    f  f+   V ",
      " ff))ff))ff))ff ",
      "                "
    ],
    [
      "                ",
      "      fffffffff ",
      "  eeeefeeeeeeef ",
      "  e   feeeeeeef ",
      "  e  :feeeeeeef ",
      "  e  cfeeeeeeef ",
      " ffffffeeeeeeef ",
      " feeeefee;Deeef ",
      " feeeefee|Deeef ",
      " feeeefeeeeeeef ",
      " feeeefeefeeeef ",
      " feeeeffffeeeef ",
      " feeeef}}feeeef ",
      " feeeef}}feeeef ",
      " ffffffffffffff ",
      "                "
    ]
  ]
}