{
  "name": "building_apartmentsmalla_floor3",
  "refpalette": "deceasedcraft:building_apartmentsmalla/building_apartmentsmalla_floor3_palette",
  "xsize": 16,
  "zsize": 16,
  "slices": [
    [
      "                ",
      " aaaaaaaaaaaaaa ",
      " abbbbbcccbbbba ",
      " abbbbbcccbbbba ",
      " abbbbbbbbbbbba ",
      " abbbbbbbbbbbba ",
      " abbbbbbbbbbbba ",
      " acccbbbbbbbbba ",
      " acccbbbbbbbbba ",
      " abbbbbbbbbbbba ",
      " abbbbbbbbdcce  ",
      " abbbbbbbb  fg  ",
      " abbbbbbbb  hg  ",
      " abbbbbbbbeijk  ",
      " aaaaaaaaa      ",
      "                "
    ],
    [
      "                ",
      " llllllllllllll ",
      " lmnnmo!pqlrs l ",
      " l tt u w l   l ",
      " l x  olyuy  Al ",
      " lBCDE l   FIJl ",
      " lllllKlLllllll ",
      " lMql      lNNl ",
      " lOPQ  RR  S  l ",
      " llll TUVWllXll ",
      " lYZ0   1l 2 e  ",
      " l  0 3 4l  5e  ",
      " l 6  3 7l  ce  ",
      " l89# 3 $l%%ee  ",
      " lllllllll      ",
      "                "
    ],
    [
      "                ",
      " llllllllllllll ",
      " ^&   o*  l  (^ ",
      " ^)   +   l  -^ ",
      " ^[   oly+y  ]^ ",
      " l{} | l  | ; l ",
      " :llll'l<llllll ",
      " >  l  ,   l.?l ",
      " >  /      `  l ",
      " :lll    \u0370ll\u0371ll ",
      " :!\u0372\u0373    l   j  ",
      " >  6   \u0374l   %  ",
      " >      \u0375l \u03765e  ",
      " > \u0377\u037a\u037a\u037a\u037b leeee  ",
      " :>^^^^^>l      ",
      "                "
    ],
    [
      "                ",
      " ll^^ll^^ll^^ll ",
      " ^\u037c   o\u037d \u037el  \u037f^ ",
      " ^\u0384   o   l  \u0385^ ",
      " ^\u0386   olyyy  \u0387^ ",
      " l     l      l ",
      " :llll\u0388l\u0388llllll ",
      " ^ \u037el      l  ^ ",
      " ^  \u0389      \u038a  ^ ",
      " :lll     lllll ",
      " >\u038c      l   e  ",
      " ^       l   e  ",
      " ^       lc\u038e e  ",
      " ^ \u038f\u0390\u0390\u0390\u0391 lee\u0392\u0393  ",
      " :>^^^^^>l      ",
      "                "
    ],
    [
      "                ",
      " ll\u0394\u0394ll\u0394\u0394ll\u0394\u0394ll ",
      " >    o   l   > ",
      " >    o   l   > ",
      " >    olyyy   > ",
      " l     l      l ",
      " :lllllllllllll ",
      " >  l      l  > ",
      " >  l      l  > ",
      " :lll     lllll ",
      " >       l   \u0392  ",
      " >   \u0395   l\u0396  \u0392  ",
      " >       l\u038e  \u0392  ",
      " >       lg%%e  ",
      " :>>>>>>>l      ",
      "                "
    ],
    [
      "                ",
      " llllllllllllll ",
      " leeeee\u0397\u0397\u0397eeeel ",
      " leeeee\u0397\u0397\u0397eeeel ",
      " leeeeeeeeeeeel ",
      " leeeeeeeeeeeel ",
      " llllllllllllll ",
      " l\u0397\u0397eeeeeeeleel ",
      " l\u0397\u0397eeeeeeeleel ",
      " leeeeeee\u0398lllll ",
      " leeeeeeelc  e  ",
      " leeeeeeeld  e  ",
      " leeeeeeel   e  ",
      " leeeeeeeleeee  ",
      " lllllllll      ",
      "                "
    ]
  ]
}