{
  "name": "building_apartmentsmalla_top",
  "refpalette": "deceasedcraft:building_apartmentsmalla/building_apartmentsmalla_top_palette",
  "xsize": 16,
  "zsize": 16,
  "slices": [
    [
      "                ",
      " aaaaaaaaaaaaaa ",
      " abbbbbbbbbbbba ",
      " abccccccccccba ",
      " abccccccccccba ",
      " abccccccccccba ",
      " abccccccccccba ",
      " abccccccccccba ",
      " abccccccccccba ",
      " abccccccccccba ",
      " abcccccccd  b  ",
      " abceccccc   f  ",
      " abccccccc   f  ",
      " abbbbbbbbbghi  ",
      " aaaaaaaaa      ",
      "                "
    ],
    [
      "                ",
      "                ",
      "  jjkbblmbjjkn  ",
      "  j     op o m  ",
      "  jpqqeeeeeeeb  ",
      "  bp!q       b  ",
      "  b ep       j  ",
      "  npe        j  ",
      "  mre        s  ",
      "  m e   ptuttb  ",
      "  w e  pxt   b  ",
      "  b e   xt   b  ",
      "  b     pt   b  ",
      "  bbbbmmybjjbb  ",
      "                ",
      "                "
    ],
    [
      "                ",
      "                ",
      "  bbjjjbbbbbbb  ",
      "  b          b  ",
      "  b qq       b  ",
      "  bpqq       b  ",
      "  b          b  ",
      "  b          b  ",
      "  b          b  ",
      "  b      tAttb  ",
      "  b     Bt C h  ",
      "  m     Dt   j  ",
      "  m      t   b  ",
      "  bjjkbbbbbbbb  ",
      "                ",
      "                "
    ],
    [
      "                ",
      "                ",
      "  bbbbbblmmbbb  ",
      "  b          m  ",
      "  b EE       m  ",
      "  m FE       m  ",
      "  m          w  ",
      "  m          b  ",
      "  b          b  ",
      "  b      IIIIb  ",
      "  b      IIIIb  ",
      "  b     pIIIIb  ",
      "  b      IIIIb  ",
      "  bbbbbmmbbbbb  ",
      "                ",
      "                "
    ],
    [
      "                ",
      "                ",
      "                ",
      "                ",
      "                ",
      "                ",
      "                ",
      "                ",
      "                ",
      "                ",
      "                ",
      "                ",
      "                ",
      "                ",
      "                ",
      "                "
    ],
    [
      "                ",
      "                ",
      "                ",
      "                ",
      "                ",
      "                ",
      "                ",
      "                ",
      "                ",
      "                ",
      "                ",
      "                ",
      "                ",
      "                ",
      "                ",
      "                "
    ]
  ]
}