{
  "name": "building_apartmentsmalla_floor1_270",
  "refpalette": "deceasedcraft:building_apartmentsmalla/building_apartmentsmalla_floor1_palette_270",
  "xsize": 16,
  "zsize": 16,
  "slices": [
    [
      "                ",
      " aaaaaaaaaaaaaa ",
      " abbbbbccbbbbba ",
      " abbbbbccbbbbba ",
      " abbbbbccbbbbba ",
      " abbbbbbbbbbbba ",
      " abbbbbbbbbbbba ",
      " abbbbbbbbbbcca ",
      " abbbbbbbbbbcca ",
      " abbbbbbbbbbcca ",
      "  e  dbbbbbbbba ",
      "  h  cbbbbbbbba ",
      "  i!fcbbbbbbbba ",
      "  jggebbbbbbbba ",
      "      aaaaaaaaa ",
      "                "
    ],
    [
      "                ",
      " kkkkkkkkkkkkkk ",
      " k4  VkNLkA  lk ",
      " k5  Wk pkBwsmk ",
      " k6 XXkOkkC smk ",
      " k       kD  lk ",
      " k000 R  J ntnk ",
      " k    SP kkk  k ",
      " k731YSP K xuok ",
      " kkkkkT  k y pk ",
      "  8   k  k xkkk ",
      "  8  ZkQkkE  qk ",
      "  ec2 U MkFw rk ",
      "  eeeek MkI   k ",
      "      kkkkkkkkk ",
      "                "
    ],
    [
      "                ",
      " |''''|''|k999k ",
      " '   \u0371k  k-(^#k ",
      " 9\u0377  \u0372k  k[   k ",
      " 9\u037a \u0374\u0373k,kk    k ",
      " 9\u037a      k]   k ",
      " 9\u037a   ?  ; n&nk ",
      " 9\u037b   / <kkk $k ",
      " ' \u0375  /  : x  k ",
      " kkkkk`  k )  k ",
      "  e   k  k{xkkk ",
      "  e\u0376  k.kk    k ",
      "  e2  \u0370 >k}   k ",
      "  ee8ik  k!+*%k ",
      "      kkkkk999k ",
      "                "
    ],
    [
      "                ",
      " |999'|99|k999k ",
      " '   \u038ck  k \u0386\u0384\u037ck ",
      " 9\u0390  \u038ek \u037ek    9 ",
      " 9\u0391   k\u0389kk    9 ",
      " 9\u0391      k    k ",
      " 9\u0391      \u0388 nnnk ",
      " 9\u0392      kkk \u037d9 ",
      " '       \u0388 x  9 ",
      " kkkkk   k x \u037ek ",
      "  ec  k  k xkkk ",
      "  e\u038f  k\u038akk    9 ",
      "  \u0393   k  k    9 ",
      "  \u0394eeek  k \u0387\u0385\u037fk ",
      "      k99kk999k ",
      "                "
    ],
    [
      "                ",
      " |''''|''|k'''k ",
      " '    k  k    k ",
      " '    k  k    \u0395 ",
      " '    kkkk    \u0395 ",
      " '  \u0396    k    k ",
      " '       k nnnk ",
      " '       kkk  \u0395 ",
      " '       k x  \u0395 ",
      " kkkkk   k x  k ",
      "  g\u038f\u0397 k  k xkkk ",
      "  8   kkkk    \u0395 ",
      "  8   k  k    \u0395 ",
      "  e\u0393\u0393\u0393k  k    k ",
      "      k''kk'''k ",
      "                "
    ],
    [
      "                ",
      " kkkkkkkkkkkkkk ",
      " keeeee\u0398\u0398keeeek ",
      " keeeee\u0398\u0398keeeek ",
      " keeeeeeekeeeek ",
      " keeeeeeekeeeek ",
      " keeeeeeekeeeek ",
      " keeeeeeekee\u0398\u0398k ",
      " keeeeeeekee\u0398\u0398k ",
      " kkkkk\u0399eekee\u0398\u0398k ",
      "  e dckeekeeeek ",
      "  e   kkkkeeeek ",
      "  e   keekeeeek ",
      "  eeeekeekeeeek ",
      "      kkkkkkkkk ",
      "                "
    ]
  ]
}