{
  "name": "building_apartmentsmalla_top_90",
  "refpalette": "deceasedcraft:building_apartmentsmalla/building_apartmentsmalla_top_palette_90",
  "xsize": 16,
  "zsize": 16,
  "slices": [
    [
      "                ",
      " aaaaaaaaa      ",
      " abbbbbbbbbffi  ",
      " abccccccc   h  ",
      " abccccccc   g  ",
      " abcccccccd  b  ",
      " abccccccccccba ",
      " abccccccccccba ",
      " abccccccccccba ",
      " abccccccccccba ",
      " abccccccccccba ",
      " abccccccccecba ",
      " abccccccccccba ",
      " abbbbbbbbbbbba ",
      " aaaaaaaaaaaaaa ",
      "                "
    ],
    [
      "                ",
      "                ",
      "  nmbbjjsbbbbb  ",
      "  k e    t   b  ",
      "  joe    t   j  ",
      "  j e    u   j  ",
      "  bpe    ttttb  ",
      "  moe    pxxpy  ",
      "  l e     p  m  ",
      "  b e        m  ",
      "  b qqp      b  ",
      "  k q!eeeeee b  ",
      "  j pp pr    b  ",
      "  jjjbbnmmwbbb  ",
      "                ",
      "                "
    ],
    [
      "                ",
      "                ",
      "  bbbbbbbbhjbb  ",
      "  b      t   b  ",
      "  b      tC  b  ",
      "  b      A   b  ",
      "  b      ttttb  ",
      "  b       BD b  ",
      "  b          b  ",
      "  j          b  ",
      "  j qq       k  ",
      "  j qq       j  ",
      "  b  p       j  ",
      "  bbbbbbbbbmmb  ",
      "                ",
      "                "
    ],
    [
      "                ",
      "                ",
      "  bmmmwbbbbbbb  ",
      "  b      IIIIb  ",
      "  b      IIIIb  ",
      "  m      IIIIb  ",
      "  m      IIIIb  ",
      "  l        p m  ",
      "  b          m  ",
      "  b          b  ",
      "  b EE       b  ",
      "  b EF       b  ",
      "  b          b  ",
      "  bbbmmmbbbbbb  ",
      "                ",
      "                "
    ],
    [
      "                ",
      "                ",
      "                ",
      "                ",
      "                ",
      "                ",
      "                ",
      "                ",
      "                ",
      "                ",
      "                ",
      "                ",
      "                ",
      "                ",
      "                ",
      "                "
    ],
    [
      "                ",
      "                ",
      "                ",
      "                ",
      "                ",
      "                ",
      "                ",
      "                ",
      "                ",
      "                ",
      "                ",
      "                ",
      "                ",
      "                ",
      "                ",
      "                "
    ]
  ]
}