{
  "name": "building_apartmentsmalla_floor2_180",
  "refpalette": "deceasedcraft:building_apartmentsmalla/building_apartmentsmalla_floor2_palette_180",
  "xsize": 16,
  "zsize": 16,
  "slices": [
    [
      "                ",
      "      aaaaaaaaa ",
      "  kjiebbbbbbbba ",
      "  gh  bbbbbbbba ",
      "  gf  bbbbbbbba ",
      "  eccdbbbbbbbba ",
      " abbbbbbbbbbbba ",
      " abbbbbbbbbccca ",
      " abbbbbbbbbccca ",
      " abbbbbbbbbbbba ",
      " abbbbbbbbbbbba ",
      " abbbbbbbbbbbba ",
      " abbbbcccbbbbba ",
      " abbbbcccbbbbba ",
      " aaaaaaaaaaaaaa ",
      "                "
    ],
    [
      "                ",
      "      lllllllll ",
      "  ee$$l# 3 987l ",
      "  ec  l6 3    l ",
      "  e5  l4 3 0  l ",
      "  e 2 l1   0ZYl ",
      " llXllWVVU llll ",
      " l  T   P  S Rl ",
      " lQQl  P   lqOl ",
      " llllllNlMlllll ",
      " lLKJ   l IFEDl ",
      " l C ABAlo   yl ",
      " l   l x w uu l ",
      " ltsrlqp omnnml ",
      " llllllllllllll ",
      "                "
    ],
    [
      "                ",
      "      l.%%%%%.< ",
      "  eeeel \u037f\u037e\u037e\u037e\u037d . ",
      "  e5\u037c l\u037b      . ",
      "  $   l\u037a   \u0377  . ",
      "  j   l    \u0376\u0375\u0374. ",
      " ll\u0373ll\u0372 \u0371  lll< ",
      " l  \u0370      `  . ",
      " l /l   ?  l  . ",
      " llllll,l>llll< ",
      " l'  :  l ;|}{l ",
      " %]  A[Alo   -% ",
      " %+  l   )   (% ",
      " %*  l  &o   ^% ",
      " llllllllllllll ",
      "                "
    ],
    [
      "                ",
      "      l.%%%%%.< ",
      "  \u0398\u0397eel \u0396\u0395\u0395\u0395\u0394 % ",
      "  e \u0393cl       % ",
      "  e   l       % ",
      "  e   l      \u0392. ",
      " lllll     lll< ",
      " %  \u0391      \u0390  % ",
      " %  l      l\u0387 % ",
      " llllll\u038fl\u038fllll< ",
      " l      l     l ",
      " %\u038e  AAAlo   \u038c% ",
      " %\u038a  l   o   \u0389% ",
      " %\u0388  l\u0387 \u0386o\u0385  \u0384% ",
      " ll%%ll%%ll%%ll ",
      "                "
    ],
    [
      "                ",
      "      l.......< ",
      "  e$$gl       . ",
      "  \u0397  \u0393l       . ",
      "  \u0397  \u039bl   \u039a   . ",
      "  \u0397   l       . ",
      " lllll     lll< ",
      " .  l      l  . ",
      " .  l      l  . ",
      " lllllllllllll< ",
      " l      l     l ",
      " .   AAAlo    . ",
      " .   l   o    . ",
      " .   l   o    . ",
      " ll\u0399\u0399ll\u0399\u0399ll\u0399\u0399ll ",
      "                "
    ],
    [
      "                ",
      "      lllllllll ",
      "  eeeeleeeeeeel ",
      "  e   leeeeeeel ",
      "  e  dleeeeeeel ",
      "  e  cleeeeeeel ",
      " lllll!eeeeeeel ",
      " leeleeeeeee\u039c\u039cl ",
      " leeleeeeeee\u039c\u039cl ",
      " llllllllllllll ",
      " leeeeeeeeeeeel ",
      " leeeeeeeeeeeel ",
      " leeee\u039c\u039c\u039ceeeeel ",
      " leeee\u039c\u039c\u039ceeeeel ",
      " llllllllllllll ",
      "                "
    ]
  ]
}