{
  "name": "building_apartmentsmalla_floor2",
  "refpalette": "deceasedcraft:building_apartmentsmalla/building_apartmentsmalla_floor2_palette",
  "xsize": 16,
  "zsize": 16,
  "slices": [
    [
      "                ",
      " aaaaaaaaaaaaaa ",
      " abbbbbcccbbbba ",
      " abbbbbcccbbbba ",
      " abbbbbbbbbbbba ",
      " abbbbbbbbbbbba ",
      " abbbbbbbbbbbba ",
      " acccbbbbbbbbba ",
      " acccbbbbbbbbba ",
      " abbbbbbbbbbbba ",
      " abbbbbbbbdcce  ",
      " abbbbbbbb  fg  ",
      " abbbbbbbb  hg  ",
      " abbbbbbbbeijk  ",
      " aaaaaaaaa      ",
      "                "
    ],
    [
      "                ",
      " llllllllllllll ",
      " lmnnmo pqlrstl ",
      " l uu w x l   l ",
      " ly   olABA C l ",
      " lDEFI l   JKLl ",
      " lllllMlNllllll ",
      " lOql   P  lQQl ",
      " lR S  P   T  l ",
      " llll UVVWllXll ",
      " lYZ0   1l 2 e  ",
      " l  0 3 4l  5e  ",
      " l    3 6l  ce  ",
      " l789 3 #l$$ee  ",
      " lllllllll      ",
      "                "
    ],
    [
      "                ",
      " llllllllllllll ",
      " %^   o&  l  *% ",
      " %(   )   l  +% ",
      " %-   olA[A  ]% ",
      " l{}|; l  :  'l ",
      " <llll>l,llllll ",
      " .  l  ?   l/ l ",
      " .  `      \u0370  l ",
      " <lll  \u0371 \u0372ll\u0373ll ",
      " .\u0374\u0375\u0376    l   j  ",
      " .  \u0377   \u037al   $  ",
      " .      \u037bl \u037c5e  ",
      " . \u037d\u037e\u037e\u037e\u037f leeee  ",
      " <.%%%%%.l      ",
      "                "
    ],
    [
      "                ",
      " ll%%ll%%ll%%ll ",
      " %\u0384  \u0385o\u0386 \u0387l  \u0388% ",
      " %\u0389   o   l  \u038a% ",
      " %\u038c   olAAA  \u038e% ",
      " l     l      l ",
      " <llll\u038fl\u038fllllll ",
      " % \u0387l      l  % ",
      " %  \u0390      \u0391  % ",
      " <lll     lllll ",
      " .\u0392      l   e  ",
      " %       l   e  ",
      " %       lc\u0393 e  ",
      " % \u0394\u0395\u0395\u0395\u0396 lee\u0397\u0398  ",
      " <.%%%%%.l      ",
      "                "
    ],
    [
      "                ",
      " ll\u0399\u0399ll\u0399\u0399ll\u0399\u0399ll ",
      " .    o   l   . ",
      " .    o   l   . ",
      " .    olAAA   . ",
      " l     l      l ",
      " <lllllllllllll ",
      " .  l      l  . ",
      " .  l      l  . ",
      " <lll     lllll ",
      " .       l   \u0397  ",
      " .   \u039a   l\u039b  \u0397  ",
      " .       l\u0393  \u0397  ",
      " .       lg$$e  ",
      " <.......l      ",
      "                "
    ],
    [
      "                ",
      " llllllllllllll ",
      " leeeee\u039c\u039c\u039ceeeel ",
      " leeeee\u039c\u039c\u039ceeeel ",
      " leeeeeeeeeeeel ",
      " leeeeeeeeeeeel ",
      " llllllllllllll ",
      " l\u039c\u039ceeeeeeeleel ",
      " l\u039c\u039ceeeeeeeleel ",
      " leeeeeee!lllll ",
      " leeeeeeelc  e  ",
      " leeeeeeeld  e  ",
      " leeeeeeel   e  ",
      " leeeeeeeleeee  ",
      " lllllllll      ",
      "                "
    ]
  ]
}