{
  "name": "building_apartmentsmalla_ground",
  "refpalette": "deceasedcraft:building_apartmentsmalla/building_apartmentsmalla_ground_palette",
  "xsize": 16,
  "zsize": 16,
  "slices": [
    [
      "aaaaaaaaaaaaaaaa",
      "abbbbbbbbbbbbbba",
      "abbbbbbccbbbbbba",
      "abbbbbbccbbbbbba",
      "abbbbbbbbbbbbbba",
      "abbbbbbbbbbbbbba",
      "abbbbbbbbbbbbbba",
      "dbbbbbbbbbbbbbba",
      "dbbbbbbbbbbbbbba",
      "abbbbbbbbbbbbbba",
      "dbbbbbbbbbccceaa",
      "abbbbbbbbbccceaa",
      "abbbbbbbbbccceaa",
      "abbbbbbbbbeeeeaa",
      "abbbbbbbbbaaaaaa",
      "aaaaaaaaaaaaaaaa"
    ],
    [
      "                ",
      " ffffffffffffff ",
      " gh  ifjkf ll g ",
      " gh mifn foppqg ",
      " gh  iffrfo!pqg ",
      " fst uf   oppqg ",
      " wx  y     AA g ",
      " BC   D       g ",
      " EC   F   IJJIg ",
      " wx      ffffff ",
      " gKt     L   e  ",
      " gM  NN  O  Pe  ",
      " gQ      f  ce  ",
      " g  RSST fUUee  ",
      " gggggggVf      ",
      "                "
    ],
    [
      "                ",
      " ffffffffffffff ",
      " g   Wf  f    g ",
      " g   Wf  f    g ",
      " g   WffXf    g ",
      " fYZ 0f       g ",
      " wx           g ",
      " 1            g ",
      " 2            g ",
      " wx      ffffff ",
      " g3Z     4   5  ",
      " g       6   U  ",
      " g       f 7Pe  ",
      " g       feeee  ",
      " gggggggVf      ",
      "                "
    ],
    [
      "                ",
      " ffggffggffggff ",
      " g   Wf  f    g ",
      " g   8f9 f    g ",
      " g   Wff#f    g ",
      " fY$  f       g ",
      " wx           g ",
      " %            g ",
      " %            g ",
      " wx      ffffff ",
      " g3$     ^   e  ",
      " g       ^   e  ",
      " g       fc& e  ",
      " g       fee*(  ",
      " gggggggVf      ",
      "                "
    ],
    [
      "                ",
      " ff))ff))ff))ff ",
      " V   +f  f    V ",
      " V    f  f    V ",
      " V    ffff    V ",
      " f-   f  f    V ",
      " wx      f    V ",
      "  x      f    V ",
      "  x      f    V ",
      " wx      ffffff ",
      " V[      f   *  ",
      " V       f]  *  ",
      " V       f&  *  ",
      " V       f{UUe  ",
      " wVVVVVVVf      ",
      "                "
    ],
    [
      "                ",
      " ffffffffffffff ",
      " feeeef}}feeeef ",
      " feeeef}}feeeef ",
      " feeeeffffeeeef ",
      " feeeefeefeeeef ",
      " feeeeeeefeeeef ",
      " feeeD|eefeeeef ",
      " feeeD;eefeeeef ",
      " feeeeeeeffffff ",
      " feeeeeeefc  e  ",
      " feeeeeeef:  e  ",
      " feeeeeeef   e  ",
      " feeeeeeefeeee  ",
      " fffffffff      ",
      "                "
    ]
  ]
}