{
  "name": "building_apartmentsmalla_floor1_90",
  "refpalette": "deceasedcraft:building_apartmentsmalla/building_apartmentsmalla_floor1_palette_90",
  "xsize": 16,
  "zsize": 16,
  "slices": [
    [
      "                ",
      " aaaaaaaaa      ",
      " abbbbbbbbeggj  ",
      " abbbbbbbbcf!i  ",
      " abbbbbbbbc  h  ",
      " abbbbbbbbd  e  ",
      " accbbbbbbbbbba ",
      " accbbbbbbbbbba ",
      " accbbbbbbbbbba ",
      " abbbbbbbbbbbba ",
      " abbbbbbbbbbbba ",
      " abbbbbccbbbbba ",
      " abbbbbccbbbbba ",
      " abbbbbccbbbbba ",
      " aaaaaaaaaaaaaa ",
      "                "
    ],
    [
      "                ",
      " kkkkkkkkk      ",
      " k   IkM keeee  ",
      " kr wFkM U 2ce  ",
      " kq  EkkQkZ  8  ",
      " kkkx k  k   8  ",
      " kp y k  Tkkkkk ",
      " koux K PSY137k ",
      " k  kkk PS    k ",
      " kntn J  R 000k ",
      " kl  Dk       k ",
      " kms CkkOkXX 6k ",
      " kmswBkp kW  5k ",
      " kl  AkLNkV  4k ",
      " kkkkkkkkkkkkkk ",
      "                "
    ],
    [
      "                ",
      " k999kkkkk      ",
      " k%*+!k  ki8ee  ",
      " k   }k> \u0370  2e  ",
      " k    kk.k  \u0376e  ",
      " kkkx{k  k   e  ",
      " k  ) k  `kkkkk ",
      " k  x :  /  \u0375 ' ",
      " k$ kkk< /   \u037b9 ",
      " kn&n ;  ?   \u037a9 ",
      " k   ]k      \u037a9 ",
      " k    kk,k\u0373\u0374 \u037a9 ",
      " k   [k  k\u0372  \u03779 ",
      " k#^(-k  k\u0371   ' ",
      " k999k|''|''''| ",
      "                "
    ],
    [
      "                ",
      " k999kk99k      ",
      " k\u037f\u0385\u0387 k  keee\u0394  ",
      " 9    k  k   \u0393  ",
      " 9    kk\u038ak  \u038fe  ",
      " kkkx k  k  ce  ",
      " k\u037e x k   kkkkk ",
      " 9  x \u0388       ' ",
      " 9\u037d kkk      \u03929 ",
      " knnn \u0388      \u03919 ",
      " k    k      \u03919 ",
      " 9    kk\u0389k   \u03919 ",
      " 9    k\u037e k\u038e  \u03909 ",
      " k\u037c\u0384\u0386 k  k\u038c   ' ",
      " k999k|99|'999| ",
      "                "
    ],
    [
      "                ",
      " k'''kk''k      ",
      " k    k  k\u0393\u0393\u0393e  ",
      " \u0395    k  k   8  ",
      " \u0395    kkkk   8  ",
      " kkkx k  k \u0397\u038fg  ",
      " k  x k   kkkkk ",
      " \u0395  x k       ' ",
      " \u0395  kkk       ' ",
      " knnn k       ' ",
      " k    k    \u0396  ' ",
      " \u0395    kkkk    ' ",
      " \u0395    k  k    ' ",
      " k    k  k    ' ",
      " k'''k|''|''''| ",
      "                "
    ],
    [
      "                ",
      " kkkkkkkkk      ",
      " keeeekeekeeee  ",
      " keeeekeek   e  ",
      " keeeekkkk   e  ",
      " keeeekeekcd e  ",
      " k\u0398\u0398eekee\u0399kkkkk ",
      " k\u0398\u0398eekeeeeeeek ",
      " k\u0398\u0398eekeeeeeeek ",
      " keeeekeeeeeeek ",
      " keeeekeeeeeeek ",
      " keeeekeeeeeeek ",
      " keeeek\u0398\u0398eeeeek ",
      " keeeek\u0398\u0398eeeeek ",
      " kkkkkkkkkkkkkk ",
      "                "
    ]
  ]
}