{
  "name": "building_apartmentsmalla_floor1_180",
  "refpalette": "deceasedcraft:building_apartmentsmalla/building_apartmentsmalla_floor1_palette_180",
  "xsize": 16,
  "zsize": 16,
  "slices": [
    [
      "                ",
      "      aaaaaaaaa ",
      "  jihebbbbbbbba ",
      "  g!  bbbbbbbba ",
      "  gf  bbbbbbbba ",
      "  eccdbbbbbbbba ",
      " abbbbbbbbbbbba ",
      " abbbbbbbbbccca ",
      " abbbbbbbbbccca ",
      " abbbbbbbbbbbba ",
      " abbbbbbbbbbbba ",
      " abbbbbbbbbbbba ",
      " abbbbcccbbbbba ",
      " abbbbcccbbbbba ",
      " aaaaaaaaaaaaaa ",
      "                "
    ],
    [
      "                ",
      "      kkkkkkkkk ",
      "  ee88k7 0 654k ",
      "  ec  k3 0    k ",
      "  e2  k1 0 X  k ",
      "  e Z kY   XWVk ",
      " kkUkkTSSR kkkk ",
      " k  Q  PP  O Nk ",
      " kMMk      kpLk ",
      " kkkkkkKkJkkkkk ",
      " kIFE   k DCBAk ",
      " k w xyxkn  w k ",
      " k   k u t ss k ",
      " k rqkpo nlmmlk ",
      " kkkkkkkkkkkkkk ",
      "                "
    ],
    [
      "                ",
      "      k'99999'| ",
      "  eeeek \u037b\u037a\u037a\u037a\u0377 ' ",
      "  e2\u0376 k\u0375      ' ",
      "  8   k    \u0374  ' ",
      "  i   k    \u0373\u0372\u0371' ",
      " kk\u0370kk`//? kkk| ",
      " k  .      ,  ' ",
      " k >k   <  k  ' ",
      " kkkkkk:k;kkkk| ",
      " k!} {  k ] [-k ",
      " 9+  x)xkn   (9 ",
      " 9*  k   &   ^9 ",
      " 9%  k  $n   #9 ",
      " kkkkkkkkkkkkkk ",
      "                "
    ],
    [
      "                ",
      "      k'99999'| ",
      "  \u0394\u0393eek \u0392\u0391\u0391\u0391\u0390 9 ",
      "  e \u038fck       9 ",
      "  e   k       9 ",
      "  e   k     \u038e\u038c' ",
      " kkkkk     kkk| ",
      " 9  \u038a      \u0389  9 ",
      " 9  k      k\u037e 9 ",
      " kkkkkk\u0388k\u0388kkkk| ",
      " k      k     k ",
      " 9\u0387  xxxkn   \u03869 ",
      " 9\u0385  k   n   \u03849 ",
      " 9\u037f  k\u037e \u037dn   \u037c9 ",
      " kk99kk99kk99kk ",
      "                "
    ],
    [
      "                ",
      "      k'''''''| ",
      "  e88gk       ' ",
      "  \u0393  \u038fk       ' ",
      "  \u0393  \u0397k   \u0396   ' ",
      "  \u0393   k       ' ",
      " kkkkk     kkk| ",
      " '  k      k  ' ",
      " '  k      k  ' ",
      " kkkkkkkkkkkkk| ",
      " k      k     k ",
      " '   xxxkn    ' ",
      " '   k   n    ' ",
      " '   k   n    ' ",
      " kk\u0395\u0395kk\u0395\u0395kk\u0395\u0395kk ",
      "                "
    ],
    [
      "                ",
      "      kkkkkkkkk ",
      "  eeeekeeeeeeek ",
      "  e   keeeeeeek ",
      "  e  dkeeeeeeek ",
      "  e  ckeeeeeeek ",
      " kkkkk\u0399eeeeeeek ",
      " keekeeeeeee\u0398\u0398k ",
      " keekeeeeeee\u0398\u0398k ",
      " kkkkkkkkkkkkkk ",
      " keeeeeeeeeeeek ",
      " keeeeeeeeeeeek ",
      " keeee\u0398\u0398\u0398eeeeek ",
      " keeee\u0398\u0398\u0398eeeeek ",
      " kkkkkkkkkkkkkk ",
      "                "
    ]
  ]
}