{
  "name": "building_apartmentsmalla_ground_90",
  "refpalette": "deceasedcraft:building_apartmentsmalla/building_apartmentsmalla_ground_palette_90",
  "xsize": 16,
  "zsize": 16,
  "slices": [
    [
      "aaaaaaaaaaaaaaaa",
      "abbbbbbbbbaaaaaa",
      "abbbbbbbbbeeeeaa",
      "abbbbbbbbbccceaa",
      "abbbbbbbbbccceaa",
      "abbbbbbbbbccceaa",
      "abbbbbbbbbbbbbba",
      "abccbbbbbbbbbbba",
      "abccbbbbbbbbbbba",
      "abbbbbbbbbbbbbba",
      "abbbbbbbbbbbbbba",
      "abbbbbbbbbbbbbba",
      "abbbbbbbbbbbbbba",
      "abbbbbbbbbbbbbba",
      "abbbbbbbbbbbbbba",
      "aaaaaaaddadaaaaa"
    ],
    [
      "                ",
      " fgggggggf      ",
      " f qqq  Ifeeee  ",
      " flpppA Jf Pce  ",
      " flp!pA Jf   U  ",
      " f ooo  If   U  ",
      " ffff    fLOfff ",
      " fk r         V ",
      " fjnf        Tg ",
      " fffff DF  N Sg ",
      " fiiiuy    N Sg ",
      " f m         Rg ",
      " f   t    t   g ",
      " fhhhsxCCxKMQ g ",
      " fgggfwBEwggggg ",
      "                "
    ],
    [
      "                ",
      " fgggggggf      ",
      " f       f5Uee  ",
      " f       f  Pe  ",
      " f       f  7e  ",
      " f       f   e  ",
      " ffff    f46fff ",
      " f  X         V ",
      " f  f         g ",
      " fffff        g ",
      " fWWW0        g ",
      " f            g ",
      " f   Z    Z   g ",
      " f   Yx  x3   g ",
      " fgggfw12wggggg ",
      "                "
    ],
    [
      "                ",
      " fgggggggf      ",
      " f       feee(  ",
      " g       f   *  ",
      " g       f  &e  ",
      " f       f  ce  ",
      " ffff    f^^fff ",
      " g  #         V ",
      " g 9f         g ",
      " fffff        g ",
      " fW8W         g ",
      " g            g ",
      " g   $    $   g ",
      " f   Yx  x3   g ",
      " fgggfw%%wggggg ",
      "                "
    ],
    [
      "                ",
      " fVVVVVVVf      ",
      " f       f***e  ",
      " )       f   U  ",
      " )       f   U  ",
      " f       f ]&{  ",
      " ffffffffffffff ",
      " )  f         V ",
      " )  f         V ",
      " fffff        V ",
      " f+           V ",
      " )            V ",
      " )            V ",
      " f   -xxxx[   V ",
      " fVVVfw  wVVVVw ",
      "                "
    ],
    [
      "                ",
      " fffffffff      ",
      " feeeeeeefeeee  ",
      " feeeeeeef   e  ",
      " feeeeeeef   e  ",
      " feeeeeeefc: e  ",
      " ffffffffffffff ",
      " f}}feeeeeeeeef ",
      " f}}feeeeeeeeef ",
      " fffffe|;eeeeef ",
      " feeeeeDDeeeeef ",
      " feeeeeeeeeeeef ",
      " feeeeeeeeeeeef ",
      " feeeeeeeeeeeef ",
      " ffffffffffffff ",
      "                "
    ]
  ]
}