{
  "name": "building_apartmentsmalla_top_270",
  "refpalette": "deceasedcraft:building_apartmentsmalla/building_apartmentsmalla_top_palette_270",
  "xsize": 16,
  "zsize": 16,
  "slices": [
    [
      "                ",
      " aaaaaaaaaaaaaa ",
      " abbbbbbbbbbbba ",
      " abccccccccccba ",
      " abceccccccccba ",
      " abccccccccccba ",
      " abccccccccccba ",
      " abccccccccccba ",
      " abccccccccccba ",
      " abccccccccccba ",
      "  b  dcccccccba ",
      "  g   cccccccba ",
      "  h   cccccccba ",
      "  iffbbbbbbbbba ",
      "      aaaaaaaaa ",
      "                "
    ],
    [
      "                ",
      "                ",
      "  bbbwmmnbbjjj  ",
      "  b    rp pp j  ",
      "  b eeeeee!q k  ",
      "  b      pqq b  ",
      "  m        e b  ",
      "  m  p     e l  ",
      "  ypxxp    eom  ",
      "  btttt    epb  ",
      "  j   u    e j  ",
      "  j   t    eoj  ",
      "  b   t    e k  ",
      "  bbbbbsjjbbmn  ",
      "                ",
      "                "
    ],
    [
      "                ",
      "                ",
      "  bmmbbbbbbbbb  ",
      "  j       p  b  ",
      "  j       qq j  ",
      "  k       qq j  ",
      "  b          j  ",
      "  b          b  ",
      "  b DB       b  ",
      "  btttt      b  ",
      "  b   A      b  ",
      "  b  Ct      b  ",
      "  b   t      b  ",
      "  bbjhbbbbbbbb  ",
      "                ",
      "                "
    ],
    [
      "                ",
      "                ",
      "  bbbbbbmmmbbb  ",
      "  b          b  ",
      "  b       FE b  ",
      "  b       EE b  ",
      "  b          b  ",
      "  m          b  ",
      "  m p        l  ",
      "  bIIII      m  ",
      "  bIIII      m  ",
      "  bIIII      b  ",
      "  bIIII      b  ",
      "  bbbbbbbwmmmb  ",
      "                ",
      "                "
    ],
    [
      "                ",
      "                ",
      "                ",
      "                ",
      "                ",
      "                ",
      "                ",
      "                ",
      "                ",
      "                ",
      "                ",
      "                ",
      "                ",
      "                ",
      "                ",
      "                "
    ],
    [
      "                ",
      "                ",
      "                ",
      "                ",
      "                ",
      "                ",
      "                ",
      "                ",
      "                ",
      "                ",
      "                ",
      "                ",
      "                ",
      "                ",
      "                ",
      "                "
    ]
  ]
}