{
  "name": "multi_taigaresidence_5_base2",
  "refpalette": "deceasedcraft:multi_taigaresidence_5/multi_taigaresidence_5_base2_palette",
  "xsize": 16,
  "zsize": 16,
  "slices": [
    [
      "HHHHHHHHHHHHabbv",
      "HHHHHHaaaaHHabbv",
      "HHHHHHaccaHHabbv",
      "HHHHHHaccaHHabbv",
      "HHHHHHdccaHHabbv",
      "HHHHHHaccaHHabbv",
      "HHHHHHaccaHHabbv",
      "HHHHHHaccaHHabbv",
      "HHHHHHaccaHHabbv",
      "HHHHHHaccaHHabbv",
      "HHHHHHaaaaHHabbv",
      "HHHHHHaHHHHHabbv",
      "HHHHHHaHHHHHabbv",
      "aaaaaaaaaaaaabbv",
      "bbbbbbbbbbbbbbbv",
      "vvvvvvvvvvvvvvvv"
    ],
    [
      "          eeabbv",
      "fgfh  aaaaeeabbv",
      "   h  aiiaHHabbv",
      "jkjh  almaHHabbv",
      "nnnh  o paHHabbv",
      "fgfh  ampaHHabbv",
      "   h  ap aHHabbv",
      "jkjh  aqraHHabbv",
      "      a laHHabbv",
      "      a!qaHHabbv",
      "fgfgfsaaaaHHabbv",
      "     saHHHHHabbv",
      "jkjkjsaHHHHHabbv",
      "aaaaaaaaaaaaabbv",
      "bbbbbbbbbbbbbbbv",
      "vvvvvvvvvvvvvvvv"
    ],
    [
      "            abbv",
      "      aaaa  abbv",
      "      a ia  abbv",
      "      a  a  abbv",
      "      t  aeeabbv",
      "      a  aeeabbv",
      "      a  aHHabbv",
      "      a  aHHabbv",
      "      a  aHHabbv",
      "      al aHHabbv",
      "      aaaaHHabbv",
      "      aHHHHHabbv",
      "      aHHHHHabbv",
      "aaaaaaaaaaaaabbv",
      "bbbbbbbbbbbbbbbv",
      "vvvvvvvvvvvvvvvv"
    ],
    [
      "      u     abbv",
      "      aaaa  abbv",
      "      al a  abbv",
      "      a  a  abbv",
      "      w  a  abbv",
      "      a  a  abbv",
      "      a  a  abbv",
      "      a la  abbv",
      "      axxaeeabbv",
      "      axxaeeabbv",
      "      aaaaHHabbv",
      "      aHHHHHabbv",
      "      aHHHHHabbv",
      "aaaaaaaaaaaaabbv",
      "bbbbbbbbbbbbbbbv",
      "vvvvvvvvvvvvvvvv"
    ],
    [
      "     ya     abbv",
      "     yaaaa  abbv",
      "yyyyyyalla  abbv",
      "     ya  a  abbv",
      "     yaxxa  abbv",
      "     yaxxa  abbv",
      "     yadda  abbv",
      "     yadda  abbv",
      "     yaHHa  abbv",
      "     yaHHa  abbv",
      "     yaeea  abbv",
      "     yaee   abbv",
      "yyyyyyaee   abbv",
      "aaaaaaaaaaaaabbv",
      "bbbbbbbbbbbbbbbv",
      "vvvvvvvvvvvvvvvv"
    ],
    [
      "AAAAAAaxxxxxabbv",
      "AAAAAAaaaaaaabbv",
      "AAAAAAadda  abbv",
      "AAAAAAadda  abbv",
      "AAAAAAaHHa  abbv",
      "AAAAAAaHHa  abbv",
      "AAAAAAaeea  abbv",
      "AAAAAAaeea  abbv",
      "AAAAAAa  a  abbv",
      "AAAAAAa  a  abbv",
      "AAAAAAa  a  abbv",
      "AAAAAAa     abbv",
      "AAAAAAa     abbv",
      "aaaaaaaaaaaaabbv",
      "bbbbbbbbbbbbbbbv",
      "vvvvvvvvvvvvvvvv"
    ]
  ]
}