{
  "name": "multi_taigaresidence_5_ground",
  "refpalette": "deceasedcraft:multi_taigaresidence_5/multi_taigaresidence_5_ground_palette",
  "xsize": 16,
  "zsize": 16,
  "slices": [
    [
      "aaaaaabHHHHHHHHH",
      "aaaaaabHHbbbbccc",
      "aaaaaabddb  beee",
      "aaaaaabddb  bacc",
      "aaaaaab  b  bacc",
      "aaaaaab  b  bffc",
      "aaaaaab  b  bccc",
      "aaaaaab  b  bccc",
      "aaaaaab  b  bccc",
      "aaaaaab  g  bccc",
      "aaaaaab  g  bccc",
      "aaaaaab     bccc",
      "aaaaaab     bccc",
      "bbbbbbbbbbbbbccc",
      "cccccccccccccccc",
      "cccccccccccccccc"
    ],
    [
      "      b         ",
      "     ab  bbbb   ",
      "h    ib  b  beee",
      "jjj  ib  b  b   ",
      "     ib  b  b   ",
      "kkk  ib  g  bff ",
      "      b  g  b   ",
      "jjj  lb     b m ",
      "     lb     b   ",
      "kkk  lb     b m ",
      "     nb     b   ",
      "bbbbbbb     b m ",
      "oooooob     b   ",
      "bbbbbbbbbbbbb m ",
      "                ",
      "                "
    ],
    [
      "     pb         ",
      "     ab  bbbb   ",
      "      b     beee",
      "qrs   b     b   ",
      "      b     b   ",
      " tq   b     bff ",
      "     pb         ",
      "u s   b       p ",
      "      b         ",
      "s u   b       p ",
      "      b         ",
      "      b       p ",
      "      b         ",
      "              p ",
      "                ",
      "                "
    ],
    [
      "      b     w   ",
      "     ab  bbbb   ",
      "      b     beee",
      "     xb     b   ",
      "      b     b   ",
      "  y  Ab     bff ",
      "      b         ",
      "B     b       C ",
      "      b         ",
      "  D   b       C ",
      "      b         ",
      "      b       C ",
      "      b         ",
      "              C ",
      "                ",
      "                "
    ],
    [
      "      b     b   ",
      "     abbbbbbb   ",
      "      b     beee",
      "      b     b   ",
      "      b     b   ",
      "      b     bff ",
      "      b         ",
      "      b       C ",
      "      b         ",
      "      b       C ",
      "      b         ",
      "      b       C ",
      "      b         ",
      "              C ",
      "                ",
      "                "
    ],
    [
      "      bEEEEEb   ",
      "     abbbbbbb   ",
      "      b     beee",
      "      b     b   ",
      "      b     b   ",
      "      b     bff ",
      "      b         ",
      "      b       F ",
      "      b         ",
      "      b       F ",
      "      b         ",
      "      b       F ",
      "      b         ",
      "              F ",
      "                ",
      "                "
    ]
  ]
}