{
  "name": "multi_taigaresidence_5_base1",
  "refpalette": "deceasedcraft:multi_taigaresidence_5/multi_taigaresidence_5_base1_palette",
  "xsize": 16,
  "zsize": 16,
  "slices": [
    [
      "HHHHHHHHHHHHabbv",
      "HHHHHHaHHaaaabbv",
      "HHHHHHaccaddabbv",
      "HHHHHHaccaddabbv",
      "HHHHHHa  a  abbv",
      "HHHHHHa  a  abbv",
      "HHHHHHa  a  abbv",
      "HHHHHHa  a  abbv",
      "HHHHHHa  a  abbv",
      "HHHHHHa  a  abbv",
      "HHHHHHa  a  abbv",
      "HHHHHHa     abbv",
      "HHHHHHa     abbv",
      "aaaaaaaaaaaaabbv",
      "bbbbbbbbbbbbbbbv",
      "vvvvvvvvvvvvvvvv"
    ],
    [
      "          ccabbv",
      "efeg  a  accabbv",
      "   g  a  aHHabbv",
      "hihg  a  aHHabbv",
      "jjjg  a  akkabbv",
      "efeg  a  akkabbv",
      "   g  a  addabbv",
      "hihg  a  addabbv",
      "      a  a  abbv",
      "      a  a  abbv",
      "efefega  a  abbv",
      "     ga     abbv",
      "hihihga     abbv",
      "aaaaaaaaaaaaabbv",
      "bbbbbbbbbbbbbbbv",
      "vvvvvvvvvvvvvvvv"
    ],
    [
      "            abbv",
      "      a  a  abbv",
      "      a  a  abbv",
      "      a  a  abbv",
      "      a  accabbv",
      "      a  accabbv",
      "      a  aHHabbv",
      "      a  aHHabbv",
      "      a  akkabbv",
      "      a  akkabbv",
      "      a  a  abbv",
      "      a     abbv",
      "      a     abbv",
      "aaaaaaaaaaaaabbv",
      "bbbbbbbbbbbbbbbv",
      "vvvvvvvvvvvvvvvv"
    ],
    [
      "      l     abbv",
      "      a  a  abbv",
      "      a  a  abbv",
      "      a  a  abbv",
      "      a  a  abbv",
      "      a  a  abbv",
      "      a  a  abbv",
      "      a  a  abbv",
      "      addaccabbv",
      "      addaccabbv",
      "      a  aHHabbv",
      "      a  HHHabbv",
      "      a  HHHabbv",
      "aaaaaaaaaaaaabbv",
      "bbbbbbbbbbbbbbbv",
      "vvvvvvvvvvvvvvvv"
    ],
    [
      "     ma     abbv",
      "     ma  a  abbv",
      "mmmmm!a  a  abbv",
      "     ma  a  abbv",
      "     madda  abbv",
      "     madda  abbv",
      "     makka  abbv",
      "     makka  abbv",
      "     maHHa  abbv",
      "     maHHa  abbv",
      "     macca  abbv",
      "     macc   abbv",
      "mmmmmmacc   abbv",
      "aaaaaaaaaaaaabbv",
      "bbbbbbbbbbbbbbbv",
      "vvvvvvvvvvvvvvvv"
    ],
    [
      "nnnnnnadddddabbv",
      "nnnnnnaaaaaaabbv",
      "nnnnnnakka  abbv",
      "nnnnnnakka  abbv",
      "nnnnnnaHHa  abbv",
      "nnnnnnaHHa  abbv",
      "nnnnnnacca  abbv",
      "nnnnnnacca  abbv",
      "nnnnnna  a  abbv",
      "nnnnnna  a  abbv",
      "nnnnnna  a  abbv",
      "nnnnnna     abbv",
      "nnnnnna     abbv",
      "aaaaaaaaaaaaabbv",
      "bbbbbbbbbbbbbbbv",
      "vvvvvvvvvvvvvvvv"
    ]
  ]
}