{
  "name": "multi_taigaresidence_5_floor3",
  "refpalette": "deceasedcraft:multi_taigaresidence_5/multi_taigaresidence_5_floor3_palette",
  "xsize": 16,
  "zsize": 16,
  "slices": [
    [
      "aaaaabcddeeefg  ",
      "cccccccddeeefg  ",
      "deeeddddddddfhhh",
      "deeeddddddddfij ",
      "deeeddddddddfij ",
      "ddddddddddddfij ",
      "ddddddddddddfij ",
      "ddddddddddddfij ",
      "ddddddddddddfij ",
      "ddddddddddddfij ",
      "ddddddddddddfij ",
      "ffkkkffffffffij ",
      "fggggghiiiiiiij ",
      "      hjjjjjjjj ",
      "      h         ",
      "                "
    ],
    [
      "      l  m  n   ",
      "ffffoff pqrqf   ",
      "qs q tq uq wfhhh",
      "qx y tq Aq Bfi  ",
      "qqCq pq Dq Efi  ",
      "qE q uq  m Ffi  ",
      "qF y Aq  qqqfi  ",
      "qqqq Iq BJKKfi  ",
      "q!KK  q BJ  fi  ",
      "qL  BJq     fi  ",
      "qL   Jq   MNfi  ",
      "ff   fffOOOffi  ",
      "f     hiiiiiii  ",
      "      h         ",
      "      h         ",
      "                "
    ],
    [
      "      P  Q R    ",
      "ffffSff TqUqf   ",
      "q Vq  q  q !fhhh",
      "q  W  q  q  f   ",
      "qqXq Yq Zq  f   ",
      "q0 q  q  Q  f   ",
      "q0 W  q 1qqqf   ",
      "qqqq 2q  34 f   ",
      "q  5 1q     f   ",
      "q     q     f   ",
      "q     q     f   ",
      "ff   fff   ff   ",
      "f     h         ",
      "      h         ",
      "      h         ",
      "                "
    ],
    [
      "      6  q 7    ",
      "ffff8ff  qqqf   ",
      "q 9q  q  q  fhhh",
      "q  q  q  q  f   ",
      "qqqq  q  q  f   ",
      "q  q  q  q  f   ",
      "q# q  q  qqqf   ",
      "qqqq  q     f   ",
      "q     q     f   ",
      "q     q     f   ",
      "q     q     f   ",
      "ff   fff   ff   ",
      "f     h         ",
      "      h         ",
      "      h         ",
      "                "
    ],
    [
      "      f  q  f   ",
      "fffffff  qqqf   ",
      "q  q  q $q  fhhh",
      "q  q  q  q  f%  ",
      "qqqq  q  q  f%  ",
      "q  q  q  q  f%  ",
      "q  q  q  qqqf%  ",
      "qqqq  q     f%  ",
      "q     q     f%  ",
      "q     q  ^  f%  ",
      "q     q     f%  ",
      "fffffffffffff%  ",
      "f     h%%%%%%%  ",
      "      h         ",
      "      h         ",
      "                "
    ],
    [
      "      f&&&&&f   ",
      "fffffff&&&&&f   ",
      "&&&&&&&&&&&&fhhh",
      "&&&&&&&&&&&&f*  ",
      "&&&&&&&&&&&&f*  ",
      "&&&&&&&&&&&&f*  ",
      "&&&&&&&&&&&&f*  ",
      "&&&&&&&&&&&&f*  ",
      "&&&&&&&&&&&&f*  ",
      "&&&&&&&&&&&&f*  ",
      "&&&&&&&&&&&&f*  ",
      "fffffffffffff*  ",
      "f     h*******  ",
      "((((((h         ",
      "      h         ",
      "                "
    ]
  ]
}