{
  "name": "multi_taigaresidence_5_floor2",
  "refpalette": "deceasedcraft:multi_taigaresidence_5/multi_taigaresidence_5_floor2_palette",
  "xsize": 16,
  "zsize": 16,
  "slices": [
    [
      "aaaaabcccdddef  ",
      "cccccccccdddef  ",
      "cccccccccdddeggg",
      "cccccccccdddehi ",
      "cccccccccdddehi ",
      "cccccccccdddehi ",
      "cccccccccdddehi ",
      "cccccccccdddehi ",
      "cccccccccdddehi ",
      "ccccccccccccehi ",
      "ccccccccccccehi ",
      "ccccceeeeeeeehi ",
      "ggggggghhhhhhhi ",
      "gggggggiiiiiiii ",
      "ggggggg         ",
      "                "
    ],
    [
      "         j  k   ",
      "     eeeleeee   ",
      " m nnoep eqreggg",
      "m     es j !eh  ",
      "   nnoes eeeeh  ",
      "      es j  eh  ",
      "t  nnoes eeeeh  ",
      "u    wep j  eh  ",
      "x    eee eeeeh  ",
      "            eh  ",
      "       yy yyeh  ",
      "     eeeAAAeeh  ",
      "      ghhhhhhh  ",
      "      g         ",
      "      g         ",
      "                "
    ],
    [
      "         B      ",
      "     eeeCeeee   ",
      "      eD e  eggg",
      "     Ee  B Fe   ",
      "      e  eeee   ",
      "     Ee  B Fe   ",
      "      eI eeee   ",
      "      e  B Fe   ",
      "J   Eeee eeee   ",
      "            e   ",
      "      K     e   ",
      "     eee   ee   ",
      "      g         ",
      "      g         ",
      "      g         ",
      "                "
    ],
    [
      "         e      ",
      "     eeeLeeee   ",
      "      e  e  eggg",
      "      e  e Me   ",
      "      e  eeee   ",
      "      e  e Me   ",
      "      e  eeee   ",
      "      e  e Me   ",
      "     eeeNeeee   ",
      "            e   ",
      "            e   ",
      "     eee   ee   ",
      "      g         ",
      "      g         ",
      "      g         ",
      "                "
    ],
    [
      "         e  e   ",
      "     eeeeeeee   ",
      "      e  e  eggg",
      "      e  e  eO  ",
      "      e  eeeeO  ",
      "      e  e  eO  ",
      "      e  eeeeO  ",
      "      e  e  eO  ",
      "     eeeeeeeeO  ",
      "            eO  ",
      "            eO  ",
      "eeeeeeeeeeeeeO  ",
      "PPPPPPgOOOOOOO  ",
      "      g         ",
      "      g         ",
      "                "
    ],
    [
      "      QQQeRRe   ",
      "LLLLLeeeeeeee   ",
      "aaaaaaeRReRReggg",
      "aaaaaaeRReRReS  ",
      "aaaaaaeRReeeeS  ",
      "aaaaaaeRReRReS  ",
      "aaaaaaeRReeeeS  ",
      "aaaaaaeRReRReS  ",
      "NNNNNeeeeeeeeS  ",
      "aaaaaaaaaaaaeS  ",
      "aaaaaaaaaaaaeS  ",
      "eeeeeeeeeeeeeS  ",
      "e     gSSSSSSS  ",
      "TTTTTTg         ",
      "      g         ",
      "                "
    ]
  ]
}