{
  "name": "multi_taigaresidence_5_floor4",
  "refpalette": "deceasedcraft:multi_taigaresidence_5/multi_taigaresidence_5_floor4_palette",
  "xsize": 16,
  "zsize": 16,
  "slices": [
    [
      "aaaaabcddeeefg  ",
      "cccccccddeeefg  ",
      "dddddddddeeefhhh",
      "dddddddddeeefij ",
      "ddddddddddddfij ",
      "ddddddddddddfij ",
      "ddddddddddddfij ",
      "ddddddddddddfij ",
      "ddddddddddddfij ",
      "ddddddddddddfij ",
      "ddddddddddddfij ",
      "ffkkkffffffffij ",
      "fggggghiiiiiiij ",
      "      hjjjjjjjj ",
      "      h         ",
      "                "
    ],
    [
      "      l  m  n   ",
      "fffffff  opqf   ",
      "orstuwxy o Afhhh",
      "oB    x  oCofi  ",
      "oB    xy o Dfi  ",
      "oE       F Dfi  ",
      "o     oooo Dfi  ",
      "oI    oJ    fi  ",
      "oJ K LoMN  Ofi  ",
      "oJ K PoMN yQfi  ",
      "o     oJ   Rfi  ",
      "ff   fffSSSffi  ",
      "f     hiiiiiii  ",
      "      h         ",
      "      h         ",
      "                "
    ],
    [
      "      T  U      ",
      "fffffff  o  f   ",
      "o    V   o Wfhhh",
      "oX       oYof   ",
      "o        o Df   ",
      "o     Z  0 Df   ",
      "o1   1oooo Df   ",
      "o     o2 3  f   ",
      "o4    o     f   ",
      "o     o    5f   ",
      "o     o    6f   ",
      "ff   fff   ff   ",
      "f     h         ",
      "      h         ",
      "      h         ",
      "                "
    ],
    [
      "      7  o      ",
      "fffffff  o  f   ",
      "o  8     o 9fhhh",
      "o        ooof   ",
      "o        o !f   ",
      "o        o  f   ",
      "o     oooo  f   ",
      "o     o     f   ",
      "o     o     f   ",
      "o     o     f   ",
      "o     o     f   ",
      "ff   fff   ff   ",
      "f     h         ",
      "      h         ",
      "      h         ",
      "                "
    ],
    [
      "      f  o  f   ",
      "fffffff  o  f   ",
      "o        o  fhhh",
      "o        ooof#  ",
      "o  $     o  f#  ",
      "o        o  f#  ",
      "o     oooo  f#  ",
      "o     o     f#  ",
      "o  % ^o&    f#  ",
      "o     o  %  f#  ",
      "o     o     f#  ",
      "fffffffffffff#  ",
      "f     h#######  ",
      "      h         ",
      "      h         ",
      "                "
    ],
    [
      "      f*****f   ",
      "fffffff*****f   ",
      "************fhhh",
      "************f(  ",
      "************f(  ",
      "************f(  ",
      "************f(  ",
      "************f(  ",
      "************f(  ",
      "************f(  ",
      "************f(  ",
      "fffffffffffff(  ",
      "f     h(((((((  ",
      "))))))h         ",
      "      h         ",
      "                "
    ]
  ]
}