{
  "name": "multi_taigaresidence_5_floor7",
  "refpalette": "deceasedcraft:multi_taigaresidence_5/multi_taigaresidence_5_floor7_palette",
  "xsize": 16,
  "zsize": 16,
  "slices": [
    [
      "aaaaabccccccde  ",
      "ffffffffffffde  ",
      "ggggggggggggdhhh",
      "ggggggggggggdf  ",
      "ggggggggggggdf  ",
      "ggggggggggggdf  ",
      "ggggggggggggdf  ",
      "ggggggggggggdf  ",
      "ggggggggggggdf  ",
      "ggggggggggggdf  ",
      "ggggggggggggdf  ",
      "iiiiiiiiiiiijf  ",
      "kkkkkkhfffffff  ",
      "      h         ",
      "      h         ",
      "                "
    ],
    [
      "        llllm   ",
      "            m   ",
      "        nnn mohh",
      "       pqqqrmshh",
      "       pqqqrmshh",
      "       pqqqrmshh",
      "            mshh",
      "       pqqqrmshh",
      "       pq!qrmshh",
      "       pqqqrmshh",
      "        ttt mshh",
      "mmmmmmmmmmmmmshh",
      "      ussssssshh",
      "      hhhhhhhhhh",
      "      hhhhhhhhhh",
      "                "
    ],
    [
      "            m   ",
      "            m   ",
      "            m   ",
      "        w x m   ",
      "         y  m   ",
      "        A B m   ",
      "        ~   m   ",
      "        w x m   ",
      "         y  m   ",
      "        A B m   ",
      "            m   ",
      "mmmmmmmmmmmmm   ",
      "                ",
      "                ",
      "                ",
      "                "
    ],
    [
      "                ",
      "                ",
      "                ",
      "        CDE     ",
      "        F I     ",
      "        JKL     ",
      "        ~       ",
      "        CDE     ",
      "        F I     ",
      "        JKL     ",
      "                ",
      "            M   ",
      "                ",
      "                ",
      "                ",
      "                "
    ],
    [
      "                ",
      "                ",
      "                ",
      "        NOP     ",
      "        Q R     ",
      "        STU     ",
      "        ~       ",
      "        NOP     ",
      "        Q R     ",
      "        STU     ",
      "                ",
      "                ",
      "                ",
      "                ",
      "                ",
      "                "
    ],
    [
      "                ",
      "                ",
      "                ",
      "        VWX     ",
      "        Y Z     ",
      "        012     ",
      "        ~       ",
      "        VWX     ",
      "        Y Z     ",
      "        012     ",
      "                ",
      "                ",
      "                ",
      "                ",
      "                ",
      "                "
    ]
  ]
}