{
  "name": "multi_taigaresidence_5_floor1",
  "refpalette": "deceasedcraft:multi_taigaresidence_5/multi_taigaresidence_5_floor1_palette",
  "xsize": 16,
  "zsize": 16,
  "slices": [
    [
      "aaaaabccccccde  ",
      "ffffffddddddde  ",
      "      d     dggg",
      "      d     d   ",
      "      d     d   ",
      "      d     dhh ",
      "      d         ",
      "      d         ",
      "      d         ",
      "      d         ",
      "      d         ",
      "      d         ",
      "      d         ",
      "                ",
      "                ",
      "                "
    ],
    [
      "      i  j  k   ",
      "llllllddddddd   ",
      "      d     dggg",
      "      d     d   ",
      "      d     d   ",
      "      d     dhh ",
      "      d     dm  ",
      "      d     dm  ",
      "      d     dm  ",
      "      d     dm  ",
      "      d     dm  ",
      "dddddddddddddm  ",
      "mmmmmmdmmmmmmm  ",
      "                ",
      "                ",
      "                "
    ],
    [
      "      n  o      ",
      "      ddddddd   ",
      "      d     dggg",
      "      d     d   ",
      "      d     d   ",
      "      d     dhh ",
      "      d     d   ",
      "      d     d   ",
      "      d     d   ",
      "      d     d   ",
      "      d     d   ",
      "ddddddddddddd   ",
      "      d         ",
      "                ",
      "                ",
      "                "
    ],
    [
      "      d  p      ",
      "      ddddddd   ",
      "      d     dggg",
      "      d     d   ",
      "      d     d   ",
      "      d     dhh ",
      "      d     dhh ",
      "      d     dhh ",
      "      d     dhh ",
      "      d     dhh ",
      "      d     dhh ",
      "dddddddddddddhh ",
      "hhhhhhhhhhhhhhh ",
      "hhhhhhhhhhhhhhh ",
      "                ",
      "                "
    ],
    [
      "      d  d  d   ",
      "      ddddddd   ",
      "      d     dggg",
      "      d     d   ",
      "      d     d   ",
      "      d     d   ",
      "      d     d   ",
      "      d     d   ",
      "      d     d   ",
      "      d     d   ",
      "qrqqqqd     d   ",
      "ddddddddddddd   ",
      "                ",
      "                ",
      "                ",
      "                "
    ],
    [
      "      dsssssd   ",
      "llllllddddddd   ",
      "ttttttdsssssdggg",
      "ttttttdsssssdl  ",
      "ttttttdsuuusdl  ",
      "ttttttdsssssdl  ",
      "ttttttdsssssdl  ",
      "ttttttdsssssdl  ",
      "ttttttdsuuusdl  ",
      "ttttttdsssssdl  ",
      "ttttttdsssssdl  ",
      "dddddddddddddl  ",
      "llllllllllllll  ",
      "                ",
      "                ",
      "                "
    ]
  ]
}