{
  "name": "multi_taigaresidence_5_floor5",
  "refpalette": "deceasedcraft:multi_taigaresidence_5/multi_taigaresidence_5_floor5_palette",
  "xsize": 16,
  "zsize": 16,
  "slices": [
    [
      "aaaaabcddeeefg  ",
      "cccccccddeeefg  ",
      "deeeddddddhifjjj",
      "deeedddddklmi n ",
      "deeedddddhmkk n ",
      "dddddddddoimf n ",
      "ddddddddddddfpn ",
      "ddddddddddddfpn ",
      "ddddddddddddfpn ",
      "ddddddddddddfpn ",
      "ddddddddddddfpn ",
      "ffqqqffffffffpn ",
      "fgggggjpppppppn ",
      "      jnnnnnnnn ",
      "      j         ",
      "                "
    ],
    [
      "      r  s  t   ",
      "ffffuff wxyxf   ",
      "xA x  x liBmojCj",
      "xD E  xmF   I   ",
      "xxJx  x KB  m   ",
      "xL xM xKN   O   ",
      "xP E  x  xxxf   ",
      "xxxxQ x RSTTfp  ",
      "xL M  x  S  fp  ",
      "xP   QxR    fp  ",
      "xPQ   x!  UVfp  ",
      "ff   fffWWWffp  ",
      "f     jppppppp  ",
      "      j         ",
      "      j         ",
      "                "
    ],
    [
      "      X  Y Z    ",
      "ffff0ff  x1xf   ",
      "x 2x  x Ii    jj",
      "x  3  x         ",
      "xx4x  x         ",
      "x  x  x         ",
      "x  3  x 5xxxO   ",
      "xxxx  x  67 f   ",
      "x     x  8  f   ",
      "x     x     f   ",
      "xP    x     f   ",
      "ff   fff   ff   ",
      "f     j         ",
      "      j         ",
      "      j         ",
      "                "
    ],
    [
      "      9  x #    ",
      "ffff$ff  xxxf   ",
      "x %x  x  x  ^CCj",
      "x  x  x         ",
      "xxxx  x         ",
      "x  x  x     ^   ",
      "x  x  x  xxxf   ",
      "xxxx  x     f   ",
      "x     x     f   ",
      "x     x     f   ",
      "x     x     f   ",
      "ff   fff   ff   ",
      "f     j         ",
      "      j         ",
      "      j         ",
      "                "
    ],
    [
      "      f  x  f   ",
      "fffffff  xxxf   ",
      "x  x Lx  x  fjjj",
      "x  x  x  x  O&  ",
      "xxxx  x  x  ^&  ",
      "x  x  x  x  f&  ",
      "xL x Lx  xxxf&  ",
      "xxxx  x     f&  ",
      "x     x     f&  ",
      "x     x     f&  ",
      "xL   Lx     f&  ",
      "fffffffffffff&  ",
      "f     j&&&&&&&  ",
      "      j         ",
      "      j         ",
      "                "
    ],
    [
      "      f*****f   ",
      "fffffff*****f   ",
      "************fjjj",
      "************f(  ",
      "************f(  ",
      "************f(  ",
      "************f(  ",
      "************f(  ",
      "************f(  ",
      "************f(  ",
      "************f(  ",
      "fffffffffffff(  ",
      "f     j(((((((  ",
      "))))))j         ",
      "      j         ",
      "                "
    ]
  ]
}