{
  "name": "multi_taigaresidence_5_floor6",
  "refpalette": "deceasedcraft:multi_taigaresidence_5/multi_taigaresidence_5_floor6_palette",
  "xsize": 16,
  "zsize": 16,
  "slices": [
    [
      "aaaaabcdddddef  ",
      "cccccccdddddef  ",
      "ggggggggggggehhh",
      "ggggggggggggeij ",
      "ggggggggggggeij ",
      "ggggggggggggeij ",
      "ggggggggggggeij ",
      "ggggggggggggeij ",
      "cccccccgggggeij ",
      "cccccccgggggeij ",
      "cccccccgggggeij ",
      "ccccccceeeeeeij ",
      "kkkkkkhiiiiiiij ",
      "      hjjjjjjjj ",
      "      h         ",
      "                "
    ],
    [
      "     lem   no   ",
      "peeeeeeqrqqqe   ",
      "  ssssqt uuuehhh",
      "      qw    ei  ",
      "x y   A     ei  ",
      "x B   q    Cei  ",
      "      qD  EFei  ",
      "IID   qD  EFei  ",
      "     ee    Cei  ",
      "      J  K  ei  ",
      "  LL  e MNO ei  ",
      "     eeePPPeei  ",
      "      hiiiiiii  ",
      "      h         ",
      "      h         ",
      "                "
    ],
    [
      "     ie   Q     ",
      "ReeeeeeqSqqqe   ",
      " TUV  qW uuuehhh",
      "      q     e   ",
      "      X     e   ",
      "      qY    e   ",
      "      qZ    e   ",
      "0 1  2q3    e   ",
      "     ee    4e   ",
      "      5     e   ",
      "     2e2   2e   ",
      "     eee   ee   ",
      "      h         ",
      "      h         ",
      "      h         ",
      "                "
    ],
    [
      "     ie6        ",
      "7eeeeeeqqqqqe   ",
      "   !  q   89ehhh",
      "      q     e   ",
      "      q     e   ",
      "      q     e   ",
      "      q     e   ",
      "     #q     e   ",
      "     ee     e   ",
      "      $     e   ",
      "      e     e   ",
      "     eee   ee   ",
      "      h         ",
      "      h         ",
      "      h         ",
      "                "
    ],
    [
      "     %e  ^  e   ",
      "eeeeeeeqqqqqe   ",
      "      q     ehhh",
      "      q     e&  ",
      "      q     e&  ",
      "*    ^q    (e&  ",
      "      q  *  e&  ",
      "      q     e&  ",
      "     ee    (e&  ",
      "      e     e&  ",
      "      e     e&  ",
      "eeeeeeeeeeeee&  ",
      "      h&&&&&&&  ",
      "      h         ",
      "      h         ",
      "                "
    ],
    [
      "      e)))))e   ",
      "eeeeeee)))))e   ",
      "))))))))))))ehhh",
      "))))))))))))e+  ",
      "))))))))))))e+  ",
      "))))))))))))e+  ",
      "))))))))))))e+  ",
      "))))))))))))e+  ",
      "-----ee)))))e+  ",
      "aaaaaae)))))e+  ",
      "aaaaaae)))))e+  ",
      "eeeeeeeeeeeee+  ",
      "      h+++++++  ",
      "[[[[[[h         ",
      "      h         ",
      "                "
    ]
  ]
}