{
  "name": "multi_officethefirst_3_floor8",
  "refpalette": "deceasedcraft:multi_officethefirst_3/multi_officethefirst_3_floor8_palette",
  "xsize": 16,
  "zsize": 16,
  "slices": [
    [
      "aaaaaabaaaa     ",
      "cccccccccca     ",
      "dddddddddca     ",
      "dddddddddca     ",
      "dddddddddca     ",
      "dddddddddca     ",
      "dddddddddca     ",
      "eeeeeeeedca     ",
      "  c   fedca     ",
      "  c  ghedca     ",
      "cccccccccca     ",
      "aaaaaaaaaaa     ",
      "                ",
      "                ",
      "                ",
      "               i"
    ],
    [
      "      b         ",
      "jjjjjjjjjj      ",
      "k  lmln oj      ",
      " pqr!r   j      ",
      "  ssmss  j      ",
      "    t    j      ",
      "u   wxy  j      ",
      "ABeccccc j      ",
      "  c    C j      ",
      "  c gD cEj      ",
      "jjjjjjjjjj      ",
      "                ",
      "                ",
      "                ",
      "                ",
      "                "
    ],
    [
      "      b         ",
      "FFFFFFFFFF      ",
      "   IJK  LF      ",
      "   MLN   F      ",
      "  O J P  F      ",
      "         F      ",
      "Q    R   F      ",
      " Beccccc F      ",
      "  cS   T F      ",
      "  chD  cUF      ",
      "FFFFFFFFFF      ",
      "                ",
      "                ",
      "                ",
      "                ",
      "                "
    ],
    [
      "      b         ",
      "FFFFFFFFFF      ",
      "         F      ",
      "         F      ",
      "         F      ",
      "         F      ",
      "V    W   F      ",
      "XBeccccc F      ",
      "  chY  Z F      ",
      "  cf   c F      ",
      "FFFFFFFFFF      ",
      "                ",
      "                ",
      "                ",
      "                ",
      "                "
    ],
    [
      "      b         ",
      "FFFFFFFFFF      ",
      "         F      ",
      "         F      ",
      "         F      ",
      "         F      ",
      "         F      ",
      "BBeccccc F      ",
      "  c 0Y c F      ",
      "  c    c F      ",
      "FFFFFFFFFF      ",
      "                ",
      "                ",
      "                ",
      "                ",
      "                "
    ],
    [
      "      b         ",
      "jjjjjjjjjj      ",
      "111111111j      ",
      "111111111j      ",
      "112111121j      ",
      "111111111j      ",
      "111111111j      ",
      "eeeccccc j      ",
      "  c  0hc3j      ",
      "  c   Sc j      ",
      "jjjjjjjjjj      ",
      "                ",
      "                ",
      "                ",
      "                ",
      "                "
    ]
  ]
}