{
  "name": "multi_officethefirst_3_base2",
  "refpalette": "deceasedcraft:multi_officethefirst_3/multi_officethefirst_3_base2_palette",
  "xsize": 16,
  "zsize": 16,
  "slices": [
    [
      "   abbb cd    cv",
      "   efffgcd    cv",
      "    hhhhcd    cv",
      "        cd    cv",
      "        cd    cv",
      "        cd    cv",
      "        cd    cv",
      "ii      cccccccv",
      "jki     cl    cv",
      "jji     cml   cv",
      "jji     cnn   cv",
      "jji     cnn   cv",
      "ii      cml   cv",
      "     o  cl    cv",
      "cccccccccccccccv",
      "vvvvvvvvvvvvvvvv"
    ],
    [
      "   appp cq    cv",
      "   frsstcq    cv",
      "    uwwwxq    cv",
      "        cq    cv",
      "        cq    cv",
      "        cq    cv",
      "        c y   cv",
      "ii      cccccccv",
      "jji     c     cv",
      "jji     cAl   cv",
      "jji     cB    cv",
      "jji     cB    cv",
      "ii      cAl   cv",
      "     o  c     cv",
      "cccccccccccccccv",
      "vvvvvvvvvvvvvvvv"
    ],
    [
      "   appp c     cv",
      "   fCDEFc     cv",
      "        I     cv",
      "        c     cv",
      "        c     cv",
      "        c     cv",
      "        c  y  cv",
      "ii      cccccccv",
      "jki     c     cv",
      "jJi     cAl   cv",
      "jji     cK    cv",
      "jJi     cK    cv",
      "ii      cAl   cv",
      "     o  c     cv",
      "cccccccccccccccv",
      "vvvvvvvvvvvvvvvv"
    ],
    [
      "   appp c    dcv",
      "   fCDDFc    dcv",
      "        cL   dcv",
      "        c    dcv",
      "        c    dcv",
      "        c    dcv",
      "        c   ydcv",
      "ii      cccccccv",
      "jMi     c     cv",
      "jji     cAl   cv",
      "jjiN    cB    cv",
      "jjioN   cB    cv",
      "ii OoN  cAl   cv",
      "    Oo  c     cv",
      "cccccccccccccccv",
      "vvvvvvvvvvvvvvvv"
    ],
    [
      "   appp c    Pcv",
      "   fCEDFc    Pcv",
      "        c    Pcv",
      "        c    Pcv",
      "       Qc    Pcv",
      "        c    Pcv",
      "        c     cv",
      "ii      cccccccv",
      "jJi     cl    cv",
      "jji     cRl   cv",
      "jji     cSS   cv",
      "jki     cSS   cv",
      "ii      cRl   cv",
      "     o  cl    cv",
      "cccccccccccccccv",
      "vvvvvvvvvvvvvvvv"
    ],
    [
      "   apppTc     cv",
      "   f!DEUc     cv",
      "       Tc     cv",
      "        c     cv",
      "       Vc     cv",
      "       Tc     cv",
      "       Tc     cv",
      "ii     Tcccccccv",
      "jji    TcW    cv",
      "jjiX   TcYl   cv",
      "jjZ0TTTTc12   cv",
      "jki     c12   cv",
      "ii      cgl   cv",
      "     o  c3    cv",
      "cccccccccccccccv",
      "vvvvvvvvvvvvvvvv"
    ]
  ]
}