{
  "name": "multi_officethefirst_3_floor12",
  "refpalette": "deceasedcraft:multi_officethefirst_3/multi_officethefirst_3_floor12_palette",
  "xsize": 16,
  "zsize": 16,
  "slices": [
    [
      "aaaaaabaaaa     ",
      "cccccccccca     ",
      "         ca     ",
      "         ca     ",
      "         ca     ",
      "         ca     ",
      "de       ca     ",
      "fffccccc ca     ",
      "  c   gc ca     ",
      "  c  hic ca     ",
      "cccccccccca     ",
      "aaaaaaaaaaa     ",
      "                ",
      "                ",
      "                ",
      "                "
    ],
    [
      "      b         ",
      "jjjjjjjjjj      ",
      "         j      ",
      "         j      ",
      "         j      ",
      "         j      ",
      "kl       j      ",
      "fffccccc j      ",
      "  c    c j      ",
      "  c hm c j      ",
      "jjjjjjjjjj      ",
      "                ",
      "                ",
      "                ",
      "                ",
      "                "
    ],
    [
      "      b         ",
      "nnnnnnnnnn      ",
      "         n      ",
      "         n      ",
      "         n      ",
      "         n      ",
      "op       n      ",
      "fffccccc n      ",
      "  cq   c n      ",
      "  cim  c n      ",
      "nnnnnnnnnn      ",
      "                ",
      "                ",
      "                ",
      "                ",
      "                "
    ],
    [
      "      b         ",
      "nnnnnnnnnn      ",
      "         n      ",
      "         n      ",
      "         n      ",
      "         n      ",
      "rs       n      ",
      "fffccccc n      ",
      "  cit  c n      ",
      "  cg   c n      ",
      "nnnnnnnnnn      ",
      "                ",
      "                ",
      "                ",
      "                ",
      "                "
    ],
    [
      "      b         ",
      "nnnnnnnnnn      ",
      "         n      ",
      "         n      ",
      "         n      ",
      "         n      ",
      "         n      ",
      "fffccccc n      ",
      "  c ut c n      ",
      "  c    c n      ",
      "nnnnnnnnnn      ",
      "                ",
      "                ",
      "                ",
      "                ",
      "                "
    ],
    [
      "      b         ",
      "jjjjjjjjjj      ",
      "wwwwwwwwwj      ",
      "wwwwwwwwwj      ",
      "wwxwwwwywj      ",
      "wwwwwwwwwj      ",
      "wwwwwwwwwj      ",
      "fffcccccqj      ",
      "  c  uicqj      ",
      "  c   qcqj      ",
      "jjjjjjjjjj      ",
      "                ",
      "                ",
      "                ",
      "                ",
      "                "
    ]
  ]
}