{
  "name": "multi_officethefirst_3_floor3",
  "refpalette": "deceasedcraft:multi_officethefirst_3/multi_officethefirst_3_floor3_palette",
  "xsize": 16,
  "zsize": 16,
  "slices": [
    [
      "aaaaaabaacd     ",
      "aaaaaaaaacd     ",
      "aaaaaaaaacd     ",
      "aaaaaaaaacd     ",
      "aaaaaaaaacd     ",
      "aaaaaaaaacd     ",
      "aaaaaaaaacd     ",
      "aaaaaaaaacd     ",
      "aaaabbbbbcef    ",
      "aaaabbbgh  f    ",
      "aaaabbbi   f    ",
      "cccccccj   k    ",
      "       fffff    ",
      "lmn  o          ",
      "                ",
      "               p"
    ],
    [
      "  qr  s tu      ",
      "  wx    wu      ",
      "  yA    yu      ",
      " BCD    Eu      ",
      " F!IJKLMNu      ",
      " Otr    qu      ",
      " Pwx    wu      ",
      "         u      ",
      " Q RcScTccef    ",
      "QUQ c VWXh f    ",
      "YQ Zc 0W   f    ",
      "cccccccW   k    ",
      "       fffff    ",
      "  mmno          ",
      "                ",
      "                "
    ],
    [
      "  1   s 23      ",
      "         3      ",
      "         3      ",
      "   4     3      ",
      "  15    63      ",
      "  71    43      ",
      "         3      ",
      "         3      ",
      "   8c9c#ccef    ",
      " $  c  W Xgf    ",
      "    c  W  %f    ",
      "^^^^&ccW  %*    ",
      "     ( fffff    ",
      "    mo)         ",
      "                ",
      "                "
    ],
    [
      "      s  3      ",
      "         3      ",
      "         3      ",
      "         3      ",
      "         3      ",
      "         3      ",
      "         3      ",
      "         3      ",
      "   +c-c-ccef    ",
      "    c [W  jf    ",
      "]{]{c} W  |f    ",
      "cccccccW %gk    ",
      "       fffff    ",
      "  mm;o          ",
      "                ",
      "                "
    ],
    [
      "      s  3      ",
      "         3      ",
      "         3      ",
      "         3      ",
      "         3      ",
      "         3      ",
      "         3      ",
      "         3      ",
      "    ccccccef    ",
      "    c  W   f    ",
      "::::c'<W   f    ",
      "cccccccW%> k    ",
      "       fffff    ",
      ",m;  o          ",
      "                ",
      "                "
    ],
    [
      "..?...b?.u      ",
      ".........u      ",
      ".........u      ",
      ".........u      ",
      ".........u      ",
      "..?....?.u      ",
      ".........u      ",
      ".........u      ",
      "////ccccccef    ",
      "////c``h   f    ",
      "\u0370\u0370\u0370\u0370c\u0371\u0372h   f    ",
      "cccccccg>  k    ",
      "       fffff    ",
      "m    o          ",
      "                ",
      "                "
    ]
  ]
}