{
  "name": "multi_officethefirst_3_floor6",
  "refpalette": "deceasedcraft:multi_officethefirst_3/multi_officethefirst_3_floor6_palette",
  "xsize": 16,
  "zsize": 16,
  "slices": [
    [
      "aaaaaabaacd     ",
      "ccbcccccccd     ",
      "eeeeeeeeecd     ",
      "eeeeeeeeecd     ",
      "eeeeeeeeecd     ",
      "eeeeeeeeecd     ",
      "eeeeeeeeecd     ",
      "bbbbbbeeecd     ",
      "ffbbbbbbccgh    ",
      "ffbbbiii   h    ",
      "bbbccccj   h    ",
      "ccccccck   l    ",
      "       hhhhh    ",
      "mno  p          ",
      "                ",
      "                "
    ],
    [
      "  g   q rs      ",
      "tubwwwwwww      ",
      "x y!A yBAw      ",
      "  CDE CDEw      ",
      "  CDE CDEw      ",
      "         w      ",
      "tFI      w      ",
      "JKbcLc   w      ",
      " MciNicOccgh    ",
      " MciPQ     h    ",
      "wwccccc    h    ",
      "ccccccc    l    ",
      "       hhhhh    ",
      "  nnop          ",
      "                ",
      "                "
    ],
    [
      "  g   q         ",
      "RubSSSSSSS      ",
      "   T   U S      ",
      "   V   W S      ",
      "       X S      ",
      "         S      ",
      "RYI      S      ",
      " KbcZc   S      ",
      " Mci0ic1ccgh    ",
      " MciQ      h    ",
      "SSccccc    h    ",
      "22223cc    l    ",
      "     4 hhhhh    ",
      "    np5         ",
      "                ",
      "                "
    ],
    [
      "  g   q         ",
      "uubSSSSSSS      ",
      "         S      ",
      "         S      ",
      "         S      ",
      "         S      ",
      "6        S      ",
      "7Kbc8c   S      ",
      " Mciiic8ccgh    ",
      " Mck       h    ",
      "SSccccc    h    ",
      "ccccccc    h    ",
      "       hhhhh    ",
      "  nn9p          ",
      "                ",
      "                "
    ],
    [
      "ggg   q         ",
      "bbbSSSSSSS      ",
      "         S      ",
      "         S      ",
      "         S      ",
      "         S      ",
      "    #    S      ",
      "KKbccc$% S      ",
      " Mc ^iccccgh    ",
      " Mc        h    ",
      "SSccccc    h    ",
      "ccccccc    h    ",
      "       hhhhh    ",
      "&n9  p          ",
      "                ",
      "                "
    ],
    [
      "      q         ",
      "wwwwwwwwww      ",
      "*********w      ",
      "*********w      ",
      "**(****(*w      ",
      "*********w      ",
      "*********w      ",
      "bbbccc000w      ",
      "))c  ^ccccgh    ",
      "))c   0++++h    ",
      "wwccccc++++h    ",
      "ccccccc++++h    ",
      "       hhhhh    ",
      "n    p          ",
      "                ",
      "                "
    ]
  ]
}