{
  "name": "multi_officethefirst_3_ground",
  "refpalette": "deceasedcraft:multi_officethefirst_3/multi_officethefirst_3_ground_palette",
  "xsize": 16,
  "zsize": 16,
  "slices": [
    [
      "aaaaaabaacbdecHH",
      "aaaaaaaaacbdecHH",
      "aaaaaaaaacbdecHH",
      "aaaaaaaaacbdecHH",
      "aaaaaaaaacbdecHH",
      "aaaaaaaaacbdecHH",
      "aaaaaaaaacbdecHH",
      "aaaaaaaaacbdecHH",
      "aaaabbbbbbbdecHH",
      "aaaabbbffffdecHH",
      "aaaabbbffffdecHH",
      "cccccccffffdecHH",
      "ggggghedddddecHH",
      "gggggieeeeeeecHH",
      "gggggheeeeeeecHH",
      "gggggheeeeeeecHH"
    ],
    [
      " j kk l  mbd    ",
      "nnnnn  oombd    ",
      " p     qombd    ",
      "       qombd    ",
      "       qombd    ",
      "       oombd    ",
      "         mbd    ",
      "        rmbd    ",
      "stu cwcxccbd    ",
      "y A c BCDffd    ",
      "yEFFc IC   d    ",
      "J   KccC   d    ",
      "       ddddd    ",
      "     L          ",
      "                ",
      "                "
    ],
    [
      "      l  Fbd    ",
      "MN       Fbd    ",
      "         Fbd    ",
      "         Fbd    ",
      "         Fbd    ",
      "         Fbd    ",
      "         Fbd    ",
      "         Fbd    ",
      " Ou cPcQccbd    ",
      "R   c  C Dfd    ",
      "REFFc  C  Sd    ",
      "    KccC  Sd    ",
      "     T ddddd    ",
      "     L          ",
      "                ",
      "                "
    ],
    [
      "      l  FUd    ",
      "         Fbd    ",
      "         Fbd    ",
      "         Fbd    ",
      "         Fbd    ",
      "         Fbd    ",
      "         Fbd    ",
      "         Fbd    ",
      "    cVcVccbd    ",
      "    c WC  Xd    ",
      "EEFFc  C  Yd    ",
      "    KccC Sfd    ",
      "       ddddd    ",
      "     L          ",
      "                ",
      "                "
    ],
    [
      "      l  F d    ",
      "         FZd    ",
      "         FUd    ",
      "         Fbd    ",
      "         Fbd    ",
      "         Fbd    ",
      "         Fbd    ",
      "       0 Fbd    ",
      "    ccccccbd    ",
      "    c  C   d    ",
      "FFFFc 1C   d    ",
      "    KccCS2Xd    ",
      "       ddddd    ",
      "     L          ",
      "                ",
      "                "
    ],
    [
      "      l  m      ",
      "         m      ",
      "         m d    ",
      "         mUd    ",
      "         mbd    ",
      "         mbd    ",
      "         mbd    ",
      "         mbd    ",
      "    ccccccbd    ",
      "    c334   d    ",
      "FFFFc354   d    ",
      "    Kccf2  d    ",
      "       ddddd    ",
      "     L          ",
      "                ",
      "                "
    ]
  ]
}