{
  "name": "multi_officethefirst_3_floor2",
  "refpalette": "deceasedcraft:multi_officethefirst_3/multi_officethefirst_3_floor2_palette",
  "xsize": 16,
  "zsize": 16,
  "slices": [
    [
      "aaaaaabaacd     ",
      "aaaaaaaaacd     ",
      "aaaaaaaaacd     ",
      "aaaaaaaaacd     ",
      "aaaaaaaaacd     ",
      "aaaaaaaaacd     ",
      "aaaaaaaaacef    ",
      "aaaaaaaaacbf    ",
      "ggggcbbbbcbf    ",
      "    cbbhi  f    ",
      "jjjjcbbk   f    ",
      "    gccl   f    ",
      "       fffff    ",
      "     m          ",
      "                ",
      "                "
    ],
    [
      " n  n o pq      ",
      " r  r   sq      ",
      "ttuutt  pq      ",
      "wwwwwt   q      ",
      "ttxxtt  pq      ",
      " y  y   sq      ",
      " A  A   pq f    ",
      "         qBf    ",
      "CCCCcDcEccbf    ",
      "    c FIJi f    ",
      "jjjjc KI   f    ",
      "    gccI   f    ",
      "       fffff    ",
      "    Lm          ",
      "                ",
      "                "
    ],
    [
      "      o  j      ",
      "        !j      ",
      "         j      ",
      "         j      ",
      "         j      ",
      "         j      ",
      "         j      ",
      "         jef    ",
      "    cMcNccbf    ",
      "OOOOc  I Jhf    ",
      "ccccc  I  Pf    ",
      "gggggccI  Pf    ",
      "     Q fffff    ",
      "    RmS         ",
      "                ",
      "                "
    ],
    [
      "      o  j      ",
      "         j      ",
      "         j      ",
      "         j      ",
      "         j      ",
      "         j      ",
      "         j      ",
      "         jef    ",
      "    cTcTccbf    ",
      "UUOOc VI  lf    ",
      "ccccc  I  Wf    ",
      "cccccccI PhC    ",
      "       fffff    ",
      "  RRXm          ",
      "                ",
      "                "
    ],
    [
      "      o  j      ",
      "         j      ",
      "         j      ",
      "         j      ",
      "         j      ",
      "         j      ",
      "         j      ",
      "         jef    ",
      "    ccccccbf    ",
      "YYOOc  I   f    ",
      "ccccc ZI   f    ",
      "cccccccIP0 C    ",
      "       fffff    ",
      "LRX  m          ",
      "                ",
      "                "
    ],
    [
      "111111b11q      ",
      "111111111q      ",
      "222221111q      ",
      "222221111q      ",
      "222221111q      ",
      "111111111q      ",
      "111111111q      ",
      "111111111q f    ",
      "3333ccccccBf    ",
      "4444c55i   f    ",
      "ccccc56i   f    ",
      "ccccccch0  C    ",
      "       fffff    ",
      "R    m          ",
      "                ",
      "                "
    ]
  ]
}