{
  "name": "multi_officethefirst_3_floor1",
  "refpalette": "deceasedcraft:multi_officethefirst_3/multi_officethefirst_3_floor1_palette",
  "xsize": 16,
  "zsize": 16,
  "slices": [
    [
      "      a  bc     ",
      "         bc     ",
      "         bc     ",
      "         bcd    ",
      "         bed    ",
      "         bfd    ",
      "         bfd    ",
      "         bfd    ",
      "    bbbbbbfd    ",
      "    b fgh  d    ",
      "iiiibjfk   d    ",
      "    lbbm   d    ",
      "       ddddd    ",
      "     n          ",
      "                ",
      "                "
    ],
    [
      "      a  o      ",
      "         o      ",
      "         o      ",
      "         o      ",
      "         o d    ",
      "         oed    ",
      "         ofd    ",
      "         ofd    ",
      "    bbbbbbfd    ",
      "    b  pqh d    ",
      "iiiibj p   d    ",
      "    lbbp   d    ",
      "       ddddd    ",
      "     n          ",
      "                ",
      "                "
    ],
    [
      "      a  i      ",
      "         i      ",
      "         i      ",
      "         i      ",
      "         i d    ",
      "         ird    ",
      "         ifd    ",
      "         ifd    ",
      "    bbbbbbfd    ",
      "    b  p qgd    ",
      "iiiibj p  sd    ",
      "    lbbp  sd    ",
      "     t ddddd    ",
      "     n          ",
      "                ",
      "                "
    ],
    [
      "      a  i      ",
      "         i      ",
      "         i      ",
      "         i      ",
      "         i      ",
      "         ird    ",
      "         ifd    ",
      "         ifd    ",
      "    bbbbbbfd    ",
      "    b  p  md    ",
      "iiiibj p  ud    ",
      "    lbbp sgd    ",
      "       ddddd    ",
      "     n          ",
      "                ",
      "                "
    ],
    [
      "      a  i      ",
      "         i      ",
      "         i      ",
      "         i      ",
      "         i      ",
      "         i d    ",
      "         ied    ",
      "         ifd    ",
      "    bbbbbbfd    ",
      "    b  p   d    ",
      "iiiibj p   d    ",
      "    lbbpswmd    ",
      "       ddddd    ",
      "     n          ",
      "                ",
      "                "
    ],
    [
      "xxxxxxfxxo      ",
      "xyxxyxxyxo      ",
      "xyxxyxxyxo      ",
      "xyxxyxxyxo      ",
      "xyxxyxxyxo      ",
      "xyxxyxxyxo      ",
      "xyxxyxxyxord    ",
      "xxxxxxxxxofd    ",
      "    bbbbbbfd    ",
      "    bAAh   d    ",
      "iiiibjAh   d    ",
      "    lbbgw  d    ",
      "       ddddd    ",
      "     n          ",
      "                ",
      "                "
    ]
  ]
}