{
  "name": "multi_officethefirst_3_base4",
  "refpalette": "deceasedcraft:multi_officethefirst_3/multi_officethefirst_3_base4_palette",
  "xsize": 16,
  "zsize": 16,
  "slices": [
    [
      "aaaaaaaabaaaaabv",
      "aaaaaaaabaaaaabv",
      "aaaaaaaabaaaaabv",
      "aaaaaaaabaaaaabv",
      "aaaaaaaaaaaaaabv",
      "aaaaaaaaaaaaaabv",
      "aaaaaaaabaaaaabv",
      "ccaaaaaabbbbabbv",
      "ddcaaaaabaaaaabv",
      "ddcaaaaabaaaaabv",
      "ddcaaaaabaaaaabv",
      "ddcaaaaabaaaaabv",
      "ccaaaaaabaaaaabv",
      "aaaaaaaabaaaaabv",
      "bbbbbbbbbbbbbbbv",
      "vvvvvvvvvvvvvvvv"
    ],
    [
      "   efff bg   hbv",
      "   ijkklbgm  nbv",
      "        bd   obv",
      "        b   pqbv",
      "        r    sbv",
      "        t    ubv",
      "w       b    xbv",
      "yy      bbbbAbbv",
      "BCy     b    Dbv",
      "BEyF    bIJ  Kbv",
      "BByF    bLM  Kbv",
      "BNy     bLM  Obv",
      "yy      bIJ  Obv",
      "P    Q  b   ORbv",
      "bbbbbbbbbbbbbbbv",
      "vvvvvvvvvvvvvvvv"
    ],
    [
      "   Sfff bT   Ubv",
      "   iVWXYbZ   Ubv",
      "        b0   1bv",
      "        b    Ubv",
      "        2    Ubv",
      "        3    Ubv",
      "        b    Ubv",
      "44      bbbb5bbv",
      "BB4     b    6bv",
      "BB4     bIJ  Kbv",
      "BB4     b7   Dbv",
      "BB4     b7    bv",
      "44      bIJ  Rbv",
      "     Q  b    Obv",
      "bbbbbbbbbbbbbbbv",
      "vvvvvvvvvvvvvvvv"
    ],
    [
      "   Sfff b     bv",
      "   iVXWYb     bv",
      "        b     bv",
      "        b     bv",
      "        8    9bv",
      "        8     bv",
      "        b   # bv",
      "44      bbbbbbbv",
      "BE4     b     bv",
      "BB4     bIJ   bv",
      "BB4$    b%    bv",
      "BE4Q$   b%    bv",
      "44 ^Q$  bIJ   bv",
      "    &Q  b     bv",
      "bbbbbbbbbbbbbbbv",
      "vvvvvvvvvvvvvvvv"
    ],
    [
      "   Sfff b     bv",
      "   iVXXYb     bv",
      "        b     bv",
      "        b     bv",
      "        8     bv",
      "        8     bv",
      "        b     bv",
      "44      bbbbbbbv",
      "EE4     bJ    bv",
      "BB4     b*J   bv",
      "BB4     b((   bv",
      "BE4     b((   bv",
      "44      b)J   bv",
      "     Q  bJ    bv",
      "bbbbbbbbbbbbbbbv",
      "vvvvvvvvvvvvvvvv"
    ],
    [
      "   Sfff+b     bv",
      "   iVXW-b     bv",
      "       +b     bv",
      "       +b     bv",
      "       +b     bv",
      "       +b     bv",
      "       +b     bv",
      "44     +bbbbbbbv",
      "BB4    +b[    bv",
      "BB4]   +b{J   bv",
      "BB}|++++b;:   bv",
      "BE4     b;:   bv",
      "44      b'J   bv",
      "     Q  b<    bv",
      "bbbbbbbbbbbbbbbv",
      "vvvvvvvvvvvvvvvv"
    ]
  ]
}