{
  "name": "multi_officethefirst_3_floor10",
  "refpalette": "deceasedcraft:multi_officethefirst_3/multi_officethefirst_3_floor10_palette",
  "xsize": 16,
  "zsize": 16,
  "slices": [
    [
      "aaaaaabaaaa     ",
      "cccccccccca     ",
      "dddddddddca     ",
      "dddddddddca     ",
      "dddddddddca     ",
      "dddddddddca     ",
      "dddddddddca     ",
      "eeeeeeeedca     ",
      "  c   fedca     ",
      "  c  ghedca     ",
      "cccccccccca     ",
      "aaaaaaaaaaa     ",
      "                ",
      "                ",
      "                ",
      "               i"
    ],
    [
      "      b         ",
      "jjjjjjjjjj      ",
      "k  lml  nj      ",
      " opqmqrs j      ",
      "  ttmtt  j      ",
      "    u    j      ",
      "w   xyA  j      ",
      "BCeccccc j      ",
      "  c    D j      ",
      "  c gE cFj      ",
      "jjjjjjjjjj      ",
      "                ",
      "                ",
      "                ",
      "                ",
      "                "
    ],
    [
      "      b         ",
      "IIIIIIIIII      ",
      "J  KLM  LI      ",
      "   NLO   I      ",
      "  PQR S  I      ",
      "         I      ",
      "T    U   I      ",
      " Ceccccc I      ",
      "  cV   W I      ",
      "  chE  cXI      ",
      "IIIIIIIIII      ",
      "                ",
      "                ",
      "                ",
      "                ",
      "                "
    ],
    [
      "      b         ",
      "IIIIIIIIII      ",
      "        YI      ",
      "         I      ",
      "         I      ",
      "         I      ",
      "Z    0   I      ",
      "1Ceccccc I      ",
      "  ch2  3 I      ",
      "  cf   c I      ",
      "IIIIIIIIII      ",
      "                ",
      "                ",
      "                ",
      "                ",
      "                "
    ],
    [
      "      b         ",
      "IIIIIIIIII      ",
      "         I      ",
      "         I      ",
      "         I      ",
      "         I      ",
      "         I      ",
      "CCeccccc I      ",
      "  c 42 c I      ",
      "  c    c I      ",
      "IIIIIIIIII      ",
      "                ",
      "                ",
      "                ",
      "                ",
      "                "
    ],
    [
      "      b         ",
      "jjjjjjjjjj      ",
      "555555555j      ",
      "555555555j      ",
      "556555565j      ",
      "555555555j      ",
      "555555555j      ",
      "eeeccccc j      ",
      "  c  4hc7j      ",
      "  c   Vc j      ",
      "jjjjjjjjjj      ",
      "                ",
      "                ",
      "                ",
      "                ",
      "                "
    ]
  ]
}