{
  "name": "multi_officethefirst_3_base3",
  "refpalette": "deceasedcraft:multi_officethefirst_3/multi_officethefirst_3_base3_palette",
  "xsize": 16,
  "zsize": 16,
  "slices": [
    [
      "   abcc de    dv",
      "   fggghde    dv",
      "    iiiide    dv",
      "        de    dv",
      "        de    dv",
      "        de    dv",
      "        de    dv",
      "jj      dddddddv",
      "kkj     dl    dv",
      "kkj     dml   dv",
      "kkj     dnn   dv",
      "kkj     dnn   dv",
      "jj      dml   dv",
      "     o  dl    dv",
      "dddddddddddddddv",
      "vvvvvvvvvvvvvvvv"
    ],
    [
      "   appp dq    dv",
      "   grsstdq    dv",
      "    uwwwxq    dv",
      "        dq    dv",
      "        dq    dv",
      "        dq    dv",
      "        d y   dv",
      "jj      dddddddv",
      "ABj     d     dv",
      "kkj     dCl   dv",
      "kkj     dD    dv",
      "kAj     dD    dv",
      "jj      dCl   dv",
      "     o  d     dv",
      "dddddddddddddddv",
      "vvvvvvvvvvvvvvvv"
    ],
    [
      "   appp d     dv",
      "   gEFFId     dv",
      "        J     dv",
      "        d     dv",
      "        d     dv",
      "        d     dv",
      "        d  y  dv",
      "jj      dddddddv",
      "kAj     d     dv",
      "kkj     dCl   dv",
      "kkj     dK    dv",
      "kkj     dK    dv",
      "jj      dCl   dv",
      "     o  d     dv",
      "dddddddddddddddv",
      "vvvvvvvvvvvvvvvv"
    ],
    [
      "   appp d    edv",
      "   gELFId    edv",
      "        dM   edv",
      "        d    edv",
      "        d    edv",
      "        d    edv",
      "        d   yedv",
      "jj      dddddddv",
      "kkj     d     dv",
      "kkj     dCl   dv",
      "kkjN    dD    dv",
      "kkjoN   dD    dv",
      "jj OoP  dCl   dv",
      "    Oo  d     dv",
      "dddddddddddddddv",
      "vvvvvvvvvvvvvvvv"
    ],
    [
      "   appp d    Qdv",
      "   gEFFId    Qdv",
      "        d    Qdv",
      "        d    Qdv",
      "        d    Qdv",
      "        d    Qdv",
      "        d     dv",
      "jj      dddddddv",
      "kkj     dl    dv",
      "kkj     dRl   dv",
      "kkj     dSS   dv",
      "kBj     dSS   dv",
      "jj      dRl   dv",
      "     o  dl    dv",
      "dddddddddddddddv",
      "vvvvvvvvvvvvvvvv"
    ],
    [
      "   apppTd     dv",
      "   gEFLUd     dv",
      "       Td     dv",
      "       Td     dv",
      "       Td     dv",
      "       Td     dv",
      "       Td     dv",
      "jj     Tdddddddv",
      "kkj    TdV    dv",
      "kkjW   TdXl   dv",
      "kkYZTTTTd01   dv",
      "kBj     d01   dv",
      "jj      dXl   dv",
      "     o  d2    dv",
      "dddddddddddddddv",
      "vvvvvvvvvvvvvvvv"
    ]
  ]
}