{
  "name": "multi_officethefirst_3_floor4",
  "refpalette": "deceasedcraft:multi_officethefirst_3/multi_officethefirst_3_floor4_palette",
  "xsize": 16,
  "zsize": 16,
  "slices": [
    [
      "aaaaaabaacd     ",
      "aaaaaaaaacd     ",
      "aaaaaaaaacd     ",
      "aaaaaaaaacd     ",
      "aaaaaaaaacd     ",
      "aaaaaaaaacd     ",
      "aaaaaaaaacd     ",
      "aaaaaaaaacd     ",
      "aaaabbbbbcef    ",
      "aaaabbbgh  f    ",
      "aaaabbbi   f    ",
      "cccccccj   k    ",
      "       fffff    ",
      "lmn  o          ",
      "                ",
      "                "
    ],
    [
      "  pq  r ps      ",
      "  tu    ws      ",
      "  xy    xs      ",
      "  AB    As      ",
      "  CDEFIJCs      ",
      " Kpq    ps      ",
      " Ltu    ts      ",
      "         s      ",
      " M NcOcPccef    ",
      "MQ Rc STUh f    ",
      "V M!c WT   f    ",
      "cccccccT   k    ",
      "       fffff    ",
      "  mmno          ",
      "                ",
      "                "
    ],
    [
      "      r XY      ",
      "         Y      ",
      "         Y      ",
      "   Z     Y      ",
      "   0    1Y      ",
      "   2    ZY      ",
      "         Y      ",
      "         Y      ",
      "   3c4c5ccef    ",
      "    c  T Ugf    ",
      "   Rc  T  6f    ",
      "77778ccT  69    ",
      "     # fffff    ",
      "    mo$         ",
      "                ",
      "                "
    ],
    [
      "      r  Y      ",
      "         Y      ",
      "         Y      ",
      "         Y      ",
      "         Y      ",
      "         Y      ",
      "         Y      ",
      "         Y      ",
      "    c%c%ccef    ",
      "    c ^T  jf    ",
      "&*&*c( T  )f    ",
      "cccccccT 6gk    ",
      "       fffff    ",
      "  mm+o          ",
      "                ",
      "                "
    ],
    [
      "      r  Y      ",
      "         Y      ",
      "         Y      ",
      "         Y      ",
      "         Y      ",
      "         Y      ",
      "         Y      ",
      "         Y      ",
      "    ccccccef    ",
      "    c  T   f    ",
      "----c[]T   f    ",
      "cccccccT6{ k    ",
      "       fffff    ",
      "}m+  o          ",
      "                ",
      "                "
    ],
    [
      "||;|||b;|s      ",
      "|||||||||s      ",
      "|||||||||s      ",
      "|||||||||s      ",
      "|||||||||s      ",
      "||;||||:|s      ",
      "|||||||||s      ",
      "|||||||||s      ",
      "''''ccccccef    ",
      "''''c<<h   f    ",
      ">>>>c,.h   f    ",
      "cccccccg{  k    ",
      "       fffff    ",
      "m    o          ",
      "                ",
      "                "
    ]
  ]
}