{
  "name": "multi_officethefirst_3_floor9",
  "refpalette": "deceasedcraft:multi_officethefirst_3/multi_officethefirst_3_floor9_palette",
  "xsize": 16,
  "zsize": 16,
  "slices": [
    [
      "aaaaaabaaaa     ",
      "cccccccccca     ",
      "dddddddddca     ",
      "dddddddddca     ",
      "dddddddddca     ",
      "dddddddddca     ",
      "dddddddddca     ",
      "eeeeeeeedca     ",
      "  c   fedca     ",
      "  c  ghedca     ",
      "cccccccccca     ",
      "aaaaaaaaaaa     ",
      "                ",
      "                ",
      "                ",
      "                "
    ],
    [
      "      b         ",
      "iiiiiiiiii      ",
      "j  klk  mi      ",
      " noplpqr i      ",
      "  sslss  i      ",
      "    t    i      ",
      "u   wxy  i      ",
      "ABeccccc i      ",
      "  c    C i      ",
      "  c gD cEi      ",
      "iiiiiiiiii      ",
      "                ",
      "                ",
      "                ",
      "                ",
      "                "
    ],
    [
      "      b         ",
      "FFFFFFFFFF      ",
      "   IJK  JF      ",
      "   LJM   F      ",
      "  N J O  F      ",
      "         F      ",
      "P    Q   F      ",
      " Beccccc F      ",
      "  cR   S F      ",
      "  chD  cTF      ",
      "FFFFFFFFFF      ",
      "                ",
      "                ",
      "                ",
      "                ",
      "                "
    ],
    [
      "      b         ",
      "FFFFFFFFFF      ",
      "        UF      ",
      "         F      ",
      "         F      ",
      "         F      ",
      "V    !   F      ",
      "WBeccccc F      ",
      "  chX  Y F      ",
      "  cf   c F      ",
      "FFFFFFFFFF      ",
      "                ",
      "                ",
      "                ",
      "                ",
      "                "
    ],
    [
      "      b         ",
      "FFFFFFFFFF      ",
      "         F      ",
      "         F      ",
      "         F      ",
      "         F      ",
      "         F      ",
      "BBeccccc F      ",
      "  c ZX c F      ",
      "  c    c F      ",
      "FFFFFFFFFF      ",
      "                ",
      "                ",
      "                ",
      "                ",
      "                "
    ],
    [
      "      b         ",
      "iiiiiiiiii      ",
      "000000000i      ",
      "000000000i      ",
      "001000010i      ",
      "000000000i      ",
      "000000000i      ",
      "eeeccccc i      ",
      "  c  Zhc2i      ",
      "  c   Rc i      ",
      "iiiiiiiiii      ",
      "                ",
      "                ",
      "                ",
      "                ",
      "                "
    ]
  ]
}