{
  "name": "multi_officethefirst_3_floor7",
  "refpalette": "deceasedcraft:multi_officethefirst_3/multi_officethefirst_3_floor7_palette",
  "xsize": 16,
  "zsize": 16,
  "slices": [
    [
      "aaaaaabaaaa     ",
      "cccccccccca     ",
      "dddddddddca     ",
      "dddddddddca     ",
      "dddddddddca     ",
      "dddddddddca     ",
      "dddddddddca     ",
      "eeeeeeeedca     ",
      "  c   fedcgh    ",
      "  c  ijedceh    ",
      "cccccccccceh    ",
      "aaaaaaahkkkh    ",
      "       hhhhh    ",
      "lmn  o          ",
      "                ",
      "                "
    ],
    [
      "      b         ",
      "pppppppppp      ",
      "qq!qqqr sp      ",
      "qqqqqqr  p      ",
      "         p      ",
      "         p      ",
      "t   uwu  p      ",
      "xyeccccc p      ",
      "  c    A pgh    ",
      "  c iB cCpkh    ",
      "pppppppppp h    ",
      "           h    ",
      "                ",
      "  mmno          ",
      "                ",
      "                "
    ],
    [
      "      b         ",
      "DDDDDDDDDD      ",
      " EFIJIK LD      ",
      "MK N     D      ",
      "         D      ",
      "         D      ",
      "O    P   D      ",
      " yeccccc D      ",
      "  cQ   R D h    ",
      "  cjB  c D h    ",
      "DDDDDDDDDD      ",
      "                ",
      "                ",
      "    mo          ",
      "                ",
      "                "
    ],
    [
      "      b         ",
      "DDDDDDDDDD      ",
      "        SD      ",
      "         D      ",
      "         D      ",
      "         D      ",
      "T    U   D      ",
      "Vyeccccc D      ",
      "  cjW  X D      ",
      "  cf   c D      ",
      "DDDDDDDDDD      ",
      "                ",
      "                ",
      "    lo          ",
      "                ",
      "                "
    ],
    [
      "      b         ",
      "DDDDDDDDDD      ",
      "         D      ",
      "         D      ",
      "         D      ",
      "         D      ",
      "         D      ",
      "yyeccccc D      ",
      "  c YW c D      ",
      "  c    c D      ",
      "DDDDDDDDDD      ",
      "                ",
      "                ",
      "     o          ",
      "                ",
      "                "
    ],
    [
      "      b         ",
      "pppppppppp      ",
      "ZZZZZZZZZp      ",
      "ZZZZZZZZZp      ",
      "ZZ0ZZZZ1Zp      ",
      "ZZZZZZZZZp      ",
      "ZZZZZZZZZp      ",
      "eeeccccc p      ",
      "  c  Yjc2p      ",
      "  c   Qc p      ",
      "pppppppppp      ",
      "                ",
      "                ",
      "     3          ",
      "                ",
      "                "
    ]
  ]
}