{
  "name": "multi_officethefirst_3_floor11",
  "refpalette": "deceasedcraft:multi_officethefirst_3/multi_officethefirst_3_floor11_palette",
  "xsize": 16,
  "zsize": 16,
  "slices": [
    [
      "aaaaaabaaaa     ",
      "cccccccccca     ",
      "dddddddddca     ",
      "dddddddddca     ",
      "dddddddddca     ",
      "dddddddddca     ",
      "dddddddddca     ",
      "eeeeeeeedca     ",
      "  c   fedca     ",
      "  c  ghedca     ",
      "cccccccccca     ",
      "aaaaaaaaaaa     ",
      "                ",
      "                ",
      "                ",
      "                "
    ],
    [
      "      b         ",
      "iiiiiiiiii      ",
      "j klk klmi      ",
      "         i      ",
      "         i      ",
      "   n o   i      ",
      "p  qqqq  i      ",
      "rseccccc i      ",
      "  c    t i      ",
      "  c gu cwi      ",
      "iiiiiiiiii      ",
      "                ",
      "                ",
      "                ",
      "                ",
      "                "
    ],
    [
      "      b         ",
      "xxxxxxxxxx      ",
      "y      ABx      ",
      "         x      ",
      "         x      ",
      "         x      ",
      "C  DEFIJ x      ",
      " seccccc x      ",
      "  cK   L x      ",
      "  chu  cMx      ",
      "xxxxxxxxxx      ",
      "                ",
      "                ",
      "                ",
      "                ",
      "                "
    ],
    [
      "      b         ",
      "xxxxxxxxxx      ",
      "        Nx      ",
      "         x      ",
      "         x      ",
      "         x      ",
      "O  I  P  x      ",
      "Qseccccc x      ",
      "  chR  S x      ",
      "  cf   c x      ",
      "xxxxxxxxxx      ",
      "                ",
      "                ",
      "                ",
      "                ",
      "                "
    ],
    [
      "      b         ",
      "xxxxxxxxxx      ",
      "        Nx      ",
      "         x      ",
      "         x      ",
      "         x      ",
      "   ITII  x      ",
      "sseccccc x      ",
      "  c UR c x      ",
      "  c    c x      ",
      "xxxxxxxxxx      ",
      "                ",
      "                ",
      "                ",
      "                ",
      "                "
    ],
    [
      "      b         ",
      "iiiiiiiiii      ",
      "         i      ",
      "         i      ",
      "         i      ",
      "         i      ",
      "   o n   i      ",
      "eeeccccc i      ",
      "  c  Uhc i      ",
      "  c   Kc i      ",
      "iiiiiiiiii      ",
      "                ",
      "                ",
      "                ",
      "                ",
      "                "
    ]
  ]
}