{
  "name": "multi_officethefirst_3_base1",
  "refpalette": "deceasedcraft:multi_officethefirst_3/multi_officethefirst_3_base1_palette",
  "xsize": 16,
  "zsize": 16,
  "slices": [
    [
      "   abbb cd    cv",
      "   efffgcd    cv",
      "        cd    cv",
      "        cd    cv",
      "        cd    cv",
      "        cd    cv",
      "hhhhhhhhcd    cv",
      "ii      cccccccv",
      "jji     ck    cv",
      "jli     cmk   cv",
      "jji     cnn   cv",
      "l!i     cnn   cv",
      "ii      cok   cv",
      "     p  ck    cv",
      "cccccccccccccccv",
      "vvvvvvvvvvvvvvvv"
    ],
    [
      "        cq    cv",
      "       rcq    cv",
      "        cq    cv",
      "        cq    cv",
      "        cq    cv",
      "        cq    cv",
      "stttttttuq    cv",
      "wi      cccccccv",
      "  i     c     cv",
      "  i     cxk   cv",
      "  i     cy    cv",
      "  i     cy    cv",
      "ii      cxk   cv",
      "     p  c     cv",
      "cccccccccccccccv",
      "vvvvvvvvvvvvvvvv"
    ],
    [
      "        c     cv",
      "        c     cv",
      "        c     cv",
      "        c     cv",
      "        c     cv",
      "        c     cv",
      "        A     cv",
      "Bi      cccccccv",
      "  i     c     cv",
      "  i     cxk   cv",
      "  i     cC    cv",
      "  i     cC    cv",
      "ii      cxk   cv",
      "     p  c     cv",
      "cccccccccccccccv",
      "vvvvvvvvvvvvvvvv"
    ],
    [
      "        c     cv",
      "        c     cv",
      "        c     cv",
      "        c     cv",
      "        c     cv",
      "        c     cv",
      "D       cE    cv",
      "FF      cccccccv",
      "  F     c     cv",
      "  FI    cxk   cv",
      "  FI    cC    cv",
      "  F     cC    cv",
      "FF      cxk   cv",
      "J    p  c     cv",
      "cccccccccccccccv",
      "vvvvvvvvvvvvvvvv"
    ],
    [
      "KKKKKKKKcKKLKKcv",
      "KKKKKKKKcKKKKKcv",
      "MKKKMMKKcKKKKKcv",
      "MKKKMMKKcKKKKKcv",
      "KKKKKKKKcKKLKKcv",
      "KKKKKKKKcKKKKKcv",
      "KKKKKKKKcKKKKKcv",
      "NNKKKKKKcccccccv",
      "OONKKKKKcKKKKKcv",
      "OONKLLKKcxKKKKcv",
      "OONKLMKKcKKKKKcv",
      "OONKKKKKcKKKKKcv",
      "NNKKKKKKcxKKKKcv",
      "KKKKKpKKcKKKKKcv",
      "cccccccccccccccv",
      "vvvvvvvvvvvvvvvv"
    ],
    [
      "PPPPPPPPPPPPPPPv",
      "PPPPPPPPPPPPPPPv",
      "PPPPPPPPPPPPPPPv",
      "PPPPPPPPPPPPPPPv",
      "PPPPPPPPPPPPPPPv",
      "PPPPPPPPPPPPPPPv",
      "PPPPPPPPPPPPPPPv",
      "PPPPPPPPPPPPPPPv",
      "PPPPPPPPPPPPPPPv",
      "PPPPPPPPPPPPPPPv",
      "PPPPPPPPPPPPPPPv",
      "PPPPPPPPPPPPPPPv",
      "PPPPPPPPPPPPPPPv",
      "PPPPPpPPPPPPPPPv",
      "PPPPPPPPPPPPPPPv",
      "vvvvvvvvvvvvvvvv"
    ]
  ]
}