{
  "name": "multi_officethefirst_3_floor5",
  "refpalette": "deceasedcraft:multi_officethefirst_3/multi_officethefirst_3_floor5_palette",
  "xsize": 16,
  "zsize": 16,
  "slices": [
    [
      "aaaaaabaacd     ",
      "aaaaaaaaacd     ",
      "aaaaaaaaacd     ",
      "aaaaaaaaacd     ",
      "aaaaaaaaacd     ",
      "aaaaaaaaacd     ",
      "aaaaaaaaacd     ",
      "aaaaaaaaacd     ",
      "aaaabbbbbcef    ",
      "aaaabbbgh  f    ",
      "aaaabbbi   f    ",
      "cccccccj   k    ",
      "       fffff    ",
      "lmn  o          ",
      "                ",
      "               p"
    ],
    [
      "  qr  stqu      ",
      "  wx    wu      ",
      "  yA   Byu      ",
      "  CD   ECu      ",
      "FIJKLM  Ju      ",
      "  qr    qu      ",
      "  wx    wu      ",
      "         u      ",
      " N OcPcQccef    ",
      "NR Nc STUh f    ",
      "VNWXc YT   f    ",
      "cccccccT   k    ",
      "       fffff    ",
      "  mmno          ",
      "                ",
      "                "
    ],
    [
      "  Z0  s  1      ",
      "         1      ",
      "         1      ",
      "   2    Z1      ",
      "  34    31      ",
      "  tZ    21      ",
      "         1      ",
      "         1      ",
      "   5c6c7ccef    ",
      " 8  c  T Ugf    ",
      "    c  T  9f    ",
      "####$ccT  9%    ",
      "     ^ fffff    ",
      "    mo&         ",
      "                ",
      "                "
    ],
    [
      "      s  1      ",
      "         1      ",
      "         1      ",
      "         1      ",
      "         1      ",
      "         1      ",
      "         1      ",
      "         1      ",
      "   *c(c(ccef    ",
      "    c )T  jf    ",
      "+-+-c[ T  ]f    ",
      "cccccccT 9gk    ",
      "       fffff    ",
      "  mm{o          ",
      "                ",
      "                "
    ],
    [
      "      s  1      ",
      "         1      ",
      "         1      ",
      "         1      ",
      "         1      ",
      "         1      ",
      "         1      ",
      "         1      ",
      "    ccccccef    ",
      "    c  T   f    ",
      "}}}}c!|T   f    ",
      "cccccccT9; k    ",
      "       fffff    ",
      ":m{  o          ",
      "                ",
      "                "
    ],
    [
      "''<'''b>'u      ",
      "'''''''''u      ",
      "'''''''''u      ",
      "'''''''''u      ",
      "'''''''''u      ",
      "''>''''>'u      ",
      "'''''''''u      ",
      "'''''''''u      ",
      ",,,,ccccccef    ",
      ",,,,c..h   f    ",
      "????c/`h   f    ",
      "cccccccg;  k    ",
      "       fffff    ",
      "m    o          ",
      "                ",
      "                "
    ]
  ]
}