{
  "name": "multi_officethefirst_3_top",
  "refpalette": "deceasedcraft:multi_officethefirst_3/multi_officethefirst_3_top_palette",
  "xsize": 16,
  "zsize": 16,
  "slices": [
    [
      "aaaaaaaaaaa     ",
      "bbbbbbbbbba     ",
      "cccccccccba     ",
      "cccccccccba     ",
      "cccccccccba     ",
      "cccccccccba     ",
      "cccccccccba     ",
      "ddddddddcba     ",
      "  b   edcba     ",
      "  b   fdcba     ",
      "bbbbbbbbbba     ",
      "aaaaaaaaaaa     ",
      "                ",
      "                ",
      "                ",
      "                "
    ],
    [
      "                ",
      "gggggggggg      ",
      "         g      ",
      " hiiij   g      ",
      " hiiij   g      ",
      "  k k    g      ",
      "  k k    g      ",
      "bbbbbbbb g      ",
      "  b    l g      ",
      "  b    b g      ",
      "mmmmmmmmgg      ",
      "                ",
      "                ",
      "                ",
      "                ",
      "                "
    ],
    [
      "                ",
      "                ",
      "                ",
      " hiiij          ",
      " hiiij          ",
      "                ",
      "                ",
      "bbbbbbbb        ",
      "  b    n        ",
      "  b    b        ",
      "mmopppom        ",
      "                ",
      "                ",
      "                ",
      "                ",
      "                "
    ],
    [
      "                ",
      "                ",
      "                ",
      "  qqq           ",
      "  qqq           ",
      "                ",
      "                ",
      "bbbbbbbb        ",
      "  b    r        ",
      "stb    b        ",
      "mmmmmmmm        ",
      "                ",
      "                ",
      "                ",
      "                ",
      "                "
    ],
    [
      "                ",
      "                ",
      "                ",
      "                ",
      "                ",
      "                ",
      "aaaaaaaaa       ",
      "uuuuuuuua       ",
      "wwwwwwwua       ",
      "wwwwwwwua       ",
      "xxxxxxxxa       ",
      "                ",
      "                ",
      "                ",
      "                ",
      "                "
    ],
    [
      "                ",
      "                ",
      "                ",
      "                ",
      "                ",
      "                ",
      "                ",
      "                ",
      "                ",
      "                ",
      "                ",
      "                ",
      "                ",
      "                ",
      "                ",
      "                "
    ]
  ]
}