{
  "name": "multi_hospitaldamaged_2_ground",
  "refpalette": "deceasedcraft:multi_hospitaldamaged_2/multi_hospitaldamaged_2_ground_palette",
  "xsize": 16,
  "zsize": 16,
  "slices": [
    [
      "aHHbHHHbacddceff",
      "aHHbHHHbacddcecc",
      "aHHbHHHbacddcecc",
      "aHHbHHHbacddcecc",
      "aHHbHHHbacddcecc",
      "gHHbHHHbgcddceff",
      "aHHbHHHbacddcefh",
      "aHHbHHHbacddceii",
      "aHHbHHHbacddceif",
      "aHHbHHHbacddcefj",
      "aHHbHHHbacddcecc",
      "aHHbHHHbacddcekk",
      "gHHbHHHbaccccekk",
      "aHHbHHHbagaageaa",
      "aHHbHHHbaaaaaaaa",
      "agabHHHbaaaaggaa"
    ],
    [
      "        lm noep ",
      "        lm noeqr",
      " st     lm noe  ",
      " uw     lm noe p",
      "        xm noeyr",
      "  A      m noeBC",
      " st     lm noeD ",
      " uw     lm noeEF",
      "        lm noeIJ",
      "        lm noeKK",
      " st      m noeLL",
      " uw     lm noeMM",
      "        lmmmme  ",
      "        x lx eNN",
      " st     NONNNPNO",
      "        NNNNPNNN"
    ],
    [
      "            Ke Q",
      "            ReSr",
      "            Ke  ",
      "             e  ",
      "            TeUr",
      "            KeVW",
      "            Xe  ",
      "            Ke  ",
      "            Ye  ",
      "             eKK",
      "             eLL",
      "             eMM",
      "             e  ",
      "             e  ",
      "                ",
      "                "
    ],
    [
      "            KeZ ",
      "            0e1r",
      "            2e  ",
      "            2e  ",
      "            re3r",
      "            Ke  ",
      "            Xe  ",
      "            2e  ",
      "             e  ",
      "             eK4",
      "             eLL",
      "             eMM",
      "             e  ",
      "             e  ",
      "                ",
      "                "
    ],
    [
      "             e  ",
      "            5err",
      "             e  ",
      "           6 e  ",
      "             err",
      "            5e  ",
      "             e  ",
      "             e  ",
      "             e  ",
      "            7eKK",
      "             eLL",
      "             eMM",
      "             e  ",
      "             e  ",
      "                ",
      "                "
    ],
    [
      "           89###",
      "            9###",
      "            9###",
      "            9###",
      "           99###",
      "           $9###",
      "           99###",
      "           $9###",
      "           $9###",
      "           $9###",
      "           $9999",
      "           $$$$$",
      "                ",
      "                ",
      "                ",
      "                "
    ]
  ]
}