{
  "name": "multi_hospitaldamaged_2_top",
  "refpalette": "deceasedcraft:multi_hospitaldamaged_2/multi_hospitaldamaged_2_top_palette",
  "xsize": 16,
  "zsize": 16,
  "slices": [
    [
      "           abccc",
      "           dbccc",
      "           dbccc",
      "           ebccc",
      "           abccc",
      "           ebccc",
      "           abccc",
      "           abccc",
      "           abccc",
      "           ebccc",
      "           abbbb",
      "           aaaea",
      "           fgffg",
      "                ",
      "                ",
      "                "
    ],
    [
      "           hbi  ",
      "           hbj! ",
      "            b k ",
      "           hbi  ",
      "           hbj  ",
      "            b k ",
      "           hbi  ",
      "           hbj  ",
      "            b k ",
      "           hbi  ",
      "           hbbbb",
      "            hh h",
      "                ",
      "                ",
      "                ",
      "                "
    ],
    [
      "           hb   ",
      "           hb   ",
      "                ",
      "           hb   ",
      "           hb   ",
      "            l   ",
      "           hb   ",
      "           hb   ",
      "            l   ",
      "           hb   ",
      "           hbblb",
      "            hh h",
      "                ",
      "                ",
      "                ",
      "                "
    ],
    [
      "           hb   ",
      "           hb   ",
      "            l   ",
      "           hb   ",
      "           hb   ",
      "            l   ",
      "           hb   ",
      "           hb   ",
      "            l   ",
      "           hb   ",
      "           hbblb",
      "            hh h",
      "                ",
      "                ",
      "                ",
      "                "
    ],
    [
      "           hb   ",
      "           hb   ",
      "            l   ",
      "           hb   ",
      "           hb   ",
      "            l   ",
      "           hb   ",
      "           hb   ",
      "            l   ",
      "           hb   ",
      "           mbblb",
      "            hh h",
      "                ",
      "                ",
      "                ",
      "                "
    ],
    [
      "           hbnoo",
      "           hbnoo",
      "            bnoo",
      "           hbnoo",
      "           hbnoo",
      "            bnoo",
      "           hbnoo",
      "           hbnoo",
      "            bnoo",
      "           hbnnn",
      "            bbbb",
      "            mh h",
      "                ",
      "                ",
      "                ",
      "                "
    ],
    [
      "           apqqr",
      "           apqqq",
      "           apqqq",
      "           apqqq",
      "           epqqq",
      "           epqqq",
      "           apqqq",
      "           epqqq",
      "           apqqq",
      "           apqqq",
      "           dpppp",
      "           eaeaa",
      "            fgff",
      "                ",
      "                ",
      "                "
    ],
    [
      "            q   ",
      "            q  r",
      "            q  s",
      "            q ss",
      "            q st",
      "            qust",
      "            q st",
      "            q ss",
      "            q  s",
      "            q   ",
      "            qqqq",
      "                ",
      "                ",
      "                ",
      "                ",
      "                "
    ],
    [
      "                ",
      "                ",
      "                ",
      "                ",
      "                ",
      "             w  ",
      "                ",
      "                ",
      "                ",
      "                ",
      "                ",
      "                ",
      "                ",
      "                ",
      "                ",
      "                "
    ]
  ]
}