{
  "name": "multi_hospitaldamaged_2_base1",
  "refpalette": "deceasedcraft:multi_hospitaldamaged_2/multi_hospitaldamaged_2_base1_palette",
  "xsize": 16,
  "zsize": 16,
  "slices": [
    [
      "v a  b     c    ",
      "v d  d  d  d  d ",
      "ved fd ed fd ed ",
      "vghgghgghgghgghg",
      "viiiiiiiiiiiiiii",
      "vj              ",
      "vj              ",
      "vj              ",
      "vj              ",
      "vjk k k klk k k ",
      "vmklk klk k k kl",
      "vmk k k k!k knk ",
      "vmkokokokokokoko",
      "vmpppppppppppppp",
      "vmmmmmmmmmmmmmmm",
      "vvvvvvvvvvvvvvvv"
    ],
    [
      "v               ",
      "v l  l  !  l    ",
      "v q  q  q  q  q ",
      "vghgghgghgghgghg",
      "viiiiiiiiiiiiiii",
      "vj              ",
      "vj              ",
      "vj              ",
      "vj              ",
      "vjkrkrkrkrkrkrkr",
      "vmkrkrkrkrkrkrkr",
      "vmkrkrkrkrkrkrkr",
      "vmkokokokokokoko",
      "vmpppppppppppppp",
      "vmmmmmmmmmmmmmmm",
      "vvvvvvvvvvvvvvvv"
    ],
    [
      "v               ",
      "v               ",
      "v               ",
      "vghgghgghgghgghg",
      "viiiiiiiiiiiiiii",
      "vj              ",
      "vj              ",
      "vj              ",
      "vj              ",
      "vjksksksksksksks",
      "vmksksksksksksks",
      "vmksksksksksksks",
      "vmkokokokokokoko",
      "vmpppppppppppppp",
      "vmmmmmmmmmmmmmmm",
      "vvvvvvvvvvvvvvvv"
    ],
    [
      "v               ",
      "v               ",
      "v               ",
      "vghgghgghgghgghg",
      "viiiiiiiiiiiiiii",
      "vj              ",
      "vj              ",
      "vj              ",
      "vj              ",
      "vjk k k k k k k ",
      "vmk k!ktk k k kt",
      "vmk kuk k kwk k ",
      "vmkokokokokokoko",
      "vmpppppppppppppp",
      "vmmmmmmmmmmmmmmm",
      "vvvvvvvvvvvvvvvv"
    ],
    [
      "vxhxxhxxhxxhxxhx",
      "vxhxxhxxhxxhxxhx",
      "vxhxxhxxhxxhxxhx",
      "vhhhhhhhhhhhhhhh",
      "viiiiiiiiiiiiiii",
      "vj              ",
      "vj              ",
      "vj              ",
      "vj              ",
      "vjkkkkkkkkkkkkkk",
      "vmkkkkkkkkkkkkkk",
      "vmkkkrkkkkkkkkkk",
      "vmkkkkkkkkkkkkkk",
      "vmpppppppppppppp",
      "vmmmmmmmmmmmmmmm",
      "vvvvvvvvvvvvvvvv"
    ],
    [
      "vppppppppppppppp",
      "vpppppmppppppppp",
      "vpppppmppppppppp",
      "vphhhhmhhhhhhhhh",
      "viiiiiiiiiiiiiii",
      "vppppppppppppppp",
      "vppppppppppppppp",
      "vppppppppppppppp",
      "vppppppppppppppp",
      "vppppppppppppppp",
      "vmpppppppppppppp",
      "vmpppppppppppppp",
      "vmpppppppppppppp",
      "vmpppppppppppppp",
      "vmmmmmmmmmmmmmmm",
      "vvvvvvvvvvvvvvvv"
    ]
  ]
}