{
  "name": "multi_nuclearpowerplant_35_base10",
  "refpalette": "deceasedcraft:multi_nuclearpowerplant_35/multi_nuclearpowerplant_35_base10_palette",
  "xsize": 16,
  "zsize": 16,
  "slices": [
    [
      "vvvvvvvvvvvvvvvv",
      "aaaaaaaaaaaaaaaa",
      "aaaaaaaaaaaaaaaa",
      "aaaaaaaaabbbbbbb",
      "aaaaaabbbcd===dc",
      "aaaabbeeecd===dc",
      "aaabeeeeecd===dc",
      "aabceeeeeccdddcc",
      "abdceeeeeeccccce",
      "bccceeeeeeeeeeee",
      "eeeeeeeeeeeeeeee",
      "fffffffffffffffe",
      "ggggggggggggggff",
      "g             gg",
      "                ",
      "                "
    ],
    [
      "vvvvvvvvvvvvvvvv",
      "aaaaaaaaaaaaaaaa",
      "aaaaaaaaaaaaaaaa",
      "aaaaaaaaahiiiiih",
      "aaaaaahhh j klim",
      "aaaahh    inopi ",
      "aaah      i  qi ",
      "aah       riiir ",
      "ahs             ",
      "h t             ",
      "                ",
      " uuuuuuuuuuuuu  ",
      "w             xu",
      "y               ",
      "y               ",
      "y               "
    ],
    [
      "vvvvvvvvvvvvvvvv",
      "aaaaaaaaaaaaaaaa",
      "aaaaaaaaaaaaaaaa",
      "aaaaaaaaahiiiiih",
      "aaaaaahhh A Blim",
      "aaaahh   CiDEFi ",
      "aaah      i I i ",
      "aah       rJJJr ",
      "ahs             ",
      "h               ",
      "                ",
      "                ",
      "                ",
      "K               ",
      "K               ",
      "K               "
    ],
    [
      "vvvvvvvvvvvvvvvv",
      "aaaaaaaaaaaaaaaa",
      "aaaaaaaaaaaaaaaa",
      "aaaaaaaaahiiiiih",
      "aaaaaahhh Lyyyim",
      "aaaahh    iMyyi ",
      "aaah      iqyyi ",
      "aah       rJJJr ",
      "ahs             ",
      "h               ",
      "                ",
      "                ",
      "                ",
      "                ",
      "                ",
      "                "
    ],
    [
      "vvvvvvvvvvvvvvvv",
      "aaaaaaaaaaaaaaaa",
      "aaaaaaaaaaaaaaaa",
      "aaaaaaaaahiiiiih",
      "aaaaaahhh iN OP ",
      "aaaahh    iQR i ",
      "aaah      iSTUi ",
      "aah       rJJJr ",
      "ahs             ",
      "h               ",
      "                ",
      "                ",
      "                ",
      "                ",
      "                ",
      "                "
    ],
    [
      "vvvvvvvvvvvvvvvv",
      "aaaaaaaaaaaaaaaa",
      "aaaaaaaaaaaaaaaa",
      "aaaaaaaaahiiiiih",
      "aaaaaahhh iV W  ",
      "aaaahh    iQ  iX",
      "aaah      iY Zi ",
      "aah       rJJJr ",
      "ahs             ",
      "h               ",
      "                ",
      "                ",
      "                ",
      "                ",
      "                ",
      "                "
    ]
  ]
}