{
  "name": "multi_nuclearpowerplant_35_ground",
  "refpalette": "deceasedcraft:multi_nuclearpowerplant_35/multi_nuclearpowerplant_35_ground_palette",
  "xsize": 16,
  "zsize": 16,
  "slices": [
    [
      "zzzzzzzzzzzzzzzz",
      "azzzazzzzzzzzzzz",
      "zzzzzzzzzzzzzzbz",
      "azazazzzzzzzzzzz",
      "azzaazazzazzzzzz",
      "zazaazazzzzzzzzz",
      "aaabaazzabzzzazz",
      "aaaazzazzzazzzzz",
      "aaaaaaacdaz azzz",
      "aaaaa d       aa",
      "eaaa            ",
      "eee             ",
      "ccef            ",
      "cz              ",
      "                ",
      "                "
    ],
    [
      "         g      ",
      "                ",
      "                ",
      "     c          ",
      "          d     ",
      "                ",
      "      b       c ",
      "                ",
      " c d            ",
      "h               ",
      "zih             ",
      "zzaj            ",
      "az              ",
      "z               ",
      "                ",
      "                "
    ],
    [
      "                ",
      "                ",
      "                ",
      "                ",
      "                ",
      "                ",
      "                ",
      "                ",
      "                ",
      "                ",
      "f               ",
      "ff              ",
      "                ",
      "c               ",
      "                ",
      "                "
    ],
    [
      "                ",
      "                ",
      "                ",
      "                ",
      "                ",
      "                ",
      "                ",
      "                ",
      "                ",
      "                ",
      "f               ",
      "fff             ",
      "  f             ",
      "                ",
      "                ",
      "                "
    ],
    [
      "                ",
      "                ",
      "                ",
      "                ",
      "                ",
      "                ",
      "                ",
      "                ",
      "                ",
      "                ",
      "k               ",
      "  k             ",
      "                ",
      "                ",
      "                ",
      "                "
    ],
    [
      "                ",
      "                ",
      "                ",
      "                ",
      "                ",
      "                ",
      "                ",
      "                ",
      "                ",
      "                ",
      "                ",
      "                ",
      "                ",
      "                ",
      "                ",
      "                "
    ]
  ]
}