{
  "name": "multi_nuclearpowerplant_35_base7",
  "refpalette": "deceasedcraft:multi_nuclearpowerplant_35/multi_nuclearpowerplant_35_base7_palette",
  "xsize": 16,
  "zsize": 16,
  "slices": [
    [
      "vvvvvvvvvvvvvvvv",
      "aaaaaaaaaaaaaaaa",
      "aaaaaaaaaaaaaaaa",
      "bbbbbbbbbbbbbbbb",
      "================",
      "cccccccccccccccc",
      "       d e      ",
      "                ",
      "                ",
      "                ",
      "fffffffgffffffff",
      "hhhhhhhhhhhhhhhf",
      "hhhhhhhhhhhhhhhh",
      "hhhhhhhhhhhhhhhh",
      "hhhhhhhhhhhhhhhh",
      "hhhhhhhh hhhhhhh"
    ],
    [
      "vvvvvvvvvvvvvvvv",
      "aaaaaaaaaaaaaaaa",
      "aaaaaaaaaaaaaaaa",
      "bbbbbbbbbbbbbbbb",
      "================",
      "cccccccccccccccc",
      "       d        ",
      "                ",
      "               i",
      "               j",
      "fffffffgffgfffff",
      "hkhhkkhhkkhhhhkg",
      "hhhkhhhhkkhkhkhh",
      "khhhhhkhkhhhkhkk",
      "hhhkhhhkkkkkhkkk",
      "hhhhhkkk@hkkkkkh"
    ],
    [
      "vvvvvvvvvvvvvvvv",
      "aaaaaaaaaaaaaaaa",
      "aaaaaaaaaaaaaaaa",
      "bbbbbbbbbbbbbbbb",
      "================",
      "cccccccccccccccc",
      "       d        ",
      "                ",
      "              i ",
      "              j ",
      "ffffgfggfggfffgf",
      "       l  m n  g",
      " nm             ",
      "   on  m  pmq   ",
      "  rstmm     pp  ",
      " u w    x       "
    ],
    [
      "vvvvvvvvvvvvvvvv",
      "aaaaaaaaaaaaaaaa",
      "aaaaaaaaaaaaaaaa",
      "bbbbbbbbbbbbbbbb",
      "================",
      "cccccccccccccccc",
      "       d        ",
      "                ",
      "y            i  ",
      "A            j  ",
      "gfffffgfgggfgfff",
      "               g",
      "                ",
      "   o            ",
      "  r!t           ",
      "   w    x       "
    ],
    [
      "vvvvvvvvvvvvvvvv",
      "aaaaaaaaaaaaaaaa",
      "aaaaaaaaaaaaaaaa",
      "bbbbbbbbbbbbbbbb",
      "================",
      "cccccccccccccccc",
      "       d        ",
      "                ",
      " y          i   ",
      " A          j   ",
      "fffffffgggffffff",
      "               f",
      "                ",
      "   o            ",
      "  r t           ",
      "   w    x       "
    ],
    [
      "vvvvvvvvvvvvvvvv",
      "aaaaaaaaaaaaaaaa",
      "aaaaaaaaaaaaaaaa",
      "bbbbbbbbbbbbbbbb",
      "================",
      "cccccccccccccccc",
      "       d        ",
      "                ",
      "  y        i    ",
      "  A        j    ",
      "ffgfffffggffffff",
      "               f",
      "                ",
      "   o            ",
      "    t           ",
      "   w    x       "
    ]
  ]
}