{
  "name": "multi_nuclearpowerplant_35_base9",
  "refpalette": "deceasedcraft:multi_nuclearpowerplant_35/multi_nuclearpowerplant_35_base9_palette",
  "xsize": 16,
  "zsize": 16,
  "slices": [
    [
      "vvvvvvvvvvvvvvvv",
      "aaaaaaaaaaaaaaaa",
      "aaaaaaaaaaaaaaaa",
      "aaaaaaaaabcccccb",
      "aaaaaabbb cd ef ",
      "aaaabb    cg  c ",
      "aaab      ch  c ",
      "aab       ijjji ",
      "abk             ",
      "b               ",
      "                ",
      "                ",
      "                ",
      "                ",
      "                ",
      "                "
    ],
    [
      "vvvvvvvvvvvvvvvv",
      "aaaaaaaaaaaaaaaa",
      "aaaaaaaaaaaaaaaa",
      "aaaaaaaaabcccccb",
      "aaaaaabbb cl  c ",
      "aaaabb    c   c ",
      "aaab      c   c ",
      "aab       ijjji ",
      "abk             ",
      "b               ",
      "                ",
      "                ",
      "                ",
      "                ",
      "            m   ",
      "                "
    ],
    [
      "vvvvvvvvvvvvvvvv",
      "aaaaaaaaaaaaaaaa",
      "aaaaaaaaaaaaaaaa",
      "aaaaaaaaabcccccb",
      "aaaaaabbb cnopc ",
      "aaaabb    c   c ",
      "aaab      c q c ",
      "aab       iccci ",
      "abk             ",
      "b               ",
      "                ",
      "                ",
      "                ",
      "                ",
      "                ",
      "                "
    ],
    [
      "vvvvvvvvvvvvvvvv",
      "aaaaaaaaaaaaaaaa",
      "aaaaaaaaaaaaaaaa",
      "aaaaaaaaabcccccb",
      "aaaaaabbb c r c ",
      "aaaabb    c   c ",
      "aaab      csssc ",
      "aab       iccci ",
      "abk        tut  ",
      "b          twt  ",
      "            w   ",
      "            w   ",
      "            w   ",
      "            w   ",
      "            w   ",
      "            w   "
    ],
    [
      "vvvvvvvvvvvvvvvv",
      "aaaaaaaaaaaaaaaa",
      "aaaaaaaaaaaaaaaa",
      "aaaaaaaaabcccccb",
      "aaaaaabbb c r c ",
      "aaaabb    c   c ",
      "aaab      csssc ",
      "aab       iccci ",
      "abkkkkkkkkkkxkkk",
      "b   k     ykkkA ",
      "    k      ykA  ",
      "    k       k   ",
      "    k       k   ",
      "    k       k   ",
      "    k       k   ",
      "    k       k   "
    ],
    [
      "vvvvvvvvvvvvvvvv",
      "aaaaaaaaaaaaaaaa",
      "aaaaaaaaaaaaaaaa",
      "aaaaaaaaabcccccb",
      "aaaaaabbb c r c ",
      "aaaabb    c   c ",
      "aaab      csssc ",
      "aab       iccci ",
      "abkB       BrB  ",
      "b          kBk  ",
      "                ",
      "                ",
      "                ",
      "                ",
      "                ",
      "                "
    ]
  ]
}