{
  "name": "multi_nuclearpowerplant_35_base4",
  "refpalette": "deceasedcraft:multi_nuclearpowerplant_35/multi_nuclearpowerplant_35_base4_palette",
  "xsize": 16,
  "zsize": 16,
  "slices": [
    [
      "vvvvvvvvvvvvvvvv",
      "aaaaaaaaaaaaaaaa",
      "aaaaaaaaaaaaaaaa",
      "bbbbbbbbbbbbbbbb",
      "================",
      "cccccccccccccccc",
      "                ",
      "                ",
      "                ",
      "                ",
      "dddddddddddddddd",
      "               d",
      "                ",
      "                ",
      "                ",
      "        efff fff"
    ],
    [
      "vvvvvvvvvvvvvvvv",
      "aaaaaaaaaaaaaaaa",
      "aaaaaaaaaaaaaaaa",
      "bbbbbbbbbbbbbbbb",
      "================",
      "cccccccccccccccc",
      "                ",
      "                ",
      "                ",
      "                ",
      "ddddddddddddgddd",
      "               g",
      "                ",
      "                ",
      "                ",
      "        eee hhhe"
    ],
    [
      "vvvvvvvvvvvvvvvv",
      "aaaaaaaaaaaaaaaa",
      "aaaaaaaaaaaaaaaa",
      "bbbbbbbbbbbbbbbb",
      "================",
      "cccccccccccccccc",
      "                ",
      "                ",
      "                ",
      "                ",
      "dddddddddgdddgdd",
      "               d",
      "                ",
      "                ",
      "                ",
      "                "
    ],
    [
      "vvvvvvvvvvvvvvvv",
      "aaaaaaaaaaaaaaaa",
      "aaaaaaaaaaaaaaaa",
      "bbbbbbbbbbbbbbbb",
      "================",
      "cccccccccccccccc",
      "                ",
      "                ",
      "                ",
      "                ",
      "dddddddgdgdddddg",
      "               g",
      "                ",
      "                ",
      "                ",
      "                "
    ],
    [
      "vvvvvvvvvvvvvvvv",
      "aaaaaaaaaaaaaaaa",
      "aaaaaaaaaaaaaaaa",
      "bbbbbbbbbbbbbbbb",
      "================",
      "cccccccccccccccc",
      "                ",
      "                ",
      "                ",
      "                ",
      "dddddddddggdddgd",
      "               g",
      "                ",
      "                ",
      "                ",
      "                "
    ],
    [
      "vvvvvvvvvvvvvvvv",
      "aaaaaaaaaaaaaaaa",
      "aaaaaaaaaaaaaaaa",
      "bbbbbbbbbbbbbbbb",
      "================",
      "cccccccccccccccc",
      "                ",
      "                ",
      "                ",
      "                ",
      "iiiiiii i  iii  ",
      "               i",
      "                ",
      "                ",
      "                ",
      "                "
    ]
  ]
}