{
  "name": "multi_nuclearpowerplant_35_base8",
  "refpalette": "deceasedcraft:multi_nuclearpowerplant_35/multi_nuclearpowerplant_35_base8_palette",
  "xsize": 16,
  "zsize": 16,
  "slices": [
    [
      "vvvvvvvvvvvvvvvv",
      "aaaaaaaaaaaaaaaa",
      "aaaaaaaaaaaaaaaa",
      "bbbbbbbbbcdddddc",
      "bbbbbbccc d e d ",
      "bbbbcc    d   d ",
      "bbbc      dfffd ",
      "bbc       gdddg ",
      "bch         e   ",
      "c          h h  ",
      "                ",
      "                ",
      "                ",
      "                ",
      "                ",
      "                "
    ],
    [
      "vvvvvvvvvvvvvvvv",
      "aaaaaaaaaaaaaaaa",
      "aaaaaaaaaaaaaaaa",
      "iiiiiiiiiiiiiiii",
      "======iiibbbjbbb",
      "====iibbbbbbbbbb",
      "===ibbbbbbbbbbbb",
      "==ibbbbbbbbbbbbb",
      "=ikbbbbbbbbbjbbb",
      "ibbbbbbbbbbbbbbb",
      "bbbbbbbbbbbbbbbb",
      "bbbbbbbbbbbbbbbb",
      "bbbbbbbbbbbbbbbb",
      "bbbbbbbbbbbbbbbb",
      "bbbbbbbbbbbbbbbb",
      "bbbbbbbbbbbbbbbb"
    ],
    [
      "vvvvvvvvvvvvvvvv",
      "aaaaaaaaaaaaaaaa",
      "aaaaaaaaaaaaaaaa",
      "cccccccccccccccc",
      "aaaaaacccaalmlaa",
      "aaaaccaaaaalnlaa",
      "aaacaaaaaaalnlaa",
      "aacaaaaaaaalolaa",
      "acaaaaaaaaalmlaa",
      "caaaaaaaaaalolaa",
      "aaaaaaaaaaalnlaa",
      "aaaaaaaaaaalnlaa",
      "aaaaaaaaaaalnlaa",
      "aaaaaaaaaaalnlaa",
      "aaaaaaaaaaalnlaa",
      "aaaaaaaaaaalnlaa"
    ],
    [
      "vvvvvvvvvvvvvvvv",
      "aaaaaaaaaaaaaaaa",
      "aaaaaaaaaaaaaaaa",
      "cccccccccccccccc",
      "aaaaaacccaaalaaa",
      "aaaaccaaaaaalaaa",
      "aaacaaaaaaaalaaa",
      "aacaaaaaaaaalaaa",
      "acaaaaaaaaaalaaa",
      "caaaaaaaaaaalaaa",
      "aaaaaaaaaaaalaaa",
      "aaaaaaaaaaaalaaa",
      "aaaaaaaaaaaalaaa",
      "aaaaaaaaaaaalaaa",
      "aaaaaaaaaaaalaaa",
      "aaaaaaaaaaaalaaa"
    ],
    [
      "vvvvvvvvvvvvvvvv",
      "aaaaaaaaaaaaaaaa",
      "aaaaaaaaaaaaaaaa",
      "cccccccccccccccc",
      "pppppppppppppppp",
      "================",
      "================",
      "================",
      "================",
      "================",
      "================",
      "================",
      "================",
      "================",
      "================",
      "================"
    ],
    [
      "vvvvvvvvvvvvvvvv",
      "aaaaaaaaaaaaaaaa",
      "aaaaaaaaaaaaaaaa",
      "cccccccccccccccc",
      "================",
      "kkkkkkkkkkkkkkkk",
      "kkkkkkkkkkkkkkkk",
      "kkkkkkkkkkkkkkkk",
      "kkkkkkkkkkkkkkkk",
      "kkkkkkkkkkkkkkkk",
      "kkkkkkkkkkkkkkkk",
      "kkkkkkkkkkkkkkkk",
      "kkkkkkkkkkkkkkkk",
      "kkkkkkkkkkkkkkkk",
      "kkkkkkkkkkkkkkkk",
      "kkkkkkkkkkkkkkkk"
    ]
  ]
}