{
  "name": "multi_nuclearpowerplant_35_base5",
  "refpalette": "deceasedcraft:multi_nuclearpowerplant_35/multi_nuclearpowerplant_35_base5_palette",
  "xsize": 16,
  "zsize": 16,
  "slices": [
    [
      "vvvvvvvvvvvvvvvv",
      "aaaaaaaaaaaaaaaa",
      "aaaaaaaaaaaaaaaa",
      "bbbbbbbbbbbbbbbb",
      "================",
      "cccccccccccccccc",
      "  d             ",
      "  e             ",
      "                ",
      "                ",
      "ffffffffffffffff",
      "               f",
      "                ",
      "                ",
      "                ",
      "        ghhhhhhh"
    ],
    [
      "vvvvvvvvvvvvvvvv",
      "aaaaaaaaaaaaaaaa",
      "aaaaaaaaaaaaaaaa",
      "bbbbbbbbbbbbbbbb",
      "================",
      "cccccccccccccccc",
      " d              ",
      " e              ",
      "                ",
      "                ",
      "ffffffffffffffff",
      "               f",
      "                ",
      "                ",
      "                ",
      "        ghihhhhh"
    ],
    [
      "vvvvvvvvvvvvvvvv",
      "aaaaaaaaaaaaaaaa",
      "aaaaaaaaaaaaaaaa",
      "bbbbbbbbbbbbbbbb",
      "================",
      "cccccccccccccccc",
      "d               ",
      "e               ",
      "                ",
      "                ",
      "ffffffffffffffff",
      "               f",
      "                ",
      "                ",
      "                ",
      "        ghhhhhhh"
    ],
    [
      "vvvvvvvvvvvvvvvv",
      "aaaaaaaaaaaaaaaa",
      "aaaaaaaaaaaaaaaa",
      "bbbbbbbbbbbbbbbb",
      "================",
      "cccccccccccccccc",
      "                ",
      "                ",
      "                ",
      "                ",
      "ffffffffffffffff",
      "               f",
      "                ",
      "                ",
      "                ",
      "        jhhhhhhh"
    ],
    [
      "vvvvvvvvvvvvvvvv",
      "aaaaaaaaaaaaaaaa",
      "aaaaaaaaaaaaaaaa",
      "bbbbbbbbbbbbbbbb",
      "================",
      "cccccccccccccccc",
      "                ",
      "                ",
      "                ",
      "                ",
      "ffffffffffffffff",
      "               f",
      "                ",
      "                ",
      "                ",
      "        jhhhhhhh"
    ],
    [
      "vvvvvvvvvvvvvvvv",
      "aaaaaaaaaaaaaaaa",
      "aaaaaaaaaaaaaaaa",
      "bbbbbbbbbbbbbbbb",
      "================",
      "cccccccccccccccc",
      "                ",
      "                ",
      "                ",
      "                ",
      "ffffffffffffffff",
      "               f",
      "                ",
      "                ",
      "                ",
      "        jhkhhhhh"
    ]
  ]
}