{
  "name": "multi_nuclearpowerplant_35_base11",
  "refpalette": "deceasedcraft:multi_nuclearpowerplant_35/multi_nuclearpowerplant_35_base11_palette",
  "xsize": 16,
  "zsize": 16,
  "slices": [
    [
      "vvvvvvvvvvvvvvvv",
      "aaaaaaaaaaaaaaaa",
      "aaaaaaaaaaaaaaaa",
      "aaaaaaaaabbbbbbb",
      "aaaaaabbb=======",
      "aaaabb==========",
      "aaab============",
      "aab=============",
      "ab==============",
      "b===============",
      "================",
      "================",
      "cccccccccccccc==",
      "cdddddddddddddcc",
      "dddddddddddddddd",
      "dddddddddddddddd"
    ],
    [
      "vvvvvvvvvvvvvvvv",
      "aaaaaaaaaaaaaaaa",
      "aaaaaaaaaaaaaaaa",
      "aaaaaaaaabbbbbbb",
      "aaaaaabbb=======",
      "aaaabb==========",
      "aaab============",
      "aab=============",
      "ab==============",
      "b===============",
      "================",
      "================",
      "cccccccccccccc==",
      "cdddddddddddddcc",
      "dddddddddddddddd",
      "dddddddddddddddd"
    ],
    [
      "vvvvvvvvvvvvvvvv",
      "aaaaaaaaaaaaaaaa",
      "aaaaaaaaaaaaaaaa",
      "aaaaaaaaabbbbbbb",
      "aaaaaabbb=======",
      "aaaabb==========",
      "aaab============",
      "aab=============",
      "ab==============",
      "b===============",
      "================",
      "================",
      "cccccccccccccc==",
      "cdddddddddddddcc",
      "dddddddddddddddd",
      "dddddddddddddddd"
    ],
    [
      "vvvvvvvvvvvvvvvv",
      "aaaaaaaaaaaaaaaa",
      "aaaaaaaaaaaaaaaa",
      "aaaaaaaaabbbbbbb",
      "aaaaaabbb=======",
      "aaaabb==========",
      "aaab============",
      "aab=============",
      "ab==============",
      "b===============",
      "================",
      "================",
      "cccccccccccccc==",
      "cdddddddddddddcc",
      "dddddddddddddddd",
      "dddddddddddddddd"
    ],
    [
      "vvvvvvvvvvvvvvvv",
      "aaaaaaaaaaaaaaaa",
      "aaaaaaaaaaaaaaaa",
      "aaaaaaaaabbbbbbb",
      "aaaaaabbb=======",
      "aaaabb==========",
      "aaab============",
      "aab=============",
      "ab==============",
      "b===============",
      "================",
      "================",
      "cccccccccccccc==",
      "cdddddddddddddcc",
      "dddddddddddddddd",
      "dddddddddddddddd"
    ],
    [
      "vvvvvvvvvvvvvvvv",
      "aaaaaaaaaaaaaaaa",
      "aaaaaaaaaaaaaaaa",
      "aaaaaaaaabbbbbbb",
      "aaaaaabbb=======",
      "aaaabb==========",
      "aaab============",
      "aab=============",
      "ab==============",
      "b===============",
      "================",
      "================",
      "cccccccccccccc==",
      "cdddddddddddddcc",
      "dddddddddddddddd",
      "dddddddddddddddd"
    ]
  ]
}