{
  "name": "multi_nuclearpowerplant_35_base6",
  "refpalette": "deceasedcraft:multi_nuclearpowerplant_35/multi_nuclearpowerplant_35_base6_palette",
  "xsize": 16,
  "zsize": 16,
  "slices": [
    [
      "vvvvvvvvvvvvvvvv",
      "aaaaaaaaaaaaaaaa",
      "aaaaaaaaaaaaaaaa",
      "bbbbbbbbbbbbbbbb",
      "================",
      "cccccccccccccccc",
      "       d        ",
      "                ",
      "   e      f     ",
      "   g      h     ",
      "iiiiiiiijiiiijii",
      "               i",
      "                ",
      "   k            ",
      "                ",
      "        l       "
    ],
    [
      "vvvvvvvvvvvvvvvv",
      "aaaaaaaaaaaaaaaa",
      "aaaaaaaaaaaaaaaa",
      "mmmmmmmmmmmmmmmm",
      "================",
      "cccccccccccccccc",
      "       d        ",
      "                ",
      "    e    f      ",
      "    g    h      ",
      "iiiiiiiiiiiiiiii",
      "               i",
      "                ",
      "                ",
      "                ",
      "        l       "
    ],
    [
      "vvvvvvvvvvvvvvvv",
      "aaaaaaaaaaaaaaaa",
      "aaaaaaaaaaaaaaaa",
      "mmmmmmmmmmmmmmmm",
      "================",
      "cccccccccccccccc",
      "      no        ",
      "      nn        ",
      "     ennf       ",
      "     gnnh       ",
      "iiiiiiiiiiiiiiii",
      "         p     i",
      "         p     p",
      "         p     p",
      "         p     p",
      "        lp     p"
    ],
    [
      "vvvvvvvvvvvvvvvv",
      "aaaaaaaaaaaaaaaa",
      "aaaaaaaaaaaaaaaa",
      "mmmmmmmmmmmmmmmm",
      "================",
      "cccccccccccccccc",
      "     fqr        ",
      "     h s        ",
      "                ",
      "      tt        ",
      "iiiiiiiiiiiiiiii",
      "               i",
      "                ",
      "                ",
      "                ",
      "        luuuuuuu"
    ],
    [
      "vvvvvvvvvvvvvvvv",
      "aaaaaaaaaaaaaaaa",
      "aaaaaaaaaaaaaaaa",
      "mmmmmmmmmmmmmmmm",
      "================",
      "cccccccccccccccc",
      "    f           ",
      "    h           ",
      "                ",
      "                ",
      "iiiiiiiiiiiiiiii",
      "               i",
      "                ",
      "                ",
      "                ",
      "        llllllll"
    ],
    [
      "vvvvvvvvvvvvvvvv",
      "aaaaaaaaaaaaaaaa",
      "aaaaaaaaaaaaaaaa",
      "mmmmmmmmmmmmmmmm",
      "================",
      "cccccccccccccccc",
      "   f            ",
      "   h            ",
      "                ",
      "                ",
      "iiiiiiiiiiiiiiii",
      "               i",
      "                ",
      "                ",
      "                ",
      "        wwwwwwww"
    ]
  ]
}