{
  "name": "multi_nuclearpowerplant_35_base2",
  "refpalette": "deceasedcraft:multi_nuclearpowerplant_35/multi_nuclearpowerplant_35_base2_palette",
  "xsize": 16,
  "zsize": 16,
  "slices": [
    [
      "vvvvvvvvvvvvvvvv",
      "aaaaaaaaaaaaaaaa",
      "aaaaaaaaaaaaaaaa",
      "bbbbbbbbbbbbbbbb",
      "================",
      "cccccccccccccccc",
      "            d   ",
      "                ",
      "                ",
      "                ",
      "                ",
      "                ",
      "                ",
      "            e   ",
      "                ",
      "                "
    ],
    [
      "vvvvvvvvvvvvvvvv",
      "aaaaaaaaaaaaaaaa",
      "aaaaaaaaaaaaaaaa",
      "bbbbbbbbbbbbbbbb",
      "================",
      "cccccccccccccccc",
      "            f   ",
      "            f   ",
      "            f   ",
      "                ",
      "                ",
      "                ",
      "                ",
      "            g   ",
      "                ",
      "                "
    ],
    [
      "vvvvvvvvvvvvvvvv",
      "aaaaaaaaaaaaaaaa",
      "aaaaaaaaaaaaaaaa",
      "bbbbbbbbbbbbbbbb",
      "================",
      "cccccccccccccccc",
      "            h   ",
      "            h   ",
      "            i   ",
      "            f   ",
      "            f   ",
      "           jfk  ",
      "            lfk ",
      "              fk",
      "               f",
      "                "
    ],
    [
      "vvvvvvvvvvvvvvvv",
      "aaaaaaaaaaaaaaaa",
      "aaaaaaaaaaaaaaaa",
      "bbbbbbbbbbbbbbbb",
      "================",
      "cccccccccccccccc",
      "mmmmmmmmmmmmmmmm",
      "                ",
      "                ",
      "            f   ",
      "            n   ",
      "                ",
      "                ",
      "                ",
      "                ",
      "                "
    ],
    [
      "vvvvvvvvvvvvvvvv",
      "aaaaaaaaaaaaaaaa",
      "aaaaaaaaaaaaaaaa",
      "bbbbbbbbbbbbbbbb",
      "oooooooooooooooo",
      "================",
      "cccccccccccccccc",
      "pppppppppppppppp",
      "                ",
      "            f   ",
      "                ",
      "                ",
      "                ",
      "                ",
      "                ",
      "                "
    ],
    [
      "vvvvvvvvvvvvvvvv",
      "aaaaaaaaaaaaaaaa",
      "aaaaaaaaaaaaaaaa",
      "bbbbbbbbbbbbbbbb",
      "oooooooooooooooo",
      "oooooooooooooooo",
      "================",
      "cccccccccccccccc",
      "cccccccccccccccc",
      "cccccccccccccccc",
      "cccccccccccccccc",
      "cccccccccccccccc",
      "ccccccqccclcqccc",
      "cccccqqcqlqqqlcl",
      "ccccqlelqq eeqql",
      "cqcqeqqqe     eq"
    ]
  ]
}