{
  "name": "multi_nuclearpowerplant_35_base12",
  "refpalette": "deceasedcraft:multi_nuclearpowerplant_35/multi_nuclearpowerplant_35_base12_palette",
  "xsize": 16,
  "zsize": 16,
  "slices": [
    [
      "vvvvvvvvvvvvvvvv",
      "aaaaaaaaaaaaaaaa",
      "aaaaaaaaaaaaaaaa",
      "aaaaaaaaaaaaaaaa",
      "aaaaaaaaaaaaaaaa",
      "aaaaaaaaaaaaaaaa",
      "aaaaaaaaaaaaaaaa",
      "aaaaaaaaaaaaaaaa",
      "aaaaaaaaaaaaaaaa",
      "aaaaaaaaaaaaaaaa",
      "aaaaaaaaaaaaaaaa",
      "aaaaaaaaaaaaaaaa",
      "aaaaaaaaaaaaaaaa",
      "aaaaaaaaaaaaaaaa",
      "aaaaaaaaaaaaaaaa",
      "aaaaaaaaaaaaaaaa"
    ],
    [
      "vvvvvvvvvvvvvvvv",
      "aaaaaaaaaaaaaaaa",
      "aaaaaaaaaaaaaaaa",
      "aaaaaaaaabbbbbbb",
      "aaaaaabbbbbbbbbb",
      "aaaabbbbbbbbbbbb",
      "aaabbbbbbbbbbbbb",
      "aabbbbbbbbbbbbbb",
      "abbbbbbbbbbbbbbb",
      "bbbbbbbbbbbbbbbb",
      "bbbbbbbbbbbbbbbb",
      "bbbbbbbbbbbbbbbb",
      "bbbbbbbbbbbbbbbb",
      "bbbbbbbbbbbbbbbb",
      "bbbbbbbbbbbbbbbb",
      "bbbbbbbbbbbbbbbb"
    ],
    [
      "vvvvvvvvvvvvvvvv",
      "aaaaaaaaaaaaaaaa",
      "aaaaaaaaaaaaaaaa",
      "aaaaaaaaaccccccc",
      "aaaaaaccc=======",
      "aaaacc==========",
      "aaac============",
      "aac=============",
      "ac==============",
      "c===============",
      "================",
      "================",
      "================",
      "================",
      "================",
      "================"
    ],
    [
      "vvvvvvvvvvvvvvvv",
      "aaaaaaaaaaaaaaaa",
      "aaaaaaaaaaaaaaaa",
      "aaaaaaaaaddddddd",
      "aaaaaaddd=======",
      "aaaadd==========",
      "aaad============",
      "aad=============",
      "ad==============",
      "d===============",
      "================",
      "================",
      "bbbbbbbbbbbbbb==",
      "beeeeeeeeeeeeebb",
      "eeeeeeeeeeeeeeee",
      "eeeeeeeeeeeeeeee"
    ],
    [
      "vvvvvvvvvvvvvvvv",
      "aaaaaaaaaaaaaaaa",
      "aaaaaaaaaaaaaaaa",
      "aaaaaaaaaddddddd",
      "aaaaaaddd=======",
      "aaaadd==========",
      "aaad============",
      "aad=============",
      "ad==============",
      "d===============",
      "================",
      "================",
      "bbbbbbbbbbbbbb==",
      "bfffffffffffffbb",
      "ffffffffffffffff",
      "ffffffffffffffff"
    ],
    [
      "vvvvvvvvvvvvvvvv",
      "aaaaaaaaaaaaaaaa",
      "aaaaaaaaaaaaaaaa",
      "aaaaaaaaaddddddd",
      "aaaaaaddd=======",
      "aaaadd==========",
      "aaad============",
      "aad=============",
      "ad==============",
      "d===============",
      "================",
      "================",
      "bbbbbbbbbbbbbb==",
      "bfffffffffffffbb",
      "ffffffffffffffff",
      "ffffffffffffffff"
    ]
  ]
}