{
  "name": "multi_casino_4_ground",
  "refpalette": "deceasedcraft:multi_casino_4/multi_casino_4_ground_palette",
  "xsize": 16,
  "zsize": 16,
  "slices": [
    [
      "HHHHHHHHHHHHHHHH",
      "HHHHHHHHHHHHHHHH",
      "HHHHHHHHHHHHHHHH",
      "aaaaaaaaaaaaHHHH",
      "bbcccccbbbbbHHHH",
      "defffffedeebHHHH",
      "defffffedeebHHHH",
      "gdfffffdhddbHHHH",
      "defffffedeebHHHH",
      "defffffedeebHHHH",
      "defffffedeebHHHH",
      "defffffedeebHHHH",
      "defffffedeebHHHH",
      "defffffedeebHHHH",
      "deeeeeeedeebHHHH",
      "gdddddddgddbHHHH"
    ],
    [
      "                ",
      "                ",
      "                ",
      "                ",
      "iijjjjjiiiiik  l",
      "         mmin  o",
      "   pqp    min  o",
      "r  s=s  r tin  o",
      "  uwxwy   min  o",
      "   sAs ~  min  o",
      "   sBs    min  o",
      "  uwCwy   tin  o",
      "   DsE    min  o",
      "          min  o",
      "          min  o",
      "          tin  o"
    ],
    [
      "                ",
      "                ",
      "                ",
      "                ",
      "                ",
      "                ",
      "                ",
      "F  IJI  F K     ",
      "   ILI          ",
      "   MMM ~        ",
      "   M M          ",
      "   NMN    K     ",
      "   OPO          ",
      "                ",
      "                ",
      "          K     "
    ],
    [
      "                ",
      "                ",
      "                ",
      "                ",
      "                ",
      "                ",
      "                ",
      "m       m       ",
      "                ",
      "   IJI ~        ",
      "   ILI          ",
      "    J           ",
      "   LLL          ",
      "                ",
      "                ",
      "                "
    ],
    [
      "                ",
      "                ",
      "                ",
      "                ",
      "                ",
      "                ",
      "                ",
      "Q       Q       ",
      "                ",
      "       ~        ",
      "                ",
      "                ",
      "                ",
      "                ",
      "                ",
      "                "
    ],
    [
      "                ",
      "                ",
      "                ",
      "                ",
      "                ",
      "                ",
      "                ",
      "Q       Q       ",
      "                ",
      "       ~        ",
      "                ",
      "                ",
      "                ",
      "                ",
      "                ",
      "                "
    ]
  ]
}