{
  "name": "multi_casino_4_base8",
  "refpalette": "deceasedcraft:multi_casino_4/multi_casino_4_base8_palette",
  "xsize": 16,
  "zsize": 16,
  "slices": [
    [
      "vvvvvvvvvvvvvvvv",
      "aaaaaaaaaaaaaaaa",
      "bbbbbbbbbbbbbbbb",
      "ccccdcccccccdccc",
      "eeeeeeeeeeeeeeee",
      "ffffffffffffffff",
      "eeeeeeeeeefggggg",
      "eeeeeeeehefggggg",
      "eeeeeeeeeefggggg",
      "eeeeeeeeeefggggg",
      "eeeeeeeeeefggggg",
      "eeeeeeeeeffggggg",
      "eeeeeeeeefgggggg",
      "eeeeeeeeefgggggg",
      "eeeeeeeeffgggggg",
      "eeeeeeeefggggggg"
    ],
    [
      "vvvvvvvvvvvvvvvv",
      "aaaaaaaaaaaaaaaa",
      "bbbbbbbbbbbbbbbb",
      "iiiidiiiiiiidiii",
      "    j       j   ",
      "                ",
      "kkkl            ",
      "eeeeeeeeh      m",
      "eeeeeeeen   o   ",
      "eeeeeeeen  pqr  ",
      "eeeeeeeen   s   ",
      "eeeeeeenn      m",
      "eeeeeeen    o   ",
      "eeeeeenn   pqr  ",
      "eeeeeen     s  t",
      "eeeeenn       mu"
    ],
    [
      "vvvvvvvvvvvvvvvv",
      "aaaaaaaaaaaaaaaa",
      "bbbbbbbbbbbbbbbb",
      "iiiidiiiiiiidiii",
      "                ",
      "                ",
      "                ",
      "        h       ",
      "                ",
      "            w   ",
      "                ",
      "  xy            ",
      "    A           ",
      "                ",
      "                ",
      "B              C"
    ],
    [
      "vvvvvvvvvvvvvvvv",
      "aaaaaaaaaaaaaaaa",
      "bbbbbbbbbbbbbbbb",
      "iiiidiiiiiiidiii",
      "                ",
      "                ",
      "                ",
      "        h       ",
      "                ",
      "                ",
      "                ",
      "                ",
      "                ",
      "                ",
      "                ",
      "D               "
    ],
    [
      "vvvvvvvvvvvvvvvv",
      "aaaaaaaaaaaaaaaa",
      "bbbbbbbbbbbbbbbb",
      "iiiidiiiiiiidiii",
      "                ",
      "                ",
      "                ",
      "        h       ",
      "                ",
      "                ",
      "                ",
      "                ",
      "                ",
      "                ",
      "                ",
      "                "
    ],
    [
      "vvvvvvvvvvvvvvvv",
      "aaaaaaaaaaaaaaaa",
      "bbbbbbbbbbbbbbbb",
      "ii idiiii iidi i",
      "                ",
      "                ",
      "                ",
      "        h       ",
      "                ",
      "                ",
      "                ",
      "                ",
      "                ",
      "                ",
      "                ",
      "                "
    ]
  ]
}