{
  "name": "multi_casino_4_base3",
  "refpalette": "deceasedcraft:multi_casino_4/multi_casino_4_base3_palette",
  "xsize": 16,
  "zsize": 16,
  "slices": [
    [
      "vvvvvvvvvvvvvvvv",
      "aaaaaaaaaaaaaaaa",
      "bbbbbbbbbbbbbbbb",
      "c  cd cc   cdc  ",
      "                ",
      "                ",
      "                ",
      "        e       ",
      "                ",
      "                ",
      "                ",
      "                ",
      "                ",
      "                ",
      "                ",
      "                "
    ],
    [
      "vvvvvvvvvvvvvvvv",
      "aaaaaaaaaaaaaaaa",
      "bbbbbbbbbbbbbbbb",
      "    d c     d   ",
      "                ",
      "                ",
      "                ",
      "        e       ",
      "                ",
      "                ",
      "                ",
      "                ",
      "                ",
      "                ",
      "                ",
      "                "
    ],
    [
      "vvvvvvvvvvvvvvvv",
      "aaaaaaaaaaaaaaaa",
      "bbbbbbbbbbbbbbbb",
      "    d       d   ",
      "                ",
      "                ",
      "                ",
      "       feg      ",
      "        h       ",
      "                ",
      "                ",
      "                ",
      "                ",
      "                ",
      "                ",
      "                "
    ],
    [
      "vvvvvvvvvvvvvvvv",
      "aaaaaaaaaaaaaaaa",
      "bbbbbbbbbbbbbbbb",
      "    d       d   ",
      "                ",
      "                ",
      "                ",
      "        e       ",
      "                ",
      "                ",
      "                ",
      "                ",
      "                ",
      "                ",
      "                ",
      "                "
    ],
    [
      "vvvvvvvvvvvvvvvv",
      "aaaaaaaaaaaaaaaa",
      "bbbbbbbbbbbbbbbb",
      "    d       d   ",
      "iiiiijiiiiijiiii",
      "iiiiiijiiijiiiii",
      "iiiiiiijijiiiiii",
      "kiiikiiieiiikiii",
      "iiiiiiijijiiiiii",
      "iiiiiijiiijiiiii",
      "iiiiijiiiiijiiii",
      "kiiikiiikiiikiii",
      "iiijiiiiiiiiijii",
      "iijiiiiiiiiiiiji",
      "ijiiiiiiiiiiiiij",
      "kiiikiiikiiikiii"
    ],
    [
      "vvvvvvvvvvvvvvvv",
      "aaaaaaaaaaaaaaaa",
      "bbbbbbbbbbbbbbbb",
      "lllldllllllldlll",
      "mmmmnemmmmmenmmm",
      "nnnnnnennnennnnn",
      "nnnnnnnenennnnnn",
      "onnnonnnennnonnn",
      "nnnnnnnenennnnnn",
      "nnnnnnennnennnnn",
      "nnnnnennnnnennnn",
      "onnnennnonnnennn",
      "nnnennnnnnnnnenn",
      "nnennnnnnnnnnnen",
      "nennnnnnnnnnnnne",
      "ennnonnnonnnonnn"
    ]
  ]
}