{
  "name": "multi_casino_4_base4",
  "refpalette": "deceasedcraft:multi_casino_4/multi_casino_4_base4_palette",
  "xsize": 16,
  "zsize": 16,
  "slices": [
    [
      "vvvvvvvvvvvvvvvv",
      "aaaaaaaaaaaaaaaa",
      "bbbbbbbbbbbbbbbb",
      "ccccdcccccccdccc",
      "eeeeeeeeeeeeeeee",
      "ffffffffffffffff",
      "gggggggggggggggg",
      "gggggggghggggggg",
      "gggggggggggggggg",
      "gggggggggggggggg",
      "gggggggggggggggg",
      "gggggggggggggggg",
      "gggggggggggggggg",
      "gggggggggggggggg",
      "gggggggggggggggg",
      "gggggggggggggggg"
    ],
    [
      "vvvvvvvvvvvvvvvv",
      "aaaaaaaaaaaaaaaa",
      "bbbbbbbbbbbbbbbb",
      "iiiidiiiiiiidiii",
      "    j       j   ",
      "                ",
      "                ",
      "  kklkk h kklkk ",
      " mnooonpqmnooonp",
      "  nnnnn   nnnnn ",
      "  rnnnr   rnnnr ",
      "   rrr     rrr  ",
      "                ",
      "                ",
      "   rrr     rrr  ",
      "  rnnnr   rnnnr "
    ],
    [
      "vvvvvvvvvvvvvvvv",
      "aaaaaaaaaaaaaaaa",
      "bbbbbbbbbbbbbbbb",
      "iiiidiiiiiiidiii",
      "                ",
      "                ",
      "                ",
      "        h       ",
      "   stu     w x  ",
      "                ",
      "                ",
      "                ",
      "                ",
      "                ",
      "                ",
      "                "
    ],
    [
      "vvvvvvvvvvvvvvvv",
      "aaaaaaaaaaaaaaaa",
      "bbbbbbbbbbbbbbbb",
      "iiiidiiiiiiidiii",
      "                ",
      "                ",
      "                ",
      "        h       ",
      "                ",
      "                ",
      "                ",
      "                ",
      "                ",
      "                ",
      "                ",
      "                "
    ],
    [
      "vvvvvvvvvvvvvvvv",
      "aaaaaaaaaaaaaaaa",
      "bbbbbbbbbbbbbbbb",
      "iiiidiiiiiiidiii",
      "                ",
      "                ",
      "                ",
      "        h       ",
      "                ",
      "                ",
      "                ",
      "                ",
      "                ",
      "                ",
      "                ",
      "                "
    ],
    [
      "vvvvvvvvvvvvvvvv",
      "aaaaaaaaaaaaaaaa",
      "bbbbbbbbbbbbbbbb",
      "ii idiiii iidi i",
      "                ",
      "                ",
      "                ",
      "        h       ",
      "                ",
      "                ",
      "                ",
      "                ",
      "                ",
      "                ",
      "                ",
      "                "
    ]
  ]
}