{
  "name": "multi_casino_4_base2",
  "refpalette": "deceasedcraft:multi_casino_4/multi_casino_4_base2_palette",
  "xsize": 16,
  "zsize": 16,
  "slices": [
    [
      "vvvvvvvvvvvvvvvv",
      "aaaaaaaaaaaaaaaa",
      "bbbbbbbbbbbbbbbb",
      "ccccdcccccccdccc",
      "eeeeeeeeeeeeeeee",
      "ffffffffffffffff",
      "gggggggggggggggg",
      "gggggggghggggggg",
      "gggggggggggggggg",
      "gggggggggggggggg",
      "gggggggggggggggg",
      "gggggggggggggggg",
      "gggggggggggggggg",
      "gggggggggggggggg",
      "gggggggggggggggg",
      "gggggggggggggggg"
    ],
    [
      "vvvvvvvvvvvvvvvv",
      "aaaaaaaaaaaaaaaa",
      "bbbbbbbbbbbbbbbb",
      "iiiidiiiiiiidiii",
      "    j       j   ",
      "                ",
      "                ",
      "k    k  h k k k ",
      "l    l  m l l l ",
      "nokkpnok  n n n ",
      "q    q    r r r ",
      "k    k    q q q ",
      "          k k k ",
      "                ",
      "    s s s       ",
      "  srrrrrrr      "
    ],
    [
      "vvvvvvvvvvvvvvvv",
      "aaaaaaaaaaaaaaaa",
      "bbbbbbbbbbbbbbbb",
      "iiiidiiiiiiidiii",
      "                ",
      "                ",
      "                ",
      "        h       ",
      "t    t    u u u ",
      "rw  xrw   yAyAyA",
      "B    B   CyCyCyC",
      "          D D D ",
      "                ",
      "                ",
      "                ",
      "   EFIJ K       "
    ],
    [
      "vvvvvvvvvvvvvvvv",
      "aaaaaaaaaaaaaaaa",
      "bbbbbbbbbbbbbbbb",
      "iiiidiiiiiiidiii",
      "                ",
      "                ",
      "                ",
      "        h       ",
      "L    L    t t t ",
      "rM  NrM   O O O ",
      "P    P    Q Q Q ",
      "          B B B ",
      "                ",
      "                ",
      "                ",
      "                "
    ],
    [
      "vvvvvvvvvvvvvvvv",
      "aaaaaaaaaaaaaaaa",
      "bbbbbbbbbbbbbbbb",
      "iiiidiiiiiiidiii",
      "                ",
      "                ",
      "                ",
      "        h       ",
      "R    R          ",
      "ST  U T   V V V ",
      "W    W    X X X ",
      "                ",
      "                ",
      "                ",
      "                ",
      "                "
    ],
    [
      "vvvvvvvvvvvvvvvv",
      "aaaaaaaaaaaaaaaa",
      "bbbbbbbbbbbbbbbb",
      "ii idiiii iidi i",
      "                ",
      "                ",
      "                ",
      "        h       ",
      "                ",
      "Y    Y          ",
      "                ",
      "                ",
      "                ",
      "                ",
      "                ",
      "                "
    ]
  ]
}