{
  "name": "multi_casino_4_base6",
  "refpalette": "deceasedcraft:multi_casino_4/multi_casino_4_base6_palette",
  "xsize": 16,
  "zsize": 16,
  "slices": [
    [
      "vvvvvvvvvvvvvvvv",
      "aaaaaaaaaaaaaaaa",
      "bbbbbbbbbbbbbbbb",
      "ccccdcccccccdccc",
      "eeeeeeeeeeeeeeee",
      "ffffffffffffffff",
      "gggggggggggggggg",
      "gggggggghggggggg",
      "gggggggggggggggg",
      "gggggggggggggggg",
      "gggggggggggggggg",
      "gggggggggggggggg",
      "gggggggggggggggg",
      "gggggggggggggggg",
      "gggggggggggggggg",
      "gggggggggggggggg"
    ],
    [
      "vvvvvvvvvvvvvvvv",
      "aaaaaaaaaaaaaaaa",
      "bbbbbbbbbbbbbbbb",
      "iiiidiiiiiiidiii",
      "    j       j   ",
      "                ",
      "                ",
      "        h       ",
      "k  kkkk l kkkk  ",
      "m  mnompppmnom  ",
      "mqrmmmmp pmmmmqr",
      "m  monmpppmonm  ",
      "k  kkkk s kkkk  ",
      "                ",
      "      l         ",
      "    kmmmk       "
    ],
    [
      "vvvvvvvvvvvvvvvv",
      "aaaaaaaaaaaaaaaa",
      "bbbbbbbbbbbbbbbb",
      "iiiidiiiiiiidiii",
      "                ",
      "                ",
      "                ",
      "        h       ",
      "                ",
      "       t u      ",
      "        w       ",
      "       x y      ",
      "                ",
      "                ",
      "                ",
      "                "
    ],
    [
      "vvvvvvvvvvvvvvvv",
      "aaaaaaaaaaaaaaaa",
      "bbbbbbbbbbbbbbbb",
      "iiiidiiiiiiidiii",
      "                ",
      "                ",
      "                ",
      "        h       ",
      "                ",
      "                ",
      "                ",
      "                ",
      "                ",
      "                ",
      "                ",
      "                "
    ],
    [
      "vvvvvvvvvvvvvvvv",
      "aaaaaaaaaaaaaaaa",
      "bbbbbbbbbbbbbbbb",
      "iiiidiiiiiiidiii",
      "                ",
      "                ",
      "                ",
      "        h       ",
      "                ",
      "                ",
      "                ",
      "                ",
      "                ",
      "                ",
      "                ",
      "                "
    ],
    [
      "vvvvvvvvvvvvvvvv",
      "aaaaaaaaaaaaaaaa",
      "bbbbbbbbbbbbbbbb",
      "ii idiiii iidi i",
      "                ",
      "                ",
      "                ",
      "        h       ",
      "                ",
      "                ",
      "                ",
      "                ",
      "                ",
      "                ",
      "                ",
      "                "
    ]
  ]
}