{
  "name": "multi_casino_4_base7",
  "refpalette": "deceasedcraft:multi_casino_4/multi_casino_4_base7_palette",
  "xsize": 16,
  "zsize": 16,
  "slices": [
    [
      "vvvvvvvvvvvvvvvv",
      "aaaaaaaaaaaaaaaa",
      "bbbbbbbbbbbbbbbb",
      "c  cd cc   cdc  ",
      "                ",
      "                ",
      "                ",
      "        e       ",
      "        f       ",
      "                ",
      "                ",
      "                ",
      "                ",
      "                ",
      "                ",
      "                "
    ],
    [
      "vvvvvvvvvvvvvvvv",
      "aaaaaaaaaaaaaaaa",
      "bbbbbbbbbbbbbbbb",
      "    d c     d   ",
      "                ",
      "                ",
      "                ",
      "        e       ",
      "       ghi      ",
      "                ",
      "                ",
      "                ",
      "                ",
      "                ",
      " j              ",
      "k               "
    ],
    [
      "vvvvvvvvvvvvvvvv",
      "aaaaaaaaaaaaaaaa",
      "bbbbbbbbbbbbbbbb",
      "    d       d   ",
      "                ",
      "                ",
      "                ",
      "        e       ",
      "       gli      ",
      "                ",
      "                ",
      "j               ",
      "                ",
      "                ",
      " m              ",
      "n   j           "
    ],
    [
      "vvvvvvvvvvvvvvvv",
      "aaaaaaaaaaaaaaaa",
      "bbbbbbbbbbbbbbbb",
      "    d       d   ",
      "                ",
      "                ",
      "                ",
      "        e       ",
      "        o       ",
      "                ",
      "                ",
      "m               ",
      "                ",
      "                ",
      "mm              ",
      "nm  m           "
    ],
    [
      "vvvvvvvvvvvvvvvv",
      "aaaaaaaaaaaaaaaa",
      "bbbbbbbbbbbbbbbb",
      "    d       d   ",
      "pppppqpppppqpppp",
      "ppppppqpppqppppp",
      "pppppppqpqpppppp",
      "rppprpppeppprppp",
      "pppppppqpqpppppp",
      "qqqpppqpppqppppp",
      "m qqqqpppppqpppp",
      "m   sqpprppprppp",
      "   k qpppppppqpp",
      "  k  qqpppppppqp",
      " n    qppppppppq",
      "n   mmqprppprppp"
    ],
    [
      "vvvvvvvvvvvvvvvv",
      "aaaaaaaaaaaaaaaa",
      "bbbbbbbbbbbbbbbb",
      "ttttdtttttttdttt",
      "uuuuweuuuuuewuuu",
      "wwwwwwewwwewwwww",
      "wwwwwwwewewwwwww",
      "nwwwnwwwewwwnwww",
      "wwwwwwwewewwwwww",
      "wwwwwwewwwewwwww",
      "nnwwwewwwwwewwww",
      "nxxxewwwnwwwewww",
      "xxxexwwwwwwwweww",
      "xxexxwwwwwwwwwew",
      "xexxxnwwwwwwwwwe",
      "exxxnnwwnwwwnwww"
    ]
  ]
}