{
  "name": "multi_casino_4_base9",
  "refpalette": "deceasedcraft:multi_casino_4/multi_casino_4_base9_palette",
  "xsize": 16,
  "zsize": 16,
  "slices": [
    [
      "vvvvvvvvvvvvvvvv",
      "aaaaaaaaaaaaaaaa",
      "aaaaaaaaaaaaaaaa",
      "aaaaaaaaaaaaaaaa",
      "aaaaaaaaaaaaaaaa",
      "aaaaaaaaaaaaaaaa",
      "aaaaaaaaaaaaaaaa",
      "bbbbbbbbbbbbbbbb",
      "bbbbbbbbbbbbbbbb",
      "bbbbbbbbbbbbbbbb",
      "bbbbbbbbbbbbbbbb",
      "bbbbbbbbbbbbbbbb",
      "bbbbbbbbbbbbbbbb",
      "bbbbbbbbbbbbbbbb",
      "bbbbbbbbbbbbbbbb",
      "bbbbbbbbbbbbbbbb"
    ],
    [
      "vvvvvvvvvvvvvvvv",
      "aaaaaaaaaaaaaaaa",
      "aaaaaaaaaaaaaaaa",
      "aaaaaaaaaaaaaaaa",
      "aaaaaaaaaaaaaaaa",
      "aaaaaaaaaaaaaaaa",
      "aaaaaaaaaaaaaaaa",
      "aaaaaaaacaaddddd",
      "aaaaaaaaaaaddddd",
      "aaaaaaaaaaaddddd",
      "aaaaaaaaaaaddddd",
      "aaaaaaaaaaaddddd",
      "aaaaaaaaaadddddd",
      "aaaaaaaaaadddddd",
      "aaaaaaaaaadddddd",
      "aaaaaaaaaddddddd"
    ],
    [
      "vvvvvvvvvvvvvvvv",
      "aaaaaaaaaaaaaaaa",
      "aaaaaaaaaaaaaaaa",
      "aaaaaaaaaaaaaaaa",
      "aaaaaaaaaaaaaaaa",
      "aaaaaaaaaaaaaaaa",
      "aaaaaaaaaaaaaaaa",
      "aaaaaaaacaaddddd",
      "aaaaaaaaaaaddddd",
      "aaaaaaaaaaaddddd",
      "aaaaaaaaaaaddddd",
      "aaaaaaaaaaaddddd",
      "aaaaaaaaaadddddd",
      "aaaaaaaaaadddddd",
      "aaaaaaaaaadddddd",
      "aaaaaaaaaddddddd"
    ],
    [
      "vvvvvvvvvvvvvvvv",
      "aaaaaaaaaaaaaaaa",
      "aaaaaaaaaaaaaaaa",
      "aaaaaaaaaaaaaaaa",
      "aaaaaaaaaaaaaaaa",
      "aaaaaaaaaaaaaaaa",
      "aaaaaaaaaaaaaaaa",
      "aaaaaaaacaaddddd",
      "aaaaaaaaaaaddddd",
      "aaaaaaaaaaaddddd",
      "aaaaaaaaaaaddddd",
      "aaaaaaaaaaaddddd",
      "aaaaaaaaaadddddd",
      "aaaaaaaaaadddddd",
      "aaaaaaaaaadddddd",
      "aaaaaaaaaddddddd"
    ],
    [
      "vvvvvvvvvvvvvvvv",
      "aaaaaaaaaaaaaaaa",
      "aaaaaaaaaaaaaaaa",
      "aaaaaaaaaaaaaaaa",
      "aaaaaaaaaaaaaaaa",
      "aaaaaaaaaaaaaaaa",
      "aaaaaaaaaaaaaaaa",
      "aaaaaaaacaaddddd",
      "aaaaaaaaaaaddddd",
      "aaaaaaaaaaaddddd",
      "aaaaaaaaaaaddddd",
      "aaaaaaaaaaaddddd",
      "aaaaaaaaaadddddd",
      "aaaaaaaaaadddddd",
      "aaaaaaaaaadddddd",
      "aaaaaaaaaddddddd"
    ],
    [
      "vvvvvvvvvvvvvvvv",
      "aaaaaaaaaaaaaaaa",
      "aaaaaaaaaaaaaaaa",
      "aaaaaaaaaaaaaaaa",
      "aaaaaaaaaaaaaaaa",
      "aaaaaaaaaaaaaaaa",
      "aaaaaaaaaaaaaaaa",
      "aaaaaaaacaaddddd",
      "aaaaaaacacaddddd",
      "aaaaaacaaacddddd",
      "aaaaacaaaaacdddd",
      "aaaacaaaaaadcddd",
      "aaacaaaaaadddcdd",
      "aacaaaaaaaddddcd",
      "acaaaaaaaadddddc",
      "caaaaaaaaddddddd"
    ]
  ]
}