{
  "name": "multi_casino_9_base9",
  "refpalette": "deceasedcraft:multi_casino_9/multi_casino_9_base9_palette",
  "xsize": 16,
  "zsize": 16,
  "slices": [
    [
      "aaaaaaaaaaaaaaaa",
      "aaaaaaaaaaaaaaaa",
      "aaaaaaaaaaaaaaaa",
      "aaaaaaaaaaaaaaaa",
      "aaaaaaaaaaaaaaaa",
      "aaaaaaaaaaaaaaaa",
      "aaaaaaaaaaaaaaaa",
      "aaaaaaaaaaaaaaaa",
      "aaaaaaaaaaaaaaaa",
      "aaaaaaaaaaaaaaaa",
      "aaaaaaaaaaaaaaaa",
      "aaaaaaaaaaaaaaaa",
      "aaaaaaaaaaaaaaaa",
      "aaaaaaaaaaaaaaaa",
      "aaaaaaaaaaaaaaaa",
      "aaaaaaaaaaaaaaaa"
    ],
    [
      "bbbb@@@cde@@@bbb",
      "bb@@@f     f@@@b",
      "bb@g         g@b",
      "h@@    ijkl   @@",
      "b@m     l     n@",
      "@@             @",
      "@o lp       p  q",
      "@r  j      lj  s",
      "@t  u       ul w",
      "@@             @",
      "b@            n@",
      "h@x    ijk    @@",
      "@ y          g@b",
      "   AB      C@@@b",
      "    @@@DEF@@@bbb",
      "   @hb@@@@@bhbbb"
    ],
    [
      "bbbb@@@I J@@@bbb",
      "bb@@@I     K@@@b",
      "bb@L         L@b",
      "h@@    lll    @@",
      "b@K           M@",
      "@@             @",
      "@N          O  M",
      "@   O       l   ",
      "@K  l          K",
      "@@             @",
      "b@            M@",
      "h@P    l l    @@",
      "@ Q          L@b",
      "   RS      K@@@b",
      "    @@@T U@@@bbb",
      "   @hb@@@@@bhbbb"
    ],
    [
      "bbbb@@@   @@@bbb",
      "bb@@@       @@@b",
      "bb@V         V@b",
      "h@@           @@",
      "b@             @",
      "@@             @",
      "@               ",
      "@               ",
      "@               ",
      "@@             @",
      "b@             @",
      "h@W           @@",
      "@ X          V@b",
      "   YZ       @@@b",
      "    @@@   @@@bbb",
      "   @hb@@@@@bhbbb"
    ],
    [
      "bbbb000j1j000bbb",
      "bb000jjjjjjj000b",
      "bb0gjjjjjjjjjg0b",
      "b00jjjjjjjjjjj00",
      "b0jjjjjjjjj2jjj0",
      "00jjjjjjjjjjjjj0",
      "0jjjjjjjjjjjjjjj",
      "03jjjjjj2jjjjjj4",
      "0jjjjjjjjjjjjjjj",
      "00jjjjjjjjjjjjj0",
      "b0jjj2jjjjjjjjj0",
      "h00jjjjjjjjjjj00",
      "@ 0jjjjjjjjjjg0b",
      "  200jjjjjjj000b",
      "    000j5j000bbb",
      "6  @hb00000bbbbb"
    ],
    [
      "b7bb000aaa000bb7",
      "bb000aaaaaaa000b",
      "bb0aaaaaaaaaaa0b",
      "b00aaaaaaaaaaa00",
      "b0aaaaaaaaaaaaa0",
      "00aaaaaaaaaaaaa0",
      "0aaaaaaaaaaaaaaa",
      "0aaaaaaaaaaaaaaa",
      "0aaaaaaaaaaaaaaa",
      "00aaaaaaaaaaaaa0",
      "b0aaaaaaaaaaaaa0",
      "b00aaaaaaaaaaa00",
      "0j0aaaaaaaaaaa0b",
      "jj000aaaaaaa000b",
      "j7jj000aaa000bb7",
      "7jj0bb00000bbbbb"
    ]
  ]
}