{
  "name": "multi_casino_9_ground",
  "refpalette": "deceasedcraft:multi_casino_9/multi_casino_9_ground_palette",
  "xsize": 16,
  "zsize": 16,
  "slices": [
    [
      "abbbbbbbcbbbbbbb",
      "abbbbbbbcbbbbbbb",
      "abbbbbdddddbbbbb",
      "abbbbddeeeddbbbb",
      "abbbdde~~~eddbbb",
      "abbdde~   ~eddbb",
      "abbde~     ~edbb",
      "accde~  f  ~edcc",
      "abbde~     ~edbb",
      "aabdde~   ~eddbb",
      "Habbdde~~~eddbbb",
      "Haabbddeeeddbbbb",
      "HHabbbdddddbbbbb",
      "HHaaabbbcbbbbbbb",
      "HHHHaaabcbbbbbbb",
      "HHHHHHaaaaaaaaaa"
    ],
    [
      "gh              ",
      "gh    ij jj     ",
      "gh   jkkkkki    ",
      "gl  ikk   kkj   ",
      "gh jkk     kkj  ",
      "ghjkk       kkj ",
      "ghjk         ki ",
      "gl k    f    k  ",
      "ghhk~        ki ",
      "gghkk       kkj ",
      "mgl kk     kkj  ",
      "nggh kk   kkj   ",
      "omghh kkkkki    ",
      " nggglhh jj     ",
      " opmggghlhhhlhhh",
      "q  opmgggggggggg"
    ],
    [
      "                ",
      "                ",
      "                ",
      " r              ",
      "                ",
      "                ",
      "        f       ",
      " r     fsf      ",
      "    ~   f       ",
      "                ",
      "  r             ",
      "                ",
      "                ",
      "     r          ",
      "        r   r   ",
      "                "
    ],
    [
      "                ",
      "                ",
      "                ",
      "                ",
      "                ",
      "        f       ",
      "                ",
      "      f   f     ",
      "    ~ ~         ",
      "        f       ",
      "                ",
      "                ",
      "                ",
      "                ",
      "                ",
      "                "
    ],
    [
      "                ",
      "                ",
      "                ",
      "                ",
      "                ",
      "        f       ",
      "                ",
      "      f   f     ",
      "    ~           ",
      "        f       ",
      "                ",
      "                ",
      "                ",
      "                ",
      "                ",
      "                "
    ],
    [
      "                ",
      "                ",
      "                ",
      "                ",
      "        f       ",
      "                ",
      "                ",
      "     f     f    ",
      "    ~           ",
      "                ",
      "        f       ",
      "                ",
      "                ",
      "                ",
      "                ",
      "                "
    ]
  ]
}