{
  "name": "multi_casino_9_base8",
  "refpalette": "deceasedcraft:multi_casino_9/multi_casino_9_base8_palette",
  "xsize": 16,
  "zsize": 16,
  "slices": [
    [
      "aaaabbbcccbbbaaa",
      "aabbbcccccccbbba",
      "aabcccccccccccba",
      "abbcccccccccccbb",
      "abcccccccccccccb",
      "bbcccccdddcccccb",
      "bcccccdddddccccc",
      "ecccccdddddccccc",
      "bcccccdddddccccc",
      "bbcccccdddcccccb",
      "abcccccccccccccb",
      "abbcccccccccccbb",
      "aabcccccccccccba",
      "aabbbcccccccbbba",
      "aaaabbbcccbbbaaa",
      "aaaaaabbebbaaaaa"
    ],
    [
      "    fff   fff   ",
      "  fff       fff ",
      "  f           f ",
      " ff           ff",
      " f             f",
      "ff     ddd     f",
      "f     ddddd     ",
      "e     ddddd     ",
      "f     ddddd     ",
      "ff     ddd     f",
      " f             f",
      " ff           ff",
      "  f           f ",
      "  fff       fff ",
      "    fff   fff   ",
      "      ffeff     "
    ],
    [
      "        e       ",
      "                ",
      "                ",
      "                ",
      "                ",
      "                ",
      "       ggg      ",
      " e     ghg     e",
      "       ggg      ",
      "                ",
      "                ",
      "                ",
      "                ",
      "                ",
      "        e       ",
      "                "
    ],
    [
      "                ",
      "        e       ",
      "                ",
      "                ",
      "                ",
      "                ",
      "        g       ",
      "  e    ghg    e ",
      "        g       ",
      "                ",
      "                ",
      "                ",
      "                ",
      "        e       ",
      "                ",
      "                "
    ],
    [
      "                ",
      "        e       ",
      "                ",
      "                ",
      "                ",
      "                ",
      "        i       ",
      "  e    iji    e ",
      "        i       ",
      "                ",
      "                ",
      "                ",
      "                ",
      "        e       ",
      "                ",
      "                "
    ],
    [
      "                ",
      "                ",
      "        e       ",
      "                ",
      "                ",
      "                ",
      "                ",
      "   e         e  ",
      "                ",
      "                ",
      "                ",
      "                ",
      "        e       ",
      "                ",
      "                ",
      "                "
    ]
  ]
}