{
  "name": "multi_casino_9_base7",
  "refpalette": "deceasedcraft:multi_casino_9/multi_casino_9_base7_palette",
  "xsize": 16,
  "zsize": 16,
  "slices": [
    [
      "                ",
      "                ",
      "                ",
      "        a       ",
      "                ",
      "                ",
      "                ",
      "    a       a   ",
      "                ",
      "                ",
      "                ",
      "        a       ",
      "                ",
      "                ",
      "                ",
      "                "
    ],
    [
      "                ",
      "                ",
      "                ",
      "        a       ",
      "                ",
      "                ",
      "                ",
      "    a       a   ",
      "                ",
      "                ",
      "                ",
      "        a       ",
      "                ",
      "                ",
      "                ",
      "                "
    ],
    [
      "                ",
      "                ",
      "                ",
      "                ",
      "        a       ",
      "                ",
      "                ",
      "     a     a    ",
      "                ",
      "                ",
      "        a       ",
      "                ",
      "                ",
      "                ",
      "                ",
      "                "
    ],
    [
      "                ",
      "                ",
      "                ",
      "                ",
      "                ",
      "        a       ",
      "                ",
      "      a   a     ",
      "                ",
      "        a       ",
      "                ",
      "                ",
      "                ",
      "                ",
      "                ",
      "                "
    ],
    [
      "bcbb         bbc",
      "bb             b",
      "bb             b",
      "b               ",
      "b               ",
      "        a       ",
      "       d d      ",
      "      a   a     ",
      "       d d      ",
      "        a       ",
      "b               ",
      "b               ",
      "bb             b",
      "bb             b",
      "bcbb         bbc",
      "dbbbbb     bbbbb"
    ],
    [
      "eaeefff g fffeea",
      "eefff   g   fffe",
      "eef     g     fe",
      "eff   hiiih   ff",
      "ef   ii~j~ii   f",
      "ff  hijjjjjih  f",
      "f   i~jkakj~i   ",
      "fgggijjalajjiggg",
      "f   i~jkakj~i   ",
      "ff  hijjjjjih  f",
      "ef   ii~j~ii   f",
      "eff   hiiih   ff",
      "eef     g     fe",
      "eefff   g   fffe",
      "eaeefff g fffeea",
      "aeeeeefffffeeeee"
    ]
  ]
}