{
  "name": "multi_casino_9_base1",
  "refpalette": "deceasedcraft:multi_casino_9/multi_casino_9_base1_palette",
  "xsize": 16,
  "zsize": 16,
  "slices": [
    [
      "                ",
      "                ",
      "                ",
      "                ",
      "                ",
      "                ",
      "                ",
      "        a       ",
      "                ",
      "                ",
      "                ",
      "                ",
      "                ",
      "                ",
      "                ",
      "                "
    ],
    [
      "                ",
      "                ",
      "                ",
      "                ",
      "                ",
      "                ",
      "                ",
      "        a       ",
      "                ",
      "                ",
      "                ",
      "                ",
      "                ",
      "                ",
      "                ",
      "                "
    ],
    [
      "                ",
      "                ",
      "                ",
      "                ",
      "                ",
      "                ",
      "                ",
      "        a       ",
      "                ",
      "                ",
      "                ",
      "                ",
      "                ",
      "                ",
      "                ",
      "                "
    ],
    [
      "                ",
      "                ",
      "                ",
      "                ",
      "                ",
      "                ",
      "                ",
      "        a       ",
      "                ",
      "                ",
      "                ",
      "                ",
      "                ",
      "                ",
      "                ",
      "                "
    ],
    [
      "bcbb         bbc",
      "bb             b",
      "bb             b",
      "b               ",
      "b               ",
      "                ",
      "                ",
      "        a       ",
      "                ",
      "                ",
      "b               ",
      "b               ",
      "bb             b",
      "bb             b",
      "bcbb         bbc",
      "dbbbbb     bbbbb"
    ],
    [
      "eaeefffgggfffeea",
      "eefffgggggggfffe",
      "eefggg     gggfe",
      "effgg       ggff",
      "efgg         ggf",
      "ffg           gf",
      "fgg           gg",
      "fgg     a     gg",
      "fgg           gg",
      "ffg           gf",
      "efgg         ggf",
      "effgg       ggff",
      "eefggg     gggfe",
      "eefffgggggggfffe",
      "eaeefffgggfffeea",
      "aeeeeefffffeeeee"
    ]
  ]
}