{
  "name": "multi_alienresearch_7_base6",
  "refpalette": "deceasedcraft:multi_alienresearch_7/multi_alienresearch_7_base6_palette",
  "xsize": 16,
  "zsize": 16,
  "slices": [
    [
      "a               ",
      "baaa    cccccccc",
      "bbbbaaddddeddddd",
      "bbbbbbbddddddddd",
      "bbbbbbbfffffffff",
      "bbbbbbbfffffffff",
      "bbbbbbbfffffffff",
      "bbbbffffffffffff",
      "bbbbfcffffffffff",
      "bbbbfgffffffffff",
      "bbbbfcffffffffff",
      "bbbbffffffffffff",
      "bbbbbbbfffffffff",
      "bbbbbbbfffffffff",
      "bbbbbbbhhhhhhhhh",
      "vvvvvvvvvvvvvvvv"
    ],
    [
      "a               ",
      "baaa  cc        ",
      "bbbbaddd        ",
      "bbbbbdddiiiiiiii",
      "bbbbbfff        ",
      "bbbbbfffjklkm   ",
      "bbbbbfff        ",
      "bbbbffff  n     ",
      "bbbbfcff       o",
      "bbbbfgff        ",
      "bbbbfcff        ",
      "bbbbffff        ",
      "bbbbbfff        ",
      "bbbbbfff      pp",
      "bbbbbhhhhhhhhhhh",
      "vvvvvvvvvvvvvvvv"
    ],
    [
      "                ",
      "aaa  cc         ",
      "bbbaddd         ",
      "bbbbbddiqqqqqqqq",
      "bbbbbf          ",
      "bbbbbf   rst    ",
      "bbbbbf          ",
      "bbbbff          ",
      "bbbbf           ",
      "bbbbfu          ",
      "bbbbf           ",
      "bbbbff          ",
      "bbbbbf          ",
      "bbbbbf        ww",
      "bbbbbhhhhhhhhhhh",
      "vvvvvvvvvvvvvvvv"
    ],
    [
      "                ",
      "aa   c          ",
      "bbaadd          ",
      "bbbbddxqqqqqqqqq",
      "bbbbff          ",
      "bbbbff          ",
      "bbbbff          ",
      "bbbbffy         ",
      "bbbbf           ",
      "bbbbf           ",
      "bbbbf           ",
      "bbbbffy         ",
      "bbbbbf          ",
      "bbbbbf        ww",
      "bbbbbhhhhhhhhhhh",
      "vvvvvvvvvvvvvvvv"
    ],
    [
      "                ",
      "aa  c           ",
      "bbadd           ",
      "bbbbdxqqqqqqqqqq",
      "bbbbf           ",
      "bbbbf           ",
      "bbbbf           ",
      "bbbbfA          ",
      "bbbbf           ",
      "bbbbf           ",
      "bbbbf           ",
      "bbbbfA          ",
      "bbbbf           ",
      "bbbbf         BC",
      "bbbbhhhhhhhhhhhh",
      "vvvvvvvvvvvvvvvv"
    ],
    [
      "                ",
      "dd  c           ",
      "bbddd           ",
      "bbbbdxqqqqqqqqqq",
      "bbbbf           ",
      "bbbbf           ",
      "bbbbf           ",
      "bbbbfA          ",
      "bbbbD           ",
      "bbbbD           ",
      "bbbbD           ",
      "bbbbfA          ",
      "bbbbf           ",
      "bbbbf           ",
      "bbbbhhhhhhhhhhhh",
      "vvvvvvvvvvvvvvvv"
    ]
  ]
}