{
  "name": "multi_alienresearch_7_top",
  "refpalette": "deceasedcraft:multi_alienresearch_7/multi_alienresearch_7_top_palette",
  "xsize": 16,
  "zsize": 16,
  "slices": [
    [
      "ab              ",
      "ab              ",
      "abcccdc         ",
      "ab              ",
      "ab              ",
      "ab              ",
      "ab              ",
      "ab              ",
      "eb              ",
      "abcccdc      c  ",
      "ffffghffg  ffiff",
      "                ",
      "                ",
      "                ",
      "                ",
      "                "
    ],
    [
      " ejab d         ",
      " eeab d         ",
      " ejabcccd !     ",
      " ejab d         ",
      " eja  d         ",
      "  jab d         ",
      " ejab d         ",
      " ejab d         ",
      " eeab d         ",
      "  jabcccd    c  ",
      " klffffig fffiff",
      "                ",
      "                ",
      "                ",
      "                ",
      "                "
    ],
    [
      "    ejab        ",
      "    ejab        ",
      "    ejabcccd    ",
      "    eee         ",
      "     eab        ",
      "    ejab        ",
      "    ejab        ",
      "    ejab        ",
      "    eeab        ",
      "    ejabcccd c  ",
      "    klffffffffff",
      "                ",
      "                ",
      "                ",
      "                ",
      "                "
    ],
    [
      "       ejab  d  ",
      "       emmm  d  ",
      "        jabcccd ",
      "         ab  d  ",
      "         nm  d  ",
      "       ejab  d  ",
      "       ejab  d  ",
      "       emmm  d  ",
      "       ejab  d  ",
      "       ejabcccdo",
      "       klgffffff",
      "                ",
      "                ",
      "                ",
      "                ",
      "                "
    ],
    [
      "          eeab  ",
      "           nab  ",
      "           jabcc",
      "          ejab  ",
      "           mab  ",
      "          ejab  ",
      "          eja   ",
      "           mab  ",
      "           jab  ",
      "          ejabcc",
      "          klkfff",
      "                ",
      "                ",
      "                ",
      "                ",
      "                "
    ],
    [
      "             eja",
      "             eem",
      "             eja",
      "             eja",
      "             ejm",
      "              ja",
      "              ja",
      "             ejm",
      "             eja",
      "              ja",
      "             klf",
      "                ",
      "                ",
      "                ",
      "                ",
      "                "
    ]
  ]
}