{
  "name": "multi_alienresearch_7_base7",
  "refpalette": "deceasedcraft:multi_alienresearch_7/multi_alienresearch_7_base7_palette",
  "xsize": 16,
  "zsize": 16,
  "slices": [
    [
      "aaaabccccdedcccc",
      "aaaabffffdddffff",
      "aaaabffffdddffff",
      "aaaabffffdddffff",
      "aaaabffffdddffff",
      "aaaabffffdddffff",
      "aaaabffffdddffff",
      "aaaabgfffdddffff",
      "aaaaghfffdddffff",
      "aaaagifffdddffff",
      "aaaaghfffdddffff",
      "bbbbbgfffdddffff",
      "j    kfffdddffff",
      "j    kfffdddffff",
      "bbbbblbbbbbbbbbb",
      "vvvvvvvvvvvvvvvv"
    ],
    [
      "aaaacccccdddcccc",
      "aaaaaaaaaaaaaaaa",
      "aaaaaaaaaaaaaaaa",
      "aaaaaaaaaaaaaaaa",
      "aaaaaaaaaaaaaaaa",
      "aaaaaaaaaaaaaaaa",
      "aaaaaaaaaaaaaaaa",
      "aaaagggaaaaaaaaa",
      "aaaaghgaaaaaaaaa",
      "aaaagigaaaaaaaaa",
      "aaaaghgaaaaaaaaa",
      "bbbbbggaaaaaaaaa",
      "    kaaaaaaaaaaa",
      "    kaaaaaaaaaaa",
      "bbbbbaaaaaaaaaaa",
      "vvvvvvvvvvvvvvvv"
    ],
    [
      "aacccc    h    c",
      "aaaaaacccdddccca",
      "aaaaaaaaaaaaaaaa",
      "aaaaaaaaaaaaaaaa",
      "aaaaaaaaaaaaaaaa",
      "aaaaaaaaaaaaaaaa",
      "aaaaaaaaaaaaaaaa",
      "aaaagggaaaaaaaaa",
      "aaaaghgaaaaaaaaa",
      "aaaagigaaaaaaaaa",
      "aaaaghgaaaaaaaaa",
      "bbbbgggaaaaaaaaa",
      "   kaaaaaaaaaaaa",
      "   kaaaaaaaaaaaa",
      "bbbbaaaaaaaaaaaa",
      "vvvvvvvvvvvvvvvv"
    ],
    [
      "accc      h     ",
      "aaaacccccdddcccc",
      "aaaaaaaaaaaaaaaa",
      "aaaaaaaaaaaaaaaa",
      "aaaaaaaaaaaaaaaa",
      "aaaaaaaaaaaaaaaa",
      "aaaaaaaaaaaaaaaa",
      "aaaagggaaaaaaaaa",
      "aaaaghgaaaaaaaaa",
      "aaaagigaaaaaaaaa",
      "aaaaghgaaaaaaaaa",
      "bbbagggaaaaaaaaa",
      "  kaaaaaaaaaaaaa",
      "  kaaaaaaaaaaaaa",
      "bbbaaaaaaaaaaaaa",
      "vvvvvvvvvvvvvvvv"
    ],
    [
      "ccc             ",
      "aaacccc   h   cc",
      "aaaaaaaccdddccaa",
      "aaaaaaaaaaaaaaaa",
      "aaaaaaaaaaaaaaaa",
      "aaaaaaaaaaaaaaaa",
      "aaaaaaaaaaaaaaaa",
      "aaaagggaaaaaaaaa",
      "aaaaghgaaaaaaaaa",
      "aaaagigaaaaaaaaa",
      "aaaaghgaaaaaaaaa",
      "bbaagggaaaaaaaaa",
      " kaaaaaaaaaaaaaa",
      " kaaaaaaaaaaaaaa",
      "bbaaaaaaaaaaaaaa",
      "vvvvvvvvvvvvvvvv"
    ],
    [
      "cc              ",
      "aacccc    h    d",
      "aaaaaaccddddddda",
      "aaaaaaaaaaaaaaaa",
      "aaaaaaaaaaaaaaaa",
      "aaaaaaaaaaaaaaaa",
      "aaaaaaaaaaaaaaaa",
      "aaaagggaaaaaaaaa",
      "aaaaghgaaaaaaaaa",
      "aaaagigaaaaaaaaa",
      "aaaaghgaaaaaaaaa",
      "baaagggaaaaaaaaa",
      "kaaaaaaaaaaaaaaa",
      "kaaaaaaaaaaaaaaa",
      "baaaaaaaaaaaaaaa",
      "vvvvvvvvvvvvvvvv"
    ]
  ]
}