{
  "name": "multi_alienresearch_7_base2",
  "refpalette": "deceasedcraft:multi_alienresearch_7/multi_alienresearch_7_base2_palette",
  "xsize": 16,
  "zsize": 16,
  "slices": [
    [
      "aaaaab         b",
      "aaaaab         b",
      "aaaaab   @@@   b",
      "aaaaab  @   @  b",
      "aaaaab  @   @  b",
      "aaaaab  @   @  b",
      "aaaaab cdefcgc b",
      "aaaaab  @   @  b",
      "aaaaab  @   @  b",
      "aaaaab  @   @  b",
      "aaaaab   @@@   b",
      "aaaaab         b",
      "aaaaab         b",
      "aaaaab         b",
      "aaaaabbbbbbbbbbb",
      "vvvvvvvvvvvvvvvv"
    ],
    [
      "aaaaab hiiiiij b",
      "aaaaab hiiiiij b",
      "aaaaab hk@@@kj b",
      "aaaaab h@lll@j b",
      "aaaaab h@lll@j b",
      "aaaaab h@lll@j b",
      "aaaaab h@lll@j b",
      "aaaaab h@lll@j b",
      "aaaaab h@lll@j b",
      "aaaaab h@lll@j b",
      "aaaaab hk@@@kj b",
      "aaaaab hiiiiij b",
      "aaaaab hiiiiij b",
      "aaaaab hiiiiij b",
      "aaaaabbbbbbbbbbb",
      "vvvvvvvvvvvvvvvv"
    ],
    [
      "aaaaabmnmmmmmnmb",
      "aaaaabmnmmmmmnmb",
      "aaaaabmnmmmmmnmb",
      "aaaaabmnmmmmmnmb",
      "aaaaabmnmmmmmnmb",
      "aaaaabmnmmmmmnmb",
      "aaaaabmnmmmmmnmb",
      "aaaaabmnmmmmmnmb",
      "aaaaabmnmmmmmnmb",
      "aaaaabmnmmmmmnmb",
      "aaaaabmnmmmmmnmb",
      "aaaaabmnmmmmmnmb",
      "aaaaabmnmmmmmnmb",
      "aaaaabmnmmmmmnmb",
      "aaaaabbbbbbbbbbb",
      "vvvvvvvvvvvvvvvv"
    ],
    [
      "aaaaaaaaaaaaaaaa",
      "aaaaaaaaaaaaaaaa",
      "aaaaaaaaaaaaaaaa",
      "aaaaaaaaaaaaaaaa",
      "aaaaaaaaaaaaaaaa",
      "aaaaaaaaaaaaaaaa",
      "aaaaaaaaaaaaaaaa",
      "aaaaaaaaaaaaaaaa",
      "aaaaaaaaaaaaaaaa",
      "aaaaaaaaaaaaaaaa",
      "aaaaaaaaaaaaaaaa",
      "aaaaaaaaaaaaaaaa",
      "aaaaaaaaaaaaaaaa",
      "aaaaaaaaaaaaaaaa",
      "aaaaaaaaaaaaaaaa",
      "vvvvvvvvvvvvvvvv"
    ],
    [
      "aaaaaaaaaaaaaaaa",
      "aaaaaaaaaaaaaaaa",
      "aaaaaaaaaaaaaaaa",
      "aaaaaaaaaaaaaaaa",
      "aaaaaaaaaaaaaaaa",
      "aaaaaaaaaaaaaaaa",
      "aaaaaaaaaaaaaaaa",
      "aaaaaaaaaaaaaaaa",
      "aaaaaaaaaaaaaaaa",
      "aaaaaaaaaaaaaaaa",
      "aaaaaaaaaaaaaaaa",
      "aaaaaaaaaaaaaaaa",
      "aaaaaaaaaaaaaaaa",
      "aaaaaaaaaaaaaaaa",
      "aaaaaaaaaaaaaaaa",
      "vvvvvvvvvvvvvvvv"
    ],
    [
      "aaaaaaaaaaaaaaaa",
      "aaaaaaaaaaaaaaaa",
      "aaaaaaaaaaaaaaaa",
      "aaaaaaaaaaaaaaaa",
      "aaaaaaaaaaaaaaaa",
      "aaaaaaaaaaaaaaaa",
      "aaaaaaaaaaaaaaaa",
      "aaaaaaaaaaaaaaaa",
      "aaaaaaaaaaaaaaaa",
      "aaaaaaaaaaaaaaaa",
      "aaaaaaaaaaaaaaaa",
      "aaaaaaaaaaaaaaaa",
      "aaaaaaaaaaaaaaaa",
      "aaaaaaaaaaaaaaaa",
      "aaaaaaaaaaaaaaaa",
      "vvvvvvvvvvvvvvvv"
    ]
  ]
}