{
  "name": "multi_alienresearch_7_base5",
  "refpalette": "deceasedcraft:multi_alienresearch_7/multi_alienresearch_7_base5_palette",
  "xsize": 16,
  "zsize": 16,
  "slices": [
    [
      "aa              ",
      "bbaaa           ",
      "ccbbd           ",
      "ccccbeffffffffff",
      "ccccg           ",
      "ccccg           ",
      "ccccg           ",
      "ccccgh          ",
      "ccccg           ",
      "ccccg           ",
      "cccci           ",
      "ccccgh          ",
      "ccccg           ",
      "ccccg           ",
      "ccccjjjjjjjjjjjj",
      "vvvvvvvvvvvvvvvv"
    ],
    [
      "                ",
      "bb  a           ",
      "ccbbb           ",
      "ccccbeffffffffff",
      "ccccg           ",
      "ccccg           ",
      "ccccg           ",
      "ccccgh          ",
      "cccci           ",
      "cccci           ",
      "ccccg           ",
      "ccccgh          ",
      "ccccg           ",
      "ccccg           ",
      "ccccjjjjjjjjjjjj",
      "vvvvvvvvvvvvvvvv"
    ],
    [
      "                ",
      "kk  a           ",
      "cckbb           ",
      "ccccbeffffffffff",
      "ccccg           ",
      "ccccg           ",
      "ccccg           ",
      "ccccgh          ",
      "ccccg           ",
      "ccccg           ",
      "ccccg           ",
      "ccccgh          ",
      "ccccg           ",
      "ccccg           ",
      "ccccjjjjjjjjjjjj",
      "vvvvvvvvvvvvvvvv"
    ],
    [
      "                ",
      "kk   a          ",
      "cckkbb          ",
      "ccccbbefffffffff",
      "ccccgg          ",
      "ccccgg          ",
      "ccccgg          ",
      "ccccgg          ",
      "ccccgg          ",
      "ccccgg          ",
      "ccccgg          ",
      "ccccgg          ",
      "ccccgg          ",
      "ccccgg          ",
      "ccccjjjjjjjjjjjj",
      "vvvvvvvvvvvvvvvv"
    ],
    [
      "                ",
      "kkk  aa         ",
      "ccckbbb         ",
      "cccccbblffffffff",
      "cccccg          ",
      "cccccg          ",
      "cccccg          ",
      "cccccg          ",
      "cccccg          ",
      "cccccg          ",
      "cccccg          ",
      "cccccg          ",
      "cccccg          ",
      "cccccg          ",
      "cccccjjjjjjjjjjj",
      "vvvvvvvvvvvvvvvv"
    ],
    [
      "k               ",
      "ckkk  aa        ",
      "cccckbbb        ",
      "cccccbbbllllllll",
      "cccccggg        ",
      "cccccggg        ",
      "cccccggg        ",
      "cccccggg  m    m",
      "cccccggg  m    m",
      "cccccggg  m    m",
      "cccccggg  m    m",
      "cccccggg  m    m",
      "cccccggg        ",
      "cccccggg        ",
      "cccccjjjjjjjjjjj",
      "vvvvvvvvvvvvvvvv"
    ]
  ]
}