{
  "name": "multi_alienresearch_7_base8",
  "refpalette": "deceasedcraft:multi_alienresearch_7/multi_alienresearch_7_base8_palette",
  "xsize": 16,
  "zsize": 16,
  "slices": [
    [
      "aaaabccccccccccc",
      "aaaabccccccccccc",
      "aaaabccccccccccc",
      "aaaabccccccccccc",
      "aaaabccccccccccc",
      "aaaabccccccccccc",
      "aaaabccccccccccc",
      "aaaabdcccccccccc",
      "aaaadccccccccccc",
      "aaaadccccccccccc",
      "aaaadccccccccccc",
      "aaaaddcccccccccc",
      "aaaaaacccccccccc",
      "aaaaaacccccccccc",
      "aaaaaabbbbbbbbbb",
      "vvvvvvvvvvvvvvvv"
    ],
    [
      "aaaabee f   f eg",
      "aaaabddddh hdddd",
      "aaaabij   k   li",
      "aaaabij   m   li",
      "aaaabddddn ndddd",
      "aaaabo      dpq ",
      "aaaabg      d   ",
      "aaaabd      drdd",
      "aaaads         t",
      "aaaadu         t",
      "aaaads         t",
      "aaaadd      dwdd",
      "aaaaax     yd   ",
      "aaaaax     AdBC ",
      "aaaaaDbbbbbbbbbb",
      "vvvvvvvvvvvvvvvv"
    ],
    [
      "aaaab           ",
      "aaaabddddh hdddd",
      "aaaabij   E   li",
      "aaaabij   F   li",
      "aaaabddddn ndddd",
      "aaaab  I    d JK",
      "aaaab       d   ",
      "aaaabd      dLdd",
      "aaaads          ",
      "aaaadu          ",
      "aaaads          ",
      "aaaabd      dMdd",
      "aaaax      Ad   ",
      "aaaax N    Od PQ",
      "aaaabRbbbbbbbbbb",
      "vvvvvvvvvvvvvvvv"
    ],
    [
      "aaaab           ",
      "aaaabddddhhhdddd",
      "aaaabij       li",
      "aaaabij       li",
      "aaaabddddnnndddd",
      "aaaabS      d  T",
      "aaaabS      d   ",
      "aaaabd      dddd",
      "aaaads         U",
      "aaaadu         V",
      "aaaads         W",
      "aaabbd      dddd",
      "aaax        d   ",
      "aaax        d  X",
      "aaabbRbbbbbbbbbb",
      "vvvvvvvvvvvvvvvv"
    ],
    [
      "aaaab     s     ",
      "aaaabddddddddddd",
      "aaaab           ",
      "aaaab           ",
      "aaaabddddddddddd",
      "aaaab     Y d   ",
      "aaaabZ      d   ",
      "aaaabd      dddd",
      "aaaads      d   ",
      "aaaadu      d   ",
      "aaaads      d   ",
      "aabbbd      dddd",
      "aax         d   ",
      "aax         d   ",
      "aabbbRbbbbbbbbbb",
      "vvvvvvvvvvvvvvvv"
    ],
    [
      "aaaab01112221110",
      "aaaab3ddddddddd3",
      "aaaab4         5",
      "aaaab4         5",
      "aaaab3ddddddddd3",
      "aaaab6      d  3",
      "aaaab       d  5",
      "aaaabd      ddd3",
      "aaaads      d  3",
      "aaaadu      d  3",
      "aaaads      d  3",
      "abbbbd      ddd3",
      "ax          d  5",
      "ax          d  3",
      "abbbbRbbbbbbbbbb",
      "vvvvvvvvvvvvvvvv"
    ]
  ]
}