{
  "name": "multi_alienresearch_7_ground",
  "refpalette": "deceasedcraft:multi_alienresearch_7/multi_alienresearch_7_ground_palette",
  "xsize": 16,
  "zsize": 16,
  "slices": [
    [
      "abaaabcdzddddedd",
      "aaaaabcdeddedddd",
      "aaabaafddededddd",
      "aaaabbcddddddddd",
      "bbababcddddddede",
      "aabaaacddddddddd",
      "ababaacddedddddd",
      "bbbaabcedddddddd",
      "bzbbbaczzeeddddd",
      "zbzbzbfezdzedfee",
      "cccccccccccccccc",
      "gvvvvgvvvvvgvvvv",
      "gggggvhggvgggghg",
      "ghzhhhghhzhghhzh",
      "zzhgzhzhzzzzzhzz",
      "zzzzzzzzzzhzzzzh"
    ],
    [
      "!i   jk l       ",
      "m n ojc         ",
      "ccpqckr         ",
      "        s       ",
      "                ",
      "                ",
      "                ",
      "                ",
      " l     l        ",
      "  t l r t l  r u",
      "wwwwwwwwwwwwwwww",
      "                ",
      "                ",
      "xxxxxxxx xxxxxxx",
      "    l     l    l",
      "l ll    l   ll  "
    ],
    [
      "     yA         ",
      "o    oA         ",
      "AABCAAr         ",
      "                ",
      "                ",
      "                ",
      "                ",
      "                ",
      "                ",
      "   D  r      r  ",
      "EE FEEEEEEEEEI E",
      "                ",
      "                ",
      "xxxxxxxxxxxxxxxx",
      "                ",
      "                "
    ],
    [
      "      A         ",
      "      A         ",
      "AAJJAAr         ",
      "                ",
      "                ",
      "                ",
      "                ",
      "                ",
      "                ",
      "   D  r  DD  rD ",
      "KEILEEEIEEEEEILE",
      "                ",
      "                ",
      "xxxxxxx  xxxxxxx",
      "                ",
      "                "
    ],
    [
      "     MN         ",
      "     MA         ",
      "AOAAAOr         ",
      "                ",
      "                ",
      "                ",
      "                ",
      "                ",
      "                ",
      "  DD  r   D  rD ",
      "KEIEIEEIP EEEEEE",
      "                ",
      "                ",
      "QQQQQQQ QQQQQQQQ",
      "                ",
      "                "
    ],
    [
      "      A         ",
      "      A         ",
      "rrROS r         ",
      "                ",
      "                ",
      "                ",
      "                ",
      "                ",
      "                ",
      "rrR D r   D  r  ",
      "KEEEIEEE  IEEKEE",
      "                ",
      "                ",
      "                ",
      "                ",
      "                "
    ]
  ]
}