{
  "name": "multi_alienresearch_7_base3",
  "refpalette": "deceasedcraft:multi_alienresearch_7/multi_alienresearch_7_base3_palette",
  "xsize": 16,
  "zsize": 16,
  "slices": [
    [
      "aaaaabcdddedddcb",
      "aaaaabcccccccccb",
      "aaaaabccfffffccb",
      "aaaaabccfcccfccb",
      "aaaaabccfcccfccb",
      "aaaaabccfcccfccb",
      "aaaaabccfcccfccb",
      "aaaaabccfcccfccb",
      "aaaaabccfcccfccb",
      "aaaaabccfcccfccb",
      "aaaaabccfffffccb",
      "aaaaabcccccccccb",
      "aaaaabcccccccccb",
      "aaaaabcccccccccb",
      "aaaaabbbbbbbbbbb",
      "vvvvvvvvvvvvvvvv"
    ],
    [
      "aaaaabg   h   gb",
      "aaaaab         b",
      "aaaaab  ijjji  b",
      "aaaaab  jjjjj  b",
      "aaaaab  jjjjjk b",
      "aaaaab  jjjjj  b",
      "aaaaabl jjjjj  b",
      "aaaaab  jjjjj  b",
      "aaaaab  jjjjjm b",
      "aaaaab  jjjjj  b",
      "aaaaab  ijjji nb",
      "aaaaabo       pb",
      "aaaaab q      rb",
      "aaaaabssttuttssb",
      "aaaaabbbbbbbbbbb",
      "vvvvvvvvvvvvvvvv"
    ],
    [
      "aaaaab         b",
      "aaaaab         b",
      "aaaaab   @@@   b",
      "aaaaab  @   @  b",
      "aaaaab  @ w @  b",
      "aaaaab  @ x @  b",
      "aaaaab  @   y  b",
      "aaaaab  @   @  b",
      "aaaaab  @ A @  b",
      "aaaaab  @   @  b",
      "aaaaab   @@@   b",
      "aaaaab         b",
      "aaaaab         b",
      "aaaaab BCD EF !b",
      "aaaaabbbbbbbbbbb",
      "vvvvvvvvvvvvvvvv"
    ],
    [
      "aaaaab         b",
      "aaaaab         b",
      "aaaaab   @@@   b",
      "aaaaab  @   @  b",
      "aaaaab  @   @  b",
      "aaaaab  @   @  b",
      "aaaaab  @ I J  b",
      "aaaaab  @   @  b",
      "aaaaab  @ K @  b",
      "aaaaab  @   @  b",
      "aaaaab   @@@   b",
      "aaaaab         b",
      "aaaaab         b",
      "aaaaab         b",
      "aaaaabbbbbbbbbbb",
      "vvvvvvvvvvvvvvvv"
    ],
    [
      "aaaaab         b",
      "aaaaab         b",
      "aaaaab   @@@   b",
      "aaaaab  @   @  b",
      "aaaaab  @   @  b",
      "aaaaab  @   @  b",
      "aaaaab  @   @  b",
      "aaaaab  @   @  b",
      "aaaaab  @   @  b",
      "aaaaab  @   @  b",
      "aaaaab   @@@   b",
      "aaaaab         b",
      "aaaaab         b",
      "aaaaab         b",
      "aaaaabbbbbbbbbbb",
      "vvvvvvvvvvvvvvvv"
    ],
    [
      "aaaaab         b",
      "aaaaab         b",
      "aaaaab   @@@   b",
      "aaaaab  @   @  b",
      "aaaaab  @   @  b",
      "aaaaab  @   @  b",
      "aaaaab  @   @  b",
      "aaaaab  @   @  b",
      "aaaaab  @   @  b",
      "aaaaab  @   @  b",
      "aaaaab   @@@   b",
      "aaaaab         b",
      "aaaaab         b",
      "aaaaab         b",
      "aaaaabbbbbbbbbbb",
      "vvvvvvvvvvvvvvvv"
    ]
  ]
}