{
  "name": "building_hardwarestoreie_base1_270",
  "refpalette": "deceasedcraft:building_hardwarestoreie/building_hardwarestoreie_base1_palette_270",
  "xsize": 16,
  "zsize": 16,
  "slices": [
    [
      "vvvvvvvvvvvvvvvv",
      "vbaaaaaaaaaaaaav",
      "vbaaaaaaaaaaaaav",
      "vbaaaaaaaacccaav",
      "vbaaaaaaaacccaav",
      "vbaaaaaaaacccaav",
      "vbaaaaaaaaaaaaav",
      "vbaaaaaaaaaaaaav",
      "vbaaaaaaaaaaaaav",
      "vbaaaaaaaaaaaaav",
      "vbaaaaaaaaaaaaav",
      "vbaaaaaaaaaaaaav",
      "vbaaaaaaaaaaaaav",
      "vbaaaaaaaaaaaaav",
      "vbbbbbbbbbbbbbbv",
      "vvvvvvvvvvvvvvvv"
    ],
    [
      "vvvvvvvvvvvvvvvv",
      "vbdddddddddddddv",
      "vbdjjjjjjfffffdv",
      "vbdjjjjjjfikhfdv",
      "vbdjjjjjjfh  fdv",
      "vbdjjjjjjfihifdv",
      "vbdjjjjjjfffffdv",
      "vbdjjjjjjjjjjgev",
      "vbdjjjjjjjjjj@ev",
      "vbdjjjjjjjjjj@ev",
      "vbdjjjjjjjjjj@ev",
      "vbdjjjjjjjjjj@ev",
      "vbdjjjjjjjjjj@ev",
      "vbdddddddddddddv",
      "vbbbbbbbbbbbbbbv",
      "vvvvvvvvvvvvvvvv"
    ],
    [
      "vvvvvvvvvvvvvvvv",
      "vbdddddddddddddv",
      "vbdBBB   fffffdv",
      "vbdB    tf   fdv",
      "vbdy t   s   fdv",
      "vbd y  y f   fdv",
      "vbd   w  fffffdv",
      "vbd  y   t    dv",
      "vbd r      p ldv",
      "vbdC  n w r  mdv",
      "vbdr        nmdv",
      "vbdCCr  n    mdv",
      "vbdCCCuAxuoqomdv",
      "vbdddddddddddddv",
      "vbbbbbbbbbbbbbbv",
      "vvvvvvvvvvvvvvvv"
    ],
    [
      "vvvvvvvvvvvvvvvv",
      "vbdddddddddddddv",
      "vbdB     fffffdv",
      "vbd     Ff   fdv",
      "vbd      E   fdv",
      "vbd     If   fdv",
      "vbd      fffffdv",
      "vbd           dv",
      "vbd           dv",
      "vbd          ldv",
      "vbd          mdv",
      "vbdn         mdv",
      "vbd!C J   Dq mdv",
      "vbdddddddddddddv",
      "vbbbbbbbbbbbbbbv",
      "vvvvvvvvvvvvvvvv"
    ],
    [
      "vvvvvvvvvvvvvvvv",
      "vbdddddddddddddv",
      "vbd      fffffdv",
      "vbd      f   fdv",
      "vbd     Lf   fdv",
      "vbd      f   fdv",
      "vbd      fffffdv",
      "vbd           dv",
      "vbd           dv",
      "vbd           dv",
      "vbd          ldv",
      "vbd          mdv",
      "vbdCM      K mdv",
      "vbdddddddddddddv",
      "vbbbbbbbbbbbbbbv",
      "vvvvvvvvvvvvvvvv"
    ],
    [
      "vvvvvvvvvvvvvvvv",
      "vbdddddddddddddv",
      "vbdNPPPPPfffffdv",
      "vbdNPPPPPfOOOfdv",
      "vbdQPPPPPfOOOfdv",
      "vbdNPPPPPfOOOfdv",
      "vbdNPPPPPfffffdv",
      "vbdNNNNNNNNNNNdv",
      "vbdNPPPPPPPPP dv",
      "vbdNPPPPPPPPP dv",
      "vbdQPPPPPPPPP dv",
      "vbdNPPPPPPPPPldv",
      "vbdNPPPPPPPPPmdv",
      "vbdddddddddddddv",
      "vbbbbbbbbbbbbbbv",
      "vvvvvvvvvvvvvvvv"
    ]
  ]
}