{
  "name": "building_hardwarestoreie_ground",
  "refpalette": "deceasedcraft:building_hardwarestoreie/building_hardwarestoreie_ground_palette",
  "xsize": 16,
  "zsize": 16,
  "slices": [
    [
      "aabbaabaaaaaaaaa",
      "abbabbccccccccaa",
      "bbddddde    fcaa",
      "abdddddcccccccaa",
      "badddddggggggcaa",
      "abdddddggggggc=a",
      "acddddgggggggchh",
      "acgggggggggggchh",
      "acgggggggggggchh",
      "acgggggggggggchh",
      "acgggggggggggchh",
      "acgggggggggggchh",
      "acgggggggggggchh",
      "accccccccccccchh",
      "aaaaa=hhhhhhhhhh",
      "aaaaaahhhhhhhhhh"
    ],
    [
      "                ",
      "      iiiiiiii  ",
      "  ddddde     i  ",
      "  djekdlllllmi  ",
      "  deeednnnnnni  ",
      "  dkekd      o= ",
      " idddd       o  ",
      " ip q   rrrr o  ",
      " ip s        o  ",
      " it s        o  ",
      " it s   rrrr o  ",
      " iu s        o  ",
      " iu s    wx  o  ",
      " iiiiooooyyooo  ",
      "     =          ",
      "                "
    ],
    [
      "                ",
      "      AAAAAAAA  ",
      "  ddddde     A  ",
      "  d   dBBBBBCA  ",
      "  d   dDE F  A  ",
      "  d   d      o= ",
      " Adddd       o  ",
      " AI     JKLM o  ",
      " AN          o  ",
      " AO P        o  ",
      " AQ     RSTl o  ",
      " AU          o  ",
      " AV      WX  o  ",
      " AAYAoooo  ooo  ",
      "     =          ",
      "                "
    ],
    [
      "                ",
      "      AAAAAAAA  ",
      "  ddddde     A  ",
      "  d   dBBBBBBA  ",
      "  d   d     ZA  ",
      "  d   d      o= ",
      " Adddd       o  ",
      " A           o  ",
      " A           o  ",
      " A           o  ",
      " A           o  ",
      " A0          o  ",
      " A           o  ",
      " AAYAooooooooo  ",
      "     =          ",
      "                "
    ],
    [
      "                ",
      "      AAYYYYAA  ",
      "  ddddde     A  ",
      "  d   dBBBBBBA  ",
      "  d   d      A  ",
      "  d   d      A1 ",
      " Adddd       A1 ",
      " A           A1 ",
      " Y           A1 ",
      " Y           A1 ",
      " Y           A1 ",
      " Y           A1 ",
      " A           A1 ",
      " AAAAAAAAAAAAA1 ",
      "     1111111111 ",
      "                "
    ],
    [
      "                ",
      "      AAAAAAAA  ",
      "  ddddd222222A  ",
      "  d   d222222A  ",
      "  d   d333333A  ",
      "  d   d333333A  ",
      " Adddd4333333A  ",
      " A33333333333A  ",
      " A33333333333A  ",
      " A33333333333A  ",
      " A33333333333A  ",
      " A33333333333A  ",
      " A33333333333A  ",
      " AAAAAAAAAAAAA  ",
      "                ",
      "                "
    ]
  ]
}