{
  "name": "building_hardwarestoreie_ground_180",
  "refpalette": "deceasedcraft:building_hardwarestoreie/building_hardwarestoreie_ground_palette_180",
  "xsize": 16,
  "zsize": 16,
  "slices": [
    [
      "hhhhhhhhhhaaaaaa",
      "hhhhhhhhhh=aaaaa",
      "hhccccccccccccca",
      "hhcgggggggggggca",
      "hhcgggggggggggca",
      "hhcgggggggggggca",
      "hhcgggggggggggca",
      "hhcgggggggggggca",
      "hhcgggggggggggca",
      "hhcgggggggddddca",
      "a=cggggggdddddba",
      "aacggggggdddddab",
      "aacccccccdddddba",
      "aacf    edddddbb",
      "aaccccccccbbabba",
      "aaaaaaaaabaabbaa"
    ],
    [
      "                ",
      "          =     ",
      "  oooyyooooiiii ",
      "  o  xw    s ui ",
      "  o        s ui ",
      "  o rrrr   s ti ",
      "  o        s ti ",
      "  o        s pi ",
      "  o rrrr   q pi ",
      "  o       ddddi ",
      " =o      dkekd  ",
      "  innnnnndeeed  ",
      "  imllllldkejd  ",
      "  i     eddddd  ",
      "  iiiiiiii      ",
      "                "
    ],
    [
      "                ",
      "          =     ",
      "  ooo  ooooAYAA ",
      "  o  XW      VA ",
      "  o          UA ",
      "  o lTSR     QA ",
      "  o        P OA ",
      "  o          NA ",
      "  o MLKJ     IA ",
      "  o       ddddA ",
      " =o      d   d  ",
      "  A  F EDd   d  ",
      "  ACBBBBBd   d  ",
      "  A     eddddd  ",
      "  AAAAAAAA      ",
      "                "
    ],
    [
      "                ",
      "          =     ",
      "  oooooooooAYAA ",
      "  o           A ",
      "  o          0A ",
      "  o           A ",
      "  o           A ",
      "  o           A ",
      "  o           A ",
      "  o       ddddA ",
      " =o      d   d  ",
      "  AZ     d   d  ",
      "  ABBBBBBd   d  ",
      "  A     eddddd  ",
      "  AAAAAAAA      ",
      "                "
    ],
    [
      "                ",
      " 1111111111     ",
      " 1AAAAAAAAAAAAA ",
      " 1A           A ",
      " 1A           Y ",
      " 1A           Y ",
      " 1A           Y ",
      " 1A           Y ",
      " 1A           A ",
      " 1A       ddddA ",
      " 1A      d   d  ",
      "  A      d   d  ",
      "  ABBBBBBd   d  ",
      "  A     eddddd  ",
      "  AAYYYYAA      ",
      "                "
    ],
    [
      "                ",
      "                ",
      "  AAAAAAAAAAAAA ",
      "  A33333333333A ",
      "  A33333333333A ",
      "  A33333333333A ",
      "  A33333333333A ",
      "  A33333333333A ",
      "  A33333333333A ",
      "  A3333334ddddA ",
      "  A333333d   d  ",
      "  A333333d   d  ",
      "  A222222d   d  ",
      "  A222222ddddd  ",
      "  AAAAAAAA      ",
      "                "
    ]
  ]
}