{
  "name": "building_hardwarestoreie_base1",
  "refpalette": "deceasedcraft:building_hardwarestoreie/building_hardwarestoreie_base1_palette",
  "xsize": 16,
  "zsize": 16,
  "slices": [
    [
      "vvvvvvvvvvvvvvvv",
      "vaaaaaaaaaaaaabv",
      "vaaaaaaaaaaaaabv",
      "vaacccaaaaaaaabv",
      "vaacccaaaaaaaabv",
      "vaacccaaaaaaaabv",
      "vaaaaaaaaaaaaabv",
      "vaaaaaaaaaaaaabv",
      "vaaaaaaaaaaaaabv",
      "vaaaaaaaaaaaaabv",
      "vaaaaaaaaaaaaabv",
      "vaaaaaaaaaaaaabv",
      "vaaaaaaaaaaaaabv",
      "vaaaaaaaaaaaaabv",
      "vbbbbbbbbbbbbbbv",
      "vvvvvvvvvvvvvvvv"
    ],
    [
      "vvvvvvvvvvvvvvvv",
      "vddddddeeeeeedbv",
      "vdfffffg@@@@@dbv",
      "vdfh ifjjjjjjdbv",
      "vdfk hfjjjjjjdbv",
      "vdfihifjjjjjjdbv",
      "vdfffffjjjjjjdbv",
      "vdjjjjjjjjjjjdbv",
      "vdjjjjjjjjjjjdbv",
      "vdjjjjjjjjjjjdbv",
      "vdjjjjjjjjjjjdbv",
      "vdjjjjjjjjjjjdbv",
      "vdjjjjjjjjjjjdbv",
      "vdddddddddddddbv",
      "vbbbbbbbbbbbbbbv",
      "vvvvvvvvvvvvvvvv"
    ],
    [
      "vvvvvvvvvvvvvvvv",
      "vdddddddddddddbv",
      "vdfffff lmmmmdbv",
      "vdf   f   n odbv",
      "vdf   f p   qdbv",
      "vdf   f  r  odbv",
      "vdffsfft    udbv",
      "vd t     w nxdbv",
      "vd   y      Adbv",
      "vd    w  n  udbv",
      "vdB t  y   rCdbv",
      "vdB  y  r  CCdbv",
      "vdBBy    CrCCdbv",
      "vdddddddddddddbv",
      "vbbbbbbbbbbbbbbv",
      "vvvvvvvvvvvvvvvv"
    ],
    [
      "vvvvvvvvvvvvvvvv",
      "vdddddddddddddbv",
      "vdfffff  lmmmdbv",
      "vdf   f      dbv",
      "vdf   f     qdbv",
      "vdf   f     Ddbv",
      "vdffEff      dbv",
      "vd F I       dbv",
      "vd           dbv",
      "vd          Jdbv",
      "vd           dbv",
      "vd          Cdbv",
      "vdB        n!dbv",
      "vdddddddddddddbv",
      "vbbbbbbbbbbbbbbv",
      "vvvvvvvvvvvvvvvv"
    ],
    [
      "vvvvvvvvvvvvvvvv",
      "vdddddddddddddbv",
      "vdfffff   lmmdbv",
      "vdf   f      dbv",
      "vdf   f     Kdbv",
      "vdf   f      dbv",
      "vdfffff      dbv",
      "vd  L        dbv",
      "vd           dbv",
      "vd           dbv",
      "vd           dbv",
      "vd          Mdbv",
      "vd          Cdbv",
      "vdddddddddddddbv",
      "vbbbbbbbbbbbbbbv",
      "vvvvvvvvvvvvvvvv"
    ],
    [
      "vvvvvvvvvvvvvvvv",
      "vdddddddddddddbv",
      "vdfffffN   lmdbv",
      "vdfOOOfNPPPPPdbv",
      "vdfOOOfNPPPPPdbv",
      "vdfOOOfNPPPPPdbv",
      "vdfffffNPPPPPdbv",
      "vdPPPPPNPPPPPdbv",
      "vdPPPPPNPPPPPdbv",
      "vdPPPPPNPPPPPdbv",
      "vdPPPPPNPPPPPdbv",
      "vdPPPPPNPPPPPdbv",
      "vdNNQNNNNNQNNdbv",
      "vdddddddddddddbv",
      "vbbbbbbbbbbbbbbv",
      "vvvvvvvvvvvvvvvv"
    ]
  ]
}