{
  "name": "building_hardwarestoreie_base2_90",
  "refpalette": "deceasedcraft:building_hardwarestoreie/building_hardwarestoreie_base2_palette_90",
  "xsize": 16,
  "zsize": 16,
  "slices": [
    [
      "vvvvvvvvvvvvvvvv",
      "vbbbbbbbbbbbbbbv",
      "vaaaaaaaaaaaaabv",
      "vaaaaaaaaaaaaabv",
      "vaaaaaaaaaaaaabv",
      "vaaaaaaaaaaaaabv",
      "vaaaaaaaaaaaaabv",
      "vaaaaaaaaaaaaabv",
      "vaaaaaaaaaaaaabv",
      "vaaaaaaaaaaaaabv",
      "vaacccaaaaaaaabv",
      "vaacccaaaaaaaabv",
      "vaacccaaaaaaaabv",
      "vaaaaaaaaaaaaabv",
      "vaaaaaaaaaaaaabv",
      "vvvvvvvvvvvvvvvv"
    ],
    [
      "vvvvvvvvvvvvvvvv",
      "vbbbbbbbbbbbbbbv",
      "vdddddddddddddbv",
      "ve@kkkkkkkkkkdbv",
      "ve@kkkkkkkkkkdbv",
      "ve@kkkkkkkkkkdbv",
      "ve@kkkkkkkkkkdbv",
      "ve@kkkkkkkkkkdbv",
      "vehkkkkkkkkkkdbv",
      "vdfgggfkkkkkkdbv",
      "vdgjilgkkkkkkdbv",
      "vdg  igkkkkkkdbv",
      "vdgillgkkkkkkdbv",
      "vdfgggfkkkkkkdbv",
      "vdddddddddddddbv",
      "vvvvvvvvvvvvvvvv"
    ],
    [
      "vvvvvvvvvvvvvvvv",
      "vbbbbbbbbbbbbbbv",
      "vdddddddddddddbv",
      "vdnoorttttCCFdbv",
      "vdn        CCdbv",
      "vdn  q q    Cdbv",
      "vdn     x x  dbv",
      "vdm  p   u   dbv",
      "vd     u   A dbv",
      "vdggggg w    dbv",
      "vdg   g  y  Edbv",
      "vdg   s   B Ddbv",
      "vdg   g w   Ddbv",
      "vdfgggg   ADDdbv",
      "vdddddddddddddbv",
      "vvvvvvvvvvvvvvvv"
    ],
    [
      "vvvvvvvvvvvvvvvv",
      "vbbbbbbbbbbbbbbv",
      "vdddddddddddddbv",
      "vdnI rKNOP C!dbv",
      "vdn          dbv",
      "vdn          dbv",
      "vdm          dbv",
      "vd           dbv",
      "vd           dbv",
      "vdggggg      dbv",
      "vdg   gM     dbv",
      "vdg   J      dbv",
      "vdg   gL     dbv",
      "vdfgggg     Ddbv",
      "vdddddddddddddbv",
      "vvvvvvvvvvvvvvvv"
    ],
    [
      "vvvvvvvvvvvvvvvv",
      "vbbbbbbbbbbbbbbv",
      "vdddddddddddddbv",
      "vdn         Cdbv",
      "vdn          dbv",
      "vdm          dbv",
      "vd           dbv",
      "vd           dbv",
      "vd           dbv",
      "vdggggg      dbv",
      "vdg   g      dbv",
      "vdg   gQ     dbv",
      "vdg   g      dbv",
      "vdfgggg      dbv",
      "vdddddddddddddbv",
      "vvvvvvvvvvvvvvvv"
    ],
    [
      "vvvvvvvvvvvvvvvv",
      "vbbbbbbbbbbbbbbv",
      "vdddddddddddddbv",
      "vdnTTTTTTTTTRdbv",
      "vdmTTTTTTTTTRdbv",
      "vd TTTTTTTTTUdbv",
      "vd TTTTTTTTTRdbv",
      "vd TTTTTTTTTRdbv",
      "vdRRRRRRRRRRRdbv",
      "vdfggggTTTTTRdbv",
      "vdgSSSgTTTTTRdbv",
      "vdgSSSgTTTTTUdbv",
      "vdgSSSgTTTTTRdbv",
      "vdfggggTTTTTRdbv",
      "vdddddddddddddbv",
      "vvvvvvvvvvvvvvvv"
    ]
  ]
}