{
  "name": "building_hardwarestoreie_base2",
  "refpalette": "deceasedcraft:building_hardwarestoreie/building_hardwarestoreie_base2_palette",
  "xsize": 16,
  "zsize": 16,
  "slices": [
    [
      "vvvvvvvvvvvvvvvv",
      "vaaaaaaaaaaaaabv",
      "vaaaaaaaaaaaaabv",
      "vaacccaaaaaaaabv",
      "vaacccaaaaaaaabv",
      "vaacccaaaaaaaabv",
      "vaaaaaaaaaaaaabv",
      "vaaaaaaaaaaaaabv",
      "vaaaaaaaaaaaaabv",
      "vaaaaaaaaaaaaabv",
      "vaaaaaaaaaaaaabv",
      "vaaaaaaaaaaaaabv",
      "vaaaaaaaaaaaaabv",
      "vaaaaaaaaaaaaabv",
      "vbbbbbbbbbbbbbbv",
      "vvvvvvvvvvvvvvvv"
    ],
    [
      "vvvvvvvvvvvvvvvv",
      "vddddddeeeeeedbv",
      "vdfgggfh@@@@@dbv",
      "vdgi jgkkkkkkdbv",
      "vdgl igkkkkkkdbv",
      "vdglilgkkkkkkdbv",
      "vdfgggfkkkkkkdbv",
      "vdkkkkkkkkkkkdbv",
      "vdkkkkkkkkkkkdbv",
      "vdkkkkkkkkkkkdbv",
      "vdkkkkkkkkkkkdbv",
      "vdkkkkkkkkkkkdbv",
      "vdkkkkkkkkkkkdbv",
      "vdddddddddddddbv",
      "vbbbbbbbbbbbbbbv",
      "vvvvvvvvvvvvvvvv"
    ],
    [
      "vvvvvvvvvvvvvvvv",
      "vdddddddddddddbv",
      "vdfgggg mnnnndbv",
      "vdg   g     odbv",
      "vdg   g     odbv",
      "vdg   g p q rdbv",
      "vdggsgg     tdbv",
      "vd     u  q tdbv",
      "vd w  w  x  tdbv",
      "vd   y  u   tdbv",
      "vdA B    x  Cdbv",
      "vdD    A   CCdbv",
      "vdDDDE    CCFdbv",
      "vdddddddddddddbv",
      "vbbbbbbbbbbbbbbv",
      "vvvvvvvvvvvvvvvv"
    ],
    [
      "vvvvvvvvvvvvvvvv",
      "vdddddddddddddbv",
      "vdfgggg  mnnndbv",
      "vdg   g     Idbv",
      "vdg   g      dbv",
      "vdg   g     rdbv",
      "vdggJgg     Kdbv",
      "vd L M      Ndbv",
      "vd          Odbv",
      "vd          Pdbv",
      "vd           dbv",
      "vd          Cdbv",
      "vdD         !dbv",
      "vdddddddddddddbv",
      "vbbbbbbbbbbbbbbv",
      "vvvvvvvvvvvvvvvv"
    ],
    [
      "vvvvvvvvvvvvvvvv",
      "vdddddddddddddbv",
      "vdfgggg   mnndbv",
      "vdg   g      dbv",
      "vdg   g      dbv",
      "vdg   g      dbv",
      "vdggggg      dbv",
      "vd  Q        dbv",
      "vd           dbv",
      "vd           dbv",
      "vd           dbv",
      "vd           dbv",
      "vd          Cdbv",
      "vdddddddddddddbv",
      "vbbbbbbbbbbbbbbv",
      "vvvvvvvvvvvvvvvv"
    ],
    [
      "vvvvvvvvvvvvvvvv",
      "vdddddddddddddbv",
      "vdfgggfR   mndbv",
      "vdgSSSgRTTTTTdbv",
      "vdgSSSgRTTTTTdbv",
      "vdgSSSgRTTTTTdbv",
      "vdgggggRTTTTTdbv",
      "vdTTTTTRTTTTTdbv",
      "vdTTTTTRTTTTTdbv",
      "vdTTTTTRTTTTTdbv",
      "vdTTTTTRTTTTTdbv",
      "vdTTTTTRTTTTTdbv",
      "vdRRURRRRRURRdbv",
      "vdddddddddddddbv",
      "vbbbbbbbbbbbbbbv",
      "vvvvvvvvvvvvvvvv"
    ]
  ]
}