{
  "name": "building_hardwarestoreie_ground_270",
  "refpalette": "deceasedcraft:building_hardwarestoreie/building_hardwarestoreie_ground_palette_270",
  "xsize": 16,
  "zsize": 16,
  "slices": [
    [
      "aaaaaaaaaaababaa",
      "aaccccccccbabbba",
      "aacggggggdddddbb",
      "aacggggggdddddab",
      "aacggggggdddddba",
      "a=cggggggdddddba",
      "hhcgggggggddddcb",
      "hhcgggggggggceca",
      "hhcgggggggggc ca",
      "hhcgggggggggc ca",
      "hhcgggggggggc ca",
      "hhcgggggggggc ca",
      "hhcgggggggggcfca",
      "hhccccccccccccca",
      "hhhhhhhhhh=aaaaa",
      "hhhhhhhhhhaaaaaa"
    ],
    [
      "                ",
      "  iiiiiiii      ",
      "  iuuttppddddd  ",
      "  i      dkejd  ",
      "  isssssqdeeed  ",
      " =o      dkekd  ",
      "  o       ddddi ",
      "  o        nlei ",
      "  o  r  r  nl i ",
      "  yw r  r  nl i ",
      "  yx r  r  nl i ",
      "  o  r  r  nl i ",
      "  o        nm i ",
      "  oooooooooiiii ",
      "          =     ",
      "                "
    ],
    [
      "                ",
      "  AAAAAAAA      ",
      "  AVUQONIddddd  ",
      "  Y      d   d  ",
      "  A   P  d   d  ",
      " =o      d   d  ",
      "  o       ddddA ",
      "  o        DBeA ",
      "  o  R  J  EB A ",
      "   W S  K   B A ",
      "   X T  L  FB A ",
      "  o  l  M   B A ",
      "  o         C A ",
      "  oooooooooAAAA ",
      "          =     ",
      "                "
    ],
    [
      "                ",
      "  AAAAAAAA      ",
      "  A 0    ddddd  ",
      "  Y      d   d  ",
      "  A      d   d  ",
      " =o      d   d  ",
      "  o       ddddA ",
      "  o         BeA ",
      "  o         B A ",
      "  o         B A ",
      "  o         B A ",
      "  o         B A ",
      "  o        ZB A ",
      "  oooooooooAAAA ",
      "          =     ",
      "                "
    ],
    [
      "                ",
      "  AAYYYYAA      ",
      "  A      ddddd  ",
      "  A      d   d  ",
      "  A      d   d  ",
      " 1A      d   d  ",
      " 1A       ddddA ",
      " 1A         BeA ",
      " 1A         B Y ",
      " 1A         B Y ",
      " 1A         B Y ",
      " 1A         B Y ",
      " 1A         B A ",
      " 1AAAAAAAAAAAAA ",
      " 1111111111     ",
      "                "
    ],
    [
      "                ",
      "  AAAAAAAA      ",
      "  A333333ddddd  ",
      "  A333333d   d  ",
      "  A333333d   d  ",
      "  A333333d   d  ",
      "  A3333334ddddA ",
      "  A33333333322A ",
      "  A33333333322A ",
      "  A33333333322A ",
      "  A33333333322A ",
      "  A33333333322A ",
      "  A33333333322A ",
      "  AAAAAAAAAAAAA ",
      "                ",
      "                "
    ]
  ]
}