{
  "name": "building_hardwarestoreie_ground_90",
  "refpalette": "deceasedcraft:building_hardwarestoreie/building_hardwarestoreie_ground_palette_90",
  "xsize": 16,
  "zsize": 16,
  "slices": [
    [
      "aaaaaahhhhhhhhhh",
      "aaaaa=hhhhhhhhhh",
      "accccccccccccchh",
      "acfcgggggggggchh",
      "ac cgggggggggchh",
      "ac cgggggggggchh",
      "ac cgggggggggchh",
      "ac cgggggggggchh",
      "acecgggggggggchh",
      "bcddddgggggggchh",
      "abdddddggggggc=a",
      "abdddddggggggcaa",
      "badddddggggggcaa",
      "bbdddddggggggcaa",
      "abbbabccccccccaa",
      "aababaaaaaaaaaaa"
    ],
    [
      "                ",
      "     =          ",
      " iiiiooooooooo  ",
      " i mn        o  ",
      " i ln  r  r  o  ",
      " i ln  r  r xy  ",
      " i ln  r  r wy  ",
      " i ln  r  r  o  ",
      " ieln        o  ",
      " idddd       o  ",
      "  dkekd      o= ",
      "  deeedqsssssi  ",
      "  djekd      i  ",
      "  dddddppttuui  ",
      "      iiiiiiii  ",
      "                "
    ],
    [
      "                ",
      "     =          ",
      " AAAAooooooooo  ",
      " A C         o  ",
      " A B   M  l  o  ",
      " A BF  L  T X   ",
      " A B   K  S W   ",
      " A BE  J  R  o  ",
      " AeBD        o  ",
      " Adddd       o  ",
      "  d   d      o= ",
      "  d   d  P   A  ",
      "  d   d      Y  ",
      "  dddddINOQUVA  ",
      "      AAAAAAAA  ",
      "                "
    ],
    [
      "                ",
      "     =          ",
      " AAAAooooooooo  ",
      " A BZ        o  ",
      " A B         o  ",
      " A B         o  ",
      " A B         o  ",
      " A B         o  ",
      " AeB         o  ",
      " Adddd       o  ",
      "  d   d      o= ",
      "  d   d      A  ",
      "  d   d      Y  ",
      "  ddddd    0 A  ",
      "      AAAAAAAA  ",
      "                "
    ],
    [
      "                ",
      "     1111111111 ",
      " AAAAAAAAAAAAA1 ",
      " A B         A1 ",
      " Y B         A1 ",
      " Y B         A1 ",
      " Y B         A1 ",
      " Y B         A1 ",
      " AeB         A1 ",
      " Adddd       A1 ",
      "  d   d      A1 ",
      "  d   d      A  ",
      "  d   d      A  ",
      "  ddddd      A  ",
      "      AAYYYYAA  ",
      "                "
    ],
    [
      "                ",
      "                ",
      " AAAAAAAAAAAAA  ",
      " A22333333333A  ",
      " A22333333333A  ",
      " A22333333333A  ",
      " A22333333333A  ",
      " A22333333333A  ",
      " A22333333333A  ",
      " Adddd4333333A  ",
      "  d   d333333A  ",
      "  d   d333333A  ",
      "  d   d333333A  ",
      "  ddddd333333A  ",
      "      AAAAAAAA  ",
      "                "
    ]
  ]
}