{
  "name": "building_hardwarestoreie_base2_180",
  "refpalette": "deceasedcraft:building_hardwarestoreie/building_hardwarestoreie_base2_palette_180",
  "xsize": 16,
  "zsize": 16,
  "slices": [
    [
      "vvvvvvvvvvvvvvvv",
      "vbbbbbbbbbbbbbbv",
      "vbaaaaaaaaaaaaav",
      "vbaaaaaaaaaaaaav",
      "vbaaaaaaaaaaaaav",
      "vbaaaaaaaaaaaaav",
      "vbaaaaaaaaaaaaav",
      "vbaaaaaaaaaaaaav",
      "vbaaaaaaaaaaaaav",
      "vbaaaaaaaaaaaaav",
      "vbaaaaaaaacccaav",
      "vbaaaaaaaacccaav",
      "vbaaaaaaaacccaav",
      "vbaaaaaaaaaaaaav",
      "vbaaaaaaaaaaaaav",
      "vvvvvvvvvvvvvvvv"
    ],
    [
      "vvvvvvvvvvvvvvvv",
      "vbbbbbbbbbbbbbbv",
      "vbdddddddddddddv",
      "vbdkkkkkkkkkkkdv",
      "vbdkkkkkkkkkkkdv",
      "vbdkkkkkkkkkkkdv",
      "vbdkkkkkkkkkkkdv",
      "vbdkkkkkkkkkkkdv",
      "vbdkkkkkkkkkkkdv",
      "vbdkkkkkkfgggfdv",
      "vbdkkkkkkglilgdv",
      "vbdkkkkkkgi lgdv",
      "vbdkkkkkkgj igdv",
      "vbd@@@@@hfgggfdv",
      "vbdeeeeeeddddddv",
      "vvvvvvvvvvvvvvvv"
    ],
    [
      "vvvvvvvvvvvvvvvv",
      "vbbbbbbbbbbbbbbv",
      "vbdddddddddddddv",
      "vbdFCC    EDDDdv",
      "vbdCC   A    Ddv",
      "vbdC  x    B Adv",
      "vbdt   u  y   dv",
      "vbdt  x  w  w dv",
      "vbdt q  u     dv",
      "vbdt     ggsggdv",
      "vbdr q p g   gdv",
      "vbdo     g   gdv",
      "vbdo     g   gdv",
      "vbdnnnnm ggggfdv",
      "vbdddddddddddddv",
      "vvvvvvvvvvvvvvvv"
    ],
    [
      "vvvvvvvvvvvvvvvv",
      "vbbbbbbbbbbbbbbv",
      "vbdddddddddddddv",
      "vbd!         Ddv",
      "vbdC          dv",
      "vbd           dv",
      "vbdP          dv",
      "vbdO          dv",
      "vbdN      M L dv",
      "vbdK     ggJggdv",
      "vbdr     g   gdv",
      "vbd      g   gdv",
      "vbdI     g   gdv",
      "vbdnnnm  ggggfdv",
      "vbdddddddddddddv",
      "vvvvvvvvvvvvvvvv"
    ],
    [
      "vvvvvvvvvvvvvvvv",
      "vbbbbbbbbbbbbbbv",
      "vbdddddddddddddv",
      "vbdC          dv",
      "vbd           dv",
      "vbd           dv",
      "vbd           dv",
      "vbd           dv",
      "vbd        Q  dv",
      "vbd      gggggdv",
      "vbd      g   gdv",
      "vbd      g   gdv",
      "vbd      g   gdv",
      "vbdnnm   ggggfdv",
      "vbdddddddddddddv",
      "vvvvvvvvvvvvvvvv"
    ],
    [
      "vvvvvvvvvvvvvvvv",
      "vbbbbbbbbbbbbbbv",
      "vbdddddddddddddv",
      "vbdRRURRRRRURRdv",
      "vbdTTTTTRTTTTTdv",
      "vbdTTTTTRTTTTTdv",
      "vbdTTTTTRTTTTTdv",
      "vbdTTTTTRTTTTTdv",
      "vbdTTTTTRTTTTTdv",
      "vbdTTTTTRgggggdv",
      "vbdTTTTTRgSSSgdv",
      "vbdTTTTTRgSSSgdv",
      "vbdTTTTTRgSSSgdv",
      "vbdnm   Rfgggfdv",
      "vbdddddddddddddv",
      "vvvvvvvvvvvvvvvv"
    ]
  ]
}