{
  "name": "building_hardwarestoreie_base1_180",
  "refpalette": "deceasedcraft:building_hardwarestoreie/building_hardwarestoreie_base1_palette_180",
  "xsize": 16,
  "zsize": 16,
  "slices": [
    [
      "vvvvvvvvvvvvvvvv",
      "vbbbbbbbbbbbbbbv",
      "vbaaaaaaaaaaaaav",
      "vbaaaaaaaaaaaaav",
      "vbaaaaaaaaaaaaav",
      "vbaaaaaaaaaaaaav",
      "vbaaaaaaaaaaaaav",
      "vbaaaaaaaaaaaaav",
      "vbaaaaaaaaaaaaav",
      "vbaaaaaaaaaaaaav",
      "vbaaaaaaaacccaav",
      "vbaaaaaaaacccaav",
      "vbaaaaaaaacccaav",
      "vbaaaaaaaaaaaaav",
      "vbaaaaaaaaaaaaav",
      "vvvvvvvvvvvvvvvv"
    ],
    [
      "vvvvvvvvvvvvvvvv",
      "vbbbbbbbbbbbbbbv",
      "vbdddddddddddddv",
      "vbdjjjjjjjjjjjdv",
      "vbdjjjjjjjjjjjdv",
      "vbdjjjjjjjjjjjdv",
      "vbdjjjjjjjjjjjdv",
      "vbdjjjjjjjjjjjdv",
      "vbdjjjjjjjjjjjdv",
      "vbdjjjjjjfffffdv",
      "vbdjjjjjjfihifdv",
      "vbdjjjjjjfh kfdv",
      "vbdjjjjjjfi hfdv",
      "vbd@@@@@gfffffdv",
      "vbdeeeeeeddddddv",
      "vvvvvvvvvvvvvvvv"
    ],
    [
      "vvvvvvvvvvvvvvvv",
      "vbbbbbbbbbbbbbbv",
      "vbdddddddddddddv",
      "vbdCCrC    yBBdv",
      "vbdCC  r  y  Bdv",
      "vbdCr   y  t Bdv",
      "vbdu  n  w    dv",
      "vbdA      y   dv",
      "vbdxn w     t dv",
      "vbdu    tffsffdv",
      "vbdo  r  f   fdv",
      "vbdq   p f   fdv",
      "vbdo n   f   fdv",
      "vbdmmmml fffffdv",
      "vbdddddddddddddv",
      "vvvvvvvvvvvvvvvv"
    ],
    [
      "vvvvvvvvvvvvvvvv",
      "vbbbbbbbbbbbbbbv",
      "vbdddddddddddddv",
      "vbd!n        Bdv",
      "vbdC          dv",
      "vbd           dv",
      "vbdJ          dv",
      "vbd           dv",
      "vbd       I F dv",
      "vbd      ffEffdv",
      "vbdD     f   fdv",
      "vbdq     f   fdv",
      "vbd      f   fdv",
      "vbdmmml  fffffdv",
      "vbdddddddddddddv",
      "vvvvvvvvvvvvvvvv"
    ],
    [
      "vvvvvvvvvvvvvvvv",
      "vbbbbbbbbbbbbbbv",
      "vbdddddddddddddv",
      "vbdC          dv",
      "vbdM          dv",
      "vbd           dv",
      "vbd           dv",
      "vbd           dv",
      "vbd        L  dv",
      "vbd      fffffdv",
      "vbd      f   fdv",
      "vbdK     f   fdv",
      "vbd      f   fdv",
      "vbdmml   fffffdv",
      "vbdddddddddddddv",
      "vvvvvvvvvvvvvvvv"
    ],
    [
      "vvvvvvvvvvvvvvvv",
      "vbbbbbbbbbbbbbbv",
      "vbdddddddddddddv",
      "vbdNNQNNNNNQNNdv",
      "vbdPPPPPNPPPPPdv",
      "vbdPPPPPNPPPPPdv",
      "vbdPPPPPNPPPPPdv",
      "vbdPPPPPNPPPPPdv",
      "vbdPPPPPNPPPPPdv",
      "vbdPPPPPNfffffdv",
      "vbdPPPPPNfOOOfdv",
      "vbdPPPPPNfOOOfdv",
      "vbdPPPPPNfOOOfdv",
      "vbdml   Nfffffdv",
      "vbdddddddddddddv",
      "vvvvvvvvvvvvvvvv"
    ]
  ]
}