{
  "name": "building_hardwarestoreie_base2_270",
  "refpalette": "deceasedcraft:building_hardwarestoreie/building_hardwarestoreie_base2_palette_270",
  "xsize": 16,
  "zsize": 16,
  "slices": [
    [
      "vvvvvvvvvvvvvvvv",
      "vbaaaaaaaaaaaaav",
      "vbaaaaaaaaaaaaav",
      "vbaaaaaaaacccaav",
      "vbaaaaaaaacccaav",
      "vbaaaaaaaacccaav",
      "vbaaaaaaaaaaaaav",
      "vbaaaaaaaaaaaaav",
      "vbaaaaaaaaaaaaav",
      "vbaaaaaaaaaaaaav",
      "vbaaaaaaaaaaaaav",
      "vbaaaaaaaaaaaaav",
      "vbaaaaaaaaaaaaav",
      "vbaaaaaaaaaaaaav",
      "vbbbbbbbbbbbbbbv",
      "vvvvvvvvvvvvvvvv"
    ],
    [
      "vvvvvvvvvvvvvvvv",
      "vbdddddddddddddv",
      "vbdkkkkkkfgggfdv",
      "vbdkkkkkkglligdv",
      "vbdkkkkkkgi  gdv",
      "vbdkkkkkkglijgdv",
      "vbdkkkkkkfgggfdv",
      "vbdkkkkkkkkkkhev",
      "vbdkkkkkkkkkk@ev",
      "vbdkkkkkkkkkk@ev",
      "vbdkkkkkkkkkk@ev",
      "vbdkkkkkkkkkk@ev",
      "vbdkkkkkkkkkk@ev",
      "vbdddddddddddddv",
      "vbbbbbbbbbbbbbbv",
      "vvvvvvvvvvvvvvvv"
    ],
    [
      "vvvvvvvvvvvvvvvv",
      "vbdddddddddddddv",
      "vbdDDA   ggggfdv",
      "vbdD   w g   gdv",
      "vbdD B   s   gdv",
      "vbdE  y  g   gdv",
      "vbd    w gggggdv",
      "vbd A   u     dv",
      "vbd   u   p  mdv",
      "vbd  x x     ndv",
      "vbdC    q q  ndv",
      "vbdCC        ndv",
      "vbdFCCttttroondv",
      "vbdddddddddddddv",
      "vbbbbbbbbbbbbbbv",
      "vvvvvvvvvvvvvvvv"
    ],
    [
      "vvvvvvvvvvvvvvvv",
      "vbdddddddddddddv",
      "vbdD     ggggfdv",
      "vbd     Lg   gdv",
      "vbd      J   gdv",
      "vbd     Mg   gdv",
      "vbd      gggggdv",
      "vbd           dv",
      "vbd           dv",
      "vbd          mdv",
      "vbd          ndv",
      "vbd          ndv",
      "vbd!C PONKr Indv",
      "vbdddddddddddddv",
      "vbbbbbbbbbbbbbbv",
      "vvvvvvvvvvvvvvvv"
    ],
    [
      "vvvvvvvvvvvvvvvv",
      "vbdddddddddddddv",
      "vbd      ggggfdv",
      "vbd      g   gdv",
      "vbd     Qg   gdv",
      "vbd      g   gdv",
      "vbd      gggggdv",
      "vbd           dv",
      "vbd           dv",
      "vbd           dv",
      "vbd          mdv",
      "vbd          ndv",
      "vbdC         ndv",
      "vbdddddddddddddv",
      "vbbbbbbbbbbbbbbv",
      "vvvvvvvvvvvvvvvv"
    ],
    [
      "vvvvvvvvvvvvvvvv",
      "vbdddddddddddddv",
      "vbdRTTTTTggggfdv",
      "vbdRTTTTTgSSSgdv",
      "vbdUTTTTTgSSSgdv",
      "vbdRTTTTTgSSSgdv",
      "vbdRTTTTTggggfdv",
      "vbdRRRRRRRRRRRdv",
      "vbdRTTTTTTTTT dv",
      "vbdRTTTTTTTTT dv",
      "vbdUTTTTTTTTT dv",
      "vbdRTTTTTTTTTmdv",
      "vbdRTTTTTTTTTndv",
      "vbdddddddddddddv",
      "vbbbbbbbbbbbbbbv",
      "vvvvvvvvvvvvvvvv"
    ]
  ]
}