{
  "name": "building_hardwarestoreie_base1_90",
  "refpalette": "deceasedcraft:building_hardwarestoreie/building_hardwarestoreie_base1_palette_90",
  "xsize": 16,
  "zsize": 16,
  "slices": [
    [
      "vvvvvvvvvvvvvvvv",
      "vbbbbbbbbbbbbbbv",
      "vaaaaaaaaaaaaabv",
      "vaaaaaaaaaaaaabv",
      "vaaaaaaaaaaaaabv",
      "vaaaaaaaaaaaaabv",
      "vaaaaaaaaaaaaabv",
      "vaaaaaaaaaaaaabv",
      "vaaaaaaaaaaaaabv",
      "vaaaaaaaaaaaaabv",
      "vaacccaaaaaaaabv",
      "vaacccaaaaaaaabv",
      "vaacccaaaaaaaabv",
      "vaaaaaaaaaaaaabv",
      "vaaaaaaaaaaaaabv",
      "vvvvvvvvvvvvvvvv"
    ],
    [
      "vvvvvvvvvvvvvvvv",
      "vbbbbbbbbbbbbbbv",
      "vdddddddddddddbv",
      "ve@jjjjjjjjjjdbv",
      "ve@jjjjjjjjjjdbv",
      "ve@jjjjjjjjjjdbv",
      "ve@jjjjjjjjjjdbv",
      "ve@jjjjjjjjjjdbv",
      "vegjjjjjjjjjjdbv",
      "vdfffffjjjjjjdbv",
      "vdfihifjjjjjjdbv",
      "vdf  hfjjjjjjdbv",
      "vdfhkifjjjjjjdbv",
      "vdfffffjjjjjjdbv",
      "vdddddddddddddbv",
      "vvvvvvvvvvvvvvvv"
    ],
    [
      "vvvvvvvvvvvvvvvv",
      "vbbbbbbbbbbbbbbv",
      "vdddddddddddddbv",
      "vdmoqouxAuCCCdbv",
      "vdm    n  rCCdbv",
      "vdmn        rdbv",
      "vdm  r w n  Cdbv",
      "vdl p      r dbv",
      "vd    t   y  dbv",
      "vdfffff  w   dbv",
      "vdf   f y  y dbv",
      "vdf   s   t ydbv",
      "vdf   ft    Bdbv",
      "vdfffff   BBBdbv",
      "vdddddddddddddbv",
      "vvvvvvvvvvvvvvvv"
    ],
    [
      "vvvvvvvvvvvvvvvv",
      "vbbbbbbbbbbbbbbv",
      "vdddddddddddddbv",
      "vdm qD   J C!dbv",
      "vdm         ndbv",
      "vdm          dbv",
      "vdl          dbv",
      "vd           dbv",
      "vd           dbv",
      "vdfffff      dbv",
      "vdf   fI     dbv",
      "vdf   E      dbv",
      "vdf   fF     dbv",
      "vdfffff     Bdbv",
      "vdddddddddddddbv",
      "vvvvvvvvvvvvvvvv"
    ],
    [
      "vvvvvvvvvvvvvvvv",
      "vbbbbbbbbbbbbbbv",
      "vdddddddddddddbv",
      "vdm K      MCdbv",
      "vdm          dbv",
      "vdl          dbv",
      "vd           dbv",
      "vd           dbv",
      "vd           dbv",
      "vdfffff      dbv",
      "vdf   f      dbv",
      "vdf   fL     dbv",
      "vdf   f      dbv",
      "vdfffff      dbv",
      "vdddddddddddddbv",
      "vvvvvvvvvvvvvvvv"
    ],
    [
      "vvvvvvvvvvvvvvvv",
      "vbbbbbbbbbbbbbbv",
      "vdddddddddddddbv",
      "vdmPPPPPPPPPNdbv",
      "vdlPPPPPPPPPNdbv",
      "vd PPPPPPPPPQdbv",
      "vd PPPPPPPPPNdbv",
      "vd PPPPPPPPPNdbv",
      "vdNNNNNNNNNNNdbv",
      "vdfffffPPPPPNdbv",
      "vdfOOOfPPPPPNdbv",
      "vdfOOOfPPPPPQdbv",
      "vdfOOOfPPPPPNdbv",
      "vdfffffPPPPPNdbv",
      "vdddddddddddddbv",
      "vvvvvvvvvvvvvvvv"
    ]
  ]
}