{
  "name": "multi_gallery_5_ground",
  "refpalette": "deceasedcraft:multi_gallery_5/multi_gallery_5_ground_palette",
  "xsize": 16,
  "zsize": 16,
  "slices": [
    [
      "abaabbbbbbbbbbbc",
      "aabbbbbbbbbbbbbb",
      "abbbbbbbbbbbbbbb",
      "babbabbbbbbbbbbb",
      "dddddddddddddddd",
      "                ",
      "                ",
      "                ",
      "                ",
      "                ",
      "                ",
      "                ",
      "dddddddddddddddd",
      "eeeeeeeeeeeeeeee",
      "eeeeeeeeeeeeeeee",
      "eeeeeeeeeeeeeeee"
    ],
    [
      "                ",
      "                ",
      "                ",
      "                ",
      "dddddddddddddddd",
      "                ",
      "                ",
      "                ",
      "                ",
      "                ",
      "                ",
      "                ",
      "dddddddddddddddd",
      "                ",
      "                ",
      "                "
    ],
    [
      "                ",
      "                ",
      "                ",
      "                ",
      "dddddddddddddddd",
      "                ",
      "                ",
      "                ",
      "                ",
      "                ",
      "                ",
      "                ",
      "dddddddddddddddd",
      "                ",
      "                ",
      "                "
    ],
    [
      "                ",
      "                ",
      "                ",
      "                ",
      "dddddddddddddddd",
      "                ",
      "                ",
      "             fff",
      "             fff",
      "             fff",
      "             fff",
      "             fff",
      "dddddddddddddddd",
      "                ",
      "                ",
      "                "
    ],
    [
      "             g  ",
      "                ",
      "                ",
      "                ",
      "dddddddhhhhhh   ",
      " ffffffii       ",
      " ffffffiiiiii   ",
      " ffffffiiiiii   ",
      " ffffffiiiiii   ",
      " ffffffiiiiii   ",
      " ffffffiiiiii   ",
      " ffffffiiiiii   ",
      "dddddddhhhhhh   ",
      "                ",
      "                ",
      "                "
    ],
    [
      "             g  ",
      "             j  ",
      "                ",
      "                ",
      "h               ",
      "i               ",
      "i               ",
      "i               ",
      "i               ",
      "i               ",
      "i               ",
      "i               ",
      "h               ",
      "                ",
      "                ",
      "                "
    ]
  ]
}