{
  "name": "multi_gallery_5_base2",
  "refpalette": "deceasedcraft:multi_gallery_5/multi_gallery_5_base2_palette",
  "xsize": 16,
  "zsize": 16,
  "slices": [
    [
      "aaaaaaaaaaaaaaaa",
      "aaaaaaaaaaaaaaaa",
      "aaaaaaaaaaaaaaaa",
      "aaaaaaaaaaaaaaaa",
      "aaaaaaaaaaaaaaaa",
      "aaaaaaaaaaaaaaaa",
      "aaaaaaaaaaaaaaaa",
      "aaaaaaaaaaaaaaaa",
      "aaaaaaaaaaaaaaaa",
      "aaaaaaaaaaaaaaaa",
      "aaaaaaaaaaaaaaaa",
      "aaaaaaaaaaaaaaaa",
      "bbbbbbbbbbbbbbbb",
      "aaaaaaaaaaaaaaaa",
      "aaaaaaaaaaaaaaaa",
      "vvvvvvvvvvvvvvvv"
    ],
    [
      "aaaaaaaaaaaaaaaa",
      "aaaaaaaaaaaaaaaa",
      "aaaaaaaaaaaaaaaa",
      "aaaaaaaaaaaaaaaa",
      "aaaaaaaaaaaaaaaa",
      "aaaaaaaaaaaaaaaa",
      "aaaaaaaaaaaaaaaa",
      "aaaaaaaaaaaaaaaa",
      "aaaaaaaaaaaaaaaa",
      "aaaaaaaaaaaaaaaa",
      "aaaaaaaaaaaaaaaa",
      "aaaaaaaaaaaaaaaa",
      "bbbbbbbbbbbbbbbb",
      "cccccccccccccccc",
      "aaaaaaaaaaaaaaaa",
      "vvvvvvvvvvvvvvvv"
    ],
    [
      "dddddddddddddddd",
      "dddddddddddddddd",
      "dddddddddddddddd",
      "cccccccccccccccc",
      "aaaaaaaaaaaaaaaa",
      "aaaaaaaaaaaaaaaa",
      "aaaaaaaaaaaaaaaa",
      "aaaaaaaaaaaaaaaa",
      "aaaaaaaaaaaaaaaa",
      "aaaaaaaaaaaaaaaa",
      "aaaaaaaaaaaaaaaa",
      "aaaaaaaaaaaaaaaa",
      "bbbbbbbbbbbbbbbb",
      "eeeeeeeeeeeeeeee",
      "cccccccccccccccc",
      "vvvvvvvvvvvvvvvv"
    ],
    [
      "                ",
      "                ",
      " fg          fg ",
      "hhhhhhhhhhhhhhhh",
      "baaaaaaaaaaaaaaa",
      "aaaaaaaaaaaaaaaa",
      "aaaaaaaaaaaaaaaa",
      "aaaaaaaaaaaaaaaa",
      "aaaaaaaaaaaaaaaa",
      "aaaaaaaaaaaaaaaa",
      "iaaaaaaaaaaaaaaa",
      "iaaaaaaaaaaaaaaa",
      "bbbbbbbbbbbbbbbb",
      "cccccccccccccccc",
      "aaaaaaaaaaaaaaaa",
      "vvvvvvvvvvvvvvvv"
    ],
    [
      "                ",
      "                ",
      "                ",
      "hhhhhhhhhhhhhhhh",
      "bbbjbbbaaaaaaaaa",
      "kkkkaaaaaaaaaaaa",
      "kkkkaaaaaaaaaaaa",
      "kkkkaaaaaaaaaaaa",
      "kkkkaaaaaaaaaaaa",
      "kkkkaaaaaaaaaaaa",
      "liiiiiiaaaaaaaaa",
      "liiiiiiaaaaaaaaa",
      "bbbjbbbbbbbbbbbb",
      "aaaaaaaaaaaaaaaa",
      "aaaaaaaaaaaaaaaa",
      "vvvvvvvvvvvvvvvv"
    ],
    [
      "                ",
      "                ",
      "                ",
      "hhhhhhhhhhhhhhhh",
      "bbbmbbbbbjbbbaaa",
      "noookkkkkkaaaaaa",
      " oookkkkkkaaaaaa",
      " oookkkkkkaaaaaa",
      " oookkkkkkaaaaaa",
      " oookkkkkkaaaaaa",
      "pqrstuliiiiiiaaa",
      "pqrstuliiiiiiaaa",
      "bbbmbbbbbjbbbbbb",
      "aaahaaaaaaaaaaaa",
      "aaaaaaaaaaaaaaaa",
      "vvvvvvvvvvvvvvvv"
    ]
  ]
}