{
  "name": "multi_gallery_5_base1",
  "refpalette": "deceasedcraft:multi_gallery_5/multi_gallery_5_base1_palette",
  "xsize": 16,
  "zsize": 16,
  "slices": [
    [
      "                ",
      "                ",
      "                ",
      "aaaaaaaaaaaaaaaa",
      "bbbbbbbbbcbbbbbd",
      "      efffgggggg",
      "       fffgggggg",
      "       fffgggggg",
      "       fffgggggg",
      "       fffgggggg",
      "      hijklmnooo",
      "      hijklmnooo",
      "bbbbbbbbbcbbbbbd",
      "pppppppppapppppp",
      "pppppppppppppppp",
      "vvvvvvvvvvvvvvvv"
    ],
    [
      "                ",
      "                ",
      "                ",
      "aaaaaaaaaaaaaaaa",
      "bbbbbbbbbbbbbbbc",
      "      !    qrfff",
      "             fff",
      "             fff",
      "             fff",
      "             fff",
      "            hijk",
      "            hijk",
      "bbbbbbbbbbbbbbbc",
      "pppppppppppppppa",
      "pppppppppppppppp",
      "vvvvvvvvvvvvvvvv"
    ],
    [
      "                ",
      "                ",
      "      s         ",
      "aaaaaaaaaaaaaaaa",
      "bbbbbbbbbbbbbbbb",
      "                ",
      "                ",
      "                ",
      "                ",
      "                ",
      "                ",
      "                ",
      "bbbbbbbbbbbbbbbb",
      "pppppppppppppppp",
      "pppppppppppppppp",
      "vvvvvvvvvvvvvvvv"
    ],
    [
      "                ",
      "                ",
      "                ",
      "aaaaaaaaaaaaaaaa",
      "bbbbbbbbbbbbbbbb",
      "                ",
      "                ",
      "                ",
      "                ",
      "                ",
      "                ",
      "                ",
      "bbbbbbbbbbbbbbbb",
      "pppppppppppppppp",
      "pppppppppppppppp",
      "vvvvvvvvvvvvvvvv"
    ],
    [
      "tttttttttttttttt",
      "tttttttttttttttt",
      "tttttttttttttttt",
      "aaaaaaaaaaaaaaaa",
      "bbbbbbbbbbbbbbbb",
      "                ",
      "                ",
      "                ",
      "                ",
      "                ",
      "                ",
      "                ",
      "bbbbbbbbbbbbbbbb",
      "pppppppppppppppp",
      "pppppppppppppppp",
      "vvvvvvvvvvvvvvvv"
    ],
    [
      "uuuuuuuuuuuuuuuu",
      "uuuuuuuuuuuuuuuu",
      "uuuuuuuuuuuuuuuu",
      "uuuuuuuuuuuuuuuu",
      "bbbbbbbbbbbbbbbb",
      "                ",
      "                ",
      "                ",
      "                ",
      "                ",
      "                ",
      "                ",
      "bbbbbbbbbbbbbbbb",
      "pppppppppppppppp",
      "pppppppppppppppp",
      "vvvvvvvvvvvvvvvv"
    ]
  ]
}