{
  "name": "multi_terraceplaza_22_floor3",
  "refpalette": "deceasedcraft:multi_terraceplaza_22/multi_terraceplaza_22_floor3_palette",
  "xsize": 16,
  "zsize": 16,
  "slices": [
    [
      "a        b      ",
      "accccccadaeacccc",
      "aaaaaaaa f aaaaa",
      "g      h     ii ",
      "                ",
      "                ",
      "                ",
      "                ",
      "                ",
      "                ",
      "                ",
      "jk    kjjbllllll",
      "         lmnnl  ",
      "         lm  l  ",
      "         lo  l  ",
      "         plqrllq"
    ],
    [
      "a        b      ",
      "astu wuaxaxau!yu",
      "aaaaaaaa   aaaaa",
      " iiiiii      ii ",
      "                ",
      "                ",
      "                ",
      "                ",
      "                ",
      "                ",
      "           A A  ",
      "jk    kjjbllllll",
      "         lmnnl  ",
      "         lm  l  ",
      "         lm  l  ",
      "         BlCCllC"
    ],
    [
      "a        b      ",
      "accccccaaaaacccc",
      "aaaaaaaa   aaaaa",
      " iiiiii      ii ",
      "                ",
      "                ",
      "                ",
      "                ",
      "                ",
      "                ",
      "            D   ",
      "jk    kjjbllllll",
      "         lmnnl  ",
      "         lm  l  ",
      "         lmEEl  ",
      "          llllll"
    ],
    [
      "a        b      ",
      "a!uFIuJaaaaauKL ",
      "aaaaaaaa   aaaaa",
      "             ii ",
      "                ",
      " MMMMMM     M  M",
      "                ",
      "                ",
      "                ",
      "                ",
      " NNNNNN  O  P   ",
      "CCCCCCCCCbllllll",
      "         lmmml  ",
      "         lmmml  ",
      "         lmmml  ",
      "         lllllll"
    ],
    [
      "a        b      ",
      "a      aaaaa    ",
      "aaaaaaaaQQQaaaaa",
      "                ",
      "                ",
      "  R  R      R  R",
      "                ",
      "                ",
      "                ",
      "                ",
      "                ",
      "CCCCCCCCCbllllll",
      "         l   l  ",
      "         l   l  ",
      "         l   l  ",
      "         lllllll"
    ],
    [
      "aSSSSSSSSbSSSSSS",
      "aSSSSSSSSSSSSSSS",
      "aaaaaaaaaaaaaaaa",
      "TU TU TU   U TU ",
      "TU TU TU   U TU ",
      "TUVTUVTU   UVTUV",
      "TU TU TU   U TU ",
      "TU TU TU   U TU ",
      "TU TU TU   U TU ",
      "TU TU TU   U TU ",
      "TU TU TU   U TU ",
      "CCCCCCCCCbllllll",
      "         l   l  ",
      "         l   l  ",
      "         l   l  ",
      "         lllllll"
    ]
  ]
}