{
  "name": "multi_terraceplaza_22_floor4",
  "refpalette": "deceasedcraft:multi_terraceplaza_22/multi_terraceplaza_22_floor4_palette",
  "xsize": 16,
  "zsize": 16,
  "slices": [
    [
      "abbbbbbbbcbbbbbb",
      "abbbbbbbbbbbbbbb",
      "aaaaaaaaaaaaaaaa",
      "aaaaaaaaaaaaaaaa",
      "aaaaaaaaaaaaaaaa",
      "aaaaaaaaaaaaaaaa",
      "aaaaaaaaaaaaaaaa",
      "aaaaaaaaaaaaaaaa",
      "aaaaaaaaaaaaaaaa",
      "aaaaaaaaaaaaaaaa",
      "aaaaaaaaaaaaaaaa",
      "dddddddddceeeeee",
      "         e f g f",
      "         e h g i",
      "         e j g j",
      "         egkgggk"
    ],
    [
      "         cl     ",
      "m  nn  o  ppqq  ",
      "r  ss  t  uwwx  ",
      "y  AA  B        ",
      "C  DD  E  FFFF  ",
      "          FIIF  ",
      "  J       FKKF  ",
      "L  MN  O  FPP   ",
      "Q  !R  S  TUUT  ",
      "V  WV  V XXXYYY ",
      "                ",
      "dddddddddcdddddd",
      "         e      ",
      "         e      ",
      "         e      ",
      "         e      "
    ],
    [
      "         c      ",
      "                ",
      "           Z0   ",
      "                ",
      "                ",
      "                ",
      "                ",
      "                ",
      "         12  31 ",
      "         444555 ",
      "                ",
      "dddddddddcdddddd",
      "         e      ",
      "         e      ",
      "         e      ",
      "666666666e      "
    ],
    [
      "         c      ",
      "                ",
      "                ",
      "                ",
      "                ",
      "                ",
      "                ",
      "                ",
      "                ",
      "         777888 ",
      "                ",
      "dddddddddcdddddd",
      "666666666e      ",
      "999999999e      ",
      "#########e      ",
      "$$$$$$$$$e      "
    ],
    [
      "         c      ",
      "                ",
      "                ",
      "                ",
      "                ",
      "                ",
      "                ",
      "                ",
      "                ",
      "6666666666666666",
      "9999999999999999",
      "%%%%%%%%%c%%%%%%",
      "$$$$$$$$$$$$$$$$",
      "$$$$$$$$$$$$$$$$",
      "^^^^^^^^^^^^^^^^",
      "&&&&&&&&&&&&&&&&"
    ],
    [
      "         c      ",
      "                ",
      "                ",
      "                ",
      "                ",
      "                ",
      "6666666666666666",
      "9999999999999999",
      "################",
      "$$$$$$$$$$$$$$$$",
      "$$$$$$$$$$$$$$$$",
      "^^^^^^^^^^^^^^^^",
      "&&&&&&&&&&&&&&&&",
      "                ",
      "                ",
      "                "
    ]
  ]
}