{
  "name": "multi_terraceplaza_22_base2",
  "refpalette": "deceasedcraft:multi_terraceplaza_22/multi_terraceplaza_22_base2_palette",
  "xsize": 16,
  "zsize": 16,
  "slices": [
    [
      "HHHHHHHHHaHHHHHH",
      "HHHHHHHHHHHHHHHH",
      "HHHHHHHHHHHHHHHH",
      "HHHHHHHHHHHHHHHH",
      "HHHHHHHHHHHHHHHH",
      "HHHHHHHHbbbbbbbb",
      "HHHHHHHHbbbbbbbb",
      "HHHHHHHHbbbbbbbb",
      "HHHccccccccccccc",
      "dddddddddddddddd",
      "dddddddddddddddd",
      "eeeeeeeeeacccccc",
      "ffffgffffc   c  ",
      "ffffhiiffc   c  ",
      "fffffffffc   c  ",
      "fffffffffj eej e"
    ],
    [
      "kllllllllallllll",
      "k               ",
      "k               ",
      "k               ",
      "k   mmmmm  m  m ",
      "k    noHHpq     ",
      "k    noHHpq     ",
      "k    noHHpq     ",
      "k  ccccccccccccc",
      "                ",
      "                ",
      "rstttttttacccccc",
      "  uuuwx  c   c  ",
      "  yA BBx c   c  ",
      "         c   c  ",
      "        CicDEccD"
    ],
    [
      "         a      ",
      "                ",
      "                ",
      "                ",
      "       mmmmm  m ",
      "        noHHpq  ",
      "        noHHpq  ",
      "        noHHpq  ",
      "   ccccccccccccc",
      "                ",
      "                ",
      "Fstttttttacccccc",
      "  IJ     c   c  ",
      "         c   c  ",
      "         c   c  ",
      "         BcKLccK"
    ],
    [
      "         a      ",
      "                ",
      "                ",
      "                ",
      "          mmmmm ",
      "           noHHp",
      "           noHHp",
      "           noHHp",
      "   ccccccccccccc",
      "                ",
      "                ",
      "Mstttttttacccccc",
      "N        c   c  ",
      "         c   c  ",
      "         c   c  ",
      "         OcPPccP"
    ],
    [
      "         a      ",
      "                ",
      "                ",
      "      Q         ",
      "             mmm",
      "              no",
      "              no",
      "              no",
      " Q ccccccccccccc",
      "                ",
      "                ",
      "sstttttttacccccc",
      "         c   c  ",
      "         c   c  ",
      "         c   c  ",
      "         Rcccccc"
    ],
    [
      "SSSSSSSSSaSSSSSS",
      "TTTTTTTTTTTTTTTT",
      "TTTTTTTTTTTTTTTT",
      "TUTTTTUTTTTTUTTT",
      "TTTTTTTTTTTTTTTT",
      "TTTTT           ",
      "TTTTT           ",
      "TTTTT           ",
      "TUTccccccccccccc",
      "TTTTTTTTTTTTTTTT",
      "TTTTTTTTTTTTTTTT",
      "SSSSSSSSSaSSSSSS",
      "VVVVVVVVVS   c  ",
      "VVVVVVVVVS   c  ",
      "VVVVVVVVVS   c  ",
      "VVVVVVVVVScccccc"
    ]
  ]
}