{
  "name": "multi_terraceplaza_22_base1",
  "refpalette": "deceasedcraft:multi_terraceplaza_22/multi_terraceplaza_22_base1_palette",
  "xsize": 16,
  "zsize": 16,
  "slices": [
    [
      "HHHHHHHHHaHHHHHH",
      "HHHHHHHHHHHHHHHH",
      "HHHHHHHHHHHHHHHH",
      "HHHHHHHHHHHHHHHH",
      "HHHHHHHHHHHHHHHH",
      "HHHHHHbc        ",
      "HHHHHHbc        ",
      "HHHHHHbc        ",
      "HHHddddddddddddd",
      "eeeeeeeeeeeeeeee",
      "eeeeeeeeeeeeeeee",
      "fffffffffadddddd",
      "gggggggggd   d  ",
      "gggggggggd   d  ",
      "gggggggggd   d  ",
      "gggggggggh ffh f"
    ],
    [
      "ijjjjjjjjajjjjjj",
      "i               ",
      "i               ",
      "i               ",
      "i   kkkkkkkkkkkk",
      "i    lmHHbc     ",
      "i    lmHHbc     ",
      "i    lmHHbc     ",
      "i  noddddddddddd",
      "                ",
      "                ",
      "pqrrrrrrradddddd",
      "         d   d  ",
      "         d   d  ",
      "         d   d  ",
      "        stduwddu"
    ],
    [
      "         a      ",
      "                ",
      "                ",
      "                ",
      "       kkkkk  k ",
      "        lmHHbc  ",
      "        lmHHbc  ",
      "        lmHHbc  ",
      "      nodddddddd",
      "                ",
      "                ",
      "xqrrrrrrradddddd",
      "         d   d  ",
      "         d   d  ",
      "         d   d  ",
      "         ydABddA"
    ],
    [
      "         a      ",
      "                ",
      "                ",
      "                ",
      "          kkkkk ",
      "           lmHHb",
      "           lmHHb",
      "           lmHHb",
      "         noddddd",
      "                ",
      "                ",
      "Cqrrrrrrradddddd",
      "D        d   d  ",
      "         d   d  ",
      "         d   d  ",
      "         EdFFddF"
    ],
    [
      "         a      ",
      "                ",
      "                ",
      "                ",
      "             kkk",
      "              lm",
      "              lm",
      "              lm",
      "            nodd",
      "                ",
      "                ",
      "qqrrrrrrradddddd",
      "         d   d  ",
      "         d   d  ",
      "         d   d  ",
      "         Idddddd"
    ],
    [
      "JJJJJJJJJaJJJJJJ",
      "K               ",
      "K               ",
      "K               ",
      "KK              ",
      "LK              ",
      "LKK             ",
      "LLKK            ",
      "LLLKKK         n",
      "LLLLLKKKKKKKKKKK",
      "LLLLLLLLLLLLLLLL",
      "JJJJJJJJJaJJJJJJ",
      "MMMMMMMMMJ   d  ",
      "MMMMMMMMMJ   d  ",
      "MMMMMMMMMJ   d  ",
      "MMMMMMMMMJdddddd"
    ]
  ]
}