{
  "name": "multi_terraceplaza_22_ground",
  "refpalette": "deceasedcraft:multi_terraceplaza_22/multi_terraceplaza_22_ground_palette",
  "xsize": 16,
  "zsize": 16,
  "slices": [
    [
      "abbbbbbbbcbbbbbb",
      "ab              ",
      "ab              ",
      "abb             ",
      "aab             ",
      "aabb            ",
      "aaabb           ",
      "aaaabbb         ",
      "aaaaaabbbbbbbbbb",
      "aaaaaaaaaaaaaaaa",
      "aaaaaaaaaaaaaaaa",
      "dddddddddceeeeee",
      "fffffffffe   egg",
      "fffffffffe   egg",
      "fffffffffe   egg",
      "fffffffffh ddh d"
    ],
    [
      " iiiiiiiiciiiiii",
      " i              ",
      " i              ",
      " ii             ",
      "  i             ",
      "  ii            ",
      "   ii           ",
      "    iii         ",
      "      iiiiiiiiii",
      "                ",
      "                ",
      "jjkllkjjjceeeeee",
      "   mn    e   eop",
      "   qq    e   eo ",
      "         e   ers",
      "        tuewxeew"
    ],
    [
      "         c      ",
      "                ",
      "                ",
      "                ",
      "                ",
      "                ",
      "                ",
      "                ",
      "                ",
      "                ",
      "                ",
      "jjk  kjjjceeeeee",
      "   yA    e   eop",
      "         e   eo ",
      "         e   eB ",
      "         CeDEeeD"
    ],
    [
      "         c      ",
      "                ",
      "                ",
      "                ",
      "                ",
      "                ",
      "                ",
      "                ",
      "                ",
      "                ",
      "            FFFF",
      "jjkIJkjjjceeeeee",
      "   KK    e   eop",
      "         e   eo ",
      "         e   eo ",
      "         LeMMeeM"
    ],
    [
      "         c      ",
      "                ",
      "                ",
      "                ",
      "                ",
      "                ",
      "                ",
      "                ",
      "                ",
      "                ",
      "            NNNN",
      "jjkkkkjjjceeeeee",
      "         e   eop",
      "         e   eo ",
      "         e   eoO",
      "          eeeeee"
    ],
    [
      "         c      ",
      "                ",
      "                ",
      "                ",
      "                ",
      "                ",
      "                ",
      "                ",
      "                ",
      "                ",
      "            PPPP",
      "jjjjjjjjjceeeeee",
      "         e   eoo",
      "         e   eoo",
      "         e   eoo",
      "         eeeeeee"
    ]
  ]
}