{
  "name": "multi_terraceplaza_22_floor2",
  "refpalette": "deceasedcraft:multi_terraceplaza_22/multi_terraceplaza_22_floor2_palette",
  "xsize": 16,
  "zsize": 16,
  "slices": [
    [
      "aaaaaaaaabaaaaaa",
      "                ",
      "                ",
      "                ",
      "                ",
      "                ",
      "                ",
      "          cccccc",
      "        !c    c ",
      "         c    c ",
      "        dc    c ",
      "ef    feebcccccc",
      "         c   c  ",
      "         c   c  ",
      "         c   c  ",
      "          cccccc"
    ],
    [
      "gggggggggbgggggg",
      "         h      ",
      "                ",
      "                ",
      "                ",
      "                ",
      "                ",
      "          cccccc",
      "         c    ! ",
      "         c    i ",
      "         c    i ",
      "jjjjjjjjjbcccccc",
      " kkkkkk  c   c  ",
      "         c   c  ",
      "         c   c  ",
      "         ccccccc"
    ],
    [
      "lllllllllbllllll",
      "                ",
      "                ",
      "                ",
      "                ",
      "                ",
      "                ",
      "          cccccc",
      "         c    i ",
      "         c    i ",
      "         c    i ",
      "jjjjjjjjjbcccccc",
      "         c   c  ",
      "         c   c  ",
      "         c   c  ",
      "         ccccccc"
    ],
    [
      "mmmmmmmmmbmmmmmm",
      "nnnnnnnnnmnnnnnn",
      "nnnnnnnnnmnnnnnn",
      "nnnnnnnnnmnnnnnn",
      "nnnnnnnnnmnnnnnn",
      "nnnnnnnnnmnnnnnn",
      "nnnnnnnnnmnnnnnn",
      "nnnnnnnnnmnnnnnn",
      "nnnnnnnnnmnnnnnn",
      "nnnnnnnnnmnnnnnn",
      "nnnnnnnnnmnnnnnn",
      "mmmmmmmmmbmmmmmm",
      "ooooooooom   c  ",
      "ooooooooom   c  ",
      "ooooooooom   c  ",
      "ooooooooomcccccc"
    ],
    [
      "pppppppppbpppppp",
      "pppppppppppppppp",
      "ppppppppqqqppppp",
      "rrrrrrrrqqqrrrrr",
      "rrrrrrrrqqqrrrrr",
      "rrrrrrrrqqqrrrrr",
      "rrrrrrrrqqqrrrrr",
      "rrrrrrrrsqsrrrrr",
      "qqqqqqqqqqqqqqqq",
      "qqqqqqqqqqqqqqqq",
      "qqqqqqqqqqqqqqqq",
      "tttttttttbcccccc",
      "uuuuuuuuucwwwc  ",
      "uuuuuuuuucwwwc  ",
      "uuuuuuuuucwwwc  ",
      "uuuuuuuuux ttx t"
    ],
    [
      "y        b      ",
      "yAAB ACyDyEyF AI",
      "yyyyyyyy   yyyyy",
      "J KLLM J        ",
      "           N OO ",
      "P QQQQ R   S OO ",
      "           T OO ",
      "        U U     ",
      "                ",
      "                ",
      "                ",
      "ef    feebcccccc",
      "         cVWWc  ",
      "         cV  c  ",
      "         cXYYc  ",
      "        Z0c12cc1"
    ]
  ]
}