{
  "name": "multi_terraceplaza_22_floor1",
  "refpalette": "deceasedcraft:multi_terraceplaza_22/multi_terraceplaza_22_floor1_palette",
  "xsize": 16,
  "zsize": 16,
  "slices": [
    [
      "         a      ",
      "                ",
      "                ",
      "                ",
      "                ",
      "                ",
      "                ",
      "                ",
      "                ",
      "                ",
      "                ",
      "bbbbbbbbbacccccc",
      "         c   c  ",
      "         c   c  ",
      "         c   c  ",
      "         ccccccc"
    ],
    [
      "dddddddddadddddd",
      "eeeeeeeeedeeeeee",
      "ffffffffedefffff",
      "fggggggfedefgggg",
      "fghhhhgfedefghhh",
      "fghhhhgfedefghhh",
      "fghhhhgfedefghhh",
      "fghhhhgfedefghhh",
      "fggggggfedefgggg",
      "ffffffffedefffff",
      "eeeeeeeeedeeeeee",
      "dddddddddadddddd",
      "hhhhhhhhhd   c  ",
      "hhhhhhhhhd   c  ",
      "hhhhhhhhhd   c  ",
      "hhhhhhhhhdcccccc"
    ],
    [
      "iiiiiiiiiaiiiiii",
      "jjjjjjjjkkkjjjjj",
      "kkkkkkkkkkkkkkkk",
      "kkkkkkkkkkkkkkkk",
      "kkkkkkkkkkkkkkkk",
      "kkkkkkkkkkkkkkkk",
      "kkkkkkkkkkkkkkkk",
      "kkkkkkkkkkkkkkkk",
      "kkkkkkkkkkkkkkkk",
      "kkkkkkkkkkkkkkkk",
      "kkkkkkkkkkkkkkkk",
      "lllllllllacccccc",
      "mmmmmmmmmc   c  ",
      "mmmmmmmmmc   c  ",
      "mmmmmmmmmc   c  ",
      "mmmmmmmmmn lln l"
    ],
    [
      "oooooooooaoooooo",
      "pqqqqqqr   pqqqq",
      "   s           t",
      "    t        u  ",
      "wx              ",
      "wx              ",
      "wx              ",
      "wx        cyAccc",
      "        BcC  DcE",
      "         cF  Dct",
      "        BcF  DcE",
      "IJ    JIIacccccc",
      "         c   c  ",
      "         c   c  ",
      "         c   c  ",
      "        KLcMNccM"
    ],
    [
      "OOOOOOOOOaOOOOOO",
      " PQPRSP     TUTU",
      "                ",
      "                ",
      "wx              ",
      "wx              ",
      "wx            V ",
      "wx       WcXYccc",
      "        Zc   0c ",
      "         c1  Dc ",
      "        2c    c ",
      "IJ    JIIacccccc",
      "         c   c  ",
      "         c   c  ",
      "         c   c  ",
      "         3c45cc4"
    ],
    [
      "OOOOOOOOOaOOOOOO",
      "     u      u u ",
      "                ",
      "                ",
      "                ",
      "                ",
      "                ",
      "          c66ccc",
      "        Bc    c ",
      "         c    c ",
      "        Bc    c ",
      "IJ    JIIacccccc",
      "         c   c  ",
      "         c   c  ",
      "         c   c  ",
      "         7c66cc6"
    ]
  ]
}