{
  "name": "multi_nuclearpowerplant_20_ground",
  "refpalette": "deceasedcraft:multi_nuclearpowerplant_20/multi_nuclearpowerplant_20_ground_palette",
  "xsize": 16,
  "zsize": 16,
  "slices": [
    [
      "        a       ",
      "        a       ",
      "bb    c ad      ",
      "bbbbb efae      ",
      "bbbbbbbbge      ",
      "hhbbbbbbbbbbbb  ",
      "ihhhbbbbbbbbbbbb",
      "iiihhhbbbbbbbbbb",
      "iiiiihhhhbbbbbbb",
      "iiiiiiiihhhhhbbb",
      "iiiiiiiiiiiihhhh",
      "ziiiiiiiiiiiiiii",
      "zziiziiiiiiiiiii",
      "izzziiziiiiiiiii",
      "zizzziziziziiiii",
      "zzzizzzzzzzzizzi"
    ],
    [
      "bbbbbbbbb       ",
      "bbbbbbbbbbbbbbbb",
      "bbbbbbbbbbbbbbbb",
      "zbbbbbbbbbbbbbbb",
      "zzzzbbbbbbbbbbbb",
      "zzzzzzzbbbbbbbbb",
      "jzzzzzzzzzzzzbbb",
      " klzzzzzzzzzzzzz",
      "   kjizzzzzzzzzz",
      "     kjjzzzzzizz",
      "        kkljzzzz",
      "            kkjl",
      "m   m           ",
      "  mm            ",
      "          m     ",
      "    m  mmm m  m "
    ],
    [
      "zzzbbbbbbbbbbbbb",
      "zzzzzzzzbbbbbbbb",
      "zzzzzzzzzzzzzzzz",
      "zzzzzzzzzzzzzzzz",
      "    zzzzzzzzzzzz",
      "nn z  zzizzzzzzz",
      " nnnm m    z zzz",
      "   nnn  mm      ",
      "     nnnno      ",
      "        nnnnn   ",
      "            nnnn",
      "                ",
      "                ",
      "                ",
      "                ",
      "                "
    ],
    [
      "   zzzzzzzzzizzi",
      "   m  zzzzzzzzzz",
      "m omm   pz     z",
      "             p  ",
      "     m m mom m  ",
      "nn            m ",
      " nnn       m m m",
      "   nnn          ",
      "     nnnn       ",
      "        nnnnn   ",
      "            nnnn",
      "                ",
      "                ",
      "                ",
      "                ",
      "                "
    ],
    [
      "    m mm  mm    ",
      "          m   m ",
      "               o",
      "                ",
      "                ",
      "q               ",
      " qq             ",
      "   qq           ",
      "     qqq        ",
      "        qqqq    ",
      "            qqqq",
      "                ",
      "                ",
      "                ",
      "                ",
      "                "
    ],
    [
      "                ",
      "                ",
      "                ",
      "                ",
      "                ",
      "                ",
      "                ",
      "                ",
      "                ",
      "                ",
      "                ",
      "                ",
      "                ",
      "                ",
      "                ",
      "                "
    ]
  ]
}