{
  "name": "multi_nuclearpowerplant_20_base7",
  "refpalette": "deceasedcraft:multi_nuclearpowerplant_20/multi_nuclearpowerplant_20_base7_palette",
  "xsize": 16,
  "zsize": 16,
  "slices": [
    [
      "                ",
      "                ",
      "                ",
      " a            a ",
      "                ",
      "      b  c      ",
      "                ",
      "                ",
      "         d      ",
      "e               ",
      "fe              ",
      "ffeee           ",
      "fffffeeeeeeeeeee",
      "ffffffffffffffff",
      "ffffffffffffffff",
      "vvvvvvvvvvvvvvvv"
    ],
    [
      "       gg       ",
      "       gg       ",
      "       gg       ",
      " a     gg     a ",
      "       gg       ",
      "      bggc      ",
      "       ggggggggg",
      "       ggggggggg",
      "         d      ",
      "e               ",
      "fe              ",
      "ffeee           ",
      "fffffeeeeeeeeeee",
      "ffffffffffffffff",
      "ffffffffffffffff",
      "vvvvvvvvvvvvvvvv"
    ],
    [
      "      hiij      ",
      "      hiij      ",
      "      hiij      ",
      " a    hiij    a ",
      "      hiij      ",
      "      hiikllllll",
      "      hiiiiiiiii",
      "      hiiiiiiiii",
      "       mmmmmmmmm",
      "e               ",
      "fe              ",
      "ffeee           ",
      "fffffeeeeeeeeeee",
      "ffffffffffffffff",
      "ffffffffffffffff",
      "vvvvvvvvvvvvvvvv"
    ],
    [
      "      hiij      ",
      "      hiij      ",
      "      hiij      ",
      " a    hiij    a ",
      "      hiij      ",
      "      hiikllllll",
      "      hiiiiiiiii",
      "      hiiiiiiiii",
      "       mmmmmmmmm",
      "e               ",
      "fe              ",
      "ffeee           ",
      "fffffeeeeeeeeeee",
      "ffffffffffffffff",
      "ffffffffffffffff",
      "vvvvvvvvvvvvvvvv"
    ],
    [
      "       nn       ",
      "       nn       ",
      "       nn       ",
      " a     nn     a ",
      "       nn       ",
      "       nn       ",
      "       nnnnnnnnn",
      "       nnnnnnnnn",
      "                ",
      "e               ",
      "fe              ",
      "ffeee           ",
      "fffffeeeeeeeeeee",
      "ffffffffffffffff",
      "ffffffffffffffff",
      "vvvvvvvvvvvvvvvv"
    ],
    [
      "ooooo      ooooo",
      "ooooo      ooooo",
      "ooooo      ooooo",
      "oaooo      oooao",
      "o ooo      ooooo",
      "ooooo      ooooo",
      "ooooo      ooooo",
      "ooooo      ooooo",
      "ooooo      ooooo",
      "eooooooo   ooooo",
      "peqrrroooooooooo",
      "ppeeerrrrrrrrrrr",
      "ppfffeeeeeeeeeee",
      "ppffffffffffffff",
      "ppffffffffffffff",
      "vvvvvvvvvvvvvvvv"
    ]
  ]
}