{
  "name": "multi_nuclearpowerplant_20_base1",
  "refpalette": "deceasedcraft:multi_nuclearpowerplant_20/multi_nuclearpowerplant_20_base1_palette",
  "xsize": 16,
  "zsize": 16,
  "slices": [
    [
      "aaaaaaaaaaaaaaaa",
      "aaaaaaaaaaaaaaaa",
      "aaaaaaaaaaaaaaaa",
      "aaaaaaaaaaaaaaaa",
      "aaaaaaaaaaaaaaaa",
      "zaaaaaaaaaaaaaaa",
      "bzzaaaaaaaaaaaaa",
      "cbbzaaaaaaaaaaaa",
      "cccbbaaaaaaaaaaa",
      "cccccbbbaaaaaaaa",
      "vcccccccbbbbaadd",
      "vcccccccccccbbbe",
      "vccccccccccccccc",
      "vccccccccccccccc",
      "vccccccccccccccc",
      "vvvvvvvvvvvvvvvv"
    ],
    [
      "                ",
      "                ",
      "                ",
      "                ",
      "                ",
      "f               ",
      "eff             ",
      "geef            ",
      "gggee hiih      ",
      "gggggeee j     a",
      "vgggggggeeeeaaad",
      "vgggggggggggeeee",
      "vggggggggggggggg",
      "vggggggggggggggg",
      "vggggggggggggggg",
      "vvvvvvvvvvvvvvvv"
    ],
    [
      "                ",
      "                ",
      "                ",
      "                ",
      "                ",
      "                ",
      "e               ",
      "gee   k         ",
      "gggee hllh      ",
      "gggggeee j      ",
      "vgggggggeeeeeaaa",
      "vgggggggggggeeee",
      "vggggggggggggggg",
      "vggggggggggggggg",
      "vggggggggggggggg",
      "vvvvvvvvvvvvvvvv"
    ],
    [
      "                ",
      "                ",
      "                ",
      "                ",
      "                ",
      "                ",
      "e               ",
      "gee   m  m      ",
      "gggee hnnh      ",
      "gggggeee j      ",
      "vgggggggeeeeeeaa",
      "vgggggggggggeeee",
      "vggggggggggggggg",
      "vggggggggggggggg",
      "vggggggggggggggg",
      "vvvvvvvvvvvvvvvv"
    ],
    [
      "      m  m      ",
      "      m  m      ",
      "      m  m      ",
      "      mmmm      ",
      "      moom      ",
      "      moom      ",
      "e     moom      ",
      "geep  qmmq      ",
      "gggee hhhh      ",
      "gggggeee j  p   ",
      "vgggggggeeeeeeea",
      "vgggggggggggeeee",
      "vggggggggggggggg",
      "vggggggggggggggg",
      "vggggggggggggggg",
      "vvvvvvvvvvvvvvvv"
    ],
    [
      "      h  h      ",
      "      h  h      ",
      "      h  h      ",
      "      h  h      ",
      "      hrrh      ",
      "ss    hhhh      ",
      "esss  hhhh      ",
      "geessshhhh      ",
      "gggeessssh      ",
      "gggggeeesssss   ",
      "vgggggggeeeessss",
      "vgggggggggggeeee",
      "vggggggggggggggg",
      "vggggggggggggggg",
      "vggggggggggggggg",
      "vvvvvvvvvvvvvvvv"
    ]
  ]
}