{
  "name": "multi_nuclearpowerplant_20_base3",
  "refpalette": "deceasedcraft:multi_nuclearpowerplant_20/multi_nuclearpowerplant_20_base3_palette",
  "xsize": 16,
  "zsize": 16,
  "slices": [
    [
      "                ",
      "a               ",
      "bb            bb",
      "bcbbb      bbbcd",
      "beddbbbbbbbbddde",
      "beeeddddddddeeee",
      "feeeeeeeeeeeeeee",
      "beeeeeeeeeeeeeee",
      "beeeeeeeeeeeeeee",
      "ddeeeeeeeeeeeedd",
      "vgdddddddddddddd",
      "vggfhhhhhhhhfdfd",
      "vggfhhhhhhhhfdff",
      "vggfhhhhhhhhfdfg",
      "vggfhhhhhhhhfdfg",
      "vvvvvvvvvvvvvvvv"
    ],
    [
      "                ",
      "i               ",
      "b               ",
      " j            jk",
      " lkk        kkk ",
      " l mkkkkkkkk    ",
      "nl              ",
      " l m            ",
      " l op          q",
      "rr m          rr",
      "vgrrrrrrrrrrrsrt",
      "vggnu wxxw yn nt",
      "vggnu  A   yn nn",
      "vggnu       B ng",
      "vggnuCDEFI  nJng",
      "vvvvvvvvvvvvvvvv"
    ],
    [
      "                ",
      "                ",
      "b               ",
      " j            jk",
      "  kk        kkk ",
      "   mkkkkkkkk    ",
      "n               ",
      "   m            ",
      "               K",
      "rrLm          rr",
      "vgrrrkkkkkkrrMrt",
      "vggnN OPQ   n nt",
      "vggnR       n nn",
      "vggnN       S ng",
      "vggnT FUED  nVng",
      "vvvvvvvvvvvvvvvv"
    ],
    [
      "                ",
      "                ",
      "b               ",
      " j            jk",
      "  kk        kkk ",
      "    kkkkkkkk    ",
      "n               ",
      "W               ",
      "W              X",
      "rr           Yrr",
      "vgrrrkkkkkkrrZrt",
      "vggnT      !n nt",
      "vggnN      0n1nn",
      "vggnR      2f ng",
      "vggnT       n ng",
      "vvvvvvvvvvvvvvvv"
    ],
    [
      "                ",
      "                ",
      "b               ",
      " j            jk",
      "  kk        kkk ",
      "    kkkkkkkk    ",
      "n  3            ",
      "                ",
      "   3            ",
      "rr            rr",
      "vgrrrkkkkkkrrrrt",
      "vggnN       ngnt",
      "vggnR       ngnn",
      "vggnT       ngng",
      "vggnN       n ng",
      "vvvvvvvvvvvvvvvv"
    ],
    [
      "                ",
      "                ",
      "b               ",
      " j            jk",
      "  kk        kkk ",
      "  44kkkkkkkk    ",
      "n 44            ",
      "  44            ",
      "  44            ",
      "rr44          rr",
      "vgrrrrrrrrrrrrrt",
      "vggn        nnnt",
      "vggn        nnnn",
      "vggn        nnng",
      "vggn        nnng",
      "vvvvvvvvvvvvvvvv"
    ]
  ]
}