{
  "name": "multi_nuclearpowerplant_20_base2",
  "refpalette": "deceasedcraft:multi_nuclearpowerplant_20/multi_nuclearpowerplant_20_base2_palette",
  "xsize": 16,
  "zsize": 16,
  "slices": [
    [
      "                ",
      "                ",
      "a               ",
      " b            bc",
      "  cc        ccc ",
      "    cccccccc    ",
      "d               ",
      "                ",
      "                ",
      "ee            ee",
      "vfeeeeeeeeeeeeeg",
      "vffd        dddg",
      "vffd        dddd",
      "vffd        dddf",
      "vffd        dddf",
      "vvvvvvvvvvvvvvvv"
    ],
    [
      "                ",
      "                ",
      "a               ",
      " b            bc",
      "  cc        ccc ",
      "    cccccccc    ",
      "d               ",
      "                ",
      "                ",
      "ee            ee",
      "vfeeeeeeeeeeeeeh",
      "vffdiiiiiiiidddh",
      "vffdiiiiiiiidddd",
      "vffdiiiiiiiidddf",
      "vffdijiiiijidddf",
      "vvvvvvvvvvvvvvvv"
    ],
    [
      "                ",
      "                ",
      "a               ",
      " b            bc",
      "  cc        ccc ",
      "    cccccccc    ",
      "d               ",
      "                ",
      "                ",
      "ee            ee",
      "vfeeeeeeeeeeeee ",
      "vffd        dddd",
      "vffd        dfff",
      "vffd        dfff",
      "vffd k    k dfff",
      "vvvvvvvvvvvvvvvv"
    ],
    [
      "                ",
      "                ",
      "a               ",
      " b            bc",
      "  cc        ccc ",
      "    cccccccc    ",
      "d               ",
      "                ",
      "                ",
      "ee            ee",
      "vfeeeeeeeeeeeee ",
      "vffd        dddd",
      "vffd        dfff",
      "vffdkkkkkkkkkkkk",
      "vffd k    k dfff",
      "vvvvvvvvvvvvvvvv"
    ],
    [
      "                ",
      "                ",
      "aa            aa",
      "aaaaa      aaaal",
      "a llaaaaaaaalll ",
      "a   llllllll    ",
      "d               ",
      "                ",
      "                ",
      "ll            ll",
      "aallllllllllllaa",
      "vaaaaaaaaaaaaaad",
      "vfffffffffffffff",
      "vfffffffffffffff",
      "vfffffffffffffff",
      "vvvvvvvvvvvvvvvv"
    ],
    [
      "mmmmmmmmmmmmmmmm",
      "mmmmmmmmmmmmmmmm",
      "aammmmmmmmmmmmaa",
      "aaaaammmmmmaaaan",
      "annnaaaaaaaannnn",
      "annnnnnnnnnnnnnn",
      "dnnnnnnnnnnnnnno",
      "nnnnnnnnnnnnnnnn",
      "nnnnnoooooonnnnn",
      "nnnnnnnnnnnnnnnn",
      "aannnnnnnnnnnnaa",
      "vaaaaaaaaaaaaaad",
      "vfffffffffffffff",
      "vfffffffffffffff",
      "vfffffffffffffff",
      "vvvvvvvvvvvvvvvv"
    ]
  ]
}