{
  "name": "multi_nuclearpowerplant_20_base4",
  "refpalette": "deceasedcraft:multi_nuclearpowerplant_20/multi_nuclearpowerplant_20_base4_palette",
  "xsize": 16,
  "zsize": 16,
  "slices": [
    [
      "                ",
      "                ",
      "                ",
      " a            a ",
      "                ",
      "                ",
      "b               ",
      "vbb             ",
      "vcdbb           ",
      "vcdddbbb        ",
      "vcddddddbbbb    ",
      "vcddddddddddbbbb",
      "vcdddddddddddddd",
      "vcdddddddddddddd",
      "vcdddddddddddddd",
      "vvvvvvvvvvvvvvvv"
    ],
    [
      "                ",
      "                ",
      "                ",
      " a            a ",
      "                ",
      "                ",
      "b               ",
      "vbb             ",
      "vcdbb           ",
      "vcdddbbb        ",
      "vcddddddbbbb    ",
      "vcddddddddddbbbb",
      "vcdddddddddddddd",
      "vcdddddddddddddd",
      "vcdddddddddddddd",
      "vvvvvvvvvvvvvvvv"
    ],
    [
      "                ",
      "                ",
      "                ",
      " a            a ",
      "                ",
      "                ",
      "b               ",
      "vbb             ",
      "vcdbb           ",
      "vcdddbbb        ",
      "vcddddddbbbb    ",
      "vcddddddddddbbbb",
      "vcdddddddddddddd",
      "vcdddddddddddddd",
      "vcdddddddddddddd",
      "vvvvvvvvvvvvvvvv"
    ],
    [
      "                ",
      "                ",
      "                ",
      " a            a ",
      "                ",
      "                ",
      "b               ",
      "vbb             ",
      "vcdbb           ",
      "vcdddbbb        ",
      "vcddddddbbbb    ",
      "vcddddddddddbbbb",
      "vcdddddddddddddd",
      "vcdddddddddddddd",
      "vcdddddddddddddd",
      "vvvvvvvvvvvvvvvv"
    ],
    [
      "                ",
      "                ",
      "                ",
      " a            a ",
      "                ",
      "                ",
      "b               ",
      "vbb             ",
      "vcdbb           ",
      "vcdddbbb        ",
      "vcddddddbbbb    ",
      "vcddddddddddbbbb",
      "vcdddddddddddddd",
      "vcdddddddddddddd",
      "vcdddddddddddddd",
      "vvvvvvvvvvvvvvvv"
    ],
    [
      "                ",
      "                ",
      "ee            ee",
      "eaeee      eeea ",
      "e   eeeeeeee    ",
      "e               ",
      "b               ",
      "vbb             ",
      "vccbb           ",
      "vccccbbb        ",
      "vcccccccbbbb    ",
      "vcccccccccccbbbb",
      "vccccccccccccccc",
      "vccccccccccccccc",
      "vccccccccccccccc",
      "vvvvvvvvvvvvvvvv"
    ]
  ]
}