{
  "name": "multi_nuclearpowerplant_20_base6",
  "refpalette": "deceasedcraft:multi_nuclearpowerplant_20/multi_nuclearpowerplant_20_base6_palette",
  "xsize": 16,
  "zsize": 16,
  "slices": [
    [
      "aaaaabccccbaaaaa",
      "aaaaabccccbaaaaa",
      "aaaaabccccbaaaaa",
      "a!aaabccccbaaada",
      "a aaabccccbaaaaa",
      "aaaaabccccbaaaaa",
      "eaaaabccccbaaaaa",
      "feeaabccccbaaaaa",
      "fffeebbbccbaaaaa",
      "effffeeebbbaaaaa",
      "veffffffeeeeaaaa",
      "vfeeefffffffeeee",
      "vfgggeeeeeeeeeee",
      "vfgggggggggggggg",
      "vfgggggggggggggg",
      "vvvvvvvvvvvvvvvv"
    ],
    [
      "                ",
      "                ",
      "              h ",
      " i            i ",
      " j              ",
      "                ",
      "k               ",
      "vkk             ",
      "vfgkk           ",
      "vfgggkkk        ",
      "vfggggggkkkk    ",
      "vfggggggggggkkkk",
      "vfgggggggggggggg",
      "vfgggggggggggggg",
      "vfgggggggggggggg",
      "vvvvvvvvvvvvvvvv"
    ],
    [
      "                ",
      "                ",
      "                ",
      " i            i ",
      "                ",
      "                ",
      "k               ",
      "vkk             ",
      "vfgkk           ",
      "vfgggkkk        ",
      "vfggggggkkkk    ",
      "vfggggggggggkkkk",
      "vfgggggggggggggg",
      "vfgggggggggggggg",
      "vfgggggggggggggg",
      "vvvvvvvvvvvvvvvv"
    ],
    [
      "                ",
      "                ",
      "                ",
      " i            i ",
      "                ",
      "                ",
      "k               ",
      "vkk             ",
      "vfgkk           ",
      "vfgggkkk        ",
      "vfggggggkkkk    ",
      "vfggggggggggkkkk",
      "vfgggggggggggggg",
      "vfgggggggggggggg",
      "vfgggggggggggggg",
      "vvvvvvvvvvvvvvvv"
    ],
    [
      "                ",
      "                ",
      "                ",
      " i            i ",
      "                ",
      "                ",
      "k               ",
      "vkk             ",
      "vfgkk           ",
      "vfgggkkk        ",
      "vfggggggkkkk    ",
      "vfggggggggggkkkk",
      "vfgggggggggggggg",
      "vfgggggggggggggg",
      "vfgggggggggggggg",
      "vvvvvvvvvvvvvvvv"
    ],
    [
      "                ",
      "                ",
      "                ",
      " i            i ",
      "                ",
      "                ",
      "k               ",
      "vkk             ",
      "vfgkk           ",
      "vfgggkkk        ",
      "vfggggggkkkk    ",
      "vfggggggggggkkkk",
      "vfgggggggggggggg",
      "vfgggggggggggggg",
      "vfgggggggggggggg",
      "vvvvvvvvvvvvvvvv"
    ]
  ]
}