{
  "name": "multi_nuclearpowerplant_20_base5",
  "refpalette": "deceasedcraft:multi_nuclearpowerplant_20/multi_nuclearpowerplant_20_base5_palette",
  "xsize": 16,
  "zsize": 16,
  "slices": [
    [
      "                ",
      "                ",
      "                ",
      " a            a ",
      "                ",
      "                ",
      "b               ",
      "vbb             ",
      "vcdbb           ",
      "vcdddbbb        ",
      "vcddddddbbbb    ",
      "vcddddddddddbbbb",
      "vcdddddddddddddd",
      "vcdddddddddddddd",
      "vcdddddddddddddd",
      "vvvvvvvvvvvvvvvv"
    ],
    [
      "                ",
      "                ",
      "                ",
      " a            a ",
      "                ",
      "                ",
      "b               ",
      "vbb             ",
      "vcdbb           ",
      "vcdddbbb        ",
      "vcddddddbbbb    ",
      "vcddddddddddbbbb",
      "vcdddddddddddddd",
      "vcdddddddddddddd",
      "vcdddddddddddddd",
      "vvvvvvvvvvvvvvvv"
    ],
    [
      "                ",
      "                ",
      "                ",
      " a            a ",
      "                ",
      "                ",
      "b               ",
      "vbb             ",
      "vcdbb           ",
      "vcdddbbb        ",
      "vcddddddbbbb    ",
      "vcddddddddddbbbb",
      "vcdddddddddddddd",
      "vcdddddddddddddd",
      "vcdddddddddddddd",
      "vvvvvvvvvvvvvvvv"
    ],
    [
      "                ",
      "                ",
      "                ",
      " a            a ",
      "                ",
      "                ",
      "b               ",
      "vbb             ",
      "vcdbb           ",
      "vcdddbbb        ",
      "vcddddddbbbb    ",
      "vcddddddddddbbbb",
      "vcdddddddddddddd",
      "vcdddddddddddddd",
      "vcdddddddddddddd",
      "vvvvvvvvvvvvvvvv"
    ],
    [
      "                ",
      "                ",
      "                ",
      " a            a ",
      "                ",
      "                ",
      "b               ",
      "vbb             ",
      "vcdbb           ",
      "vcdddbbb        ",
      "vcddddddbbbb    ",
      "vcddddddddddbbbb",
      "vcdddddddddddddd",
      "vcdddddddddddddd",
      "vcdddddddddddddd",
      "vvvvvvvvvvvvvvvv"
    ],
    [
      "                ",
      "                ",
      "                ",
      " a            a ",
      "                ",
      "                ",
      "b               ",
      "vbb             ",
      "vcdbb           ",
      "vcdddbbb        ",
      "vcddddddbbbb    ",
      "vcddddddddddbbbb",
      "vcdddddddddddddd",
      "vcdddddddddddddd",
      "vcdddddddddddddd",
      "vvvvvvvvvvvvvvvv"
    ]
  ]
}