{
  "name": "multi_filmworkstower_20_base2",
  "refpalette": "deceasedcraft:multi_filmworkstower_20/multi_filmworkstower_20_base2_palette",
  "xsize": 16,
  "zsize": 16,
  "slices": [
    [
      "vvvvvvvvvvvvvvvv",
      "aaaaaaaaaaaaaaav",
      "bbbbbbbbbbbbbbbv",
      "ccccccccccccccbv",
      "ccccccccccccccbv",
      "ccccccccccccccbv",
      "ccccccccccccccbv",
      "ccccccccccccccbv",
      "ccccccccccccccbv",
      "ccccccccccccccbv",
      "ccccccccccccccbv",
      "ccccccccccccccbv",
      "ccccccccccccccbv",
      "ccccccccccccccbv",
      "ddddddddddccccbv",
      "       e dccccbv"
    ],
    [
      "vvvvvvvvvvvvvvvv",
      "aaaaaaaaaaaaaaav",
      "bbbbbbbbbbbbbbbv",
      "f g     h ij ibv",
      "k        l  l bv",
      "m  n          bv",
      "m onp         bv",
      "q  n   rsttttubv",
      "wwwwwxywwwwwwwbv",
      "              bv",
      "              bv",
      "              bv",
      "              bv",
      "              bv",
      "AAAAAAA Ad    bv",
      "         dBC  bv"
    ],
    [
      "vvvvvvvvvvvvvvvv",
      "aaaaaaaaaaaaaaav",
      "bbbbbbbbbbbbbbbv",
      "f       D  D  bv",
      "E             bv",
      "E  F          bv",
      "I             bv",
      "E  J    KLMKLNbv",
      "wwwwwOPwwwwwwwbv",
      "              bv",
      "              bv",
      "              bv",
      "              bv",
      "              bv",
      "         d    bv",
      "         dB   bv"
    ],
    [
      "vvvvvvvvvvvvvvvv",
      "aaaaaaaaaaaaaaav",
      "bbbbbbbbbbbbbbbv",
      "f             bv",
      "I             bv",
      "E             bv",
      "I             bv",
      "I        Q  Q bv",
      "wwwwwRSwwwwwwwbv",
      "              bv",
      "              bv",
      "              bv",
      "              bv",
      "              bv",
      "         d    bv",
      "         dB   bv"
    ],
    [
      "vvvvvvvvvvvvvvvv",
      "aaaaaaaaaaaaaaav",
      "bbbbbbbbbbbbbbbv",
      "f             bv",
      "T             bv",
      "U             bv",
      "V             bv",
      "W             bv",
      "wwwwwwwwwwwwwwbv",
      "              bv",
      "              bv",
      "              bv",
      "              bv",
      "              bv",
      "         d    bv",
      "         dBX  bv"
    ],
    [
      "vvvvvvvvvvvvvvvv",
      "aaaaaaaaaaaaaaav",
      "bbbbbbbbbbbbbbbv",
      "f             bv",
      "              bv",
      "              bv",
      "              bv",
      "W             bv",
      "wwwwwwwwwwwwwwbv",
      "              bv",
      "              bv",
      "              bv",
      "              bv",
      "              bv",
      "         d    bv",
      "         dB   bv"
    ]
  ]
}