{
  "name": "multi_filmworkstower_20_base1",
  "refpalette": "deceasedcraft:multi_filmworkstower_20/multi_filmworkstower_20_base1_palette",
  "xsize": 16,
  "zsize": 16,
  "slices": [
    [
      "vvvvvvvvvvvvvvvv",
      "aaaaaaaaaaaaaaav",
      "bbbbbbbbbbbbbbbv",
      "c             bv",
      "d             bv",
      "d             bv",
      "d             bv",
      "e             bv",
      "ffffffffffffffbv",
      "ggg           bv",
      "              bv",
      "              bv",
      "              bv",
      "              bv",
      "         h    bv",
      "         hi   bv"
    ],
    [
      "vvvvvvvvvvvvvvvv",
      "aaaaaaaaaaaaaaav",
      "bbbbbbbbbbbbbbbv",
      "              bv",
      "              bv",
      "              bv",
      "!             bv",
      "e             bv",
      "ffffffffffffffbv",
      "jjj           bv",
      "              bv",
      "              bv",
      "              bv",
      "              bv",
      "         h    bv",
      "         hik  bv"
    ],
    [
      "vvvvvvvvvvvvvvvv",
      "aaaaaaaaaaaaaaav",
      "bbbbbbbbbbbbbbbv",
      "l             bv",
      "              bv",
      "              bv",
      "              bv",
      "e            mbv",
      "ffffffffffffffbv",
      "nnn           bv",
      "              bv",
      "              bv",
      "              bv",
      "              bv",
      "         h    bv",
      "         hiooobv"
    ],
    [
      "vvvvvvvvvvvvvvvv",
      "aaaaaaaaaaaaaaav",
      "bbbbbbbbbbbbbbbv",
      "              bv",
      "              bv",
      "              bv",
      "              bv",
      "ppppqppppqppppbv",
      "ffffffffffffffbv",
      "              bv",
      "              bv",
      "              bv",
      "              bv",
      "              bv",
      "              bv",
      "         ris  bv"
    ],
    [
      "vvvvvvvvvvvvvvvv",
      "aaaaaaaaaaaaaaav",
      "bbbbbbbbbbbbbbbv",
      "ttttttttttttttbv",
      "ttttttttttttttbv",
      "ttttttttttttttbv",
      "ttttttttttttttbv",
      "ttttttttttttttbv",
      "ffffffffffffffbv",
      "uuuuuuuuuuuuuubv",
      "uuuuuuuuuuuuuubv",
      "uuuuuuuuuuuuuubv",
      "uuuuuuuuuuuuuubv",
      "uuuuuuuuuuuuuubv",
      "uuuuuuuuuuuuuubv",
      "uuuuuuuuuuwuuubv"
    ],
    [
      "vvvvvvvvvvvvvvvv",
      "aaaaaaaaaaaaaaav",
      "bbbbbbbbbbbbbbbv",
      "xxxxxxxxxxxxxxbv",
      "xxxxxxxxxxxxxxbv",
      "xxxxxxxxxxxxxxbv",
      "xxxxxxxxxxxxxxbv",
      "xxxxxxxxxxxxxxbv",
      "xxxxxxxxxxxxxxbv",
      "xxxxxxxxxxxxxxbv",
      "xxxxxxxxxxxxxxbv",
      "xxxxxxxxxxxxxxbv",
      "xxxxxxxxxxxxxxbv",
      "xxxxxxxxxxxxxxbv",
      "xxxxxxxxxxxxxxbv",
      "xxxxxxxxxxxxxxbv"
    ]
  ]
}