{
  "name": "multi_casino_2_floor8",
  "refpalette": "deceasedcraft:multi_casino_2/multi_casino_2_floor8_palette",
  "xsize": 16,
  "zsize": 16,
  "slices": [
    [
      "                ",
      "      aaaaaaaaaa",
      "      abbbbbbbcd",
      "      a ceeeeeee",
      "      a ceeeeeee",
      "      a ceeeeeee",
      "      a ceeeeeee",
      "      abfgggeeee",
      "      abg    eee",
      "      abg   heee",
      "      abg   heee",
      "      abiggggeee",
      "      ab jjjjjje",
      "      ab       j",
      "      ac        ",
      "      ad        "
    ],
    [
      "                ",
      "      kaaakaaaa ",
      "      abbbbbbcd ",
      "      ablmnnoopp",
      "      ablq  rstu",
      "      kblqwx    ",
      "      ablqwyA   ",
      "      abfgggBC  ",
      "      abg   gD  ",
      "      kbg   EF  ",
      "      abg   EI  ",
      "      ab ggggJJ ",
      "      ab      KJ",
      "      kb        ",
      "      ac        ",
      "      ad        "
    ],
    [
      "                ",
      "      aaaaaaaa  ",
      "      abbbbbcdL ",
      "      abM  N    ",
      "      abM       ",
      "      abM y     ",
      "      abM w     ",
      "      abgfggM   ",
      "      abf   g   ",
      "      abg    O  ",
      "      abg    P  ",
      "      ab gggg   ",
      "      ab        ",
      "      ac        ",
      "      ad        ",
      "      QR        "
    ],
    [
      "                ",
      "      aaaaaaaa  ",
      "      abbbbbcdL ",
      "      abS       ",
      "      abS       ",
      "      abS       ",
      "      abS x     ",
      "      abggfgT   ",
      "      abg   g   ",
      "      abf   UV  ",
      "      abg   UV  ",
      "      ab gggg   ",
      "      ac        ",
      "      ad        ",
      "      WR        ",
      "      QR        "
    ],
    [
      "                ",
      "      aaaaaaa   ",
      "      abbbbcd L ",
      "      abS       ",
      "      abS       ",
      "      abS       ",
      "      abS       ",
      "      abggfg    ",
      "      abg   g   ",
      "      abf   g   ",
      "      abg   g   ",
      "      ab gggg   ",
      "      ac        ",
      "      ad        ",
      "       R        ",
      "      QR        "
    ],
    [
      "                ",
      "      aakaaaa   ",
      "      abbbbcd L ",
      "      kbS       ",
      "      abS       ",
      "      abS       ",
      "      abS       ",
      "      kbgggf    ",
      "      abg   g   ",
      "      abg   g   ",
      "      abf   g   ",
      "      kc gggg   ",
      "      ad        ",
      "      QR        ",
      "       R        ",
      "      QR        "
    ]
  ]
}