{
  "name": "multi_casino_2_floor18",
  "refpalette": "deceasedcraft:multi_casino_2/multi_casino_2_floor18_palette",
  "xsize": 16,
  "zsize": 16,
  "slices": [
    [
      "                ",
      "                ",
      "                ",
      "                ",
      "                ",
      "        a a a a ",
      "       bbbbbbbbb",
      "      abcdddeeee",
      "       bd    fff",
      "      abd   gfff",
      "       bd   gfff",
      "      abeddddfff",
      "       befffffff",
      "      abefffffff",
      "       befffffff",
      "      abcfffffff"
    ],
    [
      "                ",
      "                ",
      "                ",
      "                ",
      "                ",
      "        a a a a ",
      "       bhhhhhhhh",
      "      ahcdddi jj",
      "       hd   dk  ",
      "      aha   lm  ",
      "       hd   ln  ",
      "      ahodddd   ",
      "       hpqrsi   ",
      "      ah t      ",
      "       h u w    ",
      "      ahcxyyAB C"
    ],
    [
      "                ",
      "                ",
      "                ",
      "                ",
      "                ",
      "        a a a a ",
      "       bhhhhhhhh",
      "      ahcdddD   ",
      "       hd   d   ",
      "      aha    E  ",
      "       hd    F  ",
      "      ahIdddd   ",
      "       hJKKKD   ",
      "      ah        ",
      "       h        ",
      "      ahcL MN   "
    ],
    [
      "                ",
      "                ",
      "                ",
      "                ",
      "                ",
      "        a a a a ",
      "       bhhhhhhhh",
      "      ahcdddO   ",
      "       hd   d   ",
      "      ahd   PQ  ",
      "       hd   PQ  ",
      "      ahtdddd   ",
      "       hJKKKO   ",
      "      ah        ",
      "       h        ",
      "      ahc       "
    ],
    [
      "                ",
      "                ",
      "                ",
      "                ",
      "                ",
      "        a a a a ",
      "       bhhhhhhhh",
      "      ahcddd    ",
      "       hd   d   ",
      "      ahd   d   ",
      "       hd   d   ",
      "      ah dddd   ",
      "       hRSTU    ",
      "      ah        ",
      "       h        ",
      "      ahc       "
    ],
    [
      "                ",
      "                ",
      "                ",
      "                ",
      "                ",
      "        a a a a ",
      "       bhhhhhhhh",
      "      ahcdddVWWW",
      "       hd   XYYY",
      "      ahd   dYYY",
      "       hd   dYYY",
      "      ah!ddddYYY",
      "       hWYYZYYYY",
      "      ahWYYYYYYY",
      "       hWYYYYYYY",
      "      ahcYYYYYYY"
    ]
  ]
}