{
  "name": "multi_casino_2_floor20",
  "refpalette": "deceasedcraft:multi_casino_2/multi_casino_2_floor20_palette",
  "xsize": 16,
  "zsize": 16,
  "slices": [
    [
      "                ",
      "                ",
      "                ",
      "                ",
      "                ",
      "        a a a a ",
      "       bbbbbbbbb",
      "      abcdddeeee",
      "       bd    fff",
      "      abd   gfff",
      "       bd   gfff",
      "      abeddddfff",
      "       befffffff",
      "      abefffffff",
      "       befffffff",
      "      abcfffffff"
    ],
    [
      "                ",
      "                ",
      "                ",
      "                ",
      "                ",
      "        a a a a ",
      "       bhhhhhhhh",
      "      ahcdddi jj",
      "       hd   dk  ",
      "      aha   lm  ",
      "       hd   ln  ",
      "      ahodddd   ",
      "       hpqrsi   ",
      "      ah  t     ",
      "       hu  w    ",
      "      ahcxyyAB C"
    ],
    [
      "                ",
      "                ",
      "                ",
      "                ",
      "                ",
      "        a a a a ",
      "       bhhhhhhhh",
      "      ahcdddD   ",
      "       hd   d   ",
      "      aha    E  ",
      "       hd    F  ",
      "      ah!dddd   ",
      "       hIJJKL   ",
      "      ah        ",
      "       h        ",
      "      ahcMNO    "
    ],
    [
      "                ",
      "                ",
      "                ",
      "                ",
      "                ",
      "        a a a a ",
      "       bhhhhhhhh",
      "      ahcdddP   ",
      "       hd   d   ",
      "      ahd   QR  ",
      "       hd   QR  ",
      "      ah dddd   ",
      "       hIJSJ    ",
      "      ah        ",
      "       h        ",
      "      ahc       "
    ],
    [
      "                ",
      "                ",
      "                ",
      "                ",
      "                ",
      "        a a a a ",
      "       bhhhhhhhh",
      "      ahcddd    ",
      "       hd   d   ",
      "      ahd   d   ",
      "       hd   d   ",
      "      ah dddd   ",
      "       hTUVW    ",
      "      ah        ",
      "       h        ",
      "      ahc       "
    ],
    [
      "                ",
      "                ",
      "                ",
      "                ",
      "                ",
      "        a a a a ",
      "       bhhhhhhhh",
      "      ahcdddXYYY",
      "       hd   Z000",
      "      ahd   d000",
      "       hd   d000",
      "      ah1dddd000",
      "       hY0000000",
      "      ahY0000000",
      "       hY0000000",
      "      ahc0000000"
    ]
  ]
}