{
  "name": "multi_casino_2_base9",
  "refpalette": "deceasedcraft:multi_casino_2/multi_casino_2_base9_palette",
  "xsize": 16,
  "zsize": 16,
  "slices": [
    [
      "vaaaaaaabbbbbbbb",
      "vaaaaaaabbbbbbbb",
      "vaaaaaaabbbbbbbb",
      "vaaaaaaabbbbbbbb",
      "vaaaaaaabbbbbbbb",
      "vaaaaaaabbbbbbbb",
      "vaaaaaaabbbbbbbb",
      "vaaaaaaabbbbbbbb",
      "vaaaaaaabbbbbbbb",
      "vaaaaaaabbbbbbbb",
      "vaaaaaaabbbbbbbb",
      "vaaaaaaabbbbbbbb",
      "vaaaaaaabbbbbbbb",
      "vaaaaaaabbbbbbbb",
      "vaaaaaaabbbbbbbb",
      "vaaaaaaabbbbbbbb"
    ],
    [
      "vaaaaaaacccccccc",
      "vaaaaaaacccccccc",
      "vaaaaaaacccccccc",
      "vaaaaaaacccccccc",
      "vaaaaaaacccccccc",
      "vaaaaaaacccccccc",
      "vaaaaaaacccccccc",
      "vaaaaaaadcccccce",
      "vaaaaaaacfghcccc",
      "vaaaaaaaci  cccc",
      "vaaaaaaac   cccc",
      "vaaaaaaajcklcccc",
      "vaaaaaaajm  jccc",
      "vaaaaaaajn  jcc@",
      "vaaaaaaajo  jc@ ",
      "vaaaaaaajp  j@  "
    ],
    [
      "vaaaaaaacccccccc",
      "vaaaaaaacccccccc",
      "vaaaaaaacccccccc",
      "vaaaaaaacccccccc",
      "vaaaaaaacccccccc",
      "vaaaaaaacccccccc",
      "vaaaaaaacccccccc",
      "vaaaaaaadcccccce",
      "vaaaaaaac  qcccc",
      "vaaaaaaac   cccc",
      "vaaaaaaac   cccc",
      "vaaaaaaajcrscccc",
      "vaaaaaaajm  jccc",
      "vaaaaaaajt  jcc@",
      "vaaaaaaajn  jc@ ",
      "vaaaaaaajt  j@  "
    ],
    [
      "vaaaaaaacccccccc",
      "vaaaaaaacccccccc",
      "vaaaaaaacccccccc",
      "vaaaaaaacccccccc",
      "vaaaaaaacccccccc",
      "vaaaaaaacccccccc",
      "vaaaaaaacccccccc",
      "vaaaaaaadcccccce",
      "vaaaaaaac   cccc",
      "vaaaaaaac   cccc",
      "vaaaaaaacu  cccc",
      "vaaaaaaajcwwcccc",
      "vaaaaaaajm  jccc",
      "vaaaaaaaj   jcc@",
      "vaaaaaaaj   jc@ ",
      "vaaaaaaaj   j@  "
    ],
    [
      "vaaaaaaacccccccc",
      "vaaaaaaacccccccc",
      "vaaaaaaacccccccc",
      "vaaaaaaacccccccc",
      "vaaaaaaacccccccc",
      "vaaaaaaacccccccc",
      "vaaaaaaacccccccc",
      "vaaaaaaadccccccc",
      "vaaaaaaac   cccc",
      "vaaaaaaac x cccc",
      "vaaaaaaac   cccc",
      "vaaaaaaajccccccc",
      "vaaaaaaajm  jccc",
      "vaaaaaaaj   jcc@",
      "vaaaaaaaj   jc@ ",
      "vaaaaaaaj   j@  "
    ],
    [
      "vaaaaaaacccccccd",
      "vaaaaaaaccccccdc",
      "vaaaaaaacccccdcc",
      "vaaaaaaaccccdccc",
      "vaaaaaaacccdcccc",
      "vaaaaaaaccdccccc",
      "vaaaaaaacdcccccc",
      "vaaaaaaadccccccc",
      "vaaaaaaacbbbyccc",
      "vaaaaaaacbbbcccc",
      "vaaaaaaacbbbcccc",
      "vaaaaaaajccccccc",
      "vaaaaaaajmbbjdcc",
      "vaaaaaaajbbbjcdA",
      "vaaaaaaajbbbjcAd",
      "vaaaaaaajbbbjABB"
    ]
  ]
}