{
  "name": "multi_casino_2_base4",
  "refpalette": "deceasedcraft:multi_casino_2/multi_casino_2_base4_palette",
  "xsize": 16,
  "zsize": 16,
  "slices": [
    [
      "vaabcdefffffffff",
      "vaabcdefffffffff",
      "vaabcdefffffffff",
      "vaabgdefffffffff",
      "vaabcdefffffffff",
      "vaabcdefffffffff",
      "vaabcdefffffffff",
      "vaabcdefhiiiffff",
      "vaabcdedi    fff",
      "vaabcdedi   jfff",
      "vaabcdedi   jfff",
      "vaabgdeddiiiifff",
      "vaabcdeddddddfff",
      "vaabcdeddddddfff",
      "vaabcdeddddddfff",
      "vaabcdeddddddfff"
    ],
    [
      "vaabk    l      ",
      "vaabk   mnno    ",
      "vaabk   mpnno   ",
      "vaabgq  rpnno   ",
      "vaabk   m!nno   ",
      "vaabk   mnno    ",
      "vaabk    s      ",
      "vaabk   hiiit   ",
      "vaabk   i   iu  ",
      "vaabk   i   wx  ",
      "vaabk   i   wy  ",
      "vaabgq  Aiiii   ",
      "vaabk   A B C   ",
      "vaabk   ADA C   ",
      "vaabk   AEE C   ",
      "vaabk FIA B C   "
    ],
    [
      "vaabk           ",
      "vaabk           ",
      "vaabk    J      ",
      "vaabg    K      ",
      "vaabk    L      ",
      "vaabk           ",
      "vaabk           ",
      "vaabk   hiiiM   ",
      "vaabk   i   i   ",
      "vaabk   i    N  ",
      "vaabk   i    O  ",
      "vaabg   Aiiii   ",
      "vaabk   A P C   ",
      "vaabk   A A C   ",
      "vaabk   AEE C   ",
      "vaabk   A P C   "
    ],
    [
      "vaabk           ",
      "vaabk           ",
      "vaabk           ",
      "vaabg           ",
      "vaabk           ",
      "vaabk           ",
      "vaabk           ",
      "vaabk   hiiiQ   ",
      "vaabk   i   i   ",
      "vaabk   i   RS  ",
      "vaabk   i   RS  ",
      "vaabg   Aiiii   ",
      "vaabk   A A C   ",
      "vaabk   A A C   ",
      "vaabk   AEE C   ",
      "vaabk   A A C   "
    ],
    [
      "vaabk           ",
      "vaabk           ",
      "vaabk           ",
      "vaabg           ",
      "vaabk           ",
      "vaabk           ",
      "vaabk           ",
      "vaabk   hiii    ",
      "vaabk   i   i   ",
      "vaabk   i   i   ",
      "vaabk   i   i   ",
      "vaabg   Aiiii   ",
      "vaabk   ATTTC   ",
      "vaabk   AUTTC   ",
      "vaabk   ATTTC   ",
      "vaabk   ATTTC   "
    ],
    [
      "vaab            ",
      "vaabk           ",
      "vaabk           ",
      "vaabg           ",
      "vaabk           ",
      "vaab            ",
      "vaabk           ",
      "vaabk   hiii    ",
      "vaab    i   i   ",
      "vaabk   i   i   ",
      "vaabk   i   i   ",
      "vaabg   Aiiii   ",
      "vaabk   AVWWC   ",
      "vaab    AV  C   ",
      "vaabk   AVWWC   ",
      "vaabk   AV  C   "
    ]
  ]
}