{
  "name": "multi_casino_2_floor15",
  "refpalette": "deceasedcraft:multi_casino_2/multi_casino_2_floor15_palette",
  "xsize": 16,
  "zsize": 16,
  "slices": [
    [
      "                ",
      "                ",
      "                ",
      "                ",
      "                ",
      "        a a a a ",
      "       bbbbbbbbb",
      "      abccccd   ",
      "       bc   c   ",
      "      abc   c   ",
      "       bc   c   ",
      "      abdcccc   ",
      "       b        ",
      "      ab        ",
      "       b        ",
      "      ab        "
    ],
    [
      "                ",
      "                ",
      "                ",
      "                ",
      "                ",
      "        a a a a ",
      "       beeeeeeee",
      "      aeccccd   ",
      "       ec   c   ",
      "      aea   c   ",
      "       ec   c   ",
      "      aedcccc   ",
      "       e        ",
      "      ae        ",
      "       e        ",
      "      ae        "
    ],
    [
      "                ",
      "                ",
      "                ",
      "                ",
      "                ",
      "        a a a a ",
      "       beeeeeeee",
      "      aecccd    ",
      "       ec   c   ",
      "      aea   c   ",
      "       ed   c   ",
      "      ae cccc   ",
      "       e        ",
      "      ae        ",
      "       e       f",
      "      ae      g "
    ],
    [
      "                ",
      "                ",
      "                ",
      "                ",
      "                ",
      "        a a a a ",
      "       beeeeeeee",
      "      aeccdc    ",
      "       ec   c   ",
      "      aed   c   ",
      "       ec   c   ",
      "      ae cccc   ",
      "       e        ",
      "      ae        ",
      "       e       h",
      "      ae      i "
    ],
    [
      "                ",
      "                ",
      "                ",
      "                ",
      "                ",
      "        a a a a ",
      "       beeeeeeee",
      "      aeccdc    ",
      "       ec   c   ",
      "      aed   c   ",
      "       ec   c   ",
      "      ae cccc   ",
      "       e        ",
      "      ae       h",
      "       e      hh",
      "      ae      i "
    ],
    [
      "                ",
      "                ",
      "                ",
      "                ",
      "                ",
      "        a a a a ",
      "       beeeeeeee",
      "      aecdccjkkk",
      "       ed   lmmm",
      "      aec   cmmm",
      "       ec   cmmm",
      "      aekccccmmm",
      "       ekmmmmmmn",
      "      aekmmmmmko",
      "       ekmmmmpoq",
      "      aekmmmmpoq"
    ]
  ]
}