{
  "name": "multi_casino_2_floor14",
  "refpalette": "deceasedcraft:multi_casino_2/multi_casino_2_floor14_palette",
  "xsize": 16,
  "zsize": 16,
  "slices": [
    [
      "                ",
      "               a",
      "                ",
      "                ",
      "                ",
      "        b b b b ",
      "       ccccccccc",
      "      bcdeeeffff",
      "       ce    fff",
      "      bce   gfff",
      "       ce   gfff",
      "      bcfeeeefff",
      "       cffffffff",
      "      bcffffffff",
      "       cffffffff",
      "      bcdfffffff"
    ],
    [
      "                ",
      "                ",
      "                ",
      "                ",
      "                ",
      "        b b b b ",
      "       chhhhhhhh",
      "      bhdeeei   ",
      "       he   ej  ",
      "      bhb   kl  ",
      "       he   km  ",
      "      bhieeee   ",
      "       hn  o    ",
      "      bh  poq   ",
      "       h   o   r",
      "      bhd poq  s"
    ],
    [
      "                ",
      "                ",
      "                ",
      "                ",
      "                ",
      "        b b b b ",
      "       chhhhhhhh",
      "      bhedeet  d",
      "       hd   e   ",
      "      bhb    u  ",
      "       he    w  ",
      "      bhteeee   ",
      "       h        ",
      "      bh        ",
      "       hd  x    ",
      "      bh   y    "
    ],
    [
      "                ",
      "                ",
      "                ",
      "                ",
      "                ",
      "        b b b b ",
      "       chhhhhhhh",
      "      bheedeA d ",
      "       he   e   ",
      "      bhd   BC  ",
      "       he   BC  ",
      "      bhAeeee   ",
      "       h        ",
      "      bhd       ",
      "       h        ",
      "      bh        "
    ],
    [
      "                ",
      "                ",
      "                ",
      "                ",
      "                ",
      "        b b b b ",
      "       chhhhhhhh",
      "      bheede  d ",
      "       he   e   ",
      "      bhd   e   ",
      "       he   e   ",
      "      bh eeee   ",
      "       h        ",
      "      bhd       ",
      "       h        ",
      "      bh        "
    ],
    [
      "                ",
      "                ",
      "                ",
      "                ",
      "                ",
      "        b b b b ",
      "       chhhhhhhh",
      "      bheeed d  ",
      "       he   e   ",
      "      bhe   e   ",
      "       hd   e   ",
      "      bh eeee   ",
      "       hd       ",
      "      bh        ",
      "       h        ",
      "      bh        "
    ]
  ]
}