{
  "name": "multi_casino_2_floor25",
  "refpalette": "deceasedcraft:multi_casino_2/multi_casino_2_floor25_palette",
  "xsize": 16,
  "zsize": 16,
  "slices": [
    [
      "                ",
      "                ",
      "                ",
      "                ",
      "                ",
      "        a a a a ",
      "       bbbbbbbbb",
      "      abcddd    ",
      "       bd   d   ",
      "      abd   d   ",
      "       bd   d   ",
      "      ab dddd  e",
      "       b      fg",
      "      ab      eg",
      "       b       f",
      "      abc       "
    ],
    [
      "                ",
      "                ",
      "                ",
      "                ",
      "                ",
      "        a a a a ",
      "       bhhhhhhhh",
      "      ahcddd    ",
      "       hd   d  i",
      "      aha   d  i",
      "       hd   d  i",
      "      ah dddd  i",
      "       h       f",
      "      ah       e",
      "       h       i",
      "      ahc      i"
    ],
    [
      "                ",
      "                ",
      "                ",
      "                ",
      "                ",
      "        a a a a ",
      "       bhhhhhhhh",
      "      ahcddd   e",
      "       hd   d  j",
      "      aha   d  f",
      "       hd   d   ",
      "      ah dddd   ",
      "       h        ",
      "      ah        ",
      "       h        ",
      "      ahc       "
    ],
    [
      "                ",
      "                ",
      "                ",
      "                ",
      "                ",
      "        a a a a ",
      "       bhhhhhhhh",
      "      ahcddd  ee",
      "       hd   dkje",
      "      ahd   d f ",
      "       hd   d   ",
      "      ah dddd   ",
      "       h        ",
      "      ah        ",
      "       h        ",
      "      ahc       "
    ],
    [
      "                ",
      "                ",
      "                ",
      "                ",
      "                ",
      "        a a a a ",
      "       bhhhhhhhh",
      "      ahcddd ee ",
      "       hd   d e ",
      "      ahd   dlm ",
      "       hd   d   ",
      "      ah dddd   ",
      "       h        ",
      "      ah        ",
      "       h        ",
      "      ahc       "
    ],
    [
      "                ",
      "                ",
      "                ",
      "                ",
      "                ",
      "        a a a a ",
      "       bhhhhhhhh",
      "      ahcddd    ",
      "       hd   d   ",
      "      ahd   di  ",
      "       hd   dlm ",
      "      ahndddd   ",
      "       hoppppppq",
      "      ahoppppppq",
      "       hoppppppq",
      "      ahcppppppq"
    ]
  ]
}