{
  "name": "multi_casino_2_floor23",
  "refpalette": "deceasedcraft:multi_casino_2/multi_casino_2_floor23_palette",
  "xsize": 16,
  "zsize": 16,
  "slices": [
    [
      "                ",
      "                ",
      "                ",
      "                ",
      "                ",
      "        a a a a ",
      "       bbbbbbbbb",
      "      abcddd    ",
      "       bd   d   ",
      "      abd   d   ",
      "       bd   d   ",
      "      ab dddd  e",
      "       b      fg",
      "      ab      eg",
      "       b       f",
      "      abc       "
    ],
    [
      "                ",
      "                ",
      "                ",
      "                ",
      "                ",
      "        a a a a ",
      "       bhhhhhhhh",
      "      ahcddd    ",
      "       hd   d  i",
      "      aha   d  i",
      "       hd   d  i",
      "      ah dddd  i",
      "       h       f",
      "      ah       e",
      "       h       i",
      "      ahc      i"
    ],
    [
      "                ",
      "                ",
      "                ",
      "                ",
      "                ",
      "        a a a a ",
      "       bhhhhhhhh",
      "      ahcddd    ",
      "       hd   d   ",
      "      aha   d   ",
      "       hd   d   ",
      "      ah dddd   ",
      "       h        ",
      "      ah        ",
      "       h        ",
      "      ahc       "
    ],
    [
      "                ",
      "                ",
      "                ",
      "                ",
      "                ",
      "        a a a a ",
      "       bhhhhhhhh",
      "      ahcddd    ",
      "       hd   d   ",
      "      ahd   d   ",
      "       hd   d   ",
      "      ah dddd   ",
      "       h        ",
      "      ah        ",
      "       h        ",
      "      ahc       "
    ],
    [
      "                ",
      "                ",
      "                ",
      "                ",
      "                ",
      "        a a a a ",
      "       bhhhhhhhh",
      "      ahcddd    ",
      "       hd   d   ",
      "      ahd   d   ",
      "       hd   d   ",
      "      ah dddd   ",
      "       h        ",
      "      ah        ",
      "       h        ",
      "      ahc       "
    ],
    [
      "                ",
      "                ",
      "                ",
      "                ",
      "                ",
      "        a a a a ",
      "       bhhhhhhhh",
      "      ahcdddjkkk",
      "       hd   lmmm",
      "      ahd   dmmm",
      "       hd   dmmm",
      "      ah!ddddmmm",
      "       hkmmmmmmm",
      "      ahkmmmmmmm",
      "       hkmmmmmmm",
      "      ahcmmmmmmm"
    ]
  ]
}