{
  "name": "multi_casino_2_floor17",
  "refpalette": "deceasedcraft:multi_casino_2/multi_casino_2_floor17_palette",
  "xsize": 16,
  "zsize": 16,
  "slices": [
    [
      "                ",
      "                ",
      "                ",
      "                ",
      "                ",
      "        a a a a ",
      "       bbcdcdcdc",
      "      abeeeef   ",
      "       ce   e   ",
      "      age   e   ",
      "       ce   e   ",
      "      agfeeee   ",
      "       c        ",
      "      ag        ",
      "       c        ",
      "      ag        "
    ],
    [
      "                ",
      "                ",
      "                ",
      "                ",
      "                ",
      "        a a a a ",
      "       bccdcdcdc",
      "      aceeeef   ",
      "       ce   e   ",
      "      aga   e   ",
      "       ce   e   ",
      "      agfeeee   ",
      "       c        ",
      "      ag        ",
      "       c        ",
      "      ag        "
    ],
    [
      "                ",
      "                ",
      "                ",
      "                ",
      "                ",
      "        a a a a ",
      "       bccdcdcdc",
      "      aceeef f  ",
      "       ce   e   ",
      "      aga   e   ",
      "       cf   e   ",
      "      ag eeee   ",
      "       cf       ",
      "      ag        ",
      "       c        ",
      "      ag        "
    ],
    [
      "                ",
      "                ",
      "                ",
      "                ",
      "                ",
      "        a a a a ",
      "       bcchchchc",
      "      aceefe  f ",
      "       ce   e   ",
      "      aif   e   ",
      "       ce   e   ",
      "      ai eeee   ",
      "       c        ",
      "      aif       ",
      "       c        ",
      "      ai        "
    ],
    [
      "                ",
      "                ",
      "                ",
      "                ",
      "                ",
      "        a a a a ",
      "       bcccccccc",
      "      aceefe  f ",
      "       ce   e   ",
      "      acf   e   ",
      "       ce   e   ",
      "      ac eeee   ",
      "       c        ",
      "      acf       ",
      "       c        ",
      "      ac        "
    ],
    [
      "                ",
      "                ",
      "                ",
      "                ",
      "                ",
      "        a a a a ",
      "       bcccccccc",
      "      ac feejkkf",
      "       cf   lmmm",
      "      ace   emmm",
      "       ce   emmm",
      "      ackeeeemmm",
      "       ckmmmmmmm",
      "      ackmmmmmmm",
      "       cfmmmmmmm",
      "      acnmmmmmmm"
    ]
  ]
}