{
  "name": "multi_casino_2_floor4",
  "refpalette": "deceasedcraft:multi_casino_2/multi_casino_2_floor4_palette",
  "xsize": 16,
  "zsize": 16,
  "slices": [
    [
      "                ",
      "      abbbabbbab",
      "      b         ",
      "      b cccccccc",
      "      b cccccccc",
      "      a cccccccc",
      "      b cccccccc",
      "      b deeecccc",
      "      b e    ccc",
      "      a e   fccc",
      "      b e   fccc",
      "      b ceeeeccc",
      "      b cccccccc",
      "      a cccccccc",
      "      b cccccccc",
      "      b cccccccc"
    ],
    [
      "                ",
      "      abbbabbbab",
      "      bggggggggg",
      "      bghi  jklm",
      "      bghi      ",
      "      aghi    mm",
      "      bghi     n",
      "      bgdeeeo   ",
      "      bge   ep  ",
      "      age   qr  ",
      "      bge   qs  ",
      "      bgoeeee   ",
      "      bg    t   ",
      "      ag   uuu  ",
      "      bg  wxuyA ",
      "      bgo  yux  "
    ],
    [
      "                ",
      "      abbbabbbab",
      "      bggggggggg",
      "      bgB   Ck  ",
      "      bgB       ",
      "      agB       ",
      "      bgB       ",
      "      bgedeeB   ",
      "      bgd   e   ",
      "      age    D  ",
      "      bge    E  ",
      "      bgBeeee   ",
      "      bg        ",
      "      ag        ",
      "      bg        ",
      "      bgB       "
    ],
    [
      "                ",
      "      abbbabbbab",
      "      bggggggggg",
      "      bgF   IkJK",
      "      bgF       ",
      "      agF       ",
      "      bgF       ",
      "      bgeedeL   ",
      "      bge   e   ",
      "      agd   MN  ",
      "      bge   MN  ",
      "      bgLeeee   ",
      "      bg        ",
      "      ag        ",
      "      bg        ",
      "      bgL       "
    ],
    [
      "                ",
      "      abbbabbbab",
      "      bggggggggg",
      "      bgF     O ",
      "      bg!       ",
      "      agF       ",
      "      bgF       ",
      "      bgeede    ",
      "      bge   e   ",
      "      agd   e   ",
      "      bge   e   ",
      "      bg eeee   ",
      "      bg        ",
      "      ag        ",
      "      bg        ",
      "      bg        "
    ],
    [
      "                ",
      "      abbbabbbab",
      "      bggggggggg",
      "      bgF       ",
      "      bgF       ",
      "      agF       ",
      "      bgF       ",
      "      bgeeed    ",
      "      bge   e   ",
      "      age   e   ",
      "      bgd   e   ",
      "      bg eeee   ",
      "      bg        ",
      "      ag        ",
      "      bg        ",
      "      bg        "
    ]
  ]
}