{
  "name": "multi_casino_2_floor16",
  "refpalette": "deceasedcraft:multi_casino_2/multi_casino_2_floor16_palette",
  "xsize": 16,
  "zsize": 16,
  "slices": [
    [
      "                ",
      "                ",
      "                ",
      "                ",
      "                ",
      "        a a a a ",
      "       bbbbbbbbb",
      "      abcdddeeee",
      "       bd    eee",
      "      abd   feee",
      "       bd   feee",
      "      abeddddeee",
      "       beeeeeeee",
      "      abeeeeeeee",
      "       beeeeeeee",
      "      abeeeeeeee"
    ],
    [
      "                ",
      "                ",
      "                ",
      "                ",
      "                ",
      "        a a a a ",
      "       bgggggggg",
      "      agcdddh   ",
      "       gd   di  ",
      "      aga   jk  ",
      "       gd   jl  ",
      "      aghdddd   ",
      "       g m n   o",
      "      ag pqrs tq",
      "       g pqrs  u",
      "      ag w x    "
    ],
    [
      "                ",
      "                ",
      "                ",
      "                ",
      "                ",
      "        a a a a ",
      "       bgggggggg",
      "      agdcddy   ",
      "       gc   d   ",
      "      aga    A  ",
      "       gd    B  ",
      "      agydddd   ",
      "       g        ",
      "      ag  C y   ",
      "       g  D y   ",
      "      ag        "
    ],
    [
      "                ",
      "                ",
      "                ",
      "                ",
      "                ",
      "        a a a a ",
      "       bggEgEgEg",
      "      agddcdF   ",
      "       gd   d   ",
      "      aIc   JK  ",
      "       gd   JK  ",
      "      aIFdddd   ",
      "       g        ",
      "      aI        ",
      "       g        ",
      "      aI        "
    ],
    [
      "                ",
      "                ",
      "                ",
      "                ",
      "                ",
      "        a a a a ",
      "       bggEgEgEg",
      "      agddcd    ",
      "       gd   d   ",
      "      aIc   d   ",
      "       gd   d   ",
      "      aI dddd   ",
      "       g        ",
      "      aI        ",
      "       g        ",
      "      aI        "
    ],
    [
      "                ",
      "                ",
      "                ",
      "                ",
      "                ",
      "        a a a a ",
      "       bggEgEgEg",
      "      agdddc    ",
      "       gd   d   ",
      "      aId   d   ",
      "       gc   d   ",
      "      aI dddd   ",
      "       g        ",
      "      aI        ",
      "       g        ",
      "      aI        "
    ]
  ]
}