{
  "name": "multi_casino_2_base2",
  "refpalette": "deceasedcraft:multi_casino_2/multi_casino_2_base2_palette",
  "xsize": 16,
  "zsize": 16,
  "slices": [
    [
      "vaabcdefffffffff",
      "vaabcdefffffffff",
      "vaabcdefffffffff",
      "vaabgdefffffffff",
      "vaabcdefffffffff",
      "vaabcdefffffffff",
      "vaabcdefffffffff",
      "vaabcdefhiiiffff",
      "vaabcdedi    fff",
      "vaabcdedi   jfff",
      "vaabcdedi   jfff",
      "vaabgdeddiiiifff",
      "vaabcdeddddddfff",
      "vaabcdeddddddfff",
      "vaabcdeddddddfff",
      "vaabcdeddddddfff"
    ],
    [
      "vaabk           ",
      "vaabk  l mnop l ",
      "vaabk           ",
      "vaabgq  lmnopl  ",
      "vaabk           ",
      "vaabk  l mnopl  ",
      "vaabk           ",
      "vaabk   hiiir   ",
      "vaabk   i   is  ",
      "vaabk   i   tu  ",
      "vaabk   i   tw  ",
      "vaabgq  xiiii   ",
      "vaabk   x yAB   ",
      "vaabk   xCx!B   ",
      "vaabk   xDDEB   ",
      "vaabk FIx y B   "
    ],
    [
      "vaabk     JK    ",
      "vaabk    LMMN   ",
      "vaabk     JK    ",
      "vaabg    LMMN   ",
      "vaabk     JK    ",
      "vaabk    LMMN   ",
      "vaabk      K    ",
      "vaabk   hiiiO   ",
      "vaabk   i   i   ",
      "vaabk   i    P  ",
      "vaabk   i    Q  ",
      "vaabg   xiiii   ",
      "vaabk   x R B   ",
      "vaabk   x xAB   ",
      "vaabk   xDD B   ",
      "vaabk   x R B   "
    ],
    [
      "vaabk           ",
      "vaabk    STUV   ",
      "vaabk           ",
      "vaabg    STUV   ",
      "vaabk           ",
      "vaabk    STUV   ",
      "vaabk           ",
      "vaabk   hiiiW   ",
      "vaabk   i   i   ",
      "vaabk   i   XY  ",
      "vaabk   i   XY  ",
      "vaabg   xiiii   ",
      "vaabk   x x B   ",
      "vaabk   x x B   ",
      "vaabk   xDD B   ",
      "vaabk   x x B   "
    ],
    [
      "vaabk           ",
      "vaabk     Z0    ",
      "vaabk           ",
      "vaabg     Z0    ",
      "vaabk           ",
      "vaabk     Z0    ",
      "vaabk           ",
      "vaabk   hiii    ",
      "vaabk   i   i   ",
      "vaabk   i   i   ",
      "vaabk   i   i   ",
      "vaabg   xiiii   ",
      "vaabk   x111B   ",
      "vaabk   x211B   ",
      "vaabk   x111B   ",
      "vaabk   x111B   "
    ],
    [
      "vaab            ",
      "vaabk           ",
      "vaabk           ",
      "vaabg           ",
      "vaabk           ",
      "vaab            ",
      "vaabk           ",
      "vaabk   hiii    ",
      "vaab    i   i   ",
      "vaabk   i   i   ",
      "vaabk   i   i   ",
      "vaabg   xiiii   ",
      "vaabk   x3AAB   ",
      "vaab    x3  B   ",
      "vaabk   x3AAB   ",
      "vaabk   x3  B   "
    ]
  ]
}