{
  "name": "multi_casino_2_base6",
  "refpalette": "deceasedcraft:multi_casino_2/multi_casino_2_base6_palette",
  "xsize": 16,
  "zsize": 16,
  "slices": [
    [
      "vaabcdefffffffff",
      "vaabcdefffffffff",
      "vaabcdefffffffff",
      "vaabgdefffffffff",
      "vaabcdefffffffff",
      "vaabcdefffffffff",
      "vaabcdefffffffff",
      "vaabcdefhiiiffff",
      "vaabcdedi    fff",
      "vaabcdedi   jfff",
      "vaabcdedi   jfff",
      "vaabgdeddiiiifff",
      "vaabcdeddddddfff",
      "vaabcdeddddddfff",
      "vaabcdeddddddfff",
      "vaabcdeddddddfff"
    ],
    [
      "vaabk    lmnol  ",
      "vaabk    lonml  ",
      "vaabk    lnnnl  ",
      "vaabgp    qqq   ",
      "vaabk    rq qs  ",
      "vaabk     qqq   ",
      "vaabk      t    ",
      "vaabk   hiiiu   ",
      "vaabk   i   iw  ",
      "vaabk   i   xy  ",
      "vaabk   i   xA  ",
      "vaabgp  Biiii   ",
      "vaabk   B C D   ",
      "vaabk   BEB D   ",
      "vaabk   BFF D   ",
      "vaabk IJB C D   "
    ],
    [
      "vaabk           ",
      "vaabk           ",
      "vaabk           ",
      "vaabg     K L   ",
      "vaabk      M    ",
      "vaabk           ",
      "vaabk           ",
      "vaabk   hiiiN   ",
      "vaabk   i   i   ",
      "vaabk   i    O  ",
      "vaabk   i    P  ",
      "vaabg   Biiii   ",
      "vaabk   B Q D   ",
      "vaabk   B B D   ",
      "vaabk   BFF D   ",
      "vaabk   B Q D   "
    ],
    [
      "vaabk           ",
      "vaabk           ",
      "vaabk           ",
      "vaabg           ",
      "vaabk           ",
      "vaabk           ",
      "vaabk           ",
      "vaabk   hiiiR   ",
      "vaabk   i   i   ",
      "vaabk   i   ST  ",
      "vaabk   i   ST  ",
      "vaabg   Biiii   ",
      "vaabk   B B D   ",
      "vaabk   B B D   ",
      "vaabk   BFF D   ",
      "vaabk   B B D   "
    ],
    [
      "vaabk           ",
      "vaabk           ",
      "vaabk           ",
      "vaabg           ",
      "vaabk           ",
      "vaabk           ",
      "vaabk           ",
      "vaabk   hiii    ",
      "vaabk   i   i   ",
      "vaabk   i   i   ",
      "vaabk   i   i   ",
      "vaabg   Biiii   ",
      "vaabk   BUUUD   ",
      "vaabk   BVUUD   ",
      "vaabk   BUUUD   ",
      "vaabk   BUUUD   "
    ],
    [
      "vaab            ",
      "vaabk           ",
      "vaabk           ",
      "vaabg           ",
      "vaabk           ",
      "vaab            ",
      "vaabk           ",
      "vaabk   hiii    ",
      "vaab    i   i   ",
      "vaabk   i   i   ",
      "vaabk   i   i   ",
      "vaabg   Biiii   ",
      "vaabk   BWXXD   ",
      "vaab    BW  D   ",
      "vaabk   BWXXD   ",
      "vaabk   BW  D   "
    ]
  ]
}