{
  "name": "multi_casino_2_base5",
  "refpalette": "deceasedcraft:multi_casino_2/multi_casino_2_base5_palette",
  "xsize": 16,
  "zsize": 16,
  "slices": [
    [
      "vaab            ",
      "vaab            ",
      "vaabc           ",
      "vaabd           ",
      "vaabc           ",
      "vaab            ",
      "vaab            ",
      "vaabc   efff    ",
      "vaab    f   f   ",
      "vaab    f   f   ",
      "vaabc   f   f   ",
      "vaabd   gffff   ",
      "vaabc   ghiij   ",
      "vaab    giiij   ",
      "vaab    giiij   ",
      "vaabc   giiij   "
    ],
    [
      "vaab            ",
      "vaab            ",
      "vaab            ",
      "vaabd           ",
      "vaab            ",
      "vaab            ",
      "vaab            ",
      "vaab    efff    ",
      "vaab    f   f   ",
      "vaab    f   f   ",
      "vaabc   f   f   ",
      "vaabd   gffff   ",
      "vaab    ghklm   ",
      "vaab    gn  m   ",
      "vaab    gno m   ",
      "vaab    gn pm   "
    ],
    [
      "vaab            ",
      "vaab            ",
      "vaab            ",
      "vaabd           ",
      "vaab            ",
      "vaab            ",
      "vaab    q       ",
      "vaab    efff    ",
      "vaab    f   f   ",
      "vaab    f   f   ",
      "vaab    f   f   ",
      "vaabd   gffff   ",
      "vaab    ghrsm   ",
      "vaab    gt  m   ",
      "vaab    gt  m   ",
      "vaab    go  m   "
    ],
    [
      "vaab            ",
      "vaab            ",
      "vaab            ",
      "vaabd           ",
      "vaab            ",
      "vaab            ",
      "vaab            ",
      "vaab    efff    ",
      "vaab    f   f   ",
      "vaab    f   f   ",
      "vaab    f   f   ",
      "vaabd   gffff   ",
      "vaab    ghuum   ",
      "vaab    gr  m   ",
      "vaab    g   m   ",
      "vaab    g   m   "
    ],
    [
      "vaab wwwwwwwwwwx",
      "vaab wwwwwwwwwxw",
      "vaab wwwwwwwwxww",
      "vaabdwwwywwwywww",
      "vaab xwwwwwxwwww",
      "vaab wxwwwxwwwww",
      "vaab wwxwxwwwwww",
      "vaab wwwefffywww",
      "vaab wwxf   fwww",
      "vaab wxwf   fwww",
      "vaab xwwf   fwww",
      "vaabdwwwAffffwww",
      "vaab wwwAhBCmxww",
      "vaab wwwA   mwxw",
      "vaab wwwA   mwwx",
      "vaab wwwA   mwww"
    ],
    [
      "vaabDEFFFFFFFFFe",
      "vaabDEFFFFFFFFeF",
      "vaabDEFFFFFFFeFF",
      "vaabdFFFIFFFeFFF",
      "vaabDeFFFFFeFFFF",
      "vaabDEeFFFeFFFFF",
      "vaabDEFeFeFFFFFF",
      "vaabDEFFefffIFFF",
      "vaabDEFef   JFFF",
      "vaabDEeFf   fFFF",
      "vaabDeFFf   fFFF",
      "vaabdFFFFffffFFF",
      "vaabDEFFFhFFFeFF",
      "vaabDEFFFFFFFFeF",
      "vaabDEFFFFFFFFFe",
      "vaabDEFFFFFFFFFF"
    ]
  ]
}