{
  "name": "multi_casino_2_floor6",
  "refpalette": "deceasedcraft:multi_casino_2/multi_casino_2_floor6_palette",
  "xsize": 16,
  "zsize": 16,
  "slices": [
    [
      "                ",
      "      aaaaaaaaaa",
      "      abbbbbbbbb",
      "      abcddddddd",
      "      abcddddddd",
      "      abcddddddd",
      "      abcddddddd",
      "      abefffdddd",
      "      abf    ddd",
      "      abf   gddd",
      "      abf   gddd",
      "      abcffffddd",
      "      abcddddddd",
      "      abcddddddd",
      "      abcddddddd",
      "      abeddddddd"
    ],
    [
      "                ",
      "      haaahaaaha",
      "      abbbbbbbbb",
      "      abijklmmnn",
      "      abio  mpqr",
      "      hbij s    ",
      "      abij  mt  ",
      "      abeffftu q",
      "      abf   fw  ",
      "      hbf   xy  ",
      "      abf   xA  ",
      "      abBffff   ",
      "      ab   C    ",
      "      hb  D     ",
      "      ab E      ",
      "      abe       "
    ],
    [
      "                ",
      "      haaahaaaha",
      "      abbbbbbbbb",
      "      abF IJmK  ",
      "      abF  LpM  ",
      "      hbF  NO   ",
      "      abFPQRm   ",
      "      abfefft  e",
      "      abe   f   ",
      "      hbf    S  ",
      "      abf    T  ",
      "      abFffff   ",
      "      ab        ",
      "      hb        ",
      "      abe       ",
      "      ab        "
    ],
    [
      "                ",
      "      haaahaaaha",
      "      abbbbbbbbb",
      "      abU  Vp   ",
      "      abU   u   ",
      "      hbU   m   ",
      "      abU W t   ",
      "      abffef  e ",
      "      abf   f   ",
      "      hbe   XY  ",
      "      abf   XY  ",
      "      abZffff   ",
      "      ab        ",
      "      hbe       ",
      "      ab        ",
      "      ab        "
    ],
    [
      "                ",
      "      haaahaaaha",
      "      abbbbbbbbb",
      "      abU       ",
      "      abU       ",
      "      hbU   q   ",
      "      abU       ",
      "      abffef  e ",
      "      abf   f   ",
      "      hbe   f   ",
      "      abf   f   ",
      "      ab ffff   ",
      "      ab        ",
      "      hbe       ",
      "      ab        ",
      "      ab        "
    ],
    [
      "                ",
      "      aaaaaaaaaa",
      "      abbbbbbbbb",
      "      abU       ",
      "      abU       ",
      "      abU       ",
      "      abU       ",
      "      abfffe e  ",
      "      abf   f   ",
      "      abf   f   ",
      "      abe   f   ",
      "      ab ffff   ",
      "      abe       ",
      "      ab        ",
      "      ab        ",
      "      ab        "
    ]
  ]
}