{
  "name": "multi_casino_2_floor2",
  "refpalette": "deceasedcraft:multi_casino_2/multi_casino_2_floor2_palette",
  "xsize": 16,
  "zsize": 16,
  "slices": [
    [
      "         a      ",
      "          a     ",
      "           a    ",
      "            a   ",
      "             a  ",
      "              a ",
      "               a",
      "        abbb    ",
      "        b   b  a",
      "        b   b a ",
      "        b   ba  ",
      "        bbbba   ",
      "        b  a    ",
      "        b a     ",
      "        ba      ",
      "        a       "
    ],
    [
      "     cccddeeeeee",
      "     cccdfdeeeee",
      "     cccdffdeeee",
      "     cccdfefdeee",
      "     cccdfeefdee",
      "     cccdfeeefdf",
      "     cccdfeeeefd",
      "     cccabbbeeef",
      "     cccb   befd",
      "     cccg   bfdf",
      "     cccb   bdfe",
      "     cccbbbbdfee",
      "     cccbeedfeee",
      "     cccbedfeeee",
      "     cccbdfeeeee",
      "     cccafeeeeee"
    ],
    [
      "        a       ",
      "                ",
      "                ",
      "                ",
      "                ",
      "                ",
      "        a       ",
      "        babb   a",
      "        a   b   ",
      "        g   b   ",
      "        b   b   ",
      "        bbbbb   ",
      "        b       ",
      "        b       ",
      "        a       ",
      "        b       "
    ],
    [
      "                ",
      "        a       ",
      "                ",
      "                ",
      "                ",
      "        a       ",
      "        b       ",
      "        bbab  a ",
      "        b   b   ",
      "        a   b   ",
      "        b   b   ",
      "        bbbbb   ",
      "        b       ",
      "        a       ",
      "        b       ",
      "        b       "
    ],
    [
      "                ",
      "        a       ",
      "                ",
      "                ",
      "                ",
      "        a       ",
      "        b       ",
      "        bbab  a ",
      "        b   b   ",
      "        a   b   ",
      "        b   b   ",
      "        bbbbb   ",
      "        b       ",
      "        a       ",
      "        b       ",
      "        b       "
    ],
    [
      "                ",
      "      hhhhhhhhhh",
      "      h a       ",
      "      h         ",
      "      h a       ",
      "      h b       ",
      "      h b       ",
      "      h bbba a  ",
      "      h b   b   ",
      "      h b   b   ",
      "      h a   b   ",
      "      h bbbbb   ",
      "      h a       ",
      "      h b       ",
      "      h b       ",
      "      h b       "
    ]
  ]
}