{
  "name": "multi_casino_2_floor22",
  "refpalette": "deceasedcraft:multi_casino_2/multi_casino_2_floor22_palette",
  "xsize": 16,
  "zsize": 16,
  "slices": [
    [
      "                ",
      "                ",
      "                ",
      "                ",
      "                ",
      "        a a a a ",
      "       bbbbbbbbb",
      "      abcdddeeee",
      "       bd    eee",
      "      abd   feee",
      "       bd   feee",
      "      abeddddeee",
      "       beeeeeeee",
      "      abeeeeeeee",
      "       beeeeeeee",
      "      abceeeeeee"
    ],
    [
      "                ",
      "                ",
      "                ",
      "                ",
      "                ",
      "        a a a a ",
      "       bgggggggg",
      "      agcdddh ii",
      "       gd   dj  ",
      "      aga   kl  ",
      "       gd   km  ",
      "      aghdddd   ",
      "       gnooooppp",
      "      agqooooooo",
      "       grooooooo",
      "      agcooooooo"
    ],
    [
      "                ",
      "                ",
      "                ",
      "                ",
      "                ",
      "        a a a a ",
      "       bgggggggg",
      "      agcddds   ",
      "       gd   d   ",
      "      aga    t  ",
      "       gd    u  ",
      "      agsdddd   ",
      "       g  wx    ",
      "      ag   x    ",
      "       g   w    ",
      "      agc       "
    ],
    [
      "                ",
      "                ",
      "                ",
      "                ",
      "                ",
      "        a a a a ",
      "       bgggggggg",
      "      agcdddy   ",
      "       gd   d   ",
      "      agd   AB  ",
      "       gd   AB  ",
      "      agydddd   ",
      "       g   wx   ",
      "      ag   Cx   ",
      "       g    w   ",
      "      agc       "
    ],
    [
      "                ",
      "                ",
      "                ",
      "                ",
      "                ",
      "        a a a a ",
      "       bgggggggg",
      "      agcddd    ",
      "       gd   d   ",
      "      agd   d   ",
      "       gd   d   ",
      "      ag ddddC  ",
      "       g    wx  ",
      "      ag    Cx  ",
      "       g     w  ",
      "      agc       "
    ],
    [
      "                ",
      "                ",
      "                ",
      "                ",
      "                ",
      "        a a a a ",
      "       bgggggggg",
      "      agcddd    ",
      "       gd   d   ",
      "      agd   d   ",
      "       gd   d   ",
      "      ag dddd C ",
      "       g     wx ",
      "      ag     Cx ",
      "       g      w ",
      "      agc       "
    ]
  ]
}