{
  "name": "multi_casino_2_floor12",
  "refpalette": "deceasedcraft:multi_casino_2/multi_casino_2_floor12_palette",
  "xsize": 16,
  "zsize": 16,
  "slices": [
    [
      "                ",
      "       abbbbbbbb",
      "        cdeeeeee",
      "        ffffffff",
      "        ffffffff",
      "        ffffffff",
      "       gffffffff",
      "      hgieeeffff",
      "       ge    fff",
      "      hge   jfff",
      "       ge   jfff",
      "      hgkeeeefff",
      "       g llllllf",
      "      hg       l",
      "       g        ",
      "      hg        "
    ],
    [
      "                ",
      "        bbbbbbbb",
      "        cdmmmmmm",
      "        c  nop  ",
      "        c     q ",
      "        c      r",
      "       gc       ",
      "      hsieeet   ",
      "       se   eu  ",
      "      hsh   wx  ",
      "       se   wy  ",
      "      hs eeeeAA ",
      "       s      BA",
      "      hs        ",
      "       s        ",
      "      hs        "
    ],
    [
      "                ",
      "         bbbbbbb",
      "         cdmmmmm",
      "         c      ",
      "         c    C ",
      "        hc      ",
      "       gsc      ",
      "      hseieeD   ",
      "       si   e   ",
      "      hsh    E  ",
      "       se    F  ",
      "      hs eeee   ",
      "       s        ",
      "      hs        ",
      "       s        ",
      "      hs        "
    ],
    [
      "                ",
      "         abbbbbb",
      "          cdmmmm",
      "          c     ",
      "          c     ",
      "        h c     ",
      "       gssc     ",
      "      hseeieI   ",
      "       se   e   ",
      "      hsi   JK  ",
      "       se   JK  ",
      "      hs eeee   ",
      "       s        ",
      "      hs        ",
      "       s        ",
      "      hs        "
    ],
    [
      "                ",
      "          bbbbbb",
      "          cdmmmm",
      "          c     ",
      "          c     ",
      "        h c     ",
      "       gssc     ",
      "      hseeie    ",
      "       se   e   ",
      "      hsi   e   ",
      "       se   e   ",
      "      hs eeee   ",
      "       s        ",
      "      hs        ",
      "       s        ",
      "      hs        "
    ],
    [
      "                ",
      "           bbbbb",
      "           cdmmm",
      "           c    ",
      "           c    ",
      "        h hc    ",
      "       gsssc    ",
      "      hseeei    ",
      "       se   e   ",
      "      hse   e   ",
      "       si   e   ",
      "      hs eeee   ",
      "       s        ",
      "      hs        ",
      "       s        ",
      "      hs        "
    ]
  ]
}