{
  "name": "multi_casino_2_base1",
  "refpalette": "deceasedcraft:multi_casino_2/multi_casino_2_base1_palette",
  "xsize": 16,
  "zsize": 16,
  "slices": [
    [
      "vaab            ",
      "vaab            ",
      "vaabc           ",
      "vaabd           ",
      "vaabc           ",
      "vaab            ",
      "vaab            ",
      "vaabc   efff    ",
      "vaab    f   f   ",
      "vaab    f   f   ",
      "vaabc   f   f   ",
      "vaabd   gffff   ",
      "vaabc   ghiij   ",
      "vaab    giiij   ",
      "vaab    giiij   ",
      "vaabc   giiij   "
    ],
    [
      "vaab            ",
      "vaab            ",
      "vaab            ",
      "vaabd           ",
      "vaab            ",
      "vaab            ",
      "vaab            ",
      "vaab    efff    ",
      "vaab    f   f   ",
      "vaab    f   f   ",
      "vaabc   f   f   ",
      "vaabd   gffff   ",
      "vaab    ghklm   ",
      "vaab    gn  m   ",
      "vaab    gn om   ",
      "vaab    gn  m   "
    ],
    [
      "vaab            ",
      "vaab            ",
      "vaab            ",
      "vaabd           ",
      "vaab            ",
      "vaab            ",
      "vaab    p       ",
      "vaab    efff    ",
      "vaab    f   f   ",
      "vaab    f   f   ",
      "vaab    f   f   ",
      "vaabd   gffff   ",
      "vaab    ghq m   ",
      "vaab    gr  m   ",
      "vaab    gs  m   ",
      "vaab    gt  m   "
    ],
    [
      "vaab            ",
      "vaab            ",
      "vaab            ",
      "vaabd           ",
      "vaab            ",
      "vaab            ",
      "vaab            ",
      "vaab    efff    ",
      "vaab    f   f   ",
      "vaab    f   f   ",
      "vaab    f   f   ",
      "vaabd   gffff   ",
      "vaab    ghuum   ",
      "vaab    gs  m   ",
      "vaab    g   m   ",
      "vaab    g   m   "
    ],
    [
      "vaab wwwwwwwwwwx",
      "vaab wwwwwwwwwxw",
      "vaab wwwwwwwwxww",
      "vaabdwwwywwwywww",
      "vaab xwwwwwxwwww",
      "vaab wxwwwxwwwww",
      "vaab wwxwxwwwwww",
      "vaab wwwefffywww",
      "vaab wwxf   fwww",
      "vaab wxwf   fwww",
      "vaab xwwf   fwww",
      "vaabdwwwAffffwww",
      "vaab wwwAhB mxww",
      "vaab wwwA   mwxw",
      "vaab wwwA   mwwx",
      "vaab wwwA   mwww"
    ],
    [
      "vaabCDEEEEEEEEEe",
      "vaabCDEEEEEEEEeE",
      "vaabCDEEEEEEEeEE",
      "vaabdEEEFEEEeEEE",
      "vaabCeEEEEEeEEEE",
      "vaabCDeEEEeEEEEE",
      "vaabCDEeEeEEEEEE",
      "vaabCDEEefffFEEE",
      "vaabCDEef   IEEE",
      "vaabCDeEf   fEEE",
      "vaabCeEEf   fEEE",
      "vaabdEEEEffffEEE",
      "vaabCDEEEhEEEeEE",
      "vaabCDEEEEEEEEeE",
      "vaabCDEEEEEEEEEe",
      "vaabCDEEEEEEEEEE"
    ]
  ]
}