{
  "name": "multi_casino_2_floor7",
  "refpalette": "deceasedcraft:multi_casino_2/multi_casino_2_floor7_palette",
  "xsize": 16,
  "zsize": 16,
  "slices": [
    [
      "                ",
      "      aaaaaaaaaa",
      "      abbbbbbbbb",
      "      abc       ",
      "      abc       ",
      "      abc       ",
      "      abc       ",
      "      abdddde   ",
      "      abd   d   ",
      "      abd   d   ",
      "      abd   d   ",
      "      abedddd   ",
      "      ab        ",
      "      ab        ",
      "      ab        ",
      "      ab        "
    ],
    [
      "                ",
      "      aafaaafaaa",
      "      abbbbbbbbb",
      "      fbc       ",
      "      abc       ",
      "      abc       ",
      "      abc       ",
      "      fbdddde   ",
      "      abd   d   ",
      "      abd   d   ",
      "      abd   d   ",
      "      fbedddd   ",
      "      ab        ",
      "      ab        ",
      "      ab        ",
      "      fb        "
    ],
    [
      "                ",
      "      aafaaafaaa",
      "      abbbbbbbbb",
      "      fbc       ",
      "      abc       ",
      "      ab        ",
      "      abc       ",
      "      fbddde    ",
      "      abd   d   ",
      "      abd   d   ",
      "      abe   d   ",
      "      fb dddd   ",
      "      ab        ",
      "      ab        ",
      "      ab        ",
      "      fb        "
    ],
    [
      "                ",
      "      aafaaafaaa",
      "      abbbbbbbbb",
      "      fbc       ",
      "      ab        ",
      "      ab        ",
      "      abc       ",
      "      fbdded    ",
      "      abd   d   ",
      "      abe   d   ",
      "      abd   d   ",
      "      fb dddd   ",
      "      ab        ",
      "      ab        ",
      "      ab        ",
      "      fb        "
    ],
    [
      "                ",
      "      aaaaaaaaaa",
      "      abbbbbbbbb",
      "      ab        ",
      "      ab        ",
      "      ab        ",
      "      ab        ",
      "      abdded    ",
      "      abd   d   ",
      "      abe   d   ",
      "      abd   d   ",
      "      ab dddd   ",
      "      ab        ",
      "      ab        ",
      "      ab        ",
      "      ab        "
    ],
    [
      "                ",
      "      aaaaaaaaaa",
      "      abbbbbbbbg",
      "      abh       ",
      "      abh       ",
      "      abh       ",
      "      abh       ",
      "      abdeddi   ",
      "      abe   jk  ",
      "      abd   dk  ",
      "      abd   dk  ",
      "      ablddddk  ",
      "      ab mmmm   ",
      "      ab        ",
      "      ab        ",
      "      ag        "
    ]
  ]
}