{
  "name": "multi_casino_2_floor3",
  "refpalette": "deceasedcraft:multi_casino_2/multi_casino_2_floor3_palette",
  "xsize": 16,
  "zsize": 16,
  "slices": [
    [
      "                ",
      "      aabaaabaaa",
      "      a         ",
      "      b c       ",
      "      a d       ",
      "      a d       ",
      "      a d       ",
      "      b ddddceee",
      "      a d   deee",
      "      a d   deee",
      "      a d   deee",
      "      b cddddeee",
      "      a deeeeeee",
      "      a deeeeeee",
      "      a deeeeeee",
      "      b deeeeeee"
    ],
    [
      "                ",
      "      aabaaabaaa",
      "      a         ",
      "      b c       ",
      "      a d       ",
      "      a d       ",
      "      a d       ",
      "      b ddddc   ",
      "      a d   dddd",
      "      a d   d   ",
      "      a d   df f",
      "      b cddddddd",
      "      a d       ",
      "      a dghijk  ",
      "      a dlmnop  ",
      "      b dqrstu  "
    ],
    [
      "                ",
      "      aabaaabaaa",
      "      a         ",
      "      b         ",
      "      a c       ",
      "      a d       ",
      "      a d       ",
      "      b dddc    ",
      "      a d   dddd",
      "      a d   dw w",
      "      a c   dx x",
      "      b dddddddd",
      "      a d       ",
      "      a dyABCD  ",
      "      a dEFIJK  ",
      "      b dLMNOP  "
    ],
    [
      "                ",
      "      aabaaabaaa",
      "      a         ",
      "      b         ",
      "      a         ",
      "      a c       ",
      "      a d       ",
      "      b ddcd    ",
      "      a d   dddd",
      "      a c   d   ",
      "      a d   dx x",
      "      b dddddddd",
      "      a d       ",
      "      a dQ R    ",
      "      a dSTUV   ",
      "      b dW X    "
    ],
    [
      "                ",
      "      aabaaabaaa",
      "      a         ",
      "      b         ",
      "      a         ",
      "      a c       ",
      "      a d       ",
      "      b ddcd    ",
      "      a d   dddd",
      "      a c   d   ",
      "      a d   d   ",
      "      b dddddddd",
      "      a d       ",
      "      a d       ",
      "      a d       ",
      "      b d       "
    ],
    [
      "                ",
      "      bababababa",
      "      a         ",
      "      b         ",
      "      a         ",
      "      b         ",
      "      a c       ",
      "      b dcddY   ",
      "      a c   Zd00",
      "      b d   d1  ",
      "      a d   d2  ",
      "      b dddddddd",
      "      a d1212121",
      "      b d       ",
      "      a d       ",
      "      b d       "
    ]
  ]
}