{
  "name": "multi_casino_2_base8",
  "refpalette": "deceasedcraft:multi_casino_2/multi_casino_2_base8_palette",
  "xsize": 16,
  "zsize": 16,
  "slices": [
    [
      "vaabcdefffffffff",
      "vaabcdefffffffff",
      "vaabcdefffffffff",
      "vaabgdefffffffff",
      "vaabcdefffffffff",
      "vaabcdefffffffff",
      "vaabcdefffffffff",
      "vaabcdefhiiiffff",
      "vaabcdedi    fff",
      "vaabcdedi   jfff",
      "vaabcdedi   jfff",
      "vaabgdeddiiiifff",
      "vaabcdeddddddfff",
      "vaabcdeddddddfff",
      "vaabcdeddddddfff",
      "vaabcdeddddddfff"
    ],
    [
      "vaabk   l   l   ",
      "vaabk           ",
      "vaabk           ",
      "vaabgm          ",
      "vaabk           ",
      "vaabk           ",
      "vaabk           ",
      "vaabk   hiiin   ",
      "vaabk   i   io  ",
      "vaabk   i   pq  ",
      "vaabk   i   pr  ",
      "vaabgm  siiii   ",
      "vaabk   s t u   ",
      "vaabk   sws u   ",
      "vaabk  xsyy u   ",
      "vaabk  As t u   "
    ],
    [
      "vaabk           ",
      "vaabk           ",
      "vaabk           ",
      "vaabg           ",
      "vaabk           ",
      "vaabk           ",
      "vaabk           ",
      "vaabk   hiiiB   ",
      "vaabk   i   i   ",
      "vaabk   i    C  ",
      "vaabk   i    D  ",
      "vaabg   siiii   ",
      "vaabk   s E u   ",
      "vaabk   s s u   ",
      "vaabk   syy u   ",
      "vaabk   s E u   "
    ],
    [
      "vaabk           ",
      "vaabk           ",
      "vaabk           ",
      "vaabg           ",
      "vaabk           ",
      "vaabk           ",
      "vaabk           ",
      "vaabk   hiiiF   ",
      "vaabk   i   i   ",
      "vaabk   i   IJ  ",
      "vaabk   i   IJ  ",
      "vaabg   siiii   ",
      "vaabk   s s u   ",
      "vaabk   s s u   ",
      "vaabk   syy u   ",
      "vaabk   s s u   "
    ],
    [
      "vaabk           ",
      "vaabk           ",
      "vaabk           ",
      "vaabg           ",
      "vaabk           ",
      "vaabk           ",
      "vaabk           ",
      "vaabk   hiii    ",
      "vaabk   i   i   ",
      "vaabk   i   i   ",
      "vaabk   i   i   ",
      "vaabg   siiii   ",
      "vaabk   sKKKu   ",
      "vaabk   sLKKu   ",
      "vaabk   sKKKu   ",
      "vaabk   sKKKu   "
    ],
    [
      "vaab            ",
      "vaabk           ",
      "vaabk           ",
      "vaabg           ",
      "vaabk           ",
      "vaab            ",
      "vaabk           ",
      "vaabk   hiii    ",
      "vaab    i   i   ",
      "vaabk   i   i   ",
      "vaabk   i   i   ",
      "vaabg   siiii   ",
      "vaabk   sMNNu   ",
      "vaab    sM  u   ",
      "vaabk   sMNNu   ",
      "vaabk   sM  u   "
    ]
  ]
}