{
  "name": "multi_casino_2_floor24",
  "refpalette": "deceasedcraft:multi_casino_2/multi_casino_2_floor24_palette",
  "xsize": 16,
  "zsize": 16,
  "slices": [
    [
      "                ",
      "                ",
      "                ",
      "                ",
      "                ",
      "        a a a a ",
      "       bbbbbbbbb",
      "      abcdddeeee",
      "       bd    eee",
      "      abd   feee",
      "       bd   feee",
      "      abeddddeee",
      "       beeeeeeee",
      "      abeeeeeeee",
      "       beeeeeeee",
      "      abceeeeeee"
    ],
    [
      "                ",
      "                ",
      "                ",
      "                ",
      "                ",
      "        a a a a ",
      "       bgggggggg",
      "      agcdddhijj",
      "       gd   dk  ",
      "      aga   lm  ",
      "       gd   ln  ",
      "      aghdddd   ",
      "       goppppqqq",
      "      agrppppppp",
      "       gsppppppp",
      "      agcppppppp"
    ],
    [
      "                ",
      "                ",
      "                ",
      "                ",
      "                ",
      "        a a a a ",
      "       bgggggggg",
      "      agcdddt   ",
      "       gd   d   ",
      "      aga    u  ",
      "       gd    w  ",
      "      agtdddd   ",
      "       g  xy    ",
      "      ag   y    ",
      "       g   x    ",
      "      agc       "
    ],
    [
      "                ",
      "                ",
      "                ",
      "                ",
      "                ",
      "        a a a a ",
      "       bgggggggg",
      "      agcdddA   ",
      "       gd   d   ",
      "      agd   BC  ",
      "       gd   BC  ",
      "      agAdddd   ",
      "       g   xy   ",
      "      ag   Dy   ",
      "       g    x   ",
      "      agc       "
    ],
    [
      "                ",
      "                ",
      "                ",
      "                ",
      "                ",
      "        a a a a ",
      "       bgggggggg",
      "      agcddd    ",
      "       gd   d   ",
      "      agd   d   ",
      "       gd   d   ",
      "      ag ddddD  ",
      "       g    xy  ",
      "      ag    Dy  ",
      "       g     x  ",
      "      agc       "
    ],
    [
      "                ",
      "                ",
      "                ",
      "                ",
      "                ",
      "        a a a a ",
      "       bgggggggg",
      "      agcddd    ",
      "       gd   d   ",
      "      agd   d   ",
      "       gd   d   ",
      "      ag dddd D ",
      "       g     xy ",
      "      ag     Dy ",
      "       g      x ",
      "      agc       "
    ]
  ]
}