{
  "name": "multi_casino_2_base7",
  "refpalette": "deceasedcraft:multi_casino_2/multi_casino_2_base7_palette",
  "xsize": 16,
  "zsize": 16,
  "slices": [
    [
      "vaab            ",
      "vaab            ",
      "vaabc           ",
      "vaabd           ",
      "vaabc           ",
      "vaab            ",
      "vaab            ",
      "vaabc   efff    ",
      "vaab    f   f   ",
      "vaab    f   f   ",
      "vaabc   f   f   ",
      "vaabd   gffff   ",
      "vaabc   ghiij   ",
      "vaab    giiij   ",
      "vaab    giiij   ",
      "vaabc   giiij   "
    ],
    [
      "vaab            ",
      "vaab            ",
      "vaab            ",
      "vaabd           ",
      "vaab            ",
      "vaab            ",
      "vaab            ",
      "vaab    efff    ",
      "vaab    f   f   ",
      "vaab    f   f   ",
      "vaabc   f   f   ",
      "vaabd   gffff   ",
      "vaab    ghklm   ",
      "vaab    gnopm   ",
      "vaab    gnq m   ",
      "vaab    gn  m   "
    ],
    [
      "vaab            ",
      "vaab            ",
      "vaab            ",
      "vaabd           ",
      "vaab            ",
      "vaab            ",
      "vaab    r       ",
      "vaab    efff    ",
      "vaab    f   f   ",
      "vaab    f   f   ",
      "vaab    f   f   ",
      "vaabd   gffff   ",
      "vaab    ghs m   ",
      "vaab    go  m   ",
      "vaab    go  m   ",
      "vaab    gt  m   "
    ],
    [
      "vaab            ",
      "vaab            ",
      "vaab            ",
      "vaabd           ",
      "vaab            ",
      "vaab            ",
      "vaab            ",
      "vaab    efff    ",
      "vaab    f   f   ",
      "vaab    f   f   ",
      "vaab    f   f   ",
      "vaabd   gffff   ",
      "vaab    ghuum   ",
      "vaab    go  m   ",
      "vaab    gp  m   ",
      "vaab    g   m   "
    ],
    [
      "vaab wwwwwwwwwwx",
      "vaab wwwwwwwwwxw",
      "vaab wwwwwwwwxww",
      "vaabdwwwywwwywww",
      "vaab xwwwwwxwwww",
      "vaab wxwwwxwwwww",
      "vaab wwxwxwwwwww",
      "vaab wwwefffywww",
      "vaab wwxf   fwww",
      "vaab wxwf   fwww",
      "vaab xwwf   fwww",
      "vaabdwwwAffffwww",
      "vaab wwwAhq!mxww",
      "vaab wwwA   mwxw",
      "vaab wwwA   mwwx",
      "vaab wwwA   mwww"
    ],
    [
      "vaabBCDDDDDDDDDe",
      "vaabBCDDDDDDDDeD",
      "vaabBCDDDDDDDeDD",
      "vaabdDDDEDDDeDDD",
      "vaabBeDDDDDeDDDD",
      "vaabBCeDDDeDDDDD",
      "vaabBCDeDeDDDDDD",
      "vaabBCDDefffEDDD",
      "vaabBCDef   FDDD",
      "vaabBCeDf   fDDD",
      "vaabBeDDf   fDDD",
      "vaabdDDDDffffDDD",
      "vaabBCDDDhDDDeDD",
      "vaabBCDDDDDDDDeD",
      "vaabBCDDDDDDDDDe",
      "vaabBCDDDDDDDDDD"
    ]
  ]
}