{
  "name": "multi_casino_2_floor13",
  "refpalette": "deceasedcraft:multi_casino_2/multi_casino_2_floor13_palette",
  "xsize": 16,
  "zsize": 16,
  "slices": [
    [
      "                ",
      "           abbbb",
      "            cdee",
      "            c   ",
      "            c   ",
      "        f f c   ",
      "       gggggc   ",
      "      fghhhhi   ",
      "       gh   h   ",
      "      fgh   h   ",
      "       gh   h   ",
      "      fgihhhh   ",
      "       g        ",
      "      fg        ",
      "       g        ",
      "      fg        "
    ],
    [
      "                ",
      "            bbbb",
      "            cdee",
      "            c   ",
      "            c   ",
      "        f f c   ",
      "       gjjjjc   ",
      "      fjhhhhi   ",
      "       jh   h   ",
      "      fjf   h   ",
      "       jh   h   ",
      "      fjihhhh   ",
      "       j        ",
      "      fj        ",
      "       j        ",
      "      fj        "
    ],
    [
      "                ",
      "             bbb",
      "             cde",
      "             c  ",
      "             c  ",
      "        f f fc  ",
      "       gjjjjjc  ",
      "      fjhhhi i  ",
      "       jh   h   ",
      "      fjf   h   ",
      "       ji   h   ",
      "      fj hhhh   ",
      "       ji       ",
      "      fj        ",
      "       j        ",
      "      fj        "
    ],
    [
      "                ",
      "             abb",
      "              cd",
      "              c ",
      "              c ",
      "        f f f c ",
      "       gjjjjjjc ",
      "      fjhhih  i ",
      "       jh   h   ",
      "      fji   h   ",
      "       jh   h   ",
      "      fj hhhh   ",
      "       j        ",
      "      fji       ",
      "       j        ",
      "      fj        "
    ],
    [
      "                ",
      "              bb",
      "              cd",
      "              c ",
      "              c ",
      "        f f f c ",
      "       gjjjjjjc ",
      "      fjhhih  i ",
      "       jh   h   ",
      "      fji   h   ",
      "       jh   h   ",
      "      fj hhhh   ",
      "       j        ",
      "      fji       ",
      "       j        ",
      "      fj        "
    ],
    [
      "                ",
      "               b",
      "               c",
      "               c",
      "               c",
      "        f f f fc",
      "       gjjjjjjjc",
      "      fjhihhk  i",
      "       ji   lm  ",
      "      fjh   hm  ",
      "       jh   hm  ",
      "      fj hhhhm  ",
      "       j nnnn   ",
      "      fj        ",
      "       ji       ",
      "      fjo       "
    ]
  ]
}