{
  "name": "multi_casino_2_floor10",
  "refpalette": "deceasedcraft:multi_casino_2/multi_casino_2_floor10_palette",
  "xsize": 16,
  "zsize": 16,
  "slices": [
    [
      "                ",
      "      aaaaaaaa  ",
      "      abbbbbcde ",
      "      abcfffffff",
      "      abcfffffff",
      "      abcfffffff",
      "      accfffffff",
      "      adghhhffff",
      "      ijh    fff",
      "      kjh   lfff",
      "       jh   lfff",
      "      kjfhhhhfff",
      "       jffffffff",
      "      kjffffffff",
      "       jffffffff",
      "      kjgfffffff"
    ],
    [
      "                ",
      "      aaaaaaaaa ",
      "      abbbbbbcd ",
      "      abmnopppqr",
      "      abmn s s  ",
      "      abmn  s   ",
      "      acmn      ",
      "      adghhht   ",
      "       uh   h   ",
      "      kuk   wx  ",
      "       uh   wy  ",
      "      kuthhhh   ",
      "       u    A   ",
      "      ku  BCCCn ",
      "       u   DDD  ",
      "      kug EDDDF "
    ],
    [
      "                ",
      "      aaaaaaaaa ",
      "      abbbbbbcd ",
      "      abI o   q ",
      "      abI       ",
      "      acI       ",
      "      adI       ",
      "      kuhghhI  g",
      "       ug   h   ",
      "      kuk    J  ",
      "       uh    K  ",
      "      kuIhhhh   ",
      "       u        ",
      "      ku   LMN  ",
      "       ug       ",
      "      ku        "
    ],
    [
      "                ",
      "      aaaaaaaaaa",
      "      abbbbbbbcd",
      "      ab  oOPQq ",
      "      ac        ",
      "      adu       ",
      "      iju       ",
      "      kuhhghR g ",
      "       uh   h   ",
      "      kug   ST  ",
      "       uh   ST  ",
      "      kuRhhhh   ",
      "       u        ",
      "      kug       ",
      "       u        ",
      "      ku        "
    ],
    [
      "                ",
      "      aaaaaaaaaa",
      "      abbbbbbbcd",
      "      ab   U    ",
      "      ac        ",
      "      adu       ",
      "       ju       ",
      "      kuhhgh  g ",
      "       uh   h   ",
      "      kug   h   ",
      "       uh   h   ",
      "      ku hhhh   ",
      "       u        ",
      "      kug       ",
      "       u        ",
      "      ku        "
    ],
    [
      "                ",
      "      aaaaaaaaaa",
      "      abbbbbbbbc",
      "      ac        ",
      "      adu       ",
      "        u       ",
      "       ju       ",
      "      kuhhhg g  ",
      "       uh   h   ",
      "      kuh   h   ",
      "       ug   h   ",
      "      ku hhhh   ",
      "       ug       ",
      "      ku        ",
      "       u        ",
      "      ku        "
    ]
  ]
}