{
  "name": "multi_casino_2_floor28",
  "refpalette": "deceasedcraft:multi_casino_2/multi_casino_2_floor28_palette",
  "xsize": 16,
  "zsize": 16,
  "slices": [
    [
      "                ",
      "                ",
      "                ",
      "                ",
      "                ",
      "        a a a a ",
      "       bcccccccc",
      "      abdeeeffff",
      "       begg  fff",
      "      abeggghfff",
      "       beggghfff",
      "      abfeeeefff",
      "       bfiiiifff",
      "      abfiijifff",
      "       bfiijjfff",
      "      abdiijiiff"
    ],
    [
      "                ",
      "                ",
      "                ",
      "                ",
      "                ",
      "        a a a a ",
      "       bcccccccc",
      "      acdeee    ",
      "       ceklkem  ",
      "      aca   no  ",
      "       cep  nq  ",
      "      ac eeee   ",
      "       c        ",
      "      ac  r     ",
      "       c  r     ",
      "      acd       "
    ],
    [
      "                ",
      "                ",
      "                ",
      "                ",
      "                ",
      "        a a a a ",
      "       bcccccccc",
      "      acdeee    ",
      "       cekkke   ",
      "      aca    s  ",
      "       ce    t  ",
      "      ac eeee   ",
      "       c        ",
      "      ac        ",
      "       c        ",
      "      acd       "
    ],
    [
      "                ",
      "                ",
      "                ",
      "                ",
      "                ",
      "        a a a a ",
      "       bccccccc ",
      "      acdeee   d",
      "       cekkke   ",
      "      ace   u   ",
      "       ce   u   ",
      "      ac eeee   ",
      "       c        ",
      "      ac        ",
      "       cd       ",
      "      acw       "
    ],
    [
      "                ",
      "                ",
      "                ",
      "                ",
      "                ",
      "        a a a a ",
      "       bcccccca ",
      "      acdeee  d ",
      "       cexxxe   ",
      "      acexxxe   ",
      "       cexxxe   ",
      "      ac eeee   ",
      "       c        ",
      "      acd       ",
      "       c        ",
      "      ac        "
    ],
    [
      "                ",
      "                ",
      "                ",
      "                ",
      "                ",
      "        a a a   ",
      "       bccccc   ",
      "      acdyyyAd  ",
      "       cy   yB  ",
      "      acy C yB  ",
      "       cy   yB  ",
      "      acAyyyyB  ",
      "       cdDDDD   ",
      "      ac        ",
      "       c        ",
      "      ac        "
    ]
  ]
}