{
  "name": "multi_casino_2_floor11",
  "refpalette": "deceasedcraft:multi_casino_2/multi_casino_2_floor11_palette",
  "xsize": 16,
  "zsize": 16,
  "slices": [
    [
      "                ",
      "      aaaaaaaaaa",
      "      abcccccccb",
      "      ade       ",
      "      f e       ",
      "        e       ",
      "       ge       ",
      "      hgiiiij   ",
      "       gi   i   ",
      "      hgi   i   ",
      "       gi   i   ",
      "      hgjiiii   ",
      "       g        ",
      "      hg        ",
      "       g        ",
      "      hg        "
    ],
    [
      "                ",
      "      aaaaaaaaaa",
      "      abcccccccc",
      "      ade       ",
      "        e       ",
      "        e       ",
      "       ge       ",
      "      heiiiij   ",
      "       ei   i   ",
      "      heh   i   ",
      "       ei   i   ",
      "      hejiiii   ",
      "       e        ",
      "      he        ",
      "       e        ",
      "      he        "
    ],
    [
      "                ",
      "      aaaaaaaaaa",
      "      adbccccccc",
      "        e       ",
      "        e       ",
      "        e       ",
      "       ge       ",
      "      heiiij    ",
      "       ei   i   ",
      "      heh   i   ",
      "       ej   i   ",
      "      he iiii   ",
      "       e        ",
      "      he        ",
      "       e        ",
      "      he        "
    ],
    [
      "                ",
      "      aaaaaaaaaa",
      "      fdbccccccc",
      "        e       ",
      "        e       ",
      "        e       ",
      "       ge       ",
      "      heiiji    ",
      "       ei   i   ",
      "      hej   i   ",
      "       ei   i   ",
      "      he iiii   ",
      "       e        ",
      "      he        ",
      "       e        ",
      "      he        "
    ],
    [
      "                ",
      "      aaaaaaaaaa",
      "       dbccccccc",
      "        e       ",
      "        e       ",
      "        e       ",
      "       ge       ",
      "      heiiji    ",
      "       ei   i   ",
      "      hej   i   ",
      "       ei   i   ",
      "      he iiii   ",
      "       e        ",
      "      he        ",
      "       e        ",
      "      he        "
    ],
    [
      "                ",
      "       aaaaaaaaa",
      "       dbccccccc",
      "        e       ",
      "        e       ",
      "        e       ",
      "       ge       ",
      "      heijiik   ",
      "       ej   lm  ",
      "      hei   im  ",
      "       ei   im  ",
      "      he iiiim  ",
      "       e nnnn   ",
      "      he        ",
      "       e        ",
      "      he        "
    ]
  ]
}