{
  "name": "multi_casino_2_floor26",
  "refpalette": "deceasedcraft:multi_casino_2/multi_casino_2_floor26_palette",
  "xsize": 16,
  "zsize": 16,
  "slices": [
    [
      "                ",
      "                ",
      "                ",
      "                ",
      "                ",
      "        a a a a ",
      "       bbbbbbbbb",
      "      abcddd    ",
      "       bd   d   ",
      "      abd   d   ",
      "       bd   de  ",
      "      abfddddgh ",
      "       bffffffff",
      "      abffffffff",
      "       bffffffff",
      "      abcfffffff"
    ],
    [
      "                ",
      "                ",
      "                ",
      "                ",
      "                ",
      "        a a a a ",
      "       biiiiiiii",
      "      aicddd    ",
      "       id   d   ",
      "      aia   d   ",
      "       id   d   ",
      "      aijdddde  ",
      "       ik     ll",
      "      aimn o   p",
      "       iqrs t  u",
      "      aicwxxy  p"
    ],
    [
      "                ",
      "                ",
      "                ",
      "                ",
      "                ",
      "        a a a a ",
      "       biiiiiiii",
      "      aicddd    ",
      "       id   d   ",
      "      aia   d   ",
      "       id   d   ",
      "      aiAdddd   ",
      "       i        ",
      "      aiB       ",
      "       iC      !",
      "      aicDDDD   "
    ],
    [
      "                ",
      "                ",
      "                ",
      "                ",
      "                ",
      "        a a a a ",
      "       biiiiiiii",
      "      aicddd    ",
      "       id   d   ",
      "      aid   d   ",
      "       id   d   ",
      "      aiEdddd   ",
      "       i        ",
      "      ai        ",
      "       i        ",
      "      aicFIsJ   "
    ],
    [
      "                ",
      "                ",
      "                ",
      "                ",
      "                ",
      "        a a a a ",
      "       biiiiiiii",
      "      aicddd    ",
      "       id   d   ",
      "      aid   d   ",
      "       id   d   ",
      "      ai dddd   ",
      "       i        ",
      "      ai        ",
      "       i        ",
      "      aic       "
    ],
    [
      "                ",
      "                ",
      "                ",
      "                ",
      "                ",
      "        a a a a ",
      "       biiiiiiii",
      "      aicddd    ",
      "       id   d   ",
      "      aid   d   ",
      "       id   d   ",
      "      ai dddd   ",
      "       i        ",
      "      ai        ",
      "       i        ",
      "      aic       "
    ]
  ]
}