{
  "name": "multi_casino_2_floor5",
  "refpalette": "deceasedcraft:multi_casino_2/multi_casino_2_floor5_palette",
  "xsize": 16,
  "zsize": 16,
  "slices": [
    [
      "                ",
      "      ababababab",
      "      bccccccccc",
      "      acd       ",
      "      bcd       ",
      "      acd       ",
      "      bcd       ",
      "      aceeeef   ",
      "      bce   e   ",
      "      ace   e   ",
      "      bce   e   ",
      "      acfeeee   ",
      "      bc        ",
      "      ac        ",
      "      bc        ",
      "      ac        "
    ],
    [
      "                ",
      "      bbabbbabbb",
      "      bccccccccc",
      "      acd       ",
      "      bcd       ",
      "      bcd       ",
      "      bcd       ",
      "      aceeeef   ",
      "      bce   e   ",
      "      bce   e   ",
      "      bce   e   ",
      "      acfeeee   ",
      "      bc        ",
      "      bc        ",
      "      bc        ",
      "      ac        "
    ],
    [
      "                ",
      "      bbabbbabbb",
      "      bccccccccc",
      "      acd       ",
      "      bcd       ",
      "      bcd       ",
      "      bc        ",
      "      aceeef f  ",
      "      bce   e   ",
      "      bce   e   ",
      "      bcf   e   ",
      "      ac eeee   ",
      "      bcf       ",
      "      bc        ",
      "      bc        ",
      "      ac        "
    ],
    [
      "                ",
      "      bbabbbabbb",
      "      bccccccccc",
      "      ac        ",
      "      bcd       ",
      "      bc        ",
      "      bc        ",
      "      aceefe  f ",
      "      bce   e   ",
      "      bcf   e   ",
      "      bce   e   ",
      "      ac eeee   ",
      "      bc        ",
      "      bcf       ",
      "      bc        ",
      "      ac        "
    ],
    [
      "                ",
      "      bbabbbabbb",
      "      bccccccccc",
      "      ac        ",
      "      bc        ",
      "      bc        ",
      "      bc        ",
      "      aceefe  f ",
      "      bce   e   ",
      "      bcf   e   ",
      "      bce   e   ",
      "      ac eeee   ",
      "      bc        ",
      "      bcf       ",
      "      bc        ",
      "      ac        "
    ],
    [
      "                ",
      "      bbabbbabbb",
      "      bccccccccc",
      "      acg       ",
      "      bcg       ",
      "      bcg       ",
      "      bcg       ",
      "      acefeeh  f",
      "      bcf   ij  ",
      "      bce   ej  ",
      "      bce   ej  ",
      "      acgeeeej  ",
      "      bcgkkkk   ",
      "      bcg       ",
      "      bcf       ",
      "      acl       "
    ]
  ]
}