{
  "name": "multi_casino_2_floor9",
  "refpalette": "deceasedcraft:multi_casino_2/multi_casino_2_floor9_palette",
  "xsize": 16,
  "zsize": 16,
  "slices": [
    [
      "                ",
      "      aaaaaaa   ",
      "      abbbbcd e ",
      "      abf       ",
      "      abf       ",
      "      abf       ",
      "      abf       ",
      "      abggggh   ",
      "      abg   g   ",
      "      abg   g   ",
      "      acg   g   ",
      "      adhgggg   ",
      "      ij        ",
      "      kj        ",
      "       j        ",
      "      kj        "
    ],
    [
      "                ",
      "      aaaaaaa   ",
      "      abbbbcd e ",
      "      abf       ",
      "      abf       ",
      "      abf       ",
      "      abf       ",
      "      abggggh   ",
      "      abg   g   ",
      "      abg   g   ",
      "      acg   g   ",
      "      adhgggg   ",
      "       l        ",
      "      kl        ",
      "       l        ",
      "      kl        "
    ],
    [
      "                ",
      "      aaaaaaa   ",
      "      abbbbcd e ",
      "      abf       ",
      "      ab        ",
      "      abf       ",
      "      abf       ",
      "      abgggh h  ",
      "      abg   g   ",
      "      acg   g   ",
      "      adh   g   ",
      "      kl gggg   ",
      "       lh       ",
      "      kl        ",
      "       l        ",
      "      kl        "
    ],
    [
      "                ",
      "      aaaaaaa   ",
      "      abbbbcd e ",
      "      ab        ",
      "      ab        ",
      "      abf       ",
      "      ab        ",
      "      abgghg  h ",
      "      acg   g   ",
      "      adh   g   ",
      "      ilg   g   ",
      "      kl gggg   ",
      "       l        ",
      "      klh       ",
      "       l        ",
      "      kl        "
    ],
    [
      "                ",
      "      aaaaaaa   ",
      "      abbbbcd e ",
      "      ab        ",
      "      ab        ",
      "      ab        ",
      "      ab        ",
      "      abgghg  h ",
      "      acg   g   ",
      "      adh   g   ",
      "       lg   g   ",
      "      kl gggg   ",
      "       l        ",
      "      klh       ",
      "       l        ",
      "      kl        "
    ],
    [
      "                ",
      "      aaaaaaaa  ",
      "      abbbbbcde ",
      "      abm       ",
      "      abm       ",
      "      abm       ",
      "      abm       ",
      "      acghggn  h",
      "      adh   op  ",
      "      klg   gp  ",
      "       lg   gp  ",
      "      kl ggggp  ",
      "       l qqqq   ",
      "      kl        ",
      "       lh       ",
      "      klr       "
    ]
  ]
}