{
  "name": "multi_casino_2_ground",
  "refpalette": "deceasedcraft:multi_casino_2/multi_casino_2_ground_palette",
  "xsize": 16,
  "zsize": 16,
  "slices": [
    [
      "HHHHabcddddddddd",
      "HHHHabcddddddddd",
      "HHHHabcddddddddd",
      "HHHHabcddddddddd",
      "HHHHabcddddddddd",
      "HHHHabcddddddddd",
      "HHeeebcddddddddd",
      "HHeefbcdghhhdddd",
      "HHeeebcdhHHH ddd",
      "HHHHabcdhHHHiddd",
      "HHHHabcdhHHHiddd",
      "HHHHabcddhhhhddd",
      "HHHHabcddddddddd",
      "HHHHabcddddddddd",
      "HHHHabcddddddddd",
      "HHHHabcddddddddd"
    ],
    [
      "     j   k      ",
      "  lm j          ",
      "     j   n      ",
      "     j   o      ",
      "     j   k      ",
      "  pq j          ",
      "  rrrs          ",
      "  rtus  ghhhw   ",
      "  rrrs  h   hx  ",
      "  yA j  B   CD  ",
      "     j  h   CE  ",
      "   F j  hhhhh   ",
      "     j  B  I    ",
      "  lm j  B J     ",
      "     j  BK      ",
      "     j  BL      "
    ],
    [
      "                ",
      "                ",
      "                ",
      "                ",
      "                ",
      "                ",
      "        g       ",
      "   Mu   hghhN   ",
      "        g   h   ",
      "        B    O  ",
      "        h    P  ",
      "        hhhhh   ",
      "        B       ",
      "        B       ",
      "        B       ",
      "        B       "
    ],
    [
      "                ",
      "                ",
      "                ",
      "                ",
      "                ",
      "        g       ",
      "        h       ",
      "    u   hhghQ   ",
      "        h   h   ",
      "        g   RS  ",
      "        h   RS  ",
      "        hhhhh   ",
      "        h       ",
      "        B       ",
      "        B       ",
      "        B       "
    ],
    [
      "                ",
      "                ",
      "                ",
      "                ",
      "                ",
      "        g       ",
      "        h       ",
      "    u   hhgh    ",
      "        h   h   ",
      "        g   h   ",
      "        h   h   ",
      "        hhhhh   ",
      "        h       ",
      "        h       ",
      "        B       ",
      "        B       "
    ],
    [
      "                ",
      "                ",
      "                ",
      "                ",
      "        g       ",
      "        h       ",
      "        h       ",
      "    u   hhhg    ",
      "        h   h   ",
      "        h   h   ",
      "        g   h   ",
      "        hhhhh   ",
      "        h       ",
      "        h       ",
      "        B       ",
      "        B       "
    ]
  ]
}