{
  "name": "multi_casino_2_floor19",
  "refpalette": "deceasedcraft:multi_casino_2/multi_casino_2_floor19_palette",
  "xsize": 16,
  "zsize": 16,
  "slices": [
    [
      "                ",
      "                ",
      "                ",
      "                ",
      "                ",
      "        a a a a ",
      "       bbbbbbbbb",
      "      abcdddeeee",
      "       bd    fff",
      "      abd   gfff",
      "       bd   gfff",
      "      abeddddfff",
      "       befffffff",
      "      abefffffff",
      "       befffffff",
      "      abcfffffff"
    ],
    [
      "                ",
      "                ",
      "                ",
      "                ",
      "                ",
      "        a a a a ",
      "       bhhhhhhhh",
      "      ahcdddi jj",
      "       hd   dk  ",
      "      aha   lm  ",
      "       hd   ln  ",
      "      ahodddd   ",
      "       hpqrsi   ",
      "      ah t u    ",
      "       hw       ",
      "      ahcxyyAB C"
    ],
    [
      "                ",
      "                ",
      "                ",
      "                ",
      "                ",
      "        a a a a ",
      "       bhhhhhhhh",
      "      ahcdddD   ",
      "       hd   d   ",
      "      aha    E  ",
      "       hd    F  ",
      "      ahIdddd   ",
      "       hJKKKD   ",
      "      ah        ",
      "       h        ",
      "      ahcLM N   "
    ],
    [
      "                ",
      "                ",
      "                ",
      "                ",
      "                ",
      "        a a a a ",
      "       bhhhhhhhh",
      "      ahcdddO   ",
      "       hd   d   ",
      "      ahd   PQ  ",
      "       hd   PQ  ",
      "      ahRdddd   ",
      "       hJKSKO   ",
      "      ah        ",
      "       h        ",
      "      ahc       "
    ],
    [
      "                ",
      "                ",
      "                ",
      "                ",
      "                ",
      "        a a a a ",
      "       bhhhhhhhh",
      "      ahcddd    ",
      "       hd   d   ",
      "      ahd   d   ",
      "       hd   d   ",
      "      ahtdddd   ",
      "       hTwU     ",
      "      ah        ",
      "       h        ",
      "      ahc       "
    ],
    [
      "                ",
      "                ",
      "                ",
      "                ",
      "                ",
      "        a a a a ",
      "       bhhhhhhhh",
      "      ahcdddVWWW",
      "       hd   XYYY",
      "      ahd   dYYY",
      "       hd   dYYY",
      "      ahZddddYYY",
      "       hWYYYYYYY",
      "      ahWYYYYYYY",
      "       hWYYYYYYY",
      "      ahcYYYYYYY"
    ]
  ]
}