{
  "name": "multi_casino_2_floor27",
  "refpalette": "deceasedcraft:multi_casino_2/multi_casino_2_floor27_palette",
  "xsize": 16,
  "zsize": 16,
  "slices": [
    [
      "                ",
      "                ",
      "                ",
      "                ",
      "                ",
      "        a a a a ",
      "       bcccccccc",
      "      abdeee    ",
      "       be   e   ",
      "      abe   e   ",
      "       be   e   ",
      "      ab eeee   ",
      "       b        ",
      "      ab        ",
      "       b        ",
      "      abd       "
    ],
    [
      "                ",
      "                ",
      "                ",
      "                ",
      "                ",
      "        a a a a ",
      "       bcccccccc",
      "      acdeee    ",
      "       ce   e   ",
      "      aca   e   ",
      "       ce   e   ",
      "      ac eeee   ",
      "       c        ",
      "      ac        ",
      "       c        ",
      "      acd       "
    ],
    [
      "                ",
      "                ",
      "                ",
      "                ",
      "                ",
      "        a a a a ",
      "       bcccccccc",
      "      acdeee    ",
      "       ce   e   ",
      "      aca   e   ",
      "       ce   e   ",
      "      ac eeee   ",
      "       c        ",
      "      ac        ",
      "       c        ",
      "      acd       "
    ],
    [
      "                ",
      "                ",
      "                ",
      "                ",
      "                ",
      "        a a a a ",
      "       bcccccccc",
      "      acdeee    ",
      "       ce   e   ",
      "      ace   e   ",
      "       ce   e   ",
      "      ac eeee   ",
      "       c        ",
      "      ac        ",
      "       c        ",
      "      acd       "
    ],
    [
      "                ",
      "                ",
      "                ",
      "                ",
      "                ",
      "        a a a a ",
      "       bcccccccc",
      "      acdeee    ",
      "       ce   e   ",
      "      ace   e   ",
      "       ce   e   ",
      "      ac eeee   ",
      "       c        ",
      "      ac        ",
      "       c        ",
      "      acd       "
    ],
    [
      "                ",
      "                ",
      "                ",
      "                ",
      "                ",
      "        a a a a ",
      "       bcccccccc",
      "      acdeeefggg",
      "       ce   hiii",
      "      ace   eiii",
      "       ce   eiii",
      "      acjeeeeiii",
      "       cgiiiiiii",
      "      acgiiiiiii",
      "       cgiiiiiii",
      "      acdiiiiiii"
    ]
  ]
}