{
  "name": "multi_casino_2_floor21",
  "refpalette": "deceasedcraft:multi_casino_2/multi_casino_2_floor21_palette",
  "xsize": 16,
  "zsize": 16,
  "slices": [
    [
      "                ",
      "                ",
      "                ",
      "                ",
      "                ",
      "        a a a a ",
      "       bbbbbbbbb",
      "      abcdddeeee",
      "       bd    fff",
      "      abd   gfff",
      "       bd   gfff",
      "      abeddddfff",
      "       befffffff",
      "      abefffffff",
      "       befffffff",
      "      abcff!ffff"
    ],
    [
      "                ",
      "                ",
      "                ",
      "                ",
      "                ",
      "        a a a a ",
      "       bhhhhhhhh",
      "      ahcddd!ijj",
      "       hd   dk  ",
      "      aha   lm  ",
      "       hd   ln  ",
      "      ahodddd   ",
      "       hpqrst   ",
      "      ah        ",
      "       h  uw    ",
      "      ahcxyyAB C"
    ],
    [
      "                ",
      "                ",
      "                ",
      "                ",
      "                ",
      "        a a a a ",
      "       bhhhhhhhh",
      "      ahcdddD   ",
      "       hd   d   ",
      "      aha    E  ",
      "       hd    F  ",
      "      ahIdddd   ",
      "       hJKKKL   ",
      "      ah        ",
      "       h        ",
      "      ahcMN O   "
    ],
    [
      "                ",
      "                ",
      "                ",
      "                ",
      "                ",
      "        a a a a ",
      "       bhhhhhhhh",
      "      ahcddd    ",
      "       hd   d   ",
      "      ahd   PQ  ",
      "       hd   PQ  ",
      "      ahRdddd   ",
      "       hJKKKS   ",
      "      ah        ",
      "       h        ",
      "      ahc       "
    ],
    [
      "                ",
      "                ",
      "                ",
      "                ",
      "                ",
      "        a a a a ",
      "       bhhhhhhhh",
      "      ahcddd    ",
      "       hd   d   ",
      "      ahd   d   ",
      "       hd   d   ",
      "      ah dddd   ",
      "       hTU V    ",
      "      ah        ",
      "       h        ",
      "      ahc       "
    ],
    [
      "                ",
      "                ",
      "                ",
      "                ",
      "                ",
      "        a a a a ",
      "       bhhhhhhhh",
      "      ahcdddWXXX",
      "       hd   YZZZ",
      "      ahd   dZZZ",
      "       hd   dZZZ",
      "      ah0ddddZZZ",
      "       hXZZZZZZZ",
      "      ahXZZZZZZZ",
      "       hXZZZZZZZ",
      "      ahcZZZZZZZ"
    ]
  ]
}