{
  "name": "multi_nuclearpowerplant_4_base7",
  "refpalette": "deceasedcraft:multi_nuclearpowerplant_4/multi_nuclearpowerplant_4_base7_palette",
  "xsize": 16,
  "zsize": 16,
  "slices": [
    [
      "vaaabccccccccccc",
      "vaaabcccdccccccc",
      "vaaabccccccccccc",
      "vaaabccccccccccc",
      "vaaaabcccccccccc",
      "vaaaabcccccccccc",
      "vaaaabcccccccccc",
      "vaaaabcccccccccc",
      "vaaaaabccccccccc",
      "vaaaaabccccccccc",
      "vaaaaabccccccccc",
      "vaaaaaabcccccccc",
      "vaaaaaabcccccccc",
      "vaaaaaaabccccccc",
      "vaaaaaaabccccccc",
      "vaaaaaaaabcccccc"
    ],
    [
      "vaaabccccccccccc",
      "vaaabcccdccccccc",
      "vaaabccccccccccc",
      "vaaabccccccccccc",
      "vaaaabcccccccccc",
      "vaaaabcccccccccc",
      "vaaaabcccccccccc",
      "vaaaabcccccccccc",
      "vaaaaabccccccccc",
      "vaaaaabccccccccc",
      "vaaaaabccccccccc",
      "vaaaaaabcccccccc",
      "vaaaaaabcccccccc",
      "vaaaaaaabccccccc",
      "vaaaaaaabccccccc",
      "vaaaaaaaabcccccc"
    ],
    [
      "vaaabccccccccccc",
      "vaaabcccdccccccc",
      "vaaabccccccccccc",
      "vaaabccccccccccc",
      "vaaaabcccccccccc",
      "vaaaabcccccccccc",
      "vaaaabcccccccccc",
      "vaaaabcccccccccc",
      "vaaaaabccccccccc",
      "vaaaaabccccccccc",
      "vaaaaabccccccccc",
      "vaaaaaabcccccccc",
      "vaaaaaabcccccccc",
      "vaaaaaaabccccccc",
      "vaaaaaaabccccccc",
      "vaaaaaaaabcccccc"
    ],
    [
      "vaaabccccccccccc",
      "vaaabcccdccccccc",
      "vaaabccccccccccc",
      "vaaabccccccccccc",
      "vaaaabcccccccccc",
      "vaaaabcccccccccc",
      "vaaaabcccccccccc",
      "vaaaabcccccccccc",
      "vaaaaabccccccccc",
      "vaaaaabccccccccc",
      "vaaaaabccccccccc",
      "vaaaaaabcccccccc",
      "vaaaaaabcccccccc",
      "vaaaaaaabccccccc",
      "vaaaaaaabccccccc",
      "vaaaaaaaabcccccc"
    ],
    [
      "vaaabccccccccccc",
      "vaaabcccdccccccc",
      "vaaabccccccccccc",
      "vaaabccccccccccc",
      "vaaaabcccccccccc",
      "vaaaabcccccccccc",
      "vaaaabcccccccccc",
      "vaaaabcccccccccc",
      "vaaaaabccccccccc",
      "vaaaaabccccccccc",
      "vaaaaabccccccccc",
      "vaaaaaabcccccccc",
      "vaaaaaabcccccccc",
      "vaaaaaaabccccccc",
      "vaaaaaaabccccccc",
      "vaaaaaaaabcccccc"
    ],
    [
      "veeebccccccccccc",
      "veeebcccdccccccc",
      "veeebccccccccccc",
      "veeebccccccccccc",
      "veeeebcccccccccc",
      "veeeebcccccccccc",
      "veeeebcccccccccc",
      "veeeebcccccccccc",
      "veeeeebccccccccc",
      "veeeeebccccccccc",
      "veeeeebccccccccc",
      "veeeeeebcccccccc",
      "veeeeeebcccccccc",
      "veeeeeeebccccccc",
      "veeeeeeebccccccc",
      "veeeeeeeebcccccc"
    ]
  ]
}