{
  "name": "multi_nuclearpowerplant_4_base2",
  "refpalette": "deceasedcraft:multi_nuclearpowerplant_4/multi_nuclearpowerplant_4_base2_palette",
  "xsize": 16,
  "zsize": 16,
  "slices": [
    [
      "v   a           ",
      "v   a           ",
      "v   a           ",
      "v   a           ",
      "v    a          ",
      "v    a          ",
      "v    a          ",
      "v    a          ",
      "v     a         ",
      "v     a         ",
      "v     a         ",
      "v      a        ",
      "v      a        ",
      "v       a       ",
      "v       a       ",
      "v        a      "
    ],
    [
      "v   a           ",
      "v   a           ",
      "v   a           ",
      "v   a           ",
      "v    a          ",
      "v    a          ",
      "v    a          ",
      "v    a          ",
      "v     a         ",
      "v     a         ",
      "v     a         ",
      "v      a        ",
      "v      a        ",
      "v       a       ",
      "v       a       ",
      "v        a      "
    ],
    [
      "v   a           ",
      "v   a           ",
      "v   a           ",
      "v   a           ",
      "v    a          ",
      "v    a          ",
      "v    a          ",
      "v    a          ",
      "v     a         ",
      "v     a         ",
      "v     a         ",
      "v      a        ",
      "v      a        ",
      "v       a       ",
      "v       a       ",
      "v        a      "
    ],
    [
      "v   a           ",
      "v   a           ",
      "v   a           ",
      "v   a           ",
      "v    a          ",
      "v    a          ",
      "v    a          ",
      "v    a          ",
      "v     a         ",
      "v     a         ",
      "v     a         ",
      "v      a        ",
      "v      a        ",
      "v       a       ",
      "v       a       ",
      "v        a      "
    ],
    [
      "v   a           ",
      "v   a           ",
      "v   a           ",
      "v   a           ",
      "v    a          ",
      "v    a          ",
      "v    a          ",
      "v    a          ",
      "v     a         ",
      "v     a         ",
      "v     a         ",
      "v      a        ",
      "v      a        ",
      "v       a       ",
      "v       a       ",
      "v        a      "
    ],
    [
      "v   a    bbbbbbb",
      "v   a    bbbbbbb",
      "v   a    bbbbbbb",
      "v   a    bbbbbbb",
      "v    abbbbbbbbbb",
      "v    abbbbbbbbbb",
      "v    abbbbbbbbbb",
      "v    abbbbbbbbbb",
      "v     abbbbbbbbb",
      "v     abbbbbbbbb",
      "v     abbbbbbbbb",
      "v      abbbbbbbb",
      "v      abbbbbbbb",
      "v       abbbbbbb",
      "v       abbbbbbb",
      "v        abbbbbb"
    ]
  ]
}