{
  "name": "multi_nuclearpowerplant_4_base8",
  "refpalette": "deceasedcraft:multi_nuclearpowerplant_4/multi_nuclearpowerplant_4_base8_palette",
  "xsize": 16,
  "zsize": 16,
  "slices": [
    [
      "vaaabbcddddddddd",
      "vaaabbcddddddddd",
      "vaaabbcddddddddd",
      "vaaabbcddddddddd",
      "vaaabbcddddddddd",
      "vaaabbcddddddddd",
      "vaaabbcddddddddd",
      "vaaabbcddddddddd",
      "vaaabbcddddddddd",
      "vaaabbcddddddddd",
      "vaaabbcddddddddd",
      "vaaabbcddddddddd",
      "vaaabbcddddddddd",
      "vaaabbcddddddddd",
      "vaaabbcddddddddd",
      "vaaabbcddddddddd"
    ],
    [
      "vaaaefffffffffff",
      "vaaaefffffffffff",
      "vaaaefffffffffff",
      "vaaaefffffffffff",
      "vaaabeffffffffff",
      "vaaabeffffffffff",
      "vaaabeffffffffff",
      "vaaabeffffffffff",
      "vaaabbefffffffff",
      "vaaabbefffffffff",
      "vaaabbefffffffff",
      "vaaabbbeffffffff",
      "vaaabbbeffffffff",
      "vaaabbbbefffffff",
      "vaaabbbbefffffff",
      "vaaabbbbbeffffff"
    ],
    [
      "vaaaghhhhhhhhhhh",
      "vaaaghhhihhhhhhh",
      "vaaaghhhhhhhhhhh",
      "vaaaghhhhhhhhhhh",
      "vaaaaghhhhhhhhhh",
      "vaaaaghhhhhhhhhh",
      "vaaaaghhhhhhhhhh",
      "vaaaaghhhhhhhhhh",
      "vaaaaaghhhhhhhhh",
      "vaaaaaghhhhhhhhh",
      "vaaaaaghhhhhhhhh",
      "vaaaaaaghhhhhhhh",
      "vaaaaaaghhhhhhhh",
      "vaaaaaaaghhhhhhh",
      "vaaaaaaaghhhhhhh",
      "vaaaaaaaaghhhhhh"
    ],
    [
      "vaaaghhhhhhhhhhh",
      "vaaaghhhjhhhhhhh",
      "vaaaghhhhhhhhhhh",
      "vaaaghhhhhhhhhhh",
      "vaaaaghhhhhhhhhh",
      "vaaaaghhhhhhhhhh",
      "vaaaaghhhhhhhhhh",
      "vaaaaghhhhhhhhhh",
      "vaaaaaghhhhhhhhh",
      "vaaaaaghhhhhhhhh",
      "vaaaaaghhhhhhhhh",
      "vaaaaaaghhhhhhhh",
      "vaaaaaaghhhhhhhh",
      "vaaaaaaaghhhhhhh",
      "vaaaaaaaghhhhhhh",
      "vaaaaaaaaghhhhhh"
    ],
    [
      "vaaaghhhhhhhhhhh",
      "vaaaghhhjhhhhhhh",
      "vaaaghhhhhhhhhhh",
      "vaaaghhhhhhhhhhh",
      "vaaaaghhhhhhhhhh",
      "vaaaaghhhhhhhhhh",
      "vaaaaghhhhhhhhhh",
      "vaaaaghhhhhhhhhh",
      "vaaaaaghhhhhhhhh",
      "vaaaaaghhhhhhhhh",
      "vaaaaaghhhhhhhhh",
      "vaaaaaaghhhhhhhh",
      "vaaaaaaghhhhhhhh",
      "vaaaaaaaghhhhhhh",
      "vaaaaaaaghhhhhhh",
      "vaaaaaaaaghhhhhh"
    ],
    [
      "vaaaghhhhhhhhhhh",
      "vaaaghhhjhhhhhhh",
      "vaaaghhhhhhhhhhh",
      "vaaaghhhhhhhhhhh",
      "vaaaaghhhhhhhhhh",
      "vaaaaghhhhhhhhhh",
      "vaaaaghhhhhhhhhh",
      "vaaaaghhhhhhhhhh",
      "vaaaaaghhhhhhhhh",
      "vaaaaaghhhhhhhhh",
      "vaaaaaghhhhhhhhh",
      "vaaaaaaghhhhhhhh",
      "vaaaaaaghhhhhhhh",
      "vaaaaaaaghhhhhhh",
      "vaaaaaaaghhhhhhh",
      "vaaaaaaaaghhhhhh"
    ]
  ]
}