{
  "name": "multi_nuclearpowerplant_4_base1",
  "refpalette": "deceasedcraft:multi_nuclearpowerplant_4/multi_nuclearpowerplant_4_base1_palette",
  "xsize": 16,
  "zsize": 16,
  "slices": [
    [
      "vaaabccccddddddd",
      "vaaabccccddddddd",
      "vaaabccccddddddd",
      "vaaabccccddddddd",
      "vaaaabzddddddddd",
      "vaaaabzddddddddd",
      "vaaaabzddddddddd",
      "vaaaabzddddddddd",
      "vaaaaabzdddddddd",
      "vaaaaabzdddddddd",
      "vaaaaabzdddddddd",
      "vaaaaaabzddddddd",
      "vaaaaaabzddddddd",
      "vaaaaaaabzdddddd",
      "vaaaaaaabzdddddd",
      "vaaaaaaaabzddddd"
    ],
    [
      "veeefgg         ",
      "veeef           ",
      "veeef           ",
      "veeefhhhh       ",
      "veeeefi         ",
      "veeeef!jk       ",
      "veeeefj l       ",
      "veeeefi m       ",
      "veeeeefi        ",
      "veeeeefi        ",
      "veeeeefi        ",
      "veeeeeefi       ",
      "veeeeeefi       ",
      "veeeeeeefi      ",
      "veeeeeeefi      ",
      "veeeeeeeefi     "
    ],
    [
      "veeef           ",
      "veeef           ",
      "veeef           ",
      "veeef           ",
      "veeeef          ",
      "veeeef          ",
      "veeeef          ",
      "veeeef          ",
      "veeeeef         ",
      "veeeeef         ",
      "veeeeef         ",
      "veeeeeef        ",
      "veeeeeef        ",
      "veeeeeeef       ",
      "veeeeeeef       ",
      "veeeeeeeef      "
    ],
    [
      "veeef           ",
      "veeef           ",
      "veeef           ",
      "veeef           ",
      "veeeef          ",
      "veeeef          ",
      "veeeef          ",
      "veeeef          ",
      "veeeeef         ",
      "veeeeef         ",
      "veeeeef         ",
      "veeeeeef        ",
      "veeeeeef        ",
      "veeeeeeef       ",
      "veeeeeeef       ",
      "veeeeeeeef      "
    ],
    [
      "veeef           ",
      "veeef           ",
      "veeef           ",
      "veeef           ",
      "veeeef          ",
      "veeeef          ",
      "veeeef          ",
      "veeeef          ",
      "veeeeef         ",
      "veeeeef         ",
      "veeeeef         ",
      "veeeeeefn       ",
      "veeeeeef        ",
      "veeeeeeef       ",
      "veeeeeeef       ",
      "veeeeeeeef      "
    ],
    [
      "veeefo          ",
      "veeefo          ",
      "veeefo          ",
      "veeefoo         ",
      "veeeefo         ",
      "veeeefo         ",
      "veeeefo         ",
      "veeeefoo        ",
      "veeeeefo        ",
      "veeeeefo        ",
      "veeeeefoo       ",
      "veeeeeefo       ",
      "veeeeeefoo      ",
      "veeeeeeefo      ",
      "veeeeeeefoo     ",
      "veeeeeeeefo     "
    ]
  ]
}