{
  "name": "multi_nuclearpowerplant_4_base5",
  "refpalette": "deceasedcraft:multi_nuclearpowerplant_4/multi_nuclearpowerplant_4_base5_palette",
  "xsize": 16,
  "zsize": 16,
  "slices": [
    [
      "vaabcdddddde    ",
      "vaabcdddfddg    ",
      "vaabcddddddh    ",
      "vaaij           ",
      "vaaaaj          ",
      "vaaaaj          ",
      "vaaaaj          ",
      "vaaaaj          ",
      "vaaaaaj         ",
      "vaaaaaj         ",
      "vaaaaaj         ",
      "vaaaaaaj        ",
      "vaaaaaaj        ",
      "vaaaaaaaj       ",
      "vaaaaaaaj       ",
      "vaaaaaaaaj      "
    ],
    [
      "vaak llll       ",
      "vaak!           ",
      "vaak mmmmmm     ",
      "vaaij           ",
      "vaaaaj          ",
      "vaaaaj          ",
      "vaaaaj          ",
      "vaaaaj          ",
      "vaaaaaj         ",
      "vaaaaaj         ",
      "vaaaaaj         ",
      "vaaaaaaj        ",
      "vaaaaaaj        ",
      "vaaaaaaaj       ",
      "vaaaaaaaj       ",
      "vaaaaaaaaj      "
    ],
    [
      "vaan            ",
      "vaano           ",
      "vaan            ",
      "vaaij           ",
      "vaaaaj          ",
      "vaaaaj          ",
      "vaaaaj          ",
      "vaaaaj          ",
      "vaaaaaj         ",
      "vaaaaaj         ",
      "vaaaaaj         ",
      "vaaaaaaj        ",
      "vaaaaaaj        ",
      "vaaaaaaaj       ",
      "vaaaaaaaj       ",
      "vaaaaaaaaj      "
    ],
    [
      "vaap            ",
      "vaapq           ",
      "vaap            ",
      "vaaij           ",
      "vaaaaj          ",
      "vaaaaj          ",
      "vaaaaj          ",
      "vaaaaj          ",
      "vaaaaaj         ",
      "vaaaaaj         ",
      "vaaaaaj         ",
      "vaaaaaaj        ",
      "vaaaaaaj        ",
      "vaaaaaaaj       ",
      "vaaaaaaaj       ",
      "vaaaaaaaaj      "
    ],
    [
      "vaar            ",
      "vaar            ",
      "vaar            ",
      "vaaij           ",
      "vaaaaj          ",
      "vaaaaj          ",
      "vaaaaj          ",
      "vaaaaj          ",
      "vaaaaaj         ",
      "vaaaaaj         ",
      "vaaaaaj         ",
      "vaaaaaaj        ",
      "vaaaaaaj        ",
      "vaaaaaaaj       ",
      "vaaaaaaaj       ",
      "vaaaaaaaaj      "
    ],
    [
      "vaaij           ",
      "vaaij           ",
      "vaaij           ",
      "vaaij           ",
      "vaaaaj          ",
      "vaaaaj          ",
      "vaaaaj          ",
      "vaaaaj          ",
      "vaaaaaj         ",
      "vaaaaaj         ",
      "vaaaaaj         ",
      "vaaaaaaj        ",
      "vaaaaaaj        ",
      "vaaaaaaaj       ",
      "vaaaaaaaj       ",
      "vaaaaaaaaj      "
    ]
  ]
}