{
  "name": "multi_nuclearpowerplant_4_base11",
  "refpalette": "deceasedcraft:multi_nuclearpowerplant_4/multi_nuclearpowerplant_4_base11_palette",
  "xsize": 16,
  "zsize": 16,
  "slices": [
    [
      "vaaabc     d@   ",
      "vaaabce    d@   ",
      "vaaabcfggggh@   ",
      "vaaabc      @   ",
      "vaaabc      @   ",
      "vaaabc      @   ",
      "vaaabc      @   ",
      "vaaabc      @   ",
      "vaaabc      @   ",
      "vaaabcfi    @   ",
      "vaaabc      @   ",
      "vaaabc      c   ",
      "vaaabc      c   ",
      "vaaabc gggg c   ",
      "vaaabcg    gc   ",
      "vaaabcg    gc   "
    ],
    [
      "vaaabc     d@   ",
      "vaaabce    d@   ",
      "vaaabcfggggh@   ",
      "vaaabc      @   ",
      "vaaabc      @   ",
      "vaaabc      @   ",
      "vaaabc      @   ",
      "vaaabc      @   ",
      "vaaabc      @   ",
      "vaaabcfi    @   ",
      "vaaabc      @   ",
      "vaaabc      c   ",
      "vaaabc      c   ",
      "vaaabc gggg c   ",
      "vaaabcg    gc   ",
      "vaaabcg    gc   "
    ],
    [
      "vaaabc      c   ",
      "vaaabcjjjjjjc   ",
      "vaaabcfkkkklc   ",
      "vaaabcmnnnnoc   ",
      "vaaabc     oc   ",
      "vaaabc     oc   ",
      "vaaabc     oc   ",
      "vaaabc     oc   ",
      "vaaabc     oc   ",
      "vaaabcfi   oc   ",
      "vaaabc     oc   ",
      "vaaabc     pc   ",
      "vaaabc      c   ",
      "vaaabc gggg c   ",
      "vaaabcg    gc   ",
      "vaaabcg    gc   "
    ],
    [
      "vaaabc      c   ",
      "vaaabc    qrc   ",
      "vaaabcf   qsc   ",
      "vaaabc    qrc   ",
      "vaaabc      c   ",
      "vaaabc      c   ",
      "vaaabc      c   ",
      "vaaabc      c   ",
      "vaaabc    qrc   ",
      "vaaabcfi  qtc   ",
      "vaaabc    qrc   ",
      "vaaabc      c   ",
      "vaaabc      c   ",
      "vaaabc gggg c   ",
      "vaaabcg    gc   ",
      "vaaabcg    gc   "
    ],
    [
      "vaaabc      c   ",
      "vaaabc    quc   ",
      "vaaabcf   wxc   ",
      "vaaabc    qyc   ",
      "vaaabc      c   ",
      "vaaabc      c   ",
      "vaaabc      c   ",
      "vaaabc      c   ",
      "vaaabc    quc   ",
      "vaaabcfi  ABc   ",
      "vaaabc    qyc   ",
      "vaaabc      c   ",
      "vaaabc      c   ",
      "vaaabc gggg c   ",
      "vaaabcg    gc   ",
      "vaaabcg    gc   "
    ],
    [
      "vaaabc      c   ",
      "vaaabc    qrc   ",
      "vaaabcf   ACc   ",
      "vaaabc    qrc   ",
      "vaaabc      c   ",
      "vaaabc      c   ",
      "vaaabc      c   ",
      "vaaabc      c   ",
      "vaaabc    quc   ",
      "vaaabcfi   Dc   ",
      "vaaabc    qyc   ",
      "vaaabc      c   ",
      "vaaabc      c   ",
      "vaaabc gggg c   ",
      "vaaabcgbbbbgc   ",
      "vaaabcgbbbbgc   "
    ]
  ]
}