{
  "name": "multi_nuclearpowerplant_4_base6",
  "refpalette": "deceasedcraft:multi_nuclearpowerplant_4/multi_nuclearpowerplant_4_base6_palette",
  "xsize": 16,
  "zsize": 16,
  "slices": [
    [
      "vvvva           ",
      "vvvvab  c       ",
      "vvvva           ",
      "vvvva           ",
      "vvvvva          ",
      "vvvvva          ",
      "vvvvva          ",
      "vvvvva          ",
      "vvvvvva         ",
      "vvvvvva         ",
      "vvvvvva         ",
      "vvvvvvvab       ",
      "vvvvvvva        ",
      "vvvvvvvva       ",
      "vvvvvvvva       ",
      "vvvvvvvvva      "
    ],
    [
      "vddde           ",
      "vddde   f       ",
      "vddde           ",
      "vddde           ",
      "vdddde          ",
      "vdddde          ",
      "vdddde          ",
      "vdddde          ",
      "vddddde         ",
      "vddddde         ",
      "vddddde         ",
      "vdddddde        ",
      "vdddddde        ",
      "vddddddde       ",
      "vddddddde       ",
      "vdddddddde      "
    ],
    [
      "vgghe          i",
      "vgghe   f      j",
      "vgghe          k",
      "vgghe           ",
      "vgggge          ",
      "vgggge          ",
      "vgggge          ",
      "vgggge          ",
      "vggggge         ",
      "vggggge         ",
      "vggggge         ",
      "vgggggge        ",
      "vgggggge        ",
      "vggggggge       ",
      "vggggggge       ",
      "vgggggggge      "
    ],
    [
      "vggle         i ",
      "vggle   f     j ",
      "vggle         k ",
      "vggle           ",
      "vgggge          ",
      "vgggge          ",
      "vgggge          ",
      "vgggge          ",
      "vggggge         ",
      "vggggge         ",
      "vggggge         ",
      "vgggggge        ",
      "vgggggge        ",
      "vggggggge       ",
      "vggggggge       ",
      "vgggggggge      "
    ],
    [
      "vggle        i  ",
      "vggle   f    j  ",
      "vggle        k  ",
      "vggle           ",
      "vgggge          ",
      "vgggge          ",
      "vgggge          ",
      "vgggge          ",
      "vggggge         ",
      "vggggge         ",
      "vggggge         ",
      "vgggggge        ",
      "vgggggge        ",
      "vggggggge       ",
      "vggggggge       ",
      "vgggggggge      "
    ],
    [
      "vggle       i   ",
      "vggle   f   j   ",
      "vggle       k   ",
      "vggle           ",
      "vgggge          ",
      "vgggge          ",
      "vgggge          ",
      "vgggge          ",
      "vggggge         ",
      "vggggge         ",
      "vggggge         ",
      "vgggggge        ",
      "vgggggge        ",
      "vggggggge       ",
      "vggggggge       ",
      "vgggggggge      "
    ]
  ]
}