{
  "name": "multi_nuclearpowerplant_4_base3",
  "refpalette": "deceasedcraft:multi_nuclearpowerplant_4/multi_nuclearpowerplant_4_base3_palette",
  "xsize": 16,
  "zsize": 16,
  "slices": [
    [
      "vaa bcccc       ",
      "vaa bcccc       ",
      "vaa bcccc       ",
      "vaa bccccc      ",
      "vaa  bcccc      ",
      "vaa  bcccc      ",
      "vaa  bccccc     ",
      "vaa  bccccc     ",
      "vaa   bcccc     ",
      "vaa   bccccc    ",
      "vaa   bccccc    ",
      "vaa    bcccc    ",
      "vaa    bccccc   ",
      "vaa     bcccc   ",
      "vaa     bccccc  ",
      "vaa      bccccc "
    ],
    [
      "v d e   f       ",
      "v d eg  f       ",
      "v d e   f       ",
      "v d e    h      ",
      "v d  e   f      ",
      "v d  e   f      ",
      "v d  e    h     ",
      "v d  e    f     ",
      "v d   e   f     ",
      "v d   e    h    ",
      "v d   e    f    ",
      "v d    eg  f    ",
      "v d    e    h   ",
      "v d     e   f   ",
      "v d     e    h  ",
      "v d      e    h "
    ],
    [
      "v   e           ",
      "v   e           ",
      "v   e           ",
      "v   e           ",
      "v    e          ",
      "v    e          ",
      "v    e          ",
      "v    e          ",
      "v     e         ",
      "v     e         ",
      "v     e         ",
      "v      e        ",
      "v      e        ",
      "v       e       ",
      "v       e       ",
      "v        e      "
    ],
    [
      "v   e           ",
      "v   e           ",
      "v   e           ",
      "v   e           ",
      "v    e          ",
      "v    e          ",
      "v    e          ",
      "v    e          ",
      "v     e         ",
      "v     e         ",
      "v     e         ",
      "v      e        ",
      "v      e        ",
      "v       e       ",
      "v       e       ",
      "v        e      "
    ],
    [
      "v   e           ",
      "v   e           ",
      "v   e           ",
      "v   e           ",
      "v    e          ",
      "v    e          ",
      "v    e          ",
      "v    e          ",
      "v     e         ",
      "v     e         ",
      "v     e         ",
      "v      e        ",
      "v      e        ",
      "v       e       ",
      "v       e       ",
      "v        e      "
    ],
    [
      "v   e           ",
      "v   e           ",
      "v   e           ",
      "v   e           ",
      "v    e          ",
      "v    e          ",
      "v    e          ",
      "v    e          ",
      "v     e         ",
      "v     e         ",
      "v     e         ",
      "v      e        ",
      "v      e        ",
      "v       e       ",
      "v       e       ",
      "v        e      "
    ]
  ]
}