{
  "name": "multi_nuclearpowerplant_4_base10",
  "refpalette": "deceasedcraft:multi_nuclearpowerplant_4/multi_nuclearpowerplant_4_base10_palette",
  "xsize": 16,
  "zsize": 16,
  "slices": [
    [
      "vaaabcd     c   ",
      "vaaabcd   efc   ",
      "vaaabcg   ehc   ",
      "vaaabcd   efc   ",
      "vaaabcd     c   ",
      "vaaabcd     c   ",
      "vaaabcd     c   ",
      "vaaabcd     c   ",
      "vaaabcd   eic   ",
      "vaaabcgj  klc   ",
      "vaaabcd   emc   ",
      "vaaabcdnnnn c   ",
      "vaaabcdoooo c   ",
      "vaaabcobbbboc   ",
      "vaaabcbbbbbbc   ",
      "vaaabcbbbbbbc   "
    ],
    [
      "vaaabcp     c   ",
      "vaaabcp     c   ",
      "vaaabcp    qc   ",
      "vaaabcp     c   ",
      "vaaabcp     c   ",
      "vaaabcp     c   ",
      "vaaabcp     c   ",
      "vaaabcp     c   ",
      "vaaabcp   eic   ",
      "vaaabc    rsc   ",
      "vaaabcp   emc   ",
      "vaaabcp     c   ",
      "vaaabcp     c   ",
      "vaaabc      c   ",
      "vaaabc      c   ",
      "vaaabc      c   "
    ],
    [
      "vaaabc      c   ",
      "vaaabc      c   ",
      "vaaabc     qc   ",
      "vaaabc      c   ",
      "vaaabc      c   ",
      "vaaabc      c   ",
      "vaaabc      c   ",
      "vaaabc      c   ",
      "vaaabc    efc   ",
      "vaaabc    ehc   ",
      "vaaabc    efc   ",
      "vaaabc      c   ",
      "vaaabc      c   ",
      "vaaabc      c   ",
      "vaaabc      c   ",
      "vaaabc      c   "
    ],
    [
      "vaaabc      c   ",
      "vaaabc      c   ",
      "vaaabc     qc   ",
      "vaaabc      c   ",
      "vaaabc      c   ",
      "vaaabc      c   ",
      "vaaabc      c   ",
      "vaaabc      c   ",
      "vaaabc      c   ",
      "vaaabc     qc   ",
      "vaaabc      c   ",
      "vaaabc      c   ",
      "vaaabc      c   ",
      "vaaabc      c   ",
      "vaaabc      c   ",
      "vaaabc      c   "
    ],
    [
      "vaaabc      c   ",
      "vaaabc      c   ",
      "vaaabc qqqqqc   ",
      "vaaabc      c   ",
      "vaaabc      c   ",
      "vaaabc      c   ",
      "vaaabc      c   ",
      "vaaabc      c   ",
      "vaaabc      c   ",
      "vaaabc qqqqqc   ",
      "vaaabc      c   ",
      "vaaabc      c   ",
      "vaaabc      c   ",
      "vaaabc      c   ",
      "vaaabc      c   ",
      "vaaabc      c   "
    ],
    [
      "vaaabc      c   ",
      "vaaabc      c   ",
      "vaaabc q    c   ",
      "vaaabc      c   ",
      "vaaabc      c   ",
      "vaaabc      c   ",
      "vaaabc      c   ",
      "vaaabc      c   ",
      "vaaabc      c   ",
      "vaaabc q    c   ",
      "vaaabc      c   ",
      "vaaabc      c   ",
      "vaaabc      c   ",
      "vaaabc      c   ",
      "vaaabc      c   ",
      "vaaabc      c   "
    ]
  ]
}