{
  "name": "multi_nuclearpowerplant_4_base12",
  "refpalette": "deceasedcraft:multi_nuclearpowerplant_4/multi_nuclearpowerplant_4_base12_palette",
  "xsize": 16,
  "zsize": 16,
  "slices": [
    [
      "vaaaaaaaaaaaaaaa",
      "vaaaaaaaaaaaaaaa",
      "vaaaaaaaaaaaaaaa",
      "vaaaaaaaaaaaaaaa",
      "vaaaaaaaaaaaaaaa",
      "vaaaaaaaaaaaaaaa",
      "vaaaaaaaaaaaaaaa",
      "vaaaaaaaaaaaaaaa",
      "vaaaaaaaaaaaaaaa",
      "vaaaaaaaaaaaaaaa",
      "vaaaaaaaaaaaaaaa",
      "vaaaaaaaaaaaaaaa",
      "vaaaaaaaaaaaaaaa",
      "vaaaaaaaaaaaaaaa",
      "vaaaaaaaaaaaaaaa",
      "vaaaaaaaaaaaaaaa"
    ],
    [
      "vaaabbbbbbbbbbbb",
      "vaaabbbbbbbbbbbb",
      "vaaabbbbbbbbbbbb",
      "vaaabbbbbbbbbbbb",
      "vaaabbbbbbbbbbbb",
      "vaaabbbbbbbbbbbb",
      "vaaabbbbbbbbbbbb",
      "vaaabbbbbbbbbbbb",
      "vaaabbbbbbbbbbbb",
      "vaaabbbbbbbbbbbb",
      "vaaabbbbbbbbbbbb",
      "vaaabbbbbbbbbbbb",
      "vaaabbbbbbbbbbbb",
      "vaaabbbbbbbbbbbb",
      "vaaabbbbbbbbbbbb",
      "vaaabbbbbbbbbbbb"
    ],
    [
      "vaaabcddddddceee",
      "vaaabcddddddceee",
      "vaaabcddddddceee",
      "vaaabcddddddceee",
      "vaaabcddddddceee",
      "vaaabcddddddceee",
      "vaaabcddddddceee",
      "vaaabcddddddceee",
      "vaaabcddddddceee",
      "vaaabcddddddceee",
      "vaaabcddddddceee",
      "vaaabcddddddceee",
      "vaaabcdccccdceee",
      "vaaabcc====cceee",
      "vaaabc======ceee",
      "vaaabc======ceee"
    ],
    [
      "vaaabfggggggf   ",
      "vaaabfhhhhhhf   ",
      "vaaabfijjjjkf   ",
      "vaaabflmmno f   ",
      "vaaabf  p   f   ",
      "vaaabf      f   ",
      "vaaabfq   r f   ",
      "vaaabfq   s f   ",
      "vaaabfq  ts f   ",
      "vaaabfiu  s f   ",
      "vaaabfw   x f   ",
      "vaaabfyAAAABf   ",
      "vaaabf CCCC f   ",
      "vaaabfCbbbbCf   ",
      "vaaabfbbbbbbf   ",
      "vaaabfbbbbbbf   "
    ],
    [
      "vaaabf     D@   ",
      "vaaabfE    D@   ",
      "vaaabfiFFFFI@   ",
      "vaaabfJKL   @   ",
      "vaaabf      @   ",
      "vaaabf      @   ",
      "vaaabf    M @   ",
      "vaaabf    ! @   ",
      "vaaabfN   O @   ",
      "vaaabfiu  P @   ",
      "vaaabf    Q @   ",
      "vaaabf      f   ",
      "vaaabf      f   ",
      "vaaabf FFFF f   ",
      "vaaabfFbbbbFf   ",
      "vaaabfFbbbbFf   "
    ],
    [
      "vaaabf     D@   ",
      "vaaabfE    D@   ",
      "vaaabfiFFFFI@   ",
      "vaaabf      @   ",
      "vaaabf      @   ",
      "vaaabf      @   ",
      "vaaabf      @   ",
      "vaaabf      @   ",
      "vaaabf      @   ",
      "vaaabfiu    @   ",
      "vaaabf      @   ",
      "vaaabf      f   ",
      "vaaabf      f   ",
      "vaaabf FFFF f   ",
      "vaaabfF    Ff   ",
      "vaaabfF    Ff   "
    ]
  ]
}