{
  "name": "multi_nuclearpowerplant_4_base4",
  "refpalette": "deceasedcraft:multi_nuclearpowerplant_4/multi_nuclearpowerplant_4_base4_palette",
  "xsize": 16,
  "zsize": 16,
  "slices": [
    [
      "vaaab           ",
      "vaaab           ",
      "vaaab           ",
      "vaaab           ",
      "vaaaab          ",
      "vaaaab          ",
      "vaaaab          ",
      "vaaaab          ",
      "vaaaaab         ",
      "vaaaaab         ",
      "vaaaaab         ",
      "vaaaaaab        ",
      "vaaaaaab        ",
      "vaaaaaaab       ",
      "vaaaaaaab       ",
      "vaaaaaaaab      "
    ],
    [
      "vaaab           ",
      "vaaab           ",
      "vaaab           ",
      "vaaab           ",
      "vaaaab          ",
      "vaaaab          ",
      "vaaaab          ",
      "vaaaab          ",
      "vaaaaab         ",
      "vaaaaab         ",
      "vaaaaab         ",
      "vaaaaaab        ",
      "vaaaaaab        ",
      "vaaaaaaab       ",
      "vaaaaaaab       ",
      "vaaaaaaaab      "
    ],
    [
      "vaaab           ",
      "vaaab           ",
      "vaaab           ",
      "vaaab           ",
      "vaaaab          ",
      "vaaaab          ",
      "vaaaab          ",
      "vaaaab          ",
      "vaaaaab         ",
      "vaaaaab         ",
      "vaaaaab         ",
      "vaaaaaab        ",
      "vaaaaaab        ",
      "vaaaaaaab       ",
      "vaaaaaaab       ",
      "vaaaaaaaab      "
    ],
    [
      "vaaab           ",
      "vaaab           ",
      "vaaab           ",
      "vaaab           ",
      "vaaaab          ",
      "vaaaab          ",
      "vaaaab          ",
      "vaaaab          ",
      "vaaaaab         ",
      "vaaaaab         ",
      "vaaaaab         ",
      "vaaaaaab        ",
      "vaaaaaab        ",
      "vaaaaaaab       ",
      "vaaaaaaab       ",
      "vaaaaaaaab      "
    ],
    [
      "vaaab           ",
      "vaaab           ",
      "vaaab           ",
      "vaaab           ",
      "vaaaab          ",
      "vaaaab          ",
      "vaaaab          ",
      "vaaaab          ",
      "vaaaaab         ",
      "vaaaaab         ",
      "vaaaaab         ",
      "vaaaaaab        ",
      "vaaaaaab        ",
      "vaaaaaaab       ",
      "vaaaaaaab       ",
      "vaaaaaaaab      "
    ],
    [
      "vaaab           ",
      "vaaab           ",
      "vaaab           ",
      "vaaab           ",
      "vaaaab          ",
      "vaaaab          ",
      "vaaaab          ",
      "vaaaab          ",
      "vaaaaab         ",
      "vaaaaab         ",
      "vaaaaab         ",
      "vaaaaaab        ",
      "vaaaaaab        ",
      "vaaaaaaab       ",
      "vaaaaaaab       ",
      "vaaaaaaaab      "
    ]
  ]
}