{
  "name": "multi_nuclearpowerplant_4_ground",
  "refpalette": "deceasedcraft:multi_nuclearpowerplant_4/multi_nuclearpowerplant_4_ground_palette",
  "xsize": 16,
  "zsize": 16,
  "slices": [
    [
      "aaaaabc         ",
      "zaaaabc         ",
      "aaaaabcc        ",
      "aaaaabbc        ",
      "zaaaaabc        ",
      "azaaaabc        ",
      "azaaaabcc       ",
      "zaaaaabbc       ",
      "zaaaaaabc       ",
      "azaaaaabcc      ",
      "zaaaaaabbc      ",
      "zzazaaaabcc     ",
      "zaaaaaaabbc     ",
      "zzazaaaaabcc    ",
      "zazazaaaabbc    ",
      "zzaaaaaaaabcc   "
    ],
    [
      "    dzcc        ",
      "    dzccc       ",
      "    ezccc       ",
      "    ezzcc       ",
      "f    gzcc       ",
      "     dzccc      ",
      " f   ezccc      ",
      "     eazcc      ",
      "f     dzccc     ",
      "      gzccc     ",
      "f     eazccc    ",
      "       gzccc    ",
      "f      ezzccc   ",
      "f       dzccc   ",
      "f   f   ezzccc  ",
      "ff       dzcccc "
    ],
    [
      "     hzccc      ",
      "     hzccc      ",
      "     hzzcc      ",
      "     hhzccc     ",
      "      hzccc     ",
      "      hzccc     ",
      "      hzzccc    ",
      "      hhzccc    ",
      "       hzccc    ",
      "       hzzccc   ",
      "       hhzccc   ",
      "        hzzccc  ",
      "        hhzccc  ",
      "         hzzccc ",
      "         hhzcccc",
      "          hzaccc"
    ],
    [
      "     h zzcc     ",
      "     h zzccc    ",
      "     h zzccc    ",
      "     hh zccc    ",
      "      h azccc   ",
      "      h zzccc   ",
      "      h  zccc   ",
      "      hh zzccc  ",
      "       h azccc  ",
      "       hffzcccc ",
      "       hh zzccc ",
      "        hf zcccc",
      "        hhizzccc",
      "         h jzccc",
      "         hh zzcc",
      "          h  azc"
    ],
    [
      "     k f zccc   ",
      "     k  zzccc   ",
      "     k ffzzcc   ",
      "     k   zzccc  ",
      "      k   zccc  ",
      "      k ffazcc  ",
      "      k   zzccc ",
      "      k   fzccc ",
      "       k f azccc",
      "       k   zzccc",
      "       k    zzcc",
      "        k   zacc",
      "        k   fzzc",
      "         k  fzzz",
      "         k  f zz",
      "          k  ffz"
    ],
    [
      "         fzccc  ",
      "        f zzcc  ",
      "         fazccc ",
      "         f zccc ",
      "           zzccc",
      "            zccc",
      "            zccc",
      "            zzcc",
      "             zcc",
      "           fjzzc",
      "              zc",
      "            f zz",
      "             fiz",
      "               f",
      "                ",
      "                "
    ]
  ]
}