{
  "name": "multi_casino_6_floor2",
  "refpalette": "deceasedcraft:multi_casino_6/multi_casino_6_floor2_palette",
  "xsize": 16,
  "zsize": 16,
  "slices": [
    [
      "    aabcccbaa   ",
      "  aabcccccccbaa ",
      "  accccccccccca ",
      " abcccccccccccba",
      " accccccccccccca",
      "abcccccccccccccb",
      "bccccccccccccccc",
      "dccccccccccccccc",
      "bccccccccccccccc",
      "abcccccccccccccb",
      " accccccccccccca",
      " abcccccccccccba",
      "  accccccccccca ",
      "  aabcccccccbaa ",
      "    aabcccbaa   ",
      "      abdba     "
    ],
    [
      "cceefff   fffeec",
      "cefff       fffe",
      "cef           fe",
      "eff           ff",
      "ef             f",
      "ff             f",
      "f               ",
      "d               ",
      "f               ",
      "ff             f",
      "cf             f",
      "cff           ff",
      "ccf           fe",
      "ccfff       fffe",
      "ccccfff   fffeec",
      "ccccccffdffeeccc"
    ],
    [
      "    ggg d ggg   ",
      "  ggg       ggg ",
      "  g           g ",
      " gg           gg",
      " g             g",
      "gg             g",
      "g               ",
      "gd             d",
      "g               ",
      "gg             g",
      " g             g",
      " gg           gg",
      "  g           g ",
      "  ggg       ggg ",
      "    ggg d ggg   ",
      "      ggggg     "
    ],
    [
      "                ",
      "        d       ",
      "                ",
      "                ",
      "                ",
      "                ",
      "                ",
      "  d           d ",
      "                ",
      "                ",
      "                ",
      "                ",
      "                ",
      "        d       ",
      "                ",
      "                "
    ],
    [
      "                ",
      "        d       ",
      "                ",
      "                ",
      "                ",
      "                ",
      "                ",
      "  d           d ",
      "                ",
      "                ",
      "                ",
      "                ",
      "                ",
      "        d       ",
      "                ",
      "                "
    ],
    [
      "                ",
      "hhhhhhhhhhhhhhh ",
      "        d     h ",
      "              h ",
      "              h ",
      "              h ",
      "              h ",
      "   d         dh ",
      "              h ",
      "              h ",
      "              h ",
      "              h ",
      "        d     h ",
      "              h ",
      "              h ",
      "              h "
    ]
  ]
}