{
  "name": "multi_casino_6_base2",
  "refpalette": "deceasedcraft:multi_casino_6/multi_casino_6_base2_palette",
  "xsize": 16,
  "zsize": 16,
  "slices": [
    [
      "aaaabbbcddbbbaaa",
      "aabbb ecddffbbba",
      "aab   ecddf   ba",
      "abb   gbbbh   bb",
      "ab   ii j      b",
      "bb   i         b",
      "b               ",
      "b               ",
      "b               ",
      "bb             b",
      "ab             b",
      "abb           bb",
      "aab           ba",
      "aabbb       bbba",
      "aaaabbb   bbbaaa",
      "aaaaaabbbbbaaaaa"
    ],
    [
      "    iii   ggb   ",
      "  iii     eebhh ",
      "  i       ekdfh ",
      " ii   iiiiglf ii",
      " i    i   mh   i",
      "ii             i",
      "i               ",
      "i               ",
      "i               ",
      "ii             i",
      " i             i",
      " ii           ii",
      "  i           i ",
      "  iii       iii ",
      "    iii   iii   ",
      "      iiiii     "
    ],
    [
      "    i     iii   ",
      "             gg ",
      "             eg ",
      " i       ii ekbb",
      "          igclfh",
      "           nhffh",
      "                ",
      "i               ",
      "                ",
      "                ",
      "                ",
      " i             i",
      "                ",
      "                ",
      "    i       i   ",
      "        i       "
    ],
    [
      "    i       i   ",
      "            iii ",
      "              i ",
      " i            ii",
      "          ii   g",
      "           igeeg",
      "            bkkk",
      "i          obddd",
      "            bddd",
      "            hffh",
      "              fh",
      " i             i",
      "                ",
      "                ",
      "    i       i   ",
      "        i       "
    ],
    [
      "    i       i   ",
      "                ",
      "                ",
      " i             i",
      "               i",
      "           ii  i",
      "            i   ",
      "i           i   ",
      "            i   ",
      "           pgeeg",
      "           hlqeg",
      " i          fdbb",
      "             fh ",
      "             hh ",
      "    i       i   ",
      "        i       "
    ],
    [
      "    i       i   ",
      "                ",
      "                ",
      " i             i",
      "                ",
      "                ",
      "                ",
      "i               ",
      "            i   ",
      "           ii  i",
      "          rg   i",
      " i        hke  i",
      "          flqeg ",
      "          ffbgg ",
      "    i     hhb   ",
      "        i       "
    ]
  ]
}