{
  "name": "multi_casino_6_floor23",
  "refpalette": "deceasedcraft:multi_casino_6/multi_casino_6_floor23_palette",
  "xsize": 16,
  "zsize": 16,
  "slices": [
    [
      "                ",
      "                ",
      "                ",
      "                ",
      "                ",
      "a a a a a       ",
      "bbbbbbbbbb      ",
      "cdddddddcba     ",
      "dddddddddb      ",
      "dddddddddba     ",
      "dddddddddb      ",
      "dddddddddba     ",
      "dddddddddb      ",
      "dddddddddba     ",
      "dddddddddb      ",
      "ddddddddcba     "
    ],
    [
      "                ",
      "                ",
      "                ",
      "                ",
      "                ",
      "a a a a a       ",
      "eeeeeeeeeb      ",
      "c     f cea     ",
      "g      h e      ",
      "ijkl    mea     ",
      "ijkl     e      ",
      "g        ea     ",
      "        ne      ",
      "       opea     ",
      "q     r se      ",
      "q   tuuwcea     "
    ],
    [
      "                ",
      "                ",
      "                ",
      "                ",
      "                ",
      "a a a a a       ",
      "eeeeeeeeeb      ",
      "c       cea     ",
      "x      ! e      ",
      "         ea     ",
      "y        e      ",
      "x        ea     ",
      "        Ae      ",
      "         ea     ",
      "B       Ce      ",
      "   DEEEEcea     "
    ],
    [
      "                ",
      "                ",
      "                ",
      "                ",
      "                ",
      "a a a a a       ",
      "eeeeeeeeeb      ",
      "c       cea     ",
      "         e      ",
      "         ea     ",
      "         e      ",
      "         ea     ",
      "         e      ",
      "         ea     ",
      "         e      ",
      "     FIJcea     "
    ],
    [
      "                ",
      "                ",
      "                ",
      "                ",
      "                ",
      "a a a a a       ",
      "eeeeeeeeeb      ",
      "c       cea     ",
      "         e      ",
      "         ea     ",
      "         e      ",
      "         ea     ",
      "         e      ",
      "         ea     ",
      "         e      ",
      "        cea     "
    ],
    [
      "                ",
      "                ",
      "                ",
      "                ",
      "                ",
      "a a a a a       ",
      "eeeeeeeeeb      ",
      "cKKKKKKKcea     ",
      "LLLLLLLLKe      ",
      "LLLLLLLLKea     ",
      "LLLLLLLLKe      ",
      "LLLLLLLLKea     ",
      "LLLLLLLLKe      ",
      "LLLLLLLLKea     ",
      "LLLLLLLLKe      ",
      "LLLLLLLLcea     "
    ]
  ]
}