{
  "name": "multi_casino_6_floor18",
  "refpalette": "deceasedcraft:multi_casino_6/multi_casino_6_floor18_palette",
  "xsize": 16,
  "zsize": 16,
  "slices": [
    [
      "                ",
      "                ",
      "                ",
      "                ",
      "                ",
      "a a a a a       ",
      "bbbbbbbbbb      ",
      "cdddddddcba     ",
      "efefefefdb      ",
      "ghghghghdba     ",
      "efefefefdb      ",
      "ghghghghdba     ",
      "efefefefdb      ",
      "ghghghghdba     ",
      "efefefefdb      ",
      "ghghghghcba     "
    ],
    [
      "                ",
      "                ",
      "                ",
      "                ",
      "                ",
      "a a a a a       ",
      "iiiiiiiiib      ",
      "cjkllllmcia     ",
      "         i      ",
      "  n ooo  ia     ",
      "    opo  i      ",
      "  n ooo  ia     ",
      "         i      ",
      "    qrs  ia     ",
      "       tui      ",
      "wwwwxyxAcia     "
    ],
    [
      "                ",
      "                ",
      "                ",
      "                ",
      "                ",
      "a a a a a       ",
      "iiiiiiiiib      ",
      "c B CD Ecia     ",
      "         i      ",
      "         ia     ",
      "         i      ",
      "         ia     ",
      "         i      ",
      "         ia     ",
      "       F i      ",
      "  I J  Kcia     "
    ],
    [
      "                ",
      "                ",
      "                ",
      "                ",
      "                ",
      "a a a a a       ",
      "iiiiiiiiib      ",
      "c       cia     ",
      "         i      ",
      "         ia     ",
      "         i      ",
      "         ia     ",
      "         i      ",
      "         ia     ",
      "       F i      ",
      "        cia     "
    ],
    [
      "                ",
      "                ",
      "                ",
      "                ",
      "                ",
      "a a a a a       ",
      "iiiiiiiiib      ",
      "c       cia     ",
      "   L   L i      ",
      "         ia     ",
      "         i      ",
      "         ia     ",
      "   M   L i      ",
      "         ia     ",
      "       N i      ",
      "        cia     "
    ],
    [
      "                ",
      "                ",
      "                ",
      "                ",
      "                ",
      "a a a a a       ",
      "iiiiiiiiib      ",
      "cOOOOOOOcia     ",
      "PPPPQQQPOi      ",
      "PPPRSSSTOia     ",
      "PPPRSUSTOi      ",
      "PPPRSSSTOia     ",
      "PPPPVVVPOi      ",
      "PPPPPPPPOia     ",
      "PPPPPPPPOi      ",
      "PPPPPPPPcia     "
    ]
  ]
}