{
  "name": "multi_casino_6_floor14",
  "refpalette": "deceasedcraft:multi_casino_6/multi_casino_6_floor14_palette",
  "xsize": 16,
  "zsize": 16,
  "slices": [
    [
      "                ",
      "aaaaaaaaaa      ",
      "bcddddddcbe e   ",
      "b            e  ",
      "b               ",
      "b            e  ",
      "b            ba ",
      "fgggggggf    ca ",
      "ggggggggg    da ",
      "ggggggggg    da ",
      "ggggggggg    da ",
      "ggggggggg    da ",
      "ggggggggg    da ",
      "ggggggggg    da ",
      "ggggggggg    ca ",
      "ggggggggfbbbbba "
    ],
    [
      "                ",
      "aaaaaaaaaaa     ",
      "bcdddddddcb e   ",
      "b            e  ",
      "b               ",
      "b            ba ",
      "b            ca ",
      "fhhhhhhhf    da ",
      "   ijk  h    da ",
      "      l h    da ",
      "       mh    da ",
      "       nh    da ",
      "       oh    da ",
      "        h    da ",
      "pq      h    ca ",
      "rs      fbbbbba "
    ],
    [
      "                ",
      " aaaaaaaaaa     ",
      " bcddddddcb e   ",
      " b           e  ",
      " b              ",
      "tb           ba ",
      "ub           ca ",
      " f     f     da ",
      "        f    da ",
      "             da ",
      "             da ",
      "             da ",
      "             da ",
      "             ca ",
      "        fbbbbba ",
      "w        ut     "
    ],
    [
      "                ",
      " xaaaaaaaaaa    ",
      "  bcddddddcbe   ",
      "  b          e  ",
      "  b          ba ",
      "t b          ca ",
      "uub          da ",
      "  f   f      da ",
      "             da ",
      "        f    da ",
      "             da ",
      "             da ",
      "             ca ",
      "        fbbbbba ",
      "         u    x ",
      "         ut     "
    ],
    [
      "                ",
      "  aaaaaaaaaa    ",
      "  bcddddddcbe   ",
      "  b          e  ",
      "  b          ba ",
      "t b          ca ",
      "uub          da ",
      "  f   f      da ",
      "             da ",
      "        f    da ",
      "             da ",
      "             da ",
      "             ca ",
      "        fbbbbba ",
      "         u      ",
      "         ut     "
    ],
    [
      "                ",
      "   aaaaaaaaa    ",
      "   bcdddddcbe   ",
      "   b         e  ",
      "   b         ba ",
      "t tb         ca ",
      "uuub         da ",
      "   f f       da ",
      "             da ",
      "             da ",
      "        f    da ",
      "             ca ",
      "        fbbbbba ",
      "         ut     ",
      "         u      ",
      "y        ut     "
    ]
  ]
}