{
  "name": "multi_casino_6_floor5",
  "refpalette": "deceasedcraft:multi_casino_6/multi_casino_6_floor5_palette",
  "xsize": 16,
  "zsize": 16,
  "slices": [
    [
      "                ",
      "ababababb       ",
      "cccccccde f f   ",
      "             f  ",
      "                ",
      "             f  ",
      "                ",
      "    g        eb ",
      "             db ",
      "             ca ",
      "             cb ",
      "        g    ca ",
      "             cb ",
      "             ca ",
      "             cb ",
      "             ca "
    ],
    [
      "                ",
      "abbbabbbbb      ",
      "ccccccccdef     ",
      "                ",
      "                ",
      "             f  ",
      "             eb ",
      "    g        db ",
      "             cb ",
      "             cb ",
      "             cb ",
      "        g    ca ",
      "             cb ",
      "             cb ",
      "             cb ",
      "             ca "
    ],
    [
      "                ",
      "abbbabbbab      ",
      "ccccccccdef f   ",
      "             f  ",
      "                ",
      "             f  ",
      "             eb ",
      "   g g       da ",
      "             cb ",
      "             cb ",
      "        g    cb ",
      "             ca ",
      "        g    cb ",
      "             cb ",
      "             cb ",
      "             ca "
    ],
    [
      "                ",
      "abbbabbbab      ",
      "ccccccccdef f   ",
      "             f  ",
      "                ",
      "             f  ",
      "             eb ",
      "  g   g      da ",
      "             cb ",
      "        g    cb ",
      "             cb ",
      "             ca ",
      "             cb ",
      "        g    cb ",
      "             cb ",
      "             ca "
    ],
    [
      "                ",
      "abbbabbbab      ",
      "ccccccccdef f   ",
      "             f  ",
      "                ",
      "             f  ",
      "             eb ",
      "  g   g      da ",
      "             cb ",
      "        g    cb ",
      "             cb ",
      "             ca ",
      "             cb ",
      "        g    cb ",
      "             cb ",
      "             ca "
    ],
    [
      "                ",
      "abbbabbbbb      ",
      "ccccccccdef f   ",
      "             f  ",
      "                ",
      "             f  ",
      "             eb ",
      "hg     gh    db ",
      "        g    cb ",
      "             cb ",
      "             cb ",
      "             ca ",
      "             cb ",
      "             cb ",
      "        g    cb ",
      "        h    ca "
    ]
  ]
}