{
  "name": "multi_casino_6_floor21",
  "refpalette": "deceasedcraft:multi_casino_6/multi_casino_6_floor21_palette",
  "xsize": 16,
  "zsize": 16,
  "slices": [
    [
      "                ",
      "                ",
      "                ",
      "                ",
      "                ",
      "a a a a a       ",
      "bbbbbbbbbb      ",
      "cdddddddcba     ",
      "efefefefdb      ",
      "ghghghghdba     ",
      "efefefefdb      ",
      "ghghghghdba     ",
      "efefefefdb      ",
      "ghghghghdba     ",
      "efefefefdb      ",
      "ghghghghcba     "
    ],
    [
      "                ",
      "                ",
      "                ",
      "                ",
      "                ",
      "a a a a a       ",
      "iiiiiiiiib      ",
      "cjkllllmcia     ",
      "   n    oi      ",
      "  p qqq  ia     ",
      "    q!q  i      ",
      "  p qqq  ia     ",
      "       r i      ",
      "    stu  ia     ",
      "       w i      ",
      "xxxxyAyBcia     "
    ],
    [
      "                ",
      "                ",
      "                ",
      "                ",
      "                ",
      "a a a a a       ",
      "iiiiiiiiib      ",
      "cC   D Ecia     ",
      "         i      ",
      "         ia     ",
      "         i      ",
      "         ia     ",
      "         i      ",
      "         ia     ",
      "       F i      ",
      "  I   JKcia     "
    ],
    [
      "                ",
      "                ",
      "                ",
      "                ",
      "                ",
      "a a a a a       ",
      "iiiiiiiiib      ",
      "c       cia     ",
      "         i      ",
      "         ia     ",
      "         i      ",
      "         ia     ",
      "         i      ",
      "         ia     ",
      "       F i      ",
      "       Lcia     "
    ],
    [
      "                ",
      "                ",
      "                ",
      "                ",
      "                ",
      "a a a a a       ",
      "iiiiiiiiib      ",
      "c       cia     ",
      "   M   N i      ",
      "         ia     ",
      "         i      ",
      "         ia     ",
      "   M   M i      ",
      "         ia     ",
      "       O i      ",
      "        cia     "
    ],
    [
      "                ",
      "                ",
      "                ",
      "                ",
      "                ",
      "a a a a a       ",
      "iiiiiiiiib      ",
      "cPPPPPPPcia     ",
      "QQQQRRRQPi      ",
      "QQQSTTTUPia     ",
      "QQQSTVTUPi      ",
      "QQQSTTTUPia     ",
      "QQQQWWWQPi      ",
      "QQQQQQQQPia     ",
      "QQQQQQQQPi      ",
      "QQQQQQQQcia     "
    ]
  ]
}