{
  "name": "multi_casino_6_floor15",
  "refpalette": "deceasedcraft:multi_casino_6/multi_casino_6_floor15_palette",
  "xsize": 16,
  "zsize": 16,
  "slices": [
    [
      "                ",
      "   abbbbbbbbb   ",
      "    cdeeeeedc   ",
      "    c        cb ",
      "    c        db ",
      "f f c        eb ",
      "ggggc        eb ",
      "    h        eb ",
      "             eb ",
      "             eb ",
      "             db ",
      "        hcccccb ",
      "         g    a ",
      "         gf     ",
      "         g      ",
      "i        gf     "
    ],
    [
      "                ",
      "    bbbbbbbbb   ",
      "    cdeeeeedc   ",
      "    c        cb ",
      "    c        db ",
      "f f c        eb ",
      "jjjjc        eb ",
      "    h        eb ",
      "             eb ",
      "             eb ",
      "             db ",
      "        hcccccb ",
      "         j      ",
      "k        jf     ",
      "         j      ",
      "i        jf     "
    ],
    [
      "                ",
      "     bbbbbbbb   ",
      "     cdeeeedc   ",
      "     c       cb ",
      "     c       db ",
      "f f fc       eb ",
      "jjjjjc       eb ",
      "     h       eb ",
      "             eb ",
      "             db ",
      "        hcccccb ",
      "         jf     ",
      "         j      ",
      "l        jf     ",
      " m       j      ",
      "i k      jf     "
    ],
    [
      "                ",
      "     abbbbbbbb  ",
      "      cdeeeedcb ",
      "      c      db ",
      "      c      eb ",
      "f f f c      eb ",
      "jjjjjjc      eb ",
      "      h      eb ",
      "             db ",
      "        hcccccb ",
      "         j    a ",
      "         jf     ",
      "         j      ",
      "l        jf     ",
      " n       j      ",
      "i l      jf     "
    ],
    [
      "                ",
      "      bbbbbbbb  ",
      "      cdeeeedcb ",
      "      c      db ",
      "      c      eb ",
      "f f f c      eb ",
      "jjjjjjc      eb ",
      "      h      eb ",
      "             db ",
      "        hcccccb ",
      "         j      ",
      "         jf     ",
      "         j      ",
      "ln       jf     ",
      " nn      j      ",
      "i l      jf     "
    ],
    [
      "                ",
      "       bbbbbbb  ",
      "       cdeeedcb ",
      "       c     db ",
      "       c     eb ",
      "f f f fc     eb ",
      "jjjjjjjc     eb ",
      "ooooooohm    db ",
      "pppppppphcccccb ",
      "ppppppppojf     ",
      "ppppppppoj      ",
      "ppppppppojf     ",
      "qqppppppoj      ",
      "rropppppojf     ",
      "ssrtppppoj      ",
      "!srtppppojf     "
    ]
  ]
}