{
  "name": "multi_casino_6_base3",
  "refpalette": "deceasedcraft:multi_casino_6/multi_casino_6_base3_palette",
  "xsize": 16,
  "zsize": 16,
  "slices": [
    [
      "    a       a   ",
      "                ",
      "                ",
      " a             a",
      "                ",
      "                ",
      "                ",
      "a               ",
      "                ",
      "           a    ",
      "        b aa    ",
      " a    cddde   aa",
      "      fgghi   a ",
      "     ffgghi aaa ",
      "    accggheea   ",
      "      ddddd     "
    ],
    [
      "    a       a   ",
      "                ",
      "                ",
      " a             a",
      "                ",
      "                ",
      "                ",
      "a               ",
      "                ",
      "                ",
      "     cj   a     ",
      " a  fkeaaaa    a",
      "  cfgli         ",
      "  ccdii         ",
      "    dee   aaa   ",
      "      aaaaa     "
    ],
    [
      "    a       a   ",
      "                ",
      "                ",
      " a             a",
      "                ",
      "                ",
      "                ",
      "a               ",
      "                ",
      " cffcm          ",
      " cfkhea         ",
      " ddli aa       a",
      "  ei            ",
      "  ee            ",
      "    aaa     a   ",
      "      a a       "
    ],
    [
      "    a       a   ",
      "                ",
      "                ",
      " a             a",
      " cf             ",
      "dcffc           ",
      "dgggd           ",
      "dgggdn          ",
      "dllld           ",
      "deiiea          ",
      " e   aa         ",
      " aa            a",
      "  a             ",
      "  aaa           ",
      "    a       a   ",
      "        a       "
    ],
    [
      "opooq       qoop",
      "oocc           o",
      "oocf           o",
      "oqdgf          q",
      "oeirkc          ",
      "aeiies          ",
      "a   a           ",
      "q   a           ",
      "a   a           ",
      "aa  aa          ",
      "oa              ",
      "oq             q",
      "oo             o",
      "oo             o",
      "opooq       qoop",
      "pooooo  q  ooooo"
    ],
    [
      "tuttddd   dddttu",
      "ttdddff     dddt",
      "ttdirkf       dt",
      "tdd ilc       dd",
      "td   ew        d",
      "dd  aa         d",
      "d   a           ",
      "d               ",
      "d               ",
      "dd             d",
      "td             d",
      "tdd           dd",
      "ttd           dt",
      "ttddd       dddt",
      "tuttddd   dddttu",
      "utttttdddddttttt"
    ]
  ]
}