{
  "name": "multi_casino_6_base6",
  "refpalette": "deceasedcraft:multi_casino_6/multi_casino_6_base6_palette",
  "xsize": 16,
  "zsize": 16,
  "slices": [
    [
      "aaaabbbcddbbbaaa",
      "aabbb ecddffbbba",
      "aab   ecddf   ba",
      "abb   gbbbh   bb",
      "ab   ii j      b",
      "bb   i         b",
      "b               ",
      "b               ",
      "b               ",
      "bb             b",
      "ab             b",
      "abb           bb",
      "aab           ba",
      "aabbb       bbba",
      "aaaabbb   bbbaaa",
      "aaaaaabbbbbaaaaa"
    ],
    [
      "    iii   ggb   ",
      "  iii     eebhh ",
      "  i       ekdfh ",
      " ii   iiiiglf ii",
      " i    i   mh   i",
      "ii             i",
      "i               ",
      "i               ",
      "i               ",
      "ii             i",
      " i             i",
      " ii           ii",
      "  i           i ",
      "  iii       iii ",
      "    iii   iii   ",
      "      iiiii     "
    ],
    [
      "    i     iii   ",
      "             gg ",
      "             eg ",
      " i       ii ekbb",
      "          igclfh",
      "           nhffh",
      "                ",
      "i               ",
      "                ",
      "                ",
      "                ",
      " i             i",
      "                ",
      "                ",
      "    i       i   ",
      "        i       "
    ],
    [
      "    i       i   ",
      "            iii ",
      "              i ",
      " i            ii",
      "          ii   g",
      "           igeeg",
      "            bkkk",
      "i          !bddd",
      "            bddd",
      "            hffh",
      "              fh",
      " i             i",
      "                ",
      "                ",
      "    i       i   ",
      "        i       "
    ],
    [
      "    i       i   ",
      "                ",
      "                ",
      " i             i",
      "               i",
      "           ii  i",
      "            i   ",
      "i           i   ",
      "            i   ",
      "           ogeeg",
      "           hlpeg",
      " i          fdbb",
      "             fh ",
      "             hh ",
      "    i       i   ",
      "        i       "
    ],
    [
      "    i       i   ",
      "                ",
      "                ",
      " i             i",
      "                ",
      "                ",
      "                ",
      "i               ",
      "            i   ",
      "           ii  i",
      "          qg   i",
      " i        hke  i",
      "          flpeg ",
      "          ffbgg ",
      "    i     hhb   ",
      "        i       "
    ]
  ]
}