{
  "name": "multi_casino_6_floor20",
  "refpalette": "deceasedcraft:multi_casino_6/multi_casino_6_floor20_palette",
  "xsize": 16,
  "zsize": 16,
  "slices": [
    [
      "                ",
      "                ",
      "                ",
      "                ",
      "                ",
      "a a a a a       ",
      "bbbbbbbbbb      ",
      "cdddddddcba     ",
      "efefefefdb      ",
      "ghghghghdba     ",
      "efefefefdb      ",
      "ghghghghdba     ",
      "efefefefdb      ",
      "ghghghghdba     ",
      "efefefefdb      ",
      "ghghghghcba     "
    ],
    [
      "                ",
      "                ",
      "                ",
      "                ",
      "                ",
      "a a a a a       ",
      "iiiiiiiiib      ",
      "cjkllllmcia     ",
      "         i      ",
      "  n ooo  ia     ",
      "    opo  i      ",
      "  n ooo  ia     ",
      "         i      ",
      "    qrs  ia     ",
      "       t i      ",
      "uuuuwxwycia     "
    ],
    [
      "                ",
      "                ",
      "                ",
      "                ",
      "                ",
      "a a a a a       ",
      "iiiiiiiiib      ",
      "cA  BCD cia     ",
      "         i      ",
      "         ia     ",
      "         i      ",
      "         ia     ",
      "         i      ",
      "         ia     ",
      "       E i      ",
      "  F    Icia     "
    ],
    [
      "                ",
      "                ",
      "                ",
      "                ",
      "                ",
      "a a a a a       ",
      "iiiiiiiiib      ",
      "c       cia     ",
      "         i      ",
      "         ia     ",
      "         i      ",
      "         ia     ",
      "         i      ",
      "         ia     ",
      "       E i      ",
      "        cia     "
    ],
    [
      "                ",
      "                ",
      "                ",
      "                ",
      "                ",
      "a a a a a       ",
      "iiiiiiiiib      ",
      "c       cia     ",
      "   J   K i      ",
      "         ia     ",
      "         i      ",
      "         ia     ",
      "   K   J i      ",
      "         ia     ",
      "       L i      ",
      "        cia     "
    ],
    [
      "                ",
      "                ",
      "                ",
      "                ",
      "                ",
      "a a a a a       ",
      "iiiiiiiiib      ",
      "cMMMMMMMcia     ",
      "NNNNOOONMi      ",
      "NNNPQQQRMia     ",
      "NNNPQSQRMi      ",
      "NNNPQQQRMia     ",
      "NNNNTTTNMi      ",
      "NNNNNNNNMia     ",
      "NNNNNNNNMi      ",
      "NNNNNNNNcia     "
    ]
  ]
}