{
  "name": "multi_casino_6_base7",
  "refpalette": "deceasedcraft:multi_casino_6/multi_casino_6_base7_palette",
  "xsize": 16,
  "zsize": 16,
  "slices": [
    [
      "    a       a   ",
      "                ",
      "                ",
      " a             a",
      "                ",
      "                ",
      "                ",
      "a       b       ",
      "                ",
      "           a    ",
      "        c aa    ",
      " a    deeef   aa",
      "      ghhij   a ",
      "     gghhij aaa ",
      "    addhhiffa   ",
      "      eeeee     "
    ],
    [
      "    a       a   ",
      "                ",
      "                ",
      " a             a",
      "                ",
      "                ",
      "        b       ",
      "a      bbb      ",
      "        b       ",
      "                ",
      "     dk   a     ",
      " a  glfaaaa    a",
      "  dghmj         ",
      "  ddejj         ",
      "    eff   aaa   ",
      "      aaaaa     "
    ],
    [
      "    a       a   ",
      "                ",
      "                ",
      " a             a",
      "                ",
      "                ",
      "                ",
      "a       b       ",
      "                ",
      " dggdn          ",
      " dglifa         ",
      " eemj aa       a",
      "  fj            ",
      "  ff            ",
      "    aaa     a   ",
      "      a a       "
    ],
    [
      "    a       a   ",
      "                ",
      "                ",
      " a             a",
      " dg             ",
      "edggd           ",
      "ehhhe           ",
      "ehhheo          ",
      "emmme           ",
      "efjjfa          ",
      " f   aa         ",
      " aa            a",
      "  a             ",
      "  aaa           ",
      "    a       a   ",
      "        a       "
    ],
    [
      "pqppr       rppq",
      "ppdd           p",
      "ppdg           p",
      "prehg          r",
      "pfjsld          ",
      "afjjft          ",
      "a   a           ",
      "r   a           ",
      "a   a           ",
      "aa  aa          ",
      "pa              ",
      "pr             r",
      "pp             p",
      "pp             p",
      "pqppr       rppq",
      "qppppp  r  ppppp"
    ],
    [
      "uwuueee   eeeuuw",
      "uueeegg     eeeu",
      "uuejslg       eu",
      "uee jmd       ee",
      "ue   fx        e",
      "ee  aa         e",
      "e   a           ",
      "e               ",
      "e               ",
      "ee             e",
      "ue             e",
      "uee           ee",
      "uue           eu",
      "uueee       eeeu",
      "uwuueee   eeeuuw",
      "wuuuuueeeeeuuuuu"
    ]
  ]
}