{
  "name": "multi_casino_6_floor6",
  "refpalette": "deceasedcraft:multi_casino_6/multi_casino_6_floor6_palette",
  "xsize": 16,
  "zsize": 16,
  "slices": [
    [
      "                ",
      "aaaaaaaaaaa     ",
      "bbbbbbbbbcd     ",
      "ee           f  ",
      "eeee            ",
      "eeeee        da ",
      "eeeeeee      ca ",
      "geeeeeeeg    ba ",
      "eeeeeeeee    ba ",
      "eeeeeeeeee   ba ",
      "eeeeeeeeee   ba ",
      "eeeeeeeeeee  ba ",
      "eeeeeeeeeeee ba ",
      "eeeeeeeeeeee ba ",
      "eeeeeeeeeeeeeba ",
      "eeeeeeeegeeeeba "
    ],
    [
      "                ",
      "aahaaahaaaa     ",
      "bbbbbbbbbcd f   ",
      "ij           f  ",
      " jjj            ",
      "  kjj        da ",
      "    jjj      ca ",
      "g l   jjg    ba ",
      "   mnn  j    ba ",
      "  opqrs jj   bh ",
      "  tuwxu  j   ba ",
      "   nmn   jj  ba ",
      "          jj ba ",
      "y     AAB  j bh ",
      " C y DEEF  jjba ",
      "y    mIEg    ba "
    ],
    [
      "                ",
      "aahaaahaaaa     ",
      "bbbbbbbbbcd f   ",
      "J               ",
      "                ",
      "             da ",
      "             ca ",
      " gK L Mg     ba ",
      "    NN  g    ba ",
      "             bh ",
      "    O        ba ",
      "   P P       ba ",
      "             ba ",
      "             bh ",
      " Q      g    ba ",
      "             ba "
    ],
    [
      "                ",
      "aahaaahaaaa     ",
      "bbbbbbbbbcd f   ",
      "             f  ",
      "                ",
      "             da ",
      "             ca ",
      "  g R g      ba ",
      "             ba ",
      "        g    bh ",
      "             ba ",
      "             ba ",
      "             ba ",
      "        g    bh ",
      " Q           ba ",
      "             ba "
    ],
    [
      "                ",
      "aahaaahaaaa     ",
      "bbbbbbbbbcd f   ",
      "             f  ",
      "                ",
      "             da ",
      "             ca ",
      "  gS Tg      ba ",
      "             ba ",
      "        g    bh ",
      "             ba ",
      "             ba ",
      "             ba ",
      "        g    bh ",
      " Q           ba ",
      "             ba "
    ],
    [
      "                ",
      "aaaaaaaaaaa     ",
      "bbbbbbbbbcd f   ",
      "             f  ",
      "                ",
      "             da ",
      "             ca ",
      "   g g       ba ",
      "             ba ",
      "             ba ",
      "        g    ba ",
      "             ba ",
      "        g    ba ",
      "             ba ",
      " Q           ba ",
      "             ba "
    ]
  ]
}