{
  "name": "multi_casino_6_floor4",
  "refpalette": "deceasedcraft:multi_casino_6/multi_casino_6_floor4_palette",
  "xsize": 16,
  "zsize": 16,
  "slices": [
    [
      "                ",
      "aabaaabaaaaaaaa ",
      "      cddddddda ",
      "eeeeeeeeeeeeeda ",
      "eeeeeeeeeeeeeda ",
      "eeeeeeeeeeeeeda ",
      "eeeeeeeeeeeeeda ",
      "eeeeeeeefeeeeda ",
      "eeeeeeeeeeeeeda ",
      "eeeeeeeeeeeeecb ",
      "eeeeeeeeeeeee a ",
      "eeeeeeeeeeeee a ",
      "eeeeeeeeeeeee a ",
      "eeeeeeeeeeeee b ",
      "eeeeeeeeeeeee a ",
      "eeeeeeeeeeeee a "
    ],
    [
      "                ",
      "aabaaabaggggggg ",
      "hhhhhhcdi i i g ",
      "jklmn   opq  ig ",
      "           r  g ",
      "kkk         sig ",
      "tt          u g ",
      "        f   wig ",
      "     x       da ",
      "      r      cb ",
      "  y    A     ha ",
      "BCCCD       Eha ",
      " FFF        Iha ",
      "JF!FK     L Mhb ",
      " FFF     tL Lha ",
      "  N      tL Oha "
    ],
    [
      "                ",
      "aabaaaba        ",
      "hhhhhhcdi i i   ",
      "   PQ        i  ",
      "           R    ",
      "             i  ",
      "                ",
      "       f     i  ",
      "        f    da ",
      "      S      cb ",
      "             ha ",
      " TUV        Wha ",
      "            Iha ",
      "             hb ",
      "             ha ",
      "             ha "
    ],
    [
      "                ",
      "aabaaabaa       ",
      "hhhhhhhcd i     ",
      "XYZ01           ",
      "                ",
      "             i  ",
      "                ",
      "      f      da ",
      "             ca ",
      "        f    hb ",
      "             ha ",
      "            2ha ",
      "            Iha ",
      "            3hb ",
      "            4ha ",
      "            5ha "
    ],
    [
      "                ",
      "aabaaabaa       ",
      "hhhhhhhcd i i   ",
      "             i  ",
      "                ",
      "             i  ",
      "                ",
      "      f      da ",
      "             ca ",
      "        f    hb ",
      "             ha ",
      "             ha ",
      "             ha ",
      "             hb ",
      "             ha ",
      "             ha "
    ],
    [
      "                ",
      "aabaaabaa       ",
      "hhhhhhhcd i i   ",
      "             i  ",
      "                ",
      "             i  ",
      "                ",
      "     f       da ",
      "             ca ",
      "             hb ",
      "        f    ha ",
      "             ha ",
      "             ha ",
      "             hb ",
      "             ha ",
      "             ha "
    ]
  ]
}