{
  "name": "multi_casino_6_floor10",
  "refpalette": "deceasedcraft:multi_casino_6/multi_casino_6_floor10_palette",
  "xsize": 16,
  "zsize": 16,
  "slices": [
    [
      "                ",
      "                ",
      "a a a a a a     ",
      "b               ",
      "bbbb            ",
      "bbbbbb       a  ",
      "bbbbbbb         ",
      "cbbbbbbbc    a  ",
      "bbbbbbbbb       ",
      "bbbbbbbbbb   a  ",
      "bbbbbbbbbbb     ",
      "bbbbbbbbbbb  a  ",
      "bbbbbbbbbbbb    ",
      "bbbbbbbbbbbb a  ",
      "bbbbbbbbbbbb    ",
      "bbbbbbbbcbbbba  "
    ],
    [
      "                ",
      "                ",
      "a a a a a a a   ",
      "d            a  ",
      "dddd            ",
      "   ddd       a  ",
      "     dd         ",
      "c     ddc    a  ",
      "     e  d       ",
      "      f dd   a  ",
      "       g dd     ",
      "  h i     d  a  ",
      " jjjk     dd    ",
      "lj!jkm     d a  ",
      " jjjk      d    ",
      "  n o   c  dda  "
    ],
    [
      "                ",
      "                ",
      "a a a a a a a   ",
      "             a  ",
      "                ",
      "             a  ",
      "                ",
      " c     c     a  ",
      "        c       ",
      "             a  ",
      "                ",
      "             a  ",
      "    p           ",
      "    q        a  ",
      "    r   c       ",
      "             a  "
    ],
    [
      "                ",
      "                ",
      "a a a a a a     ",
      "                ",
      "                ",
      "             a  ",
      "                ",
      "  c   c      a  ",
      "                ",
      "        c    a  ",
      "                ",
      "             a  ",
      "                ",
      "        c    a  ",
      "                ",
      "             a  "
    ],
    [
      "                ",
      "                ",
      "a a a a a a a   ",
      "             a  ",
      "                ",
      "             a  ",
      "                ",
      "  c   c      a  ",
      "                ",
      "        c    a  ",
      "                ",
      "             a  ",
      "                ",
      "        c    a  ",
      "                ",
      "             a  "
    ],
    [
      "                ",
      "s               ",
      "t a a a a a a   ",
      "             a  ",
      "                ",
      "             a  ",
      "                ",
      "   c c       a  ",
      "                ",
      "             a  ",
      "        c       ",
      "             a  ",
      "        c       ",
      "             a  ",
      "                ",
      "             ts "
    ]
  ]
}