{
  "name": "multi_casino_6_base9",
  "refpalette": "deceasedcraft:multi_casino_6/multi_casino_6_base9_palette",
  "xsize": 16,
  "zsize": 16,
  "slices": [
    [
      "aaaaaaaaaaaaaaaa",
      "aaaaaaaaaaaaaaaa",
      "aaaaaaaaaaaaaaaa",
      "aaaaaaaaaaaaaaaa",
      "aaaaaaaaaaaaaaaa",
      "aaaaaaaaaaaaaaaa",
      "aaaaaaaaaaaaaaaa",
      "aaaaaaaaaaaaaaaa",
      "aaaaaaaaaaaaaaaa",
      "aaaaaaaaaaaaaaaa",
      "aaaaaaaaaaaaaaaa",
      "aaaaaaaaaaaaaaaa",
      "aaaaaaaaaaaaaaaa",
      "aaaaaaaaaaaaaaaa",
      "aaaaaaaaaaaaaaaa",
      "aaaaaaaaaaaaaaaa"
    ],
    [
      "bbbb@@@cde@@@   ",
      "bb@@@f      gh  ",
      "bb@i     jk   l ",
      "m@@   nopqr   s@",
      "b@t    jk      @",
      "@@             @",
      "@u kwr      wj x",
      "@y  pA     kp  B",
      "@C  Dk     nDr E",
      "@@             @",
      "b@     FIk    J@",
      "m@h    opqF   @@",
      "@ g     nk   i@b",
      "   sl      K@@@b",
      "    @@@LMN@@@bbb",
      "   @mb@@@@@bmbbb"
    ],
    [
      "bbbb@@@O P@@@   ",
      "bb@@@Q      RS  ",
      "bb@T          U ",
      "m@@    AVA    W@",
      "b@P            @",
      "@@             @",
      "@X  V       V  P",
      "@k  I       Y   ",
      "@Z  j       n  0",
      "@@             @",
      "b@            P@",
      "m@S    1YV    @@",
      "@ R          T@b",
      "   WU      2@@@b",
      "    @@@PA2@@@bbb",
      "   @mb@@@@@bmbbb"
    ],
    [
      "bbbb@@@   @@@   ",
      "bb@@@       34  ",
      "bb@5          6 ",
      "m@@           7@",
      "b@             @",
      "@@             @",
      "@               ",
      "@               ",
      "@               ",
      "@@             @",
      "b@             @",
      "m@4      F    @@",
      "@ 3          5@b",
      "   76       @@@b",
      "    @@@   @@@bbb",
      "   @mb@@@@@bmbbb"
    ],
    [
      "bbbb888p9p888   ",
      "bb888ppppppp88# ",
      "bb8ipppppppppp8 ",
      "b88ppppppppppp88",
      "b8ppppppppp#ppp8",
      "88ppppppppppppp8",
      "8ppppppppppppppp",
      "8$pppppp#pppppp%",
      "8ppppppppppppppp",
      "88ppppppppppppp8",
      "b8ppp#ppppppppp8",
      "m88ppppppppppp88",
      "@ 8ppppppppppi8b",
      "  #88ppppppp888b",
      "    888p^p888bbb",
      "&  @mb88888bbbbb"
    ],
    [
      "b*bb888aaa888pp*",
      "bb888aaaaaaa888p",
      "bb8aaaaaaaaaaa8p",
      "b88aaaaaaaaaaa88",
      "b8aaaaa(((aaaaa8",
      "88aaaa(((((aaaa8",
      "8aaaa(((((((aaaa",
      "8aaaa((()(((aaaa",
      "8aaaa(((((((aaaa",
      "88aaaa(((((aaaa8",
      "b8aaaaa(((aaaaa8",
      "b88aaaaaaaaaaa88",
      "8p8aaaaaaaaaaa8b",
      "pp888aaaaaaa888b",
      "p*pp888aaa888bb*",
      "*pp8bb88888bbbbb"
    ]
  ]
}