{
  "name": "multi_casino_6_floor8",
  "refpalette": "deceasedcraft:multi_casino_6/multi_casino_6_floor8_palette",
  "xsize": 16,
  "zsize": 16,
  "slices": [
    [
      "                ",
      "           a    ",
      "b b b b b bcb   ",
      "d            b  ",
      "dddd         ca ",
      "dddddd       b  ",
      "ddddddd         ",
      "dddddddde    b  ",
      "ddddddddd       ",
      "dddddddddd   b  ",
      "ddddddddddd     ",
      "ddddddddddd  b  ",
      "dddddddddddd    ",
      "fgdddddddddd b  ",
      " hdddddddddd    ",
      "  iddddddddddb  "
    ],
    [
      "                ",
      "                ",
      "b b b b b b b   ",
      "j            b  ",
      "jjjj            ",
      "kkkjjj       b  ",
      " l k jj         ",
      "  m   jje    b  ",
      "n       j       ",
      "        jj   b  ",
      " n  o    jj     ",
      "          j  b  ",
      "p     o   jj    ",
      "q     r    j b  ",
      " st        j    ",
      "  uw      mjjb  "
    ],
    [
      "                ",
      "                ",
      "b b b b b b b   ",
      "             b  ",
      "                ",
      "xyA          b  ",
      "   B            ",
      "       e     b  ",
      "        e       ",
      "             b  ",
      "                ",
      "             b  ",
      "                ",
      "             b  ",
      "                ",
      "             b  "
    ],
    [
      "                ",
      "                ",
      "b b b b b b     ",
      "                ",
      "                ",
      "             b  ",
      "                ",
      "      e      b  ",
      "                ",
      "        e    b  ",
      "                ",
      "             b  ",
      "                ",
      "             b  ",
      "                ",
      "             b  "
    ],
    [
      "                ",
      "                ",
      "b b b b b b b   ",
      "             b  ",
      "                ",
      "             b  ",
      "                ",
      "      e      b  ",
      "                ",
      "        e    b  ",
      "                ",
      "             b  ",
      "                ",
      "             b  ",
      "                ",
      "             b  "
    ],
    [
      "                ",
      "                ",
      "b b b b b b     ",
      "                ",
      "                ",
      "             b  ",
      "                ",
      "     e       b  ",
      "                ",
      "             b  ",
      "        e       ",
      "             b  ",
      "                ",
      "             b  ",
      "                ",
      "             b  "
    ]
  ]
}