{
  "name": "multi_casino_6_floor16",
  "refpalette": "deceasedcraft:multi_casino_6/multi_casino_6_floor16_palette",
  "xsize": 16,
  "zsize": 16,
  "slices": [
    [
      "                ",
      "       abbbbbbc ",
      "        defffeb ",
      "        d    fb ",
      "        d    fb ",
      "g g g g d    fb ",
      "hhhhhhhhd    eb ",
      "iiiiiiiijdddddb ",
      "iiiiiiiiih    a ",
      "iiiiiiiiihg     ",
      "iiiiiiiiih      ",
      "iiiiiiiiihg     ",
      "iiiiiiiiih      ",
      "iiiikiiiihg     ",
      "iiiiliiiih      ",
      "iiiiiiiiihg     "
    ],
    [
      "                ",
      "        bbbbbbb ",
      "        deffffb ",
      "        d    fb ",
      "        d    fb ",
      "g g g g d    fb ",
      "mmmmmmmmd    eb ",
      "   no   jdddddb ",
      "   pq    m      ",
      "   rs    mg     ",
      "   rq    m      ",
      "   rt    mg     ",
      "   rq    m      ",
      " u rw    mg     ",
      "   rx    m      ",
      "   yAAAABmg     "
    ],
    [
      "                ",
      "         bbbbbb ",
      "         defffb ",
      "         d   fb ",
      "         d   fb ",
      "g g g g gd   eb ",
      "mmmmmmmmmdddddb ",
      "   CD  j mg     ",
      "    E   jm      ",
      "    F    mg     ",
      "         m      ",
      "         mg     ",
      "    I    m      ",
      "         mg     ",
      "    J    m      ",
      "     K L mg     "
    ],
    [
      "                ",
      "         abbbbb ",
      "          deffb ",
      "          d  fb ",
      "          d  eb ",
      "g g g g g ddddb ",
      "MmMmMmMmmh    a ",
      "   NO j  mg     ",
      "   PQ    m      ",
      "   PR   jSg     ",
      "   PQ    m      ",
      "   PR    Sg     ",
      "   PQ    m      ",
      "   PR    Sg     ",
      "   PQ    m      ",
      "   PR    Sg     "
    ],
    [
      "                ",
      "          bbbbb ",
      "          deffb ",
      "          d  fb ",
      "          d  eb ",
      "g g g g g  dddb ",
      "MmMmMmMmmh      ",
      "      j  mg     ",
      "    T    m      ",
      "        jSg     ",
      "    J    m      ",
      "    T    Sg     ",
      "         m      ",
      "    !    Sg     ",
      "    T    m      ",
      "         Sg     "
    ],
    [
      "                ",
      "           bbbb ",
      "           defb ",
      "           d eb ",
      "           dddb ",
      "g g g g g       ",
      "MmMmMmMmmh      ",
      "     j   mg     ",
      "    T    m      ",
      "         Sg     ",
      "        jm      ",
      "    T    Sg     ",
      "         m      ",
      "         Sg     ",
      "    T    m      ",
      "         Sg     "
    ]
  ]
}