{
  "name": "multi_casino_6_floor12",
  "refpalette": "deceasedcraft:multi_casino_6/multi_casino_6_floor12_palette",
  "xsize": 16,
  "zsize": 16,
  "slices": [
    [
      "                ",
      "aaaa            ",
      "bcdef f f f f   ",
      "g            f  ",
      "gggg            ",
      "gggggg       f  ",
      "ggggggg         ",
      "ggggggggh    f  ",
      "ggggggggg       ",
      "gggggggggg   f  ",
      "ggggggggggg     ",
      "ggggggggggg  f  ",
      "gggggggggggg ea ",
      "iggggggggggg da ",
      "  gggggggggg ca ",
      "  jggggggggggca "
    ],
    [
      "                ",
      "aaaaa           ",
      "cccde f f f f   ",
      "k            f  ",
      "kkkk            ",
      "  lkkk       f  ",
      "   m kk         ",
      "    n kkh    f  ",
      "        k       ",
      "        kk   f  ",
      "         kk     ",
      "  o     l k  ea ",
      "p  m     mkk da ",
      "qp  r     nk ca ",
      "  s        k ca ",
      "  ts       kkca "
    ],
    [
      "                ",
      "aaaaa           ",
      "cccde f f f f   ",
      "             f  ",
      "                ",
      "             f  ",
      "                ",
      "       h     f  ",
      "        h       ",
      "             f  ",
      "                ",
      "             ea ",
      "   !     u   da ",
      "             ca ",
      "             ca ",
      "             ca "
    ],
    [
      "                ",
      "aaaaaa          ",
      "ccccdef f f f   ",
      "             f  ",
      "                ",
      "             f  ",
      "                ",
      "      h      f  ",
      "                ",
      "        h    f  ",
      "             ea ",
      "             da ",
      "             ca ",
      "             ca ",
      "             ca ",
      "             ca "
    ],
    [
      "                ",
      "aaaaaa          ",
      "ccccdef f f f   ",
      "             f  ",
      "                ",
      "             f  ",
      "                ",
      "      h      f  ",
      "                ",
      "        h    f  ",
      "             ea ",
      "             da ",
      "             ca ",
      "             ca ",
      "             ca ",
      "             ca "
    ],
    [
      "                ",
      "aaaaaaa         ",
      "cccccde f f f   ",
      "             f  ",
      "                ",
      "             f  ",
      "                ",
      "     h       f  ",
      "                ",
      "             ea ",
      "        h    da ",
      "             ca ",
      "             ca ",
      "             ca ",
      "             ca ",
      "             ca "
    ]
  ]
}