{
  "name": "multi_casino_6_floor27",
  "refpalette": "deceasedcraft:multi_casino_6/multi_casino_6_floor27_palette",
  "xsize": 16,
  "zsize": 16,
  "slices": [
    [
      "                ",
      "                ",
      "                ",
      "                ",
      "                ",
      "a a a a a       ",
      "bbbbbbbba       ",
      "c       caa     ",
      "d        b      ",
      "         ba     ",
      "d        b      ",
      "         ba     ",
      "d        b      ",
      "         ba     ",
      "         b      ",
      "e f  f  cba     "
    ],
    [
      "                ",
      "                ",
      "                ",
      "                ",
      "                ",
      "a a a a         ",
      "bbbbbbb         ",
      "c      cg       ",
      "d       cb      ",
      "         ba     ",
      "d        b      ",
      "d        ba     ",
      "d        b      ",
      "         ba     ",
      "d        b      ",
      "e ff f fcba     "
    ],
    [
      "                ",
      "                ",
      "                ",
      "                ",
      "                ",
      "a a a a         ",
      "bbbbbba         ",
      "c     c ~       ",
      "d               ",
      "        caa     ",
      "d        b      ",
      "d        ba     ",
      "d        b      ",
      "d        ba     ",
      "d        b      ",
      "efffff fcba     "
    ],
    [
      "                ",
      "                ",
      "                ",
      "                ",
      "                ",
      "a a a           ",
      "bbbbb           ",
      "c    c ~~       ",
      "d               ",
      "d               ",
      "d       c       ",
      "d        ba     ",
      "d        b      ",
      "d        ba     ",
      "d        b      ",
      "efffffffcba     "
    ],
    [
      "                ",
      "                ",
      "                ",
      "                ",
      "                ",
      "a a a           ",
      "bbbba           ",
      "c   c   ~       ",
      "h               ",
      "h               ",
      "h               ",
      "h       caa     ",
      "h        b      ",
      "h        ba     ",
      "h        b      ",
      "eiiiiiiicba     "
    ],
    [
      "                ",
      "                ",
      "                ",
      "                ",
      "                ",
      "a a             ",
      "bbb             ",
      "c  c    ~       ",
      "j               ",
      "j               ",
      "j               ",
      "j               ",
      "j       c       ",
      "j        ba     ",
      "j        b      ",
      "jjjjjjjjcba     "
    ]
  ]
}