{
  "name": "multi_casino_6_floor3",
  "refpalette": "deceasedcraft:multi_casino_6/multi_casino_6_floor3_palette",
  "xsize": 16,
  "zsize": 16,
  "slices": [
    [
      "                ",
      "abbbabbbabbbabb ",
      "              b ",
      "        c     a ",
      "              b ",
      "              b ",
      "              b ",
      "ddddc       c a ",
      "ddddd         b ",
      "dddddd        b ",
      "ddddddd       b ",
      "ddddddddc     a ",
      "ddddddddd     b ",
      "ddddddddd     b ",
      "ddddddddd     b ",
      "ddddddddd     a "
    ],
    [
      "                ",
      "abbbabbbabbbabb ",
      "              b ",
      "        c     a ",
      "              b ",
      "              b ",
      "              b ",
      "    c       c a ",
      "eeeef         b ",
      "   eff        b ",
      " g e ff       b ",
      "eehe  ffc     a ",
      "e  e    f     b ",
      "e  e    f     b ",
      "e  e    f     b ",
      "i  j    f     a "
    ],
    [
      "                ",
      "abbbabbbabbbabb ",
      "              b ",
      "              a ",
      "        c     b ",
      "              b ",
      "              b ",
      "     c     c  a ",
      "eeee          b ",
      " k e          b ",
      " l e    c     b ",
      "eeme          a ",
      "e  e          b ",
      "e  n          b ",
      "e  e          b ",
      "o  p          a "
    ],
    [
      "                ",
      "abbbabbbabbbabb ",
      "              b ",
      "              a ",
      "              b ",
      "        c     b ",
      "              b ",
      "      c   c   a ",
      "eeee          b ",
      "   e    c     b ",
      " l e          b ",
      "eeqe          a ",
      "e  e          b ",
      "e  r          b ",
      "e  e          b ",
      "r  r          a "
    ],
    [
      "                ",
      "abbbabbbabbbabb ",
      "              b ",
      "              a ",
      "              b ",
      "        c     b ",
      "              b ",
      "      c   c   a ",
      "eeee          b ",
      "   e    c     b ",
      "   e          b ",
      "eeee          a ",
      "e  e          b ",
      "e  e          b ",
      "e  e          b ",
      "e  e          a "
    ],
    [
      "                ",
      "abababababbbabb ",
      "      ssssssssb ",
      "             sa ",
      "             sb ",
      "             sb ",
      "        c    sb ",
      "       ctc   sa ",
      "ffee    c    sb ",
      "   e         sa ",
      "   e          b ",
      "eeee          a ",
      "e  e          b ",
      "f  f          a ",
      "f  f          b ",
      "f  f          a "
    ]
  ]
}