{
  "name": "multi_casino_6_floor25",
  "refpalette": "deceasedcraft:multi_casino_6/multi_casino_6_floor25_palette",
  "xsize": 16,
  "zsize": 16,
  "slices": [
    [
      "                ",
      "                ",
      "                ",
      "                ",
      "                ",
      "a a a a a       ",
      "bbbbbbbbbb      ",
      "cdddddddcba     ",
      "ddddeeeedb      ",
      "ddddeeeedba     ",
      "ddddeeeedb      ",
      "ddddeeeedba     ",
      "ddddeeeedb      ",
      "ddddeeeedba     ",
      "ddddeeeedb      ",
      "ddddeeeecba     "
    ],
    [
      "                ",
      "                ",
      "                ",
      "                ",
      "                ",
      "a a a a a       ",
      "fffffffffb      ",
      "cg heeeecfa     ",
      "i  jkkkkef      ",
      "l  jkkkkefa     ",
      "   jkkkkef      ",
      "mn jkkkkefa     ",
      "   jkkkkef      ",
      "   jkkkkefa     ",
      "mn jkkkkef      ",
      "   jkkkkcfa     "
    ],
    [
      "                ",
      "                ",
      "                ",
      "                ",
      "                ",
      "a a a a a       ",
      "fffffffffb      ",
      "c     o cfa     ",
      "p     q  f      ",
      "         fa     ",
      "         f      ",
      "         fa     ",
      "         f      ",
      "         fa     ",
      "         f      ",
      "        cfa     "
    ],
    [
      "                ",
      "                ",
      "                ",
      "                ",
      "                ",
      "a a a a a       ",
      "fffffffffb      ",
      "c       cfa     ",
      "         f      ",
      "         fa     ",
      "         f      ",
      "         fa     ",
      "         f      ",
      "         fa     ",
      "         f      ",
      "        cfa     "
    ],
    [
      "                ",
      "                ",
      "                ",
      "                ",
      "                ",
      "a a a a a       ",
      "fffffffffb      ",
      "c       cfa     ",
      "         f      ",
      "         fa     ",
      "         f      ",
      "         fa     ",
      "         f      ",
      "         fa     ",
      "         f      ",
      "        cfa     "
    ],
    [
      "                ",
      "                ",
      "                ",
      "                ",
      "                ",
      "a a a a a       ",
      "fffffffffb      ",
      "c       cfa     ",
      "         f      ",
      "         fa     ",
      "         f      ",
      "         fa     ",
      "         f      ",
      "         fa     ",
      "         f      ",
      "        cfa     "
    ]
  ]
}