{
  "name": "multi_casino_6_ground",
  "refpalette": "deceasedcraft:multi_casino_6/multi_casino_6_ground_palette",
  "xsize": 16,
  "zsize": 16,
  "slices": [
    [
      "aaaabbbcaaaaabdd",
      "aabbb ecaaaaaabd",
      "aab   ecaaaaaaab",
      "abb   fbbbbaaaaa",
      "ab   gg h bbaaaa",
      "bb   g     bbaaa",
      "b           bbaa",
      "b            bba",
      "b             ba",
      "bb            bb",
      "ab             b",
      "abb           bb",
      "aab           ba",
      "aabbb       bbba",
      "aaaabbb   bbbaaa",
      "aaaaaabbbbbaaaaa"
    ],
    [
      "    ggg       ii",
      "  ggg          i",
      "  g             ",
      " gg   ggggg     ",
      " g    g   gg    ",
      "gg         gg   ",
      "g           gg  ",
      "g            gg ",
      "g             g ",
      "gg            gg",
      " g             g",
      " gg           gg",
      "  g           g ",
      "  ggg       ggg ",
      "    ggg   ggg   ",
      "      ggggg     "
    ],
    [
      "    g           ",
      "                ",
      "                ",
      " g              ",
      "                ",
      "                ",
      "                ",
      "g               ",
      "                ",
      "                ",
      "                ",
      " g             g",
      "                ",
      "                ",
      "    g       g   ",
      "        g       "
    ],
    [
      "    g           ",
      "                ",
      "                ",
      " g              ",
      "                ",
      "                ",
      "                ",
      "g               ",
      "                ",
      "                ",
      "                ",
      " g             g",
      "                ",
      "                ",
      "    g       g   ",
      "        g       "
    ],
    [
      "    g           ",
      "                ",
      "                ",
      " g              ",
      "                ",
      "                ",
      "                ",
      "g               ",
      "                ",
      "                ",
      "                ",
      " g             g",
      "                ",
      "                ",
      "    g       g   ",
      "        g       "
    ],
    [
      "    g           ",
      "                ",
      "                ",
      " g              ",
      "                ",
      "                ",
      "                ",
      "g               ",
      "                ",
      "                ",
      "                ",
      " g             g",
      "                ",
      "                ",
      "    g       g   ",
      "        g       "
    ]
  ]
}