{
  "name": "multi_casino_6_floor26",
  "refpalette": "deceasedcraft:multi_casino_6/multi_casino_6_floor26_palette",
  "xsize": 16,
  "zsize": 16,
  "slices": [
    [
      "                ",
      "                ",
      "                ",
      "                ",
      "                ",
      "a a a a a       ",
      "bbbbbbbbbb      ",
      "c       cba     ",
      "         b      ",
      "         ba     ",
      "         b      ",
      "         ba     ",
      "         b      ",
      "         ba     ",
      "         b      ",
      "        cba     "
    ],
    [
      "                ",
      "                ",
      "                ",
      "                ",
      "                ",
      "a a a a a       ",
      "dddddddddb      ",
      "c       cda     ",
      "         d      ",
      "         da     ",
      "         d      ",
      "         da     ",
      "e        d      ",
      "e        da     ",
      "e        d      ",
      "e       cda     "
    ],
    [
      "                ",
      "                ",
      "                ",
      "                ",
      "                ",
      "a a a a a       ",
      "dddddddddb      ",
      "c       cda     ",
      "         d      ",
      "         da     ",
      "         d      ",
      "         da     ",
      "         d      ",
      "         da     ",
      "         d      ",
      "        cda     "
    ],
    [
      "                ",
      "                ",
      "                ",
      "                ",
      "                ",
      "a a a a a       ",
      "dddddddddb      ",
      "c       cda     ",
      "         d      ",
      "         da     ",
      "         d      ",
      "         da     ",
      "         d      ",
      "         da     ",
      "         d      ",
      "        cda     "
    ],
    [
      "                ",
      "                ",
      "                ",
      "                ",
      "                ",
      "a a a a a       ",
      "dddddddddb      ",
      "c       cda     ",
      "         d      ",
      "         da     ",
      "         d      ",
      "         da     ",
      "         d      ",
      "         da     ",
      "         d      ",
      "        cda     "
    ],
    [
      "                ",
      "                ",
      "                ",
      "                ",
      "                ",
      "a a a a a       ",
      "dddddddddb      ",
      "cfffffffcda     ",
      "fgggggggfd      ",
      "fgggggggfda     ",
      "fgggggggfd      ",
      "fgggggggfda     ",
      "fgggggggfd      ",
      "fgggggggfda     ",
      "fgggggggfd      ",
      "ffffffffcda     "
    ]
  ]
}