{
  "name": "multi_casino_6_floor24",
  "refpalette": "deceasedcraft:multi_casino_6/multi_casino_6_floor24_palette",
  "xsize": 16,
  "zsize": 16,
  "slices": [
    [
      "                ",
      "                ",
      "                ",
      "                ",
      "                ",
      "a a a a a       ",
      "bbbbbbbbbb      ",
      "cdddddddcba     ",
      "dddddddddb      ",
      "dddddddddba     ",
      "dddddddddb      ",
      "dddddddddba     ",
      "dddddddddb      ",
      "dddddddddba     ",
      "dddddddddb      ",
      "ddddddddcba     "
    ],
    [
      "                ",
      "                ",
      "                ",
      "                ",
      "                ",
      "a a a a a       ",
      "eeeeeeeeeb      ",
      "cf g    cea     ",
      "    g h  e      ",
      "  iiiii  ea     ",
      "  iiiii  e      ",
      "  fjj  h ea     ",
      "         e      ",
      "  kk  k  ea     ",
      "  lmmmnope      ",
      " qrrrstucea     "
    ],
    [
      "                ",
      "                ",
      "                ",
      "                ",
      "                ",
      "a a a a a       ",
      "eeeeeeeeeb      ",
      "c       cea     ",
      "         e      ",
      "    fw   ea     ",
      "   x f   e      ",
      "         ea     ",
      "         e      ",
      "         ea     ",
      "  yAAABoCe      ",
      " DEF !IJcea     "
    ],
    [
      "                ",
      "                ",
      "                ",
      "                ",
      "                ",
      "a a a a a       ",
      "eeeeeeeeeb      ",
      "c       cea     ",
      "         e      ",
      "         ea     ",
      "         e      ",
      "         ea     ",
      "         e      ",
      "         ea     ",
      "  KKKKKKCe      ",
      " DLMLMLMcea     "
    ],
    [
      "                ",
      "                ",
      "                ",
      "                ",
      "                ",
      "a a a a a       ",
      "eeeeeeeeeb      ",
      "c       cea     ",
      "         e      ",
      "  N N N  ea     ",
      "  N N N  e      ",
      "         ea     ",
      "         e      ",
      "         ea     ",
      "  OPQ R Se      ",
      " TUUUUUUcea     "
    ],
    [
      "                ",
      "                ",
      "                ",
      "                ",
      "                ",
      "a a a a a       ",
      "eeeeeeeeeb      ",
      "cVVVVVVVcea     ",
      "WVVVVVVVWe      ",
      "WVXVXVXVWea     ",
      "WVXVXVXVWe      ",
      "WVVVVVVVWea     ",
      "WVVVVVVVWe      ",
      "WVVVVVVVWea     ",
      "WVVVVVVVWe      ",
      "WVYYYYYYcea     "
    ]
  ]
}