{
  "name": "multi_casino_6_floor19",
  "refpalette": "deceasedcraft:multi_casino_6/multi_casino_6_floor19_palette",
  "xsize": 16,
  "zsize": 16,
  "slices": [
    [
      "                ",
      "                ",
      "                ",
      "                ",
      "                ",
      "a a a a a       ",
      "bbbbbbbbbb      ",
      "cdddddddcba     ",
      "efefefefdb      ",
      "ghghghghdba     ",
      "efefefefdb      ",
      "ghghghghdba     ",
      "efefefefdb      ",
      "ghghghghdba     ",
      "efefefefdb      ",
      "ghghghghcba     "
    ],
    [
      "                ",
      "                ",
      "                ",
      "                ",
      "                ",
      "a a a a a       ",
      "iiiiiiiiib      ",
      "cjkllllmcia     ",
      "         i      ",
      "  n ooo  ia     ",
      "    opo  i      ",
      "  n ooo  ia     ",
      "         i      ",
      "    qrs  ia     ",
      "       t i      ",
      "uuuuwxwycia     "
    ],
    [
      "                ",
      "                ",
      "                ",
      "                ",
      "                ",
      "a a a a a       ",
      "iiiiiiiiib      ",
      "cA   B Ccia     ",
      "         i      ",
      "         ia     ",
      "         i      ",
      "         ia     ",
      "         i      ",
      "         ia     ",
      "       D i      ",
      "    E FIcia     "
    ],
    [
      "                ",
      "                ",
      "                ",
      "                ",
      "                ",
      "a a a a a       ",
      "iiiiiiiiib      ",
      "c       cia     ",
      "         i      ",
      "         ia     ",
      "         i      ",
      "         ia     ",
      "         i      ",
      "         ia     ",
      "       D i      ",
      "        cia     "
    ],
    [
      "                ",
      "                ",
      "                ",
      "                ",
      "                ",
      "a a a a a       ",
      "iiiiiiiiib      ",
      "c       cia     ",
      "   J   J i      ",
      "         ia     ",
      "         i      ",
      "         ia     ",
      "   J   J i      ",
      "         ia     ",
      "       K i      ",
      "        cia     "
    ],
    [
      "                ",
      "                ",
      "                ",
      "                ",
      "                ",
      "a a a a a       ",
      "iiiiiiiiib      ",
      "cLLLLLLLcia     ",
      "MMMMNNNMLi      ",
      "MMMOPPPQLia     ",
      "MMMOP!PQLi      ",
      "MMMOPPPQLia     ",
      "MMMMRRRMLi      ",
      "MMMMMMMMLia     ",
      "MMMMMMMMLi      ",
      "MMMMMMMMcia     "
    ]
  ]
}