{
  "name": "multi_casino_6_floor22",
  "refpalette": "deceasedcraft:multi_casino_6/multi_casino_6_floor22_palette",
  "xsize": 16,
  "zsize": 16,
  "slices": [
    [
      "                ",
      "                ",
      "                ",
      "                ",
      "                ",
      "a a a a a       ",
      "bbbbbbbbbb      ",
      "cdddddddcba     ",
      "dddddddddb      ",
      "dddddddddba     ",
      "dddddddddb      ",
      "dddddddddba     ",
      "dddddddddb      ",
      "dddddddddba     ",
      "dddddddddb      ",
      "ddddddddcba     "
    ],
    [
      "                ",
      "                ",
      "                ",
      "                ",
      "                ",
      "a a a a a       ",
      "eeeeeeeeeb      ",
      "c       cea     ",
      "   fff   e      ",
      "  ggggg  ea     ",
      "  ggggg  e      ",
      "   hhh   ea     ",
      "         e      ",
      "  iiji   ea     ",
      "  klllmnoe      ",
      " pqqqrstcea     "
    ],
    [
      "                ",
      "                ",
      "                ",
      "                ",
      "                ",
      "a a a a a       ",
      "eeeeeeeeeb      ",
      "c       cea     ",
      "         e      ",
      "   u     ea     ",
      "         e      ",
      "         ea     ",
      "         e      ",
      "         ea     ",
      "  wxxxynAe      ",
      " BCDE FIcea     "
    ],
    [
      "                ",
      "                ",
      "                ",
      "                ",
      "                ",
      "a a a a a       ",
      "eeeeeeeeeb      ",
      "c       cea     ",
      "         e      ",
      "         ea     ",
      "         e      ",
      "         ea     ",
      "         e      ",
      "         ea     ",
      "  JJJJJJAe      ",
      " BKLKLKLcea     "
    ],
    [
      "                ",
      "                ",
      "                ",
      "                ",
      "                ",
      "a a a a a       ",
      "eeeeeeeeeb      ",
      "c       cea     ",
      "         e      ",
      "  M M M  ea     ",
      "  M M M  e      ",
      "         ea     ",
      "         e      ",
      "         ea     ",
      "   NO PQRe      ",
      " STTUTTTcea     "
    ],
    [
      "                ",
      "                ",
      "                ",
      "                ",
      "                ",
      "a a a a a       ",
      "eeeeeeeeeb      ",
      "cVVVVVVVcea     ",
      "VWWWWWWWVe      ",
      "VWXWXWXWVea     ",
      "VWXWXWXWVe      ",
      "VWWWWWWWVea     ",
      "VWWWWWWWVe      ",
      "VWWWWWWWVea     ",
      "VWWWWWWWVe      ",
      "VWYYYYYYcea     "
    ]
  ]
}