{
  "name": "multi_casino_6_floor7",
  "refpalette": "deceasedcraft:multi_casino_6/multi_casino_6_floor7_palette",
  "xsize": 16,
  "zsize": 16,
  "slices": [
    [
      "                ",
      "aaaaaaaaaaaa    ",
      "bbbbbbbbbbcde   ",
      "             e  ",
      "             da ",
      "             ca ",
      "             ba ",
      "    f        ba ",
      "             ba ",
      "             ba ",
      "             ba ",
      "        f    ba ",
      "             ba ",
      "             ba ",
      " g           ba ",
      "             ba "
    ],
    [
      "                ",
      "haaahaaahaaa    ",
      "bbbbbbbbbbcde   ",
      "             e  ",
      "             da ",
      "             ca ",
      "             ba ",
      "    f        bh ",
      "             ba ",
      "             ba ",
      "             ba ",
      "        f    bh ",
      "             ba ",
      "             ba ",
      " g           ba ",
      "             bh "
    ],
    [
      "                ",
      "haaahaaahaaa    ",
      "bbbbbbbbbbcde   ",
      "             e  ",
      "             da ",
      "             ca ",
      "             ba ",
      "     f       bh ",
      "             ba ",
      "             ba ",
      "        f    ba ",
      "             bh ",
      "             ba ",
      "             ba ",
      " g           ba ",
      "             bh "
    ],
    [
      "                ",
      "haaahaaahaaa    ",
      "bbcccccccccde   ",
      "             e  ",
      "             da ",
      "             ca ",
      "             ca ",
      "      f      ch ",
      "             ca ",
      "        f    ca ",
      "             ca ",
      "             ch ",
      "             ca ",
      "             ca ",
      " g           ba ",
      "             bh "
    ],
    [
      "                ",
      "aaaaaaaaaaaa    ",
      "ccddddddddcde   ",
      "             e  ",
      "             da ",
      "             ca ",
      "             da ",
      "      f      da ",
      "             da ",
      "        f    da ",
      "             da ",
      "             da ",
      "             da ",
      "             da ",
      " g           ca ",
      "             ca "
    ],
    [
      "                ",
      "aai       aa    ",
      "dde e e e dde   ",
      "             e  ",
      "             da ",
      "             da ",
      "                ",
      "       fj    e  ",
      "        f       ",
      "             e  ",
      "                ",
      "             e  ",
      "                ",
      "             ei ",
      " g           da ",
      "             da "
    ]
  ]
}