{
  "name": "multi_casino_6_floor17",
  "refpalette": "deceasedcraft:multi_casino_6/multi_casino_6_floor17_palette",
  "xsize": 16,
  "zsize": 16,
  "slices": [
    [
      "                ",
      "           abbb ",
      "            cdb ",
      "            ccb ",
      "              a ",
      "e e e e e       ",
      "fgfgfgfghh      ",
      "    i    he     ",
      "    j    g      ",
      "         ke     ",
      "         g      ",
      "    j   ike     ",
      "         g      ",
      "         ke     ",
      "    j    g      ",
      "         ke     "
    ],
    [
      "                ",
      "            bbb ",
      "            cdb ",
      "             cb ",
      "                ",
      "e e e e e       ",
      "fgfgfgfggh      ",
      "    i    ge     ",
      "    l    g      ",
      "    l    ke     ",
      "    l    g      ",
      "    l   ike     ",
      "    l    g      ",
      "    l    ke     ",
      "    l    g      ",
      "    l    ke     "
    ],
    [
      "                ",
      "             bb ",
      "             cb ",
      "                ",
      "                ",
      "e e e e e       ",
      "fgfgfgfggh      ",
      "   i i   ge     ",
      "         g      ",
      "         ke     ",
      "        ig      ",
      "         ke     ",
      "        ig      ",
      "         ke     ",
      "         g      ",
      "         ke     "
    ],
    [
      "                ",
      "             ab ",
      "              a ",
      "                ",
      "                ",
      "e e e e e       ",
      "mgmgmgmggh      ",
      "  i   i  ge     ",
      "         g      ",
      "        ine     ",
      "         g      ",
      "         ne     ",
      "         g      ",
      "        ine     ",
      "         g      ",
      "         ne     "
    ],
    [
      "                ",
      "              b ",
      "                ",
      "                ",
      "                ",
      "e e e e e       ",
      "gggggggggh      ",
      "  i   i  ge     ",
      "         g      ",
      "        ige     ",
      "         g      ",
      "         ge     ",
      "         g      ",
      "        ige     ",
      "         g      ",
      "         ge     "
    ],
    [
      "                ",
      "                ",
      "                ",
      "                ",
      "                ",
      "e e e e e       ",
      "gggggggggh      ",
      "oipppppioge     ",
      "qqqqqqqqig      ",
      "qqqqqqqqpge     ",
      "qqqqqqqqpg      ",
      "qqqqqqqqpge     ",
      "qqqqqqqqpg      ",
      "qqqqqqqqpge     ",
      "qqqqqqqqig      ",
      "qqqqqqqqoge     "
    ]
  ]
}