{
  "name": "multi_casino_6_base8",
  "refpalette": "deceasedcraft:multi_casino_6/multi_casino_6_base8_palette",
  "xsize": 16,
  "zsize": 16,
  "slices": [
    [
      "aaaabbbcccbbbaaa",
      "aabbbcccccccbbba",
      "aabcccccccccccba",
      "abbcccbbbbbcccbb",
      "abcccbbde bbcccb",
      "bbccbb    fbbccb",
      "bcccb       bccc",
      "bcccbg  hf ibccc",
      "bcccbd      bccc",
      "bbccbb  f dbbccb",
      "abcccbb j bbcccb",
      "abbcccbbbbbcccbb",
      "aabcccccccccccba",
      "aabbbcccccccbbba",
      "aaaabbbcccbbbaaa",
      "aaaaaabbbbbaaaaa"
    ],
    [
      "    k     llb   ",
      "          mmbnn ",
      "          mocpn ",
      " k    kkkklqp  k",
      "     kk   rn    ",
      "    kk     kk   ",
      "    k       k   ",
      "k   k   h   k   ",
      "    k       k   ",
      "    kk     kk   ",
      "     kk   kk    ",
      " k    kkkkk    k",
      "                ",
      "                ",
      "    k       k   ",
      "        k       "
    ],
    [
      "    k     kkk   ",
      "             ll ",
      "             ml ",
      " k       kk mobb",
      "          klsqpn",
      "       ttt unppn",
      "      ttttt     ",
      "k     tthtt     ",
      "      ttttt     ",
      "       ttt      ",
      "                ",
      " k             k",
      "                ",
      "                ",
      "    k       k   ",
      "        k       "
    ],
    [
      "    k       k   ",
      "            kkk ",
      "              k ",
      " k            kk",
      "          kk   l",
      "           klmml",
      "        t   booo",
      "k      tht ibccc",
      "        t   bccc",
      "            nppn",
      "              pn",
      " k             k",
      "                ",
      "                ",
      "    k       k   ",
      "        k       "
    ],
    [
      "    k       k   ",
      "                ",
      "                ",
      " k             k",
      "               k",
      "       ttt kk  k",
      "      ttttt k   ",
      "k     tthtt k   ",
      "      ttttt k   ",
      "       ttt wlmml",
      "           nqxml",
      " k          pcbb",
      "             pn ",
      "             nn ",
      "    k       k   ",
      "        k       "
    ],
    [
      "    k       k   ",
      "                ",
      "                ",
      " k             k",
      "                ",
      "                ",
      "        t       ",
      "k      tht      ",
      "        t   k   ",
      "           kk  k",
      "          yl   k",
      " k        nom  k",
      "          pqxml ",
      "          ppbll ",
      "    k     nnb   ",
      "        k       "
    ]
  ]
}