{
  "name": "multi_casino_6_floor13",
  "refpalette": "deceasedcraft:multi_casino_6/multi_casino_6_floor13_palette",
  "xsize": 16,
  "zsize": 16,
  "slices": [
    [
      "                ",
      "aaaaaaa         ",
      "bbbbbcd e e e   ",
      "             e  ",
      "                ",
      "             e  ",
      "                ",
      "    f        e  ",
      "                ",
      "             da ",
      "             ca ",
      "        f    ba ",
      "             ba ",
      "             ba ",
      "             ba ",
      "             ba "
    ],
    [
      "                ",
      "aaaaaaaa        ",
      "bbbbbbcde e e   ",
      "             e  ",
      "                ",
      "             e  ",
      "                ",
      "    f        e  ",
      "             da ",
      "             ca ",
      "             ba ",
      "        f    ba ",
      "             ba ",
      "             ba ",
      "             ba ",
      "             ba "
    ],
    [
      "                ",
      "aaaaaaaa        ",
      "bbbbbbcde e e   ",
      "             e  ",
      "                ",
      "             e  ",
      "                ",
      "   f f       e  ",
      "             da ",
      "             ca ",
      "        f    ba ",
      "             ba ",
      "        f    ba ",
      "             ba ",
      "             ba ",
      "             ba "
    ],
    [
      "                ",
      "aaaaaaaaa       ",
      "bbbbbbbcd e e   ",
      "             e  ",
      "                ",
      "             e  ",
      "                ",
      "  f   f      da ",
      "             ca ",
      "        f    ba ",
      "             ba ",
      "             ba ",
      "             ba ",
      "        f    ba ",
      "             ba ",
      "             ba "
    ],
    [
      "                ",
      "aaaaaaaaa       ",
      "bbbbbbbcd e e   ",
      "             e  ",
      "                ",
      "             e  ",
      "                ",
      "  f   f      da ",
      "             ca ",
      "        f    ba ",
      "             ba ",
      "             ba ",
      "             ba ",
      "        f    ba ",
      "             ba ",
      "             ba "
    ],
    [
      "                ",
      "aaaaaaaaaa      ",
      "cbbbbbbbcde e   ",
      "             e  ",
      "                ",
      "             e  ",
      "             da ",
      "gf     fg    ca ",
      "        f    ba ",
      "             ba ",
      "             ba ",
      "             ba ",
      "             ba ",
      "             ba ",
      "        f    ba ",
      "        g    ca "
    ]
  ]
}