{
  "name": "multi_laboratory_8_base6",
  "refpalette": "deceasedcraft:multi_laboratory_8/multi_laboratory_8_base6_palette",
  "xsize": 16,
  "zsize": 16,
  "slices": [
    [
      "aaaaaaa@@aaaaaaa",
      "aaaaaaaaaaaaaaaa",
      "bbbcbbbbbbbbcbbb",
      "aaaaaaaaaaaaaaaa",
      "aaaaaaaaaaaaaaaa",
      "aaaaaaaaaaaaaaaa",
      "aaaaaaaaaaaaaaaa",
      "aaaaaaaaaaaaaaad",
      "aaaaaaaaaaaaaaad",
      "aaaaaaaaaaaaaaaa",
      "aaaaaaaaaaaaaaaa",
      "aaaaaaeaaaaaaaaa",
      "aaaaaaaaaaaaaaaa",
      "aaaaaaaaaaaaaaaa",
      "aaaaaaaaaaaaaaaa",
      "aaaaaaaaaaaaaaaa"
    ],
    [
      "             f  ",
      "            g f ",
      "hhhchhhhhhhhchh ",
      "                ",
      "                ",
      "                ",
      "                ",
      "      iiii      ",
      "  jbbbbbbbbbbb k",
      "  jeeeeeeeeeebl ",
      "  beemeeenoeeb  ",
      " pbem!oeeeneebq ",
      " pbeeeeemeeeebq ",
      " pbedeersrdeebq ",
      " pbeemmst!eeebq ",
      "  beedeeneeeebum"
    ],
    [
      "                ",
      "                ",
      "wwwcwwwwwwwwcww ",
      "                ",
      "                ",
      "                ",
      "                ",
      "                ",
      "  xxxxxxxxxxxx  ",
      "  xmdmd      x  ",
      "  x mmm      x  ",
      "  xmd        x  ",
      "  xmm   k    x  ",
      "  x       y  x  ",
      "  x   y      x  ",
      "  x      u   xuk"
    ],
    [
      "                ",
      "                ",
      "wwwcwwwwwwwwcw  ",
      "                ",
      "                ",
      "                ",
      "                ",
      "                ",
      "  xxxxxxxxxxxx  ",
      "  xm y       x  ",
      "  xmd        x  ",
      "  x          x  ",
      "  xy         x  ",
      "  x          x  ",
      "  x          x  ",
      "  x     Au   xk "
    ],
    [
      "                ",
      "                ",
      "wwwcwwwwwwwwcww ",
      "                ",
      "                ",
      "                ",
      "                ",
      "                ",
      "  xxxxxxxxxxxx  ",
      "  xB         x  ",
      "  xm         x  ",
      "  x          x  ",
      "  x          x  ",
      "  x          x  ",
      "  x      CA  x  ",
      "  x     ku   x  "
    ],
    [
      "                ",
      "                ",
      "wwwcwwwwwwwwcwwD",
      "                ",
      "                ",
      "                ",
      "                ",
      "                ",
      "  xxxxxxxxxxxx  ",
      "  xm         x  ",
      "  xu         x  ",
      "  x          x  ",
      "  x          x  ",
      "  x          x  ",
      "  x       k  x  ",
      "  x      u   x  "
    ]
  ]
}