{
  "name": "multi_laboratory_8_base2",
  "refpalette": "deceasedcraft:multi_laboratory_8/multi_laboratory_8_base2_palette",
  "xsize": 16,
  "zsize": 16,
  "slices": [
    [
      "aaaaaaaaaaaaaaaa",
      "aaaaaaaaaaaaaaaa",
      "aaabaaaaaaaabaaa",
      "aaaa!aaaaaaaaaaa",
      "aaaaaaaaaaaaaaaa",
      "aaaaaaaaaaaaaaaa",
      "aaaaaaaaaaaaaaaa",
      "aaaaaaaaaaaaaaaa",
      "aaaaaaaaaaaaaaaa",
      "aaabaaaaaaaabaaa",
      "aaaaaaaaaaaaaaaa",
      "aaaaaaaaaaaaaaaa",
      "aaaaaaaaaaaaaaaa",
      "aaaaaaaaaaaaaaaa",
      "aaaaaaaaaaaaaaaa",
      "aaaaaaaaaaaaaaaa"
    ],
    [
      "  c c      c c  ",
      " dc ce    dc ce ",
      "  cbc      cbc  ",
      " dc c e   fc c e",
      "  c c      c c  ",
      "  g g      g g  ",
      "                ",
      "                ",
      "   h        h   ",
      "iiibijjkljjibiii",
      "   h        h   ",
      "                ",
      "                ",
      "m    noppqn    o",
      "rn  s t  r    nt",
      "r    nt  r     t"
    ],
    [
      "    u      w    ",
      "  w x        u  ",
      "  ybA      wbB  ",
      "    u        u  ",
      "  w        x    ",
      "                ",
      "                ",
      "                ",
      "   C        C   ",
      "DDibijjEFjjibiDD",
      "   C        C   ",
      "                ",
      "                ",
      "I     JKL      M",
      "I        N     O",
      "O     O  P     Q"
    ],
    [
      "                ",
      "                ",
      "   b        b   ",
      "                ",
      "                ",
      "                ",
      "                ",
      "                ",
      "   R        R   ",
      "DDibijjjjjjibiDD",
      "   R        R   ",
      "                ",
      "                ",
      "                ",
      "                ",
      "                "
    ],
    [
      "                ",
      "                ",
      "   b        b   ",
      "                ",
      "                ",
      "                ",
      "                ",
      "                ",
      "                ",
      "iiibiiiiiiiibiii",
      "                ",
      "                ",
      "                ",
      "                ",
      "                ",
      "                "
    ],
    [
      "STSSSTSSSSTSSSTS",
      "SSSSSSSSSSSSSSSS",
      "SSSbSSSSSSSSbSSS",
      "SSSSSSSSSSSSSSSS",
      "STSSSTSSSSTSSSTS",
      "STSSSTSSSSTSSSTS",
      "STSSSTSSSSTSSSTS",
      "STSSSTSSSSTSSSTS",
      "SSSSSSSSSSSSSSSS",
      "UUUbUUUUUUUUbUUU",
      "VVViVVVVVVVViVVV",
      "VVViVVVVVVVViVVV",
      "VVViVVVVVVVViVVV",
      "TVViVV TTTVViVVW",
      "WVViVVTVVTVViVVW",
      " VViVVWVVTVViVVT"
    ]
  ]
}