{
  "name": "multi_laboratory_8_top",
  "refpalette": "deceasedcraft:multi_laboratory_8/multi_laboratory_8_top_palette",
  "xsize": 16,
  "zsize": 16,
  "slices": [
    [
      "aaaabcd  bcdaaaa",
      "aaaa        aaaa",
      "aaaa        aaaa",
      "aaaa        aaaa",
      "aaaa        aaaa",
      "aaaa        aaaa",
      "aaaa        aaaa",
      "aaaa  !     aaaa",
      "aaaa        aaaa",
      "aaaa        aaaa",
      "aaaa        aaaa",
      "aaaa        aaaa",
      "aaaa        aaaa",
      "aaaa        aaaa",
      "aaaa        aaaa",
      "aaaa        aaaa"
    ],
    [
      "   b        d   ",
      "   b        d   ",
      "  eb        de  ",
      "   b        d   ",
      "ff b        d gg",
      "hh b        d hh",
      "ff b        d ii",
      "   b        d   ",
      "   b        d   ",
      "fjeb        degg",
      "hh b        d hh",
      "ff b        d ig",
      "   b        d   ",
      "   b        d   ",
      "ii b        d gg",
      "hh b        d hh"
    ],
    [
      "                ",
      "                ",
      "  e          e  ",
      "                ",
      "                ",
      " k            k ",
      "                ",
      "                ",
      "                ",
      "  e          e  ",
      "              kk",
      "                ",
      "                ",
      "                ",
      "                ",
      "k             k "
    ],
    [
      "                ",
      "                ",
      "  e          e  ",
      "                ",
      "                ",
      "                ",
      "                ",
      "                ",
      "                ",
      "  e          e  ",
      "                ",
      "                ",
      "                ",
      "                ",
      "                ",
      "                "
    ],
    [
      "                ",
      "                ",
      "  e          e  ",
      "                ",
      "                ",
      "                ",
      "                ",
      "                ",
      "                ",
      "  e          e  ",
      "                ",
      "                ",
      "                ",
      "                ",
      "                ",
      "                "
    ],
    [
      "    llllllll    ",
      "  lll      lll  ",
      "llm          mll",
      "l              l",
      "                ",
      "                ",
      "     llllll     ",
      "   lll    lll   ",
      "  ll        ll  ",
      "  m          m  ",
      " ll          ll ",
      " l            l ",
      " l            l ",
      " l            l ",
      " l            l ",
      " ll          ll "
    ],
    [
      "    mmmmmmmm    ",
      "  mmmnnnnnnmmm  ",
      "mmmnnnnnnnnnnmmm",
      "mnnnnnnnnnnnnnnm",
      "nnnnnnnnnnnnnnnn",
      "nnnnnnnnnnnnnnnn",
      "nnnnnzzzzzznnnnn",
      "nnnzzzoooozzznnn",
      "nnzzoooppooozznn",
      "nnzooppppppooznn",
      "nzzoppppppppozzn",
      "nzooppppppppoozn",
      "nzoppppppppppozn",
      "nzoppppppppppozn",
      "nzooppppppppoozn",
      "nzzoppppppppozzn"
    ],
    [
      "    eqqqqqqe    ",
      "  qqq      qqq  ",
      "qqq r      r qqq",
      "q              q",
      "                ",
      "                ",
      "       stt      ",
      "   sss     t    ",
      "  s         s   ",
      "             s  ",
      "  t           t ",
      " t            s ",
      " s              ",
      " t              ",
      " s            s ",
      "  t             "
    ],
    [
      "                ",
      "                ",
      "    u      u    ",
      "                ",
      "                ",
      "                ",
      "                ",
      "                ",
      "                ",
      "                ",
      "                ",
      "                ",
      "                ",
      "                ",
      "                ",
      "                "
    ]
  ]
}