{
  "name": "multi_laboratory_8_base4",
  "refpalette": "deceasedcraft:multi_laboratory_8/multi_laboratory_8_base4_palette",
  "xsize": 16,
  "zsize": 16,
  "slices": [
    [
      "aaaaaaaaaaaaaaaa",
      "aaaaaaaaaaaaaaaa",
      "aaabaaaaaaaabaaa",
      "aaaaaaaaaaaaaaaa",
      "aaaaaaaaaaaaaaaa",
      "aaaaaaaaaaaaaaaa",
      "aaaaaaaaaaaaaaaa",
      "aaaaaaaaaaaaaaaa",
      "aaaaaaaaaaaaaaaa",
      "aaabaaaaaaaabaaa",
      "aaaaaaaaaaaaaaaa",
      "aaaaaaaaaaaaaaaa",
      "aaaaaaaaaaaaaaaa",
      "aaaaaaaaaaaaaaaa",
      "aaaaaaaaaaaaaaaa",
      "aaaaaaaaaaaaaaaa"
    ],
    [
      " cd e     fe  g ",
      "  dhdi    ce j  ",
      "  eb!k     ebe  ",
      " ce ef    le e k",
      "  e el     e e  ",
      "  m m      m m  ",
      "              f ",
      "                ",
      "   n        n   ",
      "oooboppqrppobooo",
      "   n        n   ",
      "                ",
      "                ",
      "st   tuwwxt  t y",
      "A     B  A     B",
      "A   t B  A t   B"
    ],
    [
      "    j      C    ",
      "           D    ",
      "  EbF      CbF  ",
      "    j      I j  ",
      "  C J      K L  ",
      "                ",
      "                ",
      "                ",
      "   M        N   ",
      "OOoboppPQppoboOO",
      "   N        N   ",
      "                ",
      "                ",
      "      RST       ",
      "U     V  W     X",
      "      T  U      "
    ],
    [
      "                ",
      "                ",
      "   b        b   ",
      "                ",
      "                ",
      "                ",
      "                ",
      "                ",
      "            Y   ",
      "OOoboppppppoboOO",
      "   Y        Y   ",
      "                ",
      "                ",
      "                ",
      "                ",
      "                "
    ],
    [
      "                ",
      "                ",
      "   b        b   ",
      "                ",
      "                ",
      "                ",
      "              ! ",
      "                ",
      "                ",
      "oooboooooooobooo",
      "                ",
      "                ",
      "                ",
      "                ",
      "                ",
      "                "
    ],
    [
      "Z0ZZZ0ZZZZ1ZZZ0Z",
      "ZZZZZZZZZZZZZZZZ",
      "ZZZbZZZZZZZZbZZZ",
      "ZZZZZZZZZZZZZZZZ",
      "Z0ZZZ1ZZZZ0ZZZ0Z",
      "Z0ZZZ ZZZZ0ZZZ0Z",
      "Z0ZZZ0ZZZZ0ZZZ1Z",
      "Z0ZZZ0ZZZZ0ZZZ0Z",
      "ZZZZZZZZZZZZZZZZ",
      "222b22222222b222",
      "333o33333333oa33",
      "333o33333333o333",
      "333o33333333o333",
      "433o33445533o335",
      "533o33433533o335",
      "533o33533433o334"
    ]
  ]
}