{
  "name": "multi_laboratory_8_base1",
  "refpalette": "deceasedcraft:multi_laboratory_8/multi_laboratory_8_base1_palette",
  "xsize": 16,
  "zsize": 16,
  "slices": [
    [
      "aaaaaabaabaaaaaa",
      "aaaaaacaacaaaaaa",
      "aaadaaaaaaaadaaa",
      "eeaaaaaaaaaaaaee",
      "eeaaaaaaaaaaaaee",
      "eeaaaaaaaaaaaaee",
      "eeaaaaaaaaaaaaee",
      "eeaaaaaaaaaaaaee",
      "aaaaaaaaaaaaaaaa",
      "aaadaaaaaaaadaaa",
      "aaaaaaaaaaaaaaaa",
      "aaaaaaaaaaaaaaaa",
      "aaaaaaaaaaaaaaaa",
      "aaaaaaaaaaaaaaaa",
      "aaaaaaaaaaaaaaaa",
      "aaaaaaaaaaaaaaaa"
    ],
    [
      "     fghfgh     ",
      "      b  b      ",
      "  id        di  ",
      "              j ",
      "                ",
      " k            k ",
      "lm            lm",
      "k             k ",
      "  in        ni  ",
      "oood        dooo",
      " p           kqq",
      "                ",
      "                ",
      "                ",
      "                ",
      "irrn        nrri"
    ],
    [
      "                ",
      "     fghfgh     ",
      "  sd  b  b  ds  ",
      "                ",
      "                ",
      "                ",
      "              t ",
      "                ",
      "  s          s  ",
      "uuod        douu",
      "              w ",
      "                ",
      "                ",
      "                ",
      "                ",
      "s              s"
    ],
    [
      "                ",
      "                ",
      "  xd fghfgh dx  ",
      "      b  b      ",
      "                ",
      "                ",
      "                ",
      "                ",
      "  x          x  ",
      "yyod        doyy",
      "                ",
      "                ",
      "                ",
      "                ",
      "                ",
      "x              x"
    ],
    [
      "                ",
      "                ",
      "   d        d   ",
      "     fghfgh     ",
      "      b  b      ",
      "                ",
      "                ",
      "                ",
      "                ",
      "AAod        doAA",
      "                ",
      "                ",
      "                ",
      "                ",
      "                ",
      "                "
    ],
    [
      "BBBB        BBBB",
      "BBBB        BBBB",
      "BBBd        dBBB",
      "BBBB        BBBB",
      "BBBB fghfgh BBBB",
      "BBBB  b  b  BBBB",
      "BBBB bb  bb BBBB",
      "BBBB        BBBB",
      "BBBBBBBBBBBBBBBB",
      "ooodBBBBBBBBdooo",
      "BBBBBBBBBBBBBBBB",
      "BCBBBBCBBCBBBBCB",
      "BCBBBBCBBCBBBBCB",
      "BCBBBBCBBCBBBBCB",
      "BCBBBBCBBCBBBBCB",
      "BBBBBBBBBBBBBBBB"
    ]
  ]
}