{
  "name": "multi_laboratory_8_base5",
  "refpalette": "deceasedcraft:multi_laboratory_8/multi_laboratory_8_base5_palette",
  "xsize": 16,
  "zsize": 16,
  "slices": [
    [
      "                ",
      "                ",
      "aaabaaaaaaaabaaa",
      "   c            ",
      "                ",
      "                ",
      "                ",
      "                ",
      "  dddddddddddd  ",
      "  de         d  ",
      "  df         d  ",
      "  d          d  ",
      "  d          d  ",
      "  d          d  ",
      "  d      g   d  ",
      "  d      hi  d  "
    ],
    [
      "                ",
      "                ",
      "aaabaaaaaaaabaaa",
      "                ",
      "                ",
      "                ",
      "                ",
      "                ",
      "  dddddddddddd  ",
      "  de         d  ",
      "  d j        d  ",
      "  d k        d  ",
      "  d l        d  ",
      "  d m        d  ",
      "  d      n   d  ",
      "  d      hh  d  "
    ],
    [
      "                ",
      "                ",
      "aaabaaaaaaaabaaa",
      "                ",
      "                ",
      "                ",
      "                ",
      "                ",
      "  dddddddddddd  ",
      "  dop        d  ",
      "  d          d  ",
      "  d n        d  ",
      "  d          d  ",
      "  d          d  ",
      "  d    p n   d  ",
      "  d      hfi d  "
    ],
    [
      "                ",
      "                ",
      "aaabaaaaaaaabaaa",
      "                ",
      "                ",
      "                ",
      "                ",
      "                ",
      "  dddddddddddd  ",
      "  deq        d  ",
      "  dp      g  d  ",
      "  d rp       d  ",
      "  d          d  ",
      "  d          d  ",
      "  d    q n   d  ",
      "  d      h h d  "
    ],
    [
      "                ",
      "                ",
      "sssbssssssssbsss",
      "                ",
      "                ",
      "                ",
      "                ",
      "                ",
      "  dddddddddddd  ",
      "  dee        d  ",
      "  deeo    n  d  ",
      "  d rqi      d  ",
      "  d          d  ",
      "  d    p     d  ",
      "  d    o n   d  ",
      "  d    !efoh d  "
    ],
    [
      "tttttttttttttttt",
      "tttttttttttttttt",
      "uuubuuuuuuuubuuu",
      "wwwwwwwwwwwwwwww",
      "wwwwwwwwwwwwwwww",
      "wwwwwwwwwwwwwwww",
      "wwwwwwwwwwwwwwww",
      "wwwwwwwwwwwwwwww",
      "wwxxxxxxxxxxxxww",
      "wwxyyyAyyAAAAxww",
      "wwxABCDDDDEBAxww",
      "wwxyFoeyyyyFyxww",
      "wwxAFe yyyyFAxww",
      "wwxyFyeeyyyFyxww",
      "wwxyFCDDDDEFyxww",
      "wwxyFyyyyyyFyxww"
    ]
  ]
}