{
  "name": "multi_laboratory_8_ground",
  "refpalette": "deceasedcraft:multi_laboratory_8/multi_laboratory_8_ground_palette",
  "xsize": 16,
  "zsize": 16,
  "slices": [
    [
      "aaaaa      aaaaa",
      "aaaaa      aaaaa",
      "aaaaa      aaaaa",
      "aaaaa      aaaaa",
      "aaaaa      aaaaa",
      "aaaaabcdecbaaaaa",
      "aaaaaff  ffaaaaa",
      "aaaaaaaaaaaaaaaa",
      "aaaaaaaaaaaaaaaa",
      "aaaaaaaaaaaaaaaa",
      "aaaaaaghhgaaaaaa",
      "aaaaaghgghgaaaaa",
      "aaaaahgggghaaaaa",
      "aaaaaggggggaaaaa",
      "aaaaaggggggaaaaa",
      "aaaaaggggggaaaaa"
    ],
    [
      "  ije      dk  l",
      "  ije      dk  m",
      "n ije      dk  m",
      "  oje      dko p",
      "qrq  b    b  qsq",
      "t ujewd  ewdkx  ",
      "  yje ddee dkA  ",
      "qBqC   DD   EqFq",
      "  oj        ko  ",
      "   d        e   ",
      "I  d   J    e  K",
      "LM d        e NO",
      "L P   J  Q   R O",
      "L S    T     U O",
      "LM d        e NO",
      "V  d    W   e  X"
    ],
    [
      "  Yj        k   ",
      "  Yj        k   ",
      "  Zj        k   ",
      "  0j b    b k0  ",
      "q1q ewd  ewd q2q",
      "   j        k   ",
      "   j        k   ",
      "q3q          q4q",
      "  0j        k0  ",
      "   d        e   ",
      "   d        e   ",
      "   d        e  5",
      "  6          7  ",
      "  8          9  ",
      "#  d        e   ",
      "   d        e   "
    ],
    [
      "  $j        k   ",
      "   j        k   ",
      "   j b    b k   ",
      "  %jewd  ewdk%  ",
      "q^q          q^q",
      "  Yj        k&  ",
      "  Yj        k&  ",
      "q*q          q*q",
      "  %j        k%  ",
      "   d        e   ",
      "   d        e   ",
      "   d        e   ",
      "   d        e   ",
      "   d        e   ",
      "   d        e   ",
      "   d        e   "
    ],
    [
      "   j        k   ",
      "   j b    b k   ",
      "   jewd  ewdk   ",
      "   j        k   ",
      "qqq          qqq",
      "  (j        k   ",
      "  )j        k+  ",
      "qqq          qqq",
      "   j        k   ",
      "   d        e   ",
      "   d        e   ",
      "   d        e   ",
      "   d        e   ",
      "   d        e   ",
      "   d        e   ",
      "   d        e   "
    ],
    [
      "--[j b    b k[]-",
      "--[jewd  ewdk[]-",
      "[[[j        k[[[",
      "[[[j        k[[[",
      "qqqj        kqqq",
      "  )j        k[-]",
      "   j        k[-]",
      "qqq{}}}}}}}}|qqq",
      "[[[j        k[[[",
      "[[[j        k[[[",
      "--[j        k[]]",
      "--[j        k[]]",
      "[[[j        k[[[",
      "[[[j        k[[[",
      "]-[j        k[--",
      "]-[j        k[--"
    ]
  ]
}