{
  "name": "multi_laboratory_8_base3",
  "refpalette": "deceasedcraft:multi_laboratory_8/multi_laboratory_8_base3_palette",
  "xsize": 16,
  "zsize": 16,
  "slices": [
    [
      "abbbbbbcbbbbbbbb",
      "bbbbbbbbbbbbbbbc",
      "bbbdbbbabbbbdbbb",
      "bb!bbbbbbbbbbbbb",
      "bbbbbbebbbbbfbbb",
      "bcbbbbbbbbfbbbbb",
      "bbbbabbcbagbbbeb",
      "bbbbbbbbbbgbbbbb",
      "bbbbbbggbfbbbbbb",
      "bbbdbbbgggbbdbbb",
      "bbbbbbbb!bbbbbbb",
      "bbbbbbbgfgbbbbbb",
      "bbbhbbfgbgbbbbbb",
      "bbbehbbbgbbbbebb",
      "bbbbbbhbbbebbhbb",
      "bbbbhbbbbbhbbbbb"
    ],
    [
      "  i ij  k  i lmn",
      " oi im    pi iq ",
      " ridi o   sldit ",
      "  uqlw   xy glAB",
      "kCi       DgEl F",
      "  lFr  AI D  Jr ",
      "      K   u    L",
      " rMNo  O nP KQo ",
      "   RKgD  DggRS  ",
      "TTTdTUVP DVTdTTT",
      "WXYRZ01gE2YX3 24",
      "45Z67X84DD9X#7$%",
      "jF  4^& * (X) F ",
      "+ -  Z[gP K4  ^ ",
      "]Z {Q   }y   | F",
      ";  n  ]4 ]   : ]"
    ],
    [
      "  q '      <    ",
      "                ",
      "  Ld        d>  ",
      "            g,  ",
      "  <         D   ",
      "                ",
      "                ",
      "                ",
      "   . P     g.   ",
      "? TdTUU   UTdT??",
      " / ` 00ED   X0  ",
      "      X    X\u0370   ",
      "           Z    ",
      "       D        ",
      "                ",
      "                "
    ],
    [
      "                ",
      "           >    ",
      "   d        df  ",
      "            \u0371D  ",
      "                ",
      "                ",
      "                ",
      "                ",
      "           D    ",
      "??TdTU\u0372  U fdT ?",
      "  0  0 E\u0373   0   ",
      "                ",
      "                ",
      "                ",
      "                ",
      "                "
    ],
    [
      "                ",
      "           \u0374fg  ",
      "   d        dg\u0375 ",
      "                ",
      "                ",
      "                ",
      "                ",
      "                ",
      "                ",
      "TTTdTgfTTTTTdTTT",
      "       ff       ",
      "                ",
      "                ",
      "                ",
      "                ",
      "                "
    ],
    [
      "\u0376\u0377\u0376\u0376\u0376\u0377\u0376\u0376\u0376\u0376\u0377g\u0376\u0376\u0377\u0376",
      "\u0376\u0376\u0376\u0376\u0376\u0376\u0376\u0376\u0376\u0376\u0376gg\u0376\u0376\u0376",
      "\u0376\u0376\u0376d\u0376\u0376\u0376\u0376\u0376\u0376\u0376\u0376d\u0376\u0376\u0376",
      "\u0376\u0376\u0376\u0376\u0376\u0376\u0376\u0376\u0376\u0376\u0376\u0376\u0376\u0376\u0376\u0376",
      "\u0376\u0376\u0376\u0376\u0376\u037a\u0376\u0376\u0376\u0376\u0376\u0376\u0376\u0376\u037b\u0376",
      "\u0376\u0376\u0376\u0376\u0376\u037a\u0376\u0376\u0376\u0376\u0376\u0376\u0376\u0376\u037a\u0376",
      "\u0376\u0376\u0376\u0376\u0376\u037b\u0376\u0376\u0376\u0376\u0376\u0376\u0376\u0376\u037a\u0376",
      "\u0376 \u0376\u0376\u0376\u037b\u0376\u0376\u0376\u0376\u0376\u0376\u0376\u0376\u0376\u0376",
      "\u0376\u0376\u0376\u0376\u0376\u0376\u0376\u0376\u0376\u0376\u0376\u0376\u0376\u0376\u0376\u0376",
      "\u037c\u037c\u037cd\u037c\u037c\u037c\u037c\u037c\u037c\u037c\u037cd\u037c\u037c\u037c",
      "\u037d\u037d\u037dT\u037d\u037d\u037d\u037dgg\u037d\u037dT\u037d\u037d\u037d",
      "\u037d\u037d\u037dT\u037d\u037d\u037d\u037d\u037d\u037d\u037d\u037dT\u037d\u037d\u037d",
      "\u037d\u037d\u037dT\u037d\u037d\u037d\u037d\u037d\u037d\u037d\u037dT\u037d\u037d\u037d",
      "\u037e\u037d\u037dT\u037d\u037d\u037e\u037e\u037b\u037b\u037d\u037dT\u037d\u037d\u037e",
      "\u037e\u037d\u037dT\u037d\u037d\u037e\u037d\u037d\u037b\u037d\u037dT\u037d\u037d\u037a",
      "\u037a\u037d\u037dT\u037d\u037d\u037a\u037d\u037d\u037e\u037d\u037dT\u037d\u037d\u037e"
    ]
  ]
}