{
  "name": "building_apartmentsmallc_floor2_180",
  "refpalette": "deceasedcraft:building_apartmentsmallc/building_apartmentsmallc_floor2_palette_180",
  "xsize": 16,
  "zsize": 16,
  "slices": [
    [
      "                ",
      "   dddddddddddd ",
      "   diifiifffffd ",
      "   diifiifffffd ",
      "   dfifiiiffffd ",
      "   dffffifffffd ",
      "   dffffffffffd ",
      "   dffffffffffd ",
      "   dffffffffffd ",
      "   dffffffffffd ",
      " a gffffffffffd ",
      " ahggggbgfffffd ",
      " a   ebbbaddddd ",
      " a    cbba      ",
      " aaaaaaaaa      ",
      "                "
    ],
    [
      "                ",
      "   gggggggggggg ",
      "   gW g  gZ00Zg ",
      "   gYXgW g VV g ",
      "   ggUg! T  B g ",
      "   gI  gSg RQPg ",
      "   gNM g gOgggg ",
      "   gNM g   LKJg ",
      "   gI FgEDC   g ",
      "   g BA sy xxxg ",
      " awgutg   s   g ",
      " abggggrgqponmg ",
      " a  el   aggggg ",
      " a       a      ",
      " akkkjaaaa      ",
      "                "
    ],
    [
      "                ",
      "   ?gg?3//3//3? ",
      "   3 .g, g|  (g ",
      "   -:>g <g    g ",
      "   -g'g: ;    3 ",
      "   3|  g}g#{ ]g ",
      "   -   g g[gggg ",
      "   -   g +  )C6 ",
      "   3( *g&!    3 ",
      "   6  ^       3 ",
      " awg%$g#      3 ",
      " abgggg9g8 7 y6 ",
      " 5 el   4ag333g ",
      " k       a      ",
      " aaaaa221a      ",
      "                "
    ],
    [
      "                ",
      "   ?gg?3//3//3? ",
      "   3 \u0377g\u0376 g    g ",
      "   -\u0375 g  g    g ",
      "   -g\u0373g\u0375 \u0374    3 ",
      "   3   g\u0373g    g ",
      "   -   g g/gggg ",
      "   -   g      6 ",
      "   3   g      3 ",
      "   6  -       3 ",
      " awg  g       3 ",
      " abgggg\u0371g\u0372    6 ",
      " abl     ag\u0371\u0371\u0371g ",
      " abb\u0370    a      ",
      " ```aaaaaa      ",
      "                "
    ],
    [
      "                ",
      "   gggggggggggg ",
      "   g  g  g    g ",
      "   g  g  g    g ",
      "   gggg  g  \u037a g ",
      "   g   ggg    g ",
      "   g \u037a g gggggg ",
      "   g   g      g ",
      "   g  gg      g ",
      "   g  g \u037b   \u037a g ",
      " awg  g       g ",
      " abgggggg     g ",
      " a       aggggg ",
      " a  c\u0370   a      ",
      " aaaaaa222      ",
      "                "
    ],
    [
      "                ",
      "   gggggggggggg ",
      "   g\u037c\u037c\u037c\u037c\u037c\u037c\u037c\u037c\u037c\u037cg ",
      "   g\u037c\u037c\u037c\u037c\u037c\u037c\u037c\u037c\u037c\u037cg ",
      "   g\u037c\u037c\u037c\u037c\u037c\u037c\u037c\u037c\u037c\u037cg ",
      "   g\u037c\u037c\u037c\u037c\u037c\u037c\u037c\u037c\u037c\u037cg ",
      "   g\u037c\u037c\u037c\u037c\u037c\u037c\u037c\u037c\u037c\u037cg ",
      "   g\u037c\u037c\u037c\u037c\u037c\u037c\u037c\u037c\u037c\u037cg ",
      "   g\u037c\u037c\u037c\u037c\u037c\u037c\u037c\u037c\u037c\u037cg ",
      "   g\u037c\u037c\u037c\u037c\u037c\u037c\u037c\u037c\u037c\u037cg ",
      " a g\u037c\u037c\u037c\u037c\u037c\u037c\u037c\u037c\u037c\u037cg ",
      " jhgggggg\u037c\u037c\u037c\u037c\u037cg ",
      " j       aggggg ",
      " j   c\u0370  a      ",
      " aaaaaaaaa      ",
      "                "
    ]
  ]
}