{
  "name": "building_apartmentsmallc_top_270",
  "refpalette": "deceasedcraft:building_apartmentsmallc/building_apartmentsmallc_top_palette_270",
  "xsize": 16,
  "zsize": 16,
  "slices": [
    [
      "                ",
      " dddddddddddd   ",
      " dffffffffffd   ",
      " dffffffffffd   ",
      " dffffffffffd   ",
      " dffffffffffd   ",
      " dffffffffbbaaa ",
      " dfifffffffbbba ",
      " dfffffffffbbba ",
      " dfffffffffgeca ",
      " dffiffffffg  a ",
      " dfffffffffg  a ",
      " dddddddddgg  a ",
      "           h  a ",
      "          aaaaa ",
      "                "
    ],
    [
      "                ",
      " gggggggggggg   ",
      " gllllllllllg   ",
      " gl n    n lg   ",
      " gl iiiippnlg   ",
      " gl in  pp!lg   ",
      " glni     aaaaa ",
      " glii     ob  a ",
      " gl i n    m  a ",
      " gl i qq  obk a ",
      " gl inqq  ob  a ",
      " glllllllllb  j ",
      " ggggggggggb  j ",
      "          ob  j ",
      "          aaaaa ",
      "                "
    ],
    [
      "                ",
      "                ",
      "  llllllllll    ",
      "  l        l    ",
      "  l     pp l    ",
      "  l     ppnl    ",
      "  l       aaaaa ",
      "  l       ob  r ",
      "  l        u  s ",
      "  l   xw  ob  s ",
      "  l   ww  ob  a ",
      "  lllllllllb  a ",
      "          ob  a ",
      "          ob  a ",
      "          aatja ",
      "                "
    ],
    [
      "                ",
      "                ",
      "                ",
      "                ",
      "        BB      ",
      "        BC      ",
      "          aaaaa ",
      "          ob  a ",
      "          oA  a ",
      "          ob  a ",
      "          ob  a ",
      "          ob  a ",
      "          ob  y ",
      "          ob  y ",
      "          aaaay ",
      "                "
    ],
    [
      "                ",
      "                ",
      "                ",
      "                ",
      "                ",
      "                ",
      "          aaaaa ",
      "          afffa ",
      "          afffa ",
      "          afffa ",
      "          afffa ",
      "          afffa ",
      "          afffa ",
      "          afffa ",
      "          aaaaa ",
      "                "
    ],
    [
      "                ",
      "                ",
      "                ",
      "                ",
      "                ",
      "                ",
      "          sssss ",
      "          s   s ",
      "          s   s ",
      "          s   s ",
      "          s   s ",
      "          s   s ",
      "          s   s ",
      "          s   s ",
      "          sssss ",
      "                "
    ]
  ]
}