{
  "name": "building_apartmentsmallc_floor1",
  "refpalette": "deceasedcraft:building_apartmentsmallc/building_apartmentsmallc_floor1_palette",
  "xsize": 16,
  "zsize": 16,
  "slices": [
    [
      "                ",
      "      aaaaaaaaa ",
      "      abbc    a ",
      " dddddabbbe   a ",
      " dfffffgbggggha ",
      " dffffffffffg a ",
      " dffffffffffd   ",
      " dffffffffffd   ",
      " dffffffffffd   ",
      " dffffffffffd   ",
      " dfffffiffffd   ",
      " dffffiiififd   ",
      " dfffffiifiid   ",
      " dfffffiifiid   ",
      " dddddddddddd   ",
      "                "
    ],
    [
      "                ",
      "      aaaajkkka ",
      "      a       a ",
      " ggggga   le  a ",
      " gmnopqgrggggba ",
      " g       gstgua ",
      " gwww xx yABg   ",
      " g    CDgE Fg   ",
      " gIJK   g LMg   ",
      " ggggNg g LMg   ",
      " gOPQ gRg  Fg   ",
      " gPS  T UgTgg   ",
      " gV W g XgYUg   ",
      " gW  Zg  g Xg   ",
      " gggggggggggg   ",
      "                "
    ],
    [
      "                ",
      "      a011aaaaa ",
      "      a       k ",
      " g222ga3   le 4 ",
      " 5  678g9ggggba ",
      " 2      #g $gua ",
      " 2       %  5   ",
      " 2    ^&g* (2   ",
      " 5)+- [ g   ]   ",
      " gggg{g g   ]   ",
      " gPV }g|g  (2   ",
      " 2;   : 'g:g]   ",
      " g    g  g ']   ",
      " g    g <g> 2   ",
      " ,2..2..2,gg,   ",
      "                "
    ],
    [
      "                ",
      "      aaaaaa??? ",
      "      a    /bba ",
      " g```ga     lba ",
      " 5    \u0370g`ggggba ",
      " 2       gV gua ",
      " 2       ]  5   ",
      " 2      g   2   ",
      " 5      g   ]   ",
      " gggg.g g   ]   ",
      " gV   g\u0371g   2   ",
      " 2    \u0372 \u0373g\u0371g]   ",
      " g    g  g \u0373]   ",
      " g    g \u0374g\u0375 2   ",
      " ,2..2..2,gg,   ",
      "                "
    ],
    [
      "                ",
      "      111aaaaaa ",
      "      a   /c  a ",
      " ggggga       a ",
      " g     ggggggba ",
      " g       g!Vgua ",
      " g \u0376   \u0377 gV g   ",
      " g      gg  g   ",
      " g      g   g   ",
      " gggggg g \u0376 g   ",
      " g    ggg   g   ",
      " g \u0376  g  gggg   ",
      " g    g  g  g   ",
      " g   Vg  g  g   ",
      " gggggggggggg   ",
      "                "
    ],
    [
      "                ",
      "      aaaaaaaaa ",
      "      a  /c   j ",
      " ggggga       j ",
      " g\u037a\u037a\u037a\u037a\u037agggggghj ",
      " g\u037a\u037a\u037a\u037a\u037a\u037a\u037a\u037a\u037a\u037ag a ",
      " g\u037a\u037a\u037a\u037a\u037a\u037a\u037a\u037a\u037a\u037ag   ",
      " g\u037a\u037a\u037a\u037a\u037a\u037a\u037a\u037a\u037a\u037ag   ",
      " g\u037a\u037a\u037a\u037a\u037a\u037a\u037a\u037a\u037a\u037ag   ",
      " g\u037a\u037a\u037a\u037a\u037a\u037a\u037a\u037a\u037a\u037ag   ",
      " g\u037a\u037a\u037a\u037a\u037a\u037a\u037a\u037a\u037a\u037ag   ",
      " g\u037a\u037a\u037a\u037a\u037a\u037a\u037a\u037a\u037a\u037ag   ",
      " g\u037a\u037a\u037a\u037a\u037a\u037a\u037a\u037a\u037a\u037ag   ",
      " g\u037a\u037a\u037a\u037a\u037a\u037a\u037a\u037a\u037a\u037ag   ",
      " gggggggggggg   ",
      "                "
    ]
  ]
}