{
  "name": "building_apartmentsmallc_top_180",
  "refpalette": "deceasedcraft:building_apartmentsmallc/building_apartmentsmallc_top_palette_180",
  "xsize": 16,
  "zsize": 16,
  "slices": [
    [
      "                ",
      "   dddddddddddd ",
      "   dffffffffffd ",
      "   dffffifffffd ",
      "   dfiffffffffd ",
      "   dffffffffffd ",
      "   dffffffffffd ",
      "   dffffffffffd ",
      "   dffffffffffd ",
      "   dffffffffffd ",
      " a gfffffbffffd ",
      " ahggggbbbffffd ",
      " a    ebbaddddd ",
      " a    cbba      ",
      " aaaaaaaaa      ",
      "                "
    ],
    [
      "                ",
      "   gggggggggggg ",
      "   gllllllllllg ",
      "   gl   in   lg ",
      "   gliiiiiiinlg ",
      "   gln    ni lg ",
      "   glqqn   i lg ",
      "   glqq    i lg ",
      "   gl     pp lg ",
      "   gl     ppnlg ",
      " aogloo oa!n lg ",
      " abbbbbmballllg ",
      " a    k  aggggg ",
      " a       a      ",
      " ajjjaaaaa      ",
      "                "
    ],
    [
      "                ",
      "                ",
      "    llllllllll  ",
      "    l        l  ",
      "    l        l  ",
      "    l        l  ",
      "    lwx      l  ",
      "    lww      l  ",
      "    l     pp l  ",
      "    l     pp l  ",
      " aooloo oan  l  ",
      " abbbbbuballll  ",
      " t       a      ",
      " j       a      ",
      " aaaaassra      ",
      "                "
    ],
    [
      "                ",
      "                ",
      "                ",
      "                ",
      "                ",
      "                ",
      "                ",
      "                ",
      "          BB    ",
      "          CB    ",
      " aoooooooa      ",
      " abbbbbAba      ",
      " a       a      ",
      " a       a      ",
      " yyyaaaaaa      ",
      "                "
    ],
    [
      "                ",
      "                ",
      "                ",
      "                ",
      "                ",
      "                ",
      "                ",
      "                ",
      "                ",
      "                ",
      " aaaaaaaaa      ",
      " afffffffa      ",
      " afffffffa      ",
      " afffffffa      ",
      " aaaaaaaaa      ",
      "                "
    ],
    [
      "                ",
      "                ",
      "                ",
      "                ",
      "                ",
      "                ",
      "                ",
      "                ",
      "                ",
      "                ",
      " sssssssss      ",
      " s       s      ",
      " s       s      ",
      " s       s      ",
      " sssssssss      ",
      "                "
    ]
  ]
}