{
  "name": "building_apartmentsmallc_ground_270",
  "refpalette": "deceasedcraft:building_apartmentsmallc/building_apartmentsmallc_ground_palette_270",
  "xsize": 16,
  "zsize": 16,
  "slices": [
    [
      "aaaaaaaaaaaaaaaa",
      "aeeeeeeeeeeeeaab",
      "aeffffffffffebba",
      "aeffffffffffebbb",
      "aeffffffffffeabb",
      "aeffffffffffeaaa",
      "aeffffffggggccca",
      "aefffffffffgddca",
      "aefffffffffdddca",
      "aefffffffffgddca",
      "aefffffffffgddca",
      "aefffffffffgddca",
      "aeeeeeeeeeeeddca",
      "aaaaaaaaaaadddca",
      "aaaaaaaaaaccccca",
      "aaaaaaaaaaaaaaaa"
    ],
    [
      "                ",
      " Nooooggoggog   ",
      " O EEA      j   ",
      " O LFB      k   ",
      " O   C      j   ",
      " O IIB  xpppg   ",
      " O   C  ggggccc ",
      " O MJB     gl c ",
      " O KKD     q  c ",
      " o       wrg  c ",
      " g        sgm c ",
      " g yy yy  tgdhc ",
      " Noooooooogg  c ",
      "          udnic ",
      "          ccccc ",
      "                "
    ],
    [
      "                ",
      " NooOoggoggog   ",
      " O   Z      j   ",
      " O   0      U   ",
      " O   0      j   ",
      " O   0   WWWg   ",
      " O   0  ggggccc ",
      " O   0   Y g  P ",
      " O   Z     X  Q ",
      " o         g  Q ",
      " g         g  c ",
      " g         gmRc ",
      " NOOOOOOOogg  c ",
      "          udnSc ",
      "          ccVTc ",
      "                "
    ],
    [
      "                ",
      " NooOoggoggog   ",
      " O   7      j   ",
      " O   0      j   ",
      " O   0      j   ",
      " O   0   WWWg   ",
      " O   0  ggggccc ",
      " O   0   6 g  c ",
      " O   7    43  c ",
      " o         g  c ",
      " g        5g  c ",
      " g        wg 2c ",
      " NOOOOOOOoggmd1 ",
      "          uddd1 ",
      "          cccc1 ",
      "                "
    ],
    [
      "                ",
      " gggggggggggg   ",
      " g          g   ",
      " g          g   ",
      " g          g   ",
      " g          g   ",
      " g      ggggccQ ",
      " g       9 g  Q ",
      " g         g  Q ",
      " g         g  c ",
      " g         g 2c ",
      " g         g 8c ",
      " ggggggggggg lc ",
      "          udl!c ",
      "          ccccc ",
      "                "
    ],
    [
      "                ",
      " gggggggggggg   ",
      " geeeeeeeeeeg   ",
      " geeeeeeeeeeg   ",
      " geeeeeeeeeeg   ",
      " geeeeeeeeeeg   ",
      " geeeeeeggggccc ",
      " geeeeeeeeeg  c ",
      " geeeeeeeeeg  c ",
      " geeeeeeeeeg 2c ",
      " geeeeeeeeeg 8c ",
      " geeeeeeeeeg  c ",
      " ggggggggggg  c ",
      "           # lc ",
      "          cTTTc ",
      "                "
    ]
  ]
}