{
  "name": "building_apartmentsmallc_floor2_270",
  "refpalette": "deceasedcraft:building_apartmentsmallc/building_apartmentsmallc_floor2_palette_270",
  "xsize": 16,
  "zsize": 16,
  "slices": [
    [
      "                ",
      " dddddddddddd   ",
      " dffffffffffd   ",
      " dffffffffffd   ",
      " dffffffffffd   ",
      " dffffffffffd   ",
      " dffifffffffaaa ",
      " diiiifffffgbba ",
      " diiiffffffbbba ",
      " dfffffffffgbca ",
      " diiiffffffge a ",
      " diifffffffg  a ",
      " dddddddddgg  a ",
      "           h  a ",
      "          aaaaa ",
      "                "
    ],
    [
      "                ",
      " gggggggggggg   ",
      " gZ  PgJ x mg   ",
      " g0VBQgK x ng   ",
      " g0V RgL x og   ",
      " gZ   O C spg   ",
      " gggTgg Dy qaaa ",
      " g   S  Es g  a ",
      " g W!gggg  r  a ",
      " gggg   FAgg  a ",
      " g XU MM Btgl j ",
      " gWYgINNI uge k ",
      " ggggggggggg  k ",
      "          wb  k ",
      "          aaaaa ",
      "                "
    ],
    [
      "                ",
      " ?gg3gg63336g   ",
      " 3(  ]gC   y3   ",
      " /    g)    3   ",
      " /   {g    73   ",
      " 3|  #[     g   ",
      " /gg;gg+!  8aaa ",
      " / < }  &  g4 1 ",
      " 3, :gggg #9  2 ",
      " ?ggg   *^gg  2 ",
      " g.>'     $g  a ",
      " g :g|  ( %gl a ",
      " ?3--3--36gge a ",
      "          wb  a ",
      "          aa5ka ",
      "                "
    ],
    [
      "                ",
      " ?gg3gg63336g   ",
      " 3    g     \u0371   ",
      " /    g     \u0371   ",
      " /    g     \u0371   ",
      " 3    /     g   ",
      " /gg\u0374gg    \u0372aaa ",
      " /   \u0373     g  a ",
      " 3\u0376 \u0375gggg  \u0371  a ",
      " ?ggg    -gg  a ",
      " g\u0377 \u0373      g  a ",
      " g \u0375g      g \u0370a ",
      " ?3--3--36gglb` ",
      "          wbbb` ",
      "          aaaa` ",
      "                "
    ],
    [
      "                ",
      " gggggggggggg   ",
      " g    g     g   ",
      " g  \u037a g  \u037a  g   ",
      " g    g     g   ",
      " g    g     g   ",
      " gggggg     aa2 ",
      " g   g   \u037b g  2 ",
      " g   gggg  g  2 ",
      " gggg   gggg  a ",
      " g  g \u037a    g \u0370a ",
      " g  g      g ca ",
      " ggggggggggg  a ",
      "          wb  a ",
      "          aaaaa ",
      "                "
    ],
    [
      "                ",
      " gggggggggggg   ",
      " g\u037c\u037c\u037c\u037c\u037c\u037c\u037c\u037c\u037c\u037cg   ",
      " g\u037c\u037c\u037c\u037c\u037c\u037c\u037c\u037c\u037c\u037cg   ",
      " g\u037c\u037c\u037c\u037c\u037c\u037c\u037c\u037c\u037c\u037cg   ",
      " g\u037c\u037c\u037c\u037c\u037c\u037c\u037c\u037c\u037c\u037cg   ",
      " g\u037c\u037c\u037c\u037c\u037c\u037c\u037c\u037c\u037c\u037caaa ",
      " g\u037c\u037c\u037c\u037c\u037c\u037c\u037c\u037c\u037cg  a ",
      " g\u037c\u037c\u037c\u037c\u037c\u037c\u037c\u037c\u037cg  a ",
      " g\u037c\u037c\u037c\u037c\u037c\u037c\u037c\u037c\u037cg \u0370a ",
      " g\u037c\u037c\u037c\u037c\u037c\u037c\u037c\u037c\u037cg ca ",
      " g\u037c\u037c\u037c\u037c\u037c\u037c\u037c\u037c\u037cg  a ",
      " ggggggggggg  a ",
      "           h  a ",
      "          ajjja ",
      "                "
    ]
  ]
}