{
  "name": "building_apartmentsmallc_floor1_270",
  "refpalette": "deceasedcraft:building_apartmentsmallc/building_apartmentsmallc_floor1_palette_270",
  "xsize": 16,
  "zsize": 16,
  "slices": [
    [
      "                ",
      " dddddddddddd   ",
      " dffffffffffd   ",
      " dffffffffffd   ",
      " dffffffffffd   ",
      " dffffffffffd   ",
      " dffifffffffaaa ",
      " diiiifffffgbba ",
      " diiiffffffbbba ",
      " dfffffffffgbca ",
      " diiiffffffge a ",
      " diifffffffg  a ",
      " dddddddddgg  a ",
      "           h  a ",
      "          aaaaa ",
      "                "
    ],
    [
      "                ",
      " gggggggggggg   ",
      " gWVPOgI w mg   ",
      " g  SPgJ w ng   ",
      " g W QgK w og   ",
      " gZ   N    pg   ",
      " gggTgg Cx qaaa ",
      " g   R  Dx g  a ",
      " g XUgggg  r  a ",
      " gggg   Eygg  a ",
      " g YT LL Asgl j ",
      " gXUgFMMFBtge k ",
      " ggggggggggg  k ",
      "          ub  k ",
      "          aaaaa ",
      "                "
    ],
    [
      "                ",
      " ,gg2gg52225g   ",
      " 2  ;Pg)    2   ",
      " .   Vg+    2   ",
      " .    g-   62   ",
      " 2   }{    7g   ",
      " .gg:gg[^  8aaa ",
      " .   |  &  g3 0 ",
      " 2< 'gggg #9  1 ",
      " ,ggg   *%gg  1 ",
      " g> :      g  a ",
      " g 'g(  ( $gl a ",
      " ,2]]2]]25gge a ",
      "          ub  a ",
      "          aa4ka ",
      "                "
    ],
    [
      "                ",
      " ,gg2gg52225g   ",
      " 2   Vg     `   ",
      " .    g     `   ",
      " .    g     `   ",
      " 2    .     g   ",
      " .gg\u0372gg    \u0370aaa ",
      " .   \u0371     g  a ",
      " 2\u0374 \u0373gggg  `  a ",
      " ,ggg    ]gg  a ",
      " g\u0375 \u0371     Vg  a ",
      " g \u0373g      g /a ",
      " ,2]]2]]25gglb? ",
      "          ubbb? ",
      "          aaaa? ",
      "                "
    ],
    [
      "                ",
      " gggggggggggg   ",
      " g    g     g   ",
      " g  \u0376 g  \u0376  g   ",
      " g    g     g   ",
      " gV   g     g   ",
      " gggggg     aa1 ",
      " g   g   \u0377 g  1 ",
      " g   gggg  g  1 ",
      " gggg   gggg  a ",
      " g  g \u0376  V!g /a ",
      " g  g     Vg ca ",
      " ggggggggggg  a ",
      "          ub  a ",
      "          aaaaa ",
      "                "
    ],
    [
      "                ",
      " gggggggggggg   ",
      " g\u037a\u037a\u037a\u037a\u037a\u037a\u037a\u037a\u037a\u037ag   ",
      " g\u037a\u037a\u037a\u037a\u037a\u037a\u037a\u037a\u037a\u037ag   ",
      " g\u037a\u037a\u037a\u037a\u037a\u037a\u037a\u037a\u037a\u037ag   ",
      " g\u037a\u037a\u037a\u037a\u037a\u037a\u037a\u037a\u037a\u037ag   ",
      " g\u037a\u037a\u037a\u037a\u037a\u037a\u037a\u037a\u037a\u037aaaa ",
      " g\u037a\u037a\u037a\u037a\u037a\u037a\u037a\u037a\u037ag  a ",
      " g\u037a\u037a\u037a\u037a\u037a\u037a\u037a\u037a\u037ag  a ",
      " g\u037a\u037a\u037a\u037a\u037a\u037a\u037a\u037a\u037ag /a ",
      " g\u037a\u037a\u037a\u037a\u037a\u037a\u037a\u037a\u037ag ca ",
      " g\u037a\u037a\u037a\u037a\u037a\u037a\u037a\u037a\u037ag  a ",
      " ggggggggggg  a ",
      "           h  a ",
      "          ajjja ",
      "                "
    ]
  ]
}