{
  "name": "building_apartmentsmallc_top_90",
  "refpalette": "deceasedcraft:building_apartmentsmallc/building_apartmentsmallc_top_palette_90",
  "xsize": 16,
  "zsize": 16,
  "slices": [
    [
      "                ",
      " aaaaa          ",
      " a  h           ",
      " a  ggddddddddd ",
      " a  gfffffffffd ",
      " a  gffffffiffd ",
      " acegfffffffffd ",
      " abbbfffffffffd ",
      " abbbfffffffifd ",
      " aaabbffffffffd ",
      "   dffffffffffd ",
      "   dffffffffffd ",
      "   dffffffffffd ",
      "   dffffffffffd ",
      "   dddddddddddd ",
      "                "
    ],
    [
      "                ",
      " aaaaa          ",
      " j  bo          ",
      " j  bgggggggggg ",
      " j  blllllllllg ",
      " a  bo  qqni lg ",
      " a kbo  qq i lg ",
      " a  m    n i lg ",
      " a  bo     iilg ",
      " aaaaa     inlg ",
      "   gl!pp  ni lg ",
      "   glnppiiii lg ",
      "   gl n    n lg ",
      "   gllllllllllg ",
      "   gggggggggggg ",
      "                "
    ],
    [
      "                ",
      " ajtaa          ",
      " a  bo          ",
      " a  bo          ",
      " a  blllllllll  ",
      " a  bo  ww   l  ",
      " s  bo  wx   l  ",
      " s  u        l  ",
      " r  bo       l  ",
      " aaaaa       l  ",
      "    lnpp     l  ",
      "    l pp     l  ",
      "    l        l  ",
      "    llllllllll  ",
      "                ",
      "                "
    ],
    [
      "                ",
      " yaaaa          ",
      " y  bo          ",
      " y  bo          ",
      " a  bo          ",
      " a  bo          ",
      " a  bo          ",
      " a  Ao          ",
      " a  bo          ",
      " aaaaa          ",
      "      CB        ",
      "      BB        ",
      "                ",
      "                ",
      "                ",
      "                "
    ],
    [
      "                ",
      " aaaaa          ",
      " afffa          ",
      " afffa          ",
      " afffa          ",
      " afffa          ",
      " afffa          ",
      " afffa          ",
      " afffa          ",
      " aaaaa          ",
      "                ",
      "                ",
      "                ",
      "                ",
      "                ",
      "                "
    ],
    [
      "                ",
      " sssss          ",
      " s   s          ",
      " s   s          ",
      " s   s          ",
      " s   s          ",
      " s   s          ",
      " s   s          ",
      " s   s          ",
      " sssss          ",
      "                ",
      "                ",
      "                ",
      "                ",
      "                ",
      "                "
    ]
  ]
}