{
  "name": "building_apartmentsmallc_ground_180",
  "refpalette": "deceasedcraft:building_apartmentsmallc/building_apartmentsmallc_ground_palette_180",
  "xsize": 16,
  "zsize": 16,
  "slices": [
    [
      "aaaaaaaaaaaaaaaa",
      "aaaeeeeeeeeeeeea",
      "aaaeffffffffffea",
      "aaaeffffffffffea",
      "aaaeffffffffffea",
      "aaaeffffffffffea",
      "aaaeffffffffffea",
      "aaaeffffffffffea",
      "aaaefffffgffffea",
      "aaaefffffgffffea",
      "acaefffffgffffea",
      "acdegggdggffffea",
      "acdddddddceeeeea",
      "acdddddddcaabbaa",
      "acccccccccabbbaa",
      "aaaaaaaaaaabbaba"
    ],
    [
      "                ",
      "   NggoOOOOOOON ",
      "   o          o ",
      "   oy  KM I LEo ",
      "   oy  KJ I FEo ",
      "   o   DBCBCBAo ",
      "   oy         g ",
      "   oy         g ",
      "   o     gx   o ",
      "   o  w  gp   g ",
      " cugtsr  gp   g ",
      " cdggggqggp   o ",
      " cn dm  lcgjkjg ",
      " ci h    c      ",
      " ccccccccc      ",
      "                "
    ],
    [
      "                ",
      "   NggoOOOOOOON ",
      "   O          o ",
      "   O          o ",
      "   O          O ",
      "   O   Z00000Zo ",
      "   O          g ",
      "   O          g ",
      "   O     g    o ",
      "   o    YgW   g ",
      " cug     gW   g ",
      " cdggggXggW   o ",
      " Vn m    cgjUjg ",
      " TS R    c      ",
      " cccccQQPc      ",
      "                "
    ],
    [
      "                ",
      "   NggoOOOOOOON ",
      "   O          o ",
      "   O          o ",
      "   O          O ",
      "   O   7000007o ",
      "   O          g ",
      "   O          g ",
      "   O     g    o ",
      "   o    6gW   g ",
      " cugw5 4 gW   g ",
      " cdgggg3ggW   o ",
      " cdm     cgjjjg ",
      " cdd2    c      ",
      " 111cccccc      ",
      "                "
    ],
    [
      "                ",
      "   gggggggggggg ",
      "   g          g ",
      "   g          g ",
      "   g          g ",
      "   g          g ",
      "   g          g ",
      "   g          g ",
      "   g     g    g ",
      "   g    9g    g ",
      " cug     g    g ",
      " cdggggggg    g ",
      " cl      cggggg ",
      " c!l82   c      ",
      " ccccccQQQ      ",
      "                "
    ],
    [
      "                ",
      "   gggggggggggg ",
      "   geeeeeeeeeeg ",
      "   geeeeeeeeeeg ",
      "   geeeeeeeeeeg ",
      "   geeeeeeeeeeg ",
      "   geeeeeeeeeeg ",
      "   geeeeeeeeeeg ",
      "   geeeeegeeeeg ",
      "   geeeeegeeeeg ",
      " c geeeeegeeeeg ",
      " T#gggggggeeeeg ",
      " T       cggggg ",
      " Tl  82  c      ",
      " ccccccccc      ",
      "                "
    ]
  ]
}