{
  "name": "building_apartmentsmallc_floor3_180",
  "refpalette": "deceasedcraft:building_apartmentsmallc/building_apartmentsmallc_floor3_palette_180",
  "xsize": 16,
  "zsize": 16,
  "slices": [
    [
      "                ",
      "   dddddddddddd ",
      "   diifiifffffd ",
      "   diifiifffffd ",
      "   dfifiiiffffd ",
      "   dffffifffffd ",
      "   dffffffffffd ",
      "   dffffffffffd ",
      "   dffffffffffd ",
      "   dffffffffffd ",
      " a gffffffffffd ",
      " ahggggbgfffffd ",
      " a   ebbbaddddd ",
      " a    cbba      ",
      " aaaaaaaaa      ",
      "                "
    ],
    [
      "                ",
      "   gggggggggggg ",
      "   gU g  gVWWVg ",
      "   gR gUTg SS g ",
      "   ggPgR Q   yg ",
      "   gD  gPg ONMg ",
      "   gKJ g gLgggg ",
      "   gKJ g   IFEg ",
      "   gD  gCB    g ",
      "   gAyx ww uuug ",
      " atgsrg       g ",
      " abggggqgponmlg ",
      " a  ek   aggggg ",
      " a       a      ",
      " ajjjaaaaa      ",
      "                "
    ],
    [
      "                ",
      "   >gg>Z,,Z,,Z> ",
      "   Z <g' g%  %g ",
      "   );:g  g    g ",
      "   )g{g; |    Z ",
      "   Z}  g{g6][-g ",
      "   )   g g+gggg ",
      "   )   g ( *&^2 ",
      "   Z% $g #    Z ",
      "   2  9       Z ",
      " atg87g6      Z ",
      " abgggg5g4   32 ",
      " 1 ek   0agZZZg ",
      " j       a      ",
      " aaaaaYYXa      ",
      "                "
    ],
    [
      "                ",
      "   >gg>Z,,Z,,Z> ",
      "   Z \u0374g\u0373 g    g ",
      "   )\u0372 g  g    g ",
      "   )g\u0370g\u0372 \u0371  ! Z ",
      "   Z   g\u0370g    g ",
      "   )   g g,gggg ",
      "   )   g      2 ",
      "   Z   g      Z ",
      "   2  )       Z ",
      " atg  g       Z ",
      " abgggg/g`    2 ",
      " abk     ag///g ",
      " abb?    a      ",
      " ...aaaaaa      ",
      "                "
    ],
    [
      "                ",
      "   gggggggggggg ",
      "   g  g  g    g ",
      "   g  g  g    g ",
      "   gggg  g  \u0377 g ",
      "   g   ggg    g ",
      "   g \u0375 g gggggg ",
      "   g   g      g ",
      "   g  gg      g ",
      "   g  g \u0376   \u0375 g ",
      " atg  g       g ",
      " abgggggg     g ",
      " a       aggggg ",
      " a  c?   a      ",
      " aaaaaaYYY      ",
      "                "
    ],
    [
      "                ",
      "   gggggggggggg ",
      "   g\u037b\u037b\u037b\u037b\u037b\u037b\u037b\u037b\u037b\u037bg ",
      "   g\u037b\u037b\u037b\u037b\u037b\u037b\u037b\u037b\u037b\u037bg ",
      "   g\u037b\u037b\u037b\u037b\u037b\u037b\u037b\u037b\u037b\u037bg ",
      "   g\u037b\u037b\u037b\u037b\u037b\u037b\u037b\u037b\u037b\u037bg ",
      "   g\u037b\u037b\u037b\u037b\u037b\u037b\u037b\u037b\u037b\u037bg ",
      "   g\u037b\u037b\u037b\u037b\u037b\u037b\u037b\u037b\u037b\u037bg ",
      "   g\u037b\u037b\u037b\u037b\u037b\u037b\u037b\u037b\u037b\u037bg ",
      "   g\u037b\u037b\u037b\u037b\u037b\u037b\u037b\u037b\u037b\u037bg ",
      " a g\u037b\u037b\u037b\u037b\u037b\u037b\u037b\u037b\u037b\u037bg ",
      " \u037ahgggggg\u037b\u037b\u037b\u037b\u037bg ",
      " \u037a       aggggg ",
      " \u037a   c?  a      ",
      " aaaaaaaaa      ",
      "                "
    ]
  ]
}