{
  "name": "building_apartmentsmallc_ground",
  "refpalette": "deceasedcraft:building_apartmentsmallc/building_apartmentsmallc_ground_palette",
  "xsize": 16,
  "zsize": 16,
  "slices": [
    [
      "ababbaaaaaaaaaaa",
      "aabbbaccccccccca",
      "aabbaacdddddddca",
      "aeeeeecdddddddca",
      "aeffffggdgggedca",
      "aeffffgfffffeaca",
      "aeffffgfffffeaaa",
      "aeffffgfffffeaaa",
      "aeffffffffffeaaa",
      "aeffffffffffeaaa",
      "aeffffffffffeaaa",
      "aeffffffffffeaaa",
      "aeffffffffffeaaa",
      "aeffffffffffeaaa",
      "aeeeeeeeeeeeeaaa",
      "aaaaaaaaaaaaaaaa"
    ],
    [
      "                ",
      "      ccccccccc ",
      "      c    h ic ",
      " gjkjgcl  md nc ",
      " o   pggqggggdc ",
      " g   pg  rstguc ",
      " g   pg  w  o   ",
      " o   xg     o   ",
      " g         yo   ",
      " g         yo   ",
      " oABCBCBD   o   ",
      " oEF I JK  yo   ",
      " oEL I MK  yo   ",
      " o          o   ",
      " NOOOOOOOoggN   ",
      "                "
    ],
    [
      "                ",
      "      cPQQccccc ",
      "      c    R ST ",
      " gjUjgc    m nV ",
      " o   WggXggggdc ",
      " g   Wg     guc ",
      " g   WgY    o   ",
      " o    g     O   ",
      " g          O   ",
      " g          O   ",
      " oZ00000Z   O   ",
      " O          O   ",
      " o          O   ",
      " o          O   ",
      " NOOOOOOOoggN   ",
      "                "
    ],
    [
      "                ",
      "      cccccc111 ",
      "      c    2ddc ",
      " gjjjgc     mdc ",
      " o   Wgg3ggggdc ",
      " g   Wg 4 5wguc ",
      " g   Wg6    o   ",
      " o    g     O   ",
      " g          O   ",
      " g          O   ",
      " o7000007   O   ",
      " O          O   ",
      " o          O   ",
      " o          O   ",
      " NOOOOOOOoggN   ",
      "                "
    ],
    [
      "                ",
      "      QQQcccccc ",
      "      c   28l!c ",
      " gggggc      lc ",
      " g    gggggggdc ",
      " g    g     guc ",
      " g    g9    g   ",
      " g    g     g   ",
      " g          g   ",
      " g          g   ",
      " g          g   ",
      " g          g   ",
      " g          g   ",
      " g          g   ",
      " gggggggggggg   ",
      "                "
    ],
    [
      "                ",
      "      ccccccccc ",
      "      c  28  lT ",
      " gggggc       T ",
      " geeeeggggggg#T ",
      " geeeegeeeeeg c ",
      " geeeegeeeeeg   ",
      " geeeegeeeeeg   ",
      " geeeeeeeeeeg   ",
      " geeeeeeeeeeg   ",
      " geeeeeeeeeeg   ",
      " geeeeeeeeeeg   ",
      " geeeeeeeeeeg   ",
      " geeeeeeeeeeg   ",
      " gggggggggggg   ",
      "                "
    ]
  ]
}