{
  "name": "building_apartmentsmallc_floor2_90",
  "refpalette": "deceasedcraft:building_apartmentsmallc/building_apartmentsmallc_floor2_palette_90",
  "xsize": 16,
  "zsize": 16,
  "slices": [
    [
      "                ",
      " aaaaa          ",
      " a  h           ",
      " a  ggddddddddd ",
      " a  gfffffffiid ",
      " a egffffffiiid ",
      " acbgfffffffffd ",
      " abbbffffffiiid ",
      " abbgfffffiiiid ",
      " aaafffffffiffd ",
      "   dffffffffffd ",
      "   dffffffffffd ",
      "   dffffffffffd ",
      "   dffffffffffd ",
      "   dddddddddddd ",
      "                "
    ],
    [
      "                ",
      " aaaaa          ",
      " k  bw          ",
      " k  ggggggggggg ",
      " k egu INNIgYWg ",
      " j lgtB MM UX g ",
      " a  ggAF   gggg ",
      " a  r  gggg!W g ",
      " a  g sE  S   g ",
      " aaaq yD ggTggg ",
      "   gps C O   Zg ",
      "   go x LgR V0g ",
      "   gn x KgQBV0g ",
      "   gm x JgP  Zg ",
      "   gggggggggggg ",
      "                "
    ],
    [
      "                ",
      " ak5aa          ",
      " a  bw          ",
      " a egg63--3--3? ",
      " a lg% (  |g: g ",
      " a  g$     '>.g ",
      " 2  gg^*   ggg? ",
      " 2  9# gggg: ,3 ",
      " 1 4g  &  } < / ",
      " aaa8  !+gg;gg/ ",
      "   g     [#  |3 ",
      "   37    g{   / ",
      "   3    )g    / ",
      "   3y   Cg]  (3 ",
      "   g63336gg3gg? ",
      "                "
    ],
    [
      "                ",
      " `aaaa          ",
      " `bbbw          ",
      " `blgg63--3--3? ",
      " a\u0370 g      g\u0375 g ",
      " a  g      \u0373 \u0377g ",
      " a  gg-    ggg? ",
      " a  \u0371  gggg\u0375 \u03763 ",
      " a  g     \u0373   / ",
      " aaa\u0372    gg\u0374gg/ ",
      "   g     /    3 ",
      "   \u0371     g    / ",
      "   \u0371     g    / ",
      "   \u0371     g    3 ",
      "   g63336gg3gg? ",
      "                "
    ],
    [
      "                ",
      " aaaaa          ",
      " a  bw          ",
      " a  ggggggggggg ",
      " ac g      g  g ",
      " a\u0370 g    \u037a g  g ",
      " a  gggg   gggg ",
      " 2  g  gggg   g ",
      " 2  g \u037b   g   g ",
      " 2aa     gggggg ",
      "   g     g    g ",
      "   g     g    g ",
      "   g  \u037a  g \u037a  g ",
      "   g     g    g ",
      "   gggggggggggg ",
      "                "
    ],
    [
      "                ",
      " ajjja          ",
      " a  h           ",
      " a  ggggggggggg ",
      " a  g\u037c\u037c\u037c\u037c\u037c\u037c\u037c\u037c\u037cg ",
      " ac g\u037c\u037c\u037c\u037c\u037c\u037c\u037c\u037c\u037cg ",
      " a\u0370 g\u037c\u037c\u037c\u037c\u037c\u037c\u037c\u037c\u037cg ",
      " a  g\u037c\u037c\u037c\u037c\u037c\u037c\u037c\u037c\u037cg ",
      " a  g\u037c\u037c\u037c\u037c\u037c\u037c\u037c\u037c\u037cg ",
      " aaa\u037c\u037c\u037c\u037c\u037c\u037c\u037c\u037c\u037c\u037cg ",
      "   g\u037c\u037c\u037c\u037c\u037c\u037c\u037c\u037c\u037c\u037cg ",
      "   g\u037c\u037c\u037c\u037c\u037c\u037c\u037c\u037c\u037c\u037cg ",
      "   g\u037c\u037c\u037c\u037c\u037c\u037c\u037c\u037c\u037c\u037cg ",
      "   g\u037c\u037c\u037c\u037c\u037c\u037c\u037c\u037c\u037c\u037cg ",
      "   gggggggggggg ",
      "                "
    ]
  ]
}