{
  "name": "building_apartmentsmallc_floor1_180",
  "refpalette": "deceasedcraft:building_apartmentsmallc/building_apartmentsmallc_floor1_palette_180",
  "xsize": 16,
  "zsize": 16,
  "slices": [
    [
      "                ",
      "   dddddddddddd ",
      "   diifiifffffd ",
      "   diifiifffffd ",
      "   dfifiiiffffd ",
      "   dffffifffffd ",
      "   dffffffffffd ",
      "   dffffffffffd ",
      "   dffffffffffd ",
      "   dffffffffffd ",
      " a gffffffffffd ",
      " ahggggbgfffffd ",
      " a   ebbbaddddd ",
      " a    cbba      ",
      " aaaaaaaaa      ",
      "                "
    ],
    [
      "                ",
      "   gggggggggggg ",
      "   gX g  gZ  Wg ",
      "   gUYgX g W Vg ",
      "   ggTgU T  SPg ",
      "   gF  gRg QPOg ",
      "   gML g gNgggg ",
      "   gML g   KJIg ",
      "   gF EgDC    g ",
      "   gBAy xx wwwg ",
      " augtsg       g ",
      " abggggrgqponmg ",
      " a  el   aggggg ",
      " a       a      ",
      " akkkjaaaa      ",
      "                "
    ],
    [
      "                ",
      "   ,gg,2..2..2, ",
      "   2 >g< g    g ",
      "   ]' g  g    g ",
      "   ]g:g' :   ;2 ",
      "   2(  g|g} VPg ",
      "   ]   g g{gggg ",
      "   ]   g [ -+)5 ",
      "   2( *g&^    2 ",
      "   5  %       2 ",
      " aug$ g#      2 ",
      " abgggg9g876  5 ",
      " 4 el   3ag222g ",
      " k       a      ",
      " aaaaa110a      ",
      "                "
    ],
    [
      "                ",
      "   ,gg,2..2..2, ",
      "   2 \u0375g\u0374 g    g ",
      "   ]\u0373 g  g    g ",
      "   ]g\u0371g\u0373 \u0372    2 ",
      "   2   g\u0371g   Vg ",
      "   ]   g g.gggg ",
      "   ]   g      5 ",
      "   2   g      2 ",
      "   5  ]       2 ",
      " aug Vg       2 ",
      " abgggg`g\u0370    5 ",
      " abl     ag```g ",
      " abb/    a      ",
      " ???aaaaaa      ",
      "                "
    ],
    [
      "                ",
      "   gggggggggggg ",
      "   g  g  gV   g ",
      "   g  g  g    g ",
      "   gggg  g  \u0376 g ",
      "   g   ggg    g ",
      "   g \u0376 g gggggg ",
      "   g   g      g ",
      "   g  gg      g ",
      "   g Vg \u0377   \u0376 g ",
      " augV!g       g ",
      " abgggggg     g ",
      " a       aggggg ",
      " a  c/   a      ",
      " aaaaaa111      ",
      "                "
    ],
    [
      "                ",
      "   gggggggggggg ",
      "   g\u037a\u037a\u037a\u037a\u037a\u037a\u037a\u037a\u037a\u037ag ",
      "   g\u037a\u037a\u037a\u037a\u037a\u037a\u037a\u037a\u037a\u037ag ",
      "   g\u037a\u037a\u037a\u037a\u037a\u037a\u037a\u037a\u037a\u037ag ",
      "   g\u037a\u037a\u037a\u037a\u037a\u037a\u037a\u037a\u037a\u037ag ",
      "   g\u037a\u037a\u037a\u037a\u037a\u037a\u037a\u037a\u037a\u037ag ",
      "   g\u037a\u037a\u037a\u037a\u037a\u037a\u037a\u037a\u037a\u037ag ",
      "   g\u037a\u037a\u037a\u037a\u037a\u037a\u037a\u037a\u037a\u037ag ",
      "   g\u037a\u037a\u037a\u037a\u037a\u037a\u037a\u037a\u037a\u037ag ",
      " a g\u037a\u037a\u037a\u037a\u037a\u037a\u037a\u037a\u037a\u037ag ",
      " jhgggggg\u037a\u037a\u037a\u037a\u037ag ",
      " j       aggggg ",
      " j   c/  a      ",
      " aaaaaaaaa      ",
      "                "
    ]
  ]
}