{
  "name": "building_apartmentsmallc_floor3_90",
  "refpalette": "deceasedcraft:building_apartmentsmallc/building_apartmentsmallc_floor3_palette_90",
  "xsize": 16,
  "zsize": 16,
  "slices": [
    [
      "                ",
      " aaaaa          ",
      " a  h           ",
      " a  ggddddddddd ",
      " a  gfffffffiid ",
      " a egffffffiiid ",
      " acbgfffffffffd ",
      " abbbffffffiiid ",
      " abbgfffffiiiid ",
      " aaafffffffiffd ",
      "   dffffffffffd ",
      "   dffffffffffd ",
      "   dffffffffffd ",
      "   dffffffffffd ",
      "   dddddddddddd ",
      "                "
    ],
    [
      "                ",
      " aaaaa          ",
      " j  bt          ",
      " j  ggggggggggg ",
      " j egsADKKDgRUg ",
      " a kgry JJ P  g ",
      " a  ggx    gggg ",
      " a  q  ggggRU g ",
      " a  g wC  P T g ",
      " aaap wB ggQggg ",
      "   go    L   Vg ",
      "   gn u IgO SWg ",
      "   gm u FgN SWg ",
      "   gl u EgMy Vg ",
      "   gggggggggggg ",
      "                "
    ],
    [
      "                ",
      " aj1aa          ",
      " a  bt          ",
      " a egg2Z))Z))Z> ",
      " a kg8 %  }g; g ",
      " a  g7     {:<g ",
      " Y  gg9$   ggg> ",
      " Y  56 gggg; 'Z ",
      " X 0g     {   , ",
      " aaa4  #(gg|gg, ",
      "   g     +6  %Z ",
      "   Z    *g]   , ",
      "   Z    &g[   , ",
      "   Z3   ^g-  %Z ",
      "   g2ZZZ2ggZgg> ",
      "                "
    ],
    [
      "                ",
      " .aaaa          ",
      " .bbbt          ",
      " .bkgg2Z))Z))Z> ",
      " a? g      g\u0372 g ",
      " a  g      \u0370 \u0374g ",
      " a  gg)    ggg> ",
      " a  /  gggg\u0372 \u0373Z ",
      " a  g     \u0370   , ",
      " aaa`    gg\u0371gg, ",
      "   g     ,    Z ",
      "   /     g    , ",
      "   /     g !  , ",
      "   /     g    Z ",
      "   g2ZZZ2ggZgg> ",
      "                "
    ],
    [
      "                ",
      " aaaaa          ",
      " a  bt          ",
      " a  ggggggggggg ",
      " ac g      g  g ",
      " a? g    \u0375 g  g ",
      " a  gggg   gggg ",
      " Y  g  gggg   g ",
      " Y  g \u0376   g   g ",
      " Yaa     gggggg ",
      "   g     g    g ",
      "   g     g    g ",
      "   g  \u0375  g \u0377  g ",
      "   g     g    g ",
      "   gggggggggggg ",
      "                "
    ],
    [
      "                ",
      " a\u037a\u037a\u037aa          ",
      " a  h           ",
      " a  ggggggggggg ",
      " a  g\u037b\u037b\u037b\u037b\u037b\u037b\u037b\u037b\u037bg ",
      " ac g\u037b\u037b\u037b\u037b\u037b\u037b\u037b\u037b\u037bg ",
      " a? g\u037b\u037b\u037b\u037b\u037b\u037b\u037b\u037b\u037bg ",
      " a  g\u037b\u037b\u037b\u037b\u037b\u037b\u037b\u037b\u037bg ",
      " a  g\u037b\u037b\u037b\u037b\u037b\u037b\u037b\u037b\u037bg ",
      " aaa\u037b\u037b\u037b\u037b\u037b\u037b\u037b\u037b\u037b\u037bg ",
      "   g\u037b\u037b\u037b\u037b\u037b\u037b\u037b\u037b\u037b\u037bg ",
      "   g\u037b\u037b\u037b\u037b\u037b\u037b\u037b\u037b\u037b\u037bg ",
      "   g\u037b\u037b\u037b\u037b\u037b\u037b\u037b\u037b\u037b\u037bg ",
      "   g\u037b\u037b\u037b\u037b\u037b\u037b\u037b\u037b\u037b\u037bg ",
      "   gggggggggggg ",
      "                "
    ]
  ]
}