{
  "name": "building_apartmentsmallc_floor2",
  "refpalette": "deceasedcraft:building_apartmentsmallc/building_apartmentsmallc_floor2_palette",
  "xsize": 16,
  "zsize": 16,
  "slices": [
    [
      "                ",
      "      aaaaaaaaa ",
      "      abbc    a ",
      " dddddabbbe   a ",
      " dfffffgbggggha ",
      " dffffffffffg a ",
      " dffffffffffd   ",
      " dffffffffffd   ",
      " dffffffffffd   ",
      " dffffffffffd   ",
      " dfffffiffffd   ",
      " dffffiiififd   ",
      " dfffffiifiid   ",
      " dfffffiifiid   ",
      " dddddddddddd   ",
      "                "
    ],
    [
      "                ",
      "      aaaajkkka ",
      "      a       a ",
      " ggggga   le  a ",
      " gmnopqgrggggba ",
      " g   s   gtugwa ",
      " gxxx ys AB g   ",
      " g   CDEgF Ig   ",
      " gJKL   g MNg   ",
      " ggggOg g MNg   ",
      " gPQR gSg  Ig   ",
      " g B  T !gUgg   ",
      " g VV g WgXYg   ",
      " gZ00Zg  g Wg   ",
      " gggggggggggg   ",
      "                "
    ],
    [
      "                ",
      "      a122aaaaa ",
      "      a       k ",
      " g333ga4   le 5 ",
      " 6y 7 8g9ggggba ",
      " 3      #g$%gwa ",
      " 3       ^  6   ",
      " 3    !&g* (3   ",
      " 6C)  + g   -   ",
      " gggg[g g   -   ",
      " g] {#g}g  |3   ",
      " 3    ; :g'g-   ",
      " g    g< g>:-   ",
      " g(  |g ,g. 3   ",
      " ?3//3//3?gg?   ",
      "                "
    ],
    [
      "                ",
      "      aaaaaa``` ",
      "      a    \u0370bba ",
      " g\u0371\u0371\u0371ga     lba ",
      " 6    \u0372g\u0371ggggba ",
      " 3       g  gwa ",
      " 3       -  6   ",
      " 3      g   3   ",
      " 6      g   -   ",
      " gggg/g g   -   ",
      " g    g\u0373g   3   ",
      " 3    \u0374 \u0375g\u0373g-   ",
      " g    g  g \u0375-   ",
      " g    g \u0376g\u0377 3   ",
      " ?3//3//3?gg?   ",
      "                "
    ],
    [
      "                ",
      "      222aaaaaa ",
      "      a   \u0370c  a ",
      " ggggga       a ",
      " g     ggggggba ",
      " g       g  gwa ",
      " g \u037a   \u037b g  g   ",
      " g      gg  g   ",
      " g      g   g   ",
      " gggggg g \u037a g   ",
      " g    ggg   g   ",
      " g \u037a  g  gggg   ",
      " g    g  g  g   ",
      " g    g  g  g   ",
      " gggggggggggg   ",
      "                "
    ],
    [
      "                ",
      "      aaaaaaaaa ",
      "      a  \u0370c   j ",
      " ggggga       j ",
      " g\u037c\u037c\u037c\u037c\u037cgggggghj ",
      " g\u037c\u037c\u037c\u037c\u037c\u037c\u037c\u037c\u037c\u037cg a ",
      " g\u037c\u037c\u037c\u037c\u037c\u037c\u037c\u037c\u037c\u037cg   ",
      " g\u037c\u037c\u037c\u037c\u037c\u037c\u037c\u037c\u037c\u037cg   ",
      " g\u037c\u037c\u037c\u037c\u037c\u037c\u037c\u037c\u037c\u037cg   ",
      " g\u037c\u037c\u037c\u037c\u037c\u037c\u037c\u037c\u037c\u037cg   ",
      " g\u037c\u037c\u037c\u037c\u037c\u037c\u037c\u037c\u037c\u037cg   ",
      " g\u037c\u037c\u037c\u037c\u037c\u037c\u037c\u037c\u037c\u037cg   ",
      " g\u037c\u037c\u037c\u037c\u037c\u037c\u037c\u037c\u037c\u037cg   ",
      " g\u037c\u037c\u037c\u037c\u037c\u037c\u037c\u037c\u037c\u037cg   ",
      " gggggggggggg   ",
      "                "
    ]
  ]
}