{
  "name": "building_apartmentsmallc_floor1_90",
  "refpalette": "deceasedcraft:building_apartmentsmallc/building_apartmentsmallc_floor1_palette_90",
  "xsize": 16,
  "zsize": 16,
  "slices": [
    [
      "                ",
      " aaaaa          ",
      " a  h           ",
      " a  ggddddddddd ",
      " a  gfffffffiid ",
      " a egffffffiiid ",
      " acbgfffffffffd ",
      " abbbffffffiiid ",
      " abbgfffffiiiid ",
      " aaafffffffiffd ",
      "   dffffffffffd ",
      "   dffffffffffd ",
      "   dffffffffffd ",
      "   dffffffffffd ",
      "   dddddddddddd ",
      "                "
    ],
    [
      "                ",
      " aaaaa          ",
      " k  bu          ",
      " k  ggggggggggg ",
      " k egtBFMMFgUXg ",
      " j lgsA LL TY g ",
      " a  ggyE   gggg ",
      " a  r  ggggUX g ",
      " a  g xD  R   g ",
      " aaaq xC ggTggg ",
      "   gp    N   Zg ",
      "   go w KgQ W g ",
      "   gn w JgPS  g ",
      "   gm w IgOPVWg ",
      "   gggggggggggg ",
      "                "
    ],
    [
      "                ",
      " ak4aa          ",
      " a  bu          ",
      " a egg52]]2]]2, ",
      " a lg$ (  (g' g ",
      " a  g      : >g ",
      " 1  gg%*   ggg, ",
      " 1  9# gggg' <2 ",
      " 0 3g  &  |   . ",
      " aaa8  ^[gg:gg. ",
      "   g7    {}   2 ",
      "   26   -g    . ",
      "   2    +gV   . ",
      "   2    )gP;  2 ",
      "   g52225gg2gg, ",
      "                "
    ],
    [
      "                ",
      " ?aaaa          ",
      " ?bbbu          ",
      " ?blgg52]]2]]2, ",
      " a/ g      g\u0373 g ",
      " a  gV     \u0371 \u0375g ",
      " a  gg]    ggg, ",
      " a  `  gggg\u0373 \u03742 ",
      " a  g     \u0371   . ",
      " aaa\u0370    gg\u0372gg. ",
      "   g     .    2 ",
      "   `     g    . ",
      "   `     g    . ",
      "   `     gV   2 ",
      "   g52225gg2gg, ",
      "                "
    ],
    [
      "                ",
      " aaaaa          ",
      " a  bu          ",
      " a  ggggggggggg ",
      " ac gV     g  g ",
      " a/ g!V  \u0376 g  g ",
      " a  gggg   gggg ",
      " 1  g  gggg   g ",
      " 1  g \u0377   g   g ",
      " 1aa     gggggg ",
      "   g     g   Vg ",
      "   g     g    g ",
      "   g  \u0376  g \u0376  g ",
      "   g     g    g ",
      "   gggggggggggg ",
      "                "
    ],
    [
      "                ",
      " ajjja          ",
      " a  h           ",
      " a  ggggggggggg ",
      " a  g\u037a\u037a\u037a\u037a\u037a\u037a\u037a\u037a\u037ag ",
      " ac g\u037a\u037a\u037a\u037a\u037a\u037a\u037a\u037a\u037ag ",
      " a/ g\u037a\u037a\u037a\u037a\u037a\u037a\u037a\u037a\u037ag ",
      " a  g\u037a\u037a\u037a\u037a\u037a\u037a\u037a\u037a\u037ag ",
      " a  g\u037a\u037a\u037a\u037a\u037a\u037a\u037a\u037a\u037ag ",
      " aaa\u037a\u037a\u037a\u037a\u037a\u037a\u037a\u037a\u037a\u037ag ",
      "   g\u037a\u037a\u037a\u037a\u037a\u037a\u037a\u037a\u037a\u037ag ",
      "   g\u037a\u037a\u037a\u037a\u037a\u037a\u037a\u037a\u037a\u037ag ",
      "   g\u037a\u037a\u037a\u037a\u037a\u037a\u037a\u037a\u037a\u037ag ",
      "   g\u037a\u037a\u037a\u037a\u037a\u037a\u037a\u037a\u037a\u037ag ",
      "   gggggggggggg ",
      "                "
    ]
  ]
}