{
  "name": "building_apartmentsmallc_floor3",
  "refpalette": "deceasedcraft:building_apartmentsmallc/building_apartmentsmallc_floor3_palette",
  "xsize": 16,
  "zsize": 16,
  "slices": [
    [
      "                ",
      "      aaaaaaaaa ",
      "      abbc    a ",
      " dddddabbbe   a ",
      " dfffffgbggggha ",
      " dffffffffffg a ",
      " dffffffffffd   ",
      " dffffffffffd   ",
      " dffffffffffd   ",
      " dffffffffffd   ",
      " dfffffiffffd   ",
      " dffffiiififd   ",
      " dfffffiifiid   ",
      " dfffffiifiid   ",
      " dddddddddddd   ",
      "                "
    ],
    [
      "                ",
      "      aaaaajjja ",
      "      a       a ",
      " ggggga   ke  a ",
      " glmnopgqggggba ",
      " g       grsgta ",
      " guuu ww xyAg   ",
      " g    BCg  Dg   ",
      " gEFI   g JKg   ",
      " ggggLg g JKg   ",
      " gMNO gPg  Dg   ",
      " gy   Q RgPgg   ",
      " g SS gTUg Rg   ",
      " gVWWVg  g Ug   ",
      " gggggggggggg   ",
      "                "
    ],
    [
      "                ",
      "      aXYYaaaaa ",
      "      a       j ",
      " gZZZga0   ke 1 ",
      " 23   4g5ggggba ",
      " Z      6g78gta ",
      " Z       9  2   ",
      " Z    # g$ %Z   ",
      " 2^&* ( g   )   ",
      " gggg+g g   )   ",
      " g-[]6g{g  }Z   ",
      " Z    | ;g{g)   ",
      " g    g  g:;)   ",
      " g%  %g 'g< Z   ",
      " >Z,,Z,,Z>gg>   ",
      "                "
    ],
    [
      "                ",
      "      aaaaaa... ",
      "      a    ?bba ",
      " g///ga     kba ",
      " 2    `g/ggggba ",
      " Z       g  gta ",
      " Z       )  2   ",
      " Z      g   Z   ",
      " 2      g   )   ",
      " gggg,g g   )   ",
      " g    g\u0370g   Z   ",
      " Z !  \u0371 \u0372g\u0370g)   ",
      " g    g  g \u0372)   ",
      " g    g \u0373g\u0374 Z   ",
      " >Z,,Z,,Z>gg>   ",
      "                "
    ],
    [
      "                ",
      "      YYYaaaaaa ",
      "      a   ?c  a ",
      " ggggga       a ",
      " g     ggggggba ",
      " g       g  gta ",
      " g \u0375   \u0376 g  g   ",
      " g      gg  g   ",
      " g      g   g   ",
      " gggggg g \u0375 g   ",
      " g    ggg   g   ",
      " g \u0377  g  gggg   ",
      " g    g  g  g   ",
      " g    g  g  g   ",
      " gggggggggggg   ",
      "                "
    ],
    [
      "                ",
      "      aaaaaaaaa ",
      "      a  ?c   \u037a ",
      " ggggga       \u037a ",
      " g\u037b\u037b\u037b\u037b\u037bggggggh\u037a ",
      " g\u037b\u037b\u037b\u037b\u037b\u037b\u037b\u037b\u037b\u037bg a ",
      " g\u037b\u037b\u037b\u037b\u037b\u037b\u037b\u037b\u037b\u037bg   ",
      " g\u037b\u037b\u037b\u037b\u037b\u037b\u037b\u037b\u037b\u037bg   ",
      " g\u037b\u037b\u037b\u037b\u037b\u037b\u037b\u037b\u037b\u037bg   ",
      " g\u037b\u037b\u037b\u037b\u037b\u037b\u037b\u037b\u037b\u037bg   ",
      " g\u037b\u037b\u037b\u037b\u037b\u037b\u037b\u037b\u037b\u037bg   ",
      " g\u037b\u037b\u037b\u037b\u037b\u037b\u037b\u037b\u037b\u037bg   ",
      " g\u037b\u037b\u037b\u037b\u037b\u037b\u037b\u037b\u037b\u037bg   ",
      " g\u037b\u037b\u037b\u037b\u037b\u037b\u037b\u037b\u037b\u037bg   ",
      " gggggggggggg   ",
      "                "
    ]
  ]
}