{
  "name": "building_apartmentsmallc_top",
  "refpalette": "deceasedcraft:building_apartmentsmallc/building_apartmentsmallc_top_palette",
  "xsize": 16,
  "zsize": 16,
  "slices": [
    [
      "                ",
      "      aaaaaaaaa ",
      "      abbc    a ",
      " dddddabbe    a ",
      " dffffbbbggggha ",
      " dffffbfffffg a ",
      " dffffffffffd   ",
      " dffffffffffd   ",
      " dffffffffffd   ",
      " dffffffffffd   ",
      " dffffffffffd   ",
      " dffffffffifd   ",
      " dfffffiffffd   ",
      " dffffffffffd   ",
      " dddddddddddd   ",
      "                "
    ],
    [
      "                ",
      "      aaaaajjja ",
      "      a       a ",
      " ggggga  k    a ",
      " gllllabmbbbbba ",
      " gl n!ao oolgoa ",
      " glnpp     lg   ",
      " gl pp     lg   ",
      " gl i    qqlg   ",
      " gl i   nqqlg   ",
      " gl in    nlg   ",
      " glniiiiiiilg   ",
      " gl   ni   lg   ",
      " gllllllllllg   ",
      " gggggggggggg   ",
      "                "
    ],
    [
      "                ",
      "      arssaaaaa ",
      "      a       j ",
      "      a       t ",
      "  llllabubbbbba ",
      "  l  nao oolooa ",
      "  l pp     l    ",
      "  l pp     l    ",
      "  l      wwl    ",
      "  l      xwl    ",
      "  l        l    ",
      "  l        l    ",
      "  l        l    ",
      "  llllllllll    ",
      "                ",
      "                "
    ],
    [
      "                ",
      "      aaaaaayyy ",
      "      a       a ",
      "      a       a ",
      "      abAbbbbba ",
      "      aoooooooa ",
      "    BC          ",
      "    BB          ",
      "                ",
      "                ",
      "                ",
      "                ",
      "                ",
      "                ",
      "                ",
      "                "
    ],
    [
      "                ",
      "      aaaaaaaaa ",
      "      afffffffa ",
      "      afffffffa ",
      "      afffffffa ",
      "      aaaaaaaaa ",
      "                ",
      "                ",
      "                ",
      "                ",
      "                ",
      "                ",
      "                ",
      "                ",
      "                ",
      "                "
    ],
    [
      "                ",
      "      sssssssss ",
      "      s       s ",
      "      s       s ",
      "      s       s ",
      "      sssssssss ",
      "                ",
      "                ",
      "                ",
      "                ",
      "                ",
      "                ",
      "                ",
      "                ",
      "                ",
      "                "
    ]
  ]
}