{
  "name": "building_apartmentsmallc_ground_90",
  "refpalette": "deceasedcraft:building_apartmentsmallc/building_apartmentsmallc_ground_palette_90",
  "xsize": 16,
  "zsize": 16,
  "slices": [
    [
      "aaaaaaaaaaaaaaaa",
      "acccccaaaaaaaaaa",
      "acdddaaaaaaaaaaa",
      "acddeeeeeeeeeeea",
      "acddgfffffffffea",
      "acddgfffffffffea",
      "acddgfffffffffea",
      "acdddfffffffffea",
      "acddgfffffffffea",
      "acccggggffffffea",
      "aaaeffffffffffea",
      "bbaeffffffffffea",
      "bbbeffffffffffea",
      "abbeffffffffffea",
      "baaeeeeeeeeeeeea",
      "aaaaaaaaaaaaaaaa"
    ],
    [
      "                ",
      " ccccc          ",
      " cindu          ",
      " c  ggooooooooN ",
      " chdgt  yy yy g ",
      " c mgs        g ",
      " c  grw       o ",
      " c  q     DKK O ",
      " c lg     BJM O ",
      " cccgggg  C   O ",
      "   gpppx  BII O ",
      "   j      C   O ",
      "   k      BFL O ",
      "   j      AEE O ",
      "   goggoggooooN ",
      "                "
    ],
    [
      "                ",
      " cTVcc          ",
      " cSndu          ",
      " c  ggoOOOOOOON ",
      " cRmg         g ",
      " c  g         g ",
      " Q  g         o ",
      " Q  X     Z   O ",
      " P  g Y   0   O ",
      " cccgggg  0   O ",
      "   gWWW   0   O ",
      "   j      0   O ",
      "   U      0   O ",
      "   j      Z   O ",
      "   goggoggoOooN ",
      "                "
    ],
    [
      "                ",
      " 1cccc          ",
      " 1dddu          ",
      " 1dmggoOOOOOOON ",
      " c2 gw        g ",
      " c  g5        g ",
      " c  g         o ",
      " c  34    7   O ",
      " c  g 6   0   O ",
      " cccgggg  0   O ",
      "   gWWW   0   O ",
      "   j      0   O ",
      "   j      0   O ",
      "   j      7   O ",
      "   goggoggoOooN ",
      "                "
    ],
    [
      "                ",
      " ccccc          ",
      " c!ldu          ",
      " cl ggggggggggg ",
      " c8 g         g ",
      " c2 g         g ",
      " c  g         g ",
      " Q  g         g ",
      " Q  g 9       g ",
      " Qccgggg      g ",
      "   g          g ",
      "   g          g ",
      "   g          g ",
      "   g          g ",
      "   gggggggggggg ",
      "                "
    ],
    [
      "                ",
      " cTTTc          ",
      " cl #           ",
      " c  ggggggggggg ",
      " c  geeeeeeeeeg ",
      " c8 geeeeeeeeeg ",
      " c2 geeeeeeeeeg ",
      " c  geeeeeeeeeg ",
      " c  geeeeeeeeeg ",
      " cccggggeeeeeeg ",
      "   geeeeeeeeeeg ",
      "   geeeeeeeeeeg ",
      "   geeeeeeeeeeg ",
      "   geeeeeeeeeeg ",
      "   gggggggggggg ",
      "                "
    ]
  ]
}