{
  "name": "building_apartmentsmallc_floor3_270",
  "refpalette": "deceasedcraft:building_apartmentsmallc/building_apartmentsmallc_floor3_palette_270",
  "xsize": 16,
  "zsize": 16,
  "slices": [
    [
      "                ",
      " dddddddddddd   ",
      " dffffffffffd   ",
      " dffffffffffd   ",
      " dffffffffffd   ",
      " dffffffffffd   ",
      " dffifffffffaaa ",
      " diiiifffffgbba ",
      " diiiffffffbbba ",
      " dfffffffffgbca ",
      " diiiffffffge a ",
      " diifffffffg  a ",
      " dddddddddgg  a ",
      "           h  a ",
      "          aaaaa ",
      "                "
    ],
    [
      "                ",
      " gggggggggggg   ",
      " gV yMgE u lg   ",
      " gWS NgF u mg   ",
      " gWS OgI u ng   ",
      " gV   L    og   ",
      " gggQgg Bw paaa ",
      " g T P  Cw g  a ",
      " g URgggg  q  a ",
      " gggg    xgg  a ",
      " g  P JJ yrgk a ",
      " gURgDKKDAsge j ",
      " ggggggggggg  j ",
      "          tb  j ",
      "          aaaaa ",
      "                "
    ],
    [
      "                ",
      " >ggZgg2ZZZ2g   ",
      " Z%  -g^   3Z   ",
      " ,   [g&    Z   ",
      " ,   ]g*    Z   ",
      " Z%  6+     g   ",
      " ,gg|gg(#  4aaa ",
      " ,   {     g0 X ",
      " Z' ;gggg 65  Y ",
      " >ggg   $9gg  Y ",
      " g<:{     7g  a ",
      " g ;g}  % 8gk a ",
      " >Z))Z))Z2gge a ",
      "          tb  a ",
      "          aa1ja ",
      "                "
    ],
    [
      "                ",
      " >ggZgg2ZZZ2g   ",
      " Z    g     /   ",
      " ,  ! g     /   ",
      " ,    g     /   ",
      " Z    ,     g   ",
      " ,gg\u0371gg    `aaa ",
      " ,   \u0370     g  a ",
      " Z\u0373 \u0372gggg  /  a ",
      " >ggg    )gg  a ",
      " g\u0374 \u0370      g  a ",
      " g \u0372g      g ?a ",
      " >Z))Z))Z2ggkb. ",
      "          tbbb. ",
      "          aaaa. ",
      "                "
    ],
    [
      "                ",
      " gggggggggggg   ",
      " g    g     g   ",
      " g  \u0377 g  \u0375  g   ",
      " g    g     g   ",
      " g    g     g   ",
      " gggggg     aaY ",
      " g   g   \u0376 g  Y ",
      " g   gggg  g  Y ",
      " gggg   gggg  a ",
      " g  g \u0375    g ?a ",
      " g  g      g ca ",
      " ggggggggggg  a ",
      "          tb  a ",
      "          aaaaa ",
      "                "
    ],
    [
      "                ",
      " gggggggggggg   ",
      " g\u037b\u037b\u037b\u037b\u037b\u037b\u037b\u037b\u037b\u037bg   ",
      " g\u037b\u037b\u037b\u037b\u037b\u037b\u037b\u037b\u037b\u037bg   ",
      " g\u037b\u037b\u037b\u037b\u037b\u037b\u037b\u037b\u037b\u037bg   ",
      " g\u037b\u037b\u037b\u037b\u037b\u037b\u037b\u037b\u037b\u037bg   ",
      " g\u037b\u037b\u037b\u037b\u037b\u037b\u037b\u037b\u037b\u037baaa ",
      " g\u037b\u037b\u037b\u037b\u037b\u037b\u037b\u037b\u037bg  a ",
      " g\u037b\u037b\u037b\u037b\u037b\u037b\u037b\u037b\u037bg  a ",
      " g\u037b\u037b\u037b\u037b\u037b\u037b\u037b\u037b\u037bg ?a ",
      " g\u037b\u037b\u037b\u037b\u037b\u037b\u037b\u037b\u037bg ca ",
      " g\u037b\u037b\u037b\u037b\u037b\u037b\u037b\u037b\u037bg  a ",
      " ggggggggggg  a ",
      "           h  a ",
      "          a\u037a\u037a\u037aa ",
      "                "
    ]
  ]
}