{
  "name": "multi_oasiscondo_10_base1",
  "refpalette": "deceasedcraft:multi_oasiscondo_10/multi_oasiscondo_10_base1_palette",
  "xsize": 16,
  "zsize": 16,
  "slices": [
    [
      "aaaabcHHHHHHHHv ",
      "aaaabcHHHHHHHHv ",
      "aaaabcHHHHHHHHv ",
      "aaaabcHHHHHHHHv ",
      "aaadecHHHHccceve",
      "aaaafcHHHHHHHHv ",
      "aaaafcHHHHHHHHv ",
      "aaaafcHHHHHHHHv ",
      "aaaafcHHHHHHHHv ",
      " aagfcHHHHHHHHv ",
      "h   fcHHHHHHHHv ",
      "    fcHHHHHHHHv ",
      "ggggfcHHHHHHHHvi",
      "aaaaecHHHHcccece",
      "aaajfcHHHHcccccc",
      "bbbbecHHHHHccecc"
    ],
    [
      "   k      l  mv ",
      "    n      o  v ",
      "    n     pqqrv ",
      "    s     tuuwv ",
      "   xe     yyyeve",
      "    s     l  mv ",
      "   An     B  Cv ",
      "   An     lD mv ",
      "E   s     B  Cv ",
      "gFIgs     l  mvi",
      "g   n     B  CvJ",
      "g   n     l  mvK",
      "ggggs     B  Cvc",
      "  LLe     yyyeMe",
      "   js          N",
      "OPPPe        e  "
    ],
    [
      "   Q          v ",
      "    n         v ",
      "    n         v ",
      "    s         v ",
      "   Re        eve",
      "    s         v ",
      "    n         vi",
      "    n         vJ",
      "    s         vK",
      "gSTgs         vc",
      "g   n         vU",
      "g   n         vN",
      "ggggs         v ",
      "    e        e e",
      "   js           ",
      "VPPPe        e  "
    ],
    [
      "    n         v ",
      "    n         v ",
      "    n         v ",
      "    s         vi",
      "    e        eve",
      "    s         vK",
      "    n         vc",
      "    n         vU",
      "    s         vN",
      "gWWgs         v ",
      "g   n         v ",
      "g   n         v ",
      "ggggs         v ",
      "   Xe        e e",
      "   js           ",
      "PPPPe        e  "
    ],
    [
      "YYYYbYYYYYYYYbvi",
      "YYYYbYYYYYYYYbvJ",
      "YYYYbYYYYYYYYbvK",
      "YYYYbYYYYYYYYbvc",
      "bbbbZbbbbbbbbZve",
      "YYYYbYYYYYYYYbvN",
      "YYYYbYYYYYYYYbv ",
      "YYYYbYYYYYYYYbv ",
      "YYYYbYYYYYYYYbv ",
      "ggggbYYYYYYYYbv ",
      "g   bYYYYYYYYbv ",
      "g   bYYYYYYYYbv ",
      "ggggbYYYYYYYYbv ",
      "bbbbZbbbbbbbbZ e",
      "   js           ",
      "PPPPe        e  "
    ],
    [
      "dddddddddddddbvc",
      "dddddddddddddbvU",
      "dddddddddddd0bvN",
      "dddddddddddddbv ",
      "ddddddddddddd1bZ",
      "dddddddddddddbv ",
      "dddddddddddddbv ",
      "dddddddddddd0bv ",
      "dddddddddddddbv ",
      "g22gdddddddddbv ",
      "g   bddddddddbv ",
      "g   bddddddddbv ",
      "gggggddddddd3bv ",
      "bbbbZbbbbbbbb1bZ",
      "jjjjbYYYYYYYYbii",
      "bbbbZbbbbbbbbZii"
    ]
  ]
}