{
  "name": "multi_oasiscondo_10_floor1",
  "refpalette": "deceasedcraft:multi_oasiscondo_10/multi_oasiscondo_10_floor1_palette",
  "xsize": 16,
  "zsize": 16,
  "slices": [
    [
      "                ",
      "                ",
      "            a   ",
      "                ",
      "               b",
      "                ",
      "                ",
      "            a   ",
      "                ",
      "cddce           ",
      "c   c           ",
      "c   c           ",
      " cccc       f c ",
      "     c       ecb",
      "     cggggggcce ",
      "    b        b  "
    ],
    [
      "                ",
      "                ",
      "                ",
      "                ",
      "               b",
      "                ",
      "                ",
      "                ",
      "                ",
      "chhce           ",
      "c   c           ",
      "c   c           ",
      " cccc         c ",
      "     c       ecb",
      "     cggggggcce ",
      "    b        b  "
    ],
    [
      "                ",
      "                ",
      "                ",
      "                ",
      "               b",
      "                ",
      "                ",
      "                ",
      "                ",
      "chhce           ",
      "c   c           ",
      "c   c           ",
      " cccc         c ",
      "     c       ecb",
      "     cggggggcce ",
      "    b        b  "
    ],
    [
      "                ",
      "                ",
      "                ",
      "                ",
      "               b",
      "                ",
      "                ",
      "                ",
      "                ",
      "chhce           ",
      "c   c           ",
      "c   c           ",
      " cccc         c ",
      "     c       ecb",
      "     cggggggcce ",
      "    b        b  "
    ],
    [
      "             cc ",
      "             cc ",
      "             cc ",
      "             cc ",
      "             ccb",
      "             cc ",
      "             cc ",
      "             cc ",
      "             cc ",
      "chhce        cc ",
      "c   c        cc ",
      "c   c        cc ",
      " cccc        cc ",
      "     ccccccccccb",
      "     ccccccccce ",
      "    b        b  "
    ],
    [
      "            ijjj",
      "            ijjj",
      "            ijjj",
      "            ijjj",
      "            ijjb",
      "            ijjj",
      "            ijjj",
      "            ijjj",
      "            ijjj",
      "chhce       ijjj",
      "c   c       ijjj",
      "c   c      iijjj",
      "kcccciiiiiiiijjj",
      "jjjjjjjjjjjjjjjb",
      "jjjjjjjjjjjjjjjj",
      "jjjjbjjjjjjjjbjj"
    ]
  ]
}