{
  "name": "multi_oasiscondo_10_base3",
  "refpalette": "deceasedcraft:multi_oasiscondo_10/multi_oasiscondo_10_base3_palette",
  "xsize": 16,
  "zsize": 16,
  "slices": [
    [
      "    a         vv",
      "    a         vb",
      "    a         vb",
      "    c         vb",
      "    d        dvd",
      "    c         vb",
      "    a         vb",
      "    a         vb",
      "    c         vb",
      "eeeec         vb",
      "e   a         vb",
      "e   a         vb",
      "eeeec         vf",
      "    d        dvd",
      "   gc         vf",
      "hhhhd        dvi"
    ],
    [
      "    a         vv",
      "    a         vb",
      "    a         vb",
      "    c         vb",
      "    d        dvd",
      "    c         vb",
      "    a         vb",
      "    a         vb",
      "    c         vb",
      "eeeec         vf",
      "e   a         vf",
      "e   a         vf",
      "eeeec         vi",
      "    d        dvd",
      "   gc         vj",
      "hhhhd        dv "
    ],
    [
      "    a         vv",
      "    a         vb",
      "    a         vb",
      "    c         vb",
      "    d        dvd",
      "    c         vb",
      "    a         vf",
      "    a         vf",
      "    c         vf",
      "eeeec         vi",
      "e   a         vk",
      "e   a         vj",
      "eeeec         v ",
      "    d        dvd",
      "   gc         v ",
      "hhhhd        dv "
    ],
    [
      "    a         vv",
      "    a         vb",
      "    a         vb",
      "    c         vf",
      "    d        dvd",
      "    c         vf",
      "    a         vi",
      "    a         vk",
      "    c         vj",
      "eeeec         v ",
      "e   a         v ",
      "e   a         v ",
      "eeeec         v ",
      "   ld        dvd",
      "   gc         v ",
      "hhhhd        dv "
    ],
    [
      "mmmmnmmmmmmmmnvv",
      "mmmmnmmmmmmmmnvf",
      "mmmmnmmmmmmmmnvf",
      "mmmmnmmmmmmmmnvi",
      "nnnnonnnnnnnnovd",
      "mmmmnmmmmmmmmnvj",
      "mmmmnmmmmmmmmnv ",
      "mmmmnmmmmmmmmnv ",
      "mmmmnmmmmmmmmnv ",
      "eeeenmmmmmmmmnv ",
      "e   nmmmmmmmmnv ",
      "e   nmmmmmmmmnv ",
      "eeeenmmmmmmmmnv ",
      "nnnnonnnnnnnnovd",
      "   gc         v ",
      "hhhhd        dv "
    ],
    [
      "pppppppppppppnvi",
      "pppppppppppppnvk",
      "pppppppppppppnvj",
      "pppppppppppppnv ",
      "pppppppppppppqno",
      "pppppppppppppnv ",
      "pppppppppppppnv ",
      "pppppppppppppnv ",
      "pppppppppppppnv ",
      "errepppppppppnv ",
      "e   nppppppppnv ",
      "e   nppppppppnv ",
      "eeeeeppppppppnv ",
      "nnnnonnnnnnnnqno",
      "ggggnmmmmmmmmnvn",
      "nnnnonnnnnnnnovn"
    ]
  ]
}