{
  "name": "multi_oasiscondo_10_top",
  "refpalette": "deceasedcraft:multi_oasiscondo_10/multi_oasiscondo_10_top_palette",
  "xsize": 16,
  "zsize": 16,
  "slices": [
    [
      "            abbc",
      "            abbc",
      "            abbc",
      "            abbc",
      "           dabbe",
      "            abbc",
      "            abbc",
      "            abbc",
      "           fabbc",
      "ghhgi      abbbc",
      "g   g     fabbbc",
      "    g   fjjbbbbc",
      "bgbbgjjjjbbbbbbc",
      "bbbbbbbbbbbbbbbe",
      "bbbbbbbbbbbbbbkl",
      "bbbbebbbbbbbbecl"
    ],
    [
      "            m  n",
      "            m  n",
      "            m  n",
      "            m  n",
      "            m  e",
      "            m  n",
      "            m  n",
      "            m  n",
      "           mm  n",
      "googi      m   n",
      "g   g     mm   n",
      "g   g   mmm    n",
      "pgqqgmmmm      n",
      "  rs           e",
      "              tu",
      "    e        e u"
    ],
    [
      "               n",
      "               n",
      "               n",
      "               n",
      "            m  e",
      "               n",
      "               n",
      "               n",
      "               n",
      "googi          n",
      "g   g     m    n",
      "g   g          n",
      "wg  g          n",
      "  xy           e",
      "               u",
      "    e        etu"
    ],
    [
      "                ",
      "                ",
      "                ",
      "                ",
      "            m  e",
      "                ",
      "                ",
      "                ",
      "                ",
      "googi           ",
      "g   g     m     ",
      "g   g           ",
      "AgBBg           ",
      "  CD           e",
      "                ",
      "    e        e  "
    ],
    [
      "                ",
      "                ",
      "                ",
      "                ",
      "            m  e",
      "                ",
      "                ",
      "                ",
      "                ",
      "googi           ",
      "g   g     m     ",
      "g   g           ",
      " gggg           ",
      "               e",
      "                ",
      "    e        e  "
    ],
    [
      "             EE ",
      "             EE ",
      "             EE ",
      "             EE ",
      "            mEEe",
      "             EE ",
      "             EE ",
      "             EE ",
      "             EE ",
      "googi       EEE ",
      "g   g     m EEE ",
      "g   g      EEEE ",
      "Fgggg    EEEEEE ",
      "EEEEEEEEEEEEEEEe",
      "EEEEEEEEEEEEEE I",
      "EEEEeEEEEEEEEe J"
    ],
    [
      "            abba",
      "            abba",
      "            abba",
      "            abba",
      "           Kabbe",
      "            abba",
      "            abba",
      "            abba",
      "           fabba",
      "ghhgi      abbba",
      "g   g     fabbba",
      "    g   fjjbbbba",
      "bgbbgjjjjbbbbbba",
      "bbbbbbbbbbbbbbbe",
      "bbbbbbbbbbbbbbLM",
      "bbbbebbbbbbbbe  "
    ],
    [
      "            m  o",
      "            m  o",
      "            m  o",
      "            m  o",
      "            m  e",
      "            m  o",
      "            m  o",
      "            m  o",
      "           mm  o",
      "googi      m   o",
      "g   g     mm   o",
      "g   g   mmm    o",
      "pgqqgmmmm      o",
      "  rs           e",
      "                ",
      "    e        e  "
    ],
    [
      "                ",
      "                ",
      "                ",
      "                ",
      "            m  e",
      "                ",
      "                ",
      "                ",
      "                ",
      "googi           ",
      "g   g     m     ",
      "g   g           ",
      "wg  g           ",
      "  xy           e",
      "                ",
      "    e        e  "
    ],
    [
      "                ",
      "                ",
      "                ",
      "                ",
      "            m  e",
      "                ",
      "                ",
      "                ",
      "                ",
      "googi           ",
      "g   g     m     ",
      "g   g           ",
      "AgBBg           ",
      "  CD           e",
      "                ",
      "    e        e  "
    ],
    [
      "             N  ",
      "             N  ",
      "             N  ",
      "             N  ",
      "            mN e",
      "             N  ",
      "             N  ",
      "             N  ",
      "            ON  ",
      "googi       N   ",
      "g   g     mON   ",
      "g   g     P     ",
      " gggg   PQQ     ",
      "     QQQQ      e",
      "                ",
      "    e        e  "
    ],
    [
      "            REEE",
      "            REEE",
      "            REEE",
      "            REEE",
      "            REEe",
      "            REEE",
      "            REEE",
      "            REEE",
      "           RREEE",
      "googi      REEEE",
      "g   g     RREEEE",
      "g   g   RRREEEEE",
      "FggggRRRREEEEEEE",
      "EEEEEEEEEEEEEEEe",
      "EEEEEEEEEEEEEEEE",
      "EEEEeEEEEEEEEeEE"
    ],
    [
      "            ffff",
      "            ffff",
      "            ffff",
      "            ffff",
      "            ffff",
      "            ffff",
      "            ffff",
      "            ffff",
      "           fffff",
      "ghhgi      fffff",
      "g   g     ffffff",
      "g   g   ffffffff",
      "fggggfffffffffff",
      "ffffffffffffffff",
      "ffffgfffffffffff",
      "ffffgfffffffffff"
    ],
    [
      "            m   ",
      "            m SS",
      "            m SS",
      "            m SS",
      "            m   ",
      "            m   ",
      "            m   ",
      "            m   ",
      "           mm   ",
      "ggggi      m    ",
      "g   g     mm    ",
      "g   g   mmm     ",
      "gggggmmmm    TUT",
      "    V       TWWW",
      " XY g       ZWWW",
      "0123g       TWWW"
    ],
    [
      "                ",
      "              SS",
      "              SS",
      "              SS",
      "                ",
      "                ",
      "                ",
      "                ",
      "                ",
      "ggggi           ",
      "4564g           ",
      " 784g           ",
      "ggggg           ",
      "    9        #$%",
      " X^ g&       *()",
      " 1+3g        -[]"
    ],
    [
      "                ",
      "              SS",
      "              SS",
      "              SS",
      "                ",
      "                ",
      "                ",
      "                ",
      "                ",
      "ggggi           ",
      "{{{{g           ",
      "{{}{g           ",
      "{{{{g           ",
      "{{{{g        |;:",
      "{{{{g        '<>",
      "{{{{g        ,.?"
    ],
    [
      "                ",
      "              //",
      "              //",
      "              //",
      "                ",
      "                ",
      "                ",
      "                ",
      "                ",
      "                ",
      "                ",
      "                ",
      "                ",
      "             `\u0370\u0371",
      "             \u0372\u0373\u0374",
      "             \u0375\u0376\u0377"
    ],
    [
      "                ",
      "                ",
      "                ",
      "                ",
      "                ",
      "                ",
      "                ",
      "                ",
      "                ",
      "                ",
      "                ",
      "                ",
      "                ",
      "                ",
      "              X ",
      "                "
    ],
    [
      "                ",
      "                ",
      "                ",
      "                ",
      "                ",
      "                ",
      "                ",
      "                ",
      "                ",
      "                ",
      "                ",
      "                ",
      "                ",
      "              X ",
      "             XXX",
      "              X "
    ],
    [
      "                ",
      "                ",
      "                ",
      "                ",
      "                ",
      "                ",
      "                ",
      "                ",
      "                ",
      "                ",
      "                ",
      "                ",
      "                ",
      "                ",
      "              \u037a ",
      "                "
    ]
  ]
}