{
  "name": "multi_oasiscondo_10_base4",
  "refpalette": "deceasedcraft:multi_oasiscondo_10/multi_oasiscondo_10_base4_palette",
  "xsize": 16,
  "zsize": 16,
  "slices": [
    [
      "aaaaaaaaaaaaaaaa",
      "aaaaaaaaaaaaaaaa",
      "aaaaaaaaaaaaaaaa",
      "aaaaaaaaaaaaaaaa",
      "aaaaaaaaaaaaaaaa",
      "aaaaaaaaaaaaaaaa",
      "aaaaaaaaaaaaaaaa",
      "aaaaaaaaaaaaaaaa",
      "aaaaaaaaaaaaaaaa",
      "aaaaaaaaaaaaaaaa",
      "aaaaaaaaaaaaaaaa",
      "aaaaaaaaaaaaaaaa",
      "aaaaaaaaaaaaaaaa",
      "aaaaaaaaaaaaaaaa",
      "aaaaaaaaaaaaaaaa",
      "aaaaaaaaaaaaaaaa"
    ],
    [
      "aaaaaaaaaaaaaaaa",
      "aaaaaaaaaaaaaaaa",
      "aaaaaaaaaaaaaaaa",
      "aaaaaaaaaaaaaaaa",
      "aaaabaaaaaaaabab",
      "aaaaaaaaaaaaaaaa",
      "aaaaaaaaaaaaaaaa",
      "aaaaaaaaaaaaaaaa",
      "aaaaaaaaaaaaaaaa",
      "ccccaaaaaaaaaaaa",
      "ccccaaaaaaaaaaaa",
      "ccccaaaaaaaaaaaa",
      "ccccaaaaaaaaaaaa",
      "aaaabaaaaaaaabab",
      "aaaaaaaaaaaaaaaa",
      "aaaabaaaaaaaabaa"
    ],
    [
      "ddddefHHHHHHHHvv",
      "ddddefHHHHHHHHva",
      "ddddefHHHHHHHHva",
      "ddddefHHHHHHHHva",
      "dddgbfHHHHfffbvb",
      "ddddhfHHHHHHHHva",
      "ddddhfHHHHHHHHva",
      "ddddhfHHHHHHHHva",
      "ddddhfHHHHHHHHva",
      " ddihfHHHHHHHHva",
      "j   hfHHHHHHHHva",
      "    hfHHHHHHHHva",
      "iiiihfHHHHHHHHva",
      "ddddbfHHHHfffbvb",
      "dddkhfHHHHffffva",
      "eeeebfHHHHfffbva"
    ],
    [
      "   l      m  nvv",
      "    o      p  va",
      "    o     qrrsva",
      "    t     uwwxva",
      "   yb     AAAbvb",
      "    t     m  nva",
      "   Bo     C  Dva",
      "   Bo     m  nva",
      "E   t     C  Dva",
      "iFIit     m  nva",
      "i   o     C  Dva",
      "i   o     m  nva",
      "iiiit     C  Dva",
      "  JJb     AAAbvb",
      "   kt      KLMva",
      "NOOOb      PQbva"
    ],
    [
      "   R          vv",
      "    o         va",
      "    o         va",
      "    t         va",
      "   Sb        bvb",
      "    t         va",
      "    o         va",
      "    o         va",
      "    t         va",
      "iTUit         va",
      "i   o         va",
      "i   o         va",
      "iiiit         va",
      "    b        bvb",
      "   kt         va",
      "VOOOb        bva"
    ],
    [
      "    o         vv",
      "    o         va",
      "    o         va",
      "    t         va",
      "    b        bvb",
      "    t         va",
      "    o         va",
      "    o         va",
      "    t         va",
      "iWWit         va",
      "i   o         va",
      "i   o         va",
      "iiiit         va",
      "    b        bvb",
      "   kt         va",
      "OOOOb        bvX"
    ]
  ]
}