{
  "name": "multi_oasiscondo_10_floor4",
  "refpalette": "deceasedcraft:multi_oasiscondo_10/multi_oasiscondo_10_floor4_palette",
  "xsize": 16,
  "zsize": 16,
  "slices": [
    [
      "            abbb",
      "            abbb",
      "            abbb",
      "            abbb",
      "           cabbd",
      "            abbb",
      "            abbb",
      "            abbb",
      "            abbb",
      "effeg       abbb",
      "e   e       abbb",
      "    e      habbb",
      "bebbeiiiiiiijbbb",
      "bbbbbbbbbbbbbbbd",
      "bbbbbbbbbbbbbbbb",
      "bbbbdbbbbbbbbdbb"
    ],
    [
      "            k   ",
      "            k   ",
      "            k   ",
      "            k   ",
      "            k  d",
      "            k   ",
      "            k   ",
      "            k   ",
      "            k   ",
      "elleg       k   ",
      "e   e       k   ",
      "e   e      kk   ",
      "mennekkkkkkk    ",
      "  op           d",
      "                ",
      "    d        d  "
    ],
    [
      "                ",
      "                ",
      "                ",
      "               q",
      "            k  d",
      "                ",
      "                ",
      "                ",
      "                ",
      "elleg           ",
      "e   e           ",
      "e   e      k    ",
      "re  e          q",
      "  st           d",
      "                ",
      "    du       du "
    ],
    [
      "                ",
      "                ",
      "                ",
      "                ",
      "            k  d",
      "                ",
      "                ",
      "                ",
      "                ",
      "elleg           ",
      "e   e           ",
      "e   e      k    ",
      "wexxe           ",
      "  yA           d",
      "                ",
      "    d        d  "
    ],
    [
      "             B  ",
      "             B  ",
      "             B  ",
      "             B  ",
      "            kB d",
      "             B  ",
      "             B  ",
      "             B  ",
      "             B  ",
      "elleg        B  ",
      "e   e        B  ",
      "e   e      k B  ",
      " eeee        B  ",
      "     CCCCCCCC  d",
      "                ",
      "    d        d  "
    ],
    [
      "            DEEE",
      "            DEEE",
      "            DEEE",
      "            DEEE",
      "            DEEd",
      "            DEEE",
      "            DEEE",
      "            DEEE",
      "            DEEE",
      "elleg       DEEE",
      "e   e       DEEE",
      "e   e      DDEEE",
      "FeeeeDDDDDDDDEEE",
      "EEEEEEEEEEEEEEEd",
      "EEEEEEEEEEEEEEEE",
      "EEEEdEEEEEEEEdEE"
    ]
  ]
}