{
  "name": "multi_oasiscondo_10_ground",
  "refpalette": "deceasedcraft:multi_oasiscondo_10/multi_oasiscondo_10_ground_palette",
  "xsize": 16,
  "zsize": 16,
  "slices": [
    [
      "            abc ",
      "dd          abc ",
      "eed         fbc ",
      "geed       habc ",
      "iieed      jakcl",
      "iiiee      jabc ",
      "igiied     mabc ",
      "iiiieed     fbc ",
      "iiiiied     abc ",
      "noonped     abc ",
      "n   ned     abc ",
      "    ned     abc ",
      "qnqqned     fkn ",
      "qqqqqnbbbbbbrpnl",
      "qqqqqnssssssnntt",
      "qqqqlqqqqqqqqltt"
    ],
    [
      "              u ",
      "              u ",
      "            w u ",
      "              u ",
      "xx            ul",
      "xxx           u ",
      "x xx          u ",
      "xxxx        w u ",
      "xxxxx         u ",
      "nyynp         u ",
      "n   n         u ",
      "n   n         u ",
      "AnBBn       w n ",
      "  CD n       pnl",
      "     nEEFIEEnnpJ",
      "    l        l  "
    ],
    [
      "                ",
      "                ",
      "            eK  ",
      "                ",
      "               l",
      "                ",
      "            K   ",
      "            e   ",
      "                ",
      "nyynp           ",
      "n   n           ",
      "n   n       K   ",
      " n  n       e n ",
      "  LM n       pnl",
      "     nEENOEEnnpJ",
      "    l        l  "
    ],
    [
      "                ",
      "            e   ",
      "           Kee  ",
      "            K   ",
      "               l",
      "                ",
      "            e   ",
      "            ee  ",
      "            K   ",
      "nyynp           ",
      "n   n           ",
      "n   n       e   ",
      " nPPn      eeen ",
      "  QR n      Kpnl",
      "     nEESSEEnnpT",
      "    l        l  "
    ],
    [
      "                ",
      "            e   ",
      "           eee  ",
      "            e   ",
      "               l",
      "                ",
      "            e   ",
      "           eee  ",
      "            e   ",
      "nyynp           ",
      "n   n           ",
      "n   n       K   ",
      " nnnn      eeKn ",
      "     n      epnl",
      "     nEEEEEEnnp ",
      "    l        l  "
    ],
    [
      "                ",
      "            K   ",
      "           ee   ",
      "                ",
      "               l",
      "                ",
      "            K   ",
      "           Kee  ",
      "            e   ",
      "nyynp           ",
      "n   n           ",
      "n   n           ",
      " nnnn       e n ",
      "     n       pnl",
      "     nEEEEEEnnp ",
      "    l        l  "
    ]
  ]
}