{
  "name": "multi_oasiscondo_10_base2",
  "refpalette": "deceasedcraft:multi_oasiscondo_10/multi_oasiscondo_10_base2_palette",
  "xsize": 16,
  "zsize": 16,
  "slices": [
    [
      "aaaabcHHHHHHHHv ",
      "aaaabcHHHHHHHHv ",
      "aaaabcHHHHHHHHv ",
      "aaaabcHHHHHHHHv ",
      "aaadecHHHHccceve",
      "aaaafcHHHHHHHHv ",
      "aaaafcHHHHHHHHv ",
      "aaaafcHHHHHHHHv ",
      "aaaafcHHHHHHHHv ",
      " aagfcHHHHHHHHv ",
      "h   fcHHHHHHHHv ",
      "    fcHHHHHHHHv ",
      "ggggfcHHHHHHHHvi",
      "aaaaecHHHHcccece",
      "aaajfcHHHHcccccc",
      "bbbbecHHHHHccecc"
    ],
    [
      "   k      l  mv ",
      "    n      o  v ",
      "    n     pqqrv ",
      "    s     tuuwv ",
      "   xe     yyyeve",
      "    s     l  mv ",
      "   An     B  Cv ",
      "   An     l  mv ",
      "D   s     B  Cv ",
      "gEFgs     l  mvi",
      "g   n     B  CvI",
      "g   n     l  mvJ",
      "ggggs     B  Cvc",
      "  KKe     yyyeLe",
      "   js          M",
      "NOOOe        e  "
    ],
    [
      "   P          v ",
      "    n         v ",
      "    n         v ",
      "    s         v ",
      "   Qe        eve",
      "    s         v ",
      "    n         vi",
      "    n         vI",
      "    s         vJ",
      "gRSgs         vc",
      "g   n         vT",
      "g   n         vM",
      "ggggs         v ",
      "    e        e e",
      "   js           ",
      "UOOOe        e  "
    ],
    [
      "    n         v ",
      "    n         v ",
      "    n         v ",
      "    s         vi",
      "    e        eve",
      "    s         vJ",
      "    n         vc",
      "    n         vT",
      "    s         vM",
      "gVVgs         v ",
      "g   n         v ",
      "g   n         v ",
      "ggggs         v ",
      "   We        e e",
      "   js           ",
      "OOOOe        e  "
    ],
    [
      "XXXXbXXXXXXXXbvi",
      "XXXXbXXXXXXXXbvI",
      "XXXXbXXXXXXXXbvJ",
      "XXXXbXXXXXXXXbvc",
      "bbbbYbbbbbbbbYve",
      "XXXXbXXXXXXXXbvM",
      "XXXXbXXXXXXXXbv ",
      "XXXXbXXXXXXXXbv ",
      "XXXXbXXXXXXXXbv ",
      "ggggbXXXXXXXXbv ",
      "g   bXXXXXXXXbv ",
      "g   bXXXXXXXXbv ",
      "ggggbXXXXXXXXbv ",
      "bbbbYbbbbbbbbY e",
      "   js           ",
      "OOOOe        e  "
    ],
    [
      "dddddddddddddbvc",
      "dddddddddddddbvT",
      "ddddddddddddZbvM",
      "dddddddddddddbv ",
      "ddddddddddddd0bY",
      "dddddddddddddbv ",
      "dddddddddddddbv ",
      "dddddddddddd1bv ",
      "dddddddddddddbv ",
      "g22gdddddddddbv ",
      "g   bddddddddbv ",
      "g   bddddddddbv ",
      "gggggddddddd1bv ",
      "bbbbYbbbbbbbb0bY",
      "jjjjbXXXXXXXXbii",
      "bbbbYbbbbbbbbYii"
    ]
  ]
}