{
  "name": "multi_oasiscondo_10_floor11",
  "refpalette": "deceasedcraft:multi_oasiscondo_10/multi_oasiscondo_10_floor11_palette",
  "xsize": 16,
  "zsize": 16,
  "slices": [
    [
      "            abbb",
      "            abbb",
      "            abbb",
      "            abbb",
      "           cabbd",
      "            abbb",
      "            abbb",
      "            abbb",
      "           eabbb",
      "fggfh      abbbb",
      "f   f     eabbbb",
      "    f   eiibbbbb",
      "bfbbfiiiibbbbbbb",
      "bbbbbbbbbbbbbbbd",
      "bbbbbbbbbbbbbbbb",
      "bbbbdbbbbbbbbdbb"
    ],
    [
      "            j   ",
      "            j   ",
      "            j   ",
      "            j   ",
      "            j  d",
      "            j   ",
      "            j   ",
      "            j   ",
      "           jj   ",
      "fkkfh      j    ",
      "f   f     jj    ",
      "f   f   jjj     ",
      "lfmmfjjjj       ",
      "  no           d",
      "                ",
      "    d        d  "
    ],
    [
      "                ",
      "                ",
      "                ",
      "                ",
      "            j  d",
      "                ",
      "                ",
      "                ",
      "                ",
      "fkkfh           ",
      "f   f     j     ",
      "f   f           ",
      "pf  f           ",
      "  qr           d",
      "                ",
      "    d        d  "
    ],
    [
      "                ",
      "                ",
      "                ",
      "                ",
      "            j  d",
      "                ",
      "                ",
      "                ",
      "                ",
      "fkkfh           ",
      "f   f     j     ",
      "f   f           ",
      "sfttf           ",
      "  uw           d",
      "                ",
      "    d        d  "
    ],
    [
      "             x  ",
      "             x  ",
      "             x  ",
      "             x  ",
      "            jx d",
      "             x  ",
      "             x  ",
      "             x  ",
      "            yx  ",
      "fkkfh       x   ",
      "f   f     jyx   ",
      "f   f     A     ",
      " ffff   ABB     ",
      "     BBBB      d",
      "                ",
      "    d        d  "
    ],
    [
      "            CDDD",
      "            CDDD",
      "            CDDD",
      "            CDDD",
      "            CDDd",
      "            CDDD",
      "            CDDD",
      "            CDDD",
      "           CCDDD",
      "fkkfh      CDDDD",
      "f   f     CCDDDD",
      "f   f   CCCDDDDD",
      "EffffCCCCDDDDDDD",
      "DDDDDDDDDDDDDDDd",
      "DDDDDDDDDDDDDDDD",
      "DDDDdDDDDDDDDdDD"
    ]
  ]
}