{
  "name": "multi_thering_9_floor7",
  "refpalette": "deceasedcraft:multi_thering_9/multi_thering_9_floor7_palette",
  "xsize": 16,
  "zsize": 16,
  "slices": [
    [
      "aaabbb c        ",
      "aaaaabb d       ",
      "baaaaabbb c     ",
      "ebaaaaaabb cc   ",
      "eebbaaaaabbbb  c",
      "  ebbaaaaaaabbbf",
      "   eebbaaaaaaabb",
      "     eebbaaaaaaa",
      "      eeebbaaaaa",
      "        eeebbbaa",
      "           eeebb",
      "              ee",
      "                ",
      "                ",
      "                ",
      "                "
    ],
    [
      "ghh    i        ",
      "jkhhh   l       ",
      "mjgghh    i     ",
      " mjjghhh   ii   ",
      "  mmjgkhh      i",
      "   mmjjkhhhh    ",
      "     mmjjgghhh  ",
      "       mmjjgkhhh",
      "         mmjjjgg",
      "           mmmjj",
      "              mm",
      "                ",
      "                ",
      "                ",
      "                ",
      "                "
    ],
    [
      "       j        ",
      "j       i       ",
      " j        j     ",
      "  jj       jj   ",
      "    j          j",
      "     jj         ",
      "       jj       ",
      "         jj     ",
      "           jjj  ",
      "              jj",
      "                ",
      "                ",
      "                ",
      "                ",
      "                ",
      "                "
    ],
    [
      "       j        ",
      "        j       ",
      "          j     ",
      "           jj   ",
      "               j",
      "                ",
      "                ",
      "                ",
      "                ",
      "                ",
      "                ",
      "                ",
      "                ",
      "                ",
      "                ",
      "                "
    ],
    [
      "       j        ",
      "        j       ",
      "          j     ",
      "           nj   ",
      "               n",
      "                ",
      "                ",
      "                ",
      "                ",
      "                ",
      "                ",
      "                ",
      "                ",
      "                ",
      "                ",
      "                "
    ],
    [
      "       n        ",
      "        j       ",
      "          n     ",
      "            n   ",
      "                ",
      "                ",
      "                ",
      "                ",
      "                ",
      "                ",
      "                ",
      "                ",
      "                ",
      "                ",
      "                ",
      "                "
    ]
  ]
}