{
  "name": "multi_thering_9_floor6",
  "refpalette": "deceasedcraft:multi_thering_9/multi_thering_9_floor6_palette",
  "xsize": 16,
  "zsize": 16,
  "slices": [
    [
      "               a",
      "                ",
      "                ",
      "                ",
      "                ",
      "                ",
      "                ",
      "                ",
      "                ",
      "                ",
      "                ",
      "                ",
      "                ",
      "                ",
      "                ",
      "                "
    ],
    [
      "aaaaaaaaaaaaaaaa",
      "                ",
      "                ",
      "                ",
      "                ",
      "                ",
      "                ",
      "                ",
      "                ",
      "                ",
      "                ",
      "                ",
      "                ",
      "                ",
      "                ",
      "                "
    ],
    [
      "               a",
      "                ",
      "                ",
      "                ",
      "                ",
      "                ",
      "                ",
      "                ",
      "                ",
      "                ",
      "                ",
      "                ",
      "                ",
      "                ",
      "                ",
      "                "
    ],
    [
      "               a",
      "                ",
      "                ",
      "                ",
      "                ",
      "                ",
      "                ",
      "                ",
      "                ",
      "                ",
      "                ",
      "                ",
      "                ",
      "                ",
      "                ",
      "                "
    ],
    [
      "  bccccccccccccc",
      "   bbccccccccccc",
      "    bbcccccccccc",
      "      bbcccccccc",
      "       bbccccccc",
      "         bbbcccc",
      "           bbbcc",
      "              bb",
      "                ",
      "                ",
      "                ",
      "                ",
      "                ",
      "                ",
      "                ",
      "                "
    ],
    [
      "ccccccddeeeeeded",
      "bbcfcccddededeee",
      " bbbcccccdddedee",
      "  bbccccccdddddd",
      "    bccccccccddd",
      "     bbcccfccccg",
      "       bbcbccccc",
      "         bbccccc",
      "           bbbcc",
      "              bb",
      "                ",
      "                ",
      "                ",
      "                ",
      "                ",
      "                "
    ]
  ]
}