{
  "name": "multi_thering_9_ground",
  "refpalette": "deceasedcraft:multi_thering_9/multi_thering_9_ground_palette",
  "xsize": 16,
  "zsize": 16,
  "slices": [
    [
      "aaaaaaaaaaaaaaaa",
      "bbbbbbbbbbbbbbbb",
      "bbbbbbbbbbbbbbbb",
      "bbbbbbbbbbbbbbbb",
      "bbbbbbcbbbbbbcbb",
      "bbbbbbbbbbbbbbbb",
      "bbbbbbbbbbbbbbbb",
      "bbbbbbbbbbbbbbbd",
      "bbbbbbbbbbbbbbde",
      "bbbbbbbbbbbbbbdd",
      "bbbbbbbbbbbbbbbb",
      "bbbbbbbbbbbbbbbb",
      "baaaaaaaaaaaaaaa",
      "accccccccccccccc",
      "cccccccccccccccc",
      "cccccccccccccccc"
    ],
    [
      "               f",
      "                ",
      "                ",
      "                ",
      "      g      g  ",
      "                ",
      "                ",
      "               h",
      "              hi",
      "              hh",
      "                ",
      "                ",
      "      j kllm j  ",
      "jnnnnnnnnnnnnnnn",
      "n               ",
      "n               "
    ],
    [
      "               f",
      "                ",
      "                ",
      "                ",
      "      o      o  ",
      "                ",
      "                ",
      "                ",
      "                ",
      "                ",
      "                ",
      "                ",
      "      p      p  ",
      "p               ",
      "                ",
      "                "
    ],
    [
      "               f",
      "                ",
      "                ",
      "                ",
      "      n      n  ",
      "                ",
      "                ",
      "                ",
      "                ",
      "                ",
      "                ",
      "                ",
      "                ",
      "                ",
      "                ",
      "                "
    ],
    [
      "               f",
      "                ",
      "                ",
      "                ",
      "      n      n  ",
      "                ",
      "                ",
      "                ",
      "                ",
      "                ",
      "                ",
      "                ",
      "                ",
      "                ",
      "                ",
      "                "
    ],
    [
      "               f",
      "                ",
      "                ",
      "                ",
      "      n      n  ",
      "                ",
      "                ",
      "                ",
      "                ",
      "                ",
      "                ",
      "                ",
      "                ",
      "                ",
      "                ",
      "                "
    ]
  ]
}