{
  "name": "multi_flatmedium_3_ground",
  "refpalette": "deceasedcraft:multi_flatmedium_3/multi_flatmedium_3_ground_palette",
  "xsize": 16,
  "zsize": 16,
  "slices": [
    [
      "aabbbbbbbbbbbbaa",
      "aabbbbbbbbbbbbaa",
      "aabbbbbbbbbbbbaa",
      "aabbbbbbbbbbbbaa",
      "aabbbbbbbbbbbbaa",
      "aabbbbbbbbbbbbaa",
      "acbdbcbbbbcbbbca",
      "bbeeebbbbbbbbbbb",
      "bbdebbbbbbbbbbbb",
      "bbbbbbbbbbbbbbbb",
      "fcccccccccccccca",
      "aaccccccccccccaa",
      "aaccccccccccccaa",
      "aaccccccccccccaa",
      "aaaaaaaaaaaaaaaa",
      "aaaaaaaaaaaaaaaa"
    ],
    [
      " g  h  ih  i  g ",
      " g  j  kjl k  g ",
      " g lh mih  i  g ",
      " g  j  kj  k  g ",
      " g  h  ihnopq g ",
      " g  j  kj  k rg ",
      " sl qsqqqqsq ts ",
      "            l   ",
      " u     nw       ",
      "x        y      ",
      "AsBBBsccccsBBBs ",
      "ugccCCCCCCCCccg ",
      " gccccccccccccg ",
      " gccccccccccccg ",
      " gggggggggggggg ",
      "                "
    ],
    [
      "                ",
      "                ",
      "                ",
      "                ",
      "                ",
      "                ",
      " D   D    D   D ",
      "                ",
      "                ",
      "                ",
      " D   DEE!ED   D ",
      "  CFCCCCCCCCIC  ",
      "  C JC   KL  C  ",
      "  CMMCMMMMMMMC  ",
      "                ",
      "                "
    ],
    [
      "                ",
      "                ",
      "                ",
      "                ",
      "                ",
      "                ",
      " D   D    D   D ",
      "                ",
      "                ",
      "                ",
      " D   DENEED   D ",
      "  COCCCCCCCCPC  ",
      "  C QC  K    C  ",
      "  CMMCMMMMMMMC  ",
      "                ",
      "                "
    ],
    [
      " R   R    R   R ",
      " R   R    R   R ",
      " R   R    R   R ",
      " R   R    R   R ",
      " R   R    R   R ",
      " R   R    R   R ",
      " DRRRDRRRRDRRRD ",
      " R   R    R   R ",
      " R   R    R   R ",
      " R   R    R   R ",
      " DRRRDRRRRDRRRD ",
      " RCSCCCCCCCCSCR ",
      " RC  C K     CR ",
      " RCMMCMMMMMMMCR ",
      " RRRRRRRRRRRRRR ",
      "                "
    ],
    [
      " TbbbbbbbbbbbbT ",
      " TbbbbbbbbbbbbT ",
      " TbbbbbbbbbbbbT ",
      " TbbbbbbbbbbbbT ",
      " TbbbbbbbbbbbbT ",
      " TbbbbbbbbbbbbT ",
      " TbbbbbbbbbbbbT ",
      " TbbbbbbbbbbbbT ",
      " TbbbbbbbbbbbbT ",
      " TbbbbbbbbbbbbT ",
      " TbbbbbbbbbbbbT ",
      " TbbUUUUUUUUbbT ",
      " Tbbb K     bbT ",
      " TbbbbbbbbbbbbT ",
      " TTTTTTTTTTTTTT ",
      "                "
    ]
  ]
}