{
  "name": "multi_flatmedium_3_floor3",
  "refpalette": "deceasedcraft:multi_flatmedium_3/multi_flatmedium_3_floor3_palette",
  "xsize": 16,
  "zsize": 16,
  "slices": [
    [
      " abbbvvvvvvcccd ",
      " aaaavvvvvvcccd ",
      " abbavvvvvvcccd ",
      " abbavvvvvvcccd ",
      " abbavvvvvvcccd ",
      " abbavvvvvvcccd ",
      " evaaavaaaaecca ",
      " avvvvvvvvvcccd ",
      " avvvvvvvvvcccd ",
      " avvvvvvvvvcccd ",
      " avvvvavvvvcccd ",
      " eaaaaaaaaaeccd ",
      " fccgh     gccd ",
      " fccccccccccccd ",
      " aiiaiiiiiiaiia ",
      "                "
    ],
    [
      " j  k      l  a ",
      " aaaamnommma  a ",
      " apqar  stua  a ",
      " j !aw     a  a ",
      " j xar     a  a ",
      " a yaw ABCDa  a ",
      " eEaaaEaaaae  a ",
      " a         a  a ",
      " j   FI JJ a  K ",
      " j  LMN OOPa  Q ",
      " ammm!aRmmRa  a ",
      " eaaaaaaaaae  a ",
      " a  S     hS  a ",
      " a  TTTTTTTT  a ",
      " aaaaaaaaaaaaaa ",
      "                "
    ],
    [
      " UV W      X    ",
      " aYYaZ    0a    ",
      " a  a1     a    ",
      " U 2a1    3U    ",
      " U  a1    4U    ",
      " a  a1 5 6 a    ",
      " e7aaa7aaaae  8 ",
      " a   9  #$ a    ",
      " U%  ^&   3U    ",
      " U*  ()   4U    ",
      " a++-[a]]]]a    ",
      " eaaaaaaaaae    ",
      "         h      ",
      "                ",
      " 8  8      8    ",
      "                "
    ],
    [
      " U{ }      |    ",
      " aaaa      a    ",
      " a  a1     a    ",
      " U ;a1    :U    ",
      " U  a1    'U    ",
      " a <a1   > a    ",
      " eYaaaYaaaae  8 ",
      " a      $# a    ",
      " U,  .&   :U    ",
      " U?  /)   'U    ",
      " a`+11a]]]]a    ",
      " eaaaaaaaaae    ",
      "        h       ",
      "                ",
      " 8  8      8    ",
      "                "
    ],
    [
      " a\u0370\u0370a      a    ",
      " aaaa      a    ",
      " a\u0370\u0370a      a    ",
      " a\u0370\u0370a \u0371  \u0372 a    ",
      " a\u0370\u0370a      a    ",
      " a\u0370\u0370a\u0373\u0373\u0373\u0373\u0373\u0373a    ",
      " eaaaaaaaaae  8 ",
      " a         a    ",
      " a  \u0374 \u0375 \u0376  a    ",
      " a    \u0377    a    ",
      " a\u0373\u0373\u0373\u0373a\u0373\u0373\u0373\u0373a    ",
      " eaaaaaaaaae    ",
      "       h        ",
      "                ",
      " 8  8      8    ",
      "                "
    ],
    [
      " \u037ac\u037bccccccc\u037a  \u037c ",
      " \u037accccccccc\u037a  \u037c ",
      " \u037ac ccccccc\u037a  \u037c ",
      " \u037ac\u037bccccccc\u037a  \u037c ",
      " \u037ac ccccccc\u037a  \u037c ",
      " \u037ac ccccccc\u037a  \u037c ",
      " eccccccccce  e ",
      " \u037accccccccc\u037a  \u037c ",
      " \u037accccccccc\u037a  \u037c ",
      " \u037accccccccc\u037a  \u037c ",
      " \u037accccccccc\u037a  \u037c ",
      " eaaaaaaaaae  \u037c ",
      " \u037c    h       \u037c ",
      " \u037c            \u037c ",
      " e\u037c\u037ce\u037c\u037c\u037c\u037c\u037c\u037ce\u037c\u037c\u037c ",
      "                "
    ]
  ]
}