{
  "name": "multi_flatmedium_3_floor4",
  "refpalette": "deceasedcraft:multi_flatmedium_3/multi_flatmedium_3_floor4_palette",
  "xsize": 16,
  "zsize": 16,
  "slices": [
    [
      " abbbvvvvvvcccd ",
      " aaaavvvvvvcccd ",
      " abbavvvvvvcccd ",
      " abbavvvvvvcccd ",
      " abbavvvvvvcccd ",
      " abbavvvvvvcccd ",
      " evaaavaaaaecca ",
      " avvvvvvvvvcccd ",
      " avvvvvvvvvcccd ",
      " avvvvvvvvvcccd ",
      " avvvvavvvvcccd ",
      " eaaaaaaaaaeccd ",
      " fccgh     gccd ",
      " fccccccccccccd ",
      " aiiaiiiiiiaiia ",
      "                "
    ],
    [
      " j  k      l  a ",
      " aaaamnommma  a ",
      " apqar  stua  a ",
      " j !aw     a  a ",
      " j xar     a  a ",
      " a yaw ABCDa  a ",
      " eEaaaEaaaae  a ",
      " a         a  a ",
      " j      FF a  a ",
      " j  IJK LL a  a ",
      " ammmma!mmMa  a ",
      " eaaaaaaaaae  a ",
      " a  N     hN  a ",
      " a  OOOOOOOO  a ",
      " aaaaaaaaaaaaaa ",
      "                "
    ],
    [
      " PQ R      S    ",
      " aTTaU    Va    ",
      " a  aW     a    ",
      " P XaW    YP    ",
      " P  aW    ZP    ",
      " a  aW 012 a    ",
      " e3aaa3aaaae  4 ",
      " a   5  66 a    ",
      " P7       YP    ",
      " P8  9#   ZP    ",
      " a$$WWa%%%%a    ",
      " eaaaaaaaaae    ",
      "         h      ",
      "                ",
      " 4  4      4    ",
      "                "
    ],
    [
      " P^ &      *    ",
      " aaaa(     a    ",
      " a  aW     a    ",
      " P )aW    +P    ",
      " P  aW    -P    ",
      " a [aW     a    ",
      " eTaaaTaaaae  4 ",
      " a         a    ",
      " P]       +P    ",
      " P{       -P    ",
      " a$}WWa%%%%a    ",
      " eaaaaaaaaae    ",
      "        h       ",
      "                ",
      " 4  4      4    ",
      "                "
    ],
    [
      " a||a      a    ",
      " aaaa      a    ",
      " a||a      a    ",
      " a||a ;  : a    ",
      " a||a      a    ",
      " a||a''''''a    ",
      " eaaaaaaaaae  4 ",
      " a         a    ",
      " a  <   >  a    ",
      " a         a    ",
      " a''''a''''a    ",
      " eaaaaaaaaae    ",
      "       h        ",
      "                ",
      " 4  4      4    ",
      "                "
    ],
    [
      " ,c.ccccccc,  ? ",
      " ,ccccccccc,  ? ",
      " ,c ccccccc,  ? ",
      " ,c.ccccccc,  ? ",
      " ,c ccccccc,  ? ",
      " ,c ccccccc,  ? ",
      " eccccccccce  e ",
      " ,ccccccccc,  ? ",
      " ,ccccccccc,  ? ",
      " ,ccccccccc,  ? ",
      " ,ccccccccc,  ? ",
      " eaaaaaaaaae  ? ",
      " ?    h       ? ",
      " ?            ? ",
      " e??e??????e??? ",
      "                "
    ]
  ]
}