{
  "name": "multi_flatmedium_3_floor1",
  "refpalette": "deceasedcraft:multi_flatmedium_3/multi_flatmedium_3_floor1_palette",
  "xsize": 16,
  "zsize": 16,
  "slices": [
    [
      " abbavvvvvvcccd ",
      " aaaavvvvvvcccd ",
      " aaaavvvvvvcecd ",
      " abbavvvfvvcecd ",
      " abbavvvffvcccd ",
      " abbavvvvvfcced ",
      " gvaavavvvvgeca ",
      " avvvvavvvfcccd ",
      " avvvvafvfvcccd ",
      " avvvvavvvvcccd ",
      " avvvvavvvvcccd ",
      " gaaaaaaaaagccd ",
      " hccij     iccd ",
      " hccccccccccccd ",
      " akkakkkkkkakka ",
      "                "
    ],
    [
      " l  a      m  n ",
      " aaaaoopqr as t ",
      " a!aauwwxxxa ya ",
      " l AaBCD  EF It ",
      " lJKa  LM NON n ",
      " aPQa RSTU an t ",
      " gVaaWaXYZsg sa ",
      " O0123a4   a  a ",
      " n5 67a   89  a ",
      " #$% ^ar&*()M a ",
      " a+oo+aoo!oa  a ",
      " gaaaaaaaaag  a ",
      " a  -     j-  a ",
      " a  [[[[[[[[  a ",
      " aaaaaaaaaaaaaa ",
      "                "
    ],
    [
      " ] {a      }    ",
      " a||a;::::'a    ",
      " axxaxxxxxx#    ",
      " ] {a     <     ",
      " ]  a           ",
      " a  a >    ,    ",
      " g.aa?a/  `g  \u0370 ",
      " \u0371   \u0372a    a\u0373   ",
      "     `a   (\u0374    ",
      "      a\u0375  8\u0376    ",
      " a||||a\u0377\u0377\u0377\u0377a    ",
      " gaaaaaaaaag    ",
      "         j      ",
      "                ",
      " \u0370  \u0370      \u0370    ",
      "                "
    ],
    [
      " ] \u037aa      \u037b    ",
      " aaaa\u0377\u0377\u0377\u0377\u0377\u0377a    ",
      " aaaa\u037c\u037c\u037cxxxa    ",
      " ] \u037aa     \u037d#    ",
      " ]  a           ",
      " a \u037ea           ",
      " gxaa|a\u037f   F  \u0370 ",
      " t    a    a    ",
      "      a    \u037b    ",
      " ]   \u0384a    \u037b    ",
      " a||||a\u0377\u0377\u0377\u0377a    ",
      " gaaaaaaaaag    ",
      "        j       ",
      "                ",
      " \u0370  \u0370      \u0370    ",
      "                "
    ],
    [
      " a\u0385\u0385a      a    ",
      " aaaa\u0386\u0386\u0386\u0386\u0386\u0386a    ",
      " aaaa\u0387\u0387\u0387\u0387\u0387\u0387a    ",
      " a\u0385\u0385a      F    ",
      " a\u0385\u0385a \u0388  \u0389 \u038a    ",
      " a\u0385\u0385a      \u038c    ",
      " gaaaaa\u0387\u0387\u0387\u0387g  \u0370 ",
      " a    a    a    ",
      " a \u038e  a  \u038e a    ",
      " a    a    a    ",
      " a\u0386\u0386\u0386\u0386a\u0386\u0386\u0386\u0386a    ",
      " gaaaaaaaaag    ",
      "       j        ",
      "                ",
      " \u0370  \u0370      \u0370    ",
      "                "
    ],
    [
      " \u038fc\u0390ccccccc\u038f  \u0391 ",
      " \u038fccccccccc\u038f  \u0391 ",
      " \u038fccccccccc\u038f  \u0391 ",
      " \u038fc\u0390ccccccc\u038f  \u0391 ",
      " \u038fc ccccccc\u038f  \u0391 ",
      " \u038fc ccccccc\u038f  \u0391 ",
      " gcccccccccg  g ",
      " \u038fccccccccc\u038f  \u0391 ",
      " \u038fccccccccc\u038f  \u0391 ",
      " \u038fccccccccc\u038f  \u0391 ",
      " \u038fccccccccc\u038f  \u0391 ",
      " gaaaaaaaaag  \u0391 ",
      " \u0391    j       \u0391 ",
      " \u0391            \u0391 ",
      " g\u0391\u0391g\u0391\u0391\u0391\u0391\u0391\u0391g\u0391\u0391\u0391 ",
      "                "
    ]
  ]
}