{
  "name": "multi_flatmedium_3_top",
  "refpalette": "deceasedcraft:multi_flatmedium_3/multi_flatmedium_3_top_palette",
  "xsize": 16,
  "zsize": 16,
  "slices": [
    [
      " abbbvvvvccddde ",
      " aaaavvvvvvddde ",
      " abbavvvvvvddde ",
      " abbavvvvvvddde ",
      " abbavvvvvvddde ",
      " abbavvvvvvddde ",
      " fvaaavaaaafdda ",
      " avgcvvvvvvddde ",
      " hgcvvvvvvvddde ",
      " iggvvvvvvvddde ",
      " jvvvvavvvvddde ",
      " faaaaaaaaafdde ",
      " kddlm     ldde ",
      " kdddddddddddde ",
      " annannnnnnanna ",
      "                "
    ],
    [
      " o  p  q   r  j ",
      " aaaastusssawxa ",
      " ayAaB  CDEaF a ",
      " I  aJ K   a  a ",
      " o LaB   M aK a ",
      " jNOaJ PQRSa Ta ",
      " fUaaaVaaaaf  a ",
      " iW  XYZ   a  0 ",
      " 1     23  a 4  ",
      " 56       7a  j ",
      " i88ssa9ss9j xj ",
      " #iihaaaaaaf$ 5 ",
      " hW%^     m^    ",
      " j& ********  a ",
      " aaaaaaaaaaaaaa ",
      "                "
    ],
    [
      " () +      -  K ",
      " a[[a      j    ",
      " a  a]     a    ",
      " ( {a]    }(    ",
      "    a]    |(    ",
      " h  a] ; : a    ",
      " # aaa'aaaaf  I ",
      " h   <23   a    ",
      "          >(    ",
      "          ,(    ",
      " i .]]a????a  x ",
      " #hijaaaaaaf    ",
      " 5       m      ",
      "                ",
      " I6 I      I    ",
      "                "
    ],
    [
      " (/ `      \u0370    ",
      " aaaa      j    ",
      " a  a]     j    ",
      " ( \u0371a]    \u0372(    ",
      " (  a]    \u0373(    ",
      " j \u0374a]     j    ",
      " #\u0375aaa[aaaaf  I ",
      " 6         a    ",
      "          \u0376(    ",
      "      \u0377   \u037a(    ",
      " W  \u037b]a????a    ",
      " #ihaaaaaaaf    ",
      "        m       ",
      "                ",
      " I  I      I    ",
      "                "
    ],
    [
      " a\u037c\u037ca      a    ",
      " aaaa      a    ",
      " a\u037c\u037ca      a    ",
      " a\u037c\u037ca \u037d  \u037e j    ",
      " a\u037c\u037ca      a    ",
      " j\u037c\u037ca\u037f\u037f\u037f\u037f\u037f\u037fa    ",
      " #aaaaaaaaaf  I ",
      " \u0384         j    ",
      "        \u0385  a    ",
      "      \u0386    a    ",
      "     \u037fa\u037f\u037f\u037f\u037fa    ",
      "  haaaaaaaaf    ",
      "       m        ",
      "                ",
      " I  I      I    ",
      "                "
    ],
    [
      " \u0387d\u0388ddddddd\u0387  \u0389 ",
      " \u0387ddddddddd\u0387  \u0389 ",
      " \u0387d ddddddd\u0387  \u0389 ",
      " \u0387d\u0388ddddddd\u0387  \u0389 ",
      " \u0387d ddddddd\u0387  \u0389 ",
      " \u0387d ddddddd\u0387  \u0389 ",
      " fdddddddddf  f ",
      " 5 dddddddd\u0387  \u0389 ",
      "    ddddddd\u0387  \u0389 ",
      "    ddddddd\u0387  \u0389 ",
      "    ddddddd\u0387  \u0389 ",
      "  \u038ajaaaaaaaf  \u0389 ",
      "      m       \u0389 ",
      " \u0389            \u0389 ",
      " f\u0389\u0389f\u0389\u0389\u0389\u0389\u0389\u0389f\u0389\u0389\u0389 ",
      "                "
    ],
    [
      " addd\u038c\u038c\u038c\u038c\u038c\u038cddda ",
      " addd\u038c\u038c\u038c\u038c\u038c\u038cddda ",
      " addd\u038c\u038c\u038c\u038c\u038c\u038cddda ",
      " addd\u038c\u038c\u038c\u038c\u038c\u038cddda ",
      " addd\u038c\u038c\u038c\u038c\u038c\u038cddda ",
      " addd\u038c\u038c\u038c\u038c\u038c\u038cddda ",
      " addfa\u038c\u038caaafdda ",
      " jd\u038ea\u038c\u038c\u038c\u038c\u038c\u038cddda ",
      " 0\u038f\u038ea\u038c\u038c\u038c\u038c\u038c\u038cddda ",
      " \u0390 \u038fi\u038c\u038c\u038c\u038c\u038c\u038cddda ",
      "    i\u038c\u038c\u038c\u038c\u038c\u038cddda ",
      "   6#fffffffdda ",
      " \u0391\u0392\u038elm      dda ",
      " jdd        dda ",
      " jnnannnnnnanna ",
      "                "
    ],
    [
      " o       \u0393\u0394   o ",
      " o            o ",
      " o            o ",
      " o       \u0393\u0394   o ",
      " o            o ",
      " o \u0395\u0395         o ",
      " I\u0395\u0395fa\u0396\u0397aaaf  I ",
      " o  a    \u0398 a  o ",
      " \u0399  h\u039a  \u039b\u039b a  o ",
      " 1  \u039c\u039a  \u039b\u039b a  o ",
      "    i\u039d\u039a    a  o ",
      "    fjaaaaaf  o ",
      "    ^      \u039e  o ",
      " \u039f  \u03a0      \u039e  o ",
      " aa5aaaaaaaaaaa ",
      "                "
    ],
    [
      "         \u03a1      ",
      "         \u03a1      ",
      "         \u03a1      ",
      "         \u03a1      ",
      "         \u03a1      ",
      "     \u03a3  \u03a4\u03a1      ",
      "    fa\u03a5\u03a6a\u03a1af  \u03a7 ",
      "    j    \u03a1 a    ",
      "    (   \u03a8! (    ",
      "        \u03a9\u03aa (    ",
      "    h\u039a     a    ",
      "    faaaaaaf    ",
      "                ",
      "                ",
      "    I      I    ",
      "                "
    ],
    [
      "                ",
      "                ",
      "                ",
      "                ",
      "                ",
      "                ",
      "    faaaaaaf    ",
      "    a\u03ab\u03ab\u03ab\u03ab\u03ab\u03aba    ",
      "    a\u03ab\u03ab\u03ab\u03a9\u03aa\u03aba    ",
      "    j\u03ab\u03ab\u03ab\u03a8\u03a8\u03aba    ",
      "    h\u03ab\u03ab\u03ab\u03ab\u03ab\u03aba    ",
      "    f\u03ac\u03ac\u03ac\u03ac\u03ac\u03acf    ",
      "    0\u03ad\u03ad\u03ad\u03ad\u03ad\u03ad\u03ae    ",
      "    \u03ae\u03ad\u03ad\u03ad\u03ad\u03ad\u03ad\u03ae    ",
      "    f\u03ae\u03ae\u03ae\u03ae\u03ae\u03aef    ",
      "                "
    ],
    [
      "                ",
      "                ",
      "                ",
      "                ",
      "                ",
      "                ",
      "    \u03af      \u03af    ",
      "        \u03b0\u03b0      ",
      "       \u03b1\u03aa\u03aa\u03b2     ",
      "       \u03b3\u03a8\u03a9\u03b2     ",
      "        \u0390\u0390      ",
      "    \u03af      \u03af    ",
      "                ",
      "                ",
      "                ",
      "                "
    ],
    [
      "                ",
      "                ",
      "                ",
      "                ",
      "                ",
      "                ",
      "                ",
      "                ",
      "        \u03b4       ",
      "         \u03b4      ",
      "                ",
      "                ",
      "                ",
      "                ",
      "                ",
      "                "
    ]
  ]
}