{
  "name": "multi_flatmedium_3_floor5",
  "refpalette": "deceasedcraft:multi_flatmedium_3/multi_flatmedium_3_floor5_palette",
  "xsize": 16,
  "zsize": 16,
  "slices": [
    [
      " abbbvvvvvvcccd ",
      " aaaavvvvvvcccd ",
      " abbavvvvvvcccd ",
      " abbavvvvvvcccd ",
      " abbavvvvvvcccd ",
      " abbavvvvvvcccd ",
      " evaaavaaaaecca ",
      " avvvvvvvvvcccd ",
      " avvvvvvvvvcccd ",
      " avvvvvvvvvcccd ",
      " avvvvavvvvcccd ",
      " eaaaaaaaaaeccd ",
      " fccgh     gccd ",
      " fccccccccccccd ",
      " aiiaiiiiiiaiia ",
      "                "
    ],
    [
      " j  k      l  a ",
      " aaaamnommma  a ",
      " apqar  stua  a ",
      " j  aw     a  a ",
      " j xar     a  a ",
      " a yaw ABCDa  a ",
      " eEaaaEaaaae  a ",
      " a         a  a ",
      " j   FI JJ a  a ",
      " j  KLM NN a  a ",
      " ammmmaOmmOa  a ",
      " eaaaaaaaaae  a ",
      " a  P     hP  a ",
      " a  QQQQQQQQ  a ",
      " aaaaaaaaaaaaaa ",
      "                "
    ],
    [
      " RS T      U    ",
      " aVVa      a    ",
      " a  aW     a    ",
      " R XaW    YR    ",
      " R  aW    ZR    ",
      " a  aW 0 1 a    ",
      " e2aaa2aaaae  3 ",
      " a   4     a    ",
      " R5   6   YR    ",
      " R7   8   ZR    ",
      " a99WWa####a    ",
      " eaaaaaaaaae    ",
      "         h      ",
      "                ",
      " 3  3      3    ",
      "                "
    ],
    [
      " R$ %      ^    ",
      " aaaa      a    ",
      " a  aW     a    ",
      " R &aW    *R    ",
      " R  aW    (R    ",
      " a )aW     a    ",
      " eVaaaVaaaae  3 ",
      " a         a    ",
      " R+  -6   *R    ",
      " R[  ]8   (R    ",
      " a99WWa####a    ",
      " eaaaaaaaaae    ",
      "        h       ",
      "                ",
      " 3  3      3    ",
      "                "
    ],
    [
      " a{{a      a    ",
      " aaaa      a    ",
      " a{{a      a    ",
      " a{{a }  | a    ",
      " a{{a      a    ",
      " a{{a;;;;;;a    ",
      " eaaaaaaaaae  3 ",
      " a         a    ",
      " a  : ' <  a    ",
      " a    >    a    ",
      " a;;;;a;;;;a    ",
      " eaaaaaaaaae    ",
      "       h        ",
      "                ",
      " 3  3      3    ",
      "                "
    ],
    [
      " ,c.ccccccc,  ? ",
      " ,ccccccccc,  ? ",
      " ,c ccccccc,  ? ",
      " ,c.ccccccc,  ? ",
      " ,c ccccccc,  ? ",
      " ,c ccccccc,  ? ",
      " eccccccccce  e ",
      " ,ccccccccc,  ? ",
      " ,ccccccccc,  ? ",
      " ,ccccccccc,  ? ",
      " ,ccccccccc,  ? ",
      " eaaaaaaaaae  ? ",
      " ?    h       ? ",
      " ?            ? ",
      " e??e??????e??? ",
      "                "
    ]
  ]
}