{
  "name": "multi_flatmedium_3_floor2",
  "refpalette": "deceasedcraft:multi_flatmedium_3/multi_flatmedium_3_floor2_palette",
  "xsize": 16,
  "zsize": 16,
  "slices": [
    [
      " abbavvvvvvcccd ",
      " aaaavvvvvvcccd ",
      " aaaavvvvvvcccd ",
      " abbavvvvvvcccd ",
      " abbavvvvvvcccd ",
      " abbavvvvvvcccd ",
      " evaavavvvvecca ",
      " avvvvavvvvcccd ",
      " avvvvavvvvcccd ",
      " avvvvavvvvcccd ",
      " avvvvavvvvcccd ",
      " eaaaaaaaaaeccd ",
      " fccgh     gccd ",
      " fccccccccccccd ",
      " aiiaiiiiiiaiia ",
      "                "
    ],
    [
      " j  a      k  a ",
      " aaaallmnopa  a ",
      " aaaaqrrsssa  a ",
      " j  atu  uwa  a ",
      " j xa     ya  a ",
      " a Aa BCDE a  a ",
      " eFaaI!JKL e  a ",
      " a    a M  a  a ",
      " j NN a    O  a ",
      " j PP aoQR k  a ",
      " aSllSalllla  a ",
      " eaaaaaaaaae  a ",
      " a  T     hT  a ",
      " a  UUUUUUUU  a ",
      " aaaaaaaaaaaaaa ",
      "                "
    ],
    [
      " V Wa      X    ",
      " aYYaZ00001a    ",
      " assassssssa    ",
      " V Wa     2V    ",
      " V  a     3V    ",
      " a  a 4    a    ",
      " e5aa6a789#e  $ ",
      " a   #a    a%   ",
      " V   ^a    &    ",
      " V    a*   X    ",
      " aYYYYa()+-a    ",
      " eaaaaaaaaae    ",
      "         h      ",
      "                ",
      " $  $      $    ",
      "                "
    ],
    [
      " V [a      ]    ",
      " aaaa{{{{{{a    ",
      " aaaa}}}sssa    ",
      " V [a     |V    ",
      " V  a     ;V    ",
      " a :a      a    ",
      " esaasa'   e  $ ",
      " a    a    a    ",
      " V    a    ]    ",
      " V    a    ]    ",
      " aYYYYa<>,.a    ",
      " eaaaaaaaaae    ",
      "        h       ",
      "                ",
      " $  $      $    ",
      "                "
    ],
    [
      " a??a      a    ",
      " aaaa//////a    ",
      " aaaa``````a    ",
      " a??a      a    ",
      " a??a \u0370  \u0371 a    ",
      " a??a      a    ",
      " eaaaaa````e  $ ",
      " a    a    a    ",
      " a \u0372  a  \u0372 a    ",
      " a    a    a    ",
      " a////a////a    ",
      " eaaaaaaaaae    ",
      "       h        ",
      "                ",
      " $  $      $    ",
      "                "
    ],
    [
      " \u0373c\u0374ccccccc\u0373  \u0375 ",
      " \u0373ccccccccc\u0373  \u0375 ",
      " \u0373ccccccccc\u0373  \u0375 ",
      " \u0373c\u0374ccccccc\u0373  \u0375 ",
      " \u0373c ccccccc\u0373  \u0375 ",
      " \u0373c ccccccc\u0373  \u0375 ",
      " eccccccccce  e ",
      " \u0373ccccccccc\u0373  \u0375 ",
      " \u0373ccccccccc\u0373  \u0375 ",
      " \u0373ccccccccc\u0373  \u0375 ",
      " \u0373ccccccccc\u0373  \u0375 ",
      " eaaaaaaaaae  \u0375 ",
      " \u0375    h       \u0375 ",
      " \u0375            \u0375 ",
      " e\u0375\u0375e\u0375\u0375\u0375\u0375\u0375\u0375e\u0375\u0375\u0375 ",
      "                "
    ]
  ]
}