{
  "name": "multi_terraceplaza_6_base2",
  "refpalette": "deceasedcraft:multi_terraceplaza_6/multi_terraceplaza_6_base2_palette",
  "xsize": 16,
  "zsize": 16,
  "slices": [
    [
      "vabbabbbbbbbcccc",
      "vabbabbbbbbbcccc",
      "vabbabbbbbbbcccc",
      "vabbabbbbbbbcccc",
      "vabbbbbbbbbbcccc",
      "vabbbbbbbbbbcccc",
      "vabbabbbbbbbcccc",
      "vabbabbbbbbbcccc",
      "vabbabbbbbbbcccc",
      "vabbabbbbbbbcccc",
      "vabbabbbbbbdcccc",
      "vabbabbbbbbbcccc",
      "vabbabbbbbbbcccc",
      "vaaaaaaaaaaaaaaa",
      "veeeeeeeeeeeeeee",
      "vvvvvvvvvvvvvvvv"
    ],
    [
      "vaf ag     hii  ",
      "va jag     hk   ",
      "va jag     hl m ",
      "van ag     ol m ",
      "va  p      ol m ",
      "va  q      ol m ",
      "var assss  ol m ",
      "vartauwwu  hl m ",
      "va xa       y   ",
      "va raA     hii  ",
      "vaBraA     di CC",
      "va ra      DiEFF",
      "vaIIaJKJLJ !iEFF",
      "vaaaaaaaaaaaaaaa",
      "veeeeeeeeeeeeeee",
      "vvvvvvvvvvvvvvvv"
    ],
    [
      "va  a      Mii  ",
      "va faN     O    ",
      "va jaP      Q   ",
      "va  at     R    ",
      "va  S           ",
      "va  T      UN   ",
      "vaV aW WW  X    ",
      "var aY     Z    ",
      "va  a           ",
      "va  a      Oii  ",
      "vaxBa      di   ",
      "va Ba       iE00",
      "vaIBa       iE11",
      "vaaaaaaaaaaaaaaa",
      "veeeeeeeeeeeeeee",
      "vvvvvvvvvvvvvvvv"
    ],
    [
      "va  a       ii  ",
      "va  a           ",
      "va  a           ",
      "va  a           ",
      "va  2           ",
      "va  2           ",
      "va  a           ",
      "va  a           ",
      "va  a           ",
      "va  a       ii  ",
      "va  a      di   ",
      "va Ba       iE  ",
      "vax a       iE11",
      "vaaaaaaaaaaaaaaa",
      "veeeeeeeeeeeeeee",
      "vvvvvvvvvvvvvvvv"
    ],
    [
      "va  a       ii  ",
      "va  a           ",
      "va  a           ",
      "va  a           ",
      "va  a           ",
      "va  a           ",
      "va  a           ",
      "va  a           ",
      "va  a           ",
      "va  a       ii  ",
      "va  a      di   ",
      "va  a       iE  ",
      "va  a       iE1 ",
      "vaaaaaaaaaaaaaaa",
      "veeeeeeeeeeeeeee",
      "vvvvvvvvvvvvvvvv"
    ],
    [
      "va  a      3ii  ",
      "va  a      34i  ",
      "va  a      35i  ",
      "va  a      34i  ",
      "va  a      35i  ",
      "va  a      34i  ",
      "va  a      35i  ",
      "va  a      34i  ",
      "va  a      35i  ",
      "va  a      3ii  ",
      "va  a666666di   ",
      "va  a       iEEE",
      "va  a       iE78",
      "vaaaaaaaaaaaaaaa",
      "veeeeeeeeeeeeeee",
      "vvvvvvvvvvvvvvvv"
    ]
  ]
}