{
  "name": "multi_terraceplaza_6_ground",
  "refpalette": "deceasedcraft:multi_terraceplaza_6/multi_terraceplaza_6_ground_palette",
  "xsize": 16,
  "zsize": 16,
  "slices": [
    [
      "HHHabcdeffffffff",
      "HHHagcdeffffffff",
      "HHHabcdehhhhiiii",
      "HHHabcdejjjkcccc",
      "HHHabcdejjjkcccc",
      "HHHabcdejjjkllll",
      "HHHabcdejjjk    ",
      "HHHabcdejjjk    ",
      "HHHagcdejjjk    ",
      "HHHabcdejjjk    ",
      "HHHabcdejjjm    ",
      "HHHabcdejjjhn   ",
      "HHHagcdejjjhoooo",
      "HHHabbdeppqhiiii",
      "HHHadddfffffffff",
      "HHHadddfffffffff"
    ],
    [
      "    ro s        ",
      "    to s        ",
      "    uo swwwx    ",
      "    uo s   w    ",
      "    uo s  yw    ",
      "    uo sy  w    ",
      "    uo s   w    ",
      "    uo s y w    ",
      "    to s   w    ",
      "    ro s  yw    ",
      "    rA xppBC    ",
      "    ro sppDwu   ",
      "    to sppEw    ",
      "          Ewwwww",
      "                ",
      "                "
    ],
    [
      "      FI        ",
      "    JoFK        ",
      "     oFI        ",
      "     oFK        ",
      "     oFK        ",
      "     oFI        ",
      "     oFI        ",
      "     oFKppB     ",
      "    JoFIppD     ",
      "      FKppE     ",
      "     nFK  E     ",
      "      FI  E u   ",
      "    J FK  L     ",
      "      FK  M     ",
      "                ",
      "                "
    ],
    [
      "      FI        ",
      "      FK        ",
      "      FI        ",
      "      FK        ",
      "      FKppB     ",
      "      FIppD     ",
      "      FIppE     ",
      "      FK  E     ",
      "      FI  E     ",
      "      FK  L     ",
      "     uFK  M     ",
      "                ",
      "                ",
      "                ",
      "                ",
      "                "
    ],
    [
      "      FI        ",
      "      FKppB     ",
      "      FIppD     ",
      "      FKppE     ",
      "      FK  E     ",
      "      FI  E     ",
      "      FI  L     ",
      "      FK  M     ",
      "                ",
      "                ",
      "     u          ",
      "                ",
      "                ",
      "                ",
      "                ",
      "                "
    ],
    [
      "      FIppENOOOO",
      "      FK  ENOOOO",
      "      FI  ENOOOO",
      "      FK  LNOOOO",
      "      FK  M     ",
      "                ",
      "                ",
      "                ",
      "                ",
      "                ",
      "                ",
      "                ",
      "                ",
      "                ",
      "                ",
      "                "
    ]
  ]
}