{
  "name": "multi_terraceplaza_6_base1",
  "refpalette": "deceasedcraft:multi_terraceplaza_6/multi_terraceplaza_6_base1_palette",
  "xsize": 16,
  "zsize": 16,
  "slices": [
    [
      "vabba      cdd  ",
      "vabba      ced  ",
      "vabba      ced  ",
      "vabba      ced  ",
      "vabba      ced  ",
      "vabba      ced  ",
      "vabba      ced  ",
      "vabba      ced  ",
      "vabba      ced  ",
      "vabba      cdd  ",
      "vabbaffffffgd   ",
      "vabbaeeeeeeedhhh",
      "vabbaeeeeeeedhee",
      "vaaaaaaaaaaaaaaa",
      "viiiiiiiiiiiiiii",
      "vvvvvvvvvvvvvvvv"
    ],
    [
      "viiia      cdd  ",
      "viiia      c d  ",
      "viiia      c d  ",
      "viiia      c d  ",
      "viiia      c d  ",
      "viiia      c d  ",
      "viiia      c d  ",
      "viiia      c d  ",
      "viiia      c d  ",
      "viiia      cdd  ",
      "viiiaffffffgd   ",
      "viiia j   j dhhh",
      "viiia       d   ",
      "viiiaaaaaaaaaaaa",
      "viiiiiiiiiiiiiii",
      "vvvvvvvvvvvvvvvv"
    ],
    [
      "viiia      cddk ",
      "viiia      c dk ",
      "viiia      cjdk ",
      "viiia      c dk ",
      "viiia      c dk ",
      "viiia      c dk ",
      "viiia      c dk ",
      "viiia      c dk ",
      "viiia      cjdk ",
      "viiia      cddk ",
      "viiiaffffffgd   ",
      "viiia l   l dhhh",
      "viiia       dlll",
      "viiiaaaaaaaaaaaa",
      "viiiiiiiiiiiiiii",
      "vvvvvvvvvvvvvvvv"
    ],
    [
      "viiial      lddd",
      "viiial      lddd",
      "viiial      lddd",
      "viiial      lddd",
      "viiial      lddd",
      "viiial      lddd",
      "viiial      lddd",
      "viiial      lddd",
      "viiial      lddd",
      "viiial      lddd",
      "viiial     gmnnn",
      "viiiallllllllhhh",
      "viiia       llii",
      "viiiaaaaaaaaaaaa",
      "viiiiiiiiiiiiiii",
      "vvvvvvvvvvvvvvvv"
    ],
    [
      "viiiabbbbbbbllol",
      "viiiabbbbbbbiiii",
      "viiiabbbbbbbiiii",
      "viiiabbbbbbbiiii",
      "viiiabbbbbbbiiii",
      "viiiabbbbbbbiiii",
      "viiiabbbbbbbiiii",
      "viiiabbbbbbbiiii",
      "viiiabbbbbbbpppp",
      "viiiabbbbbbbpqpq",
      "viiiabbbbbbgpppq",
      "viiiabbbbbbbpppp",
      "viiiabbbbbbbpppp",
      "viiiaaaaaaaaaaaa",
      "viiiiiiiiiiiiiii",
      "vvvvvvvvvvvvvvvv"
    ],
    [
      "viiiaiiiiiiriiii",
      "viiiaiiiiiiriiii",
      "viiiaiiiiiiriiii",
      "viiiaiiisssriiii",
      "viiiaiiisssriiii",
      "viiiaiiisssrpppp",
      "viiiaiiisssrpppp",
      "viiiaiiisssrpppp",
      "viiiaiiisssr    ",
      "viiiaiiisssr    ",
      "viiiaiiisssgt   ",
      "viiiaiiisssruwxy",
      "viiiaiiisssrpppp",
      "viiiaaaaaaarrrrr",
      "viiiiiiiiiiiiiii",
      "vvvvvvvvvvvvvvvv"
    ]
  ]
}