{
  "name": "multi_terraceplaza_17_floor1",
  "refpalette": "deceasedcraft:multi_terraceplaza_17/multi_terraceplaza_17_floor1_palette",
  "xsize": 16,
  "zsize": 16,
  "slices": [
    [
      "                ",
      "                ",
      "                ",
      " a            a ",
      "                ",
      "                ",
      "                ",
      "                ",
      "                ",
      "                ",
      "                ",
      "                ",
      "                ",
      "                ",
      " a            a ",
      "                "
    ],
    [
      "bc            cb",
      "bc            cb",
      "bc            cb",
      "ca            ac",
      "bc            cb",
      "bc            cb",
      "bc            cb",
      "bc            cb",
      "bc            cb",
      "bc            cb",
      "bc            cb",
      "bc            cb",
      "bc            cb",
      "bc            cb",
      "ca            ac",
      "bc            cb"
    ],
    [
      "de            fd",
      "de            fd",
      "de            fd",
      "dag          had",
      "de            fd",
      "de            fd",
      "de            fd",
      "de            fd",
      "de            fd",
      "de            fd",
      "de            fd",
      "de            fd",
      "ie            fi",
      "je            fj",
      "jag          haj",
      "de            fd"
    ],
    [
      " k            k ",
      " k            k ",
      " k            k ",
      " a            a ",
      " k            k ",
      " k            k ",
      " k            k ",
      " k            k ",
      " k            k ",
      " k            k ",
      " k            k ",
      "ik            ki",
      "lk            kl",
      "mk            kn",
      "ma            an",
      " k            k "
    ],
    [
      "                ",
      "                ",
      "                ",
      " a            a ",
      "                ",
      "                ",
      "                ",
      "                ",
      "                ",
      "                ",
      "i              i",
      "ln            ml",
      "m              n",
      "                ",
      " a            a ",
      "                "
    ],
    [
      "                ",
      "                ",
      "                ",
      " a            a ",
      "                ",
      "                ",
      "                ",
      "                ",
      "                ",
      "i              i",
      "ln            ml",
      "m              n",
      "                ",
      "                ",
      " a            a ",
      "                "
    ]
  ]
}