{
  "name": "multi_terraceplaza_17_base2",
  "refpalette": "deceasedcraft:multi_terraceplaza_17/multi_terraceplaza_17_base2_palette",
  "xsize": 16,
  "zsize": 16,
  "slices": [
    [
      "abccccccccccccba",
      "abccccccccccccba",
      "abdccccccccccdba",
      "efghcccccccchgfa",
      "abdccccccccccdba",
      "abccccccccccccba",
      "abccccccccccccba",
      "abccccccccccccba",
      "abccccccccccccba",
      "abccccccccccccba",
      "abccccccccccccba",
      "abccccccccccccba",
      "abccccccccccccba",
      "abdccccccccccdba",
      "efghcccccccchgfa",
      "abdccccccccccdba"
    ],
    [
      "ij            kl",
      "i              l",
      "immmm      mmmml",
      "if nm      mn fl",
      "immmm      mmmml",
      "i              l",
      "io            pl",
      "ij            kl",
      "i              l",
      "i              l",
      "io            pl",
      "ij            kl",
      "i              l",
      "immmm      mmmml",
      "ef nm      mn f ",
      " qmmm      mmmr "
    ],
    [
      " s            t ",
      "us            t ",
      " s            t ",
      "wf x        x f ",
      " s            t ",
      " s            t ",
      " s            t ",
      " s            t ",
      " s            t ",
      "ys            t ",
      " s            t ",
      "As            t ",
      " s            t ",
      "Bs            t ",
      "ef x        x f ",
      "                "
    ],
    [
      " s            t ",
      " s            t ",
      " s            t ",
      "Cf D        D f ",
      " s            t ",
      " s            t ",
      " s            t ",
      " s            t ",
      " s            t ",
      " s            t ",
      " s            t ",
      " s            t ",
      " s            t ",
      " s            t ",
      "ef D        D f ",
      "                "
    ],
    [
      " s            t ",
      " s            t ",
      " s            t ",
      " f E        E f ",
      " s            t ",
      " s            t ",
      " s            t ",
      " s            t ",
      " s            t ",
      " s            t ",
      " s            t ",
      " s            t ",
      " s            t ",
      " s            t ",
      "ef E        E f ",
      "                "
    ],
    [
      " s            t ",
      " s            t ",
      " s          F t ",
      " f F        F f ",
      " s            t ",
      " s            t ",
      " s            t ",
      " s            t ",
      " s            t ",
      " s            t ",
      " s            t ",
      " s            t ",
      " s            t ",
      " s            t ",
      "ef F        F f ",
      "                "
    ]
  ]
}