{
  "name": "multi_terraceplaza_17_floor3",
  "refpalette": "deceasedcraft:multi_terraceplaza_17/multi_terraceplaza_17_floor3_palette",
  "xsize": 16,
  "zsize": 16,
  "slices": [
    [
      "                ",
      "                ",
      "                ",
      " a            a ",
      "                ",
      "                ",
      "                ",
      "bbcddddddddddcbb",
      "eecffffffffffcee",
      "ggcffffffffffcgg",
      "hh            hh",
      "ii            ii",
      "                ",
      "jjjjjjjjjjjjjjjj",
      "                ",
      "                "
    ],
    [
      "                ",
      "                ",
      "                ",
      " a            a ",
      "bbcddddddddddcbb",
      "eecffffffffffcee",
      "ggcffffffffffcgg",
      "hh            hh",
      "ii            ii",
      "                ",
      "                ",
      "                ",
      "                ",
      "                ",
      "                ",
      "                "
    ],
    [
      "                ",
      "bbcddddddddddcbb",
      "eecffffffffffcee",
      "kacllllllllllcak",
      "mmnnnnnnnnnnnnmm",
      "ii            ii",
      "                ",
      "                ",
      "                ",
      "                ",
      "                ",
      "                ",
      "                ",
      "                ",
      "                ",
      "                "
    ],
    [
      "ggcffffffffffcgg",
      "hh            hh",
      "mmmmmmmmmmmmmmmm",
      "oooooooooooooooo",
      "jjjjjjjjjjjjjjjj",
      "                ",
      "                ",
      "                ",
      "                ",
      "                ",
      "                ",
      "                ",
      "                ",
      "                ",
      "                ",
      "                "
    ],
    [
      "                ",
      "                ",
      "                ",
      "                ",
      "                ",
      "                ",
      "                ",
      "                ",
      "                ",
      "                ",
      "                ",
      "                ",
      "                ",
      "                ",
      "                ",
      "                "
    ],
    [
      "                ",
      "                ",
      "                ",
      "                ",
      "                ",
      "                ",
      "                ",
      "                ",
      "                ",
      "                ",
      "                ",
      "                ",
      "                ",
      "                ",
      "                ",
      "                "
    ]
  ]
}