{
  "name": "multi_terraceplaza_17_floor2",
  "refpalette": "deceasedcraft:multi_terraceplaza_17/multi_terraceplaza_17_floor2_palette",
  "xsize": 16,
  "zsize": 16,
  "slices": [
    [
      "                ",
      "                ",
      "                ",
      " a            a ",
      "                ",
      "                ",
      "                ",
      "                ",
      "b              b",
      "cd            ec",
      "e              d",
      "                ",
      "                ",
      "                ",
      " a            a ",
      "                "
    ],
    [
      "                ",
      "                ",
      "                ",
      " a            a ",
      "                ",
      "                ",
      "                ",
      "b              b",
      "cd            ec",
      "e              d",
      "                ",
      "                ",
      "                ",
      "                ",
      " a            a ",
      "                "
    ],
    [
      "                ",
      "                ",
      "                ",
      " a            a ",
      "                ",
      "                ",
      "b              b",
      "cd            ec",
      "e              d",
      "                ",
      "                ",
      "                ",
      "                ",
      "                ",
      " a            a ",
      "                "
    ],
    [
      "fg            gf",
      "fg            gf",
      "fg            gf",
      "ga            ag",
      "hg            gh",
      "bg            gb",
      "cg            gc",
      "eg            gd",
      " g            g ",
      " g            g ",
      " g            g ",
      " g            g ",
      " g            g ",
      " g            g ",
      "ga            ag",
      "                "
    ],
    [
      "ij            ki",
      "ij            ki",
      "ij            ki",
      "lam          nal",
      "lj            kl",
      "cj            kc",
      "ej            kd",
      " j            k ",
      " j            k ",
      " j            k ",
      " j            k ",
      " j            k ",
      " j            k ",
      "ojpqqqqqqqqqqpko",
      "gaprrrrrrrrrrpag",
      "sspttttttttttpss"
    ],
    [
      " u            u ",
      " u            u ",
      " u            u ",
      "ea            ad",
      "eu            ud",
      "eu            ud",
      " u            u ",
      " u            u ",
      " u            u ",
      " u            u ",
      "oupqqqqqqqqqqpuo",
      "wupttttttttttpuw",
      "sspttttttttttpss",
      "xxxxxxxxxxxxxxxx",
      "xxxxxxxxxxxxxxxx",
      "yyyyyyyyyyyyyyyy"
    ]
  ]
}