{
  "name": "multi_terraceplaza_17_base1",
  "refpalette": "deceasedcraft:multi_terraceplaza_17/multi_terraceplaza_17_base1_palette",
  "xsize": 16,
  "zsize": 16,
  "slices": [
    [
      " a            b ",
      " a            b ",
      " a c        c b ",
      " d cc      cccd ",
      " a c          b ",
      " a            b ",
      " a            b ",
      " a            b ",
      " a            b ",
      " a            b ",
      " a            b ",
      " a            b ",
      " a            b ",
      " a c          b ",
      "edcc       cccd ",
      "   c            "
    ],
    [
      " a            b ",
      " a            b ",
      " a            b ",
      " dccc      cc d ",
      " a c        c b ",
      " a            b ",
      " a            b ",
      " a            b ",
      " a            b ",
      " a            b ",
      " a            b ",
      " a            b ",
      " a            b ",
      " a c        c b ",
      "edccc      cccd ",
      "   c        c   "
    ],
    [
      " a            b ",
      " a            b ",
      " a            b ",
      " dcc        c d ",
      " a            b ",
      " a            b ",
      " a            b ",
      " a            b ",
      " a            b ",
      " a            b ",
      " a            b ",
      " a            b ",
      " a            b ",
      " a c        c b ",
      "ed cc       c d ",
      "                "
    ],
    [
      "fg             f",
      "f              f",
      "f              f",
      "fd c          df",
      "f              f",
      "f              f",
      "f              f",
      "f              f",
      "f              f",
      "f              f",
      "f              f",
      "f              f",
      "f              f",
      "f              f",
      "fd c        c df",
      "f              f"
    ],
    [
      "f              f",
      "f              f",
      "f              f",
      "fd            df",
      "f              f",
      "f              f",
      "f              f",
      "f              f",
      "f              f",
      "f              f",
      "f              f",
      "f              f",
      "f              f",
      "f              f",
      "fd            df",
      "f              f"
    ],
    [
      "hi            if",
      "hi            if",
      "hi            if",
      "id            di",
      "hi            if",
      "hi            if",
      "hi            if",
      "hi            if",
      "hi            if",
      "hi            if",
      "hi            if",
      "hi            if",
      "hi            if",
      "hi            if",
      "id            di",
      "hi            if"
    ]
  ]
}