{
  "name": "multi_nuclearpowerplant_14_base3",
  "refpalette": "deceasedcraft:multi_nuclearpowerplant_14/multi_nuclearpowerplant_14_base3_palette",
  "xsize": 16,
  "zsize": 16,
  "slices": [
    [
      "vvvvvvvvvvvvvvvv",
      "vaabccccccccbdba",
      "vaabccccccccbdba",
      "vaabccccccccbdbb",
      "vaabccccccccbdbd",
      "vadddddddddddddd",
      "ddeeeeeeeeeeeedd",
      "feeeeeeeeeeeeeee",
      "feeeeeeeeeeeeeee",
      "beeeeeeeeeeeeeee",
      "feeeddddddddeeee",
      "feddffffffffddde",
      "fgfff      fffgd",
      "ff            ff",
      "h               ",
      "                "
    ],
    [
      "vvvvvvvvvvvvvvvv",
      "vaaij klmk  inia",
      "vaaijo      p ia",
      "vaaij  q   ri ii",
      "vaaij stts ri iu",
      "vawwwwwwwwwwwxwu",
      "ww y          ww",
      " A             B",
      " A y            ",
      "iA              ",
      " A yCCCCCCCC    ",
      " ACC        CCC ",
      " D            DC",
      "f               ",
      "E               ",
      "                "
    ],
    [
      "vvvvvvvvvvvvvvvv",
      "vaaiF mIIJ  iKia",
      "vaaiL       M ia",
      "vaaiN      Oi ii",
      "vaaiF  PQ   i iu",
      "vawwwCCCCCCwwRwu",
      "wwSy          ww",
      "               T",
      "   y            ",
      "i               ",
      "   yCCCCCCCC    ",
      "  CC        CCC ",
      " D            DC",
      "f               ",
      "                ",
      "                "
    ],
    [
      "vvvvvvvvvvvvvvvv",
      "vaaiN       i ia",
      "vaaiF      Ub ia",
      "vaaiL       iVii",
      "vaaiF      Wi iu",
      "vawwwCCCCCCwwXwu",
      "ww           Yww",
      "Z              0",
      "Z               ",
      "i               ",
      "    CCCCCCCC    ",
      "  CC        CCC ",
      " D            DC",
      "f               ",
      "                ",
      "                "
    ],
    [
      "vvvvvvvvvvvvvvvv",
      "vaaiL       i ia",
      "vaaiN       iaia",
      "vaaiF       iaii",
      "vaaiN       iaiu",
      "vawwwCCCCCCwwwwu",
      "ww            ww",
      "   1            ",
      "                ",
      "i  1            ",
      "    CCCCCCCC    ",
      "  CC        CCC ",
      " D            DC",
      "f               ",
      "                ",
      "                "
    ],
    [
      "vvvvvvvvvvvvvvvv",
      "vaai        iiia",
      "vaai        iiia",
      "vaai        iiii",
      "vaai        iiiu",
      "vawwwwwwwwwwwwwu",
      "ww22          ww",
      "  22            ",
      "  22            ",
      "i 22            ",
      "  22CCCCCCCC    ",
      "  CC        CCC ",
      " D            DC",
      "f               ",
      "                ",
      "                "
    ]
  ]
}