{
  "name": "multi_nuclearpowerplant_14_base6",
  "refpalette": "deceasedcraft:multi_nuclearpowerplant_14/multi_nuclearpowerplant_14_base6_palette",
  "xsize": 16,
  "zsize": 16,
  "slices": [
    [
      "vvvvvvvvvvvvvvvv",
      "vabbbbbbbbbbbbbb",
      "vabbbbbbbbbbbbbb",
      "vabbbccccccccccc",
      "vacccaaaaaaacccc",
      "vcaaaaaaccccdddd",
      "caaaaccceeeddddd",
      "aaacceeeffeddddd",
      "accddeffffeddddd",
      "cddddeffffeddddd",
      "dddddeffffeddddd",
      "dgdddeffffeddddd",
      "dhdddeffffedddhd",
      "dddddeffffeddddd",
      "dddddeffffeddddd",
      "dddddeffffeddddd"
    ],
    [
      "vvvvvvvvvvvvvvvv",
      "vabbbbbbbbbbbbbb",
      "vabbbbbbbbbbbbbb",
      "vabbbbbbbbbbbbbb",
      "vabbbbbbbbbbiiii",
      "vabbbbbbiiii    ",
      "vabbbiii        ",
      "vabii           ",
      "vii             ",
      "i               ",
      "                ",
      " j              ",
      " k            k ",
      " l            l ",
      "                ",
      "                "
    ],
    [
      "vvvvvvvvvvvvvvvv",
      "vabbbbbbbbbbbbbb",
      "vabbbbbbbbbbbbbb",
      "vabbbbbbbbbbbbbb",
      "vabbbbbbbbbbiiii",
      "vabbbbbbiiii    ",
      "vabbbiii        ",
      "vabii           ",
      "vii             ",
      "i               ",
      "                ",
      "                ",
      " k            k ",
      "                ",
      "                ",
      "                "
    ],
    [
      "vvvvvvvvvvvvvvvv",
      "vabbbbbbbbbbbbbb",
      "vabbbbbbbbbbbbbb",
      "vabbbbbbbbbbbbbb",
      "vabbbbbbbbbbiiii",
      "vabbbbbbiiii    ",
      "vabbbiii        ",
      "vabii           ",
      "vii             ",
      "i               ",
      "                ",
      "                ",
      " k            k ",
      "                ",
      "                ",
      "                "
    ],
    [
      "vvvvvvvvvvvvvvvv",
      "vabbbbbbbbbbbbbb",
      "vabbbbbbbbbbbbbb",
      "vabbbbbbbbbbbbbb",
      "vabbbbbbbbbbiiii",
      "vabbbbbbiiii    ",
      "vabbbiii        ",
      "vabii           ",
      "vii             ",
      "i               ",
      "                ",
      "                ",
      " k            k ",
      "                ",
      "                ",
      "                "
    ],
    [
      "vvvvvvvvvvvvvvvv",
      "vabbbbbbbbbbbbbb",
      "vabbbbbbbbbbbbbb",
      "vabbbbbbbbbbbbbb",
      "vabbbbbbbbbbiiii",
      "vabbbbbbiiii    ",
      "vabbbiii        ",
      "vabii           ",
      "vii             ",
      "i               ",
      "                ",
      "                ",
      " k            k ",
      "                ",
      "                ",
      "                "
    ]
  ]
}