{
  "name": "multi_nuclearpowerplant_14_ground",
  "refpalette": "deceasedcraft:multi_nuclearpowerplant_14/multi_nuclearpowerplant_14_ground_palette",
  "xsize": 16,
  "zsize": 16,
  "slices": [
    [
      "zazzzzazzazzzaaz",
      "zzazzzazazzaaaaa",
      "azzzaazaaaaaaaaa",
      "zzazaaaaaaaaaaaa",
      "zazaaaaaaaaaaaaa",
      "aaaaaaaaaaaabbbb",
      "aaaaaaaabbbbbccc",
      "aaaaabbbbccccccc",
      "aaabbbcccccccccc",
      "abbbcccccccccccc",
      "bbcccccccccccc  ",
      "ccccccccde      ",
      "ccccc efge      ",
      "cc    h gi      ",
      "        g       ",
      "      j g       "
    ],
    [
      "k               ",
      "                ",
      "                ",
      "                ",
      "            llmn",
      "        llnnzzza",
      "     lnmzzzazzzz",
      "   lnzzzzzzzzazz",
      " lnzzzzzzazzzzzz",
      "mzzaazzzzzzzzccc",
      "zzzzzzzccccccccc",
      "azzzcccccccccccc",
      "zccccccccccccccc",
      "cccccccccccccccc",
      "cccccccccccccccc",
      "ccccccccc       "
    ],
    [
      "                ",
      "                ",
      "                ",
      "                ",
      "                ",
      "            oooo",
      "        ooooo   ",
      "     oooo       ",
      "   ooo          ",
      " ooo     z  zzzz",
      "oo    zzzzzzzzzz",
      " k  zzzzzzzzzzzz",
      "kzzzzzzzzzzzzzzz",
      "zzzzzzzzzzzzzzzz",
      "zzzzzzzzcccccccc",
      "zzzccccccccccccc"
    ],
    [
      "                ",
      "                ",
      "                ",
      "                ",
      "                ",
      "            oooo",
      "        ooooo   ",
      "     oooo       ",
      "   ooo          ",
      " ooo           k",
      "oo      k   p  p",
      "     p    k     ",
      "        q       ",
      " kk      k zzk  ",
      "k k z   zzzzzzzz",
      "   zzzzzzzazzzzz"
    ],
    [
      "                ",
      "                ",
      "                ",
      "                ",
      "                ",
      "            rrrr",
      "        rrrr    ",
      "     rrr        ",
      "   rr           ",
      " rr             ",
      "r               ",
      "                ",
      "                ",
      "                ",
      "          k     ",
      "   k         p  "
    ],
    [
      "                ",
      "                ",
      "                ",
      "                ",
      "                ",
      "                ",
      "                ",
      "                ",
      "                ",
      "                ",
      "                ",
      "                ",
      "                ",
      "                ",
      "                ",
      "                "
    ]
  ]
}