{
  "name": "multi_nuclearpowerplant_14_base5",
  "refpalette": "deceasedcraft:multi_nuclearpowerplant_14/multi_nuclearpowerplant_14_base5_palette",
  "xsize": 16,
  "zsize": 16,
  "slices": [
    [
      "vvvvvvvvvvvvvvvv",
      "vabbbbbbbbbbbbbb",
      "vabbbbbbbbbbbbbb",
      "vabbbbbbbbbbbbbb",
      "vabbbbbbbbbbcccc",
      "vabbbbbbcccc    ",
      "vabbbccc        ",
      "vabcc           ",
      "vcc             ",
      "c               ",
      "                ",
      "                ",
      " d            d ",
      "                ",
      "                ",
      "                "
    ],
    [
      "vvvvvvvvvvvvvvvv",
      "vabbbbbbbbbbbbbb",
      "vabbbbbbbbbbbbbb",
      "vabbbbbbbbbbbbbb",
      "vabbbbbbbbbbcccc",
      "vabbbbbbcccc    ",
      "vabbbccc        ",
      "vabcc           ",
      "vcc             ",
      "c               ",
      "                ",
      "                ",
      " d            d ",
      "                ",
      "                ",
      "                "
    ],
    [
      "vvvvvvvvvvvvvvvv",
      "vabbbbbbbbbbbbbb",
      "vabbbbbbbbbbbbbb",
      "vabbbbbbbbbbbbbb",
      "vabbbbbbbbbbcccc",
      "vabbbbbbcccc    ",
      "vabbbccc        ",
      "vabcc           ",
      "vcc             ",
      "c               ",
      "                ",
      "                ",
      " d            d ",
      "                ",
      "                ",
      "                "
    ],
    [
      "vvvvvvvvvvvvvvvv",
      "vabbbbbbbbbbbbbb",
      "vabbbbbbbbbbbbbb",
      "vabbbbbbbbbbbbbb",
      "vabbbbbbbbbbcccc",
      "vabbbbbbcccc    ",
      "vabbbccc        ",
      "vabcc           ",
      "vcc             ",
      "c               ",
      "                ",
      "                ",
      " d            d ",
      "                ",
      "                ",
      "                "
    ],
    [
      "vvvvvvvvvvvvvvvv",
      "vabbbbbbbbbbbbbb",
      "vabbbbbbbbbbbbbb",
      "vabbbbbbbbbbbbbb",
      "vabbbbbbbbbbcccc",
      "vabbbbbbcccc    ",
      "vabbbccc        ",
      "vabcc           ",
      "vcc             ",
      "c               ",
      "                ",
      "                ",
      " d            d ",
      "                ",
      "                ",
      "                "
    ],
    [
      "vvvvvvvvvvvvvvvv",
      "vabbbbbbbbbbbbbb",
      "vabbbbbbbbbbbbbb",
      "vabbbbbbbbbbbbbb",
      "vabbbbbbbbbbcccc",
      "vabbbbbbcccc    ",
      "vabbbccc        ",
      "vabcc           ",
      "vcc             ",
      "c               ",
      "                ",
      "                ",
      " d            d ",
      "                ",
      "                ",
      "                "
    ]
  ]
}