{
  "name": "multi_nuclearpowerplant_14_base2",
  "refpalette": "deceasedcraft:multi_nuclearpowerplant_14/multi_nuclearpowerplant_14_base2_palette",
  "xsize": 16,
  "zsize": 16,
  "slices": [
    [
      "vvvvvvvvvvvvvvvv",
      "vaab        bbba",
      "vaab        bbba",
      "vaab        bbbb",
      "vaab        bbbc",
      "vadddddddddddddc",
      "dd            dd",
      "                ",
      "                ",
      "b               ",
      "    eeeeeeee    ",
      "  ee        eee ",
      " f            fe",
      "g               ",
      "                ",
      "                "
    ],
    [
      "vvvvvvvvvvvvvvvv",
      "vaabhihhhhihbbba",
      "vaabhhhhhhhhbbba",
      "vaabhhhhhhhhbbbb",
      "vaabhhhhhhhhbbbj",
      "vadddddddddddddj",
      "dd            dd",
      "                ",
      "                ",
      "b               ",
      "    eeeeeeee    ",
      "  ee        eee ",
      " f            fe",
      "g               ",
      "                ",
      "                "
    ],
    [
      "vvvvvvvvvvvvvvvv",
      "vaab k    k baaa",
      "vaab        baaa",
      "vaab        baaa",
      "vaab        bbbb",
      "vadddddddddddddb",
      "dd            dd",
      "                ",
      "                ",
      "b               ",
      "    eeeeeeee    ",
      "  ee        eee ",
      " f            fe",
      "g               ",
      "                ",
      "                "
    ],
    [
      "vvvvvvvvvvvvvvvv",
      "vaab k    k baaa",
      "vaabkkkkkkkkkkkk",
      "vaab        baaa",
      "vaab        bbbb",
      "vadddddddddddddb",
      "dd            dd",
      "                ",
      "                ",
      "b               ",
      "    eeeeeeee    ",
      "  ee        eee ",
      " f            fe",
      "g               ",
      "                ",
      "                "
    ],
    [
      "vvvvvvvvvvvvvvvv",
      "vaaaaaaaaaaaaaaa",
      "vaaaaaaaaaaaaaaa",
      "vaaaaaaaaaaaaaaa",
      "vggggggggggggggb",
      "ggllllllllllllgg",
      "ll            ll",
      "                ",
      "                ",
      "b               ",
      "g   llllllll    ",
      "g llgggggggglll ",
      "ggggg      ggggl",
      "gg            gg",
      "                ",
      "                "
    ],
    [
      "vvvvvvvvvvvvvvvv",
      "vaaaaaaaaaaaaaaa",
      "vaaaaaaaaaaaaaaa",
      "vaaaaaaaaaaaaaaa",
      "vggggggggggggggb",
      "ggmmmmmmmmmmmmgg",
      "mmmmmmmmmmmmmmmm",
      "mmmmmnnnnnnmmmmm",
      "mmmmmmmmmmmmmmmm",
      "bmmmmmmmmmmmmmmn",
      "gmmmmmmmmmmmmmmm",
      "gmmmggggggggmmmm",
      "gggggooooooggggm",
      "ggoooooooooooogg",
      "oooooooooooooooo",
      "oooooooooooooooo"
    ]
  ]
}