{
  "name": "multi_nuclearpowerplant_14_base4",
  "refpalette": "deceasedcraft:multi_nuclearpowerplant_14/multi_nuclearpowerplant_14_base4_palette",
  "xsize": 16,
  "zsize": 16,
  "slices": [
    [
      "vvvvvvvvvvvvvvvv",
      "vabbbbbbbbbbbbbb",
      "vabbbbbbbbbbbbbb",
      "vabbbbbbbbbbbbbb",
      "vabbbbbbbbbbcccc",
      "vabbbbbbcccc    ",
      "vabbbccc        ",
      "vabcc           ",
      "vcc             ",
      "c               ",
      "                ",
      "                ",
      " d            d ",
      "                ",
      "                ",
      "                "
    ],
    [
      "vvvvvvvvvvvvvvvv",
      "vabbbbbbbbbbbbbb",
      "vabbbbbbbbbbbbbb",
      "vabbbbbbbbbbbbbb",
      "vabbbbbbbbbbcccc",
      "vabbbbbbcccc    ",
      "vabbbccc        ",
      "vabcc           ",
      "vcc             ",
      "c               ",
      "                ",
      "                ",
      " d            d ",
      "                ",
      "                ",
      "                "
    ],
    [
      "vvvvvvvvvvvvvvvv",
      "vabbbbbbbbbbbbbb",
      "vabbbbbbbbbbbbbb",
      "vabbbbbbbbbbbbbb",
      "vabbbbbbbbbbcccc",
      "vabbbbbbcccc    ",
      "vabbbccc        ",
      "vabcc           ",
      "vcc             ",
      "c               ",
      "                ",
      "                ",
      " d            d ",
      "                ",
      "                ",
      "                "
    ],
    [
      "vvvvvvvvvvvvvvvv",
      "vabbbbbbbbbbbbbb",
      "vabbbbbbbbbbbbbb",
      "vabbbbbbbbbbbbbb",
      "vabbbbbbbbbbcccc",
      "vabbbbbbcccc    ",
      "vabbbccc        ",
      "vabcc           ",
      "vcc             ",
      "c               ",
      "                ",
      "                ",
      " d            d ",
      "                ",
      "                ",
      "                "
    ],
    [
      "vvvvvvvvvvvvvvvv",
      "vabbbbbbbbbbbbbb",
      "vabbbbbbbbbbbbbb",
      "vabbbbbbbbbbbbbb",
      "vabbbbbbbbbbcccc",
      "vabbbbbbcccc    ",
      "vabbbccc        ",
      "vabcc           ",
      "vcc             ",
      "c               ",
      "                ",
      "                ",
      " d            d ",
      "                ",
      "                ",
      "                "
    ],
    [
      "vvvvvvvvvvvvvvvv",
      "vaaaaaaaaaaaaaaa",
      "vaaaaaaaaaaaaaaa",
      "vaaaaaaaaaaaaaaa",
      "vaaaaaaaaaaacccc",
      "vaaaaaaacccc    ",
      "vaaaaccc        ",
      "vaacc           ",
      "vcc             ",
      "c               ",
      "e               ",
      "e   eeeeeeee    ",
      "edeee      eeed ",
      "ee            ee",
      "                ",
      "                "
    ]
  ]
}