{
  "name": "multi_nuclearpowerplant_14_base7",
  "refpalette": "deceasedcraft:multi_nuclearpowerplant_14/multi_nuclearpowerplant_14_base7_palette",
  "xsize": 16,
  "zsize": 16,
  "slices": [
    [
      "vvvvvvvvvvvvvvvv",
      "aaaaaaaaaaaaaaaa",
      "aaaaaaaaaaaaaaaa",
      "aaaaabbbbbbbbbbb",
      "aabbb           ",
      "ab              ",
      "b               ",
      "         c      ",
      "                ",
      "                ",
      "      d  e      ",
      " f              ",
      " g            g ",
      "                ",
      "                ",
      "                "
    ],
    [
      "vvvvvvvvvvvvvvvv",
      "aaaaaaaaaaaaaaaa",
      "aaaaaaaaaaaaaaaa",
      "aaaaabbbbbbbbbbb",
      "aabbb           ",
      "ab              ",
      "b               ",
      "         c      ",
      "       hhhhhhhhh",
      "       hhhhhhhhh",
      "      dhhe      ",
      " f     hh       ",
      " g     hh     g ",
      "       hh       ",
      "       hh       ",
      "       hh       "
    ],
    [
      "vvvvvvvvvvvvvvvv",
      "aaaaaaaaaaaaaaaa",
      "aaaaaaaaaaaaaaaa",
      "aaaaabbbbbbbbbbb",
      "aabbb           ",
      "ab              ",
      "b               ",
      "       iiiiiiiii",
      "      jkkkkkkkkk",
      "      jkkkkkkkkk",
      "      jkklmmmmmm",
      " f    jkkn      ",
      " g    jkkn    g ",
      "      jkkn      ",
      "      jkkn      ",
      "      jkkn      "
    ],
    [
      "vvvvvvvvvvvvvvvv",
      "aaaaaaaaaaaaaaaa",
      "aaaaaaaaaaaaaaaa",
      "aaaaabbbbbbbbbbb",
      "aabbb           ",
      "ab              ",
      "b               ",
      "       iiiiiiiii",
      "      jkkkkkkkkk",
      "      jkkkkkkkkk",
      "      jkklmmmmmm",
      " f    jkkn      ",
      " g    jkkn    g ",
      "      jkkn      ",
      "      jkkn      ",
      "      jkkn      "
    ],
    [
      "vvvvvvvvvvvvvvvv",
      "aaaaaaaaaaaaaaaa",
      "aaaaaaaaaaaaaaaa",
      "aaaaabbbbbbbbbbb",
      "aabbb           ",
      "ab              ",
      "b               ",
      "                ",
      "       ooooooooo",
      "       ooooooooo",
      "       oo       ",
      " f     oo       ",
      " g     oo     g ",
      "       oo       ",
      "       oo       ",
      "       oo       "
    ],
    [
      "vvvvvvvvvvvvvvvv",
      "ppaaaaaaaaaaaaaa",
      "ppaaaaaaaaaaaaaa",
      "ppaaabbbbbbbbbbb",
      "ppbbbqqqqqqqqqqq",
      "pbrqqqssssssssss",
      "bsssssss   sssss",
      "sssss      sssss",
      "sssss      sssss",
      "sssss      sssss",
      "sssss      sssss",
      "sfsss      sssss",
      "sgsss      sssgs",
      "sssss      sssss",
      "sssss      sssss",
      "sssss      sssss"
    ]
  ]
}