{
  "name": "multi_nuclearpowerplant_14_base1",
  "refpalette": "deceasedcraft:multi_nuclearpowerplant_14/multi_nuclearpowerplant_14_base1_palette",
  "xsize": 16,
  "zsize": 16,
  "slices": [
    [
      "vvvvvvvvvvvvvvvv",
      "vaaaaaaaaaaaaaaa",
      "vaaaaaaaaaaaaaaa",
      "vaaaaaaaaaaaaaaa",
      "vaaaaaaaaaaabbbc",
      "vaaaaaaabbbbddee",
      "aaaaabbbdddddddd",
      "aaabbddddddddddd",
      "abbzdddddddddddd",
      "bzzddddddddddddd",
      "zddddddddddddddd",
      "dddddddddddddddd",
      "dddddddddddddddd",
      "dddddddddddddddd",
      "dddddddddddddddd",
      "dddddddddddddddd"
    ],
    [
      "vvvvvvvvvvvvvvvv",
      "vfffffffffffffff",
      "vfffffffffffffff",
      "vfffffffffffffff",
      "vfffffffffffcccc",
      "vfffffffccccddde",
      "fffffccc g     d",
      "fffcc hiih      ",
      "fccj            ",
      "cjj             ",
      "j               ",
      "                ",
      "                ",
      "                ",
      "                ",
      "                "
    ],
    [
      "vvvvvvvvvvvvvvvv",
      "vfffffffffffffff",
      "vfffffffffffffff",
      "vfffffffffffffff",
      "vfffffffffffcccc",
      "vfffffffcccccddd",
      "fffffccc g      ",
      "fffcc hkkh      ",
      "fcc   l         ",
      "c               ",
      "                ",
      "                ",
      "                ",
      "                ",
      "                ",
      "                "
    ],
    [
      "vvvvvvvvvvvvvvvv",
      "vfffffffffffffff",
      "vfffffffffffffff",
      "vfffffffffffffff",
      "vfffffffffffcccc",
      "vfffffffccccccdd",
      "fffffccc g      ",
      "fffcc hmmh      ",
      "fcc   n  n      ",
      "c               ",
      "                ",
      "                ",
      "                ",
      "                ",
      "                ",
      "                "
    ],
    [
      "vvvvvvvvvvvvvvvv",
      "vfffffffffffffff",
      "vfffffffffffffff",
      "vfffffffffffffff",
      "vfffffffffffcccc",
      "vfffffffcccccccd",
      "fffffccc g  o   ",
      "fffcc hhhh      ",
      "fcc   pnnp      ",
      "c     nqqn      ",
      "      nqqn      ",
      "      nqqn      ",
      "      nnnn      ",
      "      n  n      ",
      "      n  n      ",
      "      n  n      "
    ],
    [
      "vvvvvvvvvvvvvvvv",
      "vfffffffffffffff",
      "vfffffffffffffff",
      "vfffffffffffffff",
      "vfffffffffffcccc",
      "vfffffffccccrrrr",
      "fffffcccrrrrr   ",
      "fffccrrrrh      ",
      "fccrrrhhhh      ",
      "crrr  hhhh      ",
      "rr    hhhh      ",
      "      hssh      ",
      "      h  h      ",
      "      h  h      ",
      "      h  h      ",
      "      h  h      "
    ]
  ]
}