{
  "name": "multi_nuclearpowerplant_40_base5",
  "refpalette": "deceasedcraft:multi_nuclearpowerplant_40/multi_nuclearpowerplant_40_base5_palette",
  "xsize": 16,
  "zsize": 16,
  "slices": [
    [
      "   =a      bbccc",
      "  =a      bbcccc",
      " =a      bbccccc",
      "=a      bbcccccc",
      "a      bbccccccc",
      "      bbcccccccc",
      "     bbccccccccc",
      "    bbcccccccccc",
      "   bbcccdeeeeeee",
      "  bbccccefgfgfgf",
      " bbaaaccegfgfgfg",
      "bbacccacefgfgfgf",
      "bcacccacegfgfgfg",
      "ccacccacefgfgfgf",
      "cccaaaccegfgfgfg",
      "ccccccccefgfgfgf"
    ],
    [
      "   =a      bbccc",
      "  =a      bbcccc",
      " =a      bbccccc",
      "=a      bbcccccc",
      "a      bbccccccc",
      "      bbcccccccc",
      "     bbccccccccc",
      "    bbcccccccccc",
      "   bbcccdeeeeeee",
      "  bbccccefgfgfgf",
      " bbaaaccegfgfgfg",
      "bbacccacefgfgfgf",
      "bcacccacegfgfgfg",
      "ccacccacefgfgfgf",
      "cccaaaccegfgfgfg",
      "ccccccccefgfgfgf"
    ],
    [
      "   =a      bbccc",
      "  =a      bbcccc",
      " =a      bbccccc",
      "=a      bbcccccc",
      "a      bbccccccc",
      "      bbcccccccc",
      "     bbccccccccc",
      "    bbcccccccccc",
      "   bbcccdeeeeeee",
      "  bbccccefgfgfgf",
      " bbaaaccegfgfgfg",
      "bbacccacefgfgfgf",
      "bcacccacegfgfgfg",
      "ccacccacefgfgfgf",
      "cccaaaccegfgfgfg",
      "ccccccccefgfgfgf"
    ],
    [
      "   =a      bbccc",
      "  =a      bbcccc",
      " =a      bbccccc",
      "=a      bbcccccc",
      "a      bbccccccc",
      "      bbcccccccc",
      "     bbccccccccc",
      "    bbcccccccccc",
      "   bbcccdeeeeeee",
      "  bbccccefgfgfgf",
      " bbhhhccegfgfgfg",
      "bbhccchcefgfgfgf",
      "bchccchcegfgfgfg",
      "cchccchcefgfgfgf",
      "ccchhhccegfgfgfg",
      "ccccccccefgfgfgf"
    ],
    [
      "   =a      bbccc",
      "  =a      bbcccc",
      " =a      bbccccc",
      "=a      bbcccccc",
      "a      bbccccccc",
      "      bbcccccccc",
      "     bbccccccccc",
      "    bbcccccccccc",
      "   bbcccdeeeeeee",
      "  bbccccefgfgfgf",
      " bbcccccegfgfgfg",
      "bbccccccefgfgfgf",
      "bcccccccegfgfgfg",
      "ccccccccefgfgfgf",
      "ccccccccegfgfgfg",
      "ccccccccefgfgfgf"
    ],
    [
      "   =a      bbccc",
      "  =a      bbcccc",
      " =a      bbccccc",
      "=a      bbcccccc",
      "a      bbccccccc",
      "      bbcccccccc",
      "     bbccccccccc",
      "    bbcccccccccc",
      "   bbcccdeeeeeee",
      "  bbccccefgfgfgf",
      " bbcccccegfgfgfg",
      "bbccccccefgfgfgf",
      "bcccccccegfgfgfg",
      "ccccccccefgfgfgf",
      "ccccccccegfgfgfg",
      "ccccccccefgfgfgf"
    ]
  ]
}