{
  "name": "multi_nuclearpowerplant_40_base12",
  "refpalette": "deceasedcraft:multi_nuclearpowerplant_40/multi_nuclearpowerplant_40_base12_palette",
  "xsize": 16,
  "zsize": 16,
  "slices": [
    [
      "aaaaaaaaaaaaaaaa",
      "aaaaaaaaaaaaaaaa",
      "aaaaaaaaaaaaaaaa",
      "aaaaaaaaaaaaaaaa",
      "aaaaaaaaaaaaaaaa",
      "aaaaaaaaaaaaaaaa",
      "aaaaaaaaaaaaaaaa",
      "aaaaaaaaaaaaaaaa",
      "aaaaaaaaaaaaaaaa",
      "aaaaaaaaaaaaaaaa",
      "aaaaaaaaaaaaaaaa",
      "aaaaaaaaaaaaaaaa",
      "aaaaaaaaaaaaaaaa",
      "aaaaaaaaaaaaaaaa",
      "aaaaaaaaaaaaaaaa",
      "aaaaaaaaaaaaaaaa"
    ],
    [
      "bbbbbbbbbbbbbbbb",
      "bbbbbbbbbbbbbbbb",
      "bbbbbbbbbbbbbbbb",
      "bbbbbbbbbbbbbbbb",
      "bbbbbbbbbbbbbbbb",
      "bbbbbbbbbbbbbbbb",
      "bbbbbbbbbbbbbbbb",
      "bbbbbbbbbbbbbbbb",
      "bbbbbbbbbbbbbbbb",
      "bbbbbbbbbbbbbbbb",
      "bbbbbbbbbbbbbbbb",
      "bbbbbbbbbbbbbbbb",
      "bbbbbbbbbbbbbbbb",
      "bbbbbbbbbbbbbbbb",
      "bbbbbbbbbbbbbbbb",
      "bbbbbbbbbbbbbbbb"
    ],
    [
      "================",
      "================",
      "================",
      "================",
      "================",
      "================",
      "================",
      "================",
      "================",
      "================",
      "================",
      "================",
      "================",
      "================",
      "================",
      "================"
    ],
    [
      "cccccccccccccccc",
      "cccccccccccccccc",
      "cccccccccccccccc",
      "cccccccccccccccc",
      "cccccccccccccccc",
      "cccccccccccccccc",
      "cccccccccccccccc",
      "cccccccccccccccc",
      "cccccccccccccccc",
      "cccccccccccccccc",
      "cccccccccccccccc",
      "ddddddeccccccccc",
      "ddddddeccccccccc",
      "ddddddeccccccccc",
      "cccccccccccccccc",
      "cccccccccccccccc"
    ],
    [
      "fggfggfggfggfggf",
      "ffffffffffffffff",
      "fggfggfggfggfggf",
      "fggfggfggfggfggf",
      "ffffffffffffffff",
      "fggfggfggfggfggf",
      "fggfggfggfggfggf",
      "hfffffffffffffff",
      "ffffffffffffffff",
      "ffffffffffffffff",
      "ddddddifffffffff",
      "jkldddffffffffff",
      "mnldddffffffffff",
      "okldddffffffffff",
      "ddddddpfffffffff",
      "ffffffffffffffff"
    ],
    [
      "fqrfrsfqrfrsfqrf",
      "ffffffffffffffff",
      "fqtftsfqtftsfqtf",
      "frsfqrfrsfqrfrsf",
      "ffffffffffffffff",
      "ftsfqtftsfqtftsf",
      "fqrfrsfqrfrsfqrf",
      "hfffffffffffffff",
      "ffffffffffffffff",
      "ffffffffffffffff",
      "ddddddifffffffff",
      "uuwfffffffffffff",
      "uuwfffffffffffff",
      "uuwfffffffffffff",
      "ddddddpfffffffff",
      "ffffffffffffffff"
    ]
  ]
}