{
  "name": "multi_nuclearpowerplant_40_base8",
  "refpalette": "deceasedcraft:multi_nuclearpowerplant_40/multi_nuclearpowerplant_40_base8_palette",
  "xsize": 16,
  "zsize": 16,
  "slices": [
    [
      "                ",
      "           a a  ",
      "    a       b   ",
      "           a a  ",
      "                ",
      "                ",
      "                ",
      "                ",
      "                ",
      "                ",
      "  cdddc         ",
      "  deeed    a a  ",
      "  deeed     b   ",
      "  deeed    a a  ",
      "  fdddf         ",
      "                "
    ],
    [
      "gggggggggggggggg",
      "gggggggggggggggg",
      "gggggggggggghggg",
      "gggggggggggggggg",
      "gggggggggggggggg",
      "gggggggggggggggg",
      "gggggggggggggggg",
      "gggggggggggggggg",
      "gggggggggggggggg",
      "gggggggggggggggg",
      "gggdddgggggggggg",
      "ggdeeedggggggggg",
      "ggdeeedggggghggg",
      "ggdeeedggggggggg",
      "gggdddgggggggggg",
      "gggggggggggggggg"
    ],
    [
      "iiiiiiiiiiijkjii",
      "iiiiiiiiiiijljii",
      "iiiiiiiiiiijmjii",
      "iiiiiiiiiiijljii",
      "iiiiiiiiiiijkjii",
      "iiiiiiiiiiijkjii",
      "iiiiiiiiiiijkjii",
      "iiiiiiiiiiijkjii",
      "iiiiiiiiiiijkjii",
      "iiiiiiiiiiijkjii",
      "nnnnnnoiiiijkjii",
      "pppeeeqiiiijljii",
      "pppeeeqiiiijmjii",
      "pppeeeqiiiijljii",
      "nnnnnnoiiiijkjii",
      "iiiiiiiiiiijkjii"
    ],
    [
      "iiiiiiiiiiiijiii",
      "iiiiiiiiiiiijiii",
      "iiiiiiiiiiiijiii",
      "iiiiiiiiiiiijiii",
      "iiiiiiiiiiiijiii",
      "iiiiiiiiiiiijiii",
      "iiiiiiiiiiiijiii",
      "iiiiiiiiiiiijiii",
      "iiiiiiiiiiiijiii",
      "iiiiiiiiiiiijiii",
      "gggdddiiiiiijiii",
      "ggreeediiiiijiii",
      "ggreeediiiiijiii",
      "ggreeediiiiijiii",
      "gggdddiiiiiijiii",
      "iiiiiiiiiiiijiii"
    ],
    [
      "ssst============",
      "sst=============",
      "st==============",
      "t===============",
      "================",
      "================",
      "================",
      "================",
      "================",
      "================",
      "===ddd==========",
      "==deeed=========",
      "==deeed=========",
      "==deeed=========",
      "===ddd==========",
      "================"
    ],
    [
      "   =dddddddddddd",
      "  =ddddddddddddd",
      " =dddddddddddddd",
      "=ddddddddddddddd",
      "dddddddddddddddd",
      "dddddddddddddddd",
      "dddddddddddddddd",
      "dddddddddddddddd",
      "dddddddddddddddd",
      "dddddddddddddddd",
      "dddddddddddddddd",
      "dddeeedddddddddd",
      "dddeeedddddddddd",
      "dddeeedddddddddd",
      "dddddddddddddddd",
      "dddddddddddddddd"
    ]
  ]
}