{
  "name": "multi_nuclearpowerplant_40_ground",
  "refpalette": "deceasedcraft:multi_nuclearpowerplant_40/multi_nuclearpowerplant_40_ground_palette",
  "xsize": 16,
  "zsize": 16,
  "slices": [
    [
      "aabccccccccccccc",
      "aabccccccccccccc",
      "abcccccccccccccc",
      "abcccccccccccccc",
      "bccccccccccccccc",
      "bccccccccccccccc",
      "cccccccccccccccc",
      "cccccccccccccccc",
      "cccccccccccccccd",
      "ccccccccccccccdd",
      "cccccccccccccdda",
      "ccccccccccccddaa",
      "cccccccccccddaaa",
      "ccccccccccddaaaa",
      "cccccccccddaaaaa",
      "ccccccccddaaaaaa"
    ],
    [
      "cccczzzzzzzazzzz",
      "cccczzzzzzzzzzzz",
      "ccczzzzzzzzzzzzz",
      "ccczzzzzzzzzzzzz",
      "ccczzzzzzzzzzzzz",
      "cczzzzzzzzzzzzzz",
      "cczzzzzzzzzzzzza",
      "czzzzzzazzzzzzaz",
      "czzzzzzzzzzzzzzz",
      "zzzzzzzzzzzzzzzz",
      "zzzzzzzzzzzzzzze",
      "zzzzzzzzzzzzzze ",
      "zzzzzzzzzzzaze  ",
      "zzzzzzzzzzzzf   ",
      "zzzzzzzzzzzf    ",
      "zzzzazzaaze     "
    ],
    [
      "zzzz z gg       ",
      "zzzz            ",
      "zzz    g  g     ",
      "zzz  g      g  g",
      "zzz  g  hgg     ",
      "zz z       g    ",
      "zz    g g g     ",
      "zz g            ",
      "z     gi  g    j",
      "   g          jj",
      "    g       gjj ",
      "      g  g  jj  ",
      "  h        jj   ",
      " g        jj    ",
      "g  g     jj     ",
      "  gg g  jj      "
    ],
    [
      "                ",
      "                ",
      "  g             ",
      "                ",
      "                ",
      "                ",
      "                ",
      "                ",
      "               j",
      "              jj",
      "             jj ",
      "            jj  ",
      "           jj   ",
      "          jj    ",
      "         jj     ",
      "        jj      "
    ],
    [
      "                ",
      "                ",
      "                ",
      "                ",
      "                ",
      "                ",
      "                ",
      "                ",
      "                ",
      "               k",
      "              k ",
      "             k  ",
      "            k   ",
      "           l    ",
      "          l     ",
      "         l      "
    ],
    [
      "                ",
      "                ",
      "                ",
      "                ",
      "                ",
      "                ",
      "                ",
      "                ",
      "                ",
      "                ",
      "                ",
      "                ",
      "                ",
      "                ",
      "                ",
      "                "
    ]
  ]
}