{
  "name": "multi_nuclearpowerplant_40_base10",
  "refpalette": "deceasedcraft:multi_nuclearpowerplant_40/multi_nuclearpowerplant_40_base10_palette",
  "xsize": 16,
  "zsize": 16,
  "slices": [
    [
      "                ",
      "                ",
      "                ",
      "                ",
      "                ",
      "                ",
      "                ",
      "a               ",
      "                ",
      "                ",
      "  bcccb         ",
      "  cdddc         ",
      "  cdddc         ",
      "  cdddc         ",
      "  eccce         ",
      "                "
    ],
    [
      "f               ",
      "f               ",
      "f               ",
      "f               ",
      "f               ",
      "f               ",
      "f               ",
      "gfffffffffffffff",
      "f               ",
      "f               ",
      "f bcccb         ",
      "f cdddc         ",
      "f cdddc         ",
      "f cdddc         ",
      "f eccce         ",
      "f               "
    ],
    [
      "h               ",
      "h               ",
      "h               ",
      "h               ",
      "h               ",
      "h               ",
      "h               ",
      " iiiiiiiiiiiiiii",
      "h               ",
      "h               ",
      "h bcccb         ",
      "h cdddc         ",
      "jkcdddc         ",
      "h cdddc         ",
      "h eccce         ",
      "h               "
    ],
    [
      "                ",
      "                ",
      "                ",
      "                ",
      "                ",
      "                ",
      "                ",
      "                ",
      "                ",
      "                ",
      "  bcccb         ",
      "  cdddc         ",
      "  ldddc         ",
      "  cdddc         ",
      "  eccce         ",
      "                "
    ],
    [
      "                ",
      "                ",
      "                ",
      "                ",
      "                ",
      "                ",
      "                ",
      "                ",
      "                ",
      "                ",
      "  bcccb         ",
      "  cdddc         ",
      " mndddc         ",
      "  cdddc         ",
      "  eccce         ",
      "                "
    ],
    [
      "                ",
      "                ",
      "                ",
      "                ",
      "                ",
      "                ",
      "                ",
      "                ",
      "                ",
      "                ",
      "  bcccb         ",
      "  cdddc         ",
      " opdddc         ",
      "  cdddc         ",
      "  eccce         ",
      "                "
    ]
  ]
}