{
  "name": "multi_nuclearpowerplant_40_base1",
  "refpalette": "deceasedcraft:multi_nuclearpowerplant_40/multi_nuclearpowerplant_40_base1_palette",
  "xsize": 16,
  "zsize": 16,
  "slices": [
    [
      "aabcccc=========",
      "aabccc==========",
      "abccc===========",
      "abcc============",
      "bcc=============",
      "bc==============",
      "c===============",
      "================",
      "================",
      "================",
      "================",
      "================",
      "================",
      "================",
      "================",
      "================"
    ],
    [
      "aabccccccccccccc",
      "aabccccccccccccc",
      "abcccccccccccccc",
      "abcccccccccccccc",
      "bccccccccccccccc",
      "bccccccccccccccc",
      "cccccccccccccccc",
      "cccccccccccccccc",
      "cccccccccccccccc",
      "cccccccccccccccc",
      "cccccccccccccccc",
      "cccccccccccccccc",
      "cccccccccccccccc",
      "cccccccccccccccc",
      "cccccccccccccccc",
      "cccccccccccccccc"
    ],
    [
      "aabccccccccccccc",
      "aabccccccccccccc",
      "abcccccccccccccc",
      "abcccccccccccccc",
      "bccccccccccccccc",
      "bccccccccccccccc",
      "cccccccccccccccc",
      "cccccccccccccccc",
      "cccccccccccccccc",
      "cccccccccccccccc",
      "cccccccccccccccc",
      "cccccccccccccccc",
      "cccccccccccccccc",
      "cccccccccccccccc",
      "cccccccccccccccc",
      "cccccccccccccccc"
    ],
    [
      "aabccccccccccccc",
      "aabccccccccccccc",
      "abcccccccccccccc",
      "abcccccccccccccc",
      "bccccccccccccccc",
      "bccccccccccccccc",
      "cccccccccccccccc",
      "cccccccccccccccc",
      "cccccccccccccccc",
      "cccccccccccccccc",
      "cccccccccccccccc",
      "cccccccccccccccc",
      "cccccccccccccccc",
      "cccccccccccccccc",
      "cccccccccccccccc",
      "cccccccccccccccc"
    ],
    [
      "aabccccccccccccc",
      "aabccccccccccccc",
      "abcccccccccccccc",
      "abcccccccccccccc",
      "bccccccccccccccc",
      "bccccccccccccccc",
      "cccccccccccccccc",
      "cccccccccccccccc",
      "cccccccccccccccc",
      "cccccccccccccccc",
      "cccccccccccccccc",
      "cccccccccccccccc",
      "cccccccccccccccc",
      "cccccccccccccccc",
      "cccccccccccccccc",
      "cccccccccccccccc"
    ],
    [
      "aabccccccccccccc",
      "aabccccccccccccc",
      "abcccccccccccccc",
      "abcccccccccccccc",
      "bccccccccccccccc",
      "bccccccccccccccc",
      "cccccccccccccccc",
      "cccccccccccccccc",
      "cccccccccccccccd",
      "ccccccccccccccdd",
      "cccccccccccccddc",
      "ccccccccccccddcc",
      "cccccccccccddccc",
      "ccccccccccddcccc",
      "cccccccccddccccc",
      "ccccccccddcccccc"
    ]
  ]
}