{
  "name": "multi_nuclearpowerplant_40_base7",
  "refpalette": "deceasedcraft:multi_nuclearpowerplant_40/multi_nuclearpowerplant_40_base7_palette",
  "xsize": 16,
  "zsize": 16,
  "slices": [
    [
      "   =a      bbccc",
      "  =a      bbcccc",
      " =ad     bbccccc",
      "=a      bbcccccc",
      "a      bbccccccc",
      "      bbcccccccc",
      "     bbccccccccc",
      "    bbcccccccccc",
      "   bbccc ccccccc",
      "  bbcccccccccccc",
      " bbaaacccccccccc",
      "bbaeeeaccccccccc",
      "bcaeeeaccccccccc",
      "ccaeeeaccccccccc",
      "cccaaacccccccccc",
      "cccccccccccccccc"
    ],
    [
      "   =a      bbccc",
      "  =a      bbcccc",
      " =a      bbccccc",
      "=a      bbcccccc",
      "a      bbccccccc",
      "      bbcccccccc",
      "     bbccccccccc",
      "    bbcccccccccc",
      "   bbccc@cfffffc",
      "  bbcccccgfffffg",
      " bbaaaccffffffff",
      "bbaeeeacffffffff",
      "bcaeeeacffffffff",
      "ccaeeeacffffffff",
      "cccaaaccffffffff",
      "cccccccccgfffffg"
    ],
    [
      "   =a      bbeee",
      "  =a      bbeeee",
      " =a      bbeeeee",
      "=a      bbeeeeee",
      "a      bbeeeeeee",
      "      bbeeeeeeee",
      "     bbeeeeeeeee",
      "    bbeeeeeeeeee",
      "   bbeeeheeeeeee",
      "  bbeeeeegeeeeeg",
      " bbaaaeeeeeeeeee",
      "bbaeeeaeeeeeeeee",
      "beaeeeaeeeeeeeee",
      "eeaeeeaeeeeeeeee",
      "eeeaaaeeeeeeeeee",
      "eeeeeeeeegeeeeeg"
    ],
    [
      "   =a      bbeee",
      "  =a      bbeeee",
      " =a      bbeeeee",
      "=a      bbeeeeee",
      "a      bbeeeeeee",
      "      bbeeeeeeee",
      "     bbeeeeeeeee",
      "    bbeeeeeeeeee",
      "   bbeeeheeeeeee",
      "  bbeeeeegeeeeeg",
      " bbaaaeeeeeeeeee",
      "bbaeeeaeeeeeeeee",
      "beaeeeaeeeeeeeee",
      "eeaeeeaeeeeeeeee",
      "eeeaaaeeeeeeeeee",
      "eeeeeeeeegeeeeeg"
    ],
    [
      "   =a      bbeee",
      "  =a      bbeeee",
      " =a      bbeeeee",
      "=a      bbeeeeee",
      "a      bbeeeeeee",
      "      bbeeeeeeee",
      "     bbeeeeeeeee",
      "    bbeeeeeeeeee",
      "   bbeeeheeeeeee",
      "  bbeeeeegeeeeeg",
      " bbaaaeeeeeeeeee",
      "bbaeeeaeeeeeeeee",
      "beaeeeaeeeeeeeee",
      "eeaeeeaeeeeeeeee",
      "eeeaaaeeeeeeeeee",
      "eeeeeeeeegeeeeeg"
    ],
    [
      "iii=a      bbeee",
      "ii=a      bbeeee",
      "i=a      bbeeeee",
      "=a      bbeeeeee",
      "a      bbeeeeeee",
      "      bbeeeeeeee",
      "     bbeeeeeeeee",
      "    bbeeeeeeeeee",
      "   bbeeeheeeeeee",
      "  bbeeeeegeeeeeg",
      " bbaaaeeeeeeeeee",
      "bbaeeeaeeeeeeeee",
      "beaeeeaeeeeeeeee",
      "eeaeeeaeeeeeeeee",
      "eeeaaaeeeeeeeeee",
      "eeeeeeeeegeeeeeg"
    ]
  ]
}