{
  "name": "multi_nuclearpowerplant_40_base2",
  "refpalette": "deceasedcraft:multi_nuclearpowerplant_40/multi_nuclearpowerplant_40_base2_palette",
  "xsize": 16,
  "zsize": 16,
  "slices": [
    [
      "a  =b           ",
      "  =b            ",
      " =b             ",
      "=b              ",
      "b               ",
      "                ",
      "                ",
      "                ",
      "                ",
      "                ",
      "                ",
      "                ",
      "            c   ",
      "                ",
      "                ",
      "                "
    ],
    [
      "a  =b       d   ",
      "  =b        d   ",
      " =b         e   ",
      "=b          f   ",
      "b           f   ",
      "           gfg  ",
      "            f   ",
      "         g  f  g",
      "        hijkfijj",
      "       gf  gfg  ",
      "        f ikflh ",
      "     g  mgl m mg",
      "ddnjjjjjjjjkoijj",
      "     g  hgh h lg",
      "        f mlfik ",
      "       gm  gfg  "
    ],
    [
      "a  =b       p   ",
      "  =b        q   ",
      " =b         d   ",
      "=b          d   ",
      "b          rds  ",
      "          tdddu ",
      "         rd d du",
      "        rd  d  d",
      "       rd  rds  ",
      "      rd  tdddu ",
      "     td  td d du",
      "    td  rd  d  d",
      "pwddddddddddxddd",
      "    yd  Ad  d  d",
      "     Ad  yd d dB",
      "      Ad  ydddB "
    ],
    [
      "a C=bb          ",
      "  =bb           ",
      " =bb        d   ",
      "=bb         D   ",
      "bb              ",
      "b               ",
      "                ",
      "                ",
      "                ",
      "                ",
      "                ",
      "            E   ",
      "  dF       IdF  ",
      "            D   ",
      "                ",
      "                "
    ],
    [
      "JK  ==bL        ",
      "KK ==bL         ",
      "KM==bL      d   ",
      "K==bL           ",
      "==bL            ",
      "=bL             ",
      "bL              ",
      "L               ",
      "                ",
      "                ",
      "                ",
      "                ",
      "  d         d   ",
      "                ",
      "                ",
      "                "
    ],
    [
      "NKMOOO=bbbbbbbbb",
      "KKMOO=bbbbbbbbbb",
      "KMOO=bbbbbbbbbbb",
      "KMO=bbbbbbbbbbbb",
      "MO=bbbbbbbbbbbbb",
      "M=bbbbbbbbbbbbbb",
      "=bbbbbbbbbbbbbbb",
      "bbbbbbbbbbbbbbbb",
      "bbbbbbbbbbbbbbbb",
      "bbbbbbbbbbbbbbbb",
      "bbbbbbbbbbbbbbbb",
      "bbbbbbbbbbbbbbbb",
      "bbbbbbbbbbbbbbbb",
      "bbbbbbbbbbbbbbbb",
      "bbbbbbbbbbbbbbbb",
      "bbbbbbbbbbbbbbbb"
    ]
  ]
}