{
  "name": "multi_nuclearpowerplant_40_base9",
  "refpalette": "deceasedcraft:multi_nuclearpowerplant_40/multi_nuclearpowerplant_40_base9_palette",
  "xsize": 16,
  "zsize": 16,
  "slices": [
    [
      "                ",
      "                ",
      "                ",
      "                ",
      "                ",
      "                ",
      "                ",
      "                ",
      "                ",
      "                ",
      "  abbba         ",
      "  bcccb         ",
      "  bcccb         ",
      "  bcccb         ",
      "  dbbbd         ",
      "                "
    ],
    [
      "                ",
      "                ",
      "                ",
      "                ",
      "                ",
      "                ",
      "                ",
      "                ",
      "                ",
      "                ",
      "  abbba         ",
      "  bcccb         ",
      "  bcccb         ",
      "  bcccb         ",
      "  dbbbd         ",
      "                "
    ],
    [
      "                ",
      "                ",
      "                ",
      "                ",
      "                ",
      "                ",
      "                ",
      "                ",
      "                ",
      "                ",
      "  abbba         ",
      "  bcccb         ",
      "  bcccb         ",
      "  bcccb         ",
      "  dbbbd         ",
      "                "
    ],
    [
      "    e       e   ",
      "    f      geg  ",
      "hhhhhhhhhhhiejhh",
      "    k      geg  ",
      "    e       e   ",
      "    e       e   ",
      "    e       e   ",
      "    e       e   ",
      "    e       e   ",
      "    l       e   ",
      "  abbba     e   ",
      "  bcccb    geg  ",
      "  bcccbmhhhiejhh",
      "  bcccb    geg  ",
      "  dbbbd     e   ",
      "            e   "
    ],
    [
      "    n      onp  ",
      "    n     qnnnr ",
      "nnnnnnnnnnnnsnnn",
      "    n     tnnnu ",
      "    n      wnx  ",
      "    n       n   ",
      "    n       n   ",
      "    n       n   ",
      "    n       n   ",
      "    n       n   ",
      "  abbba    qnp  ",
      "  bcccb   qnnnr ",
      "nnbcccbnnnnnsnnn",
      "  bcccb   wnnnx ",
      "  dbbbd    tnx  ",
      "    n       n   "
    ],
    [
      "                ",
      "    y      nAn  ",
      "   BnC     ADA  ",
      "    E      nAn  ",
      "                ",
      "                ",
      "                ",
      "                ",
      "                ",
      "                ",
      "  abbba         ",
      "  bcccb    nAn  ",
      "  bcccb    ADA  ",
      "  bcccb    nAn  ",
      "  dbbbd         ",
      "                "
    ]
  ]
}