{
  "name": "multi_nuclearpowerplant_40_base4",
  "refpalette": "deceasedcraft:multi_nuclearpowerplant_40/multi_nuclearpowerplant_40_base4_palette",
  "xsize": 16,
  "zsize": 16,
  "slices": [
    [
      "   =a      bbccc",
      "  =a      bbcccc",
      " =a      bbccccc",
      "=a      bbcccccc",
      "a      bbccccccc",
      "      bbcccccccc",
      "     bbccccccccc",
      "    bbcccccccccc",
      "   bbcccdeeeeeee",
      "  bbccccefgfgfgf",
      " bbcccccegfgfgfg",
      "bbccccccefgfgfgf",
      "bcccccccegfgfgfg",
      "ccccccccefgfgfgf",
      "ccccccccegfgfgfg",
      "ccccccccefgfgfgf"
    ],
    [
      "   =a      bbccc",
      "  =a      bbcccc",
      " =a      bbccccc",
      "=a      bbcccccc",
      "a      bbccccccc",
      "      bbcccccccc",
      "     bbccccccccc",
      "    bbcccccccccc",
      "   bbcccdddddddd",
      "  bbccccdhdhdhdh",
      " bbcccccddhdhdhd",
      "bbccccccdhdhdhdh",
      "bcccccccddhdhdhd",
      "ccccccccdhdhdhdh",
      "ccccccccddhdhdhd",
      "ccccccccdhdhdhdh"
    ],
    [
      "   =a      bbccc",
      "  =a      bbcccc",
      " =a      bbccccc",
      "=a      bbcccccc",
      "a      bbccccccc",
      "      bbcccccccc",
      "     bbccccccccc",
      "    bbcccccccccc",
      "   bbccccccccccc",
      "  bbcccccccccccc",
      " bbccccccccccccc",
      "bbcccccccccccccc",
      "bccccccccccccccc",
      "cccccccccccccccc",
      "cccccccccccccccc",
      "cccccccccccccccc"
    ],
    [
      "   =a      bbccc",
      "  =a      bbcccc",
      " =a      bbccccc",
      "=a      bbcccccc",
      "a      bbccccccc",
      "      bbcccccccc",
      "     bbccccccccc",
      "    bbcccccccccc",
      "   bbccccccccccc",
      "  bbcccccccccccc",
      " bbccccccccccccc",
      "bbcccccccccccccc",
      "bccccccccccccccc",
      "cccccccccccccccc",
      "cccccccccccccccc",
      "cccccccccccccccc"
    ],
    [
      "   =a      bb   ",
      "  =a      bb    ",
      " =a      bb     ",
      "=a      bb      ",
      "a      bb       ",
      "      bb        ",
      "     bb         ",
      "    bb          ",
      "   bb           ",
      "  bb            ",
      " bb             ",
      "bb              ",
      "b   i           ",
      "                ",
      "                ",
      "                "
    ],
    [
      "   =a      jj   ",
      "  =a      jj    ",
      " =a      jj     ",
      "=a      jj      ",
      "a      jj       ",
      "      jj        ",
      "     jj         ",
      "    jj          ",
      "   jj           ",
      "  jj            ",
      " jj             ",
      "jj              ",
      "j  klm          ",
      "                ",
      "                ",
      "                "
    ]
  ]
}