{
  "name": "multi_nuclearpowerplant_40_base6",
  "refpalette": "deceasedcraft:multi_nuclearpowerplant_40/multi_nuclearpowerplant_40_base6_palette",
  "xsize": 16,
  "zsize": 16,
  "slices": [
    [
      "aaa=b      ccddd",
      "aa=b      ccdddd",
      "a=b      ccddddd",
      "=b      ccdddddd",
      "b      ccddddddd",
      "      ccdddddddd",
      "     ccddddddddd",
      "    ccdddddddddd",
      "   ccdddeddddddd",
      "  ccdddddfdddddf",
      " ccbbbdddddddddd",
      "ccbdddbddddddddd",
      "cdbdddbddddddddd",
      "ddbdddbddddddddd",
      "dddbbbdddddddddd",
      "dddddddddfdddddf"
    ],
    [
      "   =b      ccddd",
      "  =b      ccdddd",
      " =b      ccddddd",
      "=b      ccdddddd",
      "b      ccddddddd",
      "      ccdddddddd",
      "     ccddddddddd",
      "    ccdddddddddd",
      "   ccdddeddddddd",
      "  ccdddddfdddddf",
      " ccbbbdddddddddd",
      "ccbdddbddddddddd",
      "cdbdddbddddddddd",
      "ddbdddbddddddddd",
      "dddbbbdddddddddd",
      "dddddddddfdddddf"
    ],
    [
      "   =b      ccddg",
      "  =b      ccdddg",
      " =b      ccddddg",
      "=b      ccdddddg",
      "b      ccgdddddg",
      "      ccdgdddddg",
      "     ccddgdddddg",
      "    ccdddgdddddg",
      "   ccdddegdddddg",
      "  cchhhhhfdddddf",
      " ccbbbdddddddddd",
      "ccbdddbddddddddd",
      "cdbdddbddddddddd",
      "ddbdddbddddddddd",
      "dddbbbdddddddddd",
      "hhhhhhhhhfdddddf"
    ],
    [
      "   =b      ccddd",
      "  =b      ccdddd",
      " =b      ccddddd",
      "=b      ccdddddd",
      "b      ccddddddd",
      "      ccdddddddd",
      "     ccddddddddd",
      "    ccdddddddddd",
      "   ccdddehhhhhhh",
      "  ccddddgiiiiiii",
      " ccbbbddgiiiiiii",
      "ccbdddbdgiiiiiii",
      "cdbdddbdgiiiiiii",
      "ddbdddbdgiiiiiii",
      "dddbbbddgiiiiiii",
      "ddddddddgiiiiiii"
    ],
    [
      "   =b      ccddd",
      "  =b      ccdddd",
      " =b      ccddddd",
      "=b      ccdddddd",
      "b      ccddddddd",
      "      ccdddddddd",
      "     ccddddddddd",
      "    ccdddddddddd",
      "   ccdddeeeeeeee",
      "  ccddddejkjkjkj",
      " ccbbbddekjkjkjk",
      "ccbdddbdejkjkjkj",
      "cdbdddbdekjkjkjk",
      "ddbdddbdejkjkjkj",
      "dddbbbddekjkjkjk",
      "ddddddddejkjkjkj"
    ],
    [
      "   =b      ccddd",
      "  =b      ccdddd",
      " =b      ccddddd",
      "=b      ccdddddd",
      "b      ccddddddd",
      "      ccdddddddd",
      "     ccddddddddd",
      "    ccdddddddddd",
      "   ccdddllllllll",
      "  ccddddllllllll",
      " ccbbbddllllllll",
      "ccbdddbdllllllll",
      "cdbdddbdllllllll",
      "ddbdddbdllllllll",
      "dddbbbddllllllll",
      "ddddddddllllllll"
    ]
  ]
}