{
  "name": "multi_nuclearpowerplant_40_base11",
  "refpalette": "deceasedcraft:multi_nuclearpowerplant_40/multi_nuclearpowerplant_40_base11_palette",
  "xsize": 16,
  "zsize": 16,
  "slices": [
    [
      "abcadbabcadbabca",
      "aaaaaaaaaaaaaaaa",
      "aecadeaecadeaeca",
      "adbabcad!abcadba",
      "aaaaaaaaaaaaaaaa",
      "adeaecadeaecadea",
      "abcadbabcadbabca",
      "faaaaaaaaaaaaaaa",
      "aaaaaaaaaaaaaaaa",
      "aaaaaaaaaaaaaaaa",
      "gggggghaaaaaaaaa",
      "iijaaaaaaaaaaaaa",
      "iijaaaaaaaaaaaaa",
      "iijaaaaaaaaaaaaa",
      "ggggggkaaaaaaaaa",
      "aaaaaaaaaaaaaaaa"
    ],
    [
      "aaaaaaaaaaaaaaaa",
      "aaaaaaaaaaaaaaaa",
      "aaaaaaaaaaaaadea",
      "aaaaaaaalaaaabca",
      "aaaaaaaaaaaaaaaa",
      "aaaaaaaaaaaaaaaa",
      "aaaaaaaaaaaaaaaa",
      "faaaaaaaaaaaaaaa",
      "aaaaaaaaaaaaaaaa",
      "aaaaaaaaaaaaaaaa",
      "gggggghaaaaaaaaa",
      "iijaaaaaaaaaaaaa",
      "iijaaaaaaaaaaaaa",
      "iijaaaaaaaaaaaaa",
      "ggggggkaaaaaaaaa",
      "aaaaaaaaaaaaaaaa"
    ],
    [
      "aaaaaaaaaaaaaaaa",
      "aaaaaaaaaaaaaaaa",
      "aaaaaaaaaaaaaaaa",
      "aaaaaaaaaaaaaaaa",
      "aaaaaaaaaaaaaaaa",
      "aaaaaaaaaaaaaaaa",
      "aaaaaaaaaaaaaaaa",
      "faaaaaaaaaaaaaaa",
      "aaaaaaaaaaaaaaaa",
      "aaaaaaaaaaaaaaaa",
      "gggggghaaaaaaaaa",
      "gggaaagaaaaaaaaa",
      "gggaaagaaaaaaaaa",
      "gggaaagaaaaaaaaa",
      "ggggggkaaaaaaaaa",
      "aaaaaaaaaaaaaaaa"
    ],
    [
      "aaaaaaaaaaaaaaaa",
      "aaaaaaaaaaaaaaaa",
      "aaaaaaaaaaaaaaaa",
      "aaaaaaaaaaaaaaaa",
      "aaaaaaaaaaaaaaaa",
      "aaaaaaaaaaaaaaaa",
      "aaaaaaaaaaaaaaaa",
      "faaaaaaaaaaaaaaa",
      "aaaaaaaaaaaaaaaa",
      "aaaaaaaaaaaaaaaa",
      "gggggghaaaaaaaaa",
      "iimnnngaaaaaaaaa",
      "iimnnngaaaaaaaaa",
      "iimnnngaaaaaaaaa",
      "ggggggkaaaaaaaaa",
      "aaaaaaaaaaaaaaaa"
    ],
    [
      "aaaaaaaaaaaaaaaa",
      "aaaaaaaaaaaaaaaa",
      "aaaaaaaaaaaaaaaa",
      "aaaaaaaaaaaaaaaa",
      "aaaaaaaaaaaaaaaa",
      "aaaaaaaaaaaaaaaa",
      "aaaaaaaaaaaaaaaa",
      "faaaaaaaaaaaaaaa",
      "aaaaaaaaaaaaaaaa",
      "aaaaaaaaaaaaaaaa",
      "hhhggghaaaaaaaaa",
      "ggoaecgaaaaaaaaa",
      "ggoadbgaaaaaaaaa",
      "ggoaaagaaaaaaaaa",
      "kkkgggkaaaaaaaaa",
      "aaaaaaaaaaaaaaaa"
    ],
    [
      "aaaaaaaaaaaaaaaa",
      "aaaaaaaaaaaaaaaa",
      "aaaaaaaaaaaaaaaa",
      "aaaaaaaaaaaaaaaa",
      "aaaaaaaaaaaaaaaa",
      "aaaaaaaaaaaaaaaa",
      "aaaaaaaaaaaaaaaa",
      "faaaaaaaaaaaaaaa",
      "aaaaaaaaaaaaaaaa",
      "aaaaaaaaaaaaaaaa",
      "aahggghaaaaaaaaa",
      "aagaaagaaaaaaaaa",
      "aagaaagaaaaaaaaa",
      "aagaaagaaaaaaaaa",
      "aakgggkaaaaaaaaa",
      "aaaaaaaaaaaaaaaa"
    ]
  ]
}