{
  "name": "multi_nuclearpowerplant_46_ground",
  "refpalette": "deceasedcraft:multi_nuclearpowerplant_46/multi_nuclearpowerplant_46_ground_palette",
  "xsize": 16,
  "zsize": 16,
  "slices": [
    [
      "aaaaaaaaaabccccc",
      "aaaaaaaaaabccccc",
      "aaaaaaaaaabccccc",
      "aaaaaaaaabbccccz",
      "aaaaaaaaabcccccc",
      "aaaaaaaaabccczcz",
      "aaaaaaaaabcccczc",
      "aaaaaaaabbcccccz",
      "aaaaaaaabccccccc",
      "aaaaaaaabcccczcz",
      "aaaaaaabbcczcccz",
      "aaaaaaabccccczzz",
      "aaaaaabbcccczzzc",
      "aaaaaabccccccczz",
      "aaaaabbcccczczcz",
      "aaaaabccczcccczz"
    ],
    [
      "zzzzzzzzzzzd    ",
      "zzzzzczzzcze    ",
      "zzzzzzzzzzzf    ",
      "zzzzzzzzzzcf    ",
      "zzzzzzzzczd     ",
      "zzzzzzczczd     ",
      "zzzzzzzzzcf     ",
      "czzzzzzzzzf     ",
      "zzzzzzzzze      ",
      "zzzzzzzzcd      ",
      "zzzzzzzczf     g",
      "zzzzzzzze     gg",
      "zzczzzzzf   gg  ",
      "zzzzczze       g",
      "zzzzzzzf        ",
      "zzzzzze         "
    ],
    [
      "   hhhh   i     ",
      "   jkkj g i     ",
      "g  hkkh   i     ",
      "l  hkkh  ii     ",
      "   hkkh  i      ",
      " m jkkj  i      ",
      "   hhhh  i      ",
      "  g     ii      ",
      "  g  g  i       ",
      "        i       ",
      "       ii       ",
      "   g   i        ",
      "   g  ii        ",
      "      i         ",
      " g   ii         ",
      "     i          "
    ],
    [
      "   nopq   i     ",
      "   rs t   i     ",
      "   quuq   i     ",
      "  wxyyAB ii     ",
      "   qCCn  i      ",
      "   D  E  i      ",
      "   FIIJ  i      ",
      "   KLLK ii      ",
      "        i       ",
      "        i       ",
      "       ii       ",
      "       i        ",
      "      ii        ",
      "      i         ",
      "     ii         ",
      "     i          "
    ],
    [
      "  MqNOnP  Q     ",
      "   R  R   Q     ",
      "   R  R   Q     ",
      "   S  T   Q     ",
      "  UVVVVW Q      ",
      "   XYYZ  Q      ",
      "    00   Q      ",
      "         Q      ",
      "        Q       ",
      "        Q       ",
      "        Q       ",
      "       Q        ",
      "       Q        ",
      "      Q         ",
      "      Q         ",
      "     Q          "
    ],
    [
      "    00          ",
      "    01          ",
      "   0nq0         ",
      "  2YuuY3        ",
      "   0010         ",
      "                ",
      "                ",
      "                ",
      "                ",
      "                ",
      "                ",
      "                ",
      "                ",
      "                ",
      "                ",
      "                "
    ]
  ]
}