{
  "name": "multi_nuclearpowerplant_46_base8",
  "refpalette": "deceasedcraft:multi_nuclearpowerplant_46/multi_nuclearpowerplant_46_base8_palette",
  "xsize": 16,
  "zsize": 16,
  "slices": [
    [
      "            abbv",
      "            abbv",
      "            abbv",
      "            abbv",
      "            abbv",
      "            abbv",
      "            abbv",
      "    c      cabbv",
      "            abbv",
      "            abbv",
      "            abbv",
      "            abbv",
      "            abbv",
      "            abbv",
      "            abbv",
      "            abbv"
    ],
    [
      "ddddddddddddebbv",
      "ddddddddddddebbv",
      "ddddddddddddebbv",
      "ddddddddddddebbv",
      "ddddddddddddebbv",
      "ddddddddddddebbv",
      "ddddddddddddebbv",
      "dddddddddddfebbv",
      "ddddddddddddebbv",
      "ddddddddddddebbv",
      "ddddddddddddebbv",
      "ddddddddddddebbv",
      "ddddddddddddebbv",
      "ddddddddddddebbv",
      "ddddddddddddebbv",
      "ddddddddddddebbv"
    ],
    [
      "bbbbbbbbbbbbabbv",
      "bbbbbbbbbbbbabbv",
      "bbbbbbbbbbbbabbv",
      "bbbbbbbbbbbbabbv",
      "bbbbbbbbbbbbabbv",
      "bbbbbbbbbbbbabbv",
      "bbbbbbbbbbbbabbv",
      "bbbbbbbbbbbbabbv",
      "bbbbbbbbbbbbabbv",
      "bbbbbbbbbbbbabbv",
      "bbbbbbbbbbbbabbv",
      "bbbbbbbbbbbbabbv",
      "bbbbbbbbbbbbabbv",
      "bbbbbbbbbbbbabbv",
      "bbbbbbbbbbbbabbv",
      "bbbbbbbbbbbbabbv"
    ],
    [
      "bbbbbbbbbbbbabbv",
      "bbbbbbbbbbbbabbv",
      "bbbbbbbbbbbbabbv",
      "bbbbbbbbbbbbabbv",
      "bbbbbbbbbbbbabbv",
      "bbbbbbbbbbbbabbv",
      "bbbbbbbbbbbbabbv",
      "bbbbbbbbbbbbabbv",
      "bbbbbbbbbbbbabbv",
      "bbbbbbbbbbbbabbv",
      "bbbbbbbbbbbbabbv",
      "bbbbbbbbbbbbabbv",
      "bbbbbbbbbbbbabbv",
      "bbbbbbbbbbbbabbv",
      "bbbbbbbbbbbbabbv",
      "bbbbbbbbbbbbabbv"
    ],
    [
      "dddgheeeeeeeabbv",
      "dddgheeeeeeeabbv",
      "dddgheeeeeeeabbv",
      "ggggheeeeeeeabbv",
      "hhhhheeeeeeeabbv",
      "eeeeeeeeeeeeabbv",
      "iiiiieeeeeeeabbv",
      "=====iieeeeeabbv",
      "=======ieeeeabbv",
      "========ieeeabbv",
      "=========ieeabbv",
      "==========ieabbv",
      "==========ieabbv",
      "===========iabbv",
      "===========iabbv",
      "===========iabbv"
    ],
    [
      "ccc         abbv",
      "c c         abbv",
      "ccc         abbv",
      "          jkabbv",
      " lm       noabbv",
      " pq         abbv",
      "=====       abbv",
      "fffff==     abbv",
      "fffffff=    abbv",
      "ffffffff=   abbv",
      "fffffffff=  abbv",
      "ffffffffff=rabbv",
      "ffffffffff=sabbv",
      "fffffffffff=abbv",
      "fffffffffff=abbv",
      "fffffffffff=abbv"
    ]
  ]
}