{
  "name": "multi_nuclearpowerplant_46_base7",
  "refpalette": "deceasedcraft:multi_nuclearpowerplant_46/multi_nuclearpowerplant_46_base7_palette",
  "xsize": 16,
  "zsize": 16,
  "slices": [
    [
      "aaa         bccv",
      "ada         bccv",
      "aaa       efbccv",
      "            bccv",
      "g           bccv",
      "h           bccv",
      "=====       bccv",
      "iiiii==     bccv",
      "    jii=    bccv",
      "       i=   bccv",
      "        i=k bccv",
      "         i=lbccv",
      "mmmm     i=nbccv",
      "ooomm    pi=bccv",
      "oooomm    i=bccv",
      "ooooom    i=bccv"
    ],
    [
      "aqa         bccv",
      "rsr       efbccv",
      "aaa         bccv",
      "            bccv",
      "            bccv",
      "            bccv",
      "=====       bccv",
      "iiiii==     bccv",
      "     ii=    bccv",
      "       i=   bccv",
      "        i= tbccv",
      "         i=ubccv",
      "mmmm     i=nbccv",
      "ooomm     i=bccv",
      "oooomm    i=bccv",
      "ooooom    i=bccv"
    ],
    [
      "aaa       efbccv",
      "rwr         bccv",
      "aaa         bccv",
      "            bccv",
      "            bccv",
      "            bccv",
      "=====       bccv",
      "iiiii==     bccv",
      "     ii=    bccv",
      "       i=   bccv",
      "        i=  bccv",
      "         i==bccv",
      "mmmm     i=xbccv",
      "wwwmm     i=bccv",
      "wwwwmm    i=bccv",
      "wwwwwm    i=bccv"
    ],
    [
      "aaa         bccv",
      "rwr         bccv",
      "aaa         bccv",
      "            bccv",
      "            bccv",
      "            bccv",
      "=====       bccv",
      "iiiii==     bccv",
      "     ii=    bccv",
      "       i=   bccv",
      "        i=  bccv",
      "         i==bccv",
      "mmmm     i=xbccv",
      "wwwmm     i=bccv",
      "wwwwmm    i=bccv",
      "wwwwwm    i=bccv"
    ],
    [
      "aaa         bccv",
      "rwr         bccv",
      "aaa         bccv",
      "            bccv",
      "            bccv",
      "            bccv",
      "=====       bccv",
      "iiiii==     bccv",
      "     ii=    bccv",
      "       i=   bccv",
      "        i=  bccv",
      "         i==bccv",
      "mmmm     i=xbccv",
      "wwwmm     i=bccv",
      "wwwwmm    i=bccv",
      "wwwwwm    i=bccv"
    ],
    [
      "aaa         bccv",
      "rwr         bccv",
      "aaa         bccv",
      "            bccv",
      "            bccv",
      "            bccv",
      "=====       bccv",
      "iiiii==     bccv",
      "     ii=    bccv",
      "       i=   bccv",
      "        i=  bccv",
      "         i==bccv",
      "mmmm     i=xbccv",
      "wwwmm     i=bccv",
      "wwwwmm    i=bccv",
      "wwwwwm    i=bccv"
    ]
  ]
}