{
  "name": "multi_nuclearpowerplant_46_base4",
  "refpalette": "deceasedcraft:multi_nuclearpowerplant_46/multi_nuclearpowerplant_46_base4_palette",
  "xsize": 16,
  "zsize": 16,
  "slices": [
    [
      " a          bccv",
      " a      de  bccv",
      " a          bccv",
      " a          bccv",
      " a          bccv",
      " a          bccv",
      "fff==       bccv",
      "ggghh==     bccv",
      " a   hh=    bccv",
      " a     h=   bccv",
      " a      h=  bccv",
      " a       h==bccv",
      "iiij     h=kbccv",
      "lmljj     h=bccv",
      "lmlljj    h=bccv",
      "lmlllj    h=bccv"
    ],
    [
      "            bccv",
      "            bccv",
      "        de  bccv",
      "        nnnnbccv",
      "        nnnnbccv",
      "        nnnnbccv",
      "=====       bccv",
      "hhhhh==     bccv",
      "     hh=    bccv",
      "       h=   bccv",
      "        h=  bccv",
      "         h==bccv",
      "jjjj     h=kbccv",
      "llljj     h=bccv",
      "lllljj    h=bccv",
      "lllllj    h=bccv"
    ],
    [
      "            bccv",
      "            bccv",
      "          opbccv",
      "        q   bccv",
      "        q  rbccv",
      "        stttbccv",
      "=====       bccv",
      "hhhhh==     bccv",
      "     hh=    bccv",
      "       h=   bccv",
      "        h=  bccv",
      "         h==bccv",
      "jjjj     h=kbccv",
      "llljj     h=bccv",
      "lllljj    h=bccv",
      "lllllj    h=bccv"
    ],
    [
      "            bccv",
      "          opbccv",
      "            bccv",
      "            bccv",
      "            bccv",
      "            bccv",
      "=====       bccv",
      "hhhhh==     bccv",
      "     hh=    bccv",
      "       h=   bccv",
      "        h=  bccv",
      "         h==bccv",
      "jjjj     h=kbccv",
      "llljj     h=bccv",
      "lllljj    h=bccv",
      "lllllj    h=bccv"
    ],
    [
      "          opbccv",
      "            bccv",
      "            bccv",
      "            bccv",
      "uuuu        bccv",
      "            bccv",
      "=====       bccv",
      "hhhhh==     bccv",
      "     hh=    bccv",
      "       h=   bccv",
      "        h=  bccv",
      "         h==bccv",
      "jjjj     h=kbccv",
      "   jj     h=bccv",
      "    jj    h=bccv",
      "     j    h=bccv"
    ],
    [
      "            bccv",
      "            bccv",
      "            bccv",
      "            bccv",
      "w w         bccv",
      "            bccv",
      "=====       bccv",
      "hhhhh==     bccv",
      "     hh=    bccv",
      "       h=   bccv",
      "        h=  bccv",
      "         h==bccv",
      "xxxx     h=kbccv",
      "   xx     h=bccv",
      "    xx    h=bccv",
      "     x    h=bccv"
    ]
  ]
}