{
  "name": "multi_nuclearpowerplant_46_base1",
  "refpalette": "deceasedcraft:multi_nuclearpowerplant_46/multi_nuclearpowerplant_46_base1_palette",
  "xsize": 16,
  "zsize": 16,
  "slices": [
    [
      "   a   b    cddv",
      " effgh b    cddv",
      "       b    cddv",
      "  i    b    cddv",
      "jjjjjjjb    cddv",
      "kkllmlnb    cddv",
      "opqrsrqb    cddv",
      "bbbbbbbb    cddv",
      "ttttttbb    cddv",
      "====ttttb   cddv",
      "======tttb  cddv",
      "=======ttbbbcddv",
      "========ttbucddv",
      "========ttbbcddv",
      "=========tttcddv",
      "=========tttcddv"
    ],
    [
      "       b    cddv",
      " w xy Ab    cddv",
      "       b    cddv",
      "      Bb    cddv",
      "       b    cddv",
      "C DE   b    cddv",
      "FIqJKJqb    cddv",
      "bbbbbbbb    cddv",
      "ttttttbb    cddv",
      "ttttttttb   cddv",
      "tttttttttb  cddv",
      "tttttttttbbbcddv",
      "ttttttttttbucddv",
      "ttttttttttbbcddv",
      "ttttttttttttcddv",
      "ttttttttttttcddv"
    ],
    [
      "       b    cddv",
      "       b    cddv",
      "       b    cddv",
      "      Bb    cddv",
      "       b    cddv",
      "L M   Nb    cddv",
      "FOqPOQqb    cddv",
      "bbbbbbbb    cddv",
      "ttttttbb    cddv",
      "ttttttttb   cddv",
      "tttttttttb  cddv",
      "tttttttttbbbcddv",
      "ttttttttttbucddv",
      "ttttttttttbbcddv",
      "ttttttttttttcddv",
      "ttttttttttttcddv"
    ],
    [
      "       b    cddv",
      "       b    cddv",
      "       b    cddv",
      "       b    cddv",
      "       b    cddv",
      "RSRSRSSb    cddv",
      "qqqqqqqb    cddv",
      "bbbbbbbb    cddv",
      "ttttttbb    cddv",
      "ttttttttb   cddv",
      "tttttttttb  cddv",
      "tttttttttbbbcddv",
      "ttttttttttbucddv",
      "ttttttttttbbcddv",
      "ttttttttttttcddv",
      "ttttttttttttcddv"
    ],
    [
      "       bTTTTcddv",
      "       bTTTTcddv",
      "       bTTTTcddv",
      "       bTTTTcddv",
      "       bTTTTcddv",
      "UUUUUUUbTTTTcddv",
      "VVVVVVVbTTTTcddv",
      "bbbbbbbbTTTTcddv",
      "ttttttbbTTTTcddv",
      "ttttttttbTTTcddv",
      "tttttttttbTTcddv",
      "tttttttttbbbcddv",
      "ttttttttttbucddv",
      "ttttttttttbbcddv",
      "ttttttttttttcddv",
      "ttttttttttttcddv"
    ],
    [
      "WXWWXWWbu Ytcttv",
      "WXWWXWWbu Ytcttv",
      "WXWWXWWbu Ytcttv",
      "WXWWXWWbuYYtcttv",
      "WWWWWWWbuYttcttv",
      "WWWWWWWbuYttcttv",
      "uuuuuuZuuYttcttv",
      "bbbbbbbbYYttcttv",
      "ttttttbbYtttcttv",
      "ttttttttYtttcttv",
      "tttttttYYtttcttv",
      "tttttttYttttcttv",
      "ttttttYYttttcttv",
      "ttttttYtttttcttv",
      "tttttYYtttttcttv",
      "tttttYttttttcttv"
    ]
  ]
}