{
  "name": "multi_nuclearpowerplant_46_base5",
  "refpalette": "deceasedcraft:multi_nuclearpowerplant_46/multi_nuclearpowerplant_46_base5_palette",
  "xsize": 16,
  "zsize": 16,
  "slices": [
    [
      "aaa       bcdeev",
      "fgf         deev",
      "aaa         deev",
      " h          deev",
      " h          deev",
      " h          deev",
      "iii==       deev",
      "jjjkk==     deev",
      " h   kk=    deev",
      " h     k=   deev",
      " h      k=  deev",
      " h       k==deev",
      "lllm     k=ndeev",
      "gogmm     k=deev",
      "goggmm    k=deev",
      "gogggm    k=deev"
    ],
    [
      "aaa         deev",
      "fpf         deev",
      "aga         deev",
      "qgr         deev",
      "qgr         deev",
      "qgr         deev",
      "igi==       deev",
      "jgjkk==     deev",
      "qgr  kk=    deev",
      "qgr    k=   deev",
      "qgr     k=  deev",
      "qgr      k==deev",
      "lglm     k=ndeev",
      "sgtmm     k=deev",
      "sgtgmm    k=deev",
      "sgtggm    k=deev"
    ],
    [
      "aaa         deev",
      "aua         deev",
      "aaa         deev",
      " w          deev",
      " w          deev",
      " w          deev",
      "iii==       deev",
      "jjjkk==     deev",
      " w   kk=    deev",
      " w     k=   deev",
      " w      k=  deev",
      " w       k==deev",
      "lllm     k=ndeev",
      "gxgmm     k=deev",
      "gxggmm    k=deev",
      "gxgggm    k=deev"
    ],
    [
      "yyy         deev",
      "yAy         deev",
      "yyy         deev",
      "            deev",
      "            deev",
      "            deev",
      "=====       deev",
      "kkkkk==     deev",
      "     kk=    deev",
      "       k=   deev",
      "        k=  deev",
      "         k==deev",
      "mmmm     k=ndeev",
      "gggmm     k=deev",
      "ggggmm    k=deev",
      "gggggm    k=deev"
    ],
    [
      " h          deev",
      " h          deev",
      " h          deev",
      " h          deev",
      " h          deev",
      " h          deev",
      "iii==       deev",
      "jjjkk==     deev",
      " h   kk=    deev",
      " h     k=   deev",
      " h      k=  deev",
      " h       k==deev",
      "lllm     k=ndeev",
      "gogmm     k=deev",
      "goggmm    k=deev",
      "gogggm    k=deev"
    ],
    [
      "qgr     BC  deev",
      "qgr         deev",
      "qgr         deev",
      "qgr         deev",
      "qgr         deev",
      "qgr         deev",
      "igi==       deev",
      "jgjkk==     deev",
      "qgr  kk=    deev",
      "qgr    k=   deev",
      "qgr     k=  deev",
      "qgr      k==deev",
      "lglm     k=ndeev",
      "sgtmm     k=deev",
      "sgtgmm    k=deev",
      "sgtggm    k=deev"
    ]
  ]
}