{
  "name": "multi_nuclearpowerplant_46_base10",
  "refpalette": "deceasedcraft:multi_nuclearpowerplant_46/multi_nuclearpowerplant_46_base10_palette",
  "xsize": 16,
  "zsize": 16,
  "slices": [
    [
      "   abcccccccdeev",
      "   abcccccccdeev",
      "   abcccccccdeev",
      "   abcccccccdeev",
      "   abcccccccdeev",
      "   abcccccccdeev",
      "   abcccccffdeev",
      "   abcccccfgdeev",
      "   abcccccffdeev",
      "   abcccccccdeev",
      "   abcccccccdeev",
      "   abcccccccdeev",
      "   abcccccccdeev",
      "   abcccccccdeev",
      "   abcccccccdeev",
      "   abcccccccdeev"
    ],
    [
      "    h      ijeev",
      "    h      ijeev",
      "    h      ijeev",
      "    h      ijeev",
      "    h      ijeev",
      "    h      ijeev",
      "    h      ijeev",
      "    h     kljeev",
      "    h     mijeev",
      "    h     nijeev",
      "    h     nijeev",
      "    h     nijeev",
      "    h     nijeev",
      "    h     nijeev",
      "    h     nijeev",
      "    h     nijeev"
    ],
    [
      "          nojeev",
      "          n jeev",
      "          npjeev",
      "          nqjeev",
      "          nrjeev",
      "          nojeev",
      "          n jeev",
      "           ljeev",
      "          msjeev",
      "            jeev",
      "            jeev",
      "            jeev",
      "            jeev",
      "            jeev",
      "           tjeev",
      "            jeev"
    ],
    [
      "            jeev",
      "            jeev",
      "            jeev",
      "            jeev",
      "            jeev",
      "            jeev",
      "            jeev",
      "           ljeev",
      "            jeev",
      "            jeev",
      "            jeev",
      "            jeev",
      "            jeev",
      "            jeev",
      "            jeev",
      "            jeev"
    ],
    [
      "           ijeev",
      "           ijeev",
      "           ijeev",
      "           ijeev",
      "           ijeev",
      "           ijeev",
      "           ijeev",
      "           ljeev",
      "          mijeev",
      "          nijeev",
      "          nijeev",
      "          nijeev",
      "          nijeev",
      "          nijeev",
      "          nijeev",
      "          nijeev"
    ],
    [
      "          nojeev",
      "          npjeev",
      "          nujeev",
      "          nojeev",
      "          nojeev",
      "          n jeev",
      "          n jeev",
      "           ljeev",
      "          msjeev",
      "            jeev",
      "            jeev",
      "            jeev",
      "           ojeev",
      "            jeev",
      "            jeev",
      "            jeev"
    ]
  ]
}