{
  "name": "multi_nuclearpowerplant_46_base3",
  "refpalette": "deceasedcraft:multi_nuclearpowerplant_46/multi_nuclearpowerplant_46_base3_palette",
  "xsize": 16,
  "zsize": 16,
  "slices": [
    [
      "aaaaaaab    cddv",
      "aaaaaaab    cddv",
      "aaaaaaab    cddv",
      "aaaaaaab    cddv",
      "aaaaaaab    cddv",
      "aaaaaaab    cddv",
      "=====aab    cddv",
      "eeeee==b    cddv",
      "fffffeeb    cddv",
      "fffffffeb   cddv",
      "ffffffffeb  cddv",
      "     ffffebbcddv",
      "      fffebgcddv",
      "       fffebcddv",
      "       fffe=cddv",
      "       fffe=cddv"
    ],
    [
      "hhhhhhh=    iddv",
      "hhhhhhh=    iddv",
      "hhhhhhh=    iddv",
      "hhhhhhh=    iddv",
      "hhhhhhh=    iddv",
      "hhhhhhh=    iddv",
      "=j===hh=    iddv",
      "hkhhh===    iddv",
      "    lhh=    iddv",
      "       h=   iddv",
      "mmmmm   h=  iddv",
      "     n   h==iddv",
      "      n  h=giddv",
      "       o ph=iddv",
      "       o  h=iddv",
      "       o  h=iddv"
    ],
    [
      "   qr s=    iddv",
      "   tr s=    iddv",
      "   tr s=    iddv",
      "   ur s=    iddv",
      "      h=    iddv",
      "q qqqwh=    iddv",
      "=x===yh=    iddv",
      "h hhh===    iddv",
      "     hh=    iddv",
      "       h=   iddv",
      "        h=  iddv",
      "         h==iddv",
      "         h=giddv",
      "          h=iddv",
      "          h=iddv",
      "          h=iddv"
    ],
    [
      "   q   =AB  iddv",
      "   C   =    iddv",
      "   C   =    iddv",
      "   u  D=    iddv",
      "      h=    iddv",
      "q qqqwh=    iddv",
      "=E===Fh=    iddv",
      "h hhh===    iddv",
      "     hh=    iddv",
      "       h=   iddv",
      "        h=  iddv",
      "         h==iddv",
      "         h=giddv",
      "          h=iddv",
      "          h=iddv",
      "          h=iddv"
    ],
    [
      "   q  I=    iddv",
      "   J  I=AB  iddv",
      "   J  I=    iddv",
      "   u  I=    iddv",
      "   K  h=    iddv",
      "qLqqqwh=    iddv",
      "=j===Fh=    iddv",
      "hMhhh===    iddv",
      "     hh=    iddv",
      "       h=   iddv",
      "        h=  iddv",
      "         h==iddv",
      "         h=giddv",
      "          h=iddv",
      "          h=iddv",
      "          h=iddv"
    ],
    [
      "   h  h=    iddv",
      "   h  h=    iddv",
      "   h  h=AB  iddv",
      "   h  h=ffffiddv",
      "   h  h=ffffiddv",
      "qqqhqwh=ffffiddv",
      "=====gh=    iddv",
      "hhhhh===    iddv",
      "     hh=    iddv",
      "       h=   iddv",
      "        h=  iddv",
      "         h==iddv",
      "         h=giddv",
      "          h=iddv",
      "          h=iddv",
      "          h=iddv"
    ]
  ]
}