{
  "name": "multi_nuclearpowerplant_46_base11",
  "refpalette": "deceasedcraft:multi_nuclearpowerplant_46/multi_nuclearpowerplant_46_base11_palette",
  "xsize": 16,
  "zsize": 16,
  "slices": [
    [
      "abcd========effv",
      "ghcd========effv",
      "cccd========effv",
      "bhcd========effv",
      "agcd========effv",
      "cccd========effv",
      "abcd========effv",
      "ghcd========effv",
      "cccd========effv",
      "bhcd========effv",
      "agcd========effv",
      "cccd========effv",
      "abcd========effv",
      "ghcd========effv",
      "cccd========effv",
      "bhcd========effv"
    ],
    [
      "bhcd========effv",
      "agcd========effv",
      "cccd========effv",
      "abcd========effv",
      "ghcd========effv",
      "cccd========effv",
      "cccd========effv",
      "cccd========effv",
      "cccd========effv",
      "abcd========effv",
      "ghcd========effv",
      "cccd========effv",
      "cccd========effv",
      "cccd========effv",
      "cccd========effv",
      "cccd========effv"
    ],
    [
      "cccd========effv",
      "cccd========effv",
      "cccd========effv",
      "cccd========effv",
      "cccd========effv",
      "cccd========effv",
      "cccd========effv",
      "cccd========effv",
      "cccd========effv",
      "cccd========effv",
      "cccd========effv",
      "cccd========effv",
      "cccd========effv",
      "cccd========effv",
      "cccd========effv",
      "cccd========effv"
    ],
    [
      "cccd========effv",
      "cccd========effv",
      "cccd========effv",
      "cccd========effv",
      "cccd========effv",
      "cccd========effv",
      "cccd========effv",
      "cccd========effv",
      "cccd========effv",
      "cccd========effv",
      "cccd========effv",
      "cccd========effv",
      "cccd========effv",
      "cccd========effv",
      "cccd========effv",
      "cccd========effv"
    ],
    [
      "cccd========effv",
      "cccd========effv",
      "cccd========effv",
      "cccd========effv",
      "cccd========effv",
      "cccd========effv",
      "cccd========effv",
      "cccd========effv",
      "cccd========effv",
      "cccd========effv",
      "cccd========effv",
      "cccd========effv",
      "cccd========effv",
      "cccd========effv",
      "cccd========effv",
      "cccd========effv"
    ],
    [
      "cccd========effv",
      "cccd========effv",
      "cccd========effv",
      "cccd========effv",
      "cccd========effv",
      "cccd========effv",
      "cccd========effv",
      "cccd========effv",
      "cccd========effv",
      "cccd========effv",
      "cccd========effv",
      "cccd========effv",
      "cccd========effv",
      "cccd========effv",
      "cccd========effv",
      "cccd========effv"
    ]
  ]
}