{
  "name": "multi_nuclearpowerplant_46_base2",
  "refpalette": "deceasedcraft:multi_nuclearpowerplant_46/multi_nuclearpowerplant_46_base2_palette",
  "xsize": 16,
  "zsize": 16,
  "slices": [
    [
      "   a  a=    bccv",
      "   a  a=    bccv",
      "   a  a=  debccv",
      "   a  a=    bccv",
      "   a  a=   fbccv",
      "gggagha=iiiibccv",
      "=====ja=    bccv",
      "aaaaa===    bccv",
      " k   aa=    bccv",
      "       a=   bccv",
      "        a=  bccv",
      "         a==bccv",
      "         a=jbccv",
      "          a=bccv",
      "          a=bccv",
      "          a=bccv"
    ],
    [
      "llla  a=    bccv",
      "llla  a=  debccv",
      "llla  a=    bccv",
      "llla  a=    bccv",
      "llla  a=    bccv",
      "gggagha=    bccv",
      "=====ja=    bccv",
      "aaaaa===    bccv",
      "     aa=    bccv",
      "       a=   bccv",
      "        a=  bccv",
      "         a==bccv",
      "         a=jbccv",
      "          a=bccv",
      "          a=bccv",
      "          a=bccv"
    ],
    [
      "jjja  a=  debccv",
      "jjja  a=    bccv",
      "jjja  a=    bccv",
      "jjja  a=    bccv",
      "jjja  a=    bccv",
      "gggagha=    bccv",
      "=====ja=    bccv",
      "aaaaa===    bccv",
      "     aa=    bccv",
      "       a=   bccv",
      "        a=  bccv",
      "         a==bccv",
      "         a=jbccv",
      "          a=bccv",
      "          a=bccv",
      "          a=bccv"
    ],
    [
      "ajaaaaa=    bccv",
      "aaaaaaa=    bccv",
      "aaaaaaa=    bccv",
      "ajaaaaa=    bccv",
      "aaaaaaa=    bccv",
      "aaaaaaa=    bccv",
      "=====ja=    bccv",
      "aaaa====    bccv",
      "mmmmaa==    bccv",
      "      aa=   bccv",
      "       aa=  bccv",
      "        a===bccv",
      "         a=jbccv",
      "         a==bccv",
      "         na=bccv",
      "         na=bccv"
    ],
    [
      " j     o    bccv",
      " j     o    bccv",
      " j     o    bccv",
      " j     o    bccv",
      " j     o    bccv",
      " j    jo    bccv",
      "jjjjjjjo    bccv",
      "====oooo    bccv",
      "aaaa==oo    bccv",
      "ppppaa==o   bccv",
      "    ppa==o  bccv",
      "      pa=ooobccv",
      "       pa=ojbccv",
      "       pa=oobccv",
      "        pa=qbccv",
      "        pa=qbccv"
    ],
    [
      "rrrrrrrs    bccv",
      "rrrrrrrs    bccv",
      "rrrrrrrs    bccv",
      "rrrrrrrs    bccv",
      "rrrrrrrs    bccv",
      "rrrrrrts    bccv",
      "rrrrrrrs    bccv",
      "ssssssss    bccv",
      "====qqss    bccv",
      "aaaa==qqs   bccv",
      "aaaaaa=qqs  bccv",
      "aaaaaaa=qsssbccv",
      "aaaaaaaa=qsjbccv",
      "aaaaaaaa=qssbccv",
      "aaaaaaaaa=qqbccv",
      "aaaaaaaaa=qqbccv"
    ]
  ]
}