{
  "name": "multi_nuclearpowerplant_46_base6",
  "refpalette": "deceasedcraft:multi_nuclearpowerplant_46/multi_nuclearpowerplant_46_base6_palette",
  "xsize": 16,
  "zsize": 16,
  "slices": [
    [
      "aaa         bccv",
      "ded         bccv",
      "aaa         bccv",
      "            bccv",
      "            bccv",
      "            bccv",
      "=====       bccv",
      "fffff==     bccv",
      "     ff=    bccv",
      "       f=   bccv",
      "        f=  bccv",
      "         f==bccv",
      "gggg     f=hbccv",
      "eeegg     f=bccv",
      "eeeegg    f=bccv",
      "eeeeeg    f=bccv"
    ],
    [
      "aaa     ij  kccv",
      "ded         kccv",
      "aaa         kccv",
      "            kccv",
      "            kccv",
      "            kccv",
      "=====       kccv",
      "fffff==     kccv",
      "     ff=    kccv",
      "       f=   kccv",
      "        f=  kccv",
      "         f==kccv",
      "gggg     f=hkccv",
      "eeegg     f=kccv",
      "eeeegg    f=kccv",
      "eeeeeg    f=kccv"
    ],
    [
      "aaa         kccv",
      "ded     ij  kccv",
      "aaa         kccv",
      " l          kccv",
      "ll          kccv",
      "            kccv",
      "=====       kccv",
      "fffff==     kccv",
      "     ff=    kccv",
      "       f=   kccv",
      "        f=  kccv",
      "         f==kccv",
      "gggg     f=hkccv",
      "eeegg     f=kccv",
      "eeeegg    f=kccv",
      "eeeeeg    f=kccv"
    ],
    [
      "aaa         kccv",
      "dmd         kccv",
      "aea     ij  kccv",
      "neo     ppppkccv",
      "eeo     ppppkccv",
      "qq      ppppkccv",
      "=====       kccv",
      "fffff==     kccv",
      "     ff=    kccv",
      "       f=   kccv",
      "        f=  kccv",
      "         f==kccv",
      "gggg     f=hkccv",
      "eeegg     f=kccv",
      "eeeegg    f=kccv",
      "eeeeeg    f=kccv"
    ],
    [
      "aaa         kccv",
      "ded         kccv",
      "aaa       rskccv",
      " t      u   kccv",
      "tt      u  wkccv",
      "        xyyykccv",
      "=====       kccv",
      "fffff==     kccv",
      "     ff=    kccv",
      "       f=   kccv",
      "        f=  kccv",
      "         f==kccv",
      "gggg     f=hkccv",
      "eeegg     f=kccv",
      "eeeegg    f=kccv",
      "eeeeeg    f=kccv"
    ],
    [
      "aaa         kccv",
      "ded       rskccv",
      "aaa         kccv",
      "            kccv",
      "            kccv",
      "            kccv",
      "=====       kccv",
      "fffff==     kccv",
      "     ff=    kccv",
      "       f=   kccv",
      "        f=  kccv",
      "         f==kccv",
      "gggg     f=hkccv",
      "eeegg     f=kccv",
      "eeeegg    f=kccv",
      "eeeeeg    f=kccv"
    ]
  ]
}