{
  "name": "multi_nuclearpowerplant_46_base12",
  "refpalette": "deceasedcraft:multi_nuclearpowerplant_46/multi_nuclearpowerplant_46_base12_palette",
  "xsize": 16,
  "zsize": 16,
  "slices": [
    [
      "aaaaaaaaaaaaaaav",
      "aaaaaaaaaaaaaaav",
      "aaaaaaaaaaaaaaav",
      "aaaaaaaaaaaaaaav",
      "aaaaaaaaaaaaaaav",
      "aaaaaaaaaaaaaaav",
      "aaaaaaaaaaaaaaav",
      "aaaaaaaaaaaaaaav",
      "aaaaaaaaaaaaaaav",
      "aaaaaaaaaaaaaaav",
      "aaaaaaaaaaaaaaav",
      "aaaaaaaaaaaaaaav",
      "aaaaaaaaaaaaaaav",
      "aaaaaaaaaaaaaaav",
      "aaaaaaaaaaaaaaav",
      "aaaaaaaaaaaaaaav"
    ],
    [
      "bbbbbbbbbbbbbaav",
      "bbbbbbbbbbbbbaav",
      "bbbbbbbbbbbbbaav",
      "bbbbbbbbbbbbbaav",
      "bbbbbbbbbbbbbaav",
      "bbbbbbbbbbbbbaav",
      "bbbbbbbbbbbbbaav",
      "bbbbbbbbbbbbbaav",
      "bbbbbbbbbbbbbaav",
      "bbbbbbbbbbbbbaav",
      "bbbbbbbbbbbbbaav",
      "bbbbbbbbbbbbbaav",
      "bbbbbbbbbbbbbaav",
      "bbbbbbbbbbbbbaav",
      "bbbbbbbbbbbbbaav",
      "bbbbbbbbbbbbbaav"
    ],
    [
      "============caav",
      "============caav",
      "============caav",
      "============caav",
      "============caav",
      "============caav",
      "============caav",
      "============caav",
      "============caav",
      "============caav",
      "============caav",
      "============caav",
      "============caav",
      "============caav",
      "============caav",
      "============caav"
    ],
    [
      "dddb========eaav",
      "dddb========eaav",
      "dddb========eaav",
      "dddb========eaav",
      "dddb========eaav",
      "dddb========eaav",
      "dddb========eaav",
      "dddb========eaav",
      "dddb========eaav",
      "dddb========eaav",
      "dddb========eaav",
      "dddb========eaav",
      "dddb========eaav",
      "dddb========eaav",
      "dddb========eaav",
      "dddb========eaav"
    ],
    [
      "ffgb========eaav",
      "ffgb========eaav",
      "gggb========eaav",
      "ffgb========eaav",
      "ffgb========eaav",
      "gggb========eaav",
      "ffgb========eaav",
      "ffgb========eaav",
      "gggb========eaav",
      "ffgb========eaav",
      "ffgb========eaav",
      "gggb========eaav",
      "ffgb========eaav",
      "ffgb========eaav",
      "gggb========eaav",
      "ffgb========eaav"
    ],
    [
      "higb========eaav",
      "jkgb========eaav",
      "gggb========eaav",
      "jhgb========eaav",
      "kigb========eaav",
      "gggb========eaav",
      "higb========eaav",
      "jkgb========eaav",
      "gggb========eaav",
      "jhgb========eaav",
      "kigb========eaav",
      "gggb========eaav",
      "higb========eaav",
      "jkgb========eaav",
      "gggb========eaav",
      "jhgb========eaav"
    ]
  ]
}