{
  "name": "multi_nuclearpowerplant_46_base9",
  "refpalette": "deceasedcraft:multi_nuclearpowerplant_46/multi_nuclearpowerplant_46_base9_palette",
  "xsize": 16,
  "zsize": 16,
  "slices": [
    [
      "            abbv",
      "            abbv",
      "            abbv",
      "            abbv",
      "            abbv",
      "            abbv",
      "            abbv",
      "           cabbv",
      "            abbv",
      "            abbv",
      "            abbv",
      "            abbv",
      "            abbv",
      "            abbv",
      "            abbv",
      "            abbv"
    ],
    [
      "           dabbv",
      "           dabbv",
      "           dabbv",
      "           dabbv",
      "           dabbv",
      "           dabbv",
      "           dabbv",
      "           cabbv",
      "           dabbv",
      "           dabbv",
      "           dabbv",
      "           dabbv",
      "           dabbv",
      "           dabbv",
      "           dabbv",
      "           dabbv"
    ],
    [
      "          e abbv",
      "          efabbv",
      "          e abbv",
      "          e abbv",
      "          e abbv",
      "          efabbv",
      "          egabbv",
      "           cabbv",
      "          hiabbv",
      "          e abbv",
      "          egabbv",
      "          e abbv",
      "          e abbv",
      "          e abbv",
      "          e abbv",
      "          egabbv"
    ],
    [
      "            abbv",
      "            abbv",
      "            abbv",
      "            abbv",
      "            abbv",
      "            abbv",
      "            abbv",
      "jjjjjjjjjjkcabbv",
      "          h abbv",
      "            abbv",
      "            abbv",
      "            abbv",
      "            abbv",
      "            abbv",
      "            abbv",
      "            abbv"
    ],
    [
      "    c       abbv",
      "    c       abbv",
      "    c       abbv",
      "    c       abbv",
      "    c       abbv",
      "    c       abbv",
      "    c       abbv",
      "ccccccccccccabbv",
      "    c       abbv",
      "    c       abbv",
      "    c       abbv",
      "    c       abbv",
      "    c       abbv",
      "    c       abbv",
      "    c       abbv",
      "    c       abbv"
    ],
    [
      "            abbv",
      "            abbv",
      "            abbv",
      "            abbv",
      "            abbv",
      "            abbv",
      "    l       abbv",
      "   mcn    ocabbv",
      "    p       abbv",
      "            abbv",
      "            abbv",
      "            abbv",
      "            abbv",
      "            abbv",
      "            abbv",
      "            abbv"
    ]
  ]
}