{
  "name": "multi_hospitaldamaged_4_base2",
  "refpalette": "deceasedcraft:multi_hospitaldamaged_4/multi_hospitaldamaged_4_base2_palette",
  "xsize": 16,
  "zsize": 16,
  "slices": [
    [
      "vvvvvvvvvaaaavvv",
      "vvvvvvvvvaaaavvv",
      "vvvvvvvvvaaaavvv",
      "vvvvvvvvvvvvvvvv",
      "vvvvvvvvvvvvvvvv",
      "vvvvvvvvvvvvvvvv",
      "vvvvvvvvvvvvvvvv",
      "vvvvvvvvvvvvvvvv",
      "vvvvvvvvvvvvvvvv",
      "vvvvvvvvvvvvvvvv",
      "vvvvvvvvvvvvvvvv",
      "vvvvvvvvvvvvvvvv",
      "vvvvvvvvvvvvvvvv",
      "vvvvvvvvvvvvvvvv",
      "vvvvvvvvvvvvvvvv",
      "vvvvvvvvvvvvvvvv"
    ],
    [
      "bbbbbbbbc   @dav",
      "bbbbbbbbc   @dav",
      "bbbbbbbbc   @dav",
      "bbbbbbbbccccceav",
      "bbbbbbbbbbbbbbbv",
      "bbbbbbbbbbbbbbbv",
      "bbbbbbbbbbbbbbbv",
      "bbbbbbbbbbbbbbbv",
      "bbbbbbbbbbbbbbbv",
      "bbbbbbbbbbbbbbbv",
      "bbbbbbbbbbbbbbbv",
      "bbbbbbbbbbbbbbbv",
      "bbbbbbbbbbbbbbbv",
      "bbbbbbbbbbbbbbbv",
      "bbbbbbbbbbbbbbbv",
      "bbbbbbbbbbbbbbbv"
    ],
    [
      "bbbbbbbbc   @dav",
      "bbbbbbbbc   @dav",
      "bbbbbbbbc   @dav",
      "bbbbbbbbccccceav",
      "bbbbbbbbbbbbbbbv",
      "bbbbbbbbbbbbbbbv",
      "bbbbbbbbbbbbbbbv",
      "bbbbbbbbbbbbbbbv",
      "bbbbbbbbbbbbbbbv",
      "bbbbbbbbbbbbbbbv",
      "bbbbbbbbbbbbbbbv",
      "bbbbbbbbbbbbbbbv",
      "bbbbbbbbbbbbbbbv",
      "bbbbbbbbbbbbbbbv",
      "bbbbbbbbbbbbbbbv",
      "bbbbbbbbbbbbbbbv"
    ],
    [
      "bbbbbbbbf   @dav",
      "bbbbbbbbg   @dav",
      "bbbbbbbbc   @dav",
      "bbbbbbbbccccceav",
      "bbbbbbbbbbbbbbbv",
      "bbbbbbbbbbbbbbbv",
      "bbbbbbbbbbbbbbbv",
      "bbbbbbbbbbbbbbbv",
      "bbbbbbbbbbbbbbbv",
      "bbbbbbbbbbbbbbbv",
      "bbbbbbbbbbbbbbbv",
      "bbbbbbbbbbbbbbbv",
      "bbbbbbbbbbbbbbbv",
      "bbbbbbbbbbbbbbbv",
      "bbbbbbbbbbbbbbbv",
      "bbbbbbbbbbbbbbbv"
    ],
    [
      "cccccchhc   @dav",
      "cccccchhc   @dav",
      "cccccchhc   @dav",
      "ccccccccccccceav",
      "ccccccbbbbbbbbbv",
      "ccccccbbbbbbbbbv",
      "ccccccbbbbbbbbbv",
      "ccccccbbbbbbbbbv",
      "ccccccbbbbbbbbbv",
      "ccccccbbbbbbbbbv",
      "ccccccbbbbbbbbbv",
      "ccccccbbbbbbbbbv",
      "ccccccbbbbbbbbbv",
      "iiiiicbbbbbbbbbv",
      "iiiiiibbbbbbbbbv",
      "iiiiiibbbbbbbbbv"
    ],
    [
      "hhhhhcjjc   @dav",
      "hhhhhchhc   @dav",
      "hhhhhchhc   @dav",
      "hhhhhcccccccceav",
      "hhhhhcbbbbbbbbbv",
      "hhhhhcbbbbbbbbbv",
      "hhhhhcbbbbbbbbbv",
      "hhhhhcbbbbbbbbbv",
      "chhhhcbbbbbbbbbv",
      "chhhhcbbbbbbbbbv",
      "chhhhcbbbbbbbbbv",
      "chhhhcbbbbbbbbbv",
      "chhhhcbbbbbbbbbv",
      "hhhhhhbbbbbbbbbv",
      "hhhhhhbbbbbbbbbv",
      "hhhhhhbbbbbbbbbv"
    ]
  ]
}