{
  "name": "multi_hospitaldamaged_4_base1",
  "refpalette": "deceasedcraft:multi_hospitaldamaged_4/multi_hospitaldamaged_4_base1_palette",
  "xsize": 16,
  "zsize": 16,
  "slices": [
    [
      "aaaaab  bcccaadv",
      "aaaaabeefgccaadv",
      "aaaaabaahcccaadv",
      "aaaaabbaiaaabjdv",
      "aaaaaaaaaaaaakkv",
      "aaaaaaaaaaaaakkv",
      "aaaaaaaaaaaaakkv",
      "aaaaaaaaaaaaakkv",
      "bllmnbaaaaaabkkv",
      "bllo baaaaaabkkv",
      "b    bppppppbkkv",
      "b    bdddddqbkkv",
      "b r  bbbbbbbbkkv",
      "     skkkkkkkkkv",
      "     skkkkkkkkkv",
      "     skkkkkkkkkv"
    ],
    [
      "btu  b  bw  @qdv",
      "bt   b  bx  @qdv",
      "bjjyjA  bwBC@qdv",
      "b    bbDbEFIbjdv",
      "     s  J K skkv",
      "     L      skkv",
      "    MN      skkv",
      "     s     Oskkv",
      "b    b  PQ Rbkkv",
      "b    b SSSSTbkkv",
      "b    bppppppbkkv",
      "b    bddddqUbkkv",
      "b    bbbbbbbbkkv",
      "     skkkkkkkkkv",
      "     skkkkkkkkkv",
      "     skkkkkkkkkv"
    ],
    [
      "bV   b  bw  @qdv",
      "bWX  b  bw  @qdv",
      "bjjYjA  bw  @qdv",
      "b    bbZbE01bjdv",
      "     s2     skkv",
      "     3      skkv",
      "     4      skkv",
      "     s2     skkv",
      "b    b      bkkv",
      "b    b SSSS bkkv",
      "b    bpppp5Rbkkv",
      "b    bdddqUUbkkv",
      "b    bbbbbbbbkkv",
      "     skkkkkkkkkv",
      "     skkkkkkkkkv",
      "     skkkkkkkkkv"
    ],
    [
      "b    b  bw  @qdv",
      "b    b  bw6 @qdv",
      "bjj7jA  bw  @qdv",
      "b  8 bb9bEEEbjdv",
      "     s #    skkv",
      "     $      skkv",
      "     $      skkv",
      "     s      skkv",
      "b    b      bkkv",
      "b    b SSSS bkkv",
      "b    bppp5  bkkv",
      "b    bddqUUUbkkv",
      "b    bbbbbbbbkkv",
      "     skkkkkkkkkv",
      "     skkkkkkkkkv",
      "     skkkkkkkkkv"
    ],
    [
      "bppppb  bppp@qdv",
      "bppppb  bppp@qdv",
      "bjjjjA  bppp@qdv",
      "b    bbbbbbbbjdv",
      "     s      skkv",
      "     s      skkv",
      "     s      skkv",
      "     s      skkv",
      "b    b      bkkv",
      "b    b SSSS bkkv",
      "baaaabpp5   bkkv",
      "b%%%%bdqUUUUbkkv",
      "b%%%%bbbbbbbbkkv",
      "%%%%%^kkkkkkkkkv",
      "%%%%%^kkkkkkkkkv",
      "%%%%%^kkkkkkkkkv"
    ],
    [
      "b&&&&b&&b   @qdv",
      "b&&&&b&&b   @qdv",
      "b&&&&b&&b   @qdv",
      "b&&&&bbbbbbbbjdv",
      "&&&&&&&&&&&&&kkv",
      "&&&&&&&&&&&&&kkv",
      "&&&&&&&&&&&&&kkv",
      "&&&&&&&&&&&&&kkv",
      "b&&&&b      bkkv",
      "b&&&&b*SSSS bkkv",
      "baaaabp5    bkkv",
      "b&&&&bqUUUUUbkkv",
      "b&&&&bbbbbbbbkkv",
      "&&&&&&kkkkkkkkkv",
      "&&&&&&kkkkkkkkkv",
      "&&&&&&kkkkkkkkkv"
    ]
  ]
}