{
  "name": "multi_hospitaldamaged_4_top",
  "refpalette": "deceasedcraft:multi_hospitaldamaged_4/multi_hospitaldamaged_4_top_palette",
  "xsize": 16,
  "zsize": 16,
  "slices": [
    [
      "aaaaaaaab   b   ",
      "aaaaaaaac   bd  ",
      "aaaaaaaae   b   ",
      "aaaaaaaafbbbgd  ",
      "aaaaaaaaaaaag   ",
      "aaaaaaaaaaaagd  ",
      "aaaaaaaaaaaag   ",
      "aaaaagaaaaaagd  ",
      "bbaaaghhhhhhi   ",
      "bbaaagjddddkl   ",
      "bbaaagm     i   ",
      "bbaaaglililil   ",
      "bbaaagn         ",
      "bbbbbbo         ",
      "aaaaaao         ",
      "aaaaaap         "
    ],
    [
      "qrs t urg   w   ",
      " r x  yrg   wd  ",
      "ArB   yrg   w   ",
      "rrrrrCrrgDEFgd  ",
      "  I J  KLM  N   ",
      "   O P  Q M Nd  ",
      "R   ST K   UN   ",
      "!VP  gW  XY gd  ",
      "Zr  0g X 1 m2   ",
      " r3 0g dddd42   ",
      "5r  0g    kk2   ",
      "6r  0g222 222   ",
      " r   g7         ",
      "8r9#9ro         ",
      "   3  o         ",
      "      o         "
    ],
    [
      " o     og   w   ",
      " o    $og   wd  ",
      "%o^&   og   w   ",
      "2o22o*oogD()gd  ",
      "            2   ",
      "             d  ",
      "     +      2   ",
      "R    g     -gd  ",
      "[o   g      2   ",
      "]o   g dddd 2   ",
      " o   g   k{m2   ",
      "}o   g222222    ",
      " o   gn         ",
      "|o9;9op         ",
      "      o         ",
      "      o         "
    ],
    [
      " o     og   w   ",
      " o    :og   wd  ",
      "'o<>   og   w   ",
      "2o22o,oo.DDDgd  ",
      "     ?      g   ",
      "            gd  ",
      "     /      g   ",
      "     g      gd  ",
      "[o   g      2   ",
      "`o  \u0370g dddd 2   ",
      " o  \u0371g  k{  2   ",
      "\u0372o   g2222222   ",
      " o   gn         ",
      ",o999op         ",
      "      \u0373         ",
      "                "
    ],
    [
      " o     og   w   ",
      " o     og   wd  ",
      " o     og   w   ",
      "oooooo\u0374o\u0375g.ggd  ",
      "            g   ",
      "            gd  ",
      "            g   ",
      "     g      \u0376d  ",
      "\u0377o   g          ",
      "\u037ao  \u037bg dddd 2   ",
      "\u037co  \u037dg k{   2   ",
      "\u0377o   g2222222   ",
      "\u037ao   g          ",
      "\u037coooooo         ",
      "      p         ",
      "      o         "
    ],
    [
      " o     og   w   ",
      " o     og   wd  ",
      " o     og   w   ",
      "ooooooo.gggggd  ",
      "        .\u037e\u037e\u0375g   ",
      "        \u037e\u037e\u0375 \u0376d  ",
      "         .\u037e g   ",
      "     g      gd  ",
      "[o   g          ",
      "\u037fo   gkdddd 2   ",
      "\u037fo   gk{    2   ",
      "\u037fo   g22222 2   ",
      "\u0384o   gn         ",
      "7ooooop         ",
      "\u0385\u0385\u0385\u0385\u0385\u0385o         ",
      "\u0385\u0385\u0385\u0385\u0385\u0385p         "
    ],
    [
      "\u0386\u0386\u0386\u0386\u0386\u0386\u0386\u0386b   b   ",
      "\u0386\u0386\u0386\u0386\u0386\u0386\u0386\u0386c   bd  ",
      "\u0386\u0386\u0386\u0386\u0386\u0386\u0386\u0375e   b   ",
      "\u0386\u0386\u0386\u0386\u0386\u0386.\u0375fbbbgd  ",
      "\u0386\u0386\u0386\u0386\u0386\u0375\u0386\u037e\u037e\u0387\u0374\u0376\u0375   ",
      "\u0386\u0386\u0386\u0386\u0386\u0386\u0388\u037e\u037e\u0389\u037e\u0386g\u038a  ",
      "\u0386\u0386\u0386\u0386\u0386\u0386\u037e\u0387\u037e\u037e.\u0386\u0376   ",
      "\u038c\u038c\u038c\u038c\u038cg.\u0386\u0375\u0387\u0386\u0386gd  ",
      "XXXXXgh\u038e\u038e \u038e\u038e2   ",
      "\u038fXXXXgjdddd 2   ",
      "\u038fXXXXgm     2   ",
      "\u038fXXXXg2222222   ",
      "XXXXXg          ",
      "XXXXXX\u0390         ",
      "XXXXXXp         ",
      "XXXXXXo         "
    ],
    [
      "\u0391\u0392 \u0393 \u0394 \u0395g   w   ",
      " \u0396    \u0397\u0398g   wd  ",
      "      \u0399 g   w   ",
      "     \u039a\u039b.gD\u039c\u039dgd  ",
      "   \u039e\u039f\u03a0.\u03a1\u039c \u037eK    ",
      "  \u03a3\u03a0\u0374 \u0386\u037e   \u0387M   ",
      "\u03a4   \u0393\u0386. \u03a1 \u037e\u03a5.   ",
      "w\u03a3 \u03a6wg\u03a7\u0386\u039c  \u039cg\u038a  ",
      "\u03a8    g\u039c\u03a9  \u03a9 i   ",
      "\u03aa\u03ab   g dddd l   ",
      "\u0387\u03ab   g      i   ",
      "\u03aa\u03ab   glililil   ",
      "\u03ac    g          ",
      "                ",
      "                ",
      "                "
    ],
    [
      "        g   w   ",
      "        g \u03ad wd  ",
      "        g   w   ",
      "     \u03ae \u039cgD \u03af.d  ",
      "      \u03b0   \u03a1     ",
      "      \u039c      \u038a  ",
      "     \u03b1          ",
      "w\u03b2 \u03b3wg \u03b4    .   ",
      "     g      2   ",
      "\u03b5    g ddd\u03b6     ",
      "     g      2   ",
      "\u03b7    g222 222   ",
      "     g          ",
      "                ",
      "                ",
      "                "
    ],
    [
      "        g   w   ",
      "        g \u03ad wd  ",
      "        g   w   ",
      "        gDDDgd  ",
      "            \u0388   ",
      "            \u0375d  ",
      "                ",
      "ww \u03b2wg      K   ",
      "     g          ",
      "     g dd\u03b6  2   ",
      "     g      2   ",
      "     g2222222   ",
      "     g          ",
      "                ",
      "                ",
      "                "
    ],
    [
      "        g   g   ",
      "        g \u03ad gd  ",
      "        g   g   ",
      "        gggg\u0376d  ",
      "            \u0375   ",
      "            \u03b4\u038a  ",
      "                ",
      "wwwwwg          ",
      "     g          ",
      "     g ddd      ",
      "     g          ",
      "     g22 22     ",
      "     g          ",
      "                ",
      "                ",
      "                "
    ],
    [
      "\u0386\u0386\u0386\u0386\u0386\u0386\u0386\u0386g\u03b8\u03b8\u03b8g\u038fX ",
      "\u0386\u0386\u0386\u0386\u0386\u0386\u0386\u0386g\u03b9\u03ba\u03bbg\u038fX ",
      "\u0386\u0386\u0386\u0386\u0386\u0386\u0386\u0386g\u03b8\u03b8\u03b8g\u038fX ",
      "\u0386\u0386\u0386\u0386\u0386\u0386\u0386\u0386ggggg\u038fX ",
      "\u0386\u0386\u0386\u0386\u0386\u0386\u03bc\u03bd \u0385\u03be  \u03bfX ",
      "\u0386\u0386\u0386\u0386\u0386\u03bc\u0385      \u038fX ",
      "\u0386\u0386\u0386\u0386\u0386\u0386\u0386\u03bd     \u03c0X ",
      "\u038c\u038c\u038c\u038c\u038c\u038c\u038c\u038c     \u03c0X ",
      "\u038f\u038f\u038f\u038f\u038fghhh    \u03c1X ",
      "XXXXXghhhh   \u038fX ",
      "     ghhhhkh\u038f\u038fX ",
      "     g\u038f\u038f\u038f\u038f\u038f\u038f\u038f\u038fX ",
      "     gXXXXXXXXX ",
      "                ",
      "                ",
      "                "
    ],
    [
      "\u039c\u039c\u039c\u039c\u039c\u039c\u039c\u039c\u039c\u039c\u03c2\u039c\u039c \u039c ",
      "\u039c\u039c\u039c\u039c\u039c\u039c\u039c\u03c2\u039c\u039c\u03c3\u039c\u039c \u039c ",
      "\u039c\u039c\u039c\u039c\u039c\u039c\u039c\u039c\u039c\u039c\u039c\u039c\u039c \u039c ",
      "\u039c\u039c\u039c\u039c\u03c2\u039c\u039c\u039c\u039c\u03c2\u039c\u03c2\u039c \u039c ",
      "\u039c\u039c\u039c\u039c\u039c\u039c\u039c\u039c\u039c\u039c  \u03c4 \u039c ",
      "\u039c\u039c\u039c\u039c\u039c\u039c\u039c\u03c2\u039c     \u03c2 ",
      "\u039c\u039c\u039c\u039c\u039c\u039c\u039c\u039c\u03c2\u03c5    \u03c2 ",
      "\u039c\u039c\u039c\u039c\u039c\u039c\u039c\u039c\u03c2\u039c    \u039c ",
      "     g\u039c\u039c\u039c\u03c5\u03c2\u03c5  \u03c2 ",
      "\u039c\u039c\u039c\u039c\u039cg\u039c\u039c\u039c\u039c\u039c \u03c2 \u039c ",
      "     g\u039c\u03c2\u039c\u039c\u039c\u03c2\u039c \u039c ",
      "     g        \u039c ",
      "     g\u039c\u039c\u039c\u03c2\u039c\u03c2\u03c2\u039c\u03c2 ",
      "                ",
      "                ",
      "                "
    ],
    [
      "                ",
      "                ",
      "                ",
      "                ",
      "                ",
      "                ",
      "                ",
      "                ",
      "     g          ",
      "     g          ",
      "     g          ",
      "     g          ",
      "     g          ",
      "                ",
      "                ",
      "                "
    ]
  ]
}