{
  "name": "multi_hospitaldamaged_4_ground",
  "refpalette": "deceasedcraft:multi_hospitaldamaged_4/multi_hospitaldamaged_4_ground_palette",
  "xsize": 16,
  "zsize": 16,
  "slices": [
    [
      "aaaaaaaab   ccde",
      "aaaaaaaaf   ccge",
      "aaaaaaaah   cced",
      "aaaaaaaaicccjceg",
      "aaaaaaaaaaaaccge",
      "aaaaaaaaaaaaccge",
      "aaaaaaaaaaaaccge",
      "aaaaajaaaaaajcee",
      "ccaaajkkkkkkcced",
      "ccaaajlmmmmnccee",
      "ccaaajo     cceg",
      "ccaaajccccccccge",
      "aaaaajccccccccee",
      "aaaaacppppppppee",
      "aaaaacppppppppee",
      "aaaaacppppppppee"
    ],
    [
      "qr sqtuwj   x y ",
      "ABBBABCDj   xm  ",
      "BBBBEBFDj   x  I",
      "ABBBJBuKjLMNjm O",
      "PQ   RSTU   V   ",
      "W       I  SVmI ",
      "     X   Y  VZ  ",
      "     j      jm01",
      "234 5j     o6 7y",
      "  4 5j mmmm86 09",
      "  4 5j    nn6#$ ",
      "%^4 5j66 6666s1&",
      "334 *j  Q 9   &&",
      "(S   )+W    Q 7 ",
      " -4[])+         ",
      "{}4 |)+       0 "
    ],
    [
      ";::   Q'j   x   ",
      " <>,.E?/j   xm  ",
      "` <\u0370\u0371\u0372 /j   x   ",
      "  \u0373k\u0374.?/jL\u0375\u0376jm  ",
      "\u0377\u037a\u0377\u037b        6   ",
      "            6m  ",
      "     \u037c      6   ",
      "     j      j\u037d  ",
      "\u037e34  j      6   ",
      " \u037f4  j mmmm     ",
      " \u037f4  j   n\u0384o6   ",
      "  4  j6  6666   ",
      "334  j          ",
      "     *+         ",
      "  4  0+         ",
      " \u03854  0+         "
    ],
    [
      "\u0386\u0386     /j   x   ",
      "   \u0387\u0388s  j   xm  ",
      "       \u0389j   x   ",
      "   \u0387\u0388\u038a /jLLLjm  ",
      "\u038c\u038c\u038c\u038c\u038e  \u038f    j   ",
      "            jm  ",
      "            j   ",
      "\u0390    j      jm  ",
      "\u039134  j      6   ",
      "  4 \u0392j mmmm 6   ",
      "  4 \u0393j  n\u0384  6   ",
      "  4  j6666666   ",
      "334  j          ",
      "  V   +         ",
      "  4   +         ",
      "  4   +         "
    ],
    [
      ":   \u0394  \u0395j   x   ",
      "   k\u0396   j   xm  ",
      "  \u0397\u0398\u0399   j   x   ",
      "   k\u039a   jjjjjm  ",
      "\u037a\u0377\u0377\u0377  \u039b\u039c    j   ",
      "            jm  ",
      "            j   ",
      "     j      jm  ",
      "334\u039d j      6   ",
      "  4  j mmmm 6   ",
      "  4  j n\u0384   6   ",
      " \u039e4  j6666 66   ",
      "334\u039f j          ",
      "  4  \u03a0+         ",
      "  4  \u03a0+         ",
      "  4  \u03a0+         "
    ],
    [
      "\u03a1\u03a3\u03a3\u03a3\u03a3\u03a3\u03a3\u03a3j   x   ",
      "\u0397\u03a1\u03a1\u0397\u03a3\u03a3\u03a3\u03a3j   xm  ",
      "\u03a1\u0397\u0397\u0397\u03a1\u03a3\u03a3\u03a3j   x   ",
      "\u0397\u0397\u03a1\u03a1\u0397\u03a1\u03a3\u03a3jjjjjm  ",
      "\u03a3\u03a1\u03a1\u0397\u0397\u03a3\u03a3\u03a3\u03a3\u03a3\u03a3\u03a3j   ",
      "\u03a3\u03a3\u03a3\u03a4\u03a3\u03a3\u03a3\u03a3\u03a3\u03a3\u03a3\u03a3jm  ",
      "\u03a3\u03a3\u03a3\u03a3\u03a3\u03a3\u03a3\u03a3\u03a3\u03a3\u03a3\u03a3j   ",
      "\u03a3\u03a3\u03a3\u03a3\u03a3j\u0397\u0397\u0397\u0397\u0397\u0397jm  ",
      "\u03a3\u03a3\u03a3\u03a3\u03a3j          ",
      "\u03a3\u03a3\u03a3\u03a3\u03a3jnmmmm 6   ",
      "\u03a3\u03a3\u03a3\u03a3\u03a3jn\u0384    6   ",
      "\u03a5\u03a6\u03a3\u03a3\u03a3j6666666   ",
      "\u03a3\u03a3\u03a3\u03a3\u03a3j          ",
      "\u03a3\u03a3\u03a3\u03a3\u03a3\u03a3`         ",
      "\u03a3\u03a3\u03a3\u03a3\u03a3\u03a3`         ",
      "\u03a3\u03a3\u03a3\u03a3\u03a3\u03a3`         "
    ]
  ]
}