{
  "name": "multi_residentiale_0_ground",
  "refpalette": "deceasedcraft:multi_residentiale_0/multi_residentiale_0_ground_palette",
  "xsize": 16,
  "zsize": 16,
  "slices": [
    [
      "aaaaabaaaaabbaaa",
      "abbbbbbbbbbbbbbb",
      "abbbbbbbbbbbbbbb",
      "abbbbbbbbbbbbbbb",
      "abccccccccccccbb",
      "abcddddddddddcbb",
      "abcddddddddddcbb",
      "abcddddddddddcbb",
      "aacddddddddddcbb",
      "aacddddddddddcbb",
      "abcddddddddddcbb",
      "abbeffffffffebbb",
      "abbeffffffffebbb",
      "abbeffffffffebbb",
      "bbbeffffffffebbb",
      "bbbeffffffffebbb"
    ],
    [
      "                ",
      "               g",
      "               g",
      "               g",
      "  hijkllllkjim g",
      "  no   pq   rs g",
      "  nt  u      s g",
      " wj       xyxj g",
      "  A   BCCDE  s g",
      "  F   kkkkEIJs g",
      "  j    K!LMMMj g",
      "  ge  NOOPQReg g",
      "  geS  TT  Ueg g",
      "  geV S    Weg g",
      "  geXV     Yeg g",
      "  geZZZ01ZZZeg g"
    ],
    [
      "                ",
      "                ",
      "                ",
      "                ",
      "  lljkllllkjll  ",
      "  l23       4l  ",
      "  l          l  ",
      "  j       x5xj  ",
      "  6    7 8E  9  ",
      "  #   $$$$E  9  ",
      "  j     K%MMMj  ",
      "   e       ^e   ",
      "   &        &   ",
      "   e       *e   ",
      "   e(S     )e   ",
      "   eZZZ+-ZZZe   "
    ],
    [
      "                ",
      "                ",
      "                ",
      "                ",
      "  lljkllllkjll  ",
      "  l          l  ",
      "  l     [    l  ",
      "  j       xxxj  ",
      "  n       E  9  ",
      "  n   $$$$E  9  ",
      "  j      KMMMj  ",
      "   e        e   ",
      "   &    [   &   ",
      "   e        e   ",
      " iie        eii ",
      " ]{eZZZ}}ZZZe|] "
    ],
    [
      "                ",
      "                ",
      "                ",
      " ;;;;;;;;;;;;;; ",
      " :jjjjjjjjjjjj: ",
      "  jddddddddddj  ",
      "  jddddddddddj  ",
      "  jddddddddddj  ",
      "  jddddddddddj  ",
      "  jddddddddddj  ",
      "  jdddd   Kddj  ",
      "   edddddddde   ",
      "   edddddddde   ",
      " iieddddddddeii ",
      " ]]{dddddddd|]] ",
      "   'dddddddd<   "
    ],
    [
      "                ",
      "                ",
      "                ",
      "                ",
      " ;;;;;;;;;;;;;; ",
      " :jkkkkkkkkkkj: ",
      "  j>,,.r?/`r j  ",
      "  j \u0370\u0370.      j  ",
      "  n \u0371\u0371       s  ",
      "  n    \u0372\u0372\u0372\u0372  s  ",
      "  j\u0373\u0374  \u0375    \u0376j  ",
      "   ekk\u0377k..kke   ",
      " iiekk   \u037a\u037bkeii ",
      " ]]]{\u037b\u037c  \u037d\u037b|]]] ",
      "    '\u037b\u037c\u037e !\u037b<    ",
      "    '\u037b\u037f  \u0384\u037b<    "
    ]
  ]
}