{
  "name": "multi_residentiale_0_floor1",
  "refpalette": "deceasedcraft:multi_residentiale_0/multi_residentiale_0_floor1_palette",
  "xsize": 16,
  "zsize": 16,
  "slices": [
    [
      "                ",
      "                ",
      "                ",
      "                ",
      "                ",
      " aaaaaaaaaaaaaa ",
      " bc   defghe cb ",
      "  ci  d      c  ",
      "  j          j  ",
      "  j          j  ",
      "  ckl       mc  ",
      " nnoppqpddpponn ",
      " rrrrs t  urrrr ",
      "     w    x     ",
      "     w    x     ",
      "     wy   x     "
    ],
    [
      "                ",
      "                ",
      "                ",
      "                ",
      "                ",
      "                ",
      " aaaaaaaaaaaaaa ",
      " bc   d      cb ",
      "  cA        Bc  ",
      "  cA        Bc  ",
      " nckC       Dcn ",
      " rrrrrsppurrrrr ",
      "      w  x      ",
      "      wE x      ",
      "      w  x      ",
      "      w  x      "
    ],
    [
      "                ",
      "                ",
      "                ",
      "                ",
      "                ",
      "                ",
      "                ",
      " aaaaaaaaaaaaaa ",
      " bcF  E  I  Jcb ",
      " ncF         cn ",
      " rrrrrrsurrrrrr ",
      "       wx       ",
      "       wx       ",
      "       wx       ",
      "       wx       ",
      "       wx       "
    ],
    [
      "                ",
      "                ",
      "                ",
      "                ",
      "                ",
      "                ",
      "                ",
      "                ",
      " aaaaaaaaaaaaaa ",
      " rrrrrrrrrrrrrr ",
      "                ",
      "                ",
      "                ",
      "                ",
      "                ",
      "                "
    ],
    [
      "                ",
      "                ",
      "                ",
      "                ",
      "                ",
      "                ",
      "                ",
      "                ",
      "                ",
      "                ",
      "                ",
      "                ",
      "                ",
      "                ",
      "                ",
      "                "
    ],
    [
      "                ",
      "                ",
      "                ",
      "                ",
      "                ",
      "                ",
      "                ",
      "                ",
      "                ",
      "       ~        ",
      "                ",
      "                ",
      "                ",
      "                ",
      "                ",
      "                "
    ]
  ]
}