{
  "name": "multi_timbertower_7_floor6",
  "refpalette": "deceasedcraft:multi_timbertower_7/multi_timbertower_7_floor6_palette",
  "xsize": 16,
  "zsize": 16,
  "slices": [
    [
      "aaabc           ",
      "aaabd           ",
      "aaabd           ",
      "aaabd           ",
      "eefghi          ",
      "eeabc           ",
      "eeabc           ",
      "eeabc           ",
      "eeabd           ",
      "eeabd           ",
      "eeabd           ",
      "eefghi          ",
      "aaabc           ",
      "aaabc           ",
      "aaabc           ",
      "aaabd           "
    ],
    [
      "jkl c           ",
      " kl d           ",
      " ml d           ",
      "nnl d           ",
      "oof i           ",
      "ppl c           ",
      " ql c           ",
      "ppl c           ",
      " ql d           ",
      "ppl d           ",
      " ql d           ",
      "oof i           ",
      "rsl c           ",
      "  l c           ",
      "  l c           ",
      "t l d           "
    ],
    [
      " kl c           ",
      " ml d           ",
      " ul d           ",
      "nnl d           ",
      "oof i           ",
      "ppl c           ",
      "  l c           ",
      "ppl c           ",
      "  l d           ",
      "ppl d           ",
      "  l d           ",
      "oof i           ",
      " wl c           ",
      "  x c           ",
      "  x c           ",
      "  x d           "
    ],
    [
      " jl c           ",
      " ml d           ",
      "  l d           ",
      " nl d           ",
      "oof i           ",
      "ppl c           ",
      "  l c           ",
      "ppl c           ",
      "  l d           ",
      "ppl d           ",
      "  l d           ",
      "oof i           ",
      " yl c           ",
      "  A c           ",
      "  A c           ",
      "  A d           "
    ],
    [
      "BBl c           ",
      "BBl d           ",
      "CBl d           ",
      "BBl d           ",
      "oof i           ",
      "DDl c           ",
      "DEl c           ",
      "DDl c           ",
      "DEl d           ",
      "DDl d           ",
      "DEl d           ",
      "oof i           ",
      "  l c           ",
      "  l c           ",
      "  l c           ",
      "  l d           "
    ],
    [
      " FI c           ",
      "jFI d           ",
      "JFI d           ",
      "jFI d           ",
      "KKfhi           ",
      "jFI c           ",
      "FFI c           ",
      "jFI c           ",
      "FFI d           ",
      " FI d           ",
      "FFI d           ",
      "KKfhi           ",
      "BBI c           ",
      "LBI c           ",
      "BBI c           ",
      "BBI d           "
    ]
  ]
}