{
  "name": "multi_timbertower_7_floor8",
  "refpalette": "deceasedcraft:multi_timbertower_7/multi_timbertower_7_floor8_palette",
  "xsize": 16,
  "zsize": 16,
  "slices": [
    [
      "aabcd           ",
      "aabce           ",
      "aabce           ",
      "aabce           ",
      "aafgh           ",
      "aabcd           ",
      "aabcd           ",
      "aabcd           ",
      "aabce           ",
      "aabce           ",
      "aabce           ",
      "aafgh           ",
      "aabcd           ",
      "aabcd           ",
      "aabcd           ",
      "aabce           "
    ],
    [
      "  i             ",
      "  i             ",
      "  i e           ",
      "  i e           ",
      " jfgh           ",
      " ji             ",
      "  i d           ",
      "  i d           ",
      "  i e           ",
      "  i e           ",
      "j i             ",
      "jjfgh           ",
      " ki d           ",
      " ki d           ",
      "  i             ",
      "  i             "
    ],
    [
      "                ",
      "                ",
      "    e           ",
      "    e           ",
      " kfgh           ",
      " k              ",
      "    d           ",
      "    d           ",
      "    e           ",
      "    e           ",
      "                ",
      " kfgh           ",
      " k  d           ",
      "    d           ",
      "                ",
      "                "
    ],
    [
      "                ",
      "                ",
      "    e           ",
      "                ",
      " kfgh           ",
      "                ",
      "    d           ",
      "                ",
      "                ",
      "    e           ",
      " k              ",
      "  fgh           ",
      "                ",
      "    d           ",
      "                ",
      " k              "
    ],
    [
      "  i             ",
      "j i             ",
      "  i e           ",
      "  i             ",
      "  fgh           ",
      "  i             ",
      "  i d           ",
      "  i             ",
      "  i             ",
      "  i e           ",
      " ki             ",
      " kfgh           ",
      "  i             ",
      " ki d           ",
      "  i             ",
      " ki             "
    ],
    [
      "  l             ",
      "  l             ",
      "  l e           ",
      "  l             ",
      "mmfgh           ",
      "  l             ",
      "  l d           ",
      "  l             ",
      "  l             ",
      "  l e           ",
      " jl             ",
      "mmfgh           ",
      " jl             ",
      " kl d           ",
      " jl             ",
      " kl             "
    ]
  ]
}