{
  "name": "multi_timbertower_7_floor10",
  "refpalette": "deceasedcraft:multi_timbertower_7/multi_timbertower_7_floor10_palette",
  "xsize": 16,
  "zsize": 16,
  "slices": [
    [
      "aaab            ",
      "aaac            ",
      "aaa c           ",
      "aaac            ",
      "ddefg           ",
      "ddab            ",
      "dda b           ",
      "ddab            ",
      "ddac            ",
      "dda c           ",
      "ddac            ",
      "ddefg           ",
      "aaab            ",
      "aaa b           ",
      "aaab            ",
      "aaac            "
    ],
    [
      "  hb            ",
      "  hc            ",
      "  h             ",
      "ijhc            ",
      "kke g           ",
      "llhb            ",
      " mh             ",
      "llhb            ",
      " mhc            ",
      "llh             ",
      " mhc            ",
      "kkefg           ",
      "nohb            ",
      "  h             ",
      "  hb            ",
      " phc            "
    ],
    [
      "  qb            ",
      "  qc            ",
      "  q             ",
      " rhc            ",
      "kke g           ",
      "llhb            ",
      "  h             ",
      "llhb            ",
      "  hc            ",
      "llh             ",
      "  hc            ",
      "kkefg           ",
      "  hb            ",
      "  q             ",
      "  qb            ",
      "  qc            "
    ],
    [
      "  sb            ",
      "  sc            ",
      "  s             ",
      " thc            ",
      "kke g           ",
      "llhb            ",
      "  h             ",
      "llhb            ",
      "  hc            ",
      "llh             ",
      "  hc            ",
      "kkefg           ",
      "  hb            ",
      "  s             ",
      "  sb            ",
      "  sc            "
    ],
    [
      "uuhb            ",
      "uuhc            ",
      "wuh             ",
      "uuhc            ",
      "kke g           ",
      "xxhb            ",
      "x!h             ",
      "xxhb            ",
      "xyhc            ",
      "xxh             ",
      "xyhc            ",
      "kkefg           ",
      "uuhb            ",
      "wuh             ",
      "uuhb            ",
      "uuhc            "
    ],
    [
      "ABCb            ",
      "DBCc            ",
      "EBCc            ",
      " BCc            ",
      "FFefg           ",
      "DBCb            ",
      "BBCb            ",
      "DBCb            ",
      "BBCc            ",
      " BCc            ",
      "BBCc            ",
      "FFefg           ",
      "DBCb            ",
      "EBCb            ",
      " BCb            ",
      "DBCc            "
    ]
  ]
}