{
  "name": "multi_timbertower_7_floor13",
  "refpalette": "deceasedcraft:multi_timbertower_7/multi_timbertower_7_floor13_palette",
  "xsize": 16,
  "zsize": 16,
  "slices": [
    [
      "aaab            ",
      "aaac            ",
      "aaac            ",
      "aaac            ",
      "aadef           ",
      "aaab            ",
      "aaab            ",
      "aaab            ",
      "aaac            ",
      "aaac            ",
      "aaac            ",
      "aadef           ",
      "aaab            ",
      "aaab            ",
      "aaab            ",
      "aaac            "
    ],
    [
      "ghib            ",
      "jkic            ",
      "lkic            ",
      "lkic            ",
      "lkdef           ",
      "lkib            ",
      "mnib            ",
      "opib            ",
      "qric            ",
      "mnic            ",
      "lkic            ",
      "lkdef           ",
      "lkib            ",
      "lkib            ",
      " kib            ",
      "hhic            "
    ],
    [
      "stib            ",
      "uwic            ",
      "  ic            ",
      "  ic            ",
      "  def           ",
      "  ib            ",
      "  ib            ",
      "xyib            ",
      "ABic            ",
      "  ic            ",
      "  ic            ",
      "  def           ",
      "  ib            ",
      "  ib            ",
      "  ib            ",
      "  ic            "
    ],
    [
      " CDb            ",
      " CDc            ",
      " CDc            ",
      " CDc            ",
      "ECdef           ",
      "ECDb            ",
      "ECDb            ",
      "ECDb            ",
      "ECDc            ",
      "ECDc            ",
      "ECDc            ",
      "ECdef           ",
      "ECDb            ",
      "ECDb            ",
      "ECDb            ",
      "ECDc            "
    ],
    [
      "FC b            ",
      " C c            ",
      "  Ic            ",
      " C c            ",
      "JCdef           ",
      "KC b            ",
      "K Ib            ",
      "KC b            ",
      "KC c            ",
      "K Ic            ",
      "KC c            ",
      "KCdef           ",
      "KC b            ",
      "K Ib            ",
      "KC b            ",
      "KC c            "
    ],
    [
      "CC              ",
      "CC              ",
      "CC              ",
      "JC              ",
      "KCd             ",
      "KC              ",
      "KC              ",
      "KC              ",
      "KC              ",
      "KC              ",
      "KC              ",
      "KCd             ",
      "KC              ",
      "KC              ",
      "KC              ",
      "KC              "
    ]
  ]
}