{
  "name": "multi_timbertower_7_floor12",
  "refpalette": "deceasedcraft:multi_timbertower_7/multi_timbertower_7_floor12_palette",
  "xsize": 16,
  "zsize": 16,
  "slices": [
    [
      "aaab            ",
      "aaac            ",
      "aaac            ",
      "aaac            ",
      "aadef           ",
      "aaab            ",
      "ggab            ",
      "ggab            ",
      "ggac            ",
      "ggac            ",
      "aaac            ",
      "aadef           ",
      "aaab            ",
      "aaab            ",
      "aaab            ",
      "aaac            "
    ],
    [
      "hijb            ",
      "  jc            ",
      "kkjc            ",
      "lmjc            ",
      "nedef           ",
      "nojb            ",
      "ppjb            ",
      "  jb            ",
      "  jc            ",
      "qqjc            ",
      "nojc            ",
      "nedef           ",
      "lmjb            ",
      "rrjb            ",
      " sjb            ",
      " ijc            "
    ],
    [
      "  jb            ",
      "  jc            ",
      "kkjc            ",
      " tjc            ",
      "nudef           ",
      "wojb            ",
      "ppjb            ",
      "  xb            ",
      "  xc            ",
      "qqjc            ",
      "n!jc            ",
      "nudef           ",
      "  jb            ",
      "rrjb            ",
      "  jb            ",
      " yjc            "
    ],
    [
      "  jb            ",
      "  jc            ",
      "kkjc            ",
      "  jc            ",
      " odef           ",
      " ojb            ",
      "ppjb            ",
      "  Ab            ",
      "  Ac            ",
      "qqjc            ",
      "Bojc            ",
      " odef           ",
      "  jb            ",
      "rrjb            ",
      "  jb            ",
      "  jc            "
    ],
    [
      "  jb            ",
      " Bjc            ",
      "kkjc            ",
      " Bjc            ",
      " odef           ",
      "Bojb            ",
      "ppjb            ",
      "  jb            ",
      "  jc            ",
      "qqjc            ",
      "Bojc            ",
      "Bodef           ",
      " Bjb            ",
      "rrjb            ",
      "  jb            ",
      "  jc            "
    ],
    [
      "  Cb            ",
      " BCc            ",
      "aaCc            ",
      "aaCc            ",
      "DDdef           ",
      "aaCb            ",
      "EECb            ",
      "FFCb            ",
      "FFCc            ",
      "IICc            ",
      "aaCc            ",
      "DDdef           ",
      "aaCb            ",
      "aaCb            ",
      "  Cb            ",
      "  Cc            "
    ]
  ]
}