{
  "name": "multi_timbertower_7_floor11",
  "refpalette": "deceasedcraft:multi_timbertower_7/multi_timbertower_7_floor11_palette",
  "xsize": 16,
  "zsize": 16,
  "slices": [
    [
      "aaab            ",
      "aaac            ",
      "aaac            ",
      "aaac            ",
      "aadef           ",
      "aaab            ",
      "ggab            ",
      "ggab            ",
      "ggac            ",
      "ggac            ",
      "aaac            ",
      "aadef           ",
      "aaab            ",
      "aaab            ",
      "aaab            ",
      "aaac            "
    ],
    [
      "hijb            ",
      "  jc            ",
      "kkjc            ",
      "lmjc            ",
      "nedef           ",
      "nojb            ",
      "ppjb            ",
      "  jb            ",
      "  jc            ",
      "qqjc            ",
      "nojc            ",
      "nedef           ",
      "lmjb            ",
      "rrjb            ",
      " sjb            ",
      " ijc            "
    ],
    [
      " tjb            ",
      "  jc            ",
      "kkjc            ",
      "  jc            ",
      "nudef           ",
      "n!jb            ",
      "ppjb            ",
      "  wb            ",
      "  wc            ",
      "qqjc            ",
      "nxjc            ",
      "nudef           ",
      "  jb            ",
      "rrjb            ",
      "  jb            ",
      " yjc            "
    ],
    [
      "  jb            ",
      "  jc            ",
      "kkjc            ",
      " Ajc            ",
      " odef           ",
      " ojb            ",
      "ppjb            ",
      "  Bb            ",
      "  Bc            ",
      "qqjc            ",
      " ojc            ",
      " odef           ",
      "  jb            ",
      "rrjb            ",
      "  jb            ",
      "  jc            "
    ],
    [
      "  jb            ",
      " Ajc            ",
      "kkjc            ",
      "AAjc            ",
      " odef           ",
      "Aojb            ",
      "ppjb            ",
      "  jb            ",
      "  jc            ",
      "qqjc            ",
      "Aojc            ",
      " odef           ",
      "  jb            ",
      "rrjb            ",
      "  jb            ",
      "  jc            "
    ],
    [
      "  Cb            ",
      " ACc            ",
      "aaCc            ",
      "aaCc            ",
      "DDdef           ",
      "aaCb            ",
      "EECb            ",
      "FFCb            ",
      "FFCc            ",
      "IICc            ",
      "aaCc            ",
      "DDdef           ",
      "aaCb            ",
      "aaCb            ",
      "  Cb            ",
      "  Cc            "
    ]
  ]
}