{
  "name": "multi_timbertower_7_floor4",
  "refpalette": "deceasedcraft:multi_timbertower_7/multi_timbertower_7_floor4_palette",
  "xsize": 16,
  "zsize": 16,
  "slices": [
    [
      "aaabc           ",
      "aaabd           ",
      "aaabd           ",
      "aaabd           ",
      "eefghi          ",
      "eeabc           ",
      "eeabc           ",
      "eeabc           ",
      "eeabd           ",
      "eeabd           ",
      "eeabd           ",
      "eefghi          ",
      "aaabc           ",
      "aaabc           ",
      "aaabc           ",
      "aaabd           "
    ],
    [
      "jkl c           ",
      "m l d           ",
      "nol d           ",
      "p!l d           ",
      "qqf hi          ",
      "rrl c           ",
      " sl c           ",
      "rrl c           ",
      " sl d           ",
      "rrl d           ",
      " sl d           ",
      "qqf hi          ",
      "tul c           ",
      "  l c           ",
      "w l c           ",
      "  l d           "
    ],
    [
      "x y c           ",
      "A y d           ",
      "B y d           ",
      "CDl d           ",
      "qqf hi          ",
      "rrl c           ",
      "  l c           ",
      "rrl c           ",
      "  l d           ",
      "rrl d           ",
      "  l d           ",
      "qqf hi          ",
      "  l c           ",
      "  y c           ",
      "  y c           ",
      "  y d           "
    ],
    [
      "  E c           ",
      "  E d           ",
      "  E d           ",
      "C l d           ",
      "qqf hi          ",
      "rrl c           ",
      "  l c           ",
      "rrl c           ",
      "  l d           ",
      "rrl d           ",
      "  l d           ",
      "qqf hi          ",
      "  l c           ",
      "  E c           ",
      "  E c           ",
      "  E d           "
    ],
    [
      "FFl c           ",
      "FFl d           ",
      "IFl d           ",
      "FFl d           ",
      "qqf hi          ",
      "JJl c           ",
      "JKl c           ",
      "JJl c           ",
      "JKl d           ",
      "JJl d           ",
      "JKl d           ",
      "qqf hi          ",
      "FFl c           ",
      "FFl c           ",
      "FFl c           ",
      "FFl d           "
    ],
    [
      " LM c           ",
      "DLM d           ",
      " LM d           ",
      " LM d           ",
      "NNfOhi          ",
      "DLM c           ",
      "LLM c           ",
      "DLM c           ",
      "LLM d           ",
      " LM d           ",
      "LLM d           ",
      "NNfOhi          ",
      "DLM c           ",
      " LM c           ",
      " LM c           ",
      "DLM d           "
    ]
  ]
}