{
  "name": "multi_timbertower_7_floor7",
  "refpalette": "deceasedcraft:multi_timbertower_7/multi_timbertower_7_floor7_palette",
  "xsize": 16,
  "zsize": 16,
  "slices": [
    [
      "==abc           ",
      "==abd           ",
      "==abd           ",
      "==abd           ",
      "==efg           ",
      "==abc           ",
      "==abc           ",
      "==abc           ",
      "==abd           ",
      "==abd           ",
      "==abd           ",
      "==efg           ",
      "==abc           ",
      "==abc           ",
      "==abc           ",
      "==abd           "
    ],
    [
      "zzh c           ",
      "iih d           ",
      "jjh d           ",
      " jh d           ",
      " jefg           ",
      " kh c           ",
      " lh c           ",
      "mnh c           ",
      " oh d           ",
      "kph d           ",
      " ph d           ",
      " eefg           ",
      "qrh c           ",
      "sth c           ",
      "uwh c           ",
      "sxh d           "
    ],
    [
      "yyh c           ",
      " Ah d           ",
      "  h d           ",
      " jh d           ",
      " Befg           ",
      " Ch c           ",
      " Dh c           ",
      " Eh c           ",
      " Fh d           ",
      " Ih d           ",
      " Ih d           ",
      " eefg           ",
      " rh c           ",
      "JKh c           ",
      " sh c           ",
      "Lxh d           "
    ],
    [
      "  h c           ",
      "  h d           ",
      "  h d           ",
      "  h d           ",
      "BBefg           ",
      " Mh c           ",
      " Nh c           ",
      "  h c           ",
      "  h d           ",
      " Ih d           ",
      " Oh d           ",
      " eefg           ",
      "Prh c           ",
      " Ph c           ",
      " Lh c           ",
      " sh d           "
    ],
    [
      "  h c           ",
      "  h d           ",
      "  h d           ",
      " jh d           ",
      "QQefg           ",
      "  h c           ",
      "  h c           ",
      "  h c           ",
      " rh d           ",
      " rh d           ",
      " rh d           ",
      "reefg           ",
      "rrh c           ",
      "Prh c           ",
      "Prh c           ",
      "rrh d           "
    ],
    [
      "RRS c           ",
      "RRS d           ",
      "RRS d           ",
      "RRS d           ",
      "TTefg           ",
      "rrS c           ",
      "rrS c           ",
      "rrS c           ",
      "rrS d           ",
      "rrS d           ",
      "rrS d           ",
      "reefg           ",
      "rrS c           ",
      "rrS c           ",
      "rrS c           ",
      "rrS d           "
    ]
  ]
}