{
  "name": "multi_timbertower_7_floor3",
  "refpalette": "deceasedcraft:multi_timbertower_7/multi_timbertower_7_floor3_palette",
  "xsize": 16,
  "zsize": 16,
  "slices": [
    [
      "aaabc           ",
      "aaabd           ",
      "aaabd           ",
      "aaabd           ",
      "eefghi          ",
      "eeabc           ",
      "eeabc           ",
      "eeabc           ",
      "eeabd           ",
      "eeabd           ",
      "eeabd           ",
      "eefghi          ",
      "aaabc           ",
      "aaabc           ",
      "aaabc           ",
      "aaabd           "
    ],
    [
      "jkl c           ",
      "mnl d           ",
      "opl d           ",
      "qrl d           ",
      "ssf hi          ",
      "ttl c           ",
      " ul c           ",
      "ttl c           ",
      " ul d           ",
      "ttl d           ",
      " ul d           ",
      "ssf hi          ",
      " wl c           ",
      " xl c           ",
      "y l c           ",
      "  l d           "
    ],
    [
      "  A c           ",
      "B A d           ",
      "  A d           ",
      "CDl d           ",
      "ssf hi          ",
      "ttl c           ",
      "  l c           ",
      "ttl c           ",
      "  l d           ",
      "ttl d           ",
      "  l d           ",
      "ssf hi          ",
      "  l c           ",
      "  A c           ",
      "  A c           ",
      "  A d           "
    ],
    [
      "  E c           ",
      "  E d           ",
      "  E d           ",
      "C l d           ",
      "ssf hi          ",
      "ttl c           ",
      "  l c           ",
      "ttl c           ",
      "  l d           ",
      "ttl d           ",
      "  l d           ",
      "ssf hi          ",
      "  l c           ",
      "  E c           ",
      "  E c           ",
      "  E d           "
    ],
    [
      "FFl c           ",
      "FFl d           ",
      "IFl d           ",
      "FFl d           ",
      "ssf hi          ",
      "JJl c           ",
      "J!l c           ",
      "JJl c           ",
      "JKl d           ",
      "JJl d           ",
      "JKl d           ",
      "ssf hi          ",
      "FFl c           ",
      "FFl c           ",
      "FFl c           ",
      "FFl d           "
    ],
    [
      " LM c           ",
      "NLM d           ",
      "OLM d           ",
      " LM d           ",
      "PPfQhi          ",
      "NLM c           ",
      "LLM c           ",
      "NLM c           ",
      "LLM d           ",
      " LM d           ",
      "LLM d           ",
      "PPfQhi          ",
      "NLM c           ",
      " LM c           ",
      " LM c           ",
      "NLM d           "
    ]
  ]
}