{
  "name": "multi_timbertower_7_floor5",
  "refpalette": "deceasedcraft:multi_timbertower_7/multi_timbertower_7_floor5_palette",
  "xsize": 16,
  "zsize": 16,
  "slices": [
    [
      "aaabc           ",
      "aaabd           ",
      "aaabd           ",
      "aaabd           ",
      "eefghi          ",
      "eeabc           ",
      "eeabc           ",
      "eeabc           ",
      "eeabd           ",
      "eeabd           ",
      "eeabd           ",
      "eefghi          ",
      "aaabc           ",
      "aaabc           ",
      "aaabc           ",
      "aaabd           "
    ],
    [
      "jkl c           ",
      "m l d           ",
      "n l d           ",
      "!ol d           ",
      "ppf hi          ",
      "qql c           ",
      " rl c           ",
      "qql c           ",
      " rl d           ",
      "qql d           ",
      " rl d           ",
      "ppf hi          ",
      "s!l c           ",
      " tl c           ",
      " ul c           ",
      "  l d           "
    ],
    [
      "w x c           ",
      "y x d           ",
      "A x d           ",
      "BCl d           ",
      "ppf hi          ",
      "qql c           ",
      "  l c           ",
      "qql c           ",
      "  l d           ",
      "qql d           ",
      "  l d           ",
      "ppf hi          ",
      " Dl c           ",
      "  x c           ",
      "  x c           ",
      "  x d           "
    ],
    [
      "  E c           ",
      "  E d           ",
      "  E d           ",
      "B l d           ",
      "ppf hi          ",
      "qql c           ",
      "  l c           ",
      "qql c           ",
      "  l d           ",
      "qql d           ",
      "  l d           ",
      "ppf hi          ",
      "  l c           ",
      "  E c           ",
      "  E c           ",
      "  E d           "
    ],
    [
      "FFl c           ",
      "FFl d           ",
      "IFl d           ",
      "FFl d           ",
      "ppf hi          ",
      "JJl c           ",
      "JKl c           ",
      "JJl c           ",
      "JKl d           ",
      "JJl d           ",
      "JKl d           ",
      "ppf hi          ",
      "FFl c           ",
      "FFl c           ",
      "FFl c           ",
      "FFl d           "
    ],
    [
      " LM c           ",
      "sLM d           ",
      " LM d           ",
      " LM d           ",
      "NNfOhi          ",
      "sLM c           ",
      "LLM c           ",
      "sLM c           ",
      "LLM d           ",
      " LM d           ",
      "LLM d           ",
      "NNfOhi          ",
      "sLM c           ",
      " LM c           ",
      " LM c           ",
      "sLM d           "
    ]
  ]
}