{
  "name": "multi_timbertower_7_ground",
  "refpalette": "deceasedcraft:multi_timbertower_7/multi_timbertower_7_ground_palette",
  "xsize": 16,
  "zsize": 16,
  "slices": [
    [
      "vvvvaaaaabbbbccc",
      "vvvvaaaaabbbbccc",
      "vvvvaaaaabbbbccc",
      "vvvvaaaaabbbbccc",
      "vvdvaaaaabbbbccc",
      "vvvaaaaaabbbbccc",
      "   eaaaaabbbbccc",
      "   vaaaaabbbbccc",
      "   vaaaaabbbbccc",
      "   faaaaabbbbccc",
      "vvvaaaaaabbbbccc",
      "vvdvaaaaabbbbccc",
      "vvvvaaaaabbbbccc",
      "vvvvaaaaabbbbccc",
      "vvvvaaaaabbbbccc",
      "vvvvaaaaabbbbccc"
    ],
    [
      "bbdaabbbb       ",
      "bbdaabbbb       ",
      "bbdaabbbb       ",
      "bbdaabbbb       ",
      "bbdaabbbb       ",
      "vvdaabbbb       ",
      " gdaabbbbh      ",
      " gdaabbbbh      ",
      " gdaabbbbh      ",
      " gdaabbbbh      ",
      "vvdaabbbb       ",
      "dddaabbbb       ",
      "igdaabbbb       ",
      "igdaabbbb       ",
      "igdaabbbb       ",
      "igdaabbbb       "
    ],
    [
      "bbbbb           ",
      "bbbbb           ",
      "bbbbb           ",
      "bbbbb           ",
      "bbdbb           ",
      "vbbbb           ",
      "jjbbbh          ",
      "jjbbbh          ",
      "jjbbbh          ",
      "jjbbbh          ",
      "vbbbb           ",
      "jbdbb           ",
      "jbbbb           ",
      "jbbbb           ",
      "jbbbb           ",
      "jbbbb           "
    ],
    [
      "b               ",
      "b               ",
      "b               ",
      "b  k            ",
      "b l             ",
      "b               ",
      "bh              ",
      "bh              ",
      "bh              ",
      "bh              ",
      "b               ",
      "b d             ",
      "b               ",
      "b               ",
      "b               ",
      "b               "
    ],
    [
      "                ",
      "                ",
      "                ",
      "                ",
      "m l             ",
      "                ",
      "                ",
      "                ",
      "                ",
      "                ",
      "                ",
      "  l             ",
      "                ",
      "                ",
      "                ",
      "                "
    ],
    [
      "                ",
      "                ",
      "                ",
      "                ",
      "  d             ",
      "                ",
      "                ",
      "                ",
      "                ",
      "                ",
      "                ",
      "  l             ",
      "                ",
      "                ",
      "                ",
      "                "
    ]
  ]
}