{
  "name": "multi_communitycenter_1_base1",
  "refpalette": "deceasedcraft:multi_communitycenter_1/multi_communitycenter_1_base1_palette",
  "xsize": 16,
  "zsize": 16,
  "slices": [
    [
      "vHHHHHHHHHHHHHHH",
      "vHHHHHHHHHHHHHHH",
      "vHHHHHHHHHHHHHHH",
      "vHHHHHHHHHHHHHHH",
      "vHHHHHHHHHHHHHHH",
      "vHHHHHHHHHHHHHHH",
      "vHHHHHHHHHHHHHHH",
      "vHHHHHHHHHHHHHHH",
      "vHHHHHHHHHHHHHHH",
      "vHHHHHHHHHHHHHHH",
      "vHHHHHHHHHHHHHHH",
      "vHHHHHHHHHHHHHHH",
      "vHHHHHHHHHHHHHHH",
      "vHHHHHHHHHHHHHHH",
      "vHHHHHHHHHHHHHHH",
      "vHHHHHHHHHHHHHHH"
    ],
    [
      "vaaaa     b    c",
      "vaaaa dedeb    c",
      "vaaaa fgfgb    c",
      "vaaaa     b    c",
      "vaaaah    h    h",
      "vaaaa dede      ",
      "vaaaa           ",
      "vaaaa           ",
      "vaaaa           ",
      "vaaaa           ",
      "vaaaa fgfg      ",
      "vaaaah    h    h",
      "vaaaa     b    c",
      "vaaaa dedeb    c",
      "vaaaa fgfgb    c",
      "vaaaa   i b    c"
    ],
    [
      "vaaaa           ",
      "vaaaa           ",
      "vaaaa           ",
      "vaaaa           ",
      "vaaaah    h    h",
      "vaaaa           ",
      "vaaaa           ",
      "vaaaa           ",
      "vaaaa           ",
      "vaaaa           ",
      "vaaaa           ",
      "vaaaah    h    h",
      "vaaaa           ",
      "vaaaa           ",
      "vaaaa           ",
      "vaaaa           "
    ],
    [
      "vaaaa           ",
      "vaaaa           ",
      "vaaaa           ",
      "vaaaa           ",
      "vaaaah    h    h",
      "vaaaa           ",
      "vaaaa           ",
      "vaaaa           ",
      "vaaaa           ",
      "vaaaa           ",
      "vaaaa           ",
      "vaaaah    h    h",
      "vaaaa           ",
      "vaaaa           ",
      "vaaaa           ",
      "vaaaa           "
    ],
    [
      "vaaaah    h    h",
      "vaaaah    h    h",
      "vaaaah    h    h",
      "vaaaah    h    h",
      "vaaaahjjjjhjjjjh",
      "vaaaah    h    h",
      "vaaaah    h    h",
      "vaaaah    h    h",
      "vaaaah    h    h",
      "vaaaah    h    h",
      "vaaaah    h    h",
      "vaaaahjjjjhjjjjh",
      "vaaaah    h    h",
      "vaaaah    h    h",
      "vaaaah    h    h",
      "vaaaah    h    h"
    ],
    [
      "vaaaaaaaaaaaaaaa",
      "vaaaaaaaaaaaaaaa",
      "vaaaaaaaaaaaaaaa",
      "vaaaaaaaaaaaaaaa",
      "vaaaaaaaaaaaaaaa",
      "vaaaaaaaaaaaaaaa",
      "vaaaaaaaaaaaaaaa",
      "vaaaaaaaaaaaaaaa",
      "vaaaaaaaaaaaaaaa",
      "vaaaaaaaaaaaaaaa",
      "vaaaaaaaaaaaaaaa",
      "vaaaaaaaaaaaaaaa",
      "vaaaaaaaaaaaaaaa",
      "vaaaaaaaaaaaaaaa",
      "vaaaaaaaaaaaaaaa",
      "vaaaaaaaaaaaaaaa"
    ]
  ]
}