{
  "name": "multi_communitycenter_1_ground",
  "refpalette": "deceasedcraft:multi_communitycenter_1/multi_communitycenter_1_ground_palette",
  "xsize": 16,
  "zsize": 16,
  "slices": [
    [
      "aabcdd  e dd f  ",
      "aabcgdhi  dd  je",
      "aabcdd ke dd hle",
      "aabcgdh   dd    ",
      "aabcdd  f dd   e",
      "aabcgdhi  ddh j ",
      "aabcddhke dd hle",
      "aabmmmmmmnnnnmmm",
      "aaoooooopoooopoo",
      "aaoqqqqqpooooprr",
      "aaoqqqqqqpoooopr",
      "aaooqqqqqpoooopr",
      "aaaoqqqqqpoooopr",
      "aaaoqqqqqqpoooop",
      "aaaooqqqqqpooooo",
      "aaaaoqqqqqqpoooo"
    ],
    [
      "  b             ",
      "  bs            ",
      "  b             ",
      "  bs            ",
      "  b             ",
      "  b             ",
      "  b             ",
      "  bmmmmmm    mmm",
      "  bbtttbm    mbu",
      "  b     w    w  ",
      "  b      x    yA",
      "  bbttt  x    y ",
      "   b     x    y ",
      "   b      x    y",
      "   bbttt  x     ",
      "    b           "
    ],
    [
      "  BCCCCCCCCCCCCC",
      "  B             ",
      "  b             ",
      "  b             ",
      "  B             ",
      "  B           D ",
      "  B             ",
      "  bmmmmmm    mmm",
      "  bbEEEbm    mbu",
      "  B     w    w  ",
      "  B      x    y ",
      "  BBF I  x    y ",
      "   B     x    y ",
      "   b      x    y",
      "   bBJKL  x     ",
      "    B           "
    ],
    [
      "  bMMMMMMMMMMMMM",
      "  bNNNNNNNNNNNNN",
      "  bCCCCCCCCCCCCC",
      "  bCCCCCCCCCCCCC",
      "  BCCCCCCCCCCCCC",
      "  B    O      O ",
      "  B             ",
      "  bmmmmmm    mmm",
      "  bbbbbbm    mbu",
      "  B     w    w  ",
      "  B      x    y ",
      "  BB     x    y ",
      "   B     x    y ",
      "   b      x    y",
      "   bB     x     ",
      "    B           "
    ],
    [
      "  bP  Q  RRRRRRR",
      "  bMMMMMMMMMMMMM",
      "  bMMMMMMMMMMMMM",
      "  bMMMMMMMMMMMMM",
      "  bMMMMMMMMMMMMM",
      "  bNNNNNNNNNNNNN",
      "  bNNNNNNNNNNNNN",
      "  bmmmmmm    mmm",
      "  bbbbbbm    mbb",
      "  b     w    w  ",
      "  b      w    S ",
      "  bb     w    S ",
      "   b     w    S ",
      "   b      w    S",
      "   bb     w     ",
      "    b      w    "
    ],
    [
      "   P            ",
      "   P            ",
      "  TP            ",
      "  TP            ",
      "  bPRRRRR   Q RR",
      "  bMMMMMMMMMMMMM",
      "  btMMMMMMMMMMMM",
      "  btMMMMmmmmmmMM",
      "  bMMMMtm    mtM",
      "  bNNNNNm    mmN",
      "  bNNNNNmm    mN",
      "  bbNNNNNm    mN",
      "   bNNNNNm    mm",
      "   bNNNNNmm    m",
      "   bbNNNNNm    U",
      "    bNNNNNmm  UU"
    ]
  ]
}