{
  "name": "multi_timbertower_8_ground",
  "refpalette": "deceasedcraft:multi_timbertower_8/multi_timbertower_8_ground_palette",
  "xsize": 16,
  "zsize": 16,
  "slices": [
    [
      "vvvvaaaaabbbbccc",
      "vvvvaaaaabbbbccc",
      "vvdvaaaaabbbbccc",
      "vvvvaaaaabbbbccc",
      "vvvvaaaaabbbbccc",
      "vvvvaaaaabbbbccc",
      "vvvvaaaaabbbbccc",
      "vvvvaaaaabbbbccc",
      "vvvvaaaaabbbbccc",
      "vvdvaaaaabbbbccc",
      "vvvvaaaaabbbbccc",
      "vvvvaaaaabbbbccc",
      "vvvvvvvvvvvvvvcc",
      "cceccccccecccccc",
      "eeceececeeeceecc",
      "ecccceccecccccec"
    ],
    [
      "fgdaabbbb       ",
      " gdaabbbb       ",
      "dddaabbbb       ",
      " gdaabbbb       ",
      "hgdaabbbb       ",
      " gdaabbbb       ",
      " gdaabbbb       ",
      "hgdaabbbb       ",
      " gdaabbbb       ",
      "dddaabbbb       ",
      " gdaabbbb       ",
      " gdaabbbbi      ",
      "jjkjjjjjjkjjll  ",
      "mm mnmmmm mn    ",
      "                ",
      "                "
    ],
    [
      "obbbb           ",
      "obbbb           ",
      "obdbb           ",
      "obbbb           ",
      "obbbb           ",
      "obbbb           ",
      "obbbb           ",
      "obbbb           ",
      "obbbb           ",
      "obbbb           ",
      "obbbb           ",
      "obbbb           ",
      "jjkjjjjjlp      ",
      "                ",
      "                ",
      "                "
    ],
    [
      "b               ",
      "b q             ",
      "b rs            ",
      "b               ",
      "b               ",
      "b               ",
      "b               ",
      "b               ",
      "b               ",
      "b               ",
      "b               ",
      "b i             ",
      "jjkjll          ",
      "                ",
      "                ",
      "                "
    ],
    [
      "                ",
      "                ",
      "s r             ",
      "                ",
      "                ",
      "                ",
      "                ",
      "                ",
      "                ",
      "                ",
      "                ",
      "                ",
      "ll              ",
      "                ",
      "                ",
      "                "
    ],
    [
      "                ",
      "                ",
      "  d             ",
      "                ",
      "                ",
      "                ",
      "                ",
      "                ",
      "                ",
      "                ",
      "                ",
      "                ",
      "                ",
      "                ",
      "                ",
      "                "
    ]
  ]
}