{
  "name": "multi_timbertower_8_base2",
  "refpalette": "deceasedcraft:multi_timbertower_8/multi_timbertower_8_base2_palette",
  "xsize": 16,
  "zsize": 16,
  "slices": [
    [
      "HHHHHHHHHHHvvaav",
      "HHHHHHHHHHHvvaav",
      "HHbHHHHHHbHvvaav",
      "HHHHHHHHHHHvvaav",
      "HHHHHHHHHHHvvaav",
      "HHHHHHHHHHHvvaav",
      "HHHHHHHHHHHvvaav",
      "HHHHHHHHHHHvvaav",
      "HHHHHHHHHHHvvaav",
      "HHbHHHHHHHHvvaav",
      "HHHHHHHHHHHvvaav",
      "vvvvvvvvvvvvvaav",
      "vvvvvvvvvvvvvaav",
      "            aaav",
      "aaaaaaaaaaaaaaav",
      "vvvvvvvvvvvvvvvv"
    ],
    [
      " c d    e fgvaav",
      "ef      c dgvaav",
      "  bh    ib gvaav",
      "cdj     e fgvaav",
      "        c dgvaav",
      "        e fgvaav",
      "        c dgvaav",
      "        kkkgvaav",
      "eflefefm   gvaav",
      "  b    m b gvaav",
      "cd cdcdm   gvaav",
      "ggggggggggggvaav",
      "vvvvvvvvvvvvvaav",
      "aaaaaaaaaaaaaaav",
      "aaaaaaaaaaaaaaav",
      "vvvvvvvvvvvvvvvv"
    ],
    [
      "            vaav",
      "            vaav",
      "  b      b  vaav",
      "            vaav",
      "            vaav",
      "            vaav",
      "            vaav",
      "            vaav",
      "            vaav",
      "  b      b  vaav",
      "            vaav",
      "            vaav",
      "vvvvvvvvvvvvvaav",
      "aaaaaaaaaaaaaaav",
      "aaaaaaaaaaaaaaav",
      "vvvvvvvvvvvvvvvv"
    ],
    [
      "            vaav",
      "            vaav",
      "  b      b  vaav",
      "            vaav",
      "            vaav",
      "            vaav",
      "            vaav",
      "            vaav",
      "            vaav",
      "  b      b  vaav",
      "            vaav",
      "            vaav",
      "vvvvvvvvvvvvvaav",
      "aaaaaaaaaaaaaaav",
      "aaaaaaaaaaaaaaav",
      "vvvvvvvvvvvvvvvv"
    ],
    [
      "            vaav",
      "            vaav",
      "  b      b  vaav",
      "            vaav",
      "            vaav",
      "            vaav",
      "            vaav",
      "            vaav",
      "            vaav",
      "  b      b  vaav",
      "            vaav",
      "            vaav",
      "vvvvvvvvvvvvvaav",
      "aaaaaaaaaaaaaaav",
      "aaaaaaaaaaaaaaav",
      "vvvvvvvvvvvvvvvv"
    ],
    [
      " nbnnnnnnbnvvaav",
      "nnbnnnnnnbnvvaav",
      "bbbbbbbbbbnvvaav",
      "nnbnnnnnnbnvvaav",
      "nnbnnnnnnbnvvaav",
      "nnbnnnnnnbnvvaav",
      "nnbnnnnnnbnvvaav",
      "nnbnnnnnnbnvvaav",
      "nnbnnnnnnbnvvaav",
      "bbbbbbbbbbnvvaav",
      "nnnnnnnnnnnvvaav",
      "vvvvvvvvvvvvvaav",
      "vvvvvvvvvvvvvaav",
      "aaaaaaaaaaaaaaav",
      "aaaaaaaaaaaaaaav",
      "vvvvvvvvvvvvvvvv"
    ]
  ]
}