{
  "name": "multi_thering_7_base2",
  "refpalette": "deceasedcraft:multi_thering_7/multi_thering_7_base2_palette",
  "xsize": 16,
  "zsize": 16,
  "slices": [
    [
      "abbbbbbbbbbbbbbb",
      "bbbbbbbbbbbbbbbb",
      "bbbbbbbbbbbbbbbb",
      "bbbbbbbbbbbbbbbb",
      "bbbbbbbbbbbbbbbb",
      "bbbbbbbbbbbbbbbb",
      "bbbbbbbbbbbbbbbb",
      "bbbbbbbbbbbbbbbb",
      "bbbbbbbbbbbbbbbb",
      "bbbbbbbbbbbbbbbb",
      "bbbbbbbbbbbbbbbb",
      "bbbbbbbbbbbbbbbb",
      "bbbbbbbbbbbbbbbb",
      "bbbbbbbbbbbbbbbb",
      "bbbbbbbbbbbbbbbb",
      "abbbbbbbbbbbbbbb"
    ],
    [
      "abbbbbbbbbbbbbbb",
      "bbbbbbbbbbbbbbbb",
      "bbbbbbbbbbbbbbbb",
      "bbbbbbbbbbbbbbbb",
      "bbbbbbbbbbbbbbbb",
      "bbbbbbbbbbbbbbbb",
      "bbbbbbbbbbbbbbbb",
      "bbbbbbbbbbbbbbbb",
      "bbbbbbbbbbbbbbbb",
      "bbbbbbbbbbbbbbbb",
      "bbbbbbbbbbbbbbbb",
      "bbbbbbbbbbbbbbbb",
      "bbbbbbbbbbbbbbbb",
      "bbbbbbbbbbbbbbbb",
      "bbbbbbbbbbbbbbbb",
      "abbbbbbbbbbbbbbb"
    ],
    [
      "accccccccccccccc",
      "cccccccccccccccc",
      "cccccccccccccccc",
      "cccccccccccccccc",
      "cccccccccccccccc",
      "cccccccccccccccc",
      "cccccccccccccccc",
      "cccccccccccccccc",
      "cccccccccccccccc",
      "cccccccccccccccc",
      "cccccccccccccccc",
      "cccccccccccccccc",
      "cccccccccccccccc",
      "cccccccccccccccc",
      "cccccccccccccccc",
      "accccccccccccccc"
    ],
    [
      "deeeeeeeeeeeeeee",
      "efffffffffffffff",
      "efffffffffffffff",
      "efffffffffffffff",
      "efffffffffffffff",
      "efffffffffffffff",
      "efffffffffffffff",
      "efffffffffffffff",
      "efffffffffffffff",
      "efffffffffffffff",
      "efffffffffffffff",
      "efffffffffffffff",
      "efffffffffffffff",
      "efffffffffffffff",
      "efffffffffffffff",
      "deeeeeeeeeeeeeee"
    ],
    [
      "g        hhhhhhh",
      "h         i j kh",
      "h         l j mh",
      "h         n j oh",
      "h               ",
      "h               ",
      "                ",
      "                ",
      "                ",
      "                ",
      "h               ",
      "h               ",
      "h         i j kh",
      "h         l j mh",
      "h         n j oh",
      "g        hhhhhhh"
    ],
    [
      "g        ppppppp",
      "p              p",
      "p              p",
      "p              p",
      "p               ",
      "p               ",
      "                ",
      "                ",
      "                ",
      "                ",
      "p               ",
      "p               ",
      "p              p",
      "p              p",
      "p              p",
      "g        ppppppp"
    ]
  ]
}