{
  "name": "multi_filmworkstower_15_base2",
  "refpalette": "deceasedcraft:multi_filmworkstower_15/multi_filmworkstower_15_base2_palette",
  "xsize": 16,
  "zsize": 16,
  "slices": [
    [
      " abbbbbbbcccccbb",
      " abbbbbbbcccccbb",
      " abbbbbbbcccccbb",
      " abbbbbbbcccccbb",
      " abbbbbbbcccccbb",
      " abbbbbbbcccccbb",
      " abbbbbbbdddddbb",
      "aabbbbbbbbbbbbbb",
      "bbbbbbbbbbbbbbbb",
      "bbbbbbbbbbbbbbbb",
      "bbbbbbbbbbbbbbbb",
      "bbbbbbbbbbbbbbbb",
      "bbbbbbbbbbbbbbbb",
      "eeeeeeeeeeeeeeee",
      "ffffffffffffffff",
      "vvvvvvvvvvvvvvvv"
    ],
    [
      " a      gh    i ",
      " a      gj    k ",
      " a      gl   mk ",
      " a      gl   nk ",
      " a      glo  pk ",
      " a      gq   rk ",
      " ast    udddddw ",
      "aa              ",
      "                ",
      "                ",
      "                ",
      "                ",
      "                ",
      "eeeeeeeeeeeeeeee",
      "ffffffffffffffff",
      "vvvvvvvvvvvvvvvv"
    ],
    [
      " a      gx    y ",
      " a      gA    k ",
      " a      gB    k ",
      " a      gC    k ",
      " a      g     k ",
      " a      gD   Ek ",
      " as     ddddddd ",
      "aa              ",
      "                ",
      "                ",
      "                ",
      "                ",
      "                ",
      "eeeeeeeeeeeeeeee",
      "ffffffffffffffff",
      "vvvvvvvvvvvvvvvv"
    ],
    [
      " a      g!    F ",
      " a      gI    k ",
      " a      gJ    k ",
      " a      gJ    k ",
      " a      gJ    k ",
      " aK     gLMNO k ",
      " as    udddddddw",
      "aa              ",
      "                ",
      "                ",
      "                ",
      "                ",
      "                ",
      "eeeeeeeeeeeeeeee",
      "ffffffffffffffff",
      "vvvvvvvvvvvvvvvv"
    ],
    [
      " aP     gQQQQQk ",
      " aP     gQQQQQk ",
      " aP     gQQQQQk ",
      " aP     gQQQQQk ",
      " aP     gQQQQQk ",
      " aP     gQQQQQk ",
      " asR   ddddddddd",
      "aa              ",
      "                ",
      "                ",
      "                ",
      "                ",
      "                ",
      "eeeeeeeeeeeeeeee",
      "ffffffffffffffff",
      "vvvvvvvvvvvvvvvv"
    ],
    [
      " a              ",
      " a              ",
      " a              ",
      " a              ",
      " a              ",
      " a              ",
      " as   udddSTUddd",
      "aa              ",
      "                ",
      "                ",
      "                ",
      "                ",
      "                ",
      "eeeeeeeeeeeeeeee",
      "ffffffffffffffff",
      "vvvvvvvvvvvvvvvv"
    ]
  ]
}