{
  "name": "multi_filmworkstower_15_base3",
  "refpalette": "deceasedcraft:multi_filmworkstower_15/multi_filmworkstower_15_base3_palette",
  "xsize": 16,
  "zsize": 16,
  "slices": [
    [
      "aaabbbbbbbbbbbbb",
      "aaabbbbbbbbbbbbb",
      "aaabbbbbbbbbbbbb",
      "aaabbbbbbbbbbbbb",
      "aaabbbbbbbbbbbbb",
      "aaabbbbbbbbbbbbb",
      "aaabbbbbbaaaaabb",
      "aaabbbbbbbbbbbbb",
      "aaabbbbbbbbbbbbb",
      "bbbbbbbbbbbbbbbb",
      "bbbbbbbbbbbbbbbb",
      "bbbbbbbbbbbbbbbb",
      "bbbbbbbbbbbbbbbb",
      "bbbbbbbbbbbbbbbb",
      "bbbbbbbbbbbbbbbb",
      "vvvvvvvvvvvvvvvv"
    ],
    [
      "cdabbbbbbbbbbbbb",
      "edabbbbbbbbbbbbb",
      "cdabbbbbbbbbbbbb",
      "edabbbbbbbbbbbbb",
      "edabbbbbbbbbbbbb",
      "cdabbbbbbbbbbbbb",
      "cdabbbbbbaaaaabb",
      "ddabbbbbbbbbbbbb",
      "aaabbbbbbbbbbbbb",
      "bbbbbbbbbbbbbbbb",
      "bbbbbbbbbbbbbbbb",
      "bbbbbbbbbbbbbbbb",
      "bbbbbbbbbbbbbbbb",
      "bbbbbbbbbbbbbbbb",
      "bbbbbbbbbbbbbbbb",
      "vvvvvvvvvvvvvvvv"
    ],
    [
      " dabbbbbbbbbbbbb",
      " dabbbbbbbbbbbbb",
      " dabbbbbbbbbbbbb",
      " dabbbbbbbbbbbbb",
      " dabbbbbbbbbbbbb",
      " dabbbbbbbbbbbbb",
      " dabbbbbbaaaaabb",
      "ddabbbbbbbbbbbbb",
      "aaabbbbbbbbbbbbb",
      "bbbbbbbbbbbbbbbb",
      "bbbbbbbbbbbbbbbb",
      "bbbbbbbbbbbbbbbb",
      "bbbbbbbbbbbbbbbb",
      "bbbbbbbbbbbbbbbb",
      "bbbbbbbbbbbbbbbb",
      "vvvvvvvvvvvvvvvv"
    ],
    [
      " dabbbbbbbbbbbbb",
      " dabbbbbbbbbbbbb",
      " dabbbbbbbbbbbbb",
      " dabbbbbbbbbbbbb",
      " dabbbbbbbbbbbbb",
      " dabbbbbbbbbbbbb",
      " dabbbbbbaaaaabb",
      "ddabbbbbbbbbbbbb",
      "aaabbbbbbbbbbbbb",
      "bbbbbbbbbbbbbbbb",
      "bbbbbbbbbbbbbbbb",
      "bbbbbbbbbbbbbbbb",
      "bbbbbbbbbbbbbbbb",
      "bbbbbbbbbbbbbbbb",
      "bbbbbbbbbbbbbbbb",
      "vvvvvvvvvvvvvvvv"
    ],
    [
      " dabbbbbbbbbbbbb",
      " dabbbbbbbbbbbbb",
      " dabbbbbbbbbbbbb",
      " dabbbbbbbbbbbbb",
      " dabbbbbbbbbbbbb",
      " dabbbbbbbbbbbbb",
      " dabbbbbbaaaaabb",
      "ddabbbbbbbbbbbbb",
      "aaabbbbbbbbbbbbb",
      "bbbbbbbbbbbbbbbb",
      "bbbbbbbbbbbbbbbb",
      "bbbbbbbbbbbbbbbb",
      "bbbbbbbbbbbbbbbb",
      "bbbbbbbbbbbbbbbb",
      "bbbbbbbbbbbbbbbb",
      "vvvvvvvvvvvvvvvv"
    ],
    [
      " dabbbbbbbbbbbbb",
      " dabbbbbbbbbbbbb",
      " dabbbbbbbbbbbbb",
      " dabbbbbbbbbbbbb",
      " dabbbbbbbbbbbbb",
      " dabbbbbbbbbbbbb",
      " dabbbbbbaaaaabb",
      "ddabbbbbbbbbbbbb",
      "aaabbbbbbbbbbbbb",
      "bbbbbbbbbbbbbbbb",
      "bbbbbbbbbbbbbbbb",
      "bbbbbbbbbbbbbbbb",
      "bbbbbbbbbbbbbbbb",
      "bbbbbbbbbbbbbbbb",
      "bbbbbbbbbbbbbbbb",
      "vvvvvvvvvvvvvvvv"
    ]
  ]
}