{
  "name": "multi_filmworkstower_15_base1",
  "refpalette": "deceasedcraft:multi_filmworkstower_15/multi_filmworkstower_15_base1_palette",
  "xsize": 16,
  "zsize": 16,
  "slices": [
    [
      " a              ",
      " a              ",
      " a              ",
      " a              ",
      " a              ",
      " a              ",
      " ab   cccd   ecc",
      "aa              ",
      "                ",
      "                ",
      "                ",
      "                ",
      "                ",
      "ffffffffffffffff",
      "gggggggggggggggg",
      "vvvvvvvvvvvvvvvv"
    ],
    [
      " a              ",
      " a              ",
      " a              ",
      " a              ",
      " a              ",
      " ah             ",
      " abi jccd     ec",
      "aa              ",
      "                ",
      "                ",
      "                ",
      "                ",
      "                ",
      "ffffffffffffffff",
      "gggggggggggggggg",
      "vvvvvvvvvvvvvvvv"
    ],
    [
      " ak             ",
      " ak             ",
      " ak             ",
      " ak             ",
      " ak             ",
      " ak             ",
      " abllccd       e",
      "aa              ",
      "                ",
      "                ",
      "                ",
      "                ",
      "                ",
      "ffffffffffffffff",
      "gggggggggggggggg",
      "vvvvvvvvvvvvvvvv"
    ],
    [
      "                ",
      "                ",
      "                ",
      "                ",
      "                ",
      "                ",
      " mbnjcd         ",
      "                ",
      "                ",
      "                ",
      "                ",
      "                ",
      "                ",
      "ffffffffffffffff",
      "gggggggggggggggg",
      "vvvvvvvvvvvvvvvv"
    ],
    [
      "opqppppppppppppp",
      "opqppppppppppppp",
      "opqppppppppppppp",
      "opqppppppppppppp",
      "opqppppppppppppp",
      "opqppppppppppppp",
      "pprpccpppppppppp",
      "pppppppppppppppp",
      "pppppppppppppppp",
      "pppppppppppppppp",
      "pppppppppppppppp",
      "pppppppppppppppp",
      "pppppppppppppppp",
      "ffffffffffffffff",
      "gggggggggggggggg",
      "vvvvvvvvvvvvvvvv"
    ],
    [
      "cccccccccccccccc",
      "cccccccccccccccc",
      "cccccccccccccccc",
      "cccccccccccccccc",
      "cccccccccccccccc",
      "cccccccccccccccc",
      "c cccccccccccccc",
      "cccccccccccccccc",
      "cccccccccccccccc",
      "cccccccccccccccc",
      "cccccccccccccccc",
      "cccccccccccccccc",
      "cccccccccccccccc",
      "ffffffffffffffff",
      "gggggggggggggggg",
      "vvvvvvvvvvvvvvvv"
    ]
  ]
}