{
  "name": "multi_filmworkstower_15_floor2",
  "refpalette": "deceasedcraft:multi_filmworkstower_15/multi_filmworkstower_15_floor2_palette",
  "xsize": 16,
  "zsize": 16,
  "slices": [
    [
      "aaaaaaaaaaaaaaaa",
      "aaaaaaaaaaaaaaaa",
      "aaaaaaaaaaaaaaaa",
      "aaaaaaaaaaaaaaaa",
      "aaaaaaaaaaaaaaaa",
      "aaaaaaaaaaaaaaaa",
      "aaaaaaaaaabcbaaa",
      "dddddddddddddddd",
      "bbbbbbbbbbbbbbbb",
      "eeeeeeeeeeeeeeee",
      "                ",
      "                ",
      "                ",
      "                ",
      "                ",
      "                "
    ],
    [
      "ffff            ",
      "                ",
      "                ",
      "                ",
      "                ",
      "                ",
      "         gbhbi  ",
      "jjjjjjjjjjjjjjjj",
      "kkkkkkkkkkkkkkkk",
      "eeeeeeeeeeeeeeee",
      "                ",
      "                ",
      "                ",
      "                ",
      "                ",
      "                "
    ],
    [
      "                ",
      "                ",
      "                ",
      "                ",
      "                ",
      "                ",
      "llll m  gn ! oi ",
      "                ",
      "pppppppppppppppp",
      "eeeeeeeeeeeeeeee",
      "                ",
      "                ",
      "                ",
      "                ",
      "                ",
      "                "
    ],
    [
      "                ",
      "                ",
      "                ",
      "                ",
      "                ",
      "                ",
      "qqqq r gn  s  oi",
      "                ",
      "pppppppppppppppp",
      "eeeeeeeeeeeeeeee",
      "                ",
      "                ",
      "                ",
      "                ",
      "                ",
      "                "
    ],
    [
      "                ",
      "                ",
      "                ",
      "                ",
      "                ",
      "                ",
      "tttt ugn   s   o",
      "                ",
      "pppp ppp ppppppp",
      "eeeeeeeeeeeeeeee",
      "                ",
      "                ",
      "                ",
      "                ",
      "                ",
      "                "
    ],
    [
      "                ",
      "                ",
      "                ",
      "                ",
      "                ",
      "                ",
      "   w gn    s    ",
      "                ",
      "p  p  pp  p pp  ",
      "eeeeeeeeeeeeeeee",
      "                ",
      "                ",
      "                ",
      "                ",
      "                ",
      "                "
    ]
  ]
}