{
  "name": "multi_laboratory_7_ground",
  "refpalette": "deceasedcraft:multi_laboratory_7/multi_laboratory_7_ground_palette",
  "xsize": 16,
  "zsize": 16,
  "slices": [
    [
      "@@@@@@@@@@@@@@@@",
      "@@@@@@@@@@@@@@@@",
      "@@@@@@@@@@@@@@@@",
      "@@@@@@@@@@@@@@@@",
      "@@@@@@@@@@@@@@@@",
      "a@@@@@@@@@@@@@@a",
      "a@@@@@@@@@@@@@@a",
      "aa@@@@@@@@@@@@aa",
      "baaa@@@@@@@@aaab",
      "bbbaaa@@@@aaabbb",
      "bbbbbaaaaaabbbbb",
      "bbbbbbbbbbbbbbbb",
      "bbbbbbbbbbbbbbbb",
      "bbbbbbbbbbbbbbbb",
      "bbbbbbbbbbbbbbbb",
      "bbbbb      bbbbb"
    ],
    [
      "                ",
      "                ",
      "                ",
      "                ",
      "                ",
      "c              c",
      "c              c",
      "cc            cc",
      " ccc        ccc ",
      "   ccc    ccc   ",
      "     cccccc     ",
      "d              d",
      "ed            df",
      "ggd  hi  hi  dg ",
      "  jk llllll mng ",
      "  okp      qm   "
    ],
    [
      "                ",
      "                ",
      "                ",
      "                ",
      "                ",
      "                ",
      "                ",
      "                ",
      "                ",
      "                ",
      "                ",
      "d              d",
      "!d            df",
      "ggd          dg ",
      "  rk        m g ",
      "   k        m   "
    ],
    [
      "                ",
      "                ",
      "                ",
      "                ",
      "                ",
      "                ",
      "                ",
      "                ",
      "                ",
      "                ",
      "                ",
      "d              d",
      "sd            df",
      "ggd          dg ",
      "  tk        m g ",
      "   k        m   "
    ],
    [
      "                ",
      "                ",
      "                ",
      "                ",
      "                ",
      "                ",
      "                ",
      "                ",
      "                ",
      "                ",
      "                ",
      "d              d",
      " d            df",
      "uwd          dxf",
      "   k        m  f",
      "   k        m y "
    ],
    [
      "                ",
      "                ",
      "                ",
      "                ",
      "                ",
      "                ",
      "                ",
      "                ",
      "                ",
      "                ",
      "                ",
      "d              d",
      "Ad            d ",
      "AAd          dAA",
      "AAAk        mAAA",
      "AAAk B    B mAAA"
    ]
  ]
}