{
  "name": "multi_laboratory_7_base4",
  "refpalette": "deceasedcraft:multi_laboratory_7/multi_laboratory_7_base4_palette",
  "xsize": 16,
  "zsize": 16,
  "slices": [
    [
      "                ",
      "                ",
      "                ",
      " a              ",
      "                ",
      "b    a         b",
      "b              b",
      "bc            cb",
      "dbbb        bbbd",
      "dddbbc    cbbddd",
      "dddddbbbbbbddddd",
      "dddddddddddddddd",
      "dddddddddddddddd",
      "dddddddddddddddd",
      "dddddddddddddddd",
      "dddddddddddddddd"
    ],
    [
      "                ",
      "                ",
      "                ",
      " a              ",
      "                ",
      "e    a         e",
      "e              e",
      "ec            ce",
      " eee        eeef",
      "f  eec    cee   ",
      "gh iceeeeeec  jk",
      "lm   noooopq  rs",
      " f       t  f  f",
      "      t         ",
      "                ",
      "  u u      u    "
    ],
    [
      "                ",
      "                ",
      "                ",
      " a              ",
      "                ",
      "e    a         e",
      "e              e",
      "ec            ce",
      " eee        eee ",
      "   eec    cee   ",
      "w   xeeeeeey  A ",
      "      BCDB    Ew",
      "                ",
      "                ",
      "                ",
      "                "
    ],
    [
      "                ",
      "                ",
      "                ",
      " a              ",
      "                ",
      "e    a         e",
      "e              e",
      "ec            ce",
      " eee        eee ",
      "   eec    cee   ",
      "    !eeeeeeF    ",
      "                ",
      "                ",
      "                ",
      "                ",
      "                "
    ],
    [
      "                ",
      "                ",
      "                ",
      " a              ",
      "                ",
      "e    a         e",
      "e              e",
      "ec            ce",
      " eee        eee ",
      "   eec    cee   ",
      "     eeeeee     ",
      "                ",
      "                ",
      "                ",
      "                ",
      "                "
    ],
    [
      "                ",
      "                ",
      "                ",
      " a              ",
      "                ",
      "e    a         e",
      "e              e",
      "ec            ce",
      "Ieee        eeeI",
      "IIIeec    ceeIII",
      "IIIIIeeeeeeIIIII",
      "IIIIIIIIIIIIIIII",
      "IIIIIIIIIIIIIIII",
      "IJIIIJIIIIKIIIJI",
      "IJIIIJIIIIJIIIJI",
      "IJIIIJIIIIJIIIJI"
    ]
  ]
}