{
  "name": "multi_laboratory_7_base7",
  "refpalette": "deceasedcraft:multi_laboratory_7/multi_laboratory_7_base7_palette",
  "xsize": 16,
  "zsize": 16,
  "slices": [
    [
      "aaaabccccccbaaaa",
      "aaaabccccccbaaaa",
      "aaaabccccccbaaaa",
      "aaaabccccccbaaaa",
      "aaaabbbbbbbbaaaa",
      "daaaaaaaaaaaaaad",
      "daaaaaaaaaaaaead",
      "ddaaaaaaaafaaedd",
      "adddaaafffaaddda",
      "aaadddaaaadddaaa",
      "aaaaaddddddaaaaa",
      "aaaaaaaaaaaaaaaa",
      "aaaaaaaaaaaaaaaa",
      "aaaaaaaaaaaaaaaa",
      "aaaaaaaaaaaaaaaa",
      "aaaaaaaaaaaaaaaa"
    ],
    [
      "aa            eg",
      "aaa           hg",
      "aaa           ag",
      "aaa           ge",
      "ia            gg",
      "aaaa           a",
      "aaag         aaa",
      "ajaag        aja",
      "aaaaia k    aaaa",
      "aaaaajaa  jaaaaa",
      "aaaaaaaaaaaaaaaa",
      "aaaaaaaaaaaaaaaa",
      "aaaaaaaaaaaaaaaa",
      "aaaaaaaaaaaaaaaa",
      "aaaaaaaaaaaaaaaa",
      "aaaaaaaaaaaaaaaa"
    ],
    [
      "a               ",
      "a              e",
      "a             hl",
      "a               ",
      "              hg",
      "ag             a",
      "aggl           a",
      "ajgg         !ja",
      "aaaa    km  aaaa",
      "aaaaajmmmmjaaaaa",
      "aaaaaannnnaaaaaa",
      "aaaaaopqqroaaaaa",
      "aaaaaosttuoaaaaa",
      "aaaaaosttuoaaaaa",
      "aaaaawsttuwaaaaa",
      "aaaaaosttuoaaaaa"
    ],
    [
      "a               ",
      "                ",
      "               h",
      "                ",
      "                ",
      "al             a",
      "ag h           a",
      "ajx           ja",
      "aaaa     y  aaaa",
      "aaaaajABBCjaaaaa",
      "aaaaaanDEnaaaaaa",
      "aaaaao    oaaaaa",
      "aaaaao    oaaaaa",
      "aaaaao    oaaaaa",
      "aaaaaF    Iaaaaa",
      "aaaaao    oaaaaa"
    ],
    [
      "                ",
      "                ",
      "                ",
      "                ",
      "                ",
      "ah             a",
      "a              a",
      "ajl           ja",
      "aaaa        aaaa",
      "aaaaaj    jaaaaa",
      "aaaaaanJKnaaaaaa",
      "aaaaao    oaaaaa",
      "aaaaao    oaaaaa",
      "aaaaao    oaaaaa",
      "aaaaaF    Iaaaaa",
      "aaaaao    oaaaaa"
    ],
    [
      "                ",
      "                ",
      "                ",
      "                ",
      "                ",
      "a              a",
      "a              a",
      "ajh           ja",
      "aaaa        aaaa",
      "aaaaaj    jaaaaa",
      "aaaaaannnnaaaaaa",
      "aaaaaoLMMNoaaaaa",
      "aaaaaoL  Noaaaaa",
      "aaaaaoLMMNoaaaaa",
      "aaaaaoL  Noaaaaa",
      "aaaaaoLMMNoaaaaa"
    ]
  ]
}