{
  "name": "multi_laboratory_7_base6",
  "refpalette": "deceasedcraft:multi_laboratory_7/multi_laboratory_7_base6_palette",
  "xsize": 16,
  "zsize": 16,
  "slices": [
    [
      "                ",
      "                ",
      "                ",
      "                ",
      "                ",
      "a              a",
      "a              a",
      "ab            ba",
      "caaa        aaac",
      "cccaab    baaccc",
      "cccccaaaaaacc!cc",
      "cccccccccccccccc",
      "ccccccc@@ccccccc",
      "cccccccccccccccc",
      "ccccccc@@ccccccc",
      "cccccccccccccccc"
    ],
    [
      "                ",
      "                ",
      "                ",
      "                ",
      "                ",
      "d              d",
      "d              d",
      "db            bd",
      " ddd        ddd ",
      "   ddb    bdde  ",
      "     dddddd     ",
      "                ",
      "ffg           ff",
      "h           i j ",
      "                ",
      "              k "
    ],
    [
      "                ",
      "                ",
      "                ",
      "                ",
      "                ",
      "d              d",
      "d              d",
      "db            bd",
      " ddd        ddd ",
      "   ddb    bdd   ",
      "     dddddd     ",
      "                ",
      "l m            l",
      "                ",
      "                ",
      "                "
    ],
    [
      "                ",
      "                ",
      "                ",
      "!noop           ",
      "                ",
      "d              d",
      "d              d",
      "db            bd",
      " ddd        ddd ",
      "   ddb    bdd   ",
      "     dddddd     ",
      "                ",
      "                ",
      "                ",
      "                ",
      "                "
    ],
    [
      "                ",
      "                ",
      "                ",
      " q              ",
      "                ",
      "d              d",
      "d              d",
      "db            bd",
      " ddd        ddd ",
      "   ddb    bdd   ",
      "     dddddd     ",
      "                ",
      "                ",
      "                ",
      "                ",
      "                "
    ],
    [
      "                ",
      "                ",
      "                ",
      " r              ",
      "                ",
      "d              d",
      "d              d",
      "db            bd",
      " ddd        ddd ",
      "   ddb    bdd   ",
      "     dddddd     ",
      "                ",
      "                ",
      "                ",
      "                ",
      "                "
    ]
  ]
}