{
  "name": "multi_laboratory_7_base3",
  "refpalette": "deceasedcraft:multi_laboratory_7/multi_laboratory_7_base3_palette",
  "xsize": 16,
  "zsize": 16,
  "slices": [
    [
      "                ",
      "                ",
      "                ",
      " a              ",
      "                ",
      "b    a         b",
      "b              b",
      "bc            cb",
      "dbbb        bbbd",
      "dddbbc    cbbddd",
      "dddddbbbbbbddddd",
      "dddddddddddddddd",
      "dddddddddddddddd",
      "dddddddddddddddd",
      "dddddddddddddddd",
      "dddddddddddddddd"
    ],
    [
      "                ",
      "                ",
      "                ",
      " a              ",
      "                ",
      "e    a         e",
      "e              e",
      "ec            ce",
      " eee        eee ",
      "f  eec    cee f ",
      "ghficeeeeeecjfkl",
      "mno p !qrrrs  tu",
      "  wf  xo  y    f",
      "     ow         ",
      "                ",
      "  A A      A qB "
    ],
    [
      "                ",
      "                ",
      "                ",
      " a              ",
      "                ",
      "e    a         e",
      "e              e",
      "ec            ce",
      " eee        eee ",
      "   eec    cee   ",
      "o   CeeeeeeD  E ",
      "        FIJ     ",
      "                ",
      "                ",
      "                ",
      "                "
    ],
    [
      "                ",
      "                ",
      "                ",
      " a              ",
      "                ",
      "e    a         e",
      "e              e",
      "ec            ce",
      " eee        eee ",
      "   eec    cee   ",
      "     eeeeeeK    ",
      "                ",
      "                ",
      "                ",
      "                ",
      "                "
    ],
    [
      "                ",
      "                ",
      "                ",
      " a              ",
      "                ",
      "e    a         e",
      "e              e",
      "ec            ce",
      " eee        eee ",
      "   eec    cee   ",
      "     eeeeee     ",
      "                ",
      "                ",
      "                ",
      "                ",
      "                "
    ],
    [
      "                ",
      "                ",
      "                ",
      " a              ",
      "                ",
      "e    a         e",
      "e              e",
      "ec            ce",
      "Leee        eeeL",
      "LLLeec    ceeLLL",
      "LLLLLeeeeeeLLLLL",
      "LLLLLLLLLLLLLLLL",
      "LLLLLLLLLLLLLLLL",
      "LMLLL LLLLMLLLML",
      "LMLLL LLLLMLLLML",
      "LMLLLMLLLLMLLLML"
    ]
  ]
}