{
  "name": "multi_laboratory_7_base1",
  "refpalette": "deceasedcraft:multi_laboratory_7/multi_laboratory_7_base1_palette",
  "xsize": 16,
  "zsize": 16,
  "slices": [
    [
      "     a    a     ",
      "     a    a     ",
      "     a    a     ",
      "abaaaaaaaaaaaaaa",
      "     a    a     ",
      "c    b    a    c",
      "c    a    a    c",
      "cd   a    a   dc",
      "eccc a    a ccce",
      "eeeccf    fcceee",
      "eeeeecccccceeeee",
      "eeeeeeeeeeeeeeee",
      "eeeeeeeeeeeeeeee",
      "eeeeeeeeeeeeeeee",
      "eeeeeeeeeeeeeeee",
      "eeeeeegeegeeeeee"
    ],
    [
      "                ",
      "                ",
      "                ",
      " h              ",
      "                ",
      "i    h         i",
      "i              i",
      "id            di",
      " iii        iii ",
      " j iid    dii  j",
      "kl mdiiiiiidn kl",
      "opj          jop",
      "j               ",
      "                ",
      "                ",
      "     q rq r     "
    ],
    [
      "                ",
      "                ",
      "                ",
      "                ",
      "                ",
      "i              i",
      "i              i",
      "id            di",
      " iii        iii ",
      "   iid    dii   ",
      " s  tiiiiiit    ",
      "                ",
      "                ",
      "                ",
      "                ",
      "                "
    ],
    [
      "                ",
      "                ",
      "                ",
      "                ",
      "                ",
      "i              i",
      "i              i",
      "id            di",
      " iii        iii ",
      "   iid    dii   ",
      "    uiiiiiiu    ",
      "                ",
      "                ",
      "                ",
      "                ",
      "                "
    ],
    [
      "                ",
      "                ",
      "                ",
      "                ",
      "                ",
      "i              i",
      "i              i",
      "id            di",
      " iii        iii ",
      "   iid    dii   ",
      "     iiiiii     ",
      "                ",
      "                ",
      "                ",
      "                ",
      "                "
    ],
    [
      "                ",
      "                ",
      "                ",
      "                ",
      "                ",
      "w              w",
      "w              w",
      "wx            xw",
      "ywww        wwwy",
      "yyywwx    xwwyyy",
      "yyyyywwwwwwyyyyy",
      "yyyyyyyyyyyyyyyy",
      "yyyyyyyyyyyyyyyy",
      "yyyyyyyyyyyyyyyy",
      "yyyy        yyyy",
      "yyyy        yyyy"
    ]
  ]
}