{
  "name": "multi_laboratory_7_base2",
  "refpalette": "deceasedcraft:multi_laboratory_7/multi_laboratory_7_base2_palette",
  "xsize": 16,
  "zsize": 16,
  "slices": [
    [
      "                ",
      "                ",
      "                ",
      " a              ",
      "                ",
      "b    a         b",
      "b              b",
      "bc            cb",
      "dbbb        bbbd",
      "dddbbc    cbbddd",
      "dddddbbbbbbddddd",
      "dddddddddddddddd",
      "dddddddddddddddd",
      "dddddddddddddddd",
      "dddddddddddddddd",
      "dddddddddddddddd"
    ],
    [
      "                ",
      "                ",
      "                ",
      " a              ",
      "                ",
      "e    a         e",
      "e              e",
      "ec            ce",
      "feee        eeef",
      "  feec    cee   ",
      "gh iceeeeeecjfkk",
      "lm  noooooop  qq",
      "      r  r    f ",
      " f              ",
      "                ",
      "  s s      s s  "
    ],
    [
      "                ",
      "                ",
      "                ",
      " a              ",
      "                ",
      "e    a         e",
      "e              e",
      "ec            ce",
      " eee        eee ",
      "   eec    cee   ",
      "t   ueeeeeeu  w ",
      " x   yA  B     C",
      "                ",
      "                ",
      "                ",
      "                "
    ],
    [
      "                ",
      "                ",
      "                ",
      " a              ",
      "                ",
      "e    D         e",
      "e              e",
      "ec            ce",
      " eee        eee ",
      "   eec    cee   ",
      "    EeeeeeeE    ",
      "                ",
      "                ",
      "                ",
      "                ",
      "                "
    ],
    [
      "                ",
      "                ",
      "                ",
      " a              ",
      "                ",
      "e    a         e",
      "e              e",
      "ec            ce",
      " eee        eee ",
      "   eec    cee   ",
      "     eeeeee     ",
      "                ",
      "                ",
      "                ",
      "                ",
      "                "
    ],
    [
      "                ",
      "                ",
      "                ",
      " a              ",
      "                ",
      "e    a         e",
      "e              e",
      "ec            ce",
      "Feee        eeeF",
      "FFFeec    ceeFFF",
      "FFFFFeeeeeeFFFFF",
      "FFFFFFFFFFFFFFFF",
      "FFFFFFFFFFFFFFFF",
      "FIFFFIFFFFJFFFIF",
      "FIFFFIFFFFIFFFIF",
      "FIFFFIFFFFIFFFIF"
    ]
  ]
}