{
  "name": "multi_nuclearpowerplant_21_base3",
  "refpalette": "deceasedcraft:multi_nuclearpowerplant_21/multi_nuclearpowerplant_21_base3_palette",
  "xsize": 16,
  "zsize": 16,
  "slices": [
    [
      "vvvvvvvvvvvvvvvv",
      "aaaaaaaaaaaaaa=b",
      "aaaaaaaaacaaca=b",
      "dddddddddddddddd",
      "eeeeeeeeeeeeeeee",
      "eeeeeeeeeeeeeee=",
      "eeeeeeeeeeeeeee=",
      "ffeeeeeeeeeeee=g",
      "ffffffeeeeeeee=g",
      "ffffffffeeeeee=g",
      "fffffffffffeee=g",
      "ffffffffffffee==",
      "efffffffffffffee",
      "heefffffffffffff",
      "hhheffffffffffff",
      "  hhefffffffffff"
    ],
    [
      "vvvvvvvvvvvvvvvv",
      "aaaaaaaaaaaaaa=b",
      "aaaaaaaaacaaca=b",
      "iiiiiiiiiiiiiiii",
      "   j          ii",
      "     j klkmknki=",
      "  oppqqi ris ii=",
      "  oooooi tiu i=w",
      "   xxxoo  o  o=w",
      "      yAoooooo=w",
      "        BCCooo=w",
      "            oo==",
      "D           Eyoo",
      " DD        FIJ K",
      "   D        L   ",
      "    D           "
    ],
    [
      "vvvvvvvvvvvvvvvv",
      "aaaaaaaaaaaaaa=b",
      "aaaaaaaaacaaca=b",
      "iiiiiiiiiiiiiiii",
      "              ii",
      "       kMkNkOki=",
      "  oPQ!Ri  i  ii=",
      "  oooooi  i  i=w",
      "      oo SoT o=w",
      "        oooooo=w",
      "           ooo=w",
      "            oo==",
      "D             oo",
      " DD         U  V",
      "   D            ",
      "    D           "
    ],
    [
      "vvvvvvvvvvvvvvvv",
      "aaaaaaaaaaaaaa=b",
      "aaaaaaaaacaaca=b",
      "iiiiiiiiiiiiiiii",
      "              ii",
      "       kWk kWki=",
      "  oXYYZi  i  ii=",
      "  oooooi  i  i=w",
      "      oo 0o1 o=w",
      "        oooooo=w",
      "         2 ooo=w",
      "            oo==",
      "D             oo",
      " DD            3",
      "   D            ",
      "    D           "
    ],
    [
      "vvvvvvvvvvvvvvvv",
      "aaaaaaaaaaaaaa=b",
      "aaaaaaaaacaaca=b",
      "iiiiiiiiiiiiiiii",
      "              ii",
      "       kkkkkkki=",
      "  o    i  i  ii=",
      "  oooooi  4  i=w",
      "      oo  o  o=w",
      "        oooooo=w",
      "           ooo=w",
      "            oo==",
      "D             oo",
      " DD             ",
      "   D            ",
      "    D           "
    ],
    [
      "vvvvvvvvvvvvvvvv",
      "aaaaaaaaaaaaaa=b",
      "aaaaaaaaacaaca=b",
      "iiiiiiiiiiiiiiii",
      "              ii",
      "       kkkkkkki=",
      "ooo    i555555i=",
      "  oooooi55c555=w",
      "      oo555555=w",
      "        ooo 55=w",
      "           o55=w",
      "            oo==",
      "D             oo",
      " DD             ",
      "   D            ",
      "    D           "
    ]
  ]
}