{
  "name": "multi_nuclearpowerplant_21_base1",
  "refpalette": "deceasedcraft:multi_nuclearpowerplant_21/multi_nuclearpowerplant_21_base1_palette",
  "xsize": 16,
  "zsize": 16,
  "slices": [
    [
      "vvvvvvvvvvvvvvvv",
      "aaaaabbbbbbbbb=c",
      "aaaaabdbbdbbdb=c",
      "aeeeeeeeeeeeeeee",
      "effbbbbbbbbbbbbb",
      "gggffffbbbbbbbbb",
      "gggggggffbbbbbbb",
      "ffgggggggfffbbbb",
      "fffgggggggggfbbb",
      "ffffgggggggggffb",
      "fffffggggggggggf",
      "ffffffgggggggggg",
      "fffffffggggggggg",
      "ffffffffgggggggg",
      "ffffffffgggggggg",
      "fffffffffggggggg"
    ],
    [
      "vvvvvvvvvvvvvvvv",
      "bbbbbbbbbbbbbb=c",
      "bbbbbbdbbdbbdb=c",
      "beeeeeeeeeeeeeee",
      "effbbbbbbbbbbbbb",
      "gggffffbbbbbbbbb",
      "fggggggffbbbbbbb",
      " ffggggggfffbbbb",
      "   fggggggggfbbb",
      "    fggggggggffb",
      "     ffggggggggf",
      "      hfgggggggg",
      "       fgggggggg",
      "        fggggggg",
      "        hfgggggg",
      "         hfggggg"
    ],
    [
      "vvvvvvvvvvvvvvvv",
      "bbbbbbbbbbbbbb=c",
      "bbbbbbdbbdbbdb=c",
      "beeeeeeeeeeeeeee",
      "effbbbbbbbbbbbbb",
      "gggffffbbbbbbbbb",
      "ffgggggffbbbbbbb",
      "  ffgggggfffbbbb",
      "    fgggggggfbbb",
      "     ffggggggffb",
      "       fgggggggf",
      "        fggggggg",
      "        hfgggggg",
      "         hfggggg",
      "          hfgggg",
      "           hfggg"
    ],
    [
      "vvvvvvvvvvvvvvvv",
      "bbbbbbbbbbbbbb=c",
      "bbbbbbdbbdbbdb=c",
      "beeeeeeeeeeeeeee",
      "effbbbbbbbbbbbbb",
      "fggffffbbbbbbbbb",
      " ffggggffbbbbbbb",
      "   ffggggfffbbbb",
      "     ffgggggfbbb",
      "       fgggggffb",
      "        fggggggf",
      "         ffggggg",
      "          hfgggg",
      "           hfggg",
      "            hfgg",
      "             hfg"
    ],
    [
      "vvvvvvvvvvvvvvvv",
      "bbbbbbbbbbbbbb=c",
      "bbbbbbdbbdbbdb=c",
      "beeeeeeeeeeeeeee",
      "effbbbbbbbbbbbbb",
      "fggffffbbbbbbbbb",
      " fffgggffbbbbbbb",
      "    ffgggfffbbbb",
      "      ffggggfbbb",
      "        fggggffb",
      "         ffggggf",
      "           fgggg",
      "            fggg",
      "             fgg",
      "              fg",
      "               f"
    ],
    [
      "vvvvvvvvvvvvvvvv",
      "bbbbbbbbbbbbbb=b",
      "bbbbbbdbbdbbdb=b",
      "beeeeeeeeeeeeeee",
      "eiiiiiiiiiiiiiib",
      "iigffffbbbbbbbii",
      "  fffggffbbbbbbb",
      "     ffggfffbbbb",
      "       ffgggfbbb",
      "         ffggffb",
      "           fgggf",
      "            ffgg",
      "             hfg",
      "              hf",
      "               h",
      "                "
    ]
  ]
}