{
  "name": "multi_nuclearpowerplant_21_ground",
  "refpalette": "deceasedcraft:multi_nuclearpowerplant_21/multi_nuclearpowerplant_21_ground_palette",
  "xsize": 16,
  "zsize": 16,
  "slices": [
    [
      "zaaaaaaaaaaaaaaz",
      "aaaaaaaaaaaaaaaa",
      "aaaaaaaaaaaaaaaa",
      "aaaaaaaaaaaaaaaa",
      "abbbbbbbbbbbbbba",
      "bbcddddcccccccbb",
      "cccccccddccccccc",
      "cccccccccdddcccc",
      "ccccccccccccdccc",
      "cccccccccccccddc",
      "     ecccccccccd",
      "           ccccc",
      "               c",
      "                ",
      "                ",
      "                "
    ],
    [
      "               f",
      "                ",
      "                ",
      " gggggggggggggg ",
      "hzazazzzzzzazzzi",
      "zzzzzazzzzzzzazz",
      "zzazzzzzzzzzzzza",
      "zzzzzzzzzzzzzzzz",
      "zzzzzzzazzzzzzzz",
      "ccccccczzzzzzzzz",
      "cccccccccccczzzz",
      "cccccccccccccccc",
      "cccccccccccccccc",
      "cccccccccccccccc",
      "cccccccccccccccc",
      "cccccccccccccccc"
    ],
    [
      "                ",
      "                ",
      "                ",
      "                ",
      " jjjjjjjjjjjjjj ",
      "jj            jj",
      "        k f     ",
      "                ",
      " zf             ",
      "zzazzzz z    z  ",
      "zzzzzzzzzzzzz   ",
      "zzzzzzzzzzzzzzzz",
      "zzzzzzazzzzzzzzz",
      "zzzzzzzzzzzzzzzz",
      "czzzzzzzzzzzzzzz",
      "cccccczzzzzzzzzz"
    ],
    [
      "                ",
      "                ",
      "                ",
      "                ",
      " jjjjjjjjjjjjjj ",
      "jj            jj",
      "                ",
      "                ",
      "                ",
      "     f          ",
      "    f           ",
      "f   f f      f f",
      "         f      ",
      "  z     k  ff   ",
      "zz         f    ",
      "zzzzzz    fz   f"
    ],
    [
      "                ",
      "                ",
      "                ",
      "                ",
      " llllllllllllll ",
      "l              l",
      "                ",
      "                ",
      "                ",
      "                ",
      "                ",
      "                ",
      "                ",
      "                ",
      "                ",
      " f  f           "
    ],
    [
      "                ",
      "                ",
      "                ",
      "                ",
      "                ",
      "                ",
      "                ",
      "                ",
      "                ",
      "                ",
      "                ",
      "                ",
      "                ",
      "                ",
      "                ",
      "                "
    ]
  ]
}