{
  "name": "multi_nuclearpowerplant_21_base2",
  "refpalette": "deceasedcraft:multi_nuclearpowerplant_21/multi_nuclearpowerplant_21_base2_palette",
  "xsize": 16,
  "zsize": 16,
  "slices": [
    [
      "vvvvvvvvvvvvvvvv",
      "aaaaaaaaaaaaaa=b",
      "aaaaaaaaacaaca=b",
      "dddddddddddddddd",
      "              dd",
      "       eeeeeeed=",
      "fff    d      d=",
      "  fffffd  c   =g",
      "      ff      =g",
      "        fff hi=g",
      "           fjk=g",
      "            ff==",
      "l             ff",
      " ll             ",
      "   l            ",
      "    l           "
    ],
    [
      "vvvvvvvvvvvvvvvv",
      "aaaaaaaaaaaaaa=b",
      "aaaaaaaaacaaca=b",
      "dddddddddddddddd",
      "mmmmmmmmmmmmmmdd",
      "mmmmmmmmmmmmmmd=",
      "ffmmmmmm      d=",
      "  ffffmm  c   =g",
      "      ff      =g",
      "        fff no=g",
      "           fpq=g",
      "            ff==",
      "l             ff",
      " ll             ",
      "   l            ",
      "    l           "
    ],
    [
      "vvvvvvvvvvvvvvvv",
      "aaaaaaaaaaaaaa=b",
      "aaaaaacaacaaca=b",
      "adddddcddddddddd",
      "d     c       dd",
      "d     c       d=",
      "ff    c       d=",
      "  ffffccccc   =g",
      "      ff      =g",
      "        fff rs=g",
      "         t fuw=g",
      "            ff==",
      "l             ff",
      " ll             ",
      "   l            ",
      "    l           "
    ],
    [
      "vvvvvvvvvvvvvvvv",
      "aaaaaaaaaaaaaa=b",
      "cccccccaacaaca=b",
      "addddddddddddddd",
      "d             dd",
      "d             d=",
      "ff            d=",
      "  ffff        =g",
      "      ff      =g",
      "        fff   =g",
      "           f  =g",
      "            ff==",
      "l             ff",
      " ll             ",
      "   l            ",
      "    l           "
    ],
    [
      "vvvvvvvvvvvvvvvv",
      "aaaaaaaaaaaaaa=b",
      "aaaaaacaacaaca=b",
      "addddddddddddddd",
      "daaaaaaaaaaaaaaa",
      "xxxaaaaaaaaaaaaa",
      "yyxxxxxaaaaaaaaa",
      "  yyyyxxxaaaaaa=",
      "      yyxxxxaaa=",
      "        yyyxxaa=",
      "           yxxx=",
      "            yyxx",
      "y             yy",
      "xyy             ",
      "xxxy            ",
      "  xxy           "
    ],
    [
      "vvvvvvvvvvvvvvvv",
      "aaaaaaaaaaaaaa=b",
      "aaaaaacaacaaca=b",
      "addddddddddddddd",
      "daaaaaaaaaaaaaaa",
      "xxxaaaaaaaaaaaaa",
      "AAxxxxxaaaaaaaaa",
      "AAAAAAxxxaaaaaaa",
      "AAAAAAAAxxxxaaaa",
      "BBBBAAAAAAAxxaaa",
      "AAAAAAAAAAAAxxxa",
      "AAAAAAAAAAAAAAxx",
      "AAAAAAABBBBAAAAA",
      "xAAAAAAAAAAAAAAA",
      "xxxAAAAAAAAAAAAA",
      "CCxxAAAAAAAAAAAA"
    ]
  ]
}