{
  "name": "multi_nuclearpowerplant_21_base5",
  "refpalette": "deceasedcraft:multi_nuclearpowerplant_21/multi_nuclearpowerplant_21_base5_palette",
  "xsize": 16,
  "zsize": 16,
  "slices": [
    [
      "vvvvvvvvvvvvvvvv",
      "aaaa===========a",
      "aaaa==== b  b =a",
      "acccd=        =c",
      "c   ef        ==",
      "     f        ==",
      "    ef        ==",
      "    d=        =g",
      "      ==      =g",
      "        =======g",
      "           ====g",
      "            ====",
      "           hhh==",
      "           h h  ",
      "           hhh  ",
      "                "
    ],
    [
      "vvvvvvvvvvvvvvvv",
      "aaaa===========a",
      "aaaa==== b  b =a",
      "acccd=        =c",
      "c   ef        ==",
      "     f        ==",
      "    ef        ==",
      "    d=        =g",
      "      ==      =g",
      "        =======g",
      "           ====g",
      "            ====",
      "           hhh==",
      "           h h  ",
      "           hhh  ",
      "                "
    ],
    [
      "vvvvvvvvvvvvvvvv",
      "aaaa===========a",
      "aaaa==== b  b =a",
      "acccd=        =c",
      "c   ef        ==",
      "     f        ==",
      "    ef        ==",
      "    d=        =g",
      "      ==      =g",
      "        =======g",
      "           ====g",
      "            ====",
      "           hhh==",
      "           hhh  ",
      "           hhh  ",
      "                "
    ],
    [
      "vvvvvvvvvvvvvvvv",
      "aaaa===========a",
      "aaaa==== b  b =a",
      "acccd=        =c",
      "c   ef        ==",
      "     f        ==",
      "    ef        ==",
      "    d=        =g",
      "      ==      =g",
      "        =======g",
      "           ====g",
      "            ====",
      "              ==",
      "                ",
      "                ",
      "                "
    ],
    [
      "vvvvvvvvvvvvvvvv",
      "aaaa===========a",
      "aaaa==== b  b =a",
      "acccd=        =c",
      "c   ef        ==",
      "    ef        ==",
      "    ef        ==",
      "    d=        =g",
      "      ==      =g",
      "        =======g",
      "           ====g",
      "            ====",
      "              ==",
      "                ",
      "                ",
      "                "
    ],
    [
      "vvvvvvvvvvvvvvvv",
      "aaaa===========a",
      "aaaa==== b  b =a",
      "acccd=        =c",
      "c   ef        ==",
      "    ef        ==",
      "    ef        ==",
      "    d=        =g",
      "      ==      =g",
      "        =======g",
      "           ====g",
      "            ====",
      "              ==",
      "                ",
      "                ",
      "                "
    ]
  ]
}