{
  "name": "multi_nuclearpowerplant_21_base7",
  "refpalette": "deceasedcraft:multi_nuclearpowerplant_21/multi_nuclearpowerplant_21_base7_palette",
  "xsize": 16,
  "zsize": 16,
  "slices": [
    [
      "vvvvvvvvvvvvvvvv",
      "aaaaaaaaaaaaaaaa",
      "aaaaaaaaaaaaaaaa",
      "bbbbbbbbbbbbbbbb",
      "                ",
      "               =",
      "               =",
      "c      c      =d",
      "              =d",
      "              =d",
      "e      e      =d",
      "               =",
      "           fff  ",
      "          gf f  ",
      "           fff  ",
      "                "
    ],
    [
      "vvvvvvvvvvvvvvvv",
      "aaaaaaaaaaaaaaaa",
      "aaaaaaaaaaaaaaaa",
      "bbbbbbbbbbbbbbbb",
      "                ",
      "               =",
      "               =",
      "c      c      hi",
      "jjjjjjjjjjjjjjhi",
      "jjjjjjjjjjjjjjhi",
      "e      e      hi",
      "               =",
      "           fff  ",
      "           f f  ",
      "           fff  ",
      "                "
    ],
    [
      "vvvvvvvvvvvvvvvv",
      "aaaaaaaaaaaaaaaa",
      "aaaaaaaaaaaaaaaa",
      "bbbbbbbbbbbbbbbb",
      "                ",
      "               =",
      "               =",
      "kkkkkkkkkkkkkkhi",
      "llllllllllllllll",
      "llllllllllllllll",
      "mmmmmmmmmmmmmmhi",
      "               =",
      "           fff  ",
      "           f f  ",
      "           fff  ",
      "                "
    ],
    [
      "vvvvvvvvvvvvvvvv",
      "aaaaaaaaaaaaaaaa",
      "aaaaaaaaaaaaaaaa",
      "bbbbbbbbbbbbbbbb",
      "                ",
      "               =",
      "               =",
      "kkkkkkkkkkkkkkhi",
      "llllllllllllllll",
      "llllllllllllllll",
      "mmmmmmmmmmmmmmhi",
      "               =",
      "           fff  ",
      "           fff  ",
      "           fff  ",
      "                "
    ],
    [
      "vvvvvvvvvvvvvvvv",
      "aaaaaaaaaaaaaaaa",
      "aaaaaaaaaaaaaaaa",
      "bbbbbbbbbbbbbbbb",
      "                ",
      "               =",
      "               =",
      "              hi",
      "nnnnnnnnnnnnnnhi",
      "nnnnnnnnnnnnnnhi",
      "              hi",
      "               =",
      "                ",
      "                ",
      "                ",
      "                "
    ],
    [
      "vvvvvvvvvvvvvvvv",
      "aaaa===========a",
      "aaaa=====o=====a",
      "bbbbbbbbbobbbbbb",
      "oooooooooooooooo",
      "ppppppppppppppp=",
      "ppppppppppppppp=",
      "pppppppppppppp=d",
      "pppppppppppppp=d",
      "pppppppppppppp=d",
      "pppppppppppppp=d",
      "ppppppppppppppp=",
      "pppppppppppppppp",
      "pppppppppppppppp",
      "pppppppppppppppp",
      "pppppppppppppppp"
    ]
  ]
}