{
  "name": "multi_nuclearpowerplant_21_base6",
  "refpalette": "deceasedcraft:multi_nuclearpowerplant_21/multi_nuclearpowerplant_21_base6_palette",
  "xsize": 16,
  "zsize": 16,
  "slices": [
    [
      "vvvvvvvvvvvvvvvv",
      "aaaa===========a",
      "aaaa====bcbbbb=a",
      "dddde=bbbbbbbb=d",
      "dbbbbbbbbbbbbb==",
      "bbbbbbbbbbbbbb==",
      "bbbbbbbbbbbbbb==",
      "bbbbe=bbbbbbbb=f",
      "bbbbbb==bbbbbb=f",
      "bbbbbbbb=======f",
      "bbbbbbbbbbb====f",
      "bbbbbbbbbbbb====",
      "bbbbbbbbbbbbbb==",
      "bbbbbbbbbbbbbbbb",
      "bbbbbbbbbbbbbbbb",
      "bbbbbbbbbbbbbbbb"
    ],
    [
      "vvvvvvvvvvvvvvvv",
      "aaaa===========a",
      "aaaa====bcbbbb=a",
      "aggge=hbiiiiii=g",
      "g   jkhbilllll==",
      "    mnhbilllll==",
      "    jkhbilllll==",
      "    e=hbiiiiii=f",
      "      ==bbbbbb=f",
      "        =======f",
      "          o====f",
      "          pq====",
      "          pqqq==",
      "          pqqqqq",
      "          pqqqqq",
      "          pqqqqq"
    ],
    [
      "vvvvvvvvvvvvvvvv",
      "aaaa===========a",
      "aaaa==== c    =a",
      "aggge=        =g",
      "g   jk   rrrrr==",
      "     s   rrrrr==",
      "    jk   rrrrr==",
      "    e=        =f",
      "      ==      =f",
      "        =======f",
      "           ====f",
      "            ====",
      "           t t==",
      "            u   ",
      "           t t  ",
      "                "
    ],
    [
      "vvvvvvvvvvvvvvvv",
      "aaaa===========a",
      "aaaa==== c    =a",
      "aggge=        =g",
      "g   jk   wrrrx==",
      "    y!   Awwwx==",
      "    jk   wrrrx==",
      "    e=        =f",
      "      ==      =f",
      "        =======f",
      "           ====f",
      "            ====",
      "           uuu==",
      "          Bu u  ",
      "           uuu  ",
      "                "
    ],
    [
      "vvvvvvvvvvvvvvvv",
      "aaaa===========a",
      "aaaa==== c    =a",
      "aggge=        =g",
      "g   jk   ACDCx==",
      "    jk  EACCCx==",
      "    jk   ACCCx==",
      "    e=        =f",
      "      ==      =f",
      "        =======f",
      "           ====f",
      "            ====",
      "           uuu==",
      "           u u  ",
      "           uuu  ",
      "                "
    ],
    [
      "vvvvvvvvvvvvvvvv",
      "aaaa===========a",
      "aaaa==== c  c =a",
      "aggge=      c =g",
      "g   jk     CFx==",
      "    jk    CCCx==",
      "    jk     C x==",
      "    e=        =f",
      "      ==      =f",
      "        =======f",
      "           ====f",
      "            ====",
      "           uuu==",
      "           u u  ",
      "           uuu  ",
      "                "
    ]
  ]
}