{
  "name": "multi_nuclearpowerplant_21_base9",
  "refpalette": "deceasedcraft:multi_nuclearpowerplant_21/multi_nuclearpowerplant_21_base9_palette",
  "xsize": 16,
  "zsize": 16,
  "slices": [
    [
      "vvvvvvvvvvvvvvvv",
      "aaaaaaaaaaaaaaaa",
      "aaaaaaaaaaaaaaaa",
      "aaaaaaaaaaaaaaaa",
      "aaaaaaaaaaaaaaaa",
      "aaaaaaaaaaaaaaaa",
      "aaaaaaaaaaaaaaaa",
      "aaaaaaaaaaaaaaaa",
      "aaaaaaaaaaaaaaaa",
      "aaaaaaaaaaaaaaaa",
      "aaaaaaaaaaaaaaaa",
      "aaaaaaaaaaaaaaaa",
      "aaaaaaaaaaaaaaaa",
      "aaaaaaaaaaaaaaaa",
      "aaaaaaaaaaaaaaaa",
      "aaaaaaaaaaaaaaaa"
    ],
    [
      "vvvvvvvvvvvvvvvv",
      "aaaaaaaaaaaaaaaa",
      "aaaaaaaaaaaaaaaa",
      "aaaaaaaaaaaaaaaa",
      "aaaaaaaaaaaaaaaa",
      "aaaaaaaaaaaaaaaa",
      "aaaaaaaaaaaaaaaa",
      "aaaaaaaaaaaaaaaa",
      "aaaaaaaaaaaaaaaa",
      "aaaaaaaaaaaaaaaa",
      "aaaaaaaaaaaaaaaa",
      "aaaaaaaaaaaaaaaa",
      "aaaaaaaaaaaaaaaa",
      "aaaaaaaaaaaaaaaa",
      "aaaaaaaaaaaaaaaa",
      "aaaaaaaaaaaaaaaa"
    ],
    [
      "vvvvvvvvvvvvvvvv",
      "aaaaaaaaaaaaaaaa",
      "aaaaaaaaaaaaaaaa",
      "aaaaaaaaaaaaaaaa",
      "aaaaaaaaaaaaaaaa",
      "aaaaaaaaaaaaaaaa",
      "aaaaaaaaaaaaaaaa",
      "aaaaaaaaaaaaaaaa",
      "aaaaaaaaaaaaaaaa",
      "aaaaaaaaaaaaaaaa",
      "aaaaaaaaaaaaaaaa",
      "aaaaaaaaaaaaaaaa",
      "aaaaaaaaaaaaaaaa",
      "aaaaaaaaaaaaaaaa",
      "aaaaaaaaaaaaaaaa",
      "aaaaaaaaaaaaaaaa"
    ],
    [
      "vvvvvvvvvvvvvvvv",
      "aaaaaaaaaaaaaaaa",
      "aaaaaaaaaaaaaaaa",
      "aaaaaaaaaaaaaaab",
      "aaaaaaaaaaaaaaab",
      "aaaaaaaaaaaaaaab",
      "aaaaaaaaaaaaaaab",
      "aaaaaaaaaaaaaaab",
      "aaaaaaaaaaaaaaab",
      "aaaaaaaaaaaaaaab",
      "aaaaaaaaaaaaaaab",
      "aaaaaaaaaaaaaaab",
      "aaaaaaaaaaaaaaab",
      "aaaaaaaaaaaaaaab",
      "aaaaaaaaaaaaaaab",
      "aaaaaaaaaaaaaaab"
    ],
    [
      "vvvvvvvvvvvvvvvv",
      "aaaaaaaaaaaaaaaa",
      "aaaaaaaaaaaaaaaa",
      "aaaaaaaaaaaaaaab",
      "aaaaaaaaaaaaaaab",
      "aaaaaaaaaaaaaaab",
      "aaaaaaaaaaaaaaab",
      "aaaaaaaaaaaaaaab",
      "aaaaaaaaaaaaaaab",
      "aaaaaaaaaaaaaaab",
      "aaaaaaaaaaaaaaab",
      "aaaaaaaaaaaaaaab",
      "aaaaaaaaaaaaaaab",
      "aaaaaaaaaaaaaaab",
      "aaaaaaaaaaaaaaab",
      "aaaaaaaaaaaaaaab"
    ],
    [
      "vvvvvvvvvvvvvvvv",
      "aaaaaaaaaaaaaaaa",
      "aaaaaaaaaaaaaaaa",
      "aaaaaaaaaaaaaaab",
      "aaaaaaaaaaaaaaab",
      "aaaaaaaaaaaaaaab",
      "aaaaaaaaaaaaaaab",
      "aaaaaaaaaaaaaaab",
      "aaaaaaaaaaaaaaab",
      "aaaaaaaaaaaaaaab",
      "aaaaaaaaaaaaaaab",
      "aaaaaaaaaaaaaaab",
      "aaaaaaaaaaaaaaab",
      "aaaaaaaaaaaaaaab",
      "aaaaaaaaaaaaaaab",
      "aaaaaaaaaaaaaaab"
    ]
  ]
}