{
  "name": "multi_nuclearpowerplant_21_base4",
  "refpalette": "deceasedcraft:multi_nuclearpowerplant_21/multi_nuclearpowerplant_21_base4_palette",
  "xsize": 16,
  "zsize": 16,
  "slices": [
    [
      "vvvvvvvvvvvvvvvv",
      "aaaa===========a",
      "aaaa==== b  b =a",
      "acccd=        =c",
      "c   ef        ==",
      "     f        ==",
      "    ef        ==",
      "    d=        =g",
      "      ==      =g",
      "        =======g",
      "           ====g",
      "            ====",
      "              ==",
      "                ",
      "                ",
      "                "
    ],
    [
      "vvvvvvvvvvvvvvvv",
      "aaaa===========a",
      "aaaa==== b  b =a",
      "acccd=        =c",
      "c   ef        ==",
      "     f        ==",
      "    ef        ==",
      "    d=        =g",
      "      ==      =g",
      "        =======g",
      "           ====g",
      "            ====",
      "              ==",
      "                ",
      "                ",
      "                "
    ],
    [
      "vvvvvvvvvvvvvvvv",
      "aaaa===========a",
      "aaaa==== b  b =a",
      "acccd=        =c",
      "c   ef        ==",
      "     f        ==",
      "    ef        ==",
      "    d=        =g",
      "      ==      =g",
      "        =======g",
      "           ====g",
      "            ====",
      "              ==",
      "                ",
      "                ",
      "                "
    ],
    [
      "vvvvvvvvvvvvvvvv",
      "aaaa===========a",
      "aaaa==== b  b =a",
      "acccd=        =c",
      "c   ef        ==",
      "     f        ==",
      "    ef        ==",
      "    d=        =g",
      "      ==      =g",
      "        =======g",
      "           ====g",
      "            ====",
      "              ==",
      "                ",
      "                ",
      "                "
    ],
    [
      "vvvvvvvvvvvvvvvv",
      "aaaa===========a",
      "aaaa==== b  b =a",
      "acccd=        =c",
      "c   ef        ==",
      "    ef        ==",
      "    ef        ==",
      "    d=        =g",
      "      ==      =g",
      "        =======g",
      "           ====g",
      "            ====",
      "              ==",
      "                ",
      "                ",
      "                "
    ],
    [
      "vvvvvvvvvvvvvvvv",
      "hhhh===========a",
      "hhhh====hbhhbh=a",
      "hcccd=hhhhhhhh=c",
      "c   ehhhhhhhhh==",
      "    ehhhhhhhhh==",
      "    ehhhhhhhhh==",
      "    d=hhhhhhhh=g",
      "      ==hhhhhh=g",
      "        =======g",
      "           ====g",
      "            ====",
      "              ==",
      "i               ",
      "iii             ",
      "  ii            "
    ]
  ]
}