{
  "name": "multi_verticalschool_15_floor13",
  "refpalette": "deceasedcraft:multi_verticalschool_15/multi_verticalschool_15_floor13_palette",
  "xsize": 16,
  "zsize": 16,
  "slices": [
    [
      "                ",
      "                ",
      "                ",
      "                ",
      "                ",
      "                ",
      "                ",
      "                ",
      "                ",
      "                ",
      "                ",
      "                ",
      "                ",
      "                ",
      "                ",
      "                "
    ],
    [
      "                ",
      "                ",
      "                ",
      "                ",
      "                ",
      "                ",
      "                ",
      "                ",
      "                ",
      "                ",
      "                ",
      "                ",
      "                ",
      "                ",
      "                ",
      "                "
    ],
    [
      "                ",
      "                ",
      "                ",
      "                ",
      "                ",
      "                ",
      "aaaaaa          ",
      "      aa        ",
      "bbbbbb  a       ",
      "cccccbb a       ",
      "bbbbbcbb a      ",
      "bbbbbbcb a      ",
      "bbbbbbcb a      ",
      "bbbbbbcb a      ",
      "bbbbbbcb a      ",
      "bbbbbbcb a      "
    ],
    [
      "                ",
      "                ",
      "                ",
      "                ",
      "                ",
      "dddddd          ",
      "eeeeeedd        ",
      "ffffffeed       ",
      "ffffffffed      ",
      "ffffffffed      ",
      "fffffffffed     ",
      "fffffffffed     ",
      "fffffffffed     ",
      "fffffffffed     ",
      "fffffffffed     ",
      "fffffffffed     "
    ],
    [
      "                ",
      "                ",
      "                ",
      "                ",
      "                ",
      "dddddd          ",
      "eeeeeedd        ",
      "      eed       ",
      "       ged      ",
      "  h     ed      ",
      "  i  i   ed     ",
      "  j  k   ed     ",
      "  k  h   ed     ",
      "  h  k   ed     ",
      "         ed     ",
      "         ed     "
    ],
    [
      "                ",
      "                ",
      "                ",
      "                ",
      "                ",
      "dddddd          ",
      "lllleedd        ",
      "      eed       ",
      "       med      ",
      "  k     ed      ",
      "  j  h   ed     ",
      "  i  j   ed     ",
      "  n  k   ld     ",
      "  k  i   ld     ",
      "         ld     ",
      "         ld     "
    ]
  ]
}