{
  "name": "multi_verticalschool_15_floor1",
  "refpalette": "deceasedcraft:multi_verticalschool_15/multi_verticalschool_15_floor1_palette",
  "xsize": 16,
  "zsize": 16,
  "slices": [
    [
      "                ",
      "                ",
      "                ",
      "                ",
      "                ",
      "                ",
      "                ",
      "aaaaaaaaaaaaaaaa",
      "bbbbbbbbbbbbbbbb",
      "                ",
      "                ",
      "  c     c     c ",
      "                ",
      "                ",
      "                ",
      "                "
    ],
    [
      "                ",
      "                ",
      "                ",
      "                ",
      "                ",
      "                ",
      "                ",
      "aaaaaaaaaaaaaaaa",
      "dddddddddddddddd",
      "eeeeeeeeeeeeeeee",
      "efffffffffffffff",
      "efgfffffgfffffgf",
      "efffffffffffffff",
      "effffffffffffhhh",
      "effffffffffhh   ",
      "effffffffffh    "
    ],
    [
      "                ",
      "                ",
      "                ",
      "                ",
      "                ",
      "                ",
      "                ",
      "aaaaaaaaaaaaaaaa",
      "iiiiiiiiiiiiiiii",
      "jjjjjjjjjjjjjjjj",
      "kkkkllkkklkllkkk",
      "llllllllllllllll",
      "llllllllllllllll",
      "kklklkkllkklkjjj",
      "klkkkkkkkkkjjfff",
      "kkkkkkkkkkkjfmmm"
    ],
    [
      "                ",
      "                ",
      "                ",
      "                ",
      "                ",
      "                ",
      "                ",
      "nnnnnnnnnnnnnnnn",
      "oooooooooooooooo",
      "pppppppppppppppp",
      "                ",
      "                ",
      "                ",
      "             qqr",
      "           qr   ",
      "           q    "
    ],
    [
      "                ",
      "                ",
      "                ",
      "                ",
      "                ",
      "                ",
      "                ",
      "                ",
      "                ",
      "sssss ssss sssss",
      "                ",
      "                ",
      "                ",
      "                ",
      "                ",
      "                "
    ],
    [
      "                ",
      "                ",
      "                ",
      "                ",
      "                ",
      "                ",
      "                ",
      "                ",
      "                ",
      "                ",
      "                ",
      "                ",
      "                ",
      "                ",
      "                ",
      "                "
    ]
  ]
}