{
  "name": "multi_verticalschool_15_base1",
  "refpalette": "deceasedcraft:multi_verticalschool_15/multi_verticalschool_15_base1_palette",
  "xsize": 16,
  "zsize": 16,
  "slices": [
    [
      "vvvvvvvvvvvvvvvv",
      "aaaaaaaaaaaaaaaa",
      "                ",
      "                ",
      "                ",
      "                ",
      "                ",
      "                ",
      "                ",
      "                ",
      "            b   ",
      "           cdeff",
      "           cg hi",
      "           cj  k",
      "           c  hi",
      "           cdfff"
    ],
    [
      "vvvvvvvvvvvvvvvv",
      "aaaaaaaaaaaaaaaa",
      "                ",
      "                ",
      "                ",
      "                ",
      "                ",
      "                ",
      "                ",
      "                ",
      "            b   ",
      "           cdlmn",
      "           c    ",
      "           c    ",
      "           c    ",
      "           cdnnn"
    ],
    [
      "vvvvvvvvvvvvvvvv",
      "aaaaaaaaaaaaaaaa",
      "                ",
      "                ",
      "                ",
      "                ",
      "                ",
      "                ",
      "                ",
      "                ",
      "                ",
      "            oppp",
      "            qrrr",
      "            qr s",
      "            qrrr",
      "            oppp"
    ],
    [
      "vvvvvvvvvvvvvvvv",
      "aaaaaaaaaaaaaaaa",
      "                ",
      "                ",
      "                ",
      "                ",
      "                ",
      "                ",
      "                ",
      "                ",
      "                ",
      "                ",
      "                ",
      "              t ",
      "                ",
      "                "
    ],
    [
      "vvvvvvvvvvvvvvvv",
      "aaaaaaaaaaaaaaaa",
      "                ",
      "                ",
      "                ",
      "                ",
      "                ",
      "                ",
      "                ",
      "                ",
      "                ",
      "                ",
      "                ",
      "                ",
      "                ",
      "                "
    ],
    [
      "vvvvvvvvvvvvvvvv",
      "uuuuuuuuuuuuuuuu",
      "wwwwwwwwwwwwwwww",
      "wwwwwwwwwwwwwwww",
      "wwwwwwwwwwwwwwww",
      "wwwwwwwwwwwwwwww",
      "wwwwwxxwwwwwwwxx",
      "wwwwwwwwwwwwwwww",
      "wwwwwwwwwwwwwwww",
      "wwwwwwwwwwwwwwww",
      "wwwwwwwwwwwwwwww",
      "wwwwwwwwwwwwwwww",
      "wwwwwwwwwwwwwwww",
      "wwwwwxxwwwwwwwxx",
      "wwwwwwwwwwwwwwww",
      "wwwwwwwwwwwwwwww"
    ]
  ]
}