{
  "name": "multi_verticalschool_15_floor14",
  "refpalette": "deceasedcraft:multi_verticalschool_15/multi_verticalschool_15_floor14_palette",
  "xsize": 16,
  "zsize": 16,
  "slices": [
    [
      "                ",
      "                ",
      "                ",
      "                ",
      "                ",
      "aaaaaa          ",
      "bbbbbbaa        ",
      "      bba       ",
      "       cba      ",
      "        ba      ",
      "         ba     ",
      "         ba     ",
      "         ba     ",
      "         ba     ",
      "         ba     ",
      "         ba     "
    ],
    [
      "                ",
      "                ",
      "                ",
      "                ",
      "                ",
      "aaaaaa          ",
      "bbbbbbaa        ",
      "      bba       ",
      "        ba      ",
      "        ba      ",
      "         ba     ",
      "         ba     ",
      "         ba     ",
      "         ba     ",
      "         ba     ",
      "         ba     "
    ],
    [
      "                ",
      "                ",
      "                ",
      "                ",
      "                ",
      "aaaaaa          ",
      "bbbbbbaa        ",
      "      bba       ",
      "        ba      ",
      "        ba      ",
      "         ba     ",
      "         ba     ",
      "         ba     ",
      "         ba     ",
      "         ba     ",
      "         ba     "
    ],
    [
      "                ",
      "                ",
      "                ",
      "                ",
      "                ",
      "aaaaaa          ",
      "bbbbbbaa        ",
      "      bba       ",
      "        ba      ",
      "        ba      ",
      "         ba     ",
      "         ba     ",
      "         ba     ",
      "         ba     ",
      "         ba     ",
      "         ba     "
    ],
    [
      "                ",
      "                ",
      "                ",
      "                ",
      "                ",
      "aaaaaa          ",
      "bbbbbbaa        ",
      "ddddddbba       ",
      "ddddddddba      ",
      "eeeeddddba      ",
      "dddddddddba     ",
      "dddddddddba     ",
      "dddddddddba     ",
      "dddddddddba     ",
      "eeeedddddba     ",
      "dddddddddba     "
    ],
    [
      "                ",
      "                ",
      "                ",
      "                ",
      "                ",
      "aaaaaa          ",
      "bbbbbbaa        ",
      "bbbbbbbba       ",
      "ffffffbbba      ",
      "gggggffbba      ",
      "ggggggffbba     ",
      "gggggggfbba     ",
      "gggggggfbba     ",
      "gggggggfbba     ",
      "gggggggfbba     ",
      "gggggggfbba     "
    ]
  ]
}