{
  "name": "multi_policestation_0_ground",
  "refpalette": "deceasedcraft:multi_policestation_0/multi_policestation_0_ground_palette",
  "xsize": 16,
  "zsize": 16,
  "slices": [
    [
      "HHHHHHHHHHHHHHHH",
      "HHHHHHHHHHHHHHHH",
      "HHaabbccccccccbb",
      "HHaabbccccccccbb",
      "HHaabbccccccccbb",
      "HHaabbccccccccbb",
      "HHaabbccccccccbb",
      "HHaabbccccccccbb",
      "HHaabbccccccccbb",
      "HHaabbccccccccbb",
      "HHaadbccccccccbb",
      "dddbbdccccccccbb",
      "dccccccccccccceb",
      "bccccccccccccceb",
      "dccccccccccccceb",
      "dccccccccccccceb"
    ],
    [
      "                ",
      "                ",
      "     fgg    ggf ",
      "     fg      gf ",
      "     fg  h i gf ",
      "     fg  j k gf ",
      "     fg      gf ",
      "     fg      gf ",
      "     fg  l m gf ",
      "     fg  n o gf ",
      "     fg  ppp gf ",
      "      g  qrs gf ",
      " t    g uwxwyge ",
      "      g ABCBDEe ",
      "      g FBIBJEK ",
      "      g uwLwyEK "
    ],
    [
      "                ",
      "                ",
      "      ggMMMMgg  ",
      "      g      g  ",
      "      g      g  ",
      "      g      g  ",
      "      g      g  ",
      "      g      g  ",
      "      g      g  ",
      "      g      g  ",
      "      g      g  ",
      "      g  NON g  ",
      " t    g  OPO gQ ",
      "      g  @@@ RQ ",
      "      g F@S@J T ",
      "      g  UBU VT "
    ],
    [
      "                ",
      "                ",
      "      ggMMMMgg  ",
      "      g      g  ",
      "      W      g  ",
      "      W XXXX g  ",
      "      W      g  ",
      "      Y      g  ",
      "      Y      g  ",
      "      W      g  ",
      "      W XXX  g  ",
      "      W      g  ",
      " t    Y      gQ ",
      "      Y  ZO0  Q ",
      "      W  1 1  T ",
      "      W XX1X 2T "
    ],
    [
      "                ",
      "                ",
      "      gggggggg  ",
      "      g333333g  ",
      "      g333333g  ",
      "      g333333g  ",
      "      g333333g  ",
      "      g344443g  ",
      "      g355553g  ",
      "      g333333g  ",
      "      g333333g  ",
      "      g333333g  ",
      " t    g344443gQ ",
      "      g355553gQ ",
      "      g333333gT ",
      "      g333333gT "
    ],
    [
      "                ",
      "                ",
      "                ",
      "                ",
      "                ",
      "                ",
      "                ",
      "                ",
      "                ",
      "                ",
      "                ",
      "                ",
      " t            Q ",
      "              Q ",
      "              T ",
      "    6         T "
    ]
  ]
}