{
  "name": "multi_oasiscondo_6_ground",
  "refpalette": "deceasedcraft:multi_oasiscondo_6/multi_oasiscondo_6_ground_palette",
  "xsize": 16,
  "zsize": 16,
  "slices": [
    [
      " abc       ddddd",
      " abc      efffff",
      " abg     dffhhhf",
      " abci   dffhhhhh",
      "jakcl   dfhhhmhh",
      " abcl    fmhhhhh",
      " abcn   dfhhhhhh",
      " abg    dfhmhhhh",
      " abc    dfhhhhhh",
      " abc    dfmopqqp",
      " abc    dfhp   p",
      " abc    dffp    ",
      " pkg     dfprrpr",
      "jposbbbbbbprrrrr",
      "ttppuuuuuuprrrrr",
      "ttjrrrrrrrrjrrrr"
    ],
    [
      " w              ",
      " w              ",
      " w x        yyy ",
      " w         yyyyy",
      "jw        yyy yy",
      " w         yyyyy",
      " w        yyyyyy",
      " w x      y yyyy",
      " w        yyyyyy",
      " w         opAAp",
      " w        yp   p",
      " w         p   p",
      " p x       pBBpC",
      "jpo       p DE  ",
      "FoppIIJKIIp     ",
      "  j        j    "
    ],
    [
      "                ",
      "   L            ",
      "   f            ",
      "                ",
      "j               ",
      "                ",
      "                ",
      "   f            ",
      "                ",
      "           opAAp",
      "           p   p",
      "           p   p",
      " p fL      p  p ",
      "jpo       p MN  ",
      "FoppIIOPIIp     ",
      "  j        j    "
    ],
    [
      "                ",
      "   f            ",
      "  Lff           ",
      "   f            ",
      "j               ",
      "                ",
      "   f            ",
      "  LfL           ",
      "   f            ",
      "           opAAp",
      "           p   p",
      "   L       p   p",
      " p ff      pQQp ",
      "jpo       p RS  ",
      "ToppIIUUIIp     ",
      "  j        j    "
    ],
    [
      "                ",
      "                ",
      "  ffL           ",
      "   f            ",
      "j               ",
      "                ",
      "   f            ",
      "  fff           ",
      "   f            ",
      "           opAAp",
      "           p   p",
      "   f       p   p",
      " pLff      pppp ",
      "jpof      p     ",
      " oppIIIIIIp     ",
      "  j        j    "
    ],
    [
      "                ",
      "                ",
      "   f            ",
      "                ",
      "j               ",
      "                ",
      "   L            ",
      "  Lff           ",
      "   f            ",
      "           opAAp",
      "           p   p",
      "   f       p   p",
      " pffL      pppp ",
      "jpoL      p     ",
      " oppIIIIIIp     ",
      "  j        j    "
    ]
  ]
}