{
  "name": "multi_oasiscondo_6_base3",
  "refpalette": "deceasedcraft:multi_oasiscondo_6/multi_oasiscondo_6_base3_palette",
  "xsize": 16,
  "zsize": 16,
  "slices": [
    [
      "vv         a    ",
      "bv         a    ",
      "bv         a    ",
      "bv         c    ",
      "dvd        d    ",
      "bv         c    ",
      "bv         a    ",
      "bv         a    ",
      "bv         c    ",
      "bv         ceeee",
      "bv         a   e",
      "bv         a   e",
      "fv         ceeee",
      "dvd        d    ",
      "fv         cg   ",
      "hvd        diiii"
    ],
    [
      "vv         a    ",
      "bv         a    ",
      "bv         a    ",
      "bv         c    ",
      "dvd        d    ",
      "bv         c    ",
      "bv         a    ",
      "bv         a    ",
      "bv         c    ",
      "fv         ceeee",
      "fv         a   e",
      "fv         a   e",
      "hv         ceeee",
      "dvd        d    ",
      "jv         cg   ",
      " vd        diiii"
    ],
    [
      "vv         a    ",
      "bv         a    ",
      "bv         a    ",
      "bv         c    ",
      "dvd        d    ",
      "bv         c    ",
      "fv         a    ",
      "fv         a    ",
      "fv         c    ",
      "hv         ceeee",
      "kv         a   e",
      "jv         a   e",
      " v         ceeee",
      "dvd        d    ",
      " v         cg   ",
      " vd        diiii"
    ],
    [
      "vv         a    ",
      "bv         a    ",
      "bv         a    ",
      "fv         c    ",
      "dvd        d    ",
      "fv         c    ",
      "hv         a    ",
      "kv         a    ",
      "jv         c    ",
      " v         ceeee",
      " v         a   e",
      " v         a   e",
      " v         ceeee",
      "dvd        dl   ",
      " v         cg   ",
      " vd        diiii"
    ],
    [
      "vvmnnnnnnnnmnnnn",
      "fvmnnnnnnnnmnnnn",
      "fvmnnnnnnnnmnnnn",
      "hvmnnnnnnnnmnnnn",
      "dvommmmmmmmommmm",
      "jvmnnnnnnnnmnnnn",
      " vmnnnnnnnnmnnnn",
      " vmnnnnnnnnmnnnn",
      " vmnnnnnnnnmnnnn",
      " vmnnnnnnnnmeeee",
      " vmnnnnnnnnm   e",
      " vmnnnnnnnnm   e",
      " vmnnnnnnnnmeeee",
      "dvommmmmmmmommmm",
      " v         cg   ",
      " vd        diiii"
    ],
    [
      "hvmppppppppppppp",
      "kvmppppppppppppp",
      "jvmppppppppppppp",
      " vmppppppppppppp",
      "omqppppppppppppp",
      " vmppppppppppppp",
      " vmppppppppppppp",
      " vmppppppppppppp",
      " vmppppppppppppp",
      " vmppppppppperre",
      " vmppppppppm   e",
      " vmppppppppm   e",
      " vmppppppppeeeee",
      "omqmmmmmmmmommmm",
      "mvmnnnnnnnnmgggg",
      "mvommmmmmmmommmm"
    ]
  ]
}