{
  "name": "multi_oasiscondo_6_floor11",
  "refpalette": "deceasedcraft:multi_oasiscondo_6/multi_oasiscondo_6_floor11_palette",
  "xsize": 16,
  "zsize": 16,
  "slices": [
    [
      "aaab            ",
      "aaab            ",
      "aaab            ",
      "aaab            ",
      "caabd           ",
      "aaab            ",
      "aaab            ",
      "aaab            ",
      "aaabe           ",
      "aaaab      fghhg",
      "aaaabe     g   g",
      "aaaaaiie   g    ",
      "aaaaaaaiiiigaaga",
      "caaaaaaaaaaaaaaa",
      "aaaaaaaaaaaaaaaa",
      "aacaaaaaaaacaaaa"
    ],
    [
      "   j            ",
      "   j            ",
      "   j            ",
      "   j            ",
      "c  j            ",
      "   j            ",
      "   j            ",
      "   j            ",
      "   jj           ",
      "    j      fgkkg",
      "    jj     g   g",
      "     jjj   g   g",
      "       jjjjgllgm",
      "c           no  ",
      "                ",
      "  c        c    "
    ],
    [
      "                ",
      "                ",
      "                ",
      "                ",
      "c  j            ",
      "                ",
      "                ",
      "                ",
      "                ",
      "           fgkkg",
      "     j     g   g",
      "           g   g",
      "           g  gp",
      "c           qr  ",
      "                ",
      "  c        c    "
    ],
    [
      "                ",
      "                ",
      "                ",
      "                ",
      "c  j            ",
      "                ",
      "                ",
      "                ",
      "                ",
      "           fgkkg",
      "     j     g   g",
      "           g   g",
      "           gssgt",
      "c           uw  ",
      "                ",
      "  c        c    "
    ],
    [
      "  x             ",
      "  x             ",
      "  x             ",
      "  x             ",
      "c xj            ",
      "  x             ",
      "  x             ",
      "  x             ",
      "  xy            ",
      "   x       fgkkg",
      "   xyj     g   g",
      "     A     g   g",
      "     BBA   gggg ",
      "c      BBBB     ",
      "                ",
      "  c        c    "
    ],
    [
      "CCCD            ",
      "CCCD            ",
      "CCCD            ",
      "CCCD            ",
      "cCCD            ",
      "CCCD            ",
      "CCCD            ",
      "CCCD            ",
      "CCCDD           ",
      "CCCCD      fgkkg",
      "CCCCDD     g   g",
      "CCCCCDDD   g   g",
      "CCCCCCCDDDDggggE",
      "cCCCCCCCCCCCCCCC",
      "CCCCCCCCCCCCCCCC",
      "CCcCCCCCCCCcCCCC"
    ]
  ]
}