{
  "name": "multi_oasiscondo_6_floor1",
  "refpalette": "deceasedcraft:multi_oasiscondo_6/multi_oasiscondo_6_floor1_palette",
  "xsize": 16,
  "zsize": 16,
  "slices": [
    [
      "                ",
      "                ",
      "   a            ",
      "                ",
      "b               ",
      "                ",
      "                ",
      "   c            ",
      "                ",
      "           deffe",
      "           e   e",
      "           e   e",
      " e c       eeee ",
      "bed       e     ",
      " deegggggge     ",
      "  b        b    "
    ],
    [
      "                ",
      "                ",
      "                ",
      "                ",
      "b               ",
      "                ",
      "                ",
      "   a            ",
      "                ",
      "           dehhe",
      "           e   e",
      "           e   e",
      " e         eeee ",
      "bed       e     ",
      " deegggggge     ",
      "  b        b    "
    ],
    [
      "                ",
      "                ",
      "                ",
      "                ",
      "b               ",
      "                ",
      "                ",
      "                ",
      "                ",
      "           dehhe",
      "           e   e",
      "           e   e",
      " e         eeee ",
      "bed       e     ",
      " deegggggge     ",
      "  b        b    "
    ],
    [
      "                ",
      "                ",
      "                ",
      "                ",
      "b               ",
      "                ",
      "                ",
      "                ",
      "                ",
      "           dehhe",
      "           e   e",
      "           e   e",
      " e         eeee ",
      "bed       e     ",
      " deegggggge     ",
      "  b        b    "
    ],
    [
      "  e             ",
      "  e             ",
      "  e             ",
      "  e             ",
      "b e             ",
      "  e             ",
      "  e             ",
      "  e             ",
      "  e             ",
      "  e        dehhe",
      "  e        e   e",
      "  e        e   e",
      " ee        eeee ",
      "beeeeeeeeee     ",
      " deeeeeeeee     ",
      "  b        b    "
    ],
    [
      "iiij            ",
      "iiij            ",
      "iiij            ",
      "iiij            ",
      "biij            ",
      "iiij            ",
      "iiij            ",
      "iiij            ",
      "iiij            ",
      "iiij       dehhe",
      "iiij       e   e",
      "iiijj      e   e",
      "iiijjjjjjjjeeeek",
      "biiiiiiiiiiiiiii",
      "iiiiiiiiiiiiiiii",
      "iibiiiiiiiibiiii"
    ]
  ]
}