{
  "name": "multi_oasiscondo_6_base4",
  "refpalette": "deceasedcraft:multi_oasiscondo_6/multi_oasiscondo_6_base4_palette",
  "xsize": 16,
  "zsize": 16,
  "slices": [
    [
      "aaaaaaaaaaaaaaaa",
      "aaaaaaaaaaaaaaaa",
      "aaaaaaaaaaaaaaaa",
      "aaaaaaaaaaaaaaaa",
      "aaaaaaaaaaaaaaaa",
      "aaaaaaaaaaaaaaaa",
      "aaaaaaaaaaaaaaaa",
      "aaaaaaaaaaaaaaaa",
      "aaaaaaaaaaaaaaaa",
      "aaaaaaaaaaaaaaaa",
      "aaaaaaaaaaaaaaaa",
      "aaaaaaaaaaaaaaaa",
      "aaaaaaaaaaaaaaaa",
      "aaaaaaaaaaaaaaaa",
      "aaaaaaaaaaaaaaaa",
      "aaaaaaaaaaaaaaaa"
    ],
    [
      "aaaaaaaaaaaaaaaa",
      "aaaaaaaaaaaaaaaa",
      "aaaaaaaaaaaaaaaa",
      "aaaaaaaaaaaaaaaa",
      "babaaaaaaaabaaaa",
      "aaaaaaaaaaaaaaaa",
      "aaaaaaaaaaaaaaaa",
      "aaaaaaaaaaaaaaaa",
      "aaaaaaaaaaaaaaaa",
      "aaaaaaaaaaaacccc",
      "aaaaaaaaaaaacccc",
      "aaaaaaaaaaaacccc",
      "aaaaaaaaaaaacccc",
      "babaaaaaaaabaaaa",
      "aaaaaaaaaaaaaaaa",
      "aabaaaaaaaabaaaa"
    ],
    [
      "vvHHHHHHHHdeffff",
      "avHHHHHHHHdeffff",
      "avHHHHHHHHdeffff",
      "avHHHHHHHHdeffff",
      "bvbdddHHHHdbgfff",
      "avHHHHHHHHdhffff",
      "avHHHHHHHHdhffff",
      "avHHHHHHHHdhffff",
      "avHHHHHHHHdhffff",
      "avHHHHHHHHdhiff ",
      "avHHHHHHHHdh   j",
      "avHHHHHHHHdh    ",
      "avHHHHHHHHdhiiii",
      "bvbdddHHHHdbffff",
      "avddddHHHHdhkfff",
      "avbdddHHHHdbeeee"
    ],
    [
      "vvlmmn      o   ",
      "avpqqr     s    ",
      "av  t      s    ",
      "avu  w     x    ",
      "bvbyyy     bA   ",
      "avB  C     x    ",
      "avu  w     sD   ",
      "avB  C     sD   ",
      "avu  w     x   E",
      "avB  C     xiFIi",
      "avu  w     s   i",
      "avB  C     s   i",
      "avu  w     xiiii",
      "bvbyyy     bJJ  ",
      "avKLM      xk   ",
      "avbNO      bPPPQ"
    ],
    [
      "vv          R   ",
      "av         s    ",
      "av         s    ",
      "av         x    ",
      "bvb        bS   ",
      "av         x    ",
      "av         s    ",
      "av         s    ",
      "av         x    ",
      "av         xiTUi",
      "av         s   i",
      "av         s   i",
      "av         xiiii",
      "bvb        b    ",
      "av         xk   ",
      "avb        bPPPV"
    ],
    [
      "vv         s    ",
      "av         s    ",
      "av         s    ",
      "av         x    ",
      "bvb        b    ",
      "av         x    ",
      "av         s    ",
      "av         s    ",
      "av         x    ",
      "av         xiWWi",
      "av         s   i",
      "av         s   i",
      "av         xiiii",
      "bvb        b    ",
      "av         xk   ",
      "Xvb        bPPPP"
    ]
  ]
}