{
  "name": "multi_oasiscondo_6_floor6",
  "refpalette": "deceasedcraft:multi_oasiscondo_6/multi_oasiscondo_6_floor6_palette",
  "xsize": 16,
  "zsize": 16,
  "slices": [
    [
      "aaab            ",
      "aaab            ",
      "aaab            ",
      "aaab            ",
      "caabd           ",
      "aaab            ",
      "aaab            ",
      "aaab            ",
      "aaab            ",
      "aaab       efggf",
      "aaab       f   f",
      "aaabh      f    ",
      "aaaijjjjjjjfaafa",
      "caaaaaaaaaaaaaaa",
      "aaaaaaaaaaaaaaaa",
      "aacaaaaaaaacaaaa"
    ],
    [
      "   k            ",
      "   k            ",
      "   k            ",
      "   k            ",
      "c  k            ",
      "   k            ",
      "   k            ",
      "   k            ",
      "   k            ",
      "   k       efllf",
      "   k       f   f",
      "   kk      f   f",
      "    kkkkkkkfmmfn",
      "c           op  ",
      "                ",
      "  c        c    "
    ],
    [
      "                ",
      "                ",
      "                ",
      "                ",
      "c  k            ",
      "                ",
      "                ",
      "                ",
      "                ",
      "           efllf",
      "           f   f",
      "    k      f   f",
      "           f  fq",
      "c           rs  ",
      "t               ",
      "  c  u     c    "
    ],
    [
      "                ",
      "                ",
      "                ",
      "                ",
      "c  k            ",
      "                ",
      "                ",
      "                ",
      "                ",
      "           efllf",
      "           f   f",
      "    k      f   f",
      "           fwwfx",
      "c           yA  ",
      "                ",
      "  c        c    "
    ],
    [
      "  B             ",
      "  B             ",
      "  B             ",
      "  B             ",
      "c Bk            ",
      "  B             ",
      "  B             ",
      "  B             ",
      "  B             ",
      "  B        efllf",
      "  B        f   f",
      "  B k      f   f",
      "  B        ffff ",
      "c  CCCCCCCC     ",
      "                ",
      "  c        c    "
    ],
    [
      "DDDE            ",
      "DDDE            ",
      "DDDE            ",
      "DDDE            ",
      "cDDE            ",
      "DDDE            ",
      "DDDE            ",
      "DDDE            ",
      "DDDE            ",
      "DDDE       efllf",
      "DDDE       f   f",
      "DDDEE      f   f",
      "DDDEEEEEEEEffffF",
      "cDDDDDDDDDDDDDDD",
      "DDDDDDDDDDDDDDDD",
      "DDcDDDDDDDDcDDDD"
    ]
  ]
}