{
  "name": "multi_oasiscondo_6_base2",
  "refpalette": "deceasedcraft:multi_oasiscondo_6/multi_oasiscondo_6_base2_palette",
  "xsize": 16,
  "zsize": 16,
  "slices": [
    [
      " vHHHHHHHHabcccc",
      " vHHHHHHHHabcccc",
      " vHHHHHHHHabcccc",
      " vHHHHHHHHabcccc",
      "dvdaaaHHHHadeccc",
      " vHHHHHHHHafcccc",
      " vHHHHHHHHafcccc",
      " vHHHHHHHHafcccc",
      " vHHHHHHHHafcccc",
      " vHHHHHHHHafgcc ",
      " vHHHHHHHHaf   h",
      " vHHHHHHHHaf    ",
      "ivHHHHHHHHafgggg",
      "dadaaaHHHHadcccc",
      "aaaaaaHHHHafjccc",
      "aadaaHHHHHadbbbb"
    ],
    [
      " vkllm      n   ",
      " voppq     r    ",
      " v  s      r    ",
      " vt  u     w    ",
      "dvdxxx     dy   ",
      " vA  B     w    ",
      " vt  u     rC   ",
      " vA  B     rC   ",
      " vt  u     w   D",
      "ivA  B     wgEFg",
      "Ivt  u     r   g",
      "JvA  B     r   g",
      "avt  u     wgggg",
      "dKdxxx     dLL  ",
      "M          wj   ",
      "  d        dNNNO"
    ],
    [
      " v          P   ",
      " v         r    ",
      " v         r    ",
      " v         w    ",
      "dvd        dQ   ",
      " v         w    ",
      "iv         r    ",
      "Iv         r    ",
      "Jv         w    ",
      "av         wgRSg",
      "Tv         r   g",
      "Mv         r   g",
      " v         wgggg",
      "d d        d    ",
      "           wj   ",
      "  d        dNNNU"
    ],
    [
      " v         r    ",
      " v         r    ",
      " v         r    ",
      "iv         w    ",
      "dvd        d    ",
      "Jv         w    ",
      "av         r    ",
      "Tv         r    ",
      "Mv         w    ",
      " v         wgVVg",
      " v         r   g",
      " v         r   g",
      " v         wgggg",
      "d d        dW   ",
      "           wj   ",
      "  d        dNNNN"
    ],
    [
      "ivbXXXXXXXXbXXXX",
      "IvbXXXXXXXXbXXXX",
      "JvbXXXXXXXXbXXXX",
      "avbXXXXXXXXbXXXX",
      "dvYbbbbbbbbYbbbb",
      "MvbXXXXXXXXbXXXX",
      " vbXXXXXXXXbXXXX",
      " vbXXXXXXXXbXXXX",
      " vbXXXXXXXXbXXXX",
      " vbXXXXXXXXbgggg",
      " vbXXXXXXXXb   g",
      " vbXXXXXXXXb   g",
      " vbXXXXXXXXbgggg",
      "d YbbbbbbbbYbbbb",
      "           wj   ",
      "  d        dNNNN"
    ],
    [
      "avbeeeeeeeeeeeee",
      "Tvbeeeeeeeeeeeee",
      "MvbZeeeeeeeeeeee",
      " vbeeeeeeeeeeeee",
      "Yb0eeeeeeeeeeeee",
      " vbeeeeeeeeeeeee",
      " vbeeeeeeeeeeeee",
      " vb1eeeeeeeeeeee",
      " vbeeeeeeeeeeeee",
      " vbeeeeeeeeeg22g",
      " vbeeeeeeeeb   g",
      " vbeeeeeeeeb   g",
      " vbZeeeeeeeggggg",
      "Yb0bbbbbbbbYbbbb",
      "iibXXXXXXXXbjjjj",
      "iiYbbbbbbbbYbbbb"
    ]
  ]
}