{
  "name": "multi_oasiscondo_6_top",
  "refpalette": "deceasedcraft:multi_oasiscondo_6/multi_oasiscondo_6_top_palette",
  "xsize": 16,
  "zsize": 16,
  "slices": [
    [
      "aaab            ",
      "aaab            ",
      "aaab            ",
      "aaab            ",
      "caabd           ",
      "aaab            ",
      "aaab            ",
      "aaab            ",
      "aaabe           ",
      "aaaab      fghhg",
      "aaaabe     g   g",
      "aaaaaiie   g    ",
      "aaaaaaaiiiigaaga",
      "caaaaaaaaaaaaaaa",
      "aaaaaaaaaaaaaaaa",
      "aacaaaaaaaacaaaa"
    ],
    [
      "   j            ",
      "k  j            ",
      "k  j            ",
      "   j            ",
      "c  j            ",
      "   j            ",
      "k  j            ",
      "k  j            ",
      "   jj           ",
      "    j      fgllg",
      "k   jj     g   g",
      "k    jjj   g   g",
      "       jjjjgmmgn",
      "c           op  ",
      "                ",
      "  c        c    "
    ],
    [
      "                ",
      "                ",
      "                ",
      "                ",
      "c  j            ",
      "                ",
      "                ",
      "                ",
      "                ",
      "           fgllg",
      "     j     g   g",
      "           g   g",
      "           g  gq",
      "c           rs  ",
      "                ",
      "  c        c    "
    ],
    [
      "                ",
      "                ",
      "                ",
      "                ",
      "c  j            ",
      "                ",
      "                ",
      "                ",
      "                ",
      "           fgllg",
      "     j     g   g",
      "           g   g",
      "           gttgu",
      "c           wx  ",
      "                ",
      "  c        c    "
    ],
    [
      "                ",
      "                ",
      "                ",
      "                ",
      "c  j            ",
      "                ",
      "                ",
      "                ",
      "                ",
      "           fgllg",
      "     j     g   g",
      "           g   g",
      "           gggg ",
      "c               ",
      "                ",
      "  c        c    "
    ],
    [
      " yy             ",
      " yy             ",
      " yy             ",
      " yy             ",
      "cyyj            ",
      " yy             ",
      " yy             ",
      " yy             ",
      " yy             ",
      " yyy       fgllg",
      " yyy j     g   g",
      " yyyy      g   g",
      " yyyyyy    ggggA",
      "cyyyyyyyyyyyyyyy",
      " yyyyyyyyyyyyyyy",
      "  cyyyyyyyycyyyy"
    ],
    [
      "baab            ",
      "baab            ",
      "baab            ",
      "baab            ",
      "caabd           ",
      "baab            ",
      "baab            ",
      "baab            ",
      "baabe           ",
      "baaab      fghhg",
      "baaabe     g   g",
      "baaaaiie   g    ",
      "baaaaaaiiiigaaga",
      "caaaaaaaaaaaaaaa",
      "baaaaaaaaaaaaaaa",
      "Bicaaaaaaaacaaaa"
    ],
    [
      "l  j            ",
      "l  j            ",
      "l  j            ",
      "l  j            ",
      "c  j            ",
      "l  j            ",
      "l  j            ",
      "l  j            ",
      "l  jj           ",
      "l   j      fgllg",
      "l   jj     g   g",
      "l    jjj   g   g",
      "l      jjjjgmmgn",
      "c           op  ",
      "l               ",
      "llc        c    "
    ],
    [
      "                ",
      "                ",
      "                ",
      "                ",
      "c  j            ",
      "                ",
      "                ",
      "                ",
      "                ",
      "           fgllg",
      "     j     g   g",
      "           g   g",
      "           g  gq",
      "c           rs  ",
      "                ",
      "  c        c    "
    ],
    [
      "                ",
      "                ",
      "                ",
      "                ",
      "c  j            ",
      "                ",
      "                ",
      "                ",
      "                ",
      "           fgllg",
      "     j     g   g",
      "           g   g",
      "           gttgu",
      "c           wx  ",
      "                ",
      "  c        c    "
    ],
    [
      "  C             ",
      "  C             ",
      "  C             ",
      "  C             ",
      "c Cj            ",
      "  C             ",
      "  C             ",
      "  C             ",
      "  CD            ",
      "   C       fgllg",
      "   CDj     g   g",
      "     E     g   g",
      "     FFE   gggg ",
      "c      FFFF     ",
      "                ",
      "  c        c    "
    ],
    [
      "yyyI            ",
      "yyyI            ",
      "yyyI            ",
      "yyyI            ",
      "cyyI            ",
      "yyyI            ",
      "yyyI            ",
      "yyyI            ",
      "yyyII           ",
      "yyyyI      fgllg",
      "yyyyII     g   g",
      "yyyyyIII   g   g",
      "yyyyyyyIIIIggggA",
      "cyyyyyyyyyyyyyyy",
      "yyyyyyyyyyyyyyyy",
      "yycyyyyyyyycyyyy"
    ],
    [
      "eeee            ",
      "eeee            ",
      "eeee            ",
      "eeee            ",
      "eeee            ",
      "eeee            ",
      "eeee            ",
      "eeee            ",
      "eeeee           ",
      "eeeee      fghhg",
      "eeeeee     g   g",
      "eeeeeeee   g   g",
      "eeeeeeeeeeegggge",
      "eeeeeeeeeeeeeeee",
      "eeeeeeeeeeegeeee",
      "eeeeeeeeeeegeeee"
    ],
    [
      "   j            ",
      "JJ j            ",
      "JJ j            ",
      "JJ j            ",
      "   j            ",
      "   j            ",
      "   j            ",
      "   j            ",
      "   jj           ",
      "KK  j      fgggg",
      "KK  jj     g   g",
      "KK   jjj   g   g",
      "       jjjjggggg",
      "           L    ",
      "KK  KKK    g MN ",
      "KK  KKK    gO!PQ"
    ],
    [
      "                ",
      "JJ              ",
      "JJ              ",
      "JJ              ",
      "                ",
      "                ",
      "                ",
      "                ",
      "                ",
      " R         fgggg",
      "S          gTUV ",
      " W         gTXYT",
      "           ggggg",
      "           Z    ",
      " R  0 R   1g 2N ",
      "S    S     g34P "
    ],
    [
      "                ",
      "JJ              ",
      "JJ              ",
      "JJ              ",
      "                ",
      "                ",
      "                ",
      "                ",
      "                ",
      "56         fgggg",
      " 7         g8888",
      "9#         g8$88",
      "           g8888",
      "           g8888",
      "56  %56    g8888",
      " 7  ^ 7    g8888"
    ],
    [
      "                ",
      "&&              ",
      "&&              ",
      "&&              ",
      "                ",
      "                ",
      "                ",
      "                ",
      "                ",
      "*(              ",
      " )              ",
      "+-              ",
      "                ",
      "                ",
      "*(  [*(         ",
      " )  ] )         "
    ],
    [
      "                ",
      "                ",
      "                ",
      "                ",
      "                ",
      "                ",
      "                ",
      "                ",
      "                ",
      "{}              ",
      " |              ",
      ";:              ",
      "                ",
      "                ",
      "{}  '{}         ",
      " |  < |         "
    ],
    [
      "                ",
      "                ",
      "                ",
      "                ",
      "                ",
      "                ",
      "                ",
      "                ",
      "                ",
      ">,              ",
      ".?              ",
      "/`              ",
      "                ",
      "                ",
      ">,  \u0370>,         ",
      ".?  \u0371.?         "
    ]
  ]
}