{
  "name": "multi_oasiscondo_6_base1",
  "refpalette": "deceasedcraft:multi_oasiscondo_6/multi_oasiscondo_6_base1_palette",
  "xsize": 16,
  "zsize": 16,
  "slices": [
    [
      " vHHHHHHHHabcccc",
      " vHHHHHHHHabcccc",
      " vHHHHHHHHabcccc",
      " vHHHHHHHHabcccc",
      "dvdaaaHHHHadeccc",
      " vHHHHHHHHafcccc",
      " vHHHHHHHHafcccc",
      " vHHHHHHHHafcccc",
      " vHHHHHHHHafcccc",
      " vHHHHHHHHafgcc ",
      " vHHHHHHHHaf   h",
      " vHHHHHHHHaf    ",
      "ivHHHHHHHHafgggg",
      "dadaaaHHHHadcccc",
      "aaaaaaHHHHafjccc",
      "aadaaHHHHHadbbbb"
    ],
    [
      " vkllm      n   ",
      " voppq     r    ",
      " v  s      r    ",
      " vt  u     w    ",
      "dvdxxx     dy   ",
      " vA  B     w    ",
      " vt  u     rC   ",
      " vA  B     rC   ",
      " vt  u     w   D",
      "ivA  B E   wgFIg",
      "Jvt  u     r   g",
      "KvA  B     r   g",
      "avt  u     wgggg",
      "dLdxxx     dMM  ",
      "N          wj   ",
      "  d        dOOOP"
    ],
    [
      " v          Q   ",
      " v         r    ",
      " v         r    ",
      " v         w    ",
      "dvd        dR   ",
      " v         w    ",
      "iv         r    ",
      "Jv         r    ",
      "Kv         w    ",
      "av         wgSTg",
      "Uv         r   g",
      "Nv         r   g",
      " v         wgggg",
      "d d        d    ",
      "           wj   ",
      "  d        dOOOV"
    ],
    [
      " v         r    ",
      " v         r    ",
      " v         r    ",
      "iv         w    ",
      "dvd        d    ",
      "Kv         w    ",
      "av         r    ",
      "Uv         r    ",
      "Nv         w    ",
      " v         wgWWg",
      " v         r   g",
      " v         r   g",
      " v         wgggg",
      "d d        dX   ",
      "           wj   ",
      "  d        dOOOO"
    ],
    [
      "ivbYYYYYYYYbYYYY",
      "JvbYYYYYYYYbYYYY",
      "KvbYYYYYYYYbYYYY",
      "avbYYYYYYYYbYYYY",
      "dvZbbbbbbbbZbbbb",
      "NvbYYYYYYYYbYYYY",
      " vbYYYYYYYYbYYYY",
      " vbYYYYYYYYbYYYY",
      " vbYYYYYYYYbYYYY",
      " vbYYYYYYYYbgggg",
      " vbYYYYYYYYb   g",
      " vbYYYYYYYYb   g",
      " vbYYYYYYYYbgggg",
      "d ZbbbbbbbbZbbbb",
      "           wj   ",
      "  d        dOOOO"
    ],
    [
      "avbeeeeeeeeeeeee",
      "Uvbeeeeeeeeeeeee",
      "Nvb0eeeeeeeeeeee",
      " vbeeeeeeeeeeeee",
      "Zb1eeeeeeeeeeeee",
      " vbeeeeeeeeeeeee",
      " vbeeeeeeeeeeeee",
      " vb0eeeeeeeeeeee",
      " vbeeeeeeeeeeeee",
      " vbeeeeeeeeeg22g",
      " vbeeeeeeeeb   g",
      " vbeeeeeeeeb   g",
      " vb3eeeeeeeggggg",
      "Zb1bbbbbbbbZbbbb",
      "iibYYYYYYYYbjjjj",
      "iiZbbbbbbbbZbbbb"
    ]
  ]
}