{
  "name": "multi_filmworkstower_8_floor10",
  "refpalette": "deceasedcraft:multi_filmworkstower_8/multi_filmworkstower_8_floor10_palette",
  "xsize": 16,
  "zsize": 16,
  "slices": [
    [
      "                ",
      "                ",
      "                ",
      "                ",
      "                ",
      "                ",
      "aaa             ",
      "bbbac           ",
      "bbba            ",
      "bbba            ",
      "bbbac           ",
      "bbba            ",
      "bbba            ",
      "bbbac           ",
      "bbba            ",
      "bbb dde         "
    ],
    [
      "                ",
      "                ",
      "                ",
      "                ",
      "                ",
      "                ",
      "aaa             ",
      "ffgac           ",
      "hija            ",
      "k la            ",
      " mlac           ",
      " noa            ",
      "ppqa            ",
      "ffgac           ",
      "h ja            ",
      "k lrdde         "
    ],
    [
      "                ",
      "                ",
      "                ",
      "                ",
      "                ",
      "                ",
      "aaa             ",
      "stuac           ",
      "   a            ",
      "  wa            ",
      "  xac           ",
      "   a            ",
      "yuAa            ",
      "stuac           ",
      "  Ba            ",
      "  Crdde         "
    ],
    [
      "                ",
      "                ",
      "                ",
      "                ",
      "                ",
      "                ",
      "aaa             ",
      "   ac           ",
      "   a            ",
      "   a            ",
      "   ac           ",
      "   a            ",
      "   a            ",
      "   ac           ",
      "   a            ",
      "   rdde         "
    ],
    [
      "                ",
      "                ",
      "                ",
      "                ",
      "                ",
      "                ",
      "aaa             ",
      "   ac           ",
      "   a            ",
      "   a            ",
      "   ac           ",
      "   a            ",
      "   a            ",
      "   ac           ",
      "   a            ",
      "   rdde         "
    ],
    [
      "                ",
      "                ",
      "                ",
      "                ",
      "                ",
      "                ",
      "aaa             ",
      "DDDac           ",
      "DDDa            ",
      "EDDa            ",
      "DDDac           ",
      "DDDa            ",
      "DDDa            ",
      "DDDac           ",
      "EDDa            ",
      "FFFFdde         "
    ]
  ]
}