{
  "name": "multi_filmworkstower_8_floor11",
  "refpalette": "deceasedcraft:multi_filmworkstower_8/multi_filmworkstower_8_floor11_palette",
  "xsize": 16,
  "zsize": 16,
  "slices": [
    [
      "                ",
      "                ",
      "                ",
      "                ",
      "                ",
      "                ",
      "aaa             ",
      "bbbac           ",
      "bbba            ",
      "bbba            ",
      "bbbac           ",
      "bbba            ",
      "bbba            ",
      "bbbac           ",
      "bbba            ",
      "bbb dde         "
    ],
    [
      "                ",
      "                ",
      "                ",
      "                ",
      "                ",
      "                ",
      "aaa             ",
      "ffgac           ",
      "h ia            ",
      "j ka            ",
      "l kac           ",
      "m na            ",
      "oopa            ",
      "ffgac           ",
      "h ia            ",
      "j kqdde         "
    ],
    [
      "                ",
      "                ",
      "                ",
      "                ",
      "                ",
      "                ",
      "aaa             ",
      "rstac           ",
      "  ua            ",
      "  wa            ",
      "  xac           ",
      "  ya            ",
      "AB a            ",
      "rsCac           ",
      "  Da            ",
      "  Eqdde         "
    ],
    [
      "                ",
      "                ",
      "                ",
      "                ",
      "                ",
      "                ",
      "aaa             ",
      "   ac           ",
      "   a            ",
      "   a            ",
      "   ac           ",
      "   a            ",
      "   a            ",
      "   ac           ",
      "   a            ",
      "   qdde         "
    ],
    [
      "                ",
      "                ",
      "                ",
      "                ",
      "                ",
      "                ",
      "aaa             ",
      "   ac           ",
      "   a            ",
      "   a            ",
      "   ac           ",
      "   a            ",
      "   a            ",
      "   ac           ",
      "   a            ",
      "   qdde         "
    ],
    [
      "                ",
      "                ",
      "                ",
      "                ",
      "                ",
      "                ",
      "aaa             ",
      "FFFac           ",
      "FFFa            ",
      "IFFa            ",
      "FFFac           ",
      "FFFa            ",
      "FFFa            ",
      "FFFac           ",
      "IFFa            ",
      "JJJJdde         "
    ]
  ]
}