{
  "name": "multi_filmworkstower_8_floor4",
  "refpalette": "deceasedcraft:multi_filmworkstower_8/multi_filmworkstower_8_floor4_palette",
  "xsize": 16,
  "zsize": 16,
  "slices": [
    [
      "                ",
      "                ",
      "                ",
      "                ",
      "                ",
      "                ",
      "aaa             ",
      "bbbac           ",
      "bbba            ",
      "bbba            ",
      "bbbac           ",
      "bbba            ",
      "bbba            ",
      "bbbac           ",
      "bbba            ",
      "bbb dde         "
    ],
    [
      "                ",
      "                ",
      "                ",
      "                ",
      "                ",
      "                ",
      "aaa             ",
      "fghac           ",
      "   a            ",
      "iiia            ",
      "   ac           ",
      "jkla            ",
      "mmma            ",
      "fghac           ",
      "   a            ",
      "iiindde         "
    ],
    [
      "                ",
      "                ",
      "                ",
      "                ",
      "                ",
      "                ",
      "aaa             ",
      "   ac           ",
      "   a            ",
      "opqa            ",
      "   ac           ",
      "   a            ",
      "rrra            ",
      "   ac           ",
      "   a            ",
      "st ndde         "
    ],
    [
      "                ",
      "                ",
      "                ",
      "                ",
      "                ",
      "                ",
      "aaa             ",
      "   ac           ",
      "   a            ",
      "   a            ",
      "   ac           ",
      "   a            ",
      "   a            ",
      "   ac           ",
      "   a            ",
      "   ndde         "
    ],
    [
      "                ",
      "                ",
      "                ",
      "                ",
      "                ",
      "                ",
      "aaa             ",
      "   ac           ",
      "   a            ",
      "   a            ",
      "   ac           ",
      "   a            ",
      "   a            ",
      "   ac           ",
      "   a            ",
      "   ndde         "
    ],
    [
      "                ",
      "                ",
      "                ",
      "                ",
      "                ",
      "                ",
      "aaa             ",
      "uuuac           ",
      "uuua            ",
      "wuua            ",
      "uuuac           ",
      "uuua            ",
      "uuua            ",
      "uuuac           ",
      "wuua            ",
      "xxxxdde         "
    ]
  ]
}