{
  "name": "multi_filmworkstower_8_base1",
  "refpalette": "deceasedcraft:multi_filmworkstower_8/multi_filmworkstower_8_base1_palette",
  "xsize": 16,
  "zsize": 16,
  "slices": [
    [
      "vvvvvvvvvvvvvvvv",
      "aaaaaaaaaaaaaaaa",
      "bbbbbbbbbbbbbbbb",
      "ccccccccdddddddd",
      "       cdddddddd",
      "       cdddddddd",
      "       cdddddddd",
      "       cdeddedde",
      "cccccccccccccccc",
      "    fffffff     ",
      "                ",
      "                ",
      "                ",
      "                ",
      "                ",
      "                "
    ],
    [
      "vvvvvvvvvvvvvvvv",
      "aaaaaaaaaaaaaaaa",
      "bbbbbbbbbbbbbbbb",
      "ccccccccgh      ",
      "       ceh      ",
      "       c        ",
      "       c        ",
      "       c e  e  e",
      "cccccccccccccccc",
      "    iiiiiii     ",
      "                ",
      "                ",
      "                ",
      "                ",
      "                ",
      "                "
    ],
    [
      "vvvvvvvvvvvvvvvv",
      "aaaaaaaaaaaaaaaa",
      "bbbbbbbbbbbbbbbb",
      "ccccccccgh      ",
      "       ceh      ",
      "       c        ",
      "       c        ",
      "       c e  e  e",
      "cccccccccccccccc",
      "    jjjjjjj     ",
      "                ",
      "                ",
      "                ",
      "                ",
      "                ",
      "                "
    ],
    [
      "vvvvvvvvvvvvvvvv",
      "aaaaaaaaaaaaaaaa",
      "bbbbbbbbbbbbbbbb",
      "ccccccccgh      ",
      "kkkkkkkceh      ",
      "kkkkkkkce       ",
      "kkkkkkkce       ",
      "kkkkkkkceeeeeeee",
      "cccccccccccccccc",
      "                ",
      "                ",
      "                ",
      "                ",
      "                ",
      "                ",
      "                "
    ],
    [
      "vvvvvvvvvvvvvvvv",
      "aaaaaaaaaaaaaaaa",
      "bbbbbbbbbbbbbbbb",
      "ccccccccllllllll",
      "lllllllcllllllll",
      "lllllllcllllllll",
      "lllllllcllllllll",
      "lllllllcllllllll",
      "cccccccccccccccc",
      "mmmmmmmmmmmmmmmm",
      "mmmmmmmmmmmmmmmm",
      "mmmmmmmmmmmmmmmm",
      "mmmmmmmmmmmmmmmm",
      "mmmmmmmmmmmmmmmm",
      "mmmmmmmmmmmmmmmm",
      "mmmmmmmmmmmmmmmm"
    ],
    [
      "vvvvvvvvvvvvvvvv",
      "aaaaaaaaaaaaaaaa",
      "bbbbbbbbbbbbbbbb",
      "nnnnnnnnnnnnnnnn",
      "nnnnnnnnnnnnnnnn",
      "nnnnnnnnnnnnnnnn",
      "nnnnnnnnnnnnnnnn",
      "nnnnnnnnnnnnnnnn",
      "nnnnnnnnnnnnnnnn",
      "nnnnnnnnnnnnnnnn",
      "nnnnnnnnnnnnnnnn",
      "nnnnnnnnnnnnnnnn",
      "nnnnnnnnnnnnnnnn",
      "nnnnnnnnnnnnnnnn",
      "nnnnnnnnnnnnnnnn",
      "nnnnnnnnnnnnnnnn"
    ]
  ]
}