{
  "name": "multi_filmworkstower_8_base2",
  "refpalette": "deceasedcraft:multi_filmworkstower_8/multi_filmworkstower_8_base2_palette",
  "xsize": 16,
  "zsize": 16,
  "slices": [
    [
      "vvvvvvvvvvvvvvvv",
      "aaaaaaaaaaaaaaaa",
      "bbbbbbbbbbbbbbbb",
      "ccccccccdddddddd",
      "ccccccccdddddddd",
      "ccccccccdddddddd",
      "ccccccccdddddddd",
      "ccccccccdddedddd",
      "cccccccccccccccc",
      "cccccccccccccccc",
      "cccccccccccccccc",
      "cccccccccccccccc",
      "cccccccccccccccc",
      "cccccccccccccccc",
      "ffffffffffffffff",
      "     g          "
    ],
    [
      "vvvvvvvvvvvvvvvv",
      "aaaaaaaaaaaaaaaa",
      "bbbbbbbbbbbbbbbb",
      "hhijkllm        ",
      "       m        ",
      "       mnmmommnm",
      "       m pm pm p",
      "qqr    m smtsm s",
      "uuw    mmmmmmmmm",
      "x x             ",
      "                ",
      "                ",
      "                ",
      "                ",
      "yyyyy yyyyyyyyyy",
      "                "
    ],
    [
      "vvvvvvvvvvvvvvvv",
      "aaaaaaaaaaaaaaaa",
      "bbbbbbbbbbbbbbbb",
      "A B  C m        ",
      "       m        ",
      "       mDmmEmmDm",
      "       m  m  m  ",
      "F      mI mI mI ",
      " JK    mmmmmmmmm",
      "                ",
      "                ",
      "                ",
      "                ",
      "                ",
      "                ",
      "                "
    ],
    [
      "vvvvvvvvvvvvvvvv",
      "aaaaaaaaaaaaaaaa",
      "bbbbbbbbbbbbbbbb",
      "       m        ",
      "       m        ",
      "       mLmmLmmLm",
      "       m  m  m  ",
      "       mM mM mM ",
      "  N    mmmmmmmmm",
      "                ",
      "                ",
      "                ",
      "                ",
      "                ",
      "                ",
      "                "
    ],
    [
      "vvvvvvvvvvvvvvvv",
      "aaaaaaaaaaaaaaaa",
      "bbbbbbbbbbbbbbbb",
      "OOPOOOOm        ",
      "       m        ",
      "       mmmmmmmmm",
      "       m  m  m  ",
      "       m  m  m  ",
      "  Q    mmmmmmmmm",
      "                ",
      "                ",
      "                ",
      "                ",
      "                ",
      "                ",
      "                "
    ],
    [
      "vvvvvvvvvvvvvvvv",
      "aaaaaaaaaaaaaaaa",
      "bbbbbbbbbbbbbbbb",
      "RRmRRRRmSSSSSSSS",
      "       mSSSSSSSS",
      "       mSSSSSSSS",
      "       mSSSSSSSS",
      "       mSTSSTSST",
      "RRmRRRRmmmmmmmmm",
      "                ",
      "                ",
      "                ",
      "                ",
      "                ",
      "                ",
      "                "
    ]
  ]
}