{
  "name": "multi_terraceplaza_5_base2",
  "refpalette": "deceasedcraft:multi_terraceplaza_5/multi_terraceplaza_5_base2_palette",
  "xsize": 16,
  "zsize": 16,
  "slices": [
    [
      "vabbabbabbbbcccc",
      "vabbabbabbbbcccc",
      "vabbabbabbbbcccc",
      "vabbabbabbbbcccc",
      "vabbaaaaaaaacccc",
      "vabbabbabbbbcccc",
      "vabbabbabbbbcccc",
      "vabbbbbbbbbbcccc",
      "vabbbbbbbbbbcccc",
      "vabbabbabbbbcccc",
      "vabbabbabbbbcccc",
      "vabbabbabbbbcccc",
      "vabbabbabbbbcccc",
      "vabbabbabbbbcccc",
      "vabbaaaaaaaacccc",
      "vabbabbbbbbdcccc"
    ],
    [
      "va ea fag  hi j ",
      "va  affak   i j ",
      "va eaffak   i j ",
      "vae!affag   l   ",
      "va  aaaaaaaamm  ",
      "va eannao  hi   ",
      "vae annap  hi j ",
      "va  q  r   hi j ",
      "va  s  t   hi j ",
      "va  an au  hi j ",
      "va  a  ag  hi j ",
      "va  aw ak   i j ",
      "va xa yak   i j ",
      "va  awyag   l   ",
      "vaABaaaaaaaamm  ",
      "va  aCDDDDEdF   "
    ],
    [
      "va  a  a   IJ   ",
      "va  a fa    K   ",
      "va  af a        ",
      "va eaffa        ",
      "va  aaaaaaaamm  ",
      "va  annaL  MJ   ",
      "va  a naN  OJ   ",
      "va  P  Q   RJ   ",
      "va  S  T   UJ   ",
      "va  a  a   VJ   ",
      "va  a  a   IJ   ",
      "va  a  a    K   ",
      "va  a  a        ",
      "va  awya        ",
      "vaWXaaaaaaaamm  ",
      "va  a  YZY0dF   "
    ],
    [
      "va  a  a        ",
      "va  a  a        ",
      "va  af a        ",
      "va  a  a        ",
      "va  aaaaaaaamm  ",
      "va  an a        ",
      "va  a  a        ",
      "va  1  2        ",
      "va  1  2        ",
      "va  a  a        ",
      "va  a  a        ",
      "va  a  a        ",
      "va  a  a        ",
      "va  aw a        ",
      "va11aaaaaaaamm  ",
      "va  a      dF   "
    ],
    [
      "va  a  a        ",
      "va  a  a        ",
      "va  a  a        ",
      "va  a  a        ",
      "va  aaaaaaaamm  ",
      "va  a  a3       ",
      "va  a  a3       ",
      "va  a  a        ",
      "va  a  a        ",
      "va  a  a        ",
      "va  a  a        ",
      "va  a  a        ",
      "va  a  a        ",
      "va  a  a        ",
      "vaaaaaaaaaaamm  ",
      "va  a  33  dF   "
    ],
    [
      "va  a44a   56m  ",
      "va  a44a   57m  ",
      "va  a44a   56m  ",
      "va  a44a   57m  ",
      "va  aaaaaaaamm  ",
      "va  a44a8  57m  ",
      "va  a44a   56m  ",
      "va  a44a   57m  ",
      "va  a44a   56m  ",
      "va  a44a   57m  ",
      "va  a44a   56m  ",
      "va  a44a   57m  ",
      "va  a44a   56m  ",
      "va  a44a   57m  ",
      "vaaaaaaaaaaamm  ",
      "va  a999899dF   "
    ]
  ]
}