{
  "name": "multi_terraceplaza_5_ground",
  "refpalette": "deceasedcraft:multi_terraceplaza_5/multi_terraceplaza_5_ground_palette",
  "xsize": 16,
  "zsize": 16,
  "slices": [
    [
      "HHHabcdeffghiiii",
      "HHHabcdeffghiiii",
      "HHHajcdeffghiiii",
      "HHHabcdeffghiiii",
      "HHHabcdefklmiiii",
      "HHHabcdeffghiiii",
      "HHHajcdeffghiiii",
      "HHHabcdeffghiiii",
      "HHHabcdeffghiiii",
      "HHHabcdeffghiiii",
      "HHHabcdeffghiiii",
      "HHHabcdeffghiiii",
      "HHHabcdeffghiiii",
      "HHHajcdeffghiiii",
      "HHHabcdeffghiiii",
      "HHHabcdefklmnnnn"
    ],
    [
      "    op q  gr    ",
      "    op q  gr    ",
      "    sp q  gr    ",
      "    tp q  gruuu ",
      "    tw x   mcccy",
      "    tp q  grAAA ",
      "    sp q  grBCD ",
      "    op q  grE E ",
      "    op q  gr    ",
      "    op q  grF  F",
      "    op q  grI  I",
      "    op q  grJ  J",
      "    op q  gr    ",
      "    sp q  gr EE ",
      "    tp q  grKBDL",
      "    tw x   mMMMM"
    ],
    [
      "     pNO        ",
      "     pNP  g     ",
      "    QpNO  g     ",
      "      NP  g     ",
      "     RNO   mSSS ",
      "      NO  g     ",
      "    QpNP  g  T  ",
      "     pNP        ",
      "     pNO  g     ",
      "     pNP  g     ",
      "     pNO    U   ",
      "     pNO  g     ",
      "     pNP        ",
      "    QpNO  g     ",
      "      NO  g V  W",
      "     RNO   mMMMM"
    ],
    [
      "      NO        ",
      "      NP        ",
      "      NO        ",
      "      NP        ",
      "     oNO   m    ",
      "      NO        ",
      "      NP        ",
      "      NP        ",
      "      NO        ",
      "      NP        ",
      "      NO        ",
      "      NO        ",
      "      NP        ",
      "      NO        ",
      "      NO        ",
      "     oNO   mMMMM"
    ],
    [
      "      NO        ",
      "      NP        ",
      "      NO        ",
      "      NP        ",
      "     oNO   m    ",
      "      NO        ",
      "      NP        ",
      "      NP        ",
      "      NO        ",
      "      NP        ",
      "      NO        ",
      "      NO        ",
      "      NP        ",
      "      NO        ",
      "      NO        ",
      "     oNO   mMMMM"
    ],
    [
      "      NO   X    ",
      "      NP   X    ",
      "      NO   X    ",
      "      NP   X    ",
      "      NO   m    ",
      "      NO        ",
      "      NP        ",
      "      NP      Y ",
      "      NO        ",
      "      NP        ",
      "      NO        ",
      "      NO        ",
      "      NP      Z ",
      "      NO        ",
      "      NO00122222",
      "      NO003m4444"
    ]
  ]
}