{
  "name": "multi_terraceplaza_5_base1",
  "refpalette": "deceasedcraft:multi_terraceplaza_5/multi_terraceplaza_5_base1_palette",
  "xsize": 16,
  "zsize": 16,
  "slices": [
    [
      "va  a  b   cdef ",
      "va  ag b   cdeh ",
      "va  aiib   cdej ",
      "va  akkb   cdeh ",
      "va  abbb   ceej ",
      "va  a gbl  cdeh ",
      "va  a  b   cdem ",
      "va  a  b   cdeh ",
      "va  a  b   cde  ",
      "va  a gb   cde  ",
      "va  a  b   cde  ",
      "va  ag b   cde  ",
      "va  aikb   cde  ",
      "va  aiib   cde  ",
      "vaaaabbb   cee  ",
      "vannaoooloopq   "
    ],
    [
      "va  a      c er ",
      "va  a      c eh ",
      "va  ag     c es ",
      "va  a      c eh ",
      "va  a      cees ",
      "va  a   l  c eh ",
      "va  a      c em ",
      "va  a      c eh ",
      "va  a      c e  ",
      "va  a      c e  ",
      "va  a      c e  ",
      "va  a      c e  ",
      "va  ag     c e  ",
      "va ga      c e  ",
      "vaaaa      cee  ",
      "vtttaoooloopq   "
    ],
    [
      "va  a      c e  ",
      "va  a      c e  ",
      "va  a      cue  ",
      "va  a      c e  ",
      "va  a      cee  ",
      "va  a   l  c e  ",
      "va  a      cue  ",
      "va  a      c e  ",
      "va  a      c e  ",
      "va  a      c e  ",
      "va  a      c e  ",
      "va  a      c e  ",
      "va  a      cue  ",
      "va  a      c e  ",
      "vaaaa      cee  ",
      "vtttaoooloopq   "
    ],
    [
      "va  al      lew ",
      "va  al      lew ",
      "va  al      lew ",
      "va  al      lew ",
      "va  al  lllllew ",
      "va  allll   lew ",
      "va  al      lew ",
      "va  al      lew ",
      "va  al      lew ",
      "va  al      lew ",
      "va  al      lew ",
      "va  al      lew ",
      "va  al      lew ",
      "vaggal      lew ",
      "vaaaal  lllllxxx",
      "vtttallll  py   "
    ],
    [
      "va  annnnnnnxABB",
      "vag annnnnnnxABB",
      "va  annnnnnnxABB",
      "va  annnnnnnxABB",
      "va gannnnnnnxABB",
      "va  annnnnnnxABB",
      "va  annnnnnnxABB",
      "va gannnnnnnxABB",
      "va  annnnnnnxABB",
      "va  annnnnnnxABB",
      "va gannnnnnnxABB",
      "va  annnnnnnxABB",
      "vag annnnnnnxABB",
      "vaggannnnnnnxABB",
      "vaaaannnnnnnxxxx",
      "vtttannnnnnpCwww"
    ],
    [
      "vannatttttDEFIFF",
      "vannatttttDEFIFF",
      "vannatttttDEFIFF",
      "vannatttttDEFIFF",
      "vannatttttJpEEEE",
      "vannatttttDEFIFF",
      "vannatttttDEFIFF",
      "vannatttttDEFIFF",
      "vannatttttDEFIFF",
      "vannatttttDEFIFF",
      "vannatttttDEFIFF",
      "vannatttttDEFIFF",
      "vannatttttDEFIFF",
      "vannatttttDEFIFF",
      "vaaaatttttDEFFFF",
      "vtttatttttJpEEEE"
    ]
  ]
}