{
  "name": "multi_terraceplaza_5_floor1",
  "refpalette": "deceasedcraft:multi_terraceplaza_5/multi_terraceplaza_5_floor1_palette",
  "xsize": 16,
  "zsize": 16,
  "slices": [
    [
      "      ab  cd    ",
      "      ae  cd  f ",
      "      ab  cd    ",
      "      ae  cd    ",
      "      ab  cg    ",
      "      ab        ",
      "      ae        ",
      "      ae      h ",
      "      ab        ",
      "      ae        ",
      "      ab        ",
      "      abiijk    ",
      "      aeiilmmmmm",
      "      abiinooooo",
      "      ab  nnnnnn",
      "      ab  nnnnnn"
    ],
    [
      "      ab pqrssss",
      "      ae pqrssss",
      "      ab pqrssss",
      "      ae pqrssss",
      "      ab ptgrrrr",
      "      ab  u     ",
      "      ae        ",
      "      ae      h ",
      "      abiijk    ",
      "      aeiilmmmmm",
      "      abiinooooo",
      "      ab  nwxxxx",
      "      ae  nyyyyy",
      "      ab  A     ",
      "      ab  BBBBBB",
      "                "
    ],
    [
      "      ab  CDqqqq",
      "      ae  CDqqqq",
      "      ab  CDqqqq",
      "      ae  CDqqqq",
      "      ab  Eg    ",
      "      abiijkkkkk",
      "      aeiilmmmmm",
      "      aeiinooooo",
      "      ab  nwxxxx",
      "      ae  nyyyyy",
      "      ab  A     ",
      "      ab  B     ",
      "                ",
      "                ",
      "                ",
      "                "
    ],
    [
      "      ab        ",
      "      ae  C FFFF",
      "      abiijk    ",
      "      aeiilmkkkk",
      "      abiingIIII",
      "      ab  nnnnnn",
      "      ae  nyyyyy",
      "      ae  A     ",
      "      ab  B     ",
      "                ",
      "                ",
      "                ",
      "                ",
      "                ",
      "                ",
      "                "
    ],
    [
      "      abiilm    ",
      "      aeiinokkkk",
      "      ab  nwwwww",
      "      ae  nnnnnn",
      "      ab  AAAAAA",
      "      ab  BBBBBB",
      "                ",
      "                ",
      "                ",
      "                ",
      "                ",
      "                ",
      "                ",
      "                ",
      "                ",
      "                "
    ],
    [
      "      ab  nyJKKK",
      "      ae  A     ",
      "      ab  B     ",
      "                ",
      "                ",
      "                ",
      "                ",
      "                ",
      "                ",
      "                ",
      "                ",
      "                ",
      "                ",
      "                ",
      "                ",
      "                "
    ]
  ]
}