{
  "name": "multi_sunkenmonumentpark_9_ground",
  "refpalette": "deceasedcraft:multi_sunkenmonumentpark_9/multi_sunkenmonumentpark_9_ground_palette",
  "xsize": 16,
  "zsize": 16,
  "slices": [
    [
      "         a a   a",
      "                ",
      "          a     ",
      "            aa  ",
      "               a",
      "                ",
      "               a",
      "                ",
      "                ",
      "                ",
      "                ",
      "                ",
      "                ",
      "  b             ",
      "                ",
      "                "
    ],
    [
      "ccccccccc  d   a",
      "ccccccccc       ",
      "  e ccccccd     ",
      "      ccccc ad  ",
      "       ecccc   a",
      "         cccc   ",
      "          cccc d",
      "           ccccc",
      "           ecccc",
      "            cccc",
      "             ccc",
      "             ccc",
      "              cc",
      "ffg          ecc",
      "hhf           cc",
      "hhf           cc"
    ],
    [
      "iiiiiiiij      d",
      "iiiiiiiij       ",
      "jjjjiiiiij      ",
      "    jjiiiij     ",
      "      jjiiij   d",
      "        jiiij   ",
      "         jiiij  ",
      "          jiiijj",
      "           jiiii",
      "           jiiii",
      "            jiii",
      "            jiii",
      "             jii",
      "bbg          jii",
      "hhb          jii",
      "k g          jii"
    ],
    [
      "        l       ",
      "        m       ",
      "nnnn     l      ",
      "    on    l     ",
      "      on   l    ",
      "        o   l   ",
      "         o   l  ",
      "          o   pl",
      "           q    ",
      "           o    ",
      "            q   ",
      "            o   ",
      "             q  ",
      "rrb          q  ",
      "hhs          q  ",
      "kts          q  "
    ],
    [
      "                ",
      "                ",
      "                ",
      "                ",
      "                ",
      "                ",
      "                ",
      "                ",
      "                ",
      "                ",
      "                ",
      "                ",
      "                ",
      "uug             ",
      "hh              ",
      "ktw             "
    ],
    [
      "                ",
      "                ",
      "                ",
      "                ",
      "                ",
      "                ",
      "                ",
      "                ",
      "                ",
      "                ",
      "                ",
      "                ",
      "                ",
      "uub             ",
      "hh              ",
      "kkkt            "
    ]
  ]
}