{
  "name": "multi_sunkenmonumentpark_9_base1",
  "refpalette": "deceasedcraft:multi_sunkenmonumentpark_9/multi_sunkenmonumentpark_9_base1_palette",
  "xsize": 16,
  "zsize": 16,
  "slices": [
    [
      "aaaaaaaaaaaaaaaa",
      "aaaaaaaaaaaaaaaa",
      "aaaaaaaaaaaaaaaa",
      "aaaaaaaaaaaaaaaa",
      "aaaaaaaaaaaaaaaa",
      "aaaaaaaaaaaaaaaa",
      "aaaaaaaaaaaaaaaa",
      "aaaaaaaaaaaaaaaa",
      "bbbaaaaaaaaaaaaa",
      "bbbbbaaaaaaaaaaa",
      "bbbbbbaaaaaaaaaa",
      "bbbbbbbaaaaaaaaa",
      "bbbbbbbaaaaaaaaa",
      "bbbbbbbbaaaaaaaa",
      "bbbbbbbbaaaaaaaa",
      "bbbbbbbbaaaaaaaa"
    ],
    [
      "bbbbaaaaaaaaaaaa",
      "ccccbbbaaaaaaaaa",
      "ccdccccbbaaaaaaa",
      "cccccccccbaaaaaa",
      "cccccccdccbaaaaa",
      "cccccccccccbaaaa",
      "ccccccccccccbaaa",
      "===ccccccccccbaa",
      "eee==ccccccdcbaa",
      "eeeee=ccccccccba",
      "ffeeee=cccccccba",
      "ffffeee=ccccccba",
      "fffffee=cccccccb",
      "fffffeee=ccccdcb",
      "ffffffee=ccccccb",
      "ffffffee=ccccccb"
    ],
    [
      "gghhiiiiiiiiiiia",
      "jj  hhhiiiiiiiii",
      "  k    hhiiiiiii",
      "    lm   hiiiiii",
      "       k  hiiiii",
      "           hiiii",
      "            hiii",
      "nnn          hii",
      "   nn      k hii",
      "     n        hi",
      "ff    n     o hi",
      "ffff   n    p hi",
      "fffff  n       h",
      "fffff   n    q h",
      "ffffff  n     jr",
      "ffffff  n     jr"
    ],
    [
      "       s t t hhi",
      "             s h",
      "  u       t    h",
      "           swt  ",
      "       u       t",
      "                ",
      "               t",
      "                ",
      "           u    ",
      "                ",
      "ff              ",
      "ffff            ",
      "fffff           ",
      "fffff        u  ",
      "ffffff          ",
      "ffffff          "
    ],
    [
      "         u u   t",
      "                ",
      "  x       u     ",
      "            yu  ",
      "       x       u",
      "                ",
      "               u",
      "                ",
      "           x    ",
      "                ",
      "AA              ",
      "AAAA            ",
      "BBAAA           ",
      "BBBAA        x  ",
      "BBBBAA          ",
      "BBBBAA          "
    ],
    [
      "         x x   u",
      "                ",
      "  x       x     ",
      "            ux  ",
      "       x       x",
      "                ",
      "               x",
      "                ",
      "           x    ",
      "                ",
      "                ",
      " C              ",
      "   C            ",
      "  b          x  ",
      "    C           ",
      "                "
    ]
  ]
}