{
  "name": "multi_sunkenmonumentpark_15_base1",
  "refpalette": "deceasedcraft:multi_sunkenmonumentpark_15/multi_sunkenmonumentpark_15_base1_palette",
  "xsize": 16,
  "zsize": 16,
  "slices": [
    [
      "aaaaaaaaaaaaaaav",
      "aaaaaaaaaaaaaaav",
      "aaaaaaaaaaaaaaav",
      "aaaaaaaaaaaaaaav",
      "aaaaaaaaaaaaaaav",
      "aaaaaaaaaaaaaaav",
      "aaaaaaaaaaaaaaav",
      "aaaaaaaaaaaaaaav",
      "aaaaaaaaaaaaaaav",
      "aaaaaaaaaaaaaaav",
      "aaaaaaaaaaaaaaav",
      "aaaaaaaaaaaaaaav",
      "aaaaaaaaaaaaaaav",
      "aaaaaaaaaaaaaaav",
      "aaaaaaaaaaaaaaav",
      "vvvvvvvvvvvvvvvv"
    ],
    [
      "aaaaaaaaaaaaaaav",
      "aaaaaaaaaaaaaaav",
      "aaaaaaaaaaaaaaav",
      "aaaaaaaaaaaaaaav",
      "aaaaaaaaaaaaaaav",
      "aaaaaaaaaaaaaaav",
      "aaaaaaaaaaaaaaav",
      "aaaaaaaaaaaaaaav",
      "aaaaaaaaaaaaaaav",
      "aaaaaaaaaaaaaaav",
      "aaaaaaaaaaaaaaav",
      "aaaaaaaaaaaaaaav",
      "aaaaaaaaaaaaaaav",
      "aaaaaaaaaaaaaaav",
      "aaaaaaaaaaaaaaav",
      "vvvvvvvvvvvvvvvv"
    ],
    [
      "aaaaaaaaaaaaaaav",
      "aaaaaaaaaaaaaaav",
      "aaaaaaaaaaaaaaav",
      "aaaaaaaaaaaaaaav",
      "aaaaaaaaaaaaaaav",
      "aaaaaaaaaaaaaaav",
      "aaaaaaaaaaaaaaav",
      "aaaaaaaaaaaaaaav",
      "aaaaaaaaaaaaaaav",
      "aaaaaaaaaaaaaaav",
      "aaaaaaaaaaaaaaav",
      "aaaaaaaaaaaaaaav",
      "aaaaaaaaaaaaaaav",
      "aaaaaaaaaaaaaaav",
      "aaaaaaaaaaaaaaav",
      "vvvvvvvvvvvvvvvv"
    ],
    [
      "bbbbbaaaaaaaaaav",
      "bbbbaaaaaaaaaaav",
      "bbbaaaaaaaaaaaav",
      "bbaaaaaaaaaaaaav",
      "baaaaaaaaaaaaaav",
      "aaaaaaaaaaaaaaav",
      "aaaaaaaaaaaaaaav",
      "aaaaaaaaaaaaaaav",
      "aaaaaaaaaaaaaaav",
      "aaaaaaaaaaaaaaav",
      "aaaaaaaaaaaaaaav",
      "aaaaaaaaaaaaaaav",
      "aaaaaaaaaaaaaaav",
      "aaaaaaaaaaaaaaav",
      "aaaaaaaaaaaaaaav",
      "vvvvvvvvvvvvvvvv"
    ],
    [
      "cd  ebbbb      v",
      "   ebbbbb      v",
      "  ebbbbbb      v",
      " ebbbbbb       v",
      "ebbbbbbb       v",
      "bbbbbbb        v",
      "bbbbbbb        v",
      "bbbbb          v",
      "bbb            v",
      "               v",
      "               v",
      "               v",
      "               v",
      "               v",
      "               v",
      "vvvvvvvvvvvvvvvv"
    ],
    [
      " f      ebbb   v",
      "        ebbb   v",
      "     g  ebbb   v",
      "       ebbbb   v",
      "   ccg ebbbb   v",
      "  d c ebbbbb   v",
      "     eebbbbb   v",
      " g eebbbbbbb   v",
      "eeebbbbbbbb    v",
      "bbbbbbbbbbb    v",
      "bbbbbbbbbb     v",
      "bbbbbbbb       v",
      "               v",
      "               v",
      "               v",
      "vvvvvvvvvvvvvvvv"
    ]
  ]
}