{
  "name": "multi_sunkenmonumentpark_15_ground",
  "refpalette": "deceasedcraft:multi_sunkenmonumentpark_15/multi_sunkenmonumentpark_15_ground_palette",
  "xsize": 16,
  "zsize": 16,
  "slices": [
    [
      " a       b cddee",
      "           cddee",
      "     a     cddee",
      "         b cddee",
      "     a   bfcddee",
      "  g    ff  cddee",
      "           cddee",
      " a     b b cddee",
      "    b     cdddee",
      "b     hf  cdddee",
      "   b    ccddddee",
      "ccccccccddddddee",
      "dddddddddddddeee",
      "ddddddddddddeeee",
      "eeeeeeeeeeeeeeie",
      "eeeeeeeeeeeeeeee"
    ],
    [
      " j       a      ",
      "             b  ",
      "     j          ",
      "         a    f ",
      "     j   a      ",
      "  a             ",
      "            h   ",
      " j     a a      ",
      "    a      f    ",
      "a     g         ",
      "   a        b   ",
      "           f    ",
      "     b   b      ",
      "b f    b        ",
      "     f          ",
      "                "
    ],
    [
      " j       j      ",
      "             a  ",
      "     j          ",
      "         j      ",
      "     j   j      ",
      "  j             ",
      "            g   ",
      " j     j j      ",
      "    j           ",
      "j     a         ",
      "   j        a   ",
      "                ",
      "     a   a      ",
      "a      a        ",
      "                ",
      "                "
    ],
    [
      " k       j      ",
      "             j  ",
      "     k          ",
      "         j      ",
      "     k   j      ",
      "  j             ",
      "            a   ",
      " k     j j      ",
      "    j           ",
      "j     j         ",
      "   j        j   ",
      "                ",
      "     j   j      ",
      "j      j        ",
      "                ",
      "                "
    ],
    [
      "         k      ",
      "             j  ",
      "                ",
      "         j      ",
      "         k      ",
      "  k             ",
      "            j   ",
      "       k k      ",
      "    k           ",
      "k     j         ",
      "   k        j   ",
      "                ",
      "     j   j      ",
      "j      j        ",
      "                ",
      "                "
    ],
    [
      "                ",
      "             j  ",
      "                ",
      "         k      ",
      "                ",
      "                ",
      "            j   ",
      "                ",
      "                ",
      "      k         ",
      "            k   ",
      "                ",
      "     j   k      ",
      "k               ",
      "                ",
      "                "
    ]
  ]
}