{
  "name": "multi_alienresearch_2_base5",
  "refpalette": "deceasedcraft:multi_alienresearch_2/multi_alienresearch_2_base5_palette",
  "xsize": 16,
  "zsize": 16,
  "slices": [
    [
      "vabc      defg g",
      "vahc      deeig ",
      "vahc       deig ",
      "vaahc      deefg",
      "vaahc       deei",
      "vaaahc       dee",
      "vaaahc        ee",
      "vaaaahc        d",
      "vaaaahc         ",
      "vaaaaahc        ",
      "vaaaaaahc       ",
      "vaaaaaaabc      ",
      "vaaaaaaahbc     ",
      "vaaaaaaaaahc    ",
      "vaaaaaaaaaahcc  ",
      "vaaaaaaaaaaahhcc"
    ],
    [
      "vahc        jkkk",
      "vah          jkk",
      "vah          jkk",
      "vaah          jk",
      "vaah           j",
      "vaaah          l",
      "vaaah           ",
      "vaaaah          ",
      "vaaaah          ",
      "vaaaaah         ",
      "vaaaaaah        ",
      "vaaaaaaahc      ",
      "vaaaaaaahh      ",
      "vaaaaaaaaah     ",
      "vaaaaaaaaaah    ",
      "vaaaaaaaaaaahh  "
    ],
    [
      "vahc            ",
      "vah             ",
      "vam             ",
      "vaam            ",
      "vaam            ",
      "vaaam           ",
      "vaaam           ",
      "vaaaam          ",
      "vaaaam          ",
      "vaaaaam         ",
      "vaaaaaam        ",
      "vaaaaaaahc      ",
      "vaaaaaaaah      ",
      "vaaaaaaaaam     ",
      "vaaaaaaaaaam    ",
      "vaaaaaaaaaaamm  "
    ],
    [
      "vah             ",
      "vam             ",
      "vam             ",
      "vaam            ",
      "vaam            ",
      "vaaam           ",
      "vaaam           ",
      "vaaaam          ",
      "vaaaam          ",
      "vaaaaam         ",
      "vaaaaaam        ",
      "vaaaaaaahc      ",
      "vaaaaaaaah      ",
      "vaaaaaaaaam     ",
      "vaaaaaaaaaam    ",
      "vaaaaaaaaaaamm  "
    ],
    [
      "vah             ",
      "vam             ",
      "vaam            ",
      "vaam            ",
      "vaam            ",
      "vaaam           ",
      "vaaam           ",
      "vaaaam          ",
      "vaaaaam         ",
      "vaaaaam         ",
      "vaaaaaam        ",
      "vaaaaaaahc      ",
      "vaaaaaaaah      ",
      "vaaaaaaaaam     ",
      "vaaaaaaaaaamm   ",
      "vaaaaaaaaaaaam  "
    ],
    [
      "vam             ",
      "vaam            ",
      "vaam            ",
      "vaam            ",
      "vaaam           ",
      "vaaam           ",
      "vaaaam          ",
      "vaaaam          ",
      "vaaaaam         ",
      "vaaaaam         ",
      "vaaaaaam        ",
      "vaaaaaaahc      ",
      "vaaaaaaaah      ",
      "vaaaaaaaaam     ",
      "vaaaaaaaaaamm   ",
      "vaaaaaaaaaaaamm "
    ]
  ]
}