{
  "name": "multi_alienresearch_2_base6",
  "refpalette": "deceasedcraft:multi_alienresearch_2/multi_alienresearch_2_base6_palette",
  "xsize": 16,
  "zsize": 16,
  "slices": [
    [
      "vab             ",
      "vaab            ",
      "vaab            ",
      "vaab            ",
      "vaaab           ",
      "vaaab           ",
      "vaaaab          ",
      "vaaaab          ",
      "vaaaaab         ",
      "vaaaaaab        ",
      "vaaaaaaab       ",
      "vaaaaaaacd      ",
      "vaaaaaaaacb     ",
      "vaaaaaaaaaab    ",
      "vaaaaaaaaaaab   ",
      "vaaaaaaaaaaaabb "
    ],
    [
      "vab             ",
      "vaab            ",
      "vaab            ",
      "vaab            ",
      "vaaab           ",
      "vaaab           ",
      "vaaaab          ",
      "vaaaab          ",
      "vaaaaab         ",
      "vaaaaab         ",
      "vaaaaaab        ",
      "vaaaaaaacd      ",
      "vaaaaaaaac      ",
      "vaaaaaaaaab     ",
      "vaaaaaaaaaabb   ",
      "vaaaaaaaaaaaabb "
    ],
    [
      "vac             ",
      "vab             ",
      "vaab            ",
      "vaab            ",
      "vaab            ",
      "vaaab           ",
      "vaaab           ",
      "vaaaab          ",
      "vaaaaab         ",
      "vaaaaab         ",
      "vaaaaaab        ",
      "vaaaaaaacd      ",
      "vaaaaaaaac      ",
      "vaaaaaaaaab     ",
      "vaaaaaaaaaabb   ",
      "vaaaaaaaaaaaab  "
    ],
    [
      "vac             ",
      "vab             ",
      "vab             ",
      "vaab            ",
      "vaab            ",
      "vaaab           ",
      "vaaab           ",
      "vaaaab          ",
      "vaaaab          ",
      "vaaaaab         ",
      "vaaaaaab        ",
      "vaaaaaaacd      ",
      "vaaaaaaaac      ",
      "vaaaaaaaaab     ",
      "vaaaaaaaaaab    ",
      "vaaaaaaaaaaabb  "
    ],
    [
      "vacd         ef ",
      "vac           gf",
      "vab           he",
      "vaab           e",
      "vaab            ",
      "vaaab           ",
      "vaaab           ",
      "vaaaab          ",
      "vaaaab          ",
      "vaaaaab         ",
      "vaaaaaab        ",
      "vaaaaaaacd      ",
      "vaaaaaaaac      ",
      "vaaaaaaaaab     ",
      "vaaaaaaaaaab    ",
      "vaaaaaaaaaaabb  "
    ],
    [
      "vacd       ijk@l",
      "vac         iml@",
      "vac         inkk",
      "vaac         ijk",
      "vaac         iej",
      "vaaac         ie",
      "vaaac          i",
      "vaaaac          ",
      "vaaaac          ",
      "vaaaaac         ",
      "vaaaaaac        ",
      "vaaaaaaacd      ",
      "vaaaaaaacc      ",
      "vaaaaaaaaac     ",
      "vaaaaaaaaaac    ",
      "vaaaaaaaaaaacc  "
    ]
  ]
}