{
  "name": "multi_alienresearch_2_base7",
  "refpalette": "deceasedcraft:multi_alienresearch_2/multi_alienresearch_2_base7_palette",
  "xsize": 16,
  "zsize": 16,
  "slices": [
    [
      "vaaaabc         ",
      "vaaaabc         ",
      "vaaaabc         ",
      "vaaaaabc        ",
      "vaaaaabc        ",
      "vaaaaaabc       ",
      "vaaaaaaabc      ",
      "vaaaaaaabc      ",
      "vaaaaaaaabc d   ",
      "vaaaaaaaaaec    ",
      "vaaaaaaaaaaec   ",
      "vaaaaaaaaaaabcc ",
      "vaaaaaaaaaaaabbc",
      "vaaaaaaaaaaaaaab",
      "vaaaaaaaaaaaaaaa",
      "vaaaaaaaaaaaaaaa"
    ],
    [
      "vaaab           ",
      "vaaaab          ",
      "vaaaab          ",
      "vaaaab          ",
      "vaaaaab         ",
      "vaaaaab         ",
      "vaaaaaab        ",
      "vaaaaaaab    c  ",
      "vaaaaaaab   f   ",
      "vaaaaaaaabgc    ",
      "vaaaaaaaaahg    ",
      "vaaaaaaaaaab    ",
      "vaaaaaaaaaaabb  ",
      "vaaaaaaaaaaaaab ",
      "vaaaaaaaaaaaaaab",
      "vaaaaaaaaaaaaaaa"
    ],
    [
      "vaaab           ",
      "vaaab           ",
      "vaaab           ",
      "vaaaab          ",
      "vaaaab          ",
      "vaaaaab        d",
      "vaaaaab       c ",
      "vaaaaaab     f  ",
      "vaaaaaaab       ",
      "vaaaaaaab       ",
      "vaaaaaaaahc     ",
      "vaaaaaaaaah     ",
      "vaaaaaaaaaabb   ",
      "vaaaaaaaaaaaab  ",
      "vaaaaaaaaaaaaabb",
      "vaaaaaaaaaaaaaaa"
    ],
    [
      "vaab            ",
      "vaaab           ",
      "vaaab           ",
      "vaaab           ",
      "vaaaab          ",
      "vaaaab         c",
      "vaaaaab         ",
      "vaaaaab         ",
      "vaaaaaab        ",
      "vaaaaaaab       ",
      "vaaaaaaaahc     ",
      "vaaaaaaaaah     ",
      "vaaaaaaaaaab    ",
      "vaaaaaaaaaaab   ",
      "vaaaaaaaaaaaabb ",
      "vaaaaaaaaaaaaaab"
    ],
    [
      "vaab            ",
      "vaab            ",
      "vaaab           ",
      "vaaab           ",
      "vaaab           ",
      "vaaaab          ",
      "vaaaab          ",
      "vaaaaab         ",
      "vaaaaaab        ",
      "vaaaaaaab       ",
      "vaaaaaaab c     ",
      "vaaaaaaaah      ",
      "vaaaaaaaaabb    ",
      "vaaaaaaaaaaab   ",
      "vaaaaaaaaaaaab  ",
      "vaaaaaaaaaaaaabb"
    ],
    [
      "vaab            ",
      "vaab            ",
      "vaab            ",
      "vaaab           ",
      "vaaab           ",
      "vaaaab          ",
      "vaaaab          ",
      "vaaaaab         ",
      "vaaaaab         ",
      "vaaaaaab        ",
      "vaaaaaaab c     ",
      "vaaaaaaaah      ",
      "vaaaaaaaaab     ",
      "vaaaaaaaaaab    ",
      "vaaaaaaaaaaabb  ",
      "vaaaaaaaaaaaaabb"
    ]
  ]
}