{
  "name": "multi_alienresearch_2_ground",
  "refpalette": "deceasedcraft:multi_alienresearch_2/multi_alienresearch_2_ground_palette",
  "xsize": 16,
  "zsize": 16,
  "slices": [
    [
      "zzaaaaaaazaabvcd",
      "zzzzazaaaaaavbcd",
      "zazaaaaaaaaabvcz",
      "zzzzaazaaaaabvce",
      "zzaaaaaazazzavcf",
      "zzzaazaaaazabvce",
      "zzzaaaaabaaabvcd",
      "zzaaaaaaaaaavvcz",
      "zzzzaaaazaaabbcd",
      "zzzaazabaaabbvce",
      "zzaaaaaaaazabvce",
      "zzzzaaaaaaazbvcf",
      "zazaaaaaazababcz",
      "zzzaaaaaaaaabvcd",
      "zzaaaaaaaaaavvce",
      "zzzzazaaazaabvce"
    ],
    [
      " g         h  ij",
      "   g       h  ik",
      "       lm nh  ig",
      "   g       h  i ",
      "          gh  io",
      "       lln h  i ",
      "           h  ip",
      "           h  ig",
      "       lgqnh  i ",
      "           h  ir",
      " g         h  is",
      "       lmqth  io",
      "         g h  ig",
      "           h  ip",
      "       l lnh  iu",
      " g g       h  iw"
    ],
    [
      "           h  x ",
      "           h  xk",
      "           h  yk",
      "           h  y ",
      "           h  yo",
      "           h  A ",
      "           h  yk",
      "           h  x ",
      "           h  x ",
      "           h  y ",
      "           h  y ",
      "           h  Bo",
      "           h  y ",
      "           h  y ",
      "           h  x ",
      "           h  x "
    ],
    [
      "                ",
      "              x ",
      "           h  yk",
      "           h  C ",
      "           h  yo",
      "           h  D ",
      "           h  Bk",
      "           h  xk",
      "           h  x ",
      "           h  y ",
      "           h  y ",
      "           h  Bo",
      "           h  C ",
      "           h  y ",
      "           h  x ",
      "           h  x "
    ],
    [
      "           E    ",
      "              x ",
      "           E  y ",
      "           E  C ",
      "           E  yo",
      "           E  y ",
      "           E  C ",
      "           E  xk",
      "           E    ",
      "           E  yk",
      "           E  y ",
      "           E  Bo",
      "           E  D ",
      "              y ",
      "           E  x ",
      "           E  x "
    ],
    [
      "              BF",
      "             ICF",
      "             IyF",
      "              yF",
      "              yo",
      "              yF",
      "             JyF",
      "             JyF",
      "             IyF",
      "             JyF",
      "              yF",
      "              yo",
      "              yF",
      "             IjF",
      "             IyF",
      "             JyF"
    ]
  ]
}