{
  "name": "multi_alienresearch_2_base2",
  "refpalette": "deceasedcraft:multi_alienresearch_2/multi_alienresearch_2_base2_palette",
  "xsize": 16,
  "zsize": 16,
  "slices": [
    [
      "vabbaccccdde    ",
      "vabbacccccd e   ",
      "vabbacccccdde   ",
      "vabbaccccccd e  ",
      "vabbaccccccdde  ",
      "vabbacccccccddee",
      "vabbaccccccccffe",
      "vabbacccccccccfd",
      "vabbaccccccccccd",
      "vabbaccccccccccc",
      "vabbaccccccccccc",
      "vabbaccccccccccc",
      "vabbaccccccccccc",
      "vabbaccccccccccc",
      "vabbaccccccccccc",
      "vabbaccccccccccc"
    ],
    [
      "vccccccccccd    ",
      "vccccccccccd    ",
      "vcccccccccccd   ",
      "vcccccccccccd   ",
      "vccccccccccccd  ",
      "vcccccccccccccfe",
      "vccccccccccccccf",
      "vccccccccccccccc",
      "vccccccccccccccc",
      "vccccccccccccccc",
      "vccccccccccccccc",
      "vccccccccccccccc",
      "vccccccccccccccc",
      "vccccccccccccccc",
      "vccccccccccccccc",
      "vccccccccccccccc"
    ],
    [
      "vcccccccccccd   ",
      "vcccccccccccdd  ",
      "vccccccccccccd  ",
      "vccccccccccccdd ",
      "vcccccccccccccdf",
      "vccccccccccccccf",
      "vccccccccccccccc",
      "vccccccccccccccc",
      "vccccccccccccccc",
      "vccccccccccccccc",
      "vccccccccccccccc",
      "vccccccccccccccc",
      "vccccccccccccccc",
      "vccccccccccccccc",
      "vccccccccccccccc",
      "vccccccccccccccc"
    ],
    [
      "vccccccccccccdd ",
      "vcccccccccccccdd",
      "vcccccccccccccdd",
      "vccccccccccccccd",
      "vccccccccccccccc",
      "vccccccccccccccc",
      "vccccccccccccccc",
      "vccccccccccccccc",
      "vccccccccccccccc",
      "vccccccccccccccc",
      "vccccccccccccccc",
      "vccccccccccccccc",
      "vccccccccccccccc",
      "vccccccccccccccc",
      "vccccccccccccccc",
      "vccccccccccccccc"
    ],
    [
      "vccccccccccccccd",
      "vccccccccccccccc",
      "vccccccccccccccc",
      "vccccccccccccccc",
      "vccccccccccccccc",
      "vccccccccccccccc",
      "vccccccccccccccc",
      "vccccccccccccccc",
      "vccccccccccccccc",
      "vccccccccccccccc",
      "vccccccccccccccc",
      "vccccccccccccccc",
      "vccccccccccccccc",
      "vccccccccccccccc",
      "vccccccccccccccc",
      "vccccccccccccccc"
    ],
    [
      "vccccccccccccccc",
      "vccccccccccccccc",
      "vccccccccccccccc",
      "vccccccccccccccc",
      "vccccccccccccccc",
      "vccccccccccccccc",
      "vccccccccccccccc",
      "vccccccccccccccc",
      "vccccccccccccccc",
      "vccccccccccccccc",
      "vccccccccccccccc",
      "vccccccccccccccc",
      "vccccccccccccccc",
      "vccccccccccccccc",
      "vccccccccccccccc",
      "vccccccccccccccc"
    ]
  ]
}