{
  "name": "multi_alienresearch_2_base8",
  "refpalette": "deceasedcraft:multi_alienresearch_2/multi_alienresearch_2_base8_palette",
  "xsize": 16,
  "zsize": 16,
  "slices": [
    [
      "vaaaaaaaabb    c",
      "vaaaaaaaaab     ",
      "vaaaaaaaaabb    ",
      "vaaaaaaaaaab    ",
      "vaaaaaaaaaabb   ",
      "vaaaaaaaaaaabb d",
      "vaaaaaaaaaaaaeef",
      "vaaaaaaaaaaaaaeb",
      "vaaaaaaaaaaaaaab",
      "vaaaaaaaaaaaaaaa",
      "vaaaaaaaaaaaaaaa",
      "vaaaaaaaaaaaaaaa",
      "vaaaaaaaaaaaaaaa",
      "vaaaaaaaaaaaaaaa",
      "vaaaaaaaaaaaaaaa",
      "vaaaaaaaaaaaaaaa"
    ],
    [
      "vaaaaaaab      c",
      "vaaaaaaaab      ",
      "vaaaaaaaab      ",
      "vaaaaaaaaab     ",
      "vaaaaaaaaab     ",
      "vaaaaaaaaaab    ",
      "vaaaaaaaaaaab dg",
      "vaaaaaaaaaaaae  ",
      "vaaaaaaaaaaaaab ",
      "vaaaaaaaaaaaaaab",
      "vaaaaaaaaaaaaaaa",
      "vaaaaaaaaaaaaaaa",
      "vaaaaaaaaaaaaaaa",
      "vaaaaaaaaaaaaaaa",
      "vaaaaaaaaaaaaaaa",
      "vaaaaaaaaaaaaaaa"
    ],
    [
      "vaaaaaaab       ",
      "vaaaaaaab       ",
      "vaaaaaaab       ",
      "vaaaaaaaab      ",
      "vaaaaaaaab      ",
      "vaaaaaaaaab     ",
      "vaaaaaaaaaab    ",
      "vaaaaaaaaaaaed  ",
      "vaaaaaaaaaaaee  ",
      "vaaaaaaaaaaaaab ",
      "vaaaaaaaaaaaaaab",
      "vaaaaaaaaaaaaaaa",
      "vaaaaaaaaaaaaaaa",
      "vaaaaaaaaaaaaaaa",
      "vaaaaaaaaaaaaaaa",
      "vaaaaaaaaaaaaaaa"
    ],
    [
      "vaaaaaab        ",
      "vaaaaaab        ",
      "vaaaaaaab       ",
      "vaaaaaaab       ",
      "vaaaaaaab       ",
      "vaaaaaaaab      ",
      "vaaaaaaaaab     ",
      "vaaaaaaaaaab    ",
      "vaaaaaaaaaaed   ",
      "vaaaaaaaaaaaeb  ",
      "vaaaaaaaaaaaaab ",
      "vaaaaaaaaaaaaaab",
      "vaaaaaaaaaaaaaaa",
      "vaaaaaaaaaaaaaaa",
      "vaaaaaaaaaaaaaaa",
      "vaaaaaaaaaaaaaaa"
    ],
    [
      "vaaaaab         ",
      "vaaaaab         ",
      "vaaaaaab        ",
      "vaaaaaab        ",
      "vaaaaaaab       ",
      "vaaaaaaab       ",
      "vaaaaaaaab      ",
      "vaaaaaaaaab     ",
      "vaaaaaaaaab d   ",
      "vaaaaaaaaaae    ",
      "vaaaaaaaaaaabb  ",
      "vaaaaaaaaaaaaab ",
      "vaaaaaaaaaaaaaab",
      "vaaaaaaaaaaaaaaa",
      "vaaaaaaaaaaaaaaa",
      "vaaaaaaaaaaaaaaa"
    ],
    [
      "vaaaab          ",
      "vaaaaab         ",
      "vaaaaab         ",
      "vaaaaab         ",
      "vaaaaaab        ",
      "vaaaaaaab       ",
      "vaaaaaaab       ",
      "vaaaaaaaab      ",
      "vaaaaaaaaab d   ",
      "vaaaaaaaaaae    ",
      "vaaaaaaaaaaab   ",
      "vaaaaaaaaaaaab  ",
      "vaaaaaaaaaaaaabb",
      "vaaaaaaaaaaaaaaa",
      "vaaaaaaaaaaaaaaa",
      "vaaaaaaaaaaaaaaa"
    ]
  ]
}