{
  "name": "multi_alienresearch_2_base4",
  "refpalette": "deceasedcraft:multi_alienresearch_2/multi_alienresearch_2_base4_palette",
  "xsize": 16,
  "zsize": 16,
  "slices": [
    [
      "vab             ",
      "vaab            ",
      "vaab            ",
      "vaab            ",
      "vaaab           ",
      "vaaab           ",
      "vaaaab          ",
      "vaaaab          ",
      "vaaaaab         ",
      "vaaaaaab        ",
      "vaaaaaaab       ",
      "vaaaaaaacd      ",
      "vaaaaaaaacb     ",
      "vaaaaaaaaaab    ",
      "vaaaaaaaaaaab   ",
      "vaaaaaaaaaaaabb "
    ],
    [
      "vaab            ",
      "vaab            ",
      "vaab            ",
      "vaaab           ",
      "vaaab           ",
      "vaaaab          ",
      "vaaaab          ",
      "vaaaaab         ",
      "vaaaaab         ",
      "vaaaaaab        ",
      "vaaaaaaab d     ",
      "vaaaaaaaac      ",
      "vaaaaaaaaab     ",
      "vaaaaaaaaaab    ",
      "vaaaaaaaaaaabb  ",
      "vaaaaaaaaaaaaabb"
    ],
    [
      "vaab            ",
      "vaab            ",
      "vaaab           ",
      "vaaab           ",
      "vaaab           ",
      "vaaaab          ",
      "vaaaab          ",
      "vaaaaab         ",
      "vaaaaaab        ",
      "vaaaaaaab       ",
      "vaaaaaaab d     ",
      "vaaaaaaaac      ",
      "vaaaaaaaaabb    ",
      "vaaaaaaaaaaab   ",
      "vaaaaaaaaaaaab  ",
      "vaaaaaaaaaaaaabb"
    ],
    [
      "vaab            ",
      "vaaab           ",
      "vaaab           ",
      "vaaab           ",
      "vaaaab          ",
      "vaaaab          ",
      "vaaaaab         ",
      "vaaaaab         ",
      "vaaaaaab        ",
      "vaaaaaaab       ",
      "vaaaaaaaacd     ",
      "vaaaaaaaaac     ",
      "vaaaaaaaaaab    ",
      "vaaaaaaaaaaab   ",
      "vaaaaaaaaaaaabb ",
      "vaaaaaaaaaaaaaab"
    ],
    [
      "vaaab           ",
      "vaaab           ",
      "vaaab           ",
      "vaaaab          ",
      "vaaaab          ",
      "vaaaaab         ",
      "vaaaaab         ",
      "vaaaaaab        ",
      "vaaaaaaab       ",
      "vaaaaaaab       ",
      "vaaaaaaaacd     ",
      "vaaaaaaaaac     ",
      "vaaaaaaaaaabb   ",
      "vaaaaaaaaaaaab  ",
      "vaaaaaaaaaaaaabb",
      "vaaaaaaaaaaaaaaa"
    ],
    [
      "vaaab           ",
      "vaaaab          ",
      "vaaaab          ",
      "vaaaab          ",
      "vaaaaab         ",
      "vaaaaab         ",
      "vaaaaaab        ",
      "vaaaaaaab       ",
      "vaaaaaaab       ",
      "vaaaaaaaabed    ",
      "vaaaaaaaaace    ",
      "vaaaaaaaaaab    ",
      "vaaaaaaaaaaabb  ",
      "vaaaaaaaaaaaaab ",
      "vaaaaaaaaaaaaaab",
      "vaaaaaaaaaaaaaaa"
    ]
  ]
}