{
  "name": "multi_alienresearch_2_base3",
  "refpalette": "deceasedcraft:multi_alienresearch_2/multi_alienresearch_2_base3_palette",
  "xsize": 16,
  "zsize": 16,
  "slices": [
    [
      "vabbacdeeeefg   ",
      "vabbacdeeeeefg  ",
      "vabbacdeeeeefg  ",
      "vabbahcdeeeeefg ",
      "vabbahcdeeeeeffg",
      "vabbahhcdeeeeeff",
      "vabbahhhcdeeeeef",
      "vabbahhhcdeeeeee",
      "vabbahhhhcdeeeee",
      "vabbahhhhhideeee",
      "vabbahhhhhhideee",
      "vabbahhhhhhhcdde",
      "vabbahhhhhhhhccd",
      "vabbahhhhhhhhhhc",
      "vabbahhhhhhhhhhh",
      "vabbahhhhhhhhhhh"
    ],
    [
      "va  ac     j    ",
      "vkl ahc    mj   ",
      "va  ahc     j   ",
      "va  ahc      j  ",
      "va  ahhcnn   j  ",
      "va  ahhhcn    o ",
      "va  ahhhcl    po",
      "va  ahhhhc      ",
      "vkl ahhhhhc d   ",
      "va  ahhhhhhf    ",
      "va  ahhhhhhhc   ",
      "va  ahhhhhhhhcq ",
      "va  ahhhhhhhhhcc",
      "va  ahhhhhhhhhhh",
      "va  ahhhhhhhhhhh",
      "vkl ahhhhhhhhhhh"
    ],
    [
      "va  ahc    j    ",
      "vk  ahc     j   ",
      "va  ahhc    j   ",
      "va  ahhc     j  ",
      "va  ahhhc    j  ",
      "va  ahhhcn    o ",
      "va  ahhhhc    ro",
      "va  ahhhhhc     ",
      "vk  ahhhhhc d   ",
      "va  ahhhhhhf    ",
      "va  ahhhhhhhcc  ",
      "va  ahhhhhhhhhc ",
      "va  ahhhhhhhhhhc",
      "va  ahhhhhhhhhhh",
      "va  ahhhhhhhhhhh",
      "vk  ahhhhhhhhhhh"
    ],
    [
      "va  ahhc   j    ",
      "vk  ahhc    j   ",
      "va  ahhhc   j   ",
      "va  ahhhc    j  ",
      "va  ahhhc    j  ",
      "va  ahhhhc    o ",
      "va  ahhhhhc    o",
      "va  ahhhhhhc    ",
      "vk  ahhhhhhfd   ",
      "va  ahhhhhhhfc  ",
      "va  ahhhhhhhhhc ",
      "va  ahhhhhhhhhhc",
      "va  ahhhhhhhhhhh",
      "va  ahhhhhhhhhhh",
      "va  ahhhhhhhhhhh",
      "vk  ahhhhhhhhhhh"
    ],
    [
      "va  ahhhc  j    ",
      "vk  ahhhc   j   ",
      "va  ahhhc   j   ",
      "va  ahhhhc   j  ",
      "va  ahhhhc   j  ",
      "va  ahhhhhc   o ",
      "va  ahhhhhhc   o",
      "va  ahhhhhhhfd  ",
      "vk  ahhhhhhhff  ",
      "va  ahhhhhhhhhc ",
      "va  ahhhhhhhhhhc",
      "va  ahhhhhhhhhhh",
      "va  ahhhhhhhhhhh",
      "va  ahhhhhhhhhhh",
      "va  ahhhhhhhhhhh",
      "vk  ahhhhhhhhhhh"
    ],
    [
      "va  ahhhc  s    ",
      "vk  ahhhhc  s   ",
      "va  ahhhhc  s   ",
      "va  ahhhhhc  s  ",
      "va  ahhhhhc  s  ",
      "va  ahhhhhhc  j ",
      "va  ahhhhhhhc dj",
      "va  ahhhhhhhhf  ",
      "vk  ahhhhhhhhhc ",
      "va  ahhhhhhhhhhc",
      "va  ahhhhhhhhhhh",
      "va  ahhhhhhhhhhh",
      "va  ahhhhhhhhhhh",
      "va  ahhhhhhhhhhh",
      "va  ahhhhhhhhhhh",
      "vk  ahhhhhhhhhhh"
    ]
  ]
}