{
  "name": "multi_terraceplaza_10_ground",
  "refpalette": "deceasedcraft:multi_terraceplaza_10/multi_terraceplaza_10_ground_palette",
  "xsize": 16,
  "zsize": 16,
  "slices": [
    [
      "aaabbbcddddddedd",
      "aaabbbcddddddedd",
      "aaabbbcddddddedd",
      "aaabbbfddddddedd",
      "aaabbbcddddddedd",
      "aaabbbcddddddddd",
      "aaabbbcddddddddd",
      "bbbbbbcddddddddd",
      "bbbbbbcddddddddd",
      "bbbbbbcddddddddd",
      "bbbbbbcddddddddd",
      "bbbbbbcddddddddd",
      "bbbbbbcddddddddd",
      "bbbbbbcddddddedd",
      "ggggggfddddddedd",
      "bbbbbbcddddddedd"
    ],
    [
      "hhigj k      lm ",
      "   gn o      lp ",
      "   gq o      le ",
      "  rg  f      stu",
      "  wgj o       e ",
      "  wgn o      xe ",
      "  rgq y         ",
      "gggA            ",
      "   A            ",
      "BBBA            ",
      "                ",
      "      y         ",
      "CDE CDo      xe ",
      "FIE FIo       e ",
      "ggggggf      stu",
      "    JKo      le "
    ],
    [
      "LMNg  k         ",
      "   gO o         ",
      "   g  o         ",
      "  !g  f       P ",
      "   g  o       Q ",
      "   gR o       S ",
      "  Tg  y         ",
      "gggU            ",
      "   U            ",
      "VW              ",
      "                ",
      "      y         ",
      " V   Xo       Q ",
      "     Vo       S ",
      "ggggggf       P ",
      "    YKo         "
    ],
    [
      "ZZZg  k         ",
      "   g  o         ",
      "   g  o         ",
      "   g  f       0 ",
      "   g  o         ",
      "   g  o         ",
      "   g  y         ",
      "ggg1            ",
      "   1            ",
      "2221            ",
      "                ",
      "      y         ",
      "      o         ",
      "      o         ",
      "ggggggf       0 ",
      "    YKo         "
    ],
    [
      "   g  k         ",
      "   g  o         ",
      "   g  o         ",
      "   g  f       0 ",
      "   g  o         ",
      "   g  o         ",
      "   g  y         ",
      "ggg3            ",
      "   4            ",
      "56!5            ",
      "                ",
      "      y         ",
      "      o         ",
      "      o         ",
      "ggggggf       0 ",
      "     Ko         "
    ],
    [
      "   g  7         ",
      "   g  7         ",
      "   g  7         ",
      "   g  f         ",
      "   g  7         ",
      "   g  7         ",
      "   g  78        ",
      "ggg   78        ",
      "      78        ",
      "9  9  78        ",
      "      78        ",
      "      78        ",
      "      7         ",
      "      7         ",
      "ggggggf         ",
      "     K7         "
    ]
  ]
}