{
  "name": "multi_terraceplaza_10_base2",
  "refpalette": "deceasedcraft:multi_terraceplaza_10/multi_terraceplaza_10_base2_palette",
  "xsize": 16,
  "zsize": 16,
  "slices": [
    [
      "aaaaaaaaaaaaaaaa",
      "aaaaaaaaaaaaaaaa",
      "aaaaaaaaaaaaaaaa",
      "aaaaaabaaaaaaaaa",
      "aaaaaaaaaaaaaaaa",
      "aaaaaaaaaaaaaaaa",
      "aaaaaaaaaaaaaaaa",
      "aaaaaaaaaaaaaaaa",
      "aaaaaaaaaaaaaaaa",
      "aaaaaaaaaaaaaaaa",
      "aaaaaaaaaaaaaaaa",
      "aaaaaaaaaaaaaaaa",
      "aaaaaaaaaaaaaaaa",
      "aaaaaaaaaaaaaaaa",
      "ccccccbccccccccc",
      "aaaaaaaaaaaaaaaa"
    ],
    [
      "d               ",
      "d         e  e  ",
      "  f  ghh  g  h  ",
      "  g  ibi  h  h  ",
      "  f  fji  i  i  ",
      "  g  ijg  h  i  ",
      "  h  gjf  i  f  ",
      "  h  gji  f  i  ",
      "  i  ijg  f  i  ",
      "  i  fjf  i  g  ",
      "     kkk  k  k  ",
      "                ",
      "                ",
      "kkk kkkkk kkkkk ",
      "ccccccbccccccccc",
      " lmmmnolmmmmn   "
    ],
    [
      "                ",
      "          p  q  ",
      "  h  fgi  h  g  ",
      "  h  gbg  g  h  ",
      "  i  ijf  i  g  ",
      "  g  gjf  g  f  ",
      "  f  ijf  f  i  ",
      "  g  fjg  i  f  ",
      "  h  gjh  i  g  ",
      "  g  gji  g  f  ",
      "     rrr  r  r  ",
      "                ",
      "                ",
      "sss stsss s!sss ",
      "ccccccbccccccccc",
      "   !uwx w w     "
    ],
    [
      "                ",
      "                ",
      "                ",
      "      b         ",
      "                ",
      "                ",
      "                ",
      "                ",
      "                ",
      "                ",
      "       y     A  ",
      "                ",
      "                ",
      "BC  D E F I  J  ",
      "ccccccbccccccccc",
      "                "
    ],
    [
      "                ",
      "                ",
      "                ",
      "      b         ",
      "                ",
      "                ",
      "                ",
      "                ",
      "                ",
      "                ",
      "                ",
      "                ",
      "                ",
      "                ",
      "ccccccbccccccccc",
      "                "
    ],
    [
      "                ",
      "                ",
      "                ",
      "      b         ",
      "                ",
      "                ",
      "                ",
      "                ",
      "                ",
      "                ",
      "                ",
      "                ",
      "                ",
      "      K         ",
      "ccccccbccccccccc",
      "                "
    ]
  ]
}