{
  "name": "multi_terraceplaza_10_floor3",
  "refpalette": "deceasedcraft:multi_terraceplaza_10/multi_terraceplaza_10_floor3_palette",
  "xsize": 16,
  "zsize": 16,
  "slices": [
    [
      "                ",
      "                ",
      "                ",
      "      a         ",
      "                ",
      "                ",
      "                ",
      "      bbbbbbbbbb",
      "      cccccccccc",
      "dddddeffffffffff",
      "dddddegggggggggg",
      "hhhhhhhhhhhhhhhh",
      "                ",
      "iiiiiiiiiiiiiiii",
      "                ",
      "                "
    ],
    [
      "                ",
      "                ",
      "                ",
      "      a         ",
      "      bbbbbbbbbb",
      "      cccccccccc",
      "bbbbbbffffffffff",
      "dddddegggggggggg",
      "dddddehhhhhhhhhh",
      "                ",
      "                ",
      "                ",
      "                ",
      "                ",
      "                ",
      "                "
    ],
    [
      "                ",
      "bbbbbbbbbbbbbbbb",
      "cccccccccccccccc",
      "jjjjjjajjjjjjjjj",
      "kkkkkkkkkkkkkkkk",
      "hhhhhhhhhhhhhhhh",
      "                ",
      "                ",
      "                ",
      "                ",
      "                ",
      "                ",
      "                ",
      "                ",
      "                ",
      "                "
    ],
    [
      "ffffffffffffffff",
      "gggggggggggggggg",
      "kkkkkkkkkkkkkkkk",
      "llllllllllllllll",
      "iiiiiiiiiiiiiiii",
      "                ",
      "                ",
      "                ",
      "                ",
      "                ",
      "                ",
      "                ",
      "                ",
      "                ",
      "                ",
      "                "
    ],
    [
      "                ",
      "                ",
      "                ",
      "                ",
      "                ",
      "                ",
      "                ",
      "                ",
      "                ",
      "                ",
      "                ",
      "                ",
      "                ",
      "                ",
      "                ",
      "                "
    ],
    [
      "                ",
      "                ",
      "                ",
      "                ",
      "                ",
      "                ",
      "                ",
      "                ",
      "                ",
      "                ",
      "                ",
      "                ",
      "                ",
      "                ",
      "                ",
      "                "
    ]
  ]
}