{
  "name": "multi_terraceplaza_10_floor1",
  "refpalette": "deceasedcraft:multi_terraceplaza_10/multi_terraceplaza_10_floor1_palette",
  "xsize": 16,
  "zsize": 16,
  "slices": [
    [
      "   a  b         ",
      "   a  b         ",
      "   a  b         ",
      "   a  c         ",
      "   a  b         ",
      "   a  b         ",
      "   a  b         ",
      "aaa   b         ",
      "      b         ",
      "d  d  b         ",
      "      b         ",
      "      b         ",
      "      b         ",
      "      b         ",
      "aaaaaac         ",
      "     eb         "
    ],
    [
      "ffffffghhhhhhhhh",
      "ffffffghhhhhhhhh",
      "ffffffghhhhhhhhh",
      "ggggggcggggggggg",
      "ffffffghhhhhhhhh",
      "ffffffghhhhhhhhh",
      "ffffffghhhhhhhhh",
      "ffffffghhhhhhhhh",
      "ffffffghhhhhhhhh",
      "ffffffghhhhhhhhh",
      "ffffffghhhhhhhhh",
      "ffffffghhhhhhhhh",
      "ffffffghhhhhhhhh",
      "ffffffghhhhhhhhh",
      "ggggggcggggggggg",
      "ffffffghhhhhhhhh"
    ],
    [
      "iiiiiijkkkkkkkkk",
      "iiiiiijkkkkkkkkk",
      "iiiiiijkkkkkklkk",
      "aaaaaackkkkkklkk",
      "iiiiiijkkkkkklkk",
      "iiiiiijkkkkkklkk",
      "iiiiiijkkkkkklkk",
      "iiiiiijkkkkkkkkk",
      "iiiiiijkkkkkkkkk",
      "iiiiiijkkkkkkkkk",
      "iiiiiijkkkkkkkkk",
      "iiiiiijkkkkkkkkk",
      "iiiiiijkkkkkkkkm",
      "iiiiiijkkkkkkkkn",
      "iiiiiickkkkkkkkn",
      "iiiiiijkkkkkkkkk"
    ],
    [
      "     op         ",
      "qrqr st      ul ",
      "wx x st       l ",
      "aaaaaac      yAB",
      "CCCCDDt      El ",
      "      t      EF ",
      "      p      EI ",
      "JJJD         I  ",
      "DDDDK           ",
      "DDDDL           ",
      "MMMD            ",
      "      p        m",
      "      t       NO",
      "      t        P",
      "Q RSTUc        P",
      "      t         "
    ],
    [
      "      p         ",
      "VrVr Wt       X ",
      "YxYx Zt       0 ",
      "aaaaaac       1 ",
      "2!3223t         ",
      "      t         ",
      "      p         ",
      "454             ",
      "36637           ",
      "23238           ",
      "9 #9           m",
      "      p       NO",
      "      t        P",
      "      t         ",
      "   $%^c         ",
      "      t         "
    ],
    [
      "      p         ",
      "rrrr  t         ",
      "&x&x  t         ",
      "aaaaaac       * ",
      "333333t         ",
      "      t         ",
      "      p         ",
      "                ",
      "3333(           ",
      "3333)          m",
      "              NO",
      "      p        P",
      "      t         ",
      "      t         ",
      "      c         ",
      "      t         "
    ]
  ]
}