{
  "name": "multi_terraceplaza_10_base1",
  "refpalette": "deceasedcraft:multi_terraceplaza_10/multi_terraceplaza_10_base1_palette",
  "xsize": 16,
  "zsize": 16,
  "slices": [
    [
      "                ",
      "                ",
      "                ",
      "      a         ",
      "                ",
      "                ",
      "                ",
      "                ",
      "                ",
      "                ",
      "                ",
      "                ",
      "                ",
      "                ",
      "bbbbbbabbbbbbbbb",
      "                "
    ],
    [
      "                ",
      "                ",
      "                ",
      "      a         ",
      "                ",
      "                ",
      "                ",
      "                ",
      "                ",
      "                ",
      "                ",
      "                ",
      "                ",
      "                ",
      "bbbbbbabbbbbbbbb",
      "                "
    ],
    [
      "                ",
      "                ",
      "                ",
      "      a         ",
      "                ",
      "                ",
      "                ",
      "                ",
      "                ",
      "                ",
      "                ",
      "                ",
      "                ",
      "                ",
      "bbbbbbabbbbbbbbb",
      "                "
    ],
    [
      "              cc",
      "              cc",
      "              cc",
      "      a       cc",
      "              cc",
      "              cc",
      "              cc",
      "              cc",
      "              cc",
      "              cc",
      "              cc",
      "cccccccccccccccc",
      "cccccccccccccccc",
      "dddddddddddddddd",
      "bbbbbbabbbbbbbbb",
      "dddddddddddddddd"
    ],
    [
      "eeeeeeeeeeeeeeef",
      "eeeeeeeeeeeeeeef",
      "eeeeeeeeeeeeeeef",
      "eeeeeeaeeeeeeeef",
      "eeeeeeeeeeeeeeef",
      "eeeeeeeeeeeeeeef",
      "eeeeeeeeeeeeeeef",
      "eeeeeeeeeeeeeeef",
      "eeeeeeeeeeeeeeef",
      "eeeeeeeeeeeeeeef",
      "eeeeeeeeeeeeeeef",
      "eeeeeeeeeeeeeeef",
      "ffffffffffffffff",
      "dddddddddddddddd",
      "bbbbbbabbbbbbbbb",
      "dddddddddddddddd"
    ],
    [
      "gggggghggggggggi",
      "gggggghggggggggi",
      "gggggghggggggggi",
      "hhhhhhahhhhhhhhh",
      "gggggghggggggggi",
      "gggggghggggggggi",
      "gggggghggggggggi",
      "gggggghggggggggi",
      "gggggghggggggggi",
      "gggggghggggggggi",
      "gggggghggggggggi",
      "gggggghggggggggi",
      "iiiiiihiiiiiiiii",
      "jjjjjjhjjjjjjjjj",
      "hhhhhhahhhhhhhhh",
      "gggggghggggggggg"
    ]
  ]
}