{
  "name": "multi_terraceplaza_10_floor2",
  "refpalette": "deceasedcraft:multi_terraceplaza_10/multi_terraceplaza_10_floor2_palette",
  "xsize": 16,
  "zsize": 16,
  "slices": [
    [
      "      a         ",
      "bbbb  c         ",
      "dddd  c         ",
      "eeeeeef       g ",
      "hij k c         ",
      "      c         ",
      "      a         ",
      "                ",
      "               l",
      "              mn",
      "               o",
      "      a         ",
      "      c         ",
      "      c         ",
      "      f         ",
      "      c         "
    ],
    [
      "     pqr        ",
      "      q         ",
      "ss s  q         ",
      "eeeeeef         ",
      " t  u q         ",
      "      q         ",
      "     pqw        ",
      "     pqx       l",
      "     pqw      mn",
      "     pqw       o",
      "     pqw        ",
      "     pqw        ",
      "      q         ",
      "      q         ",
      "      f         ",
      "      q         "
    ],
    [
      "      q         ",
      "      q         ",
      "      q         ",
      "eeeeeef         ",
      "      q         ",
      "      q         ",
      "   y  q        l",
      "      q       mn",
      "      q        o",
      "      q         ",
      "      q         ",
      "   A  q         ",
      "      q         ",
      "      q         ",
      "      f         ",
      "      q         "
    ],
    [
      "BBCCBBDEEEEEEEEE",
      "BBBBBBDEEEEEEEEE",
      "BBBBBBDEEEEEEEEE",
      "DDDDDDfDDDDDDDDD",
      "BBBBBBD        F",
      "BBBBBBD        l",
      "BBBBBBD       mn",
      "BBBBBBD        o",
      "BBBBBBD         ",
      "BBBBBBD         ",
      "BBBBBBD         ",
      "BBBBBBD         ",
      "BBBBBBD         ",
      "BBBBBBD         ",
      "DDDDDDfDDDDDDDDD",
      "      D         "
    ],
    [
      "IIIJJJKLLLLLLLLL",
      "JJJJJJKLLLLLLLLL",
      "JJJJJJKLLLLLLLLL",
      "KKKKKKfMMMMMMMMN",
      "OPOOPOK       mN",
      "POPPOOK       mn",
      "OOPPOOK        o",
      "OOPOOOK         ",
      "OOOOOOK         ",
      "OOOOOOK         ",
      "OOOOOOK         ",
      "OOOOOOK         ",
      "OOOOOOK         ",
      "QQQQQQKRRRRRRRRR",
      "DDDDDDfDDDDDDDDD",
      "JJJJJJJJJJJJJJJJ"
    ],
    [
      "                ",
      "                ",
      "                ",
      "      fSSSSSSSSo",
      "      S        o",
      "    T S        o",
      "    U S         ",
      "    V S         ",
      "      S         ",
      "      S         ",
      "WXXXWXSRRRRRRRRR",
      "      YYYYYYYYYY",
      "RRRRRRJJJJJJJJJJ",
      "ZZZZZZZZZZZZZZZZ",
      "ZZZZZZZZZZZZZZZZ",
      "0000000000000000"
    ]
  ]
}