{
  "name": "multi_nuclearpowerplant_13_ground",
  "refpalette": "deceasedcraft:multi_nuclearpowerplant_13/multi_nuclearpowerplant_13_ground_palette",
  "xsize": 16,
  "zsize": 16,
  "slices": [
    [
      "zaaaaaabbbcccc  ",
      "azaaaaaaabbccccc",
      "zzazaaaaaabbbccc",
      "zazaaaaaaaaabbcc",
      "azzaazaaaaaaabbb",
      "zzzazazaaaaaaaab",
      "zazzzzaaaaaaaaaa",
      "zzazazzazaaaaaaa",
      "zzzzzzzzaazaaaaa",
      "zzzzzazzzzzaazaa",
      "zzazzzzzzazzaaaz",
      "zzzzzzazzzzzaz z",
      "zzzzzzzzazzazzza",
      "zzzzzzzzzzzzzazz",
      "zzzzzzzzzzzzzzzz",
      "zzzzzzzzzzzzzzzz"
    ],
    [
      "      dzzzzccccc",
      " e     fdzzzzccc",
      "         dzzzzzc",
      "e         fgzazz",
      "  e         gzzz",
      "      e      fdz",
      "   eee         f",
      "     e          ",
      "e  e   e        ",
      "eee      ee  e  ",
      "e    e  e     he",
      "    ee       eij",
      "   ej  e  e  ke ",
      " eeej  ee      e",
      " e       ej eee ",
      "      e ee   e  "
    ],
    [
      "       lll zzzzz",
      "         ll  zzz",
      "          lll  z",
      "            ll  ",
      "             lll",
      "               l",
      "                ",
      "                ",
      "                ",
      "                ",
      "                ",
      "                ",
      "                ",
      "                ",
      "                ",
      "                "
    ],
    [
      "       lll   e  ",
      "         ll     ",
      "          lll   ",
      "            ll  ",
      "             lll",
      "               l",
      "                ",
      "                ",
      "                ",
      "                ",
      "                ",
      "                ",
      "                ",
      "                ",
      "                ",
      "                "
    ],
    [
      "       mm       ",
      "         m      ",
      "          mm    ",
      "            m   ",
      "             mm ",
      "               m",
      "                ",
      "                ",
      "                ",
      "                ",
      "                ",
      "                ",
      "                ",
      "                ",
      "                ",
      "                "
    ],
    [
      "                ",
      "                ",
      "                ",
      "                ",
      "                ",
      "                ",
      "                ",
      "                ",
      "                ",
      "                ",
      "                ",
      "                ",
      "                ",
      "                ",
      "                ",
      "                "
    ]
  ]
}