{
  "name": "multi_nuclearpowerplant_13_base8",
  "refpalette": "deceasedcraft:multi_nuclearpowerplant_13/multi_nuclearpowerplant_13_base8_palette",
  "xsize": 16,
  "zsize": 16,
  "slices": [
    [
      "aaaaaabbbbbbbbbb",
      "aaaaaaabbbbbbbbb",
      "aaaaaaaaabbbbbbb",
      "aaaaaaaaaabbbbbb",
      "aaaaaaaaaaabbbbb",
      "aaaaaaaaaaaabbbb",
      "aaaaaaaaaaaabbbb",
      "aaaaaaaaaaaaabbb",
      "aaaaaaaaaaaaaabb",
      "aaaaaaaaaaaaaaab",
      "aaaaaaaaaaaaaaaa",
      "aaaaaaaaaaaaaaaa",
      "aaaaaaaaaaaaaaaa",
      "aaaaaaaaaaaaaaaa",
      "aaaaaaaaaaaaaaaa",
      "vvvvvvvvvvvvvvvv"
    ],
    [
      "aaaaaacddc======",
      "aaaaaaaccc======",
      "aaaaaaaaacc=====",
      "aaaaaaaaaac=====",
      "aaaaaaaaaaac====",
      "aaaaaaaaaaaac===",
      "aaaaaaaaaaaac===",
      "aaaaaaaaaaaaac==",
      "aaaaaaaaaaaaaac=",
      "aaaaaaaaaaaaaaac",
      "aaaaaaaaaaaaaaaa",
      "aaaaaaaaaaaaaaaa",
      "aaaaaaaaaaaaaaaa",
      "aaaaaaaaaaaaaaaa",
      "aaaaaaaaaaaaaaaa",
      "vvvvvvvvvvvvvvvv"
    ],
    [
      "aaaaaaeffeaaaaaa",
      "aaaaaaaeeeaaaaaa",
      "aaaaaaaaaeeaaaaa",
      "aaaaaaaaaaeaaaaa",
      "aaaaaaaaaaaeaaaa",
      "aaaaaaaaaaaaeaaa",
      "aaaaaaaaaaaaeaaa",
      "aaaaaaaaaaaaaeaa",
      "aaaaaaaaaaaaaaea",
      "aaaaaaaaaaaaaaae",
      "aaaaaaaaaaaaaaaa",
      "aaaaaaaaaaaaaaaa",
      "aaaaaaaaaaaaaaaa",
      "aaaaaaaaaaaaaaaa",
      "aaaaaaaaaaaaaaaa",
      "vvvvvvvvvvvvvvvv"
    ],
    [
      "aaaaaaeffeaaaaaa",
      "aaaaaaaeeeaaaaaa",
      "aaaaaaaaaeeaaaaa",
      "aaaaaaaaaaeaaaaa",
      "aaaaaaaaaaaeaaaa",
      "aaaaaaaaaaaaeaaa",
      "aaaaaaaaaaaaeaaa",
      "aaaaaaaaaaaaaeaa",
      "aaaaaaaaaaaaaaea",
      "aaaaaaaaaaaaaaae",
      "aaaaaaaaaaaaaaaa",
      "aaaaaaaaaaaaaaaa",
      "aaaaaaaaaaaaaaaa",
      "aaaaaaaaaaaaaaaa",
      "aaaaaaaaaaaaaaaa",
      "vvvvvvvvvvvvvvvv"
    ],
    [
      "aaaaaaeffecccccc",
      "aaaaaaaeeecccccc",
      "aaaaaaaaaeeccccc",
      "aaaaaaaaaaeccccc",
      "aaaaaaaaaaaecccc",
      "aaaaaaaaaaaaeccc",
      "aaaaaaaaaaaaeccc",
      "aaaaaaaaaaaaaecc",
      "aaaaaaaaaaaaaaec",
      "aaaaaaaaaaaaaaae",
      "aaaaaaaaaaaaaaaa",
      "aaaaaaaaaaaaaaaa",
      "aaaaaaaaaaaaaaaa",
      "aaaaaaaaaaaaaaaa",
      "aaaaaaaaaaaaaaaa",
      "vvvvvvvvvvvvvvvv"
    ],
    [
      "aaaaaaeffe      ",
      "aaaaaaaeee      ",
      "aaaaaaaaaee     ",
      "aaaaaaaaaae     ",
      "aaaaaaaaaaae    ",
      "aaaaaaaaaaaae   ",
      "aaaaaaaaaaaae   ",
      "aaaaaaaaaaaaae  ",
      "aaaaaaaaaaaaaae ",
      "aaaaaaaaaaaaaaae",
      "aaaaaaaaaaaaaaaa",
      "aaaaaaaaaaaaaaaa",
      "aaaaaaaaaaaaaaaa",
      "aaaaaaaaaaaaaaaa",
      "aaaaaaaaaaaaaaaa",
      "vvvvvvvvvvvvvvvv"
    ]
  ]
}