{
  "name": "multi_nuclearpowerplant_13_base1",
  "refpalette": "deceasedcraft:multi_nuclearpowerplant_13/multi_nuclearpowerplant_13_base1_palette",
  "xsize": 16,
  "zsize": 16,
  "slices": [
    [
      "aaaaaabzzccccccc",
      "aaaaaaabbzcccccc",
      "aaaaaaaaabzzcccc",
      "aaaaaaaaaabbzccc",
      "aaaaaaaaaaaabzzc",
      "aaaaaaaaaaaaabbz",
      "aaaaaaaaaaaaaaab",
      "aaaaaaaaaaaaaaaa",
      "aaaaaaaaaaaaaaaa",
      "aaaaaaaaaaaaaaaa",
      "vvvvvvvvvvvvvvvv",
      "ddddddddddddddde",
      "       fgggh   e",
      "         fgh   e",
      "        ifgh   e",
      "vvvvvvvvvvvvvvvv"
    ],
    [
      "jjjjjjkll       ",
      "jjjjjjjkkl      ",
      "jjjjjjjjjkll    ",
      "jjjjjjjjjjkkl   ",
      "jjjjjjjjjjjjkll ",
      "jjjjjjjjjjjjjkkl",
      "jjjjjjjjjjjjjjjk",
      "jjjjjjjjjjjjjjjj",
      "jjjjjjjjjjjjjjjj",
      "jjjjjjjjjjjjjjjj",
      "vvvvvvvvvvvvvvvv",
      "            ghhe",
      "         fggghhe",
      "          mfghhe",
      "          nfghhe",
      "vvvvvvvvvvvvvvvv"
    ],
    [
      "jjjjjjk         ",
      "jjjjjjjkk       ",
      "jjjjjjjjjk      ",
      "jjjjjjjjjjkk    ",
      "jjjjjjjjjjjjk   ",
      "jjjjjjjjjjjjjkk ",
      "jjjjjjjjjjjjjjjk",
      "jjjjjjjjjjjjjjjj",
      "jjjjjjjjjjjjjjjj",
      "jjjjjjjjjjjjjjjj",
      "vvvvvvvvvvvvvvvv",
      "            gffe",
      "           fgffe",
      "            offe",
      "            pffe",
      "vvvvvvvvvvvvvvvv"
    ],
    [
      "jjjjjjk         ",
      "jjjjjjjkk       ",
      "jjjjjjjjjk      ",
      "jjjjjjjjjjkk    ",
      "jjjjjjjjjjjjk   ",
      "jjjjjjjjjjjjjkk ",
      "jjjjjjjjjjjjjjjk",
      "jjjjjjjjjjjjjjjj",
      "jjjjjjjjjjjjjjjj",
      "jjjjjjjjjjjjjjjj",
      "vvvvvvvvvvvvvvvv",
      "            fqqe",
      "               e",
      "               e",
      "               e",
      "vvvvvvvvvvvvvvvv"
    ],
    [
      "jjjjjjk         ",
      "jjjjjjjkk       ",
      "jjjjjjjjjkr     ",
      "jjjjjjjjjjkk    ",
      "jjjjjjjjjjjjk   ",
      "jjjjjjjjjjjjjkk ",
      "jjjjjjjjjjjjjjjk",
      "jjjjjjjjjjjjjjjj",
      "jjjjjjjjjjjjjjjj",
      "jjjjjjjjjjjjjjjj",
      "vvvvvvvvvvvvvvvv",
      "            sqqe",
      "               e",
      "               e",
      "               e",
      "vvvvvvvvvvvvvvvv"
    ],
    [
      "jjjjjjkttt      ",
      "jjjjjjjkktt     ",
      "jjjjjjjjjkttt   ",
      "jjjjjjjjjjkktt  ",
      "jjjjjjjjjjjjkttt",
      "jjjjjjjjjjjjjkkt",
      "jjjjjjjjjjjjjjjk",
      "jjjjjjjjjjjjjjjj",
      "jjjjjjjjjjjjjjjj",
      "jjjjjjjjjjjjjjjj",
      "vvvvvvvvvvvvvvvv",
      "uuuuuuuuuuuuuwxe",
      "uuuuuuuuuuuuuyye",
      "uuuuuuuuuuuuuyye",
      "uuuuuuuuuuuuuAAe",
      "vvvvvvvvvvvvvvvv"
    ]
  ]
}