{
  "name": "multi_nuclearpowerplant_13_base2",
  "refpalette": "deceasedcraft:multi_nuclearpowerplant_13/multi_nuclearpowerplant_13_base2_palette",
  "xsize": 16,
  "zsize": 16,
  "slices": [
    [
      "      a         ",
      "       aa       ",
      "         a      ",
      "          aa    ",
      "            a   ",
      "             aa ",
      "              aa",
      "              ab",
      "              ab",
      "              aa",
      "             aaa",
      "               c",
      "               c",
      "               c",
      "               c",
      "vvvvvvvvvvvvvvvv"
    ],
    [
      "      a         ",
      "       aa       ",
      "         a      ",
      "          aa    ",
      "            a   ",
      "             aa ",
      "              aa",
      "              ab",
      "              ab",
      "              aa",
      "             aaa",
      "               c",
      "de             c",
      "de             c",
      "de             c",
      "vvvvvvvvvvvvvvvv"
    ],
    [
      "      a         ",
      "       aa       ",
      "         a      ",
      "          aa    ",
      "            a   ",
      "             aa ",
      "              aa",
      "              ab",
      "              ab",
      "              aa",
      "             aaa",
      "               c",
      "ddde           c",
      "fgde           c",
      "hgde           c",
      "vvvvvvvvvvvvvvvv"
    ],
    [
      "      a         ",
      "       aa       ",
      "         a      ",
      "          aa    ",
      "            a   ",
      "             aa ",
      "              aa",
      "              ab",
      "              ab",
      "              aa",
      "             aaa",
      "               c",
      " gddde         c",
      "  igde         c",
      "j kgde         c",
      "vvvvvvvvvvvvvvvv"
    ],
    [
      "      a         ",
      "       aa       ",
      "         a      ",
      "          aa    ",
      "            a   ",
      "             aa ",
      "              aa",
      "              al",
      "              al",
      "              al",
      "             aam",
      "               c",
      "   gddde       c",
      "    ngde       c",
      "     gde       c",
      "vvvvvvvvvvvvvvvv"
    ],
    [
      "      aooooooooo",
      "       aaooooooo",
      "         aoooooo",
      "          aaoooo",
      "            aooo",
      "             aao",
      "              aa",
      "              ap",
      "              ap",
      "              ap",
      "qqqqqqqqqqqqqaam",
      "               c",
      "     gddde     c",
      "      rgde     c",
      "      sgde     c",
      "vvvvvvvvvvvvvvvv"
    ]
  ]
}