{
  "name": "multi_nuclearpowerplant_13_base7",
  "refpalette": "deceasedcraft:multi_nuclearpowerplant_13/multi_nuclearpowerplant_13_base7_palette",
  "xsize": 16,
  "zsize": 16,
  "slices": [
    [
      "aaaaaabccb      ",
      "aaaaaaabbb      ",
      "aaaaaaaaabb     ",
      "aaaaaaaaaab     ",
      "aaaaaaaaaaab    ",
      "aaaaaaaaaaaab   ",
      "aaaaaaaaaaaab   ",
      "aaaaaaaaaaaaab  ",
      "aaaaaaaaaaaaaab ",
      "aaaaaaaaaaaaaaab",
      "aaaaaaaaaaaaaaaa",
      "aaaaaaaaaaaaaaaa",
      "aaaaaaaaaaaaaaaa",
      "aaaaaaaaaaaaaaaa",
      "aaaaaaaaaaaaaaaa",
      "vvvvvvvvvvvvvvvv"
    ],
    [
      "aaaaaabccb      ",
      "aaaaaaabbb      ",
      "aaaaaaaaabb     ",
      "aaaaaaaaaab     ",
      "aaaaaaaaaaab    ",
      "aaaaaaaaaaaab   ",
      "aaaaaaaaaaaab   ",
      "aaaaaaaaaaaaab  ",
      "aaaaaaaaaaaaaab ",
      "aaaaaaaaaaaaaaab",
      "aaaaaaaaaaaaaaaa",
      "aaaaaaaaaaaaaaaa",
      "aaaaaaaaaaaaaaaa",
      "aaaaaaaaaaaaaaaa",
      "aaaaaaaaaaaaaaaa",
      "vvvvvvvvvvvvvvvv"
    ],
    [
      "aaaaaabccb      ",
      "aaaaaaabbb      ",
      "aaaaaaaaabb     ",
      "aaaaaaaaaab     ",
      "aaaaaaaaaaab    ",
      "aaaaaaaaaaaab   ",
      "aaaaaaaaaaaab   ",
      "aaaaaaaaaaaaab  ",
      "aaaaaaaaaaaaaab ",
      "aaaaaaaaaaaaaaab",
      "aaaaaaaaaaaaaaaa",
      "aaaaaaaaaaaaaaaa",
      "aaaaaaaaaaaaaaaa",
      "aaaaaaaaaaaaaaaa",
      "aaaaaaaaaaaaaaaa",
      "vvvvvvvvvvvvvvvv"
    ],
    [
      "aaaaaabccb      ",
      "aaaaaaabbb      ",
      "aaaaaaaaabb     ",
      "aaaaaaaaaab     ",
      "aaaaaaaaaaab    ",
      "aaaaaaaaaaaab   ",
      "aaaaaaaaaaaab   ",
      "aaaaaaaaaaaaab  ",
      "aaaaaaaaaaaaaab ",
      "aaaaaaaaaaaaaaab",
      "aaaaaaaaaaaaaaaa",
      "aaaaaaaaaaaaaaaa",
      "aaaaaaaaaaaaaaaa",
      "aaaaaaaaaaaaaaaa",
      "aaaaaaaaaaaaaaaa",
      "vvvvvvvvvvvvvvvv"
    ],
    [
      "aaaaaabccb      ",
      "aaaaaaabbb      ",
      "aaaaaaaaabb     ",
      "aaaaaaaaaab     ",
      "aaaaaaaaaaab    ",
      "aaaaaaaaaaaab   ",
      "aaaaaaaaaaaab   ",
      "aaaaaaaaaaaaab  ",
      "aaaaaaaaaaaaaab ",
      "aaaaaaaaaaaaaaab",
      "aaaaaaaaaaaaaaaa",
      "aaaaaaaaaaaaaaaa",
      "aaaaaaaaaaaaaaaa",
      "aaaaaaaaaaaaaaaa",
      "aaaaaaaaaaaaaaaa",
      "vvvvvvvvvvvvvvvv"
    ],
    [
      "ddddddbccbeeeeee",
      "dddddddbbbeeeeee",
      "dddddddddbbeeeee",
      "ddddddddddbeeeee",
      "dddddddddddbeeee",
      "ddddddddddddbeee",
      "ddddddddddddbeee",
      "dddddddddddddbee",
      "ddddddddddddddbe",
      "dddddddddddddddb",
      "dddddddddddddddd",
      "dddddddddddddddd",
      "dddddddddddddddd",
      "dddddddddddddddd",
      "dddddddddddddddd",
      "vvvvvvvvvvvvvvvv"
    ]
  ]
}