{
  "name": "multi_nuclearpowerplant_13_base6",
  "refpalette": "deceasedcraft:multi_nuclearpowerplant_13/multi_nuclearpowerplant_13_base6_palette",
  "xsize": 16,
  "zsize": 16,
  "slices": [
    [
      "vvvvvvabcadddddd",
      "vvvvvvvaaaaddddd",
      "vvvvvvvvvaaadddd",
      "vvvvvvvvvvaadddd",
      "vvvvvvvvvvvaaddd",
      "vvvvvvvvvvvvaaad",
      "vvvvvvvvvvvvaeea",
      "vvvvvvvvvvvvvaee",
      "vvvvvvvvvvvvvvae",
      "vvvvvvvvvvvvvvva",
      "vvvvvvvvvvvvvvvv",
      "vvvvvvvvvvvvvvvv",
      "vvvvvvvvvvvvvvvv",
      "vvvvvvvvvvvvvvvv",
      "vvvvvvvvvvvvvvvv",
      "vvvvvvvvvvvvvvvv"
    ],
    [
      "ffffffg  h      ",
      "fffffffgghh     ",
      "fffffffffghh    ",
      "ffffffffffgg    ",
      "ffffffffffffg   ",
      "fffffffffffffgg ",
      "fffffffffffffffg",
      "ffffffffffffffff",
      "ffffffffffffffff",
      "ffffffffffffffff",
      "ffffffffffffffff",
      "ffffffffffffffff",
      "ffffffffffffffff",
      "ffffffffffffffff",
      "ffffffffffffffff",
      "vvvvvvvvvvvvvvvv"
    ],
    [
      "bbbbbbg         ",
      "bbbbbbbgg       ",
      "bbbbbbbbbg      ",
      "bbbbbbbbbbgg    ",
      "bbbbbbbbbbbbg   ",
      "bbbbbbbbbbbbbgg ",
      "bbbbbbbbbbbbbbbg",
      "bbbbbbbbbbbbbbbg",
      "bbbbbbbbbbbbbbbg",
      "bbbbbbbbbbbbbbbg",
      "bbbbbbbbbbbbbggg",
      "bbbbbbbbbbbbbbbi",
      "bbbbbbbbbbbbbbbi",
      "bbbbbbbbbbbbbbbi",
      "bbbbbbbbbbbbbbbi",
      "vvvvvvvvvvvvvvvv"
    ],
    [
      "bbbbbbg         ",
      "bbbbbbbgg       ",
      "bbbbbbbbbg      ",
      "bbbbbbbbbbgg    ",
      "bbbbbbbbbbbbg   ",
      "bbbbbbbbbbbbbgg ",
      "bbbbbbbbbbbbbbbg",
      "bbbbbbbbbbbbbbbg",
      "bbbbbbbbbbbbbbbg",
      "bbbbbbbbbbbbbbbg",
      "bbbbbbbbbbbbbggg",
      "bbbbbbbbbbbbbbbi",
      "bbbbbbbbbbbbbbbi",
      "bbbbbbbbbbbbbbbi",
      "bbbbbbbbbbbbbbbi",
      "vvvvvvvvvvvvvvvv"
    ],
    [
      "bbbbbbg         ",
      "bbbbbbbgg       ",
      "bbbbbbbbbg      ",
      "bbbbbbbbbbgg    ",
      "bbbbbbbbbbbbg   ",
      "bbbbbbbbbbbbbgg ",
      "bbbbbbbbbbbbbbbg",
      "bbbbbbbbbbbbbbbg",
      "bbbbbbbbbbbbbbbg",
      "bbbbbbbbbbbbbbbg",
      "bbbbbbbbbbbbbggg",
      "bbbbbbbbbbbbbbbi",
      "bbbbbbbbbbbbbbbi",
      "bbbbbbbbbbbbbbbi",
      "bbbbbbbbbbbbbbbi",
      "vvvvvvvvvvvvvvvv"
    ],
    [
      "bbbbbbg         ",
      "bbbbbbbgg       ",
      "bbbbbbbbbg      ",
      "bbbbbbbbbbgg    ",
      "bbbbbbbbbbbbg   ",
      "bbbbbbbbbbbbbgg ",
      "bbbbbbbbbbbbbbbg",
      "bbbbbbbbbbbbbbbg",
      "bbbbbbbbbbbbbbbg",
      "bbbbbbbbbbbbbbbg",
      "bbbbbbbbbbbbbggg",
      "bbbbbbbbbbbbbbbi",
      "bbbbbbbbbbbbbbbi",
      "bbbbbbbbbbbbbbbi",
      "bbbbbbbbbbbbbbbi",
      "vvvvvvvvvvvvvvvv"
    ]
  ]
}