{
  "name": "multi_nuclearpowerplant_13_base5",
  "refpalette": "deceasedcraft:multi_nuclearpowerplant_13/multi_nuclearpowerplant_13_base5_palette",
  "xsize": 16,
  "zsize": 16,
  "slices": [
    [
      "aaaaaab         ",
      "aaaaaaabb       ",
      "aaaaaaaaab      ",
      "aaaaaaaaaabb    ",
      "aaaaaaaaaaaab   ",
      "aaaaaaaaaaaaabb ",
      "aaaaaaaaaaaaaaab",
      "aaaaaaaaaaaaaaab",
      "aaaaaaaaaaaaaaab",
      "aaaaaaaaaaaaaaab",
      "aaaaaaaaaaaaabbb",
      "aaaaaaaaaaaaaaac",
      "aaaaaaaaaaaaaaac",
      "aaaaaaaaaaaaaaac",
      "aaaaaaaaaaaaaaac",
      "vvvvvvvvvvvvvvvv"
    ],
    [
      "aaaaaab         ",
      "aaaaaaabb       ",
      "aaaaaaaaab      ",
      "aaaaaaaaaabb    ",
      "aaaaaaaaaaaab   ",
      "aaaaaaaaaaaaabb ",
      "aaaaaaaaaaaaaaab",
      "aaaaaaaaaaaaaaab",
      "aaaaaaaaaaaaaaab",
      "aaaaaaaaaaaaaaab",
      "aaaaaaaaaaaaabbb",
      "aaaaaaaaaaaaaaac",
      "aaaaaaaaaaaaaaac",
      "aaaaaaaaaaaaaaac",
      "aaaaaaaaaaaaaaac",
      "vvvvvvvvvvvvvvvv"
    ],
    [
      "aaaaaab         ",
      "aaaaaaabb       ",
      "aaaaaaaaab      ",
      "aaaaaaaaaabb    ",
      "aaaaaaaaaaaab   ",
      "aaaaaaaaaaaaabb ",
      "aaaaaaaaaaaaaaab",
      "aaaaaaaaaaaaaaab",
      "aaaaaaaaaaaaaaab",
      "aaaaaaaaaaaaaaab",
      "aaaaaaaaaaaaabbb",
      "aaaaaaaaaaaaaaac",
      "aaaaaaaaaaaaaaac",
      "aaaaaaaaaaaaaaac",
      "aaaaaaaaaaaaaaac",
      "vvvvvvvvvvvvvvvv"
    ],
    [
      "aaaaaab         ",
      "aaaaaaabb       ",
      "aaaaaaaaab      ",
      "aaaaaaaaaabb    ",
      "aaaaaaaaaaaab   ",
      "aaaaaaaaaaaaabb ",
      "aaaaaaaaaaaaaaab",
      "aaaaaaaaaaaaaaab",
      "aaaaaaaaaaaaaaab",
      "aaaaaaaaaaaaaaab",
      "aaaaaaaaaaaaabbb",
      "aaaaaaaaaaaaaaac",
      "aaaaaaaaaaaaaaac",
      "aaaaaaaaaaaaaaac",
      "aaaaaaaaaaaaaaac",
      "vvvvvvvvvvvvvvvv"
    ],
    [
      "aaaaaab         ",
      "aaaaaaabb       ",
      "aaaaaaaaab      ",
      "aaaaaaaaaabb    ",
      "aaaaaaaaaaaab   ",
      "aaaaaaaaaaaaabb ",
      "aaaaaaaaaaaaaaab",
      "aaaaaaaaaaaaaaab",
      "aaaaaaaaaaaaaaab",
      "aaaaaaaaaaaaaaab",
      "aaaaaaaaaaaaabbb",
      "aaaaaaaaaaaaaaac",
      "aaaaaaaaaaaaaaac",
      "aaaaaaaaaaaaaaac",
      "aaaaaaaaaaaaaaac",
      "vvvvvvvvvvvvvvvv"
    ],
    [
      "aaaaaab         ",
      "aaaaaaabb       ",
      "aaaaaaaaab      ",
      "aaaaaaaaaabb    ",
      "aaaaaaaaaaaab   ",
      "aaaaaaaaaaaaabb ",
      "aaaaaaaaaaaaaaab",
      "aaaaaaaaaaaaaaab",
      "aaaaaaaaaaaaaaab",
      "aaaaaaaaaaaaaaab",
      "aaaaaaaaaaaaabbb",
      "aaaaaaaaaaaaaaac",
      "aaaaaaaaaaaaaaac",
      "aaaaaaaaaaaaaaac",
      "aaaaaaaaaaaaaaac",
      "vvvvvvvvvvvvvvvv"
    ]
  ]
}