{
  "name": "multi_nuclearpowerplant_13_base3",
  "refpalette": "deceasedcraft:multi_nuclearpowerplant_13/multi_nuclearpowerplant_13_base3_palette",
  "xsize": 16,
  "zsize": 16,
  "slices": [
    [
      "      abbbbbbbb ",
      "       aabbbbbbb",
      "         abbbbbb",
      "          aabbbb",
      "            abbb",
      "             aab",
      "              aa",
      "cccccccccccccccc",
      "cccccccccccccccc",
      "              aa",
      "            daaa",
      "               e",
      "               e",
      "               e",
      "               e",
      "vvvvvvvvvvvvvvvv"
    ],
    [
      "      f      gh ",
      "       ff      g",
      "         fi     ",
      "          ff    ",
      "            f   ",
      "             ff ",
      "              ff",
      "jjjjjjjjjjjjjj k",
      "llllllllllllll m",
      "              ff",
      "            nfff",
      "               e",
      "               e",
      "               e",
      "               e",
      "vvvvvvvvvvvvvvvv"
    ],
    [
      "      f         ",
      "       ff       ",
      "         f      ",
      "          ff    ",
      "            f   ",
      "             ff ",
      "              ff",
      "               o",
      "               p",
      "              ff",
      "             fff",
      "               e",
      "               e",
      "               e",
      "               e",
      "vvvvvvvvvvvvvvvv"
    ],
    [
      "      f         ",
      "       ff       ",
      "         f      ",
      "          ff    ",
      "            f   ",
      "             ff ",
      "              ff",
      "               f",
      "               f",
      "              ff",
      "             fff",
      "               e",
      "               e",
      "               e",
      "               e",
      "vvvvvvvvvvvvvvvv"
    ],
    [
      "      f         ",
      "       ff       ",
      "         f      ",
      "          ff    ",
      "            f   ",
      "             ff ",
      "              ff",
      "              fq",
      "              fq",
      "              ff",
      "             fff",
      "               e",
      "               e",
      "               e",
      "               e",
      "vvvvvvvvvvvvvvvv"
    ],
    [
      "      f         ",
      "       ff       ",
      "         f      ",
      "          ff    ",
      "            f   ",
      "             ff ",
      "              ff",
      "              fq",
      "              fq",
      "              ff",
      "             fff",
      "               e",
      "               e",
      "               e",
      "               e",
      "vvvvvvvvvvvvvvvv"
    ]
  ]
}