{
  "name": "multi_thering_8_floor3",
  "refpalette": "deceasedcraft:multi_thering_8/multi_thering_8_floor3_palette",
  "xsize": 16,
  "zsize": 16,
  "slices": [
    [
      "abbbbbbbbbbbbbbb",
      "bcccccccb  b   b",
      "bcccccccb  b   b",
      "bcccddccb  b   b",
      "bcccddccb ebffgb",
      "bcccddccbhibfffb",
      "bbbbbbbcbiiffffb",
      "bccccbfffbbbfffb",
      "bcccccfjfffffffb",
      "bccccbfffffffffb",
      "bccdddbcbbbbbbbb",
      "bccdddbccdddcccb",
      "bccccbcccdddcccb",
      "bccccbcccccccccb",
      "bccccbcccccccccb",
      "bbbbbbbbbbbbbbba"
    ],
    [
      "akkkkkkkkkkkkkkb",
      "kl      b  b   k",
      "k   mno b  b   k",
      "k   pqr b eb   k",
      "k st uw b xbyybk",
      "kABt CD b  bEFIk",
      "kbbbbbbJb K    k",
      "koLMNb   bbb   k",
      "k    O        Pk",
      "k  mnb        Pk",
      "k t QRbSbbbbbbbk",
      "k  T qb UV WXYZk",
      "k  00br 1 23X4 k",
      "k  56bw  0 0   k",
      "kl  7bD       lk",
      "bkkkkkkkkkkkkkka"
    ],
    [
      "akkkkkkkkkkkkkkb",
      "k8      b  b   k",
      "k   9#o b$eb   k",
      "k   % ^ b xb   k",
      "k  t& ^ b  b  bk",
      "k* t(   b  b)+ k",
      "kbbbbbb-b [    k",
      "ko!] b   bbb   k",
      "k    {         k",
      "k  9}b         k",
      "k t|  b;bbbbbbbk",
      "k  :' b < | X >k",
      "k  00b  ,&. X  k",
      "k    b   0 0   k",
      "k?  >b        /k",
      "bkkkkkkkkkkkkkka"
    ],
    [
      "akkkkkkkkkkkkkkb",
      "k       beeb   k",
      "k   `\u0370o bixb   k",
      "k  t  \u0371 b\u0372 b   k",
      "k  t  \u0373 b  b\u0374\u0374bk",
      "k  t\u0375 \u0376 b  b\u0377\u0377 k",
      "kbbbbbbib \u037a\u037b   k",
      "ko\u037c\u037d\u037eb   bbb   k",
      "k    i    \u037f    k",
      "k  `\u0370b         k",
      "k t\u0384  bibbbbbbbk",
      "k t   b \u0385 \u0384 X  k",
      "k  00b\u0386 \u0387   X  k",
      "k    b\u0388  000   k",
      "k    b\u0389        k",
      "bkkkkkkkkkkkkkka"
    ],
    [
      "akkkkkkkkkkkkkkb",
      "k       b  b   k",
      "k   \u038a\u038a  b  b   k",
      "k  \u038c\u038e\u038e\u038f bh b   k",
      "k  \u038c\u038e\u038e\u038f b\u0372 bbbbk",
      "k  \u038c\u038e\u038e\u038f b  b   k",
      "kbbbbbbbb  b   k",
      "k   ]b   bbb   k",
      "k    b         k",
      "k  \u038a\u038ab         k",
      "k \u038c\u038e\u038e\u038ebbbbbbbbbk",
      "k \u038c\u038e\u038e\u038eb \u038c\u038e\u038e\u038e\u038f  k",
      "k  \u0390\u0390b  \u038c\u038e\u038e\u038e\u038f  k",
      "k    b^  \u0390\u0390\u0390   k",
      "k    b\u0391        k",
      "bkkkkkkkkkkkkkka"
    ],
    [
      "akkkkkkkkkkkkkkb",
      "k\u0392\u0392\u0392\u0392\u0392\u0392\u0392b  b   k",
      "k\u0392\u038e\u038e\u038e\u038e\u038e\u038eb  b   k",
      "k\u0392\u038e\u038e  \u038e\u038eb  b   k",
      "k\u0392\u038e\u038e  \u038e\u038ebh bbbbk",
      "k\u0392\u038e\u038e\u0393\u0393\u038e\u038eb\u0372$b\u0394\u0394\u0394k",
      "kbbbbbbbb  b\u0394\u0394\u0394k",
      "k\u0392\u038e\u038e\u038eb\u0394\u0394\u0394bbb\u0394\u0394\u0394k",
      "k\u0392\u038e\u038e\u038eb\u0394\u0395\u0394\u0394\u0394\u0394\u0394\u0394\u0394k",
      "k\u0392\u038e\u038e\u038eb\u0394\u0394\u0394\u0394\u0394\u0394\u0394\u0394\u0394k",
      "k\u0392\u038e  \u0393bbbbbbbbbk",
      "k\u0392\u038e  \u0393b\u038e\u038e\u0393\u0393 \u038e\u038e\u0392k",
      "k\u0392\u038e\u038e\u038eb\u038e\u038e\u038e   \u038e\u038e\u0392k",
      "k\u0392\u038e\u038e\u038eb\u038e\u038e\u038e\u038e\u038e\u038e\u038e\u038e\u0392k",
      "k\u0392\u0392\u0392\u0392b\u0392\u0392\u0392\u0392\u0392\u0392\u0392\u0392\u0392k",
      "bkkkkkkkkkkkkkka"
    ]
  ]
}