{
  "name": "multi_thering_8_floor4",
  "refpalette": "deceasedcraft:multi_thering_8/multi_thering_8_floor4_palette",
  "xsize": 16,
  "zsize": 16,
  "slices": [
    [
      "abbbbbbbbbbbbbbb",
      "bcccccccb  b   b",
      "bcccccccb  b   b",
      "bcccddccb  b   b",
      "bcccddccb ebffgb",
      "bcccddccbhibfffb",
      "bbbbbbbcbiiffffb",
      "bccccbfffbbbfffb",
      "bcccccfjfffffffb",
      "bccccbfffffffffb",
      "bccdddbcbbbbbbbb",
      "bccdddbccdddcccb",
      "bccccbcccdddcccb",
      "bccccbcccccccccb",
      "bccccbcccccccccb",
      "bbbbbbbbbbbbbbba"
    ],
    [
      "akkkkkkkkkkkkkkb",
      "kl      b  b   k",
      "k   mno b  b   k",
      "k   pqr b eb   k",
      "k st uw b xbyybk",
      "kABt CD b  bEFIk",
      "kbbbbbbJb K    k",
      "koLMNb   bbb   k",
      "k    O        Pk",
      "k  mnb        Pk",
      "k t QRbSbbbbbbbk",
      "k  T qb UVWXYZ0k",
      "k  11br 2 34Y5 k",
      "k  67bw  1 1   k",
      "kl  8bD       lk",
      "bkkkkkkkkkkkkkka"
    ],
    [
      "akkkkkkkkkkkkkkb",
      "k9      b  b   k",
      "k   #$o b%eb   k",
      "k   ^ & b xb   k",
      "k  t* ( b  b  bk",
      "k) t+   b  b-[ k",
      "kbbbbbb]b {    k",
      "ko}| b   bbb   k",
      "k    ;         k",
      "k  # b         k",
      "k t:  b'bbbbbbbk",
      "k  <> b | : Y ,k",
      "k  11b( .*? Y  k",
      "k    b(  1 1   k",
      "k/  ,b        `k",
      "bkkkkkkkkkkkkkka"
    ],
    [
      "akkkkkkkkkkkkkkb",
      "k       beeb   k",
      "k   \u0370\u0371o bixb   k",
      "k  t  \u0372 b\u0373 b   k",
      "k  t  \u0374 b  b\u0375\u0375bk",
      "k  t\u0376 \u0377 b  b\u037a\u037a k",
      "kbbbbbbib \u037b\u037c   k",
      "ko\u037d\u037e\u037fb   bbb   k",
      "k    i    \u0384    k",
      "k  \u0370\u0371b         k",
      "k t\u0385  bibbbbbbbk",
      "k t   b \u0386 \u0385 Y  k",
      "k  11b\u0387 \u0388   Y  k",
      "k    b\u0389  111   k",
      "k    b\u038a        k",
      "bkkkkkkkkkkkkkka"
    ],
    [
      "akkkkkkkkkkkkkkb",
      "k       b  b   k",
      "k   \u038c\u038c  b  b   k",
      "k  \u038e!\u038f\u0390 bh b   k",
      "k  \u038e\u038f\u038f\u0390 b\u0373 bbbbk",
      "k  \u038e\u038f\u038f\u0390 b  b   k",
      "kbbbbbbbb  b   k",
      "k  \u0391\u0391b   bbb   k",
      "k    b         k",
      "k  \u038c\u038cb         k",
      "k \u038e\u038f\u038f\u038fbbbbbbbbbk",
      "k \u038e\u038f\u038f\u038fb \u038e\u038f\u038f\u038f\u0390  k",
      "k  \u0392\u0392b  \u038e\u038f\u038f\u038f\u0390  k",
      "k    b!  \u0392\u0392\u0392   k",
      "k    b         k",
      "bkkkkkkkkkkkkkka"
    ],
    [
      "akkkkkkkkkkkkkkb",
      "k\u0393\u0393\u0393\u0393\u0393\u0393\u0393b  b   k",
      "k\u0393\u038f\u038f\u038f\u038f\u038f\u038fb  b   k",
      "k\u0393\u038f\u038f  \u038f\u038fb  b   k",
      "k\u0393\u038f\u038f  \u038f\u038fbh bbbbk",
      "k\u0393\u038f\u038f\u0394\u0394\u038f\u038fb\u0373 b\u0395\u0395\u0395k",
      "kbbbbbbbb  b\u0395\u0395\u0395k",
      "k\u0393\u038f\u038f\u038fb\u0395\u0395\u0395bbb\u0395\u0395\u0395k",
      "k\u0393\u038f\u038f\u038fb\u0395\u0396\u0395\u0395\u0395\u0395\u0395\u0395\u0395k",
      "k\u0393\u038f\u038f\u038fb\u0395\u0395\u0395\u0395\u0395\u0395\u0395\u0395\u0395k",
      "k\u0393\u038f  \u0394bbbbbbbbbk",
      "k\u0393\u038f  \u0394b\u038f\u038f\u0394\u0394 \u038f\u038f\u0393k",
      "k\u0393\u038f\u038f\u038fb\u038f\u038f\u038f   \u038f\u038f\u0393k",
      "k\u0393\u038f\u038f\u038fb\u038f\u038f\u038f\u038f\u038f\u038f\u038f\u038f\u0393k",
      "k\u0393\u0393\u0393\u0393b\u0393\u0393\u0393\u0393\u0393\u0393\u0393\u0393\u0393k",
      "bkkkkkkkkkkkkkka"
    ]
  ]
}