{
  "name": "multi_thering_8_floor1",
  "refpalette": "deceasedcraft:multi_thering_8/multi_thering_8_floor1_palette",
  "xsize": 16,
  "zsize": 16,
  "slices": [
    [
      "abbbbbbbbbbbbbbc",
      "b       c  c   b",
      "b       c  c   b",
      "b       c  c   b",
      "b       c dccccb",
      "b       cefc   b",
      "b       cffc   b",
      "b      ggccc   b",
      "b      h       b",
      "b              b",
      "b              b",
      "b              b",
      "b              b",
      "b              b",
      "b              b",
      "cbbbbbbbbbbbbbba"
    ],
    [
      "abbbbbbbbbbbbbbc",
      "b       c  c   b",
      "b       c  c   b",
      "b       c dc   b",
      "b       c iccccb",
      "b       c  c   b",
      "b       c  c   b",
      "b      ggccc   b",
      "b      gh      b",
      "b              b",
      "b              b",
      "b              b",
      "b              b",
      "b              b",
      "b              b",
      "cbbbbbbbbbbbbbba"
    ],
    [
      "abbbbbbbbbbbbbbc",
      "b       c  c   b",
      "b       cjdc   b",
      "b       c ic   b",
      "b       c  ccccb",
      "b       c  c   b",
      "b       c  c   b",
      "b      ggccc   b",
      "b      gg      b",
      "b              b",
      "b              b",
      "b              b",
      "b              b",
      "b              b",
      "b              b",
      "cbbbbbbbbbbbbbba"
    ],
    [
      "abbbbbbbbbbbbbbc",
      "b       cddc   b",
      "b       cfic   b",
      "b       ck c   b",
      "b       c  ccccb",
      "b       c  c   b",
      "b       c  c   b",
      "b      llccc   b",
      "b      ll      b",
      "b              b",
      "b              b",
      "b              b",
      "b              b",
      "b              b",
      "b              b",
      "cbbbbbbbbbbbbbba"
    ],
    [
      "abbbbbbbbbbbbbbc",
      "b       c  c   b",
      "b       c  c   b",
      "b       ce c   b",
      "b     mmck ccccb",
      "b    mnnc  c   b",
      "b   mnnoc  c   b",
      "b   mnoppccc   b",
      "b   mnopponm   b",
      "b   mnnoonnm   b",
      "b    mnnnnm    b",
      "b     mmmm     b",
      "b              b",
      "b              b",
      "b              b",
      "cbbbbbbbbbbbbbba"
    ],
    [
      "abbbbbbbbbbbbbbc",
      "bqqqqqqqc  c   b",
      "bqrrrrrrc  c   b",
      "bqrrrrrrc  c   b",
      "bqrrrrrrce ccccb",
      "bqrrrrrrckjcrrqb",
      "bqrrrrrrc  crrqb",
      "bqrrrrrrrcccrrqb",
      "bqrrrrrrrrrrrrqb",
      "bqrrrrrrrrrrrrqb",
      "bqrrrrrrrrrrrrqb",
      "bqrrrrrrrrrrrrqb",
      "bqrrrrrrrrrrrrqb",
      "bqrrrrrrrrrrrrqb",
      "bqqqqqqqqqqqqqqb",
      "cbbbbbbbbbbbbbba"
    ]
  ]
}