{
  "name": "multi_thering_8_floor6",
  "refpalette": "deceasedcraft:multi_thering_8/multi_thering_8_floor6_palette",
  "xsize": 16,
  "zsize": 16,
  "slices": [
    [
      "abbbbbbbbbbbbbbb",
      "bcccccccb  bdefb",
      "bcggggggb  heifb",
      "bcggggggb  b   b",
      "bcggggggb  bbbbb",
      "bcggggggb  bjjcb",
      "bcggggggb  bjjcb",
      "bccccccccbbbjjcb",
      "bcggggggcgggggcb",
      "bcggggggcgggggcb",
      "bcggggggcgggggcb",
      "bcggggggcgggggcb",
      "bcggggggcgggggcb",
      "bcggggggcgggggcb",
      "bccccccccccccccb",
      "bbbbbbbbbbbbbbba"
    ],
    [
      "akkkkkkkkkkkkkkk",
      "klllllllllllmmmk",
      "klllllllllllnnnk",
      "kllllllllllllllk",
      "kllllllllllllllk",
      "kllllllllllljjlk",
      "kllllllllllljjlk",
      "kllllllllllljjlk",
      "kllllllllllllllk",
      "kllllllllllllllk",
      "kllllllllllllllk",
      "kllllllllllllllk",
      "kllllllllllllllk",
      "kllllllllllllllk",
      "kllllllllllllllk",
      "kkkkkkkkkkkkkkka"
    ],
    [
      "a               ",
      "                ",
      "                ",
      "                ",
      "                ",
      "            oo  ",
      "            oo  ",
      "            oo  ",
      "                ",
      "                ",
      "                ",
      "                ",
      "                ",
      "                ",
      "                ",
      "               a"
    ],
    [
      "a               ",
      "                ",
      "                ",
      "                ",
      "                ",
      "                ",
      "                ",
      "                ",
      "                ",
      "                ",
      "                ",
      "                ",
      "                ",
      "                ",
      "                ",
      "               a"
    ],
    [
      "ppq             ",
      "ppq             ",
      "pppq            ",
      "ppppq           ",
      "ppppq           ",
      "pppppq          ",
      "ppppppq         ",
      "pppppppq        ",
      "ppppppppq       ",
      "pppppppppq      ",
      "ppppppppppq     ",
      "pppppppppppqq   ",
      "pppppppppppppq  ",
      "ppppppppppppppqq",
      "qppppppppppppppp",
      " qpppppppppppppp"
    ],
    [
      "rst             ",
      "rst             ",
      "rsu             ",
      "rrsu            ",
      "rrswt           ",
      "rrsxu           ",
      "yrrswu          ",
      "yrrsAwu         ",
      "yyrrsxwu        ",
      "ryyrswwxu       ",
      "ryyyrswAwu      ",
      "ryyryrsswwuB    ",
      "prryyrrrssAwu   ",
      "pprryyyryrsssuBB",
      "ppprryyyyrrrrsss",
      "pppprrryyyryrrrr"
    ]
  ]
}