{
  "name": "multi_thering_8_floor2",
  "refpalette": "deceasedcraft:multi_thering_8/multi_thering_8_floor2_palette",
  "xsize": 16,
  "zsize": 16,
  "slices": [
    [
      "abbbbbbbbbbbbbbb",
      "bcccccccb  b   b",
      "bcccccccb  b   b",
      "bcccddccb  b   b",
      "bcccddccb ebffgb",
      "bcccddccbhibfffb",
      "bbbbbbbcbiiffffb",
      "bccccbfffbbbfffb",
      "bcccccfjfffffffb",
      "bccccbfffffffffb",
      "bccdddbcbbbbbbbb",
      "bccdddbccdddcccb",
      "bccccbcccdddcccb",
      "bccccbcccccccccb",
      "bccccbcccccccccb",
      "bbbbbbbbbbbbbbba"
    ],
    [
      "akkkkkkkkkkkkkkb",
      "kl      b  b   k",
      "k   mno b  b   k",
      "k   pqr b eb   k",
      "k st uw b xbyybk",
      "kABt CD b  bEFIk",
      "kbbbbbbJb K    k",
      "koLMNb   bbb   k",
      "k    O        Pk",
      "k  mnb        Pk",
      "k t QRbSbbbbbbbk",
      "k  T qb UV WXYZk",
      "k  00br 1 23X4 k",
      "k  56bw  0 0   k",
      "kl  7bD       lk",
      "bkkkkkkkkkkkkkka"
    ],
    [
      "akkkkkkkkkkkkkkb",
      "k!      b  b   k",
      "k   8 o b9eb   k",
      "k   # $ b xb   k",
      "k  t%   b  b  bk",
      "k^ t&   b  b*( k",
      "kbbbbbb)b +    k",
      "ko   b   bbb   k",
      "k    -         k",
      "k  8[b         k",
      "k t]  b{bbbbbbbk",
      "k  }| b ; ] X :k",
      "k  00b  '%< X  k",
      "k    b   0 0   k",
      "k>  :b        ,k",
      "bkkkkkkkkkkkkkka"
    ],
    [
      "akkkkkkkkkkkkkkb",
      "k       beeb   k",
      "k   .?o bixb   k",
      "k  t  / b` b   k",
      "k  t  \u0370 b  b\u0371\u0371bk",
      "k  t\u0372 \u0373 b  b\u0374\u0375 k",
      "kbbbbbbib \u0376\u0377   k",
      "ko\u037a\u037b\u037cb   bbb   k",
      "k    i    \u037d    k",
      "k  .?b         k",
      "k t\u037e  bibbbbbbbk",
      "k t   b \u037f \u037e X  k",
      "k  00b\u0384 \u0385   X  k",
      "k    b\u0386  000   k",
      "k    b\u0387        k",
      "bkkkkkkkkkkkkkka"
    ],
    [
      "akkkkkkkkkkkkkkb",
      "k       b  b   k",
      "k   \u0388\u0388  b  b   k",
      "k  \u0389\u038a\u038a\u038c bh b   k",
      "k  \u0389\u038a\u038a\u038c b` bbbbk",
      "k  \u0389\u038a\u038a\u038c b  b   k",
      "kbbbbbbbb  b   k",
      "k \u038e \u038eb   bbb   k",
      "k    b         k",
      "k  \u0388\u0388b         k",
      "k \u0389\u038a\u038a\u038abbbbbbbbbk",
      "k \u0389\u038a\u038a\u038ab \u0389\u038a\u038a\u038a\u038c  k",
      "k  \u038f\u038fb  \u0389\u038a\u038a\u038a\u038c  k",
      "k    b$  \u038f\u038f\u038f   k",
      "k    b\u0390        k",
      "bkkkkkkkkkkkkkka"
    ],
    [
      "akkkkkkkkkkkkkkb",
      "k\u0391\u0391\u0391\u0391\u0391\u0391\u0391b  b   k",
      "k\u0391\u038a\u038a\u038a\u038a\u038a\u038ab  b   k",
      "k\u0391\u038a\u038a  \u038a\u038ab  b   k",
      "k\u0391\u038a\u038a  \u038a\u038abh bbbbk",
      "k\u0391\u038a\u038a\u0392\u0392\u038a\u038ab`9b\u0393\u0393\u0393k",
      "kbbbbbbbb  b\u0393\u0393\u0393k",
      "k\u0391\u038a\u038a\u038ab\u0393\u0393\u0393bbb\u0393\u0393\u0393k",
      "k\u0391\u038a\u038a\u038ab\u0393\u0394\u0393\u0393\u0393\u0393\u0393\u0393\u0393k",
      "k\u0391\u038a\u038a\u038ab\u0393\u0393\u0393\u0393\u0393\u0393\u0393\u0393\u0393k",
      "k\u0391\u038a  \u0392bbbbbbbbbk",
      "k\u0391\u038a  \u0392b\u038a\u038a\u0392\u0392 \u038a\u038a\u0391k",
      "k\u0391\u038a\u038a\u038ab\u038a\u038a\u038a   \u038a\u038a\u0391k",
      "k\u0391\u038a\u038a\u038ab\u038a\u038a\u038a\u038a\u038a\u038a\u038a\u038a\u0391k",
      "k\u0391\u0391\u0391\u0391b\u0391\u0391\u0391\u0391\u0391\u0391\u0391\u0391\u0391k",
      "bkkkkkkkkkkkkkka"
    ]
  ]
}