{
  "name": "multi_thering_8_ground",
  "refpalette": "deceasedcraft:multi_thering_8/multi_thering_8_ground_palette",
  "xsize": 16,
  "zsize": 16,
  "slices": [
    [
      "aaaaabbbaaaaaaaa",
      "accccccca  a   a",
      "accccccca  a   a",
      "accccccca  a   a",
      "accccccca daccea",
      "accccccca faccca",
      "bcccccccagfcccca",
      "bccccccccaaaccca",
      "bcccccccccccccca",
      "bcccccccccccccca",
      "acccccccccccccca",
      "acccccccccccccca",
      "acccccccccccccca",
      "acccccccccccccca",
      "acccccccccccccca",
      "aaaaaaaaaaaaaaah"
    ],
    [
      "ijjjjk ljjjjjjja",
      "jmn     a  a   j",
      "jo      a  a   j",
      "jo      a da   j",
      "jp      a qarraj",
      "j       a  astuj",
      "w       a x    j",
      "        yaaa   j",
      "       Ay      j",
      "B       yC     j",
      "j      Ay      j",
      "jD      aaaa   j",
      "jo             j",
      "jo             j",
      "jEF            j",
      "ajjjjjjjjjjjjjji"
    ],
    [
      "ijjjjk ljjjjjjja",
      "j       a  a   j",
      "j       aIda   j",
      "j       a qa   j",
      "j       a  a  aj",
      "j       a  aJK j",
      "w       a L    j",
      "         aaa   j",
      "        M      j",
      "B       N      j",
      "j              j",
      "j       O      j",
      "j              j",
      "j              j",
      "j              j",
      "ajjjjjjjjjjjjjji"
    ],
    [
      "ijjjjPQRjjjjjjja",
      "j       adda   j",
      "j       afqa   j",
      "j      SaT a   j",
      "j      Ua  aVVaj",
      "j       a  aWW j",
      "X       a YZ   j",
      "Q        aaa   j",
      "Q              j",
      "0              j",
      "j              j",
      "j              j",
      "j              j",
      "j              j",
      "j              j",
      "ajjjjjjjjjjjjjji"
    ],
    [
      "ijjjjjjjjjjjjjja",
      "j       a  a   j",
      "j       a  a   j",
      "j      1ag a   j",
      "j      2aT aaaaj",
      "j       a  a   j",
      "j       a  a   j",
      "j       3aaa   j",
      "j              j",
      "j              j",
      "j              j",
      "j              j",
      "j              j",
      "j              j",
      "j              j",
      "ajjjjjjjjjjjjjji"
    ],
    [
      "ijjjjjjjjjjjjjja",
      "j       a  a   j",
      "j       a  a   j",
      "j       a  a   j",
      "j       ag aaaaj",
      "j       aTIa   j",
      "j       a  a   j",
      "j      34aaa   j",
      "j              j",
      "j              j",
      "j              j",
      "j              j",
      "j              j",
      "j              j",
      "j              j",
      "ajjjjjjjjjjjjjji"
    ]
  ]
}