{
  "name": "multi_thering_8_base2",
  "refpalette": "deceasedcraft:multi_thering_8/multi_thering_8_base2_palette",
  "xsize": 16,
  "zsize": 16,
  "slices": [
    [
      "abbbbbbbbbbbbbbb",
      "bbbbbbbbbbbbbbbb",
      "bbbbbbbbbbbbbbbb",
      "bbbbbbbbbbbbbbbb",
      "bbbbbbbbbbbbbbbb",
      "bbbbbbbbbbbbbbbb",
      "bbbbbbbbbbbbbbbb",
      "bbbbbbbbbbbbbbbb",
      "bbbbbbbbbbbbbbbb",
      "bbbbbbbbbbbbbbbb",
      "bbbbbbbbbbbbbbbb",
      "bbbbbbbbbbbbbbbb",
      "bbbbbbbbbbbbbbbb",
      "bbbbbbbbbbbbbbbb",
      "bbbbbbbbbbbbbbbb",
      "bbbbbbbbbbbbbbba"
    ],
    [
      "abbbbbbbbbbbbbbb",
      "bbbbbbbbbbbbbbbb",
      "bbbbbbbbbbbbbbbb",
      "bbbbbbbbbbbbbbbb",
      "bbbbbbbbbbbbbbbb",
      "bbbbbbbbbbbbbbbb",
      "bbbbbbbbbbbbbbbb",
      "bbbbbbbbbbbbbbbb",
      "bbbbbbbbbbbbbbbb",
      "bbbbbbbbbbbbbbbb",
      "bbbbbbbbbbbbbbbb",
      "bbbbbbbbbbbbbbbb",
      "bbbbbbbbbbbbbbbb",
      "bbbbbbbbbbbbbbbb",
      "bbbbbbbbbbbbbbbb",
      "bbbbbbbbbbbbbbba"
    ],
    [
      "accccccccccccccc",
      "cccccccccccccccc",
      "cccccccccccccccc",
      "cccccccccccccccc",
      "cccccccccccccccc",
      "cccccccccccccccc",
      "cccccccccccccccc",
      "cccccccccccccccc",
      "cccccccccccccccc",
      "cccccccccccccccc",
      "cccccccccccccccc",
      "cccccccccccccccc",
      "cccccccccccccccc",
      "cccccccccccccccc",
      "cccccccccccccccc",
      "ccccccccccccccca"
    ],
    [
      "dddddeeedddddddd",
      "dfffffffffgd   d",
      "dfffffffffgd   d",
      "dfffffffffgd   d",
      "dfffffffffgdhhid",
      "dffffffffffffffd",
      "dffffffffffffffd",
      "dffffffffffffffd",
      "dffffffffffffffd",
      "dffffffffffffffd",
      "dffffffffffffffd",
      "dffffffffffffffd",
      "dffffffffffffffd",
      "dffffffffffffffd",
      "dffffffffffffffd",
      "ddddddddddddddda"
    ],
    [
      "jkkkl   lkkkkkkd",
      "dmmmn   o gd   d",
      "d       o gd   d",
      "d       o gd   d",
      "d mm    o pdqqdd",
      "d mm r      stud",
      "d mm           d",
      "d mmw          d",
      "d mm    xyxA   d",
      "d             Bd",
      "d              d",
      "dCCCd   ADxy  Bd",
      "d              d",
      "d              d",
      "dECCEF  IIJJKKKd",
      "ddddddddddddddda"
    ],
    [
      "jkkkl   lkkkkkkd",
      "dLMN    o gd   d",
      "d       o gd   d",
      "d       o pd   d",
      "d OP    o  d  dd",
      "d OQ        RS d",
      "d OT           d",
      "d OQ           d",
      "d OP    DAUx   d",
      "d              d",
      "d              d",
      "dV WX   yAAx   d",
      "d              d",
      "d              d",
      "dY!ZYF       0 d",
      "ddddddddddddddda"
    ]
  ]
}