{
  "name": "multi_thering_8_base1",
  "refpalette": "deceasedcraft:multi_thering_8/multi_thering_8_base1_palette",
  "xsize": 16,
  "zsize": 16,
  "slices": [
    [
      "abbbc   cbbbbbbd",
      "d       efgd   d",
      "d       e hd   d",
      "d       e  d   d",
      "d       e  diidd",
      "d           jk d",
      "d              d",
      "d              d",
      "d              d",
      "d              d",
      "d              d",
      "d              d",
      "d              d",
      "d              d",
      "dlmlmn         d",
      "dddddddddddddddo"
    ],
    [
      "abbbc   cbbbbbbd",
      "d       eghd   d",
      "d       ep d   d",
      "d       e  d   d",
      "d       e  ddddd",
      "d              d",
      "d              d",
      "d              d",
      "d              d",
      "d              d",
      "d              d",
      "d              d",
      "d              d",
      "d              d",
      "dqrst          d",
      "dddddddddddddddo"
    ],
    [
      "abbbc   cbbbbbbd",
      "d       e  d   d",
      "d       eu d   d",
      "d       ep d   d",
      "d       e  ddddd",
      "d              d",
      "d              d",
      "d              d",
      "d              d",
      "d              d",
      "d              d",
      "d              d",
      "d              d",
      "d              d",
      "d              d",
      "dddddddddddddddo"
    ],
    [
      "abbbc   cbbbbbbd",
      "d       e  d   d",
      "d       e  d   d",
      "d       eu d   d",
      "d       ep ddddd",
      "d              d",
      "d              d",
      "d              d",
      "d              d",
      "d              d",
      "d              d",
      "d              d",
      "d              d",
      "d              d",
      "d              d",
      "dddddddddddddddo"
    ],
    [
      "abbbc   cbbbbbbd",
      "d       e  d   d",
      "d       e  d   d",
      "d       e  d   d",
      "d       eu ddddd",
      "d        p     d",
      "d              d",
      "d              d",
      "d              d",
      "d              d",
      "d              d",
      "d              d",
      "d              d",
      "d              d",
      "d              d",
      "dddddddddddddddo"
    ],
    [
      "abbbccwccbbbbbbd",
      "dgggxcwcy  d   d",
      "dgggxcwcy  d   d",
      "dgggxcwcy  d   d",
      "dgggxcwcy  ddddd",
      "dgggxcwcxuAAAAAd",
      "dgggxcwcxggggggd",
      "dgggxcwccxxxxxxd",
      "dgggxccwcccccccd",
      "dggggxccwwwwwwwd",
      "dgggggxccccccccd",
      "dggggggxxxxxxxxd",
      "dggggggggggggggd",
      "dggggggggggggggd",
      "dggggggggggggggd",
      "dddddddddddddddo"
    ]
  ]
}