{
  "name": "multi_thering_8_floor5",
  "refpalette": "deceasedcraft:multi_thering_8/multi_thering_8_floor5_palette",
  "xsize": 16,
  "zsize": 16,
  "slices": [
    [
      "abbbbbbbbbbbbbbb",
      "bcccccccb  bdddb",
      "bcccccccb  bdedb",
      "bcccffccb  bddgb",
      "bcccffccb  bhhib",
      "bcccffccbj bhhhb",
      "bbbbbbbcbkkhhhhb",
      "blcccbhhhbbbhhhb",
      "blcccchmhhhhhhhb",
      "bnoccbhhhhhhhhhb",
      "blcfffbcbbbbbbbb",
      "bpcfffbccfffcccb",
      "bccccbcccfffcccb",
      "bccccbcccccccccb",
      "bccccbcccccccccb",
      "bbbbbbbbbbbbbbba"
    ],
    [
      "aqqqqqqqqqqqqqqb",
      "qr      b  bst!q",
      "q   uwx b  b   q",
      "q   yAB b  btCDq",
      "q EF IJ b  bKKbq",
      "qLMF NO b  bPQRq",
      "qbbbbbbSb T    q",
      "qUVWXb YZbbb   q",
      "qU0123  4rx56 7q",
      "q  89b6 #uw5 $7q",
      "qU %^&b*bbbbbbbq",
      "q  ()Abt+- []W{q",
      "q}6 |bB;! :']1 q",
      "q< $>bJ t| |  ,q",
      "q.?/`bO    \u0370r  q",
      "bqqqqqqqqqqqqqqa"
    ],
    [
      "aqqqqqqqqqqqqqqb",
      "q\u0371      b  b\u0372 tq",
      "q   \u0373\u0374x b  b   q",
      "q   \u0375 \u0376 b  b C\u0377q",
      "q  F\u037a   b  b  bq",
      "q\u037b F\u037c \u037d b  b\u037e\u037f q",
      "qbbbbbb\u0384b \u0385    q",
      "q  \u0386\u0387b Y bbb   q",
      "q   \u0387\u0388  8\u0371x    q",
      "q   \u0389b \u038a\u038a\u0373\u038c    q",
      "q    \u038eb\u038fbbbbbbbq",
      "q     b   \u0390 ] \u037bq",
      "q   |b\u0391 t\u037a\u0392 ]  q",
      "q    bt  | |   q",
      "q $\u0393/b\u0394        q",
      "bqqqqqqqqqqqqqqa"
    ],
    [
      "aqqqqqqqqqqqqqqb",
      "q       b  b\u0372  q",
      "q   \u0395\u0396x b  b   q",
      "q  F  \u0397 b  b C\u0377q",
      "q  F  \u0398 b  b\u0399\u0399bq",
      "q  F\u039a \u039b b  b\u039c\u039c q",
      "qbbbbbbkb \u039d\u039e   q",
      "q \u039f\u03a0\u03a1b   bbb   q",
      "q   \u0387k    x    q",
      "q    b         q",
      "q F  \u03a3bkbbbbbbbq",
      "q     b \u03a4 \u03a5 ]  q",
      "q  ||b\u03a6 \u03a7   ]  q",
      "q    b\u03a8  |||   q",
      "q    b\u03a9        q",
      "bqqqqqqqqqqqqqqa"
    ],
    [
      "aqqqqqqqqqqqqqqb",
      "q       b  b\u03aa  q",
      "q   \u03ab\u03ab! b  b   q",
      "q  \u03ac\u03ad\u03ad\u03ae b  b C\u0377q",
      "q  \u03ac\u03ad\u03ad\u03ae b  bbbbq",
      "q  \u03ac\u03ad\u03ad\u03ae b  b   q",
      "qbbbbbbbb  b   q",
      "q\u0387\u03af\u03b0 b   bbb   q",
      "q \u03b1\u03b1Yb         q",
      "q    b         q",
      "q \u03ac\u03ad\u03ad\u03adbbbbbbbbbq",
      "q  \u03ad\u03ad\u03adb \u03ac\u03ad\u03ad\u03ad\u03ae  q",
      "q  \u03b1\u03b1bt \u03ac\u03ad\u03ad\u03ad\u03ae  q",
      "q    b   \u03b1\u03b1\u03b1   q",
      "q    b         q",
      "bqqqqqqqqqqqqqqa"
    ],
    [
      "aqqqqqqqqqqqqqqb",
      "q\u03b2\u03b2\u03b2\u03b2\u03b2\u03b2\u03b2b  b\u03b3\u03b3\u03b3q",
      "q\u03b2\u03ad\u03ad\u03ad\u03ad\u03ad\u03adb  b\u03b3\u03b3\u03b3q",
      "q\u03b2\u03ad\u03ad  \u03ad\u03adb  b\u03b4\u03b4\u03b3q",
      "q\u03b2\u03ad\u03ad  \u03ad\u03adb  bbbbq",
      "q\u03b2\u03ad\u03ad\u03b5\u03b5\u03ad\u03adb  b\u03b6\u03b6\u03b6q",
      "qbbbbbbbb  b\u03b6\u03b6\u03b6q",
      "q\u03b2\u03ad\u03ad\u03adb\u03b6\u03b6\u03b6bbb\u03b6\u03b6\u03b6q",
      "q\u03b2\u03ad\u03ad\u03adb\u03b6\u03b7\u03b6\u03b6\u03b6\u03b6\u03b6\u03b6\u03b6q",
      "q\u03b2\u03ad\u03ad\u03adb\u03b6\u03b6\u03b6\u03b6\u03b6\u03b6\u03b6\u03b6\u03b6q",
      "q\u03b2\u03ad  \u03b5bbbbbbbbbq",
      "q\u03b2\u03ad  \u03b5b\u03ad\u03ad\u03b5\u03b5 \u03ad\u03ad\u03b2q",
      "q\u03b2\u03ad\u03ad\u03adb\u03ad\u03ad\u03ad   \u03ad\u03ad\u03b2q",
      "q\u03b2\u03ad\u03ad\u03adb\u03ad\u03ad\u03ad\u03ad\u03ad\u03ad\u03ad\u03ad\u03b2q",
      "q\u03b2\u03b2\u03b2\u03b2b\u03b2\u03b2\u03b2\u03b2\u03b2\u03b2\u03b2\u03b2\u03b2q",
      "bqqqqqqqqqqqqqqa"
    ]
  ]
}