{
  "name": "multi_terraceplaza_26_base2",
  "refpalette": "deceasedcraft:multi_terraceplaza_26/multi_terraceplaza_26_base2_palette",
  "xsize": 16,
  "zsize": 16,
  "slices": [
    [
      "aaaaaaaaaaaaaaaa",
      "aaaaaaaaaaaaaaaa",
      "aaaaaaaaaaaaaaaa",
      "aaaaaaaaaaaaaaaa",
      "aaaaaaaaabaaaaaa",
      "aaaaaaaaaaaaaaaa",
      "aaaaaaaaaaaaaaaa",
      "aaaaaaaaaaaaaaaa",
      "aaaaaaaaaaaaaaaa",
      "aaaaaaaaaaaaaaaa",
      "aaaaaaaaaaaaaaaa",
      "aaaaaaaaaaaaaaaa",
      "aaaaaaaaaaaaaaaa",
      "aaaaaaaaaaaaaaaa",
      "aaaaaaaaaaaaaaaa",
      "aaaaaaaaabaaaaaa"
    ],
    [
      "     cccccccc   ",
      "                ",
      "                ",
      "     deeefeeg   ",
      "h    ijjjbjjg   ",
      "k    dllllllg   ",
      "m               ",
      "m               ",
      "m    nnnnnnnn   ",
      "m   opqrqrssqt  ",
      "m   usrpqqpqwx  ",
      "m    cccccccc   ",
      "m               ",
      "y               ",
      "h    illllllA   ",
      "     ijjjbjjA   "
    ],
    [
      "                ",
      "                ",
      "                ",
      "     dBCfBBCA   ",
      "h    ijjjbjjg   ",
      "     iDEFDEDA   ",
      "                ",
      "                ",
      "                ",
      "                ",
      "                ",
      "                ",
      "                ",
      "                ",
      "h    dIIJKIJg   ",
      "     djjjb!jg   "
    ],
    [
      "                ",
      "                ",
      "                ",
      "     iLfLLfLg   ",
      "h    dMMMbMMg   ",
      "     iEDDEDDA   ",
      "                ",
      "                ",
      "                ",
      "                ",
      "                ",
      "                ",
      "                ",
      "                ",
      "h    iJIIJIIg   ",
      "     iMMMbMMA   "
    ],
    [
      "                ",
      "                ",
      "                ",
      "                ",
      "h        b      ",
      "      NNNNNN    ",
      "                ",
      "                ",
      "                ",
      "                ",
      "                ",
      "                ",
      "                ",
      "                ",
      "h     NNNNNN    ",
      "         b      "
    ],
    [
      "h               ",
      "h               ",
      "h               ",
      "h        O      ",
      "h        b      ",
      "h        P      ",
      "h               ",
      "h               ",
      "h               ",
      "h               ",
      "h               ",
      "h               ",
      "h               ",
      "h               ",
      "h        O      ",
      "         b      "
    ]
  ]
}