{
  "name": "multi_terraceplaza_26_ground",
  "refpalette": "deceasedcraft:multi_terraceplaza_26/multi_terraceplaza_26_ground_palette",
  "xsize": 16,
  "zsize": 16,
  "slices": [
    [
      "aaaaaaaaabcccccc",
      "aaaaaaaaabcccccc",
      "daaaaaaaabcccccc",
      "eaaaaaaaabcccccc",
      "eaaaaaaaafcccccc",
      "aaaaaaaaabcccccc",
      "aaaaaaaaabcccccc",
      "aaaaaaaaabcccccc",
      "aaaaaaaaabcccccc",
      "aaaaaaaaabcccccc",
      "aaaaaaaaabcccccc",
      "aaaaaaaaabcccccc",
      "aaaaaaaaabcccccc",
      "aaaaaaaaabcccccc",
      "aaaaaaaaabcccccc",
      "bbbbbbbbbfbbbbbb"
    ],
    [
      "           ghij ",
      "d        k ghij ",
      "lm       n ghij ",
      "o        n gpiq ",
      "o        f  rst ",
      "         n guiw ",
      "         n ghij ",
      "         x gh!j ",
      "         n ghij ",
      "         n gpy A",
      "         n  rsii",
      "         n      ",
      "         x      ",
      "   BB    nCC CCC",
      "   DE    nFFFFFF",
      "IIJKKJIIIfIIIIII"
    ],
    [
      "d           LM  ",
      "lm       k   MN ",
      "o        n  OM  ",
      "         n  PMQ ",
      "         f   MQ ",
      "         n  OMP ",
      "         n   M  ",
      "         x  RMN ",
      "         n  SMN ",
      "         n  TM  ",
      "         n   MUU",
      "         n      ",
      "         x      ",
      "         n      ",
      "   VW    nX  RX ",
      "IIJ  JIIIfIIIIII"
    ],
    [
      "lm              ",
      "o        k      ",
      "         n      ",
      "         n      ",
      "         f      ",
      "         n      ",
      "         n      ",
      "         x      ",
      "         n      ",
      "         n      ",
      "         n      ",
      "         n      ",
      "         x      ",
      "         n      ",
      "   YZ    n      ",
      "IIJ01JIIIfIIIIII"
    ],
    [
      "o               ",
      "         k      ",
      "         n      ",
      "         n      ",
      "         f      ",
      "         n      ",
      "         n      ",
      "         x      ",
      "         n      ",
      "         n      ",
      "         n      ",
      "         n      ",
      "         x      ",
      "         n      ",
      "         n      ",
      "IIJJJJIIIfIIIIII"
    ],
    [
      "        234 5   ",
      "        234     ",
      "         3      ",
      "         3      ",
      "         f      ",
      "         3      ",
      "         3  5   ",
      "         3      ",
      "         3      ",
      "         3      ",
      "         3      ",
      "         3      ",
      "         3  5   ",
      "         3      ",
      "6666666663666666",
      "IIIIIIIIIf777777"
    ]
  ]
}