{
  "name": "multi_terraceplaza_26_floor1",
  "refpalette": "deceasedcraft:multi_terraceplaza_26/multi_terraceplaza_26_floor1_palette",
  "xsize": 16,
  "zsize": 16,
  "slices": [
    [
      "         a  b   ",
      "         a      ",
      "         a      ",
      "         a      ",
      "         c      ",
      "         a      ",
      "         a  b   ",
      "         a      ",
      "         a      ",
      "         a      ",
      "         a      ",
      "ddddddddda      ",
      "eeeeeeeeeaeeeeee",
      "ffffffffffffffff",
      "gggggggggggggggg",
      "gggggggggggggggg"
    ],
    [
      "         hiiiiii",
      "         hiiiiii",
      "         hiiiiii",
      "         hiiiiii",
      "hhhhhhhhhchhhhhh",
      "         h      ",
      "         h  j   ",
      "         h      ",
      "dddddddddh      ",
      "eeeeeeeeeheeeeee",
      "ffffffffffffffff",
      "kkkkkkkkkkllllll",
      "mmmmmmmmmmmmmmmm",
      "                ",
      "nnnnnnnnnnnnnnnn",
      "                "
    ],
    [
      "         opppppp",
      "         opppppp",
      "         opppppp",
      "         opppppp",
      "         c      ",
      "dddddddddhdddddd",
      "eeeeeeeeeheeeeee",
      "ffffffffffffffff",
      "kkkkkkkkkkllllll",
      "mmmmmmmmmmmmmmmm",
      "                ",
      "                ",
      "                ",
      "                ",
      "                ",
      "                "
    ],
    [
      "         q      ",
      "         qrrsrrr",
      "dddddddddq      ",
      "eeeeeeeeeedddddd",
      "hhhhhhhhhctttttt",
      "gggggggggggggggg",
      "mmmmmmmmmmmmmmmm",
      "                ",
      "                ",
      "                ",
      "                ",
      "                ",
      "                ",
      "                ",
      "                ",
      "                "
    ],
    [
      "eeeeeeeeee      ",
      "ffffffffffdddddd",
      "kkkkkkkkkkkkkkkk",
      "gggggggggggggggg",
      "uuuuuuuuuuuuuuuu",
      "nnnnnnnnnnnnnnnn",
      "                ",
      "                ",
      "                ",
      "                ",
      "                ",
      "                ",
      "                ",
      "                ",
      "                ",
      "                "
    ],
    [
      "mmmmmmmmmmwxxxxx",
      "                ",
      "                ",
      "                ",
      "                ",
      "                ",
      "                ",
      "                ",
      "                ",
      "                ",
      "                ",
      "                ",
      "                ",
      "                ",
      "                ",
      "                "
    ]
  ]
}