{
  "name": "multi_terraceplaza_26_base1",
  "refpalette": "deceasedcraft:multi_terraceplaza_26/multi_terraceplaza_26_base1_palette",
  "xsize": 16,
  "zsize": 16,
  "slices": [
    [
      "ab              ",
      "ac              ",
      "ad              ",
      "ac              ",
      "ae       f      ",
      "ac              ",
      "ae              ",
      "ac              ",
      "ag              ",
      "a               ",
      "ae              ",
      "ac              ",
      "ab              ",
      "ac              ",
      "a               ",
      "         f      "
    ],
    [
      "ah              ",
      "ac              ",
      "ad              ",
      "ac              ",
      "ad       f      ",
      "ac              ",
      "ah              ",
      "ac              ",
      "ac              ",
      "ac              ",
      "ah              ",
      "ac              ",
      "ai              ",
      "ac              ",
      "a               ",
      "         f      "
    ],
    [
      "a               ",
      "a               ",
      "a               ",
      "a               ",
      "a        f      ",
      "a               ",
      "a               ",
      "a               ",
      "a               ",
      "a               ",
      "a               ",
      "a               ",
      "a               ",
      "a               ",
      "a               ",
      "         f      "
    ],
    [
      "aj              ",
      "aj              ",
      "aj              ",
      "aj              ",
      "aj       f      ",
      "aj              ",
      "aj              ",
      "aj              ",
      "aj              ",
      "aj              ",
      "aj              ",
      "aj              ",
      "aj              ",
      "aj              ",
      "kkkkkkkkkkkkkkkk",
      "         f      "
    ],
    [
      "lmmmmmmmmmmmmmmm",
      "lmmmmmmmmmmmmmmm",
      "lmmmmmmmmmmmmmmm",
      "lmmmmmmmmmmmmmmm",
      "lmmmmmmmmfmmmmmm",
      "lmmmmmmmmmmmmmmm",
      "lmmmmmmmmmmmmmmm",
      "lmmmmmmmmmmmmmmm",
      "lmmmmmmmmmmmmmmm",
      "lmmmmmmmmmmmmmmm",
      "lmmmmmmmmmmmmmmm",
      "lmmmmmmmmmmmmmmm",
      "lmmmmmmmmmmmmmmm",
      "lmmmmmmmmmmmmmmm",
      "kkkkkkkkkkkkkkkk",
      "nnnnnnnnnfnnnnnn"
    ],
    [
      "oppppppppqpppppp",
      "oppppppppqpppppp",
      "oppppppppqpppppp",
      "oppppppppqpppppp",
      "qqqqqqqqqfqqqqqq",
      "oppppppppqpppppp",
      "oppppppppqpppppp",
      "oppppppppqpppppp",
      "oppppppppqpppppp",
      "oppppppppqpppppp",
      "oppppppppqpppppp",
      "oppppppppqpppppp",
      "oppppppppqpppppp",
      "oppppppppqpppppp",
      "kkkkkkkkkqkkkkkk",
      "qqqqqqqqqfqqqqqq"
    ]
  ]
}