{
  "name": "building_apartmentsmallcbroken_ground_180",
  "refpalette": "deceasedcraft:building_apartmentsmallcbroken/building_apartmentsmallcbroken_ground_palette_180",
  "xsize": 16,
  "zsize": 16,
  "slices": [
    [
      "aabaababcccbaccb",
      "abagggggggggggga",
      "aaaghhhhhhhhhhgb",
      "baaghhhhhhhhhhgb",
      "aaaghhhhhhhhhhgc",
      "aabghhhhhhhhhhgc",
      "aaaghhhhhhhhhhgb",
      "abaghhhhhhhhhhgc",
      "aaaghhhhhihhhhgc",
      "aaaghhhhhihhhhgb",
      "beaghhhhhihhhhgc",
      "aefgiiifiihhhhgb",
      "aefffffffeggggga",
      "befffffffebdadcb",
      "aeeeeeeeeebabdbc",
      "aaaabcbabbababaa"
    ],
    [
      "        E o  mE ",
      "   0ii032222221 ",
      "   w          0m",
      "   NL  XZ V Y w ",
      "   wL  XWKV UTN ",
      "   N   SQRQRQPwO",
      "   NL      M  i ",
      "   wL     K   iJ",
      "   w     i    w ",
      "   w  I  ixF  iE",
      " eDiCBA  ix   im",
      " efiiiiyiix   w ",
      " eu ft   esr ri ",
      " eq p    e    o ",
      " eeeneenenl    m",
      "   l  k    j    "
    ],
    [
      "                ",
      "   0iiN222222 ] ",
      "   2          1 ",
      "   2          N ",
      "   2          2 ",
      "   2   [+++-+)w ",
      "   2          i ",
      "   2          i ",
      "   2     i    N ",
      "   w    (i*   i ",
      " nDi     i^   i ",
      " efiiii&ii^   N ",
      " %$ t    eir #i ",
      " 98 7    n      ",
      " eeeee654n      ",
      "                "
    ],
    [
      "                ",
      "   1iiw22222 2  ",
      "              1 ",
      "   2          w ",
      "   2          2 ",
      "   2   :-++   N ",
      "   2          s ",
      "   2          i ",
      "   2     i    N ",
      "   N     i    i ",
      " eDi   ; iF   i ",
      " efiiii|ii^   w ",
      " eft     ei#rri ",
      " eff}    n      ",
      " {{{eeeeee      ",
      "                "
    ],
    [
      "                ",
      "   iiiiisisi<ss ",
      "   i          i ",
      "   i          i ",
      "   i          s ",
      "   i     3    i ",
      "   i          i ",
      "   i          i ",
      "   i     i    i ",
      "   i     i    s ",
      " eDi     i    i ",
      " efiiiiiii    i ",
      " e       eisiis ",
      " e  '}   e      ",
      " eeeene565      ",
      "                "
    ],
    [
      "                ",
      "   iisiiiisssii ",
      "   iggggggggggs ",
      "   iggggggggggo ",
      "   iggggggggggs ",
      "   iggggggggggs ",
      "   iggggggggggi ",
      "   igggggggggg, ",
      "   igggggiggggs ",
      "   igggggiggggi ",
      " e igggggiggggi ",
      " 9>iiiiiiiggggs ",
      " 9       eiissE ",
      " 9   '}  n      ",
      " eeeeeeeee      ",
      "                "
    ]
  ]
}