{
  "name": "building_apartmentsmallcbroken_top_180",
  "refpalette": "deceasedcraft:building_apartmentsmallcbroken/building_apartmentsmallcbroken_top_palette_180",
  "xsize": 16,
  "zsize": 16,
  "slices": [
    [
      "                ",
      "   ddddedededed ",
      "   dkkgkkggghhe ",
      "   dkkgkkgggghe ",
      "   dgkgkkkgghgd ",
      "   dggggkggggge ",
      "   dggggggggggd ",
      "   dggggggggghd ",
      "   dgggggggghge ",
      "   dggggggggghe ",
      " a iggggggggghd ",
      " ajiiiibigghgge ",
      " a   fbbbaddeed ",
      " a    cbba      ",
      " aaaaaaaaa      ",
      "                "
    ],
    [
      "                ",
      "   iiiiiiqqiq^q ",
      "   i8 i  i%$ #q ",
      "   i59i8 i 7 PJ ",
      "   ii6i5 2  43i ",
      "   iT  i2q 1EVi ",
      "   iZY q i0iqiq ",
      "   iZY i   XWVU ",
      "   iT  qSRQ A q ",
      "   i PONMLDKKKJ ",
      " aIiFEi DC BA q ",
      " abiiiiyixwutsi ",
      " a  fr   aiqqpo ",
      " a       a      ",
      " lnnnmaaal      ",
      "                "
    ],
    [
      "                ",
      "   \u037eii-(\u037d\u037c(\u037d\u037c - ",
      "   ( \u037bi\u037a i\u0375   o ",
      "   `\u0376 i  q      ",
      "   `i\u0377i\u0376 \u0374    ( ",
      "   (\u0375  i\u0374i\u0373 \u0372 q ",
      "   `   i i\u0371iqo\u0370 ",
      "   `   i / ?. < ",
      "   (, >q      ( ",
      "   <  '         ",
      " lIi:;i|      ( ",
      " abiiii}i{]  [- ",
      " + fr   )ai(( q ",
      " n       a      ",
      " aalaa**&a      ",
      "                "
    ],
    [
      "                ",
      "   -ii-(\u037d\u037d(\u037c  \u0390 ",
      "   ( \u038fi\u038e i    \u038c ",
      "   `\u038a i  i      ",
      "   `i\u0388i\u038a \u0389      ",
      "   (   i\u0388i      ",
      "   `   i q\u037dqi\u0387  ",
      "   `   q        ",
      "   (   i      ( ",
      "   <  ` !       ",
      " aIi  i         ",
      " lbiiii\u0386i     - ",
      " abr     ai\u0386\u0386\u0386\u0385 ",
      " abb\u0384    l      ",
      " \u037f\u037f\u037faaaaaa      ",
      "                "
    ],
    [
      "                ",
      "   iiiqiqoq\u0396    ",
      "   i  i  q      ",
      "   i  i  i      ",
      "   iiii  i  \u0394   ",
      "   i   qii      ",
      "   i \u0395 i iqq\u0385   ",
      "   i   i        ",
      "   i  ii\u0393       ",
      "   i  i \u0394\u0393      ",
      " aIi  i\u0393        ",
      " abiiiiii     \u0392 ",
      " a       aiiqoq ",
      " a  c\u0384   \u0391      ",
      " aaaaaa**&      ",
      "                "
    ],
    [
      "                ",
      "   iiqiq\u0370q\u0385     ",
      "   i\u0399\u0399\u0399\u0399\u0399\u0399\u0399\u0398    ",
      "   i\u0399\u0399\u0399\u0399\u0399\u0399\u0399\u0399    ",
      "   i\u0399\u0399\u0399\u0399\u0399\u0399\u0399\u0399\u0399   ",
      "   i\u0399\u0399\u0399\u0399\u0399\u0399\u0399\u0399\u0399\u0398  ",
      "   i\u0399\u0399\u0399\u0399\u0399\u0399iiq   ",
      "   i\u0399\u0399\u0399\u0399\u0399\u0399\u0399\u0399    ",
      "   i\u0399\u0399\u0399\u0399\u0399\u0399\u0399\u0399\u0398   ",
      "   i\u0399\u0399\u0399\u0399\u0399\u039a\u0399     ",
      " a i\u0399\u0399\u0399\u0399\u039c\u039c\u0399\u039b    ",
      " mjiiiiii\u0399\u039a\u0399\u0399\u0398  ",
      " m       aiqiq\u0385 ",
      " m   c\u0384  l      ",
      " aaaalaaa\u0397      ",
      "                "
    ],
    [
      "                ",
      "   ddddee       ",
      "   dkkgkkggh\u03a6\u039f  ",
      "   dkkgkkgggh\u039f  ",
      "   dgkgkkkgh\u03a4\u03a1  ",
      "   dggggkgggh\u039f\u03a3 ",
      "   dgggggghiq\u03a5  ",
      "   dgggggghg\u03a4\u03a3  ",
      "   dggggggggh\u039f  ",
      "   dggggg!\u039chg\u03a1  ",
      " a iggggg\u03a0\u039a\u039bh   ",
      " ajiiiibig\u039ch\u039b\u039f  ",
      " a   fbbbld\u039ed\u039e  ",
      " a    cbba      ",
      " aaaaaaal\u039d      ",
      "                "
    ],
    [
      "                ",
      "   iiiqq\u0385\u0396      ",
      "   i8 i  i%$V\u03af  ",
      "   i5 i8 q 7 \u03ae  ",
      "   ii2i5 6  \u03ad   ",
      "   iT  i2i 1E   ",
      "   iZY i q iq   ",
      "   iZY q #\u0396XW   ",
      "   iT  qV  [    ",
      "   iP VD   [\u03ac   ",
      " aIiFEi  \u03ab\u03a8     ",
      " abiiii\u03aao\u03a9\u03a0\u03a8B   ",
      " a  fr   a\u039c\u039boU  ",
      " a       l      ",
      " an\u03a7nmaal&      ",
      "                "
    ],
    [
      "                ",
      "   \u037eiq-(\u037c       ",
      "   ( \u037bi\u037a i      ",
      "   \u03b6\u0376\u03b5i \u03b5i      ",
      "   `i\u0374i\u0376 \u0377      ",
      "   (,  i\u0374i      ",
      "   `   i J iU   ",
      "   `   q    \u03b4   ",
      "   (\u0375 \u03b3i        ",
      "   <            ",
      " aIi \u03b2i\u0373        ",
      " abiiii\u03b1o\u03a8\u03ab     ",
      " + fr    a\u039a((   ",
      " n       l      ",
      " aaaaa**\u03b0a      ",
      "                "
    ],
    [
      "                ",
      "   \u037eii\u037e \u037d\u037c      ",
      "   ( \u038fi\u038e q      ",
      "   `\u038a i  i      ",
      "   `i\u0388i\u038a \u03b7      ",
      "   (   i\u0388i      ",
      "   `   q i\u037dq    ",
      "   `   i        ",
      "   (   i        ",
      "   <  `         ",
      " aIi  q         ",
      " lbiiii\u0386q       ",
      " abr     ao\u0386\u0386   ",
      " abb\u0384    a      ",
      " \u0391\u037f\u037faaaaal      ",
      "                "
    ],
    [
      "                ",
      "   iiiiiqq\u03b8     ",
      "   i  i  i      ",
      "   i  i  q      ",
      "   iiii  i      ",
      "   i   iqi      ",
      "   i \u0395 i qiq\u0385   ",
      "   i   q        ",
      "   i  iq        ",
      "   i  i \u0394   \u0394   ",
      " aIi  i         ",
      " abiiiiqi       ",
      " a       ao\u039aq\u03b8  ",
      " a  c\u0384   l      ",
      " aaalaa*&       ",
      "                "
    ],
    [
      "                ",
      "   iiiiqiq\u0385     ",
      "   i\u0399\u0399\u0399\u0399\u0399\u0399\u0398     ",
      "   i\u0399\u0399\u0399\u0399\u0399\u0399\u0399     ",
      "   i\u0399\u0399\u0399\u0399\u0399\u0399\u0399\u0399\u0398   ",
      "   i\u0399\u0399\u0399\u0399\u0399\u0399\u0399\u0399    ",
      "   i\u0399\u0399\u0399\u0399\u0399\u0399iiq   ",
      "   i\u0399\u0399\u0399\u0399\u0399\u0399\u0399\u0399    ",
      "   i\u0399\u0399\u0399\u0399\u0399\u0399\u0399\u039b\u0399   ",
      "   i\u0399\u0399\u0399\u0399\u0399\u0399\u0399\u0399\u039a\u0398  ",
      " a i\u0399\u0399\u0399\u0399\u0399\u039a\u0399\u0399\u0398   ",
      " mjiiiiii\u0399\u039a     ",
      " m       aiq\u03b9   ",
      " m   c\u0384  l      ",
      " aaaaaaaaa      ",
      "                "
    ],
    [
      "                ",
      "   ddddd\u039e       ",
      "   dkkgkkhgh\u039f   ",
      "   dkkgkkghg\u03a1   ",
      "   dgkgkkkgg\u03a4\u03a3  ",
      "   dggggkgghg\u039f  ",
      "   dgggggggqq   ",
      "   dgggggggh\u03a1   ",
      "   dggggggh\u03a8\u039f   ",
      "   dgggggggg\u03a8\u039f  ",
      " a iggggghh\u039a\u039b   ",
      " ajiiiibigghh\u039f\u03a3 ",
      " a   fbbble\u039ee   ",
      " a    cbbl      ",
      " aaaaaaala      ",
      "                "
    ],
    [
      "                ",
      "   iiiqiqo      ",
      "   i8 i  i%V\u03bd   ",
      "   i5 i89qA     ",
      "   ii2i5 6  A   ",
      "   iT  i2oV     ",
      "   iZY i q\u03bei\u03b8   ",
      "   iZY i  #XW   ",
      "   iT  iSR \u03bdQ   ",
      "   i PO DD[\u03bc\u03bb   ",
      " aIiFEi\u03bb A V    ",
      " abiiii\u03aaixwu\u03ba   ",
      " a  fr   aiqq\u0385  ",
      " a       a      ",
      " ann\u03a7alaal      ",
      "                "
    ],
    [
      "                ",
      "   -ii\u037e(\u037c\u037c      ",
      "   ( \u037bi\u037a q,     ",
      "   `\u0376\u03b5i  i      ",
      "   `i\u0374i\u0376 \u0377      ",
      "   (\u0375  i\u0374i|     ",
      "   `   i ^\u03c2i\u0385   ",
      "   `   i    .   ",
      "   (, >i \u03c1      ",
      "   <  '         ",
      " aIi\u03c0\u03bfi\u0373        ",
      " abiiii\u03b1i{      ",
      " + fr   )aq((   ",
      " n       a      ",
      " aalaa**\u03b0a      ",
      "                "
    ],
    [
      "                ",
      "   \u0390ii\u037e(\u037c       ",
      "   ( \u038fi\u038e \u0392      ",
      "   `\u038a i  i      ",
      "   \u03b6i\u0388i\u038a \u03b7      ",
      "   (   i\u0388q      ",
      "   `   i \u0389\u037dq    ",
      "   `   i        ",
      "   (   i        ",
      "   <  `         ",
      " aIi  i         ",
      " abiiii\u0386i\u03c3      ",
      " abr     ai\u0386\u0386   ",
      " abb\u0384    l      ",
      " \u037f\u037f\u037fllaala      ",
      "                "
    ],
    [
      "                ",
      "   iiiqiq\u03b9      ",
      "   i  i  i      ",
      "   i  i  q      ",
      "   iiii  i      ",
      "   i   iii      ",
      "   i \u0395 i iiq    ",
      "   i   i        ",
      "   i  ii        ",
      "   i  i \u03c4       ",
      " aIi  i         ",
      " abiiiiiq       ",
      " a       aioq   ",
      " a  c\u0384   a      ",
      " aaalal***      ",
      "                "
    ],
    [
      "                ",
      "   qiiiqoqU     ",
      "   i\u0399\u0399\u0399\u0399\u0399\u0399\u0399\u0399    ",
      "   i\u0399\u0399\u0399\u0399\u0399\u0399\u0399\u0398    ",
      "   i\u0399\u0399\u0399\u0399\u0399\u0399\u0399\u0399    ",
      "   i\u0399\u0399\u0399\u0399\u0399\u0399\u0399\u0399\u0398   ",
      "   i\u0399\u0399\u0399\u0399\u0399qi\u0385    ",
      "   i\u0399\u0399\u0399\u0399\u0399\u0398      ",
      "   i\u0399\u0399\u0399\u0399\u0399\u0399 \u0398    ",
      "   i\u0399\u0399\u0399\u0399\u0399\u0399\u0399\u0399    ",
      " a i\u0399\u0399\u0399\u0399\u0399\u0399\u0399\u0399\u0399   ",
      " mjiiiiii\u0399\u0399\u0399\u0398   ",
      " m       aqq\u03a5   ",
      " m   c\u0384  l      ",
      " lalaaaaa\u0397      ",
      "                "
    ],
    [
      "                ",
      "   ddddee\u039e      ",
      "   dkkgkkgh\u03a1    ",
      "   dkkgkkg\u039a\u03a9    ",
      "   dgkgkkkh\u039b\u039f   ",
      "   dggggkgg\u03a4\u039f   ",
      "   dgggggggq    ",
      "   dgggggghh\u039f   ",
      "   dggggggg\u03c6\u03a1   ",
      "   dggggghg\u03a1    ",
      " a iggggggh\u03a4\u03a3   ",
      " ajiiiibig\u03c5g\u039f   ",
      " a   fbbbl\u039eee   ",
      " l    cbbl      ",
      " aaaalalaa      ",
      "                "
    ],
    [
      "                ",
      "   iiiqioqq\u039e    ",
      "   i8Qi~ i\u03a9V    ",
      "   i5 i\u03d7~o [    ",
      "   ii6i5 \u0385B     ",
      "   i\u03d6 \u03d5o qA\u03d4    ",
      "   i\u03d3 \u03d2q iV\u03b8    ",
      "   i 3\u0375q   \u03d1    ",
      "   i\u03d0\u03d0\u03cfiSR  #   ",
      "   i\u03ce\u03ce\u03cdV  D\u03cc    ",
      " aIi\u03cb\u03cai \u0372D      ",
      " abiiii\u03aao\u039a\u03c9\u03c8    ",
      " a  fr   aqo\u0396   ",
      " a       a      ",
      " annnaaal\u03c7      ",
      "                "
    ],
    [
      "                ",
      "   -ii\u037e(\u037d\u037c(\u037c    ",
      "   ( \u037bi\u037a q      ",
      "   \u03b6\u0376\u03dbi  \u0396      ",
      "   `i\u0377i\u0376        ",
      "   (   q \u03da      ",
      "   `\u03d9  i i      ",
      "   `   i /      ",
      "   (   q        ",
      "   <  \u03ca         ",
      " aIi Pi\u0373        ",
      " abiiii\u03b1q\u039a      ",
      " + fr    ai(    ",
      " n       l      ",
      " aaaal*&\u03d8a      ",
      "                "
    ],
    [
      "                ",
      "   \u037eii-(\u037c\u037d(     ",
      "   ( \u038fi\u038e i      ",
      "   `\u038a i         ",
      "   `i\u0388i\u038a        ",
      "       i\u03dcq      ",
      "   `   q q      ",
      "   `   i        ",
      "   (   i        ",
      "   <  `         ",
      " lIi  i         ",
      " abiiii\u0386i       ",
      " abr     ao\u0386    ",
      " abb\u0384    l      ",
      " &\u037f\u037faalaal      ",
      "                "
    ],
    [
      "                ",
      "   iiiiiiqi\u03b9    ",
      "   i  i  q      ",
      "   i  i  o      ",
      "   iiii  \u03dc      ",
      "   i   iqq      ",
      "   i \u0395 i q\u03b9\u039e    ",
      "   i   q        ",
      "   i  ii        ",
      "   i  i \u03dd       ",
      " aIi  i         ",
      " abiiiiiq       ",
      " a       aq\u03b9    ",
      " a  c\u0384   l      ",
      " aaalaa&**      ",
      "                "
    ],
    [
      "                ",
      "   iiqiiqq\u0370q\u0385   ",
      "   i\u0399\u0399\u0399\u0399\u0399\u0399\u0398\u0398    ",
      "   i\u0399\u0399\u0399\u0399\u0399\u0399\u0398     ",
      "   i\u0399\u0399\u0399\u0399\u0399\u0399      ",
      "   i\u0399\u0399\u0399\u0399\u0399\u0399\u0399     ",
      "   i\u0399\u0399\u0399\u0399\u0399iiq    ",
      "   i\u0399\u0399\u0399\u0399\u0399\u0399\u0399\u0399    ",
      "   i\u0399\u0399\u0399\u0399\u0399\u0399\u0399\u0398    ",
      "   i\u0399\u0399\u0399\u0399\u0399\u0399\u0399     ",
      " a i\u0399\u0399\u0399\u0399\u0399\u0399\u0399\u0399    ",
      " mjiiiiii\u0399\u0399\u0398    ",
      " m       lqq    ",
      " m   c\u0384  l      ",
      " laallaa\u03dea      ",
      "                "
    ],
    [
      "                ",
      "   dddedee\u039ee    ",
      "   d\u0399\u0399\u0399\u0399\u0399\u0399\u0399\u039f    ",
      "   d\u0399\u0399\u0399\u0399\u03d4\u0399      ",
      "   d\u0399\u03d4\u0399\u0399\u0399\u0399\u039f\u03d4    ",
      "   d\u0399\u0399\u0399\u0399\u0399\u0399\u039f\u039f    ",
      "   d\u0399\u0399\u0399\u0399\u0399\u0399\u0399     ",
      "   d\u0399\u0399\u0399\u0399\u0399\u0399\u0399     ",
      "   d\u0399\u0399\u0399\u0399\u0399\u0399\u0399\u039f\u03a3   ",
      "   d\u0399\u0399\u0399\u0399\u0399\u0399\u0399\u03a3    ",
      " a i\u0399\u0399\u0399\u0399\u0399b\u0399     ",
      " ajiiiibbb\u0399\u039f    ",
      " a    \u03dfbbl\u039e     ",
      " a    cbba      ",
      " alaaalaal      ",
      "                "
    ],
    [
      "                ",
      "   iiiiqioq\u0396    ",
      "   q\u03e1\u03e1\u03e1\u03e1\u03e1\u03e1\u03e1     ",
      "   i\u03e1\u0393  \u03d4       ",
      "   i\u03e1\u03d4\u03d4\u03d4\u03d4\u03d4\u03d4\u03d4    ",
      "   i  \u0393         ",
      "   i\u03e1\u03e6\u03e6         ",
      "   i\u03e1\u03e6\u03e5    \u03e4    ",
      "   i\u03e1 \u0393   \u039a\u03cc    ",
      "   i\u03e1     \u03a9     ",
      " aIi\u03e1II Ia\u03e3     ",
      " lbbbbb\u03e2bl\u03e1     ",
      " a    \u03e0  aq\u03b9    ",
      " a       l      ",
      " annnaaala      ",
      "                "
    ],
    [
      "                ",
      "                ",
      "    \u03e1\u03e1\u03e1 \u03e1\u03e1\u03e1\u03e1    ",
      "    \u03e1           ",
      "    \u03e1           ",
      "    \u03e1           ",
      "    \u03e1\u03ed          ",
      "    \u03e1\u03e5    \u03e4     ",
      "         \u03ec\u03eb\u03ea    ",
      "    \u03e1     \u03e9     ",
      " \u03e8II\u03e1II Il      ",
      " abbbbb\u03e7ba\u03e1\u03e1    ",
      " +       l      ",
      " n       l      ",
      " lalaa**\u03b0l      ",
      "                "
    ],
    [
      "                ",
      "                ",
      "                ",
      "                ",
      "                ",
      "                ",
      "                ",
      "                ",
      "           \u03f0    ",
      "          \u03ef     ",
      " lIIIIIIIa      ",
      " abbbbb\u03eebl      ",
      " a       l      ",
      " a       l      ",
      " \u037f\u037f\u037faalaal      ",
      "                "
    ],
    [
      "                ",
      "                ",
      "                ",
      "                ",
      "                ",
      "                ",
      "                ",
      "                ",
      "                ",
      "                ",
      " aalalaal\u03f1      ",
      " a\u0399\u0399\u0399\u0399\u0399\u0399\u0399l      ",
      " a\u0399\u0399\u0399\u0399\u0399\u0399\u0399a      ",
      " a\u0399\u0399\u0399\u0399\u0399\u0399\u0399l      ",
      " laaaaala\u039d      ",
      "                "
    ],
    [
      "                ",
      "                ",
      "                ",
      "                ",
      "                ",
      "                ",
      "                ",
      "                ",
      "                ",
      "                ",
      " *&****&&       ",
      " &              ",
      " *       &      ",
      " &       &      ",
      "  ***&**&       ",
      "                "
    ]
  ]
}