{
  "name": "building_apartmentsmallcbroken_top",
  "refpalette": "deceasedcraft:building_apartmentsmallcbroken/building_apartmentsmallcbroken_top_palette",
  "xsize": 16,
  "zsize": 16,
  "slices": [
    [
      "                ",
      "      aaaaaaaaa ",
      "      abbc    a ",
      " deeddabbbf   a ",
      " egghggibiiiija ",
      " dhgggggggggi a ",
      " ehgggggggggd   ",
      " eghggggggggd   ",
      " dhgggggggggd   ",
      " dggggggggggd   ",
      " egggggkggggd   ",
      " dghggkkkgkgd   ",
      " ehggggkkgkkd   ",
      " ehhgggkkgkkd   ",
      " dededededddd   ",
      "                "
    ],
    [
      "                ",
      "      laaamnnnl ",
      "      a       a ",
      " opqqia   rf  a ",
      " istuwxiyiiiiba ",
      " q AB CD iEFiIa ",
      " JKKKDLMNOP i   ",
      " q A QRSq  Ti   ",
      " UVWX   i YZi   ",
      " qiqi0i q YZi   ",
      " iVE1 q2i  Ti   ",
      " i34  2 5i6ii   ",
      " JP 7 i 8i95i   ",
      " q# $%i  i 8i   ",
      " q^qiqqiiiiii   ",
      "                "
    ],
    [
      "                ",
      "      a&**aalaa ",
      "      a       n ",
      " q ((ia)   rf + ",
      " -[  ]{i}iiiiba ",
      " (      |i;:iIl ",
      "         '  <   ",
      " (      q> ,(   ",
      " < .? / i   `   ",
      " \u0370oqi\u0371i i   `   ",
      " q \u0372 \u0373i\u0374i  \u0375(   ",
      " (    \u0374 \u0376i\u0377i`   ",
      "      q  i \u0376`   ",
      " o   \u0375i \u037ai\u037b (   ",
      " - \u037c\u037d(\u037c\u037d(-ii\u037e   ",
      "                "
    ],
    [
      "                ",
      "      aaaaaa\u037f\u037f\u037f ",
      "      l    \u0384bba ",
      " \u0385\u0386\u0386\u0386ia     rba ",
      " -     i\u0386iiiibl ",
      "         i  iIa ",
      "       ! `  <   ",
      " (      i   (   ",
      "        q   `   ",
      "  \u0387iq\u037dq i   `   ",
      "      i\u0388i   (   ",
      "      \u0389 \u038ai\u0388i`   ",
      "      i  i \u038a`   ",
      " \u038c    i \u038ei\u038f (   ",
      " \u0390  \u037c(\u037d\u037d(-ii-   ",
      "                "
    ],
    [
      "                ",
      "      &**aaaaaa ",
      "      \u0391   \u0384c  a ",
      " qoqiia       a ",
      " \u0392     iiiiiiba ",
      "        \u0393i  iIa ",
      "      \u0393\u0394 i  i   ",
      "       \u0393ii  i   ",
      "        i   i   ",
      "   \u0385qqi i \u0395 i   ",
      "      iiq   i   ",
      "   \u0394  i  iiii   ",
      "      i  i  i   ",
      "      q  i  i   ",
      "    \u0396qoqiqiii   ",
      "                "
    ],
    [
      "                ",
      "      \u0397aaalaaaa ",
      "      l  \u0384c   m ",
      " \u0385qiqia       m ",
      "  \u0398\u0399\u0399\u039a\u0399iiiiiijm ",
      "    \u039b\u0399\u039c\u039c\u0399\u0399\u0399\u0399i a ",
      "     \u0399\u039a\u0399\u0399\u0399\u0399\u0399i   ",
      "   \u0398\u0399\u0399\u0399\u0399\u0399\u0399\u0399\u0399i   ",
      "    \u0399\u0399\u0399\u0399\u0399\u0399\u0399\u0399i   ",
      "   qii\u0399\u0399\u0399\u0399\u0399\u0399i   ",
      "  \u0398\u0399\u0399\u0399\u0399\u0399\u0399\u0399\u0399\u0399i   ",
      "   \u0399\u0399\u0399\u0399\u0399\u0399\u0399\u0399\u0399i   ",
      "    \u0399\u0399\u0399\u0399\u0399\u0399\u0399\u0399i   ",
      "    \u0398\u0399\u0399\u0399\u0399\u0399\u0399\u0399i   ",
      "     \u0385q\u0370qiqii   ",
      "                "
    ],
    [
      "                ",
      "      \u039dlaaaaaaa ",
      "      abbc    a ",
      "  \u039ed\u039edlbbbf   a ",
      "  \u039f\u039bh\u039cgibiiiija ",
      "   h\u039b\u039a\u03a0gggggi a ",
      "  \u03a1gh\u039c!gggggd   ",
      "  \u039fhggggggggd   ",
      "  \u03a3\u03a4ghggggggd   ",
      "  \u03a5qihggggggd   ",
      " \u03a3\u039fhgggkggggd   ",
      "  \u03a1\u03a4hgkkkgkgd   ",
      "  \u039fhgggkkgkkd   ",
      "  \u039f\u03a6hggkkgkkd   ",
      "       eedddd   ",
      "                "
    ],
    [
      "                ",
      "      &laamn\u03a7na ",
      "      l       a ",
      "  Uo\u039b\u039ca   rf  a ",
      "   B\u03a8\u03a0\u03a9o\u03aaiiiiba ",
      "     \u03a8\u03ab  iEFiIa ",
      "   \u03ac[   DV Pi   ",
      "    [  Vq  Ti   ",
      "   WX\u0396# q YZi   ",
      "   qi q i YZi   ",
      "   E1 i2i  Ti   ",
      "   \u03ad  6 5i2ii   ",
      "  \u03ae 7 q 8i 5i   ",
      "  \u03afV$%i  i 8i   ",
      "      \u0396\u0385qqiii   ",
      "                "
    ],
    [
      "                ",
      "      a\u03b0**aaaaa ",
      "      l       n ",
      "   ((\u039aa    rf + ",
      "     \u03ab\u03a8o\u03b1iiiiba ",
      "        \u0373i\u03b2 iIa ",
      "            <   ",
      "        i\u03b3 \u0375(   ",
      "   \u03b4    q   `   ",
      "   Ui J i   `   ",
      "      i\u0374i  ,(   ",
      "      \u0377 \u0376i\u0374i`   ",
      "      i\u03b5 i\u03b5\u0376\u03b6   ",
      "      i \u037ai\u037b (   ",
      "       \u037c(-qi\u037e   ",
      "                "
    ],
    [
      "                ",
      "      laaaaa\u037f\u037f\u0391 ",
      "      a    \u0384bba ",
      "   \u0386\u0386oa     rba ",
      "       q\u0386iiiibl ",
      "         q  iIa ",
      "         `  <   ",
      "        i   (   ",
      "        i   `   ",
      "    q\u037di q   `   ",
      "      i\u0388i   (   ",
      "      \u03b7 \u038ai\u0388i`   ",
      "      i  i \u038a`   ",
      "      q \u038ei\u038f (   ",
      "      \u037c\u037d \u037eii\u037e   ",
      "                "
    ],
    [
      "                ",
      "       &*aalaaa ",
      "      l   \u0384c  a ",
      "  \u03b8q\u039aoa       a ",
      "       iqiiiiba ",
      "         i  iIa ",
      "   \u0394   \u0394 i  i   ",
      "        qi  i   ",
      "        q   i   ",
      "   \u0385qiq i \u0395 i   ",
      "      iqi   i   ",
      "      i  iiii   ",
      "      q  i  i   ",
      "      i  i  i   ",
      "     \u03b8qqiiiii   ",
      "                "
    ],
    [
      "                ",
      "      aaaaaaaaa ",
      "      l  \u0384c   m ",
      "   \u03b9qia       m ",
      "     \u039a\u0399iiiiiijm ",
      "   \u0398\u0399\u0399\u039a\u0399\u0399\u0399\u0399\u0399i a ",
      "  \u0398\u039a\u0399\u0399\u0399\u0399\u0399\u0399\u0399\u0399i   ",
      "   \u0399\u039b\u0399\u0399\u0399\u0399\u0399\u0399\u0399i   ",
      "    \u0399\u0399\u0399\u0399\u0399\u0399\u0399\u0399i   ",
      "   qii\u0399\u0399\u0399\u0399\u0399\u0399i   ",
      "    \u0399\u0399\u0399\u0399\u0399\u0399\u0399\u0399i   ",
      "   \u0398\u0399\u0399\u0399\u0399\u0399\u0399\u0399\u0399i   ",
      "     \u0399\u0399\u0399\u0399\u0399\u0399\u0399i   ",
      "     \u0398\u0399\u0399\u0399\u0399\u0399\u0399i   ",
      "     \u0385qiqiiii   ",
      "                "
    ],
    [
      "                ",
      "      alaaaaaaa ",
      "      lbbc    a ",
      "   e\u039eelbbbf   a ",
      " \u03a3\u039fhhggibiiiija ",
      "   \u039b\u039ahhgggggi a ",
      "  \u039f\u03a8ggggggggd   ",
      "   \u039f\u03a8hggggggd   ",
      "   \u03a1hgggggggd   ",
      "   qqgggggggd   ",
      "  \u039fghggkggggd   ",
      "  \u03a3\u03a4ggkkkgkgd   ",
      "   \u03a1ghgkkgkkd   ",
      "   \u039fhghkkgkkd   ",
      "       \u039eddddd   ",
      "                "
    ],
    [
      "                ",
      "      laala\u03a7nna ",
      "      a       a ",
      "  \u0385qqia   rf  a ",
      "   \u03bauwxi\u03aaiiiiba ",
      "    V A \u03bbiEFiIa ",
      "   \u03bb\u03bc[DD OP i   ",
      "   Q\u03bd RSi  Ti   ",
      "   WX#  i YZi   ",
      "   \u03b8i\u03beq i YZi   ",
      "     Vo2i  Ti   ",
      "   A  6 5i2ii   ",
      "     Aq98i 5i   ",
      "   \u03bdV%i  i 8i   ",
      "      oqiqiii   ",
      "                "
    ],
    [
      "                ",
      "      a\u03b0**aalaa ",
      "      a       n ",
      "   ((qa)   rf + ",
      "      {i\u03b1iiiiba ",
      "        \u0373i\u03bf\u03c0iIa ",
      "         '  <   ",
      "      \u03c1 i> ,(   ",
      "   .    i   `   ",
      "   \u0385i\u03c2^ i   `   ",
      "     |i\u0374i  \u0375(   ",
      "      \u0377 \u0376i\u0374i`   ",
      "      i  i\u03b5\u0376`   ",
      "     ,q \u037ai\u037b (   ",
      "      \u037c\u037c(\u037eii-   ",
      "                "
    ],
    [
      "                ",
      "      alaall\u037f\u037f\u037f ",
      "      l    \u0384bba ",
      "   \u0386\u0386ia     rba ",
      "      \u03c3i\u0386iiiiba ",
      "         i  iIa ",
      "         `  <   ",
      "        i   (   ",
      "        i   `   ",
      "    q\u037d\u0389 i   `   ",
      "      q\u0388i   (   ",
      "      \u03b7 \u038ai\u0388i\u03b6   ",
      "      i  i \u038a`   ",
      "      \u0392 \u038ei\u038f (   ",
      "       \u037c(\u037eii\u0390   ",
      "                "
    ],
    [
      "                ",
      "      ***lalaaa ",
      "      a   \u0384c  a ",
      "   qoia       a ",
      "       qiiiiiba ",
      "         i  iIa ",
      "       \u03c4 i  i   ",
      "        ii  i   ",
      "        i   i   ",
      "    qii i \u0395 i   ",
      "      iii   i   ",
      "      i  iiii   ",
      "      q  i  i   ",
      "      i  i  i   ",
      "      \u03b9qiqiii   ",
      "                "
    ],
    [
      "                ",
      "      \u0397aaaaalal ",
      "      l  \u0384c   m ",
      "   \u03a5qqa       m ",
      "   \u0398\u0399\u0399\u0399iiiiiijm ",
      "   \u0399\u0399\u0399\u0399\u0399\u0399\u0399\u0399\u0399i a ",
      "    \u0399\u0399\u0399\u0399\u0399\u0399\u0399\u0399i   ",
      "    \u0398 \u0399\u0399\u0399\u0399\u0399\u0399i   ",
      "      \u0398\u0399\u0399\u0399\u0399\u0399i   ",
      "    \u0385iq\u0399\u0399\u0399\u0399\u0399i   ",
      "   \u0398\u0399\u0399\u0399\u0399\u0399\u0399\u0399\u0399i   ",
      "    \u0399\u0399\u0399\u0399\u0399\u0399\u0399\u0399i   ",
      "    \u0398\u0399\u0399\u0399\u0399\u0399\u0399\u0399i   ",
      "    \u0399\u0399\u0399\u0399\u0399\u0399\u0399\u0399i   ",
      "     Uqoqiiiq   ",
      "                "
    ],
    [
      "                ",
      "      aalalaaaa ",
      "      lbbc    l ",
      "   ee\u039elbbbf   a ",
      "   \u039fg\u03c5gibiiiija ",
      "   \u03a3\u03a4hggggggi a ",
      "    \u03a1ghgggggd   ",
      "   \u03a1\u03c6gggggggd   ",
      "   \u039fhhggggggd   ",
      "    qgggggggd   ",
      "   \u039f\u03a4ggkggggd   ",
      "   \u039f\u039bhkkkgkgd   ",
      "    \u03a9\u039agkkgkkd   ",
      "    \u03a1hgkkgkkd   ",
      "      \u039eeedddd   ",
      "                "
    ],
    [
      "                ",
      "      \u03c7laaannna ",
      "      a       a ",
      "   \u0396oqa   rf  a ",
      "    \u03c8\u03c9\u039ao\u03aaiiiiba ",
      "      D\u0372 i\u03ca\u03cbiIa ",
      "    \u03ccD  V\u03cd\u03ce\u03cei   ",
      "   #  RSi\u03cf\u03d0\u03d0i   ",
      "    \u03d1   q\u03753 i   ",
      "    \u03b8Vi q\u03d2 \u03d3i   ",
      "    \u03d4Aq o\u03d5 \u03d6i   ",
      "     B\u0385 5i6ii   ",
      "    [ o~\u03d7i 5i   ",
      "    V\u03a9i ~iQ8i   ",
      "    \u039eqqoiqiii   ",
      "                "
    ],
    [
      "                ",
      "      a\u03d8&*laaaa ",
      "      l       n ",
      "    (ia    rf + ",
      "      \u039aq\u03b1iiiiba ",
      "        \u0373iP iIa ",
      "         \u03ca  <   ",
      "        q   (   ",
      "      / i   `   ",
      "      i i  \u03d9`   ",
      "      \u03da q   (   ",
      "        \u0376i\u0377i`   ",
      "      \u0396  i\u03db\u0376\u03b6   ",
      "      q \u037ai\u037b (   ",
      "    \u037c(\u037c\u037d(\u037eii-   ",
      "                "
    ],
    [
      "                ",
      "      laalaa\u037f\u037f& ",
      "      l    \u0384bba ",
      "    \u0386oa     rba ",
      "       i\u0386iiiiba ",
      "         i  iIl ",
      "         `  <   ",
      "        i   (   ",
      "        i   `   ",
      "      q q   `   ",
      "      q\u03dci       ",
      "        \u038ai\u0388i`   ",
      "         i \u038a`   ",
      "      i \u038ei\u038f (   ",
      "     (\u037d\u037c(-ii\u037e   ",
      "                "
    ],
    [
      "                ",
      "      **&aalaaa ",
      "      l   \u0384c  a ",
      "    \u03b9qa       a ",
      "       qiiiiiba ",
      "         i  iIa ",
      "       \u03dd i  i   ",
      "        ii  i   ",
      "        q   i   ",
      "    \u039e\u03b9q i \u0395 i   ",
      "      qqi   i   ",
      "      \u03dc  iiii   ",
      "      o  i  i   ",
      "      q  i  i   ",
      "    \u03b9iqiiiiii   ",
      "                "
    ],
    [
      "                ",
      "      a\u03deaallaal ",
      "      l  \u0384c   m ",
      "    qql       m ",
      "    \u0398\u0399\u0399iiiiiijm ",
      "    \u0399\u0399\u0399\u0399\u0399\u0399\u0399\u0399i a ",
      "     \u0399\u0399\u0399\u0399\u0399\u0399\u0399i   ",
      "    \u0398\u0399\u0399\u0399\u0399\u0399\u0399\u0399i   ",
      "    \u0399\u0399\u0399\u0399\u0399\u0399\u0399\u0399i   ",
      "    qii\u0399\u0399\u0399\u0399\u0399i   ",
      "     \u0399\u0399\u0399\u0399\u0399\u0399\u0399i   ",
      "      \u0399\u0399\u0399\u0399\u0399\u0399i   ",
      "     \u0398\u0399\u0399\u0399\u0399\u0399\u0399i   ",
      "    \u0398\u0398\u0399\u0399\u0399\u0399\u0399\u0399i   ",
      "   \u0385q\u0370qqiiqii   ",
      "                "
    ],
    [
      "                ",
      "      laalaaala ",
      "      abbc    a ",
      "     \u039elbb\u03df    a ",
      "    \u039f\u0399bbbiiiija ",
      "     \u0399b\u0399\u0399\u0399\u0399\u0399i a ",
      "    \u03a3\u0399\u0399\u0399\u0399\u0399\u0399\u0399d   ",
      "   \u03a3\u039f\u0399\u0399\u0399\u0399\u0399\u0399\u0399d   ",
      "     \u0399\u0399\u0399\u0399\u0399\u0399\u0399d   ",
      "     \u0399\u0399\u0399\u0399\u0399\u0399\u0399d   ",
      "    \u039f\u039f\u0399\u0399\u0399\u0399\u0399\u0399d   ",
      "    \u03d4\u039f\u0399\u0399\u0399\u0399\u03d4\u0399d   ",
      "      \u0399\u03d4\u0399\u0399\u0399\u0399d   ",
      "    \u039f\u0399\u0399\u0399\u0399\u0399\u0399\u0399d   ",
      "    e\u039eeededdd   ",
      "                "
    ],
    [
      "                ",
      "      alaaannna ",
      "      l       a ",
      "    \u03b9qa  \u03e0    a ",
      "     \u03e1lb\u03e2bbbbbl ",
      "     \u03e3aI II\u03e1iIa ",
      "     \u03a9     \u03e1i   ",
      "    \u03cc\u039a   \u0393 \u03e1i   ",
      "    \u03e4    \u03e5\u03e6\u03e1i   ",
      "         \u03e6\u03e6\u03e1i   ",
      "         \u0393  i   ",
      "    \u03d4\u03d4\u03d4\u03d4\u03d4\u03d4\u03d4\u03e1i   ",
      "       \u03d4  \u0393\u03e1i   ",
      "     \u03e1\u03e1\u03e1\u03e1\u03e1\u03e1\u03e1q   ",
      "    \u0396qoiqiiii   ",
      "                "
    ],
    [
      "                ",
      "      l\u03b0**aalal ",
      "      l       n ",
      "      l       + ",
      "    \u03e1\u03e1ab\u03e7bbbbba ",
      "      lI II\u03e1II\u03e8 ",
      "     \u03e9     \u03e1    ",
      "    \u03ea\u03eb\u03ec         ",
      "     \u03e4    \u03e5\u03e1    ",
      "          \u03ed\u03e1    ",
      "           \u03e1    ",
      "           \u03e1    ",
      "           \u03e1    ",
      "    \u03e1\u03e1\u03e1\u03e1 \u03e1\u03e1\u03e1    ",
      "                ",
      "                "
    ],
    [
      "                ",
      "      laalaa\u037f\u037f\u037f ",
      "      l       a ",
      "      l       a ",
      "      lb\u03eebbbbba ",
      "      aIIIIIIIl ",
      "     \u03ef          ",
      "    \u03f0           ",
      "                ",
      "                ",
      "                ",
      "                ",
      "                ",
      "                ",
      "                ",
      "                "
    ],
    [
      "                ",
      "      \u039dalaaaaal ",
      "      l\u0399\u0399\u0399\u0399\u0399\u0399\u0399a ",
      "      a\u0399\u0399\u0399\u0399\u0399\u0399\u0399a ",
      "      l\u0399\u0399\u0399\u0399\u0399\u0399\u0399a ",
      "      \u03f1laalalaa ",
      "                ",
      "                ",
      "                ",
      "                ",
      "                ",
      "                ",
      "                ",
      "                ",
      "                ",
      "                "
    ],
    [
      "                ",
      "       &**&***  ",
      "      &       & ",
      "      &       * ",
      "              & ",
      "       &&****&* ",
      "                ",
      "                ",
      "                ",
      "                ",
      "                ",
      "                ",
      "                ",
      "                ",
      "                ",
      "                "
    ]
  ]
}