{
  "name": "building_apartmentsmallcbroken_top_270",
  "refpalette": "deceasedcraft:building_apartmentsmallcbroken/building_apartmentsmallcbroken_top_palette_270",
  "xsize": 16,
  "zsize": 16,
  "slices": [
    [
      "                ",
      " deededdeeded   ",
      " ehhggghghhge   ",
      " dhghggghggge   ",
      " eggggggggghd   ",
      " dggggggggggd   ",
      " eggkgggggggaaa ",
      " dkkkkgggggibba ",
      " ekkkggggggbbba ",
      " dgggggggggibca ",
      " dkkkggggggif a ",
      " dkkgggggggi  a ",
      " dddddddddii  a ",
      "           j  a ",
      "          aaaaa ",
      "                "
    ],
    [
      "                ",
      " qqJiiqUqJqio   ",
      " ^#P3ViV K sp   ",
      " q  4EqWAKAtq   ",
      " i$7 1iX KBuq   ",
      " q%   0 QD wi   ",
      " qii2qi RLCxaal ",
      " i   2  SMDi  a ",
      " i 85iqiqN y  a ",
      " iiii    Oii  a ",
      " i 96 YY PEir m ",
      " i85iTZZT Fif n ",
      " iiiiiiiiiii  n ",
      "          Ib  n ",
      "          aaaal ",
      "                "
    ],
    [
      "                ",
      " -o (q\u0370<( (-q   ",
      "      o    [    ",
      " \u037c   \u0372q.    (   ",
      " \u037d    i?    (   ",
      " (\u0375  \u0373\u0371    ]i   ",
      " \u037ciq\u0374ii/   {aaa ",
      " \u037d   \u0374     i) & ",
      " (\u037a \u0376iiiq |}  * ",
      " -iii   >'ii  * ",
      " i\u037b \u0377     ;i  a ",
      " i \u0376i\u0375  , :ir a ",
      " \u037e(``(``(<iif l ",
      "          Ib  a ",
      "          la+na ",
      "                "
    ],
    [
      "                ",
      " \u0390\u038c     (  -\u0385   ",
      "      \u0387     \u0386   ",
      "      i     \u0386   ",
      " \u037c    q     \u0386   ",
      " (    \u037d     i   ",
      " \u037dii\u0389iq     ala ",
      " \u037d   \u0388   ! i  a ",
      " (\u038e \u038aiiqi  \u0386  a ",
      " -iii    `ii  a ",
      " i\u038f \u0388      i  a ",
      " i \u038ai      i \u0384a ",
      " -(``(``(<iirb\u037f ",
      "          Ibbb\u037f ",
      "          alaa\u037f ",
      "                "
    ],
    [
      "                ",
      "           \u0392q   ",
      "            o   ",
      "    \u0394 \u0385     q   ",
      " \u0396    q     i   ",
      " q    q     i   ",
      " oqiiii  \u0393  a\u0391& ",
      " q   i  \u0393\u0394 i  * ",
      " i   qiii \u0393i  * ",
      " qiii   iiii  a ",
      " i  i \u0395    i \u0384a ",
      " i  i      i ca ",
      " iiiiiiiiiii  a ",
      "          Ib  a ",
      "          aaaaa ",
      "                "
    ],
    [
      "                ",
      "            \u0385   ",
      "     \u0398     \u0398q   ",
      "    \u0399\u0399q \u0398  \u0399i   ",
      "  \u0398\u0399\u0399\u0399i\u0399\u0399 \u039b\u0399q   ",
      " \u0385\u0399\u0399\u0399\u0399i\u0399\u0399\u0399\u0399\u039ai   ",
      " q\u0399\u0399\u0399\u0399\u0399\u0399\u0399\u039a\u039c\u0399al\u0397 ",
      " \u0370\u0399\u0399\u0399\u0399\u0399\u0399\u0399\u0399\u039ci  a ",
      " q\u0399\u0399\u0399\u0399\u0399\u0399\u0399\u0399\u0399i  a ",
      " i\u0399\u0399\u0399\u0399\u0399\u0399\u0399\u0399\u0399i \u0384a ",
      " q\u0399\u0399\u0399\u0399\u0399\u0399\u0399\u0399\u0399i cl ",
      " i\u0399\u0399\u0399\u0399\u0399\u0399\u0399\u0399\u0399i  a ",
      " iiiiiiiiiii  a ",
      "           j  a ",
      "          ammma ",
      "                "
    ],
    [
      "                ",
      "     \u03a3          ",
      "  \u039f\u039f\u03a1\u039f\u03a5\u03a3\u039f\u03a1 \u039f\u039e   ",
      "  \u03a6h\u03a4hq\u03a4hgh\u039bd   ",
      "  hghgiggh\u039bh\u039e   ",
      "  gggghhg\u039c\u039a\u039cd   ",
      "  ggkgggg!\u03a0gla\u039d ",
      " ekkkkgggggibbl ",
      " ekkkggggggbbba ",
      " dgggggggggibca ",
      " dkkkggggggif a ",
      " dkkgggggggi  a ",
      " dddddddddii  a ",
      "           j  a ",
      "          aaaaa ",
      "                "
    ],
    [
      "                ",
      "                ",
      "  \u03af\u03ae        U   ",
      "  V \u03adEqW \u03ac Bo   ",
      "  $7 1iX[[ \u03a8\u039b   ",
      "  %    \u0396  \u03a8\u03a0\u039c   ",
      " \u0396iq6iq#  \u03ab\u03a9al& ",
      " \u0385   2  V  o  l ",
      " q 85iiqqD \u03aa  a ",
      " qiii    Vii  a ",
      " i  2 YY  Eir m ",
      " i85iTZZTPFif n ",
      " iiiiiiiiiii  \u03a7 ",
      "          Ib  n ",
      "          aaaaa ",
      "                "
    ],
    [
      "                ",
      "                ",
      "                ",
      "      U\u03b4    (   ",
      "      i     (   ",
      "           \u03ab\u039a   ",
      "  ii\u0377iJ    \u03a8ala ",
      " \u037c \u03b5 \u0374     o  \u03b0 ",
      " (\u037a \u0376iiqi \u0373\u03b1  * ",
      " -iii   \u03b3 ii  * ",
      " q\u037b\u03b5\u0374     \u03b2i  a ",
      " i \u0376i,  \u0375  ir a ",
      " \u037e(\u03b6`(``(<iif a ",
      "          Ib  a ",
      "          aa+na ",
      "                "
    ],
    [
      "                ",
      "                ",
      "                ",
      "            \u0386   ",
      "      q     \u0386   ",
      "      \u037d     o   ",
      " \u037cqi\u03b7ii     aal ",
      " \u037d   \u0388     q  a ",
      "  \u038e \u038aiqii  \u0386  a ",
      " \u037eiii    `qi  a ",
      " i\u038f \u0388      i  a ",
      " i \u038ai      i \u0384a ",
      " \u037e(``(``(<iirb\u037f ",
      "          Ibbb\u037f ",
      "          alaa\u0391 ",
      "                "
    ],
    [
      "                ",
      "                ",
      "            \u03b8   ",
      "      \u0385  \u0394  q   ",
      "      q     \u039a   ",
      " \u03b8    i     o   ",
      " qiqiiq     al  ",
      " q   q   \u0394 i  & ",
      " i   iiqq  q  * ",
      " iiii   iiii  a ",
      " i  i \u0395    i \u0384a ",
      " i  i      i cl ",
      " iiiiiiiiiii  a ",
      "          Ib  a ",
      "          aaaaa ",
      "                "
    ],
    [
      "                ",
      "                ",
      "         \u0398      ",
      "    \u0398 q \u0399\u039a\u0398 \u03b9   ",
      "    \u0399\u0399i\u0399\u039b\u0399\u0399 q   ",
      " \u0385\u0398\u0399\u0399\u0399i\u0399\u0399\u0399\u0399\u039ai   ",
      " q\u0399\u0399\u0399\u0399\u0399\u0399\u0399\u0399\u039a\u0399ala ",
      " i\u0399\u0399\u0399\u0399\u0399\u0399\u0399\u0399\u0399i  a ",
      " q\u0399\u0399\u0399\u0399\u0399\u0399\u0399\u0399\u0399i  a ",
      " i\u0399\u0399\u0399\u0399\u0399\u0399\u0399\u0399\u0399i \u0384a ",
      " i\u0399\u0399\u0399\u0399\u0399\u0399\u0399\u0399\u0399i ca ",
      " i\u0399\u0399\u0399\u0399\u0399\u0399\u0399\u0399\u0399i  a ",
      " iiiiiiiiiii  a ",
      "           j  a ",
      "          ammma ",
      "                "
    ],
    [
      "                ",
      "           \u03a3    ",
      "    \u03a3\u039f   \u039f \u039f    ",
      "  \u039f\u03a1\u03a4gq\u03a1\u039f\u03a8\u039bhe   ",
      "  hgghqh\u03a8g\u039ah\u039e   ",
      "  ghgggghghge   ",
      "  hgkggggghglla ",
      " \u039ekkkkgggggibbl ",
      " dkkkggggggbbba ",
      " dgggggggggibca ",
      " dkkkggggggif a ",
      " dkkgggggggi  a ",
      " dddddddddii  a ",
      "           j  a ",
      "          aaaaa ",
      "                "
    ],
    [
      "                ",
      "                ",
      "            \u0385   ",
      "  \u03bd A \u03b8WQ\u03bb \u03baq   ",
      "  V   iX\u03bd\u03bcVuq   ",
      "  %A V\u03be# [ wi   ",
      " oiq6oq RDAxaal ",
      " q 9 2  SD i  a ",
      " i 85iiii \u03bb\u03aa  a ",
      " qiii    Oii  l ",
      " i  2 YY PEir a ",
      " i85iTZZT Fif \u03a7 ",
      " iiiiiiiiiii  n ",
      "          Ib  n ",
      "          aaaaa ",
      "                "
    ],
    [
      "                ",
      "                ",
      "                ",
      "      \u0385.    (   ",
      "      i     (   ",
      "  ,  |\u03c2     q   ",
      " \u037cqi\u0377i^ \u03c1  {aaa ",
      " \u037c   \u0374     i) \u03b0 ",
      " (\u037a \u0376iiii \u0373\u03b1  * ",
      " \u037eiii   >'ii  * ",
      " i\u037b\u03b5\u0374     \u03bfi  a ",
      " i \u0376i\u0375  , \u03c0ir a ",
      " -(``(``(<iif l ",
      "          Ib  a ",
      "          aa+na ",
      "                "
    ],
    [
      "                ",
      "                ",
      "                ",
      "            \u0386   ",
      "      q     \u0386   ",
      "      \u037d     i   ",
      "  \u0392i\u03b7q\u0389    \u03c3ala ",
      " \u037c   \u0388     i  l ",
      " (\u038e \u038aiiii  \u0386  a ",
      " \u037eiii    `ii  a ",
      " i\u038f \u0388      i  l ",
      " i \u038ai      i \u0384l ",
      " \u0390(`\u03b6(``(<iirb\u037f ",
      "          Ibbb\u037f ",
      "          aaaa\u037f ",
      "                "
    ],
    [
      "                ",
      "                ",
      "                ",
      "            q   ",
      "      q     o   ",
      "      i     i   ",
      " \u03b9iqiii     aa* ",
      " q   i   \u03c4 q  * ",
      " i   iiii  i  * ",
      " qiii   iiii  l ",
      " i  i \u0395    i \u0384a ",
      " i  i      i cl ",
      " iiiiiiiiiii  a ",
      "          Ib  a ",
      "          aaaaa ",
      "                "
    ],
    [
      "                ",
      "                ",
      "                ",
      "     \u0398    \u0399\u0398\u03a5   ",
      "  \u0399\u0398\u0399\u0399\u0385 \u0398\u0399\u0399\u0399q   ",
      " U\u0399\u0399\u0399\u0399i  \u0399\u0399\u0399q   ",
      " q\u0399\u0399\u0399\u0399q\u0398\u0399\u0399\u0399\u0399al\u0397 ",
      " o\u0399\u0399\u0399\u0399\u0399\u0399\u0399\u0399\u0399i  a ",
      " q\u0399\u0399\u0399\u0399\u0399\u0399\u0399\u0399\u0399i  a ",
      " i\u0399\u0399\u0399\u0399\u0399\u0399\u0399\u0399\u0399i \u0384a ",
      " i\u0399\u0399\u0399\u0399\u0399\u0399\u0399\u0399\u0399i ca ",
      " i\u0399\u0399\u0399\u0399\u0399\u0399\u0399\u0399\u0399i  a ",
      " qiiiiiiiiii  l ",
      "           j  a ",
      "          ammml ",
      "                "
    ],
    [
      "                ",
      "                ",
      "                ",
      "    \u039f\u039f \u039f\u03a1 \u03a3\u039fe   ",
      "  \u03a1\u03a9\u039b\u03a4qh\u03c6\u03a1\u03a4ge   ",
      "  h\u039ahgghggh\u03c5\u039e   ",
      " \u039eggkgggghgglla ",
      " ekkkkgggggibba ",
      " ekkkggggggbbbl ",
      " dgggggggggibca ",
      " dkkkggggggif l ",
      " dkkgggggggi  a ",
      " dddddddddii  a ",
      "           j  a ",
      "          aaala ",
      "                "
    ],
    [
      "                ",
      "                ",
      "                ",
      "        #   \u0396   ",
      " \u039eV[ \u03d4\u03b8\u03d1 \u03cc \u03c8o   ",
      " q\u03a9 BAV  D \u03c9q   ",
      " qio\u0385qi R D\u039aaa\u03c7 ",
      " o ~    S \u0372o  l ",
      " i~\u03d75oqqiV \u03aa  a ",
      " qiii\u03d5\u03d2\u0375\u03cf\u03cdii  a ",
      " iQ 6  3\u03d0\u03ce\u03cair a ",
      " i85i\u03d6\u03d3 \u03d0\u03ce\u03cbif n ",
      " iiiiiiiiiii  n ",
      "          Ib  n ",
      "          aaaaa ",
      "                "
    ],
    [
      "                ",
      "                ",
      "                ",
      "                ",
      " \u037c          (   ",
      " (          i   ",
      " \u037cq\u0396 \u03dai/   \u039aala ",
      " \u037d         q  \u03d8 ",
      " (\u037a \u0376qiiq \u0373\u03b1  & ",
      " \u037eiii    \u03caii  * ",
      " i\u037b\u03db\u0377     Pi  l ",
      " i \u0376i \u03d9    ir a ",
      " -(\u03b6`(``(<iif a ",
      "          Ib  a ",
      "          aa+na ",
      "                "
    ],
    [
      "                ",
      "                ",
      "                ",
      "                ",
      "            \u0386   ",
      " (          o   ",
      " \u037di  qq     all ",
      " \u037c   \u03dc     i  a ",
      " (\u038e \u038aiqii  \u0386  a ",
      " -iii    `ii  l ",
      " i\u038f \u0388      i  a ",
      " i \u038ai      i \u0384a ",
      " \u037e(`` ``(<iirb\u037f ",
      "          Ibbb\u037f ",
      "          laaa& ",
      "                "
    ],
    [
      "                ",
      "                ",
      "                ",
      "                ",
      " \u03b9    \u039e     \u03b9   ",
      " i    \u03b9     q   ",
      " qqo\u03dcqq     al* ",
      " i   q   \u03dd q  * ",
      " i   iiqi  i  & ",
      " iiii   iiii  a ",
      " i  i \u0395    i \u0384a ",
      " i  i      i cl ",
      " iiiiiiiiiii  a ",
      "          Ib  a ",
      "          aaaaa ",
      "                "
    ],
    [
      "                ",
      "                ",
      "                ",
      " \u0385              ",
      " q\u0398   q\u0399\u0398 \u0399\u0398q   ",
      " \u0370\u0398\u0398 \u0399i\u0399\u0399\u0399\u0399\u0399q   ",
      " q\u0399\u0399\u0399\u0399i\u0399\u0399\u0399\u0399\u0399lla ",
      " q\u0399\u0399\u0399\u0399\u0399\u0399\u0399\u0399\u0399i  \u03de ",
      " i\u0399\u0399\u0399\u0399\u0399\u0399\u0399\u0399\u0399i  a ",
      " i\u0399\u0399\u0399\u0399\u0399\u0399\u0399\u0399\u0399i \u0384a ",
      " q\u0399\u0399\u0399\u0399\u0399\u0399\u0399\u0399\u0399i cl ",
      " i\u0399\u0399\u0399\u0399\u0399\u0399\u0399\u0399\u0399i  l ",
      " iiiiiiiiiii  a ",
      "           j  a ",
      "          ammml ",
      "                "
    ],
    [
      "                ",
      "                ",
      "                ",
      "        \u03a3       ",
      " e\u039f \u03d4\u039f  \u039f\u03a3 \u039f    ",
      " \u039e\u0399 \u039f\u039f\u0399\u0399\u0399\u0399\u0399\u0399\u039e   ",
      " e\u0399\u0399\u0399\u0399\u0399\u0399\u0399\u0399bblal ",
      " e\u0399\u03d4\u0399\u0399\u0399\u0399\u0399\u0399\u0399bbba ",
      " d\u0399\u0399\u0399\u0399\u0399\u0399\u0399\u0399\u0399bbba ",
      " e\u0399\u0399\u0399\u0399\u0399\u0399\u0399\u0399\u0399i\u03dfcl ",
      " d\u0399\u0399\u03d4\u0399\u0399\u0399\u0399\u0399\u0399i  a ",
      " d\u0399\u0399\u0399\u0399\u0399\u0399\u0399\u0399\u0399i  a ",
      " dddddddddii  a ",
      "           j  l ",
      "          aaaaa ",
      "                "
    ],
    [
      "                ",
      "                ",
      "                ",
      "                ",
      " \u0396  \u03d4  \u03e4\u03cc   \u03b9   ",
      " q\u03e1 \u03d4   \u039a\u03a9\u03e3\u03e1q   ",
      " o\u03e1 \u03d4     alala ",
      " i\u03e1\u03d4\u03d4     Ib  l ",
      " q\u03e1 \u03d4      \u03e2  a ",
      " i\u03e1 \u03d4\u0393\u03e6\u03e5\u0393 Ib\u03e0 a ",
      " i\u03e1\u0393\u03d4 \u03e6\u03e6  Ib  a ",
      " i\u03e1\u03e1\u03e1 \u03e1\u03e1\u03e1\u03e1\u03e1b  n ",
      " iqiiiiiiiib  n ",
      "          Ib  n ",
      "          alaaa ",
      "                "
    ],
    [
      "                ",
      "                ",
      "                ",
      "                ",
      "  \u03e1     \u03ea  \u03e1    ",
      "  \u03e1    \u03e4\u03eb\u03e9 \u03e1    ",
      "  \u03e1     \u03ec lalll ",
      "  \u03e1       Ib  \u03b0 ",
      "           \u03e7  * ",
      "  \u03e1       Ib  * ",
      "  \u03e1   \u03ed\u03e5  Ib  a ",
      "  \u03e1\u03e1\u03e1\u03e1\u03e1\u03e1 \u03e1\u03e1b  a ",
      "          Ib  l ",
      "          Ib  a ",
      "          \u03e8a+nl ",
      "                "
    ],
    [
      "                ",
      "                ",
      "                ",
      "                ",
      "        \u03f0       ",
      "         \u03ef      ",
      "          allll ",
      "          Ib  a ",
      "          I\u03ee  a ",
      "          Ib  l ",
      "          Ib  a ",
      "          Ib  a ",
      "          Ib  \u037f ",
      "          Ib  \u037f ",
      "          laaa\u037f ",
      "                "
    ],
    [
      "                ",
      "                ",
      "                ",
      "                ",
      "                ",
      "                ",
      "          \u03f1lal\u039d ",
      "          l\u0399\u0399\u0399a ",
      "          a\u0399\u0399\u0399l ",
      "          a\u0399\u0399\u0399a ",
      "          l\u0399\u0399\u0399a ",
      "          a\u0399\u0399\u0399a ",
      "          l\u0399\u0399\u0399a ",
      "          a\u0399\u0399\u0399a ",
      "          aaaal ",
      "                "
    ],
    [
      "                ",
      "                ",
      "                ",
      "                ",
      "                ",
      "                ",
      "            &&  ",
      "          &   & ",
      "          &   * ",
      "          *   * ",
      "          *   & ",
      "          *   * ",
      "          *   * ",
      "          &   * ",
      "          *&*&  ",
      "                "
    ]
  ]
}