{
  "name": "building_apartmentsmallcbroken_ground_90",
  "refpalette": "deceasedcraft:building_apartmentsmallcbroken/building_apartmentsmallcbroken_ground_palette_90",
  "xsize": 16,
  "zsize": 16,
  "slices": [
    [
      "aabaabaaaaaabaaa",
      "aeeeeeaabaaaaaba",
      "aefffaaaaabaaaab",
      "aeffggggggggggga",
      "beffihhhhhhhhhga",
      "ceffihhhhhhhhhgb",
      "beffihhhhhhhhhga",
      "aefffhhhhhhhhhgb",
      "beffihhhhhhhhhgc",
      "beeeiiiihhhhhhgc",
      "abbghhhhhhhhhhgc",
      "badghhhhhhhhhhgb",
      "abaghhhhhhhhhhga",
      "bddghhhhhhhhhhgc",
      "abcggggggggggggc",
      "acbabcbccbccbbab"
    ],
    [
      "                ",
      " eeeee          ",
      " equfD          ",
      "le  iiwwwNNwNw0 ",
      " npfiC  LL LL i ",
      " e tiB        i ",
      "ke  iAI       0 ",
      " n  y     SXX 3 ",
      " e  i     QWZ 2E",
      " neeiiii  RK  2 ",
      " l sxxx K QVV 2o",
      "j  r  F  MR   2 ",
      "          QUY 2 ",
      "   r      PT  2m",
      "  oiwiiwiiwNw01E",
      " m   mE J O  m  "
    ],
    [
      "                ",
      " e9%en          ",
      " e8$fD          ",
      " e  iiw22222220 ",
      " e7ti         i ",
      " e  i         i ",
      " 6  i         N ",
      " 5  &     [   2 ",
      " 4  i (   +   2 ",
      " nneiiii  +   2 ",
      "   i^^*   +   2 ",
      "   r      -   2 ",
      "          +   2 ",
      "   #      )     ",
      "   iNiiNiiw2N1] ",
      "                "
    ],
    [
      "                ",
      " {eeee          ",
      " {fffD          ",
      " {ftiiN222222 1 ",
      " e} i         i ",
      " e  i         i ",
      " e  i         w ",
      " e  |;    :   2 ",
      " e  i     -   2 ",
      " eneiiii  +   2 ",
      "   i^F    +   2 ",
      "   #          2 ",
      "   r            ",
      "   r          2 ",
      "   iwiiNisN2w1  ",
      "                "
    ],
    [
      "                ",
      " eeeee          ",
      " e  fD          ",
      " e  iiiiiiiiiii ",
      " e' i         i ",
      " n} i         i ",
      " e  i         i ",
      " 5  i         i ",
      " 6  i         s ",
      " 5eeiiii  3   i ",
      "   i          s ",
      "   s          i ",
      "   i          < ",
      "   i          s ",
      "   siisiiiisiis ",
      "                "
    ],
    [
      "                ",
      " e999e          ",
      " e  >           ",
      " e  iiiiiiiiiii ",
      " e  igggggggggi ",
      " e' igggggggggs ",
      " e} igggggggggi ",
      " e  igggggggggi ",
      " e  igggggggggi ",
      " eneiiiiggggggi ",
      "   iggggggggggs ",
      "   iggggggggggs ",
      "   sggggggggggs ",
      "   sggggggggggi ",
      "   Esiis,issosi ",
      "                "
    ]
  ]
}