{
  "name": "building_apartmentsmallcbroken_ground_270",
  "refpalette": "deceasedcraft:building_apartmentsmallcbroken/building_apartmentsmallcbroken_ground_palette_270",
  "xsize": 16,
  "zsize": 16,
  "slices": [
    [
      "babbccbccbcbabca",
      "cggggggggggggcba",
      "cghhhhhhhhhhgddb",
      "aghhhhhhhhhhgaba",
      "bghhhhhhhhhhgdab",
      "cghhhhhhhhhhgbba",
      "cghhhhhhiiiieeeb",
      "cghhhhhhhhhiffeb",
      "bghhhhhhhhhfffea",
      "aghhhhhhhhhiffeb",
      "bghhhhhhhhhiffec",
      "aghhhhhhhhhiffeb",
      "agggggggggggffea",
      "baaaabaaaaafffea",
      "abaaaaabaaeeeeea",
      "aaabaaaaaabaabaa"
    ],
    [
      "  m  O J Em   m ",
      "E10wNwiiwiiwio  ",
      "m2  TP      r   ",
      " 2 YUQ          ",
      " 2   RM  F  r  j",
      "o2 VVQ K xxxs l ",
      " 2  KR  iiiieen ",
      "E2 ZWQ     i  e ",
      " 3 XXS     y  n ",
      " 0       IAi  ek",
      " i        Bit e ",
      " i LL LL  Cifpn ",
      " 0wNwNNwwwii  el",
      "          Dfuqe ",
      "          eeeee ",
      "                "
    ],
    [
      "                ",
      " ]1N2wiiNiiNi   ",
      "     )      #   ",
      " 2   +          ",
      " 2   -      r   ",
      " 2   +   *^^i   ",
      " 2   +  iiiienn ",
      " 2   +   ( i  4 ",
      " 2   [     &  5 ",
      " N         i  6 ",
      " i         i  e ",
      " i         it7e ",
      " 02222222wii  e ",
      "          Df$8e ",
      "          ne%9e ",
      "                "
    ],
    [
      "                ",
      "  1w2NsiNiiwi   ",
      " 2          r   ",
      "            r   ",
      " 2          #   ",
      " 2   +    F^i   ",
      " 2   +  iiiiene ",
      " 2   -     i  e ",
      " 2   :    ;|  e ",
      " w         i  e ",
      " i         i  e ",
      " i         i }e ",
      " 1 222222Niitf{ ",
      "          Dfff{ ",
      "          eeee{ ",
      "                "
    ],
    [
      "                ",
      " siisiiiisiis   ",
      " s          i   ",
      " <          i   ",
      " i          s   ",
      " s          i   ",
      " i   3  iiiiee5 ",
      " s         i  6 ",
      " i         i  5 ",
      " i         i  e ",
      " i         i }n ",
      " i         i 'e ",
      " iiiiiiiiiii  e ",
      "          Df  e ",
      "          eeeee ",
      "                "
    ],
    [
      "                ",
      " isossi,siisE   ",
      " iggggggggggs   ",
      " sggggggggggs   ",
      " sggggggggggi   ",
      " sggggggggggi   ",
      " iggggggiiiiene ",
      " igggggggggi  e ",
      " igggggggggi  e ",
      " igggggggggi }e ",
      " sgggggggggi 'e ",
      " igggggggggi  e ",
      " iiiiiiiiiii  e ",
      "           >  e ",
      "          e999e ",
      "                "
    ]
  ]
}