{
  "name": "building_apartmentsmallcbroken_top_90",
  "refpalette": "deceasedcraft:building_apartmentsmallcbroken/building_apartmentsmallcbroken_top_palette_90",
  "xsize": 16,
  "zsize": 16,
  "slices": [
    [
      "                ",
      " aaaaa          ",
      " a  j           ",
      " a  iiddddddddd ",
      " a  igggggggkkd ",
      " a figgggggkkkd ",
      " acbigggggggggd ",
      " abbbggggggkkke ",
      " abbigggggkkkkd ",
      " aaagggggggkgge ",
      "   dggggggggggd ",
      "   dhggggggggge ",
      "   eggghggghghd ",
      "   eghhghggghhe ",
      "   dedeeddedeed ",
      "                "
    ],
    [
      "                ",
      " laaaa          ",
      " n  bI          ",
      " n  iiiiiiiiiii ",
      " n fiF TZZTi58i ",
      " m riEP YY 69 i ",
      " a  iiO    iiii ",
      " a  y Nqiqi58 i ",
      " a  iDMS  2   i ",
      " laaxCLR iq2iiq ",
      "   iw DQ 0   %q ",
      "   quBK Xi1 7$i ",
      "   qtAKAWqE4  q ",
      "   ps K ViV3P#^ ",
      "   oiqJqUqiiJqq ",
      "                "
    ],
    [
      "                ",
      " an+al          ",
      " a  bI          ",
      " l fii<(``(``(\u037e ",
      " a ri: ,  \u0375i\u0376 i ",
      " a  i;     \u0377 \u037bi ",
      " *  ii'>   iii- ",
      " *  }| qiii\u0376 \u037a( ",
      " & )i     \u0374   \u037d ",
      " aaa{   /ii\u0374qi\u037c ",
      "   i]    \u0371\u0373  \u0375( ",
      "   (    ?i    \u037d ",
      "   (    .q\u0372   \u037c ",
      "    [    o      ",
      "   q-( (<\u0370q( o- ",
      "                "
    ],
    [
      "                ",
      " \u037faala          ",
      " \u037fbbbI          ",
      " \u037fbrii<(``(``(- ",
      " a\u0384 i      i\u038a i ",
      " a  i      \u0388 \u038fi ",
      " a  ii`    iii- ",
      " a  \u0386  iqii\u038a \u038e( ",
      " a  i !   \u0388   \u037d ",
      " ala     qi\u0389ii\u037d ",
      "   i     \u037d    ( ",
      "   \u0386     q    \u037c ",
      "   \u0386     i      ",
      "   \u0386     \u0387      ",
      "   \u0385-  (     \u038c\u0390 ",
      "                "
    ],
    [
      "                ",
      " aaaaa          ",
      " a  bI          ",
      " a  iiiiiiiiiii ",
      " ac i      i  i ",
      " a\u0384 i    \u0395 i  i ",
      " a  iiii   iiiq ",
      " *  i\u0393 iiiq   i ",
      " *  i \u0394\u0393  i   q ",
      " &\u0391a  \u0393  iiiiqo ",
      "   i     q    q ",
      "   i     q    \u0396 ",
      "   q     \u0385 \u0394    ",
      "   o            ",
      "   q\u0392           ",
      "                "
    ],
    [
      "                ",
      " ammma          ",
      " a  j           ",
      " a  iiiiiiiiiii ",
      " a  i\u0399\u0399\u0399\u0399\u0399\u0399\u0399\u0399\u0399i ",
      " lc i\u0399\u0399\u0399\u0399\u0399\u0399\u0399\u0399\u0399q ",
      " a\u0384 i\u0399\u0399\u0399\u0399\u0399\u0399\u0399\u0399\u0399i ",
      " a  i\u0399\u0399\u0399\u0399\u0399\u0399\u0399\u0399\u0399q ",
      " a  i\u039c\u0399\u0399\u0399\u0399\u0399\u0399\u0399\u0399\u0370 ",
      " \u0397la\u0399\u039c\u039a\u0399\u0399\u0399\u0399\u0399\u0399\u0399q ",
      "   i\u039a\u0399\u0399\u0399\u0399i\u0399\u0399\u0399\u0399\u0385 ",
      "   q\u0399\u039b \u0399\u0399i\u0399\u0399\u0399\u0398  ",
      "   i\u0399  \u0398 q\u0399\u0399    ",
      "   q\u0398     \u0398     ",
      "   \u0385            ",
      "                "
    ],
    [
      "                ",
      " aaaaa          ",
      " a  j           ",
      " a  iiddddddddd ",
      " a  igggggggkkd ",
      " a figgggggkkkd ",
      " acbigggggggggd ",
      " abbbggggggkkke ",
      " lbbigggggkkkke ",
      " \u039dalg\u03a0!ggggkgg  ",
      "   d\u039c\u039a\u039cghhgggg  ",
      "   \u039eh\u039bhggighgh  ",
      "   d\u039bhgh\u03a4qh\u03a4h\u03a6  ",
      "   \u039e\u039f \u03a1\u039f\u03a3\u03a5\u039f\u03a1\u039f\u039f  ",
      "          \u03a3     ",
      "                "
    ],
    [
      "                ",
      " aaaaa          ",
      " n  bI          ",
      " \u03a7  iiiiiiiiiii ",
      " n fiFPTZZTi58i ",
      " m riE  YY 2  i ",
      " a  iiV    iiiq ",
      " a  \u03aa Dqqii58 q ",
      " l  o  V  2   \u0385 ",
      " &la\u03a9\u03ab  #qi6qi\u0396 ",
      "   \u039c\u03a0\u03a8  \u0396    %  ",
      "   \u039b\u03a8 [[Xi1 7$  ",
      "   oB \u03ac WqE\u03ad V  ",
      "   U        \u03ae\u03af  ",
      "                ",
      "                "
    ],
    [
      "                ",
      " an+aa          ",
      " a  bI          ",
      " a fii<(``(`\u03b6(\u037e ",
      " a ri  \u0375  ,i\u0376 i ",
      " a  i\u03b2     \u0374\u03b5\u037bq ",
      " *  ii \u03b3   iii- ",
      " *  \u03b1\u0373 iqii\u0376 \u037a( ",
      " \u03b0  o     \u0374 \u03b5 \u037c ",
      " ala\u03a8    Ji\u0377ii  ",
      "   \u039a\u03ab           ",
      "   (     i      ",
      "   (    \u03b4U      ",
      "                ",
      "                ",
      "                "
    ],
    [
      "                ",
      " \u0391aala          ",
      " \u037fbbbI          ",
      " \u037fbrii<(``(``(\u037e ",
      " a\u0384 i      i\u038a i ",
      " a  i      \u0388 \u038fi ",
      " a  iq`    iii\u037e ",
      " a  \u0386  iiqi\u038a \u038e  ",
      " a  q     \u0388   \u037d ",
      " laa     ii\u03b7iq\u037c ",
      "   o     \u037d      ",
      "   \u0386     q      ",
      "   \u0386            ",
      "                ",
      "                ",
      "                "
    ],
    [
      "                ",
      " aaaaa          ",
      " a  bI          ",
      " a  iiiiiiiiiii ",
      " lc i      i  i ",
      " a\u0384 i    \u0395 i  i ",
      " a  iiii   iiii ",
      " *  q  qqii   i ",
      " &  i \u0394   q   q ",
      "  la     qiiqiq ",
      "   o     i    \u03b8 ",
      "   \u039a     q      ",
      "   q  \u0394  \u0385      ",
      "   \u03b8            ",
      "                ",
      "                "
    ],
    [
      "                ",
      " ammma          ",
      " a  j           ",
      " a  iiiiiiiiiii ",
      " a  i\u0399\u0399\u0399\u0399\u0399\u0399\u0399\u0399\u0399i ",
      " ac i\u0399\u0399\u0399\u0399\u0399\u0399\u0399\u0399\u0399i ",
      " a\u0384 i\u0399\u0399\u0399\u0399\u0399\u0399\u0399\u0399\u0399i ",
      " a  i\u0399\u0399\u0399\u0399\u0399\u0399\u0399\u0399\u0399q ",
      " a  i\u0399\u0399\u0399\u0399\u0399\u0399\u0399\u0399\u0399i ",
      " ala\u0399\u039a\u0399\u0399\u0399\u0399\u0399\u0399\u0399\u0399q ",
      "   i\u039a\u0399\u0399\u0399\u0399i\u0399\u0399\u0399\u0398\u0385 ",
      "   q \u0399\u0399\u039b\u0399i\u0399\u0399    ",
      "   \u03b9 \u0398\u039a\u0399 q \u0398    ",
      "      \u0398         ",
      "                ",
      "                "
    ],
    [
      "                ",
      " aaaaa          ",
      " a  j           ",
      " a  iiddddddddd ",
      " a  igggggggkkd ",
      " a figgggggkkkd ",
      " acbigggggggggd ",
      " abbbggggggkkkd ",
      " lbbigggggkkkk\u039e ",
      " allghgggggkgh  ",
      "   eghghgggghg  ",
      "   \u039eh\u039ag\u03a8hqhggh  ",
      "   eh\u039b\u03a8\u039f\u03a1qg\u03a4\u03a1\u039f  ",
      "    \u039f \u039f   \u039f\u03a3    ",
      "    \u03a3           ",
      "                "
    ],
    [
      "                ",
      " aaaaa          ",
      " n  bI          ",
      " n  iiiiiiiiiii ",
      " \u03a7 fiF TZZTi58i ",
      " a riEP YY 2  i ",
      " l  iiO    iiiq ",
      " a  \u03aa\u03bb iiii58 i ",
      " a  i DS  2 9 q ",
      " laaxADR qo6qio ",
      "   iw [ #\u03beV A%  ",
      "   quV\u03bc\u03bdXi   V  ",
      "   q\u03ba \u03bbQW\u03b8 A \u03bd  ",
      "   \u0385            ",
      "                ",
      "                "
    ],
    [
      "                ",
      " an+aa          ",
      " a  bI          ",
      " l fii<(``(``(- ",
      " a ri\u03c0 ,  \u0375i\u0376 i ",
      " a  i\u03bf     \u0374\u03b5\u037bi ",
      " *  ii'>   iii\u037e ",
      " *  \u03b1\u0373 iiii\u0376 \u037a( ",
      " \u03b0 )i     \u0374   \u037c ",
      " aaa{  \u03c1 ^i\u0377iq\u037c ",
      "   q     \u03c2|  ,  ",
      "   (     i      ",
      "   (    .\u0385      ",
      "                ",
      "                ",
      "                "
    ],
    [
      "                ",
      " \u037faaaa          ",
      " \u037fbbbI          ",
      " \u037fbrii<(``(\u03b6`(\u0390 ",
      " l\u0384 i      i\u038a i ",
      " l  i      \u0388 \u038fi ",
      " a  ii`    iii\u037e ",
      " a  \u0386  iiii\u038a \u038e( ",
      " l  i     \u0388   \u037c ",
      " ala\u03c3    \u0389q\u03b7i\u0392  ",
      "   i     \u037d      ",
      "   \u0386     q      ",
      "   \u0386            ",
      "                ",
      "                ",
      "                "
    ],
    [
      "                ",
      " aaaaa          ",
      " a  bI          ",
      " a  iiiiiiiiiii ",
      " lc i      i  i ",
      " a\u0384 i    \u0395 i  i ",
      " l  iiii   iiiq ",
      " *  i  iiii   i ",
      " *  q \u03c4   i   q ",
      " *aa     iiiqi\u03b9 ",
      "   i     i      ",
      "   o     q      ",
      "   q            ",
      "                ",
      "                ",
      "                "
    ],
    [
      "                ",
      " lmmma          ",
      " a  j           ",
      " l  iiiiiiiiiiq ",
      " a  i\u0399\u0399\u0399\u0399\u0399\u0399\u0399\u0399\u0399i ",
      " ac i\u0399\u0399\u0399\u0399\u0399\u0399\u0399\u0399\u0399i ",
      " a\u0384 i\u0399\u0399\u0399\u0399\u0399\u0399\u0399\u0399\u0399i ",
      " a  i\u0399\u0399\u0399\u0399\u0399\u0399\u0399\u0399\u0399q ",
      " a  i\u0399\u0399\u0399\u0399\u0399\u0399\u0399\u0399\u0399o ",
      " \u0397la\u0399\u0399\u0399\u0399\u0398q\u0399\u0399\u0399\u0399q ",
      "   q\u0399\u0399\u0399  i\u0399\u0399\u0399\u0399U ",
      "   q\u0399\u0399\u0399\u0398 \u0385\u0399\u0399\u0398\u0399  ",
      "   \u03a5\u0398\u0399    \u0398     ",
      "                ",
      "                ",
      "                "
    ],
    [
      "                ",
      " alaaa          ",
      " a  j           ",
      " a  iiddddddddd ",
      " a  igggggggkkd ",
      " l figgggggkkkd ",
      " acbigggggggggd ",
      " lbbbggggggkkke ",
      " abbigggggkkkke ",
      " allgghggggkgg\u039e ",
      "   \u039e\u03c5hgghggh\u039ah  ",
      "   eg\u03a4\u03a1\u03c6hq\u03a4\u039b\u03a9\u03a1  ",
      "   e\u039f\u03a3 \u03a1\u039f \u039f\u039f    ",
      "                ",
      "                ",
      "                "
    ],
    [
      "                ",
      " aaaaa          ",
      " n  bI          ",
      " n  iiiiiiiiiii ",
      " n fi\u03cb\u03ce\u03d0 \u03d3\u03d6i58i ",
      " a ri\u03ca\u03ce\u03d03  6 Qi ",
      " a  ii\u03cd\u03cf\u0375\u03d2\u03d5iiiq ",
      " a  \u03aa Viqqo5\u03d7~i ",
      " l  o\u0372 S    ~ o ",
      " \u03c7aa\u039aD R iq\u0385oiq ",
      "   q\u03c9 D  VAB \u03a9q ",
      "   o\u03c8 \u03cc \u03d1\u03b8\u03d4 [V\u039e ",
      "   \u0396   #        ",
      "                ",
      "                ",
      "                "
    ],
    [
      "                ",
      " an+aa          ",
      " a  bI          ",
      " a fii<(``(`\u03b6(- ",
      " a ri    \u03d9 i\u0376 i ",
      " l  iP     \u0377\u03db\u037bi ",
      " *  ii\u03ca    iii\u037e ",
      " &  \u03b1\u0373 qiiq\u0376 \u037a( ",
      " \u03d8  q         \u037d ",
      " ala\u039a   /i\u03da \u0396q\u037c ",
      "   i          ( ",
      "   (          \u037c ",
      "                ",
      "                ",
      "                ",
      "                "
    ],
    [
      "                ",
      " &aaal          ",
      " \u037fbbbI          ",
      " \u037fbrii<(`` ``(\u037e ",
      " a\u0384 i      i\u038a i ",
      " a  i      \u0388 \u038fi ",
      " l  ii`    iii- ",
      " a  \u0386  iiqi\u038a \u038e( ",
      " a  i     \u03dc   \u037c ",
      " lla     qq  i\u037d ",
      "   o          ( ",
      "   \u0386            ",
      "                ",
      "                ",
      "                ",
      "                "
    ],
    [
      "                ",
      " aaaaa          ",
      " a  bI          ",
      " a  iiiiiiiiiii ",
      " lc i      i  i ",
      " a\u0384 i    \u0395 i  i ",
      " a  iiii   iiii ",
      " &  i  iqii   i ",
      " *  q \u03dd   q   i ",
      " *la     qq\u03dcoqq ",
      "   q     \u03b9    i ",
      "   \u03b9     \u039e    \u03b9 ",
      "                ",
      "                ",
      "                ",
      "                "
    ],
    [
      "                ",
      " lmmma          ",
      " a  j           ",
      " a  iiiiiiiiiii ",
      " l  i\u0399\u0399\u0399\u0399\u0399\u0399\u0399\u0399\u0399i ",
      " lc i\u0399\u0399\u0399\u0399\u0399\u0399\u0399\u0399\u0399q ",
      " a\u0384 i\u0399\u0399\u0399\u0399\u0399\u0399\u0399\u0399\u0399i ",
      " a  i\u0399\u0399\u0399\u0399\u0399\u0399\u0399\u0399\u0399i ",
      " \u03de  i\u0399\u0399\u0399\u0399\u0399\u0399\u0399\u0399\u0399q ",
      " all\u0399\u0399\u0399\u0399\u0399i\u0399\u0399\u0399\u0399q ",
      "   q\u0399\u0399\u0399\u0399\u0399i\u0399 \u0398\u0398\u0370 ",
      "   q\u0398\u0399 \u0398\u0399q   \u0398q ",
      "              \u0385 ",
      "                ",
      "                ",
      "                "
    ],
    [
      "                ",
      " aaaaa          ",
      " l  j           ",
      " a  iiddddddddd ",
      " a  i\u0399\u0399\u0399\u0399\u0399\u0399\u0399\u0399\u0399d ",
      " a  i\u0399\u0399\u0399\u0399\u0399\u0399\u03d4\u0399\u0399d ",
      " lc\u03dfi\u0399\u0399\u0399\u0399\u0399\u0399\u0399\u0399\u0399e ",
      " abbb\u0399\u0399\u0399\u0399\u0399\u0399\u0399\u0399\u0399d ",
      " abbb\u0399\u0399\u0399\u0399\u0399\u0399\u0399\u03d4\u0399e ",
      " lalbb\u0399\u0399\u0399\u0399\u0399\u0399\u0399\u0399e ",
      "   \u039e\u0399\u0399\u0399\u0399\u0399\u0399\u039f\u039f \u0399\u039e ",
      "    \u039f \u03a3\u039f  \u039f\u03d4 \u039fe ",
      "       \u03a3        ",
      "                ",
      "                ",
      "                "
    ],
    [
      "                ",
      " aaala          ",
      " n  bI          ",
      " n  biiiiiiiiqi ",
      " n  b\u03e1\u03e1\u03e1\u03e1\u03e1 \u03e1\u03e1\u03e1i ",
      " a  bI  \u03e6\u03e6 \u03d4\u0393\u03e1i ",
      " a \u03e0bI \u0393\u03e5\u03e6\u0393\u03d4 \u03e1i ",
      " a  \u03e2      \u03d4 \u03e1q ",
      " l  bI     \u03d4\u03d4\u03e1i ",
      " alala     \u03d4 \u03e1o ",
      "   q\u03e1\u03e3\u03a9\u039a   \u03d4 \u03e1q ",
      "   \u03b9   \u03cc\u03e4  \u03d4  \u0396 ",
      "                ",
      "                ",
      "                ",
      "                "
    ],
    [
      "                ",
      " ln+a\u03e8          ",
      " a  bI          ",
      " l  bI          ",
      " a  b\u03e1\u03e1 \u03e1\u03e1\u03e1\u03e1\u03e1\u03e1  ",
      " a  bI  \u03e5\u03ed   \u03e1  ",
      " *  bI       \u03e1  ",
      " *  \u03e7           ",
      " \u03b0  bI       \u03e1  ",
      " lllal \u03ec     \u03e1  ",
      "    \u03e1 \u03e9\u03eb\u03e4    \u03e1  ",
      "    \u03e1  \u03ea     \u03e1  ",
      "                ",
      "                ",
      "                ",
      "                "
    ],
    [
      "                ",
      " \u037faaal          ",
      " \u037f  bI          ",
      " \u037f  bI          ",
      " a  bI          ",
      " a  bI          ",
      " l  bI          ",
      " a  \u03eeI          ",
      " a  bI          ",
      " lllla          ",
      "      \u03ef         ",
      "       \u03f0        ",
      "                ",
      "                ",
      "                ",
      "                "
    ],
    [
      "                ",
      " laaaa          ",
      " a\u0399\u0399\u0399a          ",
      " a\u0399\u0399\u0399l          ",
      " a\u0399\u0399\u0399a          ",
      " a\u0399\u0399\u0399l          ",
      " a\u0399\u0399\u0399a          ",
      " l\u0399\u0399\u0399a          ",
      " a\u0399\u0399\u0399l          ",
      " \u039dlal\u03f1          ",
      "                ",
      "                ",
      "                ",
      "                ",
      "                ",
      "                "
    ],
    [
      "                ",
      "  &*&*          ",
      " *   &          ",
      " *   *          ",
      " *   *          ",
      " &   *          ",
      " *   *          ",
      " *   &          ",
      " &   &          ",
      "  &&            ",
      "                ",
      "                ",
      "                ",
      "                ",
      "                ",
      "                "
    ]
  ]
}