{
  "name": "building_apartmentsmallcbroken_ground",
  "refpalette": "deceasedcraft:building_apartmentsmallcbroken/building_apartmentsmallcbroken_ground_palette",
  "xsize": 16,
  "zsize": 16,
  "slices": [
    [
      "aabababbabcbaaaa",
      "cbdbabeeeeeeeeea",
      "bcdadbefffffffeb",
      "agggggefffffffea",
      "bghhhhiifiiigfea",
      "cghhhhihhhhhgaeb",
      "bghhhhihhhhhgaaa",
      "cghhhhihhhhhgaaa",
      "cghhhhhhhhhhgaba",
      "bghhhhhhhhhhgaaa",
      "cghhhhhhhhhhgbaa",
      "cghhhhhhhhhhgaaa",
      "bghhhhhhhhhhgaab",
      "bghhhhhhhhhhgaaa",
      "aggggggggggggaba",
      "bccabcccbabaabaa"
    ],
    [
      "    j    k  l   ",
      "m    lneneeneee ",
      " o    e    p qe ",
      " ir rse   tf ue ",
      " w   xiiyiiiife ",
      "mi   xi  ABCiDe ",
      "Ei  Fxi  I  w   ",
      " w    i     w   ",
      "Ji   K     Lw   ",
      " i  M      LN   ",
      "OwPQRQRQS   N   ",
      " NTU VKWX  Lw   ",
      " w Y V ZX  LN   ",
      "m0          w   ",
      " 122222230ii0   ",
      " Em  o E        "
    ],
    [
      "                ",
      "      n456eeeee ",
      "      n    7 89 ",
      " i# rie    t $% ",
      " N   ^ii&iiiife ",
      " i   ^i     iDn ",
      " i   *i(    w   ",
      " N    i     2   ",
      " i          2   ",
      " i          2   ",
      " w)+-+++[   2   ",
      " 2          2   ",
      " N          2   ",
      " 1          2   ",
      " ] 222222Nii0   ",
      "                "
    ],
    [
      "                ",
      "      eeeeee{{{ ",
      "      n    }ffe ",
      " irr#ie     tfe ",
      " w   ^ii|iiiife ",
      " i   Fi ;   iDe ",
      " i    i     N   ",
      " N    i     2   ",
      " i          2   ",
      " s          2   ",
      " N   ++-:   2   ",
      " 2          2   ",
      " w          2   ",
      " 1              ",
      "  2 22222wii1   ",
      "                "
    ],
    [
      "                ",
      "      565eneeee ",
      "      e   }'  e ",
      " siisie       e ",
      " i    iiiiiiife ",
      " i    i     iDe ",
      " s    i     i   ",
      " i    i     i   ",
      " i          i   ",
      " i          i   ",
      " i    3     i   ",
      " s          i   ",
      " i          i   ",
      " i          i   ",
      " ss<isisiiiii   ",
      "                "
    ],
    [
      "                ",
      "      eeeeeeeee ",
      "      n  }'   9 ",
      " Essiie       9 ",
      " sggggiiiiiii>9 ",
      " iggggigggggi e ",
      " iggggigggggi   ",
      " sggggigggggi   ",
      " ,ggggggggggi   ",
      " iggggggggggi   ",
      " sggggggggggi   ",
      " sggggggggggi   ",
      " oggggggggggi   ",
      " sggggggggggi   ",
      " iisssiiiisii   ",
      "                "
    ]
  ]
}