{
  "name": "multi_verticalschool_17_floor29",
  "refpalette": "deceasedcraft:multi_verticalschool_17/multi_verticalschool_17_floor29_palette",
  "xsize": 16,
  "zsize": 16,
  "slices": [
    [
      "aabc            ",
      "aabc            ",
      "aabc            ",
      "aabc            ",
      "aabc            ",
      "aabc            ",
      "aabc            ",
      "aabc            ",
      "aabc            ",
      "aabc            ",
      "aabc            ",
      "aabc            ",
      "aabc            ",
      "aabc            ",
      "aabc            ",
      "aabc            "
    ],
    [
      "debf            ",
      "d bf            ",
      "gebf            ",
      "debf            ",
      "debf            ",
      "dhbf            ",
      "debf            ",
      "d bf            ",
      "debf            ",
      "debf            ",
      "d bf            ",
      "debf            ",
      "debf            ",
      "dhbf            ",
      "dhbf            ",
      "debf            "
    ],
    [
      "i j             ",
      "  j             ",
      "  j             ",
      "i j             ",
      "i j             ",
      "i j             ",
      "i j             ",
      "i j             ",
      "i j             ",
      "i j             ",
      "  j             ",
      "  j             ",
      "i j             ",
      "i j             ",
      "  j             ",
      "i j             "
    ],
    [
      "  j             ",
      "  j             ",
      "  j             ",
      "  j             ",
      "  j             ",
      "  j             ",
      "  j             ",
      "  j             ",
      "  j             ",
      "  j             ",
      "  j             ",
      "  j             ",
      "  j             ",
      "  j             ",
      "  j             ",
      "  j             "
    ],
    [
      "  j             ",
      "  j             ",
      "  j             ",
      "  j             ",
      "  j             ",
      "  j             ",
      "  j             ",
      "  j             ",
      "  j             ",
      "  j             ",
      "  j             ",
      "  j             ",
      "  j             ",
      "  j             ",
      "  j             ",
      "  j             "
    ],
    [
      "kkjl            ",
      "kkjl            ",
      "kkjl            ",
      "kkjl            ",
      "kkjl            ",
      "kkjl            ",
      "kkjl            ",
      "kkjl            ",
      "kkjl            ",
      "kkjl            ",
      "kkjl            ",
      "kkjl            ",
      "kkjl            ",
      "kkjl            ",
      "kkjl            ",
      "kkjl            "
    ]
  ]
}