{
  "name": "multi_verticalschool_17_floor26",
  "refpalette": "deceasedcraft:multi_verticalschool_17/multi_verticalschool_17_floor26_palette",
  "xsize": 16,
  "zsize": 16,
  "slices": [
    [
      "aabc            ",
      "aabc            ",
      "aabc            ",
      "aabc            ",
      "aabc            ",
      "aabc            ",
      "aabc            ",
      "aabc            ",
      "aabc            ",
      "aabc            ",
      "aabc            ",
      "aabc            ",
      "aabc            ",
      "aabc            ",
      "aabc            ",
      "aabc            "
    ],
    [
      "debf            ",
      "debf            ",
      "debf            ",
      "debf            ",
      "debf            ",
      "dgbf            ",
      "dgbf            ",
      "debf            ",
      "debf            ",
      "debf            ",
      "debf            ",
      "dgbf            ",
      "hebf            ",
      "debf            ",
      "debf            ",
      "d bf            "
    ],
    [
      "i j             ",
      "i j             ",
      "i j             ",
      "i j             ",
      "i j             ",
      "i j             ",
      "i j             ",
      "i j             ",
      "i j             ",
      "i j             ",
      "i j             ",
      "  j             ",
      "  j             ",
      "i j             ",
      "i j             ",
      "i j             "
    ],
    [
      "  j             ",
      "  j             ",
      "  j             ",
      "  j             ",
      "  j             ",
      "  j             ",
      "  j             ",
      "  j             ",
      "  j             ",
      "  j             ",
      "  j             ",
      "  j             ",
      "  j             ",
      "  j             ",
      "  j             ",
      "  j             "
    ],
    [
      "  j             ",
      "  j             ",
      "  j             ",
      "  j             ",
      "  j             ",
      "  j             ",
      "  j             ",
      "  j             ",
      "  j             ",
      "  j             ",
      "  j             ",
      "  j             ",
      "  j             ",
      "  j             ",
      "  j             ",
      "  j             "
    ],
    [
      "kkjl            ",
      "kkjl            ",
      "kkjl            ",
      "kkjl            ",
      "kkjl            ",
      "kkjl            ",
      "kkjl            ",
      "kkjl            ",
      "kkjl            ",
      "kkjl            ",
      "kkjl            ",
      "kkjl            ",
      "kkjl            ",
      "kkjl            ",
      "kkjl            ",
      "kkjl            "
    ]
  ]
}