{
  "name": "multi_verticalschool_17_floor7",
  "refpalette": "deceasedcraft:multi_verticalschool_17/multi_verticalschool_17_floor7_palette",
  "xsize": 16,
  "zsize": 16,
  "slices": [
    [
      "                ",
      "                ",
      "                ",
      "                ",
      "                ",
      "                ",
      "                ",
      "                ",
      "                ",
      "                ",
      "                ",
      "                ",
      "                ",
      "                ",
      "                ",
      "                "
    ],
    [
      "                ",
      "                ",
      "                ",
      "                ",
      "                ",
      "                ",
      "                ",
      "                ",
      "                ",
      "                ",
      "                ",
      "                ",
      "                ",
      "                ",
      "                ",
      "                "
    ],
    [
      "aaaaaaba c      ",
      "aaaaaaba c      ",
      "aaaaaaba c      ",
      "aaaaaaba c      ",
      "aaaaaaba c      ",
      "aaaaaaba c      ",
      "aaaaaaba c      ",
      "aaaaaaba c      ",
      "aaaaaaba c      ",
      "aaaaaaba c      ",
      "aaaaaaba c      ",
      "aaaaaaba c      ",
      "aaaaaaba c      ",
      "aaaaaaba c      ",
      "aaaaaaba c      ",
      "aaaaaaba c      "
    ],
    [
      "ddddddddefg     ",
      "ddddddddefg     ",
      "ddddddddefg     ",
      "ddddddddefg     ",
      "ddddddddefg     ",
      "ddddddddefg     ",
      "hhhhhhhhefg     ",
      "eeeeeeeeefg     ",
      "eeeeeeeeefg     ",
      "eeeeeeieefg     ",
      "eeeeeeieefg     ",
      "eeeeeeieefg     ",
      "eeeeeeieefg     ",
      "eeeeeeeeefg     ",
      "eeeeeeeeefg     ",
      "eeeeeeeeefg     "
    ],
    [
      "         fg     ",
      "         fg     ",
      "         fg     ",
      "         fg     ",
      "         fg     ",
      "         fg     ",
      "hhhjkhhhhfg     ",
      "lm    nopfg     ",
      "lm      qfg     ",
      "lm    r sfg     ",
      "t     r ufg     ",
      "wx    r ufg     ",
      "w     r yfg     ",
      "A       qfg     ",
      "B       Cfg     ",
      "B       Cfg     "
    ],
    [
      "         Dg     ",
      "         Dg     ",
      "         Dg     ",
      "         Dg     ",
      "         fg     ",
      "  E  E   fg     ",
      "hhhFIhhhhfg     ",
      "        Jfg     ",
      "         fg     ",
      "         Dg     ",
      "K        Dg     ",
      "L        Dg     ",
      "M        Dg     ",
      "        Nfg     ",
      "O        fg     ",
      "P        fg     "
    ]
  ]
}