{
  "name": "multi_verticalschool_17_floor21",
  "refpalette": "deceasedcraft:multi_verticalschool_17/multi_verticalschool_17_floor21_palette",
  "xsize": 16,
  "zsize": 16,
  "slices": [
    [
      " ab             ",
      "  b             ",
      "  b             ",
      " ab             ",
      "  b             ",
      "  b             ",
      " ab             ",
      "  b             ",
      "  b             ",
      "  b             ",
      "  b             ",
      "  b             ",
      "  b             ",
      "  b             ",
      "  b             ",
      " ab             "
    ],
    [
      "  b             ",
      "  b             ",
      "  b             ",
      "  b             ",
      "  b             ",
      "  b             ",
      "  b             ",
      "  b             ",
      "  b             ",
      "  b             ",
      "  b             ",
      "  b             ",
      "  b             ",
      "  b             ",
      "  b             ",
      "  b             "
    ],
    [
      "ccbd            ",
      "ccbd            ",
      "ccbd            ",
      "ccbd            ",
      "ccbd            ",
      "ccbd            ",
      "ccbd            ",
      "ccbd            ",
      "ccbd            ",
      "ccbd            ",
      "ccbd            ",
      "ccbd            ",
      "ccbd            ",
      "ccbd            ",
      "ccbd            ",
      "ccbd            "
    ],
    [
      "eefg            ",
      "eefg            ",
      "eefg            ",
      "eefg            ",
      "eefg            ",
      "eefg            ",
      "eefg            ",
      "eefg            ",
      "eefg            ",
      "eefg            ",
      "eefg            ",
      "eefg            ",
      "eefg            ",
      "eefg            ",
      "eefg            ",
      "eefg            "
    ],
    [
      "ggfh            ",
      "ggfh            ",
      "ggfh            ",
      "ggfh            ",
      "ggfh            ",
      "ggfh            ",
      "ggfh            ",
      "ggfh            ",
      "ggfh            ",
      "ggfh            ",
      "ggfh            ",
      "ggfh            ",
      "ggfh            ",
      "ggfh            ",
      "ggfh            ",
      "ggfh            "
    ],
    [
      "                ",
      "                ",
      "                ",
      "                ",
      "                ",
      "                ",
      "                ",
      "                ",
      "                ",
      "                ",
      "                ",
      "                ",
      "                ",
      "                ",
      "                ",
      "                "
    ]
  ]
}