{
  "name": "multi_verticalschool_17_floor17",
  "refpalette": "deceasedcraft:multi_verticalschool_17/multi_verticalschool_17_floor17_palette",
  "xsize": 16,
  "zsize": 16,
  "slices": [
    [
      "                ",
      "                ",
      "                ",
      "                ",
      "                ",
      "                ",
      "                ",
      "                ",
      "                ",
      "                ",
      "                ",
      "                ",
      "                ",
      "                ",
      "                ",
      "                "
    ],
    [
      "                ",
      "                ",
      "                ",
      "                ",
      "                ",
      "                ",
      "                ",
      "                ",
      "                ",
      "                ",
      "                ",
      "                ",
      "                ",
      "                ",
      "                ",
      "                "
    ],
    [
      "ab c            ",
      "ab c            ",
      "ab c            ",
      "ab c            ",
      "ab c            ",
      "ab c            ",
      "ab c            ",
      "ab c            ",
      "ab c            ",
      "ab c            ",
      "ab c            ",
      "ab c            ",
      "ab c            ",
      "ab c            ",
      "ab c            ",
      "ab c            "
    ],
    [
      "ddef            ",
      "ddef            ",
      "ddef            ",
      "ddef            ",
      "ddef            ",
      "ddef            ",
      "ddef            ",
      "ddef            ",
      "ddef            ",
      "ddef            ",
      "ddef            ",
      "ddef            ",
      "ddef            ",
      "ddef            ",
      "ddef            ",
      "ddef            "
    ],
    [
      "ghei            ",
      "jkei            ",
      "jkei            ",
      "jhei            ",
      "jkei            ",
      "jkei            ",
      "jhei            ",
      "jkei            ",
      "jkei            ",
      "ghei            ",
      "jkei            ",
      "jkei            ",
      "jhei            ",
      "jkei            ",
      "jkei            ",
      "jhei            "
    ],
    [
      "  l             ",
      "                ",
      "  m             ",
      " nm             ",
      "  m             ",
      "  m             ",
      " nm             ",
      "  m             ",
      "  m             ",
      " nm             ",
      "  m             ",
      "  m             ",
      " nm             ",
      "  m             ",
      "  m             ",
      " nm             "
    ]
  ]
}