{
  "name": "multi_verticalschool_17_floor22",
  "refpalette": "deceasedcraft:multi_verticalschool_17/multi_verticalschool_17_floor22_palette",
  "xsize": 16,
  "zsize": 16,
  "slices": [
    [
      "                ",
      "                ",
      "                ",
      "                ",
      "                ",
      "                ",
      "                ",
      "                ",
      "                ",
      "                ",
      "                ",
      "                ",
      "                ",
      "                ",
      "                ",
      "                "
    ],
    [
      "abaac           ",
      "abaac           ",
      "abaac           ",
      "abaac           ",
      "abaac           ",
      "abaac           ",
      "abaac           ",
      "abaac           ",
      "abaac           ",
      "abaac           ",
      "abaac           ",
      "abaac           ",
      "abaac           ",
      "abaac           ",
      "abaac           ",
      "abaac           "
    ],
    [
      "dddde           ",
      "dddde           ",
      "dddde           ",
      "dddde           ",
      "dddde           ",
      "dddde           ",
      "dddde           ",
      "dddde           ",
      "dddde           ",
      "dddde           ",
      "dddde           ",
      "dddde           ",
      "dddde           ",
      "dddde           ",
      "dddde           ",
      "dddde           "
    ],
    [
      "   fe           ",
      "   ge           ",
      "   ge           ",
      "   ge           ",
      "   ge           ",
      "   ge           ",
      "   ge           ",
      "   ge           ",
      "   ge           ",
      "   ge           ",
      "   ge           ",
      "   ge           ",
      "   ge           ",
      "   ge           ",
      "   ge           ",
      "   fe           "
    ],
    [
      "   he           ",
      "   ge           ",
      "   ge           ",
      "   ge           ",
      "   ge           ",
      "   ge           ",
      "   ge           ",
      "   ge           ",
      "   ge           ",
      "   ge           ",
      "   ge           ",
      "   ge           ",
      "   ge           ",
      "   ge           ",
      "   ge           ",
      "   !e           "
    ],
    [
      "   ie           ",
      "   ge           ",
      "   ge           ",
      "   ge           ",
      "   ge           ",
      "   ge           ",
      "   ge           ",
      "   ge           ",
      "   ge           ",
      "   ge           ",
      "   ge           ",
      "   ge           ",
      "   ge           ",
      "   ge           ",
      "   ge           ",
      "   je           "
    ]
  ]
}