{
  "name": "multi_verticalschool_17_floor3",
  "refpalette": "deceasedcraft:multi_verticalschool_17/multi_verticalschool_17_floor3_palette",
  "xsize": 16,
  "zsize": 16,
  "slices": [
    [
      "  a             ",
      "  a             ",
      "  a             ",
      "  a             ",
      "  a             ",
      "  a             ",
      "  a             ",
      "  a             ",
      "  a             ",
      "  a             ",
      "  a             ",
      "  a             ",
      "  a             ",
      "  a             ",
      "  a             ",
      " a              "
    ],
    [
      "  a             ",
      "  a             ",
      "  a             ",
      "  a             ",
      "  a             ",
      "  a             ",
      "  a             ",
      "  a             ",
      "  a             ",
      "  a             ",
      "  a             ",
      "  a             ",
      "  a             ",
      "  a             ",
      "  a             ",
      " a              "
    ],
    [
      "  a             ",
      "  a             ",
      "  a             ",
      "  a             ",
      "  a             ",
      "  a             ",
      "  a             ",
      "  a             ",
      "  a             ",
      "  a             ",
      "  a             ",
      "  a             ",
      "  a             ",
      "  a             ",
      "  a             ",
      " a              "
    ],
    [
      "  ab            ",
      "  ab            ",
      "  ab            ",
      "  ab            ",
      "  ab            ",
      "  ab            ",
      "  ab            ",
      "  ab            ",
      "  ab            ",
      "  ab            ",
      "  ab            ",
      "  ab            ",
      "  ab            ",
      "  ab            ",
      "  ab            ",
      " a b            "
    ],
    [
      "ccde            ",
      "ccde            ",
      "ccde            ",
      "ccde            ",
      "ccde            ",
      "ccde            ",
      "ccde            ",
      "ccde            ",
      "ccde            ",
      "ccde            ",
      "ccde            ",
      "ccde            ",
      "ccde            ",
      "ccde            ",
      "ccde            ",
      "cdde            "
    ],
    [
      "fgdh            ",
      "fgdh            ",
      "fgdh            ",
      "fgdh            ",
      "fgdh            ",
      "fgdh            ",
      "fgdh            ",
      "fgdh            ",
      "fgdh            ",
      "fgdh            ",
      "fgdh            ",
      "fgdh            ",
      "fgdh            ",
      "fgdh            ",
      "ggdh            ",
      "gidh            "
    ]
  ]
}