{
  "name": "multi_verticalschool_17_floor31",
  "refpalette": "deceasedcraft:multi_verticalschool_17/multi_verticalschool_17_floor31_palette",
  "xsize": 16,
  "zsize": 16,
  "slices": [
    [
      "                ",
      "  a             ",
      "  a             ",
      "  a             ",
      "  a             ",
      "  a             ",
      "  a             ",
      "  a             ",
      "  a             ",
      "  a             ",
      "  a             ",
      "  a             ",
      "  a             ",
      "  a             ",
      "  a             ",
      "  a             "
    ],
    [
      " bb             ",
      "  a             ",
      "  a             ",
      "  a             ",
      "  a             ",
      "  a             ",
      "  a             ",
      "  a             ",
      "  a             ",
      "  a             ",
      "  a             ",
      "  a             ",
      "  a             ",
      "  a             ",
      "  a             ",
      "  a             "
    ],
    [
      "  a             ",
      "  a             ",
      "  a             ",
      "  a             ",
      "  a             ",
      "  a             ",
      "  a             ",
      "  a             ",
      "  a             ",
      "  a             ",
      "  a             ",
      "  a             ",
      "  a             ",
      "  a             ",
      "  a             ",
      "  a             "
    ],
    [
      "  ac            ",
      "  ac            ",
      "  ac            ",
      "  ac            ",
      "  ac            ",
      "  ac            ",
      "  ac            ",
      "  ac            ",
      "  ac            ",
      "  ac            ",
      "  ac            ",
      "  ac            ",
      "  ac            ",
      "  ac            ",
      "  ac            ",
      "  ac            "
    ],
    [
      "ddef            ",
      "ddef            ",
      "ddef            ",
      "ddef            ",
      "ddef            ",
      "ddef            ",
      "ddef            ",
      "ddef            ",
      "ddef            ",
      "ddef            ",
      "ddef            ",
      "ddef            ",
      "ddef            ",
      "ddef            ",
      "ddef            ",
      "ddef            "
    ],
    [
      "ffff            ",
      "ffff            ",
      "ffff            ",
      "ffff            ",
      "ffff            ",
      "ffff            ",
      "ffff            ",
      "ffff            ",
      "ffff            ",
      "ffff            ",
      "ffff            ",
      "ffff            ",
      "ffff            ",
      "ffff            ",
      "ffff            ",
      "ffff            "
    ]
  ]
}