{
  "name": "multi_verticalschool_17_floor9",
  "refpalette": "deceasedcraft:multi_verticalschool_17/multi_verticalschool_17_floor9_palette",
  "xsize": 16,
  "zsize": 16,
  "slices": [
    [
      "aaab  c         ",
      "aaab  c         ",
      "aaab            ",
      "aaab            ",
      "aaab  c         ",
      "aaab  c         ",
      "aaab  c         ",
      "aaab            ",
      "aaab            ",
      "aaab            ",
      "aaab  cc        ",
      "aaab            ",
      "aaab            ",
      "aaab            ",
      "aaab  c         ",
      "aaab  c         "
    ],
    [
      "   b ccc        ",
      "   b            ",
      "   b            ",
      "   b            ",
      "   b  c         ",
      "   b cc         ",
      "   b  c         ",
      "   b            ",
      "   b            ",
      "   b  c         ",
      "   b  cc        ",
      "   b            ",
      "   b            ",
      "   b            ",
      "   b  c         ",
      "   b ccc        "
    ],
    [
      "   b  cc        ",
      "   b            ",
      "   b            ",
      "   b            ",
      "   b  c         ",
      "   b ccc        ",
      "   b            ",
      "   b            ",
      "   b            ",
      "   b  c         ",
      "   b ccc        ",
      "   b  c         ",
      "   b            ",
      "   b            ",
      "   b  c         ",
      "   b  cc        "
    ],
    [
      "   b  c         ",
      "   b            ",
      "   b            ",
      "   b            ",
      "   b            ",
      "   b  c         ",
      "   b            ",
      "   b            ",
      "   b            ",
      "   b            ",
      "   b  c         ",
      "   b  c         ",
      "   b            ",
      "   b            ",
      "   b            ",
      "   b  c         "
    ],
    [
      "ddeb            ",
      "ddeb            ",
      "ddeb            ",
      "ddeb            ",
      "ddeb            ",
      "ddeb  c         ",
      "ddeb            ",
      "ddeb            ",
      "ddeb            ",
      "ddeb            ",
      "ddeb  c         ",
      "ddeb            ",
      "ddeb            ",
      "ddeb            ",
      "ddeb            ",
      "ddeb            "
    ],
    [
      "ffgb            ",
      "ffgb            ",
      "ffgb            ",
      "ffgb            ",
      "ffgb            ",
      "ffgb            ",
      "ffgb            ",
      "ffgb            ",
      "ffgb            ",
      "ffgb            ",
      "ffgb            ",
      "ffgb            ",
      "ffgb            ",
      "ffgb            ",
      "ffgb            ",
      "ffgb            "
    ]
  ]
}