{
  "name": "multi_verticalschool_17_floor8",
  "refpalette": "deceasedcraft:multi_verticalschool_17/multi_verticalschool_17_floor8_palette",
  "xsize": 16,
  "zsize": 16,
  "slices": [
    [
      "         ab     ",
      "         ab     ",
      "         ab     ",
      "         ab     ",
      "         ab     ",
      "         ab     ",
      "cccdeccccab     ",
      "        fab     ",
      "         ab     ",
      "         ab     ",
      "         ab     ",
      "         ab     ",
      "         ab     ",
      "         ab     ",
      "        gab     ",
      "        hab     "
    ],
    [
      "iiiiiiiijab     ",
      "iiiiiiiijab     ",
      "iiiiiiiijab     ",
      "iiiiiiiijab     ",
      "iiiiiiiijab     ",
      "iiiiiiiijab     ",
      "cccccccccab     ",
      "kkkkkkkkkab     ",
      "kkkkkkkkkab     ",
      "kkkkkkkkkab     ",
      "kkkkkkkkkab     ",
      "kkkkkkkkkab     ",
      "kkkkkkkkkab     ",
      "kkkkkkkkkab     ",
      "kkkkkkkkkab     ",
      "kkkkkkkkkab     "
    ],
    [
      "lllllllmaab     ",
      "lllllllmaab     ",
      "lllllllmaab     ",
      "lllllllmaab     ",
      "lllllllmaab     ",
      "lllllllmaab     ",
      "lllllllmaab     ",
      "lllllllmaab     ",
      "lllllllmaab     ",
      "lllllllmaab     ",
      "lllllllmaab     ",
      "lllllllmaab     ",
      "lllllllmaab     ",
      "lllllllmaab     ",
      "lllllllmaab     ",
      "lllllllmaab     "
    ],
    [
      "     nop        ",
      "       p        ",
      "       p        ",
      "       p        ",
      "       o        ",
      "     qop        ",
      "       p        ",
      "       p        ",
      "       p        ",
      "       p        ",
      "     nop        ",
      "       p        ",
      "       p        ",
      "       o        ",
      "       o        ",
      "     nop        "
    ],
    [
      "      p         ",
      "                ",
      "                ",
      "                ",
      "                ",
      "      p         ",
      "                ",
      "                ",
      "                ",
      "                ",
      "      p         ",
      "                ",
      "                ",
      "                ",
      "                ",
      "      p         "
    ],
    [
      "rs t  u         ",
      "rs t            ",
      "rs t            ",
      "rs t            ",
      "rs t            ",
      "rs t  u         ",
      "rs t            ",
      "rs t            ",
      "rs t            ",
      "rs t            ",
      "rs t  u         ",
      "rs t            ",
      "rs t            ",
      "rs t            ",
      "rs t            ",
      "rs t  u         "
    ]
  ]
}