{
  "name": "multi_verticalschool_17_floor18",
  "refpalette": "deceasedcraft:multi_verticalschool_17/multi_verticalschool_17_floor18_palette",
  "xsize": 16,
  "zsize": 16,
  "slices": [
    [
      "  a             ",
      "  a             ",
      "  a             ",
      " ba             ",
      "  a             ",
      "  a             ",
      " ba             ",
      "  a             ",
      "  a             ",
      " ba             ",
      "  a             ",
      "  a             ",
      " ba             ",
      "  a             ",
      "  a             ",
      " ba             "
    ],
    [
      "  a             ",
      "  a             ",
      "  a             ",
      "  a             ",
      "  a             ",
      "  a             ",
      "  a             ",
      "  a             ",
      "  a             ",
      "  a             ",
      "  a             ",
      "  a             ",
      "  a             ",
      "  a             ",
      "  a             ",
      "  a             "
    ],
    [
      "ccad            ",
      "ccad            ",
      "ccad            ",
      "ccad            ",
      "ccad            ",
      "ccad            ",
      "ccad            ",
      "ccad            ",
      "ccad            ",
      "ccad            ",
      "ccad            ",
      "ccad            ",
      "ccad            ",
      "ccad            ",
      "ccad            ",
      "ccad            "
    ],
    [
      "eefg            ",
      "eefg            ",
      "eefg            ",
      "eefg            ",
      "eefg            ",
      "eefg            ",
      "eefg            ",
      "eefg            ",
      "eefg            ",
      "eefg            ",
      "eefg            ",
      "eefg            ",
      "eefg            ",
      "eefg            ",
      "eefg            ",
      "eefg            "
    ],
    [
      "hifj            ",
      "hkfj            ",
      "hkfj            ",
      "hifj            ",
      "hkfj            ",
      "hkfj            ",
      "hifj            ",
      "lkfj            ",
      "hkfj            ",
      "lifj            ",
      "hkfj            ",
      "hkfj            ",
      "hifj            ",
      "hkfj            ",
      "hkfj            ",
      "hifj            "
    ],
    [
      " ma             ",
      "  a             ",
      "  a             ",
      " ma             ",
      "  a             ",
      "  a             ",
      " ma             ",
      "  a             ",
      "  a             ",
      " ma             ",
      "  a             ",
      "  a             ",
      " ma             ",
      "  a             ",
      "  a             ",
      " ma             "
    ]
  ]
}