{
  "name": "multi_verticalschool_17_floor23",
  "refpalette": "deceasedcraft:multi_verticalschool_17/multi_verticalschool_17_floor23_palette",
  "xsize": 16,
  "zsize": 16,
  "slices": [
    [
      "    a           ",
      "   ba           ",
      "   ba           ",
      "   ba           ",
      "   ba           ",
      "    a           ",
      "   ba           ",
      "   ba           ",
      "   ba           ",
      "   ba           ",
      "    a           ",
      "   ba           ",
      "   ba           ",
      "   ba           ",
      "   ba           ",
      "    a           "
    ],
    [
      "ccdea           ",
      "ccdea           ",
      "ccdea           ",
      "ccdea           ",
      "ccdea           ",
      "ccdea           ",
      "ccdea           ",
      "ccdea           ",
      "ccdea           ",
      "ccdea           ",
      "ccdea           ",
      "ccdea           ",
      "ccdea           ",
      "ccdea           ",
      "ccdea           ",
      "ccdea           "
    ],
    [
      "aafaa           ",
      "aafaa           ",
      "aafaa           ",
      "aafaa           ",
      "aafaa           ",
      "aafaa           ",
      "aafaa           ",
      "aafaa           ",
      "aafaa           ",
      "aafaa           ",
      "aafaa           ",
      "aafaa           ",
      "aafaa           ",
      "aafaa           ",
      "aafaa           ",
      "aafaa           "
    ],
    [
      "g   g           ",
      "g   g           ",
      "g   g           ",
      "g   g           ",
      "g   g           ",
      "g   g           ",
      "g   g           ",
      "g   g           ",
      "g   g           ",
      "g   g           ",
      "g   g           ",
      "g   g           ",
      "g   g           ",
      "g   g           ",
      "g   g           ",
      "g   g           "
    ],
    [
      "                ",
      "                ",
      "                ",
      "                ",
      "                ",
      "                ",
      "                ",
      "                ",
      "                ",
      "                ",
      "                ",
      "                ",
      "                ",
      "                ",
      "                ",
      "                "
    ],
    [
      "                ",
      "                ",
      "                ",
      "                ",
      "                ",
      "                ",
      "                ",
      "                ",
      "                ",
      "                ",
      "                ",
      "                ",
      "                ",
      "                ",
      "                ",
      "                "
    ]
  ]
}