{
  "name": "multi_verticalschool_17_floor11",
  "refpalette": "deceasedcraft:multi_verticalschool_17/multi_verticalschool_17_floor11_palette",
  "xsize": 16,
  "zsize": 16,
  "slices": [
    [
      "             a  ",
      "             a  ",
      "             a  ",
      "             a  ",
      "      b      a  ",
      "             a  ",
      "     c       a  ",
      "             a  ",
      "     cb      a  ",
      "             a  ",
      "             a  ",
      "             a  ",
      "             a  ",
      " d   cb      a  ",
      "             a  ",
      "      b      a  "
    ],
    [
      "             a  ",
      "             a  ",
      "             a  ",
      "             a  ",
      "      b      a  ",
      "             a  ",
      "     c       a  ",
      "             a  ",
      "     cb      a  ",
      "             a  ",
      "             a  ",
      "             a  ",
      "             a  ",
      " d   cb      a  ",
      "             a  ",
      "      b      a  "
    ],
    [
      "             a  ",
      "             a  ",
      "             a  ",
      "             a  ",
      "     ef      a  ",
      "             a  ",
      "     ef      a  ",
      "             a  ",
      "     ef      a  ",
      "             a  ",
      "             a  ",
      "             a  ",
      "             a  ",
      " d   ef      a  ",
      "             a  ",
      "     ef      a  "
    ],
    [
      "             ag ",
      "             ag ",
      "             ag ",
      "             ag ",
      "     hh      ag ",
      "             ag ",
      "     hh      ag ",
      "             ag ",
      "     hh      ag ",
      "             ag ",
      "             ag ",
      "             ag ",
      "             ag ",
      " d   hh      ag ",
      "             ag ",
      "     hh      ag "
    ],
    [
      "iiiiiiiiiiiijkl ",
      "iiiiiiiiiiiijkl ",
      "iiiiiiiiiiiijkl ",
      "iiiiiiiiiiiijkl ",
      "iiiiiiiiiiiijkl ",
      "iiiimmmmiiiijkl ",
      "iiiimiimiiiijkl ",
      "iiiimmmmiiiijkl ",
      "iiiiiiiiiiiijkl ",
      "iiiiiiiiiiiijkl ",
      "iiiiiiiiiiiijkl ",
      " iiiiiiiiiiijkl ",
      "  iiiiiiiiiijkl ",
      " n iiiiiiiiijkl ",
      "   immmmiiiijkl ",
      "   imiimiiiijkl "
    ],
    [
      "opoooqqqqqoorks ",
      "poooooqqqqoorks ",
      "ooooooqqqqoorks ",
      "oopooooqqqqorks ",
      "pooooooqqqqorks ",
      "pooooooqqqqorks ",
      "tpoooooqqqqorks ",
      "uuoooooqqqqorks ",
      "uuuooooqqqqorks ",
      "uuoooooqqqqorks ",
      "uuuuoooqqqqorks ",
      "kkouoooqqqqorks ",
      "wkuuoooqqqqorks ",
      "wkkuoooqqqqorks ",
      "wwkuoooqqqqorks ",
      "wwkooooqqqqorks "
    ]
  ]
}