{
  "name": "multi_verticalschool_17_floor14",
  "refpalette": "deceasedcraft:multi_verticalschool_17/multi_verticalschool_17_floor14_palette",
  "xsize": 16,
  "zsize": 16,
  "slices": [
    [
      "aaaaaabcade     ",
      " f ga    de     ",
      "    a    de     ",
      "    a    de     ",
      "    a    de     ",
      "    a    de     ",
      "    a    de     ",
      "    h    de     ",
      "    i   jde     ",
      "    a    de     ",
      "    a    de     ",
      "    a    de     ",
      "    a    de     ",
      "    a    de     ",
      "    a    de     ",
      "akaaa   jde     "
    ],
    [
      "aaaaaaaaade     ",
      "    a    de     ",
      "    a    de     ",
      "    a    de     ",
      "    a    de     ",
      "    a    de     ",
      "    a    de     ",
      "    a    de     ",
      "    a    de     ",
      "    a    de     ",
      "    a    de     ",
      "    a    de     ",
      "    a    de     ",
      "    a    de     ",
      "    a    de     ",
      "alaaa    de     "
    ],
    [
      "aaaaaaaaade     ",
      "    a    de     ",
      "    a    de     ",
      "    a    de     ",
      "    a    de     ",
      "    a    de     ",
      "    a    de     ",
      "    a    de     ",
      "    a    de     ",
      "    a    de     ",
      "    a    de     ",
      "    a    de     ",
      "    a    de     ",
      "    a    de     ",
      "    a    de     ",
      "aaaaa    de     "
    ],
    [
      "aaaaaaaaade     ",
      "    a    de     ",
      "    a    de     ",
      "    a    de     ",
      "    a    de     ",
      "    a    de     ",
      "    a    de     ",
      "    a    de     ",
      "    a    de     ",
      "    a    de     ",
      "    a    de     ",
      "    a    de     ",
      "    a    de     ",
      "    a    de     ",
      "    a    de     ",
      "aaaaa    de     "
    ],
    [
      "aaaaaaaaade     ",
      "mmmmannnode     ",
      "mmmmannnode     ",
      "ppmmannnode     ",
      "mmmmannnode     ",
      "mmmmannnode     ",
      "ppmmannnode     ",
      "mmmmannnode     ",
      "mmmmannnode     ",
      "qqmmannnode     ",
      "mmmmannnode     ",
      "mmmmannnode     ",
      "qqmmannnode     ",
      "mmmmannnode     ",
      "mmmmannnode     ",
      "aaaaannnode     "
    ],
    [
      "rrrrrrrsdde     ",
      "rrrrrrrsdde     ",
      "rrrrrrrsdde     ",
      "rrrrrrrsdde     ",
      "rrrrrrrsdde     ",
      "rrrrrrrsdde     ",
      "rrrrrrrsdde     ",
      "rrrrrrrsdde     ",
      "rrrrrrrsdde     ",
      "rrrrrrrsdde     ",
      "rrrrrrrsdde     ",
      "rrrrrrrsdde     ",
      "rrrrrrrsdde     ",
      "rrrrrrrsdde     ",
      "rrrrrrrsdde     ",
      "rrrrrrrsdde     "
    ]
  ]
}