{
  "name": "multi_verticalschool_17_floor10",
  "refpalette": "deceasedcraft:multi_verticalschool_17/multi_verticalschool_17_floor10_palette",
  "xsize": 16,
  "zsize": 16,
  "slices": [
    [
      "  ab            ",
      "  ab            ",
      "  ab            ",
      "  ab            ",
      "  ab            ",
      "  ab            ",
      "  ab            ",
      "  ab            ",
      "  ab            ",
      "  ab            ",
      "  ab            ",
      "  ab            ",
      "  ab            ",
      "  ab            ",
      "  ab            ",
      "  ab            "
    ],
    [
      "                ",
      "                ",
      "                ",
      "                ",
      "                ",
      "                ",
      "                ",
      "                ",
      "                ",
      "                ",
      "                ",
      "                ",
      "                ",
      "                ",
      "                ",
      "                "
    ],
    [
      "cccccccccccdc e ",
      "cccccccccccdc e ",
      "cccccccccccdc e ",
      "cccccccccccdc e ",
      "cccccccccccdc e ",
      "cccccccccccdc e ",
      "cccccccccccdc e ",
      "cccccccccccdc e ",
      "cccccccccccdc e ",
      "cccccccccccdc e ",
      "cccccccccccdc e ",
      "cccccccccccdc e ",
      "cccccccccccdc e ",
      "cccccccccccdc e ",
      "cccccccccccdc e ",
      "cccccccccccdc e "
    ],
    [
      "fffffffffffffgh ",
      "fffffffffffffgh ",
      "fffffffffffffgh ",
      "fffffffffffffgh ",
      "fffffffffffffgh ",
      "fffffffffffffgh ",
      "fffffffffffffgh ",
      "fffffffffffffgh ",
      "fffffffffffffgh ",
      "fffffffffffffgh ",
      "fffffffffffffgh ",
      "iffffffffffffgh ",
      "jifffffffffffgh ",
      "jiiffffffffffgh ",
      "kkiffffffffffgh ",
      "kkiffffffffffgh "
    ],
    [
      "             gb ",
      "             gb ",
      "             gb ",
      "             gb ",
      "             gb ",
      "            lgb ",
      "            mgb ",
      "            ngb ",
      "             gb ",
      "             gb ",
      "             gb ",
      "             gb ",
      "o            gb ",
      "oa           gb ",
      "kk          lgb ",
      "ppq         mgb "
    ],
    [
      "             r  ",
      "             r  ",
      "             r  ",
      "             r  ",
      "      s      r  ",
      "             r  ",
      "     t       r  ",
      "             r  ",
      "     ts      r  ",
      "             r  ",
      "             r  ",
      "u            r  ",
      "pq           r  ",
      "pa   ts      r  ",
      "  q          r  ",
      "  q   s      r  "
    ]
  ]
}