{
  "name": "multi_verticalschool_17_floor13",
  "refpalette": "deceasedcraft:multi_verticalschool_17/multi_verticalschool_17_floor13_palette",
  "xsize": 16,
  "zsize": 16,
  "slices": [
    [
      "                ",
      "                ",
      "                ",
      "                ",
      "                ",
      "                ",
      "                ",
      "                ",
      "                ",
      "                ",
      "                ",
      "                ",
      "                ",
      "                ",
      "                ",
      "                "
    ],
    [
      "                ",
      "                ",
      "                ",
      "                ",
      "                ",
      "                ",
      "                ",
      "                ",
      "                ",
      "                ",
      "                ",
      "                ",
      "                ",
      "                ",
      "                ",
      "                "
    ],
    [
      "aaaaaaba c      ",
      "aaaaaaba c      ",
      "aaaaaaba c      ",
      "aaaaaaba c      ",
      "aaaaaaba c      ",
      "aaaaaaba c      ",
      "aaaaaaba c      ",
      "aaaaaaba c      ",
      "aaaaaaba c      ",
      "aaaaaaba c      ",
      "aaaaaaba c      ",
      "aaaaaaba c      ",
      "aaaaaaba c      ",
      "aaaaaaba c      ",
      "aaaaaaba c      ",
      "aaaaaaba c      "
    ],
    [
      "ddddddddefg     ",
      "eeeedhhhefg     ",
      "eeeedhhhefg     ",
      "eeeedhhhefg     ",
      "eeeedhhhefg     ",
      "eeeedhhhefg     ",
      "eeeedhhhefg     ",
      "eeeedhhhefg     ",
      "eeeedhhhefg     ",
      "eeeedhhhefg     ",
      "eeeedhhhefg     ",
      "eeeedhhhefg     ",
      "eeeedhhhefg     ",
      "eeeedhhhefg     ",
      "eeeedhhhefg     ",
      "dddddhhhefg     "
    ],
    [
      "ddddddijdfg     ",
      "!kkkd    fg     ",
      "    d    fg     ",
      "   ld    fg     ",
      "   md    fg     ",
      "   nd    fg     ",
      "    d    fg     ",
      "    o    fg     ",
      "    p   qfg     ",
      "    d    fg     ",
      "   rd    fg     ",
      "   ld    fg     ",
      "    d    fg     ",
      "ssssd    fg     ",
      "ttttd    fg     ",
      "dtddd   qfg     "
    ],
    [
      "dddddduwdfg     ",
      "x y dA  Afg     ",
      "    d    fg     ",
      "   Bd    fg     ",
      "    d    Cg     ",
      "    d    Cg     ",
      "    dD   fg     ",
      "    E    fg     ",
      "    F   Ifg     ",
      "    dD   fg     ",
      "    d    fg     ",
      "   Jd    Cg     ",
      "    d    Cg     ",
      "    d    fg     ",
      "    d    fg     ",
      "dKddd   Ifg     "
    ]
  ]
}