{
  "name": "multi_verticalschool_17_floor20",
  "refpalette": "deceasedcraft:multi_verticalschool_17/multi_verticalschool_17_floor20_palette",
  "xsize": 16,
  "zsize": 16,
  "slices": [
    [
      " ab             ",
      "  b             ",
      "  b             ",
      " ab             ",
      "  b             ",
      "  b             ",
      " ab             ",
      "  b             ",
      "  b             ",
      "  b             ",
      "  b             ",
      "  b             ",
      " ab             ",
      "  b             ",
      "  b             ",
      " ab             "
    ],
    [
      "  b             ",
      "  b             ",
      "  b             ",
      "  b             ",
      "  b             ",
      "  b             ",
      "  b             ",
      "  b             ",
      "  b             ",
      "  b             ",
      "  b             ",
      "  b             ",
      "  b             ",
      "  b             ",
      "  b             ",
      "  b             "
    ],
    [
      "ccbd            ",
      "ccbd            ",
      "ccbd            ",
      "ccbd            ",
      "ccbd            ",
      "ccbd            ",
      "ccbd            ",
      "ccbd            ",
      "ccbd            ",
      "ccbd            ",
      "ccbd            ",
      "ccbd            ",
      "ccbd            ",
      "ccbd            ",
      "ccbd            ",
      "ccbd            "
    ],
    [
      "eefg            ",
      "eefg            ",
      "eefg            ",
      "eefg            ",
      "eefg            ",
      "eefg            ",
      "eefg            ",
      "eefg            ",
      "eefg            ",
      "eefg            ",
      "eefg            ",
      "eefg            ",
      "eefg            ",
      "eefg            ",
      "eefg            ",
      "eefg            "
    ],
    [
      "hifj            ",
      "hkfj            ",
      "hkfj            ",
      "hifj            ",
      "lkfj            ",
      "hkfj            ",
      "hifj            ",
      "hkfj            ",
      "hkfj            ",
      "hifj            ",
      "hkfj            ",
      "hkfj            ",
      "hifj            ",
      "hkfj            ",
      "hkfj            ",
      "hifj            "
    ],
    [
      " mb             ",
      "  b             ",
      "  b             ",
      " mb             ",
      "  b             ",
      "  b             ",
      " mb             ",
      "  b             ",
      "  b             ",
      " mb             ",
      "  b             ",
      "  b             ",
      " mb             ",
      "  b             ",
      "  b             ",
      " mb             "
    ]
  ]
}