{
  "name": "multi_verticalschool_17_floor15",
  "refpalette": "deceasedcraft:multi_verticalschool_17/multi_verticalschool_17_floor15_palette",
  "xsize": 16,
  "zsize": 16,
  "slices": [
    [
      "       a        ",
      "       b        ",
      "     cab        ",
      "       b        ",
      "       b        ",
      "       b        ",
      "       b        ",
      "     dab        ",
      "       b        ",
      "       b        ",
      "       b        ",
      "       b        ",
      "     cab        ",
      "       b        ",
      "       b        ",
      "       a        "
    ],
    [
      "                ",
      "                ",
      "      b         ",
      "                ",
      "                ",
      "                ",
      "                ",
      "      b         ",
      "       ~        ",
      "                ",
      "                ",
      "                ",
      "      b         ",
      "                ",
      "                ",
      "                "
    ],
    [
      "ef g            ",
      "ef g            ",
      "ef g  h         ",
      "ef g            ",
      "ef g            ",
      "ef g            ",
      "ef g            ",
      "ef g  h         ",
      "ef g            ",
      "ef g            ",
      "ef g            ",
      "ef g            ",
      "ef g  h         ",
      "ef g            ",
      "ef g            ",
      "ef g            "
    ],
    [
      "iijk            ",
      "iijk  h         ",
      "iijk hh         ",
      "iijk            ",
      "lijk            ",
      "lijk            ",
      "iijk  h         ",
      "iijk  h         ",
      "iijk            ",
      "iijk            ",
      "iijk            ",
      "iljk  h         ",
      "iijk hh         ",
      "iijk  h         ",
      "lijk            ",
      "iijk            "
    ],
    [
      "  jm            ",
      "  jm  h         ",
      "  jm hhh        ",
      "  jm  h         ",
      "  jm            ",
      "  jm            ",
      "  jm  h         ",
      "  jm hh         ",
      "  jm  h         ",
      "  jm            ",
      "  jm            ",
      "  jm            ",
      "  jm hhh        ",
      "  jm  h         ",
      "  jm            ",
      "  jm            "
    ],
    [
      "  n             ",
      "  n             ",
      "  n  hhh        ",
      "  n   h         ",
      "  n             ",
      "  n             ",
      "  n   h         ",
      "  n   hh        ",
      "  n   h         ",
      "  n             ",
      "  n             ",
      "  n             ",
      "  n  hhh        ",
      "  n             ",
      "  n             ",
      "  n             "
    ]
  ]
}