{
  "name": "multi_verticalschool_17_floor19",
  "refpalette": "deceasedcraft:multi_verticalschool_17/multi_verticalschool_17_floor19_palette",
  "xsize": 16,
  "zsize": 16,
  "slices": [
    [
      " ab             ",
      "  b             ",
      "  b             ",
      " ab             ",
      "  b             ",
      "  b             ",
      "  b             ",
      "  b             ",
      "  b             ",
      " c              ",
      "  d             ",
      "  b             ",
      " ab             ",
      "  b             ",
      "  b             ",
      "  b             "
    ],
    [
      "  b             ",
      "  b             ",
      "  b             ",
      "  b             ",
      "  b             ",
      "  b             ",
      "  b             ",
      "  b             ",
      "  b             ",
      "  b             ",
      "  b             ",
      "  b             ",
      "  b             ",
      "  b             ",
      "  b             ",
      "  b             "
    ],
    [
      "eebf            ",
      "eebf            ",
      "eebf            ",
      "eebf            ",
      "eebf            ",
      "eebf            ",
      "eebf            ",
      "eebf            ",
      "eebf            ",
      "eebf            ",
      "eebf            ",
      "eebf            ",
      "eebf            ",
      "eebf            ",
      "eebf            ",
      "eebf            "
    ],
    [
      "gghi            ",
      "gghi            ",
      "gghi            ",
      "gghi            ",
      "gghi            ",
      "gghi            ",
      "gghi            ",
      "gghi            ",
      "gghi            ",
      "gghi            ",
      "gghi            ",
      "gghi            ",
      "gghi            ",
      "gghi            ",
      "gghi            ",
      "gghi            "
    ],
    [
      "jkhl            ",
      "jmhl            ",
      "jmhl            ",
      "jkhl            ",
      "jmhl            ",
      "jmhl            ",
      "nkhl            ",
      "jmhl            ",
      "nmhl            ",
      "jkhl            ",
      "jmhl            ",
      "jmhl            ",
      "jkhl            ",
      "jmhl            ",
      "jmhl            ",
      "jkhl            "
    ],
    [
      " ob             ",
      "  b             ",
      "  b             ",
      " ob             ",
      "  b             ",
      "  b             ",
      " ob             ",
      "  b             ",
      "  b             ",
      " ob             ",
      "  b             ",
      "  b             ",
      " ob             ",
      "  b             ",
      "  b             ",
      " ob             "
    ]
  ]
}