{
  "name": "multi_verticalschool_17_floor25",
  "refpalette": "deceasedcraft:multi_verticalschool_17/multi_verticalschool_17_floor25_palette",
  "xsize": 16,
  "zsize": 16,
  "slices": [
    [
      "aabc            ",
      "aabc            ",
      "aabc            ",
      "aabc            ",
      "aabc            ",
      "aabc            ",
      "aabc            ",
      "aabc            ",
      "aabc            ",
      "aabc            ",
      "aabc            ",
      "aabc            ",
      "aabc            ",
      "aabc            ",
      "aabc            ",
      "aabc            "
    ],
    [
      "debf            ",
      "d bf            ",
      "debf            ",
      "debf            ",
      "d bf            ",
      "debf            ",
      "debf            ",
      "d bf            ",
      "debf            ",
      "debf            ",
      "debf            ",
      "debf            ",
      "debf            ",
      "d bf            ",
      "debf            ",
      "debf            "
    ],
    [
      "g h             ",
      "g h             ",
      "g h             ",
      "g h             ",
      "g h             ",
      "g h             ",
      "g h             ",
      "g h             ",
      "g h             ",
      "g h             ",
      "g h             ",
      "g h             ",
      "g h             ",
      "g h             ",
      "g h             ",
      "g h             "
    ],
    [
      "  h             ",
      "  h             ",
      "  h             ",
      "  h             ",
      "  h             ",
      "  h             ",
      "  h             ",
      "  h             ",
      "  h             ",
      "  h             ",
      "  h             ",
      "  h             ",
      "  h             ",
      "  h             ",
      "  h             ",
      "  h             "
    ],
    [
      "  h             ",
      "  h             ",
      "  h             ",
      "  h             ",
      "  h             ",
      "  h             ",
      "  h             ",
      "  h             ",
      "  h             ",
      "  h             ",
      "  h             ",
      "  h             ",
      "  h             ",
      "  h             ",
      "  h             ",
      "  h             "
    ],
    [
      "iihj            ",
      "iihj            ",
      "iihj            ",
      "iihj            ",
      "iihj            ",
      "iihj            ",
      "iihj            ",
      "iihj            ",
      "iihj            ",
      "iihj            ",
      "iihj            ",
      "iihj            ",
      "iihj            ",
      "iihj            ",
      "iihj            ",
      "iihj            "
    ]
  ]
}