{
  "name": "multi_verticalschool_17_floor28",
  "refpalette": "deceasedcraft:multi_verticalschool_17/multi_verticalschool_17_floor28_palette",
  "xsize": 16,
  "zsize": 16,
  "slices": [
    [
      "aabc            ",
      "aabc            ",
      "aabc            ",
      "aabc            ",
      "aabc            ",
      "aabc            ",
      "aabc            ",
      "aabc            ",
      "aabc            ",
      "aabc            ",
      "aabc            ",
      "aabc            ",
      "aabc            ",
      "aabc            ",
      "aabc            ",
      "aabc            "
    ],
    [
      "debf            ",
      "debf            ",
      "dgbf            ",
      "debf            ",
      "debf            ",
      "debf            ",
      "debf            ",
      "debf            ",
      "debf            ",
      "hebf            ",
      "debf            ",
      "dgbf            ",
      "dgbf            ",
      "d bf            ",
      "debf            ",
      "debf            "
    ],
    [
      "i j             ",
      "i j             ",
      "i j             ",
      "i j             ",
      "i j             ",
      "i j             ",
      "i j             ",
      "i j             ",
      "i j             ",
      "  j             ",
      "  j             ",
      "i j             ",
      "i j             ",
      "i j             ",
      "i j             ",
      "i j             "
    ],
    [
      "  j             ",
      "  j             ",
      "  j             ",
      "  j             ",
      "  j             ",
      "  j             ",
      "  j             ",
      "  j             ",
      "  j             ",
      "  j             ",
      "  j             ",
      "  j             ",
      "  j             ",
      "  j             ",
      "  j             ",
      "  j             "
    ],
    [
      "  j             ",
      "  j             ",
      "  j             ",
      "  j             ",
      "  j             ",
      "  j             ",
      "  j             ",
      "  j             ",
      "  j             ",
      "  j             ",
      "  j             ",
      "  j             ",
      "  j             ",
      "  j             ",
      "  j             ",
      "  j             "
    ],
    [
      "kkjl            ",
      "kkjl            ",
      "kkjl            ",
      "kkjl            ",
      "kkjl            ",
      "kkjl            ",
      "kkjl            ",
      "kkjl            ",
      "kkjl            ",
      "kkjl            ",
      "kkjl            ",
      "kkjl            ",
      "kkjl            ",
      "kkjl            ",
      "kkjl            ",
      "kkjl            "
    ]
  ]
}