{
  "name": "multi_gunstore_2_ground",
  "refpalette": "deceasedcraft:multi_gunstore_2/multi_gunstore_2_ground_palette",
  "xsize": 16,
  "zsize": 16,
  "slices": [
    [
      "HHHHHHHHHHHHHHHH",
      "HHHHHHHHHHHHHHHH",
      "aaaaaaaaaaaaaaaa",
      "bbcccccbbbbbcccc",
      "                ",
      "                ",
      "                ",
      "                ",
      "                ",
      "                ",
      "                ",
      "de              ",
      "ffcccccfffffcccc",
      "aaaaaaaaaaaaaaaa",
      "HHHHHHHHHHHHHHHH",
      "HHHHHHHHHHHHHHHH"
    ],
    [
      "                ",
      "                ",
      "                ",
      "ggcccccgggggcccc",
      "  h i h     h j ",
      "                ",
      "                ",
      "                ",
      "                ",
      "                ",
      "                ",
      "ddk   k     k   ",
      " gcccccgggggcccc",
      "                ",
      "                ",
      "                "
    ],
    [
      "                ",
      "                ",
      "llllllllllllllll",
      "cccccccccccccccc",
      "                ",
      "                ",
      "                ",
      "                ",
      "                ",
      "                ",
      "                ",
      "                ",
      "cccccccccccccccc",
      "mmmmmmmmmmmmmmmm",
      "                ",
      "                "
    ],
    [
      "                ",
      "                ",
      "nnnnnnnnnnnnnnnn",
      "cccccccccccccccc",
      "                ",
      "         o      ",
      "         p      ",
      "         q      ",
      "         p      ",
      "         p      ",
      "         r      ",
      "                ",
      "cccccccccccccccc",
      "nnnnnnnnnnnnnnnn",
      "                ",
      "                "
    ],
    [
      "                ",
      "                ",
      "nnsssssnnnnnssss",
      "nntttttnnnnntttt",
      "nnnnnnnnnnnnnnnn",
      "uuuuuuuuuwuuuuuu",
      "uuuuuuuuuxuuuuuu",
      "uuuuuuuuuxuuuuuu",
      "uuuuuuuuuxuuuuuu",
      "uuuuuuuuuxuuuuuu",
      "uuuuuuuuuwuuuuuu",
      "nnnnnnnnnnnnnnnn",
      "nntttttnnnnntttt",
      "nnsssssnnnnnssss",
      "                ",
      "                "
    ],
    [
      "                ",
      "                ",
      "ss     sssss    ",
      "ss     sssss    ",
      "ssssssssssssssss",
      "yyyyyyyyyyyyyyyy",
      "ssssssssssssssys",
      "ssssssssssssssys",
      "ssssssssssssssys",
      "ssssssssssssssys",
      "yyyyyyyyyyyyyyyy",
      "ssssssssssssssss",
      "ss     sssss    ",
      "ss     sssss    ",
      "                ",
      "                "
    ]
  ]
}