{
  "name": "multi_gallery_9_base2",
  "refpalette": "deceasedcraft:multi_gallery_9/multi_gallery_9_base2_palette",
  "xsize": 16,
  "zsize": 16,
  "slices": [
    [
      "aaaaaabccccccccc",
      "aaaaaabccccccccc",
      "aaaaaabccccccccc",
      "aaaaaabbbbbbbbbb",
      "aaaaaabddddbdddd",
      "aaaaaabddddbdddd",
      "aaaaaabbbbbbbbbb",
      "aaaaaabddddddddd",
      "aaaaaabddddddddd",
      "aaaaaabddddddddd",
      "aaaaaabddddddddd",
      "aaaaaabddddddddd",
      "eeeeeeeeeeeeeeee",
      "aaaaaaaaaaaaaaaa",
      "aaaaaaaaaaaaaaaa",
      "vvvvvvvvvvvvvvvv"
    ],
    [
      "aaaaacbbfffffggg",
      "aaaaacbbfffffggg",
      "aaaaacbbffffgggg",
      "aaaaacccchcccccc",
      "aaaaacdi   j  kl",
      "aaaaacdi   m  kl",
      "aaaaaccccncccccc",
      "aaaaaco       pq",
      "aaaaacr        s",
      "aaaaacr        s",
      "aaaaaco       ts",
      "aaaaacr        q",
      "eeeeeeeeeeeeeeee",
      "bbbbbbbbbbbbbbbb",
      "aaaaaaaaaaaaaaaa",
      "vvvvvvvvvvvvvvvv"
    ],
    [
      "uuwxxxxy       f",
      "wwwxxxxy     A  ",
      "xxxxxxxb     ffB",
      "bbbbbccccCcccccc",
      "dddddi     D   E",
      "dddddi     F   E",
      "dddddccccIcccccc",
      "dddddcJ         ",
      "dddddc         K",
      "dddddc          ",
      "dddddcL        K",
      "dddddc        M ",
      "eeeeeeeeeeeeeeee",
      "NNNNNNNNNNNNNNNN",
      "bbbbbbbbbbbbbbbb",
      "vvvvvvvvvvvvvvvv"
    ],
    [
      "OO     y        ",
      "       y     P  ",
      "       b       Q",
      "RRRRRccccScccccc",
      "           T  UE",
      "           T  UE",
      "V   WccccXcccccc",
      "Y  ZWc         0",
      "1 2 3c         4",
      "1   Wc         5",
      "6  27c         8",
      "VZ  Wc         0",
      "eeeeeeeeeeeeeeee",
      "bbbbbbbbbbbbbbbb",
      "aaaaaaaaaaaaaaaa",
      "vvvvvvvvvvvvvvvv"
    ],
    [
      "99     y        ",
      "       y     #  ",
      "      $b       Q",
      "RRRRRccccccccccc",
      "           c  U%",
      "           c  U%",
      "^   Wccccccccccc",
      "&   *c         5",
      "(   Wc         8",
      ")   Wc         4",
      "    +c         0",
      "-   Wc         4",
      "eeeeeeeeeeeeeeee",
      "aaaaaaaaaaaaaaaa",
      "aaaaaaaaaaaaaaaa",
      "vvvvvvvvvvvvvvvv"
    ],
    [
      " [     y        ",
      "       y        ",
      "       b       ]",
      "RRRRRccccccccccc",
      "           c  U!",
      "           c  U ",
      "    Wccccccccccc",
      "    +c          ",
      "    Wc          ",
      "    +c          ",
      "    Wc          ",
      "    Wc          ",
      "eeeeeeeeeeeeeeee",
      "aaaaaaaaaaaaaaaa",
      "aaaaaaaaaaaaaaaa",
      "vvvvvvvvvvvvvvvv"
    ]
  ]
}