{
  "name": "multi_gallery_9_floor1",
  "refpalette": "deceasedcraft:multi_gallery_9/multi_gallery_9_floor1_palette",
  "xsize": 16,
  "zsize": 16,
  "slices": [
    [
      "aaaaaaaaabc     ",
      "aaaaaaaaabc     ",
      "aaaaaaaabb      ",
      "aaaaaaaabb      ",
      "aaaaaaaabc      ",
      "aaaaaaaabc      ",
      "baaaaaabb       ",
      "dbbbbaabb       ",
      " defbbbbc       ",
      "     fff        ",
      "                ",
      "                ",
      "                ",
      "                ",
      "                ",
      "                "
    ],
    [
      "         g      ",
      "         g      ",
      "        g       ",
      "        g       ",
      "        g       ",
      "        g       ",
      "h      g        ",
      "dhhgg  g        ",
      " dddeggg        ",
      "                ",
      "                ",
      "                ",
      "                ",
      "                ",
      "                ",
      "                "
    ],
    [
      "         g      ",
      "         g      ",
      "        g       ",
      "        g       ",
      "        g       ",
      "        g       ",
      "h      g        ",
      "dhhhg  g        ",
      " ddddggg        ",
      "     de         ",
      "                ",
      "                ",
      "                ",
      "                ",
      "                ",
      "                "
    ],
    [
      "         g      ",
      "         g      ",
      "        g       ",
      "        g       ",
      "        g       ",
      "        g       ",
      "h      g        ",
      "dhhhh  g        ",
      " ddddggg        ",
      "     ddde       ",
      "                ",
      "                ",
      "                ",
      "                ",
      "                ",
      "                "
    ],
    [
      "         g      ",
      "         g      ",
      "        g       ",
      "        g       ",
      "        g       ",
      "        g       ",
      "g      g        ",
      " gghh  g        ",
      " idddhgg        ",
      "     dddd       ",
      "         de     ",
      "                ",
      "                ",
      "                ",
      "                ",
      "                "
    ],
    [
      "jjjjjjjjjkjjjjj ",
      "jjjjjjjjjkjjjjj ",
      "jjjljjjjkjjjjjj ",
      "jjjljjjjkjjjjj  ",
      "jjjjjjjjkjjjjj  ",
      "jjjjjjjjkjjjjj  ",
      "kjjjjjjkjjjjjj  ",
      "ekkkkjjkjjjjj   ",
      " eeddkkkjjjjj   ",
      "     ddddjjjj   ",
      "         ddde   ",
      "                ",
      "                ",
      "                ",
      "                ",
      "                "
    ]
  ]
}