{
  "name": "multi_gallery_9_base1",
  "refpalette": "deceasedcraft:multi_gallery_9/multi_gallery_9_base1_palette",
  "xsize": 16,
  "zsize": 16,
  "slices": [
    [
      "aa     b        ",
      "       b        ",
      "       c       ~",
      "dddddeeeeeeeeeee",
      "    fe     e    ",
      "    fe     e    ",
      "    feeeeeeeeeee",
      "    fe          ",
      "    fe          ",
      "    fe          ",
      "    fe          ",
      "    fe          ",
      "gggggggggggggggg",
      "hhhhhhhhhhhhhhhh",
      "hhhhhhhhhhhhhhhh",
      "vvvvvvvvvvvvvvvv"
    ],
    [
      "       b        ",
      "       b        ",
      "       c        ",
      "dddddeeeeeeeeeee",
      "ii   e     e    ",
      "ji   e     e    ",
      "ii   eeeeeeeeeee",
      "ii   e          ",
      "ii   e          ",
      "ii   e          ",
      "ki   e          ",
      "ii   e          ",
      "gggggggggggggggg",
      "hhhhhhhhhhhhhhhh",
      "hhhhhhhhhhhhhhhh",
      "vvvvvvvvvvvvvvvv"
    ],
    [
      "       b        ",
      "       b        ",
      "       c        ",
      "dddddeeeeeeeeeee",
      "llllle     e    ",
      "llllle     e    ",
      "llllleeeeeeeeeee",
      "lllllellllllllll",
      "lllllellllllllll",
      "lllllellmllllnll",
      "lllllellllllllll",
      "lllllellllllllll",
      "gggggggggggggggg",
      "hhhhhhhhhhhhhhhh",
      "hhhhhhhhhhhhhhhh",
      "vvvvvvvvvvvvvvvv"
    ],
    [
      "       c        ",
      "       c        ",
      "       c        ",
      "dddddeeeeeeeeeee",
      "gogggelllllellll",
      "ppllleeelllellll",
      "ppllleeeeeeeeeel",
      "pplllellllllllll",
      "pplllellllllllll",
      "pplllellllllllll",
      "eeeeeellllllllll",
      "eeeeeellllllllll",
      "gogggggggggggggg",
      "hhhhhhhhhhhhhhhh",
      "hhhhhhhhhhhhhhhh",
      "vvvvvvvvvvvvvvvv"
    ],
    [
      "qqqqqeerssssssss",
      "qqqqqeerssssssss",
      "qqqqqeerssssssss",
      "dddddeeeeeeeeeee",
      "gtgggggogggggggg",
      "uuppppppeeeeeeee",
      "uuppppppeeeeeeee",
      "uuppppppeeeeeeee",
      "uuppppppeeeeeeee",
      "uuppppppeeeeeeee",
      "wxyABeeeeeeeeeee",
      "wxyABeeeeeeeeeee",
      "gtgggggogggggggg",
      "hdhhhhhhhhhhhhhh",
      "hhhhhhhhhhhhhhhh",
      "vvvvvvvvvvvvvvvv"
    ],
    [
      "lllllllleeeeeeee",
      "cccclllleeeeeeee",
      "cccccccceeeeeeee",
      "cccccCCceeeeeeee",
      "gggggggtgggggogg",
      "   DEuuuppppppee",
      "     uuuppppppee",
      "     uuuppppppee",
      "     uuuppppppee",
      "     uuuppppppee",
      "    FIwxyABeeeee",
      "    FIwxyABeeeee",
      "gggggggtgggggogg",
      "hhhhhhhdhhhhhhhh",
      "hhhhhhhhhhhhhhhh",
      "vvvvvvvvvvvvvvvv"
    ]
  ]
}