{
  "name": "multi_gallery_9_ground",
  "refpalette": "deceasedcraft:multi_gallery_9/multi_gallery_9_ground_palette",
  "xsize": 16,
  "zsize": 16,
  "slices": [
    [
      "aaaaabbbbbbbbbbb",
      "ccccaaaaabbbbbbb",
      "ccccccccabbbbbbb",
      "cccccdecabbbbbbb",
      "fffffffffffffgff",
      "          hiiijj",
      "           iiijj",
      "           iiijj",
      "           iiijj",
      "           iiijj",
      "          klmnop",
      "          klmnop",
      "fffffffffffffgff",
      "bbbbbbbbbbbbbbbb",
      "bbbbbbbbbbbbbbbb",
      "bbbbbbbbbbbbbbbb"
    ],
    [
      "                ",
      " q              ",
      "                ",
      "    qrs         ",
      "fffffffffffttttt",
      "          u     ",
      "                ",
      "                ",
      "                ",
      "                ",
      "                ",
      "                ",
      "fffffffffffttttt",
      "                ",
      "                ",
      "                "
    ],
    [
      "                ",
      "                ",
      "     rs         ",
      "     rs         ",
      "tttttrs         ",
      "                ",
      "                ",
      "                ",
      "                ",
      "                ",
      "                ",
      "w               ",
      "ttttt           ",
      "                ",
      "                ",
      "                "
    ],
    [
      "                ",
      "      x         ",
      "     rs         ",
      "                ",
      "     rs         ",
      "     x          ",
      "                ",
      "                ",
      "                ",
      "                ",
      "                ",
      "                ",
      "                ",
      "                ",
      "                ",
      "                "
    ],
    [
      "      x         ",
      "      x         ",
      "                ",
      "                ",
      "                ",
      "     x          ",
      "     x          ",
      "                ",
      "                ",
      "                ",
      "                ",
      "                ",
      "                ",
      "                ",
      "                ",
      "                "
    ],
    [
      "      x         ",
      "                ",
      "                ",
      "                ",
      "                ",
      "                ",
      "     x          ",
      "     y          ",
      "                ",
      "                ",
      "                ",
      "                ",
      "                ",
      "                ",
      "                ",
      "                "
    ]
  ]
}