{
  "name": "multi_gallery_9_floor2",
  "refpalette": "deceasedcraft:multi_gallery_9/multi_gallery_9_floor2_palette",
  "xsize": 16,
  "zsize": 16,
  "slices": [
    [
      "aaaaaabaaaabbbac",
      "aaaaaabaaaaadeaf",
      "aaaaaabaaaaadgaf",
      "aaaaabbaaaaaaaff",
      "aaaaabaaaaahhafi",
      "aaaaabaaaaahhafi",
      "baaaabaaaaaaaafi",
      "cbbbbbaaaajkaffi",
      " ccccbaaaakkafi ",
      "     ccccaaaafi ",
      "         ccccfi ",
      "             cl ",
      "                ",
      "                ",
      "                ",
      "                "
    ],
    [
      "               m",
      "               b",
      "               b",
      "              bb",
      "           nn ba",
      "           nn ba",
      "              ba",
      "          !o bba",
      "          oo baf",
      "       mc    baf",
      "         ccccbaf",
      "             ccc",
      "                ",
      "                ",
      "                ",
      "                "
    ],
    [
      "                ",
      "                ",
      "                ",
      "                ",
      "                ",
      "                ",
      "                ",
      "          pq    ",
      "          qq   b",
      "               b",
      "         mccc  b",
      "             ccc",
      "                ",
      "                ",
      "                ",
      "                "
    ],
    [
      "                ",
      "                ",
      "                ",
      "                ",
      "                ",
      "                ",
      "                ",
      "                ",
      "                ",
      "                ",
      "           mm   ",
      "             mmm",
      "                ",
      "                ",
      "                ",
      "                "
    ],
    [
      "                ",
      "                ",
      "                ",
      "                ",
      "                ",
      "                ",
      "                ",
      "                ",
      "                ",
      "                ",
      "                ",
      "                ",
      "                ",
      "                ",
      "                ",
      "                "
    ],
    [
      "                ",
      "                ",
      "                ",
      "                ",
      "                ",
      "                ",
      "                ",
      "                ",
      "                ",
      "                ",
      "                ",
      "                ",
      "                ",
      "                ",
      "                ",
      "                "
    ]
  ]
}