{
  "name": "multi_terraceplaza_2_base2",
  "refpalette": "deceasedcraft:multi_terraceplaza_2/multi_terraceplaza_2_base2_palette",
  "xsize": 16,
  "zsize": 16,
  "slices": [
    [
      "vabbabbbbbbabbbb",
      "vabbabbbbbbabbbb",
      "vabbabbbbbbabbbb",
      "vabbabbbbbbabbbb",
      "vabbabbbbbbabbbb",
      "vabbabbbbbbabbbb",
      "vabbabbbbbbabbbb",
      "vabbabbbbbbabbbb",
      "vabbaaabbaacaaaa",
      "vabbabbbbbbadddd",
      "vabbabbbbbbbdddd",
      "vabbabbbbbbbdddd",
      "vabbabbbbbbadddd",
      "vabbabbbbbbadddd",
      "vabbabbbbbbadddd",
      "vabbabbbbbbadddd"
    ],
    [
      "va  ae    eaf   ",
      "va  ae    ea    ",
      "va  ae    ea    ",
      "va  ae    eag   ",
      "va  ae    eah g ",
      "va  ae    ea h  ",
      "va iae    ea!hj ",
      "va  ak    kallhg",
      "va  aaamnaacaaaa",
      "va  aop  qrastu!",
      "va  a!w    x   y",
      "va  aABC   D   E",
      "va  aop   Fa   E",
      "va  aAB   IaJ  K",
      "va  aB    IaJ  K",
      "va iaC p  LaJ  K"
    ],
    [
      "va  a     Ma    ",
      "va  aN    Ma    ",
      "va  aN    Oa    ",
      "va  aP    Qa    ",
      "va  a     Ra    ",
      "va  aN    Qa g  ",
      "va  aN    Qah   ",
      "va  ak    kahj  ",
      "va  aaaSTaacaaaa",
      "va  aU     astuV",
      "va  aC     W   X",
      "va  aB     Y    ",
      "va  aZ     a0  1",
      "va  ap    2a3   ",
      "va  a     4a3  5",
      "va  a      a3   "
    ],
    [
      "va  ae    ea    ",
      "va  ae    ea    ",
      "va  ae    ea    ",
      "va  ae    ea    ",
      "va  ae    ea    ",
      "va  ae    ea    ",
      "va  ae    eag   ",
      "va  ak    ka    ",
      "va  aaa66aacaaaa",
      "va  a      astu ",
      "va  a      7    ",
      "va  a      7    ",
      "va  a      a    ",
      "va  a      a3   ",
      "va  a      a3   ",
      "va  a      a3   "
    ],
    [
      "va  a8    9a#   ",
      "va  a      a#   ",
      "va  a8    9a#   ",
      "va  a8     a#   ",
      "va  a     $a#   ",
      "va  a$    %a#   ",
      "va  a%    9a#   ",
      "va  ak    ka##^ ",
      "va  aaaaaaacaaaa",
      "va  a      a    ",
      "va  a      a    ",
      "va  a      a    ",
      "va  a      a    ",
      "va  a      a    ",
      "va  a      a    ",
      "va  a      a    "
    ],
    [
      "va  ae    e&****",
      "va  ae    e&****",
      "va  ae    e&****",
      "va  ae    e&****",
      "va  ae    e&****",
      "va  ae    e&****",
      "va  ae    e&****",
      "va  ak    k&**(*",
      "va  aaaaaaacaaaa",
      "va  a      a    ",
      "va  a      a    ",
      "va  a      a    ",
      "va  a      a    ",
      "va  a      a    ",
      "va  a      a    ",
      "va  a      a    "
    ]
  ]
}