{
  "name": "multi_terraceplaza_2_ground",
  "refpalette": "deceasedcraft:multi_terraceplaza_2/multi_terraceplaza_2_ground_palette",
  "xsize": 16,
  "zsize": 16,
  "slices": [
    [
      "HHHabcdeffghiiii",
      "HHHabcdeffghiiii",
      "HHHabcdeffghiiii",
      "HHHabcdeffghiiii",
      "HHHabcdeffghiijj",
      "HHHabcdeffghjjjj",
      "HHHakcdeffghjjjj",
      "HHHabcdeffghjjjj",
      "HHHabcdeflmnoooo",
      "HHHabcdeffghpppp",
      "HHHakcdeffghpppp",
      "HHHabcdeffghpppp",
      "HHHabcdeffghpppp",
      "HHHabcdeffghpppp",
      "HHHabcdeffghpppp",
      "HHHabcdeffghpppp"
    ],
    [
      "    qr s  go  tt",
      "    qr s  go    ",
      "    qr s  go    ",
      "    qr s  go  uu",
      "    qr s  go wx ",
      "    qr s  go    ",
      "    yr s  go    ",
      "    Ar s  goBCCB",
      "    AD E   noooo",
      "    Ar s  g FFFI",
      "    yr s  g FFFI",
      "    qr s  g FFFI",
      "    qr s  g FFFI",
      "    qr s  g FFFI",
      "    qr s  g FFFI",
      "    qr s  g oooJ"
    ],
    [
      "     rKL  gs  tt",
      "     rKM   s    ",
      "     rKM   s    ",
      "     rKM  gs  uu",
      "     rKL  go NO ",
      "     rKM   s    ",
      "    PrKL  gs   Q",
      "      KM   o RRS",
      "     TKM   noooo",
      "      KL  g  U  ",
      "    PrKL  g     ",
      "     rKM     V  ",
      "     rKL  g  W  ",
      "     rKM        ",
      "     rKM        ",
      "     rKL  g oooX"
    ],
    [
      "      KL   o  tt",
      "      KM   o    ",
      "      KM   o    ",
      "      KM   o  uu",
      "      KL   oYYO ",
      "      KM   o    ",
      "      KL   o    ",
      "      KM   oZ001",
      "     qKM   noooo",
      "      KL     2  ",
      "      KL        ",
      "      KM        ",
      "      KL        ",
      "      KM        ",
      "      KM        ",
      "      KL    ooo3"
    ],
    [
      "      KL   otttt",
      "      KM   o    ",
      "      KM   o    ",
      "      KM   ouuuu",
      "      KL   oYY4 ",
      "      KM   o    ",
      "      KL   o    ",
      "      KM   o    ",
      "     qKM   noooo",
      "      KL        ",
      "      KL        ",
      "      KM        ",
      "      KL        ",
      "      KM        ",
      "      KM     5  ",
      "      KL    ooo3"
    ],
    [
      "      KL   6tttt",
      "      KM   6    ",
      "      KM   6    ",
      "      KM   6uuuu",
      "      KL   67777",
      "      KM   67777",
      "      KL   67777",
      "      KM   67777",
      "      KM   noooo",
      "      KL   8    ",
      "      KL   8    ",
      "      KM   8    ",
      "      KL   8    ",
      "      KM   8    ",
      "      KM   8 9  ",
      "      KL   8ooo3"
    ]
  ]
}