{
  "name": "multi_terraceplaza_2_floor2",
  "refpalette": "deceasedcraft:multi_terraceplaza_2/multi_terraceplaza_2_floor2_palette",
  "xsize": 16,
  "zsize": 16,
  "slices": [
    [
      "      ab   cdddd",
      "      ae   c    ",
      "      ae   c    ",
      "      ae   cffff",
      "      ab   cggh ",
      "      ae   c    ",
      "      ab   c    ",
      "      ae   c    ",
      "      ae   icccc",
      "      ab        ",
      "      ab        ",
      "      ae        ",
      "      ab        ",
      "      ae        ",
      "      ae        ",
      "      ab    ccc "
    ],
    [
      "      ab   jdddd",
      "      ae   j    ",
      "      ae   j    ",
      "      ae   jffff",
      "      ab   jkkkk",
      "      ae   jkkkk",
      "      ab   jkkkk",
      "      ae   jkkkk",
      "      ae   icccc",
      "      ab   l    ",
      "      ab   l    ",
      "      ae   l    ",
      "      ab   l    ",
      "      ae   l    ",
      "      ae   l    ",
      "      ab   lccc "
    ],
    [
      "      ab  mjdddd",
      "      ae  mj    ",
      "      ae  mj    ",
      "      ae  mjffff",
      "      ab  mjn  n",
      "      ae  mj   n",
      "      ab  mj    ",
      "      ae  mj n n",
      "      ae  micccc",
      "      ab  mo    ",
      "      ab  mo    ",
      "      ae  mo    ",
      "      ab  mo    ",
      "      ae  mo    ",
      "      ae  mo    ",
      "      ab  moccc "
    ],
    [
      "      ab pqrkkkk",
      "      ae pqrkkkk",
      "      ae pqrkkkk",
      "      ae pqrkkkk",
      "      ab pqrn   ",
      "      ae pqrn   ",
      "      ab pqr    ",
      "      ae pqr   n",
      "      aesstirrrr",
      "      ab pqrkkkk",
      "      ab pqrkkkk",
      "      ae pqrkkuu",
      "      ab pqrkkkk",
      "      ae pqrkkkk",
      "      ae pqrkkkk",
      "      ab pqrkkkk"
    ],
    [
      "      ab  wxyyyy",
      "      ae  wxyyyy",
      "      ae  wxyyyy",
      "      ae  wxyyyy",
      "      ab  wxyyAA",
      "      ae  wxAAAA",
      "      ab  wxAAAA",
      "      ae  wxAAAA",
      "      ae  Bicccc",
      "      ab  wxCCCC",
      "      ab  wxCCCC",
      "      ae  wxCCCD",
      "      ab  wxCCDE",
      "      ae  wxCCDE",
      "      ae  wxCCDE",
      "      ab  wxCCDE"
    ],
    [
      "      ab  wc  dd",
      "      ae  wc    ",
      "      ae  wc    ",
      "      ae  wc  ff",
      "      ab  wc FI ",
      "      ae  wc    ",
      "      ab  wc    ",
      "      ae  wcJKKJ",
      "      ae   icccc",
      "      ab  w   LL",
      "      ab  w     ",
      "      ae  w     ",
      "      ab  w     ",
      "      ae  w     ",
      "      ae  w     ",
      "      ab  w     "
    ]
  ]
}