{
  "name": "multi_terraceplaza_2_base1",
  "refpalette": "deceasedcraft:multi_terraceplaza_2/multi_terraceplaza_2_base1_palette",
  "xsize": 16,
  "zsize": 16,
  "slices": [
    [
      "va  ab    cadddd",
      "va  a     eadddd",
      "va  af    badddd",
      "va  ag    hadddd",
      "va  ah    iaddjj",
      "va  ah    hajjjj",
      "va  ak    hajjjj",
      "va  al    lajjjj",
      "va  aaaaaaamaaaa",
      "va  a      a    ",
      "va  a      a    ",
      "va  a      a    ",
      "va  a      a    ",
      "va  a      a    ",
      "va  a      a    ",
      "va  a      a    "
    ],
    [
      "va  a      a  nn",
      "va  a      a    ",
      "va  a      a    ",
      "va  a      a  oo",
      "va  a      a pq ",
      "va  a      a    ",
      "va  a      a    ",
      "va  al    larssr",
      "va  aaaaaaamaaaa",
      "va  a      a    ",
      "va  a      a    ",
      "va  a      a    ",
      "va  a      a    ",
      "va  a      a    ",
      "va  a      a    ",
      "va  a      a    "
    ],
    [
      "va  a      a  nn",
      "va  a      a    ",
      "va  a      a    ",
      "va  a      a  oo",
      "va  a      a tu ",
      "va  a      a    ",
      "va  a      a   w",
      "va  al    la xxy",
      "va  aaaaaaamaaaa",
      "va  a      a    ",
      "va  a      a    ",
      "va  a      a    ",
      "va  a      a    ",
      "va  a      a    ",
      "va  a      a    ",
      "va  a      a    "
    ],
    [
      "va  aAAAAAAa  nn",
      "va  aAAAAAAa    ",
      "va  aAAAAAAa    ",
      "va  aAAAAAAa  oo",
      "va  aAAAAAAaBBu ",
      "va  aCAAAAAa    ",
      "va  aAAAAAAa    ",
      "va  aAAAAAAaDEEF",
      "va  aaaaaaamaaaa",
      "va  aAAAAAAaBBBB",
      "va  aCAAAAAaBIII",
      "va  aAAAAAAaBIII",
      "va  aAAAAAAaBII ",
      "va  aAAAAAAaBII ",
      "va  aAAAAAAaBII ",
      "va  aAAAAAAaBII "
    ],
    [
      "va  aJKKKKKannnn",
      "va  aJKKKKKa    ",
      "va  aJKKKKKa    ",
      "va  aJKKKKKaoooo",
      "va  aJKKKKKaBBL ",
      "va  aJKKKKKa    ",
      "va  aJKKKKKa    ",
      "va  aJKKKKKa    ",
      "va  aJKKKKKmaaaa",
      "va  aJKKKKKaBBBB",
      "va  aJKKKKKaBMMM",
      "va  aJKKKKKaBMNN",
      "va  aJKKKKKaBMNN",
      "va  aJKKKKKaBMNN",
      "va  aJKKKKKaBMNN",
      "va  aJKKKKKaBMNN"
    ],
    [
      "vaAAaKKKKKOPQQQQ",
      "vaAAaKKKKKOPQQQQ",
      "vaAAaKKKKKOPQQQQ",
      "vaAAaKKKKKOPQQQQ",
      "vaAAaKKKKKOPQQQQ",
      "vaAAaKKKKKOPQQQQ",
      "vaAAaKKKKKOPQQQQ",
      "vaAAaKKKKKOPQQQQ",
      "vaAAaKKKKKRmPPPP",
      "vaAAaKKKKKOPQQQQ",
      "vaAAaKKKKKOPQSSS",
      "vaAAaKKKKKOPQSgg",
      "vaAAaKKKKKOPQSgg",
      "vaAAaKKKKKOPQSgg",
      "vaAAaKKKKKOPQSgg",
      "vaAAaKKKKKOPQSgg"
    ]
  ]
}