{
  "name": "multi_terraceplaza_2_floor1",
  "refpalette": "deceasedcraft:multi_terraceplaza_2/multi_terraceplaza_2_floor1_palette",
  "xsize": 16,
  "zsize": 16,
  "slices": [
    [
      "      ab  cdeeee",
      "      af  cd    ",
      "      af  cd    ",
      "      af  cdgggg",
      "      ab  cdh  h",
      "      af  cd   h",
      "      ab  cd    ",
      "      af  cd   h",
      "      af  cijjjj",
      "      ab  ck    ",
      "      ab  ck    ",
      "      af  ck    ",
      "      ab  ck    ",
      "      af  ck    ",
      "      af  ck    ",
      "      ab  ckjjjl"
    ],
    [
      "      ab mnopppp",
      "      af mnopppp",
      "      af mnopppp",
      "      af mnopppp",
      "      ab mnoh   ",
      "      af mnoh   ",
      "      ab mno    ",
      "      af mno    ",
      "      afqqrioooo",
      "      ab mnopppp",
      "      ab mnopppp",
      "      af mnopppp",
      "      ab mnopppp",
      "      af mnopppp",
      "      af mnopppp",
      "      ab mnopppp"
    ],
    [
      "      ab  stuuuu",
      "      af  stuuuu",
      "      af  stuuuu",
      "      af  stuuuu",
      "      ab  stuuww",
      "      af  stwwww",
      "      ab  stwwww",
      "      af  stwwww",
      "      af  xijjjj",
      "      ab  styyyy",
      "      ab  styyyy",
      "      af  styyyy",
      "      ab  styyyy",
      "      af  styyyy",
      "      af  styyyy",
      "      ab  styyyy"
    ],
    [
      "      ab  sj  ee",
      "      af  sj    ",
      "      af  sj    ",
      "      af  sj  gg",
      "      ab  sj AB ",
      "      af  sj    ",
      "      ab  sj    ",
      "      af  sjCDDC",
      "      af   ijjjj",
      "      ab  s EFI ",
      "      ab  s JF  ",
      "      af  s  F K",
      "      ab  s  L K",
      "      af  s  F  ",
      "      af  s   M ",
      "      ab  s jNjK"
    ],
    [
      "      ab   O  ee",
      "      af  sO    ",
      "      af   O    ",
      "      af   O  gg",
      "      ab  sj PQ ",
      "      af  sO    ",
      "      ab   O   R",
      "      af   j SST",
      "      af   ijjjj",
      "      ab  s  UVW",
      "      ab  s X   ",
      "      af     Y Z",
      "      ab  s    0",
      "      af     1  ",
      "      af  s 2   ",
      "      ab  s j3j4"
    ],
    [
      "      ab   j  ee",
      "      af   j    ",
      "      af   j    ",
      "      af   j  gg",
      "      ab   j55Q ",
      "      af   j    ",
      "      ab   j    ",
      "      af   j6778",
      "      af   ijjjj",
      "      ab      9#",
      "      ab        ",
      "      af        ",
      "      ab        ",
      "      af        ",
      "      af        ",
      "      ab    j$j "
    ]
  ]
}