{
  "name": "multi_terraceplaza_2_floor3",
  "refpalette": "deceasedcraft:multi_terraceplaza_2/multi_terraceplaza_2_floor3_palette",
  "xsize": 16,
  "zsize": 16,
  "slices": [
    [
      "      ab  cd  ee",
      "      af   d    ",
      "      af   d    ",
      "      af  cd  gg",
      "      ab  ch ij ",
      "      af   d    ",
      "      ab   d   k",
      "      af  ch llm",
      "      af   nhhhh",
      "      ab  c   oo",
      "      ab  c     ",
      "      af        ",
      "      ab        ",
      "      af  c     ",
      "      af        ",
      "      ab  c     "
    ],
    [
      "      ab   h  ee",
      "      af   h    ",
      "      af   h    ",
      "      af   h  gg",
      "      ab   hppj ",
      "      af   h    ",
      "      ab   h    ",
      "      af   hqrrs",
      "      af   nhhhh",
      "      ab      oo",
      "      ab        ",
      "      af        ",
      "      ab        ",
      "      af        ",
      "      af        ",
      "      ab        "
    ],
    [
      "      ab   heeee",
      "      af   h    ",
      "      af   h    ",
      "      af   hgggg",
      "      ab   hppt ",
      "      af   h    ",
      "      ab   h    ",
      "      af   h    ",
      "      af   nhhhh",
      "      ab      oo",
      "      ab        ",
      "      af        ",
      "      ab        ",
      "      af        ",
      "      af        ",
      "      ab        "
    ],
    [
      "      ab   heeee",
      "      af   h    ",
      "      af   h    ",
      "      af   hgggg",
      "      ab   huuuu",
      "      af   huuuu",
      "      ab   huuuu",
      "      af   huuuu",
      "      af   nhhhh",
      "      ab        ",
      "      ab        ",
      "      af        ",
      "      ab        ",
      "      af        ",
      "      afwwxyyyyy",
      "      abwwABCCCC"
    ],
    [
      "      ab   heeee",
      "      af   h    ",
      "      af   h    ",
      "      af   hgggg",
      "      ab   hD  D",
      "      af   h   D",
      "      ab   h    ",
      "      af   h   D",
      "      af   nhhhh",
      "      ab        ",
      "      ab        ",
      "      afwwxyyyyy",
      "      abwwABCCCC",
      "      afwwEFFFFF",
      "      af  EIIIII",
      "      ab  EJ    "
    ],
    [
      "      ab   hKKKK",
      "      af   huuuu",
      "      af   huuuu",
      "      af   hLLLL",
      "      ab   h    ",
      "      af   h    ",
      "      ab   h    ",
      "      af   h    ",
      "      afwwxnMMMM",
      "      abwwABBBBB",
      "      abwwEFFFFF",
      "      af  EIIIII",
      "      ab  EJ    ",
      "      af  N     ",
      "      af  O     ",
      "                "
    ]
  ]
}