{
  "name": "multi_terraceplaza_2_floor4",
  "refpalette": "deceasedcraft:multi_terraceplaza_2/multi_terraceplaza_2_floor4_palette",
  "xsize": 16,
  "zsize": 16,
  "slices": [
    [
      "      ab   c    ",
      "      ad   c ef ",
      "      ad   c gh ",
      "      ad   c    ",
      "      ab   c    ",
      "      adiijc    ",
      "      abiikc    ",
      "      adiilc    ",
      "      ad  llllll",
      "      ab  llllll",
      "      ab  m     ",
      "      ad  n     ",
      "                ",
      "                ",
      "                ",
      "                "
    ],
    [
      "      ab   c    ",
      "      ad   c op ",
      "      adiijc qr ",
      "      adiikc    ",
      "      abiilc    ",
      "      ad  lljjjj",
      "      ab  llllll",
      "      ad  mmmmmm",
      "      ad  nnnnnn",
      "                ",
      "                ",
      "                ",
      "                ",
      "                ",
      "                ",
      "                "
    ],
    [
      "      abiikc    ",
      "      adiilc  st",
      "      ad  lljjjj",
      "      ad  llllll",
      "      ab  mmmmmm",
      "      ad  nnnnnn",
      "                ",
      "                ",
      "                ",
      "                ",
      "                ",
      "                ",
      "                ",
      "                ",
      "                ",
      "                "
    ],
    [
      "      ab  llllll",
      "      ad  mmmmmm",
      "      ad  nnnnnn",
      "                ",
      "                ",
      "                ",
      "                ",
      "                ",
      "                ",
      "                ",
      "                ",
      "                ",
      "                ",
      "                ",
      "                ",
      "                "
    ],
    [
      "                ",
      "                ",
      "                ",
      "                ",
      "                ",
      "                ",
      "                ",
      "                ",
      "                ",
      "                ",
      "                ",
      "                ",
      "                ",
      "                ",
      "                ",
      "                "
    ],
    [
      "                ",
      "                ",
      "                ",
      "                ",
      "                ",
      "                ",
      "                ",
      "                ",
      "                ",
      "                ",
      "                ",
      "                ",
      "                ",
      "                ",
      "                ",
      "                "
    ]
  ]
}