{
  "name": "multi_terraceplaza_8_ground",
  "refpalette": "deceasedcraft:multi_terraceplaza_8/multi_terraceplaza_8_ground_palette",
  "xsize": 16,
  "zsize": 16,
  "slices": [
    [
      "aaaaaabaaaaaaaac",
      "              ac",
      "              ac",
      "             aac",
      "             acc",
      "            aacc",
      "           aaccc",
      "         aaacccc",
      "aaaaaaaaaacccccc",
      "cccccccccccccccc",
      "cccccccccccccccc",
      "ddddddbeeeeeeeee",
      "ffffffdggggggggg",
      "ffffffdggggggggg",
      "ffffffdggggggggg",
      "ffffffdggggggggg"
    ],
    [
      "hhhhhhbhhhhhhhh ",
      "              h ",
      "              h ",
      "             hh ",
      "             h  ",
      "            hh  ",
      "           hh   ",
      "         hhh    ",
      "hhhhhhhhhh      ",
      "                ",
      "                ",
      "ddddddbiiijkkjii",
      "lmlmlmd    no   ",
      "l l l d    pp   ",
      "qrqrqrd         ",
      "      d         "
    ],
    [
      "      b         ",
      "                ",
      "                ",
      "                ",
      "                ",
      "                ",
      "                ",
      "                ",
      "                ",
      "                ",
      "                ",
      "ddddddbiiij  jii",
      "l l l d    st   ",
      "l l l d         ",
      "quququd         ",
      "      d         "
    ],
    [
      "      b         ",
      "                ",
      "                ",
      "                ",
      "                ",
      "                ",
      "                ",
      "                ",
      "                ",
      "                ",
      "wwww            ",
      "ddddddbiiijxyjii",
      "l l l d    AB   ",
      "l l l d         ",
      "qCqCqCd         ",
      "      d         "
    ],
    [
      "      b         ",
      "                ",
      "                ",
      "                ",
      "                ",
      "                ",
      "                ",
      "                ",
      "                ",
      "                ",
      "DDDD            ",
      "ddddddbiiijjjjii",
      "l l l d         ",
      "l l l d         ",
      "qqqqqqd         ",
      "      d         "
    ],
    [
      "      b         ",
      "                ",
      "                ",
      "                ",
      "                ",
      "                ",
      "                ",
      "                ",
      "                ",
      "                ",
      "EEEE            ",
      "ddddddbiiiiiiiii",
      "FFFFFFd         ",
      "FFFFFFd         ",
      "FFFFFFd         ",
      "FFFFFFd         "
    ]
  ]
}