{
  "name": "multi_terraceplaza_8_floor4",
  "refpalette": "deceasedcraft:multi_terraceplaza_8/multi_terraceplaza_8_floor4_palette",
  "xsize": 16,
  "zsize": 16,
  "slices": [
    [
      "aaaaabcbaaaaaaaa",
      "aaaaabbbaaaaaaaa",
      "aaaaabbbaaaaaaaa",
      "aaaaabbbaaaaaaaa",
      "aaaaabbbaaaaaaaa",
      "aaaaabbbaaaaaaaa",
      "aaaaabbbaaaaaaaa",
      "aaaaabbbaaaaaaaa",
      "aaaaabbbaaaaaaaa",
      "aaaaabbbaaaaaaaa",
      "aaaaabbbaaaaaaaa",
      "ddddddceffffffff",
      "      d         ",
      "      d         ",
      "      d         ",
      "g     d         "
    ],
    [
      "hhhhhhchhhhhhhhh",
      "iiiiiiiiiiiiiiii",
      "iiiiiiiiiiiiiiii",
      "iiiiiiiiiiiiiiii",
      "jjjjjjjjjjjjjjjj",
      "  k lmnopqrstuwx",
      "    kyA B      C",
      "   llDEFI      J",
      "   lKL   F    MN",
      "k  OP  QR Q  STU",
      " kllklVWXYZ01TT2",
      "fffff3c4ffffffff",
      "      d         ",
      "      d         ",
      "      d         ",
      "      d         "
    ],
    [
      "      c         ",
      "                ",
      "     5 6        ",
      " 7 8   9 ! # $ %",
      "jjjjjjjjjjjjjjjj",
      "    k  ^^^^^^^^^",
      "    kP          ",
      "    l           ",
      "   l&           ",
      "   *            ",
      " k lk (^^^^^^^^^",
      "ffff) cfffffffff",
      "      d         ",
      "      d         ",
      "      d         ",
      "      d+++++++++"
    ],
    [
      "      c         ",
      "                ",
      "                ",
      "   -     [      ",
      "jjjjjjjjjjjjjjjj",
      "    lP  ]{}C  |x",
      "    ;P          ",
      "    kP          ",
      "   :l           ",
      "   :kP          ",
      "   k   '  k <>T,",
      "ffff4 cfffffffff",
      "      d+++++++++",
      "      d.........",
      "      d?????????",
      "//////``````````"
    ],
    [
      "      c         ",
      "                ",
      "                ",
      "         \u0370 \u0370 \u0371 \u0372",
      "jjjjjjjjjjjjjjjj",
      "    \u0373P          ",
      "                ",
      "                ",
      "                ",
      "++++++++++++++++",
      "................",
      "\u0374\u0374\u0374\u0374\u0374\u0374c\u0374\u0374\u0374\u0374\u0374\u0374\u0374\u0374\u0374",
      "````````````````",
      "````````````````",
      "\u0375\u0375\u0375\u0375\u0375\u0375\u0375\u0375\u0375\u0375\u0375\u0375\u0375\u0375\u0375\u0375",
      "\u0376\u0376\u0376\u0376\u0376\u0376\u0376\u0376\u0376\u0376\u0376\u0376\u0376\u0376\u0376\u0376"
    ],
    [
      "      c         ",
      "                ",
      "                ",
      "                ",
      "jjjjjjjjjjjjjjjj",
      "                ",
      "++++++++++++++++",
      "................",
      "????????????????",
      "````````````````",
      "````````````````",
      "\u0375\u0375\u0375\u0375\u0375\u0375\u0375\u0375\u0375\u0375\u0375\u0375\u0375\u0375\u0375\u0375",
      "\u0376\u0376\u0376\u0376\u0376\u0376\u0376\u0376\u0376\u0376\u0376\u0376\u0376\u0376\u0376\u0376",
      "                ",
      "                ",
      "                "
    ]
  ]
}