{
  "name": "multi_terraceplaza_8_base1",
  "refpalette": "deceasedcraft:multi_terraceplaza_8/multi_terraceplaza_8_base1_palette",
  "xsize": 16,
  "zsize": 16,
  "slices": [
    [
      "HHHHHHaHHHHHHHHH",
      "HHHHHHHHHHHHHHHH",
      "HHHHHHHHHHHHHHHH",
      "HHHHHHHHHHHHHHHH",
      "HHHHHHHHHHHHHHHH",
      "        bcHHHHHH",
      "        bcHHHHHH",
      "        bcHHHHHH",
      "dddddddddddddHHH",
      "eeeeeeeeeeeeeeee",
      "eeeeeeeeeeeeeeee",
      "ddddddafffffffff",
      "ggggggdhhhhhhhhh",
      "ggggggdhhhhhhhhh",
      "ggggggdhhhhhhhhh",
      "ggggggdhhhhhhhhh"
    ],
    [
      "iiiiiiaiiiiiiiij",
      "               j",
      "               j",
      "               j",
      "kkkkkkkkkkkk   j",
      "     bcHHlm    j",
      "     bcHHlm    j",
      "     bcHHlm    j",
      "dddddddddddno  j",
      "                ",
      "                ",
      "ddddddapppppppqr",
      "s!ststd         ",
      "s s s d         ",
      "uwuxuxd         ",
      "      d         "
    ],
    [
      "      a         ",
      "                ",
      "                ",
      "                ",
      " k  kkkkk       ",
      "  bcHHlm        ",
      "  bcHHlm        ",
      "  bcHHlm        ",
      "ddddddddno      ",
      "                ",
      "                ",
      "ddddddapppppppqy",
      "s s s d         ",
      "s s s d         ",
      "uAuBuBd         ",
      "      d         "
    ],
    [
      "      a         ",
      "                ",
      "                ",
      "                ",
      " kkkkk          ",
      "cHHlm           ",
      "cHHlm           ",
      "cHHlm           ",
      "dddddno         ",
      "                ",
      "                ",
      "ddddddapppppppqC",
      "s s s d        D",
      "s s s d         ",
      "uEuEuEd         ",
      "      d         "
    ],
    [
      "      a         ",
      "                ",
      "                ",
      "                ",
      "kkk             ",
      "lm              ",
      "lm              ",
      "lm              ",
      "ddno            ",
      "                ",
      "                ",
      "ddddddapppppppqq",
      "s s s d         ",
      "s s s d         ",
      "uuuuuud         ",
      "      d         "
    ],
    [
      "FFFFFFaFFFFFFFFF",
      "               I",
      "               I",
      "               I",
      "              II",
      "              IJ",
      "             IIJ",
      "            IIJJ",
      "o         IIIJJJ",
      "JJJJJJJJJJJJJJJJ",
      "JJJJJJJJJJJJJJJJ",
      "FFFFFFaFFFFFFFFF",
      "KKKKKKFLLLLLLLLL",
      "KKKKKKFLLLLLLLLL",
      "KKKKKKFLLLLLLLLL",
      "KKKKKKFLLLLLLLLL"
    ]
  ]
}