{
  "name": "multi_terraceplaza_8_floor5",
  "refpalette": "deceasedcraft:multi_terraceplaza_8/multi_terraceplaza_8_floor5_palette",
  "xsize": 16,
  "zsize": 16,
  "slices": [
    [
      "      a         ",
      "                ",
      "                ",
      "bbbbbbbbbbbbbbbb",
      "cccccccccccccccc",
      "dddddddddddddddd",
      "eeeeeeeeeeeeeeee",
      "eeeeeeeeeeeeeeee",
      "ffffffffffffffff",
      "gggggggggggggggg",
      "                ",
      "                ",
      "                ",
      "                ",
      "                ",
      "                "
    ],
    [
      "hhhhhhahhhhhhhhh",
      "cccccccccccccccc",
      "dddddddddddddddd",
      "eeeeeeeeeeeeeeee",
      "eeeeeeeeeeeeeeee",
      "ffffffffffffffff",
      "gggggggggggggggg",
      "                ",
      "                ",
      "                ",
      "                ",
      "                ",
      "                ",
      "                ",
      "                ",
      "                "
    ],
    [
      "eeeeeeeeeeeeeeee",
      "eeeeeeeeeeeeeeee",
      "ffffffffffffffff",
      "gggggggggggggggg",
      "                ",
      "                ",
      "                ",
      "                ",
      "                ",
      "                ",
      "                ",
      "                ",
      "                ",
      "                ",
      "                ",
      "                "
    ],
    [
      "                ",
      "                ",
      "                ",
      "                ",
      "                ",
      "                ",
      "                ",
      "                ",
      "                ",
      "                ",
      "                ",
      "                ",
      "                ",
      "                ",
      "                ",
      "                "
    ],
    [
      "                ",
      "                ",
      "                ",
      "                ",
      "                ",
      "                ",
      "                ",
      "                ",
      "                ",
      "                ",
      "                ",
      "                ",
      "                ",
      "                ",
      "                ",
      "                "
    ],
    [
      "                ",
      "                ",
      "                ",
      "                ",
      "                ",
      "                ",
      "                ",
      "                ",
      "                ",
      "                ",
      "                ",
      "                ",
      "                ",
      "                ",
      "                ",
      "                "
    ]
  ]
}