{
  "name": "multi_terraceplaza_8_base2",
  "refpalette": "deceasedcraft:multi_terraceplaza_8/multi_terraceplaza_8_base2_palette",
  "xsize": 16,
  "zsize": 16,
  "slices": [
    [
      "HHHHHHaHHHHHHHHH",
      "HHHHHHHHHHHHHHHH",
      "HHHHHHHHHHHHHHHH",
      "HHHHHHHHHHHHHHHH",
      "HHHHHHHHHHHHHHHH",
      "bbbbbbbbHHHHHHHH",
      "bbbbbbbbHHHHHHHH",
      "bbbbbbbbHHHHHHHH",
      "cccccccccccccHHH",
      "dddddddddddddddd",
      "dddddddddddddddd",
      "bbbcccaeeeeeeeee",
      "bbbbbbcffffgffff",
      "bbbbbbcffhhiffff",
      "bbbbbbcfffffffff",
      "bbbbbbcfffffffff"
    ],
    [
      "jjjjjjajjjjjjjjk",
      "               k",
      "               k",
      "               k",
      " l  l  lllll   k",
      "     mnHHop    k",
      "     mnHHop    k",
      "     mnHHop    k",
      "ccccccccccccc  k",
      "                ",
      "                ",
      "   cccaqqqqqqqrs",
      "    tuc  wxyyy  ",
      "     uc wAA BC  ",
      "     uc         ",
      "    t c         "
    ],
    [
      "      a         ",
      "                ",
      "                ",
      "                ",
      " l  lllll       ",
      "  mnHHop        ",
      "  mnHHop        ",
      "  mnHHop        ",
      "ccccccccccccc   ",
      "                ",
      "   D            ",
      "EEEcccaqqqqqqqrF",
      "      c     IJ  ",
      "      c         ",
      "      c         ",
      "      c         "
    ],
    [
      "      a         ",
      "                ",
      "                ",
      "                ",
      " lllll          ",
      "nHHop           ",
      "nHHop           ",
      "nHHop           ",
      "ccccccccccccc   ",
      "                ",
      "                ",
      "EEEcccaqqqqqqqrK",
      "      c        L",
      "      c         ",
      "      c         ",
      "      c         "
    ],
    [
      "      a         ",
      "                ",
      "                ",
      "                ",
      "lll             ",
      "op              ",
      "op              ",
      "op              ",
      "ccccccccccccc M ",
      "                ",
      "                ",
      "ccccccaqqqqqqqrr",
      "NNN   c         ",
      "      c         ",
      "      c         ",
      "      c         "
    ],
    [
      "OOOOOOaOOOOOOOOO",
      "PPPPPPPPPPPPPPPP",
      "PPPPPPPPPPPPPPPP",
      "PPPQPPPPPQPPPPQP",
      "PPPPPPPPPPPPPPPP",
      "           PPPPP",
      "           PPPPP",
      "           PPPPP",
      "cccccccccccccPQP",
      "PPPPPPPPPPPPPPPP",
      "PPPPPPPPPPPPPPPP",
      "OOOOOOaOOOOOOOOO",
      "PPPPPPORRRRRRRRR",
      "PPPPPPORRRRRRRRR",
      "PPPPPPORRRRRRRRR",
      "PPPPPPORRRRRRRRR"
    ]
  ]
}