{
  "name": "multi_terraceplaza_8_floor2",
  "refpalette": "deceasedcraft:multi_terraceplaza_8/multi_terraceplaza_8_floor2_palette",
  "xsize": 16,
  "zsize": 16,
  "slices": [
    [
      "aaaaaabaaaaaaaaa",
      "                ",
      "                ",
      "                ",
      "                ",
      "                ",
      "                ",
      "                ",
      "                ",
      "                ",
      "  c !           ",
      "ddddddbeef    fe",
      "g g g d         ",
      "g g g d         ",
      "hhhhhhd         ",
      "      d         "
    ],
    [
      "iiiiiibiiiiiiiii",
      "      j         ",
      "                ",
      "                ",
      "                ",
      "                ",
      "                ",
      "                ",
      "                ",
      "                ",
      "                ",
      "ddddddbkkkkkkkkk",
      "lllllld  mmnnnm ",
      "lllllld         ",
      "lllllld         ",
      "lllllld         "
    ],
    [
      "oooooobooooooooo",
      "                ",
      "                ",
      "                ",
      "                ",
      "                ",
      "                ",
      "                ",
      "                ",
      "                ",
      "                ",
      "ddddddbkkkkkkkkk",
      "pq p pd         ",
      "rq rqrd         ",
      "rrrrrrd         ",
      "rq   qd         "
    ],
    [
      "ssssssbsssssssss",
      "llllllslllllllll",
      "llllllslllllllll",
      "llllllslllllllll",
      "llllllslllllllll",
      "llllllslllllllll",
      "llllllslllllllll",
      "llllllslllllllll",
      "llllllslllllllll",
      "llllllslllllllll",
      "llllllslllllllll",
      "ssssssbsssssssss",
      "tqqt tsuuuuuuuuu",
      "     qsuuuuuuuuu",
      "      suuuuuuuuu",
      "     qsuuuuuuuuu"
    ],
    [
      "wwwwxxbxxxxxxxxx",
      "wwwwxxxxxxxxxxxx",
      "wwwwxxxxyABxxBAC",
      "wwwwxxxx BBxxBB ",
      "wwwwxxxx BBxxBB ",
      "wwwwxxxx BBxxBB ",
      "wwwwxxxx BBxxBB ",
      "wwwwxxxx DBxxBD ",
      "wwwwxxxxxxxxxxxx",
      "wwwwxxxxxxxxxxxx",
      "wwwwxxxxxxxxxxxx",
      "ddddddbEEEEEEEEE",
      "FFFFFFdIIIIIIIII",
      "FFFFFFdIIIIIIIII",
      "FFFFFFdIIIIIIIII",
      "FFFFFFdIIIIIIIII"
    ],
    [
      "JKL MNb         ",
      " O  M   P      P",
      "   QMR  S  TU  V",
      " W  MR  SX TU XV",
      "YZ0 M1  SX TU XV",
      " 2  MR  SX TU XV",
      "   QM   SX TU XV",
      "345 MR  6  TU  7",
      "89# MR  $      $",
      "%^& MR          ",
      "   QM*          ",
      "ddddddbeef    fe",
      "g(g(g(d)        ",
      "g g g d +       ",
      "h-h-h-d         ",
      "      d         "
    ]
  ]
}