{
  "name": "multi_terraceplaza_8_floor3",
  "refpalette": "deceasedcraft:multi_terraceplaza_8/multi_terraceplaza_8_floor3_palette",
  "xsize": 16,
  "zsize": 16,
  "slices": [
    [
      "    abcd        ",
      "    ae          ",
      "   fae          ",
      "    ae         g",
      " h  ae  i      j",
      "    ae  k       ",
      "   fae  l      m",
      "    ae  n      o",
      "    ae          ",
      "    ae          ",
      "   fae          ",
      "ppppppcqqr    rq",
      "s s s p         ",
      "s s s p         ",
      "tututup         ",
      "      p         "
    ],
    [
      "    abc         ",
      "    aw          ",
      "    aw          ",
      "    ax          ",
      " y  aA          ",
      "    aB          ",
      "    aw          ",
      "    aw          ",
      "    aw          ",
      "    a           ",
      "    aw          ",
      "ppppppcqqr    rq",
      "s s s p         ",
      "s s s p         ",
      "tCtCtCp         ",
      "      p         "
    ],
    [
      "DED abc         ",
      "FDF ae          ",
      "    ae          ",
      "FDF ae          ",
      "DID ae          ",
      "FDF ae          ",
      "    ae          ",
      "    ae          ",
      "    ae          ",
      "    ae          ",
      "    ae          ",
      "ppppppcqqr    rq",
      "s s s p         ",
      "s s s p         ",
      "ttttttp         ",
      "      p         "
    ],
    [
      "    abc         ",
      "    a           ",
      "    aJ          ",
      "    aw          ",
      "    a           ",
      "    aw          ",
      "    aK          ",
      "    aw          ",
      "    aL          ",
      "    aw          ",
      "    a M  NNNNNN ",
      "ppppppcOOOOOOOOO",
      "PPPPPPp         ",
      "PPPPPPp         ",
      "PPPPPPp         ",
      "PPPPPPp         "
    ],
    [
      "    abc         ",
      "    a           ",
      "    a           ",
      "    a           ",
      "    a           ",
      "    a           ",
      "    a           ",
      "    a           ",
      "    a           ",
      "    a           ",
      "    a           ",
      "ppppppcOOOOOOOOO",
      "QRS  Op         ",
      "TRU   p         ",
      "QVW X p         ",
      "YVV   p         "
    ],
    [
      "    abc         ",
      "    a           ",
      "    a           ",
      "    a           ",
      "    a           ",
      "    a           ",
      "    a           ",
      "    a           ",
      "    a           ",
      "    a           ",
      "    a           ",
      "ppppppcOOOOOOOOO",
      "      p         ",
      " U    p         ",
      "      p         ",
      "Z     p         "
    ]
  ]
}