{
  "name": "multi_terraceplaza_8_floor1",
  "refpalette": "deceasedcraft:multi_terraceplaza_8/multi_terraceplaza_8_floor1_palette",
  "xsize": 16,
  "zsize": 16,
  "slices": [
    [
      "      a         ",
      "                ",
      "                ",
      "                ",
      "                ",
      "                ",
      "                ",
      "                ",
      "                ",
      "                ",
      "                ",
      "bbbbbbaccccccccc",
      "d ededb         ",
      "f  f fb         ",
      "ffffffb         ",
      "f  e eb         "
    ],
    [
      "ggggggaggggggggg",
      "hhhhhhghhhhhhhhh",
      "iiiiihghiiiiiiii",
      "jjjjihghijjjjjji",
      "kkkjihghijkkkkji",
      "kkkjihghijkkkkji",
      "kkkjihghijkkkkji",
      "kkkjihghijkkkkji",
      "jjjjihghijjjjjji",
      "iiiiihghiiiiiiii",
      "hhhhhhghhhhhhhhh",
      "ggggggaggggggggg",
      "l  l lgkkkkkkkkk",
      "     egkkkkkkkkk",
      "      gkkkkkkkkk",
      "e     gkkkkkkkkk"
    ],
    [
      "mmmmmmammmmmmmmm",
      "nnnnnooonnnnnnnn",
      "oooooooooooooooo",
      "oooooooooooooooo",
      "oooooooooooooooo",
      "nnnnoooooooooooo",
      "nnnnoooooooooooo",
      "oooooooooooooooo",
      "oooooooooooooooo",
      "oooooooooooooooo",
      "nnnnnooooooooooo",
      "bbbbbbappppppppp",
      "qqqqqqbrrrrrrrrr",
      "qqqqqqbrrrrrrrrr",
      "qqqqqqbrrrrrrrrr",
      "qqqqqqbrrrrrrrrr"
    ],
    [
      "ssssssasssssssss",
      "ttttu   wttttttu",
      "          x     ",
      "                ",
      "        yy   xAy",
      "tttu    AyB   yA",
      "tttu    yy    yy",
      "        yA    yy",
      "                ",
      "                ",
      "ttttu           ",
      "bbbbbbaCCD    DC",
      "EFEFEFb         ",
      "E E E b         ",
      "IJIJIJb         ",
      "      b         "
    ],
    [
      "KKKKKKaKKKKKKKKK",
      "LMNON    P QPPPQ",
      "                ",
      "                ",
      "        RS     T",
      "UVUV    RS    WX",
      "YZYZ    R0    WX",
      "        RS    WA",
      "                ",
      "                ",
      "1 2 34          ",
      "bbbbbbaCCD    DC",
      "E E E b         ",
      "E E E b         ",
      "I5I5I5b         ",
      "      b         "
    ],
    [
      "KKKKKKaKKKKKKKKK",
      "                ",
      "                ",
      "                ",
      "               6",
      "        B     B ",
      "                ",
      "               6",
      "                ",
      "                ",
      "  7 7           ",
      "bbbbbbaCCD    DC",
      "E E E b         ",
      "E E E b         ",
      "I8I8I8b         ",
      "      b         "
    ]
  ]
}