{
  "name": "multi_oasiscondo_2_base1",
  "refpalette": "deceasedcraft:multi_oasiscondo_2/multi_oasiscondo_2_base1_palette",
  "xsize": 16,
  "zsize": 16,
  "slices": [
    [
      "vHHHHHHHav      ",
      "vHHHHHHHav      ",
      "vHHHHHHHav      ",
      "vHHHHHHHav      ",
      "vHHHHHHHavb     ",
      "vHHHHHHHav      ",
      "vHHHHHHHav      ",
      "vHHHHHHHav      ",
      "vHHHHHHHav      ",
      "vHHHHHHHav      ",
      "vHHHHHHHav      ",
      "vHHHHHHHav      ",
      "vHHHHHHHavcccccc",
      "vHHHHHHHaabddddd",
      "vHHHHHHHaaaaHHHa",
      "vHHHHHHHHaaHHHHH"
    ],
    [
      "ve  f    v      ",
      "vg  h    v      ",
      "ve  f    v      ",
      "vg  h    v      ",
      "ve  f    vb     ",
      "vg  h    v      ",
      "ve  f    v      ",
      "vg  h    v      ",
      "ve if    v      ",
      "vg  h    vcccccc",
      "ve  f    vdddddd",
      "vg  h    vjjjjjj",
      "ve  f    vaaHHHa",
      "vg  h    kblmmml",
      "ve  f     nnooon",
      "vg  h           "
    ],
    [
      "v        v      ",
      "v        v      ",
      "v        v      ",
      "v        v      ",
      "v        vb     ",
      "v        v      ",
      "v        vcccccc",
      "v        vdddddd",
      "v        vjjjjjj",
      "v        vaaHHHa",
      "v        vllmmml",
      "v        vnnooon",
      "v        v      ",
      "v         b     ",
      "v               ",
      "v               "
    ],
    [
      "v        v      ",
      "v        v      ",
      "v        v      ",
      "v        vcccccc",
      "v        vbddddd",
      "v        vjjjjjj",
      "v        vaaHHHa",
      "v        vllmmml",
      "v        vnnooon",
      "v        v      ",
      "v        v      ",
      "v        v      ",
      "v        v      ",
      "v         b     ",
      "v               ",
      "v               "
    ],
    [
      "v        vcccccc",
      "v        vdddddd",
      "v        vjjjjjj",
      "v        vaaHHHa",
      "v        vblmmml",
      "v        vnnooon",
      "v        v      ",
      "v        v      ",
      "v        v      ",
      "v        v      ",
      "v        v      ",
      "v        v      ",
      "v        v      ",
      "v         bppppp",
      "v               ",
      "v               "
    ],
    [
      "vccccccccvaaHHHa",
      "vccccccccvllmmml",
      "vccccccccvnnooon",
      "vccccccccv      ",
      "vqqqqqqqqqr     ",
      "vccccccccv      ",
      "vccccccccv      ",
      "vccccccccv      ",
      "vccccccccv      ",
      "vccccccccv      ",
      "vccccccccv      ",
      "vccccccccv      ",
      "vccccccccv      ",
      "vqqqqqqqqqrqqqqq",
      "vcccccccccqccccc",
      "vcccccccccqccccc"
    ]
  ]
}