{
  "name": "multi_oasiscondo_2_floor4",
  "refpalette": "deceasedcraft:multi_oasiscondo_2/multi_oasiscondo_2_floor4_palette",
  "xsize": 16,
  "zsize": 16,
  "slices": [
    [
      "         aaaaaab",
      "         aaaaaab",
      "         aaaaaab",
      "         caaaaab",
      "          dddddd",
      "         caaaaab",
      "         aaaaaae",
      "         aaaaaab",
      "         a aaaab",
      "         aaaaaab",
      "         aaaaaab",
      "         aaaaaab",
      "         caaaaab",
      "          dddddd",
      "         caaaaab",
      "         aaaaaae"
    ],
    [
      "        bf b   b",
      "        bg bh  b",
      "        bijb k b",
      "        lbmbnopb",
      "          dddddd",
      "       qqqrsrtub",
      "       wq  x tyA",
      "       wBh  CDEb",
      "       wBF  I Jb",
      "       wB KoLMNb",
      "       wB Obbbbb",
      "       wqP Q  Rb",
      "       qqqSbiTUb",
      "          dddddd",
      "        lb VWtub",
      "        bX  Yt Z"
    ],
    [
      "        01 b   b",
      "        0  b   b",
      "        b  b   b",
      "        l23b456b",
      "          dddddd",
      "       qqq7 8t b",
      "       9q    t #",
      "       $%      ^",
      "       $%      b",
      "       $%  &*( b",
      "       $%  bbbbb",
      "       $q) + -[b",
      "       qqqSb  ]b",
      "          dddddd",
      "        {b}  t|b",
      "        b;  :t '"
    ],
    [
      "        0< b   b",
      "        0  b   b",
      "        2  b   b",
      "        {b>b,.?b",
      "          dddddd",
      "       qqq   t/b",
      "        q    t `",
      "        %    D b",
      "        %      b",
      "        %   \u0370\u0371\u0372b",
      "        %  bbbbb",
      "        q  \u0373  \u0374b",
      "       qqq\u0375b  \u0376b",
      "          dddddd",
      "        lb   t/b",
      "        2    t `"
    ],
    [
      "        0\u0377\u0377b   b",
      "        0\u0377\u0377b   b",
      "        b\u0377\u0377b \u037a b",
      "        {b\u037ab\u037b\u037b\u037bb",
      "          dddddd",
      "       qqq   t b",
      "        q    t b",
      "        \u037c  \u037d D b",
      "        \u037c      b",
      "        \u037c   \u037e  b",
      "        \u037c  bbbbb",
      "        q \u0375b\u0377\u0377\u0377b",
      "       qqq!b\u0377\u0377\u0377b",
      "          dddddd",
      "        lb   t b",
      "        b    t b"
    ],
    [
      "        2  \u037f\u037f\u037f\u037fb",
      "        b  \u037f\u037f\u037f\u037fb",
      "        b\u0384 \u037f\u037f\u037f\u037fb",
      "        l2\u037f\u037f\u037f\u037f\u037fb",
      "          dddddd",
      "       qqq\u037f\u037f\u037f\u037f\u037fb",
      "       qq\u037f\u037f\u037f\u037f\u037f\u037fb",
      "       qq\u037f\u037f\u037f\u037f\u037f\u037fb",
      "       qq\u037f\u037f\u037f\u037f\u037f\u037fb",
      "       qq\u037f\u037f\u037f\u037f\u037f\u037fb",
      "       qq\u037f\u037f\u037f\u037f\u037f\u037fb",
      "       qq\u037f\u037f\u037f   b",
      "       qqq\u037f\u037f  \u0384b",
      "          dddddd",
      "        {2\u037f\u037f\u037f\u037f\u037fb",
      "        b\u037f\u037f\u037f\u037f\u037f\u037fb"
    ]
  ]
}