{
  "name": "multi_oasiscondo_2_floor3",
  "refpalette": "deceasedcraft:multi_oasiscondo_2/multi_oasiscondo_2_floor3_palette",
  "xsize": 16,
  "zsize": 16,
  "slices": [
    [
      "         aaaaaab",
      "         aaaaaab",
      "         aaaaaab",
      "         caaaaab",
      "          dddddd",
      "         caaaaab",
      "         aaaaaae",
      "         aaaaaab",
      "         aaaaaab",
      "         aaaaaab",
      "         aaaaaab",
      "         aaaaaab",
      "         caaaaab",
      "          dddddd",
      "         caaaaab",
      "         aaaaaae"
    ],
    [
      "        bf b g b",
      "        b hb  ib",
      "        bj b klb",
      "        mbnbopqb",
      "          dddddd",
      "        mbrrrstb",
      "        bu w s x",
      "        y    ABb",
      "        bCDC E b",
      "        bF bIJ b",
      "        y  bK  b",
      "        bLMbNKOb",
      "        mP!bQQRb",
      "          dddddd",
      "        Sb TUVWb",
      "        yX  YVZx"
    ],
    [
      "        0  b   b",
      "        0  b  1b",
      "        y  b  2b",
      "        mb3b4 5b",
      "          dddddd",
      "        Sy   V b",
      "        b    6 7",
      "        0     8b",
      "        0C9C E b",
      "        0  b   b",
      "        0  b# $b",
      "        y  b   b",
      "        %^3bKB b",
      "          dddddd",
      "        Sy   V&b",
      "        y*  (V 7"
    ],
    [
      "        0) b   b",
      "        0+ b  -b",
      "        b  b  [b",
      "        mb]b  {b",
      "          dddddd",
      "        Sb   V}b",
      "        b    s |",
      "        0    6 b",
      "        0C;C A b",
      "        0  b   b",
      "        0  b   b",
      "        b  b   b",
      "        my]b:::b",
      "          dddddd",
      "        mb   V'b",
      "        b    V |"
    ],
    [
      "        0<<b   b",
      "        0<<b  >b",
      "        b<<b , b",
      "        Sy,b  .b",
      "          dddddd",
      "        mb   V b",
      "        y  ? V b",
      "        0    s b",
      "        0CCCCV b",
      "        0<<b   b",
      "        0<<b   b",
      "        y<<b ? b",
      "        mb?b   b",
      "          dddddd",
      "        mb   V b",
      "        b  / V b"
    ],
    [
      "        b  ````b",
      "        y  ````b",
      "        y\u0370 ````b",
      "        Sb`````b",
      "          dddddd",
      "        Sy`````b",
      "        y``````b",
      "        b``````b",
      "        b``````b",
      "        y  ````b",
      "        y  ````b",
      "        b\u0370 ````b",
      "        Sy`````b",
      "          dddddd",
      "        Sb`````b",
      "        y``````b"
    ]
  ]
}