{
  "name": "multi_oasiscondo_2_floor6",
  "refpalette": "deceasedcraft:multi_oasiscondo_2/multi_oasiscondo_2_floor6_palette",
  "xsize": 16,
  "zsize": 16,
  "slices": [
    [
      "         aaaaaab",
      "         aaaaaab",
      "         aaaaaab",
      "         aaaaaab",
      "         aaaaaaa",
      "         aaaaaab",
      "         aaaaaab",
      "         aaaaaab",
      "         aaaaaab",
      "         aaaaaab",
      "         aaaaaab",
      "         aaaaaab",
      "         caaaaab",
      "          dddddd",
      "         caaaaab",
      "         aaaaaae"
    ],
    [
      "        bf b g b",
      "        h  bi jb",
      "        b kbl mb",
      "        hnobpppb",
      "        qrrrrsrb",
      "        h tuwwxb",
      "        q   yABb",
      "        qCDg  Eb",
      "        hCD   Fb",
      "        hIIIIJIb",
      "        KLAkM Nb",
      "        hO  P Nb",
      "        QRSSbTUb",
      "          dddddd",
      "        VhWXWM!b",
      "        bY Z M 0"
    ],
    [
      "        1  b   b",
      "        1  b   b",
      "        1  b   b",
      "        1 2b   b",
      "        3rrrr4rb",
      "        1  t56Wb",
      "        1      b",
      "        1      b",
      "        1      b",
      "        1IIII7Ib",
      "        1   M  b",
      "        89  #$ b",
      "        Qh %b ^b",
      "          dddddd",
      "        &b* (M)b",
      "        b+   M -"
    ],
    [
      "        1[ b   b",
      "        1  b   b",
      "        1  b   b",
      "        1 ]b   b",
      "        3rrrr{rb",
      "        1    }gb",
      "        1      b",
      "        1      b",
      "        1      b",
      "        1IIII|Ib",
      "        1   M ;b",
      "        q:  ' <b",
      "        &q>,bb.b",
      "          dddddd",
      "        &b   M?b",
      "        b    M /"
    ],
    [
      "        1``b   b",
      "        1``b   b",
      "        1``b \u0370 b",
      "        1 \u0371b   b",
      "        3rrrrrrb",
      "        1 \u0372  \u0372 b",
      "        1      b",
      "        1      b",
      "        1 \u0372  \u0371 b",
      "        1IIIIIIb",
      "        1 ``M  b",
      "        h\u0372``M\u0371 b",
      "        &q``bbbb",
      "          dddddd",
      "        Vb   M b",
      "        b  \u0370 M b"
    ],
    [
      "        h  \u0373\u0373\u0373\u0373b",
      "        b  \u0373\u0373\u0373\u0373b",
      "        h\u0374 \u0373\u0373\u0373\u0373b",
      "        h\u0373\u0373\u0373\u0373\u0373\u0373b",
      "        b\u0373\u0373\u0373\u0373\u0373\u0373b",
      "        b\u0373\u0373\u0373\u0373\u0373\u0373b",
      "        b\u0373\u0373\u0373\u0373\u0373\u0373b",
      "        h\u0373\u0373\u0373\u0373\u0373\u0373b",
      "        h\u0373\u0373\u0373\u0373\u0373\u0373b",
      "        b\u0373\u0373\u0373\u0373\u0373\u0373b",
      "        h\u0373  \u0373\u0373\u0373b",
      "        b\u0373  \u0373\u0373\u0373b",
      "        &h\u0374 \u0373\u0373\u0373b",
      "          dddddd",
      "        &b\u0373\u0373\u0373\u0373\u0373b",
      "        b\u0373\u0373\u0373\u0373\u0373\u0373b"
    ]
  ]
}