{
  "name": "multi_oasiscondo_2_top",
  "refpalette": "deceasedcraft:multi_oasiscondo_2/multi_oasiscondo_2_top_palette",
  "xsize": 16,
  "zsize": 16,
  "slices": [
    [
      "         abbbbbb",
      "         abbbbbb",
      "         abbbbbb",
      "         abbbbbb",
      "         acbbbbb",
      "         abbbbbb",
      "         abbbbbb",
      "         abbbbbb",
      "         abbbbbb",
      "         abbbbbb",
      "         abbbbbb",
      "         abbbbbb",
      "         abbbbbb",
      "         acbbbbb",
      "         abbbbbb",
      "         abbbbbb"
    ],
    [
      "       dee      ",
      "       defg g hi",
      "       defjkl hi",
      "       defm m   ",
      "       de!c     ",
      "       defg g   ",
      "       defjkl hi",
      "       defm m hi",
      "       dee      ",
      "       dee      ",
      "       defg g hi",
      "       defjkl hi",
      "       defm m   ",
      "       de c     ",
      "       defg g   ",
      "       defjkl   "
    ],
    [
      "       n        ",
      "       n o      ",
      "       n op q   ",
      "       n o      ",
      "       n rc     ",
      "       n o      ",
      "       n o     s",
      "       n o     t",
      "       n        ",
      "       n        ",
      "       n o      ",
      "       n ouw    ",
      "       n o      ",
      "       n xc     ",
      "       n o      ",
      "       n o      "
    ],
    [
      "                ",
      "                ",
      "                ",
      "                ",
      "          c     ",
      "                ",
      "                ",
      "                ",
      "                ",
      "                ",
      "                ",
      "                ",
      "                ",
      "          c     ",
      "                ",
      "                "
    ],
    [
      "                ",
      "                ",
      "                ",
      "                ",
      "          c     ",
      "                ",
      "                ",
      "                ",
      "                ",
      "                ",
      "                ",
      "                ",
      "                ",
      "          c     ",
      "                ",
      "                "
    ],
    [
      "                ",
      "                ",
      "                ",
      "                ",
      "          c     ",
      "                ",
      "                ",
      "                ",
      "                ",
      "                ",
      "                ",
      "                ",
      "                ",
      "         yc     ",
      "                ",
      "                "
    ],
    [
      "                ",
      "                ",
      "                ",
      "                ",
      "         Ac     ",
      "                ",
      "                ",
      "                ",
      "                ",
      "                ",
      "                ",
      "                ",
      "                ",
      "         Ac     ",
      "                ",
      "                "
    ],
    [
      "                ",
      "                ",
      "                ",
      "                ",
      "         Bc     ",
      "                ",
      "                ",
      "                ",
      "                ",
      "                ",
      "                ",
      "                ",
      "                ",
      "          c     ",
      "                ",
      "                "
    ],
    [
      "                ",
      "                ",
      "                ",
      "                ",
      "          c     ",
      "                ",
      "                ",
      "                ",
      "                ",
      "                ",
      "                ",
      "                ",
      "                ",
      "          c     ",
      "                ",
      "                "
    ],
    [
      "                ",
      "                ",
      "                ",
      "                ",
      "          c     ",
      "                ",
      "                ",
      "                ",
      "                ",
      "                ",
      "                ",
      "                ",
      "                ",
      "          c     ",
      "                ",
      "                "
    ],
    [
      "        C       ",
      "        C       ",
      "        C       ",
      "        C       ",
      "        C c     ",
      "        C       ",
      "        C       ",
      "        C       ",
      "        C       ",
      "        C       ",
      "        C       ",
      "        C       ",
      "        C       ",
      "        C c     ",
      "        C       ",
      "        C       "
    ],
    [
      "       DDDEEEEEE",
      "       DDDEEEEEE",
      "       DDDEEEEEE",
      "       DDDEEEEEE",
      "       DDDcEEEEE",
      "       DDDEEEEEE",
      "       DDDEEEEEE",
      "       DDDEEEEEE",
      "       DDDEEEEEE",
      "       DDDEEEEEE",
      "       DDDEEEEEE",
      "       DDDEEEEEE",
      "       DDDEEEEEE",
      "       DDDcEEEEE",
      "       DDDEEEEEE",
      "       DDDEEEEEE"
    ],
    [
      "         aFIIIII",
      "         aFIIIII",
      "         aFIIIII",
      "         aFIIIII",
      "         aFIIIII",
      "         aFIIIII",
      "         aFIIIII",
      "         aFIIIII",
      "         aFIIIII",
      "         aFIIIII",
      "         aFIIIII",
      "         aFIIIII",
      "         aFIIIII",
      "         aFIIIII",
      "         aFIIIII",
      "         aFIIIII"
    ],
    [
      "          J  K  ",
      "          J  K L",
      "          J  K L",
      "          J  K L",
      "          JMNKO ",
      "          J  K  ",
      "          J  K  ",
      "          J  K  ",
      "          J  K  ",
      "          J  K P",
      "          J  K P",
      "          J  K P",
      "          J  K  ",
      "          JMNKO ",
      "          J  K P",
      "          J  K P"
    ],
    [
      "          J     ",
      "          J    L",
      "          J  KKK",
      "          J    L",
      "          J     ",
      "          J     ",
      "          J     ",
      "          J     ",
      "          J     ",
      "          J    Q",
      "          J     ",
      "          J    R",
      "          J     ",
      "          J     ",
      "          J    Q",
      "          J     "
    ],
    [
      "                ",
      "               L",
      "               L",
      "               L",
      "                ",
      "                ",
      "                ",
      "                ",
      "                ",
      "               S",
      "               T",
      "               U",
      "                ",
      "                ",
      "               S",
      "               T"
    ],
    [
      "                ",
      "                ",
      "                ",
      "                ",
      "                ",
      "                ",
      "                ",
      "                ",
      "                ",
      "               V",
      "               W",
      "               X",
      "                ",
      "                ",
      "               V",
      "               W"
    ],
    [
      "                ",
      "                ",
      "                ",
      "                ",
      "                ",
      "                ",
      "                ",
      "                ",
      "                ",
      "               Y",
      "               Z",
      "               0",
      "                ",
      "                ",
      "               Y",
      "               Z"
    ],
    [
      "                ",
      "                ",
      "                ",
      "                ",
      "                ",
      "                ",
      "                ",
      "                ",
      "                ",
      "               1",
      "               2",
      "               3",
      "                ",
      "                ",
      "               1",
      "               2"
    ]
  ]
}