{
  "name": "multi_oasiscondo_2_base2",
  "refpalette": "deceasedcraft:multi_oasiscondo_2/multi_oasiscondo_2_base2_palette",
  "xsize": 16,
  "zsize": 16,
  "slices": [
    [
      "vHHHHHHHav      ",
      "vHHHHHHHav      ",
      "vHHHHHHHav      ",
      "vHHHHHHHav      ",
      "vHHHHHHHavb     ",
      "vHHHHHHHav      ",
      "vHHHHHHHav      ",
      "vHHHHHHHav      ",
      "vHHHHHHHav      ",
      "vHHHHHHHav      ",
      "vHHHHHHHav      ",
      "vHHHHHHHav      ",
      "vHHHHHHHavcccccc",
      "vHHHHHHHaabddddd",
      "vHHHHHHHaaaaHHHa",
      "vHHHHHHHHaaHHHHH"
    ],
    [
      "ve  f    v      ",
      "vg  h    v      ",
      "ve  f    v      ",
      "vg  h    v      ",
      "ve  f    vb     ",
      "vg  h    v      ",
      "ve  f    v      ",
      "vg  h    v      ",
      "ve  f    v      ",
      "vg  h    vcccccc",
      "ve  f    vdddddd",
      "vg  h    viiiiii",
      "ve  f    vaaHHHa",
      "vg  h    jbklllk",
      "ve  f     mmnnnm",
      "vg  h           "
    ],
    [
      "v        v      ",
      "v        v      ",
      "v        v      ",
      "v        v      ",
      "v        vb     ",
      "v        v      ",
      "v        vcccccc",
      "v        vdddddd",
      "v        viiiiii",
      "v        vaaHHHa",
      "v        vkklllk",
      "v        vmmnnnm",
      "v        v      ",
      "v         b     ",
      "v               ",
      "v               "
    ],
    [
      "v        v      ",
      "v        v      ",
      "v        v      ",
      "v        vcccccc",
      "v        vbddddd",
      "v        viiiiii",
      "v        vaaHHHa",
      "v        vkklllk",
      "v        vmmnnnm",
      "v        v      ",
      "v        v      ",
      "v        v      ",
      "v        v      ",
      "v         b     ",
      "v               ",
      "v               "
    ],
    [
      "v        vcccccc",
      "v        vdddddd",
      "v        viiiiii",
      "v        vaaHHHa",
      "v        vbklllk",
      "v        vmmnnnm",
      "v        v      ",
      "v        v      ",
      "v        v      ",
      "v        v      ",
      "v        v      ",
      "v        v      ",
      "v        v      ",
      "v         booooo",
      "v               ",
      "v               "
    ],
    [
      "vccccccccvaaHHHa",
      "vccccccccvkklllk",
      "vccccccccvmmnnnm",
      "vccccccccv      ",
      "vpppppppppq     ",
      "vccccccccv      ",
      "vccccccccv      ",
      "vccccccccv      ",
      "vccccccccv      ",
      "vccccccccv      ",
      "vccccccccv      ",
      "vccccccccv      ",
      "vccccccccv      ",
      "vpppppppppqppppp",
      "vcccccccccpccccc",
      "vcccccccccpccccc"
    ]
  ]
}