{
  "name": "multi_oasiscondo_2_floor8",
  "refpalette": "deceasedcraft:multi_oasiscondo_2/multi_oasiscondo_2_floor8_palette",
  "xsize": 16,
  "zsize": 16,
  "slices": [
    [
      "         aaaaaab",
      "         aaaaaab",
      "         aaaaaab",
      "         aaaaaab",
      "         aaaaaaa",
      "         aaaaaab",
      "         aaaaaab",
      "         aaaaaab",
      "         aaaaaab",
      "         aaaaaab",
      "         aaaaaab",
      "         aaaaaab",
      "         caaaaab",
      "          dddddd",
      "         caaaaab",
      "         aaaaaae"
    ],
    [
      "        bf bg  b",
      "        b  bhihb",
      "        j kl  mb",
      "        bnol  mb",
      "        jbpq  mb",
      "        jrstu mb",
      "        b wx  mb",
      "        byA   mb",
      "        bBB CCBb",
      "        jDE  gFb",
      "        bI u JKb",
      "        bL   JKb",
      "        MjNOP Fb",
      "          dddddd",
      "        MbQRSlTb",
      "        bU V l W"
    ],
    [
      "        X  b   b",
      "        X  bhYhb",
      "        X  l  mb",
      "        X Zl  mb",
      "        0bbl  mb",
      "        X 12  mb",
      "        X  3  mb",
      "        X 4   mb",
      "        XBB CCBb",
      "        X     !b",
      "        X5     b",
      "        j6     b",
      "        Mb7   8b",
      "          dddddd",
      "        9bQR#l b",
      "        b$ V l %"
    ],
    [
      "        X^ b  gb",
      "        X  bh&hb",
      "        X  l  *b",
      "        X (l  )b",
      "        0bbl  +b",
      "        X -[   b",
      "        X  ]  {b",
      "        X }|  ;b",
      "        XBB CCBb",
      "        X      b",
      "        X      b",
      "        b      b",
      "        9b     b",
      "          dddddd",
      "        Mb  :l'b",
      "        j    l <"
    ],
    [
      "        X>>b ,!b",
      "        X>>bhhhb",
      "        X>>l   b",
      "        X ,l . b",
      "        0bbl   b",
      "        X>>l   b",
      "        X>>l . b",
      "        X>>l   b",
      "        XBBBBBBb",
      "        X      b",
      "        X ,  ? b",
      "        b      b",
      "        9j     b",
      "          dddddd",
      "        9j   l b",
      "        b  ? l b"
    ],
    [
      "        b  ////b",
      "        j  ////b",
      "        j` ////b",
      "        b//////b",
      "        b//////b",
      "        b/`////b",
      "        b  ////b",
      "        b  ////b",
      "        b//////b",
      "        b//////b",
      "        b//////b",
      "        j//////b",
      "        9\u0370/////b",
      "          dddddd",
      "        9j/////b",
      "        b//////b"
    ]
  ]
}