{
  "name": "multi_oasiscondo_2_base4",
  "refpalette": "deceasedcraft:multi_oasiscondo_2/multi_oasiscondo_2_base4_palette",
  "xsize": 16,
  "zsize": 16,
  "slices": [
    [
      "vaaaaaaaaaaaaaaa",
      "vaaaaaaaaaaaaaaa",
      "vaaaaaaaaaaaaaaa",
      "vaaaaaaaaaaaaaaa",
      "vaaaaaaaaaaaaaaa",
      "vaaaaaaaaaaaaaaa",
      "vaaaaaaaaaaaaaaa",
      "vaaaaaaaaaaaaaaa",
      "vaaaaaaaaaaaaaaa",
      "vaaaaaaaaaaaaaaa",
      "vaaaaaaaaaaaaaaa",
      "vaaaaaaaaaaaaaaa",
      "vaaaaaaaaaaaaaaa",
      "vaaaaaaaaaaaaaaa",
      "vaaaaaaaaaaaaaaa",
      "vaaaaaaaaaaaaaaa"
    ],
    [
      "vaaaaaaaaaaaaaaa",
      "vaaaaaaaaaaaaaaa",
      "vaaaaaaaaaaaaaaa",
      "vaaaaaaaaaaaaaaa",
      "vaaaaaaaaabaaaaa",
      "vaaaaaaaaaaaaaaa",
      "vaaaaaaaaaaaaaaa",
      "vaaaaaaaaaaaaaaa",
      "vaaaaaaaaaaaaaaa",
      "vaaaaaaaaaaaaaaa",
      "vaaaaaaaaaaaaaaa",
      "vaaaaaaaaaaaaaaa",
      "vaaaaaaaaaaaaaaa",
      "vaaaaaaaaabaaaaa",
      "vaaaaaaaaaaaaaaa",
      "vaaaaaaaaaaaaaaa"
    ],
    [
      "vHHHHHHHcvvvvvvv",
      "vHHHHHHHcvaaaaaa",
      "vHHHHHHHcvaaaaaa",
      "vHHHHHHHcvaaaaaa",
      "vHHHHHHHcvbaaaaa",
      "vHHHHHHHcvaaaaaa",
      "vHHHHHHHcvaaaaaa",
      "vHHHHHHHcvaaaaaa",
      "vHHHHHHHcvaaaaaa",
      "vHHHHHHHcvaaaaaa",
      "vHHHHHHHcvaaaaaa",
      "vHHHHHHHcvaaaaaa",
      "vHHHHHHHcvaaaaaa",
      "vHHHHHHHcvbaaaaa",
      "vHHHHHHHcvaaaaaa",
      "vHHHHHHHcvaaaaaa"
    ],
    [
      "v   d  e vvvvvvv",
      "v   f  g vaaaaaa",
      "v   d  e vaaaaaa",
      "v   f  g vaaaaaa",
      "v   d  e vbaaaaa",
      "v   f  g vaaaaaa",
      "v   d  e vaaaaaa",
      "v   f  g vaaaaaa",
      "v   d  e vaaaaaa",
      "v   f  g vaaaaaa",
      "v   d  e vaaaaaa",
      "v   f  g vaaaaaa",
      "v   d  e vaaaaaa",
      "v   f  g vbaaaaa",
      "v   d  e vaaaaaa",
      "v   f  g vaaaaaa"
    ],
    [
      "v        vvvvvvv",
      "v        vaaaaaa",
      "v        vaaaaaa",
      "v        vaaaaaa",
      "v        vbaaaaa",
      "v        vaaaaaa",
      "v        vaaaaaa",
      "v        vaaaaaa",
      "v        vaaaaaa",
      "v        vaaaaaa",
      "v        vaaaaaa",
      "v        vaaaaaa",
      "v        vaaaaaa",
      "v        vbaaaaa",
      "v        vaaaaaa",
      "v        vaaaaaa"
    ],
    [
      "v        vvvvvvv",
      "v        vaaaaaa",
      "v        vaaaaaa",
      "v        vaaaaaa",
      "v        vbaaaaa",
      "v        vaaaaaa",
      "v        vaaaaaa",
      "v        vaaaaaa",
      "v        vaaaaaa",
      "v        vaaaaaa",
      "v        vaaaaaa",
      "v        vaaaaaa",
      "v        vaaaaaa",
      "v        vbaaaaa",
      "v        vaaaaaa",
      "v        vhhhhhh"
    ]
  ]
}