{
  "name": "multi_oasiscondo_2_floor1",
  "refpalette": "deceasedcraft:multi_oasiscondo_2/multi_oasiscondo_2_floor1_palette",
  "xsize": 16,
  "zsize": 16,
  "slices": [
    [
      "                ",
      "   a            ",
      "                ",
      "                ",
      "   a      b     ",
      "                ",
      "                ",
      "   a            ",
      "                ",
      "                ",
      "                ",
      "        c       ",
      "        dc      ",
      "          bbbbbb",
      "       eee   !  ",
      "        ef      "
    ],
    [
      "                ",
      "                ",
      "                ",
      "                ",
      "          b     ",
      "                ",
      "                ",
      "                ",
      "                ",
      "                ",
      "                ",
      "        c       ",
      "        dc      ",
      "          bbbbbb",
      "       eee   g  ",
      "        ef      "
    ],
    [
      "                ",
      "                ",
      "                ",
      "                ",
      "          b     ",
      "                ",
      "                ",
      "                ",
      "                ",
      "                ",
      "                ",
      "        c       ",
      "        dc      ",
      "          bbbbbb",
      "       eee      ",
      "        ef      "
    ],
    [
      "                ",
      "                ",
      "                ",
      "                ",
      "          b     ",
      "                ",
      "                ",
      "                ",
      "                ",
      "                ",
      "                ",
      "        c       ",
      "        dc      ",
      "          bbbbbb",
      "       eee      ",
      "        ef      "
    ],
    [
      "         h      ",
      "         h      ",
      "         h      ",
      "         h      ",
      "         hb     ",
      "         h      ",
      "         h      ",
      "         h      ",
      "         h      ",
      "         h      ",
      "         h      ",
      "        ch      ",
      "        dc      ",
      "          bbbbbb",
      "       eee      ",
      "        ef      "
    ],
    [
      "        cciiiiii",
      "        cciiiiii",
      "        cciiiiii",
      "        cciiiiii",
      "        ccbiiiii",
      "        cciiiiii",
      "        cciiiiii",
      "        cciiiiii",
      "        cciiiiii",
      "        cciiiiii",
      "        cciiiiii",
      "        cciiiiii",
      "        dciiiiii",
      "          bbbbbb",
      "       eeeiiiiii",
      "       eeeiiiiii"
    ]
  ]
}