{
  "name": "multi_oasiscondo_2_floor9",
  "refpalette": "deceasedcraft:multi_oasiscondo_2/multi_oasiscondo_2_floor9_palette",
  "xsize": 16,
  "zsize": 16,
  "slices": [
    [
      "         aaaaaab",
      "         aaaaaab",
      "         aaaaaac",
      "         daaaaac",
      "          eeeeee",
      "         daaaaac",
      "         aaaaaac",
      "         aaaaaab",
      "         aaaaaab",
      "         aaaaaab",
      "         aaaaaab",
      "         aaaaaac",
      "         daaaaac",
      "          eeeeee",
      "         dfffffg",
      "         affhffg"
    ],
    [
      "        ciiiii j",
      "        ck k k l",
      "        c      c",
      "        mnopppqc",
      "          eeeeee",
      "        rcssst c",
      "        cu   t c",
      "        nw   txl",
      "        cu     y",
      "        c      j",
      "        cu AAA l",
      "        cB     c",
      "        rcCCDEEc",
      "          eeeeee",
      "       FFF IJ K ",
      "       LFMJN KO "
    ],
    [
      "        P      Q",
      "        P      l",
      "        c      c",
      "        rcRST Uc",
      "          eeeeee",
      "        rc   V c",
      "        c      c",
      "        P    W l",
      "        P      X",
      "        P      Q",
      "        P      l",
      "        c      c",
      "        mcYYYYYc",
      "          eeeeee",
      "       FFF      ",
      "       ZF     0 "
    ],
    [
      "        P      l",
      "        P      l",
      "        n      c",
      "        rc     c",
      "          eeeeee",
      "        rn     c",
      "        c1     c",
      "        P      l",
      "        P      l",
      "        P      l",
      "        P      l",
      "        c      c",
      "        rc22222c",
      "          eeeeee",
      "       FFF      ",
      "        F     J "
    ],
    [
      "        P      c",
      "        P      c",
      "        c      c",
      "        mc     c",
      "          eeeeee",
      "        mn1    c",
      "        c!     c",
      "        P      c",
      "        P      c",
      "        P      c",
      "        P      c",
      "        c 33333c",
      "        rc44444c",
      "          eeeeee",
      "       FFF      ",
      "        F     J "
    ],
    [
      "        n555555c",
      "        c555555c",
      "        c555555c",
      "        mc55555c",
      "          eeeeee",
      "        rn55555c",
      "        n555555c",
      "        c555555c",
      "        c555555c",
      "        c555555c",
      "        c555555c",
      "        c555555c",
      "        rc55555c",
      "          eeeeee",
      "       FFF666666",
      "       FFF666666"
    ]
  ]
}