{
  "name": "multi_oasiscondo_2_floor2",
  "refpalette": "deceasedcraft:multi_oasiscondo_2/multi_oasiscondo_2_floor2_palette",
  "xsize": 16,
  "zsize": 16,
  "slices": [
    [
      "         aaaaaab",
      "         aaaaaab",
      "         aaaaaab",
      "         caaaaab",
      "          dddddd",
      "         caaaaab",
      "         aaaaaae",
      "         aaaaaab",
      "         aaaaaab",
      "         aaaaaab",
      "         aaaaaab",
      "         aaaaaab",
      "         caaafab",
      "          dddddd",
      "         caaaaab",
      "         aaaaaae"
    ],
    [
      "        bg b   b",
      "        hijb  kb",
      "        blmb nob",
      "        pbqb  rb",
      "          dddddd",
      "        sbtutwxb",
      "        by A w B",
      "        bC   w b",
      "        hDEDFw b",
      "        bg b   b",
      "        b  b I b",
      "        hl b   b",
      "        pbJb K b",
      "          dddddd",
      "        pbtutwxb",
      "        bL A w B"
    ],
    [
      "        MN b   b",
      "        M  b   b",
      "        b  b  Ob",
      "        sbPb   b",
      "          dddddd",
      "        sbQ Rw b",
      "        by   w S",
      "        M    w b",
      "        MDTDUw b",
      "        M  b   b",
      "        M  b   b",
      "        b  b  Vb",
      "        phPb  Vb",
      "          dddddd",
      "        sbW Xw b",
      "        b    wYS"
    ],
    [
      "        MZ b   b",
      "        M  b  0b",
      "        h  b  1b",
      "        sh2b  3b",
      "          dddddd",
      "        ph   w4b",
      "        h5   w 6",
      "        M    w b",
      "        MD7D7w b",
      "        MZ b   b",
      "        M  b 89b",
      "        b  b   b",
      "        sh2bV#Vb",
      "          dddddd",
      "        pb   w4b",
      "        h    wY6"
    ],
    [
      "        M$$b   b",
      "        M$$b   b",
      "        b$$b % b",
      "        sb%b   b",
      "          dddddd",
      "        ph   w b",
      "        b  ^ w b",
      "        M    w b",
      "        MDDDDw b",
      "        M$$b  Vb",
      "        M$$b   b",
      "        b$$b % b",
      "        sb%b   b",
      "          dddddd",
      "        ph   wYb",
      "        b  ^ w!b"
    ],
    [
      "        b  &&&&b",
      "        h  &&&&b",
      "        b* &&&&b",
      "        ph&&&&&b",
      "          dddddd",
      "        sb&&&&&b",
      "        b&&&&&&b",
      "        h&&&&&&b",
      "        b&&&&&&b",
      "        h  &&&&b",
      "        b  &&&&b",
      "        h* &&&&b",
      "        pb&&&&&b",
      "          dddddd",
      "        pb&&&&&b",
      "        b&&&&&&b"
    ]
  ]
}