{
  "name": "multi_oasiscondo_2_ground",
  "refpalette": "deceasedcraft:multi_oasiscondo_2/multi_oasiscondo_2_ground_palette",
  "xsize": 16,
  "zsize": 16,
  "slices": [
    [
      "abbbbbaccd      ",
      "abbbbbaccd      ",
      "abbbbbaccd      ",
      "abbbbbaccd      ",
      "abbbbbaccde     ",
      "abbbbbaccd      ",
      "abbbbbaccd      ",
      "abbbbbaccd      ",
      "abbbbbaccd      ",
      "abbbbbaccd      ",
      "aabbbaaccd      ",
      "aaaaaaaafd      ",
      "gggggggggf      ",
      "gggggggggaeeeeee",
      "ggggggghhhiiiiii",
      "gggggggghaiiiiii"
    ],
    [
      " jkbkj  l       ",
      " jkbkj  l       ",
      " jkbkj  l       ",
      " jkbkj  m       ",
      " jkbkj  mne     ",
      " jkbkj  m       ",
      " jkbkj  l       ",
      " jkbkj  l       ",
      " jkbkj  l       ",
      " jkkkj  l       ",
      "  jjj   l       ",
      "        f       ",
      "        of      ",
      "         peeeeee",
      "       hhhqqqqqq",
      "        hr     s"
    ],
    [
      "                ",
      "   t            ",
      "                ",
      "                ",
      "   t      e     ",
      "                ",
      "                ",
      "   t            ",
      "                ",
      "                ",
      "                ",
      "        f       ",
      "        of      ",
      "          eeeeee",
      "       hhhqqqqqq",
      "        hr      "
    ],
    [
      "                ",
      "   l            ",
      "                ",
      "                ",
      "   l      e     ",
      "                ",
      "                ",
      "   l            ",
      "                ",
      "                ",
      "                ",
      "        f       ",
      "        of      ",
      "          eeeeee",
      "       hhhu w  x",
      "        hr      "
    ],
    [
      "                ",
      "   m            ",
      "                ",
      "                ",
      "   m      e     ",
      "                ",
      "                ",
      "   m            ",
      "                ",
      "                ",
      "                ",
      "        f       ",
      "        of      ",
      "          eeeeee",
      "       hhh   y  ",
      "        hr      "
    ],
    [
      "                ",
      "   m            ",
      "                ",
      "                ",
      "   m      e     ",
      "                ",
      "                ",
      "   m            ",
      "                ",
      "                ",
      "                ",
      "        f       ",
      "        of      ",
      "          eeeeee",
      "       hhh   A  ",
      "        hr      "
    ]
  ]
}