{
  "name": "multi_oasiscondo_2_base3",
  "refpalette": "deceasedcraft:multi_oasiscondo_2/multi_oasiscondo_2_base3_palette",
  "xsize": 16,
  "zsize": 16,
  "slices": [
    [
      "v        vvvvvvv",
      "v        vaaaaaa",
      "v        vaaaaaa",
      "v        vaaaaaa",
      "v        vbaaaaa",
      "v        vaaaaaa",
      "v        vaaaaaa",
      "v        vaaaaaa",
      "v        vaaaaaa",
      "v        vaaaaaa",
      "v        vaaaaaa",
      "v        vaaaaaa",
      "v        vcccccc",
      "v        vbccccc",
      "v        vcccccc",
      "v        vddHHHd"
    ],
    [
      "v        vvvvvvv",
      "v        vaaaaaa",
      "v        vaaaaaa",
      "v        vaaaaaa",
      "v        vbaaaaa",
      "v        vaaaaaa",
      "v        vaaaaaa",
      "v        vaaaaaa",
      "v        vaaaaaa",
      "v        vcccccc",
      "v        vcccccc",
      "v        vcccccc",
      "v        vddHHHd",
      "v        vbefffe",
      "v        vgghhhg",
      "v        v      "
    ],
    [
      "v        vvvvvvv",
      "v        vaaaaaa",
      "v        vaaaaaa",
      "v        vaaaaaa",
      "v        vbaaaaa",
      "v        vaaaaaa",
      "v        vcccccc",
      "v        vcccccc",
      "v        vcccccc",
      "v        vddHHHd",
      "v        veefffe",
      "v        vgghhhg",
      "v        v      ",
      "v        vb     ",
      "v        v      ",
      "v        v      "
    ],
    [
      "v        vvvvvvv",
      "v        vaaaaaa",
      "v        vaaaaaa",
      "v        vcccccc",
      "v        vbccccc",
      "v        vcccccc",
      "v        vddHHHd",
      "v        veefffe",
      "v        vgghhhg",
      "v        v      ",
      "v        v      ",
      "v        v      ",
      "v        v      ",
      "v        vb     ",
      "v        v      ",
      "v        v      "
    ],
    [
      "v        vvvvvvv",
      "v        vcccccc",
      "v        vcccccc",
      "v        vddHHHd",
      "v        vbefffe",
      "v        vgghhhg",
      "v        v      ",
      "v        v      ",
      "v        v      ",
      "v        v      ",
      "v        v      ",
      "v        v      ",
      "v        v      ",
      "v        vbiiiii",
      "v        v      ",
      "v        v      "
    ],
    [
      "vjjjjjjjjvddHHHd",
      "vjjjjjjjjveefffe",
      "vjjjjjjjjvgghhhg",
      "vjjjjjjjjv      ",
      "vkkkkkkkkkl     ",
      "vjjjjjjjjv      ",
      "vjjjjjjjjv      ",
      "vjjjjjjjjv      ",
      "vjjjjjjjjv      ",
      "vjjjjjjjjv      ",
      "vjjjjjjjjv      ",
      "vjjjjjjjjv      ",
      "vjjjjjjjjv      ",
      "vkkkkkkkkklkkkkk",
      "vjjjjjjjjvkjjjjj",
      "vjjjjjjjjvkjjjjj"
    ]
  ]
}