{
  "name": "multi_oasiscondo_2_floor11",
  "refpalette": "deceasedcraft:multi_oasiscondo_2/multi_oasiscondo_2_floor11_palette",
  "xsize": 16,
  "zsize": 16,
  "slices": [
    [
      "         aaaaaab",
      "         aaaaaab",
      "         aaaaaac",
      "         daaaaac",
      "          eeeeee",
      "         dfffffg",
      "         affffhg",
      "         afhhfhg",
      "         affhhhg",
      "         affhhfg",
      "         afhhffg",
      "         affhfhg",
      "         affhhfg",
      "         aefhffg",
      "         affhffg",
      "         aihfhfg"
    ],
    [
      "         jkllm n",
      "         j oo  n",
      "         jp   qc",
      "         jjrrrrc",
      "          eeeeee",
      "       sssttt!t ",
      "       usw xyA  ",
      "       uww      ",
      "       uww      ",
      "       uww      ",
      "       uww      ",
      "       uww   B  ",
      "       uwwC   C ",
      "       uwweC C  ",
      "       uww D  B ",
      "       uww    C "
    ],
    [
      "         j E   n",
      "         j     n",
      "         jF    c",
      "         jj    c",
      "          eeeeee",
      "       sssCCCCC ",
      "       Is       ",
      "       I        ",
      "       I        ",
      "       I        ",
      "       I        ",
      "       I        ",
      "       I        ",
      "       I  e  C  ",
      "       I   t    ",
      "       I        "
    ],
    [
      "         j     n",
      "         j     n",
      "         j     c",
      "         jj    c",
      "          eeeeee",
      "       sssCC CC ",
      "        s       ",
      "                ",
      "                ",
      "                ",
      "                ",
      "                ",
      "                ",
      "          e     ",
      "           C    ",
      "                "
    ],
    [
      "         j     c",
      "         j     c",
      "         j     c",
      "         jj    c",
      "          eeeeee",
      "       sssC  C  ",
      "        s       ",
      "        J       ",
      "        J       ",
      "        J       ",
      "        J       ",
      "        J       ",
      "        J       ",
      "        J e     ",
      "        J  K    ",
      "        J       "
    ],
    [
      "         jLLLLLc",
      "         jLLLLLc",
      "         jLLLLLc",
      "         jjLLLLc",
      "          eeeeee",
      "       sssLLLLLL",
      "       sssLLLLLL",
      "       sssLLLLLL",
      "       sssLLLLLL",
      "       sssLLLLLL",
      "       sssLLLLLL",
      "       sssLLLLLL",
      "       sssLLLLLL",
      "       ssseLLLLL",
      "       sssLLLLLL",
      "       sssLLLLLL"
    ]
  ]
}