{
  "name": "multi_oasiscondo_2_floor7",
  "refpalette": "deceasedcraft:multi_oasiscondo_2/multi_oasiscondo_2_floor7_palette",
  "xsize": 16,
  "zsize": 16,
  "slices": [
    [
      "         aaaaaab",
      "         aaaaaab",
      "         aaaaaab",
      "         aaaaaab",
      "         aaaaaaa",
      "         aaaaaab",
      "         aaaaaab",
      "         aaaaaab",
      "         aaaaaab",
      "         aaaaaab",
      "         aaaaaab",
      "         aaaaaab",
      "         caaaaab",
      "          dddddd",
      "         caaaaab",
      "         aaaaaae"
    ],
    [
      "        bf b   b",
      "        b gb   b",
      "        b hb   b",
      "        b ib   b",
      "        bjkklm b",
      "        n    m b",
      "        b    m b",
      "        b oo m b",
      "        bpqqpm b",
      "        bkkkkklb",
      "        b  r   b",
      "        nsttttub",
      "        wbxyyyyb",
      "          dddddd",
      "        wbABAm!b",
      "        bC D mEF"
    ],
    [
      "        I  b   b",
      "        I  b   b",
      "        I  b   b",
      "        I Jb   b",
      "        KLkkMm b",
      "        I   Nm b",
      "        I   Nm b",
      "        I    m b",
      "        IO  Pm b",
      "        IkkkkkMb",
      "        I      b",
      "        bQRS TUb",
      "        wbVWWWWb",
      "          dddddd",
      "        wbX YmEb",
      "        nZ   m01"
    ],
    [
      "        I2 b   b",
      "        I  b   b",
      "        I  b   b",
      "        I 3b   b",
      "        K4kk5m b",
      "        I    m b",
      "        I    m b",
      "        I    m b",
      "        I    m b",
      "        Ikkkkk5b",
      "        I      b",
      "        b      b",
      "        6bWWW7Wb",
      "          dddddd",
      "        wb   m8b",
      "        b    m 9"
    ],
    [
      "        I##b$  b",
      "        I##b   b",
      "        I##b   b",
      "        I##b$  b",
      "        Kkkkkm b",
      "        I    m b",
      "        I  % m b",
      "        I    m b",
      "        I    m^b",
      "        Ikkkkkkb",
      "        I $  ^ b",
      "        b      b",
      "        wnWWVWWb",
      "          dddddd",
      "        6b   m b",
      "        b  % m b"
    ],
    [
      "        b  &&&&b",
      "        n  &&&&b",
      "        b* &&&&b",
      "        b&&&&&&b",
      "        n&&&&&&b",
      "        b&&&&&&b",
      "        n&&&&&&b",
      "        b&&&&&&b",
      "        b&&&&&&b",
      "        n&&&&&&b",
      "        n&&&&&&b",
      "        b&&&&&&b",
      "        6n&&&&&b",
      "          dddddd",
      "        6n&&&&&b",
      "        b&&&&&&b"
    ]
  ]
}