{
  "name": "multi_oasiscondo_2_floor10",
  "refpalette": "deceasedcraft:multi_oasiscondo_2/multi_oasiscondo_2_floor10_palette",
  "xsize": 16,
  "zsize": 16,
  "slices": [
    [
      "         abccccd",
      "         abccccd",
      "         abccccd",
      "         abccccd",
      "         aeddddd",
      "         afffffg",
      "         afffffg",
      "         afffffg",
      "         afffffg",
      "         afffffg",
      "         afffffg",
      "         afffffg",
      "         hfffffg",
      "          eeeeee",
      "         haaaaad",
      "         aaaaaad"
    ],
    [
      "       ijjkl    ",
      "       ijjkl m  ",
      "       ijjkl m  ",
      "       ijjkl    ",
      "       ijje     ",
      "       ijj      ",
      "       ijj      ",
      "       ijj      ",
      "       ijj      ",
      "       ijj      ",
      "       ijj      ",
      "       inj opq  ",
      "       nnnrrrrr ",
      "          eeeeee",
      "        stu    w",
      "        t u    x"
    ],
    [
      "       y  r     ",
      "       y  A     ",
      "       y  r     ",
      "       y  r     ",
      "       y  e     ",
      "       y        ",
      "       y        ",
      "       y        ",
      "       y        ",
      "       y        ",
      "       y        ",
      "       yn       ",
      "       nnnBBBBB ",
      "          eeeeee",
      "        CDE    w",
      "        t      F"
    ],
    [
      "                ",
      "                ",
      "                ",
      "                ",
      "          e     ",
      "                ",
      "                ",
      "                ",
      "                ",
      "                ",
      "                ",
      "        n       ",
      "       nnnBBB B ",
      "          eeeeee",
      "        Ct     w",
      "        D      w"
    ],
    [
      "        I       ",
      "        I       ",
      "        I       ",
      "        I       ",
      "        I e     ",
      "        I       ",
      "        I       ",
      "        I       ",
      "        I       ",
      "        I       ",
      "        I       ",
      "        n       ",
      "       nnnB B   ",
      "          eeeeee",
      "        st     t",
      "        t      t"
    ],
    [
      "       nnnJJJJJJ",
      "       nnnJJJJJJ",
      "       nnnJJJJJJ",
      "       nnnJJJJJJ",
      "       nnneJJJJJ",
      "       nnnJJJJJJ",
      "       nnnJJJJJJ",
      "       nnnJJJJJJ",
      "       nnnJJJJJJ",
      "       nnnJJJJJJ",
      "       nnnJJJJJJ",
      "       nnnJJJJJJ",
      "       nnnJJJJJJ",
      "          eeeeee",
      "        CtKKKKKt",
      "        DKKKKKKt"
    ]
  ]
}