{
  "name": "multi_oasiscondo_2_floor5",
  "refpalette": "deceasedcraft:multi_oasiscondo_2/multi_oasiscondo_2_floor5_palette",
  "xsize": 16,
  "zsize": 16,
  "slices": [
    [
      "         aaaaaab",
      "         aaaaaab",
      "         aaaaaab",
      "         caaaaab",
      "          dddddd",
      "         caaaaab",
      "         aaaaaae",
      "         aaaaaab",
      "         aaaaaab",
      "         aaaaaab",
      "         aaaaaab",
      "         aaaaaab",
      "         caaaaab",
      "          dddddd",
      "         caaaaab",
      "         aaaaaae"
    ],
    [
      "        bf b   b",
      "        b  b ghb",
      "        bijbklmb",
      "        nbobppkb",
      "          dddddd",
      "       qqqrstuwb",
      "       xq  y   A",
      "       xB CDE Fb",
      "       xB CIE Jb",
      "       xB  KL Mb",
      "       xB  bbbbb",
      "       xq  N OPb",
      "       qqqQbiRSb",
      "          dddddd",
      "        TbUVWuwb",
      "        bX YZu A"
    ],
    [
      "        0  b   b",
      "        0  b   b",
      "        b  bg  b",
      "        n12bl3 b",
      "          dddddd",
      "       qqqrstu b",
      "       4q  y   5",
      "       4   67 8b",
      "       4   69 #b",
      "       4   $  %b",
      "       4   bbbbb",
      "       4q^ &   b",
      "       qqqQb O*b",
      "          dddddd",
      "        nb() u+b",
      "        1-   u 5"
    ],
    [
      "        0  b   b",
      "        0  b   b",
      "        1  b   b",
      "        nb[b   b",
      "          dddddd",
      "       qqq  ]u{b",
      "        q      }",
      "              8b",
      "        |     ;b",
      "              :b",
      "        |  bbbbb",
      "        q  '  <b",
      "       qqq>b  ,b",
      "          dddddd",
      "        n1   u{b",
      "        b    u }"
    ],
    [
      "        0..b   b",
      "        0..b   b",
      "        b..b ? b",
      "        Tb/b   b",
      "          dddddd",
      "       qqq   u b",
      "        q      b",
      "        `  !  \u0370b",
      "        `      b",
      "        `      b",
      "        `  bbbbb",
      "        q  b...b",
      "       qqq/b...b",
      "          dddddd",
      "        Tb   u b",
      "        b  \u0371 u b"
    ],
    [
      "        1  \u0372\u0372\u0372\u0372b",
      "        b  \u0372\u0372\u0372\u0372b",
      "        b\u0373 \u0372\u0372\u0372\u0372b",
      "        T1\u0372\u0372\u0372\u0372\u0372b",
      "          dddddd",
      "       qqq\u0372\u0372\u0372\u0372\u0372b",
      "       qq\u0372\u0372\u0372\u0372\u0372\u0372b",
      "       qq\u0372\u0372\u0372\u0372\u0372\u0372b",
      "       qq\u0372\u0372\u0372\u0372\u0372\u0372b",
      "       qq\u0372\u0372\u0372\u0372\u0372\u0372b",
      "       qq\u0372\u0372\u0372\u0372\u0372\u0372b",
      "       qq\u0372\u0372\u0372   b",
      "       qqq\u0372\u0372  \u0373b",
      "          dddddd",
      "        nb\u0372\u0372\u0372\u0372\u0372b",
      "        b\u0372\u0372\u0372\u0372\u0372\u0372b"
    ]
  ]
}