{
  "name": "multi_casino_11_base4",
  "refpalette": "deceasedcraft:multi_casino_11/multi_casino_11_base4_palette",
  "xsize": 16,
  "zsize": 16,
  "slices": [
    [
      "aaaaaaaaaaaaaaaa",
      "aaaaaaaaaaaaaaaa",
      "aaaaaaaaaaaaaaaa",
      "aaaaaaaaaaaaaaaa",
      "aaaaaaaaaaaaaaaa",
      "aaaaaaaaaaaaaaaa",
      "aaaaaaaaaaaaaaaa",
      "aaaaaaaabaaaaaaa",
      "aaaaaaaaaaaaaaaa",
      "cccccccccccccccc",
      "dddddddddddddddd",
      "eeeefeeeeeeefeee",
      "gggggggggggggggg",
      "hhhhhhhhhhhhhhhh",
      "hhhhhhhhhhhhhhhh",
      "vvvvvvvvvvvvvvvv"
    ],
    [
      "      iiiii     ",
      "                ",
      "                ",
      "  iiii     iiii ",
      " ijjjji   ijjjji",
      " ijjjji   ijjjji",
      " k!jjlm n kljjlm",
      "  opqo  b  oq o ",
      "                ",
      "                ",
      "    r       r   ",
      "ssssfsssssssfsss",
      "gggggggggggggggg",
      "hhhhhhhhhhhhhhhh",
      "hhhhhhhhhhhhhhhh",
      "vvvvvvvvvvvvvvvv"
    ],
    [
      "                ",
      "                ",
      "                ",
      "                ",
      "                ",
      "                ",
      "                ",
      "        b       ",
      "                ",
      "                ",
      "                ",
      "ssssfsssssssfsss",
      "gggggggggggggggg",
      "hhhhhhhhhhhhhhhh",
      "hhhhhhhhhhhhhhhh",
      "vvvvvvvvvvvvvvvv"
    ],
    [
      "                ",
      "                ",
      "                ",
      "                ",
      "                ",
      "                ",
      "                ",
      "        b       ",
      "                ",
      "                ",
      "                ",
      "ssssfsssssssfsss",
      "gggggggggggggggg",
      "hhhhhhhhhhhhhhhh",
      "hhhhhhhhhhhhhhhh",
      "vvvvvvvvvvvvvvvv"
    ],
    [
      "                ",
      "                ",
      "                ",
      "                ",
      "                ",
      "                ",
      "                ",
      "        b       ",
      "                ",
      "                ",
      "                ",
      "ssssfsssssssfsss",
      "gggggggggggggggg",
      "hhhhhhhhhhhhhhhh",
      "hhhhhhhhhhhhhhhh",
      "vvvvvvvvvvvvvvvv"
    ],
    [
      "                ",
      "                ",
      "                ",
      "                ",
      "                ",
      "                ",
      "                ",
      "        b       ",
      "                ",
      "                ",
      "                ",
      "s ssfssss ssfss ",
      "gggggggggggggggg",
      "hhhhhhhhhhhhhhhh",
      "hhhhhhhhhhhhhhhh",
      "vvvvvvvvvvvvvvvv"
    ]
  ]
}