{
  "name": "multi_casino_11_base7",
  "refpalette": "deceasedcraft:multi_casino_11/multi_casino_11_base7_palette",
  "xsize": 16,
  "zsize": 16,
  "slices": [
    [
      "                ",
      "                ",
      "                ",
      "                ",
      "                ",
      "                ",
      "        a       ",
      "        b       ",
      "                ",
      "                ",
      "                ",
      "c  cd c c  cdc  ",
      "eeeeeeeeeeeeeeee",
      "ffffffffffffffff",
      "ffffffffffffffff",
      "vvvvvvvvvvvvvvvv"
    ],
    [
      "               g",
      "                ",
      "                ",
      "                ",
      "                ",
      "                ",
      "       hij      ",
      "        b       ",
      "                ",
      "                ",
      "                ",
      "    d      cdc  ",
      "eeeeeeeeeeeeeeee",
      "ffffffffffffffff",
      "ffffffffffffffff",
      "vvvvvvvvvvvvvvvv"
    ],
    [
      "               k",
      "                ",
      "                ",
      "                ",
      "                ",
      "                ",
      "       hlj      ",
      "        b       ",
      "                ",
      "                ",
      "                ",
      "    d       d   ",
      "eeeeeeeeeeeeeeee",
      "ffffffffffffffff",
      "ffffffffffffffff",
      "vvvvvvvvvvvvvvvv"
    ],
    [
      "               k",
      "                ",
      "                ",
      "                ",
      "                ",
      "                ",
      "        m       ",
      "        b       ",
      "                ",
      "                ",
      "                ",
      "    d       d   ",
      "eeeeeeeeeeeeeeee",
      "ffffffffffffffff",
      "ffffffffffffffff",
      "vvvvvvvvvvvvvvvv"
    ],
    [
      "nonnnnnnnno    p",
      "nnonnnnnnnoo  q ",
      "nnnonnnnnnno q  ",
      "rnnnrnnnrnnos   ",
      "nnnnnonnnnnoooo ",
      "nnnnnnonnnonnnoo",
      "nnnnnnnononnnnnn",
      "rnnnrnnnbnnnrnnn",
      "nnnnnnnononnnnnn",
      "nnnnnnonnnonnnnn",
      "nnnnnonnnnnonnnn",
      "    d       d   ",
      "eeeeeeeeeeeeeeee",
      "ffffffffffffffff",
      "ffffffffffffffff",
      "vvvvvvvvvvvvvvvv"
    ],
    [
      "tbtttttttttpuuub",
      "ttbtttttttttuubu",
      "tttbttttttttubuu",
      "utttbtttutttbuuu",
      "tttttbtttttbtttp",
      "ttttttbtttbttttt",
      "tttttttbtbtttttt",
      "utttutttbtttuttt",
      "tttttttbtbtttttt",
      "ttttttbtttbttttt",
      "wwwwtbwwwwwbtwww",
      "xxxxdxxxxxxxdxxx",
      "eeeeeeeeeeeeeeee",
      "ffffffffffffffff",
      "ffffffffffffffff",
      "vvvvvvvvvvvvvvvv"
    ]
  ]
}