{
  "name": "multi_casino_11_base9",
  "refpalette": "deceasedcraft:multi_casino_11/multi_casino_11_base9_palette",
  "xsize": 16,
  "zsize": 16,
  "slices": [
    [
      "aaaaaaaaaaaaaaaa",
      "aaaaaaaaaaaaaaaa",
      "aaaaaaaaaaaaaaaa",
      "aaaaaaaaaaaaaaaa",
      "aaaaaaaaaaaaaaaa",
      "aaaaaaaaaaaaaaaa",
      "aaaaaaaaaaaaaaaa",
      "aaaaaaaaaaaaaaaa",
      "bbbbbbbbbbbbbbbb",
      "bbbbbbbbbbbbbbbb",
      "bbbbbbbbbbbbbbbb",
      "bbbbbbbbbbbbbbbb",
      "bbbbbbbbbbbbbbbb",
      "bbbbbbbbbbbbbbbb",
      "bbbbbbbbbbbbbbbb",
      "vvvvvvvvvvvvvvvv"
    ],
    [
      "cccccccbbbbbbbbb",
      "cccccccbbbbbbbbb",
      "cccccccbbbbbbbbb",
      "ccccccbbbbbbbbbb",
      "ccccccbbbbbbbbbb",
      "ccccccbbbbbbbbbb",
      "ccccccbbbbbbbbbb",
      "ccccccbbdbbbbbbb",
      "bbbbbbbbbbbbbbbb",
      "bbbbbbbbbbbbbbbb",
      "bbbbbbbbbbbbbbbb",
      "bbbbbbbbbbbbbbbb",
      "bbbbbbbbbbbbbbbb",
      "bbbbbbbbbbbbbbbb",
      "bbbbbbbbbbbbbbbb",
      "vvvvvvvvvvvvvvvv"
    ],
    [
      "cccccccbbbbbbbbb",
      "cccccccbbbbbbbbb",
      "cccccccbbbbbbbbb",
      "ccccccbbbbbbbbbb",
      "ccccccbbbbbbbbbb",
      "ccccccbbbbbbbbbb",
      "ccccccbbbbbbbbbb",
      "ccccccbbdbbbbbbb",
      "bbbbbbbbbbbbbbbb",
      "bbbbbbbbbbbbbbbb",
      "bbbbbbbbbbbbbbbb",
      "bbbbbbbbbbbbbbbb",
      "bbbbbbbbbbbbbbbb",
      "bbbbbbbbbbbbbbbb",
      "bbbbbbbbbbbbbbbb",
      "vvvvvvvvvvvvvvvv"
    ],
    [
      "cccccccbbbbbbbbb",
      "cccccccbbbbbbbbb",
      "cccccccbbbbbbbbb",
      "ccccccbbbbbbbbbb",
      "ccccccbbbbbbbbbb",
      "ccccccbbbbbbbbbb",
      "ccccccbbbbbbbbbb",
      "ccccccbbdbbbbbbb",
      "bbbbbbbbbbbbbbbb",
      "bbbbbbbbbbbbbbbb",
      "bbbbbbbbbbbbbbbb",
      "bbbbbbbbbbbbbbbb",
      "bbbbbbbbbbbbbbbb",
      "bbbbbbbbbbbbbbbb",
      "bbbbbbbbbbbbbbbb",
      "vvvvvvvvvvvvvvvv"
    ],
    [
      "cccccccbbbbbbbbb",
      "cccccccbbbbbbbbb",
      "cccccccbbbbbbbbb",
      "ccccccbbbbbbbbbb",
      "ccccccbbbbbbbbbb",
      "ccccccbbbbbbbbbb",
      "ccccccbbbbbbbbbb",
      "ccccccbbdbbbbbbb",
      "bbbbbbbbbbbbbbbb",
      "bbbbbbbbbbbbbbbb",
      "bbbbbbbbbbbbbbbb",
      "bbbbbbbbbbbbbbbb",
      "bbbbbbbbbbbbbbbb",
      "bbbbbbbbbbbbbbbb",
      "bbbbbbbbbbbbbbbb",
      "vvvvvvvvvvvvvvvv"
    ],
    [
      "cdcccccbbbbbbbbd",
      "ccdccccbbbbbbbdb",
      "cccdcccbbbbbbdbb",
      "ccccdcbbbbbbdbbb",
      "cccccdbbbbbdbbbb",
      "ccccccdbbbdbbbbb",
      "ccccccbdbdbbbbbb",
      "ccccccbbdbbbbbbb",
      "bbbbbbbbbbbbbbbb",
      "bbbbbbbbbbbbbbbb",
      "bbbbbbbbbbbbbbbb",
      "bbbbbbbbbbbbbbbb",
      "bbbbbbbbbbbbbbbb",
      "bbbbbbbbbbbbbbbb",
      "bbbbbbbbbbbbbbbb",
      "vvvvvvvvvvvvvvvv"
    ]
  ]
}