{
  "name": "multi_casino_11_base8",
  "refpalette": "deceasedcraft:multi_casino_11/multi_casino_11_base8_palette",
  "xsize": 16,
  "zsize": 16,
  "slices": [
    [
      "aaaaaaabbccccccc",
      "aaaaaaabcccccccc",
      "aaaaaaabcccccccc",
      "aaaaaabbcccccccc",
      "aaaaaabccccccccc",
      "aaaaaabccccccccc",
      "aaaaaabccccccccc",
      "aaaaaabcdccccccc",
      "aaaaaabccccccccc",
      "bbbbbbbbbbbbbbbb",
      "eeeeeeeeeeeeeeee",
      "ffffgfffffffgfff",
      "hhhhhhhhhhhhhhhh",
      "iiiiiiiiiiiiiiii",
      "iiiiiiiiiiiiiiii",
      "vvvvvvvvvvvvvvvv"
    ],
    [
      " j  k     lccccc",
      "   kmk   llccccc",
      "j   k    lcccccc",
      "mj      llcccccc",
      "j   k   lccccccc",
      "   kmk  lccccccc",
      "j   k   lccccccc",
      "mj      dccccccc",
      "j            noo",
      "                ",
      "    p       p   ",
      "qqqqgqqqqqqqgqqq",
      "hhhhhhhhhhhhhhhh",
      "iiiiiiiiiiiiiiii",
      "iiiiiiiiiiiiiiii",
      "vvvvvvvvvvvvvvvv"
    ],
    [
      "                ",
      "                ",
      "                ",
      "r               ",
      "                ",
      "    s           ",
      "                ",
      "r       d       ",
      "                ",
      "                ",
      "                ",
      "qqqqgqqqqqqqgqqq",
      "hhhhhhhhhhhhhhhh",
      "iiiiiiiiiiiiiiii",
      "iiiiiiiiiiiiiiii",
      "vvvvvvvvvvvvvvvv"
    ],
    [
      "                ",
      "                ",
      "                ",
      "                ",
      "                ",
      "                ",
      "                ",
      "        d       ",
      "                ",
      "                ",
      "                ",
      "qqqqgqqqqqqqgqqq",
      "hhhhhhhhhhhhhhhh",
      "iiiiiiiiiiiiiiii",
      "iiiiiiiiiiiiiiii",
      "vvvvvvvvvvvvvvvv"
    ],
    [
      "                ",
      "                ",
      "                ",
      "                ",
      "                ",
      "                ",
      "                ",
      "        d       ",
      "                ",
      "                ",
      "                ",
      "qqqqgqqqqqqqgqqq",
      "hhhhhhhhhhhhhhhh",
      "iiiiiiiiiiiiiiii",
      "iiiiiiiiiiiiiiii",
      "vvvvvvvvvvvvvvvv"
    ],
    [
      "                ",
      "                ",
      "                ",
      "                ",
      "                ",
      "                ",
      "                ",
      "        d       ",
      "                ",
      "                ",
      "                ",
      "q qqgqqqq qqgqq ",
      "hhhhhhhhhhhhhhhh",
      "iiiiiiiiiiiiiiii",
      "iiiiiiiiiiiiiiii",
      "vvvvvvvvvvvvvvvv"
    ]
  ]
}