{
  "name": "multi_casino_11_base2",
  "refpalette": "deceasedcraft:multi_casino_11/multi_casino_11_base2_palette",
  "xsize": 16,
  "zsize": 16,
  "slices": [
    [
      "aaaaaaaaaaaaaaaa",
      "aaaaaaaaaaaaaaaa",
      "aaaaaaaaaaaaaaaa",
      "aaaaaaaaaaaaaaaa",
      "aaaaaaaaaaaaaaaa",
      "aaaaaaaaaaaaaaaa",
      "aaaaaaaaaaaaaaaa",
      "aaaaaaaabaaaaaaa",
      "aaaaaaaaaaaaaaaa",
      "cccccccccccccccc",
      "dddddddddddddddd",
      "eeeefeeeeeeefeee",
      "gggggggggggggggg",
      "hhhhhhhhhhhhhhhh",
      "hhhhhhhhhhhhhhhh",
      "vvvvvvvvvvvvvvvv"
    ],
    [
      "        i i i   ",
      "                ",
      "j j j j         ",
      "k k k k    j    ",
      "l l l l    k    ",
      "m m m m  jnmojjn",
      "p p p p q  p    ",
      "j j j j b  j    ",
      "                ",
      "                ",
      "    r       r   ",
      "ssssfsssssssfsss",
      "gggggggggggggggg",
      "hhhhhhhhhhhhhhhh",
      "hhhhhhhhhhhhhhhh",
      "vvvvvvvvvvvvvvvv"
    ],
    [
      "                ",
      "                ",
      "                ",
      "t t t t         ",
      "uwuwuwuw   x    ",
      "uyuyuyu   AlB  A",
      "C C C C    D    ",
      "        b       ",
      "                ",
      "                ",
      "                ",
      "ssssfsssssssfsss",
      "gggggggggggggggg",
      "hhhhhhhhhhhhhhhh",
      "hhhhhhhhhhhhhhhh",
      "vvvvvvvvvvvvvvvv"
    ],
    [
      "                ",
      "                ",
      "                ",
      "                ",
      "E E E E    F    ",
      "I I I I   JlK  J",
      "           L    ",
      "        b       ",
      "                ",
      "                ",
      "                ",
      "ssssfsssssssfsss",
      "gggggggggggggggg",
      "hhhhhhhhhhhhhhhh",
      "hhhhhhhhhhhhhhhh",
      "vvvvvvvvvvvvvvvv"
    ],
    [
      "                ",
      "                ",
      "                ",
      "                ",
      "M M M M    N    ",
      "M M M M   OPQ  O",
      "           R    ",
      "        b       ",
      "                ",
      "                ",
      "                ",
      "ssssfsssssssfsss",
      "gggggggggggggggg",
      "hhhhhhhhhhhhhhhh",
      "hhhhhhhhhhhhhhhh",
      "vvvvvvvvvvvvvvvv"
    ],
    [
      "                ",
      "                ",
      "                ",
      "                ",
      "                ",
      "           S    ",
      "                ",
      "        b       ",
      "                ",
      "                ",
      "                ",
      "s ssfssss ssfss ",
      "gggggggggggggggg",
      "hhhhhhhhhhhhhhhh",
      "hhhhhhhhhhhhhhhh",
      "vvvvvvvvvvvvvvvv"
    ]
  ]
}