{
  "name": "multi_casino_11_base3",
  "refpalette": "deceasedcraft:multi_casino_11/multi_casino_11_base3_palette",
  "xsize": 16,
  "zsize": 16,
  "slices": [
    [
      "                ",
      "                ",
      "                ",
      "                ",
      "                ",
      "                ",
      "                ",
      "        a       ",
      "                ",
      "                ",
      "                ",
      "b  bc b b  bcb  ",
      "dddddddddddddddd",
      "eeeeeeeeeeeeeeee",
      "eeeeeeeeeeeeeeee",
      "vvvvvvvvvvvvvvvv"
    ],
    [
      "                ",
      "                ",
      "                ",
      "                ",
      "                ",
      "                ",
      "                ",
      "        a       ",
      "                ",
      "                ",
      "                ",
      "    c      bcb  ",
      "dddddddddddddddd",
      "eeeeeeeeeeeeeeee",
      "eeeeeeeeeeeeeeee",
      "vvvvvvvvvvvvvvvv"
    ],
    [
      "                ",
      "                ",
      "                ",
      "                ",
      "                ",
      "                ",
      "        f       ",
      "       gah      ",
      "                ",
      "                ",
      "                ",
      "    c       c   ",
      "dddddddddddddddd",
      "eeeeeeeeeeeeeeee",
      "eeeeeeeeeeeeeeee",
      "vvvvvvvvvvvvvvvv"
    ],
    [
      "                ",
      "                ",
      "                ",
      "                ",
      "                ",
      "                ",
      "                ",
      "        a       ",
      "                ",
      "                ",
      "                ",
      "    c       c   ",
      "dddddddddddddddd",
      "eeeeeeeeeeeeeeee",
      "eeeeeeeeeeeeeeee",
      "vvvvvvvvvvvvvvvv"
    ],
    [
      "ijiiiiiiiiiiiiij",
      "iijiiiiiiiiiiiji",
      "iiijiiiiiiiiijii",
      "kiiikiiikiiikiii",
      "iiiiijiiiiijiiii",
      "iiiiiijiiijiiiii",
      "iiiiiiijijiiiiii",
      "kiiikiiiaiiikiii",
      "iiiiiiijijiiiiii",
      "iiiiiijiiijiiiii",
      "iiiiijiiiiijiiii",
      "    c       c   ",
      "dddddddddddddddd",
      "eeeeeeeeeeeeeeee",
      "eeeeeeeeeeeeeeee",
      "vvvvvvvvvvvvvvvv"
    ],
    [
      "lallllllllllllla",
      "llalllllllllllal",
      "lllalllllllllall",
      "mlllalllmlllalll",
      "lllllalllllallll",
      "llllllalllalllll",
      "lllllllalallllll",
      "mlllmlllalllmlll",
      "lllllllalallllll",
      "llllllalllalllll",
      "nnnnlannnnnalnnn",
      "oooocooooooocooo",
      "dddddddddddddddd",
      "eeeeeeeeeeeeeeee",
      "eeeeeeeeeeeeeeee",
      "vvvvvvvvvvvvvvvv"
    ]
  ]
}