{
  "name": "multi_casino_11_ground",
  "refpalette": "deceasedcraft:multi_casino_11/multi_casino_11_ground_palette",
  "xsize": 16,
  "zsize": 16,
  "slices": [
    [
      "aaaaaaaaaabcdddd",
      "aaaaaaaaaabcdddd",
      "aaaaaaaaaabcdddd",
      "aaaaaaaaaabcdddd",
      "aaaaaaaaaabcdddd",
      "aaaaaaaaaabcdddd",
      "aaaaaaaaaabcdddd",
      "aaaaaaaaeabcffff",
      "aaaaaaaaaabcdddd",
      "bbbbbbbbbbbcdddd",
      "cccccccccccccccc",
      "gggggggdhdgggggg",
      "HHHHHHHdddHHHHHH",
      "HHHHHHHdddHHHHHH",
      "HHHHHHHHHHHHHHHH",
      "HHHHHHHHHHHHHHHH"
    ],
    [
      "       i   j    ",
      "           j    ",
      "       k   j    ",
      "       l   j    ",
      "       i   j    ",
      "           j    ",
      "mn omn     j    ",
      "    ~   e  j    ",
      "    ~      j    ",
      "           jpppp",
      "jjjjjjjqqqjjjjjj",
      "       rsr      ",
      "  t  uwrxry   t ",
      "  A   BrrrC   A ",
      "                ",
      "                "
    ],
    [
      "                ",
      "                ",
      "                ",
      "                ",
      "                ",
      "                ",
      "        e       ",
      "    ~  eDe      ",
      "                ",
      "                ",
      "                ",
      "        s       ",
      "        E       ",
      "                ",
      "                ",
      "                "
    ],
    [
      "                ",
      "                ",
      "                ",
      "                ",
      "                ",
      "        e       ",
      "                ",
      "    ~ e   e     ",
      "                ",
      "                ",
      "                ",
      "        s       ",
      "                ",
      "                ",
      "                ",
      "                "
    ],
    [
      "                ",
      "                ",
      "                ",
      "                ",
      "                ",
      "        e       ",
      "                ",
      "    ~ e   e     ",
      "                ",
      "                ",
      "                ",
      "        s       ",
      "                ",
      "                ",
      "                ",
      "                "
    ],
    [
      "                ",
      "                ",
      "                ",
      "                ",
      "        e       ",
      "                ",
      "                ",
      "    ~e     e    ",
      "                ",
      "                ",
      "                ",
      "        s       ",
      "                ",
      "                ",
      "                ",
      "                "
    ]
  ]
}