{
  "name": "multi_casino_11_base6",
  "refpalette": "deceasedcraft:multi_casino_11/multi_casino_11_base6_palette",
  "xsize": 16,
  "zsize": 16,
  "slices": [
    [
      "aaaaaaaaaaaaaaaa",
      "aaaaaaaaaaaaaaaa",
      "aaaaaaaaaaaaaaaa",
      "aaaaaaaaaaaaaaaa",
      "aaaaaaaaaaaaaaaa",
      "aaaaaaaaaaaaaaaa",
      "aaaaaaaaaaaaaaaa",
      "aaaaaaaabaaaaaaa",
      "aaaaaaaaaaaaaaaa",
      "cccccccccccccccc",
      "dddddddddddddddd",
      "eeeefeeeeeeefeee",
      "gggggggggggggggg",
      "hhhhhhhhhhhhhhhh",
      "hhhhhhhhhhhhhhhh",
      "vvvvvvvvvvvvvvvv"
    ],
    [
      "       iji      ",
      "                ",
      " kik   kik   kik",
      "lmnmo lmnmo lmnm",
      "in ni in ni in n",
      "lmnmo lmnmo lmnm",
      " jij   jij   jij",
      "        b       ",
      "                ",
      "                ",
      "    p       p   ",
      "qqqqfqqqqqqqfqqq",
      "gggggggggggggggg",
      "hhhhhhhhhhhhhhhh",
      "hhhhhhhhhhhhhhhh",
      "vvvvvvvvvvvvvvvv"
    ],
    [
      "                ",
      "                ",
      "                ",
      " rsr   tuw   tuw",
      " xys   uyu   uyu",
      " rxr   tuw   tuw",
      "                ",
      "        b       ",
      "                ",
      "                ",
      "                ",
      "qqqqfqqqqqqqfqqq",
      "gggggggggggggggg",
      "hhhhhhhhhhhhhhhh",
      "hhhhhhhhhhhhhhhh",
      "vvvvvvvvvvvvvvvv"
    ],
    [
      "                ",
      "                ",
      "                ",
      "                ",
      "  A     A     A ",
      "                ",
      "                ",
      "        b       ",
      "                ",
      "                ",
      "                ",
      "qqqqfqqqqqqqfqqq",
      "gggggggggggggggg",
      "hhhhhhhhhhhhhhhh",
      "hhhhhhhhhhhhhhhh",
      "vvvvvvvvvvvvvvvv"
    ],
    [
      "                ",
      "                ",
      "                ",
      "                ",
      "                ",
      "                ",
      "                ",
      "        b       ",
      "                ",
      "                ",
      "                ",
      "qqqqfqqqqqqqfqqq",
      "gggggggggggggggg",
      "hhhhhhhhhhhhhhhh",
      "hhhhhhhhhhhhhhhh",
      "vvvvvvvvvvvvvvvv"
    ],
    [
      "                ",
      "                ",
      "                ",
      "                ",
      "                ",
      "                ",
      "                ",
      "        b       ",
      "                ",
      "                ",
      "                ",
      "q qqfqqqq qqfqq ",
      "gggggggggggggggg",
      "hhhhhhhhhhhhhhhh",
      "hhhhhhhhhhhhhhhh",
      "vvvvvvvvvvvvvvvv"
    ]
  ]
}