{
  "name": "fountain_highrise_residential_bus",
  "refpalette": "deceasedcraft:fountains/fountain_highrise_residential_bus_palette",
  "xsize": 16,
  "zsize": 16,
  "slices": [
    [
      "                ",
      "                ",
      "       abbba    ",
      "       cdddce   ",
      "      fbdddb    ",
      "       gdddb    ",
      "        dddb    ",
      "      hgdddb i  ",
      "       gdddb    ",
      "       bdddb    ",
      "       cdddce   ",
      "       gdddb    ",
      "     j kgbbk    ",
      "        kklm    ",
      "                ",
      "                "
    ],
    [
      "                ",
      "       nooon    ",
      "       pqqqp    ",
      "       rstuw    ",
      "       xyABC    ",
      "       DpEpF    ",
      "       DpppF    ",
      "       IJKpF    ",
      "       LpppF    ",
      "       MNppE    ",
      "       OpE!w    ",
      "       PpppP    ",
      "       FQQRF    ",
      "       FS SF    ",
      "       T   T    ",
      "                "
    ],
    [
      "                ",
      "                ",
      "       UU UU    ",
      "      VW XYWZ   ",
      "       0  1     ",
      "       h2 20    ",
      "       3454h    ",
      "          6h    ",
      "      734 4     ",
      "       h8 90#   ",
      "      7h4540    ",
      "        9 $0#   ",
      "      %0^^^0#   ",
      "       00000    ",
      "        &       ",
      "                "
    ],
    [
      "                ",
      "                ",
      "        UUUU    ",
      "       U   Wf   ",
      "       *   (    ",
      "       *   F    ",
      "       )   )    ",
      "                ",
      "       )   )    ",
      "       *   *    ",
      "       )   *    ",
      "                ",
      "      +)   *    ",
      "       F(( F    ",
      "                ",
      "                "
    ],
    [
      "                ",
      "                ",
      "                ",
      "         -[]    ",
      "       {}|;{    ",
      "       :} |:    ",
      "         g|:    ",
      "       ' g;     ",
      "       :}g;:    ",
      "       :|b;{    ",
      "       '; ;{    ",
      "       '| |{    ",
      "       {};|{    ",
      "       ]<>>]    ",
      "                ",
      "                "
    ],
    [
      "                ",
      "                ",
      "                ",
      "                ",
      "                ",
      "         ,      ",
      "                ",
      "                ",
      "                ",
      "                ",
      "         .      ",
      "         ,      ",
      "                ",
      "                ",
      "                ",
      "                "
    ]
  ]
}