{
  "name": "multi_flatapartment_2_ground",
  "refpalette": "deceasedcraft:multi_flatapartment_2/multi_flatapartment_2_ground_palette",
  "xsize": 16,
  "zsize": 16,
  "slices": [
    [
      "abbbbaaaaaaaaaaa",
      "bcbbbbbbbbbbbbba",
      "bbcbbbbbbbbbbbba",
      "cbbbbbbbbbbbbbba",
      "bbbbbbbbbbbbbbba",
      "bbbbbbbbbbbbbbba",
      "bbbbbbbbbbbbbbba",
      "bbbbbbbbbbbbbbba",
      "bbbbbbbbbbbbbbba",
      "bbbbbbbbcbbbbbba",
      "bbcbbbcbbbbbbbba",
      "bcbbbcbdebcbbbba",
      "bbbbbedfgcbbbbba",
      "bbcbbbhggbbbbbba",
      "bbbbbbbgbbbbbbba",
      "abbbbaaaaaaaaaaa"
    ],
    [
      "i    iiiiiiiiiij",
      "k    klllkm  nki",
      "op        q  rsi",
      "              si",
      "tu            si",
      "k   lklllkl   ki",
      "n   m  w  n  mni",
      "r   q  x  r    i",
      "n   m  w  n  y  ",
      "r   q  x  r  qr ",
      "k  ABk CCkC   ki",
      "n  DE D       si",
      "  FI   J  K   si",
      "r  LM   K m  nsi",
      "k    ke Ckq  rki",
      "i    i  iiiiiiij"
    ],
    [
      "               N",
      "O    O   O    O ",
      "P               ",
      "                ",
      "                ",
      "O    O   O    O ",
      "                ",
      "                ",
      "                ",
      "                ",
      "O    O   O    O ",
      "                ",
      "                ",
      "                ",
      "O    O   O    O ",
      "               N"
    ],
    [
      "               Q",
      "OR  ROR ROR  RO ",
      "              R ",
      "                ",
      "              R ",
      "O    O   O    O ",
      "              R ",
      "                ",
      "                ",
      "              R ",
      "O    O   O    O ",
      "              R ",
      "                ",
      "              R ",
      "OR  ROR ROR  RO ",
      "               Q"
    ],
    [
      "                ",
      "OSSSSOSSSOSSSSO ",
      "T    T   T    S ",
      "              S ",
      "              S ",
      "O    O   O   TO ",
      "              S ",
      "              S ",
      "              S ",
      "              S ",
      "O    O   O   TO ",
      "              S ",
      "              S ",
      "T    T   T    S ",
      "OSSSSOSSSOSSSSO ",
      "                "
    ],
    [
      "                ",
      "SSSSSSSSSSSSSSS ",
      "bbbbbbbbbbbbbbS ",
      "b    b   b   bS ",
      "b    b   b   bS ",
      "bbbbbbbbbbbbbbS ",
      "b    b   b   bS ",
      "b    b   b   bS ",
      "b    b   b   bS ",
      "b    b   b   bS ",
      "bbbbbbbbbbbbbbS ",
      "b    !   b   bS ",
      "b    b   b   bS ",
      "bbbbbbbbbbbbbbS ",
      "SSSSSSSSSSSSSSS ",
      "                "
    ]
  ]
}