{
  "name": "multi_flatapartment_2_floor1",
  "refpalette": "deceasedcraft:multi_flatapartment_2/multi_flatapartment_2_floor1_palette",
  "xsize": 16,
  "zsize": 16,
  "slices": [
    [
      "                ",
      "abbbbabbbabbbba ",
      "ccccccccccddddb ",
      "ccccccccccddddb ",
      "ccccccccccddddb ",
      "cccccccccccccca ",
      "ccccccccccccccb ",
      "ccccccccccccccb ",
      "ccccccccccccccb ",
      "ccccccccccccccb ",
      "cccccccccceeeea ",
      "ccccccccccddddb ",
      "ccccccccccddddb ",
      "ccccccccccddddb ",
      "abbbbabbbabbbba ",
      "                "
    ],
    [
      "                ",
      "abffbabfbabffba ",
      "         g   hb ",
      "  ii j  kbl  mf ",
      "nopqrbs tb uwxb ",
      "byyyybs AbBbbba ",
      "bC  DbE  F   Ib ",
      "bJ  Dbbbbb    f ",
      "bK   L MNb OO f ",
      "bPii b  QbRSSRb ",
      "bTUV b   bbbbba ",
      "WXYX b   g Z0xb ",
      "     1111bl  2f ",
      "         3   4b ",
      "abffbabfbabffba ",
      "                "
    ],
    [
      "                ",
      "ab55bab5bab55ba ",
      "     6   7   8b ",
      "     j   b    5 ",
      "    9b  #b    b ",
      "b$$$$b   b%bbba ",
      "b    b   ^   $b ",
      "b&   bbbbb*   5 ",
      "b    ( ! b    5 ",
      "b    b   b    b ",
      "b    b   bbbbba ",
      "     b   7    b ",
      "     1111b    5 ",
      "         )   +b ",
      "ab55bab5bab55ba ",
      "                "
    ],
    [
      "                ",
      "ab55bab5bab55ba ",
      "         b   -b ",
      "     j   b[   5 ",
      "     b   b    b ",
      "b$$$$b   bbbbba ",
      "b    b   ]   $b ",
      "b    bbbbb    5 ",
      "b    ]   b    5 ",
      "b    b   b    b ",
      "b    b   bbbbba ",
      "{    b   b    b ",
      "     1111b[   5 ",
      "         b   }b ",
      "ab55bab5bab55ba ",
      "                "
    ],
    [
      "                ",
      "abbbbabbbabbbba ",
      "b    b   b||||b ",
      "b  ; b   b||||b ",
      "b    b : b||||b ",
      "bbbbbb   bbbbba ",
      "b    b   b   $b ",
      "b  : bbbbb    b ",
      "b    b   b    b ",
      "b    b   b    b ",
      "bbbbbb   bbbbba ",
      "b    b   b||||b ",
      "b  ; b111b||||b ",
      "b    b   b||||b ",
      "abbbbabbbabbbba ",
      "                "
    ],
    [
      "                ",
      "'<<<<'<<<'<<<<' ",
      ">>>>>>>>>>>>>>< ",
      "b>>>>b>>>b   >< ",
      "b>>>>b>>>b   >< ",
      "bbbbbb>>>bbbb>' ",
      "b>>>>b>>>b>>>>< ",
      "b>>>>bbbbb>>>>< ",
      "b>>>>b>>>b>>>>< ",
      "b>>>>b>>>b>>>>< ",
      "bbbbbb>>>bbbb>' ",
      "b>>>>b>>>b   >< ",
      "b>>>>b>>>b   >< ",
      ">>>>>>>>>>>>>>< ",
      "'<<<<'<<<'<<<<' ",
      "                "
    ]
  ]
}