{
  "name": "multi_flatapartment_2_floor2",
  "refpalette": "deceasedcraft:multi_flatapartment_2/multi_flatapartment_2_floor2_palette",
  "xsize": 16,
  "zsize": 16,
  "slices": [
    [
      "                ",
      "abbbbabbbabbbba ",
      "ccccccccccdedeb ",
      "ccccccccccddefb ",
      "ccccccccccfeedb ",
      "ccccccccccgfhca ",
      "ccccccccccccieb ",
      "ccccccccccccccb ",
      "ccccccccccccccb ",
      "ccciccccccccccb ",
      "ccciecccccjjjja ",
      "cccckcicccddddb ",
      "ciefgeicccddddb ",
      "icckecccccddddb ",
      "abflimbbbabbbba ",
      "                "
    ],
    [
      "                ",
      "abnnbabnbabopqq ",
      "      r s tuiwx ",
      "  yy A rBCiD  p ",
      "EFIJKbL Ml NuiC ",
      "bOOOObL PQ   ba ",
      "bRSTUbV  W D  b ",
      "bXY  bbbbbZ 01n ",
      "b234 5 67b899 n ",
      "b#y $b  %b^&&*b ",
      "b() +b4  bbbbba ",
      "-[lf f  0] {}|b ",
      "D w  t ;;b:  'n ",
      " <i ui>4,.   ?b ",
      "abp   hobabnnba ",
      "                "
    ],
    [
      "                ",
      "ab//bab/baC/    ",
      "     `          ",
      "     A   p      ",
      "     b  \u0370C    p ",
      "b\u0371\u0371\u0371\u0371b   Q   Qa ",
      "b\u0372   b   \u0373    b ",
      "b    bbbbb\u0374   / ",
      "b    \u0375 ! b    / ",
      "b    b   b   \u0376b ",
      "b4   b   bbbbba ",
      "  t  0   \u0377    b ",
      "       ;;b    / ",
      "         \u037a   \u037bb ",
      "ab/    /bab//ba ",
      "                "
    ],
    [
      "                ",
      "ab//bab/bab/    ",
      "         b      ",
      "     A   C      ",
      "     b   l      ",
      "b\u0371\u0371\u0371\u0371b   Q  QbQ ",
      "b    b   \u037c    b ",
      "b    bbbbb    / ",
      "b    \u037c   b    / ",
      "b    b   b    b ",
      "b    b   bbbbba ",
      "\u037d    Q   b    b ",
      "       ;;b\u037e   / ",
      "         b   \u037fb ",
      "ab/   Q/bab//ba ",
      "                "
    ],
    [
      "                ",
      "abbbbabbbabQ\u0384   ",
      "b    b   b\u0385\u0385\u0385\u0385  ",
      "b  \u0386 b   b\u0385\u0385\u0385\u0385\u0387 ",
      "b    b \u0388 C\u0385\u0385\u0385\u0385l ",
      "bbbbbb   bbbbba ",
      "b    b   b   \u0371b ",
      "b  \u0388 bbbbb    b ",
      "b    b   b    b ",
      "b    b   b    b ",
      "bbbbbb   bbbbba ",
      "b    b   b\u0385\u0385\u0385\u0385b ",
      "b  \u0386 m;;;b\u0385\u0385\u0385\u0385b ",
      "b    m   b\u0385\u0385\u0385\u0385b ",
      "abbC  Qbbabbbba ",
      "                "
    ],
    [
      "                ",
      "\u0389\u038a\u038a\u038a\u038a\u0389\u038a\u038a\u038a\u0389\u038a\u038a\u038a\u038a  ",
      "\u038c\u038c\u038c\u038c\u038c\u038c\u038c\u038c\u038c\u038c\u038c\u038c\u038c\u038c\u038a ",
      "b\u038c\u038c\u038c\u038cb\u038c\u038c\u038cb   \u038c\u038a ",
      "b\u038c\u038c\u038c\u038cb\u038c\u038c\u038cb   \u038c\u038a ",
      "bbbbbb\u038c\u038c\u038cbbbb\u038c\u0389 ",
      "b\u038c\u038c\u038c\u038cb\u038c\u038c\u038cb\u038c\u038c\u038c\u038c\u038a ",
      "b\u038c\u038c\u038c\u038cbbbbb\u038c\u038c\u038c\u038c\u038a ",
      "b\u038c\u038c\u038c\u038cb\u038c\u038c\u038cb\u038c\u038c\u038c\u038c\u038a ",
      "b\u038c\u038c\u038c\u038cb\u038c\u038c\u038cb\u038c\u038c\u038c\u038c\u038a ",
      "bbbbbb\u038c\u038c\u038cbbbb\u038c\u0389 ",
      "b\u038c\u038c\u038c\u038cb\u038c\u038c\u038cb   \u038c\u038a ",
      "b\u038c\u038c\u038c\u038cb\u038c\u038c\u038cb   \u038c\u038a ",
      "\u038c\u038c\u038c\u038c\u038c\u038c\u038c\u038c\u038c\u038c\u038c\u038c\u038c\u038c\u038a ",
      "\u0389\u038a\u038a\u038aq\u0389\u038a\u038a\u038a\u0389\u038a\u038a\u038a\u038a\u0389 ",
      "                "
    ]
  ]
}