{
  "name": "multi_flatapartment_2_floor3",
  "refpalette": "deceasedcraft:multi_flatapartment_2/multi_flatapartment_2_floor3_palette",
  "xsize": 16,
  "zsize": 16,
  "slices": [
    [
      "                ",
      "abbbbabbbabbbba ",
      "ccccccccccddddb ",
      "ccccccccccddddb ",
      "ccccccccccddddb ",
      "cccccccccccccca ",
      "ccccccccccccccb ",
      "ccccccccccccccb ",
      "ccccccccccccccb ",
      "ccccccccccccccb ",
      "cccccccccceeeea ",
      "ccccccccccddddb ",
      "ccccccccccddddb ",
      "ccccccccccddddb ",
      "abbbbabbbabbbba ",
      "                "
    ],
    [
      "                ",
      "abffbabfbabffba ",
      "         g   hb ",
      "  ii j  kbl  mf ",
      "nopqrbs tb uwxb ",
      "byyyybs AbBbbba ",
      "bC  DbE      Fb ",
      "bI  Dbbbbb    f ",
      "bJ     KLb MM f ",
      "bNii b  ObPQQPb ",
      "bRST b   bbbbba ",
      "UVWV b   g XYxb ",
      "     ZZZZbl  0f ",
      "         1   2b ",
      "abffbabfbabffba ",
      "                "
    ],
    [
      "                ",
      "ab33bab3bab33ba ",
      "     4   5   6b ",
      "     j   b    3 ",
      "    7b  8b    b ",
      "b9999b   b#bbba ",
      "b    b       9b ",
      "b$   bbbbb%   3 ",
      "b      ! b    3 ",
      "b    b   b    b ",
      "b    b   bbbbba ",
      "     b   5    b ",
      "     ZZZZb    3 ",
      "         ^   &b ",
      "ab33bab3bab33ba ",
      "                "
    ],
    [
      "                ",
      "ab33bab3bab33ba ",
      "         b   *b ",
      "     j   b(   3 ",
      "     b   b    b ",
      "b9999b   bbbbba ",
      "b    b   )   9b ",
      "b    bbbbb    3 ",
      "b    )   b    3 ",
      "b    b   b    b ",
      "b    b   bbbbba ",
      "+    b   b    b ",
      "     ZZZZb(   3 ",
      "         b   -b ",
      "ab33bab3bab33ba ",
      "                "
    ],
    [
      "                ",
      "abbbbabbbabbbba ",
      "b    b   b[[[[b ",
      "b  ] b   b[[[[b ",
      "b    b { b[[[[b ",
      "bbbbbb   bbbbba ",
      "b    b   b   9b ",
      "b  { bbbbb    b ",
      "b    b   b    b ",
      "b    b   b    b ",
      "bbbbbb   bbbbba ",
      "b    b   b[[[[b ",
      "b  ] bZZZb[[[[b ",
      "b    b   b[[[[b ",
      "abbbbabbbabbbba ",
      "                "
    ],
    [
      "                ",
      "}||||}|||}||||} ",
      ";;;;;;;;;;;;;;| ",
      "b;;;;b;;;b   ;| ",
      "b;;;;b;;;b   ;| ",
      "bbbbbb;;;bbbb;} ",
      "b;;;;b;;;b;;;;| ",
      "b;;;;bbbbb;;;;| ",
      "b;;;;b;;;b;;;;| ",
      "b;;;;b;;;b;;;;| ",
      "bbbbbb;;;bbbb;} ",
      "b;;;;b;;;b   ;| ",
      "b;;;;b;;;b   ;| ",
      ";;;;;;;;;;;;;;| ",
      "}||||}|||}||||} ",
      "                "
    ]
  ]
}