{
  "name": "multi_casino_0_base4",
  "refpalette": "deceasedcraft:multi_casino_0/multi_casino_0_base4_palette",
  "xsize": 16,
  "zsize": 16,
  "slices": [
    [
      "vvvvvvvvvvvvvvvv",
      "vaaaaaaaaaaaaaaa",
      "vaabbbbbbbbbbbbb",
      "vaabcdddddddcddd",
      "vaabdeeeeeeeeeee",
      "vaabdeffffffffff",
      "vaabdefggggggggg",
      "vaabdefghggggggg",
      "vaabdefggggggggg",
      "vaabdefggggggggg",
      "vaabdefggggggggg",
      "vaabcefggggggggg",
      "vaabdefggggggggg",
      "vaabdefggggggggg",
      "vaabdefggggggggg",
      "vaabdefggggggggg"
    ],
    [
      "vvvvvvvvvvvvvvvv",
      "vaaaaaaaaaaaaaaa",
      "vaabbbbbbbbbbbbb",
      "vaabciiiiiiiciii",
      "vaabi       j   ",
      "vaabi           ",
      "vaabi           ",
      "vaabi   h    kk ",
      "vaabi       lmmn",
      "vaabi     o pmm ",
      "vaabi      pmmmq",
      "vaabcr   kpmmmmq",
      "vaabi   lmmmmmq ",
      "vaabi   lmmmmq  ",
      "vaabi    s qq   ",
      "vaabi           "
    ],
    [
      "vvvvvvvvvvvvvvvv",
      "vaaaaaaaaaaaaaaa",
      "vaabbbbbbbbbbbbb",
      "vaabciiiiiiiciii",
      "vaabi           ",
      "vaabi           ",
      "vaabi           ",
      "vaabi   h       ",
      "vaabi           ",
      "vaabi       t   ",
      "vaabi      u    ",
      "vaabc     w     ",
      "vaabi           ",
      "vaabi           ",
      "vaabi           ",
      "vaabi           "
    ],
    [
      "vvvvvvvvvvvvvvvv",
      "vaaaaaaaaaaaaaaa",
      "vaabbbbbbbbbbbbb",
      "vaabciiiiiiiciii",
      "vaabi           ",
      "vaabi           ",
      "vaabi           ",
      "vaabi   h       ",
      "vaabi           ",
      "vaabi           ",
      "vaabi           ",
      "vaabc           ",
      "vaabi           ",
      "vaabi           ",
      "vaabi           ",
      "vaabi           "
    ],
    [
      "vvvvvvvvvvvvvvvv",
      "vaaaaaaaaaaaaaaa",
      "vaabbbbbbbbbbbbb",
      "vaabciiiiiiiciii",
      "vaabi           ",
      "vaabi           ",
      "vaabi           ",
      "vaabi   h       ",
      "vaabi           ",
      "vaabi           ",
      "vaabi           ",
      "vaabc           ",
      "vaabi           ",
      "vaabi           ",
      "vaabi           ",
      "vaabi           "
    ],
    [
      "vvvvvvvvvvvvvvvv",
      "vaaaaaaaaaaaaaaa",
      "vaabbbbbbbbbbbbb",
      "vaabciiii iicii ",
      "vaabi           ",
      "vaab            ",
      "vaabi           ",
      "vaabi   h       ",
      "vaabi           ",
      "vaabi           ",
      "vaabi           ",
      "vaabc           ",
      "vaabi           ",
      "vaabi           ",
      "vaabi           ",
      "vaab            "
    ]
  ]
}