{
  "name": "multi_casino_0_base2",
  "refpalette": "deceasedcraft:multi_casino_0/multi_casino_0_base2_palette",
  "xsize": 16,
  "zsize": 16,
  "slices": [
    [
      "vvvvvvvvvvvvvvvv",
      "vaaaaaaaaaaaaaaa",
      "vaabbbbbbbbbbbbb",
      "vaabcdddddddcddd",
      "vaabdeeeeeeeeeee",
      "vaabdeffffffffff",
      "vaabdefggggggggg",
      "vaabdefghggggggg",
      "vaabdefggggggggg",
      "vaabdefggggggggg",
      "vaabdefggggggggg",
      "vaabcefggggggggg",
      "vaabdefggggggggg",
      "vaabdefggggggggg",
      "vaabdefggggggggg",
      "vaabdefggggggggg"
    ],
    [
      "vvvvvvvvvvvvvvvv",
      "vaaaaaaaaaaaaaaa",
      "vaabbbbbbbbbbbbb",
      "vaabciiiiiiiciii",
      "vaabi       j   ",
      "vaabi           ",
      "vaabi           ",
      "vaabi   h       ",
      "vaabi      k    ",
      "vaabi      l  km",
      "vaabi    kmnok  ",
      "vaabcp     q    ",
      "vaabi      k    ",
      "vaabi     k     ",
      "vaabi     l     ",
      "vaabi   kmnok   "
    ],
    [
      "vvvvvvvvvvvvvvvv",
      "vaaaaaaaaaaaaaaa",
      "vaabbbbbbbbbbbbb",
      "vaabciiiiiiiciii",
      "vaabi           ",
      "vaabi           ",
      "vaabi           ",
      "vaabi   h       ",
      "vaabi           ",
      "vaabi      r   s",
      "vaabi     stu   ",
      "vaabc      w    ",
      "vaabi           ",
      "vaabi           ",
      "vaabi     r     ",
      "vaabi    stu    "
    ],
    [
      "vvvvvvvvvvvvvvvv",
      "vaaaaaaaaaaaaaaa",
      "vaabbbbbbbbbbbbb",
      "vaabciiiiiiiciii",
      "vaabi           ",
      "vaabi           ",
      "vaabi           ",
      "vaabi   h       ",
      "vaabi           ",
      "vaabi      x   y",
      "vaabi     ytA   ",
      "vaabc      B    ",
      "vaabi           ",
      "vaabi           ",
      "vaabi     x     ",
      "vaabi    ytA    "
    ],
    [
      "vvvvvvvvvvvvvvvv",
      "vaaaaaaaaaaaaaaa",
      "vaabbbbbbbbbbbbb",
      "vaabciiiiiiiciii",
      "vaabi           ",
      "vaabi           ",
      "vaabi           ",
      "vaabi   h       ",
      "vaabi           ",
      "vaabi      C   D",
      "vaabi     D E   ",
      "vaabc      F    ",
      "vaabi           ",
      "vaabi           ",
      "vaabi     C     ",
      "vaabi    D!E    "
    ],
    [
      "vvvvvvvvvvvvvvvv",
      "vaaaaaaaaaaaaaaa",
      "vaabbbbbbbbbbbbb",
      "vaabciiii iicii ",
      "vaabi           ",
      "vaab            ",
      "vaabi           ",
      "vaabi   h       ",
      "vaabi           ",
      "vaabi           ",
      "vaabi      I    ",
      "vaabc           ",
      "vaabi           ",
      "vaabi           ",
      "vaabi           ",
      "vaab            "
    ]
  ]
}