{
  "name": "multi_casino_0_base5",
  "refpalette": "deceasedcraft:multi_casino_0/multi_casino_0_base5_palette",
  "xsize": 16,
  "zsize": 16,
  "slices": [
    [
      "vvvvvvvvvvvvvvvv",
      "vaaaaaaaaaaaaaaa",
      "vaabbbbbbbbbbbbb",
      "vaabcdd   ddcd  ",
      "vaabd           ",
      "vaab            ",
      "vaab            ",
      "vaabd   e       ",
      "vaabd           ",
      "vaab            ",
      "vaabd           ",
      "vaabc           ",
      "vaabd           ",
      "vaabd           ",
      "vaab            ",
      "vaab            "
    ],
    [
      "vvvvvvvvvvvvvvvv",
      "vaaaaaaaaaaaaaaa",
      "vaabbbbbbbbbbbbb",
      "vaabcd     dcd  ",
      "vaabd           ",
      "vaab            ",
      "vaab            ",
      "vaabd   e       ",
      "vaab            ",
      "vaab            ",
      "vaab            ",
      "vaabc           ",
      "vaab            ",
      "vaab            ",
      "vaab            ",
      "vaab            "
    ],
    [
      "vvvvvvvvvvvvvvvv",
      "vaaaaaaaaaaaaaaa",
      "vaabbbbbbbbbbbbb",
      "vaabcd      c   ",
      "vaab            ",
      "vaab            ",
      "vaab            ",
      "vaab    ef      ",
      "vaab    g       ",
      "vaab            ",
      "vaab            ",
      "vaabc           ",
      "vaab            ",
      "vaab            ",
      "vaab            ",
      "vaab            "
    ],
    [
      "vvvvvvvvvvvvvvvv",
      "vaaaaaaaaaaaaaaa",
      "vaabbbbbbbbbbbbb",
      "vaabc       c   ",
      "vaab            ",
      "vaab            ",
      "vaab            ",
      "vaab    e       ",
      "vaab            ",
      "vaab            ",
      "vaab            ",
      "vaabc           ",
      "vaab            ",
      "vaab            ",
      "vaab            ",
      "vaab            "
    ],
    [
      "vvvvvvvvvvvvvvvv",
      "vaaaaaaaaaaaaaaa",
      "vaabbbbbbbbbbbbb",
      "vaabc       c   ",
      "vaab hiiiiihiiii",
      "vaab ihiiihiiiii",
      "vaab iihihiiiiii",
      "vaab iiieiiijiii",
      "vaab iihihiiiiii",
      "vaab ihiiihiiiii",
      "vaab hiiiiihiiii",
      "vaabciiijiiijiii",
      "vaab iiiiiiiihii",
      "vaab iiiiiiiiihi",
      "vaab iiiiiiiiiih",
      "vaab iiijiiijiii"
    ],
    [
      "vvvvvvvvvvvvvvvv",
      "vaaaaaaaaaaaaaaa",
      "vaabbbbbbbbbbbbb",
      "vaabckkkkkkkckkk",
      "vaablemmmmmenmmm",
      "vaablmennnennnnn",
      "vaablmnenennnnnn",
      "vaablmnnennnonnn",
      "vaablmnenennnnnn",
      "vaablmennnennnnn",
      "vaablennnnnennnn",
      "vaabcnnnonnnennn",
      "vaablmnnnnnnnenn",
      "vaablmnnnnnnnnen",
      "vaablmnnnnnnnnne",
      "vaablmnnonnnonnn"
    ]
  ]
}