{
  "name": "multi_casino_0_base7",
  "refpalette": "deceasedcraft:multi_casino_0/multi_casino_0_base7_palette",
  "xsize": 16,
  "zsize": 16,
  "slices": [
    [
      "vvvvvvvvvvvvvvvv",
      "vaaaaaaaaaaaaaaa",
      "vaabbbbbbbbbbbbb",
      "vaabcdd   ddcd  ",
      "vaabd           ",
      "vaab            ",
      "vaab            ",
      "vaabd   e       ",
      "vaabd           ",
      "vaab            ",
      "vaabd           ",
      "vaabc           ",
      "vaabd           ",
      "vaabd           ",
      "vaab            ",
      "vaab            "
    ],
    [
      "vvvvvvvvvvvvvvvv",
      "vaaaaaaaaaaaaaaa",
      "vaabbbbbbbbbbbbb",
      "vaabcd     dcd  ",
      "vaabd           ",
      "vaab            ",
      "vaab            ",
      "vaabd   e       ",
      "vaab            ",
      "vaab            ",
      "vaab            ",
      "vaabc           ",
      "vaab            ",
      "vaab            ",
      "vaab           f",
      "vaab            "
    ],
    [
      "vvvvvvvvvvvvvvvv",
      "vaaaaaaaaaaaaaaa",
      "vaabbbbbbbbbbbbb",
      "vaabcd      c   ",
      "vaab            ",
      "vaab            ",
      "vaab            ",
      "vaab    e       ",
      "vaab            ",
      "vaab            ",
      "vaab            ",
      "vaabc           ",
      "vaab            ",
      "vaab            ",
      "vaab           g",
      "vaab        f   "
    ],
    [
      "vvvvvvvvvvvvvvvv",
      "vaaaaaaaaaaaaaaa",
      "vaabbbbbbbbbbbbb",
      "vaabc       c   ",
      "vaab            ",
      "vaab            ",
      "vaab            ",
      "vaab    e       ",
      "vaab            ",
      "vaab            ",
      "vaab            ",
      "vaabc           ",
      "vaab            ",
      "vaab            ",
      "vaab           g",
      "vaab        g  g"
    ],
    [
      "vvvvvvvvvvvvvvvv",
      "vaaaaaaaaaaaaaaa",
      "vaabbbbbbbbbbbbb",
      "vaabc       c   ",
      "vaab hiiiiihiiii",
      "vaab ihiiihiiiii",
      "vaab iihihiiiiii",
      "vaab iiieiiijiii",
      "vaab iihihiiiiii",
      "vaab ihiiihiiihh",
      "vaab hiiiiihhhh ",
      "vaabciiijiihk   ",
      "vaab iiiiiih l  ",
      "vaab iiiiihh  l ",
      "vaab iiiiih    m",
      "vaab iiijihgg   "
    ],
    [
      "vvvvvvvvvvvvvvvv",
      "vaaaaaaaaaaaaaaa",
      "vaabbbbbbbbbbbbb",
      "vaabcnnnnnnncnnn",
      "vaaboepppppeqppp",
      "vaabopeqqqeqqqqq",
      "vaabopqeqeqqqqqq",
      "vaabopqqeqqqmqqq",
      "vaabopqeqeqqqqqq",
      "vaabopeqqqeqqqqq",
      "vaaboeqqqqqeqqqm",
      "vaabcqqqmqqqerrr",
      "vaabopqqqqqqrerr",
      "vaabopqqqqqqrrer",
      "vaabopqqqqqmrrre",
      "vaabopqqmqqmmrrr"
    ]
  ]
}