{
  "name": "multi_casino_0_base8",
  "refpalette": "deceasedcraft:multi_casino_0/multi_casino_0_base8_palette",
  "xsize": 16,
  "zsize": 16,
  "slices": [
    [
      "vvvvvvvvvvvvvvvv",
      "vaaaaaaaaaaaaaaa",
      "vaabbbbbbbbbbbbb",
      "vaabcdddddddcddd",
      "vaabdeeeeeeeeeee",
      "vaabdeffffffffff",
      "vaabdefeeeeeeeee",
      "vaabdefegeeeeeee",
      "vaabdefeeeeeeeee",
      "vaabdefeeeeeeeee",
      "vaabdefeeeeeeeee",
      "vaabcefeeeeeeeee",
      "vaabdefeeeeeeeee",
      "vaabdefeeeeeeeee",
      "vaabdefeeeeeeeee",
      "vaabdefeeeeeeeee"
    ],
    [
      "vvvvvvvvvvvvvvvv",
      "vaaaaaaaaaaaaaaa",
      "vaabbbbbbbbbbbbb",
      "vaabchhhhhhhchhh",
      "vaabh       i   ",
      "vaabh           ",
      "vaabh        jkk",
      "vaabh   geeeeeee",
      "vaabh   eeeeeeee",
      "vaabh   eeeeeeee",
      "vaabh   eeeeeeee",
      "vaabcl  eeeeeeee",
      "vaabh  meeeeeeee",
      "vaabh  neeeeeeee",
      "vaabh  neeeeeeee",
      "vaabh  neeeeeeee"
    ],
    [
      "vvvvvvvvvvvvvvvv",
      "vaaaaaaaaaaaaaaa",
      "vaabbbbbbbbbbbbb",
      "vaabchhhhhhhchhh",
      "vaabh           ",
      "vaabh           ",
      "vaabh           ",
      "vaabh   g       ",
      "vaabh           ",
      "vaabh           ",
      "vaabh           ",
      "vaabc           ",
      "vaabh           ",
      "vaabh           ",
      "vaabh           ",
      "vaabh           "
    ],
    [
      "vvvvvvvvvvvvvvvv",
      "vaaaaaaaaaaaaaaa",
      "vaabbbbbbbbbbbbb",
      "vaabchhhhhhhchhh",
      "vaabh           ",
      "vaabh           ",
      "vaabh           ",
      "vaabh   g       ",
      "vaabh           ",
      "vaabh           ",
      "vaabh           ",
      "vaabc           ",
      "vaabh           ",
      "vaabh           ",
      "vaabh           ",
      "vaabh           "
    ],
    [
      "vvvvvvvvvvvvvvvv",
      "vaaaaaaaaaaaaaaa",
      "vaabbbbbbbbbbbbb",
      "vaabchhhhhhhchhh",
      "vaabh           ",
      "vaabh           ",
      "vaabh           ",
      "vaabh   g       ",
      "vaabh           ",
      "vaabh           ",
      "vaabh           ",
      "vaabc           ",
      "vaabh           ",
      "vaabh           ",
      "vaabh           ",
      "vaabh           "
    ],
    [
      "vvvvvvvvvvvvvvvv",
      "vaaaaaaaaaaaaaaa",
      "vaabbbbbbbbbbbbb",
      "vaabchhhh hhchh ",
      "vaabh           ",
      "vaab            ",
      "vaabh           ",
      "vaabh   g       ",
      "vaabh           ",
      "vaabh           ",
      "vaabh           ",
      "vaabc           ",
      "vaabh           ",
      "vaabh           ",
      "vaabh           ",
      "vaab            "
    ]
  ]
}