{
  "name": "multi_casino_0_base6",
  "refpalette": "deceasedcraft:multi_casino_0/multi_casino_0_base6_palette",
  "xsize": 16,
  "zsize": 16,
  "slices": [
    [
      "vvvvvvvvvvvvvvvv",
      "vaaaaaaaaaaaaaaa",
      "vaabbbbbbbbbbbbb",
      "vaabcdddddddcddd",
      "vaabdeeeeeeeeeee",
      "vaabdeffffffffff",
      "vaabdefggggggggg",
      "vaabdefghggggggg",
      "vaabdefggggggggg",
      "vaabdefggggggggg",
      "vaabdefggggggggg",
      "vaabcefggggggggg",
      "vaabdefggggggggg",
      "vaabdefggggggggg",
      "vaabdefggggggggg",
      "vaabdefggggggggg"
    ],
    [
      "vvvvvvvvvvvvvvvv",
      "vaaaaaaaaaaaaaaa",
      "vaabbbbbbbbbbbbb",
      "vaabciiiiiiiciii",
      "vaabi       j   ",
      "vaabi           ",
      "vaabi           ",
      "vaabi   h       ",
      "vaabi      k lll",
      "vaabi     mmmnop",
      "vaabi    qm mnnn",
      "vaabcr    mmmnpo",
      "vaabi    lnnn ll",
      "vaabi    lpnol  ",
      "vaabi    lonpl  ",
      "vaabi    lnnnl  "
    ],
    [
      "vvvvvvvvvvvvvvvv",
      "vaaaaaaaaaaaaaaa",
      "vaabbbbbbbbbbbbb",
      "vaabciiiiiiiciii",
      "vaabi           ",
      "vaabi           ",
      "vaabi           ",
      "vaabi   h       ",
      "vaabi           ",
      "vaabi       s   ",
      "vaabi      t    ",
      "vaabc     u w   ",
      "vaabi           ",
      "vaabi           ",
      "vaabi           ",
      "vaabi           "
    ],
    [
      "vvvvvvvvvvvvvvvv",
      "vaaaaaaaaaaaaaaa",
      "vaabbbbbbbbbbbbb",
      "vaabciiiiiiiciii",
      "vaabi           ",
      "vaabi           ",
      "vaabi           ",
      "vaabi   h       ",
      "vaabi           ",
      "vaabi           ",
      "vaabi           ",
      "vaabc           ",
      "vaabi           ",
      "vaabi           ",
      "vaabi           ",
      "vaabi           "
    ],
    [
      "vvvvvvvvvvvvvvvv",
      "vaaaaaaaaaaaaaaa",
      "vaabbbbbbbbbbbbb",
      "vaabciiiiiiiciii",
      "vaabi           ",
      "vaabi           ",
      "vaabi           ",
      "vaabi   h       ",
      "vaabi           ",
      "vaabi           ",
      "vaabi           ",
      "vaabc           ",
      "vaabi           ",
      "vaabi           ",
      "vaabi           ",
      "vaabi           "
    ],
    [
      "vvvvvvvvvvvvvvvv",
      "vaaaaaaaaaaaaaaa",
      "vaabbbbbbbbbbbbb",
      "vaabciiii iicii ",
      "vaabi           ",
      "vaab            ",
      "vaabi           ",
      "vaabi   h       ",
      "vaabi           ",
      "vaabi           ",
      "vaabi           ",
      "vaabc           ",
      "vaabi           ",
      "vaabi           ",
      "vaabi           ",
      "vaab            "
    ]
  ]
}