{
  "name": "multi_casino_0_base3",
  "refpalette": "deceasedcraft:multi_casino_0/multi_casino_0_base3_palette",
  "xsize": 16,
  "zsize": 16,
  "slices": [
    [
      "vvvvvvvvvvvvvvvv",
      "vaaaaaaaaaaaaaaa",
      "vaabbbbbbbbbbbbb",
      "vaabcdd   ddcd  ",
      "vaabd           ",
      "vaab            ",
      "vaab      e     ",
      "vaabd   fge     ",
      "vaabd   h e     ",
      "vaab   iii      ",
      "vaabd           ",
      "vaabc           ",
      "vaabd           ",
      "vaabd           ",
      "vaab            ",
      "vaab            "
    ],
    [
      "vvvvvvvvvvvvvvvv",
      "vaaaaaaaaaaaaaaa",
      "vaabbbbbbbbbbbbb",
      "vaabcd     dcd  ",
      "vaabd           ",
      "vaab            ",
      "vaab            ",
      "vaabd   f       ",
      "vaab            ",
      "vaab            ",
      "vaab            ",
      "vaabc           ",
      "vaab            ",
      "vaab            ",
      "vaab            ",
      "vaab            "
    ],
    [
      "vvvvvvvvvvvvvvvv",
      "vaaaaaaaaaaaaaaa",
      "vaabbbbbbbbbbbbb",
      "vaabcd      c   ",
      "vaab            ",
      "vaab            ",
      "vaab            ",
      "vaab    fj      ",
      "vaab    k       ",
      "vaab            ",
      "vaab            ",
      "vaabc           ",
      "vaab            ",
      "vaab            ",
      "vaab            ",
      "vaab            "
    ],
    [
      "vvvvvvvvvvvvvvvv",
      "vaaaaaaaaaaaaaaa",
      "vaabbbbbbbbbbbbb",
      "vaabc       c   ",
      "vaab            ",
      "vaab            ",
      "vaab            ",
      "vaab    f       ",
      "vaab            ",
      "vaab            ",
      "vaab            ",
      "vaabc           ",
      "vaab            ",
      "vaab            ",
      "vaab            ",
      "vaab            "
    ],
    [
      "vvvvvvvvvvvvvvvv",
      "vaaaaaaaaaaaaaaa",
      "vaabbbbbbbbbbbbb",
      "vaabc       c   ",
      "vaab lmmmmmlmmmm",
      "vaab mlmmmlmmmmm",
      "vaab mmlmlmmmmmm",
      "vaab mmmfmmmnmmm",
      "vaab mmlmlmmmmmm",
      "vaab mlmmmlmmmmm",
      "vaab lmmmmmlmmmm",
      "vaabcmmmnmmmnmmm",
      "vaab mmmmmmmmlmm",
      "vaab mmmmmmmmmlm",
      "vaab mmmmmmmmmml",
      "vaab mmmnmmmnmmm"
    ],
    [
      "vvvvvvvvvvvvvvvv",
      "vaaaaaaaaaaaaaaa",
      "vaabbbbbbbbbbbbb",
      "vaabcooooooocooo",
      "vaabpfqqqqqfrqqq",
      "vaabpqfrrrfrrrrr",
      "vaabpqrfrfrrrrrr",
      "vaabpqrrfrrrsrrr",
      "vaabpqrfrfrrrrrr",
      "vaabpqfrrrfrrrrr",
      "vaabpfrrrrrfrrrr",
      "vaabcrrrsrrrfrrr",
      "vaabpqrrrrrrrfrr",
      "vaabpqrrrrrrrrfr",
      "vaabpqrrrrrrrrrf",
      "vaabpqrrsrrrsrrr"
    ]
  ]
}