{
  "name": "multi_residentialf_0_ground",
  "refpalette": "deceasedcraft:multi_residentialf_0/multi_residentialf_0_ground_palette",
  "xsize": 16,
  "zsize": 16,
  "slices": [
    [
      "aaaaaaaaaaaaaaaa",
      "abbbbbbbbbbbbbbb",
      "abbbbbbbbbbbbbbb",
      "abbbbbbbbbbbbbbb",
      "abccccccccccccbb",
      "ccccccccccccccbb",
      "cccccddddddcccbb",
      "cccccddddddcccbb",
      "cccccddddddcccbb",
      "cccccddddddcccbb",
      "ccccccccccccccbb",
      "abccccccccccccbb",
      "abbeffffffffebbb",
      "abbeffffffffebbb",
      "abbeffffffffebbb",
      "abbeffffffffebbb"
    ],
    [
      "                ",
      "               g",
      "               g",
      "               g",
      "  vvvvvvvvvvvv g",
      "h v         iv g",
      " jk         lv g",
      "  k         mv g",
      "  k    n    ov g",
      "j k         pv g",
      " hv!        qv g",
      " jvvvvvrsvvvvv g",
      "  gett   uuweg g",
      "  ge       xeg g",
      "  gey      Aeg g",
      "  geyB     Ceg g"
    ],
    [
      "                ",
      "                ",
      "                ",
      "                ",
      "  vvvvvvvvvvvv  ",
      "  v          v  ",
      "  k          v  ",
      "  k          v  ",
      "  k          v  ",
      "  k          v  ",
      "  v          v  ",
      "  vvvvvDEvvvvv  ",
      "   eF    IJ e   ",
      "   eK       e   ",
      "   eK      Le   ",
      "   eM N    Oe   "
    ],
    [
      "                ",
      "                ",
      "                ",
      "                ",
      "  vvPPPvvPPPvv  ",
      "  v         Qv  ",
      "  k        RSv  ",
      "  k        RTv  ",
      "  k          v  ",
      "  k          v  ",
      "  v          v  ",
      "  vvvvvvvvvvvv  ",
      "   eU  VV   e   ",
      "   PW       P   ",
      "   P        P   ",
      "   eX       e   "
    ],
    [
      "                ",
      "                ",
      "                ",
      "                ",
      "  vvvvvvvvvvvv  ",
      "  v          v  ",
      "  vY         v  ",
      "  vY         v  ",
      "  vY         v  ",
      "  vY         v  ",
      "  v          v  ",
      "  vvvvvvvvvvvv  ",
      "   e        e   ",
      "   e        e   ",
      "   e    Z   e   ",
      "   e        e   "
    ],
    [
      "                ",
      "                ",
      "                ",
      "                ",
      "  vvvvvvvvvvvv  ",
      "  v0000000000v  ",
      "  v0000000000v  ",
      "  v0000000000v  ",
      "  v0000000000v  ",
      "  v0000000000v  ",
      "  v0000000000v  ",
      "  vvvvvvvvvvvv  ",
      "  000000000000  ",
      "  000000000000  ",
      "  000000000000  ",
      "  000000000000  "
    ]
  ]
}