{
  "name": "building_warehouseadamaged_ground_180",
  "refpalette": "deceasedcraft:building_warehouseadamaged/building_warehouseadamaged_ground_palette_180",
  "xsize": 16,
  "zsize": 16,
  "slices": [
    [
      "zzzzzzzzzzzzzzzz",
      "zbeebbbebbbeazaa",
      "zbbbbbbbbbbbaaaz",
      "zbbbbbbbbbbbaaaa",
      "zebbbbbbbbbbaaaz",
      "zbebbbbbbbbeaazz",
      "zbbbbbbbbbgdaaaz",
      "zbccccHcccbHaaaz",
      "zbcddcccfdbeaazz",
      "zbddicccccbbaazz",
      "zbhcccccccgbaaaz",
      "zbccccfcccbbaaaz",
      "zbccccccccbeaaza",
      "zbcccdccccbbaaaa",
      "zbbbbbbbbbbbzaaa",
      "zzzzzzzzzzzzzzzz"
    ],
    [
      "    k      k   k",
      "k            K  ",
      "  nmnQPnmnn     ",
      "  mnO  OOnn N   ",
      "k  LM   ML j   k",
      "   LM    L    K ",
      "knmn!J  nnmFj   ",
      " mII   Dp DFHEjk",
      " jH dD D        ",
      " n xCuCttCuut   ",
      " dBxtAt  tAAt ok",
      " jrxtAt  tAAt  y",
      " ddxwuwttwuuts  ",
      " njr  qHnp  o   ",
      "knmnnmnmmnm j   ",
      " k  k l kjlk  j "
    ],
    [
      "                ",
      "                ",
      "  mnn$#nnnm     ",
      "  nn   MOmn     ",
      "   L     L      ",
      "   L     L      ",
      " mmnJ   nnn     ",
      " n9     8       ",
      " nr             ",
      " d7654W33UTSR   ",
      "   d2YYYYYY10   ",
      "    YYYYYYY10   ",
      " j ZYXWVVUTSR   ",
      " n      H       ",
      " nmmnLLmn       ",
      "                "
    ],
    [
      "                ",
      "                ",
      "  nnn{{nmmn     ",
      "  nm   ] nn     ",
      "   L     L      ",
      "   L     L      ",
      " nnm[[[[nnH     ",
      " n9             ",
      " j -            ",
      " n H+6^oooooo   ",
      " %  d )oooooo   ",
      "    (* oooooo   ",
      "    &&^oooooo   ",
      " %              ",
      " nnmnnHHD       ",
      "                "
    ],
    [
      "                ",
      " \u0372\u0372\u0372\u0372\u0372\u0372FFF\u0372\u0372    ",
      " \u0372nnnnn\u0371nnn\u0372    ",
      " \u0372nn]  \u0373 nn\u0372    ",
      " \u0372\u0372\u0370     \u0370\u0372\u0372    ",
      " \u0372\u0372\u0370     \u0370\u0372F    ",
      " mnnnnnnmn\u0371     ",
      " n9 {{{H \u0370H     ",
      " n `            ",
      " n /?6^oo ooo   ",
      " n   .,o>:oy    ",
      " %    <o' :     ",
      " n ;|&^oooooo   ",
      " n  }           ",
      " mnnHD          ",
      "                "
    ],
    [
      "                ",
      "                ",
      "  DDDDD DDD     ",
      "  DDDDDDDDD     ",
      "  DDDDDDDDD     ",
      "  DDDDDDDD      ",
      " nnnnn nnn      ",
      " n9\u0371\u0371\u0371\u0371         ",
      " n\u0371\u0371            ",
      " n  HH^oooo o   ",
      " n  \u0375\u0376^o:       ",
      " n  \u0375\u0374^oo       ",
      " n\u0371  H^o oooo   ",
      " n\u0371             ",
      " njE            ",
      "                "
    ]
  ]
}