{
  "name": "building_warehouseadamaged_ground",
  "refpalette": "deceasedcraft:building_warehouseadamaged/building_warehouseadamaged_ground_palette",
  "xsize": 16,
  "zsize": 16,
  "slices": [
    [
      "zzzzzzzzzzzzzzzz",
      "aaazbbbbbbbbbbbz",
      "aaaabbccccdcccbz",
      "azaaebccccccccbz",
      "zaaabbcccfccccbz",
      "zaaabgccccccchbz",
      "zzaabbccccciddbz",
      "zzaaebdfcccddcbz",
      "zaaaHbcccHccccbz",
      "zaaadgbbbbbbbbbz",
      "zzaaebbbbbbbbebz",
      "zaaabbbbbbbbbbez",
      "aaaabbbbbbbbbbbz",
      "zaaabbbbbbbbbbbz",
      "aazaebbbebbbeebz",
      "zzzzzzzzzzzzzzzz"
    ],
    [
      " j  kljk l k  k ",
      "   j mnmmnmnnmnk",
      "   o  pnHq  rjn ",
      "  stuuwttwuwxdd ",
      "y  tAAt  tAtxrj ",
      "ko tAAt  tAtxBd ",
      "   tuuCttCuCx n ",
      "        D Dd Hj ",
      "kjEHFD pD   IIm ",
      "   jFmnn  J!nmnk",
      " K    L    ML   ",
      "k   j LM   ML  k",
      "   N nnOO  Onm  ",
      "     nnmnPQnmn  ",
      "  K            k",
      "k   k      k    "
    ],
    [
      "                ",
      "       nmLLnmmn ",
      "       H      n ",
      "   RSTUVVWXYZ j ",
      "   01YYYYYYY    ",
      "   01YYYYYY2d   ",
      "   RSTU33W4567d ",
      "             rn ",
      "       8     9n ",
      "     nnn   Jnmm ",
      "      L     L   ",
      "      L     L   ",
      "     nmOM   nn  ",
      "     mnnn#$nnm  ",
      "                ",
      "                "
    ],
    [
      "                ",
      "       DHHnnmnn ",
      "              % ",
      "   oooooo^&&    ",
      "   oooooo *(    ",
      "   oooooo) d  % ",
      "   oooooo^6+H n ",
      "            - j ",
      "             9n ",
      "     Hnn[[[[mnn ",
      "      L     L   ",
      "      L     L   ",
      "     nn ]   mn  ",
      "     nmmn{{nnn  ",
      "                ",
      "                "
    ],
    [
      "                ",
      "          DHnnm ",
      "           }  n ",
      "   oooooo^&|; n ",
      "     : 'o<    % ",
      "    yo:>o,.   n ",
      "   ooo oo^6?/ n ",
      "            ` n ",
      "     H\u0370 H{{{ 9n ",
      "     \u0371nmnnnnnnm ",
      "    F\u0372\u0370     \u0370\u0372\u0372 ",
      "    \u0372\u0372\u0370     \u0370\u0372\u0372 ",
      "    \u0372nn \u0373  ]nn\u0372 ",
      "    \u0372nnn\u0371nnnnn\u0372 ",
      "    \u0372\u0372FFF\u0372\u0372\u0372\u0372\u0372\u0372 ",
      "                "
    ],
    [
      "                ",
      "            Ejn ",
      "             \u0371n ",
      "   oooo o^H  \u0371n ",
      "       oo^\u0374\u0375  n ",
      "       :o^\u0376\u0375  n ",
      "   o oooo^HH  n ",
      "            \u0371\u0371n ",
      "         \u0371\u0371\u0371\u03719n ",
      "      nnn nnnnn ",
      "      DDDDDDDD  ",
      "     DDDDDDDDD  ",
      "     DDDDDDDDD  ",
      "     DDD DDDDD  ",
      "                ",
      "                "
    ]
  ]
}