{
  "name": "building_warehouseadamaged_ground_90",
  "refpalette": "deceasedcraft:building_warehouseadamaged/building_warehouseadamaged_ground_palette_90",
  "xsize": 16,
  "zsize": 16,
  "slices": [
    [
      "zzzzzzzzzzzzzzzz",
      "zbbbbbbbbbbebbbz",
      "zbccchdccbebbbez",
      "zbccccddcbbbbbez",
      "zbccccidcbbbbbbz",
      "zbdccccccbbbbbbz",
      "zbccfcccHbbbbbbz",
      "zbcccccccbbbbbez",
      "zbcccccfcbbbbbbz",
      "zbcccccdcbbbbbbz",
      "zbbbbgbbbgbbbbbz",
      "zbbebbbeHdebbbez",
      "zzaaaaaaaaaaaaaz",
      "zaaaaaaaaaaaaazz",
      "zaazaazzaazaaaaz",
      "zaaazzzzzzzzazaz"
    ],
    [
      " k       k k  k ",
      "knndjdnjmn      ",
      " mjdrB HIm  mn  ",
      " nrxxxx InLLnm  ",
      "kn wttCd !MMOn k",
      " m uAAuD J   Q  ",
      "lnqwttC      P  ",
      " mHt  tDD   On  ",
      "kmnt  t pn MOm  ",
      "jnpwttC  nLLnn  ",
      "lm uAAu Dm  nn  ",
      "k  uAAu FF j   k",
      " jotttt Hj  N   ",
      "   s    E     K ",
      "j    o  j K     ",
      "    yk  k  k   k"
    ],
    [
      "                ",
      " nnj  dnnm      ",
      " m    7r9m  nm  ",
      " m Z d6  nLLnn  ",
      " n YY25  J   n  ",
      " L XYY4      $  ",
      " L WYYW      #  ",
      " m VYY3     Mn  ",
      " nHVYY3 8n  On  ",
      "   UYYU  nLLmn  ",
      "   TYYT  n  nm  ",
      "   S11S         ",
      "   R00R         ",
      "                ",
      "                ",
      "                "
    ],
    [
      "                ",
      " n%  %njnn      ",
      " n      9n  nn  ",
      " m    H- mLLmn  ",
      " n &(d+  [   n  ",
      " n &* 6  [   {  ",
      " H ^ )^  [   {  ",
      " H oooo  [  ]n  ",
      " D oooo  n   m  ",
      "   oooo  nLLnm  ",
      "   oooo  H  nn  ",
      "   oooo         ",
      "   oooo         ",
      "                ",
      "                ",
      "                "
    ],
    [
      "                ",
      " mnn%nnnnm\u0372\u0372\u0372\u0372\u0372 ",
      " n      9n\u0372\u0372nn\u0372 ",
      " n ;  /` n\u0370\u0370nn\u0372 ",
      " H}|  ? {n  ]n\u0372 ",
      " D & .6 {n   n\u0372 ",
      "   ^<,^ {n   n\u0372 ",
      "   oooo Hn  \u0373\u0371F ",
      "   o'>o  m   nF ",
      "   o :  \u0370n\u0370\u0370nnF ",
      "   o:oo H\u0371\u0372\u0372nn\u0372 ",
      "   o yo   F\u0372\u0372\u0372\u0372 ",
      "   o  o         ",
      "                ",
      "                ",
      "                "
    ],
    [
      "                ",
      " nnnnnnnnn      ",
      " j\u0371\u0371   \u03719nDDDD  ",
      " E     \u0371\u0371nDDDD  ",
      "    \u0375\u0375H \u0371nDDDD  ",
      "   H\u0374\u0376H \u0371nDDDD  ",
      "   ^^^^ \u0371 DDDD  ",
      "   oooo  nDDD   ",
      "    o:o  nDDDD  ",
      "   o  o  nDDDD  ",
      "   o  o    DDD  ",
      "   o            ",
      "   o  o         ",
      "                ",
      "                ",
      "                "
    ]
  ]
}