{
  "name": "building_warehouseadamaged_ground_270",
  "refpalette": "deceasedcraft:building_warehouseadamaged/building_warehouseadamaged_ground_palette_270",
  "xsize": 16,
  "zsize": 16,
  "slices": [
    [
      "zazazzzzzzzzaaaz",
      "zaaaazaazzaazaaz",
      "zzaaaaaaaaaaaaaz",
      "zaaaaaaaaaaaaazz",
      "zebbbedHebbbebbz",
      "zbbbbbgbbbgbbbbz",
      "zbbbbbbcdcccccbz",
      "zbbbbbbcfcccccbz",
      "zebbbbbcccccccbz",
      "zbbbbbbHcccfccbz",
      "zbbbbbbccccccdbz",
      "zbbbbbbcdiccccbz",
      "zebbbbbcddccccbz",
      "zebbbebccdhcccbz",
      "zbbbebbbbbbbbbbz",
      "zzzzzzzzzzzzzzzz"
    ],
    [
      "k   k  k  ky    ",
      "     K j  o    j",
      " K     E    s   ",
      "   N  jH ttttoj ",
      "k   j FF uAAu  k",
      "  nn  mD uAAu ml",
      "  nnLLn  Cttwpnj",
      "  mOM np t  tnmk",
      "  nO   DDt  tHm ",
      "  P      Cttwqnl",
      "  Q   J DuAAu m ",
      "k nOMM! dCttw nk",
      "  mnLLnI xxxxrn ",
      "  nm  mIH Brdjm ",
      "      nmjndjdnnk",
      " k  k k       k "
    ],
    [
      "                ",
      "                ",
      "                ",
      "         R00R   ",
      "         S11S   ",
      "  mn  n  TYYT   ",
      "  nmLLn  UYYU   ",
      "  nO  n8 3YYVHn ",
      "  nM     3YYV m ",
      "  #      WYYW L ",
      "  $      4YYX L ",
      "  n   J  52YY n ",
      "  nnLLn  6d Z m ",
      "  mn  m9r7    m ",
      "      mnnd  jnn ",
      "                "
    ],
    [
      "                ",
      "                ",
      "                ",
      "         oooo   ",
      "         oooo   ",
      "  nn  H  oooo   ",
      "  mnLLn  oooo   ",
      "  m   n  oooo D ",
      "  n]  [  oooo H ",
      "  {   [  ^) ^ H ",
      "  {   [  6 *& n ",
      "  n   [  +d(& n ",
      "  nmLLm -H    m ",
      "  nn  n9      n ",
      "      nnjn%  %n ",
      "                "
    ],
    [
      "                ",
      "                ",
      "                ",
      "         o  o   ",
      " \u0372\u0372\u0372\u0372F   oy o   ",
      " \u0372nn\u0372\u0372\u0371H oo:o   ",
      " Fnn\u0370\u0370n\u0370  : o   ",
      " Fn   m  o>'o   ",
      " F\u0371\u0373  nH oooo   ",
      " \u0372n   n{ ^,<^   ",
      " \u0372n   n{ 6. & D ",
      " \u0372n]  n{ ?  |}H ",
      " \u0372nn\u0370\u0370n `/  ; n ",
      " \u0372nn\u0372\u0372n9      n ",
      " \u0372\u0372\u0372\u0372\u0372mnnnn%nnm ",
      "                "
    ],
    [
      "                ",
      "                ",
      "                ",
      "         o  o   ",
      "            o   ",
      "  DDD    o  o   ",
      "  DDDDn  o  o   ",
      "  DDDDn  o:o    ",
      "   DDDn  oooo   ",
      "  DDDD \u0371 ^^^^   ",
      "  DDDDn\u0371 H\u0376\u0374H   ",
      "  DDDDn\u0371 H\u0375\u0375    ",
      "  DDDDn\u0371\u0371     E ",
      "  DDDDn9\u0371   \u0371\u0371j ",
      "      nnnnnnnnn ",
      "                "
    ]
  ]
}