{
  "name": "building_office3a_ground_90",
  "refpalette": "deceasedcraft:building_office3a/building_office3a_ground_palette_90",
  "xsize": 16,
  "zsize": 16,
  "slices": [
    [
      "aaaaaaaaaaaaaaaa",
      "aaaaaaaaaaaaaaaa",
      "aaaccccccccccaaa",
      "aaddddddddddddaa",
      "aaddddddddddddaa",
      "aaddddddddddddaa",
      "aaddddddddddddaa",
      "aaddddddddddddaa",
      "aaddddddddddddaa",
      "aaddddddddddddaa",
      "aaddddddddddddaa",
      "aaccccccccccccaa",
      "aabeeeeeeeebbbaa",
      "aaaaaaaaaaaaaaaa",
      "aaaaaaaaaaaaaaaa",
      "aaaaaaaaaaaaaaaa"
    ],
    [
      "                ",
      " f ruC    Sru Z ",
      " flqttILLIttqlZ ",
      " fk    KQ    YZ ",
      " f           XZ ",
      " fk  BFFP  VWiZ ",
      " f   AEEO  U UZ ",
      " fj  yEEN  U UZ ",
      " fj  xDDM  U UZ ",
      " fjp       U UZ ",
      " fioswoJw  U UZ ",
      " fhhhhhhhhhhhhZ ",
      " f nnnn!nnbT  Z ",
      " fgmmmmmmmRR gZ ",
      " f            Z ",
      "                "
    ],
    [
      "                ",
      " f   m    m   Z ",
      " flqttI  IttqlZ ",
      " f     45     Z ",
      " f            Z ",
      " f           iZ ",
      " f   2322  7 9Z ",
      " f   1111  6 9Z ",
      " f0          8Z ",
      " f           9Z ",
      " f!JwJwJo    8Z ",
      " fhhhhhhhhhhhhZ ",
      " f nn n nbT   Z ",
      " fg      RRR gZ ",
      " f            Z ",
      "                "
    ],
    [
      "                ",
      " f   #    #   Z ",
      " flqttI%%IttqlZ ",
      " f     $$    ^Z ",
      " f           ^Z ",
      " f           iZ ",
      " f           9Z ",
      " f           8Z ",
      " f           8Z ",
      " f           9Z ",
      " fp          9Z ",
      " fhhhhhhhhhhhhZ ",
      " f      bT    Z ",
      " fg     RRRR gZ ",
      " f            Z ",
      "                "
    ],
    [
      "                ",
      " f            Z ",
      " flqttIIIIttqlZ ",
      " f           *Z ",
      " f            Z ",
      " f           *Z ",
      " f            Z ",
      " f            Z ",
      " f           *Z ",
      " f           *Z ",
      " f            Z ",
      " fhhhhhhhhhhhhZ ",
      " f&    bT     Z ",
      " fg    RRRRR gZ ",
      " f            Z ",
      "                "
    ],
    [
      "                ",
      " f            Z ",
      " flqttqttqttqlZ ",
      " f-          {Z ",
      " f+          ]Z ",
      " f+          ]Z ",
      " f+          ]Z ",
      " f+          ]Z ",
      " f+          ]Z ",
      " f+          ]Z ",
      " f)          [Z ",
      " fhhhhhhhhhhhhZ ",
      " f(   bT     &Z ",
      " fg   RRRRRR gZ ",
      " f            Z ",
      "                "
    ]
  ]
}