{
  "name": "building_office3a_floor1_270",
  "refpalette": "deceasedcraft:building_office3a/building_office3a_floor1_palette_270",
  "xsize": 16,
  "zsize": 16,
  "slices": [
    [
      "                ",
      " n            a ",
      " nb iiiiiii  ba ",
      " nc      kj  ca ",
      " ndddddddddddda ",
      " nl          ea ",
      " n           ea ",
      " nl           a ",
      " nl          ea ",
      " nm          ea ",
      " n            a ",
      " n            a ",
      " nl          ea ",
      " nfghhghhghhgfa ",
      " n            a ",
      "                "
    ],
    [
      "                ",
      " n            a ",
      " nb iiiiiiii ba ",
      " nc       kj ca ",
      " ndddddddddddda ",
      " n            a ",
      " n            a ",
      " n            a ",
      " n            a ",
      " n            a ",
      " n            a ",
      " n            a ",
      " n            a ",
      " nfghhghhghhgfa ",
      " n            a ",
      "                "
    ],
    [
      "                ",
      " n            a ",
      " nb iiiiiiiiiba ",
      " nt        kjoa ",
      " ndddddddddddda ",
      " nppppppppppppa ",
      " npqqqqqqqqqqpa ",
      " npqqqqqqqqqqpa ",
      " npqqsqqqqrqqpa ",
      " npqqsqqqqsqqpa ",
      " npqqqqqqqqqqpa ",
      " npqqqqqqqqqqpa ",
      " np          pa ",
      " nfghhghhghhgfa ",
      " n            a ",
      "                "
    ],
    [
      "                ",
      " n            a ",
      " nbuuuuuuuuuuba ",
      " ny         kja ",
      " njjjjjjjjjjjja ",
      " njwwwwwwwwwwja ",
      " njwwwwwwwwwwja ",
      " njwwwwwwwwwwja ",
      " njwwwwwwwwwwja ",
      " njwwwwwwwwwwja ",
      " njwwwwwwwwwwja ",
      " njwwwwwwwwwwja ",
      " njxxxxxxxxxxja ",
      " nfghhghhghhgfa ",
      " n            a ",
      "                "
    ],
    [
      "                ",
      " n            a ",
      " nbghhghhghhgba ",
      " n u  u  u    a ",
      " nBBBBBBBBBBB a ",
      " n i          a ",
      " n iPN    JFC a ",
      " n iQ L       a ",
      " n i  L   DDD a ",
      " n i  L       a ",
      " n i OL   KIE a ",
      " n    L       a ",
      " nR   M      Aa ",
      " nfghhghhghhgfa ",
      " n            a ",
      "                "
    ],
    [
      "                ",
      " n            a ",
      " nbghhghhghhgba ",
      " n            a ",
      " n            a ",
      " n i          a ",
      " n i          a ",
      " n iPN        a ",
      " n iQ         a ",
      " n i          a ",
      " n i          a ",
      " n            a ",
      " nS          Sa ",
      " nfghhghhghhgfa ",
      " n            a ",
      "                "
    ]
  ]
}