{
  "name": "building_office3a_floor1",
  "refpalette": "deceasedcraft:building_office3a/building_office3a_floor1_palette",
  "xsize": 16,
  "zsize": 16,
  "slices": [
    [
      "                ",
      " aaaaaaaaaaaaaa ",
      "  bcdee ee  ef  ",
      "    d        g  ",
      "    d        h  ",
      "  ijd        h  ",
      "  ikd        g  ",
      "  i d        h  ",
      "  i d        h  ",
      "  i d        g  ",
      "  i d        h  ",
      "  i d        h  ",
      "    d        g  ",
      "  bcdl llm  lf  ",
      " nnnnnnnnnnnnnn ",
      "                "
    ],
    [
      "                ",
      " aaaaaaaaaaaaaa ",
      "  bcd        f  ",
      "    d        g  ",
      "  ijd        h  ",
      "  ikd        h  ",
      "  i d        g  ",
      "  i d        h  ",
      "  i d        h  ",
      "  i d        g  ",
      "  i d        h  ",
      "  i d        h  ",
      "    d        g  ",
      "  bcd        f  ",
      " nnnnnnnnnnnnnn ",
      "                "
    ],
    [
      "                ",
      " aaaaaaaaaaaaaa ",
      "  bodppppppppf  ",
      "  ijdpqqqqqq g  ",
      "  ikdpqqqqqq h  ",
      "  i dpqqrsqq h  ",
      "  i dpqqqqqq g  ",
      "  i dpqqqqqq h  ",
      "  i dpqqqqqq h  ",
      "  i dpqqqqqq g  ",
      "  i dpqqssqq h  ",
      "  i dpqqqqqq h  ",
      "    dpqqqqqq g  ",
      "  btdppppppppf  ",
      " nnnnnnnnnnnnnn ",
      "                "
    ],
    [
      "                ",
      " aaaaaaaaaaaaaa ",
      "  bjjjjjjjjjjf  ",
      "  ukjwwwwwwwxg  ",
      "  u jwwwwwwwxh  ",
      "  u jwwwwwwwxh  ",
      "  u jwwwwwwwxg  ",
      "  u jwwwwwwwxh  ",
      "  u jwwwwwwwxh  ",
      "  u jwwwwwwwxg  ",
      "  u jwwwwwwwxh  ",
      "  u jwwwwwwwxh  ",
      "  u jwwwwwwwxg  ",
      "  byjjjjjjjjjf  ",
      " nnnnnnnnnnnnnn ",
      "                "
    ],
    [
      "                ",
      " aaaaaaaaaaaaaa ",
      "  b         Af  ",
      "  g B C D E  g  ",
      "  h B F D I  h  ",
      "  h B J D K  h  ",
      "  guB        g  ",
      "  h B        h  ",
      "  h B        h  ",
      "  guB  LLLLLMg  ",
      "  h B N   O  h  ",
      "  h B PQ     h  ",
      "  guBiiiiii  g  ",
      "  b B       Rf  ",
      " nnnnnnnnnnnnnn ",
      "                "
    ],
    [
      "                ",
      " aaaaaaaaaaaaaa ",
      "  b         Sf  ",
      "  g          g  ",
      "  h          h  ",
      "  h          h  ",
      "  g          g  ",
      "  h          h  ",
      "  h          h  ",
      "  g          g  ",
      "  h    N     h  ",
      "  h    PQ    h  ",
      "  g  iiiiii  g  ",
      "  b         Sf  ",
      " nnnnnnnnnnnnnn ",
      "                "
    ]
  ]
}