{
  "name": "building_office3a_floor3_270",
  "refpalette": "deceasedcraft:building_office3a/building_office3a_floor3_palette_270",
  "xsize": 16,
  "zsize": 16,
  "slices": [
    [
      "                ",
      " m            a ",
      " mbeiieiieiieba ",
      " mcffffffffffca ",
      " mkgjjjjjjjjgca ",
      " mlgjjjjjjjjgca ",
      " m gjjjjjjjjgca ",
      " m gjjjjjjjjgca ",
      " m gjjjjjjjjgca ",
      " m gjjjjjjjjgca ",
      " mcgjjjjjjjjgca ",
      " mcgjjjjjjjjgca ",
      " mchhhhhhhhhhca ",
      " mdeiieiieiieda ",
      " m            a ",
      "                "
    ],
    [
      "                ",
      " m            a ",
      " mbeiieiieiieba ",
      " m           na ",
      " m     y  y  oa ",
      " m L  JA FA  oa ",
      " m L   A  A  oa ",
      " m L   A wAw oa ",
      " m L  BBBBB  pa ",
      " mkL  KA  Cxuqa ",
      " mlL  KA  Dx ra ",
      " m     I  Cx sa ",
      " m        Ex ta ",
      " mdeiieiieiieda ",
      " m            a ",
      "                "
    ],
    [
      "                ",
      " m            a ",
      " mbeiieiieiieba ",
      " m           Ma ",
      " m           Na ",
      " m L   R  R  Oa ",
      " m L   Y  S   a ",
      " m L   T  T  Pa ",
      " mkL  UU!UU  Na ",
      " mlL   Z  VxQqa ",
      " m L   0   x  a ",
      " m        Wx  a ",
      " m        Xx  a ",
      " mdeiieiieiieda ",
      " m            a ",
      "                "
    ],
    [
      "                ",
      " m            a ",
      " mbeiieiieiieba ",
      " m            a ",
      " m            a ",
      " m L          a ",
      " m L          a ",
      " mkL          a ",
      " mlL  UUUUU   a ",
      " m L      4xqqa ",
      " m L      5x 1a ",
      " m        4x 2a ",
      " m        5x 3a ",
      " mdeiieiieiieda ",
      " m            a ",
      "                "
    ],
    [
      "                ",
      " m            a ",
      " mbeiieiieiieba ",
      " m            a ",
      " m            a ",
      " m L          a ",
      " mkL          a ",
      " mlL          a ",
      " m L          a ",
      " m L      8xqqa ",
      " m L       x  a ",
      " m        9x 6a ",
      " m        #x 7a ",
      " mdeiieiieiieda ",
      " m            a ",
      "                "
    ],
    [
      "                ",
      " m            a ",
      " mbeiieiieiieba ",
      " m            a ",
      " m            a ",
      " mkL          a ",
      " mlL          a ",
      " m L          a ",
      " m L          a ",
      " m L       xqqa ",
      " m L       x  a ",
      " m         x  a ",
      " m         x  a ",
      " mdeiieiieiieda ",
      " m            a ",
      "                "
    ]
  ]
}