{
  "name": "building_office3a_floor2_180",
  "refpalette": "deceasedcraft:building_office3a/building_office3a_floor2_palette_180",
  "xsize": 16,
  "zsize": 16,
  "slices": [
    [
      "                ",
      " llllllllllllll ",
      "  ed         b  ",
      "  f  kkkkkk  f  ",
      "  g   ji     g  ",
      "  g    h     g  ",
      "  f          f  ",
      "  g          g  ",
      "  g          g  ",
      "  f          f  ",
      "  g          g  ",
      "  g          g  ",
      "  f          f  ",
      "  ed   c     b  ",
      " aaaaaaaaaaaaaa ",
      "                "
    ],
    [
      "                ",
      " llllllllllllll ",
      "  e  no      b  ",
      "  f  nkkkkk  f  ",
      "  g  ji      g  ",
      "  g   h      g  ",
      "  f          f  ",
      "  g          g  ",
      "  g          g  ",
      "  f          f  ",
      "  g          g  ",
      "  g          g  ",
      "  f          f  ",
      "  e    m     b  ",
      " aaaaaaaaaaaaaa ",
      "                "
    ],
    [
      "                ",
      " llllllllllllll ",
      "  e  rso     b  ",
      "  f  rkkkkk  f  ",
      "  g  r       g  ",
      "  g  h       g  ",
      "  f          f  ",
      "  g          g  ",
      "  g     q    g  ",
      "  f          f  ",
      "  g          g  ",
      "  g          g  ",
      "  f          f  ",
      "  e    p     b  ",
      " aaaaaaaaaaaaaa ",
      "                "
    ],
    [
      "                ",
      " llllllllllllll ",
      "  e    so    b  ",
      "  f   kkkkk  f  ",
      "  g          g  ",
      "  g          g  ",
      "  f          f  ",
      "  g    q     g  ",
      "  g     q    g  ",
      "  f          f  ",
      "  g          g  ",
      "  g          g  ",
      "  f          f  ",
      "  e          b  ",
      " aaaaaaaaaaaaaa ",
      "                "
    ],
    [
      "                ",
      " llllllllllllll ",
      "  e     so   b  ",
      "  f   kkkkk  f  ",
      "  g          g  ",
      "  g          g  ",
      "  f          f  ",
      "  g    qq    g  ",
      "  g    qq    g  ",
      "  f          f  ",
      "  g          g  ",
      "  g          g  ",
      "  f          f  ",
      "  e          b  ",
      " aaaaaaaaaaaaaa ",
      "                "
    ],
    [
      "                ",
      " llllllllllllll ",
      "  e      so  b  ",
      "  f   kkkkk  f  ",
      "  g          g  ",
      "  g          g  ",
      "  f    tt    f  ",
      "  g   tuut   g  ",
      "  g   tuut   g  ",
      "  f    tt    f  ",
      "  g          g  ",
      "  g          g  ",
      "  f          f  ",
      "  e          b  ",
      " aaaaaaaaaaaaaa ",
      "                "
    ]
  ]
}