{
  "name": "building_office3a_floor4_270",
  "refpalette": "deceasedcraft:building_office3a/building_office3a_floor4_palette_270",
  "xsize": 16,
  "zsize": 16,
  "slices": [
    [
      "                ",
      " m            a ",
      " mbeiieiieiieba ",
      " mcffffffffffca ",
      " mkgjjjjjjjjgca ",
      " mlgjjjjjjjjgca ",
      " m gjjjjjjjjgca ",
      " m gjjjjjjjjgca ",
      " m gjjjjjjjjgca ",
      " m gjjjjjjjjgca ",
      " mcgjjjjjjjjgca ",
      " mcgjjjjjjjjgca ",
      " mchhhhhhhhhhca ",
      " mdeiieiieiieda ",
      " m            a ",
      "                "
    ],
    [
      "                ",
      " m            a ",
      " mbeiieiieiieba ",
      " m          una ",
      " m     B  B  oa ",
      " m N  JC JC  oa ",
      " m N   C  C  oa ",
      " m N   CK Cy oa ",
      " m N  DDDDD  pa ",
      " mkN  MC  EAwqa ",
      " mlN  MC  FA ra ",
      " m     L  EAxsa ",
      " m        IA ta ",
      " mdeiieiieiieda ",
      " m            a ",
      "                "
    ],
    [
      "                ",
      " m            a ",
      " mbeiieiieiieba ",
      " m           Oa ",
      " m           Pa ",
      " m N   U  U  Qa ",
      " m N   Z     Ra ",
      " m N   V  V  Sa ",
      " mkN  WWWWW  ua ",
      " mlN      XATqa ",
      " m N       A  a ",
      " m         A  a ",
      " m        YA  a ",
      " mdeiieiieiieda ",
      " m            a ",
      "                "
    ],
    [
      "                ",
      " m            a ",
      " mbeiieiieiieba ",
      " m            a ",
      " m            a ",
      " m N          a ",
      " m N          a ",
      " mkN          a ",
      " mlN  WWWWW   a ",
      " m N      3Aqqa ",
      " m N      4A 0a ",
      " m        3A 1a ",
      " m        4A 2a ",
      " mdeiieiieiieda ",
      " m            a ",
      "                "
    ],
    [
      "                ",
      " m            a ",
      " mbeiieiieiieba ",
      " m            a ",
      " m            a ",
      " m N          a ",
      " mkN          a ",
      " mlN          a ",
      " m N          a ",
      " m N       Aqqa ",
      " m N      6A  a ",
      " m        7A 5a ",
      " m        8A !a ",
      " mdeiieiieiieda ",
      " m            a ",
      "                "
    ],
    [
      "                ",
      " m            a ",
      " mbeiieiieiieba ",
      " m            a ",
      " m            a ",
      " mkN          a ",
      " mlN          a ",
      " m N          a ",
      " m N          a ",
      " m N       Aqqa ",
      " m N       A  a ",
      " m         A  a ",
      " m         A  a ",
      " mdeiieiieiieda ",
      " m            a ",
      "                "
    ]
  ]
}