{
  "name": "building_office3a_floor3_90",
  "refpalette": "deceasedcraft:building_office3a/building_office3a_floor3_palette_90",
  "xsize": 16,
  "zsize": 16,
  "slices": [
    [
      "                ",
      " a            m ",
      " adeiieiieiiedm ",
      " achhhhhhhhhhcm ",
      " acgjjjjjjjjgcm ",
      " acgjjjjjjjjgcm ",
      " acgjjjjjjjjg m ",
      " acgjjjjjjjjg m ",
      " acgjjjjjjjjg m ",
      " acgjjjjjjjjg m ",
      " acgjjjjjjjjglm ",
      " acgjjjjjjjjgkm ",
      " acffffffffffcm ",
      " abeiieiieiiebm ",
      " a            m ",
      "                "
    ],
    [
      "                ",
      " a            m ",
      " adeiieiieiiedm ",
      " at xE        m ",
      " as xC  I     m ",
      " ar xD  AK  Llm ",
      " aquxC  AK  Lkm ",
      " ap  BBBBB  L m ",
      " ao wAw A   L m ",
      " ao  A  A   L m ",
      " ao  AF AJ  L m ",
      " ao  y  y     m ",
      " an           m ",
      " abeiieiieiiebm ",
      " a            m ",
      "                "
    ],
    [
      "                ",
      " a            m ",
      " adeiieiieiiedm ",
      " a  xX        m ",
      " a  xW        m ",
      " a  x   0   L m ",
      " aqQxV  Z   Llm ",
      " aN  UU!UU  Lkm ",
      " aP  T  T   L m ",
      " a   S  Y   L m ",
      " aO  R  R   L m ",
      " aN           m ",
      " aM           m ",
      " abeiieiieiiebm ",
      " a            m ",
      "                "
    ],
    [
      "                ",
      " a            m ",
      " adeiieiieiiedm ",
      " a3 x5        m ",
      " a2 x4        m ",
      " a1 x5      L m ",
      " aqqx4      L m ",
      " a   UUUUU  Llm ",
      " a          Lkm ",
      " a          L m ",
      " a          L m ",
      " a            m ",
      " a            m ",
      " abeiieiieiiebm ",
      " a            m ",
      "                "
    ],
    [
      "                ",
      " a            m ",
      " adeiieiieiiedm ",
      " a7 x#        m ",
      " a6 x9        m ",
      " a  x       L m ",
      " aqqx8      L m ",
      " a          L m ",
      " a          Llm ",
      " a          Lkm ",
      " a          L m ",
      " a            m ",
      " a            m ",
      " abeiieiieiiebm ",
      " a            m ",
      "                "
    ],
    [
      "                ",
      " a            m ",
      " adeiieiieiiedm ",
      " a  x         m ",
      " a  x         m ",
      " a  x       L m ",
      " aqqx       L m ",
      " a          L m ",
      " a          L m ",
      " a          Llm ",
      " a          Lkm ",
      " a            m ",
      " a            m ",
      " abeiieiieiiebm ",
      " a            m ",
      "                "
    ]
  ]
}