{
  "name": "building_office3a_floor3",
  "refpalette": "deceasedcraft:building_office3a/building_office3a_floor3_palette",
  "xsize": 16,
  "zsize": 16,
  "slices": [
    [
      "                ",
      " aaaaaaaaaaaaaa ",
      "  bccccccccccd  ",
      "  efgggggggghe  ",
      "  ifjjjjjjjjhi  ",
      "  ifjjjjjjjjhi  ",
      "  efjjjjjjjjhe  ",
      "  ifjjjjjjjjhi  ",
      "  ifjjjjjjjjhi  ",
      "  efjjjjjjjjhe  ",
      "  ifjjjjjjjjhi  ",
      "  ifjjjjjjjjhi  ",
      "  efgggggggghe  ",
      "  bckl    cccd  ",
      " mmmmmmmmmmmmmm ",
      "                "
    ],
    [
      "                ",
      " aaaaaaaaaaaaaa ",
      "  bnoooopqrstd  ",
      "  e      u   e  ",
      "  i    w xxxxi  ",
      "  i yAAABCDCEi  ",
      "  e  F wB    e  ",
      "  i     B    i  ",
      "  i yAAABAAI i  ",
      "  e  J  BKK  e  ",
      "  i          i  ",
      "  i          i  ",
      "  e  LLLLLL  e  ",
      "  b      kl  d  ",
      " mmmmmmmmmmmmmm ",
      "                "
    ],
    [
      "                ",
      " aaaaaaaaaaaaaa ",
      "  bMNO PNq   d  ",
      "  e      Q   e  ",
      "  i      xxxxi  ",
      "  i  RSTUV WXi  ",
      "  e     U    e  ",
      "  i     !    i  ",
      "  i  RYTUZ0  i  ",
      "  e     U    e  ",
      "  i          i  ",
      "  i          i  ",
      "  e  LLLLLL  e  ",
      "  b     kl   d  ",
      " mmmmmmmmmmmmmm ",
      "                "
    ],
    [
      "                ",
      " aaaaaaaaaaaaaa ",
      "  b      q123d  ",
      "  e      q   e  ",
      "  i      xxxxi  ",
      "  i     U4545i  ",
      "  e     U    e  ",
      "  i     U    i  ",
      "  i     U    i  ",
      "  e     U    e  ",
      "  i          i  ",
      "  i          i  ",
      "  e  LLLLLL  e  ",
      "  b    kl    d  ",
      " mmmmmmmmmmmmmm ",
      "                "
    ],
    [
      "                ",
      " aaaaaaaaaaaaaa ",
      "  b      q 67d  ",
      "  e      q   e  ",
      "  i      xxxxi  ",
      "  i      8 9#i  ",
      "  e          e  ",
      "  i          i  ",
      "  i          i  ",
      "  e          e  ",
      "  i          i  ",
      "  i          i  ",
      "  e  LLLLLL  e  ",
      "  b   kl     d  ",
      " mmmmmmmmmmmmmm ",
      "                "
    ],
    [
      "                ",
      " aaaaaaaaaaaaaa ",
      "  b      q   d  ",
      "  e      q   e  ",
      "  i      xxxxi  ",
      "  i          i  ",
      "  e          e  ",
      "  i          i  ",
      "  i          i  ",
      "  e          e  ",
      "  i          i  ",
      "  i          i  ",
      "  e  LLLLLL  e  ",
      "  b  kl      d  ",
      " mmmmmmmmmmmmmm ",
      "                "
    ]
  ]
}