{
  "name": "building_office3a_top",
  "refpalette": "deceasedcraft:building_office3a/building_office3a_top_palette",
  "xsize": 16,
  "zsize": 16,
  "slices": [
    [
      "                ",
      " aaaaaaaaaaaaaa ",
      "  bcddddddddef  ",
      "  gcddddddddeg  ",
      "  hciiiiiiiieh  ",
      "  hciiiiiiiieh  ",
      "  gciiiiiiiieg  ",
      "  hciiiiiiiieh  ",
      "  hciiiiiiiieh  ",
      "  gciiiiiiiieg  ",
      "  hciiiiiiiieh  ",
      "  hciiiiiiiieh  ",
      "  gcddddddddeg  ",
      "  bjkl    jkmf  ",
      " nnnnnnnnnnnnnn ",
      "                "
    ],
    [
      "                ",
      " aaaaaaaaaaaaaa ",
      "  bopopopopopf  ",
      "  g          g  ",
      "  h    q     h  ",
      "  h  rssssr  h  ",
      "  g  tttttt  g  ",
      "  h          h  ",
      "  h   uuuu   h  ",
      "  g  wuxxuy  g  ",
      "  h   uuuu   h  ",
      "  h   ABBC   h  ",
      "  g  DDDDDD  g  ",
      "  b       EFFf  ",
      " nnnnnnnnnnnnnn ",
      "                "
    ],
    [
      "                ",
      " aaaaaaaaaaaaaa ",
      "  bIIIIIIIIIIf  ",
      "  g          g  ",
      "  h          h  ",
      "  h   JKLMN  h  ",
      "  g          g  ",
      "  h          h  ",
      "  h          h  ",
      "  g          g  ",
      "  h          h  ",
      "  h          h  ",
      "  g  DDDDDD  g  ",
      "  b        O f  ",
      " nnnnnnnnnnnnnn ",
      "                "
    ],
    [
      "                ",
      " aaaaaaaaaaaaaa ",
      "  bIIIIIIIIIIf  ",
      "  g          g  ",
      "  h          h  ",
      "  h          h  ",
      "  g          g  ",
      "  h          h  ",
      "  h          h  ",
      "  g          g  ",
      "  h          h  ",
      "  h          h  ",
      "  g  DDDDDD  g  ",
      "  b          f  ",
      " nnnnnnnnnnnnnn ",
      "                "
    ],
    [
      "                ",
      " aaaaaaaaaaaaaa ",
      "  bPQ RS T U f  ",
      "  g          g  ",
      "  h          h  ",
      "  h          h  ",
      "  g          g  ",
      "  h          h  ",
      "  h          h  ",
      "  g          g  ",
      "  h          h  ",
      "  h          h  ",
      "  g  DDDDDD  g  ",
      "  b          f  ",
      " nnnnnnnnnnnnnn ",
      "                "
    ],
    [
      "                ",
      " aaaaaaaaaaaaaa ",
      "  bV   WX   Yf  ",
      "  g          g  ",
      "  h          h  ",
      "  h          h  ",
      "  g          g  ",
      "  h          h  ",
      "  h          h  ",
      "  g          g  ",
      "  h          h  ",
      "  h          h  ",
      "  g  DDDDDD  g  ",
      "  bV        Yf  ",
      " nnnnnnnnnnnnnn ",
      "                "
    ],
    [
      "                ",
      " aaaaaaaaaaaaaa ",
      "   ZV000000Y1   ",
      "  gg        gg  ",
      "  hh        hh  ",
      "  hh        hh  ",
      "  gg        gg  ",
      "  hh        hh  ",
      "  hh        hh  ",
      "  gg        gg  ",
      "  hh        hh  ",
      "  hh        hh  ",
      "  gg DDDDDD gg  ",
      "   ZV000000Y1   ",
      " nnnnnnnnnnnnnn ",
      "                "
    ],
    [
      "                ",
      " aaaaaaaaaaaaaa ",
      "    22222222    ",
      "   gggggggggg   ",
      "   3hhhhhhhh3   ",
      "   3hhhhhhhh3   ",
      "   gggggggggg   ",
      "   3hhhhhhhh3   ",
      "   3hhhhhhhh3   ",
      "   gggggggggg   ",
      "   3hhhhhhhh3   ",
      "   3hhhhhhhh3   ",
      "   gggggggggg   ",
      "    22222222    ",
      " nnnnnnnnnnnnnn ",
      "                "
    ],
    [
      "                ",
      " aaaaaaaaaaaaaa ",
      "                ",
      "                ",
      "                ",
      "                ",
      "                ",
      "                ",
      "                ",
      "                ",
      "                ",
      "                ",
      "                ",
      "                ",
      " nnnnnnnnnnnnnn ",
      "                "
    ]
  ]
}