{
  "name": "building_office3a_top_270",
  "refpalette": "deceasedcraft:building_office3a/building_office3a_top_palette_270",
  "xsize": 16,
  "zsize": 16,
  "slices": [
    [
      "                ",
      " n            a ",
      " nbghhghhghhgba ",
      " njccccccccccca ",
      " nkdiiiiiiiidda ",
      " nldiiiiiiiidda ",
      " n diiiiiiiidda ",
      " n diiiiiiiidda ",
      " n diiiiiiiidda ",
      " n diiiiiiiidda ",
      " njdiiiiiiiidda ",
      " nkdiiiiiiiidda ",
      " nmeeeeeeeeeeea ",
      " nfghhghhghhgfa ",
      " n            a ",
      "                "
    ],
    [
      "                ",
      " n            a ",
      " nbghhghhghhgba ",
      " n           oa ",
      " n           pa ",
      " n D  w  tr  oa ",
      " n DAuuu ts  pa ",
      " n DBuxu tsq oa ",
      " n DBuxu ts  pa ",
      " n DCuuu ts  oa ",
      " nED  y  tr  pa ",
      " nF          oa ",
      " nF          pa ",
      " nfghhghhghhgfa ",
      " n            a ",
      "                "
    ],
    [
      "                ",
      " n            a ",
      " nbghhghhghhgba ",
      " n           Ia ",
      " n           Ia ",
      " n D         Ia ",
      " n D      J  Ia ",
      " n D      K  Ia ",
      " n D      L  Ia ",
      " n D      M  Ia ",
      " n D      N  Ia ",
      " nO          Ia ",
      " n           Ia ",
      " nfghhghhghhgfa ",
      " n            a ",
      "                "
    ],
    [
      "                ",
      " n            a ",
      " nbghhghhghhgba ",
      " n           Ia ",
      " n           Ia ",
      " n D         Ia ",
      " n D         Ia ",
      " n D         Ia ",
      " n D         Ia ",
      " n D         Ia ",
      " n D         Ia ",
      " n           Ia ",
      " n           Ia ",
      " nfghhghhghhgfa ",
      " n            a ",
      "                "
    ],
    [
      "                ",
      " n            a ",
      " nbghhghhghhgba ",
      " n           Pa ",
      " n           Qa ",
      " n D          a ",
      " n D         Ra ",
      " n D         Sa ",
      " n D          a ",
      " n D         Ta ",
      " n D          a ",
      " n           Ua ",
      " n            a ",
      " nfghhghhghhgfa ",
      " n            a ",
      "                "
    ],
    [
      "                ",
      " n            a ",
      " nbghhghhghhgba ",
      " nV          Va ",
      " n            a ",
      " n D          a ",
      " n D          a ",
      " n D         Wa ",
      " n D         Xa ",
      " n D          a ",
      " n D          a ",
      " n            a ",
      " nY          Ya ",
      " nfghhghhghhgfa ",
      " n            a ",
      "                "
    ],
    [
      "                ",
      " n            a ",
      " n ghhghhghhg a ",
      " nZghhghhghhgZa ",
      " nV          Va ",
      " n0D         0a ",
      " n0D         0a ",
      " n0D         0a ",
      " n0D         0a ",
      " n0D         0a ",
      " n0D         0a ",
      " nY          Ya ",
      " n1ghhghhghhg1a ",
      " n ghhghhghhg a ",
      " n            a ",
      "                "
    ],
    [
      "                ",
      " n            a ",
      " n            a ",
      " n g33g33g33g a ",
      " n2ghhghhghhg2a ",
      " n2ghhghhghhg2a ",
      " n2ghhghhghhg2a ",
      " n2ghhghhghhg2a ",
      " n2ghhghhghhg2a ",
      " n2ghhghhghhg2a ",
      " n2ghhghhghhg2a ",
      " n2ghhghhghhg2a ",
      " n g33g33g33g a ",
      " n            a ",
      " n            a ",
      "                "
    ],
    [
      "                ",
      " n            a ",
      " n            a ",
      " n            a ",
      " n            a ",
      " n            a ",
      " n            a ",
      " n            a ",
      " n            a ",
      " n            a ",
      " n            a ",
      " n            a ",
      " n            a ",
      " n            a ",
      " n            a ",
      "                "
    ]
  ]
}