{
  "name": "building_office3a_floor4_90",
  "refpalette": "deceasedcraft:building_office3a/building_office3a_floor4_palette_90",
  "xsize": 16,
  "zsize": 16,
  "slices": [
    [
      "                ",
      " a            m ",
      " adeiieiieiiedm ",
      " achhhhhhhhhhcm ",
      " acgjjjjjjjjgcm ",
      " acgjjjjjjjjgcm ",
      " acgjjjjjjjjg m ",
      " acgjjjjjjjjg m ",
      " acgjjjjjjjjg m ",
      " acgjjjjjjjjg m ",
      " acgjjjjjjjjglm ",
      " acgjjjjjjjjgkm ",
      " acffffffffffcm ",
      " abeiieiieiiebm ",
      " a            m ",
      "                "
    ],
    [
      "                ",
      " a            m ",
      " adeiieiieiiedm ",
      " at AI        m ",
      " asxAE  L     m ",
      " ar AF  CM  Nlm ",
      " aqwAE  CM  Nkm ",
      " ap  DDDDD  N m ",
      " ao yC KC   N m ",
      " ao  C  C   N m ",
      " ao  CJ CJ  N m ",
      " ao  B  B     m ",
      " anu          m ",
      " abeiieiieiiebm ",
      " a            m ",
      "                "
    ],
    [
      "                ",
      " a            m ",
      " adeiieiieiiedm ",
      " a  AY        m ",
      " a  A         m ",
      " a  A       N m ",
      " aqTAX      Nlm ",
      " au  WWWWW  Nkm ",
      " aS  V  V   N m ",
      " aR     Z   N m ",
      " aQ  U  U   N m ",
      " aP           m ",
      " aO           m ",
      " abeiieiieiiebm ",
      " a            m ",
      "                "
    ],
    [
      "                ",
      " a            m ",
      " adeiieiieiiedm ",
      " a2 A4        m ",
      " a1 A3        m ",
      " a0 A4      N m ",
      " aqqA3      N m ",
      " a   WWWWW  Nlm ",
      " a          Nkm ",
      " a          N m ",
      " a          N m ",
      " a            m ",
      " a            m ",
      " abeiieiieiiebm ",
      " a            m ",
      "                "
    ],
    [
      "                ",
      " a            m ",
      " adeiieiieiiedm ",
      " a! A8        m ",
      " a5 A7        m ",
      " a  A6      N m ",
      " aqqA       N m ",
      " a          N m ",
      " a          Nlm ",
      " a          Nkm ",
      " a          N m ",
      " a            m ",
      " a            m ",
      " abeiieiieiiebm ",
      " a            m ",
      "                "
    ],
    [
      "                ",
      " a            m ",
      " adeiieiieiiedm ",
      " a  A         m ",
      " a  A         m ",
      " a  A       N m ",
      " aqqA       N m ",
      " a          N m ",
      " a          N m ",
      " a          Nlm ",
      " a          Nkm ",
      " a            m ",
      " a            m ",
      " abeiieiieiiebm ",
      " a            m ",
      "                "
    ]
  ]
}