{
  "name": "building_office3a_top_180",
  "refpalette": "deceasedcraft:building_office3a/building_office3a_top_palette_180",
  "xsize": 16,
  "zsize": 16,
  "slices": [
    [
      "                ",
      " nnnnnnnnnnnnnn ",
      "  fmkj    lkjb  ",
      "  geddddddddcg  ",
      "  heiiiiiiiich  ",
      "  heiiiiiiiich  ",
      "  geiiiiiiiicg  ",
      "  heiiiiiiiich  ",
      "  heiiiiiiiich  ",
      "  geiiiiiiiicg  ",
      "  heiiiiiiiich  ",
      "  heiiiiiiiich  ",
      "  geddddddddcg  ",
      "  feddddddddcb  ",
      " aaaaaaaaaaaaaa ",
      "                "
    ],
    [
      "                ",
      " nnnnnnnnnnnnnn ",
      "  fFFE       b  ",
      "  g  DDDDDD  g  ",
      "  h   CBBA   h  ",
      "  h   uuuu   h  ",
      "  g  yuxxuw  g  ",
      "  h   uuuu   h  ",
      "  h          h  ",
      "  g  tttttt  g  ",
      "  h  rssssr  h  ",
      "  h     q    h  ",
      "  g          g  ",
      "  fpopopopopob  ",
      " aaaaaaaaaaaaaa ",
      "                "
    ],
    [
      "                ",
      " nnnnnnnnnnnnnn ",
      "  f O        b  ",
      "  g  DDDDDD  g  ",
      "  h          h  ",
      "  h          h  ",
      "  g          g  ",
      "  h          h  ",
      "  h          h  ",
      "  g          g  ",
      "  h  NMLKJ   h  ",
      "  h          h  ",
      "  g          g  ",
      "  fIIIIIIIIIIb  ",
      " aaaaaaaaaaaaaa ",
      "                "
    ],
    [
      "                ",
      " nnnnnnnnnnnnnn ",
      "  f          b  ",
      "  g  DDDDDD  g  ",
      "  h          h  ",
      "  h          h  ",
      "  g          g  ",
      "  h          h  ",
      "  h          h  ",
      "  g          g  ",
      "  h          h  ",
      "  h          h  ",
      "  g          g  ",
      "  fIIIIIIIIIIb  ",
      " aaaaaaaaaaaaaa ",
      "                "
    ],
    [
      "                ",
      " nnnnnnnnnnnnnn ",
      "  f          b  ",
      "  g  DDDDDD  g  ",
      "  h          h  ",
      "  h          h  ",
      "  g          g  ",
      "  h          h  ",
      "  h          h  ",
      "  g          g  ",
      "  h          h  ",
      "  h          h  ",
      "  g          g  ",
      "  f U T SR QPb  ",
      " aaaaaaaaaaaaaa ",
      "                "
    ],
    [
      "                ",
      " nnnnnnnnnnnnnn ",
      "  fY        Vb  ",
      "  g  DDDDDD  g  ",
      "  h          h  ",
      "  h          h  ",
      "  g          g  ",
      "  h          h  ",
      "  h          h  ",
      "  g          g  ",
      "  h          h  ",
      "  h          h  ",
      "  g          g  ",
      "  fY   XW   Vb  ",
      " aaaaaaaaaaaaaa ",
      "                "
    ],
    [
      "                ",
      " nnnnnnnnnnnnnn ",
      "   1Y000000VZ   ",
      "  gg DDDDDD gg  ",
      "  hh        hh  ",
      "  hh        hh  ",
      "  gg        gg  ",
      "  hh        hh  ",
      "  hh        hh  ",
      "  gg        gg  ",
      "  hh        hh  ",
      "  hh        hh  ",
      "  gg        gg  ",
      "   1Y000000VZ   ",
      " aaaaaaaaaaaaaa ",
      "                "
    ],
    [
      "                ",
      " nnnnnnnnnnnnnn ",
      "    22222222    ",
      "   gggggggggg   ",
      "   3hhhhhhhh3   ",
      "   3hhhhhhhh3   ",
      "   gggggggggg   ",
      "   3hhhhhhhh3   ",
      "   3hhhhhhhh3   ",
      "   gggggggggg   ",
      "   3hhhhhhhh3   ",
      "   3hhhhhhhh3   ",
      "   gggggggggg   ",
      "    22222222    ",
      " aaaaaaaaaaaaaa ",
      "                "
    ],
    [
      "                ",
      " nnnnnnnnnnnnnn ",
      "                ",
      "                ",
      "                ",
      "                ",
      "                ",
      "                ",
      "                ",
      "                ",
      "                ",
      "                ",
      "                ",
      "                ",
      " aaaaaaaaaaaaaa ",
      "                "
    ]
  ]
}