{
  "name": "building_office3a_floor2_90",
  "refpalette": "deceasedcraft:building_office3a/building_office3a_floor2_palette_90",
  "xsize": 16,
  "zsize": 16,
  "slices": [
    [
      "                ",
      " a            l ",
      " aefggfggfggfel ",
      " ad          dl ",
      " a            l ",
      " a          k l ",
      " a         jk l ",
      " ac       hik l ",
      " a          k l ",
      " a          k l ",
      " a          k l ",
      " a            l ",
      " a            l ",
      " abfggfggfggfbl ",
      " a            l ",
      "                "
    ],
    [
      "                ",
      " a            l ",
      " aefggfggfggfel ",
      " a            l ",
      " a            l ",
      " a         jnnl ",
      " a        hikol ",
      " am         k l ",
      " a          k l ",
      " a          k l ",
      " a          k l ",
      " a            l ",
      " a            l ",
      " abfggfggfggfbl ",
      " a            l ",
      "                "
    ],
    [
      "                ",
      " a            l ",
      " aefggfggfggfel ",
      " a            l ",
      " a            l ",
      " a        hrrrl ",
      " a          ksl ",
      " ap         kol ",
      " a     q    k l ",
      " a          k l ",
      " a          k l ",
      " a            l ",
      " a            l ",
      " abfggfggfggfbl ",
      " a            l ",
      "                "
    ],
    [
      "                ",
      " a            l ",
      " aefggfggfggfel ",
      " a            l ",
      " a            l ",
      " a            l ",
      " a          k l ",
      " a      q   ksl ",
      " a     q    kol ",
      " a          k l ",
      " a          k l ",
      " a            l ",
      " a            l ",
      " abfggfggfggfbl ",
      " a            l ",
      "                "
    ],
    [
      "                ",
      " a            l ",
      " aefggfggfggfel ",
      " a            l ",
      " a            l ",
      " a            l ",
      " a          k l ",
      " a     qq   k l ",
      " a     qq   ksl ",
      " a          kol ",
      " a          k l ",
      " a            l ",
      " a            l ",
      " abfggfggfggfbl ",
      " a            l ",
      "                "
    ],
    [
      "                ",
      " a            l ",
      " aefggfggfggfel ",
      " a            l ",
      " a            l ",
      " a            l ",
      " a     tt   k l ",
      " a    tuut  k l ",
      " a    tuut  k l ",
      " a     tt   ksl ",
      " a          kol ",
      " a            l ",
      " a            l ",
      " abfggfggfggfbl ",
      " a            l ",
      "                "
    ]
  ]
}