{
  "name": "building_office3a_floor3_180",
  "refpalette": "deceasedcraft:building_office3a/building_office3a_floor3_palette_180",
  "xsize": 16,
  "zsize": 16,
  "slices": [
    [
      "                ",
      " mmmmmmmmmmmmmm ",
      "  dccc    lkcb  ",
      "  ehggggggggfe  ",
      "  ihjjjjjjjjfi  ",
      "  ihjjjjjjjjfi  ",
      "  ehjjjjjjjjfe  ",
      "  ihjjjjjjjjfi  ",
      "  ihjjjjjjjjfi  ",
      "  ehjjjjjjjjfe  ",
      "  ihjjjjjjjjfi  ",
      "  ihjjjjjjjjfi  ",
      "  ehggggggggfe  ",
      "  dccccccccccb  ",
      " aaaaaaaaaaaaaa ",
      "                "
    ],
    [
      "                ",
      " mmmmmmmmmmmmmm ",
      "  d  lk      b  ",
      "  e  LLLLLL  e  ",
      "  i          i  ",
      "  i          i  ",
      "  e  KKB  J  e  ",
      "  i IAABAAAy i  ",
      "  i    B     i  ",
      "  e    Bw F  e  ",
      "  iECDCBAAAy i  ",
      "  ixxxx w    i  ",
      "  e   u      e  ",
      "  dtsrqpoooonb  ",
      " aaaaaaaaaaaaaa ",
      "                "
    ],
    [
      "                ",
      " mmmmmmmmmmmmmm ",
      "  d   lk     b  ",
      "  e  LLLLLL  e  ",
      "  i          i  ",
      "  i          i  ",
      "  e    U     e  ",
      "  i  0ZUTYR  i  ",
      "  i    !     i  ",
      "  e    U     e  ",
      "  iXW VUTSR  i  ",
      "  ixxxx      i  ",
      "  e   Q      e  ",
      "  d   qNP ONMb  ",
      " aaaaaaaaaaaaaa ",
      "                "
    ],
    [
      "                ",
      " mmmmmmmmmmmmmm ",
      "  d    lk    b  ",
      "  e  LLLLLL  e  ",
      "  i          i  ",
      "  i          i  ",
      "  e    U     e  ",
      "  i    U     i  ",
      "  i    U     i  ",
      "  e    U     e  ",
      "  i5454U     i  ",
      "  ixxxx      i  ",
      "  e   q      e  ",
      "  d321q      b  ",
      " aaaaaaaaaaaaaa ",
      "                "
    ],
    [
      "                ",
      " mmmmmmmmmmmmmm ",
      "  d     lk   b  ",
      "  e  LLLLLL  e  ",
      "  i          i  ",
      "  i          i  ",
      "  e          e  ",
      "  i          i  ",
      "  i          i  ",
      "  e          e  ",
      "  i#9 8      i  ",
      "  ixxxx      i  ",
      "  e   q      e  ",
      "  d76 q      b  ",
      " aaaaaaaaaaaaaa ",
      "                "
    ],
    [
      "                ",
      " mmmmmmmmmmmmmm ",
      "  d      lk  b  ",
      "  e  LLLLLL  e  ",
      "  i          i  ",
      "  i          i  ",
      "  e          e  ",
      "  i          i  ",
      "  i          i  ",
      "  e          e  ",
      "  i          i  ",
      "  ixxxx      i  ",
      "  e   q      e  ",
      "  d   q      b  ",
      " aaaaaaaaaaaaaa ",
      "                "
    ]
  ]
}