{
  "name": "building_office3a_ground_270",
  "refpalette": "deceasedcraft:building_office3a/building_office3a_ground_palette_270",
  "xsize": 16,
  "zsize": 16,
  "slices": [
    [
      "aaaaaaaaaaaaaaaa",
      "aaaaaaaaaaaaaaaa",
      "aaaaaaaaaaaaaaaa",
      "aabbbeeeeeeeebaa",
      "aaccccccccccccaa",
      "aaddddddddddddaa",
      "aaddddddddddddaa",
      "aaddddddddddddaa",
      "aaddddddddddddaa",
      "aaddddddddddddaa",
      "aaddddddddddddaa",
      "aaddddddddddddaa",
      "aaddddddddddddaa",
      "aaaccccccccccaaa",
      "aaaaaaaaaaaaaaaa",
      "aaaaaaaaaaaaaaaa"
    ],
    [
      "                ",
      " Z            f ",
      " Zg RRmmmmmmmgf ",
      " Z  Tbnn!nnnn f ",
      " Zhhhhhhhhhhhhf ",
      " ZU U  wJowsoif ",
      " ZU U       pjf ",
      " ZU U  MDDx  jf ",
      " ZU U  NEEy  jf ",
      " ZU U  OEEA   f ",
      " ZiWV  PFFB  kf ",
      " ZX           f ",
      " ZY    QK    kf ",
      " ZlqttILLIttqlf ",
      " Z urS    Cur f ",
      "                "
    ],
    [
      "                ",
      " Z            f ",
      " Zg RRR      gf ",
      " Z   Tbn n nn f ",
      " Zhhhhhhhhhhhhf ",
      " Z8    oJwJwJ!f ",
      " Z9           f ",
      " Z8          0f ",
      " Z9 6  1111   f ",
      " Z9 7  2232   f ",
      " Zi           f ",
      " Z            f ",
      " Z     54     f ",
      " ZlqttI  Ittqlf ",
      " Z   m    m   f ",
      "                "
    ],
    [
      "                ",
      " Z            f ",
      " Zg RRRR     gf ",
      " Z    Tb      f ",
      " Zhhhhhhhhhhhhf ",
      " Z9          pf ",
      " Z9           f ",
      " Z8           f ",
      " Z8           f ",
      " Z9           f ",
      " Zi           f ",
      " Z^           f ",
      " Z^    $$     f ",
      " ZlqttI%%Ittqlf ",
      " Z   #    #   f ",
      "                "
    ],
    [
      "                ",
      " Z            f ",
      " Zg RRRRR    gf ",
      " Z     Tb    &f ",
      " Zhhhhhhhhhhhhf ",
      " Z            f ",
      " Z*           f ",
      " Z*           f ",
      " Z            f ",
      " Z            f ",
      " Z*           f ",
      " Z            f ",
      " Z*           f ",
      " ZlqttIIIIttqlf ",
      " Z            f ",
      "                "
    ],
    [
      "                ",
      " Z            f ",
      " Zg RRRRRR   gf ",
      " Z&     Tb   (f ",
      " Zhhhhhhhhhhhhf ",
      " Z[          )f ",
      " Z]          +f ",
      " Z]          +f ",
      " Z]          +f ",
      " Z]          +f ",
      " Z]          +f ",
      " Z]          +f ",
      " Z{          -f ",
      " Zlqttqttqttqlf ",
      " Z            f ",
      "                "
    ]
  ]
}