{
  "name": "building_office3a_floor2",
  "refpalette": "deceasedcraft:building_office3a/building_office3a_floor2_palette",
  "xsize": 16,
  "zsize": 16,
  "slices": [
    [
      "                ",
      " aaaaaaaaaaaaaa ",
      "  b     c   de  ",
      "  f          f  ",
      "  g          g  ",
      "  g          g  ",
      "  f          f  ",
      "  g          g  ",
      "  g          g  ",
      "  f          f  ",
      "  g     h    g  ",
      "  g     ij   g  ",
      "  f  kkkkkk  f  ",
      "  b         de  ",
      " llllllllllllll ",
      "                "
    ],
    [
      "                ",
      " aaaaaaaaaaaaaa ",
      "  b     m    e  ",
      "  f          f  ",
      "  g          g  ",
      "  g          g  ",
      "  f          f  ",
      "  g          g  ",
      "  g          g  ",
      "  f          f  ",
      "  g      h   g  ",
      "  g      ij  g  ",
      "  f  kkkkkn  f  ",
      "  b      on  e  ",
      " llllllllllllll ",
      "                "
    ],
    [
      "                ",
      " aaaaaaaaaaaaaa ",
      "  b     p    e  ",
      "  f          f  ",
      "  g          g  ",
      "  g          g  ",
      "  f          f  ",
      "  g    q     g  ",
      "  g          g  ",
      "  f          f  ",
      "  g       h  g  ",
      "  g       r  g  ",
      "  f  kkkkkr  f  ",
      "  b     osr  e  ",
      " llllllllllllll ",
      "                "
    ],
    [
      "                ",
      " aaaaaaaaaaaaaa ",
      "  b          e  ",
      "  f          f  ",
      "  g          g  ",
      "  g          g  ",
      "  f          f  ",
      "  g    q     g  ",
      "  g     q    g  ",
      "  f          f  ",
      "  g          g  ",
      "  g          g  ",
      "  f  kkkkk   f  ",
      "  b    os    e  ",
      " llllllllllllll ",
      "                "
    ],
    [
      "                ",
      " aaaaaaaaaaaaaa ",
      "  b          e  ",
      "  f          f  ",
      "  g          g  ",
      "  g          g  ",
      "  f          f  ",
      "  g    qq    g  ",
      "  g    qq    g  ",
      "  f          f  ",
      "  g          g  ",
      "  g          g  ",
      "  f  kkkkk   f  ",
      "  b   os     e  ",
      " llllllllllllll ",
      "                "
    ],
    [
      "                ",
      " aaaaaaaaaaaaaa ",
      "  b          e  ",
      "  f          f  ",
      "  g          g  ",
      "  g          g  ",
      "  f    tt    f  ",
      "  g   tuut   g  ",
      "  g   tuut   g  ",
      "  f    tt    f  ",
      "  g          g  ",
      "  g          g  ",
      "  f  kkkkk   f  ",
      "  b  os      e  ",
      " llllllllllllll ",
      "                "
    ]
  ]
}