{
  "name": "building_office3a_ground",
  "refpalette": "deceasedcraft:building_office3a/building_office3a_ground_palette",
  "xsize": 16,
  "zsize": 16,
  "slices": [
    [
      "aaaaaaaaaaaaaaaa",
      "aaaaaaaaaaaaaaaa",
      "aaabcddddddddaaa",
      "aaaecddddddddcaa",
      "aaaecddddddddcaa",
      "aaaecddddddddcaa",
      "aaaecddddddddcaa",
      "aaaecddddddddcaa",
      "aaaecddddddddcaa",
      "aaaecddddddddcaa",
      "aaaecddddddddcaa",
      "aaabcddddddddcaa",
      "aaabcddddddddcaa",
      "aaabcddddddddaaa",
      "aaaaaaaaaaaaaaaa",
      "aaaaaaaaaaaaaaaa"
    ],
    [
      "                ",
      " ffffffffffffff ",
      "  g hijjj k kl  ",
      "  mnhop      qr ",
      "  mnhs       tu ",
      "  mnhw xyAB  tC ",
      "  mnho DEEF  I  ",
      "  m!hJ DEEF KL  ",
      "  mnhw MNOP QL  ",
      "  mnh        I  ",
      "  Rbh        tS ",
      "  RThUUUUUV  tr ",
      "    h     W  qu ",
      "  g hUUUUUiXYl  ",
      " ZZZZZZZZZZZZZZ ",
      "                "
    ],
    [
      "                ",
      " ffffffffffffff ",
      "  g h! 0     l  ",
      "   nhJ       q  ",
      "   nhw       t  ",
      "    hJ  12   tm ",
      "   nhw  13   I  ",
      "    hJ  12  4   ",
      "   nho  12  5   ",
      "  Rbh        I  ",
      "  RTh        tm ",
      "  R h   67   t  ",
      "    h        q  ",
      "  g h89899i  l  ",
      " ZZZZZZZZZZZZZZ ",
      "                "
    ],
    [
      "                ",
      " ffffffffffffff ",
      "  g hp       l  ",
      "    h        q  ",
      "    h        t  ",
      "    h        t# ",
      "    h        I  ",
      "    h       $%  ",
      "  Rbh       $%  ",
      "  RTh        I  ",
      "  R h        t# ",
      "  R h        t  ",
      "    h        q  ",
      "  g h99889i^^l  ",
      " ZZZZZZZZZZZZZZ ",
      "                "
    ],
    [
      "                ",
      " ffffffffffffff ",
      "  g&h        l  ",
      "    h        q  ",
      "    h        t  ",
      "    h        t  ",
      "    h        I  ",
      "  Rbh        I  ",
      "  RTh        I  ",
      "  R h        I  ",
      "  R h        t  ",
      "  R h        t  ",
      "    h        q  ",
      "  g h **  * *l  ",
      " ZZZZZZZZZZZZZZ ",
      "                "
    ],
    [
      "                ",
      " ffffffffffffff ",
      "  g(h)++++++-l  ",
      "    h        q  ",
      "    h        t  ",
      "    h        t  ",
      "  Rbh        q  ",
      "  RTh        t  ",
      "  R h        t  ",
      "  R h        q  ",
      "  R h        t  ",
      "  R h        t  ",
      "    h        q  ",
      "  g&h[]]]]]]{l  ",
      " ZZZZZZZZZZZZZZ ",
      "                "
    ]
  ]
}