{
  "name": "building_office3a_floor2_270",
  "refpalette": "deceasedcraft:building_office3a/building_office3a_floor2_palette_270",
  "xsize": 16,
  "zsize": 16,
  "slices": [
    [
      "                ",
      " l            a ",
      " lbfggfggfggfba ",
      " l            a ",
      " l            a ",
      " l k          a ",
      " l k          a ",
      " l k          a ",
      " l kih       ca ",
      " l kj         a ",
      " l k          a ",
      " l            a ",
      " ld          da ",
      " lefggfggfggfea ",
      " l            a ",
      "                "
    ],
    [
      "                ",
      " l            a ",
      " lbfggfggfggfba ",
      " l            a ",
      " l            a ",
      " l k          a ",
      " l k          a ",
      " l k          a ",
      " l k         ma ",
      " lokih        a ",
      " lnnj         a ",
      " l            a ",
      " l            a ",
      " lefggfggfggfea ",
      " l            a ",
      "                "
    ],
    [
      "                ",
      " l            a ",
      " lbfggfggfggfba ",
      " l            a ",
      " l            a ",
      " l k          a ",
      " l k          a ",
      " l k    q     a ",
      " lok         pa ",
      " lsk          a ",
      " lrrrh        a ",
      " l            a ",
      " l            a ",
      " lefggfggfggfea ",
      " l            a ",
      "                "
    ],
    [
      "                ",
      " l            a ",
      " lbfggfggfggfba ",
      " l            a ",
      " l            a ",
      " l k          a ",
      " l k          a ",
      " lok    q     a ",
      " lsk   q      a ",
      " l k          a ",
      " l            a ",
      " l            a ",
      " l            a ",
      " lefggfggfggfea ",
      " l            a ",
      "                "
    ],
    [
      "                ",
      " l            a ",
      " lbfggfggfggfba ",
      " l            a ",
      " l            a ",
      " l k          a ",
      " lok          a ",
      " lsk   qq     a ",
      " l k   qq     a ",
      " l k          a ",
      " l            a ",
      " l            a ",
      " l            a ",
      " lefggfggfggfea ",
      " l            a ",
      "                "
    ],
    [
      "                ",
      " l            a ",
      " lbfggfggfggfba ",
      " l            a ",
      " l            a ",
      " lok          a ",
      " lsk   tt     a ",
      " l k  tuut    a ",
      " l k  tuut    a ",
      " l k   tt     a ",
      " l            a ",
      " l            a ",
      " l            a ",
      " lefggfggfggfea ",
      " l            a ",
      "                "
    ]
  ]
}