{
  "name": "building_office3a_floor1_180",
  "refpalette": "deceasedcraft:building_office3a/building_office3a_floor1_palette_180",
  "xsize": 16,
  "zsize": 16,
  "slices": [
    [
      "                ",
      " nnnnnnnnnnnnnn ",
      "  fl  mll ldcb  ",
      "  g        d    ",
      "  h        d i  ",
      "  h        d i  ",
      "  g        d i  ",
      "  h        d i  ",
      "  h        d i  ",
      "  g        dki  ",
      "  h        dji  ",
      "  h        d    ",
      "  g        d    ",
      "  fe  ee eedcb  ",
      " aaaaaaaaaaaaaa ",
      "                "
    ],
    [
      "                ",
      " nnnnnnnnnnnnnn ",
      "  f        dcb  ",
      "  g        d    ",
      "  h        d i  ",
      "  h        d i  ",
      "  g        d i  ",
      "  h        d i  ",
      "  h        d i  ",
      "  g        d i  ",
      "  h        dki  ",
      "  h        dji  ",
      "  g        d    ",
      "  f        dcb  ",
      " aaaaaaaaaaaaaa ",
      "                "
    ],
    [
      "                ",
      " nnnnnnnnnnnnnn ",
      "  fppppppppdtb  ",
      "  g qqqqqqpd    ",
      "  h qqqqqqpd i  ",
      "  h qqssqqpd i  ",
      "  g qqqqqqpd i  ",
      "  h qqqqqqpd i  ",
      "  h qqqqqqpd i  ",
      "  g qqqqqqpd i  ",
      "  h qqsrqqpd i  ",
      "  h qqqqqqpdki  ",
      "  g qqqqqqpdji  ",
      "  fppppppppdob  ",
      " aaaaaaaaaaaaaa ",
      "                "
    ],
    [
      "                ",
      " nnnnnnnnnnnnnn ",
      "  fjjjjjjjjjyb  ",
      "  gxwwwwwwwj u  ",
      "  hxwwwwwwwj u  ",
      "  hxwwwwwwwj u  ",
      "  gxwwwwwwwj u  ",
      "  hxwwwwwwwj u  ",
      "  hxwwwwwwwj u  ",
      "  gxwwwwwwwj u  ",
      "  hxwwwwwwwj u  ",
      "  hxwwwwwwwj u  ",
      "  gxwwwwwwwjku  ",
      "  fjjjjjjjjjjb  ",
      " aaaaaaaaaaaaaa ",
      "                "
    ],
    [
      "                ",
      " nnnnnnnnnnnnnn ",
      "  fR       B b  ",
      "  g  iiiiiiBug  ",
      "  h     QP B h  ",
      "  h  O   N B h  ",
      "  gMLLLLL  Bug  ",
      "  h        B h  ",
      "  h        B h  ",
      "  g        Bug  ",
      "  h  K D J B h  ",
      "  h  I D F B h  ",
      "  g  E D C B g  ",
      "  fA         b  ",
      " aaaaaaaaaaaaaa ",
      "                "
    ],
    [
      "                ",
      " nnnnnnnnnnnnnn ",
      "  fS         b  ",
      "  g  iiiiii  g  ",
      "  h    QP    h  ",
      "  h     N    h  ",
      "  g          g  ",
      "  h          h  ",
      "  h          h  ",
      "  g          g  ",
      "  h          h  ",
      "  h          h  ",
      "  g          g  ",
      "  fS         b  ",
      " aaaaaaaaaaaaaa ",
      "                "
    ]
  ]
}