{
  "name": "building_office3a_floor4_180",
  "refpalette": "deceasedcraft:building_office3a/building_office3a_floor4_palette_180",
  "xsize": 16,
  "zsize": 16,
  "slices": [
    [
      "                ",
      " mmmmmmmmmmmmmm ",
      "  dccc    lkcb  ",
      "  ehggggggggfe  ",
      "  ihjjjjjjjjfi  ",
      "  ihjjjjjjjjfi  ",
      "  ehjjjjjjjjfe  ",
      "  ihjjjjjjjjfi  ",
      "  ihjjjjjjjjfi  ",
      "  ehjjjjjjjjfe  ",
      "  ihjjjjjjjjfi  ",
      "  ihjjjjjjjjfi  ",
      "  ehggggggggfe  ",
      "  dccccccccccb  ",
      " aaaaaaaaaaaaaa ",
      "                "
    ],
    [
      "                ",
      " mmmmmmmmmmmmmm ",
      "  d  lk      b  ",
      "  e  NNNNNN  e  ",
      "  i          i  ",
      "  i          i  ",
      "  e  MMD  J  e  ",
      "  i LCCDCCCB i  ",
      "  i    DK    i  ",
      "  e    D  J  e  ",
      "  iIEFEDCCCB i  ",
      "  iAAAA y    i  ",
      "  e x w     ue  ",
      "  dtsrqpoooonb  ",
      " aaaaaaaaaaaaaa ",
      "                "
    ],
    [
      "                ",
      " mmmmmmmmmmmmmm ",
      "  d   lk     b  ",
      "  e  NNNNNN  e  ",
      "  i          i  ",
      "  i          i  ",
      "  e    W     e  ",
      "  i    WVZU  i  ",
      "  i    W     i  ",
      "  e    W     e  ",
      "  iY  XWV U  i  ",
      "  iAAAA      i  ",
      "  e   T      e  ",
      "  d   quSRQPOb  ",
      " aaaaaaaaaaaaaa ",
      "                "
    ],
    [
      "                ",
      " mmmmmmmmmmmmmm ",
      "  d    lk    b  ",
      "  e  NNNNNN  e  ",
      "  i          i  ",
      "  i          i  ",
      "  e    W     e  ",
      "  i    W     i  ",
      "  i    W     i  ",
      "  e    W     e  ",
      "  i4343W     i  ",
      "  iAAAA      i  ",
      "  e   q      e  ",
      "  d210q      b  ",
      " aaaaaaaaaaaaaa ",
      "                "
    ],
    [
      "                ",
      " mmmmmmmmmmmmmm ",
      "  d     lk   b  ",
      "  e  NNNNNN  e  ",
      "  i          i  ",
      "  i          i  ",
      "  e          e  ",
      "  i          i  ",
      "  i          i  ",
      "  e          e  ",
      "  i876       i  ",
      "  iAAAA      i  ",
      "  e   q      e  ",
      "  d!5 q      b  ",
      " aaaaaaaaaaaaaa ",
      "                "
    ],
    [
      "                ",
      " mmmmmmmmmmmmmm ",
      "  d      lk  b  ",
      "  e  NNNNNN  e  ",
      "  i          i  ",
      "  i          i  ",
      "  e          e  ",
      "  i          i  ",
      "  i          i  ",
      "  e          e  ",
      "  i          i  ",
      "  iAAAA      i  ",
      "  e   q      e  ",
      "  d   q      b  ",
      " aaaaaaaaaaaaaa ",
      "                "
    ]
  ]
}