{
  "name": "building_office3a_floor1_90",
  "refpalette": "deceasedcraft:building_office3a/building_office3a_floor1_palette_90",
  "xsize": 16,
  "zsize": 16,
  "slices": [
    [
      "                ",
      " a            n ",
      " afghhghhghhgfn ",
      " ae          ln ",
      " a            n ",
      " a            n ",
      " ae          mn ",
      " ae          ln ",
      " a           ln ",
      " ae           n ",
      " ae          ln ",
      " addddddddddddn ",
      " ac  jk      cn ",
      " ab  iiiiiii bn ",
      " a            n ",
      "                "
    ],
    [
      "                ",
      " a            n ",
      " afghhghhghhgfn ",
      " a            n ",
      " a            n ",
      " a            n ",
      " a            n ",
      " a            n ",
      " a            n ",
      " a            n ",
      " a            n ",
      " addddddddddddn ",
      " ac jk       cn ",
      " ab iiiiiiii bn ",
      " a            n ",
      "                "
    ],
    [
      "                ",
      " a            n ",
      " afghhghhghhgfn ",
      " ap          pn ",
      " apqqqqqqqqqqpn ",
      " apqqqqqqqqqqpn ",
      " apqqsqqqqsqqpn ",
      " apqqrqqqqsqqpn ",
      " apqqqqqqqqqqpn ",
      " apqqqqqqqqqqpn ",
      " appppppppppppn ",
      " addddddddddddn ",
      " aojk        tn ",
      " abiiiiiiiii bn ",
      " a            n ",
      "                "
    ],
    [
      "                ",
      " a            n ",
      " afghhghhghhgfn ",
      " ajxxxxxxxxxxjn ",
      " ajwwwwwwwwwwjn ",
      " ajwwwwwwwwwwjn ",
      " ajwwwwwwwwwwjn ",
      " ajwwwwwwwwwwjn ",
      " ajwwwwwwwwwwjn ",
      " ajwwwwwwwwwwjn ",
      " ajwwwwwwwwwwjn ",
      " ajjjjjjjjjjjjn ",
      " ajk         yn ",
      " abuuuuuuuuuubn ",
      " a            n ",
      "                "
    ],
    [
      "                ",
      " a            n ",
      " afghhghhghhgfn ",
      " aA      M   Rn ",
      " a       L    n ",
      " a EIK   LO i n ",
      " a       L  i n ",
      " a DDD   L  i n ",
      " a       L Qi n ",
      " a CFJ    NPi n ",
      " a          i n ",
      " a BBBBBBBBBBBn ",
      " a    u  u  u n ",
      " abghhghhghhgbn ",
      " a            n ",
      "                "
    ],
    [
      "                ",
      " a            n ",
      " afghhghhghhgfn ",
      " aS          Sn ",
      " a            n ",
      " a          i n ",
      " a          i n ",
      " a         Qi n ",
      " a        NPi n ",
      " a          i n ",
      " a          i n ",
      " a            n ",
      " a            n ",
      " abghhghhghhgbn ",
      " a            n ",
      "                "
    ]
  ]
}