{
  "name": "building_office3a_top_90",
  "refpalette": "deceasedcraft:building_office3a/building_office3a_top_palette_90",
  "xsize": 16,
  "zsize": 16,
  "slices": [
    [
      "                ",
      " a            n ",
      " afghhghhghhgfn ",
      " aeeeeeeeeeeemn ",
      " addiiiiiiiidkn ",
      " addiiiiiiiidjn ",
      " addiiiiiiiid n ",
      " addiiiiiiiid n ",
      " addiiiiiiiid n ",
      " addiiiiiiiid n ",
      " addiiiiiiiidln ",
      " addiiiiiiiidkn ",
      " acccccccccccjn ",
      " abghhghhghhgbn ",
      " a            n ",
      "                "
    ],
    [
      "                ",
      " a            n ",
      " afghhghhghhgfn ",
      " ap          Fn ",
      " ao          Fn ",
      " ap  rt  y  DEn ",
      " ao  st uuuCD n ",
      " ap  st uxuBD n ",
      " ao qst uxuBD n ",
      " ap  st uuuAD n ",
      " ao  rt  w  D n ",
      " ap           n ",
      " ao           n ",
      " abghhghhghhgbn ",
      " a            n ",
      "                "
    ],
    [
      "                ",
      " a            n ",
      " afghhghhghhgfn ",
      " aI           n ",
      " aI          On ",
      " aI  N      D n ",
      " aI  M      D n ",
      " aI  L      D n ",
      " aI  K      D n ",
      " aI  J      D n ",
      " aI         D n ",
      " aI           n ",
      " aI           n ",
      " abghhghhghhgbn ",
      " a            n ",
      "                "
    ],
    [
      "                ",
      " a            n ",
      " afghhghhghhgfn ",
      " aI           n ",
      " aI           n ",
      " aI         D n ",
      " aI         D n ",
      " aI         D n ",
      " aI         D n ",
      " aI         D n ",
      " aI         D n ",
      " aI           n ",
      " aI           n ",
      " abghhghhghhgbn ",
      " a            n ",
      "                "
    ],
    [
      "                ",
      " a            n ",
      " afghhghhghhgfn ",
      " a            n ",
      " aU           n ",
      " a          D n ",
      " aT         D n ",
      " a          D n ",
      " aS         D n ",
      " aR         D n ",
      " a          D n ",
      " aQ           n ",
      " aP           n ",
      " abghhghhghhgbn ",
      " a            n ",
      "                "
    ],
    [
      "                ",
      " a            n ",
      " afghhghhghhgfn ",
      " aY          Yn ",
      " a            n ",
      " a          D n ",
      " a          D n ",
      " aX         D n ",
      " aW         D n ",
      " a          D n ",
      " a          D n ",
      " a            n ",
      " aV          Vn ",
      " abghhghhghhgbn ",
      " a            n ",
      "                "
    ],
    [
      "                ",
      " a            n ",
      " a ghhghhghhg n ",
      " a1ghhghhghhg1n ",
      " aY          Yn ",
      " a0         D0n ",
      " a0         D0n ",
      " a0         D0n ",
      " a0         D0n ",
      " a0         D0n ",
      " a0         D0n ",
      " aV          Vn ",
      " aZghhghhghhgZn ",
      " a ghhghhghhg n ",
      " a            n ",
      "                "
    ],
    [
      "                ",
      " a            n ",
      " a            n ",
      " a g33g33g33g n ",
      " a2ghhghhghhg2n ",
      " a2ghhghhghhg2n ",
      " a2ghhghhghhg2n ",
      " a2ghhghhghhg2n ",
      " a2ghhghhghhg2n ",
      " a2ghhghhghhg2n ",
      " a2ghhghhghhg2n ",
      " a2ghhghhghhg2n ",
      " a g33g33g33g n ",
      " a            n ",
      " a            n ",
      "                "
    ],
    [
      "                ",
      " a            n ",
      " a            n ",
      " a            n ",
      " a            n ",
      " a            n ",
      " a            n ",
      " a            n ",
      " a            n ",
      " a            n ",
      " a            n ",
      " a            n ",
      " a            n ",
      " a            n ",
      " a            n ",
      "                "
    ]
  ]
}