{
  "name": "building_office3a_floor4",
  "refpalette": "deceasedcraft:building_office3a/building_office3a_floor4_palette",
  "xsize": 16,
  "zsize": 16,
  "slices": [
    [
      "                ",
      " aaaaaaaaaaaaaa ",
      "  bccccccccccd  ",
      "  efgggggggghe  ",
      "  ifjjjjjjjjhi  ",
      "  ifjjjjjjjjhi  ",
      "  efjjjjjjjjhe  ",
      "  ifjjjjjjjjhi  ",
      "  ifjjjjjjjjhi  ",
      "  efjjjjjjjjhe  ",
      "  ifjjjjjjjjhi  ",
      "  ifjjjjjjjjhi  ",
      "  efgggggggghe  ",
      "  bckl    cccd  ",
      " mmmmmmmmmmmmmm ",
      "                "
    ],
    [
      "                ",
      " aaaaaaaaaaaaaa ",
      "  bnoooopqrstd  ",
      "  eu     w x e  ",
      "  i    y AAAAi  ",
      "  i BCCCDEFEIi  ",
      "  e  J  D    e  ",
      "  i    KD    i  ",
      "  i BCCCDCCL i  ",
      "  e  J  DMM  e  ",
      "  i          i  ",
      "  i          i  ",
      "  e  NNNNNN  e  ",
      "  b      kl  d  ",
      " mmmmmmmmmmmmmm ",
      "                "
    ],
    [
      "                ",
      " aaaaaaaaaaaaaa ",
      "  bOPQRSuq   d  ",
      "  e      T   e  ",
      "  i      AAAAi  ",
      "  i  U VWX  Yi  ",
      "  e     W    e  ",
      "  i     W    i  ",
      "  i  UZVW    i  ",
      "  e     W    e  ",
      "  i          i  ",
      "  i          i  ",
      "  e  NNNNNN  e  ",
      "  b     kl   d  ",
      " mmmmmmmmmmmmmm ",
      "                "
    ],
    [
      "                ",
      " aaaaaaaaaaaaaa ",
      "  b      q012d  ",
      "  e      q   e  ",
      "  i      AAAAi  ",
      "  i     W3434i  ",
      "  e     W    e  ",
      "  i     W    i  ",
      "  i     W    i  ",
      "  e     W    e  ",
      "  i          i  ",
      "  i          i  ",
      "  e  NNNNNN  e  ",
      "  b    kl    d  ",
      " mmmmmmmmmmmmmm ",
      "                "
    ],
    [
      "                ",
      " aaaaaaaaaaaaaa ",
      "  b      q 5!d  ",
      "  e      q   e  ",
      "  i      AAAAi  ",
      "  i       678i  ",
      "  e          e  ",
      "  i          i  ",
      "  i          i  ",
      "  e          e  ",
      "  i          i  ",
      "  i          i  ",
      "  e  NNNNNN  e  ",
      "  b   kl     d  ",
      " mmmmmmmmmmmmmm ",
      "                "
    ],
    [
      "                ",
      " aaaaaaaaaaaaaa ",
      "  b      q   d  ",
      "  e      q   e  ",
      "  i      AAAAi  ",
      "  i          i  ",
      "  e          e  ",
      "  i          i  ",
      "  i          i  ",
      "  e          e  ",
      "  i          i  ",
      "  i          i  ",
      "  e  NNNNNN  e  ",
      "  b  kl      d  ",
      " mmmmmmmmmmmmmm ",
      "                "
    ]
  ]
}