{
  "name": "building_office3a_ground_180",
  "refpalette": "deceasedcraft:building_office3a/building_office3a_ground_palette_180",
  "xsize": 16,
  "zsize": 16,
  "slices": [
    [
      "aaaaaaaaaaaaaaaa",
      "aaaaaaaaaaaaaaaa",
      "aaaddddddddcbaaa",
      "aacddddddddcbaaa",
      "aacddddddddcbaaa",
      "aacddddddddceaaa",
      "aacddddddddceaaa",
      "aacddddddddceaaa",
      "aacddddddddceaaa",
      "aacddddddddceaaa",
      "aacddddddddceaaa",
      "aacddddddddceaaa",
      "aacddddddddceaaa",
      "aaaddddddddcbaaa",
      "aaaaaaaaaaaaaaaa",
      "aaaaaaaaaaaaaaaa"
    ],
    [
      "                ",
      " ZZZZZZZZZZZZZZ ",
      "  lYXiUUUUUh g  ",
      " uq  W     h    ",
      " rt  VUUUUUhTR  ",
      " St        hbR  ",
      "  I        hnm  ",
      "  LQ PONM whnm  ",
      "  LK FEED Jh!m  ",
      "  I  FEED ohnm  ",
      " Ct  BAyx whnm  ",
      " ut       shnm  ",
      " rq      pohnm  ",
      "  lk k jjjih g  ",
      " ffffffffffffff ",
      "                "
    ],
    [
      "                ",
      " ZZZZZZZZZZZZZZ ",
      "  l  i99898h g  ",
      "  q        h    ",
      "  t   76   h R  ",
      " mt        hTR  ",
      "  I        hbR  ",
      "   5  21  ohn   ",
      "   4  21  Jh    ",
      "  I   31  whn   ",
      " mt   21  Jh    ",
      "  t       whn   ",
      "  q       Jhn   ",
      "  l     0 !h g  ",
      " ffffffffffffff ",
      "                "
    ],
    [
      "                ",
      " ZZZZZZZZZZZZZZ ",
      "  l^^i98899h g  ",
      "  q        h    ",
      "  t        h R  ",
      " #t        h R  ",
      "  I        hTR  ",
      "  %$       hbR  ",
      "  %$       h    ",
      "  I        h    ",
      " #t        h    ",
      "  t        h    ",
      "  q        h    ",
      "  l       ph g  ",
      " ffffffffffffff ",
      "                "
    ],
    [
      "                ",
      " ZZZZZZZZZZZZZZ ",
      "  l* *  ** h g  ",
      "  q        h    ",
      "  t        h R  ",
      "  t        h R  ",
      "  I        h R  ",
      "  I        hTR  ",
      "  I        hbR  ",
      "  I        h    ",
      "  t        h    ",
      "  t        h    ",
      "  q        h    ",
      "  l        h&g  ",
      " ffffffffffffff ",
      "                "
    ],
    [
      "                ",
      " ZZZZZZZZZZZZZZ ",
      "  l{]]]]]][h&g  ",
      "  q        h    ",
      "  t        h R  ",
      "  t        h R  ",
      "  q        h R  ",
      "  t        h R  ",
      "  t        hTR  ",
      "  q        hbR  ",
      "  t        h    ",
      "  t        h    ",
      "  q        h    ",
      "  l-++++++)h(g  ",
      " ffffffffffffff ",
      "                "
    ]
  ]
}