{
  "name": "multi_oasiscondo_7_floor10",
  "refpalette": "deceasedcraft:multi_oasiscondo_7/multi_oasiscondo_7_floor10_palette",
  "xsize": 16,
  "zsize": 16,
  "slices": [
    [
      "aabccccccccccccc",
      "ddbeeeeeeeeeeefe",
      "ddbefefeeeeefffe",
      "ddbeeffffeffeeef",
      "ddbeeeefeffeefee",
      "ddbegeeeeeebeeee",
      "dh hdddddddddddd",
      "                ",
      "                ",
      "                ",
      "                ",
      "                ",
      "                ",
      "                ",
      "                ",
      "                "
    ],
    [
      "ijb             ",
      "  b k k l kmk   ",
      "nobk   l p q    ",
      " obq            ",
      " rbklsk    mk s ",
      " rbkk  mkk b m k",
      " t uwwwwwwwwwwww",
      "xy uuwwwwwwwwwww",
      "   uAAAAAAAAAAAA",
      "                ",
      "                ",
      "                ",
      "                ",
      "                ",
      "                ",
      "                "
    ],
    [
      "Bjb             ",
      "  b         k   ",
      "  b      k !    ",
      "  b             ",
      "  b  p        p ",
      "  b k   k  b    ",
      " x u            ",
      "xy uu           ",
      "   uCCCCCCCCCCCC",
      "                ",
      "                ",
      "                ",
      "                ",
      "                ",
      "                ",
      "                "
    ],
    [
      "jjb             ",
      "  b             ",
      "  b      k      ",
      "  b             ",
      "  b  k        l ",
      "  b        b    ",
      " x u            ",
      "xy uu           ",
      "   u            ",
      "                ",
      "                ",
      "                ",
      "                ",
      "                ",
      "                ",
      "                "
    ],
    [
      "xxb             ",
      "  b             ",
      "  b      l      ",
      "  b             ",
      "  b  l          ",
      "  b        b    ",
      " x u            ",
      "xD uuEEEEEEEEEEE",
      "   u            ",
      "                ",
      "                ",
      "                ",
      "                ",
      "                ",
      "                ",
      "                "
    ],
    [
      "xxbFFFFFFFFFFFFF",
      "IIbFFFFFFFFFFFFF",
      "IIbFFFFFFFFFFFFF",
      "IIbFFFFFFFFFFFFF",
      "IIbFFFFFFFFFFFFF",
      "IIbFFFFFFFFbFFFF",
      "Ix uuuuuuuuuuuuu",
      "xy uuuuuuuuuuuuu",
      "   uuuuuuuuuuuuu",
      "                ",
      "                ",
      "                ",
      "                ",
      "                ",
      "                ",
      "                "
    ]
  ]
}