{
  "name": "multi_oasiscondo_7_base2",
  "refpalette": "deceasedcraft:multi_oasiscondo_7/multi_oasiscondo_7_base2_palette",
  "xsize": 16,
  "zsize": 16,
  "slices": [
    [
      "HaaaHHHHHHHaaaaa",
      "HHHHHHHHHHHHHHHH",
      "HHHHHHHHHHHHHHHH",
      "HHHHHHHHHHHHHHHH",
      "HHaHHHHHHHHaHHHH",
      "HHbHHHHHHHHbHHHH",
      "HHaHHHHHHHHaHHHH",
      "HHaHHHHHHHHaHHHH",
      "HHaHHHHHHHHaHHHH",
      "HHaHHHHHHHHaHHHH",
      "HHaHHHHHHHHaHHHH",
      "HHaHHHHHHHHaHHHH",
      "HHHHHHHHHHHHHHHH",
      "HHHHHHHHHHHHHHHH",
      "HHHHHHHHHHHHHHHH",
      "vvvvvvvvvvvvvvvv"
    ],
    [
      "                ",
      "                ",
      "                ",
      "                ",
      "cdecdcdcdcdecdcd",
      "  b        b    ",
      "  e        e    ",
      "fgefgfgfgfgefgfg",
      "cdecdcdcdcdecdcd",
      "  e        e    ",
      "  e        e    ",
      "fgefgfgfgfgefgfg",
      "                ",
      "                ",
      "                ",
      "vvvvvvvvvvvvvvvv"
    ],
    [
      "                ",
      "                ",
      "                ",
      "                ",
      "                ",
      "  b        b    ",
      "                ",
      "                ",
      "                ",
      "                ",
      "                ",
      "                ",
      "                ",
      "                ",
      "                ",
      "vvvvvvvvvvvvvvvv"
    ],
    [
      "                ",
      "                ",
      "                ",
      "                ",
      "                ",
      "  b        b    ",
      "                ",
      "                ",
      "                ",
      "                ",
      "                ",
      "                ",
      "                ",
      "                ",
      "                ",
      "vvvvvvvvvvvvvvvv"
    ],
    [
      "                ",
      "                ",
      "                ",
      "                ",
      "                ",
      "  b        b    ",
      "                ",
      "                ",
      "                ",
      "                ",
      "                ",
      "                ",
      "                ",
      "                ",
      "                ",
      "vvvvvvvvvvvvvvvv"
    ],
    [
      "hhihhhhhhhhihhhh",
      "hhihhhhhhhhihhhh",
      "hhihhhhhhhhihhhh",
      "hhihhhhhhhhihhhh",
      "hhihhhhhhhhihhhh",
      "iijiiiiiiiijiiii",
      "hhihhhhhhhhihhhh",
      "hhihhhhhhhhihhhh",
      "hhihhhhhhhhihhhh",
      "hhihhhhhhhhihhhh",
      "hhihhhhhhhhihhhh",
      "hhihhhhhhhhihhhh",
      "hhihhhhhhhhihhhh",
      "hhihhhhhhhhihhhh",
      "hhihhhhhhhhihhhh",
      "vvvvvvvvvvvvvvvv"
    ]
  ]
}