{
  "name": "multi_oasiscondo_7_floor5",
  "refpalette": "deceasedcraft:multi_oasiscondo_7/multi_oasiscondo_7_floor5_palette",
  "xsize": 16,
  "zsize": 16,
  "slices": [
    [
      "aabacaaaaaabacaa",
      "ddbddddddddbdddd",
      "ddbddddddddbdddd",
      "ddbddddddddbdddd",
      "ddbddddddddbdddd",
      "ddbddddddddbdddd",
      "de edddddde eddd",
      "                ",
      "                ",
      "                ",
      "                ",
      "                ",
      "                ",
      "                ",
      "                ",
      "                "
    ],
    [
      "aabafaaaaaabafaa",
      " gb     ah bi   ",
      " jbkk   a  bi   ",
      " gb     a lbamaa",
      " nb     aoabp  q",
      " rb        bst u",
      "wa x      x yABC",
      "aD xxEEEExx Faaa",
      "   xIIIIIIx     ",
      "                ",
      "                ",
      "                ",
      "                ",
      "                ",
      "                ",
      "                "
    ],
    [
      "aabaJaaaaaabaJaa",
      " Kb     a LbM  N",
      "  bkk   a  bO   ",
      "  b     a  baPaa",
      " Qb     aRabS  q",
      " Tb        bU  V",
      "Wa x      x a  C",
      "aF xx    xx FaXX",
      "   xYYYYYYx     ",
      "                ",
      "                ",
      "                ",
      "                ",
      "                ",
      "                ",
      "                "
    ],
    [
      "aabaZaaaaaabaZaa",
      " 0b     a 1b2  3",
      " 0bkk   a  b2   ",
      " 0b     a  ba4aa",
      " 5b     a6ab   C",
      " 7b        b   8",
      " a x      x a  C",
      "aF xx    xx DaXX",
      "   x      x     ",
      "                ",
      "                ",
      "                ",
      "                ",
      "                ",
      "                ",
      "                "
    ],
    [
      "aabaaaaaaaabaaaa",
      " 9b     a##b    ",
      "  bkk   a##b    ",
      "  b     a##baaaa",
      "  b  $  aaab   C",
      "  b       $b   C",
      " y x      x a  C",
      "yF xx    xx FyXX",
      "   x      x     ",
      "                ",
      "                ",
      "                ",
      "                ",
      "                ",
      "                ",
      "                "
    ],
    [
      "aabaaaaaaaabaaaa",
      "%%b%%%%%% ^b%%%%",
      "%%b%%%%%%  b%%%%",
      "%%b%%%%%%  b%%%%",
      "%%b%%%%%%%%b%%%%",
      "%%b%%%%%%%%b%%%%",
      "%a x%%%%%%x a%%%",
      "aF xxxxxxxx Daay",
      "   xxxxxxxx     ",
      "                ",
      "                ",
      "                ",
      "                ",
      "                ",
      "                ",
      "                "
    ]
  ]
}