{
  "name": "multi_oasiscondo_7_ground",
  "refpalette": "deceasedcraft:multi_oasiscondo_7/multi_oasiscondo_7_ground_palette",
  "xsize": 16,
  "zsize": 16,
  "slices": [
    [
      "aabccccccccccccc",
      "aabccccccccccccc",
      "aabccccccccccaaa",
      "aabccccccccccaaa",
      "aabccccccccccaaa",
      "adedccccccdedccc",
      "dddddddddddddddd",
      "ffffffffffffffff",
      "ffffffffffffgggg",
      "ffhffffffffggggg",
      "ffffffffffgggggg",
      "ffffffffffgggggg",
      "ffffffffffgggggg",
      "ffhffffffffggggg",
      "ffffffffffffgggg",
      "ffffffffffffffff"
    ],
    [
      "i               ",
      "                ",
      "                ",
      "               j",
      "  k        k    ",
      " lel  mn  lel op",
      "llqllrssrllqllll",
      "                ",
      "            tttt",
      "  u        twwww",
      "  x       twyyyy",
      "  x       twyyyy",
      "  x       twyyyy",
      "  u        twwww",
      "            tttt",
      "                "
    ],
    [
      "                ",
      "                ",
      "                ",
      "                ",
      "  A        A    ",
      " lel  BC  lel   ",
      "ll llr  rll llll",
      "                ",
      "                ",
      "  D             ",
      "                ",
      "                ",
      "                ",
      "  D             ",
      "                ",
      "                "
    ],
    [
      "                ",
      "                ",
      "                ",
      "                ",
      "  E        F    ",
      " lel  II  lel   ",
      "ll llrJJrll llll",
      "                ",
      "                ",
      "  K             ",
      "                ",
      "                ",
      "                ",
      "  K             ",
      "                ",
      "                "
    ],
    [
      "                ",
      "                ",
      "                ",
      "                ",
      "                ",
      " lel      lel   ",
      "ll llrrrrll llll",
      "                ",
      "                ",
      "  K             ",
      "                ",
      "                ",
      "                ",
      "  K             ",
      "                ",
      "                "
    ],
    [
      "                ",
      "                ",
      "                ",
      "                ",
      "                ",
      " lel      lel   ",
      "ll llllllll llll",
      "                ",
      "                ",
      "  L             ",
      "                ",
      "                ",
      "                ",
      "  L             ",
      "                ",
      "                "
    ]
  ]
}