{
  "name": "multi_oasiscondo_7_floor2",
  "refpalette": "deceasedcraft:multi_oasiscondo_7/multi_oasiscondo_7_floor2_palette",
  "xsize": 16,
  "zsize": 16,
  "slices": [
    [
      "aabacaaaaaabacaa",
      "ddbddddddddbdddd",
      "ddbddddddddbdddd",
      "ddbddddddddbdddd",
      "ddbddddddddbdddd",
      "ddbddddddddbdddd",
      "de edddddde eddd",
      "                ",
      "                ",
      "                ",
      "                ",
      "                ",
      "                ",
      "                ",
      "                ",
      "                "
    ],
    [
      "aabafaaaaaabafaa",
      "ghbi  jklmnbo   ",
      " pbqqqq  mrbqqqq",
      " hbst u   wbx  u",
      "yAb B CaaaabD  C",
      " EbF  I    bJK I",
      "LM aNOCP Qa MRSC",
      "aT TaMaaMaT Taaa",
      "                ",
      "                ",
      "                ",
      "                ",
      "                ",
      "                ",
      "                ",
      "                "
    ],
    [
      "aabaUaaaaaabaUaa",
      " Vb      m bW   ",
      "  bqqqq  m bqqqq",
      " Xb Y Z    bx  Z",
      " !b0  Caaaab   C",
      " 1b   23 34b   2",
      "56 aN7C   M a89C",
      "a# TM$$$$aT TM$$",
      "                ",
      "                ",
      "                ",
      "                ",
      "                ",
      "                ",
      "                ",
      "                "
    ],
    [
      "aaba%aaaaaaba%aa",
      " ^b&      *b&   ",
      " ^bqqqq   (bqqqq",
      " ^b   )   +b-  )",
      " [b   Caaaab   C",
      " ]b   )   {b   )",
      " M a} C|  a a  C",
      "aT #a$$$$a# Ta$$",
      "                ",
      "                ",
      "                ",
      "                ",
      "                ",
      "                ",
      "                ",
      "                "
    ],
    [
      "aabaaaaaaaabaaaa",
      " ;b       :b    ",
      " gbqqqq  '<bqqqq",
      " >b   C   ,b   C",
      "  b . Caaaab . C",
      " ?b   C///`b   C",
      " a M  C///a M  C",
      "MT Ta$$$$a# #a$$",
      "                ",
      "                ",
      "                ",
      "                ",
      "                ",
      "                ",
      "                ",
      "                "
    ],
    [
      "aabaaaaaaaabaaaa",
      "\u0370\u0370b\u0370\u0370\u0370\u0370\u0370\u0370\u0370\u0370b\u0370\u0370\u0370\u0370",
      "\u0370\u0370b\u0370\u0370\u0370\u0370\u0370\u0370\u0370\u0370b\u0370\u0370\u0370\u0370",
      "\u0370\u0370b\u0370\u0370\u0370\u0370\u0370\u0370\u0370\u0370b\u0370\u0370\u0370\u0370",
      "\u0370\u0370b\u0370\u0370\u0370\u0370\u0370\u0370\u0370\u0370b\u0370\u0370\u0370\u0370",
      "\u0370\u0370b\u0370\u0370\u0370\u0370   \u0370b\u0370\u0370\u0370\u0370",
      "\u0370a a\u0370\u0370\u0370  \u0371M M\u0370\u0370\u0370",
      "a# TaaMaaMT TaMa",
      "                ",
      "                ",
      "                ",
      "                ",
      "                ",
      "                ",
      "                ",
      "                "
    ]
  ]
}