{
  "name": "multi_oasiscondo_7_floor11",
  "refpalette": "deceasedcraft:multi_oasiscondo_7/multi_oasiscondo_7_floor11_palette",
  "xsize": 16,
  "zsize": 16,
  "slices": [
    [
      "aabccddddccbccdd",
      "eebffffffffbffff",
      "eebffffffffbffgh",
      "iebffffffffbffj ",
      "iebffffffffbffj ",
      "eebffffffffbffkl",
      "fm mffffffm mfff",
      "                ",
      "                ",
      "                ",
      "                ",
      "                ",
      "                ",
      "                ",
      "                ",
      "                "
    ],
    [
      "  bccnopnccbccno",
      "qrbstuwxy  bA   ",
      "B bsCD EF IbA   ",
      " JbsKDL M IbA   ",
      " qbNOD PQRSbA   ",
      "qqbN DTUVWXbA   ",
      "YZ c0DE T c 1   ",
      "ZZ 2c1cc112 2ccc",
      "3Z              ",
      "                ",
      "                ",
      "                ",
      "                ",
      "                ",
      "                ",
      "                "
    ],
    [
      "  bccn45nccbccn4",
      "  b6 tN78t bA   ",
      "9 b6 #    $bA   ",
      "  b% ^    $bA   ",
      " qb6 & *   bA   ",
      "  b% ( )   bA   ",
      " Z c+-    c c   ",
      "ZZ [c]]]]c[ 2c]]",
      "{Z              ",
      "                ",
      "                ",
      "                ",
      "                ",
      "                ",
      "                ",
      "                "
    ],
    [
      "  bccnnnnccbccnn",
      "  b6 tttt  b}   ",
      "q b6       b    ",
      "  b6       b    ",
      "  b%   |   b;   ",
      "  b%       b:   ",
      " Z c      c 1   ",
      "ZZ 2c]]]]1[ 21]]",
      " Z              ",
      "                ",
      "                ",
      "                ",
      "                ",
      "                ",
      "                ",
      "                "
    ],
    [
      "  bccccccccbcccc",
      "  b'  t    b    ",
      "q b        b    ",
      "  b<       b    ",
      "  b>       b    ",
      "  b>       b    ",
      " Z c      1 c   ",
      "ZZ 2c]]]]c[ [c]]",
      " Z              ",
      "                ",
      "                ",
      "                ",
      "                ",
      "                ",
      "                ",
      "                "
    ],
    [
      ",,bccccccccbcccc",
      ",,b........b....",
      ",,b........b....",
      ",,b........b....",
      ",,b........b....",
      ",,b........b....",
      "ZZ 1......c c...",
      "ZZ 2ccc1cc2 2ccc",
      "ZZ              ",
      "                ",
      "                ",
      "                ",
      "                ",
      "                ",
      "                ",
      "                "
    ]
  ]
}