{
  "name": "multi_oasiscondo_7_floor4",
  "refpalette": "deceasedcraft:multi_oasiscondo_7/multi_oasiscondo_7_floor4_palette",
  "xsize": 16,
  "zsize": 16,
  "slices": [
    [
      "aabacaaaaaabacaa",
      "ddbddddddddbdddd",
      "ddbddddddddbdddd",
      "ddbddddddddbdddd",
      "ddbddddddddbdddd",
      "ddbddddddddbdddd",
      "de edddddde eddd",
      "                ",
      "                ",
      "                ",
      "                ",
      "                ",
      "                ",
      "                ",
      "                ",
      "                "
    ],
    [
      "aabafaaaaaabafaa",
      " gbh   iajkbh   ",
      " lbmnopqa rbssss",
      " gbtuwxwa ybA  B",
      " !bCD E aFabIJ K",
      " ibLM     NbA  O",
      "Pa QRS    Q TUVK",
      "aW QQXXXXQQ WaTT",
      "   QYYYYYYQ     ",
      "                ",
      "                ",
      "                ",
      "                ",
      "                ",
      "                ",
      "                "
    ],
    [
      "aabaZaaaaaabaZaa",
      " 0b1   2a 3b    ",
      "  b4 5 6a7 bssss",
      " 8b9 #$%a  b^  &",
      " *b(    a)ab   K",
      " 2b+      Nb   -",
      "[T Q]    {Q aU K",
      "aW QQ    QQ }T||",
      "   Q;;;;;;Q     ",
      "                ",
      "                ",
      "                ",
      "                ",
      "                ",
      "                ",
      "                "
    ],
    [
      "aaba:aaaaaaba:aa",
      " 'b<   'a>,b<   ",
      " 'b4   .a  bssss",
      " 'b   ?/a  b   u",
      " `b     a\u0370ab   K",
      " \u0371b       \u0372b   u",
      " a Q      Q a\u0373 K",
      "aW QQ\u0374 \u0374 QQ }a||",
      "   Q      Q     ",
      "                ",
      "                ",
      "                ",
      "                ",
      "                ",
      "                ",
      "                "
    ],
    [
      "aabaaaaaaaabaaaa",
      "  b    \u0375a\u0376\u0376b    ",
      "  b4   \u0377a\u0376\u0376bssss",
      "  b   \u037a\u037ba\u0376\u0376b   K",
      "  b  \u037c  aaab ! K",
      "  b       \u037db   K",
      " a Q      Q a  K",
      "a} QQ\u037e\u037e\u037e\u037eQQ Wa||",
      "   Q      Q     ",
      "                ",
      "                ",
      "                ",
      "                ",
      "                ",
      "                ",
      "                "
    ],
    [
      "aabaaaaaaaabaaaa",
      "\u037f\u037fb\u037f\u037f\u037f\u037f\u037f\u037f \u0384b\u037f\u037f\u037f\u037f",
      "\u037f\u037fb\u037f\u037f\u037f\u037f\u037f\u037f  b\u037f\u037f\u037f\u037f",
      "\u037f\u037fb\u037f\u037f\u037f\u037f\u037f\u037f  b\u037f\u037f\u037f\u037f",
      "\u037f\u037fb\u037f\u037f\u037f\u037f\u037f\u037f\u037f\u037fb\u037f\u037f\u037f\u037f",
      "\u037f\u037fb\u037f\u037f\u037f\u037f\u037f\u037f\u037f\u037fb\u037f\u037f\u037f\u037f",
      "\u037fa Q\u037f\u037f\u037f\u037f\u037f\u037fQ a\u037f\u037f\u037f",
      "aW QQQQQQQQ }aTa",
      "   QQQQQQQQ     ",
      "                ",
      "                ",
      "                ",
      "                ",
      "                ",
      "                ",
      "                "
    ]
  ]
}