{
  "name": "multi_oasiscondo_7_floor1",
  "refpalette": "deceasedcraft:multi_oasiscondo_7/multi_oasiscondo_7_floor1_palette",
  "xsize": 16,
  "zsize": 16,
  "slices": [
    [
      "                ",
      "                ",
      "                ",
      "                ",
      "                ",
      " aba      aba   ",
      "aa aaaaaaaa aaaa",
      "                ",
      "                ",
      "                ",
      "                ",
      "                ",
      "                ",
      "                ",
      "                ",
      "                "
    ],
    [
      "                ",
      "     c  c       ",
      "                ",
      "      c  c      ",
      "                ",
      " aba      aba   ",
      "aa aaaaaaaa aaaa",
      "                ",
      "                ",
      "                ",
      "                ",
      "                ",
      "                ",
      "                ",
      "                ",
      "                "
    ],
    [
      "                ",
      "    cdccdc      ",
      "                ",
      "    c dccd      ",
      "                ",
      " aba      aba   ",
      "aa aaaaaaaa aaaa",
      "                ",
      "                ",
      "                ",
      "                ",
      "                ",
      "                ",
      "                ",
      "                ",
      "                "
    ],
    [
      "                ",
      "    dddddd      ",
      "                ",
      "    dcdddd      ",
      "                ",
      " aba      aba   ",
      "aa aaaaaaaa aaaa",
      "                ",
      "                ",
      "                ",
      "                ",
      "                ",
      "                ",
      "                ",
      "                ",
      "                "
    ],
    [
      "    eeeeee      ",
      "   edddddde     ",
      "   effffffe     ",
      "   edddddde     ",
      "    eeeeee      ",
      " aba      aba   ",
      "aa aaaaaaaa aaaa",
      "                ",
      "                ",
      "                ",
      "                ",
      "                ",
      "                ",
      "                ",
      "                ",
      "                "
    ],
    [
      "gggggggggggggggg",
      "gggghhhhhhgggggg",
      "gggghhhhhhgggggg",
      "gggghhhhhhgggggg",
      "gggggggggggggggg",
      "gibiggggggibiggg",
      "iiiiiiiiiiiiiiii",
      "iiiiiiiiiiiiiiii",
      "iiiiiiiiiiiiiiii",
      "                ",
      "                ",
      "                ",
      "                ",
      "                ",
      "                ",
      "                "
    ]
  ]
}