{
  "name": "multi_oasiscondo_7_base1",
  "refpalette": "deceasedcraft:multi_oasiscondo_7/multi_oasiscondo_7_base1_palette",
  "xsize": 16,
  "zsize": 16,
  "slices": [
    [
      "HaaaHHHHHHHaaaaa",
      "HHHHHHHHHHHHHHHH",
      "HHHHHHHHHHHHHHHH",
      "HHHHHHHHHHHHHHHH",
      "HHaHHHHHHHHaHHHH",
      "HHbHHHHHHHHbHHHH",
      "HHaHHHHHHHHaHHHH",
      "HHaHHHHHHHHaHHHH",
      "HHaHHHHHHHHaHHHH",
      "HHaHHHHHHHHaHHHH",
      "HHaHHHHHHHHaHHHH",
      "HHaHHHHHHHHaHHHH",
      "HHHHHHHHHHHHHHHH",
      "HHHHHHHHHHHHHHHH",
      "HHHHHHHHHHHHHHHH",
      "vvvvvvvvvvvvvvvv"
    ],
    [
      "                ",
      "                ",
      "                ",
      "                ",
      "cdecdcdcdcdecdcd",
      "  b        b    ",
      "  e        e    ",
      "fgefgfgfgfgefgfg",
      "cdecdcdcdcdecdcd",
      "  e   h    e    ",
      "  e        e    ",
      "fgefgfgfgfgefgfg",
      "                ",
      "                ",
      "                ",
      "vvvvvvvvvvvvvvvv"
    ],
    [
      "                ",
      "                ",
      "                ",
      "                ",
      "                ",
      "  b        b    ",
      "                ",
      "                ",
      "                ",
      "                ",
      "                ",
      "                ",
      "                ",
      "                ",
      "                ",
      "vvvvvvvvvvvvvvvv"
    ],
    [
      "                ",
      "                ",
      "                ",
      "                ",
      "                ",
      "  b        b    ",
      "                ",
      "                ",
      "                ",
      "                ",
      "                ",
      "                ",
      "                ",
      "                ",
      "                ",
      "vvvvvvvvvvvvvvvv"
    ],
    [
      "                ",
      "                ",
      "                ",
      "                ",
      "                ",
      "  b        b    ",
      "                ",
      "                ",
      "                ",
      "                ",
      "                ",
      "                ",
      "                ",
      "                ",
      "                ",
      "vvvvvvvvvvvvvvvv"
    ],
    [
      "iijiiiiiiiijiiii",
      "iijiiiiiiiijiiii",
      "iijiiiiiiiijiiii",
      "iijiiiiiiiijiiii",
      "iijiiiiiiiijiiii",
      "jjkjjjjjjjjkjjjj",
      "iijiiiiiiiijiiii",
      "iijiiiiiiiijiiii",
      "iijiiiiiiiijiiii",
      "iijiiiiiiiijiiii",
      "iijiiiiiiiijiiii",
      "iijiiiiiiiijiiii",
      "iijiiiiiiiijiiii",
      "iijiiiiiiiijiiii",
      "iijiiiiiiiijiiii",
      "vvvvvvvvvvvvvvvv"
    ]
  ]
}