{
  "name": "multi_oasiscondo_7_top",
  "refpalette": "deceasedcraft:multi_oasiscondo_7/multi_oasiscondo_7_top_palette",
  "xsize": 16,
  "zsize": 16,
  "slices": [
    [
      "aabcddddddcccccd",
      "aabeeeeeeeeceeee",
      "aabeeeeeeeeceeee",
      "aabeeeeeeeeceeee",
      "aabeeeeeeeeeeeee",
      "aabeeeeeeeebeeee",
      "ef feeeeeeeeeeee",
      "                ",
      "                ",
      "                ",
      "                ",
      "                ",
      "                ",
      "                ",
      "                ",
      "                "
    ],
    [
      "ggbchiiiiicccccj",
      "kkbl      mcnnn ",
      "kkbl  op  mc    ",
      "kkbl  qpr mc    ",
      "kkbl  op   s    ",
      "kkbt      ubwxw ",
      "yA ttttttttttttt",
      "AA              ",
      "BA              ",
      "                ",
      "                ",
      "                ",
      "                ",
      "                ",
      "                ",
      "                "
    ],
    [
      "  bc CD EFcccccI",
      "  bJ      KcLLL ",
      " MbJ   N   c    ",
      "  bO   P   c    ",
      "Q b   J    R    ",
      "  bt       b    ",
      " A ttttttttttttt",
      "AA              ",
      "SA              ",
      "                ",
      "                ",
      "                ",
      "                ",
      "                ",
      "                ",
      "                "
    ],
    [
      "  bcTTTTTTcccccU",
      "  bV      WcX Y ",
      "  bZ      Wc    ",
      "  bV      Wc    ",
      "  bZ       0    ",
      "  bt       b    ",
      " A ttttttttttttt",
      "AA              ",
      " A              ",
      "                ",
      "                ",
      "                ",
      "                ",
      "                ",
      "                ",
      "                "
    ],
    [
      "  bccccccccccccc",
      "  bO       c    ",
      "  b        c    ",
      "  b1       c    ",
      "  bO       c    ",
      "  bt       b    ",
      " A ttttttttttttt",
      "AA              ",
      " A              ",
      "                ",
      "                ",
      "                ",
      "                ",
      "                ",
      "                ",
      "                "
    ],
    [
      "  bccccccccccccc",
      "  b22222222c2222",
      "  b22222222c2222",
      "  b22222222c2222",
      "  b22222222c2222",
      "  bt       b    ",
      " A ttttttttttttt",
      "AA              ",
      " A              ",
      "                ",
      "                ",
      "                ",
      "                ",
      "                ",
      "                ",
      "                "
    ],
    [
      "  bccddddddddddd",
      "  beeeeeeeeeeeee",
      "  beeeeeeeeeeeee",
      "  beeeeeeeeeeeee",
      "  beeeeeeeeeeeee",
      "  bt3333333b3333",
      " A ttttttttttttt",
      "AA              ",
      " A              ",
      "                ",
      "                ",
      "                ",
      "                ",
      "                ",
      "                ",
      "                "
    ],
    [
      "  bcc4    444   ",
      "  b5      666   ",
      "  b5 787        ",
      "  b 5 9   5   # ",
      "  b5 $  7%7^ &#*",
      "  bt5   5( b &)*",
      " A ttttttttttttt",
      "AA              ",
      " A              ",
      "                ",
      "                ",
      "                ",
      "                ",
      "                ",
      "                ",
      "                "
    ],
    [
      "  bcc4    444   ",
      "  b+            ",
      "  b- [][        ",
      "  b-            ",
      "  b{    } }     ",
      "  bt     ( b    ",
      " A ttttttttttttt",
      "AA              ",
      " A              ",
      "                ",
      "                ",
      "                ",
      "                ",
      "                ",
      "                ",
      "                "
    ],
    [
      "  bcc44444444444",
      "  b             ",
      "  b             ",
      "  b             ",
      "  b     [][     ",
      "  bt       b    ",
      " A ttttttttttttt",
      "AA              ",
      " A              ",
      "                ",
      "                ",
      "                ",
      "                ",
      "                ",
      "                ",
      "                "
    ],
    [
      "  bccccccccccccc",
      "  b             ",
      "  b             ",
      "  b             ",
      "  b             ",
      "  bt       b    ",
      " A ttttttttttttt",
      "AA              ",
      " A              ",
      "                ",
      "                ",
      "                ",
      "                ",
      "                ",
      "                ",
      "                "
    ],
    [
      "22bccccccccccccc",
      "22b2222222222222",
      "22b2222222222222",
      "22b2222222222222",
      "22b2222222222222",
      "22bt2222222b2222",
      "AA ttttttttttttt",
      "AA              ",
      "AA              ",
      "                ",
      "                ",
      "                ",
      "                ",
      "                ",
      "                ",
      "                "
    ],
    [
      "dddddddddddccccc",
      "dddddddddddddddd",
      "dddddddddddddddd",
      "dddddddddddddddd",
      "dddddddddddddddd",
      "||||||||||||||||",
      "ef feeeeeeeeeeee",
      "                ",
      "                ",
      "                ",
      "                ",
      "                ",
      "                ",
      "                ",
      "                ",
      "                "
    ],
    [
      ";;  ;;;    ccccc",
      "  :        :    ",
      "''''''''''''''''",
      "  <        <    ",
      "  >        >    ",
      ",,,,,,,,,,,,,,,,",
      "                ",
      "                ",
      "                ",
      "                ",
      "                ",
      "                ",
      "                ",
      "                ",
      "                ",
      "                "
    ],
    [
      " .  ? .    cc'cc",
      "             '  ",
      "             '  ",
      "                ",
      "                ",
      ",,,,,,,,,,,,,,,,",
      "                ",
      "                ",
      "                ",
      "                ",
      "                ",
      "                ",
      "                ",
      "                ",
      "                ",
      "                "
    ],
    [
      "/`  \u0370/`    ccccc",
      "                ",
      "                ",
      "                ",
      "                ",
      "                ",
      "                ",
      "                ",
      "                ",
      "                ",
      "                ",
      "                ",
      "                ",
      "                ",
      "                ",
      "                "
    ],
    [
      "\u0371\u0372  \u0373\u0371\u0372         ",
      "                ",
      "                ",
      "                ",
      "                ",
      "                ",
      "                ",
      "                ",
      "                ",
      "                ",
      "                ",
      "                ",
      "                ",
      "                ",
      "                ",
      "                "
    ],
    [
      "\u0374\u0375  \u0376\u0374\u0375         ",
      "                ",
      "                ",
      "                ",
      "                ",
      "                ",
      "                ",
      "                ",
      "                ",
      "                ",
      "                ",
      "                ",
      "                ",
      "                ",
      "                ",
      "                "
    ],
    [
      "\u0377\u037a  \u037b\u0377\u037a         ",
      "                ",
      "                ",
      "                ",
      "                ",
      "                ",
      "                ",
      "                ",
      "                ",
      "                ",
      "                ",
      "                ",
      "                ",
      "                ",
      "                ",
      "                "
    ]
  ]
}