{
  "name": "multi_oasiscondo_7_floor9",
  "refpalette": "deceasedcraft:multi_oasiscondo_7/multi_oasiscondo_7_floor9_palette",
  "xsize": 16,
  "zsize": 16,
  "slices": [
    [
      "aaaaaaaaaaabccdd",
      "eeefeefeefebgggg",
      "fffeeffffeebghhh",
      "efeffeffeeebghhh",
      "eeefeeeefeebghhh",
      "eebeeeeeeeebghhh",
      "ggggggggggi iggg",
      "                ",
      "                ",
      "                ",
      "                ",
      "                ",
      "                ",
      "                ",
      "                ",
      "                "
    ],
    [
      "           bccjj",
      "k l k     mbn   ",
      "    o    pmbn qr",
      "         smbn   ",
      "kto l    umbn   ",
      "  bk k    mbw xy",
      "AAAAAAAAAAB wwww",
      "AAAAAAAAABB     ",
      "CCCCCCCCCCB     ",
      "                ",
      "                ",
      "                ",
      "                ",
      "                ",
      "                ",
      "                "
    ],
    [
      "           bccjj",
      "          kbD   ",
      "          kbE   ",
      "          kbF   ",
      " m        kb    ",
      "  bl      kbw   ",
      "          B wwww",
      "         BB     ",
      "IIIIIIIIIIB     ",
      "                ",
      "                ",
      "                ",
      "                ",
      "                ",
      "                ",
      "                "
    ],
    [
      "           bccjj",
      "          kbJ   ",
      "          kbJ   ",
      "          kbJ   ",
      " k         b    ",
      "  b       kbw   ",
      "          B wwww",
      "         BB     ",
      "          B     ",
      "                ",
      "                ",
      "                ",
      "                ",
      "                ",
      "                ",
      "                "
    ],
    [
      "           bcccc",
      "           b    ",
      "          kb    ",
      "           bJ   ",
      " o         bJ   ",
      "  b        bw   ",
      "          B wwww",
      "KKKKKKKKKBB     ",
      "          B     ",
      "                ",
      "                ",
      "                ",
      "                ",
      "                ",
      "                ",
      "                "
    ],
    [
      "LLLLLLLLLLLbcccc",
      "LLLLLLLLLLLbLLLL",
      "LLLLLLLLLLLbLLLL",
      "LLLLLLLLLLLbLLLL",
      "LLLLLLLLLLLbLLLL",
      "LLbLLLLLLLLbwLLL",
      "BBBBBBBBBBB wwww",
      "BBBBBBBBBBB     ",
      "BBBBBBBBBBB     ",
      "                ",
      "                ",
      "                ",
      "                ",
      "                ",
      "                ",
      "                "
    ]
  ]
}