{
  "name": "multi_oasiscondo_7_floor8",
  "refpalette": "deceasedcraft:multi_oasiscondo_7/multi_oasiscondo_7_floor8_palette",
  "xsize": 16,
  "zsize": 16,
  "slices": [
    [
      "aabaaaaaacaaaaaa",
      "ddbddddddddddddd",
      "ddbddddddddddddd",
      "ddbddddddddddddd",
      "ddbddddddddddddd",
      "ddbddddddddddddd",
      "de edddddddddddd",
      "                ",
      "                ",
      "                ",
      "                ",
      "                ",
      "                ",
      "                ",
      "                ",
      "                "
    ],
    [
      "aabaaaaaafaaaaaa",
      "ghbijklmm nopoqr",
      " sbtu w         ",
      " hbxy lAAAB C D ",
      " EbF  lIJKL MN O",
      " PbQ ul     RR S",
      "Ta aUVlUWWX    O",
      "aY Za0aaaa00aaaa",
      "                ",
      "                ",
      "                ",
      "                ",
      "                ",
      "                ",
      "                ",
      "                "
    ],
    [
      "aabaaaaaa1aaaaaa",
      " 2bi 3l   45 678",
      "  bt  9         ",
      " #bxy l  $      ",
      "  bF  l   %  2 O",
      " ^bi& l        *",
      " 0 a()l + -    O",
      "aZ Ya[[[[[[][[[[",
      "                ",
      "                ",
      "                ",
      "                ",
      "                ",
      "                ",
      "                ",
      "                "
    ],
    [
      "aabaaaaaa{aaaaaa",
      " }bAAAl   4|||;:",
      " }b'  <         ",
      " }b   l         ",
      " >b   l        O",
      " !b,  l        .",
      " ? a  l        O",
      "0Y Za[[[[[[][[[[",
      "                ",
      "                ",
      "                ",
      "                ",
      "                ",
      "                ",
      "                ",
      "                "
    ],
    [
      "aabaaaaaaaaaaaaa",
      " /b`\u0370 l   \u0371\u0372\u0373  \u0374",
      "  b   l         ",
      " \u0375b \u0376 l         ",
      "  b   l \u0376   \u0377  O",
      "  b   l        O",
      " 0 0\u037a l        O",
      "aY Za[[[[[[][[[[",
      "                ",
      "                ",
      "                ",
      "                ",
      "                ",
      "                ",
      "                ",
      "                "
    ],
    [
      "aabaaaaaaaaaaaaa",
      "\u037b\u037bb\u037b\u037b\u037b\u037b\u037b\u037b\u037b\u037b\u037b\u037b\u037b\u037b\u037b",
      "\u037b\u037bb\u037b\u037b\u037b\u037b\u037b\u037b\u037b\u037b\u037b\u037b\u037b\u037b\u037b",
      "\u037b\u037bb\u037b\u037b\u037b\u037b\u037b\u037b\u037b\u037b\u037b\u037b\u037b\u037b\u037b",
      "\u037b\u037bb\u037b\u037b\u037b\u037b\u037b\u037b\u037b\u037b\u037b\u037b\u037b\u037b\u037b",
      "\u037b\u037bb\u037b\u037b\u037b\u037b\u037b\u037b\u037b\u037b\u037b\u037b\u037b\u037b\u037b",
      "\u037b0 a\u037b\u037b\u037b\u037b\u037b\u037b\u037b\u037b\u037b\u037b\u037b\u037b",
      "aZ Yaa0a0aaa0aa0",
      "                ",
      "                ",
      "                ",
      "                ",
      "                ",
      "                ",
      "                ",
      "                "
    ]
  ]
}