{
  "name": "multi_oasiscondo_7_base4",
  "refpalette": "deceasedcraft:multi_oasiscondo_7/multi_oasiscondo_7_base4_palette",
  "xsize": 16,
  "zsize": 16,
  "slices": [
    [
      "aaaaaaaaaaaaaaaa",
      "aaaaaaaaaaaaaaaa",
      "aaaaaaaaaaaaaaaa",
      "aaaaaaaaaaaaaaaa",
      "aaaaaaaaaaaaaaaa",
      "aaaaaaaaaaaaaaaa",
      "aaaaaaaaaaaaaaaa",
      "aaaaaaaaaaaaaaaa",
      "aaaaaaaaaaaaaaaa",
      "aaaaaaaaaaaaaaaa",
      "aaaaaaaaaaaaaaaa",
      "aaaaaaaaaaaaaaaa",
      "aaaaaaaaaaaaaaaa",
      "aaaaaaaaaaaaaaaa",
      "aaaaaaaaaaaaaaaa",
      "vvvvvvvvvvvvvvvv"
    ],
    [
      "aaaaaaaaaaaaaaaa",
      "aaaaaaaaaaaaaaaa",
      "aaaaaaaaaaaaaaaa",
      "aaaaaaaaaaaaaaaa",
      "aaaaaaaaaaaaaaaa",
      "babaaaaaaaabaaaa",
      "aaaaaaaaaaaaaaaa",
      "aaaaaaaaaaaaaaaa",
      "aaaaaaaaaaaaaaaa",
      "aaaaaaaaaaaaaaaa",
      "aaaaaaaaaaaaaaaa",
      "aaaaaaaaaaaaaaaa",
      "aaaaaaaaaaaaaaaa",
      "aaaaaaaaaaaaaaaa",
      "aaaaaaaaaaaaaaaa",
      "vvvvvvvvvvvvvvvv"
    ],
    [
      "avccccHHHHHccccc",
      "avccccHHHHHHHHHH",
      "avccccHHHHHHHHHH",
      "avccccHHHHHHHHHH",
      "avccccHHHHHcHHHH",
      "bvbcccHHHHHbHHHH",
      "avccccHHHHHcHHHH",
      "avccccHHHHHcHHHH",
      "dvcccHHHHHHcHHHH",
      "dvcccHHHHHHcHHHH",
      "ccccHHHHHHHcHHHH",
      "cccHHHHHHHHcHHHH",
      "HHHHHHHHHHHHHHHH",
      "HHHHHHHHHHHHHHHH",
      "HHHHHHHHHHHHHHHH",
      "vvvvvvvvvvvvvvvv"
    ],
    [
      "av ef           ",
      "av ef           ",
      "av ef           ",
      "av ef           ",
      "av ef    ghighgh",
      "bvbef      b    ",
      "dv ef      i    ",
      "dv ej    kliklkl",
      "cv m     ghighgh",
      "nv o       i    ",
      "pp         i    ",
      "         kliklkl",
      "                ",
      "                ",
      "                ",
      "vvvvvvvvvvvvvvvv"
    ],
    [
      "av              ",
      "av              ",
      "dv              ",
      "dv              ",
      "dv              ",
      "bvb        b    ",
      "nv              ",
      "pv              ",
      " v              ",
      " v              ",
      "                ",
      "                ",
      "                ",
      "                ",
      "                ",
      "vvvvvvvvvvvvvvvv"
    ],
    [
      "dv              ",
      "dv              ",
      "cv              ",
      "nv              ",
      "pv              ",
      "bvb        b    ",
      " v              ",
      " v              ",
      " v              ",
      " v              ",
      "                ",
      "                ",
      "                ",
      "                ",
      "                ",
      "vvvvvvvvvvvvvvvv"
    ]
  ]
}