{
  "name": "multi_oasiscondo_7_floor6",
  "refpalette": "deceasedcraft:multi_oasiscondo_7/multi_oasiscondo_7_floor6_palette",
  "xsize": 16,
  "zsize": 16,
  "slices": [
    [
      "aabaaaccaaaaaaaa",
      "ddbddddddddddddd",
      "ddbddddddddddddd",
      "ddbddddddddddddd",
      "ddbddddddddddddd",
      "ddbddddddddddddd",
      "de edddddddddddd",
      "                ",
      "                ",
      "                ",
      "                ",
      "                ",
      "                ",
      "                ",
      "                ",
      "                "
    ],
    [
      "aabaaafgaaaaaaaa",
      " hbi            ",
      " jbi  kl  mnnnnn",
      " obp  qrs tuwxyA",
      "BtbC  DEs hF I J",
      "KLbMB NE  jO   P",
      "Qa R!BSTUVWX Y J",
      "aZ 01RaRaaRaaaRR",
      "                ",
      "                ",
      "                ",
      "                ",
      "                ",
      "                ",
      "                ",
      "                "
    ],
    [
      "aabaaa23aaaaaaaa",
      " Bb             ",
      " 4b5      6nnnnn",
      "  b       7uwxy8",
      " 7b9   #  $% I J",
      "^&b B      %   *",
      "BR 1(   ) +%   J",
      "a- 0R[[[[[[][[[[",
      "                ",
      "                ",
      "                ",
      "                ",
      "                ",
      "                ",
      "                ",
      "                "
    ],
    [
      "aabaaa{{aaaaaaaa",
      " }b|            ",
      " ;b|      6nnnnn",
      " ;b       :%   '",
      " ;b       ;%   J",
      "^!b       :%   <",
      " a R(     ;%   J",
      "R- Za[[[[[[][[[[",
      "                ",
      "                ",
      "                ",
      "                ",
      "                ",
      "                ",
      "                ",
      "                "
    ],
    [
      "aabaaaaaaaaaaaaa",
      "  b             ",
      " >b       ,nnnnn",
      " .b       ?%   J",
      " /b| `  \u0370  % ` J",
      "\u0371\u0372b|      ?%   J",
      "BR a(B    $%   J",
      "aZ ZR[[[[[[][[[[",
      "                ",
      "                ",
      "                ",
      "                ",
      "                ",
      "                ",
      "                ",
      "                "
    ],
    [
      "aabaaaaaaaaaaaaa",
      "\u0373\u0373b\u0373\u0373\u0373\u0373\u0373\u0373\u0373\u0373\u0373\u0373\u0373\u0373\u0373",
      "\u0373\u0373b\u0373\u0373\u0373\u0373\u0373\u0373\u0373\u0373\u0373\u0373\u0373\u0373\u0373",
      "\u0373\u0373b\u0373\u0373\u0373\u0373\u0373\u0373\u0373\u0373\u0373\u0373\u0373\u0373\u0373",
      "\u0373\u0373b\u0373\u0373\u0373\u0373\u0373\u0373\u0373\u0373\u0373\u0373\u0373\u0373\u0373",
      "\u0373\u0373b\u0373\u0373\u0373\u0373\u0373\u0373\u0373\u0373\u0373\u0373\u0373\u0373\u0373",
      "\u0373a R\u0373\u0373\u0373\u0373\u0373\u0373\u0373\u0373\u0373\u0373\u0373\u0373",
      "aZ -aRaRRaaaaRaa",
      "                ",
      "                ",
      "                ",
      "                ",
      "                ",
      "                ",
      "                ",
      "                "
    ]
  ]
}