{
  "name": "multi_oasiscondo_7_floor7",
  "refpalette": "deceasedcraft:multi_oasiscondo_7/multi_oasiscondo_7_floor7_palette",
  "xsize": 16,
  "zsize": 16,
  "slices": [
    [
      "aabaaaccaaaaaaaa",
      "ddbddddddddddddd",
      "ddbddddddddddddd",
      "ddbddddddddddddd",
      "ddbddddddddddddd",
      "ddbddddddddddddd",
      "de edddddddddddd",
      "                ",
      "                ",
      "                ",
      "                ",
      "                ",
      "                ",
      "                ",
      "                ",
      "                "
    ],
    [
      "aabaaafgaaaaaaaa",
      "hibj            ",
      " kbl  mn   ooooo",
      " ibp qrst uwx  y",
      " AbB qCsD EF   I",
      " Jbp qCsK LM N O",
      " P aQ RsSTUVWXYI",
      "aZ ZaaP0aaPaPaaP",
      "                ",
      "                ",
      "                ",
      "                ",
      "                ",
      "                ",
      "                ",
      "                "
    ],
    [
      "aabaaa12aaaaaaaa",
      " 3b4            ",
      " 5b   67   ooooo",
      " 8b9  #$  %^   &",
      " *b   ($  )^   I",
      " Jb+   $   ^   -",
      " P P   $[ ]^   I",
      "PZ ZP{{{{{{}{{{{",
      "                ",
      "                ",
      "                ",
      "                ",
      "                ",
      "                ",
      "                ",
      "                "
    ],
    [
      "aabaaa||aaaaaaaa",
      " ;b:            ",
      " 'b<  67   ooooo",
      " 'b>   $   ^   ,",
      " .b>   $   ^   I",
      " ?b>   $   ^   /",
      " a a   $  !^   I",
      "aZ ZP{{{{{ }{{{{",
      "         {      ",
      "                ",
      "                ",
      "                ",
      "                ",
      "                ",
      "                ",
      "                "
    ],
    [
      "aabaaaaaaaaaaaaa",
      "  b             ",
      "  b   `\u0370   ooooo",
      "  b\u0371   \u0372   ^   I",
      "  b\u0373 \u0374 \u0372 \u0375 ^ \u0375 I",
      " \u0376b\u0377   \u0372   ^   I",
      " a a   \u0372  T^   I",
      "a\u037a \u037aa{{{{{{}{{{{",
      "                ",
      "                ",
      "                ",
      "                ",
      "                ",
      "                ",
      "                ",
      "                "
    ],
    [
      "aabaaaaaaaaaaaaa",
      "\u037b\u037bb\u037b\u037b\u037b\u037b\u037b\u037b\u037b\u037b\u037b\u037b\u037b\u037b\u037b",
      "\u037b\u037bb\u037b\u037b\u037b\u037b\u037b\u037b\u037b\u037b\u037b\u037b\u037b\u037b\u037b",
      "\u037b\u037bb\u037b\u037b\u037b\u037b\u037b\u037b\u037b\u037b\u037b\u037b\u037b\u037b\u037b",
      "\u037b\u037bb\u037b\u037b\u037b\u037b\u037b\u037b\u037b\u037b\u037b\u037b\u037b\u037b\u037b",
      "\u037b\u037bb\u037b\u037b\u037b\u037b\u037b\u037b\u037b\u037b\u037b\u037b\u037b\u037b\u037b",
      "\u037ba a\u037b\u037b\u037b\u037b\u037b\u037b\u037b\u037b\u037b\u037b\u037b\u037b",
      "aZ ZaaaaP00\u037cPPaa",
      "                ",
      "                ",
      "                ",
      "                ",
      "                ",
      "                ",
      "                ",
      "                "
    ]
  ]
}