{
  "name": "multi_oasiscondo_7_base3",
  "refpalette": "deceasedcraft:multi_oasiscondo_7/multi_oasiscondo_7_base3_palette",
  "xsize": 16,
  "zsize": 16,
  "slices": [
    [
      "av              ",
      "bv              ",
      " v              ",
      " v              ",
      " v              ",
      "cvc        c    ",
      " v              ",
      " v              ",
      " v              ",
      " v              ",
      " d              ",
      " d              ",
      " d              ",
      " d              ",
      " d              ",
      "vvvvvvvvvvvvvvvv"
    ],
    [
      " v              ",
      " v              ",
      " v              ",
      " v              ",
      " v              ",
      "cvc        c    ",
      " v              ",
      " v              ",
      " v              ",
      " v              ",
      " v              ",
      " v              ",
      " v              ",
      " v              ",
      " v              ",
      "vvvvvvvvvvvvvvvv"
    ],
    [
      " v              ",
      " v              ",
      " v              ",
      " v              ",
      " v              ",
      "cvc        c    ",
      " v              ",
      " v              ",
      " v              ",
      " v              ",
      " v              ",
      " v              ",
      " v              ",
      " v              ",
      " v              ",
      "vvvvvvvvvvvvvvvv"
    ],
    [
      " v              ",
      " v              ",
      " v              ",
      " v              ",
      " v              ",
      "cvc        c    ",
      " v              ",
      " v              ",
      " v              ",
      " v              ",
      " v              ",
      " v              ",
      " v              ",
      " v              ",
      " v              ",
      "vvvvvvvvvvvvvvvv"
    ],
    [
      " v              ",
      " v              ",
      " v              ",
      " v              ",
      " v              ",
      "cvc        c    ",
      " v              ",
      " v              ",
      " v              ",
      " v              ",
      " v              ",
      " v              ",
      " v              ",
      " v              ",
      " v              ",
      "vvvvvvvvvvvvvvvv"
    ],
    [
      "eveffffffffeffff",
      "eveffffffffeffff",
      "eveffffffffeffff",
      "eveffffffffeffff",
      "eveffffffffeffff",
      "gegeeeeeeeegeeee",
      "eveffffffffeffff",
      "eveffffffffeffff",
      "eveffffffffeffff",
      "eveffffffffeffff",
      "eveffffffffeffff",
      "eveffffffffeffff",
      "eveffffffffeffff",
      "eveffffffffeffff",
      "eveffffffffeffff",
      "vvvvvvvvvvvvvvvv"
    ]
  ]
}