{
  "name": "multi_oasiscondo_7_floor3",
  "refpalette": "deceasedcraft:multi_oasiscondo_7/multi_oasiscondo_7_floor3_palette",
  "xsize": 16,
  "zsize": 16,
  "slices": [
    [
      "aabacaaaaaabacaa",
      "ddbddddddddbdddd",
      "ddbddddddddbdddd",
      "ddbddddddddbdddd",
      "ddbddddddddbdddd",
      "ddbddddddddbdddd",
      "de edddddde eddd",
      "                ",
      "                ",
      "                ",
      "                ",
      "                ",
      "                ",
      "                ",
      "                ",
      "                "
    ],
    [
      "aabafaaaaaabafaa",
      " gbh   ijklbh   ",
      " mbnnnn op b!qnn",
      " gbr  s   tbu  w",
      " xbyA BaaaabCD B",
      " EbrFIJK LMbN  O",
      "Pa QR BSTUQ aVWB",
      "aX YZZQaZQX XaQa",
      "                ",
      "                ",
      "                ",
      "                ",
      "                ",
      "                ",
      "                ",
      "                "
    ],
    [
      "aaba0aaaaaaba0aa",
      " 1b2     34b5   ",
      "  bnnnn    bqqqn",
      " 6b7  8    bu  9",
      "  b   BaaaabCD B",
      " #b$  %   ^bN  &",
      "*Q aR B   a a()B",
      "aY YQ++++QX XQ++",
      "                ",
      "                ",
      "                ",
      "                ",
      "                ",
      "                ",
      "                ",
      "                "
    ],
    [
      "aaba-aaaaaaba-aa",
      " [b]   {}|;b]   ",
      " [bnnnn    bqnnn",
      " [b   :    b'  :",
      " <b   Baaaab   B",
      " >b   :   ,b   :",
      " Q a. B?  a a  B",
      "aX Ya++++aY Ya++",
      "                ",
      "                ",
      "                ",
      "                ",
      "                ",
      "                ",
      "                ",
      "                "
    ],
    [
      "aabaaaaaaaabaaaa",
      " /b    {!{ b    ",
      " `bnnnn {\u0370 bnnnn",
      "  b   B    b   B",
      "  b \u0371 Baaaab \u0371 B",
      " \u0372b   B\u0373\u0373\u0373\u0374b   B",
      " a Q  B\u0373\u0373\u0373Q a  B",
      "aX Xa++++aY Xa++",
      "                ",
      "                ",
      "                ",
      "                ",
      "                ",
      "                ",
      "                ",
      "                "
    ],
    [
      "aabaaaaaaaabaaaa",
      "\u0375\u0375b\u0375\u0375\u0375\u0375\u0375\u0375\u0375\u0375b\u0375\u0375\u0375\u0375",
      "\u0375\u0375b\u0375\u0375\u0375\u0375\u0375\u0375\u0375\u0375b\u0375\u0375\u0375\u0375",
      "\u0375\u0375b\u0375\u0375\u0375\u0375\u0375\u0375\u0375\u0375b\u0375\u0375\u0375\u0375",
      "\u0375\u0375b\u0375\u0375\u0375\u0375\u0375\u0375\u0375\u0375b\u0375\u0375\u0375\u0375",
      "\u0375\u0375b\u0375\u0375\u0375\u0375   \u0375b\u0375\u0375\u0375\u0375",
      "\u0375a a\u0375\u0375\u0375  \u0376Q a\u0375\u0375\u0375",
      "aX YaaQaaQX Yaaa",
      "                ",
      "                ",
      "                ",
      "                ",
      "                ",
      "                ",
      "                ",
      "                "
    ]
  ]
}