{
  "name": "multi_alienresearch_1_base4",
  "refpalette": "deceasedcraft:multi_alienresearch_1/multi_alienresearch_1_base4_palette",
  "xsize": 16,
  "zsize": 16,
  "slices": [
    [
      "vaaab           ",
      "vaab            ",
      "vaab            ",
      "vaab            ",
      "vab             ",
      "vab             ",
      "vac             ",
      "vac             ",
      "vacd            ",
      "vacd          e ",
      "vafd            ",
      "vacd            ",
      "vacd            ",
      "vac             ",
      "vac             ",
      "vab             "
    ],
    [
      "vaaab           ",
      "vaaab           ",
      "vaab            ",
      "vaab            ",
      "vaab            ",
      "vaab            ",
      "vab             ",
      "vab             ",
      "vac             ",
      "vac           g ",
      "vacd            ",
      "vac             ",
      "vac             ",
      "vab             ",
      "vab             ",
      "vaab            "
    ],
    [
      "vaaab           ",
      "vaaab           ",
      "vaaab           ",
      "vaab            ",
      "vaab            ",
      "vaab            ",
      "vaab            ",
      "vab             ",
      "vab             ",
      "vac           h ",
      "vacd            ",
      "vac             ",
      "vab             ",
      "vab             ",
      "vaab            ",
      "vaab            "
    ],
    [
      "vaaaab          ",
      "vaaab           ",
      "vaaab           ",
      "vaaab           ",
      "vaab            ",
      "vaab            ",
      "vaab            ",
      "vaab            ",
      "vaab            ",
      "vaac          h ",
      "vaacd           ",
      "vaac            ",
      "vaab            ",
      "vaab            ",
      "vaab            ",
      "vaab            "
    ],
    [
      "vaaaab          ",
      "vaaaab          ",
      "vaaab           ",
      "vaaab           ",
      "vaaab           ",
      "vaaab           ",
      "vaab            ",
      "vaab            ",
      "vaab            ",
      "vaac          h ",
      "vaacd           ",
      "vaac            ",
      "vaab            ",
      "vaab            ",
      "vaab            ",
      "vaaab           "
    ],
    [
      "vaaaaab         ",
      "vaaaab          ",
      "vaaaab          ",
      "vaaaab          ",
      "vaaab           ",
      "vaaab           ",
      "vaaab           ",
      "vaaab           ",
      "vaaab           ",
      "vaaac         h ",
      "vaaacd          ",
      "vaaac           ",
      "vaaab           ",
      "vaaab           ",
      "vaaab           ",
      "vaaab           "
    ]
  ]
}