{
  "name": "multi_alienresearch_1_base6",
  "refpalette": "deceasedcraft:multi_alienresearch_1/multi_alienresearch_1_base6_palette",
  "xsize": 16,
  "zsize": 16,
  "slices": [
    [
      "vaaab           ",
      "vaab            ",
      "vaab            ",
      "vaab            ",
      "vab             ",
      "vab             ",
      "vac             ",
      "vac             ",
      "vacd            ",
      "vacd            ",
      "vaed            ",
      "vacd            ",
      "vacd            ",
      "vac             ",
      "vac             ",
      "vab             "
    ],
    [
      "vaaab           ",
      "vaab            ",
      "vaab            ",
      "vaab            ",
      "vab             ",
      "vac             ",
      "vacd            ",
      "vacd            ",
      "vc              ",
      "vc              ",
      "vc              ",
      "vc              ",
      "vc              ",
      "vacd            ",
      "vacd            ",
      "vac             "
    ],
    [
      "vaab            ",
      "vaab            ",
      "vaab            ",
      "vab             ",
      "vac             ",
      "vacd            ",
      "vacd            ",
      "vc              ",
      "vc              ",
      "vc              ",
      "vc              ",
      "vc              ",
      "vc              ",
      "vc              ",
      "vacd            ",
      "vacd            "
    ],
    [
      "vaab            ",
      "vaab            ",
      "vab             ",
      "vab             ",
      "vac             ",
      "vacd           f",
      "vc             g",
      "vc            g ",
      "vc            gh",
      "vc            fi",
      "vc              ",
      "vc            fi",
      "vc            gh",
      "vc            g ",
      "vc             g",
      "vacd           f"
    ],
    [
      "vaab            ",
      "vaab           g",
      "vab           fg",
      "vac           ji",
      "vacd         gi ",
      "vc           ghi",
      "vc           ghk",
      "vc          ghkl",
      "vc          ghk ",
      "vc          fiii",
      "vc          j   ",
      "vc          fiii",
      "vc          ghk ",
      "vc          ghkl",
      "vc           ghk",
      "vc           ghi"
    ],
    [
      "vaac         mgh",
      "vaac         mhk",
      "vac         mnkk",
      "vac         mop@",
      "vacd       mhk@p",
      "vc         mhk @",
      "vcq       mghk  ",
      "vc        mhk   ",
      "vcr       mhk   ",
      "vcs       mo@@@@",
      "vc        mnpppp",
      "vc        mo@@@@",
      "vc        mhk   ",
      "vcs       mhk   ",
      "vct       mghk  ",
      "vc         mhk @"
    ]
  ]
}