{
  "name": "multi_alienresearch_1_base3",
  "refpalette": "deceasedcraft:multi_alienresearch_1/multi_alienresearch_1_base3_palette",
  "xsize": 16,
  "zsize": 16,
  "slices": [
    [
      "vaaaaabcdddddeef",
      "vaaaaabcdddddef ",
      "vaaaabcdddddef  ",
      "vaaaabcdddddef  ",
      "vaaaabcddddef   ",
      "vggggbcddddef  h",
      "vgiiecddddeef  j",
      "vgiiecddddef  h ",
      "vgiiecddddef  k ",
      "vgiiecddddef  k ",
      "vgiilcddddeemmk ",
      "vgiiecddddef  k ",
      "vgiiecddddef  k ",
      "vgiiecddddef  j ",
      "vgiiecddddeef  h",
      "vgiigbcddddef  j"
    ],
    [
      "vaaaaaab     n  ",
      "vaaaaab      n  ",
      "vaaaaabo    n   ",
      "vaaaaabo   pn   ",
      "vaaaabo    n    ",
      "vggggbq   rn    ",
      "vg  sb    t     ",
      "vg   e    n     ",
      "vg    u   n     ",
      "vg   e   wn   x ",
      "vyq Aec  Bn     ",
      "vg   e   Cn     ",
      "vg    D   n     ",
      "vg   e    n     ",
      "vg  sb    t     ",
      "vg  gbq   En    "
    ],
    [
      "vaaaaaaab    n  ",
      "vaaaaaab     n  ",
      "vaaaaaab    n   ",
      "vaaaaab!    n   ",
      "vaaaaab    n    ",
      "vgggggb    n    ",
      "vg   Fb   t     ",
      "vg   e    n     ",
      "vg    I   n     ",
      "vg   e    n     ",
      "vy   ec  Jn     ",
      "vg   e    n     ",
      "vg    K   n     ",
      "vg   e    n     ",
      "vg   !b   t     ",
      "vg  ggb    n    "
    ],
    [
      "vaaaaaaab    n  ",
      "vaaaaaaab    n  ",
      "vaaaaaaab   n   ",
      "vaaaaaab    n   ",
      "vaaaaaab   n    ",
      "vgggggb    n    ",
      "vg   Lb   t     ",
      "vg   ee   n     ",
      "vg   fe   n     ",
      "vg   ee   n     ",
      "vy   eec  n     ",
      "vg   ee   n     ",
      "vg   fe   n     ",
      "vg   ee   n     ",
      "vg   Lb   t     ",
      "vg  ggb    n    "
    ],
    [
      "vaaaaaaaab   n  ",
      "vaaaaaaaab   n  ",
      "vaaaaaaab   n   ",
      "vaaaaaaab   n   ",
      "vaaaaaaab  n    ",
      "vggggggb   n    ",
      "vg    gb  t     ",
      "vg   Mgb  n     ",
      "vg   Mgb  n     ",
      "vg   Mge  n     ",
      "vy   Mgec n     ",
      "vg   Mge  n     ",
      "vg   Mgb  n     ",
      "vg   Mgb  n     ",
      "vg    gb  t     ",
      "vg  gggb   n    "
    ],
    [
      "vaaaaaaaaab  N  ",
      "vaaaaaaaaab  N  ",
      "vaaaaaaaab  N   ",
      "vaaaaaaaab  N   ",
      "vaaaaaaab  N    ",
      "vggggggab  N    ",
      "vg    gab n     ",
      "vg    gab N     ",
      "vg    gab N     ",
      "vg    gae N     ",
      "vy   OgaecN     ",
      "vg    gae N     ",
      "vg    gab N     ",
      "vg    gab N     ",
      "vg    gab n     ",
      "vg  gggab  N    "
    ]
  ]
}