{
  "name": "multi_alienresearch_1_base9",
  "refpalette": "deceasedcraft:multi_alienresearch_1/multi_alienresearch_1_base9_palette",
  "xsize": 16,
  "zsize": 16,
  "slices": [
    [
      "vaaaaaaaaaaaaaaa",
      "vaaaaaaaaaaaaaaa",
      "vaaaaaaaaaaaaaaa",
      "vaaaaaaaaaaaaaaa",
      "vaaaaaaaaaaaaaaa",
      "vaaaaaaaaaaaaaaa",
      "vaaaaaaaaaaaaaaa",
      "vaaaaaaaaaaaaaaa",
      "vaaaaaaaaaaaaaaa",
      "vaaaaaaaaaaaaaaa",
      "vaaaaaaaaaaaaaaa",
      "vaaaaaaaaaaaaaaa",
      "vaaaaaaaaaaaaaaa",
      "vaaaaaaaaaaaaaaa",
      "vaaaaaaaaaaaaaaa",
      "vaaaaaaaaaaaaaaa"
    ],
    [
      "vaaaaaaaaaaaaaaa",
      "vaaaaaaaaaaaaaaa",
      "vaaaaaaaaaaaaaaa",
      "vaaaaaaaaaaaaaaa",
      "vaaaaaaaaaaaaaaa",
      "vaaaaaaaaaaaaaaa",
      "vaaaaaaaaaaaaaaa",
      "vaaaaaaaaaaaaaaa",
      "vaaaaaaaaaaaaaaa",
      "vaaaaaaaaaaaaaaa",
      "vaaaaaaaaaaaaaaa",
      "vaaaaaaaaaaaaaaa",
      "vaaaaaaaaaaaaaaa",
      "vaaaaaaaaaaaaaaa",
      "vaaaaaaaaaaaaaaa",
      "vaaaaaaaaaaaaaaa"
    ],
    [
      "vaaaaaaaaaaaaaaa",
      "vaaaaaaaaaaaaaaa",
      "vaaaaaaaaaaaaaaa",
      "vaaaaaaaaaaaaaaa",
      "vaaaaaaaaaaaaaab",
      "vaaaaaaaaaaaaaab",
      "vaaaaaaaaaaaaabb",
      "vaaaaaaaaaaaaabb",
      "vaaaaaaaaaaaaabb",
      "vaaaaaaaaaaaaacc",
      "vaaaaaaaaaaaaacc",
      "vaaaaaaaaaaaaacc",
      "vaaaaaaaaaaaaabb",
      "vaaaaaaaaaaaaabb",
      "vaaaaaaaaaaaaabb",
      "vaaaaaaaaaaaaaab"
    ],
    [
      "vaaaaaaaaaaaaaaa",
      "vaaaaaaaaaaaaaab",
      "vaaaaaaaaaaaaabb",
      "vaaaaaaaaaaaaabb",
      "vaaaaaaaaaaaabb ",
      "vaaaaaaaaaaaabb ",
      "vaaaaaaaaaaaab  ",
      "vaaaaaaaaaaabb  ",
      "vaaaaaaaaaaabb  ",
      "vaaaaaaaaaaacc  ",
      "vaaaaaaaaaaaccdd",
      "vaaaaaaaaaaacc  ",
      "vaaaaaaaaaaabb  ",
      "vaaaaaaaaaaabb  ",
      "vaaaaaaaaaaaab  ",
      "vaaaaaaaaaaaabb "
    ],
    [
      "vaaaaaaaaaaaaabc",
      "vaaaaaaaaaaaabb ",
      "vaaaaaaaaaaaab  ",
      "vaaaaaaaaaaabb  ",
      "vaaaaaaaaaaab   ",
      "vaaaaaaaaaabb   ",
      "vaaaaaaaaaabb   ",
      "vaaaaaaaaaab    ",
      "vaaaaaaaaaab    ",
      "vaaaaaaaaaac    ",
      "vaaaaaaaaaacdded",
      "vaaaaaaaaaac    ",
      "vaaaaaaaaaab    ",
      "vaaaaaaaaaab    ",
      "vaaaaaaaaaabb   ",
      "vaaaaaaaaaabb   "
    ],
    [
      "vaaaaaaaaaaaab  ",
      "vaaaaaaaaaaab   ",
      "vaaaaaaaaaaab   ",
      "vaaaaaaaaaab    ",
      "vaaaaaaaaaab    ",
      "vaaaaaaaaab     ",
      "vaaaaaaaaab     ",
      "vaaaaaaaaab     ",
      "vaaaaaaaaab     ",
      "vaaaaaaaaac     ",
      "vaaaaaaaaacd   e",
      "vaaaaaaaaac     ",
      "vaaaaaaaaab     ",
      "vaaaaaaaaab     ",
      "vaaaaaaaaab     ",
      "vaaaaaaaaab     "
    ]
  ]
}