{
  "name": "multi_alienresearch_1_base7",
  "refpalette": "deceasedcraft:multi_alienresearch_1/multi_alienresearch_1_base7_palette",
  "xsize": 16,
  "zsize": 16,
  "slices": [
    [
      "vaaaaabc        ",
      "vaaaaabc        ",
      "vaaaabc         ",
      "vaaaabc         ",
      "vaaaabc         ",
      "vaaaabc         ",
      "vaaabc          ",
      "vaaabc          ",
      "vaaabc          ",
      "vaaadc          ",
      "vaaaecf         ",
      "vaaadc          ",
      "vaaabc          ",
      "vaaabc          ",
      "vaaabc          ",
      "vaaaabc         "
    ],
    [
      "vaaaaab         ",
      "vaaaab          ",
      "vaaaab          ",
      "vaaaab          ",
      "vaaab           ",
      "vaaab           ",
      "vaaab           ",
      "vaaab           ",
      "vaaab           ",
      "vaaad           ",
      "vaaadcgcf       ",
      "vaaad           ",
      "vaaab           ",
      "vaaab           ",
      "vaaab           ",
      "vaaab           "
    ],
    [
      "vaaaab          ",
      "vaaaab          ",
      "vaaab           ",
      "vaaab           ",
      "vaaab           ",
      "vaaab           ",
      "vaab            ",
      "vaab            ",
      "vaab            ",
      "vaad            ",
      "vaadc   gcf     ",
      "vaad            ",
      "vaab            ",
      "vaab            ",
      "vaab            ",
      "vaaab           "
    ],
    [
      "vaaaab          ",
      "vaaab           ",
      "vaaab           ",
      "vaaab           ",
      "vaab            ",
      "vaab            ",
      "vaab            ",
      "vaab            ",
      "vaab            ",
      "vaad            ",
      "vaadc     gcf   ",
      "vaad            ",
      "vaab            ",
      "vaab            ",
      "vaab            ",
      "vaab            "
    ],
    [
      "vaaab           ",
      "vaaab           ",
      "vaaab           ",
      "vaab            ",
      "vaab            ",
      "vaab            ",
      "vaab            ",
      "vab             ",
      "vab             ",
      "vad             ",
      "vadc        gcf ",
      "vad             ",
      "vab             ",
      "vab             ",
      "vaab            ",
      "vaab            "
    ],
    [
      "vaaab           ",
      "vaaab           ",
      "vaab            ",
      "vaab            ",
      "vaab            ",
      "vaab            ",
      "vab             ",
      "vab             ",
      "vad             ",
      "vad             ",
      "vadc          gc",
      "vad             ",
      "vad             ",
      "vab             ",
      "vab             ",
      "vaab            "
    ]
  ]
}