{
  "name": "multi_alienresearch_1_ground",
  "refpalette": "deceasedcraft:multi_alienresearch_1/multi_alienresearch_1_ground_palette",
  "xsize": 16,
  "zsize": 16,
  "slices": [
    [
      "zzazaaaazabcdvdv",
      "zzzazaaaazbcvddd",
      "zzzaaaazazbcadva",
      "zzaaaaaaaabcdddd",
      "zzzzaaaaazbcdvzv",
      "zazaazazaabavdvd",
      "zzzaaaazazzdavvv",
      "zzazaazaaaazddvd",
      "zzzaaaaaazaavdvv",
      "zzzaaaadaaaadvvv",
      "zzaazaaazazadvzv",
      "zzzzaaaaaazadzdz",
      "zzaaaazaaaadavee",
      "zzzaaaaaaaazvvef",
      "zzzaaaaazazaddez",
      "zzzazaadaaaadveg"
    ],
    [
      "   h      i     ",
      " h              ",
      " h        i     ",
      "          i     ",
      "          i     ",
      "          ij    ",
      "          ik    ",
      "   h       k    ",
      "h h        k    ",
      "       lmnok    ",
      "        h  k    ",
      "   h       k h  ",
      "      hmo  k  pp",
      "           k  pq",
      "           k  ph",
      "h      mrnlk  p "
    ],
    [
      "                ",
      "                ",
      "                ",
      "                ",
      "                ",
      "           j    ",
      "           k    ",
      "           k    ",
      "           k    ",
      "           k    ",
      "           k    ",
      "           k    ",
      "           k  st",
      "           k  uq",
      "           k  u ",
      "           k  sw"
    ],
    [
      "                ",
      "                ",
      "                ",
      "                ",
      "                ",
      "           j    ",
      "           k    ",
      "           k    ",
      "           k    ",
      "           k    ",
      "                ",
      "           k    ",
      "           k    ",
      "           k  sq",
      "           k  u ",
      "           k  s "
    ],
    [
      "                ",
      "                ",
      "                ",
      "                ",
      "                ",
      "                ",
      "           x    ",
      "           x    ",
      "           x    ",
      "           x    ",
      "           x    ",
      "                ",
      "           x    ",
      "           x   q",
      "           x    ",
      "           x    "
    ],
    [
      "                ",
      "                ",
      "                ",
      "                ",
      "                ",
      "           y    ",
      "                ",
      "                ",
      "                ",
      "                ",
      "                ",
      "                ",
      "                ",
      "               A",
      "               B",
      "               B"
    ]
  ]
}