{
  "name": "multi_alienresearch_1_base2",
  "refpalette": "deceasedcraft:multi_alienresearch_1/multi_alienresearch_1_base2_palette",
  "xsize": 16,
  "zsize": 16,
  "slices": [
    [
      "vaaaaaaaaaabbc  ",
      "vaaaaaaaaaab c  ",
      "vaaaaaaaaabbc   ",
      "vaaaaaaaaab c   ",
      "vaaaaaaaabbc    ",
      "vddddddaab c    ",
      "vdeeeedaabc     ",
      "vdeeeedaabc     ",
      "vdeeeedaabc     ",
      "vdeeeedaffc     ",
      "vdeeeedaffc    g",
      "vdeeeedaffc     ",
      "vdeeeedaabc     ",
      "vdeeeedaabc     ",
      "vdeeeedaabc     ",
      "vdeedddaab c    "
    ],
    [
      "vaaaaaaaaaaaab  ",
      "vaaaaaaaaaaab   ",
      "vaaaaaaaaaaab   ",
      "vaaaaaaaaaab    ",
      "vaaaaaaaaaab    ",
      "vaaaaaaaaab     ",
      "vaaaaaaaaab     ",
      "vaaaaaaaaab     ",
      "vaaaaaaaaab     ",
      "vaaaaaaaaaf     ",
      "vaaaaaaaaafc gcc",
      "vaaaaaaaaaf     ",
      "vaaaaaaaaab     ",
      "vaaaaaaaaab     ",
      "vaaaaaaaaab     ",
      "vaaaaaaaaab     "
    ],
    [
      "vaaaaaaaaaaaaabf",
      "vaaaaaaaaaaaabb ",
      "vaaaaaaaaaaaab  ",
      "vaaaaaaaaaaabb  ",
      "vaaaaaaaaaaab   ",
      "vaaaaaaaaaabb   ",
      "vaaaaaaaaaabb   ",
      "vaaaaaaaaaab    ",
      "vaaaaaaaaaab    ",
      "vaaaaaaaaaaf    ",
      "vaaaaaaaaaafcch ",
      "vaaaaaaaaaaf    ",
      "vaaaaaaaaaab    ",
      "vaaaaaaaaaab    ",
      "vaaaaaaaaaabb   ",
      "vaaaaaaaaaabb   "
    ],
    [
      "vaaaaaaaaaaaaaaa",
      "vaaaaaaaaaaaaaab",
      "vaaaaaaaaaaaaabb",
      "vaaaaaaaaaaaaabb",
      "vaaaaaaaaaaaabb ",
      "vaaaaaaaaaaaabb ",
      "vaaaaaaaaaaaab  ",
      "vaaaaaaaaaaabb  ",
      "vaaaaaaaaaaabb  ",
      "vaaaaaaaaaaaff  ",
      "vaaaaaaaaaaaffcc",
      "vaaaaaaaaaaaff  ",
      "vaaaaaaaaaaabb  ",
      "vaaaaaaaaaaabb  ",
      "vaaaaaaaaaaaab  ",
      "vaaaaaaaaaaaabb "
    ],
    [
      "vaaaaaaaaaaaaaaa",
      "vaaaaaaaaaaaaaaa",
      "vaaaaaaaaaaaaaaa",
      "vaaaaaaaaaaaaaaa",
      "vaaaaaaaaaaaaaab",
      "vaaaaaaaaaaaaaab",
      "vaaaaaaaaaaaaabb",
      "vaaaaaaaaaaaaabb",
      "vaaaaaaaaaaaaabb",
      "vaaaaaaaaaaaaaff",
      "vaaaaaaaaaaaaaff",
      "vaaaaaaaaaaaaaff",
      "vaaaaaaaaaaaaabb",
      "vaaaaaaaaaaaaabb",
      "vaaaaaaaaaaaaabb",
      "vaaaaaaaaaaaaaab"
    ],
    [
      "vaaaaaaaaaaaaaaa",
      "vaaaaaaaaaaaaaaa",
      "vaaaaaaaaaaaaaaa",
      "vaaaaaaaaaaaaaaa",
      "vaaaaaaaaaaaaaaa",
      "vaaaaaaaaaaaaaaa",
      "vaaaaaaaaaaaaaaa",
      "vaaaaaaaaaaaaaaa",
      "vaaaaaaaaaaaaaaa",
      "vaaaaaaaaaaaaaaa",
      "vaaaaaaaaaaaaaaa",
      "vaaaaaaaaaaaaaaa",
      "vaaaaaaaaaaaaaaa",
      "vaaaaaaaaaaaaaaa",
      "vaaaaaaaaaaaaaaa",
      "vaaaaaaaaaaaaaaa"
    ]
  ]
}