{
  "name": "multi_alienresearch_1_base8",
  "refpalette": "deceasedcraft:multi_alienresearch_1/multi_alienresearch_1_base8_palette",
  "xsize": 16,
  "zsize": 16,
  "slices": [
    [
      "vaaaaaaaaaabb   ",
      "vaaaaaaaaaab    ",
      "vaaaaaaaaabb    ",
      "vaaaaaaaaab     ",
      "vaaaaaaaabb    c",
      "vaaaaaaaab     c",
      "vaaaaaaaab    cc",
      "vaaaaaaaab    cd",
      "vaaaaaaaab    cd",
      "vaaaaaaaee    cd",
      "vaaaaaaaeef   cd",
      "vaaaaaaaee    cd",
      "vaaaaaaaab    cd",
      "vaaaaaaaab    cd",
      "vaaaaaaaab    cc",
      "vaaaaaaaab     c"
    ],
    [
      "vaaaaaaaaab     ",
      "vaaaaaaaaab     ",
      "vaaaaaaaab      ",
      "vaaaaaaaab      ",
      "vaaaaaaab      c",
      "vaaaaaaab      c",
      "vaaaaaaab     cc",
      "vaaaaaaab     c ",
      "vaaaaaaab     c ",
      "vaaaaaaae     c ",
      "vaaaaaaaef    c ",
      "vaaaaaaae     c ",
      "vaaaaaaab     c ",
      "vaaaaaaab     c ",
      "vaaaaaaab     cc",
      "vaaaaaaab      c"
    ],
    [
      "vaaaaaaaab      ",
      "vaaaaaaaab      ",
      "vaaaaaaab       ",
      "vaaaaaaab       ",
      "vaaaaaaab       ",
      "vaaaaaab        ",
      "vaaaaaab        ",
      "vaaaaaab        ",
      "vaaaaaab        ",
      "vaaaaaae        ",
      "vaaaaaaef       ",
      "vaaaaaae        ",
      "vaaaaaab        ",
      "vaaaaaab        ",
      "vaaaaaab        ",
      "vaaaaaab        "
    ],
    [
      "vaaaaaaab       ",
      "vaaaaaaab       ",
      "vaaaaaaab       ",
      "vaaaaaab        ",
      "vaaaaaab        ",
      "vaaaaab         ",
      "vaaaaab         ",
      "vaaaaab         ",
      "vaaaaab         ",
      "vaaaaae         ",
      "vaaaaaef        ",
      "vaaaaae         ",
      "vaaaaab         ",
      "vaaaaab         ",
      "vaaaaab         ",
      "vaaaaab         "
    ],
    [
      "vaaaaaaab       ",
      "vaaaaaab        ",
      "vaaaaaab        ",
      "vaaaaab         ",
      "vaaaaab         ",
      "vaaaaab         ",
      "vaaaaab         ",
      "vaaaab          ",
      "vaaaab          ",
      "vaaaae          ",
      "vaaaaef         ",
      "vaaaae          ",
      "vaaaab          ",
      "vaaaab          ",
      "vaaaaab         ",
      "vaaaaab         "
    ],
    [
      "vaaaaaab        ",
      "vaaaaab         ",
      "vaaaaab         ",
      "vaaaaab         ",
      "vaaaab          ",
      "vaaaab          ",
      "vaaaab          ",
      "vaaaab          ",
      "vaaaab          ",
      "vaaaae          ",
      "vaaaaef         ",
      "vaaaae          ",
      "vaaaab          ",
      "vaaaab          ",
      "vaaaab          ",
      "vaaaab          "
    ]
  ]
}