{
  "name": "multi_alienresearch_1_base5",
  "refpalette": "deceasedcraft:multi_alienresearch_1/multi_alienresearch_1_base5_palette",
  "xsize": 16,
  "zsize": 16,
  "slices": [
    [
      "vaabc       deef",
      "vaabc      deegh",
      "vabc       defh ",
      "vabc      deefh ",
      "vaic      degh h",
      "vb        defh  ",
      "vbj      deefh  ",
      "vb       degh   ",
      "vbj      defh   ",
      "vbj      eefh   ",
      "vb       eeghhhh",
      "vbj      eefh   ",
      "vbk      defh   ",
      "vb       degh   ",
      "vbj      deefh  ",
      "vb        defh  "
    ],
    [
      "vaab           l",
      "vaab          lm",
      "vab          lmm",
      "vab          lmm",
      "vabc        lmmm",
      "vb          lmmn",
      "vbj         lmmn",
      "vb         lmmnn",
      "vbo        lmmnn",
      "vbp        lmmnn",
      "vb        qlllrs",
      "vb         lmmnn",
      "vb         lmmnn",
      "vbo        lmmnn",
      "vbt         lmmn",
      "vb          lmmn"
    ],
    [
      "vaau            ",
      "vaau            ",
      "vau             ",
      "vab             ",
      "vabc            ",
      "vb              ",
      "vb              ",
      "vb              ",
      "vb              ",
      "vb              ",
      "vb             w",
      "vb              ",
      "vb              ",
      "vb              ",
      "vb              ",
      "vb              "
    ],
    [
      "vaau            ",
      "vaau            ",
      "vau             ",
      "vau             ",
      "vab             ",
      "vabc            ",
      "vb              ",
      "vb              ",
      "vb              ",
      "vb              ",
      "vb              ",
      "vb              ",
      "vb              ",
      "vb              ",
      "vb              ",
      "vabc            "
    ],
    [
      "vaau            ",
      "vaau            ",
      "vaau            ",
      "vau             ",
      "vab             ",
      "vabc            ",
      "vabc            ",
      "vb              ",
      "vb              ",
      "vb            x ",
      "vb              ",
      "vb              ",
      "vb              ",
      "vb              ",
      "vabc            ",
      "vabc            "
    ],
    [
      "vaaau           ",
      "vaau            ",
      "vaau            ",
      "vaau            ",
      "vau             ",
      "vab             ",
      "vabc            ",
      "vabc            ",
      "vb              ",
      "vb           yAB",
      "vb              ",
      "vb              ",
      "vb              ",
      "vabc            ",
      "vabc            ",
      "vab             "
    ]
  ]
}