{
  "name": "multi_oasiscondo_3_base4",
  "refpalette": "deceasedcraft:multi_oasiscondo_3/multi_oasiscondo_3_base4_palette",
  "xsize": 16,
  "zsize": 16,
  "slices": [
    [
      "vaaaaaaaaaaaaaaa",
      "vaaaaaaaaaaaaaaa",
      "vaaaaaaaaaaaaaaa",
      "vaaaaaaaaaaaaaaa",
      "vaaaaaaaaaaaaaaa",
      "vaaaaaaaaaaaaaaa",
      "vaaaaaaaaaaaaaaa",
      "vaaaaaaaaaaaaaaa",
      "vaaaaaaaaaaaaaaa",
      "vaaaaaaaaaaaaaaa",
      "vaaaaaaaaaaaaaaa",
      "vaaaaaaaaaaaaaaa",
      "vaaaaaaaaaaaaaaa",
      "vaaaaaaaaaaaaaaa",
      "vaaaaaaaaaaaaaaa",
      "vvvvvvvvvvvvvvvv"
    ],
    [
      "vaaaaaaaaaaaaaaa",
      "vaaaaaaaaaaaaaaa",
      "vaaaaaaaaaaaaaaa",
      "vaaaaaaaaaaaaaaa",
      "vaaaaaaaaaaaaaaa",
      "vaaaaaaaaabaaaaa",
      "vaaaaaaaaaaaaaaa",
      "vaaaaaaaaaaaaaaa",
      "vaaaaaaaaaaaaaaa",
      "vaaaaaaaaaaaaaaa",
      "vaaaaaaaaaaaaaaa",
      "vaaaaaaaaaaaaaaa",
      "vaaaaaaaaaaaaaaa",
      "vaaaaaaaaaaaaaaa",
      "vaaaaaaaaaaaaaaa",
      "vvvvvvvvvvvvvvvv"
    ],
    [
      "vHHHHHHHcvaaaaaa",
      "vHHHHHHHcvaaaaaa",
      "vHHHHHHHcvaaaaaa",
      "vHHHHHHHcvaaaaaa",
      "vHHHHHHHcvaaaaaa",
      "vHHHHHHHcvbaaaaa",
      "vHHHHHHHcvaaaaaa",
      "vHHHHHHHcvaaaaaa",
      "vHHHHHHHcvdddddd",
      "vHHHHHHHcvdddddd",
      "vHHHccccccccHHHc",
      "vHHHHccccccHHHHH",
      "vHHHHHHHHHHHHHHH",
      "vHHHHHHHHHHHHHHH",
      "vHHHHHHHHHHHHHHH",
      "vvvvvvvvvvvvvvvv"
    ],
    [
      "v   e  f vaaaaaa",
      "v   g  h vaaaaaa",
      "v   e  f vaaaaaa",
      "v   g  h vaaaaaa",
      "v   e  f vaaaaaa",
      "v   g  h vbddddd",
      "v   e  f vdddddd",
      "v   g  h vdddddd",
      "v   e  f vccHHHc",
      "v   g  h viijjji",
      "v   kkkk lllmmml",
      "v               ",
      "v               ",
      "v               ",
      "v               ",
      "vvvvvvvvvvvvvvvv"
    ],
    [
      "v        vaaaaaa",
      "v        vaaaaaa",
      "v        vdddddd",
      "v        vdddddd",
      "v        vdddddd",
      "v        vbcHHHc",
      "v        viijjji",
      "v        vllmmml",
      "v        v      ",
      "v        v      ",
      "v               ",
      "v               ",
      "v               ",
      "v               ",
      "v               ",
      "vvvvvvvvvvvvvvvv"
    ],
    [
      "v        vdddddd",
      "v        vdddddd",
      "v        vccHHHc",
      "v        viijjji",
      "v        vllmmml",
      "v        vb     ",
      "v        v      ",
      "v        v      ",
      "v        v      ",
      "v        v      ",
      "v               ",
      "v               ",
      "v               ",
      "v               ",
      "v               ",
      "vvvvvvvvvvvvvvvv"
    ]
  ]
}