{
  "name": "multi_oasiscondo_3_floor10",
  "refpalette": "deceasedcraft:multi_oasiscondo_3/multi_oasiscondo_3_floor10_palette",
  "xsize": 16,
  "zsize": 16,
  "slices": [
    [
      "         aaaaaab",
      "         aaaaaaa",
      "         aaaaaaa",
      "         caaaaaa",
      "         caaaaaa",
      "          daaaaa",
      "           eeaaa",
      "                ",
      "                ",
      "                ",
      "                ",
      "                ",
      "                ",
      "                ",
      "                ",
      "                "
    ],
    [
      "        f g hijk",
      "        lmn oi  ",
      "        ffp qiii",
      "        rfs  tuw",
      "         fx     ",
      "          dyABC ",
      "           fffD ",
      "            Elff",
      "                ",
      "                ",
      "                ",
      "                ",
      "                ",
      "                ",
      "                ",
      "                "
    ],
    [
      "        F I  J  ",
      "        F    K  ",
      "        FF   LMN",
      "         F      ",
      "         l      ",
      "          d     ",
      "           fFF  ",
      "             FFF",
      "                ",
      "                ",
      "                ",
      "                ",
      "                ",
      "                ",
      "                ",
      "                "
    ],
    [
      "        F      O",
      "        F       ",
      "        FF      ",
      "         F      ",
      "         f      ",
      "          d     ",
      "           lFF  ",
      "             FFF",
      "                ",
      "                ",
      "                ",
      "                ",
      "                ",
      "                ",
      "                ",
      "                "
    ],
    [
      "        F      f",
      "        F       ",
      "        FF      ",
      "         F      ",
      "         f      ",
      "          d     ",
      "           fFF  ",
      "             FFF",
      "                ",
      "                ",
      "                ",
      "                ",
      "                ",
      "                ",
      "                ",
      "                "
    ],
    [
      "        lPPPPPPf",
      "        fPPPPPPP",
      "        ffPPPPPP",
      "        rfPPPPPP",
      "         fPPPPPP",
      "          dPPPPP",
      "           fffPP",
      "            Ellf",
      "                ",
      "                ",
      "                ",
      "                ",
      "                ",
      "                ",
      "                ",
      "                "
    ]
  ]
}