{
  "name": "multi_oasiscondo_3_floor2",
  "refpalette": "deceasedcraft:multi_oasiscondo_3/multi_oasiscondo_3_floor2_palette",
  "xsize": 16,
  "zsize": 16,
  "slices": [
    [
      "         aaaaaab",
      "         aaaaaaa",
      "         aaaaaaa",
      "         caaaaaa",
      "         caaaaaa",
      "          daaaaa",
      "           eeaaa",
      "                ",
      "                ",
      "                ",
      "                ",
      "                ",
      "                ",
      "                ",
      "                ",
      "                "
    ],
    [
      "        bfg  h b",
      "        ijkklm n",
      "        bboo m p",
      "        qb   r s",
      "         bt  m  ",
      "          duwmxx",
      "           bbbyA",
      "            Bibb",
      "                ",
      "                ",
      "                ",
      "                ",
      "                ",
      "                ",
      "                ",
      "                "
    ],
    [
      "        CD   E b",
      "        CkkkFm I",
      "        CCJK m  ",
      "         C   L M",
      "         b   m  ",
      "          dN m  ",
      "           bCC  ",
      "             CCC",
      "                ",
      "                ",
      "                ",
      "                ",
      "                ",
      "                ",
      "                ",
      "                "
    ],
    [
      "        CO   P b",
      "        CkkkQm  ",
      "        CCRS m  ",
      "         CT  P  ",
      "         b   m  ",
      "          dU m  ",
      "           bCC  ",
      "             CCC",
      "                ",
      "                ",
      "                ",
      "                ",
      "                ",
      "                ",
      "                ",
      "                "
    ],
    [
      "        C    m b",
      "        Ckkkkm  ",
      "        CCVVVm W",
      "         CVVVm  ",
      "         iVVVm  ",
      "          dX m W",
      "           iCC  ",
      "             CCC",
      "                ",
      "                ",
      "                ",
      "                ",
      "                ",
      "                ",
      "                ",
      "                "
    ],
    [
      "        bYYYYYYb",
      "        bYYYYYYY",
      "        bb   YYY",
      "        qb   YYY",
      "         bZ  YYY",
      "          dYYYYY",
      "           bbbYY",
      "            0ibb",
      "                ",
      "                ",
      "                ",
      "                ",
      "                ",
      "                ",
      "                ",
      "                "
    ]
  ]
}