{
  "name": "multi_oasiscondo_3_base2",
  "refpalette": "deceasedcraft:multi_oasiscondo_3/multi_oasiscondo_3_base2_palette",
  "xsize": 16,
  "zsize": 16,
  "slices": [
    [
      "vHHHHHHHHHHHHHHH",
      "vHHHHHHHHHHHHHHH",
      "vHHHHHHHHHHHHHHH",
      "vHHHHHHHHHHHHHHH",
      "vHHHHHHHHHHHHHHH",
      "vHHHHHHHHHaHHHHH",
      "vHHHHHHHHHHHHHHH",
      "vHHHHHHHHHHHHHHH",
      "vHHHHHHHHHHHHHHH",
      "vHHHHHHHHHHHHHHH",
      "vHHHHHHHHHHHHHHH",
      "vHHHHHHHHHHHHHHH",
      "vHHHHHHHHHHHHHHH",
      "vHHHHHHHHHHHHHHH",
      "vbbbbHHHHHHHHHHH",
      "vvvvvvvvvvvvvvvv"
    ],
    [
      "vc  d           ",
      "ve  f           ",
      "vc  d           ",
      "ve  f           ",
      "vc  d           ",
      "ve  f     a     ",
      "vc  d           ",
      "ve  f           ",
      "vc  d           ",
      "ve  f           ",
      "vc  d           ",
      "ve  f           ",
      "vc  d           ",
      "ve  f           ",
      "vgggg           ",
      "vvvvvvvvvvvvvvvv"
    ],
    [
      "v               ",
      "v               ",
      "v               ",
      "v               ",
      "v               ",
      "v         a     ",
      "v               ",
      "v               ",
      "v               ",
      "v               ",
      "v               ",
      "v               ",
      "v               ",
      "v               ",
      "v               ",
      "vvvvvvvvvvvvvvvv"
    ],
    [
      "v               ",
      "v               ",
      "v               ",
      "v               ",
      "v               ",
      "v         a     ",
      "v               ",
      "v               ",
      "v               ",
      "v               ",
      "v               ",
      "v               ",
      "v               ",
      "v               ",
      "v               ",
      "vvvvvvvvvvvvvvvv"
    ],
    [
      "v               ",
      "v               ",
      "v               ",
      "v               ",
      "v               ",
      "v         a     ",
      "v               ",
      "v               ",
      "v               ",
      "v               ",
      "v               ",
      "v               ",
      "v               ",
      "v               ",
      "v               ",
      "vvvvvvvvvvvvvvvv"
    ],
    [
      "vhhhhhhhhhihhhhh",
      "vhhhhhhhhhihhhhh",
      "vhhhhhhhhhihhhhh",
      "vhhhhhhhhhihhhhh",
      "vhhhhhhhhhihhhhh",
      "viiiiiiiiijiiiii",
      "vhhhhhhhhhihhhhh",
      "vhhhhhhhhhihhhhh",
      "vhhhhhhhhhihhhhh",
      "vhhhhhhhhhihhhhh",
      "vhhhhhhhhhihhhhh",
      "vhhhhhhhhhihhhhh",
      "vhhhhhhhhhihhhhh",
      "vhhhhhhhhhihhhhh",
      "vhhhhhhhhhihhhhh",
      "vvvvvvvvvvvvvvvv"
    ]
  ]
}