{
  "name": "multi_oasiscondo_3_base3",
  "refpalette": "deceasedcraft:multi_oasiscondo_3/multi_oasiscondo_3_base3_palette",
  "xsize": 16,
  "zsize": 16,
  "slices": [
    [
      "v        vaabbba",
      "v        vccdddc",
      "v        v      ",
      "v        v      ",
      "v        v      ",
      "v        ve     ",
      "v        v      ",
      "v        v      ",
      "v        v      ",
      "v        v      ",
      "v        f      ",
      "v        f      ",
      "v        f      ",
      "v        f      ",
      "v        f      ",
      "vvvvvvvvvvvvvvvv"
    ],
    [
      "v        v      ",
      "v        v      ",
      "v        v      ",
      "v        v      ",
      "v        v      ",
      "v        ve     ",
      "v        v      ",
      "v        v      ",
      "v        v      ",
      "v        v      ",
      "v        v      ",
      "v        v      ",
      "v        v      ",
      "v        v      ",
      "v        v      ",
      "vvvvvvvvvvvvvvvv"
    ],
    [
      "v        v      ",
      "v        v      ",
      "v        v      ",
      "v        v      ",
      "v        v      ",
      "v        ve     ",
      "v        v      ",
      "v        v      ",
      "v        v      ",
      "v        v      ",
      "v        v      ",
      "v        v      ",
      "v        v      ",
      "v        v      ",
      "v        v      ",
      "vvvvvvvvvvvvvvvv"
    ],
    [
      "v        v      ",
      "v        v      ",
      "v        v      ",
      "v        v      ",
      "v        v      ",
      "v        ve     ",
      "v        v      ",
      "v        v      ",
      "v        v      ",
      "v        v      ",
      "v        v      ",
      "v        v      ",
      "v        v      ",
      "v        v      ",
      "v        v      ",
      "vvvvvvvvvvvvvvvv"
    ],
    [
      "v        v      ",
      "v        v      ",
      "v        v      ",
      "v        v      ",
      "v        v      ",
      "v        ve     ",
      "v        v      ",
      "v        v      ",
      "v        v      ",
      "v        v      ",
      "v        v      ",
      "v        v      ",
      "v        v      ",
      "v        v      ",
      "v        v      ",
      "vvvvvvvvvvvvvvvv"
    ],
    [
      "vggggggggvhggggg",
      "vggggggggvhggggg",
      "vggggggggvhggggg",
      "vggggggggvhggggg",
      "vggggggggvhggggg",
      "vhhhhhhhhhihhhhh",
      "vggggggggvhggggg",
      "vggggggggvhggggg",
      "vggggggggvhggggg",
      "vggggggggvhggggg",
      "vggggggggvhggggg",
      "vggggggggvhggggg",
      "vggggggggvhggggg",
      "vggggggggvhggggg",
      "vggggggggvhggggg",
      "vvvvvvvvvvvvvvvv"
    ]
  ]
}