{
  "name": "multi_oasiscondo_3_floor11",
  "refpalette": "deceasedcraft:multi_oasiscondo_3/multi_oasiscondo_3_floor11_palette",
  "xsize": 16,
  "zsize": 16,
  "slices": [
    [
      "         abcccbd",
      "         aebcbbb",
      "         abbcccb",
      "         fbcbcbc",
      "         fbbbbcb",
      "          gbbbbb",
      "           hhaaa",
      "                ",
      "                ",
      "                ",
      "                ",
      "                ",
      "                ",
      "                ",
      "                ",
      "                "
    ],
    [
      "       ijjk     ",
      "       ijjkk  l ",
      "       ijjm    k",
      "       nijo m   ",
      "        ijk p  l",
      "        nngm kq ",
      "         nnjjjjj",
      "          nrrjjj",
      "            nrrr",
      "                ",
      "                ",
      "                ",
      "                ",
      "                ",
      "                ",
      "                "
    ],
    [
      "       s  k     ",
      "       s      k ",
      "       s        ",
      "       ss       ",
      "        s   l  k",
      "        ssg     ",
      "         ss     ",
      "          sss   ",
      "            ssss",
      "                ",
      "                ",
      "                ",
      "                ",
      "                ",
      "                ",
      "                "
    ],
    [
      "                ",
      "              k ",
      "                ",
      "                ",
      "            q   ",
      "          g     ",
      "                ",
      "                ",
      "                ",
      "                ",
      "                ",
      "                ",
      "                ",
      "                ",
      "                ",
      "                "
    ],
    [
      "        t       ",
      "        t       ",
      "        t       ",
      "        tu      ",
      "         t      ",
      "          g     ",
      "           wx   ",
      "            wwww",
      "                ",
      "                ",
      "                ",
      "                ",
      "                ",
      "                ",
      "                ",
      "                "
    ],
    [
      "       nnnyyyyyy",
      "       nnnyyyyyy",
      "       nnnyyyyyy",
      "       nnnyyyyyy",
      "        nnyyyyyy",
      "        nngyyyyy",
      "         nnnnnnn",
      "          nnnnnn",
      "            nnnn",
      "                ",
      "                ",
      "                ",
      "                ",
      "                ",
      "                ",
      "                "
    ]
  ]
}