{
  "name": "multi_oasiscondo_3_floor6",
  "refpalette": "deceasedcraft:multi_oasiscondo_3/multi_oasiscondo_3_floor6_palette",
  "xsize": 16,
  "zsize": 16,
  "slices": [
    [
      "         aaaaaab",
      "         aaaaaaa",
      "         aaaaaaa",
      "         caaaaaa",
      "         caaaaaa",
      "          daaaaa",
      "           eeaaa",
      "                ",
      "                ",
      "                ",
      "                ",
      "                ",
      "                ",
      "                ",
      "                ",
      "                "
    ],
    [
      "        bfg  h b",
      "        bijjkl m",
      "        bbnn l o",
      "        pb   q r",
      "         bst l  ",
      "          duwlxx",
      "           ybbAB",
      "            Cbyb",
      "                ",
      "                ",
      "                ",
      "                ",
      "                ",
      "                ",
      "                ",
      "                "
    ],
    [
      "        DE   F b",
      "        DjjjIl J",
      "        DDKL l M",
      "         D   N O",
      "         b   l  ",
      "          dP l  ",
      "           bDD Q",
      "             DDD",
      "                ",
      "                ",
      "                ",
      "                ",
      "                ",
      "                ",
      "                ",
      "                "
    ],
    [
      "        D    R b",
      "        DjjjSl  ",
      "        DDTU l  ",
      "         D   R  ",
      "         y   l  ",
      "          dV l  ",
      "           bDD  ",
      "             DDD",
      "                ",
      "                ",
      "                ",
      "                ",
      "                ",
      "                ",
      "                ",
      "                "
    ],
    [
      "        D    l b",
      "        Djjjjl  ",
      "        DDWWWl X",
      "         DWWWl  ",
      "         bWWWl  ",
      "          dY l X",
      "           yDD  ",
      "             DDD",
      "                ",
      "                ",
      "                ",
      "                ",
      "                ",
      "                ",
      "                ",
      "                "
    ],
    [
      "        bZZZZZZb",
      "        bZZZZZZZ",
      "        bb   ZZZ",
      "        0b   ZZZ",
      "         y1  ZZZ",
      "          dZZZZZ",
      "           bbbZZ",
      "            Cbby",
      "                ",
      "                ",
      "                ",
      "                ",
      "                ",
      "                ",
      "                ",
      "                "
    ]
  ]
}