{
  "name": "multi_oasiscondo_3_floor9",
  "refpalette": "deceasedcraft:multi_oasiscondo_3/multi_oasiscondo_3_floor9_palette",
  "xsize": 16,
  "zsize": 16,
  "slices": [
    [
      "         abccbbd",
      "         abcccbb",
      "         acbcbcc",
      "         ebbcccc",
      "         ebbbbcb",
      "          fbbbbb",
      "           ggaaa",
      "                ",
      "                ",
      "                ",
      "                ",
      "                ",
      "                ",
      "                ",
      "                ",
      "                "
    ],
    [
      "       hiij   k ",
      "       hiil   mk",
      "       hii      ",
      "       nhikk    ",
      "        hik op j",
      "        nnfk k o",
      "         nniiiii",
      "          nqqiii",
      "            nqqq",
      "                ",
      "                ",
      "                ",
      "                ",
      "                ",
      "                ",
      "                "
    ],
    [
      "       r        ",
      "       r  o    k",
      "       r        ",
      "       rr       ",
      "        r   k   ",
      "        rrf    k",
      "         rr     ",
      "          rrr   ",
      "            rrrr",
      "                ",
      "                ",
      "                ",
      "                ",
      "                ",
      "                ",
      "                "
    ],
    [
      "                ",
      "          k     ",
      "                ",
      "                ",
      "            k   ",
      "          f     ",
      "                ",
      "                ",
      "                ",
      "                ",
      "                ",
      "                ",
      "                ",
      "                ",
      "                ",
      "                "
    ],
    [
      "        s       ",
      "        s       ",
      "        s       ",
      "        st      ",
      "         s      ",
      "          f     ",
      "           uw   ",
      "            uuuu",
      "                ",
      "                ",
      "                ",
      "                ",
      "                ",
      "                ",
      "                ",
      "                "
    ],
    [
      "       nnnxxxxxx",
      "       nnnxxxxxx",
      "       nnnxxxxxx",
      "       nnnxxxxxx",
      "        nnxxxxxx",
      "        nnfxxxxx",
      "         nnnnnnn",
      "          nnnnnn",
      "            nnnn",
      "                ",
      "                ",
      "                ",
      "                ",
      "                ",
      "                ",
      "                "
    ]
  ]
}