{
  "name": "multi_oasiscondo_3_floor4",
  "refpalette": "deceasedcraft:multi_oasiscondo_3/multi_oasiscondo_3_floor4_palette",
  "xsize": 16,
  "zsize": 16,
  "slices": [
    [
      "         aaaaaab",
      "         aaaaaaa",
      "         aaaaaaa",
      "         caaaaaa",
      "         caaaaaa",
      "          daaaaa",
      "           eeaaa",
      "                ",
      "                ",
      "                ",
      "                ",
      "                ",
      "                ",
      "                ",
      "                ",
      "                "
    ],
    [
      "        f    g b",
      "        bhi  g j",
      "        bfk    l",
      "        mfnonp q",
      "         br sp t",
      "          d upt ",
      "           bbbwx",
      "            nffb",
      "                ",
      "                ",
      "                ",
      "                ",
      "                ",
      "                ",
      "                ",
      "                "
    ],
    [
      "        y    g b",
      "        y    g A",
      "        yy  B  C",
      "         ynDnp E",
      "         b   p  ",
      "          dF p  ",
      "           byyEI",
      "             yyy",
      "                ",
      "                ",
      "                ",
      "                ",
      "                ",
      "                ",
      "                ",
      "                "
    ],
    [
      "        y    g b",
      "        y    g  ",
      "        yy      ",
      "         ynJnp  ",
      "         fK  p  ",
      "          dL p  ",
      "           byy  ",
      "             yyy",
      "                ",
      "                ",
      "                ",
      "                ",
      "                ",
      "                ",
      "                ",
      "                "
    ],
    [
      "        y    g b",
      "        y    g  ",
      "        yy     M",
      "         yNNNp  ",
      "         bOOOp  ",
      "          dP p M",
      "           fyy  ",
      "             yyy",
      "                ",
      "                ",
      "                ",
      "                ",
      "                ",
      "                ",
      "                ",
      "                "
    ],
    [
      "        bQQQQQQb",
      "        bQQQQQQQ",
      "        bbQQQQQQ",
      "        RbQQQQQQ",
      "         bS  QQQ",
      "          dQQQQQ",
      "           bbbQQ",
      "            nbbf",
      "                ",
      "                ",
      "                ",
      "                ",
      "                ",
      "                ",
      "                ",
      "                "
    ]
  ]
}