{
  "name": "multi_oasiscondo_3_floor5",
  "refpalette": "deceasedcraft:multi_oasiscondo_3/multi_oasiscondo_3_floor5_palette",
  "xsize": 16,
  "zsize": 16,
  "slices": [
    [
      "         aaaaaab",
      "         aaaaaaa",
      "         aaaaaaa",
      "         caaaaaa",
      "         caaaaaa",
      "          daaaaa",
      "           eeaaa",
      "                ",
      "                ",
      "                ",
      "                ",
      "                ",
      "                ",
      "                ",
      "                ",
      "                "
    ],
    [
      "        bf   g b",
      "        hijkkl m",
      "        bb  nl o",
      "        pbq  j r",
      "         bs tl  ",
      "          duwlxx",
      "           bbbyA",
      "            Bhbb",
      "                ",
      "                ",
      "                ",
      "                ",
      "                ",
      "                ",
      "                ",
      "                "
    ],
    [
      "        CD   E b",
      "        CkFkkl I",
      "        CC J l  ",
      "         C   F K",
      "         h   l  ",
      "          dL l  ",
      "           bCCMN",
      "             CCC",
      "                ",
      "                ",
      "                ",
      "                ",
      "                ",
      "                ",
      "                ",
      "                "
    ],
    [
      "        CO   P b",
      "        CkQkkl  ",
      "        CC  Rl  ",
      "         C   P  ",
      "         b   l  ",
      "          dS l  ",
      "           hCC  ",
      "             CCC",
      "                ",
      "                ",
      "                ",
      "                ",
      "                ",
      "                ",
      "                ",
      "                "
    ],
    [
      "        C    l b",
      "        Ckkkkl  ",
      "        CCTTTl U",
      "         CTTTl  ",
      "         bTTTl  ",
      "          dV l U",
      "           bCC  ",
      "             CCC",
      "                ",
      "                ",
      "                ",
      "                ",
      "                ",
      "                ",
      "                ",
      "                "
    ],
    [
      "        hWWWWWWb",
      "        bWWWWWWW",
      "        bb   WWW",
      "        Xb   WWW",
      "         hY  WWW",
      "          dWWWWW",
      "           bbbWW",
      "            Bbbb",
      "                ",
      "                ",
      "                ",
      "                ",
      "                ",
      "                ",
      "                ",
      "                "
    ]
  ]
}