{
  "name": "multi_oasiscondo_3_floor3",
  "refpalette": "deceasedcraft:multi_oasiscondo_3/multi_oasiscondo_3_floor3_palette",
  "xsize": 16,
  "zsize": 16,
  "slices": [
    [
      "         aaaaaab",
      "         aaaaaaa",
      "         aaaaaaa",
      "         caaaaaa",
      "         caaaaaa",
      "          daaaaa",
      "           eeaaa",
      "                ",
      "                ",
      "                ",
      "                ",
      "                ",
      "                ",
      "                ",
      "                ",
      "                "
    ],
    [
      "        bfghij b",
      "        klmmno p",
      "        bbqqro s",
      "        tb  uw x",
      "         kyA o  ",
      "          dBCoDD",
      "           bbbEF",
      "            Ibbk",
      "                ",
      "                ",
      "                ",
      "                ",
      "                ",
      "                ",
      "                ",
      "                "
    ],
    [
      "        JK   L b",
      "        JmmMNo  ",
      "        JJOP o Q",
      "         J   R S",
      "         k   o  ",
      "          dT o  ",
      "           bJJUV",
      "             JJJ",
      "                ",
      "                ",
      "                ",
      "                ",
      "                ",
      "                ",
      "                ",
      "                "
    ],
    [
      "        J    W b",
      "        JmmM X  ",
      "        JJYZ o  ",
      "         J   W  ",
      "         b  0o  ",
      "          d1 o  ",
      "           bJJ  ",
      "             JJJ",
      "                ",
      "                ",
      "                ",
      "                ",
      "                ",
      "                ",
      "                ",
      "                "
    ],
    [
      "        J    o b",
      "        JmM  o  ",
      "        JJ230X 4",
      "         J222X  ",
      "         b222o  ",
      "          d50o 4",
      "           kJJ  ",
      "             JJJ",
      "                ",
      "                ",
      "                ",
      "                ",
      "                ",
      "                ",
      "                ",
      "                "
    ],
    [
      "        k666666b",
      "        b6666666",
      "        kb !0666",
      "        tb   666",
      "         k7 0666",
      "          d66666",
      "           bkb66",
      "            8bkb",
      "                ",
      "                ",
      "                ",
      "                ",
      "                ",
      "                ",
      "                ",
      "                "
    ]
  ]
}