{
  "name": "multi_oasiscondo_3_base1",
  "refpalette": "deceasedcraft:multi_oasiscondo_3/multi_oasiscondo_3_base1_palette",
  "xsize": 16,
  "zsize": 16,
  "slices": [
    [
      "vHHHHHHHHHHHHHHH",
      "vHHHHHHHHHHHHHHH",
      "vHHHHHHHHHHHHHHH",
      "vHHHHHHHHHHHHHHH",
      "vHHHHHHHHHHHHHHH",
      "vHHHHHHHHHaHHHHH",
      "vHHHHHHHHHHHHHHH",
      "vHHHHHHHHHHHHHHH",
      "vHHHHHHHHHHHHHHH",
      "vHHHHHHHHHHHHHHH",
      "vHHHHHHHHHHHHHHH",
      "vHHHHHHHHHHHHHHH",
      "vHHHHHHHHHHHHHHH",
      "vHHHHHHHHHHHHHHH",
      "vbbbbHHHHHHHHHHH",
      "vvvvvvvvvvvvvvvv"
    ],
    [
      "vc  d           ",
      "ve  f           ",
      "vc  d           ",
      "ve  f           ",
      "vc  d           ",
      "ve  f     a     ",
      "vc  d           ",
      "ve  f           ",
      "vc gd           ",
      "ve  f           ",
      "vc  d           ",
      "ve  f           ",
      "vc  d           ",
      "ve  f           ",
      "vhhhh           ",
      "vvvvvvvvvvvvvvvv"
    ],
    [
      "v               ",
      "v               ",
      "v               ",
      "v               ",
      "v               ",
      "v         a     ",
      "v               ",
      "v               ",
      "v               ",
      "v               ",
      "v               ",
      "v               ",
      "v               ",
      "v               ",
      "v               ",
      "vvvvvvvvvvvvvvvv"
    ],
    [
      "v               ",
      "v               ",
      "v               ",
      "v               ",
      "v               ",
      "v         a     ",
      "v               ",
      "v               ",
      "v               ",
      "v               ",
      "v               ",
      "v               ",
      "v               ",
      "v               ",
      "v               ",
      "vvvvvvvvvvvvvvvv"
    ],
    [
      "v               ",
      "v               ",
      "v               ",
      "v               ",
      "v               ",
      "v         a     ",
      "v               ",
      "v               ",
      "v               ",
      "v               ",
      "v               ",
      "v               ",
      "v               ",
      "v               ",
      "v               ",
      "vvvvvvvvvvvvvvvv"
    ],
    [
      "viiiiiiiiijiiiii",
      "viiiiiiiiijiiiii",
      "viiiiiiiiijiiiii",
      "viiiiiiiiijiiiii",
      "viiiiiiiiijiiiii",
      "vjjjjjjjjjkjjjjj",
      "viiiiiiiiijiiiii",
      "viiiiiiiiijiiiii",
      "viiiiiiiiijiiiii",
      "viiiiiiiiijiiiii",
      "viiiiiiiiijiiiii",
      "viiiiiiiiijiiiii",
      "viiiiiiiiijiiiii",
      "viiiiiiiiijiiiii",
      "viiiiiiiiijiiiii",
      "vvvvvvvvvvvvvvvv"
    ]
  ]
}