{
  "name": "multi_oasiscondo_3_floor8",
  "refpalette": "deceasedcraft:multi_oasiscondo_3/multi_oasiscondo_3_floor8_palette",
  "xsize": 16,
  "zsize": 16,
  "slices": [
    [
      "         aaaaaab",
      "         aaaaaaa",
      "         aaaaaaa",
      "         caaaaaa",
      "         caaaaaa",
      "          daaaaa",
      "           eeaaa",
      "                ",
      "                ",
      "                ",
      "                ",
      "                ",
      "                ",
      "                ",
      "                ",
      "                "
    ],
    [
      "        fgh  i b",
      "        bjklmn o",
      "        bbpp n q",
      "        rf   s t",
      "         fuw n  ",
      "          dxynAA",
      "           bbbBC",
      "            Dbfb",
      "                ",
      "                ",
      "                ",
      "                ",
      "                ",
      "                ",
      "                ",
      "                "
    ],
    [
      "        EF   I b",
      "        EJJJKn  ",
      "        EELM n N",
      "         E   O P",
      "         b  Qn  ",
      "          dRSn  ",
      "           fEE T",
      "             EEE",
      "                ",
      "                ",
      "                ",
      "                ",
      "                ",
      "                ",
      "                ",
      "                "
    ],
    [
      "        E    U b",
      "        EJJJVn  ",
      "        EEWX n  ",
      "         E   U  ",
      "         b   n  ",
      "          dY n  ",
      "           bEE  ",
      "             EEE",
      "                ",
      "                ",
      "                ",
      "                ",
      "                ",
      "                ",
      "                ",
      "                "
    ],
    [
      "        E    n b",
      "        EJJJJn  ",
      "        EEZZZn 0",
      "         EZZZn  ",
      "         bZZZn  ",
      "          d1 n 0",
      "           bEE  ",
      "             EEE",
      "                ",
      "                ",
      "                ",
      "                ",
      "                ",
      "                ",
      "                ",
      "                "
    ],
    [
      "        f222222b",
      "        b2222222",
      "        bb   222",
      "        3b   222",
      "         f4  222",
      "          d22222",
      "           bbb22",
      "            Dbff",
      "                ",
      "                ",
      "                ",
      "                ",
      "                ",
      "                ",
      "                ",
      "                "
    ]
  ]
}