{
  "name": "multi_oasiscondo_3_floor7",
  "refpalette": "deceasedcraft:multi_oasiscondo_3/multi_oasiscondo_3_floor7_palette",
  "xsize": 16,
  "zsize": 16,
  "slices": [
    [
      "         aaaaaab",
      "         aaaaaaa",
      "         aaccdaa",
      "         eacdfda",
      "         eaacdda",
      "          gaaaaa",
      "           hhaaa",
      "                ",
      "                ",
      "                ",
      "                ",
      "                ",
      "                ",
      "                ",
      "                ",
      "                "
    ],
    [
      "        ijk lm b",
      "        inoopqrs",
      "        tuwd xyA",
      "        BCc  ! D",
      "         iEFI Jy",
      "          gKLqMN",
      "           itiOP",
      "            Qbbb",
      "                ",
      "                ",
      "                ",
      "                ",
      "                ",
      "                ",
      "                ",
      "                "
    ],
    [
      "        RS   T b",
      "        Rooo q  ",
      "        RRU     ",
      "               V",
      "         t      ",
      "          gW q  ",
      "           iRR X",
      "             RRR",
      "                ",
      "                ",
      "                ",
      "                ",
      "                ",
      "                ",
      "                ",
      "                "
    ],
    [
      "        R    Y b",
      "        RoooZq  ",
      "        RR01    ",
      "         R      ",
      "         2   3  ",
      "          g4 q  ",
      "           tRR  ",
      "             RRR",
      "                ",
      "                ",
      "                ",
      "                ",
      "                ",
      "                ",
      "                ",
      "                "
    ],
    [
      "        R    q b",
      "        Rooooq  ",
      "        RR555q 6",
      "         R555q  ",
      "         i555q  ",
      "          g7Fq 6",
      "           iRR  ",
      "             RRR",
      "                ",
      "                ",
      "                ",
      "                ",
      "                ",
      "                ",
      "                ",
      "                "
    ],
    [
      "        b888888b",
      "        b8888888",
      "        ib   888",
      "        9b   888",
      "         u#  888",
      "          g88888",
      "           iib88",
      "            Qbib",
      "                ",
      "                ",
      "                ",
      "                ",
      "                ",
      "                ",
      "                ",
      "                "
    ]
  ]
}