{
  "name": "multi_oasiscondo_3_ground",
  "refpalette": "deceasedcraft:multi_oasiscondo_3/multi_oasiscondo_3_ground_palette",
  "xsize": 16,
  "zsize": 16,
  "slices": [
    [
      "aaaaaaaaabcccccc",
      "aaaaaaaaabcccccc",
      "aaaaaaaaabcccccc",
      "aaadddaaabcccccc",
      "aadddddaabbccccc",
      "adddddddabebcccc",
      "adddddddaabbbbbb",
      "addddddddaaaaaaa",
      "addddddddddaaaaa",
      "adddddddddddaaaa",
      "addddddddddddaaa",
      "addddddddddddaaa",
      "addddddddddddaaa",
      "aaddddddddddaaaa",
      "aaaddddddddaaaaa",
      "aaaaaaaaaaaaaaaa"
    ],
    [
      "         f gh i ",
      "         fj g  k",
      "         f j    ",
      "   lll   f   m  ",
      "  lnnnl  ff m  m",
      " lnooonl  ef m  ",
      " lnooonl  pfffff",
      " lnoooonl       ",
      " lnooooonll     ",
      " lnoooooonnl    ",
      " lnoooooooonl   ",
      " lnoooooooonl   ",
      " lnoooooooonl   ",
      "  lnnnnnnnnl    ",
      "   llllllll     ",
      "                "
    ],
    [
      "         f      ",
      "         f      ",
      "         f      ",
      "         f      ",
      "         ff     ",
      "          ef    ",
      "           fffff",
      "                ",
      "                ",
      "                ",
      "                ",
      "                ",
      "                ",
      "                ",
      "                ",
      "                "
    ],
    [
      "         f      ",
      "         f      ",
      "         f      ",
      "         f      ",
      "         ff     ",
      "          ef    ",
      "           fffff",
      "                ",
      "                ",
      "                ",
      "                ",
      "                ",
      "                ",
      "                ",
      "                ",
      "                "
    ],
    [
      "         f      ",
      "         f      ",
      "         f      ",
      "         f      ",
      "         ff     ",
      "          ef    ",
      "           fffff",
      "                ",
      "                ",
      "                ",
      "                ",
      "                ",
      "                ",
      "                ",
      "                ",
      "                "
    ],
    [
      "         f      ",
      "         f      ",
      "         f      ",
      "         f      ",
      "         ff     ",
      "          ef    ",
      "           fffff",
      "                ",
      "                ",
      "                ",
      "                ",
      "                ",
      "                ",
      "                ",
      "                ",
      "                "
    ]
  ]
}