{
  "name": "villager_1_floor1",
  "refpalette": "deceasedcraft:villager_1/villager_1_floor1_palette",
  "xsize": 16,
  "zsize": 16,
  "slices": [
    [
      "aaaaaaaaaaaaaaaa",
      "aaaabababaabaaaa",
      "aaabababbbababaa",
      "aabbbaaaaaaabaaa",
      "ababaaccccaababa",
      "aabaaccccccaabba",
      "abbaccccccccabba",
      "aabacccddcccabaa",
      "abbacccddcccabba",
      "abbaccccccccabba",
      "aabaaccccccaaaba",
      "ababaaccccaaabba",
      "aabbbaaaaaaabbaa",
      "aaaabbabbbbbaaaa",
      "aaaababbbbbabaaa",
      "aaaaaaaaaaaaaaaa"
    ],
    [
      "eeeeeeeeeeeeeeee",
      "eeeeeeeeeeeeeeee",
      "eeeeeeeeeeeeeeee",
      "eeeeeefgeheeeeee",
      "eeeeegccccgeeeee",
      "eeefhciiiicgeeee",
      "eeegcijiijicheee",
      "eeehciikdiicgeee",
      "eeegciilliicfeee",
      "eeegcijiijicgeee",
      "eeeegciiiicgeeee",
      "eeeeehccccheeeee",
      "eeeeeegeegeeeeee",
      "eeeeeeeeeeeeeeee",
      "eeeeeeeeeeeeeeee",
      "eeeeeeeeeeeeeeee"
    ],
    [
      "eeeeeeeeeeeeeeee",
      "eeeeeeeeeeeeeeee",
      "eeeeeeeeeeeeeeee",
      "eeeeeeeeeeeeeeee",
      "eeeeeeeeeeeeeeee",
      "eeeeeeeeeeeeeeee",
      "eeeeeeeeeeeeeeee",
      "eeeeeeelkeeeeeee",
      "eeeeeeeddeeeeeee",
      "eeeeeeeeeeeeeeee",
      "eeeeeeeeeeeeeeee",
      "eeeeeeeeeeeeeeee",
      "eeeeeeeeeeeeeeee",
      "eeeeeeeeeeeeeeee",
      "eeeeeeeeeeeeeeee",
      "eeeeeeeeeeeeeeee"
    ],
    [
      "eeeeeeeeeeeeeeee",
      "eeeeeeeeeeeeeeee",
      "eeeeeeeeeeeeeeee",
      "eeeeeeeeeeeeeeee",
      "eeeeeeeeeeeeeeee",
      "eeeeeeeeeeeeeeee",
      "eeeeeemneeeeeeee",
      "eeeeeekdleeeeeee",
      "eeeeeeklkeeeeeee",
      "eeeeeemneeeeeeee",
      "eeeeeeeeeeeeeeee",
      "eeeeeeeeeeeeeeee",
      "eeeeeeeeeeeeeeee",
      "eeeeeeeeeeeeeeee",
      "eeeeeeeeeeeeeeee",
      "eeeeeeeeeeeeeeee"
    ],
    [
      "eeeeeeeeeeeeeeee",
      "eeeeeeeeeeeeeeee",
      "eeeeeeeeeeeeeeee",
      "eeeeeeeeeeeeeeee",
      "eeeeeeeeeeeeeeee",
      "eeeeeeeeeeeeeeee",
      "eeeeeeeokeeeeeee",
      "eeeeeepmdeeeeeee",
      "eeeeeepmkeeeeeee",
      "eeeeeeeokeeeeeee",
      "eeeeeeeeeeeeeeee",
      "eeeeeeeeeeeeeeee",
      "eeeeeeeeeeeeeeee",
      "eeeeeeeeeeeeeeee",
      "eeeeeeeeeeeeeeee",
      "eeeeeeeeeeeeeeee"
    ],
    [
      "eeeeeeeeeeeeeeee",
      "eeeeeeeeeeeeeeee",
      "eeeeeeeeeeeeeeee",
      "eeeeeeeeeeeeeeee",
      "eeeeeeeeeeeeeeee",
      "eeeeeeeeeeeeeeee",
      "eeeeeeeeqeeeeeee",
      "eeeeeeerdeeeeeee",
      "eeeeeeeodeeeeeee",
      "eeeeeeeeseeeeeee",
      "eeeeeeeeeeeeeeee",
      "eeeeeeeeeeeeeeee",
      "eeeeeeeeeeeeeeee",
      "eeeeeeeeeeeeeeee",
      "eeeeeeeeeeeeeeee",
      "eeeeeeeeeeeeeeee"
    ]
  ]
}