{
  "name": "villager_1_floor2",
  "refpalette": "deceasedcraft:villager_1/villager_1_floor2_palette",
  "xsize": 16,
  "zsize": 16,
  "slices": [
    [
      "aaaaaaaaaaaaaaaa",
      "aaaaaaaaaaaaaaaa",
      "aaaaaaaaaaaaaaaa",
      "aaaaaaaaaaaaaaaa",
      "aaaaaaaaaaaaaaaa",
      "aaaaaaaaaaaaaaaa",
      "aaaaaaabcaaaaaaa",
      "aaaaaadefgaaaaaa",
      "aaaaaahifgaaaaaa",
      "aaaaaaajkaaaaaaa",
      "aaaaaaaaaaaaaaaa",
      "aaaaaaaaaaaaaaaa",
      "aaaaaaaaaaaaaaaa",
      "aaaaaaaaaaaaaaaa",
      "aaaaaaaaaaaaaaaa",
      "aaaaaaaaaaaaaaaa"
    ],
    [
      "aaaaaaaaaaaaaaaa",
      "aaaaaaaaaaaaaaaa",
      "aaaaaaaaaaaaaaaa",
      "aaaaaaaaaaaaaaaa",
      "aaaaaaaaaaaaaaaa",
      "aaaaaaaaaaaaaaaa",
      "aaaaaaadcaaaaaaa",
      "aaaaaacllmaaaaaa",
      "aaaaaaknnoaaaaaa",
      "aaaaaaahkaaaaaaa",
      "aaaaaaaaaaaaaaaa",
      "aaaaaaaaaaaaaaaa",
      "aaaaaaaaaaaaaaaa",
      "aaaaaaaaaaaaaaaa",
      "aaaaaaaaaaaaaaaa",
      "aaaaaaaaaaaaaaaa"
    ],
    [
      "aaaaaaaaaaaaaaaa",
      "aaaaaaaaaaaaaaaa",
      "aaaaaaaaaaaaaaaa",
      "aaaaaaaaaaaaaaaa",
      "aaaaaaaaaaaaaaaa",
      "aaaaaaaaaaaaaaaa",
      "aaaaaaacdaaaaaaa",
      "aaaaaaapnoaaaaaa",
      "aaaaaaaplmaaaaaa",
      "aaaaaaajhaaaaaaa",
      "aaaaaaaaaaaaaaaa",
      "aaaaaaaaaaaaaaaa",
      "aaaaaaaaaaaaaaaa",
      "aaaaaaaaaaaaaaaa",
      "aaaaaaaaaaaaaaaa",
      "aaaaaaaaaaaaaaaa"
    ],
    [
      "aaaaaaaaaaaaaaaa",
      "aaaaaaaaaaaaaaaa",
      "aaaaaaaaaaaaaaaa",
      "aaaaaaaaaaaaaaaa",
      "aaaaaaaaaaaaaaaa",
      "aaaaaaaaaaaaaaaa",
      "aaaaaaaddaaaaaaa",
      "aaaaaaannmaaaaaa",
      "aaaaaaannmaaaaaa",
      "aaaaaaakjaaaaaaa",
      "aaaaaaaaaaaaaaaa",
      "aaaaaaaaaaaaaaaa",
      "aaaaaaaaaaaaaaaa",
      "aaaaaaaaaaaaaaaa",
      "aaaaaaaaaaaaaaaa",
      "aaaaaaaaaaaaaaaa"
    ],
    [
      "aaaaaaaaaaaaaaaa",
      "aaaaaaaaaaaaaaaa",
      "aaaaaaaaaaaaaaaa",
      "aaaaaaaaaaaaaaaa",
      "aaaaaaaaaaaaaaaa",
      "aaaaaaaaaaaaaaaa",
      "aaaaaaaaaaaaaaaa",
      "aaaaaaaqqaaaaaaa",
      "aaaaaaaqqaaaaaaa",
      "aaaaaaaaaaaaaaaa",
      "aaaaaaaaaaaaaaaa",
      "aaaaaaaaaaaaaaaa",
      "aaaaaaaaaaaaaaaa",
      "aaaaaaaaaaaaaaaa",
      "aaaaaaaaaaaaaaaa",
      "aaaaaaaaaaaaaaaa"
    ],
    [
      "aaaaaaaaaaaaaaaa",
      "aaaaaaaaaaaaaaaa",
      "aaaaaaaaaaaaaaaa",
      "aaaaaaaaaaaaaaaa",
      "aaaaaaaaaaaaaaaa",
      "aaaaaaaaaaaaaaaa",
      "aaaaaaaaaaaaaaaa",
      "aaaaaaaaaaaaaaaa",
      "aaaaaaaaaaaaaaaa",
      "aaaaaaaaaaaaaaaa",
      "aaaaaaaaaaaaaaaa",
      "aaaaaaaaaaaaaaaa",
      "aaaaaaaaaaaaaaaa",
      "aaaaaaaaaaaaaaaa",
      "aaaaaaaaaaaaaaaa",
      "aaaaaaaaaaaaaaaa"
    ]
  ]
}