{
  "name": "multi_terraceplaza_34_base1",
  "refpalette": "deceasedcraft:multi_terraceplaza_34/multi_terraceplaza_34_base1_palette",
  "xsize": 16,
  "zsize": 16,
  "slices": [
    [
      "         aabcccv",
      "         adbcccv",
      "         adbcccv",
      "         adbcccv",
      "         adbcccv",
      "         adbcccv",
      "         adbcccv",
      "         adbcccv",
      "         adbcccv",
      "         aabcccv",
      "efgfef    hbcccv",
      "hhhhhhhhhhhbcccv",
      "dddddddddhhbcccv",
      "bbbbbbbbbbbbcccv",
      "cccccccccccccccv",
      "vvvvvvvvvvvvvvvv"
    ],
    [
      "         aabcccv",
      "         a bcccv",
      "         a bcccv",
      "         a bcccv",
      "         a bcccv",
      "         a bcccv",
      "         a bcccv",
      "         a bcccv",
      "         a bcccv",
      "         aabcccv",
      "ififjf    hbcccv",
      "hhhhhhhhhhhbcccv",
      "  k      hhbcccv",
      "bbbbbbbbbbbbcccv",
      "cccccccccccccccv",
      "vvvvvvvvvvvvvvvv"
    ],
    [
      "        laabcccv",
      "        la bcccv",
      "        la bcccv",
      "        la bcccv",
      "        la bcccv",
      "        la bcccv",
      "        la bcccv",
      "        la bcccv",
      "        lambcccv",
      "        laabcccv",
      "          hbcccv",
      "hhhhhhhhhhhbcccv",
      "nnnnnnnnnnnbcccv",
      "bbbbbbbbbbbbcccv",
      "cccccccccccccccv",
      "vvvvvvvvvvvvvvvv"
    ],
    [
      "aaaaaaaaaaabcccv",
      "aaaaaaaaaa bcccv",
      "aaaaaaaaaakbcccv",
      "aaaaaaaaaambcccv",
      "aaaaaaaaaambcccv",
      "aaaaaaaaaa bcccv",
      "aaaaaaaaaambcccv",
      "aaaaaaaaaakbcccv",
      "aaaaaaaaaambcccv",
      "aaaaaaaaaaabcccv",
      "oooooooooopbcccv",
      "hhhhhhhhhhhbcccv",
      "ccccccccccnbcccv",
      "bbbbbbbbbbbbcccv",
      "cccccccccccccccv",
      "vvvvvvvvvvvvvvvv"
    ],
    [
      "nnnqnnnnnnnbcccv",
      "ccccccccccnbcccv",
      "ccccccccccnbcccv",
      "ccccccccccnbcccv",
      "ccccccccccnbcccv",
      "ccccccccccnbcccv",
      "ccccccccccnbcccv",
      "ccccccccccnbcccv",
      "rrrrccccccnbcccv",
      "srsrccccccnbcccv",
      "srrrcccccctbcccv",
      "rrrrccccccnbcccv",
      "rrrrccccccnbcccv",
      "bbbbbbbbbbbbcccv",
      "cccccccccccccccv",
      "vvvvvvvvvvvvvvvv"
    ],
    [
      "ccccuccccccbcccv",
      "ccccuccccccbcccv",
      "ccccuwwwcccbcccv",
      "ccccuwwwcccbcccv",
      "ccccuwwwcccbcccv",
      "rrrruwwwcccbcccv",
      "rrrruwwwcccbcccv",
      "rrrruwwwcccbcccv",
      "    uwwwcccbcccv",
      "    uwwwcccbcccv",
      "   xywwwcccbcccv",
      "ABCDuwwwcccbcccv",
      "rrrruwwwcccbcccv",
      "uuuuubbbbbbbcccv",
      "cccccccccccccccv",
      "vvvvvvvvvvvvvvvv"
    ]
  ]
}