{
  "name": "multi_terraceplaza_34_ground",
  "refpalette": "deceasedcraft:multi_terraceplaza_34/multi_terraceplaza_34_ground_palette",
  "xsize": 16,
  "zsize": 16,
  "slices": [
    [
      "aaaaaaaabcdefHHH",
      "aaaaaaaabcdgfHHH",
      "hhhhiiiibcdefHHH",
      "ddddjkkkbcdefHHH",
      "ddddjkkkbcdefHHH",
      "lllljkkkbcdefHHH",
      "    jkkkbcdefHHH",
      "    jkkkbcdefHHH",
      "    jkkkbcdgfHHH",
      "    jkkkbcdefHHH",
      "    mkkkbcdefHHH",
      "   nikkkbcdefHHH",
      "ooooikkkbcdgfHHH",
      "hhhhipqqbceefHHH",
      "aaaaaaaaacccfHHH",
      "aaaaaaaaacccfHHH"
    ],
    [
      "        r os    ",
      "        r ot    ",
      "    uwwwr ox    ",
      "    w  yr ox    ",
      "    wAB r ox    ",
      "    wCD r ox    ",
      "    w   r ox    ",
      "    w  yr ox    ",
      "    wy  r ot    ",
      "    w y r os    ",
      "    EFqqu Is    ",
      "   xwJqqr os    ",
      "    wKqqr ot    ",
      "wwwwwK          ",
      "                ",
      "                "
    ],
    [
      "        LM      ",
      "        NMoO    ",
      "        LMo     ",
      "        NMo     ",
      "        NMo     ",
      "        LMo     ",
      "        LMo     ",
      "     FqqNMo     ",
      "     JqqLMoO    ",
      "     KqqNM      ",
      "     K  NMn     ",
      "   x K  LM      ",
      "     P  NM O    ",
      "     Q  NM      ",
      "                ",
      "                "
    ],
    [
      "        LM      ",
      "        NM      ",
      "        LM      ",
      "        NM      ",
      "     FqqNM      ",
      "     JqqLM      ",
      "     KqqLM      ",
      "     K  NM      ",
      "     K  LM      ",
      "     P  NM      ",
      "     Q  NMx     ",
      "                ",
      "                ",
      "                ",
      "                ",
      "                "
    ],
    [
      "        LM      ",
      "     FqqNM      ",
      "     JqqLM      ",
      "     KqqNM      ",
      "     K  NM      ",
      "     K  LM      ",
      "     P  LM      ",
      "     Q  NM      ",
      "                ",
      "                ",
      "          x     ",
      "                ",
      "                ",
      "                ",
      "                ",
      "                "
    ],
    [
      "RRRRSKqqLM      ",
      "RRRRSK  NM      ",
      "RRRRSK  LM      ",
      "RRRRSP  NM      ",
      "     Q  NM      ",
      "                ",
      "                ",
      "                ",
      "                ",
      "                ",
      "                ",
      "                ",
      "                ",
      "                ",
      "                ",
      "                "
    ]
  ]
}