{
  "name": "multi_terraceplaza_34_base2",
  "refpalette": "deceasedcraft:multi_terraceplaza_34/multi_terraceplaza_34_base2_palette",
  "xsize": 16,
  "zsize": 16,
  "slices": [
    [
      "aaaaaaaaaaabcccv",
      "aaaaaaaaaaabcccv",
      "aaaaaaaaaaabcccv",
      "aaaaaaaaaaabcccv",
      "aaaaaaaaaaabcccv",
      "aaaaaaaaaaabcccv",
      "aaaaaaaaaaabcccv",
      "aaaaaaaaaaabcccv",
      "aaaaaaaaaaabcccv",
      "aaaaaaaaaaabcccv",
      "aaaaaaaaaaabcccv",
      "aaaaaaaaaaabcccv",
      "aaaaaaaaaaabcccv",
      "bbbbbbbbbbbbcccv",
      "cccccccccccccccv",
      "vvvvvvvvvvvvvvvv"
    ],
    [
      "         ddbcccv",
      " eeeeee fghbcccv",
      "fijijiikf!hbcccv",
      "fiiijijkflhbcccv",
      " mmmmmm fnhbcccv",
      " eeeeee fohbcccv",
      "fppppppkfqhbcccv",
      "fppppppkfnhbcccv",
      " mmmmmm fghbcccv",
      "         ddbcccv",
      "         rsbcccv",
      "tutwwxyABssbcccv",
      "t!tttB Byssbcccv",
      "bbbbbbbbbbbbcccv",
      "cccccccccccccccv",
      "vvvvvvvvvvvvvvvv"
    ],
    [
      "         ddbcccv",
      "         fCbcccv",
      "  D  D   fEbcccv",
      " FI F D  fCbcccv",
      "         fCbcccv",
      "         fCbcccv",
      " J  KJJ  fCbcccv",
      "  IK J   fCbcccv",
      "         fCbcccv",
      "         ddbcccv",
      "         Lsbcccv",
      "u        ssbcccv",
      " twuwx BAssbcccv",
      "bbbbbbbbbbbbcccv",
      "cccccccccccccccv",
      "vvvvvvvvvvvvvvvv"
    ],
    [
      "         ddbcccv",
      "           bcccv",
      "           bcccv",
      "           bcccv",
      "           bcccv",
      "           bcccv",
      "           bcccv",
      "           bcccv",
      "           bcccv",
      "         ddbcccv",
      "         Msbcccv",
      "         ssbcccv",
      "         ssbcccv",
      "bbbbbbbbbbbbcccv",
      "cccccccccccccccv",
      "vvvvvvvvvvvvvvvv"
    ],
    [
      "         ddbcccv",
      "           bcccv",
      "           bcccv",
      "           bcccv",
      "           bcccv",
      "           bcccv",
      "           bcccv",
      "           bcccv",
      "           bcccv",
      "         ddbcccv",
      "          sbcccv",
      "         ssbcccv",
      "         ssbcccv",
      "bbbbbbbbbbbbcccv",
      "cccccccccccccccv",
      "vvvvvvvvvvvvvvvv"
    ],
    [
      "         ddbcccv",
      "         dNbcccv",
      "         dObcccv",
      "         dNbcccv",
      "         dObcccv",
      "         dNbcccv",
      "         dObcccv",
      "         dNbcccv",
      "         dObcccv",
      "         ddbcccv",
      "          sbcccv",
      "sssssssssssbcccv",
      "         ssbcccv",
      "bbbbbbbbbbbbcccv",
      "cccccccccccccccv",
      "vvvvvvvvvvvvvvvv"
    ]
  ]
}