{
  "name": "multi_laboratory_2_base2",
  "refpalette": "deceasedcraft:multi_laboratory_2/multi_laboratory_2_base2_palette",
  "xsize": 16,
  "zsize": 16,
  "slices": [
    [
      "vabcccccccccccd ",
      "vabcccccccccccd ",
      "vabcccccccccccd ",
      "vabcccccccccccde",
      "vabccccccccfcccd",
      "vabccccccccccccd",
      "vabccccccccccccc",
      "vabccccccccccccc",
      "vabccccccccccccc",
      "vabccccccccccccc",
      "vabccccccccccccc",
      "vabccccccccfcccc",
      "vabccccccccccccc",
      "vabccccccccccccc",
      "vabccccccccccccc",
      "vabccccccccccccc"
    ],
    [
      "vabghiiiij k  l ",
      "vabmhnnnnj o  l ",
      "vabp    q  r  l ",
      "vabs       t  le",
      "vab  uuuuw f  el",
      "vab xy  yr t  Al",
      "vab x BC rDt    ",
      "vab x E  r t    ",
      "vab xy  yr t    ",
      "vab  FFFF  t    ",
      "vab        t  I ",
      "vabtttJKtttfe   ",
      "vab        t    ",
      "vabLM      r    ",
      "vabNN      k    ",
      "vabM    O  o  P "
    ],
    [
      "vab  QRS   T  l ",
      "vab   UV   W  l ",
      "vab        r  l ",
      "vab        t  le",
      "vab  uuuu  f  Xl",
      "vab xY  Z  t   l",
      "vab x  0   1    ",
      "vab x    r 1    ",
      "vab xZ  Zr 1    ",
      "vab  FFFF  1    ",
      "vab        t    ",
      "vabttt23tttfX   ",
      "vab        t    ",
      "vab        r    ",
      "vab4       T    ",
      "vab        W    "
    ],
    [
      "vab        r  l ",
      "vab        r  l ",
      "vab        r  l ",
      "vab        t  le",
      "vab  uuuu  f  5l",
      "vab x6  7r t   l",
      "vab x    r 1    ",
      "vab x    r 1    ",
      "vab x7  7r 1    ",
      "vab  FFFF  1    ",
      "vab        t    ",
      "vabttttttttf5   ",
      "vab        t    ",
      "vab        r    ",
      "vab        r    ",
      "vab        r    "
    ],
    [
      "vab        t  l ",
      "vab        t  l ",
      "vab88888888t  l ",
      "vab     8  t  le",
      "vab     8  f   l",
      "vab  8  8  t   l",
      "vab  8  8  t    ",
      "vab  8  8  t    ",
      "vab88888888t    ",
      "vab        t    ",
      "vab        t    ",
      "vabttttttttf    ",
      "vab        t    ",
      "vab        t    ",
      "vab        t    ",
      "vab        t    "
    ],
    [
      "vab99#99$99%^^l ",
      "vab99&99$99%^^l ",
      "vab99$99$99%^^l ",
      "vab99999999%^^le",
      "vab99999999f^^^l",
      "vab99*99$99%^^^l",
      "vab99#99*99%^^^^",
      "vab99$99*99%^^^^",
      "vab99*99*99%^^^^",
      "vab99999999%^^^^",
      "vab99999999%^^^^",
      "vabttttttttf^^^^",
      "vab99999999%^^^^",
      "vab99999999%^&^^",
      "vab99*99*99%^&^^",
      "vab99*99#99%^&^^"
    ]
  ]
}