{
  "name": "multi_laboratory_2_base3",
  "refpalette": "deceasedcraft:multi_laboratory_2/multi_laboratory_2_base3_palette",
  "xsize": 16,
  "zsize": 16,
  "slices": [
    [
      "vabcccccccccccd ",
      "vabcccccccccccd ",
      "vabcccccccccccd ",
      "vabcccccccccccde",
      "vabccccccccfcccd",
      "vabccccccccccccd",
      "vabccccccccccccc",
      "vabccccccccccccc",
      "vabccccccccccccc",
      "vabccccccccccccc",
      "vabccccccccccccc",
      "vabccccccccfcccc",
      "vabccccccccccccc",
      "vabccccccccccccc",
      "vab!cccccccccccc",
      "vabccccccccccccc"
    ],
    [
      "vab ghhhhi j  k ",
      "vab  l  m  n ok ",
      "vabp q     r  k ",
      "vabs       t  ke",
      "vab u@@@@w f  ek",
      "vab uxyyAw tB Ck",
      "vab uxyyAw tD   ",
      "vab uxyyAw t    ",
      "vab uxEyAw t    ",
      "vab !xyFAw t    ",
      "vab uIIIIw t  J ",
      "vabttttttttfe  K",
      "vabL       t   M",
      "vabNO      r    ",
      "vabPPQ     R    ",
      "vabO    l  S  T "
    ],
    [
      "vab  UVVW  X  k ",
      "vab        Y  k ",
      "vab        r  k ",
      "vab        t  ke",
      "vab Z@@@@0 f  1k",
      "vab Z2  30 t   k",
      "vab Z4  50 6    ",
      "vab Z2  30 6    ",
      "vab Z4  50 6    ",
      "vab Z2F730 6    ",
      "vab ZIIII0 t    ",
      "vabttttttttf1   ",
      "vab        t    ",
      "vab        r    ",
      "vab8       9    ",
      "vab#       $    "
    ],
    [
      "vab        r  k ",
      "vab        r  k ",
      "vab        r  k ",
      "vab        t  ke",
      "vab Z@@@@0 f  %k",
      "vab Z2  30 t   k",
      "vab Z2  30 6    ",
      "vab Z2 ^30 6    ",
      "vab Z27 30 6    ",
      "vab Z2  30 6    ",
      "vab ZIIII0 t    ",
      "vabttttttttf%   ",
      "vab        t    ",
      "vab        r    ",
      "vab        r    ",
      "vab        r    "
    ],
    [
      "vab        t  k ",
      "vab        t  k ",
      "vab        t  k ",
      "vab        t  ke",
      "vab  &**(  f   k",
      "vab  &**(  t   k",
      "vab  &**(  t    ",
      "vab  &**(  t    ",
      "vab  &**(  t    ",
      "vab  &**(  t    ",
      "vab  &**(  t    ",
      "vabttttttttf    ",
      "vab        t    ",
      "vab        t    ",
      "vab        t    ",
      "vab        t    "
    ],
    [
      "vab))+))-))[]]k ",
      "vab))-))+))[]]k ",
      "vab))+))+))[]]k ",
      "vab))))))))[]]ke",
      "vab))))))))f]]]k",
      "vab))+))+))[]]]k",
      "vab))+))+))[]]]]",
      "vab))+))+))[]]]]",
      "vab))+))+))[]]]]",
      "vab))))))))[]]]]",
      "vab))))))))[]]]]",
      "vabttttttttf]]]]",
      "vab))))))))[]]]]",
      "vab))))))))[]{]]",
      "vab))-))+))[]{]]",
      "vab))+))-))[]{]]"
    ]
  ]
}