{
  "name": "multi_laboratory_2_base6",
  "refpalette": "deceasedcraft:multi_laboratory_2/multi_laboratory_2_base6_palette",
  "xsize": 16,
  "zsize": 16,
  "slices": [
    [
      "vabcccccccccccd ",
      "vabcccccccccccd ",
      "vabcccccccccccde",
      "vabcccccccccccdf",
      "vabccccccccgcccd",
      "vabccccccccccccd",
      "vabccccccccccccc",
      "vabccccccccccccc",
      "vabccccccccccccc",
      "vabccccccccccccc",
      "vabccccccccccccc",
      "vabccccccccgcccc",
      "vabccccccccccc!c",
      "vabccccccccccccc",
      "vabccccccccccccc",
      "vabccccccccccccc"
    ],
    [
      "vabh      ij  k ",
      "vabh       j  k ",
      "vab   l    j  k ",
      "vammmm n   o  kf",
      "vab pm     g   k",
      "vammmmqn   r   k",
      "vab   s    j    ",
      "vabh       j    ",
      "vabh      ij    ",
      "vab        j    ",
      "vammmm     t    ",
      "vabuwm     g    ",
      "vammmm      xyyy",
      "vab             ",
      "vabh         A  ",
      "vabh            "
    ],
    [
      "vabBC      D  k ",
      "vabBC         k ",
      "vabE       F  k ",
      "vammkq        kf",
      "vab        g   k",
      "vammk      I   k",
      "vabJ            ",
      "vabK       L    ",
      "vabKC           ",
      "vabE       M    ",
      "vammk           ",
      "vabuwk     g    ",
      "vammk        NO ",
      "vabJ            ",
      "vabKC           ",
      "vab!C           "
    ],
    [
      "vab           k ",
      "vab           k ",
      "vab           k ",
      "vammk         kf",
      "vab        g   k",
      "vammP          k",
      "vab             ",
      "vab             ",
      "vab             ",
      "vab             ",
      "vammk           ",
      "vabuwk     g    ",
      "vammk           ",
      "vab             ",
      "vab             ",
      "vab             "
    ],
    [
      "vabQ          k ",
      "vabQ          k ",
      "vab           k ",
      "vammk         kf",
      "vab  R     g   k",
      "vammk          k",
      "vab             ",
      "vabQ            ",
      "vabQ            ",
      "vab             ",
      "vammk           ",
      "vabuwk     g    ",
      "vammk           ",
      "vab             ",
      "vabQ            ",
      "vabQ            "
    ],
    [
      "vab           k ",
      "vabS          k ",
      "vab           k ",
      "vammk         kf",
      "vab  k     g   k",
      "vammk          k",
      "vab             ",
      "vabS            ",
      "vab             ",
      "vab             ",
      "vammk           ",
      "vabuwk     g    ",
      "vammk           ",
      "vab             ",
      "vabS            ",
      "vab             "
    ]
  ]
}