{
  "name": "multi_laboratory_2_base5",
  "refpalette": "deceasedcraft:multi_laboratory_2/multi_laboratory_2_base5_palette",
  "xsize": 16,
  "zsize": 16,
  "slices": [
    [
      "vab           c ",
      "vadd          c ",
      "vad           c ",
      "vaeec         cf",
      "vab  c     gh  c",
      "vaeec          c",
      "vabd            ",
      "vabd            ",
      "vabd            ",
      "vab             ",
      "vaeec           ",
      "vabijc     g    ",
      "vaeec           ",
      "vab             ",
      "vabd            ",
      "vab             "
    ],
    [
      "vab           c ",
      "vabd          c ",
      "vab           c ",
      "vaeec         cf",
      "vab  c     g   c",
      "vaeec          c",
      "vab             ",
      "vab             ",
      "vabd            ",
      "vab             ",
      "vaeec           ",
      "vabijc     g    ",
      "vaeec           ",
      "vabd            ",
      "vabd            ",
      "vab             "
    ],
    [
      "vabd          c ",
      "vabd          c ",
      "vab           c ",
      "vaeec         cf",
      "vab  c     g   c",
      "vaeec          c",
      "vab             ",
      "vab             ",
      "vabd            ",
      "vab             ",
      "vaeec           ",
      "vab jc     g    ",
      "vaeec           ",
      "vab             ",
      "vabd            ",
      "vab             "
    ],
    [
      "vab           c ",
      "vabd          c ",
      "vab           c ",
      "vaeec         cf",
      "vab  c     g   c",
      "vaeec          c",
      "vab             ",
      "vab             ",
      "vadd            ",
      "vad             ",
      "vaeec           ",
      "vab jc     g    ",
      "vaeec           ",
      "vab             ",
      "vabd            ",
      "vab             "
    ],
    [
      "vab           c ",
      "vabd          c ",
      "vab           c ",
      "vaeec         cf",
      "vab  c     g   c",
      "vaeec          c",
      "vab             ",
      "vab             ",
      "vabd            ",
      "vab             ",
      "vaeec           ",
      "vab jc     g    ",
      "vaeec           ",
      "vab             ",
      "vabd            ",
      "vab             "
    ],
    [
      "vabdkkkkkkkkkkc ",
      "vablkkkkkkkkkkc ",
      "vabdkkkkkkkkkkc ",
      "vaeeeekkkkkkkkcf",
      "vab  ekkkkkgkkkc",
      "vaeeeekkkkkkkkkc",
      "vabdkkkkkkkkkkkk",
      "vabdkkkkkkkkkkkk",
      "vablkkkkkkkkkkkk",
      "vabdkkkkkkkkkkkk",
      "vaeeeekkkkkkkkkk",
      "vab mekkkkkgkkkk",
      "vaeeeekkkkkkkkkk",
      "vabdkkkkkkkkkkkk",
      "vablkkkkkkkkkkkk",
      "vabdkkkkkkkkkkkk"
    ]
  ]
}