{
  "name": "multi_laboratory_2_ground",
  "refpalette": "deceasedcraft:multi_laboratory_2/multi_laboratory_2_ground_palette",
  "xsize": 16,
  "zsize": 16,
  "slices": [
    [
      "zzzzzaavbbbcddc@",
      "zzazaaevbbbcddc@",
      "azzazaevbbbcddc@",
      "zzzazavvbbbcddcc",
      "zazzaavvbbbcdddc",
      "zzaazaevbbbcdddc",
      "zaaaazeebbbcdddd",
      "zzzzzaevbbbcdddd",
      "zzzzzzevbbbcdddd",
      "azzzaaaebbbcdddd",
      "zzzaaaevbbbcdddd",
      "zazazaaebbbcdddd",
      "zzazaeevbbbcdddd",
      "zzzzzaevbbbcdddd",
      "zzaaazevbbbcdddd",
      "zzzazaeebbbcdddd"
    ],
    [
      "  ff    g  h  i ",
      "ff      j  h  i ",
      "        j  h  i ",
      "f f     g  h  ii",
      "   f    k  cl  i",
      "        k  h   i",
      "        k  h    ",
      "f  m    k  no   ",
      " f   f  k  hpo  ",
      "   q    k  nrrol",
      "        k  h  so",
      "f   f   k  c   r",
      "q       k  h   r",
      " m      k  h rrr",
      "f       k  h    ",
      "        k  h    "
    ],
    [
      "        g  t    ",
      "        j  t    ",
      "        g  t    ",
      "        j  t    ",
      "        k  cu   ",
      "        w  t    ",
      "        k  h    ",
      "   ~    k  no   ",
      "        k  hxo  ",
      "        k  nrrou",
      "        k  t  so",
      "        k  c   r",
      "        k  h   r",
      " ~      k  h rrr",
      "        k  h    ",
      "        k  h    "
    ],
    [
      "        j  t    ",
      "        j  t    ",
      "        j  t    ",
      "        j  t    ",
      "        w  cy   ",
      "        A  t    ",
      "        w  h    ",
      "        A  no   ",
      "        w  h o  ",
      "        A  nrroy",
      "        w  t  so",
      "        w  c   r",
      "        w  h   r",
      "        A  h rrr",
      "        w  h    ",
      "        A  h    "
    ],
    [
      "        j  t    ",
      "        j  t    ",
      "        j  t    ",
      "        j  t    ",
      "        w  c    ",
      "        w  t    ",
      "        A  h    ",
      "        A  no   ",
      "        A  hBo  ",
      "        A  h Bo ",
      "        w  t  so",
      "        A  c   C",
      "        A  h   D",
      "        A  h  EF",
      "        A  h    ",
      "        A  h    "
    ],
    [
      "        j  hI   ",
      "        j  hI   ",
      "        j  hI   ",
      "        g  hI   ",
      "        A  cI   ",
      "        A  hI   ",
      "        A  hI   ",
      "        w  no   ",
      "        A  hIo  ",
      "        A  hIIo ",
      "        A  hIIso",
      "        A  cIIII",
      "        w  hIJJI",
      "        A  hIJJI",
      "        A  hIIII",
      "        w  hIIII"
    ]
  ]
}