{
  "name": "multi_laboratory_2_base1",
  "refpalette": "deceasedcraft:multi_laboratory_2/multi_laboratory_2_base1_palette",
  "xsize": 16,
  "zsize": 16,
  "slices": [
    [
      "vabcccccccccccd ",
      "vabcccccccccccd ",
      "vabcccccccccccd ",
      "vabcccccccccccde",
      "vabccccccccfcc!d",
      "vabccccccccccccd",
      "vabccccccccccccc",
      "vabccccccccccccc",
      "vabccccccccccccc",
      "vabccccccccccccc",
      "vabccccccccccccc",
      "vabccccccccfcccc",
      "vabccccccccccccc",
      "vabccccccccccccc",
      "vabccccccccccccc",
      "vabccccccccccccc"
    ],
    [
      "vabg      hi  j ",
      "vabk      hi  j ",
      "vabk    lmhi  j ",
      "vabnopo qrsi  jt",
      "vabiiiiuiiif  tj",
      "vabwww l xxy   j",
      "vabwwA     y  B ",
      "vabCCDm m  y    ",
      "vabA EqFqI y    ",
      "vabgDEJKJI y    ",
      "vabL  M m  y    ",
      "vabNO      ft   ",
      "vabL  m m  P    ",
      "vabg EqrqI P    ",
      "vabk EJQJI R    ",
      "vabk  M M  S    "
    ],
    [
      "vabT       y  j ",
      "vab       Uy  j ",
      "vab        y  j ",
      "vab! p  VW y  jt",
      "vabiiiiXiiif  Yj",
      "vab!AU     y   j",
      "vabAl      y    ",
      "vabC       y    ",
      "vab   Z    y    ",
      "vab0    O  y    ",
      "vab        y    ",
      "vab        fY   ",
      "vab1       P    ",
      "vab2  03   P    ",
      "vab4  l    5    ",
      "vab6       7    "
    ],
    [
      "vabC       y  j ",
      "vab        y  j ",
      "vab        y  j ",
      "vab89##    y  jt",
      "vabiiiiiiiif  $j",
      "vabA     %#y   j",
      "vab        y    ",
      "vabD       y    ",
      "vab        y    ",
      "vab        y    ",
      "vab        y    ",
      "vab        f$   ",
      "vab        P    ",
      "vab        P    ",
      "vab^       P    ",
      "vab&       P    "
    ],
    [
      "vab        y  j ",
      "vab        y  j ",
      "vab        y  j ",
      "vabn       y  jt",
      "vabiiiiiiiif   j",
      "vab        y   j",
      "vab        y    ",
      "vab        y    ",
      "vab        y    ",
      "vab        y    ",
      "vab        y    ",
      "vab        f    ",
      "vab        P    ",
      "vab        P    ",
      "vab        P    ",
      "vab        P    "
    ],
    [
      "vab**(***(*)**+ ",
      "vab**(***(*)**+ ",
      "vab**(***(*)**+ ",
      "vabn*******)**+-",
      "vabiiii[iiif***+",
      "vab********)***+",
      "vab**(***(*)****",
      "vab**(***(*)****",
      "vab**(***(*)****",
      "vab**(***(*)****",
      "vab********)****",
      "vab********f****",
      "vab********)****",
      "vab**(***(*)****",
      "vab**(***(*)****",
      "vab**(***(*)****"
    ]
  ]
}