{
  "name": "multi_laboratory_2_base4",
  "refpalette": "deceasedcraft:multi_laboratory_2/multi_laboratory_2_base4_palette",
  "xsize": 16,
  "zsize": 16,
  "slices": [
    [
      "vabcccccccccccd ",
      "vabcccccccccccd ",
      "vabcccccccccccd ",
      "vabcccccccccccde",
      "vabccccccccfcccd",
      "vabccccccccccccd",
      "vabccccccccccccc",
      "vabccccccccccccc",
      "vabcccc!cccccccc",
      "vabccccccccccccc",
      "vabccccccccccccc",
      "vabccccccccfcccc",
      "vabccccccccccccc",
      "vabccccccccccccc",
      "vabccccccccccccc",
      "vabccccccccccccc"
    ],
    [
      "vabg hhhh  i  j ",
      "vabk llll  m  j ",
      "vabkno poq q  j ",
      "vab  rrrr  s  je",
      "vab  llll  f  ej",
      "vab not oq s  uj",
      "vab  rrrr  s    ",
      "vab  llll  s    ",
      "vab no woq s    ",
      "vab  rrrr  s    ",
      "vab       xs  y ",
      "vabsssABsssfe   ",
      "vab        s    ",
      "vabCD      q    ",
      "vabEE      i    ",
      "vabD       m  F "
    ],
    [
      "vab  I Jx  K  j ",
      "vab  llll  L  j ",
      "vab nM  Mq q  j ",
      "vab  rrrr  s  je",
      "vab  llll  f  Nj",
      "vab nO  Oq s   j",
      "vab  rrrr  P    ",
      "vab  llll  P    ",
      "vab nO  Oq P    ",
      "vab  rrrr  P    ",
      "vab        s    ",
      "vabsssQRsssfN   ",
      "vab        s    ",
      "vab        q    ",
      "vabS       K    ",
      "vab        L    "
    ],
    [
      "vab        q  j ",
      "vab  llll  q  j ",
      "vab nT  Tq q  j ",
      "vab  rrrr  s  je",
      "vab  llll  f  Uj",
      "vab nV  Vq s   j",
      "vab  rrrr  P    ",
      "vab  llll  P    ",
      "vab nV  Vq P    ",
      "vab  rrrr  P    ",
      "vab        s    ",
      "vabssssssssfU   ",
      "vab        s    ",
      "vab        q    ",
      "vab        q    ",
      "vab        q    "
    ],
    [
      "vab        s  j ",
      "vab        s  j ",
      "vabWWWWWWWWs  j ",
      "vab     W  s  je",
      "vab     W  f   j",
      "vab  W  W  s   j",
      "vab  W  W  s    ",
      "vab  W  W  s    ",
      "vabWWWWWWWWs    ",
      "vab        s    ",
      "vab        s    ",
      "vabssssssssf    ",
      "vab        s    ",
      "vab        s    ",
      "vab        s    ",
      "vab        s    "
    ],
    [
      "vabXXYXXZXX011j ",
      "vabXXZXXYXX011j ",
      "vabXXYXXYXX011j ",
      "vabXXXXXXXX011je",
      "vabXXXXXXXXf111j",
      "vabXXYXXYXX0111j",
      "vabXXYXXYXX01111",
      "vabXXYXXYXX01111",
      "vabXXYXXYXX01111",
      "vabXXXXXXXX01111",
      "vabXXXXXXXX01111",
      "vabssssssssf1111",
      "vabXXXXXXXX01111",
      "vabXXXXXXXX01211",
      "vabXXYXXYXX01211",
      "vabXXYXXYXX01211"
    ]
  ]
}