{
  "name": "building_fastfood_ground",
  "refpalette": "deceasedcraft:building_fastfood/building_fastfood_ground_palette",
  "xsize": 16,
  "zsize": 16,
  "slices": [
    [
      "aaaaaaaaaaaaaaaa",
      "aaaaaaaaaaaaaaaa",
      "aabbbbbbbbbbbbaa",
      "aabccccccccccbaa",
      "aabccccccccccbaa",
      "aabccccccccccbaa",
      "aabccccccccccbaa",
      "aadccccccccccbaa",
      "aadccccccccccbaa",
      "aadccccccccccdaa",
      "aadccccccccccdee",
      "aadccccccccccdee",
      "eeddddddddddddee",
      "ffffffffffffffff",
      "HHHHHHHHHHHHHHHH",
      "HHHHHHHHHHHHHHHH"
    ],
    [
      "                ",
      "                ",
      "  ggggghhggggg  ",
      "  giji kl    g  ",
      "  g      m m g  ",
      "  giji       g  ",
      "  g    nnnnn g  ",
      " opiji q   r g  ",
      " stuuuwuunuuug  ",
      " xty A BCDEEFpo ",
      " xtI J       to ",
      " Kt!LJMN OPPOu  ",
      " QuRuuRuuRRRR   ",
      "                ",
      "                ",
      "                "
    ],
    [
      "                ",
      "                ",
      "  ggggg  ggggg  ",
      "  g    ST    g  ",
      "  g          g  ",
      "  g U        g  ",
      "  g     VWVW g  ",
      " op          g  ",
      " stuuu uuXuuug  ",
      " xtY Z 0  123po ",
      " xt4 J       to ",
      " Kt56J5  7  8u  ",
      " Qu uu uu       ",
      "  9             ",
      "                ",
      "                "
    ],
    [
      "                ",
      "                ",
      "  gggggggggggg  ",
      "  g          g  ",
      "  g          g  ",
      "  g          g  ",
      "  g          g  ",
      " op #        g  ",
      " stuuu$uu$uuug  ",
      " xt% J ^ &**(po ",
      " xt  J       to ",
      " Kt)+J)  ))))u  ",
      " Qu-uu-uu-----  ",
      "                ",
      "                ",
      "                "
    ],
    [
      "                ",
      " [[[[[[[[[[[[[[ ",
      " [pppppppppppp[ ",
      " [p          p[ ",
      " [p          p[ ",
      " [p ]        p[ ",
      " [p          p[ ",
      " {p    }}}}} p[ ",
      " stuuuuuuuuuup[ ",
      " xt|||;  ;  ;p{ ",
      " xt|||       to ",
      " Kt|||:::'<>,u[ ",
      " .uuuuuuuuuuuu[ ",
      " [[[[[[[[[[[[[[ ",
      " [[[[[[[[[[[[[[ ",
      "                "
    ],
    [
      "                ",
      "                ",
      "  tttttttttttt  ",
      "  t??????????t  ",
      "  t??????????t  ",
      "  t??????????t  ",
      "  t??????????t  ",
      "  t??????????t  ",
      " st??????????t  ",
      " x////;//;//;t  ",
      " x//?????????t  ",
      " Kt??????????t  ",
      "  tttttttttttt  ",
      "                ",
      "                ",
      "                "
    ]
  ]
}