{
  "name": "building_fastfood_ground_180",
  "refpalette": "deceasedcraft:building_fastfood/building_fastfood_ground_palette_180",
  "xsize": 16,
  "zsize": 16,
  "slices": [
    [
      "HHHHHHHHHHHHHHHH",
      "HHHHHHHHHHHHHHHH",
      "ffffffffffffffff",
      "eeddddddddddddee",
      "eedccccccccccdaa",
      "eedccccccccccdaa",
      "aadccccccccccdaa",
      "aabccccccccccdaa",
      "aabccccccccccdaa",
      "aabccccccccccbaa",
      "aabccccccccccbaa",
      "aabccccccccccbaa",
      "aabccccccccccbaa",
      "aabbbbbbbbbbbbaa",
      "aaaaaaaaaaaaaaaa",
      "aaaaaaaaaaaaaaaa"
    ],
    [
      "                ",
      "                ",
      "                ",
      "   RRRRuuRuuRuQ ",
      "  uOPPO NMJL!tK ",
      " ot       J Itx ",
      " opFEEDCB A ytx ",
      "  guuunuuwuuuts ",
      "  g r   q ijipo ",
      "  g nnnnn    g  ",
      "  g       ijig  ",
      "  g m m      g  ",
      "  g    lk ijig  ",
      "  ggggghhggggg  ",
      "                ",
      "                "
    ],
    [
      "                ",
      "                ",
      "             9  ",
      "       uu uu uQ ",
      "  u8  7  5J65tK ",
      " ot       J 4tx ",
      " op321  0 Z Ytx ",
      "  guuuXuu uuuts ",
      "  g          po ",
      "  g WVWV     g  ",
      "  g        U g  ",
      "  g          g  ",
      "  g    TS    g  ",
      "  ggggg  ggggg  ",
      "                ",
      "                "
    ],
    [
      "                ",
      "                ",
      "                ",
      "  -----uu-uu-uQ ",
      "  u))))  )J+)tK ",
      " ot       J  tx ",
      " op(**& ^ J %tx ",
      "  guuu$uu$uuuts ",
      "  g        # po ",
      "  g          g  ",
      "  g          g  ",
      "  g          g  ",
      "  g          g  ",
      "  gggggggggggg  ",
      "                ",
      "                "
    ],
    [
      "                ",
      " [[[[[[[[[[[[[[ ",
      " [[[[[[[[[[[[[[ ",
      " [uuuuuuuuuuuu. ",
      " [u,><':::|||tK ",
      " ot       |||tx ",
      " {p;  ;  ;|||tx ",
      " [puuuuuuuuuuts ",
      " [p }}}}}    p{ ",
      " [p          p[ ",
      " [p        ] p[ ",
      " [p          p[ ",
      " [p          p[ ",
      " [pppppppppppp[ ",
      " [[[[[[[[[[[[[[ ",
      "                "
    ],
    [
      "                ",
      "                ",
      "                ",
      "  tttttttttttt  ",
      "  t??????????tK ",
      "  t?????????//x ",
      "  t;//;//;////x ",
      "  t??????????ts ",
      "  t??????????t  ",
      "  t??????????t  ",
      "  t??????????t  ",
      "  t??????????t  ",
      "  t??????????t  ",
      "  tttttttttttt  ",
      "                ",
      "                "
    ]
  ]
}