{
  "name": "building_fastfood_ground_90",
  "refpalette": "deceasedcraft:building_fastfood/building_fastfood_ground_palette_90",
  "xsize": 16,
  "zsize": 16,
  "slices": [
    [
      "aaaaaaaaaaeeefHH",
      "aaaaaaaaaaeeefHH",
      "aabbbbbbbddddfHH",
      "aabcccccccccdfHH",
      "aabcccccccccdfHH",
      "aabcccccccccdfHH",
      "aabcccccccccdfHH",
      "aabcccccccccdfHH",
      "aabcccccccccdfHH",
      "aabcccccccccdfHH",
      "aabcccccccccdfHH",
      "aabcccccccccdfHH",
      "aabcccccccccdfHH",
      "aabbbbbddddddfHH",
      "aaaaaaaaaaaaefHH",
      "aaaaaaaaaaaaefHH"
    ],
    [
      "                ",
      "         oo     ",
      "  gggggggptu    ",
      "  g     uF OR   ",
      "  g m nruE PR   ",
      "  g   n uE PR   ",
      "  g m n nD OR   ",
      "  hl  n uC  u   ",
      "  hk  nquB Nu   ",
      "  g     w  MR   ",
      "  gi i iuAJJu   ",
      "  gj j ju  Lu   ",
      "  gi i iuyI!R   ",
      "  gggggpttttu   ",
      "       osxxKQ   ",
      "                "
    ],
    [
      "                ",
      "         oo     ",
      "  gggggggptu    ",
      "  g     u3 8    ",
      "  g   W u2      ",
      "  g   V u1      ",
      "  g   W X  7    ",
      "   T  V u   u   ",
      "   S    u0  u   ",
      "  g        5    ",
      "  g     uZJJu   ",
      "  g  U  u  6u   ",
      "  g     uY45    ",
      "  gggggpttttu9  ",
      "       osxxKQ   ",
      "                "
    ],
    [
      "                ",
      "         oo     ",
      "  gggggggptu-   ",
      "  g     u( )-   ",
      "  g     u* )-   ",
      "  g     u* )-   ",
      "  g     $& )-   ",
      "  g     u   u   ",
      "  g     u^  u   ",
      "  g     $  )-   ",
      "  g     uJJJu   ",
      "  g    #u  +u   ",
      "  g     u% )-   ",
      "  gggggpttttu   ",
      "       osxxKQ   ",
      "                "
    ],
    [
      "                ",
      " [[[[[[[[{o[[[[ ",
      " [pppppppptuu[[ ",
      " [p     u; ,u[[ ",
      " [p    }u  >u[[ ",
      " [p    }u  <u[[ ",
      " [p    }u; 'u[[ ",
      " [p    }u  :u[[ ",
      " [p    }u  :u[[ ",
      " [p     u; :u[[ ",
      " [p     u|||u[[ ",
      " [p  ]  u|||u[[ ",
      " [p     u|||u[[ ",
      " [ppppppttttu[[ ",
      " [[[[[[{sxxK.[[ ",
      "                "
    ],
    [
      "                ",
      "                ",
      "  ttttttttttt   ",
      "  t??????;??t   ",
      "  t??????/??t   ",
      "  t??????/??t   ",
      "  t??????;??t   ",
      "  t??????/??t   ",
      "  t??????/??t   ",
      "  t??????;??t   ",
      "  t??????/??t   ",
      "  t??????/??t   ",
      "  t??????//?t   ",
      "  ttttttt//tt   ",
      "        sxxK    ",
      "                "
    ]
  ]
}