{
  "name": "building_fastfood_ground_270",
  "refpalette": "deceasedcraft:building_fastfood/building_fastfood_ground_palette_270",
  "xsize": 16,
  "zsize": 16,
  "slices": [
    [
      "HHfeaaaaaaaaaaaa",
      "HHfeaaaaaaaaaaaa",
      "HHfddddddbbbbbaa",
      "HHfdcccccccccbaa",
      "HHfdcccccccccbaa",
      "HHfdcccccccccbaa",
      "HHfdcccccccccbaa",
      "HHfdcccccccccbaa",
      "HHfdcccccccccbaa",
      "HHfdcccccccccbaa",
      "HHfdcccccccccbaa",
      "HHfdcccccccccbaa",
      "HHfdcccccccccbaa",
      "HHfddddbbbbbbbaa",
      "HHfeeeaaaaaaaaaa",
      "HHfeeeaaaaaaaaaa"
    ],
    [
      "                ",
      "   QKxxso       ",
      "   uttttpggggg  ",
      "   R!Iyui i ig  ",
      "   uL  uj j jg  ",
      "   uJJAui i ig  ",
      "   RM  w     g  ",
      "   uN Buqn  kh  ",
      "   u  Cu n  lh  ",
      "   RO Dn n m g  ",
      "   RP Eu n   g  ",
      "   RP Eurn m g  ",
      "   RO Fu     g  ",
      "    utpggggggg  ",
      "     oo         ",
      "                "
    ],
    [
      "                ",
      "   QKxxso       ",
      "  9uttttpggggg  ",
      "    54Yu     g  ",
      "   u6  u  U  g  ",
      "   uJJZu     g  ",
      "    5        g  ",
      "   u  0u    S   ",
      "   u   u V  T   ",
      "    7  X W   g  ",
      "      1u V   g  ",
      "      2u W   g  ",
      "    8 3u     g  ",
      "    utpggggggg  ",
      "     oo         ",
      "                "
    ],
    [
      "                ",
      "   QKxxso       ",
      "   uttttpggggg  ",
      "   -) %u     g  ",
      "   u+  u#    g  ",
      "   uJJJu     g  ",
      "   -)  $     g  ",
      "   u  ^u     g  ",
      "   u   u     g  ",
      "   -) &$     g  ",
      "   -) *u     g  ",
      "   -) *u     g  ",
      "   -) (u     g  ",
      "   -utpggggggg  ",
      "     oo         ",
      "                "
    ],
    [
      "                ",
      " [[.Kxxs{[[[[[[ ",
      " [[uttttpppppp[ ",
      " [[u|||u     p[ ",
      " [[u|||u  ]  p[ ",
      " [[u|||u     p[ ",
      " [[u: ;u     p[ ",
      " [[u:  u}    p[ ",
      " [[u:  u}    p[ ",
      " [[u' ;u}    p[ ",
      " [[u<  u}    p[ ",
      " [[u>  u}    p[ ",
      " [[u, ;u     p[ ",
      " [[uutpppppppp[ ",
      " [[[[o{[[[[[[[[ ",
      "                "
    ],
    [
      "                ",
      "    Kxxs        ",
      "   tt//ttttttt  ",
      "   t?//??????t  ",
      "   t??/??????t  ",
      "   t??/??????t  ",
      "   t??;??????t  ",
      "   t??/??????t  ",
      "   t??/??????t  ",
      "   t??;??????t  ",
      "   t??/??????t  ",
      "   t??/??????t  ",
      "   t??;??????t  ",
      "   ttttttttttt  ",
      "                ",
      "                "
    ]
  ]
}