{
  "name": "building_office4_base1_270",
  "refpalette": "deceasedcraft:building_office4/building_office4_base1_palette_270",
  "xsize": 16,
  "zsize": 16,
  "slices": [
    [
      "vvvvvvvvvvvvvvvv",
      "vaaaaaaaaaaaaaav",
      "va  bc   dcb  av",
      "va  b      b  av",
      "vabb        bbav",
      "vac          cav",
      "va     bb     av",
      "va    b  b    av",
      "va    b  b    av",
      "va     bb     av",
      "vac          cav",
      "vabb        bbav",
      "va  b      b  av",
      "va  bc    cb  av",
      "vaaaaaaaaaaaaaav",
      "vvvvvvvvvvvvvvvv"
    ],
    [
      "vvvvvvvvvvvvvvvv",
      "vaaaaaaaaaaaaaav",
      "va  bc   dcb  av",
      "va  b      b  av",
      "vabb        bbav",
      "vac          cav",
      "va     bb     av",
      "va    b  b    av",
      "va    b  b    av",
      "va     bb     av",
      "vac          cav",
      "vabb        bbav",
      "va  b      b  av",
      "va  bc    cb  av",
      "vaaaaaaaaaaaaaav",
      "vvvvvvvvvvvvvvvv"
    ],
    [
      "vvvvvvvvvvvvvvvv",
      "vaaaaaaaaaaaaaav",
      "va  bc   dcb  av",
      "va  b      b  av",
      "vabb        bbav",
      "vac          cav",
      "va     bb     av",
      "va    b  b    av",
      "va    b  b    av",
      "va     bb     av",
      "vac          cav",
      "vabb        bbav",
      "va  b      b  av",
      "va ebc    cb  av",
      "vaaaaaaaaaaaaaav",
      "vvvvvvvvvvvvvvvv"
    ],
    [
      "vvvvvvvvvvvvvvvv",
      "vaaaaaaaaaaaaaav",
      "va~~bc   dcb~~av",
      "va~~b      b~~av",
      "vabb        bbav",
      "vac          cav",
      "vaf   gbbg   fav",
      "vaf   b~~b   fav",
      "vaffffi~~hffffav",
      "vaf    bbg   fav",
      "vac          cav",
      "vabb        bbav",
      "vae b      b~~av",
      "va  bcffffcb~~av",
      "vaaaaaaaaaaaaaav",
      "vvvvvvvvvvvvvvvv"
    ],
    [
      "vvvvvvvvvvvvvvvv",
      "vaaaaaaaaaaaaaav",
      "vajjkc   dckjjav",
      "vajjko    nkjjav",
      "vakkk      kkkav",
      "vacl   mm   lcav",
      "va    kkkk    av",
      "va   nkppko   av",
      "va   nkppko   av",
      "va    kkkk    av",
      "vacm   ll   mcav",
      "vakkk      kkkav",
      "vaeeko    nkjjav",
      "va ekc    ckjjav",
      "vaaaaaaaaaaaaaav",
      "vvvvvvvvvvvvvvvv"
    ],
    [
      "vvvvvvvvvvvvvvvv",
      "vaaaaaaaaaaaaaav",
      "vaqaacaaadcaaqav",
      "vaaaaaaaaaaaaaav",
      "vaaaaaaaaaaaaaav",
      "vacaaaaaaaaaacav",
      "vaaaaaaaaaaaaaav",
      "vaaaaaaaaaaaaaav",
      "vaaaaaaaaaaaaaav",
      "vaaaaaaaaaaaaaav",
      "vacaaaaaaaaaacav",
      "vaaaaaaaaaaaaaav",
      "vaaaaaaaaaaaaaav",
      "vaqaacaaaacaaqav",
      "vaaaaaaaaaaaaaav",
      "vvvvvvvvvvvvvvvv"
    ]
  ]
}