{
  "name": "building_office4_floor1_180",
  "refpalette": "deceasedcraft:building_office4/building_office4_floor1_palette_180",
  "xsize": 16,
  "zsize": 16,
  "slices": [
    [
      "                ",
      " abbbcbbbbcbbba ",
      " bdddc    cdddb ",
      " bd   mmmm   db ",
      " bd          db ",
      " cc        gfcc ",
      " b         hlkb ",
      " bi        hj b ",
      " bi        h  b ",
      " b         h  b ",
      " cc        gfcc ",
      " bd          db ",
      " bd   eeee   db ",
      " bdddc    cdddb ",
      " abbbcbbbbcbbba ",
      "                "
    ],
    [
      "                ",
      "  obbcbbbbcbbn  ",
      " sqqqc    cqqqs ",
      " bq   mmmm   qb ",
      " bq          qb ",
      " cc        gfcc ",
      " b         h  b ",
      " b         hr b ",
      " bi        hj b ",
      " b         h  b ",
      " cc        gfcc ",
      " bq          qb ",
      " bq   eeee   qb ",
      " pqqqc    cqqqp ",
      "  obbcbbbbcbbn  ",
      "                "
    ],
    [
      "                ",
      "   bbcbbbbcbb   ",
      "  qqqc    cqqq  ",
      " bq   mmmm   qb ",
      " bq          qb ",
      " cc        gfcc ",
      " b         h  b ",
      " bi        h  b ",
      " b         hr b ",
      " b         hjtb ",
      " cc        gfcc ",
      " bq          qb ",
      " bq   eeee   qb ",
      "  qqqc    cqqq  ",
      "   bbcbbbbcbb   ",
      "                "
    ],
    [
      "                ",
      "   obcbbbbcbn   ",
      "  qqqc    cqqq  ",
      " sq   mmmm   qs ",
      " bq          qb ",
      " cc        gfcc ",
      " b         h  b ",
      " b         h  b ",
      " bi        h lb ",
      " b         hwub ",
      " cc        gfcc ",
      " bq          qb ",
      " pq   eeee   qp ",
      "  qqqc    cqqq  ",
      "   obcbbbbcbn   ",
      "                "
    ],
    [
      "                ",
      "   obcbbbbcbn   ",
      "  qqqc~~~~cqqq  ",
      " sq   mmmm   qs ",
      " bq          qb ",
      " cc        gfcc ",
      " b         h  b ",
      " b         h lb ",
      " b         h kb ",
      " b         h  b ",
      " cc        gfcc ",
      " bq          qb ",
      " pq   eeee   qp ",
      "  qqqc~~~~cqqq  ",
      "   obcbbbbcbn   ",
      "                "
    ],
    [
      "                ",
      "   obcbbbbcbn   ",
      "  qqqcxxFxcqqq  ",
      " sqyyABBBBAyyqs ",
      " bqyyABBBBAyyqb ",
      " ccyyABBBBAgfcc ",
      " bEyyABBBBAC lb ",
      " bDyyABBBBAC kb ",
      " bEyyABBBBAC  b ",
      " bDyyABBBBAC  b ",
      " ccyyABBBBAgfcc ",
      " bqyyABBBBAyyqb ",
      " pqyyABBBBAyyqp ",
      "  qqqcxxxxcqqq  ",
      "   obcbbbbcbn   ",
      "                "
    ]
  ]
}