{
  "name": "building_office4_floor3_90",
  "refpalette": "deceasedcraft:building_office4/building_office4_floor3_palette_90",
  "xsize": 16,
  "zsize": 16,
  "slices": [
    [
      "                ",
      "   gbcbbbbcbo   ",
      "  eeeckkkkceee  ",
      " deffffffffffed ",
      " befiiiiiiiifeb ",
      " ccfiiiiiiiifcc ",
      " bffiiiiiiiiffb ",
      " bffiiiiiiiiffb ",
      " bffiiiiiiiiffb ",
      " bffiiiiiiiiffb ",
      " ccfiiiiiiiifcc ",
      " behhjjjjjjifeb ",
      " aehhj  lnjffea ",
      "  eeec   mceee  ",
      "   gbcbbbbcbo   ",
      "                "
    ],
    [
      "                ",
      "   gbcbbbbcbo   ",
      "  pppcKMKOcppp  ",
      " dp          pd ",
      " bp          pb ",
      " cc  EE  EE  cc ",
      " bq  DJ  DJ  Sb ",
      " br xCI xCI  Tb ",
      " br  CIL CIR Tb ",
      " bq  BF  BFQ Sb ",
      " ccswAAAAAA  cc ",
      " bp ukkkkkk  pb ",
      " ap ty lN P  pa ",
      "  pppc    cppp  ",
      "   gbcbbbbcbo   ",
      "                "
    ],
    [
      "                ",
      "   gbcbbbbcbo   ",
      "  pppc# $&cppp  ",
      " dp          pd ",
      " bp          pb ",
      " cc          cc ",
      " bX  49  ^(  -b ",
      " bW  38  38  +b ",
      " bV  27  27  1b ",
      " bU  16  %   )b ",
      " ccYZ000000  cc ",
      " bp  kkkkkk  pb ",
      " ap  ylN  *  pa ",
      "  pppc5   cppp  ",
      "   gbcbbbbcbo   ",
      "                "
    ],
    [
      "                ",
      "   gbcbbbbcbo   ",
      "  pppc    cppp  ",
      " dp          pd ",
      " bp          pb ",
      " cc          cc ",
      " b            b ",
      " b            b ",
      " b            b ",
      " b            b ",
      " cc[Z000000  cc ",
      " bp ]kkkkkk  pb ",
      " ap  y}   |  pa ",
      "  pppc{n  cppp  ",
      "   gbcbbbbcbo   ",
      "                "
    ],
    [
      "                ",
      "   gbcbbbbcbo   ",
      "  pppc    cppp  ",
      " dp          pd ",
      " bp          pb ",
      " cc          cc ",
      " b            b ",
      " b            b ",
      " b            b ",
      " b            b ",
      " cc;:''''''  cc ",
      " bp !kkkkkk  pb ",
      " ap  y    y  pa ",
      "  pppc mn cppp  ",
      "   gbcbbbbcbo   ",
      "                "
    ],
    [
      "                ",
      "   gbcbbbbcbo   ",
      "  pppc><<>cppp  ",
      " dp..........pd ",
      " bp..........pb ",
      " cc..........cc ",
      " b>..........>b ",
      " b<..........>b ",
      " b<..........>b ",
      " b<..........<b ",
      " cc..........cc ",
      " bp,,kkkkkk,,pb ",
      " ap,,y   5y,,pa ",
      "  pppc  mncppp  ",
      "   gbcbbbbcbo   ",
      "                "
    ]
  ]
}