{
  "name": "building_office4_floor2",
  "refpalette": "deceasedcraft:building_office4/building_office4_floor2_palette",
  "xsize": 16,
  "zsize": 16,
  "slices": [
    [
      "                ",
      "   abcbbbbcbd   ",
      "  eeecffffceee  ",
      " gehhffffffffeg ",
      " behhiiiiiiifeb ",
      " ccjjiiiiiiifcc ",
      " b  jiiiiiiifkb ",
      " b  jiiiiiiifkb ",
      " b ljiiiiiiifkb ",
      " bmnjiiiiiiifkb ",
      " ccjjiiiiiiifcc ",
      " befiiiiiiiifeb ",
      " oeffffffffffeo ",
      "  eeecffffceee  ",
      "   abcbbbbcbd   ",
      "                "
    ],
    [
      "                ",
      "   abcbbbbcbd   ",
      "  pppcqrrqcppp  ",
      " gp  s       pg ",
      " bptuw  x    pb ",
      " ccykABCCDE  cc ",
      " b  kAFIIJE KLb ",
      " b lkAM      Nb ",
      " b OkA  x    Lb ",
      " b  kABCCDE  Pb ",
      " ccQkAFIIJE  cc ",
      " bp    R     pb ",
      " op    S     po ",
      "  pppcTUUTcppp  ",
      "   abcbbbbcbd   ",
      "                "
    ],
    [
      "                ",
      "   abcbbbbcbd   ",
      "  pppcVWXYcppp  ",
      " gp  Z       pg ",
      " bp  0       pb ",
      " ccyk12345   cc ",
      " b6lk!X789   #b ",
      " b Ok1        b ",
      " b  k1       $b ",
      " b  k1%^4    &b ",
      " cc*k1W78(   cc ",
      " bp          pb ",
      " op          po ",
      "  pppc )+5cppp  ",
      "   abcbbbbcbd   ",
      "                "
    ],
    [
      "                ",
      "   abcbbbbcbd   ",
      "  pppc    cppp  ",
      " gp  -       pg ",
      " bp [0       pb ",
      " ccyk1       cc ",
      " b]{k1        b ",
      " bn k1        b ",
      " b  k1        b ",
      " b  k1        b ",
      " cc}k1       cc ",
      " bp          pb ",
      " op          po ",
      "  pppc    cppp  ",
      "   abcbbbbcbd   ",
      "                "
    ],
    [
      "                ",
      "   abcbbbbcbd   ",
      "  pppc    cppp  ",
      " gp  |       pg ",
      " bp  ;       pb ",
      " ccyk:       cc ",
      " b  k:        b ",
      " bm k:        b ",
      " bn k:        b ",
      " b  k:        b ",
      " ccyk:       cc ",
      " bp          pb ",
      " op          po ",
      "  pppc    cppp  ",
      "   abcbbbbcbd   ",
      "                "
    ],
    [
      "                ",
      "   abcbbbbcbd   ",
      "  pppc''''cppp  ",
      " gp<<>>>>>>>>pg ",
      " bp<<>>>>>>>>pb ",
      " ccyk>>>>>>>>cc ",
      " b  k>>>>>>>>,b ",
      " b  k>>>>>>>>,b ",
      " bm k>>>>>>>>'b ",
      " bn6k>>>>>>>>'b ",
      " ccyk>>>>>>>>cc ",
      " bp<<>>>>>>>>pb ",
      " op<<>>>>>>>>po ",
      "  pppc''',cppp  ",
      "   abcbbbbcbd   ",
      "                "
    ]
  ]
}