{
  "name": "building_office4_top_270",
  "refpalette": "deceasedcraft:building_office4/building_office4_top_palette_270",
  "xsize": 16,
  "zsize": 16,
  "slices": [
    [
      "                ",
      "   mbcbbbbcbg   ",
      "  eeecl   ceee  ",
      " aehffffffffhea ",
      " befiiiiiiiifeb ",
      " ccfiikiikiifcc ",
      " bffiikkkkiiffb ",
      " bffiijkkjiiffb ",
      " bffiiijjiiiffb ",
      " bffijkiikjiffb ",
      " ccfijjiijjifcc ",
      " befiiiiiiiifeb ",
      " dehffffffffhed ",
      "  eeecffffceee  ",
      "   mbcbbbbcbg   ",
      "                "
    ],
    [
      "                ",
      "   mbcbbbbcbg   ",
      "  nnno    onnn  ",
      " anstt    ttsna ",
      " bnt        tnb ",
      " cot        toc ",
      " by          pb ",
      " bA          qb ",
      " bA          qb ",
      " bB          rb ",
      " cot        toc ",
      " bnt        tnb ",
      " dnstt    ttsnd ",
      "  nnnoxwwuonnn  ",
      "   mbcbbbbcbg   ",
      "                "
    ],
    [
      "                ",
      "   mbcbbbbcbg   ",
      "  nnno    onnn  ",
      " anC        Cna ",
      " bn          nb ",
      " co          oc ",
      " b            b ",
      " b            b ",
      " b            b ",
      " b            b ",
      " co          oc ",
      " bn          nb ",
      " dnC        Cnd ",
      "  nnno    onnn  ",
      "   mbcbbbbcbg   ",
      "                "
    ],
    [
      "                ",
      "   mbcFFFFcbg   ",
      "  nnnoEEEEonnn  ",
      " an          na ",
      " bn          nb ",
      " co          oc ",
      " JE          ED ",
      " JE          ED ",
      " JE          ED ",
      " JE          ED ",
      " co          oc ",
      " bn          nb ",
      " dn          nd ",
      "  nnnoEEEEonnn  ",
      "   mbcIIIIcbg   ",
      "                "
    ],
    [
      "                ",
      "   mb      bg   ",
      "  nnnonnnnonnn  ",
      " an          na ",
      " bn          nb ",
      "  o          o  ",
      "  n          n  ",
      "  n          n  ",
      "  n          n  ",
      "  n          n  ",
      "  o          o  ",
      " bn          nb ",
      " dn          nd ",
      "  nnnonnnnonnn  ",
      "   mb      bg   ",
      "                "
    ],
    [
      "                ",
      "   mg      mg   ",
      "  nnnonnnnonnn  ",
      " an          na ",
      " dn          nd ",
      "  o          o  ",
      "  n          n  ",
      "  n          n  ",
      "  n          n  ",
      "  n          n  ",
      "  o          o  ",
      " an          na ",
      " dn          nd ",
      "  nnnonnnnonnn  ",
      "   mg      mg   ",
      "                "
    ],
    [
      "                ",
      "   m        g   ",
      "   nnonnnnonn   ",
      " an          na ",
      "  n          n  ",
      "  o          o  ",
      "  n          n  ",
      "  n          n  ",
      "  n          n  ",
      "  n          n  ",
      "  o          o  ",
      "  n          n  ",
      " dn          nd ",
      "   nnonnnnonn   ",
      "   m        g   ",
      "                "
    ],
    [
      "                ",
      "                ",
      "   nnonnnnonn   ",
      "  n          n  ",
      "  n          n  ",
      "  o          o  ",
      "  n          n  ",
      "  n          n  ",
      "  n          n  ",
      "  n          n  ",
      "  o          o  ",
      "  n          n  ",
      "  n          n  ",
      "   nnonnnnonn   ",
      "                ",
      "                "
    ],
    [
      "                ",
      "                ",
      "   nnonnnnonn   ",
      "  nnnonnnnonnn  ",
      "  nn        nn  ",
      "  oo        oo  ",
      "  nn        nn  ",
      "  nn        nn  ",
      "  nn        nn  ",
      "  nn        nn  ",
      "  oo        oo  ",
      "  nn        nn  ",
      "  nnnonnnnonnn  ",
      "   nnonnnnonn   ",
      "                ",
      "                "
    ],
    [
      "                ",
      "                ",
      "                ",
      "   nnonnnnonn   ",
      "   nnonnnnonn   ",
      "   ooKooooKoo   ",
      "   nnoKKKKonn   ",
      "   nnoKKKKonn   ",
      "   nnoKKKKonn   ",
      "   nnoKKKKonn   ",
      "   ooKooooKoo   ",
      "   nnonnnnonn   ",
      "   nnonnnnonn   ",
      "                ",
      "                ",
      "                "
    ]
  ]
}