{
  "name": "building_office4_top",
  "refpalette": "deceasedcraft:building_office4/building_office4_top_palette",
  "xsize": 16,
  "zsize": 16,
  "slices": [
    [
      "                ",
      "   abcbbbbcbd   ",
      "  eeecffffceee  ",
      " gehffffffffheg ",
      " befiiiiiiiifeb ",
      " ccfiiiiijjifcc ",
      " b fikkjikjiffb ",
      " b fiikkjiiiffb ",
      " b fiikkjiiiffb ",
      " blfikkjikjiffb ",
      " ccfiiiiijjifcc ",
      " befiiiiiiiifeb ",
      " mehffffffffhem ",
      "  eeecffffceee  ",
      "   abcbbbbcbd   ",
      "                "
    ],
    [
      "                ",
      "   abcbbbbcbd   ",
      "  nnnopqqronnn  ",
      " gnstt    ttsng ",
      " bnt        tnb ",
      " cot        toc ",
      " b           ub ",
      " b           wb ",
      " b           wb ",
      " b           xb ",
      " cot        toc ",
      " bnt        tnb ",
      " mnstt    ttsnm ",
      "  nnnoyAABonnn  ",
      "   abcbbbbcbd   ",
      "                "
    ],
    [
      "                ",
      "   abcbbbbcbd   ",
      "  nnno    onnn  ",
      " gnC        Cng ",
      " bn          nb ",
      " co          oc ",
      " b            b ",
      " b            b ",
      " b            b ",
      " b            b ",
      " co          oc ",
      " bn          nb ",
      " mnC        Cnm ",
      "  nnno    onnn  ",
      "   abcbbbbcbd   ",
      "                "
    ],
    [
      "                ",
      "   abcDDDDcbd   ",
      "  nnnoEEEEonnn  ",
      " gn          ng ",
      " bn          nb ",
      " co          oc ",
      " FE          EI ",
      " FE          EI ",
      " FE          EI ",
      " FE          EI ",
      " co          oc ",
      " bn          nb ",
      " mn          nm ",
      "  nnnoEEEEonnn  ",
      "   abcJJJJcbd   ",
      "                "
    ],
    [
      "                ",
      "   ab      bd   ",
      "  nnnonnnnonnn  ",
      " gn          ng ",
      " bn          nb ",
      "  o          o  ",
      "  n          n  ",
      "  n          n  ",
      "  n          n  ",
      "  n          n  ",
      "  o          o  ",
      " bn          nb ",
      " mn          nm ",
      "  nnnonnnnonnn  ",
      "   ab      bd   ",
      "                "
    ],
    [
      "                ",
      "   ad      ad   ",
      "  nnnonnnnonnn  ",
      " gn          ng ",
      " mn          nm ",
      "  o          o  ",
      "  n          n  ",
      "  n          n  ",
      "  n          n  ",
      "  n          n  ",
      "  o          o  ",
      " gn          ng ",
      " mn          nm ",
      "  nnnonnnnonnn  ",
      "   ad      ad   ",
      "                "
    ],
    [
      "                ",
      "   a        d   ",
      "   nnonnnnonn   ",
      " gn          ng ",
      "  n          n  ",
      "  o          o  ",
      "  n          n  ",
      "  n          n  ",
      "  n          n  ",
      "  n          n  ",
      "  o          o  ",
      "  n          n  ",
      " mn          nm ",
      "   nnonnnnonn   ",
      "   a        d   ",
      "                "
    ],
    [
      "                ",
      "                ",
      "   nnonnnnonn   ",
      "  n          n  ",
      "  n          n  ",
      "  o          o  ",
      "  n          n  ",
      "  n          n  ",
      "  n          n  ",
      "  n          n  ",
      "  o          o  ",
      "  n          n  ",
      "  n          n  ",
      "   nnonnnnonn   ",
      "                ",
      "                "
    ],
    [
      "                ",
      "                ",
      "   nnonnnnonn   ",
      "  nnnonnnnonnn  ",
      "  nn        nn  ",
      "  oo        oo  ",
      "  nn        nn  ",
      "  nn        nn  ",
      "  nn        nn  ",
      "  nn        nn  ",
      "  oo        oo  ",
      "  nn        nn  ",
      "  nnnonnnnonnn  ",
      "   nnonnnnonn   ",
      "                ",
      "                "
    ],
    [
      "                ",
      "                ",
      "                ",
      "   nnonnnnonn   ",
      "   nnonnnnonn   ",
      "   ooKooooKoo   ",
      "   nnoKKKKonn   ",
      "   nnoKKKKonn   ",
      "   nnoKKKKonn   ",
      "   nnoKKKKonn   ",
      "   ooKooooKoo   ",
      "   nnonnnnonn   ",
      "   nnonnnnonn   ",
      "                ",
      "                ",
      "                "
    ]
  ]
}