{
  "name": "building_office4_floor4",
  "refpalette": "deceasedcraft:building_office4/building_office4_floor4_palette",
  "xsize": 16,
  "zsize": 16,
  "slices": [
    [
      "                ",
      "   abcbbbbcbd   ",
      "  eeecffffceee  ",
      " gehhffffffffeg ",
      " behhiiiiiiifeb ",
      " ccjjiiiiiiifcc ",
      " b  jiiiiiiifkb ",
      " b  jiiiiiiifkb ",
      " b ljiiiiiiifkb ",
      " bmnjiiiiiiifkb ",
      " ccjjiiiiiiifcc ",
      " befiiiiiiiifeb ",
      " oeffffffffffeo ",
      "  eeecffffceee  ",
      "   abcbbbbcbd   ",
      "                "
    ],
    [
      "                ",
      "   abcbbbbcbd   ",
      "  pppcqqqqcppp  ",
      " gp  r       pg ",
      " bpstu       pb ",
      " ccwk        cc ",
      " b  k x x x  qb ",
      " b lkyAAAAB  qb ",
      " b CkDAAAAE  qb ",
      " b  k F F F  qb ",
      " ccIk        cc ",
      " bp          pb ",
      " op          po ",
      "  pppcqqqqcppp  ",
      "   abcbbbbcbd   ",
      "                "
    ],
    [
      "                ",
      "   abcbbbbcbd   ",
      "  pppcJJJJcppp  ",
      " gp  K       pg ",
      " bp  L       pb ",
      " ccwk        cc ",
      " bMlk        Nb ",
      " b CkOPQRSP  Nb ",
      " b  k T UVW  Nb ",
      " b  k        Nb ",
      " ccXk        cc ",
      " bp          pb ",
      " op          po ",
      "  pppcJJJ!cppp  ",
      "   abcbbbbcbd   ",
      "                "
    ],
    [
      "                ",
      "   abcbbbbcbd   ",
      "  pppcJJJJcppp  ",
      " gp  Y       pg ",
      " bp ZL       pb ",
      " ccwk        cc ",
      " b01k        2b ",
      " bn k        2b ",
      " b  k        2b ",
      " b  k        2b ",
      " cc3k        cc ",
      " bp          pb ",
      " op          po ",
      "  pppcJJJJcppp  ",
      "   abcbbbbcbd   ",
      "                "
    ],
    [
      "                ",
      "   abcbbbbcbd   ",
      "  pppcV456cppp  ",
      " gp  7       pg ",
      " bp  8       pb ",
      " ccwk        cc ",
      " b  k         b ",
      " bm k         b ",
      " bn k         b ",
      " b  k         b ",
      " ccwk        cc ",
      " bp          pb ",
      " op          po ",
      "  pppc9O#$cppp  ",
      "   abcbbbbcbd   ",
      "                "
    ],
    [
      "                ",
      "   abcbbbbcbd   ",
      "  pppc%%^^cppp  ",
      " gp&&********pg ",
      " bp&&********pb ",
      " ccwk********cc ",
      " b  k********^b ",
      " b  k********%b ",
      " bm k********^b ",
      " bnMk********^b ",
      " ccwk********cc ",
      " bp&&********pb ",
      " op&&********po ",
      "  pppc^%%%cppp  ",
      "   abcbbbbcbd   ",
      "                "
    ]
  ]
}