{
  "name": "building_office4_floor2_180",
  "refpalette": "deceasedcraft:building_office4/building_office4_floor2_palette_180",
  "xsize": 16,
  "zsize": 16,
  "slices": [
    [
      "                ",
      "   dbcbbbbcba   ",
      "  eeecffffceee  ",
      " oeffffffffffeo ",
      " befiiiiiiiifeb ",
      " ccfiiiiiiijjcc ",
      " bkfiiiiiiijnmb ",
      " bkfiiiiiiijl b ",
      " bkfiiiiiiij  b ",
      " bkfiiiiiiij  b ",
      " ccfiiiiiiijjcc ",
      " befiiiiiiihheb ",
      " geffffffffhheg ",
      "  eeecffffceee  ",
      "   dbcbbbbcba   ",
      "                "
    ],
    [
      "                ",
      "   dbcbbbbcba   ",
      "  pppcTUUTcppp  ",
      " op     S    po ",
      " bp     R    pb ",
      " cc  EJIIFAkQcc ",
      " bP  EDCCBAk  b ",
      " bL    x  AkO b ",
      " bN      MAkl b ",
      " bLK EJIIFAk  b ",
      " cc  EDCCBAkycc ",
      " bp    x  wutpb ",
      " gp       s  pg ",
      "  pppcqrrqcppp  ",
      "   dbcbbbbcba   ",
      "                "
    ],
    [
      "                ",
      "   dbcbbbbcba   ",
      "  pppc5+) cppp  ",
      " op          po ",
      " bp          pb ",
      " cc   (87W1k*cc ",
      " b&    4^%1k  b ",
      " b$       1k  b ",
      " b        1kO b ",
      " b#   987X!kl6b ",
      " cc   54321kycc ",
      " bp       0  pb ",
      " gp       Z  pg ",
      "  pppcYXWVcppp  ",
      "   dbcbbbbcba   ",
      "                "
    ],
    [
      "                ",
      "   dbcbbbbcba   ",
      "  pppc    cppp  ",
      " op          po ",
      " bp          pb ",
      " cc       1k}cc ",
      " b        1k  b ",
      " b        1k  b ",
      " b        1k nb ",
      " b        1k{]b ",
      " cc       1kycc ",
      " bp       0[ pb ",
      " gp       -  pg ",
      "  pppc    cppp  ",
      "   dbcbbbbcba   ",
      "                "
    ],
    [
      "                ",
      "   dbcbbbbcba   ",
      "  pppc    cppp  ",
      " op          po ",
      " bp          pb ",
      " cc       :kycc ",
      " b        :k  b ",
      " b        :k nb ",
      " b        :k mb ",
      " b        :k  b ",
      " cc       :kycc ",
      " bp       ;  pb ",
      " gp       |  pg ",
      "  pppc    cppp  ",
      "   dbcbbbbcba   ",
      "                "
    ],
    [
      "                ",
      "   dbcbbbbcba   ",
      "  pppc,'''cppp  ",
      " op>>>>>>>><<po ",
      " bp>>>>>>>><<pb ",
      " cc>>>>>>>>kycc ",
      " b'>>>>>>>>k6nb ",
      " b'>>>>>>>>k mb ",
      " b,>>>>>>>>k  b ",
      " b,>>>>>>>>k  b ",
      " cc>>>>>>>>kycc ",
      " bp>>>>>>>><<pb ",
      " gp>>>>>>>><<pg ",
      "  pppc''''cppp  ",
      "   dbcbbbbcba   ",
      "                "
    ]
  ]
}