{
  "name": "building_office4_ground",
  "refpalette": "deceasedcraft:building_office4/building_office4_ground_palette",
  "xsize": 16,
  "zsize": 16,
  "slices": [
    [
      "aaaaaaaaaaaaaaaa",
      "abbbbbbbbbbbbbba",
      "abcccdccccdcccba",
      "abccceeeeeeeecba",
      "abccceffffffecba",
      "abdcceffffffedba",
      "abgcceffffffecba",
      "abccceffffffecba",
      "abccceffffffecba",
      "abccceffffffecba",
      "abdcceffffffedba",
      "abccceffffffecba",
      "abccceeeeeeeecba",
      "abcccdccccdcccba",
      "abbbbbbbbbbbbbba",
      "aaaaaaaaaaaaaaaa"
    ],
    [
      "                ",
      " hhhhdhhhhdhhhh ",
      " hijkd    djkih ",
      " hl   mmmm   nh ",
      " ho          ph ",
      " ddqr  s     dd ",
      " h tu wsx    yA ",
      " hBCu  s    DEF ",
      " h Iu  s    JEK ",
      " h    wsx    yL ",
      " ddqr  s     dd ",
      " hl          nh ",
      " ho   MMMM   ph ",
      " hiNOd    dNOih ",
      " hhhhdhhhhdhhhh ",
      "                "
    ],
    [
      "                ",
      " hhhhdhhhhdhhhh ",
      " hP  d    d  Ph ",
      " h    mmmm    h ",
      " h            h ",
      " ddqr  Q     dd ",
      " hRST        yA ",
      " hUIT  V    W X ",
      " h  T       Y Z ",
      " h           yL ",
      " ddqr  V     dd ",
      " h            h ",
      " h    MMMM    h ",
      " hP  d    d  Ph ",
      " hhhhdhhhhdhhhh ",
      "                "
    ],
    [
      "                ",
      " hhhhdhhhhdhhhh ",
      " hP  d    d  Ph ",
      " h    mmmm    h ",
      " h            h ",
      " ddqr        dd ",
      " hC0T        y1 ",
      " h2 T        y3 ",
      " h  T        y3 ",
      " h           y4 ",
      " ddqr        dd ",
      " h            h ",
      " h    MMMM    h ",
      " hP  d    d  Ph ",
      " hhhhdhhhhdhhhh ",
      "                "
    ],
    [
      "                ",
      " hhhhdhhhhdhhhh ",
      " h   d    d   h ",
      " h    mmmm    h ",
      " h            h ",
      " ddqr        dd ",
      " h  T        5h ",
      " h6 T        7h ",
      " h2 T        5h ",
      " h           7h ",
      " ddqr        dd ",
      " h            h ",
      " h    MMMM    h ",
      " h   d    d   h ",
      " hhhhdhhhhdhhhh ",
      "                "
    ],
    [
      "                ",
      " hhhhdhhhhdhhhh ",
      " h8  d    d  8h ",
      " h    mmmm    h ",
      " h            h ",
      " ddqr        dd ",
      " h  T         h ",
      " h  T         h ",
      " h6 T         h ",
      " h2           h ",
      " ddqr        dd ",
      " h            h ",
      " h    MMMM    h ",
      " h8  d    d  8h ",
      " hhhhdhhhhdhhhh ",
      "                "
    ]
  ]
}