{
  "name": "building_office4_ground_180",
  "refpalette": "deceasedcraft:building_office4/building_office4_ground_palette_180",
  "xsize": 16,
  "zsize": 16,
  "slices": [
    [
      "aaaaaaaaaaaaaaaa",
      "abbbbbbbbbbbbbba",
      "abcccdccccdcccba",
      "abceeeeeeeecccba",
      "abceffffffecccba",
      "abdeffffffeccdba",
      "abceffffffecccba",
      "abceffffffecccba",
      "abceffffffecccba",
      "abceffffffeccgba",
      "abdeffffffeccdba",
      "abceffffffecccba",
      "abceeeeeeeecccba",
      "abcccdccccdcccba",
      "abbbbbbbbbbbbbba",
      "aaaaaaaaaaaaaaaa"
    ],
    [
      "                ",
      " hhhhdhhhhdhhhh ",
      " hiONd    dONih ",
      " hp   MMMM   oh ",
      " hn          lh ",
      " dd     s  rqdd ",
      " Ly    xsw    h ",
      " KEJ    s  uI h ",
      " FED    s  uCBh ",
      " Ay    xsw ut h ",
      " dd     s  rqdd ",
      " hp          oh ",
      " hn   mmmm   lh ",
      " hikjd    dkjih ",
      " hhhhdhhhhdhhhh ",
      "                "
    ],
    [
      "                ",
      " hhhhdhhhhdhhhh ",
      " hP  d    d  Ph ",
      " h    MMMM    h ",
      " h            h ",
      " dd     V  rqdd ",
      " Ly           h ",
      " Z Y       T  h ",
      " X W    V  TIUh ",
      " Ay        TSRh ",
      " dd     Q  rqdd ",
      " h            h ",
      " h    mmmm    h ",
      " hP  d    d  Ph ",
      " hhhhdhhhhdhhhh ",
      "                "
    ],
    [
      "                ",
      " hhhhdhhhhdhhhh ",
      " hP  d    d  Ph ",
      " h    MMMM    h ",
      " h            h ",
      " dd        rqdd ",
      " 4y           h ",
      " 3y        T  h ",
      " 3y        T 2h ",
      " 1y        T0Ch ",
      " dd        rqdd ",
      " h            h ",
      " h    mmmm    h ",
      " hP  d    d  Ph ",
      " hhhhdhhhhdhhhh ",
      "                "
    ],
    [
      "                ",
      " hhhhdhhhhdhhhh ",
      " h   d    d   h ",
      " h    MMMM    h ",
      " h            h ",
      " dd        rqdd ",
      " h7           h ",
      " h5        T 2h ",
      " h7        T 6h ",
      " h5        T  h ",
      " dd        rqdd ",
      " h            h ",
      " h    mmmm    h ",
      " h   d    d   h ",
      " hhhhdhhhhdhhhh ",
      "                "
    ],
    [
      "                ",
      " hhhhdhhhhdhhhh ",
      " h8  d    d  8h ",
      " h    MMMM    h ",
      " h            h ",
      " dd        rqdd ",
      " h           2h ",
      " h         T 6h ",
      " h         T  h ",
      " h         T  h ",
      " dd        rqdd ",
      " h            h ",
      " h    mmmm    h ",
      " h8  d    d  8h ",
      " hhhhdhhhhdhhhh ",
      "                "
    ]
  ]
}