{
  "name": "building_office4_base2",
  "refpalette": "deceasedcraft:building_office4/building_office4_base2_palette",
  "xsize": 16,
  "zsize": 16,
  "slices": [
    [
      "vvvvvvvvvvvvvvvv",
      "vaaaaaaaaaaaaaav",
      "vaaaaaaaaaaaaaav",
      "vaaaaaaaaaaaaaav",
      "vaaaaaaaaaaaaaav",
      "vaaaaaaaaaaaaaav",
      "vaaaaaaaaaaaaaav",
      "vaaaaaaaaaaaaaav",
      "vaaaaaaaaaaaaaav",
      "vaaaaaaaaaaaaaav",
      "vaaaaaaaaaaaaaav",
      "vaaaaaaaaaaaaaav",
      "vaaaaaaaaaaaaaav",
      "vaaaaaaaaaaaaaav",
      "vaaaaaaaaaaaaaav",
      "vvvvvvvvvvvvvvvv"
    ],
    [
      "vvvvvvvvvvvvvvvv",
      "vaaaaaaaaaaaaaav",
      "vab cdeffgdc hav",
      "va  ci j  kc  av",
      "vaccc      cccav",
      "vadl   mm   ldav",
      "van   cccc   oav",
      "vap  kc  ci  qav",
      "varp kc  ci sqav",
      "vat   cccc   uav",
      "vadm   ll  wmdav",
      "vaccc    x cccav",
      "va  cis y kc Aav",
      "va  cdBCCDdc !av",
      "vaaaaaaaaaaaaaav",
      "vvvvvvvvvvvvvvvv"
    ],
    [
      "vvvvvvvvvvvvvvvv",
      "vaaaaaaaaaaaaaav",
      "va  ydEFIJdy  av",
      "va  y      y  av",
      "vayy        yyav",
      "vad          dav",
      "van    yyK    av",
      "va    y  y   Lav",
      "va    y  y   Mav",
      "va    Kyy    Nav",
      "vad          dav",
      "vayy       Oyyav",
      "va  y        Aav",
      "va  ydPQRSdyA av",
      "vaaaaaaaaaaaaaav",
      "vvvvvvvvvvvvvvvv"
    ],
    [
      "vvvvvvvvvvvvvvvv",
      "vaaaaaaaaaaaaaav",
      "va  ydTUUVdy  av",
      "va  y      y  av",
      "vayy        yyav",
      "vad          dav",
      "van    yy    Wav",
      "va    y  y   Xav",
      "va    y  y   Xav",
      "va     yy    Yav",
      "vad          dav",
      "vayy        Zyav",
      "va  y         av",
      "va  yd0112dy  av",
      "vaaaaaaaaaaaaaav",
      "vvvvvvvvvvvvvvvv"
    ],
    [
      "vvvvvvvvvvvvvvvv",
      "vaaaaaaaaaaaaaav",
      "va  yd3433dy  av",
      "va  y      y  av",
      "vayy        yyav",
      "vad          dav",
      "van    yy    5av",
      "va    y  y    av",
      "va    y  y   6av",
      "va     yy    6av",
      "vad          dav",
      "vayy        yyav",
      "va  y         av",
      "va  yd7899dy  av",
      "vaaaaaaaaaaaaaav",
      "vvvvvvvvvvvvvvvv"
    ],
    [
      "vvvvvvvvvvvvvvvv",
      "vaaaaaaaaaaaaaav",
      "va  yd    dy  av",
      "va  y      y  av",
      "vayy        yyav",
      "vad          dav",
      "van    yy     av",
      "va    y  y    av",
      "va    y  y    av",
      "va     yy     av",
      "vad          dav",
      "vayy        yyav",
      "va  y      #  av",
      "va  yd    dy  av",
      "vaaaaaaaaaaaaaav",
      "vvvvvvvvvvvvvvvv"
    ]
  ]
}