{
  "name": "building_office4_floor1_270",
  "refpalette": "deceasedcraft:building_office4/building_office4_floor1_palette_270",
  "xsize": 16,
  "zsize": 16,
  "slices": [
    [
      "                ",
      " abbbcbbbbcbbba ",
      " bdddck   cdddb ",
      " bd  flj  f  db ",
      " bd  ghhhhg  db ",
      " cc          cc ",
      " b m        e b ",
      " b m        e b ",
      " b m        e b ",
      " b m        e b ",
      " cc          cc ",
      " bd          db ",
      " bd          db ",
      " bdddc ii cdddb ",
      " abbbcbbbbcbbba ",
      "                "
    ],
    [
      "                ",
      "  sbbcbbbbcbbp  ",
      " nqqqc    cqqqn ",
      " bq  f rj f  qb ",
      " bq  ghhhhg  qb ",
      " cc          cc ",
      " b m        e b ",
      " b m        e b ",
      " b m        e b ",
      " b m        e b ",
      " cc          cc ",
      " bq          qb ",
      " bq          qb ",
      " oqqqc  i cqqqo ",
      "  sbbcbbbbcbbp  ",
      "                "
    ],
    [
      "                ",
      "   bbcbbbbcbb   ",
      "  qqqc   tcqqq  ",
      " bq  f  rjf  qb ",
      " bq  ghhhhg  qb ",
      " cc          cc ",
      " b m        e b ",
      " b m        e b ",
      " b m        e b ",
      " b m        e b ",
      " cc          cc ",
      " bq          qb ",
      " bq          qb ",
      "  qqqc i  cqqq  ",
      "   bbcbbbbcbb   ",
      "                "
    ],
    [
      "                ",
      "   sbcbbbbcbp   ",
      "  qqqc  lucqqq  ",
      " nq  f   wf  qn ",
      " bq  ghhhhg  qb ",
      " cc          cc ",
      " b m        e b ",
      " b m        e b ",
      " b m        e b ",
      " b m        e b ",
      " cc          cc ",
      " bq          qb ",
      " oq          qo ",
      "  qqqc  i cqqq  ",
      "   sbcbbbbcbp   ",
      "                "
    ],
    [
      "                ",
      "   sbcbbbbcbp   ",
      "  qqqc lk cqqq  ",
      " nq  f    f  qn ",
      " bq  ghhhhg  qb ",
      " cc          cc ",
      " b~m        e~b ",
      " b~m        e~b ",
      " b~m        e~b ",
      " b~m        e~b ",
      " cc          cc ",
      " bq          qb ",
      " oq          qo ",
      "  qqqc    cqqq  ",
      "   sbcbbbbcbp   ",
      "                "
    ],
    [
      "                ",
      "   sbcbbbbcbp   ",
      "  qqqclk  cqqq  ",
      " nqyyf    fyyqn ",
      " bqyygCCCCgyyqb ",
      " ccAAAAAAAAAAcc ",
      " bxBBBBBBBBBBxb ",
      " bFBBBBBBBBBBxb ",
      " bxBBBBBBBBBBxb ",
      " bxBBBBBBBBBBxb ",
      " ccAAAAAAAAAAcc ",
      " bqyyyyyyyyyyqb ",
      " oqyyyyyyyyyyqo ",
      "  qqqcEDEDcqqq  ",
      "   sbcbbbbcbp   ",
      "                "
    ]
  ]
}