{
  "name": "building_office4_base1_180",
  "refpalette": "deceasedcraft:building_office4/building_office4_base1_palette_180",
  "xsize": 16,
  "zsize": 16,
  "slices": [
    [
      "vvvvvvvvvvvvvvvv",
      "vaaaaaaaaaaaaaav",
      "va  bc    cb  av",
      "va  b      b  av",
      "vabb        bbav",
      "vac          cav",
      "va     bb     av",
      "va    b  b    av",
      "va    b  b    av",
      "va     bb    dav",
      "vac          cav",
      "vabb        bbav",
      "va  b      b  av",
      "va  bc    cb  av",
      "vaaaaaaaaaaaaaav",
      "vvvvvvvvvvvvvvvv"
    ],
    [
      "vvvvvvvvvvvvvvvv",
      "vaaaaaaaaaaaaaav",
      "va  bc    cb  av",
      "va  b      b  av",
      "vabb        bbav",
      "vac          cav",
      "va     bb     av",
      "va    b  b    av",
      "va    b  b    av",
      "va     bb    dav",
      "vac          cav",
      "vabb        bbav",
      "va  b      b  av",
      "va  bc    cb  av",
      "vaaaaaaaaaaaaaav",
      "vvvvvvvvvvvvvvvv"
    ],
    [
      "vvvvvvvvvvvvvvvv",
      "vaaaaaaaaaaaaaav",
      "va  bc    cb  av",
      "vae b      b  av",
      "vabb        bbav",
      "vac          cav",
      "va     bb     av",
      "va    b  b    av",
      "va    b  b    av",
      "va     bb    dav",
      "vac          cav",
      "vabb        bbav",
      "va  b      b  av",
      "va  bc    cb  av",
      "vaaaaaaaaaaaaaav",
      "vvvvvvvvvvvvvvvv"
    ],
    [
      "vvvvvvvvvvvvvvvv",
      "vaaaaaaaaaaaaaav",
      "va ebcffffcb~~av",
      "va  b  f   b~~av",
      "vabb   f    bbav",
      "vac    f     cav",
      "vaf    ibg    av",
      "vaf   b~~b    av",
      "vaf   b~~b    av",
      "vaf   ghbg   dav",
      "vac    f     cav",
      "vabb   f    bbav",
      "va~~b  f   b~~av",
      "va~~bcffffcb~~av",
      "vaaaaaaaaaaaaaav",
      "vvvvvvvvvvvvvvvv"
    ],
    [
      "vvvvvvvvvvvvvvvv",
      "vaaaaaaaaaaaaaav",
      "va ekc    ckjjav",
      "vaeekm    lkjjav",
      "vakkk      kkkav",
      "vaco   nn   ocav",
      "va    kkkk    av",
      "va   lkppkm   av",
      "va   lkppkm   av",
      "va    kkkk   dav",
      "vacn   oo   ncav",
      "vakkk      kkkav",
      "vajjkm    lkjjav",
      "vajjkc    ckjjav",
      "vaaaaaaaaaaaaaav",
      "vvvvvvvvvvvvvvvv"
    ],
    [
      "vvvvvvvvvvvvvvvv",
      "vaaaaaaaaaaaaaav",
      "vaqaacaaaacaaqav",
      "vaaaaaaaaaaaaaav",
      "vaaaaaaaaaaaaaav",
      "vacaaaaaaaaaacav",
      "vaaaaaaaaaaaaaav",
      "vaaaaaaaaaaaaaav",
      "vaaaaaaaaaaaaaav",
      "vaaaaaaaaaaaadav",
      "vacaaaaaaaaaacav",
      "vaaaaaaaaaaaaaav",
      "vaaaaaaaaaaaaaav",
      "vaqaacaaaacaaqav",
      "vaaaaaaaaaaaaaav",
      "vvvvvvvvvvvvvvvv"
    ]
  ]
}