{
  "name": "building_office4_base2_90",
  "refpalette": "deceasedcraft:building_office4/building_office4_base2_palette_90",
  "xsize": 16,
  "zsize": 16,
  "slices": [
    [
      "vvvvvvvvvvvvvvvv",
      "vaaaaaaaaaaaaaav",
      "vaaaaaaaaaaaaaav",
      "vaaaaaaaaaaaaaav",
      "vaaaaaaaaaaaaaav",
      "vaaaaaaaaaaaaaav",
      "vaaaaaaaaaaaaaav",
      "vaaaaaaaaaaaaaav",
      "vaaaaaaaaaaaaaav",
      "vaaaaaaaaaaaaaav",
      "vaaaaaaaaaaaaaav",
      "vaaaaaaaaaaaaaav",
      "vaaaaaaaaaaaaaav",
      "vaaaaaaaaaaaaaav",
      "vaaaaaaaaaaaaaav",
      "vvvvvvvvvvvvvvvv"
    ],
    [
      "vvvvvvvvvvvvvvvv",
      "vaaaaaaaaaaaaaav",
      "vah cdoqqudcA!av",
      "va  cl  s mc  av",
      "vaccc     wcccav",
      "vadk   ii   kdav",
      "vag   cccc x Dav",
      "vaf  mc  cl yCav",
      "vafj mc  cl  Cav",
      "vae   cccc  sBav",
      "vadi   kk   idav",
      "vaccc      cccav",
      "va  cl  p mc  av",
      "vab cdnprtdc  av",
      "vaaaaaaaaaaaaaav",
      "vvvvvvvvvvvvvvvv"
    ],
    [
      "vvvvvvvvvvvvvvvv",
      "vaaaaaaaaaaaaaav",
      "va  yd LMNdyA av",
      "va  y      y Aav",
      "vayy       O yav",
      "vad          dav",
      "vaJ   Kyy    Sav",
      "vaI   y  y   Rav",
      "vaF   y  y   Qav",
      "vaE    yyK   Pav",
      "vad          dav",
      "vayy        yyav",
      "va  y      y  av",
      "va  ydn   dy  av",
      "vaaaaaaaaaaaaaav",
      "vvvvvvvvvvvvvvvv"
    ],
    [
      "vvvvvvvvvvvvvvvv",
      "vaaaaaaaaaaaaaav",
      "va  ydWXXYdy  av",
      "va  y      Z  av",
      "vayy         yav",
      "vad          dav",
      "vaV    yy    2av",
      "vaU   y  y   1av",
      "vaU   y  y   1av",
      "vaT    yy    0av",
      "vad          dav",
      "vayy        yyav",
      "va  y      y  av",
      "va  ydn   dy  av",
      "vaaaaaaaaaaaaaav",
      "vvvvvvvvvvvvvvvv"
    ],
    [
      "vvvvvvvvvvvvvvvv",
      "vaaaaaaaaaaaaaav",
      "va  yd5 66dy  av",
      "va  y      y  av",
      "vayy         yav",
      "vad          dav",
      "va3    yy    9av",
      "va3   y  y   9av",
      "va4   y  y   8av",
      "va3    yy    7av",
      "vad          dav",
      "vayy        yyav",
      "va  y      y  av",
      "va  ydn   dy  av",
      "vaaaaaaaaaaaaaav",
      "vvvvvvvvvvvvvvvv"
    ],
    [
      "vvvvvvvvvvvvvvvv",
      "vaaaaaaaaaaaaaav",
      "va  yd    dy  av",
      "va  y      y  av",
      "vayy        #yav",
      "vad          dav",
      "va     yy     av",
      "va    y  y    av",
      "va    y  y    av",
      "va     yy     av",
      "vad          dav",
      "vayy        yyav",
      "va  y      y  av",
      "va  ydn   dy  av",
      "vaaaaaaaaaaaaaav",
      "vvvvvvvvvvvvvvvv"
    ]
  ]
}