{
  "name": "building_office4_floor4_90",
  "refpalette": "deceasedcraft:building_office4/building_office4_floor4_palette_90",
  "xsize": 16,
  "zsize": 16,
  "slices": [
    [
      "                ",
      "   gbcbbbbcbo   ",
      "  eeeckkkkceee  ",
      " deffffffffffed ",
      " befiiiiiiiifeb ",
      " ccfiiiiiiiifcc ",
      " bffiiiiiiiiffb ",
      " bffiiiiiiiiffb ",
      " bffiiiiiiiiffb ",
      " bffiiiiiiiiffb ",
      " ccfiiiiiiiifcc ",
      " behhjjjjjjifeb ",
      " aehhj  lnjffea ",
      "  eeec   mceee  ",
      "   gbcbbbbcbo   ",
      "                "
    ],
    [
      "                ",
      "   gbcbbbbcbo   ",
      "  pppcqqqqcppp  ",
      " dp          pd ",
      " bp          pb ",
      " cc   xBEF   cc ",
      " bq    AA    qb ",
      " bq   xAAF   qb ",
      " bq    AA    qb ",
      " bq   xAAF   qb ",
      " ccru  yD    cc ",
      " bp tkkkkkk  pb ",
      " ap sw lC I  pa ",
      "  pppc    cppp  ",
      "   gbcbbbbcbo   ",
      "                "
    ],
    [
      "                ",
      "   gbcbbbbcbo   ",
      "  pppcNNNNcppp  ",
      " dp          pd ",
      " bp          pb ",
      " cc    PW    cc ",
      " bJ    SV    !b ",
      " bJ    RU    Jb ",
      " bJ    Q     Jb ",
      " bJ    PT    Jb ",
      " ccKL  O     cc ",
      " bp  kkkkkk  pb ",
      " ap  wlC  X  pa ",
      "  pppcM   cppp  ",
      "   gbcbbbbcbo   ",
      "                "
    ],
    [
      "                ",
      "   gbcbbbbcbo   ",
      "  pppc2222cppp  ",
      " dp          pd ",
      " bp          pb ",
      " cc          cc ",
      " bJ          Jb ",
      " bJ          Jb ",
      " bJ          Jb ",
      " bJ          Jb ",
      " ccYL        cc ",
      " bp Zkkkkkk  pb ",
      " ap  w1   3  pa ",
      "  pppc0n  cppp  ",
      "   gbcbbbbcbo   ",
      "                "
    ],
    [
      "                ",
      "   gbcbbbbcbo   ",
      "  pppc    cppp  ",
      " dp          pd ",
      " bp          pb ",
      " cc          cc ",
      " b6          $b ",
      " b5          #b ",
      " b4          Ob ",
      " bV          9b ",
      " cc78        cc ",
      " bp  kkkkkk  pb ",
      " ap  w    w  pa ",
      "  pppc mn cppp  ",
      "   gbcbbbbcbo   ",
      "                "
    ],
    [
      "                ",
      "   gbcbbbbcbo   ",
      "  pppc^%^^cppp  ",
      " dp**********pd ",
      " bp**********pb ",
      " cc**********cc ",
      " b^**********%b ",
      " b^**********%b ",
      " b%**********%b ",
      " b%**********^b ",
      " cc**********cc ",
      " bp&&kkkkkk&&pb ",
      " ap&&w   Mw&&pa ",
      "  pppc  mncppp  ",
      "   gbcbbbbcbo   ",
      "                "
    ]
  ]
}