{
  "name": "building_office4_base1",
  "refpalette": "deceasedcraft:building_office4/building_office4_base1_palette",
  "xsize": 16,
  "zsize": 16,
  "slices": [
    [
      "vvvvvvvvvvvvvvvv",
      "vaaaaaaaaaaaaaav",
      "va  bc    cb  av",
      "va  b      b  av",
      "vabb        bbav",
      "vac          cav",
      "vad    bb     av",
      "va    b  b    av",
      "va    b  b    av",
      "va     bb     av",
      "vac          cav",
      "vabb        bbav",
      "va  b      b  av",
      "va  bc    cb  av",
      "vaaaaaaaaaaaaaav",
      "vvvvvvvvvvvvvvvv"
    ],
    [
      "vvvvvvvvvvvvvvvv",
      "vaaaaaaaaaaaaaav",
      "va  bc    cb  av",
      "va  b      b  av",
      "vabb        bbav",
      "vac          cav",
      "vad    bb     av",
      "va    b  b    av",
      "va    b  b    av",
      "va     bb     av",
      "vac          cav",
      "vabb        bbav",
      "va  b      b  av",
      "va  bc    cb  av",
      "vaaaaaaaaaaaaaav",
      "vvvvvvvvvvvvvvvv"
    ],
    [
      "vvvvvvvvvvvvvvvv",
      "vaaaaaaaaaaaaaav",
      "va  bc    cb  av",
      "va  b      b  av",
      "vabb        bbav",
      "vac          cav",
      "vad    bb     av",
      "va    b  b    av",
      "va    b  b    av",
      "va     bb     av",
      "vac          cav",
      "vabb        bbav",
      "va  b      b eav",
      "va  bc    cb  av",
      "vaaaaaaaaaaaaaav",
      "vvvvvvvvvvvvvvvv"
    ],
    [
      "vvvvvvvvvvvvvvvv",
      "vaaaaaaaaaaaaaav",
      "va~~bcffffcb~~av",
      "va~~b   f  b~~av",
      "vabb    f   bbav",
      "vac     f    cav",
      "vad   gbhg   fav",
      "va    b~~b   fav",
      "va    b~~b   fav",
      "va    gbi    fav",
      "vac     f    cav",
      "vabb    f   bbav",
      "va~~b   f  b  av",
      "va~~bcffffcbe av",
      "vaaaaaaaaaaaaaav",
      "vvvvvvvvvvvvvvvv"
    ],
    [
      "vvvvvvvvvvvvvvvv",
      "vaaaaaaaaaaaaaav",
      "vajjkc    ckjjav",
      "vajjkl    mkjjav",
      "vakkk      kkkav",
      "vacn   oo   ncav",
      "vad   kkkk    av",
      "va   mkppkl   av",
      "va   mkppkl   av",
      "va    kkkk    av",
      "vaco   nn   ocav",
      "vakkk      kkkav",
      "vajjkl    mkeeav",
      "vajjkc    cke av",
      "vaaaaaaaaaaaaaav",
      "vvvvvvvvvvvvvvvv"
    ],
    [
      "vvvvvvvvvvvvvvvv",
      "vaaaaaaaaaaaaaav",
      "vaqaacaaaacaaqav",
      "vaaaaaaaaaaaaaav",
      "vaaaaaaaaaaaaaav",
      "vacaaaaaaaaaacav",
      "vadaaaaaaaaaaaav",
      "vaaaaaaaaaaaaaav",
      "vaaaaaaaaaaaaaav",
      "vaaaaaaaaaaaaaav",
      "vacaaaaaaaaaacav",
      "vaaaaaaaaaaaaaav",
      "vaaaaaaaaaaaaaav",
      "vaqaacaaaacaaqav",
      "vaaaaaaaaaaaaaav",
      "vvvvvvvvvvvvvvvv"
    ]
  ]
}