{
  "name": "building_office4_base1_90",
  "refpalette": "deceasedcraft:building_office4/building_office4_base1_palette_90",
  "xsize": 16,
  "zsize": 16,
  "slices": [
    [
      "vvvvvvvvvvvvvvvv",
      "vaaaaaaaaaaaaaav",
      "va  bc    cb  av",
      "va  b      b  av",
      "vabb        bbav",
      "vac          cav",
      "va     bb     av",
      "va    b  b    av",
      "va    b  b    av",
      "va     bb     av",
      "vac          cav",
      "vabb        bbav",
      "va  b      b  av",
      "va  bcd   cb  av",
      "vaaaaaaaaaaaaaav",
      "vvvvvvvvvvvvvvvv"
    ],
    [
      "vvvvvvvvvvvvvvvv",
      "vaaaaaaaaaaaaaav",
      "va  bc    cb  av",
      "va  b      b  av",
      "vabb        bbav",
      "vac          cav",
      "va     bb     av",
      "va    b  b    av",
      "va    b  b    av",
      "va     bb     av",
      "vac          cav",
      "vabb        bbav",
      "va  b      b  av",
      "va  bcd   cb  av",
      "vaaaaaaaaaaaaaav",
      "vvvvvvvvvvvvvvvv"
    ],
    [
      "vvvvvvvvvvvvvvvv",
      "vaaaaaaaaaaaaaav",
      "va  bc    cbe av",
      "va  b      b  av",
      "vabb        bbav",
      "vac          cav",
      "va     bb     av",
      "va    b  b    av",
      "va    b  b    av",
      "va     bb     av",
      "vac          cav",
      "vabb        bbav",
      "va  b      b  av",
      "va  bcd   cb  av",
      "vaaaaaaaaaaaaaav",
      "vvvvvvvvvvvvvvvv"
    ],
    [
      "vvvvvvvvvvvvvvvv",
      "vaaaaaaaaaaaaaav",
      "va~~bcffffcb  av",
      "va~~b      b eav",
      "vabb        bbav",
      "vac          cav",
      "vaf   gbb    fav",
      "vaffffh~~iffffav",
      "vaf   b~~b   fav",
      "vaf   gbbg   fav",
      "vac          cav",
      "vabb        bbav",
      "va~~b      b~~av",
      "va~~bcd   cb~~av",
      "vaaaaaaaaaaaaaav",
      "vvvvvvvvvvvvvvvv"
    ],
    [
      "vvvvvvvvvvvvvvvv",
      "vaaaaaaaaaaaaaav",
      "vajjkc    cke av",
      "vajjkn    okeeav",
      "vakkk      kkkav",
      "vacm   ll   mcav",
      "va    kkkk    av",
      "va   okppkn   av",
      "va   okppkn   av",
      "va    kkkk    av",
      "vacl   mm   lcav",
      "vakkk      kkkav",
      "vajjkn    okjjav",
      "vajjkcd   ckjjav",
      "vaaaaaaaaaaaaaav",
      "vvvvvvvvvvvvvvvv"
    ],
    [
      "vvvvvvvvvvvvvvvv",
      "vaaaaaaaaaaaaaav",
      "vaqaacaaaacaaqav",
      "vaaaaaaaaaaaaaav",
      "vaaaaaaaaaaaaaav",
      "vacaaaaaaaaaacav",
      "vaaaaaaaaaaaaaav",
      "vaaaaaaaaaaaaaav",
      "vaaaaaaaaaaaaaav",
      "vaaaaaaaaaaaaaav",
      "vacaaaaaaaaaacav",
      "vaaaaaaaaaaaaaav",
      "vaaaaaaaaaaaaaav",
      "vaqaacdaaacaaqav",
      "vaaaaaaaaaaaaaav",
      "vvvvvvvvvvvvvvvv"
    ]
  ]
}