{
  "name": "building_office4_top_90",
  "refpalette": "deceasedcraft:building_office4/building_office4_top_palette_90",
  "xsize": 16,
  "zsize": 16,
  "slices": [
    [
      "                ",
      "   gbcbbbbcbm   ",
      "  eeecffffceee  ",
      " dehffffffffhed ",
      " befiiiiiiiifeb ",
      " ccfijjiijjifcc ",
      " bffijkiikjiffb ",
      " bffiiijjiiiffb ",
      " bffiijkkjiiffb ",
      " bffiikkkkiiffb ",
      " ccfiikiikiifcc ",
      " befiiiiiiiifeb ",
      " aehffffffffhea ",
      "  eeec   lceee  ",
      "   gbcbbbbcbm   ",
      "                "
    ],
    [
      "                ",
      "   gbcbbbbcbm   ",
      "  nnnouwwxonnn  ",
      " dnstt    ttsnd ",
      " bnt        tnb ",
      " cot        toc ",
      " br          Bb ",
      " bq          Ab ",
      " bq          Ab ",
      " bp          yb ",
      " cot        toc ",
      " bnt        tnb ",
      " anstt    ttsna ",
      "  nnno    onnn  ",
      "   gbcbbbbcbm   ",
      "                "
    ],
    [
      "                ",
      "   gbcbbbbcbm   ",
      "  nnno    onnn  ",
      " dnC        Cnd ",
      " bn          nb ",
      " co          oc ",
      " b            b ",
      " b            b ",
      " b            b ",
      " b            b ",
      " co          oc ",
      " bn          nb ",
      " anC        Cna ",
      "  nnno    onnn  ",
      "   gbcbbbbcbm   ",
      "                "
    ],
    [
      "                ",
      "   gbcIIIIcbm   ",
      "  nnnoEEEEonnn  ",
      " dn          nd ",
      " bn          nb ",
      " co          oc ",
      " DE          EJ ",
      " DE          EJ ",
      " DE          EJ ",
      " DE          EJ ",
      " co          oc ",
      " bn          nb ",
      " an          na ",
      "  nnnoEEEEonnn  ",
      "   gbcFFFFcbm   ",
      "                "
    ],
    [
      "                ",
      "   gb      bm   ",
      "  nnnonnnnonnn  ",
      " dn          nd ",
      " bn          nb ",
      "  o          o  ",
      "  n          n  ",
      "  n          n  ",
      "  n          n  ",
      "  n          n  ",
      "  o          o  ",
      " bn          nb ",
      " an          na ",
      "  nnnonnnnonnn  ",
      "   gb      bm   ",
      "                "
    ],
    [
      "                ",
      "   gm      gm   ",
      "  nnnonnnnonnn  ",
      " dn          nd ",
      " an          na ",
      "  o          o  ",
      "  n          n  ",
      "  n          n  ",
      "  n          n  ",
      "  n          n  ",
      "  o          o  ",
      " dn          nd ",
      " an          na ",
      "  nnnonnnnonnn  ",
      "   gm      gm   ",
      "                "
    ],
    [
      "                ",
      "   g        m   ",
      "   nnonnnnonn   ",
      " dn          nd ",
      "  n          n  ",
      "  o          o  ",
      "  n          n  ",
      "  n          n  ",
      "  n          n  ",
      "  n          n  ",
      "  o          o  ",
      "  n          n  ",
      " an          na ",
      "   nnonnnnonn   ",
      "   g        m   ",
      "                "
    ],
    [
      "                ",
      "                ",
      "   nnonnnnonn   ",
      "  n          n  ",
      "  n          n  ",
      "  o          o  ",
      "  n          n  ",
      "  n          n  ",
      "  n          n  ",
      "  n          n  ",
      "  o          o  ",
      "  n          n  ",
      "  n          n  ",
      "   nnonnnnonn   ",
      "                ",
      "                "
    ],
    [
      "                ",
      "                ",
      "   nnonnnnonn   ",
      "  nnnonnnnonnn  ",
      "  nn        nn  ",
      "  oo        oo  ",
      "  nn        nn  ",
      "  nn        nn  ",
      "  nn        nn  ",
      "  nn        nn  ",
      "  oo        oo  ",
      "  nn        nn  ",
      "  nnnonnnnonnn  ",
      "   nnonnnnonn   ",
      "                ",
      "                "
    ],
    [
      "                ",
      "                ",
      "                ",
      "   nnonnnnonn   ",
      "   nnonnnnonn   ",
      "   ooKooooKoo   ",
      "   nnoKKKKonn   ",
      "   nnoKKKKonn   ",
      "   nnoKKKKonn   ",
      "   nnoKKKKonn   ",
      "   ooKooooKoo   ",
      "   nnonnnnonn   ",
      "   nnonnnnonn   ",
      "                ",
      "                ",
      "                "
    ]
  ]
}