{
  "name": "building_office4_ground_90",
  "refpalette": "deceasedcraft:building_office4/building_office4_ground_palette_90",
  "xsize": 16,
  "zsize": 16,
  "slices": [
    [
      "aaaaaaaaaaaaaaaa",
      "abbbbbbbbbbbbbba",
      "abcccdccccdcccba",
      "abceeeeeeeeeecba",
      "abceffffffffecba",
      "abdeffffffffedba",
      "abceffffffffecba",
      "abceffffffffecba",
      "abceffffffffecba",
      "abceffffffffecba",
      "abdeeeeeeeeeedba",
      "abccccccccccccba",
      "abccccccccccccba",
      "abcccdgcccdcccba",
      "abbbbbbbbbbbbbba",
      "aaaaaaaaaaaaaaaa"
    ],
    [
      "                ",
      " hhhhdAFKLdhhhh ",
      " hinpdyEEydnpih ",
      " hk    DJ    Oh ",
      " hj          Nh ",
      " dd          dd ",
      " h m        M h ",
      " h m  x  x  M h ",
      " h m ssssss M h ",
      " h m  w  w  M h ",
      " dd          dd ",
      " hk  ruuu r  Oh ",
      " hj  qtCI q  Nh ",
      " hilod B  dloih ",
      " hhhhdhhhhdhhhh ",
      "                "
    ],
    [
      "                ",
      " hhhhdAXZLdhhhh ",
      " hP  dy  yd  Ph ",
      " h     WY     h ",
      " h            h ",
      " dd          dd ",
      " h m        M h ",
      " h m        M h ",
      " h m Q V  V M h ",
      " h m        M h ",
      " dd          dd ",
      " h   rTTT r   h ",
      " h   qSI  q   h ",
      " hP  dRU  d  Ph ",
      " hhhhdhhhhdhhhh ",
      "                "
    ],
    [
      "                ",
      " hhhhd1334dhhhh ",
      " hP  dyyyyd  Ph ",
      " h            h ",
      " h            h ",
      " dd          dd ",
      " h m        M h ",
      " h m        M h ",
      " h m        M h ",
      " h m        M h ",
      " dd          dd ",
      " h   rTTT r   h ",
      " h   q0   q   h ",
      " hP  dC2  d  Ph ",
      " hhhhdhhhhdhhhh ",
      "                "
    ],
    [
      "                ",
      " hhhhdhhhhdhhhh ",
      " h   d5757d   h ",
      " h            h ",
      " h            h ",
      " dd          dd ",
      " h m        M h ",
      " h m        M h ",
      " h m        M h ",
      " h m        M h ",
      " dd          dd ",
      " h   rTTT r   h ",
      " h   q    q   h ",
      " h   d 62 d   h ",
      " hhhhdhhhhdhhhh ",
      "                "
    ],
    [
      "                ",
      " hhhhdhhhhdhhhh ",
      " h8  d    d  8h ",
      " h            h ",
      " h            h ",
      " dd          dd ",
      " h m        M h ",
      " h m        M h ",
      " h m        M h ",
      " h m        M h ",
      " dd          dd ",
      " h   rTTT r   h ",
      " h   q    q   h ",
      " h8  d  62d  8h ",
      " hhhhdhhhhdhhhh ",
      "                "
    ]
  ]
}