{
  "name": "building_office4_top_180",
  "refpalette": "deceasedcraft:building_office4/building_office4_top_palette_180",
  "xsize": 16,
  "zsize": 16,
  "slices": [
    [
      "                ",
      "   dbcbbbbcba   ",
      "  eeecffffceee  ",
      " mehffffffffhem ",
      " befiiiiiiiifeb ",
      " ccfijjiiiiifcc ",
      " bffijkijkkiflb ",
      " bffiiijkkiif b ",
      " bffiiijkkiif b ",
      " bffijkijkkif b ",
      " ccfijjiiiiifcc ",
      " befiiiiiiiifeb ",
      " gehffffffffheg ",
      "  eeecffffceee  ",
      "   dbcbbbbcba   ",
      "                "
    ],
    [
      "                ",
      "   dbcbbbbcba   ",
      "  nnnoBAAyonnn  ",
      " mnstt    ttsnm ",
      " bnt        tnb ",
      " cot        toc ",
      " bx           b ",
      " bw           b ",
      " bw           b ",
      " bu           b ",
      " cot        toc ",
      " bnt        tnb ",
      " gnstt    ttsng ",
      "  nnnorqqponnn  ",
      "   dbcbbbbcba   ",
      "                "
    ],
    [
      "                ",
      "   dbcbbbbcba   ",
      "  nnno    onnn  ",
      " mnC        Cnm ",
      " bn          nb ",
      " co          oc ",
      " b            b ",
      " b            b ",
      " b            b ",
      " b            b ",
      " co          oc ",
      " bn          nb ",
      " gnC        Cng ",
      "  nnno    onnn  ",
      "   dbcbbbbcba   ",
      "                "
    ],
    [
      "                ",
      "   dbcJJJJcba   ",
      "  nnnoEEEEonnn  ",
      " mn          nm ",
      " bn          nb ",
      " co          oc ",
      " IE          EF ",
      " IE          EF ",
      " IE          EF ",
      " IE          EF ",
      " co          oc ",
      " bn          nb ",
      " gn          ng ",
      "  nnnoEEEEonnn  ",
      "   dbcDDDDcba   ",
      "                "
    ],
    [
      "                ",
      "   db      ba   ",
      "  nnnonnnnonnn  ",
      " mn          nm ",
      " bn          nb ",
      "  o          o  ",
      "  n          n  ",
      "  n          n  ",
      "  n          n  ",
      "  n          n  ",
      "  o          o  ",
      " bn          nb ",
      " gn          ng ",
      "  nnnonnnnonnn  ",
      "   db      ba   ",
      "                "
    ],
    [
      "                ",
      "   da      da   ",
      "  nnnonnnnonnn  ",
      " mn          nm ",
      " gn          ng ",
      "  o          o  ",
      "  n          n  ",
      "  n          n  ",
      "  n          n  ",
      "  n          n  ",
      "  o          o  ",
      " mn          nm ",
      " gn          ng ",
      "  nnnonnnnonnn  ",
      "   da      da   ",
      "                "
    ],
    [
      "                ",
      "   d        a   ",
      "   nnonnnnonn   ",
      " mn          nm ",
      "  n          n  ",
      "  o          o  ",
      "  n          n  ",
      "  n          n  ",
      "  n          n  ",
      "  n          n  ",
      "  o          o  ",
      "  n          n  ",
      " gn          ng ",
      "   nnonnnnonn   ",
      "   d        a   ",
      "                "
    ],
    [
      "                ",
      "                ",
      "   nnonnnnonn   ",
      "  n          n  ",
      "  n          n  ",
      "  o          o  ",
      "  n          n  ",
      "  n          n  ",
      "  n          n  ",
      "  n          n  ",
      "  o          o  ",
      "  n          n  ",
      "  n          n  ",
      "   nnonnnnonn   ",
      "                ",
      "                "
    ],
    [
      "                ",
      "                ",
      "   nnonnnnonn   ",
      "  nnnonnnnonnn  ",
      "  nn        nn  ",
      "  oo        oo  ",
      "  nn        nn  ",
      "  nn        nn  ",
      "  nn        nn  ",
      "  nn        nn  ",
      "  oo        oo  ",
      "  nn        nn  ",
      "  nnnonnnnonnn  ",
      "   nnonnnnonn   ",
      "                ",
      "                "
    ],
    [
      "                ",
      "                ",
      "                ",
      "   nnonnnnonn   ",
      "   nnonnnnonn   ",
      "   ooKooooKoo   ",
      "   nnoKKKKonn   ",
      "   nnoKKKKonn   ",
      "   nnoKKKKonn   ",
      "   nnoKKKKonn   ",
      "   ooKooooKoo   ",
      "   nnonnnnonn   ",
      "   nnonnnnonn   ",
      "                ",
      "                ",
      "                "
    ]
  ]
}