{
  "name": "building_office4_floor2_270",
  "refpalette": "deceasedcraft:building_office4/building_office4_floor2_palette_270",
  "xsize": 16,
  "zsize": 16,
  "slices": [
    [
      "                ",
      "   obcbbbbcbg   ",
      "  eeecm   ceee  ",
      " aeffjnl  jhhea ",
      " befijjjjjjhheb ",
      " ccfiiiiiiiifcc ",
      " bffiiiiiiiiffb ",
      " bffiiiiiiiiffb ",
      " bffiiiiiiiiffb ",
      " bffiiiiiiiiffb ",
      " ccfiiiiiiiifcc ",
      " befiiiiiiiifeb ",
      " deffffffffffed ",
      "  eeeckkkkceee  ",
      "   obcbbbbcbg   ",
      "                "
    ],
    [
      "                ",
      "   obcbbbbcbg   ",
      "  pppc    cppp  ",
      " ap  Q Ol yt pa ",
      " bp  kkkkkku pb ",
      " cc  AAAAAAwscc ",
      " bT  FB MFB  qb ",
      " bUSRIC  IC  rb ",
      " bU  ICx ICx rb ",
      " bT  JD  JD  qb ",
      " cc  EE  EE  cc ",
      " bp          pb ",
      " dp      K   pd ",
      "  pppcPLNLcppp  ",
      "   obcbbbbcbg   ",
      "                "
    ],
    [
      "                ",
      "   obcbbbbcbg   ",
      "  pppc   6cppp  ",
      " ap  *  Oly  pa ",
      " bp  kkkkkk  pb ",
      " cc  1111!10Zcc ",
      " b   W%  X2  Vb ",
      " b)  7^  73  Wb ",
      " b+  84  84  Xb ",
      " b5  (   95  Yb ",
      " cc          cc ",
      " bp          pb ",
      " dp          pd ",
      "  pppc&$ #cppp  ",
      "   obcbbbbcbg   ",
      "                "
    ],
    [
      "                ",
      "   obcbbbbcbg   ",
      "  pppc  n]cppp  ",
      " ap  }   {y  pa ",
      " bp  kkkkkk[ pb ",
      " cc  1111110-cc ",
      " b            b ",
      " b            b ",
      " b            b ",
      " b            b ",
      " cc          cc ",
      " bp          pb ",
      " dp          pd ",
      "  pppc    cppp  ",
      "   obcbbbbcbg   ",
      "                "
    ],
    [
      "                ",
      "   obcbbbbcbg   ",
      "  pppc nm cppp  ",
      " ap  y    y  pa ",
      " bp  kkkkkk  pb ",
      " cc  ::::::;|cc ",
      " b            b ",
      " b            b ",
      " b            b ",
      " b            b ",
      " cc          cc ",
      " bp          pb ",
      " dp          pd ",
      "  pppc    cppp  ",
      "   obcbbbbcbg   ",
      "                "
    ],
    [
      "                ",
      "   obcbbbbcbg   ",
      "  pppcnm  cppp  ",
      " ap<<y6   y<<pa ",
      " bp<<kkkkkk<<pb ",
      " cc>>>>>>>>>>cc ",
      " b'>>>>>>>>>>'b ",
      " b'>>>>>>>>>>'b ",
      " b'>>>>>>>>>>'b ",
      " b,>>>>>>>>>>'b ",
      " cc>>>>>>>>>>cc ",
      " bp>>>>>>>>>>pb ",
      " dp>>>>>>>>>>pd ",
      "  pppc'',,cppp  ",
      "   obcbbbbcbg   ",
      "                "
    ]
  ]
}