{
  "name": "building_office4_base2_270",
  "refpalette": "deceasedcraft:building_office4/building_office4_base2_palette_270",
  "xsize": 16,
  "zsize": 16,
  "slices": [
    [
      "vvvvvvvvvvvvvvvv",
      "vaaaaaaaaaaaaaav",
      "vaaaaaaaaaaaaaav",
      "vaaaaaaaaaaaaaav",
      "vaaaaaaaaaaaaaav",
      "vaaaaaaaaaaaaaav",
      "vaaaaaaaaaaaaaav",
      "vaaaaaaaaaaaaaav",
      "vaaaaaaaaaaaaaav",
      "vaaaaaaaaaaaaaav",
      "vaaaaaaaaaaaaaav",
      "vaaaaaaaaaaaaaav",
      "vaaaaaaaaaaaaaav",
      "vaaaaaaaaaaaaaav",
      "vaaaaaaaaaaaaaav",
      "vvvvvvvvvvvvvvvv"
    ],
    [
      "vvvvvvvvvvvvvvvv",
      "vaaaaaaaaaaaaaav",
      "va  cdtrpndc bav",
      "va  cm p  lc  av",
      "vaccc      cccav",
      "vadi   kk   idav",
      "vaBs  cccc   eav",
      "vaC  lc  cm jfav",
      "vaCy lc  cm  fav",
      "vaD x cccc   gav",
      "vadk   ii   kdav",
      "vacccw     cccav",
      "va  cm s  lc  av",
      "va!Acduqqodc hav",
      "vaaaaaaaaaaaaaav",
      "vvvvvvvvvvvvvvvv"
    ],
    [
      "vvvvvvvvvvvvvvvv",
      "vaaaaaaaaaaaaaav",
      "va  yd   ndy  av",
      "va  y      y  av",
      "vayy        yyav",
      "vad          dav",
      "vaP   Kyy    Eav",
      "vaQ   y  y   Fav",
      "vaR   y  y   Iav",
      "vaS    yyK   Jav",
      "vad          dav",
      "vay O       yyav",
      "vaA y      y  av",
      "va AydNML dy  av",
      "vaaaaaaaaaaaaaav",
      "vvvvvvvvvvvvvvvv"
    ],
    [
      "vvvvvvvvvvvvvvvv",
      "vaaaaaaaaaaaaaav",
      "va  yd   ndy  av",
      "va  y      y  av",
      "vayy        yyav",
      "vad          dav",
      "va0    yy    Tav",
      "va1   y  y   Uav",
      "va1   y  y   Uav",
      "va2    yy    Vav",
      "vad          dav",
      "vay         yyav",
      "va  Z      y  av",
      "va  ydYXXWdy  av",
      "vaaaaaaaaaaaaaav",
      "vvvvvvvvvvvvvvvv"
    ],
    [
      "vvvvvvvvvvvvvvvv",
      "vaaaaaaaaaaaaaav",
      "va  yd   ndy  av",
      "va  y      y  av",
      "vayy        yyav",
      "vad          dav",
      "va7    yy    3av",
      "va8   y  y   4av",
      "va9   y  y   3av",
      "va9    yy    3av",
      "vad          dav",
      "vay         yyav",
      "va  y      y  av",
      "va  yd66 5dy  av",
      "vaaaaaaaaaaaaaav",
      "vvvvvvvvvvvvvvvv"
    ],
    [
      "vvvvvvvvvvvvvvvv",
      "vaaaaaaaaaaaaaav",
      "va  yd   ndy  av",
      "va  y      y  av",
      "vayy        yyav",
      "vad          dav",
      "va     yy     av",
      "va    y  y    av",
      "va    y  y    av",
      "va     yy     av",
      "vad          dav",
      "vay#        yyav",
      "va  y      y  av",
      "va  yd    dy  av",
      "vaaaaaaaaaaaaaav",
      "vvvvvvvvvvvvvvvv"
    ]
  ]
}