{
  "name": "building_office4_floor1",
  "refpalette": "deceasedcraft:building_office4/building_office4_floor1_palette",
  "xsize": 16,
  "zsize": 16,
  "slices": [
    [
      "                ",
      " abbbcbbbbcbbba ",
      " bdddc    cdddb ",
      " bd   eeee   db ",
      " bd          db ",
      " ccfg        cc ",
      " b  h         b ",
      " b  h        ib ",
      " b jh        ib ",
      " bklh         b ",
      " ccfg        cc ",
      " bd          db ",
      " bd   mmmm   db ",
      " bdddc    cdddb ",
      " abbbcbbbbcbbba ",
      "                "
    ],
    [
      "                ",
      "  nbbcbbbbcbbo  ",
      " pqqqc    cqqqp ",
      " bq   eeee   qb ",
      " bq          qb ",
      " ccfg        cc ",
      " b  h         b ",
      " b jh        ib ",
      " b rh         b ",
      " b  h         b ",
      " ccfg        cc ",
      " bq          qb ",
      " bq   mmmm   qb ",
      " sqqqc    cqqqs ",
      "  nbbcbbbbcbbo  ",
      "                "
    ],
    [
      "                ",
      "   bbcbbbbcbb   ",
      "  qqqc    cqqq  ",
      " bq   eeee   qb ",
      " bq          qb ",
      " ccfg        cc ",
      " btjh         b ",
      " b rh         b ",
      " b  h        ib ",
      " b  h         b ",
      " ccfg        cc ",
      " bq          qb ",
      " bq   mmmm   qb ",
      "  qqqc    cqqq  ",
      "   bbcbbbbcbb   ",
      "                "
    ],
    [
      "                ",
      "   nbcbbbbcbo   ",
      "  qqqc    cqqq  ",
      " pq   eeee   qp ",
      " bq          qb ",
      " ccfg        cc ",
      " buwh         b ",
      " bl h        ib ",
      " b  h         b ",
      " b  h         b ",
      " ccfg        cc ",
      " bq          qb ",
      " sq   mmmm   qs ",
      "  qqqc    cqqq  ",
      "   nbcbbbbcbo   ",
      "                "
    ],
    [
      "                ",
      "   nbcbbbbcbo   ",
      "  qqqc~~~~cqqq  ",
      " pq   eeee   qp ",
      " bq          qb ",
      " ccfg        cc ",
      " b  h         b ",
      " bk h         b ",
      " bl h         b ",
      " b  h         b ",
      " ccfg        cc ",
      " bq          qb ",
      " sq   mmmm   qs ",
      "  qqqc~~~~cqqq  ",
      "   nbcbbbbcbo   ",
      "                "
    ],
    [
      "                ",
      "   nbcbbbbcbo   ",
      "  qqqcxxxxcqqq  ",
      " pqyyABBBBAyyqp ",
      " bqyyABBBBAyyqb ",
      " ccfgABBBBAyycc ",
      " b  CABBBBAyyDb ",
      " b  CABBBBAyyEb ",
      " bk CABBBBAyyDb ",
      " bl CABBBBAyyEb ",
      " ccfgABBBBAyycc ",
      " bqyyABBBBAyyqb ",
      " sqyyABBBBAyyqs ",
      "  qqqcxFxxcqqq  ",
      "   nbcbbbbcbo   ",
      "                "
    ]
  ]
}