{
  "name": "building_office4_floor2_90",
  "refpalette": "deceasedcraft:building_office4/building_office4_floor2_palette_90",
  "xsize": 16,
  "zsize": 16,
  "slices": [
    [
      "                ",
      "   gbcbbbbcbo   ",
      "  eeeckkkkceee  ",
      " deffffffffffed ",
      " befiiiiiiiifeb ",
      " ccfiiiiiiiifcc ",
      " bffiiiiiiiiffb ",
      " bffiiiiiiiiffb ",
      " bffiiiiiiiiffb ",
      " bffiiiiiiiiffb ",
      " ccfiiiiiiiifcc ",
      " behhjjjjjjifeb ",
      " aehhj  lnjffea ",
      "  eeec   mceee  ",
      "   gbcbbbbcbo   ",
      "                "
    ],
    [
      "                ",
      "   gbcbbbbcbo   ",
      "  pppcLNLPcppp  ",
      " dp   K      pd ",
      " bp          pb ",
      " cc  EE  EE  cc ",
      " bq  DJ  DJ  Tb ",
      " br xCI xCI  Ub ",
      " br  CI  CIRSUb ",
      " bq  BFM BF  Tb ",
      " ccswAAAAAA  cc ",
      " bp ukkkkkk  pb ",
      " ap ty lO Q  pa ",
      "  pppc    cppp  ",
      "   gbcbbbbcbo   ",
      "                "
    ],
    [
      "                ",
      "   gbcbbbbcbo   ",
      "  pppc# $&cppp  ",
      " dp          pd ",
      " bp          pb ",
      " cc          cc ",
      " bY  59   (  5b ",
      " bX  48  48  +b ",
      " bW  37  ^7  )b ",
      " bV  2X  %W   b ",
      " ccZ01!1111  cc ",
      " bp  kkkkkk  pb ",
      " ap  ylO  *  pa ",
      "  pppc6   cppp  ",
      "   gbcbbbbcbo   ",
      "                "
    ],
    [
      "                ",
      "   gbcbbbbcbo   ",
      "  pppc    cppp  ",
      " dp          pd ",
      " bp          pb ",
      " cc          cc ",
      " b            b ",
      " b            b ",
      " b            b ",
      " b            b ",
      " cc-0111111  cc ",
      " bp [kkkkkk  pb ",
      " ap  y{   }  pa ",
      "  pppc]n  cppp  ",
      "   gbcbbbbcbo   ",
      "                "
    ],
    [
      "                ",
      "   gbcbbbbcbo   ",
      "  pppc    cppp  ",
      " dp          pd ",
      " bp          pb ",
      " cc          cc ",
      " b            b ",
      " b            b ",
      " b            b ",
      " b            b ",
      " cc|;::::::  cc ",
      " bp  kkkkkk  pb ",
      " ap  y    y  pa ",
      "  pppc mn cppp  ",
      "   gbcbbbbcbo   ",
      "                "
    ],
    [
      "                ",
      "   gbcbbbbcbo   ",
      "  pppc,,''cppp  ",
      " dp>>>>>>>>>>pd ",
      " bp>>>>>>>>>>pb ",
      " cc>>>>>>>>>>cc ",
      " b'>>>>>>>>>>,b ",
      " b'>>>>>>>>>>'b ",
      " b'>>>>>>>>>>'b ",
      " b'>>>>>>>>>>'b ",
      " cc>>>>>>>>>>cc ",
      " bp<<kkkkkk<<pb ",
      " ap<<y   6y<<pa ",
      "  pppc  mncppp  ",
      "   gbcbbbbcbo   ",
      "                "
    ]
  ]
}