{
  "name": "building_office4_floor1_90",
  "refpalette": "deceasedcraft:building_office4/building_office4_floor1_palette_90",
  "xsize": 16,
  "zsize": 16,
  "slices": [
    [
      "                ",
      " abbbcbbbbcbbba ",
      " bdddc ii cdddb ",
      " bd          db ",
      " bd          db ",
      " cc          cc ",
      " b e        m b ",
      " b e        m b ",
      " b e        m b ",
      " b e        m b ",
      " cc          cc ",
      " bd  ghhhhg  db ",
      " bd  f  jlf  db ",
      " bdddc   kcdddb ",
      " abbbcbbbbcbbba ",
      "                "
    ],
    [
      "                ",
      "  pbbcbbbbcbbs  ",
      " oqqqc i  cqqqo ",
      " bq          qb ",
      " bq          qb ",
      " cc          cc ",
      " b e        m b ",
      " b e        m b ",
      " b e        m b ",
      " b e        m b ",
      " cc          cc ",
      " bq  ghhhhg  qb ",
      " bq  f jr f  qb ",
      " nqqqc    cqqqn ",
      "  pbbcbbbbcbbs  ",
      "                "
    ],
    [
      "                ",
      "   bbcbbbbcbb   ",
      "  qqqc  i cqqq  ",
      " bq          qb ",
      " bq          qb ",
      " cc          cc ",
      " b e        m b ",
      " b e        m b ",
      " b e        m b ",
      " b e        m b ",
      " cc          cc ",
      " bq  ghhhhg  qb ",
      " bq  fjr  f  qb ",
      "  qqqct   cqqq  ",
      "   bbcbbbbcbb   ",
      "                "
    ],
    [
      "                ",
      "   pbcbbbbcbs   ",
      "  qqqc i  cqqq  ",
      " oq          qo ",
      " bq          qb ",
      " cc          cc ",
      " b e        m b ",
      " b e        m b ",
      " b e        m b ",
      " b e        m b ",
      " cc          cc ",
      " bq  ghhhhg  qb ",
      " nq  fw   f  qn ",
      "  qqqcul  cqqq  ",
      "   pbcbbbbcbs   ",
      "                "
    ],
    [
      "                ",
      "   pbcbbbbcbs   ",
      "  qqqc    cqqq  ",
      " oq          qo ",
      " bq          qb ",
      " cc          cc ",
      " b~e        m~b ",
      " b~e        m~b ",
      " b~e        m~b ",
      " b~e        m~b ",
      " cc          cc ",
      " bq  ghhhhg  qb ",
      " nq  f    f  qn ",
      "  qqqc kl cqqq  ",
      "   pbcbbbbcbs   ",
      "                "
    ],
    [
      "                ",
      "   pbcbbbbcbs   ",
      "  qqqcDEDEcqqq  ",
      " oqyyyyyyyyyyqo ",
      " bqyyyyyyyyyyqb ",
      " ccAAAAAAAAAAcc ",
      " bxBBBBBBBBBBxb ",
      " bxBBBBBBBBBBxb ",
      " bxBBBBBBBBBBFb ",
      " bxBBBBBBBBBBxb ",
      " ccAAAAAAAAAAcc ",
      " bqyygCCCCgyyqb ",
      " nqyyf    fyyqn ",
      "  qqqc  klcqqq  ",
      "   pbcbbbbcbs   ",
      "                "
    ]
  ]
}