{
  "name": "building_office4_floor3_180",
  "refpalette": "deceasedcraft:building_office4/building_office4_floor3_palette_180",
  "xsize": 16,
  "zsize": 16,
  "slices": [
    [
      "                ",
      "   dbcbbbbcba   ",
      "  eeecffffceee  ",
      " oeffffffffffeo ",
      " befiiiiiiiifeb ",
      " ccfiiiiiiijjcc ",
      " bkfiiiiiiijnmb ",
      " bkfiiiiiiijl b ",
      " bkfiiiiiiij  b ",
      " bkfiiiiiiij  b ",
      " ccfiiiiiiijjcc ",
      " befiiiiiiihheb ",
      " geffffffffhheg ",
      "  eeecffffceee  ",
      "   dbcbbbbcba   ",
      "                "
    ],
    [
      "                ",
      "   dbcbbbbcba   ",
      "  pppcSTTScppp  ",
      " op          po ",
      " bp     RQ   pb ",
      " cc  EJIIFAkPcc ",
      " bO  EDCCBAk  b ",
      " bK    x  AkN b ",
      " bM     L Akl b ",
      " bK  EJIIFAk  b ",
      " cc  EDCCBAkycc ",
      " bp    x  wutpb ",
      " gp       s  pg ",
      "  pppcqrrqcppp  ",
      "   dbcbbbbcba   ",
      "                "
    ],
    [
      "                ",
      "   dbcbbbbcba   ",
      "  pppc-+1)cppp  ",
      " op          po ",
      " bp          pb ",
      " cc   (87 0k*cc ",
      " b&   ^32%0k  b ",
      " b$       0k  b ",
      " b        0kN b ",
      " b#   98760kl5b ",
      " cc   43210kycc ",
      " bp       Z  pb ",
      " gp       Y  pg ",
      "  pppcXWVUcppp  ",
      "   dbcbbbbcba   ",
      "                "
    ],
    [
      "                ",
      "   dbcbbbbcba   ",
      "  pppc    cppp  ",
      " op          po ",
      " bp          pb ",
      " cc       0k|cc ",
      " b        0k  b ",
      " b        0k  b ",
      " b        0k nb ",
      " b        0k}{b ",
      " cc       0kycc ",
      " bp       Z] pb ",
      " gp       [  pg ",
      "  pppc    cppp  ",
      "   dbcbbbbcba   ",
      "                "
    ],
    [
      "                ",
      "   dbcbbbbcba   ",
      "  pppc    cppp  ",
      " op          po ",
      " bp          pb ",
      " cc       'kycc ",
      " b        'k  b ",
      " b        'k nb ",
      " b        'k mb ",
      " b        'k  b ",
      " cc       'kycc ",
      " bp       :! pb ",
      " gp       ;  pg ",
      "  pppc    cppp  ",
      "   dbcbbbbcba   ",
      "                "
    ],
    [
      "                ",
      "   dbcbbbbcba   ",
      "  pppc>>><cppp  ",
      " op........,,po ",
      " bp........,,pb ",
      " cc........kycc ",
      " b>........k5nb ",
      " b<........k mb ",
      " b<........k  b ",
      " b>........k  b ",
      " cc........kycc ",
      " bp........,,pb ",
      " gp........,,pg ",
      "  pppc><<<cppp  ",
      "   dbcbbbbcba   ",
      "                "
    ]
  ]
}