{
  "name": "building_office4_floor3",
  "refpalette": "deceasedcraft:building_office4/building_office4_floor3_palette",
  "xsize": 16,
  "zsize": 16,
  "slices": [
    [
      "                ",
      "   abcbbbbcbd   ",
      "  eeecffffceee  ",
      " gehhffffffffeg ",
      " behhiiiiiiifeb ",
      " ccjjiiiiiiifcc ",
      " b  jiiiiiiifkb ",
      " b  jiiiiiiifkb ",
      " b ljiiiiiiifkb ",
      " bmnjiiiiiiifkb ",
      " ccjjiiiiiiifcc ",
      " befiiiiiiiifeb ",
      " oeffffffffffeo ",
      "  eeecffffceee  ",
      "   abcbbbbcbd   ",
      "                "
    ],
    [
      "                ",
      "   abcbbbbcbd   ",
      "  pppcqrrqcppp  ",
      " gp  s       pg ",
      " bptuw  x    pb ",
      " ccykABCCDE  cc ",
      " b  kAFIIJE  Kb ",
      " b lkA L     Mb ",
      " b NkA  x    Kb ",
      " b  kABCCDE  Ob ",
      " ccPkAFIIJE  cc ",
      " bp   QR     pb ",
      " op          po ",
      "  pppcSTTScppp  ",
      "   abcbbbbcbd   ",
      "                "
    ],
    [
      "                ",
      "   abcbbbbcbd   ",
      "  pppcUVWXcppp  ",
      " gp  Y       pg ",
      " bp  Z       pb ",
      " ccyk01234   cc ",
      " b5lk06789   #b ",
      " b Nk0        b ",
      " b  k0       $b ",
      " b  k0%23^   &b ",
      " cc*k0 78(   cc ",
      " bp          pb ",
      " op          po ",
      "  pppc)1+-cppp  ",
      "   abcbbbbcbd   ",
      "                "
    ],
    [
      "                ",
      "   abcbbbbcbd   ",
      "  pppc    cppp  ",
      " gp  [       pg ",
      " bp ]Z       pb ",
      " ccyk0       cc ",
      " b{}k0        b ",
      " bn k0        b ",
      " b  k0        b ",
      " b  k0        b ",
      " cc|k0       cc ",
      " bp          pb ",
      " op          po ",
      "  pppc    cppp  ",
      "   abcbbbbcbd   ",
      "                "
    ],
    [
      "                ",
      "   abcbbbbcbd   ",
      "  pppc    cppp  ",
      " gp  ;       pg ",
      " bp !:       pb ",
      " ccyk'       cc ",
      " b  k'        b ",
      " bm k'        b ",
      " bn k'        b ",
      " b  k'        b ",
      " ccyk'       cc ",
      " bp          pb ",
      " op          po ",
      "  pppc    cppp  ",
      "   abcbbbbcbd   ",
      "                "
    ],
    [
      "                ",
      "   abcbbbbcbd   ",
      "  pppc<<<>cppp  ",
      " gp,,........pg ",
      " bp,,........pb ",
      " ccyk........cc ",
      " b  k........>b ",
      " b  k........<b ",
      " bm k........<b ",
      " bn5k........>b ",
      " ccyk........cc ",
      " bp,,........pb ",
      " op,,........po ",
      "  pppc<>>>cppp  ",
      "   abcbbbbcbd   ",
      "                "
    ]
  ]
}