{
  "name": "building_office4_floor3_270",
  "refpalette": "deceasedcraft:building_office4/building_office4_floor3_palette_270",
  "xsize": 16,
  "zsize": 16,
  "slices": [
    [
      "                ",
      "   obcbbbbcbg   ",
      "  eeecm   ceee  ",
      " aeffjnl  jhhea ",
      " befijjjjjjhheb ",
      " ccfiiiiiiiifcc ",
      " bffiiiiiiiiffb ",
      " bffiiiiiiiiffb ",
      " bffiiiiiiiiffb ",
      " bffiiiiiiiiffb ",
      " ccfiiiiiiiifcc ",
      " befiiiiiiiifeb ",
      " deffffffffffed ",
      "  eeeckkkkceee  ",
      "   obcbbbbcbg   ",
      "                "
    ],
    [
      "                ",
      "   obcbbbbcbg   ",
      "  pppc    cppp  ",
      " ap  P Nl yt pa ",
      " bp  kkkkkku pb ",
      " cc  AAAAAAwscc ",
      " bS QFB  FB  qb ",
      " bT RIC LIC  rb ",
      " bT  ICx ICx rb ",
      " bS  JD  JD  qb ",
      " cc  EE  EE  cc ",
      " bp          pb ",
      " dp          pd ",
      "  pppcOKMKcppp  ",
      "   obcbbbbcbg   ",
      "                "
    ],
    [
      "                ",
      "   obcbbbbcbg   ",
      "  pppc   5cppp  ",
      " ap  *  Nly  pa ",
      " bp  kkkkkk  pb ",
      " cc  000000ZYcc ",
      " b)   %  61  Ub ",
      " b1  72  72  Vb ",
      " b+  83  83  Wb ",
      " b-  (^  94  Xb ",
      " cc          cc ",
      " bp          pb ",
      " dp          pd ",
      "  pppc&$ #cppp  ",
      "   obcbbbbcbg   ",
      "                "
    ],
    [
      "                ",
      "   obcbbbbcbg   ",
      "  pppc  n{cppp  ",
      " ap  |   }y  pa ",
      " bp  kkkkkk] pb ",
      " cc  000000Z[cc ",
      " b            b ",
      " b            b ",
      " b            b ",
      " b            b ",
      " cc          cc ",
      " bp          pb ",
      " dp          pd ",
      "  pppc    cppp  ",
      "   obcbbbbcbg   ",
      "                "
    ],
    [
      "                ",
      "   obcbbbbcbg   ",
      "  pppc nm cppp  ",
      " ap  y    y  pa ",
      " bp  kkkkkk! pb ",
      " cc  '''''':;cc ",
      " b            b ",
      " b            b ",
      " b            b ",
      " b            b ",
      " cc          cc ",
      " bp          pb ",
      " dp          pd ",
      "  pppc    cppp  ",
      "   obcbbbbcbg   ",
      "                "
    ],
    [
      "                ",
      "   obcbbbbcbg   ",
      "  pppcnm  cppp  ",
      " ap,,y5   y,,pa ",
      " bp,,kkkkkk,,pb ",
      " cc..........cc ",
      " b<..........<b ",
      " b>..........<b ",
      " b>..........<b ",
      " b>..........>b ",
      " cc..........cc ",
      " bp..........pb ",
      " dp..........pd ",
      "  pppc><<>cppp  ",
      "   obcbbbbcbg   ",
      "                "
    ]
  ]
}