{
  "name": "building_office4_base2_180",
  "refpalette": "deceasedcraft:building_office4/building_office4_base2_palette_180",
  "xsize": 16,
  "zsize": 16,
  "slices": [
    [
      "vvvvvvvvvvvvvvvv",
      "vaaaaaaaaaaaaaav",
      "vaaaaaaaaaaaaaav",
      "vaaaaaaaaaaaaaav",
      "vaaaaaaaaaaaaaav",
      "vaaaaaaaaaaaaaav",
      "vaaaaaaaaaaaaaav",
      "vaaaaaaaaaaaaaav",
      "vaaaaaaaaaaaaaav",
      "vaaaaaaaaaaaaaav",
      "vaaaaaaaaaaaaaav",
      "vaaaaaaaaaaaaaav",
      "vaaaaaaaaaaaaaav",
      "vaaaaaaaaaaaaaav",
      "vaaaaaaaaaaaaaav",
      "vvvvvvvvvvvvvvvv"
    ],
    [
      "vvvvvvvvvvvvvvvv",
      "vaaaaaaaaaaaaaav",
      "va! cdDCCBdc  av",
      "vaA ck y sic  av",
      "vaccc x    cccav",
      "vadmw  ll   mdav",
      "vau   cccc   tav",
      "vaqs ic  ck prav",
      "vaq  ic  ck  pav",
      "vao   cccc   nav",
      "vadl   mm   ldav",
      "vaccc      cccav",
      "va  ck  j ic  av",
      "vah cdgffedc bav",
      "vaaaaaaaaaaaaaav",
      "vvvvvvvvvvvvvvvv"
    ],
    [
      "vvvvvvvvvvvvvvvv",
      "vaaaaaaaaaaaaaav",
      "va AydSRQPdy  av",
      "vaA        y  av",
      "vayyO       yyav",
      "vad          dav",
      "vaN    yyK    av",
      "vaM   y  y    av",
      "vaL   y  y    av",
      "va    Kyy    nav",
      "vad          dav",
      "vayy        yyav",
      "va  y      y  av",
      "va  ydJIFEdy  av",
      "vaaaaaaaaaaaaaav",
      "vvvvvvvvvvvvvvvv"
    ],
    [
      "vvvvvvvvvvvvvvvv",
      "vaaaaaaaaaaaaaav",
      "va  yd2110dy  av",
      "va         y  av",
      "vayZ        yyav",
      "vad          dav",
      "vaY    yy     av",
      "vaX   y  y    av",
      "vaX   y  y    av",
      "vaW    yy    nav",
      "vad          dav",
      "vayy        yyav",
      "va  y      y  av",
      "va  ydVUUTdy  av",
      "vaaaaaaaaaaaaaav",
      "vvvvvvvvvvvvvvvv"
    ],
    [
      "vvvvvvvvvvvvvvvv",
      "vaaaaaaaaaaaaaav",
      "va  yd9987dy  av",
      "va         y  av",
      "vayy        yyav",
      "vad          dav",
      "va6    yy     av",
      "va6   y  y    av",
      "va    y  y    av",
      "va5    yy    nav",
      "vad          dav",
      "vayy        yyav",
      "va  y      y  av",
      "va  yd3343dy  av",
      "vaaaaaaaaaaaaaav",
      "vvvvvvvvvvvvvvvv"
    ],
    [
      "vvvvvvvvvvvvvvvv",
      "vaaaaaaaaaaaaaav",
      "va  yd    dy  av",
      "va  #      y  av",
      "vayy        yyav",
      "vad          dav",
      "va     yy     av",
      "va    y  y    av",
      "va    y  y    av",
      "va     yy    nav",
      "vad          dav",
      "vayy        yyav",
      "va  y      y  av",
      "va  yd    dy  av",
      "vaaaaaaaaaaaaaav",
      "vvvvvvvvvvvvvvvv"
    ]
  ]
}