{
  "name": "building_office4_floor4_270",
  "refpalette": "deceasedcraft:building_office4/building_office4_floor4_palette_270",
  "xsize": 16,
  "zsize": 16,
  "slices": [
    [
      "                ",
      "   obcbbbbcbg   ",
      "  eeecm   ceee  ",
      " aeffjnl  jhhea ",
      " befijjjjjjhheb ",
      " ccfiiiiiiiifcc ",
      " bffiiiiiiiiffb ",
      " bffiiiiiiiiffb ",
      " bffiiiiiiiiffb ",
      " bffiiiiiiiiffb ",
      " ccfiiiiiiiifcc ",
      " befiiiiiiiifeb ",
      " deffffffffffed ",
      "  eeeckkkkceee  ",
      "   obcbbbbcbg   ",
      "                "
    ],
    [
      "                ",
      "   obcbbbbcbg   ",
      "  pppc    cppp  ",
      " ap  I Cl ws pa ",
      " bp  kkkkkkt pb ",
      " cc    Dy  urcc ",
      " bq   FAAx   qb ",
      " bq    AA    qb ",
      " bq   FAAx   qb ",
      " bq    AA    qb ",
      " cc   FEBx   cc ",
      " bp          pb ",
      " dp          pd ",
      "  pppcqqqqcppp  ",
      "   obcbbbbcbg   ",
      "                "
    ],
    [
      "                ",
      "   obcbbbbcbg   ",
      "  pppc   Mcppp  ",
      " ap  X  Clw  pa ",
      " bp  kkkkkk  pb ",
      " cc     O  LKcc ",
      " bJ    TP    Jb ",
      " bJ     Q    Jb ",
      " bJ    UR    Jb ",
      " b!    VS    Jb ",
      " cc    WP    cc ",
      " bp          pb ",
      " dp          pd ",
      "  pppcNNNNcppp  ",
      "   obcbbbbcbg   ",
      "                "
    ],
    [
      "                ",
      "   obcbbbbcbg   ",
      "  pppc  n0cppp  ",
      " ap  3   1w  pa ",
      " bp  kkkkkkZ pb ",
      " cc        LYcc ",
      " bJ          Jb ",
      " bJ          Jb ",
      " bJ          Jb ",
      " bJ          Jb ",
      " cc          cc ",
      " bp          pb ",
      " dp          pd ",
      "  pppc2222cppp  ",
      "   obcbbbbcbg   ",
      "                "
    ],
    [
      "                ",
      "   obcbbbbcbg   ",
      "  pppc nm cppp  ",
      " ap  w    w  pa ",
      " bp  kkkkkk  pb ",
      " cc        87cc ",
      " b9          Vb ",
      " bO          4b ",
      " b#          5b ",
      " b$          6b ",
      " cc          cc ",
      " bp          pb ",
      " dp          pd ",
      "  pppc    cppp  ",
      "   obcbbbbcbg   ",
      "                "
    ],
    [
      "                ",
      "   obcbbbbcbg   ",
      "  pppcnm  cppp  ",
      " ap&&wM   w&&pa ",
      " bp&&kkkkkk&&pb ",
      " cc**********cc ",
      " b^**********%b ",
      " b%**********%b ",
      " b%**********^b ",
      " b%**********^b ",
      " cc**********cc ",
      " bp**********pb ",
      " dp**********pd ",
      "  pppc^^%^cppp  ",
      "   obcbbbbcbg   ",
      "                "
    ]
  ]
}