{
  "name": "building_office4_ground_270",
  "refpalette": "deceasedcraft:building_office4/building_office4_ground_palette_270",
  "xsize": 16,
  "zsize": 16,
  "slices": [
    [
      "aaaaaaaaaaaaaaaa",
      "abbbbbbbbbbbbbba",
      "abcccdcccgdcccba",
      "abccccccccccccba",
      "abccccccccccccba",
      "abdeeeeeeeeeedba",
      "abceffffffffecba",
      "abceffffffffecba",
      "abceffffffffecba",
      "abceffffffffecba",
      "abdeffffffffedba",
      "abceffffffffecba",
      "abceeeeeeeeeecba",
      "abcccdccccdcccba",
      "abbbbbbbbbbbbbba",
      "aaaaaaaaaaaaaaaa"
    ],
    [
      "                ",
      " hhhhdhhhhdhhhh ",
      " hiold  B dolih ",
      " hN  q ICtq  jh ",
      " hO  r uuur  kh ",
      " dd          dd ",
      " h M  w  w  m h ",
      " h M ssssss m h ",
      " h M  x  x  m h ",
      " h M        m h ",
      " dd          dd ",
      " hN          jh ",
      " hO    JD    kh ",
      " hipndyEEydpnih ",
      " hhhhdLKFAdhhhh ",
      "                "
    ],
    [
      "                ",
      " hhhhdhhhhdhhhh ",
      " hP  d  URd  Ph ",
      " h   q  ISq   h ",
      " h   r TTTr   h ",
      " dd          dd ",
      " h M        m h ",
      " h M V  V Q m h ",
      " h M        m h ",
      " h M        m h ",
      " dd          dd ",
      " h            h ",
      " h     YW     h ",
      " hP  dy  yd  Ph ",
      " hhhhdLZXAdhhhh ",
      "                "
    ],
    [
      "                ",
      " hhhhdhhhhdhhhh ",
      " hP  d  2Cd  Ph ",
      " h   q   0q   h ",
      " h   r TTTr   h ",
      " dd          dd ",
      " h M        m h ",
      " h M        m h ",
      " h M        m h ",
      " h M        m h ",
      " dd          dd ",
      " h            h ",
      " h            h ",
      " hP  dyyyyd  Ph ",
      " hhhhd4331dhhhh ",
      "                "
    ],
    [
      "                ",
      " hhhhdhhhhdhhhh ",
      " h   d 26 d   h ",
      " h   q    q   h ",
      " h   r TTTr   h ",
      " dd          dd ",
      " h M        m h ",
      " h M        m h ",
      " h M        m h ",
      " h M        m h ",
      " dd          dd ",
      " h            h ",
      " h            h ",
      " h   d7575d   h ",
      " hhhhdhhhhdhhhh ",
      "                "
    ],
    [
      "                ",
      " hhhhdhhhhdhhhh ",
      " h8  d26  d  8h ",
      " h   q    q   h ",
      " h   r TTTr   h ",
      " dd          dd ",
      " h M        m h ",
      " h M        m h ",
      " h M        m h ",
      " h M        m h ",
      " dd          dd ",
      " h            h ",
      " h            h ",
      " h8  d    d  8h ",
      " hhhhdhhhhdhhhh ",
      "                "
    ]
  ]
}