{
  "name": "building_office4_floor4_180",
  "refpalette": "deceasedcraft:building_office4/building_office4_floor4_palette_180",
  "xsize": 16,
  "zsize": 16,
  "slices": [
    [
      "                ",
      "   dbcbbbbcba   ",
      "  eeecffffceee  ",
      " oeffffffffffeo ",
      " befiiiiiiiifeb ",
      " ccfiiiiiiijjcc ",
      " bkfiiiiiiijnmb ",
      " bkfiiiiiiijl b ",
      " bkfiiiiiiij  b ",
      " bkfiiiiiiij  b ",
      " ccfiiiiiiijjcc ",
      " befiiiiiiihheb ",
      " geffffffffhheg ",
      "  eeecffffceee  ",
      "   dbcbbbbcba   ",
      "                "
    ],
    [
      "                ",
      "   dbcbbbbcba   ",
      "  pppcqqqqcppp  ",
      " op          po ",
      " bp          pb ",
      " cc        kIcc ",
      " bq  F F F k  b ",
      " bq  EAAAADkC b ",
      " bq  BAAAAykl b ",
      " bq  x x x k  b ",
      " cc        kwcc ",
      " bp       utspb ",
      " gp       r  pg ",
      "  pppcqqqqcppp  ",
      "   dbcbbbbcba   ",
      "                "
    ],
    [
      "                ",
      "   dbcbbbbcba   ",
      "  pppc!JJJcppp  ",
      " op          po ",
      " bp          pb ",
      " cc        kXcc ",
      " bN        k  b ",
      " bN  WVU T k  b ",
      " bN  PSRQPOkC b ",
      " bN        klMb ",
      " cc        kwcc ",
      " bp       L  pb ",
      " gp       K  pg ",
      "  pppcJJJJcppp  ",
      "   dbcbbbbcba   ",
      "                "
    ],
    [
      "                ",
      "   dbcbbbbcba   ",
      "  pppcJJJJcppp  ",
      " op          po ",
      " bp          pb ",
      " cc        k3cc ",
      " b2        k  b ",
      " b2        k  b ",
      " b2        k nb ",
      " b2        k10b ",
      " cc        kwcc ",
      " bp       LZ pb ",
      " gp       Y  pg ",
      "  pppcJJJJcppp  ",
      "   dbcbbbbcba   ",
      "                "
    ],
    [
      "                ",
      "   dbcbbbbcba   ",
      "  pppc$#O9cppp  ",
      " op          po ",
      " bp          pb ",
      " cc        kwcc ",
      " b         k  b ",
      " b         k nb ",
      " b         k mb ",
      " b         k  b ",
      " cc        kwcc ",
      " bp       8  pb ",
      " gp       7  pg ",
      "  pppc654Vcppp  ",
      "   dbcbbbbcba   ",
      "                "
    ],
    [
      "                ",
      "   dbcbbbbcba   ",
      "  pppc%%%^cppp  ",
      " op********&&po ",
      " bp********&&pb ",
      " cc********kwcc ",
      " b^********kMnb ",
      " b^********k mb ",
      " b%********k  b ",
      " b^********k  b ",
      " cc********kwcc ",
      " bp********&&pb ",
      " gp********&&pg ",
      "  pppc^^%%cppp  ",
      "   dbcbbbbcba   ",
      "                "
    ]
  ]
}