{
  "name": "multi_gasstation_1_ground",
  "refpalette": "deceasedcraft:multi_gasstation_1/multi_gasstation_1_ground_palette",
  "xsize": 16,
  "zsize": 16,
  "slices": [
    [
      "HHHHaHHaaaaaaabb",
      "HHHHHHHaaaaaaabb",
      "HHHHHHHaaaaaaabb",
      "HHHHaHHaaaaaaabb",
      "HHHHaHHaaaaaaabb",
      "HHHHaHHaaaaaaabb",
      "HHHHaHHaaaaaaabb",
      "HHHHaHHaaaaaaabb",
      "HHHHaHHaaaaaaabb",
      "HHHHaHHaaaaaaabb",
      "HHHHaHHaaaaaaabb",
      "HHHHaHHaaaaaaabb",
      "HHHHaHHaaaaaaabb",
      "HHHHHHHHHHHcbbbb",
      "HHHHHHHHHHHcbbbb",
      "bbbbbbbbbbbbbbbb"
    ],
    [
      "  def  g     h  ",
      "       ij kllh  ",
      "       im nnoh  ",
      "    f  g     h  ",
      "  pqr  g  stuh  ",
      "       h     h  ",
      "  def  g    wh  ",
      "  pqx  g    yh  ",
      "       iA   Bh  ",
      "  def  hCCDhhh  ",
      "  pqx  EF  IJh  ",
      "       EKLMhNh  ",
      "  def  hhhhhhh  ",
      "       O  Px    ",
      "       Q  Rx    ",
      "                "
    ],
    [
      "    f  g     h  ",
      "        S kklh  ",
      "        T onoh  ",
      "    f  g     h  ",
      "    U  g  Vush  ",
      "       h     h  ",
      "    f  g     h  ",
      "       g     h  ",
      "        W    h  ",
      "    f  hX  hhh  ",
      "       Y   Z h  ",
      "       Y   h0h  ",
      "    f  hhhhhhh  ",
      "                ",
      "                ",
      "                "
    ],
    [
      "    f  1     2  ",
      "       1     1  ",
      "       1     1  ",
      "    f  1     2  ",
      "       1     2  ",
      "       1     1  ",
      "    f  1     2  ",
      "       1     2  ",
      "       1     1  ",
      "    f  1   hh1  ",
      "       1  3h 2  ",
      "       1   h 2  ",
      "    f  1111111  ",
      "                ",
      "                ",
      "                "
    ],
    [
      "    h4 h  5 Jh  ",
      "       h     h  ",
      "       h     h  ",
      "    h4 h  4  h  ",
      "       h     h  ",
      "       hhhhhhh  ",
      "    h5 h  5  h  ",
      "       h     h  ",
      "       h    Jh  ",
      "    h! h  5hhh  ",
      "       h   h h  ",
      "       h   hJh  ",
      "    h5 hhhhhhh  ",
      "                ",
      "                ",
      "                "
    ],
    [
      " 6xxaxxxxxxxxa6 ",
      " 6xxaxxxxxxxxa6 ",
      " 6xxaxxxxxxxxa6 ",
      " 6xxaxxxxxxxxa6 ",
      " 6xxaxxxxxxxxa6 ",
      " 6xxaaaaaaaaaa6 ",
      " 6xxaxxxxxxxxa6 ",
      " 6xxaxxxxxxxxa6 ",
      " 6xxaxxxxxxxxa6 ",
      " 6xxaxxxxxxxxa6 ",
      " 6xxaxxxxxxxxa6 ",
      " 6xxaxxxxxxxxa6 ",
      " 6xxaaaaaaaaaa6 ",
      " 66666666666666 ",
      "                ",
      "                "
    ]
  ]
}