{
  "name": "multi_terraceplaza_32_floor2",
  "refpalette": "deceasedcraft:multi_terraceplaza_32/multi_terraceplaza_32_floor2_palette",
  "xsize": 16,
  "zsize": 16,
  "slices": [
    [
      "        ab      ",
      "        ab      ",
      "        cb      ",
      "        ab      ",
      " d      cb      ",
      "        ab      ",
      "        ab      ",
      " d      cb      ",
      "        cb      ",
      "eeeefghhab      ",
      "iiiijkhhcb      ",
      "iiiilmhhab      ",
      "nnnnnm  ab      ",
      "    om  cb      ",
      "     p  ab      ",
      "     q  ab      "
    ],
    [
      "        ab      ",
      " r      ab      ",
      "        cb      ",
      "        ab      ",
      " r      cb      ",
      "        ab      ",
      "iiiiighhab      ",
      "jjjjjkhhcb      ",
      "lllllmhhcb      ",
      "mmmmmm  ab      ",
      "mmmmmm  cb      ",
      "     p  ab      ",
      "     q  ab      ",
      "                ",
      "                ",
      "                "
    ],
    [
      "        ab      ",
      " r      ab      ",
      "        cb      ",
      "iiiiighhab      ",
      "jjjjjkhhcb      ",
      "sssslmhhab      ",
      "nnnnnm  ab      ",
      "ooooom  cb      ",
      "pppppp  cb      ",
      "qqqqqq  ab      ",
      "                ",
      "                ",
      "                ",
      "                ",
      "                ",
      "                "
    ],
    [
      "iiiiighhab      ",
      "jjjjjkhhab      ",
      "sssslmhhcb      ",
      "nnnnnm  ab      ",
      "ooooom  cb      ",
      "     p  ab      ",
      "     q  ab      ",
      "                ",
      "                ",
      "                ",
      "                ",
      "                ",
      "                ",
      "                ",
      "                ",
      "                "
    ],
    [
      "nnnnnm  ab      ",
      "ooooom  ab      ",
      "     p  cb      ",
      "     q  ab      ",
      "                ",
      "                ",
      "                ",
      "                ",
      "                ",
      "                ",
      "                ",
      "                ",
      "                ",
      "                ",
      "                ",
      "                "
    ],
    [
      "     q  ab      ",
      "                ",
      "                ",
      "                ",
      "                ",
      "                ",
      "                ",
      "                ",
      "                ",
      "                ",
      "                ",
      "                ",
      "                ",
      "                ",
      "                ",
      "                "
    ]
  ]
}