{
  "name": "multi_terraceplaza_32_ground",
  "refpalette": "deceasedcraft:multi_terraceplaza_32/multi_terraceplaza_32_ground_palette",
  "xsize": 16,
  "zsize": 16,
  "slices": [
    [
      "aaaabcddefghiHHH",
      "aaaabcddefgjiHHH",
      "aaaabcddefgjiHHH",
      "aaaabcddefgjiHHH",
      "aaaabcddefgjiHHH",
      "aaaabcddefgjiHHH",
      "aaaabcddefgjiHHH",
      "aaaabcddefghiHHH",
      "aaaabcddefgjiHHH",
      "kkkklmndefgjiHHH",
      "aaaabcddefgjiHHH",
      "aaaabcddefghiHHH",
      "aaaabcddefgjiHHH",
      "aaaabcddefgjiHHH",
      "aaaabcddefgjiHHH",
      "aaaabcddefgjiHHH"
    ],
    [
      "   o c  p qr    ",
      "st o c  p qu    ",
      "wx o c  p qu    ",
      "   o c  p qu    ",
      "   o c  p qu    ",
      "ykAk c  p qu    ",
      "kB k c  p qu    ",
      "kC k c  p qr    ",
      "kCBk c  p qD    ",
      "kkkkl   E FD    ",
      "IJJk c  p qD    ",
      "   k c  p qr    ",
      "KJ k c  p qu    ",
      "LkMk c  p qu    ",
      "N    c  p qu    ",
      "LOO  c  p qu    "
    ],
    [
      "   P    QRqS    ",
      "TU V c  QRq     ",
      "WX Y    ZRq     ",
      "   0 c  QRq     ",
      "   1 c  ZRq     ",
      "2k3k c  QRq     ",
      "k4 p    QRq     ",
      "k5 p c  ZRqS    ",
      "kB6k    ZR      ",
      "kkkkl   QR7     ",
      "  Jk c  ZR      ",
      "   p    QRqS    ",
      "L8 p    QRq     ",
      " k9k c  ZRq     ",
      "#    c  QRq     ",
      "#       QRq     "
    ],
    [
      "        QR      ",
      "        QR      ",
      "        ZR      ",
      "        QR      ",
      "        ZR      ",
      " k$k    QR      ",
      "k% k    QR      ",
      "k^ k    ZR      ",
      "k& k    ZR      ",
      "kkkkl   QRu     ",
      "  *k    ZR      ",
      "   k    QR      ",
      "(  k    QR      ",
      "$k)k    ZR      ",
      "        QR      ",
      "        QR      "
    ],
    [
      "        QR      ",
      "        QR      ",
      "        ZR      ",
      "        QR      ",
      "        ZR      ",
      " kkk    QR      ",
      "k  k    QR      ",
      "k+ k    ZR      ",
      "k- k    ZR      ",
      "kkkkl   QRu     ",
      "   k    ZR      ",
      "   k    QR      ",
      "   k    QR      ",
      "kkkk    ZR      ",
      "        QR      ",
      "        QR      "
    ],
    [
      "    [   QR      ",
      "    [   QR      ",
      "    [   ZR      ",
      "    [   QR      ",
      "    [   ZR      ",
      " kkk[   QR      ",
      "k   [   QR      ",
      "k   [   ZR      ",
      "k   [   ZR      ",
      "kkkkl   QR      ",
      "   k[   ZR      ",
      "   k[   QR      ",
      "   k[   QR      ",
      "kkkk[   ZR      ",
      "    [   QR      ",
      "    [   QR      "
    ]
  ]
}