{
  "name": "multi_terraceplaza_32_floor1",
  "refpalette": "deceasedcraft:multi_terraceplaza_32/multi_terraceplaza_32_floor1_palette",
  "xsize": 16,
  "zsize": 16,
  "slices": [
    [
      "    ab  cd      ",
      "    ab  cd      ",
      "    ab  ed      ",
      "    ab  cd      ",
      "    ab  ed      ",
      " fffab  cd      ",
      "f   ab  cd      ",
      "f   ab  ed      ",
      "f   ab  ed      ",
      "ffffgb  cd      ",
      "   fab  ed      ",
      "   fab  cd      ",
      "   fab  cd      ",
      "ffffab  ed      ",
      "    ab  cd      ",
      "    ab  cd      "
    ],
    [
      "hhhhijk cd      ",
      "llhhijk cd      ",
      "hhhhijk ed      ",
      "hhhhijk cd      ",
      "hhhhijk ed      ",
      "hhhhijk cd      ",
      "hhhhijk cd      ",
      "hhhhijk ed      ",
      "hhhhijk ed      ",
      "iiiigmnncd      ",
      "hhhhijk ed      ",
      "hhhhijk cd      ",
      "hhhhijk cd      ",
      "hhhhijk ed      ",
      "hhhhijk cd      ",
      "hhhhijk cd      "
    ],
    [
      "oooopq  cd      ",
      "oooopq  cd      ",
      "oooopq  ed      ",
      "oooopq  cd      ",
      "oooopq  ed      ",
      "oooopq  cd      ",
      "oooopq  cd      ",
      "oooopq  ed      ",
      "oooopq  ed      ",
      "rrrrgs  cd      ",
      "ttjjpq  ed      ",
      "jtjjpq  cd      ",
      "tjjjpq  cd      ",
      "jtjjpq  ed      ",
      "jjtjpq  cd      ",
      "jjjjpq  cd      "
    ],
    [
      "u    q  cd      ",
      "u    q  cd      ",
      "u    q  ed      ",
      "u    q  cd      ",
      "u    q  ed      ",
      "u    q  cd      ",
      "u  w q  cd      ",
      "     q  ed      ",
      "   x q  ed      ",
      "yAAAg   cd      ",
      "     q  ed      ",
      "  B  q  cd      ",
      "  C  q  cd      ",
      "  D  q  ed      ",
      "     q  cd      ",
      "     q  cd      "
    ],
    [
      "E  F    cd      ",
      "I  J    cd      ",
      "   F q  ed      ",
      "K  L q  cd      ",
      "M  N    ed      ",
      "O  J q  cd      ",
      "P    q  cd      ",
      "   Q    ed      ",
      "   R q  ed      ",
      "    g   cd      ",
      "        ed      ",
      "     q  cd      ",
      "        cd      ",
      "     q  ed      ",
      "     q  cd      ",
      "    STUUcd      "
    ],
    [
      "   V    cd      ",
      "   V    cd      ",
      "   V    ed      ",
      "   V    cd      ",
      "   V    ed      ",
      "   V    cd      ",
      "   V    cd      ",
      "   V    ed      ",
      "   W    ed      ",
      "    g   cd      ",
      "        ed      ",
      "        cd      ",
      "    STUUcd      ",
      "XXXYZ0UUed      ",
      "XXXYo1UUcd      ",
      "XXXY21  cd      "
    ]
  ]
}