{
  "name": "multi_terraceplaza_32_base2",
  "refpalette": "deceasedcraft:multi_terraceplaza_32/multi_terraceplaza_32_base2_palette",
  "xsize": 16,
  "zsize": 16,
  "slices": [
    [
      "aaaaaaaaaaabcccv",
      "aaaaaaaaaaabcccv",
      "aaaaaaaaaaabcccv",
      "aaaaaaaaaaabcccv",
      "aaaaaaaaaaabcccv",
      "aaaaaaaaaaabcccv",
      "aaaaaaaaaaabcccv",
      "aaaaaaaaaaabcccv",
      "aaaaaaaaaaabcccv",
      "aaaaaaaaaaabcccv",
      "aaaaaaaaaaabcccv",
      "aaaaaaaaaaabcccv",
      "aaaaaaaaaaabcccv",
      "aaaaaaaaaaabcccv",
      "aaaaaaaaaaabcccv",
      "aaaaaaaaaaabcccv"
    ],
    [
      " dd  dd efgbcccv",
      "ehhiejjiefgbcccv",
      "ehhiejjiefgbcccv",
      " kk  kk efgbcccv",
      " dd  dd efgbcccv",
      "elliemmiengbcccv",
      "elliemmiefgbcccv",
      " kk  kk efgbcccv",
      "         oobcccv",
      " pppppq  robcccv",
      "         oobcccv",
      " ssssss tugbcccv",
      "twwxwxxytugbcccv",
      "txwxxwwytugbcccv",
      " AAAAAA tugbcccv",
      " ssssss tugbcccv"
    ],
    [
      "         eBbcccv",
      "  C  DC  eBbcccv",
      " EF   I  eBbcccv",
      "         eBbcccv",
      "         eBbcccv",
      "  J  K   eLbcccv",
      " MC  NC  e!bcccv",
      "         eBbcccv",
      "         oobcccv",
      "         Oobcccv",
      "         oobcccv",
      "         tPbcccv",
      " Q QQR   tSbcccv",
      " TU Q Q  tPbcccv",
      "         tPbcccv",
      "         tPbcccv"
    ],
    [
      "          Ibcccv",
      "           bcccv",
      "          Ibcccv",
      "          Fbcccv",
      "          Vbcccv",
      "           bcccv",
      "          Ibcccv",
      "          Fbcccv",
      "         oobcccv",
      "         Wobcccv",
      "         oobcccv",
      "          Xbcccv",
      "           bcccv",
      "          Kbcccv",
      "          Xbcccv",
      "           bcccv"
    ],
    [
      "           bcccv",
      "           bcccv",
      "           bcccv",
      "           bcccv",
      "           bcccv",
      "           bcccv",
      "           bcccv",
      "           bcccv",
      "         oobcccv",
      "          obcccv",
      "         oobcccv",
      "           bcccv",
      "           bcccv",
      "           bcccv",
      "           bcccv",
      "           bcccv"
    ],
    [
      "         oYbcccv",
      "         oZbcccv",
      "         oYbcccv",
      "         oZbcccv",
      "         oYbcccv",
      "         oZbcccv",
      "         oYbcccv",
      "         oZbcccv",
      "         oobcccv",
      "          obcccv",
      "         oobcccv",
      "         oYbcccv",
      "         oZbcccv",
      "         oYbcccv",
      "         oZbcccv",
      "         oYbcccv"
    ]
  ]
}