{
  "name": "multi_terraceplaza_32_base1",
  "refpalette": "deceasedcraft:multi_terraceplaza_32/multi_terraceplaza_32_base1_palette",
  "xsize": 16,
  "zsize": 16,
  "slices": [
    [
      "         abcdddv",
      "        eabcdddv",
      "         abcdddv",
      "        fabcdddv",
      "         abcdddv",
      "         abcdddv",
      "         abcdddv",
      "         abcdddv",
      "         aacdddv",
      "          acdddv",
      "         aacdddv",
      "        gabcdddv",
      "        habcdddv",
      "        iabcdddv",
      "        habcdddv",
      "        fabcdddv"
    ],
    [
      "        ha cdddv",
      "        ga cdddv",
      "         a cdddv",
      "        ja cdddv",
      "         akcdddv",
      "         akcdddv",
      "         a cdddv",
      "         akcdddv",
      "         akcdddv",
      "          acdddv",
      "        hakcdddv",
      "        hakcdddv",
      "        ha cdddv",
      "        lakcdddv",
      "        ha cdddv",
      "        lakcdddv"
    ],
    [
      "         a cdddv",
      "         akcdddv",
      "         a cdddv",
      "         a cdddv",
      "         a cdddv",
      "         a cdddv",
      "         a cdddv",
      "         a cdddv",
      "         akcdddv",
      "          acdddv",
      "         a cdddv",
      "         a cdddv",
      "         akcdddv",
      "         a cdddv",
      "         a cdddv",
      "         a cdddv"
    ],
    [
      " mmnoooooakcdddv",
      " mmnoooooapcdddv",
      " mmnoooooakcdddv",
      " mmnoooooa cdddv",
      " mmnoooooakcdddv",
      " mmnoooooakcdddv",
      " mmnoooooapcdddv",
      " mmnoooooa cdddv",
      " mmnoooooa cdddv",
      " mmn      qcdddv",
      " mmnoooooa cdddv",
      " mmnoooooa cdddv",
      " mmnoooooapcdddv",
      " mmnoooooa cdddv",
      " mmnoooooakcdddv",
      " mmnoooooakcdddv"
    ],
    [
      "rrsnttttttucdddv",
      "rrsntwwwttucdddv",
      "rrsnttttttucdddv",
      "rrsnttttttucdddv",
      "rrsnttttttucdddv",
      "rrsnttttttucdddv",
      "rrsntwwwttucdddv",
      "rrsnttttttucdddv",
      "rrsnttttttucdddv",
      "rrsnttttttxcdddv",
      "rrsnttttttucdddv",
      "rrsnttttttucdddv",
      "rrsntwwwttucdddv",
      "rrsnttttttucdddv",
      "rrsnttttttucdddv",
      "rrsnttttttucdddv"
    ],
    [
      "yyAnBCdddddcdddv",
      "yyAnBCdddddcdddv",
      "yyAnBCdddddcdddv",
      "yyAnBCdddddcdddv",
      "yyAnBCdddddcdddv",
      "yyAnBCdddddcdddv",
      "yyAnBCdddddcdddv",
      "yyAnBCdddddcdddv",
      "yyAnBCdddddcdddv",
      "BBBBDEdddddcdddv",
      "yyAnBCdddddcdddv",
      "yyAnBCdddddcdddv",
      "yyAnBCdddddcdddv",
      "yyAnBCdddddcdddv",
      "yyAnBCdddddcdddv",
      "yyAnBCdddddcdddv"
    ]
  ]
}