{
  "name": "multi_terraceplaza_9_floor1",
  "refpalette": "deceasedcraft:multi_terraceplaza_9/multi_terraceplaza_9_floor1_palette",
  "xsize": 16,
  "zsize": 16,
  "slices": [
    [
      "aaaaaab         ",
      "      b         ",
      "      b         ",
      "ccccccb         ",
      "de  eeb         ",
      "ddddddb         ",
      "d  dedb         ",
      "fe f fb         ",
      "bbbbbbg         ",
      "      h         ",
      "      h         ",
      "      h         ",
      "      h         ",
      "      h         ",
      "      h         ",
      "bbb   h         "
    ],
    [
      "iiiiiijkkkkkkkkk",
      "iiiiiijkkkkkkkkk",
      "iiiiiijkkkkkkkkk",
      "iiiiiijkkkkkkkkk",
      "      jkkkkkkkkk",
      "      jkkkkkkkkk",
      "e     jkkkkkkkkk",
      "l  l ljkkkkkkkkk",
      "jjjjjjgjjjjjjjjj",
      "iiiiiijkkkkkkkkk",
      "iiiiiijkkkkkkkkk",
      "iiiiiijkkkkkkkkk",
      "iiiiiijkkkkkkkkk",
      "iiiiiijkkkkkkkkk",
      "iiiiiijkkkkkkkkk",
      "iiiiiijkkkkkkkkk"
    ],
    [
      "mmmmmmnooooooooo",
      "mmmmmmnooooooooo",
      "mmmmmmnooooooooo",
      "mmmmmmnooooooooo",
      "ppppppbooooooooo",
      "ppppppbooooooqoo",
      "ppppppbooooooqoo",
      "ppppppbooooooqoo",
      "bbbbbbgooooooqoo",
      "rrrrrrnooooooqoo",
      "rrrrrrnooooooooo",
      "rrrrrrnooooooooo",
      "rrrrrrnooooooooo",
      "rrrrrrnooooooooo",
      "rrrrrrnooooooooo",
      "rrrrrrnooooooooo"
    ],
    [
      "aaaaaas         ",
      "                ",
      "                ",
      "ccccccs         ",
      "      b      t  ",
      "cucucub      wt ",
      "x x x b      wy ",
      "xAxAxAb      wq ",
      "bbbbbbg      BCD",
      "    EFI       q ",
      "     FI      Jq ",
      "KKKK LM         ",
      "KKKK            ",
      "                ",
      "                ",
      "KKKK            "
    ],
    [
      "aaaaaaN         ",
      "                ",
      "                ",
      "ccccccO         ",
      "      b         ",
      "cPcPcPb         ",
      "x x x b         ",
      "x x x b         ",
      "bbbbbbg       Q ",
      "RSTUV I       W ",
      "     XI       Y ",
      "Z012  M         ",
      "3456            ",
      "                ",
      "                ",
      "2001            "
    ],
    [
      "aaaaaa          ",
      "                ",
      "                ",
      "cccccc          ",
      "      b         ",
      "c7c7c7b         ",
      "x x x b         ",
      "x x x b         ",
      "bbbbbbg       8 ",
      "99#$% I         ",
      "      I         ",
      "      M         ",
      "                ",
      "                ",
      "                ",
      "                "
    ]
  ]
}