{
  "name": "multi_terraceplaza_9_base2",
  "refpalette": "deceasedcraft:multi_terraceplaza_9/multi_terraceplaza_9_base2_palette",
  "xsize": 16,
  "zsize": 16,
  "slices": [
    [
      "aaaaaabccccccccc",
      "aaaaaaaccccccccc",
      "aaaaaaaccccccccc",
      "aaaaaabccccccccc",
      "aaaaaabccccccccc",
      "aaaaaabccccccccc",
      "aaaaaabccccccccc",
      "aaaaaabccccccccc",
      "bbbbbbdeeeeeeeee",
      "ffffffffffffffff",
      "ffffffffffffffff",
      "ffffffffffffffff",
      "ffffffffffffffff",
      "ffffffffffffffff",
      "ffffffffffffffff",
      "ffffffffffffffff"
    ],
    [
      "     gb         ",
      "      h         ",
      "      i         ",
      "      b         ",
      "     jb         ",
      "     kb         ",
      "    jkb         ",
      "    jkb         ",
      "bbbbbbdllm    ml",
      "n               ",
      "n               ",
      "n o             ",
      "n o             ",
      "n o  pqq  rrss  ",
      "n o  ptu  wxww  ",
      "n o             "
    ],
    [
      "      b         ",
      "      y         ",
      "      A         ",
      "      b         ",
      "      b         ",
      "      b         ",
      "      b         ",
      "      b         ",
      "bbbbbbdllm    ml",
      "                ",
      "                ",
      "                ",
      "                ",
      "                ",
      "          B C   ",
      "                "
    ],
    [
      "      b         ",
      "      D         ",
      "      D         ",
      "      b         ",
      "      b         ",
      "      b         ",
      "      b         ",
      "      b         ",
      "bbbbbbdllm    ml",
      "                ",
      "                ",
      "                ",
      "                ",
      "                ",
      "                ",
      "                "
    ],
    [
      "      b         ",
      "      b         ",
      "      b         ",
      "      b         ",
      "      b         ",
      "      b         ",
      "      b         ",
      "      b         ",
      "bbbbbbdllm    ml",
      "                ",
      "                ",
      "                ",
      "                ",
      "                ",
      "                ",
      "                "
    ],
    [
      "EEEEEEFIIIIIIIII",
      "EEEEEEFIIIIIIIII",
      "EEEEEEFIIIIIIIII",
      "EEEEEEFIIIIIIIII",
      "EEEEEEFIIIIIIIII",
      "EEEEEEFIIIIIIIII",
      "EEEEEEFIIIIIIIII",
      "EEEEEEFIIIIIIIII",
      "bbbbbbdFFFFFFFFF",
      "      J  KKKKKK ",
      "                ",
      "                ",
      "                ",
      "                ",
      "                ",
      "                "
    ]
  ]
}