{
  "name": "multi_terraceplaza_9_floor2",
  "refpalette": "deceasedcraft:multi_terraceplaza_9/multi_terraceplaza_9_floor2_palette",
  "xsize": 16,
  "zsize": 16,
  "slices": [
    [
      "aaaaaa          ",
      "                ",
      "                ",
      "bbbbbb          ",
      "      c         ",
      "bbbbbbc         ",
      "d d d c         ",
      "d d d c         ",
      "cccccce       f ",
      "      g         ",
      "      g         ",
      "      h         ",
      "                ",
      "                ",
      "                ",
      "                "
    ],
    [
      "aaaaaac         ",
      "      c         ",
      "      c         ",
      "bbbbbbc         ",
      "iiiiiic         ",
      "iiiiiic         ",
      "iiiiiic         ",
      "iiiiiic         ",
      "cccccce         ",
      "      j         ",
      "      j         ",
      "     kjl        ",
      "     kjl        ",
      "     kjl        ",
      "     kjl        ",
      "     kjl        "
    ],
    [
      "aaaaaac         ",
      "      c         ",
      "      c         ",
      "bbbbbbc         ",
      "mn n  c         ",
      "mmmmmmc         ",
      "m  mnmc         ",
      "o no oc         ",
      "cccccce         ",
      "      j         ",
      "      j         ",
      "      j         ",
      "      j         ",
      "      j         ",
      "      j         ",
      "      j         "
    ],
    [
      "iiiiiipqqqqqqqqq",
      "iiiiiipqqqqqqqqq",
      "iiiiiipqqqqqqqqq",
      "iiiiiipqqqqqqqqq",
      "n    npqqqqqqqqq",
      "n     pqqqqqqqqq",
      "      pqqqqqqqqq",
      "r  r rpqqqqqqqqq",
      "ppppppeppppppppp",
      "iiiiiipqqqqqqqqq",
      "iiiiiipqqqqqqqqq",
      "iissiipqqqqqqqqq",
      "iiiiiipqqqqqqqqq",
      "iiiiiipqqqqqqqqq",
      "iiiiiipqqqqqqqqq",
      "iiiiiipqqqqqqqqq"
    ],
    [
      "ttttttuwwwwwwwww",
      "ttttttuwwwwwwwww",
      "ttttttuwwwwwwwww",
      "ttttttuwwwwwwwww",
      "xxxxxxcwwwwwwwww",
      "xxxxxxcwwwwwwyww",
      "xxxxxxcwwwwwwyww",
      "xxxxxxcwwwwwwyww",
      "ccccccewwwwwwyww",
      "AAAAAAuwwwwwwyww",
      "AAAAAAuwwwwwwyww",
      "BBBAAAuwwwwwwyww",
      "CCCBAAuwwwwwwwww",
      "DDCBAAuwwwwwwwww",
      "DDCBAAuwwwwwwwww",
      "CCCBAAuwwwwwwwww"
    ],
    [
      "aaaaaaE         ",
      "                ",
      "                ",
      "bbbbbbE         ",
      "      c      F  ",
      "bIbIbIc      BF ",
      "d d d c      BJ ",
      "dKdKdKc      By ",
      "cccccce      L!M",
      "NNNN         By ",
      "             BO ",
      "             BF ",
      "             F  ",
      "                ",
      "                ",
      "                "
    ]
  ]
}