{
  "name": "multi_terraceplaza_9_floor3",
  "refpalette": "deceasedcraft:multi_terraceplaza_9/multi_terraceplaza_9_floor3_palette",
  "xsize": 16,
  "zsize": 16,
  "slices": [
    [
      "aaaaaab         ",
      "                ",
      "                ",
      "ccccccd         ",
      "      e         ",
      "cfcfcfe         ",
      "g g g e         ",
      "g g g e         ",
      "eeeeeeh       i ",
      "jjjj            ",
      "                ",
      "                ",
      "                ",
      "                ",
      "                ",
      "                "
    ],
    [
      "aaaaaa          ",
      "                ",
      "                ",
      "cccccc          ",
      "      e         ",
      "ckckcke         ",
      "g g g e         ",
      "g g g e         ",
      "eeeeeeh       l ",
      "jjjj            ",
      "                ",
      "                ",
      "                ",
      "                ",
      "                ",
      "                "
    ],
    [
      "aaaaaa          ",
      "                ",
      "                ",
      "cccccc          ",
      "      e         ",
      "cccccce         ",
      "g g g e         ",
      "g g g e         ",
      "eeeeeeh       l ",
      "jjjj            ",
      "                ",
      "                ",
      "                ",
      "                ",
      "                ",
      "                "
    ],
    [
      "aaaaaae         ",
      "      e         ",
      "      e         ",
      "cccccce         ",
      "mmmmmme         ",
      "mmmmmme         ",
      "mmmmmme         ",
      "mmmmmme         ",
      "eeeeeeh         ",
      "                ",
      "                ",
      "                ",
      "                ",
      "                ",
      "nnnnnnnnnnnnnnnn",
      "oooooopppppppppp"
    ],
    [
      "aaaaaae         ",
      "      e         ",
      "      e         ",
      "cccccce         ",
      "qr  rre         ",
      "s     e         ",
      "s     e         ",
      "!r    e         ",
      "eeeeeeh         ",
      "                ",
      "                ",
      "nnnnnnnnnnnnnnnn",
      "oooooopppppppppp",
      "tttttttttttttttt",
      "uuuuuuuuuuuuuuuu",
      "      wwwwwwwwww"
    ],
    [
      "xxxxxxe         ",
      "mmmmmme         ",
      "mmmmmme         ",
      "yyyyyye         ",
      "A     e         ",
      "      e         ",
      "      e         ",
      "     re         ",
      "BBBBBBhBBBBBBBBB",
      "pppppppppppppppp",
      "tttttttttttttttt",
      "uuuuuuuuuuuuuuuu",
      "      wwwwwwwwww",
      "                ",
      "                ",
      "                "
    ]
  ]
}