{
  "name": "multi_terraceplaza_9_ground",
  "refpalette": "deceasedcraft:multi_terraceplaza_9/multi_terraceplaza_9_ground_palette",
  "xsize": 16,
  "zsize": 16,
  "slices": [
    [
      "aaaaaabccccccccc",
      "aaaaaabccccccccc",
      "aaaaaabccccccccc",
      "aaaaaabccccccccc",
      "ddddddeccccccccc",
      "ddddddeccccccccc",
      "ddddddeccccccccc",
      "ddddddeccccccccc",
      "eeeeeefccccccccc",
      "ggggggbccccccccc",
      "ggggggbccccccccc",
      "ggggggbccccccccc",
      "ggggggbccccccccc",
      "ggggggbccccccccc",
      "ggggggbccccccccc",
      "ggggggbccccccccc"
    ],
    [
      "hhhhhhi         ",
      "                ",
      "                ",
      "jjjjjji         ",
      "      e         ",
      "jkjkjle         ",
      "m m m e         ",
      "mnmnmne       o ",
      "eeeeeef      pqr",
      " s  s t       u ",
      " wx wxt         ",
      "      y         ",
      " ss s t         ",
      " ww w t         ",
      " AA A t         ",
      "eee   t      B  "
    ],
    [
      "hhhhhhC         ",
      "                ",
      "                ",
      "jjjjjjD         ",
      "      e         ",
      "jEjEjFe         ",
      "m m m e         ",
      "m m m e         ",
      "eeeeeef       I ",
      "      t         ",
      " J  K t         ",
      "      y         ",
      "      t         ",
      " LM   t         ",
      "      t         ",
      "eee   t         "
    ],
    [
      "hhhhhh          ",
      "                ",
      "                ",
      "jjjjjj          ",
      "      e         ",
      "jNjNjNe         ",
      "m m m e         ",
      "m m m e         ",
      "eeeeeef       O ",
      "      t         ",
      "      t         ",
      "      y         ",
      "      t         ",
      "      t         ",
      "      t         ",
      "eee   t         "
    ],
    [
      "hhhhhh          ",
      "                ",
      "                ",
      "jjjjjj          ",
      "      e         ",
      "jjjjjje         ",
      "m m m e         ",
      "m m m e         ",
      "eeeeeef       O ",
      "      t         ",
      "      t         ",
      "      y         ",
      "      t         ",
      "      t         ",
      " P    t         ",
      "eee   t         "
    ],
    [
      "hhhhhhe         ",
      "      e         ",
      "      e         ",
      "jjjjjje         ",
      "QQQQQQe         ",
      "QQQQQQe         ",
      "QQQQQQe         ",
      "QQQQQ!e         ",
      "eeeeeef         ",
      "      R         ",
      "      R         ",
      "      R         ",
      "      R         ",
      "      R         ",
      " S    R         ",
      "eee   R         "
    ]
  ]
}