{
  "name": "multi_terraceplaza_9_floor4",
  "refpalette": "deceasedcraft:multi_terraceplaza_9/multi_terraceplaza_9_floor4_palette",
  "xsize": 16,
  "zsize": 16,
  "slices": [
    [
      "a     b         ",
      "c de  b         ",
      "c fg  b         ",
      "a     b         ",
      "h     b         ",
      "      biiiiiiiii",
      "      bjjjjjjjjj",
      "      bkkkkkkkkk",
      "llllllllllllllll",
      "llllllllllllllll",
      "                ",
      "                ",
      "                ",
      "                ",
      "                ",
      "                "
    ],
    [
      "m     b         ",
      "n op  b         ",
      "  qr  biiiiiiiii",
      "      bjjjjjjjjj",
      "      bkkkkkkkkk",
      "ssssssllllllllll",
      "llllllllllllllll",
      "tttttttttttttttt",
      "uuuuuuuuuuuuuuuu",
      "                ",
      "                ",
      "                ",
      "                ",
      "                ",
      "                ",
      "                "
    ],
    [
      "      bjjjjjjjjj",
      "hah   bkkkkkkkkk",
      "ssssssllllllllll",
      "llllllllllllllll",
      "tttttttttttttttt",
      "uuuuuuuuuuuuuuuu",
      "                ",
      "                ",
      "                ",
      "                ",
      "                ",
      "                ",
      "                ",
      "                ",
      "                ",
      "                "
    ],
    [
      "llllllllllllllll",
      "tttttttttttttttt",
      "uuuuuuuuuuuuuuuu",
      "                ",
      "                ",
      "                ",
      "                ",
      "                ",
      "                ",
      "                ",
      "                ",
      "                ",
      "                ",
      "                ",
      "                ",
      "                "
    ],
    [
      "                ",
      "                ",
      "                ",
      "                ",
      "                ",
      "                ",
      "                ",
      "                ",
      "                ",
      "                ",
      "                ",
      "                ",
      "                ",
      "                ",
      "                ",
      "                "
    ],
    [
      "                ",
      "                ",
      "                ",
      "                ",
      "                ",
      "                ",
      "                ",
      "                ",
      "                ",
      "                ",
      "                ",
      "                ",
      "                ",
      "                ",
      "                ",
      "                "
    ]
  ]
}