{
  "name": "multi_terraceplaza_9_base1",
  "refpalette": "deceasedcraft:multi_terraceplaza_9/multi_terraceplaza_9_base1_palette",
  "xsize": 16,
  "zsize": 16,
  "slices": [
    [
      "aaaaaabccccccccc",
      "aaaaaabccccccccc",
      "aaaaaabccccccccc",
      "aaaaaabccccccccc",
      "ddddddeccccccccc",
      "ddddddeccccccccc",
      "ddddddecccffgccc",
      "ddddddeccccchccc",
      "eeeeeeijjjjjjjjj",
      "                ",
      "                ",
      "                ",
      "                ",
      "                ",
      "                ",
      "                "
    ],
    [
      "kkkkkkl         ",
      "                ",
      "                ",
      "mmmmmml         ",
      "      e         ",
      "mnmnmne         ",
      "o o o e  pqq rs ",
      "ototote   puwww ",
      "eeeeeeixxxxxxxxx",
      "                ",
      "                ",
      "                ",
      "                ",
      "                ",
      "                ",
      "                "
    ],
    [
      "kkkkkky         ",
      "                ",
      "                ",
      "mmmmmmA         ",
      "      e         ",
      "mBmBmBe         ",
      "o o o e         ",
      "o o o e      CD ",
      "eeeeeei         ",
      "                ",
      "                ",
      "                ",
      "                ",
      "                ",
      "                ",
      "                "
    ],
    [
      "kkkkkk          ",
      "                ",
      "                ",
      "mmmmmm          ",
      "      e         ",
      "mEmEmEe         ",
      "o o o e         ",
      "o o o e         ",
      "eeeeeei         ",
      "FFFFFFFFFFFFFFFF",
      "IIIIIIIIIIIIIIII",
      "IIIIIIIIIIIIIIII",
      "              II",
      "              II",
      "              II",
      "              II"
    ],
    [
      "kkkkkkJ         ",
      "      J         ",
      "      J         ",
      "mmmmmmJ         ",
      "      e         ",
      "mmmmmme         ",
      "o o o e         ",
      "o o o e         ",
      "eeeeeei         ",
      "FFFFFFFFFFFFFFFF",
      "KKKKKKKKKKKKKKKK",
      "LLLLLLLLLLLLLLLK",
      "LLLLLLLLLLLLLLLK",
      "LLLLLLLLLLLLLLLK",
      "LLLLLLLLLLLLLLLK",
      "LLLLLLLLLLLLLLLK"
    ],
    [
      "MMMMMMNOOOOOOOOO",
      "MMMMMMNOOOOOOOOO",
      "MMMMMMNOOOOOOOOO",
      "MMMMMMNOOOOOOOOO",
      "MMMMMMNOOOOOOOOO",
      "MMMMMMNOOOOOOOOO",
      "MMMMMMNOOOOOOOOO",
      "MMMMMMNOOOOOOOOO",
      "NNNNNNiNNNNNNNNN",
      "MMMMMMNMMMMMMMMM",
      "PPPPPPNPPPPPPPPP",
      "QQQQQQNQQQQQQQQP",
      "QQQQQQNQQQQQQQQP",
      "QQQQQQNQQQQQQQQP",
      "QQQQQQNQQQQQQQQP",
      "QQQQQQNQQQQQQQQP"
    ]
  ]
}