{
  "name": "multi_flatlarge_3_ground",
  "refpalette": "deceasedcraft:multi_flatlarge_3/multi_flatlarge_3_ground_palette",
  "xsize": 16,
  "zsize": 16,
  "slices": [
    [
      "aaaaaaaaaaaaaaaa",
      "bbbbbaaaaaaaabbb",
      "bbbbbcaacaaaabbb",
      "bbbbbcaacaaaabbb",
      "bbbbbcaacaaaabbb",
      "bbbbbcaacaaaabbb",
      "bbbbbcaacaaaabbb",
      "bbbbbcaacaaaabbb",
      "bbbbbcaacaaaabbb",
      "bbbbbcaacaaaabbb",
      "bbbbbccccaaaabbb",
      "bbbbbaddaaaaabbb",
      "ddbbbddddddddbbb",
      "eeeeeeeeeeeeeeee",
      "HHHHHHHHHHHHHHHH",
      "HHHHHHHHHHHHHHHH"
    ],
    [
      "fgggfh  ifggfgfg",
      "jkjkjl  l       ",
      "     c cc  m    ",
      "     c an  m    ",
      "opopocqan  m    ",
      "     caan       ",
      "     caan       ",
      "     caan       ",
      "j    caan  m    ",
      "     caan  m    ",
      "     cccc  m    ",
      "o    l  lr      ",
      "ss   ssssssss   ",
      "                ",
      "                ",
      "                "
    ],
    [
      "                ",
      "     t  t       ",
      "     c cc       ",
      "     c au       ",
      "     c au       ",
      "     cqau       ",
      "     caau       ",
      "     caau       ",
      "     caau       ",
      "     caau       ",
      "     cccc       ",
      "     t  t       ",
      "                ",
      "                ",
      "                ",
      "                "
    ],
    [
      "                ",
      "     t  t       ",
      "     cccc       ",
      "     c au       ",
      "     c au       ",
      "     c au       ",
      "     cqau       ",
      "     caau       ",
      "     caau       ",
      "     c  u       ",
      "     cccc       ",
      "     t  t       ",
      "                ",
      "                ",
      "                ",
      "                "
    ],
    [
      "                ",
      "wwwwwtwwtwwwwwww",
      "     cccc       ",
      "     c ax       ",
      "     c ax       ",
      "     c ax       ",
      "     c yx       ",
      "     c  x       ",
      "     c  x       ",
      "     c  x       ",
      "     cccc       ",
      "AAAAAtAAtAAAAAAA",
      "                ",
      "                ",
      "                ",
      "                "
    ],
    [
      "BBBBBCBBCBBBBBBB",
      "CCCCCCCCCCCCCCCC",
      "BBBBBccccBBBBBBB",
      "BBBBBcDacBBBBBBB",
      "BBBBBc acBBBBBBB",
      "BBBBBc ycBBBBBBB",
      "BBBBBc  cBBBBBBB",
      "BBBBBc  cBBBBBBB",
      "BBBBBc  cBBBBBBB",
      "BBBBBc  cBBBBBBB",
      "BBBBBcEEcBBBBBBB",
      "CCCCCCCCCCCCCCCC",
      "wwwwwwwwwwwwwwww",
      "                ",
      "                ",
      "                "
    ]
  ]
}