{
  "name": "multi_flatlarge_3_floor1",
  "refpalette": "deceasedcraft:multi_flatlarge_3/multi_flatlarge_3_floor1_palette",
  "xsize": 16,
  "zsize": 16,
  "slices": [
    [
      "aaaaaaaaaaaaaaaa",
      "aaaaaaaaaaaaaaaa",
      "bbbbbcbbcbbbbbbb",
      "bbbbbcbbcbbbbbbb",
      "bbbbbcdecbbbbbbb",
      "bbbbbc  cbbbbbbb",
      "bbbbbc  cbbbbbbb",
      "bbbbbc  cbbbbbbb",
      "bbbbbc  cbbbbbff",
      "bbbbbc  cbbbbbff",
      "bbbbbccccbbbbbff",
      "bbbbbcghcbbbbbff",
      "ccccci  iccccccc",
      "                ",
      "                ",
      "                "
    ],
    [
      "                ",
      "jjjkjl  ljmjjjjj",
      " cn oc  cp qc   ",
      "rcs tc  cu wcxy ",
      "rcn ocA cp qcxy ",
      " c  Bcd cC  c   ",
      " D  qc  cn  E   ",
      "cc FIc  cIF cccJ",
      "K  LLc  cLL  KM ",
      "N    c  c    OM ",
      "P   QccccR   SM ",
      "T   UcghcV   WM ",
      "MMMMci  icMMMMXM",
      "                ",
      "                ",
      "                "
    ],
    [
      "                ",
      "jjjYj    jZjjjjj",
      " c   c  c   c   ",
      " c   c  c   c   ",
      " c   c  c   c   ",
      " c  0cA c1  c   ",
      " 2   cd c   3   ",
      "cc   c  c   ccc4",
      "     c  c     M ",
      "     c  c     M ",
      "     cccc     M ",
      " 567 cghc 765 M ",
      "M888ci  ic888MX8",
      "                ",
      "                ",
      "                "
    ],
    [
      "                ",
      "jjj9j    j9jjjjj",
      " c#  c  c  $c   ",
      " c#  c  c  $c   ",
      " c#  c  c  $c   ",
      " c   c  c   c   ",
      " g   cA%c   h   ",
      "cc   cddc   ccc9",
      "     c^^c     M ",
      "     c  c     M ",
      "     c&&c     M ",
      " *() cghc )(* M ",
      "M888ci  ic888MX8",
      "                ",
      "                ",
      "                "
    ],
    [
      "                ",
      "jjjjj    jjjjjjj",
      " c   c  c   c   ",
      " c   c  c   c   ",
      " c   c  c   c   ",
      " c   c %c   c   ",
      " c   c ec   c   ",
      "cc   c  c   cccc",
      "     c++c     c-",
      "     c  c     c-",
      "     cccc     c-",
      "     cghc     c-",
      "ccccci  iccccccc",
      "                ",
      "                ",
      "                "
    ],
    [
      "[[[[[[[[[[[[[[[[",
      "]]]]]]]]]]]]]]]]",
      "aaaaac  caaaaaaa",
      "aaaaac  caaaaaaa",
      "aaaaac %caaaaaaa",
      "aaaaac ecaaaaaaa",
      "aaaaac  caaaaaaa",
      "aaaaac  caaaaaaa",
      "aaaaac  caaaaaa ",
      "aaaaac  caaaaaa ",
      "aaaaac&&caaaaaa ",
      "aaaaacghcaaaaaaa",
      "&&&&&i  i&&&&&&&",
      "                ",
      "                ",
      "                "
    ]
  ]
}