{
  "name": "multi_flatlarge_3_top",
  "refpalette": "deceasedcraft:multi_flatlarge_3/multi_flatlarge_3_top_palette",
  "xsize": 16,
  "zsize": 16,
  "slices": [
    [
      "aaaaabccbaaaaaaa",
      "dddddbccbddddddd",
      "cccccccccccccccc",
      "cccccbccbccccccc",
      "cccccb ebccccccc",
      "cccccb  bccccccc",
      "cccccb  bccccccc",
      "cccccb  bccccccc",
      "cccccb  bccccccc",
      "cccccb  bccccccc",
      "cccccbbbbccccccc",
      "cccccfghfccccccc",
      "bbbbbi  ibbbbbbb",
      "                ",
      "                ",
      "                "
    ],
    [
      "     b  b       ",
      "iiiiib  biiiiiii",
      "                ",
      "     bj b       ",
      "     b  b       ",
      "     b  b       ",
      "     b  b       ",
      "     b  b       ",
      "     b  b       ",
      "     b  b       ",
      "     bbbb       ",
      "     kghk       ",
      "iiiiii  iiiiiiii",
      "                ",
      "                ",
      "                "
    ],
    [
      "     l  l       ",
      "     b  b       ",
      "                ",
      "     b  b       ",
      "     b  b       ",
      "     b  b       ",
      "     b  b       ",
      "     b  b       ",
      "     b  b       ",
      "     b  b       ",
      "     bbbb       ",
      "     m  m       ",
      "                ",
      "                ",
      "                ",
      "                "
    ],
    [
      "    nnnnnn      ",
      "    nnnnnn      ",
      "    nnnnnn      ",
      "    nnnnnn      ",
      "    nnnnnn      ",
      "    nnnnnn      ",
      "    nnnnnn      ",
      "    nnnnnn      ",
      "    nnnnnn      ",
      "    nnnnnn      ",
      "    nnnnnn      ",
      "    nnnnnn      ",
      "                ",
      "                ",
      "                ",
      "                "
    ]
  ]
}