{
  "name": "multi_flatlarge_3_floor2",
  "refpalette": "deceasedcraft:multi_flatlarge_3/multi_flatlarge_3_floor2_palette",
  "xsize": 16,
  "zsize": 16,
  "slices": [
    [
      "aaaaaaaaaaaaaaaa",
      "aaaaaaaaaaaaaaaa",
      "bbbbbcbbcbbbbbbb",
      "bbbbbcbbcbbbbbbb",
      "bbbbbcdecbbbbbbb",
      "bbbbbc  cbbbbbbb",
      "bbbbbc  cbbbbbbb",
      "bbbbbc  cbbbbbbb",
      "bbbbbc  cbbbbbff",
      "bbbbbc  cbbbbbff",
      "bbbbbccccbbbbbff",
      "bbbbbcghcbbbbbff",
      "ccccci  iccccccc",
      "                ",
      "                ",
      "                "
    ],
    [
      "                ",
      "jjjkjl  ljmjjjjj",
      " cn oc  cp qc   ",
      "rcs tc  cu wcxy ",
      "rcn ocA cp qcxy ",
      " c  Bcd cC  c   ",
      " D  qc  cn  E   ",
      "cc FIc  cJF cccK",
      "L  MMc  cMM  LN ",
      "O    c  c    PN ",
      "Q   RccccS   TN ",
      "U   VcghcW   XN ",
      "NNNNci  icNNNNYN",
      "                ",
      "                ",
      "                "
    ],
    [
      "                ",
      "jjjZj    j0jjjjj",
      " c   c  c   c   ",
      " c   c  c   c   ",
      " c   c  c   c   ",
      " c  1cA c2  c   ",
      " 3   cd c   4   ",
      "cc   c  c   ccc5",
      "     c  c     N ",
      "     c  c     N ",
      "     cccc     N ",
      " 678 cghc 678 N ",
      "N999ci  ic999NY9",
      "                ",
      "                ",
      "                "
    ],
    [
      "                ",
      "jjj#j    j#jjjjj",
      " c$  c  c  %c   ",
      " c$  c  c  %c   ",
      " c$  c  c  %c   ",
      " c   c  c   c   ",
      " g   cA^c   h   ",
      "cc   cddc   ccc#",
      "     c&&c     N ",
      "     c  c     N ",
      "     c**c     N ",
      " ()+ cghc ()+ N ",
      "N999ci  ic999NY9",
      "                ",
      "                ",
      "                "
    ],
    [
      "                ",
      "jjjjj    jjjjjjj",
      " c   c  c   c   ",
      " c   c  c   c   ",
      " c   c  c   c   ",
      " c   c ^c   c   ",
      " c   c ec   c   ",
      "cc   c  c   cccc",
      "     c--c     c[",
      "     c  c     c[",
      "     cccc     c[",
      "     cghc     c[",
      "ccccci  iccccccc",
      "                ",
      "                ",
      "                "
    ],
    [
      "]]]]]]]]]]]]]]]]",
      "{{{{{{{{{{{{{{{{",
      "aaaaac  caaaaaaa",
      "aaaaac  caaaaaaa",
      "aaaaac ^caaaaaaa",
      "aaaaac ecaaaaaaa",
      "aaaaac  caaaaaaa",
      "aaaaac  caaaaaaa",
      "aaaaac  caaaaaa ",
      "aaaaac  caaaaaa ",
      "aaaaaccccaaaaaa ",
      "aaaaacghcaaaaaaa",
      "*****i  i*******",
      "                ",
      "                ",
      "                "
    ]
  ]
}