{
  "name": "multi_timbertower_5_floor6",
  "refpalette": "deceasedcraft:multi_timbertower_5/multi_timbertower_5_floor6_palette",
  "xsize": 16,
  "zsize": 16,
  "slices": [
    [
      "aaaaaaaaaaaaaaaa",
      "aaaaaaaaaaaaaaaa",
      "aaaabaaaaaabaaaa",
      "ccccdccccccdcccc",
      "efffgeeefffgeeef",
      "    h      h    ",
      "                ",
      "                ",
      "                ",
      "                ",
      "                ",
      "                ",
      "                ",
      "                ",
      "                ",
      "                "
    ],
    [
      " ijklmjn ioon io",
      " ijplqjn rss   s",
      "ttttbttttttbtttt",
      "                ",
      "efffheeefffheeef",
      "                ",
      "                ",
      "                ",
      "                ",
      "                ",
      "                ",
      "                ",
      "                ",
      "                ",
      "                ",
      "                "
    ],
    [
      "  u w r   x    y",
      "    A           ",
      "ttttbttttttbtttt",
      "                ",
      "efffheeefffheeef",
      "                ",
      "                ",
      "                ",
      "                ",
      "                ",
      "                ",
      "                ",
      "                ",
      "                ",
      "                ",
      "                "
    ],
    [
      "                ",
      "                ",
      "ttttbttttttbtttt",
      "                ",
      "efffheeefffheeef",
      "                ",
      "                ",
      "                ",
      "                ",
      "                ",
      "                ",
      "                ",
      "                ",
      "                ",
      "                ",
      "                "
    ],
    [
      "                ",
      "                ",
      "BCBCbBCBCBCbBCBC",
      "                ",
      "efffheeefffheeef",
      "                ",
      "                ",
      "                ",
      "                ",
      "                ",
      "                ",
      "                ",
      "                ",
      "                ",
      "                ",
      "                "
    ],
    [
      "DDEDFDEDDIDFDIDD",
      "DDDDFDDDDDDFDDDD",
      "JJJJbJJJJJJbJJJJ",
      "    g      g    ",
      "efffheeefffheeef",
      "                ",
      "                ",
      "                ",
      "                ",
      "                ",
      "                ",
      "                ",
      "                ",
      "                ",
      "                ",
      "                "
    ]
  ]
}