{
  "name": "multi_timbertower_5_floor13",
  "refpalette": "deceasedcraft:multi_timbertower_5/multi_timbertower_5_floor13_palette",
  "xsize": 16,
  "zsize": 16,
  "slices": [
    [
      "aaaaaaaaaaaaaaaa",
      "aaaaaaaaaaaaaaaa",
      "aaaabaaaaaabaaaa",
      "cdddecccdddecccd",
      "    f      f    ",
      "                ",
      "                ",
      "                ",
      "                ",
      "                ",
      "                ",
      "                ",
      "                ",
      "                ",
      "                ",
      "                "
    ],
    [
      "gh ijklmklmn l l",
      "goipj lllllllq q",
      "rrrrbrrrrrrbrrrr",
      "cdddecccdddecccd",
      "    f      f    ",
      "                ",
      "                ",
      "                ",
      "                ",
      "                ",
      "                ",
      "                ",
      "                ",
      "                ",
      "                ",
      "                "
    ],
    [
      "s   jtuwtuwn    ",
      " h ij      n x x",
      "rrrrbrrrrrrbrrrr",
      "cdddecccdddecccd",
      "    f      f    ",
      "                ",
      "                ",
      "                ",
      "                ",
      "                ",
      "                ",
      "                ",
      "                ",
      "                ",
      "                ",
      "                "
    ],
    [
      "    jyAByABCDDDD",
      "    j      CEEEE",
      "rrrrbrrrrrrbrrrr",
      "cdddecccdddecccd",
      "    f      f    ",
      "                ",
      "                ",
      "                ",
      "                ",
      "                ",
      "                ",
      "                ",
      "                ",
      "                ",
      "                ",
      "                "
    ],
    [
      "    jFIJFIJn KKK",
      "    j      nEEEE",
      "CCCCbCCCCCCbLLLL",
      "cdddecccdddecccd",
      "    f      f    ",
      "                ",
      "                ",
      "                ",
      "                ",
      "                ",
      "                ",
      "                ",
      "                ",
      "                ",
      "                ",
      "                "
    ],
    [
      "    MNOPNOPMEKKK",
      "QQRQMQRQQQQMEEEE",
      "SSSSbSSSSSSb    ",
      "cdddecccdddecccd",
      "    f      f    ",
      "                ",
      "                ",
      "                ",
      "                ",
      "                ",
      "                ",
      "                ",
      "                ",
      "                ",
      "                ",
      "                "
    ]
  ]
}