{
  "name": "multi_timbertower_5_floor11",
  "refpalette": "deceasedcraft:multi_timbertower_5/multi_timbertower_5_floor11_palette",
  "xsize": 16,
  "zsize": 16,
  "slices": [
    [
      "aaaaaaaaaaaaaaaa",
      "aaaaaaaaaaaaaaaa",
      "aaaabaaaaaabaaaa",
      "cdddecccdddecccd",
      "    f      f    ",
      "                ",
      "                ",
      "                ",
      "                ",
      "                ",
      "                ",
      "                ",
      "                ",
      "                ",
      "                ",
      "                "
    ],
    [
      "g  hijg  klimn  ",
      " op i po  qiq  o",
      "rrrrbrrrrrrbrrrr",
      "cdddecccdddecccd",
      "    f      f    ",
      "                ",
      "                ",
      "                ",
      "                ",
      "                ",
      "                ",
      "                ",
      "                ",
      "                ",
      "                ",
      "                "
    ],
    [
      "    i      i    ",
      "sst i uwwxyiABss",
      "CCCrbrCCCCrbrCCC",
      "cdddecccdddecccd",
      "    f      f    ",
      "                ",
      "                ",
      "                ",
      "                ",
      "                ",
      "                ",
      "                ",
      "                ",
      "                ",
      "                ",
      "                "
    ],
    [
      "    i      i    ",
      "DDE i FIIJ i KDD",
      "LLLrbrLLLLrbrLLL",
      "cdddecccdddecccd",
      "    f      f    ",
      "                ",
      "                ",
      "                ",
      "                ",
      "                ",
      "                ",
      "                ",
      "                ",
      "                ",
      "                ",
      "                "
    ],
    [
      "    i      i    ",
      "    i      i    ",
      "rrrrbrrrrrrbrrrr",
      "cdddecccdddecccd",
      "    f      f    ",
      "                ",
      "                ",
      "                ",
      "                ",
      "                ",
      "                ",
      "                ",
      "                ",
      "                ",
      "                ",
      "                "
    ],
    [
      "M   NO     N    ",
      "    N      N    ",
      "PPPPbPPPPPPbPPPP",
      "cdddecccdddecccd",
      "    f      f    ",
      "                ",
      "                ",
      "                ",
      "                ",
      "                ",
      "                ",
      "                ",
      "                ",
      "                ",
      "                ",
      "                "
    ]
  ]
}