{
  "name": "multi_timbertower_5_floor9",
  "refpalette": "deceasedcraft:multi_timbertower_5/multi_timbertower_5_floor9_palette",
  "xsize": 16,
  "zsize": 16,
  "slices": [
    [
      "aaaaaaaa        ",
      "aaaaaaaa   b   c",
      "aaaadaaaaaadaaaa",
      "eeeefeeeeeefeeee",
      "  g h i  g h i  ",
      "                ",
      "                ",
      "                ",
      "                ",
      "                ",
      "                ",
      "                ",
      "                ",
      "                ",
      "                ",
      "                "
    ],
    [
      " j  k  l        ",
      "       m        ",
      "lllldlllllldnnnn",
      "    f      f    ",
      "  g h i  g h i  ",
      "                ",
      "                ",
      "                ",
      "                ",
      "                ",
      "                ",
      "                ",
      "                ",
      "                ",
      "                ",
      "                "
    ],
    [
      " o  j           ",
      "       p        ",
      "lllldlllllld    ",
      "    f      f    ",
      "  g h i  g h i  ",
      "                ",
      "                ",
      "                ",
      "                ",
      "                ",
      "                ",
      "                ",
      "                ",
      "                ",
      "                ",
      "                "
    ],
    [
      "                ",
      "       q        ",
      "lllldlllllld    ",
      "   gf  ig  fi   ",
      "  g h i  g h i  ",
      "                ",
      "                ",
      "                ",
      "                ",
      "                ",
      "                ",
      "                ",
      "                ",
      "                ",
      "                ",
      "                "
    ],
    [
      "                ",
      "                ",
      "rsrsdrsrsrsdnnnn",
      "   gf  ig  fi   ",
      "  g h i  g h i  ",
      "                ",
      "                ",
      "                ",
      "                ",
      "                ",
      "                ",
      "                ",
      "                ",
      "                ",
      "                ",
      "                "
    ],
    [
      "    tuwueeeteeee",
      "    tuuueeeteeee",
      "xxxxdxxxxxxdxxxx",
      "ig gfi ig gfi ig",
      "  g h i  g h i  ",
      "                ",
      "                ",
      "                ",
      "                ",
      "                ",
      "                ",
      "                ",
      "                ",
      "                ",
      "                ",
      "                "
    ]
  ]
}