{
  "name": "multi_timbertower_5_ground",
  "refpalette": "deceasedcraft:multi_timbertower_5/multi_timbertower_5_ground_palette",
  "xsize": 16,
  "zsize": 16,
  "slices": [
    [
      "vvvvvvvvvvvvvvvv",
      "HHHHHHHHHHHHHvvv",
      "HHHHaHHHHHHaHvvv",
      "HHHHHHHHHHHHHvvv",
      "HHHHHHHHHHHHHvvv",
      "HHHHHHHHHHHHHvvv",
      "HHHHHHHHHHHHHvvv",
      "HHHHHHHHHHHHHvvv",
      "HHHHHHHHHHHHHvvv",
      "HHHHaHHHHHHaHvvv",
      "HHHHHHHHHHHHHvvv",
      "vvvvvvvvvvvvvvvv",
      "vvvvvvvvvvvvvvvv",
      "bbbbcbbbbbbcbbbb",
      "cbcccbccbbcbccbc",
      "bbbbbcbbcbbbbbcb"
    ],
    [
      "dddeeeddddeeeddd",
      "fgfg fgfgfg     ",
      "    a      aaaaa",
      "hihijhihihik lm ",
      "             lnm",
      "             lm ",
      "             lm ",
      "             lnm",
      "fgfgofgfgfgo lm ",
      "    a      aaaaa",
      "hihi hihihi  lm ",
      "llllllllllllllm ",
      "ppppqppppppqpppp",
      "rrsr rrrrrs rsrr",
      "                ",
      "                "
    ],
    [
      "             ttu",
      "             ttu",
      "    a      a ttu",
      "             ttu",
      "             ttu",
      "             ttu",
      "             ttu",
      "             ttu",
      "             ttu",
      "    a      a ttu",
      "             ttu",
      "             ttu",
      "ppppqppppppqpppp",
      "                ",
      "                ",
      "                "
    ],
    [
      "         ttauwww",
      "         ttauwww",
      "    aaaaaaaauwww",
      "         ttauwww",
      "         ttauwww",
      "         ttauwww",
      "         ttauwww",
      "         ttauwww",
      "         ttauwww",
      "    aaaaaaaauwww",
      "         ttauwww",
      "         ttauwww",
      "ppppqppppppqpppp",
      "                ",
      "                ",
      "                "
    ],
    [
      "     ttuuwwww   ",
      "     ttuuwwww   ",
      "    attuuwwaw   ",
      "     ttuuwwww   ",
      "     ttuuwwww   ",
      "     ttuuwwww   ",
      "     ttuuwwww   ",
      "     ttuuwwww   ",
      "     ttuuwwww   ",
      "    attuuwwww   ",
      "     ttuuwwww   ",
      "     ttuuwwww   ",
      "ppppqppppppqpppp",
      "                ",
      "                ",
      "                "
    ],
    [
      "ttttawwww       ",
      "ttttawwww       ",
      "aaaaawwww  xy   ",
      "ttttawwww       ",
      "ttttawwww       ",
      "ttttawwww       ",
      "ttttawwww       ",
      "ttttawwww       ",
      "ttttawwww       ",
      "aaaaawwww       ",
      "ttttawwww       ",
      "ttttawwww  A    ",
      "ppppqppppppqBB  ",
      "                ",
      "                ",
      "                "
    ]
  ]
}