{
  "name": "multi_timbertower_5_floor4",
  "refpalette": "deceasedcraft:multi_timbertower_5/multi_timbertower_5_floor4_palette",
  "xsize": 16,
  "zsize": 16,
  "slices": [
    [
      "    abbbbbbbbbbb",
      "    abbbbbbbbbbb",
      "ccccdbbbbbbdbbbb",
      "cccceccccccecccc",
      "fggghfffggghfffg",
      "    i      i    ",
      "                ",
      "                ",
      "                ",
      "                ",
      "                ",
      "                ",
      "                ",
      "                ",
      "                ",
      "                "
    ],
    [
      "    j    k l    ",
      "    j   mnolpqrq",
      "jjjjdjjjjjjdssss",
      "                ",
      "fggghfffggghfffg",
      "    i      i    ",
      "                ",
      "                ",
      "                ",
      "                ",
      "                ",
      "                ",
      "                ",
      "                ",
      "                ",
      "                "
    ],
    [
      "    j      l    ",
      "    j   tuwlxy A",
      "jjjjdjjjjjjdsBBB",
      "                ",
      "fggghfffggghfffg",
      "    i      i    ",
      "                ",
      "                ",
      "                ",
      "                ",
      "                ",
      "                ",
      "                ",
      "                ",
      "                ",
      "                "
    ],
    [
      "    j      l    ",
      "    j      lC   ",
      "jjjjdjjjjjjdsDDD",
      "                ",
      "fggghfffggghfffg",
      "    i      i    ",
      "                ",
      "                ",
      "                ",
      "                ",
      "                ",
      "                ",
      "                ",
      "                ",
      "                ",
      "                "
    ],
    [
      "    lEFEEIEJEKEE",
      "    lEEEEEEJEEEE",
      "LMLMdssssssdssss",
      "                ",
      "fggghfffggghfffg",
      "    i      i    ",
      "                ",
      "                ",
      "                ",
      "                ",
      "                ",
      "                ",
      "                ",
      "                ",
      "                ",
      "                "
    ],
    [
      "    N OPQORN O P",
      "    NP  P RN    ",
      "SSSSdSSSSSSdSSSS",
      "    T      T    ",
      "fggghfffggghfffg",
      "    i      i    ",
      "                ",
      "                ",
      "                ",
      "                ",
      "                ",
      "                ",
      "                ",
      "                ",
      "                ",
      "                "
    ]
  ]
}