{
  "name": "multi_timbertower_5_base2",
  "refpalette": "deceasedcraft:multi_timbertower_5/multi_timbertower_5_base2_palette",
  "xsize": 16,
  "zsize": 16,
  "slices": [
    [
      "HHHHHHHHHHHHHHHH",
      "HHHHHHHHHHHHHHHH",
      "HHHHaHHHHHHaHHHH",
      "HHHHHHHHHHHHHHHH",
      "HHHHHHHHHHHHHHHH",
      "HHHHHHHHHHHHHHHH",
      "HHHHHHHHHHHHHHHH",
      "HHHHHHHHHHHHHHHH",
      "HHHHHHHHHHHHHHHH",
      "HHHHaHHHHHHaHHHH",
      "HHHHHHHHHHHHHHHH",
      "vvvvvvvvvvvvvvvv",
      "vvvvvvvvvvvvvvvv",
      "bb              ",
      "bbbbbbbbbbbbbbbb",
      "vvvvvvvvvvvvvvvv"
    ],
    [
      "                ",
      "cdcd cdcdcd cdcd",
      "    a      a  e ",
      "fgfghfgfgfghfgfg",
      "                ",
      "                ",
      "                ",
      "                ",
      "cdcdicdcdcdjcdcd",
      "    a      a    ",
      "fgfg fgfgfg fgfg",
      "kkkkkkkkkkkkkkkk",
      "vvvvvvvvvvvvvvvv",
      "bbbbbbbbbbbbbbbb",
      "bbbbbbbbbbbbbbbb",
      "vvvvvvvvvvvvvvvv"
    ],
    [
      "                ",
      "                ",
      "    a      a    ",
      "                ",
      "                ",
      "                ",
      "                ",
      "                ",
      "                ",
      "    a      a    ",
      "                ",
      "                ",
      "vvvvvvvvvvvvvvvv",
      "bbbbbbbbbbbbbbbb",
      "bbbbbbbbbbbbbbbb",
      "vvvvvvvvvvvvvvvv"
    ],
    [
      "                ",
      "                ",
      "    a      a    ",
      "                ",
      "                ",
      "                ",
      "                ",
      "                ",
      "                ",
      "    a      a    ",
      "                ",
      "                ",
      "vvvvvvvvvvvvvvvv",
      "bbbbbbbbbbbbbbbb",
      "bbbbbbbbbbbbbbbb",
      "vvvvvvvvvvvvvvvv"
    ],
    [
      "                ",
      "                ",
      "    a      a    ",
      "                ",
      "                ",
      "                ",
      "                ",
      "                ",
      "                ",
      "    a      a    ",
      "                ",
      "                ",
      "vvvvvvvvvvvvvvvv",
      "bbbbbbbbbbbbbbbb",
      "bbbbbbbbbbbbbbbb",
      "vvvvvvvvvvvvvvvv"
    ],
    [
      "    a      a    ",
      "llllallllllallll",
      "aaaaaaaaaaaaaaaa",
      "llllallllllallll",
      "llllallllllallll",
      "llllallllllallll",
      "llllallllllallll",
      "llllallllllallll",
      "llllallllllallll",
      "aaaaaaaaaaaaaaaa",
      "llllllllllllllll",
      "vvvvvvvvvvvvvvvv",
      "vvvvvvvvvvvvvvvv",
      "bbbbbbbbbbbbbbbb",
      "bbbbbbbbbbbbbbbb",
      "vvvvvvvvvvvvvvvv"
    ]
  ]
}