{
  "name": "multi_timbertower_5_floor10",
  "refpalette": "deceasedcraft:multi_timbertower_5/multi_timbertower_5_floor10_palette",
  "xsize": 16,
  "zsize": 16,
  "slices": [
    [
      "    abbbbbbccccc",
      "    abbbbbbccccc",
      "ddddeccccccecccc",
      "fg ghf fg ghf fg",
      "  g i f  g i f  ",
      "                ",
      "                ",
      "                ",
      "                ",
      "                ",
      "                ",
      "                ",
      "                ",
      "                ",
      "                ",
      "                "
    ],
    [
      "    jk l k m    ",
      "    jnk   nmopqp",
      "jjjjejjjjjjerrrr",
      "fg ghf fg ghf fg",
      "    i      i    ",
      "                ",
      "                ",
      "                ",
      "                ",
      "                ",
      "                ",
      "                ",
      "                ",
      "                ",
      "                ",
      "                "
    ],
    [
      "    j      m    ",
      "    js    smtu  ",
      "jjjjejjjjjjerwww",
      "fg ghf fg ghf fg",
      "    i      i    ",
      "                ",
      "                ",
      "                ",
      "                ",
      "                ",
      "                ",
      "                ",
      "                ",
      "                ",
      "                ",
      "                "
    ],
    [
      "    j      m    ",
      "    jx    xmy   ",
      "jjjjejjjjjjerAAA",
      "fg ghf fg ghf fg",
      "    i      i    ",
      "                ",
      "                ",
      "                ",
      "                ",
      "                ",
      "                ",
      "                ",
      "                ",
      "                ",
      "                ",
      "                "
    ],
    [
      "    m      mBCBB",
      "    m      mBBBB",
      "DEDEeDEDEDEerrrr",
      "fg ghf fg ghf fg",
      "    i      i    ",
      "                ",
      "                ",
      "                ",
      "                ",
      "                ",
      "                ",
      "                ",
      "                ",
      "                ",
      "                ",
      "                "
    ],
    [
      "    FBIBBIBF J K",
      "    FBBBBBBF    ",
      "LLLLeLLLLLLeLLLL",
      "fggghfffggghfffg",
      "    i      i    ",
      "                ",
      "                ",
      "                ",
      "                ",
      "                ",
      "                ",
      "                ",
      "                ",
      "                ",
      "                ",
      "                "
    ]
  ]
}