{
  "name": "multi_timbertower_5_floor7",
  "refpalette": "deceasedcraft:multi_timbertower_5/multi_timbertower_5_floor7_palette",
  "xsize": 16,
  "zsize": 16,
  "slices": [
    [
      "aaaaa========bbb",
      "aaaaa===========",
      "ccccdccccccdcccc",
      "eeeefeeeeeefeeee",
      "ghhhiggghhhigggh",
      "                ",
      "                ",
      "                ",
      "                ",
      "                ",
      "                ",
      "                ",
      "                ",
      "                ",
      "                ",
      "                "
    ],
    [
      "   jaaaaaaakl  m",
      "  jjaaaaaaaanoof",
      "ppppdqqqqqqdqqqq",
      "    f      f    ",
      "ghhhiggghhhigggh",
      "                ",
      "                ",
      "                ",
      "                ",
      "                ",
      "                ",
      "                ",
      "                ",
      "                ",
      "                ",
      "                "
    ],
    [
      "     jaaaar s   ",
      "   jjjaaaaaatuwf",
      "    dqqqqqqdqqqq",
      "    f      f    ",
      "ghhhiggghhhigggh",
      "                ",
      "                ",
      "                ",
      "                ",
      "                ",
      "                ",
      "                ",
      "                ",
      "                ",
      "                ",
      "                "
    ],
    [
      "     j  aaaa    ",
      "    xjjjaaaawayA",
      "    dqqqqqqdqqqq",
      "    f      f    ",
      "  hhiggghhhigggh",
      "                ",
      "                ",
      "                ",
      "                ",
      "                ",
      "                ",
      "                ",
      "                ",
      "                ",
      "                ",
      "                "
    ],
    [
      "          jaaa w",
      " x xxjj B jaaaya",
      "ppppdppppppdqqqq",
      "    f      f    ",
      "  hhi gghh igggh",
      "                ",
      "                ",
      "                ",
      "                ",
      "                ",
      "                ",
      "                ",
      "                ",
      "                ",
      "                ",
      "                "
    ],
    [
      "            Baaa",
      "xxxxjj   xjjxaaa",
      "CCCCdCCCCCCdCCCC",
      "    f      f    ",
      "  h i gghh igg  ",
      "                ",
      "                ",
      "                ",
      "                ",
      "                ",
      "                ",
      "                ",
      "                ",
      "                ",
      "                ",
      "                "
    ]
  ]
}