{
  "name": "multi_timbertower_5_floor5",
  "refpalette": "deceasedcraft:multi_timbertower_5/multi_timbertower_5_floor5_palette",
  "xsize": 16,
  "zsize": 16,
  "slices": [
    [
      "    abbbbbbbbbbb",
      "    abbbbbbbbbbb",
      "ccccdbbbbbbdbbbb",
      "cccceccccccecccc",
      "fggghfffggghfffg",
      "    i      i    ",
      "                ",
      "                ",
      "                ",
      "                ",
      "                ",
      "                ",
      "                ",
      "                ",
      "                ",
      "                "
    ],
    [
      "    j    k l    ",
      "    j  mnoplqrsr",
      "jjjjdjjjjjjdtttt",
      "                ",
      "fggghfffggghfffg",
      "    i      i    ",
      "                ",
      "                ",
      "                ",
      "                ",
      "                ",
      "                ",
      "                ",
      "                ",
      "                ",
      "                "
    ],
    [
      "    j      l    ",
      "    j   uwxlyA  ",
      "jjjjdjjjjjjdtBBB",
      "                ",
      "fggghfffggghfffg",
      "    i      i    ",
      "                ",
      "                ",
      "                ",
      "                ",
      "                ",
      "                ",
      "                ",
      "                ",
      "                ",
      "                "
    ],
    [
      "    j      l    ",
      "    j      lC   ",
      "jjjjdjjjjjjdtDDD",
      "                ",
      "fggghfffggghfffg",
      "    i      i    ",
      "                ",
      "                ",
      "                ",
      "                ",
      "                ",
      "                ",
      "                ",
      "                ",
      "                ",
      "                "
    ],
    [
      "    lEFEEFEIEJEE",
      "    lEEEEEEIEEEE",
      "KLKLdttttttdtttt",
      "                ",
      "fggghfffggghfffg",
      "    i      i    ",
      "                ",
      "                ",
      "                ",
      "                ",
      "                ",
      "                ",
      "                ",
      "                ",
      "                ",
      "                "
    ],
    [
      "    M NN OPM O N",
      "    MN  N PM    ",
      "QQQQdQQQQQQdQQQQ",
      "    R      R    ",
      "fggghfffggghfffg",
      "    i      i    ",
      "                ",
      "                ",
      "                ",
      "                ",
      "                ",
      "                ",
      "                ",
      "                ",
      "                ",
      "                "
    ]
  ]
}