{
  "name": "multi_timbertower_5_floor3",
  "refpalette": "deceasedcraft:multi_timbertower_5/multi_timbertower_5_floor3_palette",
  "xsize": 16,
  "zsize": 16,
  "slices": [
    [
      "aaaabbbbbbbbbbbb",
      "aaaabbbbbbbbbbbb",
      "bbbbcbbbbbbcbbbb",
      "ddddeddddddedddd",
      "fggghfffggghfffg",
      "    i      i    ",
      "                ",
      "                ",
      "                ",
      "                ",
      "                ",
      "                ",
      "                ",
      "                ",
      "                ",
      "                "
    ],
    [
      "j j klm  n o   p",
      " j  kqr stuowxyx",
      "AAAAcAAAAAAcBBBB",
      "                ",
      "fggghfffggghfffg",
      "    i      i    ",
      "                ",
      "                ",
      "                ",
      "                ",
      "                ",
      "                ",
      "                ",
      "                ",
      "                ",
      "                "
    ],
    [
      "    CD     o    ",
      "    CE  FIJoKL M",
      "AAAAcAAAAAAcBNNN",
      "                ",
      "fggghfffggghfffg",
      "    i      i    ",
      "                ",
      "                ",
      "                ",
      "                ",
      "                ",
      "                ",
      "                ",
      "                ",
      "                ",
      "                "
    ],
    [
      "    O      o    ",
      "    O      oP   ",
      "AAAAcAAAAAAcBQQQ",
      "                ",
      "fggghfffggghfffg",
      "    i      i    ",
      "                ",
      "                ",
      "                ",
      "                ",
      "                ",
      "                ",
      "                ",
      "                ",
      "                ",
      "                "
    ],
    [
      "           RSTSS",
      "           RSSSS",
      "UVUVcUVUVUVcBBBB",
      "                ",
      "fggghfffggghfffg",
      "    i      i    ",
      "                ",
      "                ",
      "                ",
      "                ",
      "                ",
      "                ",
      "                ",
      "                ",
      "                ",
      "                "
    ],
    [
      "    WSTSSXSW Y Z",
      "    WSSSSSSW    ",
      "0000c000000c0000",
      "    1      1    ",
      "fggghfffggghfffg",
      "    i      i    ",
      "                ",
      "                ",
      "                ",
      "                ",
      "                ",
      "                ",
      "                ",
      "                ",
      "                ",
      "                "
    ]
  ]
}