{
  "name": "multi_thering_6_floor15",
  "refpalette": "deceasedcraft:multi_thering_6/multi_thering_6_floor15_palette",
  "xsize": 16,
  "zsize": 16,
  "slices": [
    [
      "a              b",
      "                ",
      "                ",
      "                ",
      "                ",
      "                ",
      "                ",
      "                ",
      "        caaa    ",
      "        cdda    ",
      "        ceda    ",
      "        c faaaaa",
      "        c  a   g",
      "        c  a   g",
      "        c  a   g",
      "b       agggggga"
    ],
    [
      "a              b",
      "                ",
      "                ",
      "                ",
      "                ",
      "                ",
      "                ",
      "                ",
      "        caaa    ",
      "        c  a    ",
      "        c  a    ",
      "        c haaaaa",
      "        c fa   g",
      "        c  a   g",
      "        c  a   g",
      "b       agggggga"
    ],
    [
      "a              b",
      "                ",
      "                ",
      "                ",
      "                ",
      "                ",
      "                ",
      "                ",
      "        caaa    ",
      "        c  a    ",
      "        c  a    ",
      "        c  aaaaa",
      "        c ha   g",
      "        cifa   g",
      "        c  a   g",
      "b       agggggga"
    ],
    [
      "a              b",
      "                ",
      "                ",
      "                ",
      "                ",
      "                ",
      "                ",
      "                ",
      "        caaa    ",
      "        c  a    ",
      "        c  a    ",
      "        c  aaaaa",
      "        cj a   g",
      "        cdha   g",
      "        cffa   g",
      "b       agggggga"
    ],
    [
      "a              b",
      "                ",
      "                ",
      "                ",
      "                ",
      "                ",
      "                ",
      "                ",
      "        caaa    ",
      "        c  a    ",
      "        c  a    ",
      "        cj aaaaa",
      "        ce a   g",
      "        c  a   g",
      "        c  a   g",
      "b       agggggga"
    ],
    [
      "a              b",
      "                ",
      "                ",
      "                ",
      "                ",
      "                ",
      "                ",
      "                ",
      "        caaa    ",
      "        c  a    ",
      "        cjia    ",
      "        ce aaaaa",
      "        c  a   g",
      "        c  a   g",
      "        c  a   g",
      "b       agggggga"
    ]
  ]
}