{
  "name": "multi_thering_6_floor16",
  "refpalette": "deceasedcraft:multi_thering_6/multi_thering_6_floor16_palette",
  "xsize": 16,
  "zsize": 16,
  "slices": [
    [
      "abbbbbbbbbbbbbbc",
      "bddddddddddddddd",
      "bddddddddddddddd",
      "bddddddddddddddd",
      "bddddddddddddddd",
      "bddddddddddddddd",
      "bddddddddddddddd",
      "bddddddddddddddd",
      "bdddddddeaaabbbb",
      "bdddddddeffa    ",
      "bdddddddegfa    ",
      "bddddddde haaaaa",
      "bddddddde  a   i",
      "bddddddde  a   i",
      "bddddddde  a   i",
      "cbbbbbbbaiiiiiia"
    ],
    [
      "ajjjjjjjjjjjjjjc",
      "j              a",
      "j kkkkkkkkkkkkka",
      "j k            a",
      "j k lmlnooooop a",
      "j k mlm        a",
      "j k lmloooooqrsa",
      "j k          tua",
      "j k    waxaayyya",
      "j k    Aa  aBBBB",
      "j k    Aa  a    ",
      "j k    Aa Caaaaa",
      "j k    Da ha   i",
      "j kkkkkka  a   i",
      "j       a  a   i",
      "cjjjjjjjaiiiiiia"
    ],
    [
      "ajjjjjjjjjjjjjjc",
      "j              a",
      "j kkkkkkkkkkkkka",
      "j k           Ea",
      "j k FIF      JKL",
      "j k IFI        a",
      "j k FIF     MNOa",
      "j k          PQa",
      "j k    waRaaddda",
      "j k    Sa Tabbb ",
      "j k    !a  abbb ",
      "j k    Ua  aaaaa",
      "j k     a Ca   i",
      "j kkkkkkaVha   i",
      "j       a  a   i",
      "cjjjjjjjaiiiiiia"
    ],
    [
      "ajjjjjjjjjjjjjjc",
      "jVVVVVVVVVVVVVVf",
      "jVWWWWWWWWWWWWWW",
      "jVWWWWWWWWWWWWWW",
      "jVWWWWWWWWWWWWWW",
      "jVWWWWWWWWWWWWWW",
      "jVWWWWWWXXXXWWWW",
      "jVWWWWWWXXXXWWWW",
      "jVWWWWWWaaaafffa",
      "jVWWWWWWf  afffa",
      "jVWWWWWWf  afffa",
      "jVWWWWWWf  aYYZa",
      "jVWWWWWWf0 a   i",
      "jVWWWWWWffCa   i",
      "jVVVVVVVfhha   i",
      "cjjjjjjjaiiiiiia"
    ],
    [
      "ajjjjjjjjjjjjjjc",
      "j111111111111111",
      "j1 2            ",
      "j134            ",
      "j1              ",
      "j1 2            ",
      "j134            ",
      "j1       5 6    ",
      "j1 2    aaaa   a",
      "j134    7  a   i",
      "j1      7  a89#i",
      "j1$2    70 a%%aa",
      "j134    7g a   i",
      "j1         a   i",
      "j11111117  a   i",
      "cjjjjjjjaiiiiiia"
    ],
    [
      "ajjjjjjjjjjjjjjc",
      "j               ",
      "j  ^            ",
      "j               ",
      "j               ",
      "j  &            ",
      "j               ",
      "j       * *    (",
      "j  )    aaaa  +a",
      "j       -  a   i",
      "j       -0Va[] i",
      "j       -g a  aa",
      "j       -  a   i",
      "j          a   i",
      "j       -  a   i",
      "cjjjjjjjaiiiiiia"
    ]
  ]
}