{
  "name": "multi_thering_6_base1",
  "refpalette": "deceasedcraft:multi_thering_6/multi_thering_6_base1_palette",
  "xsize": 16,
  "zsize": 16,
  "slices": [
    [
      "a bccdcdddeeef g",
      "a              h",
      "a              h",
      "a              h",
      "a              i",
      "a               ",
      "a               ",
      "a               ",
      "a              i",
      "a              h",
      "aj          kl h",
      "a       m  annah",
      "aooop   m  a   h",
      "aqqqp   m ra   h",
      "astup   mwxa   h",
      "ghhhi   ihhhhhha"
    ],
    [
      "a              g",
      "a              h",
      "a              h",
      "a              h",
      "a              i",
      "a               ",
      "a               ",
      "a               ",
      "a              i",
      "a              h",
      "a              h",
      "a       m  aaaah",
      "aooop   m  a   h",
      "aqqqp   my a   h",
      "aAAAp   mxra   h",
      "ghhhi   ihhhhhha"
    ],
    [
      "a              g",
      "a              h",
      "a              h",
      "a              h",
      "a              i",
      "a               ",
      "a               ",
      "a               ",
      "a              i",
      "a              h",
      "a              h",
      "a       m  aaaah",
      "aooop   my a   h",
      "aqqqp   mB a   h",
      "a   p   m  a   h",
      "ghhhi   ihhhhhha"
    ],
    [
      "a              g",
      "a              h",
      "a              h",
      "a              h",
      "a              i",
      "a               ",
      "a               ",
      "a               ",
      "a              i",
      "a              h",
      "a              h",
      "a       my aaaah",
      "aooop   mB a   h",
      "aqqqp   m  a   h",
      "aCDEp   m  a   h",
      "ghhhi   ihhhhhha"
    ],
    [
      "a              g",
      "a              h",
      "a              h",
      "a              h",
      "a              i",
      "a               ",
      "a               ",
      "a               ",
      "a              i",
      "a              h",
      "a        y     h",
      "a       mB aaaah",
      "aoooF   m  a   h",
      "aqqqF   m  a   h",
      "aAAAF   m  a   h",
      "ghhhi   ihhhhhha"
    ],
    [
      "aIIIIIIIIIIIIIIg",
      "axxxxxxxxxxxxxxh",
      "axxxxxxxxxxxxxxh",
      "axxxxxxxxxxxxxxh",
      "axxxxxxIIIIIIIIi",
      "axxxxxIiiiiiiiii",
      "axxxxIiiJJJJJJJJ",
      "axxxIiiJiiiiiiii",
      "axxxIiJiiIIIIIIi",
      "axxxIiJiIxxxxxxh",
      "axxxIiJiIBKKKKKh",
      "axxxIiJiL  aaaah",
      "axxxIiJiL  a   h",
      "axxxIiJiL  a   h",
      "axxxIiJiL  a   h",
      "ghhhiiJiihhhhhha"
    ]
  ]
}