{
  "name": "multi_thering_6_floor7",
  "refpalette": "deceasedcraft:multi_thering_6/multi_thering_6_floor7_palette",
  "xsize": 16,
  "zsize": 16,
  "slices": [
    [
      "aabbc          d",
      "abbc c          ",
      "bb c         eff",
      "b g         ehii",
      "          efhiii",
      "c        ehiiiii",
      "        ehiiiiii",
      "       jkiiiiiii",
      "     cbbbliliiil",
      "     bb lmmliiil",
      "   cbb  lnmliiil",
      "   cb   l olppql",
      " cgbb   l  l   l",
      " cbb    l  l   l",
      "c b     l  l   l",
      "d b     lrrrrrrl"
    ],
    [
      "ss  t          d",
      "s  t t          ",
      "   t            ",
      "  u             ",
      "                ",
      "t               ",
      "                ",
      "                ",
      "     twwxl l   x",
      "     ww l yl   w",
      "   tww  l  lABCw",
      "   tw   l DlEEll",
      " tuxw   l ol   r",
      " tww    l  l   r",
      "t w     l  l   r",
      "d w     lrrrrrrl"
    ],
    [
      "    F          d",
      "   F F          ",
      "   F            ",
      "  t             ",
      "                ",
      "F               ",
      "                ",
      "                ",
      "     F   l l    ",
      "        l Il    ",
      "   F    l  lJK  ",
      "   F    l  l  ll",
      " Ft     l Dl   r",
      " F      lLol   r",
      "F       l  l   r",
      "d       lrrrrrrl"
    ],
    [
      "    F          d",
      "   F F          ",
      "   F            ",
      "  F             ",
      "                ",
      "F               ",
      "                ",
      "                ",
      "     F   lMl    ",
      "        l Nl    ",
      "   F    l  lOO  ",
      "   F    l  lPPll",
      " FF     lQ l   r",
      " F      lmDl   r",
      "F       lool   r",
      "d       lrrrrrrl"
    ],
    [
      "    R          d",
      "   F R          ",
      "   R            ",
      "  F             ",
      "                ",
      "R               ",
      "                ",
      "                ",
      "     R   lll    ",
      "        l  l    ",
      "   F    l  l    ",
      "   R    lQ lllll",
      " RF     ln l   r",
      " F      l  l   r",
      "R       l  l   r",
      "d       lrrrrrrl"
    ],
    [
      "               d",
      "   R            ",
      "                ",
      "  R             ",
      "                ",
      "                ",
      "                ",
      "                ",
      "         lll    ",
      "        l  l    ",
      "   R    lQLl    ",
      "        ln lllll",
      "  R     l  l   r",
      " R      l  l   r",
      "        l  l   r",
      "d       lrrrrrrl"
    ]
  ]
}