{
  "name": "multi_thering_6_floor12",
  "refpalette": "deceasedcraft:multi_thering_6/multi_thering_6_floor12_palette",
  "xsize": 16,
  "zsize": 16,
  "slices": [
    [
      "aaaaaaaaaaaaaaab",
      "accccccccccccdda",
      "accccccccccccdda",
      "accccccccccccdda",
      "acccccccc!cccdda",
      "aaaaaaacaaaaaaaa",
      "accccaeeeeeeeeea",
      "accccaefeeeeeeea",
      "accccaeeeaaaeeea",
      "accccaacaggeeeea",
      "acccccccahgaeeea",
      "accccccca iaeeja",
      "acccccdda  a   a",
      "accccddda  a   a",
      "accccddda  a   a",
      "baaaaaaaaaaaaaaa"
    ],
    [
      "akkkkkkkkkkkkkkb",
      "klm         nopk",
      "k   qrs tu  wx k",
      "k yyABCw DE FI k",
      "kJKKJrL tDMMNO k",
      "kaaaaaaPaaaaaaak",
      "kQRRQa        Sk",
      "k TT a        Sk",
      "k   ma   aaa   k",
      "k rr!aaUa V    k",
      "k WWW   a  aXYZk",
      "k 0t  12a 3a44ak",
      "kA56789#a ia   k",
      "k   F$ %a  a   k",
      "kMMMN^& a  a   k",
      "bkkkkkkkkkkkkkka"
    ],
    [
      "akkkkkkkkkkkkkkb",
      "k *         n  k",
      "k    ()      +-k",
      "k    ()       -k",
      "k[  [(    ] { }k",
      "kaaaaaa|aaaaaaak",
      "k;  ;a         k",
      "k    a:        k",
      "k   'a   aaa   k",
      "k (((aa<a >    k",
      "k    ,, a  a.? k",
      "k     /2a  a  ak",
      "k ww`29 a 3a   k",
      "k       a\u0370ia   k",
      "k  \u0371\u0372  \u0373a  a   k",
      "bkkkkkkkkkkkkkka"
    ],
    [
      "akkkkkkkkkkkkkkb",
      "k           n  k",
      "k    (\u0374     n  k",
      "k    (\u0375     \u0376  k",
      "k    (\u0377     \u037a \u037bk",
      "kaaaaaagaaaaaaak",
      "k    a         k",
      "k    a\u037c        k",
      "k    a   aaa   k",
      "k (((aaga \u037d\u037e   k",
      "k \u037f\u0384\u0385   a  a\u0386\u0386 k",
      "k     22a  a\u0387\u0387ak",
      "k    29 a\u0388 a   k",
      "k   \u0376   ag3a   k",
      "k   \u037a  \u0389aiia   k",
      "bkkkkkkkkkkkkkka"
    ],
    [
      "akkkkkkkkkkkkkkb",
      "k           \u038a  k",
      "k           \u038a  k",
      "k           \u038a  k",
      "k    \u038c      \u038a  k",
      "kaaaaaaaaaaaaaak",
      "k    a         k",
      "k    a         k",
      "k    a   aaa   k",
      "k \u038e\u038e aaaa  a   k",
      "k       a  a   k",
      "k     \u038f\u038fa\u0388 aaaak",
      "k    \u038f\u0390 ah a   k",
      "k    \u0390  a  a   k",
      "k    \u0390  a  a   k",
      "bkkkkkkkkkkkkkka"
    ],
    [
      "akkkkkkkkkkkkkkb",
      "k\u0391\u0391\u0391\u0391\u0391\u0391\u0391\u0391\u0391\u0391\u0391\u0391\u0392\u0392k",
      "k\u0391\u0391\u0391\u0391\u0391\u0391\u0391\u0391\u0391\u0391\u0391\u0391\u0392\u0392k",
      "k\u0391\u0391\u0391\u0391\u0391\u0391\u0391\u0391\u0391\u0391\u0391\u0391\u0392\u0392k",
      "k\u0391\u0391\u0391\u0391\u0391\u0391\u0391\u0391\u0391\u0391\u0391\u0391\u0392\u0392k",
      "kaaaaaaaaaaaaaak",
      "k\u0391\u0391\u0391\u0391a\u0393\u0393\u0393\u0393\u0393\u0393\u0393\u0393\u0393k",
      "k\u0391\u0391\u0391\u0391a\u0393\u0394\u0393\u0393\u0393\u0393\u0393\u0393\u0393k",
      "k\u0391\u0391\u0391\u0391a\u0393\u0393\u0393aaa\u0393\u0393\u0393k",
      "k\u0391\u0391\u0391\u0391aaaa  a\u0393\u0393\u0393k",
      "k\u0391\u0391\u0391\u0391\u0391\u0391\u0391a\u0388\u0370a\u0393\u0393\u0393k",
      "k\u0391\u0391\u0391\u0391\u0391\u0391\u0391ah aaaak",
      "k\u0391\u0391\u0391\u0391\u0392\u0392\u0392a  a   k",
      "k\u0391\u0391\u0391\u0391\u0392\u0392\u0392a  a   k",
      "k\u0391\u0391\u0391\u0391\u0392\u0392\u0392a  a   k",
      "bkkkkkkkkkkkkkka"
    ]
  ]
}