{
  "name": "multi_thering_6_floor13",
  "refpalette": "deceasedcraft:multi_thering_6/multi_thering_6_floor13_palette",
  "xsize": 16,
  "zsize": 16,
  "slices": [
    [
      "aaaaaaaaaaaaaaab",
      "accccccccccccdda",
      "accccccccccccdda",
      "accccccccccccdda",
      "accccccccccccdda",
      "aaaaaaacaaaaaaaa",
      "accccaeeeeeeeeea",
      "accccaefeeeeeeea",
      "accccaeeeaaaeeea",
      "accccaacaggeeeea",
      "acccccccahgaeeea",
      "accccccca iaeeja",
      "acccccdda  a   a",
      "accccddda  a   a",
      "accccddda  a   a",
      "baaaaaaaaaaaaaaa"
    ],
    [
      "akkkkkkkkkkkkkkb",
      "klm         nopk",
      "k   qrs  t   u k",
      "k wwx!y AB  CD k",
      "kEFFErI ABJJKL k",
      "kaaaaaaMaaaaaaak",
      "kNOONa        Pk",
      "k QQ a        Pk",
      "k   ma   aaa  !k",
      "k rrRaaSa T    k",
      "k UUU   a  aVWXk",
      "k YA  Z0a 1a22ak",
      "kx345678a ia   k",
      "k   C9 #a  a   k",
      "kJJJK$  a  a   k",
      "bkkkkkkkkkkkkkka"
    ],
    [
      "akkkkkkkkkkkkkkb",
      "k %         n  k",
      "k    ^&      *(k",
      "k    ^)  +    (k",
      "k-  -^   []{} |k",
      "kaaaaaa;aaaaaaak",
      "k:  :a         k",
      "k    a'        k",
      "k   <a   aaa   k",
      "k ^^^aa>a ,    k",
      "k    .. a  a?/ k",
      "k     `0a  a  ak",
      "k {\u0370\u037107 a 1a   k",
      "k       a\u0372ia   k",
      "k \u0373 {  \u0374a  a   k",
      "bkkkkkkkkkkkkkka"
    ],
    [
      "akkkkkkkkkkkkkkb",
      "k           n  k",
      "k    ^\u0375     n  k",
      "k    ^\u0376     \u0377  k",
      "k    ^\u037a     \u037b \u037ck",
      "kaaaaaagaaaaaaak",
      "k    a         k",
      "k    a\u037d        k",
      "k    a   aaa   k",
      "k ^^^aaga \u037e\u037f   k",
      "k \u0384\u0385\u0386   a  a\u0387\u0387 k",
      "k     00a  a\u0388\u0388ak",
      "k    07 a\u0389 a   k",
      "k   \u0377   ag1a   k",
      "k   \u037b  \u038aaiia   k",
      "bkkkkkkkkkkkkkka"
    ],
    [
      "akkkkkkkkkkkkkkb",
      "k           \u038c  k",
      "k           \u038c  k",
      "k           \u038c  k",
      "k           \u038c  k",
      "kaaaaaaaaaaaaaak",
      "k    a         k",
      "k    a         k",
      "k    a   aaa   k",
      "k   \u038eaaaa  a   k",
      "k  \u038f\u038f   a  a   k",
      "k     \u0390\u0390a\u0389 aaaak",
      "k    \u0390\u0391 ah a   k",
      "k    \u0391  a  a   k",
      "k    \u0391  a  a   k",
      "bkkkkkkkkkkkkkka"
    ],
    [
      "akkkkkkkkkkkkkkb",
      "k\u0392\u0392\u0392\u0392\u0392\u0392\u0392\u0392\u0392\u0392\u0392\u0392\u0393\u0393k",
      "k\u0392\u0392\u0392\u0392\u0392\u0392\u0392\u0392\u0392\u0392\u0392\u0392\u0393\u0393k",
      "k\u0392\u0392\u0392\u0392\u0392\u0392\u0392\u0392\u0392\u0392\u0392\u0392\u0393\u0393k",
      "k\u0392\u0392\u0392\u0392\u0392\u0392\u0392\u0392\u0392\u0392\u0392\u0392\u0393\u0393k",
      "kaaaaaaaaaaaaaak",
      "k\u0392\u0392\u0392\u0392a\u0394\u0394\u0394\u0394\u0394\u0394\u0394\u0394\u0394k",
      "k\u0392\u0392\u0392\u0392a\u0394\u0395\u0394\u0394\u0394\u0394\u0394\u0394\u0394k",
      "k\u0392\u0392\u0392\u0392a\u0394\u0394\u0394aaa\u0394\u0394\u0394k",
      "k\u0392\u0392\u0392\u0392aaaa  a\u0394\u0394\u0394k",
      "k\u0392\u0392\u0392\u0392\u0392\u0392\u0392a\u0389\u0372a\u0394\u0394\u0394k",
      "k\u0392\u0392\u0392\u0392\u0392\u0392\u0392ah aaaak",
      "k\u0392\u0392\u0392\u0392\u0393\u0393\u0393a  a   k",
      "k\u0392\u0392\u0392\u0392\u0393\u0393\u0393a  a   k",
      "k\u0392\u0392\u0392\u0392\u0393\u0393\u0393a  a   k",
      "bkkkkkkkkkkkkkka"
    ]
  ]
}