{
  "name": "multi_thering_6_floor4",
  "refpalette": "deceasedcraft:multi_thering_6/multi_thering_6_floor4_palette",
  "xsize": 16,
  "zsize": 16,
  "slices": [
    [
      "aaaaaaaaaaaaaaab",
      "accccaccccccccca",
      "accccaccccccccca",
      "accccacccdddccca",
      "accdddaccdddccca",
      "accdddacaaaaaaaa",
      "accccaeeeeeeeeea",
      "acccccefeeeeeeea",
      "acc!caeeeaaaeeea",
      "aaaaaaacaggeeeea",
      "acccddccahgaeeea",
      "acccddcca iaeeja",
      "acccddcca  a   a",
      "accccccca  a   a",
      "accccccca  a   a",
      "baaaaaaaaaaaaaaa"
    ],
    [
      "akkkkkkkkkkkkkkb",
      "kl  man       lk",
      "k  opaq  r r   k",
      "k  rras t uwxy k",
      "k  A Ba CD ExFIk",
      "k J KLaMaaaaaaak",
      "k  NOa        Pk",
      "k Q  R        Pk",
      "kSTUVa   aaa   k",
      "kaaaaaaWa X    k",
      "kYZJ 0n a  a123k",
      "k45J 6q a 7a88ak",
      "k  9#Bs a ia   k",
      "k  $mtS4a  a   k",
      "k%^opC! a  a   k",
      "bkkkkkkkkkkkkkka"
    ],
    [
      "akkkkkkkkkkkkkkb",
      "k&  *a        (k",
      "k    a   r r   k",
      "k  rra  )+- x  k",
      "k  [] a { } x !k",
      "k J}  a|aaaaaaak",
      "k  ; a         k",
      "k    :         k",
      "kS  'a   aaa   k",
      "kaaaaaa<a >    k",
      "k  J, . a  a?/ k",
      "k  J+   a  a  ak",
      "k   ` ^ a 7a   k",
      "k   l)S a\u0370ia   k",
      "k    \u0371  a  a   k",
      "bkkkkkkkkkkkkkka"
    ],
    [
      "akkkkkkkkkkkkkkb",
      "k    a\u0372        k",
      "k    a\u0373  rrr   k",
      "k  rra\u0374 \u0375   x  k",
      "k J   a \u0376 \u0377 x  k",
      "k J\u0377  agaaaaaaak",
      "k  \u037a\u037ba         k",
      "k    g    \u037c    k",
      "kS\u037d\u037e\u037fa   aaa   k",
      "kaaaaaaga \u0384\u0385   k",
      "k  J\u0386 \u0387 a  a\u0388\u0389 k",
      "k  J  \u038a a  a\u038c\u038cak",
      "k  J  \u038e a\u038f a   k",
      "k   \u037a\u037bS ag7a   k",
      "k       aiia   k",
      "bkkkkkkkkkkkkkka"
    ],
    [
      "akkkkkkkkkkkkkkb",
      "k    a.        k",
      "k    a   \u0390\u0390\u0390   k",
      "k  \u0390\u0390a. \u0391\u0392\u0392\u0392\u0393  k",
      "k \u0391\u0392\u0392\u0392a \u0391\u0392\u0392\u0392\u0393  k",
      "k \u0391\u0392\u0392\u0392aaaaaaaaak",
      "k  \u0394\u0394a         k",
      "k    a         k",
      "k    a   aaa   k",
      "kaaaaaaaa  a   k",
      "k  \u0391\u0392\u0392\u0393 a  a   k",
      "k  \u0391\u0392\u0392\u0393 a\u038f aaaak",
      "k  \u0391\u0392\u0392\u0393 ah a   k",
      "k   \u0394\u0394  a  a   k",
      "k       a  a   k",
      "bkkkkkkkkkkkkkka"
    ],
    [
      "akkkkkkkkkkkkkkb",
      "k\u0395\u0395\u0395\u0395a\u0395\u0395\u0395\u0395\u0395\u0395\u0395\u0395\u0395k",
      "k\u0395\u0392\u0392\u0392a\u0392\u0392\u0392\u0392\u0392\u0392\u0392\u0392\u0395k",
      "k\u0395\u0392\u0392\u0392a\u0392\u0392\u0392   \u0392\u0392\u0395k",
      "k\u0395\u0392  \u0396a\u0392\u0392\u0396\u0396 \u0392\u0392\u0395k",
      "k\u0395\u0392  \u0396aaaaaaaaak",
      "k\u0395\u0392\u0392\u0392a\u0397\u0397\u0397\u0397\u0397\u0397\u0397\u0397\u0397k",
      "k\u0395\u0392\u0392\u0392a\u0397\u0398\u0397\u0397\u0397\u0397\u0397\u0397\u0397k",
      "k\u0395\u0392\u0392\u0392a\u0397\u0397\u0397aaa\u0397\u0397\u0397k",
      "kaaaaaaaa  a\u0397\u0397\u0397k",
      "k\u0395\u0392\u0392\u0396\u0396\u0392\u0392a\u038f\u0370a\u0397\u0397\u0397k",
      "k\u0395\u0392\u0392  \u0392\u0392ah aaaak",
      "k\u0395\u0392\u0392  \u0392\u0392a  a   k",
      "k\u0395\u0392\u0392\u0392\u0392\u0392\u0392a  a   k",
      "k\u0395\u0395\u0395\u0395\u0395\u0395\u0395a  a   k",
      "bkkkkkkkkkkkkkka"
    ]
  ]
}