{
  "name": "multi_thering_6_floor5",
  "refpalette": "deceasedcraft:multi_thering_6/multi_thering_6_floor5_palette",
  "xsize": 16,
  "zsize": 16,
  "slices": [
    [
      "aaaaaaaaaaaaaaab",
      "acccccccccccccca",
      "acccccccccccccca",
      "acccccccccccccca",
      "acccccccccccccca",
      "acccccccccccccca",
      "acccccccccccccca",
      "acccccccccccccca",
      "acccccccccccccca",
      "accc!cccaddaccca",
      "acccccccaedaccca",
      "accccccca faggha",
      "accccccca  a   a",
      "accccccca  a   a",
      "accccccca  a   a",
      "baaaaaaaaaaaaaaa"
    ],
    [
      "aiiiiiiiiiiiiiib",
      "i              i",
      "i   j      k   i",
      "i llm      n  oi",
      "i          p  oi",
      "i   q  r   n   i",
      "i llm  r   p   i",
      "i          n  oi",
      "i   s  r   p  oi",
      "i llm  tauwa   i",
      "i      xa  ayABi",
      "i   C  xa DaEEai",
      "i llm  xa fa   i",
      "i      xa  a   i",
      "i      Fa  a   i",
      "biiiiiiiiiiiiiia"
    ],
    [
      "aiiiiiiiiiiiiiib",
      "i              i",
      "i      r       i",
      "i          I   i",
      "i      r   J   i",
      "i      r       i",
      "i      r   J   i",
      "i      r   K   i",
      "i      r   L   i",
      "i      MaNOa   i",
      "i      Ja  aPQ i",
      "i      La  a  ai",
      "i      Ra Da   i",
      "i      SaTfa   i",
      "i      Ua  a   i",
      "biiiiiiiiiiiiiia"
    ],
    [
      "aiiiiiiiiiiiiiib",
      "i              i",
      "i      r       i",
      "i      r       i",
      "i      r       i",
      "i      r       i",
      "i      r       i",
      "i      r       i",
      "i      r       i",
      "i       aVWa   i",
      "i       a  aXX i",
      "i       a  aYYai",
      "i       aZ a   i",
      "i       adDa   i",
      "i       affa   i",
      "biiiiiiiiiiiiiia"
    ],
    [
      "aiiiiiiiiiiiiiib",
      "i              i",
      "i      0       i",
      "i      0       i",
      "i      0       i",
      "i      0       i",
      "i      0       i",
      "i      0       i",
      "i      0       i",
      "i       a12a   i",
      "i       a  a   i",
      "i       aZ aaaai",
      "i       ae a   i",
      "i       a  a   i",
      "i       a  a   i",
      "biiiiiiiiiiiiiia"
    ],
    [
      "aiiiiiiiiiiiiiib",
      "i33333333333333i",
      "i34444443333333i",
      "i34444443333333i",
      "i34444443333333i",
      "i34444443333333i",
      "i34444443333333i",
      "i34444443333333i",
      "i34444443333333i",
      "i3444444a56a333i",
      "i3444444aZTa333i",
      "i3444444ae aaaai",
      "i3444444a  a   i",
      "i3444444a  a   i",
      "i3333333a  a   i",
      "biiiiiiiiiiiiiia"
    ]
  ]
}