{
  "name": "multi_thering_6_floor8",
  "refpalette": "deceasedcraft:multi_thering_6/multi_thering_6_floor8_palette",
  "xsize": 16,
  "zsize": 16,
  "slices": [
    [
      "               a",
      "                ",
      "                ",
      "                ",
      "                ",
      "                ",
      "                ",
      "                ",
      "         bbb    ",
      "        bccb    ",
      "        bdcb    ",
      "        b ebbbbb",
      "        b  b   f",
      "        b  b   f",
      "        b  b   f",
      "a       bffffffb"
    ],
    [
      "               a",
      "                ",
      "                ",
      "                ",
      "                ",
      "                ",
      "                ",
      "                ",
      "         bbb    ",
      "        b  b    ",
      "        b  b    ",
      "        b gbbbbb",
      "        b eb   f",
      "        b  b   f",
      "        b  b   f",
      "a       bffffffb"
    ],
    [
      "               a",
      "                ",
      "                ",
      "                ",
      "                ",
      "                ",
      "                ",
      "                ",
      "         bbb    ",
      "        b  b    ",
      "        b  b    ",
      "        b  bbbbb",
      "        b gb   f",
      "        bheb   f",
      "        b  b   f",
      "a       bffffffb"
    ],
    [
      "               a",
      "                ",
      "                ",
      "                ",
      "                ",
      "                ",
      "                ",
      "                ",
      "         bbb    ",
      "        b  b    ",
      "        b  b    ",
      "        b  bbbbb",
      "        bi b   f",
      "        bcgb   f",
      "        beeb   f",
      "a       bffffffb"
    ],
    [
      "               a",
      "                ",
      "                ",
      "                ",
      "                ",
      "                ",
      "                ",
      "                ",
      "         bbb    ",
      "        b  b    ",
      "        b  b    ",
      "        bi bbbbb",
      "        bd b   f",
      "        b  b   f",
      "        b  b   f",
      "a       bffffffb"
    ],
    [
      "               a",
      " jjjjjjjjjjjjjj ",
      " jkkkkkkkkkkkkj ",
      " jkkkkkkkkkkkkj ",
      " jkkkkkkkkkkkkj ",
      " jkkkkkkkkkkkkj ",
      " jkkkkkkkkkkkkj ",
      " jkkkkkkkkkkkkjj",
      " jkkkkkkkbbbkkkk",
      " jkkkkkkb  bkkkk",
      " jkkkkkkbihbkkkk",
      " jkkkkkkbd bbbbb",
      " jkkkkkkb  b   f",
      " jkkkkkkb  b   f",
      " jjjjjjjb  b   f",
      "a       bffffffb"
    ]
  ]
}