{
  "name": "multi_thering_6_floor18",
  "refpalette": "deceasedcraft:multi_thering_6/multi_thering_6_floor18_palette",
  "xsize": 16,
  "zsize": 16,
  "slices": [
    [
      "aaaaaaaaaaaaaaab",
      "acccccccccccccca",
      "acccccccccccccca",
      "acccccccccccccca",
      "acccccccccccccca",
      "acccccccccccccca",
      "acccccccccccccca",
      "acccccccccccccca",
      "aaaaaacacaaaddda",
      "acccccccaeedddda",
      "acccccccafeaddda",
      "accccggga haddia",
      "accccggga  a   a",
      "accccggga  a   a",
      "accccggga  a   a",
      "baaaaaaaaaaaaaaa"
    ],
    [
      "ajjjjjjjjjjjjjjb",
      "jk    lm    nopj",
      "jk  q  r   ssstj",
      "ju  u  www xssyj",
      "jA  uB CDE Fssyj",
      "ju  uI JJJ Kssyj",
      "jL  uI     sssMj",
      "jN  u         pj",
      "jOPOQaRapaaaSTaj",
      "j      Ua V    j",
      "j W   XUa  aYZ0j",
      "j1  23 3a 4a55aj",
      "j6  27 8a ha   j",
      "j 992# $a  a   j",
      "j%^^%&  a  a   j",
      "bjjjjjjjjjjjjjja"
    ],
    [
      "ajjjjjjjjjjjjjjb",
      "j     m       *j",
      "j(    r3      )j",
      "j+             j",
      "j             -j",
      "j[  ]          j",
      "j   ]         {j",
      "j}  |         *j",
      "j;;;;a:a*aaa'<aj",
      "j    >  a ,    j",
      "j .   ? a  a/` j",
      "j   23 3a  a  aj",
      "j   2   a 4a   j",
      "j   2   a\u0370ha   j",
      "j\u0371  2  \u0372a  a   j",
      "bjjjjjjjjjjjjjja"
    ],
    [
      "ajjjjjjjjjjjjjjb",
      "j    m        \u0373j",
      "j    r3        j",
      "j              j",
      "j              j",
      "j              j",
      "j              j",
      "j             \u0373j",
      "j;;;;aaa\u0373aaaeeaj",
      "j      \u0374a \u0375\u0376   j",
      "j      \u0377a  a\u037a\u037b j",
      "j   2333a  a\u037c\u037caj",
      "j   2   a\u037d a   j",
      "j   2   ae4a   j",
      "j   2  \u037eahha   j",
      "bjjjjjjjjjjjjjja"
    ],
    [
      "ajjjjjjjjjjjjjjb",
      "j   m          j",
      "j   r3         j",
      "j              j",
      "j              j",
      "j              j",
      "j              j",
      "j              j",
      "j;;;;aaa aaaaaaj",
      "j       a  a  \u037fj",
      "j    \u0384\u0384\u0384a  a   j",
      "j   \u0385   a\u037d aaaaj",
      "j   \u0385   af a   j",
      "j   \u0385   a  a   j",
      "j   \u0385   a  a   j",
      "bjjjjjjjjjjjjjja"
    ],
    [
      "ajjjjjjjjjjjjjjb",
      "j\u0386 m           j",
      "j\u0386\u0386r3          j",
      "j\u0386\u0387\u0386           j",
      "j\u0386\u0387\u0387\u0386          j",
      "j\u0386\u0387\u0387\u0387\u0386         j",
      "j\u0386\u0387\u0388\u0387\u0387\u0386        j",
      "j\u0389\u0387\u0387\u0387\u0387\u0387\u0386       j",
      "jaaaaaaa\u0386aaaaaaj",
      "j\u038a\u0387\u0387\u0387\u0387\u0387\u0387a  a   j",
      "j\u0386\u0387\u0387\u0387\u0387\u0387\u0387a\u037d\u0370a   j",
      "j\u0386\u0387\u0387\u0387\u0387\u0387\u0387af aaaaj",
      "j\u0386\u0387\u0387\u0387\u0387\u0387\u0387a  a   j",
      "j\u0386\u0387\u0387\u0387\u0387\u0387\u0387a  a   j",
      "j\u0386\u0386\u0386\u038c\u0387\u0387\u0387a  a   j",
      "bjjjjjjjjjjjjjja"
    ]
  ]
}