{
  "name": "multi_thering_6_floor20",
  "refpalette": "deceasedcraft:multi_thering_6/multi_thering_6_floor20_palette",
  "xsize": 16,
  "zsize": 16,
  "slices": [
    [
      "aaaaaaaaaaaaaaab",
      "acccccccccccccca",
      "acccccccccccccca",
      "acccccccccccccca",
      "acccccccccccccca",
      "acccccccccccccca",
      "acccccccccccccca",
      "acccccccccccccca",
      "aaaaacaaaaaaddaa",
      "accccceeaffdddda",
      "accccceeagfaddda",
      "accccceea haddia",
      "accccceea  ajjka",
      "accccceea  ajlja",
      "accccceea  ajjja",
      "baaaaaaaaaaaaaaa"
    ],
    [
      "ammmmmmmmmmmmmmb",
      "mno   pq rpp  sm",
      "mtuuuw        sm",
      "mxuuyAB     C Dm",
      "mxuuEFI    B  Jm",
      "mxuuKL M     MNm",
      "mOuuu   PBQRS Im",
      "mnTUVr  WXYYYZYm",
      "m0aaa1aafaaa23am",
      "m456 789a#$%^^ m",
      "m   r7  a &a*()m",
      "muu++ -[a ]a{{am",
      "mu}}+r|[a ha;:'m",
      "mu<<u7>,a  a # m",
      "m.??.7/`a  a\u0370 &m",
      "bmmmmmmmmmmmmmma"
    ],
    [
      "ammmmmmmmmmmmmmb",
      "m\u0371     p p    \u0372m",
      "m              m",
      "m\u0373   \u0374         m",
      "m\u0375   \u0376         m",
      "m              m",
      "m\u0377     \u037a       m",
      "m\u0371\u037b    W  Q\u037cI\u037dwm",
      "maaaa\u037eaf\u037faaa\u0384\u0385am",
      "m \u0386 \u03877  a \u0388%   m",
      "m    7 \u0389a  a\u038a\u038c m",
      "m     \u038e a  a  am",
      "m     \u038f\u0390a ]a :\u0391m",
      "m    7 \u0392a\u0393ha   m",
      "m\u0394  \u03957\u0396 a  a\u0397  m",
      "bmmmmmmmmmmmmmma"
    ],
    [
      "ammmmmmmmmmmmmmb",
      "m\u0398      pp     m",
      "m              m",
      "m              m",
      "m              m",
      "m              m",
      "m     \u037a\u0399       m",
      "m\u0398    W        m",
      "maaaaaf\u037f\u037faaaffam",
      "m    7\u039a\u039ba \u039c\u039d   m",
      "m    7  a  a\u039e\u039f m",
      "m    7 \u03a0a  a\u03a1\u03a1am",
      "m    7 \u03a3a\u03a4 a :\u0391m",
      "m    7 \u03a5af]a   m",
      "m    7  ahha\u0397  m",
      "bmmmmmmmmmmmmmma"
    ],
    [
      "ammmmmmmmmmmmmmb",
      "m      p pp    m",
      "m              m",
      "m              m",
      "m              m",
      "m              m",
      "m    \u037a\u0399        m",
      "m    W         m",
      "maaaaf\u037f\u037f\u037faaaaaam",
      "m    \u03a6\u03a7\u03a8a& a  \u03a9m",
      "m    \u03a6  a  a   m",
      "m    \u03a6  a\u03a4 aaaam",
      "m    \u03a6  ag a :\u0391m",
      "m    \u03a6  a  a   m",
      "m    \u03a6  a  a\u03aa  m",
      "bmmmmmmmmmmmmmma"
    ],
    [
      "ammmmmmmmmmmmmmb",
      "m     pp  pp   m",
      "m              m",
      "m              m",
      "m              m",
      "m              m",
      "m   \u037a\u0399         m",
      "m   W          m",
      "maaaf\u037f\u037f\u037f\u037faaaaaam",
      "m\u03ab\u03ac\u03ac\u03ac\u03ac\u03ac\u03ada!&a   m",
      "m\u03ab\u03ac\u03ac\u03ac\u03ac\u03ac\u03aca\u03a4\u0393a   m",
      "m\u03ab\u03ac\u03ac\u03ac\u03ac\u03ac\u03acag aaaam",
      "m\u03ab\u03ac\u03ac\u03ac\u03ac\u03ac\u03aca  a\u03ae\u03ae\u03afm",
      "m\u03ab\u03ac\u03ac\u03ac\u03ac\u03ac\u03aca  a\u03af\u03af\u03afm",
      "m\u03ab\u03ab\u03ab\u03ab\u03b0\u03ac\u03aca  a\u03af\u03af\u03afm",
      "bmmmmmmmmmmmmmma"
    ]
  ]
}