{
  "name": "multi_thering_6_floor22",
  "refpalette": "deceasedcraft:multi_thering_6/multi_thering_6_floor22_palette",
  "xsize": 16,
  "zsize": 16,
  "slices": [
    [
      "abbbbbbbbbbbbbbc",
      "a              b",
      "a              b",
      "a              b",
      "a      d       b",
      "a              b",
      "aeeef          b",
      "aghi      jklm b",
      "annnnnnnnaaaaaab",
      "annnnnooappa   b",
      "annnnnooaqpa   b",
      "annnnnooa raaaab",
      "annnnnooa  a   b",
      "annnnnooa  a   b",
      "annnnnooa  a   b",
      "caaaaaaaaaaaaaaa"
    ],
    [
      "abbbbbbbbbbbbbbc",
      "b              b",
      "b              b",
      "b              b",
      "b      sd      b",
      "b      d       b",
      "bfff           b",
      "b  ffffff tuwx b",
      "by    aaAaaaaaab",
      "bB    CDa  a   b",
      "bEFIFJ Ka  a   b",
      "bLMMLJ Na Oaaaab",
      "bPQQPJ Ra ra   b",
      "bPPPPJ  a  a   b",
      "bSy  JTUa  a   b",
      "cbbbbbbbbbbbbbba"
    ],
    [
      "abbbbbbbbbbbbbbc",
      "b              b",
      "b              b",
      "b              b",
      "b      ssd     b",
      "b     dsd      b",
      "b              b",
      "b         VWXY b",
      "bZ   0aa1aaaaaab",
      "b     2 a  a   b",
      "b3333J  a  a   b",
      "b4  5J  a  aaaab",
      "b    J  a Oa   b",
      "b    J 6a7ra   b",
      "b 8  J  a  a   b",
      "cbbbbbbbbbbbbbba"
    ],
    [
      "abbbbbbbbbbbbbbc",
      "b              b",
      "b              b",
      "b              b",
      "b   9ddsssd9   b",
      "b   9dsssdd9   b",
      "b              b",
      "b              b",
      "b     aa#aaaaaab",
      "b    J $a  a   b",
      "b3333J  a  a   b",
      "b    J  a  aaaab",
      "b    J  a% a   b",
      "b    J ^apOa   b",
      "b    J  arra   b",
      "cbbbbbbbbbbbbbba"
    ],
    [
      "abbbbbbbbbbbbbbc",
      "b              b",
      "b              b",
      "b              b",
      "b   &&&&&&&&   b",
      "b   &&&&&&&&   b",
      "b              b",
      "b              b",
      "b     aa*aaaaaab",
      "b    (  a  a   b",
      "b    (  a  a   b",
      "b    (  a% aaaab",
      "b    (  aq a   b",
      "b    (  a  a   b",
      "b    (  a  a   b",
      "cbbbbbbbbbbbbbba"
    ],
    [
      "abbbbbbbbbbbbbbc",
      "b))))))))))))))b",
      "b)++++++++++++)b",
      "b)+-[[[[[[[[-+)b",
      "b)+[]]]]]]]][+)b",
      "b)+[]]]]]]]][+)b",
      "b)+-[[[[[[[[-+)b",
      "b)++++++++++++)b",
      "b)++++aa+aaaaaab",
      "b)++++++a  a{{{b",
      "b)++++++a%7a{{{b",
      "b)++++++aq aaaab",
      "b)++++++a  a   b",
      "b)++++++a  a   b",
      "b))))}++a  a   b",
      "cbbbbbbbbbbbbbba"
    ]
  ]
}