{
  "name": "multi_thering_6_ground",
  "refpalette": "deceasedcraft:multi_thering_6/multi_thering_6_ground_palette",
  "xsize": 16,
  "zsize": 16,
  "slices": [
    [
      "HHHabccccbbbdddd",
      "HHabcccbbdddeeed",
      "Habcccbddeeeeeed",
      "abcccbdeeeeeeeed",
      "bcccbfeeeeeeeeed",
      "cccbfeeeeeeeeeef",
      "ccbdeeeeeeeeeeef",
      "cbdeeeeeeeeeeeef",
      "cbdeeeeeedddeeed",
      "bdeeeeeedgheeeed",
      "bdeeeeeed hdeeed",
      "bdeeeeeed ideejd",
      "deeeeeeed  d   d",
      "deeeeeeed  d   d",
      "deeeeeeed  d   d",
      "dddddfffdddddddd"
    ],
    [
      " k          lllm",
      "         lll   l",
      "       ll      l",
      "      n   d o  l",
      "          dppppl",
      "           q q r",
      "   n            ",
      "  l            s",
      "  l      ddd   l",
      " l      d t    l",
      " lu     d  dwxyl",
      " lA     d BdCCdl",
      "l A     d id   l",
      "l A     d  d   l",
      "l DE    d  d   l",
      "mllllF Illllllld"
    ],
    [
      "            lllm",
      "         lll   l",
      "       ll      l",
      "      n        l",
      "          J K  l",
      "               r",
      "   n            ",
      "  l            s",
      "  l      ddd   l",
      " l      d L    l",
      " l      d  dMN l",
      " l      d  d  dl",
      "l       d Bd   l",
      "l       dOid   l",
      "l       d  d   l",
      "mllllF Illllllld"
    ],
    [
      "            lllm",
      "         lll   l",
      "       ll      l",
      "      n        l",
      "     P         l",
      "    P          Q",
      "   n           P",
      "  l       R    S",
      "  l      ddd   l",
      " l      d TU   l",
      " l      d  dVV l",
      " l     Wd  dXXdl",
      "l      YdZ d   l",
      "l       dhBd   l",
      "l       diid   l",
      "mllll0P1llllllld"
    ],
    [
      "            lllm",
      "         lll   l",
      "       ll      l",
      "      l        l",
      "     l         l",
      "    l          l",
      "   l           l",
      "  l       2    l",
      "  l    3 ddd   l",
      " l      d  d   l",
      " l      d  d   l",
      " l     4dZ ddddl",
      "l      5dg d   l",
      "l       d  d   l",
      "l       d  d   l",
      "mlllllllllllllld"
    ],
    [
      "            lllm",
      "         lll   l",
      "       ll      l",
      "      l        l",
      "     l         l",
      "    l          l",
      "   l           l",
      "  l    !       l",
      "  l    6 ddd   l",
      " l      d  d   l",
      " l      dZOd   l",
      " l      dg ddddl",
      "l       d  d   l",
      "l       d  d   l",
      "l       d  d   l",
      "mlllllllllllllld"
    ]
  ]
}