{
  "name": "multi_thering_6_floor17",
  "refpalette": "deceasedcraft:multi_thering_6/multi_thering_6_floor17_palette",
  "xsize": 16,
  "zsize": 16,
  "slices": [
    [
      "abbbbbbbbbbbbbbc",
      "b               ",
      "b               ",
      "b               ",
      "b               ",
      "b               ",
      "b               ",
      "b       d d     ",
      "b       aaaa   a",
      "b       effa   g",
      "b       ehiajk g",
      "b       e lammaa",
      "b       e  a   g",
      "b          a   g",
      "b       e  a   g",
      "cbbbbbbbagggggga"
    ],
    [
      "abbbbbbbbbbbbbbc",
      "b               ",
      "b               ",
      "b               ",
      "b               ",
      "b               ",
      "b               ",
      "b               ",
      "b       aaaa   a",
      "b       e  a   g",
      "b       e  a   g",
      "b       e naaaaa",
      "b       o la   g",
      "b       p  a   g",
      "b       q  a   g",
      "cbbbbbbbagggggga"
    ],
    [
      "abbbbbbbbbbbbbbc",
      "b               ",
      "b               ",
      "b               ",
      "b               ",
      "b               ",
      "b               ",
      "b               ",
      "b       aaaa   a",
      "b       e  a   g",
      "b       e  a   g",
      "b       e  aaaaa",
      "b       e na   g",
      "b       rsla   g",
      "b       e  a   g",
      "cbbbbbbbagggggga"
    ],
    [
      "abbbbbbbbbbbbbbc",
      "b               ",
      "b               ",
      "b               ",
      "b               ",
      "b               ",
      "b               ",
      "b               ",
      "b       aaaa   a",
      "b       e  a   g",
      "b       e  a   g",
      "b       e  aaaaa",
      "b       ef a   g",
      "b       eina   g",
      "b       ella   g",
      "cbbbbbbbagggggga"
    ],
    [
      "abbbbbbbbbbbbbbc",
      "b               ",
      "b               ",
      "b               ",
      "b               ",
      "b               ",
      "b               ",
      "b               ",
      "b       aaaa   a",
      "b       e  a   g",
      "b       e  a   g",
      "b       ef aaaaa",
      "b       eh a   g",
      "b       e  a   g",
      "b       e  a   g",
      "cbbbbbbbagggggga"
    ],
    [
      "abbbbbbbbbbbbbbc",
      "btttttttttttttt ",
      "btuuuuuuuuuuuut ",
      "btuuuuuuuuuuuut ",
      "btuuuuuuuuuuuut ",
      "btuuuuuuuuuuuut ",
      "btuuuuuuuuuuuut ",
      "btuuuuuuuuuuuut ",
      "btuuuuuuaaaauuta",
      "btuuuuuuw  auutg",
      "btuuuuuuwfsauutg",
      "btuuuuuuwh aaaaa",
      "btuuuuuuw  a   g",
      "btuuuuuuw  a   g",
      "btttttttw  a   g",
      "cbbbbbbbagggggga"
    ]
  ]
}