{
  "name": "multi_thering_6_floor2",
  "refpalette": "deceasedcraft:multi_thering_6/multi_thering_6_floor2_palette",
  "xsize": 16,
  "zsize": 16,
  "slices": [
    [
      "aaaaaaaaaaaaaaab",
      "accccaccccccccca",
      "accccaccccccccca",
      "accccacccdddccca",
      "accdddaccdddccca",
      "accdddacaaaaaaaa",
      "accccaeeeeeeeeea",
      "acccccefeeeeeeea",
      "accccaeeeaaaeeea",
      "aaaaaaacaggeeeea",
      "acccddccahgaeeea",
      "acccddcca iaeeja",
      "acccddcca  a   a",
      "accccccca  a   a",
      "accccccca  a   a",
      "baaaaaaaaaaaaaaa"
    ],
    [
      "akkkkkkkkkkkkkkb",
      "kl  man       lk",
      "k  opaq  r r   k",
      "k  rras t uwxy k",
      "k  A Ba CD ExFIk",
      "k J KLaMaaaaaaak",
      "k  NOa        Pk",
      "k    Q        Pk",
      "kRSTUa   aaa   k",
      "kaaaaaaVa W    k",
      "kXYJ!Zn a  a012k",
      "k 3J 4q a 5a66ak",
      "k   7Bs a ia   k",
      "k   NOR a  a   k",
      "kl      a  a   k",
      "bkkkkkkkkkkkkkka"
    ],
    [
      "akkkkkkkkkkkkkkb",
      "k!  8a9       #k",
      "k    a9  r r   k",
      "k  rra$ %^& x  k",
      "k  *( a ) + x 8k",
      "k J+  a-aaaaaaak",
      "k  []a         k",
      "k    {         k",
      "kR   a   aaa   k",
      "kaaaaaa}a |    k",
      "k; J:   a  a'< k",
      "k  J^   a  a  ak",
      "k   > 9 a 5a   k",
      "k   []R a,ia   k",
      "k.      a  a   k",
      "bkkkkkkkkkkkkkka"
    ],
    [
      "akkkkkkkkkkkkkkb",
      "k    a?        k",
      "k    a/  rrr   k",
      "k  rra` \u0370   x  k",
      "k J   a \u0371 \u0372 x  k",
      "k J\u0372  agaaaaaaak",
      "k  \u0373\u0374a         k",
      "k    g    \u0375    k",
      "kR\u0376\u0377\u037aa   aaa   k",
      "kaaaaaaga \u037b\u037c   k",
      "k  J\u037d \u037e a  a\u037f\u037f k",
      "k  J  \u0384 a  a\u0385\u0385ak",
      "k  J  \u0386 a\u0387 a   k",
      "k   \u0373\u0374R ag5a   k",
      "k       aiia   k",
      "bkkkkkkkkkkkkkka"
    ],
    [
      "akkkkkkkkkkkkkkb",
      "k    a         k",
      "k    a   \u0388\u0388\u0388   k",
      "k  \u0388\u0388a  \u0389\u038a\u038a\u038a\u038c  k",
      "k \u0389\u038a\u038a\u038aa \u0389\u038a\u038a\u038a\u038c  k",
      "k \u0389\u038a\u038a\u038aaaaaaaaaak",
      "k  \u038e\u038ea         k",
      "k    a         k",
      "k\u038f\u0390  a   aaa   k",
      "kaaaaaaaa  a   k",
      "k  \u0389\u038a\u038a\u038c a  a   k",
      "k  \u0389\u038a\u038a\u038c a\u0387 aaaak",
      "k  \u0389\u038a\u038a\u038c ah a   k",
      "k   \u038e\u038e  a  a   k",
      "k       a  a   k",
      "bkkkkkkkkkkkkkka"
    ],
    [
      "akkkkkkkkkkkkkkb",
      "k\u0391\u0391\u0391\u0391a\u0391\u0391\u0391\u0391\u0391\u0391\u0391\u0391\u0391k",
      "k\u0391\u038a\u038a\u038aa\u038a\u038a\u038a\u038a\u038a\u038a\u038a\u038a\u0391k",
      "k\u0391\u038a\u038a\u038aa\u038a\u038a\u038a   \u038a\u038a\u0391k",
      "k\u0391\u038a  \u0392a\u038a\u038a\u0392\u0392 \u038a\u038a\u0391k",
      "k\u0391\u038a  \u0392aaaaaaaaak",
      "k\u0391\u038a\u038a\u038aa\u0393\u0393\u0393\u0393\u0393\u0393\u0393\u0393\u0393k",
      "k\u0391\u038a\u038a\u038aa\u0393\u0394\u0393\u0393\u0393\u0393\u0393\u0393\u0393k",
      "k\u0391\u038a\u038a\u038aa\u0393\u0393\u0393aaa\u0393\u0393\u0393k",
      "kaaaaaaaa  a\u0393\u0393\u0393k",
      "k\u0391\u038a\u038a\u0392\u0392\u038a\u038aa\u0387,a\u0393\u0393\u0393k",
      "k\u0391\u038a\u038a  \u038a\u038aah aaaak",
      "k\u0391\u038a\u038a  \u038a\u038aa  a   k",
      "k\u0391\u038a\u038a\u038a\u038a\u038a\u038aa  a   k",
      "k\u0391\u0391\u0391\u0391\u0391\u0391\u0391a  a   k",
      "bkkkkkkkkkkkkkka"
    ]
  ]
}