{
  "name": "multi_thering_6_floor9",
  "refpalette": "deceasedcraft:multi_thering_6/multi_thering_6_floor9_palette",
  "xsize": 16,
  "zsize": 16,
  "slices": [
    [
      "aaaaaaaaaaaaaaab",
      "acdedfggggcded!a",
      "ahdedigggghdedfa",
      "ahdedjggggkdedia",
      "akdddlggggldddja",
      "agggggggggggggga",
      "agggggggggggggga",
      "agggggggggggggga",
      "aggggggggaaagggm",
      "annaaaaaaooggggm",
      "annnnnnnapoagggm",
      "annnnnnna qarrsa",
      "annnnnnna  a   a",
      "annnnnnna  a   a",
      "annnnnnna  a   a",
      "baaaaaaaaaaaaaaa"
    ],
    [
      "attttttttttttttb",
      "t     uwxu     t",
      "t     u  u     t",
      "t     u  u     t",
      "t              t",
      "tuuuuuu  uuuuuut",
      "t              t",
      "t  yyyyyy      t",
      "t  AAAAAAaaa   B",
      "tCDaEEFaa I     ",
      "t      Ja  aKLMN",
      "t  OP  Qa RaSSat",
      "t  TU  Va qa   t",
      "t     WXa  a   t",
      "tYYYAZAAa  a   t",
      "btttttttatttttta"
    ],
    [
      "attttttttttttttb",
      "t     u 0u     t",
      "t     u  u     t",
      "t     u  u     t",
      "t              t",
      "tuuuuuu  uuuuuut",
      "t              t",
      "t              t",
      "t   12 3 aaa   B",
      "t  4444aa 5     ",
      "t      Ja  a67 N",
      "t   8   a  a  at",
      "t     9#a Ra   t",
      "t      Xa$qa   t",
      "t%%^& ^!a  a   t",
      "btttttttatttttta"
    ],
    [
      "attttttttttttttb",
      "t              t",
      "t              t",
      "t              t",
      "t              t",
      "t              t",
      "t              t",
      "t              t",
      "t        aaa   *",
      "t  4444aa ()   +",
      "t      Ja  a-[ ]",
      "t       a  a{{at",
      "t      }a| a   t",
      "t     ;XaoRa   t",
      "t       aqqa   t",
      "btttttttatttttta"
    ],
    [
      "attttttttttttttb",
      "t              t",
      "t              t",
      "t              t",
      "t              t",
      "t              t",
      "t              t",
      "t              t",
      "t        aaa   t",
      "t  ::::aa  a   t",
      "t      Xa  a   t",
      "t     ' a| aaaat",
      "t     <>ap a   t",
      "t      Xa  a   t",
      "t       a  a   t",
      "btttttttatttttta"
    ],
    [
      "attttttttttttttb",
      "t,,,,,,,,      t",
      "t,,,,,,,,      t",
      "t,,,,,,,,      t",
      "t,,,,,,,,      t",
      "t,,,,,,,,      t",
      "t,,,,,,,,      t",
      "t,,,,,,,,      t",
      "t,,,,,,,,aaa   t",
      "taaaaaaaa  a   t",
      "t      Xa|$a   t",
      "t     . ap aaaat",
      "t     ?/a  a   t",
      "t      Xa  a   t",
      "t       a  a   t",
      "btttttttatttttta"
    ]
  ]
}