{
  "name": "multi_thering_6_floor19",
  "refpalette": "deceasedcraft:multi_thering_6/multi_thering_6_floor19_palette",
  "xsize": 16,
  "zsize": 16,
  "slices": [
    [
      "abbbbbbbbbbbbbbc",
      "ade            b",
      "addf           b",
      "addd           b",
      "adddd          b",
      "addddd         b",
      "adddddd        b",
      "addddddd  ghij b",
      "addddddddaaaaaab",
      "adddddddakka   b",
      "adddddddalka   b",
      "addddmmma naaaab",
      "addddmmma  a   b",
      "addddmmma  a   b",
      "addddmmma  a   b",
      "caaaaaaaaaaaaaaa"
    ],
    [
      "abbbbbbbbbbbbbbc",
      "b              b",
      "b fo           b",
      "b  fo          b",
      "b   fo         b",
      "bpqqqfo        b",
      "brstq fo       b",
      "brstq ufo wxyA b",
      "bpqqq   Baaaaaab",
      "b      Ca  a   b",
      "b   DEFIa  a   b",
      "b   JKLMa Naaaab",
      "bO   P Qa na   b",
      "bu  J   a  a   b",
      "b R J STa  a   b",
      "cbbbbbbbbbbbbbba"
    ],
    [
      "abbbbbbbbbbbbbbc",
      "b              b",
      "b              b",
      "b              b",
      "b              b",
      "bU             b",
      "b              b",
      "b     V        b",
      "bW      Xaaaaaab",
      "b       a  a   b",
      "b   YZZZa  a   b",
      "b   J   a  aaaab",
      "b    0  a Na   b",
      "b1  J2 3a4na   b",
      "b   J2  a  a   b",
      "cbbbbbbbbbbbbbba"
    ],
    [
      "abbbbbbbbbbbbbbc",
      "b              b",
      "b              b",
      "b              b",
      "b              b",
      "b              b",
      "b              b",
      "b              b",
      "b       5aaaaaab",
      "b       a  a   b",
      "b   6ZZZa  a   b",
      "b   J   a  aaaab",
      "b   J  7a8 a   b",
      "b   J  9akNa   b",
      "b   J   anna   b",
      "cbbbbbbbbbbbbbba"
    ],
    [
      "abbbbbbbbbbbbbbc",
      "b              b",
      "b              b",
      "b              b",
      "b              b",
      "b              b",
      "b              b",
      "b              b",
      "b       #aaaaaab",
      "b       a  a   b",
      "b    $$$a  a   b",
      "b   %   a8 aaaab",
      "b   %   al a   b",
      "b   %   a  a   b",
      "b   %   a  a   b",
      "cbbbbbbbbbbbbbba"
    ],
    [
      "abbbbbbbbbbbbbbc",
      "b^^^^^^^^^^^^^^b",
      "b^&&&&&&&&&&&&^b",
      "b^&*((((((((*&^b",
      "b^&())))))))(&^b",
      "b^&())))))))(&^b",
      "b^&*((((((((*&^b",
      "b^&&&&&&&&&&&&^b",
      "b^&&&&&&&aaaaaab",
      "b^&&&&&&a  a+++b",
      "b^&&&&&&a84a+++b",
      "b^&&&&&&al aaaab",
      "b^&&&&&&a  a   b",
      "b^&&&&&&a  a   b",
      "b^^^-&&&a  a   b",
      "cbbbbbbbbbbbbbba"
    ]
  ]
}