{
  "name": "multi_thering_6_top",
  "refpalette": "deceasedcraft:multi_thering_6/multi_thering_6_top_palette",
  "xsize": 16,
  "zsize": 16,
  "slices": [
    [
      "aaaaaaaaaaaaaaab",
      "acccccccccccccca",
      "acccccccccccccca",
      "acccccccccccccca",
      "acccccccccccccca",
      "acccccccccccccca",
      "acccccccccccccca",
      "acccccccccccccca",
      "accccccccaaaccca",
      "acccccc addcccca",
      "acccccceafdaccca",
      "acccccc!a gahhia",
      "accccccea  a   a",
      "accccccja  a   a",
      "accccccea  a   a",
      "baaaaaaaaaaaaaaa"
    ],
    [
      "akkkkkkkkkkkkkkb",
      "k              k",
      "k              k",
      "kl   mnnnnno   k",
      "kp  qrs tu w   k",
      "kx   rs yA w   k",
      "k   Brs CA w   k",
      "kl   rs yA D   k",
      "kp  Br  Eaaa   k",
      "kx   r Fa I    k",
      "k   Br Ja  aKLMk",
      "kl   r Ja NaOOak",
      "kp  Br Ja ga   k",
      "kx   r Ja  a   k",
      "k   Br Pa  a   k",
      "bkkkkkkkkkkkkkka"
    ],
    [
      "akkkkkkkkkkkkkkb",
      "k              k",
      "k              k",
      "k     QRSTUV   k",
      "kW      XY     k",
      "k    Z  01 2   k",
      "k    3   1     k",
      "k       45     k",
      "k6      7aaa   k",
      "k      8a 9    k",
      "k    # 0a  a$% k",
      "k      ^a  a  ak",
      "k&   * (a Na   k",
      "k      )a+ga   k",
      "k    - [a  a   k",
      "bkkkkkkkkkkkkkka"
    ],
    [
      "akkkkkkkkkkkkkkb",
      "k              k",
      "k              k",
      "k              k",
      "k       ]{     k",
      "k       }|     k",
      "k       ;:     k",
      "k       '<     k",
      "k       >aaa   k",
      "k      ,a .?   k",
      "k      /a  a`\u0370 k",
      "k      /a  a\u0371\u0371ak",
      "k      /a\u0372 a   k",
      "k      /adNa   k",
      "k      \u0373agga   k",
      "bkkkkkkkkkkkkkka"
    ],
    [
      "akkkkkkkkkkkkkkb",
      "k              k",
      "k              k",
      "k              k",
      "k              k",
      "k       \u0374\u0374     k",
      "k       \u0375      k",
      "k       \u0376      k",
      "k       #aaa   k",
      "k       a  a   k",
      "k       a  a   k",
      "k       a\u0372 aaaak",
      "k       af a   k",
      "k       a  a   k",
      "k       a  a   k",
      "bkkkkkkkkkkkkkka"
    ],
    [
      "akkkkkkkkkkkkkkb",
      "k              k",
      "k              k",
      "k              k",
      "k              k",
      "k       \u0374\u0374     k",
      "k              k",
      "k              k",
      "k        aaa   k",
      "k       a  a   k",
      "k       a\u0372+a   k",
      "k       af aaaak",
      "k       a  a   k",
      "k       a  a   k",
      "k       a  a   k",
      "bkkkkkkkkkkkkkka"
    ],
    [
      "akkkkkkkkkkkkkkb",
      "k              k",
      "k              k",
      "k              k",
      "k              k",
      "k       \u0374\u0374     k",
      "k              k",
      "k              k",
      "k        aaa   k",
      "k       adda   k",
      "k       afda   k",
      "k       a gaaaak",
      "k       a  a   k",
      "k       a  a   k",
      "k       a  a   k",
      "bkkkkkkkkkkkkkka"
    ],
    [
      "akkkkkkkkkkkkkkb",
      "k              k",
      "k              k",
      "k              k",
      "k              k",
      "k       \u0374\u0374     k",
      "k              k",
      "k              k",
      "k        aaa   k",
      "k       a  a   k",
      "k       a  a   k",
      "k       a Naaaak",
      "k       a ga   k",
      "k       a  a   k",
      "k       a  a   k",
      "bkkkkkkkkkkkkkka"
    ],
    [
      "akkkkkkkkkkkkkkb",
      "k\u0377\u0377\u0377\u0377\u0377\u0377\u0377\u0377\u0377\u0377\u0377\u0377\u0377\u0377k",
      "k\u0377\u037a\u037a\u037a\u037a\u037a\u037a\u037a\u037a\u037a\u037a\u037a\u037a\u0377k",
      "k\u0377\u037a\u037a\u037a\u037a\u037a\u037a\u037a\u037a\u037a\u037a\u037a\u037a\u0377k",
      "k\u0377\u037a\u037a\u037a\u037a\u037a\u037a\u037a\u037a\u037a\u037a\u037a\u037a\u0377k",
      "k\u0377\u037a\u037a\u037a\u037a\u037a\u037a\u037a\u037a\u037a\u037a\u037a\u037a\u0377k",
      "k\u0377\u037a\u037a\u037a\u037a\u037a\u037a\u037a\u037a\u037a\u037a\u037a\u037a\u0377k",
      "k\u0377\u037a\u037a\u037a\u037a\u037a\u037a\u037a\u037a\u037a\u037a\u037a\u037a\u0377k",
      "k\u0377\u037a\u037a\u037a\u037a\u037a\u037a\u037aaaa\u037a\u037a\u0377k",
      "k\u0377\u037a\u037a\u037a\u037a\u037a\u037aa  a\u037a\u037a\u0377k",
      "k\u0377\u037a\u037a\u037a\u037a\u037a\u037aa  a\u037a\u037a\u0377k",
      "k\u0377\u037a\u037a\u037a\u037a\u037a\u037aa  aaaak",
      "k\u0377\u037a\u037a\u037a\u037a\u037a\u037aa Na   k",
      "k\u0377\u037a\u037a\u037a\u037a\u037a\u037aa ga   k",
      "k\u0377\u0377\u0377\u0377\u0377\u0377\u0377a  a   k",
      "bkkkkkkkkkkkkkka"
    ],
    [
      "aaaaaaaaaaaaaaab",
      "a\u037b\u037b\u037b\u037b\u037b\u037b\u037b\u037b\u037b\u037b\u037b\u037b\u037b\u037ba",
      "a\u037b\u037b\u037c\u037c\u037c\u037c\u037c\u037c\u037c\u037c\u037c\u037c\u037c\u037ca",
      "a\u037b\u037c\u037c\u037b\u037b\u037b\u037b\u037b\u037b\u037b\u037b\u037b\u037b\u037ba",
      "a\u037b\u037c\u037b\u037b\u037c\u037c\u037c\u037c\u037c\u037c\u037c\u037c\u037c\u037ca",
      "a\u037b\u037c\u037b\u037c\u037c\u037d\u037d\u037d\u037d\u037d\u037d\u037d\u037d\u037da",
      "a\u037b\u037c\u037b\u037c\u037d\u037d\u037e\u037e\u037e\u037e\u037e\u037e\u037e\u037ea",
      "a\u037b\u037c\u037b\u037c\u037d\u037e\u037e\u037e\u037e\u037e\u037e\u037e\u037e\u037ea",
      "a\u037b\u037c\u037b\u037c\u037d\u037e\u037e\u037e\u037e\u037e\u037e\u037e\u037e\u037ea",
      "a\u037b\u037c\u037b\u037c\u037d\u037e\u037e\u037e  \u037e\u037e\u037e\u037ea",
      "a\u037b\u037c\u037b\u037c\u037d\u037e\u037e\u037e  \u037e\u037e\u037e\u037ea",
      "a\u037b\u037c\u037b\u037c\u037d\u037e\u037e\u037e  ahhia",
      "a\u037b\u037c\u037b\u037c\u037d\u037e\u037e\u037e  a   a",
      "a\u037b\u037c\u037b\u037c\u037d\u037e\u037e\u037e Na   a",
      "a\u037b\u037c\u037b\u037c\u037d\u037e\u037e\u037edda   a",
      "baaaaaaaaaaaaaaa"
    ],
    [
      "a\u037f\u037f\u037f\u037f\u037f\u037f\u037f\u037f\u037f\u037f\u037f\u037f\u037f\u037fb",
      "\u0384\u0385\u0386\u0386\u0386\u0386\u0386\u0386\u0386\u0386\u0386\u0386\u0386\u0386\u0386\u0387",
      "\u0384\u0386\u0386\u037c\u037c\u037c\u037c\u037c\u037c\u037c\u037c\u037c\u037c\u037c\u037c\u0387",
      "\u0384\u0386\u037c\u037c\u0388\u0388\u0388\u0388\u0388\u0388\u0388\u0388\u0388\u0388\u0388\u0389",
      "\u0384\u0386\u037c\u0388\u0388\u038a\u038a\u038a\u038a\u038a\u038a\u038a\u038a\u038a\u038a\u0389",
      "\u0384\u0386\u037c\u0388\u038a\u038a\u038c\u038c\u038c\u038c\u038e\u038c\u038c\u038c\u038e\u0389",
      "\u0384\u0386\u037c\u0388\u038a\u038c\u038e \u038f\u0390  \u038f\u0390 \u0389",
      "\u0384\u0386\u037c\u0388\u038a\u038c         \u0389",
      "\u0384\u0386\u037c\u0388\u038a\u038c\u0391        \u0389",
      "\u0384\u0386\u037c\u0388\u038a\u038c\u0392 \u0393\u0394\u0394\u0389   \u0389",
      "\u0384\u0386\u037c\u0388\u038a\u038e  \u0393  \u0389KLM\u0389",
      "\u0384\u0386\u037c\u0388\u038a\u038c  \u0393  aOOa\u0389",
      "\u0384\u0386\u037c\u0388\u038a\u038c\u0391 \u0393  a   k",
      "\u0384\u0386\u037c\u0388\u038a\u038c\u0392 \u0393\u0395 a   k",
      "\u0384\u0386\u037c\u0388\u038a\u038e     a   k",
      "b\u0396\u0396\u0394\u0394\u0394\u0394\u0394\u0394\u0394\u0394\u0394kkka"
    ],
    [
      "a\u0395\u0395\u0395\u0395\u0395\u0395\u0395\u0395\u0395\u0395\u0395\u0395\u0395\u0395b",
      "\u0393\u0397\u0398\u0398\u0398\u0398\u0398\u0398\u0398\u0398\u0398\u0398\u0398\u0398\u0398\u0389",
      "\u0393\u0398\u0398            \u0389",
      "\u0393\u0398              ",
      "\u0393\u0398              ",
      "\u0393\u0398        \u0399   \u0399 ",
      "\u0393\u0398    \u0399         ",
      "\u0393\u0398              ",
      "\u0393\u0398              ",
      "\u0393\u0398              ",
      "\u0393\u0398   \u0399      $%  ",
      "\u0393\u0398         a  a ",
      "\u0393\u0398         a   k",
      "\u0393\u0398         a   k",
      "\u0393\u0398   \u0399     a   k",
      "b\u0394\u0394         kkka"
    ],
    [
      "a              b",
      "                ",
      "                ",
      "                ",
      "                ",
      "          \u039a   \u039a ",
      "      \u039a         ",
      "                ",
      "                ",
      "                ",
      "     \u039a      ``  ",
      "           a\u0371\u0371a ",
      "           a   k",
      "           a   k",
      "     \u039a     a   k",
      "b           kkka"
    ],
    [
      "a              b",
      "                ",
      "                ",
      "                ",
      "                ",
      "                ",
      "                ",
      "                ",
      "                ",
      "                ",
      "                ",
      "           aaaa ",
      "           a   k",
      "           a   k",
      "           a   k",
      "b           kkka"
    ],
    [
      "a              b",
      "                ",
      "                ",
      "                ",
      "                ",
      "                ",
      "                ",
      "                ",
      "                ",
      "                ",
      "                ",
      "           aaaa ",
      "           a   k",
      "           a   k",
      "           a   k",
      "b           kkka"
    ],
    [
      "a              b",
      "                ",
      "                ",
      "                ",
      "                ",
      "                ",
      "                ",
      "                ",
      "                ",
      "                ",
      "                ",
      "           aaaa ",
      "           a   k",
      "           a   k",
      "           a   k",
      "b           kkka"
    ],
    [
      "a              b",
      "                ",
      "                ",
      "                ",
      "                ",
      "                ",
      "                ",
      "                ",
      "                ",
      "                ",
      "                ",
      "           aaaa ",
      "           a   k",
      "           a   k",
      "           a   k",
      "b           kkka"
    ],
    [
      "a              b",
      " \u039b\u039b\u039b\u039b\u039b\u039b\u039b\u039b\u039b\u039b\u039b\u039b\u039b\u039b ",
      " \u039b            \u039b ",
      " \u039b            \u039b ",
      " \u039b            \u039b ",
      " \u039b            \u039b ",
      " \u039b            \u039b ",
      " \u039b            \u039b ",
      " \u039b            \u039b ",
      " \u039b            \u039b ",
      " \u039b            \u039b ",
      " \u039b         aaaa ",
      " \u039b         a\u039c\u039c\u039ck",
      " \u039b         a\u039c \u039ck",
      " \u039b\u039b\u039b\u039b\u039b\u039b\u039b\u039b\u039b\u039ba\u039c\u039c\u039ck",
      "b           kkka"
    ],
    [
      "aaaaaaaaaaaaaaab",
      "a\u039d\u039e\u039e\u039e\u039d\u039e\u039e\u039e\u039e\u039d\u039e\u039e\u039e\u039da",
      "a\u039e\u039f\u039f\u039f\u039e\u039f\u039f\u039f\u039f\u039e\u039f\u039f\u039f\u039ea",
      "a\u039e\u039f\u039f\u039f\u039e\u039f\u039f\u039f\u039f\u039e\u039f\u039f\u039f\u039ea",
      "a\u039e\u039f\u039f\u039f\u039e\u039f\u039f\u039f\u039f\u039e\u039f\u039f\u039f\u039ea",
      "a\u039d\u039e\u039e\u039e\u039d\u039e\u039e\u039e\u039e\u039d\u039e\u039e\u039e\u039da",
      "a\u039e\u039f\u039f\u039f\u039e\u039f\u039f\u039f\u039f\u039e\u039f\u039f\u039f\u039ea",
      "a\u039e\u039f\u039f\u039f\u039e\u039f\u039f\u039f\u039f\u039e\u039f\u039f\u039f\u039ea",
      "a\u039e\u039f\u039f\u039f\u039e\u039f\u039f\u039f\u039f\u039e\u039f\u039f\u039f\u039ea",
      "a\u039e\u039f\u039f\u039f\u039e\u039f\u039f\u039f\u039f\u039e\u039f\u039f\u039f\u039ea",
      "a\u039d\u039e\u039e\u039e\u039d\u039e\u039e\u039e\u039e\u039d\u039e\u039e\u039e\u039da",
      "a\u039e\u039f\u039f\u039f\u039e\u039f\u039f\u039f\u039f\u039eaaaaa",
      "a\u039e\u039f\u039f\u039f\u039e\u039f\u039f\u039f\u039f\u039ea   a",
      "a\u039e\u039f\u039f\u039f\u039e\u039f\u039f\u039f\u039f\u039e\u03a0\u03a1\u03a3\u03a4a",
      "a\u039d\u039e\u039e\u039e\u039d\u039e\u039e\u039e\u039e\u039da\u03a5\u03a1\u03a4a",
      "baaaaaaaaaaaaaaa"
    ],
    [
      "\u03a6\u03a6\u03a6\u03a6\u03a6\u03a6\u03a6\u03a6\u03a6\u03a6\u03a6\u03a6\u03a6\u03a6\u03a6b",
      "\u03a6\u03a7\u03a7\u03a7\u03a7\u03a7\u03a7\u03a7\u03a7\u03a7\u03a7\u03a7\u03a7\u03a7\u03a7\u03a6",
      "\u03a6\u03a7\u03a8\u03a8\u03a8\u03a7\u03a8\u03a8\u03a8\u03a8\u03a7\u03a8\u03a8\u03a8\u03a7\u03a6",
      "\u03a6\u03a7\u03a8\u03a8\u03a8\u03a7\u03a8\u03a8\u03a8\u03a8\u03a7\u03a8\u03a8\u03a8\u03a7\u03a6",
      "\u03a6\u03a7\u03a8\u03a8\u03a8\u03a7\u03a8\u03a8\u03a8\u03a8\u03a7\u03a8\u03a8\u03a8\u03a7\u03a6",
      "\u03a6\u03a7\u03a7\u03a7\u03a7\u03a7\u03a7\u03a7\u03a7\u03a7\u03a7\u03a7\u03a7\u03a7\u03a7\u03a6",
      "\u03a6\u03a7\u03a8\u03a8\u03a8\u03a7\u03a8\u03a8\u03a8\u03a8\u03a7\u03a8\u03a8\u03a8\u03a7\u03a6",
      "\u03a6\u03a7\u03a8\u03a8\u03a8\u03a7\u03a8\u03a8\u03a8\u03a8\u03a7\u03a8\u03a8\u03a8\u03a7\u03a6",
      "\u03a6\u03a7\u03a8\u03a8\u03a8\u03a7\u03a8\u03a8\u03a8\u03a8\u03a7\u03a8\u03a8\u03a8\u03a7\u03a6",
      "\u03a6\u03a7\u03a8\u03a8\u03a8\u03a7\u03a8\u03a8\u03a8\u03a8\u03a7\u03a8\u03a8\u03a8\u03a7\u03a6",
      "\u03a6\u03a7\u03a7\u03a7\u03a7\u03a7\u03a7\u03a7\u03a7\u03a7\u03a7\u03a7\u03a7\u03a7\u03a7\u03a6",
      "\u03a6\u03a7\u03a8\u03a8\u03a8\u03a7\u03a8\u03a8\u03a8\u03a8\u03a7\u03a7\u03a7\u03a7\u03a7\u03a6",
      "\u03a6\u03a7\u03a8\u03a8\u03a8\u03a7\u03a8\u03a8\u03a8\u03a8\u03a7\u03a7\u03a7\u03a7\u03a7\u03a6",
      "\u03a6\u03a7\u03a8\u03a8\u03a8\u03a7\u03a8\u03a8\u03a8\u03a8\u03a7\u03a7\u03a9\u03aa\u03aa\u03a6",
      "\u03a6\u03a7\u03a7\u03a7\u03a7\u03a7\u03a7\u03a7\u03a7\u03a7\u03a7\u03a7\u03ab\u03ab\u03ab\u03a6",
      "b\u03a6\u03a6\u03a6\u03a6\u03a6\u03a6\u03a6\u03a6\u03a6\u03a6\u03a6\u03a6\u03a6\u03a6\u03a6"
    ]
  ]
}