{
  "name": "multi_thering_6_floor11",
  "refpalette": "deceasedcraft:multi_thering_6/multi_thering_6_floor11_palette",
  "xsize": 16,
  "zsize": 16,
  "slices": [
    [
      "aaaaaaaaaaaaaaab",
      "accccccccccccdda",
      "accccccccccccdda",
      "accccccccccccdda",
      "accccccccccccdda",
      "aaaaaaacaaaaaaaa",
      "accccaeeeeeeeeea",
      "accccaefeeeeeeea",
      "accccaeeeaaaeeea",
      "accccaacaggeeeea",
      "acccccccahgaeeea",
      "accccccca iaeeja",
      "acccccdda  a   a",
      "accccddda  a   a",
      "accccddda  a   a",
      "baaaaaaaaaaaaaaa"
    ],
    [
      "akkkkkkkkkkkkkkb",
      "klm         nopk",
      "k   qrs  t   uwk",
      "k xxyAB CD  EF k",
      "kIJJIrK CDLLMN k",
      "kaaaaaaOaaaaaaak",
      "kPQQPa        Rk",
      "k SS a        Rk",
      "k   ma   aaa   k",
      "k rrTaaUa V    k",
      "k WWW   a  aXYZk",
      "k0 C1 23a 4a55ak",
      "ky6789#$a ia   k",
      "k  %E^ &a  a   k",
      "kLLLM* !a  a   k",
      "bkkkkkkkkkkkkkka"
    ],
    [
      "akkkkkkkkkkkkkkb",
      "k !         n  k",
      "k    (       ) k",
      "k    (   +    -k",
      "k[  [(   ]%{} |k",
      "kaaaaaa;aaaaaaak",
      "k:  [a         k",
      "k    a'        k",
      "k   <a   aaa   k",
      "k (((aa>a ,    k",
      "k    .. a  a?/ k",
      "k     `3a  a  ak",
      "k  \u0370%\u0371  a 4a   k",
      "k       a\u0372ia   k",
      "k\u0373  \u0374  \u0375a  a   k",
      "bkkkkkkkkkkkkkka"
    ],
    [
      "akkkkkkkkkkkkkkb",
      "k           n  k",
      "k    (\u0376     n  k",
      "k    (\u0377     \u037a  k",
      "k    (\u037b     \u037c \u037dk",
      "kaaaaaagaaaaaaak",
      "k    a         k",
      "k    a\u037e        k",
      "k    a   aaa   k",
      "k (((aaga \u037f\u0384   k",
      "k \u0385\u0386\u0387   a  a\u0388\u0389 k",
      "k     33a  a\u038a\u038aak",
      "k    \u038c# a\u038e a   k",
      "k   \u037a   ag4a   k",
      "k   \u037c  \u038faiia   k",
      "bkkkkkkkkkkkkkka"
    ],
    [
      "akkkkkkkkkkkkkkb",
      "k           \u0390  k",
      "k           \u0390  k",
      "k           \u0390  k",
      "k     w     \u0390  k",
      "kaaaaaaaaaaaaaak",
      "k    a         k",
      "k    a         k",
      "k    a   aaa   k",
      "k    aaaa  a   k",
      "k \u0371     a  a   k",
      "k     \u0391\u0391a\u038e aaaak",
      "k    \u0391\u0392 ah a   k",
      "k    \u0392  a  a   k",
      "k    \u0392  a  a   k",
      "bkkkkkkkkkkkkkka"
    ],
    [
      "akkkkkkkkkkkkkkb",
      "k\u0393\u0393\u0393\u0393\u0393\u0393\u0393\u0393\u0393\u0393\u0393\u0393\u0394\u0394k",
      "k\u0393\u0393\u0393\u0393\u0393\u0393\u0393\u0393\u0393\u0393\u0393\u0393\u0394\u0394k",
      "k\u0393\u0393\u0393\u0393\u0393\u0393\u0393\u0393\u0393\u0393\u0393\u0393\u0394\u0394k",
      "k\u0393\u0393\u0393\u0393\u0393\u0393\u0393\u0393\u0393\u0393\u0393\u0393\u0394\u0394k",
      "kaaaaaaaaaaaaaak",
      "k\u0393\u0393\u0393\u0393a\u0395\u0395\u0395\u0395\u0395\u0395\u0395\u0395\u0395k",
      "k\u0393\u0393\u0393\u0393a\u0395\u0396\u0395\u0395\u0395\u0395\u0395\u0395\u0395k",
      "k\u0393\u0393\u0393\u0393a\u0395\u0395\u0395aaa\u0395\u0395\u0395k",
      "k\u0393\u0393\u0393\u0393aaaa  a\u0395\u0395\u0395k",
      "k\u0393\u0393\u0393\u0393\u0393\u0393\u0393a\u038e\u0372a\u0395\u0395\u0395k",
      "k\u0393\u0393\u0393\u0393\u0393\u0393\u0393ah aaaak",
      "k\u0393\u0393\u0393\u0393\u0394\u0394\u0394a  a   k",
      "k\u0393\u0393\u0393\u0393\u0394\u0394\u0394a  a   k",
      "k\u0393\u0393\u0393\u0393\u0394\u0394\u0394a  a   k",
      "bkkkkkkkkkkkkkka"
    ]
  ]
}