{
  "name": "multi_thering_6_floor23",
  "refpalette": "deceasedcraft:multi_thering_6/multi_thering_6_floor23_palette",
  "xsize": 16,
  "zsize": 16,
  "slices": [
    [
      "aaaaaaaaaaaaaaab",
      "acccccccccccccca",
      "acddddccccccccca",
      "acddddccccccccca",
      "acddddccccccccca",
      "acddddccccccccca",
      "acddddccccccccca",
      "acccccccccccccca",
      "aceeeecccaaaffaa",
      "aaccccacaggffffa",
      "acccccccahgafffa",
      "accccccca iaffja",
      "accccccca  a   a",
      "accccccca  a   a",
      "accccccca  a   a",
      "baaaaaaaaaaaaaaa"
    ],
    [
      "akkkkkkkkkkkkkkb",
      "kl mn  o       k",
      "kpqqqq r       k",
      "ksqttq  uwxyxA k",
      "ksqttq   BCDEF k",
      "ksqttq  uwIJIA k",
      "kKqqqq         k",
      "k LMMN         k",
      "kgiiiig OaaaPQak",
      "kaRSSTaUa V    k",
      "k WWW   a  aXYZk",
      "k       a 0a11ak",
      "k    2 3a ia   k",
      "k    456a  a   k",
      "k7898# $a  a   k",
      "bkkkkkkkkkkkkkka"
    ],
    [
      "akkkkkkkkkkkkkkb",
      "k%    o3       k",
      "k     r        k",
      "k        ^& ** k",
      "k         ( )& k",
      "k        ^& ** k",
      "k              k",
      "k +--[         k",
      "k]]]]]] {aaa}|ak",
      "ka ; :a'a <    k",
      "k       a  a>, k",
      "k       a  a  ak",
      "k      3a 0a   k",
      "k     . a?ia   k",
      "k/      a  a   k",
      "bkkkkkkkkkkkkkka"
    ],
    [
      "akkkkkkkkkkkkkkb",
      "k%   o3        k",
      "k    r         k",
      "k              k",
      "k              k",
      "k              k",
      "k              k",
      "k              k",
      "k]]]]]] `aaaggak",
      "ka\u0370\u0370\u0370\u0370aga \u0371\u0372   k",
      "k       a  a\u0373\u0373 k",
      "k       a  a\u0374\u0374ak",
      "k     33a\u0375 a   k",
      "k    \u0376  ag0a   k",
      "k    \u0377  aiia   k",
      "bkkkkkkkkkkkkkka"
    ],
    [
      "akkkkkkkkkkkkkkb",
      "k%  o3         k",
      "k   r          k",
      "k              k",
      "k              k",
      "k              k",
      "k              k",
      "k              k",
      "k]]]]]]  aaaaaak",
      "kaaaaaaaa  a  \u037ak",
      "k       a  a   k",
      "k       a\u0375 aaaak",
      "k     \u037b\u037bah a   k",
      "k    \u037c  a  a   k",
      "k    \u037c  a  a   k",
      "bkkkkkkkkkkkkkka"
    ],
    [
      "akkkkkkkkkkkkkkb",
      "k\u037d o3          k",
      "k  r           k",
      "k              k",
      "k              k",
      "k              k",
      "k              k",
      "k              k",
      "k]]]]]] \u037eaaaaaak",
      "kaaaaaaaa  a   k",
      "k\u037f\u0384\u0384\u0384\u0384\u0384\u0384a\u0375?a   k",
      "k\u037f\u0384\u0384\u0384\u0384\u0384\u0384ah aaaak",
      "k\u037f\u0384\u0384\u0384\u0384\u0384\u0384a  a   k",
      "k\u037f\u0384\u0384\u0384\u0384\u0384\u0384a  a   k",
      "k\u037f\u037f\u037f\u037f\u037f\u037f\u037fa  a   k",
      "bkkkkkkkkkkkkkka"
    ]
  ]
}