{
  "name": "multi_thering_6_floor10",
  "refpalette": "deceasedcraft:multi_thering_6/multi_thering_6_floor10_palette",
  "xsize": 16,
  "zsize": 16,
  "slices": [
    [
      "aaaaaaaaaaaaaaab",
      "accccccca      d",
      "accccccca      d",
      "accccccca      d",
      "accccccca      d",
      "accccccca      d",
      "accccccca      d",
      "accccccca      d",
      "accccccccaaa   d",
      "acccccccceea   d",
      "accccccfagea   d",
      "acccccc a haaaad",
      "accccccia  a   d",
      "accccccfa  a   d",
      "accccccca  a   d",
      "baaaaaaaadddddda"
    ],
    [
      "addddddddddddddb",
      "dj     ka      d",
      "dl mno pa      d",
      "dj mqo par     d",
      "ds mto pau     d",
      "dj mno wax     d",
      "dy ABA wa      d",
      "d      wa      d",
      "d  CCCAAAaaa   d",
      "d       D  a   d",
      "d  EF  Ia  a   d",
      "d  JK  La Maaaad",
      "d  NO Pia ha   d",
      "d  QR  Ia  a   d",
      "d       a  a   d",
      "bdddddddadddddda"
    ],
    [
      "addddddddddddddb",
      "d       a      d",
      "d  l S  a      d",
      "d  l S  aT     d",
      "d  U    aV     d",
      "d  W X YaZ     d",
      "d  0 s Ya      d",
      "d      Ya      d",
      "d  112  3aaa   d",
      "d       4  a   d",
      "d      Ia  a   d",
      "d  51  6a  aaaad",
      "d  17  8a Ma   d",
      "d  !  9Ia#ha   d",
      "d       a  a   d",
      "bdddddddadddddda"
    ],
    [
      "addddddddddddddb",
      "d       a      d",
      "d  $%^ &a      d",
      "d  $!^ *a(     d",
      "d  $%^  a)     d",
      "d  $%^  a+     d",
      "d       a      d",
      "d       a      d",
      "d       -aaa   d",
      "d       [] a   d",
      "d      Ia  a   d",
      "d     {}a  aaaad",
      "d     |;a: a   d",
      "d      IaeMa   d",
      "d       ahha   d",
      "bdddddddadddddda"
    ],
    [
      "addddddddddddddb",
      "d       a      d",
      "d   %   a      d",
      "d   %   a      d",
      "d   %   a      d",
      "d   %   a      d",
      "d       a      d",
      "d       a      d",
      "d      'aaaa   d",
      "d       a  a   d",
      "d      Ia  a   d",
      "d     <}a: aaaad",
      "d     >,ag a   d",
      "d      Ia  a   d",
      "d       a  a   d",
      "bdddddddadddddda"
    ],
    [
      "addddddddddddddb",
      "d.......a......d",
      "d.??%???a......d",
      "d.??%???a......d",
      "d.??%???a......d",
      "d.??%???a......d",
      "d.??????a......d",
      "d.??????a......d",
      "d.??????aaaa...d",
      "d.??????a  a...d",
      "d.?????fa:#a...d",
      "d.?????/ag aaaad",
      "d.?????`a  a   d",
      "d.?????fa  a   d",
      "d.......a  a   d",
      "bdddddddadddddda"
    ]
  ]
}