{
  "name": "multi_thering_6_floor14",
  "refpalette": "deceasedcraft:multi_thering_6/multi_thering_6_floor14_palette",
  "xsize": 16,
  "zsize": 16,
  "slices": [
    [
      "aaaaaaaaaaaaaaab",
      "acccccccccccccca",
      "acccccccccccccca",
      "acccccccccccccca",
      "acccccccccccccca",
      "acccccccccccccca",
      "acccccccccccccca",
      "accccccccc!cccca",
      "acccccccdaaaccca",
      "acccccccdddaccca",
      "acccccccdedaccca",
      "acccccccd faggha",
      "acccccccd  a   a",
      "acccccccd  a   a",
      "acccccccd  a   a",
      "baaaaaaaaaaaaaaa"
    ],
    [
      "aiiiiiiiiiiiiiib",
      "i              i",
      "ijklm    n o   i",
      "i      pqr s   i",
      "i ttt  pur s   i",
      "i      pur s   i",
      "ijwxy  pur s   i",
      "i       ABCs   i",
      "i       Daaa   i",
      "ijklm      a   i",
      "i       D  aEFIi",
      "i ttt   D JaKKaa",
      "i       D fa   L",
      "ijwxy   D  a   L",
      "i       D  a   L",
      "biiiiiiiaLLLLLLa"
    ],
    [
      "a              b",
      "                ",
      " M         N    ",
      "         O P    ",
      "         Q R    ",
      "           S    ",
      " T       U P    ",
      "         V W    ",
      "        Xaaa    ",
      " U         a    ",
      "        X  aYZ  ",
      "        X  a  aa",
      "        X Ja   L",
      "        X0fa   L",
      "        X  a   L",
      "b       aLLLLLLa"
    ],
    [
      "a              b",
      "                ",
      "                ",
      "           1    ",
      "                ",
      "           2    ",
      "           1    ",
      "           3    ",
      "        Xaaa    ",
      "           a    ",
      "        X  a44  ",
      "        X  a55aa",
      "        X6 a   L",
      "        XdJa   L",
      "        Xffa   L",
      "b       aLLLLLLa"
    ],
    [
      "a              b",
      "                ",
      "                ",
      "                ",
      "                ",
      "                ",
      "                ",
      "                ",
      "        7aaa    ",
      "        8  a    ",
      "        9  a    ",
      "        X6 aaaaa",
      "        Xe a   L",
      "        X  a   L",
      "        X  a   L",
      "b       aLLLLLLa"
    ],
    [
      "a              b",
      "                ",
      "                ",
      "                ",
      "                ",
      "                ",
      "                ",
      "                ",
      "        Xaaa    ",
      "        D  a    ",
      "        X60a    ",
      "        Xe aaaaa",
      "        X  a   L",
      "        X  a   L",
      "        X  a   L",
      "b       aLLLLLLa"
    ]
  ]
}