{
  "name": "multi_thering_6_floor6",
  "refpalette": "deceasedcraft:multi_thering_6/multi_thering_6_floor6_palette",
  "xsize": 16,
  "zsize": 16,
  "slices": [
    [
      "aaaaaaaaaaaaaaab",
      "acccccccccccccca",
      "acddddddcdddddca",
      "acddddddcdddddca",
      "acddddddcdddddca",
      "acddddddcdddddca",
      "acddddddcdddddca",
      "acddddddcdddddca",
      "accccccceaaaffca",
      "acddddddaggaffca",
      "acddddddahgaffca",
      "acdddddda iaaaaa",
      "acdddddda  a   a",
      "acdddddda  a   a",
      "accccccca  a   a",
      "baaaaaaaaaaaaaaa"
    ],
    [
      "               b",
      " jjjjjjjjjjjjjj ",
      " jjjjjjjjjjjjjj ",
      " jjjjjjjjjjjjjj ",
      " jjjjjjjjjjjjjj ",
      " jjjjjjjjjjjjjj ",
      " jjjjjjjjjjjjjj ",
      " jjjjjjjjjjjjjj ",
      " jjjjjjjkaaaffj ",
      " jjjjjjja  affj ",
      " jjjjjjja  affj ",
      " jjjjjjja laaaaa",
      " jjjjjjja ia   m",
      " jjjjjjja  a   m",
      " jjjjjjja  a   m",
      "b       ammmmmma"
    ],
    [
      "               b",
      "                ",
      "                ",
      "                ",
      "                ",
      "                ",
      "                ",
      "                ",
      "         aaann  ",
      "        a  ann  ",
      "        a  ann  ",
      "        a  aaaaa",
      "        a la   m",
      "        aoia   m",
      "        a  a   m",
      "b       ammmmmma"
    ],
    [
      "               b",
      "                ",
      "                ",
      "                ",
      "                ",
      "                ",
      "                ",
      "                ",
      "         aaa    ",
      "        a  a    ",
      "        a  a    ",
      "        a  aaaaa",
      "        ap a   m",
      "        agla   m",
      "        aiia   m",
      "b       ammmmmma"
    ],
    [
      " qrrrrrrrrrrrrrb",
      "qrrrrrrrrrrrrrrr",
      "rrrrrrrrrrrrrrqq",
      "rrrrrrrrrrrrrq  ",
      "rrrrrrrrrrrqq   ",
      "rrrrrrrrrrq     ",
      "rrrrrrrrrq      ",
      "rrrrrrrrq       ",
      "rrrrrrrq aaa    ",
      "rrrrrrq a  a    ",
      "rrrrrq  a  a    ",
      "rrrrq   ap aaaaa",
      "rrrrq   ah a   m",
      "rrrq    a  a   m",
      "rrq     a  a   m",
      "brq     ammmmmma"
    ],
    [
      "rrrrssssstttstsb",
      "rrrsssststttssss",
      "rrsssststtsssuww",
      "rssssstttsssu   ",
      "ssssstttssuw    ",
      "ssstttsssu      ",
      "ssstttssu       ",
      "tstttssu        ",
      "stttssu  aaa    ",
      "ststsu  a  a    ",
      "tttsu   apoa    ",
      "tsssx   ah aaaaa",
      "tssu    a  a   m",
      "ssu     a  a   m",
      "ssx     a  a   m",
      "bsx     ammmmmma"
    ]
  ]
}