{
  "name": "multi_thering_6_base2",
  "refpalette": "deceasedcraft:multi_thering_6/multi_thering_6_base2_palette",
  "xsize": 16,
  "zsize": 16,
  "slices": [
    [
      "aaaaaaaaaaaaaaab",
      "aaaaaaaaaaaaaaaa",
      "aaaaaaaaaaaaaaaa",
      "aaaaaaaaaaaaaaaa",
      "aaaaaaaaaaaaaaaa",
      "aaaaaaaaaaaaaaaa",
      "aaaaaaaaaaaaaaaa",
      "aaaaaaaaaaaaaaaa",
      "aaaaaaaaaaaaaaaa",
      "aaaaaaaaaaaaaaaa",
      "aaaaaaaaaaaaaaaa",
      "aaaaaaaaaaaaaaaa",
      "aaaaaaaaaaaaaaaa",
      "aaaaaaaaaaaaaaaa",
      "aaaaaaaaaaaaaaaa",
      "baaaaaaaaaaaaaaa"
    ],
    [
      "aaaaaaaaaaaaaaab",
      "aaaaaaaaaaaaaaaa",
      "aaaaaaaaaaaaaaaa",
      "aaaaaaaaaaaaaaaa",
      "aaaaaaaaaaaaaaaa",
      "aaaaaaaaaaaaaaaa",
      "aaaaaaaaaaaaaaaa",
      "aaaaaaaaaaaaaaaa",
      "aaaaaaaaaaaaaaaa",
      "aaaaaaaaaaaaaaaa",
      "aaaaaaaaaaaaaaaa",
      "aaaaaaaaaaaaaaaa",
      "aaaaaaaaaaaaaaaa",
      "aaaaaaaaaaaaaaaa",
      "aaaaaaaaaaaaaaaa",
      "baaaaaaaaaaaaaaa"
    ],
    [
      "cccccccccccccccb",
      "cccccccccccccccc",
      "cccccccccccccccc",
      "cccccccccccccccc",
      "cccccccccccccccc",
      "cccccccccccccccc",
      "cccccccccccccccc",
      "cccccccccccccccc",
      "cccccccccccccccc",
      "cccccccccccccccc",
      "cccccccccccccccc",
      "cccccccccccccccc",
      "cccccccccccccccc",
      "cccccccccccccccc",
      "cccccccccccccccc",
      "bccccccccccccccc"
    ],
    [
      "deeffffffffffeed",
      "deeeeeeeeeeeeeed",
      "deeeeeeeeeeeeeed",
      "degggeeeeeeeeeed",
      "degggeeeeeeeeeed",
      "degggeeefffeeeeh",
      "degggeeefifeeeeh",
      "degggeeefffeeeeh",
      "d!gggeeeeeeeeeed",
      "degggeeeeeeeeeed",
      "deeeeeeeeeeeeeed",
      "deeeeeeeeejdkkld",
      "deeeeeeeeejd   d",
      "dfffeeeeeejd   d",
      "dfffeeeeeejd   d",
      "dddddhhhdddddddd"
    ],
    [
      "d  mmmmmmmmmm  n",
      "d              o",
      "d              o",
      "d ppp          o",
      "dqppp          r",
      "dsptp   uuu     ",
      "dsptp   uwu     ",
      "dsptp   uuu     ",
      "dxppp          r",
      "d ppp          o",
      "dy A        BCDo",
      "d       E FdIIdo",
      "dJKLM   E jd   o",
      "dNNNM   E jd   o",
      "dOOOM   E jd   o",
      "nooor   rooooood"
    ],
    [
      "d PQRRRRRRRRST n",
      "d  UUUVVVWVWW  o",
      "d              o",
      "d              o",
      "d              r",
      "d               ",
      "d               ",
      "d               ",
      "d              r",
      "d              o",
      "dX          YZ o",
      "d       E  d  do",
      "d0001   E Fd   o",
      "dNNN1   E jd   o",
      "d   1   E jd   o",
      "nooor   rooooood"
    ]
  ]
}