{
  "name": "multi_thering_6_floor25",
  "refpalette": "deceasedcraft:multi_thering_6/multi_thering_6_floor25_palette",
  "xsize": 16,
  "zsize": 16,
  "slices": [
    [
      "abbbbbbbbbbbbbbc",
      "a              b",
      "a              b",
      "a              b",
      "a      de      b",
      "a              b",
      "a f            b",
      "agh            b",
      "aiiiiiiiiaaaaaab",
      "aiiiiijjakka   b",
      "aiiiiijjalka   b",
      "aiiiiijja maaaab",
      "aiiiiijja  a   b",
      "aiiiiijja  a   b",
      "a   nijja  a   b",
      "caaaaaaaaaaaaaaa"
    ],
    [
      "abbbbbbbbbbbbbbc",
      "b              b",
      "b              b",
      "b              b",
      "b      eed     b",
      "b       d      b",
      "b              b",
      "b f            b",
      "bopqpqpqraaaaaab",
      "b    stua  a   b",
      "bwwwws xa  a   b",
      "bwyyw ABa Caaaab",
      "bwDDw EBa ma   b",
      "bFIIFs  a  a   b",
      "bJJJJsKLa  a   b",
      "cbbbbbbbbbbbbbba"
    ],
    [
      "abbbbbbbbbbbbbbc",
      "b              b",
      "b              b",
      "b              b",
      "b     deeed    b",
      "b      ded     b",
      "b              b",
      "b MM  MM       b",
      "b NO PQQRaaaaaab",
      "b    s  a  a   b",
      "b    s  a  a   b",
      "b     S a  aaaab",
      "b     T a Ca   b",
      "bU  Us VaWma   b",
      "b    s  a  a   b",
      "cbbbbbbbbbbbbbba"
    ],
    [
      "abbbbbbbbbbbbbbc",
      "b              b",
      "b              b",
      "b              b",
      "b   XdeeeeeX   b",
      "b   XddeeedX   b",
      "b              b",
      "b MM MMM       b",
      "b     QQYaaaaaab",
      "b    s  a  a   b",
      "b    s  a  a   b",
      "b    s Za  aaaab",
      "b    s 0a1 a   b",
      "b    s 2akCa   b",
      "b    s  amma   b",
      "cbbbbbbbbbbbbbba"
    ],
    [
      "abbbbbbbbbbbbbbc",
      "b              b",
      "b              b",
      "b              b",
      "b   33333333   b",
      "b   33333333   b",
      "b              b",
      "b 445444       b",
      "b     44 aaaaaab",
      "b    6  a  a   b",
      "b    6  a  a   b",
      "b    6  a1 aaaab",
      "b    6  al a   b",
      "b    6  a  a   b",
      "b    6  a  a   b",
      "cbbbbbbbbbbbbbba"
    ],
    [
      "abbbbbbbbbbbbbbc",
      "b77777777777777b",
      "b78888888888887b",
      "b789########987b",
      "b78#$$$$$$$$#87b",
      "b78#$$$$$$$$#87b",
      "b789########987b",
      "b78888888888887b",
      "b78888888aaaaaab",
      "b7888888a  a%%%b",
      "b7888888a1Wa%%%b",
      "b7888888al aaaab",
      "b7888888a  a   b",
      "b7888888a  a   b",
      "b7777^88a  a   b",
      "cbbbbbbbbbbbbbba"
    ]
  ]
}