{
  "name": "multi_thering_6_floor21",
  "refpalette": "deceasedcraft:multi_thering_6/multi_thering_6_floor21_palette",
  "xsize": 16,
  "zsize": 16,
  "slices": [
    [
      "aaaaaaaaaaaaaaab",
      "acccccccccccccca",
      "acccccccccccccca",
      "acccccccccccccca",
      "acccccccccccccca",
      "acccccccccccccca",
      "acccccccccccccca",
      "acccccccccccccca",
      "aaaaacaaaaaaddaa",
      "accccceeaffdddda",
      "accccceeagfaddda",
      "accccceea haddia",
      "accccceea  ajjka",
      "accccceea  ajlja",
      "accccceea  ajjja",
      "baaaaaaaaaaaaaaa"
    ],
    [
      "ammmmmmmmmmmmmmb",
      "mnop          qm",
      "mrsss      t  qm",
      "mussw xyA BC DEm",
      "mussF xIA BC  Cm",
      "mussJ xKA BC  Lm",
      "mMsss   N  O  Cm",
      "mnPQ    R     Sm",
      "m!aaaTaafaaaUVam",
      "mpW  XYZa 0    m",
      "m    X 1a  a234m",
      "mssss 56a 7a88am",
      "ms99s #6a ha $%m",
      "ms^^sX  a  a   m",
      "m&**&X()a  a+  m",
      "bmmmmmmmmmmmmmma"
    ],
    [
      "ammmmmmmmmmmmmmb",
      "m-            [m",
      "m]            {m",
      "m          }  !m",
      "m|         ;  :m",
      "m              m",
      "m      N'     <m",
      "m->,   R      .m",
      "maaaa?af/aaa`\u0370am",
      "m \u0371 \u0372X  a \u0373    m",
      "m    X  a  a\u0374\u0375 m",
      "m     \u0376 a  a  am",
      "m     \u0377 a 7a $\u037am",
      "m    X \u037ba\u037cha   m",
      "m\u037d  \u037eX  a  a\u037f  m",
      "bmmmmmmmmmmmmmma"
    ],
    [
      "ammmmmmmmmmmmmmb",
      "m\u0384             m",
      "m              m",
      "m              m",
      "m              m",
      "m              m",
      "m     N'       m",
      "m\u0384    R        m",
      "maaaaaf//aaaffam",
      "m    X\u0385\u0386a \u0387\u0388   m",
      "m    X  a  a\u0389\u0389 m",
      "m    X \u038aa  a\u038c\u038cam",
      "m    X \u038ea\u038f a $\u037am",
      "m    X \u0390af7a   m",
      "m    X  ahha\u037f  m",
      "bmmmmmmmmmmmmmma"
    ],
    [
      "ammmmmmmmmmmmmmb",
      "m              m",
      "m              m",
      "m              m",
      "m              m",
      "m              m",
      "m    N'        m",
      "m    R         m",
      "maaaaf///aaaaaam",
      "m    \u0391\u0392\u0393a  a  \u0394m",
      "m    \u0391  a  a   m",
      "m    \u0391  a\u038f aaaam",
      "m    \u0391  ag a $\u037am",
      "m    \u0391  a  a   m",
      "m    \u0391  a  a\u0395  m",
      "bmmmmmmmmmmmmmma"
    ],
    [
      "ammmmmmmmmmmmmmb",
      "m              m",
      "m              m",
      "m              m",
      "m              m",
      "m              m",
      "m   N'         m",
      "m   R          m",
      "maaaf////aaaaaam",
      "m\u0396\u0397\u0397\u0397\u0397\u0397\u0397a  a   m",
      "m\u0396\u0397\u0397\u0397\u0397\u0397\u0397a\u038f\u037ca   m",
      "m\u0396\u0397\u0397\u0397\u0397\u0397\u0397ag aaaam",
      "m\u0396\u0397\u0397\u0397\u0397\u0397\u0397a  a\u0398\u0398\u0399m",
      "m\u0396\u0397\u0397\u0397\u0397\u0397\u0397a  a\u0399\u0399\u0399m",
      "m\u0396\u0396\u0396\u0396\u039a\u0397\u0397a  a\u0399\u0399\u0399m",
      "bmmmmmmmmmmmmmma"
    ]
  ]
}