{
  "name": "multi_thering_6_floor1",
  "refpalette": "deceasedcraft:multi_thering_6/multi_thering_6_floor1_palette",
  "xsize": 16,
  "zsize": 16,
  "slices": [
    [
      "            aaab",
      "         aaa   a",
      "       aa      a",
      "      a        a",
      "     a         a",
      "    a          a",
      "   a           a",
      "  a    c       a",
      "  a    cdeee   a",
      " a      effe   a",
      " a      egfe   a",
      " a      e heeeea",
      "a       e  e   a",
      "a       e  e   a",
      "a       e  e   a",
      "baaaaaaaaaaaaaae"
    ],
    [
      "            aaab",
      "         aaa   a",
      "       aa      a",
      "      a        a",
      "     a         a",
      "    a          a",
      "   a           a",
      "  a    cd      a",
      "  a    cceee   a",
      " a      e  e   a",
      " a      e  e   a",
      " a      e ieeeea",
      "a       e he   a",
      "a       e  e   a",
      "a       e  e   a",
      "baaaaaaaaaaaaaae"
    ],
    [
      "            aaab",
      "         aaa   a",
      "       aa      a",
      "      a        a",
      "     a         a",
      "    a          a",
      "   a           a",
      "  a    cc      a",
      "  a    cceee   a",
      " a      e  e   a",
      " a      e  e   a",
      " a      e  eeeea",
      "a       e ie   a",
      "a       ejhe   a",
      "a       e  e   a",
      "baaaaaaaaaaaaaae"
    ],
    [
      "            aaab",
      "         aaa   a",
      "       aa      a",
      "      a        a",
      "     a         a",
      "    a          a",
      "   a           a",
      "  a    kk      a",
      "  a    kkeee   a",
      " a      e  e   a",
      " a      e  e   a",
      " a      e  eeeea",
      "a       el e   a",
      "a       efie   a",
      "a       ehhe   a",
      "baaaaaaaaaaaaaae"
    ],
    [
      "            aaab",
      "         aaa   a",
      "       aa      a",
      "      a        a",
      "     ammmm     a",
      "    amnnnnm    a",
      "   amnnoonnm   a",
      "  a mnopponm   a",
      "  a mnoppeee   a",
      " a  mnnoe  e   a",
      " a   mnne  e   a",
      " a    mmel eeeea",
      "a       eg e   a",
      "a       e  e   a",
      "a       e  e   a",
      "baaaaaaaaaaaaaae"
    ],
    [
      "qqqqqqqqqqqqrrrb",
      "qqqqqqqqqrrrrrqa",
      "qqqqqqqrrrrrrrqa",
      "qqqqqqrrrrrrrrqa",
      "qqqqqrrrrrrrrrqa",
      "qqqqrrrrrrrrrrqa",
      "qqqrrrrrrrrrrrqa",
      "qqrrrrrrrrrrrrqa",
      "qqrrrrrrreeerrqa",
      "qrrrrrrre  errqa",
      "qrrrrrrreljerrqa",
      "qrrrrrrreg eeeea",
      "rrrrrrrre  e   a",
      "rrrrrrrre  e   a",
      "rqqqqqqqe  e   a",
      "baaaaaaaaaaaaaae"
    ]
  ]
}