{
  "name": "multi_thering_6_floor24",
  "refpalette": "deceasedcraft:multi_thering_6/multi_thering_6_floor24_palette",
  "xsize": 16,
  "zsize": 16,
  "slices": [
    [
      "abbbbbbbbbbbbbbc",
      "adef           b",
      "a g            b",
      "a              b",
      "a              b",
      "a              b",
      "a              b",
      "a              b",
      "ahhhhhhhhaaaaaab",
      "ahhhhhaaaiia   b",
      "ahhhhhaaajia   b",
      "ahhhhhaaa kaaaab",
      "ahhhhhaaa  a   b",
      "ahhhhhaaa  a   b",
      "ahhhhhaaa  a   b",
      "caaaaaaaaaaaaaaa"
    ],
    [
      "abbbbbbbbbbbbbbc",
      "b f            b",
      "blm            b",
      "b              b",
      "b              b",
      "b              b",
      "b              b",
      "bffffffff      b",
      "bn     nnaaaaaab",
      "b    oapa  a   b",
      "b    qara  a   b",
      "blm sqara taaaab",
      "b    qara ka   b",
      "b    qaua  a   b",
      "bwxxyAaaa  a   b",
      "cbbbbbbbbbbbbbba"
    ],
    [
      "abbbbbbbbbbbbbbc",
      "b              b",
      "b B            b",
      "blm            b",
      "b              b",
      "b              b",
      "b              b",
      "b         CDEF b",
      "bn n  nnnaaaaaab",
      "b    IaJa  a   b",
      "b    Ka a  a   b",
      "b B  La a  aaaab",
      "blm  Ma a ta   b",
      "b    !aNaOka   b",
      "b PQRSaaa  a   b",
      "cbbbbbbbbbbbbbba"
    ],
    [
      "abbbbbbbbbbbbbbc",
      "b              b",
      "b              b",
      "b B            b",
      "blm            b",
      "b              b",
      "b              b",
      "b         TUVW b",
      "bnnnn nnnaaaaaab",
      "b    Xaaa  a   b",
      "b    YaZa  a   b",
      "b    Ya a  aaaab",
      "b B  Ya a0 a   b",
      "blm  Ya1aita   b",
      "b2   3aaakka   b",
      "cbbbbbbbbbbbbbba"
    ],
    [
      "abbbbbbbbbbbbbbc",
      "b              b",
      "b              b",
      "b              b",
      "b B            b",
      "blm            b",
      "b              b",
      "b         4567 b",
      "bnnnnnnnnaaaaaab",
      "b    8aaa  a   b",
      "b    9a a  a   b",
      "b    8a a0 aaaab",
      "b    9a aj a   b",
      "b B  8a a  a   b",
      "b #  9aaa  a   b",
      "cbbbbbbbbbbbbbba"
    ],
    [
      "abbbbbbbbbbbbbbc",
      "b              b",
      "b              b",
      "b              b",
      "b       $      b",
      "b B            b",
      "blm            b",
      "b         %^&* b",
      "b((((((((aaaaaab",
      "b     aaa  a   b",
      "b     a)a0Oa   b",
      "b  +  a)aj aaaab",
      "b     a)a  a   b",
      "b     a-a  a   b",
      "b  #  aaa  a   b",
      "cbbbbbbbbbbbbbba"
    ]
  ]
}