{
  "name": "multi_thering_6_floor3",
  "refpalette": "deceasedcraft:multi_thering_6/multi_thering_6_floor3_palette",
  "xsize": 16,
  "zsize": 16,
  "slices": [
    [
      "aaaaaaaaaaaaaaab",
      "accccaccccccccca",
      "acccca!cccccccca",
      "accccacccdddccca",
      "accdddaccdddccca",
      "accdddacaaaaaaaa",
      "accccaeeeeeeeeea",
      "acccccefeeeeeeea",
      "accccaeeeaaaeeea",
      "aaaaaaacaggeeeea",
      "acccddccahgaeeea",
      "acccddcca iaeeja",
      "acccddcca  a   a",
      "accccccca  a   a",
      "accccccca  a   a",
      "baaaaaaaaaaaaaaa"
    ],
    [
      "akkkkkkkkkkkkkkb",
      "kl  man       lk",
      "k  opaq  r r   k",
      "k  rras t uwxy k",
      "k  A Ba CD ExFIk",
      "k J KLaMaaaaaaak",
      "k  NOa        Pk",
      "k    Q        Pk",
      "kRSTUa   aaa   k",
      "kaaaaaaVa W    k",
      "kXYJZ0n a  a123k",
      "k 4J 5q a 6a77ak",
      "k   8Bs9a ia   k",
      "k   NOR a  a   k",
      "kl      a  a   k",
      "bkkkkkkkkkkkkkka"
    ],
    [
      "akkkkkkkkkkkkkkb",
      "k#  $a        %k",
      "k    a   r r   k",
      "k  rra  ^&* x  k",
      "k  () a + - x $k",
      "k J-  a[aaaaaaak",
      "k  ]{a         k",
      "k    }         k",
      "kR99 a   aaa   k",
      "kaaaaaa|a ;    k",
      "k$ J: ' a  a<> k",
      "k  J&   a  a  ak",
      "k   ,   a 6a   k",
      "k   ]{R a.ia   k",
      "k?      a  a   k",
      "bkkkkkkkkkkkkkka"
    ],
    [
      "akkkkkkkkkkkkkkb",
      "k    a/        k",
      "k    a`  rrr   k",
      "k  rra\u0370 \u0371   x  k",
      "k J   a \u0372 \u0373 x  k",
      "k J\u0373  agaaaaaaak",
      "k  \u0374\u0375a         k",
      "k    g    \u0376    k",
      "kR\u0377\u037a\u037ba   aaa   k",
      "kaaaaaaga \u037c\u037d   k",
      "k  J\u037e \u037f a  a\u0384\u0384 k",
      "k  J  \u0385 a  a\u0386\u0386ak",
      "k  J  \u0387 a\u0388 a   k",
      "k   \u0374\u0375R ag6a   k",
      "k       aiia   k",
      "bkkkkkkkkkkkkkka"
    ],
    [
      "akkkkkkkkkkkkkkb",
      "k    a         k",
      "k    a'  \u0389\u0389\u0389   k",
      "k  \u0389\u0389a' \u038a\u038c\u038c\u038c\u038e  k",
      "k \u038a\u038c\u038c\u038ca \u038a\u038c\u038c\u038c\u038e  k",
      "k \u038a\u038c\u038c\u038caaaaaaaaak",
      "k  \u038f\u038fa         k",
      "k    a         k",
      "k    a   aaa   k",
      "kaaaaaaaa  a   k",
      "k  \u038a\u038c\u038c\u038e a  a   k",
      "k  \u038a\u038c\u038c\u038e a\u0388 aaaak",
      "k  \u038a\u038c\u038c\u038e ah a   k",
      "k   \u038f\u038f! a  a   k",
      "k       a  a   k",
      "bkkkkkkkkkkkkkka"
    ],
    [
      "akkkkkkkkkkkkkkb",
      "k\u0390\u0390\u0390\u0390a\u0390\u0390\u0390\u0390\u0390\u0390\u0390\u0390\u0390k",
      "k\u0390\u038c\u038c\u038ca\u038c\u038c\u038c\u038c\u038c\u038c\u038c\u038c\u0390k",
      "k\u0390\u038c\u038c\u038ca\u038c\u038c\u038c   \u038c\u038c\u0390k",
      "k\u0390\u038c  \u0391a\u038c\u038c\u0391\u0391 \u038c\u038c\u0390k",
      "k\u0390\u038c  \u0391aaaaaaaaak",
      "k\u0390\u038c\u038c\u038ca\u0392\u0392\u0392\u0392\u0392\u0392\u0392\u0392\u0392k",
      "k\u0390\u038c\u038c\u038ca\u0392\u0393\u0392\u0392\u0392\u0392\u0392\u0392\u0392k",
      "k\u0390\u038c\u038c\u038ca\u0392\u0392\u0392aaa\u0392\u0392\u0392k",
      "kaaaaaaaa  a\u0392\u0392\u0392k",
      "k\u0390\u038c\u038c\u0391\u0391\u038c\u038ca\u0388.a\u0392\u0392\u0392k",
      "k\u0390\u038c\u038c  \u038c\u038cah aaaak",
      "k\u0390\u038c\u038c  \u038c\u038ca  a   k",
      "k\u0390\u038c\u038c\u038c\u038c\u038c\u038ca  a   k",
      "k\u0390\u0390\u0390\u0390\u0390\u0390\u0390a  a   k",
      "bkkkkkkkkkkkkkka"
    ]
  ]
}