{
  "name": "multi_oasiscondo_8_floor11",
  "refpalette": "deceasedcraft:multi_oasiscondo_8/multi_oasiscondo_8_floor11_palette",
  "xsize": 16,
  "zsize": 16,
  "slices": [
    [
      "                ",
      "                ",
      "                ",
      "                ",
      "                ",
      "                ",
      "                ",
      "                ",
      "                ",
      "aaab baaaaaab ba",
      "aaaacaaaaaaaacdd",
      "aaaacaaaaaaaacde",
      "aaaacaaaaaaaacde",
      "aaaacaaaaaaaacdd",
      "aaaacaaaaaaaacdd",
      "ffggcggffffggchh"
    ],
    [
      "                ",
      "                ",
      "                ",
      "                ",
      "                ",
      "                ",
      "                ",
      "              ij",
      "gkgl lggggkgl ii",
      "mmnk go  p og iq",
      "    cr      sc t",
      " u wcr x  y scA ",
      " u Bcr x  y scC ",
      " u Dcr x  y EcAF",
      "    cr      sc A",
      "IJggcggJKIJggc  "
    ],
    [
      "                ",
      "                ",
      "                ",
      "                ",
      "                ",
      "                ",
      "                ",
      "              iL",
      "MMgl lkMMMMgN ii",
      " OPg g      g i ",
      "    cQ      Ec  ",
      "    cR      sc  ",
      "    cR      scS ",
      "    cR      sc  ",
      "    cT      Ec A",
      "UJggcggJVUJggc  "
    ],
    [
      "                ",
      "                ",
      "                ",
      "                ",
      "                ",
      "                ",
      "                ",
      "              i ",
      "MMgN lkMMMMgl ii",
      "   g g      k i ",
      "    c        c  ",
      "    c       Wc  ",
      "    c        cA ",
      "    c        c  ",
      "    c        c  ",
      "JJggcggJJJJggc  "
    ],
    [
      "                ",
      "                ",
      "                ",
      "                ",
      "                ",
      "                ",
      "                ",
      "              i ",
      "MMgl NgMMMMgN ii",
      "   k g      g i ",
      "    c        c  ",
      "    c        c  ",
      "    c        cA ",
      "    c        c  ",
      "    c        c  ",
      "ggggcggggggggc  "
    ],
    [
      "                ",
      "                ",
      "                ",
      "                ",
      "                ",
      "                ",
      "                ",
      "              ii",
      "kkgl Nkgggggl ii",
      "XXXg kXXXXXXg ii",
      "XXXXcXXXXXXXXcYY",
      "XXXXcXXXXXXXXcYY",
      "XXXXcXXXXXXXXcYY",
      "XXXXcXXXXXXXXcYY",
      "XXXXcXXXXXXXXcYY",
      "ggggcggggggggcYY"
    ]
  ]
}