{
  "name": "multi_oasiscondo_8_floor6",
  "refpalette": "deceasedcraft:multi_oasiscondo_8/multi_oasiscondo_8_floor6_palette",
  "xsize": 16,
  "zsize": 16,
  "slices": [
    [
      "                ",
      "                ",
      "                ",
      "                ",
      "                ",
      "                ",
      "                ",
      "                ",
      "                ",
      "aaaaaaaaaaaab ba",
      "aaaaaaaaaaaaacaa",
      "aaaaaaaaaaaaacaa",
      "aaaaaaaaaaaaacaa",
      "aaaaaaaaaaaaacaa",
      "aaaaaaaaaaaaacaa",
      "ddddddddeedddcdd"
    ],
    [
      "                ",
      "                ",
      "                ",
      "                ",
      "                ",
      "                ",
      "                ",
      "                ",
      "fddfdfddffddg gd",
      "hijiklmnop qr ds",
      "t u kwxyAB  CcD ",
      "h   kDEFAI  JcD ",
      "K   LM  NO  Pcw ",
      "QQQQQR FST  UcV ",
      "           WUcw ",
      "ddddddddXYdddcdd"
    ],
    [
      "                ",
      "                ",
      "                ",
      "                ",
      "                ",
      "                ",
      "                ",
      "                ",
      "ZZZZ0ZZZZZZd1 gd",
      "h2 2ky  y3 4f d5",
      "6   kE       c7 ",
      "h   k!      8c9 ",
      "#   L$  %   ^c& ",
      "QQQQQ*       c  ",
      "             c( ",
      "dddddddd)+dddcdd"
    ],
    [
      "                ",
      "                ",
      "                ",
      "                ",
      "                ",
      "                ",
      "                ",
      "                ",
      "ZZZZ0ZZZZZZfg gd",
      "h   k-     4d d[",
      "]   k{       c} ",
      "h   k-       c} ",
      "|   k{       c{ ",
      "QQQQQ*      ;c{ ",
      "            ;c{ ",
      "dddddddd::dddcdd"
    ],
    [
      "                ",
      "                ",
      "                ",
      "                ",
      "                ",
      "                ",
      "                ",
      "                ",
      "ZZZZ0ZZZZZZd' gd",
      "h   k      4d d ",
      "h   k<      ;c  ",
      "h > k  ,  > ;c  ",
      "h   k.       c? ",
      "QQQQQ/       c. ",
      "             c  ",
      "dddddddddddddcdd"
    ],
    [
      "                ",
      "                ",
      "                ",
      "                ",
      "                ",
      "                ",
      "                ",
      "                ",
      "ddd`ffddfddd' 'd",
      "\u0370\u0370\u0370\u0370\u0370\u0370\u0370\u0370\u0370\u0370\u0370\u0370d d\u0370",
      "\u0370\u0370\u0370\u0370\u0370\u0370\u0370\u0370\u0370\u0370\u0370\u0370\u0370c\u0370\u0370",
      "\u0370\u0370\u0370\u0370\u0370\u0370\u0370\u0370\u0370\u0370\u0370\u0370\u0370c\u0370\u0370",
      "\u0370\u0370\u0370\u0370\u0370\u0370\u0370\u0370\u0370\u0370\u0370\u0370\u0370c\u0370\u0370",
      "\u0370\u0370\u0370\u0370\u0370\u0370\u0370\u0370\u0370\u0370\u0370\u0370\u0370c\u0370\u0370",
      "\u0370\u0370\u0370\u0370\u0370\u0370\u0370\u0370\u0370\u0370\u0370\u0370\u0370c\u0370\u0370",
      "dddddddddddddcdd"
    ]
  ]
}