{
  "name": "multi_oasiscondo_8_base3",
  "refpalette": "deceasedcraft:multi_oasiscondo_8/multi_oasiscondo_8_base3_palette",
  "xsize": 16,
  "zsize": 16,
  "slices": [
    [
      "vvvvvvvvvvvvvvvv",
      "                ",
      "                ",
      "                ",
      "                ",
      "                ",
      "                ",
      "                ",
      "                ",
      "                ",
      "    a        a  ",
      "                ",
      "                ",
      "                ",
      "                ",
      "                "
    ],
    [
      "vvvvvvvvvvvvvvvv",
      "                ",
      "                ",
      "                ",
      "                ",
      "                ",
      "                ",
      "                ",
      "                ",
      "                ",
      "    a        a  ",
      "                ",
      "                ",
      "                ",
      "                ",
      "                "
    ],
    [
      "vvvvvvvvvvvvvvvv",
      "                ",
      "                ",
      "                ",
      "                ",
      "                ",
      "                ",
      "                ",
      "                ",
      "                ",
      "    a        a  ",
      "                ",
      "                ",
      "                ",
      "                ",
      "                "
    ],
    [
      "vvvvvvvvvvvvvvvv",
      "                ",
      "                ",
      "                ",
      "                ",
      "                ",
      "                ",
      "                ",
      "                ",
      "                ",
      "    a        a  ",
      "                ",
      "                ",
      "                ",
      "                ",
      "                "
    ],
    [
      "vvvvvvvvvvvvvvvv",
      "                ",
      "                ",
      "                ",
      "                ",
      "                ",
      "                ",
      "                ",
      "                ",
      "                ",
      "    a        a  ",
      "                ",
      "                ",
      "                ",
      "                ",
      "                "
    ],
    [
      "vvvvvvvvvvvvvvvv",
      "bbbbcbbbbbbbbcbb",
      "bbbbcbbbbbbbbcbb",
      "bbbbcbbbbbbbbcbb",
      "bbbbcbbbbbbbbcbb",
      "bbbbcbbbbbbbbcbb",
      "bbbbcbbbbbbbbcbb",
      "bbbbcbbbbbbbbcbb",
      "bbbbcbbbbbbbbcbb",
      "bbbbcbbbbbbbbcbb",
      "ccccdccccccccdcc",
      "bbbbcbbbbbbbbcbb",
      "bbbbcbbbbbbbbcbb",
      "bbbbcbbbbbbbbcbb",
      "bbbbcbbbbbbbbcbb",
      "bbbbcbbbbbbbbcbb"
    ]
  ]
}