{
  "name": "multi_oasiscondo_8_ground",
  "refpalette": "deceasedcraft:multi_oasiscondo_8/multi_oasiscondo_8_ground_palette",
  "xsize": 16,
  "zsize": 16,
  "slices": [
    [
      "aaaaaaaaaaaaaaab",
      "aaaaaaaaaaaaaaab",
      "aaaaaaaaaaaaacab",
      "bbbbbbaaaaaaaaab",
      "dddddbaaaaaaaaab",
      "bbbbbbaaaaaaaaab",
      "aaaaaaaaaaaaacab",
      "aaaaaaaaaaaaaaab",
      "aaaaaaaaaaaeaaae",
      "bbbbbbbbbbbbebef",
      "gggbhbggggggghff",
      "ggggggiiiiiighff",
      "ggggggiii!iighfj",
      "ggggggiiiiiighfj",
      "ggggggiiiiiighfj",
      "ggggggiiiiiighfj"
    ],
    [
      "                ",
      "                ",
      "             k  ",
      "lllllm       n  ",
      "oooool       n  ",
      "lllllm       n  ",
      "             k  ",
      "                ",
      "           ep pe",
      "qlrrsrrrrrrrese ",
      "t  rhruwxxyu h  ",
      "    A        h  ",
      "        BB  Ch  ",
      "            Dh  ",
      "            Eh  ",
      "            uh  "
    ],
    [
      "                ",
      "                ",
      "             F  ",
      "                ",
      "                ",
      "                ",
      "             F  ",
      "                ",
      "           ep pe",
      " lrr rrrrrrre e ",
      "I  rhr     J h  ",
      "    K        h  ",
      "             h  ",
      "             h  ",
      "             h  ",
      "             h  "
    ],
    [
      "                ",
      "                ",
      "             L  ",
      "                ",
      "                ",
      "                ",
      "             L  ",
      "                ",
      "           ep pe",
      "Mlrr rrrrrrre e ",
      "N  rhr       h  ",
      "    O        h  ",
      "             h  ",
      "             h  ",
      "             h  ",
      "             h  "
    ],
    [
      "                ",
      "                ",
      "             L  ",
      "                ",
      "                ",
      "                ",
      "             L  ",
      "                ",
      "           ep pe",
      "llrr rrrrrrre e ",
      "   rhr       h  ",
      "             h  ",
      "            Ph  ",
      "            Qh  ",
      "            Rh  ",
      "             h  "
    ],
    [
      "                ",
      "                ",
      "             S  ",
      "                ",
      "                ",
      "                ",
      "             S  ",
      "                ",
      "           ep pe",
      "rrrr rrrrrrre e ",
      "   rhr       h  ",
      "             h  ",
      "            Th  ",
      "            Uh  ",
      "            Vh  ",
      "             h  "
    ]
  ]
}