{
  "name": "multi_oasiscondo_8_floor7",
  "refpalette": "deceasedcraft:multi_oasiscondo_8/multi_oasiscondo_8_floor7_palette",
  "xsize": 16,
  "zsize": 16,
  "slices": [
    [
      "                ",
      "                ",
      "                ",
      "                ",
      "                ",
      "                ",
      "                ",
      "                ",
      "                ",
      "aaaaaaaaaaaab ba",
      "aaaaaaaaaaaaacaa",
      "aaaaaaaaaaaaacaa",
      "aaaaaaaaaaaaacaa",
      "aaaaaaaaaaaaacaa",
      "aaaaaaaaaaaaacaa",
      "ddddddddeedddcdd"
    ],
    [
      "                ",
      "                ",
      "                ",
      "                ",
      "                ",
      "                ",
      "                ",
      "                ",
      "dfdfgfhgfdfdi jd",
      "kl  mnopqr sd dt",
      "u   wxyAqBC DcE ",
      "k FIJK LqBC McN ",
      "O   wPQRqSC DcTU",
      "VVVVVW  XY  Zc0 ",
      "       W 1  2cT ",
      "dddddddd34dddcdd"
    ],
    [
      "                ",
      "                ",
      "                ",
      "                ",
      "                ",
      "                ",
      "                ",
      "                ",
      "55556555555fj jd",
      "k   m7 89#  f d$",
      "%   ^&  9   *c( ",
      "k   ^)  9*   c+ ",
      "-   ^   9[   c] ",
      "VVVVV   {}  |c  ",
      "            ;c: ",
      "dddddddd'<dddcdd"
    ],
    [
      "                ",
      "                ",
      "                ",
      "                ",
      "                ",
      "                ",
      "                ",
      "                ",
      "55556555555dj jd",
      "k   ^p  9   d d ",
      ">   ^   9   ,c. ",
      "k   ^   9   ,c? ",
      "/   ^   9   ,c` ",
      "VVVVV   {}  \u0370c` ",
      "            .c` ",
      "dddddddd\u0371\u0371dddcdd"
    ],
    [
      "                ",
      "                ",
      "                ",
      "                ",
      "                ",
      "                ",
      "                ",
      "                ",
      "55556555555d\u0372 jd",
      "k   ^   9   d d ",
      "k   ^   9   \u0373c\u0374 ",
      "k \u0375 ^ \u0375 9 \u0376 \u0377c  ",
      "k   ^   9    c  ",
      "VVVVV   \u037a\u037b   c\u037c ",
      "             c  ",
      "dddddddddddddcdd"
    ],
    [
      "                ",
      "                ",
      "                ",
      "                ",
      "                ",
      "                ",
      "                ",
      "                ",
      "ddfdffdfddfd\u0372 \u0372d",
      "\u037d\u037d\u037d\u037d\u037d\u037d\u037d\u037d\u037d\u037d\u037d\u037dd d\u037d",
      "\u037d\u037d\u037d\u037d\u037d\u037d\u037d\u037d\u037d\u037d\u037d\u037d\u037dc\u037d\u037d",
      "\u037d\u037d\u037d\u037d\u037d\u037d\u037d\u037d\u037d\u037d\u037d\u037d\u037dc\u037d\u037d",
      "\u037d\u037d\u037d\u037d\u037d\u037d\u037d\u037d\u037d\u037d\u037d\u037d\u037dc\u037d\u037d",
      "\u037d\u037d\u037d\u037d\u037d\u037d\u037d\u037d\u037d\u037d\u037d\u037d\u037dc\u037d\u037d",
      "\u037d\u037d\u037d\u037d\u037d\u037d\u037d\u037d\u037d\u037d\u037d\u037d\u037dc\u037d\u037d",
      "dddddddddddddcdd"
    ]
  ]
}