{
  "name": "multi_oasiscondo_8_floor3",
  "refpalette": "deceasedcraft:multi_oasiscondo_8/multi_oasiscondo_8_floor3_palette",
  "xsize": 16,
  "zsize": 16,
  "slices": [
    [
      "                ",
      "                ",
      "                ",
      "                ",
      "                ",
      "                ",
      "                ",
      "                ",
      "                ",
      "aaab baaaaaab ba",
      "aaaacaaaaaaaacaa",
      "aaaacaaaaaaaacaa",
      "aaaacaaaaaaaacaa",
      "aaaacaaaaaaaacaa",
      "aaaacaaaaaaaacaa",
      "ddedcddddddedcdd"
    ],
    [
      "                ",
      "                ",
      "                ",
      "                ",
      "                ",
      "                ",
      "                ",
      "                ",
      "dddf fddddddf fg",
      "hijd dklmh jd dn",
      "o  pcqr  s  pct ",
      "h uwcddxdh yAcB ",
      "C  pc DE C  pcF ",
      "IIIIc J  IIIIcK ",
      "   Lc       LcF ",
      "ddMdcddddddMdcdd"
    ],
    [
      "                ",
      "                ",
      "                ",
      "                ",
      "                ",
      "                ",
      "                ",
      "                ",
      "NNdf OdNNNNgO fd",
      "h jd d   h jd dP",
      "Q  RcSl  T   cU ",
      "h   cdxVdh   cW ",
      "X  Yc    X   cZ ",
      "IIIIc 0  IIIIc  ",
      "   Yc        c1 ",
      "dd2dcdddddd2dcdd"
    ],
    [
      "                ",
      "                ",
      "                ",
      "                ",
      "                ",
      "                ",
      "                ",
      "                ",
      "NNgf OgNNNNdO Od",
      "h3 d d  4h  d d ",
      "5   c6   5   c7 ",
      "h   cddddh   c8 ",
      "5   c    5   c9 ",
      "IIIIc    IIIIc9 ",
      "   #c       #c9 ",
      "dd$dcdddddd$dcdd"
    ],
    [
      "                ",
      "                ",
      "                ",
      "                ",
      "                ",
      "                ",
      "                ",
      "                ",
      "NNdf O%NNNNdf fd",
      "h  d d^ &h  d d ",
      "h   c  &&h   c* ",
      "h ( cddddh ( c  ",
      "h   c    h   c) ",
      "IIIIc +  IIIIc- ",
      "    c        c[ ",
      "ddddcddddddddcdd"
    ],
    [
      "                ",
      "                ",
      "                ",
      "                ",
      "                ",
      "                ",
      "                ",
      "                ",
      "dddO ]{%gddgO Od",
      "}}}d g! ^}}}d d}",
      "}}}}c^^  }}}}c}}",
      "}}}}c}}}}}}}}c}}",
      "}}}}c}}}}}}}}c}}",
      "}}}}c}}}}}}}}c}}",
      "}}}}c}}}}}}}}c}}",
      "ddddcddddddddcdd"
    ]
  ]
}