{
  "name": "multi_oasiscondo_8_floor9",
  "refpalette": "deceasedcraft:multi_oasiscondo_8/multi_oasiscondo_8_floor9_palette",
  "xsize": 16,
  "zsize": 16,
  "slices": [
    [
      "                ",
      "                ",
      "                ",
      "                ",
      "                ",
      "                ",
      "                ",
      "                ",
      "                ",
      "aaab baaaaaaaaaa",
      "acaadeefeeefedee",
      "agaadeeeeefeeeee",
      "c@cadeeffffeffef",
      "aaaadeefefeffeff",
      "aaaadeeeeeefeeee",
      "hhccdiiiiiiiiiii"
    ],
    [
      "                ",
      "                ",
      "                ",
      "                ",
      "                ",
      "                ",
      "                ",
      "     jkkkkkkkkkk",
      "     jjlllllllll",
      "mmmm jllllllllll",
      "ncomdp      qdqq",
      "rcstdpu    w xyq",
      "cAc dpB         ",
      "   CdpD   q     ",
      "    dp      wp q",
      "EEccd           "
    ],
    [
      "                ",
      "                ",
      "                ",
      "                ",
      "                ",
      "                ",
      "                ",
      "     jFFFFFFFFFF",
      "     jj         ",
      "mmmm j          ",
      " c mdq       dw ",
      "IcJ dq          ",
      "cAc dq          ",
      "   Kdq          ",
      "    dq       q  ",
      "EEccd           "
    ],
    [
      "                ",
      "                ",
      "                ",
      "                ",
      "                ",
      "                ",
      "                ",
      "     j          ",
      "     jj         ",
      "mmmm j          ",
      " c md        d  ",
      "LcM dq          ",
      "cAcNdq          ",
      "    d           ",
      "    dq       w  ",
      "EEccd           "
    ],
    [
      "                ",
      "                ",
      "                ",
      "                ",
      "                ",
      "                ",
      "                ",
      "     j          ",
      "     jjOOOOOOOOO",
      "mmmm j          ",
      " c md        d  ",
      " c  d           ",
      "ccccdq          ",
      "    d           ",
      "    d           ",
      "ccccd           "
    ],
    [
      "                ",
      "                ",
      "                ",
      "                ",
      "                ",
      "                ",
      "                ",
      "     jjjjjjjjjjj",
      "     jjjjjjjjjjj",
      "mmmm jjjjjjjjjjj",
      "PcPmdPPPPPPPPdPP",
      "PcPPdPPPPPPPPPPP",
      "ccccdPPPPPPPPPPP",
      "PPPPdPPPPPPPPPPP",
      "PPPPdPPPPPPPPPPP",
      "ccccdPPPPPPPPPPP"
    ]
  ]
}