{
  "name": "multi_oasiscondo_8_floor4",
  "refpalette": "deceasedcraft:multi_oasiscondo_8/multi_oasiscondo_8_floor4_palette",
  "xsize": 16,
  "zsize": 16,
  "slices": [
    [
      "                ",
      "                ",
      "                ",
      "                ",
      "                ",
      "                ",
      "                ",
      "                ",
      "                ",
      "aaab baaaaaab ba",
      "aaaacaaaaaaaacaa",
      "aaaacaaaaaaaacaa",
      "aaaacaaaaaaaacaa",
      "aaaacaaaaaaaacaa",
      "aaaacaaaaaaaacaa",
      "ddedcddddddedcdd"
    ],
    [
      "                ",
      "                ",
      "                ",
      "                ",
      "                ",
      "                ",
      "                ",
      "     fggggggf   ",
      "hdhi ffjjjjff id",
      "klmd fn   o f dp",
      "q  rcs tu   rcw ",
      "k xycdAdBC DEcF ",
      "I  rcJ dK   rcL ",
      "MMMMcN dw OMMcP ",
      "   QcRSdP   QcL ",
      "ddTdcddddddTdcdd"
    ],
    [
      "                ",
      "                ",
      "                ",
      "                ",
      "                ",
      "                ",
      "                ",
      "     fUUUUUUf   ",
      "VVhW ff    ff ih",
      "k md f    X f dY",
      "Z  lc0       c1 ",
      "k   cd2d3    c  ",
      "4  5c  d6   7c8 ",
      "MMMMc  d1 OMMc  ",
      "    c9#d     c$ ",
      "dd%dcdddddd%dcdd"
    ],
    [
      "                ",
      "                ",
      "                ",
      "                ",
      "                ",
      "                ",
      "                ",
      "     f      f   ",
      "VVdi ff^^ ^ff Wd",
      "k &d f      f d ",
      "*   c0       c( ",
      "k   cd)d     c+ ",
      "*   c  d-    c[ ",
      "MMMMc  d] OMMc[ ",
      "   {c}|d[   {c[ ",
      "dd;dcdddddd;dcdd"
    ],
    [
      "                ",
      "                ",
      "                ",
      "                ",
      "                ",
      "                ",
      "                ",
      "     f      f   ",
      "VVdi ff::::ff id",
      "k  d f '  < f h ",
      "k   c>       c  ",
      "k , cddd  ,  c  ",
      "k   c..d?    c/ ",
      "MMMMc..d` OMMc\u0370 ",
      "    c..d\u0371    c\u0371 ",
      "ddddcddddddddcdd"
    ],
    [
      "                ",
      "                ",
      "                ",
      "                ",
      "                ",
      "                ",
      "                ",
      "     ffffffff   ",
      "hdhW ffffffff id",
      "\u0372\u0372\u0372d f\u0372\u0372\u0372\u0372\u0372\u0372f d\u0372",
      "\u0372\u0372\u0372\u0372c\u0372\u0372\u0372\u0372\u0372\u0372\u0372\u0372c\u0372\u0372",
      "\u0372\u0372\u0372\u0372c\u0372\u0372\u0372\u0372\u0372\u0372\u0372\u0372c\u0372\u0372",
      "\u0372\u0372\u0372\u0372c  \u0372\u0372\u0372\u0372\u0372\u0372c\u0372\u0372",
      "\u0372\u0372\u0372\u0372c  \u0372\u0372\u0372\u0372\u0372\u0372c\u0372\u0372",
      "\u0372\u0372\u0372\u0372c\u0373 \u0372\u0372\u0372\u0372\u0372\u0372c\u0372\u0372",
      "ddddcddddddddcdd"
    ]
  ]
}