{
  "name": "multi_oasiscondo_8_base1",
  "refpalette": "deceasedcraft:multi_oasiscondo_8/multi_oasiscondo_8_base1_palette",
  "xsize": 16,
  "zsize": 16,
  "slices": [
    [
      "vvvvvvvvvvvvvvvv",
      "HHHHHHHHHHHHHHHH",
      "HHHHHHHHHHHHHHHH",
      "HHHHHHHHHHHHHHHH",
      "HHHHaHHHHHHHHaHH",
      "HHHHaHHHHHHHHaHH",
      "HHHHaHHHHHHHHaHH",
      "HHHHaHHHHHHHHaHH",
      "HHHHaHHHHHHHHaHH",
      "HHHHaHHHHHHHHaHH",
      "HHHHbHHHHHHHHbHH",
      "HHHHaHHHHHHHHaHH",
      "HHHHHHHHHHHHHHHH",
      "HHHHHHHHHHHHHHHH",
      "HHHHHHHHHHHHHHHH",
      "HHHHaHHHHHHHHaaa"
    ],
    [
      "vvvvvvvvvvvvvvvv",
      "                ",
      "                ",
      "                ",
      "cdcdecdcdcdcde  ",
      "    e   f    e  ",
      "    e        e  ",
      "ghgheghghghghe  ",
      "cdcdecdcdcdcde  ",
      "    e        e  ",
      "    b        b  ",
      "ghgheghghghghe  ",
      "                ",
      "                ",
      "                ",
      "c  dec idc  de  "
    ],
    [
      "vvvvvvvvvvvvvvvv",
      "                ",
      "                ",
      "                ",
      "                ",
      "                ",
      "                ",
      "                ",
      "                ",
      "                ",
      "    b        b  ",
      "                ",
      "                ",
      "                ",
      "                ",
      "                "
    ],
    [
      "vvvvvvvvvvvvvvvv",
      "                ",
      "                ",
      "                ",
      "                ",
      "                ",
      "                ",
      "                ",
      "                ",
      "                ",
      "    b        b  ",
      "                ",
      "                ",
      "                ",
      "                ",
      "                "
    ],
    [
      "vvvvvvvvvvvvvvvv",
      "                ",
      "                ",
      "                ",
      "                ",
      "                ",
      "                ",
      "                ",
      "                ",
      "                ",
      "    b        b  ",
      "                ",
      "                ",
      "                ",
      "                ",
      "                "
    ],
    [
      "vvvvvvvvvvvvvvvv",
      "jjjjkjjjjjjjjkjj",
      "jjjjkjjjjjjjjkjj",
      "jjjjkjjjjjjjjkjj",
      "jjjjkjjjjjjjjkjj",
      "jjjjkjjjjjjjjkjj",
      "jjjjkjjjjjjjjkjj",
      "jjjjkjjjjjjjjkjj",
      "jjjjkjjjjjjjjkjj",
      "jjjjkjjjjjjjjkjj",
      "kkkklkkkkkkkklkk",
      "jjjjkjjjjjjjjkjj",
      "jjjjkjjjjjjjjkjj",
      "jjjjkjjjjjjjjkjj",
      "jjjjkjjjjjjjjkjj",
      "jjjjkjjjjjjjjkjj"
    ]
  ]
}