{
  "name": "multi_oasiscondo_8_top",
  "refpalette": "deceasedcraft:multi_oasiscondo_8/multi_oasiscondo_8_top_palette",
  "xsize": 16,
  "zsize": 16,
  "slices": [
    [
      "                ",
      "                ",
      "                ",
      "                ",
      "                ",
      "                ",
      "                ",
      "                ",
      "                ",
      "aaab baaaaaaaaaa",
      "aaaacddddddddcaa",
      "aaaaceeeeeeeeefg",
      "aaaaceeeeeeeeefg",
      "aaaaceeeeeeeeefg",
      "aaaaceeeeeeeeefg",
      "hhhhceeeeeeeeefg"
    ],
    [
      "                ",
      "                ",
      "                ",
      "                ",
      "                ",
      "                ",
      "                ",
      "     iiiiiiiiiii",
      "hhhj iiiiiiiiiii",
      " klh i mm mm  n ",
      " o pcq       crs",
      " kttc         fg",
      " u pcq        fg",
      " kttc         fg",
      " o pcq        fg",
      "hhhhc        wxg"
    ],
    [
      "                ",
      "                ",
      "                ",
      "                ",
      "                ",
      "                ",
      "                ",
      "     iyyyyyyyyyy",
      "AAhj iiiiiiiiiii",
      " k h i        B ",
      " C  c        cDE",
      " kttcF        fg",
      " I  c         fg",
      " kttcF       wxg",
      " C  c        w g",
      "hhhhcF         g"
    ],
    [
      "                ",
      "                ",
      "                ",
      "                ",
      "                ",
      "                ",
      "                ",
      "     iAAAAAAAAAA",
      "AAhj ii      wxx",
      " kJh i       wxx",
      " k  c        cxx",
      " kttcK       wxx",
      " k Lc        w  ",
      " kttcK          ",
      " k  c           ",
      "hhhhcK          "
    ],
    [
      "                ",
      "                ",
      "                ",
      "                ",
      "                ",
      "                ",
      "                ",
      "     iAAAAAAAAAA",
      "AAhj ii         ",
      " kMh i          ",
      " kMMc        c  ",
      " kMMc           ",
      " kM!c           ",
      " kMMc           ",
      " kMMc           ",
      "hhhhc           "
    ],
    [
      "                ",
      "                ",
      "                ",
      "                ",
      "                ",
      "                ",
      "                ",
      "     i          ",
      "hhhj ii         ",
      "NNLh i          ",
      "NN Oc        c  ",
      "NNL c           ",
      "NN Oc           ",
      "NN Lc           ",
      "NNLOc           ",
      "hhhhc           "
    ],
    [
      "                ",
      "                ",
      "                ",
      "                ",
      "                ",
      "                ",
      "                ",
      "     i          ",
      "     ii         ",
      "aaab i          ",
      "aaaac        c  ",
      "aaaac           ",
      "aaaac           ",
      "aaaac           ",
      "aaaac           ",
      "hhaac           "
    ],
    [
      "                ",
      "                ",
      "                ",
      "                ",
      "                ",
      "                ",
      "                ",
      "     i          ",
      "hhhj ii         ",
      "   h i          ",
      "PQ Rc        c  ",
      " Q Rc           ",
      "PQ  c           ",
      " Q Rc           ",
      "PQ Rc           ",
      "hh  c           "
    ],
    [
      "                ",
      "                ",
      "                ",
      "                ",
      "                ",
      "                ",
      "                ",
      "     i          ",
      "AAhj ii         ",
      "   h i          ",
      "    c        c  ",
      "    c           ",
      "    c           ",
      "    c           ",
      "    c           ",
      "hh  c           "
    ],
    [
      "                ",
      "                ",
      "                ",
      "                ",
      "                ",
      "                ",
      "                ",
      "     i          ",
      "AAhj ii         ",
      "   h i          ",
      "ST  c        c  ",
      " U  c           ",
      "S   c           ",
      " V  c           ",
      "SW  c           ",
      "hhXXc           "
    ],
    [
      "                ",
      "                ",
      "                ",
      "                ",
      "                ",
      "                ",
      "                ",
      "     i          ",
      "AAhj iiYYYYYYYYY",
      "   h i          ",
      "Z   c        c  ",
      "    c           ",
      "Z   c           ",
      "    c           ",
      "Z   c           ",
      "hhhhc           "
    ],
    [
      "                ",
      "                ",
      "                ",
      "                ",
      "                ",
      "                ",
      "                ",
      "     iiiiiiiiiii",
      "hhhj iiiiiiiiiii",
      "NNNh iiiiiiiiiii",
      "NNNNc00000000c00",
      "NNNNc00000000000",
      "NNNNc00000000000",
      "NNNNc00000000000",
      "NNNNc00000000000",
      "hhhhc00000000000"
    ],
    [
      "                ",
      "                ",
      "                ",
      "                ",
      "                ",
      "                ",
      "                ",
      "                ",
      "                ",
      "aaab baaaaaaaaaa",
      "1111111111111111",
      "2222222222222222",
      "2222222222222222",
      "2222222222222222",
      "2222222222222222",
      "2222222222222222"
    ],
    [
      "                ",
      "                ",
      "                ",
      "                ",
      "                ",
      "                ",
      "                ",
      "                ",
      "                ",
      "                ",
      "3333333333333333",
      "    4        4  ",
      "    5        5  ",
      "6666!66666666666",
      "    7        7  ",
      "         888  88"
    ],
    [
      "                ",
      "                ",
      "                ",
      "                ",
      "                ",
      "                ",
      "                ",
      "                ",
      "                ",
      "                ",
      "3333333333333333",
      "                ",
      "                ",
      "                ",
      "                ",
      "         9 9  9 "
    ],
    [
      "                ",
      "                ",
      "                ",
      "                ",
      "                ",
      "                ",
      "                ",
      "                ",
      "                ",
      "                ",
      "                ",
      "                ",
      "                ",
      "                ",
      "                ",
      "         ###  ##"
    ],
    [
      "                ",
      "                ",
      "                ",
      "                ",
      "                ",
      "                ",
      "                ",
      "                ",
      "                ",
      "                ",
      "                ",
      "                ",
      "                ",
      "                ",
      "                ",
      "         ###  ##"
    ],
    [
      "                ",
      "                ",
      "                ",
      "                ",
      "                ",
      "                ",
      "                ",
      "                ",
      "                ",
      "                ",
      "                ",
      "                ",
      "                ",
      "                ",
      "                ",
      "         ###  ##"
    ],
    [
      "                ",
      "                ",
      "                ",
      "                ",
      "                ",
      "                ",
      "                ",
      "                ",
      "                ",
      "                ",
      "                ",
      "                ",
      "                ",
      "                ",
      "                ",
      "         $##  ##"
    ]
  ]
}