{
  "name": "multi_oasiscondo_8_base2",
  "refpalette": "deceasedcraft:multi_oasiscondo_8/multi_oasiscondo_8_base2_palette",
  "xsize": 16,
  "zsize": 16,
  "slices": [
    [
      "vvvvvvvvvvvvvvvv",
      "HHHHHHHHHHHHHHHH",
      "HHHHHHHHHHHHHHHH",
      "HHHHHHHHHHHHHHHH",
      "HHHHaHHHHHHHHaHH",
      "HHHHaHHHHHHHHaHH",
      "HHHHaHHHHHHHHaHH",
      "HHHHaHHHHHHHHaHH",
      "HHHHaHHHHHHHHaHH",
      "HHHHaHHHHHHHHaHH",
      "HHHHbHHHHHHHHbHH",
      "HHHHaHHHHHHHHaHH",
      "HHHHHHHHHHHHHHHH",
      "HHHHHHHHHHHHHHHH",
      "HHHHHHHHHHHHHHHH",
      "HHHHaHHHHHHHHaaa"
    ],
    [
      "vvvvvvvvvvvvvvvv",
      "                ",
      "                ",
      "                ",
      "cdcdecdcdcdcde  ",
      "    e        e  ",
      "    e        e  ",
      "fgfgefgfgfgfge  ",
      "cdcdecdcdcdcde  ",
      "    e        e  ",
      "    b        b  ",
      "fgfgefgfgfgfge  ",
      "                ",
      "                ",
      "                ",
      "c  dec  dc  de  "
    ],
    [
      "vvvvvvvvvvvvvvvv",
      "                ",
      "                ",
      "                ",
      "                ",
      "                ",
      "                ",
      "                ",
      "                ",
      "                ",
      "    b        b  ",
      "                ",
      "                ",
      "                ",
      "                ",
      "                "
    ],
    [
      "vvvvvvvvvvvvvvvv",
      "                ",
      "                ",
      "                ",
      "                ",
      "                ",
      "                ",
      "                ",
      "                ",
      "                ",
      "    b        b  ",
      "                ",
      "                ",
      "                ",
      "                ",
      "                "
    ],
    [
      "vvvvvvvvvvvvvvvv",
      "                ",
      "                ",
      "                ",
      "                ",
      "                ",
      "                ",
      "                ",
      "                ",
      "                ",
      "    b        b  ",
      "                ",
      "                ",
      "                ",
      "                ",
      "                "
    ],
    [
      "vvvvvvvvvvvvvvvv",
      "hhhhihhhhhhhhihh",
      "hhhhihhhhhhhhihh",
      "hhhhihhhhhhhhihh",
      "hhhhihhhhhhhhihh",
      "hhhhihhhhhhhhihh",
      "hhhhihhhhhhhhihh",
      "hhhhihhhhhhhhihh",
      "hhhhihhhhhhhhihh",
      "hhhhihhhhhhhhihh",
      "iiiijiiiiiiiijii",
      "hhhhihhhhhhhhihh",
      "hhhhihhhhhhhhihh",
      "hhhhihhhhhhhhihh",
      "hhhhihhhhhhhhihh",
      "hhhhihhhhhhhhihh"
    ]
  ]
}