{
  "name": "multi_oasiscondo_8_floor1",
  "refpalette": "deceasedcraft:multi_oasiscondo_8/multi_oasiscondo_8_floor1_palette",
  "xsize": 16,
  "zsize": 16,
  "slices": [
    [
      "                ",
      "                ",
      "                ",
      "                ",
      "                ",
      "                ",
      "                ",
      "                ",
      "           ab ba",
      "cccc ccccccca a ",
      "   cdc       d  ",
      "             d  ",
      "            ed  ",
      "            fd  ",
      "            gd  ",
      "             d  "
    ],
    [
      "                ",
      "                ",
      "                ",
      "                ",
      "                ",
      "                ",
      "                ",
      "                ",
      "           ab ba",
      "cccc ccccccca a ",
      "   cdc       d  ",
      "             d  ",
      "h            d  ",
      "            id  ",
      "  h          d  ",
      "             d  "
    ],
    [
      "                ",
      "                ",
      "                ",
      "                ",
      "                ",
      "                ",
      "                ",
      "                ",
      "           ab ba",
      "cccc ccccccca a ",
      "   cdc       d  ",
      "             d  ",
      "jh           d  ",
      "            kd  ",
      "hhj          d  ",
      "             d  "
    ],
    [
      "                ",
      "                ",
      "                ",
      "                ",
      "                ",
      "                ",
      "                ",
      "                ",
      "           ab ba",
      "cccc ccccccca a ",
      "   cdc       d  ",
      "             d  ",
      "jjh          d  ",
      "             d  ",
      "jjj          d  ",
      "             d  "
    ],
    [
      "                ",
      "                ",
      "                ",
      "                ",
      "                ",
      "                ",
      "                ",
      "                ",
      "           ab ba",
      "cccc ccccccca al",
      "   cdc       d  ",
      "mmm          d  ",
      "jjjm         d  ",
      "nnnm         d  ",
      "jjjm         d  ",
      "mmm          d  "
    ],
    [
      "                ",
      "                ",
      "                ",
      "                ",
      "                ",
      "                ",
      "                ",
      "                ",
      "aaaaaaaaaaaab ba",
      "aaaaaaaaaaaaa aa",
      "oooadaooooooodoo",
      "ooooooooooooodoo",
      "pppoooooooooodoo",
      "pppoooooooooodoo",
      "pppoooooooooodoo",
      "ooooooooooooodoo"
    ]
  ]
}