{
  "name": "multi_oasiscondo_8_floor2",
  "refpalette": "deceasedcraft:multi_oasiscondo_8/multi_oasiscondo_8_floor2_palette",
  "xsize": 16,
  "zsize": 16,
  "slices": [
    [
      "                ",
      "                ",
      "                ",
      "                ",
      "                ",
      "                ",
      "                ",
      "                ",
      "                ",
      "aaab baaaaaab ba",
      "aaaacaaaaaaaacaa",
      "aaaacaaaaaaaacaa",
      "aaaacaaaaaaaacaa",
      "aaaacaaaaaaaacaa",
      "aaaacaaaaaaaacaa",
      "ddedcddddddedcdd"
    ],
    [
      "                ",
      "                ",
      "                ",
      "                ",
      "                ",
      "                ",
      "                ",
      "                ",
      "fddg hfijffdg gd",
      "k ld dm nkold dp",
      "q  rcstu wxurcy ",
      "k ABcCDjdk ABcE ",
      "F  rcIJ  F  rcKL",
      "MMMMc N  MMMMcO ",
      "   PcQRS    PcK ",
      "ddTdcddddddTdcdd"
    ],
    [
      "                ",
      "                ",
      "                ",
      "                ",
      "                ",
      "                ",
      "                ",
      "                ",
      "UUdg VWUUUUfg gf",
      "k ld d  Xk ld dY",
      "Z  0c1u  2  uc3 ",
      "k   c4!5dk   c6 ",
      "7  8c    7  9c# ",
      "MMMMc    MMMMc  ",
      "   $c% N    ^c& ",
      "dd*dcdddddd*dcdd"
    ],
    [
      "                ",
      "                ",
      "                ",
      "                ",
      "                ",
      "                ",
      "                ",
      "                ",
      "UUdg gd UUUdg Vd",
      "k xd d  (k )d d ",
      "+   c-   +   c[ ",
      "k   c]{}dk   c| ",
      "+   c    +   c; ",
      "MMMMc    MMMMc; ",
      "   :c'<>    :c; ",
      "dd,dcdddddd,dcdd"
    ],
    [
      "                ",
      "                ",
      "                ",
      "                ",
      "                ",
      "                ",
      "                ",
      "                ",
      "UUdh gdUUUUdg hd",
      "k  d d...k  d f ",
      "k   c?...k  uc  ",
      "k / cd`ddk / c  ",
      "k   c    k   c  ",
      "MMMMc ?  MMMMc\u0370 ",
      "    c\u0371\u0372\u0373     c\u0374 ",
      "ddddcddddddddcdd"
    ],
    [
      "                ",
      "                ",
      "                ",
      "                ",
      "                ",
      "                ",
      "                ",
      "                ",
      "dddh gddddddg \u0375f",
      "\u0376\u0376\u0376d d\u0377  \u0376\u0376\u0376d i\u0376",
      "\u0376\u0376\u0376\u0376c\u0376   \u0376\u0376\u0376\u0376c\u0376\u0376",
      "\u0376\u0376\u0376\u0376c\u0376\u0376\u0376\u0376\u0376\u0376\u0376\u0376c\u0376\u0376",
      "\u0376\u0376\u0376\u0376c\u0376\u0376\u0376\u0376\u0376\u0376\u0376\u0376c\u0376\u0376",
      "\u0376\u0376\u0376\u0376c\u0376\u0376\u0376\u0376\u0376\u0376\u0376\u0376c\u0376\u0376",
      "\u0376\u0376\u0376\u0376c\u0376\u0376\u0376\u0376\u0376\u0376\u0376\u0376c\u0376\u0376",
      "ddddcddddddddcdd"
    ]
  ]
}