{
  "name": "multi_oasiscondo_8_floor5",
  "refpalette": "deceasedcraft:multi_oasiscondo_8/multi_oasiscondo_8_floor5_palette",
  "xsize": 16,
  "zsize": 16,
  "slices": [
    [
      "                ",
      "                ",
      "                ",
      "                ",
      "                ",
      "                ",
      "                ",
      "                ",
      "                ",
      "aaab baaaaaab ba",
      "aaaacaaaaaaaacaa",
      "aaaacaaaaaaaacaa",
      "aaaacaaaaaaaacaa",
      "aaaacaaaaaaaacaa",
      "aaaacaaaaaaaacaa",
      "ddedcddddddedcdd"
    ],
    [
      "                ",
      "                ",
      "                ",
      "                ",
      "                ",
      "                ",
      "                ",
      "     fggggggf   ",
      "hihj ffkkkkff jd",
      "lmnh f      f do",
      "pqmrc        cs ",
      "l tucdwd     cx ",
      "yA rcB d     cC ",
      "DDDDcE d     cF ",
      "  IJc  d     cC ",
      "ddKdcddddddKdcdd"
    ],
    [
      "                ",
      "                ",
      "                ",
      "                ",
      "                ",
      "                ",
      "                ",
      "     fLLLLLLf   ",
      "MMiN ff    ff jd",
      "lmnd f      f dO",
      "P QRc        cS ",
      "l   cdTd     c  ",
      "U   c  d     cV ",
      "DDDDc  d     c  ",
      "   WcX d     cY ",
      "ddZdcddddddZdcdd"
    ],
    [
      "                ",
      "                ",
      "                ",
      "                ",
      "                ",
      "                ",
      "                ",
      "     f      f   ",
      "MMh0 ff    ff jd",
      "lR1h f      f d ",
      "2   c        c3 ",
      "l   cd4d  !1 c5 ",
      "2   c  d     c6 ",
      "DDDDc  d     c6 ",
      "   7c8 d    1c6 ",
      "dd9dcdddddd9dcdd"
    ],
    [
      "                ",
      "                ",
      "                ",
      "                ",
      "                ",
      "                ",
      "                ",
      "     f      f   ",
      "MM#0 ff    ff Nd",
      "l1!i f1     f h ",
      "l 11c$      1c% ",
      "l ^ cddd  $ 1c  ",
      "l   c&&d     c  ",
      "DDDDc&&d    1c* ",
      "    c&&d1   1c( ",
      "ddddcddddddddcdd"
    ],
    [
      "                ",
      "                ",
      "                ",
      "                ",
      "                ",
      "                ",
      "                ",
      "     ffffffff   ",
      "dhdN ffffffff Nd",
      ")))d f))))))f d)",
      "))))c))))))))c))",
      "))))c))))))))c))",
      "))))c  ))))))c))",
      "))))c  ))))))c))",
      "))))c+ ))))))c))",
      "ddddcddddddddcdd"
    ]
  ]
}