{
  "name": "multi_oasiscondo_8_floor10",
  "refpalette": "deceasedcraft:multi_oasiscondo_8/multi_oasiscondo_8_floor10_palette",
  "xsize": 16,
  "zsize": 16,
  "slices": [
    [
      "                ",
      "                ",
      "                ",
      "                ",
      "                ",
      "                ",
      "                ",
      "                ",
      "                ",
      "aaaaaaaaaaaab ba",
      "cdccecccccccceaa",
      "dcccccddccccceaa",
      "cddcdddddcddceaa",
      "dcddcdccdddcceaa",
      "cccdccccccccdeaa",
      "fffffffffffffegg"
    ],
    [
      "                ",
      "                ",
      "                ",
      "                ",
      "                ",
      "                ",
      "                ",
      "hhhhhhhhhhhhi   ",
      "jjjjjjjjjjjii kl",
      "jjjjjjjjjjjji lm",
      "  noeon   o peq ",
      "   ors  oo o et ",
      "         p  net ",
      " o    o      et ",
      "s   noopo un ew ",
      "             exy"
    ],
    [
      "                ",
      "                ",
      "                ",
      "                ",
      "                ",
      "                ",
      "                ",
      "AAAAAAAAAAAAi   ",
      "           ii Bl",
      "            i C ",
      "   oe     o uet ",
      "             et ",
      "         u   et ",
      "      o      eq ",
      "       u  o  eD ",
      "             exE"
    ],
    [
      "                ",
      "                ",
      "                ",
      "                ",
      "                ",
      "                ",
      "                ",
      "            i   ",
      "           ii BC",
      "            i l ",
      "    e       oeF ",
      "             eI ",
      "         o   eI ",
      "             eJ ",
      "       s  s  eK ",
      "             exx"
    ],
    [
      "                ",
      "                ",
      "                ",
      "                ",
      "                ",
      "                ",
      "                ",
      "            i   ",
      "LLLLLLLLLLLii Bl",
      "            i l ",
      "    e       se  ",
      "             e  ",
      "         o   e  ",
      "             e  ",
      "             e  ",
      "             ell"
    ],
    [
      "                ",
      "                ",
      "                ",
      "                ",
      "                ",
      "                ",
      "                ",
      "iiiiiiiiiiiii   ",
      "iiiiiiiiiiiii Bl",
      "iiiiiiiiiiiii lM",
      "NNNNeNNNNNNNNeMM",
      "NNNNNNNNNNNNNeMM",
      "NNNNNNNNNNNNNeMM",
      "NNNNNNNNNNNNNeMM",
      "NNNNNNNNNNNNNeMM",
      "NNNNNNNNNNNNNell"
    ]
  ]
}