{
  "name": "multi_oasiscondo_8_floor8",
  "refpalette": "deceasedcraft:multi_oasiscondo_8/multi_oasiscondo_8_floor8_palette",
  "xsize": 16,
  "zsize": 16,
  "slices": [
    [
      "                ",
      "                ",
      "                ",
      "                ",
      "                ",
      "                ",
      "                ",
      "                ",
      "                ",
      "aaaaaaaaaaaab ba",
      "aaaaaaaaaaaaacaa",
      "aaaaaaaaaaaaacaa",
      "aaaaaaaaaaaaacaa",
      "aaaaaaaaaaaaacaa",
      "aaaaaaaaaaaaacaa",
      "ddddddeddddddcdd"
    ],
    [
      "                ",
      "                ",
      "                ",
      "                ",
      "                ",
      "                ",
      "                ",
      "                ",
      "fdddddddddddg gd",
      "h   ijkklmnld do",
      "p qq     mr sctu",
      "h wx yABCm DEcFI",
      "  JK LMMMm  scN ",
      "         O  PcQ ",
      "RSTUTV WWm XYcN ",
      "ddddddZddddddcdd"
    ],
    [
      "                ",
      "                ",
      "                ",
      "                ",
      "                ",
      "                ",
      "                ",
      "                ",
      "00001000000dg gd",
      "h   23 4 m56d dI",
      "7        m  8c9 ",
      "h    #   m   c! ",
      "      $$$m  %cI ",
      "         ^ &*c  ",
      "()+ -[   m  Yc] ",
      "dddddd{ddddddcdd"
    ],
    [
      "                ",
      "                ",
      "                ",
      "                ",
      "                ",
      "                ",
      "                ",
      "                ",
      "00001000000dg gd",
      "h        m }f d ",
      "|        m   c; ",
      "h        m   c: ",
      "         m  'c< ",
      "         >  Mc< ",
      ";,...[   m  Mc< ",
      "dddddd?ddddddcdd"
    ],
    [
      "                ",
      "                ",
      "                ",
      "                ",
      "                ",
      "                ",
      "                ",
      "                ",
      "00001000000dg /d",
      "h        m `d d ",
      "h        m   cI ",
      "h  \u0370   \u0371 m   c  ",
      "         m \u0371 c  ",
      "         m   c] ",
      "\u0372 \u0373\u0374 \u0375   m  \u0376c\u0377 ",
      "dddddddddddddcdd"
    ],
    [
      "                ",
      "                ",
      "                ",
      "                ",
      "                ",
      "                ",
      "                ",
      "                ",
      "dfddddddffdd/ /f",
      "\u037a\u037a\u037a\u037a\u037a\u037a\u037a\u037a\u037a\u037a\u037a\u037ad d\u037a",
      "\u037a\u037a\u037a\u037a\u037a\u037a\u037a\u037a\u037a\u037a\u037a\u037a\u037ac\u037a\u037a",
      "\u037a\u037a\u037a\u037a\u037a\u037a\u037a\u037a\u037a\u037a\u037a\u037a\u037ac\u037a\u037a",
      "\u037a\u037a\u037a\u037a\u037a\u037a\u037a\u037a\u037a\u037a\u037a\u037a\u037ac\u037a\u037a",
      "\u037a\u037a\u037a\u037a\u037a\u037a\u037a\u037a\u037a\u037a\u037a\u037a\u037ac\u037a\u037a",
      "\u037a\u037a\u037a\u037a\u037a\u037a\u037a\u037a\u037a\u037a\u037a\u037a\u037ac\u037a\u037a",
      "dddddddddddddcdd"
    ]
  ]
}