{
  "name": "multi_thering_18_base1",
  "refpalette": "deceasedcraft:multi_thering_18/multi_thering_18_base1_palette",
  "xsize": 16,
  "zsize": 16,
  "slices": [
    [
      "aaaabbbbbbbbbbbc",
      "aaabbbbbbbbbbbbb",
      "aabbbbbbbbbbbbbb",
      "abbbbbbbbbbbbbbb",
      "bbbbbbbbbbbbbbbb",
      "bbbbbbbbbbbbbbbb",
      "bbbbbbbbbbbbbbbb",
      "bbbbbbbbbbbbbbbb",
      "bbbbbbbbbbbbbbbb",
      "bbbbbbbbbbbbbbbb",
      "bbbbbbbbbbbbbbbb",
      "bbbbbbbbbbbbbbbb",
      "bbbbbbbbbbbbbbbb",
      "bbbbbbbbbbbbbbbb",
      "bbbbbbbbbbbbbbbb",
      "cbbbbbbbbbbbbbbb"
    ],
    [
      "deeeaaabbbbbbbbc",
      "eeeaaabbbbbbbbbb",
      "eeaaabbbbbbbbbbb",
      "eaaabbbbbbbbbbbb",
      "aaabbbbbbbbbbbbb",
      "aabbbbbbbbbbbbbb",
      "abbbbbbbbbbbbbbb",
      "bbbbbbbbbbbbbbbb",
      "bbbbbbbbbbbbbbbb",
      "bbbbbbbbbbbbbbbb",
      "bbbbbbbbbbbbbbbb",
      "bbbbbbbbbbbbbbbb",
      "bbbbbbbbbbbbbbbb",
      "bbbbbbbbbbbbbbbb",
      "bbbbbbbbbbbbbbbb",
      "cbbbbbbbbbbbbbbb"
    ],
    [
      "   deeeaabbbbbbc",
      "  ddeeaaabbbbbbb",
      " ddeeaaabbbbbbbb",
      "ddeeaaabbbbbbbbb",
      "eeeaaaabbbbbbbbb",
      "eeaaaabbbbbbbbbb",
      "eaaaabbbbbbbbbbb",
      "aaabbbbbbbbbbbbb",
      "aabbbbbbbbbbbbbb",
      "bbbbbbbbbbbbbbbb",
      "bbbbbbbbbbbbbbbb",
      "bbbbbbbbbbbbbbbb",
      "bbbbbbbbbbbbbbbb",
      "bbbbbbbbbbbbbbbb",
      "bbbbbbbbbbbbbbbb",
      "cbbbbbbbbbbbbbbb"
    ],
    [
      "      deeaaabbbc",
      "     ddeeaabbbbb",
      "    ddeeaaabbbbb",
      "   ddeeaaabbbbbb",
      "  ddeeeaaabbbbbb",
      " ddeeeaaabbbbbbb",
      "ddeeeaaabbbbbbbb",
      "eeeaaaabbbbbbbbb",
      "eeaaaabbbbbbbbbb",
      "aaaaabbbbbbbbbbb",
      "aaabbbbbbbbbbbbb",
      "abbbbbbbbbbbbbbb",
      "bbbbbbbbbbbbbbbb",
      "bbbbbbbbbbbbbbbb",
      "bbbbbbbbbbbbbbbb",
      "cbbbbbbbbbbbbbbb"
    ],
    [
      "        ddeeaaac",
      "        deeaaabb",
      "       ddeeaaabb",
      "      ddeeaaabbb",
      "      deeeaaabbb",
      "     ddeeaaabbbb",
      "   dddeeaaabbbbb",
      "  ddeeeaaaabbbbb",
      "dddeeeaaaabbbbbb",
      "deeeeaaaabbbbbbb",
      "eeeaaaaabbbbbbbb",
      "eaaaaabbbbbbbbbb",
      "aaaaabbbbbbbbbbb",
      "aaabbbbbbbbbbbbb",
      "abbbbbbbbbbbbbbb",
      "cbbbbbbbbbbbbbbb"
    ],
    [
      "           deeec",
      "          ddeeaa",
      "          deeeaa",
      "         ddeeaaa",
      "         deeeaaa",
      "        ddeeaaaa",
      "       ddeeaaaaa",
      "      ddeeeaaaaa",
      "     ddeeeaaaaaa",
      "   dddeeeaaaaaaa",
      " dddeeeeaaaaaaaa",
      "ddeeeeaaaaaaaaaa",
      "eeeeeaaaaaaaaaaa",
      "eeeaaaaaaaaaaaaa",
      "eaaaaaaaaaaaaaaa",
      "caaaaaaaaaaaaaaa"
    ]
  ]
}