{
  "name": "multi_thering_18_floor6",
  "refpalette": "deceasedcraft:multi_thering_18/multi_thering_18_floor6_palette",
  "xsize": 16,
  "zsize": 16,
  "slices": [
    [
      "               a",
      "                ",
      "                ",
      "                ",
      "                ",
      "                ",
      "                ",
      "                ",
      "                ",
      "                ",
      "                ",
      "                ",
      "                ",
      "                ",
      "                ",
      "a               "
    ],
    [
      "               a",
      "                ",
      "                ",
      "                ",
      "                ",
      "                ",
      "                ",
      "                ",
      "                ",
      "                ",
      "                ",
      "                ",
      "                ",
      "                ",
      "                ",
      "a               "
    ],
    [
      "               a",
      "                ",
      "                ",
      "                ",
      "                ",
      "                ",
      "                ",
      "                ",
      "                ",
      "                ",
      "                ",
      "                ",
      "                ",
      "                ",
      "                ",
      "a               "
    ],
    [
      "               a",
      "                ",
      "                ",
      "                ",
      "                ",
      "                ",
      "                ",
      "                ",
      "                ",
      "                ",
      "                ",
      "                ",
      "                ",
      "                ",
      "                ",
      "a               "
    ],
    [
      "             bcc",
      "             bcc",
      "            bccc",
      "           bcccc",
      "           bcccc",
      "          bccccc",
      "         bcccccc",
      "        bccccccc",
      "       bcccccccc",
      "      bccccccccc",
      "     bcccccccccc",
      "   bbccccccccccc",
      "  bccccccccccccc",
      "bbcccccccccccccc",
      "cccccccccccccccb",
      "ccccccccccccccb "
    ],
    [
      "             dee",
      "             def",
      "             gee",
      "            geef",
      "           deeef",
      "           gefff",
      "          geeffe",
      "         geffefe",
      "        geffffee",
      "       gefffeehh",
      "      gefffehhij",
      "    kgeefeehiili",
      "   geeefffhilijc",
      "kkgeeefffehiiicc",
      "eeeefeffehijiccc",
      "eefffffeehjicccc"
    ]
  ]
}