{
  "name": "multi_verticalschool_16_floor22",
  "refpalette": "deceasedcraft:multi_verticalschool_16/multi_verticalschool_16_floor22_palette",
  "xsize": 16,
  "zsize": 16,
  "slices": [
    [
      "                ",
      "                ",
      "                ",
      "                ",
      "                ",
      "                ",
      "                ",
      "                ",
      "                ",
      "                ",
      "                ",
      "                ",
      "                ",
      "                ",
      "                ",
      "                "
    ],
    [
      "abaac           ",
      "abaac           ",
      "abaac           ",
      "abaac           ",
      "abaac           ",
      "abaac           ",
      "abaac           ",
      "abaac           ",
      "abaac           ",
      "abaac           ",
      "abaac           ",
      "abaac           ",
      "abaac           ",
      "abaac           ",
      "abaac           ",
      "abaac           "
    ],
    [
      "dddde           ",
      "dddde           ",
      "dddde           ",
      "dddde           ",
      "dddde           ",
      "dddde           ",
      "dddde           ",
      "dddde           ",
      "dddde           ",
      "dddde           ",
      "dddde           ",
      "dddde           ",
      "dddde           ",
      "dddde           ",
      "dddde           ",
      "dddde           "
    ],
    [
      "   fe           ",
      "   ge           ",
      "   fe           ",
      "   fe           ",
      "   fe           ",
      "   fe           ",
      "   fe           ",
      "   fe           ",
      "   fe           ",
      "   fe           ",
      "   fe           ",
      "   fe           ",
      "   fe           ",
      "   fe           ",
      "   fe           ",
      "   fe           "
    ],
    [
      "   fe           ",
      "   he           ",
      "   fe           ",
      "   fe           ",
      "   fe           ",
      "   fe           ",
      "   fe           ",
      "   fe           ",
      "   fe           ",
      "   fe           ",
      "   fe           ",
      "   fe           ",
      "   fe           ",
      "   fe           ",
      "   fe           ",
      "   fe           "
    ],
    [
      "   fe           ",
      "   ie           ",
      "   fe           ",
      "   fe           ",
      "   fe           ",
      "   fe           ",
      "   fe           ",
      "   fe           ",
      "   fe           ",
      "   fe           ",
      "   fe           ",
      "   fe           ",
      "   fe           ",
      "   fe           ",
      "   fe           ",
      "   fe           "
    ]
  ]
}