{
  "name": "multi_verticalschool_16_floor15",
  "refpalette": "deceasedcraft:multi_verticalschool_16/multi_verticalschool_16_floor15_palette",
  "xsize": 16,
  "zsize": 16,
  "slices": [
    [
      "       a        ",
      "       a        ",
      "       b        ",
      "     cba        ",
      "       a        ",
      "       a        ",
      "       a        ",
      "       a        ",
      "     dba        ",
      "       a        ",
      "       a        ",
      "       a        ",
      "       a        ",
      "     dba        ",
      "       a        ",
      "       a        "
    ],
    [
      "                ",
      "                ",
      "                ",
      "      a         ",
      "       ~        ",
      "                ",
      "                ",
      "                ",
      "      a         ",
      "                ",
      "                ",
      "                ",
      "                ",
      "      a         ",
      "       ~        ",
      "                "
    ],
    [
      "ee f            ",
      "ge f            ",
      "ge f            ",
      "ge f  h         ",
      "ge f            ",
      "ge f            ",
      "ge f            ",
      "ge f            ",
      "ge f  h         ",
      "ge f            ",
      "ge f            ",
      "ge f            ",
      "ge f            ",
      "ge f  h         ",
      "ge f            ",
      "ge f            "
    ],
    [
      "iijk            ",
      "iijk            ",
      "lijk  h         ",
      "iijk  hh        ",
      "iijk            ",
      "iljk            ",
      "iijk            ",
      "iijk  h         ",
      "lijk hh         ",
      "iijk  h         ",
      "iijk            ",
      "lijk            ",
      "iijk            ",
      "iijk hh         ",
      "iijk            ",
      "iljk            "
    ],
    [
      "  jm            ",
      "  jm            ",
      "  jm  h         ",
      "  jm hhh        ",
      "  jm  h         ",
      "  jm            ",
      "  jm            ",
      "  jm  h         ",
      "  jm hhh        ",
      "  jm  h         ",
      "  jm            ",
      "  jm            ",
      "  jm  h         ",
      "  jm hhh        ",
      "  jm            ",
      "  jm            "
    ],
    [
      "  n             ",
      "  n             ",
      "  n   h         ",
      "  n  hhh        ",
      "  n   h         ",
      "  n             ",
      "  n             ",
      "  n   h         ",
      "  n   h         ",
      "  n             ",
      "  n             ",
      "  n             ",
      "  n   h         ",
      "  n   hh        ",
      "  n   h         ",
      "  n             "
    ]
  ]
}