{
  "name": "multi_verticalschool_16_floor20",
  "refpalette": "deceasedcraft:multi_verticalschool_16/multi_verticalschool_16_floor20_palette",
  "xsize": 16,
  "zsize": 16,
  "slices": [
    [
      "  a             ",
      " ba             ",
      "  a             ",
      "  a             ",
      " ba             ",
      "  a             ",
      "  a             ",
      " ba             ",
      "  a             ",
      "  a             ",
      "  a             ",
      "  a             ",
      "  a             ",
      " ba             ",
      "  a             ",
      "  a             "
    ],
    [
      "  a             ",
      "  a             ",
      "  a             ",
      "  a             ",
      "  a             ",
      "  a             ",
      "  a             ",
      "  a             ",
      "  a             ",
      "  a             ",
      "  a             ",
      "  a             ",
      "  a             ",
      "  a             ",
      "  a             ",
      "  a             "
    ],
    [
      "ccad            ",
      "ccad            ",
      "ccad            ",
      "ccad            ",
      "ccad            ",
      "ccad            ",
      "ccad            ",
      "ccad            ",
      "ccad            ",
      "ccad            ",
      "ccad            ",
      "ccad            ",
      "ccad            ",
      "ccad            ",
      "ccad            ",
      "ccad            "
    ],
    [
      "eefg            ",
      "eefg            ",
      "eefg            ",
      "eefg            ",
      "eefg            ",
      "eefg            ",
      "eefg            ",
      "eefg            ",
      "eefg            ",
      "eefg            ",
      "eefg            ",
      "eefg            ",
      "eefg            ",
      "eefg            ",
      "eefg            ",
      "eefg            "
    ],
    [
      "hifj            ",
      "hkfj            ",
      "lifj            ",
      "hifj            ",
      "hkfj            ",
      "hifj            ",
      "hifj            ",
      "hkfj            ",
      "hifj            ",
      "hifj            ",
      "hkfj            ",
      "hifj            ",
      "hifj            ",
      "hkfj            ",
      "hifj            ",
      "lifj            "
    ],
    [
      "  a             ",
      " ma             ",
      "  a             ",
      "  a             ",
      " ma             ",
      "  a             ",
      "  a             ",
      " ma             ",
      "  a             ",
      "  a             ",
      " ma             ",
      "  a             ",
      "  a             ",
      " ma             ",
      "  a             ",
      "  a             "
    ]
  ]
}