{
  "name": "multi_verticalschool_16_floor29",
  "refpalette": "deceasedcraft:multi_verticalschool_16/multi_verticalschool_16_floor29_palette",
  "xsize": 16,
  "zsize": 16,
  "slices": [
    [
      "aabc            ",
      "aabc            ",
      "aabc            ",
      "aabc            ",
      "aabc            ",
      "aabc            ",
      "aabc            ",
      "aabc            ",
      "aabc            ",
      "aabc            ",
      "aabc            ",
      "aabc            ",
      "aabc            ",
      "aabc            ",
      "aabc            ",
      "aabc            "
    ],
    [
      "debf            ",
      "debf            ",
      "debf            ",
      "debf            ",
      "d bf            ",
      "dgbf            ",
      "hgbf            ",
      "debf            ",
      "debf            ",
      "debf            ",
      "debf            ",
      "d bf            ",
      "debf            ",
      "dgbf            ",
      "dgbf            ",
      "debf            "
    ],
    [
      "i j             ",
      "i j             ",
      "  j             ",
      "i j             ",
      "i j             ",
      "i j             ",
      "  j             ",
      "i j             ",
      "  j             ",
      "i j             ",
      "i j             ",
      "i j             ",
      "i j             ",
      "i j             ",
      "i j             ",
      "i j             "
    ],
    [
      "  j             ",
      "  j             ",
      "  j             ",
      "  j             ",
      "  j             ",
      "  j             ",
      "  j             ",
      "  j             ",
      "  j             ",
      "  j             ",
      "  j             ",
      "  j             ",
      "  j             ",
      "  j             ",
      "  j             ",
      "  j             "
    ],
    [
      "  j             ",
      "  j             ",
      "  j             ",
      "  j             ",
      "  j             ",
      "  j             ",
      "  j             ",
      "  j             ",
      "  j             ",
      "  j             ",
      "  j             ",
      "  j             ",
      "  j             ",
      "  j             ",
      "  j             ",
      "  j             "
    ],
    [
      "kkjl            ",
      "kkjl            ",
      "kkjl            ",
      "kkjl            ",
      "kkjl            ",
      "kkjl            ",
      "kkjl            ",
      "kkjl            ",
      "kkjl            ",
      "kkjl            ",
      "kkjl            ",
      "kkjl            ",
      "kkjl            ",
      "kkjl            ",
      "kkjl            ",
      "kkjl            "
    ]
  ]
}