{
  "name": "multi_verticalschool_16_ground",
  "refpalette": "deceasedcraft:multi_verticalschool_16/multi_verticalschool_16_ground_palette",
  "xsize": 16,
  "zsize": 16,
  "slices": [
    [
      "aaaaaaaaaaaaaaaa",
      "aaaaaaaaaaaaaaba",
      "aaaaaaaaaaaaaaaa",
      "aaaaaaaaaaaaaaaa",
      "aaaaaaaaaaaaaaaa",
      "aaaaaaaaaaaaaaaa",
      "aaaaaaaaaaaaaaaa",
      "aaaaaaaaaaaaaaaa",
      "aaaaaaaaaaaaaaaa",
      "aaaaaaaaaaaaaaaa",
      "cccccccccccccccc",
      "dddddddddddddddd",
      "dddddddddddddddd",
      "dddddddddddddddd",
      "ddddddddddddddee",
      "ddddddddddddeeff"
    ],
    [
      "ggggggggggggghhh",
      "ggggggggggggghih",
      "ggggggggggggghhh",
      "gggggggggggggggg",
      "gggggggggggggggg",
      "gggggggggggggggg",
      "gggggggggggggggg",
      "gggggggggggggggg",
      "gggggggggggggggg",
      "gggggggggggggggg",
      "jjjjjjjjjjjjjjjj",
      "kkkkkkkkkkkkkkkk",
      "                ",
      "                ",
      "              ll",
      "  m         llnn"
    ],
    [
      "    o           ",
      "   o o        p ",
      "    o           ",
      "         q r    ",
      "   s     t r    ",
      "  s s    t      ",
      "   s     uwwx   ",
      "                ",
      "                ",
      "  yyy y  yyyy   ",
      "ABCCCCDEBCCCCDAB",
      "FFFFFFFFFFFFFFFF",
      "                ",
      "                ",
      "                ",
      "                "
    ],
    [
      "              l ",
      "             ll ",
      "                ",
      "                ",
      "                ",
      "                ",
      "                ",
      "                ",
      "                ",
      "                ",
      " IJ  K  LM NM ! ",
      "OOOOOOOOOOOOOOOO",
      "                ",
      "                ",
      "                ",
      "                "
    ],
    [
      "              l ",
      "             lll",
      "              l ",
      "                ",
      "                ",
      "                ",
      "                ",
      "                ",
      "                ",
      "                ",
      "                ",
      "OOOOOOOOOOOOOOOO",
      "                ",
      "                ",
      "                ",
      "                "
    ],
    [
      "                ",
      "             ll ",
      "              l ",
      "                ",
      "                ",
      "                ",
      "                ",
      "                ",
      "                ",
      "                ",
      "PPPPPPPPPPPPPPPP",
      "FFFFFFFFFFFFFFFF",
      "                ",
      "                ",
      "                ",
      "                "
    ]
  ]
}