{
  "name": "multi_verticalschool_16_floor31",
  "refpalette": "deceasedcraft:multi_verticalschool_16/multi_verticalschool_16_floor31_palette",
  "xsize": 16,
  "zsize": 16,
  "slices": [
    [
      "  a             ",
      "  a             ",
      "  a             ",
      "  a             ",
      "  a             ",
      "  a             ",
      "  a             ",
      "  a             ",
      "  a             ",
      "  a             ",
      "  a             ",
      "  a             ",
      "  a             ",
      "  a             ",
      " ba             ",
      "  c             "
    ],
    [
      "  a             ",
      "  a             ",
      "  a             ",
      "  a             ",
      "  a             ",
      "  a             ",
      "  a             ",
      "  a             ",
      "  a             ",
      "  a             ",
      "  a             ",
      "  a             ",
      "  a             ",
      "  a             ",
      "  b             ",
      "                "
    ],
    [
      "  a             ",
      "  a             ",
      "  a             ",
      "  a             ",
      "  a             ",
      "  a             ",
      "  a             ",
      "  a             ",
      "  a             ",
      "  a             ",
      "  a             ",
      "  a             ",
      "  a             ",
      "  a             ",
      "  a             ",
      "  a             "
    ],
    [
      "  ad            ",
      "  ad            ",
      "  ad            ",
      "  ad            ",
      "  ad            ",
      "  ad            ",
      "  ad            ",
      "  ad            ",
      "  ad            ",
      "  ad            ",
      "  ad            ",
      "  ad            ",
      "  ad            ",
      "  ad            ",
      "  ad            ",
      "  ad            "
    ],
    [
      "eefg            ",
      "eefg            ",
      "eefg            ",
      "eefg            ",
      "eefg            ",
      "eefg            ",
      "eefg            ",
      "eefg            ",
      "eefg            ",
      "eefg            ",
      "eefg            ",
      "eefg            ",
      "eefg            ",
      "eefg            ",
      "eefg            ",
      "eefg            "
    ],
    [
      "gggg            ",
      "gggg            ",
      "gggg            ",
      "gggg            ",
      "gggg            ",
      "gggg            ",
      "gggg            ",
      "gggg            ",
      "gggg            ",
      "gggg            ",
      "gggg            ",
      "gggg            ",
      "gggg            ",
      "gggg            ",
      "gggg            ",
      "gggg            "
    ]
  ]
}