{
  "name": "multi_verticalschool_16_floor19",
  "refpalette": "deceasedcraft:multi_verticalschool_16/multi_verticalschool_16_floor19_palette",
  "xsize": 16,
  "zsize": 16,
  "slices": [
    [
      "  a             ",
      " ba             ",
      "  a             ",
      "  a             ",
      " ba             ",
      "  a             ",
      "  a             ",
      "  a             ",
      "  a             ",
      "  a             ",
      " ba             ",
      "  a             ",
      "  a             ",
      " ba             ",
      "  a             ",
      "  a             "
    ],
    [
      "  a             ",
      "  a             ",
      "  a             ",
      "  a             ",
      "  a             ",
      "  a             ",
      "  a             ",
      "  a             ",
      "  a             ",
      "  a             ",
      "  a             ",
      "  a             ",
      "  a             ",
      "  a             ",
      "  a             ",
      "  a             "
    ],
    [
      "ccad            ",
      "ccad            ",
      "ccad            ",
      "ccad            ",
      "ccad            ",
      "ccad            ",
      "ccad            ",
      "ccad            ",
      "ccad            ",
      "ccad            ",
      "ccad            ",
      "ccad            ",
      "ccad            ",
      "ccad            ",
      "ccad            ",
      "ccad            "
    ],
    [
      "eefg            ",
      "eefg            ",
      "eefg            ",
      "eefg            ",
      "eefg            ",
      "eefg            ",
      "eefg            ",
      "eefg            ",
      "eefg            ",
      "eefg            ",
      "eefg            ",
      "eefg            ",
      "eefg            ",
      "eefg            ",
      "eefg            ",
      "eefg            "
    ],
    [
      "hifj            ",
      "klfj            ",
      "kifj            ",
      "hifj            ",
      "hlfj            ",
      "hifj            ",
      "hifj            ",
      "hlfj            ",
      "hifj            ",
      "kifj            ",
      "hlfj            ",
      "hifj            ",
      "hifj            ",
      "klfj            ",
      "hifj            ",
      "hifj            "
    ],
    [
      "  a             ",
      " ma             ",
      "  a             ",
      "  a             ",
      " ma             ",
      "  a             ",
      "  a             ",
      " ma             ",
      "  a             ",
      "  a             ",
      " ma             ",
      "  a             ",
      "  a             ",
      " ma             ",
      "  a             ",
      "  a             "
    ]
  ]
}