{
  "name": "multi_verticalschool_16_floor9",
  "refpalette": "deceasedcraft:multi_verticalschool_16/multi_verticalschool_16_floor9_palette",
  "xsize": 16,
  "zsize": 16,
  "slices": [
    [
      "abbc            ",
      "ddbc            ",
      "bbbc            ",
      "bbbc            ",
      "bbbc            ",
      "bbbc            ",
      "bbbc            ",
      "bbbc            ",
      "bbbc            ",
      "bbbc            ",
      "bbbc            ",
      "bbbc            ",
      "bbbc            ",
      "bbbc            ",
      "bbbc            ",
      "bbbc  e         "
    ],
    [
      " ffc            ",
      "ggfc            ",
      "  hc            ",
      "   c            ",
      "   c            ",
      "   c            ",
      "   c            ",
      "   c            ",
      "   c            ",
      "   c            ",
      "   c            ",
      "   c            ",
      "   c            ",
      "   c            ",
      "   c            ",
      "   c  e         "
    ],
    [
      "gffc            ",
      "  fc            ",
      "   c            ",
      "   c            ",
      "   c            ",
      "   c            ",
      "   c            ",
      "   c            ",
      "   c            ",
      "   c            ",
      "   c            ",
      "   c            ",
      "   c            ",
      "   c            ",
      "   c            ",
      "   c            "
    ],
    [
      " ffc            ",
      "  fc            ",
      "   c            ",
      "   c            ",
      "   c            ",
      "   c            ",
      "   c            ",
      "   c            ",
      "   c            ",
      "   c            ",
      "   c            ",
      "   c            ",
      "   c            ",
      "   c            ",
      "   c            ",
      "   c            "
    ],
    [
      " ffc            ",
      "  fc            ",
      "iijc            ",
      "iijc            ",
      "iijc            ",
      "iijc            ",
      "iijc            ",
      "iijc            ",
      "iijc            ",
      "iijc            ",
      "iijc            ",
      "iijc            ",
      "iijc            ",
      "iijc            ",
      "iijc            ",
      "iijc            "
    ],
    [
      " ddc            ",
      "  dc            ",
      "kkdc            ",
      "kkdc            ",
      "kkdc            ",
      "kkdc            ",
      "kkdc            ",
      "kkdc            ",
      "kkdc            ",
      "kkdc            ",
      "kkdc            ",
      "kkdc            ",
      "kkdc            ",
      "kkdc            ",
      "kkdc            ",
      "kkdc            "
    ]
  ]
}