{
  "name": "multi_verticalschool_16_base1",
  "refpalette": "deceasedcraft:multi_verticalschool_16/multi_verticalschool_16_base1_palette",
  "xsize": 16,
  "zsize": 16,
  "slices": [
    [
      "            a   ",
      "                ",
      "            b   ",
      "           cdeff",
      "           cg hi",
      "           cj  k",
      "           c  hi",
      "           cdfff",
      "            a   ",
      "            b   ",
      "           cdeff",
      "           cg hi",
      "           cj  k",
      "           c  hi",
      "           cdfff",
      "            a   "
    ],
    [
      "            l   ",
      "                ",
      "            b   ",
      "           cdmno",
      "           c    ",
      "           c    ",
      "           c    ",
      "           cdooo",
      "            l   ",
      "            b   ",
      "           cdmno",
      "           c    ",
      "           c    ",
      "           c    ",
      "           cdooo",
      "            l   "
    ],
    [
      "                ",
      "                ",
      "                ",
      "            pqqq",
      "            rsss",
      "            rs!t",
      "            rsss",
      "            pqqq",
      "                ",
      "                ",
      "            pqqq",
      "            rsss",
      "            rs t",
      "            rsss",
      "            pqqq",
      "                "
    ],
    [
      "                ",
      "                ",
      "                ",
      "                ",
      "                ",
      "              u ",
      "                ",
      "                ",
      "                ",
      "                ",
      "                ",
      "                ",
      "              u ",
      "                ",
      "                ",
      "                "
    ],
    [
      "                ",
      "                ",
      "                ",
      "                ",
      "                ",
      "                ",
      "                ",
      "                ",
      "                ",
      "                ",
      "                ",
      "                ",
      "                ",
      "                ",
      "                ",
      "                "
    ],
    [
      "wwwwwwwwwwwwwwww",
      "wwwwwwwwwwwwwwww",
      "wwwwwwwwwwwwwwww",
      "wwwwwwwwwwwwwwww",
      "wwwwwwwwwwwwwwww",
      "wwwwwxxwwwwwwwxx",
      "wwwwwwwwwwwwwwww",
      "wwwwwwwwwwwwwwww",
      "wwwwwwwwwwwwwwww",
      "wwwwwwwwwwwwwwww",
      "wwwwwwwwwwwwwwww",
      "wwwwwwwwwwwwwwww",
      "wwwwwxxwwwwwwwxx",
      "wwwwwwwwwwwwwwww",
      "wwwwwwwwwwwwwwww",
      "wwwwwwwwwwwwwwyy"
    ]
  ]
}