{
  "name": "multi_verticalschool_16_floor3",
  "refpalette": "deceasedcraft:multi_verticalschool_16/multi_verticalschool_16_floor3_palette",
  "xsize": 16,
  "zsize": 16,
  "slices": [
    [
      "  a             ",
      "  a             ",
      "  a             ",
      "  a             ",
      "  a             ",
      "  a             ",
      "  a             ",
      "  a             ",
      "  a             ",
      "  a             ",
      "  a             ",
      "  a             ",
      "  a             ",
      "  a             ",
      "  a             ",
      "  a             "
    ],
    [
      "  a             ",
      "  a             ",
      "  a             ",
      "  a             ",
      "  a             ",
      "  a             ",
      "  a             ",
      "  a             ",
      "  a             ",
      "  a             ",
      "  a             ",
      "  a             ",
      "  a             ",
      "  a             ",
      "  a             ",
      "  a             "
    ],
    [
      "  a             ",
      "  a             ",
      "  a             ",
      "  a             ",
      "  a             ",
      "  a             ",
      "  a             ",
      "  a             ",
      "  a             ",
      "  a             ",
      "  a             ",
      "  a             ",
      "  a             ",
      "  a             ",
      "  a             ",
      "  a             "
    ],
    [
      "  ab            ",
      "  ab            ",
      "  ab            ",
      "  ab            ",
      "  ab            ",
      "  ab            ",
      "  ab            ",
      "  ab            ",
      "  ab            ",
      "  ab            ",
      "  ab            ",
      "  ab            ",
      "  ab            ",
      "  ab            ",
      "  ab            ",
      "  ab            "
    ],
    [
      "ccde            ",
      "ccde            ",
      "ccde            ",
      "ccde            ",
      "ccde            ",
      "ccde            ",
      "ccde            ",
      "ccde            ",
      "ccde            ",
      "ccde            ",
      "ccde            ",
      "ccde            ",
      "ccde            ",
      "ccde            ",
      "ccde            ",
      "ccde            "
    ],
    [
      "fddg            ",
      "ffdg            ",
      "hfdg            ",
      "hfdg            ",
      "hfdg            ",
      "hfdg            ",
      "hfdg            ",
      "hfdg            ",
      "hfdg            ",
      "hfdg            ",
      "hfdg            ",
      "hfdg            ",
      "hfdg            ",
      "hfdg            ",
      "hfdg            ",
      "hfdg            "
    ]
  ]
}