{
  "name": "multi_verticalschool_16_floor26",
  "refpalette": "deceasedcraft:multi_verticalschool_16/multi_verticalschool_16_floor26_palette",
  "xsize": 16,
  "zsize": 16,
  "slices": [
    [
      "aabc            ",
      "aabc            ",
      "aabc            ",
      "aabc            ",
      "aabc            ",
      "aabc            ",
      "aabc            ",
      "aabc            ",
      "aabc            ",
      "aabc            ",
      "aabc            ",
      "aabc            ",
      "aabc            ",
      "aabc            ",
      "aabc            ",
      "aabc            "
    ],
    [
      "debf            ",
      "debf            ",
      "dgbf            ",
      "debf            ",
      "debf            ",
      "d bf            ",
      "debf            ",
      "debf            ",
      "dgbf            ",
      "debf            ",
      "debf            ",
      "dgbf            ",
      "hebf            ",
      "debf            ",
      "d bf            ",
      "d bf            "
    ],
    [
      "  i             ",
      "j i             ",
      "j i             ",
      "j i             ",
      "  i             ",
      "j i             ",
      "j i             ",
      "j i             ",
      "j i             ",
      "j i             ",
      "j i             ",
      "j i             ",
      "  i             ",
      "j i             ",
      "  i             ",
      "j i             "
    ],
    [
      "  i             ",
      "  i             ",
      "  i             ",
      "  i             ",
      "  i             ",
      "  i             ",
      "  i             ",
      "  i             ",
      "  i             ",
      "  i             ",
      "  i             ",
      "  i             ",
      "  i             ",
      "  i             ",
      "  i             ",
      "  i             "
    ],
    [
      "  i             ",
      "  i             ",
      "  i             ",
      "  i             ",
      "  i             ",
      "  i             ",
      "  i             ",
      "  i             ",
      "  i             ",
      "  i             ",
      "  i             ",
      "  i             ",
      "  i             ",
      "  i             ",
      "  i             ",
      "  i             "
    ],
    [
      "kkil            ",
      "kkil            ",
      "kkil            ",
      "kkil            ",
      "kkil            ",
      "kkil            ",
      "kkil            ",
      "kkil            ",
      "kkil            ",
      "kkil            ",
      "kkil            ",
      "kkil            ",
      "kkil            ",
      "kkil            ",
      "kkil            ",
      "kkil            "
    ]
  ]
}