{
  "name": "multi_verticalschool_16_floor10",
  "refpalette": "deceasedcraft:multi_verticalschool_16/multi_verticalschool_16_floor10_palette",
  "xsize": 16,
  "zsize": 16,
  "slices": [
    [
      " aab            ",
      "ccab            ",
      "  ab            ",
      "  ab            ",
      "  ab            ",
      "  ab            ",
      "  ab            ",
      "  ab            ",
      "  ab            ",
      "  ab            ",
      "  ab            ",
      "  ab            ",
      "  ab            ",
      "  ab            ",
      "  ab            ",
      "  ab            "
    ],
    [
      "                ",
      "                ",
      "                ",
      "                ",
      "                ",
      "                ",
      "                ",
      "                ",
      "                ",
      "                ",
      "                ",
      "                ",
      "                ",
      "                ",
      "                ",
      "                "
    ],
    [
      "                ",
      "                ",
      "                ",
      "                ",
      "                ",
      "ddddddddddd     ",
      "           dd   ",
      "eeeeeeeeeee  d  ",
      "ffffffffffee d  ",
      "eeeeeeeeeefee d ",
      "eeeeeeeeeeefe d ",
      "eeeeeeeeeeefe d ",
      "eeeeeeeeeeefe d ",
      "eeeeeeeeeeefe d ",
      "eeeeeeeeeeefe d ",
      "eeeeeeeeeeefe d "
    ],
    [
      "                ",
      "                ",
      "                ",
      "                ",
      "                ",
      "ggggggggggg     ",
      "hhhhhhhhhhhgg   ",
      "iiiiiiiiiiihhg  ",
      "iiiiiiiiiiiihg  ",
      "iiiiiiiiiiiiihg ",
      "iiiiiiiiiiiiihg ",
      "iiijjjjjjiiiihg ",
      "iiijjjjjjiiiihg ",
      "iiijjjjjjiiiihg ",
      "iiijjjjjjiiiihg ",
      "iiijjjjjjiiiihg "
    ],
    [
      "                ",
      "                ",
      "                ",
      "                ",
      "                ",
      "bbbbbbbbbbb     ",
      "hhhhhhhhhhhbb   ",
      "     kl    hhb  ",
      "            hb  ",
      "             hb ",
      "             hb ",
      "             hb ",
      "    mmmm    nhb ",
      "    mmmm    ohb ",
      "    mmmm    phb ",
      "             hb "
    ],
    [
      "                ",
      "                ",
      "                ",
      "                ",
      "                ",
      "                ",
      "qqqqqqqqqqq     ",
      "           qq   ",
      "            q   ",
      "             q  ",
      "             q  ",
      "             q  ",
      "             q  ",
      "    r sr     q  ",
      "             q  ",
      "             q  "
    ]
  ]
}