{
  "name": "multi_verticalschool_16_floor1",
  "refpalette": "deceasedcraft:multi_verticalschool_16/multi_verticalschool_16_floor1_palette",
  "xsize": 16,
  "zsize": 16,
  "slices": [
    [
      "                ",
      "  a     a     b ",
      "                ",
      "                ",
      "                ",
      "                ",
      "                ",
      "  a     a     a ",
      "                ",
      "                ",
      "cccccccccccccccc",
      "dddddddddddddddd",
      "                ",
      "                ",
      "                ",
      "  b             "
    ],
    [
      "efffffffffg     ",
      "efhfffffhfg     ",
      "efffffffffg     ",
      "effffffffffg    ",
      "effffffffffgg   ",
      "effffffffffffggg",
      "efffffffffffffff",
      "efhfffffhfffffhf",
      "efffffffffffffff",
      "eeeeeeeeeeeeeeee",
      "iiiiiiiiiiiiiiii",
      "dddddddddddddddd",
      "                ",
      "                ",
      "                ",
      "  b             "
    ],
    [
      "jjjjjjjjjjkfllll",
      "jjjjjjjjjjkfllll",
      "jjjjjjjjjjkfllll",
      "jjjjjjjjjjjkflll",
      "jjjjjjjjjmjkkfff",
      "jjjjmmjjjjjjjkkk",
      "mmmmmmmmmmmmjjmm",
      "mmmmmmmmmmmmmmmm",
      "jmjmjjjjjjmjmmmj",
      "kkkkkkkkkkkkkkkk",
      "nnnnnnnnnnnnnnnn",
      "dddddddddddddddd",
      "                ",
      "                ",
      "                ",
      "                "
    ],
    [
      "          o     ",
      "          p     ",
      "          p     ",
      "           p    ",
      "           pp   ",
      "             ppp",
      "                ",
      "                ",
      "                ",
      "qqqqqqqqqqqqqqqq",
      "rrrrrrrrrrrrrrrr",
      "ssssssssssssssss",
      "                ",
      "                ",
      "                ",
      "                "
    ],
    [
      "                ",
      "                ",
      "                ",
      "                ",
      "                ",
      "                ",
      "                ",
      "                ",
      "                ",
      "tt ttttttttttt t",
      "                ",
      "                ",
      "                ",
      "                ",
      "                ",
      "                "
    ],
    [
      "                ",
      "                ",
      "                ",
      "                ",
      "                ",
      "                ",
      "                ",
      "                ",
      "                ",
      "                ",
      "                ",
      "                ",
      "                ",
      "                ",
      "                ",
      "                "
    ]
  ]
}