{
  "name": "multi_verticalschool_16_floor16",
  "refpalette": "deceasedcraft:multi_verticalschool_16/multi_verticalschool_16_floor16_palette",
  "xsize": 16,
  "zsize": 16,
  "slices": [
    [
      "  a             ",
      "  a             ",
      "  a   b         ",
      "  a   b         ",
      "  a             ",
      "  a             ",
      "  a             ",
      "  a  ~          ",
      "  a   b         ",
      "  a             ",
      "  a             ",
      "  a             ",
      "  a   b         ",
      "  a   b         ",
      "  a             ",
      "  a             "
    ],
    [
      "  a             ",
      "  a             ",
      "  a  ~          ",
      "  a   b         ",
      "  a             ",
      "  a             ",
      "  a             ",
      "  a             ",
      "  a             ",
      "  a             ",
      "  a             ",
      "  a             ",
      "  a  ~          ",
      "  a   b         ",
      "  a             ",
      "  a             "
    ],
    [
      "  a             ",
      "  a             ",
      "  a             ",
      "  a             ",
      "  a             ",
      "  a             ",
      "  a             ",
      "  a             ",
      "  a             ",
      "  a             ",
      "  a             ",
      "  a             ",
      "  a             ",
      "  a             ",
      "  a             ",
      "  a             "
    ],
    [
      "ccad            ",
      "ccad            ",
      "ccad            ",
      "ccad            ",
      "ccad            ",
      "ccad            ",
      "ccad            ",
      "ccad            ",
      "ccad            ",
      "ccad            ",
      "ccad            ",
      "ccad            ",
      "ccad            ",
      "ccad            ",
      "ccad            ",
      "ccad            "
    ],
    [
      "cefg            ",
      "cefg            ",
      "cefg            ",
      "chfg            ",
      "chfg            ",
      "cefg            ",
      "cefg            ",
      "cefg            ",
      "chfg            ",
      "chfg            ",
      "cefg            ",
      "cefg            ",
      "cefg            ",
      "chfg            ",
      "chfg            ",
      "cefg            "
    ],
    [
      "ggfi            ",
      "ggfi            ",
      "ggfi            ",
      "ggfi            ",
      "ggfi            ",
      "ggfi            ",
      "ggfi            ",
      "ggfi            ",
      "ggfi            ",
      "ggfi            ",
      "ggfi            ",
      "ggfi            ",
      "ggfi            ",
      "ggfi            ",
      "ggfi            ",
      "ggfi            "
    ]
  ]
}