{
  "name": "multi_verticalschool_16_floor11",
  "refpalette": "deceasedcraft:multi_verticalschool_16/multi_verticalschool_16_floor11_palette",
  "xsize": 16,
  "zsize": 16,
  "slices": [
    [
      "                ",
      "                ",
      "                ",
      "                ",
      "                ",
      "                ",
      "aaaaaaaaaaa     ",
      "           aa   ",
      "            a   ",
      "             a  ",
      "             a  ",
      "             a  ",
      "             a  ",
      "     b       a  ",
      "             a  ",
      "             a  "
    ],
    [
      "                ",
      "                ",
      "                ",
      "                ",
      "                ",
      "                ",
      "aaaaaaaaaaa     ",
      "           aa   ",
      "            a   ",
      "             a  ",
      "             a  ",
      "             a  ",
      "             a  ",
      "     cd      a  ",
      "             a  ",
      "             a  "
    ],
    [
      "                ",
      "                ",
      "                ",
      "                ",
      "                ",
      "                ",
      "aaaaaaaaaaa     ",
      "           aa   ",
      "            a   ",
      "             a  ",
      "             a  ",
      "             a  ",
      "             a  ",
      "     cc      a  ",
      "             a  ",
      "             a  "
    ],
    [
      "                ",
      "                ",
      "                ",
      "                ",
      "                ",
      "eeeeeeeeeee     ",
      "aaaaaaaaaaaee   ",
      "           aae  ",
      "            ae  ",
      "             ae ",
      "             ae ",
      "             ae ",
      "             ae ",
      "     cc      ae ",
      "             ae ",
      "             ae "
    ],
    [
      "                ",
      "                ",
      "                ",
      "                ",
      "                ",
      "fffffffffff     ",
      "gggggggggggff   ",
      "hhhhhhhhhhhggf  ",
      "iiiiiiiiiiihgf  ",
      "iiiiiiiiiiiihgf ",
      "iiiiiiiiiiiihgf ",
      "iiiiiiiiiiiihgf ",
      "iiiijjjjiiiihgf ",
      "iiiijiijiiiihgf ",
      "iiiijjjjiiiihgf ",
      "iiiiiiiiiiiihgf "
    ],
    [
      "                ",
      "                ",
      "                ",
      "                ",
      "                ",
      "kkkkkkkkkkk     ",
      "gggggggggggkk   ",
      "llllllllllgggk  ",
      "mmmmmmmmmlllgk  ",
      "nmmmmmmmmmmlggk ",
      "nnnnmmmmmmmllgk ",
      "nnnnnmmmmmmmlgk ",
      "nnnnnnnmmmmmlgk ",
      "mnnnnnnnmmmmlgk ",
      "mmmnnnnnmmmmlgk ",
      "mmmmnnnnnmmmlgk "
    ]
  ]
}