{
  "name": "multi_verticalschool_16_floor13",
  "refpalette": "deceasedcraft:multi_verticalschool_16/multi_verticalschool_16_floor13_palette",
  "xsize": 16,
  "zsize": 16,
  "slices": [
    [
      "                ",
      "                ",
      "                ",
      "                ",
      "                ",
      "                ",
      "                ",
      "                ",
      "                ",
      "                ",
      "                ",
      "                ",
      "                ",
      "                ",
      "                ",
      "                "
    ],
    [
      "                ",
      "                ",
      "                ",
      "                ",
      "                ",
      "                ",
      "                ",
      "                ",
      "                ",
      "                ",
      "                ",
      "                ",
      "                ",
      "                ",
      "                ",
      "                "
    ],
    [
      "aaaaaaba c      ",
      "aaaaaaba c      ",
      "aaaaaaba c      ",
      "aaaaaaba c      ",
      "aaaaaaba c      ",
      "aaaaaaba c      ",
      "aaaaaaba c      ",
      "aaaaaaba c      ",
      "aaaaaaba c      ",
      "aaaaaaba c      ",
      "aaaaaaba c      ",
      "aaaaaaba c      ",
      "aaaaaaba c      ",
      "aaaaaaba c      ",
      "aaaaaaba c      ",
      "aaaaaaba c      "
    ],
    [
      "dddddddddef     ",
      "ggggggggdef     ",
      "hhhhgddddef     ",
      "hhhhgddddef     ",
      "hhhhgddddef     ",
      "hhhhgddddef     ",
      "hhhhgddddef     ",
      "hhhhgddddef     ",
      "hhhhgddddef     ",
      "hhhhgddddef     ",
      "hhhhgddddef     ",
      "hhhhgddddef     ",
      "hhhhgddddef     ",
      "hhhhgddddef     ",
      "hhhhgddddef     ",
      "hhhhgddddef     "
    ],
    [
      "iiiii iiief     ",
      "gggggggggef     ",
      "jjjjg   kef     ",
      "    g  l ef     ",
      "    g   kef     ",
      "mmmmg  l ef     ",
      "jjjjg  n ef     ",
      "    o   pef     ",
      "   qo   oef     ",
      "   qor  sef     ",
      "    o   sef     ",
      "mmmmg   oef     ",
      "jjjjg   tef     ",
      "    u   tef     ",
      "    w   tef     ",
      "mmmmg   tef     "
    ],
    [
      "xyABx !CDef     ",
      "gggggggggef     ",
      " E Eg F  ef     ",
      "    g    ef     ",
      "    g    ef     ",
      "IJJIg    Kf     ",
      "LMLLg    Kf     ",
      "    N    Kf     ",
      "    O   Pef     ",
      "         ef     ",
      "         ef     ",
      "JIJIg   Qef     ",
      "LMLLg   Ref     ",
      "    S   TKf     ",
      "    U   VKf     ",
      " W  g    ef     "
    ]
  ]
}