{
  "name": "multi_verticalschool_16_floor8",
  "refpalette": "deceasedcraft:multi_verticalschool_16/multi_verticalschool_16_floor8_palette",
  "xsize": 16,
  "zsize": 16,
  "slices": [
    [
      "                ",
      "                ",
      "                ",
      "                ",
      "                ",
      "                ",
      "                ",
      "                ",
      "                ",
      "                ",
      "aaaaaa          ",
      "bbbbbbaa        ",
      "      bba       ",
      "       cba      ",
      "        ba      ",
      "         ba     "
    ],
    [
      "                ",
      "                ",
      "                ",
      "                ",
      "                ",
      "                ",
      "                ",
      "                ",
      "                ",
      "                ",
      "aaaaaa          ",
      "bbbbbbaa        ",
      "ddddddbba       ",
      "eeeeeeddba      ",
      "eeeeeeedba      ",
      "eeeeeeeedba     "
    ],
    [
      "                ",
      "                ",
      "                ",
      "                ",
      "                ",
      "                ",
      "                ",
      "                ",
      "                ",
      "                ",
      "aaaaaa          ",
      "bbbbbbaa        ",
      "bbbbbbbba       ",
      "ffffffbbba      ",
      "gggggffbba      ",
      "ggggggffbba     "
    ],
    [
      "                ",
      "                ",
      "                ",
      "                ",
      "                ",
      "                ",
      "                ",
      "                ",
      "                ",
      "                ",
      "                ",
      "                ",
      "                ",
      "hhhhhh          ",
      "     hh         ",
      "      hi        "
    ],
    [
      "                ",
      "                ",
      "                ",
      "                ",
      "                ",
      "                ",
      "                ",
      "                ",
      "                ",
      "                ",
      "                ",
      "                ",
      "                ",
      "                ",
      "                ",
      "                "
    ],
    [
      "jj k            ",
      "lj k            ",
      "lj k            ",
      "lj k            ",
      "lj k            ",
      "lj k            ",
      "lj k            ",
      "lj k            ",
      "lj k            ",
      "lj k            ",
      "lj k            ",
      "lj k            ",
      "lj k            ",
      "lj k            ",
      "lj k            ",
      "lj k            "
    ]
  ]
}