{
  "name": "multi_verticalschool_16_floor27",
  "refpalette": "deceasedcraft:multi_verticalschool_16/multi_verticalschool_16_floor27_palette",
  "xsize": 16,
  "zsize": 16,
  "slices": [
    [
      "aabc            ",
      "aabc            ",
      "aabc            ",
      "aabc            ",
      "aabc            ",
      "aabc            ",
      "aabc            ",
      "aabc            ",
      "aabc            ",
      "aabc            ",
      "aabc            ",
      "aabc            ",
      "aabc            ",
      "aabc            ",
      "aabc            ",
      "aabc            "
    ],
    [
      "debf            ",
      "debf            ",
      "debf            ",
      "debf            ",
      "ghbf            ",
      "d bf            ",
      "dhbf            ",
      "debf            ",
      "d bf            ",
      "debf            ",
      "debf            ",
      "debf            ",
      "debf            ",
      "gebf            ",
      "debf            ",
      "debf            "
    ],
    [
      "i j             ",
      "i j             ",
      "i j             ",
      "i j             ",
      "  j             ",
      "i j             ",
      "  j             ",
      "i j             ",
      "i j             ",
      "i j             ",
      "  j             ",
      "i j             ",
      "i j             ",
      "  j             ",
      "i j             ",
      "  j             "
    ],
    [
      "  j             ",
      "  j             ",
      "  j             ",
      "  j             ",
      "  j             ",
      "  j             ",
      "  j             ",
      "  j             ",
      "  j             ",
      "  j             ",
      "  j             ",
      "  j             ",
      "  j             ",
      "  j             ",
      "  j             ",
      "  j             "
    ],
    [
      "  j             ",
      "  j             ",
      "  j             ",
      "  j             ",
      "  j             ",
      "  j             ",
      "  j             ",
      "  j             ",
      "  j             ",
      "  j             ",
      "  j             ",
      "  j             ",
      "  j             ",
      "  j             ",
      "  j             ",
      "  j             "
    ],
    [
      "kkjl            ",
      "kkjl            ",
      "kkjl            ",
      "kkjl            ",
      "kkjl            ",
      "kkjl            ",
      "kkjl            ",
      "kkjl            ",
      "kkjl            ",
      "kkjl            ",
      "kkjl            ",
      "kkjl            ",
      "kkjl            ",
      "kkjl            ",
      "kkjl            ",
      "kkjl            "
    ]
  ]
}