{
  "name": "multi_verticalschool_16_floor14",
  "refpalette": "deceasedcraft:multi_verticalschool_16/multi_verticalschool_16_floor14_palette",
  "xsize": 16,
  "zsize": 16,
  "slices": [
    [
      "         ab     ",
      "cccccccccab     ",
      "ddddc    ab     ",
      "    c    ab     ",
      "    c    ab     ",
      "    c    ab     ",
      "    c    ab     ",
      "    e    ab     ",
      "    e    ab     ",
      "    e    ab     ",
      "    e    ab     ",
      "    c    ab     ",
      "    c    ab     ",
      "    e    ab     ",
      "    e    ab     ",
      "ffffc    ab     "
    ],
    [
      "         ab     ",
      "cccccccccab     ",
      "g g!c    ab     ",
      "    c    ab     ",
      "    c    ab     ",
      "    c    ab     ",
      "    c    ab     ",
      "    c    ab     ",
      "    c    ab     ",
      "    c    ab     ",
      "    c    ab     ",
      "    c    ab     ",
      "    c    ab     ",
      "    c    ab     ",
      "    c    ab     ",
      " h hc    ab     "
    ],
    [
      "         ab     ",
      "cccccccccab     ",
      "    c    ab     ",
      "    c    ab     ",
      "    c    ab     ",
      "    c    ab     ",
      "    c    ab     ",
      "    c    ab     ",
      "    c    ab     ",
      "    c    ab     ",
      "    c    ab     ",
      "    c    ab     ",
      "    c    ab     ",
      "    c    ab     ",
      "    c    ab     ",
      "    c    ab     "
    ],
    [
      "         ab     ",
      "cccccccccab     ",
      "    c    ab     ",
      "    c    ab     ",
      "    c    ab     ",
      "    c    ab     ",
      "    c    ab     ",
      "    c    ab     ",
      "    c    ab     ",
      "    c    ab     ",
      "    c    ab     ",
      "    c    ab     ",
      "    c    ab     ",
      "    c    ab     ",
      "    c    ab     ",
      "    c    ab     "
    ],
    [
      "iiiiiiiiiab     ",
      "cccccccccab     ",
      "jjjjckkkkab     ",
      "jjjjckkkkab     ",
      "lljjckmmkab     ",
      "jjjjckkkkab     ",
      "jjjjckkkkab     ",
      "nnjjckmmkab     ",
      "jjjjckkkkab     ",
      "jjjjckkkkab     ",
      "lljjckmmkab     ",
      "jjjjckkkkab     ",
      "jjjjckkkkab     ",
      "lljjckmmkab     ",
      "jjjjckkkkab     ",
      "jjjjckkkkab     "
    ],
    [
      "ooooooopaab     ",
      "ooooooopaab     ",
      "ooooooopaab     ",
      "ooooooopaab     ",
      "ooooooopaab     ",
      "ooooooopaab     ",
      "ooooooopaab     ",
      "ooooooopaab     ",
      "ooooooopaab     ",
      "ooooooopaab     ",
      "ooooooopaab     ",
      "ooooooopaab     ",
      "ooooooopaab     ",
      "ooooooopaab     ",
      "ooooooopaab     ",
      "ooooooopaab     "
    ]
  ]
}