{
  "name": "multi_verticalschool_16_floor17",
  "refpalette": "deceasedcraft:multi_verticalschool_16/multi_verticalschool_16_floor17_palette",
  "xsize": 16,
  "zsize": 16,
  "slices": [
    [
      "                ",
      "                ",
      "                ",
      "                ",
      "                ",
      "                ",
      "                ",
      "                ",
      "                ",
      "                ",
      "                ",
      "                ",
      "                ",
      "                ",
      "                ",
      "                "
    ],
    [
      "                ",
      "                ",
      "                ",
      "                ",
      "                ",
      "                ",
      "                ",
      "                ",
      "                ",
      "                ",
      "                ",
      "                ",
      "                ",
      "                ",
      "                ",
      "                "
    ],
    [
      "aa b            ",
      "ca b            ",
      "ca b            ",
      "ca b            ",
      "ca b            ",
      "ca b            ",
      "ca b            ",
      "ca b            ",
      "ca b            ",
      "ca b            ",
      "ca b            ",
      "ca b            ",
      "ca b            ",
      "ca b            ",
      "ca b            ",
      "ca b            "
    ],
    [
      "ddef            ",
      "ddef            ",
      "ddef            ",
      "ddef            ",
      "ddef            ",
      "ddef            ",
      "ddef            ",
      "ddef            ",
      "ddef            ",
      "ddef            ",
      "ddef            ",
      "ddef            ",
      "ddef            ",
      "ddef            ",
      "ddef            ",
      "ddef            "
    ],
    [
      "ghei            ",
      "jkei            ",
      "jhei            ",
      "jhei            ",
      "jkei            ",
      "ghei            ",
      "ghei            ",
      "jkei            ",
      "jhei            ",
      "jhei            ",
      "jkei            ",
      "jhei            ",
      "jhei            ",
      "jkei            ",
      "jhei            ",
      "ghei            "
    ],
    [
      "  l             ",
      " ml             ",
      "  l             ",
      "  l             ",
      " ml             ",
      "  l             ",
      "  l             ",
      " ml             ",
      "  l             ",
      "  l             ",
      " ml             ",
      "  l             ",
      "  l             ",
      " ml             ",
      "  l             ",
      "  l             "
    ]
  ]
}