{
  "name": "multi_oasiscondo_12_floor9",
  "refpalette": "deceasedcraft:multi_oasiscondo_12/multi_oasiscondo_12_floor9_palette",
  "xsize": 16,
  "zsize": 16,
  "slices": [
    [
      "                ",
      "                ",
      "                ",
      "                ",
      "                ",
      "                ",
      "                ",
      "                ",
      "                ",
      "aaabb           ",
      "ccddce          ",
      "cdccfcg         ",
      "dcdcchg         ",
      "cdddcfa         ",
      "cccdcca         ",
      "icddcca         "
    ],
    [
      "                ",
      "                ",
      "                ",
      "                ",
      "                ",
      "                ",
      "                ",
      "jjjk            ",
      "llljjk          ",
      "lllllkk         ",
      " m  nekk        ",
      "o     lp        ",
      "   qrmlpk       ",
      "    m llp       ",
      "m    ollp       ",
      " s   mllp       "
    ],
    [
      "                ",
      "                ",
      "                ",
      "                ",
      "                ",
      "                ",
      "                ",
      "tttt            ",
      "   ttt          ",
      "     tt         ",
      "     ett        ",
      "q      t        ",
      "   m m tt       ",
      "        t       ",
      "     q  t       ",
      "        t       "
    ],
    [
      "                ",
      "                ",
      "                ",
      "                ",
      "                ",
      "                ",
      "                ",
      "                ",
      "                ",
      "                ",
      "     e          ",
      "n               ",
      "                ",
      "                ",
      "     m          ",
      "                "
    ],
    [
      "                ",
      "                ",
      "                ",
      "                ",
      "                ",
      "                ",
      "                ",
      "                ",
      "uuuu            ",
      "   wu           ",
      "     e          ",
      "      x         ",
      "      yx        ",
      "       x        ",
      "     m x        ",
      "       x        "
    ],
    [
      "                ",
      "                ",
      "                ",
      "                ",
      "                ",
      "                ",
      "                ",
      "kkkk            ",
      "kkkkkk          ",
      "kkkkkkk         ",
      "AAAAAekk        ",
      "AAAAAAkk        ",
      "AAAAAAkkk       ",
      "AAAAAAkkk       ",
      "AAAAAAkkk       ",
      "AAAAAAkkk       "
    ]
  ]
}