{
  "name": "multi_oasiscondo_12_floor4",
  "refpalette": "deceasedcraft:multi_oasiscondo_12/multi_oasiscondo_12_floor4_palette",
  "xsize": 16,
  "zsize": 16,
  "slices": [
    [
      "                ",
      "                ",
      "                ",
      "                ",
      "                ",
      "                ",
      "                ",
      "                ",
      "                ",
      "aaabb           ",
      "aaaaac          ",
      "aaadaae         ",
      "aaaadae         ",
      "aaaadda         ",
      "aaaaaaa         ",
      "faaaaaa         "
    ],
    [
      "                ",
      "                ",
      "                ",
      "                ",
      "                ",
      "                ",
      "                ",
      "                ",
      "gfgh            ",
      "ijfff           ",
      "  klmc          ",
      "nnko pf         ",
      "qrks tfu        ",
      "wwx   ff        ",
      "  kyyAyf        ",
      "f B   Cg        "
    ],
    [
      "                ",
      "                ",
      "                ",
      "                ",
      "                ",
      "                ",
      "                ",
      "                ",
      "DDD             ",
      "EFDDf           ",
      "  k Ic          ",
      "  k   f         ",
      "JKkL  D         ",
      "  MNO DD        ",
      "  kyyPyD        ",
      "f Q   RD        "
    ],
    [
      "                ",
      "                ",
      "                ",
      "                ",
      "                ",
      "                ",
      "                ",
      "                ",
      "DDD             ",
      "  DDf           ",
      "  k Sc          ",
      "  k   g         ",
      "  kT  D         ",
      "  U   DD        ",
      "  kyyVyD        ",
      "f W    D        "
    ],
    [
      "                ",
      "                ",
      "                ",
      "                ",
      "                ",
      "                ",
      "                ",
      "                ",
      "DDD             ",
      "  DDf           ",
      "X k Xc          ",
      "  kYYYf         ",
      "  kYYYD         ",
      "Z kYYYDD        ",
      "  kyyyyD        ",
      "f k    D        "
    ],
    [
      "                ",
      "                ",
      "                ",
      "                ",
      "                ",
      "                ",
      "                ",
      "                ",
      "fffh            ",
      "00ffg           ",
      "00000c          ",
      "000  1f         ",
      "000   fu        ",
      "000   ff        ",
      "0000000f        ",
      "f000000g        "
    ]
  ]
}