{
  "name": "multi_oasiscondo_12_floor7",
  "refpalette": "deceasedcraft:multi_oasiscondo_12/multi_oasiscondo_12_floor7_palette",
  "xsize": 16,
  "zsize": 16,
  "slices": [
    [
      "                ",
      "                ",
      "                ",
      "                ",
      "                ",
      "                ",
      "                ",
      "                ",
      "                ",
      "aaabb           ",
      "aaaaac          ",
      "aaaaaad         ",
      "aaaaaad         ",
      "aaaaaaa         ",
      "aaaaaaa         ",
      "eaaaaaa         "
    ],
    [
      "                ",
      "                ",
      "                ",
      "                ",
      "                ",
      "                ",
      "                ",
      "                ",
      "eefg            ",
      "hiejf           ",
      "klm lc          ",
      "n op qf         ",
      "  r s et        ",
      "uwxyAAee        ",
      "BumCDDEe        ",
      "e F IJKf        "
    ],
    [
      "                ",
      "                ",
      "                ",
      "                ",
      "                ",
      "                ",
      "                ",
      "                ",
      "LLL             ",
      " kLLM           ",
      "  m Nc          ",
      "      f         ",
      "  !   L         ",
      "  x OPLL        ",
      "  mQDDDL        ",
      "e R   SL        "
    ],
    [
      "                ",
      "                ",
      "                ",
      "                ",
      "                ",
      "                ",
      "                ",
      "                ",
      "LLL             ",
      "  LLf           ",
      "  m Tc          ",
      "  x   U         ",
      "  o   L         ",
      "  m VWLL        ",
      "  mXDDDL        ",
      "e Y    L        "
    ],
    [
      "                ",
      "                ",
      "                ",
      "                ",
      "                ",
      "                ",
      "                ",
      "                ",
      "LLL             ",
      "  LLe           ",
      "Z m Zc          ",
      "  m000M         ",
      "  m000L         ",
      "1 x000LL        ",
      "  mDDDDL        ",
      "e m    L        "
    ],
    [
      "                ",
      "                ",
      "                ",
      "                ",
      "                ",
      "                ",
      "                ",
      "                ",
      "efeg            ",
      "22eef           ",
      "22222c          ",
      "222  3f         ",
      "222   e4        ",
      "222   ef        ",
      "2222222e        ",
      "e222222e        "
    ]
  ]
}