{
  "name": "multi_oasiscondo_12_base1",
  "refpalette": "deceasedcraft:multi_oasiscondo_12/multi_oasiscondo_12_base1_palette",
  "xsize": 16,
  "zsize": 16,
  "slices": [
    [
      "vvvvvvvvvvvvvvvv",
      "HHHHaavbbbbbbbbv",
      "HHHHaavbbbbbbbbv",
      "HHHHaavbbbbbbbbv",
      "HHHHaavbbbbbbbbv",
      "HHHHaavbbbbbbbbv",
      "HHHHaavbbbbbbbbv",
      "HHHHaavbbbbbbbbv",
      "HHHHaavbbbbbbbbv",
      "HHHHaavvvvvvvvvv",
      "HHHHacaaaaaaaaav",
      "HHHHHaaaaaaaaaav",
      "HHHHHHHHHHHHHHHv",
      "HHHHHHHHHHHHHHHv",
      "HHHHHHHHHHHHHHHv",
      "HHHHHHHHHHHHHHHv"
    ],
    [
      "vvvvvvvvvvvvvvvv",
      "      vbbbbbbbbv",
      "      vbbbbbbbbv",
      "      vbbbbbbbbv",
      "      vbbbbbbbbv",
      "      vbbbbbbbbv",
      "      vbbbbbbbbv",
      "      vbbbbbbbbv",
      "      vbbbbbbbbv",
      "      vvvvvvvvvv",
      "     c         v",
      "           ddddv",
      "           e  fv",
      "           gh iv",
      "           e  fv",
      "           g  iv"
    ],
    [
      "vvvvvvvvvvvvvvvv",
      "      vbbbbbbbbv",
      "      vbbbbbbbbv",
      "      vbbbbbbbbv",
      "      vbbbbbbbbv",
      "      vbbbbbbbbv",
      "      vbbbbbbbbv",
      "      vbbbbbbbbv",
      "      vbbbbbbbbv",
      "      vvvvvvvvvv",
      "     c         v",
      "               v",
      "               v",
      "               v",
      "               v",
      "               v"
    ],
    [
      "vvvvvvvvvvvvvvvv",
      "      vbbbbbbbbv",
      "      vbbbbbbbbv",
      "      vbbbbbbbbv",
      "      vbbbbbbbbv",
      "      vbbbbbbbbv",
      "      vbbbbbbbbv",
      "      vbbbbbbbbv",
      "      vbbbbbbbbv",
      "      vvvvvvvvvv",
      "     c         v",
      "               v",
      "               v",
      "               v",
      "               v",
      "               v"
    ],
    [
      "vvvvvvvvvvvvvvvv",
      "      vbbbbbbbbv",
      "      vbbbbbbbbv",
      "      vbbbbbbbbv",
      "      vbbbbbbbbv",
      "      vbbbbbbbbv",
      "      vbbbbbbbbv",
      "      vbbbbbbbbv",
      "      vbbbbbbbbv",
      "      vvvvvvvvvv",
      "     c         v",
      "               v",
      "               v",
      "               v",
      "               v",
      "               v"
    ],
    [
      "vvvvvvvvvvvvvvvv",
      "jjjjjkvbbbbbbbbv",
      "jjjjjkvbbbbbbbbv",
      "jjjjjkvbbbbbbbbv",
      "jjjjjkvbbbbbbbbv",
      "jjjjjkvbbbbbbbbv",
      "jjjjjkvbbbbbbbbv",
      "jjjjjkvbbbbbbbbv",
      "jjjjjkvbbbbbbbbv",
      "jjjjjkvvvvvvvvvv",
      "kkkkklkkkkkkkkkv",
      "jjjjjkjjjjjjjjjv",
      "jjjjjkjjjjjjjjjv",
      "jjjjjkjjjjjjjjjv",
      "jjjjjkjjjjjjjjjv",
      "jjjjjkjjjjjjjjjv"
    ]
  ]
}