{
  "name": "multi_oasiscondo_12_floor5",
  "refpalette": "deceasedcraft:multi_oasiscondo_12/multi_oasiscondo_12_floor5_palette",
  "xsize": 16,
  "zsize": 16,
  "slices": [
    [
      "                ",
      "                ",
      "                ",
      "                ",
      "                ",
      "                ",
      "                ",
      "                ",
      "                ",
      "aaabb           ",
      "aaaaac          ",
      "aaaaaad         ",
      "aaaaaad         ",
      "aaaaaaa         ",
      "aaaaaaa         ",
      "eaaaaaa         "
    ],
    [
      "                ",
      "                ",
      "                ",
      "                ",
      "                ",
      "                ",
      "                ",
      "                ",
      "eeef            ",
      "gheee           ",
      "iijklc          ",
      " mj  no         ",
      "p q   or        ",
      "s j ttee        ",
      "umjwxxye        ",
      "e A  BCe        "
    ],
    [
      "                ",
      "                ",
      "                ",
      "                ",
      "                ",
      "                ",
      "                ",
      "                ",
      "DDD             ",
      "mEDDe           ",
      "  j Fc          ",
      "  jI  e         ",
      "J K   D         ",
      "L j MNDD        ",
      "O jPxxxD        ",
      "e Q   RD        "
    ],
    [
      "                ",
      "                ",
      "                ",
      "                ",
      "                ",
      "                ",
      "                ",
      "                ",
      "DDD             ",
      "  DDe           ",
      "  j Sc          ",
      "  j   o         ",
      "  T   D         ",
      "  j UVDD        ",
      "  jWxxxD        ",
      "e T    D        "
    ],
    [
      "                ",
      "                ",
      "                ",
      "                ",
      "                ",
      "                ",
      "                ",
      "                ",
      "DDD             ",
      "  DDo           ",
      "X j Xc          ",
      "  jYYYe         ",
      "  jYYYD         ",
      "Z jYYYDD        ",
      "  jxxxxD        ",
      "e j    D        "
    ],
    [
      "                ",
      "                ",
      "                ",
      "                ",
      "                ",
      "                ",
      "                ",
      "                ",
      "eoef            ",
      "00eoe           ",
      "00000c          ",
      "000  1e         ",
      "000   er        ",
      "000   ee        ",
      "0000000e        ",
      "e000000e        "
    ]
  ]
}