{
  "name": "multi_oasiscondo_12_floor11",
  "refpalette": "deceasedcraft:multi_oasiscondo_12/multi_oasiscondo_12_floor11_palette",
  "xsize": 16,
  "zsize": 16,
  "slices": [
    [
      "                ",
      "                ",
      "                ",
      "                ",
      "                ",
      "                ",
      "                ",
      "                ",
      "                ",
      "aaabb           ",
      "cccccd          ",
      "ecceccf         ",
      "eeecccf         ",
      "eceecca         ",
      "ccececa         ",
      "gccecca         "
    ],
    [
      "                ",
      "                ",
      "                ",
      "                ",
      "                ",
      "                ",
      "                ",
      "hhhi            ",
      "jjjhhi          ",
      "jjjjjii         ",
      "k ll dii        ",
      " l  mnjo        ",
      "    l joi       ",
      " l   kjjo       ",
      "pm   njjo       ",
      " l  lljjo       "
    ],
    [
      "                ",
      "                ",
      "                ",
      "                ",
      "                ",
      "                ",
      "                ",
      "qqqq            ",
      "   qqq          ",
      "     qq         ",
      "l l  dqq        ",
      "    k  q        ",
      "       qq       ",
      "     l  q       ",
      " k      q       ",
      "     l  q       "
    ],
    [
      "                ",
      "                ",
      "                ",
      "                ",
      "                ",
      "                ",
      "                ",
      "                ",
      "                ",
      "                ",
      "     d          ",
      "    n           ",
      "                ",
      "     l          ",
      " l              ",
      "                "
    ],
    [
      "                ",
      "                ",
      "                ",
      "                ",
      "                ",
      "                ",
      "                ",
      "                ",
      "rrrr            ",
      "   sr           ",
      "     d          ",
      "      t         ",
      "      ut        ",
      "       t        ",
      " n     t        ",
      "       t        "
    ],
    [
      "                ",
      "                ",
      "                ",
      "                ",
      "                ",
      "                ",
      "                ",
      "iiii            ",
      "iiiiii          ",
      "iiiiiii         ",
      "wwwwwdii        ",
      "wwwwwwii        ",
      "wwwwwwiii       ",
      "wwwwwwiii       ",
      "wwwwwwiii       ",
      "wwwwwwiii       "
    ]
  ]
}