{
  "name": "multi_oasiscondo_12_floor6",
  "refpalette": "deceasedcraft:multi_oasiscondo_12/multi_oasiscondo_12_floor6_palette",
  "xsize": 16,
  "zsize": 16,
  "slices": [
    [
      "                ",
      "                ",
      "                ",
      "                ",
      "                ",
      "                ",
      "                ",
      "                ",
      "                ",
      "aaabb           ",
      "aaaaac          ",
      "aaaaaad         ",
      "aaaaaad         ",
      "aaaaaaa         ",
      "aaaaaaa         ",
      "eaaaaaa         "
    ],
    [
      "                ",
      "                ",
      "                ",
      "                ",
      "                ",
      "                ",
      "                ",
      "                ",
      "eeef            ",
      "gheee           ",
      "iijklc          ",
      "  m nop         ",
      "q jrsteu        ",
      "w jxeeep        ",
      "ynj ABCe        ",
      "e D  EFe        "
    ],
    [
      "                ",
      "                ",
      "                ",
      "                ",
      "                ",
      "                ",
      "                ",
      "                ",
      "III             ",
      " JIIe           ",
      "  j Kc          ",
      "  L  Me         ",
      "  j   I         ",
      "r jNeeII        ",
      "O j   PI        ",
      "e Q    I        "
    ],
    [
      "                ",
      "                ",
      "                ",
      "                ",
      "                ",
      "                ",
      "                ",
      "                ",
      "III             ",
      "  IIe           ",
      "  j Rc          ",
      "  S  Te         ",
      "  j   I         ",
      "  jUeeII        ",
      "  j    I        ",
      "e S    I        "
    ],
    [
      "                ",
      "                ",
      "                ",
      "                ",
      "                ",
      "                ",
      "                ",
      "                ",
      "III             ",
      "  IIp           ",
      "V j Vc          ",
      "  jWWWp         ",
      "  jWWWI         ",
      "X jeeeII        ",
      "  j    I        ",
      "e j    I        "
    ],
    [
      "                ",
      "                ",
      "                ",
      "                ",
      "                ",
      "                ",
      "                ",
      "                ",
      "eeef            ",
      "YYeee           ",
      "YYYYYc          ",
      "YYY  Ze         ",
      "YYY   e0        ",
      "YYYYYYee        ",
      "YYYYYYYe        ",
      "eYYYYYYe        "
    ]
  ]
}