{
  "name": "multi_oasiscondo_12_floor3",
  "refpalette": "deceasedcraft:multi_oasiscondo_12/multi_oasiscondo_12_floor3_palette",
  "xsize": 16,
  "zsize": 16,
  "slices": [
    [
      "                ",
      "                ",
      "                ",
      "                ",
      "                ",
      "                ",
      "                ",
      "                ",
      "                ",
      "aaabb           ",
      "ccaaad          ",
      "ccaaaae         ",
      "ccaaaae         ",
      "aaaaaaa         ",
      "aaaaaaa         ",
      "faaaaaa         "
    ],
    [
      "                ",
      "                ",
      "                ",
      "                ",
      "                ",
      "                ",
      "                ",
      "                ",
      "fgfh            ",
      "iiffg           ",
      "j kf d          ",
      "j lf mf         ",
      "n of pfq        ",
      "  rstuuf        ",
      "w r  xyg        ",
      "f A   lf        "
    ],
    [
      "                ",
      "                ",
      "                ",
      "                ",
      "                ",
      "                ",
      "                ",
      "                ",
      "BBB             ",
      "CDBBf           ",
      "   fEd          ",
      "  FfI g         ",
      "J Kf  B         ",
      "  rsLuBB        ",
      "w r   MB        ",
      "f N   OB        "
    ],
    [
      "                ",
      "                ",
      "                ",
      "                ",
      "                ",
      "                ",
      "                ",
      "                ",
      "BBB             ",
      "  BBf           ",
      "   fPd          ",
      "   f Qf         ",
      "   f  B         ",
      "  rsRuBB        ",
      "w r    B        ",
      "f S    B        "
    ],
    [
      "                ",
      "                ",
      "                ",
      "                ",
      "                ",
      "                ",
      "                ",
      "                ",
      "BBB             ",
      "  BBg           ",
      "   fTd          ",
      " U fVVf         ",
      "   fVVB         ",
      "  rWuuBB        ",
      "  r    B        ",
      "f r    B        "
    ],
    [
      "                ",
      "                ",
      "                ",
      "                ",
      "                ",
      "                ",
      "                ",
      "                ",
      "ggfX            ",
      "YYffg           ",
      "YYYYYd          ",
      "YYYY Zg         ",
      "YYYY  f0        ",
      "YYYYYYff        ",
      "YYYYYYYf        ",
      "fYYYYYYf        "
    ]
  ]
}