{
  "name": "multi_oasiscondo_12_base2",
  "refpalette": "deceasedcraft:multi_oasiscondo_12/multi_oasiscondo_12_base2_palette",
  "xsize": 16,
  "zsize": 16,
  "slices": [
    [
      "vvvvvvvvvvvvvvvv",
      "HHHHaavbbbbbbbbv",
      "HHHHaavbbbbbbbbv",
      "HHHHaavbbbbbbbbv",
      "HHHHaavbbbbbbbbv",
      "HHHHaavbbbbbbbbv",
      "HHHHaavbbbbbbbbv",
      "HHHHaavbbbbbbbbv",
      "HHHHaavbbbbbbbbv",
      "HHHHaavvvvvvvvvv",
      "HHHHacaaaaaaaaav",
      "HHHHHaaaaaaaaaav",
      "HHHHHHHHHHHHHHHv",
      "HHHHHHHHHHHHHHHv",
      "HHHHHHHHHHHHHHHv",
      "HHHHHHHHHHHHHHHv"
    ],
    [
      "vvvvvvvvvvvvvvvv",
      "      vbbbbbbbbv",
      "      vbbbbbbbbv",
      "      vbbbbbbbbv",
      "      vbbbbbbbbv",
      "      vbbbbbbbbv",
      "      vbbbbbbbbv",
      "      vbbbbbbbbv",
      "      vbbbbbbbbv",
      "      vvvvvvvvvv",
      "     c         v",
      "           ddddv",
      "           e  fv",
      "           g  hv",
      "           e  fv",
      "           g  hv"
    ],
    [
      "vvvvvvvvvvvvvvvv",
      "      vbbbbbbbbv",
      "      vbbbbbbbbv",
      "      vbbbbbbbbv",
      "      vbbbbbbbbv",
      "      vbbbbbbbbv",
      "      vbbbbbbbbv",
      "      vbbbbbbbbv",
      "      vbbbbbbbbv",
      "      vvvvvvvvvv",
      "     c         v",
      "               v",
      "               v",
      "               v",
      "               v",
      "               v"
    ],
    [
      "vvvvvvvvvvvvvvvv",
      "      vbbbbbbbbv",
      "      vbbbbbbbbv",
      "      vbbbbbbbbv",
      "      vbbbbbbbbv",
      "      vbbbbbbbbv",
      "      vbbbbbbbbv",
      "      vbbbbbbbbv",
      "      vbbbbbbbbv",
      "      vvvvvvvvvv",
      "     c         v",
      "               v",
      "               v",
      "               v",
      "               v",
      "               v"
    ],
    [
      "vvvvvvvvvvvvvvvv",
      "      vbbbbbbbbv",
      "      vbbbbbbbbv",
      "      vbbbbbbbbv",
      "      vbbbbbbbbv",
      "      vbbbbbbbbv",
      "      vbbbbbbbbv",
      "      vbbbbbbbbv",
      "      vbbbbbbbbv",
      "      vvvvvvvvvv",
      "     c         v",
      "               v",
      "               v",
      "               v",
      "               v",
      "               v"
    ],
    [
      "vvvvvvvvvvvvvvvv",
      "iiiiijvbbbbbbbbv",
      "iiiiijvbbbbbbbbv",
      "iiiiijvbbbbbbbbv",
      "iiiiijvbbbbbbbbv",
      "iiiiijvbbbbbbbbv",
      "iiiiijvbbbbbbbbv",
      "iiiiijvbbbbbbbbv",
      "iiiiijvbbbbbbbbv",
      "iiiiijvvvvvvvvvv",
      "jjjjjkjjjjjjjjjv",
      "iiiiijiiiiiiiiiv",
      "iiiiijiiiiiiiiiv",
      "iiiiijiiiiiiiiiv",
      "iiiiijiiiiiiiiiv",
      "iiiiijiiiiiiiiiv"
    ]
  ]
}