{
  "name": "multi_oasiscondo_12_floor2",
  "refpalette": "deceasedcraft:multi_oasiscondo_12/multi_oasiscondo_12_floor2_palette",
  "xsize": 16,
  "zsize": 16,
  "slices": [
    [
      "                ",
      "                ",
      "                ",
      "                ",
      "                ",
      "                ",
      "                ",
      "                ",
      "                ",
      "aaabb           ",
      "aaaaac          ",
      "aaaaaad         ",
      "aaaaaad         ",
      "aaaaaaa         ",
      "aaaaaaa         ",
      "eaaaaaa         "
    ],
    [
      "                ",
      "                ",
      "                ",
      "                ",
      "                ",
      "                ",
      "                ",
      "                ",
      "efeg            ",
      "hiefe           ",
      "jklmnc          ",
      "  l  oe         ",
      "p q  res        ",
      "t l uuee        ",
      "w lxyyye        ",
      "e A   Be        "
    ],
    [
      "                ",
      "                ",
      "                ",
      "                ",
      "                ",
      "                ",
      "                ",
      "                ",
      "CCC             ",
      "  CCf           ",
      "  l Dc          ",
      "  lE  e         ",
      "F I   C         ",
      "J l KLCC        ",
      "  lMyNyC        ",
      "e O   PC        "
    ],
    [
      "                ",
      "                ",
      "                ",
      "                ",
      "                ",
      "                ",
      "                ",
      "                ",
      "CCC             ",
      "  CCe           ",
      "  l Qc          ",
      "  l   e         ",
      "  R   C         ",
      "  l STCC        ",
      "  lUyVyC        ",
      "e R   PC        "
    ],
    [
      "                ",
      "                ",
      "                ",
      "                ",
      "                ",
      "                ",
      "                ",
      "                ",
      "CCC             ",
      "  CCe           ",
      "W l Wc          ",
      "  lXXXf         ",
      "  lXXXC         ",
      "Y lXXXCC        ",
      "  lyyyyC        ",
      "e l   ZC        "
    ],
    [
      "                ",
      "                ",
      "                ",
      "                ",
      "                ",
      "                ",
      "                ",
      "                ",
      "eee0            ",
      "11eef           ",
      "11111c          ",
      "111  2e         ",
      "111   e3        ",
      "111   ef        ",
      "1111111e        ",
      "e111111e        "
    ]
  ]
}