{
  "name": "multi_oasiscondo_12_base4",
  "refpalette": "deceasedcraft:multi_oasiscondo_12/multi_oasiscondo_12_base4_palette",
  "xsize": 16,
  "zsize": 16,
  "slices": [
    [
      "vvvvvvvvvvvvvvvv",
      "aaaaaaaaaaaaaaav",
      "aaaaaaaaaaaaaaav",
      "aaaaaaaaaaaaaaav",
      "aaaaaaaaaaaaaaav",
      "aaaaaaaaaaaaaaav",
      "aaaaaaaaaaaaaaav",
      "aaaaaaaaaaaaaaav",
      "aaaaaaaaaaaaaaav",
      "aaaaaaaaaaaaaaav",
      "aaaaaaaaaaaaaaav",
      "aaaaaaaaaaaaaaav",
      "aaaaaaaaaaaaaaav",
      "aaaaaaaaaaaaaaav",
      "aaaaaaaaaaaaaaav",
      "aaaaaaaaaaaaaaav"
    ],
    [
      "vvvvvvvvvvvvvvvv",
      "aaaaaaaaaaaaaaav",
      "aaaaaaaaaaaaaaav",
      "aaaaaaaaaaaaaaav",
      "aaaaaaaaaaaaaaav",
      "aaaaaaaaaaaaaaav",
      "aaaaaaaaaaaaaaav",
      "aaaaaaaaaaaaaaav",
      "aaaaaaaaaaaaaaav",
      "aaaaaaaaaaaaaaav",
      "aaaaabaaaaaaaaav",
      "aaaaaaaaaaaaaaav",
      "aaaaaaaaaaaaaaav",
      "aaaaaaaaaaaaaaav",
      "aaaaaaaaaaaaaaav",
      "aaaaaaaaaaaaaaav"
    ],
    [
      "vvvvvvvvvvvvvvvv",
      "HHHHccvaaaaaaaav",
      "HHHHccvaaaaaaaav",
      "HHHHccvaaaaaaaav",
      "HHHHccvaaaaaaaav",
      "HHHHccvaaaaaaaav",
      "HHHHccvaaaaaaaav",
      "HHHHccvaaaaaaaav",
      "HHHHccvaaaaaaaav",
      "HHHHccvvvvvvvvvv",
      "HHHHcbcccccccccv",
      "HHHHHccccccccccv",
      "HHHHHHHHHHHHHHHv",
      "HHHHHHHHHHHHHHHv",
      "HHHHHHHHHHHHHHHv",
      "cccccccccccHHHHv"
    ],
    [
      "vvvvvvvvvvvvvvvv",
      "      vaaaaaaaav",
      "      vaaaaaaaav",
      "      vaaaaaaaav",
      "      vaaaaaaaav",
      "      vaaaaaaaav",
      "      vaaaaaaaav",
      "      vaaaaaaaav",
      "      vaaaaaaaav",
      "      vvvvvvvvvv",
      "     b         v",
      "               v",
      "               v",
      "               v",
      "               v",
      "               v"
    ],
    [
      "vvvvvvvvvvvvvvvv",
      "      vaaaaaaaav",
      "      vaaaaaaaav",
      "      vaaaaaaaav",
      "      vaaaaaaaav",
      "      vaaaaaaaav",
      "      vaaaaaaaav",
      "      vaaaaaaaav",
      "      vaaaaaaaav",
      "      vvvvvvvvvv",
      "     b         v",
      "               v",
      "               v",
      "               v",
      "               v",
      "               v"
    ],
    [
      "vvvvvvvvvvvvvvvv",
      "      vaaaaaaaav",
      "      vaaaaaaaav",
      "      vaaaaaaaav",
      "      vaaaaaaaav",
      "      vaaaaaaaav",
      "      vaaaaaaaav",
      "      vaaaaaaaav",
      "      vaaaaaaaav",
      "      vvvvvvvvvv",
      "     b         v",
      "               v",
      "               v",
      "               v",
      "               v",
      "               v"
    ]
  ]
}