{
  "name": "multi_oasiscondo_12_floor8",
  "refpalette": "deceasedcraft:multi_oasiscondo_12/multi_oasiscondo_12_floor8_palette",
  "xsize": 16,
  "zsize": 16,
  "slices": [
    [
      "                ",
      "                ",
      "                ",
      "                ",
      "                ",
      "                ",
      "                ",
      "                ",
      "                ",
      "aaabb           ",
      "aaaccd          ",
      "aaaeccf         ",
      "aaaacef         ",
      "aaaaaaa         ",
      "aaaaaaa         ",
      "gaaaaaa         "
    ],
    [
      "                ",
      "                ",
      "                ",
      "                ",
      "                ",
      "                ",
      "                ",
      "                ",
      "hghi            ",
      "jkhlh           ",
      "mnoppd          ",
      "mqorpph         ",
      "sqtup wx        ",
      "yqoABBlh        ",
      "CnDEFIJh        ",
      "g KL  Mg        "
    ],
    [
      "                ",
      "                ",
      "                ",
      "                ",
      "                ",
      "                ",
      "                ",
      "                ",
      "NNN             ",
      "OPNNl           ",
      "  Q Rd          ",
      " qQ   l         ",
      "nqSr  N         ",
      " nQTUVNN        ",
      "W QXFIIN        ",
      "g Y   ZN        "
    ],
    [
      "                ",
      "                ",
      "                ",
      "                ",
      "                ",
      "                ",
      "                ",
      "                ",
      "NNN             ",
      "  NNw           ",
      "  D 0d          ",
      "  Q   h         ",
      " W1r  N         ",
      "  QT23NN        ",
      "  D4IIIN        ",
      "g 1    N        "
    ],
    [
      "                ",
      "                ",
      "                ",
      "                ",
      "                ",
      "                ",
      "                ",
      "                ",
      "NNN             ",
      "  NNl           ",
      "5 Q 5d          ",
      "  D666g         ",
      "  D666N         ",
      "7 D666NN        ",
      "  DIIIIN        ",
      "g D    N        "
    ],
    [
      "                ",
      "                ",
      "                ",
      "                ",
      "                ",
      "                ",
      "                ",
      "                ",
      "ghg8            ",
      "99ggh           ",
      "99999d          ",
      "999  #h         ",
      "999   g$        ",
      "999   gg        ",
      "9999999g        ",
      "g999999g        "
    ]
  ]
}