{
  "name": "multi_oasiscondo_12_base3",
  "refpalette": "deceasedcraft:multi_oasiscondo_12/multi_oasiscondo_12_base3_palette",
  "xsize": 16,
  "zsize": 16,
  "slices": [
    [
      "vvvvvvvvvvvvvvvv",
      "      vaaaaaaaav",
      "      vaaaaaaaav",
      "      vaaaaaaaav",
      "      vaaaaaaaav",
      "      vaaaaaaaav",
      "      vaaaaaaaav",
      "      vaaaaaaaav",
      "      vaaaaaaaav",
      "      vvvvvvvvvv",
      "     b         v",
      "               v",
      "               v",
      "               v",
      "               v",
      "               v"
    ],
    [
      "vvvvvvvvvvvvvvvv",
      "      vaaaaaaaav",
      "      vaaaaaaaav",
      "      vaaaaaaaav",
      "      vaaaaaaaav",
      "      vaaaaaaaav",
      "      vaaaaaaaav",
      "      vaaaaaaaav",
      "      vaaaaaaaav",
      "      vvvvvvvvvv",
      "     b         v",
      "               v",
      "               v",
      "               v",
      "               v",
      "               v"
    ],
    [
      "vvvvvvvvvvvvvvvv",
      "      vaaaaaaaav",
      "      vaaaaaaaav",
      "      vaaaaaaaav",
      "      vaaaaaaaav",
      "      vaaaaaaaav",
      "      vaaaaaaaav",
      "      vaaaaaaaav",
      "      vaaaaaaaav",
      "      vvvvvvvvvv",
      "     b         v",
      "               v",
      "               v",
      "               v",
      "               v",
      "               v"
    ],
    [
      "vvvvvvvvvvvvvvvv",
      "      vaaaaaaaav",
      "      vaaaaaaaav",
      "      vaaaaaaaav",
      "      vaaaaaaaav",
      "      vaaaaaaaav",
      "      vaaaaaaaav",
      "      vaaaaaaaav",
      "      vaaaaaaaav",
      "      vvvvvvvvvv",
      "     b         v",
      "               v",
      "               v",
      "               v",
      "               v",
      "               v"
    ],
    [
      "vvvvvvvvvvvvvvvv",
      "      vaaaaaaaav",
      "      vaaaaaaaav",
      "      vaaaaaaaav",
      "      vaaaaaaaav",
      "      vaaaaaaaav",
      "      vaaaaaaaav",
      "      vaaaaaaaav",
      "      vaaaaaaaav",
      "      vvvvvvvvvv",
      "     b         v",
      "               v",
      "               v",
      "               v",
      "               v",
      "               v"
    ],
    [
      "vvvvvvvvvvvvvvvv",
      "cccccdvaaaaaaaav",
      "cccccdvaaaaaaaav",
      "cccccdvaaaaaaaav",
      "cccccdvaaaaaaaav",
      "cccccdvaaaaaaaav",
      "cccccdvaaaaaaaav",
      "cccccdvaaaaaaaav",
      "cccccdvaaaaaaaav",
      "cccccdvvvvvvvvvv",
      "dddddedddddddddv",
      "cccccdcccccccccv",
      "cccccdcccccccccv",
      "cccccdcccccccccv",
      "cccccdcccccccccv",
      "cccccdcccccccccv"
    ]
  ]
}