{
  "name": "multi_verticalschool_4_floor5",
  "refpalette": "deceasedcraft:multi_verticalschool_4/multi_verticalschool_4_floor5_palette",
  "xsize": 16,
  "zsize": 16,
  "slices": [
    [
      "     aabbbbbbbbb",
      "     aabbbbbbbbb",
      "     aabbbbbbbbb",
      "     aabbbbbbbbb",
      "     aabbbbbbbbb",
      "     aabbbbbbbbb",
      "     aabbbbbbbbb",
      "     aabbbbbbbbb",
      "     aabbbbbbbbb",
      "     aaaaaaaaaaa",
      "     aaaaaaaaaaa",
      "                ",
      "                ",
      "                ",
      "                ",
      "                "
    ],
    [
      "     acd        ",
      "     ace    e   ",
      "     ac         ",
      "     ac         ",
      "     ac         ",
      "     ac         ",
      "     ace    e   ",
      "     ac         ",
      "     acd        ",
      "     acccccccccc",
      "     aaaaaaaaaaa",
      "                ",
      "                ",
      "                ",
      "                ",
      "                "
    ],
    [
      "     ac         ",
      "     ace    ed  ",
      "     ac         ",
      "     ac         ",
      "     ac         ",
      "     acd        ",
      "     ace    e   ",
      "     acd        ",
      "     acdd       ",
      "     acccccccccc",
      "     aaaaaaaaaaa",
      "                ",
      "                ",
      "                ",
      "                ",
      "                "
    ],
    [
      "     abbbbbbbbbb",
      "     abbbbbbbbbb",
      "     abbbbbbbbbb",
      "     abbbbbbbbbb",
      "     abbbbbbbbbb",
      "     abbbbbbbbbb",
      "     abbbbbbbbbb",
      "     abbbbbbbbbb",
      "     abbbbbbbbbb",
      "     abbbbbbbbbb",
      "     aaaaaaaaaaa",
      "                ",
      "                ",
      "                ",
      "                ",
      "                "
    ],
    [
      "     a          ",
      "     a          ",
      "     a          ",
      "     a          ",
      "     a          ",
      "     a          ",
      "     a          ",
      "     a          ",
      "     af ghi ghi ",
      "     ajkkkkkkkkk",
      "     aaaaaaaaaaa",
      "                ",
      "                ",
      "                ",
      "                ",
      "                "
    ],
    [
      "     a          ",
      "     a          ",
      "     a          ",
      "     a          ",
      "     a          ",
      "     a          ",
      "     a          ",
      "     a          ",
      "     al         ",
      "     ajkkkkkkkkk",
      "     aaaaaaaaaaa",
      "                ",
      "                ",
      "                ",
      "                ",
      "                "
    ]
  ]
}