{
  "name": "multi_verticalschool_4_base1",
  "refpalette": "deceasedcraft:multi_verticalschool_4/multi_verticalschool_4_base1_palette",
  "xsize": 16,
  "zsize": 16,
  "slices": [
    [
      "vaaaaaaaaaaaaaaa",
      "vaaaaaaaaaaaaaaa",
      "vaaaaaaaaaaaaaaa",
      "vaaaaaaaaaaaaaaa",
      "vaaaaaaaaaaaaaaa",
      "vaaaaaaaaaaaaaaa",
      "vaaaaaaaaaaaaaaa",
      "vaaaaaaaaaaaaaaa",
      "vaaaaaaaaaaaaaaa",
      "vaaaaaaaaaaaaaaa",
      "vaaaaaaaaaaaaaaa",
      "vaaaaaaaaaaaaaaa",
      "vaaaaaaaaaaaaaaa",
      "vaaaaaaaaaaaaaaa",
      "vaaaaaaaaaaaaaaa",
      "vvvvvvvvvvvvvvvv"
    ],
    [
      "vaaaaaaaaaaaaaaa",
      "vaaaaaaaaaaaaaaa",
      "vaaaaaaaaaaaaaaa",
      "vaaaaaaaaaaaaaaa",
      "vaaaaaaaaaaaaaaa",
      "vaaaaaaaaaaaaaaa",
      "vaaaaaaaaaaaaaaa",
      "vaaaaaaaaaaaaaaa",
      "vaaaaaaaaaaaaaaa",
      "vaaaaaaaaaaaaaaa",
      "vaaaaaaaaaaaaaaa",
      "vaaaaaaaaaaaaaaa",
      "vaaaaaaaaaaaaaaa",
      "vaaaaaaaaaaaaaaa",
      "vaaaaaaaaaaaaaaa",
      "vvvvvvvvvvvvvvvv"
    ],
    [
      "vaaaaaaaaaaaaaab",
      "vaaaaaaaaaaaaaac",
      "vaaaaaaaaaaaaaad",
      "vaaaaaaaaaaaaaad",
      "vaaaaaaaaaaaaaad",
      "vaaaaaaaaaaaaaad",
      "vaaaaaaaaaaaaaad",
      "vaaaaaaaaaaaaaad",
      "vaaaaaaaaaaaaaac",
      "vaaaaaaaaaaaaaaa",
      "vaaaaaaaaaaaaaaa",
      "vaaaaaaaaaaaaaaa",
      "vaaaaaaaaaaaaaaa",
      "vaaaaaaaaaaaaaaa",
      "vaaaaaaaaaaaaaaa",
      "vvvvvvvvvvvvvvvv"
    ],
    [
      "vaaaaaaaaaaabbbe",
      "vaaaaaaaaaaacccf",
      "vaaaaaaaaaaadddg",
      "vaaaaaaaaaaadddH",
      "vaaaaaaaaaaadddH",
      "vaaaaaaaaaaadddH",
      "vaaaaaaaaaaadddH",
      "vaaaaaaaaaaadddg",
      "vaaaaaaaaaaacccc",
      "vaaaaaaaaaaaaaaa",
      "vaaaaaaaaaaaaaaa",
      "vaaaaaaaaaaaaaaa",
      "vaaaaaaaaaaaaaaa",
      "vaaaaaaaaaaaaaaa",
      "vaaaaaaaaaaaaaaa",
      "vvvvvvvvvvvvvvvv"
    ],
    [
      "vaaaaaaaabbbeeh ",
      "vaaaaaaaacccfffi",
      "vaaaaaaaadddgjk ",
      "vaaaaaaaadddHlm ",
      "vaaaaaaaadddHlm ",
      "vaaaaaaaadddHlm ",
      "vaaaaaaaadddHlm ",
      "vaaaaaaaadddgjk ",
      "vaaaaaaaaccccccc",
      "vaaaaaaaaaaaaaaa",
      "vaaaaaaaaaaaaaaa",
      "vaaaaaaaaaaaaaaa",
      "vaaaaaaaaaaaaaaa",
      "vaaaaaaaaaaaaaaa",
      "vaaaaaaaaaaaaaaa",
      "vvvvvvvvvvvvvvvv"
    ],
    [
      "vddddddcceeh    ",
      "vddddddddfffin  ",
      "vddddddddgjk    ",
      "vddddddddHlm    ",
      "vddddddddHlm    ",
      "vddddddddHlm    ",
      "vddddddddHlm    ",
      "vddddddddgjk    ",
      "vddddddddccccccc",
      "vddddddccddddddd",
      "vdddddcddddddddd",
      "vddddddddddddddd",
      "vddddddddddddddd",
      "vddddddddddddddd",
      "vddddddddddddddd",
      "vvvvvvvvvvvvvvvv"
    ]
  ]
}