{
  "name": "multi_verticalschool_4_floor6",
  "refpalette": "deceasedcraft:multi_verticalschool_4/multi_verticalschool_4_floor6_palette",
  "xsize": 16,
  "zsize": 16,
  "slices": [
    [
      "     a          ",
      "     a          ",
      "     a          ",
      "     a          ",
      "     a          ",
      "     a          ",
      "     a          ",
      "     a          ",
      "     ab         ",
      "     acddddddddd",
      "     aaaaaaaaaaa",
      "                ",
      "                ",
      "                ",
      "                ",
      "                "
    ],
    [
      "     aef       g",
      "     aef       g",
      "     aef       g",
      "     aef       g",
      "     aef       g",
      "     aef       g",
      "     aef       g",
      "     aef       g",
      "     aef       g",
      "     acddddddddd",
      "     aaaaaaaaaaa",
      "                ",
      "                ",
      "                ",
      "                ",
      "                "
    ],
    [
      "     aahiiiiiiih",
      "     aahiiiiiiih",
      "     aahiiiiiiih",
      "     aahiiiiiiih",
      "     aahiiiiiiih",
      "     aahiiiiiiih",
      "     aahiiiiiiih",
      "     aahiiiiiiih",
      "     aahiiiiiiih",
      "     aaaaaaaaaaa",
      "     aaaaaaaaaaa",
      "                ",
      "                ",
      "                ",
      "                ",
      "                "
    ],
    [
      "     j          ",
      "     j          ",
      "     j          ",
      "     j          ",
      "     j          ",
      "     j          ",
      "     j          ",
      "     j          ",
      "     j          ",
      "     j          ",
      "     jjjjjjjjjjj",
      "                ",
      "                ",
      "                ",
      "                ",
      "                "
    ],
    [
      "                ",
      "                ",
      "                ",
      "                ",
      "                ",
      "                ",
      "                ",
      "                ",
      "                ",
      "                ",
      "                ",
      "                ",
      "                ",
      "                ",
      "                ",
      "                "
    ],
    [
      "                ",
      "                ",
      "                ",
      "                ",
      "                ",
      "                ",
      "                ",
      "                ",
      "                ",
      "                ",
      "                ",
      "                ",
      "                ",
      "                ",
      "                ",
      "                "
    ]
  ]
}