{
  "name": "multi_sunkenclub_4_base2",
  "refpalette": "deceasedcraft:multi_sunkenclub_4/multi_sunkenclub_4_base2_palette",
  "xsize": 16,
  "zsize": 16,
  "slices": [
    [
      "vvvvvvvvvvvvvvvv",
      "vvvvvvvvvvvvvvvv",
      "vvvvvvvvvvvvvvvv",
      "vvvvvvvvvvvvvvvv",
      "vvvvvvvvvvvvvvvv",
      "vvvvvvvvvvvvvvvv",
      "vvvvvvvvvvvvvvvv",
      "vvvvvvvvvvvvvvvv",
      "vvvvvvvvvvvvvvvv",
      "vvvvvvvvvvvvvvvv",
      "vvvvvvvvvvvvvvvv",
      "vvvvvvvvvvvvvvvv",
      "vvvvvvvvvvvvvvvv",
      "vvvvvvvvvvvvvvvv",
      "vvvvvvvvvvvvvvvv",
      "vvvvvvvvvvvvvvvv"
    ],
    [
      "aaaaaaaaaaaaaaaa",
      "aaaaaaaaaaaaaaaa",
      "aaaaaaaaaaaaaaaa",
      "aaaaaaaaaaaaaaaa",
      "aaaaaaaaaaaaaaaa",
      "aaaaaaaaaaaaaaaa",
      "baaaaaaaaaaaaaaa",
      "bbbbbbbccbbbbbbb",
      "bbbbbbbccbdbbbbb",
      "bbbbbbdccbbbbbbb",
      "bbbbbbbccdbbbbbb",
      "bbbbbbbccbbbbbbb",
      "bbbbbbdccdbbbbbb",
      "bbbbbdbccddbbeee",
      "bbbbbbdccbdbbeee",
      "bbbbbbdccdbbbeee"
    ],
    [
      "aaaaaaaaaaaaaaaa",
      "aaaaaaaaaaaaaaaa",
      "aaaaaaaaaaaaaaaa",
      "aaaaaaaaaaaaaaaa",
      "bbbbbbbbbbbbbbbb",
      "bbbbbbbbbbbbbbbb",
      " bbbbbbbbbbbbbbb",
      "f   bbbbbbbb    ",
      "      gggg    f ",
      "  f f  h        ",
      "f     h         ",
      "     i    h     ",
      "jjjj    i   jjjj",
      "kklj   h    jmkk",
      "nknjo    i pjkkn",
      " kkjq      rjkkk"
    ],
    [
      "aaaaaaaaaaaaaaaa",
      "bbbbbbbbbbbbbbbb",
      "bbbbbbbbbbbbbbbb",
      "bbbbbbbbbbbbbbbb",
      "  bbbbbbbbbbbbbb",
      "      gggg  ff  ",
      "                ",
      "     f     f    ",
      "                ",
      "                ",
      "                ",
      "                ",
      "                ",
      "ss           tss",
      " s           ss ",
      " ss          sss"
    ],
    [
      "bbbbbbbbbbbbbbbb",
      "bbbbbbbbbbbbbbbb",
      "  fbbbbbbbbbbbbb",
      "    f gggg   fff",
      "            f ff",
      "                ",
      "                ",
      "                ",
      "                ",
      "                ",
      "                ",
      "                ",
      "                ",
      "                ",
      "                ",
      "                "
    ],
    [
      "    bbbbbbbbbbbb",
      "ff    gggg     f",
      "               f",
      "                ",
      "                ",
      "                ",
      "                ",
      "                ",
      "                ",
      "                ",
      "                ",
      "                ",
      "                ",
      "                ",
      "                ",
      "                "
    ]
  ]
}