{
  "name": "multi_farmhouse1_5_floor1",
  "refpalette": "deceasedcraft:multi_farmhouse1_5/multi_farmhouse1_5_floor1_palette",
  "xsize": 16,
  "zsize": 16,
  "slices": [
    [
      "aaaaaaaaaaaaaaaa",
      "ababbabaaaaccaaa",
      "aabbabaaaccccaaa",
      "abbaaaaaacccccaa",
      "aabbbaaaaaccccaa",
      "ababaaaaaaacccca",
      "aabbaaaaaaacccaa",
      "aabaaaaaaaacccaa",
      "aaaabaaaaaacaaaa",
      "aaabaabaaaaaaaab",
      "aaaaaaaaaaaaaaab",
      "abaaaaaaabaaabba",
      "aaabaaabbbbbbbbb",
      "aabaabaabbbabaaa",
      "aaaaaabaababaaab",
      "aaaaaaaababaaaaa"
    ],
    [
      "dddddddddddddddd",
      "deeeeeeefeeeeeed",
      "deeeeeeefeeeeeed",
      "deeeeeeefeeeeeed",
      "deeeeeeeefeeeeed",
      "deeeeeeeeeeeeeed",
      "deeeeeeeeeeeeegd",
      "deeeeeeeeeeeeegd",
      "ddeeeeeeeeeeeedd",
      "hddeeeeeeeegedde",
      "ehddddddiejddjee",
      "heehhehkeeeieeee",
      "hhheheeeeeeeeeee",
      "hheeheeeeeeeeeee",
      "eeheheeeeeeeeeee",
      "hdhdeheeeeeeelei"
    ],
    [
      "eeeeeeeeeeeeeeee",
      "eeeeeeeefeeeeeee",
      "eeeeeeeefeeeeeee",
      "eeeeeeeefeeeeeee",
      "eeeeeeeeefeeeeee",
      "eeeeeeeeeeeeeeee",
      "eeeeeeeeeeeeeege",
      "eeeeeeeeeeeeeege",
      "eeeeeeeeeeeeeeee",
      "meeeeeeeeeegeeee",
      "emeeeeeeeeeeeeee",
      "meemmemeeeeeeeee",
      "mmmemeeeeeeeeeee",
      "mmeemeeeeeeeeeee",
      "eememeeeeeeeeeee",
      "memeemeeeeeeenee"
    ],
    [
      "eeeeeeeeeeeeeeee",
      "eeeeeeeefeeeeeee",
      "eeeeeeeefeeeeeee",
      "eeeeeeeefeeeeeee",
      "eeeeeeeeefeeeeee",
      "eeeeeeeeeeeeeeee",
      "eeeeeeeeeeeeeege",
      "eeeeeeeeeeeeeege",
      "eeeeeeeeeeeeeeee",
      "eeeeeeeeeeegeeee",
      "eeeeeeeeeeeeeeee",
      "eeeeeeeeeeeeeeee",
      "eeeeeeeeeeeeeeee",
      "eeeeeeeeeeeeeeee",
      "eeeeeeeeeeeeeeee",
      "eeeeeeeeeeeeeeee"
    ],
    [
      "eeeeeeeeeeeeeeee",
      "eeeeeeeefeeeeeee",
      "eeeeeeeefeeeeeee",
      "eeeeeeeefeeeeeee",
      "eeeeeeeeefeeeeee",
      "eeeeeeeeeeeeeeee",
      "eeeeeeeeeeeeeege",
      "eeeeeeeeeeeeeeee",
      "eeeeeeeeeeeeeeee",
      "eeeeeeeeeeeeeeee",
      "eeeeeeeeeeeeeeee",
      "eeeeeeeeeeeeeeee",
      "eeeeeeeeeeeeeeee",
      "eeeeeeeeeeeeeeee",
      "eeeeeeeeeeeeeeee",
      "eeeeeeeeeeeeeeee"
    ],
    [
      "eeeeeeeeeeeeeeee",
      "eeeeeeeefeeeeeee",
      "eeeeeeeefeeeeeee",
      "eeeeeeeefeeeeeee",
      "eeeeeeeeefeeeeee",
      "eeeeeeeeeeeeeeee",
      "eeeeeeeeeeeeeeee",
      "eeeeeeeeeeeeeeee",
      "eeeeeeeeeeeeeeee",
      "eeeeeeeeeeeeeeee",
      "eeeeeeeeeeeeeeee",
      "eeeeeeeeeeeeeeee",
      "eeeeeeeeeeeeeeee",
      "eeeeeeeeeeeeeeee",
      "eeeeeeeeeeeeeeee",
      "eeeeeeeeeeeeeeee"
    ]
  ]
}