{
  "name": "multi_nuclearpowerplant_28_base6",
  "refpalette": "deceasedcraft:multi_nuclearpowerplant_28/multi_nuclearpowerplant_28_base6_palette",
  "xsize": 16,
  "zsize": 16,
  "slices": [
    [
      "vvvvvvvvvvvvvvvv",
      "aaaaaaaaaaaaaaaa",
      "aaaaaaaaaaaaaaaa",
      "bbbbbbbbbbbbbbbb",
      "================",
      "=ccccccccccccccc",
      "c           d   ",
      "      efffg     ",
      "      ehiij     ",
      "      ehiij     ",
      "      efffg d kk",
      "c            kk ",
      "=c          kk  ",
      "==c         k   ",
      "l==c        k   ",
      "lll=c       k   "
    ],
    [
      "vvvvvvvvvvvvvvvv",
      "aaaaaaaaaaaaaaaa",
      "aaaaaaaaaaaaaaaa",
      "mmmmmmmmmmmmmmmm",
      "================",
      "=ccccccccccccccc",
      "c           d   ",
      "      efffg     ",
      "      ehiij     ",
      "      ehiij     ",
      "      efffg d kk",
      "c            kk ",
      "=c          kk  ",
      "==c         k   ",
      "n==c        k   ",
      "nnn=c       k   "
    ],
    [
      "vvvvvvvvvvvvvvvv",
      "aaaaaaaaaaaaaaaa",
      "aaaaaaaaaaaaaaaa",
      "mmmmmmmmmmmmmmmm",
      "================",
      "=ccccccccccccccc",
      "c           d   ",
      "      efffg     ",
      "      ehiij     ",
      "      ehiij     ",
      "      efffg d kk",
      "c            kk ",
      "=c          kk  ",
      "==c         k   ",
      " ==c        k   ",
      "   =c       k   "
    ],
    [
      "vvvvvvvvvvvvvvvv",
      "aaaaaaaaaaaaaaaa",
      "aaaaaaaaaaaaaaaa",
      "mmmmmmmmmmmmmmmm",
      "================",
      "=ccccccccccccccc",
      "c           d   ",
      "      efffg     ",
      "      ehiij     ",
      "      ehiij     ",
      "      efffg d kk",
      "c            kk ",
      "=c          kk  ",
      "==c         k   ",
      " ==c        k   ",
      "   =c       k   "
    ],
    [
      "vvvvvvvvvvvvvvvv",
      "aaaaaaaaaaaaaaaa",
      "aaaaaaaaaaaaaaaa",
      "mmmmmmmmmmmmmmmm",
      "================",
      "=ccccccccccccccc",
      "c           d   ",
      "      efffg     ",
      "      ehiij     ",
      "      ehiij     ",
      "      efffg d kk",
      "c            kk ",
      "=c          kk  ",
      "==c         k   ",
      " ==c        k   ",
      "   =c       k   "
    ],
    [
      "vvvvvvvvvvvvvvvv",
      "aaaaaaaaaaaaaaaa",
      "aaaaaaaaaaaaaaaa",
      "mmmmmmmmmmmmmmmm",
      "================",
      "=ccccccccccccccc",
      "c           d   ",
      "      efffg     ",
      "      ehiij     ",
      "      ehiij     ",
      "      efffg d kk",
      "c            kk ",
      "=c          kk  ",
      "==c         k   ",
      " ==c        k   ",
      "   =c       k   "
    ]
  ]
}