{
  "name": "multi_nuclearpowerplant_28_base2",
  "refpalette": "deceasedcraft:multi_nuclearpowerplant_28/multi_nuclearpowerplant_28_base2_palette",
  "xsize": 16,
  "zsize": 16,
  "slices": [
    [
      "vvvvvvvvvvvvvvvv",
      "aaaaaaaaaaaaaaaa",
      "aaaaaaaaaaaaaaaa",
      "bbbbbbbbbbbbbbbb",
      "b===============",
      "=ccccccccccccccc",
      "c               ",
      "                ",
      "                ",
      "                ",
      "                ",
      "c               ",
      "=c              ",
      "d=c             ",
      " ddc            ",
      "   dc           "
    ],
    [
      "vvvvvvvvvvvvvvvv",
      "aaaaaaaaaaaaaaaa",
      "aaaaaaaaaaaaaaaa",
      "bbbbbbbbbbbbbbbb",
      "b===============",
      "=ccccccccccccccc",
      "c               ",
      "                ",
      "                ",
      "                ",
      "                ",
      "c               ",
      "=c              ",
      "d=c             ",
      " ddc            ",
      "   dc           "
    ],
    [
      "vvvvvvvvvvvvvvvv",
      "aaaaaaaaaaaaaaaa",
      "aaaaaaaaaaaaaaaa",
      "bbbbbbbbbbbbbbbb",
      "b===============",
      "=ccccccccccccccc",
      "c               ",
      "                ",
      "                ",
      "                ",
      "                ",
      "c               ",
      "=c              ",
      "d=c             ",
      " ddc            ",
      "   dc           "
    ],
    [
      "vvvvvvvvvvvvvvvv",
      "aaaaaaaaaaaaaaaa",
      "aaaaaaaaaaaaaaaa",
      "bbbbbbbbbbbbbbbb",
      "b===============",
      "=ccccccccccccccc",
      "ceeeeeeeeeeeeeee",
      "f               ",
      "f               ",
      "f               ",
      "c               ",
      "cc              ",
      "=cc             ",
      "d=cc            ",
      " ddcc           ",
      "   dcc          "
    ],
    [
      "vvvvvvvvvvvvvvvv",
      "aaaaaaaaaaaaaaaa",
      "aaaaaaaaaaaaaaaa",
      "bbbbbbbbbbbbbbbb",
      "gggggggggggggggg",
      "g===============",
      "=ccccccccccccccc",
      "cchhhhhhhhhhhhhh",
      "ch              ",
      "ch              ",
      "=ch             ",
      "i=ch            ",
      "ii=ch           ",
      "jiiich          ",
      " jjiich         ",
      "   jiich        "
    ],
    [
      "vvvvvvvvvvvvvvvv",
      "aaaaaaaaaaaaaaaa",
      "aaaaaaaaaaaaaaaa",
      "bbbbbbbbbbbbbbbb",
      "gggggggggggggggg",
      "gggggggggggggggg",
      "g===============",
      "==cccccccccccccc",
      "=ccccccccccccccc",
      "=ccccccccccccccc",
      "==cccccccccccccc",
      "i==ccccccccccccc",
      "ii==cccccccccccc",
      "kiii=ccccccccccc",
      "kkkii=cccccccccc",
      "kkkkii=ccccccccc"
    ]
  ]
}