{
  "name": "multi_nuclearpowerplant_28_base5",
  "refpalette": "deceasedcraft:multi_nuclearpowerplant_28/multi_nuclearpowerplant_28_base5_palette",
  "xsize": 16,
  "zsize": 16,
  "slices": [
    [
      "vvvvvvvvvvvvvvvv",
      "aaaaaaaaaaaaaaaa",
      "aaaaaaaaaaaaaaaa",
      "bbbbbbbbbbbbbbbb",
      "================",
      "=ccccccccccccccc",
      "c           d   ",
      "      efffg     ",
      "      ehiij     ",
      "      ehiij     ",
      "      efffg d kk",
      "c       l    kk ",
      "=c      l   kk  ",
      "==c     l   m   ",
      " ==c    llllml  ",
      "   =c       m   "
    ],
    [
      "vvvvvvvvvvvvvvvv",
      "aaaaaaaaaaaaaaaa",
      "aaaaaaaaaaaaaaaa",
      "bbbbbbbbbbbbbbbb",
      "================",
      "=ccccccccccccccc",
      "c           d   ",
      "      efffg     ",
      "      ennnj     ",
      "      ennnj     ",
      "      efifg d kk",
      "c      oip   kk ",
      "=c     oip  kk  ",
      "==c    oiqrrmrr ",
      " ==c   oiiiii~  ",
      "   =c   ssssmss "
    ],
    [
      "vvvvvvvvvvvvvvvv",
      "aaaaaaaaaaaaaaaa",
      "aaaaaaaaaaaaaaaa",
      "bbbbbbbbbbbbbbbb",
      "================",
      "=ccccccccccccccc",
      "c           d   ",
      "      efffg     ",
      "      efffg     ",
      "      efffg     ",
      "      efffg d kk",
      "c       t    kk ",
      "=c      t   kk  ",
      "==c     t   m   ",
      " ==c    ttttmttt",
      "   =c       m   "
    ],
    [
      "vvvvvvvvvvvvvvvv",
      "aaaaaaaaaaaaaaaa",
      "aaaaaaaaaaaaaaaa",
      "bbbbbbbbbbbbbbbb",
      "================",
      "=ccccccccccccccc",
      "c           d  u",
      "      efffg    w",
      "      efffg     ",
      "      efffg     ",
      "      efffg d kk",
      "c            kk ",
      "=c          kk  ",
      "==c         k   ",
      " ==c        k   ",
      "   =c       k   "
    ],
    [
      "vvvvvvvvvvvvvvvv",
      "aaaaaaaaaaaaaaaa",
      "aaaaaaaaaaaaaaaa",
      "bbbbbbbbbbbbbbbb",
      "================",
      "=ccccccccccccccc",
      "c           d u ",
      "              w ",
      "                ",
      "                ",
      "            d kk",
      "c            kk ",
      "=c          kk  ",
      "==c         k   ",
      " ==c        k   ",
      "   =c       k   "
    ],
    [
      "vvvvvvvvvvvvvvvv",
      "aaaaaaaaaaaaaaaa",
      "aaaaaaaaaaaaaaaa",
      "bbbbbbbbbbbbbbbb",
      "================",
      "=ccccccccccccccc",
      "cxxxxxxxx  xyu  ",
      "xxxxxxxxx  xxw  ",
      "xxxxxx     xx   ",
      "xxxxxx     xx   ",
      "xxxxxx     xy kk",
      "cxxxxx       kk ",
      "=c          kk  ",
      "==c         k   ",
      " ==c        k   ",
      "   =c       k   "
    ]
  ]
}