{
  "name": "multi_nuclearpowerplant_28_base7",
  "refpalette": "deceasedcraft:multi_nuclearpowerplant_28/multi_nuclearpowerplant_28_base7_palette",
  "xsize": 16,
  "zsize": 16,
  "slices": [
    [
      "vvvvvvvvvvvvvvvv",
      "aaaaaaaaaaaaaaaa",
      "aaaaaaaaaaaaaaaa",
      "bbbbbbbbbbbbbbbb",
      "c===============",
      "=ddddddddddddddd",
      "d     eeeee f   ",
      "      ggggg     ",
      "      gggggh i  ",
      "      ggggg! j  ",
      "      ggggg f kk",
      "d     lllll  kkm",
      "=d          kkmm",
      " =d         kmmm",
      "  =d        kmmm",
      "   =d       kmmm"
    ],
    [
      "vvvvvvvvvvvvvvvv",
      "aaaaaaaaaaaaaaaa",
      "aaaaaaaaaaaaaaaa",
      "bbbbbbbbbbbbbbbb",
      "c===============",
      "=ddddddddddddddd",
      "d           f   ",
      "      nooop     ",
      "qqqqqqrooop   i ",
      "qqqqqqrooop   j ",
      "      nooop f kk",
      "d            kkm",
      "=d          kkmm",
      " =d         kmmm",
      "  =d        kmmm",
      "   =d       kmms"
    ],
    [
      "vvvvvvvvvvvvvvvv",
      "aaaaaaaaaaaaaaaa",
      "aaaaaaaaaaaaaaaa",
      "bbbbbbbbbbbbbbbb",
      "c===============",
      "=ddddddddddddddd",
      "d           f   ",
      "ttttttrooop     ",
      "uuuuuuuwwwx    i",
      "uuuuuuuwwwx    j",
      "yyyyyyrooop f kk",
      "d            kk ",
      "=d          kk  ",
      " =d         k   ",
      "  =d        k   ",
      "   =d       k   "
    ],
    [
      "vvvvvvvvvvvvvvvv",
      "aaaaaaaaaaaaaaaa",
      "aaaaaaaaaaaaaaaa",
      "bbbbbbbbbbbbbbbb",
      "c===============",
      "=ddddddddddddddd",
      "d           f   ",
      "ttttttrooop     ",
      "uuuuuuuwwwx     ",
      "uuuuuuuwwwx     ",
      "yyyyyyrooop f kk",
      "d            kk ",
      "=d          kk  ",
      " =d         k   ",
      "  =d        k   ",
      "   =d       k   "
    ],
    [
      "vvvvvvvvvvvvvvvv",
      "aaaaaaaaaaaaaaaa",
      "aaaaaaaaaaaaaaaa",
      "bbbbbbbbbbbbbbbb",
      "c===============",
      "=ddddddddddddddd",
      "d           f   ",
      "      nooop     ",
      "AAAAAArBuux     ",
      "AAAAAArBuux     ",
      "      nooop f kk",
      "d            kk ",
      "=d          kk  ",
      " =d         k   ",
      "  =d        k   ",
      "   =d       k   "
    ],
    [
      "vvvvvvvvvvvvvvvv",
      "aaaaaaaaaaaaaaaa",
      "aaaaaaaaaaaaaaaa",
      "bbbbbbbbbbbbbbbb",
      "c===============",
      "=ddddddddddddddd",
      "d           f   ",
      "      nooop     ",
      "      nBuux     ",
      "      nBuux     ",
      "      nooop f kk",
      "d            kk ",
      "=d          kk  ",
      "C=d         k   ",
      "CC=d        k   ",
      "CCC=d       k   "
    ]
  ]
}