{
  "name": "multi_nuclearpowerplant_28_base1",
  "refpalette": "deceasedcraft:multi_nuclearpowerplant_28/multi_nuclearpowerplant_28_base1_palette",
  "xsize": 16,
  "zsize": 16,
  "slices": [
    [
      "vvvvvvvvvvvvvvvv",
      "aaaaaaaaaaaaaaaa",
      "aaaaaaaaaaaaaaaa",
      "bbbbbbbbbbbbbbbb",
      "cccccccccccccccc",
      "cccccccccccccccc",
      "cccccccccccccccc",
      "cc==============",
      "c===============",
      "c===============",
      "dc==============",
      "edc=============",
      "eedd============",
      "eeeed===========",
      "eeeeed==========",
      "eeeeeed========="
    ],
    [
      "vvvvvvvvvvvvvvvv",
      "aaaaaaaaaaaaaaaa",
      "aaaaaaaaaaaaaaaa",
      "bbbbbbbbbbbbbbbb",
      "cccccccccccccccc",
      "cccccccccccccccc",
      "cccccccccccccccc",
      "cccccccccccccccc",
      "cccccccccccccccc",
      "cccccccccccccccc",
      "dccccccccccccccc",
      "edcccccccccccccc",
      "eeddcccccccccccc",
      "eeeedccccccccccc",
      "eeeeedcccccccccc",
      "eeeeeedccccccccc"
    ],
    [
      "vvvvvvvvvvvvvvvv",
      "aaaaaaaaaaaaaaaa",
      "aaaaaaaaaaaaaaaa",
      "bbbbbbbbbbbbbbbb",
      "cccccccccccccccc",
      "cccccccccccccccc",
      "cccccccccccccccc",
      "cccccccccccccccc",
      "cccccccccccccccc",
      "cccccccccccccccc",
      "dccccccccccccccc",
      "edcccccccccccccc",
      "eeddcccccccccccc",
      "eeeedccccccccccc",
      "eeeeedcccccccccc",
      "eeeeeedccccccccc"
    ],
    [
      "vvvvvvvvvvvvvvvv",
      "aaaaaaaaaaaaaaaa",
      "aaaaaaaaaaaaaaaa",
      "bbbbbbbbbbbbbbbb",
      "cccccccccccccccc",
      "cccccccccccccccc",
      "cccccccccccccccc",
      "cccccccccccccccc",
      "cccccccccccccccc",
      "cccccccccccccccc",
      "dccccccccccccccc",
      "edcccccccccccccc",
      "eeddcccccccccccc",
      "eeeedccccccccccc",
      "eeeeedcccccccccc",
      "eeeeeedccccccccc"
    ],
    [
      "vvvvvvvvvvvvvvvv",
      "aaaaaaaaaaaaaaaa",
      "aaaaaaaaaaaaaaaa",
      "bbbbbbbbbbbbbbbb",
      "cccccccccccccccc",
      "cccccccccccccccc",
      "cccccccccccccccc",
      "cccccccccccccccc",
      "cccccccccccccccc",
      "cccccccccccccccc",
      "dccccccccccccccc",
      "edcccccccccccccc",
      "eeddcccccccccccc",
      "eeeedccccccccccc",
      "eeeeedcccccccccc",
      "eeeeeedccccccccc"
    ],
    [
      "vvvvvvvvvvvvvvvv",
      "cccccccccccccccc",
      "cccccccccccccccc",
      "bbbbbbbbbbbbbbbb",
      "cccccccccccccccc",
      "ffffcccccccccccc",
      "cccfffffcccccccc",
      "cccccccffffccccc",
      "ccccccccccfffccc",
      "ccccccccccccfffc",
      "dcccccccccccccff",
      "edcccccccccccccc",
      "eeddcccccccccccc",
      "eeeedccccccccccc",
      "deeeedcccccccccc",
      "gdeeeedccccccccc"
    ]
  ]
}