{
  "name": "multi_nuclearpowerplant_28_base4",
  "refpalette": "deceasedcraft:multi_nuclearpowerplant_28/multi_nuclearpowerplant_28_base4_palette",
  "xsize": 16,
  "zsize": 16,
  "slices": [
    [
      "vvvvvvvvvvvvvvvv",
      "aaaaaaaaaaaaaaaa",
      "aaaaaaaaaaaaaaaa",
      "bbbbbbbbbbbbbbbb",
      "================",
      "=ccccccccccccccc",
      "c          de   ",
      "      fff  g    ",
      "           gh   ",
      "          i h   ",
      "          jfk ll",
      "c            ll ",
      "=c          ll  ",
      "==c         l   ",
      " ==c        l   ",
      "   =c       l   "
    ],
    [
      "vvvvvvvvvvvvvvvv",
      "aaaaaaaaaaaaaaaa",
      "aaaaaaaaaaaaaaaa",
      "bbbbbbbbbbbbbbbb",
      "================",
      "=ccccccccccccccc",
      "c               ",
      "                ",
      "                ",
      "         i      ",
      "         j    ll",
      "c            ll ",
      "=c          ll  ",
      "==c         l   ",
      " ==c        l   ",
      "   =c       l   "
    ],
    [
      "vvvvvvvvvvvvvvvv",
      "aaaaaaaaaaaaaaaa",
      "aaaaaaaaaaaaaaaa",
      "bbbbbbbbbbbbbbbb",
      "================",
      "=ccccccccccccccc",
      "c               ",
      "                ",
      "                ",
      "        i       ",
      "        j     ll",
      "c            ll ",
      "=c          ll  ",
      "==c         l   ",
      " ==c        l   ",
      "   =c       l   "
    ],
    [
      "vvvvvvvvvvvvvvvv",
      "aaaaaaaaaaaaaaaa",
      "aaaaaaaaaaaaaaaa",
      "bbbbbbbbbbbbbbbb",
      "================",
      "=ccccccccccccccc",
      "c               ",
      "                ",
      "                ",
      "       i        ",
      "       j      ll",
      "c            ll ",
      "=c          ll  ",
      "==c         l   ",
      " ==c        l   ",
      "   =c       l   "
    ],
    [
      "vvvvvvvvvvvvvvvv",
      "aaaaaaaaaaaaaaaa",
      "aaaaaaaaaaaaaaaa",
      "bbbbbbbbbbbbbbbb",
      "================",
      "=ccccccccccccccc",
      "c               ",
      "                ",
      "                ",
      "      i         ",
      "      j       ll",
      "c            ll ",
      "=c          ll  ",
      "==c         l   ",
      " ==c        l   ",
      "   =c       l   "
    ],
    [
      "vvvvvvvvvvvvvvvv",
      "aaaaaaaaaaaaaaaa",
      "aaaaaaaaaaaaaaaa",
      "bbbbbbbbbbbbbbbb",
      "================",
      "=ccccccccccccccc",
      "c               ",
      "                ",
      "                ",
      "     i          ",
      "     j        mm",
      "c            mm ",
      "=c          mm  ",
      "==c         m   ",
      " ==c        m   ",
      "   =c       m   "
    ]
  ]
}