{
  "name": "multi_nuclearpowerplant_28_base8",
  "refpalette": "deceasedcraft:multi_nuclearpowerplant_28/multi_nuclearpowerplant_28_base8_palette",
  "xsize": 16,
  "zsize": 16,
  "slices": [
    [
      "vvvvvvvvvvvvvvvv",
      "aaaaaaaaaaaaaaaa",
      "aaaaaaaaaaaaaaaa",
      "bbbbbbbbbbbbbbbb",
      "cbbbbbbbbbbbbbbb",
      "bbbbbbbbbbbbbbbb",
      "bbbbbbbbbbbbbbbb",
      "bbbbbbbbbbbbbbbb",
      "bbbbbbbbbbbbbbbb",
      "bbbbbbbbbbbbbbbb",
      "bbbbbbbbbbbbbbbd",
      "bbbbbbbbbbbbbbd ",
      "bbbbbbbbbbbbbbd ",
      "bbbbbbbbbbbbbd  ",
      "bbbbbbbbbbbbbd  ",
      "bbbbbbbbbbbbbd  "
    ],
    [
      "vvvvvvvvvvvvvvvv",
      "aaaaaaaaaaaaaaaa",
      "aaaaaaaaaaaaaaaa",
      "eeeeeeeeeeeeeeee",
      "c===============",
      "================",
      "================",
      "================",
      "================",
      "================",
      "===============e",
      "==============eb",
      "==============eb",
      "=============ebb",
      "=============ebb",
      "=============ebb"
    ],
    [
      "vvvvvvvvvvvvvvvv",
      "aaaaaaaaaaaaaaaa",
      "aaaaaaaaaaaaaaaa",
      "dddddddddddddddd",
      "cbaaaaaaaaaaaaaa",
      "bbaaaaaaaaaaaaaa",
      "aaaaaaaaaaaaaaaa",
      "aaaaaaaaaaaaaaaa",
      "aaaaaaaaaaaaaaaa",
      "aaaaaaaaaaaaaaaa",
      "aaaaaaaaaaaaaaad",
      "aaaaaaaaaaaaaada",
      "aaaaaaaaaaaaaada",
      "aaaaaaaaaaaaadaa",
      "aaaaaaaaaaaaadaa",
      "aaaaaaaaaaaaadaa"
    ],
    [
      "vvvvvvvvvvvvvvvv",
      "aaaaaaaaaaaaaaaa",
      "aaaaaaaaaaaaaaaa",
      "dddddddddddddddd",
      "cbaaaaaaaaaaaaaa",
      "bbaaaaaaaaaaaaaa",
      "aaaaaaaaaaaaaaaa",
      "aaaaaaaaaaaaaaaa",
      "aaaaaaaaaaaaaaaa",
      "aaaaaaaaaaaaaaaa",
      "aaaaaaaaaaaaaaad",
      "aaaaaaaaaaaaaada",
      "aaaaaaaaaaaaaada",
      "aaaaaaaaaaaaadaa",
      "aaaaaaaaaaaaadaa",
      "aaaaaaaaaaaaadaa"
    ],
    [
      "vvvvvvvvvvvvvvvv",
      "aaaaaaaaaaaaaaaa",
      "aaaaaaaaaaaaaaaa",
      "dddddddddddddddd",
      "cfffffffffffffff",
      "f===============",
      "================",
      "================",
      "================",
      "================",
      "================",
      "================",
      "f===============",
      "gf==============",
      "=gf=============",
      "==gf============"
    ],
    [
      "vvvvvvvvvvvvvvvv",
      "aaaaaaaaaaaaaaaa",
      "aaaaaaaaaaaaaaaa",
      "dddddddddddddddd",
      "c===============",
      "=hhhhhhhhhhhhhhh",
      "hhhhhhhhhhhhhhhh",
      "hhhhhhhhhhhhhhhh",
      "hhhhhhhhhhhhhhhh",
      "hhhhhhhhhhhhhhhh",
      "hhhhhhhhhhhhhhhh",
      "hhhhhhhhhhhhhhhh",
      "=hhhhhhhhhhhhhhh",
      " =hhhhhhhhhhhhhh",
      "  =hhhhhhhhhhhhh",
      "   =hhhhhhhhhhhh"
    ]
  ]
}