{
  "name": "multi_nuclearpowerplant_28_base11",
  "refpalette": "deceasedcraft:multi_nuclearpowerplant_28/multi_nuclearpowerplant_28_base11_palette",
  "xsize": 16,
  "zsize": 16,
  "slices": [
    [
      "vvvvvvvvvvvvvvvv",
      "aaaaaaaaaaaaaaaa",
      "aaaaaaaaaaaaaaaa",
      "aaaaaaaaaaaaaaaa",
      "aaaaaaaaaaaaaaaa",
      "aaaaaaaaaaaaaaaa",
      "aaaaaaaaaaaaaaaa",
      "aaaaaaaaaaaaaaaa",
      "aaaaaaaaaaaaaaaa",
      "aaaaaaaaaaaaaaaa",
      "aaaaaaaaaaaaaaab",
      "aaaaaaaaaaaaaab=",
      "aaaaaaaaaaaaaabc",
      "aaaaaaaaaaaaabcc",
      "aaaaaaaaaaaaabcd",
      "aaaaaaaaaaaaabcd"
    ],
    [
      "vvvvvvvvvvvvvvvv",
      "aaaaaaaaaaaaaaaa",
      "aaaaaaaaaaaaaaaa",
      "aaaaaaaaaaaaaaaa",
      "aaaaaaaaaaaaaaaa",
      "aaaaaaaaaaaaaaaa",
      "aaaaaaaaaaaaaaaa",
      "aaaaaaaaaaaaaaaa",
      "aaaaaaaaaaaaaaaa",
      "aaaaaaaaaaaaaaaa",
      "aaaaaaaaaaaaaaab",
      "aaaaaaaaaaaaaab=",
      "aaaaaaaaaaaaaabc",
      "aaaaaaaaaaaaabcc",
      "aaaaaaaaaaaaabcd",
      "aaaaaaaaaaaaabcd"
    ],
    [
      "vvvvvvvvvvvvvvvv",
      "aaaaaaaaaaaaaaaa",
      "aaaaaaaaaaaaaaaa",
      "aaaaaaaaaaaaaaaa",
      "aaaaaaaaaaaaaaaa",
      "aaaaaaaaaaaaaaaa",
      "aaaaaaaaaaaaaaaa",
      "aaaaaaaaaaaaaaaa",
      "aaaaaaaaaaaaaaaa",
      "aaaaaaaaaaaaaaaa",
      "aaaaaaaaaaaaaaab",
      "aaaaaaaaaaaaaab=",
      "aaaaaaaaaaaaaabc",
      "aaaaaaaaaaaaabcc",
      "aaaaaaaaaaaaabcd",
      "aaaaaaaaaaaaabcd"
    ],
    [
      "vvvvvvvvvvvvvvvv",
      "aaaaaaaaaaaaaaaa",
      "aaaaaaaaaaaaaaaa",
      "aaaaaaaaaaaaaaaa",
      "aaaaaaaaaaaaaaaa",
      "aaaaaaaaaaaaaaaa",
      "aaaaaaaaaaaaaaaa",
      "aaaaaaaaaaaaaaaa",
      "aaaaaaaaaaaaaaaa",
      "aaaaaaaaaaaaaaaa",
      "aaaaaaaaaaaaaaab",
      "aaaaaaaaaaaaaab=",
      "aaaaaaaaaaaaaabc",
      "aaaaaaaaaaaaabcc",
      "aaaaaaaaaaaaabcd",
      "aaaaaaaaaaaaabcd"
    ],
    [
      "vvvvvvvvvvvvvvvv",
      "aaaaaaaaaaaaaaaa",
      "aaaaaaaaaaaaaaaa",
      "aaaaaaaaaaaaaaaa",
      "aaaaaaaaaaaaaaaa",
      "aaaaaaaaaaaaaaaa",
      "aaaaaaaaaaaaaaaa",
      "aaaaaaaaaaaaaaaa",
      "aaaaaaaaaaaaaaaa",
      "aaaaaaaaaaaaaaaa",
      "aaaaaaaaaaaaaaab",
      "aaaaaaaaaaaaaab=",
      "aaaaaaaaaaaaaabc",
      "aaaaaaaaaaaaabcc",
      "aaaaaaaaaaaaabcd",
      "aaaaaaaaaaaaabcd"
    ],
    [
      "vvvvvvvvvvvvvvvv",
      "aaaaaaaaaaaaaaaa",
      "aaaaaaaaaaaaaaaa",
      "aaaaaaaaaaaaaaaa",
      "aaaaaaaaaaaaaaaa",
      "aaaaaaaaaaaaaaaa",
      "aaaaaaaaaaaaaaaa",
      "aaaaaaaaaaaaaaaa",
      "aaaaaaaaaaaaaaaa",
      "aaaaaaaaaaaaaaaa",
      "aaaaaaaaaaaaaaab",
      "aaaaaaaaaaaaaab=",
      "aaaaaaaaaaaaaabc",
      "aaaaaaaaaaaaabcc",
      "aaaaaaaaaaaaabcd",
      "aaaaaaaaaaaaabcd"
    ]
  ]
}