{
  "name": "multi_nuclearpowerplant_28_ground",
  "refpalette": "deceasedcraft:multi_nuclearpowerplant_28/multi_nuclearpowerplant_28_ground_palette",
  "xsize": 16,
  "zsize": 16,
  "slices": [
    [
      "zzaazzaaazzazzaz",
      "aaaaazazzaazazzz",
      "aaaaaazaaazaaaaz",
      "aaaaaaaaaaazaaza",
      "aaaaaaaaaaaaaaaa",
      "bbbbaaaaaaaaaaaa",
      "cccbbbbbaaaaaaaa",
      "cccccccbbbbaaaaa",
      "ccccccccccbbbaaa",
      "ccccccccccccbbba",
      "dcccccccccccccbb",
      "cdcccccccccccccc",
      "ccddcccccccccccc",
      "edccdccccccccccc",
      " edacdcccccccccc",
      " fedaadcccccccg "
    ],
    [
      "    hh          ",
      "       hh       ",
      "                ",
      "              h ",
      "ijkk            ",
      "zazzijkk        ",
      "zzzazzzzjik     ",
      "zzzzzazzzzzjk   ",
      "zzzzzzazzazzzjk ",
      "zzzzzzzzzzzzazai",
      "zzzzzzzzzzzzzzzz",
      "zzzzzzzzzzzzzzaz",
      "ccczzzzzzzzazzzz",
      "ccccczzzzzzzzzzz",
      "ccccccczzzzlzzza",
      "ccccccccczzzzz  "
    ],
    [
      "                ",
      "                ",
      "                ",
      "                ",
      "                ",
      "mmmm            ",
      "   mmmmm        ",
      "       mmmm     ",
      "    h     mmm   ",
      " h          mmm ",
      "      l       mm",
      "z       c       ",
      "zzah         l  ",
      "zzzzzz          ",
      "zzzzzzz         ",
      "zzzzzzzzz       "
    ],
    [
      "                ",
      "                ",
      "                ",
      "                ",
      "                ",
      "mmmm            ",
      "   mmmmm        ",
      "       mmmm     ",
      "          mmm   ",
      "            mmm ",
      "              mm",
      "                ",
      "                ",
      "                ",
      "                ",
      " h h n          "
    ],
    [
      "                ",
      "                ",
      "                ",
      "                ",
      "                ",
      "ooo             ",
      "    oooo        ",
      "        ooo     ",
      "           oo   ",
      "             o  ",
      "               o",
      "                ",
      "                ",
      "                ",
      "                ",
      "                "
    ],
    [
      "                ",
      "                ",
      "                ",
      "                ",
      "                ",
      "                ",
      "                ",
      "                ",
      "                ",
      "                ",
      "                ",
      "                ",
      "                ",
      "                ",
      "                ",
      "                "
    ]
  ]
}