{
  "name": "multi_nuclearpowerplant_28_base3",
  "refpalette": "deceasedcraft:multi_nuclearpowerplant_28/multi_nuclearpowerplant_28_base3_palette",
  "xsize": 16,
  "zsize": 16,
  "slices": [
    [
      "vvvvvvvvvvvvvvvv",
      "aaaaaaaaaaaaaaaa",
      "aaaaaaaaaaaaaaaa",
      "bbbbbbbbbbbbbbbb",
      "c===============",
      "=ddddddddddddddd",
      "deeeeeeeeeeeeeee",
      "eeeeeeeeeeeeeeee",
      "eeeeeeeeeeeeeeee",
      "eeeef           ",
      "eeeeg           ",
      "deeee           ",
      "=deeee          ",
      "c=deeee         ",
      "hccdeeee        ",
      "hhhcdeeee       "
    ],
    [
      "vvvvvvvvvvvvvvvv",
      "aaaaaaaaaaaaaaaa",
      "aaaaaaaaaaaaaaaa",
      "iiiiiiiiiiiiiiii",
      "i===============",
      "=jjjjjjjjjjjjjjj",
      "jk           k  ",
      "                ",
      "    llllllllllll",
      "                ",
      "                ",
      "jm  n           ",
      "=j   n          ",
      "o=j   n         ",
      "pooj   n        ",
      "pqqoj   n       "
    ],
    [
      "vvvvvvvvvvvvvvvv",
      "aaaaaaaaaaaaaaaa",
      "aaaaaaaaaaaaaaaa",
      "iiiiiiiiiiiiiiii",
      "i===============",
      "=jjjjjjjjjjjjjjj",
      "j               ",
      "                ",
      "                ",
      "                ",
      "                ",
      "j               ",
      "=j              ",
      "o=j             ",
      " ooj            ",
      "   oj           "
    ],
    [
      "vvvvvvvvvvvvvvvv",
      "aaaaaaaaaaaaaaaa",
      "aaaaaaaaaaaaaaaa",
      "iiiiiiiiiiiiiiii",
      "i===============",
      "=jjjjjjjjjjjjjjj",
      "j               ",
      "                ",
      "                ",
      "                ",
      "                ",
      "j               ",
      "=j              ",
      "o=j             ",
      " ooj            ",
      "   oj           "
    ],
    [
      "vvvvvvvvvvvvvvvv",
      "aaaaaaaaaaaaaaaa",
      "aaaaaaaaaaaaaaaa",
      "iiiiiiiiiiiiiiii",
      "i===============",
      "=jjjjjjjjjjjjjjj",
      "j               ",
      "                ",
      "                ",
      "                ",
      "                ",
      "j               ",
      "=j              ",
      "o=j             ",
      " ooj            ",
      "   oj           "
    ],
    [
      "vvvvvvvvvvvvvvvv",
      "aaaaaaaaaaaaaaaa",
      "aaaaaaaaaaaaaaaa",
      "iiiiiiiiiiiiiiii",
      "i===============",
      "=jjjjjjjjjjjjjjj",
      "j               ",
      "                ",
      "                ",
      "                ",
      "                ",
      "j               ",
      "=j              ",
      "o=j             ",
      " ooj            ",
      "   oj           "
    ]
  ]
}