{
  "name": "multi_nuclearpowerplant_28_base9",
  "refpalette": "deceasedcraft:multi_nuclearpowerplant_28/multi_nuclearpowerplant_28_base9_palette",
  "xsize": 16,
  "zsize": 16,
  "slices": [
    [
      "vvvvvvvvvvvvvvvv",
      "aaaaaaaaaaaaaaaa",
      "aaaaaaaaaaaaaaaa",
      "aaaaaaaaaaaaaaaa",
      "aaaaaaaaaaaaaaaa",
      "aaaaaaaaaaaaaaaa",
      "aaaaaaaaaaaaaaaa",
      "aaaaaaaaaaaaaaaa",
      "aaaaaaaaaaaaaaaa",
      "aaaaaaaaaaaaaaaa",
      "aaaaaaaaaaaaaaab",
      "aaaaaaaaaaaaaab ",
      "aaaaaaaaaaaaaab ",
      "aaaaaaaaaaaaab  ",
      "aaaaaaaaaaaaab  ",
      "aaaaaaaaaaaaab  "
    ],
    [
      "vvvvvvvvvvvvvvvv",
      "aaaaaaaaaaaaaaaa",
      "aaaaaaaaaaaaaaaa",
      "aaaaaaaaaaaaaaaa",
      "aaaaaaaaaaaaaaaa",
      "aaaaaaaaaaaaaaaa",
      "aaaaaaaaaaaaaaaa",
      "aaaaaaaaaaaaaaaa",
      "aaaaaaaaaaaaaaaa",
      "aaaaaaaaaaaaaaaa",
      "aaaaaaaaaaaaaaab",
      "aaaaaaaaaaaaaab ",
      "aaaaaaaaaaaaaab ",
      "aaaaaaaaaaaaab  ",
      "aaaaaaaaaaaaab  ",
      "aaaaaaaaaaaaab  "
    ],
    [
      "vvvvvvvvvvvvvvvv",
      "aaaaaaaaaaaaaaaa",
      "aaaaaaaaaaaaaaaa",
      "aaaaaaaaaaaaaaaa",
      "aaaaaaaaaaaaaaaa",
      "aaaaaaaaaaaaaaaa",
      "aaaaaaaaaaaaaaaa",
      "aaaaaaaaaaaaaaaa",
      "aaaaaaaaaaaaaaaa",
      "aaaaaaaaaaaaaaaa",
      "aaaaaaaaaaaaaaab",
      "aaaaaaaaaaaaaab ",
      "aaaaaaaaaaaaaab ",
      "aaaaaaaaaaaaab  ",
      "aaaaaaaaaaaaab  ",
      "aaaaaaaaaaaaab  "
    ],
    [
      "vvvvvvvvvvvvvvvv",
      "aaaaaaaaaaaaaaaa",
      "aaaaaaaaaaaaaaaa",
      "ccaaaaaaaaaaaaaa",
      "ccaaaaaaaaaaaaaa",
      "ccaaaaaaaaaaaaaa",
      "ccaaaaaaaaaaaaaa",
      "ccaaaaaaaaaaaaaa",
      "ccaaaaaaaaaaaaaa",
      "ccaaaaaaaaaaaaaa",
      "ccaaaaaaaaaaaaab",
      "ccaaaaaaaaaaaab ",
      "ccaaaaaaaaaaaab ",
      "ccaaaaaaaaaaab  ",
      "ccaaaaaaaaaaab  ",
      "ccaaaaaaaaaaab  "
    ],
    [
      "vvvvvvvvvvvvvvvv",
      "aaaaaaaaaaaaaaaa",
      "aaaaaaaaaaaaaaaa",
      "ccaaaaaaaaaaaaaa",
      "dcaaaaaaaaaaaaaa",
      "dcaaaaaaaaaaaaaa",
      "dcaaaaaaaaaaaaaa",
      "dcaaaaaaaaaaaaaa",
      "dcaaaaaaaaaaaaaa",
      "dcaaaaaaaaaaaaaa",
      "dcaaaaaaaaaaaaab",
      "dcaaaaaaaaaaaab ",
      "dcaaaaaaaaaaaab ",
      "dcaaaaaaaaaaab  ",
      "dcaaaaaaaaaaab  ",
      "dcaaaaaaaaaaab  "
    ],
    [
      "vvvvvvvvvvvvvvvv",
      "aaaaaaaaaaaaaaaa",
      "aaaaaaaaaaaaaaaa",
      "ccaaaaaaaaaaaaaa",
      "dcaaaaaaaaaaaaaa",
      "ccaaaaaaaaaaaaaa",
      "ccaaaaaaaaaaaaaa",
      "ccaaaaaaaaaaaaaa",
      "ccaaaaaaaaaaaaaa",
      "ccaaaaaaaaaaaaaa",
      "ccaaaaaaaaaaaaab",
      "ccaaaaaaaaaaaab ",
      "ccaaaaaaaaaaaab ",
      "ccaaaaaaaaaaab  ",
      "ccaaaaaaaaaaab  ",
      "ccaaaaaaaaaaab  "
    ]
  ]
}