{
  "name": "multi_terraceplaza_11_ground",
  "refpalette": "deceasedcraft:multi_terraceplaza_11/multi_terraceplaza_11_ground_palette",
  "xsize": 16,
  "zsize": 16,
  "slices": [
    [
      "aaaaaabccccccdcc",
      "aaaaaabccccccdcc",
      "aaaaaabccccccccc",
      "aaaaaabccccccccc",
      "aaaaaabccccccccc",
      "aaaaaabccccccccc",
      "aaaaaabccccccccc",
      "aaaaaabccccccccc",
      "aaaaaabccccccccc",
      "eeeeeefccccccccc",
      "aaaaaabccccccccc",
      "aaaaaabccccccccc",
      "aaaaaabccccccccc",
      "aaaaaabccccccccc",
      "aaaaaabccccccccc",
      "aaaaaabccccccccc"
    ],
    [
      " g  hij      kl ",
      "     mn      ko ",
      "     m       o  ",
      "     m          ",
      "     m          ",
      "p    m          ",
      "    qmn         ",
      "    hij         ",
      "   phij       r ",
      "eeeeeef      stu",
      "wwxy  j       A ",
      "   B  j         ",
      "   y  n         ",
      "   y            ",
      "CCDE            ",
      "FFF             "
    ],
    [
      "    hij         ",
      "     mn         ",
      "     m          ",
      "     m          ",
      "     m          ",
      "     m          ",
      "     mn         ",
      "    hij         ",
      "     ij         ",
      "eeeeeef       I ",
      "  J   j         ",
      "      j         ",
      "   K  n         ",
      "   L            ",
      "  MN            ",
      "                "
    ],
    [
      "     ij         ",
      "     mn         ",
      "     m          ",
      "     m          ",
      "     m          ",
      "     m          ",
      "     mn         ",
      "     ij         ",
      "    hij         ",
      "eeeeeef       O ",
      "      j         ",
      "      j         ",
      "      n         ",
      "                ",
      "PPQ             ",
      "               R"
    ],
    [
      "     ij         ",
      "     mn         ",
      "     m          ",
      "     m          ",
      "     m          ",
      "     m          ",
      "     mn         ",
      "     ij         ",
      "    hij         ",
      "eeeeeef       O ",
      "      j         ",
      "      j         ",
      "      n         ",
      "                ",
      "  S            R",
      "              TU"
    ],
    [
      "     iV         ",
      "     WV         ",
      "     WVX        ",
      "     WV         ",
      "     WV         ",
      "     WVX        ",
      "     WV         ",
      "     iV         ",
      "     iV         ",
      "eeeeeef         ",
      "      V         ",
      "      V         ",
      "     WVY        ",
      "     WVY       R",
      "  Z  WVY      TU",
      "     WVY       0"
    ]
  ]
}