{
  "name": "multi_terraceplaza_11_base1",
  "refpalette": "deceasedcraft:multi_terraceplaza_11/multi_terraceplaza_11_base1_palette",
  "xsize": 16,
  "zsize": 16,
  "slices": [
    [
      "                ",
      "                ",
      "                ",
      "                ",
      "                ",
      "                ",
      "                ",
      "                ",
      "                ",
      "      a         ",
      "               b",
      "               b",
      "               b",
      "               b",
      "               b",
      "               b"
    ],
    [
      "                ",
      "                ",
      "                ",
      "                ",
      "                ",
      "                ",
      "                ",
      "                ",
      "                ",
      "      a         ",
      "               b",
      "               b",
      "               b",
      "               b",
      "               b",
      "               b"
    ],
    [
      "                ",
      "                ",
      "                ",
      "                ",
      "                ",
      "                ",
      "                ",
      "                ",
      "                ",
      "      a         ",
      "               b",
      "               b",
      "               b",
      "               b",
      "               b",
      "               b"
    ],
    [
      "              cc",
      "              cc",
      "              cc",
      "              cc",
      "              cc",
      "              cc",
      "              cc",
      "              cc",
      "              cc",
      "      a       cc",
      "              cb",
      "              cb",
      "              cb",
      "              cb",
      "              cb",
      "              cb"
    ],
    [
      "ddddddddddddddde",
      "ddddddddddddddde",
      "ddddddddddddddde",
      "ddddddddddddddde",
      "ddddddddddddddde",
      "ddddddddddddddde",
      "ddddddddddddddde",
      "ddddddddddddddde",
      "ddddddddddddddde",
      "ddddddadddddddde",
      "ddddddddddddddde",
      "ddddddddddddddde",
      "ddddddddddddddde",
      "ddddddddddddddde",
      "ddddddddddddddde",
      "ddddddddddddddde"
    ],
    [
      "ffffffgffffffffh",
      "ffffffgffffffffh",
      "ffffffgffffffffh",
      "ffffffgffffffffh",
      "ffffffgffffffffh",
      "ffffffgffffffffh",
      "ffffffgffffffffh",
      "ffffffgffffffffh",
      "ffffffgffffffffh",
      "ggggggaggggggggg",
      "ffffffgffffffffh",
      "ffffffgffffffffh",
      "ffffffgffffffffh",
      "ffffffgffffffffh",
      "ffffffgffffffffh",
      "ffffffgffffffffh"
    ]
  ]
}