{
  "name": "multi_terraceplaza_11_floor1",
  "refpalette": "deceasedcraft:multi_terraceplaza_11/multi_terraceplaza_11_floor1_palette",
  "xsize": 16,
  "zsize": 16,
  "slices": [
    [
      "     ab         ",
      "      b         ",
      "      b         ",
      "      b         ",
      "      b         ",
      "      b         ",
      "      b         ",
      "     ab         ",
      "     ab         ",
      "ccccccd         ",
      "      b         ",
      "      b         ",
      "   e  b        f",
      "      b       gh",
      "  i   b        j",
      "      b         "
    ],
    [
      "kkkkkklmmmmmmmmm",
      "kkknkklmmmmmmmmm",
      "kkkkkklmmmmmmmmm",
      "kkkkkklmmmmmmmmm",
      "kkkkkklmmmmmmmmm",
      "kkkkkklmmmmmmmmm",
      "kkknkklmmmmmmmmm",
      "kkkkkklmmmmmmmmm",
      "kkkkkklmmmmmmmmm",
      "lllllldlllllllll",
      "kkkkkkl        o",
      "kkkkkkl        f",
      "kkkkkkl       gh",
      "kkkkkkl        j",
      "kkkkkkl         ",
      "kkkkkkl         "
    ],
    [
      "ppppppqrrrrrrrrr",
      "ppppppqrrrrrrrrr",
      "ppppppqrrrrrrrrr",
      "ppppppqrrrrrrrrr",
      "ppppppqrrrrrrrrr",
      "ppppppqrrrrrrrrr",
      "ppppppqrrrrrrrrr",
      "ppppppqrrrrrrrrr",
      "ppppppqrrrrrrrrr",
      "qqqqqqdsssssssst",
      "uwuuwwq       gt",
      "wwuwuwq       gh",
      "uwwwwwq        j",
      "wwwwwwq         ",
      "wwwwwwq         ",
      "wuwwwwq         "
    ],
    [
      "      x         ",
      "k   k y         ",
      "m   mAx         ",
      "m   mBx         ",
      "m   mCx         ",
      "mD  mEx         ",
      "k   k y         ",
      "      x         ",
      "      x         ",
      "  F  Idyyyyyyyyj",
      "      y        j",
      "   J  y        j",
      "      y         ",
      "      y         ",
      "      y         ",
      "      y         "
    ],
    [
      "      x         ",
      "K   L y         ",
      "M     x         ",
      "    N x         ",
      "O   P x         ",
      "Q     x         ",
      "D     y         ",
      "      x         ",
      "      x         ",
      "      d         ",
      "                ",
      "                ",
      "                ",
      "                ",
      "                ",
      "      RRRRRRRRRR"
    ],
    [
      "      x         ",
      "      y         ",
      "      x         ",
      "      x         ",
      "      x         ",
      "      x         ",
      "      y         ",
      "      x         ",
      "      x         ",
      "      d         ",
      "                ",
      "                ",
      "      RRRRRRRRRR",
      "SSSSSTUUUUUUUUUU",
      "SSSSSTpppppppppp",
      "SSSSSTVVVVVVVVVV"
    ]
  ]
}