{
  "name": "multi_terraceplaza_11_floor2",
  "refpalette": "deceasedcraft:multi_terraceplaza_11/multi_terraceplaza_11_floor2_palette",
  "xsize": 16,
  "zsize": 16,
  "slices": [
    [
      "      a         ",
      "      b         ",
      "      a         ",
      "      a         ",
      "      a         ",
      "      a         ",
      "      b         ",
      "      a         ",
      "      a         ",
      "ccccccdccccccccc",
      "eeeeeeffffffffff",
      "eeeeeegggggggggg",
      "hhhhhhhhhhhhhhhh",
      "      iiiiiiiiii",
      "                ",
      "                "
    ],
    [
      "      j         ",
      "      j         ",
      "      j         ",
      "      j         ",
      "      j         ",
      "      j         ",
      "eeeeeejeeeeeeeee",
      "ffffffjfffffffff",
      "ggggggjggggggggg",
      "kkkkkkkkkkkkkkkk",
      "kkkkkkkkkkkkkkkk",
      "                ",
      "                ",
      "                ",
      "                ",
      "                "
    ],
    [
      "      j         ",
      "      j         ",
      "      j         ",
      "eeeeeejeeeeeeeee",
      "ffffffjfffffffff",
      "llllllgggggggggg",
      "hhhhhhhhhhhhhhhh",
      "iiiiiiiiiiiiiiii",
      "mmmmmmmmmmmmmmmm",
      "nnnnnnnnnnnnnnnn",
      "                ",
      "                ",
      "                ",
      "                ",
      "                ",
      "                "
    ],
    [
      "eeeeeeoeeeeeeeee",
      "ffffffofffffffff",
      "llllllgggggggggg",
      "hhhhhhhhhhhhhhhh",
      "iiiiiiiiiiiiiiii",
      "                ",
      "                ",
      "                ",
      "                ",
      "                ",
      "                ",
      "                ",
      "                ",
      "                ",
      "                ",
      "                "
    ],
    [
      "hhhhhhhhhhhhhhhh",
      "iiiiiiiiiiiiiiii",
      "                ",
      "                ",
      "                ",
      "                ",
      "                ",
      "                ",
      "                ",
      "                ",
      "                ",
      "                ",
      "                ",
      "                ",
      "                ",
      "                "
    ],
    [
      "                ",
      "                ",
      "                ",
      "                ",
      "                ",
      "                ",
      "                ",
      "                ",
      "                ",
      "                ",
      "                ",
      "                ",
      "                ",
      "                ",
      "                ",
      "                "
    ]
  ]
}