{
  "name": "multi_terraceplaza_11_base2",
  "refpalette": "deceasedcraft:multi_terraceplaza_11/multi_terraceplaza_11_base2_palette",
  "xsize": 16,
  "zsize": 16,
  "slices": [
    [
      "aaaaaaaaaaaaaaaa",
      "aaaaaaaaaaaaaaaa",
      "aaaaaaaaaaaaaaaa",
      "aaaaaaaaaaaaaaaa",
      "aaaaaaaaaaaaaaaa",
      "aaaaaaaaaaaaaaaa",
      "aaaaaaaaaaaaaaaa",
      "aaaaaaaaaaaaaaaa",
      "aaaaaaaaaaaaaaaa",
      "aaaaaabaaaaaaaaa",
      "aaaaaaaaaaaaaaaa",
      "aaaaaaaaaaaaaaaa",
      "aaaaaaaaaaaaaaaa",
      "aaaaaaaaaaaaaaaa",
      "aaaaaaaaaaaaaaaa",
      "aaaaaaaaaaaaaaaa"
    ],
    [
      " cccccdcccccc   ",
      "                ",
      "                ",
      "                ",
      "                ",
      "                ",
      "                ",
      " e  ccdccc  e   ",
      " f  ghdgih  f   ",
      " j  ccbccc  j   ",
      "      d        k",
      " e  ccdccc  e   ",
      " f  ghdgih  f   ",
      " j  ccdccc  j   ",
      "      d         ",
      " e  ccdccc  e   "
    ],
    [
      "      l         ",
      "                ",
      "                ",
      "                ",
      "                ",
      "                ",
      "                ",
      "      l         ",
      "    m l         ",
      "      b         ",
      "      l        k",
      "      l         ",
      "      l m   n   ",
      "      l         ",
      "      l         ",
      "      l         "
    ],
    [
      "                ",
      "                ",
      "                ",
      "                ",
      "                ",
      "                ",
      "                ",
      "                ",
      "                ",
      "      b         ",
      "               k",
      "                ",
      "                ",
      "                ",
      "                ",
      "                "
    ],
    [
      "                ",
      "                ",
      "                ",
      "                ",
      "                ",
      "                ",
      "                ",
      "                ",
      "                ",
      "      b         ",
      "               k",
      "                ",
      "                ",
      "                ",
      "                ",
      "                "
    ],
    [
      "                ",
      "                ",
      "                ",
      "                ",
      "                ",
      "                ",
      "                ",
      "                ",
      "                ",
      "      b         ",
      "               k",
      "               k",
      "               k",
      "               k",
      "               k",
      "               k"
    ]
  ]
}