{
  "name": "multi_verticalschool_20_ground",
  "refpalette": "deceasedcraft:multi_verticalschool_20/multi_verticalschool_20_ground_palette",
  "xsize": 16,
  "zsize": 16,
  "slices": [
    [
      "HHHHHHHHHHHHHHHH",
      "HHHHHHHHHHHHHHHH",
      "HHHHHHHHHHHHHHHH",
      "HHHHHHHHHHHHHHHH",
      "aaaaaaaaaaaaaaaa",
      "bbbbbbbbbbbcbbcb",
      "bbbbbbbbbbbcbbcb",
      "bbbbbbbbbbbcbbcb",
      "ddddddddbbbcbbcb",
      "eeeeeeedbbbcbbcb",
      "eeeeeeedbbbcbbcb",
      "eeeeeeedbbbcbbcb",
      "eeeeeeedbbbcbbcb",
      "eeeeeeedbbbcbbcb",
      "eeeeeeedbbbcbbcb",
      "eeeeeeedbbbcbbcb"
    ],
    [
      "            ff  ",
      "            ff  ",
      "            ff  ",
      "            ff  ",
      "            ff  ",
      "           ghhg ",
      "           ghhg ",
      "iiiiiiiii  ghhg ",
      "jjjjjjjji  ghhg ",
      "kkkkkkkji  ghhg ",
      "kkkkkkkji  ghhg ",
      "kkkkkkkji  ghhg ",
      "kkkkkkkji  ghhg ",
      "kkkkkkkji  ghhg ",
      "kkkkkkkji  ghhg ",
      "kkkkkkkji  ghhg "
    ],
    [
      "                ",
      "                ",
      "                ",
      "                ",
      "                ",
      "                ",
      "                ",
      "lllllllll       ",
      "mmmmmmmjl       ",
      "       ml       ",
      "       ml       ",
      "       ml       ",
      "noop   ml       ",
      "   q   ml       ",
      " r q   ml       ",
      " r s   ml       "
    ],
    [
      "                ",
      "                ",
      "                ",
      "                ",
      "                ",
      "                ",
      "                ",
      "lllllllll       ",
      "mmmmmmmjl       ",
      "       ml       ",
      "       ml       ",
      "       ml       ",
      "       ml       ",
      "       ml       ",
      "       ml       ",
      "       ml       "
    ],
    [
      "                ",
      "                ",
      "                ",
      "                ",
      "                ",
      "                ",
      "                ",
      "lllllllll       ",
      "mmmmmmmjl       ",
      "       ml       ",
      "       ml       ",
      "       ml       ",
      "       ml       ",
      "       ml       ",
      "       ml       ",
      "       ml       "
    ],
    [
      "                ",
      "                ",
      "                ",
      "                ",
      "                ",
      "                ",
      "                ",
      "lllllllll       ",
      "mmmmmmmjl       ",
      "       ml       ",
      "       ml       ",
      "       ml       ",
      "       ml       ",
      "       ml       ",
      "       ml       ",
      "       ml       "
    ]
  ]
}