{
  "name": "multi_verticalschool_20_base1",
  "refpalette": "deceasedcraft:multi_verticalschool_20/multi_verticalschool_20_base1_palette",
  "xsize": 16,
  "zsize": 16,
  "slices": [
    [
      "vvvvvvvvvvvvvvvv",
      "aaaaaaaaaaabbbbv",
      "       cccabbbbv",
      "          abbbbv",
      "          abbbbv",
      "          abbbbv",
      "          abbbbv",
      "          abbbbv",
      "          abbbbv",
      "          abbbbv",
      "dddddd    abbbbv",
      "eeeeeee   abbbbv",
      "fgfgfhei  abbbbv",
      " j k hei  abbbbv",
      "fgfgfhei  abbbbv",
      "eeeelee   abbbbv"
    ],
    [
      "vvvvvvvvvvvvvvvv",
      "aaaaaaaaaaabbbbv",
      "       cccabbbbv",
      "          abbbbv",
      "          abbbbv",
      "          abbbbv",
      "          abbbbv",
      "          abbbbv",
      "          abbbbv",
      "          abbbbv",
      "          abbbbv",
      "mmmmmmn   abbbbv",
      "      o   abbbbv",
      "      o   abbbbv",
      "      o   abbbbv",
      "mmmmpmn   abbbbv"
    ],
    [
      "vvvvvvvvvvvvvvvv",
      "aaaaaaaaaaabbbbv",
      "       cccabbbbv",
      "          abbbbv",
      "          abbbbv",
      "          abbbbv",
      "          abbbbv",
      "          abbbbv",
      "          abbbbv",
      "          abbbbv",
      "          abbbbv",
      "qqqqqqr   abbbbv",
      "sssssst   abbbbv",
      "uuu !st   abbbbv",
      "sssssst   abbbbv",
      "qqqqqqr   abbbbv"
    ],
    [
      "vvvvvvvvvvvvvvvv",
      "aaaaaaaaaaabbbbv",
      "       cccabbbbv",
      "          abbbbv",
      "          abbbbv",
      "          abbbbv",
      "          abbbbv",
      "          abbbbv",
      "          abbbbv",
      "          abbbbv",
      "          abbbbv",
      "          abbbbv",
      "          abbbbv",
      "   wx     abbbbv",
      "          abbbbv",
      "          abbbbv"
    ],
    [
      "vvvvvvvvvvvvvvvv",
      "aaaaaaaaaaabbbbv",
      "       cccabbbbv",
      "          abbbbv",
      "          abbbbv",
      "          abbbbv",
      "          abbbbv",
      "          abbbbv",
      "          abbbbv",
      "          abbbbv",
      "          abbbbv",
      "          abbbbv",
      "          abbbbv",
      "          abbbbv",
      "          abbbbv",
      "          abbbbv"
    ],
    [
      "vvvvvvvvvvvvvvvv",
      "yyyyyyyyyyybbbbv",
      "AAAAAAAcccybbbbv",
      "AAAAAAAAAAybbbbv",
      "AAAAAAAAAAybbbbv",
      "AAAAAAAAAAybbbbv",
      "AAAAAAABBAybbbbv",
      "AAAAAAAAAAybbbbv",
      "AAAAAAAAAAybbbbv",
      "AAAAAAAAAAybbbbv",
      "AAAAAAAAAAybbbbv",
      "AAAAAAAAAAybbbbv",
      "AAAAAAAAAAybbbbv",
      "AAAAAAABBAybbbbv",
      "AAAAAAAAAAybbbbv",
      "AAAAAAAAAAybbbbv"
    ]
  ]
}