{
  "name": "multi_verticalschool_20_base2",
  "refpalette": "deceasedcraft:multi_verticalschool_20/multi_verticalschool_20_base2_palette",
  "xsize": 16,
  "zsize": 16,
  "slices": [
    [
      "vvvvvvvvvvvvvvvv",
      "vvvvvvvvvvvvvvvv",
      "vvvvvvvvvvvvvvvv",
      "vvvvvvvvvvvvvvvv",
      "vvvvvvvvvvvvvvvv",
      "vvvvvvvvvvvvvvvv",
      "vvvvvvvvvvvvvvvv",
      "vvvvvvvvvvvvvvvv",
      "vvvvvvvvvvvvvvvv",
      "vvvvvvvvvvvvvvvv",
      "vvvvvvvvvvvvvvvv",
      "vvvvvvvvvvvvvvvv",
      "vvvvvvvvvvvvvvvv",
      "vvvvvvvvvvvvvvvv",
      "vvvvvvvvvvvvvvvv",
      "vvvvvvvvvvvvvvvv"
    ],
    [
      "vvvvvvvvvvvvvvvv",
      "aaaaaaaaaaabbbbv",
      "aaaaaaacccabbbbv",
      "aaaaaaaaaaabbbbv",
      "aaaaaaaaaaabbbbv",
      "aaaaaaaaaaabbbbv",
      "aaaaaaaaaaabbbbv",
      "aaaaaaaaaaabbbbv",
      "aaaaaaaaaaabbbbv",
      "aaaaaaaaaaabbbbv",
      "aaaaaaaaaaabbbbv",
      "aaaaaaaaaaabbbbv",
      "aaaaaaaaaaabbbbv",
      "aaaaaaaaaaabbbbv",
      "aaaaaaaaaaabbbbv",
      "aaaaaaaaaaabbbbv"
    ],
    [
      "vvvvvvvvvvvvvvvv",
      "aaaaaaaaaaabbbbv",
      "aaaaaaacccabbbbv",
      "aaaaaaaaaaabbbbv",
      "aaaaaaaaaaabbbbv",
      "aaaaaaaaaaabbbbv",
      "aaaaaaaaaaabbbbv",
      "aaaaaaaaaaabbbbv",
      "aaaaaaaaaaabbbbv",
      "aaaaaaaaaaabbbbv",
      "aaaaaaaaaaabbbbv",
      "aaaaaaaaaaabbbbv",
      "aaaaaaaaaaabbbbv",
      "aaaaaaaaaaabbbbv",
      "aaaaaaaaaaabbbbv",
      "aaaaaaaaaaabbbbv"
    ],
    [
      "vvvvvvvvvvvvvvvv",
      "dddddddddddbbbbv",
      "eeeeeeecccdbbbbv",
      "HHHHHHHHHedbbbbv",
      "HHHHHHHHHedbbbbv",
      "HHHHHHHHHedbbbbv",
      "HHHHHHHHHedbbbbv",
      "HHHHHHHHHedbbbbv",
      "HHHHHHHHHedbbbbv",
      "HHHHHHHHHedbbbbv",
      "HHHHHHHHHedbbbbv",
      "HHHHHHHHHedbbbbv",
      "HHHHHHHHHedbbbbv",
      "HHHHHHHHHedbbbbv",
      "HHHHHHHHHedbbbbv",
      "HHHHHHHHHedbbbbv"
    ],
    [
      "vvvvvvvvvvvvvvvv",
      "dddddddddddbbbbv",
      "       cccdbbbbv",
      "          dbbbbv",
      "       f  dbbbbv",
      "          dbbbbv",
      "g         dbbbbv",
      "          dbbbbv",
      "       h  dbbbbv",
      "          dbbbbv",
      "   i      dbbbbv",
      "jjjkjlmf  dbbbbv",
      "nnnnnjl   dbbbbv",
      "nnnnnjl   dbbbbv",
      "nnnnnjl   dbbbbv",
      "jjjkjlmh  dbbbbv"
    ],
    [
      "vvvvvvvvvvvvvvvv",
      "ooooooooooobbbbv",
      "       cccobbbbv",
      "          obbbbv",
      "          obbbbv",
      "          obbbbv",
      "          obbbbv",
      "          obbbbv",
      "          obbbbv",
      "          obbbbv",
      "          obbbbv",
      "ppqrsppt  obbbbv",
      "uuuuuwx   obbbbv",
      "uuuuuwx   obbbbv",
      "uuuuuwx   obbbbv",
      "ppqysppt  obbbbv"
    ]
  ]
}