{
  "name": "multi_verticalschool_20_floor1",
  "refpalette": "deceasedcraft:multi_verticalschool_20/multi_verticalschool_20_floor1_palette",
  "xsize": 16,
  "zsize": 16,
  "slices": [
    [
      "                ",
      "                ",
      "                ",
      "                ",
      "                ",
      "                ",
      "                ",
      "aaaaaaaaa       ",
      "bbbbbbbca       ",
      "       ba       ",
      "       ba       ",
      "    d  ba       ",
      "       ba       ",
      "       ba       ",
      "       ba       ",
      "       ba       "
    ],
    [
      "                ",
      "                ",
      "                ",
      "                ",
      "                ",
      "                ",
      "                ",
      "aaaaaaaaa       ",
      "cccccccca       ",
      "eeeeeeeca       ",
      "ffffffeca       ",
      "ffffgfeca       ",
      "ffffffeca       ",
      "ffffffeca       ",
      "hhffffeca       ",
      " hffffeca       "
    ],
    [
      "                ",
      "                ",
      "                ",
      "                ",
      "                ",
      "                ",
      "                ",
      "aaaaaaaaa       ",
      "iiiiiiiia       ",
      "jjjjjjjia       ",
      "kllkkkjia       ",
      "llllkkjia       ",
      "llkllkjia       ",
      "kklllljia       ",
      "jjkllkjia       ",
      "fjkklkjia       "
    ],
    [
      "                ",
      "                ",
      "                ",
      "                ",
      "                ",
      "                ",
      "                ",
      "mmmmmmmmm       ",
      "nnnnnnnnm       ",
      "ooooooonm       ",
      "      onm       ",
      "      onm       ",
      "      onm       ",
      "      onm       ",
      "pp    onm       ",
      " p    onm       "
    ],
    [
      "                ",
      "                ",
      "                ",
      "                ",
      "                ",
      "                ",
      "                ",
      "                ",
      "                ",
      "qqqqqqq         ",
      "      q         ",
      "      q         ",
      "      q         ",
      "      q         ",
      "      q         ",
      "      q         "
    ],
    [
      "                ",
      "                ",
      "                ",
      "                ",
      "                ",
      "                ",
      "                ",
      "                ",
      "                ",
      "                ",
      "                ",
      "                ",
      "                ",
      "                ",
      "                ",
      "                "
    ]
  ]
}