{
  "name": "multi_courtyardofficetower_0_base1",
  "refpalette": "deceasedcraft:multi_courtyardofficetower_0/multi_courtyardofficetower_0_base1_palette",
  "xsize": 16,
  "zsize": 16,
  "slices": [
    [
      "vvvvvvvvvvvvvvvv",
      "vvvvvvvvvvvvvvvv",
      "vvvvvvvvvvvvvvvv",
      "vvvvvvvvvvvvvvvv",
      "vvvvvvvvvvvvvvvv",
      "vvvvvvvvvvvvvvvv",
      "vvvvvvvvvvvvvvvv",
      "vvvvvvvvvvvvvvvv",
      "vvvvvvvvvvabvvvv",
      "vvvvvvvvvaabvvvv",
      "vvvvvvvvaaabvvvv",
      "vvvvvvvvbbbbvvvv",
      "vvvvvvvvvvvvaaaa",
      "vvvvvvvvvvvvaaaa",
      "vvvvvvvvvvvvaaaa",
      "vvvvvvvvvvvvaaaa"
    ],
    [
      "vvvvvvvvvvvvvvvv",
      "vvvccccccccccccc",
      "vvccHHHHHHHHHHHH",
      "vccHHHHHHHHHHHHH",
      "vcHHHHHHHHHHHHHH",
      "vcHHHHHHHHHHHHHH",
      "vcHHHHHHHccccccc",
      "vcHHHHHHccvccccc",
      "vcHHHHHccvabcccc",
      "vcHHHHccvaabcccc",
      "vcHHHHcvaaabcccc",
      "vcHHHHccbbbbcccc",
      "vcHHHHccccccdddd",
      "vcHHHHccccccdeee",
      "vcHHHHccccccdeee",
      "vcHHHHccccccdeee"
    ],
    [
      "vvvvvvvvvvvvvvvv",
      "vvv             ",
      "vv              ",
      "v               ",
      "v               ",
      "v               ",
      "v               ",
      "v         v f g ",
      "v        vab    ",
      "v       vaab    ",
      "v      vaaabh i ",
      "v       bbbbjjjj",
      "v      f  gkllll",
      "v        m kleee",
      "v      h  ikleee",
      "v          kleee"
    ],
    [
      "vvvvvvvvvvvvvvvv",
      "vvv             ",
      "vv              ",
      "v               ",
      "v               ",
      "v               ",
      "v               ",
      "v         v     ",
      "v        vab    ",
      "v       vaab    ",
      "v      vaaab    ",
      "v       bbbb    ",
      "v           llll",
      "v           leee",
      "v           leee",
      "v           leee"
    ],
    [
      "vvvvvvvvvvvvvvvv",
      "vvv             ",
      "vv              ",
      "v               ",
      "v               ",
      "v               ",
      "v               ",
      "v         v     ",
      "v        vab    ",
      "v       vaab    ",
      "v      vaaab    ",
      "v       bbbb    ",
      "v           llll",
      "v           leee",
      "v           leee",
      "v           leee"
    ],
    [
      "vvvvvvvvvvvvvvvv",
      "vvvnnnnnnnnnnnnn",
      "vvnnnnnnnnnnnnnn",
      "vnnnnnnnnnnnnnnn",
      "vnnnnnnnnnnnnnnn",
      "vnnnnnnnnnnnnnnn",
      "vnnnnnnnnnnnnnnn",
      "vnnnnnnnnnvonnnn",
      "vnnnnnnnnvabnnnn",
      "vnnnnnnnvaabnnnn",
      "vnnnnnnvaaabnnnn",
      "vnnnnnnobbbbnnnn",
      "vnnnnnnnnnnnllll",
      "vnnnnnnnnnnnleee",
      "vnnnnnnnnnnnleee",
      "vnnnnnnnnnnnleee"
    ]
  ]
}