{
  "name": "multi_courtyardofficetower_0_ground",
  "refpalette": "deceasedcraft:multi_courtyardofficetower_0/multi_courtyardofficetower_0_ground_palette",
  "xsize": 16,
  "zsize": 16,
  "slices": [
    [
      "aaaaaaaaaaaabccb",
      "aaaaaaaaaaaaabcc",
      "aaaaaaaaaaaaadbc",
      "aaaaaaaaaaaaadab",
      "aaaaaaaaaaaaaadd",
      "aaaaaaaaaaaaaadd",
      "aaaaaaaaaaaaaddd",
      "aaaaaaaaaaaaddda",
      "aaaaaaaaaaaedddd",
      "aaaaaaaaaaaeaddd",
      "aaaaaaaaaaaeadda",
      "aaaaaaaaeeeefdda",
      "aaaaaaaaagggaddd",
      "aaaaaaaaaghifddd",
      "aaaaaaaaaghijddd",
      "aaaaaaaaagkijdda"
    ],
    [
      " l              ",
      "     ll     m   ",
      " n l   l   l    ",
      "      n         ",
      "  l             ",
      "    n    nl     ",
      "  l             ",
      " n  l    l      ",
      "      nll  e    ",
      " l         e    ",
      " l n       e    ",
      "        eeee   m",
      "    ll  oiii    ",
      "        oi      ",
      "     n  oi      ",
      "        oi      "
    ],
    [
      "                ",
      "                ",
      " o              ",
      "      o         ",
      "                ",
      "    o    o      ",
      "                ",
      " o              ",
      "      o    e    ",
      "           e    ",
      "   o       e    ",
      "        eeee    ",
      "                ",
      "                ",
      "     o          ",
      "                "
    ],
    [
      "                ",
      "                ",
      " l              ",
      "      l         ",
      "                ",
      "    l    l      ",
      "                ",
      " l              ",
      "      l    e    ",
      "           e    ",
      "   l       e    ",
      "        eeee    ",
      "                ",
      "                ",
      "     l          ",
      "                "
    ],
    [
      "                ",
      "                ",
      " l              ",
      "      l         ",
      "                ",
      "    l    l      ",
      "                ",
      " l              ",
      "      l    e    ",
      "           e    ",
      "   l       e    ",
      "        eeee    ",
      "                ",
      "                ",
      "     l          ",
      "                "
    ],
    [
      "                ",
      "                ",
      " l              ",
      "      l         ",
      "                ",
      "    l    l      ",
      "                ",
      " l              ",
      "      l    e    ",
      "           e    ",
      "   l       e    ",
      "        eeee    ",
      "                ",
      "                ",
      "     l          ",
      "                "
    ]
  ]
}