{
  "name": "stair_4",
  "refpalette": "deceasedcraft:stairs/stair_4_palette",
  "xsize": 16,
  "zsize": 16,
  "slices": [
    [
      "aaaa            ",
      "bbcd            ",
      "bbcd            ",
      "bbcd            ",
      "bbcd            ",
      "abcd            ",
      "bbcd            ",
      "bbcd            ",
      "bbcd            ",
      "bbcd            ",
      "abcd            ",
      "bbcd            ",
      "bbcd            ",
      "bbcd            ",
      "bbcd            ",
      "aaaa            "
    ],
    [
      "eeeee           ",
      "fgeee           ",
      "fheee           ",
      "feeee           ",
      "fheee           ",
      "igeee           ",
      "fheee           ",
      "fheee           ",
      "fgeee           ",
      "fheee           ",
      "ieeee           ",
      "fheee           ",
      "fgeee           ",
      "fheee           ",
      "feeee           ",
      "eeeee           "
    ],
    [
      "eeeee           ",
      "eeeee           ",
      "feeee           ",
      "feeee           ",
      "feeee           ",
      "ieeee           ",
      "feeee           ",
      "feeee           ",
      "feeee           ",
      "feeee           ",
      "ieeee           ",
      "feeee           ",
      "feeee           ",
      "eeeee           ",
      "feeee           ",
      "eeeee           "
    ],
    [
      "eeeee           ",
      "eeeee           ",
      "eeeee           ",
      "feeee           ",
      "eeeee           ",
      "iieee           ",
      "eeeee           ",
      "eeeee           ",
      "feeee           ",
      "eeeee           ",
      "iieee           ",
      "eeeee           ",
      "eeeee           ",
      "eeeee           ",
      "eeeee           ",
      "eeeee           "
    ],
    [
      "eeeee           ",
      "eeeee           ",
      "eeeee           ",
      "eeeee           ",
      "jeeee           ",
      "iiiee           ",
      "eeeej           ",
      "eeeee           ",
      "eeeee           ",
      "eeeej           ",
      "iiiee           ",
      "jeeee           ",
      "eeeee           ",
      "eeeee           ",
      "eeeee           ",
      "eeeee           "
    ],
    [
      "veeee           ",
      "veeee           ",
      "veeee           ",
      "kveee           ",
      "kkvee           ",
      "kkkvv           ",
      "kkkkkv          ",
      "kkkkkv          ",
      "kkkkkv          ",
      "kkkkkv          ",
      "kkkvv           ",
      "kkve            ",
      "kveee           ",
      "veeee           ",
      "veeee           ",
      "veeee           "
    ]
  ],
  "meta": [
    {
      "integer": 3,
      "key": "z1"
    },
    {
      "integer": 12,
      "key": "z2"
    }
  ]
}