{
  "name": "stair_deadzone_1",
  "refpalette": "deceasedcraft:stairs/stair_deadzone_1_palette",
  "xsize": 16,
  "zsize": 16,
  "slices": [
    [
      "ababaaaaaaababcd",
      "a           efff",
      "a           efff",
      "b           efff",
      "avvvvvvvvvvbaacc",
      "a               ",
      "b               ",
      "b               ",
      "a               ",
      "a               ",
      "a               ",
      "bvvvvvvvvvvabvdc",
      "a           efff",
      "a           efff",
      "a           efff",
      "aaabbaaaababvacd"
    ],
    [
      "aabaaabababagg  ",
      "b         ef    ",
      "a         ef    ",
      "a         ef    ",
      "avvvvvvvvaabgh  ",
      "b               ",
      "b               ",
      "a               ",
      "a               ",
      "a               ",
      "v               ",
      "vvvvvvvvvvabgh  ",
      "b         ef    ",
      "a         ef    ",
      "v         ef    ",
      "bavaabaabvbagg  "
    ],
    [
      "baaaaaavbaggg   ",
      "b       ef      ",
      "a       ef      ",
      "b       ef      ",
      "vvvvvvvbbagggi  ",
      "a               ",
      "b               ",
      "a               ",
      "a               ",
      "v               ",
      "b               ",
      "avvvvvvabagggi  ",
      "b       ef      ",
      "b       ef      ",
      "a       ef      ",
      "bavabbvbvaggg   "
    ],
    [
      "aabavavaggg     ",
      "b     ef        ",
      "v     ef        ",
      "a     ef        ",
      "avvvvvaaggg  j  ",
      "a               ",
      "v               ",
      "a               ",
      "b               ",
      "b               ",
      "b               ",
      "avvvvavaggg  j  ",
      "b     ef        ",
      "b     ef        ",
      "a     ef        ",
      "abbbvvvvggg     "
    ],
    [
      "abbabbggg       ",
      "a   ef          ",
      "a   ef          ",
      "b   ef          ",
      "avvavbggg       ",
      "b               ",
      "b               ",
      "v               ",
      "v               ",
      "b               ",
      "v               ",
      "bvvbbbggg       ",
      "a   ef          ",
      "a   ef          ",
      "b   ef          ",
      "aavbvbggg       "
    ],
    [
      "vbbvggg         ",
      "beef            ",
      "veef            ",
      "beef            ",
      "bvbbggg         ",
      "                ",
      "                ",
      "                ",
      "                ",
      "                ",
      "                ",
      "vbvbggg         ",
      "beef            ",
      "beef            ",
      "veef            ",
      "bvbaggg         "
    ]
  ],
  "meta": [
    {
      "integer": 0,
      "key": "z1"
    },
    {
      "integer": 15,
      "key": "z2"
    }
  ]
}