{
  "name": "stair_deadzone_2",
  "refpalette": "deceasedcraft:stairs/stair_deadzone_2_palette",
  "xsize": 16,
  "zsize": 16,
  "slices": [
    [
      "ababaabaabba    ",
      "zzzzzzzzzzza    ",
      "zzzzzzzzzzzb    ",
      "zzzazzzazzza    ",
      "aaabbaaaabab    ",
      "a               ",
      "b               ",
      "b               ",
      "a               ",
      "a               ",
      "a               ",
      "ababaaaaaaab    ",
      "zzzazzzbzzza    ",
      "zzzzzzzzzzza    ",
      "zzzzzzzzzzzb    ",
      "aaababaaabab    "
    ],
    [
      "                ",
      " c cc c c c     ",
      "cc  cc   c      ",
      " ddeddde dd     ",
      "bavaabaabvff    ",
      "b               ",
      "b               ",
      "a               ",
      "a               ",
      "a               ",
      "v               ",
      "aabaaababaff    ",
      "ddde dded d     ",
      "c cc c  c       ",
      "c c   cc  c     ",
      "                "
    ],
    [
      "                ",
      "                ",
      "                ",
      "   g   g        ",
      "bavabbvbfff     ",
      "a               ",
      "b               ",
      "a               ",
      "a               ",
      "v               ",
      "b               ",
      "baaaaaavfff     ",
      "   g   g        ",
      "                ",
      "                ",
      "                "
    ],
    [
      "                ",
      "                ",
      "                ",
      "                ",
      "abbbvvfff       ",
      "a               ",
      "v               ",
      "a               ",
      "b               ",
      "b               ",
      "b               ",
      "aabavafff       ",
      "                ",
      "                ",
      "                ",
      "                "
    ],
    [
      "                ",
      "                ",
      "                ",
      "                ",
      "aavbfff         ",
      "b               ",
      "b               ",
      "v               ",
      "v               ",
      "b               ",
      "v               ",
      "abbafff         ",
      "                ",
      "                ",
      "                ",
      "                "
    ],
    [
      "                ",
      "                ",
      "                ",
      "                ",
      "bvfff           ",
      "                ",
      "                ",
      "                ",
      "                ",
      "                ",
      "                ",
      "vbfff           ",
      "                ",
      "                ",
      "                ",
      "                "
    ]
  ],
  "meta": [
    {
      "integer": 5,
      "key": "z1"
    },
    {
      "integer": 10,
      "key": "z2"
    }
  ]
}