{
  "name": "stair_1",
  "refpalette": "deceasedcraft:stairs/stair_1_palette",
  "xsize": 16,
  "zsize": 16,
  "slices": [
    [
      "aaaaaaaaaaaabbbb",
      "acccccccccvddddb",
      "acccccccccvddddb",
      "acccccccccvddddb",
      "aaaaaaaaaaaaaaab",
      "acvccccceeeeeeab",
      "acvccccceeeeeeab",
      "acvccccceeeeeeab",
      "acvccccceeeeeeab",
      "acvccccceeeeeeab",
      "acvccccceeeeeeab",
      "aaaaaaaaaaaaaaab",
      "acccccccccvddddb",
      "acccccccccvddddb",
      "acccccccccvddddb",
      "aaaaaaaaaaaabbbb"
    ],
    [
      "aaaaaaaaafffgggg",
      "vcccccccvdgggggg",
      "vcccccccvdgggggg",
      "vcccccccvdgggggg",
      "aaaaaaaaafffgggg",
      "vcvhhhhaiggggggg",
      "vcvhhhhaiggggggg",
      "vcvhhhhaiggggggg",
      "vcvhhhhaiggggggg",
      "vcvhhhhaiggggggg",
      "vcvhhhhaiggggggg",
      "aaaaaaaaafffgggg",
      "vcccccccvdgggggg",
      "vcccccccvdgggggg",
      "vcccccccvdgggggg",
      "aaaaaaaaafffgggg"
    ],
    [
      "aaaaaaafffgggggg",
      "vcccccvdgggggggg",
      "vcccccvdgggggggg",
      "vcccccvdgggggggg",
      "aaaaaaafffgggggg",
      "vvvggggggggggggg",
      "vvvjgggggggggggg",
      "vvvggggggggggggg",
      "vvvggggggggggggg",
      "vvvjgggggggggggg",
      "vvvggggggggggggg",
      "aaaaaaafffgggggg",
      "vcccccvdgggggggg",
      "vcccccvdgggggggg",
      "vcccccvdgggggggg",
      "aaaaaaafffgggggg"
    ],
    [
      "aaaaafffgggggggg",
      "vcccvdgggggggggg",
      "vcccvdgggggggggg",
      "vcccvdgggggggggg",
      "aaaaafffgggggggg",
      "vvvggggggggggggg",
      "vhklgggggggggggg",
      "vvvggggggggggggg",
      "vvvggggggggggggg",
      "vhklgggggggggggg",
      "vvvggggggggggggg",
      "aaaaafffgggggggg",
      "vcccvdgggggggggg",
      "vcccvdgggggggggg",
      "vcccvdgggggggggg",
      "aaaaafffgggggggg"
    ],
    [
      "aaafffgggggggggg",
      "vcvdgggggggggggg",
      "vcvdgggggggggggg",
      "vcvdgggggggggggg",
      "aaafffgggggggggg",
      "vvvmgggggggggggg",
      "vvvmgggggggggggg",
      "vvvmgggggggggggg",
      "vvvmgggggggggggg",
      "vvvmgggggggggggg",
      "vvvmgggggggggggg",
      "aaafffgggggggggg",
      "vcvdgggggggggggg",
      "vcvdgggggggggggg",
      "vcvdgggggggggggg",
      "aaafffgggggggggg"
    ],
    [
      "afffgggggggggggg",
      "vdgggggggggggggg",
      "vdgggggggggggggg",
      "vdgggggggggggggg",
      "afffgggggggggggg",
      "gggfgggggggggggg",
      "gggfgggggggggggg",
      "gggfgggggggggggg",
      "gggfgggggggggggg",
      "gggfgggggggggggg",
      "gggfgggggggggggg",
      "afffgggggggggggg",
      "vdgggggggggggggg",
      "vdgggggggggggggg",
      "vdgggggggggggggg",
      "afffgggggggggggg"
    ]
  ],
  "meta": [
    {
      "integer": 0,
      "key": "z1"
    },
    {
      "integer": 15,
      "key": "z2"
    }
  ]
}