{
  "name": "stair_3",
  "refpalette": "deceasedcraft:stairs/stair_3_palette",
  "xsize": 16,
  "zsize": 16,
  "slices": [
    [
      "abbbbbbbbbbbbbbb",
      "accccccccccccccb",
      "accccccccccccccb",
      "adddddddddddcccb",
      "adeeeeeeeeedcccb",
      "adeeeeeeeeedcccb",
      "adeeeeeeeeedcccb",
      "adddddddddddcccb",
      "accccccccccccccb",
      "accccccccccccccb",
      "ffffffffffffbbbb",
      "aggggggggghiiiii",
      "aggggggggghiiiii",
      "aggggggggghiiiii",
      "aggggggggghiiiii",
      "ffffffffffffbbbb"
    ],
    [
      "ajjjjjjjjjjjjjjj",
      "ajjjjjjjjjjjjjjj",
      "ajjjjjjjjjjjjjjj",
      "akkkkkkkkkkkjjjj",
      "akljjjljjjlkjjjj",
      "akljmjljmjlkjjjj",
      "akljjjljjjlkjjjj",
      "akkkkkkkkkkkjjjj",
      "ajjjjjjjjjjjjjjj",
      "ajjjjjjjjjjjjjjj",
      "ffffffffffnnjjjj",
      "aggggggghijjjjjj",
      "aggggggghijjjjjj",
      "aggggggghijjjjjj",
      "aggggggghijjjjjj",
      "ffffffffffnnjjjj"
    ],
    [
      "ajjjjjjjjjjjjjjj",
      "ajjjjjjjjjjjjjjj",
      "ajjjjjjjjjjjjjjj",
      "ajjjjjjjjjjjjjjj",
      "ajjjjjjjjjjjjjjj",
      "ajjj~jjj~jjjjjjj",
      "ajjjjjjjjjjjjjjj",
      "ajjjjjjjjjjjjjjj",
      "ajjjjjjjjjjjjjjj",
      "ajjjjjjjjjjjjjjj",
      "ffffffffnnjjjjjj",
      "aggggghijjjjjjjj",
      "aggggghijjjjjjjj",
      "aggggghijjjjjjjj",
      "aggggghijjjjjjjj",
      "ffffffffnnjjjjjj"
    ],
    [
      "ajjjjjjjjjjjjjjj",
      "ajjjjjjjjjjjjjjj",
      "ajjjjjjjjjjjjjjj",
      "ajjjjjjjjjjjjjjj",
      "ajjjjjjjjjjjjjjj",
      "ajjjjjjjjjjjjjjj",
      "ajjjjjjjjjjjjjjj",
      "ajjjjjjjjjjjjjjj",
      "ajjjjjjjjjjjjjjj",
      "ajjjjjjjjjjjjjjj",
      "ffffffnnjjjjjjjj",
      "aggghijjjjjjjjjj",
      "aggghijjjjjjjjjj",
      "aggghijjjjjjjjjj",
      "aggghijjjjjjjjjj",
      "ffffffnnjjjjjjjj"
    ],
    [
      "ajjjjjjjjjjjjjjj",
      "ajjjjjjjjjjjjjjj",
      "ajjjjjjjjjjjjjjj",
      "ajjjjjjjjjjjjjjj",
      "ajjjjjjjjjjjjjjj",
      "ajjjjjjjjjjjjjjj",
      "ajjjjjjjjjjjjjjj",
      "ajjjjjjjjjjjjjjj",
      "ajjjjjjjjjjjjjjj",
      "ajjjjjjjjjjjjjjj",
      "ffffnnjjjjjjjjjj",
      "aghijjjjjjjjjjjj",
      "aghijjjjjjjjjjjj",
      "aghijjjjjjjjjjjj",
      "aghijjjjjjjjjjjj",
      "ffffnnjjjjjjjjjj"
    ],
    [
      "bjjjjjjjjjjjjjjj",
      "bjjjjjjjjjjjjjjj",
      "bjjjjjjjjjjjjjjj",
      "bjjjjjjjjjjjjjjj",
      "bjjjjjjjjjjjjjjj",
      "bjjjjjjjjjjjjjjj",
      "bjjjjjjjjjjjjjjj",
      "bjjjjjjjjjjjjjjj",
      "bjjjjjjjjjjjjjjj",
      "bjjjjjjjjjjjjjjj",
      "ffnnjjjjjjjjjjjj",
      "hijjjjjjjjjjjjjj",
      "hijjjjjjjjjjjjjj",
      "hijjjjjjjjjjjjjj",
      "hijjjjjjjjjjjjjj",
      "ffnnjjjjjjjjjjjj"
    ]
  ],
  "meta": [
    {
      "integer": 11,
      "key": "z1"
    },
    {
      "integer": 14,
      "key": "z2"
    }
  ]
}