{
  "name": "stair_2",
  "refpalette": "deceasedcraft:stairs/stair_2_palette",
  "xsize": 16,
  "zsize": 16,
  "slices": [
    [
      "aaaaaaaaaaaaaaaa",
      "abbbbbbbbbbbbbba",
      "abccccccccccccba",
      "abccccccccccccba",
      "ddddddddddddddaa",
      "deeeeeeeeeeffggg",
      "deeeeeeeeeeHHhhh",
      "deeeeeeeeeeHHhhh",
      "deeeeeeeeeeHHhhh",
      "deeeeeeeeeeHHhhh",
      "deeeeeeeeeeffggg",
      "ddd dd dd ddddaa",
      "abccccccccccccba",
      "abccccccccccccba",
      "abbbbbbbbbbbbbba",
      "aaaaaaaaaaaaaaaa"
    ],
    [
      "iiiiiiiiiiiiiiii",
      "ijjjjjjjjjjjjjji",
      "ijikiikiikiikiji",
      "ijiiiiiiiiiiiiji",
      "dddlddlddlddaiii",
      "deemeemeemfgiiii",
      "deeeeeeeeHHhiiii",
      "deeeeeeeeHHhiiii",
      "deeeeeeeeHHhiiii",
      "deeeeeeeeHHhiiii",
      "deemeemeemfgiiii",
      "dddlddlddlddaiii",
      "ijiiiiiiiiiiiiji",
      "ijikiikiikiikiji",
      "ijjijjjjjjjjijji",
      "iiiiiiiiiiiiiiii"
    ],
    [
      "iiiiiiiiiiiiiiii",
      "iiiiiiiiiiiiiiii",
      "iiiniiniiniiniii",
      "iiiiiiiiiiiiiiii",
      "ddddddddddaiiiii",
      "deeeeeeffgiiiiii",
      "deeeeeeHHhiiiiii",
      "deeeeeeHHhiiiiii",
      "deeeeeeHHhiiiiii",
      "deeeeeeHHhiiiiii",
      "deeeeeeffgiiiiii",
      "ddddddddddaiiiii",
      "iiiiiiiiiiiiiiii",
      "iiiniiniiniiniii",
      "iiiiiiiiiiiiiiii",
      "iiiiiiiiiiiiiiii"
    ],
    [
      "iiiiiiiiiiiiiiii",
      "iiiiiiiiiiiiiiii",
      "iiiiiiiiiiiiiiii",
      "iiiiiiiiiiiiiiii",
      "ddddddddaiiiiiii",
      "deeeeffgiiiiiiii",
      "deeeeHHhiiiiiiii",
      "deeeeHHhiiiiiiii",
      "deeeeHHhiiiiiiii",
      "deeeeHHhiiiiiiii",
      "deeeeffgiiiiiiii",
      "ddddddddaiiiiiii",
      "iiiiiiiiiiiiiiii",
      "iiiiiiiiiiiiiiii",
      "iiiiiiiiiiiiiiii",
      "iiiiiiiiiiiiiiii"
    ],
    [
      "iiiiiiiiiiiiiiii",
      "iiiiiiiiiiiiiiii",
      "iiiiiiiiiiiiiiii",
      "iiiiiiiiiiiiiiii",
      "ddddddaiiiiiiiii",
      "deeffgiiiiiiiiii",
      "deeHHh iiiiiiiii",
      "deeHHhiiiiiiiiii",
      "deeHHhiiiiiiiiii",
      "deeHHhiiiiiiiiii",
      "deeffgiiiiiiiiii",
      "ddddddaiiiiiiiii",
      "iiiiiiiiiiiiiiii",
      "iiiiiiiiiiiiiiii",
      "iiiiiiiiiiiiiiii",
      "iiiiiiiiiiiiiiii"
    ],
    [
      "iiiiiiiiiiiiiiii",
      "iiiiiiiiiiiiiiii",
      "iiiiiiiiiiiiiiii",
      "iiiiiiiiiiiiiiii",
      "ddddaiiiiiiiiiii",
      "fffgiiiiiiiiiiii",
      "HHHhiiiiiiiiiiii",
      "HHHhiiiiiiiiiiii",
      "HHHhiiiiiiiiiiii",
      "HHHhiiiiiiiiiiii",
      "fffgiiiiiiiiiiii",
      "ddddaiiiiiiiiiii",
      "iiiiiiiiiiiiiiii",
      "iiiiiiiiiiiiiiii",
      "iiiiiiiiiiiiiiii",
      "iiiiiiiiiiiiiiii"
    ],
    [
      "iiiiiiiiiiiiiiii",
      "iiiiiiiiiiiiiiii",
      "iiiiiiiiiiiiiiii",
      "iiiiiiiiiiiiiiii",
      "iiiiiiiiiiiiiiii",
      "iiiiiiiiiiiiiiii",
      "iiiiiiiiiiiiiiii",
      "iiiiiiiiiiiiiiii",
      "iiiiiiiiiiiiiiii",
      "iiiiiiiiiiiiiiii",
      "iiiiiiiiiiiiiiii",
      "iii iiiiiiiiiiii",
      "iiiiiiiiiiiiiiii",
      "iiiiiiiiiiiiiiii",
      "iiiiiiiiiiiiiiii",
      "iiiiiiiiiiiiiiii"
    ]
  ],
  "meta": [
    {
      "integer": 5,
      "key": "z1"
    },
    {
      "integer": 10,
      "key": "z2"
    }
  ]
}