{
  "name": "multi_taigaresidence_1_base2",
  "refpalette": "deceasedcraft:multi_taigaresidence_1/multi_taigaresidence_1_base2_palette",
  "xsize": 16,
  "zsize": 16,
  "slices": [
    [
      "vaHHHHHHHHHHHHHH",
      "vaHHHHHHHHaHHHHH",
      "vaHHHHHHHHHHHHHH",
      "vaHHHHHHHHHHHHHH",
      "vaHHHHHHHHHHHHHH",
      "vaHHHHHHHHHHHHHH",
      "vaHHHHHHHHHHHHHH",
      "vaHHHHHHHHHHHHHH",
      "vaHHHHHHHHHHHHHH",
      "vaHHHHHHHHHHHHHH",
      "vaHHHHHHHHHHHHHH",
      "vaHHHHHHHHHHHHHH",
      "vaHHHHHHHHHHHHHH",
      "vaHHHHHHHHHHHHHH",
      "vaHHHHHHHHaHHHHH",
      "vaHHHHHHHHHHHHHH"
    ],
    [
      "vab c           ",
      "vad e  fffafff  ",
      "vab c  b cgb c  ",
      "vad e  d egd e  ",
      "vab c  b cgb c  ",
      "vad e  d egd e  ",
      "vab c  b cgb c  ",
      "vad e  d egdhe  ",
      "vab c  b cgb c  ",
      "vad e  d egd e  ",
      "vab c  b cgb c  ",
      "vad ei d egd e  ",
      "vab c  b cgb c  ",
      "vad e  d egd e  ",
      "vajjj  jjjajjj  ",
      "va              "
    ],
    [
      "va              ",
      "va        a     ",
      "va              ",
      "va              ",
      "va              ",
      "va              ",
      "va              ",
      "va              ",
      "va              ",
      "va              ",
      "va              ",
      "va              ",
      "va              ",
      "va              ",
      "va        a     ",
      "va              "
    ],
    [
      "va              ",
      "va        a     ",
      "va              ",
      "va              ",
      "va              ",
      "va              ",
      "va              ",
      "va              ",
      "va              ",
      "va              ",
      "va              ",
      "va              ",
      "va              ",
      "va              ",
      "va        a     ",
      "va              "
    ],
    [
      "vak       a     ",
      "vaaaaaaaaaaaaaaa",
      "vak       a     ",
      "vak       a     ",
      "vak       a     ",
      "vak       a     ",
      "vak       a     ",
      "vak       a     ",
      "vak       a     ",
      "vak       a     ",
      "vak       a     ",
      "vak       a     ",
      "vak       a     ",
      "vak       a     ",
      "vaaaaaaaaaaaaaaa",
      "vak       a     "
    ],
    [
      "vallllllllalllll",
      "vaaaaaaaaaaaaaaa",
      "vallllllllalllll",
      "vallllllllalllll",
      "vallllllllalllll",
      "vallllllllalllll",
      "vallllllllalllll",
      "vallllllllalllll",
      "vallllllllalllll",
      "vallllllllalllll",
      "vallllllllalllll",
      "vallllllllalllll",
      "vallllllllalllll",
      "vallllllllalllll",
      "vaaaaaaaaaaaaaaa",
      "vallllllllalllll"
    ]
  ]
}