{
  "name": "multi_taigaresidence_1_floor4",
  "refpalette": "deceasedcraft:multi_taigaresidence_1/multi_taigaresidence_1_floor4_palette",
  "xsize": 16,
  "zsize": 16,
  "slices": [
    [
      "   abcccddefgggg",
      "  hhbbbbbbefgijj",
      "   ab     efgk  ",
      "   ab    lefgk  ",
      "   ak     efgk  ",
      "   ak     efgk  ",
      "   ak     efgk  ",
      "   ak     efgk  ",
      "   ak     efgk  ",
      "   ak     efgk  ",
      "   ak     efgk  ",
      "   ak     efgk  ",
      "   ab     efgk  ",
      "   ab     efgk  ",
      "  hhbbbbbbefgmnn",
      "   abcccddefgggg"
    ],
    [
      "    bopqrrb     ",
      "  hhbbbbbbb  sss",
      "    b    t   s  ",
      "    b        s  ",
      "         u   s  ",
      "         uw  s  ",
      "         uw  s  ",
      "         u   s  ",
      "         u   s  ",
      "         uw  s  ",
      "         uw  s  ",
      "         u   s  ",
      "    b    u   s  ",
      "    b    u   s  ",
      "  hhbbbbbbb  sss",
      "    bxyqAAb     "
    ],
    [
      "    b  qBBb     ",
      "  hhbbbbbbb     ",
      "    b   t       ",
      "    b           ",
      "                ",
      "                ",
      "                ",
      "                ",
      "                ",
      "                ",
      "                ",
      "                ",
      "    b           ",
      "    b     C     ",
      "  hhbbbbbbb     ",
      "    b  qDDb     "
    ],
    [
      "    b  q  b     ",
      "  hhbbbbbbb     ",
      "    bEEt        ",
      "    bEE         ",
      "                ",
      "                ",
      "                ",
      "                ",
      "                ",
      "                ",
      "                ",
      "                ",
      "    b           ",
      "    b           ",
      "  hhbbbbbbb     ",
      "    b FqI b     "
    ],
    [
      "    b  q  b     ",
      "  hhbbbbbbb     ",
      "    b           ",
      "    bJJl        ",
      "                ",
      "                ",
      "                ",
      "                ",
      "                ",
      "                ",
      "                ",
      "                ",
      "    b           ",
      "    b           ",
      "  hhbbbbbbb     ",
      "    b  q  b     "
    ],
    [
      "    bKKKKKb     ",
      "  hhbbbbbbb     ",
      "    b           ",
      "    b   l       ",
      "                ",
      "       L        ",
      "                ",
      "                ",
      "                ",
      "                ",
      "       LL       ",
      "                ",
      "    b           ",
      "    b           ",
      "  hhbbbbbbb     ",
      "    bKKKKKb     "
    ]
  ]
}