{
  "name": "multi_taigaresidence_1_floor5",
  "refpalette": "deceasedcraft:multi_taigaresidence_1/multi_taigaresidence_1_floor5_palette",
  "xsize": 16,
  "zsize": 16,
  "slices": [
    [
      "   abcccddefgggg",
      "  hhbbbbbbefgijj",
      "   ab     efgk  ",
      "   ab    lefgk  ",
      "   akeeeeeefgk  ",
      "   akeeeeeefgk  ",
      "   akeeeeeefgk  ",
      "   akeeeeeefgk  ",
      "   akeeeeeefgk  ",
      "   akeeeeeefgk  ",
      "   akeeeeeefgk  ",
      "   akeeeeeefgk  ",
      "   abeeeeeefgk  ",
      "   abeeeeeefgk  ",
      "  hhbbbbbbefgmnn",
      "   abcccddefgggg"
    ],
    [
      "    bopqrrb     ",
      "  hhbbbbbbb  sss",
      "    b    tu ws  ",
      "    bxxxxxy  s  ",
      "      ABCADE s  ",
      "      E    u s  ",
      "       FIJK Ls  ",
      "      M   N Os  ",
      "     D P Q Rws  ",
      "     S T  UV s  ",
      "     W  X  X s  ",
      "      AFIA   s  ",
      "    b      YZs  ",
      "    b000!0   s  ",
      "  hhbbbbbbb1 sss",
      "    b23q44b     "
    ],
    [
      "    b  q55b     ",
      "  hhbbbbbbb     ",
      "    b   t       ",
      "    b           ",
      "                ",
      "                ",
      "                ",
      "                ",
      "                ",
      "                ",
      "                ",
      "                ",
      "    b           ",
      "    b000006     ",
      "  hhbbbbbbb     ",
      "    b  q77b     "
    ],
    [
      "    b  q  b     ",
      "  hhbbbbbbb     ",
      "    b88t        ",
      "    b88         ",
      "                ",
      "                ",
      "                ",
      "                ",
      "                ",
      "                ",
      "                ",
      "                ",
      "    b           ",
      "    b           ",
      "  hhbbbbbbb     ",
      "    b  q !b     "
    ],
    [
      "    b  q  b     ",
      "  hhbbbbbbb     ",
      "    b           ",
      "    bxxl        ",
      "                ",
      "                ",
      "                ",
      "                ",
      "                ",
      "                ",
      "                ",
      "                ",
      "    b           ",
      "    b           ",
      "  hhbbbbbbb     ",
      "    b  q  b     "
    ],
    [
      "    b99999b     ",
      "  hhbbbbbbb     ",
      "    b           ",
      "    b   l       ",
      "                ",
      "        #       ",
      "                ",
      "                ",
      "                ",
      "                ",
      "                ",
      "                ",
      "    b           ",
      "    b           ",
      "  hhbbbbbbb     ",
      "    b99999b     "
    ]
  ]
}