{
  "name": "multi_taigaresidence_1_floor6",
  "refpalette": "deceasedcraft:multi_taigaresidence_1/multi_taigaresidence_1_floor6_palette",
  "xsize": 16,
  "zsize": 16,
  "slices": [
    [
      "   abcccccdeffff",
      "  ggbbbbbbdefhii",
      "   ab     defj  ",
      "   ab    kdefj  ",
      "   ajddddddefj  ",
      "   ajddddddefj  ",
      "   ajddddddefj  ",
      "   ajddddddefj  ",
      "   ajddddddefj  ",
      "   ajddddddefj  ",
      "   ajddddddefj  ",
      "   ajddddddefj  ",
      "   abddddddefj  ",
      "   abddddddefj  ",
      "  ggbbbbbbdeflmm",
      "   abcccccdeffff"
    ],
    [
      "    b   nob     ",
      "  ggbbbbbbb  ppp",
      "    b    q   p  ",
      "    brrrrr   p  ",
      "             p  ",
      "      st     p  ",
      "         u   p  ",
      "      ww x   p  ",
      "      ww x   p  ",
      "         y   p  ",
      "      AB     p  ",
      "             p  ",
      "    b        p  ",
      "    bCCCCC   p  ",
      "  ggbbbbbbb  ppp",
      "    bDE F b     "
    ],
    [
      "    bI    b     ",
      "  ggbbbbbbb     ",
      "    bJ  J K     ",
      "    b           ",
      "                ",
      "                ",
      "                ",
      "                ",
      "                ",
      "                ",
      "                ",
      "                ",
      "    b           ",
      "    bCCCCCK     ",
      "  ggbbbbbbb     ",
      "    b     b     "
    ],
    [
      "    bL   Mb     ",
      "  ggbbbbbbb     ",
      "    bN JNJ      ",
      "    b           ",
      "                ",
      "                ",
      "                ",
      "                ",
      "                ",
      "                ",
      "                ",
      "                ",
      "    b           ",
      "    bJ  J       ",
      "  ggbbbbbbb     ",
      "    b   O b     "
    ],
    [
      "    b     b     ",
      "  ggbbbbbbb     ",
      "    bNJNNN      ",
      "    b           ",
      "                ",
      "                ",
      "                ",
      "                ",
      "                ",
      "                ",
      "                ",
      "                ",
      "    b           ",
      "    bNJ NJ      ",
      "  ggbbbbbbb     ",
      "    b     b     "
    ],
    [
      "    bPPPPPb     ",
      "  ggbbbbbbb     ",
      "    bNNNNN      ",
      "    b           ",
      "                ",
      "                ",
      "                ",
      "                ",
      "                ",
      "                ",
      "                ",
      "                ",
      "    b           ",
      "    bNNJNN      ",
      "  ggbbbbbbb     ",
      "    bPPPPPb     "
    ]
  ]
}