{
  "name": "multi_taigaresidence_1_ground",
  "refpalette": "deceasedcraft:multi_taigaresidence_1/multi_taigaresidence_1_ground_palette",
  "xsize": 16,
  "zsize": 16,
  "slices": [
    [
      "aaabcbbbbbbbbbbb",
      "aaddcbbbbbbbbbbb",
      "aaabcbbbbbbbbbbb",
      "aaabcbbbbbbbbebb",
      "afabbbbbeebbbbbb",
      "aaabbbbbbbebebbb",
      "fafbbbbbbbbbbebb",
      "fffbbbbbebbbbbbb",
      "affbbbbbbebbbbbb",
      "fffbbbbbbebebbbb",
      "faabbbbbbbbbbbbb",
      "aaabbbbbbebbbbbb",
      "aafbcbbbbbbbbbbb",
      "aaabcbbbbbbebbbb",
      "aaddcbbbbbbbbbbb",
      "aaabcbbbbbbbbbbb"
    ],
    [
      "    cg        h ",
      "  ddci     jj   ",
      "    ck  l m     ",
      "    c     n o   ",
      "    pl     q    ",
      "   rp   sl      ",
      "    p      o s t",
      "    uwu     x   ",
      "    uyu o A B   ",
      "    p        o t",
      "   Cp     DE    ",
      "    p l m  FD   ",
      "    c  I   E    ",
      "    ck JE       ",
      "  ddciK    jj   ",
      "    cL        M "
    ],
    [
      "    c           ",
      "  ddc           ",
      "   NcO          ",
      "    c           ",
      "    p           ",
      "   rp           ",
      "    p           ",
      "     P          ",
      "     Q          ",
      "    p           ",
      "   Cp           ",
      "    p           ",
      "    c           ",
      "   NcO          ",
      "  ddc           ",
      "    c           "
    ],
    [
      "    c           ",
      "  ddc           ",
      "   RcO          ",
      "    c           ",
      "    p           ",
      "   rp           ",
      "    p           ",
      "    p           ",
      "    p           ",
      "    p           ",
      "   Cp           ",
      "    p           ",
      "    c           ",
      "   RcO          ",
      "  ddc           ",
      "    c           "
    ],
    [
      "    c           ",
      "  ddc           ",
      "    cS          ",
      "    c           ",
      "    p           ",
      "   rp           ",
      "    p           ",
      "    p           ",
      "    p           ",
      "    p           ",
      "   Cp           ",
      "    p           ",
      "    c           ",
      "    cS          ",
      "  ddc           ",
      "    c           "
    ],
    [
      "    c           ",
      "  ddc           ",
      "    c           ",
      "    c           ",
      "    p           ",
      "   rp           ",
      "    p           ",
      "    p           ",
      "    p           ",
      "    p           ",
      "   Cp           ",
      "    p           ",
      "    c           ",
      "    c           ",
      "  ddc           ",
      "    c           "
    ]
  ]
}