{
  "name": "multi_taigaresidence_1_floor7",
  "refpalette": "deceasedcraft:multi_taigaresidence_1/multi_taigaresidence_1_floor7_palette",
  "xsize": 16,
  "zsize": 16,
  "slices": [
    [
      "   abccccccdeeee",
      "  ffgggggggdehii",
      "   ajkkkkkgdej  ",
      "   ajggggggdej  ",
      "   aj@@@@@gdej  ",
      "   aj@@@@@gdej  ",
      "   aj@@@@@gdej  ",
      "   aj@@@@@gdej  ",
      "   aj@@@@@gdej  ",
      "   aj@@@@@gdej  ",
      "   aj@@@@@gdej  ",
      "   aj@@@@@gdej  ",
      "   ajggggggdej  ",
      "   ajkkkkkgdej  ",
      "  ffgggggggdelmm",
      "   abccccccdeeee"
    ],
    [
      "    n           ",
      "  ffnnnnnno  ppp",
      "     qqqqqn  p  ",
      "          n  p  ",
      "          n  p  ",
      "          n  p  ",
      "          n  p  ",
      "          n  p  ",
      "          n  p  ",
      "          n  p  ",
      "          n  p  ",
      "          n  p  ",
      "          n  p  ",
      "     rrrrrn  p  ",
      "  ffnnnnnno  ppp",
      "    n           "
    ],
    [
      "    n           ",
      "  ffnnnnnno     ",
      "          n     ",
      "          n     ",
      "          n     ",
      "          n     ",
      "          n     ",
      "          n     ",
      "          n     ",
      "          n     ",
      "          n     ",
      "          n     ",
      "          n     ",
      "          n     ",
      "  ffnnnnnno     ",
      "    n           "
    ],
    [
      "                ",
      "  ff            ",
      "                ",
      "                ",
      "                ",
      "                ",
      "                ",
      "                ",
      "                ",
      "                ",
      "                ",
      "                ",
      "                ",
      "                ",
      "  ff            ",
      "                "
    ],
    [
      "                ",
      "  ff            ",
      "                ",
      "                ",
      "                ",
      "                ",
      "                ",
      "                ",
      "                ",
      "                ",
      "                ",
      "                ",
      "                ",
      "                ",
      "  ff            ",
      "                "
    ],
    [
      "                ",
      "  ff            ",
      "                ",
      "                ",
      "                ",
      "                ",
      "                ",
      "                ",
      "                ",
      "                ",
      "                ",
      "                ",
      "                ",
      "                ",
      "  ff            ",
      "                "
    ]
  ]
}