{
  "name": "multi_taigaresidence_1_floor2",
  "refpalette": "deceasedcraft:multi_taigaresidence_1/multi_taigaresidence_1_floor2_palette",
  "xsize": 16,
  "zsize": 16,
  "slices": [
    [
      "   abccccccdeeee",
      "  ffbccccccdeghh",
      "   abccccccdei@@",
      "   abccccccdei@@",
      "   aiccccccdei@@",
      "   aiccccccdei@@",
      "   aiccccccdei@@",
      "   aiccccccdei@@",
      "   aiccccccdei@@",
      "   aiccccccdei@@",
      "   aiccccccdei@@",
      "   aiccccccdei@@",
      "   abccccccdei@@",
      "   abccccccdei@@",
      "  ffbccccccdejkk",
      "   abccccccdeeee"
    ],
    [
      "    blmn        ",
      "  ffbbbbbbb  ooo",
      "    b    p   o  ",
      "    b        o  ",
      "             o  ",
      "      qr     o  ",
      "         s   o  ",
      "      tt u   o  ",
      "      tt u   o  ",
      "         w   o  ",
      "      xy     o  ",
      "             o  ",
      "    b        o  ",
      "    bAAAAA   o  ",
      "  ffbbbbbbb  ooo",
      "    bBCbD       "
    ],
    [
      "    b  E  F     ",
      "  ffbbbbbbb     ",
      "    bF  p       ",
      "    b           ",
      "                ",
      "                ",
      "                ",
      "                ",
      "                ",
      "                ",
      "                ",
      "                ",
      "    b           ",
      "    bAAAAAF     ",
      "  ffbbbbbbb     ",
      "    b  b  F     "
    ],
    [
      "    b           ",
      "  ffbbbbbbb     ",
      "    bIIp        ",
      "    bII         ",
      "                ",
      "                ",
      "                ",
      "                ",
      "                ",
      "                ",
      "                ",
      "                ",
      "    b           ",
      "    b           ",
      "  ffbbbbbbb     ",
      "    b  b        "
    ],
    [
      "    b           ",
      "  ffbbbbbbb     ",
      "    b           ",
      "    bJJK        ",
      "                ",
      "                ",
      "                ",
      "                ",
      "                ",
      "                ",
      "                ",
      "                ",
      "    b           ",
      "    b           ",
      "  ffbbbbbbb     ",
      "    b  b        "
    ],
    [
      "    bLLLLLL     ",
      "  ffbbbbbbb     ",
      "    b           ",
      "    b   K       ",
      "                ",
      "                ",
      "                ",
      "                ",
      "                ",
      "                ",
      "        M       ",
      "                ",
      "    b           ",
      "    b           ",
      "  ffbbbbbbb     ",
      "    bNNbLLL     "
    ]
  ]
}