{
  "name": "multi_taigaresidence_1_floor1",
  "refpalette": "deceasedcraft:multi_taigaresidence_1/multi_taigaresidence_1_floor1_palette",
  "xsize": 16,
  "zsize": 16,
  "slices": [
    [
      "   abccccccccccc",
      "  ddbeeeeeeeeeee",
      "    b           ",
      "    b           ",
      "    f           ",
      "   gf           ",
      "    f           ",
      "    f           ",
      "    f           ",
      "    f           ",
      "   hf           ",
      "    f           ",
      "    b           ",
      "    b           ",
      "  ddbiiiiiiiiiii",
      "   abccccccccccc"
    ],
    [
      "    b           ",
      "  ddbjjjjjjjjjjj",
      "    b           ",
      "    b           ",
      "    f           ",
      "   gf           ",
      "    f           ",
      "    f           ",
      "    f           ",
      "    f           ",
      "   hf           ",
      "    f           ",
      "    b           ",
      "    b           ",
      "  ddbjjjjjjjjjjj",
      "    b           "
    ],
    [
      "    b           ",
      "  ddb           ",
      "    b           ",
      "    b           ",
      "    f           ",
      "   gf           ",
      "    f           ",
      "    f           ",
      "    f           ",
      "    f           ",
      "   hf          k",
      "    f           ",
      "    b           ",
      "    b           ",
      "  ddb           ",
      "    b           "
    ],
    [
      "    b           ",
      "  ddb           ",
      "    b           ",
      "    b           ",
      "    f           ",
      "   lf           ",
      "   mf           ",
      "   mf           ",
      "   mf           ",
      "   mf           ",
      "   nf          k",
      "    f           ",
      "    b           ",
      "    b           ",
      "  ddb           ",
      "    b           "
    ],
    [
      "    b           ",
      "  ddb           ",
      "    b           ",
      "    b           ",
      "    f           ",
      "    f           ",
      "    f          k",
      "    f           ",
      "    f           ",
      "    f           ",
      "    f          o",
      "    f           ",
      "    b           ",
      "    b           ",
      "  ddb           ",
      "    b           "
    ],
    [
      "    b  pp       ",
      "  ddb           ",
      "    b           ",
      "    b           ",
      "    q           ",
      "    q  pp       ",
      "    q          o",
      "    q           ",
      "    q           ",
      "    q           ",
      "    q  pp      o",
      "    q           ",
      "    b           ",
      "    b           ",
      "  ddb           ",
      "    b  pp       "
    ]
  ]
}