{
  "name": "multi_taigaresidence_1_floor3",
  "refpalette": "deceasedcraft:multi_taigaresidence_1/multi_taigaresidence_1_floor3_palette",
  "xsize": 16,
  "zsize": 16,
  "slices": [
    [
      "   abcccddefgggg",
      "  hhbbbbbbefgijj",
      "   ab     efgk  ",
      "   ab    lefgk  ",
      "   akeeeeeefgk  ",
      "   akeeeeeefgk  ",
      "   akeeeeeefgk  ",
      "   akeeeeeefgk  ",
      "   akeeeeeefgk  ",
      "   akeeeeeefgk  ",
      "   akeeeeeefgk  ",
      "   akeeeeeefgk  ",
      "   abeeeeeefgk  ",
      "   abeeeeeefgk  ",
      "  hhbbbbbbefgmnn",
      "   abcccddefgggg"
    ],
    [
      "    bopqrrb     ",
      "  hhbbbbbbb  sss",
      "    b    t   s  ",
      "    buuuuu   s  ",
      "      wxyw   s  ",
      "             s  ",
      "       AB    s  ",
      "             s  ",
      "             s  ",
      "       xy    s  ",
      "             s  ",
      "      wABw   s  ",
      "    b        s  ",
      "    bCCCCC   s  ",
      "  hhbbbbbbb  sss",
      "    bDEqFFb     "
    ],
    [
      "    b  qIIb     ",
      "  hhbbbbbbb     ",
      "    b   t       ",
      "    b           ",
      "                ",
      "                ",
      "                ",
      "                ",
      "                ",
      "                ",
      "                ",
      "                ",
      "    b           ",
      "    bCCCCCJ     ",
      "  hhbbbbbbb     ",
      "    b  qKKb     "
    ],
    [
      "    b  q  b     ",
      "  hhbbbbbbb     ",
      "    bLLt        ",
      "    bLL         ",
      "                ",
      "                ",
      "                ",
      "                ",
      "                ",
      "                ",
      "                ",
      "                ",
      "    b           ",
      "    b   M       ",
      "  hhbbbbbbb     ",
      "    b  q! b     "
    ],
    [
      "    b  q  b     ",
      "  hhbbbbbbb     ",
      "    b           ",
      "    buul        ",
      "                ",
      "                ",
      "                ",
      "                ",
      "                ",
      "                ",
      "                ",
      "                ",
      "    b           ",
      "    b           ",
      "  hhbbbbbbb     ",
      "    b  q  b     "
    ],
    [
      "    bNNNNNb     ",
      "  hhbbbbbbb     ",
      "    b           ",
      "    b   l       ",
      "                ",
      "                ",
      "                ",
      "                ",
      "                ",
      "                ",
      "                ",
      "                ",
      "    b           ",
      "    b           ",
      "  hhbbbbbbb     ",
      "    bNNNNNb     "
    ]
  ]
}