{
  "name": "multi_gallery_4_base2",
  "refpalette": "deceasedcraft:multi_gallery_4/multi_gallery_4_base2_palette",
  "xsize": 16,
  "zsize": 16,
  "slices": [
    [
      "vvvvvvvvvvvvvvvv",
      "aaaaaaaaaaaaaaaa",
      "aaaaaaaaaaaaaaaa",
      "aaaaaaaaaaaaaaaa",
      "aaaaaaaaaaaaaaaa",
      "aaaaaaaaaaaaaaaa",
      "aaaaaaaaaaaaaaaa",
      "aaaaaaaaaaaaaaaa",
      "aaaaaaaaaaaaaaaa",
      "aaaaaaaaaaaaaaaa",
      "aaaaaaaaaaaaaaaa",
      "aaaaaaaaaaaaaaaa",
      "aaaaaaaaaaaaaaaa",
      "aaaaaaaaaaaaaaaa",
      "aaaaaaaaaaaaaaaa",
      "aaaaaaaaaaaaaaaa"
    ],
    [
      "vvvvvvvvvvvvvvvv",
      "aaaaaaaaaaaaaaaa",
      "aaaaaaaaaaaaaaaa",
      "aaaaaaaaaaaaaaaa",
      "aaaaaaaaaaaaaaaa",
      "aaaaaaaaaaaaaaaa",
      "aaaaaaaaaaaaaaaa",
      "aaaaaaaaaaaaaaaa",
      "aaaaaaaaaaaaaaaa",
      "aaaaaaaaaaaaaaaa",
      "aaaaaaaaaaaaaaaa",
      "aaaaaaaaaaaaaaaa",
      "aaaaaaaaaaaaaaaa",
      "aaaaaaaaaaaaaaaa",
      "aaaaaaaaaaaaaaaa",
      "aaaaaaaaaaaaaaaa"
    ],
    [
      "vvvvvvvvvvvvvvvv",
      "bbbbbbbbbbbbbbbb",
      "cccccccccccccccc",
      "cccccccccccccccc",
      "cccccccccccccccc",
      "cccccccccccccccc",
      "cccccccccccccccc",
      "cccccccccccccccc",
      "cccccccccccccccc",
      "cccccddddddccccc",
      "cccccdeeeedccccc",
      "cccccdeeeedccccc",
      "cccccdeeeedccccc",
      "cccccdeeeedccccc",
      "cccccddddddccccc",
      "cccccccccccccccc"
    ],
    [
      "vvvvvvvvvvvvvvvv",
      "ffffffffffffffff",
      "       gh       ",
      "                ",
      "                ",
      "                ",
      "                ",
      "                ",
      "                ",
      " ij             ",
      "kllm  nnnn      ",
      "      nnnn      ",
      "      nnnn   ij ",
      "      nnnn  kllm",
      "                ",
      "                "
    ],
    [
      "vvvvvvvvvvvvvvvv",
      "fopffffffffffqqf",
      "                ",
      "                ",
      "                ",
      "                ",
      "                ",
      "                ",
      "                ",
      "                ",
      "kllm  r  r      ",
      "       st       ",
      "       tt       ",
      "      r  r  kllm",
      "                ",
      "                "
    ],
    [
      "vvvvvvvvvvvvvvvv",
      "fopffffffffffppf",
      "    u           ",
      "                ",
      "                ",
      "                ",
      "                ",
      "                ",
      "                ",
      "                ",
      "kllm            ",
      " wx             ",
      "       t        ",
      "            kllm",
      "             wx ",
      "                "
    ]
  ]
}