{
  "name": "multi_gallery_4_ground",
  "refpalette": "deceasedcraft:multi_gallery_4/multi_gallery_4_ground_palette",
  "xsize": 16,
  "zsize": 16,
  "slices": [
    [
      "aaaaaaaaaaaaaaaa",
      "babababa!abababa",
      "babababababababa",
      "aacababababababa",
      "aaaaaacababababa",
      "aaaaaaaaaacababa",
      "aaaaaaaaaaaaaaca",
      "daaaaaaaaaaaaaaa",
      "dddddaaaaaaaaaaa",
      "eeeedddddaaaaaaa",
      "efgeeeeedddddaaa",
      "eeeeeeeeeeeedddd",
      "ddddeeeeeeeeeeee",
      "hiidddddeeeeefge",
      "iihihhhdddddeeee",
      "iiihihhhhhhddddd"
    ],
    [
      "                ",
      "  j     j     j ",
      "                ",
      "                ",
      "                ",
      "                ",
      "                ",
      "                ",
      "                ",
      "  k             ",
      " lm k           ",
      "       k        ",
      "         k k   k",
      "             lm ",
      "                ",
      "                "
    ],
    [
      "                ",
      "  n     n     n ",
      "                ",
      "                ",
      "                ",
      "                ",
      "                ",
      "                ",
      "                ",
      " lm             ",
      " lm             ",
      " lm             ",
      "             lm ",
      "             lm ",
      "             lm ",
      "                "
    ],
    [
      "  o     o     o ",
      "  oo    o     oo",
      "                ",
      "                ",
      "                ",
      "                ",
      "                ",
      "                ",
      "  p             ",
      " lm             ",
      "                ",
      " lm           p ",
      " p           lm ",
      "                ",
      "             lm ",
      "             p  "
    ],
    [
      "  o     o     o ",
      " oo    ooo   oo ",
      "  o     o     o ",
      "                ",
      "                ",
      "                ",
      "                ",
      "  p             ",
      "  p             ",
      "                ",
      "              p ",
      "              p ",
      " p              ",
      " p              ",
      "                ",
      "             p  "
    ],
    [
      "                ",
      "  o    oo     o ",
      "        o       ",
      "                ",
      "                ",
      "                ",
      "  q             ",
      "  p             ",
      "                ",
      "              q ",
      "              p ",
      "                ",
      "                ",
      " p              ",
      " r              ",
      "                "
    ]
  ]
}