{
  "name": "multi_gallery_4_floor1",
  "refpalette": "deceasedcraft:multi_gallery_4/multi_gallery_4_floor1_palette",
  "xsize": 16,
  "zsize": 16,
  "slices": [
    [
      "                ",
      "        a       ",
      "                ",
      "                ",
      "bcc             ",
      "bbbbbcc         ",
      "dddbbbbbbcc     ",
      "dddddddbbbbbbcc ",
      "dddddddddddbbbbb",
      "dddddddddddddddb",
      "dddddddddddddddd",
      "dddddddddddddddd",
      "dddddddddddddddd",
      "dddddddddddddddd",
      "bddddddddddddddd",
      "ebbbbddddddddddd"
    ],
    [
      "                ",
      "                ",
      "                ",
      "                ",
      "                ",
      "fff             ",
      "gh ffff         ",
      "       ffff     ",
      "        gh ffff ",
      "    i          f",
      "  jk            ",
      "                ",
      "                ",
      "                ",
      "l  m            ",
      "ellll  m        "
    ],
    [
      "                ",
      "                ",
      "                ",
      "                ",
      "                ",
      "fff             ",
      "   ffff         ",
      "       ffff     ",
      "           ffff ",
      "               f",
      "                ",
      "                ",
      "                ",
      "                ",
      "l  n            ",
      "ellll  o        "
    ],
    [
      "                ",
      "                ",
      "                ",
      "                ",
      "                ",
      "fff             ",
      "   ffff         ",
      "       ffff     ",
      "           ffff ",
      "               f",
      "                ",
      "                ",
      "                ",
      "                ",
      "l               ",
      "ellll           "
    ],
    [
      "                ",
      "                ",
      "                ",
      "                ",
      "                ",
      "fff             ",
      "   ffff         ",
      "       ffff     ",
      "           ffff ",
      "               f",
      "                ",
      "                ",
      "                ",
      "                ",
      "f               ",
      " ffff           "
    ],
    [
      "                ",
      "                ",
      "                ",
      "                ",
      "ppp             ",
      "qqqpppp         ",
      "rrrqqqqpppp     ",
      "rrrrrrrqqqqpppp ",
      "rrrrrrrrrrrqqqqp",
      "rrrrrrrrrrrrrrrq",
      "rrrsrrrrrrrrrrrr",
      "rrrtrrrrrrrrrrrr",
      "rrrrrrrrrrrurrrr",
      "rrrrrrrrrrrurrrr",
      "qrrrrrrrrrrrrrrr",
      "pqqqqrrrrrrrrrrr"
    ]
  ]
}