{
  "name": "multi_gallery_4_base1",
  "refpalette": "deceasedcraft:multi_gallery_4/multi_gallery_4_base1_palette",
  "xsize": 16,
  "zsize": 16,
  "slices": [
    [
      "vvvvvvvvvvvvvvvv",
      "abcaaaaaaaaaacca",
      "    d           ",
      "                ",
      "                ",
      "                ",
      "                ",
      "                ",
      "                ",
      "                ",
      "effg            ",
      " hi             ",
      "                ",
      "            effg",
      "             ji ",
      "                "
    ],
    [
      "vvvvvvvvvvvvvvvv",
      "abcaaaaaaaaaakka",
      "    l           ",
      "                ",
      "                ",
      "                ",
      "                ",
      "                ",
      "                ",
      "                ",
      "effg            ",
      "                ",
      "                ",
      "            effg",
      "                ",
      "                "
    ],
    [
      "vvvvvvvvvvvvvvvv",
      "aaaaaaaaaaaaaaaa",
      "                ",
      "                ",
      "                ",
      "                ",
      "                ",
      "                ",
      "                ",
      "                ",
      "effg            ",
      "                ",
      "                ",
      "            effg",
      "                ",
      "                "
    ],
    [
      "vvvvvvvvvvvvvvvv",
      "aaaaaaaaaaaaaaaa",
      "                ",
      "                ",
      "                ",
      "                ",
      "                ",
      "                ",
      "                ",
      "                ",
      "effg            ",
      "                ",
      "                ",
      "            effg",
      "                ",
      "                "
    ],
    [
      "vvvvvvvvvvvvvvvv",
      "aaaaaaaaaaaaaaaa",
      "mmmmnnnnnnnnmmmm",
      "nnnnnnnnnnnnnnnn",
      "nnnnnnnnnnnnnnnn",
      "nnnnnnnnnnnnnnnn",
      "nnnnnnnnnnnnnnnn",
      "nnnnnnnnnnnnnnnn",
      "nnnnnnnnnnnnnnnn",
      "nnnnnnnnnnnnnnnn",
      "nffnnnmmmmnnnnnn",
      "nnnnnnmmmmnnnnnn",
      "nnnnnnmmmmnnnnnn",
      "nnnnnnmmmmnnnffn",
      "nnnnnnnnnnnnnnnn",
      "nnnnnnnnnnnnnnnn"
    ],
    [
      "vvvvvvvvvvvvvvvv",
      "aaaaaaaaaaaaaaaa",
      "oooooooooooooooo",
      "oooooooooooooooo",
      "oooooooooooooooo",
      "oooooooooooooooo",
      "oooooooooooooooo",
      "oooooooooooooooo",
      "oooooooooooooooo",
      "ppppoooooooooooo",
      "pqqpppppoooooooo",
      "ppppppppppppoooo",
      "oooopppppppppppp",
      "oooooooopppppqqp",
      "oooooooooooopppp",
      "oooooooooooooooo"
    ]
  ]
}