{
  "name": "multi_planecrash1_8_ground",
  "refpalette": "deceasedcraft:multi_planecrash1_8/multi_planecrash1_8_ground_palette",
  "xsize": 16,
  "zsize": 16,
  "slices": [
    [
      "aaaaaaaaaaaaaaab",
      "aaaaaaaaaaaaaabb",
      "aacaaaaaaaaaabbb",
      "aaaaaaaaaaaabbbb",
      "aaaaaaaaaaabbbbb",
      "aaaaaaaaaabbbbbb",
      "aaaaaaaaabbbbbbb",
      "aaaaaaaabbbbbbbb",
      "aaaaaaaabbbbbbbb",
      "aaaaaaaaabbbbbbb",
      "aaaaaaaaaabbbbbb",
      "aaaaaaaaabbbbbbb",
      "aaaaaaaabbbbbbbb",
      "aaaaaaabbbbbbbbb",
      "aaaaaabbbbbbbbbb",
      "aaaaabbbbbbbbbbb"
    ],
    [
      "bbbbbbbbbbbbbbbb",
      "bbdbbabbbbbbbbbb",
      "bbebbabbbbbbbbbb",
      "bbbbbbbbbbbbbbbb",
      "bbbbbbbbbbbbbbbb",
      "bbbbbbbbbbbbbbbb",
      "bbbbbbbbbbbbbbbb",
      "bbbbbbbbbbbbbbbb",
      "bbbbbbbbbbbbbbbb",
      "bbbbbbbbbbbbbbbb",
      "bbabbbbbbbbbbbbb",
      "bbbbbbbbbbbbbbbb",
      "bbbbbbbbbbbbbbbb",
      "bbbbbbbbbbbbbbbb",
      "bbbbbbbbbbbbbbbb",
      "bbbbbbbbbbbbbbbb"
    ],
    [
      "bbbbbbbbbbbbbbbb",
      "bbbbbabbbbbbbbbb",
      "bbbbbabbbbbbbbbb",
      "bbbbbbbbbbbbbbbb",
      "bbbbbbbbbbbbbbbb",
      "bbbbbbbbbbbbbbbb",
      "bbbbbbbbbbbbbbbb",
      "bbbbbbbbbbbbbbbb",
      "bbbbbbbbbbbbbbbb",
      "bbbbbbbbbbbbbbbb",
      "bbabbbbbbbbbbbbb",
      "bbbbbbbbbbbbbbbb",
      "bbbbbbbbbbbbbbbb",
      "bbbbbbbbbbbbbbbb",
      "bbbbbbbbbbbbbbbb",
      "bbbbbbbbbbbbbbbb"
    ],
    [
      "bbbbbbbbbbbbbbbb",
      "bbbbbabbbbbbbbbb",
      "bbbbbabbbbbbbbbb",
      "bbbbbbbbbbbbbbbb",
      "bbbbbbbbbbbbbbbb",
      "bbbbbbbbbbbbbbbb",
      "bbbbbbbbbbbbbbbb",
      "bbbbbbbbbbbbbbbb",
      "bbbbbbbbbbbbbbbb",
      "bbbbbbbbbbbbbbbb",
      "bbabbbbbbbbbbbbb",
      "bbbbbbbbbbbbbbbb",
      "bbbbbbbbbbbbbbbb",
      "bbbbbbbbbbbbbbbb",
      "bbbbbbbbbbbbbbbb",
      "bbbbbbbbbbbbbbbb"
    ],
    [
      "bbbbbbbbbbbbbbbb",
      "bbbbbabbbbbbbbbb",
      "bbbbbabbbbbbbbbb",
      "bbbbbbbbbbbbbbbb",
      "bbbbbbbbbbbbbbbb",
      "bbbbbbbbbbbbbbbb",
      "bbbbbbbbbbbbbbbb",
      "bbbbbbbbbbbbbbbb",
      "bbbbbbbbbbbbbbbb",
      "bbbbbbbbbbbbbbbb",
      "bbabbbbbbbbbbbbb",
      "bbbbbbbbbbbbbbbb",
      "bbbbbbbbbbbbbbbb",
      "bbbbbbbbbbbbbbbb",
      "bbbbbbbbbbbbbbbb",
      "bbbbbbbbbbbbbbbb"
    ],
    [
      "bbbbbbbbbbbbbbbb",
      "bbbbbabbbbbbbbbb",
      "bbbbbabbbbbabbbb",
      "bbbbbbbbbbabbbbb",
      "bbbbbbbbbbbbbbbb",
      "bbbbbbbbbbbbbbbb",
      "bbbbbbbbabbbbbbb",
      "bbbabbaaabbbbbbb",
      "bbbabbabbbbbbbbb",
      "bbbabbbbbbbbbbbb",
      "bbabbabbbbbbbbbb",
      "bbababbbbbbbbbbb",
      "bbabbbbbbbbbbbbb",
      "bbbbbbbbbbbbbbbb",
      "bbbbbbbbbbbbbbbb",
      "bbbbbbbbbbbbbbbb"
    ]
  ]
}