{
  "name": "building_residentiala_ground_90",
  "refpalette": "deceasedcraft:building_residentiala/building_residentiala_ground_palette_90",
  "xsize": 16,
  "zsize": 16,
  "slices": [
    [
      "abbbbbbbbbbbbbba",
      "abbbbbbbbbbbbbba",
      "abcccccccbbbbbba",
      "bbcdddddeeeeebba",
      "abcdddddggggebba",
      "abcdddddggggebba",
      "abcdddddffffebba",
      "abcdddddffffebba",
      "abcdddddffffebbb",
      "abcdddddffffebba",
      "abcdddddffffebbb",
      "bbcdddddffffebbb",
      "bbcdddddeeeeebba",
      "bbcccccccbbbbbba",
      "abbaabbbbbbbbbba",
      "aaaaaaaaaaaaaaaa"
    ],
    [
      " hhhhhhhhhhhhhh ",
      "                ",
      "  jkkjkkjhhhhh  ",
      "  j  swAeeeeeh  ",
      "  k   u!CI Peh  ",
      "  k   usCFJJeh  ",
      "  k   u    Leh  ",
      "  jn ruy   Oeh  ",
      "  jm qu    Neh  ",
      "  k      E Meh  ",
      "  k  p  BD Leh  ",
      "  k  p  BD Keh  ",
      "  j  ptxeeeeeh  ",
      "  jlojkkjhhhhh  ",
      "  i             ",
      "                "
    ],
    [
      "                ",
      "                ",
      "  jkkjkkj       ",
      "  j    Wee1ee   ",
      "  k   uVC   e   ",
      "  k   u CZJJe   ",
      "  k   uy    0   ",
      "  jT  u    50   ",
      "  jS  u    40   ",
      "  k      Y  0   ",
      "  k  p     3e   ",
      "  k  p   X 2e   ",
      "  jR p  ee0ee   ",
      "  jQUjkkj       ",
      "                ",
      "                "
    ],
    [
      "                ",
      "                ",
      "  j88j88j    9  ",
      "  j     ee1ee9  ",
      "  6   u C   e9  ",
      "  6   uyCJJJe9  ",
      "  6   u     e9  ",
      "  j   u     e9  ",
      "  j   u     e9  ",
      "  6         e9  ",
      "  6  p      e9  ",
      "  6  p      e9  ",
      "  j  p  ee0ee9  ",
      "  j77j77j    9  ",
      "                ",
      "                "
    ],
    [
      "                ",
      "                ",
      "  jjjjjjj  9%^  ",
      "  jdddddeeee%^  ",
      "  jddddyC$$$%^  ",
      "  jdddd C###%^  ",
      "  jdddd    9%^  ",
      "  jdddd    9%^  ",
      "  jdddd    9%^  ",
      "  jdddd    9%^  ",
      "  jdddd    9%^  ",
      "  jdddd    9%^  ",
      "  jdddd eeee%^  ",
      "  jjjjjjj  9%^  ",
      "                ",
      "                "
    ],
    [
      "                ",
      " &              ",
      " &jkkkkkj9%^    ",
      " &j-    je%^    ",
      " &j-   <C>%^    ",
      " &j+|: <CJ%^    ",
      " &j)}; < 9%^    ",
      " &j {  < 9%^    ",
      " &j    < 9%^    ",
      " &j((((< 9%^    ",
      " &j(]](< 9%^    ",
      " &j([[(< 9%^    ",
      " &j*77'<ee%^    ",
      " &jkkkkkj9%^    ",
      " &              ",
      "                "
    ]
  ]
}