{
  "name": "building_residentiala_ground",
  "refpalette": "deceasedcraft:building_residentiala/building_residentiala_ground_palette",
  "xsize": 16,
  "zsize": 16,
  "slices": [
    [
      "aabbbaaaaaaabaaa",
      "abbbbbbbbbbbbbbb",
      "abccccccccccccbb",
      "aacddddddddddcbb",
      "aacddddddddddcbb",
      "abcddddddddddcbb",
      "abcddddddddddcbb",
      "abcddddddddddcbb",
      "abceffffffggecbb",
      "abbeffffffggebbb",
      "abbeffffffggebbb",
      "abbeffffffggebbb",
      "abbeeeeeeeeeebbb",
      "abbbbbbbbbbbbbbb",
      "abbbbbbbbbbbbbbb",
      "aaaabbabaaaaaaaa"
    ],
    [
      "                ",
      "               h",
      " ijjkkkjjkkkjj h",
      "  l    mn    k h",
      "  o          k h",
      "  jppp qr   sj h",
      "  kt   uuuuuwk h",
      "  kx    y s!Ak h",
      "  jeBB    CCej h",
      "  heDDE   FIeh h",
      "  he      J eh h",
      "  heKLMNOLJPeh h",
      "  heeeeeeeeeeh h",
      "  hhhhhhhhhhhh h",
      "               h",
      "                "
    ],
    [
      "                ",
      "                ",
      "  jjkkkjjkkkjj  ",
      "  QR   ST    k  ",
      "  U          k  ",
      "  jppp       j  ",
      "  k    uuuuu k  ",
      "  k      y VWk  ",
      "  je      CCej  ",
      "   eX Y   Z e   ",
      "   0      J 1   ",
      "   e23 45 J e   ",
      "   eee0000eee   ",
      "                ",
      "                ",
      "                "
    ],
    [
      "                ",
      "                ",
      "  jj666jj666jj  ",
      "  7          8  ",
      "  7          8  ",
      "  jppp       j  ",
      "  7    uuuuu 8  ",
      "  7       y  8  ",
      "  je      CCej  ",
      "   e      J e   ",
      "   0      J 1   ",
      "   e      J e   ",
      "   eeeeeeeeee   ",
      "  999999999999  ",
      "                ",
      "                "
    ],
    [
      "                ",
      "                ",
      "  jjjjjjjjjjjj  ",
      "  jddddddddddj  ",
      "  jddddddddddj  ",
      "  jddddddddddj  ",
      "  jddddddddddj  ",
      "  j        ydj  ",
      "  je      CCej  ",
      "   e      #$e   ",
      "   e      #$e   ",
      "  9e999999#$e9  ",
      "  %%%%%%%%%%%%  ",
      "  ^^^^^^^^^^^^  ",
      "                ",
      "                "
    ],
    [
      "                ",
      " &&&&&&&&&&&&&& ",
      "  jjjjjjjjjjjj  ",
      "  k*(((  )+--k  ",
      "  k7[]( {}|  k  ",
      "  k7[](  ;:  k  ",
      "  k'(((      k  ",
      "  k<<<<<<<<< k  ",
      "  je      CCjj  ",
      "  9e999999J>e9  ",
      "  %%%%%%%%%%%%  ",
      "  ^^^^^^^^^^^^  ",
      "                ",
      "                ",
      "                ",
      "                "
    ]
  ]
}