{
  "name": "building_residentiala_floor1_90",
  "refpalette": "deceasedcraft:building_residentiala/building_residentiala_floor1_palette_90",
  "xsize": 16,
  "zsize": 16,
  "slices": [
    [
      "                ",
      " abc            ",
      " abdffffdm      ",
      " abe    dm      ",
      " abe    lm      ",
      " abe    lm      ",
      " abehj  lm      ",
      " abe    lm      ",
      " abe    lm      ",
      " abe    lm      ",
      " abe    lm      ",
      " abe    lm      ",
      " abegik dm      ",
      " abdffffdm      ",
      " abc            ",
      "                "
    ],
    [
      "                ",
      "   abc          ",
      "   abdffd       ",
      "   abe  d       ",
      "   abe  o       ",
      "   aben o       ",
      "   abe  o       ",
      "   abe  o       ",
      "   abe  o       ",
      "   abe  o       ",
      "   aben o       ",
      "   abe  o       ",
      "   abe  d       ",
      "   abdffd       ",
      "   abc          ",
      "                "
    ],
    [
      "                ",
      "     abc        ",
      "     abdd       ",
      "     abed       ",
      "     abed       ",
      "     abed       ",
      "     abed       ",
      "     abed       ",
      "     abed       ",
      "     abed       ",
      "     abed       ",
      "     abed       ",
      "     abed       ",
      "     abdd       ",
      "     abc        ",
      "                "
    ],
    [
      "                ",
      "       abc      ",
      "       abc      ",
      "       abc      ",
      "       abc      ",
      "       abc      ",
      "       abc      ",
      "       abc      ",
      "       abc      ",
      "       abc      ",
      "       abc      ",
      "       abc      ",
      "       abc      ",
      "       abc      ",
      "       abc      ",
      "                "
    ],
    [
      "                ",
      "         a      ",
      "         a      ",
      "         a      ",
      "         a      ",
      "         a      ",
      "         a      ",
      "         a      ",
      "         a      ",
      "         a      ",
      "         a      ",
      "         a      ",
      "         a      ",
      "         a      ",
      "         a      ",
      "                "
    ],
    [
      "                ",
      "                ",
      "                ",
      "                ",
      "                ",
      "                ",
      "                ",
      "         ~      ",
      "                ",
      "                ",
      "                ",
      "                ",
      "                ",
      "                ",
      "                ",
      "                "
    ]
  ]
}