{
  "name": "building_residentiala_floor1_270",
  "refpalette": "deceasedcraft:building_residentiala/building_residentiala_floor1_palette_270",
  "xsize": 16,
  "zsize": 16,
  "slices": [
    [
      "                ",
      "            cba ",
      "      mdffffdba ",
      "      md kigeba ",
      "      ml    eba ",
      "      ml    eba ",
      "      ml    eba ",
      "      ml    eba ",
      "      ml    eba ",
      "      ml  jheba ",
      "      ml    eba ",
      "      ml    eba ",
      "      md    eba ",
      "      mdffffdba ",
      "            cba ",
      "                "
    ],
    [
      "                ",
      "          cba   ",
      "       dffdba   ",
      "       d  eba   ",
      "       o  eba   ",
      "       o neba   ",
      "       o  eba   ",
      "       o  eba   ",
      "       o  eba   ",
      "       o  eba   ",
      "       o neba   ",
      "       o  eba   ",
      "       d  eba   ",
      "       dffdba   ",
      "          cba   ",
      "                "
    ],
    [
      "                ",
      "        cba     ",
      "       ddba     ",
      "       deba     ",
      "       deba     ",
      "       deba     ",
      "       deba     ",
      "       deba     ",
      "       deba     ",
      "       deba     ",
      "       deba     ",
      "       deba     ",
      "       deba     ",
      "       ddba     ",
      "        cba     ",
      "                "
    ],
    [
      "                ",
      "      cba       ",
      "      cba       ",
      "      cba       ",
      "      cba       ",
      "      cba       ",
      "      cba       ",
      "      cba       ",
      "      cba       ",
      "      cba       ",
      "      cba       ",
      "      cba       ",
      "      cba       ",
      "      cba       ",
      "      cba       ",
      "                "
    ],
    [
      "                ",
      "      a         ",
      "      a         ",
      "      a         ",
      "      a         ",
      "      a         ",
      "      a         ",
      "      a         ",
      "      a         ",
      "      a         ",
      "      a         ",
      "      a         ",
      "      a         ",
      "      a         ",
      "      a         ",
      "                "
    ],
    [
      "                ",
      "                ",
      "                ",
      "                ",
      "                ",
      "                ",
      "                ",
      "                ",
      "      ~         ",
      "                ",
      "                ",
      "                ",
      "                ",
      "                ",
      "                ",
      "                "
    ]
  ]
}