{
  "name": "building_residentiala_ground_270",
  "refpalette": "deceasedcraft:building_residentiala/building_residentiala_ground_palette_270",
  "xsize": 16,
  "zsize": 16,
  "slices": [
    [
      "aaaaaaaaaaaaaaaa",
      "abbbbbbbbbbaabba",
      "abbbbbbcccccccbb",
      "abbeeeeedddddcbb",
      "bbbeffffdddddcbb",
      "bbbeffffdddddcba",
      "abbeffffdddddcba",
      "bbbeffffdddddcba",
      "abbeffffdddddcba",
      "abbeffffdddddcba",
      "abbeggggdddddcba",
      "abbeggggdddddcba",
      "abbeeeeedddddcbb",
      "abbbbbbcccccccba",
      "abbbbbbbbbbbbbba",
      "abbbbbbbbbbbbbba"
    ],
    [
      "                ",
      "             i  ",
      "  hhhhhjkkjolj  ",
      "  heeeeextp  j  ",
      "  heK DB  p  k  ",
      "  heL DB  p  k  ",
      "  heM E      k  ",
      "  heN    uq mj  ",
      "  heO   yur nj  ",
      "  heL    u   k  ",
      "  heJJFCsu   k  ",
      "  heP IC!u   k  ",
      "  heeeeeAws  j  ",
      "  hhhhhjkkjkkj  ",
      "                ",
      " hhhhhhhhhhhhhh "
    ],
    [
      "                ",
      "                ",
      "       jkkjUQj  ",
      "   ee0ee  p Rj  ",
      "   e2 X   p  k  ",
      "   e3     p  k  ",
      "   0  Y      k  ",
      "   04    u  Sj  ",
      "   05    u  Tj  ",
      "   0    yu   k  ",
      "   eJJZC u   k  ",
      "   e   CVu   k  ",
      "   ee1eeW    j  ",
      "       jkkjkkj  ",
      "                ",
      "                "
    ],
    [
      "                ",
      "                ",
      "  9    j77j77j  ",
      "  9ee0ee  p  j  ",
      "  9e      p  6  ",
      "  9e      p  6  ",
      "  9e         6  ",
      "  9e     u   j  ",
      "  9e     u   j  ",
      "  9e     u   6  ",
      "  9eJJJCyu   6  ",
      "  9e   C u   6  ",
      "  9ee1ee     j  ",
      "  9    j88j88j  ",
      "                ",
      "                "
    ],
    [
      "                ",
      "                ",
      "  ^%9  jjjjjjj  ",
      "  ^%eeee ddddj  ",
      "  ^%9    ddddj  ",
      "  ^%9    ddddj  ",
      "  ^%9    ddddj  ",
      "  ^%9    ddddj  ",
      "  ^%9    ddddj  ",
      "  ^%9    ddddj  ",
      "  ^%###C ddddj  ",
      "  ^%$$$Cyddddj  ",
      "  ^%eeeedddddj  ",
      "  ^%9  jjjjjjj  ",
      "                ",
      "                "
    ],
    [
      "                ",
      "              & ",
      "    ^%9jkkkkkj& ",
      "    ^%ee<'77*j& ",
      "    ^%9 <([[(j& ",
      "    ^%9 <(]](j& ",
      "    ^%9 <((((j& ",
      "    ^%9 <    j& ",
      "    ^%9 <  { j& ",
      "    ^%9 < ;})j& ",
      "    ^%JC< :|+j& ",
      "    ^%>C<   -j& ",
      "    ^%ej    -j& ",
      "    ^%9jkkkkkj& ",
      "              & ",
      "                "
    ]
  ]
}