{
  "name": "building_residentiala_floor1",
  "refpalette": "deceasedcraft:building_residentiala/building_residentiala_floor1_palette",
  "xsize": 16,
  "zsize": 16,
  "slices": [
    [
      "                ",
      " aaaaaaaaaaaaaa ",
      " bbbbbbbbbbbbbb ",
      " cdeeeeeeeeeedc ",
      "  fg     h   f  ",
      "  fi     j   f  ",
      "  fk         f  ",
      "  f          f  ",
      "  ddlllllllldd  ",
      "  mmmmmmmmmmmm  ",
      "                ",
      "                ",
      "                ",
      "                ",
      "                ",
      "                "
    ],
    [
      "                ",
      "                ",
      "                ",
      " aaaaaaaaaaaaaa ",
      " bbbbbbbbbbbbbb ",
      " cdeeeeeeeeeedc ",
      "  f  n    n  f  ",
      "  f          f  ",
      "  ddoooooooodd  ",
      "                ",
      "                ",
      "                ",
      "                ",
      "                ",
      "                ",
      "                "
    ],
    [
      "                ",
      "                ",
      "                ",
      "                ",
      "                ",
      " aaaaaaaaaaaaaa ",
      " bbbbbbbbbbbbbb ",
      " cdeeeeeeeeeedc ",
      "  dddddddddddd  ",
      "                ",
      "                ",
      "                ",
      "                ",
      "                ",
      "                ",
      "                "
    ],
    [
      "                ",
      "                ",
      "                ",
      "                ",
      "                ",
      "                ",
      "                ",
      " aaaaaaaaaaaaaa ",
      " bbbbbbbbbbbbbb ",
      " cccccccccccccc ",
      "                ",
      "                ",
      "                ",
      "                ",
      "                ",
      "                "
    ],
    [
      "                ",
      "                ",
      "                ",
      "                ",
      "                ",
      "                ",
      "                ",
      "                ",
      "                ",
      " aaaaaaaaaaaaaa ",
      "                ",
      "                ",
      "                ",
      "                ",
      "                ",
      "                "
    ],
    [
      "                ",
      "                ",
      "                ",
      "                ",
      "                ",
      "                ",
      "                ",
      "                ",
      "                ",
      "        ~       ",
      "                ",
      "                ",
      "                ",
      "                ",
      "                ",
      "                "
    ]
  ]
}