{
  "name": "building_residentiala_ground_180",
  "refpalette": "deceasedcraft:building_residentiala/building_residentiala_ground_palette_180",
  "xsize": 16,
  "zsize": 16,
  "slices": [
    [
      "aaaaaaaababbaaaa",
      "bbbbbbbbbbbbbbba",
      "bbbbbbbbbbbbbbba",
      "bbbeeeeeeeeeebba",
      "bbbeggffffffebba",
      "bbbeggffffffebba",
      "bbbeggffffffebba",
      "bbceggffffffecba",
      "bbcddddddddddcba",
      "bbcddddddddddcba",
      "bbcddddddddddcba",
      "bbcddddddddddcaa",
      "bbcddddddddddcaa",
      "bbccccccccccccba",
      "bbbbbbbbbbbbbbba",
      "aaabaaaaaaabbbaa"
    ],
    [
      "                ",
      "h               ",
      "h hhhhhhhhhhhh  ",
      "h heeeeeeeeeeh  ",
      "h hePJLONMLKeh  ",
      "h he J      eh  ",
      "h heIF   EDDeh  ",
      "h jeCC    BBej  ",
      "h kA!s y    xk  ",
      "h kwuuuuu   tk  ",
      "h js   rq pppj  ",
      "h k          o  ",
      "h k    nm    l  ",
      "h jjkkkjjkkkjji ",
      "h               ",
      "                "
    ],
    [
      "                ",
      "                ",
      "                ",
      "   eee0000eee   ",
      "   e J 54 32e   ",
      "   1 J      0   ",
      "   e Z   Y Xe   ",
      "  jeCC      ej  ",
      "  kWV y      k  ",
      "  k uuuuu    k  ",
      "  j       pppj  ",
      "  k          U  ",
      "  k    TS   RQ  ",
      "  jjkkkjjkkkjj  ",
      "                ",
      "                "
    ],
    [
      "                ",
      "                ",
      "  999999999999  ",
      "   eeeeeeeeee   ",
      "   e J      e   ",
      "   1 J      0   ",
      "   e J      e   ",
      "  jeCC      ej  ",
      "  8  y       7  ",
      "  8 uuuuu    7  ",
      "  j       pppj  ",
      "  8          7  ",
      "  8          7  ",
      "  jj666jj666jj  ",
      "                ",
      "                "
    ],
    [
      "                ",
      "                ",
      "  ^^^^^^^^^^^^  ",
      "  %%%%%%%%%%%%  ",
      "  9e$#999999e9  ",
      "   e$#      e   ",
      "   e$#      e   ",
      "  jeCC      ej  ",
      "  jdy        j  ",
      "  jddddddddddj  ",
      "  jddddddddddj  ",
      "  jddddddddddj  ",
      "  jddddddddddj  ",
      "  jjjjjjjjjjjj  ",
      "                ",
      "                "
    ],
    [
      "                ",
      "                ",
      "                ",
      "                ",
      "  ^^^^^^^^^^^^  ",
      "  %%%%%%%%%%%%  ",
      "  9e>J999999e9  ",
      "  jjCC      ej  ",
      "  k <<<<<<<<<k  ",
      "  k      ((('k  ",
      "  k  :;  (][7k  ",
      "  k  |}{ (][7k  ",
      "  k--+)  (((*k  ",
      "  jjjjjjjjjjjj  ",
      " &&&&&&&&&&&&&& ",
      "                "
    ]
  ]
}