{
  "name": "building_residentiala_floor1_180",
  "refpalette": "deceasedcraft:building_residentiala/building_residentiala_floor1_palette_180",
  "xsize": 16,
  "zsize": 16,
  "slices": [
    [
      "                ",
      "                ",
      "                ",
      "                ",
      "                ",
      "                ",
      "  mmmmmmmmmmmm  ",
      "  ddlllllllldd  ",
      "  f          f  ",
      "  f         kf  ",
      "  f   j     if  ",
      "  f   h     gf  ",
      " cdeeeeeeeeeedc ",
      " bbbbbbbbbbbbbb ",
      " aaaaaaaaaaaaaa ",
      "                "
    ],
    [
      "                ",
      "                ",
      "                ",
      "                ",
      "                ",
      "                ",
      "                ",
      "  ddoooooooodd  ",
      "  f          f  ",
      "  f  n    n  f  ",
      " cdeeeeeeeeeedc ",
      " bbbbbbbbbbbbbb ",
      " aaaaaaaaaaaaaa ",
      "                ",
      "                ",
      "                "
    ],
    [
      "                ",
      "                ",
      "                ",
      "                ",
      "                ",
      "                ",
      "                ",
      "  dddddddddddd  ",
      " cdeeeeeeeeeedc ",
      " bbbbbbbbbbbbbb ",
      " aaaaaaaaaaaaaa ",
      "                ",
      "                ",
      "                ",
      "                ",
      "                "
    ],
    [
      "                ",
      "                ",
      "                ",
      "                ",
      "                ",
      "                ",
      " cccccccccccccc ",
      " bbbbbbbbbbbbbb ",
      " aaaaaaaaaaaaaa ",
      "                ",
      "                ",
      "                ",
      "                ",
      "                ",
      "                ",
      "                "
    ],
    [
      "                ",
      "                ",
      "                ",
      "                ",
      "                ",
      "                ",
      " aaaaaaaaaaaaaa ",
      "                ",
      "                ",
      "                ",
      "                ",
      "                ",
      "                ",
      "                ",
      "                ",
      "                "
    ],
    [
      "                ",
      "                ",
      "                ",
      "                ",
      "                ",
      "                ",
      "       ~        ",
      "                ",
      "                ",
      "                ",
      "                ",
      "                ",
      "                ",
      "                ",
      "                ",
      "                "
    ]
  ]
}