{
  "name": "building_officebank_floor3_180",
  "refpalette": "deceasedcraft:building_officebank/building_officebank_floor3_palette_180",
  "xsize": 16,
  "zsize": 16,
  "slices": [
    [
      "                ",
      "      abaj  a   ",
      "   ajdddddddba  ",
      "  abdeeeei  dg  ",
      "   deeeeeee  d  ",
      "   deeeeeeee da ",
      "  fdeeeeeeeehdb ",
      "  adeeeeeeeeeda ",
      "  bdeeeeeeeeedg ",
      "  adeeeeeeeeed  ",
      "   deeeeeeeeed  ",
      "   fdeeeeeeedba ",
      "   abdddddddca  ",
      "    a  caba     ",
      "                ",
      "                "
    ],
    [
      "                ",
      "     Jaba  Ja   ",
      "   a lllllllba  ",
      "  abl       l   ",
      "  ul w  BBB  lp ",
      "   lnnx wn Bhla ",
      "   lIF    EBDlb ",
      "  al A    CB la ",
      "  bl  w      l  ",
      "  alAynx w   l  ",
      "  ul tn snrq lp ",
      "    lo   nm lba ",
      "   ablllllll a  ",
      "    ak  abak    ",
      "                ",
      "                "
    ],
    [
      "                ",
      "    abaj  aba   ",
      "     lllllllg   ",
      "  ajl       l a ",
      "  bl    RRR!hlb ",
      "  alV    U RDla ",
      "   lTS     R lg ",
      "   l       R l  ",
      "  fl         l  ",
      "  al QP      la ",
      "  bl O   NM  lb ",
      "  a l    LK lca ",
      "    flllllll    ",
      "    aba  caba   ",
      "                ",
      "                "
    ],
    [
      "                ",
      "    aba  Jaba   ",
      "    ulllllll    ",
      "  a l      WlJa ",
      "  bl    RRReDlb ",
      "  al       R la ",
      "  ul       R l  ",
      "   l       R l  ",
      "   l         lp ",
      "  al         la ",
      "  bl         lb ",
      "  akl       l a ",
      "     lllllllp   ",
      "    abak  aba   ",
      "                ",
      "                "
    ],
    [
      "                ",
      "    aj  abaj    ",
      "   ablllllll a  ",
      "    l     Wilba ",
      "  fl    RRRX lg ",
      "  al       R l  ",
      "  bl       R l  ",
      "  al       R la ",
      "   l         lb ",
      "   l         la ",
      "  fl         lg ",
      "  abl       l   ",
      "   a lllllllba  ",
      "     caba  ca   ",
      "                ",
      "                "
    ],
    [
      "                ",
      "    a  Jaba     ",
      "   ablllllllJa  ",
      "   ul   ZWi lba ",
      "   l    YYY  l  ",
      "  al       Y l  ",
      "  bl       Y lp ",
      "  al       Y la ",
      "  ul         lb ",
      "   l         la ",
      "   l         l  ",
      "  abl       lp  ",
      "   aklllllllba  ",
      "      abak  a   ",
      "                ",
      "                "
    ]
  ]
}