{
  "name": "building_officebank_ground_90",
  "refpalette": "deceasedcraft:building_officebank/building_officebank_ground_palette_90",
  "xsize": 16,
  "zsize": 16,
  "slices": [
    [
      "ccbaaaaaaaaaaaaa",
      "cccbaaaaaaaaaaaa",
      "bcccbbbbbbbbbbaa",
      "abcccdddddddbbba",
      "aabcdddddfhhdbba",
      "aabddddddfhhbdba",
      "aabddddddfhhbdba",
      "aabddddddfhhbdba",
      "aabddddddfffbdba",
      "aabdddddf  fbdba",
      "aabdddddf gfbdba",
      "aabdddddeff!bdba",
      "aabbddddedbbdbba",
      "aabbbdddddddbbba",
      "aaabbbbbbbbbbbaa",
      "aaaaaaaaaaaaaaaa"
    ],
    [
      "  i             ",
      "   i p     p    ",
      "i   ioiiiiioii  ",
      " i   lllllll ii ",
      "  i nquw fCEl i ",
      " jklm    y  Fljk",
      "  il     f  Fli ",
      "  il  t  fBDFli ",
      "  il fsssfffFli ",
      "  il  r f  fFli ",
      "  il    f gfFli ",
      " jkl     ff Fljk",
      "  i l    xA l i ",
      "  ii lllllll ii ",
      "   iipiiiiipii  ",
      "     o     o    "
    ],
    [
      "                ",
      "     p     p    ",
      "    IJI   IJI   ",
      "     lllllll    ",
      "  I  L   fPQl I ",
      " jJlK    O   lJk",
      "  Il     f   lI ",
      "   l     f   l  ",
      "   l   MNfff l  ",
      "   l    f  f l  ",
      "  Il    f gf lI ",
      " jJl     ff  lJk",
      "  I l     xAl I ",
      "     lllllll    ",
      "    IJI   IJI   ",
      "     o     o    "
    ],
    [
      "                ",
      "     p     p    ",
      "    IJIT VIJI   ",
      "    SlllllllS   ",
      "  ITU    fYZlVI ",
      " jJl     X   lJk",
      "  Il     f   lI ",
      "  Sl     f   lS ",
      "   l     fff l  ",
      "  Rl    f  f lR ",
      "  Il    fWgf lI ",
      " jJl     ffe0lJk",
      "  ITl      xlVI ",
      "    RlllllllR   ",
      "    IJIT VIJI   ",
      "     o     o    "
    ],
    [
      "                ",
      "                ",
      "    IJIJIJIJI   ",
      "   IJlllllllJI  ",
      "  IJl    f13lJI ",
      "  Jl     f   lJ ",
      "  Il     f   lI ",
      "  Jl     f   lJ ",
      "  Il     fff lI ",
      "  Jl    fW f lJ ",
      "  Il    fWgf0lI ",
      "  Jl     ff24lJ ",
      "  IJl       lJI ",
      "   IJlllllllJI  ",
      "    IJIJIJIJI   ",
      "                "
    ],
    [
      "                ",
      "                ",
      "    I5 JIJI5    ",
      "   IJlllllllJI  ",
      "   Jl    f88lJI ",
      "  5l     f777l5 ",
      "  Il     f777l  ",
      "  Jl     f777lJ ",
      "  Il    6fff9lI ",
      "  Jl    f!Wf0lJ ",
      "   l    f gf4lI ",
      "  5l     ff  l5 ",
      "  IJl       lJ  ",
      "   IJlllllllJI  ",
      "     5IJIJ 5I   ",
      "                "
    ]
  ]
}