{
  "name": "building_officebank_base2",
  "refpalette": "deceasedcraft:building_officebank/building_officebank_base2_palette",
  "xsize": 16,
  "zsize": 16,
  "slices": [
    [
      "vvvvvvvvvvvvvvvv",
      "vvvvvvvvvvvvvvvv",
      "vaaaaaaaaaaaaavv",
      "vaaaaaaaaaaaaavv",
      "vaaaaaaaaaaaaavv",
      "vaaaaaaaaaaaaavv",
      "vaaaaaaaaaaaaavv",
      "vaaaaaaaaaaaaavv",
      "vaaaaaaaaaaaaavv",
      "vaaaaaaaaaaaaavv",
      "vaaaaaaaaaaaaavv",
      "vaaaaaaaaaaaaavv",
      "vaaaaaaaaaaaaavv",
      "vaaaaaaaaaaaaavv",
      "vaaaaaaaaaaaaavv",
      "vvvvvvvvvvvvvvvv"
    ],
    [
      "vvvvvvvvvvvvvvvv",
      "vvvvvvvvvvvvvvvv",
      "vaaaaaaaaaaaaavv",
      "vabbabbbbbabbavv",
      "vabb abbba bbavv",
      "vaa bcbbbcb aavv",
      "vabad bbb eabavv",
      "vabbbbbbbbbbbavv",
      "vabbbbbbbbbbbavv",
      "vabbbbbbbbbbbavv",
      "vabbbbbbb eabavv",
      "vabbbbbbbfb aavv",
      "vabbbbbbba bbavv",
      "vabbbbbbbbabbavv",
      "vaaaaaaaaaaaaavv",
      "vvvvvvvvvvvvvvvv"
    ],
    [
      "vvvvvvvvvvvvvvvv",
      "vvvvvvvvvvvvvvvv",
      "vaaaaaaaaaaaaavv",
      "vaggagggggaggavv",
      "vagggggggggggavv",
      "vaagggggggggaavv",
      "vagggggggggggavv",
      "vagggggggggggavv",
      "vaaaaagggggggavv",
      "vahhaggggggggavv",
      "vahhaggagggggavv",
      "vahhhaaaggggaavv",
      "vahhhhhagggggavv",
      "vahhhhhaggaggavv",
      "vaaaaaaaaaaaaavv",
      "vvvvvvvvvvvvvvvv"
    ],
    [
      "vvvvvvvvvvvvvvvv",
      "vvvvvvvvvvvvvvvv",
      "vaaaaaaaaaaaaavv",
      "vaijaklllkamnavv",
      "vaopq     r oavv",
      "vaas       taavv",
      "va   u   u  wavv",
      "va          xavv",
      "vaayaaA     xavv",
      "va  a  A    xavv",
      "vB  aC a u  wavv",
      "va  Daaa   Eaavv",
      "vB     F  IJKavv",
      "va     a  amLavv",
      "vaaBaBaaaaaaaavv",
      "vvvvvvvvvvvvvvvv"
    ],
    [
      "vvvvvvvvvvvvvvvv",
      "vvvvvvvvvvvvvvvv",
      "vaaaaaaaaaaaaavv",
      "va!Ma     aN!avv",
      "vaM O     P Navv",
      "vaaQ       Raavv",
      "va           avv",
      "vaS          avv",
      "vaaTaaA      avv",
      "va  a  A     avv",
      "vU  aC a     avv",
      "va  Vaaa   Waavv",
      "vU     X  Y Zavv",
      "va     a0 aZZavv",
      "vaa1a1aaaaaaaavv",
      "vvvvvvvvvvvvvvvv"
    ],
    [
      "vvvvvvvvvvvvvvvv",
      "vvvvvvvvvvvvvvvv",
      "vaaaaaaaaaaaaavv",
      "va2 a 3 4 a Navv",
      "vaM O     P  avv",
      "vaaQ       Raavv",
      "va           avv",
      "va 5        6avv",
      "vaaaaaA      avv",
      "va  a  A    7avv",
      "vB8 a9 a     avv",
      "va   aaa   Waavv",
      "vB8    a# Y $avv",
      "va % % a  aZ avv",
      "vaaBaBaaaaaaaavv",
      "vvvvvvvvvvvvvvvv"
    ]
  ]
}