{
  "name": "building_officebank_ground",
  "refpalette": "deceasedcraft:building_officebank/building_officebank_ground_palette",
  "xsize": 16,
  "zsize": 16,
  "slices": [
    [
      "aaaaaaaaaaaaabcc",
      "aaaaaaaaaaaabccc",
      "aabbbbbbbbbbcccb",
      "abbbdddddddcccba",
      "abbdddddddddcbaa",
      "abdddddddddddbaa",
      "abdddddddddddbaa",
      "abdddddddddddbaa",
      "abdeeffddddddbaa",
      "abddf  fffffdbaa",
      "abdbfg fhhhhdbaa",
      "abdb!fffhhhhdbaa",
      "abbdbbbbbbbdbbaa",
      "abbbdddddddbbbaa",
      "aabbbbbbbbbbbaaa",
      "aaaaaaaaaaaaaaaa"
    ],
    [
      "             i  ",
      "    j     j i   ",
      "  iikiiiiiki   i",
      " ii lllllll   i ",
      " i l      mn i  ",
      "opl    f   qlop ",
      " il   rst  uli  ",
      " il    s   wli  ",
      " il  ffs    li  ",
      " ilxf  fffyfli  ",
      " ilAfg fB  Cli  ",
      "opl  fffD  Elop ",
      " i lFFFFFFFl i  ",
      " ii lllllll ii  ",
      "  iijiiiiijii   ",
      "    k     k     "
    ],
    [
      "                ",
      "    j     j     ",
      "   IJI   IJI    ",
      "    lllllll     ",
      " I l      K  I  ",
      "oJl        LlJp ",
      " Il         lI  ",
      "  l    M    l   ",
      "  l  ffN    l   ",
      "  l f  fffOfl   ",
      " Ilxfg f   PlI  ",
      "oJlA fff   QlJp ",
      " I l       l I  ",
      "    lllllll     ",
      "   IJI   IJI    ",
      "    k     k     "
    ],
    [
      "                ",
      "    j     j     ",
      "   IJIR SIJI    ",
      "   TlllllllT    ",
      " IRl       USI  ",
      "oJl         lJp ",
      " Il         lI  ",
      " Tl         lT  ",
      "  l  ff     l   ",
      " Vl fW fffXflV  ",
      " Il fg f   YlI  ",
      "oJlxefff   ZlJp ",
      " IRl0      lSI  ",
      "   VlllllllV    ",
      "   IJIR SIJI    ",
      "    k     k     "
    ],
    [
      "                ",
      "                ",
      "   IJIJIJIJI    ",
      "  IJlllllllJI   ",
      " IJl       lJI  ",
      " Jl         lJ  ",
      " Il         lI  ",
      " Jl         lJ  ",
      " Il  ff     lI  ",
      " Jl fWWffffflJ  ",
      " Il fg f   1lI  ",
      " Jl 2fff   3lJ  ",
      " IJl40     lJI  ",
      "  IJlllllllJI   ",
      "   IJIJIJIJI    ",
      "                "
    ],
    [
      "                ",
      "                ",
      "   I5 JIJI5     ",
      "  IJlllllllJI   ",
      "  Jl       lJI  ",
      " 5l         l5  ",
      " Il         l   ",
      " Jl         lJ  ",
      " Il  ff6    lI  ",
      " Jl f !ffffflJ  ",
      "  l fgWf7778lI  ",
      " 5l  fff7778l5  ",
      " IJl 409777lJ   ",
      "  IJlllllllJI   ",
      "    5IJIJ 5I    ",
      "                "
    ]
  ]
}