{
  "name": "building_officebank_base2_270",
  "refpalette": "deceasedcraft:building_officebank/building_officebank_base2_palette_270",
  "xsize": 16,
  "zsize": 16,
  "slices": [
    [
      "vvvvvvvvvvvvvvvv",
      "vaaaaaaaaaaaaavv",
      "vaaaaaaaaaaaaavv",
      "vaaaaaaaaaaaaavv",
      "vaaaaaaaaaaaaavv",
      "vaaaaaaaaaaaaavv",
      "vaaaaaaaaaaaaavv",
      "vaaaaaaaaaaaaavv",
      "vaaaaaaaaaaaaavv",
      "vaaaaaaaaaaaaavv",
      "vaaaaaaaaaaaaavv",
      "vaaaaaaaaaaaaavv",
      "vaaaaaaaaaaaaavv",
      "vaaaaaaaaaaaaavv",
      "vvvvvvvvvvvvvvvv",
      "vvvvvvvvvvvvvvvv"
    ],
    [
      "vvvvvvvvvvvvvvvv",
      "vaaaaaaaaaaaaavv",
      "vabbbbbbbbabbavv",
      "vabbbbbbba bbavv",
      "vabbbbbbbdb aavv",
      "vabbbbbbb cabavv",
      "vabbbbbbbbbbbavv",
      "vabbbbbbbbbbbavv",
      "vabbbbbbbbbbbavv",
      "vabaf bbb cabavv",
      "vaa bebbbeb aavv",
      "vabb abbba bbavv",
      "vabbabbbbbabbavv",
      "vaaaaaaaaaaaaavv",
      "vvvvvvvvvvvvvvvv",
      "vvvvvvvvvvvvvvvv"
    ],
    [
      "vvvvvvvvvvvvvvvv",
      "vaaaaaaaaaaaaavv",
      "vahhhhhaggaggavv",
      "vahhhhhagggggavv",
      "vahhhaaaggggaavv",
      "vahhaggagggggavv",
      "vahhaggggggggavv",
      "vaaaaagggggggavv",
      "vagggggggggggavv",
      "vagggggggggggavv",
      "vaagggggggggaavv",
      "vagggggggggggavv",
      "vaggagggggaggavv",
      "vaaaaaaaaaaaaavv",
      "vvvvvvvvvvvvvvvv",
      "vvvvvvvvvvvvvvvv"
    ],
    [
      "vvvvvvvvvvvvvvvv",
      "vaaBaBaaaaaaaavv",
      "va     a  aoiavv",
      "vB     y  spjavv",
      "va  Daaa   qaavv",
      "vB  aC a u  kavv",
      "va  a  A    lavv",
      "vaaFaaA     lavv",
      "va          lavv",
      "va   u   u  kavv",
      "vaaI       raavv",
      "vamJE     t mavv",
      "vaLKawxxxwaonavv",
      "vaaaaaaaaaaaaavv",
      "vvvvvvvvvvvvvvvv",
      "vvvvvvvvvvvvvvvv"
    ],
    [
      "vvvvvvvvvvvvvvvv",
      "vaaUaUaaaaaaaavv",
      "va     aS aM!avv",
      "v1     T  Q Mavv",
      "va  Vaaa   Oaavv",
      "v1  aC a     avv",
      "va  a  A     avv",
      "vaaXaaA      avv",
      "va0          avv",
      "va           avv",
      "vaaY       Paavv",
      "vaZ W     R Navv",
      "vaZZa     aN!avv",
      "vaaaaaaaaaaaaavv",
      "vvvvvvvvvvvvvvvv",
      "vvvvvvvvvvvvvvvv"
    ],
    [
      "vvvvvvvvvvvvvvvv",
      "vaaBaBaaaaaaaavv",
      "va 8 8 a  aM2avv",
      "vB%    a5 Q  avv",
      "va   aaa   Oaavv",
      "vB% a9 a     avv",
      "va  a  A    3avv",
      "vaaaaaA      avv",
      "va #        4avv",
      "va           avv",
      "vaaY       Paavv",
      "vaZ W     R  avv",
      "va $a 7 6 a Navv",
      "vaaaaaaaaaaaaavv",
      "vvvvvvvvvvvvvvvv",
      "vvvvvvvvvvvvvvvv"
    ]
  ]
}