{
  "name": "building_officebank_floor1_270",
  "refpalette": "deceasedcraft:building_officebank/building_officebank_floor1_palette_270",
  "xsize": 16,
  "zsize": 16,
  "slices": [
    [
      "                ",
      "     abag  a    ",
      "  agdddddddba   ",
      " abd  ieeeedc   ",
      "  d  hheeeeed   ",
      "  d hjhheeeeda  ",
      " ldkhhhheeeedb  ",
      " adeehhheeeeda  ",
      " bdeeeeeeeeedc  ",
      " adeeeeeeeeed   ",
      "  deeeeeeeeed   ",
      "  ldeeeeeeedba  ",
      "  abdddddddfa   ",
      "   a  faba      ",
      "                ",
      "                "
    ],
    [
      "                ",
      "    raba  ra    ",
      "  a nnnnnnnba   ",
      " abn iDA  hn    ",
      " Fn  hhA  s nm  ",
      "  n h  h  h na  ",
      "  n h  B wtonb  ",
      " an  hE   hpna  ",
      " bn      wtqn   ",
      " anw  w w h n   ",
      " Fnhyhyhyh  nm  ",
      "   nqxqCqx nba  ",
      "  abnnnnnnn a   ",
      "   au  abau     ",
      "                ",
      "                "
    ],
    [
      "                ",
      "   abag  aba    ",
      "    nnnnnnnc    ",
      " agniD    hn a  ",
      " bn  hh     nb  ",
      " an h  h  h na  ",
      "  n h  L  I nc  ",
      "  n  hM   h n   ",
      " ln       J n   ",
      " an       h na  ",
      " bnhKhNhKh  nb  ",
      " a n       nfa  ",
      "   lnnnnnnn     ",
      "   aba  faba    ",
      "                ",
      "                "
    ],
    [
      "                ",
      "   aba  raba    ",
      "   Fnnnnnnn     ",
      " a nD     hnra  ",
      " bnRehh     nb  ",
      " an h  h  h na  ",
      " Fn h  h  O n   ",
      "  n  hh   h n   ",
      "  n       O nm  ",
      " an       h na  ",
      " bnhQhPhPh  nb  ",
      " aun       n a  ",
      "    nnnnnnnm    ",
      "   abau  aba    ",
      "                ",
      "                "
    ],
    [
      "                ",
      "   ag  abag     ",
      "  abnnnnnnn a   ",
      "   n      hnba  ",
      " lnkAhh   h nc  ",
      " anRh  h  h n   ",
      " bn h  h  h n   ",
      " an  hh   h na  ",
      "  n       h nb  ",
      "  n       h na  ",
      " lnhhhhhhh  nc  ",
      " abn       n    ",
      "  a nnnnnnnba   ",
      "    faba  fa    ",
      "                ",
      "                "
    ],
    [
      "                ",
      "   a  raba      ",
      "  abnnnnnnnra   ",
      "  Fn   TSShnba  ",
      "  n  hhTSSh n   ",
      " ankh  hSSh n   ",
      " bnRh  hSSh nm  ",
      " anTThhUSSh na  ",
      " FnSSSSSSSh nb  ",
      "  nSSSSSSSh na  ",
      "  nhhhhhhh! n   ",
      " abn       nm   ",
      "  aunnnnnnnba   ",
      "     abau  a    ",
      "                ",
      "                "
    ]
  ]
}