{
  "name": "building_officebank_ground_270",
  "refpalette": "deceasedcraft:building_officebank/building_officebank_ground_palette_270",
  "xsize": 16,
  "zsize": 16,
  "slices": [
    [
      "aaaaaaaaaaaaaaaa",
      "aabbbbbbbbbbbaaa",
      "abbbdddddddbbbaa",
      "abbdbbdeddddbbaa",
      "abdb!ffedddddbaa",
      "abdbfg fdddddbaa",
      "abdbf  fdddddbaa",
      "abdbfffddddddbaa",
      "abdbhhfddddddbaa",
      "abdbhhfddddddbaa",
      "abdbhhfddddddbaa",
      "abbdhhfdddddcbaa",
      "abbbdddddddcccba",
      "aabbbbbbbbbbcccb",
      "aaaaaaaaaaaabccc",
      "aaaaaaaaaaaaabcc"
    ],
    [
      "    o     o     ",
      "  iipiiiiipii   ",
      " ii lllllll ii  ",
      " i l Ax    l i  ",
      "kjlF ff     lkj ",
      " ilFfg f    li  ",
      " ilFf  f r  li  ",
      " ilFfffsssf li  ",
      " ilFDBf  t  li  ",
      " ilF  f     li  ",
      "kjlF  y    mlkj ",
      " i lECf wuqn i  ",
      " ii lllllll   i ",
      "  iioiiiiioi   i",
      "    p     p i   ",
      "             i  "
    ],
    [
      "    o     o     ",
      "   IJI   IJI    ",
      "    lllllll     ",
      " I lAx     l I  ",
      "kJl  ff     lJj ",
      " Il fg f    lI  ",
      "  l f  f    l   ",
      "  l fffNM   l   ",
      "  l   f     l   ",
      " Il   f     lI  ",
      "kJl   O    KlJj ",
      " I lQPf   L  I  ",
      "    lllllll     ",
      "   IJI   IJI    ",
      "    p     p     ",
      "                "
    ],
    [
      "    o     o     ",
      "   IJIV TIJI    ",
      "   RlllllllR    ",
      " IVlx      lTI  ",
      "kJl0eff     lJj ",
      " Il fgWf    lI  ",
      " Rl f  f    lR  ",
      "  l fff     l   ",
      " Sl   f     lS  ",
      " Il   f     lI  ",
      "kJl   X     lJj ",
      " IVlZYf    UTI  ",
      "   SlllllllS    ",
      "   IJIV TIJI    ",
      "    p     p     ",
      "                "
    ],
    [
      "                ",
      "   IJIJIJIJI    ",
      "  IJlllllllJI   ",
      " IJl       lJI  ",
      " Jl42ff     lJ  ",
      " Il0fgWf    lI  ",
      " Jl f Wf    lJ  ",
      " Il fff     lI  ",
      " Jl   f     lJ  ",
      " Il   f     lI  ",
      " Jl   f     lJ  ",
      " IJl31f    lJI  ",
      "  IJlllllllJI   ",
      "   IJIJIJIJI    ",
      "                ",
      "                "
    ],
    [
      "                ",
      "   I5 JIJI5     ",
      "  IJlllllllJI   ",
      "  Jl       lJI  ",
      " 5l  ff     l5  ",
      " Il4fg f    l   ",
      " Jl0fW!f    lJ  ",
      " Il9fff6    lI  ",
      " Jl777f     lJ  ",
      "  l777f     lI  ",
      " 5l777f     l5  ",
      " IJl88f    lJ   ",
      "  IJlllllllJI   ",
      "    5IJIJ 5I    ",
      "                ",
      "                "
    ]
  ]
}