{
  "name": "building_officebank_base2_90",
  "refpalette": "deceasedcraft:building_officebank/building_officebank_base2_palette_90",
  "xsize": 16,
  "zsize": 16,
  "slices": [
    [
      "vvvvvvvvvvvvvvvv",
      "vvvvvvvvvvvvvvvv",
      "vvaaaaaaaaaaaaav",
      "vvaaaaaaaaaaaaav",
      "vvaaaaaaaaaaaaav",
      "vvaaaaaaaaaaaaav",
      "vvaaaaaaaaaaaaav",
      "vvaaaaaaaaaaaaav",
      "vvaaaaaaaaaaaaav",
      "vvaaaaaaaaaaaaav",
      "vvaaaaaaaaaaaaav",
      "vvaaaaaaaaaaaaav",
      "vvaaaaaaaaaaaaav",
      "vvaaaaaaaaaaaaav",
      "vvaaaaaaaaaaaaav",
      "vvvvvvvvvvvvvvvv"
    ],
    [
      "vvvvvvvvvvvvvvvv",
      "vvvvvvvvvvvvvvvv",
      "vvaaaaaaaaaaaaav",
      "vvabbabbbbbabbav",
      "vvabb abbba bbav",
      "vvaa bebbbeb aav",
      "vvabac bbb fabav",
      "vvabbbbbbbbbbbav",
      "vvabbbbbbbbbbbav",
      "vvabbbbbbbbbbbav",
      "vvabac bbbbbbbav",
      "vvaa bdbbbbbbbav",
      "vvabb abbbbbbbav",
      "vvabbabbbbbbbbav",
      "vvaaaaaaaaaaaaav",
      "vvvvvvvvvvvvvvvv"
    ],
    [
      "vvvvvvvvvvvvvvvv",
      "vvvvvvvvvvvvvvvv",
      "vvaaaaaaaaaaaaav",
      "vvaggagggggaggav",
      "vvagggggggggggav",
      "vvaagggggggggaav",
      "vvagggggggggggav",
      "vvagggggggggggav",
      "vvagggggggaaaaav",
      "vvaggggggggahhav",
      "vvagggggaggahhav",
      "vvaaggggaaahhhav",
      "vvagggggahhhhhav",
      "vvaggaggahhhhhav",
      "vvaaaaaaaaaaaaav",
      "vvvvvvvvvvvvvvvv"
    ],
    [
      "vvvvvvvvvvvvvvvv",
      "vvvvvvvvvvvvvvvv",
      "vvaaaaaaaaaaaaav",
      "vvanoawxxxwaKLav",
      "vvam t     EJmav",
      "vvaar       Iaav",
      "vvak  u   u   av",
      "vval          av",
      "vval     AaaFaav",
      "vval    A  a  av",
      "vvak  u a Ca  Bv",
      "vvaaq   aaaD  av",
      "vvajps  y     Bv",
      "vvaioa  a     av",
      "vvaaaaaaaaBaBaav",
      "vvvvvvvvvvvvvvvv"
    ],
    [
      "vvvvvvvvvvvvvvvv",
      "vvvvvvvvvvvvvvvv",
      "vvaaaaaaaaaaaaav",
      "vva!Na     aZZav",
      "vvaN R     W Zav",
      "vvaaP       Yaav",
      "vva           av",
      "vva          0av",
      "vva      AaaXaav",
      "vva     A  a  av",
      "vva     a Ca  1v",
      "vvaaO   aaaV  av",
      "vvaM Q  T     1v",
      "vva!Ma Sa     av",
      "vvaaaaaaaaUaUaav",
      "vvvvvvvvvvvvvvvv"
    ],
    [
      "vvvvvvvvvvvvvvvv",
      "vvvvvvvvvvvvvvvv",
      "vvaaaaaaaaaaaaav",
      "vvaN a 6 7 a$ av",
      "vva  R     W Zav",
      "vvaaP       Yaav",
      "vva           av",
      "vva4        # av",
      "vva      Aaaaaav",
      "vva3    A  a  av",
      "vva     a 9a %Bv",
      "vvaaO   aaa   av",
      "vva  Q 5a    %Bv",
      "vva2Ma  a 8 8 av",
      "vvaaaaaaaaBaBaav",
      "vvvvvvvvvvvvvvvv"
    ]
  ]
}