{
  "name": "building_officebank_floor1_180",
  "refpalette": "deceasedcraft:building_officebank/building_officebank_floor1_palette_180",
  "xsize": 16,
  "zsize": 16,
  "slices": [
    [
      "                ",
      "      abal  a   ",
      "   aldddddddba  ",
      "  abdeeeek  dg  ",
      "   deeeeehh  d  ",
      "   deeeehhjh da ",
      "  fdeeeehhhhidb ",
      "  adeeeehhheeda ",
      "  bdeeeeeeeeedg ",
      "  adeeeeeeeeed  ",
      "   deeeeeeeeed  ",
      "   fdeeeeeeedba ",
      "   abdddddddca  ",
      "    a  caba     ",
      "                ",
      "                "
    ],
    [
      "                ",
      "     Faba  Fa   ",
      "   a nnnnnnnba  ",
      "  abnhw     n   ",
      "  unqy   hh  nr ",
      "   nxh  h  hina ",
      "   nqyw E  hDnb ",
      "  anCh   BhAAna ",
      "  bnqyw      n  ",
      "  anxh w w   n  ",
      "  un  hththshnr ",
      "    n  qpo  nba ",
      "   abnnnnnnn a  ",
      "    am  abam    ",
      "                ",
      "                "
    ],
    [
      "                ",
      "    abal  aba   ",
      "     nnnnnnng   ",
      "  alnh      n a ",
      "  bn K   hh inb ",
      "  an h  h  hDna ",
      "   n N  M  h ng ",
      "   n h   Lh  n  ",
      "  fn K       n  ",
      "  an h       na ",
      "  bn  hJhIh hnb ",
      "  a n       nca ",
      "    fnnnnnnn    ",
      "    aba  caba   ",
      "                ",
      "                "
    ],
    [
      "                ",
      "    aba  Faba   ",
      "    unnnnnnn    ",
      "  a nh     RnFa ",
      "  bn Q   hheDnb ",
      "  an h  h  h na ",
      "  un P  h  h n  ",
      "   n h   hh  n  ",
      "   n P       nr ",
      "  an h       na ",
      "  bn  hOhOh hnb ",
      "  amn       n a ",
      "     nnnnnnnr   ",
      "    abam  aba   ",
      "                ",
      "                "
    ],
    [
      "                ",
      "    al  abal    ",
      "   abnnnnnnn a  ",
      "    nh    Rknba ",
      "  fn h   hhA ng ",
      "  an h  h  h n  ",
      "  bn h  h  h n  ",
      "  an h   hh  na ",
      "   n h       nb ",
      "   n h       na ",
      "  fn  hhhhhhhng ",
      "  abn       n   ",
      "   a nnnnnnnba  ",
      "     caba  ca   ",
      "                ",
      "                "
    ],
    [
      "                ",
      "    a  Faba     ",
      "   abnnnnnnnFa  ",
      "   unhSSTRk nba ",
      "   n hSSThh  n  ",
      "  an hSSh  h n  ",
      "  bn hSSh  h nr ",
      "  an hSSUhhTTna ",
      "  un hSSSSSSSnb ",
      "   n hSSSSSSSna ",
      "   n !hhhhhhhn  ",
      "  abn       nr  ",
      "   amnnnnnnnba  ",
      "      abam  a   ",
      "                ",
      "                "
    ]
  ]
}