{
  "name": "building_officebank_floor3_270",
  "refpalette": "deceasedcraft:building_officebank/building_officebank_floor3_palette_270",
  "xsize": 16,
  "zsize": 16,
  "slices": [
    [
      "                ",
      "     abag  a    ",
      "  agdddddddba   ",
      " abd  heeeedc   ",
      "  d  eeeeeeed   ",
      "  d eeeeeeeeda  ",
      " jdieeeeeeeedb  ",
      " adeeeeeeeeeda  ",
      " bdeeeeeeeeedc  ",
      " adeeeeeeeeed   ",
      "  deeeeeeeeed   ",
      "  jdeeeeeeedba  ",
      "  abdddddddfa   ",
      "   a  faba      ",
      "                ",
      "                "
    ],
    [
      "                ",
      "    paba  pa    ",
      "  a lllllllba   ",
      " abl hD    l    ",
      " Jl  BBB  q lk  ",
      "  l B EC  rmla  ",
      "  l Bn   wnnlb  ",
      " al Bw    s la  ",
      " bl      x  l   ",
      " al  x  wnn l   ",
      " Jl wnFA ytolk  ",
      "   l nI  A lba  ",
      "  ablllllll a   ",
      "   au  abau     ",
      "                ",
      "                "
    ],
    [
      "                ",
      "   abag  aba    ",
      "    lllllllc    ",
      " aglhD     l a  ",
      " bl !RRR    lb  ",
      " al R     MKla  ",
      "  l RU    NLlc  ",
      "  l R       l   ",
      " jl         l   ",
      " al      P  la  ",
      " bl   S  QO lb  ",
      " a l VT    lfa  ",
      "   jlllllll     ",
      "   aba  faba    ",
      "                ",
      "                "
    ],
    [
      "                ",
      "   aba  paba    ",
      "   Jlllllll     ",
      " a lD      lpa  ",
      " blWeRRR    lb  ",
      " al R       la  ",
      " Jl R       l   ",
      "  l R       l   ",
      "  l         lk  ",
      " al         la  ",
      " bl         lb  ",
      " aul       l a  ",
      "    lllllllk    ",
      "   abau  aba    ",
      "                ",
      "                "
    ],
    [
      "                ",
      "   ag  abag     ",
      "  ablllllll a   ",
      "   l       lba  ",
      " jliXRRR    lc  ",
      " alWR       l   ",
      " bl R       l   ",
      " al R       la  ",
      "  l         lb  ",
      "  l         la  ",
      " jl         lc  ",
      " abl       l    ",
      "  a lllllllba   ",
      "    faba  fa    ",
      "                ",
      "                "
    ],
    [
      "                ",
      "   a  paba      ",
      "  ablllllllpa   ",
      "  Jl       lba  ",
      "  l  YYY    l   ",
      " aliY       l   ",
      " blWY       lk  ",
      " alZY       la  ",
      " Jl         lb  ",
      "  l         la  ",
      "  l         l   ",
      " abl       lk   ",
      "  aulllllllba   ",
      "     abau  a    ",
      "                ",
      "                "
    ]
  ]
}