{
  "name": "building_officebank_base2_180",
  "refpalette": "deceasedcraft:building_officebank/building_officebank_base2_palette_180",
  "xsize": 16,
  "zsize": 16,
  "slices": [
    [
      "vvvvvvvvvvvvvvvv",
      "vvaaaaaaaaaaaaav",
      "vvaaaaaaaaaaaaav",
      "vvaaaaaaaaaaaaav",
      "vvaaaaaaaaaaaaav",
      "vvaaaaaaaaaaaaav",
      "vvaaaaaaaaaaaaav",
      "vvaaaaaaaaaaaaav",
      "vvaaaaaaaaaaaaav",
      "vvaaaaaaaaaaaaav",
      "vvaaaaaaaaaaaaav",
      "vvaaaaaaaaaaaaav",
      "vvaaaaaaaaaaaaav",
      "vvaaaaaaaaaaaaav",
      "vvvvvvvvvvvvvvvv",
      "vvvvvvvvvvvvvvvv"
    ],
    [
      "vvvvvvvvvvvvvvvv",
      "vvaaaaaaaaaaaaav",
      "vvabbabbbbbbbbav",
      "vvabb abbbbbbbav",
      "vvaa bfbbbbbbbav",
      "vvabae bbbbbbbav",
      "vvabbbbbbbbbbbav",
      "vvabbbbbbbbbbbav",
      "vvabbbbbbbbbbbav",
      "vvabae bbb dabav",
      "vvaa bcbbbcb aav",
      "vvabb abbba bbav",
      "vvabbabbbbbabbav",
      "vvaaaaaaaaaaaaav",
      "vvvvvvvvvvvvvvvv",
      "vvvvvvvvvvvvvvvv"
    ],
    [
      "vvvvvvvvvvvvvvvv",
      "vvaaaaaaaaaaaaav",
      "vvaggaggahhhhhav",
      "vvagggggahhhhhav",
      "vvaaggggaaahhhav",
      "vvagggggaggahhav",
      "vvaggggggggahhav",
      "vvagggggggaaaaav",
      "vvagggggggggggav",
      "vvagggggggggggav",
      "vvaagggggggggaav",
      "vvagggggggggggav",
      "vvaggagggggaggav",
      "vvaaaaaaaaaaaaav",
      "vvvvvvvvvvvvvvvv",
      "vvvvvvvvvvvvvvvv"
    ],
    [
      "vvvvvvvvvvvvvvvv",
      "vvaaaaaaaaBaBaav",
      "vvaLma  a     av",
      "vvaKJI  F     Bv",
      "vvaaE   aaaD  av",
      "vvaw  u a Ca  Bv",
      "vvax    A  a  av",
      "vvax     Aaayaav",
      "vvax          av",
      "vvaw  u   u   av",
      "vvaat       saav",
      "vvao r     qpoav",
      "vvanmaklllkajiav",
      "vvaaaaaaaaaaaaav",
      "vvvvvvvvvvvvvvvv",
      "vvvvvvvvvvvvvvvv"
    ],
    [
      "vvvvvvvvvvvvvvvv",
      "vvaaaaaaaa1a1aav",
      "vvaZZa 0a     av",
      "vvaZ Y  X     Uv",
      "vvaaW   aaaV  av",
      "vva     a Ca  Uv",
      "vva     A  a  av",
      "vva      AaaTaav",
      "vva          Sav",
      "vva           av",
      "vvaaR       Qaav",
      "vvaN P     O Mav",
      "vva!Na     aM!av",
      "vvaaaaaaaaaaaaav",
      "vvvvvvvvvvvvvvvv",
      "vvvvvvvvvvvvvvvv"
    ],
    [
      "vvvvvvvvvvvvvvvv",
      "vvaaaaaaaaBaBaav",
      "vva Za  a % % av",
      "vva$ Y #a    8Bv",
      "vvaaW   aaa   av",
      "vva     a 9a 8Bv",
      "vva7    A  a  av",
      "vva      Aaaaaav",
      "vva6        5 av",
      "vva           av",
      "vvaaR       Qaav",
      "vva  P     O Mav",
      "vvaN a 4 3 a 2av",
      "vvaaaaaaaaaaaaav",
      "vvvvvvvvvvvvvvvv",
      "vvvvvvvvvvvvvvvv"
    ]
  ]
}