{
  "name": "building_officebank_floor2_270",
  "refpalette": "deceasedcraft:building_officebank/building_officebank_floor2_palette_270",
  "xsize": 16,
  "zsize": 16,
  "slices": [
    [
      "                ",
      "     abag  a    ",
      "  agdddddddba   ",
      " abd  heeeedc   ",
      "  d  eeeeeeed   ",
      "  d eeeeeeeeda  ",
      " jdieeeeeeeedb  ",
      " adeeeeeeeeeda  ",
      " bdeeeeeeeeedc  ",
      " adeeeeeeeeed   ",
      "  deeeeeeeeed   ",
      "  jdeeeeeeedba  ",
      "  abdddddddfa   ",
      "   a  faba      ",
      "                ",
      "                "
    ],
    [
      "                ",
      "    oaba  oa    ",
      "  a lllllllba   ",
      " abl hC   pl    ",
      " Il  AAA    lk  ",
      "  l A DB  qmla  ",
      "  l An   unnlb  ",
      " al Au    r la  ",
      " bl      w  l   ",
      " al  w  unn l   ",
      " Il unEy xs lk  ",
      "   l nF! y lba  ",
      "  ablllllll a   ",
      "   at  abat     ",
      "                ",
      "                "
    ],
    [
      "                ",
      "   abag  aba    ",
      "    lllllllc    ",
      " aglhC     l a  ",
      " bl  PPP    lb  ",
      " al P      Jla  ",
      "  l PS    LKlc  ",
      "  l P       l   ",
      " jl         l   ",
      " al      OM la  ",
      " bl  TQ   N lb  ",
      " a l UR    lfa  ",
      "   jlllllll     ",
      "   aba  faba    ",
      "                ",
      "                "
    ],
    [
      "                ",
      "   aba  oaba    ",
      "   Illlllll     ",
      " a lC      loa  ",
      " blVePPP    lb  ",
      " al P       la  ",
      " Il P       l   ",
      "  l P       l   ",
      "  l         lk  ",
      " al         la  ",
      " bl         lb  ",
      " atl       l a  ",
      "    lllllllk    ",
      "   abat  aba    ",
      "                ",
      "                "
    ],
    [
      "                ",
      "   ag  abag     ",
      "  ablllllll a   ",
      "   l       lba  ",
      " jliWPPP    lc  ",
      " alVP       l   ",
      " bl P       l   ",
      " al P       la  ",
      "  l         lb  ",
      "  l         la  ",
      " jl         lc  ",
      " abl       l    ",
      "  a lllllllba   ",
      "    faba  fa    ",
      "                ",
      "                "
    ],
    [
      "                ",
      "   a  oaba      ",
      "  abllllllloa   ",
      "  Il       lba  ",
      "  l  XXX    l   ",
      " aliX       l   ",
      " blVX       lk  ",
      " alYX       la  ",
      " Il         lb  ",
      "  l         la  ",
      "  l         l   ",
      " abl       lk   ",
      "  atlllllllba   ",
      "     abat  a    ",
      "                ",
      "                "
    ]
  ]
}