{
  "name": "building_officebank_floor3_90",
  "refpalette": "deceasedcraft:building_officebank/building_officebank_floor3_palette_90",
  "xsize": 16,
  "zsize": 16,
  "slices": [
    [
      "                ",
      "                ",
      "      abaf  a   ",
      "   afdddddddba  ",
      "  abdeeeeeeedj  ",
      "   deeeeeeeeed  ",
      "   deeeeeeeeeda ",
      "  cdeeeeeeeeedb ",
      "  adeeeeeeeeeda ",
      "  bdeeeeeeeeidj ",
      "  adeeeeeeee d  ",
      "   deeeeeee  d  ",
      "   cdeeeeh  dba ",
      "   abdddddddga  ",
      "    a  gaba     ",
      "                "
    ],
    [
      "                ",
      "                ",
      "     uaba  ua   ",
      "   a lllllllba  ",
      "  abl A  In l   ",
      "  kloty AFnw lJ ",
      "   l nnw  x  la ",
      "   l  x      lb ",
      "  al s    wB la ",
      "  blnnw   nB l  ",
      "  almr  CE B l  ",
      "  kl q  BBB  lJ ",
      "    l    Dh lba ",
      "   ablllllll a  ",
      "    ap  abap    ",
      "                "
    ],
    [
      "                ",
      "                ",
      "    abaf  aba   ",
      "     lllllllj   ",
      "  afl    TV l a ",
      "  bl OQ  S   lb ",
      "  al  P      la ",
      "   l         lj ",
      "   l       R l  ",
      "  clLN    UR l  ",
      "  alKM     R la ",
      "  bl    RRR! lb ",
      "  a l     Dhlga ",
      "    clllllll    ",
      "    aba  gaba   ",
      "                "
    ],
    [
      "                ",
      "                ",
      "    aba  uaba   ",
      "    klllllll    ",
      "  a l       lua ",
      "  bl         lb ",
      "  al         la ",
      "  kl         l  ",
      "   l       R l  ",
      "   l       R lJ ",
      "  al       R la ",
      "  bl    RRReWlb ",
      "  apl      Dl a ",
      "     lllllllJ   ",
      "    abap  aba   ",
      "                "
    ],
    [
      "                ",
      "                ",
      "    af  abaf    ",
      "   ablllllll a  ",
      "    l       lba ",
      "  cl         lj ",
      "  al         l  ",
      "  bl         l  ",
      "  al       R la ",
      "   l       R lb ",
      "   l       RWla ",
      "  cl    RRRXilj ",
      "  abl       l   ",
      "   a lllllllba  ",
      "     gaba  ga   ",
      "                "
    ],
    [
      "                ",
      "                ",
      "    a  uaba     ",
      "   ablllllllua  ",
      "   kl       lba ",
      "   l         l  ",
      "  al         l  ",
      "  bl         lJ ",
      "  al       YZla ",
      "  kl       YWlb ",
      "   l       Yila ",
      "   l    YYY  l  ",
      "  abl       lJ  ",
      "   aplllllllba  ",
      "      abap  a   ",
      "                "
    ]
  ]
}