{
  "name": "building_officebank_floor2_90",
  "refpalette": "deceasedcraft:building_officebank/building_officebank_floor2_palette_90",
  "xsize": 16,
  "zsize": 16,
  "slices": [
    [
      "                ",
      "                ",
      "      abaf  a   ",
      "   afdddddddba  ",
      "  abdeeeeeeedj  ",
      "   deeeeeeeeed  ",
      "   deeeeeeeeeda ",
      "  cdeeeeeeeeedb ",
      "  adeeeeeeeeeda ",
      "  bdeeeeeeeeidj ",
      "  adeeeeeeee d  ",
      "   deeeeeee  d  ",
      "   cdeeeeh  dba ",
      "   abdddddddga  ",
      "    a  gaba     ",
      "                "
    ],
    [
      "                ",
      "                ",
      "     taba  ta   ",
      "   a lllllllba  ",
      "  abl y !Fn l   ",
      "  kl sx yEnu lI ",
      "   l nnu  w  la ",
      "   l  w      lb ",
      "  al r    uA la ",
      "  blnnu   nA l  ",
      "  almq  BD A l  ",
      "  kl    AAA  lI ",
      "    lp   Ch lba ",
      "   ablllllll a  ",
      "    ao  abao    ",
      "                "
    ],
    [
      "                ",
      "                ",
      "    abaf  aba   ",
      "     lllllllj   ",
      "  afl    RU l a ",
      "  bl N   QT  lb ",
      "  al MO      la ",
      "   l         lj ",
      "   l       P l  ",
      "  clKL    SP l  ",
      "  alJ      P la ",
      "  bl    PPP  lb ",
      "  a l     Chlga ",
      "    clllllll    ",
      "    aba  gaba   ",
      "                "
    ],
    [
      "                ",
      "                ",
      "    aba  taba   ",
      "    klllllll    ",
      "  a l       lta ",
      "  bl         lb ",
      "  al         la ",
      "  kl         l  ",
      "   l       P l  ",
      "   l       P lI ",
      "  al       P la ",
      "  bl    PPPeVlb ",
      "  aol      Cl a ",
      "     lllllllI   ",
      "    abao  aba   ",
      "                "
    ],
    [
      "                ",
      "                ",
      "    af  abaf    ",
      "   ablllllll a  ",
      "    l       lba ",
      "  cl         lj ",
      "  al         l  ",
      "  bl         l  ",
      "  al       P la ",
      "   l       P lb ",
      "   l       PVla ",
      "  cl    PPPWilj ",
      "  abl       l   ",
      "   a lllllllba  ",
      "     gaba  ga   ",
      "                "
    ],
    [
      "                ",
      "                ",
      "    a  taba     ",
      "   ablllllllta  ",
      "   kl       lba ",
      "   l         l  ",
      "  al         l  ",
      "  bl         lI ",
      "  al       XYla ",
      "  kl       XVlb ",
      "   l       Xila ",
      "   l    XXX  l  ",
      "  abl       lI  ",
      "   aolllllllba  ",
      "      abao  a   ",
      "                "
    ]
  ]
}