{
  "name": "building_officebank_floor1_90",
  "refpalette": "deceasedcraft:building_officebank/building_officebank_floor1_palette_90",
  "xsize": 16,
  "zsize": 16,
  "slices": [
    [
      "                ",
      "                ",
      "      abaf  a   ",
      "   afdddddddba  ",
      "  abdeeeeeeedl  ",
      "   deeeeeeeeed  ",
      "   deeeeeeeeeda ",
      "  cdeeeeeeeeedb ",
      "  adeeeehhheeda ",
      "  bdeeeehhhhkdl ",
      "  adeeeehhjh d  ",
      "   deeeeehh  d  ",
      "   cdeeeei  dba ",
      "   abdddddddga  ",
      "    a  gaba     ",
      "                "
    ],
    [
      "                ",
      "                ",
      "     uaba  ua   ",
      "   a nnnnnnnba  ",
      "  abn xqCqxqn   ",
      "  mn  hyhyhyhnF ",
      "   n h w w  wna ",
      "   nqtw      nb ",
      "  anph   Eh  na ",
      "  bnotw B  h n  ",
      "  an h  h  h n  ",
      "  mn s  Ahh  nF ",
      "    nh  ADi nba ",
      "   abnnnnnnn a  ",
      "    ar  abar    ",
      "                "
    ],
    [
      "                ",
      "                ",
      "    abaf  aba   ",
      "     nnnnnnnl   ",
      "  afn       n a ",
      "  bn  hKhNhKhnb ",
      "  an h       na ",
      "   n J       nl ",
      "   n h   Mh  n  ",
      "  cn I  L  h n  ",
      "  an h  h  h na ",
      "  bn     hh  nb ",
      "  a nh    Dinga ",
      "    cnnnnnnn    ",
      "    aba  gaba   ",
      "                "
    ],
    [
      "                ",
      "                ",
      "    aba  uaba   ",
      "    mnnnnnnn    ",
      "  a n       nua ",
      "  bn  hPhPhQhnb ",
      "  an h       na ",
      "  mn O       n  ",
      "   n h   hh  n  ",
      "   n O  h  h nF ",
      "  an h  h  h na ",
      "  bn     hheRnb ",
      "  arnh     Dn a ",
      "     nnnnnnnF   ",
      "    abar  aba   ",
      "                "
    ],
    [
      "                ",
      "                ",
      "    af  abaf    ",
      "   abnnnnnnn a  ",
      "    n       nba ",
      "  cn  hhhhhhhnl ",
      "  an h       n  ",
      "  bn h       n  ",
      "  an h   hh  na ",
      "   n h  h  h nb ",
      "   n h  h  hRna ",
      "  cn h   hhAknl ",
      "  abnh      n   ",
      "   a nnnnnnnba  ",
      "     gaba  ga   ",
      "                "
    ],
    [
      "                ",
      "                ",
      "    a  uaba     ",
      "   abnnnnnnnua  ",
      "   mn       nba ",
      "   n !hhhhhhhn  ",
      "  an hSSSSSSSn  ",
      "  bn hSSSSSSSnF ",
      "  an hSSUhhTTna ",
      "  mn hSSh  hRnb ",
      "   n hSSh  hkna ",
      "   n hSSThh  n  ",
      "  abnhSST   nF  ",
      "   arnnnnnnnba  ",
      "      abar  a   ",
      "                "
    ]
  ]
}