{
  "name": "building_officebank_base1_90",
  "refpalette": "deceasedcraft:building_officebank/building_officebank_base1_palette_90",
  "xsize": 16,
  "zsize": 16,
  "slices": [
    [
      "vvvvvvvvvvvvvvvv",
      "vvvvvvvvvvvvvvvv",
      "vvaaaaaaaaaaaaav",
      "vva  a b b a  av",
      "vva  g     l  av",
      "vvaae       maav",
      "vva           av",
      "vvab          av",
      "vva      haaaaav",
      "vvab    h  a  av",
      "vva     a ja  nv",
      "vvaad   aaak  av",
      "vva  f  a     nv",
      "vva ca  a     av",
      "vvaaaaaaaaiaiaav",
      "vvvvvvvvvvvvvvvv"
    ],
    [
      "vvvvvvvvvvvvvvvv",
      "vvvvvvvvvvvvvvvv",
      "vvaaaaaaaaaaaaav",
      "vva  a p p a  av",
      "vva  g     l  av",
      "vvaae       maav",
      "vva           av",
      "vvao          av",
      "vva      haaaaav",
      "vvao    h  a  av",
      "vva     a ja sqv",
      "vvaad   aaak  av",
      "vva  f  a    sqv",
      "vva  a  a r r av",
      "vvaaaaaaaaqaqaav",
      "vvvvvvvvvvvvvvvv"
    ],
    [
      "vvvvvvvvvvvvvvvv",
      "vvvvvvvvvvvvvvvv",
      "vvaaaaaaaaaaaaav",
      "vva  a     a  av",
      "vva  g     l  av",
      "vvaae       maav",
      "vva           av",
      "vva           av",
      "vva      haaaaav",
      "vva     h  a  av",
      "vva     a ja  nv",
      "vvaad   aaak  av",
      "vva  f  a     nv",
      "vva  a  a     av",
      "vvaaaaaaaaiaiaav",
      "vvvvvvvvvvvvvvvv"
    ],
    [
      "vvvvvvvvvvvvvvvv",
      "vvvvvvvvvvvvvvvv",
      "vvaaaaaaaaaaaaav",
      "vvab attttta bav",
      "vva  y     C  av",
      "vvaaw       Eaav",
      "vvat         Aav",
      "vvat         Aav",
      "vvat    Bhaaaaav",
      "vvat    h  a  av",
      "vvat    a ja sqv",
      "vvaau   aaak  av",
      "vva  x  a    sqv",
      "vva  aAAa r D av",
      "vvaaaaaaaaqaqaav",
      "vvvvvvvvvvvvvvvv"
    ],
    [
      "vvvvvvvvvvvvvvvv",
      "vvvvvvvvvvvvvvvv",
      "vvaaaaaaaaaaaaav",
      "vvaFFaFFFFFaFFav",
      "vvaFFFFFFFFFFFav",
      "vvaaFFFFFFFFFaav",
      "vvaFFFFFFFFFFFav",
      "vvaFFFFFFFFFFFav",
      "vvaFFFFFaaaaaaav",
      "vvaFFFFFa  aIIav",
      "vvaFFFFFa jaIIav",
      "vvaaFFFFaaaJIIav",
      "vvaFFFFFaIIIIIav",
      "vvaFFaFFaIIIIIav",
      "vvaaaaaaaaaaaaav",
      "vvvvvvvvvvvvvvvv"
    ],
    [
      "vvvvvvvvvvvvvvvv",
      "vvvvvvvvvvvvvvvv",
      "vvaaaaaaaaaaaaav",
      "vvaaaaaaaaaaaaav",
      "vvaaaaaaaaaaaaav",
      "vvaaaaaaaaaaaaav",
      "vvaaaaaaaaaaaaav",
      "vvaaaaaaaaaaaaav",
      "vvaaaaaaaaaaaaav",
      "vvaaaaaaa  aaaav",
      "vvaaaaaaa jaaaav",
      "vvaaaaaaaaaaaaav",
      "vvaaaaaaaaaaaaav",
      "vvaaaaaaaaaaaaav",
      "vvaaaaaaaaaaaaav",
      "vvvvvvvvvvvvvvvv"
    ]
  ]
}