{
  "name": "building_officebank_base1_270",
  "refpalette": "deceasedcraft:building_officebank/building_officebank_base1_palette_270",
  "xsize": 16,
  "zsize": 16,
  "slices": [
    [
      "vvvvvvvvvvvvvvvv",
      "vaaiaiaaaaaaaavv",
      "va     a  ac avv",
      "vn     a  f  avv",
      "va  kaaa   daavv",
      "vn  aj a     avv",
      "va  a  h    bavv",
      "vaaaaah      avv",
      "va          bavv",
      "va           avv",
      "vaam       eaavv",
      "va  l     g  avv",
      "va  a b b a  avv",
      "vaaaaaaaaaaaaavv",
      "vvvvvvvvvvvvvvvv",
      "vvvvvvvvvvvvvvvv"
    ],
    [
      "vvvvvvvvvvvvvvvv",
      "vaaqaqaaaaaaaavv",
      "va r r a  a  avv",
      "vqs    a  f  avv",
      "va  kaaa   daavv",
      "vqs aj a     avv",
      "va  a  h    oavv",
      "vaaaaah      avv",
      "va          oavv",
      "va           avv",
      "vaam       eaavv",
      "va  l     g  avv",
      "va  a p p a  avv",
      "vaaaaaaaaaaaaavv",
      "vvvvvvvvvvvvvvvv",
      "vvvvvvvvvvvvvvvv"
    ],
    [
      "vvvvvvvvvvvvvvvv",
      "vaaiaiaaaaaaaavv",
      "va     a  a  avv",
      "vn     a  f  avv",
      "va  kaaa   daavv",
      "vn  aj a     avv",
      "va  a  h     avv",
      "vaaaaah      avv",
      "va           avv",
      "va           avv",
      "vaam       eaavv",
      "va  l     g  avv",
      "va  a     a  avv",
      "vaaaaaaaaaaaaavv",
      "vvvvvvvvvvvvvvvv",
      "vvvvvvvvvvvvvvvv"
    ],
    [
      "vvvvvvvvvvvvvvvv",
      "vaaqaqaaaaaaaavv",
      "va D r aAAa  avv",
      "vqs    a  x  avv",
      "va  kaaa   uaavv",
      "vqs aj a    tavv",
      "va  a  h    tavv",
      "vaaaaahB    tavv",
      "vaA         tavv",
      "vaA         tavv",
      "vaaE       waavv",
      "va  C     y  avv",
      "vab attttta bavv",
      "vaaaaaaaaaaaaavv",
      "vvvvvvvvvvvvvvvv",
      "vvvvvvvvvvvvvvvv"
    ],
    [
      "vvvvvvvvvvvvvvvv",
      "vaaaaaaaaaaaaavv",
      "vaIIIIIaFFaFFavv",
      "vaIIIIIaFFFFFavv",
      "vaIIJaaaFFFFaavv",
      "vaIIaj aFFFFFavv",
      "vaIIa  aFFFFFavv",
      "vaaaaaaaFFFFFavv",
      "vaFFFFFFFFFFFavv",
      "vaFFFFFFFFFFFavv",
      "vaaFFFFFFFFFaavv",
      "vaFFFFFFFFFFFavv",
      "vaFFaFFFFFaFFavv",
      "vaaaaaaaaaaaaavv",
      "vvvvvvvvvvvvvvvv",
      "vvvvvvvvvvvvvvvv"
    ],
    [
      "vvvvvvvvvvvvvvvv",
      "vaaaaaaaaaaaaavv",
      "vaaaaaaaaaaaaavv",
      "vaaaaaaaaaaaaavv",
      "vaaaaaaaaaaaaavv",
      "vaaaaj aaaaaaavv",
      "vaaaa  aaaaaaavv",
      "vaaaaaaaaaaaaavv",
      "vaaaaaaaaaaaaavv",
      "vaaaaaaaaaaaaavv",
      "vaaaaaaaaaaaaavv",
      "vaaaaaaaaaaaaavv",
      "vaaaaaaaaaaaaavv",
      "vaaaaaaaaaaaaavv",
      "vvvvvvvvvvvvvvvv",
      "vvvvvvvvvvvvvvvv"
    ]
  ]
}