{
  "name": "building_officebank_base1_180",
  "refpalette": "deceasedcraft:building_officebank/building_officebank_base1_palette_180",
  "xsize": 16,
  "zsize": 16,
  "slices": [
    [
      "vvvvvvvvvvvvvvvv",
      "vvaaaaaaaananaav",
      "vva  a  a     av",
      "vva  m  a     iv",
      "vvaal   aaak  av",
      "vva     a ja  iv",
      "vvab    h  a  av",
      "vva      haaaaav",
      "vvab          av",
      "vva           av",
      "vvaag       faav",
      "vva  e     d cav",
      "vva  a b b a  av",
      "vvaaaaaaaaaaaaav",
      "vvvvvvvvvvvvvvvv",
      "vvvvvvvvvvvvvvvv"
    ],
    [
      "vvvvvvvvvvvvvvvv",
      "vvaaaaaaaaqaqaav",
      "vva  a  a s s av",
      "vva  m  a    rqv",
      "vvaal   aaak  av",
      "vva     a ja rqv",
      "vvap    h  a  av",
      "vva      haaaaav",
      "vvap          av",
      "vva           av",
      "vvaag       faav",
      "vva  e     d  av",
      "vva  a o o a  av",
      "vvaaaaaaaaaaaaav",
      "vvvvvvvvvvvvvvvv",
      "vvvvvvvvvvvvvvvv"
    ],
    [
      "vvvvvvvvvvvvvvvv",
      "vvaaaaaaaananaav",
      "vva  a  a     av",
      "vva  m  a     iv",
      "vvaal   aaak  av",
      "vva     a ja  iv",
      "vva     h  a  av",
      "vva      haaaaav",
      "vva           av",
      "vva           av",
      "vvaag       faav",
      "vva  e     d  av",
      "vva  a     a  av",
      "vvaaaaaaaaaaaaav",
      "vvvvvvvvvvvvvvvv",
      "vvvvvvvvvvvvvvvv"
    ],
    [
      "vvvvvvvvvvvvvvvv",
      "vvaaaaaaaaqaqaav",
      "vvab aAAa s s av",
      "vva  E  a    Dqv",
      "vvaaC   aaak  av",
      "vvat    a ja rqv",
      "vvat    h  a  av",
      "vvat    Bhaaaaav",
      "vvat         Aav",
      "vvat         Aav",
      "vvaay       xaav",
      "vva  w     u  av",
      "vvab attttta  av",
      "vvaaaaaaaaaaaaav",
      "vvvvvvvvvvvvvvvv",
      "vvvvvvvvvvvvvvvv"
    ],
    [
      "vvvvvvvvvvvvvvvv",
      "vvaaaaaaaaaaaaav",
      "vvaFFaFFaIIIIIav",
      "vvaFFFFFaIIIIIav",
      "vvaaFFFFaaaJIIav",
      "vvaFFFFFa jaIIav",
      "vvaFFFFFa  aIIav",
      "vvaFFFFFaaaaaaav",
      "vvaFFFFFFFFFFFav",
      "vvaFFFFFFFFFFFav",
      "vvaaFFFFFFFFFaav",
      "vvaFFFFFFFFFFFav",
      "vvaFFaFFFFFaFFav",
      "vvaaaaaaaaaaaaav",
      "vvvvvvvvvvvvvvvv",
      "vvvvvvvvvvvvvvvv"
    ],
    [
      "vvvvvvvvvvvvvvvv",
      "vvaaaaaaaaaaaaav",
      "vvaaaaaaaaaaaaav",
      "vvaaaaaaaaaaaaav",
      "vvaaaaaaaaaaaaav",
      "vvaaaaaaa jaaaav",
      "vvaaaaaaa  aaaav",
      "vvaaaaaaaaaaaaav",
      "vvaaaaaaaaaaaaav",
      "vvaaaaaaaaaaaaav",
      "vvaaaaaaaaaaaaav",
      "vvaaaaaaaaaaaaav",
      "vvaaaaaaaaaaaaav",
      "vvaaaaaaaaaaaaav",
      "vvvvvvvvvvvvvvvv",
      "vvvvvvvvvvvvvvvv"
    ]
  ]
}