{
  "name": "building_officebank_top_180",
  "refpalette": "deceasedcraft:building_officebank/building_officebank_top_palette_180",
  "xsize": 16,
  "zsize": 16,
  "slices": [
    [
      "                ",
      "      abaj  a   ",
      "   ajdddddddba  ",
      "  abdeeeei  dg  ",
      "   deeeeeee  d  ",
      "   deeeeeeee da ",
      "  fdeeeeeeeehdb ",
      "  adeeeeeeeeeda ",
      "  bdeeeeeeeeedg ",
      "  adeeeeeeeeed  ",
      "   deeeeeeeeed  ",
      "   fdeeeeeeedba ",
      "   abdddddddca  ",
      "    a  caba     ",
      "                ",
      "                "
    ],
    [
      "                ",
      "     Iaba  Ia   ",
      "   a lllllllba  ",
      "  abm F     m   ",
      "  rl E   yy  ln ",
      "   lD    Byy la ",
      "   lC    BAyylb ",
      "  al    tpxw la ",
      "  bl     psu l  ",
      "  alq   tps  l  ",
      "  rlq    po  ln ",
      "    m       mba ",
      "   ablllllll a  ",
      "    ak  abak    ",
      "                ",
      "                "
    ],
    [
      "                ",
      "    abaj  aba   ",
      "     mlllllmg   ",
      "  ajl       l a ",
      "  bm R   PP  mb ",
      "  al     BPP la ",
      "   l     BQPPlg ",
      "   l      O  l  ",
      "  fl      N  l  ",
      "  al     M   la ",
      "  bmL    KJ  mb ",
      "  a l       lca ",
      "    fmlllllm    ",
      "    aba  caba   ",
      "                ",
      "                "
    ],
    [
      "                ",
      "    aba  Iaba   ",
      "    rlmlllml    ",
      "  a l       lIa ",
      "  bl         lb ",
      "  am     V   ma ",
      "  rl     U   l  ",
      "   l         l  ",
      "   l         ln ",
      "  amT        ma ",
      "  blS        lb ",
      "  akl       l a ",
      "     lmlllmln   ",
      "    abak  aba   ",
      "                ",
      "                "
    ],
    [
      "                ",
      "    aj  abaj    ",
      "   abllmlmll a  ",
      "    l       lba ",
      "  fl         lg ",
      "  al         l  ",
      "  bm         m  ",
      "  al         la ",
      "   m         mb ",
      "   l         la ",
      "  fl         lg ",
      "  abl       l   ",
      "   a llmlmllba  ",
      "     caba  ca   ",
      "                ",
      "                "
    ],
    [
      "                ",
      "    a  Iaba     ",
      "   ablllmlllIa  ",
      "   rl       lba ",
      "   l         l  ",
      "  al    W    l  ",
      "  bl         ln ",
      "  am  W X W  ma ",
      "  rl         lb ",
      "   l    W    la ",
      "   l         l  ",
      "  abl       ln  ",
      "   aklllmlllba  ",
      "      abak  a   ",
      "                ",
      "                "
    ],
    [
      "                ",
      "      abaj  a   ",
      "   ajllmlmllba  ",
      "  abl       lg  ",
      "   l         l  ",
      "   l    W    la ",
      "  fm    1    mb ",
      "  al  W0!ZW  la ",
      "  bm    Y    mg ",
      "  al    W    l  ",
      "   l         l  ",
      "   fl       lba ",
      "   abllmlmllca  ",
      "    a  caba     ",
      "                ",
      "                "
    ],
    [
      "                ",
      "     Iaj 2Iba   ",
      "    2lmlllmlg   ",
      "  ajl       l2  ",
      "  bl         ln ",
      "  rm    W    ma ",
      "  2l   333   lg ",
      "   l  W343W  l  ",
      "  fl   333   l2 ",
      "  am    W    mn ",
      "  bl         lb ",
      "   2l       lca ",
      "    flmlllll2   ",
      "    abk2 cak    ",
      "                ",
      "                "
    ],
    [
      "                ",
      "    abbbbbbba   ",
      "   abmlllllmba  ",
      "  abl       lba ",
      "  bm         mb ",
      "  bl         lb ",
      "  bl         lb ",
      "  bl    5    lb ",
      "  bl         lb ",
      "  bl         lb ",
      "  bm         mb ",
      "  abl       lba ",
      "   abmlllllmba  ",
      "    abbbbbbba   ",
      "                ",
      "                "
    ],
    [
      "                ",
      "     6666666    ",
      "    6lllllll6   ",
      "   6m       m6  ",
      "  6l         l6 ",
      "  6l         l6 ",
      "  6l         l6 ",
      "  6l    5    l6 ",
      "  6l         l6 ",
      "  6l         l6 ",
      "  6l         l6 ",
      "   6m       m6  ",
      "    6lllllll6   ",
      "     6666666    ",
      "                ",
      "                "
    ],
    [
      "                ",
      "                ",
      "                ",
      "     lllllll    ",
      "    lmlllllml   ",
      "    llmlllmll   ",
      "    lllmlmlll   ",
      "    llll7llll   ",
      "    lllmlmlll   ",
      "    llmlllmll   ",
      "    lmlllllml   ",
      "     lllllll    ",
      "                ",
      "                ",
      "                ",
      "                "
    ],
    [
      "                ",
      "                ",
      "                ",
      "                ",
      "                ",
      "                ",
      "                ",
      "        8       ",
      "                ",
      "                ",
      "                ",
      "                ",
      "                ",
      "                ",
      "                ",
      "                "
    ]
  ]
}