{
  "name": "building_officebank_top_270",
  "refpalette": "deceasedcraft:building_officebank/building_officebank_top_palette_270",
  "xsize": 16,
  "zsize": 16,
  "slices": [
    [
      "                ",
      "     abag  a    ",
      "  agdddddddba   ",
      " abd  heeeedc   ",
      "  d  eeeeeeed   ",
      "  d eeeeeeeeda  ",
      " jdieeeeeeeedb  ",
      " adeeeeeeeeeda  ",
      " bdeeeeeeeeedc  ",
      " adeeeeeeeeed   ",
      "  deeeeeeeeed   ",
      "  jdeeeeeeedba  ",
      "  abdddddddfa   ",
      "   a  faba      ",
      "                ",
      "                "
    ],
    [
      "                ",
      "    naba  na    ",
      "  a lllllllba   ",
      " abm  y    m    ",
      " Il  yywu   lk  ",
      "  l yyAxsso la  ",
      "  l yBBpppp lb  ",
      " al    t t  la  ",
      " bl         l   ",
      " alF        l   ",
      " Il E       lk  ",
      "   m DC  qqmba  ",
      "  ablllllll a   ",
      "   ar  abar     ",
      "                ",
      "                "
    ],
    [
      "                ",
      "   abag  aba    ",
      "    mlllllmc    ",
      " agl  P    l a  ",
      " bm  PP     mb  ",
      " al PPQON J la  ",
      "  l PBB  MK lc  ",
      "  l         l   ",
      " jl         l   ",
      " al         la  ",
      " bm R       mb  ",
      " a l      Llfa  ",
      "   jmlllllm     ",
      "   aba  faba    ",
      "                ",
      "                "
    ],
    [
      "                ",
      "   aba  naba    ",
      "   Ilmlllml     ",
      " a l       lna  ",
      " bl         lb  ",
      " am         ma  ",
      " Il  VU     l   ",
      "  l         l   ",
      "  l         lk  ",
      " am         ma  ",
      " bl         lb  ",
      " arl     TSl a  ",
      "    lmlllmlk    ",
      "   abar  aba    ",
      "                ",
      "                "
    ],
    [
      "                ",
      "   ag  abag     ",
      "  abllmlmll a   ",
      "   l       lba  ",
      " jl         lc  ",
      " al         l   ",
      " bm         m   ",
      " al         la  ",
      "  m         mb  ",
      "  l         la  ",
      " jl         lc  ",
      " abl       l    ",
      "  a llmlmllba   ",
      "    faba  fa    ",
      "                ",
      "                "
    ],
    [
      "                ",
      "   a  naba      ",
      "  ablllmlllna   ",
      "  Il       lba  ",
      "  l         l   ",
      " al    W    l   ",
      " bl         lk  ",
      " am  W X W  ma  ",
      " Il         lb  ",
      "  l    W    la  ",
      "  l         l   ",
      " abl       lk   ",
      "  arlllmlllba   ",
      "     abar  a    ",
      "                ",
      "                "
    ],
    [
      "                ",
      "     abag  a    ",
      "  agllmlmllba   ",
      " abl       lc   ",
      "  l         l   ",
      "  l    W    la  ",
      " jm    Z    mb  ",
      " al  W1!YW  la  ",
      " bm    0    mc  ",
      " al    W    l   ",
      "  l         l   ",
      "  jl       lba  ",
      "  abllmlmllfa   ",
      "   a  faba      ",
      "                ",
      "                "
    ],
    [
      "                ",
      "    nag 2nba    ",
      "   2lmlllmlc    ",
      " agl       l2   ",
      " bl         lk  ",
      " Im    W    la  ",
      " 2l   333   lc  ",
      "  l  W343W  l   ",
      " jl   333   l2  ",
      " am    W    mk  ",
      " Il         lb  ",
      "  2l       lfa  ",
      "   jlmlllml2    ",
      "   abr2 fab     ",
      "                ",
      "                "
    ],
    [
      "                ",
      "   abbbbbbba    ",
      "  abmlllllmba   ",
      " abl       lba  ",
      " bm         mb  ",
      " bl         lb  ",
      " bl         lb  ",
      " bl    5    lb  ",
      " bl         lb  ",
      " bl         lb  ",
      " bm         mb  ",
      " abl       lba  ",
      "  abmlllllmba   ",
      "   abbbbbbba    ",
      "                ",
      "                "
    ],
    [
      "                ",
      "    6666666     ",
      "   6lllllll6    ",
      "  6m       m6   ",
      " 6l         l6  ",
      " 6l         l6  ",
      " 6l         l6  ",
      " 6l    5    l6  ",
      " 6l         l6  ",
      " 6l         l6  ",
      " 6l         l6  ",
      "  6m       m6   ",
      "   6lllllll6    ",
      "    6666666     ",
      "                ",
      "                "
    ],
    [
      "                ",
      "                ",
      "                ",
      "    lllllll     ",
      "   lmlllllml    ",
      "   llmlllmll    ",
      "   lllmlmlll    ",
      "   llll7llll    ",
      "   lllmlmlll    ",
      "   llmlllmll    ",
      "   lmlllllml    ",
      "    lllllll     ",
      "                ",
      "                ",
      "                ",
      "                "
    ],
    [
      "                ",
      "                ",
      "                ",
      "                ",
      "                ",
      "                ",
      "                ",
      "       8        ",
      "                ",
      "                ",
      "                ",
      "                ",
      "                ",
      "                ",
      "                ",
      "                "
    ]
  ]
}