{
  "name": "building_officebank_floor2",
  "refpalette": "deceasedcraft:building_officebank/building_officebank_floor2_palette",
  "xsize": 16,
  "zsize": 16,
  "slices": [
    [
      "                ",
      "                ",
      "     abac  a    ",
      "  acdddddddba   ",
      " abdeeeeeeedf   ",
      "  deeeeeeeeed   ",
      "  deeeeeeeeeda  ",
      " gdeeeeeeeeedb  ",
      " adeeeeeeeeeda  ",
      " bdheeeeeeeedf  ",
      " ad eeeeeeeed   ",
      "  d  eeeeeeed   ",
      "  gd  ieeeedba  ",
      "  abdddddddja   ",
      "   a  jaba      ",
      "                "
    ],
    [
      "                ",
      "                ",
      "    kaba  ka    ",
      "  a lllllllba   ",
      " abl mn    l    ",
      " olp qnr ns lt  ",
      "  l   u wnxyla  ",
      "  l      u  lb  ",
      " al AB    y!la  ",
      " blCAD    EFl   ",
      " alhA nu wnnl   ",
      " ol  AAA  u lt  ",
      "   l       lba  ",
      "  ablllllll a   ",
      "   aI  abaI     ",
      "                "
    ],
    [
      "                ",
      "                ",
      "   abac  aba    ",
      "    lllllllf    ",
      " acl JK    l a  ",
      " bl   L  MN lb  ",
      " al      O  la  ",
      "  l         lf  ",
      "  l P       l   ",
      " gl P     QRl   ",
      " alCP S   TUla  ",
      " blh PPP    lb  ",
      " a l       lja  ",
      "   glllllll     ",
      "   aba  jaba    ",
      "                "
    ],
    [
      "                ",
      "                ",
      "   aba  kaba    ",
      "   olllllll     ",
      " a l       lka  ",
      " bl         lb  ",
      " al         la  ",
      " ol         l   ",
      "  l P       l   ",
      "  l P       lt  ",
      " al P       la  ",
      " blCePPP    lb  ",
      " aIlV      l a  ",
      "    lllllllt    ",
      "   abaI  aba    ",
      "                "
    ],
    [
      "                ",
      "                ",
      "   ac  abac     ",
      "  ablllllll a   ",
      "   l       lba  ",
      " gl         lf  ",
      " al         l   ",
      " bl         l   ",
      " al P       la  ",
      "  l P       lb  ",
      "  l P       la  ",
      " gl WPPP    lf  ",
      " abliV     l    ",
      "  a lllllllba   ",
      "    jaba  ja    ",
      "                "
    ],
    [
      "                ",
      "                ",
      "   a  kaba      ",
      "  ablllllllka   ",
      "  ol       lba  ",
      "  l         l   ",
      " al         l   ",
      " bl         lt  ",
      " al X       la  ",
      " ol X       lb  ",
      "  l X       la  ",
      "  l  XXX    l   ",
      " abl iVY   lt   ",
      "  aIlllllllba   ",
      "     abaI  a    ",
      "                "
    ]
  ]
}