{
  "name": "building_officebank_base1",
  "refpalette": "deceasedcraft:building_officebank/building_officebank_base1_palette",
  "xsize": 16,
  "zsize": 16,
  "slices": [
    [
      "vvvvvvvvvvvvvvvv",
      "vvvvvvvvvvvvvvvv",
      "vaaaaaaaaaaaaavv",
      "va  a b b a  avv",
      "vac d     e  avv",
      "vaaf       gaavv",
      "va           avv",
      "va          bavv",
      "vaaaaah      avv",
      "va  a  h    bavv",
      "vi  aj a     avv",
      "va  kaaa   laavv",
      "vi     a  m  avv",
      "va     a  a  avv",
      "vaananaaaaaaaavv",
      "vvvvvvvvvvvvvvvv"
    ],
    [
      "vvvvvvvvvvvvvvvv",
      "vvvvvvvvvvvvvvvv",
      "vaaaaaaaaaaaaavv",
      "va  a o o a  avv",
      "va  d     e  avv",
      "vaaf       gaavv",
      "va           avv",
      "va          pavv",
      "vaaaaah      avv",
      "va  a  h    pavv",
      "vqr aj a     avv",
      "va  kaaa   laavv",
      "vqr    a  m  avv",
      "va s s a  a  avv",
      "vaaqaqaaaaaaaavv",
      "vvvvvvvvvvvvvvvv"
    ],
    [
      "vvvvvvvvvvvvvvvv",
      "vvvvvvvvvvvvvvvv",
      "vaaaaaaaaaaaaavv",
      "va  a     a  avv",
      "va  d     e  avv",
      "vaaf       gaavv",
      "va           avv",
      "va           avv",
      "vaaaaah      avv",
      "va  a  h     avv",
      "vi  aj a     avv",
      "va  kaaa   laavv",
      "vi     a  m  avv",
      "va     a  a  avv",
      "vaananaaaaaaaavv",
      "vvvvvvvvvvvvvvvv"
    ],
    [
      "vvvvvvvvvvvvvvvv",
      "vvvvvvvvvvvvvvvv",
      "vaaaaaaaaaaaaavv",
      "va  attttta bavv",
      "va  u     w  avv",
      "vaax       yaavv",
      "vaA         tavv",
      "vaA         tavv",
      "vaaaaahB    tavv",
      "va  a  h    tavv",
      "vqr aj a    tavv",
      "va  kaaa   Caavv",
      "vqD    a  E  avv",
      "va s s aAAa bavv",
      "vaaqaqaaaaaaaavv",
      "vvvvvvvvvvvvvvvv"
    ],
    [
      "vvvvvvvvvvvvvvvv",
      "vvvvvvvvvvvvvvvv",
      "vaaaaaaaaaaaaavv",
      "vaFFaFFFFFaFFavv",
      "vaFFFFFFFFFFFavv",
      "vaaFFFFFFFFFaavv",
      "vaFFFFFFFFFFFavv",
      "vaFFFFFFFFFFFavv",
      "vaaaaaaaFFFFFavv",
      "vaIIa  aFFFFFavv",
      "vaIIaj aFFFFFavv",
      "vaIIJaaaFFFFaavv",
      "vaIIIIIaFFFFFavv",
      "vaIIIIIaFFaFFavv",
      "vaaaaaaaaaaaaavv",
      "vvvvvvvvvvvvvvvv"
    ],
    [
      "vvvvvvvvvvvvvvvv",
      "vvvvvvvvvvvvvvvv",
      "vaaaaaaaaaaaaavv",
      "vaaaaaaaaaaaaavv",
      "vaaaaaaaaaaaaavv",
      "vaaaaaaaaaaaaavv",
      "vaaaaaaaaaaaaavv",
      "vaaaaaaaaaaaaavv",
      "vaaaaaaaaaaaaavv",
      "vaaaa  aaaaaaavv",
      "vaaaaj aaaaaaavv",
      "vaaaaaaaaaaaaavv",
      "vaaaaaaaaaaaaavv",
      "vaaaaaaaaaaaaavv",
      "vaaaaaaaaaaaaavv",
      "vvvvvvvvvvvvvvvv"
    ]
  ]
}