{
  "name": "building_officebank_top",
  "refpalette": "deceasedcraft:building_officebank/building_officebank_top_palette",
  "xsize": 16,
  "zsize": 16,
  "slices": [
    [
      "                ",
      "                ",
      "     abac  a    ",
      "  acdddddddba   ",
      " abdeeeeeeedf   ",
      "  deeeeeeeeed   ",
      "  deeeeeeeeeda  ",
      " gdeeeeeeeeedb  ",
      " adeeeeeeeeeda  ",
      " bdheeeeeeeedf  ",
      " ad eeeeeeeed   ",
      "  d  eeeeeeed   ",
      "  gd  ieeeedba  ",
      "  abdddddddja   ",
      "   a  jaba      ",
      "                "
    ],
    [
      "                ",
      "                ",
      "    kaba  ka    ",
      "  a lllllllba   ",
      " abm       m    ",
      " nl  op    qlr  ",
      "  l  spt   qla  ",
      "  l usp     lb  ",
      " al wxpt    la  ",
      " blyyAB    Cl   ",
      " al yyB    Dl   ",
      " nl  yy   E lr  ",
      "   m     F mba  ",
      "  ablllllll a   ",
      "   aI  abaI     ",
      "                "
    ],
    [
      "                ",
      "                ",
      "   abac  aba    ",
      "    mlllllmf    ",
      " acl       l a  ",
      " bm  JK    Lmb  ",
      " al   M     la  ",
      "  l  N      lf  ",
      "  l  O      l   ",
      " glPPQB     l   ",
      " al PPB     la  ",
      " bm  PP   R mb  ",
      " a l       lja  ",
      "   gmlllllm     ",
      "   aba  jaba    ",
      "                "
    ],
    [
      "                ",
      "                ",
      "   aba  kaba    ",
      "   nlmlllml     ",
      " a l       lka  ",
      " bl        Slb  ",
      " am        Tma  ",
      " nl         l   ",
      "  l         l   ",
      "  l   U     lr  ",
      " am   V     ma  ",
      " bl         lb  ",
      " aIl       l a  ",
      "    lmlllmlr    ",
      "   abaI  aba    ",
      "                "
    ],
    [
      "                ",
      "                ",
      "   ac  abac     ",
      "  abllmlmll a   ",
      "   l       lba  ",
      " gl         lf  ",
      " al         l   ",
      " bm         m   ",
      " al         la  ",
      "  m         mb  ",
      "  l         la  ",
      " gl         lf  ",
      " abl       l    ",
      "  a llmlmllba   ",
      "    jaba  ja    ",
      "                "
    ],
    [
      "                ",
      "                ",
      "   a  kaba      ",
      "  ablllmlllka   ",
      "  nl       lba  ",
      "  l         l   ",
      " al    W    l   ",
      " bl         lr  ",
      " am  W X W  ma  ",
      " nl         lb  ",
      "  l    W    la  ",
      "  l         l   ",
      " abl       lr   ",
      "  aIlllmlllba   ",
      "     abaI  a    ",
      "                "
    ],
    [
      "                ",
      "                ",
      "     abac  a    ",
      "  acllmlmllba   ",
      " abl       lf   ",
      "  l         l   ",
      "  l    W    la  ",
      " gm    Y    mb  ",
      " al  WZ!0W  la  ",
      " bm    1    mf  ",
      " al    W    l   ",
      "  l         l   ",
      "  gl       lba  ",
      "  abllmlmllja   ",
      "   a  jaba      ",
      "                "
    ],
    [
      "                ",
      "                ",
      "    kac 2kba    ",
      "   2lllllmlf    ",
      " acl       l2   ",
      " bl         lb  ",
      " nm    W    ma  ",
      " 2l   333   lf  ",
      "  l  W343W  l   ",
      " gl   333   l2  ",
      " am    W    mr  ",
      " nl         lb  ",
      "  2l       lja  ",
      "   glmlllml2    ",
      "   abI2 jaI     ",
      "                "
    ],
    [
      "                ",
      "                ",
      "   abbbbbbba    ",
      "  abmlllllmba   ",
      " abl       lba  ",
      " bm         mb  ",
      " bl         lb  ",
      " bl         lb  ",
      " bl    5    lb  ",
      " bl         lb  ",
      " bl         lb  ",
      " bm         mb  ",
      " abl       lba  ",
      "  abmlllllmba   ",
      "   abbbbbbba    ",
      "                "
    ],
    [
      "                ",
      "                ",
      "    6666666     ",
      "   6lllllll6    ",
      "  6m       m6   ",
      " 6l         l6  ",
      " 6l         l6  ",
      " 6l         l6  ",
      " 6l    5    l6  ",
      " 6l         l6  ",
      " 6l         l6  ",
      " 6l         l6  ",
      "  6m       m6   ",
      "   6lllllll6    ",
      "    6666666     ",
      "                "
    ],
    [
      "                ",
      "                ",
      "                ",
      "                ",
      "    lllllll     ",
      "   lmlllllml    ",
      "   llmlllmll    ",
      "   lllmlmlll    ",
      "   llll7llll    ",
      "   lllmlmlll    ",
      "   llmlllmll    ",
      "   lmlllllml    ",
      "    lllllll     ",
      "                ",
      "                ",
      "                "
    ],
    [
      "                ",
      "                ",
      "                ",
      "                ",
      "                ",
      "                ",
      "                ",
      "                ",
      "       8        ",
      "                ",
      "                ",
      "                ",
      "                ",
      "                ",
      "                ",
      "                "
    ]
  ]
}