{
  "name": "building_officebank_floor2_180",
  "refpalette": "deceasedcraft:building_officebank/building_officebank_floor2_palette_180",
  "xsize": 16,
  "zsize": 16,
  "slices": [
    [
      "                ",
      "      abaj  a   ",
      "   ajdddddddba  ",
      "  abdeeeei  dg  ",
      "   deeeeeee  d  ",
      "   deeeeeeee da ",
      "  fdeeeeeeeehdb ",
      "  adeeeeeeeeeda ",
      "  bdeeeeeeeeedg ",
      "  adeeeeeeeeed  ",
      "   deeeeeeeeed  ",
      "   fdeeeeeeedba ",
      "   abdddddddca  ",
      "    a  caba     ",
      "                ",
      "                "
    ],
    [
      "                ",
      "     Iaba  Ia   ",
      "   a lllllllba  ",
      "  abl       l   ",
      "  tl u  AAA  lo ",
      "   lnnw un Ahla ",
      "   lFE    DAClb ",
      "  al!y    BA la ",
      "  bl  u      l  ",
      "  alyxnw u   l  ",
      "  tl sn rnq plo ",
      "    l    nm lba ",
      "   ablllllll a  ",
      "    ak  abak    ",
      "                ",
      "                "
    ],
    [
      "                ",
      "    abaj  aba   ",
      "     lllllllg   ",
      "  ajl       l a ",
      "  bl    PPP hlb ",
      "  alUT   S PCla ",
      "   lRQ     P lg ",
      "   l       P l  ",
      "  fl         l  ",
      "  al  O      la ",
      "  bl NM  L   lb ",
      "  a l    KJ lca ",
      "    flllllll    ",
      "    aba  caba   ",
      "                ",
      "                "
    ],
    [
      "                ",
      "    aba  Iaba   ",
      "    tlllllll    ",
      "  a l      VlIa ",
      "  bl    PPPeClb ",
      "  al       P la ",
      "  tl       P l  ",
      "   l       P l  ",
      "   l         lo ",
      "  al         la ",
      "  bl         lb ",
      "  akl       l a ",
      "     lllllllo   ",
      "    abak  aba   ",
      "                ",
      "                "
    ],
    [
      "                ",
      "    aj  abaj    ",
      "   ablllllll a  ",
      "    l     Vilba ",
      "  fl    PPPW lg ",
      "  al       P l  ",
      "  bl       P l  ",
      "  al       P la ",
      "   l         lb ",
      "   l         la ",
      "  fl         lg ",
      "  abl       l   ",
      "   a lllllllba  ",
      "     caba  ca   ",
      "                ",
      "                "
    ],
    [
      "                ",
      "    a  Iaba     ",
      "   ablllllllIa  ",
      "   tl   YVi lba ",
      "   l    XXX  l  ",
      "  al       X l  ",
      "  bl       X lo ",
      "  al       X la ",
      "  tl         lb ",
      "   l         la ",
      "   l         l  ",
      "  abl       lo  ",
      "   aklllllllba  ",
      "      abak  a   ",
      "                ",
      "                "
    ]
  ]
}