{
  "name": "building_officebank_floor3",
  "refpalette": "deceasedcraft:building_officebank/building_officebank_floor3_palette",
  "xsize": 16,
  "zsize": 16,
  "slices": [
    [
      "                ",
      "                ",
      "     abac  a    ",
      "  acdddddddba   ",
      " abdeeeeeeedf   ",
      "  deeeeeeeeed   ",
      "  deeeeeeeeeda  ",
      " gdeeeeeeeeedb  ",
      " adeeeeeeeeeda  ",
      " bdheeeeeeeedf  ",
      " ad eeeeeeeed   ",
      "  d  eeeeeeed   ",
      "  gd  ieeeedba  ",
      "  abdddddddja   ",
      "   a  jaba      ",
      "                "
    ],
    [
      "                ",
      "                ",
      "    kaba  ka    ",
      "  a lllllllba   ",
      " abl mn   ol    ",
      " pl qrns nt lu  ",
      "  l   w xnyAla  ",
      "  l      w  lb  ",
      " al BC    A la  ",
      " blDBE    FIl   ",
      " alhB nw xnnl   ",
      " pl  BBB  w lu  ",
      "   l       lba  ",
      "  ablllllll a   ",
      "   aJ  abaJ     ",
      "                "
    ],
    [
      "                ",
      "                ",
      "   abac  aba    ",
      "    lllllllf    ",
      " acl KL    l a  ",
      " bl  MN   O lb  ",
      " al      PQ la  ",
      "  l         lf  ",
      "  l R       l   ",
      " gl R     STl   ",
      " alDR U    Vla  ",
      " blh!RRR    lb  ",
      " a l       lja  ",
      "   glllllll     ",
      "   aba  jaba    ",
      "                "
    ],
    [
      "                ",
      "                ",
      "   aba  kaba    ",
      "   plllllll     ",
      " a l       lka  ",
      " bl         lb  ",
      " al         la  ",
      " pl         l   ",
      "  l R       l   ",
      "  l R       lu  ",
      " al R       la  ",
      " blDeRRR    lb  ",
      " aJlW      l a  ",
      "    lllllllu    ",
      "   abaJ  aba    ",
      "                "
    ],
    [
      "                ",
      "                ",
      "   ac  abac     ",
      "  ablllllll a   ",
      "   l       lba  ",
      " gl         lf  ",
      " al         l   ",
      " bl         l   ",
      " al R       la  ",
      "  l R       lb  ",
      "  l R       la  ",
      " gl XRRR    lf  ",
      " abliW     l    ",
      "  a lllllllba   ",
      "    jaba  ja    ",
      "                "
    ],
    [
      "                ",
      "                ",
      "   a  kaba      ",
      "  ablllllllka   ",
      "  pl       lba  ",
      "  l         l   ",
      " al         l   ",
      " bl         lu  ",
      " al Y       la  ",
      " pl Y       lb  ",
      "  l Y       la  ",
      "  l  YYY    l   ",
      " abl iWZ   lu   ",
      "  aJlllllllba   ",
      "     abaJ  a    ",
      "                "
    ]
  ]
}