{
  "name": "building_officebank_top_90",
  "refpalette": "deceasedcraft:building_officebank/building_officebank_top_palette_90",
  "xsize": 16,
  "zsize": 16,
  "slices": [
    [
      "                ",
      "                ",
      "      abaf  a   ",
      "   afdddddddba  ",
      "  abdeeeeeeedj  ",
      "   deeeeeeeeed  ",
      "   deeeeeeeeeda ",
      "  cdeeeeeeeeedb ",
      "  adeeeeeeeeeda ",
      "  bdeeeeeeeeidj ",
      "  adeeeeeeee d  ",
      "   deeeeeee  d  ",
      "   cdeeeeh  dba ",
      "   abdddddddga  ",
      "    a  gaba     ",
      "                "
    ],
    [
      "                ",
      "                ",
      "     raba  ra   ",
      "   a lllllllba  ",
      "  abmqq  CD m   ",
      "  kl       E lI ",
      "   l        Fla ",
      "   l         lb ",
      "  al  t t    la ",
      "  bl ppppBBy l  ",
      "  al ossxAyy l  ",
      "  kl   uwyy  lI ",
      "    m    y  mba ",
      "   ablllllll a  ",
      "    an  aban    ",
      "                "
    ],
    [
      "                ",
      "                ",
      "    abaf  aba   ",
      "     mlllllmj   ",
      "  aflL      l a ",
      "  bm       R mb ",
      "  al         la ",
      "   l         lj ",
      "   l         l  ",
      "  cl KM  BBP l  ",
      "  al J NOQPP la ",
      "  bm     PP  mb ",
      "  a l    P  lga ",
      "    cmlllllm    ",
      "    aba  gaba   ",
      "                "
    ],
    [
      "                ",
      "                ",
      "    aba  raba   ",
      "    klmlllml    ",
      "  a lST     lra ",
      "  bl         lb ",
      "  am         ma ",
      "  kl         l  ",
      "   l         l  ",
      "   l     UV  lI ",
      "  am         ma ",
      "  bl         lb ",
      "  anl       l a ",
      "     lmlllmlI   ",
      "    aban  aba   ",
      "                "
    ],
    [
      "                ",
      "                ",
      "    af  abaf    ",
      "   abllmlmll a  ",
      "    l       lba ",
      "  cl         lj ",
      "  al         l  ",
      "  bm         m  ",
      "  al         la ",
      "   m         mb ",
      "   l         la ",
      "  cl         lj ",
      "  abl       l   ",
      "   a llmlmllba  ",
      "     gaba  ga   ",
      "                "
    ],
    [
      "                ",
      "                ",
      "    a  raba     ",
      "   ablllmlllra  ",
      "   kl       lba ",
      "   l         l  ",
      "  al    W    l  ",
      "  bl         lI ",
      "  am  W X W  ma ",
      "  kl         lb ",
      "   l    W    la ",
      "   l         l  ",
      "  abl       lI  ",
      "   anlllmlllba  ",
      "      aban  a   ",
      "                "
    ],
    [
      "                ",
      "                ",
      "      abaf  a   ",
      "   afllmlmllba  ",
      "  abl       lj  ",
      "   l         l  ",
      "   l    W    la ",
      "  cm    0    mb ",
      "  al  WY!1W  la ",
      "  bm    Z    mj ",
      "  al    W    l  ",
      "   l         l  ",
      "   cl       lba ",
      "   abllmlmllga  ",
      "    a  gaba     ",
      "                "
    ],
    [
      "                ",
      "                ",
      "     baf 2rba   ",
      "    2lmlllmlj   ",
      "  afl       l2  ",
      "  bl         lI ",
      "  km    W    ma ",
      "  2l   333   lj ",
      "   l  W343W  l  ",
      "  cl   333   l2 ",
      "  al    W    mI ",
      "  kl         lb ",
      "   2l       lga ",
      "    clmlllml2   ",
      "    abn2 gan    ",
      "                "
    ],
    [
      "                ",
      "                ",
      "    abbbbbbba   ",
      "   abmlllllmba  ",
      "  abl       lba ",
      "  bm         mb ",
      "  bl         lb ",
      "  bl         lb ",
      "  bl    5    lb ",
      "  bl         lb ",
      "  bl         lb ",
      "  bm         mb ",
      "  abl       lba ",
      "   abmlllllmba  ",
      "    abbbbbbba   ",
      "                "
    ],
    [
      "                ",
      "                ",
      "     6666666    ",
      "    6lllllll6   ",
      "   6m       m6  ",
      "  6l         l6 ",
      "  6l         l6 ",
      "  6l         l6 ",
      "  6l    5    l6 ",
      "  6l         l6 ",
      "  6l         l6 ",
      "  6l         l6 ",
      "   6m       m6  ",
      "    6lllllll6   ",
      "     6666666    ",
      "                "
    ],
    [
      "                ",
      "                ",
      "                ",
      "                ",
      "     lllllll    ",
      "    lmlllllml   ",
      "    llmlllmll   ",
      "    lllmlmlll   ",
      "    llll7llll   ",
      "    lllmlmlll   ",
      "    llmlllmll   ",
      "    lmlllllml   ",
      "     lllllll    ",
      "                ",
      "                ",
      "                "
    ],
    [
      "                ",
      "                ",
      "                ",
      "                ",
      "                ",
      "                ",
      "                ",
      "                ",
      "        8       ",
      "                ",
      "                ",
      "                ",
      "                ",
      "                ",
      "                ",
      "                "
    ]
  ]
}