{
  "name": "building_officebank_floor1",
  "refpalette": "deceasedcraft:building_officebank/building_officebank_floor1_palette",
  "xsize": 16,
  "zsize": 16,
  "slices": [
    [
      "                ",
      "                ",
      "     abac  a    ",
      "  acdddddddba   ",
      " abdeeeeeeedf   ",
      "  deeeeeeeeed   ",
      "  deeeeeeeeeda  ",
      " gdeeeeeeeeedb  ",
      " adeehhheeeeda  ",
      " bdihhhheeeedf  ",
      " ad hjhheeeed   ",
      "  d  hheeeeed   ",
      "  gd  keeeedba  ",
      "  abdddddddla   ",
      "   a  laba      ",
      "                "
    ],
    [
      "                ",
      "                ",
      "    maba  ma    ",
      "  a nnnnnnnba   ",
      " abn  opq  n    ",
      " rnhshthth  nu  ",
      "  n   w w hxna  ",
      "  n      wyqnb  ",
      " anAAhB   hCna  ",
      " bnDh  E wyqn   ",
      " anih  h  hxn   ",
      " rn  hh   yqnu  ",
      "   n     whnba  ",
      "  abnnnnnnn a   ",
      "   aF  abaF     ",
      "                "
    ],
    [
      "                ",
      "                ",
      "   abac  aba    ",
      "    nnnnnnnf    ",
      " acn       n a  ",
      " bnh hIhJh  nb  ",
      " an       h na  ",
      "  n       K nf  ",
      "  n  hL   h n   ",
      " gn h  M  N n   ",
      " anDh  h  h na  ",
      " bni hh   K nb  ",
      " a n      hnla  ",
      "   gnnnnnnn     ",
      "   aba  laba    ",
      "                "
    ],
    [
      "                ",
      "                ",
      "   aba  maba    ",
      "   rnnnnnnn     ",
      " a n       nma  ",
      " bnh hOhOh  nb  ",
      " an       h na  ",
      " rn       P n   ",
      "  n  hh   h n   ",
      "  n h  h  P nu  ",
      " an h  h  h na  ",
      " bnDehh   Q nb  ",
      " aFnR     hn a  ",
      "    nnnnnnnu    ",
      "   abaF  aba    ",
      "                "
    ],
    [
      "                ",
      "                ",
      "   ac  abac     ",
      "  abnnnnnnn a   ",
      "   n       nba  ",
      " gnhhhhhhh  nf  ",
      " an       h n   ",
      " bn       h n   ",
      " an  hh   h na  ",
      "  n h  h  h nb  ",
      "  n h  h  h na  ",
      " gn Ahh   h nf  ",
      " abnkR    hn    ",
      "  a nnnnnnnba   ",
      "    laba  la    ",
      "                "
    ],
    [
      "                ",
      "                ",
      "   a  maba      ",
      "  abnnnnnnnma   ",
      "  rn       nba  ",
      "  nhhhhhhh! n   ",
      " anSSSSSSSh n   ",
      " bnSSSSSSSh nu  ",
      " anTThhUSSh na  ",
      " rn h  hSSh nb  ",
      "  n h  hSSh na  ",
      "  n  hhTSSh n   ",
      " abn kRTSShnu   ",
      "  aFnnnnnnnba   ",
      "     abaF  a    ",
      "                "
    ]
  ]
}