{
  "name": "building_officebank_ground_180",
  "refpalette": "deceasedcraft:building_officebank/building_officebank_ground_palette_180",
  "xsize": 16,
  "zsize": 16,
  "slices": [
    [
      "aaaaaaaaaaaaaaaa",
      "aaabbbbbbbbbbbaa",
      "aabbbdddddddbbba",
      "aabbdbbbbbbbdbba",
      "aabdhhhhfff!bdba",
      "aabdhhhhf gfbdba",
      "aabdfffff  fddba",
      "aabddddddffeedba",
      "aabdddddddddddba",
      "aabdddddddddddba",
      "aabdddddddddddba",
      "aabcdddddddddbba",
      "abcccdddddddbbba",
      "bcccbbbbbbbbbbaa",
      "cccbaaaaaaaaaaaa",
      "ccbaaaaaaaaaaaaa"
    ],
    [
      "     k     k    ",
      "   iijiiiiijii  ",
      "  ii lllllll ii ",
      "  i lFFFFFFFl i ",
      " polE  Dfff  lpo",
      "  ilC  Bf gfAli ",
      "  ilfyfff  fxli ",
      "  il    sff  li ",
      "  ilw   s    li ",
      "  ilu  tsr   li ",
      " polq   f    lpo",
      "  i nm      l i ",
      " i   lllllll ii ",
      "i   ikiiiiikii  ",
      "   i j     j    ",
      "  i             "
    ],
    [
      "     k     k    ",
      "    IJI   IJI   ",
      "     lllllll    ",
      "  I l       l I ",
      " pJlQ   fff AlJo",
      "  IlP   f gfxlI ",
      "   lfOfff  f l  ",
      "   l    Nff  l  ",
      "   l    M    l  ",
      "  Il         lI ",
      " pJlL        lJo",
      "  I  K      l I ",
      "     lllllll    ",
      "    IJI   IJI   ",
      "     j     j    ",
      "                "
    ],
    [
      "     k     k    ",
      "    IJIS RIJI   ",
      "    VlllllllV   ",
      "  ISl      0lRI ",
      " pJlZ   fffexlJo",
      "  IlY   f gf lI ",
      "  VlfXfff Wf lV ",
      "   l     ff  l  ",
      "  Tl         lT ",
      "  Il         lI ",
      " pJl         lJo",
      "  ISU       lRI ",
      "    TlllllllT   ",
      "    IJIS RIJI   ",
      "     j     j    ",
      "                "
    ],
    [
      "                ",
      "    IJIJIJIJI   ",
      "   IJlllllllJI  ",
      "  IJl     04lJI ",
      "  Jl3   fff2 lJ ",
      "  Il1   f gf lI ",
      "  JlfffffWWf lJ ",
      "  Il     ff  lI ",
      "  Jl         lJ ",
      "  Il         lI ",
      "  Jl         lJ ",
      "  IJl       lJI ",
      "   IJlllllllJI  ",
      "    IJIJIJIJI   ",
      "                ",
      "                "
    ],
    [
      "                ",
      "    I5 JIJI5    ",
      "   IJlllllllJI  ",
      "   Jl777904 lJI ",
      "  5l8777fff  l5 ",
      "  Il8777fWgf l  ",
      "  Jlfffff! f lJ ",
      "  Il    6ff  lI ",
      "  Jl         lJ ",
      "   l         lI ",
      "  5l         l5 ",
      "  IJl       lJ  ",
      "   IJlllllllJI  ",
      "     5IJIJ 5I   ",
      "                ",
      "                "
    ]
  ]
}