{
  "name": "multi_sunkenmonumentpark_5_base1",
  "refpalette": "deceasedcraft:multi_sunkenmonumentpark_5/multi_sunkenmonumentpark_5_base1_palette",
  "xsize": 16,
  "zsize": 16,
  "slices": [
    [
      "aaaaaaaaaaaaaaaa",
      "aaaaaaaaaaaaaaaa",
      "aaaaaaaaaaaaaaaa",
      "aaaaaaaaaaaaaaaa",
      "aaaaaaaaaaaaaaaa",
      "aaaaaaaaaaaaaaaa",
      "aaaaaaaaaaaaaaaa",
      "aaaaaaaaaaaaaaaa",
      "aaaaaaaaaaaaabbb",
      "aaaaaaaaaaabbbbb",
      "aaaaaaaaaabbbbbb",
      "aaaaaaaaabbbbbbb",
      "aaaaaaaaabbbbbbb",
      "aaaaaaaabbbbbbbb",
      "aaaaaaaabbbbbbbb",
      "aaaaaaaabbbbbbbb"
    ],
    [
      "aaaaaaaaaaaabbbb",
      "aaaaaaaaabbbcccc",
      "aaaaaaabbccccdcc",
      "aaaaaabccccccccc",
      "aaaaabccdccccccc",
      "aaaabccccccccccc",
      "aaabcccccccccccc",
      "aabcccccccccc===",
      "aabc!cccccc==eee",
      "abcccccccc=eeeee",
      "abccccccc=eeeeff",
      "abcccccc=eeeffff",
      "bccccccc=eefffff",
      "bcdcccc=eeefffff",
      "bcccccc=eeffffff",
      "bcccccc=eeffffff"
    ],
    [
      "aggggggggggghhii",
      "ggggggggghhh  jj",
      "ggggggghh    k  ",
      "ggggggh   lm    ",
      "gggggh  k       ",
      "ggggh           ",
      "gggh            ",
      "ggh          nnn",
      "ggh k      nn   ",
      "gh        n     ",
      "gh o     n    ff",
      "gh p    n   ffff",
      "h       n  fffff",
      "h k    n   fffff",
      "qj     n  ffffff",
      "qj     n  ffffff"
    ],
    [
      "ghh  rs         ",
      "hs              ",
      "h t t        u  ",
      "                ",
      "  ts    u       ",
      " rs             ",
      " s              ",
      "                ",
      "s   u           ",
      "                ",
      "              ff",
      "            ffff",
      "           fffff",
      "  u        fffff",
      "          ffffff",
      "          ffffff"
    ],
    [
      "     w          ",
      "                ",
      "  u u        x  ",
      "                ",
      "  u     x       ",
      " w              ",
      "                ",
      "                ",
      "    x           ",
      "                ",
      "              yy",
      "            yyyy",
      "           yyyAA",
      "  x        yyAAA",
      "          yyAAAA",
      "          yyAAAA"
    ],
    [
      "     u          ",
      "                ",
      "  x x        x  ",
      "                ",
      "  x     x       ",
      " u              ",
      "                ",
      "                ",
      "    x           ",
      "                ",
      "                ",
      "              B ",
      "            B   ",
      "  x          b  ",
      "           B    ",
      "                "
    ]
  ]
}