{
  "name": "multi_sunkenmonumentpark_5_ground",
  "refpalette": "deceasedcraft:multi_sunkenmonumentpark_5/multi_sunkenmonumentpark_5_ground_palette",
  "xsize": 16,
  "zsize": 16,
  "slices": [
    [
      "     a          ",
      "                ",
      "  a a           ",
      "                ",
      "  a             ",
      " a              ",
      "                ",
      "                ",
      "                ",
      "                ",
      "                ",
      "                ",
      "                ",
      "             b  ",
      "                ",
      "                "
    ],
    [
      "     a ccccccccc",
      "       ccccccccc",
      "  a d cccccc e  ",
      "     ccccc      ",
      "  d ccccf       ",
      " a cccc         ",
      "  cccc          ",
      "ccccc           ",
      "ccccg           ",
      "cccc            ",
      "ccc             ",
      "ccc             ",
      "cc              ",
      "ccf          hii",
      "cc           ijj",
      "cc           ijj"
    ],
    [
      "     d kllllllll",
      "       kllllllll",
      "  d   klllllkkkk",
      "     kllllkk    ",
      "    klllkk      ",
      " d klllk        ",
      "  klllk         ",
      "kklllk          ",
      "llllk           ",
      "llllk           ",
      "lllk            ",
      "lllk            ",
      "llk             ",
      "llk          hhh",
      "llk          bjj",
      "llk          h m"
    ],
    [
      "       n        ",
      "       o        ",
      "      n     pppp",
      "     n    pq    ",
      "    n   pq      ",
      "   n   q        ",
      "  n   q         ",
      "nr   q          ",
      "    s           ",
      "    q           ",
      "   s            ",
      "   q            ",
      "  s             ",
      "  s          btt",
      "  s          ujj",
      "  s          uwm"
    ],
    [
      "                ",
      "                ",
      "                ",
      "                ",
      "                ",
      "                ",
      "                ",
      "                ",
      "                ",
      "                ",
      "                ",
      "                ",
      "                ",
      "             bxx",
      "              jj",
      "           y  wm"
    ],
    [
      "                ",
      "                ",
      "                ",
      "                ",
      "                ",
      "                ",
      "                ",
      "                ",
      "                ",
      "                ",
      "                ",
      "                ",
      "                ",
      "             hxx",
      "              jj",
      "           mmABm"
    ]
  ]
}