{
  "name": "multi_thering_11_floor16",
  "refpalette": "deceasedcraft:multi_thering_11/multi_thering_11_floor16_palette",
  "xsize": 16,
  "zsize": 16,
  "slices": [
    [
      "abbbbbbbbbbbbbbb",
      "cccccccccccccccc",
      "cccccccccccccccc",
      "cccccccccccccccc",
      "cccccccccccccccc",
      "cccccccccccccccc",
      "cccccccccccccccc",
      "cccccccccccccccc",
      "bbbbbbbbbbbbbbbb",
      "                ",
      "                ",
      "                ",
      "                ",
      "                ",
      "                ",
      "                "
    ],
    [
      "dddddddddddddddd",
      "dddddddddddddddd",
      "dddddddddddddddd",
      "dddddddddddddddd",
      "dddddddddddddddd",
      "dddddddddddddddd",
      "dddddddddddddddd",
      "dddddddddddddddd",
      "dddddddddddddddd",
      "eeeeeeeeeeeeeeee",
      "                ",
      "                ",
      "                ",
      "                ",
      "                ",
      "                "
    ],
    [
      "ddddddddddfdddd!",
      "ddddddddddgggggg",
      "fddddfddddgggggg",
      "hddddhdddigggggg",
      "gggggggggggggggg",
      "gggggggggggggggg",
      "jggggggggggggggg",
      "gggggggggggggggg",
      "kkkkkkkkkkkkkkkk",
      "                ",
      "                ",
      "                ",
      "                ",
      "                ",
      "                ",
      "                "
    ],
    [
      "dddddddddddddddd",
      "llllllllligggggg",
      "mmmmmmmmlggggggg",
      "mmmmmmmmlggggggg",
      "gggggggggggggggg",
      "gggggggggggggggg",
      "jggggggggggggggg",
      "gggggggggggggggg",
      "kkkkkkkkkkkkkkkk",
      "                ",
      "                ",
      "                ",
      "                ",
      "                ",
      "                ",
      "                "
    ],
    [
      "annnnonnnnonnnno",
      "                ",
      "pq pq pq        ",
      "                ",
      "                ",
      "                ",
      "                ",
      "                ",
      "                ",
      "                ",
      "                ",
      "                ",
      "                ",
      "                ",
      "                ",
      "                "
    ],
    [
      "a               ",
      "                ",
      "r  s  t         ",
      "                ",
      "                ",
      "                ",
      "                ",
      "                ",
      "                ",
      "                ",
      "                ",
      "                ",
      "                ",
      "                ",
      "                ",
      "                "
    ]
  ]
}