{
  "name": "multi_thering_11_base2",
  "refpalette": "deceasedcraft:multi_thering_11/multi_thering_11_base2_palette",
  "xsize": 16,
  "zsize": 16,
  "slices": [
    [
      "abbbbbbbbbbbbbba",
      "bbbbbbbbbbbbbbbb",
      "bbbbbbbbbbbbbbbb",
      "bbbbbbbbbbbbbbbb",
      "bbbbbbbbbbbbbbbb",
      "bbbbbbbbbbbbbbbb",
      "bbbbbbbbbbbbbbbb",
      "bbbbbbbbbbbbbbbb",
      "bbbbbbbbbbbbbbbb",
      "bbbbbbbbbbbbbbbb",
      "bbbbbbbbbbbbbbbb",
      "bbbbbbbbbbbbbbbb",
      "bbbbbbbbbbbbbbbb",
      "bbbbbbbbbbbbbbbb",
      "bbbbbbbbbbbbbbbb",
      "bbbbbbbbbbbbbbbb"
    ],
    [
      "abbbbbbbbbbbbbba",
      "bbbbbbbbbbbbbbbb",
      "bbbbbbbbbbbbbbbb",
      "bbbbbbbbbbbbbbbb",
      "bbbbbbbbbbbbbbbb",
      "bbbbbbbbbbbbbbbb",
      "bbbbbbbbbbbbbbbb",
      "bbbbbbbbbbbbbbbb",
      "bbbbbbbbbbbbbbbb",
      "bbbbbbbbbbbbbbbb",
      "bbbbbbbbbbbbbbbb",
      "bbbbbbbbbbbbbbbb",
      "bbbbbbbbbbbbbbbb",
      "bbbbbbbbbbbbbbbb",
      "bbbbbbbbbbbbbbbb",
      "bbbbbbbbbbbbbbbb"
    ],
    [
      "acccccccccccccca",
      "cccccccccccccccc",
      "cccccccccccccccc",
      "cccccccccccccccc",
      "cccccccccccccccc",
      "cccccccccccccccc",
      "cccccccccccccccc",
      "cccccccccccccccc",
      "cccccccccccccccc",
      "cccccccccccccccc",
      "cccccccccccccccc",
      "cccccccccccccccc",
      "cccccccccccccccc",
      "cccccccccccccccc",
      "cccccccccccccccc",
      "cccccccccccccccc"
    ],
    [
      "deeeeeeeeeeeeeed",
      "effffffffffffffe",
      "effffffffffffffe",
      "effffffffffffffe",
      "effffffffffffffe",
      "effffffffffffffe",
      "effffffffffffffe",
      "effffffffffffffe",
      "effffffffffffffe",
      "effffffffffffffe",
      "effffffffffffffe",
      "effffffffffffffe",
      "effffffffffffffe",
      "effffffffffffffe",
      "effffffffffffffe",
      "effffffffffffffe"
    ],
    [
      "g              g",
      "h              h",
      "h              h",
      "h              h",
      "                ",
      "                ",
      "                ",
      "                ",
      "                ",
      "h              h",
      "hijk        ijkh",
      "h              h",
      "hlll        lllh",
      "h              h",
      "hmno        mnoh",
      "hhhh        hhhh"
    ],
    [
      "g              g",
      "p              p",
      "p              p",
      "p              p",
      "                ",
      "                ",
      "                ",
      "                ",
      "                ",
      "p              p",
      "p              p",
      "p              p",
      "p              p",
      "p              p",
      "p              p",
      "pppp        pppp"
    ]
  ]
}