{
  "name": "multi_oasiscondo_5_base1",
  "refpalette": "deceasedcraft:multi_oasiscondo_5/multi_oasiscondo_5_base1_palette",
  "xsize": 16,
  "zsize": 16,
  "slices": [
    [
      "aabHHHHHHHHbHHHH",
      "aaavvvvvvvvvvvvv",
      "babccccccccbdddd",
      "aaaaaaaaaaaefg  ",
      "HHHHHHHHHaaehij ",
      "HHHHHHHHHHaeklll",
      "HHHHHHHHHHaeffff",
      "HHHHHHHHHHaeffff",
      "HHHHHHHHHHaeffff",
      "aaaaaHHHHHaeffff",
      "aaaaaaHHHHaeffff",
      "babaaaHHHHabmfff",
      "avHHHHHHHHanffff",
      "avHHHHHHHHanffff",
      "ovHHHHHHHHanffff",
      "pvHHHHHHHHanffff"
    ],
    [
      "  bq  rq  rbq  r",
      "  svvvvvvvvvvvvv",
      "b b        btttt",
      "           u    ",
      "           w x  ",
      "           w  jj",
      "           uy   ",
      "           u    ",
      "           wA   ",
      "           wA   ",
      "           u    ",
      "bBbCCC     bt   ",
      " vDEEF I   u    ",
      " vJKKL     w    ",
      " v  M      w    ",
      " vq  r      N   "
    ],
    [
      "  b        b    ",
      "   vvvvvvvvvvvvv",
      "b b        bOOOO",
      "           u    ",
      "           w    ",
      "           w    ",
      "           uy   ",
      "           u    ",
      "           w    ",
      "           w    ",
      "           u    ",
      "b b        bP   ",
      " v         u    ",
      " v         w    ",
      " v         w    ",
      " v          Q   "
    ],
    [
      "  b        b    ",
      "   vvvvvvvvvvvvv",
      "b b        bRRRR",
      "           u   S",
      "           w    ",
      "           w    ",
      "           uy   ",
      "           u    ",
      "           w    ",
      "           w    ",
      "           u    ",
      "b b        b    ",
      " v         u    ",
      " v         w    ",
      " v         w    ",
      " v         w    "
    ],
    [
      "  b        b    ",
      "   vvvvvvvvvvvvv",
      "b TnnnnnnnnTnnnn",
      "  nUUUUUUUUn  Sg",
      "  nUUUUUUUUn   V",
      "  nUUUUUUUUn    ",
      "  nUUUUUUUUny   ",
      "  nUUUUUUUUnUUUU",
      "  nUUUUUUUUnUUUU",
      "  nUUUUUUUUnUUUU",
      "  nUUUUUUUUnUUUU",
      "b TnnnnnnnnTnnnn",
      " vnUUUUUUUUnUUUU",
      " vnUUUUUUUUnUUUU",
      " vnUUUUUUUUnUUUU",
      " vnUUUUUUUUnUUUU"
    ],
    [
      "WWTnnnnnnnnTnnnn",
      "WWnvvvvvvvvnvvvv",
      "TnXnnnnnnnnTnnnn",
      "nUnYmmmmmmmy Sg ",
      "nUnmmmmmmmmy  Vj",
      "nUnmmmmmmmmyUUUU",
      "nUnmmmmmmmmmyZZZ",
      "nUnmmmmmmmmmmmmm",
      "nUnYmmmmmmmmmmmm",
      "nUnmmmmmmmmmmmmm",
      "nUnmmmmmmmmmmmmm",
      "TnXmmmmmmmmmmmmm",
      "Wvnmmmmmmmmmmmmm",
      "Wvn0mmmmmmmmmmmm",
      "1vnmmmmmmmmmmmmm",
      "2vnmmmmmmmmmmmmm"
    ]
  ]
}