{
  "name": "multi_oasiscondo_5_base3",
  "refpalette": "deceasedcraft:multi_oasiscondo_5/multi_oasiscondo_5_base3_palette",
  "xsize": 16,
  "zsize": 16,
  "slices": [
    [
      "  a        a    ",
      "   vvvvvvvvvvvvv",
      "a a        abbb ",
      "           c    ",
      "           d    ",
      "           d    ",
      "           ce   ",
      "           c    ",
      "           d    ",
      "           d    ",
      "           c    ",
      "a a        a    ",
      " v         c    ",
      " v         d    ",
      " v         d    ",
      "av         d    "
    ],
    [
      "  a        a    ",
      "   vvvvvvvvvvvvv",
      "a a        ab b ",
      "           c    ",
      "           d    ",
      "           d    ",
      "           ce   ",
      "           c    ",
      "           d    ",
      "           d    ",
      "           c    ",
      "a a        a    ",
      " v         c    ",
      " v         d    ",
      " v         d    ",
      "av         d    "
    ],
    [
      "  a        a    ",
      "   vvvvvvvvvvvvv",
      "a a        a    ",
      "           c    ",
      "           d    ",
      "           d    ",
      "           ce   ",
      "           c    ",
      "           d    ",
      "           d    ",
      "           c    ",
      "a a        a    ",
      " v         c    ",
      " v         d    ",
      " v         d    ",
      "av         d    "
    ],
    [
      "  a        a    ",
      "   vvvvvvvvvvvvv",
      "a a        affff",
      "           c   g",
      "           d    ",
      "           d    ",
      "           ce   ",
      "           c    ",
      "           d    ",
      "           d    ",
      "           c    ",
      "a a        a    ",
      " v         c    ",
      " v         d    ",
      " v         d    ",
      "av         d    "
    ],
    [
      "  a        a    ",
      "   vvvvvvvvvvvvv",
      "a hiiiiiiiihiiii",
      "  ijjjjjjjji  gk",
      "  ijjjjjjjji   l",
      "  ijjjjjjjji    ",
      "  ijjjjjjjjie   ",
      "  ijjjjjjjjijjjj",
      "  ijjjjjjjjijjjj",
      "  ijjjjjjjjijjjj",
      "  ijjjjjjjjijjjj",
      "a hiiiiiiiihiiii",
      " vijjjjjjjjijjjj",
      " vijjjjjjjjijjjj",
      " vijjjjjjjjijjjj",
      "avijjjjjjjjijjjj"
    ],
    [
      "mmhiiiiiiiihiiii",
      "mmivvvvvvvvivvvv",
      "hiniiiiiiiihiiii",
      "ijiooooooooe gk ",
      "ijiooooooooe  lp",
      "ijiooooooooejjjj",
      "ijioooooooooeqqq",
      "ijiooooooooooooo",
      "ijiooooooooooooo",
      "ijiooooooooooooo",
      "ijiooooooooooooo",
      "hinooooooooooooo",
      "iviooooooooooooo",
      "iviooooooooooooo",
      "iviooooooooooooo",
      "hviooooooooooooo"
    ]
  ]
}