{
  "name": "multi_oasiscondo_5_base4",
  "refpalette": "deceasedcraft:multi_oasiscondo_5/multi_oasiscondo_5_base4_palette",
  "xsize": 16,
  "zsize": 16,
  "slices": [
    [
      "aaaaaaaaaaaaaaaa",
      "aaaaaaaaaaaaaaaa",
      "aaaaaaaaaaaaaaaa",
      "aaaaaaaaaaaaaaaa",
      "aaaaaaaaaaaaaaaa",
      "aaaaaaaaaaaaaaaa",
      "aaaaaaaaaaaaaaaa",
      "aaaaaaaaaaaaaaaa",
      "aaaaaaaaaaaaaaaa",
      "aaaaaaaaaaaaaaaa",
      "aaaaaaaaaaaaaaaa",
      "aaaaaaaaaaaaaaaa",
      "aaaaaaaaaaaaaaaa",
      "aaaaaaaaaaaaaaaa",
      "aaaaaaaaaaaaaaaa",
      "aaaaaaaaaaaaaaaa"
    ],
    [
      "aabaaaaaaaabaaaa",
      "aaaaaaaaaaaaaaaa",
      "babaaaaaaaabaaaa",
      "aaaaaaaaaaaaaaaa",
      "aaaaaaaaaaaaaaaa",
      "aaaaaaaaaaaaaaaa",
      "aaaaaaaaaaaaaaaa",
      "aaaaaaaaaaaaaaaa",
      "aaaaaaaaaaaaaaaa",
      "aaaaaaaaaaaaaaaa",
      "aaaaaaaaaaaaaaaa",
      "babaaaaaaaabaaaa",
      "aaaaaaaaaaaaaaaa",
      "aaaaaaaaaaaaaaaa",
      "aaaaaaaaaaaaaaaa",
      "aaaaaaaaaaaaaaaa"
    ],
    [
      "ccbHHHHHHHHbHHHH",
      "cccvvvvvvvvvvvvv",
      "bcbddddddddbeeee",
      "cccccccccccfgggg",
      "HHHHHHHHHccfgggg",
      "HHHHHHHHHHcfgggg",
      "HHHHHHHHHHcfgggg",
      "HHHHHHHHHHcfgggg",
      "HHHHHHHHHHcfgggg",
      "HHHHHHHHHHcfgggg",
      "cccccHHHHHcfgggg",
      "bcbcccHHHHcbhggg",
      "fvHHHHHHHHcigggg",
      "fvHHHHHHHHcigggg",
      "fvHHHHHHHHcigggg",
      "bvHHHHHHHHcigggg"
    ],
    [
      "jkbl  ml  mbl  m",
      "nopvvvvvvvvvvvvv",
      "bqb        brrrr",
      "           s    ",
      "           t  uw",
      "           t   x",
      "           sy  A",
      "           s    ",
      "           tB   ",
      "           tB   ",
      "           s    ",
      "bCbDDD     br   ",
      " vEFFI     s    ",
      " vJKKL     t    ",
      " v  M      t    ",
      "bvl  m      N   "
    ],
    [
      "  b        b    ",
      "   vvvvvvvvvvvvv",
      "b b        bOOOO",
      "           s    ",
      "           t   u",
      "           t    ",
      "           sy  P",
      "           s    ",
      "           t    ",
      "           t    ",
      "           s    ",
      "b b        bQ   ",
      " v         s    ",
      " v         t    ",
      " v         t    ",
      "bv          R   "
    ],
    [
      "  b        b    ",
      "   vvvvvvvvvvvvv",
      "b b        bOOOO",
      "           s    ",
      "           t    ",
      "           t    ",
      "           sy   ",
      "           s    ",
      "           t    ",
      "           t    ",
      "           s    ",
      "b b        b    ",
      " v         s    ",
      " v         t    ",
      " v         t    ",
      "bv         t    "
    ]
  ]
}