{
  "name": "multi_oasiscondo_5_ground",
  "refpalette": "deceasedcraft:multi_oasiscondo_5/multi_oasiscondo_5_ground_palette",
  "xsize": 16,
  "zsize": 16,
  "slices": [
    [
      "abcddddddddcdddd",
      "abeeffffffeddddd",
      "ceghiiiiiieddddd",
      "aejk     lmefn  ",
      "abio      meppq ",
      "abio     lmerrrr",
      "abio     lmgesss",
      "abio     lmotooo",
      "abik     lmmooot",
      "abiou     lmotoo",
      "abiow     lmmtoo",
      "cbjow      xmmmo",
      "abioy       llmm",
      "abik          ll",
      "Abio            ",
      "Bbio            "
    ],
    [
      "  c        c    ",
      " geeCCDECCe     ",
      "ceg       e  FFF",
      " e I       e    ",
      " J         eqq  ",
      " J         eKKKK",
      " J         geLLL",
      " J              ",
      " J I            ",
      " J              ",
      " J              ",
      "cJ              ",
      " J              ",
      " J I            ",
      " J              ",
      " J              "
    ],
    [
      "  c        c    ",
      " geeCCMNCCe     ",
      "ceg       e     ",
      " e mO      e    ",
      "           e    ",
      "           ePPPP",
      "           geLLL",
      "   O            ",
      "   m            ",
      "                ",
      "                ",
      "c               ",
      "                ",
      "   m            ",
      "                ",
      "                "
    ],
    [
      "  c        c    ",
      " geeCCQQCCe     ",
      "cegm      e    R",
      " emmm      e   S",
      "   O       e    ",
      "           eP PP",
      "           geLLL",
      "   m            ",
      "  Omm           ",
      "   O            ",
      "                ",
      "c               ",
      "   m            ",
      "   mO           ",
      "   O            ",
      "                "
    ],
    [
      "  c        c    ",
      " geeCCCCCCe     ",
      "cegO      e   RT",
      " emmm      e  SU",
      "   m       e    ",
      "           e    ",
      "           geLLL",
      "   m            ",
      "  mmm           ",
      "   m            ",
      "                ",
      "c               ",
      "   m            ",
      "  mmm           ",
      "   m            ",
      "                "
    ],
    [
      "  c        c    ",
      " geeCCCCCCe     ",
      "ceg       e  RTT",
      " e mO      eVSU ",
      "           eV Wq",
      "           eV   ",
      "           geLLL",
      "   m            ",
      "  OmO           ",
      "   m            ",
      "                ",
      "c               ",
      "                ",
      "  OmO           ",
      "   m            ",
      "                "
    ]
  ]
}