{
  "name": "multi_oasiscondo_5_top",
  "refpalette": "deceasedcraft:multi_oasiscondo_5/multi_oasiscondo_5_top_palette",
  "xsize": 16,
  "zsize": 16,
  "slices": [
    [
      "aabaaaaaaaabaaaa",
      "aaaaaaaaaaaaaaaa",
      "baaaaaaaaaaaaaaa",
      "aaaaaaaccccdefff",
      "aaaaaccg   de   ",
      "aaaahg     dei  ",
      "aaaah      jdk  ",
      "aaahg           ",
      "aaah            ",
      "aaah            ",
      "aaah            ",
      "baahl           ",
      "aaah            ",
      "aaah            ",
      "aaah            ",
      "aaah            "
    ],
    [
      "  b      m b    ",
      "                ",
      "b               ",
      "       nnnndoppp",
      "q    nnn   dor  ",
      " s  nn     d ti ",
      "    n      jduk ",
      "   nn           ",
      "s  n            ",
      "s  n            ",
      "   n            ",
      "b  n            ",
      "   n            ",
      "s  n            ",
      "s  n            ",
      "   n            "
    ],
    [
      "  b        b    ",
      "                ",
      "b               ",
      "           d    ",
      "           d wr ",
      "     n     d  ti",
      "           jdpuk",
      "                ",
      "                ",
      "                ",
      "                ",
      "b  n            ",
      "                ",
      "                ",
      "                ",
      "                "
    ],
    [
      "  b        b    ",
      "                ",
      "b               ",
      "           d    ",
      "           d  wr",
      "     n     d   t",
      "           jd pu",
      "                ",
      "                ",
      "                ",
      "                ",
      "b  n            ",
      "                ",
      "                ",
      "                ",
      "                "
    ],
    [
      "  b        b    ",
      "                ",
      "b               ",
      "           d    ",
      "           d   w",
      "     n     d    ",
      "           jd  p",
      "                ",
      "                ",
      "                ",
      "                ",
      "b  n            ",
      "                ",
      "                ",
      "                ",
      "                "
    ],
    [
      "  b        bxxxx",
      " xxxxxxxxxxxxxxx",
      "bxxxxxxxxxxxxxxx",
      " xxxxxx    d    ",
      " xxxx      dy   ",
      " xxx n     dy   ",
      " xxx       jd   ",
      " xx             ",
      " xx             ",
      " xx             ",
      " xx             ",
      "bxxn            ",
      " xx             ",
      " xx             ",
      " xx             ",
      " xx             "
    ],
    [
      "Acbccccccccbaaaa",
      "haaaaaaaaaaaaaaa",
      "baaaaaaaaaaaaaaa",
      "haaaaaaccccdBfff",
      "haaaaccg   ddy  ",
      "haaahg     dgy  ",
      "haaah      jdk  ",
      "haahg           ",
      "haah            ",
      "haah            ",
      "haah            ",
      "baahC           ",
      "haah            ",
      "haah            ",
      "haah            ",
      "haah            "
    ],
    [
      "DDbDDDDDDDDb    ",
      "D               ",
      "b               ",
      "D      nnnndoppp",
      "D    nnn   dEdy ",
      "D   nn     d hy ",
      "D   n      jdDk ",
      "D  nn           ",
      "D  n            ",
      "D  n            ",
      "D  n            ",
      "b  n            ",
      "D  n            ",
      "D  n            ",
      "D  n            ",
      "D  n            "
    ],
    [
      "  b        b    ",
      "                ",
      "b               ",
      "           d    ",
      "           dFddy",
      "     n     d  hy",
      "           jdDDk",
      "                ",
      "                ",
      "                ",
      "                ",
      "b  n            ",
      "                ",
      "                ",
      "                ",
      "                "
    ],
    [
      "  b        b    ",
      "                ",
      "b               ",
      "           dI   ",
      "           ddddd",
      "     n     d   h",
      "           jdDDD",
      "                ",
      "                ",
      "                ",
      "                ",
      "b  n            ",
      "                ",
      "                ",
      "                ",
      "                "
    ],
    [
      "  b        b    ",
      "                ",
      "b      JJJJ     ",
      "     JJK   d    ",
      "     K     ddddd",
      "   LMn     d    ",
      "   L       jdDDD",
      "  LM            ",
      "  L             ",
      "  L             ",
      "  L             ",
      "b Ln            ",
      "  L             ",
      "  L             ",
      "  L             ",
      "  L             "
    ],
    [
      "xxbxxxxxxxxbxxxx",
      "xxxxxxxxxxxxxxxx",
      "bxxxxxxxxxxxxxxx",
      "xxxxxxxNNNNd    ",
      "xxxxxNNN   ddddd",
      "xxxxNN     d    ",
      "xxxxN      jdDDD",
      "xxxNN           ",
      "xxxN            ",
      "xxxN            ",
      "xxxN            ",
      "bxxN            ",
      "xxxN            ",
      "xxxN            ",
      "xxxN            ",
      "xxxN            "
    ],
    [
      "gggggggggggggggg",
      "gggggggggggggggg",
      "gggggggggggggggg",
      "gggggggggggdgggg",
      "gggggggg   ddddd",
      "gggggg     d    ",
      "ggggg      jdDDD",
      "ggggg           ",
      "gggg            ",
      "gggg            ",
      "gggg            ",
      "gggg            ",
      "gggg            ",
      "gggg            ",
      "gggg            ",
      "gggg            "
    ],
    [
      "OOOP            ",
      "OOOQ            ",
      "OOOP            ",
      "PRP    nnnnd    ",
      "     nnn   ddddd",
      "    nn     d    ",
      "    n      jdDDD",
      "   nn           ",
      "   n            ",
      "   n            ",
      "   n            ",
      "   n            ",
      "SS n            ",
      "ST n            ",
      "SS n            ",
      "   n            "
    ],
    [
      "UVW             ",
      "XYZ             ",
      "012             ",
      "           d    ",
      "           ddddd",
      "           d    ",
      "           jdDDD",
      "                ",
      "                ",
      "                ",
      "                ",
      "                ",
      "SS              ",
      "SS              ",
      "TT              ",
      "                "
    ],
    [
      "345             ",
      "678             ",
      "9#$             ",
      "           d%%%%",
      "           d%%%%",
      "           d%%%%",
      "           jdddd",
      "                ",
      "                ",
      "                ",
      "                ",
      "                ",
      "SS              ",
      "ST              ",
      "T^              ",
      "                "
    ],
    [
      "&*(             ",
      ")+-             ",
      "[]{             ",
      "                ",
      "                ",
      "                ",
      "                ",
      "                ",
      "                ",
      "                ",
      "                ",
      "                ",
      "}|              ",
      "||              ",
      "                ",
      "                "
    ],
    [
      "                ",
      " ;              ",
      "                ",
      "                ",
      "                ",
      "                ",
      "                ",
      "                ",
      "                ",
      "                ",
      "                ",
      "                ",
      "                ",
      "                ",
      "                ",
      "                "
    ],
    [
      " ;              ",
      ";;;             ",
      " ;              ",
      "                ",
      "                ",
      "                ",
      "                ",
      "                ",
      "                ",
      "                ",
      "                ",
      "                ",
      "                ",
      "                ",
      "                ",
      "                "
    ],
    [
      "                ",
      " :              ",
      "                ",
      "                ",
      "                ",
      "                ",
      "                ",
      "                ",
      "                ",
      "                ",
      "                ",
      "                ",
      "                ",
      "                ",
      "                ",
      "                "
    ]
  ]
}