{
  "name": "multi_oasiscondo_5_base2",
  "refpalette": "deceasedcraft:multi_oasiscondo_5/multi_oasiscondo_5_base2_palette",
  "xsize": 16,
  "zsize": 16,
  "slices": [
    [
      "aabHHHHHHHHbHHHH",
      "aaavvvvvvvvvvvvv",
      "babccccccccbdddd",
      "aaaaaaaaaaaefg  ",
      "HHHHHHHHHaaehij ",
      "HHHHHHHHHHaeklll",
      "HHHHHHHHHHaeffff",
      "HHHHHHHHHHaeffff",
      "HHHHHHHHHHaeffff",
      "aaaaaHHHHHaeffff",
      "aaaaaaHHHHaeffff",
      "babaaaHHHHabmfff",
      "avHHHHHHHHanffff",
      "avHHHHHHHHanffff",
      "ovHHHHHHHHanffff",
      "pvHHHHHHHHanffff"
    ],
    [
      "  bq  rq  rbq  r",
      "  svvvvvvvvvvvvv",
      "b b        btttt",
      "           u    ",
      "           w x  ",
      "           w  jj",
      "           uy   ",
      "           u    ",
      "           wA   ",
      "           wA   ",
      "           u    ",
      "bBbCCC     bt   ",
      " vDEEF     u    ",
      " vIJJK     w    ",
      " v  L      w    ",
      " vq  r      M   "
    ],
    [
      "  b        b    ",
      "   vvvvvvvvvvvvv",
      "b b        bNNNN",
      "           u    ",
      "           w    ",
      "           w    ",
      "           uy   ",
      "           u    ",
      "           w    ",
      "           w    ",
      "           u    ",
      "b b        bO   ",
      " v         u    ",
      " v         w    ",
      " v         w    ",
      " v          P   "
    ],
    [
      "  b        b    ",
      "   vvvvvvvvvvvvv",
      "b b        bQQQQ",
      "           u   R",
      "           w    ",
      "           w    ",
      "           uy   ",
      "           u    ",
      "           w    ",
      "           w    ",
      "           u    ",
      "b b        b    ",
      " v         u    ",
      " v         w    ",
      " v         w    ",
      " v         w    "
    ],
    [
      "  b        b    ",
      "   vvvvvvvvvvvvv",
      "b SnnnnnnnnSnnnn",
      "  nTTTTTTTTn  Rg",
      "  nTTTTTTTTn   U",
      "  nTTTTTTTTn    ",
      "  nTTTTTTTTny   ",
      "  nTTTTTTTTnTTTT",
      "  nTTTTTTTTnTTTT",
      "  nTTTTTTTTnTTTT",
      "  nTTTTTTTTnTTTT",
      "b SnnnnnnnnSnnnn",
      " vnTTTTTTTTnTTTT",
      " vnTTTTTTTTnTTTT",
      " vnTTTTTTTTnTTTT",
      " vnTTTTTTTTnTTTT"
    ],
    [
      "VVSnnnnnnnnSnnnn",
      "VVnvvvvvvvvnvvvv",
      "SnWnnnnnnnnSnnnn",
      "nTnXmmmmmmmy Rg ",
      "nTnmmmmmmmmy  Uj",
      "nTnmmmmmmmmyTTTT",
      "nTnmmmmmmmmmyYYY",
      "nTnmmmmmmmmmmmmm",
      "nTnXmmmmmmmmmmmm",
      "nTnmmmmmmmmmmmmm",
      "nTnmmmmmmmmmmmmm",
      "SnWmmmmmmmmmmmmm",
      "Vvnmmmmmmmmmmmmm",
      "VvnZmmmmmmmmmmmm",
      "0vnmmmmmmmmmmmmm",
      "1vnmmmmmmmmmmmmm"
    ]
  ]
}