{
  "name": "multi_oasiscondo_5_floor9",
  "refpalette": "deceasedcraft:multi_oasiscondo_5/multi_oasiscondo_5_floor9_palette",
  "xsize": 16,
  "zsize": 16,
  "slices": [
    [
      "aabaaaaaaaabaaaa",
      "aaaaaaaaaaaaaaaa",
      "baaaaaaaaaaaaaaa",
      "aaaaaaaccccdefff",
      "aaaaaccg   de   ",
      "aaaahg     dei  ",
      "aaaah      jdk  ",
      "aaahg           ",
      "aaah            ",
      "aaah            ",
      "aaah            ",
      "baahl           ",
      "aaah            ",
      "aaah            ",
      "aaah            ",
      "aaah            "
    ],
    [
      "  b        b    ",
      "                ",
      "b               ",
      "       mmmmdnooo",
      "     mmm   dnp  ",
      "    mm     d qi ",
      "    m      jdrk ",
      "   mm           ",
      "   m            ",
      "   m            ",
      "   m            ",
      "b  m            ",
      "   m            ",
      "   m            ",
      "   m            ",
      "   m            "
    ],
    [
      "  b        b    ",
      "                ",
      "b               ",
      "           d    ",
      "           d sp ",
      "     m     d  qi",
      "           jdork",
      "                ",
      "                ",
      "                ",
      "                ",
      "b  m            ",
      "                ",
      "                ",
      "                ",
      "                "
    ],
    [
      "  b        b    ",
      "                ",
      "b               ",
      "           d    ",
      "           d  sp",
      "     m     d   q",
      "           jd or",
      "                ",
      "                ",
      "                ",
      "                ",
      "b  m            ",
      "                ",
      "                ",
      "                ",
      "                "
    ],
    [
      "  b        b    ",
      "                ",
      "b      tttt     ",
      "     ttu   d    ",
      "     u     d   s",
      "   wxm     d    ",
      "   w       jd  o",
      "  wx            ",
      "  w             ",
      "  w             ",
      "  w             ",
      "b wm            ",
      "  w             ",
      "  w             ",
      "  w             ",
      "  w             "
    ],
    [
      "yybyyyyyyyybyyyy",
      "yyyyyyyyyyyyyyyy",
      "byyyyyyyyyyyyyyy",
      "yyyyyyyAAAAdB   ",
      "yyyyyAAA   dB   ",
      "yyyyAA     dB   ",
      "yyyyA      jd   ",
      "yyyAA           ",
      "yyyA            ",
      "yyyA            ",
      "yyyA            ",
      "byyA            ",
      "yyyA            ",
      "yyyA            ",
      "yyyA            ",
      "yyyA            "
    ]
  ]
}