{
  "name": "multi_oasiscondo_5_floor6",
  "refpalette": "deceasedcraft:multi_oasiscondo_5/multi_oasiscondo_5_floor6_palette",
  "xsize": 16,
  "zsize": 16,
  "slices": [
    [
      "aabaaaaaaaabaaaa",
      "aaaaaaaaaaaaaaaa",
      "baaaaaaaaaaaaaaa",
      "aaacdddddddefggg",
      "aaahi      ef   ",
      "aaah       efj  ",
      "aaah       kel  ",
      "aaah            ",
      "aaah            ",
      "aaah            ",
      "aaah            ",
      "baahm           ",
      "aaah            ",
      "aaah            ",
      "aaah            ",
      "aaah            "
    ],
    [
      "  b        b    ",
      "                ",
      "b               ",
      "    nnnnnnneoppp",
      "   nn      eoq  ",
      "   n       e rj ",
      "   n       kesl ",
      "   n            ",
      "   n            ",
      "   n            ",
      "   n            ",
      "b  n            ",
      "   n            ",
      "   n            ",
      "   n            ",
      "   n            "
    ],
    [
      " tb        b    ",
      "                ",
      "b               ",
      "           e    ",
      "    n      e uq ",
      "w          e  rj",
      "           kepsl",
      "                ",
      "                ",
      "                ",
      "                ",
      "b  n            ",
      "                ",
      "                ",
      "                ",
      "                "
    ],
    [
      "  b        b    ",
      "                ",
      "b               ",
      "           e    ",
      "    n      e  uq",
      "           e   r",
      "           ke ps",
      "                ",
      "                ",
      "                ",
      "                ",
      "b  n            ",
      "                ",
      "                ",
      "                ",
      "                "
    ],
    [
      "  b        b    ",
      "                ",
      "b  xxxxxxxx     ",
      "  y        e    ",
      "  y n      e   u",
      "  y        e    ",
      "  y        ke  p",
      "  y             ",
      "  y             ",
      "  y             ",
      "  y             ",
      "b yn            ",
      "  y             ",
      "  y             ",
      "  y             ",
      "  y             "
    ],
    [
      "AAbAAAAAAAAbAAAA",
      "AAAAAAAAAAAAAAAA",
      "bAAAAAAAAAAAAAAA",
      "AAABBBBBBBBeC   ",
      "AAABB      eC   ",
      "AAAB       eC   ",
      "AAAB       ke   ",
      "AAAB            ",
      "AAAB            ",
      "AAAB            ",
      "AAAB            ",
      "bAAB            ",
      "AAAB            ",
      "AAAB            ",
      "AAAB            ",
      "AAAB            "
    ]
  ]
}