{
  "name": "multi_oasiscondo_5_floor1",
  "refpalette": "deceasedcraft:multi_oasiscondo_5/multi_oasiscondo_5_floor1_palette",
  "xsize": 16,
  "zsize": 16,
  "slices": [
    [
      "  a        a    ",
      " bccddddddc     ",
      "acb       c efff",
      " c g       chi  ",
      "           chjk ",
      "           chl  ",
      "           bcmnn",
      "                ",
      "   o            ",
      "                ",
      "                ",
      "a               ",
      "                ",
      "   o            ",
      "                ",
      "                "
    ],
    [
      "  a        a    ",
      " bccddddddc     ",
      "acb       ceffff",
      " c         c    ",
      "           cpe  ",
      "           c ql ",
      "           bcrmn",
      "                ",
      "   g            ",
      "                ",
      "                ",
      "a               ",
      "                ",
      "                ",
      "                ",
      "                "
    ],
    [
      "  a        a    ",
      " bccddddddc     ",
      "acb       cfffff",
      " c         c    ",
      "           c se ",
      "           c  ql",
      "           bckrm",
      "                ",
      "                ",
      "                ",
      "                ",
      "a               ",
      "                ",
      "                ",
      "                ",
      "                "
    ],
    [
      "  a        a    ",
      " bccddddddc     ",
      "acb       cfffff",
      " c         c    ",
      "           c  se",
      "           c   q",
      "           bc kr",
      "                ",
      "                ",
      "                ",
      "                ",
      "a               ",
      "                ",
      "                ",
      "                ",
      "                "
    ],
    [
      "  a        a    ",
      " bccccccccc     ",
      "accccccccccfffff",
      " cc        c    ",
      "  c        c   s",
      "  c        c    ",
      "  c        bc  k",
      "  c             ",
      "  c             ",
      "  c             ",
      "  c             ",
      "a c             ",
      "  c             ",
      "  c             ",
      "  c             ",
      "  c             "
    ],
    [
      "ttattttttttatttt",
      "tttttttttttttttt",
      "attttttttttttttt",
      "tttuuuuuuuucw   ",
      "tttuu      cw   ",
      "tttu       cw   ",
      "tttu       bc   ",
      "tttu            ",
      "tttu            ",
      "tttu            ",
      "tttu            ",
      "attu            ",
      "tttu            ",
      "tttu            ",
      "tttu            ",
      "tttu            "
    ]
  ]
}