{
  "name": "multi_oasiscondo_5_floor10",
  "refpalette": "deceasedcraft:multi_oasiscondo_5/multi_oasiscondo_5_floor10_palette",
  "xsize": 16,
  "zsize": 16,
  "slices": [
    [
      "aabaaaaaaaabaaaa",
      "aaaaaaaaaaaaaaaa",
      "baaaaaaaaaaaaaaa",
      "aaaaaaaccccdefff",
      "aaaaaccg   de   ",
      "aaaahg     dei  ",
      "aaaah      jdk  ",
      "aaahg           ",
      "aaah            ",
      "aaah            ",
      "aaah            ",
      "baahl           ",
      "aaah            ",
      "aaah            ",
      "aaah            ",
      "aaah            "
    ],
    [
      "m b        b    ",
      "                ",
      "b               ",
      "       nnnndoppp",
      "     nnn   doq  ",
      "    nn     d ri ",
      "    n      jdsk ",
      "   nn           ",
      "   n            ",
      "   n            ",
      "   n            ",
      "b  n            ",
      "   n            ",
      "   n            ",
      "   n            ",
      "   n            "
    ],
    [
      "  b        b    ",
      "                ",
      "b               ",
      "           d    ",
      "           d tq ",
      "     n     d  ri",
      "           jdpsk",
      "                ",
      "                ",
      "                ",
      "                ",
      "b  n            ",
      "                ",
      "                ",
      "                ",
      "                "
    ],
    [
      "  b        b    ",
      "                ",
      "b               ",
      "           d    ",
      "           d  tq",
      "     n     d   r",
      "           jd ps",
      "                ",
      "                ",
      "                ",
      "                ",
      "b  n            ",
      "                ",
      "                ",
      "                ",
      "                "
    ],
    [
      "  b        b    ",
      "                ",
      "b      uuuu     ",
      "     uuw   d    ",
      "     w     d   t",
      "   xyn     d    ",
      "   x       jd  p",
      "  xy            ",
      "  x             ",
      "  x             ",
      "  x             ",
      "b xn            ",
      "  x             ",
      "  x             ",
      "  x             ",
      "  x             "
    ],
    [
      "AAbAAAAAAAAbAAAA",
      "AAAAAAAAAAAAAAAA",
      "bAAAAAAAAAAAAAAA",
      "AAAAAAABBBBdC   ",
      "AAAAABBB   dC   ",
      "AAAABB     dC   ",
      "AAAAB      jd   ",
      "AAABB           ",
      "AAAB            ",
      "AAAB            ",
      "AAAB            ",
      "bAAB            ",
      "AAAB            ",
      "AAAB            ",
      "AAAB            ",
      "AAAB            "
    ]
  ]
}