{
  "name": "multi_nuclearpowerplant_11_base12",
  "refpalette": "deceasedcraft:multi_nuclearpowerplant_11/multi_nuclearpowerplant_11_base12_palette",
  "xsize": 16,
  "zsize": 16,
  "slices": [
    [
      "aaaaaaaaaaaaaaaa",
      "aaaaaaaaaaaaaaaa",
      "aaaaaaaaaaaaaaaa",
      "aaaaaaaaaaaaaaaa",
      "aaaaaaaaaaaaaaaa",
      "aaaaaaaaaaaaaaaa",
      "aaaaaaaaaaaaaaaa",
      "aaaaaaaaaaaaaaaa",
      "aaaaaaaaaaaaaaaa",
      "aaaaaaaaaaaaaaaa",
      "aaaaaaaaaaaaaaaa",
      "aaaaaaaaaaaaaaaa",
      "aaaaaaaaaaaaaaaa",
      "aaaaaaaaaaaaaaaa",
      "aaaaaaaaaaaaaaaa",
      "aaaaaaaaaaaaaaaa"
    ],
    [
      "bbbbbbbbbbbbbbbb",
      "bbbbbbbbbbbbbbbb",
      "bbbbbbbbbbbbbbbb",
      "bbbbbbbbbbbbbbbb",
      "bbbbbbbbbbbbbbbb",
      "bbbbbbbbbbbbbbbb",
      "bbbbbbbbbbbbbbbb",
      "bbbbbbbbbbbbbbbb",
      "bbbbbbbbbbbbbbbb",
      "bbbbbbbbbbbbbbbb",
      "bbbbbbbbbbbbbbbb",
      "bbbbbbbbbbbbbbbb",
      "bbbbbbbbbbbbbbbb",
      "bbbbbbbbbbbbbbbb",
      "bbbbbbbbbbbbbbbb",
      "bbbbbbbbbbbbbbbb"
    ],
    [
      "cccccccccccccccc",
      "cccccccccccccccc",
      "cccccccccccccccc",
      "cccccccccccccccc",
      "cccccccccccccccc",
      "cccccccccccccccc",
      "cccccccccccccccc",
      "cccccccccccccccc",
      "cccccccccccccccc",
      "cccccccccccccccc",
      "cccccccccccccccc",
      "cccccccccccccccc",
      "cccccccccccccccc",
      "cccccccccccccccc",
      "cccccccccccccccc",
      "cccccccccccccccc"
    ],
    [
      "                ",
      "                ",
      "     defgeh   de",
      "                ",
      "                ",
      "                ",
      "      ieejjjjjje",
      "      klllmlmmmm",
      "      klllllllll",
      "      kllllmmmmm",
      "      neeooooooe",
      "                ",
      "                ",
      "                ",
      "     defgeh   de",
      "                "
    ],
    [
      "                ",
      "                ",
      "      eeeef   ge",
      "       ee       ",
      "       ee       ",
      "       ee       ",
      "       eef    ge",
      "                ",
      "                ",
      "                ",
      "       eef    ge",
      "       ee       ",
      "       ee       ",
      "       ee       ",
      "      eeee     e",
      "                "
    ],
    [
      "                ",
      "          pppppq",
      "      e  eeeeeee",
      "      e   pppppr",
      "      e         ",
      "      e         ",
      "      eeeeeeeeee",
      "      e         ",
      "      e         ",
      "      e         ",
      "      eeeeeeeeee",
      "      e         ",
      "      e         ",
      "      e         ",
      "      e  e     e",
      "                "
    ]
  ]
}