{
  "name": "multi_nuclearpowerplant_11_base7",
  "refpalette": "deceasedcraft:multi_nuclearpowerplant_11/multi_nuclearpowerplant_11_base7_palette",
  "xsize": 16,
  "zsize": 16,
  "slices": [
    [
      "a     bccddddddd",
      "a      bcddddddd",
      "a      bccdddddd",
      "da      bccddddd",
      "da       bccdddd",
      "da        bccddd",
      "da         bccdd",
      "da          bccc",
      "da           bbc",
      "da             b",
      "dda             ",
      "dda             ",
      "dda             ",
      "dda             ",
      "dda             ",
      "dda             "
    ],
    [
      "a     bccddddddd",
      "a      bcddddddd",
      "a      bccdddddd",
      "da      bccddddd",
      "da       bccdddd",
      "da        bccddd",
      "da         bccdd",
      "da          bccc",
      "da           bbc",
      "da             b",
      "dda             ",
      "dda             ",
      "dda             ",
      "dda             ",
      "dda             ",
      "dda             "
    ],
    [
      "a     bccddddddd",
      "a      bcddddddd",
      "a      beedddddd",
      "da       eeddddd",
      "da        eedddd",
      "da         eeddd",
      "da          eedd",
      "da           ecc",
      "da           bbc",
      "da             b",
      "dda             ",
      "dda             ",
      "dda             ",
      "dda             ",
      "dda             ",
      "dda             "
    ],
    [
      "a     bccddddddd",
      "a      bcddddddd",
      "a      beedddddd",
      "da       eeddddd",
      "da        eedddd",
      "da         eeddd",
      "da          eedd",
      "da           ecc",
      "da           bbc",
      "da             b",
      "dda             ",
      "dda             ",
      "dda             ",
      "dda             ",
      "dda             ",
      "dda             "
    ],
    [
      "a     bccddddddd",
      "a      bcdfddgdd",
      "a      bccgfdddd",
      "da      bccgdddd",
      "da       bccdddd",
      "da        bccddd",
      "da         bccdf",
      "da          bccc",
      "da           bbc",
      "da             b",
      "dda             ",
      "dda             ",
      "dda             ",
      "dda             ",
      "dda             ",
      "dda             "
    ],
    [
      "ahhhhi cc       ",
      "ahhhhii c       ",
      "ahhhhhi cc      ",
      "dahhhhij cc     ",
      "dahhhhhii cc    ",
      "dahhhhhhii cc   ",
      "dahhhhhhhii cc  ",
      "dahhhhhhhhii ccc",
      "dahhhhhhhhhij  c",
      "dahhhhhhhhhhiii ",
      "ddahhhhhhhhhhhii",
      "ddahhhhhhhhhhhhh",
      "ddahhhhhhhhhhhhh",
      "ddahhhhhhhhhhhhh",
      "ddahhhhhhhhhhhhh",
      "ddahhhhhhhhhhhhh"
    ]
  ]
}