{
  "name": "multi_nuclearpowerplant_11_base8",
  "refpalette": "deceasedcraft:multi_nuclearpowerplant_11/multi_nuclearpowerplant_11_base8_palette",
  "xsize": 16,
  "zsize": 16,
  "slices": [
    [
      "aaaaabc==d e    ",
      "aaaaaabc==de    ",
      "aaaaaabc==de    ",
      "aaaaaaabc==d    ",
      "aaaaaaaabc==dfff",
      "aaaaaaaaabc==dd ",
      "aaaaaaaaaabc===d",
      "aaaaaaaaaaabc===",
      "aaaaaaaaaaaabcc=",
      "aaaaaaaaaaaaabbc",
      "aaaaaaaaaaaaaaab",
      "aaaaaaaaaaaaaaaa",
      "aaaaaaaaaaaaaaaa",
      "aaaaaaaaaaaaaaaa",
      "aaaaaaaaaaaaaaaa",
      "aaaaaaaaaaaaaaaa"
    ],
    [
      "g=====hddiiiiiii",
      "g======hdiiiiiii",
      "g======hddiiiiii",
      "ig======hddiiiii",
      "ig=======hddiiii",
      "ig========hddiii",
      "ig=========hddii",
      "ig==========hddd",
      "ig===========hhd",
      "ig=============h",
      "iig=============",
      "iig=============",
      "iig=============",
      "iig=============",
      "iig=============",
      "iig============="
    ],
    [
      "jkkkkklddmmmmmmm",
      "jkkkkkkldmmmmmmm",
      "jkkkkkklddmmmmmm",
      "mjkkkkkklddmmmmm",
      "mjkkkkkkklddmmmm",
      "mjkkkkkkkklddmmm",
      "mjkkkkkkkkklddmm",
      "mjkkkkkkkkkklddd",
      "mjkkkkkkkkkkklld",
      "mjkkkkkkkkkkkkkl",
      "mmjkkkkkkkkkkkkk",
      "mmjkkkkkkkkkkkkk",
      "mmjkkkkkkkkkkkkk",
      "mmjkkkkkkkkkkkkk",
      "mmjkkkkkkkkkkkkk",
      "mmjkkkkkkkkkkkkk"
    ],
    [
      "jkkkkklddmmmmmmm",
      "jkkkkkkldmmmmmmm",
      "jkkkkkklddmmmmmm",
      "mjkkkkkklddmmmmm",
      "mjkkkkkkklddmmmm",
      "mjkkkkkkkklddmmm",
      "mjkkkkkkkkklddmm",
      "mjkkkkkkkkkklddd",
      "mjkkkkkkkkkkklld",
      "mjkkkkkkkkkkkkkl",
      "mmjkkkkkkkkkkkkk",
      "mmjkkkkkkkkkkkkk",
      "mmjkkkkkkkkkkkkk",
      "mmjkkkkkkkkkkkkk",
      "mmjkkkkkkkkkkkkk",
      "mmjkkkkkkkkkkkkk"
    ],
    [
      "jggggnhddmmmmmmm",
      "jggggnnhdmmmmmmm",
      "jgggggnhddmmmmmm",
      "mjggggnnhddmmmmm",
      "mjgggggnnhddmmmm",
      "mjggggggnnhddmmm",
      "mjgggggggnnhddmm",
      "mjggggggggnnhddd",
      "mjgggggggggnnhhd",
      "mjggggggggggnnnh",
      "mmjgggggggggggnn",
      "mmjggggggggggggg",
      "mmjggggggggggggg",
      "mmjggggggggggggg",
      "mmjggggggggggggg",
      "mmjggggggggggggg"
    ],
    [
      "j     lddmmmmmmm",
      "j      ldmmmmmmm",
      "j      lddmmmmmm",
      "mj      lddmmmmm",
      "mj       lddmmmm",
      "mj        lddmmm",
      "mj         lddmm",
      "mj          lddd",
      "mj           lld",
      "mj             l",
      "mmj             ",
      "mmj             ",
      "mmj             ",
      "mmj             ",
      "mmj             ",
      "mmj             "
    ]
  ]
}