{
  "name": "multi_nuclearpowerplant_11_base6",
  "refpalette": "deceasedcraft:multi_nuclearpowerplant_11/multi_nuclearpowerplant_11_base6_palette",
  "xsize": 16,
  "zsize": 16,
  "slices": [
    [
      "abbbbcd         ",
      "abbbbccd        ",
      "aabbbbcd        ",
      " abbbbccd       ",
      " abbbbbccd      ",
      " abbbbbbccd     ",
      " abbbbbbbccd    ",
      " abbbbbbbbccd   ",
      " abbbbbbbbbccdd ",
      " aabbbbbbbbbcccd",
      "  abbbbbbbbbbbcc",
      "  abbbbbbbbbbbbb",
      "  abbbbbbbbbbbbb",
      "  abbbbbbbbbbbbb",
      "  abbbbbbbbbbbbb",
      "  aabbbbbbbbbbbb"
    ],
    [
      "e     fgg       ",
      "h      fg       ",
      "ij     fgg      ",
      " kl     fgg     ",
      " k       fgg    ",
      " km       fgg   ",
      " kn        fgg  ",
      " ko         fggg",
      " k           ffg",
      " kk            f",
      "  k             ",
      "  k             ",
      "  k             ",
      "  k             ",
      "  k             ",
      "  kk            "
    ],
    [
      "       ==       ",
      "        =       ",
      "        ==      ",
      "         ==     ",
      "          ==    ",
      "           ==   ",
      "            ==  ",
      "             ===",
      "               =",
      "                ",
      "                ",
      "                ",
      "                ",
      "                ",
      "                ",
      "                "
    ],
    [
      "                ",
      "                ",
      "                ",
      "                ",
      "          =     ",
      "           =    ",
      "                ",
      "                ",
      "                ",
      "                ",
      "                ",
      "                ",
      "                ",
      "                ",
      "                ",
      "                "
    ],
    [
      "                ",
      "                ",
      "                ",
      "          p     ",
      "          q     ",
      "           rs   ",
      "                ",
      "                ",
      "                ",
      "                ",
      "                ",
      "                ",
      "                ",
      "                ",
      "                ",
      "                "
    ],
    [
      "                ",
      "                ",
      "                ",
      "          =     ",
      "                ",
      "            =   ",
      "                ",
      "                ",
      "                ",
      "                ",
      "                ",
      "                ",
      "                ",
      "                ",
      "                ",
      "                "
    ]
  ]
}