{
  "name": "building_warehousea_ground_180",
  "refpalette": "deceasedcraft:building_warehousea/building_warehousea_ground_palette_180",
  "xsize": 16,
  "zsize": 16,
  "slices": [
    [
      "zzzzzzzzzzzzzzzz",
      "zbddbbbdbbbdazaa",
      "zbbbbbbbbbbbaaaz",
      "zbbbbbbbbbbbaaaa",
      "zdbbbbbbbbbbaaaz",
      "zbdbbbbbbbbdaazz",
      "zbbbbbbbbbfdaaaz",
      "zbccccccccbdaaaz",
      "zbccccccecbdaazz",
      "zbccgcccccbbaazz",
      "zbccccccccfbaaaz",
      "zbccccecccbbaaaz",
      "zbccccccccbdaaza",
      "zbccccccccbbaaaa",
      "zbbbbbbbbbbbzaaa",
      "zzzzzzzzzzzzzzzz"
    ],
    [
      "  L h   L  h   h",
      "h            A  ",
      "  jijKJjijj     ",
      "  ijI  DFjj q   ",
      "h  BE  DCB     h",
      "   B     B    A ",
      "hjijy   jji     ",
      " i!w    x k  u h",
      " jw       k     ",
      "hj        ku    ",
      " j        j    h",
      " jt       k     ",
      "hjsr      k  q  ",
      " iponm l  k     ",
      "hjijjijiiji     ",
      " h  h h h  h  h "
    ],
    [
      "                ",
      "                ",
      "  ijjRQjjji     ",
      "  jjE  PFij     ",
      "   B   O B      ",
      "   B     B      ",
      " iij    jjj     ",
      " jw     N k     ",
      " j        k     ",
      " j        k     ",
      " j        j     ",
      " i        k     ",
      " j        k     ",
      " jM       k     ",
      " jiijBBijji     ",
      "                "
    ],
    [
      "                ",
      "                ",
      "  jjjVVjiij     ",
      "  ji   U jj     ",
      "   B     B      ",
      "   B     B      ",
      " jjiTTTTjjj     ",
      " jS       k     ",
      " i        k     ",
      " j        k     ",
      " j        j     ",
      " j        k     ",
      " i        k     ",
      " j        k     ",
      " jjijjjjjjj     ",
      "                "
    ],
    [
      "                ",
      " WWWWWWWWWWW    ",
      " WjjjjjjjjjW    ",
      " WjjU  Z jjW    ",
      " WWX     XWW    ",
      " WWX     XWW    ",
      " ijjjjjjijjW    ",
      " jS VVVV XjW    ",
      " j       XiW    ",
      " j       XjW    ",
      " j   Y    jW    ",
      " j       XjW    ",
      " j       XjW    ",
      " j       XjW    ",
      " ijjjjjjjij     ",
      "                "
    ],
    [
      "                ",
      "                ",
      "  111111111     ",
      "  111111111     ",
      "  111111111     ",
      "  111111111     ",
      " jjjjjjjjjj     ",
      " jS0000000j     ",
      " j00000000j     ",
      " j00000000j     ",
      " j000b0000i     ",
      " j00000000j     ",
      " j00000000i     ",
      " j00000000j     ",
      " jjjjijjjjj     ",
      "                "
    ]
  ]
}