{
  "name": "building_warehousea_ground_270",
  "refpalette": "deceasedcraft:building_warehousea/building_warehousea_ground_palette_270",
  "xsize": 16,
  "zsize": 16,
  "slices": [
    [
      "zazazzzzzzzzaaaz",
      "zaaaazaazzaazaaz",
      "zzaaaaaaaaaaaaaz",
      "zaaaaaaaaaaaaazz",
      "zdbbbddddbbbdbbz",
      "zbbbbbfbbbfbbbbz",
      "zbbbbbbcccccccbz",
      "zbbbbbbcecccccbz",
      "zdbbbbbcccccccbz",
      "zbbbbbbcccceccbz",
      "zbbbbbbcccccccbz",
      "zbbbbbbccgccccbz",
      "zdbbbbbcccccccbz",
      "zdbbbdbcccccccbz",
      "zbbbdbbbbbbbbbbz",
      "zzzzzzzzzzzzzzzz"
    ],
    [
      "h   h  h  h     ",
      "     A         h",
      " A     u    q   ",
      "   q            ",
      "h        u     h",
      "  jj  ikkkjkkki ",
      "  jjBBj       j ",
      "L iFC jx      ih",
      "  jDD        li ",
      "  J           jh",
      "  K          mi ",
      "h jIE y      njh",
      "  ijBBjw    roj ",
      "L ji  i!w  tspi ",
      "      jijjjjjijh",
      " h  h h  h  h h "
    ],
    [
      "                ",
      "                ",
      "                ",
      "                ",
      "                ",
      "  ij  jkkkjkkki ",
      "  jiBBj       j ",
      "  jF  jN      j ",
      "  jPO         i ",
      "  Q           B ",
      "  R           B ",
      "  jE          j ",
      "  jjBBj       i ",
      "  ij  iw     Mi ",
      "      ijjjjijjj ",
      "                "
    ],
    [
      "                ",
      "                ",
      "                ",
      "                ",
      "                ",
      "  jj  jkkkjkkkj ",
      "  ijBBj       j ",
      "  i   j       j ",
      "  jU  T       j ",
      "  V   T       j ",
      "  V   T       j ",
      "  j   T       j ",
      "  jiBBi       i ",
      "  jj  jS      j ",
      "      jjijjjijj ",
      "                "
    ],
    [
      "                ",
      "                ",
      "                ",
      "                ",
      " WWWWWWWWWWWWW  ",
      " WjjWWjjijjjjjj ",
      " WjjXXjXXX XXXi ",
      " Wj   i       j ",
      " WjZ  jV      j ",
      " Wj   jV      j ",
      " Wj   jV  Y   j ",
      " WjU  jV      j ",
      " WjjXXj       j ",
      " WjjWWjS      j ",
      " WWWWWijjjjjjji ",
      "                "
    ],
    [
      "                ",
      "                ",
      "                ",
      "                ",
      "                ",
      "  1111jjjjijijj ",
      "  1111j0000000j ",
      "  1111j0000000j ",
      "  1111j0000000j ",
      "  1111j0000000j ",
      "  1111j000b000i ",
      "  1111j0000000j ",
      "  1111j0000000j ",
      "  1111jS000000j ",
      "      jjjjjjjjj ",
      "                "
    ]
  ]
}