{
  "name": "building_warehousea_ground_90",
  "refpalette": "deceasedcraft:building_warehousea/building_warehousea_ground_palette_90",
  "xsize": 16,
  "zsize": 16,
  "slices": [
    [
      "zzzzzzzzzzzzzzzz",
      "zbbbbbbbbbbdbbbz",
      "zbcccccccbdbbbdz",
      "zbcccccccbbbbbdz",
      "zbccccgccbbbbbbz",
      "zbcccccccbbbbbbz",
      "zbcceccccbbbbbbz",
      "zbcccccccbbbbbdz",
      "zbcccccecbbbbbbz",
      "zbcccccccbbbbbbz",
      "zbbbbfbbbfbbbbbz",
      "zbbdbbbddddbbbdz",
      "zzaaaaaaaaaaaaaz",
      "zaaaaaaaaaaaaazz",
      "zaazaazzaazaaaaz",
      "zaaazzzzzzzzazaz"
    ],
    [
      " h h  h  h h  h ",
      "hjijjjjjij      ",
      " ipst  w!i  ij L",
      " jor    wjBBji  ",
      "hjn      y EIj h",
      " im          K  ",
      "hj           J  ",
      " il        DDj  ",
      "hi      xj CFi L",
      " j       jBBjj  ",
      " ikkkjkkki  jj  ",
      "h     u        h",
      "            q   ",
      "   q    u     A ",
      "h         A     ",
      "     h  h  h   h"
    ],
    [
      "                ",
      " jjjijjjji      ",
      " iM     wi  ji  ",
      " i       jBBjj  ",
      " j          Ej  ",
      " B           R  ",
      " B           Q  ",
      " i         OPj  ",
      " j      Nj  Fj  ",
      " j       jBBij  ",
      " ikkkjkkkj  ji  ",
      "                ",
      "                ",
      "                ",
      "                ",
      "                "
    ],
    [
      "                ",
      " jjijjjijj      ",
      " j      Sj  jj  ",
      " i       iBBij  ",
      " j       T   j  ",
      " j       T   V  ",
      " j       T   V  ",
      " j       T  Uj  ",
      " j       j   i  ",
      " j       jBBji  ",
      " jkkkjkkkj  jj  ",
      "                ",
      "                ",
      "                ",
      "                ",
      "                "
    ],
    [
      "                ",
      " ijjjjjjjiWWWWW ",
      " j      SjWWjjW ",
      " j       jXXjjW ",
      " j      Vj  UjW ",
      " j   Y  Vj   jW ",
      " j      Vj   jW ",
      " j      Vj  ZjW ",
      " j       i   jW ",
      " iXXX XXXjXXjjW ",
      " jjjjjjijjWWjjW ",
      "  WWWWWWWWWWWWW ",
      "                ",
      "                ",
      "                ",
      "                "
    ],
    [
      "                ",
      " jjjjjjjjj      ",
      " j000000Sj1111  ",
      " j0000000j1111  ",
      " j0000000j1111  ",
      " i000b000j1111  ",
      " j0000000j1111  ",
      " j0000000j1111  ",
      " j0000000j1111  ",
      " j0000000j1111  ",
      " jjijijjjj1111  ",
      "                ",
      "                ",
      "                ",
      "                ",
      "                "
    ]
  ]
}