{
  "name": "building_warehousea_ground",
  "refpalette": "deceasedcraft:building_warehousea/building_warehousea_ground_palette",
  "xsize": 16,
  "zsize": 16,
  "slices": [
    [
      "zzzzzzzzzzzzzzzz",
      "aaazbbbbbbbbbbbz",
      "aaaabbccccccccbz",
      "azaadbccccccccbz",
      "zaaabbccceccccbz",
      "zaaabfccccccccbz",
      "zzaabbcccccgccbz",
      "zzaadbceccccccbz",
      "zaaadbccccccccbz",
      "zaaadfbbbbbbbbbz",
      "zzaadbbbbbbbbdbz",
      "zaaabbbbbbbbbbdz",
      "aaaabbbbbbbbbbbz",
      "zaaabbbbbbbbbbbz",
      "aazadbbbdbbbddbz",
      "zzzzzzzzzzzzzzzz"
    ],
    [
      " h  h  h h h  h ",
      "     ijiijijjijh",
      "     k  l mnopi ",
      "  q  k      rsjh",
      "     k       tj ",
      "h    j        j ",
      "    uk        jh",
      "     k       wj ",
      "h u  k x    w!i ",
      "     ijj   yjijh",
      " A    B     B   ",
      "h     BCD  EB  h",
      "   q jjFD  Iji  ",
      "     jjijJKjij  ",
      "  A            h",
      "h   h  L   h L  "
    ],
    [
      "                ",
      "     ijjiBBjiij ",
      "     k       Mj ",
      "     k        j ",
      "     k        i ",
      "     j        j ",
      "     k        j ",
      "     k        j ",
      "     k N     wj ",
      "     jjj    jii ",
      "      B     B   ",
      "      B O   B   ",
      "     jiFP  Ejj  ",
      "     ijjjQRjji  ",
      "                ",
      "                "
    ],
    [
      "                ",
      "     jjjjjjjijj ",
      "     k        j ",
      "     k        i ",
      "     k        j ",
      "     j        j ",
      "     k        j ",
      "     k        i ",
      "     k       Sj ",
      "     jjjTTTTijj ",
      "      B     B   ",
      "      B     B   ",
      "     jj U   ij  ",
      "     jiijVVjjj  ",
      "                ",
      "                "
    ],
    [
      "                ",
      "     jijjjjjjji ",
      "    WjX       j ",
      "    WjX       j ",
      "    WjX       j ",
      "    Wj    Y   j ",
      "    WjX       j ",
      "    WiX       j ",
      "    WjX VVVV Sj ",
      "    Wjjijjjjjji ",
      "    WWX     XWW ",
      "    WWX     XWW ",
      "    Wjj Z  UjjW ",
      "    WjjjjjjjjjW ",
      "    WWWWWWWWWWW ",
      "                "
    ],
    [
      "                ",
      "     jjjjjijjjj ",
      "     j00000000j ",
      "     i00000000j ",
      "     j00000000j ",
      "     i0000b000j ",
      "     j00000000j ",
      "     j00000000j ",
      "     j0000000Sj ",
      "     jjjjjjjjjj ",
      "     111111111  ",
      "     111111111  ",
      "     111111111  ",
      "     111111111  ",
      "                ",
      "                "
    ]
  ]
}