{
  "name": "multi_farmhouse1_2_floor1",
  "refpalette": "deceasedcraft:multi_farmhouse1_2/multi_farmhouse1_2_floor1_palette",
  "xsize": 16,
  "zsize": 16,
  "slices": [
    [
      "aaaaaaaaaaaaaaaa",
      "aaaaaaaaaaaaaaaa",
      "aaaaaaaaaaaaaaaa",
      "aaaaaaaaaaaaaaaa",
      "aaaaaaaaaaaaaaaa",
      "aaaaaaaaaaaaaaaa",
      "aaaaaaaaaaaaaaaa",
      "aaaaaaaaaaaaaaaa",
      "baaaaaaaaaaaaaaa",
      "baaaaaaaaaaaaaaa",
      "aaaaaaaaaaaaaaaa",
      "baaaaaaaaaaaaaaa",
      "baaaaaaaaaaaaaaa",
      "bbaaaaaaaaaaaaaa",
      "bbbbbaaaaaaaaaaa",
      "bbbbbbbaaaaaaaaa"
    ],
    [
      "cbdddbdddddddddb",
      "cbdbdddddddddddd",
      "eddbbddddfbddddd",
      "cbdddddddddddddd",
      "dddbddddddfddddb",
      "cdbddddddddddddd",
      "cddddddddddddddd",
      "dbdddddddddddddb",
      "bcbbdbdddddddddd",
      "bcgddddbdddddddb",
      "bbcdbbdbdddddddd",
      "bbecbddddddddddd",
      "bbbccbdbbbdbdbdd",
      "bbbbccbgdbdddddb",
      "bbbbbbgcbdbbdbdd",
      "bbbbbbbcccgcbdcc"
    ],
    [
      "bbhhhbhhhhhhhhhb",
      "bbhbhhhhhhhhhhhh",
      "bhhbbhhhhibhhhhh",
      "bbhhhhhhhhhhhhhh",
      "hhhbhhhhhhfhhhhb",
      "bhbhhhhhhhhhhhhh",
      "bhhhhhhhhhhhhhhh",
      "hbhhhhhhhhhhhhhb",
      "bbbbhbhhhhhhhhhh",
      "bbbhhhhbhhhhhhhb",
      "bbbhbbhbhhhhhhhh",
      "bbbbbhhhhhhhhhhh",
      "bbbbbbhbbbhbhbhh",
      "bbbbbbbbhbhhhhhb",
      "bbbbbbbbbhbbhbhh",
      "bbbbbbbbbbbbbhbb"
    ],
    [
      "bbbbbbbbbbbbbbbb",
      "bbbbbbbbbbbbbbbb",
      "bbbbbbbbbbbbbbbb",
      "bbbbbbbbbbbbbbbb",
      "bbbbbbbbbbjbbbbb",
      "bbbbbbbbbbbbbbbb",
      "bbbbbbbbbbbbbbbb",
      "bbbbbbbbbbbbbbbb",
      "bbbbbbbbbbbbbbbb",
      "bbbbbbbbbbbbbbbb",
      "bbbbbbbbbbbbbbbb",
      "bbbbbbbbbbbbbbbb",
      "bbbbbbbbbbbbbbbb",
      "bbbbbbbbbbbbbbbb",
      "bbbbbbbbbbbbbbbb",
      "bbbbbbbbbbbbbbbb"
    ],
    [
      "bbbbbbbbbbbbbbbb",
      "bbbbbbbbbbbbbbbb",
      "bbbbbbbbbbbbbbbb",
      "bbbbbbbbbbbbbbbb",
      "bbbbbbbbbbbbbbbb",
      "bbbbbbbbbbbbbbbb",
      "bbbbbbbbbbbbbbbb",
      "bbbbbbbbbbbbbbbb",
      "bbbbbbbbbbbbbbbb",
      "bbbbbbbbbbbbbbbb",
      "bbbbbbbbbbbbbbbb",
      "bbbbbbbbbbbbbbbb",
      "bbbbbbbbbbbbbbbb",
      "bbbbbbbbbbbbbbbb",
      "bbbbbbbbbbbbbbbb",
      "bbbbbbbbbbbbbbbb"
    ],
    [
      "bbbbbbbbbbbbbbbb",
      "bbbbbbbbbbbbbbbb",
      "bbbbbbbbbbbbbbbb",
      "bbbbbbbbbbbbbbbb",
      "bbbbbbbbbbbbbbbb",
      "bbbbbbbbbbbbbbbb",
      "bbbbbbbbbbbbbbbb",
      "bbbbbbbbbbbbbbbb",
      "bbbbbbbbbbbbbbbb",
      "bbbbbbbbbbbbbbbb",
      "bbbbbbbbbbbbbbbb",
      "bbbbbbbbbbbbbbbb",
      "bbbbbbbbbbbbbbbb",
      "bbbbbbbbbbbbbbbb",
      "bbbbbbbbbbbbbbbb",
      "bbbbbbbbbbbbbbbb"
    ]
  ]
}