{
  "name": "multi_verticalschool_14_floor14",
  "refpalette": "deceasedcraft:multi_verticalschool_14/multi_verticalschool_14_floor14_palette",
  "xsize": 16,
  "zsize": 16,
  "slices": [
    [
      "                ",
      "                ",
      "    a        a  ",
      "bbbbbbbbbbbbbbbb",
      "cccccccccccccccc",
      "                ",
      "                ",
      "                ",
      "                ",
      "                ",
      "                ",
      "                ",
      "                ",
      "                ",
      "                ",
      "                "
    ],
    [
      "                ",
      "                ",
      "                ",
      "bbbbbbbbbbbbbbbb",
      "cccccccccccccccc",
      "                ",
      "                ",
      "                ",
      "                ",
      "                ",
      "                ",
      "                ",
      "                ",
      "                ",
      "                ",
      "                "
    ],
    [
      "                ",
      "                ",
      "                ",
      "bbbbbbbbbbbbbbbb",
      "cccccccccccccccc",
      "                ",
      "                ",
      "                ",
      "                ",
      "                ",
      "                ",
      "                ",
      "                ",
      "                ",
      "                ",
      "                "
    ],
    [
      "                ",
      "                ",
      "                ",
      "bbbbbbbbbbbbbbbb",
      "cccccccccccccccc",
      "                ",
      "                ",
      "                ",
      "                ",
      "                ",
      "                ",
      "                ",
      "                ",
      "                ",
      "                ",
      "                "
    ],
    [
      "dddddddddddddddd",
      "dddddddddddddddd",
      "eeeeeeeeeeeeeeee",
      "bbbbbbbbbbbbbbbb",
      "cccccccccccccccc",
      "                ",
      "                ",
      "                ",
      "                ",
      "                ",
      "                ",
      "                ",
      "                ",
      "                ",
      "                ",
      "                "
    ],
    [
      "ffffffffffffffff",
      "gggggggggggggggg",
      "bbbbbbbbbbbbbbbb",
      "bbbbbbbbbbbbbbbb",
      "cccccccccccccccc",
      "                ",
      "                ",
      "                ",
      "                ",
      "                ",
      "                ",
      "                ",
      "                ",
      "                ",
      "                ",
      "                "
    ]
  ]
}