{
  "name": "multi_verticalschool_14_floor11",
  "refpalette": "deceasedcraft:multi_verticalschool_14/multi_verticalschool_14_floor11_palette",
  "xsize": 16,
  "zsize": 16,
  "slices": [
    [
      "                ",
      "     a          ",
      "                ",
      "                ",
      "                ",
      "                ",
      "                ",
      "                ",
      "bbbbbbbbbbbbbbbb",
      "                ",
      "                ",
      "                ",
      "                ",
      "                ",
      "                ",
      "                "
    ],
    [
      "    c           ",
      "    de          ",
      "    f           ",
      "                ",
      "                ",
      "                ",
      "                ",
      "                ",
      "bbbbbbbbbbbbbbbb",
      "                ",
      "                ",
      "                ",
      "                ",
      "                ",
      "                ",
      "                "
    ],
    [
      "                ",
      "    g!          ",
      "                ",
      "                ",
      "                ",
      "                ",
      "                ",
      "                ",
      "bbbbbbbbbbbbbbbb",
      "                ",
      "                ",
      "                ",
      "                ",
      "                ",
      "                ",
      "                "
    ],
    [
      "                ",
      "    g           ",
      "                ",
      "                ",
      "                ",
      "                ",
      "                ",
      "                ",
      "bbbbbbbbbbbbbbbb",
      "hhhhhhhhhhhhhhhh",
      "                ",
      "                ",
      "                ",
      "                ",
      "                ",
      "                "
    ],
    [
      "iiijjjjiiiiiiiii",
      "iiijiijiiiiiiiii",
      "iiijjjjiiiiiiiii",
      "iiiiiiiiiiiiiiii",
      "iiiiiiiiiiiiiiii",
      "iiiiiiiiiiiiiiii",
      "iiiiiiiiiiiiiiii",
      "kkkkkkkkkkkkkkkk",
      "llllllllllllllll",
      "mmmmmmmmmmmmmmmm",
      "                ",
      "                ",
      "                ",
      "                ",
      "                ",
      "                "
    ],
    [
      "nnnooooonnnnnnnn",
      "nnnooooooonnnnnn",
      "nnnnoooooooooooo",
      "nnnnnnoooooooooo",
      "nnnnnnnooooooooo",
      "nnnnnnnnnnoooooo",
      "ppnnnnnnnnnnnnnn",
      "lppppppppppppppp",
      "llllllllllllllll",
      "qqqqqqqqqqqqqqqq",
      "                ",
      "                ",
      "                ",
      "                ",
      "                ",
      "                "
    ]
  ]
}