{
  "name": "multi_verticalschool_14_base1",
  "refpalette": "deceasedcraft:multi_verticalschool_14/multi_verticalschool_14_base1_palette",
  "xsize": 16,
  "zsize": 16,
  "slices": [
    [
      "                ",
      "                ",
      "                ",
      "                ",
      "                ",
      "                ",
      "                ",
      "                ",
      "                ",
      "                ",
      "                ",
      "a               ",
      "va              ",
      "bvaa        ccc ",
      "bbvvaaaaaaaaaaaa",
      "vvvvvvvvvvvvvvvv"
    ],
    [
      "                ",
      "                ",
      "                ",
      "                ",
      "                ",
      "                ",
      "                ",
      "                ",
      "                ",
      "                ",
      "                ",
      "a               ",
      "va              ",
      "bvaa        ccc ",
      "bbvvaaaaaaaaaaaa",
      "vvvvvvvvvvvvvvvv"
    ],
    [
      "                ",
      "                ",
      "                ",
      "                ",
      "                ",
      "                ",
      "                ",
      "                ",
      "                ",
      "                ",
      "                ",
      "a               ",
      "va              ",
      "bvaa        ccc ",
      "bbvvaaaaaaaaaaaa",
      "vvvvvvvvvvvvvvvv"
    ],
    [
      "                ",
      "                ",
      "                ",
      "                ",
      "                ",
      "                ",
      "                ",
      "                ",
      "                ",
      "                ",
      "                ",
      "a               ",
      "va              ",
      "bvaa        ccc ",
      "bbvvaaaaaaaaaaaa",
      "vvvvvvvvvvvvvvvv"
    ],
    [
      "             d  ",
      "             d  ",
      "             d  ",
      "             d  ",
      "             d  ",
      "            d   ",
      "            d   ",
      "          dd    ",
      "dddddddddd      ",
      "                ",
      "                ",
      "a               ",
      "va              ",
      "bvaa        ccc ",
      "bbvvaaaaaaaaaaaa",
      "vvvvvvvvvvvvvvvv"
    ],
    [
      "             cee",
      "             cee",
      "             cee",
      "             cee",
      "             cee",
      "            ceee",
      "            ceee",
      "          cceeee",
      "cccccccccceeeeee",
      "eeeeeeeeeeeeeeee",
      "eeeeeeeeeeeeeeee",
      "feeeeeeeeeeeeeee",
      "vfeeeeeeeeeeeeee",
      "gvffeeeeeeeeccce",
      "ggvvffffffffffff",
      "vvvvvvvvvvvvvvvv"
    ]
  ]
}