{
  "name": "multi_verticalschool_14_floor8",
  "refpalette": "deceasedcraft:multi_verticalschool_14/multi_verticalschool_14_floor8_palette",
  "xsize": 16,
  "zsize": 16,
  "slices": [
    [
      "                ",
      "                ",
      "    a        a  ",
      "bbbbbbbbbbbbbbbb",
      "cccccccccccccccc",
      "                ",
      "                ",
      "                ",
      "                ",
      "                ",
      "                ",
      "                ",
      "                ",
      "                ",
      "                ",
      "                "
    ],
    [
      "dddddddddddddddd",
      "dddddddddddddddd",
      "eeeeeeeeeeeeeeee",
      "bbbbbbbbbbbbbbbb",
      "cccccccccccccccc",
      "                ",
      "                ",
      "                ",
      "                ",
      "                ",
      "                ",
      "                ",
      "                ",
      "                ",
      "                ",
      "                "
    ],
    [
      "ffffffffffffffff",
      "gggggggggggggggg",
      "bbbbbbbbbbbbbbbb",
      "bbbbbbbbbbbbbbbb",
      "cccccccccccccccc",
      "                ",
      "                ",
      "                ",
      "                ",
      "                ",
      "                ",
      "                ",
      "                ",
      "                ",
      "                ",
      "                "
    ],
    [
      "                ",
      "hhiiiiiiiiiiiihi",
      "                ",
      "                ",
      "                ",
      "                ",
      "                ",
      "                ",
      "                ",
      "                ",
      "                ",
      "                ",
      "                ",
      "                ",
      "                ",
      "                "
    ],
    [
      "                ",
      "                ",
      "                ",
      "                ",
      "                ",
      "                ",
      "                ",
      "                ",
      "                ",
      "                ",
      "                ",
      "                ",
      "                ",
      "                ",
      "                ",
      "                "
    ],
    [
      "jjjjjjjjjjjjjjjk",
      "kkkkkkkkkkkkkkkk",
      "                ",
      "llllllllllllllll",
      "                ",
      "                ",
      "                ",
      "                ",
      "                ",
      "                ",
      "                ",
      "                ",
      "                ",
      "                ",
      "                ",
      "                "
    ]
  ]
}