{
  "name": "multi_verticalschool_14_ground",
  "refpalette": "deceasedcraft:multi_verticalschool_14/multi_verticalschool_14_ground_palette",
  "xsize": 16,
  "zsize": 16,
  "slices": [
    [
      "             abb",
      "             abb",
      "             abb",
      "             abb",
      "             abb",
      "            abbb",
      "            abbb",
      "          aabbbb",
      "aaaaaaaaaabbbbbb",
      "bbbbbbbbbbbbbb b",
      "bbbbbbbbbbbbbbbb",
      "cccccccccccccccc",
      "bbbbbbbbbbbbbbbb",
      "bbbbbbbbbbbbbbbb",
      "cccccccccccccccc",
      "bbbbbbbbbbbbbbbb"
    ],
    [
      "              d ",
      "              d ",
      "              d ",
      "              d ",
      "             ed ",
      "             d  ",
      "            ed  ",
      "           f    ",
      "         fgg  h ",
      "gggggggggg   ijk",
      "              l ",
      "mmmmmmmmmmmmmmmm",
      "nnnnnnnnnnnnnnnn",
      "nnnnnnnnnnnnnnnn",
      "mmmmmmmmmmmmmmmm",
      "                "
    ],
    [
      "                ",
      "                ",
      "                ",
      "                ",
      "                ",
      "                ",
      "                ",
      "                ",
      "                ",
      "              o ",
      "                ",
      "                ",
      "                ",
      "                ",
      "                ",
      "                "
    ],
    [
      "                ",
      "                ",
      "                ",
      "                ",
      "                ",
      "                ",
      "                ",
      "                ",
      "                ",
      "              p ",
      "                ",
      "                ",
      "                ",
      "                ",
      "                ",
      "                "
    ],
    [
      "                ",
      "                ",
      "                ",
      "                ",
      "                ",
      "                ",
      "                ",
      "                ",
      "                ",
      "              m ",
      "                ",
      "                ",
      "                ",
      "                ",
      "                ",
      "                "
    ],
    [
      "                ",
      "                ",
      "                ",
      "                ",
      "                ",
      "                ",
      "                ",
      "                ",
      "              m ",
      "             mmm",
      "              m ",
      "                ",
      "                ",
      "                ",
      "                ",
      "                "
    ]
  ]
}