{
  "name": "multi_verticalschool_14_floor20",
  "refpalette": "deceasedcraft:multi_verticalschool_14/multi_verticalschool_14_floor20_palette",
  "xsize": 16,
  "zsize": 16,
  "slices": [
    [
      "                ",
      " a  a     a  a  ",
      "bbbbbbbbbbbbbbbb",
      "                ",
      "                ",
      "                ",
      "                ",
      "                ",
      "                ",
      "                ",
      "                ",
      "                ",
      "                ",
      "                ",
      "                ",
      "                "
    ],
    [
      "                ",
      "                ",
      "bbbbbbbbbbbbbbbb",
      "                ",
      "                ",
      "                ",
      "                ",
      "                ",
      "                ",
      "                ",
      "                ",
      "                ",
      "                ",
      "                ",
      "                ",
      "                "
    ],
    [
      "cccccccccccccccc",
      "cccccccccccccccc",
      "bbbbbbbbbbbbbbbb",
      "dddddddddddddddd",
      "                ",
      "                ",
      "                ",
      "                ",
      "                ",
      "                ",
      "                ",
      "                ",
      "                ",
      "                ",
      "                ",
      "                "
    ],
    [
      "eeeeeeeeeeeeeeee",
      "eeeeeeeeeeeeeeee",
      "ffffffffffffffff",
      "gggggggggggggggg",
      "                ",
      "                ",
      "                ",
      "                ",
      "                ",
      "                ",
      "                ",
      "                ",
      "                ",
      "                ",
      "                ",
      "                "
    ],
    [
      "hhhhhihhhhiihhhh",
      "jkjjkjjkjjkjjkjj",
      "ffffffffffffffff",
      "llllllllllllllll",
      "                ",
      "                ",
      "                ",
      "                ",
      "                ",
      "                ",
      "                ",
      "                ",
      "                ",
      "                ",
      "                ",
      "                "
    ],
    [
      "                ",
      " m  m  m  m  m  ",
      "bbbbbbbbbbbbbbbb",
      "                ",
      "                ",
      "                ",
      "                ",
      "                ",
      "                ",
      "                ",
      "                ",
      "                ",
      "                ",
      "                ",
      "                ",
      "                "
    ]
  ]
}