{
  "name": "multi_verticalschool_14_floor23",
  "refpalette": "deceasedcraft:multi_verticalschool_14/multi_verticalschool_14_floor23_palette",
  "xsize": 16,
  "zsize": 16,
  "slices": [
    [
      "                ",
      "                ",
      "                ",
      "aa aaaa aaaa aaa",
      "bbbbbbbbbbbbbbbb",
      "                ",
      "                ",
      "                ",
      "                ",
      "                ",
      "                ",
      "                ",
      "                ",
      "                ",
      "                ",
      "                "
    ],
    [
      "cccccccccccccccc",
      "cccccccccccccccc",
      "cccccccccccccccc",
      "dddddddddddddddd",
      "bbbbbbbbbbbbbbbb",
      "                ",
      "                ",
      "                ",
      "                ",
      "                ",
      "                ",
      "                ",
      "                ",
      "                ",
      "                ",
      "                "
    ],
    [
      "eeeeffffffffffgg",
      "eeeeffffffffffgg",
      "gggggggggggggggg",
      "gggggggggggggggg",
      "bbbbbbbbbbbbbbbb",
      "                ",
      "                ",
      "                ",
      "                ",
      "                ",
      "                ",
      "                ",
      "                ",
      "                ",
      "                ",
      "                "
    ],
    [
      "hij           kl",
      "ihj           ml",
      "kmmmmmmkmkmkmmml",
      "llllllllllllllll",
      "nnnnnnnnnnnnnnnn",
      "                ",
      "                ",
      "                ",
      "                ",
      "                ",
      "                ",
      "                ",
      "                ",
      "                ",
      "                ",
      "                "
    ],
    [
      "oo             p",
      "oo             p",
      "               p",
      "p pppp pppppppp ",
      "                ",
      "                ",
      "                ",
      "                ",
      "                ",
      "                ",
      "                ",
      "                ",
      "                ",
      "                ",
      "                ",
      "                "
    ],
    [
      "                ",
      "                ",
      "                ",
      "                ",
      "                ",
      "                ",
      "                ",
      "                ",
      "                ",
      "                ",
      "                ",
      "                ",
      "                ",
      "                ",
      "                ",
      "                "
    ]
  ]
}