{
  "name": "multi_verticalschool_14_floor10",
  "refpalette": "deceasedcraft:multi_verticalschool_14/multi_verticalschool_14_floor10_palette",
  "xsize": 16,
  "zsize": 16,
  "slices": [
    [
      "                ",
      "               a",
      "aaaaaaaaaaaaaaaa",
      "bbbbbbbbbbbbbbbb",
      "                ",
      "                ",
      "                ",
      "                ",
      "                ",
      "                ",
      "                ",
      "                ",
      "                ",
      "                ",
      "                ",
      "                "
    ],
    [
      "                ",
      "                ",
      "                ",
      "                ",
      "                ",
      "                ",
      "                ",
      "                ",
      "                ",
      "                ",
      "                ",
      "                ",
      "                ",
      "                ",
      "                ",
      "                "
    ],
    [
      "cccccccccccccccc",
      "cccccccccccccccc",
      "cccccccccccccccc",
      "cccccccccccccccc",
      "cccccccccccccccc",
      "dccccccccccccccc",
      "cddddddddddddddd",
      "cccccccccccccccc",
      "                ",
      "eeeeeeeeeeeeeeee",
      "                ",
      "                ",
      "                ",
      "                ",
      "                ",
      "                "
    ],
    [
      "ffggggggffffffff",
      "ffggggggffffffff",
      "ffggggggffffffff",
      "ffggggggffffffff",
      "ffffffffffffffff",
      "ffffffffffffffff",
      "ffffffffffffffff",
      "ffffffffffffffff",
      "hhhhhhhhhhhhhhhh",
      "iiiiiiiiiiiiiiii",
      "                ",
      "                ",
      "                ",
      "                ",
      "                ",
      "                "
    ],
    [
      "   jjjj         ",
      "   jjjj         ",
      "   jjjj         ",
      "                ",
      "                ",
      "                ",
      "                ",
      "   kllm     nop ",
      "hhhhhhhhhhhhhhhh",
      "bbbbbbbbbbbbbbbb",
      "                ",
      "                ",
      "                ",
      "                ",
      "                ",
      "                "
    ],
    [
      "    q           ",
      "   rs r         ",
      "                ",
      "                ",
      "                ",
      "                ",
      "                ",
      "                ",
      "tttttttttttttttt",
      "                ",
      "                ",
      "                ",
      "                ",
      "                ",
      "                ",
      "                "
    ]
  ]
}