{
  "name": "multi_alienresearch_15_base3",
  "refpalette": "deceasedcraft:multi_alienresearch_15/multi_alienresearch_15_base3_palette",
  "xsize": 16,
  "zsize": 16,
  "slices": [
    [
      "aaaaaaaaaaaaaaav",
      "aaaaaaaaaaaaaaav",
      "aaaaaaaaaaaaaaav",
      "aaaaaaaaaaaaaaav",
      "aaaabbbbbbbbbbbv",
      "aaaabb       bbv",
      "aaaab         bv",
      "aaaab   ccc   bv",
      "aaaab  c   c  bv",
      "aaaab  c   c  bv",
      "aaaab  c   cddbv",
      "aaaab  ecccfffbv",
      "aaaab     gfffbv",
      "aaaabb    gffhbv",
      "aaaabbbbbbbbbbbv",
      "vvvvvvvvvvvvvvvv"
    ],
    [
      "aaaaaaaaaaaaaaav",
      "aaaaaaaaaaaaaaav",
      "aaaaaaaaaaaaaaav",
      "aaaaaaaaaaaaaaav",
      "aaaabbbbbbbbbbbv",
      "aaaabb       bbv",
      "aaaab         bv",
      "aaaab   ccc   bv",
      "aaaab  c   cddbv",
      "aaaab  c   cffbv",
      "aaaab  c   cggbv",
      "aaaab   ccci  bv",
      "aaaab         bv",
      "aaaabb       hbv",
      "aaaabbbbbbbbbbbv",
      "vvvvvvvvvvvvvvvv"
    ],
    [
      "aaaaaaaaaaaaaaav",
      "aaaaaaaaaaaaaaav",
      "aaaaaaaaaaaaaaav",
      "aaaaaaaaaaaaaaav",
      "aaaabbbbbbbbbbbv",
      "aaaabb    dffbbv",
      "aaaab     dfffbv",
      "aaaab   cccfffbv",
      "aaaab  c   cggbv",
      "aaaab  c   c  bv",
      "aaaab  c   c  bv",
      "aaaab   ccce  bv",
      "aaaab         bv",
      "aaaabb       hbv",
      "aaaabbbbbbbbbbbv",
      "vvvvvvvvvvvvvvvv"
    ],
    [
      "aaaaaaaaaaaaaaav",
      "aaaaaaaaaaaaaaav",
      "aaaaaaaaaaaaaaav",
      "aaaaaaaaaaaaaaav",
      "aaaabbbbbbbbbbbv",
      "aaaabb  dfg  bbv",
      "aaaab   dfg   bv",
      "aaaab   ccci  bv",
      "aaaab  c   c  bv",
      "aaaab  c   c  bv",
      "aaaab  c   c  bv",
      "aaaab   ccc   bv",
      "aaaab         bv",
      "aaaabb       hbv",
      "aaaabbbbbbbbbbbv",
      "vvvvvvvvvvvvvvvv"
    ],
    [
      "aaaaaaaaaaaaaaav",
      "aaaaaaaaaaaaaaav",
      "aaaaaaaaaaaaaaav",
      "aaaaaaaaaaaaaaav",
      "aaaabbbbbbbbbbbv",
      "aaaabbffg    bbv",
      "aaaabfffg     bv",
      "aaaabfffccce  bv",
      "aaaabddc   c  bv",
      "aaaab  c   c  bv",
      "aaaab  c   c  bv",
      "aaaab   ccc   bv",
      "aaaab         bv",
      "aaaabb       hbv",
      "aaaabbbbbbbbbbbv",
      "vvvvvvvvvvvvvvvv"
    ],
    [
      "aaaaaaaaaaaaaaav",
      "aaaaaaaaaaaaaaav",
      "aaaaaaaaaaaaaaav",
      "aaaaaaaaaaaaaaav",
      "aaaabbbbbbbbbbbv",
      "aaaabb       bbv",
      "aaaab         bv",
      "aaaab  iccc   bv",
      "aaaabggc   c  bv",
      "aaaabffc   c  bv",
      "aaaabddc   c  bv",
      "aaaab   ccc   bv",
      "aaaab         bv",
      "aaaabb       hbv",
      "aaaabbbbbbbbbbbv",
      "vvvvvvvvvvvvvvvv"
    ]
  ]
}