{
  "name": "multi_alienresearch_15_base5",
  "refpalette": "deceasedcraft:multi_alienresearch_15/multi_alienresearch_15_base5_palette",
  "xsize": 16,
  "zsize": 16,
  "slices": [
    [
      "              av",
      "              av",
      "              av",
      "              av",
      "      bbbbb   av",
      "     cdde    cav",
      "    fddde     av",
      "     dddgggh  av",
      "     iig   j  av",
      "       g   j  av",
      "       g   j  av",
      "        jjj   av",
      "              av",
      "     c       kav",
      "aaaaaaaaaaaaaaav",
      "vvvvvvvvvvvvvvvv"
    ],
    [
      "              av",
      "              av",
      "              av",
      "              av",
      "      bb      av",
      "     c       cav",
      "    f         av",
      "    f  cggg   av",
      "    feeg   j  av",
      "    fddg   j  av",
      "     iig   j  av",
      "        jjj   av",
      "              av",
      "     c       kav",
      "aaaaaaaaaaaaaaav",
      "vvvvvvvvvvvvvvvv"
    ],
    [
      "              av",
      "              av",
      "              av",
      "              av",
      "              av",
      "     c       cav",
      "              av",
      "       hggg   av",
      "    f  g   j  av",
      "    f  g   j  av",
      "    feeg   j  av",
      "    fdddjjj   av",
      "    fdddi     av",
      "     cddi    kav",
      "aaaaaaaaaaaaaaav",
      "vvvvvvvvvvvvvvvv"
    ],
    [
      "              av",
      "              av",
      "              av",
      "              av",
      "              av",
      "     c       cav",
      "              av",
      "        ggg   av",
      "       g   j  av",
      "       g   j  av",
      "       g   j  av",
      "    f  cjjj   av",
      "    f   edi   av",
      "     c  edi  lav",
      "aaaaaaaaaaaaaaav",
      "vvvvvvvvvvvvvvvv"
    ],
    [
      "              av",
      "              av",
      "              av",
      "              av",
      "              av",
      "     c       cav",
      "              av",
      "        ggg   av",
      "       g   j  av",
      "       g   j  av",
      "       g   jiiav",
      "       hjjjdddav",
      "          edddav",
      "     c    eddkav",
      "aaaaaaaaaaaaaaav",
      "vvvvvvvvvvvvvvvv"
    ],
    [
      "   m          av",
      "   m          av",
      "   m          av",
      "mmmm   mmmmm  av",
      "              av",
      "     c       cav",
      "              av",
      "   m    ggg   av",
      "   m   g   jiiav",
      "   m   g   jddav",
      "   m   g   jeeav",
      "   m    jjjc  av",
      "              av",
      "     c       kav",
      "aaaaaaaaaaaaaaav",
      "vvvvvvvvvvvvvvvv"
    ]
  ]
}