{
  "name": "multi_alienresearch_15_base1",
  "refpalette": "deceasedcraft:multi_alienresearch_15/multi_alienresearch_15_base1_palette",
  "xsize": 16,
  "zsize": 16,
  "slices": [
    [
      "aaaabbbbaaaaaaav",
      "aaaabbbbcccccaav",
      "aaaabbbbcccccaav",
      "aaaabbbbcccccaav",
      "aaaabbbbbbbbbbbv",
      "aaaabbbbd    bbv",
      "aaaabbbbd     bv",
      "aaaabbbbbbbe  bv",
      "aaaabbbb   b  bv",
      "aaaabbbb   b  bv",
      "aaaabbbb    f bv",
      "aaaabbbbbbbgbbbv",
      "aaaabhhhhhhhhhbv",
      "aaaabbiiiiiiijbv",
      "aaaabbbbbbbbbbbv",
      "vvvvvvvvvvvvvvvv"
    ],
    [
      "aaaak  kaaaaaaav",
      "aaaaklmkcccccaav",
      "aaaanopnc   caav",
      "aaaakqqkcccccaav",
      "aaaak  kkkkkkkkv",
      "aaaak        kkv",
      "aaaak         kv",
      "aaaak  rkkk   kv",
      "aaaak  s   k  kv",
      "aaaak  k   k  kv",
      "aaaakt k   k  kv",
      "aaaakkukkkkkkkkv",
      "aaaakw  x y AAkv",
      "aaaak!     xAjkv",
      "aaaakkkkkkkkkkkv",
      "vvvvvvvvvvvvvvvv"
    ],
    [
      "aaaak  kaaaaaaav",
      "aaaakl kcccccaav",
      "aaaaBCDEFI  caav",
      "aaaak  kcccccaav",
      "aaaak  kkkkkkkkv",
      "aaaak        kkv",
      "aaaak         kv",
      "aaaak   kkk   kv",
      "aaaak  J   k  kv",
      "aaaak  k   k  kv",
      "aaaakK k   k  kv",
      "aaaakkLkkkkkkkkv",
      "aaaak     M  Nkv",
      "aaaakw      Ojkv",
      "aaaakkkkkkkkkkkv",
      "vvvvvvvvvvvvvvvv"
    ],
    [
      "aaaak  kaaaaaaav",
      "aaaak  kcccccaav",
      "aaaakbbkcP  caav",
      "aaaak  kcccccaav",
      "aaaak  kkkkkkkkv",
      "aaaak        kkv",
      "aaaak         kv",
      "aaaak  Qkkk   kv",
      "aaaak  k   k  kv",
      "aaaak  k   k  kv",
      "aaaakR k   k  kv",
      "aaaakkkkkkkkkkkv",
      "aaaak    MM   kv",
      "aaaak        jkv",
      "aaaakkkkkkkkkkkv",
      "vvvvvvvvvvvvvvvv"
    ],
    [
      "aaaak  kaaaaaaav",
      "aaaak lkcccccaav",
      "aaaakbbkcccccaav",
      "aaaak  kcccccaav",
      "aaaak  kkkkkkkkv",
      "aaaak        kkv",
      "aaaak         kv",
      "aaaak  Skkk   kv",
      "aaaak  k   k  kv",
      "aaaak  k   k  kv",
      "aaaak  k   k  kv",
      "aaaakkkkkkkkkkkv",
      "aaaak   Ty   ykv",
      "aaaaky      yjkv",
      "aaaakkkkkkkkkkkv",
      "vvvvvvvvvvvvvvvv"
    ],
    [
      "aaaakiikaaaaaaav",
      "aaaakiikaaaaaaav",
      "aaaakbbkaaaaaaav",
      "aaaakbbkaaaaaaav",
      "aaaakbbkkkkkkkkv",
      "aaaakbbbbbbbbkkv",
      "aaaakbbbbbbbbbkv",
      "aaaakbbbAAUbbbkv",
      "aaaakbbA  MAbbkv",
      "aaaakbbA  VAbbkv",
      "aaaakbbA  WAbbkv",
      "aaaakkkkAAXkkkkv",
      "aaaakbbY MyZbbkv",
      "aaaakbbbbbbbbjkv",
      "aaaakkkkkkkkkkkv",
      "vvvvvvvvvvvvvvvv"
    ]
  ]
}