{
  "name": "multi_alienresearch_15_base6",
  "refpalette": "deceasedcraft:multi_alienresearch_15/multi_alienresearch_15_base6_palette",
  "xsize": 16,
  "zsize": 16,
  "slices": [
    [
      "aaaaaaaaaaaaaabv",
      "aaaaaaaaaaaaaabv",
      "aaaaaaaaaaaaaabv",
      "aaaaaaaaaaaaaabv",
      "aaaaaaaaaaaaaabv",
      "aaaaaaaaaaaaaabv",
      "aaaaaaaaaaaaaabv",
      "aaaaaaaaccccccbv",
      "aaaaaaacdddaeebv",
      "aaaaaaacddda  bv",
      "aaaaaaacdd  f bv",
      "aaaaaaacaaagh bv",
      "aaaaaaaci  j  bv",
      "aaaaaaaci    kbv",
      "bbbbbbbbbbbbbbbv",
      "vvvvvvvvvvvvvvvv"
    ],
    [
      "  lm       n obv",
      "  lmp      n obv",
      "qq!m         rbv",
      "sss           bv",
      "  t           bv",
      "     u       ubv",
      "              bv",
      "       wxyyABCbv",
      "       Dw Ea  bv",
      "       y  Ea  bv",
      "       yFFIa  bv",
      "nn     uaaaJ  bv",
      "        eci   bv",
      "KKL  u  eci  Mbv",
      "bbbbbbbbbbbbbbbv",
      "vvvvvvvvvvvvvvvv"
    ],
    [
      "NN O          bv",
      "NN            bv",
      "              bv",
      " P            bv",
      "              bv",
      "     u       ubv",
      "              bv",
      "        QyyARSbv",
      "       T  Ea  bv",
      "       y  Ea  bv",
      "       yFFUaiibv",
      "       Vaaacccbv",
      "          ecccbv",
      "     u    ecckbv",
      "bbbbbbbbbbbbbbbv",
      "vvvvvvvvvvvvvvvv"
    ],
    [
      "              bv",
      "              bv",
      "              bv",
      "              bv",
      "              bv",
      "     u       ubv",
      "              bv",
      "        yyyAWWbv",
      "       y  Eaiibv",
      "       y  Eaccbv",
      "       yFFXaeebv",
      "        aaau  bv",
      "              bv",
      "     u       kbv",
      "bbbbbbbbbbbbbbbv",
      "vvvvvvvvvvvvvvvv"
    ],
    [
      "              bv",
      "              bv",
      "              bv",
      "              bv",
      "            Y bv",
      "     u    iccubv",
      "          icccbv",
      "        yyycccbv",
      "       yZZ0aeebv",
      "       yZZ0a  bv",
      "       y112a  bv",
      "        aaaV  bv",
      "              bv",
      "     u       kbv",
      "bbbbbbbbbbbbbbbv",
      "vvvvvvvvvvvvvvvv"
    ],
    [
      "              bv",
      "              bv",
      "              bv",
      "              bv",
      "         YYYY bv",
      "     u  ice  ubv",
      "        ice   bv",
      "        yyyu  bv",
      "       y   a  bv",
      "       y   a  bv",
      "       y   a  bv",
      "        aaa   bv",
      "              bv",
      "     u       kbv",
      "bbbbbbbbbbbbbbbv",
      "vvvvvvvvvvvvvvvv"
    ]
  ]
}