{
  "name": "multi_alienresearch_15_base8",
  "refpalette": "deceasedcraft:multi_alienresearch_15/multi_alienresearch_15_base8_palette",
  "xsize": 16,
  "zsize": 16,
  "slices": [
    [
      "aaaabaaaaaaaaabv",
      "aaaabaaaaaaaaabv",
      "aaaabaaaaaaaaabv",
      "aaaabaaaaaaaaabv",
      "bbbbbaaaaaaaaabv",
      "aaaaaaaaaaaaaabv",
      "aaaaaaaaaaaaaabv",
      "aaaaaaaaccccccbv",
      "aaaaaaac   cddbv",
      "aaaaaaac   c  bv",
      "aaaaaaac    e bv",
      "aaaaaaaacccfg bv",
      "aaaaaaaah  i  bv",
      "aaaaaaaah    jbv",
      "bbbbbbbbbbbbbbbv",
      "vvvvvvvvvvvvvvvv"
    ],
    [
      "    k         bv",
      "    l         bv",
      "   mb    n    bv",
      "  opbq  nr n  bv",
      "stbbbq   n    bv",
      "  uwwx       xbv",
      "              bv",
      "       yABBCDEbv",
      "   n   F   B  bv",
      " n rn  B   B  bv",
      "   n   B   B  bv",
      "        BBBI  bv",
      "        dch   bv",
      "     x  dch  jbv",
      "bbbbbbbbbbbbbbbv",
      "vvvvvvvvvvvvvvvv"
    ],
    [
      "    J         bv",
      "    K         bv",
      "    b         bv",
      "    b    L    bv",
      "MNbbb         bv",
      "     x       xbv",
      "              bv",
      "        OBBCPQbv",
      "       R   B  bv",
      "   !   B   B  bv",
      "       B   Bhhbv",
      "        BBBcccbv",
      "          dcccbv",
      "     x    dccjbv",
      "bbbbbbbbbbbbbbbv",
      "vvvvvvvvvvvvvvvv"
    ],
    [
      "    b         bv",
      "    b         bv",
      "    b         bv",
      "    b         bv",
      "bbbbb         bv",
      "     x       xbv",
      "            S bv",
      "        BBBCTTbv",
      "       B   Bhhbv",
      "       B   Bccbv",
      "       B   Bddbv",
      "        BBB   bv",
      "              bv",
      "     x       jbv",
      "bbbbbbbbbbbbbbbv",
      "vvvvvvvvvvvvvvvv"
    ],
    [
      "    b         bv",
      "    b         bv",
      "    b         bv",
      "    b         bv",
      "bbbbb       U bv",
      "     x    hccxbv",
      "          hcccbv",
      "        BBBcccbv",
      "       B   Bddbv",
      "       B   B  bv",
      "       B   B  bv",
      "        BBB   bv",
      "              bv",
      "     x       jbv",
      "bbbbbbbbbbbbbbbv",
      "vvvvvvvvvvvvvvvv"
    ],
    [
      "    b         bv",
      "    b         bv",
      "    b         bv",
      "    b         bv",
      "bbbbb    UUUU bv",
      "     x  hcd  xbv",
      "        hcd   bv",
      "        BBB   bv",
      "       B   B  bv",
      "       B   B  bv",
      "       B   B  bv",
      "        BBB   bv",
      "              bv",
      "     x       jbv",
      "bbbbbbbbbbbbbbbv",
      "vvvvvvvvvvvvvvvv"
    ]
  ]
}