{
  "name": "multi_alienresearch_15_base7",
  "refpalette": "deceasedcraft:multi_alienresearch_15/multi_alienresearch_15_base7_palette",
  "xsize": 16,
  "zsize": 16,
  "slices": [
    [
      "aaaabcc       bv",
      "aaaabcc       bv",
      "aaaabcc       bv",
      "aaaabcc       bv",
      "bbbbbccdddd   bv",
      "ccccceeef    gbv",
      "ccccceeef     bv",
      "     eeehhh   bv",
      "     cch   h  bv",
      "       h   h  bv",
      "       h   h  bv",
      "        hhh   bv",
      "              bv",
      "     g       ibv",
      "bbbbbbbbbbbbbbbv",
      "vvvvvvvvvvvvvvvv"
    ],
    [
      "    j k       bv",
      "    l k       bv",
      "   mb k       bv",
      "  n!b k       bv",
      "opbbb kd      bv",
      "     g       gbv",
      "ddddd         bv",
      "    k   hhh   bv",
      "    kffh   h  bv",
      "    keeh   h  bv",
      "     cch   h  bv",
      "        hhh   bv",
      "              bv",
      "     g       ibv",
      "bbbbbbbbbbbbbbbv",
      "vvvvvvvvvvvvvvvv"
    ],
    [
      "    q         bv",
      "    r         bv",
      "    b         bv",
      "    b         bv",
      "stbbb         bv",
      "     g       gbv",
      "              bv",
      "        hhh   bv",
      "    k  h   h  bv",
      "    k  h   h  bv",
      "    kffh   h  bv",
      "    keeehhh   bv",
      "    keeec     bv",
      "     geec    ibv",
      "bbbbbbbbbbbbbbbv",
      "vvvvvvvvvvvvvvvv"
    ],
    [
      "    b         bv",
      "    b         bv",
      "    b         bv",
      "    b         bv",
      "bbbbb         bv",
      "     g       gbv",
      "              bv",
      "        hhh   bv",
      "       h   h  bv",
      "       h   h  bv",
      "       h   h  bv",
      "    k   hhh   bv",
      "    k   fec   bv",
      "     g  fec  ibv",
      "bbbbbbbbbbbbbbbv",
      "vvvvvvvvvvvvvvvv"
    ],
    [
      "    b         bv",
      "    b         bv",
      "    b         bv",
      "    b         bv",
      "bbbbb         bv",
      "     g       gbv",
      "              bv",
      "        hhh   bv",
      "       h   h  bv",
      "       h   h  bv",
      "       h   hccbv",
      "        hhheeebv",
      "          feeebv",
      "     g    feeibv",
      "bbbbbbbbbbbbbbbv",
      "vvvvvvvvvvvvvvvv"
    ],
    [
      "    b         bv",
      "    b         bv",
      "    b         bv",
      "    b         bv",
      "bbbbb         bv",
      "     g       gbv",
      "              bv",
      "        hhh   bv",
      "       h   hccbv",
      "       h   heebv",
      "       h   hffbv",
      "        hhh u bv",
      "           w  bv",
      "     g       ibv",
      "bbbbbbbbbbbbbbbv",
      "vvvvvvvvvvvvvvvv"
    ]
  ]
}