{
  "name": "multi_alienresearch_15_base2",
  "refpalette": "deceasedcraft:multi_alienresearch_15/multi_alienresearch_15_base2_palette",
  "xsize": 16,
  "zsize": 16,
  "slices": [
    [
      "aaaaaaaaaaaaaaav",
      "aaaaaaaaaaaaaaav",
      "aaaaaaaaaaaaaaav",
      "aaaaaaaaaaaaaaav",
      "aaaabbbbbbbbbbbv",
      "aaaabb       bbv",
      "aaaab         bv",
      "aaaab  cddd   bv",
      "aaaab  d   d  bv",
      "aaaab  d   d  bv",
      "aaaabeed   d  bv",
      "aaaabfffddd   bv",
      "aaaabfffg     bv",
      "aaaabbffg    hbv",
      "aaaabbbbbbbbbbbv",
      "vvvvvvvvvvvvvvvv"
    ],
    [
      "aaaaaaaaaaaaaaav",
      "aaaaaaaaaaaaaaav",
      "aaaaaaaaaaaaaaav",
      "aaaaaaaaaaaaaaav",
      "aaaabbbbbbbbbbbv",
      "aaaabb       bbv",
      "aaaab         bv",
      "aaaab   ddd   bv",
      "aaaab  d   d  bv",
      "aaaab  d   d  bv",
      "aaaab  d   d  bv",
      "aaaab  iddd   bv",
      "aaaab   efg   bv",
      "aaaabb  efg  jbv",
      "aaaabbbbbbbbbbbv",
      "vvvvvvvvvvvvvvvv"
    ],
    [
      "aaaaaaaaaaaaaaav",
      "aaaaaaaaaaaaaaav",
      "aaaaaaaaaaaaaaav",
      "aaaaaaaaaaaaaaav",
      "aaaabbbbbbbbbbbv",
      "aaaabb       bbv",
      "aaaab         bv",
      "aaaab   ddd   bv",
      "aaaab  d   d  bv",
      "aaaab  d   d  bv",
      "aaaab  d   dggbv",
      "aaaab  cdddfffbv",
      "aaaab     efffbv",
      "aaaabb    effhbv",
      "aaaabbbbbbbbbbbv",
      "vvvvvvvvvvvvvvvv"
    ],
    [
      "aaaaaaaaaaaaaaav",
      "aaaaaaaaaaaaaaav",
      "aaaaaaaaaaaaaaav",
      "aaaaaaaaaaaaaaav",
      "aaaabbbbbbbbbbbv",
      "aaaabb       bbv",
      "aaaab         bv",
      "aaaab   ddd   bv",
      "aaaab  d   dggbv",
      "aaaab  d   dffbv",
      "aaaab  d   deebv",
      "aaaab   dddi  bv",
      "aaaab         bv",
      "aaaabb       hbv",
      "aaaabbbbbbbbbbbv",
      "vvvvvvvvvvvvvvvv"
    ],
    [
      "aaaaaaaaaaaaaaav",
      "aaaaaaaaaaaaaaav",
      "aaaaaaaaaaaaaaav",
      "aaaaaaaaaaaaaaav",
      "aaaabbbbbbbbbbbv",
      "aaaabb    gffbbv",
      "aaaab     gfffbv",
      "aaaab   dddfffbv",
      "aaaab  d   deebv",
      "aaaab  d   d  bv",
      "aaaab  d   d  bv",
      "aaaab   dddc  bv",
      "aaaab         bv",
      "aaaabb       hbv",
      "aaaabbbbbbbbbbbv",
      "vvvvvvvvvvvvvvvv"
    ],
    [
      "aaaaaaaaaaaaaaav",
      "aaaaaaaaaaaaaaav",
      "aaaaaaaaaaaaaaav",
      "aaaaaaaaaaaaaaav",
      "aaaabbbbbbbbbbbv",
      "aaaabb  gfe  bbv",
      "aaaab   gfe   bv",
      "aaaab   dddi  bv",
      "aaaab  d   d  bv",
      "aaaab  d   d  bv",
      "aaaab  d   d  bv",
      "aaaab   dddk  bv",
      "aaaab         bv",
      "aaaabb       hbv",
      "aaaabbbbbbbbbbbv",
      "vvvvvvvvvvvvvvvv"
    ]
  ]
}