{
  "name": "multi_alienresearch_15_base4",
  "refpalette": "deceasedcraft:multi_alienresearch_15/multi_alienresearch_15_base4_palette",
  "xsize": 16,
  "zsize": 16,
  "slices": [
    [
      "aaaaaaaaaaaaaabv",
      "aaaaaaaaaaaaaabv",
      "aaaaaaaaaaaaaabv",
      "aaaaaaaaaaaaaabv",
      "aaaaaaaaaaaaaabv",
      "aaaaab    cddbbv",
      "aaaaa     cdddbv",
      "aaaaa   ddddddbv",
      "aaaaa  d   deebv",
      "aaaaa  d   d  bv",
      "aaaaa  d   d  bv",
      "aaaaa   dddf  bv",
      "aaaaa         bv",
      "aaaaab       gbv",
      "bbbbbbbbbbbbbbbv",
      "vvvvvvvvvvvvvvvv"
    ],
    [
      "hhhhhhhhhhhhhhhv",
      "hhhhhhhhhhhhhhhv",
      "hhhhhhhhhhhhhhhv",
      "hhhhhhhhhhhhhhhv",
      "hhhhbbbbbbbbbbbv",
      "hhhhbb  cde  bbv",
      "hhhhb   cde   bv",
      "hhhhb   aaai  bv",
      "hhhhb  a   a  bv",
      "hhhhb  a   a  bv",
      "hhhhb  a   a  bv",
      "hhhhb   aaa   bv",
      "hhhhb         bv",
      "hhhhbb       gbv",
      "hhhhbbbbbbbbbbbv",
      "vvvvvvvvvvvvvvvv"
    ],
    [
      "hhhhhhhhhhhhhhhv",
      "hhhhhhhhhhhhhhhv",
      "hhhhhhhhhhhhhhhv",
      "hhhhhhhhhhhhhhhv",
      "hhhhbbbbbbbbbbbv",
      "hhhhbbdde    bbv",
      "hhhhbddde     bv",
      "hhhhbdddaaaf  bv",
      "hhhhbcca   a  bv",
      "hhhhb  a   a  bv",
      "hhhhb  a   a  bv",
      "hhhhb   aaa   bv",
      "hhhhb         bv",
      "hhhhbb       gbv",
      "hhhhbbbbbbbbbbbv",
      "vvvvvvvvvvvvvvvv"
    ],
    [
      "hhhhhhhhhhhhhhhv",
      "hhhhhhhhhhhhhhhv",
      "hhhhhhhhhhhhhhhv",
      "hhhhhhhhhhhhhhhv",
      "hhhhbbbbbbbbbbbv",
      "hhhhbb       bbv",
      "hhhhb         bv",
      "hhhhb  iaaa   bv",
      "hhhhbeea   a  bv",
      "hhhhbdda   a  bv",
      "hhhhbcca   a  bv",
      "hhhhb   aaa   bv",
      "hhhhb         bv",
      "hhhhbb       gbv",
      "hhhhbbbbbbbbbbbv",
      "vvvvvvvvvvvvvvvv"
    ],
    [
      "hhhhhhhhhhhhhhhv",
      "hhhhhhhhhhhhhhhv",
      "hhhhhhhhhhhhhhhv",
      "hhhhhhhhhhhhhhhv",
      "hhhhbbbbbbbbbbbv",
      "hhhhbb       bbv",
      "hhhhb         bv",
      "hhhhb  !aaa   bv",
      "hhhhb  a   a  bv",
      "hhhhb  a   a  bv",
      "hhhhbeea   a  bv",
      "hhhhbdddaaa   bv",
      "hhhhbdddc     bv",
      "hhhhbbddc    gbv",
      "hhhhbbbbbbbbbbbv",
      "vvvvvvvvvvvvvvvv"
    ],
    [
      "hhhhhhhhhhhhhhhv",
      "hhhhhhhhhhhhhhhv",
      "hhhhhhhhhhhhhhhv",
      "hhhhhhhhhhhhhhhv",
      "hhhhbbbbbbbbbbbv",
      "hhhhbb       bbv",
      "hhhhb         bv",
      "hhhhb   aaa   bv",
      "hhhhb  a   a  bv",
      "hhhhb  a   a  bv",
      "hhhhb  a   a  bv",
      "hhhhb  iaaa   bv",
      "hhhhb   edc   bv",
      "hhhhbb  edc  jbv",
      "hhhhbbbbbbbbbbbv",
      "vvvvvvvvvvvvvvvv"
    ]
  ]
}