{
  "name": "multi_alienresearch_15_top",
  "refpalette": "deceasedcraft:multi_alienresearch_15/multi_alienresearch_15_top_palette",
  "xsize": 16,
  "zsize": 16,
  "slices": [
    [
      "       abcd     ",
      "       abcd     ",
      "  efeeeabcd     ",
      "       abgd     ",
      "       abcd     ",
      "       abgd     ",
      "       abcd     ",
      "       abcd     ",
      "       a gd     ",
      "  efeeeabcd     ",
      "hhhhhhhhhi      ",
      "                ",
      "                ",
      "                ",
      "                ",
      "                "
    ],
    [
      "  f abcg        ",
      "  f abcg        ",
      "feeeabgg        ",
      "  f abcg        ",
      "  f abcg        ",
      "  f abcg        ",
      "  f abcg        ",
      "  f abc         ",
      "  f abc         ",
      "feeeabcg        ",
      "hhjhhhid        ",
      "                ",
      "                ",
      "                ",
      "                ",
      "                "
    ],
    [
      " abcg           ",
      " abcg           ",
      "eabcg           ",
      " abcg           ",
      " abcg           ",
      " abcg           ",
      " abcg           ",
      " abc            ",
      " abcg           ",
      "eabcg           ",
      "hh id           ",
      "                ",
      "                ",
      "                ",
      "                ",
      "                "
    ],
    [
      "c               ",
      "k               ",
      "gg              ",
      "cg              ",
      "lg              ",
      "cg              ",
      "cg              ",
      "lg              ",
      "cg              ",
      "cg              ",
      "id              ",
      "                ",
      "                ",
      "                ",
      "                ",
      "                "
    ]
  ]
}