{
  "name": "multi_alienresearch_15_base9",
  "refpalette": "deceasedcraft:multi_alienresearch_15/multi_alienresearch_15_base9_palette",
  "xsize": 16,
  "zsize": 16,
  "slices": [
    [
      "aaaabcccccccccbv",
      "aaaabcccccccccbv",
      "aaaabcccccccccbv",
      "aaaabcccccccccbv",
      "aaaabcccccccccbv",
      "aaaabcccccccccbv",
      "aaaabcccccccccbv",
      "aaaabcccccccccbv",
      "aaaabcccdddcccbv",
      "aaaabcccdddcccbv",
      "aaaabcccdddcccbv",
      "aaaabcccccccccbv",
      "aaaabcccccccccbv",
      "aaaabbccccccccbv",
      "aaaabbbbbbbbbbbv",
      "vvvvvvvvvvvvvvvv"
    ],
    [
      "aaaab efe efe bv",
      "aaaab efe efe bv",
      "aaaab fgf fgf bv",
      "aaaab         bv",
      "aaaab         bv",
      "aaaabh       hbv",
      "aaaab         bv",
      "aaaab  hiiih  bv",
      "aaaab  ij kik bv",
      "aaaablli kmi  bv",
      "aaaabcci jji  bv",
      "aaaabccciii  kbv",
      "aaaabccck n  obv",
      "aaaabbccpk  qrbv",
      "aaaabbbbbbbbbbbv",
      "vvvvvvvvvvvvvvvv"
    ],
    [
      "aaaab sst sst bv",
      "aaaab sss sss bv",
      "aaaab ggg ggg bv",
      "aaaab  u   w  bv",
      "aaaab         bv",
      "aaaabh       hbv",
      "aaaab         bv",
      "aaaab  hiiih  bv",
      "aaaab  i  ki  bv",
      "aaaab  i   !k bv",
      "aaaabllij ki  bv",
      "aaaabccciiik  bv",
      "aaaabcccx     bv",
      "aaaabbccx     bv",
      "aaaabbbbbbbbbbbv",
      "vvvvvvvvvvvvvvvv"
    ],
    [
      "aaaab sss sss bv",
      "aaaab  s   s  bv",
      "aaaab         bv",
      "aaaab         bv",
      "aaaab         bv",
      "aaaabh       hbv",
      "aaaab         bv",
      "aaaab  hiiih  bv",
      "aaaab  i   i  bv",
      "aaaab  i   i  bv",
      "aaaab  ik  i  bv",
      "aaaab   iii   bv",
      "aaaab   ycx  kbv",
      "aaaabb  ycxk Abv",
      "aaaabbbbbbbbbbbv",
      "vvvvvvvvvvvvvvvv"
    ],
    [
      "aaaab         bv",
      "aaaab         bv",
      "aaaab         bv",
      "aaaab         bv",
      "aaaab         bv",
      "aaaabh       hbv",
      "aaaab         bv",
      "aaaab  hiiih  bv",
      "aaaab  i   i  bv",
      "aaaab  i   i  bv",
      "aaaab  i   ixxbv",
      "aaaab   iiicccbv",
      "aaaab     ycccbv",
      "aaaabb    yccBbv",
      "aaaabbbbbbbbbbbv",
      "vvvvvvvvvvvvvvvv"
    ],
    [
      "aaaabxxxxxxxxxbv",
      "aaaabxxxxxxxxxbv",
      "aaaabxxxxxxxxxbv",
      "aaaabxxxxxxxxxbv",
      "aaaabxxxxxxxxxbv",
      "aaaabiiiiiiiiibv",
      "aaaab         bv",
      "aaaab  hiiih  bv",
      "aaaab  idddixxbv",
      "aaaab  idddiccbv",
      "aaaab  idddiyybv",
      "aaaab   iii C bv",
      "aaaab      D  bv",
      "aaaabb       Bbv",
      "aaaabbbbbbbbbbbv",
      "vvvvvvvvvvvvvvvv"
    ]
  ]
}