{
  "name": "multi_alienresearch_15_ground",
  "refpalette": "deceasedcraft:multi_alienresearch_15/multi_alienresearch_15_ground_palette",
  "xsize": 16,
  "zsize": 16,
  "slices": [
    [
      "abczdeddddcvfzgz",
      "bbceeedzeecvggzz",
      "bbhdddeddhcvfzzz",
      "bbczeeddeecvfgzz",
      "bbceddedddcvffzz",
      "bbcdedddezcffgzz",
      "abcddddddecvfggz",
      "bbcededddecvfgzz",
      "bbcdddddedcvfzgz",
      "bbhdezeddhcfgfzz",
      "cccccccccccvfgzz",
      "fvvvvfvfvfvffgzz",
      "gfffvfffvvfvfgzg",
      "fzgggggfggfgzfgz",
      "zzzfzzzzgzzzzgzz",
      "zgzzzgzzzgzzgzzz"
    ],
    [
      "  ijk lk  m  n  ",
      "  i ll j om  nj ",
      "  picqrcipm  n  ",
      "  sj    t!m  n  ",
      "          m  nj ",
      "         um  nj ",
      "         wm  n j",
      "          m  n  ",
      "        xsm  n  ",
      "ltptl    pm  nj ",
      "mmmmmmmmmmm  n  ",
      "             n  ",
      "             nj ",
      "nnnnnnnnnnnnnn j",
      "j     j    j    ",
      "    j  j     j  "
    ],
    [
      "  y       A  n  ",
      "  B       A  n  ",
      "  pBBCDyypA  n  ",
      "         tA  n  ",
      "          A  n  ",
      "         w   n  ",
      "         wE  n  ",
      "          A  n  ",
      "          A  n  ",
      "  p   F  pA  n  ",
      "AAAAAAAAAAA     ",
      "             n  ",
      "             n  ",
      "nnnnnnnnnnnnnn  ",
      "                ",
      "                "
    ],
    [
      "  y      wA  n  ",
      "  y       A  n  ",
      "  pByIJyBpA  n  ",
      "          A  n  ",
      "         wA  n  ",
      "         wE  n  ",
      "         w   n  ",
      "         wK  n  ",
      "          A  n  ",
      "  p   FF pA  n  ",
      "AAAAAALAAAA  n  ",
      "             n  ",
      "             n  ",
      "nnnnnnnnnnnnnn  ",
      "                ",
      "                "
    ],
    [
      "  MN     wA  O  ",
      "  yN      A  O  ",
      "  pyyyyyypA  O  ",
      "          A  O  ",
      "          A  O  ",
      "         wE  O  ",
      "         w   O  ",
      "         wL  O  ",
      "          A  O  ",
      "  p  FF  pA     ",
      "AAAAAALAAAL  O  ",
      "             O  ",
      "             O  ",
      "OOOOOOOOOOOOOO  ",
      "                ",
      "                "
    ],
    [
      "  y      PAQ    ",
      "  y      PA     ",
      "  pyByPpppA     ",
      "         PA     ",
      "         PAQ    ",
      "         PAR    ",
      "         PAQ    ",
      "         PSR    ",
      "         PA     ",
      "  p   PpppA     ",
      "AAAAAAAAAAL     ",
      "                ",
      "                ",
      "                ",
      "                ",
      "                "
    ]
  ]
}