{
  "name": "multi_farmhouse1_6_floor1",
  "refpalette": "deceasedcraft:multi_farmhouse1_6/multi_farmhouse1_6_floor1_palette",
  "xsize": 16,
  "zsize": 16,
  "slices": [
    [
      "aaaaaaaaaaaaaaaa",
      "aaaaaaaaaaaaaaaa",
      "aaaaaaaaaaaaaaaa",
      "aaaaaaaaaaaaaaaa",
      "aaaaaaaaaaaaaaaa",
      "aaaaaaaaaaaaaaaa",
      "aaaaaaaaaaaaaaaa",
      "aaaaaaaaaaaaaaaa",
      "aaaaaaaaaaaaaaaa",
      "aaaaaaaaaaaaaaaa",
      "aaaaaaaaaaaaaaaa",
      "aaaaaaaaaaaaaaaa",
      "aaaaaaaaaaaaaaaa",
      "aaaaaaaaaaaaaaaa",
      "aaaaaaaaaaaaaaaa",
      "aaaaaaaaaaaaaaaa"
    ],
    [
      "bbccbccbbccccccc",
      "cbcbbbcbcbbcbccb",
      "cbbbbcbbbcccbbcc",
      "cbbccbbbbcbbcbcc",
      "cbbbbbbcbbbbccbc",
      "bbbbbbbbbbbbbbcc",
      "bbbbcbbbbbcbbccb",
      "bbbbbbcbbbbbbcbc",
      "bbbbbbbbbbbbbccc",
      "bbbbbbbbbbcbccbc",
      "bbbbbbbbbbbbbbcc",
      "bbbbbbbbbbbbcbcb",
      "bbbbbbbbbbbbbcbc",
      "bcbbcbbcbbbbbbbd",
      "ccbccbbbbbbbcbcc",
      "ccceccbbbbbcbcbd"
    ],
    [
      "ffccfccffccccccc",
      "cfcfffcfcffcfccf",
      "cffffcfffcccffcc",
      "cffccffffcffcfcc",
      "cffffffcffffccfc",
      "ffffffffffffffcc",
      "ffffcfffffcffccf",
      "ffffffcffffffcfc",
      "fffffffffffffccc",
      "ffffffffffcfccfc",
      "ffffffffffffffcc",
      "ffffffffffffcfcf",
      "fffffffffffffcfc",
      "fcffcffcfffffffc",
      "ccfccfffffffcfcc",
      "cccgccfffffcfcfc"
    ],
    [
      "cccccccccccccccc",
      "cccccccccccccccc",
      "cccccccccccccccc",
      "cccccccccccccccc",
      "cccccccccccccccc",
      "cccccccccccccccc",
      "cccccccccccccccc",
      "cccccccccccccccc",
      "cccccccccccccccc",
      "cccccccccccccccc",
      "cccccccccccccccc",
      "cccccccccccccccc",
      "cccccccccccccccc",
      "cccccccccccccccc",
      "cccccccccccccccc",
      "cccccccccccccccc"
    ],
    [
      "cccccccccccccccc",
      "cccccccccccccccc",
      "cccccccccccccccc",
      "cccccccccccccccc",
      "cccccccccccccccc",
      "cccccccccccccccc",
      "cccccccccccccccc",
      "cccccccccccccccc",
      "cccccccccccccccc",
      "cccccccccccccccc",
      "cccccccccccccccc",
      "cccccccccccccccc",
      "cccccccccccccccc",
      "cccccccccccccccc",
      "cccccccccccccccc",
      "cccccccccccccccc"
    ],
    [
      "cccccccccccccccc",
      "cccccccccccccccc",
      "cccccccccccccccc",
      "cccccccccccccccc",
      "cccccccccccccccc",
      "cccccccccccccccc",
      "cccccccccccccccc",
      "cccccccccccccccc",
      "cccccccccccccccc",
      "cccccccccccccccc",
      "cccccccccccccccc",
      "cccccccccccccccc",
      "cccccccccccccccc",
      "cccccccccccccccc",
      "cccccccccccccccc",
      "cccccccccccccccc"
    ]
  ]
}