{
  "xsize": 16,
  "zsize": 16,
  "palette": {
    "palette": [
      {
        "char": " ",
        "block": "minecraft:air"
      },
      {
        "char": "r",
        "block": "minecraft:deepslate[axis=y]"
      },
      {
        "char": "o",
        "block": "minecraft:blackstone"
      },
      {
        "char": "m",
        "block": "minecraft:cobbled_deepslate"
      },
      {
        "char": "q",
        "block": "minecraft:cyan_terracotta"
      },
      {
        "char": "p",
        "block": "minecraft:basalt[axis=x]"
      },
      {
        "char": "e",
        "block": "minecraft:stone"
      },
      {
        "char": "ͽ",
        "block": "minecraft:polished_diorite"
      },
      {
        "char": "v",
        "block": "minecraft:quartz_block"
      },
      {
        "char": ";",
        "block": "minecraft:diorite"
      },
      {
        "char": "A",
        "block": "minecraft:cracked_stone_bricks"
      },
      {
        "char": "k",
        "block": "minecraft:grass_block[snowy=false]"
      },
      {
        "char": "Α",
        "block": "minecraft:dirt"
      },
      {
        "char": "f",
        "block": "minecraft:cobblestone"
      },
      {
        "char": "j",
        "block": "minecraft:smooth_stone_slab[type=double]"
      },
      {
        "char": "Ω",
        "block": "minecraft:cobblestone_slab[type=bottom]"
      },
      {
        "char": "d",
        "block": "minecraft:vine[east=false,north=false,south=true,up=false,west=false]"
      },
      {
        "char": "Ϳ",
        "block": "minecraft:stone_slab[type=bottom]"
      },
      {
        "char": "н",
        "block": "minecraft:stone_stairs[facing=west,half=bottom,shape=straight]"
      },
      {
        "char": "γ",
        "block": "minecraft:brick_slab[type=bottom]"
      },
      {
        "char": "a",
        "block": "minecraft:bricks"
      },
      {
        "char": "s",
        "block": "minecraft:air"
      },
      {
        "char": "g",
        "block": "minecraft:stone_bricks"
      },
      {
        "char": "ΰ",
        "block": "minecraft:air"
      },
      {
        "char": "е",
        "block": "minecraft:air"
      },
      {
        "char": "Ή",
        "block": "minecraft:stone_brick_stairs[facing=south,half=bottom,shape=straight]"
      },
      {
        "char": "Ѱ",
        "block": "minecraft:air"
      },
      {
        "char": "z",
        "block": "minecraft:mossy_stone_bricks"
      },
      {
        "char": "Ҽ",
        "block": "minecraft:air"
      },
      {
        "char": "Ќ",
        "block": "minecraft:oak_wall_sign",
        "tag": {
          "z": 623,
          "x": 195,
          "is_waxed": "0b",
          "ForgeCaps": {
            "supplementaries:antique_ink": {
              "ink": "0b"
            }
          },
          "id": "minecraft:sign",
          "y": 136,
          "front_text": {
            "color": "black",
            "has_glowing_text": "0b",
            "messages": [
              "{\"text\":\"344\"}",
              "{\"text\":\"\"}",
              "{\"text\":\"\"}",
              "{\"text\":\"\"}"
            ]
          },
          "back_text": {
            "color": "black",
            "has_glowing_text": "0b",
            "messages": [
              "{\"text\":\"\"}",
              "{\"text\":\"\"}",
              "{\"text\":\"\"}",
              "{\"text\":\"\"}"
            ]
          }
        }
      },
      {
        "char": "Ѯ",
        "block": "minecraft:air"
      }
    ]
  },
  "slices": [
    [
      "romqoommomrrpopo",
      "pmpprpomqrrpmqro",
      "oropmmmoqpprpoqo",
      "pqqrrommqpmmmmor",
      "moqorpmmpmprpmpo",
      "poqppmpmrpqroomm",
      "pqmqmpopoooqpqmq",
      "pmmooqoppromqoqo",
      "qqpqqrqqormpqomr",
      "qqqppmrrqorqmrqo",
      "oorqrqmrmprrqpmq",
      "mmmeͽvvvvͽ;ͽͽ;v;",
      "oppAvͽvkvkͽv;Α;v",
      "mpmAfffffvvvffff",
      "prmj     jΑjΩ   ",
      "qrmjd dddjΑjdddͿ"
    ],
    [
      "                ",
      "                ",
      "                ",
      "                ",
      "                ",
      "                ",
      "                ",
      "                ",
      "                ",
      "                ",
      "                ",
      "   A  Ϳ     н γa",
      "   A   s    eͿ  ",
      "   gΰΰΰΰеΉΉΉѰΰΰΰ",
      "   z     jjj    ",
      "   zd dddjjjdddd"
    ],
    [
      "                ",
      "                ",
      "                ",
      "                ",
      "                ",
      "                ",
      "                ",
      "                ",
      "                ",
      "                ",
      "                ",
      "   Ҽ           Ϳ",
      "   A            ",
      "   A            ",
      "   g     ΉΉΉ    ",
      "   zd dddjjjdddd"
    ],
    [
      "                ",
      "                ",
      "                ",
      "                ",
      "                ",
      "                ",
      "                ",
      "                ",
      "                ",
      "                ",
      "                ",
      "                ",
      "   A            ",
      "   A            ",
      "   A            ",
      "   Ad ddd   dddd"
    ],
    [
      "                ",
      "                ",
      "                ",
      "                ",
      "                ",
      "                ",
      "                ",
      "                ",
      "                ",
      "                ",
      "                ",
      "                ",
      "                ",
      "   A            ",
      "   z            ",
      "   zd ddd  Ќdddd"
    ],
    [
      "                ",
      "                ",
      "                ",
      "                ",
      "                ",
      "                ",
      "                ",
      "                ",
      "                ",
      "                ",
      "                ",
      "                ",
      "                ",
      "   Ѯ            ",
      "                ",
      "   Ad ddd   dddd"
    ]
  ]
}