{
  "xsize": 16,
  "zsize": 16,
  "palette": {
    "palette": [
      {
        "char": " ",
        "block": "minecraft:air"
      },
      {
        "char": "f",
        "block": "minecraft:light_gray_concrete"
      },
      {
        "char": "d",
        "block": "minecraft:cobbled_deepslate"
      },
      {
        "char": "c",
        "block": "minecraft:deepslate[axis=y]"
      },
      {
        "char": "b",
        "block": "minecraft:basalt[axis=x]"
      },
      {
        "char": "a",
        "block": "minecraft:blackstone"
      },
      {
        "char": "e",
        "block": "minecraft:cyan_terracotta"
      },
      {
        "char": "q",
        "block": "minecraft:gold_block"
      },
      {
        "char": "l",
        "block": "minecraft:yellow_concrete"
      },
      {
        "char": "i",
        "block": "minecraft:white_concrete"
      },
      {
        "char": "g",
        "block": "minecraft:redstone_lamp[lit=false]"
      },
      {
        "char": "x",
        "block": "minecraft:quartz_stairs[facing=north,half=bottom,shape=straight]"
      },
      {
        "char": "w",
        "block": "minecraft:quartz_stairs[facing=south,half=bottom,shape=straight]"
      },
      {
        "char": "楼",
        "block": "minecraft:smooth_quartz_stairs[facing=east,half=bottom,shape=straight]"
      },
      {
        "char": "暴",
        "block": "minecraft:smooth_quartz_stairs[facing=west,half=bottom,shape=straight]"
      },
      {
        "char": "须",
        "block": "minecraft:smooth_quartz_stairs[facing=north,half=bottom,shape=straight]"
      },
      {
        "char": "y",
        "block": "minecraft:quartz_slab[type=top]"
      },
      {
        "char": "n",
        "block": "minecraft:black_concrete"
      },
      {
        "char": "M",
        "block": "minecraft:quartz_pillar[axis=y]"
      },
      {
        "char": "闯",
        "block": "minecraft:lever[face=ceiling,facing=west,powered=true]"
      },
      {
        "char": "唷",
        "block": "minecraft:white_wall_banner",
        "tag": {
          "z": 944,
          "Patterns": [
            {
              "Color": 8,
              "Pattern": "dls"
            },
            {
              "Color": 0,
              "Pattern": "dls"
            },
            {
              "Color": 3,
              "Pattern": "gru"
            },
            {
              "Color": 8,
              "Pattern": "bo"
            }
          ],
          "x": -405,
          "ForgeCaps": {},
          "id": "minecraft:banner",
          "y": 110
        }
      },
      {
        "char": "s",
        "block": "minecraft:quartz_slab[type=bottom]"
      },
      {
        "char": "穴",
        "block": "minecraft:air"
      },
      {
        "char": "绑",
        "block": "minecraft:smooth_quartz_stairs[facing=east,half=bottom,shape=outer_right]"
      },
      {
        "char": "约",
        "block": "minecraft:smooth_quartz_stairs[facing=south,half=bottom,shape=straight]"
      },
      {
        "char": "渺",
        "block": "minecraft:smooth_quartz_stairs[facing=south,half=bottom,shape=outer_right]"
      },
      {
        "char": "蓄",
        "block": "minecraft:smooth_quartz_stairs[facing=north,half=bottom,shape=outer_right]"
      },
      {
        "char": "伺",
        "block": "minecraft:smooth_quartz_stairs[facing=west,half=bottom,shape=outer_right]"
      }
    ]
  },
  "slices": [
    [
      "fd   cfcccdcbaab",
      "fb e afadacadbbd",
      "faqq dfdddddadbc",
      "ef   feaebddacdb",
      "dbfffbbddddccdbe",
      "cbbecabdceddbabd",
      "ffffffflllllllll",
      "eededaadbdeaebdd",
      "ccbeecfabbceedbe",
      "iiddeefbbdeaaace",
      "dbcdebaaeeabbbbd",
      "abegcafddbebbcdd",
      "laeaicfxxxxxxxxx",
      "leeaicfwwwwwwwww",
      "ebagbdfaddbaebdc",
      "daeaddfeaeeeaddc"
    ],
    [
      "楼i ffi暴         ",
      "楼i  bi暴         ",
      "楼iqq i暴         ",
      " 须iii暴          ",
      "  须须须           ",
      "                ",
      "                ",
      "                ",
      "                ",
      "                ",
      "                ",
      "y               ",
      "nyy             ",
      "nyy             ",
      "y               ",
      "                "
    ],
    [
      " i cei          ",
      " iqqMi  闯       ",
      " i  唷i          ",
      "  iii           ",
      "                ",
      "                ",
      "                ",
      "                ",
      "                ",
      "                ",
      "                ",
      "s               ",
      "xs              ",
      "ws              ",
      "s               ",
      "                "
    ],
    [
      " 楼bb 暴          ",
      " 楼cb accd穴      ",
      " 楼ec 暴          ",
      "  须须须           ",
      "                ",
      "                ",
      "                ",
      "                ",
      "                ",
      "                ",
      "                ",
      "                ",
      "                ",
      "                ",
      "                ",
      "                "
    ],
    [
      "  绑约渺           ",
      "  楼i暴           ",
      "  蓄须伺           ",
      "                ",
      "                ",
      "                ",
      "                ",
      "                ",
      "                ",
      "                ",
      "                ",
      "                ",
      "                ",
      "                ",
      "                ",
      "                "
    ],
    [
      "                ",
      "                ",
      "                ",
      "                ",
      "                ",
      "                ",
      "                ",
      "                ",
      "                ",
      "                ",
      "                ",
      "                ",
      "                ",
      "                ",
      "                ",
      "                "
    ]
  ]
}