{
  "xsize": 16,
  "zsize": 16,
  "palette": {
    "palette": [
      {
        "char": " ",
        "block": "minecraft:air"
      },
      {
        "char": "a",
        "block": "minecraft:blackstone"
      },
      {
        "char": "b",
        "block": "minecraft:basalt[axis=x]"
      },
      {
        "char": "d",
        "block": "minecraft:cobbled_deepslate"
      },
      {
        "char": "c",
        "block": "minecraft:deepslate[axis=y]"
      },
      {
        "char": "e",
        "block": "minecraft:cyan_terracotta"
      },
      {
        "char": "o",
        "block": "minecraft:black_stained_glass"
      },
      {
        "char": "g",
        "block": "minecraft:redstone_lamp[lit=false]"
      },
      {
        "char": "w",
        "block": "minecraft:quartz_stairs[facing=south,half=bottom,shape=straight]"
      },
      {
        "char": "x",
        "block": "minecraft:quartz_stairs[facing=north,half=bottom,shape=straight]"
      },
      {
        "char": "税",
        "block": "minecraft:dark_oak_trapdoor[facing=north,half=top,open=false]"
      },
      {
        "char": "未",
        "block": "minecraft:chest",
        "tag": {
          "z": 948,
          "x": -513,
          "ForgeCaps": {},
          "id": "minecraft:chest",
          "y": 117,
          "NodePos": "-141012362379147L",
          "Connections": [
            "L"
          ]
        }
      },
      {
        "char": "沦",
        "block": "minecraft:chest",
        "tag": {
          "z": 980,
          "x": -455,
          "ForgeCaps": {},
          "id": "minecraft:chest",
          "y": 139,
          "NodePos": "-125069443645301L",
          "Connections": [
            "L"
          ]
        }
      },
      {
        "char": "酱",
        "block": "minecraft:chest",
        "tag": {
          "z": 997,
          "x": -462,
          "ForgeCaps": {},
          "id": "minecraft:chest",
          "y": 139,
          "NodePos": "-126993588924277L",
          "Connections": [
            "L"
          ]
        }
      },
      {
        "char": "啪",
        "block": "minecraft:dark_oak_trapdoor[facing=south,half=top,open=false]"
      }
    ]
  },
  "slices": [
    [
      "                ",
      "                ",
      "                ",
      "                ",
      "                ",
      "                ",
      "                ",
      "   abdcbbeacco  ",
      " deb         ooo",
      "eg              ",
      "                ",
      "                ",
      "                ",
      "                ",
      "                ",
      "                "
    ],
    [
      "                ",
      "                ",
      "                ",
      "                ",
      "                ",
      "                ",
      "                ",
      "                ",
      "   gbcceeacdbg  ",
      " cdcedeaaedacccd",
      "cabcadbbceaaceeb",
      "cecaedbebacaeddd",
      "ddebecacdeeccceb",
      "cecdcadcbdebebad",
      "eabaeccbebedceea",
      "aabbbbbebeccaaaa"
    ],
    [
      "                ",
      "                ",
      "                ",
      "                ",
      "                ",
      "                ",
      "                ",
      "   aeaeaadbcab  ",
      "edde         adc",
      "a     w w  w    ",
      "                ",
      "                ",
      "                ",
      "                ",
      "   x   x        ",
      "    税税税         "
    ],
    [
      "                ",
      "                ",
      "                ",
      "                ",
      "                ",
      "                ",
      "  aeadcddbdddcc ",
      "bee未沦沦 沦 沦沦 沦未ba",
      "                ",
      "                ",
      "                ",
      "                ",
      "                ",
      "                ",
      "                ",
      "         酱      "
    ],
    [
      "                ",
      "                ",
      "                ",
      "                ",
      "                ",
      "                ",
      "                ",
      "   ecbadadebbd  ",
      "eaeaececcaacbadc",
      "cedcbbecbeecbdde",
      "aeccebbecddacdbd",
      "eebacbebbbddedce",
      "bdedbabaceeeaebc",
      "ccacdbbabdeaacbd",
      "eeaaecaeeadcebcc",
      "edddbeecebcbbcbd"
    ],
    [
      "                ",
      "                ",
      "                ",
      "                ",
      "                ",
      "                ",
      "                ",
      "  oooooooooooo  ",
      "oo            oo",
      "   cdabadadcd   ",
      "acc啪啪啪啪啪啪啪啪啪啪a  ",
      "              a ",
      "               a",
      "    cacbcacdb   ",
      "    dddecdacc   ",
      "    acaaeecee   "
    ]
  ]
}