{
  "xsize": 16,
  "zsize": 16,
  "palette": {
    "palette": [
      {
        "char": " ",
        "block": "minecraft:air"
      },
      {
        "char": "c",
        "block": "minecraft:deepslate[axis=y]"
      },
      {
        "char": "a",
        "block": "minecraft:blackstone"
      },
      {
        "char": "陌",
        "block": "minecraft:air"
      },
      {
        "char": "B",
        "block": "minecraft:iron_trapdoor[facing=north,half=bottom,open=false]"
      },
      {
        "char": "b",
        "block": "minecraft:basalt[axis=x]"
      },
      {
        "char": "i",
        "block": "minecraft:white_concrete"
      },
      {
        "char": "z",
        "block": "minecraft:quartz_stairs[facing=west,half=bottom,shape=straight]"
      },
      {
        "char": "C",
        "block": "minecraft:quartz_stairs[facing=east,half=bottom,shape=straight]"
      },
      {
        "char": "介",
        "block": "minecraft:iron_trapdoor[facing=east,half=bottom,open=false]"
      },
      {
        "char": "砸",
        "block": "minecraft:quartz_stairs[facing=west,half=bottom,shape=inner_right]"
      },
      {
        "char": "歪",
        "block": "minecraft:quartz_stairs[facing=north,half=bottom,shape=outer_left]"
      },
      {
        "char": "d",
        "block": "minecraft:cobbled_deepslate"
      },
      {
        "char": "仿",
        "block": "minecraft:quartz_stairs[facing=west,half=bottom,shape=outer_right]"
      },
      {
        "char": "邻",
        "block": "minecraft:quartz_stairs[facing=south,half=bottom,shape=outer_left]"
      },
      {
        "char": "札",
        "block": "minecraft:quartz_stairs[facing=east,half=bottom,shape=inner_right]"
      },
      {
        "char": "w",
        "block": "minecraft:quartz_stairs[facing=south,half=bottom,shape=straight]"
      },
      {
        "char": "e",
        "block": "minecraft:cyan_terracotta"
      },
      {
        "char": "l",
        "block": "minecraft:yellow_concrete"
      },
      {
        "char": "穹",
        "block": "minecraft:stone_brick_stairs[facing=north,half=bottom,shape=straight]"
      },
      {
        "char": "搅",
        "block": "minecraft:lever[face=floor,facing=west,powered=true]"
      },
      {
        "char": "肆",
        "block": "minecraft:lever[face=floor,facing=west,powered=false]"
      },
      {
        "char": "s",
        "block": "minecraft:quartz_slab[type=bottom]"
      },
      {
        "char": "o",
        "block": "minecraft:black_stained_glass"
      }
    ]
  },
  "slices": [
    [
      "ca陌B            ",
      "biiiBB          ",
      "azCiac介B        ",
      "砸歪CdbicdBB      ",
      "仿邻札dcdbicd介B    ",
      "w札eaaebcaiccBBB ",
      "eecacdbaeeedlllB",
      "edbccdccclllddcd",
      "eaaecblllbaccdec",
      "aaelllceabccbbc ",
      "lllaebdbdedeb   ",
      "cbeebddbbbeca   ",
      "daaabdcebc穹b搅   ",
      "dbeaaacdaa d    ",
      "ecdebadacd e    ",
      "dcaeccabda c肆   "
    ],
    [
      "  ss            ",
      "    ss          ",
      "      ss        ",
      "        ss      ",
      "          ss    ",
      "            s   ",
      "                ",
      "                ",
      "               o",
      "             oo ",
      "            o   ",
      "            o   ",
      "           o    ",
      "           o    ",
      "           o    ",
      "           o    "
    ],
    [
      "                ",
      "                ",
      "                ",
      "                ",
      "                ",
      "                ",
      "                ",
      "                ",
      "                ",
      "               o",
      "             ooo",
      "             ooo",
      "            oooo",
      "            oooo",
      "            oooo",
      "            oooo"
    ],
    [
      "                ",
      "                ",
      "                ",
      "                ",
      "                ",
      "                ",
      "                ",
      "                ",
      "                ",
      "                ",
      "                ",
      "                ",
      "                ",
      "                ",
      "                ",
      "                "
    ],
    [
      "                ",
      "                ",
      "                ",
      "                ",
      "                ",
      "                ",
      "                ",
      "                ",
      "                ",
      "                ",
      "                ",
      "                ",
      "                ",
      "                ",
      "                ",
      "                "
    ],
    [
      "                ",
      "                ",
      "                ",
      "                ",
      "                ",
      "                ",
      "                ",
      "                ",
      "                ",
      "                ",
      "                ",
      "                ",
      "                ",
      "                ",
      "                ",
      "                "
    ]
  ]
}