{
  "xsize": 16,
  "zsize": 16,
  "palette": {
    "palette": [
      {
        "char": " ",
        "block": "minecraft:air"
      },
      {
        "char": "c",
        "block": "minecraft:deepslate[axis=y]"
      },
      {
        "char": "a",
        "block": "minecraft:blackstone"
      },
      {
        "char": "b",
        "block": "minecraft:basalt[axis=x]"
      },
      {
        "char": "e",
        "block": "minecraft:cyan_terracotta"
      },
      {
        "char": "d",
        "block": "minecraft:cobbled_deepslate"
      },
      {
        "char": "l",
        "block": "minecraft:yellow_concrete"
      },
      {
        "char": "g",
        "block": "minecraft:redstone_lamp[lit=false]"
      },
      {
        "char": "n",
        "block": "minecraft:black_concrete"
      },
      {
        "char": "y",
        "block": "minecraft:quartz_slab[type=top]"
      },
      {
        "char": "C",
        "block": "minecraft:quartz_stairs[facing=east,half=bottom,shape=straight]"
      },
      {
        "char": "乏",
        "block": "minecraft:furnace[facing=north,lit=false]",
        "tag": {
          "z": 946,
          "x": -346,
          "CookTimeTotal": 0,
          "ForgeData": {
            "LockFlag": "1b"
          },
          "CookTime": 0,
          "ForgeCaps": {
            "polymorph:block_entity_recipe_data": {}
          },
          "id": "minecraft:furnace",
          "y": 120,
          "Items": [],
          "BurnTime": 0,
          "RecipesUsed": {}
        }
      },
      {
        "char": "z",
        "block": "minecraft:quartz_stairs[facing=west,half=bottom,shape=straight]"
      },
      {
        "char": "Q",
        "block": "minecraft:quartz_slab[type=double]"
      },
      {
        "char": "s",
        "block": "minecraft:quartz_slab[type=bottom]"
      },
      {
        "char": "振",
        "block": "minecraft:smooth_quartz_slab[type=bottom]"
      },
      {
        "char": "o",
        "block": "minecraft:black_stained_glass"
      },
      {
        "char": "赠",
        "block": "minecraft:quartz_stairs[facing=north,half=bottom,shape=outer_right]"
      },
      {
        "char": "歪",
        "block": "minecraft:quartz_stairs[facing=north,half=bottom,shape=outer_left]"
      },
      {
        "char": "H",
        "block": "minecraft:quartz_stairs[facing=south,half=top,shape=straight]"
      },
      {
        "char": "x",
        "block": "minecraft:quartz_stairs[facing=north,half=bottom,shape=straight]"
      }
    ]
  },
  "slices": [
    [
      "                ",
      "                ",
      "            cabc",
      "     becddddceca",
      "acdbdebbdldcdcal",
      "adlaecedlldbabcl",
      "balecceblledecbl",
      "lelcabaallbaecal",
      "lclcedadlldbaaal",
      "ldldecbbllebddbl",
      "lalceebelldccael",
      "laleaecdlledccal",
      "laladcdcllllllll",
      "lllllllllebbdcae",
      "lbbdcceaabbbcdgg",
      "laddebbbceaebcee"
    ],
    [
      "                ",
      "           ceacc",
      "    eaabcacb    ",
      "bdbeb      n n  ",
      "    n n         ",
      "                ",
      "           y y  ",
      "    y y     y   ",
      "     y      y   ",
      "     y      n   ",
      "     n          ",
      "                ",
      "                ",
      "                ",
      "                ",
      "                "
    ],
    [
      "          bbcdae",
      "   ebedbece     ",
      "dada            ",
      "           C乏z  ",
      "    C乏z     Q   ",
      "     Q   zs振Q振sC",
      "  zs振Q振sC ssQss ",
      "   ssQss   Coz  ",
      "C   Coz    赠o歪  ",
      "    赠o歪     s   ",
      "     s      s   ",
      "     s          ",
      "                ",
      "                ",
      "                ",
      "                "
    ],
    [
      "  abddabdd      ",
      "dea             ",
      "                ",
      "           yHy  ",
      "    yHy     x   ",
      "     x          ",
      "                ",
      "                ",
      "                ",
      "                ",
      "                ",
      "                ",
      "                ",
      "                ",
      "                ",
      "                "
    ],
    [
      "bag             ",
      "                ",
      "                ",
      "                ",
      "                ",
      "                ",
      "                ",
      "                ",
      "                ",
      "                ",
      "                ",
      "                ",
      "                ",
      "                ",
      "                ",
      "                "
    ],
    [
      "c               ",
      "                ",
      "                ",
      "                ",
      "                ",
      "                ",
      "                ",
      "                ",
      "                ",
      "                ",
      "                ",
      "                ",
      "                ",
      "                ",
      "                ",
      "                "
    ]
  ]
}