{
  "xsize": 16,
  "zsize": 16,
  "palette": {
    "palette": [
      {
        "char": " ",
        "block": "minecraft:air"
      },
      {
        "char": "c",
        "block": "minecraft:deepslate[axis=y]"
      },
      {
        "char": "a",
        "block": "minecraft:blackstone"
      },
      {
        "char": "e",
        "block": "minecraft:cyan_terracotta"
      },
      {
        "char": "l",
        "block": "minecraft:yellow_concrete"
      },
      {
        "char": "d",
        "block": "minecraft:cobbled_deepslate"
      },
      {
        "char": "b",
        "block": "minecraft:basalt[axis=x]"
      },
      {
        "char": "y",
        "block": "minecraft:quartz_slab[type=top]"
      },
      {
        "char": "n",
        "block": "minecraft:black_concrete"
      },
      {
        "char": "振",
        "block": "minecraft:smooth_quartz_slab[type=bottom]"
      },
      {
        "char": "s",
        "block": "minecraft:quartz_slab[type=bottom]"
      },
      {
        "char": "C",
        "block": "minecraft:quartz_stairs[facing=east,half=bottom,shape=straight]"
      },
      {
        "char": "Q",
        "block": "minecraft:quartz_slab[type=double]"
      },
      {
        "char": "o",
        "block": "minecraft:black_stained_glass"
      },
      {
        "char": "z",
        "block": "minecraft:quartz_stairs[facing=west,half=bottom,shape=straight]"
      },
      {
        "char": "秘",
        "block": "minecraft:furnace[facing=south,lit=false]",
        "tag": {
          "z": 983,
          "x": -458,
          "CookTimeTotal": 0,
          "ForgeData": {
            "LockFlag": "1b"
          },
          "CookTime": 0,
          "ForgeCaps": {
            "polymorph:block_entity_recipe_data": {}
          },
          "id": "minecraft:furnace",
          "y": 130,
          "Items": [],
          "BurnTime": 0,
          "RecipesUsed": {}
        }
      },
      {
        "char": "w",
        "block": "minecraft:quartz_stairs[facing=south,half=bottom,shape=straight]"
      },
      {
        "char": "ϓ",
        "block": "minecraft:quartz_stairs[facing=north,half=top,shape=straight]"
      },
      {
        "char": "g",
        "block": "minecraft:redstone_lamp[lit=false]"
      }
    ]
  },
  "slices": [
    [
      "cacelldaebdlcada",
      "ebbellccaacleabb",
      "eeddlledbeelddcc",
      "babceldcdbalaeea",
      "ccaccabdeedldbcb",
      "   aadecacbdcded",
      "         ebdcccc",
      "               c",
      "                ",
      "                ",
      "                ",
      "                ",
      "                ",
      "                ",
      "                ",
      "                "
    ],
    [
      "     y y     y  ",
      "            y y ",
      "n               ",
      "     n n        ",
      "cd          n n ",
      " cadcdbe        ",
      "       ecbeeea  ",
      "             bcc",
      "                ",
      "                ",
      "                ",
      "                ",
      "                ",
      "                ",
      "                ",
      "                "
    ],
    [
      "振sC ssQss   Coz ",
      "   zs振Q振sC ssQss",
      "z     Q   zs振Q振s",
      "     C秘z     Q  ",
      "            C秘z ",
      "c               ",
      "ceecdad         ",
      "      cdddcdc   ",
      "            aebe",
      "                ",
      "                ",
      "                ",
      "                ",
      "                ",
      "                ",
      "                "
    ],
    [
      "                ",
      "                ",
      "y     w         ",
      "     yϓy     w  ",
      "            yϓy ",
      "                ",
      "                ",
      "bddbeb          ",
      "     aeabeac    ",
      "           aceea",
      "                ",
      "                ",
      "                ",
      "                ",
      "                ",
      "                "
    ],
    [
      "                ",
      "                ",
      "                ",
      "                ",
      "                ",
      "                ",
      "                ",
      "                ",
      "cbbabg          ",
      "    aeceaaag    ",
      "          acddeb",
      "                ",
      "                ",
      "                ",
      "                ",
      "                "
    ],
    [
      "                ",
      "                ",
      "                ",
      "                ",
      "                ",
      "                ",
      "                ",
      "                ",
      "deac            ",
      "    ccecad      ",
      "          cbabae",
      "                ",
      "                ",
      "                ",
      "                ",
      "                "
    ]
  ]
}