{
  "xsize": 16,
  "zsize": 16,
  "palette": {
    "palette": [
      {
        "char": " ",
        "block": "minecraft:air"
      },
      {
        "char": "c",
        "block": "minecraft:deepslate[axis=y]"
      },
      {
        "char": "a",
        "block": "minecraft:blackstone"
      },
      {
        "char": "d",
        "block": "minecraft:cobbled_deepslate"
      },
      {
        "char": "e",
        "block": "minecraft:cyan_terracotta"
      },
      {
        "char": "b",
        "block": "minecraft:basalt[axis=x]"
      },
      {
        "char": "i",
        "block": "minecraft:white_concrete"
      },
      {
        "char": "f",
        "block": "minecraft:light_gray_concrete"
      },
      {
        "char": "q",
        "block": "minecraft:gold_block"
      },
      {
        "char": "约",
        "block": "minecraft:smooth_quartz_stairs[facing=south,half=bottom,shape=straight]"
      },
      {
        "char": "楼",
        "block": "minecraft:smooth_quartz_stairs[facing=east,half=bottom,shape=straight]"
      },
      {
        "char": "暴",
        "block": "minecraft:smooth_quartz_stairs[facing=west,half=bottom,shape=straight]"
      },
      {
        "char": "须",
        "block": "minecraft:smooth_quartz_stairs[facing=north,half=bottom,shape=straight]"
      },
      {
        "char": "雳",
        "block": "minecraft:white_wall_banner",
        "tag": {
          "z": 949,
          "Patterns": [
            {
              "Color": 8,
              "Pattern": "dls"
            },
            {
              "Color": 0,
              "Pattern": "dls"
            },
            {
              "Color": 3,
              "Pattern": "gru"
            },
            {
              "Color": 8,
              "Pattern": "bo"
            }
          ],
          "x": -433,
          "ForgeCaps": {},
          "id": "minecraft:banner",
          "y": 117
        }
      },
      {
        "char": "槟",
        "block": "minecraft:lever[face=ceiling,facing=east,powered=true]"
      },
      {
        "char": "M",
        "block": "minecraft:quartz_pillar[axis=y]"
      },
      {
        "char": "H",
        "block": "minecraft:quartz_stairs[facing=south,half=top,shape=straight]"
      },
      {
        "char": "y",
        "block": "minecraft:quartz_slab[type=top]"
      },
      {
        "char": "ϓ",
        "block": "minecraft:quartz_stairs[facing=north,half=top,shape=straight]"
      },
      {
        "char": "绑",
        "block": "minecraft:smooth_quartz_stairs[facing=east,half=bottom,shape=outer_right]"
      },
      {
        "char": "渺",
        "block": "minecraft:smooth_quartz_stairs[facing=south,half=bottom,shape=outer_right]"
      },
      {
        "char": "g",
        "block": "minecraft:redstone_lamp[lit=false]"
      },
      {
        "char": "w",
        "block": "minecraft:quartz_stairs[facing=south,half=bottom,shape=straight]"
      },
      {
        "char": "蓄",
        "block": "minecraft:smooth_quartz_stairs[facing=north,half=bottom,shape=outer_right]"
      },
      {
        "char": "伺",
        "block": "minecraft:smooth_quartz_stairs[facing=west,half=bottom,shape=outer_right]"
      },
      {
        "char": "s",
        "block": "minecraft:quartz_slab[type=bottom]"
      },
      {
        "char": "x",
        "block": "minecraft:quartz_stairs[facing=north,half=bottom,shape=straight]"
      }
    ]
  },
  "slices": [
    [
      "cacdebdddbcddced",
      "aceeaaaccadaaaab",
      "dedebaceacbebdad",
      "ddbdbabdcceeeced",
      "ecdeeecebbbcbaed",
      "iiiiiiiiiiiiiiii",
      "ccbbcabaaadadbcb",
      "addebcbbaadaiiii",
      "aaebefffbacdibab",
      "accef   fbaaiadd",
      "edefe qqdfceibbc",
      "dddfd e dfeeidbd",
      "bcbfa   bfdbieed",
      "aebbfabefcddibba",
      "ebeabfffaecdidcd",
      "bbbbebebeebdiccb"
    ],
    [
      "                ",
      "                ",
      "                ",
      "                ",
      "                ",
      "                ",
      "                ",
      "                ",
      "     约约约        ",
      "    楼iii约       ",
      "   楼i qqi暴      ",
      "   楼id  i暴      ",
      "   楼iff i暴      ",
      "    须iii须       ",
      "     须须须        ",
      "                "
    ],
    [
      "                ",
      "                ",
      "                ",
      "                ",
      "                ",
      "                ",
      "                ",
      "                ",
      "                ",
      "     iii        ",
      "    i雳  i       ",
      "槟   iMqqi       ",
      "    ied i       ",
      "     iii        ",
      "                ",
      "                "
    ],
    [
      "                ",
      "                ",
      "                ",
      "                ",
      "                ",
      "                ",
      "                ",
      "                ",
      "                ",
      "     约约约        ",
      "    楼 dc暴       ",
      "cbdca aa暴      H",
      "    楼 bd暴      y",
      "     须须须       y",
      "               y",
      "               ϓ"
    ],
    [
      "                ",
      "                ",
      "                ",
      "                ",
      "                ",
      "                ",
      "                ",
      "                ",
      "                ",
      "                ",
      "     绑约渺        ",
      "     楼g暴       w",
      "     蓄须伺        ",
      "               s",
      "                ",
      "               x"
    ],
    [
      "                ",
      "                ",
      "                ",
      "                ",
      "                ",
      "                ",
      "                ",
      "                ",
      "                ",
      "                ",
      "                ",
      "                ",
      "                ",
      "                ",
      "                ",
      "                "
    ]
  ]
}