{
  "xsize": 16,
  "zsize": 16,
  "palette": {
    "palette": [
      {
        "char": " ",
        "block": "minecraft:air"
      },
      {
        "char": "b",
        "block": "minecraft:basalt[axis=x]"
      },
      {
        "char": "e",
        "block": "minecraft:cyan_terracotta"
      },
      {
        "char": "c",
        "block": "minecraft:deepslate[axis=y]"
      },
      {
        "char": "d",
        "block": "minecraft:cobbled_deepslate"
      },
      {
        "char": "a",
        "block": "minecraft:blackstone"
      },
      {
        "char": "y",
        "block": "minecraft:quartz_slab[type=top]"
      },
      {
        "char": "n",
        "block": "minecraft:black_concrete"
      },
      {
        "char": "邻",
        "block": "minecraft:quartz_stairs[facing=south,half=bottom,shape=outer_left]"
      },
      {
        "char": "o",
        "block": "minecraft:black_stained_glass"
      },
      {
        "char": "泛",
        "block": "minecraft:quartz_stairs[facing=south,half=bottom,shape=outer_right]"
      },
      {
        "char": "C",
        "block": "minecraft:quartz_stairs[facing=east,half=bottom,shape=straight]"
      },
      {
        "char": "z",
        "block": "minecraft:quartz_stairs[facing=west,half=bottom,shape=straight]"
      },
      {
        "char": "s",
        "block": "minecraft:quartz_slab[type=bottom]"
      },
      {
        "char": "Q",
        "block": "minecraft:quartz_slab[type=double]"
      },
      {
        "char": "振",
        "block": "minecraft:smooth_quartz_slab[type=bottom]"
      },
      {
        "char": "秘",
        "block": "minecraft:furnace[facing=south,lit=false]",
        "tag": {
          "z": 983,
          "x": -458,
          "CookTimeTotal": 0,
          "ForgeData": {
            "LockFlag": "1b"
          },
          "CookTime": 0,
          "ForgeCaps": {
            "polymorph:block_entity_recipe_data": {}
          },
          "id": "minecraft:furnace",
          "y": 130,
          "Items": [],
          "BurnTime": 0,
          "RecipesUsed": {}
        }
      },
      {
        "char": "w",
        "block": "minecraft:quartz_stairs[facing=south,half=bottom,shape=straight]"
      },
      {
        "char": "ϓ",
        "block": "minecraft:quartz_stairs[facing=north,half=top,shape=straight]"
      },
      {
        "char": "g",
        "block": "minecraft:redstone_lamp[lit=false]"
      }
    ]
  },
  "slices": [
    [
      "becdbbbddcccbadb",
      "adccaceebdebbdec",
      "badbababccbdcaea",
      "bcdcedabcadaccdc",
      "beddecbdaeeaeaca",
      "eacccebccaeebdbb",
      "beaeecdddacad   ",
      "aeaadc          ",
      "                ",
      "                ",
      "                ",
      "                ",
      "                ",
      "                ",
      "                ",
      "                "
    ],
    [
      "       y        ",
      "       y        ",
      "      y y       ",
      "                ",
      "y               ",
      "      n n       ",
      "             aec",
      "n     eacbabce  ",
      "bdeaacb         ",
      "b               ",
      "                ",
      "                ",
      "                ",
      "                ",
      "                ",
      "                "
    ],
    [
      "      邻o泛       ",
      "      Coz       ",
      "泛    ssQss      ",
      "z   zs振Q振sC     ",
      "ss     Q        ",
      "振sC   C秘z       ",
      "                ",
      "z             cd",
      "       bbacbbac ",
      " cbedeea        ",
      "ad              ",
      "                ",
      "                ",
      "                ",
      "                ",
      "                "
    ],
    [
      "                ",
      "                ",
      "                ",
      "                ",
      "       w        ",
      "      yϓy       ",
      "                ",
      "y               ",
      "               e",
      "        cdbabbb ",
      "  cddabbc       ",
      "ece             ",
      "                ",
      "                ",
      "                ",
      "                "
    ],
    [
      "                ",
      "                ",
      "                ",
      "                ",
      "                ",
      "                ",
      "                ",
      "                ",
      "                ",
      "              gb",
      "        gdaabdab",
      "  gdeacabe      ",
      "dcec            ",
      "                ",
      "                ",
      "                "
    ],
    [
      "                ",
      "                ",
      "                ",
      "                ",
      "                ",
      "                ",
      "                ",
      "                ",
      "                ",
      "                ",
      "          babdbe",
      "    acaecc      ",
      "acce            ",
      "                ",
      "                ",
      "                "
    ]
  ]
}