{
  "xsize": 16,
  "zsize": 16,
  "palette": {
    "palette": [
      {
        "char": " ",
        "block": "minecraft:air"
      },
      {
        "char": "h",
        "block": "minecraft:red_terracotta"
      },
      {
        "char": "d",
        "block": "minecraft:cobbled_deepslate"
      },
      {
        "char": "a",
        "block": "minecraft:blackstone"
      },
      {
        "char": "c",
        "block": "minecraft:deepslate[axis=y]"
      },
      {
        "char": "b",
        "block": "minecraft:basalt[axis=x]"
      },
      {
        "char": "e",
        "block": "minecraft:cyan_terracotta"
      },
      {
        "char": "ϔ",
        "block": "minecraft:observer[facing=south,powered=false]"
      },
      {
        "char": "ϖ",
        "block": "minecraft:cauldron"
      },
      {
        "char": "燕",
        "block": "minecraft:dark_oak_door[facing=east,half=lower,hinge=right,open=false]"
      },
      {
        "char": "暨",
        "block": "minecraft:air"
      },
      {
        "char": "喂",
        "block": "minecraft:dark_oak_door[facing=south,half=lower,hinge=right,open=false]"
      },
      {
        "char": "B",
        "block": "minecraft:iron_trapdoor[facing=north,half=bottom,open=false]"
      },
      {
        "char": "陌",
        "block": "minecraft:air"
      },
      {
        "char": "奔",
        "block": "minecraft:tripwire_hook[attached=false,facing=south,powered=false]"
      },
      {
        "char": "斜",
        "block": "minecraft:dark_oak_door[facing=east,half=upper,hinge=right,open=false]"
      },
      {
        "char": "滋",
        "block": "minecraft:dark_oak_door[facing=south,half=upper,hinge=right,open=false]"
      },
      {
        "char": "P",
        "block": "minecraft:dark_oak_trapdoor[facing=north,half=bottom,open=true]"
      },
      {
        "char": "家",
        "block": "minecraft:white_wall_banner",
        "tag": {
          "z": 939,
          "Patterns": [
            {
              "Color": 8,
              "Pattern": "dls"
            },
            {
              "Color": 0,
              "Pattern": "dls"
            },
            {
              "Color": 3,
              "Pattern": "gru"
            },
            {
              "Color": 8,
              "Pattern": "bo"
            }
          ],
          "x": -499,
          "ForgeCaps": {},
          "id": "minecraft:banner",
          "y": 117
        }
      },
      {
        "char": "恢",
        "block": "minecraft:dark_oak_trapdoor[facing=west,half=top,open=true]"
      },
      {
        "char": "诡",
        "block": "minecraft:dark_oak_trapdoor[facing=east,half=top,open=true]"
      },
      {
        "char": "蛙",
        "block": "minecraft:tripwire_hook[attached=false,facing=west,powered=false]"
      },
      {
        "char": "胞",
        "block": "minecraft:dark_oak_trapdoor[facing=north,half=top,open=true]"
      },
      {
        "char": "燃",
        "block": "minecraft:dark_oak_trapdoor[facing=south,half=top,open=true]"
      },
      {
        "char": "g",
        "block": "minecraft:redstone_lamp[lit=false]"
      },
      {
        "char": "啪",
        "block": "minecraft:dark_oak_trapdoor[facing=south,half=top,open=false]"
      },
      {
        "char": "采",
        "block": "minecraft:tripwire_hook[attached=false,facing=north,powered=false]"
      }
    ]
  },
  "slices": [
    [
      "  hh       h    ",
      "hhhhhhhh   h    ",
      "           d    ",
      "                ",
      "                ",
      "                ",
      "                ",
      "                ",
      "                ",
      "                ",
      "                ",
      "                ",
      "                ",
      "                ",
      "                ",
      "                "
    ],
    [
      "  hh       h    ",
      "hhhhhhhhh       ",
      "                ",
      "                ",
      "                ",
      "                ",
      "                ",
      "                ",
      "                ",
      "                ",
      "                ",
      "                ",
      "                ",
      "                ",
      "                ",
      "                "
    ],
    [
      "hhhhhhhhhh  d   ",
      "dacacabebceec   ",
      "edcebed         ",
      "cabcbaa         ",
      "ddb             ",
      "                ",
      "                ",
      "                ",
      "                ",
      "                ",
      "                ",
      "                ",
      "                ",
      "                ",
      "                ",
      "                "
    ],
    [
      "ϔdcbeabecb   d  ",
      "ϖ      燕暨c   c  ",
      "   c喂b喂acee  b  ",
      "喂d喂aBc陌a        ",
      "ϖaϖdaaa         ",
      "ada             ",
      "                ",
      "                ",
      "                ",
      "                ",
      "                ",
      "                ",
      "                ",
      "                ",
      "                ",
      "                "
    ],
    [
      "beeeceebbd      ",
      "奔      斜 d      ",
      "   a滋d滋bcb    ed",
      "滋d滋e c adcddadb ",
      "PcPecbccd       ",
      "ecbc            ",
      "                ",
      "                ",
      "                ",
      "                ",
      "                ",
      "                ",
      "                ",
      "                ",
      "                ",
      "                "
    ],
    [
      "bdaecbbaba      ",
      "家 恢    诡蛙e      ",
      " 胞 c燃c燃agd   gbd",
      "燃d啪g采g采gbadbcaa ",
      " g ebacec       ",
      "bbee            ",
      "                ",
      "                ",
      "                ",
      "                ",
      "                ",
      "                ",
      "                ",
      "                ",
      "                ",
      "                "
    ]
  ]
}