{
  "xsize": 16,
  "zsize": 16,
  "palette": {
    "palette": [
      {
        "char": " ",
        "block": "minecraft:air"
      },
      {
        "char": "c",
        "block": "minecraft:deepslate[axis=y]"
      },
      {
        "char": "d",
        "block": "minecraft:cobbled_deepslate"
      },
      {
        "char": "e",
        "block": "minecraft:cyan_terracotta"
      },
      {
        "char": "b",
        "block": "minecraft:basalt[axis=x]"
      },
      {
        "char": "q",
        "block": "minecraft:gold_block"
      },
      {
        "char": "a",
        "block": "minecraft:blackstone"
      },
      {
        "char": "f",
        "block": "minecraft:light_gray_concrete"
      },
      {
        "char": "愈",
        "block": "minecraft:birch_wall_sign[facing=west,waterlogged=false]",
        "tag": {
          "z": 979,
          "x": -456,
          "is_waxed": "0b",
          "ForgeCaps": {
            "supplementaries:antique_ink": {
              "ink": "0b"
            }
          },
          "id": "minecraft:sign",
          "y": 116,
          "front_text": {
            "color": "black",
            "has_glowing_text": "0b",
            "messages": [
              "{\"extra\":[{\"text\":\"Officer's bunks\"}],\"text\":\"\"}",
              "{\"extra\":[{\"text\":\"^\"}],\"text\":\"\"}",
              "{\"extra\":[{\"text\":\"|\"}],\"text\":\"\"}",
              "{\"text\":\"\"}"
            ]
          },
          "back_text": {
            "color": "black",
            "has_glowing_text": "0b",
            "messages": [
              "{\"text\":\"\"}",
              "{\"text\":\"\"}",
              "{\"text\":\"\"}",
              "{\"text\":\"\"}"
            ]
          }
        }
      },
      {
        "char": "妇",
        "block": "minecraft:lever[face=wall,facing=west,powered=false]"
      },
      {
        "char": "g",
        "block": "minecraft:redstone_lamp[lit=false]"
      },
      {
        "char": "H",
        "block": "minecraft:quartz_stairs[facing=south,half=top,shape=straight,waterlogged=false]"
      },
      {
        "char": "推",
        "block": "minecraft:quartz_block"
      },
      {
        "char": "z",
        "block": "minecraft:quartz_stairs[facing=west,half=bottom,shape=straight,waterlogged=false]"
      },
      {
        "char": "鄙",
        "block": "minecraft:dark_oak_button[face=wall,facing=west,powered=false]"
      },
      {
        "char": "未",
        "block": "minecraft:air",
        "tag": {
          "z": 948,
          "x": -513,
          "ForgeCaps": {},
          "id": "minecraft:air",
          "y": 117,
          "NodePos": "-141012362379147L",
          "Connections": [
            "L"
          ]
        }
      },
      {
        "char": "C",
        "block": "minecraft:quartz_stairs[facing=east,half=bottom,shape=straight,waterlogged=false]"
      },
      {
        "char": "父",
        "block": "minecraft:air",
        "tag": {
          "z": 953,
          "x": -457,
          "ForgeCaps": {},
          "id": "minecraft:air",
          "y": 117,
          "NodePos": "-125619199569803L",
          "Connections": [
            "L"
          ]
        }
      },
      {
        "char": "井",
        "block": "minecraft:air",
        "tag": {
          "z": 958,
          "x": -325,
          "ForgeCaps": {},
          "id": "minecraft:air",
          "y": 117,
          "NodePos": "-89335315832715L",
          "Connections": [
            "L"
          ]
        }
      }
    ]
  },
  "slices": [
    [
      "                ",
      "                ",
      "                ",
      "                ",
      "                ",
      "                ",
      "ccdeb           ",
      "q qqdaebaed     ",
      "q qq qq qqbeabbe",
      "q qq qq qq qq qq",
      "                ",
      "ffffffffffffffff",
      "               愈",
      "                ",
      "               妇",
      "ffffffffffffffff"
    ],
    [
      "                ",
      "                ",
      "                ",
      "                ",
      "                ",
      "aaedaa          ",
      "q qqgeeaebca    ",
      "q qq qq qqgccbed",
      "q qq qq qq qq qq",
      "q qq qq qq qq qq",
      "q qq qq qq qq qq",
      "ffffffffffffffff",
      "                ",
      "                ",
      "                ",
      "ffffffffffffffff"
    ],
    [
      "                ",
      "                ",
      "                ",
      "c               ",
      "ceededc         ",
      "caaddeaccceac   ",
      "abeccbcadabedcbe",
      "deeddecccbdedeac",
      "aedabeeaddacddcc",
      "cabaadeddeaacece",
      "eabdcdeabbccaecd",
      "cbeededcdcbbaebe",
      "dbcacbabddbcebae",
      "acebadeccdbadeac",
      "aabddceeeddecdda",
      "acecaacdeadbbded"
    ],
    [
      "                ",
      "                ",
      "ba              ",
      " cabcbbc        ",
      "       adadadb  ",
      " H           dbe",
      " f    推z        ",
      "ff              ",
      " f         推z   ",
      "ff              ",
      " f              ",
      "dcecbabdbceceebc",
      "                ",
      "                ",
      "                ",
      "bdedeacceaccaede"
    ],
    [
      "                ",
      "                ",
      "ac              ",
      " cdeaccc        ",
      "       abedeee  ",
      "             ecb",
      "     鄙推         ",
      "ff              ",
      "          鄙推    ",
      "ff              ",
      "               鄙",
      "ffffffffffffffff",
      "                ",
      "                ",
      "               妇",
      "ffffffffffffffff"
    ],
    [
      "                ",
      "ede             ",
      " gdbdbadd       ",
      "       gbddbebe ",
      " 未       未   gdd",
      "                ",
      "      g         ",
      " C              ",
      "           g    ",
      " C              ",
      "  父      父      ",
      "ffffffffffffffff",
      "  井     井     井 ",
      "                ",
      "  井     井     井 ",
      "fffgfffffgffffff"
    ]
  ]
}