{
  "xsize": 16,
  "zsize": 16,
  "palette": {
    "palette": [
      {
        "char": " ",
        "block": "minecraft:air"
      },
      {
        "char": "B",
        "block": "minecraft:iron_trapdoor[facing=north,half=bottom,open=false]"
      },
      {
        "char": "陌",
        "block": "minecraft:air"
      },
      {
        "char": "e",
        "block": "minecraft:cyan_terracotta"
      },
      {
        "char": "d",
        "block": "minecraft:cobbled_deepslate"
      },
      {
        "char": "b",
        "block": "minecraft:basalt[axis=x]"
      },
      {
        "char": "c",
        "block": "minecraft:deepslate[axis=y]"
      },
      {
        "char": "a",
        "block": "minecraft:blackstone"
      },
      {
        "char": "i",
        "block": "minecraft:white_concrete"
      },
      {
        "char": "g",
        "block": "minecraft:redstone_lamp[lit=false]"
      },
      {
        "char": "n",
        "block": "minecraft:black_concrete"
      },
      {
        "char": "y",
        "block": "minecraft:quartz_slab[type=top]"
      },
      {
        "char": "x",
        "block": "minecraft:quartz_stairs[facing=north,half=bottom,shape=straight]"
      },
      {
        "char": "s",
        "block": "minecraft:quartz_slab[type=bottom]"
      },
      {
        "char": "w",
        "block": "minecraft:quartz_stairs[facing=south,half=bottom,shape=straight]"
      },
      {
        "char": "振",
        "block": "minecraft:smooth_quartz_slab[type=bottom]"
      },
      {
        "char": "谜",
        "block": "minecraft:quartz_stairs[facing=west,half=bottom,shape=outer_left]"
      },
      {
        "char": "驻",
        "block": "minecraft:furnace[facing=west,lit=false]",
        "tag": {
          "z": 953,
          "x": -551,
          "CookTimeTotal": 0,
          "ForgeData": {
            "LockFlag": "1b"
          },
          "CookTime": 0,
          "ForgeCaps": {
            "polymorph:block_entity_recipe_data": {}
          },
          "id": "minecraft:furnace",
          "y": 120,
          "Items": [],
          "BurnTime": 0,
          "RecipesUsed": {}
        }
      },
      {
        "char": "Q",
        "block": "minecraft:quartz_slab[type=double]"
      },
      {
        "char": "o",
        "block": "minecraft:black_stained_glass"
      },
      {
        "char": "仿",
        "block": "minecraft:quartz_stairs[facing=west,half=bottom,shape=outer_right]"
      },
      {
        "char": "J",
        "block": "minecraft:quartz_stairs[facing=east,half=top,shape=straight]"
      },
      {
        "char": "z",
        "block": "minecraft:quartz_stairs[facing=west,half=bottom,shape=straight]"
      }
    ]
  },
  "slices": [
    [
      "                ",
      "BB陌BBBBBBBBBBBBB",
      "edbecaccdceeecec",
      "bbbbeecdeedcaabc",
      "bbcbdabaededbdbb",
      "iiiiiiiiiiiiiiii",
      "cbabdeddcbacccad",
      "ccedaebebdadedec",
      "cbaddaaacdcdcdba",
      "bbeadbdcdbcdddec",
      "cebccaeebaecebba",
      "aabbdbcaceaacdcb",
      "edebbdccdcdabaed",
      "giaedigiacbigiaa",
      "cbdeaedcebecbeca",
      "eecbaddaacadcbed"
    ],
    [
      "                ",
      "                ",
      "            dg  ",
      "       acadbeg  ",
      "            cg  ",
      "                ",
      "                ",
      "                ",
      "                ",
      "                ",
      "       n  y     ",
      "           yyn  ",
      "       n  y     ",
      "                ",
      "                ",
      "                "
    ],
    [
      "                ",
      "                ",
      "             g  ",
      "          ceeg  ",
      "             g  ",
      "                ",
      "                ",
      "                ",
      "         x      ",
      "         ss     ",
      "       w 振sw谜   ",
      "       驻QQQooss ",
      "       x 振sx仿   ",
      "         ss     ",
      "         w      ",
      "                "
    ],
    [
      "                ",
      "                ",
      "             g  ",
      "            ag  ",
      "             g  ",
      "                ",
      "                ",
      "                ",
      "                ",
      "                ",
      "       y        ",
      "       Jz       ",
      "       y        ",
      "                ",
      "                ",
      "                "
    ],
    [
      "                ",
      "                ",
      "                ",
      "                ",
      "                ",
      "                ",
      "                ",
      "                ",
      "                ",
      "                ",
      "                ",
      "                ",
      "                ",
      "                ",
      "                ",
      "                "
    ],
    [
      "                ",
      "                ",
      "                ",
      "                ",
      "                ",
      "                ",
      "                ",
      "                ",
      "                ",
      "                ",
      "                ",
      "                ",
      "                ",
      "                ",
      "                ",
      "                "
    ]
  ]
}