{
  "xsize": 16,
  "zsize": 16,
  "palette": {
    "palette": [
      {
        "char": " ",
        "block": "minecraft:air"
      },
      {
        "char": "e",
        "block": "minecraft:cyan_terracotta"
      },
      {
        "char": "b",
        "block": "minecraft:basalt[axis=x]"
      },
      {
        "char": "a",
        "block": "minecraft:blackstone"
      },
      {
        "char": "c",
        "block": "minecraft:deepslate[axis=y]"
      },
      {
        "char": "d",
        "block": "minecraft:cobbled_deepslate"
      },
      {
        "char": "ҕ",
        "block": "minecraft:chest",
        "loot": "bigbuildingsloot",
        "tag": {
          "z": 942,
          "x": -502,
          "ForgeData": {
            "LockFlag": "1b"
          },
          "ForgeCaps": {},
          "id": "minecraft:chest",
          "y": 112,
          "Items": []
        }
      },
      {
        "char": "Ѷ",
        "block": "minecraft:chest",
        "loot": "bigbuildingsloot",
        "tag": {
          "z": 940,
          "x": -437,
          "ForgeData": {
            "LockFlag": "1b"
          },
          "ForgeCaps": {},
          "id": "minecraft:chest",
          "y": 115,
          "Items": []
        }
      },
      {
        "char": "寮",
        "block": "minecraft:sticky_piston[extended=true,facing=east]"
      },
      {
        "char": "衰",
        "block": "minecraft:piston_head[facing=east,short=false,type=sticky]"
      },
      {
        "char": "蹈",
        "block": "minecraft:piston_head[facing=west,short=false,type=sticky]"
      },
      {
        "char": "竿",
        "block": "minecraft:sticky_piston[extended=true,facing=west]"
      },
      {
        "char": "啪",
        "block": "minecraft:dark_oak_trapdoor[facing=south,half=top,open=false]"
      },
      {
        "char": "椅",
        "block": "minecraft:sticky_piston[extended=true,facing=south]"
      },
      {
        "char": "鹤",
        "block": "minecraft:piston_head[facing=south,short=false,type=sticky]"
      },
      {
        "char": "g",
        "block": "minecraft:redstone_lamp[lit=false]"
      },
      {
        "char": "澈",
        "block": "minecraft:redstone_wire[north=none,west=none]"
      },
      {
        "char": "坛",
        "block": "minecraft:redstone_wall_torch[facing=west,lit=true]"
      },
      {
        "char": "虞",
        "block": "minecraft:redstone_wire[north=none,west=none]"
      },
      {
        "char": "芦",
        "block": "minecraft:redstone_wire[north=none,south=none]"
      },
      {
        "char": "挚",
        "block": "minecraft:redstone_wire[north=none,south=none]"
      },
      {
        "char": "蜡",
        "block": "minecraft:redstone_wire[north=none,south=none]"
      },
      {
        "char": "裙",
        "block": "minecraft:redstone_wire[north=none,south=none]"
      },
      {
        "char": "芸",
        "block": "minecraft:redstone_wire[east=none]"
      },
      {
        "char": "绅",
        "block": "minecraft:redstone_wire[east=none,west=none]"
      },
      {
        "char": "谭",
        "block": "minecraft:redstone_wire[east=none,west=none]"
      },
      {
        "char": "莽",
        "block": "minecraft:redstone_wire[east=none,north=none,south=up]"
      },
      {
        "char": "篠",
        "block": "minecraft:redstone_wire[north=none,south=up,west=none]"
      }
    ]
  },
  "slices": [
    [
      "                ",
      "                ",
      "                ",
      "                ",
      "                ",
      "                ",
      "                ",
      "                ",
      "                ",
      "                ",
      "                ",
      "                ",
      "                ",
      "                ",
      "                ",
      "                "
    ],
    [
      "                ",
      "                ",
      "                ",
      "                ",
      "                ",
      "                ",
      "                ",
      "                ",
      "                ",
      "                ",
      "                ",
      "                ",
      "                ",
      "                ",
      "                ",
      "                "
    ],
    [
      "                ",
      "                ",
      "                ",
      "                ",
      "                ",
      "                ",
      "                ",
      "                ",
      "                ",
      "                ",
      "                ",
      "          eb    ",
      "        accaacab",
      "    bcdaeecbeaca",
      "eebdbaadaeadaeda",
      "cbedbbdbedbecdda"
    ],
    [
      "                ",
      "                ",
      "                ",
      "                ",
      "                ",
      "                ",
      "                ",
      "                ",
      "                ",
      "                ",
      "        d bdcaeb",
      "    acbdabҕѶdcad",
      "dacdaadb寮衰da蹈竿  ",
      "cebebb   e  b   ",
      "啪啪啪啪啪c椅椅d    e椅椅",
      "     d鹤鹤b    d鹤鹤"
    ],
    [
      "                ",
      "                ",
      "                ",
      "                ",
      "                ",
      "                ",
      "                ",
      "                ",
      "                ",
      "          caaeac",
      "   dbadedeaccc a",
      "baad a  cc  da a",
      "accbga  寮衰ca蹈竿  ",
      "     dcdca  edad",
      "     b椅椅e    b椅椅",
      "     e鹤鹤c    d鹤鹤"
    ],
    [
      "                ",
      "                ",
      "                ",
      "                ",
      "                ",
      "                ",
      "                ",
      "                ",
      "         aeeabcd",
      "  ebebeaaeg  澈坛b",
      "cdeg d  虞芦挚蜡裙芸  ",
      "     e  绅 ad 谭  ",
      "bacdgd   bcca   ",
      "     b裙莽 adac 篠裙",
      "     a b dgga e ",
      "     a cbcddccc "
    ]
  ]
}