{
  "xsize": 16,
  "zsize": 16,
  "palette": {
    "palette": [
      {
        "char": " ",
        "block": "minecraft:air"
      },
      {
        "char": "c",
        "block": "minecraft:deepslate[axis=y]"
      },
      {
        "char": "b",
        "block": "minecraft:basalt[axis=x]"
      },
      {
        "char": "d",
        "block": "minecraft:cobbled_deepslate"
      },
      {
        "char": "a",
        "block": "minecraft:blackstone"
      },
      {
        "char": "e",
        "block": "minecraft:cyan_terracotta"
      },
      {
        "char": "i",
        "block": "minecraft:white_concrete"
      },
      {
        "char": "f",
        "block": "minecraft:light_gray_concrete"
      },
      {
        "char": "A",
        "block": "minecraft:iron_trapdoor[facing=south,half=bottom,open=false]"
      },
      {
        "char": "介",
        "block": "minecraft:iron_trapdoor[facing=east,half=bottom,open=false]"
      },
      {
        "char": "约",
        "block": "minecraft:smooth_quartz_stairs[facing=south,half=bottom,shape=straight]"
      },
      {
        "char": "暴",
        "block": "minecraft:smooth_quartz_stairs[facing=west,half=bottom,shape=straight]"
      },
      {
        "char": "须",
        "block": "minecraft:smooth_quartz_stairs[facing=north,half=bottom,shape=straight]"
      },
      {
        "char": "M",
        "block": "minecraft:quartz_pillar[axis=y]"
      },
      {
        "char": "闯",
        "block": "minecraft:lever[face=ceiling,facing=west,powered=true]"
      },
      {
        "char": "唷",
        "block": "minecraft:white_wall_banner",
        "tag": {
          "z": 944,
          "Patterns": [
            {
              "Color": 8,
              "Pattern": "dls"
            },
            {
              "Color": 0,
              "Pattern": "dls"
            },
            {
              "Color": 3,
              "Pattern": "gru"
            },
            {
              "Color": 8,
              "Pattern": "bo"
            }
          ],
          "x": -405,
          "ForgeCaps": {},
          "id": "minecraft:banner",
          "y": 110
        }
      },
      {
        "char": "穴",
        "block": "minecraft:air"
      },
      {
        "char": "救",
        "block": "minecraft:iron_trapdoor[facing=west,half=bottom,open=false]"
      }
    ]
  },
  "slices": [
    [
      "cbdbbaebcddaaaad",
      "babebcaeadbaaeae",
      "abbbaaebccbbaecc",
      "eebbcbcdceadaceb",
      "deceddabdbcaacbe",
      "iiiiiiiiiiiiiiii",
      "bbabdbeedeebabae",
      "abceecebcbbecbdc",
      "fdadbddbbbdcabee",
      "dfeaabcacdedccab",
      " afdaaaaeeddedda",
      "edfbeecbdcceeaba",
      " efdaeeddbecbaAA",
      " fcbedbeAAAAA介  ",
      "fdbcaAAA        ",
      "AA              "
    ],
    [
      "                ",
      "                ",
      "                ",
      "                ",
      "                ",
      "                ",
      "                ",
      "                ",
      "约               ",
      "i约              ",
      "fi暴             ",
      "ai暴             ",
      " i暴             ",
      "i暴              ",
      "须               ",
      "                "
    ],
    [
      "                ",
      "                ",
      "                ",
      "                ",
      "                ",
      "                ",
      "                ",
      "                ",
      "                ",
      "i               ",
      "ai              ",
      "Mi    闯         ",
      "唷i              ",
      "i               ",
      "                ",
      "                "
    ],
    [
      "                ",
      "                ",
      "                ",
      "                ",
      "                ",
      "                ",
      "                ",
      "                ",
      "                ",
      "约               ",
      "c暴              ",
      "dbdddca穴        ",
      "d暴              ",
      "须               ",
      "                ",
      "                "
    ],
    [
      "                ",
      "                ",
      "                ",
      "                ",
      "                ",
      "                ",
      "                ",
      "                ",
      "                ",
      "                ",
      "救               ",
      "救               ",
      "救               ",
      "                ",
      "                ",
      "                "
    ],
    [
      "                ",
      "                ",
      "                ",
      "                ",
      "                ",
      "                ",
      "                ",
      "                ",
      "                ",
      "                ",
      "                ",
      "                ",
      "                ",
      "                ",
      "                ",
      "                "
    ]
  ]
}