{
  "xsize": 16,
  "zsize": 16,
  "palette": {
    "palette": [
      {
        "char": " ",
        "block": "minecraft:air"
      },
      {
        "char": "m",
        "block": "minecraft:water"
      },
      {
        "char": "җ",
        "block": "minecraft:water"
      },
      {
        "char": "n",
        "block": "minecraft:black_concrete"
      },
      {
        "char": "佬",
        "block": "minecraft:quartz_slab[type=top]"
      },
      {
        "char": "罩",
        "block": "minecraft:water"
      },
      {
        "char": "捏",
        "block": "minecraft:quartz_stairs[facing=north,half=bottom,shape=straight]"
      },
      {
        "char": "矢",
        "block": "minecraft:quartz_slab[type=bottom]"
      },
      {
        "char": "s",
        "block": "minecraft:quartz_slab[type=bottom]"
      },
      {
        "char": "庚",
        "block": "minecraft:quartz_stairs[facing=south,half=bottom,shape=straight]"
      },
      {
        "char": "翟",
        "block": "minecraft:smooth_quartz_slab[type=bottom]"
      },
      {
        "char": "w",
        "block": "minecraft:quartz_stairs[facing=south,half=bottom,shape=straight]"
      },
      {
        "char": "谜",
        "block": "minecraft:quartz_stairs[facing=west,half=bottom,shape=outer_left]"
      },
      {
        "char": "驻",
        "block": "minecraft:furnace[facing=west,lit=false]",
        "tag": {
          "z": 953,
          "x": -551,
          "CookTimeTotal": 0,
          "ForgeData": {
            "LockFlag": "1b"
          },
          "CookTime": 0,
          "ForgeCaps": {
            "polymorph:block_entity_recipe_data": {}
          },
          "id": "minecraft:furnace",
          "y": 120,
          "Items": [],
          "BurnTime": 0,
          "RecipesUsed": {}
        }
      },
      {
        "char": "Q",
        "block": "minecraft:quartz_slab[type=double]"
      },
      {
        "char": "o",
        "block": "minecraft:black_stained_glass"
      },
      {
        "char": "振",
        "block": "minecraft:smooth_quartz_slab[type=bottom]"
      },
      {
        "char": "x",
        "block": "minecraft:quartz_stairs[facing=north,half=bottom,shape=straight]"
      },
      {
        "char": "仿",
        "block": "minecraft:quartz_stairs[facing=west,half=bottom,shape=outer_right]"
      }
    ]
  },
  "slices": [
    [
      "                ",
      "                ",
      "       m m      ",
      "      mm mmm    ",
      "     m mmmmmmm  ",
      "     m  mmmm  m ",
      "     m mmmmmmm  ",
      "      mm mmm    ",
      "       m m      ",
      "                ",
      "                ",
      "                ",
      "                ",
      "                ",
      "                ",
      "                "
    ],
    [
      "                ",
      "                ",
      "       m m      ",
      "      mm mmm    ",
      "     m mmmmmmm  ",
      "     m  mmmm  m ",
      "     m mmmmmmm  ",
      "      mm mmm    ",
      "       m m      ",
      "                ",
      "                ",
      "                ",
      "                ",
      "                ",
      "                ",
      "                "
    ],
    [
      "                ",
      "                ",
      "       m m      ",
      "      mm mmm    ",
      "     m mmmmmmm  ",
      "     m  mmmm  m ",
      "     m mmmmmmm  ",
      "      mm mmm    ",
      "       m m      ",
      "                ",
      "                ",
      "                ",
      "                ",
      "                ",
      "                ",
      "                "
    ],
    [
      "                ",
      "                ",
      "       m m      ",
      "      mm mmm    ",
      "     m mmmmmmm  ",
      "     m  mmmm  m ",
      "     m mmmmmmm  ",
      "      mm mmm    ",
      "       m m      ",
      "                ",
      "                ",
      "                ",
      "                ",
      "                ",
      "                ",
      "                "
    ],
    [
      "                ",
      "                ",
      "       m m      ",
      "      mm җmm    ",
      "     mnmҗ佬җҗmm  ",
      "     m  罩җ佬佬n m ",
      "     mnmҗ佬җҗmm  ",
      "      mm җmm    ",
      "       m m      ",
      "                ",
      "                ",
      "                ",
      "                ",
      "                ",
      "                ",
      "                "
    ],
    [
      "                ",
      "                ",
      "       җ捏җ      ",
      "      mҗ矢smm    ",
      "     m庚m翟sw谜mҗ  ",
      "     m驻QQQoos矢җ ",
      "     m捏m振sx仿mҗ  ",
      "      mҗ矢矢mm    ",
      "       җ庚җ      ",
      "                ",
      "                ",
      "                ",
      "                ",
      "                ",
      "                ",
      "                "
    ]
  ]
}