{
  "xsize": 16,
  "zsize": 16,
  "palette": {
    "palette": [
      {
        "char": " ",
        "block": "minecraft:air"
      },
      {
        "char": "f",
        "block": "minecraft:air"
      },
      {
        "char": "b",
        "block": "minecraft:air"
      },
      {
        "char": "p",
        "block": "minecraft:air"
      },
      {
        "char": "n",
        "block": "minecraft:air"
      },
      {
        "char": "C",
        "block": "minecraft:air"
      },
      {
        "char": "物",
        "block": "minecraft:air"
      },
      {
        "char": "ђ",
        "block": "minecraft:chest",
        "tag": {
          "SpawnData": {
            "entity": {}
          },
          "MaxNearbyEntities": "6s",
          "MinSpawnDelay": "200s",
          "z": 359,
          "x": 108,
          "MaxSpawnDelay": "800s",
          "RequiredPlayerRange": "16s",
          "SpawnCount": "4s",
          "ForgeCaps": {},
          "id": "minecraft:mob_spawner",
          "SpawnPotentials": [],
          "y": 132,
          "SpawnRange": "4s",
          "Delay": "416s"
        }
      },
      {
        "char": "Ӥ",
        "block": "minecraft:air"
      },
      {
        "char": "q",
        "block": "minecraft:tall_grass"
      },
      {
        "char": "J",
        "block": "minecraft:air"
      },
      {
        "char": "k",
        "block": "minecraft:air"
      },
      {
        "char": "z",
        "block": "minecraft:air"
      },
      {
        "char": "y",
        "block": "minecraft:air"
      },
      {
        "char": "I",
        "block": "minecraft:air"
      },
      {
        "char": "地",
        "block": "minecraft:air"
      },
      {
        "char": "t",
        "block": "minecraft:air"
      },
      {
        "char": "o",
        "block": "minecraft:air"
      },
      {
        "char": "h",
        "block": "minecraft:air"
      },
      {
        "char": "Q",
        "block": "minecraft:air"
      },
      {
        "char": "U",
        "block": "minecraft:tall_grass[half=lower]"
      },
      {
        "char": "些",
        "block": "minecraft:air"
      },
      {
        "char": "名",
        "block": "minecraft:air"
      },
      {
        "char": "u",
        "block": "minecraft:air"
      },
      {
        "char": "w",
        "block": "minecraft:air"
      },
      {
        "char": "清",
        "block": "minecraft:air"
      },
      {
        "char": "长",
        "block": "minecraft:chest",

        "tag": {
          "z": 338,
          "x": 108,
          "ForgeData": {
            "LockFlag": "1b"
          },
          "ForgeCaps": {},
          "id": "minecraft:chest",
          "y": 133,
          "Items": []
        }
      },
      {
        "char": "快",
        "block": "minecraft:air"
      },
      {
        "char": "O",
        "block": "minecraft:air"
      },
      {
        "char": "黑",
        "block": "minecraft:air"
      },
      {
        "char": "r",
        "block": "minecraft:air"
      },
      {
        "char": "i",
        "block": "minecraft:air"
      },
      {
        "char": "3",
        "block": "minecraft:air"
      },
      {
        "char": "V",
        "block": "minecraft:tall_grass[half=upper]"
      },
      {
        "char": "s",
        "block": "minecraft:air"
      },
      {
        "char": "m",
        "block": "minecraft:air"
      },
      {
        "char": "v",
        "block": "minecraft:air"
      },
      {
        "char": "H",
        "block": "minecraft:air"
      }
    ]
  },
  "slices": [
    [
      "fffbffffffffffff",
      "bfffffffffffffff",
      "bppfffffffffffff",
      "fppfffffffffffff",
      "nnppffffffffffff",
      "nCppffffffffffff",
      "nn物nbbffffffffff",
      "Cn物nbfffffffffff",
      "nђCpbfffffffffff",
      "ppnCbfffffffffff",
      "n物物pbfffffffffff",
      "n物物pbfffffffffff",
      "npppbbffffffffff",
      "pnnnbfffffffffff",
      "nnppbfffffffffff",
      "nnCpbfffffffffff"
    ],
    [
      "ӤqqJkkzzkqkzqqqq",
      "yIIkkqz地zkqqkqkq",
      "tohIzkkzkkkqkqqz",
      "qtoQkkkkqkzzqzqq",
      "kztoIqqqqqkkqzqq",
      "  toIkUUkkkk qqq",
      "些k名tuwkzqkzkk qz",
      "些q名tyIkq地kqqqzkz",
      " 清清tyӤzqkkkqqqqk",
      "kkktuQkqqqqzqkqk",
      "k名名tyQkzUqkqqkzz",
      "k名名tyQkkkqqqzqkq",
      "ttttow地kkzqkkqzk",
      "kq长tuIqkkkkqkqkk",
      "快快 toOq黑kqkqqkqq",
      "快快 tuIqkqzqkzqkz"
    ],
    [
      "                ",
      "r               ",
      "ir3             ",
      " ir             ",
      "  ir            ",
      "  iu  VV        ",
      "   sow          ",
      "   mu           ",
      "   ir           ",
      "   ir           ",
      "   ir   V       ",
      "   mo           ",
      "smmsuw          ",
      "   vo           ",
      "H  ir           ",
      "   ir           "
    ],
    [
      "                ",
      "r               ",
      " r3             ",
      " ir             ",
      "  ir            ",
      "  io            ",
      "   sow          ",
      "   mu           ",
      "   ir           ",
      "   ir           ",
      "    r           ",
      "   mo           ",
      "mmvsow          ",
      "   vu           ",
      "   ir           ",
      "   ir           "
    ],
    [
      "                ",
      "r               ",
      "ir3             ",
      " ir             ",
      "  ir            ",
      "   o            ",
      "   sow          ",
      "   mo           ",
      "   ir           ",
      "   ir           ",
      "   ir           ",
      "   my           ",
      "mmmmuw          ",
      "   sy           ",
      "   ir           ",
      "   ir           "
    ],
    [
      "                ",
      "r               ",
      "ir3             ",
      " ir             ",
      "   r            ",
      "  io            ",
      "   sow          ",
      "   su           ",
      " H ir           ",
      " H  r           ",
      "    r           ",
      "   vo           ",
      "vmsmyw          ",
      "   mo           ",
      "    r           ",
      "   ir           "
    ]
  ]
}