{
  "xsize": 16,
  "zsize": 16,
  "palette": {
    "palette": [
      {
        "char": " ",
        "block": "minecraft:air"
      },
      {
        "char": "a",
        "block": "minecraft:stone"
      },
      {
        "char": "i",
        "block": "minecraft:glass"
      },
      {
        "char": "请",
        "block": "minecraft:stone_brick_stairs[facing=north,half=bottom,shape=straight,waterlogged=false]"
      },
      {
        "char": "投",
        "block": "minecraft:mossy_stone_brick_stairs[facing=north,half=bottom,shape=straight,waterlogged=false]"
      },
      {
        "char": "d",
        "block": "minecraft:stone_bricks"
      },
      {
        "char": "下",
        "block": "minecraft:stone_brick_slab[type=bottom,waterlogged=false]"
      },
      {
        "char": "太",
        "block": "minecraft:mossy_stone_brick_stairs[facing=south,half=bottom,shape=straight,waterlogged=false]"
      },
      {
        "char": "步",
        "block": "minecraft:cobblestone_stairs[facing=south,half=bottom,shape=straight,waterlogged=false]"
      },
      {
        "char": "c",
        "block": "minecraft:mossy_stone_bricks"
      },
      {
        "char": "古",
        "block": "minecraft:cobblestone_stairs[facing=north,half=bottom,shape=straight,waterlogged=false]"
      },
      {
        "char": "仔",
        "block": "minecraft:cobblestone_stairs[facing=east,half=bottom,shape=inner_left,waterlogged=false]"
      },
      {
        "char": "吧",
        "block": "minecraft:stone_brick_stairs[facing=east,half=bottom,shape=straight,waterlogged=false]"
      },
      {
        "char": "期",
        "block": "minecraft:mossy_cobblestone_stairs[facing=east,half=bottom,shape=straight,waterlogged=false]"
      },
      {
        "char": "ӛ",
        "block": "minecraft:vine[east=false,north=false,south=true,up=false,west=false]"
      },
      {
        "char": "b",
        "block": "minecraft:dirt"
      },
      {
        "char": "鹰",
        "block": "minecraft:cobblestone_stairs[facing=east,half=bottom,shape=straight,waterlogged=false]"
      }
    ]
  },
  "slices": [
    [
      "aaaaaaaaaaaaaaaa",
      "aaaaaaaaaaaaaaaa",
      "aaaaaaaaaaaaaaaa",
      "aaaaaaaaaaaaaaaa",
      "iaaaaaaaaaaaaaaa",
      "iaaaaaaaaaaaaaaa",
      "iaaaaaaaaaaaaaaa",
      "iaaaaaaaaaaaaaaa",
      "aaaaaaaaaaaaaaaa",
      "aaaaaaaaaaaaaaaa",
      "aaaaaaaaaaaaaaaa",
      "aaaaaaaaaaaaaaaa",
      "aaaaaaaaaaaaaaaa",
      "aaaaaaaaaaaaaaaa",
      "aaaaaaaaaaaaaaaa",
      "aaaaaaaaaaaaaaaa"
    ],
    [
      "aaaaaaaaaaaaaaaa",
      "aaaaaaaaaaaaaaaa",
      "aaaaaaaaaaaaaaaa",
      "aaaaaaaaaaaaaaaa",
      "iaaaaaaaaaaaaaaa",
      "iaaaaaaaaaaaaaaa",
      "iaaaaaaaaaaaaaaa",
      "iaaaaaaaaaaaaaaa",
      "aaaaaaaaaaaaaaaa",
      "aaaaaaaaaaaaaaaa",
      "aaaaaaaaaaaaaaaa",
      "aaaaaaaaaaaaaaaa",
      "aaaaaaaaaaaaaaaa",
      "aaaaaaaaaaaaaaaa",
      "aaaaaaaaaaaaaaaa",
      "aaaaaaaaaaaaaaaa"
    ],
    [
      "aaaaaaaaaaaaaaaa",
      "aaaaaaaaaaaaaaaa",
      "aaaaaaaaaaaaaaaa",
      "aaaaaaaaaaaaaaaa",
      "iaaaaaaaaaaaaaaa",
      "iaaaaaaaaaaaaaaa",
      "iaaaaaaaaaaaaaaa",
      "iaaaaaaaaaaaaaaa",
      "aaaaaaaaaaaaaaaa",
      "aaaaaaaaaaaaaaaa",
      "aaaaaaaaaaaaaaaa",
      "aaaaaaaaaaaaaaaa",
      "aaaaaaaaaaaaaaaa",
      "aaaaaaaaaaaaaaaa",
      "aaaaaaaaaaaaaaaa",
      "aaaaaaaaaaaaaaaa"
    ],
    [
      "aaaaaaaaaaaaaaaa",
      "请投daaaaaaaaaaaaa",
      "下下daaaaaaaaaaaaa",
      "太步caaaaaaaaaaaaa",
      "idaaaaaaaaaaaaaa",
      "iaaaaaaaaaaaaaaa",
      "iaaaaaaaaaaaaaaa",
      "iaaaaaaaaaaaaaaa",
      "aaaaaaaaaaaaaaaa",
      "aaaaaaaaaaaaaaaa",
      "aaaaaaaaaaaaaaaa",
      "aaaaaaaaaaaaaaaa",
      "aaaaaaaaaaaaaaaa",
      "aaaaaaaaaaaaaaaa",
      "aaaaaaaaaaaaaaaa",
      "aaaaaaaaaaaaaaaa"
    ],
    [
      "请古仔aaaaaaaaaaaaa",
      "  吧aaaaaaaaaaaaa",
      "  期caaaaaaaaaaaa",
      "ӛ caaaaaaaaaaaaa",
      "icaaaaaaaaaaaaaa",
      "iaaaaaaaaaaaaaaa",
      "iaaaaaaaaaaaaaaa",
      "iaaaaaaaaaaaaaaa",
      "aaaaaaaaaaaaaaaa",
      "aaaaaaaaaaaaaaaa",
      "aaaaaaaaaaaaaaaa",
      "aaaaaaaaaaaaaaaa",
      "bbbbbbbbbbbbbbbb",
      "bbbbbbbbbbbbbbbb",
      "bbbbbbbbbbbbbbbb",
      "bbbbbbbbbbbbbbbb"
    ],
    [
      "   鹰aaaaaaaaaaaa",
      "   吧aaaaaaaaaaaa",
      "   daaaaaaaaaaaa",
      "ӛ daaaaaaaaaaaaa",
      "idaaaaaaaaaaaaaa",
      "iaaaaaaaaaaaaaaa",
      "iaaaaaaaaaaaaaaa",
      "iaaaaaaaaaaaaaaa",
      "aaaaaaaaaaaaaaaa",
      "aaaaaaaaaaaaaaaa",
      "aaaaaaaaaaaaaaaa",
      "aaaaaaaaaaaaaaaa",
      "bbbbbbbbbbbbbbbb",
      "bbbbbbbbbbbbbbbb",
      "bbbbbbbbbbbbbbbb",
      "bbbbbbbbbbbbbbbb"
    ]
  ]
}