{
  "xsize": 16,
  "zsize": 16,
  "palette": {
    "palette": [
      {
        "char": " ",
        "block": "minecraft:air"
      },
      {
        "char": "d",
        "block": "minecraft:stone_bricks"
      },
      {
        "char": "e",
        "block": "minecraft:cracked_stone_bricks"
      },
      {
        "char": "c",
        "block": "minecraft:mossy_stone_bricks"
      },
      {
        "char": "j",
        "block": "minecraft:cobblestone"
      },
      {
        "char": "g",
        "block": "minecraft:mossy_cobblestone"
      },
      {
        "char": "V",
        "block": "minecraft:air"
      },
      {
        "char": "ї",
        "block": "minecraft:water"
      },
      {
        "char": "8",
        "block": "minecraft:chiseled_stone_bricks"
      },
      {
        "char": "急",
        "block": "minecraft:oak_trapdoor[facing=south,half=bottom,open=true]"
      },
      {
        "char": "m",
        "block": "minecraft:white_concrete"
      },
      {
        "char": "猪",
        "block": "minecraft:oak_trapdoor[facing=south,half=bottom,open=false]"
      },
      {
        "char": "选",
        "block": "minecraft:tripwire_hook[attached=false,facing=south,powered=false]"
      },
      {
        "char": "毕",
        "block": "minecraft:birch_door[facing=north,half=upper,hinge=right,open=false]"
      },
      {
        "char": "压",
        "block": "minecraft:birch_door[facing=north,half=upper,hinge=left,open=false]"
      },
      {
        "char": "哥",
        "block": "minecraft:light_gray_wall_banner",
        "tag": {
          "z": 318,
          "Patterns": [
            {
              "Color": 0,
              "Pattern": "dls"
            },
            {
              "Color": 3,
              "Pattern": "gru"
            },
            {
              "Color": 15,
              "Pattern": "bo"
            }
          ],
          "x": 107,
          "ForgeCaps": {},
          "id": "minecraft:banner",
          "y": 127
        }
      },
      {
        "char": "B",
        "block": "minecraft:smooth_stone"
      },
      {
        "char": "但",
        "block": "minecraft:stone_brick_stairs[facing=west,half=top,shape=straight]"
      },
      {
        "char": "F",
        "block": "minecraft:stone_brick_slab[type=top]"
      },
      {
        "char": "H",
        "block": "minecraft:redstone_lamp[lit=false]"
      },
      {
        "char": "5",
        "block": "minecraft:water"
      },
      {
        "char": "人",
        "block": "minecraft:redstone_lamp[lit=true]"
      },
      {
        "char": "a",
        "block": "minecraft:stone"
      },
      {
        "char": "G",
        "block": "minecraft:quartz_slab[type=bottom]"
      },
      {
        "char": "刻",
        "block": "minecraft:polished_diorite_slab[type=double]"
      },
      {
        "char": "ӝ",
        "block": "minecraft:water"
      },
      {
        "char": "ό",
        "block": "minecraft:air"
      }
    ]
  },
  "slices": [
    [
      "ddecejgcjgeccegg",
      "gjgedgeggedcdjgj",
      "cgcejcgjcecjecdc",
      "jjcejjecjcjcgcec",
      "eceggcjcccgcegec",
      "jjgceegjcegceccc",
      "ccegcgggc       ",
      "ccgegcjjc VV  ї ",
      "gegcgeejc V 8   ",
      "ecgjgcgje       ",
      "egjeegcge       ",
      "cjjjjgjce V     ",
      "gceccgcecV      ",
      "gjjgcgcdjecg8   ",
      "ccgcc急m猪m选选选c   ",
      "djecc毕m压m   c   "
    ],
    [
      "ccgcgcejcdgdgeej",
      "jecedeccggdjcced",
      "cgecgeedccdejcjc",
      "gcgejgeejcjecgee",
      "gjggeecededdcccg",
      "gggegecgeggccgcg",
      "eggccccgg       ",
      "ggcecceee     ї ",
      "ccjgcggcc   8   ",
      "ecececjec       ",
      "cgeceeceg       ",
      "cceccggge       ",
      "jgecjjgcg       ",
      "ejegjccccgcg8   ",
      "ceece    哥哥哥g   ",
      "jecce       g   "
    ],
    [
      "dgdgdgcccejdjccc",
      "cgejcgjcgccjcccg",
      "jeeejjcdcdggccjc",
      "cccecdgjjgccjegc",
      "Bjccecgcgcjeeecc",
      "Bcccgcjjdeegceeg",
      "Bjdgegjce       ",
      "Beegecegj     ї ",
      "Bcegccded   8   ",
      "Bejcjgccc       ",
      "Bgcjgdejc       ",
      "Bgececdeg       ",
      "Bgcgccgjc       ",
      "Beecgegececg8但  ",
      "BdjgjgejgecgjF  ",
      "BcgecccjHeggjF  "
    ],
    [
      "dddjdgegdcdcgccc",
      "cegjjdjddeeeddce",
      "ccececgcggccgddd",
      "Bdeecgdddjcgddde",
      "BBjjegededcccdce",
      "BBceeddecdeecdgd",
      "BBggcedgggeeegdg",
      "BBedgdcggegcjd5d",
      "BBgecgedgjdHdded",
      "BBjccgejgeeegddj",
      "BBeejegccjdecHgd",
      "BBcgccgjgdgecHgg",
      "BBeeececcddgdHjg",
      "BBjcddedjgeece人H",
      "BBeeccggecdgdgcd",
      "BBjcgdcedgjejegg"
    ],
    [
      "aaaaaaaaaaaaaaaa",
      "aaaaaaaaaaaaaaaa",
      "aaaaaaaaaaaaaaaa",
      "Baaaaaaaaaaaaaaa",
      "jBaaaaaaaaaaaaaa",
      "jBaaaaaaaaaaaaaa",
      "jBaaaaaaaaaaaaaa",
      "jBaaaaaaaaaaaa5a",
      "jBaaaaaaaaaaaaaa",
      "jBaaaaaaaaaaaaaa",
      "jBaaaaaaaaaaaaaa",
      "jBaaaaaaaaaaaaaa",
      "jBaaaaaaaaaaaaaa",
      "jBaaaaaaaaaaaaaa",
      "jBaaaaaaaaaaaaaa",
      "jBaaaaaaaaaaaaaa"
    ],
    [
      "aaaaaaaaaaaaaaaa",
      "aaaaaaaaaaaaaaaa",
      "aaaaaaaaaaaaaaaa",
      "aaaaaaaaaaaaaaaa",
      "Baaaaaaaaaaaaaaa",
      "Baaaaaaaaaaaaaaa",
      "BaaaaaaaaaaaaaGa",
      "Baaaaaaaaaaaa刻5G",
      "Baaaaaaaaaaaaaӝό",
      "Baaaaaaaaaaaaaόa",
      "Baaaaaaaaaaaaaaa",
      "Baaaaaaaaaaaaaaa",
      "Baaaaaaaaaaaaaaa",
      "Baaaaaaaaaaaaaaa",
      "Baaaaaaaaaaaaaaa",
      "Baaaaaaaaaaaaaaa"
    ]
  ]
}