{
  "xsize": 16,
  "zsize": 16,
  "palette": {
    "palette": [
      {
        "char": " ",
        "block": "minecraft:air"
      },
      {
        "char": "r",
        "block": "minecraft:light_gray_carpet"
      },
      {
        "char": "i",
        "block": "minecraft:glass"
      },
      {
        "char": "o",
        "block": "minecraft:cyan_terracotta"
      },
      {
        "char": "s",
        "block": "minecraft:polished_diorite"
      },
      {
        "char": "w",
        "block": "minecraft:quartz_pillar[axis=y]"
      },
      {
        "char": "m",
        "block": "minecraft:white_concrete"
      },
      {
        "char": "v",
        "block": "minecraft:smooth_quartz"
      },
      {
        "char": "y",
        "block": "minecraft:gray_concrete"
      },
      {
        "char": "ӏ",
        "block": "minecraft:brown_terracotta"
      },
      {
        "char": "Ӣ",
        "block": "minecraft:spruce_slab[type=top]"
      },
      {
        "char": "问",
        "block": "minecraft:flower_pot"
      },
      {
        "char": "形",
        "block": "minecraft:chest",
        "tag": {
          "z": 335,
          "x": 165,
          "ForgeData": {
            "LockFlag": "1b"
          },
          "ForgeCaps": {},
          "id": "minecraft:chest",
          "y": 142,
          "Items": []
        }
      },
      {
        "char": "t",
        "block": "minecraft:acacia_wood[axis=y]"
      },
      {
        "char": "u",
        "block": "minecraft:light_gray_concrete"
      },
      {
        "char": "Ӕ",
        "block": "minecraft:brown_mushroom_block[down=true,east=true,north=true,south=true,up=true,west=true]"
      },
      {
        "char": "境",
        "block": "minecraft:chest",
        "tag": {
          "z": 333,
          "x": 107,
          "ForgeData": {
            "LockFlag": "1b"
          },
          "ForgeCaps": {},
          "id": "minecraft:chest",
          "y": 145,
          "Items": []
        }
      },
      {
        "char": "2",
        "block": "minecraft:red_concrete"
      },
      {
        "char": "原",
        "block": "minecraft:chest",
        "loot": "bigbuildingsloot",
        "tag": {
          "z": 324,
          "x": 177,
          "ForgeData": {
            "LockFlag": "1b"
          },
          "ForgeCaps": {},
          "id": "minecraft:chest",
          "y": 133,
          "Items": []
        }
      },
      {
        "char": "ϐ",
        "block": "minecraft:green_wool"
      },
      {
        "char": "G",
        "block": "minecraft:quartz_slab[type=bottom]"
      },
      {
        "char": "l",
        "block": "minecraft:andesite"
      },
      {
        "char": "h",
        "block": "minecraft:polished_andesite"
      },
      {
        "char": "P",
        "block": "minecraft:diorite_slab[type=bottom]"
      },
      {
        "char": "ͱ",
        "block": "minecraft:smooth_quartz_slab[type=bottom]"
      },
      {
        "char": "A",
        "block": "minecraft:quartz_block"
      },
      {
        "char": "D",
        "block": "minecraft:smooth_stone_slab[type=bottom]"
      },
      {
        "char": "0",
        "block": "minecraft:diorite"
      },
      {
        "char": "3",
        "block": "minecraft:stone_brick_wall[up=true]"
      },
      {
        "char": "4",
        "block": "minecraft:red_carpet"
      },
      {
        "char": "大",
        "block": "minecraft:rail[shape=north_east]"
      },
      {
        "char": "没",
        "block": "minecraft:rail[shape=south_east]"
      }
    ]
  },
  "slices": [
    [
      "        ri      ",
      "        os      ",
      "       womsmsvmm",
      "        yӏӢӢ 问形m",
      "        ri     s",
      "        ri     m",
      "        ri     t",
      "        uӏ     t",
      "       wuӔ     t",
      "        oӏ     t",
      "        ri     t",
      "        ri     v",
      "        ri     s",
      "        oӏӢӢ 境 m",
      "       wommvsmmm",
      "        o2     m"
    ],
    [
      "        ri      ",
      "        um      ",
      "       wusssmsvs",
      "        oӔ 问 ӢӢm",
      "        ri     m",
      "        ri     s",
      "        ri     t",
      "        uӔ     i",
      "       wuӏ     i",
      "        yӔ     i",
      "        r      t",
      "        r      m",
      "        ri     s",
      "        oӔ原境 ӢӢm",
      "       womsvvvmv",
      "        oϐ     m"
    ],
    [
      "        ri      ",
      "        um      ",
      "       wumvmssmm",
      "        yӏ   形 s",
      "        ri     m",
      "        ri     v",
      "        r      t",
      "        oӏ     i",
      "       wuӔ      ",
      "        oӏ     i",
      "        ri     t",
      "        ri     v",
      "        r      s",
      "        oӏ    问s",
      "       wysmsmmvm",
      "        yϐ     m"
    ],
    [
      "       Guvlhhhlh",
      "       Gumllhlhl",
      "       wumlhhhhh",
      "       Pyvhhhhlh",
      "       Povhllllh",
      "       Gomlhlhhh",
      "       Gyvhlhhlh",
      "       Povlhllhh",
      "       wumhllhll",
      "       ͱumlllhhl",
      "       Pyshhhllh",
      "       Gushhhlhl",
      "       ͱomlhhlhh",
      "       Gumhhhllh",
      "       womllllhl",
      "       Poshhlhll"
    ],
    [
      "       A D     y",
      "       A D      ",
      "       0 D     y",
      "       v D     y",
      "       A D      ",
      "       A D     3",
      "       0 D      ",
      "       0 D     3",
      "       v D      ",
      "       v D      ",
      "       A D      ",
      "       v D  4   ",
      "       v D 4    ",
      "       v D4     ",
      "       A D4     ",
      "       v D4     "
    ],
    [
      "               大",
      "                ",
      "               没",
      "               大",
      "                ",
      "               y",
      "               y",
      "               y",
      "                ",
      "                ",
      "                ",
      "                ",
      "                ",
      "                ",
      "                ",
      "                "
    ]
  ]
}