{
  "xsize": 16,
  "zsize": 16,
  "palette": {
    "palette": [
      {
        "char": " ",
        "block": "minecraft:air"
      },
      {
        "char": "海",
        "block": "minecraft:ladder[facing=north]"
      },
      {
        "char": "ӎ",
        "block": "minecraft:black_stained_glass_pane[east=true,north=false,south=true,west=false]"
      },
      {
        "char": "w",
        "block": "minecraft:quartz_pillar[axis=y]"
      },
      {
        "char": "o",
        "block": "minecraft:cyan_terracotta"
      },
      {
        "char": "r",
        "block": "minecraft:light_gray_carpet"
      },
      {
        "char": "意",
        "block": "minecraft:smooth_quartz_stairs[facing=west,half=top,shape=straight]"
      },
      {
        "char": "O",
        "block": "minecraft:smooth_quartz_slab[type=top]"
      },
      {
        "char": "着",
        "block": "minecraft:smooth_quartz_stairs[facing=east,half=top,shape=straight]"
      },
      {
        "char": "u",
        "block": "minecraft:light_gray_concrete"
      },
      {
        "char": "v",
        "block": "minecraft:smooth_quartz"
      },
      {
        "char": "i",
        "block": "minecraft:glass"
      },
      {
        "char": "m",
        "block": "minecraft:white_concrete"
      },
      {
        "char": "y",
        "block": "minecraft:gray_concrete"
      },
      {
        "char": "Ӭ",
        "block": "minecraft:smooth_quartz_stairs[facing=south,half=top,shape=straight]"
      },
      {
        "char": "s",
        "block": "minecraft:polished_diorite"
      },
      {
        "char": "反",
        "block": "minecraft:black_stained_glass_pane[east=true,north=false,south=true,west=true]"
      },
      {
        "char": "P",
        "block": "minecraft:diorite_slab[type=bottom]"
      },
      {
        "char": "G",
        "block": "minecraft:quartz_slab[type=bottom]"
      },
      {
        "char": "Ӫ",
        "block": "minecraft:polished_diorite_slab[type=bottom]"
      },
      {
        "char": "ͱ",
        "block": "minecraft:smooth_quartz_slab[type=bottom]"
      },
      {
        "char": "l",
        "block": "minecraft:andesite"
      },
      {
        "char": "h",
        "block": "minecraft:polished_andesite"
      },
      {
        "char": "A",
        "block": "minecraft:quartz_block"
      },
      {
        "char": "者",
        "block": "minecraft:oak_slab[type=double]"
      },
      {
        "char": "妳",
        "block": "minecraft:oak_slab[type=bottom]"
      },
      {
        "char": "D",
        "block": "minecraft:smooth_stone_slab[type=bottom]"
      },
      {
        "char": "Е",
        "block": "minecraft:coarse_dirt"
      },
      {
        "char": "ӡ",
        "block": "minecraft:stone_brick_wall[east=low,west=low]"
      },
      {
        "char": "U",
        "block": "minecraft:air"
      },
      {
        "char": "了",
        "block": "minecraft:rail[shape=south_west]"
      },
      {
        "char": "没",
        "block": "minecraft:rail[shape=south_east]"
      },
      {
        "char": "中",
        "block": "minecraft:rail[shape=north_west]"
      },
      {
        "char": "大",
        "block": "minecraft:rail[shape=north_east]"
      }
    ]
  },
  "slices": [
    [
      "                ",
      "                ",
      "                ",
      "                ",
      "                ",
      "                ",
      "    海           ",
      "   ӎw           ",
      "   or           ",
      "意O着urrr         ",
      "   v irrr       ",
      "      i ro      ",
      "        imow    ",
      "         my     ",
      "         ir     ",
      "         ir     "
    ],
    [
      "                ",
      "                ",
      "                ",
      "                ",
      "                ",
      "                ",
      "                ",
      "   ӎw           ",
      "ӬӬӬyr           ",
      "wwwurrr         ",
      "   siirrr       ",
      "      iiro      ",
      "         syw    ",
      "         su     ",
      "         ir     ",
      "          r     "
    ],
    [
      "                ",
      "                ",
      "                ",
      "                ",
      "                ",
      "                ",
      "    海           ",
      "   ӎw           ",
      "反反反yr           ",
      "wwworrr         ",
      "   viirrr       ",
      "      iiro      ",
      "        imuw    ",
      "         mu     ",
      "         ir     ",
      "          r     "
    ],
    [
      "                ",
      "                ",
      "                ",
      "                ",
      "                ",
      "                ",
      "                ",
      "PGGӪw           ",
      "yyoooPG         ",
      "oyyyyoyͱӪ       ",
      "mmvmvsoooG      ",
      "lllhlhvmouͱ     ",
      "lhllhllhsmow    ",
      "hllhhhhllmuG    ",
      "llhhlhhhlmuP    ",
      "hhlhlhlhlvoP    "
    ],
    [
      "                ",
      "                ",
      "                ",
      "                ",
      "                ",
      "                ",
      "    海           ",
      "vvAvv           ",
      "    者vA         ",
      "    妳  vv       ",
      "DDDDDD  ЕA      ",
      "      DD  v     ",
      "yӡyy    DD v    ",
      "y yy     D v    ",
      "         D A    ",
      "yӡyy     D v    "
    ],
    [
      "                ",
      "                ",
      "                ",
      "                ",
      "                ",
      "                ",
      "                ",
      "                ",
      "                ",
      "                ",
      "        U       ",
      "                ",
      "了 没了            ",
      "中 大中            ",
      "                ",
      "了 没了            "
    ]
  ]
}