{
  "xsize": 16,
  "zsize": 16,
  "palette": {
    "palette": [
      {
        "char": " ",
        "block": "minecraft:air"
      },
      {
        "char": "a",
        "block": "minecraft:stone"
      },
      {
        "char": "ό",
        "block": "minecraft:air"
      },
      {
        "char": "j",
        "block": "minecraft:cobblestone"
      },
      {
        "char": "d",
        "block": "minecraft:stone_bricks"
      },
      {
        "char": "e",
        "block": "minecraft:cracked_stone_bricks"
      },
      {
        "char": "g",
        "block": "minecraft:mossy_cobblestone"
      },
      {
        "char": "c",
        "block": "minecraft:mossy_stone_bricks"
      },
      {
        "char": "f",
        "block": "minecraft:grass_block[snowy=false]"
      },
      {
        "char": "5",
        "block": "minecraft:water"
      },
      {
        "char": "ӝ",
        "block": "minecraft:water"
      },
      {
        "char": "8",
        "block": "minecraft:chiseled_stone_bricks"
      },
      {
        "char": "入",
        "block": "minecraft:water"
      },
      {
        "char": "M",
        "block": "minecraft:blue_terracotta"
      },
      {
        "char": "ђ",
        "block": "minecraft:spawner",
        "tag": {
          "SpawnData": {
            "entity": {}
          },
          "MaxNearbyEntities": "6s",
          "MinSpawnDelay": "200s",
          "z": 359,
          "x": 108,
          "MaxSpawnDelay": "800s",
          "RequiredPlayerRange": "16s",
          "SpawnCount": "4s",
          "ForgeCaps": {},
          "id": "minecraft:mob_spawner",
          "SpawnPotentials": [],
          "y": 132,
          "SpawnRange": "4s",
          "Delay": "416s"
        }
      },
      {
        "char": "q",
        "block": "minecraft:air"
      },
      {
        "char": "式",
        "block": "minecraft:poppy"
      },
      {
        "char": "由",
        "block": "minecraft:dandelion"
      },
      {
        "char": "U",
        "block": "minecraft:air"
      },
      {
        "char": "照",
        "block": "minecraft:dark_oak_trapdoor[facing=north,half=top,open=true]"
      },
      {
        "char": "ї",
        "block": "minecraft:water"
      },
      {
        "char": "耶",
        "block": "minecraft:dark_oak_trapdoor[facing=west,half=top,open=true]"
      },
      {
        "char": "萤",
        "block": "minecraft:white_stained_glass_pane[east=true,north=false,south=false,west=false]"
      },
      {
        "char": "科",
        "block": "minecraft:white_stained_glass_pane[east=false,north=true,south=true,west=false]"
      },
      {
        "char": "Ӫ",
        "block": "minecraft:polished_diorite_slab[type=bottom]"
      },
      {
        "char": "G",
        "block": "minecraft:quartz_slab[type=bottom]"
      },
      {
        "char": "阳",
        "block": "minecraft:dark_oak_trapdoor[facing=east,half=top,open=true]"
      },
      {
        "char": "Ӻ",
        "block": "minecraft:cauldron"
      },
      {
        "char": "m",
        "block": "minecraft:white_concrete"
      },
      {
        "char": "息",
        "block": "minecraft:birch_door[facing=north,half=lower,hinge=right,open=false]"
      },
      {
        "char": "首",
        "block": "minecraft:birch_door[facing=north,half=lower,hinge=left,open=false]"
      }
    ]
  },
  "slices": [
    [
      "aaaaaaaaaaaaaaaa",
      "aaaaaaaaaaaaaaaa",
      "aaaaaaaaaaaaaaaa",
      "aaaaaaaaaaaaaaaa",
      "aaaaaaaaaaaaaaaa",
      "aaaaaaaaaaaaaaaa",
      "aaaaaaaaaaaaaaaa",
      "aaaaaaaaaaaaaaaa",
      "aaaaaaaaaaaaaaaa",
      "aaaaaaaaaaaaaaaa",
      "aaaaaaaaaaaaaaaa",
      "aaaaaaaaaaaaaaaa",
      "aaaaaaaaaaaaaaaa",
      "aaaaaaaaaaaaaaaa",
      "aaaaaaaaaaaaaaaa",
      "aaaaaaaaaaaaaaaa"
    ],
    [
      "aaaaaaaaaaaaaaaa",
      "aaaaaaaaaaaaaaaa",
      "aaaaaaaaaaaaaaaa",
      "aaaaaaaaaaaaaaaa",
      "aaaaaaaaaaaaaaaa",
      "aaaaaaaaaaaaaaaa",
      "όaaaaaaaaaaaaaaa",
      "aaaaaaaaaaaaaaaa",
      "aaaaaaaaaaaaaaaa",
      "aaaaaaaaaaaaaaaa",
      "aaaaaaaaaaaaaaaa",
      "aaaaaaaaaaaaaaaa",
      "aaaaaaaaaaaaaaaa",
      "aaaaaaaaaaaaaaaa",
      "aaaaaaaaaaaaaaaa",
      "όaaaaaaaaaaaaaaa"
    ],
    [
      "jdegcejeegcgeccc",
      "jjdddjgdecgecjjg",
      "jjccgeeccecejccd",
      "jdcccdccggccejdc",
      "dgdedjjgcjcjegec",
      "cccccjcjejecjdcg",
      "gggejjcjgccjdege",
      "cdejcgcdejcgceeg",
      "ddjeecegjjccecje",
      "jdccegeceecccegj",
      "cjegeeecdjgjgcjc",
      "ecgdeegcdeejegec",
      "ddcjdgccdcjccegg",
      "dccjecjecgcjddee",
      "eggdcccegcdcgjgg",
      "cccgggggjjcccgcg"
    ],
    [
      "gjgcjegdggeejjcg",
      "ecjceddcecjgggje",
      "gccjcejgjceejegd",
      "gejjcdeecccecccj",
      "dcjgcegeeejegdje",
      "ceeedjgecjcecgjg",
      "dgegcgejeeedgcec",
      "cdgecgcgggeejjec",
      "ecddgcgeccegedec",
      "ddjccgjccecjcccc",
      "cejgddegdccdjcee",
      "cdccgddjjcjdjgdd",
      "ggjgccddeecgecjc",
      "egeccggjceccccec",
      "cddgcgceeccececc",
      "dcdgdceecdceedcg"
    ],
    [
      "cecddcgdgccgccgj",
      "dgeeegcdececejcc",
      "ecjecggegecggeeg",
      "ceceejceecedecdc",
      "ccececcegcejcjee",
      "edcgegecjdjccece",
      "ejgcejecjfffff5f",
      "dggeeedeeffff55c",
      "egejcjccjfffjӝӝ8",
      "dejcgegcgfff8入入c",
      "gcgecjdgdfff8gee",
      "jcgdcegjdfff8eMM",
      "ccgejgggefff8gMe",
      "jegejgcegdgcceђe",
      "cggegeddedceccMc",
      "ecgcgeeggeceeeMc"
    ],
    [
      "gcjcgdjjjejegggj",
      "cgcjcjjeegedgege",
      "cdggcdgcdcggdecg",
      "gcgjcgegcegegege",
      "gcgeccececeejdej",
      "ceccdejddcejeccg",
      "dgdceeccgq式q由q 式",
      "cceceejceqUU照 ї ",
      "ceeccggjcqU耶8  萤",
      "cejejeede q式科  Ӫ",
      "ecccjcjejq式q科 G ",
      "cecccggcgqUq科   ",
      "cecceeecdUqq科   ",
      "geeggjdeegcc8阳Ӫ ",
      "cccjjӺmӺmӺӺӺc   ",
      "gjjce息m首m   g   "
    ]
  ]
}