{
  "xsize": 16,
  "zsize": 16,
  "palette": {
    "palette": [
      {
        "char": " ",
        "block": "minecraft:air"
      },
      {
        "char": "F",
        "block": "minecraft:coarse_dirt"
      },
      {
        "char": "a",
        "block": "minecraft:grass_block[snowy=false]"
      },
      {
        "char": "k",
        "block": "minecraft:cobblestone"
      },
      {
        "char": "J",
        "block": "minecraft:dead_brain_coral_block"
      },
      {
        "char": "L",
        "block": "minecraft:dead_bubble_coral_block"
      },
      {
        "char": "I",
        "block": "minecraft:gravel"
      },
      {
        "char": "K",
        "block": "minecraft:polished_andesite"
      },
      {
        "char": "E",
        "block": "minecraft:andesite"
      },
      {
        "char": "V",
        "block": "minecraft:rooted_dirt"
      },
      {
        "char": "T",
        "block": "minecraft:stone_brick_stairs[facing=south,half=bottom,shape=straight]"
      },
      {
        "char": "ʹ",
        "block": "minecraft:stone_brick_stairs[facing=east,half=bottom,shape=straight]"
      },
      {
        "char": "z",
        "block": "minecraft:cobbled_deepslate"
      },
      {
        "char": "n",
        "block": "minecraft:cyan_terracotta"
      },
      {
        "char": "Ѹ",
        "block": "minecraft:deepslate[axis=x]"
      },
      {
        "char": "w",
        "block": "minecraft:deepslate[axis=y]"
      },
      {
        "char": "m",
        "block": "minecraft:oak_leaves"
      },
      {
        "char": "e",
        "block": "minecraft:air"
      },
      {
        "char": "h",
        "block": "minecraft:air"
      },
      {
        "char": "x",
        "block": "minecraft:air"
      },
      {
        "char": "s",
        "block": "minecraft:air"
      },
      {
        "char": "ϰ",
        "block": "minecraft:spruce_trapdoor[facing=north,half=bottom,open=true]"
      },
      {
        "char": "Ы",
        "block": "minecraft:air"
      },
      {
        "char": "H",
        "block": "minecraft:oak_wood[axis=y]"
      },
      {
        "char": "я",
        "block": "minecraft:air"
      },
      {
        "char": "Ό",
        "block": "minecraft:air"
      },
      {
        "char": "f",
        "block": "minecraft:air"
      },
      {
        "char": "A",
        "block": "minecraft:spruce_trapdoor[facing=south,half=bottom,open=true]"
      },
      {
        "char": "ӏ",
        "block": "minecraft:air"
      },
      {
        "char": "6",
        "block": "minecraft:air"
      },
      {
        "char": "Β",
        "block": "minecraft:spruce_fence"
      },
      {
        "char": "l",
        "block": "minecraft:air"
      },
      {
        "char": "ϥ",
        "block": "minecraft:oak_leaves"
      },
      {
        "char": "ҏ",
        "block": "minecraft:air"
      },
      {
        "char": "位",
        "block": "minecraft:air"
      },
      {
        "char": "Ͷ",
        "block": "minecraft:spruce_fence[east=true]"
      },
      {
        "char": "Φ",
        "block": "minecraft:spruce_fence[south=true,west=true]"
      },
      {
        "char": "Σ",
        "block": "minecraft:spruce_fence[north=true]"
      }
    ]
  },
  "slices": [
    [
      "FaaaaaaaaakJaaaa",
      "FaaaaaaaaakLaaaa",
      "IKJKEILkLkEkJkEJ",
      "KLLKkJLkkLKkEkKE",
      "LKEEELkkJkkKEJkk",
      "KEKKJEKLEkKLLEkE",
      "aaaaaaaaaakkaaaa",
      "FaaaaaaaaaKLaaaa",
      "VaaaaaaaaaJkaaTT",
      "aaaaaaaaaaEkaʹzn",
      "aaaaaaaaaakkʹznn",
      "aaaaaaaaaaLkʹzѸn",
      "aaaaaaaaaaJJʹnnz",
      "aaaaaaaaaaKLʹnnz",
      "aaaaaaaaaakkʹnnn",
      "aaaaaaaaaakKʹnnw"
    ],
    [
      "mmeheexemhs hmhe",
      "mhheexeexe sehee",
      " s  ϰϰϰ  s ss s ",
      "s ЫHaaaHя  s s  ",
      "   HaaaHΌss   s ",
      " fs AAA s  s  ss",
      "m xhehhexes eehe",
      "mmxeehmhees hmxӏ",
      "m heehmhex  mh  ",
      "hfxeeexmhe  e  s",
      "feeeeeehhee   s ",
      "eehx xhhmh s   6",
      "x eeheemmh s s  ",
      "x ee xhmhes  s6 ",
      " ehΒhhheehs  ss ",
      "exxh mhhmh   s  "
    ],
    [
      "m  l     l  l l ",
      " ll          l  ",
      "                ",
      "   ϥhmhs        ",
      "   ҏmhhϥΌ       ",
      "                ",
      "   l ll       l ",
      "m    l      l  ӏ",
      "  l   ml     l  ",
      "l       l       ",
      "       ll       ",
      "  l   l  l      ",
      "    l  m l      ",
      "      l l       ",
      "  lΒlll  l      ",
      "       l l      "
    ],
    [
      "                ",
      "                ",
      "                ",
      "   sl l         ",
      "                ",
      "                ",
      "                ",
      "               位",
      "                ",
      "                ",
      "                ",
      "                ",
      "                ",
      "                ",
      "   m            ",
      "                "
    ],
    [
      "                ",
      "                ",
      "                ",
      "                ",
      "                ",
      "                ",
      "                ",
      "                ",
      "                ",
      "                ",
      "                ",
      "                ",
      "                ",
      "   m            ",
      "   Β            ",
      "   m            "
    ],
    [
      "                ",
      "                ",
      "                ",
      "                ",
      "                ",
      "                ",
      "                ",
      "                ",
      "                ",
      "                ",
      "                ",
      "                ",
      "                ",
      "   m            ",
      "  ͶΦm           ",
      "  mΣ            "
    ]
  ]
}