{
  "xsize": 16,
  "zsize": 16,
  "palette": {
    "palette": [
      {
        "char": " ",
        "block": "minecraft:air"
      },
      {
        "char": "a",
        "block": "minecraft:grass_block[snowy=false]"
      },
      {
        "char": "家",
        "block": "minecraft:stone_brick_stairs[facing=north,half=bottom,shape=inner_left]"
      },
      {
        "char": "S",
        "block": "minecraft:stone_brick_stairs[facing=north,half=bottom,shape=straight]"
      },
      {
        "char": "Υ",
        "block": "minecraft:stone_brick_stairs[facing=west,half=bottom,shape=straight]"
      },
      {
        "char": "w",
        "block": "minecraft:deepslate[axis=y]"
      },
      {
        "char": "z",
        "block": "minecraft:cobbled_deepslate"
      },
      {
        "char": "n",
        "block": "minecraft:cyan_terracotta"
      },
      {
        "char": "e",
        "block": "minecraft:air"
      },
      {
        "char": "h",
        "block": "minecraft:air"
      },
      {
        "char": "x",
        "block": "minecraft:air"
      },
      {
        "char": "D",
        "block": "minecraft:dark_oak_leaves"
      },
      {
        "char": "6",
        "block": "minecraft:air"
      },
      {
        "char": "ϊ",
        "block": "minecraft:spruce_fence[east=true,south=true]"
      },
      {
        "char": "ͳ",
        "block": "minecraft:spruce_fence[west=true]"
      },
      {
        "char": "H",
        "block": "minecraft:oak_wood[axis=y]"
      },
      {
        "char": "Ξ",
        "block": "minecraft:spruce_fence[south=true]"
      },
      {
        "char": "ΐ",
        "block": "minecraft:air"
      },
      {
        "char": "ή",
        "block": "minecraft:spruce_fence[east=true,north=true]"
      },
      {
        "char": "1",
        "block": "minecraft:spruce_stairs[facing=north,half=bottom,shape=straight]"
      },
      {
        "char": "ӷ",
        "block": "minecraft:air"
      },
      {
        "char": "ͼ",
        "block": "minecraft:spruce_wood[axis=y]"
      },
      {
        "char": "Я",
        "block": "minecraft:dark_oak_fence[south=true,west=true]"
      },
      {
        "char": "ѥ",
        "block": "minecraft:dark_oak_slab[type=bottom]"
      },
      {
        "char": "Һ",
        "block": "minecraft:dark_oak_stairs[facing=east,half=bottom,shape=straight]"
      },
      {
        "char": "ϒ",
        "block": "minecraft:dark_oak_fence[west=true]"
      },
      {
        "char": "θ",
        "block": "minecraft:dark_oak_fence[east=true]"
      },
      {
        "char": "Ϣ",
        "block": "minecraft:dark_oak_fence[north=true,west=true]"
      },
      {
        "char": "情",
        "block": "minecraft:air"
      },
      {
        "char": "l",
        "block": "minecraft:air"
      },
      {
        "char": "Σ",
        "block": "minecraft:spruce_fence[north=true]"
      },
      {
        "char": "Ѝ",
        "block": "minecraft:dark_oak_fence[east=true,south=true]"
      },
      {
        "char": "ώ",
        "block": "minecraft:dark_oak_fence[north=true]"
      },
      {
        "char": "s",
        "block": "minecraft:air"
      },
      {
        "char": "Ҡ",
        "block": "minecraft:spruce_stairs[facing=west,half=bottom,shape=straight]"
      },
      {
        "char": "i",
        "block": "minecraft:air"
      },
      {
        "char": "f",
        "block": "minecraft:air"
      },
      {
        "char": "o",
        "block": "minecraft:air"
      }
    ]
  },
  "slices": [
    [
      "aaaaaaaaaaaaaaaa",
      "aaaaaaaaa家SSSSSS",
      "aaaaaaaaaΥwwzwnn",
      "aaaaaaaaaΥzznznn",
      "aaaaaaaaaΥnwnwnn",
      "aaaaaaaaaΥznzwzz",
      "aaaaaaaaaΥzznznw",
      "aaaaaaaaaΥnwznzw",
      "aaaaaaaaaΥwwwnnn",
      "aaaaaaaaaΥnzwzwn",
      "aaaaaaaaaΥnzwnnw",
      "aaaaaaaaaΥnnzznn",
      "aaaaaaaaaΥnwznzn",
      "aaaaaaaaaΥnznnwn",
      "aaaaaaaaaΥwnznnz",
      "aaaaaaaaaΥzzwnwn"
    ],
    [
      "eehxexheehehexxe",
      "hhDhDhDhD       ",
      "hDDDxDhhh  6    ",
      "hD DeehDe 6  6  ",
      "Deϊͳeeeex       ",
      "xhHeΞehhe  ΐ   ΐ",
      "hDήHHxeDh    ΐ  ",
      "hDe1hhDDh 6 e ΐ ",
      "xhDheeDhe       ",
      " DhexӷhDe  6  ΐ ",
      "ehDehhxhe     ΐ ",
      "ee hͼЯѥhx      e",
      "ehDeҺͼϒh e  e   ",
      "ehDhθϢh情D e   ΐ ",
      "eDheehDDh      ΐ",
      "hxeDxeeDe    ΐ  "
    ],
    [
      "  l   l  l l    ",
      "ll l l          ",
      "l D  Dll        ",
      "l     l         ",
      "                ",
      " lΞ   ll        ",
      "l ήHH   l       ",
      "l  Σl   l       ",
      " lDl  Dl        ",
      "  l   l         ",
      " l  ll l        ",
      "   l            ",
      " l  Ѝͼ          ",
      " lDlώ l s       ",
      "  l  l Dl       ",
      "l               "
    ],
    [
      "                ",
      "                ",
      "                ",
      "                ",
      "                ",
      "                ",
      "   HҠ           ",
      "                ",
      "                ",
      "                ",
      "                ",
      "                ",
      "    θͼ          ",
      "                ",
      "                ",
      "                "
    ],
    [
      "                ",
      "                ",
      "                ",
      "                ",
      "                ",
      "                ",
      "   Hͳ           ",
      "                ",
      "                ",
      "                ",
      "                ",
      "                ",
      "     ͼ          ",
      "                ",
      "                ",
      "ii     ii       "
    ],
    [
      "                ",
      "                ",
      "                ",
      "                ",
      "                ",
      "                ",
      "   H            ",
      "                ",
      "                ",
      "                ",
      "                ",
      "                ",
      "     ͼ          ",
      "     ώ          ",
      "                ",
      " foi iof        "
    ]
  ]
}