{
  "xsize": 16,
  "zsize": 16,
  "palette": {
    "palette": [
      {
        "char": " ",
        "block": "minecraft:air"
      },
      {
        "char": "a",
        "block": "minecraft:grass_block[snowy=false]"
      },
      {
        "char": "L",
        "block": "minecraft:dead_bubble_coral_block"
      },
      {
        "char": "K",
        "block": "minecraft:polished_andesite"
      },
      {
        "char": "ʹ",
        "block": "minecraft:stone_brick_stairs[facing=east,half=bottom,shape=straight]"
      },
      {
        "char": "n",
        "block": "minecraft:cyan_terracotta"
      },
      {
        "char": "w",
        "block": "minecraft:deepslate[axis=y]"
      },
      {
        "char": "k",
        "block": "minecraft:cobblestone"
      },
      {
        "char": "J",
        "block": "minecraft:dead_brain_coral_block"
      },
      {
        "char": "E",
        "block": "minecraft:andesite"
      },
      {
        "char": "Ѹ",
        "block": "minecraft:deepslate[axis=x]"
      },
      {
        "char": "z",
        "block": "minecraft:cobbled_deepslate"
      },
      {
        "char": "S",
        "block": "minecraft:stone_brick_stairs[facing=north,half=bottom,shape=straight]"
      },
      {
        "char": "h",
        "block": "minecraft:air"
      },
      {
        "char": "x",
        "block": "minecraft:air"
      },
      {
        "char": "e",
        "block": "minecraft:air"
      },
      {
        "char": "m",
        "block": "minecraft:oak_leaves"
      },
      {
        "char": "s",
        "block": "minecraft:air"
      },
      {
        "char": "6",
        "block": "minecraft:air"
      },
      {
        "char": "ΐ",
        "block": "minecraft:air"
      },
      {
        "char": "ͼ",
        "block": "minecraft:spruce_wood[axis=y]"
      },
      {
        "char": "Я",
        "block": "minecraft:dark_oak_fence[south=true,west=true]"
      },
      {
        "char": "ѥ",
        "block": "minecraft:dark_oak_slab[type=bottom]"
      },
      {
        "char": "Һ",
        "block": "minecraft:dark_oak_stairs[facing=east,half=bottom,shape=straight]"
      },
      {
        "char": "ϒ",
        "block": "minecraft:dark_oak_fence[west=true]"
      },
      {
        "char": "θ",
        "block": "minecraft:dark_oak_fence[east=true]"
      },
      {
        "char": "Ϣ",
        "block": "minecraft:dark_oak_fence[north=true,west=true]"
      },
      {
        "char": "Β",
        "block": "minecraft:spruce_fence"
      },
      {
        "char": "l",
        "block": "minecraft:air"
      },
      {
        "char": "Ѝ",
        "block": "minecraft:dark_oak_fence[east=true,south=true]"
      },
      {
        "char": "ώ",
        "block": "minecraft:dark_oak_fence[north=true]"
      },
      {
        "char": "Ξ",
        "block": "minecraft:spruce_fence[south=true]"
      },
      {
        "char": "ϊ",
        "block": "minecraft:spruce_fence[east=true,south=true]"
      },
      {
        "char": "ψ",
        "block": "minecraft:spruce_fence[north=true,west=true]"
      },
      {
        "char": "Σ",
        "block": "minecraft:spruce_fence[north=true]"
      }
    ]
  },
  "slices": [
    [
      "aaaaaaaaaaLKʹnwn",
      "aaaaaaaaaaLkʹnnn",
      "aaaaaaaaaaJkʹnnw",
      "aaaaaaaaaaJEʹnwn",
      "aaaaaaaaaaKkʹwnn",
      "aaaaaaaaaakkʹѸnn",
      "aaaaaaaaaaLkʹnnѸ",
      "aaaaaaaaaaEJʹznn",
      "aaaaaaaaaaJkʹnwn",
      "aaaaaaaaaakkʹnnn",
      "aaaaaaaaaaJkʹѸnz",
      "aaaaaaaaaakkaʹzn",
      "EKKKKEkKEkKKaaSS",
      "aaaaaaaaaaaaaaaa",
      "aaaaaaaaaaaaaaaa",
      "aaaaaaaaaaaaaaaa"
    ],
    [
      "hxxhehemmhs  6 e",
      "xeeehheemhs  s  ",
      "eeeehmhhehs   6 ",
      "xehhmhemhe   e ΐ",
      "eͼЯѥmmhhees    s",
      "xҺͼϒhmhexe    6s",
      "eθϢhxheehe s 6  ",
      "ehhheexemhs     ",
      "ehmmhheh xs  s ΐ",
      "ehemmheΒ hs  s 6",
      "mehhxmheme s  e ",
      "ehexhhhehe  x  s",
      "ss e ss s s he  ",
      "eeexeehxehhmmmee",
      "hehhhe xhemhhhme",
      "eeexeexeexeee xe"
    ],
    [
      "l      m l      ",
      "                ",
      "                ",
      "  ll l  l       ",
      "     m l        ",
      " Ѝͼ l           ",
      " ώ l l  l       ",
      "  l      l      ",
      "       l        ",
      " l m l m l      ",
      "  ll  l         ",
      " l  lll l       ",
      "            l   ",
      "      l  ll m   ",
      "l lll   l  ll   ",
      "                "
    ],
    [
      "                ",
      "                ",
      "                ",
      "                ",
      "                ",
      " θͼ             ",
      "                ",
      "                ",
      "       m        ",
      "       mm       ",
      "       m        ",
      "                ",
      "                ",
      "                ",
      "                ",
      "                "
    ],
    [
      "                ",
      "                ",
      "                ",
      "                ",
      "                ",
      "  ͼ             ",
      "                ",
      "                ",
      "       mΞ       ",
      "      mϊψ       ",
      "       Σm       ",
      "                ",
      "                ",
      "                ",
      "                ",
      "                "
    ],
    [
      "                ",
      "                ",
      "                ",
      "                ",
      "                ",
      "  ͼ             ",
      "  ώ             ",
      "                ",
      "                ",
      "       m        ",
      "                ",
      "                ",
      "                ",
      "                ",
      "                ",
      "                "
    ]
  ]
}