{
  "xsize": 16,
  "zsize": 16,
  "palette": {
    "palette": [
      {
        "char": " ",
        "block": "minecraft:air"
      },
      {
        "char": "a",
        "block": "minecraft:grass_block[snowy=false]"
      },
      {
        "char": "N",
        "block": "minecraft:diorite"
      },
      {
        "char": "4",
        "block": "minecraft:calcite"
      },
      {
        "char": "Ϡ",
        "block": "minecraft:diorite_stairs[facing=north,half=bottom,shape=straight]"
      },
      {
        "char": "z",
        "block": "minecraft:cobbled_deepslate"
      },
      {
        "char": "n",
        "block": "minecraft:cyan_terracotta"
      },
      {
        "char": "w",
        "block": "minecraft:deepslate[axis=y]"
      },
      {
        "char": "λ",
        "block": "minecraft:diorite_stairs[facing=south,half=bottom,shape=straight]"
      },
      {
        "char": "K",
        "block": "minecraft:polished_andesite"
      },
      {
        "char": "E",
        "block": "minecraft:andesite"
      },
      {
        "char": "k",
        "block": "minecraft:cobblestone"
      },
      {
        "char": "V",
        "block": "minecraft:rooted_dirt"
      },
      {
        "char": "e",
        "block": "minecraft:air"
      },
      {
        "char": "h",
        "block": "minecraft:air"
      },
      {
        "char": "x",
        "block": "minecraft:air"
      },
      {
        "char": "m",
        "block": "minecraft:oak_leaves"
      },
      {
        "char": "П",
        "block": "minecraft:stone_brick_slab[type=bottom]"
      },
      {
        "char": "6",
        "block": "minecraft:air"
      },
      {
        "char": "҃",
        "block": "minecraft:air"
      },
      {
        "char": "什",
        "block": "minecraft:air"
      },
      {
        "char": "人",
        "block": "minecraft:air"
      },
      {
        "char": "ѥ",
        "block": "minecraft:dark_oak_slab[type=bottom]"
      },
      {
        "char": "ϗ",
        "block": "minecraft:dark_oak_fence[south=true]"
      },
      {
        "char": "ͼ",
        "block": "minecraft:spruce_wood[axis=y]"
      },
      {
        "char": "他",
        "block": "minecraft:dark_oak_stairs[facing=west,half=bottom,shape=straight]"
      },
      {
        "char": "Ϭ",
        "block": "minecraft:stone_brick_slab[type=bottom]"
      },
      {
        "char": "ϓ",
        "block": "minecraft:air"
      },
      {
        "char": "s",
        "block": "minecraft:air"
      },
      {
        "char": "可",
        "block": "minecraft:dark_oak_stairs[facing=north,half=bottom,shape=straight]"
      },
      {
        "char": "ʹ",
        "block": "minecraft:stone_brick_stairs[facing=east,half=bottom,shape=straight]"
      },
      {
        "char": "ó",
        "block": "minecraft:air"
      },
      {
        "char": "但",
        "block": "minecraft:air"
      },
      {
        "char": "ώ",
        "block": "minecraft:dark_oak_fence[north=true]"
      },
      {
        "char": "l",
        "block": "minecraft:air"
      },
      {
        "char": "Я",
        "block": "minecraft:dark_oak_fence[south=true,west=true]"
      },
      {
        "char": "ҝ",
        "block": "minecraft:dark_oak_fence[east=true,north=true]"
      },
      {
        "char": "θ",
        "block": "minecraft:dark_oak_fence[east=true]"
      }
    ]
  },
  "slices": [
    [
      "aaaaaaaaaN44ϠϠNz",
      "aaaaaaaaaNnnnnnz",
      "aaaaaaaaaNwnzznn",
      "aaaaaaaaaNnnznwn",
      "aaaaaaaaaNϠϠN4λz",
      "aaaaaaaaaNwnnnwn",
      "aaaaaaaaaNnwnwwn",
      "aaaaaaaaaNzznnzn",
      "aaaaaaaaa4NNλ4Ϡn",
      "aaaaaaaaaNznnnwz",
      "aaaaaaaaaNnnnwnn",
      "aaaaaaaaaNwznwnz",
      "aaaaaaaaaNNNλN4n",
      "aaaaaaaaaaKEaaaa",
      "aaaaaaaaaaEkaaaa",
      "Vaaaaaaaaakkaaaa"
    ],
    [
      "e eheheex       ",
      "emxhmeh hП   66 ",
      "ehxxeee h҃ 6    ",
      "ehmeeeemhП  6   ",
      "exhxxehme       ",
      "xehheheeeП  66  ",
      "eehxmhehe҃ 什  人6",
      "hhheemhehП   6  ",
      "eѥϗhemmhe  e    ",
      "heͼ他eemeeϬ  ϓ s ",
      "ee可ͼhehxeʹ ó  但6",
      "eeeώѥhmeeϬ ϓ6  s",
      "heeehmheh s  e s",
      "hhhhmmexehssexxe",
      "mheexhexhe sehem",
      "ehehmehhhm  hmmh"
    ],
    [
      "     l          ",
      "      l         ",
      "        l       ",
      "        l       ",
      "      l         ",
      "   l l          ",
      "  l  l l        ",
      "lll   l l       ",
      "   l m l        ",
      "l ͼЯ            ",
      "  ҝͼl l         ",
      "   ώ l          ",
      "l   lml l       ",
      "llll     l      ",
      " l   l  l    l  ",
      " l l  l l   l ml"
    ],
    [
      "                ",
      "                ",
      "                ",
      "                ",
      "                ",
      "                ",
      "                ",
      "                ",
      "                ",
      "  ϗ             ",
      "  ҝͼ            ",
      "                ",
      "                ",
      "                ",
      "                ",
      "                "
    ],
    [
      "                ",
      "                ",
      "                ",
      "                ",
      "                ",
      "                ",
      "                ",
      "                ",
      "                ",
      "                ",
      "  θͼ            ",
      "                ",
      "                ",
      "                ",
      "                ",
      "                "
    ],
    [
      "                ",
      "                ",
      "                ",
      "                ",
      "                ",
      "                ",
      "                ",
      "                ",
      "                ",
      "                ",
      "   ͼ            ",
      "                ",
      "                ",
      "                ",
      "                ",
      "                "
    ]
  ]
}