{
  "xsize": 16,
  "zsize": 16,
  "palette": {
    "palette": [
      {
        "char": " ",
        "block": "minecraft:air"
      },
      {
        "char": "a",
        "block": "minecraft:grass_block[snowy=false]"
      },
      {
        "char": "S",
        "block": "minecraft:stone_brick_stairs[facing=north,half=bottom,shape=straight]"
      },
      {
        "char": "n",
        "block": "minecraft:cyan_terracotta"
      },
      {
        "char": "z",
        "block": "minecraft:cobbled_deepslate"
      },
      {
        "char": "w",
        "block": "minecraft:deepslate[axis=y]"
      },
      {
        "char": "T",
        "block": "minecraft:stone_brick_stairs[facing=south,half=bottom,shape=straight]"
      },
      {
        "char": "E",
        "block": "minecraft:andesite"
      },
      {
        "char": "J",
        "block": "minecraft:dead_brain_coral_block"
      },
      {
        "char": "4",
        "block": "minecraft:calcite"
      },
      {
        "char": "Ϡ",
        "block": "minecraft:diorite_stairs[facing=north,half=bottom,shape=straight]"
      },
      {
        "char": "N",
        "block": "minecraft:diorite"
      },
      {
        "char": "λ",
        "block": "minecraft:diorite_stairs[facing=south,half=bottom,shape=straight]"
      },
      {
        "char": "e",
        "block": "minecraft:air"
      },
      {
        "char": "x",
        "block": "minecraft:air"
      },
      {
        "char": "6",
        "block": "minecraft:air"
      },
      {
        "char": "ϓ",
        "block": "minecraft:air"
      },
      {
        "char": "ς",
        "block": "minecraft:air"
      },
      {
        "char": "ҟ",
        "block": "minecraft:air"
      },
      {
        "char": "h",
        "block": "minecraft:air"
      },
      {
        "char": "就",
        "block": "minecraft:air"
      },
      {
        "char": "m",
        "block": "minecraft:oak_leaves"
      },
      {
        "char": "П",
        "block": "minecraft:stone_brick_slab[type=bottom]"
      },
      {
        "char": "ΐ",
        "block": "minecraft:air"
      },
      {
        "char": "҃",
        "block": "minecraft:air"
      },
      {
        "char": "ϊ",
        "block": "minecraft:spruce_fence[east=true,south=true]"
      },
      {
        "char": "H",
        "block": "minecraft:oak_wood[axis=y]"
      },
      {
        "char": "ή",
        "block": "minecraft:spruce_fence[east=true,north=true]"
      },
      {
        "char": "Ҡ",
        "block": "minecraft:spruce_stairs[facing=west,half=bottom,shape=straight]"
      },
      {
        "char": "З",
        "block": "minecraft:spruce_slab[type=bottom]"
      },
      {
        "char": "Σ",
        "block": "minecraft:spruce_fence[north=true]"
      },
      {
        "char": "Ϭ",
        "block": "minecraft:stone_brick_slab[type=bottom]"
      },
      {
        "char": "ʹ",
        "block": "minecraft:stone_brick_stairs[facing=east,half=bottom,shape=straight]"
      },
      {
        "char": "l",
        "block": "minecraft:air"
      },
      {
        "char": "Ͷ",
        "block": "minecraft:spruce_fence[east=true]"
      },
      {
        "char": "ͳ",
        "block": "minecraft:spruce_fence[west=true]"
      },
      {
        "char": "в",
        "block": "minecraft:spruce_stairs[facing=south,half=bottom,shape=straight]"
      },
      {
        "char": "Ξ",
        "block": "minecraft:spruce_fence[south=true]"
      },
      {
        "char": "u",
        "block": "minecraft:oak_leaves"
      }
    ]
  },
  "slices": [
    [
      "aaaaaaaaaaaaaaaa",
      "SSSSSSSSSSSSSSSS",
      "nzzwwwnnwnnnwnwn",
      "znwznwzwnznzwnzw",
      "wwwzwnzwnzznwwnz",
      "znnznnznzzzwznnw",
      "TTTTTTTTTTTTTTTT",
      "aaaaaaaaaaEJaaaa",
      "aaaaaaaaa4ϠϠNNλn",
      "aaaaaaaaa4zznwnz",
      "aaaaaaaaa4nwnwzn",
      "aaaaaaaaaNnzznwn",
      "aaaaaaaaaN4ϠNλλn",
      "aaaaaaaaaNnznznn",
      "aaaaaaaaa4wzzzwn",
      "aaaaaaaaa4nwznnn"
    ],
    [
      "exxxeeexexxeeexe",
      " e              ",
      "      e    e  6 ",
      "  ϓ     ς       ",
      "    6      e ςҟ ",
      " ς     6 6  6 ҟ ",
      "          e   ҟ ",
      "ehhexeexee  e 就e",
      "hmemeheh        ",
      "h mhmxemhП   ΐ  ",
      "mxeehmxmh҃ ΐ  e ",
      "xehϊHhem П      ",
      "hxeήHҠeeh e e  ΐ",
      "xeeЗΣmhehϬ 6    ",
      "exehmhheeʹ 6ΐ ΐ ",
      "eeehmexexϬ   ΐ  "
    ],
    [
      "                ",
      "                ",
      "                ",
      "                ",
      "                ",
      "                ",
      "                ",
      " ll             ",
      "l    l l        ",
      "l ml    l       ",
      "    l  ml       ",
      "  l Hl          ",
      "l  ͶHͳ  l       ",
      "      l l       ",
      "    mll         ",
      "   l            "
    ],
    [
      "                ",
      "                ",
      "                ",
      "                ",
      "                ",
      "                ",
      "                ",
      "                ",
      "                ",
      "                ",
      "                ",
      "    в           ",
      "   ͶHͳ          ",
      "                ",
      "                ",
      "                "
    ],
    [
      "                ",
      "                ",
      "                ",
      "                ",
      "                ",
      "                ",
      "                ",
      "                ",
      "                ",
      "                ",
      "                ",
      "    Ξ           ",
      "   ͶH           ",
      "                ",
      "                ",
      "                "
    ],
    [
      "                ",
      "                ",
      "                ",
      "                ",
      "                ",
      "                ",
      "                ",
      "                ",
      "                ",
      "                ",
      "                ",
      "    Ξ           ",
      "    H           ",
      "    Σ u         ",
      "                ",
      "                "
    ]
  ]
}