{
  "xsize": 16,
  "zsize": 16,
  "palette": {
    "palette": [
      {
        "char": " ",
        "block": "minecraft:air"
      },
      {
        "char": "a",
        "block": "minecraft:air"
      },
      {
        "char": "g",
        "block": "minecraft:air"
      },
      {
        "char": "S",
        "block": "minecraft:air"
      },
      {
        "char": "o",
        "block": "minecraft:air"
      },
      {
        "char": "b",
        "block": "minecraft:air"
      },
      {
        "char": "c",
        "block": "minecraft:short_grass"
      },
      {
        "char": "R",
        "block": "minecraft:air"
      },
      {
        "char": "f",
        "block": "minecraft:tall_grass[half=lower]"
      },
      {
        "char": "h",
        "block": "minecraft:air"
      },
      {
        "char": "k",
        "block": "minecraft:air"
      }
    ]
  },
  "slices": [
    [
      "aaaaaaaaaaaaaaaa",
      "aaaaaaaaaaaaaaaa",
      "aaaaaaaaaaaaaaaa",
      "aaaaaaaaaaaaaaaa",
      "aaaaaaaaaaagggga",
      "aaaaaaaaaaggggga",
      "aaaaaaaaaaggggga",
      "aaaaaaaaaaggSgga",
      "aaaaaaaaaagg oga",
      "aaaaaaaaaagg gga",
      "aaaaaaagaagg gga",
      "aaaaaaaaaagg gga",
      "aaaaaaabaagg gga",
      "aaaaabaaaagg gga",
      "aaaaabaaaaog gga",
      "aaaaaaaabbggggga"
    ],
    [
      "aaaaaaaaaaaaaaaa",
      "aaaaaaaaaaaaaaaa",
      "aaaaaaaaaaaaaaaa",
      "aaaaaaaaaaabobab",
      "aaaaaaaaaag   gb",
      "aaaaaaaaag    cg",
      "aaaaaaaaag  c cg",
      "aaaaaaaaag    cg",
      "aaaaaaaaag     g",
      "aaaaaabaagc  c g",
      "aaaaaag ao    cg",
      "aaaaaaaaag     g",
      "aaaaagg ggcc   g",
      "aaaaacgggg     o",
      "aaaaacggggg    g",
      "aaaaagggccc  cgg"
    ],
    [
      "bbbbbbbbbbbbabbb",
      "bbbbbbbbbbbbbbbb",
      "bbbbbbbbbbbbbbbb",
      "bbbbbbbbbbbcc b ",
      "bbbbbbbbbb      ",
      "bbbbbbbab       ",
      "bbbbbabbb       ",
      "bbbbbbbbb      c",
      "bbbbbbbbbc      ",
      "bbbbbb bb       ",
      "bbbbbb  bR      ",
      "bbbbbabbb       ",
      "bbbbbbbbb       ",
      "bbbbb bbb       ",
      "bbbbb  b        ",
      "bbbbbb c        "
    ],
    [
      "fffc cc  c ch cc",
      " fcfc  ccc   ccc",
      "cccff  c c c   c",
      " ffffcccc       ",
      "ccfccfcfc       ",
      "ccfcf  hc       ",
      "ccccfgccc       ",
      "cccccccc        ",
      "cccff           ",
      "ffccc  c        ",
      "c cccc          ",
      "cffccgc         ",
      "ccc c c c       ",
      "fffcf c         ",
      "cfff            ",
      "ccffcc          "
    ],
    [
      "                ",
      "                ",
      "                ",
      "                ",
      "                ",
      "                ",
      "                ",
      "                ",
      "                ",
      "                ",
      "                ",
      "                ",
      "                ",
      "                ",
      "                ",
      "                "
    ],
    [
      "                ",
      "                ",
      "                ",
      "                ",
      "                ",
      "                ",
      "                ",
      "                ",
      "                ",
      "                ",
      "                ",
      "                ",
      "                ",
      "                ",
      "                ",
      "            k   "
    ]
  ]
}