{
  "xsize": 16,
  "zsize": 16,
  "palette": {
    "palette": [
      {
        "char": " ",
        "block": "minecraft:air"
      },
      {
        "char": "d",
        "block": "minecraft:vine[east=false,north=false,south=true,up=false,west=false]"
      },
      {
        "char": "Ή",
        "block": "minecraft:rail[shape=north_east]"
      },
      {
        "char": "Ύ",
        "block": "minecraft:rail[shape=north_west]"
      },
      {
        "char": "k",
        "block": "minecraft:terracotta"
      },
      {
        "char": "g",
        "block": "minecraft:vine[east=false,north=false,south=false,up=false,west=true]"
      },
      {
        "char": "o",
        "block": "minecraft:air"
      },
      {
        "char": "Ϲ",
        "block": "minecraft:cobblestone_wall[south=tall,up=true,west=tall]"
      },
      {
        "char": "Ё",
        "block": "minecraft:cobblestone_wall[east=tall,south=tall,up=true]"
      },
      {
        "char": "b",
        "block": "minecraft:bricks"
      },
      {
        "char": "l",
        "block": "minecraft:granite"
      },
      {
        "char": "a",
        "block": "minecraft:smooth_quartz"
      },
      {
        "char": "h",
        "block": "minecraft:vine[east=true,north=false,south=false,up=false,west=false]"
      },
      {
        "char": "n",
        "block": "minecraft:stone"
      },
      {
        "char": "c",
        "block": "minecraft:vine[east=false,north=true,south=false,up=false,west=false]"
      },
      {
        "char": "e",
        "block": "minecraft:polished_andesite"
      },
      {
        "char": "υ",
        "block": "minecraft:mossy_cobblestone_wall[south=tall,up=true]"
      },
      {
        "char": "0",
        "block": "minecraft:polished_andesite_slab[type=double]"
      },
      {
        "char": "E",
        "block": "minecraft:vine[east=false,north=false,south=true,up=true,west=false]"
      },
      {
        "char": "F",
        "block": "minecraft:cobblestone_wall[north=tall,south=tall]"
      },
      {
        "char": "ζ",
        "block": "minecraft:mossy_cobblestone_wall[north=tall,south=tall]"
      },
      {
        "char": "H",
        "block": "minecraft:vine[east=true,north=false,south=false,up=true,west=false]"
      },
      {
        "char": "M",
        "block": "minecraft:vine[east=false,north=false,south=false,up=true,west=true]"
      },
      {
        "char": "K",
        "block": "minecraft:vine[east=false,north=true,south=false,up=true,west=false]"
      },
      {
        "char": "R",
        "block": "minecraft:stone_slab[type=bottom]"
      },
      {
        "char": "f",
        "block": "minecraft:gray_concrete"
      },
      {
        "char": "N",
        "block": "minecraft:quartz_pillar[axis=y]"
      },
      {
        "char": "u",
        "block": "minecraft:smooth_stone_slab[type=bottom]"
      },
      {
        "char": "Ί",
        "block": "minecraft:rail[shape=south_east]"
      },
      {
        "char": "Ό",
        "block": "minecraft:rail[shape=south_west]"
      }
    ]
  },
  "slices": [
    [
      " dd ddΉΎ  ddkg  ",
      "oooϹ     Ёobbg  ",
      "llbaaaaaaabbkg  ",
      "lbo       lbbg  ",
      "hng  c     ec   ",
      " c              ",
      "                ",
      "                ",
      "                ",
      "                ",
      "                ",
      "                ",
      "                ",
      "                ",
      "                ",
      "                "
    ],
    [
      " ddυdddd υddlg  ",
      "oklbbololbblog  ",
      "lkkklbbklllkkg  ",
      "kbkblkkkokbklg  ",
      "h0g  c     n    ",
      " c              ",
      "                ",
      "                ",
      "                ",
      "                ",
      "                ",
      "                ",
      "                ",
      "                ",
      "                ",
      "                "
    ],
    [
      " E F     ζEEog  ",
      "kobblobkkbobkg  ",
      "blklbbbllbkblg  ",
      "bllbboboobblbg  ",
      "H0M  K     n    ",
      " c              ",
      "                ",
      "                ",
      "                ",
      "                ",
      "                ",
      "                ",
      "                ",
      "                ",
      "                ",
      "                "
    ],
    [
      "bblbbbklblokb   ",
      "bokbllbkbkkbb   ",
      "bbblbbkbbblblg  ",
      "lbbbbblklblbbg  ",
      "eReeeeneeeeR    ",
      "                ",
      "                ",
      "                ",
      "                ",
      "                ",
      "                ",
      "                ",
      "                ",
      "                ",
      "                ",
      "                "
    ],
    [
      " fffff  NNN u   ",
      "        NNN u   ",
      "            u   ",
      "uuuuuuuuuuuuu   ",
      "                ",
      "                ",
      "                ",
      "                ",
      "                ",
      "                ",
      "                ",
      "                ",
      "                ",
      "                ",
      "                ",
      "                "
    ],
    [
      "        ΊΌ      ",
      "        ΉΎ      ",
      "                ",
      "                ",
      "                ",
      "                ",
      "                ",
      "                ",
      "                ",
      "                ",
      "                ",
      "                ",
      "                ",
      "                ",
      "                ",
      "                "
    ]
  ]
}