{
  "xsize": 16,
  "zsize": 16,
  "palette": {
    "palette": [
      {
        "char": " ",
        "block": "minecraft:structure_void"
      },
      {
        "char": "f",
        "block": "minecraft:air"
      },
      {
        "char": "G",
        "block": "minecraft:dark_oak_leaves"
      },
      {
        "char": "F",
        "block": "minecraft:oak_leaves"
      },
      {
        "char": "ϛ",
        "block": "minecraft:oak_leaves"
      },
      {
        "char": "Ϧ",
        "block": "minecraft:dark_oak_leaves"
      },
      {
        "char": "Σ",
        "block": "minecraft:oak_leaves"
      },
      {
        "char": "Ρ",
        "block": "minecraft:dark_oak_leaves"
      },
      {
        "char": "S",
        "block": "minecraft:oak_wood[axis=y]"
      },
      {
        "char": "п",
        "block": "minecraft:spruce_fence[west=true]"
      },
      {
        "char": "s",
        "block": "minecraft:air"
      },
      {
        "char": "έ",
        "block": "minecraft:oak_leaves"
      },
      {
        "char": "Ο",
        "block": "minecraft:oak_leaves"
      },
      {
        "char": "Ё",
        "block": "minecraft:stone_brick_stairs[facing=south,half=top,shape=straight]"
      },
      {
        "char": "Ϥ",
        "block": "minecraft:stone_brick_stairs[facing=south,half=top,shape=straight]"
      },
      {
        "char": "d",
        "block": "minecraft:stone_bricks"
      },
      {
        "char": "j",
        "block": "minecraft:stone_bricks"
      },
      {
        "char": "r",
        "block": "minecraft:air"
      },
      {
        "char": "p",
        "block": "minecraft:air"
      },
      {
        "char": "A",
        "block": "minecraft:air"
      },
      {
        "char": "ϖ",
        "block": "minecraft:stone_brick_stairs[facing=west,half=top,shape=straight]"
      },
      {
        "char": "Ϊ",
        "block": "minecraft:stone_slab[type=bottom]"
      },
      {
        "char": "x",
        "block": "minecraft:smooth_stone_slab[type=bottom]"
      },
      {
        "char": "Л",
        "block": "minecraft:air"
      },
      {
        "char": "ϭ",
        "block": "minecraft:air"
      },
      {
        "char": "Τ",
        "block": "minecraft:oak_leaves"
      },
      {
        "char": "Π",
        "block": "minecraft:dark_oak_leaves"
      },
      {
        "char": "Ω",
        "block": "minecraft:dark_oak_leaves"
      },
      {
        "char": "o",
        "block": "minecraft:air"
      },
      {
        "char": "B",
        "block": "minecraft:air"
      },
      {
        "char": "ҋ",
        "block": "minecraft:rail[shape=south_east]"
      },
      {
        "char": "҉",
        "block": "minecraft:rail[shape=south_west]"
      },
      {
        "char": "Ғ",
        "block": "minecraft:rail[shape=north_east]"
      },
      {
        "char": "҈",
        "block": "minecraft:rail[shape=north_west]"
      },
      {
        "char": "Ψ",
        "block": "minecraft:dark_oak_leaves"
      }
    ]
  },
  "slices": [
    [
      "                ",
      " f GfF          ",
      "G GF FFF        ",
      " f f FGϛF       ",
      " FGF Gϛ Ϧ       ",
      " f F  G ΣϦF     ",
      " GFG G ΣΡ       ",
      " FF  fF   F     ",
      "  Gf GG SпG F   ",
      " sG     έΟ      ",
      "ЁϤϤdϤϤϤϤЁϤϤjr   ",
      "  ppp f ffAϖ    ",
      "f  fff  AAAϖ    ",
      "ΪxxxxΪxЛϭffϖ    ",
      "f ffffAϭϭAfϖ    ",
      " f f  fxAffϖ    "
    ],
    [
      "                ",
      "  F F           ",
      "  G  f          ",
      "   G FF         ",
      " FGG            ",
      "F F G G  F      ",
      " f  G  Τ FG     ",
      " FFG G Π  F     ",
      "  FF   Ωέ       ",
      "   f    Ω F     ",
      "ooo F     Fo    ",
      "    p FG  B     ",
      "        BB      ",
      "       ҋ҉  o    ",
      "      BҒ҈B      ",
      "           o    "
    ],
    [
      "                ",
      "                ",
      "                ",
      "   GF  f        ",
      " GfFG F         ",
      "  F FF          ",
      "    fG Σ        ",
      "   F ϛΣΡ  f     ",
      "   fG     F     ",
      "   F  GF        ",
      "          f     ",
      "       GfF      ",
      "                ",
      "                ",
      "                ",
      "                "
    ],
    [
      "                ",
      "                ",
      "                ",
      "     f          ",
      "    fG          ",
      "  GF            ",
      "     G          ",
      "       ΨϦ       ",
      "   G G ϛ FG     ",
      "    G  G G      ",
      "                ",
      "                ",
      "                ",
      "                ",
      "                ",
      "                "
    ],
    [
      "                ",
      "                ",
      "                ",
      "                ",
      "     f          ",
      "                ",
      "    FG          ",
      "     f          ",
      "     G          ",
      "                ",
      "                ",
      "                ",
      "                ",
      "                ",
      "                ",
      "                "
    ],
    [
      "                ",
      "                ",
      "                ",
      "                ",
      "                ",
      "                ",
      "                ",
      "                ",
      "                ",
      "                ",
      "                ",
      "                ",
      "                ",
      "                ",
      "                ",
      "                "
    ]
  ]
}