{
  "xsize": 16,
  "zsize": 16,
  "palette": {
    "palette": [
      {
        "char": " ",
        "block": "minecraft:structure_void"
      },
      {
        "char": "q",
        "block": "minecraft:deepslate_bricks"
      },
      {
        "char": "k",
        "block": "minecraft:cracked_deepslate_bricks"
      },
      {
        "char": "d",
        "block": "minecraft:stone_bricks"
      },
      {
        "char": "i",
        "block": "minecraft:basalt[axis=y]"
      },
      {
        "char": "l",
        "block": "minecraft:mossy_stone_bricks"
      },
      {
        "char": "E",
        "block": "minecraft:deepslate_bricks"
      },
      {
        "char": "j",
        "block": "minecraft:stone_bricks"
      },
      {
        "char": "Ϝ",
        "block": "minecraft:air"
      },
      {
        "char": "h",
        "block": "minecraft:oak_leaves[distance=7,persistent=true,waterlogged=false]"
      },
      {
        "char": "p",
        "block": "minecraft:air"
      },
      {
        "char": "f",
        "block": "minecraft:air"
      },
      {
        "char": "F",
        "block": "minecraft:oak_leaves[distance=7,persistent=false,waterlogged=false]"
      },
      {
        "char": "G",
        "block": "minecraft:dark_oak_leaves[distance=7,persistent=false,waterlogged=false]"
      },
      {
        "char": "m",
        "block": "minecraft:cracked_stone_bricks"
      },
      {
        "char": "O",
        "block": "minecraft:stone_slab[type=top,waterlogged=false]"
      },
      {
        "char": "Φ",
        "block": "minecraft:stone_slab[type=top,waterlogged=false]"
      },
      {
        "char": "c",
        "block": "minecraft:smooth_stone_slab[type=top,waterlogged=false]"
      },
      {
        "char": "x",
        "block": "minecraft:smooth_stone_slab[type=bottom,waterlogged=false]"
      },
      {
        "char": "D",
        "block": "minecraft:stone"
      },
      {
        "char": "L",
        "block": "minecraft:dead_fire_coral_block"
      },
      {
        "char": "e",
        "block": "minecraft:grass_block[snowy=false]"
      },
      {
        "char": "K",
        "block": "minecraft:dead_bubble_coral_block"
      },
      {
        "char": "J",
        "block": "minecraft:dead_brain_coral_block"
      },
      {
        "char": "C",
        "block": "minecraft:cobblestone"
      },
      {
        "char": "Э",
        "block": "minecraft:stone_brick_stairs[facing=north,half=bottom,shape=straight,waterlogged=false]"
      },
      {
        "char": "ϴ",
        "block": "minecraft:stone_brick_stairs[facing=north,half=bottom,shape=straight,waterlogged=false]"
      },
      {
        "char": "o",
        "block": "minecraft:air"
      }
    ]
  },
  "slices": [
    [
      "                ",
      "                ",
      "qkdkqilEdiiqqdEj",
      "Ϝhp  ϜhhϜp ϜhhpϜ",
      "                ",
      "  f             ",
      " f              ",
      "F F             ",
      "  G             ",
      " G              ",
      "                ",
      "                ",
      "                ",
      "                ",
      "                ",
      "                "
    ],
    [
      "                ",
      "                ",
      "ddjdEqijjdkddmld",
      "p   p p    p   p",
      "                ",
      "                ",
      "FF              ",
      "f               ",
      "                ",
      "                ",
      "                ",
      "                ",
      "                ",
      "                ",
      "                ",
      "                "
    ],
    [
      "                ",
      "                ",
      "mdlldkdlljdilmdl",
      " p  p p   pp   p",
      "                ",
      "                ",
      "                ",
      "                ",
      "                ",
      "                ",
      "                ",
      "                ",
      "                ",
      "                ",
      "                ",
      "                "
    ],
    [
      "                ",
      "                ",
      "OOmmOΦΦldjOOΦdjΦ",
      "  p      p      ",
      "                ",
      "                ",
      "                ",
      "                ",
      "                ",
      "                ",
      "                ",
      "                ",
      "                ",
      "                ",
      "                ",
      "                "
    ],
    [
      "cccccccccccccccc",
      "cccccccccccccccc",
      "lddmmdjdjdmmdldl",
      "xxxcccccccccxcxx",
      "                ",
      "                ",
      "                ",
      "                ",
      "                ",
      "                ",
      "                ",
      "                ",
      "                ",
      "                ",
      "                ",
      "                "
    ],
    [
      "DLeeeDeDKeeeJDLL",
      "eeeeJeKCeeeeeeJK",
      "ЭЭЭϴϴϴЭϴjЭϴϴЭЭЭϴ",
      "        Ϝoo     ",
      "                ",
      "                ",
      "                ",
      "                ",
      "                ",
      "                ",
      "                ",
      "                ",
      "                ",
      "                ",
      "                ",
      "                "
    ]
  ]
}