{
  "xsize": 16,
  "zsize": 16,
  "palette": {
    "palette": [
      {
        "char": " ",
        "block": "minecraft:air"
      },
      {
        "char": "g",
        "block": "minecraft:air"
      },
      {
        "char": "h",
        "block": "minecraft:air"
      },
      {
        "char": "k",
        "block": "minecraft:air"
      },
      {
        "char": "G",
        "block": "minecraft:air"
      },
      {
        "char": "d",
        "block": "minecraft:air"
      },
      {
        "char": "l",
        "block": "minecraft:air"
      },
      {
        "char": "j",
        "block": "minecraft:air"
      },
      {
        "char": "a",
        "block": "minecraft:air"
      },
      {
        "char": "m",
        "block": "minecraft:air"
      },
      {
        "char": "Λ",
        "block": "minecraft:chest",
        "tag": {
          "SpawnData": {
            "entity": {}
          },
          "MaxNearbyEntities": "6s",
          "MinSpawnDelay": "200s",
          "z": 564,
          "x": 93,
          "MaxSpawnDelay": "800s",
          "RequiredPlayerRange": "16s",
          "SpawnCount": "4s",
          "ForgeCaps": {},
          "id": "minecraft:mob_spawner",
          "SpawnPotentials": [],
          "y": 132,
          "SpawnRange": "4s",
          "Delay": "300s"
        }
      },
      {
        "char": "e",
        "block": "minecraft:air"
      },
      {
        "char": "Ω",
        "block": "minecraft:air"
      },
      {
        "char": ";",
        "block": "minecraft:air"
      },
      {
        "char": "f",
        "block": "minecraft:air"
      },
      {
        "char": "c",
        "block": "minecraft:tall_grass"
      },
      {
        "char": "i",
        "block": "minecraft:air"
      },
      {
        "char": "Ξ",
        "block": "minecraft:air"
      },
      {
        "char": "r",
        "block": "minecraft:air"
      },
      {
        "char": "Φ",
        "block": "minecraft:air"
      },
      {
        "char": "β",
        "block": "minecraft:air"
      },
      {
        "char": "Ώ",
        "block": "minecraft:air"
      },
      {
        "char": "v",
        "block": "minecraft:air"
      },
      {
        "char": "u",
        "block": "minecraft:air"
      },
      {
        "char": "y",
        "block": "minecraft:air"
      },
      {
        "char": "C",
        "block": "minecraft:air"
      },
      {
        "char": "x",
        "block": "minecraft:air"
      },
      {
        "char": "A",
        "block": "minecraft:air"
      },
      {
        "char": "ώ",
        "block": "minecraft:air"
      },
      {
        "char": "L",
        "block": "minecraft:air"
      },
      {
        "char": "ύ",
        "block": "minecraft:air"
      },
      {
        "char": "·",
        "block": "minecraft:air"
      },
      {
        "char": "Ϭ",
        "block": "minecraft:air"
      },
      {
        "char": "Σ",
        "block": "minecraft:air"
      },
      {
        "char": "І",
        "block": "minecraft:air"
      },
      {
        "char": "b",
        "block": "minecraft:air"
      },
      {
        "char": "ρ",
        "block": "minecraft:air"
      },
      {
        "char": "ϩ",
        "block": "minecraft:air"
      },
      {
        "char": "ϑ",
        "block": "minecraft:air"
      }
    ]
  },
  "slices": [
    [
      "ghkGddlkkjglkakl",
      "kjlgjgjkhlggkhhk",
      "kjkkddklhjjkhkhl",
      "jkhkhhjkjgaalgkh",
      "Gjahddklaljljjkg",
      "GGGGGljaggkljggk",
      "mmaaaaaaahhahjhk",
      "mmaaaahglljkhggk",
      "mmaaaaghgklghhka",
      "gjklaajgkhjjljgl",
      "hglaΛggllkhjgghl",
      "gΛjjkΛjlagaghgkh",
      "hajkddgglkjghjgl",
      "lalakjhlghkggjhj",
      "jghaddhkhlglkjgj",
      "llagllglajkgljgj"
    ],
    [
      "e eeΩ           ",
      "    ;f          ",
      "                ",
      "        c cc   c",
      "  c ;f cc       ",
      "ciiiΞf c        ",
      "rrcccf     c    ",
      "Φrcccf          ",
      "rr ccf     c   c",
      "     c         c",
      "   βΏv          ",
      "cΏ  vu  ccc     ",
      "i  vu           ",
      " c c       c    ",
      "   c            ",
      "  c c   cc      "
    ],
    [
      "e eee           ",
      "yCCxAf          ",
      "AAxACώ          ",
      "yCAAAώ          ",
      "xCyyAf          ",
      " iii f          ",
      "e    f          ",
      "L    f          ",
      "i  i f          ",
      "                ",
      "                ",
      "     v          ",
      "i   v           ",
      "                ",
      "                ",
      "                "
    ],
    [
      "e ee            ",
      "AxCACf          ",
      "    ύf          ",
      "·Ϭ·ΣІf          ",
      "yxyyxf          ",
      " iii f          ",
      "e    f          ",
      "b    f          ",
      "i  i f          ",
      "                ",
      "                ",
      "                ",
      "i               ",
      "                ",
      "                ",
      "                "
    ],
    [
      "e ee            ",
      "CAAAC           ",
      "    ρf          ",
      "· · ϩf          ",
      "xxyAA           ",
      " iii f          ",
      "     f          ",
      "b    f          ",
      "i  i f          ",
      "                ",
      "                ",
      "                ",
      "i               ",
      "                ",
      "                ",
      "                "
    ],
    [
      "e  e            ",
      "Cyxyyϑ          ",
      "xCAAyf          ",
      "ACxAyf          ",
      "AxAxCϑ          ",
      " iii f          ",
      "     f          ",
      "b    f          ",
      "i  i f          ",
      "                ",
      "                ",
      "                ",
      "i               ",
      "                ",
      "                ",
      "                "
    ]
  ]
}