{
  "xsize": 16,
  "zsize": 16,
  "palette": {
    "palette": [
      {
        "char": " ",
        "block": "minecraft:air"
      },
      {
        "char": "j",
        "block": "minecraft:vine[east=true,north=false,south=false,up=false,west=false]"
      },
      {
        "char": "u",
        "block": "minecraft:red_concrete"
      },
      {
        "char": "y",
        "block": "minecraft:quartz_slab[type=top]"
      },
      {
        "char": "z",
        "block": "minecraft:clay"
      },
      {
        "char": "袱",
        "block": "minecraft:quartz_stairs[facing=east,half=top,shape=straight]"
      },
      {
        "char": "e",
        "block": "minecraft:quartz_block"
      },
      {
        "char": "b",
        "block": "minecraft:polished_diorite"
      },
      {
        "char": "v",
        "block": "minecraft:red_terracotta"
      },
      {
        "char": "d",
        "block": "minecraft:diorite"
      },
      {
        "char": "儸",
        "block": "minecraft:diorite_stairs[facing=east,half=top,shape=straight]"
      },
      {
        "char": "c",
        "block": "minecraft:smooth_quartz"
      },
      {
        "char": "p",
        "block": "minecraft:quartz_pillar[axis=y]"
      },
      {
        "char": "m",
        "block": "minecraft:vine[east=false,north=true,south=false,up=false,west=false]"
      },
      {
        "char": "f",
        "block": "minecraft:basalt[axis=x]"
      },
      {
        "char": "w",
        "block": "minecraft:quartz_slab[type=bottom]"
      },
      {
        "char": "I",
        "block": "minecraft:black_concrete"
      },
      {
        "char": "q",
        "block": "minecraft:blackstone"
      },
      {
        "char": "K",
        "block": "minecraft:diorite_slab[type=bottom]"
      },
      {
        "char": "i",
        "block": "minecraft:cobbled_deepslate"
      },
      {
        "char": "袅",
        "block": "minecraft:quartz_stairs[facing=east,half=bottom,shape=straight]"
      },
      {
        "char": "h",
        "block": "minecraft:deepslate[axis=y]"
      },
      {
        "char": "g",
        "block": "minecraft:cyan_terracotta"
      },
      {
        "char": "C",
        "block": "minecraft:air"
      },
      {
        "char": "N",
        "block": "minecraft:diorite_slab[type=top]"
      },
      {
        "char": "J",
        "block": "minecraft:polished_blackstone"
      },
      {
        "char": "拭",
        "block": "minecraft:cobblestone_wall[east=low,west=low]"
      },
      {
        "char": "逄",
        "block": "minecraft:cobblestone_wall[up=true,west=low]"
      },
      {
        "char": "飒",
        "block": "minecraft:cobblestone_wall[east=low,south=low,up=true,west=low]"
      },
      {
        "char": "H",
        "block": "minecraft:glass_pane[east=false,north=true,south=true,west=false]"
      },
      {
        "char": "繁",
        "block": "minecraft:cobblestone_wall[east=tall,up=true]"
      },
      {
        "char": "涨",
        "block": "minecraft:glass_pane[east=false,north=false,south=true,west=false]"
      },
      {
        "char": "瀑",
        "block": "minecraft:mossy_cobblestone_wall[east=tall,up=true]"
      },
      {
        "char": "捕",
        "block": "minecraft:glass_pane[east=false,north=true,south=false,west=false]"
      },
      {
        "char": "沿",
        "block": "minecraft:cobblestone_wall[east=tall,south=tall,up=true]"
      }
    ]
  },
  "slices": [
    [
      "          ju  yz",
      "             袱eb",
      "              yz",
      "           v  yz",
      "           v 袱bd",
      "           v  yz",
      "              yz",
      "           u 儸bc",
      "             pdb",
      "           j cce",
      "           j pee",
      "           j 儸ec",
      "           j  yz",
      "            m yf",
      "             袱cc",
      "              yz"
    ],
    [
      "           u  wI",
      "             wdc",
      "              wq",
      "           u  wq",
      "             wdc",
      "           u  wI",
      "              wI",
      "           u Kbc",
      "             pee",
      "           j ccc",
      "           j eii",
      "           j袅dqh",
      "           j chg",
      "            mcCh",
      "            袅bCq",
      "             bCh"
    ],
    [
      "           v  NJ",
      "           v拭拭ec",
      "              NI",
      "           v拭逄y ",
      "           u jcd",
      "           u拭逄yq",
      "              yJ",
      "           u拭飒eb",
      "             pdd",
      "           j dde",
      "           j pce",
      "           j dpb",
      "           j e  ",
      "            mbm ",
      "             c  ",
      "             c  "
    ],
    [
      "               H",
      "              繁b",
      "                ",
      "               涨",
      "             j瀑c",
      "               捕",
      "                ",
      "              沿b",
      "             pcb",
      "           j bed",
      "           j pec",
      "           j  pc",
      "           j    ",
      "            mmm ",
      "                ",
      "                "
    ],
    [
      "               涨",
      "              繁c",
      "               H",
      "               H",
      "             j繁b",
      "                ",
      "                ",
      "              沿c",
      "             pcd",
      "           j bec",
      "           j bdd",
      "           j  pb",
      "           j    ",
      "            mmm ",
      "                ",
      "                "
    ],
    [
      "              Kz",
      "              eb",
      "              wz",
      "              wh",
      "             jdb",
      "              wz",
      "              wz",
      "              bd",
      "             bec",
      "           j ebb",
      "           j pcd",
      "           j  pe",
      "           j    ",
      "            mmm ",
      "                ",
      "                "
    ]
  ]
}