{
  "xsize": 16,
  "zsize": 16,
  "palette": {
    "palette": [
      {
        "char": " ",
        "block": "minecraft:air"
      },
      {
        "char": "e",
        "block": "minecraft:quartz_block"
      },
      {
        "char": "c",
        "block": "minecraft:smooth_quartz"
      },
      {
        "char": "b",
        "block": "minecraft:polished_diorite"
      },
      {
        "char": "d",
        "block": "minecraft:diorite"
      },
      {
        "char": "稽",
        "block": "minecraft:rail[shape=south_east]"
      },
      {
        "char": "峨",
        "block": "minecraft:rail[shape=north_west]"
      },
      {
        "char": "L",
        "block": "minecraft:air"
      },
      {
        "char": "耻",
        "block": "minecraft:air"
      },
      {
        "char": "噹",
        "block": "minecraft:air"
      },
      {
        "char": "喃",
        "block": "minecraft:cobblestone_slab[type=bottom]"
      },
      {
        "char": "Q",
        "block": "minecraft:smooth_stone_slab[type=bottom]"
      },
      {
        "char": "K",
        "block": "minecraft:diorite_slab[type=bottom]"
      },
      {
        "char": "w",
        "block": "minecraft:quartz_slab[type=bottom]"
      },
      {
        "char": "锁",
        "block": "minecraft:stone_slab[type=bottom]"
      },
      {
        "char": "M",
        "block": "minecraft:air"
      },
      {
        "char": "a",
        "block": "minecraft:smooth_stone_slab[type=top]"
      },
      {
        "char": "k",
        "block": "minecraft:stone_slab[type=top]"
      },
      {
        "char": "r",
        "block": "minecraft:cobblestone_slab[type=top]"
      },
      {
        "char": "雎",
        "block": "minecraft:diorite_stairs[facing=south,half=bottom,shape=outer_left]"
      },
      {
        "char": "唆",
        "block": "minecraft:quartz_stairs[facing=south,half=bottom,shape=straight]"
      },
      {
        "char": "箍",
        "block": "minecraft:diorite_stairs[facing=south,half=bottom,shape=straight]"
      },
      {
        "char": "蜒",
        "block": "minecraft:quartz_stairs[facing=west,half=bottom,shape=outer_left]"
      },
      {
        "char": "踵",
        "block": "minecraft:quartz_stairs[facing=east,half=bottom,shape=outer_right]"
      },
      {
        "char": "袅",
        "block": "minecraft:quartz_stairs[facing=east,half=bottom,shape=straight]"
      },
      {
        "char": "嗅",
        "block": "minecraft:quartz_stairs[facing=west,half=bottom,shape=straight]"
      },
      {
        "char": "狩",
        "block": "minecraft:quartz_stairs[facing=east,half=bottom,shape=outer_left]"
      },
      {
        "char": "蒙",
        "block": "minecraft:quartz_stairs[facing=north,half=bottom,shape=straight]"
      },
      {
        "char": "佚",
        "block": "minecraft:diorite_stairs[facing=west,half=bottom,shape=outer_right]"
      },
      {
        "char": "珈",
        "block": "minecraft:rail[shape=south_west]"
      },
      {
        "char": "鹃",
        "block": "minecraft:rail[shape=north_east]"
      }
    ]
  },
  "slices": [
    [
      "  ecceceb    dde",
      "  c 稽   e    d 稽",
      "  c     d    b  ",
      "  d   峨 b    e  ",
      "  bccdbcd    bec",
      "    L  耻      耻 ",
      "    耻  噹      耻 ",
      "                ",
      "   dddecd    dde",
      "   b喃QQQK    wQ锁",
      "   bQQQQw    w喃锁",
      "   bQQQ锁K    wQQ",
      "   eQQQ锁K    K锁锁",
      "   cbecbc    ccd",
      "                ",
      "    噹  M      耻 "
    ],
    [
      "  QQQQQQQ    锁Q锁",
      "  QQQ喃QQ锁    QQ锁",
      "  QQQQQ锁Q    QQQ",
      "  锁锁QQQQQ    锁锁Q",
      "  QQQ锁QQ锁    Q锁Q",
      "                ",
      "    噹  噹      L ",
      "                ",
      "   bQebQc    eQe",
      "   e    K    w  ",
      "   d    K    w  ",
      "   e    K    w  ",
      "   c    w    K  ",
      "   b喃cdQd    eQb",
      "                ",
      "    L  M      L "
    ],
    [
      "                ",
      "                ",
      "                ",
      "                ",
      "                ",
      "                ",
      "    L  耻      噹 ",
      "    耻  L      L ",
      "   bbcbdd    dbd",
      "   b    w    w  ",
      "   e    w    w  ",
      "   e    K    K  ",
      "   d    K    w  ",
      "   cddbbe    bdb",
      "    耻  噹      噹 ",
      "    耻  M      L "
    ],
    [
      "                ",
      "                ",
      "                ",
      "                ",
      "                ",
      "                ",
      "                ",
      "                ",
      "   dacbkd    bac",
      "   b    w    K  ",
      "   e    w    K  ",
      "   d    w    K  ",
      "   d    w    w  ",
      "   drecke    cab",
      "                ",
      "                "
    ],
    [
      "                ",
      "                ",
      "                ",
      "                ",
      "                ",
      "                ",
      "                ",
      "                ",
      "   QQQQQQ    QQQ",
      "   Q雎唆箍蜒Q    锁踵箍",
      "   喃袅bd嗅锁    Q袅e",
      "   锁袅be嗅Q    Q袅d",
      "   Q狩蒙蒙佚Q    锁狩蒙",
      "   锁QQQQQ    喃锁Q",
      "                ",
      "                "
    ],
    [
      "                ",
      "                ",
      "                ",
      "                ",
      "                ",
      "                ",
      "                ",
      "                ",
      "                ",
      "                ",
      "     稽珈        稽",
      "     鹃峨        鹃",
      "                ",
      "                ",
      "                ",
      "                "
    ]
  ]
}