{
  "xsize": 16,
  "zsize": 16,
  "palette": {
    "palette": [
      {
        "char": " ",
        "block": "minecraft:air"
      },
      {
        "char": "l",
        "block": "minecraft:vine[east=false,north=false,south=false,up=false,west=true]"
      },
      {
        "char": "焢",
        "block": "minecraft:vine[east=false,north=true,south=true,up=true,west=false]"
      },
      {
        "char": "硫",
        "block": "minecraft:redstone_wire[west=none]"
      },
      {
        "char": "E",
        "block": "minecraft:redstone_wire[north=none,south=none]"
      },
      {
        "char": "x",
        "block": "minecraft:redstone_lamp[lit=false]"
      },
      {
        "char": "C",
        "block": "minecraft:air"
      },
      {
        "char": "歉",
        "block": "minecraft:vine[east=false,north=false,south=true,up=false,west=true]"
      },
      {
        "char": "n",
        "block": "minecraft:vine[east=false,north=false,south=true,up=false,west=false]"
      },
      {
        "char": "D",
        "block": "minecraft:redstone_wire[east=none,west=none]"
      },
      {
        "char": "h",
        "block": "minecraft:deepslate[axis=y]"
      },
      {
        "char": "g",
        "block": "minecraft:cyan_terracotta"
      },
      {
        "char": "摸",
        "block": "minecraft:repeater[delay=1,facing=south,locked=false,powered=false]"
      },
      {
        "char": "淆",
        "block": "minecraft:redstone_wire[north=none,west=none]"
      },
      {
        "char": "鳞",
        "block": "minecraft:redstone_wire[south=none]"
      },
      {
        "char": "怨",
        "block": "minecraft:repeater[delay=1,facing=west,locked=false,powered=false]"
      },
      {
        "char": "捏",
        "block": "minecraft:redstone_wire[east=none,south=none]"
      },
      {
        "char": "醉",
        "block": "minecraft:repeater[delay=1,facing=north,locked=false,powered=false]"
      },
      {
        "char": "e",
        "block": "minecraft:quartz_block"
      },
      {
        "char": "d",
        "block": "minecraft:diorite"
      },
      {
        "char": "b",
        "block": "minecraft:polished_diorite"
      },
      {
        "char": "c",
        "block": "minecraft:smooth_quartz"
      },
      {
        "char": "z",
        "block": "minecraft:clay"
      },
      {
        "char": "杠",
        "block": "minecraft:stone_brick_stairs[facing=east,half=top,shape=straight]"
      },
      {
        "char": "y",
        "block": "minecraft:quartz_slab[type=top]"
      },
      {
        "char": "i",
        "block": "minecraft:cobbled_deepslate"
      },
      {
        "char": "q",
        "block": "minecraft:blackstone"
      },
      {
        "char": "f",
        "block": "minecraft:basalt[axis=x]"
      },
      {
        "char": "Q",
        "block": "minecraft:smooth_stone_slab[type=bottom]"
      },
      {
        "char": "剷",
        "block": "minecraft:stone_button[face=floor,facing=east,powered=false]"
      },
      {
        "char": "锁",
        "block": "minecraft:stone_slab[type=bottom]"
      },
      {
        "char": "刍",
        "block": "minecraft:stone_button[face=floor,facing=north,powered=false]"
      },
      {
        "char": "w",
        "block": "minecraft:quartz_slab[type=bottom]"
      }
    ]
  },
  "slices": [
    [
      "l     焢    硫Ex  ",
      "CC歉nn C    D    ",
      "  ChCg     D    ",
      "        x  D    ",
      "        摸  D    ",
      " x      D x   x ",
      "       淆鳞怨xEE怨xE",
      "       D        ",
      "       xx       ",
      "       摸        ",
      "EE怨xEEE捏        ",
      "   x            ",
      " 醉              ",
      " x              ",
      "   edbbdbddeczgb",
      "   杠deeeeebcbyyd"
    ],
    [
      "l     CCihqfqChq",
      "q歉n    hhhhqgfCi",
      " qff  hhiqiqgCfi",
      "hghifgifiiqiiCqq",
      "gChfggfffqqhhfqq",
      "fggigCighqfggqfh",
      "qqhhCihqqhghiqqh",
      "gqCiqfgihfgighhg",
      "ffiCifhfqhhgfqgi",
      "hqihCfghfgqfqggC",
      "hfggfgCqigggihCq",
      "gfqhgqhhiiCChhfh",
      "fgggffiqiCqfqqhq",
      "iqhChggqffgqfiqq",
      "ggfigfCfqqggihiC",
      "CgCedbbdifqqhhhg"
    ],
    [
      "            Q   ",
      "         剷      ",
      "  锁          刍  ",
      "                ",
      "Q   Q           ",
      "      刍 Q       ",
      "                ",
      "                ",
      "   刍            ",
      "                ",
      "                ",
      "                ",
      "                ",
      "  刍             ",
      "Q               ",
      "   edcdb        "
    ],
    [
      "                ",
      "                ",
      "                ",
      "                ",
      "                ",
      "                ",
      "                ",
      "                ",
      "                ",
      "                ",
      "                ",
      "                ",
      "                ",
      "                ",
      "                ",
      "   cddw         "
    ],
    [
      "                ",
      "                ",
      "                ",
      "                ",
      "                ",
      "                ",
      "                ",
      "                ",
      "                ",
      "                ",
      "                ",
      "                ",
      "                ",
      "                ",
      "                ",
      "   ww           "
    ],
    [
      "                ",
      "                ",
      "                ",
      "                ",
      "                ",
      "                ",
      "                ",
      "                ",
      "                ",
      "                ",
      "                ",
      "                ",
      "                ",
      "                ",
      "                ",
      "                "
    ]
  ]
}