{
  "xsize": 16,
  "zsize": 16,
  "palette": {
    "palette": [
      {
        "char": " ",
        "block": "minecraft:air"
      },
      {
        "char": "醉",
        "block": "minecraft:repeater[delay=1,facing=north,locked=false,powered=false]"
      },
      {
        "char": "z",
        "block": "minecraft:clay"
      },
      {
        "char": "y",
        "block": "minecraft:quartz_slab[type=top]"
      },
      {
        "char": "x",
        "block": "minecraft:redstone_lamp[lit=false]"
      },
      {
        "char": "e",
        "block": "minecraft:quartz_block"
      },
      {
        "char": "d",
        "block": "minecraft:diorite"
      },
      {
        "char": "D",
        "block": "minecraft:redstone_wire[east=none,west=none]"
      },
      {
        "char": "i",
        "block": "minecraft:cobbled_deepslate"
      },
      {
        "char": "g",
        "block": "minecraft:cyan_terracotta"
      },
      {
        "char": "N",
        "block": "minecraft:diorite_slab[type=top]"
      },
      {
        "char": "b",
        "block": "minecraft:polished_diorite"
      },
      {
        "char": "c",
        "block": "minecraft:smooth_quartz"
      },
      {
        "char": "l",
        "block": "minecraft:vine[east=false,north=false,south=false,up=false,west=true]"
      },
      {
        "char": "n",
        "block": "minecraft:vine[east=false,north=false,south=true,up=false,west=false]"
      },
      {
        "char": "p",
        "block": "minecraft:quartz_pillar[axis=y]"
      },
      {
        "char": "捏",
        "block": "minecraft:redstone_wire[east=none,south=none]"
      },
      {
        "char": "T",
        "block": "minecraft:vine[east=false,north=true,south=false,up=false,west=true]"
      },
      {
        "char": "f",
        "block": "minecraft:basalt[axis=x]"
      },
      {
        "char": "h",
        "block": "minecraft:deepslate[axis=y]"
      },
      {
        "char": "J",
        "block": "minecraft:polished_blackstone"
      },
      {
        "char": "w",
        "block": "minecraft:quartz_slab[type=bottom]"
      },
      {
        "char": "B",
        "block": "minecraft:moss_block"
      },
      {
        "char": "I",
        "block": "minecraft:black_concrete"
      },
      {
        "char": "K",
        "block": "minecraft:diorite_slab[type=bottom]"
      },
      {
        "char": "G",
        "block": "minecraft:cobblestone_slab[type=double]"
      },
      {
        "char": "q",
        "block": "minecraft:blackstone"
      },
      {
        "char": "染",
        "block": "minecraft:mossy_cobblestone_slab[type=double]"
      },
      {
        "char": "a",
        "block": "minecraft:smooth_stone_slab[type=top]"
      },
      {
        "char": "k",
        "block": "minecraft:stone_slab[type=top]"
      },
      {
        "char": "役",
        "block": "minecraft:dead_fire_coral_block"
      },
      {
        "char": "r",
        "block": "minecraft:cobblestone_slab[type=top]"
      },
      {
        "char": "拔",
        "block": "minecraft:mossy_cobblestone_slab[type=top]"
      },
      {
        "char": "酷",
        "block": "minecraft:air"
      },
      {
        "char": "麒",
        "block": "minecraft:vine[east=false,north=false,south=false,up=true,west=false]"
      },
      {
        "char": "裔",
        "block": "minecraft:vine[east=false,north=false,south=false,up=true,west=true]"
      },
      {
        "char": "C",
        "block": "minecraft:air"
      }
    ]
  },
  "slices": [
    [
      "醉  zy           ",
      "xx ed           ",
      "D  iy           ",
      "D  gN           ",
      "D  bb           ",
      "醉  zy           ",
      "xx zN           ",
      "D  ccl          ",
      "D  zy           ",
      "醉  zN           ",
      "xx ce      nn   ",
      "D  ebp    pbpl  ",
      "D  debbyycbdbbl ",
      "D  ddcbzzdddcel ",
      "D          ebpl ",
      "捏          ddT  "
    ],
    [
      "fghJw           ",
      "ffgdd           ",
      "BhiIK           ",
      "iGfJw           ",
      "Giiee           ",
      "GiBJK           ",
      "hfBqK           ",
      "Gg染bbl          ",
      "hghqK           ",
      "gghIw           ",
      "hgfdb      nn   ",
      "fBBbed    pbel  ",
      "ghgddbbKwddebd  ",
      "gffdebdJJbceecl ",
      "cchfhfih染Bfecel ",
      "ccfigBighhBebT  "
    ],
    [
      "aka役w           ",
      "aarbe           ",
      "aaazw           ",
      "aak役w           ",
      "ebbbb           ",
      "arazw           ",
      "aa拔zw           ",
      "aaabbl          ",
      "kaaiw           ",
      "kaazw           ",
      "aaaed           ",
      "kaadec    pep   ",
      "cccdccdKwbdbcp  ",
      "aaadeedzzdebed  ",
      "krabaakaa酷recp  ",
      "aaadaaaaraadb   "
    ],
    [
      "   zN           ",
      "   be           ",
      "   zy           ",
      "   hy           ",
      "   bc           ",
      "   zy           ",
      "   zy麒麒         ",
      "   dc裔麒         ",
      "   zN           ",
      "   zy           ",
      "   cd           ",
      "   ebe    bbc   ",
      "   dbbdNybbcdp  ",
      "   dbbczhcddeb  ",
      "           dcb  ",
      "           be   "
    ],
    [
      "qfqffbe         ",
      "ifgqidb         ",
      "gfgCice         ",
      "ghgihbb         ",
      "iqgihee         ",
      "igqgfce         ",
      "hqihfce         ",
      "fqfhCcd         ",
      "fhCgiee         ",
      "ihhifce         ",
      "fhfgfbccdecdded ",
      "fqhgfbbcdcebecb ",
      "hhiihqghfggifbb ",
      "fqgqigqiqfqfCcd ",
      "ifgiiqChigfihce ",
      "hifqfgqfghqChdd "
    ],
    [
      "     ec         ",
      "     ec         ",
      "     cb         ",
      "     bb         ",
      "     cc         ",
      "     dd         ",
      "     bb         ",
      "     cc         ",
      "     de         ",
      "     ee         ",
      "     ebeedeebdd ",
      "     bdeecbbbee ",
      "             cb ",
      "             dd ",
      "             eb ",
      "             cd "
    ]
  ]
}