{
  "xsize": 16,
  "zsize": 16,
  "palette": {
    "palette": [
      {
        "char": " ",
        "block": "minecraft:air"
      },
      {
        "char": "床",
        "block": "minecraft:oak_leaves"
      },
      {
        "char": "j",
        "block": "minecraft:vine[east=true,north=false,south=false,up=false,west=false]"
      },
      {
        "char": "竺",
        "block": "minecraft:quartz_pillar[axis=z]"
      },
      {
        "char": "b",
        "block": "minecraft:polished_diorite"
      },
      {
        "char": "e",
        "block": "minecraft:quartz_block"
      },
      {
        "char": "巡",
        "block": "minecraft:oak_leaves"
      },
      {
        "char": "y",
        "block": "minecraft:quartz_slab[type=top]"
      },
      {
        "char": "d",
        "block": "minecraft:diorite"
      },
      {
        "char": "睫",
        "block": "minecraft:quartz_stairs[facing=east,half=top,shape=outer_right]"
      },
      {
        "char": "亥",
        "block": "minecraft:quartz_stairs[facing=south,half=top,shape=straight]"
      },
      {
        "char": "袱",
        "block": "minecraft:quartz_stairs[facing=east,half=top,shape=straight]"
      },
      {
        "char": "c",
        "block": "minecraft:smooth_quartz"
      },
      {
        "char": "儸",
        "block": "minecraft:diorite_stairs[facing=east,half=top,shape=straight]"
      },
      {
        "char": "p",
        "block": "minecraft:quartz_pillar[axis=y]"
      },
      {
        "char": "m",
        "block": "minecraft:vine[east=false,north=true,south=false,up=false,west=false]"
      },
      {
        "char": "n",
        "block": "minecraft:vine[east=false,north=false,south=true,up=false,west=false]"
      },
      {
        "char": "K",
        "block": "minecraft:diorite_slab[type=bottom]"
      },
      {
        "char": "v",
        "block": "minecraft:red_terracotta"
      },
      {
        "char": "箍",
        "block": "minecraft:diorite_stairs[facing=south,half=bottom,shape=straight]"
      },
      {
        "char": "u",
        "block": "minecraft:red_concrete"
      },
      {
        "char": "擂",
        "block": "minecraft:diorite_stairs[facing=north,half=bottom,shape=straight]"
      },
      {
        "char": "w",
        "block": "minecraft:quartz_slab[type=bottom]"
      },
      {
        "char": "唆",
        "block": "minecraft:quartz_stairs[facing=south,half=bottom,shape=straight]"
      },
      {
        "char": "蒙",
        "block": "minecraft:quartz_stairs[facing=north,half=bottom,shape=straight]"
      },
      {
        "char": "庇",
        "block": "minecraft:diorite_stairs[facing=east,half=bottom,shape=straight]"
      },
      {
        "char": "袅",
        "block": "minecraft:quartz_stairs[facing=east,half=bottom,shape=straight]"
      },
      {
        "char": "佯",
        "block": "minecraft:diorite_stairs[facing=south,half=top,shape=straight]"
      },
      {
        "char": "椎",
        "block": "minecraft:quartz_stairs[facing=north,half=top,shape=straight]"
      },
      {
        "char": "N",
        "block": "minecraft:diorite_slab[type=top]"
      }
    ]
  },
  "slices": [
    [
      "床           j竺be",
      "巡            yed",
      "床         睫亥亥亥eb",
      "          袱ddccc",
      "         j袱cdbbc",
      "          儸eeedc",
      "          袱cdccb",
      "          儸cbbcd",
      "          袱edddd",
      "          袱eebed",
      "          袱decbd",
      "          袱ecccd",
      "          袱bebcc",
      "          袱dbcbe",
      "          儸cebed",
      "          袱cbddc"
    ],
    [
      "            jpbb",
      "床             bc",
      "             pcd",
      "           j  ee",
      "         j   eec",
      "          mj  be",
      "             cdc",
      "              db",
      "             pec",
      "          j   dc",
      "             pbc",
      "              cc",
      "           n pec",
      "          j   bb",
      "             pdc",
      "           n  ed"
    ],
    [
      "             Kcv",
      "             箍bu",
      "          u  竺bv",
      "           j 擂cu",
      "         j   wcv",
      "          mj wev",
      "             Keu",
      "             唆eu",
      "          u  竺cu",
      "          j  擂cv",
      "             weu",
      "             Kbv",
      "           n weu",
      "          j  箍cv",
      "          v  竺cu",
      "           n 蒙bu"
    ],
    [
      "             袱bb",
      "              ed",
      "          v  dce",
      "           j  be",
      "         j   袱bb",
      "          mj  dc",
      "             儸ec",
      "              dc",
      "          v  pee",
      "          j   ee",
      "             袱dc",
      "              eb",
      "           n 儸cd",
      "          j   bd",
      "          v  ddc",
      "           n  de"
    ],
    [
      "             庇cc",
      "              dd",
      "          u  eed",
      "           j  db",
      "         j   袅ed",
      "          mj  ec",
      "             袅ed",
      "              ee",
      "          u  pec",
      "          j   ed",
      "             袅bd",
      "              bd",
      "           n 袅bc",
      "          j   be",
      "          u  pbc",
      "           n  be"
    ],
    [
      "             yee",
      "             佯dc",
      "          u  竺bd",
      "           j 椎cc",
      "         j   Ndb",
      "          mj ydc",
      "             ybe",
      "             佯cb",
      "          u  edc",
      "          j  椎bd",
      "             yec",
      "             Nec",
      "           n yed",
      "          j  亥bb",
      "          v  竺db",
      "           n 椎de"
    ]
  ]
}