{
  "xsize": 16,
  "zsize": 16,
  "palette": {
    "palette": [
      {
        "char": " ",
        "block": "minecraft:air"
      },
      {
        "char": "p",
        "block": "minecraft:quartz_pillar[axis=y]"
      },
      {
        "char": "d",
        "block": "minecraft:diorite"
      },
      {
        "char": "c",
        "block": "minecraft:smooth_quartz"
      },
      {
        "char": "踵",
        "block": "minecraft:quartz_stairs[facing=east,half=bottom,shape=outer_right]"
      },
      {
        "char": "峋",
        "block": "minecraft:quartz_stairs[facing=south,half=bottom,shape=outer_right]"
      },
      {
        "char": "谟",
        "block": "minecraft:quartz_stairs[facing=north,half=bottom,shape=outer_right]"
      },
      {
        "char": "佚",
        "block": "minecraft:diorite_stairs[facing=west,half=bottom,shape=outer_right]"
      },
      {
        "char": "衹",
        "block": "minecraft:quartz_stairs[facing=west,half=bottom,shape=outer_right]"
      },
      {
        "char": "N",
        "block": "minecraft:diorite_slab[type=top]"
      },
      {
        "char": "y",
        "block": "minecraft:quartz_slab[type=top]"
      },
      {
        "char": "b",
        "block": "minecraft:polished_diorite"
      },
      {
        "char": "v",
        "block": "minecraft:red_terracotta"
      },
      {
        "char": "u",
        "block": "minecraft:red_concrete"
      },
      {
        "char": "w",
        "block": "minecraft:quartz_slab[type=bottom]"
      },
      {
        "char": "K",
        "block": "minecraft:diorite_slab[type=bottom]"
      },
      {
        "char": "e",
        "block": "minecraft:quartz_block"
      },
      {
        "char": "n",
        "block": "minecraft:vine[east=false,north=false,south=true,up=false,west=false]"
      }
    ]
  },
  "slices": [
    [
      "                ",
      "                ",
      "                ",
      "                ",
      "                ",
      "                ",
      "                ",
      "                ",
      "                ",
      "                ",
      " pd           pd",
      " cp           pc",
      "                ",
      "                ",
      "                ",
      "                "
    ],
    [
      "                ",
      "                ",
      "                ",
      "                ",
      "                ",
      "                ",
      "                ",
      "                ",
      "                ",
      "                ",
      " 踵峋           踵峋",
      " 谟佚           谟衹",
      "                ",
      "                ",
      "                ",
      "                "
    ],
    [
      "                ",
      "                ",
      "                ",
      "                ",
      "                ",
      "                ",
      "                ",
      "                ",
      "NyyNNNNNyNyyyyNy",
      "yyyyyyyyyyyyNNyy",
      "Ncd           bc",
      "ycc           cc",
      "N               ",
      "y               ",
      "y               ",
      "N               "
    ],
    [
      "                ",
      "                ",
      "                ",
      "                ",
      "                ",
      "                ",
      "                ",
      "                ",
      "                ",
      "vuvuvuvvuuvuvuuv",
      "uuuvuvuuvvuuuvuv",
      "vuuvvuvvuvuuuuuv",
      "vuuvuuvuuvvuvvuv",
      "vuvuuvvvvvuuuvvu",
      "uuuvvvuuuvuuuuuu",
      "vvvuuuvvuuuvvvuu"
    ],
    [
      "                ",
      "                ",
      "                ",
      "                ",
      "                ",
      "                ",
      "                ",
      "                ",
      "wwKwwKwKKwwwwwwK",
      "cbcccceecccbecec",
      "cededeceeeeddcce",
      "beebcdbccbeceede",
      "ccbbbeedbdcdeede",
      "bddbbbcbebddcddc",
      "bebcccdeebddbdbd",
      "dbbebbdccbdddccb"
    ],
    [
      "                ",
      "                ",
      "                ",
      "                ",
      "                ",
      "                ",
      "                ",
      "                ",
      "                ",
      "          w     ",
      "           e w w",
      "                ",
      "              b ",
      "        d K w K ",
      "                ",
      "nnnn nnn  nb w  "
    ]
  ]
}