{
  "xsize": 16,
  "zsize": 16,
  "palette": {
    "palette": [
      {
        "char": " ",
        "block": "minecraft:air"
      },
      {
        "char": "y",
        "block": "minecraft:quartz_slab[type=top]"
      },
      {
        "char": "z",
        "block": "minecraft:clay"
      },
      {
        "char": "D",
        "block": "minecraft:redstone_wire[east=none,west=none]"
      },
      {
        "char": "j",
        "block": "minecraft:vine[east=true,north=false,south=false,up=false,west=false]"
      },
      {
        "char": "d",
        "block": "minecraft:diorite"
      },
      {
        "char": "b",
        "block": "minecraft:polished_diorite"
      },
      {
        "char": "醉",
        "block": "minecraft:repeater[delay=1,facing=north,locked=false,powered=false]"
      },
      {
        "char": "x",
        "block": "minecraft:redstone_lamp[lit=false]"
      },
      {
        "char": "伟",
        "block": "minecraft:vine[east=true,north=false,south=true,up=false,west=false]"
      },
      {
        "char": "c",
        "block": "minecraft:smooth_quartz"
      },
      {
        "char": "e",
        "block": "minecraft:quartz_block"
      },
      {
        "char": "p",
        "block": "minecraft:quartz_pillar[axis=y]"
      },
      {
        "char": "q",
        "block": "minecraft:blackstone"
      },
      {
        "char": "役",
        "block": "minecraft:dead_fire_coral_block"
      },
      {
        "char": "N",
        "block": "minecraft:diorite_slab[type=top]"
      },
      {
        "char": "T",
        "block": "minecraft:vine[east=false,north=true,south=false,up=false,west=true]"
      },
      {
        "char": "m",
        "block": "minecraft:vine[east=false,north=true,south=false,up=false,west=false]"
      },
      {
        "char": "w",
        "block": "minecraft:quartz_slab[type=bottom]"
      },
      {
        "char": "I",
        "block": "minecraft:black_concrete"
      },
      {
        "char": "f",
        "block": "minecraft:basalt[axis=x]"
      },
      {
        "char": "i",
        "block": "minecraft:cobbled_deepslate"
      },
      {
        "char": "h",
        "block": "minecraft:deepslate[axis=y]"
      },
      {
        "char": "G",
        "block": "minecraft:cobblestone_slab[type=double]"
      },
      {
        "char": "g",
        "block": "minecraft:cyan_terracotta"
      },
      {
        "char": "B",
        "block": "minecraft:moss_block"
      },
      {
        "char": "J",
        "block": "minecraft:polished_blackstone"
      },
      {
        "char": "K",
        "block": "minecraft:diorite_slab[type=bottom]"
      },
      {
        "char": "a",
        "block": "minecraft:smooth_stone_slab[type=top]"
      },
      {
        "char": "k",
        "block": "minecraft:stone_slab[type=top]"
      },
      {
        "char": "剖",
        "block": "minecraft:glass_pane[east=false,north=false,south=false,west=false]"
      },
      {
        "char": "r",
        "block": "minecraft:cobblestone_slab[type=top]"
      },
      {
        "char": "C",
        "block": "minecraft:air"
      },
      {
        "char": "逛",
        "block": "minecraft:repeater[delay=1,facing=east,locked=false,powered=false]"
      },
      {
        "char": "贷",
        "block": "minecraft:redstone_wire[east=none,north=none]"
      },
      {
        "char": "揭",
        "block": "minecraft:redstone_wire[south=none,west=none]"
      }
    ]
  },
  "slices": [
    [
      "      yz  D   D ",
      "     jdb  D   D ",
      "   j  yz  醉   醉 ",
      "   j  yz  x   x ",
      "     伟ce        ",
      "    jpdc        ",
      "   jjdccebqzd役zc",
      "   j dbddcyydyNc",
      "   j  dbeT     m",
      "   j  mmm       ",
      "         mmmmm  ",
      "                ",
      "                ",
      "                ",
      "                ",
      "                "
    ],
    [
      "      wIfihGghgh",
      "     jdefBffgffg",
      "   j  wqGfGfgigf",
      "   j  wqfgiBBfii",
      "     伟bcGiiggfff",
      "    jpdbhifighhi",
      "   jjeccebqIeIJd",
      "   j pebeewKcwwb",
      "   j  dceT     m",
      "   j  mmm       ",
      "         mmmmm  ",
      "                ",
      "                ",
      "                ",
      "                ",
      "                "
    ],
    [
      "      wzaaaak剖kk",
      "      edaakaaaak",
      "   j  whkaakaaak",
      "   j  w役aaaaaaaa",
      "      bbaaaaaraa",
      "     ceekraaaakr",
      "   j cddcbzCdz役d",
      "   j cebcbwwewwc",
      "   j  dbp       ",
      "   j            ",
      "         mmmmm  ",
      "                ",
      "                ",
      "                ",
      "                ",
      "                "
    ],
    [
      "      Ni     x逛贷",
      "      dc       揭",
      "   j  yz        ",
      "   j  yz        ",
      "      ed        ",
      "     pee        ",
      "   j dddbbiCczzc",
      "   j pdbecyybyyc",
      "   j  ebp       ",
      "   j            ",
      "         mmmmm  ",
      "                ",
      "                ",
      "                ",
      "                ",
      "                "
    ],
    [
      "    beghiCihhiqq",
      "    echghfqfigif",
      "   jcdhffqfhqiCC",
      "   jbbqgCqihCfgi",
      "    dcigiChgiifg",
      "    bchgCgggqhiC",
      "   jeegfghiqgfiq",
      "   jdefihqqgifgg",
      "   jbebcbccbcced",
      "   jeceddbcececc",
      "         mmmmm  ",
      "                ",
      "                ",
      "                ",
      "                ",
      "                "
    ],
    [
      "    cb          ",
      "    ee          ",
      "   jbe          ",
      "   jed          ",
      "    bd          ",
      "    ed          ",
      "   jec          ",
      "   jce          ",
      "   jbedcdecdcbee",
      "   jbebcecdededc",
      "         mmmmm  ",
      "                ",
      "                ",
      "                ",
      "                ",
      "                "
    ]
  ]
}