{
  "xsize": 16,
  "zsize": 16,
  "palette": {
    "palette": [
      {
        "char": " ",
        "block": "minecraft:air"
      },
      {
        "char": "t",
        "block": "minecraft:grass_block[snowy=false]"
      },
      {
        "char": "o",
        "block": "minecraft:dirt"
      },
      {
        "char": "p",
        "block": "minecraft:quartz_pillar[axis=y]"
      },
      {
        "char": "c",
        "block": "minecraft:smooth_quartz"
      },
      {
        "char": "b",
        "block": "minecraft:polished_diorite"
      },
      {
        "char": "e",
        "block": "minecraft:quartz_block"
      },
      {
        "char": "s",
        "block": "minecraft:air"
      },
      {
        "char": "胡",
        "block": "minecraft:air"
      },
      {
        "char": "j",
        "block": "minecraft:vine[east=true,north=false,south=false,up=false,west=false]"
      },
      {
        "char": "d",
        "block": "minecraft:diorite"
      },
      {
        "char": "瓣",
        "block": "minecraft:oak_log[axis=y]"
      },
      {
        "char": "K",
        "block": "minecraft:diorite_slab[type=bottom]"
      },
      {
        "char": "w",
        "block": "minecraft:quartz_slab[type=bottom]"
      },
      {
        "char": "恁",
        "block": "minecraft:oak_leaves"
      },
      {
        "char": "劲",
        "block": "minecraft:oak_leaves"
      },
      {
        "char": "床",
        "block": "minecraft:oak_leaves"
      },
      {
        "char": "巡",
        "block": "minecraft:oak_leaves"
      },
      {
        "char": "u",
        "block": "minecraft:red_concrete"
      },
      {
        "char": "v",
        "block": "minecraft:red_terracotta"
      },
      {
        "char": "踵",
        "block": "minecraft:quartz_stairs[facing=east,half=bottom,shape=outer_right]"
      },
      {
        "char": "唆",
        "block": "minecraft:quartz_stairs[facing=south,half=bottom,shape=straight]"
      },
      {
        "char": "庇",
        "block": "minecraft:diorite_stairs[facing=east,half=bottom,shape=straight]"
      },
      {
        "char": "狩",
        "block": "minecraft:quartz_stairs[facing=east,half=bottom,shape=outer_left]"
      },
      {
        "char": "擂",
        "block": "minecraft:diorite_stairs[facing=north,half=bottom,shape=straight]"
      },
      {
        "char": "躅",
        "block": "minecraft:quartz_stairs[facing=south,half=bottom,shape=outer_left]"
      },
      {
        "char": "袅",
        "block": "minecraft:quartz_stairs[facing=east,half=bottom,shape=straight]"
      },
      {
        "char": "竺",
        "block": "minecraft:quartz_pillar[axis=z]"
      },
      {
        "char": "谟",
        "block": "minecraft:quartz_stairs[facing=north,half=bottom,shape=outer_right]"
      },
      {
        "char": "蒙",
        "block": "minecraft:quartz_stairs[facing=north,half=bottom,shape=straight]"
      },
      {
        "char": "雎",
        "block": "minecraft:diorite_stairs[facing=south,half=bottom,shape=outer_left]"
      },
      {
        "char": "伟",
        "block": "minecraft:vine[east=true,north=false,south=true,up=false,west=false]"
      },
      {
        "char": "m",
        "block": "minecraft:vine[east=false,north=true,south=false,up=false,west=false]"
      },
      {
        "char": "调",
        "block": "minecraft:vine[east=true,north=true,south=false,up=false,west=false]"
      }
    ]
  },
  "slices": [
    [
      "tttttttttttttooo",
      "ttttottttttotooo",
      "tttttttttttttooo",
      "tttttttttotttooo",
      "tttttttttttooooo",
      "tttottttttttoooo",
      "ttttotttttttoooo",
      "ttttttttotttoooo",
      "ttttttttttttoooo",
      "ttottottttotpppp",
      "tttttttttottpppp",
      "tttttottottocppp",
      "ttttttttttttppcp",
      "ttototttttttbppp",
      "tttttttototopppp",
      "ttttttotttttpepp"
    ],
    [
      "ss胡s胡胡胡sssssjpde",
      "ssss瓣ssssssbsbde",
      "ssssss胡sssssjcpc",
      "ss胡胡胡胡胡ssbssscbd",
      "sssssssssssKedcd",
      "ssscssssss胡sdbce",
      "sssscssssssscbdc",
      "ssssss胡s瓣sssdcdc",
      "sssssssssssseced",
      "sswsswsssswscecb",
      "ssssssssscssbcbd",
      "sssssbssdssccddc",
      "ssssssssssssdedb",
      "sscswsssssssecce",
      "ssssssswswsKbbbd",
      "ssss胡胡bsssssdbbd"
    ],
    [
      "            jpbd",
      "    瓣       jcce",
      "            jpde",
      "             ebd",
      "            eded",
      "      恁劲床劲  bddd",
      "      劲床巡床劲 ecdc",
      "      床巡瓣巡床 bede",
      "      劲床巡床劲 dbee",
      "       劲床劲恁 edbu",
      "            dbbv",
      "            edcu",
      "            bbbv",
      "            ebbc",
      "            becv",
      "            dbdu"
    ],
    [
      "  劲床巡床劲     jppb",
      "  床巡瓣巡床     jcdb",
      "  劲床巡床劲     jppb",
      "   劲床劲恁      wec",
      "            踵唆de",
      "      恁劲床劲恁 庇bbb",
      "      劲床巡床劲 狩擂db",
      "      床巡瓣巡床 躅唆de",
      "      劲床巡床劲 袅竺ce",
      "      恁劲床劲恁 谟蒙dc",
      "            雎唆eb",
      "            庇ecd",
      "            谟蒙dd",
      "            雎唆dc",
      "            袅竺cb",
      "            谟擂bb"
    ],
    [
      "  劲床巡床劲     jced",
      "  床巡瓣巡床     jddb",
      "  劲床巡床劲     jppd",
      "  恁劲床劲        bc",
      "             伟ce",
      "            jdcc",
      "       床巡    mcc",
      "       巡瓣巡    cd",
      "       床巡床   pbb",
      "              db",
      "              ce",
      "            jpde",
      "             调cc",
      "             伟de",
      "            jcdb",
      "  劲床劲恁        bb"
    ],
    [
      "    巡       jppe",
      "   巡瓣巡      jddd",
      "   床巡       jbpc",
      "              eb",
      "             伟ce",
      "            jpce",
      "        床    mdd",
      "       床巡床    bc",
      "        床    pdd",
      "              cd",
      "              db",
      "            jpbd",
      "             调cd",
      "             伟ee",
      "            jpbc",
      "  劲床劲         eb"
    ]
  ]
}