{
  "xsize": 16,
  "zsize": 16,
  "palette": {
    "palette": [
      {
        "char": " ",
        "block": "minecraft:air"
      },
      {
        "char": "杠",
        "block": "minecraft:stone_brick_stairs[facing=east,half=top,shape=straight]"
      },
      {
        "char": "廖",
        "block": "minecraft:stone_brick_stairs[facing=west,half=bottom,shape=straight]"
      },
      {
        "char": "b",
        "block": "minecraft:polished_diorite"
      },
      {
        "char": "d",
        "block": "minecraft:diorite"
      },
      {
        "char": "c",
        "block": "minecraft:smooth_quartz"
      },
      {
        "char": "m",
        "block": "minecraft:vine[east=false,north=true,south=false,up=false,west=false]"
      },
      {
        "char": "e",
        "block": "minecraft:quartz_block"
      },
      {
        "char": "z",
        "block": "minecraft:clay"
      },
      {
        "char": "y",
        "block": "minecraft:quartz_slab[type=top]"
      },
      {
        "char": "h",
        "block": "minecraft:deepslate[axis=y]"
      },
      {
        "char": "i",
        "block": "minecraft:cobbled_deepslate"
      },
      {
        "char": "C",
        "block": "minecraft:air"
      },
      {
        "char": "g",
        "block": "minecraft:cyan_terracotta"
      },
      {
        "char": "f",
        "block": "minecraft:basalt[axis=x]"
      },
      {
        "char": "q",
        "block": "minecraft:blackstone"
      },
      {
        "char": "Q",
        "block": "minecraft:smooth_stone_slab[type=bottom]"
      },
      {
        "char": "牒",
        "block": "minecraft:air"
      },
      {
        "char": "谦",
        "block": "minecraft:air"
      },
      {
        "char": "锁",
        "block": "minecraft:stone_slab[type=bottom]"
      },
      {
        "char": "剷",
        "block": "minecraft:stone_button[face=floor,facing=east,powered=false]"
      },
      {
        "char": "荀",
        "block": "minecraft:stone_button[face=floor,facing=south,powered=false]"
      },
      {
        "char": "钞",
        "block": "minecraft:oak_wall_sign",
        "tag": {
          "z": 479,
          "x": -90,
          "is_waxed": "0b",
          "ForgeCaps": {
            "supplementaries:antique_ink": {
              "ink": "0b"
            }
          },
          "id": "minecraft:sign",
          "y": 153,
          "front_text": {
            "color": "black",
            "has_glowing_text": "0b",
            "messages": [
              "{\"text\":\"\"}",
              "{\"text\":\"\"}",
              "{\"text\":\"\"}",
              "{\"text\":\"\"}"
            ]
          },
          "back_text": {
            "color": "black",
            "has_glowing_text": "0b",
            "messages": [
              "{\"text\":\"\"}",
              "{\"text\":\"\"}",
              "{\"text\":\"\"}",
              "{\"text\":\"\"}"
            ]
          }
        }
      },
      {
        "char": "狡",
        "block": "minecraft:vine[east=false,north=true,south=false,up=true,west=false]"
      },
      {
        "char": "w",
        "block": "minecraft:quartz_slab[type=bottom]"
      },
      {
        "char": "K",
        "block": "minecraft:diorite_slab[type=bottom]"
      },
      {
        "char": "乒",
        "block": "minecraft:oak_slab[type=bottom]"
      }
    ]
  },
  "slices": [
    [
      "   杠廖    bdb    ",
      "   杠廖    cd    m",
      "   cde   de     ",
      "  dccd   ec     ",
      "  d      ce     ",
      "  e      ddc    ",
      "zdbddebdccbc    ",
      "yebebeebcccd    ",
      "        cbb     ",
      "mmmm mmm        ",
      "                ",
      "                ",
      "                ",
      "                ",
      "                ",
      "                "
    ],
    [
      "hhi廖    ChCccecd",
      "gff廖    CfCe   m",
      "ghhcecedhhqc    ",
      "iqCgffhfqihc    ",
      "fqgihCCiCiib    ",
      "fqifCfhihggd    ",
      "hhffhhiffgqe    ",
      "hhfgCighffid    ",
      "ccebcdbeecec    ",
      "mmmm mmm        ",
      "                ",
      "                ",
      "                ",
      "                ",
      "                ",
      "                "
    ],
    [
      "Q 牒谦   e   bbcec",
      "       d   d   m",
      "锁 剷ceeec   c    ",
      "           d    ",
      "           b    ",
      "           e    ",
      "荀          e    ",
      "       钞   b    ",
      "bbddbbcebeeb    ",
      "m  m mm狡        ",
      "                ",
      "                ",
      "                ",
      "                ",
      "                ",
      "                "
    ],
    [
      "  牒谦 yw         ",
      "     yK         ",
      "   ebdw         ",
      "                ",
      "                ",
      "                ",
      "                ",
      "                ",
      "       乒        ",
      "       乒        ",
      "                ",
      "                ",
      "                ",
      "                ",
      "                ",
      "                "
    ],
    [
      "   ww           ",
      "   wK           ",
      "   ww           ",
      "                ",
      "                ",
      "                ",
      "                ",
      "                ",
      "                ",
      "                ",
      "                ",
      "                ",
      "                ",
      "                ",
      "                ",
      "                "
    ],
    [
      "                ",
      "                ",
      "                ",
      "                ",
      "                ",
      "                ",
      "                ",
      "                ",
      "                ",
      "                ",
      "                ",
      "                ",
      "                ",
      "                ",
      "                ",
      "                "
    ]
  ]
}