{
  "xsize": 16,
  "zsize": 16,
  "palette": {
    "palette": [
      {
        "char": " ",
        "block": "minecraft:air"
      },
      {
        "char": "e",
        "block": "minecraft:quartz_block"
      },
      {
        "char": "d",
        "block": "minecraft:diorite"
      },
      {
        "char": "g",
        "block": "minecraft:cyan_terracotta"
      },
      {
        "char": "h",
        "block": "minecraft:deepslate[axis=y]"
      },
      {
        "char": "i",
        "block": "minecraft:cobbled_deepslate"
      },
      {
        "char": "c",
        "block": "minecraft:smooth_quartz"
      },
      {
        "char": "b",
        "block": "minecraft:polished_diorite"
      },
      {
        "char": "f",
        "block": "minecraft:basalt[axis=x]"
      },
      {
        "char": "啻",
        "block": "minecraft:redstone_wall_torch[facing=west,lit=false]"
      },
      {
        "char": "甯",
        "block": "minecraft:repeater[delay=1,facing=east,locked=false,powered=true]"
      },
      {
        "char": "鸾",
        "block": "minecraft:redstone_wall_torch[facing=south,lit=true]"
      },
      {
        "char": "q",
        "block": "minecraft:blackstone"
      },
      {
        "char": "C",
        "block": "minecraft:air"
      },
      {
        "char": "E",
        "block": "minecraft:redstone_wire[north=none,south=none]"
      },
      {
        "char": "怨",
        "block": "minecraft:repeater[delay=1,facing=west,locked=false,powered=false]"
      },
      {
        "char": "x",
        "block": "minecraft:redstone_lamp[lit=false]"
      },
      {
        "char": "D",
        "block": "minecraft:redstone_wire[east=none,west=none]"
      },
      {
        "char": "膨",
        "block": "minecraft:redstone_wire[east=none]"
      },
      {
        "char": "醉",
        "block": "minecraft:repeater[delay=1,facing=north,locked=false,powered=false]"
      },
      {
        "char": "痹",
        "block": "minecraft:redstone_torch[lit=true]"
      },
      {
        "char": "P",
        "block": "minecraft:blue_terracotta"
      },
      {
        "char": "O",
        "block": "minecraft:light_blue_terracotta"
      },
      {
        "char": "B",
        "block": "minecraft:moss_block"
      },
      {
        "char": "染",
        "block": "minecraft:mossy_cobblestone_slab[type=double]"
      },
      {
        "char": "a",
        "block": "minecraft:smooth_stone_slab[type=top]"
      },
      {
        "char": "k",
        "block": "minecraft:stone_slab[type=top]"
      },
      {
        "char": "痰",
        "block": "minecraft:lime_wool"
      },
      {
        "char": "r",
        "block": "minecraft:cobblestone_slab[type=top]"
      },
      {
        "char": "剖",
        "block": "minecraft:glass_pane[east=false,north=false,south=false,west=false]"
      },
      {
        "char": "酷",
        "block": "minecraft:air"
      },
      {
        "char": "拔",
        "block": "minecraft:mossy_cobblestone_slab[type=top]"
      },
      {
        "char": "萼",
        "block": "minecraft:orange_wool"
      },
      {
        "char": "叨",
        "block": "minecraft:redstone_torch[lit=false]"
      },
      {
        "char": "逛",
        "block": "minecraft:repeater[delay=1,facing=east,locked=false,powered=false]"
      }
    ]
  },
  "slices": [
    [
      "edghige   c   b ",
      " cf  fb       b ",
      " chi fb       b ",
      "啻f甯鸾 ie       b ",
      " dqq Cdcbdbbedd ",
      " bde ecdcbbebde ",
      "                ",
      " EE怨xEE怨xEEEE怨xE",
      "    x   x     x ",
      "                ",
      "                ",
      "            D   ",
      "怨xEE怨xEE怨xEE膨  x",
      " x   x   x  D  x",
      "            D   ",
      "            醉   "
    ],
    [
      "defgiqc   c   dg",
      "hbg  Cc       cf",
      "hbh痹 fe       ef",
      "hef  gb       bi",
      "fcigCgbbcdcdddeg",
      "geccceecbcdddedh",
      "iighiiggfigggfig",
      "dbdeecbeebcecedd",
      "cbedcddecddddbeb",
      "gihggeeghihfhgii",
      "hfhhgbbhifhfhggh",
      "PPOfibeggfBfhBbi",
      "OPOigcbhgiggihcf",
      "OPOggdehhfgghhcc",
      "OOOhidbfihB染ffbd",
      "OOPiieefhihhfidi"
    ],
    [
      "ddqhqCe   d   ca",
      "adq  Cd       da",
      "acgi ic       da",
      "kd痰  fb       ck",
      "abCfCqedcbbddeea",
      "abbdcccdebdbebea",
      "racaaaakaaakbrka",
      "剖aea剖aaaa剖kaba剖k",
      " kda aark aaca k",
      "kadkaaraaaraeaak",
      "ebddarakdcdecbbd",
      "karea 剖acraaa酷ba",
      "rkacaaaadaaaaaek",
      "kkaceddcca拔剖kkda",
      "kaacakaad酷酷aaaca",
      "aaacakaacakakaba"
    ],
    [
      "cbqhqge   c   b ",
      " bf萼 qb       b ",
      " bi叨 fe       c ",
      "  逛  fd       b ",
      " bgCigecdeeceed ",
      " ddbcdbbcbbecee ",
      "                ",
      "x  怨x   怨x   怨x ",
      "x   x    x    x ",
      "                ",
      "      醉         ",
      "     xx         ",
      "           醉    ",
      "           x    ",
      "                ",
      "      醉         "
    ],
    [
      "igqhgCc   c   cf",
      "fifqihe       bh",
      "Cfiqfid       cC",
      "iqhqfhd       cf",
      "Cfgifgdcdcedbedq",
      "fqfiqihCgqhfihih",
      "hqqfgfqqiqifgggq",
      "hfqfhfifCgqgqCqh",
      "qqgqiigqhihhCqCg",
      "hCffghCffghfigfi",
      "qiiCqqihgqigqCgq",
      "igfqqCfhhfCghqif",
      "qigqifqiqfqhqCgg",
      "hhqgghhiqCCqhhig",
      "iCChfqfhCqiqCigg",
      "CqCihhCghhfgghii"
    ],
    [
      "      b   d   d ",
      "      e       d ",
      "      b       c ",
      "      b       b ",
      "      eddeebbdb ",
      "                ",
      "                ",
      "                ",
      "                ",
      "                ",
      "                ",
      "                ",
      "                ",
      "                ",
      "                ",
      "                "
    ]
  ]
}