{
  "xsize": 16,
  "zsize": 16,
  "palette": {
    "palette": [
      {
        "char": " ",
        "block": "minecraft:air"
      },
      {
        "char": "噹",
        "block": "minecraft:air"
      },
      {
        "char": "M",
        "block": "minecraft:air"
      },
      {
        "char": "d",
        "block": "minecraft:diorite"
      },
      {
        "char": "e",
        "block": "minecraft:quartz_block"
      },
      {
        "char": "b",
        "block": "minecraft:polished_diorite"
      },
      {
        "char": "c",
        "block": "minecraft:smooth_quartz"
      },
      {
        "char": "锁",
        "block": "minecraft:stone_slab[type=bottom]"
      },
      {
        "char": "w",
        "block": "minecraft:quartz_slab[type=bottom]"
      },
      {
        "char": "喃",
        "block": "minecraft:cobblestone_slab[type=bottom]"
      },
      {
        "char": "Q",
        "block": "minecraft:smooth_stone_slab[type=bottom]"
      },
      {
        "char": "K",
        "block": "minecraft:diorite_slab[type=bottom]"
      },
      {
        "char": "耻",
        "block": "minecraft:air"
      },
      {
        "char": "G",
        "block": "minecraft:cobblestone_slab[type=double]"
      },
      {
        "char": "k",
        "block": "minecraft:stone_slab[type=top]"
      },
      {
        "char": "r",
        "block": "minecraft:cobblestone_slab[type=top]"
      },
      {
        "char": "a",
        "block": "minecraft:smooth_stone_slab[type=top]"
      },
      {
        "char": "滂",
        "block": "minecraft:stone_slab[type=top]"
      },
      {
        "char": "芩",
        "block": "minecraft:cobblestone_wall[up=true]"
      },
      {
        "char": "L",
        "block": "minecraft:air"
      },
      {
        "char": "躅",
        "block": "minecraft:quartz_stairs[facing=south,half=bottom,shape=outer_left]"
      },
      {
        "char": "唆",
        "block": "minecraft:quartz_stairs[facing=south,half=bottom,shape=straight]"
      },
      {
        "char": "蜒",
        "block": "minecraft:quartz_stairs[facing=west,half=bottom,shape=outer_left]"
      },
      {
        "char": "踵",
        "block": "minecraft:quartz_stairs[facing=east,half=bottom,shape=outer_right]"
      },
      {
        "char": "袅",
        "block": "minecraft:quartz_stairs[facing=east,half=bottom,shape=straight]"
      },
      {
        "char": "嗅",
        "block": "minecraft:quartz_stairs[facing=west,half=bottom,shape=straight]"
      },
      {
        "char": "庇",
        "block": "minecraft:diorite_stairs[facing=east,half=bottom,shape=straight]"
      },
      {
        "char": "狩",
        "block": "minecraft:quartz_stairs[facing=east,half=bottom,shape=outer_left]"
      },
      {
        "char": "蒙",
        "block": "minecraft:quartz_stairs[facing=north,half=bottom,shape=straight]"
      },
      {
        "char": "衹",
        "block": "minecraft:quartz_stairs[facing=west,half=bottom,shape=outer_right]"
      },
      {
        "char": "稽",
        "block": "minecraft:rail[shape=south_east]"
      },
      {
        "char": "珈",
        "block": "minecraft:rail[shape=south_west]"
      },
      {
        "char": "鹃",
        "block": "minecraft:rail[shape=north_east]"
      },
      {
        "char": "峨",
        "block": "minecraft:rail[shape=north_west]"
      }
    ]
  },
  "slices": [
    [
      "                ",
      "    噹  M      噹 ",
      "                ",
      "   debbec    edc",
      "   c锁锁锁锁w    w喃Q",
      "   dQQQQw    KQQ",
      "   bQQQQw    wQQ",
      "   d锁锁锁Qw    w锁锁",
      "   ebdecd    dcd",
      "                ",
      "    耻  耻      耻 ",
      "                ",
      "              Gk",
      "              ra",
      "              滂a",
      "              芩 "
    ],
    [
      "                ",
      "    耻  耻      耻 ",
      "                ",
      "   cQebQc    cQe",
      "   d    K    w  ",
      "   d    K    w  ",
      "   c    K    K  ",
      "   b    w    w  ",
      "   c锁bcQe    bQc",
      "                ",
      "    耻  耻      耻 ",
      "                ",
      "                ",
      "                ",
      "                ",
      "              QQ"
    ],
    [
      "                ",
      "    噹  M      噹 ",
      "    耻  噹      L ",
      "   eddbce    dec",
      "   e    w    w  ",
      "   c    w    K  ",
      "   b    w    K  ",
      "   c    w    K  ",
      "   ddbeee    cbc",
      "    M  耻      耻 ",
      "    耻  M      耻 ",
      "                ",
      "                ",
      "                ",
      "                ",
      "                "
    ],
    [
      "                ",
      "                ",
      "                ",
      "   eaccae    cke",
      "   e    w    w  ",
      "   d    w    K  ",
      "   d    K    w  ",
      "   b    w    w  ",
      "   daceae    dab",
      "                ",
      "                ",
      "                ",
      "                ",
      "                ",
      "                ",
      "                "
    ],
    [
      "                ",
      "                ",
      "                ",
      "   QQ喃锁Q锁    锁QQ",
      "   Q躅唆唆蜒Q    锁踵唆",
      "   Q袅db嗅喃    锁袅b",
      "   Q庇ed嗅Q    锁庇d",
      "   Q狩蒙蒙衹Q    喃狩蒙",
      "   QQQ锁QQ    Q锁锁",
      "                ",
      "                ",
      "                ",
      "                ",
      "                ",
      "                ",
      "                "
    ],
    [
      "                ",
      "                ",
      "                ",
      "                ",
      "                ",
      "     稽珈        稽",
      "     鹃峨        鹃",
      "                ",
      "                ",
      "                ",
      "                ",
      "                ",
      "                ",
      "                ",
      "                ",
      "                "
    ]
  ]
}