{
  "xsize": 16,
  "zsize": 16,
  "palette": {
    "palette": [
      {
        "char": " ",
        "block": "minecraft:air"
      },
      {
        "char": "n",
        "block": "minecraft:vine[east=false,north=false,south=true,up=false,west=false]"
      },
      {
        "char": "岛",
        "block": "minecraft:glass_pane[east=true,north=false,south=false,west=true]"
      },
      {
        "char": "b",
        "block": "minecraft:polished_diorite"
      },
      {
        "char": "c",
        "block": "minecraft:smooth_quartz"
      },
      {
        "char": "e",
        "block": "minecraft:quartz_block"
      },
      {
        "char": "d",
        "block": "minecraft:diorite"
      },
      {
        "char": "l",
        "block": "minecraft:vine[east=false,north=false,south=false,up=false,west=true]"
      },
      {
        "char": "m",
        "block": "minecraft:vine[east=false,north=true,south=false,up=false,west=false]"
      },
      {
        "char": "辽",
        "block": "minecraft:glass_pane[east=true,north=false,south=false,west=false]"
      },
      {
        "char": "暗",
        "block": "minecraft:glass_pane[east=false,north=false,south=false,west=true]"
      },
      {
        "char": "划",
        "block": "minecraft:chest",
        "tag": {
          "z": 453,
          "x": -27,
          "ForgeCaps": {},
          "id": "minecraft:chest",
          "y": 148,
          "NodePos": "-7421701631852L",
          "Connections": [
            "L"
          ]
        }
      },
      {
        "char": "伤",
        "block": "minecraft:chest",
        "tag": {
          "z": 411,
          "x": -94,
          "ForgeCaps": {},
          "id": "minecraft:chest",
          "y": 136,
          "NodePos": "-25838521569144L",
          "Connections": [
            "L"
          ]
        }
      },
      {
        "char": "法",
        "block": "minecraft:chest",
        "tag": {
          "z": 483,
          "x": -73,
          "ForgeCaps": {},
          "id": "minecraft:chest",
          "y": 160,
          "NodePos": "-20066085228384L",
          "Connections": [
            "L"
          ]
        }
      },
      {
        "char": "A",
        "block": "minecraft:smooth_stone_slab[type=double]"
      },
      {
        "char": "k",
        "block": "minecraft:stone_slab[type=top]"
      },
      {
        "char": "r",
        "block": "minecraft:cobblestone_slab[type=top]"
      },
      {
        "char": "a",
        "block": "minecraft:smooth_stone_slab[type=top]"
      },
      {
        "char": "亥",
        "block": "minecraft:quartz_stairs[facing=south,half=top,shape=straight]"
      },
      {
        "char": "佯",
        "block": "minecraft:diorite_stairs[facing=south,half=top,shape=straight]"
      },
      {
        "char": "椎",
        "block": "minecraft:quartz_stairs[facing=north,half=top,shape=straight]"
      },
      {
        "char": "桨",
        "block": "minecraft:diorite_stairs[facing=north,half=top,shape=straight]"
      }
    ]
  },
  "slices": [
    [
      "                ",
      "                ",
      "                ",
      "                ",
      "                ",
      " nn      nn   n ",
      "岛bc岛岛ed岛岛ed岛岛dd ",
      " dd  eb  del ec ",
      "mmm     m mmmmm ",
      "                ",
      "   mmm          ",
      "                ",
      "                ",
      "                ",
      "                ",
      "                "
    ],
    [
      "                ",
      "                ",
      "                ",
      "                ",
      "                ",
      " nn      nn     ",
      "岛bc 辽bd岛岛bb岛岛dc岛",
      " cc  cd  edl bd ",
      "mmm     m mmmmm ",
      "                ",
      "   mmm          ",
      "                ",
      "                ",
      "                ",
      "                ",
      "                "
    ],
    [
      "                ",
      "                ",
      "                ",
      "                ",
      "                ",
      " nn      nn     ",
      "岛db岛岛de 辽ee岛岛cd ",
      " ed  ed  dcl cb ",
      "mmm     m mmmmm ",
      "                ",
      "   mmm          ",
      "                ",
      "                ",
      "                ",
      "                ",
      "                "
    ],
    [
      "                ",
      "                ",
      "                ",
      "                ",
      "                ",
      " nn       n     ",
      "岛eb岛岛ee  db岛岛eb暗",
      " bb  cb  bd  bb ",
      "mmm     m mmmmm ",
      "                ",
      "   mmm          ",
      "                ",
      "                ",
      "                ",
      "                ",
      "                "
    ],
    [
      "划  伤伤  伤伤  法法  法",
      "                ",
      "                ",
      "伤  伤伤  伤伤  法法  法",
      "                ",
      "          n     ",
      "岛cd 辽db岛岛cc岛岛ed岛",
      " db  eb  cc  ce ",
      "m m     m mmmmm ",
      "                ",
      "   mmm          ",
      "                ",
      "                ",
      "                ",
      "                ",
      "                "
    ],
    [
      "AkrAAkaAAkkAAraA",
      "aakrakaarrakakkk",
      "raraaaaakaakaaka",
      "AakAAaaAArrAAkkA",
      "aaaaraaaaaaaakak",
      "aaaaakaraaaarkaa",
      "亥ce佯亥bd亥亥cb亥亥dd佯",
      "椎ec椎椎ed椎椎ce桨桨db椎",
      "m m     m mmm m ",
      "                ",
      "   mmm          ",
      "                ",
      "                ",
      "                ",
      "                ",
      "                "
    ]
  ]
}