{
  "xsize": 16,
  "zsize": 16,
  "palette": {
    "palette": [
      {
        "char": " ",
        "block": "minecraft:air"
      },
      {
        "char": "i",
        "block": "minecraft:vine[east=false,north=false,south=true,up=false,west=false]"
      },
      {
        "char": "g",
        "block": "minecraft:vine[east=true,north=false,south=false,up=false,west=false]"
      },
      {
        "char": "k",
        "block": "minecraft:stone_bricks"
      },
      {
        "char": "У",
        "block": "minecraft:vine[east=false,north=false,south=true,up=true,west=true]"
      },
      {
        "char": "σ",
        "block": "minecraft:vine[east=false,north=true,south=false,up=true,west=false]"
      },
      {
        "char": "c",
        "block": "minecraft:stone"
      },
      {
        "char": "b",
        "block": "minecraft:glass"
      },
      {
        "char": "d",
        "block": "minecraft:mossy_cobblestone"
      },
      {
        "char": "B",
        "block": "minecraft:water"
      },
      {
        "char": "a",
        "block": "minecraft:cobblestone"
      },
      {
        "char": "e",
        "block": "minecraft:smooth_stone_slab[type=double]"
      },
      {
        "char": "u",
        "block": "minecraft:stone_brick_slab[type=top]"
      },
      {
        "char": "z",
        "block": "minecraft:cracked_stone_bricks"
      },
      {
        "char": "ʹ",
        "block": "minecraft:spawner",
        "tag": {
          "SpawnData": {
            "entity": {}
          },
          "MaxNearbyEntities": "6s",
          "MinSpawnDelay": "200s",
          "z": 579,
          "x": 51,
          "MaxSpawnDelay": "800s",
          "RequiredPlayerRange": "16s",
          "SpawnCount": "4s",
          "ForgeCaps": {},
          "id": "minecraft:mob_spawner",
          "SpawnPotentials": [],
          "y": 132,
          "SpawnRange": "4s",
          "Delay": "94s"
        }
      },
      {
        "char": "j",
        "block": "minecraft:bookshelf"
      },
      {
        "char": "H",
        "block": "minecraft:oak_stairs[facing=north,half=bottom,shape=straight]"
      },
      {
        "char": "Q",
        "block": "minecraft:oak_stairs[facing=west,half=bottom,shape=straight]"
      },
      {
        "char": ";",
        "block": "minecraft:air"
      },
      {
        "char": "w",
        "block": "minecraft:air"
      },
      {
        "char": "A",
        "block": "minecraft:air"
      },
      {
        "char": "E",
        "block": "minecraft:oak_stairs[facing=south,half=bottom,shape=straight]"
      },
      {
        "char": "v",
        "block": "minecraft:stone_brick_stairs[facing=south,half=bottom,shape=straight]"
      },
      {
        "char": "I",
        "block": "minecraft:iron_bars[east=false,north=true,south=true,west=false]"
      },
      {
        "char": "U",
        "block": "minecraft:flower_pot"
      },
      {
        "char": "Ϳ",
        "block": "minecraft:ladder[facing=west]"
      },
      {
        "char": "Ο",
        "block": "minecraft:air"
      },
      {
        "char": "Ε",
        "block": "minecraft:vine[east=true,north=false,south=false,up=true,west=false]"
      }
    ]
  },
  "slices": [
    [
      "                ",
      "                ",
      "                ",
      "                ",
      "                ",
      "                ",
      "                ",
      "        i  iiiii",
      "       gkУ      ",
      "       gσcbdbcb ",
      "       g bBb    ",
      "         cb     ",
      "         b      ",
      "         a      ",
      "         b      ",
      "         d      "
    ],
    [
      "                ",
      "                ",
      "                ",
      "                ",
      "                ",
      "                ",
      "                ",
      "        i  iiiii",
      "       geeeeeeee",
      "       geaaaaaaa",
      "       geaBbccdc",
      "        eabccaaa",
      "        eaacdcac",
      "      uueacdadca",
      "      u eacadacd",
      "      u eaacccdc"
    ],
    [
      "                ",
      "                ",
      "                ",
      "                ",
      "                ",
      "                ",
      "                ",
      "        i  iiiii",
      "       gz       ",
      "       g dbabdbc",
      "       g bBʹj  H",
      "         aʹj  Qk",
      "     ;wwwbj   Qk",
      "     A   d     E",
      "     A v b      ",
      "     I   a      "
    ],
    [
      "                ",
      "                ",
      "                ",
      "                ",
      "                ",
      "                ",
      "                ",
      "        i  iiiii",
      "       gz       ",
      "       g cbcbdbc",
      "       g bBbj   ",
      "         abj   U",
      "         bj    U",
      "         c      ",
      "       g b      ",
      "       v c      "
    ],
    [
      "                ",
      "                ",
      "                ",
      "                ",
      "                ",
      "                ",
      "                ",
      "        i  iiiii",
      "       gz       ",
      "       g abcbaba",
      "       g bBb    ",
      "         db     ",
      "         b      ",
      "         a      ",
      "       g b      ",
      "       g c      "
    ],
    [
      "                ",
      "                ",
      "                ",
      "                ",
      "                ",
      "                ",
      "              ͿΟ",
      "        i  iiiii",
      "       geeeeeeee",
      "       geaaaaaaa",
      "       geaBbcacd",
      "        eabdadcc",
      "        eaacddac",
      "      uueaaddaac",
      "      uΕeacdaadd",
      "      ugeadaaaaa"
    ]
  ]
}