{
  "xsize": 16,
  "zsize": 16,
  "palette": {
    "palette": [
      {
        "char": " ",
        "block": "minecraft:air"
      },
      {
        "char": "A",
        "block": "minecraft:air"
      },
      {
        "char": "b",
        "block": "minecraft:glass"
      },
      {
        "char": "g",
        "block": "minecraft:vine[east=true,north=false,south=false,up=false,west=false]"
      },
      {
        "char": "d",
        "block": "minecraft:mossy_cobblestone"
      },
      {
        "char": "v",
        "block": "minecraft:stone_brick_stairs[facing=south,half=bottom,shape=straight]"
      },
      {
        "char": "·",
        "block": "minecraft:air"
      },
      {
        "char": "w",
        "block": "minecraft:air"
      },
      {
        "char": "k",
        "block": "minecraft:stone_bricks"
      },
      {
        "char": "j",
        "block": "minecraft:bookshelf"
      },
      {
        "char": "c",
        "block": "minecraft:stone"
      },
      {
        "char": "y",
        "block": "minecraft:mossy_stone_bricks"
      },
      {
        "char": "f",
        "block": "minecraft:vine[east=false,north=true,south=false,up=false,west=false]"
      },
      {
        "char": "a",
        "block": "minecraft:cobblestone"
      },
      {
        "char": "ͻ",
        "block": "minecraft:vine[east=false,north=false,south=false,up=true,west=false]"
      },
      {
        "char": "Ε",
        "block": "minecraft:vine[east=true,north=false,south=false,up=true,west=false]"
      },
      {
        "char": "u",
        "block": "minecraft:stone_brick_slab[type=top]"
      },
      {
        "char": "e",
        "block": "minecraft:smooth_stone_slab[type=double]"
      },
      {
        "char": "Q",
        "block": "minecraft:oak_stairs[facing=west,half=bottom,shape=straight]"
      },
      {
        "char": "G",
        "block": "minecraft:oak_stairs[facing=east,half=bottom,shape=straight]"
      },
      {
        "char": "͵",
        "block": "minecraft:glass_pane[east=true,north=false,south=false,west=true]"
      },
      {
        "char": "Ϙ",
        "block": "minecraft:glass_pane[east=false,north=false,south=false,west=true]"
      },
      {
        "char": "E",
        "block": "minecraft:oak_stairs[facing=south,half=bottom,shape=straight]"
      },
      {
        "char": "K",
        "block": "minecraft:glass_pane[east=false,north=true,south=true,west=false]"
      },
      {
        "char": "ͺ",
        "block": "minecraft:gray_carpet"
      },
      {
        "char": "Δ",
        "block": "minecraft:glass_pane[east=false,north=true,south=false,west=false]"
      },
      {
        "char": "z",
        "block": "minecraft:cracked_stone_bricks"
      }
    ]
  },
  "slices": [
    [
      "     A   b      ",
      "     A  gd      ",
      "     A   bvv    ",
      "     ·wwwdkk    ",
      "       g bkk jj ",
      "       g dkk jj ",
      "       g bjj    ",
      "       g dbcbdbd",
      "        y       ",
      "         ff f   ",
      "                ",
      "                ",
      "                ",
      "                ",
      "                ",
      "                "
    ],
    [
      "         b      ",
      "        ga      ",
      "         b      ",
      "         cvv    ",
      "       g bkk jj ",
      "       g dkk jj ",
      "       g bjj    ",
      "       g abcbdbc",
      "        k       ",
      "         ff f   ",
      "                ",
      "                ",
      "                ",
      "                ",
      "                ",
      "                "
    ],
    [
      "       vͻb      ",
      "        Εa      ",
      "        ͻb      ",
      "        ͻa      ",
      "       g bvv    ",
      "       g dkk    ",
      "       g bjj    ",
      "       g ababdbc",
      "        y       ",
      "         ff f   ",
      "                ",
      "                ",
      "                ",
      "                ",
      "                ",
      "                "
    ],
    [
      "      u eaccaaaa",
      "      uveadacadd",
      "      uuea  dcdc",
      "        ea  dcdc",
      "       gea  dddc",
      "       geavvdcca",
      "       geaddcdcd",
      "       geaaaaaaa",
      "        eeeeeeee",
      "         ff f   ",
      "                ",
      "                ",
      "                ",
      "                ",
      "                ",
      "                "
    ],
    [
      "     A  gb QkkG ",
      "     A   a͵ϘEE  ",
      "     A   b  K   ",
      "     ·wwwa  K   ",
      "       g b  K ͺͺ",
      "       g d  Δ ͺͺ",
      "       g b      ",
      "       g cbabcbd",
      "        z       ",
      "         ff f   ",
      "                ",
      "                ",
      "                ",
      "                ",
      "                ",
      "                "
    ],
    [
      "         b      ",
      "         d      ",
      "         b      ",
      "       g a      ",
      "       g b      ",
      "       g d      ",
      "       g b      ",
      "       g abdbdbc",
      "        y       ",
      "         ff f   ",
      "                ",
      "                ",
      "                ",
      "                ",
      "                ",
      "                "
    ]
  ]
}