{
  "xsize": 16,
  "zsize": 16,
  "palette": {
    "palette": [
      {
        "char": " ",
        "block": "minecraft:air"
      },
      {
        "char": "v",
        "block": "minecraft:stone_brick_stairs[facing=south,half=bottom,shape=straight]"
      },
      {
        "char": "a",
        "block": "minecraft:cobblestone"
      },
      {
        "char": "b",
        "block": "minecraft:glass"
      },
      {
        "char": "d",
        "block": "minecraft:mossy_cobblestone"
      },
      {
        "char": "g",
        "block": "minecraft:vine[east=true,north=false,south=false,up=false,west=false]"
      },
      {
        "char": "c",
        "block": "minecraft:stone"
      },
      {
        "char": "k",
        "block": "minecraft:stone_bricks"
      },
      {
        "char": "j",
        "block": "minecraft:bookshelf"
      },
      {
        "char": "f",
        "block": "minecraft:vine[east=false,north=true,south=false,up=false,west=false]"
      },
      {
        "char": "u",
        "block": "minecraft:stone_brick_slab[type=top]"
      },
      {
        "char": "e",
        "block": "minecraft:smooth_stone_slab[type=double]"
      },
      {
        "char": "A",
        "block": "minecraft:air"
      },
      {
        "char": "L",
        "block": "minecraft:polished_andesite_slab[type=bottom]"
      },
      {
        "char": "͵",
        "block": "minecraft:glass_pane[east=true,north=false,south=false,west=true]"
      },
      {
        "char": "Ϙ",
        "block": "minecraft:glass_pane[east=false,north=false,south=false,west=true]"
      },
      {
        "char": "Μ",
        "block": "minecraft:glass_pane[east=false,north=false,south=true,west=false]"
      },
      {
        "char": "·",
        "block": "minecraft:air"
      },
      {
        "char": "w",
        "block": "minecraft:air"
      },
      {
        "char": "K",
        "block": "minecraft:glass_pane[east=false,north=true,south=true,west=false]"
      },
      {
        "char": "ͺ",
        "block": "minecraft:gray_carpet"
      },
      {
        "char": "Δ",
        "block": "minecraft:glass_pane[east=false,north=true,south=false,west=false]"
      },
      {
        "char": "Ξ",
        "block": "minecraft:vine[east=true,north=false,south=true,up=false,west=false]"
      },
      {
        "char": "z",
        "block": "minecraft:cracked_stone_bricks"
      },
      {
        "char": "h",
        "block": "minecraft:vine[east=false,north=false,south=false,up=false,west=true]"
      },
      {
        "char": "Љ",
        "block": "minecraft:vine[east=true,north=false,south=true,up=true,west=false]"
      },
      {
        "char": "y",
        "block": "minecraft:mossy_stone_bricks"
      },
      {
        "char": "Π",
        "block": "minecraft:vine[east=false,north=false,south=false,up=true,west=true]"
      }
    ]
  },
  "slices": [
    [
      "       v        ",
      "         a      ",
      "         b      ",
      "         d      ",
      "       g bvv    ",
      "       g ckk    ",
      "       g bjj    ",
      "       g cbcbcbd",
      "        k       ",
      "        fffff   ",
      "                ",
      "                ",
      "                ",
      "                ",
      "                ",
      "                "
    ],
    [
      "      u eadcaacc",
      "      uveaadccdd",
      "      uuea  cdac",
      "        ea  acdc",
      "       gea  ccca",
      "       geavvdadc",
      "       geaacccca",
      "       geaaaaaaa",
      "        eeeeeeee",
      "        fffff   ",
      "                ",
      "                ",
      "                ",
      "                ",
      "                ",
      "                "
    ],
    [
      "     A   b L    ",
      "     A   c͵ϘL  b",
      "     A   b  ΜL  ",
      "     ·wwwa  K ͺͺ",
      "       g b  K ͺͺ",
      "       g c  Δ   ",
      "       g b      ",
      "       gΞabdbcbd",
      "        zh      ",
      "        fffff   ",
      "                ",
      "                ",
      "                ",
      "                ",
      "                ",
      "                "
    ],
    [
      "         b      ",
      "         a      ",
      "         b      ",
      "         a      ",
      "       g b      ",
      "       g a      ",
      "       g b      ",
      "       gΞabdbdbc",
      "        zh      ",
      "        fffff   ",
      "                ",
      "                ",
      "                ",
      "                ",
      "                ",
      "                "
    ],
    [
      "       v b      ",
      "         a      ",
      "         b      ",
      "         c      ",
      "       g b      ",
      "       g d      ",
      "       g b      ",
      "       gЉcbcbdbc",
      "        yΠ      ",
      "        fffff   ",
      "                ",
      "                ",
      "                ",
      "                ",
      "                ",
      "                "
    ],
    [
      "      ugeaaaaacd",
      "      uveacccdca",
      "      uueadcddad",
      "        eaccdcaa",
      "       geaaaacad",
      "       geaccacda",
      "       geacadada",
      "       geaaaaaaa",
      "        eeeeeeee",
      "         ffff   ",
      "                ",
      "                ",
      "                ",
      "                ",
      "                ",
      "                "
    ]
  ]
}