{
  "xsize": 16,
  "zsize": 16,
  "palette": {
    "palette": [
      {
        "char": " ",
        "block": "minecraft:air"
      },
      {
        "char": "i",
        "block": "minecraft:vine[east=false,north=false,south=true,up=false,west=false]"
      },
      {
        "char": "g",
        "block": "minecraft:vine[east=true,north=false,south=false,up=false,west=false]"
      },
      {
        "char": "y",
        "block": "minecraft:mossy_stone_bricks"
      },
      {
        "char": "Ί",
        "block": "minecraft:vine[east=false,north=false,south=true,up=false,west=true]"
      },
      {
        "char": "d",
        "block": "minecraft:mossy_cobblestone"
      },
      {
        "char": "b",
        "block": "minecraft:glass"
      },
      {
        "char": "B",
        "block": "minecraft:water"
      },
      {
        "char": "h",
        "block": "minecraft:vine[east=false,north=false,south=false,up=false,west=true]"
      },
      {
        "char": "c",
        "block": "minecraft:stone"
      },
      {
        "char": ";",
        "block": "minecraft:air"
      },
      {
        "char": "w",
        "block": "minecraft:air"
      },
      {
        "char": "A",
        "block": "minecraft:air"
      },
      {
        "char": "a",
        "block": "minecraft:cobblestone"
      },
      {
        "char": "I",
        "block": "minecraft:iron_bars[east=false,north=true,south=true,west=false]"
      },
      {
        "char": "v",
        "block": "minecraft:stone_brick_stairs[facing=south,half=bottom,shape=straight]"
      },
      {
        "char": "k",
        "block": "minecraft:stone_bricks"
      },
      {
        "char": "F",
        "block": "minecraft:redstone_lamp[lit=false]"
      },
      {
        "char": "z",
        "block": "minecraft:cracked_stone_bricks"
      },
      {
        "char": "e",
        "block": "minecraft:smooth_stone_slab[type=double]"
      },
      {
        "char": "u",
        "block": "minecraft:stone_brick_slab[type=top]"
      },
      {
        "char": "M",
        "block": "minecraft:cobblestone_slab[type=bottom]"
      },
      {
        "char": "ΐ",
        "block": "minecraft:vine[east=true,north=true,south=false,up=false,west=false]"
      },
      {
        "char": "j",
        "block": "minecraft:bookshelf"
      },
      {
        "char": "H",
        "block": "minecraft:oak_stairs[facing=north,half=bottom,shape=straight]"
      },
      {
        "char": "Q",
        "block": "minecraft:oak_stairs[facing=west,half=bottom,shape=straight]"
      },
      {
        "char": "G",
        "block": "minecraft:oak_stairs[facing=east,half=bottom,shape=straight]"
      },
      {
        "char": "f",
        "block": "minecraft:vine[east=false,north=true,south=false,up=false,west=false]"
      },
      {
        "char": "U",
        "block": "minecraft:flower_pot"
      }
    ]
  },
  "slices": [
    [
      "                ",
      "                ",
      "                ",
      "                ",
      "                ",
      "                ",
      "                ",
      "        i  iiiii",
      "       gyΊ      ",
      "       g dbdb   ",
      "       g bBb h  ",
      "         cb     ",
      "     ;wwwb      ",
      "     A   a      ",
      "     I v b      ",
      "     A   c      "
    ],
    [
      "                ",
      "                ",
      "                ",
      "                ",
      "                ",
      "                ",
      "                ",
      "        i  iiiii",
      "       gkΊ      ",
      "       g abab   ",
      "       g bBF h  ",
      "         cF     ",
      "         b      ",
      "         d      ",
      "         b      ",
      "       v d      "
    ],
    [
      "                ",
      "                ",
      "                ",
      "                ",
      "                ",
      "                ",
      "                ",
      "        i  iiiii",
      "       gzΊ      ",
      "       g abab   ",
      "       g bBb h  ",
      "         db     ",
      "         b      ",
      "         d      ",
      "         b      ",
      "         c      "
    ],
    [
      "                ",
      "                ",
      "                ",
      "                ",
      "                ",
      "                ",
      "                ",
      "        i  iiiii",
      "       geΊ eee  ",
      "       geaaaaaa ",
      "       geaBbdh  ",
      "        eabaa   ",
      "        eacdcd  ",
      "      uueacdcddM",
      "      u eadcdcac",
      "      u eaaacccd"
    ],
    [
      "                ",
      "                ",
      "                ",
      "                ",
      "                ",
      "                ",
      "                ",
      "        i  iiiii",
      "       gyΊ      ",
      "       gΐababd  ",
      "       g bBbj   ",
      "         abj    ",
      "     ;wwwbj     ",
      "     I   a      ",
      "     I v b HH   ",
      "     A   dQkkG  "
    ],
    [
      "                ",
      "                ",
      "                ",
      "                ",
      "                ",
      "                ",
      "                ",
      "        i  iiiii",
      "       gzΊ      ",
      "       gfdbaba  ",
      "       g bBbj   ",
      "         abj    ",
      "         bj     ",
      "         d      ",
      "         b      ",
      "       v a U    "
    ]
  ]
}