{
  "xsize": 16,
  "zsize": 16,
  "palette": {
    "palette": [
      {
        "char": " ",
        "block": "minecraft:air"
      },
      {
        "char": "v",
        "block": "minecraft:stone_brick_stairs[facing=south,half=bottom,shape=straight]"
      },
      {
        "char": "b",
        "block": "minecraft:glass"
      },
      {
        "char": "a",
        "block": "minecraft:cobblestone"
      },
      {
        "char": "d",
        "block": "minecraft:mossy_cobblestone"
      },
      {
        "char": "g",
        "block": "minecraft:vine[east=true,north=false,south=false,up=false,west=false]"
      },
      {
        "char": "c",
        "block": "minecraft:stone"
      },
      {
        "char": "k",
        "block": "minecraft:stone_bricks"
      },
      {
        "char": "f",
        "block": "minecraft:vine[east=false,north=true,south=false,up=false,west=false]"
      },
      {
        "char": "u",
        "block": "minecraft:stone_brick_slab[type=top]"
      },
      {
        "char": "e",
        "block": "minecraft:smooth_stone_slab[type=double]"
      },
      {
        "char": "I",
        "block": "minecraft:iron_bars[east=false,north=true,south=true,west=false]"
      },
      {
        "char": "Κ",
        "block": "minecraft:iron_bars[east=true,north=true,south=false,west=false]"
      },
      {
        "char": "N",
        "block": "minecraft:iron_bars[east=true,north=false,south=false,west=true]"
      },
      {
        "char": "w",
        "block": "minecraft:air"
      },
      {
        "char": "H",
        "block": "minecraft:oak_stairs[facing=north,half=bottom,shape=straight]"
      },
      {
        "char": "Q",
        "block": "minecraft:oak_stairs[facing=west,half=bottom,shape=straight]"
      },
      {
        "char": "E",
        "block": "minecraft:oak_stairs[facing=south,half=bottom,shape=straight]"
      },
      {
        "char": "z",
        "block": "minecraft:cracked_stone_bricks"
      }
    ]
  },
  "slices": [
    [
      "       v b      ",
      "         a      ",
      "         b      ",
      "         d      ",
      "       g b      ",
      "       g c      ",
      "       g b      ",
      "       g dbdbaba",
      "        k       ",
      "        fffff  f",
      "                ",
      "                ",
      "                ",
      "                ",
      "                ",
      "                "
    ],
    [
      "      u eaacdcda",
      "      uveacaddcc",
      "      uueacdacaa",
      "        eadddaad",
      "       geadcdada",
      "       geacccaca",
      "       geaacadda",
      "       geaaaaaaa",
      "        eeeeeeee",
      "        fffff  f",
      "                ",
      "                ",
      "                ",
      "                ",
      "                ",
      "                "
    ],
    [
      "     I   b      ",
      "     I   d      ",
      "     I   bvv    ",
      "     ΚNNwdkk   H",
      "       g bkk  Qk",
      "       g dkk  Qk",
      "       g b     E",
      "       g dbdbabc",
      "        z       ",
      "        fffff   ",
      "                ",
      "                ",
      "                ",
      "                ",
      "                ",
      "                "
    ],
    [
      "         b      ",
      "         d      ",
      "         b      ",
      "         dvv    ",
      "       g bkk    ",
      "       g dkk    ",
      "       g b      ",
      "       g abcbaba",
      "        z       ",
      "        fffff   ",
      "                ",
      "                ",
      "                ",
      "                ",
      "                ",
      "                "
    ],
    [
      "       v b      ",
      "         a      ",
      "         b      ",
      "         a      ",
      "       g bvv    ",
      "       g dkk    ",
      "       g b      ",
      "       g abdbcbd",
      "        k       ",
      "        fffff   ",
      "                ",
      "                ",
      "                ",
      "                ",
      "                ",
      "                "
    ],
    [
      "      ugeacdcadc",
      "      uveaddadca",
      "      uuea  ccca",
      "        ea  cdda",
      "       gea  dcda",
      "       geavvddad",
      "       geaacdadd",
      "       geaaaaaaa",
      "        eeeeeeee",
      "        fffff   ",
      "                ",
      "                ",
      "                ",
      "                ",
      "                ",
      "                "
    ]
  ]
}