{
  "xsize": 16,
  "zsize": 16,
  "palette": {
    "palette": [
      {
        "char": " ",
        "block": "minecraft:air"
      },
      {
        "char": "i",
        "block": "minecraft:vine[east=false,north=false,south=true,up=false,west=false]"
      },
      {
        "char": "g",
        "block": "minecraft:vine[east=true,north=false,south=false,up=false,west=false]"
      },
      {
        "char": "k",
        "block": "minecraft:stone_bricks"
      },
      {
        "char": "d",
        "block": "minecraft:mossy_cobblestone"
      },
      {
        "char": "b",
        "block": "minecraft:glass"
      },
      {
        "char": "c",
        "block": "minecraft:stone"
      },
      {
        "char": "B",
        "block": "minecraft:water"
      },
      {
        "char": "e",
        "block": "minecraft:smooth_stone_slab[type=double]"
      },
      {
        "char": "a",
        "block": "minecraft:cobblestone"
      },
      {
        "char": "u",
        "block": "minecraft:stone_brick_slab[type=top]"
      },
      {
        "char": "z",
        "block": "minecraft:cracked_stone_bricks"
      },
      {
        "char": "h",
        "block": "minecraft:vine[east=false,north=false,south=false,up=false,west=true]"
      },
      {
        "char": "M",
        "block": "minecraft:cobblestone_slab[type=bottom]"
      },
      {
        "char": ";",
        "block": "minecraft:air"
      },
      {
        "char": "N",
        "block": "minecraft:iron_bars[east=true,north=false,south=false,west=true]"
      },
      {
        "char": "w",
        "block": "minecraft:air"
      },
      {
        "char": "I",
        "block": "minecraft:iron_bars[east=false,north=true,south=true,west=false]"
      },
      {
        "char": "v",
        "block": "minecraft:stone_brick_stairs[facing=south,half=bottom,shape=straight]"
      },
      {
        "char": "A",
        "block": "minecraft:air"
      },
      {
        "char": "f",
        "block": "minecraft:vine[east=false,north=true,south=false,up=false,west=false]"
      }
    ]
  },
  "slices": [
    [
      "                ",
      "                ",
      "                ",
      "                ",
      "                ",
      "                ",
      "                ",
      "        i  iiiii",
      "       gk       ",
      "       g dbcbdbd",
      "       g bBb    ",
      "         cb     ",
      "         b      ",
      "         c g    ",
      "         b      ",
      "         c      "
    ],
    [
      "                ",
      "                ",
      "                ",
      "                ",
      "                ",
      "                ",
      "                ",
      "        i  iiiii",
      "       geeeeeeee",
      "       geaaaaaaa",
      "       geaBbaddc",
      "        eabaadac",
      "        eacaaadd",
      "      uueacgcdca",
      "      u ea   daa",
      "      u eaa   c "
    ],
    [
      "                ",
      "                ",
      "                ",
      "                ",
      "                ",
      "                ",
      "                ",
      "        i  iiiii",
      "       gzh      ",
      "       g cbdbdbc",
      "       g bBb hdM",
      "         db  a  ",
      "     ;NNwb    M ",
      "     I   d    h ",
      "     I v b    d ",
      "     A   a      "
    ],
    [
      "                ",
      "                ",
      "                ",
      "                ",
      "                ",
      "                ",
      "                ",
      "        i  iiiii",
      "       gzh      ",
      "       g cbababa",
      "       g bBb hf ",
      "         db     ",
      "         b      ",
      "         d    h ",
      "         b      ",
      "       v d      "
    ],
    [
      "                ",
      "                ",
      "                ",
      "                ",
      "                ",
      "                ",
      "                ",
      "        i  iiiii",
      "       gz       ",
      "       g cbdbcbc",
      "       g bBb hf ",
      "         db     ",
      "         b      ",
      "         c    h ",
      "         b      ",
      "         a      "
    ],
    [
      "                ",
      "                ",
      "                ",
      "                ",
      "                ",
      "                ",
      "                ",
      "        i  iiiii",
      "       geeeeeee ",
      "       geaaaa aM",
      "       geaBbahf ",
      "        eaba    ",
      "        eaada   ",
      "      uueacccdh ",
      "      u eaaacdac",
      "      u eaacccdd"
    ]
  ]
}