{
  "xsize": 16,
  "zsize": 16,
  "palette": {
    "palette": [
      {
        "char": " ",
        "block": "minecraft:air"
      },
      {
        "char": "H",
        "block": "minecraft:oak_stairs[facing=north,half=bottom,shape=straight]"
      },
      {
        "char": "З",
        "block": "minecraft:oak_stairs[facing=east,half=bottom,shape=inner_left]"
      },
      {
        "char": "b",
        "block": "minecraft:glass"
      },
      {
        "char": "h",
        "block": "minecraft:vine[east=false,north=false,south=false,up=false,west=true]"
      },
      {
        "char": "G",
        "block": "minecraft:oak_stairs[facing=east,half=bottom,shape=straight]"
      },
      {
        "char": "c",
        "block": "minecraft:stone"
      },
      {
        "char": "k",
        "block": "minecraft:stone_bricks"
      },
      {
        "char": "Q",
        "block": "minecraft:oak_stairs[facing=west,half=bottom,shape=straight]"
      },
      {
        "char": "d",
        "block": "minecraft:mossy_cobblestone"
      },
      {
        "char": "Ъ",
        "block": "minecraft:oak_stairs[facing=south,half=bottom,shape=inner_right]"
      },
      {
        "char": "E",
        "block": "minecraft:oak_stairs[facing=south,half=bottom,shape=straight]"
      },
      {
        "char": "F",
        "block": "minecraft:redstone_lamp[lit=false]"
      },
      {
        "char": "a",
        "block": "minecraft:cobblestone"
      },
      {
        "char": "y",
        "block": "minecraft:mossy_stone_bricks"
      },
      {
        "char": "f",
        "block": "minecraft:vine[east=false,north=true,south=false,up=false,west=false]"
      },
      {
        "char": "U",
        "block": "minecraft:flower_pot"
      },
      {
        "char": "z",
        "block": "minecraft:cracked_stone_bricks"
      },
      {
        "char": "e",
        "block": "minecraft:smooth_stone_slab[type=double]"
      },
      {
        "char": "ϻ",
        "block": "minecraft:oak_stairs[facing=north,half=bottom,shape=inner_right]"
      },
      {
        "char": "ύ",
        "block": "minecraft:oak_stairs[facing=west,half=bottom,shape=inner_left]"
      }
    ]
  },
  "slices": [
    [
      "   HHHЗb h      ",
      "      Gc        ",
      "  kkk Gb        ",
      "Q kkk Gd        ",
      "Q kkk Gb        ",
      "Q     Gc        ",
      "ЪEEEEEFb        ",
      "bababdba h      ",
      "        yh      ",
      " fff ffff       ",
      "                ",
      "                ",
      "                ",
      "                ",
      "                ",
      "                "
    ],
    [
      "       b h      ",
      "       d        ",
      "  U U  b        ",
      "       d        ",
      "  U    b        ",
      "       d        ",
      "      Fb        ",
      "babababd h      ",
      "        kh      ",
      " fff ffff       ",
      "                ",
      "                ",
      "                ",
      "                ",
      "                ",
      "                "
    ],
    [
      "       b h      ",
      "       a        ",
      "       b        ",
      "       c        ",
      "       b        ",
      "       a        ",
      "      Fb        ",
      "bdbabdbc h      ",
      "        zh      ",
      " fff ffff       ",
      "                ",
      "                ",
      "                ",
      "                ",
      "                ",
      "                "
    ],
    [
      "accdcacaeh      ",
      "aaacadaae       ",
      "caadcdcae       ",
      "accaaadae       ",
      "dacdadaae       ",
      "cacaddcae       ",
      "ddcadacae       ",
      "aaaaaaaaeh      ",
      "eeeeeeeeeh      ",
      " fff ffff       ",
      "                ",
      "                ",
      "                ",
      "                ",
      "                ",
      "                "
    ],
    [
      "  HH   b h      ",
      " QkkG  ch       ",
      " QkkG  b        ",
      "  EE  ϻd        ",
      "      Gb        ",
      "      Ga        ",
      "   ύEEFb        ",
      "babdbcbc h      ",
      "        zh      ",
      " fff    f       ",
      "                ",
      "                ",
      "                ",
      "                ",
      "                ",
      "                "
    ],
    [
      "       b h      ",
      "   U   ch       ",
      "       b        ",
      "       c        ",
      "       b        ",
      "       d        ",
      "      Fb        ",
      "bcbdbabd h      ",
      "        zh      ",
      " fff    f       ",
      "                ",
      "                ",
      "                ",
      "                ",
      "                ",
      "                "
    ]
  ]
}