{
  "xsize": 16,
  "zsize": 16,
  "palette": {
    "palette": [
      {
        "char": " ",
        "block": "minecraft:air"
      },
      {
        "char": "i",
        "block": "minecraft:vine[east=false,north=false,south=true,up=false,west=false]"
      },
      {
        "char": "g",
        "block": "minecraft:vine[east=true,north=false,south=false,up=false,west=false]"
      },
      {
        "char": "z",
        "block": "minecraft:cracked_stone_bricks"
      },
      {
        "char": "d",
        "block": "minecraft:mossy_cobblestone"
      },
      {
        "char": "b",
        "block": "minecraft:glass"
      },
      {
        "char": "c",
        "block": "minecraft:stone"
      },
      {
        "char": "B",
        "block": "minecraft:water"
      },
      {
        "char": "j",
        "block": "minecraft:bookshelf"
      },
      {
        "char": "a",
        "block": "minecraft:cobblestone"
      },
      {
        "char": ";",
        "block": "minecraft:air"
      },
      {
        "char": "w",
        "block": "minecraft:air"
      },
      {
        "char": "N",
        "block": "minecraft:iron_bars[east=true,north=false,south=false,west=true]"
      },
      {
        "char": "A",
        "block": "minecraft:air"
      },
      {
        "char": "΄",
        "block": "minecraft:green_carpet"
      },
      {
        "char": "v",
        "block": "minecraft:stone_brick_stairs[facing=south,half=bottom,shape=straight]"
      },
      {
        "char": "y",
        "block": "minecraft:mossy_stone_bricks"
      },
      {
        "char": "e",
        "block": "minecraft:smooth_stone_slab[type=double]"
      },
      {
        "char": "u",
        "block": "minecraft:stone_brick_slab[type=top]"
      },
      {
        "char": "k",
        "block": "minecraft:stone_bricks"
      },
      {
        "char": "Q",
        "block": "minecraft:oak_stairs[facing=west,half=bottom,shape=straight]"
      },
      {
        "char": "H",
        "block": "minecraft:oak_stairs[facing=north,half=bottom,shape=straight]"
      },
      {
        "char": "G",
        "block": "minecraft:oak_stairs[facing=east,half=bottom,shape=straight]"
      },
      {
        "char": "U",
        "block": "minecraft:flower_pot"
      }
    ]
  },
  "slices": [
    [
      "                ",
      "                ",
      "                ",
      "                ",
      "                ",
      "                ",
      "                ",
      "        i       ",
      "       gz       ",
      "       g dbcbdbc",
      "       g bBbj   ",
      "         abj    ",
      "     ;wNwbj   jj",
      "     A   d    ΄΄",
      "     A v b    ΄΄",
      "     A   c    jj"
    ],
    [
      "                ",
      "                ",
      "                ",
      "                ",
      "                ",
      "                ",
      "                ",
      "        i       ",
      "       gy       ",
      "       g cbcbaba",
      "       g bBbj   ",
      "         dbj    ",
      "         bj   jj",
      "         c      ",
      "         b      ",
      "       v d    jj"
    ],
    [
      "                ",
      "                ",
      "                ",
      "                ",
      "                ",
      "                ",
      "                ",
      "        i       ",
      "       gz       ",
      "       g abcbabd",
      "       g bBb    ",
      "         cb     ",
      "         b      ",
      "         d      ",
      "         b      ",
      "         a      "
    ],
    [
      "                ",
      "                ",
      "                ",
      "                ",
      "                ",
      "                ",
      "                ",
      "        i       ",
      "       geeeeeeee",
      "       geaaaaaaa",
      "       geaBbddcc",
      "        eabddcda",
      "        eaaadaaa",
      "      uueaccaadc",
      "      u eaddaacc",
      "      u eadacccd"
    ],
    [
      "                ",
      "                ",
      "                ",
      "                ",
      "                ",
      "                ",
      "                ",
      "        i       ",
      "       gk       ",
      "       g cbdbcbd",
      "       g bBbj   ",
      "         abj    ",
      "     ;wwwbj    Q",
      "     A   d     Q",
      "     A vgb  HH  ",
      "     A  gc QkkG "
    ],
    [
      "                ",
      "                ",
      "                ",
      "                ",
      "                ",
      "                ",
      "                ",
      "        i       ",
      "       gy       ",
      "       g dbdbcba",
      "       g bBbj   ",
      "         cbj    ",
      "         bj     ",
      "         d      ",
      "         b      ",
      "       vgc   U  "
    ]
  ]
}