{
  "xsize": 16,
  "zsize": 16,
  "palette": {
    "palette": [
      {
        "char": " ",
        "block": "minecraft:air"
      },
      {
        "char": "i",
        "block": "minecraft:vine[east=false,north=false,south=true,up=false,west=false]"
      },
      {
        "char": "y",
        "block": "minecraft:mossy_stone_bricks"
      },
      {
        "char": "h",
        "block": "minecraft:vine[east=false,north=false,south=false,up=false,west=true]"
      },
      {
        "char": "d",
        "block": "minecraft:mossy_cobblestone"
      },
      {
        "char": "b",
        "block": "minecraft:glass"
      },
      {
        "char": "a",
        "block": "minecraft:cobblestone"
      },
      {
        "char": "Π",
        "block": "minecraft:vine[east=false,north=false,south=false,up=true,west=true]"
      },
      {
        "char": "k",
        "block": "minecraft:stone_bricks"
      },
      {
        "char": "c",
        "block": "minecraft:stone"
      },
      {
        "char": "C",
        "block": "minecraft:stone_brick_stairs[facing=north,half=bottom,shape=straight]"
      },
      {
        "char": "j",
        "block": "minecraft:bookshelf"
      },
      {
        "char": "e",
        "block": "minecraft:smooth_stone_slab[type=double]"
      },
      {
        "char": "H",
        "block": "minecraft:oak_stairs[facing=north,half=bottom,shape=straight]"
      },
      {
        "char": "G",
        "block": "minecraft:oak_stairs[facing=east,half=bottom,shape=straight]"
      },
      {
        "char": "Μ",
        "block": "minecraft:glass_pane[east=false,north=false,south=true,west=false]"
      },
      {
        "char": "K",
        "block": "minecraft:glass_pane[east=false,north=true,south=true,west=false]"
      },
      {
        "char": "E",
        "block": "minecraft:oak_stairs[facing=south,half=bottom,shape=straight]"
      },
      {
        "char": "Χ",
        "block": "minecraft:glass_pane[east=true,north=true,south=false,west=false]"
      },
      {
        "char": "͵",
        "block": "minecraft:glass_pane[east=true,north=false,south=false,west=true]"
      },
      {
        "char": "z",
        "block": "minecraft:cracked_stone_bricks"
      },
      {
        "char": "ͻ",
        "block": "minecraft:vine[east=false,north=false,south=false,up=true,west=false]"
      }
    ]
  },
  "slices": [
    [
      "                ",
      "                ",
      "                ",
      "                ",
      "                ",
      "                ",
      "                ",
      "   iii  i       ",
      "        yh      ",
      "   dbdbaΠ       ",
      "       b        ",
      "     kkc        ",
      "     CCb h      ",
      "     j d h      ",
      "       b h      ",
      "       d        "
    ],
    [
      "                ",
      "                ",
      "                ",
      "                ",
      "                ",
      "                ",
      "                ",
      "   iii  i       ",
      "eeeeeeeeeh      ",
      "aaaaaaaae       ",
      "addaddaae       ",
      "aadadCCae       ",
      "acacd  aeh      ",
      "cdccd  aeh      ",
      "dccdc  aeh      ",
      "aadcaadae       "
    ],
    [
      "                ",
      "                ",
      "                ",
      "                ",
      "                ",
      "                ",
      "                ",
      "   iii  i       ",
      "        kh      ",
      "bcba dbd        ",
      "H      b        ",
      "kG  Μ  c        ",
      "kG  K  b h      ",
      "E   K  c h      ",
      "    K  b h      ",
      "    Χ͵͵ah       "
    ],
    [
      "                ",
      "                ",
      "                ",
      "                ",
      "                ",
      "                ",
      "                ",
      "   iii  i       ",
      "        kh      ",
      "bcbabdbd        ",
      "       b        ",
      "       c        ",
      "       b h      ",
      "       d h      ",
      "       b h      ",
      "       ah       "
    ],
    [
      "                ",
      "                ",
      "                ",
      "                ",
      "                ",
      "                ",
      "                ",
      "   iii  i       ",
      "        zh      ",
      "babababa        ",
      "       b        ",
      "       d        ",
      "       b h      ",
      "       c h      ",
      "       bͻh      ",
      "       aΠ       "
    ],
    [
      "                ",
      "                ",
      "                ",
      "                ",
      "                ",
      "                ",
      "                ",
      "   iii  i       ",
      "eeeeeeeeeh      ",
      "aaaaaaaae       ",
      "cadacddae       ",
      "cdaacadae       ",
      "daacaaaaeh      ",
      "aaacacaaeh      ",
      "ccaadccaeh      ",
      "ddcdacaae       "
    ]
  ]
}