{
  "xsize": 16,
  "zsize": 16,
  "palette": {
    "palette": [
      {
        "char": " ",
        "block": "minecraft:air"
      },
      {
        "char": "ξ",
        "block": "minecraft:oak_trapdoor[facing=north,half=bottom,open=true]"
      },
      {
        "char": "i",
        "block": "minecraft:vine[east=false,north=false,south=true,up=false,west=false]"
      },
      {
        "char": "ρ",
        "block": "minecraft:oak_trapdoor[facing=west,half=top,open=true]"
      },
      {
        "char": "F",
        "block": "minecraft:redstone_lamp[lit=false]"
      },
      {
        "char": "Ь",
        "block": "minecraft:air"
      },
      {
        "char": "g",
        "block": "minecraft:vine[east=true,north=false,south=false,up=false,west=false]"
      },
      {
        "char": "k",
        "block": "minecraft:stone_bricks"
      },
      {
        "char": "κ",
        "block": "minecraft:oak_trapdoor[facing=south,half=top,open=true]"
      },
      {
        "char": "d",
        "block": "minecraft:mossy_cobblestone"
      },
      {
        "char": "b",
        "block": "minecraft:glass"
      },
      {
        "char": "c",
        "block": "minecraft:stone"
      },
      {
        "char": "a",
        "block": "minecraft:cobblestone"
      },
      {
        "char": "B",
        "block": "minecraft:water"
      },
      {
        "char": "j",
        "block": "minecraft:bookshelf"
      },
      {
        "char": "H",
        "block": "minecraft:oak_stairs[facing=north,half=bottom,shape=straight]"
      },
      {
        "char": "χ",
        "block": "minecraft:iron_bars[east=true,north=false,south=true,west=false]"
      },
      {
        "char": "N",
        "block": "minecraft:iron_bars[east=true,north=false,south=false,west=true]"
      },
      {
        "char": "Q",
        "block": "minecraft:oak_stairs[facing=west,half=bottom,shape=straight]"
      },
      {
        "char": "A",
        "block": "minecraft:air"
      },
      {
        "char": "I",
        "block": "minecraft:iron_bars[east=false,north=true,south=true,west=false]"
      },
      {
        "char": "v",
        "block": "minecraft:stone_brick_stairs[facing=south,half=bottom,shape=straight]"
      },
      {
        "char": "E",
        "block": "minecraft:oak_stairs[facing=south,half=bottom,shape=straight]"
      },
      {
        "char": "ε",
        "block": "minecraft:stone_brick_stairs[facing=north,half=top,shape=straight]"
      },
      {
        "char": "z",
        "block": "minecraft:cracked_stone_bricks"
      },
      {
        "char": "U",
        "block": "minecraft:flower_pot"
      },
      {
        "char": "e",
        "block": "minecraft:smooth_stone_slab[type=double]"
      },
      {
        "char": "u",
        "block": "minecraft:stone_brick_slab[type=top]"
      }
    ]
  },
  "slices": [
    [
      "                ",
      "                ",
      "                ",
      "                ",
      "                ",
      "                ",
      "                ",
      "   ξ    i  iiiii",
      "  ρFЬ  gk       ",
      "   κ   g dbcbabc",
      "       g bBbj   ",
      "       g abj   H",
      "     χNNNbj   Qk",
      "     A   d    Qk",
      "     I v b jj  E",
      "     I ε d jj   "
    ],
    [
      "                ",
      "                ",
      "                ",
      "                ",
      "                ",
      "                ",
      "                ",
      "        i  iiiii",
      "       gz       ",
      "       g abcbcbd",
      "       g bBbj   ",
      "       g abj    ",
      "         bj    U",
      "         a      ",
      "         b jj   ",
      "       v c jj   "
    ],
    [
      "                ",
      "                ",
      "                ",
      "                ",
      "                ",
      "                ",
      "                ",
      "        i  iiiii",
      "       gz       ",
      "       g cbabdba",
      "       g bBb    ",
      "       g db     ",
      "         b      ",
      "         a      ",
      "         b      ",
      "         c      "
    ],
    [
      "                ",
      "                ",
      "                ",
      "                ",
      "                ",
      "                ",
      "                ",
      "        i  iiiii",
      "       geeeeeeee",
      "       geaaaaaaa",
      "       geaBbcdad",
      "       geabccaad",
      "        eacaddcc",
      "      uueacdadca",
      "      u eacdcdad",
      "      u eacdaddd"
    ],
    [
      "                ",
      "                ",
      "                ",
      "                ",
      "                ",
      "                ",
      "                ",
      "        i  iiiii",
      "       gz       ",
      "       g ababcbd",
      "       g bBbj   ",
      "         dbj    ",
      "     χNNNbj     ",
      "     I   a g  HH",
      "     I v b   Qkk",
      "     I   c   Qkk"
    ],
    [
      "                ",
      "                ",
      "                ",
      "                ",
      "                ",
      "                ",
      "                ",
      "        i  iiiii",
      "       gk       ",
      "       g abcbcbc",
      "       g bBbj   ",
      "         dbj    ",
      "         bj     ",
      "         c g    ",
      "         b      ",
      "       v d     U"
    ]
  ]
}