{
  "xsize": 16,
  "zsize": 16,
  "palette": {
    "palette": [
      {
        "char": " ",
        "block": "minecraft:air"
      },
      {
        "char": "e",
        "block": "minecraft:polished_andesite"
      },
      {
        "char": "a",
        "block": "minecraft:stone_bricks"
      },
      {
        "char": "ф",
        "block": "minecraft:polished_andesite_slab[type=bottom]"
      },
      {
        "char": "c",
        "block": "minecraft:bricks"
      },
      {
        "char": "j",
        "block": "minecraft:air"
      },
      {
        "char": "Ѻ",
        "block": "minecraft:air"
      },
      {
        "char": "х",
        "block": "minecraft:air"
      },
      {
        "char": "g",
        "block": "minecraft:air"
      },
      {
        "char": "f",
        "block": "minecraft:stone"
      },
      {
        "char": "l",
        "block": "minecraft:andesite"
      },
      {
        "char": "Ы",
        "block": "minecraft:smooth_stone"
      },
      {
        "char": "H",
        "block": "minecraft:smooth_stone_slab[type=top]"
      },
      {
        "char": "y",
        "block": "minecraft:polished_andesite_slab[type=top]"
      },
      {
        "char": "C",
        "block": "minecraft:air"
      },
      {
        "char": "b",
        "block": "minecraft:cracked_stone_bricks"
      },
      {
        "char": "е",
        "block": "minecraft:air"
      },
      {
        "char": "u",
        "block": "minecraft:stone_bricks"
      },
      {
        "char": "E",
        "block": "minecraft:smooth_stone_slab[type=bottom]"
      },
      {
        "char": "v",
        "block": "minecraft:bricks"
      },
      {
        "char": "Э",
        "block": "minecraft:air"
      },
      {
        "char": "m",
        "block": "minecraft:grass_block[snowy=false]"
      },
      {
        "char": "B",
        "block": "minecraft:dead_brain_coral_block"
      },
      {
        "char": "A",
        "block": "minecraft:dead_fire_coral_block"
      },
      {
        "char": "z",
        "block": "minecraft:dead_bubble_coral_block"
      },
      {
        "char": "i",
        "block": "minecraft:air"
      },
      {
        "char": "R",
        "block": "minecraft:cobblestone"
      },
      {
        "char": "Ҷ",
        "block": "minecraft:stone"
      },
      {
        "char": "p",
        "block": "minecraft:air"
      },
      {
        "char": "я",
        "block": "minecraft:air"
      },
      {
        "char": "G",
        "block": "minecraft:air"
      },
      {
        "char": "с",
        "block": "minecraft:air"
      },
      {
        "char": "w",
        "block": "minecraft:air"
      },
      {
        "char": "N",
        "block": "minecraft:stone_slab[type=bottom]"
      },
      {
        "char": "р",
        "block": "minecraft:spruce_fence"
      },
      {
        "char": "o",
        "block": "minecraft:air"
      },
      {
        "char": "P",
        "block": "minecraft:air"
      },
      {
        "char": "h",
        "block": "minecraft:oak_leaves"
      }
    ]
  },
  "slices": [
    [
      "eeeeaф          ",
      "cjjeѺх          ",
      "ggjefф          ",
      "jcglЫH          ",
      "cggeay          ",
      "cggeaC          ",
      "cjclbC          ",
      "gccefе          ",
      "ccglѺф          ",
      "eleeuE          ",
      "gjclѺф          ",
      "cggeЫх          ",
      "vcgebх          ",
      "cjclaC          ",
      "gggeЫy          ",
      "cggefy          "
    ],
    [
      "cgclЭ           ",
      "mmmv            ",
      "BAmc            ",
      "mfmg            ",
      "zAmjхi          ",
      "mmmcх           ",
      "Rmmg i          ",
      "fBBci           ",
      "Bffv            ",
      "BAfe            ",
      "fҶmvi           ",
      "zmmvЭ           ",
      "mmmcp           ",
      "mmmgеi          ",
      "mmmjф           ",
      "mmmjхi          "
    ],
    [
      "яiяep           ",
      "GGGс            ",
      "EEGс            ",
      "wEwсp           ",
      "NEwс            ",
      "wwwi            ",
      "рwwс            ",
      "  iс            ",
      "  рсp           ",
      "  oep           ",
      " iwс            ",
      " wwi            ",
      "wwGi            ",
      "wGGсp           ",
      "GwGсp           ",
      "wGwсp           "
    ],
    [
      "   i            ",
      "P P             ",
      "  P             ",
      "                ",
      "                ",
      "                ",
      "h               ",
      "                ",
      "  h             ",
      "   i            ",
      "                ",
      "                ",
      "  P             ",
      " PP             ",
      "P P             ",
      " P              "
    ],
    [
      "                ",
      "                ",
      "                ",
      "                ",
      "                ",
      "                ",
      "h               ",
      "                ",
      "  h             ",
      "                ",
      "                ",
      "                ",
      "                ",
      "                ",
      "                ",
      "                "
    ],
    [
      "                ",
      "                ",
      "                ",
      "                ",
      "                ",
      "                ",
      "                ",
      "                ",
      "  h             ",
      "                ",
      "                ",
      "                ",
      "                ",
      "                ",
      "                ",
      "                "
    ]
  ]
}