{
  "xsize": 16,
  "zsize": 16,
  "palette": {
    "palette": [
      {
        "char": " ",
        "block": "minecraft:air"
      },
      {
        "char": "l",
        "block": "minecraft:andesite"
      },
      {
        "char": "j",
        "block": "minecraft:air"
      },
      {
        "char": "c",
        "block": "minecraft:bricks"
      },
      {
        "char": "v",
        "block": "minecraft:bricks"
      },
      {
        "char": "g",
        "block": "minecraft:air"
      },
      {
        "char": "n",
        "block": "minecraft:air"
      },
      {
        "char": "e",
        "block": "minecraft:polished_andesite"
      },
      {
        "char": "q",
        "block": "minecraft:air"
      },
      {
        "char": "m",
        "block": "minecraft:grass_block[snowy=false]"
      },
      {
        "char": "B",
        "block": "minecraft:dead_brain_coral_block"
      },
      {
        "char": "z",
        "block": "minecraft:dead_bubble_coral_block"
      },
      {
        "char": "R",
        "block": "minecraft:cobblestone"
      },
      {
        "char": "f",
        "block": "minecraft:stone"
      },
      {
        "char": "o",
        "block": "minecraft:air"
      },
      {
        "char": "Ҷ",
        "block": "minecraft:stone"
      },
      {
        "char": "A",
        "block": "minecraft:dead_fire_coral_block"
      },
      {
        "char": "情",
        "block": "minecraft:cobblestone"
      },
      {
        "char": "з",
        "block": "minecraft:air"
      },
      {
        "char": "w",
        "block": "minecraft:air"
      },
      {
        "char": "G",
        "block": "minecraft:air"
      },
      {
        "char": "E",
        "block": "minecraft:smooth_stone_slab[type=bottom]"
      },
      {
        "char": "N",
        "block": "minecraft:stone_slab[type=bottom]"
      },
      {
        "char": "i",
        "block": "minecraft:air"
      },
      {
        "char": "я",
        "block": "minecraft:air"
      },
      {
        "char": "棒",
        "block": "minecraft:stone_slab[type=bottom]"
      },
      {
        "char": "р",
        "block": "minecraft:spruce_fence"
      },
      {
        "char": "Q",
        "block": "minecraft:air"
      },
      {
        "char": "и",
        "block": "minecraft:air"
      },
      {
        "char": "P",
        "block": "minecraft:air"
      },
      {
        "char": "h",
        "block": "minecraft:oak_leaves"
      },
      {
        "char": "Ӝ",
        "block": "minecraft:air"
      },
      {
        "char": "Ӛ",
        "block": "minecraft:air"
      },
      {
        "char": "p",
        "block": "minecraft:air"
      }
    ]
  },
  "slices": [
    [
      "        ljcjvcjj",
      "        lcgccgjc",
      " n nn  necccjccv",
      "eeeeelleegcgggcc",
      "lccgcggceccccgjc",
      "eggcggcclcjgccvj",
      "eccvcjgjlccggcvc",
      "lccjcjcglggccccv",
      "egggcccglccccggc",
      "lccgccvjevccgccv",
      "evvcjgccecgcgccv",
      "eeleeeelellelele",
      "   q   q       q",
      "                ",
      "                ",
      "n    n          "
    ],
    [
      "        cmmBzBmB",
      "        cmmzmRmf",
      "n      ojfmҶmAmA",
      "lcjcvcgglBBzmAzz",
      "jzmmmmfAAB情ABBRf",
      "vmmmzmmfBBzBzRf情",
      "jmmRBzҶҶRfRABAff",
      "gmmAmmmmmfAffBAA",
      "gmmBAmBmfmzzffBm",
      "cmmAzBBzzBAAzABf",
      "gBmmRmzmzmmBAAmm",
      "lgjccggcecggcccg",
      "  q q      q q  ",
      "                ",
      "                ",
      " n  n    n n    "
    ],
    [
      "        зwGEEEwN",
      "        iwGNGEwE",
      " n n   nз wEwEwE",
      "lяiяiiяяei EwN E",
      "з wwww iqi E N E",
      "зwwG ww    EiEi棒",
      "iwGEENNNNNENрE N",
      "iwGEGGwww рi EEE",
      "iwGEQGQGQwi рi w",
      "зwwNQNQEQENNNNEE",
      "з wwQwQwQGw i ww",
      "lиииииииeиииииии",
      "q q q qq qq qq q",
      "                ",
      "                ",
      "  n  n   n   n n"
    ],
    [
      "          P     ",
      "            P   ",
      "                ",
      "i       i       ",
      "                ",
      "   P            ",
      "  P         h   ",
      "  P PP    h n   ",
      "  P ӜPӜPӜ q h   ",
      "    Ӝ Ӝ Ӝ       ",
      "    Ӛ Ӛ ӚP      ",
      "i       i       ",
      "                ",
      "                ",
      "                ",
      "                "
    ],
    [
      "                ",
      "                ",
      "                ",
      "                ",
      "                ",
      "                ",
      "            hp  ",
      "          i n   ",
      "           oh   ",
      "                ",
      "                ",
      "                ",
      "                ",
      "                ",
      "                ",
      "                "
    ],
    [
      "                ",
      "                ",
      "                ",
      "                ",
      "                ",
      "                ",
      "            i   ",
      "                ",
      "           oh   ",
      "                ",
      "                ",
      "                ",
      "                ",
      "                ",
      "                ",
      "                "
    ]
  ]
}