{
  "xsize": 16,
  "zsize": 16,
  "palette": {
    "palette": [
      {
        "char": " ",
        "block": "minecraft:air"
      },
      {
        "char": "o",
        "block": "minecraft:air"
      },
      {
        "char": "a",
        "block": "minecraft:stone_bricks"
      },
      {
        "char": "e",
        "block": "minecraft:polished_andesite"
      },
      {
        "char": "u",
        "block": "minecraft:stone_bricks"
      },
      {
        "char": "b",
        "block": "minecraft:cracked_stone_bricks"
      },
      {
        "char": "f",
        "block": "minecraft:stone"
      },
      {
        "char": "m",
        "block": "minecraft:grass_block[snowy=false]"
      },
      {
        "char": "z",
        "block": "minecraft:dead_bubble_coral_block"
      },
      {
        "char": "R",
        "block": "minecraft:cobblestone"
      },
      {
        "char": "A",
        "block": "minecraft:dead_fire_coral_block"
      },
      {
        "char": "B",
        "block": "minecraft:dead_brain_coral_block"
      },
      {
        "char": "w",
        "block": "minecraft:air"
      },
      {
        "char": "л",
        "block": "minecraft:air"
      },
      {
        "char": "N",
        "block": "minecraft:stone_slab[type=bottom]"
      },
      {
        "char": "i",
        "block": "minecraft:air"
      },
      {
        "char": "p",
        "block": "minecraft:air"
      },
      {
        "char": "E",
        "block": "minecraft:smooth_stone_slab[type=bottom]"
      },
      {
        "char": "Q",
        "block": "minecraft:air"
      },
      {
        "char": "Э",
        "block": "minecraft:air"
      },
      {
        "char": "Ҁ",
        "block": "minecraft:spruce_fence[east=true]"
      },
      {
        "char": "G",
        "block": "minecraft:air"
      },
      {
        "char": "з",
        "block": "minecraft:air"
      },
      {
        "char": "Ѯ",
        "block": "minecraft:rail[shape=north_east]"
      },
      {
        "char": "Ѱ",
        "block": "minecraft:rail[shape=south_east]"
      },
      {
        "char": "h",
        "block": "minecraft:oak_leaves"
      },
      {
        "char": "щ",
        "block": "minecraft:air"
      },
      {
        "char": "P",
        "block": "minecraft:air"
      },
      {
        "char": "区",
        "block": "minecraft:spruce_fence[south=true,west=true]"
      },
      {
        "char": "全",
        "block": "minecraft:spruce_fence[north=true,south=true]"
      },
      {
        "char": "Ӄ",
        "block": "minecraft:spruce_fence[north=true]"
      }
    ]
  },
  "slices": [
    [
      "          oaeuab",
      "          oaeaaa",
      "          obebba",
      "          obeaba",
      "          obeaba",
      "           aebbb",
      "          oueaba",
      "          oaeaaa",
      "          obeuaa",
      "           aeabb",
      "          obeaaa",
      "           bebba",
      "          oaebba",
      "           aeaaa",
      "          obebbb",
      "           aefff"
    ],
    [
      "           bemmz",
      "          oaemmR",
      "          oaefmf",
      "           aezAB",
      "          oaezRR",
      "           bezAA",
      "          oaefAf",
      "          oaezAf",
      "           aezAB",
      "          obezBz",
      "          oaeffB",
      "           aeBzf",
      "          oaezmA",
      "           bemmA",
      "          oaemmm",
      "           aeeee"
    ],
    [
      "           bewwл",
      "          obewwN",
      "          oaeiwл",
      "           ae iл",
      "          obep E",
      "           bei Q",
      "          oaei Q",
      "           ae   ",
      "           beii ",
      "          obepiE",
      "          obeЭ E",
      "          oae ҀQ",
      "           bepwQ",
      "           bewGQ",
      "          obeGGw",
      "           aeeee"
    ],
    [
      "           зi  Ѯ",
      "           ii   ",
      "           i   Ѱ",
      "          oз   Ѯ",
      "           ii   ",
      "           зi  Ѱ",
      "           i   Ѯ",
      "           з    ",
      "          oз    ",
      "           з    ",
      "           ii   ",
      "          oзi hщ",
      "           зi  щ",
      "           i   щ",
      "           зiP  ",
      "           ii  i"
    ],
    [
      "                ",
      "                ",
      "                ",
      "                ",
      "                ",
      "                ",
      "                ",
      "                ",
      "                ",
      "                ",
      "             Ҁ区 ",
      "             h全h",
      "              Ӄ ",
      "                ",
      "                ",
      "                "
    ],
    [
      "                ",
      "                ",
      "                ",
      "                ",
      "                ",
      "                ",
      "                ",
      "                ",
      "                ",
      "                ",
      "             hh ",
      "             hhh",
      "              h ",
      "                ",
      "                ",
      "                "
    ]
  ]
}