{
  "xsize": 16,
  "zsize": 16,
  "palette": {
    "palette": [
      {
        "char": " ",
        "block": "minecraft:air"
      },
      {
        "char": "е",
        "block": "minecraft:air"
      },
      {
        "char": "u",
        "block": "minecraft:stone_bricks"
      },
      {
        "char": "e",
        "block": "minecraft:polished_andesite"
      },
      {
        "char": "f",
        "block": "minecraft:stone"
      },
      {
        "char": "F",
        "block": "minecraft:stone_slab[type=top]"
      },
      {
        "char": "a",
        "block": "minecraft:stone_bricks"
      },
      {
        "char": "l",
        "block": "minecraft:andesite"
      },
      {
        "char": "b",
        "block": "minecraft:cracked_stone_bricks"
      },
      {
        "char": "C",
        "block": "minecraft:air"
      },
      {
        "char": "E",
        "block": "minecraft:smooth_stone_slab[type=bottom]"
      },
      {
        "char": "I",
        "block": "minecraft:air"
      },
      {
        "char": "m",
        "block": "minecraft:grass_block[snowy=false]"
      },
      {
        "char": "z",
        "block": "minecraft:dead_bubble_coral_block"
      },
      {
        "char": "R",
        "block": "minecraft:cobblestone"
      },
      {
        "char": "A",
        "block": "minecraft:dead_fire_coral_block"
      },
      {
        "char": "B",
        "block": "minecraft:dead_brain_coral_block"
      },
      {
        "char": "G",
        "block": "minecraft:air"
      },
      {
        "char": "w",
        "block": "minecraft:air"
      },
      {
        "char": "Q",
        "block": "minecraft:air"
      },
      {
        "char": "л",
        "block": "minecraft:air"
      },
      {
        "char": "N",
        "block": "minecraft:stone_slab[type=bottom]"
      },
      {
        "char": "i",
        "block": "minecraft:air"
      },
      {
        "char": "Э",
        "block": "minecraft:air"
      },
      {
        "char": "Ҁ",
        "block": "minecraft:spruce_fence[east=true]"
      },
      {
        "char": "p",
        "block": "minecraft:air"
      },
      {
        "char": "з",
        "block": "minecraft:air"
      },
      {
        "char": "Ѱ",
        "block": "minecraft:rail[shape=south_east]"
      },
      {
        "char": "Ѯ",
        "block": "minecraft:rail[shape=north_east]"
      },
      {
        "char": "h",
        "block": "minecraft:oak_leaves"
      },
      {
        "char": "щ",
        "block": "minecraft:air"
      },
      {
        "char": "区",
        "block": "minecraft:spruce_fence[south=true,west=true]"
      },
      {
        "char": "全",
        "block": "minecraft:spruce_fence[north=true,south=true]"
      },
      {
        "char": "Ӄ",
        "block": "minecraft:spruce_fence[north=true]"
      }
    ]
  },
  "slices": [
    [
      "          еuefff",
      "          Falffb",
      "          Fblbfa",
      "          Cfeauf",
      "          Ebeuff",
      "          Fblaff",
      "          Cblbff",
      "          Faeafb",
      "          еaebfb",
      "          Ifeffb",
      "          Ibeaaf",
      "          Ffebbf",
      "          Eaeaff",
      "          еbebbb",
      "          Faefaa",
      "          Iflfff"
    ],
    [
      "           aemmm",
      "           aemmz",
      "           bemmz",
      "           aemmR",
      "           aefmf",
      "           aezAB",
      "           aezRR",
      "           bezAA",
      "           aefAf",
      "           aezAf",
      "           aezAB",
      "           bezBz",
      "           aeffB",
      "           aeBzf",
      "           aezmA",
      "           aemmm"
    ],
    [
      "           beGww",
      "           aeGwQ",
      "           bewwл",
      "           bewwN",
      "           aeiwл",
      "           ae iл",
      "           be  E",
      "           bei Q",
      "           aei Q",
      "           ae   ",
      "           beii ",
      "           be iE",
      "           beЭ E",
      "           ae ҀQ",
      "           bepwQ",
      "           beGww"
    ],
    [
      "           ii   ",
      "           зi  Ѱ",
      "           зi  Ѯ",
      "           ii   ",
      "           i   Ѱ",
      "           з   Ѯ",
      "           i    ",
      "           зi  Ѱ",
      "           i   Ѯ",
      "           з    ",
      "           з    ",
      "           з    ",
      "           ii   ",
      "           зi hщ",
      "           зi  щ",
      "           ii   "
    ],
    [
      "                ",
      "                ",
      "                ",
      "                ",
      "                ",
      "                ",
      "                ",
      "                ",
      "                ",
      "                ",
      "                ",
      "                ",
      "             Ҁ区 ",
      "             h全h",
      "              Ӄ ",
      "                "
    ],
    [
      "                ",
      "                ",
      "                ",
      "                ",
      "                ",
      "                ",
      "                ",
      "                ",
      "                ",
      "                ",
      "                ",
      "                ",
      "             hh ",
      "             hhh",
      "              h ",
      "                "
    ]
  ]
}