{
  "xsize": 16,
  "zsize": 16,
  "palette": {
    "palette": [
      {
        "char": " ",
        "block": "minecraft:air"
      },
      {
        "char": "g",
        "block": "minecraft:air"
      },
      {
        "char": "j",
        "block": "minecraft:air"
      },
      {
        "char": "e",
        "block": "minecraft:polished_andesite"
      },
      {
        "char": "f",
        "block": "minecraft:stone"
      },
      {
        "char": "ф",
        "block": "minecraft:polished_andesite_slab[type=bottom]"
      },
      {
        "char": "c",
        "block": "minecraft:bricks"
      },
      {
        "char": "C",
        "block": "minecraft:air"
      },
      {
        "char": "v",
        "block": "minecraft:bricks"
      },
      {
        "char": "l",
        "block": "minecraft:andesite"
      },
      {
        "char": "u",
        "block": "minecraft:stone_bricks"
      },
      {
        "char": "y",
        "block": "minecraft:polished_andesite_slab[type=top]"
      },
      {
        "char": "I",
        "block": "minecraft:air"
      },
      {
        "char": "Ы",
        "block": "minecraft:smooth_stone"
      },
      {
        "char": "Ѻ",
        "block": "minecraft:air"
      },
      {
        "char": "х",
        "block": "minecraft:air"
      },
      {
        "char": "N",
        "block": "minecraft:stone_slab[type=bottom]"
      },
      {
        "char": "ѹ",
        "block": "minecraft:air"
      },
      {
        "char": "е",
        "block": "minecraft:air"
      },
      {
        "char": "H",
        "block": "minecraft:smooth_stone_slab[type=top]"
      },
      {
        "char": "b",
        "block": "minecraft:cracked_stone_bricks"
      },
      {
        "char": "a",
        "block": "minecraft:stone_bricks"
      },
      {
        "char": "E",
        "block": "minecraft:smooth_stone_slab[type=bottom]"
      },
      {
        "char": "m",
        "block": "minecraft:grass_block[snowy=false]"
      },
      {
        "char": "z",
        "block": "minecraft:dead_bubble_coral_block"
      },
      {
        "char": "B",
        "block": "minecraft:dead_brain_coral_block"
      },
      {
        "char": "Ҷ",
        "block": "minecraft:stone"
      },
      {
        "char": "棒",
        "block": "minecraft:stone_slab[type=bottom]"
      },
      {
        "char": "i",
        "block": "minecraft:air"
      },
      {
        "char": "R",
        "block": "minecraft:cobblestone"
      },
      {
        "char": "p",
        "block": "minecraft:air"
      },
      {
        "char": "A",
        "block": "minecraft:dead_fire_coral_block"
      },
      {
        "char": "G",
        "block": "minecraft:air"
      },
      {
        "char": "w",
        "block": "minecraft:air"
      },
      {
        "char": "с",
        "block": "minecraft:air"
      },
      {
        "char": "р",
        "block": "minecraft:spruce_fence"
      },
      {
        "char": "Q",
        "block": "minecraft:air"
      },
      {
        "char": "и",
        "block": "minecraft:air"
      },
      {
        "char": "P",
        "block": "minecraft:air"
      },
      {
        "char": "h",
        "block": "minecraft:oak_leaves"
      },
      {
        "char": "Ѳ",
        "block": "minecraft:rail[shape=south_west]"
      },
      {
        "char": "ѱ",
        "block": "minecraft:rail[shape=north_west]"
      }
    ]
  },
  "slices": [
    [
      "ggjefф          ",
      "ggcefC          ",
      "jcvluy          ",
      "cgjluI          ",
      "ggjlЫC          ",
      "cjgeЫф          ",
      "ccjlѺх          ",
      "cgceЫN          ",
      "ccceѹе          ",
      "gcgefх          ",
      "ccgeЫH          ",
      "cvceby          ",
      "gjglby          ",
      "gcceaE          ",
      "jvvebN          ",
      "lleeaE          "
    ],
    [
      "mzmc            ",
      "mzmgф           ",
      "mBmgе           ",
      "mfҶj棒i          ",
      "RfzgEi          ",
      "fRzcp           ",
      "zfmvi           ",
      "mfml            ",
      "mBmgi           ",
      "AAmc            ",
      "BzAgхi          ",
      "RRBcфi          ",
      "ABAvф           ",
      "Bfmci           ",
      "mmmg            ",
      "ggge            "
    ],
    [
      "GEwi            ",
      "GNwс            ",
      "wEwсp           ",
      "wEiсp           ",
      "рE с            ",
      "iEрсp           ",
      " Nwi            ",
      "wNGl            ",
      "wEGс            ",
      " Ewсp           ",
      "iE i            ",
      " E сp           ",
      "QN i            ",
      "QNwс            ",
      "wwGсp           ",
      "iииep           "
    ],
    [
      "P               ",
      "P               ",
      "                ",
      "                ",
      "h               ",
      "  h             ",
      "                ",
      "   i            ",
      "                ",
      "                ",
      "                ",
      "                ",
      "Ѳ               ",
      "ѱ               ",
      "  P             ",
      "   i            "
    ],
    [
      "                ",
      "                ",
      "                ",
      "                ",
      "h               ",
      "  h             ",
      "                ",
      "                ",
      "                ",
      "                ",
      "                ",
      "                ",
      "                ",
      "                ",
      "                ",
      "                "
    ],
    [
      "                ",
      "                ",
      "                ",
      "                ",
      "h               ",
      "                ",
      "                ",
      "                ",
      "                ",
      "                ",
      "                ",
      "                ",
      "                ",
      "                ",
      "                ",
      "                "
    ]
  ]
}