{
  "xsize": 16,
  "zsize": 16,
  "palette": {
    "palette": [
      {
        "char": " ",
        "block": "minecraft:air"
      },
      {
        "char": "f",
        "block": "minecraft:stone"
      },
      {
        "char": "b",
        "block": "minecraft:cracked_stone_bricks"
      },
      {
        "char": "a",
        "block": "minecraft:stone_bricks"
      },
      {
        "char": "u",
        "block": "minecraft:stone_bricks"
      },
      {
        "char": "e",
        "block": "minecraft:polished_andesite"
      },
      {
        "char": "m",
        "block": "minecraft:grass_block[snowy=false]"
      },
      {
        "char": "A",
        "block": "minecraft:dead_fire_coral_block"
      },
      {
        "char": "B",
        "block": "minecraft:dead_brain_coral_block"
      },
      {
        "char": "z",
        "block": "minecraft:dead_bubble_coral_block"
      },
      {
        "char": "R",
        "block": "minecraft:cobblestone"
      },
      {
        "char": "买",
        "block": "minecraft:air"
      },
      {
        "char": "S",
        "block": "minecraft:air"
      },
      {
        "char": "p",
        "block": "minecraft:air"
      },
      {
        "char": "G",
        "block": "minecraft:air"
      },
      {
        "char": "w",
        "block": "minecraft:air"
      },
      {
        "char": "i",
        "block": "minecraft:air"
      },
      {
        "char": "Q",
        "block": "minecraft:air"
      },
      {
        "char": "N",
        "block": "minecraft:stone_slab[type=bottom]"
      },
      {
        "char": "E",
        "block": "minecraft:smooth_stone_slab[type=bottom]"
      },
      {
        "char": "р",
        "block": "minecraft:spruce_fence"
      },
      {
        "char": "л",
        "block": "minecraft:air"
      },
      {
        "char": "Э",
        "block": "minecraft:air"
      },
      {
        "char": "呢",
        "block": "minecraft:air"
      },
      {
        "char": "Я",
        "block": "minecraft:air"
      },
      {
        "char": "o",
        "block": "minecraft:air"
      },
      {
        "char": "同",
        "block": "minecraft:air"
      },
      {
        "char": "Ц",
        "block": "minecraft:spruce_slab[type=bottom]"
      },
      {
        "char": "觉",
        "block": "minecraft:oak_wood[axis=z]"
      },
      {
        "char": "P",
        "block": "minecraft:air"
      },
      {
        "char": "ц",
        "block": "minecraft:air"
      },
      {
        "char": "h",
        "block": "minecraft:oak_leaves"
      },
      {
        "char": "Ѱ",
        "block": "minecraft:rail[shape=south_east]"
      },
      {
        "char": "Ѯ",
        "block": "minecraft:rail[shape=north_east]"
      },
      {
        "char": "n",
        "block": "minecraft:air"
      },
      {
        "char": "щ",
        "block": "minecraft:air"
      },
      {
        "char": "r",
        "block": "minecraft:air"
      },
      {
        "char": "љ",
        "block": "minecraft:air"
      },
      {
        "char": "ї",
        "block": "minecraft:air"
      },
      {
        "char": "Ҁ",
        "block": "minecraft:spruce_fence[east=true]"
      },
      {
        "char": "ѿ",
        "block": "minecraft:spruce_fence[west=true]"
      },
      {
        "char": "ы",
        "block": "minecraft:stone_brick_slab[type=bottom]"
      },
      {
        "char": "Ѷ",
        "block": "minecraft:stone_brick_slab[type=bottom]"
      }
    ]
  },
  "slices": [
    [
      "ffffffffffffffff",
      "ffbfbafafabfuufb",
      "fabfabbaabfuffff",
      "fbbabbfbafffffbf",
      "ffabbfbbaafbfbaf",
      "ffaaabababffaaaa",
      "fabfbbbfabfbbfaf",
      "ffababfbbfufbbab",
      "fabbfbbfbafbaaba",
      "ffbfffbafaaffbfa",
      "fbafbbafabaufaff",
      "fafafauuafafbbbb",
      "fuabffaababbffaa",
      "ffbbbbbffbafbaaa",
      "fbfafbabfabbaabf",
      "fabfabffabfafbbf"
    ],
    [
      "emmmmmmmAAfBfzzm",
      "emmfmzfffzAfRBff",
      "emmBmRmzRfzBfmmm",
      "eBmzmAmfmRRmBfmm",
      "eABfmmmzmmBmRfmm",
      "ezBAmAmBmmmmfBAA",
      "eBRAzzzBfAfRzABB",
      "eAAzAfBARzRzBRzf",
      "efAzzRAzBBfRfzff",
      "efzBBAffAzfAzRRR",
      "eRzAfABRmmBzBzRR",
      "efAABzAmmmmzffBz",
      "eAR买SzAAAzmmAfmm",
      "eab  azmmRmmfmBm",
      "eaap aAAmAmmfmAm",
      "emmmmmmmAAfBfzzm"
    ],
    [
      "eGwwGGGw  ii   w",
      "ewGQNQEQiр iEEEл",
      "ewGQGQGQi   EwGQ",
      "epwQGQGQwi wE wG",
      "e iNGwGEGw wEiwл",
      "eЭ Ew wEGGwGEiiл",
      "e  E   NEEEEE   ",
      "eЭ   ii   р    Q",
      "e i   i i   рi Q",
      "e   呢     i  ii ",
      "e    Яi ww рii i",
      "eob bapwGGwii  i",
      "e ap同uENEEGw  ww",
      "e b oaEwGEGwQwQG",
      "e b oaNЦ觉EGwQwQG",
      "eGwwGGGw  ii   w"
    ],
    [
      " P  P           ",
      "i Pц ц ц h     Ѱ",
      "  PцPцPц       Ѯ",
      "i  ц ц ц        ",
      "        P      Ѱ",
      "i          P   Ѯ",
      "                ",
      "i         h    Ѱ",
      "            h  Ѯ",
      "i               ",
      "  n        h    ",
      "i b aap         ",
      "i b oap   P     ",
      "iob  a  P   щ щP",
      "  bp b  р P щ щ ",
      " P  P           "
    ],
    [
      "         h      ",
      "        hhh     ",
      "                ",
      "                ",
      "                ",
      "                ",
      "                ",
      "          h     ",
      "            h   ",
      "                ",
      "    n           ",
      "  aabbp         ",
      " ob rb n        ",
      "  bљїa hn       ",
      "  b raphhр      ",
      "         h      "
    ],
    [
      "         hh     ",
      "        hҀѿ     ",
      "         h      ",
      "                ",
      "                ",
      "                ",
      "                ",
      "                ",
      "            h   ",
      "                ",
      "  ыNыы          ",
      "  ыNNN          ",
      "  ѶыNѶr         ",
      "  ѶыNыnhpn      ",
      "  Nыыыhhhh      ",
      "         hh     "
    ]
  ]
}