{
  "xsize": 16,
  "zsize": 16,
  "palette": {
    "palette": [
      {
        "char": " ",
        "block": "minecraft:air"
      },
      {
        "char": "f",
        "block": "minecraft:stone"
      },
      {
        "char": "b",
        "block": "minecraft:cracked_stone_bricks"
      },
      {
        "char": "u",
        "block": "minecraft:stone_bricks"
      },
      {
        "char": "a",
        "block": "minecraft:stone_bricks"
      },
      {
        "char": "m",
        "block": "minecraft:grass_block[snowy=false]"
      },
      {
        "char": "z",
        "block": "minecraft:dead_bubble_coral_block"
      },
      {
        "char": "B",
        "block": "minecraft:dead_brain_coral_block"
      },
      {
        "char": "A",
        "block": "minecraft:dead_fire_coral_block"
      },
      {
        "char": "e",
        "block": "minecraft:polished_andesite"
      },
      {
        "char": "R",
        "block": "minecraft:cobblestone"
      },
      {
        "char": "S",
        "block": "minecraft:air"
      },
      {
        "char": "买",
        "block": "minecraft:air"
      },
      {
        "char": "o",
        "block": "minecraft:air"
      },
      {
        "char": "w",
        "block": "minecraft:air"
      },
      {
        "char": "i",
        "block": "minecraft:air"
      },
      {
        "char": "G",
        "block": "minecraft:air"
      },
      {
        "char": "л",
        "block": "minecraft:air"
      },
      {
        "char": "E",
        "block": "minecraft:smooth_stone_slab[type=bottom]"
      },
      {
        "char": "р",
        "block": "minecraft:spruce_fence"
      },
      {
        "char": "Q",
        "block": "minecraft:air"
      },
      {
        "char": "N",
        "block": "minecraft:stone_slab[type=bottom]"
      },
      {
        "char": "Ь",
        "block": "minecraft:air"
      },
      {
        "char": "呢",
        "block": "minecraft:air"
      },
      {
        "char": "Я",
        "block": "minecraft:air"
      },
      {
        "char": "p",
        "block": "minecraft:air"
      },
      {
        "char": "同",
        "block": "minecraft:air"
      },
      {
        "char": "觉",
        "block": "minecraft:oak_wood[axis=z]"
      },
      {
        "char": "Ц",
        "block": "minecraft:spruce_slab[type=bottom]"
      },
      {
        "char": "P",
        "block": "minecraft:air"
      },
      {
        "char": "Ѳ",
        "block": "minecraft:rail[shape=south_west]"
      },
      {
        "char": "h",
        "block": "minecraft:oak_leaves"
      },
      {
        "char": "ц",
        "block": "minecraft:air"
      },
      {
        "char": "ѱ",
        "block": "minecraft:rail[shape=north_west]"
      },
      {
        "char": "n",
        "block": "minecraft:air"
      },
      {
        "char": "щ",
        "block": "minecraft:air"
      },
      {
        "char": "r",
        "block": "minecraft:air"
      },
      {
        "char": "љ",
        "block": "minecraft:air"
      },
      {
        "char": "ї",
        "block": "minecraft:air"
      },
      {
        "char": "Ҁ",
        "block": "minecraft:spruce_fence[east=true]"
      },
      {
        "char": "ѿ",
        "block": "minecraft:spruce_fence[west=true]"
      },
      {
        "char": "ы",
        "block": "minecraft:stone_brick_slab[type=bottom]"
      },
      {
        "char": "Ѷ",
        "block": "minecraft:stone_brick_slab[type=bottom]"
      }
    ]
  },
  "slices": [
    [
      "ffffffffffffffff",
      "bfuufbafafabfbff",
      "ffffufbaabbafbaf",
      "fbfffffabfbbabbf",
      "fabfbfaabbfbbaff",
      "uuaaffbababaaaff",
      "fufbbfbafbbbfbaf",
      "babbfufbbfbabaff",
      "abaabfabfbbfbbaf",
      "afbffuafabfffbff",
      "ffafuabafabbfabf",
      "bbbbfafauuafafaf",
      "aaffbbabaaffbaaf",
      "aaabfabffbbbbbff",
      "fbaabbafbabfafbf",
      "fbbfafbaffbafbaf"
    ],
    [
      "mzzfBfAAmmmmmmme",
      "ffBRfAzfffzmfmme",
      "mmmfBzfRzmRmBmme",
      "mmfBmRRmfmAmzmBe",
      "mmfRmBmmzmmmfBAe",
      "AABfmmmmBmAmABze",
      "BBAzRfAfBzzzARBe",
      "fzRBzRzRABfAzAAe",
      "ffzfRfBBzARzzAfe",
      "RRRzAfzAffABBzfe",
      "RRzBzBmmRBAfAzRe",
      "zBffzmmmmAzBAAfe",
      "mmfAmmzAAAzS买RAe",
      "mBmfmmRmmza  bae",
      "mAmfmmAmAAa oaae",
      "mzzfBfAAmmmmmmme"
    ],
    [
      "w   ii  wGGGwwGe",
      "лEEEi рiQEQNQGwe",
      "QGwE   iQGQGQGwe",
      "Gw Ew iwQGQGQwoe",
      "лwiEw wGEGwGNi e",
      "лiiEGwGGEw wE Ьe",
      "   EEEEEN   E  e",
      "Q    р   ii   Ьe",
      "Q iр   i i   i e",
      " ii  i     呢   e",
      "i iiр ww iЯ    e",
      "i  iiwGGwoab bpe",
      "ww  wGEENEu同oa e",
      "GQwQwGEGwEup b e",
      "GQwQwGE觉ЦNap b e",
      "w   ii  wGGGwwGe"
    ],
    [
      "         P    P ",
      "Ѳ     h ц ц ц  i",
      "ѱ       ц цPц   ",
      "        ц ц ц  i",
      "Ѳ        P P    ",
      "ѱ   P P        i",
      "                ",
      "Ѳ    h         i",
      "ѱ  h            ",
      "               i",
      "    h        n  ",
      "         oaa b i",
      "     P   oap b i",
      " щ щ   P  a  bpi",
      " щ щ   р  b ob  ",
      "         P      "
    ],
    [
      "      h         ",
      "     hhh        ",
      "                ",
      "                ",
      "                ",
      "                ",
      "                ",
      "     h          ",
      "   h            ",
      "                ",
      "           n    ",
      "         obbaa  ",
      "        n br bp ",
      "       nh aљїb  ",
      "      рhhoar b  ",
      "      h         "
    ],
    [
      "     hh         ",
      "     Ҁѿh        ",
      "      h         ",
      "                ",
      "                ",
      "                ",
      "                ",
      "                ",
      "   h            ",
      "                ",
      "          ыыNы  ",
      "          NNNѶ  ",
      "         rѶNѶѶ  ",
      "      nohnѶNыѶ  ",
      "      hhhhыыыN  ",
      "     hh         "
    ]
  ]
}