{
  "xsize": 16,
  "zsize": 16,
  "palette": {
    "palette": [
      {
        "char": " ",
        "block": "minecraft:air"
      },
      {
        "char": "N",
        "block": "minecraft:stone_slab[type=bottom,waterlogged=false]"
      },
      {
        "char": "Ѻ",
        "block": "minecraft:air"
      },
      {
        "char": "e",
        "block": "minecraft:polished_andesite"
      },
      {
        "char": "c",
        "block": "minecraft:bricks"
      },
      {
        "char": "х",
        "block": "minecraft:air"
      },
      {
        "char": "u",
        "block": "minecraft:stone_bricks"
      },
      {
        "char": "j",
        "block": "minecraft:air"
      },
      {
        "char": "g",
        "block": "minecraft:air"
      },
      {
        "char": "ф",
        "block": "minecraft:polished_andesite_slab[type=bottom,waterlogged=false]"
      },
      {
        "char": "b",
        "block": "minecraft:cracked_stone_bricks"
      },
      {
        "char": "е",
        "block": "minecraft:air"
      },
      {
        "char": "y",
        "block": "minecraft:polished_andesite_slab[type=top,waterlogged=false]"
      },
      {
        "char": "Ы",
        "block": "minecraft:smooth_stone"
      },
      {
        "char": "F",
        "block": "minecraft:stone_slab[type=top,waterlogged=false]"
      },
      {
        "char": "a",
        "block": "minecraft:stone_bricks"
      },
      {
        "char": "H",
        "block": "minecraft:smooth_stone_slab[type=top,waterlogged=false]"
      },
      {
        "char": "v",
        "block": "minecraft:bricks"
      },
      {
        "char": "l",
        "block": "minecraft:andesite"
      },
      {
        "char": "q",
        "block": "minecraft:air"
      },
      {
        "char": "n",
        "block": "minecraft:air"
      },
      {
        "char": "i",
        "block": "minecraft:air"
      },
      {
        "char": "m",
        "block": "minecraft:grass_block[snowy=false]"
      },
      {
        "char": "f",
        "block": "minecraft:stone"
      },
      {
        "char": "B",
        "block": "minecraft:dead_brain_coral_block"
      },
      {
        "char": "R",
        "block": "minecraft:cobblestone"
      },
      {
        "char": "A",
        "block": "minecraft:dead_fire_coral_block"
      },
      {
        "char": "o",
        "block": "minecraft:air"
      },
      {
        "char": "z",
        "block": "minecraft:dead_bubble_coral_block"
      },
      {
        "char": "E",
        "block": "minecraft:smooth_stone_slab[type=bottom,waterlogged=false]"
      },
      {
        "char": "з",
        "block": "minecraft:air"
      },
      {
        "char": "G",
        "block": "minecraft:air"
      },
      {
        "char": "л",
        "block": "minecraft:air"
      },
      {
        "char": "Q",
        "block": "minecraft:air"
      },
      {
        "char": "w",
        "block": "minecraft:air"
      },
      {
        "char": "и",
        "block": "minecraft:air"
      },
      {
        "char": "P",
        "block": "minecraft:air"
      },
      {
        "char": "Ѱ",
        "block": "minecraft:rail[shape=south_east,waterlogged=false]"
      },
      {
        "char": "Ѳ",
        "block": "minecraft:rail[shape=south_west,waterlogged=false]"
      },
      {
        "char": "Ѯ",
        "block": "minecraft:rail[shape=north_east,waterlogged=false]"
      },
      {
        "char": "ѱ",
        "block": "minecraft:rail[shape=north_west,waterlogged=false]"
      }
    ]
  },
  "slices": [
    [
      "          NѺeccc",
      "          хuejcj",
      "          хeeggc",
      "          фbecgc",
      "          еѺejcg",
      "          yЫegcc",
      "          Faecgg",
      "          Hbegcj",
      "          еaejcv",
      "          хeecgc",
      "          еulggc",
      "          еeeeee",
      "            q   ",
      "                ",
      "                ",
      "            n   "
    ],
    [
      "           icmfB",
      "           icRAm",
      "           ovRzm",
      "            vmBm",
      "           ovRAm",
      "           фcBBm",
      "          iEjmfm",
      "           NcBzm",
      "           ogABm",
      "           igmzf",
      "            cmmm",
      "           ievjc",
      "            qq  ",
      "                ",
      "                ",
      "           nn   "
    ],
    [
      "            зGEE",
      "            iлQw",
      "           oзQлG",
      "            зGNG",
      "           oзллw",
      "           oзлQw",
      "            iGEG",
      "           oзQлw",
      "            iQQG",
      "           oзGNE",
      "            зwGG",
      "            eиии",
      "               q",
      "                ",
      "                ",
      "           n n  "
    ],
    [
      "             P  ",
      "             ѰѲ ",
      "             Ѯѱ ",
      "             P P",
      "             ѰѲ ",
      "             Ѯѱ ",
      "             P P",
      "             ѰѲ ",
      "             Ѯѱ ",
      "             P  ",
      "              PP",
      "            i   ",
      "                ",
      "                ",
      "                ",
      "                "
    ],
    [
      "                ",
      "                ",
      "                ",
      "                ",
      "                ",
      "                ",
      "                ",
      "                ",
      "                ",
      "                ",
      "                ",
      "                ",
      "                ",
      "                ",
      "                ",
      "                "
    ],
    [
      "                ",
      "                ",
      "                ",
      "                ",
      "                ",
      "                ",
      "                ",
      "                ",
      "                ",
      "                ",
      "                ",
      "                ",
      "                ",
      "                ",
      "                ",
      "                "
    ]
  ]
}