{
  "xsize": 16,
  "zsize": 16,
  "palette": {
    "palette": [
      {
        "char": " ",
        "block": "minecraft:air"
      },
      {
        "char": "y",
        "block": "minecraft:polished_andesite_slab[type=top]"
      },
      {
        "char": "a",
        "block": "minecraft:stone_bricks"
      },
      {
        "char": "l",
        "block": "minecraft:andesite"
      },
      {
        "char": "b",
        "block": "minecraft:cracked_stone_bricks"
      },
      {
        "char": "f",
        "block": "minecraft:stone"
      },
      {
        "char": "u",
        "block": "minecraft:stone_bricks"
      },
      {
        "char": "F",
        "block": "minecraft:stone_slab[type=top]"
      },
      {
        "char": "e",
        "block": "minecraft:polished_andesite"
      },
      {
        "char": "I",
        "block": "minecraft:air"
      },
      {
        "char": "х",
        "block": "minecraft:air"
      },
      {
        "char": "е",
        "block": "minecraft:air"
      },
      {
        "char": "H",
        "block": "minecraft:smooth_stone_slab[type=top]"
      },
      {
        "char": "ф",
        "block": "minecraft:polished_andesite_slab[type=bottom]"
      },
      {
        "char": "E",
        "block": "minecraft:smooth_stone_slab[type=bottom]"
      },
      {
        "char": "m",
        "block": "minecraft:grass_block[snowy=false]"
      },
      {
        "char": "z",
        "block": "minecraft:dead_bubble_coral_block"
      },
      {
        "char": "R",
        "block": "minecraft:cobblestone"
      },
      {
        "char": "A",
        "block": "minecraft:dead_fire_coral_block"
      },
      {
        "char": "B",
        "block": "minecraft:dead_brain_coral_block"
      },
      {
        "char": "G",
        "block": "minecraft:air"
      },
      {
        "char": "w",
        "block": "minecraft:air"
      },
      {
        "char": "Q",
        "block": "minecraft:air"
      },
      {
        "char": "л",
        "block": "minecraft:air"
      },
      {
        "char": "N",
        "block": "minecraft:stone_slab[type=bottom]"
      },
      {
        "char": "i",
        "block": "minecraft:air"
      },
      {
        "char": "p",
        "block": "minecraft:air"
      },
      {
        "char": "Э",
        "block": "minecraft:air"
      },
      {
        "char": "Ҁ",
        "block": "minecraft:spruce_fence[east=true]"
      },
      {
        "char": "з",
        "block": "minecraft:air"
      },
      {
        "char": "Ѱ",
        "block": "minecraft:rail[shape=south_east]"
      },
      {
        "char": "Ѯ",
        "block": "minecraft:rail[shape=north_east]"
      },
      {
        "char": "h",
        "block": "minecraft:oak_leaves"
      },
      {
        "char": "щ",
        "block": "minecraft:air"
      },
      {
        "char": "P",
        "block": "minecraft:air"
      },
      {
        "char": "区",
        "block": "minecraft:spruce_fence[south=true,west=true]"
      },
      {
        "char": "全",
        "block": "minecraft:spruce_fence[north=true,south=true]"
      },
      {
        "char": "Ӄ",
        "block": "minecraft:spruce_fence[north=true]"
      }
    ]
  },
  "slices": [
    [
      "          yalbfu",
      "          Fbebaa",
      "          Ifefbb",
      "          хfeaaf",
      "          еaeabf",
      "          Iblafa",
      "          ybebab",
      "          Hbebaf",
      "          фblfbf",
      "          Faeabf",
      "          yflabb",
      "          Hbeabf",
      "          Eaefaa",
      "          Fbefbf",
      "          yblabf",
      "          Hbebff"
    ],
    [
      "           aemmz",
      "           bemmz",
      "           aemmR",
      "           uefmf",
      "           aezAB",
      "           aezRR",
      "           bezAA",
      "           aefAf",
      "           aezAf",
      "           aezAB",
      "           bezBz",
      "           aeffB",
      "           aeBzf",
      "           aezmA",
      "           bemmA",
      "           aemmm"
    ],
    [
      "           aeGwQ",
      "           bewwл",
      "           bewwN",
      "           aeiwл",
      "           ae iл",
      "           bep E",
      "           bei Q",
      "           aei Q",
      "           ae   ",
      "           beii ",
      "           be iE",
      "           beЭ E",
      "           ae ҀQ",
      "           bepwQ",
      "           bewGQ",
      "           beGGw"
    ],
    [
      "           зi  Ѱ",
      "           зi  Ѯ",
      "           ii   ",
      "           i   Ѱ",
      "           з   Ѯ",
      "           i    ",
      "           зi  Ѱ",
      "           i   Ѯ",
      "           з    ",
      "           з    ",
      "           з    ",
      "           ii   ",
      "           зi hщ",
      "           зi  щ",
      "           i   щ",
      "           зiP  "
    ],
    [
      "                ",
      "                ",
      "                ",
      "                ",
      "                ",
      "                ",
      "                ",
      "                ",
      "                ",
      "                ",
      "                ",
      "             Ҁ区 ",
      "             h全h",
      "              Ӄ ",
      "                ",
      "                "
    ],
    [
      "                ",
      "                ",
      "                ",
      "                ",
      "                ",
      "                ",
      "                ",
      "                ",
      "                ",
      "                ",
      "                ",
      "             hh ",
      "             hhh",
      "              h ",
      "                ",
      "                "
    ]
  ]
}