{
  "xsize": 16,
  "zsize": 16,
  "palette": {
    "palette": [
      {
        "char": " ",
        "block": "minecraft:air"
      },
      {
        "char": "c",
        "block": "minecraft:bricks"
      },
      {
        "char": "e",
        "block": "minecraft:polished_andesite"
      },
      {
        "char": "Ѻ",
        "block": "minecraft:air"
      },
      {
        "char": "N",
        "block": "minecraft:stone_slab[type=bottom]"
      },
      {
        "char": "j",
        "block": "minecraft:air"
      },
      {
        "char": "a",
        "block": "minecraft:stone_bricks"
      },
      {
        "char": "х",
        "block": "minecraft:air"
      },
      {
        "char": "g",
        "block": "minecraft:air"
      },
      {
        "char": "b",
        "block": "minecraft:cracked_stone_bricks"
      },
      {
        "char": "ф",
        "block": "minecraft:polished_andesite_slab[type=bottom]"
      },
      {
        "char": "е",
        "block": "minecraft:air"
      },
      {
        "char": "Ы",
        "block": "minecraft:smooth_stone"
      },
      {
        "char": "y",
        "block": "minecraft:polished_andesite_slab[type=top]"
      },
      {
        "char": "F",
        "block": "minecraft:stone_slab[type=top]"
      },
      {
        "char": "H",
        "block": "minecraft:smooth_stone_slab[type=top]"
      },
      {
        "char": "v",
        "block": "minecraft:bricks"
      },
      {
        "char": "l",
        "block": "minecraft:andesite"
      },
      {
        "char": "u",
        "block": "minecraft:stone_bricks"
      },
      {
        "char": "q",
        "block": "minecraft:air"
      },
      {
        "char": "n",
        "block": "minecraft:air"
      },
      {
        "char": "B",
        "block": "minecraft:dead_brain_coral_block"
      },
      {
        "char": "f",
        "block": "minecraft:stone"
      },
      {
        "char": "m",
        "block": "minecraft:grass_block[snowy=false]"
      },
      {
        "char": "i",
        "block": "minecraft:air"
      },
      {
        "char": "A",
        "block": "minecraft:dead_fire_coral_block"
      },
      {
        "char": "R",
        "block": "minecraft:cobblestone"
      },
      {
        "char": "z",
        "block": "minecraft:dead_bubble_coral_block"
      },
      {
        "char": "p",
        "block": "minecraft:air"
      },
      {
        "char": "E",
        "block": "minecraft:smooth_stone_slab[type=bottom]"
      },
      {
        "char": "G",
        "block": "minecraft:air"
      },
      {
        "char": "с",
        "block": "minecraft:air"
      },
      {
        "char": "w",
        "block": "minecraft:air"
      },
      {
        "char": "Q",
        "block": "minecraft:air"
      },
      {
        "char": "л",
        "block": "minecraft:air"
      },
      {
        "char": "и",
        "block": "minecraft:air"
      },
      {
        "char": "Ѱ",
        "block": "minecraft:rail[shape=south_east]"
      },
      {
        "char": "Ѳ",
        "block": "minecraft:rail[shape=south_west]"
      },
      {
        "char": "P",
        "block": "minecraft:air"
      },
      {
        "char": "Ѯ",
        "block": "minecraft:rail[shape=north_east]"
      },
      {
        "char": "ѱ",
        "block": "minecraft:rail[shape=north_west]"
      }
    ]
  },
  "slices": [
    [
      "ccceѺN          ",
      "jcjeaх          ",
      "cggeeх          ",
      "cgcebф          ",
      "gcjeѺе          ",
      "ccgeЫy          ",
      "ggceaF          ",
      "jcgebH          ",
      "vcjeaе          ",
      "cgceeх          ",
      "cggluе          ",
      "eeeeeе          ",
      "   q            ",
      "                ",
      "                ",
      "   n            "
    ],
    [
      "Bfmci           ",
      "mARvi           ",
      "mzRvp           ",
      "mBmv            ",
      "mARvp           ",
      "mBBvф           ",
      "mfmjEi          ",
      "mzBcN           ",
      "mBAgp           ",
      "fzmgi           ",
      "mmmc            ",
      "cjvei           ",
      "  qq            ",
      "                ",
      "                ",
      "   nn           "
    ],
    [
      "EEGс            ",
      "wQлi            ",
      "GлQсp           ",
      "GNGс            ",
      "wллсp           ",
      "wQлсp           ",
      "GEGi            ",
      "wлQсp           ",
      "GQQi            ",
      "ENGсp           ",
      "GGwс            ",
      "иииe            ",
      "q               ",
      "                ",
      "                ",
      "  n             "
    ],
    [
      "                ",
      " ѰѲ             ",
      "PѮѱ             ",
      "P P             ",
      " ѰѲ             ",
      " Ѯѱ             ",
      "P               ",
      " ѰѲ             ",
      "PѮѱ             ",
      "  P             ",
      "PP              ",
      "   i            ",
      "                ",
      "                ",
      "                ",
      "                "
    ],
    [
      "                ",
      "                ",
      "                ",
      "                ",
      "                ",
      "                ",
      "                ",
      "                ",
      "                ",
      "                ",
      "                ",
      "                ",
      "                ",
      "                ",
      "                ",
      "                "
    ],
    [
      "                ",
      "                ",
      "                ",
      "                ",
      "                ",
      "                ",
      "                ",
      "                ",
      "                ",
      "                ",
      "                ",
      "                ",
      "                ",
      "                ",
      "                ",
      "                "
    ]
  ]
}