{
  "xsize": 16,
  "zsize": 16,
  "palette": {
    "palette": [
      {
        "char": " ",
        "block": "minecraft:air"
      },
      {
        "char": "l",
        "block": "minecraft:andesite"
      },
      {
        "char": "e",
        "block": "minecraft:polished_andesite"
      },
      {
        "char": "p",
        "block": "minecraft:air"
      },
      {
        "char": "g",
        "block": "minecraft:air"
      },
      {
        "char": "c",
        "block": "minecraft:bricks"
      },
      {
        "char": "v",
        "block": "minecraft:bricks"
      },
      {
        "char": "j",
        "block": "minecraft:air"
      },
      {
        "char": "ҽ",
        "block": "minecraft:air"
      },
      {
        "char": "m",
        "block": "minecraft:grass_block[snowy=false]"
      },
      {
        "char": "B",
        "block": "minecraft:dead_brain_coral_block"
      },
      {
        "char": "A",
        "block": "minecraft:dead_fire_coral_block"
      },
      {
        "char": "z",
        "block": "minecraft:dead_bubble_coral_block"
      },
      {
        "char": "f",
        "block": "minecraft:stone"
      },
      {
        "char": "R",
        "block": "minecraft:cobblestone"
      },
      {
        "char": "Ҷ",
        "block": "minecraft:stone"
      },
      {
        "char": "S",
        "block": "minecraft:air"
      },
      {
        "char": "i",
        "block": "minecraft:air"
      },
      {
        "char": "я",
        "block": "minecraft:air"
      },
      {
        "char": "G",
        "block": "minecraft:air"
      },
      {
        "char": "w",
        "block": "minecraft:air"
      },
      {
        "char": "с",
        "block": "minecraft:air"
      },
      {
        "char": "Q",
        "block": "minecraft:air"
      },
      {
        "char": "E",
        "block": "minecraft:smooth_stone_slab[type=bottom]"
      },
      {
        "char": "N",
        "block": "minecraft:stone_slab[type=bottom]"
      },
      {
        "char": "n",
        "block": "minecraft:air"
      },
      {
        "char": "o",
        "block": "minecraft:air"
      },
      {
        "char": "岛",
        "block": "minecraft:air"
      },
      {
        "char": "q",
        "block": "minecraft:air"
      },
      {
        "char": "р",
        "block": "minecraft:spruce_fence"
      },
      {
        "char": "P",
        "block": "minecraft:air"
      },
      {
        "char": "Ӝ",
        "block": "minecraft:air"
      },
      {
        "char": "h",
        "block": "minecraft:oak_leaves"
      },
      {
        "char": "С",
        "block": "minecraft:air"
      },
      {
        "char": "о",
        "block": "minecraft:air"
      },
      {
        "char": "У",
        "block": "minecraft:brick_slab[type=bottom]"
      },
      {
        "char": "Ҁ",
        "block": "minecraft:spruce_fence[east=true]"
      },
      {
        "char": "行",
        "block": "minecraft:spruce_fence[east=true,west=true]"
      },
      {
        "char": "ѿ",
        "block": "minecraft:spruce_fence[west=true]"
      }
    ]
  },
  "slices": [
    [
      "leleeeeep       ",
      "gcvvcggep       ",
      "gccvjjce        ",
      "ccgcccglp       ",
      "ccjcggglp       ",
      "cvjjjjcl        ",
      "cjjvccgl        ",
      "ccg  ҽ l        ",
      "vcc    e        ",
      "eeelllee        ",
      "cgcccvve        ",
      "gcggccclp       ",
      "ccggcjge        ",
      "gcccjcce        ",
      "cvjcgcje        ",
      "gccccvce        "
    ],
    [
      "cvcgggjl        ",
      "mmmmmmmc        ",
      "BAAzAfRgp       ",
      "BmAmfmBc        ",
      "zARffRzg        ",
      "mmmmmmmj        ",
      "AmzAҶffc        ",
      "zffSҽ  c        ",
      "BBBS   g        ",
      "fmffAfzc        ",
      "mmmmmRmjp       ",
      "zmmmfBmg        ",
      "ffffzBAc        ",
      "AzzBmffg        ",
      "mABmmmAg        ",
      "mAmmmmRg        "
    ],
    [
      "iяяяяiяe        ",
      "GGwwGwGс        ",
      "QEQNQNEi        ",
      "QwQwQwEс        ",
      "QNQEQEEс        ",
      "wwwnwwwс        ",
      "iwcjgccg        ",
      " og    g        ",
      "i岛     cp       ",
      " wggcjjg        ",
      "wGGGq wс        ",
      " www рwс        ",
      "i     iс        ",
      "  i w  i        ",
      "wi wGwii        ",
      "w wGGw i        "
    ],
    [
      "       i        ",
      "PP  P P         ",
      "Ӝ Ӝ Ӝ           ",
      "Ӝ Ӝ Ӝ           ",
      "Ӝ Ӝ Ӝ           ",
      "    n n         ",
      " ogccjgg        ",
      " oc    c        ",
      "       g        ",
      "  cccgcc        ",
      " PPPqqq         ",
      "     h          ",
      "                ",
      "                ",
      "    P           ",
      "   PP           "
    ],
    [
      "                ",
      "                ",
      "                ",
      "                ",
      "                ",
      "  n  n n        ",
      "  cvjggc        ",
      "  c    c        ",
      "  g    g        ",
      " ocgcjgc        ",
      "   q   q        ",
      "    hh          ",
      "     р          ",
      "                ",
      "                ",
      "                "
    ],
    [
      " q              ",
      "                ",
      "                ",
      "                ",
      "                ",
      "                ",
      " СоУССУС        ",
      " УСУССоУ        ",
      " оУСУСУС        ",
      " СУУСоСУ        ",
      "     h          ",
      "    Ҁ行ѿ         ",
      "     h          ",
      "                ",
      "                ",
      "                "
    ]
  ]
}