{
  "xsize": 16,
  "zsize": 16,
  "palette": {
    "palette": [
      {
        "char": " ",
        "block": "minecraft:air"
      },
      {
        "char": "c",
        "block": "minecraft:bricks"
      },
      {
        "char": "g",
        "block": "minecraft:air"
      },
      {
        "char": "e",
        "block": "minecraft:polished_andesite"
      },
      {
        "char": "b",
        "block": "minecraft:cracked_stone_bricks"
      },
      {
        "char": "ф",
        "block": "minecraft:polished_andesite_slab[type=bottom]"
      },
      {
        "char": "v",
        "block": "minecraft:bricks"
      },
      {
        "char": "f",
        "block": "minecraft:stone"
      },
      {
        "char": "F",
        "block": "minecraft:stone_slab[type=top]"
      },
      {
        "char": "I",
        "block": "minecraft:air"
      },
      {
        "char": "е",
        "block": "minecraft:air"
      },
      {
        "char": "ѹ",
        "block": "minecraft:air"
      },
      {
        "char": "Ѻ",
        "block": "minecraft:air"
      },
      {
        "char": "E",
        "block": "minecraft:smooth_stone_slab[type=bottom]"
      },
      {
        "char": "C",
        "block": "minecraft:air"
      },
      {
        "char": "j",
        "block": "minecraft:air"
      },
      {
        "char": "y",
        "block": "minecraft:polished_andesite_slab[type=top]"
      },
      {
        "char": "a",
        "block": "minecraft:stone_bricks"
      },
      {
        "char": "N",
        "block": "minecraft:stone_slab[type=bottom]"
      },
      {
        "char": "х",
        "block": "minecraft:air"
      },
      {
        "char": "m",
        "block": "minecraft:grass_block[snowy=false]"
      },
      {
        "char": "A",
        "block": "minecraft:dead_fire_coral_block"
      },
      {
        "char": "z",
        "block": "minecraft:dead_bubble_coral_block"
      },
      {
        "char": "B",
        "block": "minecraft:dead_brain_coral_block"
      },
      {
        "char": "情",
        "block": "minecraft:cobblestone"
      },
      {
        "char": "R",
        "block": "minecraft:cobblestone"
      },
      {
        "char": "p",
        "block": "minecraft:air"
      },
      {
        "char": "w",
        "block": "minecraft:air"
      },
      {
        "char": "G",
        "block": "minecraft:air"
      },
      {
        "char": "с",
        "block": "minecraft:air"
      },
      {
        "char": "Q",
        "block": "minecraft:air"
      },
      {
        "char": "i",
        "block": "minecraft:air"
      },
      {
        "char": "и",
        "block": "minecraft:air"
      },
      {
        "char": "P",
        "block": "minecraft:air"
      },
      {
        "char": "Ѱ",
        "block": "minecraft:rail[shape=south_east]"
      },
      {
        "char": "Ѳ",
        "block": "minecraft:rail[shape=south_west]"
      },
      {
        "char": "Ѯ",
        "block": "minecraft:rail[shape=north_east]"
      },
      {
        "char": "ѱ",
        "block": "minecraft:rail[shape=north_west]"
      }
    ]
  },
  "slices": [
    [
      "cgcebф          ",
      "vcvefF          ",
      "vvvefI          ",
      "ccceeI          ",
      "ccgefе          ",
      "ccceѹф          ",
      "gcgeѺE          ",
      "ccgeѺC          ",
      "jcgefy          ",
      "ggcefе          ",
      "gccebф          ",
      "gcgeeE          ",
      "jjceeC          ",
      "ggjefC          ",
      "ggjeaN          ",
      "eeeebх          "
    ],
    [
      "mmmv            ",
      "fAmvN           ",
      "mzmjх           ",
      "mBzvN           ",
      "mAAv            ",
      "mzmv            ",
      "BAmc            ",
      "情AmgE           ",
      "BzmgN           ",
      "RAzg            ",
      "mfmc            ",
      "mmmc            ",
      "mmmgх           ",
      "mmRcх           ",
      "Ammc            ",
      "fBzep           "
    ],
    [
      "wGGс            ",
      "EEGс            ",
      "GNG             ",
      "wQQс            ",
      "wQQ             ",
      "wNGс            ",
      " Ewс            ",
      " Nw             ",
      "iNwс            ",
      " E с            ",
      "w wс            ",
      "Gww             ",
      "GGwс            ",
      "wGiс            ",
      " wwс            ",
      " ииep           "
    ],
    [
      " PP             ",
      "  P             ",
      "P P             ",
      " ѰѲ             ",
      " Ѯѱ             ",
      "  P             ",
      "                ",
      "                ",
      "                ",
      "                ",
      "                ",
      "P               ",
      "PP              ",
      " P              ",
      "                ",
      "   i            "
    ],
    [
      "                ",
      "                ",
      "                ",
      "                ",
      "                ",
      "                ",
      "                ",
      "                ",
      "                ",
      "                ",
      "                ",
      "                ",
      "                ",
      "                ",
      "p               ",
      "                "
    ],
    [
      "                ",
      "                ",
      "                ",
      "                ",
      "                ",
      "                ",
      "                ",
      "                ",
      "                ",
      "                ",
      "                ",
      "                ",
      "                ",
      "p               ",
      "                ",
      "                "
    ]
  ]
}