{
  "xsize": 16,
  "zsize": 16,
  "palette": {
    "palette": [
      {
        "char": " ",
        "block": "minecraft:air"
      },
      {
        "char": "o",
        "block": "minecraft:air"
      },
      {
        "char": "e",
        "block": "minecraft:polished_andesite"
      },
      {
        "char": "l",
        "block": "minecraft:andesite"
      },
      {
        "char": "g",
        "block": "minecraft:air"
      },
      {
        "char": "c",
        "block": "minecraft:bricks"
      },
      {
        "char": "v",
        "block": "minecraft:bricks"
      },
      {
        "char": "j",
        "block": "minecraft:air"
      },
      {
        "char": "Ҿ",
        "block": "minecraft:air"
      },
      {
        "char": "m",
        "block": "minecraft:grass_block[snowy=false]"
      },
      {
        "char": "R",
        "block": "minecraft:cobblestone"
      },
      {
        "char": "f",
        "block": "minecraft:stone"
      },
      {
        "char": "A",
        "block": "minecraft:dead_fire_coral_block"
      },
      {
        "char": "z",
        "block": "minecraft:dead_bubble_coral_block"
      },
      {
        "char": "B",
        "block": "minecraft:dead_brain_coral_block"
      },
      {
        "char": "Ҷ",
        "block": "minecraft:stone"
      },
      {
        "char": "S",
        "block": "minecraft:air"
      },
      {
        "char": "я",
        "block": "minecraft:air"
      },
      {
        "char": "i",
        "block": "minecraft:air"
      },
      {
        "char": "з",
        "block": "minecraft:air"
      },
      {
        "char": "G",
        "block": "minecraft:air"
      },
      {
        "char": "w",
        "block": "minecraft:air"
      },
      {
        "char": "E",
        "block": "minecraft:smooth_stone_slab[type=bottom]"
      },
      {
        "char": "N",
        "block": "minecraft:stone_slab[type=bottom]"
      },
      {
        "char": "Q",
        "block": "minecraft:air"
      },
      {
        "char": "n",
        "block": "minecraft:air"
      },
      {
        "char": "p",
        "block": "minecraft:air"
      },
      {
        "char": "搞",
        "block": "minecraft:air"
      },
      {
        "char": "q",
        "block": "minecraft:air"
      },
      {
        "char": "р",
        "block": "minecraft:spruce_fence"
      },
      {
        "char": "P",
        "block": "minecraft:air"
      },
      {
        "char": "Ӛ",
        "block": "minecraft:air"
      },
      {
        "char": "h",
        "block": "minecraft:oak_leaves"
      },
      {
        "char": "С",
        "block": "minecraft:air"
      },
      {
        "char": "У",
        "block": "minecraft:brick_slab[type=bottom]"
      },
      {
        "char": "о",
        "block": "minecraft:air"
      },
      {
        "char": "Ҁ",
        "block": "minecraft:spruce_fence[east=true]"
      },
      {
        "char": "行",
        "block": "minecraft:spruce_fence[east=true,west=true]"
      },
      {
        "char": "ѿ",
        "block": "minecraft:spruce_fence[west=true]"
      }
    ]
  },
  "slices": [
    [
      "       oeeeeelel",
      "       oeggcvccg",
      "        ecjjcccg",
      "       olgcccgcc",
      "       olgggcjvv",
      "        lcjjjjcv",
      "        lgcccjjc",
      "        l Ҿ  gcc",
      "        e    cvv",
      "        eellleee",
      "        evvvccgc",
      "       olcvcggcg",
      "        egjcggcc",
      "        eccjcccg",
      "        ejcgcjcc",
      "        evcccvcg"
    ],
    [
      "        ljgggcvv",
      "        cmmmmmmm",
      "       ogRfAzAAB",
      "        cBmfmAmB",
      "        gzRffRAz",
      "        jmmmmmmm",
      "        cffҶAzmA",
      "        c  ҾSffz",
      "        g   SBBB",
      "        czfAffmf",
      "       ojmRmmmmm",
      "        gmBfmmmz",
      "        cABzffff",
      "        gffmBzzA",
      "        gAmmmBAm",
      "        gRmmmmAm"
    ],
    [
      "        eяiяяяяi",
      "        зGwGwwGG",
      "        iENQNQEQ",
      "        зEwQwQwQ",
      "        зEEQEQNQ",
      "        зwwwnwww",
      "        gccgjcwi",
      "        g    gp ",
      "       oc     搞i",
      "        gjjcggw ",
      "        зw qGGGw",
      "        зwр www ",
      "        зi     i",
      "        i  w i  ",
      "        iiwGw iw",
      "        i wGGw w"
    ],
    [
      "        i       ",
      "         P P  P ",
      "           Ӛ Ӛ Ӛ",
      "           Ӛ Ӛ Ӛ",
      "           Ӛ Ӛ Ӛ",
      "         n n    ",
      "        ggjccgp ",
      "        c    cp ",
      "        g       ",
      "        ccgccc  ",
      "         qqqP   ",
      "          h     ",
      "                ",
      "                ",
      "           P    ",
      "           PP   "
    ],
    [
      "                ",
      "                ",
      "                ",
      "                ",
      "                ",
      "        n n  n  ",
      "        cggjcc  ",
      "        c    c  ",
      "        g    g  ",
      "        cgjcgcp ",
      "        q   q   ",
      "          hh    ",
      "          р     ",
      "                ",
      "                ",
      "                "
    ],
    [
      "              q ",
      "                ",
      "                ",
      "                ",
      "                ",
      "                ",
      "        СУССУоС ",
      "        УоССУСУ ",
      "        СУСУСУо ",
      "        УСоСУУС ",
      "          h     ",
      "         Ҁ行ѿ    ",
      "          h     ",
      "                ",
      "                ",
      "                "
    ]
  ]
}