{
  "xsize": 16,
  "zsize": 16,
  "palette": {
    "palette": [
      {
        "char": " ",
        "block": "minecraft:air"
      },
      {
        "char": "n",
        "block": "minecraft:air"
      },
      {
        "char": "Я",
        "block": "minecraft:air"
      },
      {
        "char": "b",
        "block": "minecraft:cracked_stone_bricks"
      },
      {
        "char": "a",
        "block": "minecraft:stone_bricks"
      },
      {
        "char": "e",
        "block": "minecraft:polished_andesite"
      },
      {
        "char": "f",
        "block": "minecraft:stone"
      },
      {
        "char": "u",
        "block": "minecraft:stone_bricks"
      },
      {
        "char": "m",
        "block": "minecraft:grass_block[snowy=false]"
      },
      {
        "char": "R",
        "block": "minecraft:cobblestone"
      },
      {
        "char": "z",
        "block": "minecraft:dead_bubble_coral_block"
      },
      {
        "char": "A",
        "block": "minecraft:dead_fire_coral_block"
      },
      {
        "char": "B",
        "block": "minecraft:dead_brain_coral_block"
      },
      {
        "char": "G",
        "block": "minecraft:air"
      },
      {
        "char": "w",
        "block": "minecraft:air"
      },
      {
        "char": "q",
        "block": "minecraft:air"
      },
      {
        "char": "i",
        "block": "minecraft:air"
      },
      {
        "char": "Q",
        "block": "minecraft:air"
      },
      {
        "char": "N",
        "block": "minecraft:stone_slab[type=bottom]"
      },
      {
        "char": "E",
        "block": "minecraft:smooth_stone_slab[type=bottom]"
      },
      {
        "char": "р",
        "block": "minecraft:spruce_fence"
      },
      {
        "char": "л",
        "block": "minecraft:air"
      },
      {
        "char": "я",
        "block": "minecraft:air"
      },
      {
        "char": "P",
        "block": "minecraft:air"
      },
      {
        "char": "ц",
        "block": "minecraft:air"
      },
      {
        "char": "h",
        "block": "minecraft:oak_leaves"
      },
      {
        "char": "Ѱ",
        "block": "minecraft:rail[shape=south_east]"
      },
      {
        "char": "Ҁ",
        "block": "minecraft:spruce_fence[east=true]"
      },
      {
        "char": "ѿ",
        "block": "minecraft:spruce_fence[west=true]"
      }
    ]
  },
  "slices": [
    [
      "                ",
      "                ",
      "                ",
      "                ",
      "                ",
      "                ",
      "                ",
      "                ",
      "                ",
      "                ",
      "n Я  nn n n    n",
      "babbaaabaabaabab",
      "eeeeeeeeeeeeeeee",
      "fabaaaaaabaauabb",
      "fbbabbaaabbaabaa",
      "fbbaaauabbbaabaa"
    ],
    [
      "                ",
      "                ",
      "                ",
      "                ",
      "                ",
      "                ",
      "                ",
      "                ",
      "                ",
      "                ",
      "  n   n n n n  n",
      "baababbaabaabbab",
      "eeeeeeeeeeeeeeee",
      "emmmmmmmmRzfmmmm",
      "emmmmmmmAAfBfzzm",
      "emmfmzfffzAfRBff"
    ],
    [
      "                ",
      "                ",
      "                ",
      "                ",
      "                ",
      "                ",
      "                ",
      "                ",
      "                ",
      "                ",
      " n    nn   n n  ",
      "aabbbababbbbaabb",
      "eeeeeeeeeeeeeeee",
      "eGGwGGwGwqq wwww",
      "eGwwGGGw  ii   w",
      "ewGQNQEQiр iEEEл"
    ],
    [
      "                ",
      "                ",
      "                ",
      "                ",
      "                ",
      "                ",
      "                ",
      "                ",
      "                ",
      "                ",
      "  n n    n   n  ",
      "iiяяяяiiяяiяяяяi",
      " iii    ii   ii ",
      " PP PP P        ",
      " P  P           ",
      "i Pц ц ц h     Ѱ"
    ],
    [
      "                ",
      "                ",
      "                ",
      "                ",
      "                ",
      "                ",
      "                ",
      "                ",
      "                ",
      "                ",
      "                ",
      "                ",
      "                ",
      "                ",
      "         h      ",
      "        hhh     "
    ],
    [
      "                ",
      "                ",
      "                ",
      "                ",
      "                ",
      "                ",
      "                ",
      "                ",
      "                ",
      "                ",
      "                ",
      "                ",
      "                ",
      "                ",
      "         hh     ",
      "        hҀѿ     "
    ]
  ]
}