{
  "xsize": 16,
  "zsize": 16,
  "palette": {
    "palette": [
      {
        "char": " ",
        "block": "minecraft:air"
      },
      {
        "char": "f",
        "block": "minecraft:stone"
      },
      {
        "char": "e",
        "block": "minecraft:polished_andesite"
      },
      {
        "char": "u",
        "block": "minecraft:stone_bricks"
      },
      {
        "char": "е",
        "block": "minecraft:air"
      },
      {
        "char": "b",
        "block": "minecraft:cracked_stone_bricks"
      },
      {
        "char": "l",
        "block": "minecraft:andesite"
      },
      {
        "char": "a",
        "block": "minecraft:stone_bricks"
      },
      {
        "char": "F",
        "block": "minecraft:stone_slab[type=top]"
      },
      {
        "char": "C",
        "block": "minecraft:air"
      },
      {
        "char": "E",
        "block": "minecraft:smooth_stone_slab[type=bottom]"
      },
      {
        "char": "I",
        "block": "minecraft:air"
      },
      {
        "char": "m",
        "block": "minecraft:grass_block[snowy=false]"
      },
      {
        "char": "z",
        "block": "minecraft:dead_bubble_coral_block"
      },
      {
        "char": "R",
        "block": "minecraft:cobblestone"
      },
      {
        "char": "H",
        "block": "minecraft:smooth_stone_slab[type=top]"
      },
      {
        "char": "B",
        "block": "minecraft:dead_brain_coral_block"
      },
      {
        "char": "A",
        "block": "minecraft:dead_fire_coral_block"
      },
      {
        "char": "i",
        "block": "minecraft:air"
      },
      {
        "char": "下",
        "block": "minecraft:quartz_block"
      },
      {
        "char": "提",
        "block": "minecraft:polished_diorite"
      },
      {
        "char": "好",
        "block": "minecraft:calcite"
      },
      {
        "char": "w",
        "block": "minecraft:air"
      },
      {
        "char": "G",
        "block": "minecraft:air"
      },
      {
        "char": "p",
        "block": "minecraft:air"
      },
      {
        "char": "Q",
        "block": "minecraft:air"
      },
      {
        "char": "л",
        "block": "minecraft:air"
      },
      {
        "char": "N",
        "block": "minecraft:stone_slab[type=bottom]"
      },
      {
        "char": "o",
        "block": "minecraft:air"
      },
      {
        "char": "开",
        "block": "minecraft:smooth_quartz"
      },
      {
        "char": "ӷ",
        "block": "minecraft:diorite"
      },
      {
        "char": "Ь",
        "block": "minecraft:air"
      },
      {
        "char": "ѿ",
        "block": "minecraft:spruce_fence[west=true]"
      },
      {
        "char": "P",
        "block": "minecraft:air"
      },
      {
        "char": "Ѳ",
        "block": "minecraft:rail[shape=south_west]"
      },
      {
        "char": "ѱ",
        "block": "minecraft:rail[shape=north_west]"
      },
      {
        "char": "щ",
        "block": "minecraft:air"
      },
      {
        "char": "h",
        "block": "minecraft:oak_leaves"
      },
      {
        "char": "处",
        "block": "minecraft:spruce_fence[east=true,south=true]"
      },
      {
        "char": "全",
        "block": "minecraft:spruce_fence[north=true,south=true]"
      },
      {
        "char": "Ӄ",
        "block": "minecraft:spruce_fence[north=true]"
      }
    ]
  },
  "slices": [
    [
      "fffeuе          ",
      "bfflaF          ",
      "afblbF          ",
      "fuaefC          ",
      "ffuebE          ",
      "ffalbF          ",
      "ffblbC          ",
      "bfaeaF          ",
      "bfbeuе          ",
      "bffefI          ",
      "faaebI          ",
      "fbbefF          ",
      "ffaeaE          ",
      "bbbebе          ",
      "aafeaF          ",
      "ffflfI          "
    ],
    [
      "mmmeE           ",
      "zmmeE           ",
      "zmmeE           ",
      "RmmeH           ",
      "fmfeE           ",
      "BAzeEi          ",
      "RRze下i          ",
      "AAze            ",
      "fAfeE           ",
      "fAze提i          ",
      "BAzeE           ",
      "zBze提           ",
      "BffeH           ",
      "fzBeE           ",
      "Amze            ",
      "mmme好           "
    ],
    [
      "wwGep           ",
      "QwGe            ",
      "лwwep           ",
      "Nwwe            ",
      "лwie            ",
      "лi ep           ",
      "E oe开           ",
      "Q ie            ",
      "Q ie            ",
      "   e提           ",
      " iie            ",
      "Eioeӷ           ",
      "E Ьe            ",
      "Qѿ e            ",
      "Qwoe            ",
      "wwGe开           "
    ],
    [
      "  Pi            ",
      "Ѳ Pi            ",
      "ѱ  i            ",
      "   i            ",
      "Ѳ               ",
      "ѱ               ",
      "   i            ",
      "Ѳ  i提           ",
      "ѱ               ",
      "    提           ",
      "                ",
      "    好           ",
      "   i            ",
      "щh i            ",
      "щ  i            ",
      "  Pi提           "
    ],
    [
      "                ",
      "                ",
      "                ",
      "                ",
      "                ",
      "                ",
      "                ",
      "                ",
      "    下           ",
      "    ӷ           ",
      "                ",
      "    开           ",
      " 处ѿ ӷ           ",
      "h全h             ",
      " Ӄ              ",
      "    提           "
    ],
    [
      "                ",
      "                ",
      "                ",
      "                ",
      "                ",
      "                ",
      "                ",
      "    下           ",
      "                ",
      "    开           ",
      "                ",
      "    ӷ           ",
      " hh             ",
      "hhh 下           ",
      " h              ",
      "    下           "
    ]
  ]
}