{
  "xsize": 16,
  "zsize": 16,
  "palette": {
    "palette": [
      {
        "char": " ",
        "block": "minecraft:air"
      },
      {
        "char": "o",
        "block": "minecraft:vine[east=false,north=false,south=true,up=false,west=false]"
      },
      {
        "char": "y",
        "block": "minecraft:air"
      },
      {
        "char": "g",
        "block": "minecraft:vine[east=false,north=false,south=false,up=false,west=true]"
      },
      {
        "char": "d",
        "block": "minecraft:cracked_stone_bricks"
      },
      {
        "char": "a",
        "block": "minecraft:stone_bricks"
      },
      {
        "char": "c",
        "block": "minecraft:mossy_stone_bricks"
      },
      {
        "char": "ϣ",
        "block": "minecraft:smooth_quartz_slab[type=double]"
      },
      {
        "char": "Ϯ",
        "block": "minecraft:smooth_quartz_slab[type=bottom]"
      },
      {
        "char": "h",
        "block": "minecraft:glass_pane[east=false,north=true,south=true,west=false]"
      },
      {
        "char": "p",
        "block": "minecraft:gray_carpet"
      },
      {
        "char": "α",
        "block": "minecraft:stone_brick_stairs[facing=north,half=bottom,shape=straight]"
      },
      {
        "char": "n",
        "block": "minecraft:light_gray_carpet"
      },
      {
        "char": "Н",
        "block": "minecraft:oak_door[facing=north,half=lower,hinge=right,open=true]"
      },
      {
        "char": "Ί",
        "block": "minecraft:stone_brick_stairs[facing=west,half=bottom,shape=straight]"
      },
      {
        "char": "О",
        "block": "minecraft:oak_door[facing=north,half=upper,hinge=right,open=true]"
      },
      {
        "char": "γ",
        "block": "minecraft:vine[east=true,north=true,south=false,up=false,west=false]"
      },
      {
        "char": "w",
        "block": "minecraft:bookshelf"
      },
      {
        "char": "z",
        "block": "minecraft:air"
      },
      {
        "char": "Е",
        "block": "minecraft:stone_bricks"
      },
      {
        "char": "i",
        "block": "minecraft:vine[east=false,north=true,south=false,up=false,west=false]"
      },
      {
        "char": "j",
        "block": "minecraft:vine[east=true,north=false,south=false,up=false,west=false]"
      },
      {
        "char": "Ъ",
        "block": "minecraft:redstone_lamp[lit=true]"
      },
      {
        "char": "ϥ",
        "block": "minecraft:stone_brick_stairs[facing=west,half=top,shape=straight]"
      },
      {
        "char": "e",
        "block": "minecraft:mossy_cobblestone"
      },
      {
        "char": "b",
        "block": "minecraft:cobblestone"
      },
      {
        "char": "Β",
        "block": "minecraft:cobblestone"
      },
      {
        "char": "f",
        "block": "minecraft:stone"
      },
      {
        "char": "ҧ",
        "block": "minecraft:lever[face=floor,facing=south,powered=true]"
      },
      {
        "char": "k",
        "block": "minecraft:glass_pane[east=true,north=false,south=false,west=true]"
      },
      {
        "char": "Ж",
        "block": "minecraft:dark_oak_trapdoor[facing=west,half=top,open=true]"
      },
      {
        "char": "К",
        "block": "minecraft:dark_oak_trapdoor[facing=east,half=top,open=true]"
      },
      {
        "char": "а",
        "block": "minecraft:dark_oak_trapdoor[facing=south,half=top,open=true]"
      }
    ]
  },
  "slices": [
    [
      "                ",
      "                ",
      "                ",
      "                ",
      "                ",
      "                ",
      "      ooo       ",
      "        yg      ",
      "ddaaadca g      ",
      " ϣϮaa  d        ",
      " ϣϮaa  d        ",
      " ϣϮa a h        ",
      " ϣϮapααh        ",
      " ϣϣap nh        ",
      "Нaaa pnc        ",
      " nnapn cΊ       "
    ],
    [
      "                ",
      "                ",
      "                ",
      "                ",
      "                ",
      "                ",
      "      ooo       ",
      "        yg      ",
      "daacaaaa g      ",
      "   aaaac        ",
      "   aaaac        ",
      "   a ααh        ",
      "   a   h        ",
      "   a   h        ",
      "Оaaa   a        ",
      "   a   a        "
    ],
    [
      "                ",
      "                ",
      "                ",
      "                ",
      "                ",
      "                ",
      "      ooo       ",
      "        yg      ",
      "dcaacaad g      ",
      "   aΊγwa        ",
      "   aΊ γa        ",
      "   a   h        ",
      "   a   h        ",
      "   a   h        ",
      "aaaa   c        ",
      "   a   d        "
    ],
    [
      "                ",
      "                ",
      "                ",
      "                ",
      "                ",
      "                ",
      "      ooo       ",
      "        zg      ",
      "aaacЕcdd g      ",
      "   Ίiγγd        ",
      "   Ί  jc        ",
      "   a   h        ",
      "   a   h        ",
      "   a   h        ",
      "Ъaaa   a        ",
      "   a   dϥ       "
    ],
    [
      "                ",
      "                ",
      "                ",
      "                ",
      "                ",
      "                ",
      "      ooo       ",
      "ebbbbbbΒeg      ",
      "fbbΒΒΒeeeg      ",
      "bbΊ iγγbe       ",
      "fbΊ   jfb       ",
      "bfba   bb       ",
      "fbfebfbbe       ",
      "bbbebfebe       ",
      "ҧbbbebbbf       ",
      "bebaaaabb       "
    ],
    [
      "                ",
      "                ",
      "                ",
      "                ",
      "                ",
      "                ",
      "      ooo       ",
      "        yg      ",
      "cckkkЕЕЕ g      ",
      "n    γγd        ",
      " p    jd        ",
      "np n   a        ",
      "Нaaaaaad        ",
      "ЖwКwww a        ",
      "nа     a        ",
      "   pnn aΊ       "
    ]
  ]
}