{
  "xsize": 16,
  "zsize": 16,
  "palette": {
    "palette": [
      {
        "char": " ",
        "block": "minecraft:air"
      },
      {
        "char": "b",
        "block": "minecraft:quartz_pillar[axis=y]"
      },
      {
        "char": "h",
        "block": "minecraft:mossy_stone_bricks"
      },
      {
        "char": "͵",
        "block": "minecraft:spruce_fence[north=true,west=true]"
      },
      {
        "char": "i",
        "block": "minecraft:cracked_stone_bricks"
      },
      {
        "char": "ͷ",
        "block": "minecraft:stone_brick_stairs[facing=west,half=top,shape=straight]"
      },
      {
        "char": "ͼ",
        "block": "minecraft:stone_brick_stairs[facing=north,half=top,shape=straight]"
      },
      {
        "char": "d",
        "block": "minecraft:glass"
      },
      {
        "char": "0",
        "block": "minecraft:ladder[facing=south]"
      },
      {
        "char": "j",
        "block": "minecraft:stone_bricks"
      },
      {
        "char": "n",
        "block": "minecraft:vine[east=false,north=false,south=false,up=false,west=true]"
      },
      {
        "char": "A",
        "block": "minecraft:vine[east=false,north=true,south=false,up=false,west=true]"
      },
      {
        "char": "m",
        "block": "minecraft:vine[east=false,north=true,south=false,up=false,west=false]"
      },
      {
        "char": "g",
        "block": "minecraft:smooth_stone_slab[type=double]"
      },
      {
        "char": "o",
        "block": "minecraft:mossy_cobblestone"
      },
      {
        "char": "c",
        "block": "minecraft:cobblestone"
      },
      {
        "char": "z",
        "block": "minecraft:smooth_stone_slab[type=top]"
      },
      {
        "char": "t",
        "block": "minecraft:stone"
      },
      {
        "char": "F",
        "block": "minecraft:air"
      },
      {
        "char": "E",
        "block": "minecraft:redstone_lamp[lit=false]"
      },
      {
        "char": "P",
        "block": "minecraft:air"
      },
      {
        "char": "T",
        "block": "minecraft:air"
      },
      {
        "char": "5",
        "block": "minecraft:air"
      },
      {
        "char": "N",
        "block": "minecraft:air"
      },
      {
        "char": "J",
        "block": "minecraft:air"
      },
      {
        "char": "4",
        "block": "minecraft:air"
      },
      {
        "char": "ΐ",
        "block": "minecraft:quartz_stairs[facing=east,half=bottom,shape=straight]"
      },
      {
        "char": "Z",
        "block": "minecraft:air"
      },
      {
        "char": "Ͱ",
        "block": "minecraft:stone_button[face=wall,facing=north,powered=false]"
      },
      {
        "char": "r",
        "block": "minecraft:smooth_stone_slab[type=bottom]"
      }
    ]
  },
  "slices": [
    [
      "   b       h    ",
      "  b͵  iͷ  i     ",
      "bb    ͼ   d     ",
      "0         d     ",
      "   jͷ     d     ",
      "   ͼ     dn     ",
      "        jA      ",
      "       dA       ",
      "   idddm        ",
      "ddin            ",
      " mm             ",
      "                ",
      "                ",
      "                ",
      "                ",
      "                "
    ],
    [
      "b bb   ggggo    ",
      "  b͵  ggggc     ",
      "bb    ggggh     ",
      "0z   gggggi     ",
      "zz gggggggh     ",
      "ggggggggghn     ",
      "ggggggggtA      ",
      "gggggggjA       ",
      "gggcjjhm        ",
      "hion            ",
      " mm             ",
      "                ",
      "                ",
      "                ",
      "                ",
      "                "
    ],
    [
      "   b   F   i    ",
      "  bE  PT  h     ",
      "bb    F   d     ",
      "0F   PT   d     ",
      " F P5T    d     ",
      " N5T     d      ",
      "        hA      ",
      "  PJ   dA       ",
      "  4idddm        ",
      "ddhn            ",
      " mm             ",
      "                ",
      "                ",
      "                ",
      "                ",
      "                "
    ],
    [
      "ΐb b       h    ",
      "bbb       h     ",
      "bb        d     ",
      "          d     ",
      "          d     ",
      "         d      ",
      "        jA      ",
      "   Z   dA       ",
      "   hdddm        ",
      "ddin            ",
      " mm             ",
      "                ",
      "                ",
      "                ",
      "                ",
      "                "
    ],
    [
      " Ͱbb       o    ",
      "bbb       t     ",
      "bb        i     ",
      "          j     ",
      "          i     ",
      "         i      ",
      "        oA      ",
      "   Z   hA       ",
      "   cjjjm        ",
      "jjon            ",
      " mm             ",
      "                ",
      "                ",
      "                ",
      "                ",
      "                "
    ],
    [
      " Ͱbr      4j    ",
      "bbr       h     ",
      "rr        d     ",
      "          d     ",
      "          d     ",
      "         d      ",
      "        iA      ",
      "   Z   dA       ",
      "   hdddm        ",
      "ddin            ",
      " mm             ",
      "                ",
      "                ",
      "                ",
      "                ",
      "                "
    ]
  ]
}