{
  "xsize": 16,
  "zsize": 16,
  "palette": {
    "palette": [
      {
        "char": " ",
        "block": "minecraft:air"
      },
      {
        "char": "l",
        "block": "minecraft:vine[east=false,north=false,south=true,up=false,west=false]"
      },
      {
        "char": "a",
        "block": "minecraft:stone_bricks"
      },
      {
        "char": "i",
        "block": "minecraft:mossy_stone_bricks"
      },
      {
        "char": "h",
        "block": "minecraft:cracked_stone_bricks"
      },
      {
        "char": "π",
        "block": "minecraft:ladder[facing=south]"
      },
      {
        "char": "o",
        "block": "minecraft:vine[east=false,north=false,south=false,up=false,west=true]"
      },
      {
        "char": "q",
        "block": "minecraft:smooth_stone_slab[type=bottom]"
      },
      {
        "char": "Δ",
        "block": "minecraft:oak_trapdoor[facing=south,half=bottom,open=false]"
      },
      {
        "char": "Μ",
        "block": "minecraft:daylight_detector[inverted=true]",
        "tag": {
          "z": 327,
          "x": 75,
          "ForgeCaps": {},
          "id": "minecraft:daylight_detector",
          "y": 145
        }
      },
      {
        "char": "ͳ",
        "block": "minecraft:daylight_detector[inverted=false]",
        "tag": {
          "z": 337,
          "x": 75,
          "ForgeCaps": {},
          "id": "minecraft:daylight_detector",
          "y": 145
        }
      },
      {
        "char": "y",
        "block": "minecraft:quartz_block"
      },
      {
        "char": "θ",
        "block": "minecraft:powered_rail[powered=false,shape=east_west]"
      },
      {
        "char": "ϕ",
        "block": "minecraft:detector_rail[powered=false,shape=east_west]"
      }
    ]
  },
  "slices": [
    [
      "                ",
      "                ",
      "                ",
      "                ",
      "                ",
      "   llll         ",
      "aiihiahhhihhi   ",
      "ahiiihπaiihhh   ",
      "hahhhhihihhhh   ",
      "haahiiaiaiaia   ",
      "hiiiaiiaiihii   ",
      "iiihaiaiiahhh   ",
      "ihhiaihhihihi   ",
      "hhihaiaiihahh   ",
      "iiahhhaiihahio  ",
      "ahhhhhhiaahhio  "
    ],
    [
      "                ",
      "                ",
      "                ",
      "                ",
      "                ",
      "                ",
      "qqqqqqqqqqqqq   ",
      "      Δ    Μq   ",
      "           ͳq   ",
      "        yy ͳq   ",
      "        yy ͳq   ",
      "q       yy ͳq   ",
      "           ͳq   ",
      "q          ͳq   ",
      "    q      ͳq   ",
      "  q   q    ͳq   "
    ],
    [
      "                ",
      "                ",
      "                ",
      "                ",
      "                ",
      "                ",
      "                ",
      "                ",
      "                ",
      "        θθ      ",
      "        ϕϕ      ",
      "        θθ      ",
      "                ",
      "                ",
      "                ",
      "                "
    ],
    [
      "                ",
      "                ",
      "                ",
      "                ",
      "                ",
      "                ",
      "                ",
      "                ",
      "                ",
      "                ",
      "                ",
      "                ",
      "                ",
      "                ",
      "                ",
      "                "
    ],
    [
      "                ",
      "                ",
      "                ",
      "                ",
      "                ",
      "                ",
      "                ",
      "                ",
      "                ",
      "                ",
      "                ",
      "                ",
      "                ",
      "                ",
      "                ",
      "                "
    ],
    [
      "                ",
      "                ",
      "                ",
      "                ",
      "                ",
      "                ",
      "                ",
      "                ",
      "                ",
      "                ",
      "                ",
      "                ",
      "                ",
      "                ",
      "                ",
      "                "
    ]
  ]
}