{
  "xsize": 16,
  "zsize": 16,
  "palette": {
    "palette": [
      {
        "char": " ",
        "block": "minecraft:air"
      },
      {
        "char": "a",
        "block": "minecraft:grass_block[snowy=false]"
      },
      {
        "char": "x",
        "block": "minecraft:dirt"
      },
      {
        "char": "b",
        "block": "minecraft:air"
      },
      {
        "char": "p",
        "block": "minecraft:air"
      },
      {
        "char": "e",
        "block": "minecraft:spruce_slab[type=top]"
      },
      {
        "char": "d",
        "block": "minecraft:oak_slab[type=top]"
      },
      {
        "char": "A",
        "block": "minecraft:oak_fence"
      },
      {
        "char": "h",
        "block": "minecraft:oak_stairs[facing=east,half=bottom,shape=straight]"
      },
      {
        "char": "Y",
        "block": "minecraft:oak_fence[east=true]"
      },
      {
        "char": "L",
        "block": "minecraft:spruce_slab[type=double]"
      },
      {
        "char": "y",
        "block": "minecraft:vine[east=false,north=true,south=false,up=false,west=false]"
      },
      {
        "char": "i",
        "block": "minecraft:oak_fence[north=true,south=true]"
      },
      {
        "char": "m",
        "block": "minecraft:oak_fence[east=true,north=true,south=true]"
      },
      {
        "char": "c",
        "block": "minecraft:spruce_planks"
      },
      {
        "char": "k",
        "block": "minecraft:oak_slab[type=double]"
      },
      {
        "char": "0",
        "block": "minecraft:oak_fence[north=true]"
      },
      {
        "char": "ρ",
        "block": "minecraft:air"
      },
      {
        "char": "o",
        "block": "minecraft:oak_fence[east=true,west=true]"
      },
      {
        "char": "w",
        "block": "minecraft:oak_fence[east=true,north=true,west=true]"
      },
      {
        "char": "ή",
        "block": "minecraft:air"
      },
      {
        "char": "ͱ",
        "block": "minecraft:glass_pane[east=true,north=false,south=false,west=true]"
      },
      {
        "char": "G",
        "block": "minecraft:oak_fence[east=true,north=true]"
      },
      {
        "char": "E",
        "block": "minecraft:oak_fence[north=true,west=true]"
      },
      {
        "char": "n",
        "block": "minecraft:spruce_slab[type=bottom]"
      },
      {
        "char": "q",
        "block": "minecraft:oak_stairs[facing=south,half=bottom,shape=straight]"
      },
      {
        "char": "z",
        "block": "minecraft:spruce_stairs[facing=east,half=bottom,shape=straight]"
      },
      {
        "char": "ͳ",
        "block": "minecraft:oak_fence_gate[facing=north,in_wall=false,open=false]"
      },
      {
        "char": "t",
        "block": "minecraft:vine[east=true,north=false,south=false,up=false,west=false]"
      },
      {
        "char": "f",
        "block": "minecraft:oak_planks"
      },
      {
        "char": "Ͱ",
        "block": "minecraft:oak_stairs[facing=west,half=top,shape=straight]"
      }
    ]
  },
  "slices": [
    [
      "aaaaaaaaaaaaaaaa",
      "aaaaaaaaaaaaaaaa",
      "aaaaaaaxaaaaaaaa",
      "aaaaaaaxaaaaaaaa",
      "aaaaaaaaxaaaaaaa",
      "aaaaaaaaaaaaaaaa",
      "aaaaaaaaaaaaaaaa",
      "aaaaaaaaaaaaaaaa",
      "aaaaaaaaaaaaaaaa",
      "aaaaaaaaaaaaaaaa",
      "aaaaaaaaaaaaaaaa",
      "aaaaaaaaaaaaaaaa",
      "aaaaaaaaaaaaaaaa",
      "aaaaaaaaaaaaaaaa",
      "aaaaaaaaaaaaaaaa",
      "aaaaaaaaaaaaaaaa"
    ],
    [
      "bpbbbb  eddddddd",
      "bbbbbbbAeddddddd",
      "ppbb   hdddddddd",
      "bbbp   hdddddddd",
      "bbpbbbbYLeeeeeee",
      "bbbbbbb bbb bbyb",
      "bbbbb b   bbbbbb",
      "pbbp bb bbb  b  ",
      "bbbbbbb bbb  b b",
      "bbbbbbbbbbbbbbbb",
      "bbbbb bbbb  bbb ",
      "pbbpbbbbbbbb  bb",
      "ppbbbb b  bbbbbb",
      "bbpbbbbbbbbb b b",
      "bbbb bbbbb bbbbb",
      "bbpbbbbbbbbbbb b"
    ],
    [
      "        i mck   ",
      "        0 mck   ",
      "          mck  ρ",
      "          mccccc",
      "        Yowwwwww",
      "              y ",
      "                ",
      "                ",
      "                ",
      "                ",
      "                ",
      "                ",
      "                ",
      "                ",
      "                ",
      "                "
    ],
    [
      "          mck   ",
      "        A mck   ",
      "          mck  ή",
      "          mccͱͱͱ",
      "        A GwE   ",
      "              y ",
      "                ",
      "                ",
      "                ",
      "                ",
      "                ",
      "                ",
      "                ",
      "                ",
      "                ",
      "                "
    ],
    [
      "        nhkcq   ",
      "        nhkck   ",
      "        nhkck   ",
      "        nhkccccc",
      "        nzkwwͳͳͳ",
      "              y ",
      "                ",
      "                ",
      "                ",
      "                ",
      "                ",
      "                ",
      "                ",
      "                ",
      "                ",
      "                "
    ],
    [
      "        t hc fff",
      "        t hcqfff",
      "          hkffff",
      "          hccccc",
      "          zͰGwww",
      "              y ",
      "                ",
      "                ",
      "                ",
      "                ",
      "                ",
      "                ",
      "                ",
      "                ",
      "                ",
      "                "
    ]
  ]
}