{
  "xsize": 16,
  "zsize": 16,
  "palette": {
    "palette": [
      {
        "char": " ",
        "block": "minecraft:air"
      },
      {
        "char": "p",
        "block": "minecraft:quartz_stairs[facing=south,half=bottom,shape=straight]"
      },
      {
        "char": "a",
        "block": "minecraft:polished_andesite_slab[type=top]"
      },
      {
        "char": "Ύ",
        "block": "minecraft:note_block"
      },
      {
        "char": "q",
        "block": "minecraft:granite"
      },
      {
        "char": "h",
        "block": "minecraft:bricks"
      },
      {
        "char": "Ά",
        "block": "minecraft:polished_andesite_slab[type=double]"
      },
      {
        "char": "J",
        "block": "minecraft:air"
      },
      {
        "char": "ΰ",
        "block": "minecraft:vine[east=false,north=false,south=false,up=true,west=true]"
      },
      {
        "char": "Ζ",
        "block": "minecraft:vine[east=true,north=true,south=true,up=false,west=true]"
      },
      {
        "char": "΄",
        "block": "minecraft:quartz_stairs[facing=south,half=bottom,shape=outer_right]"
      },
      {
        "char": "b",
        "block": "minecraft:polished_andesite"
      },
      {
        "char": "x",
        "block": "minecraft:quartz_stairs[facing=west,half=bottom,shape=straight]"
      },
      {
        "char": "e",
        "block": "minecraft:andesite"
      },
      {
        "char": "f",
        "block": "minecraft:grass_block[snowy=false]"
      },
      {
        "char": "w",
        "block": "minecraft:terracotta"
      },
      {
        "char": "n",
        "block": "minecraft:air"
      },
      {
        "char": "A",
        "block": "minecraft:quartz_pillar[axis=y]"
      },
      {
        "char": "Υ",
        "block": "minecraft:rail[shape=south_west]"
      },
      {
        "char": "Φ",
        "block": "minecraft:rail[shape=south_east]"
      },
      {
        "char": "Χ",
        "block": "minecraft:rail[shape=north_west]"
      },
      {
        "char": "Ο",
        "block": "minecraft:rail[shape=north_east]"
      }
    ]
  },
  "slices": [
    [
      "ppppppppppppppp ",
      "aΎaaaaaaaaaaΎq  ",
      "aaaaaaaaaaaaah  ",
      "aaaaaaaaaaaaaq  ",
      "aaaaaaaaaaaaah  ",
      "Άaaaaaaaaaaaah  ",
      "aaaaaaaaaaaaah  ",
      "ΆaaaaaaaaaaaaJΰ ",
      "aaaaaaaaaaaaah  ",
      "aaaaaaaaΆaΆaah  ",
      "Άaaaaaaaaaaaah  ",
      "aaaaaaaaaaaaah  ",
      "Άaaaaaaaaaaaah  ",
      "aaaaaaaaaaaaah  ",
      "aaaaaaaaaaaaaq  ",
      "aaaaaΖ aaaaaah  "
    ],
    [
      "                ",
      "pppppppppppppp΄ ",
      "bbbbbbbbbbbbbhx ",
      "ebeebebfeebbehx ",
      "eeebbbebbbebehx ",
      "bbebbebbeebbbqx ",
      "bbbebeeebeebbqx ",
      "beebbebebebebwx ",
      "eeebbbeebbbfeqx ",
      "bbebeeeebbbbbhx ",
      "bbebbbeebbbebhx ",
      "eebbbbbeeebbbhx ",
      "bbbebbeebebbehx ",
      "eebbbbeebebeehx ",
      "bbe eb bebeeehx ",
      "bebbeΖeebbbebhx "
    ],
    [
      "                ",
      "                ",
      "ppppppppppppp΄  ",
      "       n     x  ",
      "             x  ",
      "             x  ",
      "A AA AA      x  ",
      "A AA AA      x  ",
      "             x  ",
      "A AA AA      x  ",
      "A AA AA      x  ",
      "             x  ",
      "             x  ",
      "    b        x  ",
      "             x  ",
      "       b     x  "
    ],
    [
      "                ",
      "                ",
      "                ",
      "                ",
      "                ",
      "                ",
      "Υ ΦΥ ΦΥ         ",
      "Χ ΟΧ ΟΧ         ",
      "                ",
      "Υ ΦΥ ΦΥ         ",
      "Χ ΟΧ ΟΧ         ",
      "                ",
      "                ",
      "                ",
      "                ",
      "                "
    ],
    [
      "                ",
      "                ",
      "                ",
      "                ",
      "                ",
      "                ",
      "                ",
      "                ",
      "                ",
      "                ",
      "                ",
      "                ",
      "                ",
      "                ",
      "                ",
      "                "
    ],
    [
      "                ",
      "                ",
      "                ",
      "                ",
      "                ",
      "                ",
      "                ",
      "                ",
      "                ",
      "                ",
      "                ",
      "                ",
      "                ",
      "                ",
      "                ",
      "                "
    ]
  ]
}