{
  "xsize": 16,
  "zsize": 16,
  "palette": {
    "palette": [
      {
        "char": " ",
        "block": "minecraft:air"
      },
      {
        "char": "a",
        "block": "minecraft:smooth_stone"
      },
      {
        "char": "b",
        "block": "minecraft:grass_block[snowy=false]"
      },
      {
        "char": "T",
        "block": "minecraft:red_wool"
      },
      {
        "char": "S",
        "block": "minecraft:red_concrete_powder"
      },
      {
        "char": "i",
        "block": "minecraft:red_concrete"
      },
      {
        "char": "Σ",
        "block": "minecraft:glass"
      },
      {
        "char": "U",
        "block": "minecraft:red_terracotta"
      },
      {
        "char": "Ω",
        "block": "minecraft:smooth_quartz_stairs[facing=east,half=top,shape=outer_left]"
      },
      {
        "char": "Γ",
        "block": "minecraft:smooth_quartz_stairs[facing=north,half=top,shape=straight]"
      },
      {
        "char": "϶",
        "block": "minecraft:smooth_quartz_stairs[facing=west,half=top,shape=outer_right]"
      },
      {
        "char": "t",
        "block": "minecraft:smooth_quartz_slab[type=top]"
      },
      {
        "char": "Ђ",
        "block": "minecraft:diorite_stairs[facing=west,half=top,shape=outer_right]"
      },
      {
        "char": "P",
        "block": "minecraft:diorite_slab[type=top]"
      },
      {
        "char": "ϭ",
        "block": "minecraft:diorite_stairs[facing=north,half=top,shape=straight]"
      },
      {
        "char": "E",
        "block": "minecraft:quartz_pillar[axis=y]"
      },
      {
        "char": "d",
        "block": "minecraft:air"
      },
      {
        "char": "r",
        "block": "minecraft:smooth_quartz_slab[type=bottom]"
      },
      {
        "char": "W",
        "block": "minecraft:air"
      },
      {
        "char": "G",
        "block": "minecraft:diorite_slab[type=bottom]"
      },
      {
        "char": "X",
        "block": "minecraft:polished_andesite_slab[type=bottom]"
      },
      {
        "char": "l",
        "block": "minecraft:air"
      },
      {
        "char": "ε",
        "block": "minecraft:rail[shape=north_east]"
      },
      {
        "char": "Ϗ",
        "block": "minecraft:rail[shape=north_west]"
      },
      {
        "char": "V",
        "block": "minecraft:air"
      },
      {
        "char": "ό",
        "block": "minecraft:rail[shape=south_east]"
      },
      {
        "char": "π",
        "block": "minecraft:rail[shape=south_west]"
      }
    ]
  },
  "slices": [
    [
      "aaaaaaaaaaaaaabT",
      "aaaaaaaaaaaaabbS",
      "aaaaaaaaaaaaaabi",
      "aaaaaaaaaaaaaaai",
      "aaaaaaaaaaaaaabi",
      "ΣΣΣaaaaaaaaaaaaU",
      "aaaaaaaaaaaaaaaT",
      "aaaaaaaaaaaaaaai",
      "iiiiiiiiiiiiiiiS",
      "ΩΓ϶tttttΩΓЂPttPϭ",
      "                ",
      "                ",
      "                ",
      "                ",
      "                ",
      "                "
    ],
    [
      "           EEEdr",
      "             WdG",
      "            EEWr",
      "            EE r",
      "XXXX          dr",
      "   X        EE G",
      "XXXX        EE G",
      "               r",
      "rrrrrrrrrrrrGGGr",
      "llllllllllllllll",
      "                ",
      "                ",
      "                ",
      "                ",
      "                ",
      "                "
    ],
    [
      "           εϏ   ",
      "             V  ",
      "            όπV ",
      "            εϏ  ",
      "                ",
      "            όπ  ",
      "            εϏ  ",
      "                ",
      "                ",
      "                ",
      "                ",
      "                ",
      "                ",
      "                ",
      "                ",
      "                "
    ],
    [
      "                ",
      "                ",
      "                ",
      "                ",
      "                ",
      "                ",
      "                ",
      "                ",
      "                ",
      "                ",
      "                ",
      "                ",
      "                ",
      "                ",
      "                ",
      "                "
    ],
    [
      "                ",
      "                ",
      "                ",
      "                ",
      "                ",
      "                ",
      "                ",
      "                ",
      "                ",
      "                ",
      "                ",
      "                ",
      "                ",
      "                ",
      "                ",
      "                "
    ],
    [
      "                ",
      "                ",
      "                ",
      "                ",
      "                ",
      "                ",
      "                ",
      "                ",
      "                ",
      "                ",
      "                ",
      "                ",
      "                ",
      "                ",
      "                ",
      "                "
    ]
  ]
}