{
  "xsize": 16,
  "zsize": 16,
  "palette": {
    "palette": [
      {
        "char": " ",
        "block": "minecraft:air"
      },
      {
        "char": "a",
        "block": "minecraft:polished_andesite_slab[type=top]"
      },
      {
        "char": "w",
        "block": "minecraft:terracotta"
      },
      {
        "char": "h",
        "block": "minecraft:bricks"
      },
      {
        "char": "Ύ",
        "block": "minecraft:note_block"
      },
      {
        "char": "q",
        "block": "minecraft:granite"
      },
      {
        "char": "Ά",
        "block": "minecraft:polished_andesite_slab[type=double]"
      },
      {
        "char": "Ν",
        "block": "minecraft:vine[east=false,north=true,south=false,up=true,west=false]"
      },
      {
        "char": "t",
        "block": "minecraft:vine[east=false,north=true,south=false,up=false,west=false]"
      },
      {
        "char": "e",
        "block": "minecraft:andesite"
      },
      {
        "char": "b",
        "block": "minecraft:polished_andesite"
      },
      {
        "char": "x",
        "block": "minecraft:quartz_stairs[facing=west,half=bottom,shape=straight]"
      },
      {
        "char": "r",
        "block": "minecraft:quartz_stairs[facing=north,half=bottom,shape=straight]"
      },
      {
        "char": "ͽ",
        "block": "minecraft:quartz_stairs[facing=west,half=bottom,shape=outer_right]"
      },
      {
        "char": "Α",
        "block": "minecraft:quartz_stairs[facing=north,half=bottom,shape=outer_left]"
      }
    ]
  },
  "slices": [
    [
      "aaaaa aaaaaaaw  ",
      "aaaaaaaaaaaaah  ",
      "aaaaaaΎaaaaaΎq  ",
      "aaaaaaahhqwwhq  ",
      "aaaaaaawaaaaaq  ",
      "aaaaaaahaaaaaq  ",
      "aaaaaaahaahhhh  ",
      "aΆaaaaaqaahaaq  ",
      "aaaaaaawaahaaq  ",
      "aaaaaaaqaahaaw  ",
      "aaaaaaahaaqaaw  ",
      "aaaaaaaqaahaaq  ",
      "aaaaaaaqaawaah  ",
      "aaaaaaΎqaahaah  ",
      "wqhhhwwhqqwhhh  ",
      "     Ν    Νtt   "
    ],
    [
      "ebbe ebbbbeebhx ",
      "ebe  b ebeeeehx ",
      "beebeeeeebbbbqx ",
      "bbbeeeeeeeebbqx ",
      " eeebbbeeeeeehx ",
      "e beeeebbeebehx ",
      "   bebbbeeebbhx ",
      "bebeebeebebbbqx ",
      "ebeebeebebeeehx ",
      "bbbbbeeebeebehx ",
      "eebbeeeebbebewx ",
      "ebbebeeeeeebbwx ",
      "ebbbbbeebbeebwx ",
      "beeebeebebbbbhx ",
      "qqqwhhqhhhhhwqx ",
      "rrrrrrrrrrrrrrͽ "
    ],
    [
      "  b          x  ",
      "             x  ",
      "             x  ",
      "             x  ",
      "             x  ",
      "    b        x  ",
      "             x  ",
      "             x  ",
      "             x  ",
      "b            x  ",
      "             x  ",
      "             x  ",
      "             x  ",
      "             x  ",
      "rrrrrrrrrrrrrΑ  ",
      "                "
    ],
    [
      "                ",
      "                ",
      "                ",
      "                ",
      "                ",
      "                ",
      "                ",
      "                ",
      "                ",
      "                ",
      "                ",
      "                ",
      "                ",
      "                ",
      "                ",
      "                "
    ],
    [
      "                ",
      "                ",
      "                ",
      "                ",
      "                ",
      "                ",
      "                ",
      "                ",
      "                ",
      "                ",
      "                ",
      "                ",
      "                ",
      "                ",
      "                ",
      "                "
    ],
    [
      "                ",
      "                ",
      "                ",
      "                ",
      "                ",
      "                ",
      "                ",
      "                ",
      "                ",
      "                ",
      "                ",
      "                ",
      "                ",
      "                ",
      "                ",
      "                "
    ]
  ]
}