{
  "xsize": 16,
  "zsize": 16,
  "palette": {
    "palette": [
      {
        "char": " ",
        "block": "minecraft:air"
      },
      {
        "char": "c",
        "block": "minecraft:vine[east=false,north=false,south=true,up=false,west=false]"
      },
      {
        "char": "p",
        "block": "minecraft:vine[east=true,north=false,south=false,up=false,west=false]"
      },
      {
        "char": "e",
        "block": "minecraft:stone_bricks"
      },
      {
        "char": "g",
        "block": "minecraft:glass_pane[east=true,north=false,south=false,west=true]"
      },
      {
        "char": "h",
        "block": "minecraft:cracked_stone_bricks"
      },
      {
        "char": "i",
        "block": "minecraft:mossy_stone_bricks"
      },
      {
        "char": "f",
        "block": "minecraft:glass_pane[east=false,north=true,south=true,west=false]"
      },
      {
        "char": "ї",
        "block": "minecraft:spruce_fence"
      },
      {
        "char": "a",
        "block": "minecraft:cobblestone"
      },
      {
        "char": "d",
        "block": "minecraft:mossy_cobblestone"
      },
      {
        "char": "b",
        "block": "minecraft:stone"
      },
      {
        "char": "J",
        "block": "minecraft:glass_pane[east=true,north=false,south=true,west=true]"
      },
      {
        "char": "I",
        "block": "minecraft:glass_pane[east=true,north=true,south=true,west=false]"
      },
      {
        "char": "l",
        "block": "minecraft:bookshelf"
      },
      {
        "char": "Ы",
        "block": "minecraft:spruce_stairs[facing=east,half=bottom,shape=straight]"
      },
      {
        "char": "Θ",
        "block": "minecraft:white_wool"
      },
      {
        "char": "k",
        "block": "minecraft:red_carpet"
      },
      {
        "char": "S",
        "block": "minecraft:oak_slab[type=double]"
      },
      {
        "char": "y",
        "block": "minecraft:redstone_wire"
      },
      {
        "char": "ϻ",
        "block": "minecraft:oak_stairs[facing=south,half=bottom,shape=straight]"
      },
      {
        "char": "Й",
        "block": "minecraft:glass_pane[east=false,north=false,south=false,west=true]"
      },
      {
        "char": "Һ",
        "block": "minecraft:spruce_stairs[facing=east,half=top,shape=straight]"
      },
      {
        "char": "ς",
        "block": "minecraft:player_head",
        "tag": {
          "z": 624,
          "x": 72,
          "ForgeCaps": {},
          "id": "minecraft:skull",
          "y": 147
        }
      },
      {
        "char": "ϟ",
        "block": "minecraft:oak_wall_sign",
        "tag": {
          "z": 617,
          "x": 85,
          "is_waxed": "0b",
          "ForgeCaps": {
            "supplementaries:antique_ink": {
              "ink": "0b"
            }
          },
          "id": "minecraft:sign",
          "y": 153,
          "front_text": {
            "color": "black",
            "has_glowing_text": "0b",
            "messages": [
              "{\"extra\":[{\"text\":\"Floor 3\"}],\"text\":\"\"}",
              "{\"extra\":[{\"text\":\"Complaints\"}],\"text\":\"\"}",
              "{\"text\":\"\"}",
              "{\"text\":\"\"}"
            ]
          },
          "back_text": {
            "color": "black",
            "has_glowing_text": "0b",
            "messages": [
              "{\"text\":\"\"}",
              "{\"text\":\"\"}",
              "{\"text\":\"\"}",
              "{\"text\":\"\"}"
            ]
          }
        }
      }
    ]
  },
  "slices": [
    [
      "                ",
      "                ",
      "                ",
      "                ",
      "                ",
      "                ",
      "                ",
      "       cccccc cc",
      "      peghgegige",
      "      pf        ",
      "      pi        ",
      "      pf        ",
      "      pe      ї ",
      "      pf        ",
      "      pe        ",
      "      pf        "
    ],
    [
      "                ",
      "                ",
      "                ",
      "                ",
      "                ",
      "                ",
      "                ",
      "       cccccc cc",
      "      paaadaadda",
      "      pdbbbaaabb",
      "      pdbaabbbbb",
      "      pdaabbbaaa",
      "      pdaaaaaaba",
      "      pdabbbbaaa",
      "      pabbbbabaa",
      "      pabbabbbba"
    ],
    [
      "                ",
      "                ",
      "                ",
      "                ",
      "                ",
      "                ",
      "                ",
      "       cccccc cc",
      "      piJighghJh",
      "      pIll  ЫΘΘΘ",
      "      pil     k ",
      "      pf k k k k",
      "      pe k kk k ",
      "      pf  k    S",
      "      phkk   y  ",
      "      pf k  ϻ ϻ "
    ],
    [
      "                ",
      "                ",
      "                ",
      "                ",
      "                ",
      "                ",
      "                ",
      "       cccccc cc",
      "      phJegeЙ  h",
      "      pIl   ҺΘΘΘ",
      "      pi        ",
      "      pf        ",
      "      pe        ",
      "      pf       ς",
      "      pe        ",
      "      pf        "
    ],
    [
      "                ",
      "                ",
      "                ",
      "                ",
      "                ",
      "                ",
      "                ",
      "       cccccc cc",
      "      paaaadd ad",
      "      pd    ЫΘΘΘ",
      "      pd      ϟϟ",
      "      pa        ",
      "      pa        ",
      "      pd        ",
      "      pd        ",
      "      pd        "
    ],
    [
      "                ",
      "                ",
      "                ",
      "                ",
      "                ",
      "                ",
      "                ",
      "       cccccc cc",
      "      phghgegiJe",
      "       f    ҺΘΘΘ",
      "      pi        ",
      "       f        ",
      "      ph        ",
      "       f        ",
      "      pi        ",
      "       f        "
    ]
  ]
}