{
  "xsize": 16,
  "zsize": 16,
  "palette": {
    "palette": [
      {
        "char": " ",
        "block": "minecraft:air"
      },
      {
        "char": "h",
        "block": "minecraft:cracked_stone_bricks"
      },
      {
        "char": "f",
        "block": "minecraft:glass_pane[east=false,north=true,south=true,west=false]"
      },
      {
        "char": "i",
        "block": "minecraft:mossy_stone_bricks"
      },
      {
        "char": "g",
        "block": "minecraft:glass_pane[east=true,north=false,south=false,west=true]"
      },
      {
        "char": "a",
        "block": "minecraft:cobblestone"
      },
      {
        "char": "b",
        "block": "minecraft:stone"
      },
      {
        "char": "d",
        "block": "minecraft:mossy_cobblestone"
      },
      {
        "char": "k",
        "block": "minecraft:red_carpet"
      },
      {
        "char": "u",
        "block": "minecraft:cobblestone_stairs[facing=south,half=bottom,shape=straight]"
      },
      {
        "char": "e",
        "block": "minecraft:stone_bricks"
      },
      {
        "char": "l",
        "block": "minecraft:bookshelf"
      },
      {
        "char": "S",
        "block": "minecraft:oak_slab[type=double]"
      },
      {
        "char": "Ѻ",
        "block": "minecraft:oak_slab[type=top]"
      },
      {
        "char": "Ϊ",
        "block": "minecraft:oak_wall_sign",
        "tag": {
          "z": 621,
          "x": 75,
          "is_waxed": "0b",
          "ForgeCaps": {
            "supplementaries:antique_ink": {
              "ink": "0b"
            }
          },
          "id": "minecraft:sign",
          "y": 219,
          "front_text": {
            "color": "black",
            "has_glowing_text": "0b",
            "messages": [
              "{\"extra\":[{\"text\":\"D. Herron\"}],\"text\":\"\"}",
              "{\"text\":\"\"}",
              "{\"text\":\"\"}",
              "{\"text\":\"\"}"
            ]
          },
          "back_text": {
            "color": "black",
            "has_glowing_text": "0b",
            "messages": [
              "{\"text\":\"\"}",
              "{\"text\":\"\"}",
              "{\"text\":\"\"}",
              "{\"text\":\"\"}"
            ]
          }
        }
      },
      {
        "char": "τ",
        "block": "minecraft:dark_oak_trapdoor[facing=north,half=bottom,open=true]"
      },
      {
        "char": "ϴ",
        "block": "minecraft:spruce_log[axis=y]"
      },
      {
        "char": "φ",
        "block": "minecraft:dark_oak_trapdoor[facing=east,half=bottom,open=true]"
      },
      {
        "char": "д",
        "block": "minecraft:sea_pickle[pickles=3,waterlogged=false]"
      },
      {
        "char": "϶",
        "block": "minecraft:dark_oak_leaves"
      },
      {
        "char": "ϸ",
        "block": "minecraft:dark_oak_leaves"
      },
      {
        "char": "ҙ",
        "block": "minecraft:spruce_fence[east=true]"
      }
    ]
  },
  "slices": [
    [
      "       h        ",
      "       f        ",
      "       h        ",
      "       f        ",
      "       i        ",
      "       f        ",
      "       h        ",
      "       f        ",
      "       hgigighgi",
      "                ",
      "                ",
      "                ",
      "                ",
      "                ",
      "                ",
      "                "
    ],
    [
      "       aabbbaaab",
      "       abbabbaaa",
      "       aaaabbbbb",
      "       dbbaabbaa",
      "       aabbbaaba",
      "       daabaaaaa",
      "       aaabababa",
      "       aabbabbaa",
      "       ddddddadd",
      "                ",
      "                ",
      "                ",
      "                ",
      "                ",
      "                ",
      "                "
    ],
    [
      "       i k     k",
      "       fuuu   kk",
      "       e  l     ",
      "       f  l   SѺ",
      "       e  l     ",
      "       f  l    Ϊ",
      "       eaalτ    ",
      "       f   ϴφ   ",
      "       egigigige",
      "                ",
      "                ",
      "                ",
      "                ",
      "                ",
      "                ",
      "                "
    ],
    [
      "       h        ",
      "       f        ",
      "       iuuu     ",
      "       f  l    д",
      "       h  l     ",
      "       f  l     ",
      "       iaal     ",
      "       f   ϶    ",
      "       igegigigh",
      "                ",
      "                ",
      "                ",
      "                ",
      "                ",
      "                ",
      "                "
    ],
    [
      "       a        ",
      "       d        ",
      "       d        ",
      "       duuu     ",
      "       a  l     ",
      "       d  l     ",
      "       aaal     ",
      "       d   ϸ    ",
      "       dddaaddda",
      "                ",
      "                ",
      "                ",
      "                ",
      "                ",
      "                ",
      "                "
    ],
    [
      "       h        ",
      "       f       ҙ",
      "       i        ",
      "       f        ",
      "       huuu     ",
      "       f  l     ",
      "       haal     ",
      "       f        ",
      "       ighgegegh",
      "                ",
      "                ",
      "                ",
      "                ",
      "                ",
      "                ",
      "                "
    ]
  ]
}