{
  "xsize": 16,
  "zsize": 16,
  "palette": {
    "palette": [
      {
        "char": " ",
        "block": "minecraft:air"
      },
      {
        "char": "c",
        "block": "minecraft:mossy_cobblestone"
      },
      {
        "char": "A",
        "block": "minecraft:vine[east=false,north=true,south=true,up=false,west=true]"
      },
      {
        "char": "b",
        "block": "minecraft:cobblestone"
      },
      {
        "char": "a",
        "block": "minecraft:smooth_stone_slab[type=double]"
      },
      {
        "char": "f",
        "block": "minecraft:vine[east=false,north=false,south=false,up=false,west=true]"
      },
      {
        "char": "j",
        "block": "minecraft:glass_pane[east=false,north=true,south=true,west=false]"
      },
      {
        "char": "g",
        "block": "minecraft:vine[east=false,north=true,south=false,up=false,west=false]"
      },
      {
        "char": "e",
        "block": "minecraft:stone"
      },
      {
        "char": "i",
        "block": "minecraft:glass_pane[east=true,north=false,south=false,west=true]"
      },
      {
        "char": "n",
        "block": "minecraft:cracked_stone_bricks"
      },
      {
        "char": "p",
        "block": "minecraft:vine[east=true,north=false,south=false,up=false,west=true]"
      },
      {
        "char": "m",
        "block": "minecraft:mossy_stone_bricks"
      },
      {
        "char": "D",
        "block": "minecraft:vine[east=false,north=true,south=false,up=false,west=true]"
      },
      {
        "char": "k",
        "block": "minecraft:stone_bricks"
      },
      {
        "char": "G",
        "block": "minecraft:redstone_lamp[lit=false]"
      },
      {
        "char": "N",
        "block": "minecraft:smooth_stone_slab[type=bottom]"
      },
      {
        "char": "κ",
        "block": "minecraft:oak_stairs[facing=east,half=bottom,shape=straight]"
      },
      {
        "char": "R",
        "block": "minecraft:oak_stairs[facing=south,half=bottom,shape=straight]"
      },
      {
        "char": "v",
        "block": "minecraft:bookshelf"
      },
      {
        "char": "F",
        "block": "minecraft:glass_pane[east=false,north=true,south=true,west=true]"
      },
      {
        "char": "L",
        "block": "minecraft:glass_pane[east=true,north=true,south=false,west=true]"
      }
    ]
  },
  "slices": [
    [
      "      cA        ",
      "      baf       ",
      "      jg        ",
      "      baf       ",
      "      eaf       ",
      "      jg        ",
      "beiebin         ",
      " apaa  af       ",
      " g gg  g        ",
      "                ",
      "                ",
      "                ",
      "                ",
      "                ",
      "                ",
      "                "
    ],
    [
      "      eA        ",
      "      baf       ",
      "      j         ",
      "      baf       ",
      "      baf       ",
      "      jg        ",
      "cbiecim         ",
      " apaa  af       ",
      " g gg  g        ",
      "                ",
      "                ",
      "                ",
      "                ",
      "                ",
      "                ",
      "                "
    ],
    [
      "      cD        ",
      "      ea        ",
      "      j         ",
      "      caf       ",
      "      eaf       ",
      "      jg        ",
      "ceiebik         ",
      " apaa  af       ",
      " g gg  g        ",
      "                ",
      "                ",
      "                ",
      "                ",
      "                ",
      "                ",
      "                "
    ],
    [
      "  bb  cD        ",
      "  bbbbca        ",
      "  bbbbc         ",
      " bbbbbcaf       ",
      "bbbbbbeaf       ",
      "Gebbbbbg        ",
      "ebcbbbb         ",
      " apaa  af       ",
      " g gg  g        ",
      "                ",
      "                ",
      "                ",
      "                ",
      "                ",
      "                ",
      "                "
    ],
    [
      "  Nak c         ",
      "      ea        ",
      "   N  j         ",
      "  N  κcaf       ",
      "     κeaf       ",
      "   RRvFg        ",
      "cciecLk         ",
      " apaa  af       ",
      " g gg  g        ",
      "                ",
      "                ",
      "                ",
      "                ",
      "                ",
      "                ",
      "                "
    ],
    [
      "      e         ",
      "      ca        ",
      "      j         ",
      "      baf       ",
      "      eaf       ",
      "     vFg        ",
      "cbiecLn         ",
      " apaa  af       ",
      " g gg  g        ",
      "                ",
      "                ",
      "                ",
      "                ",
      "                ",
      "                ",
      "                "
    ]
  ]
}