{
  "xsize": 16,
  "zsize": 16,
  "palette": {
    "palette": [
      {
        "char": " ",
        "block": "minecraft:air"
      },
      {
        "char": "h",
        "block": "minecraft:vine[east=false,north=false,south=true,up=false,west=false]"
      },
      {
        "char": "a",
        "block": "minecraft:smooth_stone_slab[type=double]"
      },
      {
        "char": "f",
        "block": "minecraft:vine[east=false,north=false,south=false,up=false,west=true]"
      },
      {
        "char": "c",
        "block": "minecraft:mossy_cobblestone"
      },
      {
        "char": "b",
        "block": "minecraft:cobblestone"
      },
      {
        "char": "i",
        "block": "minecraft:glass_pane[east=true,north=false,south=false,west=true]"
      },
      {
        "char": "e",
        "block": "minecraft:stone"
      },
      {
        "char": "k",
        "block": "minecraft:stone_bricks"
      },
      {
        "char": "j",
        "block": "minecraft:glass_pane[east=false,north=true,south=true,west=false]"
      },
      {
        "char": "z",
        "block": "minecraft:vine[east=false,north=false,south=true,up=false,west=true]"
      },
      {
        "char": "F",
        "block": "minecraft:glass_pane[east=false,north=true,south=true,west=true]"
      },
      {
        "char": "H",
        "block": "minecraft:glass_pane[east=true,north=false,south=true,west=true]"
      },
      {
        "char": "m",
        "block": "minecraft:mossy_stone_bricks"
      },
      {
        "char": "Ζ",
        "block": "minecraft:oak_stairs[facing=north,half=bottom,shape=straight]"
      },
      {
        "char": "v",
        "block": "minecraft:bookshelf"
      },
      {
        "char": "ϓ",
        "block": "minecraft:oak_stairs[facing=east,half=top,shape=straight]"
      },
      {
        "char": "8",
        "block": "minecraft:oak_wall_sign",
        "tag": {
          "z": 619,
          "x": 51,
          "is_waxed": "0b",
          "ForgeCaps": {
            "supplementaries:antique_ink": {
              "ink": "0b"
            }
          },
          "id": "minecraft:sign",
          "y": 185,
          "front_text": {
            "color": "black",
            "has_glowing_text": "0b",
            "messages": [
              "{\"extra\":[{\"text\":\"Floor 11:\"}],\"text\":\"\"}",
              "{\"extra\":[{\"text\":\"CEO Offices\"}],\"text\":\"\"}",
              "{\"text\":\"\"}",
              "{\"text\":\"\"}"
            ]
          },
          "back_text": {
            "color": "black",
            "has_glowing_text": "0b",
            "messages": [
              "{\"text\":\"\"}",
              "{\"text\":\"\"}",
              "{\"text\":\"\"}",
              "{\"text\":\"\"}"
            ]
          }
        }
      },
      {
        "char": "Ϙ",
        "block": "minecraft:player_head",
        "tag": {
          "z": 622,
          "x": 49,
          "ForgeCaps": {},
          "id": "minecraft:skull",
          "y": 208
        }
      },
      {
        "char": "n",
        "block": "minecraft:cracked_stone_bricks"
      }
    ]
  },
  "slices": [
    [
      "                ",
      "                ",
      "                ",
      "                ",
      "                ",
      "                ",
      "                ",
      "                ",
      " h  h  h        ",
      " a aaf a        ",
      "cbiceik         ",
      "b     jz        ",
      "      ca        ",
      "   a  ba        ",
      "   a kF         ",
      "   a  eaf       "
    ],
    [
      "                ",
      "                ",
      "                ",
      "                ",
      "                ",
      "                ",
      "                ",
      "                ",
      " h  h  h        ",
      " a aaf a        ",
      "bbieeik         ",
      "      jz        ",
      "      ba        ",
      "   akkca        ",
      "   a  j         ",
      "      eaf       "
    ],
    [
      "                ",
      "                ",
      "                ",
      "                ",
      "                ",
      "                ",
      "                ",
      "                ",
      " h  h  h        ",
      " a aaf a        ",
      "ecccbce         ",
      "  bbbbbz        ",
      "   bbbba        ",
      "   b  ba        ",
      "   b  c         ",
      "   b  baf       "
    ],
    [
      "                ",
      "                ",
      "                ",
      "                ",
      "                ",
      "                ",
      "                ",
      "                ",
      " h  h  h        ",
      " a aaf a        ",
      "ebiebHm         ",
      "   ΖΖvFz        ",
      "      ea        ",
      "   a  ea        ",
      "  ϓa  j         ",
      "   a  baf       "
    ],
    [
      "                ",
      "                ",
      "                ",
      "                ",
      "                ",
      "                ",
      "                ",
      "                ",
      " h  h  h        ",
      " a aaf a        ",
      "ebiceHk         ",
      "   8 vFz        ",
      "      ba        ",
      "   a  ea        ",
      "  Ϙ   j         ",
      "    kkeaf       "
    ],
    [
      "                ",
      "                ",
      "                ",
      "                ",
      "                ",
      "                ",
      "                ",
      "                ",
      "    h  h        ",
      " a aaf a        ",
      "beibbin         ",
      "      jz        ",
      "      ba        ",
      "   a  ea        ",
      "   akkF         ",
      "      baf       "
    ]
  ]
}