{
  "xsize": 16,
  "zsize": 16,
  "palette": {
    "palette": [
      {
        "char": " ",
        "block": "minecraft:air"
      },
      {
        "char": "a",
        "block": "minecraft:smooth_stone_slab[type=double]"
      },
      {
        "char": "A",
        "block": "minecraft:vine[east=false,north=true,south=true,up=false,west=true]"
      },
      {
        "char": "e",
        "block": "minecraft:stone"
      },
      {
        "char": "f",
        "block": "minecraft:vine[east=false,north=false,south=false,up=false,west=true]"
      },
      {
        "char": "b",
        "block": "minecraft:cobblestone"
      },
      {
        "char": "F",
        "block": "minecraft:glass_pane[east=false,north=true,south=true,west=true]"
      },
      {
        "char": "g",
        "block": "minecraft:vine[east=false,north=true,south=false,up=false,west=false]"
      },
      {
        "char": "c",
        "block": "minecraft:mossy_cobblestone"
      },
      {
        "char": "L",
        "block": "minecraft:glass_pane[east=true,north=true,south=false,west=true]"
      },
      {
        "char": "m",
        "block": "minecraft:mossy_stone_bricks"
      },
      {
        "char": "p",
        "block": "minecraft:vine[east=true,north=false,south=false,up=false,west=true]"
      },
      {
        "char": "j",
        "block": "minecraft:glass_pane[east=false,north=true,south=true,west=false]"
      },
      {
        "char": "n",
        "block": "minecraft:cracked_stone_bricks"
      },
      {
        "char": "i",
        "block": "minecraft:glass_pane[east=true,north=false,south=false,west=true]"
      },
      {
        "char": "k",
        "block": "minecraft:stone_bricks"
      },
      {
        "char": "N",
        "block": "minecraft:smooth_stone_slab[type=bottom]"
      }
    ]
  },
  "slices": [
    [
      "   a   A        ",
      "   a  eaf       ",
      "     bFg        ",
      "    bbbaf       ",
      "    bbcaf       ",
      "    bbFg        ",
      "    cLm         ",
      "  p a  af       ",
      " g gg  g        ",
      "                ",
      "                ",
      "                ",
      "                ",
      "                ",
      "                ",
      "                "
    ],
    [
      "      eA        ",
      "      baf       ",
      "      jg        ",
      "     bcaf       ",
      "    bbcaf       ",
      "    bbFg        ",
      "   eeLn         ",
      "  paa  af       ",
      " g gg  g        ",
      "                ",
      "                ",
      "                ",
      "                ",
      "                ",
      "                ",
      "                "
    ],
    [
      "      bA        ",
      "      eaf       ",
      "      jg        ",
      "      caf       ",
      "     bbaf       ",
      "     bFg        ",
      "ccieeLm         ",
      " apaa  af       ",
      " g gg  g        ",
      "                ",
      "                ",
      "                ",
      "                ",
      "                ",
      "                ",
      "                "
    ],
    [
      "      cA        ",
      "      caf       ",
      "      jg        ",
      "      eaf       ",
      "      baf       ",
      "     bFg        ",
      "cbieeLk         ",
      " apaa  af       ",
      " g gg  g        ",
      "                ",
      "                ",
      "                ",
      "                ",
      "                ",
      "                ",
      "                "
    ],
    [
      "   b  eA        ",
      "  bbbbeaf       ",
      "  bbbbeg        ",
      "  b   caf       ",
      "  b   baf       ",
      " bbb  cg        ",
      "bbbbccc         ",
      " apaa  af       ",
      " g gg  g        ",
      "                ",
      "                ",
      "                ",
      "                ",
      "                ",
      "                ",
      "                "
    ],
    [
      "   a  bA        ",
      "  N  Nbaf       ",
      "  N   jg        ",
      "      caf       ",
      "      baf       ",
      "      jg        ",
      "cbicbin         ",
      " apaa  af       ",
      " g gg  g        ",
      "                ",
      "                ",
      "                ",
      "                ",
      "                ",
      "                ",
      "                "
    ]
  ]
}