{
  "xsize": 16,
  "zsize": 16,
  "palette": {
    "palette": [
      {
        "char": " ",
        "block": "minecraft:air"
      },
      {
        "char": "h",
        "block": "minecraft:vine[east=false,north=false,south=true,up=false,west=false]"
      },
      {
        "char": "a",
        "block": "minecraft:smooth_stone_slab[type=double]"
      },
      {
        "char": "f",
        "block": "minecraft:vine[east=false,north=false,south=false,up=false,west=true]"
      },
      {
        "char": "b",
        "block": "minecraft:cobblestone"
      },
      {
        "char": "i",
        "block": "minecraft:glass_pane[east=true,north=false,south=false,west=true]"
      },
      {
        "char": "c",
        "block": "minecraft:mossy_cobblestone"
      },
      {
        "char": "m",
        "block": "minecraft:mossy_stone_bricks"
      },
      {
        "char": "8",
        "block": "minecraft:oak_wall_sign",
        "tag": {
          "z": 619,
          "x": 51,
          "is_waxed": "0b",
          "ForgeCaps": {
            "supplementaries:antique_ink": {
              "ink": "0b"
            }
          },
          "id": "minecraft:sign",
          "y": 185,
          "front_text": {
            "color": "black",
            "has_glowing_text": "0b",
            "messages": [
              "{\"extra\":[{\"text\":\"Floor 11:\"}],\"text\":\"\"}",
              "{\"extra\":[{\"text\":\"CEO Offices\"}],\"text\":\"\"}",
              "{\"text\":\"\"}",
              "{\"text\":\"\"}"
            ]
          },
          "back_text": {
            "color": "black",
            "has_glowing_text": "0b",
            "messages": [
              "{\"text\":\"\"}",
              "{\"text\":\"\"}",
              "{\"text\":\"\"}",
              "{\"text\":\"\"}"
            ]
          }
        }
      },
      {
        "char": "j",
        "block": "minecraft:glass_pane[east=false,north=true,south=true,west=false]"
      },
      {
        "char": "z",
        "block": "minecraft:vine[east=false,north=false,south=true,up=false,west=true]"
      },
      {
        "char": "e",
        "block": "minecraft:stone"
      },
      {
        "char": "k",
        "block": "minecraft:stone_bricks"
      },
      {
        "char": "G",
        "block": "minecraft:redstone_lamp[lit=false]"
      },
      {
        "char": "H",
        "block": "minecraft:glass_pane[east=true,north=false,south=true,west=true]"
      },
      {
        "char": "Ζ",
        "block": "minecraft:oak_stairs[facing=north,half=bottom,shape=straight]"
      },
      {
        "char": "v",
        "block": "minecraft:bookshelf"
      },
      {
        "char": "F",
        "block": "minecraft:glass_pane[east=false,north=true,south=true,west=true]"
      }
    ]
  },
  "slices": [
    [
      "                ",
      "                ",
      "                ",
      "                ",
      "                ",
      "                ",
      "                ",
      "                ",
      " h  h  h        ",
      " a aaf a        ",
      "bbiccim         ",
      "   8  jz        ",
      "      ba        ",
      "   a  ea        ",
      "   a            ",
      "   a  baf       "
    ],
    [
      "                ",
      "                ",
      "                ",
      "                ",
      "                ",
      "                ",
      "                ",
      "                ",
      " h  h  h        ",
      " a aaf a        ",
      "ecicbim         ",
      "      jz        ",
      "      ba        ",
      "   a  ea        ",
      "   ak j         ",
      "      baf       "
    ],
    [
      "                ",
      "                ",
      "                ",
      "                ",
      "                ",
      "                ",
      "                ",
      "                ",
      " h  h  h        ",
      " a aaf a        ",
      "ebibcim         ",
      "      jz        ",
      "      ea        ",
      "   akkea        ",
      "   a  j         ",
      "      baf       "
    ],
    [
      "                ",
      "                ",
      "                ",
      "                ",
      "                ",
      "                ",
      "                ",
      "                ",
      " h  h  h        ",
      " a aaf a        ",
      "cceebcc         ",
      "Gbbbbbez        ",
      "bbbbbbba        ",
      " bbb  ca        ",
      "  bb  b         ",
      "  bb  eaf       "
    ],
    [
      "                ",
      "                ",
      "                ",
      "                ",
      "                ",
      "                ",
      "                ",
      "                ",
      " h  h  h        ",
      " a aaf a        ",
      "bbicbHk         ",
      "bb ΖΖvFz        ",
      "bb    ba        ",
      "   a  ca        ",
      "   a  j         ",
      "   a  baf       "
    ],
    [
      "                ",
      "                ",
      "                ",
      "                ",
      "                ",
      "                ",
      "                ",
      "                ",
      " h  h  h        ",
      " a aaf a        ",
      "beibcHk         ",
      "bb 8 vFz        ",
      "b     ea        ",
      "   a  ba        ",
      "   a  j         ",
      "   akkcaf       "
    ]
  ]
}