{
  "xsize": 16,
  "zsize": 16,
  "palette": {
    "palette": [
      {
        "char": " ",
        "block": "minecraft:air"
      },
      {
        "char": "c",
        "block": "minecraft:vine[east=false,north=false,south=true,up=false,west=false]"
      },
      {
        "char": "i",
        "block": "minecraft:mossy_stone_bricks"
      },
      {
        "char": "g",
        "block": "minecraft:glass_pane[east=true,north=false,south=false,west=true]"
      },
      {
        "char": "h",
        "block": "minecraft:cracked_stone_bricks"
      },
      {
        "char": "e",
        "block": "minecraft:stone_bricks"
      },
      {
        "char": "f",
        "block": "minecraft:glass_pane[east=false,north=true,south=true,west=false]"
      },
      {
        "char": "Л",
        "block": "minecraft:dark_oak_fence"
      },
      {
        "char": "d",
        "block": "minecraft:mossy_cobblestone"
      },
      {
        "char": "a",
        "block": "minecraft:cobblestone"
      },
      {
        "char": "b",
        "block": "minecraft:stone"
      },
      {
        "char": "з",
        "block": "minecraft:cobblestone_slab[type=top]"
      },
      {
        "char": "σ",
        "block": "minecraft:cobblestone_slab[type=bottom]"
      },
      {
        "char": "J",
        "block": "minecraft:glass_pane[east=true,north=false,south=true,west=true]"
      },
      {
        "char": "I",
        "block": "minecraft:glass_pane[east=true,north=true,south=true,west=false]"
      },
      {
        "char": "大",
        "block": "minecraft:spruce_stairs[facing=north,half=bottom,shape=inner_left]"
      },
      {
        "char": "K",
        "block": "minecraft:spruce_stairs[facing=north,half=bottom,shape=straight]"
      },
      {
        "char": "Ӯ",
        "block": "minecraft:spruce_stairs[facing=east,half=bottom,shape=inner_left]"
      },
      {
        "char": "к",
        "block": "minecraft:spruce_stairs[facing=west,half=bottom,shape=straight]"
      },
      {
        "char": "j",
        "block": "minecraft:light_gray_carpet"
      },
      {
        "char": "ӭ",
        "block": "minecraft:spruce_stairs[facing=south,half=bottom,shape=inner_right]"
      },
      {
        "char": "y",
        "block": "minecraft:redstone_wire"
      },
      {
        "char": "Έ",
        "block": "minecraft:oak_wall_sign",
        "tag": {
          "z": 618,
          "x": 74,
          "is_waxed": "0b",
          "ForgeCaps": {
            "supplementaries:antique_ink": {
              "ink": "0b"
            }
          },
          "id": "minecraft:sign",
          "y": 219,
          "front_text": {
            "color": "black",
            "has_glowing_text": "0b",
            "messages": [
              "{\"extra\":[{\"text\":\"T. Cabel\"}],\"text\":\"\"}",
              "{\"text\":\"\"}",
              "{\"text\":\"\"}",
              "{\"text\":\"\"}"
            ]
          },
          "back_text": {
            "color": "black",
            "has_glowing_text": "0b",
            "messages": [
              "{\"text\":\"\"}",
              "{\"text\":\"\"}",
              "{\"text\":\"\"}",
              "{\"text\":\"\"}"
            ]
          }
        }
      },
      {
        "char": "Й",
        "block": "minecraft:glass_pane[east=false,north=false,south=false,west=true]"
      }
    ]
  },
  "slices": [
    [
      "                ",
      "                ",
      "                ",
      "                ",
      "                ",
      "                ",
      "                ",
      "        ccc c cc",
      "       ighghgige",
      "       f        ",
      "       i  Л     ",
      "       f        ",
      "       e        ",
      "       f        ",
      "       i        ",
      "       f        "
    ],
    [
      "                ",
      "                ",
      "                ",
      "                ",
      "                ",
      "                ",
      "                ",
      "        ccc c cc",
      "       ddaaaaadd",
      "       daababbbb",
      "       daababbba",
      "       abaabb ba",
      "       aabab  aa",
      "       daaaab  з",
      "       aaabb    ",
      "       dbbbbaσ  "
    ],
    [
      "                ",
      "                ",
      "                ",
      "                ",
      "                ",
      "                ",
      "                ",
      "        ccc c cc",
      "       iJiJigegh",
      "       I大KKӮ    ",
      "       hк   j jj",
      "       Iк a     ",
      "       eӭj     j",
      "       f    j   ",
      "       hjjyj    ",
      "       fyj j    "
    ],
    [
      "                ",
      "                ",
      "                ",
      "                ",
      "                ",
      "                ",
      "                ",
      "        ccc c cc",
      "       igegegige",
      "       f        ",
      "       h        ",
      "       f  a     ",
      "       h        ",
      "       f        ",
      "       e        ",
      "       f        "
    ],
    [
      "                ",
      "                ",
      "                ",
      "                ",
      "                ",
      "                ",
      "                ",
      "        ccc c cc",
      "       aaaddaaad",
      "       d        ",
      "       a        ",
      "       a  a     ",
      "       aΈ       ",
      "       d        ",
      "       a        ",
      "       d        "
    ],
    [
      "                ",
      "                ",
      "                ",
      "                ",
      "                ",
      "                ",
      "                ",
      "        ccc c   ",
      "       hghghgiЙ ",
      "       f        ",
      "       h        ",
      "       f  a     ",
      "       e        ",
      "       f        ",
      "       i        ",
      "       f        "
    ]
  ]
}