{
  "xsize": 16,
  "zsize": 16,
  "palette": {
    "palette": [
      {
        "char": " ",
        "block": "minecraft:air"
      },
      {
        "char": "h",
        "block": "minecraft:vine[east=false,north=false,south=true,up=false,west=false]"
      },
      {
        "char": "f",
        "block": "minecraft:vine[east=false,north=false,south=false,up=false,west=true]"
      },
      {
        "char": "a",
        "block": "minecraft:smooth_stone_slab[type=double,waterlogged=false]"
      },
      {
        "char": "p",
        "block": "minecraft:vine[east=true,north=false,south=false,up=false,west=true]"
      },
      {
        "char": "d",
        "block": "minecraft:vine[east=true,north=false,south=false,up=false,west=false]"
      },
      {
        "char": "e",
        "block": "minecraft:stone"
      },
      {
        "char": "c",
        "block": "minecraft:mossy_cobblestone"
      },
      {
        "char": "i",
        "block": "minecraft:glass_pane[east=true,north=false,south=false,waterlogged=false,west=true]"
      },
      {
        "char": "n",
        "block": "minecraft:cracked_stone_bricks"
      },
      {
        "char": "D",
        "block": "minecraft:vine[east=false,north=true,south=false,up=false,west=true]"
      },
      {
        "char": "8",
        "block": "minecraft:oak_wall_sign[facing=south,waterlogged=false]",
        "tag": {
          "z": 619,
          "x": 51,
          "is_waxed": "0b",
          "ForgeCaps": {
            "supplementaries:antique_ink": {
              "ink": "0b"
            }
          },
          "id": "minecraft:sign",
          "y": 185,
          "front_text": {
            "color": "black",
            "has_glowing_text": "0b",
            "messages": [
              "{\"extra\":[{\"text\":\"Floor 11:\"}],\"text\":\"\"}",
              "{\"extra\":[{\"text\":\"CEO Offices\"}],\"text\":\"\"}",
              "{\"text\":\"\"}",
              "{\"text\":\"\"}"
            ]
          },
          "back_text": {
            "color": "black",
            "has_glowing_text": "0b",
            "messages": [
              "{\"text\":\"\"}",
              "{\"text\":\"\"}",
              "{\"text\":\"\"}",
              "{\"text\":\"\"}"
            ]
          }
        }
      },
      {
        "char": "j",
        "block": "minecraft:glass_pane[east=false,north=true,south=true,waterlogged=false,west=false]"
      },
      {
        "char": "z",
        "block": "minecraft:vine[east=false,north=false,south=true,up=false,west=true]"
      },
      {
        "char": "w",
        "block": "minecraft:polished_diorite"
      },
      {
        "char": "b",
        "block": "minecraft:cobblestone"
      },
      {
        "char": "k",
        "block": "minecraft:stone_bricks"
      },
      {
        "char": "F",
        "block": "minecraft:glass_pane[east=false,north=true,south=true,waterlogged=false,west=true]"
      },
      {
        "char": "m",
        "block": "minecraft:mossy_stone_bricks"
      },
      {
        "char": "Υ",
        "block": "minecraft:glass_pane[east=false,north=true,south=false,waterlogged=false,west=false]"
      },
      {
        "char": "А",
        "block": "minecraft:glass_pane[east=false,north=false,south=true,waterlogged=false,west=true]"
      },
      {
        "char": "G",
        "block": "minecraft:redstone_lamp[lit=false]"
      },
      {
        "char": "H",
        "block": "minecraft:glass_pane[east=true,north=false,south=true,waterlogged=false,west=true]"
      }
    ]
  },
  "slices": [
    [
      "                ",
      "                ",
      "                ",
      "                ",
      "                ",
      "                ",
      "                ",
      "                ",
      " h hh  h        ",
      "fapaafda        ",
      "eciccinD        ",
      "   8  jz        ",
      "    c ea        ",
      "wwwabbca        ",
      "w  akbF         ",
      "   akmeaf       "
    ],
    [
      "                ",
      "                ",
      "                ",
      "                ",
      "                ",
      "                ",
      "                ",
      "                ",
      " h hh  h        ",
      "fapaafda        ",
      "eeicbinD        ",
      "      jz        ",
      "      ca        ",
      "   a mba        ",
      "   abbF         ",
      "   ackeaf       "
    ],
    [
      "                ",
      "                ",
      "                ",
      "                ",
      "                ",
      "                ",
      "                ",
      "                ",
      " h hh  h        ",
      "fapaafda        ",
      "ebieeikD        ",
      "      Υz        ",
      "       a        ",
      "   abb a        ",
      "   abbА         ",
      "    bkbaf       "
    ],
    [
      "                ",
      "                ",
      "                ",
      "                ",
      "                ",
      "                ",
      "                ",
      "                ",
      " h hh  h        ",
      "fapaafda        ",
      "cbebceeD        ",
      "Gbbbbbcz        ",
      "bbbbbbca        ",
      "bbbbbbea        ",
      "bbbbkke         ",
      "bbbbbbcaf       "
    ],
    [
      "                ",
      "                ",
      "                ",
      "                ",
      "                ",
      "                ",
      "                ",
      "                ",
      " h hh  h        ",
      "fapaafda        ",
      "ecHccimD        ",
      "  bbb jz        ",
      " bb   ea        ",
      "bbbambba        ",
      "bbbamkF         ",
      "bbbambbaf       "
    ],
    [
      "                ",
      "                ",
      "                ",
      "                ",
      "                ",
      "                ",
      "                ",
      "                ",
      " h hh  h        ",
      "fapaafda        ",
      "ceicbikD        ",
      "   8  jz        ",
      "  b   ca        ",
      "bbbakcba        ",
      "bbbabbF         ",
      "bbbabmcaf       "
    ]
  ]
}