{
  "xsize": 16,
  "zsize": 16,
  "palette": {
    "palette": [
      {
        "char": " ",
        "block": "minecraft:air"
      },
      {
        "char": "и",
        "block": "minecraft:dark_oak_fence[south=true,west=true]"
      },
      {
        "char": "ъ",
        "block": "minecraft:dark_oak_fence[east=true,south=true]"
      },
      {
        "char": "e",
        "block": "minecraft:stone_bricks"
      },
      {
        "char": "ѝ",
        "block": "minecraft:dark_oak_fence[north=true,west=true]"
      },
      {
        "char": "Ф",
        "block": "minecraft:dark_oak_fence[east=true,north=true]"
      },
      {
        "char": "f",
        "block": "minecraft:glass_pane[east=false,north=true,south=true,west=false]"
      },
      {
        "char": "i",
        "block": "minecraft:mossy_stone_bricks"
      },
      {
        "char": "h",
        "block": "minecraft:cracked_stone_bricks"
      },
      {
        "char": "g",
        "block": "minecraft:glass_pane[east=true,north=false,south=false,west=true]"
      },
      {
        "char": "m",
        "block": "minecraft:vine[east=false,north=true,south=false,up=false,west=false]"
      },
      {
        "char": "b",
        "block": "minecraft:stone"
      },
      {
        "char": "a",
        "block": "minecraft:cobblestone"
      },
      {
        "char": "d",
        "block": "minecraft:mossy_cobblestone"
      },
      {
        "char": "У",
        "block": "minecraft:stone_button[face=floor,facing=north,powered=false]"
      },
      {
        "char": "σ",
        "block": "minecraft:cobblestone_slab[type=bottom]"
      },
      {
        "char": "T",
        "block": "minecraft:flower_pot"
      },
      {
        "char": "Я",
        "block": "minecraft:stone_button[face=floor,facing=east,powered=false]"
      },
      {
        "char": "j",
        "block": "minecraft:light_gray_carpet"
      },
      {
        "char": "Q",
        "block": "minecraft:crafting_table"
      },
      {
        "char": "C",
        "block": "minecraft:redstone_lamp[lit=false]"
      },
      {
        "char": "б",
        "block": "minecraft:sea_pickle[pickles=2,waterlogged=false]"
      },
      {
        "char": "Ί",
        "block": "minecraft:glass_pane[east=false,north=true,south=true,west=true]"
      },
      {
        "char": "Ѩ",
        "block": "minecraft:sea_pickle[pickles=1,waterlogged=false]"
      },
      {
        "char": "y",
        "block": "minecraft:redstone_wire"
      },
      {
        "char": "ѳ",
        "block": "minecraft:skeleton_skull",
        "tag": {
          "z": 629,
          "x": 84,
          "ForgeCaps": {},
          "id": "minecraft:skull",
          "y": 219
        }
      },
      {
        "char": "P",
        "block": "minecraft:glass_pane[east=true,north=true,south=false,west=true]"
      },
      {
        "char": "л",
        "block": "minecraft:stone_button[face=floor,facing=south,powered=false]"
      },
      {
        "char": "ӵ",
        "block": "minecraft:stone_button[face=wall,facing=west,powered=false]"
      },
      {
        "char": "в",
        "block": "minecraft:glass_pane[east=true,north=false,south=false,west=false]"
      }
    ]
  },
  "slices": [
    [
      "и   ъи e        ",
      "ѝ   Фѝ f        ",
      "       e        ",
      "       f        ",
      "       e        ",
      "и   ъи f        ",
      "ѝ   Фѝ i        ",
      "       f        ",
      " hgighgi        ",
      "   mmm          ",
      "                ",
      "                ",
      "                ",
      "                ",
      "                ",
      "                "
    ],
    [
      "babbaabd        ",
      "aaaabbbd        ",
      "abbbbabd        ",
      "baabaaaa        ",
      "abaaabaa        ",
      "aaaaaaaa        ",
      "baaaaaaa        ",
      "baaaabbd        ",
      "dadaaaad        ",
      "   mmm          ",
      "                ",
      "                ",
      "                ",
      "                ",
      "                ",
      "                "
    ],
    [
      "У  σTЯjh        ",
      "QbC jбCΊ        ",
      " jCbbУTh        ",
      "ab σbjQΊ        ",
      " ѨjQ  Qe        ",
      "a Qy j f        ",
      "Qy jC Ti        ",
      " jyѳQQjf        ",
      " egePigh        ",
      "   mmm          ",
      "                ",
      "                ",
      "                ",
      "                ",
      "                ",
      "                "
    ],
    [
      "       h        ",
      "      Уf        ",
      "  лӵa  i        ",
      "aУ  a  f        ",
      "      Qi        ",
      "       f        ",
      "       i        ",
      "       f        ",
      "вigeghgi        ",
      "   mmm          ",
      "                ",
      "                ",
      "                ",
      "                ",
      "                ",
      "                "
    ],
    [
      "       d        ",
      "       a        ",
      "       d        ",
      "    T  a        ",
      "      Ta        ",
      "       d        ",
      "       d        ",
      "       a        ",
      "daaadada        ",
      "   mmm          ",
      "                ",
      "                ",
      "                ",
      "                ",
      "                ",
      "                "
    ],
    [
      "       i        ",
      "       f        ",
      "       e        ",
      "       f        ",
      "       e        ",
      "    C  f        ",
      "       e        ",
      "       f        ",
      " hghghge        ",
      "   mmm          ",
      "                ",
      "                ",
      "                ",
      "                ",
      "                ",
      "                "
    ]
  ]
}