{
  "xsize": 16,
  "zsize": 16,
  "palette": {
    "palette": [
      {
        "char": " ",
        "block": "minecraft:air"
      },
      {
        "char": "c",
        "block": "minecraft:vine[east=false,north=false,south=true,up=false,west=false]"
      },
      {
        "char": "g",
        "block": "minecraft:glass_pane[east=true,north=false,south=false,west=true]"
      },
      {
        "char": "i",
        "block": "minecraft:mossy_stone_bricks"
      },
      {
        "char": "h",
        "block": "minecraft:cracked_stone_bricks"
      },
      {
        "char": "Ҍ",
        "block": "minecraft:vine[east=false,north=false,south=true,up=false,west=true]"
      },
      {
        "char": "Д",
        "block": "minecraft:stone_slab[type=bottom]"
      },
      {
        "char": "Б",
        "block": "minecraft:glass_pane[east=false,north=false,south=true,west=false]"
      },
      {
        "char": "f",
        "block": "minecraft:glass_pane[east=false,north=true,south=true,west=false]"
      },
      {
        "char": "e",
        "block": "minecraft:stone_bricks"
      },
      {
        "char": "a",
        "block": "minecraft:cobblestone"
      },
      {
        "char": "d",
        "block": "minecraft:mossy_cobblestone"
      },
      {
        "char": "b",
        "block": "minecraft:stone"
      },
      {
        "char": "o",
        "block": "minecraft:vine[east=false,north=false,south=false,up=false,west=true]"
      },
      {
        "char": "j",
        "block": "minecraft:light_gray_carpet"
      },
      {
        "char": "n",
        "block": "minecraft:quartz_slab[type=double]"
      },
      {
        "char": "x",
        "block": "minecraft:cobblestone_stairs[facing=north,half=bottom,shape=straight]"
      },
      {
        "char": "Έ",
        "block": "minecraft:oak_wall_sign",
        "tag": {
          "z": 618,
          "x": 74,
          "is_waxed": "0b",
          "ForgeCaps": {
            "supplementaries:antique_ink": {
              "ink": "0b"
            }
          },
          "id": "minecraft:sign",
          "y": 219,
          "front_text": {
            "color": "black",
            "has_glowing_text": "0b",
            "messages": [
              "{\"extra\":[{\"text\":\"T. Cabel\"}],\"text\":\"\"}",
              "{\"text\":\"\"}",
              "{\"text\":\"\"}",
              "{\"text\":\"\"}"
            ]
          },
          "back_text": {
            "color": "black",
            "has_glowing_text": "0b",
            "messages": [
              "{\"text\":\"\"}",
              "{\"text\":\"\"}",
              "{\"text\":\"\"}",
              "{\"text\":\"\"}"
            ]
          }
        }
      },
      {
        "char": "б",
        "block": "minecraft:sea_pickle[pickles=2,waterlogged=false]"
      },
      {
        "char": "l",
        "block": "minecraft:bookshelf"
      },
      {
        "char": "е",
        "block": "minecraft:stone_slab[type=top]"
      }
    ]
  },
  "slices": [
    [
      "                ",
      "                ",
      "                ",
      "                ",
      "                ",
      "                ",
      "                ",
      "cccccccc        ",
      "gi hҌД          ",
      "       Б        ",
      "       i        ",
      "       f        ",
      "       e        ",
      "       f        ",
      "       h        ",
      "       f        "
    ],
    [
      "                ",
      "                ",
      "                ",
      "                ",
      "                ",
      "                ",
      "                ",
      "cccccccc        ",
      "ad  Ҍ           ",
      "bbabaaba        ",
      "aaabaabd        ",
      "baababaa        ",
      "baabbbad        ",
      "aaaaabaa        ",
      "bbaaaaba        ",
      "baababbd        "
    ],
    [
      "                ",
      "                ",
      "                ",
      "                ",
      "                ",
      "                ",
      "                ",
      "cccccccc        ",
      "gi  o           ",
      "jj              ",
      "nj jaaah        ",
      "n jjaa f        ",
      " j  a  h        ",
      "nj ja  f        ",
      "njj a  i        ",
      "   jxxxf        "
    ],
    [
      "                ",
      "                ",
      "                ",
      "                ",
      "                ",
      "                ",
      "                ",
      "cccccccc        ",
      "ge  o           ",
      "                ",
      "nΈ  aaa         ",
      "n   бl          ",
      "     l e        ",
      "nΈ  a  f        ",
      "n   xxxe        ",
      "       f        "
    ],
    [
      "                ",
      "                ",
      "                ",
      "                ",
      "                ",
      "                ",
      "                ",
      "cccccccc        ",
      "aa еo           ",
      "                ",
      "    aaa         ",
      "     l a        ",
      "     l a        ",
      "    xxxa        ",
      "       d        ",
      "       a        "
    ],
    [
      "                ",
      "                ",
      "                ",
      "                ",
      "                ",
      "                ",
      "                ",
      "cccccccc        ",
      " e hoh          ",
      "                ",
      "    aaa         ",
      "    a           ",
      "    xxxi        ",
      "       f        ",
      "       e        ",
      "       f        "
    ]
  ]
}