{
  "xsize": 16,
  "zsize": 16,
  "palette": {
    "palette": [
      {
        "char": " ",
        "block": "minecraft:air"
      },
      {
        "char": "d",
        "block": "minecraft:vine[east=true,north=false,south=false,up=false,west=false]"
      },
      {
        "char": "y",
        "block": "minecraft:vine[east=true,north=true,south=true,up=false,west=false]"
      },
      {
        "char": "b",
        "block": "minecraft:cobblestone"
      },
      {
        "char": "a",
        "block": "minecraft:smooth_stone_slab[type=double]"
      },
      {
        "char": "c",
        "block": "minecraft:mossy_cobblestone"
      },
      {
        "char": "E",
        "block": "minecraft:cobblestone_slab[type=bottom]"
      },
      {
        "char": "j",
        "block": "minecraft:glass_pane[east=false,north=true,south=true,west=false]"
      },
      {
        "char": "v",
        "block": "minecraft:bookshelf"
      },
      {
        "char": "k",
        "block": "minecraft:stone_bricks"
      },
      {
        "char": "i",
        "block": "minecraft:glass_pane[east=true,north=false,south=false,west=true]"
      },
      {
        "char": "e",
        "block": "minecraft:stone"
      },
      {
        "char": "p",
        "block": "minecraft:vine[east=true,north=false,south=false,up=false,west=true]"
      },
      {
        "char": "g",
        "block": "minecraft:vine[east=false,north=true,south=false,up=false,west=false]"
      },
      {
        "char": "·",
        "block": "minecraft:glass_pane[east=true,north=true,south=true,west=false]"
      },
      {
        "char": "n",
        "block": "minecraft:cracked_stone_bricks"
      },
      {
        "char": "m",
        "block": "minecraft:mossy_stone_bricks"
      }
    ]
  },
  "slices": [
    [
      "        dyb    b",
      "        dac   Eb",
      "          j E  b",
      "        dab   vb",
      "        dab     ",
      "          j     ",
      "          kiebie",
      "        da daapa",
      "         g  gg  ",
      "                ",
      "                ",
      "                ",
      "                ",
      "                ",
      "                ",
      "                "
    ],
    [
      "        dye    b",
      "        dac    b",
      "          j    b",
      "        dac     ",
      "        dab     ",
      "          j     ",
      "          kicbib",
      "        da daapa",
      "         g  gg  ",
      "                ",
      "                ",
      "                ",
      "                ",
      "                ",
      "                ",
      "                "
    ],
    [
      "        dybb   b",
      "        dabb   b",
      "          ebb  E",
      "        daebbb  ",
      "        dacbbbbb",
      "          bbbbbb",
      "          ebccee",
      "        da daapa",
      "         g  gg  ",
      "                ",
      "                ",
      "                ",
      "                ",
      "                ",
      "                ",
      "                "
    ],
    [
      "        dyc    E",
      "        dab    v",
      "          ·vv   ",
      "        dab  v  ",
      "        dac     ",
      "          j     ",
      "          niebic",
      "        da daapa",
      "         g  gg  ",
      "                ",
      "                ",
      "                ",
      "                ",
      "                ",
      "                ",
      "                "
    ],
    [
      "        dyb     ",
      "        dab     ",
      "          j E   ",
      "        dae  v  ",
      "        dae     ",
      "          j     ",
      "          mieeib",
      "        da daapa",
      "         g  gg  ",
      "                ",
      "                ",
      "                ",
      "                ",
      "                ",
      "                ",
      "                "
    ],
    [
      "        dyc     ",
      "        dae     ",
      "          j     ",
      "        dab     ",
      "        dac     ",
      "          j     ",
      "          nibbie",
      "        da daapa",
      "         g  gg  ",
      "                ",
      "                ",
      "                ",
      "                ",
      "                ",
      "                ",
      "                "
    ]
  ]
}