{
  "xsize": 16,
  "zsize": 16,
  "palette": {
    "palette": [
      {
        "char": " ",
        "block": "minecraft:air"
      },
      {
        "char": "i",
        "block": "minecraft:mossy_stone_bricks"
      },
      {
        "char": "f",
        "block": "minecraft:glass_pane[east=false,north=true,south=true,west=false]"
      },
      {
        "char": "Ѝ",
        "block": "minecraft:redstone_torch[lit=true]"
      },
      {
        "char": "u",
        "block": "minecraft:cobblestone_stairs[facing=south,half=bottom,shape=straight]"
      },
      {
        "char": "h",
        "block": "minecraft:cracked_stone_bricks"
      },
      {
        "char": "a",
        "block": "minecraft:cobblestone"
      },
      {
        "char": "l",
        "block": "minecraft:bookshelf"
      },
      {
        "char": "e",
        "block": "minecraft:stone_bricks"
      },
      {
        "char": "g",
        "block": "minecraft:glass_pane[east=true,north=false,south=false,west=true]"
      },
      {
        "char": "b",
        "block": "minecraft:stone"
      },
      {
        "char": "d",
        "block": "minecraft:mossy_cobblestone"
      },
      {
        "char": "ц",
        "block": "minecraft:skeleton_skull",
        "tag": {
          "z": 631,
          "x": 81,
          "ForgeCaps": {},
          "id": "minecraft:skull",
          "y": 133
        }
      },
      {
        "char": "y",
        "block": "minecraft:redstone_wire"
      },
      {
        "char": "j",
        "block": "minecraft:light_gray_carpet"
      },
      {
        "char": "L",
        "block": "minecraft:black_carpet"
      },
      {
        "char": "I",
        "block": "minecraft:glass_pane[east=true,north=true,south=true,west=false]"
      },
      {
        "char": "ӏ",
        "block": "minecraft:oak_stairs[facing=west,half=bottom,shape=inner_left]"
      },
      {
        "char": "ϻ",
        "block": "minecraft:oak_stairs[facing=south,half=bottom,shape=straight]"
      },
      {
        "char": "一",
        "block": "minecraft:oak_stairs[facing=east,half=bottom,shape=inner_right]"
      },
      {
        "char": "Ј",
        "block": "minecraft:air"
      },
      {
        "char": "Љ",
        "block": "minecraft:air"
      },
      {
        "char": "ҋ",
        "block": "minecraft:air"
      },
      {
        "char": "Ͽ",
        "block": "minecraft:air"
      },
      {
        "char": "χ",
        "block": "minecraft:air"
      },
      {
        "char": "k",
        "block": "minecraft:red_carpet"
      },
      {
        "char": "Є",
        "block": "minecraft:air"
      },
      {
        "char": "ϳ",
        "block": "minecraft:oak_wall_sign",
        "tag": {
          "z": 618,
          "x": 75,
          "is_waxed": "0b",
          "ForgeCaps": {
            "supplementaries:antique_ink": {
              "ink": "0b"
            }
          },
          "id": "minecraft:sign",
          "y": 224,
          "front_text": {
            "color": "black",
            "has_glowing_text": "0b",
            "messages": [
              "{\"text\":\"\"}",
              "{\"text\":\"\"}",
              "{\"text\":\"\"}",
              "{\"text\":\"\"}"
            ]
          },
          "back_text": {
            "color": "black",
            "has_glowing_text": "0b",
            "messages": [
              "{\"text\":\"\"}",
              "{\"text\":\"\"}",
              "{\"text\":\"\"}",
              "{\"text\":\"\"}"
            ]
          }
        }
      }
    ]
  },
  "slices": [
    [
      "       i        ",
      "       f       Ѝ",
      "       i        ",
      "       f        ",
      "       i        ",
      "       fuuu     ",
      "       haal     ",
      "       f        ",
      "       eghgigige",
      "                ",
      "                ",
      "                ",
      "                ",
      "                ",
      "                ",
      "                "
    ],
    [
      "       aaaabbbbb",
      "       abaaabaaa",
      "       aabbababb",
      "       a   abaab",
      "       a   babbb",
      "       d   baaaa",
      "       duuuabaab",
      "       abbabbbbb",
      "       ddaddadda",
      "                ",
      "                ",
      "                ",
      "                ",
      "                ",
      "                ",
      "                "
    ],
    [
      "       hцy   j L",
      "       Iӏϻϻ一jL  ",
      "       iЈЈЉҋ j j",
      "       f   Ͽj  j",
      "       e   χ jk ",
      "       f   χk jk",
      "       h   Є kk ",
      "       f jkjkj  ",
      "       igighgege",
      "                ",
      "                ",
      "                ",
      "                ",
      "                ",
      "                ",
      "                "
    ],
    [
      "       e        ",
      "       f        ",
      "       ijjjj    ",
      "       f        ",
      "       h        ",
      "       f        ",
      "       e        ",
      "       f ϳ      ",
      "       hgigighgi",
      "                ",
      "                ",
      "                ",
      "                ",
      "                ",
      "                ",
      "                "
    ],
    [
      "       d        ",
      "       d        ",
      "       d        ",
      "       d        ",
      "       a        ",
      "       d        ",
      "       d        ",
      "       d        ",
      "       adaadadda",
      "                ",
      "                ",
      "                ",
      "                ",
      "                ",
      "                ",
      "                "
    ],
    [
      "                ",
      "                ",
      "       i        ",
      "       f        ",
      "       i        ",
      "       f        ",
      "       h        ",
      "       f        ",
      "       egegeghge",
      "                ",
      "                ",
      "                ",
      "                ",
      "                ",
      "                ",
      "                "
    ]
  ]
}