{
  "xsize": 16,
  "zsize": 16,
  "palette": {
    "palette": [
      {
        "char": " ",
        "block": "minecraft:structure_void"
      },
      {
        "char": "D",
        "block": "minecraft:polished_deepslate_slab[type=bottom]"
      },
      {
        "char": "I",
        "block": "minecraft:polished_deepslate_slab[type=double]"
      },
      {
        "char": "q",
        "block": "minecraft:polished_deepslate_slab[type=top]"
      },
      {
        "char": "r",
        "block": "minecraft:air"
      },
      {
        "char": "h",
        "block": "minecraft:cobbled_deepslate_slab[type=bottom]"
      },
      {
        "char": "k",
        "block": "minecraft:cobbled_deepslate_slab[type=double]"
      },
      {
        "char": "b",
        "block": "minecraft:pink_terracotta"
      },
      {
        "char": "ί",
        "block": "minecraft:air"
      },
      {
        "char": "p",
        "block": "minecraft:cobbled_deepslate_slab[type=top]"
      },
      {
        "char": "n",
        "block": "minecraft:oak_leaves"
      },
      {
        "char": "s",
        "block": "minecraft:dark_oak_leaves"
      },
      {
        "char": "B",
        "block": "minecraft:oak_leaves"
      },
      {
        "char": "Ά",
        "block": "minecraft:dark_oak_leaves"
      },
      {
        "char": "ϭ",
        "block": "minecraft:spruce_trapdoor[facing=north,half=bottom,open=true]"
      },
      {
        "char": "K",
        "block": "minecraft:oak_wood[axis=y]"
      },
      {
        "char": "Ώ",
        "block": "minecraft:spruce_fence[east=true,south=true]"
      },
      {
        "char": "Ϳ",
        "block": "minecraft:oak_leaves"
      },
      {
        "char": "΅",
        "block": "minecraft:oak_leaves"
      },
      {
        "char": "ϱ",
        "block": "minecraft:spruce_fence[east=true,north=true]"
      },
      {
        "char": "β",
        "block": "minecraft:spruce_fence[north=true,west=true]"
      },
      {
        "char": "2",
        "block": "minecraft:oak_leaves"
      },
      {
        "char": "L",
        "block": "minecraft:oak_leaves"
      },
      {
        "char": "H",
        "block": "minecraft:air"
      },
      {
        "char": "έ",
        "block": "minecraft:spruce_trapdoor[facing=north,half=bottom,open=false]"
      },
      {
        "char": "ͷ",
        "block": "minecraft:dark_oak_leaves"
      },
      {
        "char": "Λ",
        "block": "minecraft:spruce_fence[south=true]"
      },
      {
        "char": "Β",
        "block": "minecraft:dark_oak_leaves"
      },
      {
        "char": "Ι",
        "block": "minecraft:dark_oak_leaves"
      },
      {
        "char": "J",
        "block": "minecraft:oak_leaves"
      },
      {
        "char": "΄",
        "block": "minecraft:spruce_fence[north=true]"
      },
      {
        "char": "ͺ",
        "block": "minecraft:dark_oak_leaves"
      },
      {
        "char": "Ο",
        "block": "minecraft:spruce_fence[east=true]"
      },
      {
        "char": "ͻ",
        "block": "minecraft:dark_oak_leaves"
      },
      {
        "char": "Ξ",
        "block": "minecraft:spruce_fence"
      }
    ]
  },
  "slices": [
    [
      "      DIq   rr r",
      "      hkbbbίίbbb",
      "      hkp      p",
      "      hkp      p",
      "   nn hkp      p",
      "  sn  hkp      p",
      "   ns hkp      p",
      "n B  nhkp      p",
      " Ά ϭK hkp      p",
      "  ΏKͿ΅hkp      p",
      "  ϱβ΅2hkp      p",
      "  LB  hkp      p",
      "    nnhkp      p",
      "    s hkbbbbbbbb",
      "    s DIq  HH  q",
      "                "
    ],
    [
      "        DIqέέqID",
      "        hkbbbbkh",
      "        hkp  pkh",
      "     s  hkp  pkh",
      "   n nn hkp  pkh",
      "       nhkp  pkh",
      "  B  n  hkp  pkh",
      " B2ͷΛn  hkp  pkh",
      " 2ͷͿK Ά hkp  pkh",
      " ͷΒΒΒ΅2 hkp  pkh",
      " ͿK  ΙΆ hkp  pkk",
      "n  2    hkp  pkh",
      "      s hkp  pkh",
      "    n   hkbbbbkh",
      "   sn   DIqH qID",
      "                "
    ],
    [
      "          DIID  ",
      "          hkkh  ",
      "          hkkh  ",
      "  nn  n   hkkh  ",
      "    s n   hkkh  ",
      "n B nnn   hkkh  ",
      "  2΅    s hkkh  ",
      "L ͷͿK Jn  hkkh  ",
      "  2ͷ΄ͺLJn hkkh  ",
      "n         hkkh  ",
      " ΟKͿ BL   hkkh  ",
      " n΄ͷ  J s hkkh  ",
      " nͺ Jn    hkkh  ",
      "     n    hkkh  ",
      "   s      DIID  ",
      "                "
    ],
    [
      "                ",
      "                ",
      "                ",
      "    s           ",
      "  n  n          ",
      " n    sn        ",
      "ͻ    n  n       ",
      "B2ͷͿK nn        ",
      "      J         ",
      " nͺ   n         ",
      "  Ξ΅   sn       ",
      "nn 2BL ns       ",
      " ͺLBͻ ss        ",
      " s Lͺ           ",
      "   J n          ",
      "                "
    ],
    [
      "                ",
      "                ",
      "                ",
      "    n           ",
      "   ͻJn          ",
      "  LB  nn        ",
      " LBΙ n s        ",
      "   ΅ snn        ",
      " s   nn         ",
      " Jͻ L ns        ",
      "  B2B n         ",
      " n              ",
      "     n          ",
      "    nn          ",
      "                ",
      "                "
    ],
    [
      "                ",
      "                ",
      "                ",
      "                ",
      "   J            ",
      "    n           ",
      "   B            ",
      " ͻBΙΆ n         ",
      "  ͻBL s         ",
      "  JLͺ           ",
      "   BL n         ",
      "    J  s        ",
      "  n             ",
      "                ",
      "                ",
      "                "
    ]
  ]
}