{
  "xsize": 16,
  "zsize": 16,
  "palette": {
    "palette": [
      {
        "char": " ",
        "block": "minecraft:structure_void"
      },
      {
        "char": "t",
        "block": "minecraft:polished_deepslate_slab[type=bottom]"
      },
      {
        "char": "A",
        "block": "minecraft:polished_deepslate_slab[type=double]"
      },
      {
        "char": "n",
        "block": "minecraft:polished_deepslate_slab[type=top]"
      },
      {
        "char": "Δ",
        "block": "minecraft:air"
      },
      {
        "char": "G",
        "block": "minecraft:air"
      },
      {
        "char": "e",
        "block": "minecraft:cobbled_deepslate_slab[type=bottom]"
      },
      {
        "char": "f",
        "block": "minecraft:cobbled_deepslate_slab[type=double]"
      },
      {
        "char": "b",
        "block": "minecraft:blue_terracotta"
      },
      {
        "char": "h",
        "block": "minecraft:cobbled_deepslate_slab[type=top]"
      },
      {
        "char": "Α",
        "block": "minecraft:dark_oak_stairs[facing=west,half=bottom,shape=straight]"
      },
      {
        "char": "Ѓ",
        "block": "minecraft:air"
      },
      {
        "char": "v",
        "block": "minecraft:air"
      },
      {
        "char": "B",
        "block": "minecraft:dark_oak_leaves"
      }
    ]
  },
  "slices": [
    [
      "                ",
      "       tAnΔG  nA",
      "       efbbbbbbf",
      "       efh    hf",
      "       efh    hf",
      "       efh    hf",
      "       efh    hf",
      "       efh    hf",
      "       efh    hf",
      "   ttttefh    hf",
      "   Affffbbbbbbbb",
      "   nb    bΑ     ",
      "   Ѓb    b      ",
      "   vb    b      ",
      "   vb    b      ",
      "    bbbbbbbbbbbb"
    ],
    [
      "                ",
      "         tAnnAt ",
      "         efbbfe ",
      "         efhhfe ",
      "         efhhfe ",
      "         efhhfe ",
      "         efhhfe ",
      "         efhhfe ",
      "         efhhfe ",
      "         efhhfe ",
      "        eeffffee",
      "   teeeeeffffffe",
      "   Affffffffffff",
      "   nbhhhhbhhhhhh",
      "   vb    b      ",
      "   vbbbbbbbbbbbb"
    ],
    [
      "                ",
      "           tt   ",
      "           ee   ",
      "           ee   ",
      "           ee   ",
      "           ee   ",
      "           ee   ",
      "           ee   ",
      "           ee   ",
      "           ee   ",
      "           ee   ",
      "           ee   ",
      "          eeee  ",
      "   teeeeeeeeeeee",
      "   Affffffffffff",
      "   nbbbbbbbbbbbb"
    ],
    [
      "                ",
      "                ",
      "                ",
      "                ",
      "                ",
      "                ",
      "                ",
      "                ",
      "                ",
      "                ",
      "                ",
      "                ",
      "                ",
      "                ",
      "                ",
      "   teeeeeeeeeeee"
    ],
    [
      "                ",
      "                ",
      "                ",
      "                ",
      "                ",
      "                ",
      "                ",
      "                ",
      "                ",
      "                ",
      "                ",
      "                ",
      "                ",
      "                ",
      "                ",
      "              B "
    ],
    [
      "                ",
      "                ",
      "                ",
      "                ",
      "                ",
      "                ",
      "                ",
      "                ",
      "                ",
      "                ",
      "                ",
      "                ",
      "                ",
      "                ",
      "                ",
      "                "
    ]
  ]
}