{
  "xsize": 16,
  "zsize": 16,
  "palette": {
    "palette": [
      {
        "char": " ",
        "block": "minecraft:air"
      },
      {
        "char": "c",
        "block": "minecraft:light_blue_terracotta"
      },
      {
        "char": "b",
        "block": "minecraft:oak_leaves"
      },
      {
        "char": "Щ",
        "block": "minecraft:chest",
        "loot": "suburbanloot",
        "tag": {
          "ForgeData": {
            "LockFlag": "1b"
          },
          "x": -402,
          "y": -59,
          "Items": [],
          "z": -157,
          "id": "minecraft:chest"
        }
      },
      {
        "char": "B",
        "block": "minecraft:stripped_oak_wood[axis=y]"
      },
      {
        "char": "G",
        "block": "minecraft:air"
      },
      {
        "char": "有",
        "block": "minecraft:air"
      },
      {
        "char": "ͺ",
        "block": "minecraft:spruce_button[face=floor,facing=west,powered=false]"
      },
      {
        "char": "к",
        "block": "minecraft:chest",
        "loot": "suburbanloot",
        "tag": {
          "ForgeData": {
            "LockFlag": "1b"
          },
          "x": -400,
          "y": -55,
          "Items": [],
          "z": -185,
          "id": "minecraft:chest"
        }
      },
      {
        "char": "ϟ",
        "block": "minecraft:spruce_trapdoor[facing=north,half=bottom,open=false]"
      },
      {
        "char": "Ά",
        "block": "minecraft:spruce_button[face=floor,facing=south,powered=false]"
      },
      {
        "char": "Ҍ",
        "block": "minecraft:air"
      },
      {
        "char": "Ҷ",
        "block": "minecraft:air"
      },
      {
        "char": "只",
        "block": "minecraft:air"
      },
      {
        "char": "ә",
        "block": "minecraft:air"
      },
      {
        "char": "用",
        "block": "minecraft:air"
      },
      {
        "char": "D",
        "block": "minecraft:air"
      },
      {
        "char": "意",
        "block": "minecraft:air"
      },
      {
        "char": "ӈ",
        "block": "minecraft:air"
      },
      {
        "char": "工",
        "block": "minecraft:dark_oak_trapdoor[facing=west,half=top,open=true]"
      },
      {
        "char": "Ґ",
        "block": "minecraft:dark_oak_trapdoor[facing=south,half=top,open=true]"
      },
      {
        "char": "ͽ",
        "block": "minecraft:air"
      },
      {
        "char": "ύ",
        "block": "minecraft:oak_trapdoor[facing=south,half=top,open=true]"
      },
      {
        "char": "d",
        "block": "minecraft:spruce_slab[type=top]"
      },
      {
        "char": "q",
        "block": "minecraft:brick_slab[type=top]"
      },
      {
        "char": "ͳ",
        "block": "minecraft:oak_trapdoor[facing=south,half=top,open=false]"
      },
      {
        "char": "u",
        "block": "minecraft:brick_slab[type=double]"
      },
      {
        "char": "p",
        "block": "minecraft:brick_slab[type=bottom]"
      },
      {
        "char": "t",
        "block": "minecraft:air"
      }
    ]
  },
  "slices": [
    [
      "cb ЩBG          ",
      "有ͺ кc           ",
      "cϟΆbc           ",
      "ccҌcc           ",
      "cҶΆ只cG          ",
      "cә 用cG          ",
      "ccccB           ",
      " DD             ",
      "      b         ",
      "                ",
      "                ",
      "                ",
      "                ",
      "                ",
      "                ",
      "                "
    ],
    [
      "c   BG          ",
      "意   c           ",
      "c   cG          ",
      "ccӈccG          ",
      "c   c           ",
      "c   c           ",
      "ccccBG          ",
      "  D D           ",
      "                ",
      "                ",
      "                ",
      "                ",
      "                ",
      "                ",
      "                ",
      "                "
    ],
    [
      "c   B           ",
      "工   c           ",
      "c   cG          ",
      "ccҐcc           ",
      "c   c           ",
      "c   c           ",
      "ccͽcB           ",
      " ύ D            ",
      "                ",
      "                ",
      "                ",
      "                ",
      "                ",
      "                ",
      "                ",
      "                "
    ],
    [
      "cdddBq          ",
      "cdddcq          ",
      "cdddcq          ",
      "cccccq          ",
      "cdddcq          ",
      "cdddcq          ",
      "ccccBq          ",
      "ͳͳͳͳqq          ",
      "                ",
      "                ",
      "                ",
      "                ",
      "                ",
      "                ",
      "                ",
      "                "
    ],
    [
      "  qupt          ",
      "  qppt          ",
      "  qup           ",
      "  qppt          ",
      "  qpp           ",
      "  qup           ",
      "cccup           ",
      "  qup           ",
      "                ",
      "                ",
      "                ",
      "                ",
      "                ",
      "                ",
      "                ",
      "                "
    ],
    [
      "qu              ",
      "qup             ",
      "qupt            ",
      "qpp             ",
      "qp              ",
      "qp t            ",
      "cupt            ",
      "qup             ",
      "                ",
      "                ",
      "                ",
      "                ",
      "                ",
      "                ",
      "                ",
      "                "
    ]
  ]
}