{
  "xsize": 16,
  "zsize": 16,
  "palette": {
    "palette": [
      {
        "char": " ",
        "block": "minecraft:air"
      },
      {
        "char": "y",
        "block": "minecraft:oak_leaves"
      },
      {
        "char": "s",
        "block": "minecraft:cobbled_deepslate_slab[type=bottom]"
      },
      {
        "char": "w",
        "block": "minecraft:cobbled_deepslate_slab[type=double]"
      },
      {
        "char": "H",
        "block": "minecraft:cobbled_deepslate_slab[type=top]"
      },
      {
        "char": "C",
        "block": "minecraft:dark_oak_leaves"
      },
      {
        "char": "3",
        "block": "minecraft:oak_leaves"
      },
      {
        "char": "e",
        "block": "minecraft:air"
      },
      {
        "char": "ʹ",
        "block": "minecraft:dark_oak_leaves"
      },
      {
        "char": "X",
        "block": "minecraft:spruce_trapdoor[facing=north,half=bottom,open=true]"
      },
      {
        "char": "M",
        "block": "minecraft:oak_wood[axis=y]"
      },
      {
        "char": "Е",
        "block": "minecraft:spruce_fence[east=true,south=true]"
      },
      {
        "char": "ή",
        "block": "minecraft:oak_leaves"
      },
      {
        "char": "Ψ",
        "block": "minecraft:oak_leaves"
      },
      {
        "char": "对",
        "block": "minecraft:spruce_fence[east=true,north=true]"
      },
      {
        "char": "҄",
        "block": "minecraft:spruce_fence[north=true,west=true]"
      },
      {
        "char": "4",
        "block": "minecraft:oak_leaves"
      },
      {
        "char": "ͷ",
        "block": "minecraft:oak_leaves"
      },
      {
        "char": "f",
        "block": "minecraft:pink_terracotta"
      },
      {
        "char": "I",
        "block": "minecraft:polished_deepslate_slab[type=bottom]"
      },
      {
        "char": "U",
        "block": "minecraft:polished_deepslate_slab[type=double]"
      },
      {
        "char": "z",
        "block": "minecraft:polished_deepslate_slab[type=top]"
      },
      {
        "char": "D",
        "block": "minecraft:air"
      },
      {
        "char": ";",
        "block": "minecraft:dark_oak_leaves"
      },
      {
        "char": "я",
        "block": "minecraft:spruce_fence[south=true]"
      },
      {
        "char": "μ",
        "block": "minecraft:dark_oak_leaves"
      },
      {
        "char": "Ϗ",
        "block": "minecraft:dark_oak_leaves"
      },
      {
        "char": "ͱ",
        "block": "minecraft:oak_leaves"
      },
      {
        "char": "ϧ",
        "block": "minecraft:spruce_fence[north=true]"
      },
      {
        "char": "Σ",
        "block": "minecraft:dark_oak_leaves"
      },
      {
        "char": "Ѧ",
        "block": "minecraft:spruce_fence[east=true]"
      },
      {
        "char": "Π",
        "block": "minecraft:dark_oak_leaves"
      },
      {
        "char": "л",
        "block": "minecraft:spruce_fence"
      }
    ]
  },
  "slices": [
    [
      "   yy swH      H",
      "  Cy  swH      H",
      "   yC swH      H",
      "y 3 eyswH      H",
      " ʹ XM swH      H",
      "  ЕMήΨswH      H",
      "  对҄Ψ4swH      H",
      "  ͷ3  swH      H",
      "    yyswH      H",
      "    C swffffffff",
      "    C IUz  DD  z",
      "                ",
      "                ",
      "                ",
      "                ",
      "                "
    ],
    [
      "   y yy swH  Hws",
      "     e yswH  Hws",
      "e 3  y  swH  Hws",
      " 34;яy  swH  Hws",
      " 4;ήM ʹ swH  Hws",
      " ;μμμΨ4 swH  Hws",
      " ήM  Ϗʹ swH  Hww",
      "y  4    swH  Hws",
      "      C swH  Hws",
      "    y e swffffws",
      "   Cy   IUzD zUI",
      "                ",
      "                ",
      "                ",
      "                ",
      "                "
    ],
    [
      "    C y   swws  ",
      "y 3 yyy   swws  ",
      "  4Ψ    C swws  ",
      "ͷ ;ήM ͱy  swws  ",
      "  4;ϧΣͷͱy swws  ",
      "y       e swws  ",
      " ѦMή 3ͷ   swws  ",
      " yϧ;  ͱ C swws  ",
      " yΣ ͱy    swws  ",
      "     y    swws  ",
      "   C      IUUI  ",
      "                ",
      "                ",
      "                ",
      "                ",
      "                "
    ],
    [
      "  y  y          ",
      " y  e Cy        ",
      "Π    y  y       ",
      "34;ήM yy        ",
      "      ͱ         ",
      " yΣ   y         ",
      "  лΨ   Cy       ",
      "yy 43ͷ yC       ",
      " Σͷ3Π CC        ",
      " C ͷΣ e         ",
      "   ͱ y          ",
      "                ",
      "                ",
      "                ",
      "                ",
      "                "
    ],
    [
      "   Πͱy          ",
      "  ͷ3  yy        ",
      " ͷ3Ϗ y C        ",
      "   Ψ Cyy        ",
      " C   yy         ",
      " ͱΠ ͷ yC        ",
      "  343 y         ",
      " y              ",
      "     y          ",
      "    yy          ",
      "                ",
      "                ",
      "                ",
      "                ",
      "                ",
      "                "
    ],
    [
      "   ͱ            ",
      "    ye          ",
      "   3  e         ",
      " Π3Ϗʹ ye        ",
      "  Π3ͷ C         ",
      "  ͱͷΣ           ",
      "   3ͷ y         ",
      "    ͱ  C        ",
      "  y  e          ",
      "                ",
      "                ",
      "                ",
      "                ",
      "                ",
      "                ",
      "                "
    ]
  ]
}