{
  "xsize": 16,
  "zsize": 16,
  "palette": {
    "palette": [
      {
        "char": " ",
        "block": "minecraft:air"
      },
      {
        "char": "Ο",
        "block": "minecraft:air"
      },
      {
        "char": "g",
        "block": "minecraft:air"
      },
      {
        "char": "O",
        "block": "minecraft:air"
      },
      {
        "char": "b",
        "block": "minecraft:oak_leaves"
      },
      {
        "char": "Ώ",
        "block": "minecraft:air"
      },
      {
        "char": "Ҹ",
        "block": "minecraft:air"
      },
      {
        "char": "J",
        "block": "minecraft:air"
      },
      {
        "char": "ψ",
        "block": "minecraft:oak_button[face=floor,facing=north,powered=false]"
      },
      {
        "char": "ό",
        "block": "minecraft:oak_button[face=floor,facing=east,powered=false]"
      },
      {
        "char": "Ϝ",
        "block": "minecraft:air"
      },
      {
        "char": "3",
        "block": "minecraft:oak_leaves"
      },
      {
        "char": "Π",
        "block": "minecraft:dark_oak_leaves"
      },
      {
        "char": "4",
        "block": "minecraft:oak_leaves"
      },
      {
        "char": "ʹ",
        "block": "minecraft:dark_oak_leaves"
      },
      {
        "char": "Ψ",
        "block": "minecraft:oak_leaves"
      },
      {
        "char": ";",
        "block": "minecraft:dark_oak_leaves"
      },
      {
        "char": "C",
        "block": "minecraft:dark_oak_leaves"
      },
      {
        "char": "μ",
        "block": "minecraft:dark_oak_leaves"
      },
      {
        "char": "M",
        "block": "minecraft:oak_wood[axis=y]"
      },
      {
        "char": "ή",
        "block": "minecraft:oak_leaves"
      },
      {
        "char": "y",
        "block": "minecraft:oak_leaves"
      },
      {
        "char": "Χ",
        "block": "minecraft:air"
      },
      {
        "char": "в",
        "block": "minecraft:air"
      },
      {
        "char": "б",
        "block": "minecraft:air"
      },
      {
        "char": "ͱ",
        "block": "minecraft:oak_leaves"
      },
      {
        "char": "δ",
        "block": "minecraft:air"
      },
      {
        "char": "Ђ",
        "block": "minecraft:air"
      },
      {
        "char": "ζ",
        "block": "minecraft:air"
      },
      {
        "char": "e",
        "block": "minecraft:air"
      },
      {
        "char": "Ϲ",
        "block": "minecraft:birch_trapdoor[facing=east,half=top,open=false]"
      },
      {
        "char": "z",
        "block": "minecraft:polished_deepslate_slab[type=top]"
      },
      {
        "char": "x",
        "block": "minecraft:oak_slab[type=top]"
      },
      {
        "char": "ͷ",
        "block": "minecraft:oak_leaves"
      },
      {
        "char": "s",
        "block": "minecraft:cobbled_deepslate_slab[type=bottom]"
      },
      {
        "char": "I",
        "block": "minecraft:polished_deepslate_slab[type=bottom]"
      },
      {
        "char": "w",
        "block": "minecraft:cobbled_deepslate_slab[type=double]"
      },
      {
        "char": "U",
        "block": "minecraft:polished_deepslate_slab[type=double]"
      }
    ]
  },
  "slices": [
    [
      "                ",
      "    Ο           ",
      "gO bΏb          ",
      "Ҹg  bJ          ",
      "bg              ",
      "ψg              ",
      "bg              ",
      "όg              ",
      "Ϝg              ",
      " g              ",
      "gO              ",
      "                ",
      "     3Π         ",
      "  43ʹ4ʹ         ",
      "  Ψ Ο; C        ",
      " ;μμMή y        "
    ],
    [
      "                ",
      "    b           ",
      "gO bJ           ",
      " g              ",
      " Χ              ",
      " g              ",
      "вб              ",
      " g              ",
      "вб              ",
      " g              ",
      "gO              ",
      "    yCC         ",
      "      ͱ         ",
      "    δЂ y        ",
      "  ΨήMζCe        ",
      "   Ψμe          "
    ],
    [
      "                ",
      "                ",
      "gO  b           ",
      " g              ",
      "вбϹ             ",
      " g              ",
      " ΧϹ             ",
      " g              ",
      "вбϹ             ",
      " g              ",
      "gO              ",
      "   y e          ",
      "  e  y y        ",
      "   C   y        ",
      "e 4 Jeyy        ",
      "  3  C          "
    ],
    [
      "                ",
      "zzz             ",
      "gOz             ",
      "xg              ",
      "xg              ",
      "xg              ",
      "xg              ",
      "xg              ",
      "xg              ",
      "xg              ",
      "gOz             ",
      "zzz y           ",
      "  yCy C         ",
      " ey C e         ",
      "     Cye        ",
      "y ͷ yC          "
    ],
    [
      "                ",
      "                ",
      "ssI             ",
      "wwU             ",
      " gz             ",
      " g              ",
      " g              ",
      " g              ",
      " gz             ",
      "wwU             ",
      "ssI             ",
      "                ",
      "                ",
      "     C          ",
      "   CyC          ",
      "    CCC         "
    ],
    [
      "                ",
      "                ",
      "                ",
      "                ",
      "ssI             ",
      "wwU             ",
      " gz             ",
      "wwU             ",
      "ssI             ",
      "                ",
      "                ",
      "                ",
      "                ",
      "                ",
      "    ye          ",
      "   e            "
    ]
  ]
}