{
  "xsize": 16,
  "zsize": 16,
  "palette": {
    "palette": [
      {
        "char": " ",
        "block": "minecraft:structure_void"
      },
      {
        "char": "o",
        "block": "minecraft:blackstone"
      },
      {
        "char": "i",
        "block": "minecraft:deepslate[axis=y]"
      },
      {
        "char": "j",
        "block": "minecraft:basalt[axis=x]"
      },
      {
        "char": "d",
        "block": "minecraft:cyan_terracotta"
      },
      {
        "char": "l",
        "block": "minecraft:cobbled_deepslate"
      },
      {
        "char": "a",
        "block": "minecraft:grass_block[snowy=false]"
      },
      {
        "char": "F",
        "block": "minecraft:cobblestone"
      },
      {
        "char": "E",
        "block": "minecraft:dead_brain_coral_block"
      },
      {
        "char": "z",
        "block": "minecraft:dead_fire_coral_block"
      },
      {
        "char": "y",
        "block": "minecraft:stone"
      },
      {
        "char": "A",
        "block": "minecraft:dead_bubble_coral_block"
      },
      {
        "char": "g",
        "block": "minecraft:air"
      },
      {
        "char": "c",
        "block": "minecraft:oak_leaves"
      },
      {
        "char": "x",
        "block": "minecraft:air"
      },
      {
        "char": "t",
        "block": "minecraft:air"
      },
      {
        "char": "m",
        "block": "minecraft:stone_bricks"
      },
      {
        "char": "ϋ",
        "block": "minecraft:air"
      },
      {
        "char": "Ͷ",
        "block": "minecraft:air"
      },
      {
        "char": "ϙ",
        "block": "minecraft:air"
      },
      {
        "char": "v",
        "block": "minecraft:air"
      },
      {
        "char": "G",
        "block": "minecraft:air"
      },
      {
        "char": "π",
        "block": "minecraft:air"
      },
      {
        "char": "Ϸ",
        "block": "minecraft:air"
      },
      {
        "char": "1",
        "block": "minecraft:air"
      },
      {
        "char": "u",
        "block": "minecraft:air"
      },
      {
        "char": "͵",
        "block": "minecraft:stone_brick_wall[up=true]"
      },
      {
        "char": "Μ",
        "block": "minecraft:spruce_trapdoor[facing=east,half=top,open=true]"
      },
      {
        "char": "Ύ",
        "block": "minecraft:spruce_trapdoor[facing=east,half=top,open=false]"
      },
      {
        "char": "ͳ",
        "block": "minecraft:campfire[facing=east,lit=false]",
        "tag": {
          "x": -569,
          "y": -55,
          "Items": [],
          "z": 0,
          "CookingTimes": [
            "I",
            0,
            0,
            0,
            0
          ],
          "CookingTotalTimes": [
            "I",
            0,
            0,
            0,
            0
          ],
          "id": "minecraft:campfire"
        }
      },
      {
        "char": "C",
        "block": "minecraft:spruce_trapdoor[facing=west,half=bottom,open=false]"
      },
      {
        "char": "0",
        "block": "minecraft:campfire[facing=west,lit=false]",
        "tag": {
          "x": -565,
          "y": -55,
          "Items": [],
          "z": -1,
          "CookingTimes": [
            "I",
            0,
            0,
            0,
            0
          ],
          "CookingTotalTimes": [
            "I",
            0,
            0,
            0,
            0
          ],
          "id": "minecraft:campfire"
        }
      }
    ]
  },
  "slices": [
    [
      "oiijiidjdjjolodo",
      "ijiddddaaojdddai",
      "olioddddajjdlioo",
      "jljjjjdiiijdjili",
      "dlijiildjljiooji",
      "ldjlijldliiijadl",
      "aialiddldloodida",
      "djdiijioolidojji",
      "odjllljdoiaiiidi",
      "aaaaaaaaaaaaaaaa",
      "aaaaaaaaaaaaaaaa",
      "aaaaaaaaaaaaaaaa",
      "aaaaaaFFEFzFyyAE",
      "aaaaaayAFyEyzzEz",
      "aaaaaaFAFEzFzFEy",
      "aaaaaaAyzEAyzzFE"
    ],
    [
      "                ",
      "       gg     g ",
      "        g       ",
      "                ",
      "                ",
      "             g  ",
      "g g            g",
      "                ",
      "          g     ",
      "ccxcccxccxccxcxc",
      "cgcttcggcctgggtc",
      "cgccggcmgggtmccg",
      "ctgggcϋͶϙvvv    ",
      "Gcgggc Ͷ        ",
      "ctccgg π        ",
      "cgcggg Ϸ        "
    ],
    [
      "                ",
      "                ",
      "                ",
      "                ",
      "                ",
      "                ",
      "                ",
      "                ",
      "                ",
      "c1ccc1111cc1c111",
      "c cuu     u   uc",
      "G      ͵   u͵   ",
      "Gu              ",
      "c               ",
      "cu              ",
      "G c             "
    ],
    [
      "                ",
      "                ",
      "                ",
      "                ",
      "                ",
      "                ",
      "                ",
      "                ",
      "                ",
      "                ",
      "                ",
      "       ͵    ͵   ",
      "                ",
      "                ",
      "                ",
      "                "
    ],
    [
      "                ",
      "                ",
      "                ",
      "                ",
      "                ",
      "                ",
      "                ",
      "                ",
      "                ",
      "                ",
      "                ",
      "       ͵    ͵   ",
      "       c        ",
      "        Μ Ύc    ",
      "            Μ   ",
      "        Ύc  Ύ   "
    ],
    [
      "                ",
      "                ",
      "                ",
      "                ",
      "                ",
      "                ",
      "                ",
      "                ",
      "                ",
      "                ",
      "                ",
      "       ͳCͳCͳCͳCͳ",
      "       c 0C0CcC0",
      "       0 0 cC0c0",
      "       0c0Cc cC0",
      "       0 c 0 cCc"
    ]
  ]
}