{
  "xsize": 16,
  "zsize": 16,
  "palette": {
    "palette": [
      {
        "char": " ",
        "block": "minecraft:air"
      },
      {
        "char": "k",
        "block": "minecraft:vine[east=false,north=false,south=true,up=false,west=false]"
      },
      {
        "char": "f",
        "block": "minecraft:vine[east=true,north=false,south=false,up=false,west=false]"
      },
      {
        "char": "c",
        "block": "minecraft:cracked_stone_bricks"
      },
      {
        "char": "g",
        "block": "minecraft:glass_pane[east=true,north=false,south=false,west=true]"
      },
      {
        "char": "n",
        "block": "minecraft:air"
      },
      {
        "char": "a",
        "block": "minecraft:mossy_cobblestone"
      },
      {
        "char": "m",
        "block": "minecraft:stone_bricks"
      },
      {
        "char": "h",
        "block": "minecraft:glass_pane[east=false,north=true,south=true,west=false]"
      },
      {
        "char": "i",
        "block": "minecraft:cobblestone"
      },
      {
        "char": "l",
        "block": "minecraft:oak_leaves"
      },
      {
        "char": "j",
        "block": "minecraft:stone"
      },
      {
        "char": "b",
        "block": "minecraft:mossy_stone_bricks"
      },
      {
        "char": "Ι",
        "block": "minecraft:vine[east=true,north=false,south=false,up=true,west=false]"
      },
      {
        "char": "y",
        "block": "minecraft:stone_slab[type=top]"
      },
      {
        "char": "Γ",
        "block": "minecraft:air"
      },
      {
        "char": "Ω",
        "block": "minecraft:oak_stairs[facing=north,half=bottom,shape=straight]"
      },
      {
        "char": ";",
        "block": "minecraft:spruce_stairs[facing=west,half=top,shape=straight]"
      },
      {
        "char": "C",
        "block": "minecraft:spruce_slab[type=top]"
      },
      {
        "char": "ͼ",
        "block": "minecraft:spruce_stairs[facing=east,half=top,shape=straight]"
      },
      {
        "char": "Κ",
        "block": "minecraft:spruce_slab[type=bottom]"
      }
    ]
  },
  "slices": [
    [
      "                ",
      "                ",
      "                ",
      "                ",
      "                ",
      "                ",
      "              k ",
      "          kkkkkk",
      "       fcgngagmg",
      "       fh       ",
      "       fi       ",
      "       fh       ",
      "       la       ",
      "      llh       ",
      "        c       ",
      "        h       "
    ],
    [
      "                ",
      "                ",
      "                ",
      "                ",
      "                ",
      "                ",
      "              k ",
      "          kkkkkk",
      "       fjcmjjacb",
      "       fjjaiaacb",
      "       fjabcaccb",
      "       fbbjabcbi",
      "       Ιacbaanca",
      "       laijbcb y",
      "       ljbjiij y",
      "       ljbncnbΓ "
    ],
    [
      "                ",
      "                ",
      "                ",
      "                ",
      "                ",
      "                ",
      "              k ",
      "          kkkkkk",
      "       fmgbgagbg",
      "       fh       ",
      "       fc       ",
      "        h       ",
      "       lb  Ω   Ω",
      "       lh ;Cͼ ;C",
      "       lb CCC CΚ",
      "      llh ;Cͼ Κ "
    ],
    [
      "                ",
      "                ",
      "                ",
      "                ",
      "                ",
      "                ",
      "              k ",
      "          kkkkkk",
      "       figagigbg",
      "       fh       ",
      "       Ιm       ",
      "       lh       ",
      "       lm       ",
      "        h       ",
      "       li       ",
      "       lh       "
    ],
    [
      "                ",
      "                ",
      "                ",
      "                ",
      "                ",
      "                ",
      "              k ",
      "          kkkkkk",
      "       fbjnababa",
      "       Ιj       ",
      "       la       ",
      "       lj       ",
      "       fn       ",
      "        m       ",
      "        i       ",
      "       lm       "
    ],
    [
      "                ",
      "                ",
      "                ",
      "                ",
      "                ",
      "                ",
      "              k ",
      "          kkkkkk",
      "       figagbgbg",
      "       lh       ",
      "       Ιm       ",
      "       fh       ",
      "       fb       ",
      "        h       ",
      "        a       ",
      "       lh       "
    ]
  ]
}