{
  "xsize": 16,
  "zsize": 16,
  "palette": {
    "palette": [
      {
        "char": " ",
        "block": "minecraft:air"
      },
      {
        "char": "f",
        "block": "minecraft:vine[east=true,north=false,south=false,up=false,west=false]"
      },
      {
        "char": "k",
        "block": "minecraft:vine[east=false,north=false,south=true,up=false,west=false]"
      },
      {
        "char": "b",
        "block": "minecraft:mossy_stone_bricks"
      },
      {
        "char": "g",
        "block": "minecraft:glass_pane[east=true,north=false,south=false,west=true]"
      },
      {
        "char": "j",
        "block": "minecraft:stone"
      },
      {
        "char": "m",
        "block": "minecraft:stone_bricks"
      },
      {
        "char": "i",
        "block": "minecraft:cobblestone"
      },
      {
        "char": "d",
        "block": "minecraft:vine[east=false,north=false,south=false,up=false,west=true]"
      },
      {
        "char": "h",
        "block": "minecraft:glass_pane[east=false,north=true,south=true,west=false]"
      },
      {
        "char": "c",
        "block": "minecraft:cracked_stone_bricks"
      },
      {
        "char": "l",
        "block": "minecraft:oak_leaves"
      },
      {
        "char": "a",
        "block": "minecraft:mossy_cobblestone"
      },
      {
        "char": "n",
        "block": "minecraft:air"
      },
      {
        "char": "y",
        "block": "minecraft:stone_slab[type=top]"
      },
      {
        "char": "Γ",
        "block": "minecraft:air"
      },
      {
        "char": "A",
        "block": "minecraft:terracotta"
      },
      {
        "char": "x",
        "block": "minecraft:light_gray_carpet"
      },
      {
        "char": "σ",
        "block": "minecraft:oak_wall_sign",
        "tag": {
          "z": 581,
          "x": 242,
          "is_waxed": "0b",
          "ForgeCaps": {
            "supplementaries:antique_ink": {
              "ink": "0b"
            }
          },
          "id": "minecraft:sign",
          "y": 184,
          "front_text": {
            "color": "black",
            "has_glowing_text": "0b",
            "messages": [
              "{\"text\":\"\"}",
              "{\"text\":\"\"}",
              "{\"text\":\"\"}",
              "{\"text\":\"\"}"
            ]
          },
          "back_text": {
            "color": "black",
            "has_glowing_text": "0b",
            "messages": [
              "{\"text\":\"\"}",
              "{\"text\":\"\"}",
              "{\"text\":\"\"}",
              "{\"text\":\"\"}"
            ]
          }
        }
      },
      {
        "char": "Ζ",
        "block": "minecraft:smooth_stone_slab[type=bottom]"
      },
      {
        "char": "K",
        "block": "minecraft:cobblestone_slab[type=bottom]"
      }
    ]
  },
  "slices": [
    [
      "                ",
      "                ",
      "                ",
      "                ",
      "                ",
      "                ",
      "fkkk            ",
      "                ",
      "bgjgmgigbd      ",
      "        hd      ",
      "        jd      ",
      "        hd      ",
      "        cdd     ",
      "        hdd     ",
      " ll     a       ",
      "  ll    h       "
    ],
    [
      "                ",
      "                ",
      "                ",
      "                ",
      "                ",
      "                ",
      "fkkk            ",
      "                ",
      "ijmbbabaad      ",
      "bjmbnnanid      ",
      "babbaiibad      ",
      "bncaacabbd      ",
      "bmbbabbbndd     ",
      "maiaiccbmdd     ",
      "ymΓjcaaim       ",
      " llaimnca       "
    ],
    [
      "                ",
      "                ",
      "                ",
      "                ",
      "                ",
      "                ",
      "fkkk            ",
      "                ",
      "agmgigigad      ",
      "     lllhd      ",
      "     lllnd      ",
      "    lll hd      ",
      "A   Alx idd     ",
      "AlllAl  hdd     ",
      "AlσΖA   a       ",
      "  ll    h       "
    ],
    [
      "                ",
      "                ",
      "                ",
      "                ",
      "                ",
      "                ",
      "fkkk            ",
      "                ",
      "ngagigcgad      ",
      "       lhd      ",
      "      llid      ",
      "      l hd      ",
      "    ll  bdd     ",
      "l  l    hdd     ",
      " lll    a       ",
      "   l    h       "
    ],
    [
      "                ",
      "                ",
      "                ",
      "                ",
      "                ",
      "                ",
      "fkkk            ",
      "                ",
      "amjancbaad      ",
      "      llnd      ",
      "       lcd      ",
      "        id      ",
      "        cdd     ",
      "        jdd     ",
      "  K     a       ",
      "        c       "
    ],
    [
      "                ",
      "                ",
      "                ",
      "                ",
      "                ",
      "                ",
      "fkkk            ",
      "      l         ",
      "bgjgngblnd      ",
      "      llhd      ",
      "        bd      ",
      "        hd      ",
      "        idd     ",
      "        hdd     ",
      "        i       ",
      "        h       "
    ]
  ]
}