{
  "xsize": 16,
  "zsize": 16,
  "palette": {
    "palette": [
      {
        "char": " ",
        "block": "minecraft:air"
      },
      {
        "char": "f",
        "block": "minecraft:vine[east=true,north=false,south=false,up=false,west=false]"
      },
      {
        "char": "k",
        "block": "minecraft:vine[east=false,north=false,south=true,up=false,west=false]"
      },
      {
        "char": "Ϫ",
        "block": "minecraft:vine[east=false,north=false,south=true,up=true,west=false]"
      },
      {
        "char": "l",
        "block": "minecraft:oak_leaves"
      },
      {
        "char": "b",
        "block": "minecraft:mossy_stone_bricks"
      },
      {
        "char": "g",
        "block": "minecraft:glass_pane[east=true,north=false,south=false,west=true]"
      },
      {
        "char": "a",
        "block": "minecraft:mossy_cobblestone"
      },
      {
        "char": "d",
        "block": "minecraft:vine[east=false,north=false,south=false,up=false,west=true]"
      },
      {
        "char": "h",
        "block": "minecraft:glass_pane[east=false,north=true,south=true,west=false]"
      },
      {
        "char": "j",
        "block": "minecraft:stone"
      },
      {
        "char": "m",
        "block": "minecraft:stone_bricks"
      },
      {
        "char": "i",
        "block": "minecraft:cobblestone"
      },
      {
        "char": "c",
        "block": "minecraft:cracked_stone_bricks"
      },
      {
        "char": "y",
        "block": "minecraft:stone_slab[type=top]"
      },
      {
        "char": "ц",
        "block": "minecraft:cobblestone_stairs[facing=east,half=top,shape=straight]"
      },
      {
        "char": "у",
        "block": "minecraft:stone_stairs[facing=east,half=top,shape=straight]"
      },
      {
        "char": "ϧ",
        "block": "minecraft:cobblestone_slab[type=top]"
      },
      {
        "char": "x",
        "block": "minecraft:light_gray_carpet"
      },
      {
        "char": "Ц",
        "block": "minecraft:vine[east=true,north=false,south=true,up=false,west=false]"
      }
    ]
  },
  "slices": [
    [
      "                ",
      "                ",
      "                ",
      "                ",
      "                ",
      "                ",
      "f kϪ            ",
      "l ll            ",
      "bgbgagagad      ",
      "        hd      ",
      "        bd      ",
      "        hd      ",
      "        bdd     ",
      "        hdd     ",
      "        b       ",
      "        h       "
    ],
    [
      "                ",
      "                ",
      "                ",
      "                ",
      "                ",
      "                ",
      "flkl            ",
      " lllll          ",
      "jaamiccicd      ",
      "      yцbd      ",
      "       уcd      ",
      "       ϧad      ",
      "        jdd     ",
      "        bdd     ",
      "        b       ",
      "       ya       "
    ],
    [
      "                ",
      "                ",
      "                ",
      "                ",
      "                ",
      "                ",
      "fl  l           ",
      "lllflll         ",
      "jgjgigcgbd      ",
      "        hd      ",
      "        bd      ",
      "       xhd      ",
      "        bdd     ",
      "        hdd     ",
      "        a       ",
      "        h       "
    ],
    [
      "                ",
      "                ",
      "                ",
      "                ",
      "                ",
      "                ",
      "    Цl          ",
      "ll flll         ",
      "bgbgigagad      ",
      "        hd      ",
      "        cd      ",
      "        hd      ",
      "        bdd     ",
      "        hdd     ",
      "        c       ",
      "        h       "
    ],
    [
      "                ",
      "                ",
      "                ",
      "                ",
      "                ",
      "                ",
      "     kl         ",
      "l    lll        ",
      "ijimbbbamd      ",
      "        cd      ",
      "        bd      ",
      "        ad      ",
      "        cdd     ",
      "        bdd     ",
      "        c       ",
      "        c       "
    ],
    [
      "                ",
      "                ",
      "                ",
      "                ",
      "                ",
      "                ",
      "     kk         ",
      "l    lll        ",
      "bgmgjgmgjd      ",
      "        hd      ",
      "        bd      ",
      "        hd      ",
      "        jdd     ",
      "        hdd     ",
      "        a       ",
      "        h       "
    ]
  ]
}