{
  "xsize": 16,
  "zsize": 16,
  "palette": {
    "palette": [
      {
        "char": " ",
        "block": "minecraft:air"
      },
      {
        "char": "c",
        "block": "minecraft:cracked_stone_bricks"
      },
      {
        "char": "f",
        "block": "minecraft:vine[east=true,north=false,south=false,up=false,west=false]"
      },
      {
        "char": "h",
        "block": "minecraft:glass_pane[east=false,north=true,south=true,west=false]"
      },
      {
        "char": "a",
        "block": "minecraft:mossy_cobblestone"
      },
      {
        "char": "b",
        "block": "minecraft:mossy_stone_bricks"
      },
      {
        "char": "m",
        "block": "minecraft:stone_bricks"
      },
      {
        "char": "g",
        "block": "minecraft:glass_pane[east=true,north=false,south=false,west=true]"
      },
      {
        "char": "n",
        "block": "minecraft:air"
      },
      {
        "char": "e",
        "block": "minecraft:vine[east=false,north=true,south=false,up=false,west=false]"
      },
      {
        "char": "j",
        "block": "minecraft:stone"
      },
      {
        "char": "i",
        "block": "minecraft:cobblestone"
      },
      {
        "char": "H",
        "block": "minecraft:spruce_trapdoor[facing=west,half=bottom,open=true]"
      },
      {
        "char": "B",
        "block": "minecraft:farmland[moisture=7]"
      },
      {
        "char": "F",
        "block": "minecraft:spruce_trapdoor[facing=east,half=bottom,open=true]"
      },
      {
        "char": "ϴ",
        "block": "minecraft:water"
      },
      {
        "char": "ν",
        "block": "minecraft:spruce_trapdoor[facing=south,half=bottom,open=true]"
      },
      {
        "char": "Ў",
        "block": "minecraft:chest",
        "loot": "bigbuildingsloot",
        "tag": {
          "z": 583,
          "x": 241,
          "ForgeCaps": {},
          "id": "minecraft:chest",
          "y": 178,
          "Items": []
        }
      },
      {
        "char": "Њ",
        "block": "minecraft:chest",
        "loot": "bigbuildingsloot",
        "tag": {
          "z": 583,
          "x": 242,
          "ForgeCaps": {},
          "id": "minecraft:chest",
          "y": 178,
          "Items": []
        }
      },
      {
        "char": "G",
        "block": "minecraft:oak_sapling"
      },
      {
        "char": "E",
        "block": "minecraft:redstone_lamp[lit=false]"
      },
      {
        "char": "Ϙ",
        "block": "minecraft:oak_fence[east=true,west=true]"
      },
      {
        "char": "А",
        "block": "minecraft:smooth_stone_slab[type=top]"
      },
      {
        "char": "ч",
        "block": "minecraft:lever[face=wall,facing=east,powered=false]"
      },
      {
        "char": "P",
        "block": "minecraft:redstone_wire[east=none,west=none]"
      },
      {
        "char": "Q",
        "block": "minecraft:oak_fence"
      },
      {
        "char": "Ѕ",
        "block": "minecraft:redstone_wire[west=none]"
      },
      {
        "char": "Ѐ",
        "block": "minecraft:redstone_wire[north=none,south=none]"
      },
      {
        "char": "Ї",
        "block": "minecraft:redstone_wire[east=none]"
      }
    ]
  },
  "slices": [
    [
      "        c       ",
      "       fh       ",
      "       fa       ",
      "       fh       ",
      "       fb       ",
      "       fh       ",
      "       fa       ",
      "       fh       ",
      "       fmgbgbgng",
      "        eeeeeeee",
      "                ",
      "                ",
      "                ",
      "                ",
      "                ",
      "                "
    ],
    [
      "        abnaj   ",
      "       fbbbmbc  ",
      "       faababc j",
      "       fncmjcaan",
      "       fnbccajac",
      "       fnanjccbj",
      "       ficaaaama",
      "       fnjjmccii",
      "       fambmbacn",
      "        eeeeeeee",
      "                ",
      "                ",
      "                ",
      "                ",
      "                ",
      "                "
    ],
    [
      "        mHBBBF  ",
      "       fhHBBBF  ",
      "       faHBBBF  ",
      "       fhHBϴBF  ",
      "       faHBBBF  ",
      "       fhHBBBF  ",
      "       fcHBBBF  ",
      "       fh ννν ЎЊ",
      "       fagcgagcg",
      "        eeeeeeee",
      "                ",
      "                ",
      "                ",
      "                ",
      "                ",
      "                "
    ],
    [
      "        i G G   ",
      "       fh G G   ",
      "       fn G G   ",
      "       fh G G   ",
      "       fa G G   ",
      "       fh G G   ",
      "       fa G G   ",
      "       fh       ",
      "       fmgagjgbg",
      "        eeeeeeee",
      "                ",
      "                ",
      "                ",
      "                ",
      "                ",
      "                "
    ],
    [
      "        i E E   ",
      "       fb EϘE   ",
      "       fc E E   ",
      "       fa EАEч  ",
      "       fa E E   ",
      "       fc EϘE   ",
      "       fa E E   ",
      "       fa       ",
      "       fabbacaaa",
      "        eeeeeeee",
      "                ",
      "                ",
      "                ",
      "                ",
      "                ",
      "                "
    ],
    [
      "        b       ",
      "       fh PQP   ",
      "       fa P P   ",
      "       fh ЅЀЇ   ",
      "       fb P P   ",
      "       fh PQP   ",
      "       fb       ",
      "        h       ",
      "        ngmgigmg",
      "        eeeeeeee",
      "                ",
      "                ",
      "                ",
      "                ",
      "                ",
      "                "
    ]
  ]
}