{
  "xsize": 16,
  "zsize": 16,
  "palette": {
    "palette": [
      {
        "char": " ",
        "block": "minecraft:air"
      },
      {
        "char": "k",
        "block": "minecraft:vine[east=false,north=false,south=true,up=false,west=false]"
      },
      {
        "char": "l",
        "block": "minecraft:oak_leaves"
      },
      {
        "char": "c",
        "block": "minecraft:cracked_stone_bricks"
      },
      {
        "char": "g",
        "block": "minecraft:glass_pane[east=true,north=false,south=false,west=true]"
      },
      {
        "char": "n",
        "block": "minecraft:air"
      },
      {
        "char": "m",
        "block": "minecraft:stone_bricks"
      },
      {
        "char": "h",
        "block": "minecraft:glass_pane[east=false,north=true,south=true,west=false]"
      },
      {
        "char": "a",
        "block": "minecraft:mossy_cobblestone"
      },
      {
        "char": "ψ",
        "block": "minecraft:vine[east=true,north=true,south=false,up=false,west=false]"
      },
      {
        "char": "f",
        "block": "minecraft:vine[east=true,north=false,south=false,up=false,west=false]"
      },
      {
        "char": "b",
        "block": "minecraft:mossy_stone_bricks"
      },
      {
        "char": "j",
        "block": "minecraft:stone"
      },
      {
        "char": "i",
        "block": "minecraft:cobblestone"
      },
      {
        "char": "ш",
        "block": "minecraft:vine[east=true,north=true,south=false,up=true,west=false]"
      },
      {
        "char": "z",
        "block": "minecraft:stone_slab[type=bottom]"
      },
      {
        "char": "y",
        "block": "minecraft:stone_slab[type=top]"
      },
      {
        "char": "ϰ",
        "block": "minecraft:spruce_trapdoor[facing=north,half=top,open=true]"
      },
      {
        "char": "I",
        "block": "minecraft:bookshelf"
      },
      {
        "char": "N",
        "block": "minecraft:glass_pane[east=true,north=true,south=true,west=false]"
      },
      {
        "char": "O",
        "block": "minecraft:spruce_trapdoor[facing=east,half=bottom,open=false]"
      }
    ]
  },
  "slices": [
    [
      "                ",
      "                ",
      "                ",
      "                ",
      "                ",
      "                ",
      "              k ",
      "          kkkkkk",
      "       lcgngmgmg",
      "       lh       ",
      "       la       ",
      "        h       ",
      "       ψa       ",
      "       f        ",
      "        m       ",
      "                "
    ],
    [
      "                ",
      "                ",
      "                ",
      "                ",
      "                ",
      "                ",
      "              k ",
      "          kkkkkk",
      "       fcacaamab",
      "       lcbabjabm",
      "       libiacjba",
      "       labcbii  ",
      "       шnai   i ",
      "       fnbmaamiz",
      "        iacij y ",
      "        ccaz    "
    ],
    [
      "                ",
      "                ",
      "                ",
      "                ",
      "                ",
      "                ",
      "              k ",
      "          kkkkkk",
      "       fbgbgngbg",
      "       lhϰ      ",
      "      llmI      ",
      "       lNI      ",
      "       ljI      ",
      "        NI      ",
      "        iI      ",
      "        NI      "
    ],
    [
      "                ",
      "                ",
      "                ",
      "                ",
      "                ",
      "                ",
      "              k ",
      "          kkkkkk",
      "       figigngbg",
      "       fh       ",
      "       fcO      ",
      "       lhO      ",
      "       lcO      ",
      "        hO      ",
      "        aO      ",
      "        hO      "
    ],
    [
      "                ",
      "                ",
      "                ",
      "                ",
      "                ",
      "                ",
      "              k ",
      "          kkkkkk",
      "       fcjbabacc",
      "       fc       ",
      "       fa       ",
      "       lc       ",
      "       li       ",
      "       la       ",
      "        b       ",
      "        c       "
    ],
    [
      "                ",
      "                ",
      "                ",
      "                ",
      "                ",
      "                ",
      "              k ",
      "          kkkkkk",
      "       fagagagjg",
      "       fh       ",
      "       fm       ",
      "       fh       ",
      "       lc       ",
      "       lh       ",
      "        j       ",
      "        h       "
    ]
  ]
}