{
  "xsize": 16,
  "zsize": 16,
  "palette": {
    "palette": [
      {
        "char": " ",
        "block": "minecraft:air"
      },
      {
        "char": "f",
        "block": "minecraft:vine[east=true,north=false,south=false,up=false,west=false]"
      },
      {
        "char": "k",
        "block": "minecraft:vine[east=false,north=false,south=true,up=false,west=false]"
      },
      {
        "char": "j",
        "block": "minecraft:stone"
      },
      {
        "char": "g",
        "block": "minecraft:glass_pane[east=true,north=false,south=false,west=true]"
      },
      {
        "char": "a",
        "block": "minecraft:mossy_cobblestone"
      },
      {
        "char": "b",
        "block": "minecraft:mossy_stone_bricks"
      },
      {
        "char": "c",
        "block": "minecraft:cracked_stone_bricks"
      },
      {
        "char": "d",
        "block": "minecraft:vine[east=false,north=false,south=false,up=false,west=true]"
      },
      {
        "char": "h",
        "block": "minecraft:glass_pane[east=false,north=true,south=true,west=false]"
      },
      {
        "char": "i",
        "block": "minecraft:cobblestone"
      },
      {
        "char": "m",
        "block": "minecraft:stone_bricks"
      },
      {
        "char": "n",
        "block": "minecraft:air"
      },
      {
        "char": "z",
        "block": "minecraft:stone_slab[type=bottom]"
      },
      {
        "char": "Б",
        "block": "minecraft:air"
      },
      {
        "char": "Ω",
        "block": "minecraft:oak_stairs[facing=north,half=bottom,shape=straight]"
      },
      {
        "char": "C",
        "block": "minecraft:spruce_slab[type=top]"
      },
      {
        "char": "ͼ",
        "block": "minecraft:spruce_stairs[facing=east,half=top,shape=straight]"
      },
      {
        "char": "Κ",
        "block": "minecraft:spruce_slab[type=bottom]"
      }
    ]
  },
  "slices": [
    [
      "                ",
      "                ",
      "                ",
      "                ",
      "                ",
      "                ",
      "fkkk            ",
      "k       k       ",
      "jgagbgagcd      ",
      "        hd      ",
      "        ad      ",
      "        hd      ",
      "        bdd     ",
      "        hdd     ",
      "        b       ",
      "        h       "
    ],
    [
      "                ",
      "                ",
      "                ",
      "                ",
      "                ",
      "                ",
      "fkkk            ",
      "k       k       ",
      "jcibbcaacd      ",
      "aacacbccbd      ",
      "jaacbcbaad      ",
      "mjajjmbbbd      ",
      "mnncicbabdd     ",
      " zc bancbdd     ",
      "   Бabbbn       ",
      "    bbijn       "
    ],
    [
      "                ",
      "                ",
      "                ",
      "                ",
      "                ",
      "                ",
      "fkkk            ",
      "k       k       ",
      "igcgcgbgbd      ",
      "        hd      ",
      "        ad      ",
      "        hd      ",
      "   Ω    cdd     ",
      "   Cͼ   hdd     ",
      "  ΚΚC   m       ",
      "   Κͼ   h       "
    ],
    [
      "                ",
      "                ",
      "                ",
      "                ",
      "                ",
      "                ",
      "fkkk            ",
      "k       k       ",
      "bgcgcgcgbd      ",
      "        hd      ",
      "        ad      ",
      "        hd      ",
      "        bdd     ",
      "        hdd     ",
      "        j       ",
      "        h       "
    ],
    [
      "                ",
      "                ",
      "                ",
      "                ",
      "                ",
      "                ",
      "fkkk            ",
      "k       k       ",
      "bmcbcamcad      ",
      "        cd      ",
      "        ad      ",
      "        cd      ",
      "        cdd     ",
      "        bdd     ",
      "        c       ",
      "        a       "
    ],
    [
      "                ",
      "                ",
      "                ",
      "                ",
      "                ",
      "                ",
      "fkkk            ",
      "k       k       ",
      "igagjgagjd      ",
      "        hd      ",
      "        jd      ",
      "        hd      ",
      "        cdd     ",
      "        hdd     ",
      "        b       ",
      "        h       "
    ]
  ]
}