{
  "xsize": 16,
  "zsize": 16,
  "palette": {
    "palette": [
      {
        "char": " ",
        "block": "minecraft:air"
      },
      {
        "char": "a",
        "block": "minecraft:mossy_cobblestone"
      },
      {
        "char": "h",
        "block": "minecraft:glass_pane[east=false,north=true,south=true,west=false]"
      },
      {
        "char": "m",
        "block": "minecraft:stone_bricks"
      },
      {
        "char": "d",
        "block": "minecraft:vine[east=false,north=false,south=false,up=false,west=true]"
      },
      {
        "char": "ϓ",
        "block": "minecraft:cobweb"
      },
      {
        "char": "c",
        "block": "minecraft:cracked_stone_bricks"
      },
      {
        "char": "n",
        "block": "minecraft:air"
      },
      {
        "char": "g",
        "block": "minecraft:glass_pane[east=true,north=false,south=false,west=true]"
      },
      {
        "char": "i",
        "block": "minecraft:cobblestone"
      },
      {
        "char": "b",
        "block": "minecraft:mossy_stone_bricks"
      },
      {
        "char": "j",
        "block": "minecraft:stone"
      },
      {
        "char": "e",
        "block": "minecraft:vine[east=false,north=true,south=false,up=false,west=false]"
      },
      {
        "char": "y",
        "block": "minecraft:stone_slab[type=top]"
      },
      {
        "char": "Κ",
        "block": "minecraft:spruce_slab[type=bottom]"
      },
      {
        "char": "ͼ",
        "block": "minecraft:spruce_stairs[facing=east,half=top,shape=straight]"
      },
      {
        "char": "C",
        "block": "minecraft:spruce_slab[type=top]"
      },
      {
        "char": ";",
        "block": "minecraft:spruce_stairs[facing=west,half=top,shape=straight]"
      },
      {
        "char": "χ",
        "block": "minecraft:oak_stairs[facing=south,half=bottom,shape=straight]"
      }
    ]
  },
  "slices": [
    [
      "        a       ",
      "        h       ",
      "        m       ",
      "        hd      ",
      "        ad      ",
      "       ϓhd      ",
      "       ϓcd      ",
      "      ϓϓhd      ",
      "ngigbgjgmd      ",
      "ee  eeeee       ",
      "                ",
      "                ",
      "                ",
      "                ",
      "                ",
      "                "
    ],
    [
      "   bimbac       ",
      "    mcijc       ",
      "  ymjicmj       ",
      " c  iijjnd      ",
      "miicaciicd      ",
      "abjaaacamd      ",
      "nabjnmmjcd      ",
      "aicnncnnad      ",
      "biacaanbbd      ",
      "ee  eeeee       ",
      "                ",
      "                ",
      "                ",
      "                ",
      "                ",
      "                "
    ],
    [
      "        j       ",
      "        h       ",
      "        j       ",
      "   Κͼ   h       ",
      "C ΚCC   cd      ",
      "ͼ ;Cͼ   hd      ",
      "   χ    id      ",
      "        hd      ",
      "ngagbgigad      ",
      "ee     ee       ",
      "                ",
      "                ",
      "                ",
      "                ",
      "                ",
      "                "
    ],
    [
      "        m       ",
      "        h       ",
      "        a       ",
      "        h       ",
      "        ad      ",
      "        hd      ",
      "        bd      ",
      "        hd      ",
      "ngigcgigmd      ",
      "ee     ee       ",
      "                ",
      "                ",
      "                ",
      "                ",
      "                ",
      "                "
    ],
    [
      "        n       ",
      "        i       ",
      "        m       ",
      "        m       ",
      "        md      ",
      "        ad      ",
      "        ad      ",
      "        ad      ",
      "jbmibajnbd      ",
      "ee     ee       ",
      "                ",
      "                ",
      "                ",
      "                ",
      "                ",
      "                "
    ],
    [
      "        a       ",
      "        h       ",
      "        b       ",
      "        h       ",
      "        bd      ",
      "        hd      ",
      "        cd      ",
      "        hd      ",
      "jgagagjgcd      ",
      "ee     ee       ",
      "                ",
      "                ",
      "                ",
      "                ",
      "                ",
      "                "
    ]
  ]
}