{
  "xsize": 16,
  "zsize": 16,
  "palette": {
    "palette": [
      {
        "char": " ",
        "block": "minecraft:air"
      },
      {
        "char": "c",
        "block": "minecraft:cracked_stone_bricks"
      },
      {
        "char": "f",
        "block": "minecraft:vine[east=true,north=false,south=false,up=false,west=false]"
      },
      {
        "char": "h",
        "block": "minecraft:glass_pane[east=false,north=true,south=true,west=false]"
      },
      {
        "char": "a",
        "block": "minecraft:mossy_cobblestone"
      },
      {
        "char": "l",
        "block": "minecraft:oak_leaves"
      },
      {
        "char": "j",
        "block": "minecraft:stone"
      },
      {
        "char": "g",
        "block": "minecraft:glass_pane[east=true,north=false,south=false,west=true]"
      },
      {
        "char": "b",
        "block": "minecraft:mossy_stone_bricks"
      },
      {
        "char": "n",
        "block": "minecraft:air"
      },
      {
        "char": "e",
        "block": "minecraft:vine[east=false,north=true,south=false,up=false,west=false]"
      },
      {
        "char": "m",
        "block": "minecraft:stone_bricks"
      },
      {
        "char": "i",
        "block": "minecraft:cobblestone"
      },
      {
        "char": "z",
        "block": "minecraft:stone_slab[type=bottom]"
      },
      {
        "char": "v",
        "block": "minecraft:light_gray_concrete"
      },
      {
        "char": "N",
        "block": "minecraft:glass_pane[east=true,north=true,south=true,west=false]"
      },
      {
        "char": "Х",
        "block": "minecraft:spruce_stairs[facing=west,half=bottom,shape=inner_right]"
      },
      {
        "char": "ϩ",
        "block": "minecraft:spruce_stairs[facing=north,half=bottom,shape=straight]"
      },
      {
        "char": "Й",
        "block": "minecraft:spruce_stairs[facing=west,half=bottom,shape=outer_right]"
      },
      {
        "char": "Л",
        "block": "minecraft:spruce_stairs[facing=north,half=bottom,shape=outer_left]"
      },
      {
        "char": "Ϳ",
        "block": "minecraft:birch_slab[type=top]"
      },
      {
        "char": ";",
        "block": "minecraft:spruce_stairs[facing=west,half=top,shape=straight]"
      },
      {
        "char": "C",
        "block": "minecraft:spruce_slab[type=top]"
      },
      {
        "char": "ͼ",
        "block": "minecraft:spruce_stairs[facing=east,half=top,shape=straight]"
      },
      {
        "char": "χ",
        "block": "minecraft:oak_stairs[facing=south,half=bottom,shape=straight]"
      },
      {
        "char": "Ψ",
        "block": "minecraft:heavy_weighted_pressure_plate[power=0]"
      }
    ]
  },
  "slices": [
    [
      "        c       ",
      "       fh       ",
      "       fa       ",
      "       fh       ",
      "       fal      ",
      "       fhl      ",
      "       fjll l   ",
      "       fhllllll ",
      "       fagbgcgng",
      "        eeeeeeee",
      "                ",
      "                ",
      "                ",
      "                ",
      "                ",
      "                "
    ],
    [
      "        cjjmma  ",
      "       faibmicz ",
      "       fiibbja  ",
      "       fajbcicjz",
      "       fbcncciba",
      "       fabcjjimb",
      "       facbbbbaj",
      "       fnimaaabc",
      "       fjjibaanb",
      "        eeeeeeee",
      "                ",
      "                ",
      "                ",
      "                ",
      "                ",
      "                "
    ],
    [
      "        avvvvv  ",
      "       fNХϩЙ    ",
      "       fnЛ      ",
      "       fh       ",
      "       fa      Ϳ",
      "       fh  ;Cͼ  ",
      "       fb   χ   ",
      "       fh       ",
      "       fagcgigcg",
      "        eeeeeeee",
      "                ",
      "                ",
      "                ",
      "                ",
      "                ",
      "                "
    ],
    [
      "        avvvv   ",
      "       fh       ",
      "       fa       ",
      "       fh       ",
      "       fb       ",
      "       fh   Ψ   ",
      "       fa       ",
      "       fh       ",
      "       fngcgbgag",
      "        eeeeeeee",
      "                ",
      "                ",
      "                ",
      "                ",
      "                ",
      "                "
    ],
    [
      "        a       ",
      "       fa       ",
      "       fc       ",
      "       fm       ",
      "       fj       ",
      "       fn       ",
      "       fa       ",
      "       fj       ",
      "       fabijmaac",
      "        eeeeeeee",
      "                ",
      "                ",
      "                ",
      "                ",
      "                ",
      "                "
    ],
    [
      "        m       ",
      "       fh       ",
      "       fb       ",
      "       fh       ",
      "       fb       ",
      "       fh       ",
      "       fb       ",
      "       fh       ",
      "       fbgagagag",
      "        eeeeeeee",
      "                ",
      "                ",
      "                ",
      "                ",
      "                ",
      "                "
    ]
  ]
}