{
  "xsize": 16,
  "zsize": 16,
  "palette": {
    "palette": [
      {
        "char": " ",
        "block": "minecraft:air"
      },
      {
        "char": "l",
        "block": "minecraft:oak_leaves"
      },
      {
        "char": "b",
        "block": "minecraft:mossy_stone_bricks"
      },
      {
        "char": "h",
        "block": "minecraft:glass_pane[east=false,north=true,south=true,west=false]"
      },
      {
        "char": "f",
        "block": "minecraft:vine[east=true,north=false,south=false,up=false,west=false]"
      },
      {
        "char": "n",
        "block": "minecraft:air"
      },
      {
        "char": "a",
        "block": "minecraft:mossy_cobblestone"
      },
      {
        "char": "m",
        "block": "minecraft:stone_bricks"
      },
      {
        "char": "g",
        "block": "minecraft:glass_pane[east=true,north=false,south=false,west=true]"
      },
      {
        "char": "j",
        "block": "minecraft:stone"
      },
      {
        "char": "i",
        "block": "minecraft:cobblestone"
      },
      {
        "char": "c",
        "block": "minecraft:cracked_stone_bricks"
      },
      {
        "char": "e",
        "block": "minecraft:vine[east=false,north=true,south=false,up=false,west=false]"
      },
      {
        "char": "y",
        "block": "minecraft:stone_slab[type=top]"
      },
      {
        "char": "v",
        "block": "minecraft:light_gray_concrete"
      },
      {
        "char": "ϩ",
        "block": "minecraft:spruce_stairs[facing=north,half=bottom,shape=straight]"
      },
      {
        "char": "Ι",
        "block": "minecraft:vine[east=true,north=false,south=false,up=true,west=false]"
      },
      {
        "char": "Ϳ",
        "block": "minecraft:birch_slab[type=top]"
      },
      {
        "char": ";",
        "block": "minecraft:spruce_stairs[facing=west,half=top,shape=straight]"
      },
      {
        "char": "C",
        "block": "minecraft:spruce_slab[type=top]"
      },
      {
        "char": "ͼ",
        "block": "minecraft:spruce_stairs[facing=east,half=top,shape=straight]"
      },
      {
        "char": "χ",
        "block": "minecraft:oak_stairs[facing=south,half=bottom,shape=straight]"
      },
      {
        "char": "Ψ",
        "block": "minecraft:heavy_weighted_pressure_plate[power=0]"
      }
    ]
  },
  "slices": [
    [
      "       lb       ",
      "       lh       ",
      "       fn       ",
      "       fh       ",
      "       fb       ",
      "       fh       ",
      "       fa       ",
      "       fh       ",
      "       fmgjgigcg",
      "        eeeeeeee",
      "                ",
      "                ",
      "                ",
      "                ",
      "                ",
      "                "
    ],
    [
      "       lmnbai   ",
      "       lcammb   ",
      "       fbajai y ",
      "       fnjmbabjb",
      "       faiiacabc",
      "       fmbjcbcbi",
      "       fnacaaanb",
      "       faamcbnjc",
      "       facibaaac",
      "        eeeeeeee",
      "                ",
      "                ",
      "                ",
      "                ",
      "                ",
      "                "
    ],
    [
      "       lilvvv   ",
      "       lhϩ ϩ    ",
      "       Ιb       ",
      "        h       ",
      "       fb      Ϳ",
      "       fh  ;Cͼ  ",
      "       fa   χ   ",
      "       fh       ",
      "       fagbgjgag",
      "        eeeeeeee",
      "                ",
      "                ",
      "                ",
      "                ",
      "                ",
      "                "
    ],
    [
      "        mlvv    ",
      "       lhl      ",
      "       lc       ",
      "        h       ",
      "       fc       ",
      "       fh   Ψ   ",
      "       fa       ",
      "       fh       ",
      "       fagbgbgjg",
      "        eeeeeeee",
      "                ",
      "                ",
      "                ",
      "                ",
      "                ",
      "                "
    ],
    [
      "        il      ",
      "       Ιbl      ",
      "       lnl      ",
      "       lm       ",
      "       fn       ",
      "       fi       ",
      "       fa       ",
      "       fm       ",
      "       fbcjaaabb",
      "        eeeeeeee",
      "                ",
      "                ",
      "                ",
      "                ",
      "                ",
      "                "
    ],
    [
      "        al      ",
      "       lhll     ",
      "       lcll   l ",
      "       lhl l    ",
      "       fi       ",
      "       fh       ",
      "       fm       ",
      "       fh       ",
      "       fjgbgcgag",
      "        eeeeeeee",
      "                ",
      "                ",
      "                ",
      "                ",
      "                ",
      "                "
    ]
  ]
}