{
  "xsize": 16,
  "zsize": 16,
  "palette": {
    "palette": [
      {
        "char": " ",
        "block": "minecraft:air"
      },
      {
        "char": "u",
        "block": "minecraft:cyan_terracotta"
      },
      {
        "char": "q",
        "block": "minecraft:blackstone"
      },
      {
        "char": "t",
        "block": "minecraft:deepslate[axis=y]"
      },
      {
        "char": "r",
        "block": "minecraft:basalt[axis=x]"
      },
      {
        "char": "o",
        "block": "minecraft:grass_block[snowy=false]"
      },
      {
        "char": "a",
        "block": "minecraft:mossy_cobblestone"
      },
      {
        "char": "m",
        "block": "minecraft:stone_bricks"
      },
      {
        "char": "L",
        "block": "minecraft:andesite"
      },
      {
        "char": "c",
        "block": "minecraft:cracked_stone_bricks"
      },
      {
        "char": "i",
        "block": "minecraft:cobblestone"
      },
      {
        "char": "s",
        "block": "minecraft:cobbled_deepslate"
      },
      {
        "char": "b",
        "block": "minecraft:mossy_stone_bricks"
      },
      {
        "char": "j",
        "block": "minecraft:stone"
      },
      {
        "char": "w",
        "block": "minecraft:dirt"
      },
      {
        "char": "p",
        "block": "minecraft:air"
      },
      {
        "char": "K",
        "block": "minecraft:cobblestone_slab[type=bottom,waterlogged=false]"
      },
      {
        "char": "f",
        "block": "minecraft:vine[east=true,north=false,south=false,up=false,west=false]"
      },
      {
        "char": "ϕ",
        "block": "minecraft:stone_brick_slab[type=bottom,waterlogged=false]"
      },
      {
        "char": "Ϻ",
        "block": "minecraft:air"
      },
      {
        "char": "M",
        "block": "minecraft:acacia_leaves[distance=7,persistent=true,waterlogged=false]"
      },
      {
        "char": "D",
        "block": "minecraft:gravel"
      },
      {
        "char": "΄",
        "block": "minecraft:mossy_cobblestone_slab[type=bottom,waterlogged=false]"
      },
      {
        "char": "ϵ",
        "block": "minecraft:infested_cracked_stone_bricks"
      },
      {
        "char": "n",
        "block": "minecraft:air"
      },
      {
        "char": "e",
        "block": "minecraft:vine[east=false,north=true,south=false,up=false,west=false]"
      },
      {
        "char": "г",
        "block": "minecraft:skeleton_skull[rotation=7]",
        "tag": {
          "z": 585,
          "x": 238,
          "ForgeCaps": {},
          "id": "minecraft:skull",
          "y": 135
        }
      },
      {
        "char": "Є",
        "block": "minecraft:air"
      },
      {
        "char": "о",
        "block": "minecraft:azure_bluet"
      },
      {
        "char": "В",
        "block": "minecraft:air"
      },
      {
        "char": "β",
        "block": "minecraft:glass_pane[east=false,north=false,south=true,waterlogged=false,west=false]"
      },
      {
        "char": "h",
        "block": "minecraft:glass_pane[east=false,north=true,south=true,waterlogged=false,west=false]"
      },
      {
        "char": "g",
        "block": "minecraft:glass_pane[east=true,north=false,south=false,waterlogged=false,west=true]"
      },
      {
        "char": "z",
        "block": "minecraft:stone_slab[type=bottom,waterlogged=false]"
      },
      {
        "char": "Θ",
        "block": "minecraft:air"
      }
    ]
  },
  "slices": [
    [
      "uqtrooooaamLLcim",
      "tqrsooooboabbjLb",
      "ttsqoowowmambLci",
      "ssqroooowibbiiia",
      "rsqtoooowjiibimb",
      "rqqqoooowabaacai",
      "ttquwooowajcaaja",
      "rqttoooowcbjacaj",
      "uqrsoooowwwwwwww",
      "rutsoooooooooooo",
      "rqtsoooooooooooo",
      "stsssursrtsquqqt",
      "qtrtttuqrrrusqrt",
      "rrqtrtsrqrruuuqu",
      "qqssqtuqrstqussu",
      "tsrrussqruqsusrq"
    ],
    [
      "     ppp  Kbaacb",
      "    pppfm  caajb",
      "    ppϕfb  imaji",
      "     pϺfb   mimj",
      "    pppMcDD   im",
      "    pppMc   D ΄a",
      "    ϵppMc a    D",
      "      pMb       ",
      "    pppMjaaabcnb",
      "     pp pepeepгЄ",
      "    ppp p p оpЄ ",
      "                ",
      "                ",
      "                ",
      "                ",
      "                "
    ],
    [
      "            ajbi",
      "       f    bcam",
      "       f    maja",
      "      Вfβ    ΄am",
      "       fc      i",
      "       fh       ",
      "       fb       ",
      "       fh       ",
      "       fagbgbgbg",
      "        eeeeeeee",
      "                ",
      "                ",
      "                ",
      "                ",
      "                ",
      "                "
    ],
    [
      "             jjc",
      "       f    z Θa",
      "       fc      D",
      "       fh      a",
      "       fn       ",
      "       fh       ",
      "       fc       ",
      "       fh       ",
      "       fagcgcgjg",
      "        eeeeeeee",
      "                ",
      "                ",
      "                ",
      "                ",
      "                ",
      "                "
    ],
    [
      "             K  ",
      "       f        ",
      "       fa       ",
      "       fb       ",
      "       fb       ",
      "       fc       ",
      "       fc       ",
      "       fn       ",
      "       fbbnaaibb",
      "        eeeeeeee",
      "                ",
      "                ",
      "                ",
      "                ",
      "                ",
      "                "
    ],
    [
      "        a       ",
      "       f        ",
      "       fa       ",
      "       fh       ",
      "       fj       ",
      "       fh       ",
      "       fb       ",
      "       fh       ",
      "       figbgigng",
      "        eeeeeeee",
      "                ",
      "                ",
      "                ",
      "                ",
      "                ",
      "                "
    ]
  ]
}