{
  "xsize": 16,
  "zsize": 16,
  "palette": {
    "palette": [
      {
        "char": " ",
        "block": "minecraft:air"
      },
      {
        "char": "j",
        "block": "minecraft:stone"
      },
      {
        "char": "L",
        "block": "minecraft:andesite"
      },
      {
        "char": "i",
        "block": "minecraft:cobblestone"
      },
      {
        "char": "c",
        "block": "minecraft:cracked_stone_bricks"
      },
      {
        "char": "w",
        "block": "minecraft:dirt"
      },
      {
        "char": "o",
        "block": "minecraft:grass_block[snowy=false]"
      },
      {
        "char": "s",
        "block": "minecraft:cobbled_deepslate"
      },
      {
        "char": "q",
        "block": "minecraft:blackstone"
      },
      {
        "char": "u",
        "block": "minecraft:cyan_terracotta"
      },
      {
        "char": "r",
        "block": "minecraft:basalt[axis=x]"
      },
      {
        "char": "b",
        "block": "minecraft:mossy_stone_bricks"
      },
      {
        "char": "a",
        "block": "minecraft:mossy_cobblestone"
      },
      {
        "char": "t",
        "block": "minecraft:deepslate[axis=y]"
      },
      {
        "char": "m",
        "block": "minecraft:stone_bricks"
      },
      {
        "char": "n",
        "block": "minecraft:air"
      },
      {
        "char": "ͽ",
        "block": "minecraft:crafting_table"
      },
      {
        "char": "D",
        "block": "minecraft:gravel"
      },
      {
        "char": "M",
        "block": "minecraft:acacia_leaves"
      },
      {
        "char": "p",
        "block": "minecraft:air"
      },
      {
        "char": "K",
        "block": "minecraft:cobblestone_slab[type=bottom]"
      },
      {
        "char": "΄",
        "block": "minecraft:mossy_cobblestone_slab[type=bottom]"
      },
      {
        "char": "Д",
        "block": "minecraft:mossy_stone_brick_slab[type=bottom]"
      },
      {
        "char": "d",
        "block": "minecraft:vine[east=false,north=false,south=false,up=false,west=true]"
      },
      {
        "char": "Ю",
        "block": "minecraft:cornflower"
      },
      {
        "char": "e",
        "block": "minecraft:vine[east=false,north=true,south=false,up=false,west=false]"
      },
      {
        "char": "ϣ",
        "block": "minecraft:dandelion"
      },
      {
        "char": "н",
        "block": "minecraft:oxeye_daisy"
      },
      {
        "char": "а",
        "block": "minecraft:air"
      },
      {
        "char": "h",
        "block": "minecraft:glass_pane[east=false,north=true,south=true,west=false]"
      },
      {
        "char": "ϝ",
        "block": "minecraft:glass_pane[east=false,north=true,south=false,west=false]"
      },
      {
        "char": "g",
        "block": "minecraft:glass_pane[east=true,north=false,south=false,west=true]"
      },
      {
        "char": "Ͼ",
        "block": "minecraft:glass_pane[east=false,north=false,south=false,west=true]"
      },
      {
        "char": "z",
        "block": "minecraft:stone_slab[type=bottom]"
      },
      {
        "char": "е",
        "block": "minecraft:glass_pane[east=false,north=false,south=false,west=false]"
      },
      {
        "char": "Κ",
        "block": "minecraft:spruce_slab[type=bottom]"
      }
    ]
  },
  "slices": [
    [
      "jLicijjjwooosqur",
      "bccaacaawooorstt",
      "cciicbmmwooorrur",
      "LccLccbjwooourut",
      "aLLaacbbowootsqs",
      "niLLcjnmwooossts",
      "mmiibabcoooourtr",
      "baaanjcoowoouruq",
      "wwwwiioooooortuu",
      "ooooooooooootsuq",
      "oooooooooooorstt",
      "sttttstqttqsssuu",
      "rutusrqrsrrtuqru",
      "rtquuquruqrstsuq",
      "qqsqrusqtsqutusu",
      "uutuqtsqtqstququ"
    ],
    [
      "bbibͽ DbcMpp    ",
      "caaDK ͽ cMp     ",
      "cjjaD  DcM p    ",
      "iabcD ΄DbMpp    ",
      "cibbm   pД      ",
      " bjm j  KdЮp    ",
      "DD  D    dp     ",
      "     K p ΄p     ",
      "amai     dpp    ",
      "pepppepppppϣ    ",
      "pppнpp аϣ       ",
      "                ",
      "                ",
      "                ",
      "                ",
      "                "
    ],
    [
      "DDc     c       ",
      "bicK    h       ",
      "icDD    nd      ",
      "mjaj    hd      ",
      "jjcj    cd      ",
      "        ϝd      ",
      "         d      ",
      "         d      ",
      "bgiϾ     d      ",
      "eeeeeeeee       ",
      "                ",
      "                ",
      "                ",
      "                ",
      "                ",
      "                "
    ],
    [
      "K       i       ",
      "am      h       ",
      "mi      bd      ",
      "Dz      hd      ",
      "        ad      ",
      "        ϝd      ",
      "         d      ",
      "         d      ",
      "igbϾ   е d      ",
      "ee eeeeee       ",
      "                ",
      "                ",
      "                ",
      "                ",
      "                ",
      "                "
    ],
    [
      "        j       ",
      "        j       ",
      "        ad      ",
      "Κ       id      ",
      "        cd      ",
      "        cd      ",
      "        bd      ",
      "        id      ",
      "cajb jcand      ",
      "ee eeeeee       ",
      "                ",
      "                ",
      "                ",
      "                ",
      "                ",
      "                "
    ],
    [
      "        j       ",
      "        h       ",
      "        bd      ",
      "        hd      ",
      "        jd      ",
      "        hd      ",
      "        id      ",
      "        hd      ",
      "bgcgmgmgad      ",
      "ee  eeeee       ",
      "                ",
      "                ",
      "                ",
      "                ",
      "                ",
      "                "
    ]
  ]
}