{
  "xsize": 16,
  "zsize": 16,
  "palette": {
    "palette": [
      {
        "char": " ",
        "block": "minecraft:air"
      },
      {
        "char": "f",
        "block": "minecraft:vine[east=true,north=false,south=false,up=false,west=false]"
      },
      {
        "char": "k",
        "block": "minecraft:vine[east=false,north=false,south=true,up=false,west=false]"
      },
      {
        "char": "a",
        "block": "minecraft:mossy_cobblestone"
      },
      {
        "char": "g",
        "block": "minecraft:glass_pane[east=true,north=false,south=false,west=true]"
      },
      {
        "char": "m",
        "block": "minecraft:stone_bricks"
      },
      {
        "char": "c",
        "block": "minecraft:cracked_stone_bricks"
      },
      {
        "char": "d",
        "block": "minecraft:vine[east=false,north=false,south=false,up=false,west=true]"
      },
      {
        "char": "h",
        "block": "minecraft:glass_pane[east=false,north=true,south=true,west=false]"
      },
      {
        "char": "i",
        "block": "minecraft:cobblestone"
      },
      {
        "char": "n",
        "block": "minecraft:air"
      },
      {
        "char": "b",
        "block": "minecraft:mossy_stone_bricks"
      },
      {
        "char": "j",
        "block": "minecraft:stone"
      },
      {
        "char": "y",
        "block": "minecraft:stone_slab[type=top]"
      },
      {
        "char": "ϰ",
        "block": "minecraft:spruce_trapdoor[facing=north,half=top,open=true]"
      },
      {
        "char": "ϟ",
        "block": "minecraft:spruce_trapdoor[facing=west,half=top,open=true]"
      },
      {
        "char": "ϡ",
        "block": "minecraft:sand"
      },
      {
        "char": "ϱ",
        "block": "minecraft:spruce_trapdoor[facing=south,half=top,open=true]"
      },
      {
        "char": "с",
        "block": "minecraft:spruce_trapdoor[facing=north,half=top,open=false]"
      },
      {
        "char": "Ϟ",
        "block": "minecraft:spruce_trapdoor[facing=west,half=top,open=false]"
      },
      {
        "char": "Ϭ",
        "block": "minecraft:kelp"
      },
      {
        "char": "Ъ",
        "block": "minecraft:spruce_trapdoor[facing=south,half=top,open=false]"
      },
      {
        "char": "ϥ",
        "block": "minecraft:spruce_trapdoor[facing=west,half=bottom,open=false]"
      }
    ]
  },
  "slices": [
    [
      "                ",
      "                ",
      "                ",
      "                ",
      "                ",
      "                ",
      "fkkk            ",
      "k     kkk       ",
      "agmgmgagcd      ",
      "        hd      ",
      "        id      ",
      "        hd      ",
      "        ndd     ",
      "        hdd     ",
      "        m       ",
      "        h       "
    ],
    [
      "                ",
      "                ",
      "                ",
      "                ",
      "                ",
      "                ",
      "fkkk            ",
      "k      kk       ",
      "aibiccbcbd      ",
      "abcijabcbd      ",
      "bjabbaacbd      ",
      " j bccbnad      ",
      "  maccbccdd     ",
      " ybjcaajbdd     ",
      "     bnai       ",
      "   ibijnj       "
    ],
    [
      "                ",
      "                ",
      "                ",
      "                ",
      "                ",
      "                ",
      "fkkk            ",
      "k       k       ",
      "bgmgigigjd      ",
      "       ϰhd      ",
      "      ϟϡid      ",
      "      ϟϡad      ",
      "      ϟϡbdd     ",
      "       ϱhdd     ",
      "        b       ",
      "        h       "
    ],
    [
      "                ",
      "                ",
      "                ",
      "                ",
      "                ",
      "                ",
      "fkkk            ",
      "k       k       ",
      "bgagjgjgad      ",
      "       сhd      ",
      "      ϞϬad      ",
      "      ϞϬjd      ",
      "      ϞϬbdd     ",
      "       Ъhdd     ",
      "        m       ",
      "        h       "
    ],
    [
      "                ",
      "                ",
      "                ",
      "                ",
      "                ",
      "                ",
      "fkkk            ",
      "k       k       ",
      "cmiiaiaijd      ",
      "        ad      ",
      "       ϥad      ",
      "       ϥ d      ",
      "       ϥadd     ",
      "        mdd     ",
      "        b       ",
      "        b       "
    ],
    [
      "                ",
      "                ",
      "                ",
      "                ",
      "                ",
      "                ",
      "fkkk            ",
      "k       k       ",
      "igbgmgmgcd      ",
      "        hd      ",
      "        bd      ",
      "        hd      ",
      "        cdd     ",
      "        hdd     ",
      "        b       ",
      "        h       "
    ]
  ]
}