{
  "xsize": 16,
  "zsize": 16,
  "palette": {
    "palette": [
      {
        "char": " ",
        "block": "minecraft:air"
      },
      {
        "char": "k",
        "block": "minecraft:vine[east=false,north=false,south=true,up=false,west=false]"
      },
      {
        "char": "f",
        "block": "minecraft:vine[east=true,north=false,south=false,up=false,west=false]"
      },
      {
        "char": "b",
        "block": "minecraft:mossy_stone_bricks"
      },
      {
        "char": "g",
        "block": "minecraft:glass_pane[east=true,north=false,south=false,west=true]"
      },
      {
        "char": "a",
        "block": "minecraft:mossy_cobblestone"
      },
      {
        "char": "h",
        "block": "minecraft:glass_pane[east=false,north=true,south=true,west=false]"
      },
      {
        "char": "j",
        "block": "minecraft:stone"
      },
      {
        "char": "m",
        "block": "minecraft:stone_bricks"
      },
      {
        "char": "c",
        "block": "minecraft:cracked_stone_bricks"
      },
      {
        "char": "n",
        "block": "minecraft:air"
      },
      {
        "char": "i",
        "block": "minecraft:cobblestone"
      },
      {
        "char": "Γ",
        "block": "minecraft:air"
      },
      {
        "char": "Δ",
        "block": "minecraft:glass_pane[east=true,north=false,south=true,west=true]"
      },
      {
        "char": "Я",
        "block": "minecraft:spruce_stairs[facing=east,half=bottom,shape=outer_left]"
      },
      {
        "char": "Ϡ",
        "block": "minecraft:spruce_stairs[facing=north,half=bottom,shape=inner_right]"
      },
      {
        "char": "Ј",
        "block": "minecraft:spruce_stairs[facing=east,half=bottom,shape=straight]"
      },
      {
        "char": "Ϛ",
        "block": "minecraft:spruce_stairs[facing=north,half=top,shape=straight]"
      },
      {
        "char": "в",
        "block": "minecraft:spruce_stairs[facing=north,half=bottom,shape=outer_right]"
      },
      {
        "char": "Χ",
        "block": "minecraft:oak_stairs[facing=west,half=bottom,shape=straight]"
      },
      {
        "char": "C",
        "block": "minecraft:spruce_slab[type=top]"
      },
      {
        "char": "ϙ",
        "block": "minecraft:spruce_stairs[facing=south,half=top,shape=straight]"
      },
      {
        "char": "Ϳ",
        "block": "minecraft:birch_slab[type=top]"
      },
      {
        "char": "Ψ",
        "block": "minecraft:heavy_weighted_pressure_plate[power=0]"
      },
      {
        "char": "ϳ",
        "block": "minecraft:potted_wither_rose"
      }
    ]
  },
  "slices": [
    [
      "                ",
      "                ",
      "                ",
      "                ",
      "                ",
      "                ",
      "              k ",
      "          kkkkk ",
      "       fbgagbgag",
      "       fh       ",
      "       fa       ",
      "        h       ",
      "        j       ",
      "        h       ",
      "        a       ",
      "        h       "
    ],
    [
      "                ",
      "                ",
      "                ",
      "                ",
      "                ",
      "                ",
      "              k ",
      "          kkkkk ",
      "       faaamccaa",
      "       fnjibmaii",
      "       fcnabbbci",
      "        ncbabiic",
      "        ajmjbijm",
      "        bccjcc j",
      "        iccicaΓ ",
      "        majaic  "
    ],
    [
      "                ",
      "                ",
      "                ",
      "                ",
      "                ",
      "                ",
      "              k ",
      "          kkkkk ",
      "       fagbgbgaΔ",
      "       fh     ЯϠ",
      "       fc      Ј",
      "        h  Ϛ   в",
      "        b ΧC    ",
      "        h  ϙ    ",
      "        m       ",
      "        h   Ϳ   "
    ],
    [
      "                ",
      "                ",
      "                ",
      "                ",
      "                ",
      "                ",
      "              k ",
      "          kkkkk ",
      "       fagmgcgag",
      "       fh       ",
      "       fa       ",
      "        h       ",
      "        i  Ψ    ",
      "        h       ",
      "        i       ",
      "        h   ϳ   "
    ],
    [
      "                ",
      "                ",
      "                ",
      "                ",
      "                ",
      "                ",
      "              k ",
      "          kkkkk ",
      "       fbmjccnjj",
      "       fm       ",
      "       fc       ",
      "        i       ",
      "        c       ",
      "        i       ",
      "        i       ",
      "        c       "
    ],
    [
      "                ",
      "                ",
      "                ",
      "                ",
      "                ",
      "                ",
      "              k ",
      "          kkkkk ",
      "       fjgigngcg",
      "       fh       ",
      "       fa       ",
      "        h       ",
      "        b       ",
      "        h       ",
      "        c       ",
      "        h       "
    ]
  ]
}