{
  "xsize": 16,
  "zsize": 16,
  "palette": {
    "palette": [
      {
        "char": " ",
        "block": "minecraft:air"
      },
      {
        "char": "f",
        "block": "minecraft:vine[east=true,north=false,south=false,up=false,west=false]"
      },
      {
        "char": "k",
        "block": "minecraft:vine[east=false,north=false,south=true,up=false,west=false]"
      },
      {
        "char": "a",
        "block": "minecraft:mossy_cobblestone"
      },
      {
        "char": "g",
        "block": "minecraft:glass_pane[east=true,north=false,south=false,west=true]"
      },
      {
        "char": "j",
        "block": "minecraft:stone"
      },
      {
        "char": "c",
        "block": "minecraft:cracked_stone_bricks"
      },
      {
        "char": "b",
        "block": "minecraft:mossy_stone_bricks"
      },
      {
        "char": "d",
        "block": "minecraft:vine[east=false,north=false,south=false,up=false,west=true]"
      },
      {
        "char": "h",
        "block": "minecraft:glass_pane[east=false,north=true,south=true,west=false]"
      },
      {
        "char": "i",
        "block": "minecraft:cobblestone"
      },
      {
        "char": "n",
        "block": "minecraft:air"
      },
      {
        "char": "m",
        "block": "minecraft:stone_bricks"
      },
      {
        "char": "z",
        "block": "minecraft:stone_slab[type=bottom]"
      },
      {
        "char": "y",
        "block": "minecraft:stone_slab[type=top]"
      },
      {
        "char": "v",
        "block": "minecraft:light_gray_concrete"
      },
      {
        "char": "Ϳ",
        "block": "minecraft:birch_slab[type=top]"
      },
      {
        "char": "Ω",
        "block": "minecraft:oak_stairs[facing=north,half=bottom,shape=straight]"
      },
      {
        "char": ";",
        "block": "minecraft:spruce_stairs[facing=west,half=top,shape=straight]"
      },
      {
        "char": "C",
        "block": "minecraft:spruce_slab[type=top]"
      },
      {
        "char": "ͼ",
        "block": "minecraft:spruce_stairs[facing=east,half=top,shape=straight]"
      },
      {
        "char": "Ϡ",
        "block": "minecraft:spruce_stairs[facing=north,half=bottom,shape=inner_right]"
      },
      {
        "char": "Р",
        "block": "minecraft:spruce_stairs[facing=west,half=bottom,shape=inner_left]"
      },
      {
        "char": "ϛ",
        "block": "minecraft:spruce_stairs[facing=south,half=bottom,shape=straight]"
      },
      {
        "char": "з",
        "block": "minecraft:spruce_stairs[facing=east,half=bottom,shape=inner_right]"
      },
      {
        "char": "μ",
        "block": "minecraft:glass_pane[east=false,north=true,south=true,west=true]"
      },
      {
        "char": "ϫ",
        "block": "minecraft:flower_pot"
      },
      {
        "char": "Ψ",
        "block": "minecraft:heavy_weighted_pressure_plate[power=0]"
      },
      {
        "char": "l",
        "block": "minecraft:oak_leaves"
      }
    ]
  },
  "slices": [
    [
      "                ",
      "                ",
      "                ",
      "                ",
      "                ",
      "                ",
      "fkkk            ",
      "                ",
      "agagjgcgbd      ",
      "        hd      ",
      "        bd      ",
      "        hd      ",
      "        add     ",
      "        hdd     ",
      "        c       ",
      "        h       "
    ],
    [
      "                ",
      "                ",
      "                ",
      "                ",
      "                ",
      "                ",
      "fkkk            ",
      "                ",
      "ccjbbinaad      ",
      "baajajmabd      ",
      "aabbbaniid      ",
      "bbanabicad      ",
      "cacnainbbdd     ",
      "  zccaambdd     ",
      "   yccbca       ",
      "    cijmb       "
    ],
    [
      "                ",
      "                ",
      "                ",
      "                ",
      "                ",
      "                ",
      "fkkk            ",
      "                ",
      "agjgcgbgjd      ",
      "vͿ      hd      ",
      "v   Ω   bd      ",
      "vͿ ;Cͼ  hd      ",
      "vͿ      jdd     ",
      "        hdd     ",
      "       Ϡi       ",
      "    Рϛϛзμ       "
    ],
    [
      "                ",
      "                ",
      "                ",
      "                ",
      "                ",
      "                ",
      "fkkk            ",
      "                ",
      "igjgjgmgbd      ",
      "v       hd      ",
      "v       bd      ",
      "v  ϫΨ   hd      ",
      "v       idd     ",
      "        hdd     ",
      "        c       ",
      "        h       "
    ],
    [
      "                ",
      "                ",
      "                ",
      "                ",
      "                ",
      "                ",
      "fkkk            ",
      "                ",
      "mjjmmaccbd      ",
      "        ad      ",
      "        cd      ",
      "        ad      ",
      "        bdd     ",
      "        idd     ",
      "        a       ",
      "        j       "
    ],
    [
      "                ",
      "                ",
      "                ",
      "                ",
      "                ",
      "                ",
      "fkkk            ",
      "                ",
      "mgjgmgigbd      ",
      "        hd      ",
      "        ad      ",
      "        hd      ",
      "        cdd     ",
      "        hdd     ",
      "        m       ",
      "   l    h       "
    ]
  ]
}