{
  "xsize": 16,
  "zsize": 16,
  "palette": {
    "palette": [
      {
        "char": " ",
        "block": "minecraft:air"
      },
      {
        "char": "f",
        "block": "minecraft:vine[east=true,north=false,south=false,up=false,west=false]"
      },
      {
        "char": "k",
        "block": "minecraft:vine[east=false,north=false,south=true,up=false,west=false]"
      },
      {
        "char": "a",
        "block": "minecraft:mossy_cobblestone"
      },
      {
        "char": "g",
        "block": "minecraft:glass_pane[east=true,north=false,south=false,west=true]"
      },
      {
        "char": "i",
        "block": "minecraft:cobblestone"
      },
      {
        "char": "b",
        "block": "minecraft:mossy_stone_bricks"
      },
      {
        "char": "d",
        "block": "minecraft:vine[east=false,north=false,south=false,up=false,west=true]"
      },
      {
        "char": "h",
        "block": "minecraft:glass_pane[east=false,north=true,south=true,west=false]"
      },
      {
        "char": "m",
        "block": "minecraft:stone_bricks"
      },
      {
        "char": "c",
        "block": "minecraft:cracked_stone_bricks"
      },
      {
        "char": "l",
        "block": "minecraft:oak_leaves"
      },
      {
        "char": "j",
        "block": "minecraft:stone"
      },
      {
        "char": "n",
        "block": "minecraft:air"
      },
      {
        "char": "y",
        "block": "minecraft:stone_slab[type=top]"
      },
      {
        "char": "Δ",
        "block": "minecraft:glass_pane[east=true,north=false,south=true,west=true]"
      },
      {
        "char": "J",
        "block": "minecraft:green_wool"
      },
      {
        "char": "μ",
        "block": "minecraft:glass_pane[east=false,north=true,south=true,west=true]"
      },
      {
        "char": "ϊ",
        "block": "minecraft:spruce_trapdoor[facing=north,half=bottom,open=true]"
      }
    ]
  },
  "slices": [
    [
      "                ",
      "                ",
      "                ",
      "                ",
      "                ",
      "                ",
      "fkkk            ",
      "                ",
      "agigbgigid      ",
      "        hd      ",
      "        md      ",
      "        hd      ",
      "        cdd     ",
      "        hdd     ",
      "   l l  b       ",
      "  lllll h       "
    ],
    [
      "                ",
      "                ",
      "                ",
      "                ",
      "                ",
      "                ",
      "fkkk            ",
      "                ",
      "aiciajacad      ",
      "mbajcbacad      ",
      "mbnabcibad      ",
      "acacjicccd      ",
      "ccjcaajiadd     ",
      "yy cajciadd     ",
      "   ycaacn       ",
      " llliiaac       "
    ],
    [
      "                ",
      "                ",
      "                ",
      "                ",
      "                ",
      "                ",
      "fkkk            ",
      "                ",
      "bgcΔiΔiΔcd      ",
      "  JJJJJJμd      ",
      "  J    Jcd      ",
      "       Jμd      ",
      "       Jidd     ",
      "      JJμdd     ",
      "   l    j       ",
      "  llϊϊϊ h       "
    ],
    [
      "                ",
      "                ",
      "                ",
      "                ",
      "                ",
      "                ",
      "fkkk            ",
      "                ",
      "agmgmgbgmd      ",
      "        hd      ",
      "        bd      ",
      "        hd      ",
      "        add     ",
      "        hdd     ",
      "  ll    b       ",
      " lll    h       "
    ],
    [
      "                ",
      "                ",
      "                ",
      "                ",
      "                ",
      "                ",
      "fkkk            ",
      "                ",
      "ncbijmimnd      ",
      "        ad      ",
      "        bd      ",
      "        nd      ",
      "        jdd     ",
      "        add     ",
      " ll     n       ",
      " ll     b       "
    ],
    [
      "                ",
      "                ",
      "                ",
      "                ",
      "                ",
      "                ",
      "fkkk            ",
      "                ",
      "agcgagcgbd      ",
      "        hd      ",
      "        bd      ",
      "        hd      ",
      "        bdd     ",
      "        hdd     ",
      "  l     c       ",
      " lll    h       "
    ]
  ]
}