{
  "xsize": 16,
  "zsize": 16,
  "palette": {
    "palette": [
      {
        "char": " ",
        "block": "minecraft:air"
      },
      {
        "char": "j",
        "block": "minecraft:polished_andesite_slab[type=top]"
      },
      {
        "char": "a",
        "block": "minecraft:cyan_terracotta"
      },
      {
        "char": "b",
        "block": "minecraft:blackstone"
      },
      {
        "char": "d",
        "block": "minecraft:cobbled_deepslate"
      },
      {
        "char": "e",
        "block": "minecraft:basalt[axis=y]"
      },
      {
        "char": "g",
        "block": "minecraft:gray_concrete"
      },
      {
        "char": "c",
        "block": "minecraft:deepslate[axis=y]"
      },
      {
        "char": "o",
        "block": "minecraft:chiseled_quartz_block"
      },
      {
        "char": "Ѧ",
        "block": "minecraft:quartz_bricks"
      },
      {
        "char": "C",
        "block": "minecraft:quartz_pillar[axis=y]"
      },
      {
        "char": "n",
        "block": "minecraft:smooth_quartz"
      },
      {
        "char": "i",
        "block": "minecraft:light_gray_concrete"
      },
      {
        "char": "A",
        "block": "minecraft:red_concrete"
      },
      {
        "char": "F",
        "block": "minecraft:light_blue_terracotta"
      },
      {
        "char": "ӟ",
        "block": "minecraft:iron_bars[east=true,north=false,south=true,west=true]"
      },
      {
        "char": "Ѵ",
        "block": "minecraft:white_stained_glass_pane[east=false,north=false,south=false,west=true]"
      },
      {
        "char": "Ѳ",
        "block": "minecraft:white_stained_glass_pane[east=true,north=false,south=false,west=false]"
      },
      {
        "char": "x",
        "block": "minecraft:cauldron"
      },
      {
        "char": "Ѯ",
        "block": "minecraft:diorite_slab[type=bottom]"
      },
      {
        "char": "P",
        "block": "minecraft:smooth_quartz_slab[type=bottom]"
      },
      {
        "char": "看",
        "block": "minecraft:birch_trapdoor[facing=north,half=bottom,open=true]"
      },
      {
        "char": "会",
        "block": "minecraft:birch_stairs[facing=east,half=bottom,shape=straight]"
      },
      {
        "char": "好",
        "block": "minecraft:birch_stairs[facing=west,half=bottom,shape=straight]"
      },
      {
        "char": "问",
        "block": "minecraft:birch_trapdoor[facing=south,half=bottom,open=true]"
      },
      {
        "char": "ϓ",
        "block": "minecraft:air"
      },
      {
        "char": "r",
        "block": "minecraft:polished_diorite"
      },
      {
        "char": "ҝ",
        "block": "minecraft:stone_brick_slab[type=top]"
      },
      {
        "char": "k",
        "block": "minecraft:oak_leaves"
      },
      {
        "char": "K",
        "block": "minecraft:quartz_block"
      },
      {
        "char": "J",
        "block": "minecraft:diorite"
      },
      {
        "char": "ѩ",
        "block": "minecraft:diorite_slab[type=top]"
      },
      {
        "char": "M",
        "block": "minecraft:smooth_quartz_slab[type=top]"
      },
      {
        "char": "Т",
        "block": "minecraft:polished_andesite_stairs[facing=north,half=top,shape=straight]"
      },
      {
        "char": "h",
        "block": "minecraft:andesite_slab[type=top]"
      },
      {
        "char": "T",
        "block": "minecraft:redstone_lamp[lit=false]"
      }
    ]
  },
  "slices": [
    [
      "                ",
      "                ",
      "                ",
      "                ",
      "                ",
      "jjjjjj  aa   a  ",
      "bbdbdbeaagadcabe",
      "ebcdbcado       ",
      "caebdeebѦ       ",
      "bbcccbdbC       ",
      "eceebdabѦ       ",
      "daaeacaan       ",
      "bdbeccebѦ       ",
      "dbdaedbega      ",
      "ddacecceai      ",
      "abcebdccѦ     A "
    ],
    [
      "                ",
      "                ",
      "                ",
      "                ",
      "                ",
      "FӟFFFF  ia   a  ",
      "bcdacadbaiѴ Ѳa  ",
      "  x  x  Ѯ       ",
      "        P       ",
      "看看 看看   P       ",
      "会好 会好   P       ",
      "会好 会好   P       ",
      "会好 会好   P       ",
      "问问 问问   aa      ",
      "  ϓ     ag      ",
      "看看 看看   Ѯ       "
    ],
    [
      "                ",
      "                ",
      "                ",
      "                ",
      "                ",
      "rFFӟoF  gg   a  ",
      "dddbbaedaaҝҝҝgҝҝ",
      "  k  k          ",
      "                ",
      "                ",
      "                ",
      "                ",
      "                ",
      "        aa      ",
      "        aa      ",
      "                "
    ],
    [
      "                ",
      "                ",
      "                ",
      "                ",
      "                ",
      "FFoFӟFPPaaPPPPPP",
      "adecbabeagcdbbce",
      "  k  k          ",
      "                ",
      "                ",
      "                ",
      "                ",
      "                ",
      "        aa      ",
      "        ia      ",
      "                "
    ],
    [
      "                ",
      "                ",
      "                ",
      "                ",
      "                ",
      "rKFJoFѩMaaMMMMMѩ",
      "ebdbbdeeaabdaeee",
      "                ",
      "                ",
      "                ",
      "                ",
      "                ",
      "                ",
      "        gg      ",
      "        aa      ",
      "                "
    ],
    [
      "                ",
      "                ",
      "                ",
      "                ",
      "                ",
      "FFӟFFF  ai      ",
      "bdaeaccecdedecca",
      "ТТТТТТТТТТТТТТТТ",
      "hhhhhhhhhhhhhhhh",
      "hhhhhhhhhhhhhhhh",
      "hhhhhhhhhhhhhhhh",
      "hhhhhhhhhhhhhhhh",
      "hhhhhhhhhhhhhhhh",
      "hhhhhhhhaahhhhhh",
      "hhhhhhhhaihhhhhh",
      "hhhhhhhhhhhhhThh"
    ]
  ]
}