{
  "xsize": 16,
  "zsize": 16,
  "palette": {
    "palette": [
      {
        "char": " ",
        "block": "minecraft:air"
      },
      {
        "char": "b",
        "block": "minecraft:blackstone"
      },
      {
        "char": "c",
        "block": "minecraft:deepslate[axis=y]"
      },
      {
        "char": "d",
        "block": "minecraft:cobbled_deepslate"
      },
      {
        "char": "e",
        "block": "minecraft:basalt[axis=y]"
      },
      {
        "char": "a",
        "block": "minecraft:cyan_terracotta"
      },
      {
        "char": "g",
        "block": "minecraft:gray_concrete"
      },
      {
        "char": "Ѱ",
        "block": "minecraft:cobblestone_slab[type=bottom]"
      },
      {
        "char": "E",
        "block": "minecraft:red_terracotta"
      },
      {
        "char": "A",
        "block": "minecraft:red_concrete"
      },
      {
        "char": "ϒ",
        "block": "minecraft:polished_andesite_stairs[facing=east,half=top,shape=straight]"
      },
      {
        "char": "位",
        "block": "minecraft:iron_bars[east=true,north=true,south=false,west=false]"
      },
      {
        "char": "ѭ",
        "block": "minecraft:polished_andesite_stairs[facing=west,half=top,shape=straight]"
      },
      {
        "char": "交",
        "block": "minecraft:polished_andesite_stairs[facing=west,half=bottom,shape=straight]"
      },
      {
        "char": "何",
        "block": "minecraft:polished_andesite_stairs[facing=south,half=top,shape=inner_right]"
      },
      {
        "char": "体",
        "block": "minecraft:polished_andesite_stairs[facing=south,half=top,shape=outer_right]"
      },
      {
        "char": "也",
        "block": "minecraft:stone_brick_wall[east=tall,up=true]"
      },
      {
        "char": "相",
        "block": "minecraft:polished_andesite_stairs[facing=west,half=top,shape=outer_left]"
      },
      {
        "char": "i",
        "block": "minecraft:light_gray_concrete"
      },
      {
        "char": "X",
        "block": "minecraft:red_wool"
      },
      {
        "char": "W",
        "block": "minecraft:polished_andesite_stairs[facing=south,half=top,shape=straight]"
      },
      {
        "char": "山",
        "block": "minecraft:air"
      },
      {
        "char": "全",
        "block": "minecraft:air"
      },
      {
        "char": "再",
        "block": "minecraft:stone_brick_wall[east=low,south=low,up=true]"
      },
      {
        "char": "张",
        "block": "minecraft:stone_brick_wall[east=low,south=low,up=true,west=low]"
      },
      {
        "char": "动",
        "block": "minecraft:air"
      },
      {
        "char": "水",
        "block": "minecraft:air"
      },
      {
        "char": "哈",
        "block": "minecraft:air"
      },
      {
        "char": "然",
        "block": "minecraft:air"
      },
      {
        "char": "每",
        "block": "minecraft:stone_brick_wall[east=low,north=tall,up=true]"
      },
      {
        "char": "理",
        "block": "minecraft:air"
      },
      {
        "char": "á",
        "block": "minecraft:cobblestone_wall[up=true]"
      },
      {
        "char": "就",
        "block": "minecraft:stone_brick_wall[north=low,up=true]"
      }
    ]
  },
  "slices": [
    [
      " bcdeddaecbcdbda",
      "abd             ",
      " ce             ",
      "  db            ",
      "  dd            ",
      "   ec           ",
      "   ab           ",
      "  g ba          ",
      "    ca          ",
      "     ae         ",
      "     Ѱae        ",
      "                ",
      "                ",
      "                ",
      "                ",
      "                "
    ],
    [
      " Ecaddcdeacebbbb",
      " Ab            ϒ",
      " Aa            ϒ",
      "  Ad            ",
      "  位d            ",
      "   Ec           ",
      "   Ea           ",
      "  g Ec          ",
      "    Aa          ",
      "     Eb         ",
      "      Ae        ",
      "                ",
      "                ",
      "                ",
      "                ",
      "                "
    ],
    [
      " Abcecddaedeccec",
      " Adѭ          ϒ交",
      " Ed何体         ϒ交",
      "  Ebѭ          也",
      "  Eb何体          ",
      "   Aeѭ          ",
      "   Ea何相         ",
      "  i Eaѭ         ",
      "    Xe何相        ",
      "     Ae何W       ",
      "      Ed        ",
      "                ",
      "                ",
      "                ",
      "                ",
      "                "
    ],
    [
      " 山cddeeecabdcbdb",
      " Adcdbeccbbedc交 ",
      " 全ddebacebceac交 ",
      "  Xddbccbeedaeed",
      "  Eeeadabcddcbdc",
      "   Aeebdeccaecbe",
      "   Xdcbceacedceb",
      "  a Eeceebcebcac",
      "    Aeddece   cb",
      "     Aeea       ",
      "      Ae        ",
      "       E        ",
      "                ",
      "                ",
      "                ",
      "                "
    ],
    [
      " Accaaeeaeecadeb",
      " Eb             ",
      " Ea             ",
      "  Xe          再张",
      "  Ae        动 ad",
      "   Ab       水哈be",
      "   Ac        然每c",
      "  a Xe          ",
      "    Ae          ",
      "     Eb         ",
      "      Ade       ",
      "       理        ",
      "                ",
      "                ",
      "                ",
      "                "
    ],
    [
      " Aadaacaaeabdcee",
      " Eb             ",
      " Ea             ",
      "  Aa          á ",
      "  Eb           a",
      "   Ae         be",
      "   Xb         就 ",
      "  a Ae          ",
      "    Eb          ",
      "     Ab         ",
      "      Aaa       ",
      "       EA       ",
      "                ",
      "                ",
      "                ",
      "                "
    ]
  ]
}