{
  "xsize": 16,
  "zsize": 16,
  "palette": {
    "palette": [
      {
        "char": " ",
        "block": "minecraft:air"
      },
      {
        "char": "d",
        "block": "minecraft:cobbled_deepslate"
      },
      {
        "char": "e",
        "block": "minecraft:basalt[axis=y]"
      },
      {
        "char": "c",
        "block": "minecraft:deepslate[axis=y]"
      },
      {
        "char": "a",
        "block": "minecraft:cyan_terracotta"
      },
      {
        "char": "b",
        "block": "minecraft:blackstone"
      },
      {
        "char": "x",
        "block": "minecraft:cauldron"
      },
      {
        "char": "j",
        "block": "minecraft:polished_andesite_slab[type=top]"
      },
      {
        "char": "Ӛ",
        "block": "minecraft:dark_oak_door[facing=south,half=lower,hinge=left,open=false]"
      },
      {
        "char": "П",
        "block": "minecraft:barrel[facing=up,open=false]",
        "tag": {
          "z": -275,
          "x": -15,
          "ForgeData": {
            "LockFlag": "1b"
          },
          "id": "minecraft:barrel",
          "y": 2,
          "Items": []
        }
      },
      {
        "char": "H",
        "block": "minecraft:quartz_stairs[facing=south,half=bottom,shape=straight]"
      },
      {
        "char": "f",
        "block": "minecraft:glass"
      },
      {
        "char": "k",
        "block": "minecraft:oak_leaves"
      },
      {
        "char": "ҟ",
        "block": "minecraft:spruce_trapdoor[facing=south,half=bottom,open=false]"
      },
      {
        "char": "ӗ",
        "block": "minecraft:tripwire_hook[attached=false,facing=north,powered=false]"
      },
      {
        "char": "ә",
        "block": "minecraft:dark_oak_door[facing=south,half=upper,hinge=left,open=false]"
      },
      {
        "char": "ѷ",
        "block": "minecraft:air"
      },
      {
        "char": "ο",
        "block": "minecraft:air"
      },
      {
        "char": "Ә",
        "block": "minecraft:white_wall_banner",
        "tag": {
          "z": -268,
          "Patterns": [
            {
              "Color": 8,
              "Pattern": "dls"
            },
            {
              "Color": 0,
              "Pattern": "dls"
            },
            {
              "Color": 3,
              "Pattern": "gru"
            },
            {
              "Color": 8,
              "Pattern": "bo"
            }
          ],
          "x": -29,
          "id": "minecraft:banner",
          "y": -14
        }
      },
      {
        "char": "С",
        "block": "minecraft:stone_brick_stairs[facing=north,half=top,shape=straight]"
      },
      {
        "char": "Ҽ",
        "block": "minecraft:birch_wall_sign",
        "tag": {
          "z": -283,
          "x": -20,
          "is_waxed": "0b",
          "id": "minecraft:sign",
          "y": -49,
          "front_text": {
            "color": "black",
            "has_glowing_text": "0b",
            "messages": [
              "{\"text\":\"\"}",
              "{\"text\":\"INFORMATION\"}",
              "{\"text\":\"\"}",
              "{\"text\":\"\"}"
            ]
          },
          "back_text": {
            "color": "black",
            "has_glowing_text": "0b",
            "messages": [
              "{\"text\":\"\"}",
              "{\"text\":\"\"}",
              "{\"text\":\"\"}",
              "{\"text\":\"\"}"
            ]
          }
        }
      },
      {
        "char": "g",
        "block": "minecraft:gray_concrete"
      }
    ]
  },
  "slices": [
    [
      "deecabbeacebdabb",
      "abedbeacccebabdb",
      "cecadaddedcabddc",
      "bdaacbbdecdcaade",
      "adbddeeeebcbceab",
      "bceecedeeaabeaab",
      "cbccaeecaeccadce",
      "bcacebbdcaccebdc",
      "bbbadbdeabedaeca",
      "adaddcdacccbcdbd",
      "cbcbdceedadebcee",
      "bdacbdcdbeeebaae",
      "cbabdeaecdecbcee",
      "baaeceebaccdbaba",
      "eadaacacbcbadbca",
      "adedcdaeeaaadbca"
    ],
    [
      "ceecbbcbx       ",
      " e xjjja        ",
      " e     e     e  ",
      " e     cx    b  ",
      " d x   b     b  ",
      "dabebӚbad   dcaa",
      " a            x ",
      "                ",
      "                ",
      "                ",
      " a ecb Пbd ada d",
      "    H   H   H   ",
      "                ",
      "   aeb edc aec  ",
      " e  H   H   H   ",
      "               f"
    ],
    [
      "dbeedeaek       ",
      " c ҟ   b        ",
      " e     d     d  ",
      " c     ak    a  ",
      " b ӗ   c     d  ",
      "abcecәadc   aebc",
      " e            k ",
      "                ",
      "                ",
      "                ",
      " b  ѷ   ο   ο   ",
      "                ",
      "                ",
      "    ο   ѷ   ѷ   ",
      " c              ",
      "                "
    ],
    [
      "cecdadbck       ",
      " d     c        ",
      " a     a     b  ",
      " d     dk    d  ",
      " b Ә   a     c  ",
      "bdccdСedb   beba",
      " d            k ",
      "                ",
      "                ",
      "                ",
      " e              ",
      "                ",
      "                ",
      "                ",
      " d              ",
      "               f"
    ],
    [
      "bcbcacae     j  ",
      " b     a     j  ",
      " b     c     a  ",
      " a     a     a  ",
      " b     b     d  ",
      "beddadbbajjjcacd",
      " d   Ҽ          ",
      " j              ",
      " j              ",
      " j              ",
      " d              ",
      " j              ",
      " j              ",
      " j              ",
      " e              ",
      " j             f"
    ],
    [
      "cadceebb     e  ",
      " d     c     b  ",
      " e     b     c  ",
      " a     c     e  ",
      " d     e     c  ",
      "ceaecaaacdecdbbc",
      " b              ",
      " c              ",
      " e              ",
      " c              ",
      " a              ",
      " e              ",
      " d              ",
      " c              ",
      " b              ",
      " d             g"
    ]
  ]
}