{
  "xsize": 16,
  "zsize": 16,
  "palette": {
    "palette": [
      {
        "char": " ",
        "block": "minecraft:air"
      },
      {
        "char": "a",
        "block": "minecraft:cyan_terracotta"
      },
      {
        "char": "g",
        "block": "minecraft:gray_concrete"
      },
      {
        "char": "У",
        "block": "minecraft:stone_brick_stairs[facing=south,half=bottom,shape=straight]"
      },
      {
        "char": "e",
        "block": "minecraft:basalt[axis=y]"
      },
      {
        "char": "没",
        "block": "minecraft:air"
      },
      {
        "char": "d",
        "block": "minecraft:cobbled_deepslate"
      },
      {
        "char": "c",
        "block": "minecraft:deepslate[axis=y]"
      },
      {
        "char": "b",
        "block": "minecraft:blackstone"
      },
      {
        "char": "同",
        "block": "minecraft:air"
      },
      {
        "char": "期",
        "block": "minecraft:stone_brick_stairs[facing=west,half=bottom,shape=straight]"
      },
      {
        "char": "他",
        "block": "minecraft:stone_brick_stairs[facing=west,half=bottom,shape=straight]"
      },
      {
        "char": "i",
        "block": "minecraft:light_gray_concrete"
      },
      {
        "char": "给",
        "block": "minecraft:stone_brick_stairs[facing=south,half=top,shape=straight]"
      },
      {
        "char": "乐",
        "block": "minecraft:stone_brick_stairs[facing=east,half=top,shape=inner_right]"
      },
      {
        "char": "ӝ",
        "block": "minecraft:air"
      },
      {
        "char": "ӛ",
        "block": "minecraft:air"
      },
      {
        "char": "Ӣ",
        "block": "minecraft:air"
      },
      {
        "char": "ϓ",
        "block": "minecraft:air"
      },
      {
        "char": "Ѻ",
        "block": "minecraft:air"
      },
      {
        "char": "号",
        "block": "minecraft:stone_brick_stairs[facing=north,half=top,shape=inner_left]"
      },
      {
        "char": "作",
        "block": "minecraft:stone_brick_stairs[facing=west,half=top,shape=straight]"
      },
      {
        "char": "Ѯ",
        "block": "minecraft:diorite_slab[type=bottom]"
      },
      {
        "char": "P",
        "block": "minecraft:smooth_quartz_slab[type=bottom]"
      },
      {
        "char": "M",
        "block": "minecraft:smooth_quartz_slab[type=top]"
      },
      {
        "char": "ѩ",
        "block": "minecraft:diorite_slab[type=top]"
      },
      {
        "char": "Т",
        "block": "minecraft:polished_andesite_stairs[facing=north,half=top,shape=straight]"
      },
      {
        "char": "请",
        "block": "minecraft:polished_andesite_stairs[facing=north,half=top,shape=inner_right]"
      },
      {
        "char": "h",
        "block": "minecraft:andesite_slab[type=top]"
      },
      {
        "char": "真",
        "block": "minecraft:polished_andesite_stairs[facing=east,half=top,shape=outer_left]"
      },
      {
        "char": "ϒ",
        "block": "minecraft:polished_andesite_stairs[facing=east,half=top,shape=straight]"
      }
    ]
  },
  "slices": [
    [
      "                ",
      "                ",
      "                ",
      "                ",
      "                ",
      "      ag        ",
      "УУe没没daaae      ",
      "cddcdabaad      ",
      "ddeeccdbaaa     ",
      "dccabcddcaa     ",
      "eadbdecddd      ",
      "adaeeabea同      ",
      "acaabdbdb期      ",
      "eaeebcadda      ",
      "daeddecda他      ",
      "eeaceecbc他      "
    ],
    [
      "                ",
      "                ",
      "                ",
      "                ",
      "                ",
      "      ai        ",
      "给乐cdaegaca      ",
      "   ӝ   ӝ c      ",
      "ӛ Ӣϓӛ Ӣϓӛia     ",
      "   Ѻ   Ѻ aa     ",
      "         e      ",
      "   ӝ   ӝ c      ",
      "ӛ Ӣϓӛ Ӣϓӛa      ",
      "   Ѻ   Ѻ b      ",
      "         号      ",
      "   ӝ   ӝ 作      "
    ],
    [
      "                ",
      "                ",
      "                ",
      "                ",
      "                ",
      "      aa        ",
      "abedcbaadc      ",
      "         a      ",
      "         aa     ",
      "         ig     ",
      "         a      ",
      "         e      ",
      "         c      ",
      "         a      ",
      "         e      ",
      "         a      "
    ],
    [
      "                ",
      "                ",
      "                ",
      "                ",
      "                ",
      "ѮPѮPPPgiPPP     ",
      "aadbcbaaacP     ",
      "         dP     ",
      "         ag     ",
      "         ag     ",
      "         dP     ",
      "         bѮ     ",
      "         bP     ",
      "         bP     ",
      "         bP     ",
      "         dѮ     "
    ],
    [
      "                ",
      "                ",
      "                ",
      "                ",
      "                ",
      "MѩMMѩMaaMMM     ",
      "cebceagadeM     ",
      "         dM     ",
      "         ia     ",
      "         ga     ",
      "         aM     ",
      "         aM     ",
      "         eѩ     ",
      "         eM     ",
      "         aѩ     ",
      "         cM     "
    ],
    [
      "                ",
      "                ",
      "                ",
      "                ",
      "                ",
      "      ag        ",
      "cabeadbdbe      ",
      "ТТТТТТТ请ee      ",
      "hhhhhhh真请da     ",
      "hhhhhhhhϒca     ",
      "hhhhhhhhϒd      ",
      "hhhhhhhhϒe      ",
      "hhhhhhhhϒd      ",
      "hhhhhhhhϒd      ",
      "hhhhhhhhϒa      ",
      "hhhhhhhhϒe      "
    ]
  ]
}