{
  "xsize": 16,
  "zsize": 16,
  "palette": {
    "palette": [
      {
        "char": " ",
        "block": "minecraft:air"
      },
      {
        "char": "b",
        "block": "minecraft:blackstone"
      },
      {
        "char": "e",
        "block": "minecraft:basalt[axis=y]"
      },
      {
        "char": "d",
        "block": "minecraft:cobbled_deepslate"
      },
      {
        "char": "a",
        "block": "minecraft:cyan_terracotta"
      },
      {
        "char": "c",
        "block": "minecraft:deepslate[axis=y]"
      },
      {
        "char": "i",
        "block": "minecraft:light_gray_concrete"
      },
      {
        "char": "ϕ",
        "block": "minecraft:quartz_stairs[facing=north,half=bottom,shape=straight]"
      },
      {
        "char": "O",
        "block": "minecraft:quartz_stairs[facing=west,half=bottom,shape=straight]"
      },
      {
        "char": "ϓ",
        "block": "minecraft:air"
      },
      {
        "char": "ϔ",
        "block": "minecraft:quartz_stairs[facing=east,half=bottom,shape=straight]"
      },
      {
        "char": "f",
        "block": "minecraft:glass"
      },
      {
        "char": "x",
        "block": "minecraft:cauldron"
      },
      {
        "char": "m",
        "block": "minecraft:iron_trapdoor[facing=west,half=bottom,open=false]"
      },
      {
        "char": "k",
        "block": "minecraft:oak_leaves"
      },
      {
        "char": "u",
        "block": "minecraft:iron_trapdoor[facing=south,half=bottom,open=false]"
      },
      {
        "char": "q",
        "block": "minecraft:iron_trapdoor[facing=west,half=top,open=false]"
      },
      {
        "char": "w",
        "block": "minecraft:iron_trapdoor[facing=south,half=top,open=false]"
      },
      {
        "char": "I",
        "block": "minecraft:stone_slab[type=top]"
      },
      {
        "char": "ϗ",
        "block": "minecraft:stone_brick_wall[up=true]"
      }
    ]
  },
  "slices": [
    [
      "bebddbabedcccbeb",
      "dcbbaebbbeeacbab",
      "aeeeeeeebddaadcd",
      "eecdcbcdbdaeddee",
      "ccbeebabdccbacda",
      "aeeecbcbeaeacdbc",
      "aaidaabacbbccedb",
      "  a bcdabceaabcc",
      "    ccaebaeabaac",
      "     cddebcbacae",
      "      aedbeade  ",
      "       ddceee   ",
      "         cab    ",
      "                ",
      "                ",
      "                "
    ],
    [
      "           caace",
      "                ",
      "  c             ",
      "  c             ",
      "  c   ϕ   bed   ",
      "ecb  Oϓϔ  a     ",
      "   dee    a     ",
      "  a  f    cx    ",
      "          b     ",
      "      f   d     ",
      "         ba     ",
      "         cb     ",
      "         e e    ",
      "                ",
      "                ",
      "                "
    ],
    [
      "           cccee",
      "                ",
      "  c             ",
      "  c             ",
      "  e       ccc   ",
      "eac       b     ",
      "   cad    b     ",
      "  a mf    ck    ",
      "    mf    c     ",
      "     m    b     ",
      "      mffed     ",
      "       uuad     ",
      "         e d    ",
      "                ",
      "                ",
      "                "
    ],
    [
      "           cdecb",
      "                ",
      "  b             ",
      "  c             ",
      "  a       dec   ",
      "bba       b     ",
      "   dac    c     ",
      "  i qf    dk    ",
      "    qf    a     ",
      "     wf   c     ",
      "      qf cc     ",
      "       wwc  a   ",
      "                ",
      "                ",
      "                ",
      "                "
    ],
    [
      "  I        aecad",
      "  I             ",
      "  d             ",
      "  a             ",
      "  e       cadIII",
      "eda       d     ",
      "   eeb    d     ",
      "  a  f    e     ",
      "     f    c     ",
      "      f   e     ",
      "       ffa      ",
      "         c  b   ",
      "                ",
      "                ",
      "                ",
      "                "
    ],
    [
      "  e        debaa",
      "  b             ",
      "  b             ",
      "  d             ",
      "  a       cebdce",
      "abc       a     ",
      "   dea    a     ",
      "  a eb    e     ",
      "    aa    d     ",
      "     ba   b     ",
      "      eaee      ",
      "       ea   ϗ   ",
      "                ",
      "                ",
      "                ",
      "                "
    ]
  ]
}