{
  "xsize": 16,
  "zsize": 16,
  "palette": {
    "palette": [
      {
        "char": " ",
        "block": "minecraft:air"
      },
      {
        "char": "a",
        "block": "minecraft:cyan_terracotta"
      },
      {
        "char": "c",
        "block": "minecraft:deepslate[axis=y]"
      },
      {
        "char": "b",
        "block": "minecraft:blackstone"
      },
      {
        "char": "d",
        "block": "minecraft:cobbled_deepslate"
      },
      {
        "char": "e",
        "block": "minecraft:basalt[axis=y]"
      },
      {
        "char": "Р",
        "block": "minecraft:stone_brick_stairs[facing=north,half=bottom,shape=straight]"
      },
      {
        "char": "z",
        "block": "minecraft:iron_bars[east=false,north=true,south=true,west=false]"
      },
      {
        "char": "Y",
        "block": "minecraft:iron_bars[east=false,north=true,south=false,west=false]"
      },
      {
        "char": "f",
        "block": "minecraft:glass"
      },
      {
        "char": "O",
        "block": "minecraft:quartz_stairs[facing=west,half=bottom,shape=straight]"
      },
      {
        "char": "П",
        "block": "minecraft:barrel[facing=up,open=false]",
        "tag": {
          "z": -275,
          "x": -15,
          "ForgeData": {
            "LockFlag": "1b"
          },
          "id": "minecraft:barrel",
          "y": 2,
          "Items": []
        }
      },
      {
        "char": "x",
        "block": "minecraft:cauldron"
      },
      {
        "char": "У",
        "block": "minecraft:stone_brick_stairs[facing=south,half=bottom,shape=straight]"
      },
      {
        "char": "С",
        "block": "minecraft:stone_brick_stairs[facing=north,half=top,shape=straight]"
      },
      {
        "char": "Ѫ",
        "block": "minecraft:air"
      },
      {
        "char": "N",
        "block": "minecraft:white_stained_glass_pane[east=true,north=false,south=false,west=true]"
      },
      {
        "char": "k",
        "block": "minecraft:oak_leaves"
      },
      {
        "char": "у",
        "block": "minecraft:stone_brick_stairs[facing=south,half=top,shape=straight]"
      },
      {
        "char": "j",
        "block": "minecraft:polished_andesite_slab[type=top]"
      },
      {
        "char": "g",
        "block": "minecraft:gray_concrete"
      }
    ]
  },
  "slices": [
    [
      "acbdcaecadabbeae",
      "bbcbaacdaecbbcad",
      "dbecbabdcceabdee",
      "abbacaeedceddeab",
      "cdebdeecebebecce",
      "eedeccacdbcddabd",
      "caedeeedecdbecea",
      "baebeedbbabeedcb",
      "dbbbcaabcbbceecb",
      "adcabcbbcdedbbec",
      "dbdbbaaaaeeecced",
      "bcaeccdbebaabdcc",
      "cdcbeabaddacРz d",
      "eedaacacaaed z d",
      "cdabaddcdeab Y c",
      "eddceedabdec   a"
    ],
    [
      "f   Od    c     ",
      "     d          ",
      "                ",
      "  e  П    b     ",
      " Oa Oe    edeeab",
      "  c  a     a  x ",
      "           c    ",
      "  c  c          ",
      " Oe Oc          ",
      "  d  d          ",
      "           c    ",
      "  c  П     a e d",
      " Oe Oc     e zУb",
      "  b  a     d zСd",
      "eeaccdb   ba Y e",
      "  e  d     d   d"
    ],
    [
      "     Ѫ    d     ",
      "                ",
      "                ",
      "          a     ",
      "  Ѫ  Ѫ    eacNNN",
      "           e  k ",
      "           a    ",
      "                ",
      "  Ѫ  Ѫ          ",
      "                ",
      "           e    ",
      "           d b c",
      "  Ѫ  Ѫ     d z d",
      "           c zУb",
      "dedbdbd   ba YСd",
      "     d     d   a"
    ],
    [
      "          d     ",
      "                ",
      "                ",
      "          c     ",
      "          ecbNNN",
      "           d  k ",
      "           b    ",
      "                ",
      "                ",
      "                ",
      "           a    ",
      "           c d b",
      "           c z d",
      "           b z b",
      "aedccdd   aaуzУb",
      "     c     eabbc"
    ],
    [
      "f         d     ",
      "          j     ",
      "          j     ",
      "          a     ",
      "          edecce",
      "           b    ",
      "           a    ",
      "           j    ",
      "           j    ",
      "           j    ",
      "           c    ",
      "           cadcb",
      "           e z b",
      "           eуz c",
      "adddadejjjbcРY b",
      "     b     d   e"
    ],
    [
      "g         b     ",
      "          c     ",
      "          a     ",
      "          b     ",
      "          dcaeee",
      "           b    ",
      "           b    ",
      "           b    ",
      "           c    ",
      "           e    ",
      "           d    ",
      "           aaaed",
      "           aуz e",
      "           cРz b",
      "eeaacdcaaddc Y a",
      "     e     a   a"
    ]
  ]
}