{
  "xsize": 16,
  "zsize": 16,
  "palette": {
    "palette": [
      {
        "char": " ",
        "block": "minecraft:air"
      },
      {
        "char": "a",
        "block": "minecraft:cyan_terracotta"
      },
      {
        "char": "c",
        "block": "minecraft:deepslate[axis=y]"
      },
      {
        "char": "e",
        "block": "minecraft:basalt[axis=y]"
      },
      {
        "char": "d",
        "block": "minecraft:cobbled_deepslate"
      },
      {
        "char": "b",
        "block": "minecraft:blackstone"
      },
      {
        "char": "g",
        "block": "minecraft:gray_concrete"
      },
      {
        "char": "小",
        "block": "minecraft:air"
      },
      {
        "char": "选",
        "block": "minecraft:stone_brick_stairs[facing=north,half=top,shape=straight]"
      },
      {
        "char": "С",
        "block": "minecraft:stone_brick_stairs[facing=north,half=top,shape=straight]"
      },
      {
        "char": "G",
        "block": "minecraft:iron_bars[east=false,north=false,south=true,west=false]"
      },
      {
        "char": "Y",
        "block": "minecraft:iron_bars[east=false,north=true,south=false,west=false]"
      },
      {
        "char": "ϓ",
        "block": "minecraft:air"
      },
      {
        "char": "f",
        "block": "minecraft:glass"
      },
      {
        "char": "Ѷ",
        "block": "minecraft:spruce_planks"
      },
      {
        "char": "ѹ",
        "block": "minecraft:iron_bars[east=true,north=false,south=false,west=true]"
      },
      {
        "char": "ӟ",
        "block": "minecraft:iron_bars[east=true,north=false,south=true,west=true]"
      },
      {
        "char": "後",
        "block": "minecraft:stone_pressure_plate[powered=false]"
      },
      {
        "char": "望",
        "block": "minecraft:iron_door[facing=west,half=lower,hinge=right,open=false]"
      },
      {
        "char": "代",
        "block": "minecraft:iron_door[facing=west,half=lower,hinge=left,open=false]"
      },
      {
        "char": "z",
        "block": "minecraft:iron_bars[east=false,north=true,south=true,west=false]"
      },
      {
        "char": "字",
        "block": "minecraft:iron_door[facing=west,half=upper,hinge=right,open=false]"
      },
      {
        "char": "算",
        "block": "minecraft:iron_door[facing=west,half=upper,hinge=left,open=false]"
      },
      {
        "char": "解",
        "block": "minecraft:stone_stairs[facing=east,half=top,shape=straight]"
      },
      {
        "char": "作",
        "block": "minecraft:stone_brick_stairs[facing=west,half=top,shape=straight]"
      },
      {
        "char": "у",
        "block": "minecraft:stone_brick_stairs[facing=south,half=top,shape=straight]"
      },
      {
        "char": "T",
        "block": "minecraft:redstone_lamp[lit=false]"
      },
      {
        "char": "情",
        "block": "minecraft:air"
      },
      {
        "char": "ӽ",
        "block": "minecraft:air"
      },
      {
        "char": "应",
        "block": "minecraft:air"
      }
    ]
  },
  "slices": [
    [
      "         acedbae",
      "       eeacdbdca",
      "      cedeeebeca",
      "     bbebadaaeba",
      "    aacabeaaeeac",
      "  g badebcccdaac",
      "aaaaaccebcbdacae",
      "bdeceeabaadabcce",
      "cbaeccdcccedcdee",
      "ddcbebeebccdbbdd",
      "eadadadbcceaeade",
      "cdbacbaadddbbbab",
      "abadadbcedaa小选Сd",
      "baebaaedbbbe G a",
      "ebdbbbbacbce Y b",
      "babcaaceedee   c"
    ],
    [
      "         eccb ϓ ",
      "       ffad     ",
      "                ",
      "                ",
      "    f       ѶѶ  ",
      "  a f       ѶѶ  ",
      "   cd           ",
      "ѹѹӟca           ",
      "  aa            ",
      "  ba            ",
      " db             ",
      " daϓ    ϓ     ϓa",
      "後望後        d dbe",
      "後代後        c z a",
      " ca        d Y a",
      " ad        c   c"
    ],
    [
      "         caed ϓ ",
      "        fac     ",
      "      f         ",
      "     f          ",
      "            ѶѶ  ",
      "  a f       ѶѶ  ",
      "   cd           ",
      "   bc           ",
      "  da            ",
      "  dd            ",
      " cc             ",
      " ecϓ    ϓ     ϓd",
      " 字         a aac",
      " 算         e z b",
      " cc        c Y d",
      " dc        c   d"
    ],
    [
      "         cadb ϓ ",
      "       f da     ",
      "      f         ",
      "     f          ",
      "    f           ",
      "  g f           ",
      "   ec           ",
      "   ce           ",
      "  ec            ",
      "  ce            ",
      " da             ",
      " dcϓ    ϓ     ϓd",
      " 解作        cуaad",
      " 解作        b z c",
      " ce        d Y b",
      " ad        c   d"
    ],
    [
      "         bdee ϓ ",
      "       ffee     ",
      "      f         ",
      "     f          ",
      "    f           ",
      "  a             ",
      "   ec           ",
      "   da           ",
      "  db            ",
      "  ed            ",
      " dd             ",
      " acϓ    ϓ     ϓd",
      " db        adceb",
      " dd        b z e",
      " aa        c Y c",
      " ec        c   a"
    ],
    [
      "         addb ϓ ",
      "       adda     ",
      "     Tdca       ",
      "     ee         ",
      "    ba          ",
      "  a ee          ",
      "   aa           ",
      "   ee           ",
      "  db            ",
      "  cb            ",
      " db             ",
      " cb情ӽӽӽӽӽӽӽӽӽӽ应c",
      " ad        adcaa",
      " bc        e   c",
      " ab        e   d",
      " ce        b   a"
    ]
  ]
}