{
  "xsize": 16,
  "zsize": 16,
  "palette": {
    "palette": [
      {
        "char": " ",
        "block": "minecraft:air"
      },
      {
        "char": "a",
        "block": "minecraft:cyan_terracotta"
      },
      {
        "char": "b",
        "block": "minecraft:blackstone"
      },
      {
        "char": "d",
        "block": "minecraft:cobbled_deepslate"
      },
      {
        "char": "c",
        "block": "minecraft:deepslate[axis=y]"
      },
      {
        "char": "i",
        "block": "minecraft:light_gray_concrete"
      },
      {
        "char": "g",
        "block": "minecraft:gray_concrete"
      },
      {
        "char": "e",
        "block": "minecraft:basalt[axis=y]"
      },
      {
        "char": "ϔ",
        "block": "minecraft:quartz_stairs[facing=east,half=bottom,shape=straight]"
      },
      {
        "char": "f",
        "block": "minecraft:glass"
      },
      {
        "char": "x",
        "block": "minecraft:cauldron"
      },
      {
        "char": "H",
        "block": "minecraft:quartz_stairs[facing=south,half=bottom,shape=straight]"
      },
      {
        "char": "Ӻ",
        "block": "minecraft:chest",
        "tag": {
          "z": -276,
          "x": -15,
          "id": "minecraft:chest",
          "y": 27,
          "NodePos": "-3848291827685L",
          "Connections": [
            "L"
          ]
        }
      },
      {
        "char": "l",
        "block": "minecraft:iron_trapdoor[facing=east,half=bottom,open=false]"
      },
      {
        "char": "Ӟ",
        "block": "minecraft:air"
      },
      {
        "char": "k",
        "block": "minecraft:oak_leaves"
      },
      {
        "char": "ϐ",
        "block": "minecraft:chest",
        "tag": {
          "z": -259,
          "x": -34,
          "id": "minecraft:chest",
          "y": -21,
          "NodePos": "-9070971985941L",
          "Connections": [
            "L"
          ]
        }
      },
      {
        "char": "u",
        "block": "minecraft:iron_trapdoor[facing=south,half=bottom,open=false]"
      },
      {
        "char": "t",
        "block": "minecraft:iron_trapdoor[facing=east,half=top,open=false]"
      },
      {
        "char": "在",
        "block": "minecraft:air"
      },
      {
        "char": "w",
        "block": "minecraft:iron_trapdoor[facing=south,half=top,open=false]"
      }
    ]
  },
  "slices": [
    [
      "abddbdcid       ",
      "bbbbbcdgd       ",
      "edadddead       ",
      "cdebbbab        ",
      "ddbdcdga        ",
      "beddadabg       ",
      "cdbacbada       ",
      "cbbdciaa        ",
      "debccaci        ",
      "beeeabi         ",
      "ecdaaaa         ",
      "bdcaba          ",
      "acgbga          ",
      "cbaea           ",
      "cgea            ",
      "aba             "
    ],
    [
      "e ϔ    f        ",
      "c      f        ",
      "bdb             ",
      "      f         ",
      "                ",
      "ecaaediba       ",
      "  x             ",
      "                ",
      "     f          ",
      "    f           ",
      "db  f           ",
      "H   b           ",
      "  f  a          ",
      "  f             ",
      "                ",
      "                "
    ],
    [
      "Ӻ      fl       ",
      "       fl       ",
      "       fl       ",
      "      fl        ",
      "      fӞ        ",
      "caabbcacg       ",
      "  k   fl        ",
      "     fl         ",
      "      l         ",
      "    fl          ",
      "ϐ   fl          ",
      "   fd           ",
      "   u i          ",
      "   l            ",
      " fl             ",
      "fl              "
    ],
    [
      "       ft       ",
      "       ft       ",
      "       ft       ",
      "      ft        ",
      "      ft        ",
      "dadabaada       ",
      "  k   ft        ",
      "     ft         ",
      "     ft         ",
      "    ft          ",
      "    f在          ",
      "    a           ",
      "   w a          ",
      "   t            ",
      " ft             ",
      " w              "
    ],
    [
      "       f        ",
      "       f        ",
      "                ",
      "      f         ",
      "      f         ",
      "eaecadada       ",
      "                ",
      "     f          ",
      "                ",
      "    f           ",
      "    f           ",
      "   fa           ",
      "  f  i          ",
      "  f             ",
      "                ",
      "f               "
    ],
    [
      "       ad       ",
      "       id       ",
      "       aa       ",
      "      ab        ",
      "      ad        ",
      "dcbadbaca       ",
      "      aa        ",
      "     aa         ",
      "     ab         ",
      "    ad          ",
      "    ge          ",
      "   gd           ",
      "  ac g          ",
      "  ad            ",
      " ad             ",
      "ae              "
    ]
  ]
}