{
  "xsize": 16,
  "zsize": 16,
  "palette": {
    "palette": [
      {
        "char": " ",
        "block": "minecraft:air"
      },
      {
        "char": "a",
        "block": "minecraft:cyan_terracotta"
      },
      {
        "char": "g",
        "block": "minecraft:gray_concrete"
      },
      {
        "char": "i",
        "block": "minecraft:light_gray_concrete"
      },
      {
        "char": "E",
        "block": "minecraft:red_terracotta"
      },
      {
        "char": "A",
        "block": "minecraft:red_concrete"
      },
      {
        "char": "c",
        "block": "minecraft:deepslate[axis=y]"
      },
      {
        "char": "e",
        "block": "minecraft:basalt[axis=y]"
      },
      {
        "char": "b",
        "block": "minecraft:blackstone"
      },
      {
        "char": "D",
        "block": "minecraft:smooth_stone_slab[type=bottom]"
      },
      {
        "char": "0",
        "block": "minecraft:stone_slab[type=bottom]"
      },
      {
        "char": "d",
        "block": "minecraft:cobbled_deepslate"
      },
      {
        "char": "X",
        "block": "minecraft:red_wool"
      },
      {
        "char": "Ӥ",
        "block": "minecraft:stone_brick_wall[north=tall,up=true]"
      },
      {
        "char": "ϗ",
        "block": "minecraft:stone_brick_wall[up=true]"
      },
      {
        "char": "f",
        "block": "minecraft:glass"
      },
      {
        "char": "ϕ",
        "block": "minecraft:quartz_stairs[facing=north,half=bottom,shape=straight]"
      },
      {
        "char": "O",
        "block": "minecraft:quartz_stairs[facing=west,half=bottom,shape=straight]"
      },
      {
        "char": "ϓ",
        "block": "minecraft:air"
      },
      {
        "char": "ϔ",
        "block": "minecraft:quartz_stairs[facing=east,half=bottom,shape=straight]"
      },
      {
        "char": "清",
        "block": "minecraft:air"
      },
      {
        "char": "s",
        "block": "minecraft:iron_trapdoor[facing=north,half=bottom,open=false]"
      },
      {
        "char": "都",
        "block": "minecraft:cobblestone_wall[north=tall,up=true]"
      },
      {
        "char": "l",
        "block": "minecraft:iron_trapdoor[facing=east,half=bottom,open=false]"
      },
      {
        "char": "Ҝ",
        "block": "minecraft:air",
        "tag": {
          "z": -292,
          "x": -29,
          "id": "minecraft:air",
          "y": 63,
          "NodePos": "-7696582590401L",
          "Connections": [
            "L"
          ]
        }
      },
      {
        "char": "p",
        "block": "minecraft:iron_trapdoor[facing=north,half=top,open=false]"
      },
      {
        "char": "意",
        "block": "minecraft:stone_brick_wall[east=low,north=low,up=true]"
      },
      {
        "char": "Ӽ",
        "block": "minecraft:stone_brick_wall[east=low,west=low]"
      },
      {
        "char": "政",
        "block": "minecraft:cobblestone_wall[east=low,north=tall,up=true,west=low]"
      },
      {
        "char": "出",
        "block": "minecraft:cobblestone_wall[north=low,up=true]"
      }
    ]
  },
  "slices": [
    [
      "                ",
      "                ",
      "                ",
      "                ",
      "                ",
      "         ag     ",
      " i       aa  EAE",
      "cebccbD0gD0DDdDd",
      "aaaagibaba0D000D",
      "edaddbaaagce0D0D",
      "dcddaedabcagdaDa",
      "cdaeeecbbcdeiaeD",
      "dddebbdcedddebga",
      "abbdedccbcddbdca",
      "ebcecceccdcabbad",
      "accceaecdceadcbc"
    ],
    [
      "                ",
      "                ",
      "                ",
      "                ",
      "                ",
      "                ",
      " g           X  ",
      " d      a    Ӥ ϗ",
      "fa fff  b       ",
      " c    ffaf      ",
      " e      c f    i",
      " e      d   ffb ",
      " d e ϕ  a       ",
      " d b    e      f",
      " a bdeacb  ϕ    ",
      " c      e Oϓϔ   "
    ],
    [
      "                ",
      "                ",
      "                ",
      "                ",
      "                ",
      "                ",
      " a           清 清",
      "sdssss  a    都 Ӥ",
      "fa fffssbs      ",
      " c     fg ss    ",
      " a      b  fss a",
      " e      b   ffc ",
      " c      e     fl",
      " b      b      f",
      " e  Ҝ Ҝ b       ",
      " c      b       "
    ],
    [
      "                ",
      "                ",
      "                ",
      "                ",
      "                ",
      "                ",
      " g           E X",
      "pepppp  a    意Ӽ政",
      "faff  ppap      ",
      " a    ffafpp    ",
      " b      c f pp g",
      " d      c    fe ",
      " b      a     fp",
      " e      d       ",
      " b      c       ",
      " e      b       "
    ],
    [
      "                ",
      "                ",
      "                ",
      "                ",
      "                ",
      "                ",
      " i           A A",
      " b      g      出",
      " gf ff  c       ",
      " e    ffaf      ",
      " b      e ff   a",
      " a      a   ffe ",
      " e      e     f ",
      " e      d      f",
      " c      e       ",
      " e      e       "
    ],
    [
      "                ",
      "                ",
      "                ",
      "                ",
      "                ",
      "                ",
      " g             A",
      "becddb  i       ",
      "aagagiebae      ",
      " b    aaaabc    ",
      " a      b gida a",
      " a      b   iaa ",
      " d      c     ac",
      " d      d      a",
      " b      b       ",
      " a      b       "
    ]
  ]
}