{
  "xsize": 16,
  "zsize": 16,
  "palette": {
    "palette": [
      {
        "char": " ",
        "block": "minecraft:air"
      },
      {
        "char": "e",
        "block": "minecraft:basalt[axis=y]"
      },
      {
        "char": "d",
        "block": "minecraft:cobbled_deepslate"
      },
      {
        "char": "b",
        "block": "minecraft:blackstone"
      },
      {
        "char": "c",
        "block": "minecraft:deepslate[axis=y]"
      },
      {
        "char": "a",
        "block": "minecraft:cyan_terracotta"
      },
      {
        "char": "i",
        "block": "minecraft:light_gray_concrete"
      },
      {
        "char": "g",
        "block": "minecraft:gray_concrete"
      },
      {
        "char": "W",
        "block": "minecraft:polished_andesite_stairs[facing=south,half=top,shape=straight]"
      },
      {
        "char": "П",
        "block": "minecraft:barrel[facing=up,open=false]",
        "tag": {
          "z": -275,
          "x": -15,
          "ForgeData": {
            "LockFlag": "1b"
          },
          "id": "minecraft:barrel",
          "y": 2,
          "Items": []
        }
      },
      {
        "char": "Ѻ",
        "block": "minecraft:air"
      },
      {
        "char": "ϐ",
        "block": "minecraft:air",
        "tag": {
          "z": -259,
          "x": -34,
          "id": "minecraft:air",
          "y": -21,
          "NodePos": "-9070971985941L",
          "Connections": [
            "L"
          ]
        }
      },
      {
        "char": "Ѩ",
        "block": "minecraft:white_stained_glass_pane[east=false,north=true,south=true,west=false]"
      },
      {
        "char": "小",
        "block": "minecraft:air"
      },
      {
        "char": "Р",
        "block": "minecraft:stone_brick_stairs[facing=north,half=bottom,shape=straight]"
      },
      {
        "char": "目",
        "block": "minecraft:stone_brick_stairs[facing=north,half=bottom,shape=straight]"
      },
      {
        "char": "P",
        "block": "minecraft:smooth_quartz_slab[type=bottom]"
      },
      {
        "char": "Ѯ",
        "block": "minecraft:diorite_slab[type=bottom]"
      },
      {
        "char": "M",
        "block": "minecraft:smooth_quartz_slab[type=top]"
      },
      {
        "char": "ѩ",
        "block": "minecraft:diorite_slab[type=top]"
      },
      {
        "char": "h",
        "block": "minecraft:andesite_slab[type=top]"
      },
      {
        "char": "ϒ",
        "block": "minecraft:polished_andesite_stairs[facing=east,half=top,shape=straight]"
      },
      {
        "char": "建",
        "block": "minecraft:polished_andesite_stairs[facing=south,half=top,shape=inner_left]"
      }
    ]
  },
  "slices": [
    [
      "edeebcaca       ",
      "aeecccabb       ",
      "adbebeddc       ",
      "bbdbedddc       ",
      "edddabccc       ",
      "ecddbdcde       ",
      "ecddacaaaa      ",
      "  d     igWWWWbW",
      "  e      baebeae",
      "                ",
      "                ",
      "                ",
      "                ",
      "                ",
      "                ",
      "                "
    ],
    [
      "        d       ",
      " cac cbПb       ",
      "  Ѻ   Ѻ c       ",
      "        a       ",
      " dad bbca       ",
      "  Ѻ   Ѻ a       ",
      "ceeeaaacgaWWWWWW",
      "  edaceaaabcabcd",
      "  dbaaecec      ",
      "                ",
      "                ",
      "                ",
      "                ",
      "                ",
      "                ",
      "                "
    ],
    [
      "        b       ",
      "  ϐ   ϐ Ѩ       ",
      "        Ѩ       ",
      "        Ѩ       ",
      "  ϐ   ϐ Ѩ       ",
      "        a       ",
      "ccbdbdddaabbdaec",
      "  b     aa小Р小目РР",
      "  e      b      ",
      "                ",
      "                ",
      "                ",
      "                ",
      "                ",
      "                ",
      "                "
    ],
    [
      "        d       ",
      "        Ѩ       ",
      "        Ѩ       ",
      "        Ѩ       ",
      "        Ѩ       ",
      "        e       ",
      "bdbaedbbggeacbeb",
      "PPѮPPPPPaa      ",
      "  d      d      ",
      "                ",
      "                ",
      "                ",
      "                ",
      "                ",
      "                ",
      "                "
    ],
    [
      "        b       ",
      "        c       ",
      "        d       ",
      "        b       ",
      "        c       ",
      "        c       ",
      "dbcbddcdaiccbdca",
      "MѩѩMMMѩMgaMMMѩMM",
      "  a      a      ",
      "                ",
      "                ",
      "                ",
      "                ",
      "                ",
      "                ",
      "                "
    ],
    [
      "hhhhhhhϒchhhhhhh",
      "hhhhhhhϒdhhhhhhh",
      "hhhhhhhϒehhhhhhh",
      "hhhhhhhϒbhhhhhhh",
      "hhhhhhhϒdhhhhhhh",
      "WWWWWWW建eWWWWWWW",
      "adaddcdcdbdbdbaa",
      "        ia      ",
      "  b      c      ",
      "                ",
      "                ",
      "                ",
      "                ",
      "                ",
      "                ",
      "                "
    ]
  ]
}