{
  "xsize": 16,
  "zsize": 16,
  "palette": {
    "palette": [
      {
        "char": " ",
        "block": "minecraft:air"
      },
      {
        "char": "a",
        "block": "minecraft:cyan_terracotta"
      },
      {
        "char": "j",
        "block": "minecraft:polished_andesite_slab[type=top]"
      },
      {
        "char": "0",
        "block": "minecraft:stone_slab[type=bottom]"
      },
      {
        "char": "d",
        "block": "minecraft:cobbled_deepslate"
      },
      {
        "char": "g",
        "block": "minecraft:gray_concrete"
      },
      {
        "char": "c",
        "block": "minecraft:deepslate[axis=y]"
      },
      {
        "char": "b",
        "block": "minecraft:blackstone"
      },
      {
        "char": "e",
        "block": "minecraft:basalt[axis=y]"
      },
      {
        "char": "系",
        "block": "minecraft:spruce_fence[east=true]"
      },
      {
        "char": "F",
        "block": "minecraft:light_blue_terracotta"
      },
      {
        "char": "x",
        "block": "minecraft:cauldron"
      },
      {
        "char": "看",
        "block": "minecraft:birch_trapdoor[facing=north,half=bottom,open=true]"
      },
      {
        "char": "会",
        "block": "minecraft:birch_stairs[facing=east,half=bottom,shape=straight]"
      },
      {
        "char": "好",
        "block": "minecraft:birch_stairs[facing=west,half=bottom,shape=straight]"
      },
      {
        "char": "问",
        "block": "minecraft:birch_trapdoor[facing=south,half=bottom,open=true]"
      },
      {
        "char": "ϓ",
        "block": "minecraft:air"
      },
      {
        "char": "k",
        "block": "minecraft:oak_leaves"
      },
      {
        "char": "P",
        "block": "minecraft:smooth_quartz_slab[type=bottom]"
      },
      {
        "char": "Ѯ",
        "block": "minecraft:diorite_slab[type=bottom]"
      },
      {
        "char": "i",
        "block": "minecraft:light_gray_concrete"
      },
      {
        "char": "M",
        "block": "minecraft:smooth_quartz_slab[type=top]"
      },
      {
        "char": "ѩ",
        "block": "minecraft:diorite_slab[type=top]"
      },
      {
        "char": "们",
        "block": "minecraft:polished_andesite_stairs[facing=west,half=top,shape=inner_right]"
      },
      {
        "char": "Т",
        "block": "minecraft:polished_andesite_stairs[facing=north,half=top,shape=straight]"
      },
      {
        "char": "让",
        "block": "minecraft:polished_andesite_stairs[facing=north,half=top,shape=inner_left]"
      },
      {
        "char": "而",
        "block": "minecraft:polished_andesite_stairs[facing=north,half=top,shape=outer_left]"
      },
      {
        "char": "h",
        "block": "minecraft:andesite_slab[type=top]"
      },
      {
        "char": "ѭ",
        "block": "minecraft:polished_andesite_stairs[facing=west,half=top,shape=straight]"
      }
    ]
  },
  "slices": [
    [
      "                ",
      "                ",
      "                ",
      "                ",
      "                ",
      "           aa  j",
      "        0dagacdb",
      "         cceddae",
      "        aaeaebda",
      "        aadaebdb",
      "         eaadccc",
      "         dbeabab",
      "         bddbbac",
      "         aabdcae",
      "         bdcbbca",
      "        系cbabeca"
    ],
    [
      "                ",
      "                ",
      "                ",
      "                ",
      "                ",
      "           aa  F",
      "         ebggcbb",
      "         a  x  x",
      "        aa      ",
      "        aax  看看 ",
      "         c   会好 ",
      "         a   会好 ",
      "         ex  会好 ",
      "         b   问问 ",
      "         e     ϓ",
      "         dx  看看 "
    ],
    [
      "                ",
      "                ",
      "                ",
      "                ",
      "                ",
      "           ag  F",
      "         ceaabec",
      "         a  k  k",
      "        aa      ",
      "        agk     ",
      "         c      ",
      "         b      ",
      "         bk     ",
      "         d      ",
      "         c      ",
      "         bk     "
    ],
    [
      "                ",
      "                ",
      "                ",
      "                ",
      "                ",
      "        PPPaaPPF",
      "        Ѯeeaabac",
      "        Pb  k  k",
      "        ia      ",
      "        aak     ",
      "        Pc      ",
      "        Pc      ",
      "        Pck     ",
      "        Pa      ",
      "        Pb      ",
      "        Pck     "
    ],
    [
      "                ",
      "                ",
      "                ",
      "                ",
      "                ",
      "        MMMaaѩMF",
      "        Mabagecc",
      "        Mc      ",
      "        aa      ",
      "        ag      ",
      "        ѩb      ",
      "        ѩb      ",
      "        Me      ",
      "        Mc      ",
      "        Ma      ",
      "        Me      "
    ],
    [
      "                ",
      "                ",
      "                ",
      "                ",
      "                ",
      "           ai  F",
      "         eeadbce",
      "         ca们ТТТТ",
      "        ac让而hhhh",
      "        geѭhhhhh",
      "         bѭhhhhh",
      "         cѭhhhhh",
      "         bѭhhhhh",
      "         eѭhhhhh",
      "         dѭhhhhh",
      "         dѭhhhhh"
    ]
  ]
}