{
  "xsize": 16,
  "zsize": 16,
  "palette": {
    "palette": [
      {
        "char": " ",
        "block": "minecraft:air"
      },
      {
        "char": "e",
        "block": "minecraft:basalt[axis=y]"
      },
      {
        "char": "c",
        "block": "minecraft:deepslate[axis=y]"
      },
      {
        "char": "b",
        "block": "minecraft:blackstone"
      },
      {
        "char": "a",
        "block": "minecraft:cyan_terracotta"
      },
      {
        "char": "d",
        "block": "minecraft:cobbled_deepslate"
      },
      {
        "char": "g",
        "block": "minecraft:gray_concrete"
      },
      {
        "char": "x",
        "block": "minecraft:cauldron"
      },
      {
        "char": "j",
        "block": "minecraft:polished_andesite_slab[type=top]"
      },
      {
        "char": "Ӛ",
        "block": "minecraft:dark_oak_door[facing=south,half=lower,hinge=left,open=false]"
      },
      {
        "char": "П",
        "block": "minecraft:barrel[facing=up,open=false]",
        "tag": {
          "z": -275,
          "x": -15,
          "ForgeData": {
            "LockFlag": "1b"
          },
          "id": "minecraft:barrel",
          "y": 2,
          "Items": []
        }
      },
      {
        "char": "H",
        "block": "minecraft:quartz_stairs[facing=south,half=bottom,shape=straight]"
      },
      {
        "char": "f",
        "block": "minecraft:glass"
      },
      {
        "char": "k",
        "block": "minecraft:oak_leaves"
      },
      {
        "char": "ҟ",
        "block": "minecraft:spruce_trapdoor[facing=south,half=bottom,open=false]"
      },
      {
        "char": "ӗ",
        "block": "minecraft:tripwire_hook[attached=false,facing=north,powered=false]"
      },
      {
        "char": "ә",
        "block": "minecraft:dark_oak_door[facing=south,half=upper,hinge=left,open=false]"
      },
      {
        "char": "ο",
        "block": "minecraft:air"
      },
      {
        "char": "ѧ",
        "block": "minecraft:air"
      },
      {
        "char": "Ә",
        "block": "minecraft:white_wall_banner",
        "tag": {
          "z": -268,
          "Patterns": [
            {
              "Color": 8,
              "Pattern": "dls"
            },
            {
              "Color": 0,
              "Pattern": "dls"
            },
            {
              "Color": 3,
              "Pattern": "gru"
            },
            {
              "Color": 8,
              "Pattern": "bo"
            }
          ],
          "x": -29,
          "id": "minecraft:banner",
          "y": -14
        }
      },
      {
        "char": "С",
        "block": "minecraft:stone_brick_stairs[facing=north,half=top,shape=straight]"
      },
      {
        "char": "Ҽ",
        "block": "minecraft:birch_wall_sign",
        "tag": {
          "z": -283,
          "x": -20,
          "is_waxed": "0b",
          "id": "minecraft:sign",
          "y": -49,
          "front_text": {
            "color": "black",
            "has_glowing_text": "0b",
            "messages": [
              "{\"text\":\"\"}",
              "{\"text\":\"INFORMATION\"}",
              "{\"text\":\"\"}",
              "{\"text\":\"\"}"
            ]
          },
          "back_text": {
            "color": "black",
            "has_glowing_text": "0b",
            "messages": [
              "{\"text\":\"\"}",
              "{\"text\":\"\"}",
              "{\"text\":\"\"}",
              "{\"text\":\"\"}"
            ]
          }
        }
      }
    ]
  },
  "slices": [
    [
      "ecbbebaeaeeaecbe",
      "cabeccbecdcdeaad",
      "dbabbdacabadbaec",
      "eedcaeeeaedbeeea",
      "bbecaccbcdccabea",
      "eedbdadedcdebaed",
      "bcdbacddbbcadeee",
      "eacdccabeabcdcca",
      "beadbadceccbbbde",
      "cbbedbbcebdccaec",
      "badbccbeacebdebc",
      "aaaeedccbaeabbcb",
      "adebabddcdeedeee",
      "abadacebbecbdcba",
      "aecbacecedbbddba",
      "ecbcaddedeceaccg"
    ],
    [
      "cbabdaadx       ",
      " a xjjjb        ",
      " c     c     b  ",
      " e     ax    c  ",
      " d x   c     d  ",
      "dbedbӚdab   daea",
      " b            x ",
      "                ",
      "                ",
      "                ",
      " b Пec ebd dbd a",
      "    H   H   H   ",
      "                ",
      "   dbe cae dbb  ",
      " a  H   H   H   ",
      "               f"
    ],
    [
      "ededcddbk       ",
      " a ҟ   b        ",
      " d     e     c  ",
      " b     ek    b  ",
      " b ӗ   e     a  ",
      "adcdeәaaa   dbcb",
      " d            k ",
      "                ",
      "                ",
      "                ",
      " d  οѧ  οѧ  οѧ  ",
      "                ",
      "                ",
      "    οѧ  οѧ  οѧ  ",
      " b              ",
      "               f"
    ],
    [
      "dcbdcbdek       ",
      " e     a        ",
      " b     a     e  ",
      " b     ak    d  ",
      " c Ә   c     d  ",
      "eceeaСbab   ddcc",
      " a            k ",
      "                ",
      "                ",
      "                ",
      " e              ",
      "                ",
      "                ",
      "                ",
      " e              ",
      "               f"
    ],
    [
      "adcdbbcc     j  ",
      " b     d     j  ",
      " b     d     a  ",
      " d     a     a  ",
      " c     b     c  ",
      "caebbacbdjjjdcca",
      " b   Ҽ          ",
      " j              ",
      " j              ",
      " j              ",
      " c              ",
      " j              ",
      " j              ",
      " j              ",
      " b              ",
      " j             f"
    ],
    [
      "ccecbedc     a  ",
      " b     c     c  ",
      " d     a     e  ",
      " c     a     c  ",
      " b     e     d  ",
      "daddcbdacaedceac",
      " b              ",
      " c              ",
      " c              ",
      " b              ",
      " a              ",
      " b              ",
      " c              ",
      " e              ",
      " d              ",
      " b             a"
    ]
  ]
}