{
  "xsize": 16,
  "zsize": 16,
  "palette": {
    "palette": [
      {
        "char": " ",
        "block": "minecraft:air"
      },
      {
        "char": "e",
        "block": "minecraft:basalt[axis=y]"
      },
      {
        "char": "a",
        "block": "minecraft:cyan_terracotta"
      },
      {
        "char": "d",
        "block": "minecraft:cobbled_deepslate"
      },
      {
        "char": "c",
        "block": "minecraft:deepslate[axis=y]"
      },
      {
        "char": "b",
        "block": "minecraft:blackstone"
      },
      {
        "char": "Z",
        "block": "minecraft:stone_brick_wall[east=tall,north=tall,up=true,west=tall]"
      },
      {
        "char": "Ӿ",
        "block": "minecraft:cobblestone_wall[east=tall,north=tall,up=true,west=tall]"
      },
      {
        "char": "G",
        "block": "minecraft:iron_bars[east=false,north=false,south=true,west=false]"
      },
      {
        "char": "f",
        "block": "minecraft:glass"
      },
      {
        "char": "x",
        "block": "minecraft:cauldron"
      },
      {
        "char": "v",
        "block": "minecraft:quartz_pillar[axis=x]"
      },
      {
        "char": "n",
        "block": "minecraft:smooth_quartz"
      },
      {
        "char": "r",
        "block": "minecraft:polished_diorite"
      },
      {
        "char": "s",
        "block": "minecraft:iron_trapdoor[facing=north,half=bottom,open=false]"
      },
      {
        "char": "l",
        "block": "minecraft:iron_trapdoor[facing=east,half=bottom,open=false]"
      },
      {
        "char": "k",
        "block": "minecraft:oak_leaves"
      },
      {
        "char": "p",
        "block": "minecraft:iron_trapdoor[facing=north,half=top,open=false]"
      },
      {
        "char": "t",
        "block": "minecraft:iron_trapdoor[facing=east,half=top,open=false]"
      },
      {
        "char": "I",
        "block": "minecraft:stone_slab[type=top]"
      },
      {
        "char": "j",
        "block": "minecraft:polished_andesite_slab[type=top]"
      },
      {
        "char": "o",
        "block": "minecraft:chiseled_quartz_block"
      }
    ]
  },
  "slices": [
    [
      "eaddcbbcda      ",
      "dcebbadcaeab    ",
      "beebeecdabdaa   ",
      "cdebecaadddbcb  ",
      "edcccdcbadcecae ",
      "ddcdabbdecdcbbc ",
      "eceaecdcaddaaedc",
      "ddbbbacedeaccacd",
      "cdaadbedbadadcbc",
      "aabdcdacaceaadac",
      "eaaddddcebabdbaa",
      "bdadabddeeaddebe",
      "ZӾZcӾZZceedbbcdc",
      "   c   badeacdcc",
      "   e   beccbccea",
      " G e G cbadbebbb"
    ],
    [
      " b       e      ",
      "         b      ",
      "          ff    ",
      "            f   ",
      " a              ",
      "xbx             ",
      " d      x     cd",
      "dbec   dacbeecab",
      "          x  x  ",
      "                ",
      "                ",
      "   a   d        ",
      "vnvbnvre        ",
      "   b   d        ",
      "   b   ea      d",
      " G d G e        "
    ],
    [
      " c       b      ",
      "         css    ",
      "           fs   ",
      "            fl  ",
      " c            l ",
      "kdk          fl ",
      " a      k     ab",
      "baec   dcbaaddaa",
      "          k  k  ",
      "                ",
      "                ",
      "   b   e        ",
      "vvvavvva        ",
      "   d   a        ",
      "   d   ca      d",
      " G b G e        "
    ],
    [
      " c       c      ",
      "         bpp    ",
      "          ffp   ",
      "             p  ",
      " e           ft ",
      "kak          fp ",
      " e      k     cd",
      "caee   dbabcecdd",
      "          k  k  ",
      "                ",
      "                ",
      "   c   c        ",
      "vvnbvvvc        ",
      "   c   b        ",
      "   e   cc      a",
      " G c G e        "
    ],
    [
      " a       a      ",
      " I       e      ",
      " I        ff    ",
      " I              ",
      " e           f  ",
      " d           f  ",
      " a            ea",
      "adcbIIIaeceabdbd",
      "                ",
      "                ",
      "                ",
      "jjjejjjd        ",
      "ovvevvve        ",
      "   b   c        ",
      "   d   ddIIIIIIc",
      " G d G d        "
    ],
    [
      " e       e      ",
      " e        eb    ",
      " c        aaa   ",
      " a          db  ",
      " c           de ",
      " a           de ",
      " c             a",
      "badceaddbebeaeca",
      "                ",
      "                ",
      "                ",
      "daccaabd        ",
      "   c   e        ",
      "   c   e        ",
      "   e   bdbbddedc",
      " G c G d        "
    ]
  ]
}