{
  "xsize": 16,
  "zsize": 16,
  "palette": {
    "palette": [
      {
        "char": " ",
        "block": "minecraft:air"
      },
      {
        "char": "a",
        "block": "minecraft:cyan_terracotta"
      },
      {
        "char": "g",
        "block": "minecraft:gray_concrete"
      },
      {
        "char": "i",
        "block": "minecraft:light_gray_concrete"
      },
      {
        "char": "c",
        "block": "minecraft:deepslate[axis=y]"
      },
      {
        "char": "e",
        "block": "minecraft:basalt[axis=y]"
      },
      {
        "char": "b",
        "block": "minecraft:blackstone"
      },
      {
        "char": "d",
        "block": "minecraft:cobbled_deepslate"
      },
      {
        "char": "У",
        "block": "minecraft:stone_brick_stairs[facing=south,half=bottom,shape=straight]"
      },
      {
        "char": "Ѧ",
        "block": "minecraft:quartz_bricks"
      },
      {
        "char": "那",
        "block": "minecraft:white_terracotta"
      },
      {
        "char": "区",
        "block": "minecraft:air"
      },
      {
        "char": "n",
        "block": "minecraft:smooth_quartz"
      },
      {
        "char": "E",
        "block": "minecraft:red_terracotta"
      },
      {
        "char": "A",
        "block": "minecraft:red_concrete"
      },
      {
        "char": "Ѳ",
        "block": "minecraft:white_stained_glass_pane[east=true,north=false,south=false,west=false]"
      },
      {
        "char": "N",
        "block": "minecraft:white_stained_glass_pane[east=true,north=false,south=false,west=true]"
      },
      {
        "char": "Ѵ",
        "block": "minecraft:white_stained_glass_pane[east=false,north=false,south=false,west=true]"
      },
      {
        "char": "结",
        "block": "minecraft:stone_brick_stairs[facing=west,half=top,shape=inner_left]"
      },
      {
        "char": "Ѯ",
        "block": "minecraft:diorite_slab[type=bottom]"
      },
      {
        "char": "ӝ",
        "block": "minecraft:air"
      },
      {
        "char": "P",
        "block": "minecraft:smooth_quartz_slab[type=bottom]"
      },
      {
        "char": "x",
        "block": "minecraft:cauldron"
      },
      {
        "char": "Ӣ",
        "block": "minecraft:air"
      },
      {
        "char": "ϓ",
        "block": "minecraft:air"
      },
      {
        "char": "Ѻ",
        "block": "minecraft:air"
      },
      {
        "char": "ҝ",
        "block": "minecraft:stone_brick_slab[type=top]"
      },
      {
        "char": "还",
        "block": "minecraft:air"
      },
      {
        "char": "k",
        "block": "minecraft:oak_leaves"
      },
      {
        "char": "发",
        "block": "minecraft:chain[axis=y]"
      },
      {
        "char": "M",
        "block": "minecraft:smooth_quartz_slab[type=top]"
      },
      {
        "char": "ѩ",
        "block": "minecraft:diorite_slab[type=top]"
      },
      {
        "char": "Т",
        "block": "minecraft:polished_andesite_stairs[facing=north,half=top,shape=straight]"
      },
      {
        "char": "h",
        "block": "minecraft:andesite_slab[type=top]"
      },
      {
        "char": "T",
        "block": "minecraft:redstone_lamp[lit=false]"
      }
    ]
  },
  "slices": [
    [
      "                ",
      "                ",
      "                ",
      "                ",
      "                ",
      "     a   gi     ",
      "cecbagdaeggaУУbУ",
      "          Ѧaacdb",
      "          Ѧaacee",
      "          那baabd",
      "         区Ѧeaecd",
      "          Ѧddaac",
      "          nddecb",
      "         aacaced",
      "         iaebcae",
      "E A A     Ѧaabbc"
    ],
    [
      "                ",
      "                ",
      "                ",
      "                ",
      "                ",
      "     i   aa     ",
      "ѲNѴ ѲaNѴ igeebd结",
      "          Ѯ    ӝ",
      "          Px  Ӣϓ",
      "          P    Ѻ",
      "          Ѯ     ",
      "          Ѯx   ӝ",
      "          P   Ӣϓ",
      "         aa    Ѻ",
      "         aa     ",
      "E E       Ѯ    ӝ"
    ],
    [
      "                ",
      "                ",
      "                ",
      "                ",
      "                ",
      "     g   gg     ",
      "ҝ还还还ҝiҝҝҝgaaeddc",
      "                ",
      "           k    ",
      "                ",
      "                ",
      "           k    ",
      "                ",
      "         gg     ",
      "         ia     ",
      "发 发             "
    ],
    [
      "                ",
      "                ",
      "                ",
      "                ",
      "                ",
      "PPPPPѮѮPѮaaPPPPP",
      "adeeabcbaiaeecbb",
      "                ",
      "           k    ",
      "                ",
      "                ",
      "           k    ",
      "                ",
      "         ag     ",
      "         ga     ",
      "发 发             "
    ],
    [
      "                ",
      "                ",
      "                ",
      "                ",
      "                ",
      "MѩMѩѩMMMMgaMѩMMM",
      "dbadcebedaadaded",
      "                ",
      "                ",
      "                ",
      "                ",
      "                ",
      "                ",
      "         aa     ",
      "         aa     ",
      "发 发             "
    ],
    [
      "                ",
      "                ",
      "                ",
      "                ",
      "                ",
      "         ga     ",
      "bidbceedeabadccd",
      "ТТТТТТТТТТТТТТТТ",
      "hhhhhhhhhhhhhhhh",
      "hhhhhhhhhhhhhhhh",
      "hhhhhhhhhhhhhhhh",
      "hThhhhhhhhhhhhhh",
      "hhhhhhhhhhhhhhhh",
      "hhhhhhhhhaghhhhh",
      "hhhhhhhhhighhhhh",
      "ahehhThhhhhhhhhh"
    ]
  ]
}