{
  "xsize": 16,
  "zsize": 16,
  "palette": {
    "palette": [
      {
        "char": " ",
        "block": "minecraft:air"
      },
      {
        "char": "r",
        "block": "minecraft:polished_diorite"
      },
      {
        "char": "ѹ",
        "block": "minecraft:iron_bars[east=true,north=false,south=false,west=true]"
      },
      {
        "char": "F",
        "block": "minecraft:light_blue_terracotta"
      },
      {
        "char": "a",
        "block": "minecraft:cyan_terracotta"
      },
      {
        "char": "g",
        "block": "minecraft:gray_concrete"
      },
      {
        "char": "D",
        "block": "minecraft:smooth_stone_slab[type=bottom]"
      },
      {
        "char": "改",
        "block": "minecraft:cobblestone_slab[type=double]"
      },
      {
        "char": "Ѱ",
        "block": "minecraft:cobblestone_slab[type=bottom]"
      },
      {
        "char": "别",
        "block": "minecraft:smooth_stone_slab[type=double]"
      },
      {
        "char": "e",
        "block": "minecraft:basalt[axis=y]"
      },
      {
        "char": "d",
        "block": "minecraft:cobbled_deepslate"
      },
      {
        "char": "0",
        "block": "minecraft:stone_slab[type=bottom]"
      },
      {
        "char": "c",
        "block": "minecraft:deepslate[axis=y]"
      },
      {
        "char": "b",
        "block": "minecraft:blackstone"
      },
      {
        "char": "台",
        "block": "minecraft:cobblestone_wall[north=low,south=low]"
      },
      {
        "char": "ѯ",
        "block": "minecraft:stone_brick_wall[north=low,south=low]"
      },
      {
        "char": "就",
        "block": "minecraft:stone_brick_wall[north=low,up=true]"
      },
      {
        "char": "出",
        "block": "minecraft:cobblestone_wall[north=low,up=true]"
      },
      {
        "char": "f",
        "block": "minecraft:glass"
      },
      {
        "char": "ϕ",
        "block": "minecraft:quartz_stairs[facing=north,half=bottom,shape=straight]"
      },
      {
        "char": "现",
        "block": "minecraft:air"
      },
      {
        "char": "车",
        "block": "minecraft:air"
      },
      {
        "char": "П",
        "block": "minecraft:barrel[facing=up,open=false]",
        "tag": {
          "z": -275,
          "x": -15,
          "ForgeData": {
            "LockFlag": "1b"
          },
          "id": "minecraft:barrel",
          "y": 2,
          "Items": []
        }
      },
      {
        "char": "对",
        "block": "minecraft:polished_andesite_slab[type=bottom]"
      },
      {
        "char": "s",
        "block": "minecraft:iron_trapdoor[facing=north,half=bottom,open=false]"
      },
      {
        "char": "东",
        "block": "minecraft:air"
      },
      {
        "char": "m",
        "block": "minecraft:iron_trapdoor[facing=west,half=bottom,open=false]"
      },
      {
        "char": "Ҝ",
        "block": "minecraft:chest",
        "tag": {
          "z": -292,
          "x": -29,
          "id": "minecraft:chest",
          "y": 63,
          "NodePos": "-7696582590401L",
          "Connections": [
            "L"
          ]
        }
      },
      {
        "char": "p",
        "block": "minecraft:iron_trapdoor[facing=north,half=top,open=false]"
      },
      {
        "char": "q",
        "block": "minecraft:iron_trapdoor[facing=west,half=top,open=false]"
      }
    ]
  },
  "slices": [
    [
      "                ",
      "                ",
      "                ",
      "                ",
      "                ",
      "rѹFFѹF  ag      ",
      "        aa      ",
      "DD改DѰ别DDDDgDDead",
      "DD0DD0DDDccadaaa",
      "ѰDD0D00deagaadac",
      "0DѰgѰbcaaadcebab",
      "D00Deagceaeeccdd",
      "ѰDdeadbecaeadaad",
      "0baaebdddbdabcac",
      "baccdeacebdeeabe",
      "abeedcbbbbdaacab"
    ],
    [
      "                ",
      "                ",
      "                ",
      "                ",
      "                ",
      "FFFFFF          ",
      "  台  ѯ          ",
      "  就  出    g     ",
      "          c   ff",
      "         faff   ",
      "   a   ff a     ",
      "    dff   e     ",
      "    f     d ϕ现  ",
      "  ff      a 车 c ",
      " f        dddeП ",
      "f    b    d     "
    ],
    [
      "                ",
      "                ",
      "                ",
      "                ",
      "                ",
      "对对对对对对          ",
      "                ",
      "          g  sss",
      "         scss ff",
      "       ss g f   ",
      "   g ss f c     ",
      "    af    a     ",
      "  ss      b 东   ",
      " s f      e     ",
      "mf        a Ҝ   ",
      "          a     "
    ],
    [
      "                ",
      "                ",
      "                ",
      "                ",
      "                ",
      "                ",
      "                ",
      "          a  ppp",
      "         pcppfff",
      "       pp aff   ",
      "   a ppff e     ",
      "    aff   d     ",
      "  pqf     c     ",
      " pff      d     ",
      "pf        a     ",
      "f         d     "
    ],
    [
      "                ",
      "                ",
      "                ",
      "                ",
      "                ",
      "                ",
      "                ",
      "          a     ",
      "          c  fff",
      "         faf    ",
      "   g   ff e     ",
      "    cff   d     ",
      "          e     ",
      "  ff      c     ",
      "          a     ",
      "          a     "
    ],
    [
      "                ",
      "                ",
      "                ",
      "                ",
      "                ",
      "                ",
      "                ",
      "          a  ceb",
      "         eecaaga",
      "       ebaaga   ",
      "   a caga b     ",
      "    eaa   c     ",
      "  bea     a     ",
      " caa      a     ",
      "bg        a     ",
      "a         b     "
    ]
  ]
}