{
  "xsize": 16,
  "zsize": 16,
  "palette": {
    "palette": [
      {
        "char": " ",
        "block": "minecraft:air"
      },
      {
        "char": "c",
        "block": "minecraft:deepslate[axis=y]"
      },
      {
        "char": "b",
        "block": "minecraft:blackstone"
      },
      {
        "char": "a",
        "block": "minecraft:cyan_terracotta"
      },
      {
        "char": "e",
        "block": "minecraft:basalt[axis=y]"
      },
      {
        "char": "d",
        "block": "minecraft:cobbled_deepslate"
      },
      {
        "char": "g",
        "block": "minecraft:gray_concrete"
      },
      {
        "char": "D",
        "block": "minecraft:smooth_stone_slab[type=bottom]"
      },
      {
        "char": "i",
        "block": "minecraft:light_gray_concrete"
      },
      {
        "char": "Ѱ",
        "block": "minecraft:cobblestone_slab[type=bottom]"
      },
      {
        "char": "0",
        "block": "minecraft:stone_slab[type=bottom]"
      },
      {
        "char": "f",
        "block": "minecraft:glass"
      },
      {
        "char": "H",
        "block": "minecraft:quartz_stairs[facing=south,half=bottom,shape=straight]"
      },
      {
        "char": "ϐ",
        "block": "minecraft:chest",
        "tag": {
          "z": -259,
          "x": -34,
          "id": "minecraft:chest",
          "y": -21,
          "NodePos": "-9070971985941L",
          "Connections": [
            "L"
          ]
        }
      },
      {
        "char": "l",
        "block": "minecraft:iron_trapdoor[facing=east,half=bottom,open=false]"
      },
      {
        "char": "u",
        "block": "minecraft:iron_trapdoor[facing=south,half=bottom,open=false]"
      },
      {
        "char": "w",
        "block": "minecraft:iron_trapdoor[facing=south,half=top,open=false]"
      },
      {
        "char": "j",
        "block": "minecraft:polished_andesite_slab[type=top]"
      }
    ]
  },
  "slices": [
    [
      "cbaaeddbadbadcge",
      "ccdddcbeededgaaD",
      "aaeeadbbbagaaaDg",
      "cbecacgiiaecDDDѰ",
      "agaaaidded0DѰѰ0D",
      "bacedb0DaD0D0D0D",
      " i       ag     ",
      "         ga     ",
      " d       c    b ",
      "                ",
      "                ",
      "                ",
      "                ",
      "                ",
      "                ",
      "                "
    ],
    [
      "   acb bcd    f ",
      "    H   H   ffb ",
      " e        f    i",
      " e    ffgf      ",
      "fiff f  a       ",
      " d      g       ",
      " g              ",
      "                ",
      " d       a    b ",
      "                ",
      "                ",
      "                ",
      "                ",
      "                ",
      "                ",
      "                "
    ],
    [
      "    ϐ   ϐ     fl",
      "            f c ",
      " e         fuu i",
      " a    ffafuu    ",
      "fa  ffuucu      ",
      "uauuuu  a       ",
      " a              ",
      "                ",
      " a       a    a ",
      "                ",
      "                ",
      "                ",
      "                ",
      "                ",
      "                ",
      "                "
    ],
    [
      "              fw",
      "            ffb ",
      " a        ffww a",
      " e     fa ww    ",
      " iff fwwcw      ",
      "wawwww  a       ",
      " g              ",
      "                ",
      " a       d    a ",
      "                ",
      "                ",
      "                ",
      "                ",
      "                ",
      "                ",
      "                "
    ],
    [
      " j            f ",
      " j          ffe ",
      " a        ff   a",
      " b    ffaf      ",
      "faff f  e       ",
      " a      a       ",
      " g              ",
      "                ",
      " e       b    e ",
      "                ",
      "                ",
      "                ",
      "                ",
      "                ",
      "                ",
      "                "
    ],
    [
      " d            ad",
      " e          age ",
      " e        aadd a",
      " b    aaaaad    ",
      "aiggaadacb      ",
      "bbdbae  g       ",
      " g              ",
      "                ",
      " d       e    c ",
      "                ",
      "                ",
      "                ",
      "                ",
      "                ",
      "                ",
      "                "
    ]
  ]
}