{
  "xsize": 16,
  "zsize": 16,
  "palette": {
    "palette": [
      {
        "char": " ",
        "block": "minecraft:air"
      },
      {
        "char": "o",
        "block": "minecraft:chiseled_quartz_block"
      },
      {
        "char": "n",
        "block": "minecraft:smooth_quartz"
      },
      {
        "char": "K",
        "block": "minecraft:quartz_block"
      },
      {
        "char": "C",
        "block": "minecraft:quartz_pillar[axis=y]"
      },
      {
        "char": "b",
        "block": "minecraft:blackstone"
      },
      {
        "char": "a",
        "block": "minecraft:cyan_terracotta"
      },
      {
        "char": "Q",
        "block": "minecraft:grass_block[snowy=false]"
      },
      {
        "char": "y",
        "block": "minecraft:basalt[axis=x]"
      },
      {
        "char": "r",
        "block": "minecraft:polished_diorite"
      },
      {
        "char": "J",
        "block": "minecraft:diorite"
      },
      {
        "char": "c",
        "block": "minecraft:deepslate[axis=y]"
      },
      {
        "char": "d",
        "block": "minecraft:cobbled_deepslate"
      },
      {
        "char": "资",
        "block": "minecraft:dirt"
      },
      {
        "char": "同",
        "block": "minecraft:air"
      },
      {
        "char": "U",
        "block": "minecraft:air"
      },
      {
        "char": "统",
        "block": "minecraft:spruce_trapdoor[facing=south,half=top,open=false]"
      },
      {
        "char": "ӝ",
        "block": "minecraft:air"
      },
      {
        "char": "Ӣ",
        "block": "minecraft:air"
      },
      {
        "char": "ϓ",
        "block": "minecraft:air"
      },
      {
        "char": "ӛ",
        "block": "minecraft:air"
      },
      {
        "char": "他",
        "block": "minecraft:stone_brick_stairs[facing=west,half=bottom,shape=straight]"
      },
      {
        "char": "e",
        "block": "minecraft:basalt[axis=y]"
      },
      {
        "char": "Ѻ",
        "block": "minecraft:air"
      },
      {
        "char": "i",
        "block": "minecraft:light_gray_concrete"
      },
      {
        "char": "g",
        "block": "minecraft:gray_concrete"
      },
      {
        "char": "x",
        "block": "minecraft:cauldron"
      },
      {
        "char": "Ѩ",
        "block": "minecraft:white_stained_glass_pane[east=false,north=true,south=true,west=false]"
      },
      {
        "char": "V",
        "block": "minecraft:air"
      },
      {
        "char": "Ѥ",
        "block": "minecraft:air",
        "tag": {
          "z": -276,
          "x": -43,
          "id": "minecraft:air",
          "y": -39,
          "NodePos": "-11544873218087L",
          "Connections": [
            "L"
          ]
        }
      },
      {
        "char": "k",
        "block": "minecraft:oak_leaves"
      },
      {
        "char": "麽",
        "block": "minecraft:white_stained_glass_pane[east=false,north=false,south=true,west=false]"
      },
      {
        "char": "A",
        "block": "minecraft:red_concrete"
      },
      {
        "char": "E",
        "block": "minecraft:red_terracotta"
      },
      {
        "char": "z",
        "block": "minecraft:iron_bars[east=false,north=true,south=true,west=false]"
      },
      {
        "char": "还",
        "block": "minecraft:air"
      },
      {
        "char": "ѩ",
        "block": "minecraft:diorite_slab[type=top]"
      },
      {
        "char": "M",
        "block": "minecraft:smooth_quartz_slab[type=top]"
      }
    ]
  },
  "slices": [
    [
      "ooonKoConboaaQyQ",
      "rnnnrKCJCyrcddby",
      "onnrnnoJocndydca",
      "KoonKnonKbKbabbb",
      "nJrnrCKJrdobyacb",
      "JrroCrKCJdybQcay",
      "ronKoornKadbdccc",
      "rrnoJKCKryrcbdyy",
      "JnrCJnCnocobddac",
      "ConnCnoJr资oyacby",
      "oorKrnnJJcrcbbQb",
      "CnrnnnroodCQacdd",
      "nrCKKJJrrcybdycc",
      "nrnronnnrbrdybcd",
      "rCnCJnoKoddaaycc",
      "roroConKJbabdydd"
    ],
    [
      " c       同   U U",
      " 统     ӝ c      ",
      "Ӣd    Ӣϓӛ他      ",
      " e     Ѻ 他      ",
      " d       d      ",
      "dia      aa U   ",
      " aa      ag     ",
      "         e      ",
      "        xb      ",
      "         e      ",
      "         ag   U ",
      "           U    ",
      "                ",
      "                ",
      "                ",
      "                "
    ],
    [
      "         Ѩ   V V",
      "         d      ",
      " Ѥ              ",
      "                ",
      "         a      ",
      " aa      aa V   ",
      " aa      ia     ",
      "         Ѩ      ",
      "        kѨ      ",
      "         Ѩ      ",
      "         aa   V ",
      "           V    ",
      "                ",
      "                ",
      "                ",
      "                "
    ],
    [
      "         Ѩ      ",
      "         c      ",
      "         Ѩ      ",
      "         Ѩ      ",
      "         e      ",
      " aa      ga     ",
      " ai      aa     ",
      "                ",
      "        k麽      ",
      "         Ѩ      ",
      "         ag     ",
      "                ",
      "                ",
      "                ",
      "                ",
      "                "
    ],
    [
      "A        麽      ",
      "E        a      ",
      "z        Ѩ      ",
      "E        Ѩ      ",
      "E        d      ",
      " aa      ag     ",
      " ai      aa     ",
      "         Ѩ      ",
      "         Ѩ      ",
      "         Ѩ      ",
      "         ai     ",
      "                ",
      "                ",
      "                ",
      "                ",
      "                "
    ],
    [
      "A        还      ",
      "E        a      ",
      "z        还      ",
      "A        还      ",
      "E        c      ",
      " igѩѩMMMMig     ",
      " ag      ag     ",
      " ѩ              ",
      " M       麽      ",
      " M       Ѩ      ",
      " M       ia     ",
      " ѩ              ",
      " ѩ              ",
      " ѩ              ",
      " M              ",
      " M              "
    ]
  ]
}