{
  "xsize": 16,
  "zsize": 16,
  "palette": {
    "palette": [
      {
        "char": " ",
        "block": "minecraft:air"
      },
      {
        "char": "e",
        "block": "minecraft:smooth_quartz"
      },
      {
        "char": "o",
        "block": "minecraft:quartz_block"
      },
      {
        "char": "p",
        "block": "minecraft:diorite"
      },
      {
        "char": "f",
        "block": "minecraft:polished_diorite"
      },
      {
        "char": "h",
        "block": "minecraft:white_stained_glass"
      },
      {
        "char": "x",
        "block": "minecraft:smooth_stone"
      },
      {
        "char": "头",
        "block": "minecraft:rail[shape=south_east]"
      },
      {
        "char": "考",
        "block": "minecraft:rail[shape=south_west]"
      },
      {
        "char": "城",
        "block": "minecraft:rail[shape=north_south]"
      },
      {
        "char": "难",
        "block": "minecraft:rail[shape=north_east]"
      },
      {
        "char": "喜",
        "block": "minecraft:rail[shape=north_west]"
      }
    ]
  },
  "slices": [
    [
      "eeoepppfefeoffff",
      "hofooeffefhhhhhh",
      "heeoefffffhhhhhh",
      "hoffeeefpphhhhhh",
      "hefpoeeefehhhhhh",
      "heepefeepehhhhhh",
      "hfffpoffoehhhhhh",
      "heefeefeefhhhhhh",
      "feefffoeffpeofee",
      "eehhhhhhheeeoefo",
      "fphhhhhhheeeoofe",
      "eehhhhhhheeoofeo",
      "fphhhhhhhfepppfo",
      "eehhhhhhhppeefff",
      "ffhhhhhhhfoopefp",
      "eehhhhhhheepeepo"
    ],
    [
      "                ",
      "                ",
      "                ",
      "    xx          ",
      "    xx          ",
      "    xx          ",
      "                ",
      "                ",
      "                ",
      "                ",
      "                ",
      "                ",
      "             xx ",
      "             xx ",
      "             xx ",
      "                "
    ],
    [
      "                ",
      "                ",
      "                ",
      "    头考          ",
      "    城城          ",
      "    难喜          ",
      "                ",
      "                ",
      "                ",
      "                ",
      "                ",
      "                ",
      "             头考 ",
      "             城城 ",
      "             难喜 ",
      "                "
    ],
    [
      "                ",
      "                ",
      "                ",
      "                ",
      "                ",
      "                ",
      "                ",
      "                ",
      "                ",
      "                ",
      "                ",
      "                ",
      "                ",
      "                ",
      "                ",
      "                "
    ],
    [
      "                ",
      "                ",
      "                ",
      "                ",
      "                ",
      "                ",
      "                ",
      "                ",
      "                ",
      "                ",
      "                ",
      "                ",
      "                ",
      "                ",
      "                ",
      "                "
    ],
    [
      "                ",
      "                ",
      "                ",
      "                ",
      "                ",
      "                ",
      "                ",
      "                ",
      "                ",
      "                ",
      "                ",
      "                ",
      "                ",
      "                ",
      "                ",
      "                "
    ]
  ]
}