{
  "xsize": 16,
  "zsize": 16,
  "palette": {
    "palette": [
      {
        "char": " ",
        "block": "minecraft:air"
      },
      {
        "char": "F",
        "block": "minecraft:stone_brick_slab[type=top]"
      },
      {
        "char": "u",
        "block": "minecraft:smooth_quartz_slab[type=bottom]"
      },
      {
        "char": "D",
        "block": "minecraft:cracked_stone_bricks"
      },
      {
        "char": "z",
        "block": "minecraft:mossy_stone_bricks"
      },
      {
        "char": "H",
        "block": "minecraft:cobblestone"
      },
      {
        "char": "E",
        "block": "minecraft:stone_bricks"
      },
      {
        "char": "C",
        "block": "minecraft:mossy_cobblestone"
      },
      {
        "char": "o",
        "block": "minecraft:quartz_block"
      },
      {
        "char": "h",
        "block": "minecraft:white_stained_glass"
      },
      {
        "char": "e",
        "block": "minecraft:smooth_quartz"
      },
      {
        "char": "f",
        "block": "minecraft:polished_diorite"
      },
      {
        "char": "p",
        "block": "minecraft:diorite"
      },
      {
        "char": "x",
        "block": "minecraft:smooth_stone"
      },
      {
        "char": "头",
        "block": "minecraft:rail[shape=south_east]"
      },
      {
        "char": "考",
        "block": "minecraft:rail[shape=south_west]"
      },
      {
        "char": "城",
        "block": "minecraft:rail[shape=north_south]"
      },
      {
        "char": "难",
        "block": "minecraft:rail[shape=north_east]"
      },
      {
        "char": "喜",
        "block": "minecraft:rail[shape=north_west]"
      }
    ]
  },
  "slices": [
    [
      "                ",
      "FFFFFFFFFFFFFFFF",
      "uuuuuuuuuuuuuuuu",
      "uuuuuuuuuuuuuuuu",
      "uuuuuuuuuuuuuuuu",
      "uuuuuuuuuuuuuuuu",
      "uuuuuuuuuuuuuuuu",
      "uDuuuuuuuzuuuuuu",
      "HHzEHCzDECCDDEzE",
      "oohhhhhhheffeeof",
      "fohhhhhhhefefpfe",
      "oehhhhhhheeeeeef",
      "oehhhhhhheoffoep",
      "efhhhhhhheefffee",
      "efhhhhhhhopfpfee",
      "oehhhhhhhpoefoep"
    ],
    [
      "                ",
      "                ",
      "                ",
      "                ",
      "                ",
      "                ",
      "                ",
      "                ",
      "                ",
      "                ",
      "                ",
      "                ",
      "             xx ",
      "             xx ",
      "             xx ",
      "                "
    ],
    [
      "                ",
      "                ",
      "                ",
      "                ",
      "                ",
      "                ",
      "                ",
      "                ",
      "                ",
      "                ",
      "                ",
      "                ",
      "             头考 ",
      "             城城 ",
      "             难喜 ",
      "                "
    ],
    [
      "                ",
      "                ",
      "                ",
      "                ",
      "                ",
      "                ",
      "                ",
      "                ",
      "                ",
      "                ",
      "                ",
      "                ",
      "                ",
      "                ",
      "                ",
      "                "
    ],
    [
      "                ",
      "                ",
      "                ",
      "                ",
      "                ",
      "                ",
      "                ",
      "                ",
      "                ",
      "                ",
      "                ",
      "                ",
      "                ",
      "                ",
      "                ",
      "                "
    ],
    [
      "                ",
      "                ",
      "                ",
      "                ",
      "                ",
      "                ",
      "                ",
      "                ",
      "                ",
      "                ",
      "                ",
      "                ",
      "                ",
      "                ",
      "                ",
      "                "
    ]
  ]
}