{
  "xsize": 16,
  "zsize": 16,
  "palette": {
    "palette": [
      {
        "char": " ",
        "block": "minecraft:air"
      },
      {
        "char": "b",
        "block": "minecraft:basalt[axis=x]"
      },
      {
        "char": "k",
        "block": "minecraft:blackstone"
      },
      {
        "char": "a",
        "block": "minecraft:cyan_terracotta"
      },
      {
        "char": "r",
        "block": "minecraft:grass_block[snowy=false]"
      },
      {
        "char": "d",
        "block": "minecraft:deepslate[axis=y]"
      },
      {
        "char": "c",
        "block": "minecraft:cobbled_deepslate"
      },
      {
        "char": "y",
        "block": "minecraft:quartz_pillar[axis=y]"
      },
      {
        "char": "p",
        "block": "minecraft:diorite"
      },
      {
        "char": "f",
        "block": "minecraft:polished_diorite"
      },
      {
        "char": "I",
        "block": "minecraft:dirt"
      },
      {
        "char": "s",
        "block": "minecraft:yellow_concrete"
      },
      {
        "char": "J",
        "block": "minecraft:yellow_terracotta"
      },
      {
        "char": "动",
        "block": "minecraft:air"
      },
      {
        "char": "q",
        "block": "minecraft:air"
      },
      {
        "char": "水",
        "block": "minecraft:air"
      },
      {
        "char": "u",
        "block": "minecraft:smooth_quartz_slab[type=bottom]"
      },
      {
        "char": "多",
        "block": "minecraft:quartz_slab[type=bottom]"
      },
      {
        "char": "与",
        "block": "minecraft:oak_log[axis=y]"
      },
      {
        "char": "N",
        "block": "minecraft:cobblestone_wall[up=true]"
      },
      {
        "char": "龙",
        "block": "minecraft:air"
      },
      {
        "char": "Ҫ",
        "block": "minecraft:oak_leaves"
      },
      {
        "char": "L",
        "block": "minecraft:oak_leaves"
      },
      {
        "char": "比",
        "block": "minecraft:oak_leaves"
      },
      {
        "char": "问",
        "block": "minecraft:oak_leaves"
      },
      {
        "char": "版",
        "block": "minecraft:oak_trapdoor[facing=north,half=top,open=true]"
      },
      {
        "char": "林",
        "block": "minecraft:oak_trapdoor[facing=west,half=top,open=true]"
      },
      {
        "char": "没",
        "block": "minecraft:redstone_lamp[lit=false]"
      },
      {
        "char": "跟",
        "block": "minecraft:cobblestone_wall[east=low,up=true,west=low]"
      },
      {
        "char": "空",
        "block": "minecraft:oak_trapdoor[facing=east,half=top,open=true]"
      }
    ]
  },
  "slices": [
    [
      "bbkkbaardcbbrkbb",
      "ckbkkaackacbddck",
      "kdccrcdacdkackkc",
      "dkabdcrdaccbkcbc",
      "daarbbkadkkddkbd",
      "cbycrkbbaccbckca",
      "ckpbracbkaarddcb",
      "dcfacccccdaackda",
      "dddkakbddddbbkbd",
      "ddakkabkdabkdraa",
      "abckakbbcabdkkda",
      "cdkcracrIrassJJJ",
      "crcdbbcrrrksackk",
      "cdkackdrrrdJdbkr",
      "acbadcarrrcJkdbd",
      "kcadbadrrrdsssss"
    ],
    [
      "       动   qq   ",
      "  q 水           ",
      "    q           ",
      "      q         ",
      "  qq            ",
      "    动           ",
      "    q           ",
      "         q      ",
      "                ",
      "      水 水水水  q  ",
      "       uuu水     ",
      "      多水与水多     ",
      " q    多q q多     ",
      "      多水q水多    q",
      "      多  q多     ",
      "      多q q多N    "
    ],
    [
      "       龙        ",
      "                ",
      "                ",
      "                ",
      "                ",
      "    龙           ",
      "                ",
      "                ",
      "                ",
      "                ",
      "                ",
      "        与       ",
      "                ",
      "                ",
      "                ",
      "           N    "
    ],
    [
      "                ",
      "                ",
      "                ",
      "                ",
      "                ",
      "                ",
      "                ",
      "                ",
      "                ",
      "                ",
      "                ",
      "        与       ",
      "                ",
      "                ",
      "                ",
      "           N    "
    ],
    [
      "                ",
      "                ",
      "                ",
      "                ",
      "                ",
      "                ",
      "                ",
      "                ",
      "                ",
      "       ҪLҪ比     ",
      "      ҪL问LҪ     ",
      "      L问与问L     ",
      "      ҪL问LҪ     ",
      "      比ҪLҪ      ",
      "                ",
      "           N    "
    ],
    [
      "                ",
      "                ",
      "                ",
      "                ",
      "                ",
      "                ",
      "                ",
      "                ",
      "                ",
      "      比ҪLҪ      ",
      "      ҪL问LҪ     ",
      "      L问与问L     ",
      "      ҪL问LҪ     ",
      "       ҪLҪ比     ",
      "          版 版   ",
      "         林没跟没空  "
    ]
  ]
}