{
  "xsize": 16,
  "zsize": 16,
  "palette": {
    "palette": [
      {
        "char": " ",
        "block": "minecraft:air"
      },
      {
        "char": "a",
        "block": "minecraft:cyan_terracotta"
      },
      {
        "char": "d",
        "block": "minecraft:deepslate[axis=y]"
      },
      {
        "char": "k",
        "block": "minecraft:blackstone"
      },
      {
        "char": "r",
        "block": "minecraft:grass_block[snowy=false]"
      },
      {
        "char": "c",
        "block": "minecraft:cobbled_deepslate"
      },
      {
        "char": "b",
        "block": "minecraft:basalt[axis=x]"
      },
      {
        "char": "s",
        "block": "minecraft:yellow_concrete"
      },
      {
        "char": "J",
        "block": "minecraft:yellow_terracotta"
      },
      {
        "char": "p",
        "block": "minecraft:diorite"
      },
      {
        "char": "q",
        "block": "minecraft:air"
      },
      {
        "char": "提",
        "block": "minecraft:smooth_stone_slab[type=top]"
      },
      {
        "char": "之",
        "block": "minecraft:black_concrete"
      },
      {
        "char": "N",
        "block": "minecraft:cobblestone_wall[up=true]"
      },
      {
        "char": "花",
        "block": "minecraft:oxeye_daisy"
      },
      {
        "char": "规",
        "block": "minecraft:spruce_trapdoor[facing=north,half=top,open=true]"
      },
      {
        "char": "说",
        "block": "minecraft:air"
      },
      {
        "char": "评",
        "block": "minecraft:barrel[facing=north,open=false]",
        "tag": {
          "z": 388,
          "x": 115,
          "ForgeData": {
            "LockFlag": "1b"
          },
          "ForgeCaps": {},
          "id": "minecraft:barrel",
          "y": 134,
          "Items": []
        }
      },
      {
        "char": "雄",
        "block": "minecraft:air"
      },
      {
        "char": "h",
        "block": "minecraft:white_stained_glass"
      },
      {
        "char": "猫",
        "block": "minecraft:white_stained_glass_pane[east=false,north=true,south=true,west=false]"
      },
      {
        "char": "院",
        "block": "minecraft:white_stained_glass_pane[east=true,north=true,south=false,west=false]"
      },
      {
        "char": "元",
        "block": "minecraft:white_stained_glass_pane[east=true,north=false,south=false,west=true]"
      },
      {
        "char": "图",
        "block": "minecraft:white_stained_glass_pane[east=false,north=true,south=false,west=true]"
      },
      {
        "char": "便",
        "block": "minecraft:air"
      },
      {
        "char": "卡",
        "block": "minecraft:air"
      },
      {
        "char": "般",
        "block": "minecraft:air"
      },
      {
        "char": "度",
        "block": "minecraft:oak_trapdoor[facing=south,half=top,open=true]"
      },
      {
        "char": "版",
        "block": "minecraft:oak_trapdoor[facing=north,half=top,open=true]"
      },
      {
        "char": "林",
        "block": "minecraft:oak_trapdoor[facing=west,half=top,open=true]"
      },
      {
        "char": "没",
        "block": "minecraft:redstone_lamp[lit=false]"
      },
      {
        "char": "跟",
        "block": "minecraft:cobblestone_wall[east=low,up=true,west=low]"
      }
    ]
  },
  "slices": [
    [
      "adkdrdkcabkbbkcs",
      "babbdkabackbddks",
      "cdkbkaakaacckaks",
      "sscdadkkassssJss",
      "bcakkbadackcabas",
      "dackaaaabdkdkkbs",
      "dbabcddkckaccdcs",
      "ssdckabkbsJsssss",
      "abbkkckacaabkccJ",
      "baaaddabakkkccrs",
      "kabacddcbraadcds",
      "ssdbcckckssssJsJ",
      "cakcbkkkcdabakds",
      "bdcdaddbkcrbdkbs",
      "kaadakdbrbbaacbJ",
      "ssdcapaakssssssJ"
    ],
    [
      "    q           ",
      "                ",
      "              q ",
      "        q       ",
      "  提提提           ",
      "  之 之           ",
      "  提 提           ",
      "  提 提           ",
      "  之 之           ",
      "  提提提           ",
      "        qq      ",
      "               N",
      "                ",
      "          花     ",
      "  q     q       ",
      "q               "
    ],
    [
      "                ",
      "                ",
      "                ",
      "   规            ",
      "  说评说           ",
      "  说说说           ",
      "  说说说           ",
      "  说说说           ",
      "  说说说           ",
      "  说说说           ",
      "                ",
      "               N",
      "                ",
      "                ",
      "                ",
      "                "
    ],
    [
      "                ",
      "                ",
      "                ",
      "                ",
      "   雄            ",
      "  说h说           ",
      "  猫 猫           ",
      "  说 说           ",
      "  院元图           ",
      "   便            ",
      "                ",
      "               N",
      "                ",
      "                ",
      "                ",
      "                "
    ],
    [
      "                ",
      "                ",
      "                ",
      "                ",
      "                ",
      "  卡便便           ",
      "  卡般便           ",
      "  卡般便           ",
      "  便卡便           ",
      "                ",
      "                ",
      "               N",
      "                ",
      "                ",
      "                ",
      "                "
    ],
    [
      "              度 ",
      "                ",
      "                ",
      "                ",
      "                ",
      "                ",
      "                ",
      "                ",
      "                ",
      "                ",
      "              版 ",
      "             林没跟",
      "              度 ",
      "                ",
      "                ",
      "                "
    ]
  ]
}