{
  "xsize": 16,
  "zsize": 16,
  "palette": {
    "palette": [
      {
        "char": " ",
        "block": "minecraft:air"
      },
      {
        "char": "r",
        "block": "minecraft:grass_block[snowy=false]"
      },
      {
        "char": "a",
        "block": "minecraft:cyan_terracotta"
      },
      {
        "char": "d",
        "block": "minecraft:deepslate[axis=y]"
      },
      {
        "char": "b",
        "block": "minecraft:basalt[axis=x]"
      },
      {
        "char": "k",
        "block": "minecraft:blackstone"
      },
      {
        "char": "c",
        "block": "minecraft:cobbled_deepslate"
      },
      {
        "char": "s",
        "block": "minecraft:yellow_concrete"
      },
      {
        "char": "J",
        "block": "minecraft:yellow_terracotta"
      },
      {
        "char": "开",
        "block": "minecraft:spawner",
        "tag": {
          "SpawnData": {
            "entity": {}
          },
          "MaxNearbyEntities": "6s",
          "MinSpawnDelay": "200s",
          "z": 387,
          "x": 24,
          "MaxSpawnDelay": "800s",
          "RequiredPlayerRange": "16s",
          "SpawnCount": "4s",
          "ForgeCaps": {},
          "id": "minecraft:mob_spawner",
          "SpawnPotentials": [],
          "y": 132,
          "SpawnRange": "4s",
          "Delay": "584s"
        }
      },
      {
        "char": "q",
        "block": "minecraft:air"
      },
      {
        "char": "提",
        "block": "minecraft:smooth_stone_slab[type=top]"
      },
      {
        "char": "之",
        "block": "minecraft:black_concrete"
      },
      {
        "char": "说",
        "block": "minecraft:air"
      },
      {
        "char": "嗯",
        "block": "minecraft:spruce_trapdoor[facing=west,half=top,open=true]"
      },
      {
        "char": "某",
        "block": "minecraft:barrel[facing=west,open=false]",
        "tag": {
          "z": 385,
          "x": 162,
          "ForgeData": {
            "LockFlag": "1b"
          },
          "ForgeCaps": {},
          "id": "minecraft:barrel",
          "y": 134,
          "Items": []
        }
      },
      {
        "char": "元",
        "block": "minecraft:white_stained_glass_pane[east=true,north=false,south=false,west=true]"
      },
      {
        "char": "段",
        "block": "minecraft:white_stained_glass_pane[east=false,north=false,south=true,west=true]"
      },
      {
        "char": "边",
        "block": "minecraft:air"
      },
      {
        "char": "h",
        "block": "minecraft:white_stained_glass"
      },
      {
        "char": "猫",
        "block": "minecraft:white_stained_glass_pane[east=false,north=true,south=true,west=false]"
      },
      {
        "char": "形",
        "block": "minecraft:air"
      },
      {
        "char": "图",
        "block": "minecraft:white_stained_glass_pane[east=false,north=true,south=false,west=true]"
      },
      {
        "char": "脑",
        "block": "minecraft:air"
      },
      {
        "char": "专",
        "block": "minecraft:air"
      },
      {
        "char": "般",
        "block": "minecraft:air"
      },
      {
        "char": "版",
        "block": "minecraft:oak_trapdoor[facing=north,half=top,open=true]"
      },
      {
        "char": "林",
        "block": "minecraft:oak_trapdoor[facing=west,half=top,open=true]"
      },
      {
        "char": "没",
        "block": "minecraft:redstone_lamp[lit=false]"
      }
    ]
  },
  "slices": [
    [
      "raadddadbkckkdkb",
      "bbkaaakadbcrdckc",
      "bcbcrbdacadbbkbk",
      "kckrdccccacccbrk",
      "rkddckkadkbdkack",
      "ccdbkbbcbbrdaadk",
      "kddkbabkdbbddcdd",
      "kbkckbrcdabdddac",
      "cbbkcbbcbdkbacaa",
      "brcakcacbbccraba",
      "ckbkkcbkdbkcakka",
      "adbkcbddcksssssJ",
      "aaabddbdcbckcbbb",
      "akadckcddccdccca",
      "kkkrbaakadbbcd开d",
      "bcbkkkcddrssJsJs"
    ],
    [
      "q               ",
      "      q    q    ",
      " q  q          q",
      "   q          q ",
      "                ",
      "                ",
      "                ",
      "      q  q      ",
      "        q       ",
      "            q   ",
      "                ",
      "            q   ",
      "          提之提提之提",
      "          提    提",
      "          提之提提之提",
      "         q      "
    ],
    [
      "                ",
      "                ",
      "                ",
      "                ",
      "                ",
      "                ",
      "                ",
      "                ",
      "                ",
      "                ",
      "                ",
      "                ",
      "          说说说说说说",
      "         嗯某说说说说说",
      "          说说说说说说",
      "                "
    ],
    [
      "                ",
      "                ",
      "                ",
      "                ",
      "                ",
      "                ",
      "                ",
      "                ",
      "                ",
      "                ",
      "                ",
      "                ",
      "          说说元说段 ",
      "          边h  猫形",
      "          说说元说图 ",
      "                "
    ],
    [
      "                ",
      "                ",
      "                ",
      "                ",
      "                ",
      "                ",
      "                ",
      "                ",
      "                ",
      "                ",
      "                ",
      "                ",
      "           脑脑脑脑 ",
      "           专般般脑 ",
      "           专边边脑 ",
      "                "
    ],
    [
      "                ",
      "                ",
      "                ",
      "                ",
      "                ",
      "                ",
      "                ",
      "                ",
      "                ",
      "                ",
      "                ",
      "                ",
      "                ",
      "                ",
      "               版",
      "              林没"
    ]
  ]
}