{
  "xsize": 16,
  "zsize": 16,
  "palette": {
    "palette": [
      {
        "char": " ",
        "block": "minecraft:air"
      },
      {
        "char": "d",
        "block": "minecraft:deepslate[axis=y]"
      },
      {
        "char": "k",
        "block": "minecraft:blackstone"
      },
      {
        "char": "c",
        "block": "minecraft:cobbled_deepslate"
      },
      {
        "char": "b",
        "block": "minecraft:basalt[axis=x]"
      },
      {
        "char": "r",
        "block": "minecraft:grass_block[snowy=false]"
      },
      {
        "char": "a",
        "block": "minecraft:cyan_terracotta"
      },
      {
        "char": "e",
        "block": "minecraft:smooth_quartz"
      },
      {
        "char": "s",
        "block": "minecraft:yellow_concrete"
      },
      {
        "char": "J",
        "block": "minecraft:yellow_terracotta"
      },
      {
        "char": "q",
        "block": "minecraft:air"
      },
      {
        "char": "问",
        "block": "minecraft:oak_leaves"
      },
      {
        "char": "L",
        "block": "minecraft:oak_leaves"
      },
      {
        "char": "运",
        "block": "minecraft:jungle_log[axis=y]"
      },
      {
        "char": "Ҫ",
        "block": "minecraft:oak_leaves"
      },
      {
        "char": "N",
        "block": "minecraft:cobblestone_wall[up=true]"
      },
      {
        "char": "版",
        "block": "minecraft:oak_trapdoor[facing=north,half=top,open=true]"
      },
      {
        "char": "林",
        "block": "minecraft:oak_trapdoor[facing=west,half=top,open=true]"
      },
      {
        "char": "没",
        "block": "minecraft:redstone_lamp[lit=false]"
      },
      {
        "char": "跟",
        "block": "minecraft:cobblestone_wall[east=low,up=true,west=low]"
      },
      {
        "char": "空",
        "block": "minecraft:oak_trapdoor[facing=east,half=top,open=true]"
      }
    ]
  },
  "slices": [
    [
      "dkcddbkcrdakbbdc",
      "abkcarababdbabcd",
      "cbbcbkaabdbkkbbr",
      "bkckckkcdcddkbkb",
      "dakacadcbbdckrka",
      "bckcdkckkkabbacb",
      "kdkbdbaradakdakd",
      "aadakccdaaakdbcb",
      "ddbkrdbdkcbkcdkc",
      "aaabrcccbdadcakr",
      "cakkkkdabcbdkbde",
      "sssssssssssbakea",
      "ccadsdcrkddkkacd",
      "bacbsabcdbaakbak",
      "ddbdJcbaadbdcdab",
      "sssssssssJsbdrcc"
    ],
    [
      "        q       ",
      "        q     问L",
      "             问运问",
      "            ҪL问L",
      "             qLҪ",
      "     q          ",
      "                ",
      "                ",
      "    q           ",
      "    q          q",
      "                ",
      "                ",
      "       q        ",
      "                ",
      "      q         ",
      "    N           "
    ],
    [
      "                ",
      "                ",
      "              问L",
      "             ҪL ",
      "                ",
      "                ",
      "                ",
      "                ",
      "                ",
      "                ",
      "                ",
      "                ",
      "                ",
      "                ",
      "                ",
      "    N           "
    ],
    [
      "                ",
      "                ",
      "                ",
      "                ",
      "                ",
      "                ",
      "                ",
      "                ",
      "                ",
      "                ",
      "                ",
      "                ",
      "                ",
      "                ",
      "                ",
      "    N           "
    ],
    [
      "                ",
      "                ",
      "                ",
      "                ",
      "                ",
      "                ",
      "                ",
      "                ",
      "                ",
      "                ",
      "                ",
      "                ",
      "                ",
      "                ",
      "                ",
      "    N           "
    ],
    [
      "                ",
      "                ",
      "                ",
      "                ",
      "                ",
      "                ",
      "                ",
      "                ",
      "                ",
      "                ",
      "                ",
      "                ",
      "                ",
      "                ",
      "   版 版          ",
      "  林没跟没空         "
    ]
  ]
}