{
  "xsize": 16,
  "zsize": 16,
  "palette": {
    "palette": [
      {
        "char": " ",
        "block": "minecraft:air"
      },
      {
        "char": "F",
        "block": "minecraft:stone_brick_slab[type=top]"
      },
      {
        "char": "u",
        "block": "minecraft:smooth_quartz_slab[type=bottom]"
      },
      {
        "char": "E",
        "block": "minecraft:stone_bricks"
      },
      {
        "char": "C",
        "block": "minecraft:mossy_cobblestone"
      },
      {
        "char": "D",
        "block": "minecraft:cracked_stone_bricks"
      },
      {
        "char": "z",
        "block": "minecraft:mossy_stone_bricks"
      },
      {
        "char": "H",
        "block": "minecraft:cobblestone"
      },
      {
        "char": "e",
        "block": "minecraft:smooth_quartz"
      },
      {
        "char": "o",
        "block": "minecraft:quartz_block"
      },
      {
        "char": "h",
        "block": "minecraft:white_stained_glass"
      },
      {
        "char": "f",
        "block": "minecraft:polished_diorite"
      },
      {
        "char": "p",
        "block": "minecraft:diorite"
      },
      {
        "char": "呵",
        "block": "minecraft:vine[east=true,north=true,south=true,up=false,west=true]"
      },
      {
        "char": "思",
        "block": "minecraft:vine[east=true,north=true,south=false,up=false,west=true]"
      },
      {
        "char": "l",
        "block": "minecraft:vine[east=true,north=false,south=false,up=false,west=false]"
      },
      {
        "char": "j",
        "block": "minecraft:vine[east=false,north=false,south=false,up=false,west=true]"
      },
      {
        "char": "队",
        "block": "minecraft:vine[east=true,north=true,south=true,up=false,west=false]"
      },
      {
        "char": "必",
        "block": "minecraft:vine[east=false,north=true,south=true,up=false,west=true]"
      },
      {
        "char": "那",
        "block": "minecraft:vine[east=true,north=false,south=true,up=false,west=false]"
      },
      {
        "char": "x",
        "block": "minecraft:smooth_stone"
      },
      {
        "char": "头",
        "block": "minecraft:rail[shape=south_east]"
      },
      {
        "char": "考",
        "block": "minecraft:rail[shape=south_west]"
      },
      {
        "char": "城",
        "block": "minecraft:rail[shape=north_south]"
      },
      {
        "char": "难",
        "block": "minecraft:rail[shape=north_east]"
      },
      {
        "char": "喜",
        "block": "minecraft:rail[shape=north_west]"
      }
    ]
  },
  "slices": [
    [
      "                ",
      "FFFFFFFFFFFFFFFF",
      "uuuuuuuuuuuuuuuu",
      "uuuuuuuuuuuuuuuu",
      "uuuuuuuuuuuuuuuu",
      "uuuuuuuuuuuuuuuu",
      "uuuuuuuuuuuuuuuu",
      "uEuuuuuuuEuuuuuu",
      "ECDEDEDDDCzCHEDE",
      "eohhhhhhhfefeofo",
      "ffhhhhhhhepfeefe",
      "eehhhhhhhffoepep",
      "oehh呵hhhhoefeffp",
      "fehhh思hlheffppeo",
      "pfhhhj队hhpffffpp",
      "oehh必那hhhfefoffe"
    ],
    [
      "                ",
      "                ",
      "                ",
      "                ",
      "                ",
      "                ",
      "                ",
      "                ",
      "                ",
      "                ",
      "                ",
      "                ",
      "             xx ",
      "             xx ",
      "             xx ",
      "                "
    ],
    [
      "                ",
      "                ",
      "                ",
      "                ",
      "                ",
      "                ",
      "                ",
      "                ",
      "                ",
      "                ",
      "                ",
      "                ",
      "             头考 ",
      "             城城 ",
      "             难喜 ",
      "                "
    ],
    [
      "                ",
      "                ",
      "                ",
      "                ",
      "                ",
      "                ",
      "                ",
      "                ",
      "                ",
      "                ",
      "                ",
      "                ",
      "                ",
      "                ",
      "                ",
      "                "
    ],
    [
      "                ",
      "                ",
      "                ",
      "                ",
      "                ",
      "                ",
      "                ",
      "                ",
      "                ",
      "                ",
      "                ",
      "                ",
      "                ",
      "                ",
      "                ",
      "                "
    ],
    [
      "                ",
      "                ",
      "                ",
      "                ",
      "                ",
      "                ",
      "                ",
      "                ",
      "                ",
      "                ",
      "                ",
      "                ",
      "                ",
      "                ",
      "                ",
      "                "
    ]
  ]
}