{
  "xsize": 16,
  "zsize": 16,
  "palette": {
    "palette": [
      {
        "char": " ",
        "block": "minecraft:air"
      },
      {
        "char": "a",
        "block": "minecraft:cyan_terracotta"
      },
      {
        "char": "b",
        "block": "minecraft:basalt[axis=x]"
      },
      {
        "char": "c",
        "block": "minecraft:cobbled_deepslate"
      },
      {
        "char": "d",
        "block": "minecraft:deepslate[axis=y]"
      },
      {
        "char": "k",
        "block": "minecraft:blackstone"
      },
      {
        "char": "r",
        "block": "minecraft:grass_block[snowy=false]"
      },
      {
        "char": "半",
        "block": "minecraft:air"
      },
      {
        "char": "e",
        "block": "minecraft:smooth_quartz"
      },
      {
        "char": "y",
        "block": "minecraft:quartz_pillar[axis=y]"
      },
      {
        "char": "s",
        "block": "minecraft:yellow_concrete"
      },
      {
        "char": "J",
        "block": "minecraft:yellow_terracotta"
      },
      {
        "char": "哪",
        "block": "minecraft:oak_leaves"
      },
      {
        "char": "ҭ",
        "block": "minecraft:oak_leaves"
      },
      {
        "char": "q",
        "block": "minecraft:air"
      },
      {
        "char": "L",
        "block": "minecraft:oak_leaves"
      },
      {
        "char": "Ҫ",
        "block": "minecraft:oak_leaves"
      },
      {
        "char": "朋",
        "block": "minecraft:oak_leaves"
      },
      {
        "char": "命",
        "block": "minecraft:oak_leaves"
      },
      {
        "char": "N",
        "block": "minecraft:cobblestone_wall[up=true]"
      },
      {
        "char": "版",
        "block": "minecraft:oak_trapdoor[facing=north,half=top,open=true]"
      },
      {
        "char": "林",
        "block": "minecraft:oak_trapdoor[facing=west,half=top,open=true]"
      },
      {
        "char": "没",
        "block": "minecraft:redstone_lamp[lit=false]"
      },
      {
        "char": "跟",
        "block": "minecraft:cobblestone_wall[east=low,up=true,west=low]"
      },
      {
        "char": "空",
        "block": "minecraft:oak_trapdoor[facing=east,half=top,open=true]"
      }
    ]
  },
  "slices": [
    [
      "abccdbbcdbdadbka",
      "kbdddbbrdckdrabr",
      "kcbrakdraabkbrac",
      "kdkrkcackkbkcbdb",
      "kc半bdddbdaaackdb",
      "arbckcccakdckrbc",
      "kdbdcbccckkddkkc",
      "rdkkccabccbckaca",
      "drkccdkdcdbkaddd",
      "ckccckbckcbkcbdk",
      "eybrbdcaaccbbcdk",
      "cdsJsJsssssssssa",
      "dkkkaacaJcbbbacb",
      "krkkrckbscdkdbkk",
      "ccabkdkdsacdrkaa",
      "drJsssssssssJssb"
    ],
    [
      "                ",
      "   哪ҭҭ q    q  q",
      "LҪ朋命哪ҭҭq     q  ",
      "Ҫ 命哪ҭҭҭ         ",
      "   ҭҭҭҭ         ",
      " q   ҭ       q  ",
      "            q   ",
      "         q    q ",
      " q              ",
      "                ",
      "   q            ",
      "                ",
      "                ",
      " q  q          q",
      "            q   ",
      " q      N       "
    ],
    [
      "                ",
      "                ",
      "   哪            ",
      "   ҭҭҭ          ",
      "                ",
      "                ",
      "                ",
      "                ",
      "                ",
      "                ",
      "                ",
      "                ",
      "                ",
      "                ",
      "                ",
      "        N       "
    ],
    [
      "                ",
      "                ",
      "                ",
      "                ",
      "                ",
      "                ",
      "                ",
      "                ",
      "                ",
      "                ",
      "                ",
      "                ",
      "                ",
      "                ",
      "                ",
      "        N       "
    ],
    [
      "                ",
      "                ",
      "                ",
      "                ",
      "                ",
      "                ",
      "                ",
      "                ",
      "                ",
      "                ",
      "                ",
      "                ",
      "                ",
      "                ",
      "                ",
      "        N       "
    ],
    [
      "                ",
      "                ",
      "                ",
      "                ",
      "                ",
      "                ",
      "                ",
      "                ",
      "                ",
      "                ",
      "                ",
      "                ",
      "                ",
      "                ",
      "       版 版      ",
      "      林没跟没空     "
    ]
  ]
}