{
  "xsize": 16,
  "zsize": 16,
  "palette": {
    "palette": [
      {
        "char": " ",
        "block": "minecraft:air"
      },
      {
        "char": "p",
        "block": "minecraft:diorite"
      },
      {
        "char": "f",
        "block": "minecraft:polished_diorite"
      },
      {
        "char": "o",
        "block": "minecraft:quartz_block"
      },
      {
        "char": "e",
        "block": "minecraft:smooth_quartz"
      },
      {
        "char": "h",
        "block": "minecraft:white_stained_glass"
      },
      {
        "char": "z",
        "block": "minecraft:mossy_stone_bricks"
      },
      {
        "char": "D",
        "block": "minecraft:cracked_stone_bricks"
      },
      {
        "char": "E",
        "block": "minecraft:stone_bricks"
      },
      {
        "char": "C",
        "block": "minecraft:mossy_cobblestone"
      },
      {
        "char": "F",
        "block": "minecraft:stone_brick_slab[type=top]"
      },
      {
        "char": "直",
        "block": "minecraft:air"
      },
      {
        "char": "H",
        "block": "minecraft:cobblestone"
      },
      {
        "char": "别",
        "block": "minecraft:mossy_stone_brick_slab[type=top]"
      },
      {
        "char": "x",
        "block": "minecraft:smooth_stone"
      },
      {
        "char": "头",
        "block": "minecraft:rail[shape=south_east]"
      },
      {
        "char": "考",
        "block": "minecraft:rail[shape=south_west]"
      },
      {
        "char": "城",
        "block": "minecraft:rail[shape=north_south]"
      },
      {
        "char": "难",
        "block": "minecraft:rail[shape=north_east]"
      },
      {
        "char": "喜",
        "block": "minecraft:rail[shape=north_west]"
      }
    ]
  },
  "slices": [
    [
      "pfofeeffpeefeffp",
      "hfeoefeeefhhhhhh",
      "heeeopeeoehhhhhh",
      "hfpfffpeeehhhhhh",
      "heepfeeffehhhhhh",
      "hepepfpofehhhhhh",
      "hfeeepefophhhhhh",
      "hpffpeefeehhhhhh",
      "pfooffeoozzzDECz",
      "fehhhhhhhDFF直FFF",
      "efhhhhhhhDFeffef",
      "oehhhhhhhEFeeoep",
      "efhhhhhhhH别offee",
      "pfhhhhhhhE别ffepf",
      "pphhhhhhhHFpfooe",
      "eohhhhhhhzFFoope"
    ],
    [
      "                ",
      "                ",
      "                ",
      "    xx          ",
      "    xx          ",
      "    xx          ",
      "                ",
      "                ",
      "                ",
      "                ",
      "                ",
      "                ",
      "                ",
      "                ",
      "                ",
      "                "
    ],
    [
      "                ",
      "                ",
      "                ",
      "    头考          ",
      "    城城          ",
      "    难喜          ",
      "                ",
      "                ",
      "                ",
      "                ",
      "                ",
      "                ",
      "                ",
      "                ",
      "                ",
      "                "
    ],
    [
      "                ",
      "                ",
      "                ",
      "                ",
      "                ",
      "                ",
      "                ",
      "                ",
      "                ",
      "                ",
      "                ",
      "                ",
      "                ",
      "                ",
      "                ",
      "                "
    ],
    [
      "                ",
      "                ",
      "                ",
      "                ",
      "                ",
      "                ",
      "                ",
      "                ",
      "                ",
      "                ",
      "                ",
      "                ",
      "                ",
      "                ",
      "                ",
      "                "
    ],
    [
      "                ",
      "                ",
      "                ",
      "                ",
      "                ",
      "                ",
      "                ",
      "                ",
      "                ",
      "                ",
      "                ",
      "                ",
      "                ",
      "                ",
      "                ",
      "                "
    ]
  ]
}