{
  "xsize": 16,
  "zsize": 16,
  "palette": {
    "palette": [
      {
        "char": " ",
        "block": "minecraft:air"
      },
      {
        "char": "f",
        "block": "minecraft:polished_diorite"
      },
      {
        "char": "e",
        "block": "minecraft:smooth_quartz"
      },
      {
        "char": "o",
        "block": "minecraft:quartz_block"
      },
      {
        "char": "p",
        "block": "minecraft:diorite"
      },
      {
        "char": "h",
        "block": "minecraft:white_stained_glass"
      },
      {
        "char": "x",
        "block": "minecraft:smooth_stone"
      },
      {
        "char": "头",
        "block": "minecraft:rail[shape=south_east]"
      },
      {
        "char": "考",
        "block": "minecraft:rail[shape=south_west]"
      },
      {
        "char": "城",
        "block": "minecraft:rail[shape=north_south]"
      },
      {
        "char": "难",
        "block": "minecraft:rail[shape=north_east]"
      },
      {
        "char": "喜",
        "block": "minecraft:rail[shape=north_west]"
      }
    ]
  },
  "slices": [
    [
      "ffeffeoopofffpef",
      "heffffeoefhhhhhh",
      "heoopffeeehhhhhh",
      "heoeoeeepphhhhhh",
      "hppeppeeephhhhhh",
      "hofeeepooehhhhhh",
      "heffefeoephhhhhh",
      "hpfoeeofefhhhhhh",
      "offepfpeffeeppof",
      "pehhhhhhhfpeeefe",
      "ofhhhhhhhffpeeof",
      "ffhhhhhhheeeeeee",
      "fphhhhhhhfeefeef",
      "fehhhhhhhfpeppee",
      "ephhhhhhhpeefeeo",
      "efhhhhhhhffefefp"
    ],
    [
      "                ",
      "                ",
      "                ",
      "    xx          ",
      "    xx          ",
      "    xx          ",
      "                ",
      "                ",
      "                ",
      "                ",
      "                ",
      "                ",
      "                ",
      "                ",
      "                ",
      "                "
    ],
    [
      "                ",
      "                ",
      "                ",
      "    头考          ",
      "    城城          ",
      "    难喜          ",
      "                ",
      "                ",
      "                ",
      "                ",
      "                ",
      "                ",
      "                ",
      "                ",
      "                ",
      "                "
    ],
    [
      "                ",
      "                ",
      "                ",
      "                ",
      "                ",
      "                ",
      "                ",
      "                ",
      "                ",
      "                ",
      "                ",
      "                ",
      "                ",
      "                ",
      "                ",
      "                "
    ],
    [
      "                ",
      "                ",
      "                ",
      "                ",
      "                ",
      "                ",
      "                ",
      "                ",
      "                ",
      "                ",
      "                ",
      "                ",
      "                ",
      "                ",
      "                ",
      "                "
    ],
    [
      "                ",
      "                ",
      "                ",
      "                ",
      "                ",
      "                ",
      "                ",
      "                ",
      "                ",
      "                ",
      "                ",
      "                ",
      "                ",
      "                ",
      "                ",
      "                "
    ]
  ]
}