{
  "xsize": 16,
  "zsize": 16,
  "palette": {
    "palette": [
      {
        "char": " ",
        "block": "minecraft:air"
      },
      {
        "char": "c",
        "block": "minecraft:cobbled_deepslate"
      },
      {
        "char": "k",
        "block": "minecraft:blackstone"
      },
      {
        "char": "b",
        "block": "minecraft:basalt[axis=x]"
      },
      {
        "char": "d",
        "block": "minecraft:deepslate[axis=y]"
      },
      {
        "char": "a",
        "block": "minecraft:cyan_terracotta"
      },
      {
        "char": "s",
        "block": "minecraft:yellow_concrete"
      },
      {
        "char": "r",
        "block": "minecraft:grass_block[snowy=false]"
      },
      {
        "char": "J",
        "block": "minecraft:yellow_terracotta"
      },
      {
        "char": "开",
        "block": "minecraft:spawner",
        "tag": {
          "SpawnData": {
            "entity": {}
          },
          "MaxNearbyEntities": "6s",
          "MinSpawnDelay": "200s",
          "z": 387,
          "x": 24,
          "MaxSpawnDelay": "800s",
          "RequiredPlayerRange": "16s",
          "SpawnCount": "4s",
          "ForgeCaps": {},
          "id": "minecraft:mob_spawner",
          "SpawnPotentials": [],
          "y": 132,
          "SpawnRange": "4s",
          "Delay": "584s"
        }
      },
      {
        "char": "I",
        "block": "minecraft:dirt"
      },
      {
        "char": "多",
        "block": "minecraft:quartz_slab[type=bottom]"
      },
      {
        "char": "q",
        "block": "minecraft:air"
      },
      {
        "char": "动",
        "block": "minecraft:air"
      },
      {
        "char": "水",
        "block": "minecraft:air"
      },
      {
        "char": "园",
        "block": "minecraft:air"
      },
      {
        "char": "博",
        "block": "minecraft:air"
      },
      {
        "char": "u",
        "block": "minecraft:smooth_quartz_slab[type=bottom]"
      },
      {
        "char": "与",
        "block": "minecraft:oak_log[axis=y]"
      },
      {
        "char": "千",
        "block": "minecraft:rose_bush[half=lower]"
      },
      {
        "char": "N",
        "block": "minecraft:cobblestone_wall[up=true]"
      },
      {
        "char": "龙",
        "block": "minecraft:air"
      },
      {
        "char": "杀",
        "block": "minecraft:rose_bush[half=upper]"
      },
      {
        "char": "Ҫ",
        "block": "minecraft:oak_leaves"
      },
      {
        "char": "L",
        "block": "minecraft:oak_leaves"
      },
      {
        "char": "问",
        "block": "minecraft:oak_leaves"
      },
      {
        "char": "比",
        "block": "minecraft:oak_leaves"
      },
      {
        "char": "度",
        "block": "minecraft:oak_trapdoor[facing=south,half=top,open=true]"
      },
      {
        "char": "版",
        "block": "minecraft:oak_trapdoor[facing=north,half=top,open=true]"
      },
      {
        "char": "林",
        "block": "minecraft:oak_trapdoor[facing=west,half=top,open=true]"
      },
      {
        "char": "没",
        "block": "minecraft:redstone_lamp[lit=false]"
      },
      {
        "char": "跟",
        "block": "minecraft:cobblestone_wall[east=low,up=true,west=low]"
      },
      {
        "char": "空",
        "block": "minecraft:oak_trapdoor[facing=east,half=top,open=true]"
      }
    ]
  },
  "slices": [
    [
      "cckcbdbaasbrrrcc",
      "brdbadadkJkrrrab",
      "baakdadbbsarrr开c",
      "dcksssJssJarrrcd",
      "cbckkradksbrrrkd",
      "acbcrbaabJbrIrak",
      "rkddacckbsbrrrca",
      "rbbsssssssarrrbb",
      "kkakdaacasbrrrbc",
      "dkaaackakscrrrad",
      "dbbadbcdcsarrr开b",
      "cbdJsssssJdrrrak",
      "bcdrddaccJarrrad",
      "bkckkradbscrrrbb",
      "kkbacrkkbsbrrraa",
      "dccsssssss开rIrab"
    ],
    [
      "          多qqq多 ",
      " q        多qqq多 ",
      "          多q动动多 ",
      "q         多水园动多 ",
      "          多q博水多 ",
      "    q  q  u水与q多 ",
      "q         多qqq多 ",
      "q         多q水水多 ",
      "          多qqq多 ",
      "          多qq动多 ",
      "         q多千qq多 ",
      "         N多qqq多 ",
      "   q      多q动q多 ",
      "     q    多qqq多 ",
      "     q    多qqq多 ",
      "          多水与qu "
    ],
    [
      "                ",
      "                ",
      "            龙龙  ",
      "             龙  ",
      "                ",
      "            与   ",
      "                ",
      "                ",
      "                ",
      "             龙  ",
      "           杀    ",
      "         N      ",
      "            龙   ",
      "           ҪLҪ  ",
      "          ҪL问LҪ ",
      "          L问与问L "
    ],
    [
      "                ",
      "                ",
      "                ",
      "                ",
      "                ",
      "            与   ",
      "                ",
      "                ",
      "                ",
      "                ",
      "                ",
      "         N      ",
      "                ",
      "          比ҪLҪ比 ",
      "          ҪL问LҪ ",
      "          L问与问L "
    ],
    [
      "                ",
      "                ",
      "                ",
      "           ҪLҪ比 ",
      "          ҪL问LҪ ",
      "          L问与问L ",
      "          ҪL问LҪ ",
      "           ҪLҪ  ",
      "                ",
      "                ",
      "                ",
      "         N      ",
      "                ",
      "                ",
      "           L问   ",
      "           问与问  "
    ],
    [
      "        度 度     ",
      "                ",
      "                ",
      "           ҪLҪ  ",
      "          ҪL问LҪ ",
      "          L问与问L ",
      "          ҪL问LҪ ",
      "           ҪLҪ  ",
      "                ",
      "                ",
      "        版 版     ",
      "       林没跟没空    ",
      "        度 度     ",
      "                ",
      "            L   ",
      "           L问L  "
    ]
  ]
}