{
  "name": "multi_nuclearpowerplant_31_base10",
  "refpalette": "deceasedcraft:multi_nuclearpowerplant_31/multi_nuclearpowerplant_31_base10_palette",
  "xsize": 16,
  "zsize": 16,
  "slices": [
    [
      "           abc  ",
      "           abc  ",
      "          dabe  ",
      "        fgfabc  ",
      "        gfgabc  ",
      "        fgfabc  ",
      "           abc  ",
      "           abc  ",
      "           abc  ",
      "           abc  ",
      "        fgfabc  ",
      "        gfgabc  ",
      "        fgfabc  ",
      "          dabe  ",
      "           abc  ",
      "           abc  "
    ],
    [
      "           ah   ",
      "           ah   ",
      "          iahjk ",
      "        fgfah   ",
      "        gfgah   ",
      "        fgfah   ",
      "           ah   ",
      "           ah   ",
      "           ah   ",
      "           ah   ",
      "        fgfah   ",
      "        gfgah   ",
      "        fgfah   ",
      "          iahjk ",
      "           ah   ",
      "           ah   "
    ],
    [
      "           ah   ",
      "           ah   ",
      "           ahj  ",
      "        lmlah   ",
      "        mlmah   ",
      "        lmlah   ",
      "           ah   ",
      "           ah   ",
      "           ah   ",
      "           ah   ",
      "        lmlah   ",
      "        mlmah   ",
      "        lmlah   ",
      "           ahj  ",
      "           ah   ",
      "           ah   "
    ],
    [
      "           ah   ",
      "           ah   ",
      "           ahj  ",
      "         n ah   ",
      "        opqah   ",
      "         r ah   ",
      "           ah   ",
      "           ah   ",
      "           ah   ",
      "           ah   ",
      "         n ah   ",
      "        opqah   ",
      "         r ah   ",
      "           ahj  ",
      "           ah   ",
      "           ah   "
    ],
    [
      "           ah   ",
      "           ah   ",
      "           ahj  ",
      "           ah   ",
      "           ah   ",
      "           ah   ",
      "           ah   ",
      "           ah   ",
      "           ah   ",
      "           ah   ",
      "           ah   ",
      "           ah   ",
      "           ah   ",
      "           ahj  ",
      "           ah   ",
      "           ah   "
    ],
    [
      "           ah   ",
      "           ah   ",
      "           ahj  ",
      "           ah   ",
      "           ah   ",
      "           ah   ",
      "           ah   ",
      "           ah   ",
      "           ah   ",
      "           ah   ",
      "           ah   ",
      "           ah   ",
      "           ah   ",
      "           ahj  ",
      "           ah   ",
      "           ah   "
    ]
  ]
}