{
  "name": "multi_nuclearpowerplant_31_base6",
  "refpalette": "deceasedcraft:multi_nuclearpowerplant_31/multi_nuclearpowerplant_31_base6_palette",
  "xsize": 16,
  "zsize": 16,
  "slices": [
    [
      "abcd   efg    g ",
      "abc    hf       ",
      "abc    df    !  ",
      "abc     ifff   f",
      "abc         d jj",
      "abcccccccccccccc",
      "abbbbbbbbbbbbbbb",
      "akkkkkkkkkkkkkkk",
      "akkkkkkkkkkkkkkk",
      "alllllllllllllll",
      "alcccccccccccccc",
      "alc         d mm",
      "alc     ifffffff",
      "alc    df       ",
      "alc    nf       ",
      "alcd   efggggggg"
    ],
    [
      "  odpqrrstt  ttt",
      "  ou   wfg    gg",
      "  o   xyfg      ",
      "  o    Aiffff ff",
      "  o    B kkkdCjj",
      "  oooooooooooooo",
      "                ",
      "                ",
      "                ",
      "                ",
      "  oooooooooooooo",
      "  o    D kkkdEmm",
      "  o    Fifffffff",
      "  o   Iyfggggggg",
      "  oC   Jfggggggg",
      "  odKLMMsttttttt"
    ],
    [
      "  Nd   Ofg    gg",
      "  N    Pf       ",
      "  N    df       ",
      "  N     ifffffff",
      "  N      QRNd jj",
      "   SSSSSS    SSS",
      "                ",
      "                ",
      "                ",
      "                ",
      "   TTTTTT   TTTT",
      "  N      QUNd mm",
      "  N     ifffffff",
      "  N    df       ",
      "  N    Vf       ",
      "  Nd   Ofggggggg"
    ],
    [
      "   d   Wf       ",
      "       df       ",
      "        f       ",
      "        if fffff",
      "            d jj",
      "                ",
      "                ",
      "                ",
      "                ",
      "                ",
      "                ",
      "            d mm",
      "        if fffff",
      "        f       ",
      "       df       ",
      "   d   dfggggggg"
    ],
    [
      "   d    Xf     f",
      "        Xf f  ff",
      "        ifffffff",
      "        iiiiiiii",
      "            d jj",
      "                ",
      "                ",
      "                ",
      "                ",
      "                ",
      "                ",
      "            d mm",
      "        iiiiiiii",
      "        ifffffff",
      "        ifffffff",
      "   d    ifffffff"
    ],
    [
      "   d           k",
      "            Y kk",
      "            Y kk",
      "           Zydnn",
      "            d   ",
      "                ",
      "                ",
      "                ",
      "                ",
      "                ",
      "                ",
      "            d   ",
      "           0ydhh",
      "            Y kk",
      "            Y kk",
      "   d        Y kk"
    ]
  ]
}