{
  "name": "multi_nuclearpowerplant_31_base11",
  "refpalette": "deceasedcraft:multi_nuclearpowerplant_31/multi_nuclearpowerplant_31_base11_palette",
  "xsize": 16,
  "zsize": 16,
  "slices": [
    [
      "a      aaaa@bcdd",
      "ceeeeeecccccbcdd",
      "c      cccccfgdd",
      "            hddd",
      "            hddd",
      "            hddd",
      "            hddd",
      "            hddd",
      "            hddd",
      "            hddd",
      "            hddd",
      "            hddd",
      "            hddd",
      "c      cccccigdd",
      "ceeeeeecccccjcdd",
      "k      kkkk@jcdd"
    ],
    [
      "a      aaaa@bcdd",
      "ceeeeeecccccbcdd",
      "c      cccccfgdd",
      "            hddd",
      "            hddd",
      "            hddd",
      "            hddd",
      "            hddd",
      "            hddd",
      "            hddd",
      "            hddd",
      "            hddd",
      "            hddd",
      "c      cccccigdd",
      "ceeeeeecccccjcdd",
      "k      kkkk@jcdd"
    ],
    [
      "a      aaaa@lcdd",
      "ceeeeeeccccclcdd",
      "mnnnnnnmcccclgdd",
      "c      ccccclcdd",
      "c      cc cclcdd",
      "c      ccccclcdd",
      "c      ccccclcdd",
      "c      ccccclcdd",
      "c      ccccclcdd",
      "c      ccccclcdd",
      "c      ccccclcdd",
      "c      cc cclcdd",
      "c      ccccclcdd",
      "mnnnnnnmcccclgdd",
      "ceeeeeeccccclcdd",
      "k      kkkk@lcdd"
    ],
    [
      "           opcdd",
      "c      cccccqcdd",
      "ceeeeeecccccrgdd",
      "ceeeeeecstscpcdd",
      "ceeeeeectstcpcdd",
      "cuuuuuucstscpcdd",
      "ceeeeeecccccpcdd",
      "ceeeeeecccccpcdd",
      "ceeeeeecccccpcdd",
      "ceeeeeecccccpcdd",
      "cuuuuuucstscpcdd",
      "ceeeeeectstcpcdd",
      "ceeeeeecstscpcdd",
      "ceeeeeecccccrgdd",
      "c      cccccqcdd",
      "           opcdd"
    ],
    [
      "           o cdd",
      "           o cdd",
      "w      wwwwo gdd",
      "w      wxyxo cdd",
      "w      wyxyo cdd",
      "w      wxyxo cdd",
      "w      wwwwo cdd",
      "w      wwwwo cdd",
      "w      wwwwo cdd",
      "w      wwwwo cdd",
      "w      wxyxo cdd",
      "w      wyxyo cdd",
      "w      wxyxo cdd",
      "w      wwwwo gdd",
      "           o cdd",
      "           o cdd"
    ],
    [
      "           olcdd",
      "           olcdd",
      "          Aolgdd",
      "        xyxolcdd",
      "        yxyolcdd",
      "        xyxolcdd",
      "           olcdd",
      "           olcdd",
      "           olcdd",
      "           olcdd",
      "        xyxolcdd",
      "        yxyolcdd",
      "        xyxolcdd",
      "          Aolgdd",
      "           olcdd",
      "           olcdd"
    ]
  ]
}