{
  "name": "multi_nuclearpowerplant_31_base2",
  "refpalette": "deceasedcraft:multi_nuclearpowerplant_31/multi_nuclearpowerplant_31_base2_palette",
  "xsize": 16,
  "zsize": 16,
  "slices": [
    [
      "   ab           ",
      "    b           ",
      "    b           ",
      "    b           ",
      "    b           ",
      "    b           ",
      "    b           ",
      "    b           ",
      "    b           ",
      "    b           ",
      "    b           ",
      "    b           ",
      "    b           ",
      "    b           ",
      "    b           ",
      "   ab           "
    ],
    [
      "   ab           ",
      "    b           ",
      "    b           ",
      "    b           ",
      "    b           ",
      "    b           ",
      "    b           ",
      "    b           ",
      "    b           ",
      "    b           ",
      "    b           ",
      "    b           ",
      "    b           ",
      "    b           ",
      "    b           ",
      "   ab           "
    ],
    [
      "   ab           ",
      "    b           ",
      "    b           ",
      "    b           ",
      "    b           ",
      "    b           ",
      "    b           ",
      "    b           ",
      "    b           ",
      "    b           ",
      "    b           ",
      "    b           ",
      "    b           ",
      "    b           ",
      "    b           ",
      "   ab           "
    ],
    [
      "   ab           ",
      "    b           ",
      "    b           ",
      "    b           ",
      "    b           ",
      "    b           ",
      "    b           ",
      "    b           ",
      "    b           ",
      "    b           ",
      "    b           ",
      "    b           ",
      "    b           ",
      "    b           ",
      "    b           ",
      "   ab           "
    ],
    [
      "  ccd           ",
      "   cd           ",
      "   cd           ",
      "   cd           ",
      "   cd           ",
      "   cd           ",
      "   cd           ",
      "   cd           ",
      "   cd           ",
      "   cd           ",
      "   cd           ",
      "   cd           ",
      "   cd           ",
      "   cd           ",
      "   cd           ",
      "  ccd           "
    ],
    [
      "eeccfffgggfffffg",
      "eeecffffffffffff",
      "eeecffffffffffff",
      "eeecfhi         ",
      "eeecfhi         ",
      "eeecfhi         ",
      "eeecfhi         ",
      "eeecfhi         ",
      "eeecfhi         ",
      "eeecfhi         ",
      "eeecfhi         ",
      "eeecfhi         ",
      "eeecfhi         ",
      "eeecffffffffffff",
      "eeecffffffffffff",
      "eeccfffgggfffffg"
    ]
  ]
}