{
  "name": "multi_nuclearpowerplant_31_base9",
  "refpalette": "deceasedcraft:multi_nuclearpowerplant_31/multi_nuclearpowerplant_31_base9_palette",
  "xsize": 16,
  "zsize": 16,
  "slices": [
    [
      "           ab   ",
      "           ab   ",
      "           abc  ",
      "           ab   ",
      "           ab   ",
      "           ab   ",
      "           ab   ",
      "           ab   ",
      "           ab   ",
      "           ab   ",
      "           ab   ",
      "           ab   ",
      "           ab   ",
      "           abc  ",
      "           ab   ",
      "           ab   "
    ],
    [
      "           ab   ",
      "           ab   ",
      "           abc  ",
      "           ab   ",
      "           ab   ",
      "           ab   ",
      "           ab   ",
      "           ab   ",
      "           ab   ",
      "           ab   ",
      "           ab   ",
      "           ab   ",
      "           ab   ",
      "           abc  ",
      "           ab   ",
      "           ab   "
    ],
    [
      "           ab   ",
      "           ab   ",
      "           abc  ",
      "           ab   ",
      "           ab   ",
      "           ab   ",
      "           ab   ",
      "           ab   ",
      "           ab   ",
      "           ab   ",
      "           ab   ",
      "           ab   ",
      "           ab   ",
      "           abc  ",
      "           ab   ",
      "           ab   "
    ],
    [
      "           ab   ",
      "           ab   ",
      "           abcde",
      "           ab   ",
      "           ab   ",
      "           ab   ",
      "           ab   ",
      "           ab   ",
      "           ab   ",
      "           ab   ",
      "           ab   ",
      "           ab   ",
      "           ab   ",
      "           abcde",
      "           ab   ",
      "           ab   "
    ],
    [
      "           ab   ",
      "           ab   ",
      "           abccc",
      "           ab   ",
      "           ab   ",
      "           ab   ",
      "           ab   ",
      "           ab   ",
      "           ab   ",
      "           ab   ",
      "           ab   ",
      "           ab   ",
      "           ab   ",
      "           abccc",
      "           ab   ",
      "           ab   "
    ],
    [
      "           ab   ",
      "           ab   ",
      "           abcf ",
      "           ab   ",
      "           ab   ",
      "           ab   ",
      "           ab   ",
      "           ab   ",
      "           ab   ",
      "           ab   ",
      "           ab   ",
      "           ab   ",
      "           ab   ",
      "           abcf ",
      "           ab   ",
      "           ab   "
    ]
  ]
}