{
  "name": "multi_nuclearpowerplant_31_base7",
  "refpalette": "deceasedcraft:multi_nuclearpowerplant_31/multi_nuclearpowerplant_31_base7_palette",
  "xsize": 16,
  "zsize": 16,
  "slices": [
    [
      "   a     bcd    ",
      "         efg    ",
      "        heee    ",
      "                ",
      "       a    a ii",
      "                ",
      "                ",
      "                ",
      "                ",
      "                ",
      "                ",
      "       a    a jj",
      "                ",
      "        keee    ",
      "         eee    ",
      "   a     eee    "
    ],
    [
      "   a    le m    ",
      "         b n    ",
      "         eog    ",
      "                ",
      "       a    a ii",
      "                ",
      "                ",
      "                ",
      "                ",
      "                ",
      "                ",
      "       a    a jj",
      "                ",
      "         epe    ",
      "          qe    ",
      "   a    leqprsss"
    ],
    [
      "   a     b      ",
      "         ng     ",
      "         gg     ",
      "       t    t   ",
      "       a    a ii",
      "                ",
      "                ",
      "                ",
      "                ",
      "                ",
      "                ",
      "       a    a jj",
      "       u    u   ",
      "         eee    ",
      "         eee    ",
      "   a     eee    "
    ],
    [
      "   a   a    a   ",
      "       a    a   ",
      "       a    a   ",
      "       aaaaaaaaa",
      "       a    a ii",
      "            w   ",
      "                ",
      "                ",
      "                ",
      "                ",
      "            x   ",
      "       a    a jj",
      "       aaaaaaaaa",
      "       a    a   ",
      "       a    a   ",
      "   a   a    a   "
    ],
    [
      "   a    yb bAbyy",
      "        yA bAyAy",
      "        yybAAyyy",
      "        ynnnyyyy",
      "            a ii",
      "                ",
      "                ",
      "                ",
      "                ",
      "                ",
      "                ",
      "            a jj",
      "        yyyyyyyy",
      "        yyyyyyyy",
      "        yyyyyyyy",
      "   a    yyyyyyyy"
    ],
    [
      "B  a   aC       ",
      "B      aC       ",
      "B       C    D  ",
      "B       yCECC  C",
      "B           a ii",
      "B               ",
      "B               ",
      "B               ",
      "B               ",
      "B               ",
      "B               ",
      "B           a jj",
      "B       yCECCCCC",
      "B       C       ",
      "B      aC       ",
      "B  a   aCFFFFFFF"
    ]
  ]
}