{
  "name": "multi_nuclearpowerplant_31_base4",
  "refpalette": "deceasedcraft:multi_nuclearpowerplant_31/multi_nuclearpowerplant_31_base4_palette",
  "xsize": 16,
  "zsize": 16,
  "slices": [
    [
      "   a      b     ",
      "          b     ",
      "          b     ",
      "          b     ",
      "          b     ",
      "bbbbbbbbbbb     ",
      "                ",
      "                ",
      "                ",
      "                ",
      "bbbbbbbbbbb     ",
      "          b     ",
      "          b     ",
      "          b     ",
      "          b     ",
      "   a      b     "
    ],
    [
      "   a     cde    ",
      "         cde    ",
      "         cde    ",
      "         cde    ",
      "fffffffffgde    ",
      "ddddddddddde    ",
      "hhhhhhhhhhhi    ",
      "                ",
      "                ",
      "fffffffffffj    ",
      "ddddddddddde    ",
      "hhhhhhhhhgde    ",
      "         cde    ",
      "         cde    ",
      "         cde    ",
      "   a     cde    "
    ],
    [
      "   a      k     ",
      "          k     ",
      "          k     ",
      "          k     ",
      "         lk     ",
      "kkkkkkkkkkk     ",
      "           i    ",
      "                ",
      "                ",
      "           j    ",
      "kkkkkkkkkkk     ",
      "         mk     ",
      "          k     ",
      "          k     ",
      "          k     ",
      "   a      k     "
    ],
    [
      "   a            ",
      "                ",
      "                ",
      "                ",
      "         l      ",
      "                ",
      "           i    ",
      "                ",
      "                ",
      "           j    ",
      "                ",
      "         m      ",
      "                ",
      "                ",
      "                ",
      "   a            "
    ],
    [
      "   a            ",
      "                ",
      "                ",
      "                ",
      "         l      ",
      "                ",
      "           i    ",
      "                ",
      "                ",
      "           j    ",
      "                ",
      "         m      ",
      "                ",
      "                ",
      "                ",
      "   a            "
    ],
    [
      "  na            ",
      "   n            ",
      "   n            ",
      "   n            ",
      "   n     l      ",
      "   n            ",
      "   n       i    ",
      "   n            ",
      "   n            ",
      "   n       j    ",
      "   n            ",
      "   n     m      ",
      "   n            ",
      "   n            ",
      "   n            ",
      "  na            "
    ]
  ]
}