{
  "name": "multi_nuclearpowerplant_31_base12",
  "refpalette": "deceasedcraft:multi_nuclearpowerplant_31/multi_nuclearpowerplant_31_base12_palette",
  "xsize": 16,
  "zsize": 16,
  "slices": [
    [
      "aaaaaaaaaaaaaaaa",
      "aaaaaaaaaaaaaaaa",
      "aaaaaaaaaaaaaaaa",
      "aaaaaaaaaaaaaaaa",
      "aaaaaaaaaaaaaaaa",
      "aaaaaaaaaaaaaaaa",
      "aaaaaaaaaaaaaaaa",
      "aaaaaaaaaaaaaaaa",
      "aaaaaaaaaaaaaaaa",
      "aaaaaaaaaaaaaaaa",
      "aaaaaaaaaaaaaaaa",
      "aaaaaaaaaaaaaaaa",
      "aaaaaaaaaaaaaaaa",
      "aaaaaaaaaaaaaaaa",
      "aaaaaaaaaaaaaaaa",
      "aaaaaaaaaaaaaaaa"
    ],
    [
      "bbbbbbbbbbbbbbbb",
      "bbbbbbbbbbbbbbbb",
      "bbbbbbbbbbbbbbbb",
      "bbbbbbbbbbbbbbbb",
      "bbbbbbbbbbbbbbbb",
      "bbbbbbbbbbbbbbbb",
      "bbbbbbbbbbbbbbbb",
      "bbbbbbbbbbbbbbbb",
      "bbbbbbbbbbbbbbbb",
      "bbbbbbbbbbbbbbbb",
      "bbbbbbbbbbbbbbbb",
      "bbbbbbbbbbbbbbbb",
      "bbbbbbbbbbbbbbbb",
      "bbbbbbbbbbbbbbbb",
      "bbbbbbbbbbbbbbbb",
      "bbbbbbbbbbbbbbbb"
    ],
    [
      "ccccccccccc d===",
      "bbbbbbbbbbbbd===",
      "bbbbbbbbbbbbd===",
      "bbbbbbbbbbbbd===",
      "bbbbbbbbbbbbd===",
      "bbbbbbbbbbbbd===",
      "bbbbbbbbbbbbd===",
      "bbbbbbbbbbbbd===",
      "bbbbbbbbbbbbd===",
      "bbbbbbbbbbbbd===",
      "bbbbbbbbbbbbd===",
      "bbbbbbbbbbbbd===",
      "bbbbbbbbbbbbd===",
      "bbbbbbbbbbbbd===",
      "bbbbbbbbbbbbd===",
      "eeeeeeeeeee d==="
    ],
    [
      "fggggggffff@hbii",
      "bhhhhhhbbbbbhbii",
      "bjjjjjjbbbbbhbii",
      "kkkkkkkkkkkkhlii",
      "kkkkkkkkkkkkhlii",
      "kkkkkkkkkkkkhlii",
      "kkkkkkkkkkkkhlii",
      "kkkkkkkkkkkkhlii",
      "kkkkkkkkkkkkhmii",
      "kkkkkkkkkkkkhmii",
      "kkkkkkkkkkkkhmii",
      "kkkkkkkkkkkkhmii",
      "kkkkkkkkkkkkhmii",
      "bjjjjjjbbbbbhbii",
      "bhhhhhhbbbbbhbii",
      "noooooonnnn@hbii"
    ],
    [
      "f      ffff@pbqq",
      "brrrrrrbbbbbpbqq",
      "bs     bbbbbtuqq",
      "            wqqq",
      "            wqqq",
      "            wqqq",
      "            wqqq",
      "            wqqq",
      "            wqqq",
      "            wqqq",
      "            wqqq",
      "            wqqq",
      "            wqqq",
      "b     xbbbbbyuqq",
      "brrrrrrbbbbbAbqq",
      "n      nnnn@Abqq"
    ],
    [
      "f      ffff@pbqq",
      "bBBBBBBbbbbbpbqq",
      "bC     bbbbbtuqq",
      "            wqqq",
      "            wqqq",
      "            wqqq",
      "            wqqq",
      "            wqqq",
      "            wqqq",
      "            wqqq",
      "            wqqq",
      "            wqqq",
      "            wqqq",
      "b     Cbbbbbyuqq",
      "bBBBBBBbbbbbAbqq",
      "n      nnnn@Abqq"
    ]
  ]
}