{
  "name": "multi_nuclearpowerplant_31_base1",
  "refpalette": "deceasedcraft:multi_nuclearpowerplant_31/multi_nuclearpowerplant_31_base1_palette",
  "xsize": 16,
  "zsize": 16,
  "slices": [
    [
      "aaabbbbbbbbbbbbb",
      "aaabbbbbbbbbbbbb",
      "aaabbbbccccccccc",
      "aaabbbbcde      ",
      "aaabbbbcde      ",
      "aaabbbbcde      ",
      "aaabbbbcde      ",
      "aaabbbbcde      ",
      "aaabbbbcde      ",
      "aaabbbbcde      ",
      "aaabbbbcde      ",
      "aaabbbbcde      ",
      "aaabbbbcde      ",
      "aaabbbbccccccccc",
      "aaabbbbbbbbbbbbb",
      "aaabbbbbbbbbbbbb"
    ],
    [
      "   fgabbbbbbbbbb",
      "   fgabbbbbbbbbb",
      "   fgabbbbcccccc",
      "   fgabbbbcde   ",
      "   fgabbbbcde   ",
      "   fgabbbbcde   ",
      "   fgabbbbcde   ",
      "   fgabbbbcde   ",
      "   fgabbbbcde   ",
      "   fgabbbbcde   ",
      "   fgabbbbcde   ",
      "   fgabbbbcde   ",
      "   fgabbbbcde   ",
      "   fgabbbbcccccc",
      "   fgabbbbbbbbbb",
      "   fgabbbbbbbbbb"
    ],
    [
      "      fgabbbbbbb",
      "      fgabbbbbbb",
      "      fgabbbbccc",
      "      fgabbbbcde",
      "      fgabbbbcde",
      "      fgabbbbcde",
      "      fgabbbbcde",
      "      fgabbbbcde",
      "      fgabbbbcde",
      "      fgabbbbcde",
      "      fgabbbbcde",
      "      fgabbbbcde",
      "      fgabbbbcde",
      "      fgabbbbccc",
      "      fgabbbbbbb",
      "      fgabbbbbbb"
    ],
    [
      "         fgabbbb",
      "         fgabbbb",
      "         fgabbbb",
      "         fgabbbb",
      "         fgabbbb",
      "         fgabbbb",
      "         fgabbbb",
      "         fgabbbb",
      "         fgabbbb",
      "         fgabbbb",
      "         fgabbbb",
      "         fgabbbb",
      "         fgabbbb",
      "         fgabbbb",
      "         fgabbbb",
      "         fgabbbb"
    ],
    [
      "            fgab",
      "            fgab",
      "            fgab",
      "            fgab",
      "            fgab",
      "            fgab",
      "            fgab",
      "            fgab",
      "            fgab",
      "            fgab",
      "            fgab",
      "            fgab",
      "            fgab",
      "            fgab",
      "            fgab",
      "            fgab"
    ],
    [
      "               f",
      "               f",
      "               f",
      "               f",
      "               f",
      "               f",
      "               f",
      "               f",
      "               f",
      "               f",
      "               f",
      "               f",
      "               f",
      "               f",
      "               f",
      "               f"
    ]
  ]
}