{
  "name": "multi_nuclearpowerplant_31_base3",
  "refpalette": "deceasedcraft:multi_nuclearpowerplant_31/multi_nuclearpowerplant_31_base3_palette",
  "xsize": 16,
  "zsize": 16,
  "slices": [
    [
      "  abcddddddddddd",
      "   acddddddddddd",
      "   acddddddddddd",
      "   acddddddddddd",
      "   acddddddddddd",
      "   acddddddddddd",
      "   acddddddddddd",
      "   acddddddddddd",
      "   acddddddddddd",
      "   acddddddddddd",
      "   acddddddddddd",
      "   acddddddddddd",
      "   acddddddddddd",
      "   acddddddddddd",
      "   acddddddddddd",
      "  abcddddddddddd"
    ],
    [
      "   ef  ggggggggg",
      "    f   hiijjjji",
      "    f         kl",
      "    f          m",
      "    f       n   ",
      "    f   o n   o ",
      "    f  pqqqqqqqq",
      "    f  prrrrrrrr",
      "    f  pr!rrrrrr",
      "    f  pqqqqqqqq",
      "    f       s s ",
      "    f   s s     ",
      "    f           ",
      "    f           ",
      "    f   hiijjjji",
      "   ef  ggggggggg"
    ],
    [
      "   ef  ttttttttt",
      "    f   hhhhhhhh",
      "    f    uuu    ",
      "    f           ",
      "    f           ",
      "    f           ",
      "    f  wxwyAxwyw",
      "    f           ",
      "    f           ",
      "    f   xBxCyCyC",
      "    f           ",
      "    f           ",
      "    f           ",
      "    f    DDD    ",
      "    f   hhhhhhhh",
      "   ef  ttttttttt"
    ],
    [
      "   ef  ttttttttt",
      "    f   hhhhhhhh",
      "    f        uuu",
      "    f           ",
      "    f           ",
      "    f           ",
      "    f           ",
      "    f           ",
      "    f           ",
      "    f           ",
      "    f           ",
      "    f           ",
      "    f           ",
      "    f        DDD",
      "    f   hhhhhhhh",
      "   ef  ttttttttt"
    ],
    [
      "   ef  EEEEEEEEE",
      "    f   FFFFFFFF",
      "    f           ",
      "    f           ",
      "    f           ",
      "    f           ",
      "    f           ",
      "    f           ",
      "    f           ",
      "    f           ",
      "    f           ",
      "    f           ",
      "    f           ",
      "    f           ",
      "    f   FFFFFFFF",
      "   ef  EEEEEEEEE"
    ],
    [
      "   ef           ",
      "    f           ",
      "    f           ",
      "    f           ",
      "    f           ",
      "    f           ",
      "    f           ",
      "    f           ",
      "    f           ",
      "    f           ",
      "    f           ",
      "    f           ",
      "    f           ",
      "    f           ",
      "    f           ",
      "   ef           "
    ]
  ]
}