{
  "name": "multi_nuclearpowerplant_31_base8",
  "refpalette": "deceasedcraft:multi_nuclearpowerplant_31/multi_nuclearpowerplant_31_base8_palette",
  "xsize": 16,
  "zsize": 16,
  "slices": [
    [
      "aaaaaaaaab cd   ",
      "aaaaaaaaab cd   ",
      "aaaaaaaaab cde  ",
      "aaaaaaaaab cd   ",
      "aaaaaaaaab cd   ",
      "aaaaaaaaab cd   ",
      "aaaaaaaaab cd   ",
      "aaaaaaaaab cd   ",
      "aaaaaaaaab cd   ",
      "aaaaaaaaab cd   ",
      "aaaaaaaaab cd   ",
      "aaaaaaaaab cd   ",
      "aaaaaaaaab cd   ",
      "aaaaaaaaab cde  ",
      "aaaaaaaaab cd   ",
      "aaaaaaaaab cd   "
    ],
    [
      "=========fgfhiii",
      "=========fgfhiii",
      "=========fgfhjii",
      "=========fgfhiii",
      "=========fgfhiii",
      "=========fgfhiii",
      "ffffffffffgfhiii",
      "ffffffffffgfhiii",
      "ffffffffffgfhiii",
      "ffffffffffgfhiii",
      "=========fgfhiii",
      "=========fgfhiii",
      "=========fgfhiii",
      "=========fgfhjii",
      "=========fgfhiii",
      "=========fgfhiii"
    ],
    [
      "kkkkkkkkkflfdkkk",
      "kkkkkkkkkflfdkkk",
      "kkkkkkkkkflfdkkk",
      "kkkkkkkkkflfdkkk",
      "kkkkkkkkkflfdkkk",
      "kkkkkkkkkflfdkkk",
      "fffffffffflfdkkk",
      "lllllllllllfdkkk",
      "lllllllllllfdkkk",
      "fffffffffflfdkkk",
      "kkkkkkkkkflfdkkk",
      "kkkkkkkkkflfdkkk",
      "kkkkkkkkkflfdkkk",
      "kkkkkkkkkflfdkkk",
      "kkkkkkkkkflfdkkk",
      "kkkkkkkkkflfdkkk"
    ],
    [
      "kkkkkkkkkfffdkkk",
      "kkkkkkkkkfffdkkk",
      "kkkkkkkkkfffdkkk",
      "kkkkkkkkkfffdkkk",
      "kkkkkkkkkfffdkkk",
      "kkkkkkkkkfffdkkk",
      "ffffffffffffdkkk",
      "ffffffffffffdkkk",
      "ffffffffffffdkkk",
      "ffffffffffffdkkk",
      "kkkkkkkkkfffdkkk",
      "kkkkkkkkkfffdkkk",
      "kkkkkkkkkfffdkkk",
      "kkkkkkkkkfffdkkk",
      "kkkkkkkkkfffdkkk",
      "kkkkkkkkkfffdkkk"
    ],
    [
      "hhhjhhmn========",
      "hhhhhhmn========",
      "hhhhhhmn========",
      "hhhhhhmn========",
      "hhhhhhmjoooojooo",
      "hhhhhhmmmmmmmmmm",
      "hhhhhhhhhhhhhhhh",
      "hhhhhhhhhhhhhhhh",
      "hhhhhhhhhhhhhhhh",
      "hhhhhhhhhhhhhhhh",
      "hhhhhhmmmmmmmmmm",
      "hhhhhhmjoooojooo",
      "hhhhhhmn========",
      "hhhhhhmn========",
      "hhhhhhmn========",
      "hhhjhhmn========"
    ],
    [
      "   e   pqrrs    ",
      "       pqsss    ",
      "      tuqsss    ",
      "       w      xx",
      "       ewwwwe yy",
      "       A        ",
      "                ",
      "                ",
      "                ",
      "                ",
      "       B        ",
      "       ewwwwe CC",
      "       w      DD",
      "      EFqsss    ",
      "       pqsss    ",
      "   e   pqsss    "
    ]
  ]
}