{
  "name": "multi_timbertower_4_floor5",
  "refpalette": "deceasedcraft:multi_timbertower_4/multi_timbertower_4_floor5_palette",
  "xsize": 16,
  "zsize": 16,
  "slices": [
    [
      "a   bbbbbbbbbbbb",
      "a   bbbbbbbbbbbb",
      "a   bbbbbbbbbbbb",
      "c ddbbbbbbbbbbbb",
      "bbbbebbbbbbeffff",
      "bbbbbbbbbbbbffff",
      "bbbbbbbbbbbbffff",
      "bbbbbbbbbbbbffff",
      "bbbbbbbbbbbbffff",
      "bbbbbbbbbbbbffff",
      "bbbbbbbbbbbbffff",
      "ggggebbbbbbeffff",
      "    hbbbbbbbbbbb",
      "    hbbbbbbbbbbb",
      "    hbbbbbbbbbbb",
      "    hbbbbbbbbbbb"
    ],
    [
      "a   ij     k  lm",
      "a   in     o   m",
      "a   ip     q   m",
      "adrri     sqs tt",
      "uwxyes  ttteABAA",
      "    C   DEFqI  A",
      "    J  K L qI  M",
      "N   O      qP  A",
      "s   Q      qP  M",
      "    J    R qI  A",
      "S   C   TUVqI  M",
      "CCCCes  ttteAWAA",
      "    C   DEFq    ",
      "    C    L q   X",
      "    C      Y  Z0",
      "    C      1   2"
    ],
    [
      "a   i      3    ",
      "a   i      4    ",
      "a   i      q    ",
      "ad  i     5q5 66",
      "u 78e5  666eA9AA",
      "    C   #$%q^  A",
      "    J      &   *",
      "(   )      &!  A",
      "5   +      &   *",
      "    J      &   A",
      "-   C   [] q{  *",
      "    e5  666eA}AA",
      "    C   K$%q    ",
      "    C      q    ",
      "    C      |   ;",
      "    C      :    "
    ],
    [
      "a   i      '    ",
      "a   i      '    ",
      "a   i      q    ",
      "adddi     <q< 66",
      "u>  e<  ,,,eAAAA",
      "    C      q   A",
      "    J      &.  A",
      "    J      &?  A",
      "<   J      &?  A",
      "    J      &/  A",
      "    C      q   A",
      "    e<  ,,,eAAAA",
      "    C      q    ",
      "    C      q    ",
      "    C      '    ",
      "    C      '    "
    ],
    [
      "a   `\u0370\u0370\u0370\u0370\u0370\u0370\u0371\u0370\u0370\u0370\u0370",
      "a   `\u0370\u0370\u0370\u0370\u0370\u0370\u0371\u0370\u0370\u0370\u0370",
      "a   `\u0370\u0372\u0370\u0370\u0372\u0370\u0371\u0370\u0372\u0370\u0370",
      "addd`\u0370\u0370\u0370\u0370\u0370\u0370\u0371\u0370\u0370\u0370\u0370",
      "uuuue\u0370\u0370\u0370\u0370\u0370\u0370eAAAA",
      "    q\u0370\u0370\u0370\u0370\u0370\u0370\u0371\u0373\u0373\u0373\u0373",
      "    q\u0370\u0372\u0370\u0370\u0374\u0370\u0371\u0373\u0373\u0373\u0373",
      "    q\u0370\u0370\u0370\u0370\u0370\u0370\u0371\u0373\u0373\u0373\u0373",
      "    q\u0370\u0370\u0370\u0370\u0370\u0370\u0371\u0373\u0373\u0373\u0373",
      "    q\u0370\u0372\u0370\u0370\u0372\u0370\u0371\u0373\u0373\u0373\u0373",
      "    q\u0370\u0370\u0370\u0370\u0370\u0370\u0371\u0373\u0373\u0373\u0373",
      "    e\u0370\u0370\u0370\u0370\u0370\u0370eAAAA",
      "    q\u0370\u0370\u0370\u0370\u0370\u0370\u0371\u0370\u0370\u0370\u0370",
      "    q\u0370\u0372\u0370\u0370\u0374\u0370\u0371\u0370\u0375\u0370\u0370",
      "    q\u0370\u0370\u0370\u0370\u0370\u0370\u0371\u0370\u0370\u0370\u0370",
      "    q\u0370\u0370\u0370\u0370\u0370\u0370\u0371\u0370\u0370\u0370\u0370"
    ],
    [
      "\u0376   \u0376     \u0377\u0376    ",
      "\u0376   \u0376    \u037a\u0377\u0376\u037a\u037a \u037a",
      "\u0376   \u0376\u037a\u037b  \u037b\u0377\u0376 \u037b\u037a ",
      "\u0376d\u037c\u037c\u0376   \u037a \u037d\u0376\u037a\u037a \u037a",
      "\u037e\u037e\u037e\u037ee\u037e\u037e\u037e\u037e\u037e\u037ee\u037e\u037e\u037e\u037e",
      "\u0370\u0370\u0370\u0370\u0376 \u037a   \u037d\u0376 \u037a  ",
      "\u0370\u0370\u0372\u0370\u0376 \u037b \u037a\u037b\u0377\u0376\u0377\u0377\u0377\u0377",
      "\u0370\u0370\u0370\u0370\u0376\u037a    \u0377\u0376\u037a \u0377\u037a",
      "\u0370\u0370\u0370\u0370\u0376  \u037a \u037a\u0377\u0376  \u0377\u0377",
      "\u0370\u0370\u0374\u0370\u0376 \u037b  \u037b\u0377\u0376  \u0377\u037a",
      "\u0370\u0370\u0370\u0370\u0376   \u037a \u037d\u0376\u037a\u037a\u0377\u0377",
      "\u037e\u037e\u037e\u037ee\u037e\u037e\u037e\u037e\u037e\u037ee\u037e\u037e\u037e\u037e",
      "    \u0376 \u037a   \u037d\u0376 \u037a \u037a",
      "    \u0376 \u037b \u037a\u037b\u0377\u0376 \u037b  ",
      "    \u0376\u037a \u037a  \u0377\u0376 \u037a  ",
      "    \u0376\u037a  \u037a\u037a\u0377\u0376    "
    ]
  ]
}