{
  "name": "multi_timbertower_4_floor9",
  "refpalette": "deceasedcraft:multi_timbertower_4/multi_timbertower_4_floor9_palette",
  "xsize": 16,
  "zsize": 16,
  "slices": [
    [
      "a   b           ",
      "a   bcc       de",
      "a   bff         ",
      "g hhbff         ",
      "bbbbibbb   i    ",
      "bbbbbbbb        ",
      "bbbbbbbb        ",
      "bbbbbbbb        ",
      "bbbbbbbb        ",
      "bbbbbbbb        ",
      "bbbbbbbb   e    ",
      "bbbbibbb   ie   ",
      "bbbbbbbb        ",
      "bbbbbbbb  dd    ",
      "bbbbbbbb       e",
      "bbbbbbbb       e"
    ],
    [
      "a   j           ",
      "a   j          d",
      "a   j           ",
      "ahkkj           ",
      "lmnoi      i    ",
      "       p        ",
      "       q        ",
      " r sr  q        ",
      " tu r  q        ",
      "ur  r  q        ",
      " s u   p        ",
      "    i      i    ",
      "  u u  p        ",
      " r sw  q        ",
      " !  r  q       e",
      " tu r  q        "
    ],
    [
      "a   j           ",
      "a   j           ",
      "a   j           ",
      "ah  j           ",
      "l xyi  !   i    ",
      "       A        ",
      "                ",
      " r  r           ",
      " r  B           ",
      "    C           ",
      "       A        ",
      "    i      i    ",
      "       A        ",
      " C              ",
      " r  r          d",
      " r  C           "
    ],
    [
      "a   j           ",
      "a   j           ",
      "a   j           ",
      "ahhhj           ",
      "lD  i  E   i    ",
      "       F        ",
      "                ",
      "                ",
      "                ",
      "                ",
      "       F        ",
      "    i  E   i    ",
      "       F        ",
      "                ",
      "                ",
      "                "
    ],
    [
      "a   j           ",
      "a   j           ",
      "a   j           ",
      "ahhhj           ",
      "lllli  E   i    ",
      "                ",
      "                ",
      "                ",
      "                ",
      "                ",
      "                ",
      "    i  E   i    ",
      "                ",
      "                ",
      "                ",
      "                "
    ],
    [
      "I   IJJJKKKIKKKK",
      "I   IJJJKKKIKKKK",
      "I   IJLJKKKIKKKK",
      "IhMMIJJJKKKIKKKK",
      "NNNNiNNNNNNiNNNN",
      "JJJJIJJJKKKIKKKK",
      "JJLJIJLJKKKIKKKK",
      "JJJJIJJJKKKIKKKK",
      "JJJJIJJJKKKIKKKK",
      "JJLJIJLJKKKIKKKK",
      "JJJJIJJJKKKIKKKK",
      "NNNNiNNNNNNiNNNN",
      "    IJJJKKKIKKKK",
      "    IJLJKKKIKKKK",
      "    IJJJKKKIKKKK",
      "    IJJJKKKIKKKK"
    ]
  ]
}