{
  "name": "multi_timbertower_4_base2",
  "refpalette": "deceasedcraft:multi_timbertower_4/multi_timbertower_4_base2_palette",
  "xsize": 16,
  "zsize": 16,
  "slices": [
    [
      "vaaavHHHHHHHHHHH",
      "vaaavHHHHHHHHHHH",
      "v aavHHHHHHHHHHH",
      "b ccvHHHHHHHHHHH",
      "vvvvdHHHHHHdHHHH",
      "vvvvvvvvvvvvvvvv",
      "vvvvvvaaaavvvvvv",
      "vvvvvvaaaavvvvvv",
      "vvvvvvaaaavvvvvv",
      "vvvvvvaaaavvvvvv",
      "vvvvvvvvvvvvvvvv",
      "HHHHdHHHHHHdHHHH",
      "HHHHHHHHHHHHHHHH",
      "HHHeeeeeeHeeeHHH",
      "HHHeHHHHeHeHeHHH",
      "HHHeeeHHeHeeeHHH"
    ],
    [
      "fg  h           ",
      "fi  h           ",
      "fajkh           ",
      "fcllhm nm n m nm",
      "opqrds ts tds ts",
      "     vvvvvvvvvvv",
      "     vuuwwHHHHHH",
      "     vuxxuHHHHHH",
      "    yv    HHHHHH",
      "    !v   AHHHHHH",
      "vvvvvvvvBvvvvvvv",
      "    d CC C d    ",
      "                ",
      "                ",
      "                ",
      "                "
    ],
    [
      "fg  h           ",
      "fg  h           ",
      "faDEh           ",
      "fc  h           ",
      "o FId      d    ",
      "    yvvvvvvvvvvv",
      "     v  J HHHHKL",
      "     v    HHHHKL",
      "     v    HHHHKL",
      "    yv    HHHHKL",
      "vvvvvvvBvvvvvvvv",
      "    d CCC yd    ",
      "                ",
      "                ",
      "                ",
      "                "
    ],
    [
      "fg  h           ",
      "fg  h           ",
      "faMMh           ",
      "fccch           ",
      "oN  d      d    ",
      "    yvvvvvvvvvvv",
      "     vOOOOHKL   ",
      "    yvOOOOHKL   ",
      "     vOOOOHKL   ",
      "     vOOOOHKL   ",
      "vvvvvvvvvvvvvvvv",
      "    dy C  yd    ",
      "                ",
      "                ",
      "                ",
      "                "
    ],
    [
      "fPQQh           ",
      "fPQQh           ",
      "faaah           ",
      "fccch           ",
      "ooood      d    ",
      "    yvvvvvvvvvvv",
      "    yvHHKL      ",
      "    yvHHKL      ",
      "     vHHKL      ",
      "    yvHHKL      ",
      "vvvvvvvvvvvvvvvv",
      "y  ydy   yydy  y",
      "    y           ",
      "                ",
      "                ",
      "                "
    ],
    [
      "d   dRRRRRRRRRRR",
      "d   dRRRRRRRRRRR",
      "d   dRRRRRRRRRRR",
      "dcSTdRRRRRRRRRRR",
      "dddddddddddddddd",
      "RRRRdvvvvvvvvvvv",
      "RRRRdKL         ",
      "RRRRdKL         ",
      "RRRRdKL         ",
      "RRRRdKL         ",
      "vvvvdvvvvvvvvvvv",
      "dddddddddddddddd",
      "    d      d    ",
      "    d      d    ",
      "    d      d    ",
      "    d      d    "
    ]
  ]
}