{
  "name": "multi_timbertower_4_base1",
  "refpalette": "deceasedcraft:multi_timbertower_4/multi_timbertower_4_base1_palette",
  "xsize": 16,
  "zsize": 16,
  "slices": [
    [
      "a   vHHHHHHHHHHH",
      "a   vHHHHHHHHHHH",
      "a   vHHHHHHHHHHH",
      "b ccvHHHHHHHHHHH",
      "vvvvdHHHHHHdHHHH",
      "vvvvevvvvvvvvvvv",
      "HHfgh           ",
      "HHfgh           ",
      "HHfgh           ",
      "HHfgh           ",
      "vvvvivvvvvvvvvvv",
      "    d      d    ",
      "                ",
      "                ",
      "                ",
      "                "
    ],
    [
      "a   j           ",
      "a   j           ",
      "a   j           ",
      "ackkjl mlnm l ml",
      "opqrds ts tds ts",
      "     vvvvvvvvvvv",
      "             uua",
      "             uua",
      "             uua",
      "             uua",
      "vvvvvvvvvvvvvvvv",
      "    d      d    ",
      "                ",
      "                ",
      "                ",
      "                "
    ],
    [
      "a   j           ",
      "a   j           ",
      "a   j           ",
      "ac  j           ",
      "o wxd      d    ",
      "     vvvvvvvvvvv",
      "          uuaHfg",
      "          uuaHfg",
      "          uuaHfg",
      "          uuaHfg",
      "vvvvvvvvvvvvvvvv",
      "    d      d    ",
      "                ",
      "                ",
      "                ",
      "                "
    ],
    [
      "a   j           ",
      "a   j           ",
      "a   j           ",
      "acccj           ",
      "oy  d      d    ",
      "     vvvvvvvvvvv",
      "       uuaHfg   ",
      "       uuaHfg   ",
      "       uuaHfg   ",
      "       uuaHfg   ",
      "vvvvvvvvvvvvvvvv",
      "    d      d    ",
      "                ",
      "                ",
      "                ",
      "                "
    ],
    [
      "a   j           ",
      "a   j           ",
      "a   j           ",
      "acccj           ",
      "ooood      d    ",
      "     vvvvvvvvvvv",
      "     uaHfg      ",
      "     uaHfg      ",
      "     uaHfg      ",
      "     uaHfg      ",
      "vvvvvvvvvvvvvvvv",
      "    d      d    ",
      "                ",
      "                ",
      "                ",
      "                "
    ],
    [
      "d   duuuuuuuuuuu",
      "d   duuuuuuuuuuu",
      "d   duuuuuuuuuuu",
      "dcABduuuuuuuuuuu",
      "dddddddddddddddd",
      "uuuudvvvvvvvvvvv",
      "uuuudfg         ",
      "uuuudfg         ",
      "uuuudfg         ",
      "uuuudfg         ",
      "vvvvdvvvvvvvvvvv",
      "dddddddddddddddd",
      "    d      d    ",
      "    d      d    ",
      "    d      d    ",
      "    d      d    "
    ]
  ]
}