{
  "name": "multi_timbertower_4_floor4",
  "refpalette": "deceasedcraft:multi_timbertower_4/multi_timbertower_4_floor4_palette",
  "xsize": 16,
  "zsize": 16,
  "slices": [
    [
      "a   bbbbbbbbbbbb",
      "a   bbbbbbbbbbbb",
      "a   bbbbbbbbbbbb",
      "c ddbbbbbbbbbbbb",
      "bbbbebbbbbbeffff",
      "bbbbbbbbbbbbffff",
      "bbbbbbbbbbbbffff",
      "bbbbbbbbbbbbffff",
      "bbbbbbbbbbbbffff",
      "bbbbbbbbbbbbffff",
      "bbbbbbbbbbbbffff",
      "ggggebbbbbbeffff",
      "    hbbbbbbbbbbb",
      "    hbbbbbbbbbbb",
      "    hbbbbbbbbbbb",
      "    hbbbbbbbbbbb"
    ],
    [
      "a   ij     k  lm",
      "a   in     o   m",
      "a   ip     q   m",
      "adrris    tqt uu",
      "wxyAet  uuueBCBB",
      "    D   EFIqJ  B",
      "    K    L qJ  M",
      "N   O      qP  B",
      "t   Q      qP  M",
      "    K    R qJ  B",
      "S   D   TUVqJ  M",
      "DDDDet  uuueBWBB",
      "    D   EFIq    ",
      "    D   XL q   Y",
      "    D      Z  Y0",
      "    D      1   2"
    ],
    [
      "a   i      3    ",
      "a   i      4    ",
      "a   i      q    ",
      "ad  i     5q5 66",
      "w 78e5  666eB9BB",
      "    D   #$%q^  B",
      "    K      &   *",
      "(   )      &   B",
      "5   +      &   *",
      "    K      &   B",
      "    D   -[!q]  *",
      "    e5  666eB{BB",
      "    D   }$%q    ",
      "    D      q    ",
      "    D      |   ;",
      "    D      :    "
    ],
    [
      "a   i      '    ",
      "a   i      '    ",
      "a   i      q    ",
      "adddi     <q< 66",
      "w>  e<  ,,,eBBBB",
      "    D      q   B",
      "    K      &.  B",
      "    K      &?  B",
      "<   K      &?  B",
      "    K      &/  B",
      "    D      q   B",
      "    e<  ,,,eBBBB",
      "    D      q    ",
      "    D      q    ",
      "    D      '    ",
      "    D      '    "
    ],
    [
      "a   `\u0370\u0370\u0370\u0370\u0370\u0370\u0371\u0370\u0370\u0370\u0370",
      "a   `\u0370\u0370\u0370\u0370\u0370\u0370\u0371\u0370\u0370\u0370\u0370",
      "a   `\u0370\u0372\u0370\u0370\u0373\u0370\u0371\u0370\u0372\u0370\u0370",
      "addd`\u0370\u0370\u0370\u0370\u0370\u0370\u0371\u0370\u0370\u0370\u0370",
      "wwwwe\u0370\u0370\u0370\u0370\u0370\u0370eBBBB",
      "    q\u0370\u0370\u0370\u0370\u0370\u0370\u0371\u0374\u0374\u0374\u0374",
      "    q\u0370\u0372\u0370\u0370\u0372\u0370\u0371\u0374\u0374\u0374\u0374",
      "    q\u0370\u0370\u0370\u0370\u0370\u0370\u0371\u0374\u0374\u0374\u0374",
      "    q\u0370\u0370\u0370\u0370\u0370\u0370\u0371\u0374\u0374\u0374\u0374",
      "    q\u0370\u0373\u0370\u0370\u0372\u0370\u0371\u0374\u0374\u0374\u0374",
      "    q\u0370\u0370\u0370\u0370\u0370\u0370\u0371\u0374\u0374\u0374\u0374",
      "    e\u0370\u0370\u0370\u0370\u0370\u0370eBBBB",
      "    q\u0370\u0370\u0370\u0370\u0370\u0370\u0371\u0370\u0370\u0370\u0370",
      "    q\u0370\u0373\u0370\u0370\u0372\u0370\u0371\u0370\u0375\u0370\u0370",
      "    q\u0370\u0370\u0370\u0370\u0370\u0370\u0371\u0370\u0370\u0370\u0370",
      "    q\u0370\u0370\u0370\u0370\u0370\u0370\u0371\u0370\u0370\u0370\u0370"
    ],
    [
      "\u0376   \u0376     \u0377\u0376    ",
      "\u0376   \u0376    \u037a\u0377\u0376\u037a\u037a \u037a",
      "\u0376   \u0376\u037a\u037b  \u037b\u0377\u0376 \u037b\u037a ",
      "\u0376d\u037c\u037d\u0376   \u037a \u037e\u0376\u037a\u037a \u037a",
      "\u037f\u037f\u037f\u037fe\u037f\u037f\u037f\u037f\u037f\u037fe\u037f\u037f\u037f\u037f",
      "\u0370\u0370\u0370\u0370\u0376 \u037a   \u037e\u0376 \u037a  ",
      "\u0370\u0370\u0372\u0370\u0376 \u037b \u037a\u037b\u0377\u0376\u0377\u0377\u0377\u0377",
      "\u0370\u0370\u0370\u0370\u0376\u037a    \u0377\u0376\u037a \u0377\u037a",
      "\u0370\u0370\u0370\u0370\u0376    \u037a\u0377\u0376  \u0377\u0377",
      "\u0370\u0370\u0372\u0370\u0376 \u037b  \u037b\u0377\u0376  \u0377\u037a",
      "\u0370\u0370\u0370\u0370\u0376   \u037a \u037e\u0376\u037a\u037a\u0377\u0377",
      "\u037f\u037f\u037f\u037fe\u037f\u037f\u037f\u037f\u037f\u037fe\u037f\u037f\u037f\u037f",
      "    \u0376 \u037a   \u037e\u0376 \u037a \u037a",
      "    \u0376 \u037b \u037a\u037b\u0377\u0376 \u037b  ",
      "    \u0376\u037a    \u0377\u0376 \u037a  ",
      "    \u0376\u037a  \u037a\u037a\u0377\u0376    "
    ]
  ]
}