{
  "name": "multi_timbertower_4_floor2",
  "refpalette": "deceasedcraft:multi_timbertower_4/multi_timbertower_4_floor2_palette",
  "xsize": 16,
  "zsize": 16,
  "slices": [
    [
      "a   b           ",
      "a   b           ",
      "a   b           ",
      "c ddb           ",
      "eeeef      g!   ",
      "eeeeb           ",
      "eeeeb           ",
      "eeeeb           ",
      "eeeeb           ",
      "eeeeb           ",
      "eeeeb           ",
      "eeeef      f    ",
      "eeeeb           ",
      "eeeeb           ",
      "eeeeb           ",
      "eeeeb           "
    ],
    [
      "a   h           ",
      "a   h           ",
      "a   h           ",
      "adiih           ",
      "jklmf      g    ",
      "    n           ",
      "    n           ",
      "    n           ",
      "    n           ",
      "  o n           ",
      "  p n           ",
      "q rqf      f    ",
      "n o n           ",
      "n p n           ",
      "n   n           ",
      "n o n           "
    ],
    [
      "a   h           ",
      "a   h           ",
      "a   h           ",
      "ad  h           ",
      "j stf      f    ",
      "                ",
      "                ",
      "                ",
      "                ",
      "                ",
      "                ",
      "!  uf      f    ",
      "                ",
      "                ",
      "                ",
      "                "
    ],
    [
      "a   h           ",
      "a   h           ",
      "a   h           ",
      "adddh           ",
      "jw  f      f    ",
      "                ",
      "                ",
      "                ",
      "                ",
      "                ",
      "                ",
      "   xf      f    ",
      "                ",
      "                ",
      "                ",
      "                "
    ],
    [
      "a   h           ",
      "a   h           ",
      "a   h           ",
      "adddh           ",
      "jjjjf      f    ",
      "                ",
      "                ",
      "                ",
      "                ",
      "                ",
      "                ",
      "    f      f    ",
      "                ",
      "                ",
      "                ",
      "                "
    ],
    [
      "f   fyyyyyyfyyyy",
      "f   fyyyyyyfyyyy",
      "f   fyyyyyyfyyyy",
      "fdABfyyyyyyfyyyy",
      "ffffffffffffffff",
      "yyyyfyyyyyyfyyyy",
      "yyyyfyyyyyyfyyyy",
      "yyyyfyyyyyyfyyyy",
      "yyyyfyyyyyyfyyyy",
      "yyyyfyyyyyyfyyyy",
      "yyyyfyyyyyyfyyyy",
      "ffffffffffffffff",
      "yyyyfyyyyyyfyyyy",
      "yyyyfyyyyyyfyyyy",
      "yyyyfyyyyyyfyyyy",
      "yyyyfyyyyyyfyyyy"
    ]
  ]
}