{
  "name": "multi_timbertower_4_floor1",
  "refpalette": "deceasedcraft:multi_timbertower_4/multi_timbertower_4_floor1_palette",
  "xsize": 16,
  "zsize": 16,
  "slices": [
    [
      "a   bb          ",
      "a   bb          ",
      "a   bb          ",
      "c ddbb          ",
      "bbbbeb  f  g    ",
      "bbbbbb          ",
      "bbbbbbh         ",
      "bbbbbbh         ",
      "bbbbbbh         ",
      "bbbbbbh         ",
      "bbbbbb          ",
      "bbbbeb     g    ",
      "bbbbbb          ",
      "bbbbbb          ",
      "bbbbbb          ",
      "bbbbbb          "
    ],
    [
      "a   i           ",
      "a   i           ",
      "a   i           ",
      "adjji           ",
      "klmne      e    ",
      "                ",
      "                ",
      "                ",
      "                ",
      "                ",
      "                ",
      "o   e      g    ",
      "pd  i           ",
      "    i           ",
      "    i           ",
      "    i           "
    ],
    [
      "a   i           ",
      "a   i           ",
      "a   i           ",
      "ad  i           ",
      "k qre      g    ",
      "                ",
      "                ",
      "                ",
      "                ",
      "                ",
      "                ",
      "    e      e    ",
      "st  i           ",
      "    i           ",
      "    i           ",
      "    i           "
    ],
    [
      "a   i           ",
      "a   i           ",
      "a   i           ",
      "adddi           ",
      "ku  e      g    ",
      "                ",
      "                ",
      "                ",
      "                ",
      "                ",
      "                ",
      "    e      e    ",
      "    i           ",
      "    i           ",
      "    i           ",
      "    i           "
    ],
    [
      "a   i           ",
      "a   i           ",
      "a   i           ",
      "adddi           ",
      "kkkke      g    ",
      "                ",
      "                ",
      "                ",
      "                ",
      "                ",
      "                ",
      "    e      g    ",
      "    i           ",
      "    i           ",
      "    i           ",
      "    i           "
    ],
    [
      "e   e           ",
      "e   e           ",
      "e   e           ",
      "edwwe           ",
      "eeeeeeeegeggggge",
      "xxxxe           ",
      "xxxxe           ",
      "xxxxe           ",
      "xxxxe           ",
      "xxxxe           ",
      "xxxxe           ",
      "eeeeeeeeegeggeee",
      "xxxxe           ",
      "xxxxe           ",
      "xxxxe           ",
      "xxxxe           "
    ]
  ]
}