{
  "name": "multi_timbertower_4_floor14",
  "refpalette": "deceasedcraft:multi_timbertower_4/multi_timbertower_4_floor14_palette",
  "xsize": 16,
  "zsize": 16,
  "slices": [
    [
      "a   bccccdcefghh",
      "a   bccccdcefghh",
      "a   bccccdcefghh",
      "i jjbccccdcefghh",
      "bbbbkcccccckfhhh",
      "bbbbbbbbbbbefhhh",
      "bbbbbbbbbbbefhhh",
      "bbbbbbbbbbbefhhh",
      "bbbbbbbbbbbefhhh",
      "bbbbbbbbbbbefhhh",
      "bbbbbbbbbbbefhhh",
      "bbbbkbbbbbbkfhhh",
      "bbbbbbbbbbbefhhh",
      "bbbbbbbbbbbefhhh",
      "bbbbbbbbbbbefhhh",
      "bbblbbbbbbbefhhh"
    ],
    [
      "a   a m m       ",
      "a   anonop      ",
      "a   a   m       ",
      "ajqqarr mp      ",
      "stuwkxxyx  k    ",
      "    A           ",
      "    B  CD       ",
      "D   E  F        ",
      "D   I  CD       ",
      "    B           ",
      "   JA  CD       ",
      "  KLk  F   k    ",
      "   JA  CD       ",
      "   MA           ",
      "    A  CD       ",
      " NNOA  F    PQ  "
    ],
    [
      "a   a m mR      ",
      "a   aSoSo       ",
      "a   a T mR      ",
      "aj  a   m       ",
      "s UVkxxWx  k    ",
      "    A           ",
      "    B           ",
      "    X  F        ",
      "    Y           ",
      "    B           ",
      "   ZA           ",
      "   0k  F   k    ",
      "   ZA           ",
      "    A           ",
      "    A           ",
      "    A  F        "
    ],
    [
      "a   a m m1      ",
      "a   aoooo       ",
      "a   a   m1      ",
      "ajjja23 m       ",
      "s4  kxx5x  k    ",
      "    A           ",
      "    B           ",
      "    B  6        ",
      "    B           ",
      "    B           ",
      "    A           ",
      "    k  7   k    ",
      "    A           ",
      "    A           ",
      "    A           ",
      "    A  6        "
    ],
    [
      "a   a8o8o       ",
      "a   aoooo       ",
      "a   a888o       ",
      "ajjja888o       ",
      "sssskxxxx  k    ",
      "    9           ",
      "    # $%$       ",
      "    9 %^%       ",
      "    # $%$       ",
      "    9           ",
      "   &# $%$       ",
      "9#9#k %*%  k    ",
      "   &9 $%$       ",
      "    #           ",
      "    9 $%$       ",
      "    # %^%       "
    ],
    [
      "(  ()   +       ",
      "(  ()-! +       ",
      "(  ()-- +       ",
      "(((()   +       ",
      "[[[[k++++  k    ",
      "]]]])           ",
      "]]]])           ",
      "]]]])           ",
      "]]]])           ",
      "]]]])           ",
      "]]]])           ",
      "[[[[k      k    ",
      "]]]])           ",
      "]]]])           ",
      "]]]])           ",
      "]]]])           "
    ]
  ]
}