{
  "name": "multi_timbertower_4_floor8",
  "refpalette": "deceasedcraft:multi_timbertower_4/multi_timbertower_4_floor8_palette",
  "xsize": 16,
  "zsize": 16,
  "slices": [
    [
      "a   bbbbbbbbcccc",
      "a   bbbbbbbbcccc",
      "a   bbbbbbbbcccc",
      "adddbbbbbbbbcccc",
      "bbbbebbbbbbecccc",
      "             ccc",
      "             ccc",
      "             fcc",
      "              cc",
      "              cc",
      "              cc",
      "    e      e  gc",
      "           h   c",
      "h              c",
      "g              c",
      "h       g      c"
    ],
    [
      "a   ij          ",
      "a   ij         k",
      "a   il          ",
      "adddim n     f  ",
      "ooooeppppppe    ",
      "                ",
      "              f ",
      "                ",
      "              k ",
      "                ",
      "              gg",
      "    e      e  g ",
      "                ",
      "                ",
      "g              k",
      "        g       "
    ],
    [
      "a   i           ",
      "a   i          q",
      "a   i           ",
      "adddiq          ",
      "ooooe      e    ",
      "                ",
      "                ",
      "                ",
      "              q ",
      "                ",
      "    h           ",
      "    e      e    ",
      "                ",
      "                ",
      "h              q",
      "        h       "
    ],
    [
      "a   i          h",
      "a   i          g",
      "a   i           ",
      "adddir          ",
      "ooooe      e    ",
      "                ",
      "                ",
      "                ",
      "              g ",
      "                ",
      "    h     h     ",
      "    e      e h  ",
      "     g          ",
      "                ",
      "               g",
      "                "
    ],
    [
      "a   i          g",
      "a   i          g",
      "a   i          g",
      "adddi           ",
      "ooooe      e    ",
      "                ",
      "                ",
      "                ",
      "              g ",
      "                ",
      "    hh    hg    ",
      "    egg    ehh  ",
      "     g          ",
      "          h    g",
      "              gg",
      "               g"
    ],
    [
      "s   stt    s   g",
      "s   s      s  gg",
      "s   s      s   h",
      "sduws      s    ",
      "xxxxexxxxxxexxxx",
      "yyyys      s    ",
      "yyAys      s    ",
      "yyyys      s    ",
      "yyyys      s  h ",
      "yyAys      s    ",
      "yyyys     hsg   ",
      "xxxxexxxxxxexxxx",
      "yyyys      s    ",
      "yyAys     hs   h",
      "yyyys      s  gg",
      "yyyys      s   g"
    ]
  ]
}