{
  "name": "multi_timbertower_4_floor6",
  "refpalette": "deceasedcraft:multi_timbertower_4/multi_timbertower_4_floor6_palette",
  "xsize": 16,
  "zsize": 16,
  "slices": [
    [
      "a   bbbbbbbbbbbb",
      "a   bbbbbbbbbbbb",
      "a   bbbbbbbbbbbb",
      "c ddbbbbbbbbbbbb",
      "bbbbebbbbbbeffff",
      "bbbbbbbbbbbbffff",
      "bbbbbbbbbbbbffff",
      "bbbbbbbbbbbbffff",
      "bbbbbbbbbbbbffff",
      "bbbbbbbbbbbbffff",
      "bbbbbbbbbbbbffff",
      "bbbbebbbbbbeffff",
      "bbbbbbbbbbbbbbbb",
      "bbbbbbbbbbbbbbbb",
      "bbbbbbbbbbbbbbbb",
      "bbbbbbbbbbbbbbbb"
    ],
    [
      "a   ag         h",
      "a   ai  jkkl   m",
      "a   ai        no",
      "adppaq        no",
      "rstuewwxywweABAA",
      "         C DE  A",
      "        FI DE  J",
      "        FI DK  A",
      " L      FI DK  J",
      " MNOP   FI DE  A",
      " MNQPR   C DE  J",
      "   SeS    SeATAA",
      " MNUPVNW    S XY",
      " MNZP0NW        ",
      "       1        ",
      "     1    22  32"
    ],
    [
      "a   a4         5",
      "a   a6   78    9",
      "a   a#         o",
      "ad  a$         o",
      "r %^eww&*wweA(AA",
      "           D)  A",
      "         + -   [",
      "         ] -   A",
      "           -   [",
      "  L {    } -   A",
      "  | ;      D:  [",
      "   'e'    'eA<AA",
      "  3 {       '   ",
      "    ; 3         ",
      "                ",
      "                "
    ],
    [
      "a   a          o",
      "a   a>         o",
      "a   a,         o",
      "addda          o",
      "r.  eww??wweAAAA",
      "         / D   A",
      "         / -`  A",
      "         / -\u0370  A",
      "         / -\u0370  A",
      "         / -\u0371  A",
      "         / D   A",
      "   \u0372e\u0372    \u0372eAAAA",
      "            \u0372  !",
      "                ",
      "                ",
      "                "
    ],
    [
      "a   a\u0373\u0373\u0373\u0373\u0373\u0373\u0373\u0373\u0373\u0373\u0374",
      "a   a\u0373\u0373\u0373\u0373\u0373\u0373\u0373\u0373\u0373\u0373\u0374",
      "a   a\u0373\u0375\u0373\u0373\u0375\u0373\u0373\u0373\u0375\u0373\u0374",
      "addda\u0373\u0373\u0373\u0373\u0373\u0373\u0373\u0373\u0373\u0373\u0374",
      "rrrrewwwwwweAAAA",
      "           \u0376\u0377\u0377\u0377\u0377",
      "         \u037a \u0376\u0377\u0377\u0377\u0377",
      "           \u0376\u0377\u0377\u0377\u0377",
      "           \u0376\u0377\u0377\u0377\u0377",
      "         \u037a \u0376\u0377\u0377\u0377\u0377",
      "           \u0376\u0377\u0377\u0377\u0377",
      "    e      eAAAA",
      "                ",
      "                ",
      "                ",
      "                "
    ],
    [
      "a   \u037b\u037c \u037c  \u037c\u037b\u037c   ",
      "a   \u037b  \u037c \u037c \u037b  \u037c ",
      "a   \u037b \u037a  \u037a \u037b \u037a \u037c",
      "ad\u037d\u037d\u037b\u037c     \u037b\u037c   ",
      "\u037e\u037e\u037e\u037ee\u037e\u037e\u037e\u037e\u037e\u037ee\u037e\u037e\u037e\u037e",
      "\u0373\u0373\u0373\u0373\u037b\u0373\u0373\u0373\u0373\u0373\u0373\u037b \u037c  ",
      "\u0373\u0373\u037f\u0373\u037b\u0373\u037f\u0373\u0373\u0384\u0373\u037b\u0385\u0385\u0385\u0385",
      "\u0373\u0373\u0373\u0373\u037b\u0373\u0373\u0373\u0373\u0373\u0373\u037b\u037c \u0385\u037c",
      "\u0373\u0373\u0373\u0373\u037b\u0373\u0373\u0373\u0373\u0373\u0373\u037b  \u0385\u0385",
      "\u0373\u0373\u037f\u0373\u037b\u0373\u037f\u0373\u0373\u0386\u0373\u037b  \u0385\u037c",
      "\u0373\u0373\u0373\u0373\u037b\u0373\u0373\u0373\u0373\u0373\u0373\u037b\u037c\u037c\u0385\u0385",
      "\u037e\u037e\u037e\u037ee\u037e\u037e\u037e\u037e\u037e\u037ee\u037e\u037e\u037e\u037e",
      "\u0373\u0373\u0373\u0373\u037b\u0373\u0373\u0373\u0373\u0373\u0373\u037b\u0373\u0373\u0373\u0373",
      "\u0373\u0373\u037f\u0373\u037b\u0373\u037f\u0373\u0373\u037f\u0373\u037b\u0373\u037f\u0373\u0373",
      "\u0373\u0373\u0373\u0373\u037b\u0373\u0373\u0373\u0373\u0373\u0373\u037b\u0373\u0373\u0373\u0373",
      "\u0373\u0373\u0373\u0373\u037b\u0373\u0373\u0373\u0373\u0373\u0373\u037b\u0373\u0373\u0373\u0373"
    ]
  ]
}