{
  "name": "multi_timbertower_4_floor3",
  "refpalette": "deceasedcraft:multi_timbertower_4/multi_timbertower_4_floor3_palette",
  "xsize": 16,
  "zsize": 16,
  "slices": [
    [
      "a   bbbbbbbbbbbb",
      "a   bbbbbbbbbbbb",
      "a   bbbbbbbbbbbb",
      "c ddbbbbbbbbbbbb",
      "bbbbebbbbbbeffff",
      "bbbbbbbbbbbbffff",
      "bbbbbbbbbbbbffff",
      "bbbbbbbbbbbbffff",
      "bbbbbbbbbbbbffff",
      "bbbbbbbbbbbbffff",
      "bbbbbbbbbbbbffff",
      "bbbbebbbbbbeffff",
      "gbbbbbbbbbbbbbbb",
      "gbbbbbbbbbbbbbbb",
      "ggbbbbbbbbbbbbbb",
      "g!ggbbbbbbbbbbbb"
    ],
    [
      "a   hi     j  kl",
      "a   hm     n   l",
      "a   ho     p   l",
      "adqqh     rpr ss",
      "tuwxeyAwxAyeBCBB",
      "    r      pD  B",
      "           pD  E",
      "F          pI  B",
      "   JsK     pI  L",
      "  kMsNO  P pD  B",
      "Q  RsS  TUVpD  L",
      "s  reW  ssseBXBB",
      "    r   YZ0p    ",
      "1        2 p   3",
      "           4  56",
      " 7  sK     8   9"
    ],
    [
      "a   h      #    ",
      "a   h      $    ",
      "a   h      p    ",
      "ad  h     %p% ^^",
      "t &*eyA&*AyeB(BB",
      "    %      p)  B",
      "           +   -",
      "[          +   B",
      "   ]^{     +   }",
      "   |^;     +   B",
      ":  '^<  >,.p?  }",
      "^  %e   ^^^eB/BB",
      "    %   `\u0370\u0371p    ",
      "           p    ",
      "           \u0372   \u0373",
      "    ^{     \u0374    "
    ],
    [
      "a   h      \u0375    ",
      "a   h      \u0375    ",
      "a   h      p    ",
      "adddh     \u0376p\u0376 ^^",
      "t\u0377  eyAAAAyeBBBB",
      "    \u0376      p   B",
      "           +\u037a  B",
      "           +\u037b  B",
      "    \u037c      +\u037b  B",
      "    \u037c      +\u037d  B",
      "    \u037c      p   B",
      "\u037c  \u0376e   \u037c\u037c\u037ceBBBB",
      "    \u0376      p    ",
      "           p    ",
      "           \u0375    ",
      "    \u037c      \u0375    "
    ],
    [
      "a   \u037e\u037f\u037f\u037f\u037f\u037f\u037f\u0384\u037f\u037f\u037f\u037f",
      "a   \u037e\u037f\u037f\u037f\u037f\u037f\u037f\u0384\u037f\u037f\u037f\u037f",
      "a   \u037e\u037f\u0385\u037f\u037f\u0385\u037f\u0384\u037f\u0385\u037f\u037f",
      "addd\u037e\u037f\u037f\u037f\u037f\u037f\u037f\u0384\u037f\u037f\u037f\u037f",
      "tttte\u0386\u0386\u0386\u0386\u0386\u0386eBBBB",
      "           \u0384\u0387\u0387\u0387\u0387",
      "           \u0384\u0387\u0387\u0387\u0387",
      "           \u0384\u0387\u0387\u0387\u0387",
      "           \u0384\u0387\u0387\u0387\u0387",
      "           \u0384\u0387\u0387\u0387\u0387",
      "           \u0384\u0387\u0387\u0387\u0387",
      "    e      eBBBB",
      "           \u0384\u037f\u037f\u037f\u037f",
      "           \u0384\u037f\u0388\u037f\u037f",
      "           \u0384\u037f\u037f\u037f\u037f",
      "           \u0384\u037f\u037f\u037f\u037f"
    ],
    [
      "\u0389   \u0389    \u038a\u038c\u0389    ",
      "\u0389   \u0389 \u038a\u038a  \u038c\u0389\u038a\u038a \u038a",
      "\u0389   \u0389 \u038e  \u038e\u038c\u0389 \u038e\u038a ",
      "\u0389d\u038f\u0390\u0389\u038a \u038a\u038a \u0391\u0389\u038a\u038a \u038a",
      "\u0392\u0392\u0392\u0392e\u0392\u0392\u0392\u0392\u0392\u0392e\u0392\u0392\u0392\u0392",
      "\u037f\u037f\u037f\u037f\u0389\u037f\u037f\u037f\u037f\u037f\u037f\u0389 \u038a  ",
      "\u037f\u037f\u0385\u037f\u0389\u037f\u0393\u037f\u037f\u0393\u037f\u0389\u038c\u038c\u038c\u038c",
      "\u037f\u037f\u037f\u037f\u0389\u037f\u037f\u037f\u037f\u037f\u037f\u0389\u038a \u038c\u038a",
      "\u037f\u037f\u037f\u037f\u0389\u037f\u037f\u037f\u037f\u037f\u037f\u0389  \u038c\u038c",
      "\u037f\u037f\u0393\u037f\u0389\u037f\u0385\u037f\u037f\u0393\u037f\u0389  \u038c\u038a",
      "\u037f\u037f\u037f\u037f\u0389\u037f\u037f\u037f\u037f\u037f\u037f\u0389\u038a\u038a\u038c\u038c",
      "\u0392\u0392\u0392\u0392e\u0392\u0392\u0392\u0392\u0392\u0392e\u0392\u0392\u0392\u0392",
      "    \u0389\u037f\u037f\u037f\u037f\u037f\u037f\u0389 \u038a \u038a",
      "    \u0389\u037f\u0393\u037f\u037f\u0385\u037f\u0389 \u038e  ",
      "    \u0389\u037f\u037f\u037f\u037f\u037f\u037f\u0389 \u038a  ",
      "    \u0389\u037f\u037f\u037f\u037f\u037f\u037f\u0389    "
    ]
  ]
}