{
  "name": "multi_timbertower_4_floor13",
  "refpalette": "deceasedcraft:multi_timbertower_4/multi_timbertower_4_floor13_palette",
  "xsize": 16,
  "zsize": 16,
  "slices": [
    [
      "a   bbbbbbbbbbbb",
      "a   bbbbbbbbbbbb",
      "a   bbbbbbbbbbbb",
      "c ddbbbbbbbbbbbb",
      "bbbbebbbbbbebbbb",
      "bbbbbbbbbbbbbbbb",
      "bbbbbbbbbbbbbbbb",
      "bbbbbbbbbbbbbbbb",
      "bbbbbbbbbbbbbbbb",
      "bbbbbbbbbbbbbbbb",
      "bbbbbbbbbbbbbbbb",
      "bbbbebbbbbbebbbb",
      "bbbbbbbbbbbbbbbb",
      "bbbbbbbbbbbbbbbb",
      "bbbbbbbbbbbbbbbb",
      "bbbbbbbbbbbbbbbb"
    ],
    [
      "a   af ghi jkkl ",
      "a   am nop jk ll",
      "a   a  qrs j    ",
      "adtta  uwx j    ",
      "yABCe     De    ",
      "    E    DDj    ",
      "    FFFIJFFK    ",
      "           L    ",
      "           M    ",
      "    NNNOPNNK    ",
      "    EQ    Rj    ",
      "OSNNe     Re    ",
      "   TE      j    ",
      "   TE      j    ",
      "   TEU VU Vj   W",
      "   XE Y  Y j ZZZ"
    ],
    [
      "a   am 012 j  34",
      "a   a  567 j  33",
      "a   a  89# j    ",
      "ad  a  $%^ j    ",
      "y &*e      e    ",
      "    E(    Dj    ",
      "    FFF)+FFK    ",
      "           -    ",
      "           [    ",
      "    NNN]{NNK    ",
      "    E     Rj    ",
      "]}NNe      e    ",
      "   |E      j    ",
      "    E      j    ",
      "   ;E:'<:'<j    ",
      "   XE>,.> .j    "
    ],
    [
      "a   a   ?  /   `",
      "a   a  \u0370\u0371\u0372 /    ",
      "a   a   \u0373  /    ",
      "addda  \u0374\u0375\u0376 /    ",
      "y\u0377  e      e\u037a\u037a\u037a\u037a",
      "    E      \u037b\u037c\u037a\u037a\u037a",
      "    FFFFFFFK\u037a\u037a\u037a\u037a",
      "           K\u037a\u037a\u037a\u037a",
      "           K\u037a\u037a\u037a\u037a",
      "    NNNNNNNK\u037a\u037a\u037a\u037a",
      "    E      \u037b\u037c\u037a\u037a\u037a",
      "NNNNe      e\u037a\u037a\u037a\u037a",
      "   \u037dE      /\u037a\u037a\u037a\u037a",
      "    E      /\u037a\u037a\u037a\u037a",
      "    E\u037e\u037f\u0384\u037e\u037f\u0384/\u037a\u037a\u037a\u037a",
      "   \u0385E\u0386,\u0387\u0386 \u0387/\u037a\u037a\u037a\u037a"
    ],
    [
      "a   a      j   \u0388",
      "a   a      j    ",
      "a   a      j    ",
      "addda      j    ",
      "yyyye\u0389\u037c\u0389\u0389\u037c\u0389e\u038a\u038a\u038a\u038a",
      "    \u038c\u0389\u0389\u0389\u0389\u0389\u0389\u038e\u038a\u038f\u038f\u038f",
      "    FFFFFFFK \u038f\u038f\u038f",
      "           K\u038a\u038f\u038f\u038f",
      "           K\u038a\u038f\u038f\u038f",
      "    NNNNNNNK \u038f\u038f\u038f",
      "    \u038c\u0389\u0389\u0389\u0389\u0389\u0389\u038e\u038a\u038f\u038f\u038f",
      "NNNNe\u0389\u037c\u0389\u0389\u037c\u0389e\u038a\u038f\u038f\u038f",
      "    E      j\u038a\u038f\u038f\u038f",
      "    E      j \u038f\u038f\u038f",
      "    E\u0390\u0391\u0392\u0390\u0391\u0392j\u038a\u038f\u038f\u038f",
      "    E\u0393,\u0394\u0393 \u0394j\u038a\u038f\u038f\u038f"
    ],
    [
      "\u0395   \u0395      \u0395\u038a\u038a\u038a\u038a",
      "\u0395   \u0395      \u0395\u038a\u038a\u038a\u038a",
      "\u0395   \u0395      \u0395\u038a\u038a\u038a\u038a",
      "\u0395d\u0396\u0396\u0395\u0397\u0397\u0397\u0397\u0397\u0397\u0395\u038a\u038a\u038a\u038a",
      "\u0398\u0398\u0398\u0398e\u0398\u0398\u0398\u0398\u0398\u0398e\u038a\u038a\u038a\u038a",
      "    \u0395\u0399\u0399\u0399\u0399\u0399\u0399\u0395\u038a\u038f\u038f\u038f",
      "    \u0395 \u0399  \u0399 \u0395\u038a\u038f\u038f\u038f",
      "    \u0395 \u0399  \u0399 \u0395\u038a\u038f\u038f\u038f",
      "    \u0395 \u0399  \u0399 \u0395\u038a\u038f\u038f\u038f",
      "    \u0395 \u0399  \u0399 \u0395\u038a\u038f\u038f\u038f",
      "\u0399\u0399\u039a\u0399\u0395\u0399\u0399\u0399\u0399\u0399\u0399\u0395\u038a\u038f\u038f\u038f",
      "\u0398\u0398\u0398\u0398e\u0398\u0398\u0398\u0398\u0398\u0398e\u038a\u038f\u038f\u038f",
      "\u039b\u039b\u039b\u039b\u0395\u039b\u039b\u039b\u039b\u039b\u039b\u0395\u038a\u038f\u038f\u038f",
      "    \u0395      \u0395\u038a\u038f\u038f\u038f",
      "    \u0395\u039c\u039d\u039e\u039c\u039d\u039e\u0395\u038a\u038f\u038f\u038f",
      "    \u0395\u039f\u03a0\u03a1\u039f\u03a0\u03a1\u0395\u038a\u038f\u038f\u038f"
    ]
  ]
}