{
  "name": "multi_timbertower_4_floor12",
  "refpalette": "deceasedcraft:multi_timbertower_4/multi_timbertower_4_floor12_palette",
  "xsize": 16,
  "zsize": 16,
  "slices": [
    [
      "a   bbbbbbbbbbbb",
      "a   bbbbbbbbbbbb",
      "a   bbbbbbbbbbbb",
      "c ddbbbbbbbbbbbb",
      "bbbbebbbbbbebbbb",
      "bbbbbbbbbbbbbbbb",
      "ffffffffffffffff",
      "ffffffffffffffff",
      "ffffffffffffffff",
      "ffffffffffffffff",
      "bbbbbbbbbbbbbbbb",
      "bbbbebbbbbbebbbb",
      "bbbbbbbbbbbbbbbb",
      "bbbbbbbbbbbbbbbb",
      "bbbbbbbbbbbbbbbb",
      "bbbbbbbbbbbbbbbb"
    ],
    [
      "a   ag  hijklm  ",
      "a   anh  hokop  ",
      "a   aqq rqqkqqs ",
      "adttauw r xky s ",
      "ABCDeEF I res J ",
      "     KF rLr@sLs ",
      "     MMNMMM MMMO",
      "                ",
      "                ",
      "PQPP PPRPPP PPPS",
      "s TU@KF rVr@sVs ",
      "W TEeEF X res W ",
      "shwukuw r xky s ",
      "s YYkYY rYYkYYsh",
      "   Zk0    okoh h",
      " hh1kg   ijklm  "
    ],
    [
      "a   a      k    ",
      "a   a    23k45  ",
      "a   aqq rqqkqqs ",
      "ad  a   r6 k 7s ",
      "A 89e#F $ res % ",
      "     KF r r@s s ",
      "     MM^MMM MMM&",
      "                ",
      "                ",
      "P*PP PP(PPP PPP)",
      "s TU@KF r r@s s ",
      "+ T#e#F - res + ",
      "s  !k   r6 k 7s ",
      "s YYkYY rYYkYYs ",
      "    k     [k]{  ",
      "   }k|     k    "
    ],
    [
      "a   a      k    ",
      "a   a      k ;  ",
      "a   aqq rqqkqqs ",
      "addda   r: k 's ",
      "A<  eK  r res s ",
      "     K> r,r@s,s ",
      "     MM.MMM MMM.",
      "                ",
      "                ",
      "P?PP PP?PPP PPP?",
      "s  U@K  r/r@s/s ",
      "s  UeK  r res s ",
      "s  >k>  r: k  s ",
      "s YYkYY rYYkYYs ",
      "    k      k `  ",
      "    k      k    "
    ],
    [
      "a   a      k    ",
      "a   a>     k>   ",
      "a   aqq rqqkqqs ",
      "addda   r >k  s ",
      "AAAAeK  r res s ",
      "     K> r r s s ",
      "     MMMMMM\u0370MMMM",
      "                ",
      "                ",
      "PPPP\u0371PPPPPP\u0371PPPP",
      "s >U K  r>r s s>",
      "s  UeK  r res s ",
      "s >>k>  r >k> s ",
      "s YYkYY rYYkYYs ",
      "    k      k    ",
      "    k      k    "
    ],
    [
      "\u0372   \u0372>   \u0373 \u0372    ",
      "\u0372   \u0372>     \u0372    ",
      "\u0372   \u0372bbbbbb\u0372bbbb",
      "\u0372d\u0374\u0374\u0372bbbbbb\u0372bbbb",
      "\u0375\u0375\u0375\u0375e\u0375\u0375\u0375\u0375\u0375\u0375e\u0375\u0375\u0375\u0375",
      "\u0376\u0376\u0376\u0376\u0372bbbbbb\u0372bbbb",
      "\u0376\u0376\u0376\u0376\u0372\u0377\u0377\u0377\u0377\u0377\u0377\u0372\u0377\u0377\u0377\u0377",
      "\u0376\u0376\u0376\u0376\u0372\u0376\u0376\u0376\u0376\u0376\u0376\u0372\u0376\u0376\u0376\u0376",
      "\u0376\u0376\u0376\u0376\u0372\u0376\u0376\u0376\u0376\u0376\u0376\u0372\u0376\u0376\u0376\u0376",
      "\u037a\u037a\u037a\u037a\u0372\u037a\u037a\u037a\u037a\u037a\u037a\u0372\u037a\u037a\u037a\u037a",
      "bbbb\u0372bbbbbb\u0372bbbb",
      "\u0375\u0375\u0375\u0375e\u0375\u0375\u0375\u0375\u0375\u0375e\u0375\u0375\u0375\u0375",
      "bbbb\u0372bbbbbb\u0372bbbb",
      "bbbb\u0372bbbbbb\u0372bbbb",
      "   >\u0372      \u0372>   ",
      "\u0373   \u0372   \u0373  \u0372  \u0373 "
    ]
  ]
}