{
  "name": "multi_timbertower_4_floor10",
  "refpalette": "deceasedcraft:multi_timbertower_4/multi_timbertower_4_floor10_palette",
  "xsize": 16,
  "zsize": 16,
  "slices": [
    [
      "a   bbbbbbbbbbbb",
      "a   bbbbbbbbbbbb",
      "a   bbbbbbbbbbbb",
      "c ddbbbbbbbbbbbb",
      "bbbbebbbbbbeffff",
      "bbbbbbbbbbbbffff",
      "bbbbbbbbbbbbffff",
      "bbbbbbbbbbbbffff",
      "bbbbbbbbbbbbffff",
      "bbbbbbbbbbbbffff",
      "bbbbbbbbbbbbffff",
      "ggggebbbbbbeffff",
      "    hbbbbbbbbbbb",
      "    hbbbbbbbbbbb",
      "    hiiiiiibbbbb",
      "    hiiiiiibbbbb"
    ],
    [
      "a   jk ll mn o o",
      "a   jp ll qn    ",
      "a   j      r    ",
      "adssj      n   t",
      "uwxye   dd eABAA",
      "        C DnE  A",
      "       FCI nE  J",
      "        C  nK  A",
      "        C  nK  J",
      "       FCI nE  A",
      "        C DnE  J",
      "LLLLe   dd eAMAA",
      "    L      n    ",
      "    L      N   O",
      "    L P  Q n  RS",
      "    L   Q Pn   T"
    ],
    [
      "a   j      n    ",
      "a   j      n    ",
      "a   j      U    ",
      "ad  j      n    ",
      "u VWe    X eAYAA",
      "        Z 0n1  A",
      "           2   3",
      "        4  2   A",
      "        Z  2   3",
      "        5  2   A",
      "          0n6  3",
      "    e      eA7AA",
      "    L      n    ",
      "    L      8    ",
      "    L      n   !",
      "    L      n    "
    ],
    [
      "a   j      n    ",
      "a   j      n    ",
      "a   j      9    ",
      "adddj      n    ",
      "u#  e      eAAAA",
      "          $n   A",
      "           2%  A",
      "           2^  A",
      "           2^  A",
      "           2&  A",
      "          $n   A",
      "    e      eAAAA",
      "    L      n    ",
      "    L      9    ",
      "    L      n    ",
      "    L      n    "
    ],
    [
      "a   j      n****",
      "a   j      n****",
      "a   j      n*(**",
      "adddj      n****",
      "uuuue      eAAAA",
      "           n))))",
      "           n))))",
      "           n))))",
      "           n))))",
      "           n))))",
      "           n))))",
      "    e      eAAAA",
      "    n      n****",
      "    n      n*+**",
      "    n      n****",
      "    n      n****"
    ],
    [
      "-   -******-    ",
      "-   -******-[[ [",
      "-   -*]**]*- {[ ",
      "-d}|-******-[[ [",
      ";;;;e;;;;;;e;;;;",
      "****-******- [  ",
      "**]*-*]**+*-::::",
      "****-******-[ :[",
      "****-******-  ::",
      "**]*-*]**+*-  :[",
      "****-******-[[::",
      ";;;;e;;;;;;e;;;;",
      "    -******- [ [",
      "    -*]**]*- {  ",
      "    -******- [  ",
      "    -******-    "
    ]
  ]
}