{
  "name": "multi_timbertower_4_floor11",
  "refpalette": "deceasedcraft:multi_timbertower_4/multi_timbertower_4_floor11_palette",
  "xsize": 16,
  "zsize": 16,
  "slices": [
    [
      "a   bbbbbbbbbbbb",
      "a   bbbbbbbbbbbb",
      "a   bbbbbbbbbbbb",
      "c ddbbbbbbbbbbbb",
      "bbbbebbbbbbebbbb",
      "bbbbbbbbbbbbbbbb",
      "ffffffffffffffff",
      "ffffffffffffffff",
      "ffffffffffffffff",
      "ffffffffffffffff",
      "bbbbbbbbbbbbbbbb",
      "bbbbebbbbbbebbbb",
      "bbbbbbbbbbbbbbbb",
      "bbbbbbbbbbbbbbbb",
      "bbbbbbbbbbbbbbbb",
      "bbbbbbbbbbbbbbbb"
    ],
    [
      "a   ag  hijklm  ",
      "a   anh  hoko   ",
      "a   app qppkpprh",
      "adssatu q wkx r ",
      "yABCeDE F qer I ",
      "     JE qKq@rKr ",
      "     LLMLLL LLLN",
      "                ",
      "                ",
      "OPOO OOQOOO OOOP",
      "r RS@JE qTq@rTr ",
      "I RDeDE U qer V ",
      "rhutktu q wkx r ",
      "rhWWkWW qWWkWWrh",
      "   XkY    okoh h",
      " hhZkg   ijklm  "
    ],
    [
      "a   a0     k    ",
      "a   a 1  23k4   ",
      "a   app qppkppr ",
      "ad  a   q5 k 6r ",
      "y 78e9E # qer $ ",
      "     JE q q@r r ",
      "     LL%LLL LLL^",
      "                ",
      "                ",
      "O&OO OO*OOO OOO&",
      "r RS@JE q q@r r ",
      "$ R9e9E ( qer ) ",
      "r  !k   q5 k 6r ",
      "r WWkWW qWWkWWr ",
      "    k     +k-[  ",
      "   ]k]     k    "
    ],
    [
      "a   a      k    ",
      "a   a    { k }  ",
      "a   app qppkppr ",
      "addda   q| k ;r ",
      "y:  eJ  q qer r ",
      "     J' q<q@r>r ",
      "     LL,LLL LLL,",
      "                ",
      "                ",
      "O.OO OO.OOO OOO.",
      "r  S@J  q?q@r?r ",
      "r  SeJ  q qer r ",
      "r  'k'  q| k ;r ",
      "r WWkWW qWWkWWr ",
      "    k    / k `  ",
      "    k      k    "
    ],
    [
      "a   a      k    ",
      "a   a'     k'   ",
      "a   app qppkppr ",
      "addda   q 'k  r ",
      "yyyyeJ  q qer r'",
      "     J' q q r\u0370r ",
      "     LLLLLL\u0371LLLL",
      "                ",
      "                ",
      "OOOO\u0372OOOOOO\u0372OOOO",
      "r 'S J  q'q!r r ",
      "r  SeJ  q qer r ",
      "r ''k'  q 'k' r ",
      "r WWkWW qWWkWWr ",
      "    k      k    ",
      "    k      k    "
    ],
    [
      "\u0373   \u0373'  \u0374  \u0373  \u0374 ",
      "\u0373   \u0373'     \u0373    ",
      "\u0373   \u0373bbbbbb\u0373bbbb",
      "\u0373d\u0375\u0376\u0373bbbbbb\u0373bbbb",
      "\u0377\u0377\u0377\u0377e\u0377\u0377\u0377\u0377\u0377\u0377e\u0377\u0377\u0377\u0377",
      "\u037a\u037a\u037a\u037a\u0373bbbbbb\u0373bbbb",
      "\u037a\u037a\u037a\u037a\u0373\u037b\u037b\u037b\u037b\u037b\u037b\u0373\u037b\u037b\u037b\u037b",
      "\u037a\u037a\u037a\u037a\u0373\u037a\u037a\u037a\u037a\u037a\u037a\u0373\u037a\u037a\u037a\u037a",
      "\u037a\u037a\u037a\u037a\u0373\u037a\u037a\u037a\u037a\u037a\u037a\u0373\u037a\u037a\u037a\u037a",
      "\u037c\u037c\u037c\u037c\u0373\u037c\u037c\u037c\u037c\u037c\u037c\u0373\u037c\u037c\u037c\u037c",
      "bbbb\u0373bbbbbb\u0373bbbb",
      "\u0377\u0377\u0377\u0377e\u0377\u0377\u0377\u0377\u0377\u0377e\u0377\u0377\u0377\u0377",
      "bbbb\u0373bbbbbb\u0373bbbb",
      "bbbb\u0373bbbbbb\u0373bbbb",
      "   '\u0373      \u0373    ",
      "    \u0373   \u0374  \u0373  \u0374 "
    ]
  ]
}