{
  "name": "multi_timbertower_4_ground",
  "refpalette": "deceasedcraft:multi_timbertower_4/multi_timbertower_4_ground_palette",
  "xsize": 16,
  "zsize": 16,
  "slices": [
    [
      "a   vvvvvvvvvvvv",
      "a   vvvvvvvvvvvv",
      "a   vvvvvvvvvvvv",
      "b ccvvvvvvvvvvvv",
      "vvvvdvvvvvvdvvvv",
      "vvvvevvvvvvvvvvv",
      "HHfgh           ",
      "HHfgh           ",
      "HHfgh           ",
      "HHfgh           ",
      "vvvvivvvvvvvvvvv",
      "    d      d    ",
      "                ",
      "                ",
      "                ",
      "                "
    ],
    [
      "a   jk     lammm",
      "a   j      nammm",
      "a   jopq   rammm",
      "acssjoq    lammm",
      "tuwxdoyoqnpdammm",
      "    Avvvvvvvvvvv",
      "                ",
      "                ",
      "                ",
      "                ",
      "BBBCAvvvvvvvvvvv",
      "    d      ddddd",
      "                ",
      "                ",
      "                ",
      "                "
    ],
    [
      "a   j       ammm",
      "a   j       ammm",
      "a   j      Dammm",
      "ac  jp      ammm",
      "t EFdIo p pdammm",
      "     vvvvvvvvvvv",
      "             JJa",
      "             JJa",
      "             JJa",
      "             JJa",
      "     vvvvvvvvvvv",
      "    d      d JJa",
      "             JJa",
      "             JJa",
      "             JJa",
      "             JJa"
    ],
    [
      "a   j    JJdmmmm",
      "a   j    JJdmmmm",
      "a   j    JJdmmmm",
      "acccj    JJdmmmm",
      "tK  ddddddddmmmm",
      "     vvvvvvdvmmm",
      "         JJdaamm",
      "         JJdaamm",
      "         JJdaamm",
      "         JJdaamm",
      "     vvvvvvdvmmm",
      "    ddddddddammm",
      "         JJdammm",
      "         JJdammm",
      "         JJdammm",
      "         JJdammm"
    ],
    [
      "a   LJJaammmm   ",
      "a   LJJaammmm   ",
      "a   LJJaammmm   ",
      "acccLJJaammmm   ",
      "ttttdJJaammdmM  ",
      "     vvvvmmmm   ",
      "     JJaammmmN  ",
      "     JJaammmmN  ",
      "     JJaammmmN  ",
      "     JJaammmmN  ",
      "     vvvvmmmm   ",
      "    dJJaammdm   ",
      "     JJaammmm   ",
      "     JJaammmm   ",
      "     JJaammmm   ",
      "     JJaammmm   "
    ],
    [
      "d   dmmmm       ",
      "d   dmmmm       ",
      "d   dmmmm       ",
      "dcOPdmmmmQ M    ",
      "dddddmmmm  d    ",
      "JJJJdmmmm M Q   ",
      "JJJJdmmmmN      ",
      "JJJJdmmmmN      ",
      "JJJJdmmmmN      ",
      "JJJJdmmmmN      ",
      "JJJJdmmmm       ",
      "dddddmmmm  d    ",
      "JJJJdmmmm Q     ",
      "JJJJdmmmm       ",
      "JJJJdmmmm       ",
      "JJJJdmmmm       "
    ]
  ]
}