{
  "name": "multi_timbertower_4_floor7",
  "refpalette": "deceasedcraft:multi_timbertower_4/multi_timbertower_4_floor7_palette",
  "xsize": 16,
  "zsize": 16,
  "slices": [
    [
      "a   b===========",
      "a   b===========",
      "a   b===========",
      "c ddb===========",
      "bbbbe======e====",
      "bbbbf===========",
      "bbbbf===========",
      "ggggh===========",
      "iiiii===========",
      "iiiii===========",
      "iiiii===========",
      "iiiie======e====",
      "iiiii===========",
      "iiiii===========",
      "iiiii========jjj",
      "iiiii========jjj"
    ],
    [
      "a   akzlmzkzzzkm",
      "a   annnnnnnnnnn",
      "a   ao          ",
      "adppao          ",
      "qrsteuuqquue   w",
      "     o  oii     ",
      "        iix     ",
      "      oiiiyA    ",
      "     iiiiiy     ",
      "     iiiiixy    ",
      "     iiiiixA    ",
      "    eiiiiiie    ",
      "    iiiiiiBCA   ",
      "    iiiiiiiDE  F",
      "I   iiiiiiJKL   ",
      "    iiiiiiiJM   "
    ],
    [
      "a   aN   OoO Oo ",
      "a   aP P P P P P",
      "a   ao          ",
      "ad  a           ",
      "q QReuuqquue w w",
      "         oii    ",
      "        oii     ",
      "       iii      ",
      "       iiiy     ",
      "       iiixS    ",
      "       iiii     ",
      "    e  iiiie    ",
      "       iiiiT   T",
      "       iiiiL    ",
      "U     iiiiJ T   ",
      "     ViiiiiD    "
    ],
    [
      "a   ao          ",
      "a   a           ",
      "a   a           ",
      "addda           ",
      "qW  euuuuuueww w",
      "          oi    ",
      "         ii     ",
      "         ii     ",
      "         ii     ",
      "         ii     ",
      "         ii     ",
      "    e    iie    ",
      "         iiiT  X",
      "         iiT  T ",
      "V        ii X   ",
      "        IiiY T T"
    ],
    [
      "a   a           ",
      "a   a           ",
      "a   ao          ",
      "adddao          ",
      "qqqqeuuuuuueZZZZ",
      "           i    ",
      "          oi    ",
      "         0 i    ",
      "           ii   ",
      "           ii   ",
      "           ii   ",
      "    e     1ei   ",
      "          1iiiTX",
      "V          ii X ",
      "V1         iiT T",
      "V       U 0iiX X"
    ],
    [
      "2   233333323333",
      "2   233333323333",
      "2   233333323333",
      "2ddd233333323333",
      "4444e444444e4444",
      "            i  i",
      "            i  i",
      "            ii i",
      "             iii",
      "             iii",
      "             iii",
      "    e      eViii",
      "           1 iii",
      "V            iii",
      "VV          0iii",
      "1       V    iJi"
    ]
  ]
}