{
  "name": "multi_courtyardofficetower_14_base1",
  "refpalette": "deceasedcraft:multi_courtyardofficetower_14/multi_courtyardofficetower_14_base1_palette",
  "xsize": 16,
  "zsize": 16,
  "slices": [
    [
      "aaaaaaaaaaaaaaav",
      "aaaaaaaaaaaaaaav",
      "aaaaaaaaaaaaaaav",
      "aaaaaaaaaaaaaaav",
      "aaaaaaaaaaaaaaav",
      "aaaaaaaaaaaaaaav",
      "aaaaaaaaaaaaaaav",
      "aaaaaaaaaaaaaaav",
      "aaaaaaaaaaaaaaav",
      "aaaaaaaaaaaaaaav",
      "aaaaaaaaaaaaaaav",
      "aaaaaaaaaaaaaaav",
      "aaaaaaaaaaaaaaav",
      "aaaaaaaaaaaaaaav",
      "aaaaaaaaaaaaaaav",
      "aaaaaaaaaaaaaaav"
    ],
    [
      "aaaaaaaaaaaaaaav",
      "aaaaaaaaaaaaaaav",
      "aaaaaaaaaaaaaaav",
      "vvvaaaaaaaaaaaav",
      "b!bvaaaaaaaaaaav",
      "bbbvaaaaaaaaaaav",
      "bbbvaaaaaaaaaaav",
      "bbbvaaaaaaaaaaav",
      "bbbvaaaaaaaaaaav",
      "bbbvaaaaaaaaaaav",
      "bbbvaaaaaaaaaaav",
      "bbbvaaaaaaaaaaav",
      "bbbvaaaaaaaaaaav",
      "bbbvaaaaaaaaaaav",
      "bbbvaaaaaaaaaaav",
      "vvvvaaaaaaaaaaav"
    ],
    [
      "aavvvvvvvaaaaaav",
      "aavvvvvvvaaaaaav",
      "aaaaaaaaaaaaaaav",
      "vvvaaaaaaaaaaaav",
      "cccvaaaaaaaaaaav",
      "   vaaaaaaaaaaav",
      "  dvaaaaaaaaaaav",
      "  evaaaaaaaaaaav",
      "  fvaaaaaaaaaaav",
      "  gvaaaaaaaaaaav",
      "   vaaaaaaaaaaav",
      " h vaaaaaaaaaaav",
      "ijivaaaaaaaaaaav",
      "kjkvaaaaaaaaaaav",
      "kkkvaaaaaaaaaaav",
      "vvvvaaaaaaaaaaav"
    ],
    [
      "aavlHHHlvaaaaaav",
      "aavlHHHlvaaaaaav",
      "aavvvvvvvaaaaaav",
      "vvvvvvvvvvaaaaav",
      "m  vvvvvvvaaaaav",
      "   vaaaaaaaaaaav",
      "   vaaaaaaaaaaav",
      "   vaaaaaaaaaaav",
      "   vaaaaaaaaaaav",
      "   vaaaaaaaaaaav",
      "   vaaaaaaaaaaav",
      "nnnvaaaaaaaaaaav",
      "kokvaaaaaaaaaaav",
      "kpkvaaaaaaaaaaav",
      "kkkvaaaaaaaaaaav",
      "vvvvaaaaaaaaaaav"
    ],
    [
      "aav     vaaaaaav",
      "aavqrrrqvaaaaaav",
      "aavstttsvaaaaaav",
      "vvvlHHHllvaaaaav",
      "uuuvHHHHlvaaaaav",
      "uuuvvvvvvvaaaaav",
      "uuuvvvvvvvaaaaav",
      "uuuvvvvvvvaaaaav",
      "uuuvaaaaaaaaaaav",
      "uuuvaaaaaaaaaaav",
      "uuuvaaaaaaaaaaav",
      "uuuvaaaaaaaaaaav",
      "w wvaaaaaaaaaaav",
      " x vaaaaaaaaaaav",
      "w wvaaaaaaaaaaav",
      "vvvvaaaaaaaaaaav"
    ],
    [
      "aav     vaaaaaav",
      "aav     vaaaaaav",
      "aav     vaaaaaav",
      "aav      vaaaaav",
      "aavqrrrrqvaaaaav",
      "aavsttttsvaaaaav",
      "aavlHHHHlvaaaaav",
      "aavllHHHlvaaaaav",
      "aaavvvvvvvaaaaav",
      "aaavvvvvvvaaaaav",
      "aaavvvvvvvaaaaav",
      "aaavvvvvvvvaaaav",
      "aaavvvvvvvvaaaav",
      "aaavvvvvvvvaaaav",
      "aaavvvvvvvvaaaav",
      "vvvvvvvvvvvaaaav"
    ]
  ]
}