{
  "name": "multi_nuclearpowerplant_10_top",
  "refpalette": "deceasedcraft:multi_nuclearpowerplant_10/multi_nuclearpowerplant_10_top_palette",
  "xsize": 16,
  "zsize": 16,
  "slices": [
    [
      "             abb",
      "             abb",
      "            abb=",
      "            ab= ",
      "            bb= ",
      "           cbb= ",
      "           cb=  ",
      "           cb=  ",
      "           cb=  ",
      "           cb=  ",
      "           cbb= ",
      "            bb= ",
      "            ab= ",
      "            abb=",
      "             abb",
      "             abb"
    ],
    [
      "d            abb",
      " e           abb",
      "            abb=",
      "            ab= ",
      "            bb= ",
      "           cbb= ",
      "           cb=  ",
      "           cb=  ",
      "           cb=  ",
      "           cb=  ",
      "           cbb= ",
      "            bb= ",
      "            ab= ",
      "            abb=",
      " e           abb",
      "d            abb"
    ],
    [
      "dff           bb",
      "df           abb",
      "df           bb=",
      "ff          ab= ",
      "f           bb= ",
      "f           bb= ",
      "f          cb=  ",
      "f          cb=  ",
      "f          cb=  ",
      "f          cb=  ",
      "f           bb= ",
      "f           bb= ",
      "ff          ab= ",
      "df           bb=",
      "df           abb",
      "dff           bb"
    ],
    [
      "zff           ab",
      "zf           abb",
      "zf           bb=",
      "ff          ab= ",
      "f           ab= ",
      "f           bb= ",
      "f          cb=  ",
      "f          cb=  ",
      "f          cb=  ",
      "f          cb=  ",
      "f           bb= ",
      "f           ab= ",
      "ff          ab= ",
      "zf           bb=",
      "zf           abb",
      "zff           ab"
    ],
    [
      "ghh           ab",
      " h            bb",
      "ih           bb=",
      "hh           b= ",
      "h           ab= ",
      "h           bb= ",
      "h           b=  ",
      "h           b=  ",
      "h           b=  ",
      "h           b=  ",
      "h           bb= ",
      "h           ab= ",
      "hh           b= ",
      "ih           bb=",
      " h            bb",
      "ihh           ab"
    ],
    [
      "              ab",
      "              bb",
      "             bb=",
      "             b= ",
      "            ab= ",
      "            bb= ",
      "            b=  ",
      "            b=  ",
      "            b=  ",
      "            b=  ",
      "            bb= ",
      "            ab= ",
      "             b= ",
      "             bb=",
      "              bb",
      "              ab"
    ],
    [
      "              ab",
      "              bb",
      "             bb=",
      "             b= ",
      "            ab= ",
      "            bb= ",
      "            b=  ",
      "            b=  ",
      "            b=  ",
      "            b=  ",
      "            bb= ",
      "            ab= ",
      "             b= ",
      "             bb=",
      "              bb",
      "              ab"
    ],
    [
      "              ab",
      "              bb",
      "             bb=",
      "             b= ",
      "            ab= ",
      "            bb= ",
      "            b=  ",
      "            b=  ",
      "            b=  ",
      "            b=  ",
      "            bb= ",
      "            ab= ",
      "             b= ",
      "             bb=",
      "              bb",
      "              ab"
    ],
    [
      "               b",
      "              bb",
      "             bb=",
      "             b= ",
      "             b= ",
      "            bb= ",
      "            b=  ",
      "            b=  ",
      "            b=  ",
      "            b=  ",
      "            bb= ",
      "             b= ",
      "             b= ",
      "             bb=",
      "              bb",
      "               b"
    ],
    [
      "               b",
      "              bb",
      "             bb=",
      "             b= ",
      "             b= ",
      "            bb= ",
      "            b=  ",
      "            b=  ",
      "            b=  ",
      "            b=  ",
      "            bb= ",
      "             b= ",
      "             b= ",
      "             bb=",
      "              bb",
      "               b"
    ],
    [
      "               b",
      "              bb",
      "             bb=",
      "             b= ",
      "             b= ",
      "            bb= ",
      "            b=  ",
      "            b=  ",
      "            b=  ",
      "            b=  ",
      "            bb= ",
      "             b= ",
      "             b= ",
      "             bb=",
      "              bb",
      "               b"
    ],
    [
      "               b",
      "              bb",
      "             bb=",
      "             b= ",
      "             b= ",
      "            bb= ",
      "            b=  ",
      "            b=  ",
      "            b=  ",
      "            b=  ",
      "            bb= ",
      "             b= ",
      "             b= ",
      "             bb=",
      "              bb",
      "               b"
    ],
    [
      "               b",
      "              bb",
      "             bb=",
      "             b= ",
      "             b= ",
      "            bb= ",
      "            b=  ",
      "            b=  ",
      "            b=  ",
      "            b=  ",
      "            bb= ",
      "             b= ",
      "             b= ",
      "             bb=",
      "              bb",
      "               b"
    ],
    [
      "               b",
      "              bb",
      "             bb=",
      "             b= ",
      "             b= ",
      "            bb= ",
      "            b=  ",
      "            b=  ",
      "            b=  ",
      "            b=  ",
      "            bb= ",
      "             b= ",
      "             b= ",
      "             bb=",
      "              bb",
      "               b"
    ],
    [
      "               b",
      "              bb",
      "             bb=",
      "             b= ",
      "             b= ",
      "            bb= ",
      "            b=  ",
      "            b=  ",
      "            b=  ",
      "            b=  ",
      "            bb= ",
      "             b= ",
      "             b= ",
      "             bb=",
      "              bb",
      "               b"
    ],
    [
      "              ab",
      "              bb",
      "             bb=",
      "             b= ",
      "            ab= ",
      "            bb= ",
      "            b=  ",
      "            b=  ",
      "            b=  ",
      "            b=  ",
      "            bb= ",
      "            ab= ",
      "             b= ",
      "             bb=",
      "              bb",
      "              ab"
    ],
    [
      "              ab",
      "              bb",
      "             bb=",
      "             b= ",
      "            ab= ",
      "            bb= ",
      "            b=  ",
      "            b=  ",
      "            b=  ",
      "            b=  ",
      "            bb= ",
      "            ab= ",
      "             b= ",
      "             bb=",
      "              bb",
      "              ab"
    ],
    [
      "              bb",
      "              bb",
      "             bb=",
      "             b= ",
      "            bb= ",
      "            bb= ",
      "            b=  ",
      "            b=  ",
      "            b=  ",
      "            b=  ",
      "            bb= ",
      "            bb= ",
      "             b= ",
      "             bb=",
      "              bb",
      "              bb"
    ],
    [
      "              bb",
      "             cbb",
      "             bb=",
      "            cb= ",
      "            bb= ",
      "           cbb= ",
      "           cb=  ",
      "           cb=  ",
      "           cb=  ",
      "           cb=  ",
      "           cbb= ",
      "            bb= ",
      "            cb= ",
      "             bb=",
      "             cbb",
      "              bb"
    ],
    [
      "              bb",
      "             cbb",
      "             bb=",
      "            cb= ",
      "            bb= ",
      "           cbb= ",
      "           cb=  ",
      "           cb=  ",
      "           cb=  ",
      "           cb=  ",
      "           cbb= ",
      "            bb= ",
      "            cb= ",
      "             bb=",
      "             cbb",
      "              bb"
    ],
    [
      "             bbj",
      "             bjj",
      "            bbj ",
      "            bj  ",
      "           bbj  ",
      "           bjj  ",
      "           bj   ",
      "           bj   ",
      "           bj   ",
      "           bj   ",
      "           bjj  ",
      "           bbj  ",
      "            bj  ",
      "            bbj ",
      "             bjj",
      "             bbj"
    ]
  ]
}