{
  "name": "multi_nuclearpowerplant_10_ground",
  "refpalette": "deceasedcraft:multi_nuclearpowerplant_10/multi_nuclearpowerplant_10_ground_palette",
  "xsize": 16,
  "zsize": 16,
  "slices": [
    [
      "             aa=",
      "             a==",
      "            aa= ",
      "            a=  ",
      "           aa=  ",
      "           a==  ",
      "           a=   ",
      "           a=   ",
      "           a=   ",
      "           a=   ",
      "           a==  ",
      "           aa=  ",
      "            a=  ",
      "            aa= ",
      "             a==",
      "             aa="
    ],
    [
      "             aa=",
      "             a==",
      "            aa= ",
      "            a=  ",
      "           aa=  ",
      "           a==  ",
      "           a=   ",
      "           a=   ",
      "           a=   ",
      "           a=   ",
      "           a==  ",
      "           aa=  ",
      "            a=  ",
      "            aa= ",
      "             a==",
      "             aa="
    ],
    [
      "             aa=",
      "             a==",
      "            aa= ",
      "            a=  ",
      "           aa=  ",
      "           a==  ",
      "           a=   ",
      "           a=   ",
      "           a=   ",
      "           a=   ",
      "           a==  ",
      "           aa=  ",
      "            a=  ",
      "            aa= ",
      "             a==",
      "             aa="
    ],
    [
      "             aa=",
      "             a==",
      "            aa= ",
      "            a=  ",
      "           aa=  ",
      "           a==  ",
      "           a=   ",
      "           a=   ",
      "           a=   ",
      "           a=   ",
      "           a==  ",
      "           aa=  ",
      "            a=  ",
      "            aa= ",
      "             a==",
      "             aa="
    ],
    [
      "             aa=",
      "             a==",
      "            aa= ",
      "            a=  ",
      "           aa=  ",
      "           a==  ",
      "           a=   ",
      "           a=   ",
      "           a=   ",
      "           a=   ",
      "           a==  ",
      "           aa=  ",
      "            a=  ",
      "            aa= ",
      "             a==",
      "             aa="
    ],
    [
      "             baa",
      "             baa",
      "            baa=",
      "            ba= ",
      "            aa= ",
      "           caa= ",
      "           ca=  ",
      "           ca=  ",
      "           ca=  ",
      "           ca=  ",
      "           caa= ",
      "            aa= ",
      "            ba= ",
      "            baa=",
      "             baa",
      "             baa"
    ]
  ]
}