{
  "name": "multi_nuclearpowerplant_10_base7",
  "refpalette": "deceasedcraft:multi_nuclearpowerplant_10/multi_nuclearpowerplant_10_base7_palette",
  "xsize": 16,
  "zsize": 16,
  "slices": [
    [
      "a     bcdddddddd",
      "a    bccdddddddd",
      "a    bcddddddddd",
      "a    bcddddddddd",
      "a   bccddddddddd",
      "a   bcdddddddddd",
      "a   bcdddddddddd",
      "a   bcdddddddddd",
      "a   bcdddddddddd",
      "a   bcdddddddddd",
      "a   bcdddddddddd",
      "a   bccddddddddd",
      "a    bcddddddddd",
      "a    bcddddddddd",
      "a    bccdddddddd",
      "a     bcdddddddd"
    ],
    [
      "a     bcdddddddd",
      "a    bccdddddddd",
      "a    bcddddddddd",
      "a    bcddddddddd",
      "a   bccddddddddd",
      "a   bcdddddddddd",
      "e   fcdddddddddd",
      "egggfcdddddddddd",
      "egggfcdddddddddd",
      "e   fcdddddddddd",
      "a   bcdddddddddd",
      "a   bccddddddddd",
      "a    bcddddddddd",
      "a    bcddddddddd",
      "a    bccdddddddd",
      "a     bcdddddddd"
    ],
    [
      "a     bcdddddddd",
      "a    bccdddddddd",
      "a    bcddddddddd",
      "a    bcddddddddd",
      "a   bccddddddddd",
      "a   bcdddddddddd",
      "ehhhfcdddddddddd",
      "dddddddddddddddd",
      "dddddddddddddddd",
      "eiiifcdddddddddd",
      "a   bcdddddddddd",
      "a   bccddddddddd",
      "a    bcddddddddd",
      "a    bcddddddddd",
      "a    bccdddddddd",
      "a     bcdddddddd"
    ],
    [
      "a     bcdddddddd",
      "a    bccdddddddd",
      "a    bcddddddddd",
      "a    bcddddddddd",
      "a   bccddddddddd",
      "a   bcdddddddddd",
      "ehhhfcdddddddddd",
      "dddddddddddddddd",
      "dddddddddddddddd",
      "eiiifcdddddddddd",
      "a   bcdddddddddd",
      "a   bccddddddddd",
      "a    bcddddddddd",
      "a    bcddddddddd",
      "a    bccdddddddd",
      "a     bcdddddddd"
    ],
    [
      "a     bcjddjdddd",
      "a    bcckddddddd",
      "a    bcddddddddd",
      "a    bckjddddddd",
      "a   bccjdjdddddd",
      "a   bckddddddddd",
      "e   fckddddddddd",
      "elllfcdjdddddddd",
      "elllfcdddddddddd",
      "e   fcddkddddddd",
      "a   bcjdddjddddd",
      "a   bccjjddddddd",
      "a    bckjjdddddd",
      "a    bckkjdddddd",
      "a    bccdddddddd",
      "a     bckjdddddd"
    ],
    [
      "ammmnn c        ",
      "ammmn cc        ",
      "ammmn c         ",
      "ammno c         ",
      "ammn cc         ",
      "ammn c          ",
      "ammn c          ",
      "ammn c          ",
      "ammn c          ",
      "ammn c          ",
      "ammn c          ",
      "ammn cc         ",
      "ammno c         ",
      "ammmn c         ",
      "ammmn cc        ",
      "ammmnn c        "
    ]
  ]
}