{
  "name": "multi_nuclearpowerplant_10_base4",
  "refpalette": "deceasedcraft:multi_nuclearpowerplant_10/multi_nuclearpowerplant_10_base4_palette",
  "xsize": 16,
  "zsize": 16,
  "slices": [
    [
      "         ab==  c",
      "         bb=   c",
      "        ab=    c",
      "        ab=    c",
      "        bb=dddde",
      "       ab=cfffff",
      "       ab= gggge",
      "       ab=     c",
      "       ab=     c",
      "       ab= dddde",
      "       ab=cfffff",
      "        bb=gggge",
      "        ab=    c",
      "        ab=    c",
      "         bb=   c",
      "         ab==  c"
    ],
    [
      "         ab==   ",
      "         bb=    ",
      "        ab=     ",
      "        ab=     ",
      "        bb=     ",
      "       ab=      ",
      "       ab=      ",
      "       ab=      ",
      "       ab=      ",
      "       ab=      ",
      "       ab=      ",
      "        bb=     ",
      "        ab=     ",
      "        ab=     ",
      "         bb=    ",
      "         ab==   "
    ],
    [
      "          b==   ",
      "         bb=    ",
      "         b=     ",
      "         b=     ",
      "        bb=     ",
      "        b=      ",
      "        b=      ",
      "        b=      ",
      "        b=      ",
      "        b=      ",
      "        b=      ",
      "        bb=     ",
      "         b=     ",
      "         b=     ",
      "         bb=    ",
      "          b==   "
    ],
    [
      "          hbb=  ",
      "          bb=   ",
      "         ab==   ",
      "         ab=    ",
      "         bb=    ",
      "        ab=     ",
      "        ab=     ",
      "        ab=     ",
      "        ab=     ",
      "        ab=     ",
      "        ab=     ",
      "         bb=    ",
      "         ab=    ",
      "         ab==   ",
      "          bb=   ",
      "          hbb=  "
    ],
    [
      "          hbb=  ",
      "          bb=   ",
      "         ab==   ",
      "         ab=    ",
      "         bb=    ",
      "        ab=     ",
      "        ab=     ",
      "        ab=     ",
      "        ab=     ",
      "        ab=     ",
      "        ab=     ",
      "         bb=    ",
      "         ab=    ",
      "         ab==   ",
      "          bb=   ",
      "          hbb=  "
    ],
    [
      "          hbb=  ",
      "          bb=   ",
      "         ab==   ",
      "         ab=    ",
      "         bb=    ",
      "        ab=     ",
      "        ab=     ",
      "        ab=     ",
      "        ab=     ",
      "        ab=     ",
      "        ab=     ",
      "         bb=    ",
      "         ab=    ",
      "         ab==   ",
      "          bb=   ",
      "          hbb=  "
    ]
  ]
}