{
  "name": "multi_nuclearpowerplant_10_base8",
  "refpalette": "deceasedcraft:multi_nuclearpowerplant_10/multi_nuclearpowerplant_10_base8_palette",
  "xsize": 16,
  "zsize": 16,
  "slices": [
    [
      "aaaaabc==defeeee",
      "aaaabc==d  g    ",
      "aaaabc==d  g    ",
      "aaaabc==d  g    ",
      "aaabc==d   g    ",
      "aaabc==dhhhfhhhh",
      "aaabc==d   g    ",
      "aaabc==d   g    ",
      "aaabc==d   g    ",
      "aaabc==d   g    ",
      "aaabc==dhhhfhhhh",
      "aaabc==d   g    ",
      "aaaabc==d  g    ",
      "aaaabc==d  g    ",
      "aaaabc==d  g    ",
      "aaaaabc==defeeee"
    ],
    [
      "i=====jdkkkkkkkk",
      "i====jddkkkkkkkk",
      "i====jdkkkkkkkkk",
      "i====jdkkkkkkkkk",
      "i===jddkkkkkkkkk",
      "i===jdkkkkkkkkkk",
      "i===jdkkkkkkkkkk",
      "i===jdkkkkkkkkkk",
      "i===jdkkkkkkkkkk",
      "i===jdkkkkkkkkkk",
      "i===jdkkkkkkkkkk",
      "i===jddkkkkkkkkk",
      "i====jdkkkkkkkkk",
      "i====jdkkkkkkkkk",
      "i====jddkkkkkkkk",
      "i=====jdkkkkkkkk"
    ],
    [
      "lmmmmmndoooooooo",
      "lmmmmnddoooooooo",
      "lmmmmndooooooooo",
      "lmmmmndooooooooo",
      "lmmmnddooooooooo",
      "lmmmndoooooooooo",
      "lmmmndoooooooooo",
      "lmmmndoooooooooo",
      "lmmmndoooooooooo",
      "lmmmndoooooooooo",
      "lmmmndoooooooooo",
      "lmmmnddooooooooo",
      "lmmmmndooooooooo",
      "lmmmmndooooooooo",
      "lmmmmnddoooooooo",
      "lmmmmmndoooooooo"
    ],
    [
      "lmmmmmndoooooooo",
      "lmmmmnddoooooooo",
      "lmmmmndooooooooo",
      "lmmmmndooooooooo",
      "lmmmnddooooooooo",
      "lmmmndoooooooooo",
      "lmmmndoooooooooo",
      "lmmmndoooooooooo",
      "lmmmndoooooooooo",
      "lmmmndoooooooooo",
      "lmmmndoooooooooo",
      "lmmmnddooooooooo",
      "lmmmmndooooooooo",
      "lmmmmndooooooooo",
      "lmmmmnddoooooooo",
      "lmmmmmndoooooooo"
    ],
    [
      "liiippjdoooooooo",
      "liiipjddoooooooo",
      "liiipjdooooooooo",
      "liippjdooooooooo",
      "liipjddooooooooo",
      "liipjdoooooooooo",
      "liipjdoooooooooo",
      "liipjdoooooooooo",
      "liipjdoooooooooo",
      "liipjdoooooooooo",
      "liipjdoooooooooo",
      "liipjddooooooooo",
      "liippjdooooooooo",
      "liiipjdooooooooo",
      "liiipjddoooooooo",
      "liiippjdoooooooo"
    ],
    [
      "l     ndoooooooo",
      "l    nddoooooooo",
      "l    ndooooooooo",
      "l    ndooooooooo",
      "l   nddooooooooo",
      "l   ndoooooooooo",
      "l   ndoooooooooo",
      "l   ndoooooooooo",
      "l   ndoooooooooo",
      "l   ndoooooooooo",
      "l   ndoooooooooo",
      "l   nddooooooooo",
      "l    ndooooooooo",
      "l    ndooooooooo",
      "l    nddoooooooo",
      "l     ndoooooooo"
    ]
  ]
}