{
  "name": "multi_nuclearpowerplant_10_base1",
  "refpalette": "deceasedcraft:multi_nuclearpowerplant_10/multi_nuclearpowerplant_10_base1_palette",
  "xsize": 16,
  "zsize": 16,
  "slices": [
    [
      "ab           cc=",
      "bb          dc==",
      "b           cc= ",
      "b          dc=  ",
      "b          cc=  ",
      "b         dc==  ",
      "b         dc=   ",
      "b         dc=   ",
      "b         dc=   ",
      "b         dc=   ",
      "b         dc==  ",
      "b          cc=  ",
      "b          dc=  ",
      "b           cc= ",
      "bb          dc==",
      "ab           cc="
    ],
    [
      " e           cc=",
      "ee          dc==",
      "e           cc= ",
      "e          dc=  ",
      "e          cc=  ",
      "e         dc==  ",
      "e         dc=   ",
      "e         dc=   ",
      "e         dc=   ",
      "e         dc=   ",
      "e         dc==  ",
      "e          cc=  ",
      "e          dc=  ",
      "e           cc= ",
      "ee          dc==",
      " e           cc="
    ],
    [
      "             cc=",
      "            dc==",
      "            cc= ",
      "           dc=  ",
      "           cc=  ",
      "          dc==  ",
      "          dc=   ",
      "          dc=   ",
      "          dc=   ",
      "          dc=   ",
      "          dc==  ",
      "           cc=  ",
      "           dc=  ",
      "            cc= ",
      "            dc==",
      "             cc="
    ],
    [
      "             cc=",
      "             c==",
      "            cc= ",
      "            c=  ",
      "           cc=  ",
      "           c==  ",
      "           c=   ",
      "           c=   ",
      "           c=   ",
      "           c=   ",
      "           c==  ",
      "           cc=  ",
      "            c=  ",
      "            cc= ",
      "             c==",
      "             cc="
    ],
    [
      "             cc=",
      "             c==",
      "            cc= ",
      "            c=  ",
      "           cc=  ",
      "           c==  ",
      "           c=   ",
      "           c=   ",
      "           c=   ",
      "           c=   ",
      "           c==  ",
      "           cc=  ",
      "            c=  ",
      "            cc= ",
      "             c==",
      "             cc="
    ],
    [
      "             cc=",
      "             c==",
      "            cc= ",
      "            c=  ",
      "           cc=  ",
      "           c==  ",
      "           c=   ",
      "           c=   ",
      "           c=   ",
      "           c=   ",
      "           c==  ",
      "           cc=  ",
      "            c=  ",
      "            cc= ",
      "             c==",
      "             cc="
    ]
  ]
}