{
  "name": "multi_nuclearpowerplant_10_base9",
  "refpalette": "deceasedcraft:multi_nuclearpowerplant_10/multi_nuclearpowerplant_10_base9_palette",
  "xsize": 16,
  "zsize": 16,
  "slices": [
    [
      "                ",
      "                ",
      "                ",
      "                ",
      "                ",
      "                ",
      "                ",
      "                ",
      "                ",
      "                ",
      "                ",
      "                ",
      "                ",
      "                ",
      "                ",
      "                "
    ],
    [
      "                ",
      "                ",
      "                ",
      "                ",
      "                ",
      "                ",
      "                ",
      "                ",
      "                ",
      "                ",
      "                ",
      "                ",
      "                ",
      "                ",
      "                ",
      "                "
    ],
    [
      "                ",
      "                ",
      "                ",
      "                ",
      "                ",
      "                ",
      "                ",
      "                ",
      "                ",
      "                ",
      "                ",
      "                ",
      "                ",
      "                ",
      "                ",
      "                "
    ],
    [
      "        aaaaaaaa",
      "       aaaaaaaaa",
      "       aaaaaaaaa",
      "       aaaaaaaaa",
      "      aaaaaaaaaa",
      "      aaaaaaaaaa",
      "      aaaaaaaaaa",
      "      aaaaaaaaaa",
      "      aaaaaaaaaa",
      "      aaaaaaaaaa",
      "      aaaaaaaaaa",
      "      aaaaaaaaaa",
      "       aaaaaaaaa",
      "       aaaaaaaaa",
      "       aaaaaaaaa",
      "        aaaaaaaa"
    ],
    [
      "        bcdef  d",
      "       bc  g    ",
      "       bc       ",
      "       bc       ",
      "      bc   h    ",
      "      bc  def  d",
      "      bc   g    ",
      "      bc        ",
      "      bc        ",
      "      bc   h    ",
      "      bc  def  d",
      "      bc   g    ",
      "       bc       ",
      "       bc       ",
      "       bc  h    ",
      "        bcdef  d"
    ],
    [
      "       b=c e    ",
      "      b=c       ",
      "      b=c       ",
      "      b=c       ",
      "     b=c        ",
      "     b=c   e    ",
      "     b=c        ",
      "     b=c        ",
      "     b=c        ",
      "     b=c        ",
      "     b=c   e    ",
      "     b=c        ",
      "      b=c       ",
      "      b=c       ",
      "      b=c       ",
      "       b=c e    "
    ]
  ]
}