{
  "name": "multi_nuclearpowerplant_10_base2",
  "refpalette": "deceasedcraft:multi_nuclearpowerplant_10/multi_nuclearpowerplant_10_base2_palette",
  "xsize": 16,
  "zsize": 16,
  "slices": [
    [
      "            aa= ",
      "           ba=  ",
      "           aa=  ",
      "          ca=   ",
      "          aa=   ",
      "         ca=    ",
      "         ca=    ",
      "         ca=    ",
      "         ca=    ",
      "         ca=    ",
      "         ca=    ",
      "          aa=   ",
      "          ca=   ",
      "           aa=  ",
      "           ba=  ",
      "            aa= "
    ],
    [
      "            aa= ",
      "           ba=  ",
      "           aa=  ",
      "           a=   ",
      "          aa=   ",
      "          a=    ",
      "          a=    ",
      "          a=    ",
      "          a=    ",
      "          a=    ",
      "          a=    ",
      "          aa=   ",
      "           a=   ",
      "           aa=  ",
      "           ba=  ",
      "            aa= "
    ],
    [
      "            aa= ",
      "            a=  ",
      "           aa=  ",
      "           a=   ",
      "          aa=   ",
      "          a=    ",
      "          a=    ",
      "          a=    ",
      "          a=    ",
      "          a=    ",
      "          a=    ",
      "          aa=   ",
      "           a=   ",
      "           aa=  ",
      "            a=  ",
      "            aa= "
    ],
    [
      "            aa= ",
      "            a=  ",
      "           aa=  ",
      "           a=   ",
      "          aa=   ",
      "          a=    ",
      "          a=    ",
      "          a=    ",
      "          a=    ",
      "          a=    ",
      "          a=    ",
      "          aa=   ",
      "           a=   ",
      "           aa=  ",
      "            a=  ",
      "            aa= "
    ],
    [
      "             aa=",
      "            ca==",
      "            aa= ",
      "           ca=  ",
      "           aa=  ",
      "          ca==  ",
      "          ca=   ",
      "          ca=   ",
      "          ca=   ",
      "          ca=   ",
      "          ca==  ",
      "           aa=  ",
      "           ca=  ",
      "            aa= ",
      "            ca==",
      "             aa="
    ],
    [
      "d            aa=",
      "            ca==",
      "            aa= ",
      "           ca=  ",
      "           aa=  ",
      "          ca==  ",
      "          ca=   ",
      "          ca=   ",
      "          ca=   ",
      "          ca=   ",
      "          ca==  ",
      "           aa=  ",
      "           ca=  ",
      "            aa= ",
      "            ca==",
      "d            aa="
    ]
  ]
}