{
  "name": "multi_nuclearpowerplant_10_base5",
  "refpalette": "deceasedcraft:multi_nuclearpowerplant_10/multi_nuclearpowerplant_10_base5_palette",
  "xsize": 16,
  "zsize": 16,
  "slices": [
    [
      "        =       ",
      "                ",
      "                ",
      "       =        ",
      "                ",
      "                ",
      "      =         ",
      "                ",
      "                ",
      "      =         ",
      "                ",
      "                ",
      "       =        ",
      "                ",
      "                ",
      "        =       "
    ],
    [
      "         a      ",
      "                ",
      "                ",
      "        b       ",
      "        a       ",
      "       b        ",
      "       a        ",
      "                ",
      "                ",
      "       b        ",
      "       a        ",
      "        b       ",
      "        a       ",
      "                ",
      "                ",
      "         b      "
    ],
    [
      "                ",
      "                ",
      "                ",
      "                ",
      "        =       ",
      "       =        ",
      "                ",
      "                ",
      "                ",
      "                ",
      "       =        ",
      "        =       ",
      "                ",
      "                ",
      "                ",
      "                "
    ],
    [
      "        cdefffff",
      "       ccdefffff",
      "       cdeffffff",
      "       cdeffffff",
      "      cc=fffffff",
      "      c=efffffff",
      "      cdefffffff",
      "      cdefffffff",
      "      cdefffffff",
      "      cdefffffff",
      "      c=efffffff",
      "      cc=fffffff",
      "       cdeffffff",
      "       cdeffffff",
      "       ccdefffff",
      "        cdefffff"
    ],
    [
      "        gh=     ",
      "        hh=     ",
      "       gh=      ",
      "       gh=      ",
      "       hh=      ",
      "      gh=       ",
      "      gh=       ",
      "      gh=       ",
      "      gh=       ",
      "      gh=       ",
      "      gh=       ",
      "       hh=      ",
      "       gh=      ",
      "       gh=      ",
      "        hh=     ",
      "        gh=     "
    ],
    [
      "         h=    i",
      "        hh=     ",
      "        h=      ",
      "        h=      ",
      "       hh= j    ",
      "       h= i~kllm",
      "       h=  n    ",
      "       h=       ",
      "       h=       ",
      "       h=  j    ",
      "       h= i~kllm",
      "       hh= n    ",
      "        h=      ",
      "        h=      ",
      "        hh=     ",
      "         h=    i"
    ]
  ]
}