{
  "name": "multi_nuclearpowerplant_10_base6",
  "refpalette": "deceasedcraft:multi_nuclearpowerplant_10/multi_nuclearpowerplant_10_base6_palette",
  "xsize": 16,
  "zsize": 16,
  "slices": [
    [
      "abbbccd         ",
      "abbbcd          ",
      "abbbcd          ",
      "abbccd          ",
      "abbcd           ",
      "abbcd           ",
      "abbcd           ",
      "abbcd           ",
      "abbed           ",
      "abbed           ",
      "abbed           ",
      "abbed           ",
      "abbeed          ",
      "abbbed          ",
      "abbbed          ",
      "abbbeed         "
    ],
    [
      "fg    hi        ",
      "f    hii        ",
      "f    hi         ",
      "f    hi         ",
      "f   hii         ",
      "f   hi          ",
      "f   hi          ",
      "f   hi          ",
      "f   hi          ",
      "f   hi          ",
      "f   hi          ",
      "f   hii         ",
      "f    hi         ",
      "f    hi         ",
      "f    hii        ",
      "fg    hi        "
    ],
    [
      "       =        ",
      "      ==        ",
      "      =         ",
      "      =         ",
      "     ==         ",
      "     =          ",
      "     =          ",
      "     =          ",
      "     =          ",
      "     =          ",
      "     =          ",
      "     ==         ",
      "      =         ",
      "      =         ",
      "      ==        ",
      "       =        "
    ],
    [
      "                ",
      "      =j        ",
      "      k         ",
      "                ",
      "                ",
      "                ",
      "                ",
      "     =          ",
      "     =          ",
      "                ",
      "                ",
      "                ",
      "                ",
      "      l         ",
      "      =j        ",
      "                "
    ],
    [
      "       l        ",
      "       k        ",
      "      =         ",
      "                ",
      "                ",
      "                ",
      "     l          ",
      "     k          ",
      "     l          ",
      "     k          ",
      "                ",
      "                ",
      "                ",
      "      =         ",
      "       l        ",
      "       k        "
    ],
    [
      "        =       ",
      "                ",
      "       l        ",
      "       k        ",
      "                ",
      "                ",
      "      =         ",
      "                ",
      "                ",
      "      =         ",
      "                ",
      "                ",
      "       l        ",
      "       k        ",
      "                ",
      "        =       "
    ]
  ]
}