{
  "name": "multi_nuclearpowerplant_10_base3",
  "refpalette": "deceasedcraft:multi_nuclearpowerplant_10/multi_nuclearpowerplant_10_base3_palette",
  "xsize": 16,
  "zsize": 16,
  "slices": [
    [
      "           aa=  ",
      "          aa=   ",
      "          a==   ",
      "          a=    ",
      "         aa=    ",
      "         a=     ",
      "         a=     ",
      "         a=     ",
      "         a=     ",
      "         a=     ",
      "         a=     ",
      "         aa=    ",
      "          a=    ",
      "          a==   ",
      "          aa=   ",
      "           aa=  "
    ],
    [
      "           aa=  ",
      "          aa=   ",
      "          a==   ",
      "          a=    ",
      "         aa=    ",
      "         a=     ",
      "         a=     ",
      "         a=     ",
      "         a=     ",
      "         a=     ",
      "         a=     ",
      "         aa=    ",
      "          a=    ",
      "          a==   ",
      "          aa=   ",
      "           aa=  "
    ],
    [
      "           baa= ",
      "           aa=  ",
      "          caa=  ",
      "          ca=   ",
      "          aa=   ",
      "         ca=    ",
      "         ca=    ",
      "         ca=    ",
      "         ca=    ",
      "         ca=    ",
      "         ca=    ",
      "          aa=   ",
      "          ca=   ",
      "          caa=  ",
      "           aa=  ",
      "           baa= "
    ],
    [
      "           baa= ",
      "           aa=  ",
      "          caa=  ",
      "          ca=   ",
      "          aa=   ",
      "         ca=    ",
      "         ca=    ",
      "         ca=    ",
      "         ca=    ",
      "         ca=    ",
      "         ca=    ",
      "          aa=   ",
      "          ca=   ",
      "          caa=  ",
      "           aa=  ",
      "           baa= "
    ],
    [
      "            aa= ",
      "           aa=  ",
      "           aa=  ",
      "          ca=   ",
      "          aa=   ",
      "         ca=    ",
      "         ca=    ",
      "         ca=    ",
      "         ca=    ",
      "         ca=    ",
      "         ca=    ",
      "          aa=   ",
      "          ca=   ",
      "           aa=  ",
      "           aa=  ",
      "            aa= "
    ],
    [
      "            aa= ",
      "           ba=  ",
      "           aa=  ",
      "          ca=   ",
      "          aa=   ",
      "         ca=    ",
      "         ca=    ",
      "         ca=    ",
      "         ca=    ",
      "         ca=    ",
      "         ca=    ",
      "          aa=   ",
      "          ca=   ",
      "           aa=  ",
      "           ba=  ",
      "            aa= "
    ]
  ]
}