{
  "xsize": 16,
  "zsize": 16,
  "refpalette": "lce2:port",
  "slices": [
    [
      "          $$**  ",
      "          $$**  ",
      "          $$**  ",
      "          $$**  ",
      "          $$**  ",
      "          $$**  ",
      "          $$**  ",
      "          $$**  ",
      "          $$**  ",
      "          $$**  ",
      "          $$**  ",
      "          $$**  ",
      "          $$**  ",
      "          $$**  ",
      "          $$**  ",
      "          $$**  "
    ],
    [
      "           $**  ",
      "           $**  ",
      "           $**  ",
      "           $**  ",
      "           $**  ",
      "           $**  ",
      "           $**  ",
      "           $**  ",
      "           $**  ",
      "           $**  ",
      "           $**  ",
      "           $**  ",
      "           $**  ",
      "           $**  ",
      "           $**  ",
      "           $**  "
    ],
    [
      "           $**  ",
      "           $**  ",
      "           $**  ",
      "           $**  ",
      "           $**  ",
      "           $**  ",
      "           $**  ",
      "           $**  ",
      "           $**  ",
      "           $**  ",
      "           $**  ",
      "           $**  ",
      "           $**  ",
      "           $**  ",
      "           $**  ",
      "           $**  "
    ],
    [
      "           $**  ",
      "           $**  ",
      "           $**  ",
      "           $**  ",
      "           $**  ",
      "           $**  ",
      "           $**  ",
      "           $**  ",
      "           $**  ",
      "           $**  ",
      "           $**  ",
      "        && $**  ",
      "        && $**  ",
      "        &  $**  ",
      "        &  $**  ",
      "       &&  $**  "
    ],
    [
      "%%%%%%%%%%%%**  ",
      "%%%%%%%%%%%%**  ",
      "%%%%%%%%%%%%**  ",
      "%%%%%%%%%%%%**  ",
      "%%%%%%%%%%%%**  ",
      "%%%%%%%%%%%%**  ",
      "%%%%%%%%%%%%**  ",
      "%%%%%%%%%%%%**  ",
      "%%%%%%%%%%%%**  ",
      "%%%%%%%%%%%%**  ",
      "%%%%%%%%%%%%**  ",
      "%%%%%%%%%%%%**  ",
      "%%%%%%%%%%%%**  ",
      "%%%%%%%%%%%%**  ",
      "%%%%%%%%%%%%**  ",
      "%%%%%%%%%%%%**  "
    ],
    [
      "            **  ",
      "            **  ",
      "            **  ",
      "            **  ",
      "            **  ",
      "            **  ",
      "            **  ",
      "            **  ",
      "            **  ",
      "            **  ",
      "            **  ",
      "        &&  **  ",
      "        &&  **  ",
      "        &   **  ",
      "        &   **  ",
      "       &&   **  "
    ]
  ]
}