{
  "name": "multi_laboratory_4_base4",
  "refpalette": "deceasedcraft:multi_laboratory_4/multi_laboratory_4_base4_palette",
  "xsize": 16,
  "zsize": 16,
  "slices": [
    [
      "vaabbbbbbbbcbbbb",
      "vaabbbbbbbbbbbbb",
      "vaabbbbbbbbbbbbb",
      "vaabbbbbbbbbbbbb",
      "vaabbbbbbbbbbbbb",
      "vaabbbbbbbbbbbbb",
      "vaabbbbbbbbbbbbb",
      "vaabbbbbbbbcbbbb",
      "vaaddddddddbbbbb",
      "vaaddddddddbbbbb",
      "vaaddddddddbbbbb",
      "vaaddddddddbbbbb",
      "vaaddddddddbbb!b",
      "vaaaaaaaaaaaaaaa",
      "vaaaaaaaaaaaeeee",
      "vvvvvvvvvvvvvvvv"
    ],
    [
      "vaaffffffffc   g",
      "vaah ij   kf   g",
      "vaal     mnf   o",
      "vaap      nf  qr",
      "vaap       f    ",
      "vaas       t    ",
      "vaah uw    f    ",
      "vaaffffffffc    ",
      "vaaqqxxxxqqf    ",
      "vaa        y    ",
      "vaaABABCBABf    ",
      "vaa D D D Df    ",
      "vaaEDEDEDEDfFII ",
      "vaaaaaaaaaaaaaaa",
      "vaaaaaaaaaaaeeee",
      "vvvvvvvvvvvvvvvv"
    ],
    [
      "vaaffffffffc    ",
      "vaaJ       f    ",
      "vaa        f    ",
      "vaa        f   K",
      "vaa        f    ",
      "vaa        L    ",
      "vaaJ       f    ",
      "vaaffffffffc    ",
      "vaaJ      Jf    ",
      "vaa        M    ",
      "vaaNBNBOBNBf    ",
      "vaa D D D Df    ",
      "vaa D D D Df    ",
      "vaaaaaaaaaaaaaaa",
      "vaaaaaaaaaaaeeee",
      "vvvvvvvvvvvvvvvv"
    ],
    [
      "vaaffffffffc    ",
      "vaaP       f    ",
      "vaa        fQ   ",
      "vaa        fR   ",
      "vaa        f    ",
      "vaa        S    ",
      "vaaP       f    ",
      "vaaffffffffc    ",
      "vaa TUUUUV f    ",
      "vaa        f    ",
      "vaaBBBBBBBBf    ",
      "vaa D D D Df    ",
      "vaa D D D Df    ",
      "vaaaaaaaaaaaaaaa",
      "vaaaaaaaaaaaeeee",
      "vvvvvvvvvvvvvvvv"
    ],
    [
      "vaaffffffffc    ",
      "vaa        f    ",
      "vaa        f    ",
      "vaa        f    ",
      "vaa        f    ",
      "vaa        f    ",
      "vaa        f    ",
      "vaaffffffffc    ",
      "vaaWWWWWWWWf    ",
      "vaaWWWWWWWWf    ",
      "vaaWWWWWWWWf    ",
      "vaaWWWWWWWWf    ",
      "vaaXW!WXWXWf    ",
      "vaaaaaaaaaaaaaaa",
      "vaaaaaaaaaaaeeee",
      "vvvvvvvvvvvvvvvv"
    ],
    [
      "veaffffffffcYYZY",
      "vea00000000SYYZY",
      "vea01000020SYY3Y",
      "vea00000000SYY33",
      "vea00000000SYYYY",
      "vea04000040SYYYY",
      "vea00000000SYYYY",
      "veaffffffffcffff",
      "vea55555555f6666",
      "vea5 5 5 5 f6Z66",
      "vea5 5 5 5 f6Z66",
      "vea5 5 5 5 f6366",
      "vea5 5 5 5 f6666",
      "veaaaaaaaaaaaaaa",
      "veeeeeeeeeeeeeee",
      "vvvvvvvvvvvvvvvv"
    ]
  ]
}