{
  "name": "multi_laboratory_4_base1",
  "refpalette": "deceasedcraft:multi_laboratory_4/multi_laboratory_4_base1_palette",
  "xsize": 16,
  "zsize": 16,
  "slices": [
    [
      "vabccccccccdcccc",
      "vabccccccccccccc",
      "vabccccccccccccc",
      "vabccccccccccccc",
      "vabccccccccccccc",
      "vabccccccccccccc",
      "vabccccccccccccc",
      "vabccccccccdcccc",
      "vabeeeeeeeeccccc",
      "vabeeeeeeeeccccc",
      "vabeeeeeeeeccccc",
      "vabeeeeeeeeccccc",
      "vabeeeeeeeeccccc",
      "vabbbbbbbbbbbbbb",
      "vaaaaaaaaaaaaaaa",
      "vvvvvvvvvvvvvvvv"
    ],
    [
      "vabfg      d    ",
      "vabf  h i  j    ",
      "vabk lmnmo j    ",
      "vabp lqrqo s    ",
      "vabk  i i  j    ",
      "vabfh      j    ",
      "vabf  ttuwwj    ",
      "vabxxxxxxxxd   y",
      "vabAArrrrAAx   B",
      "vab        C   B",
      "vabDEFEDEDEx   B",
      "vab I I I Ix   B",
      "vabJIJIJIJIxyBB!",
      "vabbbbbbbbbbbbbb",
      "vaaaaaaaaaaaaaaa",
      "vvvvvvvvvvvvvvvv"
    ],
    [
      "vabK       d    ",
      "vabL       j    ",
      "vabM  N    j    ",
      "vab     O  P    ",
      "vabQ       j    ",
      "vabR       j    ",
      "vabR       j    ",
      "vabxxxxxxxxd   S",
      "vabT      Tx   U",
      "vab        V    ",
      "vabWEXEWEWEx    ",
      "vab I I I Ix    ",
      "vab I I I IxSYYS",
      "vabbbbbbbbbbbbbb",
      "vaaaaaaaaaaaaaaa",
      "vvvvvvvvvvvvvvvv"
    ],
    [
      "vab        d    ",
      "vab        Z    ",
      "vab        j    ",
      "vab        j    ",
      "vab        j    ",
      "vab0       j    ",
      "vab0       j    ",
      "vabxxxxxxxxd   T",
      "vab 122223 x    ",
      "vab        x    ",
      "vabEEEEEEEEx    ",
      "vab I I I Ix    ",
      "vab I I I IxT 4T",
      "vabbbbbbbbbbbbbb",
      "vaaaaaaaaaaaaaaa",
      "vvvvvvvvv5vvvvvv"
    ],
    [
      "vab        d    ",
      "vab        j    ",
      "vab        j    ",
      "vab        Z    ",
      "vab        Z    ",
      "vab        Z    ",
      "vab        Z    ",
      "vabxxxxxxxxd    ",
      "vab666 6666x    ",
      "vab6 666666x    ",
      "vab76666666x    ",
      "vab66666666x    ",
      "vab86868686x    ",
      "vabbbbbbbbbbbbbb",
      "vaaaaaaaaaaaaaaa",
      "vvvvvvvvvvvvvvvv"
    ],
    [
      "vab99999999d9999",
      "vab99999999#9999",
      "vab99$999%9#9999",
      "vab99$999$9#9999",
      "vab99$999$9#9999",
      "vab99$999$9#9999",
      "vab99999999#9999",
      "vab^^^^^^^^d9999",
      "vab&&&&&&&&^9999",
      "vab& & & & ^9999",
      "vab& & & & ^9999",
      "vab&!& & & ^9999",
      "vab& & & & ^9999",
      "vabbbbbbbbbbbbbb",
      "vaaaaaaaaaaaaaaa",
      "vvvvvvvvvvvvvvvv"
    ]
  ]
}