{
  "name": "multi_laboratory_4_base6",
  "refpalette": "deceasedcraft:multi_laboratory_4/multi_laboratory_4_base6_palette",
  "xsize": 16,
  "zsize": 16,
  "slices": [
    [
      "vabbbbcbbbbcbbbb",
      "vabbbbbbbbbbbbbb",
      "vabbbbbbbbbbbbbb",
      "vabbbbbbbbbbbbbb",
      "vabbbbbbbbbbbbbb",
      "vabbbbbbbbbbbbbb",
      "vabbbbbbbbbbbbbb",
      "vabbbbcbbbbcbbbb",
      "vabbbbbbbbbbbbbb",
      "vabbbbbbbbbbbbbb",
      "vabbbbbbbbbbbbbb",
      "vabbbbbbbbbbbbbb",
      "vabbbbbbbbbbbbbb",
      "vabbbbbbbbbbaaaa",
      "vaaaaaaaaaaadddd",
      "vvvvvvvvvvvvvvvv"
    ],
    [
      "vceeeec    c  f ",
      "vaghhge    e if ",
      "vaj k e    e    ",
      "va    e    e    ",
      "va l  e    e    ",
      "vamn  e    e    ",
      "vaop qe    e  f ",
      "vcop  c    c rf ",
      "va!pq e    e  f ",
      "vags  t    e    ",
      "va    u    u    ",
      "va    w    w    ",
      "vax x t    e    ",
      "vamyyme    eaaaa",
      "vaaaaaaaaaaadddd",
      "vvvvvvvvvvvvvvvv"
    ],
    [
      "vceeeec    c  A ",
      "vaB  Ce    D    ",
      "va    D    D    ",
      "va    D    D    ",
      "va    D    D    ",
      "vaEC  D    D    ",
      "vaF   e    D    ",
      "vcF   c    c  A ",
      "va    e    e  I ",
      "vaJ   t    e    ",
      "va    K    K    ",
      "va    L    L    ",
      "va    t    e    ",
      "vaMMMMe    eaaaa",
      "vaaaaaaaaaaadddd",
      "vvvvvvvvvvvvvvvv"
    ],
    [
      "vceeeec    c    ",
      "va    e    D    ",
      "va    D    D    ",
      "va    D    D    ",
      "va    D    D    ",
      "va    D    D    ",
      "va    e    D    ",
      "vc    c    c    ",
      "va    e    e    ",
      "va    t    e    ",
      "va    t    t    ",
      "va    t    t    ",
      "va    t    e    ",
      "vaNNNNe    eaaaa",
      "vaaaaaaaaaaadddd",
      "vvvvvvvvvvvvvvvv"
    ],
    [
      "vceeeec    c    ",
      "va    e    D    ",
      "va    e    D    ",
      "va    e    D    ",
      "va    e    D    ",
      "va    e    D    ",
      "va    e    D    ",
      "vc    c    c    ",
      "va    e    e    ",
      "va    e    e    ",
      "va    e    t    ",
      "va    e    t    ",
      "va    e    e    ",
      "va    e    eaaaa",
      "vaaaaaaaaaaadddd",
      "vvvvvvvvvvvvvvvv"
    ],
    [
      "vceeeec    c    ",
      "vaOOOOe    D    ",
      "vaOPPOe    D    ",
      "vaOOOOe    D    ",
      "vaOOOOe    D    ",
      "vaOPPOe    D    ",
      "vaOOOOe    D    ",
      "vceeeec    c    ",
      "vaOOOOe    e    ",
      "vaOPPOe    e    ",
      "vaOOOOe    t    ",
      "vaOOOOe    t    ",
      "vaOPPOe    e    ",
      "vaOOOOe    eaaaa",
      "vaaaaaaaaaaadddd",
      "vvvvvvvvvvvvvvvv"
    ]
  ]
}