{
  "name": "multi_laboratory_4_base2",
  "refpalette": "deceasedcraft:multi_laboratory_4/multi_laboratory_4_base2_palette",
  "xsize": 16,
  "zsize": 16,
  "slices": [
    [
      "vabccccccccdcccc",
      "vabccccccccccccc",
      "vabccccccccccccc",
      "vabccccccccccccc",
      "vabccccccccccccc",
      "vabccccccccccccc",
      "vabccccccccccccc",
      "vabccccccccdcccc",
      "vabeeeeeeeeccccc",
      "vabeeeeeeeeccccc",
      "vabeeeeeeeeccccc",
      "vabeeeeeeeeccccc",
      "vabeeee!eeeccccc",
      "vabbbbbbbbbbbbbb",
      "vaaaaaaaaaaaaaaa",
      "vvvvvvvvvvvvvvvv"
    ],
    [
      "vabffffffffd   g",
      "vabhhhijk lf  mg",
      "vabhnhhjk of  pq",
      "vabhhhhjk lf  rs",
      "vabhhhhjk  f    ",
      "vabhhhijk  t    ",
      "vabnhiijk  f    ",
      "vabffffffffd    ",
      "vabrruuuurrf    ",
      "vab        w    ",
      "vabxyAyAyAyf    ",
      "vab B B B Bf    ",
      "vabCBCBCBCBfDEE ",
      "vabbbbbbbbbbbbbb",
      "vaaaaaaaaaaaaaaa",
      "vvvvvvvvvvvvvvvv"
    ],
    [
      "vabffffffffd    ",
      "vab F  @   f    ",
      "vabIIJ @  Kf   L",
      "vab M M@   f   N",
      "vabF   @   f    ",
      "vab O  @   P    ",
      "vabIFQR@   f    ",
      "vabffffffffd    ",
      "vabS      Sf    ",
      "vab        T    ",
      "vabUyVyVyVyf    ",
      "vab B B B Bf    ",
      "vab B B B Bf    ",
      "vabbbbbbbbbbbbbb",
      "vaaaaaaaaaaaaaaa",
      "vvvvvvvvvvvvvvvv"
    ],
    [
      "vabffffffffd    ",
      "vab    @   f    ",
      "vab I  @   fW   ",
      "vab    @   fX   ",
      "vabY   @   f    ",
      "vab    @   Z    ",
      "vabI   @   f    ",
      "vabffffffffd    ",
      "vab 011112 f    ",
      "vab        f    ",
      "vabyyyyyyyyf    ",
      "vab B B B Bf    ",
      "vab B B B Bf    ",
      "vabbbbbbbbbbbbbb",
      "vaaaaaaaaaaaaaaa",
      "vvvvvvvvvvvvvvvv"
    ],
    [
      "vabffffffffd    ",
      "vab    @   f    ",
      "vab    @   f    ",
      "vab    @   f    ",
      "vab    @   f    ",
      "vab    @   f    ",
      "vab    @   f    ",
      "vabffffffffd    ",
      "vab33333333f    ",
      "vab33 33333f    ",
      "vab3 333333f    ",
      "vab33333333f    ",
      "vab43434343f    ",
      "vabbbbbbbbbbbbbb",
      "vaaaaaaaaaaaaaaa",
      "vvvvvvvvvvvvvvvv"
    ],
    [
      "vabffffffffd5565",
      "vab    7777Z5585",
      "vab    77!7Z5585",
      "vab    7777Z5566",
      "vab    7777Z5555",
      "vab    7797Z5555",
      "vab    7777Z5555",
      "vabffffffffdffff",
      "vab########f$$$$",
      "vab# # #%# f$^$$",
      "vab#%# # # f$^$$",
      "vab#%# # # f$^$$",
      "vab# # # # f$$$$",
      "vabbbbbbbbbbbbbb",
      "vaaaaaaaaaaaaaaa",
      "vvvvvvvvvvvvvvvv"
    ]
  ]
}