{
  "name": "multi_laboratory_4_ground",
  "refpalette": "deceasedcraft:multi_laboratory_4/multi_laboratory_4_ground_palette",
  "xsize": 16,
  "zsize": 16,
  "slices": [
    [
      "zazzaabvcccdeeee",
      "zzazzabvcccdeeee",
      "azaaaabbcccdeeee",
      "zzzazbbvcccdffff",
      "zazzaaavcccdffff",
      "zzazzabvcccdffff",
      "zazzazbvcccdffff",
      "zzazzabvcccdffff",
      "azzaaabvcccdffff",
      "zzaazabbcccdffff",
      "zazaazbvcccddddd",
      "zzzazaavvccccccc",
      "zzzzaabbvccccccc",
      "zazzzaababbccccc",
      "zzzazzzaazaaaaaz",
      "zzzzzzzzzzzzazzz"
    ],
    [
      "  g        d   h",
      "   i       j    ",
      " i         kllll",
      "           jmnop",
      "i  q       j   p",
      " i         jrrsr",
      "   i       j    ",
      "           d   t",
      "           j   u",
      " i  w      kx  t",
      "i          kkjdj",
      "ii              ",
      " yi             ",
      "  iii           ",
      " i   i          ",
      " i  i i  i    i "
    ],
    [
      "           d    ",
      "           A    ",
      "           kllll",
      "           j   p",
      "   ~       j   p",
      "           jrrBr",
      "           C    ",
      "           d    ",
      "           j    ",
      "           jD   ",
      "           kjjdC",
      "                ",
      "                ",
      "                ",
      "                ",
      "                "
    ],
    [
      "           d    ",
      "           A    ",
      "           kllll",
      "           j  Ep",
      "           j   p",
      "           jrrrr",
      "           C    ",
      "           d    ",
      "           j   F",
      "           jI   ",
      "           kjjdC",
      "                ",
      "                ",
      "                ",
      "                ",
      "                "
    ],
    [
      "           d    ",
      "           A    ",
      "           kllll",
      "           j   p",
      "           j   p",
      "           jrrrr",
      "           C    ",
      "           d    ",
      "           j    ",
      "           j    ",
      "           kjjdC",
      "                ",
      "                ",
      "                ",
      "                ",
      "                "
    ],
    [
      "           dJJJJ",
      "           jJJJJ",
      "           kllll",
      "           jKKKK",
      "           jKLKL",
      "           jKKKK",
      "           jKLKK",
      "           dKKKK",
      "           jKLKM",
      "           jKKKK",
      "           kjjdj",
      "                ",
      "                ",
      "                ",
      "                ",
      "                "
    ]
  ]
}