{
  "name": "multi_laboratory_4_base5",
  "refpalette": "deceasedcraft:multi_laboratory_4/multi_laboratory_4_base5_palette",
  "xsize": 16,
  "zsize": 16,
  "slices": [
    [
      "vabbbba    ac   ",
      "vdbbbba    e    ",
      "vdbbbba    e    ",
      "vdbbbba    e    ",
      "vdbbbba    e    ",
      "vdbbbba    e    ",
      "vdbbbba    e    ",
      "vabbbba    ac   ",
      "vdbbbba    f    ",
      "vdbbbba    f    ",
      "vdbbbba    g    ",
      "vdbbbba    g    ",
      "vdbbbba    f    ",
      "vdbbbba    fdddd",
      "vdddddddddddhhhh",
      "vvvvvvvvvvvvvvvv"
    ],
    [
      "vaffffa    a    ",
      "vdii jf    e    ",
      "vd k  f    e    ",
      "vdl   f    e    ",
      "vdmm  f    e    ",
      "vdii  f    e    ",
      "vd k  f    e    ",
      "van   a    a    ",
      "vdii  f    f    ",
      "vd    g    f    ",
      "vd    o    g    ",
      "vdl   p    g    ",
      "vd  n g    f    ",
      "vdmqqmf    fdddd",
      "vdddddddddddhhhh",
      "vvvvvvvvvvvvvvvv"
    ],
    [
      "vaffffa    a    ",
      "vd r  f    e    ",
      "vd    e    e    ",
      "vd    e    e    ",
      "vds   e    e    ",
      "vdtr  e    e    ",
      "vd    f    e    ",
      "va    a    a    ",
      "vd    f    f    ",
      "vd    g    f    ",
      "vd    u    g    ",
      "vd    w    g    ",
      "vd    g    f    ",
      "vd x yf    fdddd",
      "vdddddddddddhhhh",
      "vvvvvvvvvvvvvvvv"
    ],
    [
      "vaffffa    a    ",
      "vd    f    e    ",
      "vd    e    e    ",
      "vd    e    e    ",
      "vd    e    e    ",
      "vd    e    e    ",
      "vd    f    e    ",
      "va    a    a    ",
      "vd    f    f    ",
      "vd    g    f    ",
      "vd    g    g    ",
      "vd    g    g    ",
      "vd    g    f    ",
      "vd    f    fdddd",
      "vdddddddddddhhhh",
      "vvvvvvvvvvvvvvvv"
    ],
    [
      "vaffffa    a    ",
      "vd    f    f    ",
      "vd    f    f    ",
      "vd    f    f    ",
      "vd    f    f    ",
      "vd    f    f    ",
      "vd    f    f    ",
      "va    a    a    ",
      "vd    f    f    ",
      "vd    f    f    ",
      "vd    f    f    ",
      "vd    f    f    ",
      "vd    f    f    ",
      "vd    f    fdddd",
      "vdddddddddddhhhh",
      "vvvvvvvvvvvvvvvv"
    ],
    [
      "vaffffaAAAAfAAAA",
      "vdBBBBfAAAAfAAAA",
      "vdBCCBfAAAAfAAAA",
      "vdBBBBfADDAfAAAA",
      "vdBBBBfADDAfAAAA",
      "vdBCCBfAAAAfAAAA",
      "vdBBBBfAAAAfAAAA",
      "vaffffaAAAAfAAAA",
      "vdBBBBfAAAAfAAAA",
      "vdBCEBfAAAAfAAAA",
      "vdBBBBfADFAfAAAA",
      "vdBBBBfADFAfAAAA",
      "vdBCCBfAAAAfAAAA",
      "vdBBBBfAAAAfdddd",
      "vdddddddddddhhhh",
      "vvvvvvvvvvvvvvvv"
    ]
  ]
}