{
  "name": "multi_laboratory_4_base3",
  "refpalette": "deceasedcraft:multi_laboratory_4/multi_laboratory_4_base3_palette",
  "xsize": 16,
  "zsize": 16,
  "slices": [
    [
      "vabccccccccdcccc",
      "vabccccccccccccc",
      "vabccccccccccccc",
      "vabccccccefcfccc",
      "vabccccccccfgccc",
      "vabccccccchccccc",
      "vabccccccccccccc",
      "vabccccccccdcccc",
      "vabiiiiiiiiccccc",
      "vabiiiiiiiiccccc",
      "vabiiiiiiiiccccc",
      "vabjiiiiiiiccccc",
      "vab!kiiiiiiccccc",
      "vabbbbbbbbbbbbbb",
      "vaaaaaaaaaaaaaaa",
      "vvvvvvvvvvvvvvvv"
    ],
    [
      "vablllllllld   m",
      "vab! nn onpl q m",
      "vabrsttt upl   w",
      "vabxyAAA   q  BC",
      "vabxDAAAAE      ",
      "vabr FFFF  Iq   ",
      "vabJ   KL  l   q",
      "vablllllllld   M",
      "vabBBNNNNBBl    ",
      "vab        O    ",
      "vabPQRQRQRQl    ",
      "vab S S S Sl    ",
      "vabTSUSUSUSlVWW ",
      "vabbbbbbbbbbbbbb",
      "vaaaaaaaaaaaaaaa",
      "vvvvvvvvvvvvvvvv"
    ],
    [
      "vablllllllld    ",
      "vab       Xl    ",
      "vab u     X     ",
      "vabY            ",
      "vabZ    0       ",
      "vab        1    ",
      "vab        l    ",
      "vablllllllld   2",
      "vab3      2l    ",
      "vab        4    ",
      "vab5Q6Q6Q6Ql    ",
      "vab S S S Sl    ",
      "vab7S S S Sl    ",
      "vabbbbbbbbbbbbbb",
      "vaaaaaaaaaaaaaaa",
      "vvvvvvvvvvvvvvvv"
    ],
    [
      "vablllllllld    ",
      "vab        l    ",
      "vab        8    ",
      "vab             ",
      "vab             ",
      "vab        9    ",
      "vab        l    ",
      "vablllllllld    ",
      "vab #$$$$% l    ",
      "vab        l    ",
      "vabQQQQQQQQl    ",
      "vab S S S Sl    ",
      "vabjS S7S Sl    ",
      "vabbbbbbbbbbbbbb",
      "vaaaaaaaaaaaaaaa",
      "vvvvvvvvvvvvvvvv"
    ],
    [
      "vablllllllld    ",
      "vab        l    ",
      "vab        l    ",
      "vab        l    ",
      "vab        l    ",
      "vab        l    ",
      "vab        l    ",
      "vablllllllld    ",
      "vab^^^^^^^^l    ",
      "vab^^^^^^^^l    ",
      "vab^^^^^^^^l    ",
      "vab^^^^^^^^l    ",
      "vabT^&^T^&^l    ",
      "vabbbbbbbbbbbbbb",
      "vaaaaaaaaaaaaaaa",
      "vvvvvvvvvvvvvvvv"
    ],
    [
      "vablllllllld**(*",
      "vab))))))))9**(*",
      "vab)+))))s)9**(*",
      "vab))))))))9**((",
      "vab))))))))9****",
      "vab)s))))+)9****",
      "vab))))))))9****",
      "vablllllllldllll",
      "vab--------l8888",
      "vab- - - - l8(88",
      "vab- - - - l8(88",
      "vabT - - - l8(88",
      "vabT - - - l8888",
      "vabbbbbbbbbbbbbb",
      "vaaaaaaaaaaaaaaa",
      "vvvvvvvvvvvvvvvv"
    ]
  ]
}