{
  "name": "multi_laboratory_4_top",
  "refpalette": "deceasedcraft:multi_laboratory_4/multi_laboratory_4_top_palette",
  "xsize": 16,
  "zsize": 16,
  "slices": [
    [
      "        abcdeeee",
      "        affdeeee",
      "        affdeeee",
      "        affdeeee",
      "        affdeeee",
      "        affdeeee",
      "        affdeeee",
      "        abcdeeee",
      "        affdee!e",
      "        affdeeee",
      "        affddddd",
      "         agggghg",
      "         aagggbg",
      "           aaaaa",
      "                ",
      "                "
    ],
    [
      "        i  j    ",
      "        i  kl   ",
      "        i  km   ",
      "        n  ko   ",
      "        i  k    ",
      "        i  k    ",
      "        i  k    ",
      "        i  jp qr",
      "        i  k  s ",
      "        i  kt s ",
      "        i  kkkjk",
      "         i      ",
      "         ii     ",
      "           iiiii",
      "                ",
      "                "
    ],
    [
      "        u  j    ",
      "        u       ",
      "        u       ",
      "        u       ",
      "        u       ",
      "        n       ",
      "        u       ",
      "        n  jw   ",
      "        u       ",
      "        u       ",
      "        n     j ",
      "         n      ",
      "         nu     ",
      "           nuuun",
      "                ",
      "                "
    ],
    [
      "        u  j    ",
      "        u       ",
      "        n       ",
      "        u       ",
      "        n       ",
      "        u       ",
      "        u       ",
      "        u  jx   ",
      "        u       ",
      "        u       ",
      "        u     j ",
      "         u      ",
      "         nu     ",
      "           uunuu",
      "                ",
      "                "
    ],
    [
      "        u  j    ",
      "        n       ",
      "        u       ",
      "        u       ",
      "        u       ",
      "        u       ",
      "        u       ",
      "        u  j    ",
      "        u       ",
      "        u       ",
      "        n     j ",
      "         u      ",
      "         uu     ",
      "           nuuuu",
      "                ",
      "                "
    ],
    [
      "        u  d    ",
      "        u  b    ",
      "        u  b    ",
      "        u  b    ",
      "        u  b    ",
      "        u  b    ",
      "        n  b    ",
      "        u  d    ",
      "        u  b    ",
      "        u  b    ",
      "        u  bbbdb",
      "         u      ",
      "         nn     ",
      "           uunuu",
      "                ",
      "                "
    ],
    [
      "        ubcdyyyy",
      "        u  dyyyy",
      "        u  dyyyy",
      "        u  dyyyy",
      "        u  dyyyy",
      "        u  dyyyy",
      "        u  dyyyy",
      "        ubcdyyyy",
      "        u  dyyyy",
      "        u  dyyyy",
      "        u  ddddd",
      "         u    hA",
      "         un   bA",
      "           uuuuu",
      "                ",
      "                "
    ],
    [
      "        u  B    ",
      "        u  k    ",
      "        u  k    ",
      "        u  kC   ",
      "        u  kD   ",
      "        u  kE   ",
      "        u  kp   ",
      "        u  B    ",
      "        u  k    ",
      "        u  k    ",
      "        n  kkkj ",
      "         u    k ",
      "         uu   k ",
      "           nuuuu",
      "                ",
      "                "
    ],
    [
      "        u       ",
      "        u       ",
      "        u       ",
      "        u       ",
      "        u       ",
      "        u       ",
      "        u   F   ",
      "        u       ",
      "        u       ",
      "        u       ",
      "        u       ",
      "         u      ",
      "         nu     ",
      "           uuuuu",
      "                ",
      "                "
    ],
    [
      "                ",
      "                ",
      "        I       ",
      "        I       ",
      "        I       ",
      "        u       ",
      "        u       ",
      "        u       ",
      "        u       ",
      "        u       ",
      "        u       ",
      "         u      ",
      "         uu     ",
      "           uuuuu",
      "                ",
      "                "
    ],
    [
      "                ",
      "                ",
      "                ",
      "                ",
      "                ",
      "                ",
      "                ",
      "                ",
      "        I       ",
      "        I       ",
      "        I       ",
      "         u      ",
      "         uu     ",
      "           uuuuu",
      "                ",
      "                "
    ]
  ]
}