{
  "name": "multi_gallery_10_ground",
  "refpalette": "deceasedcraft:multi_gallery_10/multi_gallery_10_ground_palette",
  "xsize": 16,
  "zsize": 16,
  "slices": [
    [
      "aaaaaaaaaaaaaaaa",
      "aaaaaaaabbvcaaaa",
      "aaaaaaaabbvcaaab",
      "aaaaaaaabadcaaab",
      "aaaaaaabeadcaaab",
      "aaaaaaabbvcaaaab",
      "aaaaaaabbvcaaabb",
      "aaaaaaabadcaaabb",
      "aaaaaabeadcaaabb",
      "aaaaaabbvcaaaabb",
      "aaaaaabbvcaaabbb",
      "aaaaaabadcaaabbb",
      "aaaaabeadcaaabbb",
      "aaaaabbvcaaaabbb",
      "aaaaabbvcaaabbbb",
      "aaaaaaaaaaaabbbb"
    ],
    [
      "          f     ",
      "        ghv     ",
      "        ghv     ",
      "        gvi     ",
      "       ggvi     ",
      "       ghv      ",
      "       ghv      ",
      "       gvi      ",
      "      ggvi      ",
      "      ghv       ",
      "      ghv       ",
      "      gvi       ",
      "     ggvi       ",
      "     g v        ",
      "     g v        ",
      "       j        "
    ],
    [
      "                ",
      "          k     ",
      "                ",
      "         l      ",
      "         m      ",
      "         l      ",
      "         m      ",
      "        n       ",
      "        m       ",
      "        n       ",
      "        m       ",
      "       o        ",
      "       m        ",
      "       p        ",
      "       m        ",
      "                "
    ],
    [
      "                ",
      "          m     ",
      "          m     ",
      "         o      ",
      "         m      ",
      "         q      ",
      "         m      ",
      "                ",
      "        m       ",
      "                ",
      "        m       ",
      "       o        ",
      "       m        ",
      "       q        ",
      "       m        ",
      "                "
    ],
    [
      "                ",
      "                ",
      "                ",
      "                ",
      "                ",
      "                ",
      "                ",
      "                ",
      "                ",
      "                ",
      "                ",
      "                ",
      "                ",
      "                ",
      "                ",
      "                "
    ],
    [
      "                ",
      "                ",
      "                ",
      "                ",
      "                ",
      "                ",
      "                ",
      "                ",
      "                ",
      "                ",
      "                ",
      "                ",
      "                ",
      "                ",
      "                ",
      "                "
    ]
  ]
}