{
  "name": "multi_gallery_10_base1",
  "refpalette": "deceasedcraft:multi_gallery_10/multi_gallery_10_base1_palette",
  "xsize": 16,
  "zsize": 16,
  "slices": [
    [
      "vvvvvvvvvvvvvvvv",
      "aaaaaaaaaaaaaabv",
      "      c       av",
      "~             av",
      "     d    ~  dav",
      "              av",
      "  e           av",
      "  e         f av",
      "              av",
      "              av",
      "              av",
      "              av",
      "  e           av",
      "  e          fav",
      "              av",
      "            d av"
    ],
    [
      "vvvvvvvvvvvvvvvv",
      "aaaaaaaaaaaaaabv",
      "      d       av",
      "              av",
      "              av",
      "              av",
      "              av",
      "            ~ av",
      "              av",
      "              av",
      "              av",
      "              av",
      "              av",
      "             fav",
      "              av",
      "              av"
    ],
    [
      "vvvvvvvvvvvvvvvv",
      "aaaaaaaaaaaaaabv",
      "              av",
      "              av",
      "              av",
      "              av",
      "              av",
      "              av",
      "              av",
      "              av",
      "              av",
      "              av",
      "              av",
      "             ~av",
      "              av",
      "              av"
    ],
    [
      "vvvvvvvvvvvvvvvv",
      "aaaaaaaaaaaaaabv",
      "              av",
      "              av",
      "              av",
      "              av",
      "              av",
      "              av",
      "              av",
      "              av",
      "              av",
      "              av",
      "              av",
      "              av",
      "              av",
      "              av"
    ],
    [
      "vvvvvvvvvvvvvvvv",
      "aaaaaaaaaaaaaabv",
      "ggggggggggggggav",
      "ggggggggggggggav",
      "ggggggggggggggav",
      "ggggggggggggggav",
      "ggggggggggggggav",
      "ggggggggggggggav",
      "ggggggggggggggav",
      "ggggggggggggggav",
      "ggggggggggggggav",
      "ggggggggggggggav",
      "ggggggggggggggav",
      "ggggggggggggggav",
      "ggggggggggggggav",
      "ggggggggggggggav"
    ],
    [
      "vvvvvvvvvvvvvvvv",
      "aaaaaaaaaaaaaabv",
      "aaaaaaaaaaaaaabv",
      "aaaaaaaaaaaaaabv",
      "aaaaaaaaaaaaaabv",
      "aaaaaaaaaaaaaabv",
      "aaaaaaaaaaaaaabv",
      "aaaaaaaaaaaaaabv",
      "aaaaaaaaaaaaaabv",
      "aaaaaaaaaaaaaabv",
      "aaaaaaaaaaaaaabv",
      "aaaaaaaaaaaaaabv",
      "aaaaaaaaaaaaaabv",
      "aaaaaaaaaaaaaabv",
      "aaaaaaaaaaaaaabv",
      "aaaaaaaaaaaaaabv"
    ]
  ]
}