{
  "name": "multi_gallery_10_base2",
  "refpalette": "deceasedcraft:multi_gallery_10/multi_gallery_10_base2_palette",
  "xsize": 16,
  "zsize": 16,
  "slices": [
    [
      "vvvvvvvvvvvvvvvv",
      "aaaaaaaaaaaaaaav",
      "bbbbbbbbbbbbbbav",
      "bbbbbbbbbbbbbbav",
      "bbbbbbbbbbbbbbav",
      "bbbbbbbbbbbbbbav",
      "bbbbbbbbbbbbbbav",
      "bbbbbbbbbbbbbbav",
      "bbbbbbbbbbbbbbav",
      "bbbbbbbbbbbbbbav",
      "bbbbbbbbbbbbbbav",
      "bbbbbbbbbbbbbbav",
      "bbbbbbbbbbbbbbav",
      "bbbbbbbbbbbbbbav",
      "bbbbbbbbbbbbbbav",
      "bbbbbbbbbbbbbbav"
    ],
    [
      "vvvvvvvvvvvvvvvv",
      "bbbbbbbbbbbbbbav",
      "ccccccccccccccbv",
      "ccccccccccccccbv",
      "ccccccccccccccbv",
      "ccccccccccccccbv",
      "ccccccccccccccbv",
      "ddddeeddddccccbv",
      "ddddeeddddccccbv",
      "ddddeeddddccccbv",
      "ddddeeddddccccbv",
      "ddddeeddddccccbv",
      "ddddeeddddccccbv",
      "ccccccccccccccbv",
      "ccccccccccccccbv",
      "ccccccccccccccbv"
    ],
    [
      "vvvvvvvvvvvvvvvv",
      "bbbbbbbbbbbbbbav",
      "f g  hg f g  ibv",
      "j  gf  g g fg bv",
      " gi  g    j  gbv",
      "   eee  eee f bv",
      "ddddeeddddeg  bv",
      "k  k  k  kd jgbv",
      "          d   bv",
      "          d   bv",
      "          d f bv",
      "          d   bv",
      "k  k  k  kd g bv",
      "ddddeedddde  jbv",
      "   eee  eee g bv",
      "       f f  g bv"
    ],
    [
      "vvvvvvvvvvvvvvvv",
      "bbbbbbbbbbbbbbav",
      "  l   m   m  nbv",
      "o  m   m m  m bv",
      " ln  m    o  mbv",
      "    ee   ee   bv",
      "ddddeeddddem  bv",
      "p  p  p  pd jmbv",
      "          d   bv",
      "          d   bv",
      "          d   bv",
      "          d   bv",
      "p  p  p  pd m bv",
      "ddddeedddde  jbv",
      "    ee   ee l bv",
      "            m bv"
    ],
    [
      "vvvvvvvvvvvvvvvv",
      "bbbbbbbbbbbbbbav",
      "      m   l  nbv",
      "o  l   m l  l bv",
      "  ~  m    o  mbv",
      "              bv",
      "dddd edddd m  bv",
      "q  qeeq  qd ombv",
      "    ee    d   bv",
      "    ee    dd  bv",
      "    ee    dd  bv",
      "    ee    d   bv",
      "q  qeeq  qd m bv",
      "dddd edddd   jbv",
      "              bv",
      "            m bv"
    ],
    [
      "vvvvvvvvvvvvvvvv",
      "bbbbbbbbbbbbbbav",
      "      m      ~bv",
      "r      l    s bv",
      "     m    r  mbv",
      "              bv",
      "  e        l  bv",
      "dddd edddd  rlbv",
      "dddd edddd    bv",
      "dttd edttddd  bv",
      "dttd edttddd  bv",
      "dddd edddd    bv",
      "dddd edddd  l bv",
      "  e          obv",
      "              bv",
      "            m bv"
    ]
  ]
}