{
  "name": "multi_nuclearpowerplant_6_base3",
  "refpalette": "deceasedcraft:multi_nuclearpowerplant_6/multi_nuclearpowerplant_6_base3_palette",
  "xsize": 16,
  "zsize": 16,
  "slices": [
    [
      "vaa             ",
      "vaa             ",
      "vaa             ",
      "vaa             ",
      "vaa             ",
      "vaa             ",
      "vaa             ",
      "vaaaaaaaaaaaaaaa",
      "vaaaaaaaaaaaaaaa",
      "vaa             ",
      "vaa             ",
      "vaa             ",
      "vaa             ",
      "vbb             ",
      "vbb             ",
      "vvvvvvvvvvvvvvvv"
    ],
    [
      "v c             ",
      "v c             ",
      "v c             ",
      "v c             ",
      "v c             ",
      "v c             ",
      "v c             ",
      "v  ddddddddddddd",
      "v efffffffffffff",
      "vgc             ",
      "vhc             ",
      "vhc             ",
      "vijkb           ",
      "vllkb           ",
      "vllkb           ",
      "vvvvvvvvvvvvvvvv"
    ],
    [
      "v               ",
      "v               ",
      "v               ",
      "v               ",
      "v               ",
      "v               ",
      "v               ",
      "v               ",
      "v               ",
      "v               ",
      "v               ",
      "v               ",
      "v  kkkb         ",
      "v  mlkb         ",
      "v nolkb         ",
      "vvvvvvvvvvvvvvvv"
    ],
    [
      "v               ",
      "v               ",
      "v               ",
      "v               ",
      "v               ",
      "v               ",
      "v               ",
      "v               ",
      "v               ",
      "v               ",
      "v               ",
      "v               ",
      "v   lkkkb       ",
      "v    plkb       ",
      "v     lkb       ",
      "vvvvvvvvvvvvvvvv"
    ],
    [
      "v               ",
      "v               ",
      "v               ",
      "v               ",
      "v               ",
      "v               ",
      "v               ",
      "v               ",
      "v               ",
      "v               ",
      "v               ",
      "v               ",
      "v     lkkkb     ",
      "v      qlkb     ",
      "v      elkb     ",
      "vvvvvvvvvvvvvvvv"
    ],
    [
      "v               ",
      "v               ",
      "v               ",
      "v               ",
      "v               ",
      "v               ",
      "v               ",
      "v               ",
      "v               ",
      "v               ",
      "v               ",
      "v               ",
      "v       lkkkb   ",
      "v        plkb   ",
      "v         lkb   ",
      "vvvvvvvvvvvvvvvv"
    ]
  ]
}