{
  "name": "multi_gallery_3_ground",
  "refpalette": "deceasedcraft:multi_gallery_3/multi_gallery_3_ground_palette",
  "xsize": 16,
  "zsize": 16,
  "slices": [
    [
      "     abcdccccccc",
      "      bceccccccf",
      "      abcccccccc",
      "       bcccccfcc",
      "      ghhhhhhhhh",
      "                ",
      "                ",
      "                ",
      "                ",
      "                ",
      "                ",
      "                ",
      "hhhhhhhhhhhhhhhh",
      "iiiiiiiiiiiiiiii",
      "iiiiiiiiiiiiiiii",
      "iiiiiiiiiiiiiiii"
    ],
    [
      "     jj k       ",
      "      jlm  n    ",
      "      jjn       ",
      "       j  l     ",
      "     ghhhhhhhhhh",
      "                ",
      "                ",
      "                ",
      "                ",
      "                ",
      "                ",
      "                ",
      "hhhhhhhhhhhhhhhh",
      "                ",
      "                ",
      "                "
    ],
    [
      "                ",
      "        m       ",
      "                ",
      "                ",
      "    ghhhhhhhhhhh",
      "                ",
      "                ",
      "                ",
      "                ",
      "                ",
      "                ",
      "                ",
      "hhhhhhhhhhhhhhhh",
      "                ",
      "                ",
      "                "
    ],
    [
      "         m      ",
      "        m       ",
      "                ",
      "                ",
      "   ghhhhhhhhhhhh",
      "                ",
      "                ",
      "                ",
      "                ",
      "                ",
      "                ",
      "                ",
      "hhhhhhhhhhhhhhhh",
      "                ",
      "                ",
      "                "
    ],
    [
      "j      oomoo    ",
      "j      omooo    ",
      "        oo      ",
      "                ",
      "  ghhhhhhhhhhhhh",
      "                ",
      "                ",
      "                ",
      "                ",
      "                ",
      "                ",
      "                ",
      "hhhhhhhhhhhhhhhh",
      "                ",
      "                ",
      "                "
    ],
    [
      "j       ooo     ",
      "        mo      ",
      "                ",
      "  g             ",
      "  hhhhhhhhhppppp",
      "  qqqqqqqqqrrrrr",
      "   qqqqqqqqrrrrr",
      "   qqqqqqqqrrrrr",
      "    qqqqqqqrrrrr",
      "    qqqqqqqrrrrr",
      "     qqqqqqrrrrr",
      "     qqqqqqrrrrr",
      "hhhhhhhhhhhppppp",
      "                ",
      "                ",
      "                "
    ]
  ]
}