{
  "name": "multi_gallery_3_base1",
  "refpalette": "deceasedcraft:multi_gallery_3/multi_gallery_3_base1_palette",
  "xsize": 16,
  "zsize": 16,
  "slices": [
    [
      " aaa   b        ",
      "   aa  b        ",
      "   caa  b       ",
      "  cdda  beeeeeee",
      "acddf  ggggggggg",
      "aafff           ",
      "                ",
      "                ",
      "                ",
      "                ",
      "                ",
      "                ",
      "gggggggggggggggg",
      "hhhhhhhhhhhhhhhh",
      "hhhhhhhhhhhhhhhh",
      "vvvvvvvvvvvvvvvv"
    ],
    [
      "       b        ",
      "   aa  b        ",
      "    aa  b       ",
      "     a  beeeeeee",
      "    ca ggggggggg",
      "aaccca          ",
      " addda          ",
      "  fff           ",
      "    f           ",
      "                ",
      "                ",
      "                ",
      "gggggggggggggggg",
      "hhhhhhhhhhhhhhhh",
      "hhhhhhhhhhhhhhhh",
      "vvvvvvvvvvvvvvvv"
    ],
    [
      "       b        ",
      "       b        ",
      "        b i     ",
      "        beeeeeee",
      "     a ggggggggg",
      " a   a          ",
      " a   a          ",
      " accca          ",
      " fddca          ",
      "  fdda          ",
      "   f            ",
      "                ",
      "gggggggggggggggg",
      "hhhhhhhhhhhhhhhh",
      "hhhhhhhhhhhhhhhh",
      "vvvvvvvvvvvvvvvv"
    ],
    [
      "      jb        ",
      "      jb        ",
      "       jb       ",
      "       jbeeeeeee",
      "       ggggggggg",
      "                ",
      " a   a          ",
      "aa   a          ",
      "ac   a          ",
      "fdc  a          ",
      "fddcaa          ",
      "ffd a           ",
      "gggggggggggggggg",
      "hhhhhhhhhhhhhhhh",
      "hhhhhhhhhhhhhhhh",
      "vvvvvvvvvvvvvvvv"
    ],
    [
      "      gdkkkkkkkk",
      "      gdkkkkkkkk",
      "       gdkkkkkkk",
      "       gdeeeeeee",
      "       ggggggggg",
      "                ",
      "                ",
      "a               ",
      "a               ",
      "c               ",
      "c   a           ",
      "cc aa           ",
      "gggggggggggggggg",
      "hhhhhhhhhhhhhhhh",
      "hhhhhhhhhhhhhhhh",
      "vvvvvvvvvvvvvvvv"
    ],
    [
      "      glllllllll",
      "      glllllllll",
      "       gllllllll",
      "       gllllllll",
      "       ggggggggg",
      "                ",
      "                ",
      "                ",
      "a               ",
      "                ",
      "                ",
      "                ",
      "gggggggggggggggg",
      "hhhhhhhhhhhhhhhh",
      "hhhhhhhhhhhhhhhh",
      "vvvvvvvvvvvvvvvv"
    ]
  ]
}