{
  "name": "multi_gallery_3_base2",
  "refpalette": "deceasedcraft:multi_gallery_3/multi_gallery_3_base2_palette",
  "xsize": 16,
  "zsize": 16,
  "slices": [
    [
      "aaaaaaaaaaaaaaaa",
      "aaaaaaaaaaaaaaaa",
      "aaaaaaaaaaaaaaaa",
      "aaaaaaaaaaaaaaaa",
      "aaaaaaaaaaaaaaaa",
      "aaaaaaaaaaaaaaaa",
      "aaaaaaaaaaaaaaaa",
      "aaaaaaaaaaaaaaaa",
      "aaaaaaaaaaaaaaaa",
      "aaaaaaaaaaaaaaaa",
      "aaaaaaaaaaaaaaaa",
      "aaaaaaaaaaaaaaaa",
      "bbbbbbbbbbbbbbbb",
      "aaaaaaaaaaaaaaaa",
      "aaaaaaaaaaaaaaaa",
      "vvvvvvvvvvvvvvvv"
    ],
    [
      "aaaaaaaaaaaaaaaa",
      "aaaaaaaaaaaaaaaa",
      "aaaaaaaaaaaaaaaa",
      "aaaaaaaaaaaaaaaa",
      "aaaaaaaaaaaaaaaa",
      "aaaaaaaaaaaaaaaa",
      "aaaaaaaaaaaaaaaa",
      "aaaaaaaaaaaaaaaa",
      "aaaaaaaaaaaaaaaa",
      "aaaaaaaaaaaaaaaa",
      "aaaaaaaaaaaaaaaa",
      "aaaaaaaaaaaaaaaa",
      "bbbbbbbbbbbbbbbb",
      "aaaacccccccccccc",
      "aaaaaaaaaaaaaaaa",
      "vvvvvvvvvvvvvvvv"
    ],
    [
      "aaaaaaacdddddddd",
      "aaaaaaacdddddddd",
      "aaaaaaaacddddddd",
      "aaaaaaaacccccccc",
      "aaaaaaaaaaaaaaaa",
      "aaaaaaaaaaaaaaaa",
      "aaaaaaaaaaaaaaaa",
      "aaaaaaaaaaaaaaaa",
      "aaaaaaaaaaaaaaaa",
      "aaaaaaaaaaaaaaaa",
      "aaaaeffffffaaaaa",
      "aaaaeffffffaaaaa",
      "bbbbgbbbbbbbbbbb",
      "aaacgggggggggggg",
      "aaaacccccccccccc",
      "vvvvvvvvvvvvvvvv"
    ],
    [
      "hhhhhhhi        ",
      "hhhhhhhi        ",
      "hhhhhhhhi       ",
      "hhhhhhhhijjjjjjj",
      "hhhhhhhbbbbbbkbb",
      "hhhhhhhhhhhhhhaa",
      "hhhhhhhhhhhhhhaa",
      "hhhhhhhhhhhhhhaa",
      "hhhhhhhhhhhhhhaa",
      "hhhhhhhhhhhhhhaa",
      "hhhhlmmmmmmfffff",
      "hhhhlmmmmmmfffff",
      "bkbbbbbkbbbbbkbb",
      "aaaacccccccccccc",
      "aaaaaaaaaaaaaaaa",
      "vvvvvvvvvvvvvvvv"
    ],
    [
      "       i        ",
      "nn     i        ",
      "n       i       ",
      "n       ijjjjjjj",
      "       bbbbbbobb",
      "          pqqqhh",
      "           qqqhh",
      "           qqqhh",
      "           qqqhh",
      "           qqqhh",
      "          rstuwx",
      "          rstuwx",
      "bobbbbbobbbbbobb",
      "ajaaaaajaaaaajaa",
      "aaaaaaaaaaaaaaaa",
      "vvvvvvvvvvvvvvvv"
    ],
    [
      "yyyy   i        ",
      "AAcy   i        ",
      "Accn    i       ",
      "Acn     ijjjjjjj",
      "yn     bbbbbbbbb",
      "          B    C",
      "                ",
      "                ",
      "                ",
      "                ",
      "                ",
      "                ",
      "bbbbbbbbbbbbbbbb",
      "aaaaaaaaaaaaaaaa",
      "aaaaaaaaaaaaaaaa",
      "vvvvvvvvvvvvvvvv"
    ]
  ]
}