{
  "name": "multi_terraceplaza_3_floor1",
  "refpalette": "deceasedcraft:multi_terraceplaza_3/multi_terraceplaza_3_floor1_palette",
  "xsize": 16,
  "zsize": 16,
  "slices": [
    [
      "      ab  cd   e",
      "      ab  cd   e",
      "      ab  cd   e",
      "      af  cgeeee",
      "      ab  cd   e",
      "      af  cd   e",
      "      ab  cd   e",
      "      ab  cdeeeh",
      "      af  cd    ",
      "      af  cd    ",
      "      ab  cd    ",
      "      af  cd    ",
      "      ab  cd    ",
      "      ab  cd    ",
      "      af  cgeeee",
      "      ab  cdij  "
    ],
    [
      "      ab klmnnnn",
      "      ab klmnnnn",
      "      ab klmnnnn",
      "      afoopgmmmm",
      "      ab klmnnnn",
      "      af klmnnnn",
      "      ab klmnnnn",
      "      ab klmnnnn",
      "      af klmnnnn",
      "      af klmnnnn",
      "      ab klmnnnn",
      "      af klmnnnn",
      "      ab klmnnnn",
      "      ab klmnnnn",
      "      afoopgmmmm",
      "      ab klmnnnn"
    ],
    [
      "      ab  qrssss",
      "      ab  qrssss",
      "      ab  qrssss",
      "      af  tgeeee",
      "      ab  qrssss",
      "      af  qrssss",
      "      ab  qrssss",
      "      ab  qruwss",
      "      af  qruxss",
      "      af  qruxss",
      "      ab  qruyss",
      "      af  qrssss",
      "      ab  qrssss",
      "      ab  qrssss",
      "      af  tgssss",
      "      ab  qrssss"
    ],
    [
      "      ab  q e Ae",
      "      ab  q e Ae",
      "      ab  q e Ae",
      "      af   geeee",
      "      ab  q BCCD",
      "      af  q     ",
      "      ab  q     ",
      "      ab  q    C",
      "      af  q   EC",
      "      af  q   FC",
      "      ab  q    C",
      "      af  q     ",
      "      ab  q     ",
      "      ab  q IIII",
      "      af   gJJJJ",
      "      ab  q KLKL"
    ],
    [
      "      ab  q M Ne",
      "      ab    M Oe",
      "      ab  q e Pe",
      "      af   geeee",
      "      ab  q  QQQ",
      "      af        ",
      "      ab  q     ",
      "      ab  q    R",
      "      af      SQ",
      "      af      TQ",
      "      ab        ",
      "      af  q     ",
      "      ab  q     ",
      "      ab    UV R",
      "      af   gWWWW",
      "      ab  q     "
    ],
    [
      "      ab    e Xe",
      "      ab    e Ye",
      "      ab    e Ze",
      "      af   geeee",
      "      ab     QQQ",
      "      af        ",
      "      ab        ",
      "      ab        ",
      "      af      0Q",
      "      af      1Q",
      "      ab        ",
      "      af        ",
      "      ab        ",
      "      ab        ",
      "      af   g    ",
      "      ab        "
    ]
  ]
}