{
  "name": "multi_terraceplaza_3_base2",
  "refpalette": "deceasedcraft:multi_terraceplaza_3/multi_terraceplaza_3_base2_palette",
  "xsize": 16,
  "zsize": 16,
  "slices": [
    [
      "vabbabbbbbbacccc",
      "vabbabbbbbbacccc",
      "vabbaaaaaaaacccc",
      "vabbaccccccdcccc",
      "vabbaccccccccccc",
      "vabbaccccccccccc",
      "vabbaccccccccccc",
      "vabbaccccccccccc",
      "vabbaccccccccccc",
      "vabbaccccccccccc",
      "vabbaccccccccccc",
      "vabbaccccccccccc",
      "vabbaccccccccccc",
      "vabbaaaaaaaacccc",
      "vabbabbabbbdaaaa",
      "vabbabbabbbbcccc"
    ],
    [
      "va  aef   gah  i",
      "va  ajkllmjah  n",
      "va  aaaaaaaaopqr",
      "va  astuwxxdy  A",
      "va  a   B   o  A",
      "va  a       A  o",
      "va  aC  DD  y  o",
      "va  aE  DD  y  y",
      "va FaI  DD  y  y",
      "va  aJ  DD  y  o",
      "va  a           ",
      "va  a           ",
      "va  aKLMNOOO    ",
      "va  aaaaaaaah PP",
      "va  a  aQQQdaaaa",
      "va  a  aR   SS  "
    ],
    [
      "va  a      aT  U",
      "va  aVWWWWVaT   ",
      "va  aaaaaaaay  y",
      "va  aXY wZ0do  r",
      "va  a   1   o  y",
      "va  a       A  2",
      "va  a   34  A  A",
      "va  a   56  7  y",
      "va  a   89  A  o",
      "va  a   #$  y  r",
      "va  a           ",
      "va  a           ",
      "va  a    %^&    ",
      "va  aaaaaaaa* ((",
      "va  a  a)))daaaa",
      "va  a  a    SS  "
    ],
    [
      "va  a      aT   ",
      "va  aVWWWWVaT   ",
      "va  aaaaaaaa    ",
      "va  a      d    ",
      "va  a           ",
      "va  a           ",
      "va  a           ",
      "va  a           ",
      "va  a           ",
      "va  a           ",
      "va  a           ",
      "va  a           ",
      "va  a+-[[       ",
      "va  aaaaaaaa  ] ",
      "va  a  a   daaaa",
      "va  a  a    SS  "
    ],
    [
      "va  a      a    ",
      "va  aVVVVVVa    ",
      "va  aaaaaaaa    ",
      "va  a      d    ",
      "va  a           ",
      "va  a           ",
      "va  a           ",
      "va  a           ",
      "va  a           ",
      "va  a           ",
      "va  a           ",
      "va  a           ",
      "va  a           ",
      "va  aaaaaaaa    ",
      "va  a  a   daaaa",
      "va  a  a    SS  "
    ],
    [
      "va  a      a    ",
      "va  a      a    ",
      "va  aaaaaaaa    ",
      "va  a      d    ",
      "va  a           ",
      "va  a           ",
      "va  a           ",
      "va  a           ",
      "va  a           ",
      "va  a           ",
      "va  a           ",
      "va  a           ",
      "va  a           ",
      "va  aaaaaaaa    ",
      "va  a{{a   daaaa",
      "va  a{{a   }SS  "
    ]
  ]
}