{
  "name": "multi_terraceplaza_3_ground",
  "refpalette": "deceasedcraft:multi_terraceplaza_3/multi_terraceplaza_3_ground_palette",
  "xsize": 16,
  "zsize": 16,
  "slices": [
    [
      "HHHabcdeffghiiii",
      "HHHajcdeffghiiii",
      "HHHabcdeffghiiii",
      "HHHabcdefklmiiii",
      "HHHabcdeffghiiii",
      "HHHajcdeffghiiii",
      "HHHabcdeffghiiii",
      "HHHabcdeffghnnnn",
      "HHHabcdeffghnnnn",
      "HHHabcdeffghnnnn",
      "HHHabcdeffghnnnn",
      "HHHabcdeffghnnnn",
      "HHHajcdeffghnnnn",
      "HHHabcdeffghnnnn",
      "HHHabcdefklmoooo",
      "HHHabcdeffghnnnn"
    ],
    [
      "    pq r  g osso",
      "    tq r  g o uo",
      "    wq r  g o uo",
      "    wx y   moAoB",
      "    wq r  g o   ",
      "    tq r  g oC  ",
      "    pq r  g oD  ",
      "    pq r  g oooE",
      "    pq r  gF    ",
      "    pq r  gIJJJK",
      "    pq r  g     ",
      "    pq r  g     ",
      "    tq r  g LMN ",
      "    wq r  g OPN ",
      "    wx y   moooo",
      "    wq r  g QRS "
    ],
    [
      "     qTU  g r so",
      "    VqTU    r  o",
      "      TU    o uo",
      "     WTX   moYoZ",
      "      TU  g o   ",
      "    VqTX    r   ",
      "     qTU  g r   ",
      "     qTU    ooo0",
      "     qTX      1 ",
      "     qTX  g  23 ",
      "     qTU        ",
      "     qTX  g     ",
      "    VqTU  g     ",
      "      TU  g  4  ",
      "     WTX   moooo",
      "      TU  g QR  "
    ],
    [
      "      TU    o 5o",
      "      TU    o 6o",
      "      TU    o 7o",
      "     pTX   mo8oo",
      "      TU    o  o",
      "      TX    o  o",
      "      TU    o  o",
      "      TU    ooo9",
      "      TX        ",
      "      TX        ",
      "      TU        ",
      "      TX        ",
      "      TU        ",
      "      TU        ",
      "     pTX   moooo",
      "      TU    QR  "
    ],
    [
      "      TU    o #o",
      "      TU    o $o",
      "      TU    o $o",
      "     pTX   moooo",
      "      TU    o  o",
      "      TX    o  o",
      "      TU    o  o",
      "      TU    ooo%",
      "      TX        ",
      "      TX        ",
      "      TU        ",
      "      TX        ",
      "      TU        ",
      "      TU        ",
      "     pTX   moooo",
      "      TU    QR  "
    ],
    [
      "      TU   ^   o",
      "      TU   ^   o",
      "      TU   ^   o",
      "      TX   moooo",
      "      TU   ^   o",
      "      TX   ^   o",
      "      TU   ^   o",
      "      TU   ^ooo%",
      "      TX   ^    ",
      "      TX   ^    ",
      "      TU   ^    ",
      "      TX   ^    ",
      "      TU   ^    ",
      "      TU   ^    ",
      "      TX   moooo",
      "      TU   ^Q   "
    ]
  ]
}