{
  "name": "multi_terraceplaza_3_base1",
  "refpalette": "deceasedcraft:multi_terraceplaza_3/multi_terraceplaza_3_base1_palette",
  "xsize": 16,
  "zsize": 16,
  "slices": [
    [
      "va  a      a    ",
      "va  a      a    ",
      "va  aaaaaaaa    ",
      "va  a      b    ",
      "va  a           ",
      "va  a           ",
      "va  a           ",
      "va  a           ",
      "va  a           ",
      "va  a           ",
      "va  a           ",
      "va  a           ",
      "va  a           ",
      "va  aaaaaaaa    ",
      "va  a  c   baaaa",
      "va  a  c   dee  "
    ],
    [
      "va  a      a    ",
      "va  a      a    ",
      "va  aaaaaaaa    ",
      "va  a      b    ",
      "va  a           ",
      "va  a           ",
      "va  a           ",
      "va  a           ",
      "va  a           ",
      "va  a           ",
      "va  a           ",
      "va  a           ",
      "va  a           ",
      "va  aaaaaaaa    ",
      "va  a      baaaa",
      "va  a      dee  "
    ],
    [
      "va  a      a    ",
      "va  a      a    ",
      "va  aaaaaaaa    ",
      "va  a      b    ",
      "va  a           ",
      "va  a           ",
      "va  a           ",
      "va  a           ",
      "va  a           ",
      "va  a           ",
      "va  a           ",
      "va  a           ",
      "va  a           ",
      "va  aaaaaaaa    ",
      "va  a      baaaa",
      "va  a      dee  "
    ],
    [
      "va  afgggggahii ",
      "va  aggggggahii ",
      "va  aaaaaaaahii ",
      "va  aeeeeeebhii ",
      "va  aeeeeee hii ",
      "va  aeeeeee hii ",
      "va  aeeeeee hii ",
      "va  aeeeeee hii ",
      "va  aeeeeee hii ",
      "va  aeeeeee hii ",
      "va  aeeeeee hii ",
      "va  aeeeeee hiii",
      "va  aeeeeee hiii",
      "va  ajaaaaaahhhh",
      "va  aj     baaaa",
      "va  aj  jjjjjhhh"
    ],
    [
      "va  ajkkkkkahlmm",
      "va  ajkkkkkahlmm",
      "va  ajaaaaaahlmm",
      "va  ajkkkkkbhlmm",
      "va  ajnn nemhlmm",
      "va  ajjjjjomhlmm",
      "va  ajnnnnemhlmm",
      "va  aj  n emhlmm",
      "va  ajn   emhlmm",
      "va  aj  n emhlmm",
      "va  aj  nnemhlmm",
      "va  ajjjjjomhlmm",
      "va  ajnn nemhlll",
      "va  ajaaaaaahhhh",
      "va  aggggggbaaaa",
      "va  aggggggghhhh"
    ],
    [
      "vaggakkkkkpqrstt",
      "vaggakkkkkpqrstt",
      "vaggakkkkkpqrstt",
      "vaggaaaaaaubqqqq",
      "vaggakkkkkpqrstt",
      "vaggakkkkkpqrstt",
      "vaggakkkkkpqrstt",
      "vaggakkkkkpqrstt",
      "vaggakkkkkpqrstt",
      "vaggakkkkkpqrstt",
      "vaggakkkkkpqrstt",
      "vaggakkkkkpqrstt",
      "vaggakkkkkpqrsss",
      "vaggaaaaaapqrrrr",
      "vaggakkkkkubqqqq",
      "vaggakkkkkpqtttt"
    ]
  ]
}