{
  "name": "multi_terraceplaza_3_floor2",
  "refpalette": "deceasedcraft:multi_terraceplaza_3/multi_terraceplaza_3_floor2_palette",
  "xsize": 16,
  "zsize": 16,
  "slices": [
    [
      "      ab    c dc",
      "      ab    c ec",
      "      ab    c fc",
      "      ag   hcccc",
      "      ab     i j",
      "      ag        ",
      "      ab        ",
      "      ab        ",
      "      ag        ",
      "      ag        ",
      "      ab        ",
      "      ag        ",
      "      ab        ",
      "      ab        ",
      "      ag   h    ",
      "      ab        "
    ],
    [
      "      ab   k   c",
      "      ab   k   c",
      "      ab   k   c",
      "      ag   hcccc",
      "      ab   k  l ",
      "      ag   k    ",
      "      ab   k    ",
      "      ab   k    ",
      "      ag   k    ",
      "      ag   k    ",
      "      ab   k    ",
      "      ag   k    ",
      "      ab   k    ",
      "      ab   k    ",
      "      ag   h    ",
      "      ab        "
    ],
    [
      "      ab  mn   c",
      "      ab  mn   c",
      "      ab  mn   c",
      "      ag  mhcccc",
      "      ab  mn    ",
      "      ag  mn    ",
      "      ab  mn  o ",
      "      ab  mn    ",
      "      ag  mn    ",
      "      ag  mn    ",
      "      ab  mn    ",
      "      ag  mn  p ",
      "      ab  mn    ",
      "      ab  mn    ",
      "      ag  mh    ",
      "      ab        "
    ],
    [
      "      ab qrstttt",
      "      ab qrstttt",
      "      ab qrstttt",
      "      aguuwhssss",
      "      ab qrstttt",
      "      ag qrstttt",
      "      ab qrstttt",
      "      ab qrstttt",
      "      ag qrstttt",
      "      ag qrstttt",
      "      ab qrstttt",
      "      ag qrstttt",
      "      ab qrstttt",
      "      ab qrstttt",
      "      ag qwhssss",
      "      ab  x     "
    ],
    [
      "      ab  yABBBC",
      "      ab  yABBBB",
      "      ab  yABBBB",
      "      ag  DhEEEE",
      "      ab  yAFrFF",
      "      ag  yArrFr",
      "      ab  yArrrr",
      "      ab  yArrFr",
      "      ag  yArrrr",
      "      ag  yArFrr",
      "      ab  yArrrr",
      "      ag  yArrrr",
      "      ab  yArrrr",
      "      abIIJAKKKK",
      "      agIILhssss",
      "      abIIMBBBBB"
    ],
    [
      "      ab  y     ",
      "      ab  y     ",
      "      ab  y     ",
      "      ag   h    ",
      "      ab  y     ",
      "      ag  y  N  ",
      "      ab  y  O  ",
      "      ab  y  P  ",
      "      ag  y     ",
      "      ag  y     ",
      "      abIIJQRRSR",
      "      agIILT    ",
      "      abIIMBQQQQ",
      "      ab  MMMMMM",
      "      ag  MMMMMM",
      "      ab  UUUUUU"
    ]
  ]
}