{
  "name": "multi_terraceplaza_3_floor3",
  "refpalette": "deceasedcraft:multi_terraceplaza_3/multi_terraceplaza_3_floor3_palette",
  "xsize": 16,
  "zsize": 16,
  "slices": [
    [
      "      ab  c     ",
      "      ab        ",
      "      ab  c     ",
      "      ad   e    ",
      "      ab        ",
      "      ad  c     ",
      "      ab        ",
      "      abffgh    ",
      "      adffij    ",
      "      adffklmnnn",
      "      ab  komnnn",
      "      ad  kppppp",
      "      ab  q     ",
      "      ab  rrrrrr",
      "                ",
      "                "
    ],
    [
      "      ab        ",
      "      ab        ",
      "      ab        ",
      "      ad   e    ",
      "      abffgh    ",
      "      adffij    ",
      "      abffklhhhh",
      "      ab  komnnn",
      "      ad  kpmnnn",
      "      ad  q     ",
      "      ab  r     ",
      "                ",
      "                ",
      "                ",
      "                ",
      "                "
    ],
    [
      "      ab        ",
      "      abffghhhhh",
      "      abffijjjjj",
      "      adffkessss",
      "      ab  kkkkkk",
      "      ad  kppppp",
      "      ab  q     ",
      "      ab  r     ",
      "                ",
      "                ",
      "                ",
      "                ",
      "                ",
      "                ",
      "                ",
      "                "
    ],
    [
      "      abffklllll",
      "      ab  kooooo",
      "      ab  kkkkkk",
      "      ad  qqqqqq",
      "      ab  rrrrrr",
      "                ",
      "                ",
      "                ",
      "                ",
      "                ",
      "                ",
      "                ",
      "                ",
      "                ",
      "                ",
      "                "
    ],
    [
      "      ab  q     ",
      "      ab  r     ",
      "                ",
      "                ",
      "                ",
      "                ",
      "                ",
      "                ",
      "                ",
      "                ",
      "                ",
      "                ",
      "                ",
      "                ",
      "                ",
      "                "
    ],
    [
      "                ",
      "                ",
      "                ",
      "                ",
      "                ",
      "                ",
      "                ",
      "                ",
      "                ",
      "                ",
      "                ",
      "                ",
      "                ",
      "                ",
      "                ",
      "                "
    ]
  ]
}