{
  "name": "multi_policeapartment_3_ground",
  "refpalette": "deceasedcraft:multi_policeapartment_3/multi_policeapartment_3_ground_palette",
  "xsize": 16,
  "zsize": 16,
  "slices": [
    [
      "HHHHHHHHHHHHHHHH",
      "HHHHHHHHHHHHHHHH",
      "HHHHHHHHHHHHHHHH",
      "HHHHHHHHHHHHHHHH",
      "HHHHHHHHHHHHHHHH",
      "aaaaaaaaaaaaaaaa",
      "bbbccccdddeaaaaa",
      "eeeefffcddeaaaaa",
      "eeeefffcddeaaaaa",
      "eeeefffcddeaaaaa",
      "eeeefffcddeaaaaa",
      "eeeegffcddeeeeee",
      "eeeeffhcdddddddd",
      "cccccccddddddddd",
      "dddddddddddddddd",
      "dddddddddddddddd"
    ],
    [
      "                ",
      "    i j klj     ",
      "     mnoppnq    ",
      "    rstuwxuy    ",
      "    Aonoppn     ",
      "  B   C D  E    ",
      "FIJccccK  L     ",
      "  MNfffc OLPQPQP",
      "    R  c SL     ",
      "   TfUVc OL     ",
      "  WXf fc OLYZYZY",
      "  W0f1fc OLLLLLL",
      "23456fhc OOSOOOO",
      "cccccccK        ",
      "                ",
      "                "
    ],
    [
      "                ",
      "                ",
      "      7i@p89#   ",
      "     7$ @%o9    ",
      "     77$@p8$    ",
      "  B      ^      ",
      "&*JccccK        ",
      "  MNfffc        ",
      "    (  c        ",
      "   Tf )c        ",
      "  WXfUVc        ",
      "  WXf fc        ",
      "22456f+c        ",
      "cccccccK        ",
      "                ",
      "                "
    ],
    [
      "                ",
      "                ",
      "        -       ",
      "        7 7     ",
      "        [       ",
      "  B             ",
      "]]JccccK        ",
      "  MNfffc        ",
      "   +f  c        ",
      "   Tf  c        ",
      "  WXf )c        ",
      "  WXfUVc        ",
      "{24Xfffc        ",
      "cccccccK        ",
      "                ",
      "                "
    ],
    [
      "                ",
      "                ",
      "                ",
      "                ",
      "                ",
      "}}|             ",
      "JJJccccK        ",
      "MMMXfffc        ",
      "   Xf  c        ",
      "   Xf  c        ",
      "  WXf  c        ",
      "  WX;:)c        ",
      "444X ' c        ",
      "cccccccK        ",
      "                ",
      "                "
    ],
    [
      "                ",
      "                ",
      "                ",
      "                ",
      "                ",
      "                ",
      "cccccccK        ",
      "   cfffc        ",
      "   cf  c        ",
      "   cf  c        ",
      "   c;: c        ",
      "   c<  c        ",
      "   c   c        ",
      "cccccccK        ",
      "                ",
      "                "
    ]
  ]
}