{
  "name": "multi_policeapartment_3_top",
  "refpalette": "deceasedcraft:multi_policeapartment_3/multi_policeapartment_3_top_palette",
  "xsize": 16,
  "zsize": 16,
  "slices": [
    [
      "aab             ",
      "aab             ",
      "aab             ",
      "aab             ",
      "aab             ",
      "aab             ",
      "aacccccd        ",
      "aaae   c        ",
      "aaae   c        ",
      "aaae   c        ",
      "aaae   c        ",
      "aaaeffgc        ",
      "aaaeeh c        ",
      "cccccccd        ",
      "                ",
      "                "
    ],
    [
      " ij             ",
      " kj             ",
      "  j             ",
      " lj             ",
      " mj             ",
      " nj             ",
      " ncccccd        ",
      "   k   c        ",
      "  ok   c        ",
      "  ok   c        ",
      "  ok   c        ",
      "  ok   c        ",
      "    pp c        ",
      "cccccccd        ",
      "                ",
      "                "
    ],
    [
      "                ",
      "                ",
      "                ",
      "                ",
      "                ",
      " n              ",
      " ncccccd        ",
      "       c        ",
      "  o    c        ",
      "  o    c        ",
      "  o    c        ",
      "  o    c        ",
      "       c        ",
      "qqqqqrcd        ",
      "                ",
      "                "
    ],
    [
      "                ",
      "                ",
      "                ",
      "                ",
      "                ",
      "st              ",
      "stcccccd        ",
      "       c        ",
      "  o    c        ",
      "  o    c        ",
      "  o    c        ",
      "  o    c        ",
      "       c        ",
      "cccccccd        ",
      "                ",
      "                "
    ],
    [
      "                ",
      "                ",
      "                ",
      "                ",
      "                ",
      "                ",
      "cccccccd        ",
      "       c        ",
      "  o    c        ",
      "  o    c        ",
      "  o    c        ",
      "  o    c        ",
      "       c        ",
      "cccccccd        ",
      "                ",
      "                "
    ],
    [
      "                ",
      "                ",
      "                ",
      "                ",
      "                ",
      "                ",
      "cccccccd        ",
      "       c        ",
      "  o    c        ",
      "  o    c        ",
      "  o    c        ",
      "  o    c        ",
      "       c        ",
      "cccccccd        ",
      "                ",
      "                "
    ],
    [
      "                ",
      "                ",
      "                ",
      "                ",
      "                ",
      "                ",
      "cccccccd        ",
      "aaaaaaac        ",
      "aaaaaaac        ",
      "aaaaaaac        ",
      "aaaaaaac        ",
      "aaaaaaac        ",
      "aaaaaaac        ",
      "cccccccd        ",
      "                ",
      "                "
    ],
    [
      "                ",
      "                ",
      "                ",
      "                ",
      "                ",
      "                ",
      "cccccccd        ",
      "uwxyyyyc        ",
      "       c        ",
      "       c        ",
      "      xc        ",
      "       c        ",
      "      xc        ",
      "cccccccd        ",
      "                ",
      "                "
    ],
    [
      "                ",
      "                ",
      "                ",
      "                ",
      "                ",
      "                ",
      "cccccccd        ",
      " AAAAAAc        ",
      "      xc        ",
      "       c        ",
      "       c        ",
      "       c        ",
      "x   x xc        ",
      "cccccccd        ",
      "                ",
      "                "
    ],
    [
      "                ",
      "                ",
      "                ",
      "                ",
      "                ",
      "                ",
      "BBBBBBB         ",
      "CCCCCCCD        ",
      "CCCCCCCD        ",
      "CCCCCCCD        ",
      "CCCCCCCD        ",
      "CCCCCCCD        ",
      "CCCCCCCD        ",
      "EEEEEEE         ",
      "                ",
      "                "
    ]
  ]
}