{
  "name": "multi_policeapartment_3_floor1",
  "refpalette": "deceasedcraft:multi_policeapartment_3/multi_policeapartment_3_floor1_palette",
  "xsize": 16,
  "zsize": 16,
  "slices": [
    [
      "                ",
      "                ",
      "                ",
      "                ",
      "                ",
      "                ",
      "aaaaaaab        ",
      "   accca        ",
      "   ac  a        ",
      "   ade a        ",
      "   af  a        ",
      "   a   a        ",
      "   a   a        ",
      "aaaaaaab        ",
      "                ",
      "                "
    ],
    [
      "gggggggggggggggg",
      "gggggggggggggggg",
      "gggggg ggggggggg",
      "gggg gggg gggggg",
      "gggg ggggggggggg",
      "hhhhhhhhhhhhhhhh",
      "aaaaaaab        ",
      "   accca        ",
      "   adeia        ",
      "   af  a        ",
      "   a   a        ",
      "   a   a        ",
      "   a   a        ",
      "aaaaaaab        ",
      "                ",
      "                "
    ],
    [
      "                ",
      "                ",
      "                ",
      "                ",
      "                ",
      "                ",
      "aaaaaaab        ",
      "   a j a        ",
      "   afkla        ",
      "   a  ia        ",
      "   a   a        ",
      "   a   a        ",
      "   a   a        ",
      "mmmmmnab        ",
      "                ",
      "                "
    ],
    [
      "                ",
      "                ",
      "                ",
      "                ",
      "                ",
      "                ",
      "aaaaaaab        ",
      "   a   a        ",
      "   a  oa        ",
      "   a kla        ",
      "   a  ia        ",
      "   a   a        ",
      "  pa   a        ",
      "aaaaaaab        ",
      "                ",
      "                "
    ],
    [
      "                ",
      "                ",
      "                ",
      "                ",
      "                ",
      "                ",
      "aaaaaaab        ",
      "qqra   a        ",
      "qqqa   a        ",
      "qqqa  oa        ",
      "qqqa kla        ",
      "qqqa  ia        ",
      "qq!a   a        ",
      "aaaaaaab        ",
      "                ",
      "                "
    ],
    [
      "                ",
      "                ",
      "                ",
      "                ",
      "                ",
      "                ",
      "aaaaaaab        ",
      "sssat  a        ",
      "   a   a        ",
      "   a   a        ",
      "p  a  oa        ",
      "p pa kla        ",
      "sssatuca        ",
      "aaaaaaab        ",
      "                ",
      "                "
    ]
  ]
}