{
  "name": "multi_policeapartment_3_floor4",
  "refpalette": "deceasedcraft:multi_policeapartment_3/multi_policeapartment_3_floor4_palette",
  "xsize": 16,
  "zsize": 16,
  "slices": [
    [
      "aab             ",
      "aab             ",
      "aab             ",
      "aab             ",
      "aab             ",
      "aab             ",
      "aacccccd        ",
      "aaaeef c        ",
      "aaaeg  c        ",
      "aaae   c        ",
      "aaae   c        ",
      "aaaehhic        ",
      "aaaeej!c        ",
      "cccccccd        ",
      "                ",
      "                "
    ],
    [
      " kl             ",
      " kl             ",
      " kl             ",
      " kl             ",
      " kl             ",
      " ml             ",
      " mcccccd        ",
      "   nopec        ",
      "   k gqc        ",
      "  rk   c        ",
      "  rk   c        ",
      "  rk   c        ",
      "    ss c        ",
      "cccccccd        ",
      "                ",
      "                "
    ],
    [
      "                ",
      "                ",
      "                ",
      "                ",
      "                ",
      " m              ",
      " mcccccd        ",
      "     otc        ",
      "     uwc        ",
      "  x   qc        ",
      "  r    c        ",
      "  r    c        ",
      "       c        ",
      "yyyyyAcd        ",
      "                ",
      "                "
    ],
    [
      "                ",
      "                ",
      "                ",
      "                ",
      "                ",
      "BC              ",
      "BCcccccd        ",
      "       c        ",
      "  x   ic        ",
      "  r  uwc        ",
      "  r   qc        ",
      "  r    c        ",
      "       c        ",
      "cccccccd        ",
      "                ",
      "                "
    ],
    [
      "                ",
      "                ",
      "                ",
      "                ",
      "                ",
      "                ",
      "cccccccd        ",
      "       c        ",
      "  r    c        ",
      "  r   ic        ",
      "  r  uwc        ",
      "  r   qc        ",
      "       c        ",
      "cccccccd        ",
      "                ",
      "                "
    ],
    [
      "                ",
      "                ",
      "                ",
      "                ",
      "                ",
      "                ",
      "cccccccd        ",
      "   D   c        ",
      "  rD   c        ",
      "  rD   c        ",
      "  rD  ic        ",
      "  rD uwc        ",
      "   DDEec        ",
      "cccccccd        ",
      "                ",
      "                "
    ]
  ]
}