{
  "name": "multi_policeapartment_3_floor3",
  "refpalette": "deceasedcraft:multi_policeapartment_3/multi_policeapartment_3_floor3_palette",
  "xsize": 16,
  "zsize": 16,
  "slices": [
    [
      "aab             ",
      "aab             ",
      "aab             ",
      "aab             ",
      "aab             ",
      "aab             ",
      "aacccccd        ",
      "aaaeef c        ",
      "aaaeg  c        ",
      "aaae   c        ",
      "aaae   c        ",
      "aaaehhic        ",
      "aaaeej c        ",
      "cccccccd        ",
      "                ",
      "                "
    ],
    [
      " kl             ",
      " kl             ",
      " kl             ",
      " kl             ",
      " kl             ",
      " ml             ",
      " mcccccd        ",
      "    noec        ",
      "  pk gqc        ",
      "  pk   c        ",
      "  pk   c        ",
      "  pk   c        ",
      "    rr c        ",
      "cccccccd        ",
      "                ",
      "                "
    ],
    [
      "                ",
      "                ",
      "                ",
      "                ",
      "                ",
      " m              ",
      " mcccccd        ",
      "     n c        ",
      "  p  stc        ",
      "  p   qc        ",
      "  p    c        ",
      "  p    c        ",
      "       c        ",
      "uuuuuwcd        ",
      "                ",
      "                "
    ],
    [
      "                ",
      "                ",
      "                ",
      "                ",
      "                ",
      "xy              ",
      "xycccccd        ",
      "       c        ",
      "  p   ic        ",
      "  p  stc        ",
      "  p   qc        ",
      "  p    c        ",
      "       c        ",
      "cccccccd        ",
      "                ",
      "                "
    ],
    [
      "                ",
      "                ",
      "                ",
      "                ",
      "                ",
      "                ",
      "cccccccd        ",
      "       c        ",
      "  p    c        ",
      "  p   ic        ",
      "  p  stc        ",
      "  p   qc        ",
      "       c        ",
      "cccccccd        ",
      "                ",
      "                "
    ],
    [
      "                ",
      "                ",
      "                ",
      "                ",
      "                ",
      "                ",
      "cccccccd        ",
      "   A   c        ",
      "  pA   c        ",
      "  pA   c        ",
      "  pA  ic        ",
      "  pA stc        ",
      "   AABec        ",
      "cccccccd        ",
      "                ",
      "                "
    ]
  ]
}