{
  "name": "multi_policeapartment_3_base1",
  "refpalette": "deceasedcraft:multi_policeapartment_3/multi_policeapartment_3_base1_palette",
  "xsize": 16,
  "zsize": 16,
  "slices": [
    [
      "aaaaaaaaaaaaaaaa",
      "aaaaaaaaaaaaaaaa",
      "aaaaaaaaaaaaaaaa",
      "aaaaaaaaaaaaaaaa",
      "aaaaaaaaaaaaaaaa",
      "aaaaaaaaaaaaaaaa",
      "bbbbbbbbaaaaaaaa",
      "cdcdddebaaaaaaaa",
      "ddddcddbaaaaaaaa",
      "dddddddbaaaaaaaa",
      "ddddddebaaaaaaaa",
      "ddddddbbaaaaaaaa",
      "ddddddfbaaaaaaaa",
      "bbbbbbbbaaaaaaaa",
      "aaaaaaaaaaaaaaaa",
      "vvvvvvvvvvvvvvvv"
    ],
    [
      "aaaaaaaaaaaaaaaa",
      "aaaaaaaaaaaaaaaa",
      "aaaaaaaaaaaaaaaa",
      "aaaaaaaaaaaaaaaa",
      "aaaaaaaaaaaaaaaa",
      "aaaaaaaaaaaaaaaa",
      "ggcagabbaaaaaaaa",
      "   h hibaaaaaaaa",
      "j k   lbaaaaaaaa",
      "mmmb  nbaaaaaaaa",
      "ooobh pbaaaaaaaa",
      "q qh  bbaaaaaaaa",
      " h    hraaaaaaaa",
      "gbababbbaaaaaaaa",
      "aaaaaaaaaaaaaaaa",
      "vvvvvvvvvvvvvvvv"
    ],
    [
      "aaaaaaaaaaaaaaaa",
      "aaaaaaaaaaaaaaaa",
      "aaaaaaaaaaaaaaaa",
      "aaaaaaaaaaaaaaaa",
      "aaaaaaaaaaaaaaaa",
      "aaaaaaaaaaaaaaaa",
      "aagabbabaaaaaaaa",
      "     hsbaaaaaaaa",
      "      nbaaaaaaaa",
      "tu w  xbaaaaaaaa",
      " hy   Abaaaaaaaa",
      "     Bbbaaaaaaaa",
      "      Cbaaaaaaaa",
      "abbbbbbbaaaaaaaa",
      "aaaaaaaaaaaaaaaa",
      "vvvvvvvvvvvvvvvv"
    ],
    [
      "aaaaaaaaaaaaaaaa",
      "aaaaaaaaaaaaaaaa",
      "aaaaaaaaaaaaaaaa",
      "aaaaaaaaaaaaaaaa",
      "aaaaaaaaaaaaaaaa",
      "aaaaaaaaaaaaaaaa",
      "abbabbbbaaaaaaaa",
      "       baaaaaaaa",
      "       baaaaaaaa",
      "      hbaaaaaaaa",
      "       baaaaaaaa",
      "      bbaaaaaaaa",
      "      Cbaaaaaaaa",
      "bbbbbbbbaaaaaaaa",
      "aaaaaaaaaaaaaaaa",
      "vvvvvvvvvvvvvvvv"
    ],
    [
      "aaaaaaaaaaaaaaaa",
      "aaaaaaaaaaaaaaaa",
      "aaaaaaaaaaaaaaaa",
      "aaaaaaaaaaaaaaaa",
      "aaaaaaaaaaaaaaaa",
      "aaaaaaaaaaaaaaaa",
      "bbbbbbbbaaaaaaaa",
      "   h hhbaaaaaaaa",
      "      hbaaaaaaaa",
      "       baaaaaaaa",
      " h    hbaaaaaaaa",
      "     Dbbaaaaaaaa",
      "h h    baaaaaaaa",
      "bbbbbbbbaaaaaaaa",
      "aaaaaaaaaaaaaaaa",
      "vvvvvvvvvvvvvvvv"
    ],
    [
      "aaaaaaaaaaaaaaaa",
      "aaaaaaaaaaaaaaaa",
      "aaaaaaaaaaaaaaaa",
      "aaaaaaaaaaaaaaaa",
      "aaaaaaaaaaaaaaaa",
      "aaaaaaaaaaaaaaaa",
      "bbbbbbbbaaaaaaaa",
      "bbbbbbbbaaaaaaaa",
      "bbbbbbbbaaaaaaaa",
      "bbbbbbbbaaaaaaaa",
      "bbbbbbbbaaaaaaaa",
      "bbbbbbbbaaaaaaaa",
      "bbbbbbCbaaaaaaaa",
      "bbbbbbbbaaaaaaaa",
      "aaaaaaaaaaaaaaaa",
      "vvvvvvvvvvvvvvvv"
    ]
  ]
}