{
  "name": "multi_gunstore_1_base1",
  "refpalette": "deceasedcraft:multi_gunstore_1/multi_gunstore_1_base1_palette",
  "xsize": 16,
  "zsize": 16,
  "slices": [
    [
      "vvvvvvvvvvvvvvvv",
      "aabbbbbbbcccccdc",
      "eabbbbbbbcfcccdc",
      "gfffffffffhffcdc",
      "eiiiiiiiijjjgddc",
      "iijjjjjjjjjjgccc",
      "iijjjjjjjjjjgbbb",
      "iijjjjjjjjjjgbbb",
      "iijjjjjjjjjjgbbb",
      "iijjjjjjjjjjgbbb",
      "iijjjjjjjjjjgbbb",
      "eiiiiiiiiiiigbbb",
      "gfffffffffffbbbb",
      "eabbbbbbbbbbbbbb",
      "aabbbbbbbbbbbbbb",
      "vvvvvvvvvvvvvvvv"
    ],
    [
      "vvvvvvvvvvvvvvvv",
      "aabbbbbbbcccdd c",
      "eabbbbbbbcfccc c",
      "kffffffffflffc c",
      "e  !mnonp  qg  c",
      "r           gccc",
      "r           gbbb",
      "r           gbbb",
      "r           gbbb",
      "r           gbbb",
      "r           gbbb",
      "e   stuwx   gbbb",
      "kfffffffffyfbbbb",
      "eabbbbbbbbbbbbbb",
      "aabbbbbbbbbbbbbb",
      "vvvvvvvvvvvvvvvv"
    ],
    [
      "vvvvvvvvvvvvvvvv",
      "aabbbbbbbccdA  c",
      "eabbbbbbbcfccdcc",
      " ffffffffflfffff",
      "e       BBBBgggg",
      "r       BBBBgggg",
      "r       BBBBgggg",
      "r       BBBBgggg",
      "r       BBBBgggg",
      "r       BBBBgggg",
      "r       BBBBgCDg",
      "e       BBBBggEg",
      " fffffffffffff!f",
      "eabbbbbbbbbbbbbb",
      "aabbbbbbbbbbbbbb",
      "vvvvvvvvvvvvvvvv"
    ],
    [
      "vvvvvvvvvvvvvvvv",
      "aabbbbbbbcF    c",
      "eabbbbbbbcIcc cc",
      " fffffffffffffff",
      "e     BgJ   KLMN",
      "r     BgJ    O  ",
      "r     BgJ      O",
      "r     BgJ       ",
      "r     BgJP   Q R",
      "r     BgJ  STUVU",
      "r     BgJ   W   ",
      "e     BgJ X YZ00",
      " fffffffffffffff",
      "eabbbbbbbbbbbbbb",
      "aabbbbbbbbbbbbbb",
      "vvvvvvvvvvvvvvvv"
    ],
    [
      "vvvvvvvvvvvvvvvv",
      "aabbbbbbbcFdcccc",
      "eabbbbbbbcIccccc",
      " fffffffffffffff",
      "e   BgJ         ",
      "r   BgJ         ",
      "r   BgJ         ",
      "r   BgJ         ",
      "r   BgJ         ",
      "r   BgJ1        ",
      "r   BgJ2        ",
      "e3  BgJ      4 5",
      " fffffffffffffff",
      "eabbbbbbbbbbbbbb",
      "aabbbbbbbbbbbbbb",
      "vvvvvvvvvvvvvvvv"
    ],
    [
      "vvvvvvvvvvvvvvvv",
      "aabbbbbbbccccccc",
      "eabbbbbbbccccccc",
      "6fffffffffffffff",
      "e BgJ           ",
      "e BgJ           ",
      "e BgJ           ",
      "e BgJ           ",
      "e BgJ1          ",
      "e BgJ           ",
      "e BgJ           ",
      "e!BgJ           ",
      "6fffffffffffffff",
      "eabbbbbbbbbbbbbb",
      "aabbbbbbbbbbbbbb",
      "vvvvvvvvvvvvvvvv"
    ]
  ]
}