{
  "name": "multi_gunstore_1_ground",
  "refpalette": "deceasedcraft:multi_gunstore_1/multi_gunstore_1_ground_palette",
  "xsize": 16,
  "zsize": 16,
  "slices": [
    [
      "HHHHHHHHHHHHHHHH",
      "HHHHHHHHHHHHHHHH",
      "aaaaaaaaaaaaaaaa",
      "bccdddddcccccddd",
      "bbe             ",
      "bbe             ",
      "bbe             ",
      "bbe             ",
      "bbe             ",
      "bbe             ",
      "bbef            ",
      "bbe    g       h",
      "bcciiiiiccccciii",
      "aaaaaaaaaaaaaaaa",
      "HHHHHHHHHHHHHHHH",
      "HHHHHHHHHHHHHHHH"
    ],
    [
      "                ",
      "                ",
      "                ",
      "cccjjjjjcccccjjj",
      "cklmm   l n l   ",
      "op              ",
      "qp              ",
      "c               ",
      "cp              ",
      "or              ",
      "qp              ",
      "c s   ggs   s  g",
      "cccjjjj cccccjjj",
      "                ",
      "                ",
      "                "
    ],
    [
      "                ",
      "                ",
      "tttttttttttttttt",
      "cccccccccccccccc",
      "c   m           ",
      "u               ",
      "w               ",
      "c               ",
      "c               ",
      "u               ",
      "w               ",
      "c               ",
      "cccccccccccccccc",
      "xxxxxxxxxxxxxxxx",
      "                ",
      "                "
    ],
    [
      "                ",
      "                ",
      "tyyyyyyyyyyyyyyy",
      "cccccccccccccccc",
      "c               ",
      "c    A         B",
      "c    C         D",
      "c    C         D",
      "c    D         D",
      "c    C         D",
      "c    E         F",
      "c               ",
      "cccccccccccccccc",
      "xyyyyyyyyyyyyyyy",
      "                ",
      "                "
    ],
    [
      "                ",
      "                ",
      "IyyyyyyyJJJJJyyy",
      "KyyyyyyyLLLLLyyy",
      "Kyyyyyyyyyyyyyyy",
      "KyMMMNMMMMMMMMMN",
      "KyMMMOMMMMMMMMMO",
      "KyMMMOMMMMMMMMMO",
      "KyMMMOMMMMMMMMMO",
      "KyMMMOMMMMMMMMMO",
      "KyMMMNMMMMMMMMMN",
      "Kyyyyyyyyyyyyyyy",
      "KyyyyyyyLLLLLyyy",
      "PyyyyyyyJJJJJyyy",
      "                ",
      "                "
    ],
    [
      "                ",
      "                ",
      "JJJJJJJJ     JJJ",
      "JJJJJJJJ     JJJ",
      "JJJJJJJJJJJJJJJJ",
      "JJJQRRRRRRRRRRRR",
      "JJJJJJJJJJJJJJJR",
      "JJJJJJJJJJJJJJJR",
      "JJJJJJJJJJJJJJJR",
      "JJJJJJJJJJJJJJJR",
      "JJJQRRRRRRRRRRRR",
      "JJJJJJJJJJJJJJJJ",
      "JJJJJJJJ     JJJ",
      "JJJJJJJJ     JJJ",
      "                ",
      "                "
    ]
  ]
}