{
  "name": "multi_cabin2_0_floor1",
  "refpalette": "deceasedcraft:multi_cabin2_0/multi_cabin2_0_floor1_palette",
  "xsize": 16,
  "zsize": 16,
  "slices": [
    [
      "aaaaaaaaaaaaaaaa",
      "aaaabababaaaaaaa",
      "aabbbbbbaaaaaaaa",
      "aabbaabbbaaaaaaa",
      "abbaccccccccaaaa",
      "aabaccccccccaaaa",
      "abaacddddddcaaaa",
      "abbacddddddcaaaa",
      "abbacddddddcaaaa",
      "abaacddddddcaaaa",
      "babacddddddcaaaa",
      "abbacadddddcaaaa",
      "bbbbcddddddcaaaa",
      "ababcddddddcaaaa",
      "aabbcadddddcaaaa",
      "aaabccccccccaaaa"
    ],
    [
      "eeeeeeeeeeeeeeee",
      "eeeeeeeeeeeeeeee",
      "eeeeeeeeeeeeefee",
      "eeeeeeeeeeeeeeee",
      "eeeghchhhhchgeee",
      "eeeiccccccccgeee",
      "eeegcjjjjjjcgeef",
      "eeegckleelkceeee",
      "eeeecemeemecgeee",
      "eeegceeeeencgeee",
      "eeegccoeeocceeee",
      "eeegcpeeeeqceefe",
      "eeeereeeeescgeee",
      "eeeeteeeeeucgeee",
      "eeeecpeeeevceeee",
      "ewwxccoeeoccgefe"
    ],
    [
      "eeeeeeeeeeeeeeee",
      "eeeeeeeeeeeeeeee",
      "eeeeeeeeeeeeeyee",
      "eeeeeeeeeeeeeeee",
      "eeeeeeeeeeeeeeee",
      "eeeeeheeeeheeeee",
      "eeeehchhhhcheeey",
      "eeeeczzzzzzceeee",
      "eeeeceeeeeeceeee",
      "eeeeceeeeeeceeee",
      "eeeeccoeeocceeee",
      "eeeecpeeeeAceeye",
      "eeeeBeeeeeeCeeee",
      "eeeeDeeeeeeCeeee",
      "eeeecpeeeeeceeee",
      "eeeeccoeeocceeye"
    ],
    [
      "eeeeeeeeeeeeeeee",
      "eeeeeeeeeeeeeeee",
      "eeeeeeeeeeeeeeee",
      "eeeeeeeeeeeeeeee",
      "eeeeeeeeeeeeeeee",
      "eeeeeeeeeeeeeeee",
      "eeeeeeeeeeeeeeee",
      "eeeeeheeeeheeeee",
      "eeeehchhhhcheeee",
      "eeeeczzzzzzceeee",
      "eeeeccoeeocceeee",
      "eeeeceeeeeeceeee",
      "eeeeceeeeeeceeee",
      "eeeeceeeeeeceeee",
      "eeeeceeeeeeceeee",
      "eeeeccoeeocceeee"
    ],
    [
      "eeeeeeeeeeeeeeee",
      "eeeeeeeeeeeeeeee",
      "eeeeeeeeeeeeeeee",
      "eeeeeeeeeeeeeeee",
      "eeeeeeeeeeeeeeee",
      "eeeeeeeeeeeeeeee",
      "eeeeeeeeeeeeeeee",
      "eeeeeeeeeeeeeeee",
      "eeeeeeeeeeeeeeee",
      "eeeeeheeeeheeeee",
      "eeeehchhhhcheeee",
      "eeeeczzzzzzceeee",
      "eeeeceeeeeeceeee",
      "eeeeceeeeeeceeee",
      "eeeeceeeeeeceeee",
      "eeeecccccccceeee"
    ],
    [
      "eeeeeeeeeeeeeeee",
      "eeeeeeeeeeeeeeee",
      "eeeeeeeeeeeeeeee",
      "eeeeeeeeeeeeeeee",
      "eeeeeeeeeeeeeeee",
      "eeeeeeeeeeeeeeee",
      "eeeeeeeeeeeeeeee",
      "eeeeeeeeeeeeeeee",
      "eeeeeeeeeeeeeeee",
      "eeeeeeeeeeeeeeee",
      "eeeeeeeeeeeeeeee",
      "eeeeeheeeeheeeee",
      "eeeehchhhhcheeee",
      "eeeeczzzzzzceeee",
      "eeeecEzzzzEceeee",
      "eeeeccFFFFcceeee"
    ]
  ]
}