{
  "name": "multi_terraceplaza_28_base1",
  "refpalette": "deceasedcraft:multi_terraceplaza_28/multi_terraceplaza_28_base1_palette",
  "xsize": 16,
  "zsize": 16,
  "slices": [
    [
      "vvvvvvvvvvvvvvvv",
      "aaaaaaaaaaaabbbv",
      "cccccccccccabbbv",
      "cccccccccccabbbv",
      "HHHHHHHHHccbbbbv",
      "HHHHdHHHHccaaaav",
      "HHHHHHHHHccabbbv",
      "HHHHHHHHHccabbbv",
      "HHHHHHHHHccabbbv",
      "HHHHHHHHHccabbbv",
      "HHHHHHHHHccabbbv",
      "HHHHHHHHHccabbbv",
      "HHHHHHHHHccabbbv",
      "HHHHHHHHHccabbbv",
      "HHHHHHHHHccabbbv",
      "HHHHHHHHHccbbbbv"
    ],
    [
      "vvvvvvvvvvvvvvvv",
      "aaaaaaaaaaaaeefv",
      "           af  v",
      "           a  gv",
      "hihijhihi  k glv",
      "    d      aaaav",
      "    j      am  v",
      "nono nono  a pqv",
      "           a mrv",
      "           a   v",
      "           a pqv",
      "           a  rv",
      "hihi       a  mv",
      "    j      a sqv",
      "   tj      a mrv",
      "nonoj      u   v"
    ],
    [
      "vvvvvvvvvvvvvvvv",
      "aaaaaaaaaaaa   v",
      "           a   v",
      "           a   v",
      "           w   v",
      "    d      aaaav",
      "           a   v",
      "           a   v",
      "           a  rv",
      "           a   v",
      "           a   v",
      "           a  rv",
      "           a   v",
      "           a  mv",
      "           a  rv",
      "           x   v"
    ],
    [
      "vvvvvvvvvvvvvvvv",
      "aaaaaaaaaaaa   v",
      "           a   v",
      "           a   v",
      "          yA   v",
      "    d      aaaav",
      "           a  mv",
      "           a  Bv",
      "           a  Cv",
      "           a   v",
      "           a  Bv",
      "           a  Cv",
      "           a   v",
      "           a  Bv",
      "           a  Cv",
      "          DA   v"
    ],
    [
      "vvvvvvvvvvvvvvvv",
      "aaaaaaaaaaaa  Ev",
      "FFFFIFFFFFFFFFFv",
      "JJJJJJJJJJJa  Fv",
      "JJJJJJJJJJJa  Fv",
      "JJJJdJJJJJJaaaFv",
      "           a  Fv",
      "           a  Fv",
      " K         a  Fv",
      "           a  Fv",
      "           a  Fv",
      "           a  Fv",
      "           a  Fv",
      "           a  Fv",
      "           a  Fv",
      "           a  Fv"
    ],
    [
      "vvvvvvvvvvvvvvvv",
      "aaaaaaaaaaaaLLLv",
      "LLLLMLLLLLLaLLLv",
      "NNNNMLLLLLLaLLLv",
      "N NNMLLLLLLaLLLv",
      "MMMMdLLLLLLaaaav",
      "LLLLMLLLLLLaLLLv",
      "LLLLMLLLLLLaLLLv",
      "LOLLMLLOLLLaLLLv",
      "LLLLMLLLLLLaLLLv",
      "LLLLMLLLLLLaLLLv",
      "LLLLMLLLLLLaLLLv",
      "LLLLMLLLLLLaLLLv",
      "LOLLMLLOLLLaLLLv",
      "LLLLMLLLLLLaLLLv",
      "LLLLMLLLLLLaLLLv"
    ]
  ]
}