{
  "name": "multi_terraceplaza_28_floor2",
  "refpalette": "deceasedcraft:multi_terraceplaza_28/multi_terraceplaza_28_floor2_palette",
  "xsize": 16,
  "zsize": 16,
  "slices": [
    [
      "                ",
      "                ",
      "                ",
      "                ",
      "                ",
      "    a   b       ",
      "        b       ",
      "        b       ",
      "        cd      ",
      "        ed      ",
      "        ed      ",
      "        cd      ",
      "        cd      ",
      "        ed      ",
      "        cd      ",
      "        ed      "
    ],
    [
      "                ",
      "                ",
      "                ",
      "        b       ",
      "        b       ",
      "ffffa   b       ",
      "    g   cd      ",
      "    g   ed      ",
      "    g   cd      ",
      "    g   ed      ",
      "    g   ed      ",
      "    g   cd      ",
      "    g   cd      ",
      "    g   ed      ",
      "    g   cd      ",
      "    g   ed      "
    ],
    [
      "                ",
      "bbbbbbbbb       ",
      "        b       ",
      "        b       ",
      "    h   ed      ",
      "iiiiaj  ed      ",
      "kkkkgl  cd      ",
      "mnopql  ed      ",
      "ooopql  cd      ",
      "ooopql  ed      ",
      "ooopql  ed      ",
      "ooopql  cd      ",
      "ooopql  cd      ",
      "ooopql  ed      ",
      "nmopql  cd      ",
      "rrrrgl  ed      "
    ],
    [
      "ddddddddd       ",
      "ceecceceed      ",
      "sssstssscd      ",
      "sssstsssed      ",
      "ggggugssed      ",
      "wwwwauxxed      ",
      "yyyywgsscd      ",
      "yyyywgssed      ",
      "yyyywgsscd      ",
      "yyyywgssed      ",
      "yyyywgssed      ",
      "yyyywgsscd      ",
      "yyyywgsscd      ",
      "yyyywgssed      ",
      "yyyywgsscd      ",
      "yyyywgssed      "
    ],
    [
      "ddddddddd       ",
      "ceecceceed      ",
      "AAAAAAAAcd      ",
      "AAAAAAAAed      ",
      "AAAAAAAAed      ",
      "BAAAaAAAed      ",
      "BAAAAAAAcd      ",
      "BAAABBBAed      ",
      "BAAABBBAcd      ",
      "BAAABBBAed      ",
      "BAAABBBAed      ",
      "BAAABBBAcd      ",
      "BAAAB!BAcd      ",
      "BAAABCBAed      ",
      "DAAABBBAcd      ",
      "DAAAAAAAed      "
    ],
    [
      "ddddddddd       ",
      "ceecceceed      ",
      "        cd      ",
      "        ed      ",
      "        ed      ",
      "    aEEFed      ",
      "        cd      ",
      "        ed      ",
      "     I  cd      ",
      "        ed      ",
      "     J  ed      ",
      "        cd      ",
      "        cd      ",
      "     K  ed      ",
      "L       cd      ",
      "L       ed      "
    ]
  ]
}