{
  "name": "multi_terraceplaza_28_floor3",
  "refpalette": "deceasedcraft:multi_terraceplaza_28/multi_terraceplaza_28_floor3_palette",
  "xsize": 16,
  "zsize": 16,
  "slices": [
    [
      "aaaaaaaaa       ",
      "bccbbcbcca      ",
      "        ba      ",
      "        ca      ",
      "        ca      ",
      "    d  eca      ",
      "    fgghba      ",
      "        ca      ",
      "        ba      ",
      "        ca      ",
      "        ca      ",
      "        ba      ",
      "        ba      ",
      "     i  ca      ",
      "j       ba      ",
      "j       ca      "
    ],
    [
      "aaaaaaaaa       ",
      "bccbbcbcca      ",
      "        ba      ",
      "        ca      ",
      "        ca      ",
      "    d   ca      ",
      "    k  eba      ",
      "    fgghca      ",
      "        ba      ",
      "        ca      ",
      "        ca      ",
      "        ba      ",
      "        ba      ",
      "        ca      ",
      "j       ba      ",
      "jl      ca      "
    ],
    [
      "aaaaaaaaa       ",
      "bccbbcbcca      ",
      "        ba      ",
      "        ca      ",
      "        ca      ",
      "    d   ca      ",
      "        ba      ",
      "    k  eca      ",
      "    fgghba      ",
      "        ca      ",
      "        ca      ",
      "        ba      ",
      "        ba      ",
      "        ca      ",
      "j       ba      ",
      "j       ca      "
    ],
    [
      "aaaaaaaaa       ",
      "bccbbcbcca      ",
      "        ba      ",
      "        ca      ",
      "        ca      ",
      "    d   ca      ",
      "        ba      ",
      "        ca      ",
      "    k  eba      ",
      "    fgghca      ",
      "        ca      ",
      "        ba      ",
      "        ba      ",
      "        ca      ",
      "j       ba      ",
      "j       ca      "
    ],
    [
      "aaaaaaaaa       ",
      "bccbbcbcca      ",
      "        ba      ",
      "        ca      ",
      "        ca      ",
      "    d   ca      ",
      "        ba      ",
      "        ca      ",
      "        ba      ",
      "    k  eca      ",
      "    fgghca      ",
      "        ba      ",
      "        ba      ",
      "        ca      ",
      "j       ba      ",
      "j       ca      "
    ],
    [
      "aaaaaaaaa       ",
      "bccbbcbcca      ",
      "        ba      ",
      "        ca      ",
      "        ca      ",
      "    d   ca      ",
      "        ba      ",
      "        ca      ",
      "        ba      ",
      "        ca      ",
      "    k  eca      ",
      "    fgghba      ",
      "        ba      ",
      "        ca      ",
      "j       ba      ",
      "j       ca      "
    ]
  ]
}