{
  "name": "multi_terraceplaza_28_base2",
  "refpalette": "deceasedcraft:multi_terraceplaza_28/multi_terraceplaza_28_base2_palette",
  "xsize": 16,
  "zsize": 16,
  "slices": [
    [
      "vvvvvvvvvvvvvvvv",
      "aaaaaaaaaaaabbbv",
      "cccccccccccabbbv",
      "cccccccccccabbbv",
      "HHHHHHHHHccbbbbv",
      "HHHHdHHHHccaaaav",
      "HHHHHHHHHccabbbv",
      "HHHHHHHHHccabbbv",
      "HHHHHHHHHccabbbv",
      "HHHHHHHHHccabbbv",
      "HHHHHHHHHccabbbv",
      "HHHHHHHHHccabbbv",
      "HHHHHHHHHccabbbv",
      "HHHHHHHHHccabbbv",
      "HHHHHHHHHccabbbv",
      "HHHHHHHHHccbbbbv"
    ],
    [
      "vvvvvvvvvvvvvvvv",
      "aaaaaaaaaaaaeefv",
      "           a g v",
      "           ag hv",
      "ijijkijij  l  hv",
      "    d      aaaav",
      "    k      amm v",
      "nono nono  a  pv",
      "           a  qv",
      "           a  mv",
      "           a  pv",
      "           a  qv",
      "ijij       a   v",
      "    k      a  rv",
      "    k      a  qv",
      "nonok      s  mv"
    ],
    [
      "vvvvvvvvvvvvvvvv",
      "aaaaaaaaaaaat uv",
      "           a   v",
      "           a   v",
      "           w   v",
      "    d      aaaav",
      "           am  v",
      "           a   v",
      "           a  qv",
      "           a   v",
      "           a   v",
      "           a  qv",
      "           a   v",
      "           a   v",
      "           a  qv",
      "           x   v"
    ],
    [
      "vvvvvvvvvvvvvvvv",
      "aaaaaaaaaaaa g v",
      "           a   v",
      "           a   v",
      "          yA   v",
      "    d      aaaav",
      "           a   v",
      "           a  Bv",
      "           a  Cv",
      "           a   v",
      "           a  Bv",
      "           a  Cv",
      "           a   v",
      "           a  Bv",
      "           a  Cv",
      "          DA   v"
    ],
    [
      "vvvvvvvvvvvvvvvv",
      "aaaaaaaaaaaa  Ev",
      "FFFFFFFFFFFFFFFv",
      "IIIIIIIIIIIa  Fv",
      "IIIIIIIIIIIa  Fv",
      "IIIIdIIIIIIaaaFv",
      "           a  Fv",
      "           a mFv",
      "       J   a  Fv",
      "           a  Fv",
      "           a  Fv",
      "           a  Fv",
      "           a  Fv",
      "           a  Fv",
      "           a  Fv",
      "           a  Fv"
    ],
    [
      "vvvvvvvvvvvvvvvv",
      "aaaaaaaaaaaaKKKv",
      "KKKKKKKKKKKaKKKv",
      "KKKKKKKKKKKaKKKv",
      "KKKKKKKKKKKaKKKv",
      "LLLLdKKKKKKaaaav",
      "KKKKLKKKKKKaKKKv",
      "KKKKLKKKKKKaKKKv",
      "KMKKLKKMKKKaKKKv",
      "KKKKLKKKKKKaKKKv",
      "KKKKLKKKKKKaKKKv",
      "KKKKLKKKKKKaKKKv",
      "KKKKLKKKKKKaKKKv",
      "KMKKLKKMKKKaKKKv",
      "KKKKLKKKKKKaKKKv",
      "KKKKLKKKKKKaKKKv"
    ]
  ]
}