{
  "name": "multi_terraceplaza_28_floor4",
  "refpalette": "deceasedcraft:multi_terraceplaza_28/multi_terraceplaza_28_floor4_palette",
  "xsize": 16,
  "zsize": 16,
  "slices": [
    [
      "aaaaaaaaa       ",
      "bccbbcbcca      ",
      "        ba      ",
      "        ca      ",
      "        ca      ",
      "    d   ca      ",
      "        ba      ",
      "        ca      ",
      "        ba      ",
      "        ca      ",
      "        ca      ",
      "    e  fba      ",
      "    ghhiba      ",
      "jjjjjjj ca      ",
      "jjjjjjj ba      ",
      "jjjjjjj ca      "
    ],
    [
      "aaaaaaaaa       ",
      "bccbbcbcca      ",
      "        ba      ",
      "        ca      ",
      "        ca      ",
      "    d   ca      ",
      "        ba      ",
      "        ca      ",
      "        ba      ",
      "        ca      ",
      "        ca      ",
      "        ba      ",
      "    e  fba      ",
      "kkkkk  fca      ",
      "       fba      ",
      "       fca      "
    ],
    [
      "aaaaaaaaa       ",
      "bccbbcbcca      ",
      "        ba      ",
      "        ca      ",
      "        ca      ",
      "    d   ca      ",
      "        ba      ",
      "        ca      ",
      "        ba      ",
      "        ca      ",
      "        ca      ",
      "        ba      ",
      "        ba      ",
      "        ca      ",
      "        ba      ",
      "        ca      "
    ],
    [
      "aaaaaaaaa       ",
      "bccbbcbcca      ",
      "        ba      ",
      "        ca      ",
      "        ca      ",
      "    d   ca      ",
      "        ba      ",
      "        ca      ",
      "        ba      ",
      "        ca      ",
      "        ca      ",
      "        ba      ",
      "        ba      ",
      "        ca      ",
      "        ba      ",
      "        ca      "
    ],
    [
      "aaaaaaaaa       ",
      "bccbbcbcca      ",
      "        ba      ",
      "        ca      ",
      "        ca      ",
      "    d   ca      ",
      "        ba      ",
      "        ca      ",
      "        ba      ",
      "        ca      ",
      "        ca      ",
      "        ba      ",
      "        ba      ",
      "        ca      ",
      "        ba      ",
      "        ca      "
    ],
    [
      "aaaaaaaaa       ",
      "bccbbcbcca      ",
      "        ba      ",
      "        ca      ",
      "        ca      ",
      "    d   ca      ",
      "        ba      ",
      "        ca      ",
      "        ba      ",
      "        ca      ",
      "        ca      ",
      "        ba      ",
      "        ba      ",
      "        ca      ",
      "        ba      ",
      "    l   ca      "
    ]
  ]
}