{
  "name": "multi_terraceplaza_28_floor5",
  "refpalette": "deceasedcraft:multi_terraceplaza_28/multi_terraceplaza_28_floor5_palette",
  "xsize": 16,
  "zsize": 16,
  "slices": [
    [
      "aaaaaaaaa       ",
      "bccbbcbcca      ",
      "        ba      ",
      "        ca      ",
      "        ca      ",
      "    d   ca      ",
      "        ba      ",
      "        ca      ",
      "        ba      ",
      "        ca      ",
      "        ca      ",
      "        ba      ",
      "        ba      ",
      "        ca      ",
      "        ba      ",
      "        ca      "
    ],
    [
      "aaaaaaaaa       ",
      "bccbbcbcca      ",
      "eeeeeeeeba      ",
      "eeeeeeeeca      ",
      "ffffffeeca      ",
      "ggggdfeeca      ",
      "hhhhhfeeba      ",
      "    hfeeca      ",
      "    hfeeba      ",
      "hhhhhfeeca      ",
      "hhhhhfeeca      ",
      "hhhhhfeeba      ",
      "hhhhhfeeba      ",
      "    hfeeca      ",
      "    hfeeba      ",
      "hhhhhfeeca      "
    ],
    [
      "aaaaaaaaa       ",
      "bccbbcbcca      ",
      "        ba      ",
      "        ca      ",
      "iiiiii  ca      ",
      "iiiiii  ca      ",
      "iiiiii  ba      ",
      "@@@@ii  ca      ",
      "@@@@ii  ba      ",
      "iiiiii  ca      ",
      "iiiiii  ca      ",
      "iiiiii  ba      ",
      "iiiiii  ba      ",
      "@@@@ii  ca      ",
      "@@@@ii  ba      ",
      "iiiiii  ca      "
    ],
    [
      "aaaaaaaaa       ",
      "bccbbcbcca      ",
      "        ba      ",
      "        ca      ",
      "        ca      ",
      "        ca      ",
      "        ba      ",
      "        ca      ",
      "        ba      ",
      "        ca      ",
      "        ca      ",
      "        ba      ",
      "        ba      ",
      "        ca      ",
      "        ba      ",
      "        ca      "
    ],
    [
      "                ",
      "                ",
      "                ",
      "                ",
      "                ",
      "                ",
      "                ",
      "                ",
      "                ",
      "                ",
      "                ",
      "                ",
      "                ",
      "                ",
      "                ",
      "                "
    ],
    [
      "                ",
      "                ",
      "                ",
      "                ",
      "                ",
      "                ",
      "                ",
      "                ",
      "                ",
      "                ",
      "                ",
      "                ",
      "                ",
      "                ",
      "                ",
      "                "
    ]
  ]
}