{
  "name": "multi_filmworkstower_21_base1",
  "refpalette": "deceasedcraft:multi_filmworkstower_21/multi_filmworkstower_21_base1_palette",
  "xsize": 16,
  "zsize": 16,
  "slices": [
    [
      "         a    bv",
      "         a    bv",
      "         a    bv",
      "         a    bv",
      "         a    bv",
      "         a    bv",
      "         a    bv",
      "         a    bv",
      "         a    bv",
      "         a    bv",
      "         a    bv",
      "         a    bv",
      "         ac   bv",
      "         a    bv",
      "         a    bv",
      "         a    bv"
    ],
    [
      "         ad   bv",
      "         a    bv",
      "         a    bv",
      "         a    bv",
      "         a    bv",
      "         a    bv",
      "         a    bv",
      "         a    bv",
      "         a    bv",
      "         a    bv",
      "         a    bv",
      "         ae   bv",
      "         acf  bv",
      "         ad   bv",
      "         a    bv",
      "         a    bv"
    ],
    [
      "         ag   bv",
      "         ag   bv",
      "         ag   bv",
      "         ag   bv",
      "         ag   bv",
      "         ag   bv",
      "         ag   bv",
      "         ag   bv",
      "         ag   bv",
      "         ag   bv",
      "         ag   bv",
      "         ag   bv",
      "         achhhbv",
      "         ag   bv",
      "         ag   bv",
      "         ag   bv"
    ],
    [
      "              bv",
      "   i          bv",
      "   i          bv",
      "   i          bv",
      "   i          bv",
      "   i          bv",
      "   j          bv",
      "   i          bv",
      "   i          bv",
      "   i          bv",
      "   i          bv",
      "   k          bv",
      "   i     lcm  bv",
      "   i          bv",
      "   i          bv",
      "   i          bv"
    ],
    [
      "nnnnnnnnnopooobv",
      "qqqqqqqqnopooobv",
      "rsrrrsrqnopooobv",
      "rtrrrtrqnopooobv",
      "rtrrrtrqnopooobv",
      "rtrrrtrqnopooobv",
      "uwuquwuqnopooobv",
      "rtrrrtrqnopooobv",
      "rtrrrtrqnopooobv",
      "rtrrrtrqnopooobv",
      "rtrrrtrqnopooobv",
      "uwuquwuqnopooobv",
      "rtrrrtrqnoxooobv",
      "rtrrrtrqnopooobv",
      "rtrrrtrqnopooobv",
      "rtrrrtrqnopooobv"
    ],
    [
      "yyyyyyyyyyyyyybv",
      "yyyyyyyyyyyyyybv",
      "yyyyyyyyyyyyyybv",
      "yyyyyyyyyyyyyybv",
      "yyyyyyyyyyyyyybv",
      "yyyyyyyyyyyyyybv",
      "yyyyyyyyyyyyyybv",
      "yyyyyyyyyyyyyybv",
      "yyyyyyyyyyyyyybv",
      "yyyyyyyyyyyyyybv",
      "yyyyyyyyyyyyyybv",
      "yyyyyyyyyyyyyybv",
      "yyyyyyyyyyyyyybv",
      "yyyyyyyyyyyyyybv",
      "yyyyyyyyyyyyyybv",
      "yyyyyyyyyyyyyybv"
    ]
  ]
}