{
  "name": "multi_filmworkstower_21_base2",
  "refpalette": "deceasedcraft:multi_filmworkstower_21/multi_filmworkstower_21_base2_palette",
  "xsize": 16,
  "zsize": 16,
  "slices": [
    [
      "         abbbbcv",
      "         abbbbcv",
      "         abbbbcv",
      "         abbbbcv",
      "         abbbbcv",
      "         abbbbcv",
      "         abbbbcv",
      "         abbbbcv",
      "         abbbbcv",
      "         abbbbcv",
      "         abbbbcv",
      "         abbbbcv",
      "         abbbbcv",
      "         abbbbcv",
      "         abbbbcv",
      "         abbbbcv"
    ],
    [
      "         a    cv",
      "         a    cv",
      "         a    cv",
      "         a    cv",
      "         a    cv",
      "         a    cv",
      "         a    cv",
      "         a    cv",
      "         a    cv",
      "         a    cv",
      "         a    cv",
      "         a    cv",
      "         ade  cv",
      "         a    cv",
      "         a    cv",
      "         a    cv"
    ],
    [
      "         a    cv",
      "         a    cv",
      "         a    cv",
      "         a    cv",
      "         a    cv",
      "         a    cv",
      "         a    cv",
      "         a    cv",
      "         a    cv",
      "         a    cv",
      "         a    cv",
      "         a    cv",
      "         ad   cv",
      "         a    cv",
      "         a    cv",
      "         a    cv"
    ],
    [
      "         af   cv",
      "         a    cv",
      "         a    cv",
      "         a    cv",
      "         a    cv",
      "         a    cv",
      "         a    cv",
      "         a    cv",
      "         a    cv",
      "         a    cv",
      "         a    cv",
      "         ag   cv",
      "         ad   cv",
      "         af   cv",
      "         a    cv",
      "         a    cv"
    ],
    [
      "         ah   cv",
      "         ah   cv",
      "         ah   cv",
      "         ah   cv",
      "         ah   cv",
      "         ah   cv",
      "         ah   cv",
      "         ah   cv",
      "         ah   cv",
      "         ah   cv",
      "         ah   cv",
      "         ah   cv",
      "         adi  cv",
      "         ah   cv",
      "         ah   cv",
      "         ah   cv"
    ],
    [
      "         a    cv",
      "         a    cv",
      "         a    cv",
      "         a    cv",
      "         a    cv",
      "         a    cv",
      "         a    cv",
      "         a    cv",
      "         a    cv",
      "         a    cv",
      "         a    cv",
      "         a    cv",
      "         ad   cv",
      "         a    cv",
      "         a    cv",
      "         a    cv"
    ]
  ]
}