{
  "name": "multi_filmworkstower_21_base3",
  "refpalette": "deceasedcraft:multi_filmworkstower_21/multi_filmworkstower_21_base3_palette",
  "xsize": 16,
  "zsize": 16,
  "slices": [
    [
      "aaaaaaaaaaabbbbv",
      "aaaaaaaaaaabbbbv",
      "aaaaaaaaaaabbbbv",
      "aaaaaaaaaaabbbbv",
      "aaaaaaaaaaabbbbv",
      "aaaaaaaaaaabbbbv",
      "aaaaaaaaaaabbbbv",
      "aaaaaaaaaaabbbbv",
      "aaaaaaaaaaabbbbv",
      "aaaaaaaaaaabbbbv",
      "aaaaaaaaaaabbbbv",
      "aaaaaaaaaaabbbbv",
      "aaaaaaaaaaabbbbv",
      "aaaaaaaaaaabbbbv",
      "aaaaaaaaaaabbbbv",
      "aaaaaaaaaaabbbbv"
    ],
    [
      "cccccccccdabbbbv",
      "cccccccccdabbbbv",
      "cccccccccdabbbbv",
      "cccccccccdabbbbv",
      "cccccccccdabbbbv",
      "cccccccccdabbbbv",
      "cccccccccdabbbbv",
      "cccccccecdabbbbv",
      "cccccccccdabbbbv",
      "cccccccccdabbbbv",
      "cccccccccdabbbbv",
      "cccccccccdabbbbv",
      "cccccccccdabbbbv",
      "cccccccccdabbbbv",
      "cccccccccdabbbbv",
      "cccccccccdabbbbv"
    ],
    [
      "cccfcccccdabbbbv",
      "cccccceccdabbbbv",
      "c   ggcchdabbbbv",
      "f if jfkcdabbbbv",
      "klfmfcfccdabbbbv",
      "nonnnnpfcdabbbbv",
      "coccccnendabbbbv",
      "cocccccqodabbbbv",
      "cccccccccdabbbbv",
      "ccoccccccdabbbbv",
      "cccccccccdabbbbv",
      "cccccccccdabbbbv",
      "rffcccfccdabbbbv",
      " fsfffsfcdabbbbv",
      "fc c s ccdabbbbv",
      "  fc   ccdabbbbv"
    ],
    [
      "  t      dabbbbv",
      " s   u wsdabbbbv",
      "i     x  dabbbbv",
      "         dabbbbv",
      "       x dabbbbv",
      "nenn n  ydabbbbv",
      "A nBC noedabbbbv",
      "w AA AA  dabbbbv",
      "fDf  ff fdabbbbv",
      "f   f ffrdabbbbv",
      " f      fdabbbbv",
      " r  f r sdabbbbv",
      "   t     dabbbbv",
      "         dabbbbv",
      "        rdabbbbv",
      "         dabbbbv"
    ],
    [
      "         dabbbbv",
      "         dabbbbv",
      "         dabbbbv",
      "         dabbbbv",
      "         dabbbbv",
      "BBB      dabbbbv",
      "      BEDdabbbbv",
      "         dabbbbv",
      "         dabbbbv",
      "         dabbbbv",
      "         dabbbbv",
      "         dabbbbv",
      "         dabbbbv",
      "         dabbbbv",
      "         dabbbbv",
      "         dabbbbv"
    ],
    [
      "         dabbbbv",
      "         dabbbbv",
      "         dabbbbv",
      "         dabbbbv",
      "         dabbbbv",
      "         dabbbbv",
      "         dabbbbv",
      "         dabbbbv",
      "         dabbbbv",
      "         dabbbbv",
      "         dabbbbv",
      "         dabbbbv",
      "         dabbbbv",
      "         dabbbbv",
      "         dabbbbv",
      "         dabbbbv"
    ]
  ]
}