{
  "name": "multi_hospitaldamaged_0_base2",
  "refpalette": "deceasedcraft:multi_hospitaldamaged_0/multi_hospitaldamaged_0_base2_palette",
  "xsize": 16,
  "zsize": 16,
  "slices": [
    [
      "vvvvvvvvvvvvvvvv",
      "vvvvvvvvvvvvvvvv",
      "vvvvvvvvvvvvvvvv",
      "vvvvvvvvvvvvvvvv",
      "vvvvvvvvvvvvvvvv",
      "vvvvvvvvvvvvvvvv",
      "vvvvvvvvvvvvvvvv",
      "vvvvvvvvvvvvvvvv",
      "vvvvvvvvvvvvvvvv",
      "vvvvvvvvvvvvvvvv",
      "vvvvvvvvvvvvvvvv",
      "vvvvvvvvvvvvvvvv",
      "vvvvvvvvvvvvvvvv",
      "vvvvvvvvvvvvvvvv",
      "vvvvvvvvvvvvvvvv",
      "vvvvvvvvvvvvvvvv"
    ],
    [
      "vvvvvvvvvvvvvvvv",
      "vvvvvvvvvvvvvvvv",
      "vaaaaaaaaaaaaaaa",
      "vaaaaaaaaaaaaaaa",
      "vaaaaaaaaaaaaaaa",
      "vaaaaaaaaaaaaaaa",
      "vaaaaaaaaaaaaaaa",
      "vaaaaaaaaaaaaaaa",
      "vaaaaaaaaaaaaaaa",
      "vaaaaaaaaaaaaaaa",
      "vaaaaaaaaaaaaaaa",
      "vaaaaaaaaaaaaaaa",
      "vaaaaaaaaaaaaaaa",
      "vaaaaaaaaaaaaaaa",
      "vaaaaaaaaaaaaaaa",
      "vaaaaaaaaaaaaaaa"
    ],
    [
      "vvvvvvvvvvvvvvvv",
      "vbbbbbbbbbbbbbbb",
      "vccccccccccccccc",
      "vccccccccccccccc",
      "vccccccccccccccc",
      "vccccccccccccccc",
      "vccccccccccccccc",
      "vccccccccccccccc",
      "vccccccccccccccc",
      "vccccccccccccccc",
      "vccccccccccccccc",
      "vccccccccccccccc",
      "vccccccccccccccc",
      "vccccccccccccccc",
      "vccccccccccccccc",
      "vddddddddddddddd"
    ],
    [
      "vvvvvvvvvvvvvvvv",
      "vbbbbbbbbbbbbbbb",
      "vcbebbfbbebcbebb",
      "vcgggggggggcggff",
      "vcgggggggggggggg",
      "vcgggggggggggggg",
      "vcgggggggggggggg",
      "vcgggggggggggggg",
      "vcgggggggggggggg",
      "vcgggggggggggggg",
      "vcgggggggggggggg",
      "vcgggggggggggggg",
      "vcgggggggggggggg",
      "vcgggggggggcggff",
      "vcbebbfbbebcbebb",
      "vddddddddddddddd"
    ],
    [
      "vvvvvvvvvvvvvvvv",
      "vbbhbbbbbhbbbibb",
      "vcb bbfbb bcbjbb",
      "vc         c  kk",
      "vc         l    ",
      "vcmmmm     n    ",
      "vcoooo      p   ",
      "vcoooo   qrrr   ",
      "vcoooost  rrr u ",
      "vcoooo    rrr   ",
      "vcoooow   xyqA  ",
      "vcBBBB          ",
      "vc         l    ",
      "vc         cC DD",
      "vcbEbbfbbEbcbEbb",
      "vddddddccccccccc"
    ],
    [
      "vvvvvvvvvvvvvvvv",
      "vbbhbbbbbhbbbibb",
      "vcb bbfbb bcb bb",
      "vc         c  FI",
      "vc         J    ",
      "vcmmmm     K    ",
      "vcLLLLM    K    ",
      "vN       O PQ   ",
      "vNRSSTUR   V    ",
      "vN        WX    ",
      "vcLLLLY     O   ",
      "vcBBBB          ",
      "vc         J    ",
      "vc         c  Z0",
      "vcbEbbfbbEbcbEbb",
      "vcdccccccccccccc"
    ]
  ]
}