{
  "name": "multi_hospitaldamaged_0_base1",
  "refpalette": "deceasedcraft:multi_hospitaldamaged_0/multi_hospitaldamaged_0_base1_palette",
  "xsize": 16,
  "zsize": 16,
  "slices": [
    [
      "vvvvvvvvvvvvvvvv",
      "vaabaaaaacaaacaa",
      "vda aaeaa ada aa",
      "vd         d    ",
      "vd         f    ",
      "vdgggg          ",
      "vdhhhh          ",
      "vi         j    ",
      "vi              ",
      "vi              ",
      "vdhhhh          ",
      "vdkkkk          ",
      "vd         f    ",
      "vd         d    ",
      "vdalaaeaaladalaa",
      "vdmmmmmmmmmmmmmm"
    ],
    [
      "vvvvvvvvvvvvvvvv",
      "vaacaaaaabaaacaa",
      "vda aaeaa ada aa",
      "vd         d    ",
      "vd         f    ",
      "vd              ",
      "vdnnnn          ",
      "vdhhhh    ooo   ",
      "vdhhhh    ooo   ",
      "vdhhhh    ooo   ",
      "vdnnnn          ",
      "vd         p    ",
      "vd         f    ",
      "vd         d    ",
      "vdaqaaeaaqadaqaa",
      "vdr  sdtu rdr  s"
    ],
    [
      "vvvvvvvvvvvvvvvv",
      "vaacaaaaacaaacaa",
      "vda aaeaa ada aa",
      "vd         d    ",
      "vd         w    ",
      "vd              ",
      "vd              ",
      "vd         x    ",
      "vd        yAB   ",
      "vd         C    ",
      "vd              ",
      "vd         D    ",
      "vd         w    ",
      "vd         d    ",
      "vdaqaaeaaqadaqaa",
      "vd   EdF   d   I"
    ],
    [
      "vvvvvvvvvvvvvvvv",
      "vaabaaaaacaaacaa",
      "vda aaeaa ada aa",
      "vd         d    ",
      "vd         d    ",
      "vd         d    ",
      "vd         d    ",
      "vd         d    ",
      "vd         d    ",
      "vd         d    ",
      "vd         d    ",
      "vd         d    ",
      "vd         d    ",
      "vd         d    ",
      "vdaqaaeaaqadaqaa",
      "vdJ   d   JdJ   "
    ],
    [
      "vvvvvvvvvvvvvvvv",
      "vaaaaaaaaaaaaaaa",
      "vdahaaeaahadahaa",
      "vdhhhhhhhhhdhhhh",
      "vdhhhhhhhhhdhhhh",
      "vdhhhhhhhhhdhhhh",
      "vdhhhhhhhhhdhhhh",
      "vdhhhhhhhhhdhhhh",
      "vdhhhhhhhhhdhhhh",
      "vdhhhhhhhhhdhhhh",
      "vdhhhhhhhhhdhhhh",
      "vdhhhhhhhhhdhhhh",
      "vdhhhhhhhhhdhhhh",
      "vdhhhhhhhhhdhhhh",
      "vdahaaeaahadahaa",
      "vdhhhhdhhhhdhhhh"
    ],
    [
      "vvvvvvvvvvvvvvvv",
      "vaaaaaaaaaaaaaaa",
      "vdaaaaeaaaadaaaa",
      "vdKKKKKKKKKdLKKK",
      "vdKKKKKKKKKdLKKK",
      "vdKKKKKKKKKdLKKK",
      "vdKKKKKKKKKdLKKK",
      "vdKKKKKKKKKdLKKK",
      "vdKKKKKKKKKdLKKK",
      "vdKKKKKKKKKdLKKK",
      "vdKKKKKKKKKdLKKK",
      "vdKKKKKKKKKdLKKK",
      "vdKKKKKKKKKdLKKK",
      "vdKKKKKKKKKdLKKK",
      "vdaaaaeaaaadLKKK",
      "vdKKKKdKKKKdKKKK"
    ]
  ]
}