{
  "name": "multi_hospitaldamaged_0_ground",
  "refpalette": "deceasedcraft:multi_hospitaldamaged_0/multi_hospitaldamaged_0_ground_palette",
  "xsize": 16,
  "zsize": 16,
  "slices": [
    [
      "abbcHHHcaabaaaba",
      "bdbcHHHcabbaaaaa",
      "aaacHHHcaeeefggg",
      "cccHHHHHcehi    ",
      "HHHHHHHHcehi   j",
      "HHHHHHHHcehi  kl",
      "HHHHHHHHcehi  kk",
      "HHHHHHHHcehi  kl",
      "HHHHHHHHcehi   m",
      "HHHHHHHHcehi    ",
      "HHHHHHHHcehi    ",
      "HHHHHHHHcehi    ",
      "HHHHHHHHcehi    ",
      "HHHHHHHHcehi    ",
      "cccHHHHHcehi    ",
      "aHHcHHHcneoooooe"
    ],
    [
      "                ",
      " p q    r rssrss",
      " q          fttt",
      "   uwwwx        ",
      "   yAAAB        ",
      "   yAAAB     CDE",
      "   yAAAB     FIJ",
      "   yAAAB     CDK",
      "   yAAAB        ",
      "   yAAAB        ",
      "   yAAAB        ",
      "   yAAAB        ",
      "   yAAA         ",
      "   yA AB        ",
      "   L M          ",
      " NO      PooooQR"
    ],
    [
      "                ",
      " S              ",
      "            fttt",
      "                ",
      "               T",
      "              UV",
      "              UV",
      "              UV",
      "               W",
      "                ",
      "                ",
      "                ",
      "                ",
      "                ",
      "                ",
      "          oQoXQR"
    ],
    [
      " Y              ",
      " Z              ",
      "            ftRR",
      "            0   ",
      "            0   ",
      "            0  1",
      "            0  2",
      "            0  1",
      "            0   ",
      "            0   ",
      "            0   ",
      "            0   ",
      "            0   ",
      "            0   ",
      "            0   ",
      "          ooXQ  "
    ],
    [
      "                ",
      " 34             ",
      " Y          ftR ",
      "            5   ",
      "            5   ",
      "            5   ",
      "            5   ",
      "            5   ",
      "            5   ",
      "            5   ",
      "            5   ",
      "            5   ",
      "            5   ",
      "            5   ",
      "            5   ",
      "          ooooXR"
    ],
    [
      "                ",
      "  6             ",
      "            fttt",
      "            5   ",
      "            5   ",
      "            5   ",
      "            5   ",
      "            5   ",
      "            5   ",
      "            5   ",
      "            5   ",
      "            5   ",
      "            5   ",
      "            5   ",
      "            5   ",
      "      7777oooooo"
    ]
  ]
}