{
  "name": "multi_flatmedium_0_floor4",
  "refpalette": "deceasedcraft:multi_flatmedium_0/multi_flatmedium_0_floor4_palette",
  "xsize": 16,
  "zsize": 16,
  "slices": [
    [
      "                ",
      " abbabbbbbbabba ",
      " cdddddddddddde ",
      " cddf     gfdde ",
      " haaaaaaaaahdde ",
      " avvvvavvvvddde ",
      " avvvvvvvvvddde ",
      " avvvvvvvvvddde ",
      " avvvvvvvvvddde ",
      " hvaaavaaaahdda ",
      " aiiavvvvvvddde ",
      " aiiavvvvvvddde ",
      " aiiavvvvvvddde ",
      " aiiavvvvvvddde ",
      " aaaavvvvvvddde ",
      " aiiivvvvvvddde "
    ],
    [
      "                ",
      " aaaaaaaaaaaaaa ",
      " a  jjjjjjjj  a ",
      " a  kg     k  a ",
      " haaaaaaaaah  a ",
      " alllla!llma  a ",
      " n  opqrss a  a ",
      " nt  uw xx a  a ",
      " a     y  Aa  a ",
      " hBaaaBaaaah  a ",
      " a CaD EFIJa  a ",
      " n KaD     a  a ",
      " n  aD    Aa  a ",
      " aLMaD yNOPa  a ",
      " aaaaDQRllla  a ",
      " n  S      T  a "
    ],
    [
      "                ",
      " U  U      U    ",
      "                ",
      "      g         ",
      " haaaaaaaaah    ",
      " aVVWWaXXXXa    ",
      " YZ  01   2Y    ",
      " Y3  45   6Y    ",
      " a   7     a    ",
      " h8aaa8aaaah  U ",
      " a  a9  #$%a    ",
      " Y  a^    2Y    ",
      " Y &a^    6Y    ",
      " a  a*     a    ",
      " a((a)  y+-a    ",
      " Y[ ]      {    "
    ],
    [
      "                ",
      " U  U      U    ",
      "                ",
      "       g        ",
      " haaaaaaaaah    ",
      " a}VWWaXXXXa    ",
      " Y|  ;1   :Y    ",
      " Y'  <5   >Y    ",
      " a         a    ",
      " h(aaa(aaaah  U ",
      " a ,a.     a    ",
      " Y  a.    :Y    ",
      " Y ?a/    >Y    ",
      " a  a.     a    ",
      " aaaa      a    ",
      " Y` \u0370      \u0371    "
    ],
    [
      "                ",
      " U  U      U    ",
      "                ",
      "        g       ",
      " haaaaaaaaah    ",
      " a\u0372\u0372\u0372\u0372a\u0372\u0372\u0372\u0372a    ",
      " a    \u0373    a    ",
      " a    \u0374 \u0375  a    ",
      " a         a    ",
      " haaaaaaaaah  U ",
      " a\u0376\u0376a\u0372\u0372\u0372\u0372\u0372\u0372a    ",
      " a\u0376\u0376a      a    ",
      " a\u0376\u0376a \u0377  \u037a a    ",
      " a\u0376\u0376a      a    ",
      " aaaa      a    ",
      " a\u0376\u0376a      a    "
    ],
    [
      "                ",
      " h\u037b\u037bh\u037b\u037b\u037b\u037b\u037b\u037bh\u037b\u037b\u037b ",
      " \u037b            \u037b ",
      " \u037b       g    \u037b ",
      " haaaaaaaaah  \u037b ",
      " \u037cddddddddd\u037c  \u037b ",
      " \u037cddddddddd\u037c  \u037b ",
      " \u037cddddddddd\u037c  \u037b ",
      " \u037cddddddddd\u037c  \u037b ",
      " hdddddddddh  h ",
      " \u037cd ddddddd\u037c  \u037b ",
      " \u037cd ddddddd\u037c  \u037b ",
      " \u037cd\u037dddddddd\u037c  \u037b ",
      " \u037cd ddddddd\u037c  \u037b ",
      " \u037cddddddddd\u037c  \u037b ",
      " \u037cd\u037dddddddd\u037c  \u037b "
    ]
  ]
}