{
  "name": "multi_flatmedium_0_ground",
  "refpalette": "deceasedcraft:multi_flatmedium_0/multi_flatmedium_0_ground_palette",
  "xsize": 16,
  "zsize": 16,
  "slices": [
    [
      "aaaaaaaaaaaaaaaa",
      "aaaaaaaaaaaaaaaa",
      "aabbbbbbbbbbbbaa",
      "aabbbbbbbbbbbbaa",
      "aabbbbbbbbbbbbaa",
      "abbbbbbbbbbbbbba",
      "cccccccccccccdcc",
      "cccccceeccccdffc",
      "cccccccecccccfcc",
      "abcccbccccbcccba",
      "aaccccccceccccaa",
      "aaccccccccccccaa",
      "aaccccccccecccaa",
      "aacccffcceccccaa",
      "aacccefcccccccaa",
      "aaccccfcccccccaa"
    ],
    [
      "                ",
      "                ",
      "  bbbbbbbbbbbb  ",
      "  bbbbbbbbbbbb  ",
      "  bbggggggggbb  ",
      " hiiihbbbbhiiih ",
      "                ",
      "                ",
      "      j k       ",
      " h  lhmlnlhl  h ",
      " o  pq rp  r  o ",
      " o  s tus  u  o ",
      " o  pqwrpx r  o ",
      " oy s  us  uA o ",
      " o  p  rpBlr  o ",
      " o  s  us  u  o "
    ],
    [
      "                ",
      "                ",
      "  gCCCCCCCgCCg  ",
      "  g  DE   g!Fg  ",
      "  gIggggggggJg  ",
      " K   KLLLLK   K ",
      "                ",
      "                ",
      "                ",
      " K   K    K   K ",
      "                ",
      "                ",
      "                ",
      "                ",
      "                ",
      "                "
    ],
    [
      "                ",
      "                ",
      "  gCCCCCCCgCCg  ",
      "  g    E  gM g  ",
      "  gNggggggggOg  ",
      " K   KLPL!K   K ",
      "                ",
      "                ",
      "                ",
      " K   K    K   K ",
      "                ",
      "                ",
      "                ",
      "                ",
      "                ",
      "                "
    ],
    [
      "                ",
      " QQQQQQQQQQQQQQ ",
      " QgCCCCCCCgCCgQ ",
      " Qg     E gF gQ ",
      "  gRggggggggRgQ ",
      " KQQQKQQQQKQQQK ",
      " Q   Q    Q   Q ",
      " Q   Q    Q   Q ",
      " Q   Q    Q   Q ",
      " KQQQKQQQQKQQQK ",
      " Q   Q    Q   Q ",
      " Q   Q    Q   Q ",
      " Q   Q    Q   Q ",
      " Q   Q    Q   Q ",
      " Q   Q    Q   Q ",
      " Q   Q    Q   Q "
    ],
    [
      "                ",
      " SSSSSSSSSSSSSS ",
      " SccccccccccccS ",
      " Scc     E cccS ",
      " SccTTTTTTTTccS ",
      " SccccccccccccS ",
      " SccccccccccccS ",
      " SccccccccccccS ",
      " SccccccccccccS ",
      " SccccccccccccS ",
      " SccccccccccccS ",
      " SccccccccccccS ",
      " SccccccccccccS ",
      " SccccccccccccS ",
      " SccccccccccccS ",
      " SccccccccccccS "
    ]
  ]
}