{
  "name": "multi_flatmedium_0_top",
  "refpalette": "deceasedcraft:multi_flatmedium_0/multi_flatmedium_0_top_palette",
  "xsize": 16,
  "zsize": 16,
  "slices": [
    [
      "                ",
      " abbabbbbbbabba ",
      " cdddddddddddde ",
      " cddf     gfdde ",
      " haaaaaaaaahdde ",
      " avvvvavvvvddde ",
      " avvvvvvvvvddde ",
      " aivvivivvvddde ",
      " avivvvvvvvddde ",
      " hvaaavaaaahdda ",
      " ajjavvvvvvddde ",
      " ajjavvvvvvddde ",
      " ajjavivvvvddde ",
      " ajjavvivvvddde ",
      " aaaavvvvvvddde ",
      " ajjjvvvivvddde "
    ],
    [
      "                ",
      " aaaaaaaaaaaaaa ",
      " a  klllllll  a ",
      " a  mg     m  a ",
      " haaaaaaaaahnop ",
      " aqqqqarqqrast  ",
      " u wxyA BB ao C ",
      " u      DD a Ea ",
      " a        FaC a ",
      " hIaaaJaaaah  a ",
      " a Kaq LMNOaP a ",
      " u QaR     Snoa ",
      " u  aT     a UC ",
      " aVWaR  XYZSP   ",
      " aaaaT 0qqqa 1a ",
      " u  234    5 6a "
    ],
    [
      "                ",
      " 7  7      7    ",
      "                ",
      "      g         ",
      " haaaaaaaaah    ",
      " a8899a####a    ",
      " $%       ^$    ",
      " $&       *$  ( ",
      " a   )    !S    ",
      " h+aaa-aaaah  7 ",
      " a  a[   ] a    ",
      " $  a{    }$    ",
      " $ |a;    :$    ",
      " a  a{     a    ",
      " a''a;     a    ",
      " $< >,     .    "
    ],
    [
      "                ",
      " 7  7      7    ",
      "                ",
      "       g        ",
      " haaaaaaaaah    ",
      " a8?99a####S    ",
      " $/ `\u0370    \u0371$    ",
      " $\u0372 \u0373     \u0374$    ",
      " a         a    ",
      " h'aaa'aaaah  7 ",
      " a \u0375a\u0376     a    ",
      " $  a     \u0377$    ",
      " $ \u037aa;    \u037b$    ",
      " a  a      a    ",
      " aaaa;     S    ",
      " $\u037c \u037d\u037e     \u037f    "
    ],
    [
      "                ",
      " 7  7      7    ",
      "                ",
      "        g       ",
      " haaaaaaaaah    ",
      " a\u0384\u0384\u0384\u0384a\u0384\u0384\u0384\u0384a    ",
      " a         a    ",
      " a      \u0385  a    ",
      " a         S    ",
      " haaaaaaaaah  7 ",
      " a\u0386\u0386a\u0384\u0384\u0384\u0384\u0384\u0384a    ",
      " a\u0386\u0386a\u0387     a    ",
      " a\u0386\u0386a\u0387\u0388  \u0389 a    ",
      " a\u0386\u0386a\u0387     a    ",
      " aaaa\u0387     a    ",
      " a\u0386\u0386a      a    "
    ],
    [
      "                ",
      " h\u038a\u038ah\u038a\u038a\u038a\u038a\u038a\u038ah\u038a\u038a\u038a ",
      " \u038a            \u038a ",
      " \u038a       g    \u038a ",
      " haaaaaaaaah  \u038a ",
      " CdddddddddC  \u038a ",
      " CdddddddddC  \u038a ",
      " CdddddddddC  \u038a ",
      " CdddddddddC  \u038a ",
      " hdddddddddh  h ",
      " Cd dddddddC  \u038a ",
      " Cd dddddddC  \u038a ",
      " Cd\u038cdddddddC  \u038a ",
      " Cd dddddddC  \u038a ",
      " CdddddddddC  \u038a ",
      " Cd\u038cdddddddC  \u038a "
    ],
    [
      "                ",
      " aaaaaaaaaaaaaa ",
      " add        dda ",
      " add      gfdda ",
      " addhhhhhhhhdda ",
      " adda\u038e\u038e\u038e\u038e\u038e\u038eddda ",
      " adda\u038e\u038e\u038e\u038e\u038e\u038eddda ",
      " adda\u038e\u038e\u038e\u038e\u038e\u038eddda ",
      " adda\u038e\u038e\u038e\u038e\u038e\u038eddda ",
      " addha\u038e\u038eaaahdda ",
      " addd\u038e\u038e\u038e\u038e\u038e\u038eddda ",
      " addd\u038e\u038e\u038e\u038e\u038e\u038eddda ",
      " addd\u038e\u038e\u038e\u038e\u038e\u038eddda ",
      " addd\u038e\u038e\u038e\u038e\u038e\u038eddda ",
      " addd\u038e\u038e\u038e\u038e\u038e\u038eddda ",
      " addd\u038e\u038e\u038e\u038e\u038e\u038eddda "
    ],
    [
      "                ",
      " 7uu7uuuuuu7uu7 ",
      " u  \u038f      \u0390  u ",
      " u  \u038f      mk u ",
      " u  haaaaaahss7 ",
      " u  a\u0391\u0392\u0393\u0394\u0395\u0396a  u ",
      " u  a\u0397\u0398 \u0399\u0399\u0396a  u ",
      " u  a\u039a  \u0399\u0399\u0395a  u ",
      " u  a\u039b\u039c\u039d\u039e\u039f a  u ",
      " 7  ha\u03a0\u03a1aaah  u ",
      " u    sss     u ",
      " u            u ",
      " u       \u03a3\u03a4   u ",
      " u            u ",
      " u            u ",
      " u       \u03a3\u03a4   u "
    ],
    [
      "                ",
      "    7      7    ",
      "                ",
      "                ",
      "    haaaaaah    ",
      "    a\u0393    \u0395a    ",
      "    $\u039a  \u03a5\u03a6 $    ",
      "    $\u039a  \u03a7\u03a8 $    ",
      "    a \u03a9  \u03aa a    ",
      " \u03ab  ha\u03ac\u03ada\u03aaah    ",
      "     \u03ae  \u03af\u03aa      ",
      "         \u03aa      ",
      "         \u03aa      ",
      "         \u03aa      ",
      "         \u03aa      ",
      "         \u03aa      "
    ],
    [
      "                ",
      "    h\u03b0\u03b0\u03b0\u03b0\u03b0\u03b0h    ",
      "    \u03b0\u03b1\u03b1\u03b1\u03b1\u03b1\u03b1\u03b0    ",
      "    \u03b0\u03b1\u03b1\u03b1\u03b1\u03b1\u03b1\u03b0    ",
      "    h\u03b2\u03b2\u03b2\u03b2\u03b2\u03b2h    ",
      "    a\u03b3\u03b3\u03b3\u03b3\u03b3\u03b3a    ",
      "    a\u03b3\u03b3\u03b3\u03b4\u03b4\u03b3a    ",
      "    a\u03b3\u03b3\u03b3\u038c\u03b4\u03b3a    ",
      "    a\u03b3\u03b3\u03b3\u03b3\u03b3\u03b3a    ",
      "    haaaaaah    ",
      "                ",
      "                ",
      "                ",
      "                ",
      "                ",
      "                "
    ],
    [
      "                ",
      "                ",
      "                ",
      "                ",
      "    \u03b5      \u03b5    ",
      "        \u03b6\u03b6      ",
      "       \u03b7\u03b4\u03b4\u03b8     ",
      "       \u03b7\u03b9\u03b4\u03b8     ",
      "        \u03ba\u03ba      ",
      "    \u03b5      \u03b5    ",
      "                ",
      "                ",
      "                ",
      "                ",
      "                ",
      "                "
    ],
    [
      "                ",
      "                ",
      "                ",
      "                ",
      "                ",
      "                ",
      "        \u03bb\u03bb      ",
      "         \u03bb      ",
      "                ",
      "                ",
      "                ",
      "                ",
      "                ",
      "                ",
      "                ",
      "                "
    ]
  ]
}