{
  "name": "multi_flatmedium_0_floor2",
  "refpalette": "deceasedcraft:multi_flatmedium_0/multi_flatmedium_0_floor2_palette",
  "xsize": 16,
  "zsize": 16,
  "slices": [
    [
      "                ",
      " abbabbbbbbabba ",
      " cdddddddddddde ",
      " cddf     gfdde ",
      " haaaaaaaaahdde ",
      " avvvvavvvvddde ",
      " avvvvavvvvddde ",
      " avvvvavvvvddde ",
      " avvvvavvvvddde ",
      " hvaavavvvvhdda ",
      " aiiavvvvvvddde ",
      " aiiavvvvvvddde ",
      " aiiavvvvvvddde ",
      " aaaavvvvvvddde ",
      " aaaavvvvvvddde ",
      " aiiavvvvvvddde "
    ],
    [
      "                ",
      " aaaaaaaaaaaaaa ",
      " a  jjjjjjjj  a ",
      " a  kg     k  a ",
      " haaaaaaaaah  a ",
      " almmla!mmma  a ",
      " n oo apqr s  a ",
      " n tt a    u  a ",
      " a    a    a  a ",
      " hwaaxayAB h  a ",
      " a Ca DEFI a  a ",
      " n Ja    KLa  a ",
      " n  aM   KNa  a ",
      " aaaaOPPQQQa  a ",
      " aaaammRSp a  a ",
      " n  a      s  a "
    ],
    [
      "                ",
      " T  T      T    ",
      "                ",
      "      g         ",
      " haaaaaaaaah    ",
      " aUUUUaVVVVa    ",
      " W    a    X    ",
      " W    a    Y    ",
      " a   Za    a0   ",
      " h1aa2a3  Zh  T ",
      " a  a 4    a    ",
      " W  a     5W    ",
      " W 6a     7W    ",
      " aQQaQQQQQQa    ",
      " aUUa89999#a    ",
      " W 6a      X    "
    ],
    [
      "                ",
      " T  T      T    ",
      "                ",
      "       g        ",
      " haaaaaaaaah    ",
      " aUUUUaVVVVa    ",
      " W    a    $    ",
      " W    a    $    ",
      " a    a    a    ",
      " hQaaQa%   h  T ",
      " a ^a &    a    ",
      " W  a     *W    ",
      " W (a     )W    ",
      " aaaa+++QQQa    ",
      " aaaaVVVVVVa    ",
      " W (a      $    "
    ],
    [
      "                ",
      " T  T      T    ",
      "                ",
      "        g       ",
      " haaaaaaaaah    ",
      " a----a----a    ",
      " a    a    a    ",
      " a [  a  [ a    ",
      " a    a    a    ",
      " haaaaa]]]]h  T ",
      " a{{a      a    ",
      " a{{a }  | a    ",
      " a{{a      a    ",
      " aaaa]]]]]]a    ",
      " aaaa------a    ",
      " a{{a      a    "
    ],
    [
      "                ",
      " h;;h;;;;;;h;;; ",
      " ;            ; ",
      " ;       g    ; ",
      " haaaaaaaaah  ; ",
      " :ddddddddd:  ; ",
      " :ddddddddd:  ; ",
      " :ddddddddd:  ; ",
      " :ddddddddd:  ; ",
      " hdddddddddh  h ",
      " :d ddddddd:  ; ",
      " :d ddddddd:  ; ",
      " :d'ddddddd:  ; ",
      " :ddddddddd:  ; ",
      " :ddddddddd:  ; ",
      " :d'ddddddd:  ; "
    ]
  ]
}