{
  "name": "multi_flatmedium_0_floor3",
  "refpalette": "deceasedcraft:multi_flatmedium_0/multi_flatmedium_0_floor3_palette",
  "xsize": 16,
  "zsize": 16,
  "slices": [
    [
      "                ",
      " abbabbbbbbabba ",
      " cdddddddddddde ",
      " cddf     gfdde ",
      " haaaaaaaaahdde ",
      " avvvvavvvvddde ",
      " avvvvvvvvvddde ",
      " avivvvvvvvddde ",
      " avvvvvivvvddde ",
      " hvaaavaaaahdda ",
      " ajjavvvvvvddde ",
      " ajjavvvvvvddde ",
      " ajjavvvvvvddde ",
      " ajjavvvvvvddde ",
      " aaaavvvvvvddde ",
      " ajjjvvvvvvddde "
    ],
    [
      "                ",
      " aaaaaaaaaaaaaa ",
      " a  kkkkkkkk  a ",
      " a  lg     l  a ",
      " haaaaaaaaah  a ",
      " ammmmanmmna  a ",
      " op qrs tt a  u ",
      " o   wx yy a  a ",
      " a         a  a ",
      " hAaaaAaaaah  a ",
      " a BaC DEFIa  a ",
      " o JaK  L  a  a ",
      " o  aC     a  u ",
      " aMNaK  OPQa  a ",
      " aaaa!RSmmma  u ",
      " o  T U    V  u "
    ],
    [
      "                ",
      " W  W      W    ",
      "                ",
      "      g         ",
      " haaaaaaaaah    ",
      " aXXYZa0000a    ",
      " 12  34   51    ",
      " 16   7   81    ",
      " a   9     a    ",
      " h#aaa#aaaah  W ",
      " a  aY   $ a    ",
      " 1  aY    51    ",
      " 1 %aY    81    ",
      " a  aY     a    ",
      " a^^a      a    ",
      " 1& *      (    "
    ],
    [
      "                ",
      " W  W      W    ",
      "                ",
      "       g        ",
      " haaaaaaaaah    ",
      " aX)YYa0000a    ",
      " 1+   4   -1    ",
      " 1[   7   ]1    ",
      " a         a    ",
      " h^aaa^aaaah  W ",
      " a {aY     a    ",
      " 1  aY    -1    ",
      " 1 }aY    ]1    ",
      " a  aY     a    ",
      " aaaa      a    ",
      " 1| ;      :    "
    ],
    [
      "                ",
      " W  W      W    ",
      "                ",
      "        g       ",
      " haaaaaaaaah    ",
      " a''''a''''a    ",
      " a    <    a    ",
      " a    > ,  a    ",
      " a         a    ",
      " haaaaaaaaah  W ",
      " a..a''''''a    ",
      " a..a      a    ",
      " a..a ?  / a    ",
      " a..a      a    ",
      " aaaa      a    ",
      " a..a      a    "
    ],
    [
      "                ",
      " h``h``````h``` ",
      " `            ` ",
      " `       g    ` ",
      " haaaaaaaaah  ` ",
      " \u0370ddddddddd\u0370  ` ",
      " \u0370ddddddddd\u0370  ` ",
      " \u0370ddddddddd\u0370  ` ",
      " \u0370ddddddddd\u0370  ` ",
      " hdddddddddh  h ",
      " \u0370d ddddddd\u0370  ` ",
      " \u0370d ddddddd\u0370  ` ",
      " \u0370d\u0371ddddddd\u0370  ` ",
      " \u0370d ddddddd\u0370  ` ",
      " \u0370ddddddddd\u0370  ` ",
      " \u0370d\u0371ddddddd\u0370  ` "
    ]
  ]
}