{
  "name": "multi_flatmedium_0_floor1",
  "refpalette": "deceasedcraft:multi_flatmedium_0/multi_flatmedium_0_floor1_palette",
  "xsize": 16,
  "zsize": 16,
  "slices": [
    [
      "                ",
      " abbabbbbbbabba ",
      " cdddddddddddde ",
      " cddf     gfdde ",
      " haaaaaaaaahdde ",
      " avvvvavvvvddde ",
      " avvvvavvvvddde ",
      " avvvvavvvvddde ",
      " avvvvavvvvddde ",
      " hvaavavvvvhdda ",
      " aiiavvvvvvddde ",
      " aiiavvvvvvddde ",
      " aiiavvvvvvddde ",
      " aaaavvvvvvddde ",
      " aaaavvvvvvddde ",
      " aiiavvvvvvddde "
    ],
    [
      "                ",
      " aaaaaaaaaaaaaa ",
      " a  jjjjjjjj  a ",
      " a  kg     k  a ",
      " haaaaaaaaah  a ",
      " almm!ammmma  a ",
      " n oo apqr s  a ",
      " n tt a    u  a ",
      " aw   a    a  a ",
      " hxaayaABC h  a ",
      " D Ea FIJK a  a ",
      " nLMa      a  a ",
      " N  aO   PQa  a ",
      " aaaaRSSTTTa  U ",
      " aaaammVWp a  a ",
      " nXXa    Y s Za "
    ],
    [
      "                ",
      " N  N      N    ",
      "                ",
      "      g         ",
      " haaaaaaaaah    ",
      " a0000a1111a    ",
      " 2    a    3    ",
      " 2    a    4    ",
      " a   5a    a6   ",
      " h7aa8a9#$5h  N ",
      " D  a %^   a    ",
      "  & a     *2    ",
      " 2 (a    )+2    ",
      " a--a------a    ",
      " a00a[]]]]{a    ",
      " 2  a      3    "
    ],
    [
      "                ",
      " N  N      N    ",
      "                ",
      "       g        ",
      " haaaaaaaaah    ",
      " a0000a1111a    ",
      " 2    a    }    ",
      " 2    a    }    ",
      " a    a    a    ",
      " h-aa-a|   h  N ",
      " a ;a :    a    ",
      " 2  a     '2    ",
      " 2 <a     >2    ",
      " aaaa,,,---a    ",
      " aaaa111111a    ",
      " 2 <a      }    "
    ],
    [
      "                ",
      " N  N      N    ",
      "                ",
      "        g       ",
      " haaaaaaaaah    ",
      " a....a....a    ",
      " a    a    a    ",
      " a ?  a  ? a    ",
      " a    a    a    ",
      " haaaaa////h  N ",
      " a``a      a    ",
      " a``a \u0370  \u0371 a    ",
      " a``a      a    ",
      " aaaa//////a    ",
      " aaaa......a    ",
      " a\u0372\u0372a      a    "
    ],
    [
      "                ",
      " h\u0373\u0373h\u0373\u0373\u0373\u0373\u0373\u0373h\u0373\u0373\u0373 ",
      " \u0373            \u0373 ",
      " \u0373       g    \u0373 ",
      " haaaaaaaaah  \u0373 ",
      " \u0374ddddddddd\u0374  \u0373 ",
      " \u0374ddddddddd\u0374  \u0373 ",
      " \u0374ddddddddd\u0374  \u0373 ",
      " \u0374ddddddddd\u0374  \u0373 ",
      " hdddddddddh  h ",
      " \u0374d ddddddd\u0374  \u0373 ",
      " \u0374d ddddddd\u0374  \u0373 ",
      " \u0374d\u0375ddddddd\u0374  \u0373 ",
      " \u0374ddddddddd\u0374  \u0373 ",
      " \u0374ddddddddd\u0374  \u0373 ",
      " \u0374d\u0375ddddddd\u0374  \u0373 "
    ]
  ]
}