{
  "name": "multi_flatmedium_0_floor5",
  "refpalette": "deceasedcraft:multi_flatmedium_0/multi_flatmedium_0_floor5_palette",
  "xsize": 16,
  "zsize": 16,
  "slices": [
    [
      "                ",
      " abbabbbbbbabba ",
      " cdddddddddddde ",
      " cddf     gfdde ",
      " haaaaaaaaahdde ",
      " avvvvavvvvddde ",
      " avvvvvvvvvddde ",
      " avvvvvvvvvddde ",
      " avvvvvvvvvddde ",
      " hvaaavaaaahdda ",
      " aiiavvvvvvddde ",
      " aiiavvvvvvddde ",
      " aiiavvvvvvddde ",
      " aiiavvvvvvddde ",
      " aaaavvvvvvddde ",
      " aiiivvvvvvddde "
    ],
    [
      "                ",
      " aaaaaaaaaaaaaa ",
      " a  jjjjjjjj  a ",
      " a  kg     k  a ",
      " haaaaaaaaah  a ",
      " allllamllma  a ",
      " n  opq rr a  a ",
      " n   st uu a  a ",
      " a         a  a ",
      " hwaaawaaaah  a ",
      " a xay ABCDa  a ",
      " n EaF     a  a ",
      " n  ay     a  a ",
      " aIJaF  KLMa  a ",
      " aaaalNOllla  a ",
      " n  P      Q  a "
    ],
    [
      "                ",
      " R  R      R    ",
      "                ",
      "      g         ",
      " haaaaaaaaah    ",
      " aSSTTaUUUUa    ",
      " VW   X   YV    ",
      " VZ   0   1V    ",
      " a   2     a    ",
      " h3aaa3aaaah  R ",
      " a  aT   4 a    ",
      " V  aT    YV    ",
      " V 5aT    1V    ",
      " a  aT     a    ",
      " a66a      a    ",
      " V7 8      9    "
    ],
    [
      "                ",
      " R  R      R    ",
      "                ",
      "       g        ",
      " haaaaaaaaah    ",
      " aSSTTaUUUUa    ",
      " V#  $X   %V    ",
      " V^  &0   *V    ",
      " a         a    ",
      " h6aaa6aaaah  R ",
      " a (aT     a    ",
      " V  aT    %V    ",
      " V )aT    *V    ",
      " a  aT     a    ",
      " aaaa      a    ",
      " V+ -      [    "
    ],
    [
      "                ",
      " R  R      R    ",
      "                ",
      "        g       ",
      " haaaaaaaaah    ",
      " a]]]]a]]]]a    ",
      " a    {    a    ",
      " a    } |  a    ",
      " a         a    ",
      " haaaaaaaaah  R ",
      " a;;a]]]]]]a    ",
      " a;;a      a    ",
      " a;;a :  ' a    ",
      " a;;a      a    ",
      " aaaa      a    ",
      " a;;a      a    "
    ],
    [
      "                ",
      " h<<h<<<<<<h<<< ",
      " <            < ",
      " <       g    < ",
      " haaaaaaaaah  < ",
      " >ddddddddd>  < ",
      " >ddddddddd>  < ",
      " >ddddddddd>  < ",
      " >ddddddddd>  < ",
      " hdddddddddh  h ",
      " >d ddddddd>  < ",
      " >d ddddddd>  < ",
      " >d,ddddddd>  < ",
      " >d ddddddd>  < ",
      " >ddddddddd>  < ",
      " >d,ddddddd>  < "
    ]
  ]
}