{
  "name": "multi_alienresearch_9_ground",
  "refpalette": "deceasedcraft:multi_alienresearch_9/multi_alienresearch_9_ground_palette",
  "xsize": 16,
  "zsize": 16,
  "slices": [
    [
      "aazaabaaaaaaaaaa",
      "aavaazaaavzaavav",
      "aaaaavaaaaaaaaaz",
      "vvavvvvbaavvvvaa",
      "avvvzvvavvvvvavv",
      "vvvvvvvvzavzvvvv",
      "vvzvavvvvvvvvvvv",
      "vvvvzzvvvvbvvvva",
      "vvzvvvvvvvvvzvvv",
      "vvvvvvvvvvvvvvvv",
      "vzvvvbvvzvvvvvvz",
      "vvvvvvvvvvvvvvvv",
      "cccccccccccccccc",
      "dzeedededzzfdddz",
      "dedddeddeedezeee",
      "dddeddzeddeedded"
    ],
    [
      "                ",
      "                ",
      "               g",
      "                ",
      "                ",
      "                ",
      "                ",
      "                ",
      "                ",
      "                ",
      "               g",
      "                ",
      "h       hiiiiih ",
      "          jklmmm",
      "                ",
      "      g         "
    ],
    [
      "                ",
      "                ",
      "                ",
      "                ",
      "                ",
      "                ",
      "                ",
      "                ",
      "                ",
      "                ",
      "                ",
      "                ",
      "h       hiiiiih ",
      "           klmmm",
      "                ",
      "                "
    ],
    [
      "                ",
      "                ",
      "                ",
      "                ",
      "                ",
      "                ",
      "                ",
      "                ",
      "                ",
      "                ",
      "                ",
      "                ",
      "h       hiiiiih ",
      "           klmmm",
      "                ",
      "                "
    ],
    [
      "                ",
      "                ",
      "                ",
      "                ",
      "                ",
      "                ",
      "                ",
      "                ",
      "                ",
      "                ",
      "                ",
      "                ",
      "h       hiiiiih ",
      "           klmmm",
      "                ",
      "                "
    ],
    [
      "                ",
      "                ",
      "                ",
      "                ",
      "                ",
      "                ",
      "                ",
      "                ",
      "                ",
      "                ",
      "                ",
      "                ",
      "h       hiiiiih ",
      "           klmmm",
      "                ",
      "                "
    ]
  ]
}