{
  "name": "multi_alienresearch_9_base5",
  "refpalette": "deceasedcraft:multi_alienresearch_9/multi_alienresearch_9_base5_palette",
  "xsize": 16,
  "zsize": 16,
  "slices": [
    [
      "a   abccd       ",
      "     aeccd      ",
      "      abcd      ",
      "f     abccd     ",
      "gf  aa aecd     ",
      "ggfa   abcd     ",
      "ggf    abccd    ",
      "gggf    aecd    ",
      "gggf    abcd    ",
      "gggf    abcc    ",
      "gggfaaaaaecc    ",
      "gggf    abcc    ",
      "gggf    abcd    ",
      "gggf    aecd    ",
      "ggf    abccd    ",
      "ggfa   abcd     "
    ],
    [
      "hhiijj          ",
      "hhhk  j         ",
      "hhlm   j        ",
      "@no m  j        ",
      " @  m   j       ",
      "  e  m  j       ",
      "  @  m  j       ",
      "  p@  m  j      ",
      "  qb  m  j      ",
      "  r@ sm  j      ",
      "  t@nlkjjju     ",
      "  r@hhhiij      ",
      "  qbhhhiij      ",
      "  p@hhhiij      ",
      "  @hhhiij       ",
      "  ehhhiij       "
    ],
    [
      "                ",
      "                ",
      "  w             ",
      "@w              ",
      " @              ",
      "  @             ",
      "  @             ",
      "  x@            ",
      "   @            ",
      "   @            ",
      "   @ww          ",
      "   @            ",
      "   @            ",
      "  x@            ",
      "  @             ",
      "  @             "
    ],
    [
      "                ",
      "                ",
      "                ",
      "mi              ",
      "hiy             ",
      "hiiy            ",
      "chiy            ",
      "chiiy           ",
      " chiy           ",
      " chiy           ",
      " chii           ",
      " chiy           ",
      " chiy           ",
      "chiiy           ",
      "chiy            ",
      "hiiy            "
    ],
    [
      "                ",
      "  A             ",
      "                ",
      "                ",
      "                ",
      "                ",
      "                ",
      "                ",
      "i               ",
      "i               ",
      "i               ",
      "i               ",
      "i               ",
      "                ",
      "                ",
      "                "
    ],
    [
      "                ",
      "  B             ",
      "                ",
      "                ",
      "                ",
      "                ",
      "                ",
      "                ",
      "                ",
      "                ",
      "                ",
      "                ",
      "                ",
      "                ",
      "                ",
      "                "
    ]
  ]
}