{
  "name": "multi_alienresearch_9_base8",
  "refpalette": "deceasedcraft:multi_alienresearch_9/multi_alienresearch_9_base8_palette",
  "xsize": 16,
  "zsize": 16,
  "slices": [
    [
      "aaa  bbbccdddddd",
      "eeaabbbbbcdddddd",
      "eeebbbbbbccddddd",
      "eeeebbbbbbcddddd",
      "eeeebbbbbbccffff",
      "eeeeebbbbbbcgggg",
      "eeeeebbbbbbcgggg",
      "heeeeebbbbbigggg",
      "heeeeebbbbbigggg",
      "heeeeebbbbbiiggg",
      "heeeeebbbbjiiggg",
      "heeeeebbbbbiiggg",
      "heeeeebbbbbigggg",
      "heeeeebbbbbigggg",
      "eeeeebbbbbbcgggg",
      "eeeeebbbbbbcgggg"
    ],
    [
      "aaa  k  lmcddddd",
      "  aak    ncddddd",
      "   o      pcdddd",
      "           cdddd",
      "           qcfff",
      "  r        sc!  ",
      "  t        ucw  ",
      "x yA        ii  ",
      "  B          C  ",
      "D           ii  ",
      "D          jij  ",
      "D           ii  ",
      "  r          E  ",
      "x FA        ii  ",
      "  I        JcK  ",
      "  B        qcK  "
    ],
    [
      "          lcdddd",
      "           cdddd",
      "            cddd",
      "            cddd",
      "            cfff",
      "             c  ",
      "  L          c  ",
      "  M          i  ",
      "             N  ",
      "             i  ",
      "            jij ",
      "             i  ",
      "             O  ",
      "  P          i  ",
      "             c  ",
      "             c  "
    ],
    [
      "            cddd",
      "            cddd",
      "            cddd",
      "             cdd",
      "             cff",
      "              c ",
      "              c ",
      "              i ",
      "             Qi ",
      "              i ",
      "             jij",
      "              i ",
      "             Qi ",
      "              i ",
      "              c ",
      "              c "
    ],
    [
      "            cddd",
      "             cdd",
      "             cdd",
      "              cd",
      "              cf",
      "              cc",
      "              cc",
      "               c",
      "               c",
      "               i",
      "              ji",
      "               i",
      "               c",
      "               c",
      "              cc",
      "              cc"
    ],
    [
      "             cdd",
      "              cd",
      "              cd",
      "              cd",
      "               c",
      "               c",
      "               c",
      "               c",
      "               c",
      "               i",
      "              ji",
      "               i",
      "               c",
      "               c",
      "               c",
      "               c"
    ]
  ]
}