{
  "name": "multi_alienresearch_9_base9",
  "refpalette": "deceasedcraft:multi_alienresearch_9/multi_alienresearch_9_base9_palette",
  "xsize": 16,
  "zsize": 16,
  "slices": [
    [
      "aaaaaaaaaaaaaaaa",
      "aaaaaaaaaaaaaaaa",
      "aaaaaaaaaaaaaaaa",
      "aaaaaaaaaaaaaaaa",
      "baaaaaaaaaaaaaaa",
      "baaaaaaaaaaaaaaa",
      "bcaaaaaaaaaaaaaa",
      "bccaaaaaaaaaaaaa",
      "bbcaaaaaaaaaaaaa",
      "bbbaaaaaaaaaaaaa",
      "dbbaaaaaaaaaaaaa",
      "bbbaaaaaaaaaaaaa",
      "bbcaaaaaaaaaaaaa",
      "bccaaaaaaaaaaaaa",
      "bcaaaaaaaaaaaaaa",
      "baaaaaaaaaaaaaaa"
    ],
    [
      "aaaaaaaaaaaaaaaa",
      "caaaaaaaaaaaaaaa",
      "cbaaaaaaaaaaaaaa",
      "bbbaaaaaaaaaaaaa",
      "ebccaaaaaaaaaaaa",
      " cccaaaaaaaaaaaa",
      "  cccaaaaaaaaaaa",
      "   ccaaaaaaaaaaa",
      "e  ccaaaaaaaaaaa",
      "e  bbaaaaaaaaaaa",
      "eeebbaaaaaaaaaaa",
      "e  bbaaaaaaaaaaa",
      "e  ccaaaaaaaaaaa",
      "   ccaaaaaaaaaaa",
      "  cccaaaaaaaaaaa",
      " cccaaaaaaaaaaaa"
    ],
    [
      "cccaaaaaaaaaaaaa",
      " cbbaaaaaaaaaaaa",
      "  bbcaaaaaaaaaaa",
      " e ccaaaaaaaaaaa",
      "    ccaaaaaaaaaa",
      "    ccaaaaaaaaaa",
      "     ccaaaaaaaaa",
      "     ccaaaaaaaaa",
      "     ccaaaaaaaaa",
      "     bbaaaaaaaaa",
      "   eebbaaaaaaaaa",
      "     bbaaaaaaaaa",
      "     ccaaaaaaaaa",
      "     ccaaaaaaaaa",
      "     ccaaaaaaaaa",
      "    ccaaaaaaaaaa"
    ],
    [
      "   bbaaaaaaaaaaa",
      "   ebcaaaaaaaaaa",
      "  e  ccaaaaaaaaa",
      "     ccaaaaaaaaa",
      "      ccaaaaaaaa",
      "      ccaaaaaaaa",
      "       caaaaaaaa",
      "       ccaaaaaaa",
      "       ccaaaaaaa",
      "       bbaaaaaaa",
      "     eebbaaaaaaa",
      "       bbaaaaaaa",
      "       ccaaaaaaa",
      "       ccaaaaaaa",
      "       caaaaaaaa",
      "      ccaaaaaaaa"
    ],
    [
      "    ebcaaaaaaaaa",
      "   f  ccaaaaaaaa",
      "  e    caaaaaaaa",
      " g     ccaaaaaaa",
      "        caaaaaaa",
      "        ccaaaaaa",
      "        ccaaaaaa",
      "         caaaaaa",
      "         caaaaaa",
      "         baaaaaa",
      "    gefeebaaaaaa",
      "         baaaaaa",
      "         caaaaaa",
      "         caaaaaa",
      "        ccaaaaaa",
      "        ccaaaaaa"
    ],
    [
      "       caaaaaaaa",
      "        caaaaaaa",
      "e f     caaaaaaa",
      " e       caaaaaa",
      "e e      caaaaaa",
      "   e      caaaaa",
      "   eh     caaaaa",
      "    e     caaaaa",
      "e   e     caaaaa",
      "e   e     baaaaa",
      "eeeeef   ebaaaaa",
      "e   e     baaaaa",
      "e   e     caaaaa",
      "    e     caaaaa",
      "   eh     caaaaa",
      "   e      caaaaa"
    ]
  ]
}