{
  "name": "multi_alienresearch_9_base3",
  "refpalette": "deceasedcraft:multi_alienresearch_9/multi_alienresearch_9_base3_palette",
  "xsize": 16,
  "zsize": 16,
  "slices": [
    [
      "ab  cdeefffffghi",
      "  jc  defffffghi",
      "   j   defffffgh",
      "    k  defffffgh",
      "    l   deffffgh",
      "     k  deffffgh",
      "     l  deeffffg",
      "m     k  deffffg",
      "      n  deffffg",
      "      n  deffffg",
      "      ncceeffffg",
      "      n  deffffg",
      "      n  deffffg",
      "      l  deffffg",
      "     k   deeeeeg",
      "     l   dddddgh"
    ],
    [
      "       o     hii",
      "  p    o      hi",
      "        o     hi",
      "        oq    hi",
      "         o     h",
      "         o    rh",
      "          s    h",
      "tu        o    e",
      "          o    w",
      "          o    e",
      "          ox  ge",
      "          oy   e",
      "          oA   B",
      "          oyC  e",
      "          sooooh",
      "               h"
    ],
    [
      "       o    hiii",
      "       o     hii",
      "        o    hii",
      "        o     hi",
      "         o    hi",
      "         o    hD",
      "          s   hE",
      "F         o    e",
      "          o    I",
      "          o    e",
      "          oJ  ge",
      "          o    e",
      "          oK   L",
      "          o!   e",
      "          sooohE",
      "              hD"
    ],
    [
      "       o    hiii",
      "       o    hiii",
      "        o   hiii",
      "        o    hii",
      "         o   hii",
      "         o    hD",
      "          s   hE",
      "M         o   ee",
      "          o   ed",
      "          o   ee",
      "          o  gee",
      "          o   ee",
      "          o   ed",
      "          o   ee",
      "          sooghE",
      "              hD"
    ],
    [
      "       o   hiiii",
      "       o   hiiii",
      "        o   hiii",
      "        o   hiii",
      "         o  hiii",
      "         o   hDD",
      "          s  hDN",
      "O         o  hDP",
      "          o  hDP",
      "          o  eDP",
      "          o geDP",
      "          o  eDP",
      "          o  hDP",
      "          o  hDP",
      "          soghDQ",
      "             hDD"
    ],
    [
      "       R  hiiiii",
      "       R  hiiiii",
      "        R  hiiii",
      "        R  hiiii",
      "         R  hiii",
      "         R  hiDD",
      "          o hiD ",
      "O         R hiD ",
      "          R hiD ",
      "          R eiD ",
      "          RgeiD ",
      "          R eiD ",
      "          R hiD ",
      "          R hiD ",
      "          oghiD ",
      "            hiDD"
    ]
  ]
}