{
  "name": "multi_alienresearch_9_base6",
  "refpalette": "deceasedcraft:multi_alienresearch_9/multi_alienresearch_9_base6_palette",
  "xsize": 16,
  "zsize": 16,
  "slices": [
    [
      "                ",
      "                ",
      "a               ",
      " a              ",
      "  a             ",
      "   a            ",
      "   a            ",
      "    a           ",
      "    a           ",
      "    a           ",
      "    a           ",
      "    a           ",
      "    a           ",
      "    a           ",
      "   a            ",
      "   a            "
    ],
    [
      "                ",
      "                ",
      "                ",
      "                ",
      "                ",
      "                ",
      "                ",
      "                ",
      "                ",
      "                ",
      "                ",
      "                ",
      "                ",
      "                ",
      "                ",
      "                "
    ],
    [
      "                ",
      "                ",
      "                ",
      "b               ",
      "cb              ",
      "ccc             ",
      "ddd             ",
      "dccb            ",
      "edcb            ",
      "edcc            ",
      "eddd            ",
      "edcc            ",
      "edcb            ",
      "dccb            ",
      "ddd             ",
      "ccc             "
    ],
    [
      " c              ",
      "fgb             ",
      "gg b            ",
      "hgggc           ",
      " hgf            ",
      "  f fc          ",
      "  ifgb          ",
      "  jhg b         ",
      "   hggb         ",
      "  klffc         ",
      "  min           ",
      "  klffc         ",
      "   hggb         ",
      "  jhg b         ",
      "  ifgb          ",
      "  f fc          "
    ],
    [
      " fggb           ",
      "f hggb          ",
      "  ohgbc         ",
      "    ffp         ",
      "   f  fb        ",
      "  f ffgb        ",
      "  if hgb        ",
      "     ohgb       ",
      "      hgb       ",
      "    ffffc       ",
      "   in   p       ",
      "    ffffc       ",
      "      hgb       ",
      "     ohgb       ",
      "  if hgb        ",
      "  f ffgb        "
    ],
    [
      "q@  ggbd        ",
      "@    hgd        ",
      "     hhrd       ",
      "    @@qsd       ",
      "   @qq@hgd      ",
      "  @q@@ hgd      ",
      "  i@   hgbd     ",
      "        hgd     ",
      "        hgd     ",
      "    @@@@@sd     ",
      "   iqqqqqrd     ",
      "    @@@@@sd     ",
      "        hgd     ",
      "        hgd     ",
      "  i@   hgbd     ",
      "  @q@@ hgd      "
    ]
  ]
}