{
  "name": "multi_alienresearch_9_base2",
  "refpalette": "deceasedcraft:multi_alienresearch_9/multi_alienresearch_9_base2_palette",
  "xsize": 16,
  "zsize": 16,
  "slices": [
    [
      "       abbcccccc",
      "       a bcccccc",
      "a d     abbccccc",
      " a      a bccccc",
      "d a      abbcccc",
      "   a     a bccee",
      "f  a      abcce ",
      "g   a     abcce ",
      " f  a     abcce ",
      " h  a     aiice ",
      " hddad    aiice ",
      " h  a     aiice ",
      " g  a     abcce ",
      "f   a     abcce ",
      "g  a      abcce ",
      "   a       bccee"
    ],
    [
      "    d  bcccccccc",
      "   a    bccccccc",
      "  a     bccccccc",
      " j       bcccccc",
      "         bcccccc",
      "          bcccee",
      "          bccce ",
      "k         bcccel",
      "          bcccem",
      "          icccem",
      "    jaad aicccem",
      "          icccem",
      "          bcccem",
      "          bcccen",
      "          bccce ",
      "          bcccee"
    ],
    [
      "    aibccccccccc",
      "   j  bbcccccccc",
      "       bcccccccc",
      "       bbccccccc",
      "        bccccccc",
      "        bbccccee",
      "        bbcccceb",
      "         bcccceo",
      "         bcccceb",
      "         icccceb",
      "      jaaicccceb",
      "         icccceb",
      "         bcccceb",
      "         bcccceo",
      "        bbcccceb",
      "        bbccccee"
    ],
    [
      "   iiccccccccccc",
      "   aibcccccccccc",
      "  a  bbccccccccc",
      "     bbccccccccc",
      "      bbcccccccc",
      "      bbcccccccc",
      "       bcccccccc",
      "       bbccccccc",
      "       bbccccccc",
      "       iiccccccc",
      "     aaiiccccccc",
      "       iiccccccc",
      "       bbccccccc",
      "       bbccccccc",
      "       bcccccccc",
      "      bbcccccccc"
    ],
    [
      "bbbccccccccccccc",
      " biicccccccccccc",
      "  iibccccccccccc",
      " a bbccccccccccc",
      "    bbcccccccccc",
      "    bbcccccccccc",
      "     bbccccccccc",
      "     bbccccccccc",
      "     bbccccccccc",
      "     iiccccccccc",
      "   aaiiccccccccc",
      "     iiccccccccc",
      "     bbccccccccc",
      "     bbccccccccc",
      "     bbccccccccc",
      "    bbcccccccccc"
    ],
    [
      "cccccccccccccccc",
      "bccccccccccccccc",
      "bicccccccccccccc",
      "iiiccccccccccccc",
      "aibbcccccccccccc",
      " bbbcccccccccccc",
      "  bbbccccccccccc",
      "   bbccccccccccc",
      "a  bbccccccccccc",
      "a  iiccccccccccc",
      "aaaiiccccccccccc",
      "a  iiccccccccccc",
      "a  bbccccccccccc",
      "   bbccccccccccc",
      "  bbbccccccccccc",
      " bbbcccccccccccc"
    ]
  ]
}