{
  "name": "multi_verticalschool_24_base1",
  "refpalette": "deceasedcraft:multi_verticalschool_24/multi_verticalschool_24_base1_palette",
  "xsize": 16,
  "zsize": 16,
  "slices": [
    [
      "aaaaaaa   bccccv",
      "dededfag  bccccv",
      " h i fag  bccccv",
      "dededfag  bccccv",
      "aaaajaa   bccccv",
      "kkkk k    bccccv",
      "llllll    bccccv",
      "aaaaaaa   bccccv",
      "dededfag  bccccv",
      " h i fag  bccccv",
      "dededfag  bccccv",
      "aaaajaa   bccccv",
      "kkkk k    bccccv",
      "       mmmbccccv",
      "bbbbbbbbbbbccccv",
      "vvvvvvvvvvvvvvvv"
    ],
    [
      "nnnnnno   bccccv",
      "      p   bccccv",
      "      p   bccccv",
      "      p   bccccv",
      "nnnnqno   bccccv",
      "          bccccv",
      "          bccccv",
      "nnnnnno   bccccv",
      "      p   bccccv",
      "      p   bccccv",
      "      p   bccccv",
      "nnnnqno   bccccv",
      "          bccccv",
      "       mmmbccccv",
      "bbbbbbbbbbbccccv",
      "vvvvvvvvvvvvvvvv"
    ],
    [
      "rrrrrrs   bccccv",
      "ttttttu   bccccv",
      "www  tu   bccccv",
      "ttttttu   bccccv",
      "rrrrrrs   bccccv",
      "          bccccv",
      "          bccccv",
      "rrrrrrs   bccccv",
      "ttttttu   bccccv",
      "www  tu   bccccv",
      "ttttttu   bccccv",
      "rrrrrrs   bccccv",
      "          bccccv",
      "       mmmbccccv",
      "bbbbbbbbbbbccccv",
      "vvvvvvvvvvvvvvvv"
    ],
    [
      "          bccccv",
      "          bccccv",
      "   xy     bccccv",
      "          bccccv",
      "          bccccv",
      "          bccccv",
      "          bccccv",
      "          bccccv",
      "          bccccv",
      "   xy     bccccv",
      "          bccccv",
      "          bccccv",
      "          bccccv",
      "       mmmbccccv",
      "bbbbbbbbbbbccccv",
      "vvvvvvvvvvvvvvvv"
    ],
    [
      "          bccccv",
      "          bccccv",
      "          bccccv",
      "          bccccv",
      "          bccccv",
      "          bccccv",
      "          bccccv",
      "          bccccv",
      "          bccccv",
      "          bccccv",
      "          bccccv",
      "          bccccv",
      "          bccccv",
      "       mmmbccccv",
      "bbbbbbbbbbbccccv",
      "vvvvvvvvvvvvvvvv"
    ],
    [
      "AAAAAAAAAABccccv",
      "AAAAAAAAAABccccv",
      "AAAAAAACCABccccv",
      "AAAAAAAAAABccccv",
      "AAAAAAAAAABccccv",
      "AAAAAAAAAABccccv",
      "AAAAAAAAAABccccv",
      "AAAAAAAAAABccccv",
      "AAAAAAAAAABccccv",
      "AAAAAAACCABccccv",
      "AAAAAAAAAABccccv",
      "AAAAAAAAAABccccv",
      "AAAAAAAAAABccccv",
      "AAAAAAAmmmBccccv",
      "BBBBBBBBBBBccccv",
      "vvvvvvvvvvvvvvvv"
    ]
  ]
}