{
  "name": "multi_verticalschool_24_ground",
  "refpalette": "deceasedcraft:multi_verticalschool_24/multi_verticalschool_24_ground_palette",
  "xsize": 16,
  "zsize": 16,
  "slices": [
    [
      "aabcddcddddcdcba",
      "abcddcdddddcdcba",
      "bcddcddddddcdcba",
      "cddcdddddddcdcba",
      "ddcddddddddcdcba",
      "dcdddddddddcdcba",
      "cddddddddddcdcba",
      "dddddddddddcdcba",
      "ddddddddddcddcba",
      "ddddddddddcddcba",
      "ddddddddccddcbaa",
      "ccccccccddddcbaa",
      "ddddddddddccbaaa",
      "ccccccccccbbaaaa",
      "bbbbbbbbbbaaaaaa",
      "aaaaaaaaaaaaaaaa"
    ],
    [
      "  efggchijhcgfe ",
      " efggcihkhicgfe ",
      "efggchiihhicgfe ",
      "fggchhjiliicgfe ",
      "ggclhhhiiimcgfe ",
      "gchhhhhnnoicgfe ",
      "chihnhihhhncgfe ",
      "iininhiiphhcgfe ",
      "ihhhihiihncggfe ",
      "iqjrhislhicggfe ",
      "lihihpihccggfe  ",
      "ccccccccggggfe  ",
      "ggggggggggffe   ",
      "ffffffffffee    ",
      "eeeeeeeeee      ",
      "                "
    ],
    [
      "                ",
      "         t      ",
      "                ",
      "        t t     ",
      "      t  u      ",
      "          t     ",
      "    t t         ",
      "                ",
      "  u    tt       ",
      "   t   u        ",
      "                ",
      "                ",
      "                ",
      "                ",
      "                ",
      "                "
    ],
    [
      "                ",
      "                ",
      "                ",
      "                ",
      "                ",
      "                ",
      "                ",
      "                ",
      "                ",
      "                ",
      "                ",
      "                ",
      "                ",
      "                ",
      "                ",
      "                "
    ],
    [
      "                ",
      "                ",
      "                ",
      "                ",
      "                ",
      "                ",
      "                ",
      "                ",
      "                ",
      "                ",
      "                ",
      "                ",
      "                ",
      "                ",
      "                ",
      "                "
    ],
    [
      "                ",
      "                ",
      "                ",
      "                ",
      "                ",
      "                ",
      "                ",
      "                ",
      "                ",
      "                ",
      "                ",
      "                ",
      "                ",
      "                ",
      "                ",
      "                "
    ]
  ]
}