{
  "name": "multi_verticalschool_24_base2",
  "refpalette": "deceasedcraft:multi_verticalschool_24/multi_verticalschool_24_base2_palette",
  "xsize": 16,
  "zsize": 16,
  "slices": [
    [
      "vvvvvvvvvvvvvvvv",
      "vvvvvvvvvvvvvvvv",
      "vvvvvvvvvvvvvvvv",
      "vvvvvvvvvvvvvvvv",
      "vvvvvvvvvvvvvvvv",
      "vvvvvvvvvvvvvvvv",
      "vvvvvvvvvvvvvvvv",
      "vvvvvvvvvvvvvvvv",
      "vvvvvvvvvvvvvvvv",
      "vvvvvvvvvvvvvvvv",
      "vvvvvvvvvvvvvvvv",
      "vvvvvvvvvvvvvvvv",
      "vvvvvvvvvvvvvvvv",
      "vvvvvvvvvvvvvvvv",
      "vvvvvvvvvvvvvvvv",
      "vvvvvvvvvvvvvvvv"
    ],
    [
      "aaaaaaaaaaabbbbv",
      "aaaaaaaaaaabbbbv",
      "aaaaaaaaaaabbbbv",
      "aaaaaaaaaaabbbbv",
      "aaaaaaaaaaabbbbv",
      "aaaaaaaaaaabbbbv",
      "aaaaaaaaaaabbbbv",
      "aaaaaaaaaaabbbbv",
      "aaaaaaaaaaabbbbv",
      "aaaaaaaaaaabbbbv",
      "aaaaaaaaaaabbbbv",
      "aaaaaaaaaaabbbbv",
      "aaaaaaaaaaabbbbv",
      "aaaaaaacccabbbbv",
      "aaaaaaaaaaabbbbv",
      "vvvvvvvvvvvvvvvv"
    ],
    [
      "aaaaaaaaaaabbbbv",
      "aaaaaaaaaaabbbbv",
      "aaaaaaaaaaabbbbv",
      "aaaaaaaaaaabbbbv",
      "aaaaaaaaaaabbbbv",
      "aaaaaaaaaaabbbbv",
      "aaaaaaaaaaabbbbv",
      "aaaaaaaaaaabbbbv",
      "aaaaaaaaaaabbbbv",
      "aaaaaaaaaaabbbbv",
      "aaaaaaaaaaabbbbv",
      "aaaaaaaaaaabbbbv",
      "aaaaaaaaaaabbbbv",
      "aaaaaaacccabbbbv",
      "aaaaaaaaaaabbbbv",
      "vvvvvvvvvvvvvvvv"
    ],
    [
      "HHHHHHHHHdebbbbv",
      "HHHHHHHHHdebbbbv",
      "HHHHHHHHHdebbbbv",
      "HHHHHHHHHdebbbbv",
      "HHHHHHHHHdebbbbv",
      "HHHHHHHHHdebbbbv",
      "HHHHHHHHHdebbbbv",
      "HHHHHHHHHdebbbbv",
      "HHHHHHHHHdebbbbv",
      "HHHHHHHHHdebbbbv",
      "HHHHHHHHHdebbbbv",
      "HHHHHHHHHdebbbbv",
      "HHHHHHHHHdebbbbv",
      "dddddddcccebbbbv",
      "eeeeeeeeeeebbbbv",
      "vvvvvvvvvvvvvvvv"
    ],
    [
      "fffgfhij  ebbbbv",
      "kkkkkfh   ebbbbv",
      "kkkkkfh   ebbbbv",
      "kkkkkfh   ebbbbv",
      "fffgfhil  ebbbbv",
      "   m      ebbbbv",
      "   n      ebbbbv",
      "fffgfhij  ebbbbv",
      "kkkkkfh   ebbbbv",
      "kkkkkfh   ebbbbv",
      "kkkkkfh   ebbbbv",
      "fffgfhil  ebbbbv",
      "   m      ebbbbv",
      "       cccebbbbv",
      "eeeeeeeeeeebbbbv",
      "vvvvvvvvvvvvvvvv"
    ],
    [
      "oopqroos  tbbbbv",
      "uuuuuwx   tbbbbv",
      "uuuuuwx   tbbbbv",
      "uuuuuwx   tbbbbv",
      "oopyroos  tbbbbv",
      "          tbbbbv",
      "          tbbbbv",
      "oopqroos  tbbbbv",
      "uuuuuwx   tbbbbv",
      "uuuuuwx   tbbbbv",
      "uuuuuwx   tbbbbv",
      "oopyroos  tbbbbv",
      "          tbbbbv",
      "       ccctbbbbv",
      "tttttttttttbbbbv",
      "vvvvvvvvvvvvvvvv"
    ]
  ]
}