{
  "name": "multi_terraceplaza_1_floor4",
  "refpalette": "deceasedcraft:multi_terraceplaza_1/multi_terraceplaza_1_floor4_palette",
  "xsize": 16,
  "zsize": 16,
  "slices": [
    [
      "      ab ccdcccc",
      "      ae ccccccc",
      "      ab ccccccc",
      "      ab ccccccc",
      "      ab ccccccc",
      "      ae ccccccc",
      "      ab ccccccc",
      "      ae ccccccc",
      "      ab ccccccc",
      "      ab ccccccc",
      "      ae ccccccc",
      "      ae   dffff",
      "      ab   fgg  ",
      "      ae   f    ",
      "      ab   f    ",
      "      ab   f    "
    ],
    [
      "      abh  diiii",
      "      aeh   jjjj",
      "      abh   jjjj",
      "      abh   jjjj",
      "      abh   kkkk",
      "      aeh   k   ",
      "      abh   k   ",
      "      aeh   k   ",
      "      abh   k   ",
      "      abh   l   ",
      "      aeh   k   ",
      "      ae mmdnonn",
      "      ab   f    ",
      "      ae   f    ",
      "      ab   f    ",
      "      ab   f    "
    ],
    [
      "      ab   d    ",
      "      ae    p   ",
      "      ab    p   ",
      "      ab    pq r",
      "      ab    kkkk",
      "      ae    k   ",
      "      ab    k   ",
      "      ae    k   ",
      "      ab    k   ",
      "      ab    s   ",
      "      ae    k   ",
      "      ae   dntnn",
      "      ab   f    ",
      "      ae   f    ",
      "      ab   f    ",
      "      abuuwf    "
    ],
    [
      "      ab   d    ",
      "      ae        ",
      "      ab        ",
      "      ab        ",
      "      ab    kkkk",
      "      ae    k   ",
      "      ab    k   ",
      "      ae    k   ",
      "      ab    k   ",
      "      ab    x   ",
      "      ae    ky  ",
      "      ae   dnnnn",
      "      abuuwf    ",
      "      aeuuAf    ",
      "      abuuBf    ",
      "      ab  BBwwww"
    ],
    [
      "      ab   d    ",
      "      ae        ",
      "      ab        ",
      "      ab        ",
      "      ab    kkkk",
      "      ae    k   ",
      "      ab    k   ",
      "      ae    k   ",
      "      ab    k   ",
      "      abuuwCkCCC",
      "      aeuuADkDDD",
      "      aeuuBdEEEE",
      "      ab  BBBBBB",
      "      ae  BBBBBB",
      "      ab  FFFFFF",
      "      ab  IIIIII"
    ],
    [
      "      ab   d    ",
      "      ae        ",
      "      ab        ",
      "      ab        ",
      "      ab    kkkk",
      "      ae    k   ",
      "      abuuwCkCCC",
      "      aeuuADkDDD",
      "      abuuBJJJJJ",
      "      ab  BBBBBB",
      "      ae  BBBBBB",
      "      ae  FFFFFF",
      "      ab  IIIIII",
      "                ",
      "                ",
      "                "
    ]
  ]
}