{
  "name": "multi_terraceplaza_1_base1",
  "refpalette": "deceasedcraft:multi_terraceplaza_1/multi_terraceplaza_1_base1_palette",
  "xsize": 16,
  "zsize": 16,
  "slices": [
    [
      "vaaabccHHHHdHHHH",
      "vaaabccHHHHHHHHH",
      "vaaabccHHHHHHHHH",
      "vaaabccHHHHHHHHH",
      "vaaabccHHHHHHHHH",
      "vaaabccHHHef    ",
      "vaaabccHHHef    ",
      "vaaabccHHHef    ",
      "vbbbbccgggggbbbb",
      "vb  bccccccccccc",
      "vb  bccccccccccc",
      "vb  bbbbbbbdbbbb",
      "vb  bh    hbiiii",
      "vb  bj    jbiiii",
      "vb  bk    jbiiii",
      "vb  b!    lbmmii"
    ],
    [
      "vaaab      dnnnn",
      "vaaab           ",
      "vaaab           ",
      "vaaab           ",
      "vaaab      ooooo",
      "vaaab           ",
      "vaaab           ",
      "vaaab           ",
      "vbbbb      obbbb",
      "vb  b           ",
      "vb  b           ",
      "vb  bbbbbbbdbbbb",
      "vb  bh    hbpqqp",
      "vb  b      b    ",
      "vb  b      b    ",
      "vb  b      b rs "
    ],
    [
      "vaaab      d    ",
      "vaaab           ",
      "vaaab           ",
      "vaaab           ",
      "vaaab      o  o ",
      "vaaab           ",
      "vaaab           ",
      "vaaab           ",
      "vbbbb      obbbb",
      "vb  b           ",
      "vb  b           ",
      "vb  bbbbbbbdbbbb",
      "vb  bh    hb ttu",
      "vb  b      b   w",
      "vb  b      b    ",
      "vb  b      b xy "
    ],
    [
      "vaaab      d    ",
      "vaaab           ",
      "vaaab           ",
      "vaaab           ",
      "vaaab      o  o ",
      "vaaab          A",
      "vaaab          A",
      "vaaab          A",
      "vbbbb      obbbb",
      "vb  b           ",
      "vb  b           ",
      "vb  bbbbbbbdbbbb",
      "vb  bBBBBBBbCDDE",
      "vb  bBBBBBBb    ",
      "vb  bFBBBBBb    ",
      "vb  bBBBBBBbIIy "
    ],
    [
      "vaaab      d    ",
      "vaaab           ",
      "vaaab           ",
      "vaaab   J       ",
      "vaaab      ooooo",
      "vaaab      oAKHH",
      "vaaab      oAKHH",
      "vaaab      oAKHH",
      "vbbbb      obbbb",
      "vb  b           ",
      "vb  b           ",
      "vb  bLbbbbbdbbbb",
      "vb  bMaaaaab    ",
      "vb  bMaaaaab    ",
      "vb  bMaaaaab    ",
      "vb  bMaaaaabIIN "
    ],
    [
      "vaaabBBBBBBdOOOO",
      "vaaabBBBBBBOHHHo",
      "vaaabBBBBBBOHHHo",
      "vaaabBBBPBBOHHHo",
      "vaaabBBBBBBOQQQo",
      "vaaabBBBBBBOfff ",
      "vaaabBBBBBBOfff ",
      "vaaabBBBBBBOfff ",
      "vbbbbBBBPBBObbbR",
      "vbBBbBBBBBBOBBBB",
      "vbBBbBBBBBBOBBBB",
      "vbBBbbbbbbSdOOOO",
      "vbBBbaaaaaTOUUUU",
      "vbBBbaaaaaTOUUUU",
      "vbBBbaaaaaTOUUUU",
      "vbBBbaaaaaTOUUUU"
    ]
  ]
}