{
  "name": "multi_terraceplaza_1_floor1",
  "refpalette": "deceasedcraft:multi_terraceplaza_1/multi_terraceplaza_1_floor1_palette",
  "xsize": 16,
  "zsize": 16,
  "slices": [
    [
      "           a    ",
      "       b        ",
      "       b        ",
      "       b        ",
      "      cd        ",
      "      ce        ",
      "      cd        ",
      "      ce        ",
      "      cd        ",
      "      cd        ",
      "      ce        ",
      "      ce  fagggg",
      "      cd  fh  ii",
      "      ce  fh   i",
      "      cd  fh    ",
      "      cd  fh   i"
    ],
    [
      "       b   ajjjj",
      "       b   jkkkk",
      "      cd   jklll",
      "      cd   jklmm",
      "      cd   jklmn",
      "      ce   jklmn",
      "      cd   jklmn",
      "      ce   jklmn",
      "      cd   jklmm",
      "      cd   jklll",
      "      ce  ojkkkk",
      "      ceppqajjjj",
      "      cd rsji  i",
      "      ce rsj    ",
      "      cd rsji   ",
      "      cd rsji   "
    ],
    [
      "      cd   atttt",
      "      ce   uwxxx",
      "      cd   uwwww",
      "      cd   uwwww",
      "      cd   uwwww",
      "      ce   uwwxx",
      "      cd   uwwxx",
      "      ce   uwwww",
      "      cd   uwwww",
      "      cd   uwwww",
      "      ce   uwxxx",
      "      ce  yagggg",
      "      cd  ABCCCC",
      "      ce  ABCCCC",
      "      cd  ABCCCC",
      "      cd  ABDDCC"
    ],
    [
      "      cd   aEEEE",
      "      ce   E FII",
      "      cd   E    ",
      "      cd   E    ",
      "      cd   E    ",
      "      ce   E  FI",
      "      cd   E  FI",
      "      ce   E    ",
      "      cd   E    ",
      "      cd   E    ",
      "      ce   EJFII",
      "      ce   agggg",
      "      cd  AgKLLK",
      "      ce  Ag    ",
      "      cd  Ag    ",
      "      cd  Ag MN "
    ],
    [
      "      cd   aeeee",
      "      ce   e OPQ",
      "      cd   e    ",
      "      cd   e    ",
      "      cd   e    ",
      "      ce   e  RS",
      "      cd   e  TU",
      "      ce   e    ",
      "      cd   e    ",
      "      cd   e    ",
      "      ce   e  V ",
      "      ce   agggg",
      "      cd   g WWX",
      "      ce  Ab   Y",
      "      cd   b    ",
      "      cd  Ag Z0 "
    ],
    [
      "      cd   aeeee",
      "      ce   e    ",
      "      cd   e    ",
      "      cd   e    ",
      "      cd   e    ",
      "      ce   e    ",
      "      cd   e    ",
      "      ce   e    ",
      "      cd   e    ",
      "      cd   e    ",
      "      ce   e 1 1",
      "      ce   agggg",
      "      cd   g2334",
      "      ce   g    ",
      "      cd   g    ",
      "      cd   g550 "
    ]
  ]
}