{
  "name": "multi_terraceplaza_1_floor2",
  "refpalette": "deceasedcraft:multi_terraceplaza_1/multi_terraceplaza_1_floor2_palette",
  "xsize": 16,
  "zsize": 16,
  "slices": [
    [
      "      ab   cdddd",
      "      ad   d    ",
      "      ab   d    ",
      "      ab   d    ",
      "      ab   d    ",
      "      ad   d    ",
      "      ab   d    ",
      "      ad   d    ",
      "      ab   d    ",
      "      ab   d    ",
      "      ad   d e f",
      "      ad   cgggg",
      "      ab   g    ",
      "      ad   g    ",
      "      ab   g    ",
      "      ab   ghhi "
    ],
    [
      "      ab   cjjjj",
      "      ad   k    ",
      "      ab   k    ",
      "      ab   k    ",
      "      ab   k    ",
      "      ad   k    ",
      "      ab   k    ",
      "      ad   k    ",
      "      ab   k    ",
      "      ab   k    ",
      "      ad   k    ",
      "      ad   cgggg",
      "      ab   lmmmm",
      "      ad   lmmmm",
      "      ab   lmmmm",
      "      ab   lmmmm"
    ],
    [
      "      ab  ncoooo",
      "      ad   p    ",
      "      ab   p    ",
      "      ab   p    ",
      "      ab   p    ",
      "      ad   p    ",
      "      ab   p    ",
      "      ad   p    ",
      "      ab   p    ",
      "      ab   p    ",
      "      ad   p    ",
      "      ad  ncgggg",
      "      ab  nlq   ",
      "      ad  nl    ",
      "      ab  nl    ",
      "      ab  nl   q"
    ],
    [
      "      abrrsctttt",
      "      aduuwtmmmm",
      "      abuuwtmmmm",
      "      abuuwtmmmm",
      "      abuuwtmmmm",
      "      aduuwtmmmm",
      "      abuuwtmmmm",
      "      aduuwtmmmm",
      "      abuuwtmmmm",
      "      abuuwtmmmm",
      "      aduuwtmmmm",
      "      adrrsctttt",
      "      ab xyt   q",
      "      ad xyt    ",
      "      ab xyt    ",
      "      ab xytq   "
    ],
    [
      "      ablllclllA",
      "      adlllllllA",
      "      ablAAAlllA",
      "      ablAAAlllA",
      "      ablAAAlllA",
      "      adlAAAlllA",
      "      ablAAAlllA",
      "      adlAAAlllA",
      "      ablAAAlllA",
      "      ablAAAlllA",
      "      adlllllllA",
      "      ad  Bcgggg",
      "      ab  CDEEEE",
      "      ad  CDEEEE",
      "      ab  CDEEEE",
      "      ab  CDwwEE"
    ],
    [
      "      ab   c    ",
      "      ad        ",
      "      ab        ",
      "      ab FI     ",
      "      ab JK     ",
      "      ad J      ",
      "      ab JL     ",
      "      ad MN     ",
      "      ab OP     ",
      "      ab        ",
      "      ad        ",
      "      adQQQcgggg",
      "      ab  CgRSSR",
      "      ad  Cg  TU",
      "      ab  Cg   V",
      "      ab  Cg WX "
    ]
  ]
}