{
  "name": "multi_terraceplaza_1_base2",
  "refpalette": "deceasedcraft:multi_terraceplaza_1/multi_terraceplaza_1_base2_palette",
  "xsize": 16,
  "zsize": 16,
  "slices": [
    [
      "vaaabccHHHHdHHHH",
      "vaaabccHHHHHHHHH",
      "vaaabccHHHHHHHHH",
      "vaaabccHHHHHHHHH",
      "vaaabccHHHHHHHHH",
      "vaaabcceeeeeeeee",
      "vaaabcceeeeeeeee",
      "vaaabcceeeeeeeee",
      "vbbbbcceeeeebbbb",
      "vbeeeccccccccccc",
      "vbeeeccccccccccc",
      "vbeebbeeeebdbbbe",
      "vbeebeeeeeebeeee",
      "vbeebeeeeeebeeee",
      "vbeebeeeeeebeeee",
      "vbeebeeeeeebeeee"
    ],
    [
      "vaaab      dffff",
      "vaaab           ",
      "vaaab           ",
      "vaaab           ",
      "vaaab         g ",
      "vaaab           ",
      "vaaab           ",
      "vaaab           ",
      "vbbbb       bbbb",
      "vb  h           ",
      "vb  i           ",
      "vb  bbjjjjbdbbb ",
      "vb  bk    kbl m ",
      "vb nbo    obm   ",
      "vb  bo    oblm  ",
      "vb  bo    ob    "
    ],
    [
      "vaaab      d    ",
      "vaaab           ",
      "vaaab           ",
      "vaaab           ",
      "vaaab         g ",
      "vaaab           ",
      "vaaab           ",
      "vaaab           ",
      "vbbbbp      bbbb",
      "vb  q           ",
      "vb  r         s ",
      "vb  bbjjjjbdbbbj",
      "vb  bk    kbt   ",
      "vb  bu    wb    ",
      "vb  bx     bt   ",
      "vb  by    yb    "
    ],
    [
      "vaaab      d    ",
      "vaaab           ",
      "vaaab           ",
      "vaaab           ",
      "vaaab         g ",
      "vaaab          A",
      "vaaab          A",
      "vaaab          A",
      "vbbbb       bbbb",
      "vb  B           ",
      "vb  B           ",
      "vb  bbjjjjbdbbbj",
      "vb  bk    kbC   ",
      "vb  bo    obD   ",
      "vb  bo    obC   ",
      "vb  bo    ob    "
    ],
    [
      "vaaab      d    ",
      "vaaab           ",
      "vaaab           ",
      "vaaab         E ",
      "vaaab         gg",
      "vaaab       AFHH",
      "vaaab       AFHH",
      "vaaab       AFHH",
      "vbbbb   E   bbbb",
      "vb  b           ",
      "vb  b           ",
      "vb  bbbbbbbdbbbb",
      "vb  bkIIIIkbJDKI",
      "vb  bL    wb    ",
      "vb  bL    MbJ   ",
      "vb  bN    LbD   "
    ],
    [
      "vaaabOOOOOOdPPPP",
      "vaaabOOOOOOPOOOO",
      "vaaabOOOOOOPOOOO",
      "vaaabOOOQOOPOOQO",
      "vaaabOOOOOOPOOOO",
      "vaaabOOOOOOPHRS ",
      "vaaabOOOOOOPHRS ",
      "vaaabOOOOOOPHRS ",
      "vbbbbOOOQOOPbbbb",
      "vb  bOOOOOOPOOOO",
      "vb  bOOOOOOPOOOO",
      "vb  bbbbbbbdPPPP",
      "vb  bk    kPOOCO",
      "vb  bo    oPOOOO",
      "vb  bo    oPOOOO",
      "vb  bo    oPOOOO"
    ]
  ]
}