{
  "name": "multi_terraceplaza_1_floor3",
  "refpalette": "deceasedcraft:multi_terraceplaza_1/multi_terraceplaza_1_floor3_palette",
  "xsize": 16,
  "zsize": 16,
  "slices": [
    [
      "      ab   c    ",
      "      ad        ",
      "      ab        ",
      "      ab        ",
      "      ab        ",
      "      ad        ",
      "      ab        ",
      "      ad        ",
      "      ab        ",
      "      ab        ",
      "      ad        ",
      "      ad   ceeee",
      "      ab  fe gg!",
      "      ad   h   i",
      "      ab   h    ",
      "      ab  fe jk "
    ],
    [
      "      ab   c    ",
      "      ad        ",
      "      ab        ",
      "      ab        ",
      "      ab        ",
      "      ad        ",
      "      ab        ",
      "      ad        ",
      "      ab        ",
      "      ab        ",
      "      ad        ",
      "      ad   ceeee",
      "      ab   elmmn",
      "      ad   e    ",
      "      ab   e    ",
      "      ab   eook "
    ],
    [
      "      ab   c    ",
      "      ad        ",
      "      ab        ",
      "      ab        ",
      "      ab        ",
      "      ad        ",
      "      ab        ",
      "      ad        ",
      "      ab        ",
      "      ab        ",
      "      ad        ",
      "      ad   ceeee",
      "      ab   e    ",
      "      ad   e    ",
      "      ab   e    ",
      "      ab   eoop "
    ],
    [
      "      ab   c    ",
      "      ad        ",
      "      ab        ",
      "      ab        ",
      "      ab        ",
      "      ad        ",
      "      ab        ",
      "      ad        ",
      "      ab        ",
      "      ab        ",
      "      ad        ",
      "      ad   ceeee",
      "      ab   eqqqq",
      "      ad   eqqqq",
      "      ab   eqqqq",
      "      ab   eqqqq"
    ],
    [
      "      ab   c    ",
      "      ad        ",
      "      ab        ",
      "      ab        ",
      "      ab        ",
      "      ad        ",
      "      ab        ",
      "      ad        ",
      "      ab        ",
      "      ab        ",
      "      ad        ",
      "      ad   ceeee",
      "      ab   erstu",
      "      ad   estuw",
      "      ab   exxtu",
      "      ab   eyrst"
    ],
    [
      "      ab   c    ",
      "      ad        ",
      "      ab        ",
      "      ab        ",
      "      ab        ",
      "      ad        ",
      "      ab        ",
      "      ad        ",
      "      ab        ",
      "      ab        ",
      "      ad        ",
      "      ad   ceeee",
      "      ab   e    ",
      "      ad   exx  ",
      "      ab   e    ",
      "      ab   e    "
    ]
  ]
}