{
  "name": "multi_terraceplaza_1_ground",
  "refpalette": "deceasedcraft:multi_terraceplaza_1/multi_terraceplaza_1_ground_palette",
  "xsize": 16,
  "zsize": 16,
  "slices": [
    [
      "HHHabbccddefHHHg",
      "HHHabcceddeghhhi",
      "HHHajckeddegllli",
      "HHHabckeddeg   i",
      "HHHabckeddeg    ",
      "HHHabckeddeg    ",
      "HHHabckeddeg    ",
      "HHHabckeddeg    ",
      "HHHabckeddeggggg",
      "HHHajckedddddddd",
      "HHHabckedddddddd",
      "HHHabckedmnfoooo",
      "HHHabckeddpqrrrr",
      "HHHajckeddpqrrrr",
      "HHHabckeddpqrrrr",
      "HHHabckeddpqssrr"
    ],
    [
      "    ttuu   f w i",
      "    tux    i   i",
      "    yu     i    ",
      "    Au     i    ",
      "    Au     i    ",
      "    Au     i    ",
      "    Au     i    ",
      "    Au     i    ",
      "    Au     iiiii",
      "    yu          ",
      "    tu          ",
      "    tx B   foooo",
      "    tu C  poDEED",
      "    yu C  po    ",
      "    Au C  po    ",
      "    Au C  po FI "
    ],
    [
      "           f    ",
      "      J         ",
      "    Ku          ",
      "     u          ",
      "     u          ",
      "     u          ",
      "     u          ",
      "     u          ",
      "     u          ",
      "    Ku C        ",
      "       C        ",
      "     J C   foooo",
      "      LM  po NNO",
      "    KuLP   C   Q",
      "     uLM  pC    ",
      "     uLM   o RS "
    ],
    [
      "           f    ",
      "      A         ",
      "                ",
      "                ",
      "                ",
      "                ",
      "                ",
      "       C        ",
      "       C        ",
      "       C        ",
      "      LP      TT",
      "     ALP   foooo",
      "      LM   oUVVW",
      "      LP   o    ",
      "      LM   o    ",
      "      LM   oXXS "
    ],
    [
      "           f    ",
      "      A         ",
      "                ",
      "                ",
      "                ",
      "       C        ",
      "       C        ",
      "       C        ",
      "      LM        ",
      "      LM        ",
      "      LP      YY",
      "     ALP   foooo",
      "      LM   o    ",
      "      LP   o    ",
      "      LM   o    ",
      "      LM   oXXZ "
    ],
    [
      "           f    ",
      "                ",
      "                ",
      "       C        ",
      "       C        ",
      "       C        ",
      "      LM        ",
      "      LP        ",
      "      LM        ",
      "      LM        ",
      "      LP      00",
      "      LP   foooo",
      "      LM   12222",
      "      LP   12222",
      "      LM   12222",
      "      LM   12222"
    ]
  ]
}