{
  "name": "multi_gallery_8_base2",
  "refpalette": "deceasedcraft:multi_gallery_8/multi_gallery_8_base2_palette",
  "xsize": 16,
  "zsize": 16,
  "slices": [
    [
      "vvvvvvvvvvvvvvvv",
      "aaaaaabbbbbbbbbb",
      "aaaaaabccccccccc",
      "aaaaaabccccccccc",
      "aaaaaabccccccccc",
      "aaaaaabccccccccc",
      "aaaaaabccccccccc",
      "aaaaaabccccccccc",
      "aaaaaabccccccccc",
      "aaaaaabccccccccc",
      "aaaaaabccccccccc",
      "aaaaaabccccccccc",
      "aaaaaabccccccccc",
      "aaaaaabccccccccc",
      "aaaaaabccccccccc",
      "aaaaaabccccccccc"
    ],
    [
      "vvvvvvvvvvvvvvvv",
      "aaaaaccccccccccc",
      "aaaaacbbdddddddd",
      "aaaaacbbdddddddd",
      "aaaaacbbdddddddd",
      "aaaaacbbdddddddd",
      "aaaaacbbdddddddd",
      "aaaaacbbdddddddd",
      "aaaaacbbddddddde",
      "aaaaacbbddddddde",
      "aaaaacbbddddddde",
      "aaaaacbbddddddde",
      "aaaaacbbdddddddd",
      "aaaaacbbdddddddd",
      "aaaaacbbdfdddddd",
      "aaaaacbbdfffdddd"
    ],
    [
      "vvvvvvvvvvvvvvvv",
      "bbbbbccccccccccc",
      "gggggggb    h f ",
      "gggggggij  hf  h",
      "gggggggi h  j h ",
      "gggggggi  f     ",
      "gggggggi    fj  ",
      "gggggggi   f   e",
      "gggggggi f    ee",
      "gggggggi  f   ee",
      "gggggggi      ee",
      "gggggggi f    ee",
      "kkkggggi       e",
      "llkggggi    f   ",
      "llkggggi      f ",
      "llkggggi    ~m  "
    ],
    [
      "vvvvvvvvvvvvvvvv",
      "nnnnnccccccccccc",
      "o      b    p   ",
      "       iq  r   p",
      "       i p  q r ",
      "       i        ",
      "       i     q  ",
      "       i       s",
      "       i      ee",
      "       i      se",
      "       i      se",
      "       i      ee",
      "       i       s",
      "tt     i        ",
      "ut     i        ",
      "ut     i     w  "
    ],
    [
      "vvvvvvvvvvvvvvvv",
      "nnnnnccccccccccc",
      "      xb    p   ",
      "       i~      r",
      "       i r  ~ ! ",
      "       i        ",
      "       i     ~  ",
      "       i       s",
      "       i       s",
      "       i       e",
      "       i       e",
      "       i       s",
      "       i       s",
      " y     i        ",
      "y      i        ",
      " A     i     w  "
    ],
    [
      "vvvvvvvvvvvvvvvv",
      "nnnnnccccccccccc",
      "       b    p   ",
      "       i        ",
      "       i        ",
      "       i        ",
      "       i        ",
      "       i       e",
      "       i       e",
      "       i       e",
      "       i       e",
      "       i       e",
      "       i       e",
      "yy     i        ",
      " A     i        ",
      " A     i     ~  "
    ]
  ]
}