{
  "name": "multi_gallery_8_base1",
  "refpalette": "deceasedcraft:multi_gallery_8/multi_gallery_8_base1_palette",
  "xsize": 16,
  "zsize": 16,
  "slices": [
    [
      "vvvvvvvvvvvvvvvv",
      "aaaaabbbbbbbbbbb",
      "       c    d   ",
      "       e        ",
      "       e        ",
      "       e        ",
      "       e        ",
      "       e        ",
      "       e        ",
      "       e        ",
      "       e        ",
      "       e        ",
      "       e        ",
      "       e        ",
      " f     e        ",
      "       e        "
    ],
    [
      "vvvvvvvvvvvvvvvv",
      "aaaaabbbbbbbbbbb",
      "       c        ",
      "       e        ",
      "       e        ",
      "       e        ",
      "       e        ",
      "       e        ",
      "       e        ",
      "       e        ",
      "       e        ",
      "       e        ",
      "       e        ",
      "       e        ",
      "       e        ",
      "       e        "
    ],
    [
      "vvvvvvvvvvvvvvvv",
      "aaaaabbbbbbbbbbb",
      "       c        ",
      "       e        ",
      "       e        ",
      "       e        ",
      "       e        ",
      "       e        ",
      "       e        ",
      "       e        ",
      "       e        ",
      "       e        ",
      "       e        ",
      "       e        ",
      "       e        ",
      "       e        "
    ],
    [
      "vvvvvvvvvvvvvvvv",
      "aaaaabbbbbbbbbbb",
      "       c        ",
      "       c        ",
      "       c        ",
      "       c        ",
      "       c        ",
      "       c        ",
      "       c        ",
      "       c        ",
      "       c        ",
      "       c        ",
      "       c        ",
      "       c        ",
      "       c        ",
      "       c        "
    ],
    [
      "vvvvvvvvvvvvvvvv",
      "aaaaabbbbbbbbbbb",
      "gggggbbhiiiiiiii",
      "gggggbbhiiiiiiii",
      "gggggbbhiiiiiiii",
      "gggggbbhiiiiiiii",
      "gggggbbhiiiiiiii",
      "gggggbbhiiiiiiii",
      "gggggbbhiiiiiiii",
      "gggggbbhiiiiiiii",
      "gggggbbhiiiiiiii",
      "gggggbbhiiiiiiii",
      "gggggbbhiiiiiiii",
      "gggggbbhiiiiiiii",
      "gggggbbhiiiiiiii",
      "gggggbbhiiiiiiii"
    ],
    [
      "vvvvvvvvvvvvvvvv",
      "aaaaabbbbbbbbbbb",
      "jjjjjjjjbbbbbbbb",
      "jjjjjjjjbbbbbbbb",
      "jjjjjjjjbbbbbbbb",
      "jjjjjjjjbbbbbbbb",
      "jjjjjjjjbbbbbbbb",
      "jjjjjjjjbbbbbbbb",
      "jjjjjjjjbbbbbbbb",
      "jjjjjjjjbbbbbbbb",
      "jjjjjjjjbbbbbbbb",
      "jjjjjjjjbbbbbbbb",
      "jjjjjjjjbbbbbbbb",
      "jjjjjjjjbbbbbbbb",
      "jjjjjjjjbbbbbbbb",
      "jjjjjjjjbbbbbbbb"
    ]
  ]
}