{
  "name": "multi_gallery_8_ground",
  "refpalette": "deceasedcraft:multi_gallery_8/multi_gallery_8_ground_palette",
  "xsize": 16,
  "zsize": 16,
  "slices": [
    [
      "aaaaaaaaaaaaaaaa",
      "babababababaaaaa",
      "babababababaaaaa",
      "babababababaaaaa",
      "babababababaaaaa",
      "babababababaaaaa",
      "babababababaaaaa",
      "babababababaaaaa",
      "babababababaaaaa",
      "babababababaaaaa",
      "babababababaaaaa",
      "aacababababaaaaa",
      "aaaaaacababaaaaa",
      "aaaaaaaaaacaaaaa",
      "aaaaaaaaaaaaaaaa",
      "daaaaaaaaaaaaaaa"
    ],
    [
      "                ",
      "e     e         ",
      "                ",
      "                ",
      "                ",
      "                ",
      "                ",
      "                ",
      "                ",
      "                ",
      "                ",
      "                ",
      "                ",
      "                ",
      "                ",
      "                "
    ],
    [
      "                ",
      "f     f         ",
      "                ",
      "                ",
      "                ",
      "                ",
      "                ",
      "                ",
      "                ",
      "                ",
      "                ",
      "                ",
      "                ",
      "                ",
      "                ",
      "                "
    ],
    [
      "                ",
      "g     g         ",
      "      g         ",
      "                ",
      "                ",
      "                ",
      "                ",
      "                ",
      "                ",
      "                ",
      "                ",
      "                ",
      "                ",
      "                ",
      "                ",
      "                "
    ],
    [
      "      g         ",
      "gg    gg        ",
      "g     g         ",
      "                ",
      "                ",
      "                ",
      "                ",
      "                ",
      "                ",
      "                ",
      "                ",
      "                ",
      "                ",
      "                ",
      "                ",
      "                "
    ],
    [
      "g               ",
      "gg   ggg        ",
      "g               ",
      "                ",
      "                ",
      "                ",
      "                ",
      "                ",
      "                ",
      "                ",
      "                ",
      "                ",
      "                ",
      "                ",
      "                ",
      "      h         "
    ]
  ]
}