{
  "name": "multi_casino_1_base4",
  "refpalette": "deceasedcraft:multi_casino_1/multi_casino_1_base4_palette",
  "xsize": 16,
  "zsize": 16,
  "slices": [
    [
      "vaabcdefffffffff",
      "vaabcdefffffffff",
      "vaabcdefffffffff",
      "vaabgdefffffffff",
      "vaabcdefffffffff",
      "vaabcdefffffffff",
      "vaabcdefffffffff",
      "vaabcdefhfffffff",
      "vaabcdefffffffff",
      "vaabcdefffffffff",
      "vaabcdefffffffff",
      "vaabgdefffffffff",
      "vaabcdefffffffff",
      "vaabcdefffffffff",
      "vaabcdefffffffff",
      "vaabcdefffffffff"
    ],
    [
      "vaabi    j      ",
      "vaabi   kllm    ",
      "vaabi   knllm  m",
      "vaabgo  pnllm  m",
      "vaabi   knllm  m",
      "vaabi   kllm    ",
      "vaabi    q      ",
      "vaabi   hr      ",
      "vaabi    j      ",
      "vaabi   kllm    ",
      "vaabi   knllm  m",
      "vaabgo  pnllm  m",
      "vaabi   knllm  m",
      "vaabi   kllm    ",
      "vaabi    q      ",
      "vaabi           "
    ],
    [
      "vaabi           ",
      "vaabi           ",
      "vaabi    s      ",
      "vaabg    t      ",
      "vaabi           ",
      "vaabi           ",
      "vaabi           ",
      "vaabi   h       ",
      "vaabi           ",
      "vaabi           ",
      "vaabi           ",
      "vaabg    s      ",
      "vaabi    u      ",
      "vaabi           ",
      "vaabi           ",
      "vaabi           "
    ],
    [
      "vaabi           ",
      "vaabi           ",
      "vaabi           ",
      "vaabg           ",
      "vaabi           ",
      "vaabi           ",
      "vaabi           ",
      "vaabi   h       ",
      "vaabi           ",
      "vaabi           ",
      "vaabi           ",
      "vaabg           ",
      "vaabi           ",
      "vaabi           ",
      "vaabi           ",
      "vaabi           "
    ],
    [
      "vaabi           ",
      "vaabi           ",
      "vaabi           ",
      "vaabg           ",
      "vaabi           ",
      "vaabi           ",
      "vaabi           ",
      "vaabi   h       ",
      "vaabi           ",
      "vaabi           ",
      "vaabi           ",
      "vaabg           ",
      "vaabi           ",
      "vaabi           ",
      "vaabi           ",
      "vaabi           "
    ],
    [
      "vaabi           ",
      "vaab            ",
      "vaabi           ",
      "vaabg           ",
      "vaabi           ",
      "vaabi           ",
      "vaabi           ",
      "vaabi   h       ",
      "vaabi           ",
      "vaabi           ",
      "vaabi           ",
      "vaabg           ",
      "vaabi           ",
      "vaabi           ",
      "vaabi           ",
      "vaabi           "
    ]
  ]
}