{
  "name": "multi_casino_1_base9",
  "refpalette": "deceasedcraft:multi_casino_1/multi_casino_1_base9_palette",
  "xsize": 16,
  "zsize": 16,
  "slices": [
    [
      "vaaaaaaabbbbbbbb",
      "vaaaaaaabbbbbbbb",
      "vaaaaaaabbbbbbbb",
      "vaaaaaaabbbbbbbb",
      "vaaaaaaabbbbbbbb",
      "vaaaaaaabbbbbbbb",
      "vaaaaaaabbbbbbbb",
      "vaaaaaaabbbbbbbb",
      "vaaaaaaabbbbbbbb",
      "vaaaaaaabbbbbbbb",
      "vaaaaaaabbbbbbbb",
      "vaaaaaaabbbbbbbb",
      "vaaaaaaabbbbbbbb",
      "vaaaaaaabbbbbbbb",
      "vaaaaaaabbbbbbbb",
      "vaaaaaaabbbbbbbb"
    ],
    [
      "vaaaaaaaaaaaaaaa",
      "vaaaaaaaaaaaaaaa",
      "vaaaaaaaaaaaaaaa",
      "vaaaaaaaaaaaaaaa",
      "vaaaaaaaaaaaaaaa",
      "vaaaaaaaaaaaaaaa",
      "vaaaaaaaaaaaaaaa",
      "vaaaaaaacaaaaaaa",
      "vaaaaaaaaaaaaaaa",
      "vaaaaaaaaaaaaddd",
      "vaaaaaaadddddddd",
      "vaaaaaaadddddddd",
      "vaaaaaaadddddddd",
      "vaaaaaaadddddddd",
      "vaaaaaaadddddddd",
      "vaaaaaaadddddddd"
    ],
    [
      "vaaaaaaaaaaaaaaa",
      "vaaaaaaaaaaaaaaa",
      "vaaaaaaaaaaaaaaa",
      "vaaaaaaaaaaaaaaa",
      "vaaaaaaaaaaaaaaa",
      "vaaaaaaaaaaaaaaa",
      "vaaaaaaaaaaaaaaa",
      "vaaaaaaacaaaaaaa",
      "vaaaaaaaaaaaaaaa",
      "vaaaaaaaaaaaaddd",
      "vaaaaaaadddddddd",
      "vaaaaaaadddddddd",
      "vaaaaaaadddddddd",
      "vaaaaaaadddddddd",
      "vaaaaaaadddddddd",
      "vaaaaaaadddddddd"
    ],
    [
      "vaaaaaaaaaaaaaaa",
      "vaaaaaaaaaaaaaaa",
      "vaaaaaaaaaaaaaaa",
      "vaaaaaaaaaaaaaaa",
      "vaaaaaaaaaaaaaaa",
      "vaaaaaaaaaaaaaaa",
      "vaaaaaaaaaaaaaaa",
      "vaaaaaaacaaaaaaa",
      "vaaaaaaaaaaaaaaa",
      "vaaaaaaaaaaaaddd",
      "vaaaaaaadddddddd",
      "vaaaaaaadddddddd",
      "vaaaaaaadddddddd",
      "vaaaaaaadddddddd",
      "vaaaaaaadddddddd",
      "vaaaaaaadddddddd"
    ],
    [
      "vaaaaaaaaaaaaaaa",
      "vaaaaaaaaaaaaaaa",
      "vaaaaaaaaaaaaaaa",
      "vaaaaaaaaaaaaaaa",
      "vaaaaaaaaaaaaaaa",
      "vaaaaaaaaaaaaaaa",
      "vaaaaaaaaaaaaaaa",
      "vaaaaaaacaaaaaaa",
      "vaaaaaaaaaaaaaaa",
      "vaaaaaaaaaaaaddd",
      "vaaaaaaadddddddd",
      "vaaaaaaadddddddd",
      "vaaaaaaadddddddd",
      "vaaaaaaadddddddd",
      "vaaaaaaadddddddd",
      "vaaaaaaadddddddd"
    ],
    [
      "vaaaaaaaaaaaaaac",
      "vaaaaaaaaaaaaaca",
      "vaaaaaaaaaaaacaa",
      "vaaaaaaaaaaacaaa",
      "vaaaaaaaaaacaaaa",
      "vaaaaaaaaacaaaaa",
      "vaaaaaaaacaaaaaa",
      "vaaaaaaacaaaaaaa",
      "vaaaaaaaacaaaaaa",
      "vaaaaaaaaacaaddd",
      "vaaaaaaadddcdddd",
      "vaaaaaaaddddcddd",
      "vaaaaaaadddddcdd",
      "vaaaaaaaddddddcd",
      "vaaaaaaadddddddc",
      "vaaaaaaadddddddd"
    ]
  ]
}