{
  "name": "multi_casino_1_base1",
  "refpalette": "deceasedcraft:multi_casino_1/multi_casino_1_base1_palette",
  "xsize": 16,
  "zsize": 16,
  "slices": [
    [
      "vaab            ",
      "vaab            ",
      "vaabc           ",
      "vaabd           ",
      "vaabc           ",
      "vaab            ",
      "vaab            ",
      "vaabc   e       ",
      "vaab            ",
      "vaabc           ",
      "vaabc           ",
      "vaabd           ",
      "vaabc           ",
      "vaabc           ",
      "vaab            ",
      "vaabc           "
    ],
    [
      "vaab            ",
      "vaab            ",
      "vaab            ",
      "vaabd           ",
      "vaab            ",
      "vaab            ",
      "vaab            ",
      "vaab    e       ",
      "vaab            ",
      "vaab            ",
      "vaabc           ",
      "vaabd           ",
      "vaabc           ",
      "vaab            ",
      "vaab            ",
      "vaab            "
    ],
    [
      "vaab            ",
      "vaab            ",
      "vaab            ",
      "vaabd           ",
      "vaab            ",
      "vaab            ",
      "vaab    f       ",
      "vaab    eg      ",
      "vaab    h       ",
      "vaab            ",
      "vaab            ",
      "vaabd           ",
      "vaab            ",
      "vaab            ",
      "vaab            ",
      "vaab            "
    ],
    [
      "vaab            ",
      "vaab            ",
      "vaab            ",
      "vaabd           ",
      "vaab            ",
      "vaab            ",
      "vaab            ",
      "vaab    e       ",
      "vaab            ",
      "vaab            ",
      "vaab            ",
      "vaabd           ",
      "vaab            ",
      "vaab            ",
      "vaab            ",
      "vaab            "
    ],
    [
      "vaab iiiiiiiiiij",
      "vaab iiiiiiiiiji",
      "vaab iiiiiiiijii",
      "vaabdiiikiiikiii",
      "vaab jiiiiijiiii",
      "vaab ijiiijiiiii",
      "vaab iijijiiiiii",
      "vaab iiieiiikiii",
      "vaab iijijiiiiii",
      "vaab ijiiijiiiii",
      "vaab jiiiiijiiii",
      "vaabdiiikiiikiii",
      "vaab iiiiiiiijii",
      "vaab iiiiiiiiiji",
      "vaab iiiiiiiiiij",
      "vaab iiikiiikiii"
    ],
    [
      "vaablmnnnnnnnnne",
      "vaablmnnnnnnnnen",
      "vaablmnnnnnnnenn",
      "vaabdnnnonnnennn",
      "vaablennnnnennnn",
      "vaablmennnennnnn",
      "vaablmnenennnnnn",
      "vaablmnnennnonnn",
      "vaablmnenennnnnn",
      "vaablmennnennnnn",
      "vaablennnnnennnn",
      "vaabdnnnonnnennn",
      "vaablmnnnnnnnenn",
      "vaablmnnnnnnnnen",
      "vaablmnnnnnnnnne",
      "vaablmnnonnnonnn"
    ]
  ]
}