{
  "name": "multi_casino_1_base6",
  "refpalette": "deceasedcraft:multi_casino_1/multi_casino_1_base6_palette",
  "xsize": 16,
  "zsize": 16,
  "slices": [
    [
      "vaabcdefffffffff",
      "vaabcdefffffffff",
      "vaabcdefffffffff",
      "vaabgdefffffffff",
      "vaabcdefffffffff",
      "vaabcdefffffffff",
      "vaabcdefffffffff",
      "vaabcdefhfffffff",
      "vaabcdefffffffff",
      "vaabcdefffffffff",
      "vaabcdefffffffff",
      "vaabgdefffffffff",
      "vaabcdefffffffff",
      "vaabcdefffffffff",
      "vaabcdefffffffff",
      "vaabcdefffffffff"
    ],
    [
      "vaabi      j    ",
      "vaabi      k    ",
      "vaabi    lmmml  ",
      "vaabgn   lompl  ",
      "vaabi    lpmol  ",
      "vaabi    lmmml q",
      "vaabi     rrr   ",
      "vaabi   hqr!rs  ",
      "vaabi     rrr   ",
      "vaabi    lmmml  ",
      "vaabi    lompl  ",
      "vaabgn   lpmol  ",
      "vaabi    lmmml  ",
      "vaabi      j    ",
      "vaabi      k    ",
      "vaabi    lmmml  "
    ],
    [
      "vaabi           ",
      "vaabi           ",
      "vaabi           ",
      "vaabg           ",
      "vaabi           ",
      "vaabi           ",
      "vaabi     t u   ",
      "vaabi   h  w    ",
      "vaabi     x y   ",
      "vaabi           ",
      "vaabi           ",
      "vaabg           ",
      "vaabi           ",
      "vaabi           ",
      "vaabi           ",
      "vaabi           "
    ],
    [
      "vaabi           ",
      "vaabi           ",
      "vaabi           ",
      "vaabg           ",
      "vaabi           ",
      "vaabi           ",
      "vaabi           ",
      "vaabi   h       ",
      "vaabi           ",
      "vaabi           ",
      "vaabi           ",
      "vaabg           ",
      "vaabi           ",
      "vaabi           ",
      "vaabi           ",
      "vaabi           "
    ],
    [
      "vaabi           ",
      "vaabi           ",
      "vaabi           ",
      "vaabg           ",
      "vaabi           ",
      "vaabi           ",
      "vaabi           ",
      "vaabi   h       ",
      "vaabi           ",
      "vaabi           ",
      "vaabi           ",
      "vaabg           ",
      "vaabi           ",
      "vaabi           ",
      "vaabi           ",
      "vaabi           "
    ],
    [
      "vaabi           ",
      "vaab            ",
      "vaabi           ",
      "vaabg           ",
      "vaabi           ",
      "vaabi           ",
      "vaabi           ",
      "vaabi   h       ",
      "vaabi           ",
      "vaabi           ",
      "vaabi           ",
      "vaabg           ",
      "vaabi           ",
      "vaabi           ",
      "vaabi           ",
      "vaabi           "
    ]
  ]
}