{
  "name": "multi_casino_1_base8",
  "refpalette": "deceasedcraft:multi_casino_1/multi_casino_1_base8_palette",
  "xsize": 16,
  "zsize": 16,
  "slices": [
    [
      "vaabcdeddddddddd",
      "vaabcdeddddddddd",
      "vaabcdeddddddddd",
      "vaabfdeddddddddd",
      "vaabcdeddddddddd",
      "vaabcdeddddddddd",
      "vaabcdeddddddddd",
      "vaabcdedgdddddde",
      "vaabcdedddddeeee",
      "vaabcdeeeeeeehhh",
      "vaabcdehhhhhhhhh",
      "vaabfdehhhhhhhhh",
      "vaabcdehhhhhhhhh",
      "vaabcdehhhhhhhhh",
      "vaabcdehhhhhhhhh",
      "vaabcdehhhhhhhhh"
    ],
    [
      "vaabi  jdddddddd",
      "vaabi  jdddddddd",
      "vaabi  kdddddddd",
      "vaabfl  dddddddd",
      "vaabi   dddddddd",
      "vaabi   ddddddmm",
      "vaabi   ddddmmm ",
      "vaabi   gmmmm   ",
      "vaabi           ",
      "vaabi           ",
      "vaabi     n   n ",
      "vaabfl   opq opq",
      "vaabi     r   r ",
      "vaabi           ",
      "vaabi   s   s  t",
      "vaabi  tuw tuw  "
    ],
    [
      "vaabi           ",
      "vaabi    x y    ",
      "vaabi           ",
      "vaabf           ",
      "vaabi           ",
      "vaabi           ",
      "vaabi           ",
      "vaabi   g       ",
      "vaabi           ",
      "vaabi           ",
      "vaabi           ",
      "vaabf     A     ",
      "vaabi           ",
      "vaabi           ",
      "vaabi           ",
      "vaabi   B   B   "
    ],
    [
      "vaabi           ",
      "vaabi           ",
      "vaabi           ",
      "vaabf           ",
      "vaabi           ",
      "vaabi           ",
      "vaabi           ",
      "vaabi   g       ",
      "vaabi           ",
      "vaabi           ",
      "vaabi           ",
      "vaabf           ",
      "vaabi           ",
      "vaabi           ",
      "vaabi           ",
      "vaabi           "
    ],
    [
      "vaabi           ",
      "vaabi           ",
      "vaabi           ",
      "vaabf           ",
      "vaabi           ",
      "vaabi           ",
      "vaabi           ",
      "vaabi   g       ",
      "vaabi           ",
      "vaabi           ",
      "vaabi           ",
      "vaabf           ",
      "vaabi           ",
      "vaabi           ",
      "vaabi           ",
      "vaabi           "
    ],
    [
      "vaabi           ",
      "vaab            ",
      "vaabi           ",
      "vaabf           ",
      "vaabi           ",
      "vaabi           ",
      "vaabi           ",
      "vaabi   g       ",
      "vaabi           ",
      "vaabi           ",
      "vaabi           ",
      "vaabf           ",
      "vaabi           ",
      "vaabi           ",
      "vaabi           ",
      "vaabi           "
    ]
  ]
}