{
  "name": "multi_casino_1_base7",
  "refpalette": "deceasedcraft:multi_casino_1/multi_casino_1_base7_palette",
  "xsize": 16,
  "zsize": 16,
  "slices": [
    [
      "vaab            ",
      "vaab            ",
      "vaabc           ",
      "vaabd           ",
      "vaabc           ",
      "vaab            ",
      "vaab            ",
      "vaabc   ef      ",
      "vaab            ",
      "vaabc           ",
      "vaabc           ",
      "vaabd           ",
      "vaabc           ",
      "vaabc           ",
      "vaab            ",
      "vaabc           "
    ],
    [
      "vaab           g",
      "vaab            ",
      "vaab            ",
      "vaabd           ",
      "vaab            ",
      "vaab            ",
      "vaab     h      ",
      "vaab    ei      ",
      "vaab     j      ",
      "vaab            ",
      "vaabc           ",
      "vaabd           ",
      "vaabc           ",
      "vaab            ",
      "vaab            ",
      "vaab            "
    ],
    [
      "vaab           k",
      "vaab            ",
      "vaab            ",
      "vaabd           ",
      "vaab            ",
      "vaab            ",
      "vaab     h      ",
      "vaab    el      ",
      "vaab     j      ",
      "vaab            ",
      "vaab            ",
      "vaabd           ",
      "vaab            ",
      "vaab            ",
      "vaab            ",
      "vaab            "
    ],
    [
      "vaab           k",
      "vaab            ",
      "vaab            ",
      "vaabd           ",
      "vaab            ",
      "vaab            ",
      "vaab            ",
      "vaab    em      ",
      "vaab            ",
      "vaab            ",
      "vaab            ",
      "vaabd           ",
      "vaab            ",
      "vaab            ",
      "vaab            ",
      "vaab            "
    ],
    [
      "vaab nnnnno    p",
      "vaab nnnnnoo  q ",
      "vaab nnnnnno q  ",
      "vaabdnnnrnnos   ",
      "vaab onnnnnoooo ",
      "vaab nonnnonnnoo",
      "vaab nnononnnnnn",
      "vaab nnnennnrnnn",
      "vaab nnononnnnnn",
      "vaab nonnnonnnnn",
      "vaab onnnnnonnnn",
      "vaabdnnnrnnnrnnn",
      "vaab nnnnnnnnonn",
      "vaab nnnnnnnnnon",
      "vaab nnnnnnnnnno",
      "vaab nnnrnnnrnnn"
    ],
    [
      "vaabtuwwwwwpxxxe",
      "vaabtuwwwwwwxxex",
      "vaabtuwwwwwwxexx",
      "vaabdwwwpwwwexxx",
      "vaabtewwwwwewwwp",
      "vaabtuewwwewwwww",
      "vaabtuwewewwwwww",
      "vaabtuwwewwwpwww",
      "vaabtuwewewwwwww",
      "vaabtuewwwewwwww",
      "vaabtewwwwwewwww",
      "vaabdwwwpwwwewww",
      "vaabtuwwwwwwweww",
      "vaabtuwwwwwwwwew",
      "vaabtuwwwwwwwwwe",
      "vaabtuwwpwwwpwww"
    ]
  ]
}