{
  "name": "multi_casino_1_base2",
  "refpalette": "deceasedcraft:multi_casino_1/multi_casino_1_base2_palette",
  "xsize": 16,
  "zsize": 16,
  "slices": [
    [
      "vaabcdefffffffff",
      "vaabcdefffffffff",
      "vaabcdefffffffff",
      "vaabgdefffffffff",
      "vaabcdefffffffff",
      "vaabcdefffffffff",
      "vaabcdefffffffff",
      "vaabcdefhfffffff",
      "vaabcdefffffffff",
      "vaabcdefffffffff",
      "vaabcdefffffffff",
      "vaabgdefffffffff",
      "vaabcdefffffffff",
      "vaabcdefffffffff",
      "vaabcdefffffffff",
      "vaabcdefffffffff"
    ],
    [
      "vaabi     j     ",
      "vaabi     k     ",
      "vaabi     k     ",
      "vaabgl    m    n",
      "vaabi   kopq k  ",
      "vaabi     j    n",
      "vaabi    k      ",
      "vaabi   hr     n",
      "vaabi           ",
      "vaabi   kopsqk  ",
      "vaabi           ",
      "vaabgl  kopsqk  ",
      "vaabi           ",
      "vaabi   kopsqk  ",
      "vaabi           ",
      "vaabi   kopsq k "
    ],
    [
      "vaabi     t     ",
      "vaabi           ",
      "vaabi           ",
      "vaabg     u     ",
      "vaabi    wsx    ",
      "vaabi     t     ",
      "vaabi           ",
      "vaabi   h       ",
      "vaabi     y     ",
      "vaabi    ABBC   ",
      "vaabi     yD    ",
      "vaabg    ABBC   ",
      "vaabi     yD    ",
      "vaabi    ABBC   ",
      "vaabi     yD    ",
      "vaabi    ABBC   "
    ],
    [
      "vaabi     E     ",
      "vaabi           ",
      "vaabi           ",
      "vaabg     F     ",
      "vaabi    IsJ    ",
      "vaabi     E     ",
      "vaabi           ",
      "vaabi   h       ",
      "vaabi           ",
      "vaabi    wKLx   ",
      "vaabi           ",
      "vaabg    wKLx   ",
      "vaabi           ",
      "vaabi    wKLx   ",
      "vaabi           ",
      "vaabi    wKLx   "
    ],
    [
      "vaabi     M     ",
      "vaabi           ",
      "vaabi           ",
      "vaabg     N     ",
      "vaabi    O P    ",
      "vaabi     M     ",
      "vaabi           ",
      "vaabi   h       ",
      "vaabi           ",
      "vaabi     QR    ",
      "vaabi           ",
      "vaabg     QR    ",
      "vaabi           ",
      "vaabi     QR    ",
      "vaabi           ",
      "vaabi     QR    "
    ],
    [
      "vaabi           ",
      "vaab            ",
      "vaabi           ",
      "vaabg           ",
      "vaabi     S     ",
      "vaabi           ",
      "vaabi           ",
      "vaabi   h       ",
      "vaabi           ",
      "vaabi           ",
      "vaabi           ",
      "vaabg           ",
      "vaabi           ",
      "vaabi           ",
      "vaabi           ",
      "vaabi           "
    ]
  ]
}