{
  "name": "multi_casino_1_ground",
  "refpalette": "deceasedcraft:multi_casino_1/multi_casino_1_ground_palette",
  "xsize": 16,
  "zsize": 16,
  "slices": [
    [
      "HHHHabccdccccccc",
      "HHHHabccdccccccc",
      "HHHHabccdccccccc",
      "HHHHabccdccccccc",
      "HHHHabbbbbbbbbbb",
      "HHHHabeeeeeeeeee",
      "HHcccbefffffffff",
      "HHccgbefhfffffff",
      "HHcccbefffffffff",
      "HHHHabefffffffff",
      "HHHHabefffffffff",
      "HHHHabefffffffff",
      "HHHHabefffffffff",
      "HHHHabefffffffff",
      "HHHHabefffffffff",
      "HHHHabefffffffff"
    ],
    [
      "     ij         ",
      "  kl ij         ",
      "     ij         ",
      "     ij         ",
      "   m iiiiiiiiiii",
      "  no i          ",
      "  pppq          ",
      "  prsq  h       ",
      "  pppq     tuw t",
      "  xy i          ",
      "     i   A      ",
      "     i   B      ",
      "     i   C      ",
      "  kl i          ",
      "     i   A      ",
      "     i   B      "
    ],
    [
      "                ",
      "                ",
      "                ",
      "                ",
      "                ",
      "                ",
      "        h       ",
      "   Ds   Eh      ",
      "    ~   h       ",
      "                ",
      "                ",
      "                ",
      "                ",
      "                ",
      "                ",
      "                "
    ],
    [
      "                ",
      "                ",
      "                ",
      "                ",
      "                ",
      "        h       ",
      "                ",
      "    s     h     ",
      "    ~           ",
      "        h       ",
      "                ",
      "                ",
      "                ",
      "                ",
      "                ",
      "                "
    ],
    [
      "                ",
      "                ",
      "                ",
      "                ",
      "                ",
      "        h       ",
      "                ",
      "    s     h     ",
      "    ~           ",
      "        h       ",
      "                ",
      "                ",
      "                ",
      "                ",
      "                ",
      "                "
    ],
    [
      "                ",
      "                ",
      "                ",
      "                ",
      "        h       ",
      "                ",
      "                ",
      "    s      h    ",
      "    ~           ",
      "                ",
      "        h       ",
      "                ",
      "                ",
      "                ",
      "                ",
      "                "
    ]
  ]
}