{
  "name": "multi_alienresearch_13_base3",
  "refpalette": "deceasedcraft:multi_alienresearch_13/multi_alienresearch_13_base3_palette",
  "xsize": 16,
  "zsize": 16,
  "slices": [
    [
      "aaaaaaaaaaaaaaav",
      "aaaaaaaaaaaaaaav",
      "aaaaaaaaaaaaaaav",
      "aaaaaaaaaaaaaaav",
      "aaaaaaaaaaaaaaav",
      "bbbbbbbbbbbbbbbv",
      "cdddddddddddddbv",
      "cdddddddddddddbv",
      "cdddddddddddddbv",
      "cdddddddddddddbv",
      "edddddddddddddbv",
      "cdddddddddddddbv",
      "cdddddddddddddbv",
      "cdddddddddddddbv",
      "cdddddddddddddbv",
      "bbbbbbbbbbbbbbbv"
    ],
    [
      "aaaaaaaaaaaaaaav",
      "aaaaaaaaaaaaaaav",
      "aaaaaaaaaaaaaaav",
      "aaaaaaaaaaaaaaav",
      "aaaaaaaaaaaaaaav",
      "bbbbbbbbbbbbbbbv",
      "f  g g ! g  hibv",
      "             jbv",
      "    k k k    lbv",
      "   mnnnnno   pbv",
      "q rpssssst   pbv",
      "   uwwwwwx   pbv",
      "    y y y    lbv",
      "             Abv",
      "f  g g g g  hibv",
      "bbbbbbbbbbbbbbbv"
    ],
    [
      "aaaaaaaaaaaaaaav",
      "aaaaaaaaaaaaaaav",
      "aaaaaaaaaaaaaaav",
      "aaaaaaaaaaaaaaav",
      "aaaaaaaaaaaaaaav",
      "bbbbbbbbbbbbbbbv",
      "   BCBCBCD   Ebv",
      "              bv",
      "             Fbv",
      "    I J I     bv",
      "   I         Kbv",
      "      I J    Lbv",
      "              bv",
      "              bv",
      "   MCMCMCN   Ebv",
      "bbbbbbbbbbbbbbbv"
    ],
    [
      "aaaaaaaaaaaaaaav",
      "aaaaaaaaaaaaaaav",
      "aaaaaaaaaaaaaaav",
      "aaaaaaaaaaaaaaav",
      "aaaaaaaaaaaaaaav",
      "bbbbbbbbbbbbbbbv",
      "             ibv",
      "              bv",
      "              Ov",
      "              Ov",
      "              Ov",
      "              Ov",
      "              Ov",
      "              bv",
      "             ibv",
      "bbbbbbbbbbbbbbbv"
    ],
    [
      "aaaaaaaaaaaaaaav",
      "aaaaaaaaaaaaaaav",
      "aaaaaaaaaaaaaaav",
      "aaaaaaaaaaaaaaav",
      "aaaaaaaaaaaaaaav",
      "bbbbbbbbbbbbbbbv",
      "              bv",
      "              bv",
      "              Ov",
      "              Ov",
      "              Ov",
      "              Ov",
      "              Ov",
      "              bv",
      "              bv",
      "bbbbbbbbbbbbbbbv"
    ],
    [
      "aaaaaaaaaaaaaaav",
      "aaaaaaaaaaaaaaav",
      "aaaaaaaaaaaaaaav",
      "aaaaaaaaaaaaaaav",
      "aaaaaaaaaaaaaaav",
      "bbbbbbbbbbbbbbbv",
      "              bv",
      "              bv",
      "              Ov",
      "              Ov",
      "           P  Ov",
      "              Ov",
      "              Ov",
      "              bv",
      "              bv",
      "bbbbbbbbbbbbbbbv"
    ]
  ]
}