{
  "name": "multi_alienresearch_13_base10",
  "refpalette": "deceasedcraft:multi_alienresearch_13/multi_alienresearch_13_base10_palette",
  "xsize": 16,
  "zsize": 16,
  "slices": [
    [
      "aaaaaaaaaaaaaaav",
      "aaaaaaaaaaaaaaav",
      "aaaaaaaaaaaaaaav",
      "aaaaaaaaaaaaaaav",
      "aaaaaaaaaaaaaaav",
      "aaaaaaaaaaaaaaav",
      "aaaaaaaaaaaaaaav",
      "aaaaaaaaaaaaaaav",
      "aaaaaaaaaaaaaaav",
      "aaaaaaaaaaaaaaav",
      "aaaaaaaaaaaaaaav",
      "aaaaaaaaaaaaaaav",
      "aaaaaaaaaaaaaaav",
      "aaaaaaaaaaaaaaav",
      "aaaaaaaaaaaaaaav",
      "aaaaaaaaaaaaaaav"
    ],
    [
      "aaaaaaaaaaaaaaav",
      "aaaaaaaaaaaaaaav",
      "aaaaaaaaaaaaaaav",
      "aaaaaaaaaaaaaaav",
      "aaaaaaaaaaaaaaav",
      "aaaaaaaaaaaaaaav",
      "aaaaaaaaaaaaaaav",
      "aaaaaaaaaaaaaaav",
      "aaaaaaaaaaaaaaav",
      "aaaaaaaaaaaaaaav",
      "aaaaaaaaaaaaaaav",
      "aaaaaaaaaaaaaaav",
      "aaaaaaaaaaaaaaav",
      "aaaaaaaaaaaaaaav",
      "aaaaaaaaaaaaaaav",
      "aaaaaaaaaaaaaaav"
    ],
    [
      "aaaaaaaaaaaaaaav",
      "aaaaaaaaaaaaaaav",
      "aaaaaaaaaaaaaaav",
      "aaaaaaaaaaaaaaav",
      "aaaaaaaaaaaaaaav",
      "aaaaaaaaaaaaaaav",
      "aaaaaaaaaaaaaaav",
      "aaaaaaaaaaaaaaav",
      "aaaaaaaaaaaaaaav",
      "aaaaaaaaaaaaaaav",
      "aaaaaaaaaaaaaaav",
      "aaaaaaaaaaaaaaav",
      "aaaaaaaaaaaaaaav",
      "aaaaaaaaaaaaaaav",
      "aaaaaaaaaaaaaaav",
      "aaaaaaaaaaaaaaav"
    ],
    [
      "aaaaaaaaaaaaaaav",
      "aaaaaaaaaaaaaaav",
      "aaaaaaaaaaaaaaav",
      "aaaaaaaaaaaaaaav",
      "aaaaaaaaaaaaaaav",
      "aaaaaaaaaaaaaaav",
      "aaaaaaaaaaaaaaav",
      "aaaaaaaaaaaaaaav",
      "aaaaaaaaaaaaaaav",
      "aaaaaaaaaaaaaaav",
      "aaaaaaaaaaaaaaav",
      "aaaaaaaaaaaaaaav",
      "aaaaaaaaaaaaaaav",
      "aaaaaaaaaaaaaaav",
      "aaaaaaaaaaaaaaav",
      "aaaaaaaaaaaaaaav"
    ],
    [
      "aaaaaaaaaaaaaaav",
      "aaaaaaaaaaaaaaav",
      "aaaaaaaaaaaaaaav",
      "aaaaaaaaaaaaaaav",
      "aaaaaaaaaaaaaaav",
      "aaaaaaaaaaaaaaav",
      "aaaaaaaaaaaaaaav",
      "aaaaaaaaaaaaaaav",
      "aaaaaaaaaaaaaaav",
      "aaaaaaaaaaaaaaav",
      "aaaaaaaaaaaaaaav",
      "aaaaaaaaaaaaaaav",
      "aaaaaaaaaaaaaaav",
      "aaaaaaaaaaaaaaav",
      "aaaaaaaaaaaaaaav",
      "aaaaaaaaaaaaaaav"
    ],
    [
      "aaaaaaaaaaaaaaav",
      "aaaaaaaaaaaaaaav",
      "aaaaaaaaaaaaaaav",
      "aaaaaaaaaaaaaaav",
      "aaaaaaaaaaaaaaav",
      "aaaaaaaaaaaaaaav",
      "aaaaaaaaaaaaaaav",
      "aaaaaaaaaaaaaaav",
      "aaaaaaaaaaaaaaav",
      "aaaaaaaaaaaaaaav",
      "aaaaaaaaaaaaaaav",
      "aaaaaaaaaaaaaaav",
      "aaaaaaaaaaaaaaav",
      "aaaaaaaaaaaaaaav",
      "aaaaaaaaaaaaaaav",
      "aaaaaaaaaaaaaaav"
    ]
  ]
}