{
  "name": "multi_alienresearch_13_base6",
  "refpalette": "deceasedcraft:multi_alienresearch_13/multi_alienresearch_13_base6_palette",
  "xsize": 16,
  "zsize": 16,
  "slices": [
    [
      "abbbbbbbbbbbbbbv",
      " abbbbbbbbbbbbbv",
      " abbbbbbbbbbbbbv",
      " abbbbbbbbbbbbbv",
      "  abbbbcccccbbbv",
      "  abbbbcdedcbbbv",
      "  fbbbbcccccbbbv",
      "  ffccccccccccgv",
      " dffccccccccccgv",
      " dffccccccccccgv",
      " dhfccccccccccgv",
      " dffccccccccccgv",
      " dffccccccccccgv",
      " dffccccccccccgv",
      " dffccccccccccgv",
      " dffccccccccccgv"
    ],
    [
      "abbbbbbbbbbbbbbv",
      " abbbbbbbbbbbbbv",
      " abbbbbbbbbbbbbv",
      " abbbbbbbbbbbbbv",
      "  abbbbcccccbbbv",
      "  ffccccdedcccgv",
      " dffccccccccccgv",
      " dffccccccccccgv",
      "   i j        gv",
      "   i kl       gv",
      "   i m        gv",
      "   i k        gv",
      "   i n        gv",
      "   i          gv",
      "   i         ogv",
      "   i    p    ogv"
    ],
    [
      " abbbbbbbbbbbbbv",
      " abbbbbbbbbbbbbv",
      " abbbbbbbbbbbbbv",
      "  abbbbbbbbbbbbv",
      "  fbbbbcccccbbbv",
      " dffcccc q cccgv",
      " dff          gv",
      "   i          gv",
      "   r          gv",
      "   r s        gv",
      "   r t        gv",
      "   r u        gv",
      "   r          gv",
      "   r          gv",
      "   r         wgv",
      "   r         wgv"
    ],
    [
      " abbbbbbbbbbbbbv",
      " abbbbbbbbbbbbbv",
      "  abbbbbbbbbbbbv",
      "  abbbbbbbbbbbbv",
      "  ffccccccccccgv",
      " dffcccc   cccgv",
      "   x   y   y  gv",
      "   r          gv",
      "   r          gv",
      "   r          gv",
      "   r          gv",
      "   r          gv",
      "   r          gv",
      "   r          gv",
      "   r         wgv",
      "   r         Agv"
    ],
    [
      " abbbbbbbbbbbbbv",
      " abbbbbbbbbbbbbv",
      "  abbbbbbbbbbbbv",
      "  fbbbbbbbbbbbbv",
      " dffcccccBccccgv",
      "   x   C   C  gv",
      "   r          gv",
      "   r          gv",
      "   r          gv",
      "   r          gv",
      "   r          gv",
      "   r          gv",
      "   r          gv",
      "   r          gv",
      "   r         Dgv",
      "   r         Egv"
    ],
    [
      " fbbbbbbbbbbbbbv",
      " fbbbbbbbbbbbbbv",
      "  fbbbbbbbbbbbbv",
      "  fbbbbbbbbbbbbv",
      " dffccccBcBcccgv",
      "   x   C   C  gv",
      "   r          gv",
      "   r          gv",
      "   r          gv",
      "   r          gv",
      "   r          gv",
      "   r          gv",
      "   r          gv",
      "   r          gv",
      "   r          gv",
      "   r          gv"
    ]
  ]
}