{
  "name": "multi_alienresearch_13_base5",
  "refpalette": "deceasedcraft:multi_alienresearch_13/multi_alienresearch_13_base5_palette",
  "xsize": 16,
  "zsize": 16,
  "slices": [
    [
      "abcccccccccccccv",
      "abcccccccccccccv",
      " abccccccccccccv",
      " abccccccccccccv",
      " adbeeeefeeeeegv",
      "   h   i   i  gv",
      "   j          gv",
      "   j          gv",
      "   j          gv",
      "   j          gv",
      "   j          gv",
      "   j          gv",
      "   j          gv",
      "   j          gv",
      "   j          gv",
      "   j          gv"
    ],
    [
      " bcccccccccccccv",
      " bcccccccccccccv",
      "  bccccccccccccv",
      "  bccccccccccccv",
      " abbeeeeeffeeegv",
      "   h   i   i  gv",
      "   j          gv",
      "   j          gv",
      "   j          gv",
      "   j          gv",
      "   j          gv",
      "   j          gv",
      "   j          gv",
      "   j          gv",
      "   j          gv",
      "   j          gv"
    ],
    [
      " kcccccccccccccv",
      " kcccccccccccccv",
      "  kccccccccccccv",
      "  bccccccccccccv",
      " abbeeeeeeeeeegv",
      "   h   i   i  gv",
      "   j          gv",
      "   j          gv",
      "   j          gv",
      "   j          gv",
      "   j          gv",
      "   j          gv",
      "   j          gv",
      "   j          gv",
      "   j          gv",
      "   j          gv"
    ],
    [
      " kcccccccccccccv",
      " kcccccccccccccv",
      "  kccccccccccccv",
      "  kccccccccccccv",
      "  bbeeeeeeeeeegv",
      " abbeeeeeeeeeegv",
      "   h          gv",
      "   j          gv",
      "   j          gv",
      "   j          gv",
      "   j          gv",
      "   j          gv",
      "   j          gv",
      "   j          gv",
      "   j          gv",
      "   j          gv"
    ],
    [
      " kcccccccccccccv",
      " kcccccccccccccv",
      " kcccccccccccccv",
      "  kccccccccccccv",
      "  bccccccccccccv",
      " abbeeeeeeeeeegv",
      " abb          gv",
      "   l          gv",
      "   j          gv",
      "   j          gv",
      "   j          gv",
      "   j          gv",
      "   j          gv",
      "   j          gv",
      "   j          gv",
      "   j          gv"
    ],
    [
      "kccccccccccccccv",
      " kcccccccccccccv",
      " kcccccccccccccv",
      " kcccccccccccccv",
      "  kccccccccccccv",
      "  bbeeeeeeeeeegv",
      " abbeeeeeeeeeegv",
      " abbeeeeeeeeeegv",
      "   l          gv",
      "   l          gv",
      "   l   mmmmm  gv",
      "   l          gv",
      "   l          gv",
      "   l          gv",
      "   l          gv",
      "   l   mmmmm  gv"
    ]
  ]
}