{
  "name": "multi_alienresearch_13_base7",
  "refpalette": "deceasedcraft:multi_alienresearch_13/multi_alienresearch_13_base7_palette",
  "xsize": 16,
  "zsize": 16,
  "slices": [
    [
      "aaaaaaaaaaabccbv",
      "aaaaaaaaaaab  bv",
      "aaaaaaaaaaab  bv",
      "aaaaaaaaaaab  bv",
      "bbbbbbbbdddb  bv",
      "effffffdghgdiijv",
      "efffffffffffffbv",
      "efffffffffffffbv",
      "efffffffffffffbv",
      "kkkkkkkkkkkkkkbv",
      "lkkkkkkkkkkkkkbv",
      "kkkkkkkkkkkkkkbv",
      "efffffffffffffbv",
      "efffffffffffffbv",
      "efffffffffffffbv",
      "efffffffffffffbv"
    ],
    [
      "aaaaaaaaaaab  bv",
      "aaaaaaaaaaab  bv",
      "aaaaaaaaaaab  bv",
      "aaaaaaaaaaab  bv",
      "eaaaaaaddddbiibv",
      "eaaaaaadghgdaaav",
      "eaaaaaadddddaaav",
      "eaaaaaaaaaaaaaav",
      "eaaaaaaaaaaaaaav",
      "kaaaaaaaaaaaaaav",
      "kaaaaaaaaaaaaaav",
      "kaaaaaaaaaaaaaav",
      "eaaaaaaaaaaaaaav",
      "eaaaaaaaaaaaaaav",
      "eaaaaaaaaaaaaaav",
      "eaaaaaaaaaaaaaav"
    ],
    [
      "aaaaaaaaaaab  bv",
      "aaaaaaaaaaab  bv",
      "eaaaaaaaaaab  bv",
      "eaaaaaaaaaabiibv",
      "eaaaaaadddddaaav",
      "eaaaaaadghgdaaav",
      " eaaaaadddddaaav",
      " eaaaaaaaaaaaaav",
      " eaaaaaaaaaaaaav",
      " kaaaaaaaaaaaaav",
      "gkaaaaaaaaaaaaav",
      " kaaaaaaaaaaaaav",
      " eaaaaaaaaaaaaav",
      " eaaaaaaaaaaaaav",
      " eaaaaaaaaaaaaav",
      "eaaaaaaaaaaaaaav"
    ],
    [
      "aaaaaaaaaaab  bv",
      "eaaaaaaaaaab  bv",
      "eaaaaaaaaaabiibv",
      "eaaaaaaaaaaaaaav",
      " eaaaaadddddaaav",
      " eaaaaadghgdaaav",
      " eaaaaadddddaaav",
      " eaaaaaaaaaaaaav",
      " eaaaaaaaaaaaaav",
      " kaaaaaaaaaaaaav",
      "gkaaaaaaaaaaaaav",
      " kaaaaaaaaaaaaav",
      " eaaaaaaaaaaaaav",
      " eaaaaaaaaaaaaav",
      " eaaaaaaaaaaaaav",
      " eaaaaaaaaaaaaav"
    ],
    [
      "eaaaaaaaaaab  bv",
      "eaaaaaaaaaabiibv",
      "eaaaaaaaaaaaaaav",
      " eaaaaaaaaaaaaav",
      " eaaaaadddddaaav",
      " eaaaaadghgdaaav",
      " eaaaaadddddaaav",
      "  eaaaaaaaaaaaav",
      "  eaaaaaaaaaaaav",
      "  kaaaaaaaaaaaav",
      " gkaaaaaaaaaaaav",
      "  kaaaaaaaaaaaav",
      "  eaaaaaaaaaaaav",
      "  eaaaaaaaaaaaav",
      " eaaaaaaaaaaaaav",
      " eaaaaaaaaaaaaav"
    ],
    [
      "eaaaaaaaaaabiibv",
      "eaaaaaaaaaaaaaav",
      " eaaaaaaaaaaaaav",
      " eaaaaaaaaaaaaav",
      " eaaaaadddddaaav",
      " eaaaaadghgdaaav",
      "  eaaaadddddaaav",
      "  eaaaaaaaaaaaav",
      "  kaaaaaaaaaaaav",
      "  kaaaaaaaaaaaav",
      " gkaaaaaaaaaaaav",
      "  kaaaaaaaaaaaav",
      "  kaaaaaaaaaaaav",
      "  kaaaaaaaaaaaav",
      "  kaaaaaaaaaaaav",
      " kaaaaaaaaaaaaav"
    ]
  ]
}