{
  "name": "multi_alienresearch_13_ground",
  "refpalette": "deceasedcraft:multi_alienresearch_13/multi_alienresearch_13_ground_palette",
  "xsize": 16,
  "zsize": 16,
  "slices": [
    [
      "avaavaaavaaaazzz",
      "aaavzavaazvaabbz",
      "aaaaaaaaaaaabazz",
      "bvvavvazvvavazbz",
      "vavvvvbvvvvaabzz",
      "vvvvvvvvvazvabzz",
      "vbvvvvavvbvvabzz",
      "vvvvvavvavvabazz",
      "vvvvvvvvvvvvabzz",
      "vvzvvvvvzvvavbbz",
      "vvvvzvvvvvvvazzz",
      "vvvvvvvvvvvvvbzz",
      "cccccccccccvabbz",
      "ddefgfzfgecaabzz",
      "ddcfggggfgcvaazz",
      "ddcggffgffcabbzz"
    ],
    [
      "   hieiieij  kl ",
      "    miiiim   k  ",
      "     nnnn    k l",
      "             k  ",
      "             k  ",
      "             k  ",
      "             kl ",
      "             k  ",
      "             kl ",
      "        l    k  ",
      "             kl ",
      "             k  ",
      "  ooooooooo  k l",
      "pqr   s  ro  k  ",
      "   t      o  k  ",
      "          o  kl "
    ],
    [
      "             k  ",
      "             k  ",
      "             k  ",
      "             k  ",
      "             k  ",
      "             k  ",
      "             k  ",
      "             k  ",
      "             k  ",
      "             k  ",
      "             k  ",
      "             k  ",
      "  uwwxwuwxw  k  ",
      "pqr  y   rw  k  ",
      "          w  k  ",
      "         Aw  k  "
    ],
    [
      "             k  ",
      "             k  ",
      "             k  ",
      "             k  ",
      "             k  ",
      "             k  ",
      "             k  ",
      "             k  ",
      "             k  ",
      "             k  ",
      "             k  ",
      "             k  ",
      "  uww wuwww  k  ",
      "pqr yy   rw  k  ",
      "          w  k  ",
      "          w  k  "
    ],
    [
      "             B  ",
      "             B  ",
      "             B  ",
      "             B  ",
      "             B  ",
      "             B  ",
      "             B  ",
      "             B  ",
      "             B  ",
      "             B  ",
      "             B  ",
      "             B  ",
      "   wwuwuwwu  B  ",
      "pqr  y yyrw  B  ",
      "          w     ",
      "         Au  B  "
    ],
    [
      "                ",
      "                ",
      "                ",
      "                ",
      "                ",
      "                ",
      "                ",
      "                ",
      "                ",
      "                ",
      "                ",
      "                ",
      "  wwwCwwwwu     ",
      "pqr   Drrrw     ",
      "         Dw     ",
      "         DCE    "
    ]
  ]
}