{
  "name": "multi_alienresearch_13_base8",
  "refpalette": "deceasedcraft:multi_alienresearch_13/multi_alienresearch_13_base8_palette",
  "xsize": 16,
  "zsize": 16,
  "slices": [
    [
      "aaaaaaaaaaaaaaav",
      "aaaaaaaaaaaaaaav",
      "aaaaaaaaaaaaaaav",
      "aaaaaaaaaaaaaaav",
      "bbbbbbbbccccaaav",
      "dddddddcdddcaaav",
      "ddddddddddddddbv",
      "ddddddddddddddbv",
      "ddddddddddddddbv",
      "ddddddddddddddbv",
      "ddddddddddddddbv",
      "ddddddddddddddbv",
      "ddddddddddddddbv",
      "ddddddddddddddbv",
      "ddddddddddddddbv",
      "ddddddddddddddbv"
    ],
    [
      "aaaaaaaaaaaaaaav",
      "aaaaaaaaaaaaaaav",
      "aaaaaaaaaaaaaaav",
      "aaaaaaaaaaaaaaav",
      "bbbbbbbbccccaaav",
      "ecffcggchihcjjkv",
      "lcmmc         bv",
      " c  c         bv",
      "nc  c         bv",
      " o  p         bv",
      "  qr          bv",
      " o  p      stubv",
      "nc  cccc   cccbv",
      " c  cw x   y Abv",
      "lcBBcC c   c Dbv",
      "ecffc  cEEEc  bv"
    ],
    [
      "aaaaaaaaaaaaaaav",
      "aaaaaaaaaaaaaaav",
      "aaaaaaaaaaaaaaav",
      "aaaaaaaaaaaaaaav",
      "bbbbbbbbcccbjjbv",
      " cffc  chihc  Fv",
      " cmmc        Ibv",
      " c  cJ        bv",
      " c  c         bv",
      " o  p         bv",
      "  KL          bv",
      " o  p       MNbv",
      " c  cccc   cccbv",
      " c  c  O   P  bv",
      " cBBcQ c   c Rbv",
      " cffcS c   c Tbv"
    ],
    [
      "aaaaaaaaaaaaaaav",
      "aaaaaaaaaaaaaaav",
      "aaaaaaaaaaaaaaav",
      "aaaaaaaaaaabjjbv",
      "bbbbbbbbcccb  bv",
      " c!fcUUchihc  Fv",
      " cmmc         bv",
      " c  c         bv",
      " c  c         bv",
      " o  p         bv",
      " o  p         bv",
      " o  p         bv",
      " c  cccc   cccbv",
      " c  c  c   c  bv",
      " cBBc  c   c  bv",
      "VcffcW cXYZc 0bv"
    ],
    [
      "aaaaaaaaaaaaaaav",
      "aaaaaaaaaaaaaaav",
      "aaaaaaaaaaabjjbv",
      "aaaaaaaaaaab  bv",
      "bbbbbbbbcccb  bv",
      " c  c !chihc  Fv",
      " c  c         bv",
      " c  c         bv",
      " c  c         bv",
      " c  c         bv",
      "hc  c1        bv",
      " c  c         bv",
      " c  ccccccccccbv",
      " c  c  c   c  bv",
      " c  c  c   c  bv",
      " c  c  c   c  bv"
    ],
    [
      "aaaaaaaaaaaaaaav",
      "aaaaaaaaaaabjjbv",
      "aaaaaaaaaaab  bv",
      "aaaaaaaaaaab  bv",
      "bbbbbbbbcccb  bv",
      "234435 chihc  Fv",
      "6c  c         bv",
      "6c  c         bv",
      "6c  c         bv",
      "7c  c         bv",
      "7c  c         bv",
      "7c  c         bv",
      "6c  ccccccccccbv",
      "6c  c  c   c  bv",
      "6c  c  c   c  bv",
      "23883383333383bv"
    ]
  ]
}