{
  "name": "multi_alienresearch_13_base4",
  "refpalette": "deceasedcraft:multi_alienresearch_13/multi_alienresearch_13_base4_palette",
  "xsize": 16,
  "zsize": 16,
  "slices": [
    [
      "abbbbbbbbbbbbbbv",
      " abbbbbbbbbbbbbv",
      " abbbbbbbbbbbbbv",
      " abbbbbbbbbbbbbv",
      "  abbbbbbbbbbbbv",
      "  abbbbbbbbbbbbv",
      "  cbbbbbbbbbbbbv",
      "  ccddddddddddev",
      " fccddddddddddev",
      " fccddddddddddev",
      " fgcddddddddddev",
      " fccddddddddddev",
      " fccddddddddddev",
      " fccddddddddddev",
      " fccddddddddddev",
      " fccddddddddddev"
    ],
    [
      "abbbbbbbbbbbbbbv",
      "abbbbbbbbbbbbbbv",
      " abbbbbbbbbbbbbv",
      " abbbbbbbbbbbbbv",
      " abbbbbbbbbbbbbv",
      " abbbbbbbbbbbbbv",
      "  abbbbbbbbbbbbv",
      "  abbbbbbbbbbbbv",
      "  cbbbbbbbbbbbbv",
      "  cbbbbbbbbbbbbv",
      " fcbbbbbbbbbbbbv",
      "  cbbbbbbbbbbbbv",
      "  cbbbbbbbbbbbbv",
      "  cbbbbbbbbbbbbv",
      "  cbbbbbbbbbbbbv",
      " cbbbbbbbbbbbbbv"
    ],
    [
      "abbbbbbbbbbbbbbv",
      "abbbbbbbbbbbbbbv",
      "abbbbbbbbbbbbbbv",
      " abbbbbbbbbbbbbv",
      " abbbbbbbbbbbbbv",
      " abbbbbbbbbbbbbv",
      " abbbbbbbbbbbbbv",
      "  abbbbbbbbbbbbv",
      "  abbbbbbbbbbbbv",
      "  cbbbbbbbbbbbbv",
      " fcbbbbbbbbbbbbv",
      "  cbbbbbbbbbbbbv",
      "  abbbbbbbbbbbbv",
      "  abbbbbbbbbbbbv",
      " abbbbbbbbbbbbbv",
      " abbbbbbbbbbbbbv"
    ],
    [
      "bbbbbbbbbbbbbbbv",
      "abbbbbbbbbbbbbbv",
      "abbbbbbbbbbbbbbv",
      "abbbbbbbbbbbbbbv",
      " abbbbbbbbbbbbbv",
      " abbbbbbbbbbbbbv",
      " abbbbbbbbbbbbbv",
      " abbbbbbbbbbbbbv",
      " abbbbbbbbbbbbbv",
      " cbbbbbbbbbbbbbv",
      "fcbbbbbbbbbbbbbv",
      " cbbbbbbbbbbbbbv",
      " abbbbbbbbbbbbbv",
      " abbbbbbbbbbbbbv",
      " abbbbbbbbbbbbbv",
      " abbbbbbbbbbbbbv"
    ],
    [
      "bbbbbbbbbbbbbbbv",
      "bbbbbbbbbbbbbbbv",
      "abbbbbbbbbbbbbbv",
      "abbbbbbbbbbbbbbv",
      "abbbbbbbbbbbbbbv",
      "abbbbbbbbbbbbbbv",
      " abbbbbbbbbbbbbv",
      " abbbbbbbbbbbbbv",
      " abbbbbbbbbbbbbv",
      " cbbbbbbbbbbbbbv",
      "fcbbbbbbbbbbbbbv",
      " cbbbbbbbbbbbbbv",
      " abbbbbbbbbbbbbv",
      " abbbbbbbbbbbbbv",
      " abbbbbbbbbbbbbv",
      "abbbbbbbbbbbbbbv"
    ],
    [
      "bbbbbbbbbbbbbbbv",
      "bbbbbbbbbbbbbbbv",
      "bbbbbbbbbbbbbbbv",
      "bbbbbbbbbbbbbbbv",
      "abbbbbbbbbbbbbbv",
      "abbbbbbbbbbbbbbv",
      "abbbbbbbbbbbbbbv",
      "abbbbbbbbbbbbbbv",
      "abbbbbbbbbbbbbbv",
      "cbbbbbbbbbbbbbbv",
      "cbbbbbbbbbbbbbbv",
      "cbbbbbbbbbbbbbbv",
      "abbbbbbbbbbbbbbv",
      "abbbbbbbbbbbbbbv",
      "abbbbbbbbbbbbbbv",
      "abbbbbbbbbbbbbbv"
    ]
  ]
}