{
  "name": "multi_cabin3_0_floor1",
  "refpalette": "deceasedcraft:multi_cabin3_0/multi_cabin3_0_floor1_palette",
  "xsize": 16,
  "zsize": 16,
  "slices": [
    [
      "aaaaaaaaaababbab",
      "aaaaaaaaaaabbabb",
      "aaaaaaaaaabbacab",
      "aaaaddddaaabaadd",
      "aaaaddefaabbaadg",
      "aaaaadffaabaaadg",
      "aaaaddddaaabaadd",
      "aaaaaadaaabbacab",
      "aaaaaaaaaaabaabb",
      "aaaaaaaaabbbbbab",
      "aaaahaaaaabbaaab",
      "aaaahhaaaaabaaaa",
      "aaaahhhaaabaaaab",
      "aaaaaaaaaaaaahaa",
      "aaaaaaaaaaabaaaa",
      "aaaaaaaaabaaaaaa"
    ],
    [
      "iiiiiiiiiiiiiiii",
      "iiiiiiiiiiiiiiii",
      "iiijjjjjjiiiicki",
      "iiljiiiljiiiikmn",
      "iiijiiopjiiiiiqi",
      "iiijiiirjiiiiiqi",
      "iiljsiiljiiiikmt",
      "iiijiiiijiiiicki",
      "iiijiiiijiiiijii",
      "iiijiiiijiiiiuii",
      "iiijviiijiiiijii",
      "iiijwwiijiiiijxi",
      "iiijwwwijiiiijyi",
      "iizjjjjjjiiiicjj",
      "iiiiiiiiiiiiiiii",
      "iiiiiiiiiiiiiiii"
    ],
    [
      "iiiiiiiiiiiiiiii",
      "iiiiiiiiiiiiiiii",
      "iiiiiiiiiiiiicii",
      "iiliiiiliiiiiimA",
      "iiiiiiiiiiiiiiqi",
      "iiiiiiiBiiiiiiqi",
      "iiliiiiliiiiiimC",
      "iiiiiiiiiiiiicii",
      "iiiiiiiiiiiiiiii",
      "iiiiiiiiiiiiiiii",
      "iiiiiiiiiiiiiiii",
      "iiiiiiiiiiiiiiii",
      "iiiiwwiiiiiiiiii",
      "iiiiiiiiiiiiiDii",
      "iiiiiiiiiiiiiiii",
      "iiiiiiiiiiiiiiii"
    ],
    [
      "iiiiiiiiiiiiiiii",
      "iiiiiiiiiiiiiiii",
      "iiiiiiiiiiiiicii",
      "iiliiiiliiiiiimm",
      "iiiiiiiiiiiiiiqi",
      "iiiiiiiiiiiiiiqi",
      "iiliEiiliiiiiimm",
      "iiiiiiiiiiiiicii",
      "iiiiiiiiiiiiiiii",
      "iiiiiiiiiiiiiiii",
      "iiiiiiiiiiiiiiii",
      "iiiiiiiiiiiiiiii",
      "iiiiiiiiiiiiiiii",
      "iiiiiiiiiiiiiiii",
      "iiiiiiiiiiiiiiii",
      "iiiiiiiiiiiiiiii"
    ],
    [
      "iiiiiiiiiiiiiiii",
      "iiiiiiiiiiiiiiiF",
      "iiiiiiiiiiiiiciF",
      "iGGGGGGGGGGGGGHH",
      "iGGGGGGGGGGGGGHI",
      "iGGGGGGGGGGGGGHI",
      "iGGGGGGGGGGGGGHH",
      "iiiiiiiiiiiiiciF",
      "iiiiiiiiiiiiiiiF",
      "iiiiiiiiiiiiiiii",
      "iiiiiiiiiiiiiiii",
      "iiiiiiiiiiiiiiii",
      "iiiiiiiiiiiiiiii",
      "iiiiiiiiiiiiiiii",
      "iiiiiiiiiiiiiiii",
      "iiiiiiiiiiiiiiii"
    ],
    [
      "iiiiiiiiiiiiiiii",
      "iiiiiiiiiiFFJKKi",
      "iiiiiiiiiiFFJKKi",
      "iiiiiiiiiiFFLMMi",
      "iiiiiiiiiiFFLMMi",
      "iiiiiiiiiiFFLMMi",
      "iiiiiiiiiiFFLMMi",
      "iiiiiiiiiiFFJKKi",
      "iiiiiiiiiiFFJKKi",
      "iiiiiiiiiiiiiiii",
      "iiiiiiiiiiiiiiii",
      "iiiiiiiiiiiiiiii",
      "iiiiiiiiiiiiiiii",
      "iiiiiiiiiiiiiiii",
      "iiiiiiiiiiiiiiii",
      "iiiiiiiiiiiiiiii"
    ]
  ]
}