{
  "name": "building_office2a_ground",
  "refpalette": "deceasedcraft:building_office2a/building_office2a_ground_palette",
  "xsize": 16,
  "zsize": 16,
  "slices": [
    [
      "aaaaaaaaaaaaaaaa",
      "aaabbbbbbbbbbaaa",
      "aabbbbbbbbbbbbaa",
      "abbbbcaaaaaaabba",
      "abbbbbaaaaaaabba",
      "abbbbbbbbbbbbbba",
      "abbddddddddddbba",
      "abbddddddddddbba",
      "abbddddddddddbba",
      "abbddddddddddbba",
      "abbddddddddddbba",
      "abbddddddddddbba",
      "abbddddddddddbba",
      "aabbbbbbbbbbbbaa",
      "aaabbbbbbbbbbaaa",
      "aaaaaaaaaaaaaaaa"
    ],
    [
      "                ",
      "  ef ff  ff fe  ",
      " gfhihhiihhihfj ",
      " fh        kkhf ",
      "  i  lm    n i  ",
      " fh  oooooooohf ",
      " fh          hp ",
      "  i          qr ",
      "  i          sr ",
      " fh   t  t   he ",
      " fh uwwwwwwu hf ",
      "  i x y  y A i  ",
      " fhBC      DEhf ",
      " gfhihhiihhihfj ",
      "  pf ff  ff fp  ",
      "                "
    ],
    [
      "                ",
      "  ef ff  ff fe  ",
      " gfhihhiihhihfj ",
      " fh          hf ",
      "  i   lm   F i  ",
      " fh  IIIIIIIIhf ",
      " fh          hp ",
      "  i          J  ",
      "  i          K  ",
      " fh          he ",
      " fh L M  M N hf ",
      "  i          i  ",
      " fhO        Ohf ",
      " gfhihhiihhihfj ",
      "  pf ff  ff fp  ",
      "                "
    ],
    [
      "                ",
      "  ef ff  ff fe  ",
      " gfhihhiihhihfj ",
      " fh    Pm    hf ",
      "  i    lm    i  ",
      " fh  QQQQQQQQhf ",
      " fh          hp ",
      "  i     R    i  ",
      "  i          i  ",
      " fh          he ",
      " fh          hf ",
      "  i          i  ",
      " fhS        Shf ",
      " gfhihhiihhihfj ",
      "  pf ff  ff fp  ",
      "                "
    ],
    [
      "                ",
      "  efTffTTffTfe  ",
      " gfhhhhhhhhhhfj ",
      " fh   PcUVVVVhf ",
      " Wh     UVVVVhW ",
      " fhXXXXXXXXXXYf ",
      " fh          hZ ",
      " Wh    0R    hW ",
      " Wh    10    hW ",
      " fh          hT ",
      " fh          hf ",
      " Wh          hW ",
      " fh          hf ",
      " gfhhhhhhhhhhfj ",
      "  pfWffWWffWfp  ",
      "                "
    ],
    [
      "                ",
      "  effffffffffe  ",
      " gfhhhhhhfffffj ",
      " fff Pc 2ffffff ",
      " ff     2ffffff ",
      " ffXXXXXXXXXfff ",
      " ff3333333333ff ",
      " ff3333443333ff ",
      " ff3333443333ff ",
      " ff3333333333ff ",
      " ff3333333333ff ",
      " ff3333333333ff ",
      " ff3333333333ff ",
      " gffffffffffffj ",
      "  pffffffffffp  ",
      "                "
    ]
  ]
}