{
  "name": "building_office2a_top_90",
  "refpalette": "deceasedcraft:building_office2a/building_office2a_top_palette_90",
  "xsize": 16,
  "zsize": 16,
  "slices": [
    [
      "                ",
      "                ",
      "     ijmmjjmji  ",
      "     jhhhhhhhj  ",
      "  acajkkkkkkhn  ",
      "  agbjkkkkkkhj  ",
      "  bbbhkkkkkkhj  ",
      "  affhkkkkkkhn  ",
      "  a  hkkkkkkhn  ",
      "  a  hkkkkkkhj  ",
      "  be hkkkkkkhj  ",
      "  adhhkkkkkkhn  ",
      "  acajhhhhhhhj  ",
      "     ijlljjlji  ",
      "                ",
      "                "
    ],
    [
      "                ",
      "                ",
      "     ijBBjjBji  ",
      "     jA     Oj  ",
      "  acajy  K   B  ",
      "  aprjxEIIIM j  ",
      "  bo t       j  ",
      "  affj       B  ",
      "  a  jwDFJ   B  ",
      "  a  juCuCL  j  ",
      "  b qj       j  ",
      "  a  s       B  ",
      "  acaj      Nj  ",
      "     ijBBjjBji  ",
      "                ",
      "                "
    ],
    [
      "                ",
      "                ",
      "     ijBBjjBji  ",
      "     jV     1j  ",
      "  acajU      B  ",
      "  a  jTWXYZ0 j  ",
      "  b PR       j  ",
      "  affj       B  ",
      "  a  j!      B  ",
      "  a qjSSSSL  j  ",
      "  b  j       j  ",
      "  a  Q       B  ",
      "  acaj      1j  ",
      "     ijBBjjBji  ",
      "                ",
      "                "
    ],
    [
      "                ",
      "                ",
      "     ijBBjjBji  ",
      "     j      4j  ",
      "  acaj       B  ",
      "  a 2j       j  ",
      "  b  3       j  ",
      "  affj       B  ",
      "  a qj       B  ",
      "  a  jSSSSL  j  ",
      "  b  j       j  ",
      "  a  3       B  ",
      "  acaj      4j  ",
      "     ijBBjjBji  ",
      "                ",
      "                "
    ],
    [
      "                ",
      "                ",
      "     ijBBjjBji  ",
      "     j       j  ",
      "  acaj       B  ",
      "  a67j       j  ",
      "  b55j       j  ",
      "  afqj       B  ",
      "  a  j       B  ",
      "  a  j   8   j  ",
      "  b  j       j  ",
      "  a  j       B  ",
      "  acaj       j  ",
      "     ijBBjjBji  ",
      "                ",
      "                "
    ],
    [
      "                ",
      "                ",
      "     ijBBjjBji  ",
      "     j       j  ",
      "  amaj       B  ",
      "  a#%j       j  ",
      "  b9$j   ^   j  ",
      "  af j       B  ",
      "  a  j       B  ",
      "  a  j   ^   j  ",
      "  b  j       j  ",
      "  a  j       B  ",
      "  acaj       j  ",
      "     ijBBjjBji  ",
      "                ",
      "                "
    ],
    [
      "                ",
      "                ",
      "     ijBBjjBji  ",
      "     j       j  ",
      "  aaaj       B  ",
      "  a  j       j  ",
      "  b%&j   *   j  ",
      "  af j       B  ",
      "  a  j       B  ",
      "  a  j   *   j  ",
      "  b  j       j  ",
      "  a  j       B  ",
      "  alaj       j  ",
      "     ijBBjjBji  ",
      "                ",
      "                "
    ],
    [
      "                ",
      "                ",
      "     ijBBjjBji  ",
      "     j       j  ",
      "  (aaj       B  ",
      "  (  j       j  ",
      "  )++j   *   j  ",
      "  (f-j       B  ",
      "  (  j       B  ",
      "  (  j   *   j  ",
      "  )  j       j  ",
      "  (  j       B  ",
      "  (aaj       j  ",
      "     ijBBjjBji  ",
      "                ",
      "                "
    ],
    [
      "                ",
      "                ",
      "     ijmmjjmji  ",
      "     j       j  ",
      "   (aj       n  ",
      "   ([j       j  ",
      "   )[j   ]   j  ",
      "   (aj       n  ",
      "   (aj       n  ",
      "   (aj   ]   j  ",
      "   )bj       j  ",
      "   (aj       n  ",
      "   (aj       j  ",
      "     ijlljjlji  ",
      "                ",
      "                "
    ],
    [
      "                ",
      "                ",
      "     ijjjjjjji  ",
      "     jhhhhhhhj  ",
      "    (jh{{{{{hj  ",
      "    (jh{{{{{hj  ",
      "    )jh{{{{{hj  ",
      "    (jh{{{{{hj  ",
      "    (jh{{{{{hj  ",
      "    (jh{{{{{hj  ",
      "    )jh{{{{{hj  ",
      "    (jh{{{{{hj  ",
      "    (jhhhhhhhj  ",
      "     ijjjjjjji  ",
      "                ",
      "                "
    ],
    [
      "                ",
      "                ",
      "     ijjjjjjji  ",
      "     j}}}}}}}j  ",
      "     j}}}}}}}j  ",
      "     j}}}}}}}j  ",
      "     j}}}}}}}j  ",
      "     j}}}}}}}j  ",
      "     j}}}}}}}j  ",
      "     j}}}}}}}j  ",
      "     j}}}}}}}j  ",
      "     j}}}}}}}j  ",
      "     j}}}}}}}j  ",
      "     ijjjjjjji  ",
      "                ",
      "                "
    ],
    [
      "                ",
      "                ",
      "      |||||||   ",
      "     |       |  ",
      "     |%      |  ",
      "     |;;:<   |  ",
      "     |  ;    |  ",
      "     |  ;    |  ",
      "     |;;:<   |  ",
      "     | %;    |  ",
      "     |  ;%   |  ",
      "     |;;:'   |  ",
      "     |       |  ",
      "      |||||||   ",
      "                ",
      "                "
    ]
  ]
}