{
  "name": "building_office2a_floor2",
  "refpalette": "deceasedcraft:building_office2a/building_office2a_floor2_palette",
  "xsize": 16,
  "zsize": 16,
  "slices": [
    [
      "                ",
      "                ",
      "   aabaaabaa    ",
      "   cde  fbgc    ",
      "   ahi  fbba    ",
      "  jkhhhhhhkkkj  ",
      "  khllllllllhk  ",
      "  mhllllllllhn  ",
      "  mhllllllllhn  ",
      "  khllllllllhk  ",
      "  khllllllllhk  ",
      "  mhllllllllhn  ",
      "  khhhhhhhhhhk  ",
      "  jkokkookkokj  ",
      "                ",
      "                "
    ],
    [
      "                ",
      "                ",
      "   aabaaabaa    ",
      "   c    fpqc    ",
      "   a ri f sa    ",
      "  jktkkkkukkkj  ",
      "  kw xyAB xCDk  ",
      "  E          E  ",
      "  E          E  ",
      "  kF   FF   Fk  ",
      "  kI   JI   Jk  ",
      "  EKL MNK  MNE  ",
      "  kO   POQ  Pk  ",
      "  jkEkkEEkkEkj  ",
      "                ",
      "                "
    ],
    [
      "                ",
      "                ",
      "   aabaaabaa    ",
      "   c    f  c    ",
      "   a  rif  a    ",
      "  jkRkkkkSkkkj  ",
      "  kT xUUB x Vk  ",
      "  E          E  ",
      "  E          E  ",
      "  k          k  ",
      "  kW   XW   Yk  ",
      "  EZ   0Z   0E  ",
      "  kY   12   1k  ",
      "  jkEkkEEkkEkj  ",
      "                ",
      "                "
    ],
    [
      "                ",
      "                ",
      "   aabaaabaa    ",
      "   c   dh3 c    ",
      "   a   rh34a    ",
      "  jk5kkkk5kkkj  ",
      "  k6 xUUB x78k  ",
      "  E          E  ",
      "  E          E  ",
      "  k          k  ",
      "  k          k  ",
      "  E          E  ",
      "  k          k  ",
      "  jkEkkEEkkEkj  ",
      "                ",
      "                "
    ],
    [
      "                ",
      "                ",
      "   aabaaabaa    ",
      "   c  def  c    ",
      "   a    f  a    ",
      "  jkkkkkkkkkkj  ",
      "  k   9#   $%k  ",
      "  E          E  ",
      "  E          E  ",
      "  k          k  ",
      "  k          k  ",
      "  E          E  ",
      "  k          k  ",
      "  jkEkkEEkkEkj  ",
      "                ",
      "                "
    ],
    [
      "                ",
      "                ",
      "   aabaaabaa    ",
      "   c de f^!c    ",
      "   a    f^^a    ",
      "  jkkkkkkkkkkj  ",
      "  k          k  ",
      "  E          E  ",
      "  E          E  ",
      "  k   &      k  ",
      "  k          k  ",
      "  E          E  ",
      "  k          k  ",
      "  jkEkkEEkkEkj  ",
      "                ",
      "                "
    ]
  ]
}