{
  "name": "building_office2a_floor3",
  "refpalette": "deceasedcraft:building_office2a/building_office2a_floor3_palette",
  "xsize": 16,
  "zsize": 16,
  "slices": [
    [
      "                ",
      "                ",
      "   aabaaabaa    ",
      "   cde  fbgc    ",
      "   ahi  fbba    ",
      "  jkhhhhhhkkkj  ",
      "  khllllllllhk  ",
      "  mhllllllllhn  ",
      "  mhllllllllhn  ",
      "  khllllllllhk  ",
      "  khllllllllhk  ",
      "  mhllllllllhn  ",
      "  khhhhhhhhhhk  ",
      "  jkokkookkokj  ",
      "                ",
      "                "
    ],
    [
      "                ",
      "                ",
      "   aabaaabaa    ",
      "   c    fpqc    ",
      "   a ri fsta    ",
      "  jkukkkkwkkkj  ",
      "  k! xyyA  BCk  ",
      "  D    E     D  ",
      "  D   F F F  D  ",
      "  k  IIIIII  k  ",
      "  k  IIIIII  k  ",
      "  D  J J J   D  ",
      "  kK        Lk  ",
      "  jkDkkDDkkDkj  ",
      "                ",
      "                "
    ],
    [
      "                ",
      "                ",
      "   aabaaabaa    ",
      "   c    f  c    ",
      "   a  rif  a    ",
      "  jkMkkkkNkkkj  ",
      "  k   OPQ  R k  ",
      "  D          D  ",
      "  D          D  ",
      "  k   S TUT  k  ",
      "  k  VWX Y   k  ",
      "  D          D  ",
      "  kZ        Zk  ",
      "  jkDkkDDkkDkj  ",
      "                ",
      "                "
    ],
    [
      "                ",
      "                ",
      "   aabaaabaa    ",
      "   c   dh0 c    ",
      "   a   rh01a    ",
      "  jk2kkkk2kkkj  ",
      "  k          k  ",
      "  D          D  ",
      "  D          D  ",
      "  k          k  ",
      "  k          k  ",
      "  D          D  ",
      "  k3        3k  ",
      "  jkDkkDDkkDkj  ",
      "                ",
      "                "
    ],
    [
      "                ",
      "                ",
      "   aabaaabaa    ",
      "   c  def  c    ",
      "   a    f  a    ",
      "  jkkkkkkkkkkj  ",
      "  k          k  ",
      "  D          D  ",
      "  D          D  ",
      "  k          k  ",
      "  k          k  ",
      "  D          D  ",
      "  k          k  ",
      "  jkDkkDDkkDkj  ",
      "                ",
      "                "
    ],
    [
      "                ",
      "                ",
      "   aabaaabaa    ",
      "   c de f45c    ",
      "   a    f44a    ",
      "  jkkkkkkkkkkj  ",
      "  k          k  ",
      "  D          D  ",
      "  D          D  ",
      "  k   6  6   k  ",
      "  k          k  ",
      "  D          D  ",
      "  k          k  ",
      "  jkDkkDDkkDkj  ",
      "                ",
      "                "
    ]
  ]
}