{
  "name": "building_office2a_floor1",
  "refpalette": "deceasedcraft:building_office2a/building_office2a_floor1_palette",
  "xsize": 16,
  "zsize": 16,
  "slices": [
    [
      "                ",
      "                ",
      "   aabaaabaa    ",
      "   cde  fbgc    ",
      "   ahi  fbba    ",
      "  jkhhhhhhkkkj  ",
      "  khllllllllhk  ",
      "  mhllllllllhn  ",
      "  mhllllllllhn  ",
      "  khllllllllhk  ",
      "  khllllllllhk  ",
      "  mhllllllllhn  ",
      "  khhhhhhhhhhk  ",
      "  jkokkookkokj  ",
      "                ",
      "                "
    ],
    [
      "                ",
      "                ",
      "   aabaaabaa    ",
      "   c    fpqc    ",
      "   a ri f sa    ",
      "  jktkkkkukkkj  ",
      "  kw xyAB xCDk  ",
      "  E          E  ",
      "  E          E  ",
      "  kF   FF   Fk  ",
      "  kI   JI   Jk  ",
      "  EKLM NKL MNE  ",
      "  kO   PO   Pk  ",
      "  jkEkkEEkkEkj  ",
      "                ",
      "                "
    ],
    [
      "                ",
      "                ",
      "   aabaaabaa    ",
      "   c    f  c    ",
      "   a  rif  a    ",
      "  jkQkkkkRkkkj  ",
      "  kS xT!B x Uk  ",
      "  E          E  ",
      "  E          E  ",
      "  k          k  ",
      "  kV   WV   Xk  ",
      "  EY   ZY   ZE  ",
      "  k0   12   1k  ",
      "  jkEkkEEkkEkj  ",
      "                ",
      "                "
    ],
    [
      "                ",
      "                ",
      "   aabaaabaa    ",
      "   c   dh3 c    ",
      "   a   rh34a    ",
      "  jk5kkkk5kkkj  ",
      "  k6 xTTB x78k  ",
      "  E          E  ",
      "  E          E  ",
      "  k          k  ",
      "  k          k  ",
      "  E          E  ",
      "  k          k  ",
      "  jkEkkEEkkEkj  ",
      "                ",
      "                "
    ],
    [
      "                ",
      "                ",
      "   aabaaabaa    ",
      "   c  def  c    ",
      "   a    f  a    ",
      "  jkkkkkkkkkkj  ",
      "  k   9#   $%k  ",
      "  E          E  ",
      "  E          E  ",
      "  k          k  ",
      "  k          k  ",
      "  E          E  ",
      "  k          k  ",
      "  jkEkkEEkkEkj  ",
      "                ",
      "                "
    ],
    [
      "                ",
      "                ",
      "   aabaaabaa    ",
      "   c de f^&c    ",
      "   a    f^^a    ",
      "  jkkkkkkkkkkj  ",
      "  k          k  ",
      "  E          E  ",
      "  E          E  ",
      "  k          k  ",
      "  k          k  ",
      "  E          E  ",
      "  k          k  ",
      "  jkEkkEEkkEkj  ",
      "                ",
      "                "
    ]
  ]
}