{
  "name": "building_office2a_floor3_90",
  "refpalette": "deceasedcraft:building_office2a/building_office2a_floor3_palette_90",
  "xsize": 16,
  "zsize": 16,
  "slices": [
    [
      "                ",
      "                ",
      "     jknnkknkj  ",
      "     khhhhhhhk  ",
      "  acakllllllho  ",
      "  agbkllllllhk  ",
      "  bbbhllllllhk  ",
      "  affhllllllho  ",
      "  a  hllllllho  ",
      "  a  hllllllhk  ",
      "  beihllllllhk  ",
      "  adhhllllllho  ",
      "  acakhhhhhhhk  ",
      "     jkmmkkmkj  ",
      "                ",
      "                "
    ],
    [
      "                ",
      "                ",
      "     jkDDkkDkj  ",
      "     kC     Lk  ",
      "  acakB      D  ",
      "  aqtk  FII  k  ",
      "  bpsw   IIJ k  ",
      "  affkA FII  D  ",
      "  a  kyE IIJ D  ",
      "  a iky FII  k  ",
      "  b rkx  IIJ k  ",
      "  a  u       D  ",
      "  acak!     Kk  ",
      "     jkDDkkDkj  ",
      "                ",
      "                "
    ],
    [
      "                ",
      "                ",
      "     jkDDkkDkj  ",
      "     k      Zk  ",
      "  acakR      D  ",
      "  a  k   T   k  ",
      "  b  N   UY  k  ",
      "  affkQ  T   D  ",
      "  a ikP   X  D  ",
      "  a rkO  SW  k  ",
      "  b  k    V  k  ",
      "  a  M       D  ",
      "  acak      Zk  ",
      "     jkDDkkDkj  ",
      "                ",
      "                "
    ],
    [
      "                ",
      "                ",
      "     jkDDkkDkj  ",
      "     k      3k  ",
      "  acak       D  ",
      "  a 1k       k  ",
      "  b002       k  ",
      "  ahhk       D  ",
      "  adrk       D  ",
      "  a  k       k  ",
      "  b  k       k  ",
      "  a  2       D  ",
      "  acak      3k  ",
      "     jkDDkkDkj  ",
      "                ",
      "                "
    ],
    [
      "                ",
      "                ",
      "     jkDDkkDkj  ",
      "     k       k  ",
      "  acak       D  ",
      "  a  k       k  ",
      "  b  k       k  ",
      "  affk       D  ",
      "  ae k       D  ",
      "  ad k       k  ",
      "  b  k       k  ",
      "  a  k       D  ",
      "  acak       k  ",
      "     jkDDkkDkj  ",
      "                ",
      "                "
    ],
    [
      "                ",
      "                ",
      "     jkDDkkDkj  ",
      "     k       k  ",
      "  acak       D  ",
      "  a54k       k  ",
      "  b44k   6   k  ",
      "  affk       D  ",
      "  a  k       D  ",
      "  ae k   6   k  ",
      "  bd k       k  ",
      "  a  k       D  ",
      "  acak       k  ",
      "     jkDDkkDkj  ",
      "                ",
      "                "
    ]
  ]
}