{
  "name": "building_office2a_floor1_90",
  "refpalette": "deceasedcraft:building_office2a/building_office2a_floor1_palette_90",
  "xsize": 16,
  "zsize": 16,
  "slices": [
    [
      "                ",
      "                ",
      "     jknnkknkj  ",
      "     khhhhhhhk  ",
      "  acakllllllho  ",
      "  agbkllllllhk  ",
      "  bbbhllllllhk  ",
      "  affhllllllho  ",
      "  a  hllllllho  ",
      "  a  hllllllhk  ",
      "  beihllllllhk  ",
      "  adhhllllllho  ",
      "  acakhhhhhhhk  ",
      "     jkmmkkmkj  ",
      "                ",
      "                "
    ],
    [
      "                ",
      "                ",
      "     jkEEkkEkj  ",
      "     kD  FJNPk  ",
      "  acakC    M E  ",
      "  aqskx      k  ",
      "  bp u     L k  ",
      "  affkB  FIKOE  ",
      "  a  kA  FJNPE  ",
      "  a iky      k  ",
      "  b rkx    M k  ",
      "  a  t     L E  ",
      "  acakw  FIKOk  ",
      "     jkEEkkEkj  ",
      "                ",
      "                "
    ],
    [
      "                ",
      "                ",
      "     jkEEkkEkj  ",
      "     kU   XZ1k  ",
      "  acak       E  ",
      "  a  kx      k  ",
      "  b  R       k  ",
      "  affkB   VY2E  ",
      "  a ik!   WZ1E  ",
      "  a rkT      k  ",
      "  b  kx      k  ",
      "  a  Q       E  ",
      "  acakS   VY0k  ",
      "     jkEEkkEkj  ",
      "                ",
      "                "
    ],
    [
      "                ",
      "                ",
      "     jkEEkkEkj  ",
      "     k8      k  ",
      "  acak7      E  ",
      "  a 4kx      k  ",
      "  b335       k  ",
      "  ahhkB      E  ",
      "  adrkT      E  ",
      "  a  kT      k  ",
      "  b  kx      k  ",
      "  a  5       E  ",
      "  acak6      k  ",
      "     jkEEkkEkj  ",
      "                ",
      "                "
    ],
    [
      "                ",
      "                ",
      "     jkEEkkEkj  ",
      "     k%      k  ",
      "  acak$      E  ",
      "  a  k       k  ",
      "  b  k       k  ",
      "  affk       E  ",
      "  ae k#      E  ",
      "  ad k9      k  ",
      "  b  k       k  ",
      "  a  k       E  ",
      "  acak       k  ",
      "     jkEEkkEkj  ",
      "                ",
      "                "
    ],
    [
      "                ",
      "                ",
      "     jkEEkkEkj  ",
      "     k       k  ",
      "  acak       E  ",
      "  a&^k       k  ",
      "  b^^k       k  ",
      "  affk       E  ",
      "  a  k       E  ",
      "  ae k       k  ",
      "  bd k       k  ",
      "  a  k       E  ",
      "  acak       k  ",
      "     jkEEkkEkj  ",
      "                ",
      "                "
    ]
  ]
}