{
  "name": "building_office2a_top",
  "refpalette": "deceasedcraft:building_office2a/building_office2a_top_palette",
  "xsize": 16,
  "zsize": 16,
  "slices": [
    [
      "                ",
      "                ",
      "   aabaaabaa    ",
      "   cde  fbgc    ",
      "   ah   fbba    ",
      "  ijhhhhhhjjji  ",
      "  jhkkkkkkkkhj  ",
      "  lhkkkkkkkkhm  ",
      "  lhkkkkkkkkhm  ",
      "  jhkkkkkkkkhj  ",
      "  jhkkkkkkkkhj  ",
      "  lhkkkkkkkkhm  ",
      "  jhhhhhhhhhhj  ",
      "  ijnjjnnjjnji  ",
      "                ",
      "                "
    ],
    [
      "                ",
      "                ",
      "   aabaaabaa    ",
      "   c    fopc    ",
      "   a q  f ra    ",
      "  ijsjjjjtjjji  ",
      "  j   uw  xyAj  ",
      "  B   CD  E  B  ",
      "  B   uF  I  B  ",
      "  j   CJ  IK j  ",
      "  j   L   I  j  ",
      "  B       M  B  ",
      "  jN        Oj  ",
      "  ijBjjBBjjBji  ",
      "                ",
      "                "
    ],
    [
      "                ",
      "                ",
      "   aabaaabaa    ",
      "   c    f  c    ",
      "   a  q fP a    ",
      "  ijQjjjjRjjji  ",
      "  j   S!  TUVj  ",
      "  B   S   W  B  ",
      "  B   S   X  B  ",
      "  j   S   Y  j  ",
      "  j   L   Z  j  ",
      "  B       0  B  ",
      "  j1        1j  ",
      "  ijBjjBBjjBji  ",
      "                ",
      "                "
    ],
    [
      "                ",
      "                ",
      "   aabaaabaa    ",
      "   c    f  c    ",
      "   a   qf 2a    ",
      "  ij3jjjj3jjji  ",
      "  j   S      j  ",
      "  B   S      B  ",
      "  B   S      B  ",
      "  j   S      j  ",
      "  j   L      j  ",
      "  B          B  ",
      "  j4        4j  ",
      "  ijBjjBBjjBji  ",
      "                ",
      "                "
    ],
    [
      "                ",
      "                ",
      "   aabaaabaa    ",
      "   c    f56c    ",
      "   a    q57a    ",
      "  ijjjjjjjjjji  ",
      "  j          j  ",
      "  B          B  ",
      "  B          B  ",
      "  j   8      j  ",
      "  j          j  ",
      "  B          B  ",
      "  j          j  ",
      "  ijBjjBBjjBji  ",
      "                ",
      "                "
    ],
    [
      "                ",
      "                ",
      "   aabaaabaa    ",
      "   c    f9#m    ",
      "   a     $%a    ",
      "  ijjjjjjjjjji  ",
      "  j          j  ",
      "  B          B  ",
      "  B          B  ",
      "  j   ^  ^   j  ",
      "  j          j  ",
      "  B          B  ",
      "  j          j  ",
      "  ijBjjBBjjBji  ",
      "                ",
      "                "
    ],
    [
      "                ",
      "                ",
      "   aabaaabaa    ",
      "   l    f% a    ",
      "   a     & a    ",
      "  ijjjjjjjjjji  ",
      "  j          j  ",
      "  B          B  ",
      "  B          B  ",
      "  j   *  *   j  ",
      "  j          j  ",
      "  B          B  ",
      "  j          j  ",
      "  ijBjjBBjjBji  ",
      "                ",
      "                "
    ],
    [
      "                ",
      "                ",
      "   (()((()((    ",
      "   a    f+ a    ",
      "   a    -+ a    ",
      "  ijjjjjjjjjji  ",
      "  j          j  ",
      "  B          B  ",
      "  B          B  ",
      "  j   *  *   j  ",
      "  j          j  ",
      "  B          B  ",
      "  j          j  ",
      "  ijBjjBBjjBji  ",
      "                ",
      "                "
    ],
    [
      "                ",
      "                ",
      "                ",
      "   (()((()((    ",
      "   aabaaa[[a    ",
      "  ijjjjjjjjjji  ",
      "  j          j  ",
      "  l          m  ",
      "  l          m  ",
      "  j   ]  ]   j  ",
      "  j          j  ",
      "  l          m  ",
      "  j          j  ",
      "  ijnjjnnjjnji  ",
      "                ",
      "                "
    ],
    [
      "                ",
      "                ",
      "                ",
      "                ",
      "   (()((()((    ",
      "  ijjjjjjjjjji  ",
      "  jhhhhhhhhhhj  ",
      "  jh{{{{{{{{hj  ",
      "  jh{{{{{{{{hj  ",
      "  jh{{{{{{{{hj  ",
      "  jh{{{{{{{{hj  ",
      "  jh{{{{{{{{hj  ",
      "  jhhhhhhhhhhj  ",
      "  ijjjjjjjjjji  ",
      "                ",
      "                "
    ],
    [
      "                ",
      "                ",
      "                ",
      "                ",
      "                ",
      "  ijjjjjjjjjji  ",
      "  j}}}}}}}}}}j  ",
      "  j}}}}}}}}}}j  ",
      "  j}}}}}}}}}}j  ",
      "  j}}}}}}}}}}j  ",
      "  j}}}}}}}}}}j  ",
      "  j}}}}}}}}}}j  ",
      "  j}}}}}}}}}}j  ",
      "  ijjjjjjjjjji  ",
      "                ",
      "                "
    ],
    [
      "                ",
      "                ",
      "                ",
      "                ",
      "                ",
      "   ||||||||||   ",
      "  | ;  ;  ;% |  ",
      "  | ; %;  ;  |  ",
      "  | :;;:;;:  |  ",
      "  | '% <  <  |  ",
      "  |          |  ",
      "  |          |  ",
      "  |          |  ",
      "   ||||||||||   ",
      "                ",
      "                "
    ]
  ]
}