{
  "name": "building_office2a_ground_90",
  "refpalette": "deceasedcraft:building_office2a/building_office2a_ground_palette_90",
  "xsize": 16,
  "zsize": 16,
  "slices": [
    [
      "aaaaaaaaaaaaaaaa",
      "aaabbbbbbbbbbaaa",
      "aabbbbbbbbbbbbaa",
      "abbaabdddddddbba",
      "abbaabdddddddbba",
      "abbaabdddddddbba",
      "abbaabdddddddbba",
      "abbaabdddddddbba",
      "abbaabdddddddbba",
      "abbaabdddddddbba",
      "abbcbbdddddddbba",
      "abbbbbdddddddbba",
      "abbbbbdddddddbba",
      "aabbbbbbbbbbbbaa",
      "aaabbbbbbbbbbaaa",
      "aaaaaaaaaaaaaaaa"
    ],
    [
      "                ",
      "  jf fprref fj  ",
      " efhihhqshhihfp ",
      " fhk o      Ehf ",
      "  ikno    uADi  ",
      " fh  o    w  hf ",
      " fh  o   twy hf ",
      "  i  o    w  i  ",
      "  i  o    w  i  ",
      " fh mo   twy hf ",
      " fh lo    w  hf ",
      "  i       uxCi  ",
      " fh         Bhf ",
      " efhihhiihhihfp ",
      "  gf ff  ff fg  ",
      "                "
    ],
    [
      "                ",
      "  jf fp  ef fj  ",
      " efhihhJKhhihfp ",
      " fh  I      Ohf ",
      "  i FI    N  i  ",
      " fh  I       hf ",
      " fh  I    M  hf ",
      "  i  I       i  ",
      "  i mI       i  ",
      " fh lI    M  hf ",
      " fh  I       hf ",
      "  i       L  i  ",
      " fh         Ohf ",
      " efhihhiihhihfp ",
      "  gf ff  ff fg  ",
      "                "
    ],
    [
      "                ",
      "  jf fp  ef fj  ",
      " efhihhiihhihfp ",
      " fh  Q      Shf ",
      "  i  Q       i  ",
      " fh  Q       hf ",
      " fh  Q       hf ",
      "  immQ R     i  ",
      "  iPlQ       i  ",
      " fh  Q       hf ",
      " fh  Q       hf ",
      "  i          i  ",
      " fh         Shf ",
      " efhihhiihhihfp ",
      "  gf ff  ff fg  ",
      "                "
    ],
    [
      "                ",
      "  jfWfZWWTfWfj  ",
      " efhhYhhhhhhhfp ",
      " fhVVX       hf ",
      " ThVVX       hW ",
      " fhVVX       hf ",
      " fhVVX       hf ",
      " ThUUX R0    hW ",
      " Thc X 01    hW ",
      " fhP X       hf ",
      " fh  X       hf ",
      " Th  X       hW ",
      " fh  X       hf ",
      " efhhhhhhhhhhfp ",
      "  gfWffWWffWfg  ",
      "                "
    ],
    [
      "                ",
      "  jffffffffffj  ",
      " effffffffffffp ",
      " fffff3333333ff ",
      " ffffX3333333ff ",
      " ffffX3333333ff ",
      " ffffX3333333ff ",
      " fh22X3443333ff ",
      " fh  X3443333ff ",
      " fhc X3333333ff ",
      " fhP X3333333ff ",
      " fh  X3333333ff ",
      " fhf X3333333ff ",
      " effffffffffffp ",
      "  gffffffffffg  ",
      "                "
    ]
  ]
}