{
  "name": "building_office2a_floor2_270",
  "refpalette": "deceasedcraft:building_office2a/building_office2a_floor2_palette_270",
  "xsize": 16,
  "zsize": 16,
  "slices": [
    [
      "                ",
      "                ",
      "  jkmkkmmkj     ",
      "  khhhhhhhkaca  ",
      "  ohllllllhhda  ",
      "  khllllllhieb  ",
      "  khllllllh  a  ",
      "  ohllllllh  a  ",
      "  ohllllllhffa  ",
      "  khllllllhbbb  ",
      "  khllllllkbga  ",
      "  ohllllllkaca  ",
      "  khhhhhhhk     ",
      "  jknkknnkj     ",
      "                ",
      "                "
    ],
    [
      "                ",
      "                ",
      "  jkEkkEEkj     ",
      "  kOKIF  wkaca  ",
      "  E L     t  a  ",
      "  k      xkr b  ",
      "  k M    yki a  ",
      "  EPNJF  Ak  a  ",
      "  EOKIF  Bkffa  ",
      "  kQ      u pb  ",
      "  k      xksqa  ",
      "  E M    Ckaca  ",
      "  kPNJF  Dk     ",
      "  jkEkkEEkj     ",
      "                ",
      "                "
    ],
    [
      "                ",
      "                ",
      "  jkEkkEEkj     ",
      "  kYZW   Tkaca  ",
      "  E       R  a  ",
      "  k      xk  b  ",
      "  k      Ukr a  ",
      "  E10X   Uki a  ",
      "  E2ZW   Bkffa  ",
      "  k       S  b  ",
      "  k      xk  a  ",
      "  E       kaca  ",
      "  k10Y   Vk     ",
      "  jkEkkEEkj     ",
      "                ",
      "                "
    ],
    [
      "                ",
      "                ",
      "  jkEkkEEkj     ",
      "  k      6kaca  ",
      "  E       5  a  ",
      "  k      xk  b  ",
      "  k      Uk  a  ",
      "  E      Ukrda  ",
      "  E      Bkhha  ",
      "  k       533b  ",
      "  k      xk4 a  ",
      "  E      7kaca  ",
      "  k      8k     ",
      "  jkEkkEEkj     ",
      "                ",
      "                "
    ],
    [
      "                ",
      "                ",
      "  jkEkkEEkj     ",
      "  k       kaca  ",
      "  E       k  a  ",
      "  k       k  b  ",
      "  k      9k da  ",
      "  E      #k ea  ",
      "  E       kffa  ",
      "  k       k  b  ",
      "  k       k  a  ",
      "  E      $kaca  ",
      "  k      %k     ",
      "  jkEkkEEkj     ",
      "                ",
      "                "
    ],
    [
      "                ",
      "                ",
      "  jkEkkEEkj     ",
      "  k       kaca  ",
      "  E       k  a  ",
      "  k       k db  ",
      "  k   &   k ea  ",
      "  E       k  a  ",
      "  E       kffa  ",
      "  k       k^^b  ",
      "  k       k^!a  ",
      "  E       kaca  ",
      "  k       k     ",
      "  jkEkkEEkj     ",
      "                ",
      "                "
    ]
  ]
}