{
  "name": "building_office2a_top_270",
  "refpalette": "deceasedcraft:building_office2a/building_office2a_top_palette_270",
  "xsize": 16,
  "zsize": 16,
  "slices": [
    [
      "                ",
      "                ",
      "  ijljjllji     ",
      "  jhhhhhhhjaca  ",
      "  nhkkkkkkhhda  ",
      "  jhkkkkkkh eb  ",
      "  jhkkkkkkh  a  ",
      "  nhkkkkkkh  a  ",
      "  nhkkkkkkhffa  ",
      "  jhkkkkkkhbbb  ",
      "  jhkkkkkkjbga  ",
      "  nhkkkkkkjaca  ",
      "  jhhhhhhhj     ",
      "  ijmjjmmji     ",
      "                ",
      "                "
    ],
    [
      "                ",
      "                ",
      "  ijBjjBBji     ",
      "  jN      jaca  ",
      "  B       s  a  ",
      "  j       jq b  ",
      "  j  LCuCuj  a  ",
      "  B   JFDwj  a  ",
      "  B       jffa  ",
      "  j       t ob  ",
      "  j MIIIExjrpa  ",
      "  B   K  yjaca  ",
      "  jO     Aj     ",
      "  ijBjjBBji     ",
      "                ",
      "                "
    ],
    [
      "                ",
      "                ",
      "  ijBjjBBji     ",
      "  j1      jaca  ",
      "  B       Q  a  ",
      "  j       j  b  ",
      "  j  LSSSSjq a  ",
      "  B      !j  a  ",
      "  B       jffa  ",
      "  j       RP b  ",
      "  j 0ZYXWTj  a  ",
      "  B      Ujaca  ",
      "  j1     Vj     ",
      "  ijBjjBBji     ",
      "                ",
      "                "
    ],
    [
      "                ",
      "                ",
      "  ijBjjBBji     ",
      "  j4      jaca  ",
      "  B       3  a  ",
      "  j       j  b  ",
      "  j  LSSSSj  a  ",
      "  B       jq a  ",
      "  B       jffa  ",
      "  j       3  b  ",
      "  j       j2 a  ",
      "  B       jaca  ",
      "  j4      j     ",
      "  ijBjjBBji     ",
      "                ",
      "                "
    ],
    [
      "                ",
      "                ",
      "  ijBjjBBji     ",
      "  j       jaca  ",
      "  B       j  a  ",
      "  j       j  b  ",
      "  j   8   j  a  ",
      "  B       j  a  ",
      "  B       jqfa  ",
      "  j       j55b  ",
      "  j       j76a  ",
      "  B       jaca  ",
      "  j       j     ",
      "  ijBjjBBji     ",
      "                ",
      "                "
    ],
    [
      "                ",
      "                ",
      "  ijBjjBBji     ",
      "  j       jaca  ",
      "  B       j  a  ",
      "  j       j  b  ",
      "  j   ^   j  a  ",
      "  B       j  a  ",
      "  B       j fa  ",
      "  j   ^   j$9b  ",
      "  j       j%#a  ",
      "  B       jama  ",
      "  j       j     ",
      "  ijBjjBBji     ",
      "                ",
      "                "
    ],
    [
      "                ",
      "                ",
      "  ijBjjBBji     ",
      "  j       jala  ",
      "  B       j  a  ",
      "  j       j  b  ",
      "  j   *   j  a  ",
      "  B       j  a  ",
      "  B       j fa  ",
      "  j   *   j&%b  ",
      "  j       j  a  ",
      "  B       jaaa  ",
      "  j       j     ",
      "  ijBjjBBji     ",
      "                ",
      "                "
    ],
    [
      "                ",
      "                ",
      "  ijBjjBBji     ",
      "  j       jaa(  ",
      "  B       j  (  ",
      "  j       j  )  ",
      "  j   *   j  (  ",
      "  B       j  (  ",
      "  B       j-f(  ",
      "  j   *   j++)  ",
      "  j       j  (  ",
      "  B       jaa(  ",
      "  j       j     ",
      "  ijBjjBBji     ",
      "                ",
      "                "
    ],
    [
      "                ",
      "                ",
      "  ijljjllji     ",
      "  j       ja(   ",
      "  n       ja(   ",
      "  j       jb)   ",
      "  j   ]   ja(   ",
      "  n       ja(   ",
      "  n       ja(   ",
      "  j   ]   j[)   ",
      "  j       j[(   ",
      "  n       ja(   ",
      "  j       j     ",
      "  ijmjjmmji     ",
      "                ",
      "                "
    ],
    [
      "                ",
      "                ",
      "  ijjjjjjji     ",
      "  jhhhhhhhj(    ",
      "  jh{{{{{hj(    ",
      "  jh{{{{{hj)    ",
      "  jh{{{{{hj(    ",
      "  jh{{{{{hj(    ",
      "  jh{{{{{hj(    ",
      "  jh{{{{{hj)    ",
      "  jh{{{{{hj(    ",
      "  jh{{{{{hj(    ",
      "  jhhhhhhhj     ",
      "  ijjjjjjji     ",
      "                ",
      "                "
    ],
    [
      "                ",
      "                ",
      "  ijjjjjjji     ",
      "  j}}}}}}}j     ",
      "  j}}}}}}}j     ",
      "  j}}}}}}}j     ",
      "  j}}}}}}}j     ",
      "  j}}}}}}}j     ",
      "  j}}}}}}}j     ",
      "  j}}}}}}}j     ",
      "  j}}}}}}}j     ",
      "  j}}}}}}}j     ",
      "  j}}}}}}}j     ",
      "  ijjjjjjji     ",
      "                ",
      "                "
    ],
    [
      "                ",
      "                ",
      "   |||||||      ",
      "  |       |     ",
      "  |   ':;;|     ",
      "  |   %;  |     ",
      "  |    ;% |     ",
      "  |   <:;;|     ",
      "  |    ;  |     ",
      "  |    ;  |     ",
      "  |   <:;;|     ",
      "  |      %|     ",
      "  |       |     ",
      "   |||||||      ",
      "                ",
      "                "
    ]
  ]
}