{
  "name": "building_office2a_top_180",
  "refpalette": "deceasedcraft:building_office2a/building_office2a_top_palette_180",
  "xsize": 16,
  "zsize": 16,
  "slices": [
    [
      "                ",
      "                ",
      "  ijnjjnnjjnji  ",
      "  jhhhhhhhhhhj  ",
      "  mhkkkkkkkkhl  ",
      "  jhkkkkkkkkhj  ",
      "  jhkkkkkkkkhj  ",
      "  mhkkkkkkkkhl  ",
      "  mhkkkkkkkkhl  ",
      "  jhkkkkkkkkhj  ",
      "  ijjjhhhhhhji  ",
      "    abbf   ha   ",
      "    cgbf  edc   ",
      "    aabaaabaa   ",
      "                ",
      "                "
    ],
    [
      "                ",
      "                ",
      "  ijBjjBBjjBji  ",
      "  jO        Nj  ",
      "  B  M       B  ",
      "  j  I   L   j  ",
      "  j KI  JC   j  ",
      "  B  I  Fu   B  ",
      "  B  E  DC   B  ",
      "  jAyx  wu   j  ",
      "  ijjjtjjjjsji  ",
      "    ar f  q a   ",
      "    cpof    c   ",
      "    aabaaabaa   ",
      "                ",
      "                "
    ],
    [
      "                ",
      "                ",
      "  ijBjjBBjjBji  ",
      "  j1        1j  ",
      "  B  0       B  ",
      "  j  Z   L   j  ",
      "  j  Y   S   j  ",
      "  B  X   S   B  ",
      "  B  W   S   B  ",
      "  jVUT  !S   j  ",
      "  ijjjRjjjjQji  ",
      "    a Pf q  a   ",
      "    c  f    c   ",
      "    aabaaabaa   ",
      "                ",
      "                "
    ],
    [
      "                ",
      "                ",
      "  ijBjjBBjjBji  ",
      "  j4        4j  ",
      "  B          B  ",
      "  j      L   j  ",
      "  j      S   j  ",
      "  B      S   B  ",
      "  B      S   B  ",
      "  j      S   j  ",
      "  ijjj3jjjj3ji  ",
      "    a2 fq   a   ",
      "    c  f    c   ",
      "    aabaaabaa   ",
      "                ",
      "                "
    ],
    [
      "                ",
      "                ",
      "  ijBjjBBjjBji  ",
      "  j          j  ",
      "  B          B  ",
      "  j          j  ",
      "  j      8   j  ",
      "  B          B  ",
      "  B          B  ",
      "  j          j  ",
      "  ijjjjjjjjjji  ",
      "    a75q    a   ",
      "    c65f    c   ",
      "    aabaaabaa   ",
      "                ",
      "                "
    ],
    [
      "                ",
      "                ",
      "  ijBjjBBjjBji  ",
      "  j          j  ",
      "  B          B  ",
      "  j          j  ",
      "  j   ^  ^   j  ",
      "  B          B  ",
      "  B          B  ",
      "  j          j  ",
      "  ijjjjjjjjjji  ",
      "    a%$     a   ",
      "    m#9f    c   ",
      "    aabaaabaa   ",
      "                ",
      "                "
    ],
    [
      "                ",
      "                ",
      "  ijBjjBBjjBji  ",
      "  j          j  ",
      "  B          B  ",
      "  j          j  ",
      "  j   *  *   j  ",
      "  B          B  ",
      "  B          B  ",
      "  j          j  ",
      "  ijjjjjjjjjji  ",
      "    a &     a   ",
      "    a %f    l   ",
      "    aabaaabaa   ",
      "                ",
      "                "
    ],
    [
      "                ",
      "                ",
      "  ijBjjBBjjBji  ",
      "  j          j  ",
      "  B          B  ",
      "  j          j  ",
      "  j   *  *   j  ",
      "  B          B  ",
      "  B          B  ",
      "  j          j  ",
      "  ijjjjjjjjjji  ",
      "    a +-    a   ",
      "    a +f    a   ",
      "    (()((()((   ",
      "                ",
      "                "
    ],
    [
      "                ",
      "                ",
      "  ijnjjnnjjnji  ",
      "  j          j  ",
      "  m          l  ",
      "  j          j  ",
      "  j   ]  ]   j  ",
      "  m          l  ",
      "  m          l  ",
      "  j          j  ",
      "  ijjjjjjjjjji  ",
      "    a[[aaabaa   ",
      "    (()((()((   ",
      "                ",
      "                ",
      "                "
    ],
    [
      "                ",
      "                ",
      "  ijjjjjjjjjji  ",
      "  jhhhhhhhhhhj  ",
      "  jh{{{{{{{{hj  ",
      "  jh{{{{{{{{hj  ",
      "  jh{{{{{{{{hj  ",
      "  jh{{{{{{{{hj  ",
      "  jh{{{{{{{{hj  ",
      "  jhhhhhhhhhhj  ",
      "  ijjjjjjjjjji  ",
      "    (()((()((   ",
      "                ",
      "                ",
      "                ",
      "                "
    ],
    [
      "                ",
      "                ",
      "  ijjjjjjjjjji  ",
      "  j}}}}}}}}}}j  ",
      "  j}}}}}}}}}}j  ",
      "  j}}}}}}}}}}j  ",
      "  j}}}}}}}}}}j  ",
      "  j}}}}}}}}}}j  ",
      "  j}}}}}}}}}}j  ",
      "  j}}}}}}}}}}j  ",
      "  ijjjjjjjjjji  ",
      "                ",
      "                ",
      "                ",
      "                ",
      "                "
    ],
    [
      "                ",
      "                ",
      "   ||||||||||   ",
      "  |          |  ",
      "  |          |  ",
      "  |          |  ",
      "  |  <  < %' |  ",
      "  |  :;;:;;: |  ",
      "  |  ;  ;% ; |  ",
      "  | %;  ;  ; |  ",
      "   ||||||||||   ",
      "                ",
      "                ",
      "                ",
      "                ",
      "                "
    ]
  ]
}