{
  "name": "building_office2a_floor1_180",
  "refpalette": "deceasedcraft:building_office2a/building_office2a_floor1_palette_180",
  "xsize": 16,
  "zsize": 16,
  "slices": [
    [
      "                ",
      "                ",
      "  jkokkookkokj  ",
      "  khhhhhhhhhhk  ",
      "  nhllllllllhm  ",
      "  khllllllllhk  ",
      "  khllllllllhk  ",
      "  nhllllllllhm  ",
      "  nhllllllllhm  ",
      "  khllllllllhk  ",
      "  jkkkhhhhhhkj  ",
      "    abbf  iha   ",
      "    cgbf  edc   ",
      "    aabaaabaa   ",
      "                ",
      "                "
    ],
    [
      "                ",
      "                ",
      "  jkEkkEEkkEkj  ",
      "  kP   OP   Ok  ",
      "  ENM LKN MLKE  ",
      "  kJ   IJ   Ik  ",
      "  kF   FF   Fk  ",
      "  E          E  ",
      "  E          E  ",
      "  kDCx BAyx wk  ",
      "  jkkkukkkktkj  ",
      "    as f ir a   ",
      "    cqpf    c   ",
      "    aabaaabaa   ",
      "                ",
      "                "
    ],
    [
      "                ",
      "                ",
      "  jkEkkEEkkEkj  ",
      "  k1   21   0k  ",
      "  EZ   YZ   YE  ",
      "  kX   VW   Vk  ",
      "  k          k  ",
      "  E          E  ",
      "  E          E  ",
      "  kU x B!Tx Sk  ",
      "  jkkkRkkkkQkj  ",
      "    a  fir  a   ",
      "    c  f    c   ",
      "    aabaaabaa   ",
      "                ",
      "                "
    ],
    [
      "                ",
      "                ",
      "  jkEkkEEkkEkj  ",
      "  k          k  ",
      "  E          E  ",
      "  k          k  ",
      "  k          k  ",
      "  E          E  ",
      "  E          E  ",
      "  k87x BTTx 6k  ",
      "  jkkk5kkkk5kj  ",
      "    a43hr   a   ",
      "    c 3hd   c   ",
      "    aabaaabaa   ",
      "                ",
      "                "
    ],
    [
      "                ",
      "                ",
      "  jkEkkEEkkEkj  ",
      "  k          k  ",
      "  E          E  ",
      "  k          k  ",
      "  k          k  ",
      "  E          E  ",
      "  E          E  ",
      "  k%$   #9   k  ",
      "  jkkkkkkkkkkj  ",
      "    a  f    a   ",
      "    c  fed  c   ",
      "    aabaaabaa   ",
      "                ",
      "                "
    ],
    [
      "                ",
      "                ",
      "  jkEkkEEkkEkj  ",
      "  k          k  ",
      "  E          E  ",
      "  k          k  ",
      "  k          k  ",
      "  E          E  ",
      "  E          E  ",
      "  k          k  ",
      "  jkkkkkkkkkkj  ",
      "    a^^f    a   ",
      "    c&^f ed c   ",
      "    aabaaabaa   ",
      "                ",
      "                "
    ]
  ]
}