{
  "name": "building_office2a_ground_180",
  "refpalette": "deceasedcraft:building_office2a/building_office2a_ground_palette_180",
  "xsize": 16,
  "zsize": 16,
  "slices": [
    [
      "aaaaaaaaaaaaaaaa",
      "aaabbbbbbbbbbaaa",
      "aabbbbbbbbbbbbaa",
      "abbddddddddddbba",
      "abbddddddddddbba",
      "abbddddddddddbba",
      "abbddddddddddbba",
      "abbddddddddddbba",
      "abbddddddddddbba",
      "abbddddddddddbba",
      "abbbbbbbbbbbbbba",
      "abbaaaaaaabbbbba",
      "abbaaaaaaacbbbba",
      "aabbbbbbbbbbbbaa",
      "aaabbbbbbbbbbaaa",
      "aaaaaaaaaaaaaaaa"
    ],
    [
      "                ",
      "  pf ff  ff fp  ",
      " jfhihhiihhihfg ",
      " fhED      CBhf ",
      "  i A y  y x i  ",
      " fh uwwwwwwu hf ",
      " eh   t  t   hf ",
      " rs          i  ",
      " rq          i  ",
      " ph          hf ",
      " fhoooooooo  hf ",
      "  i n    ml  i  ",
      " fhkk        hf ",
      " jfhihhiihhihfg ",
      "  ef ff  ff fe  ",
      "                "
    ],
    [
      "                ",
      "  pf ff  ff fp  ",
      " jfhihhiihhihfg ",
      " fhO        Ohf ",
      "  i          i  ",
      " fh N M  M L hf ",
      " eh          hf ",
      "  K          i  ",
      "  J          i  ",
      " ph          hf ",
      " fhIIIIIIII  hf ",
      "  i F   ml   i  ",
      " fh          hf ",
      " jfhihhiihhihfg ",
      "  ef ff  ff fe  ",
      "                "
    ],
    [
      "                ",
      "  pf ff  ff fp  ",
      " jfhihhiihhihfg ",
      " fhS        Shf ",
      "  i          i  ",
      " fh          hf ",
      " eh          hf ",
      "  i          i  ",
      "  i    R     i  ",
      " ph          hf ",
      " fhQQQQQQQQ  hf ",
      "  i    ml    i  ",
      " fh    mP    hf ",
      " jfhihhiihhihfg ",
      "  ef ff  ff fe  ",
      "                "
    ],
    [
      "                ",
      "  pfWffWWffWfp  ",
      " jfhhhhhhhhhhfg ",
      " fh          hf ",
      " Wh          hW ",
      " fh          hf ",
      " Th          hf ",
      " Wh    01    hW ",
      " Wh    R0    hW ",
      " Zh          hf ",
      " fYXXXXXXXXXXhf ",
      " WhVVVVU     hW ",
      " fhVVVVUcP   hf ",
      " jfhhhhhhhhhhfg ",
      "  efTffTTffTfe  ",
      "                "
    ],
    [
      "                ",
      "  pffffffffffp  ",
      " jffffffffffffg ",
      " ff3333333333ff ",
      " ff3333333333ff ",
      " ff3333333333ff ",
      " ff3333333333ff ",
      " ff3333443333ff ",
      " ff3333443333ff ",
      " ff3333333333ff ",
      " fffXXXXXXXXXff ",
      " ffffff2     ff ",
      " ffffff2 cP fff ",
      " jfffffhhhhhhfg ",
      "  effffffffffe  ",
      "                "
    ]
  ]
}