{
  "name": "building_office2a_floor3_270",
  "refpalette": "deceasedcraft:building_office2a/building_office2a_floor3_palette_270",
  "xsize": 16,
  "zsize": 16,
  "slices": [
    [
      "                ",
      "                ",
      "  jkmkkmmkj     ",
      "  khhhhhhhkaca  ",
      "  ohllllllhhda  ",
      "  khllllllhieb  ",
      "  khllllllh  a  ",
      "  ohllllllh  a  ",
      "  ohllllllhffa  ",
      "  khllllllhbbb  ",
      "  khllllllkbga  ",
      "  ohllllllkaca  ",
      "  khhhhhhhk     ",
      "  jknkknnkj     ",
      "                ",
      "                "
    ],
    [
      "                ",
      "                ",
      "  jkDkkDDkj     ",
      "  kK     !kaca  ",
      "  D       u  a  ",
      "  k JII  xkr b  ",
      "  k  IIF yki a  ",
      "  D JII Eyk  a  ",
      "  D  IIF Akffa  ",
      "  k JII   wspb  ",
      "  k  IIF  ktqa  ",
      "  D      Bkaca  ",
      "  kL     Ck     ",
      "  jkDkkDDkj     ",
      "                ",
      "                "
    ],
    [
      "                ",
      "                ",
      "  jkDkkDDkj     ",
      "  kZ      kaca  ",
      "  D       M  a  ",
      "  k  V    k  b  ",
      "  k  WS  Okr a  ",
      "  D  X   Pki a  ",
      "  D   T  Qkffa  ",
      "  k  YU   N  b  ",
      "  k   T   k  a  ",
      "  D      Rkaca  ",
      "  kZ      k     ",
      "  jkDkkDDkj     ",
      "                ",
      "                "
    ],
    [
      "                ",
      "                ",
      "  jkDkkDDkj     ",
      "  k3      kaca  ",
      "  D       2  a  ",
      "  k       k  b  ",
      "  k       k  a  ",
      "  D       krda  ",
      "  D       khha  ",
      "  k       200b  ",
      "  k       k1 a  ",
      "  D       kaca  ",
      "  k3      k     ",
      "  jkDkkDDkj     ",
      "                ",
      "                "
    ],
    [
      "                ",
      "                ",
      "  jkDkkDDkj     ",
      "  k       kaca  ",
      "  D       k  a  ",
      "  k       k  b  ",
      "  k       k da  ",
      "  D       k ea  ",
      "  D       kffa  ",
      "  k       k  b  ",
      "  k       k  a  ",
      "  D       kaca  ",
      "  k       k     ",
      "  jkDkkDDkj     ",
      "                ",
      "                "
    ],
    [
      "                ",
      "                ",
      "  jkDkkDDkj     ",
      "  k       kaca  ",
      "  D       k  a  ",
      "  k       k db  ",
      "  k   6   k ea  ",
      "  D       k  a  ",
      "  D       kffa  ",
      "  k   6   k44b  ",
      "  k       k45a  ",
      "  D       kaca  ",
      "  k       k     ",
      "  jkDkkDDkj     ",
      "                ",
      "                "
    ]
  ]
}