{
  "name": "building_office2a_floor2_90",
  "refpalette": "deceasedcraft:building_office2a/building_office2a_floor2_palette_90",
  "xsize": 16,
  "zsize": 16,
  "slices": [
    [
      "                ",
      "                ",
      "     jknnkknkj  ",
      "     khhhhhhhk  ",
      "  acakllllllho  ",
      "  agbkllllllhk  ",
      "  bbbhllllllhk  ",
      "  affhllllllho  ",
      "  a  hllllllho  ",
      "  a  hllllllhk  ",
      "  beihllllllhk  ",
      "  adhhllllllho  ",
      "  acakhhhhhhhk  ",
      "     jkmmkkmkj  ",
      "                ",
      "                "
    ],
    [
      "                ",
      "                ",
      "     jkEEkkEkj  ",
      "     kD  FJNPk  ",
      "  acakC    M E  ",
      "  aqskx      k  ",
      "  bp u      Qk  ",
      "  affkB  FIKOE  ",
      "  a  kA  FJNPE  ",
      "  a iky    M k  ",
      "  b rkx      k  ",
      "  a  t     L E  ",
      "  acakw  FIKOk  ",
      "     jkEEkkEkj  ",
      "                ",
      "                "
    ],
    [
      "                ",
      "                ",
      "     jkEEkkEkj  ",
      "     kV   Y01k  ",
      "  acak       E  ",
      "  a  kx      k  ",
      "  b  S       k  ",
      "  affkB   WZ2E  ",
      "  a ikU   X01E  ",
      "  a rkU      k  ",
      "  b  kx      k  ",
      "  a  R       E  ",
      "  acakT   WZYk  ",
      "     jkEEkkEkj  ",
      "                ",
      "                "
    ],
    [
      "                ",
      "                ",
      "     jkEEkkEkj  ",
      "     k8      k  ",
      "  acak7      E  ",
      "  a 4kx      k  ",
      "  b335       k  ",
      "  ahhkB      E  ",
      "  adrkU      E  ",
      "  a  kU      k  ",
      "  b  kx      k  ",
      "  a  5       E  ",
      "  acak6      k  ",
      "     jkEEkkEkj  ",
      "                ",
      "                "
    ],
    [
      "                ",
      "                ",
      "     jkEEkkEkj  ",
      "     k%      k  ",
      "  acak$      E  ",
      "  a  k       k  ",
      "  b  k       k  ",
      "  affk       E  ",
      "  ae k#      E  ",
      "  ad k9      k  ",
      "  b  k       k  ",
      "  a  k       E  ",
      "  acak       k  ",
      "     jkEEkkEkj  ",
      "                ",
      "                "
    ],
    [
      "                ",
      "                ",
      "     jkEEkkEkj  ",
      "     k       k  ",
      "  acak       E  ",
      "  a!^k       k  ",
      "  b^^k       k  ",
      "  affk       E  ",
      "  a  k       E  ",
      "  ae k   &   k  ",
      "  bd k       k  ",
      "  a  k       E  ",
      "  acak       k  ",
      "     jkEEkkEkj  ",
      "                ",
      "                "
    ]
  ]
}