{
  "name": "building_office2a_ground_270",
  "refpalette": "deceasedcraft:building_office2a/building_office2a_ground_palette_270",
  "xsize": 16,
  "zsize": 16,
  "slices": [
    [
      "aaaaaaaaaaaaaaaa",
      "aaabbbbbbbbbbaaa",
      "aabbbbbbbbbbbbaa",
      "abbdddddddbbbbba",
      "abbdddddddbbbbba",
      "abbdddddddbbcbba",
      "abbdddddddbaabba",
      "abbdddddddbaabba",
      "abbdddddddbaabba",
      "abbdddddddbaabba",
      "abbdddddddbaabba",
      "abbdddddddbaabba",
      "abbdddddddbaabba",
      "aabbbbbbbbbbbbaa",
      "aaabbbbbbbbbbaaa",
      "aaaaaaaaaaaaaaaa"
    ],
    [
      "                ",
      "  gf ff  ff fg  ",
      " pfhihhiihhihfe ",
      " fhB         hf ",
      "  iCxu       i  ",
      " fh  w    ol hf ",
      " fh ywt   om hf ",
      "  i  w    o  i  ",
      "  i  w    o  i  ",
      " fh ywt   o  hf ",
      " fh  w    o  hf ",
      "  iDAu    onki  ",
      " fhE      o khf ",
      " pfhihhsqhhihfe ",
      "  jf ferrpf fj  ",
      "                "
    ],
    [
      "                ",
      "  gf ff  ff fg  ",
      " pfhihhiihhihfe ",
      " fhO         hf ",
      "  i  L       i  ",
      " fh       I  hf ",
      " fh  M    Il hf ",
      "  i       Im i  ",
      "  i       I  i  ",
      " fh  M    I  hf ",
      " fh       I  hf ",
      "  i  N    IF i  ",
      " fhO      I  hf ",
      " pfhihhKJhhihfe ",
      "  jf fe  pf fj  ",
      "                "
    ],
    [
      "                ",
      "  gf ff  ff fg  ",
      " pfhihhiihhihfe ",
      " fhS         hf ",
      "  i          i  ",
      " fh       Q  hf ",
      " fh       Q  hf ",
      "  i       QlPi  ",
      "  i     R Qmmi  ",
      " fh       Q  hf ",
      " fh       Q  hf ",
      "  i       Q  i  ",
      " fhS      Q  hf ",
      " pfhihhiihhihfe ",
      "  jf fe  pf fj  ",
      "                "
    ],
    [
      "                ",
      "  gfWffWWffWfg  ",
      " pfhhhhhhhhhhfe ",
      " fh       X  hf ",
      " Wh       X  hT ",
      " fh       X  hf ",
      " fh       X Phf ",
      " Wh    10 X chT ",
      " Wh    0R XUUhT ",
      " fh       XVVhf ",
      " fh       XVVhf ",
      " Wh       XVVhT ",
      " fh       XVVhf ",
      " pfhhhhhhhYhhfe ",
      "  jfWfTWWZfWfj  ",
      "                "
    ],
    [
      "                ",
      "  gffffffffffg  ",
      " pffffffffffffe ",
      " ff3333333X fhf ",
      " ff3333333X  hf ",
      " ff3333333X Phf ",
      " ff3333333X chf ",
      " ff3333443X  hf ",
      " ff3333443X22hf ",
      " ff3333333Xffff ",
      " ff3333333Xffff ",
      " ff3333333Xffff ",
      " ff3333333fffff ",
      " pffffffffffffe ",
      "  jffffffffffj  ",
      "                "
    ]
  ]
}