{
  "name": "building_office2a_floor3_180",
  "refpalette": "deceasedcraft:building_office2a/building_office2a_floor3_palette_180",
  "xsize": 16,
  "zsize": 16,
  "slices": [
    [
      "                ",
      "                ",
      "  jkokkookkokj  ",
      "  khhhhhhhhhhk  ",
      "  nhllllllllhm  ",
      "  khllllllllhk  ",
      "  khllllllllhk  ",
      "  nhllllllllhm  ",
      "  nhllllllllhm  ",
      "  khllllllllhk  ",
      "  jkkkhhhhhhkj  ",
      "    abbf  iha   ",
      "    cgbf  edc   ",
      "    aabaaabaa   ",
      "                ",
      "                "
    ],
    [
      "                ",
      "                ",
      "  jkDkkDDkkDkj  ",
      "  kL        Kk  ",
      "  D   J J J  D  ",
      "  k  IIIIII  k  ",
      "  k  IIIIII  k  ",
      "  D  F F F   D  ",
      "  D     E    D  ",
      "  kCB  Ayyx !k  ",
      "  jkkkwkkkkukj  ",
      "    atsf ir a   ",
      "    cqpf    c   ",
      "    aabaaabaa   ",
      "                ",
      "                "
    ],
    [
      "                ",
      "                ",
      "  jkDkkDDkkDkj  ",
      "  kZ        Zk  ",
      "  D          D  ",
      "  k   Y XWV  k  ",
      "  k  TUT S   k  ",
      "  D          D  ",
      "  D          D  ",
      "  k R  QPO   k  ",
      "  jkkkNkkkkMkj  ",
      "    a  fir  a   ",
      "    c  f    c   ",
      "    aabaaabaa   ",
      "                ",
      "                "
    ],
    [
      "                ",
      "                ",
      "  jkDkkDDkkDkj  ",
      "  k3        3k  ",
      "  D          D  ",
      "  k          k  ",
      "  k          k  ",
      "  D          D  ",
      "  D          D  ",
      "  k          k  ",
      "  jkkk2kkkk2kj  ",
      "    a10hr   a   ",
      "    c 0hd   c   ",
      "    aabaaabaa   ",
      "                ",
      "                "
    ],
    [
      "                ",
      "                ",
      "  jkDkkDDkkDkj  ",
      "  k          k  ",
      "  D          D  ",
      "  k          k  ",
      "  k          k  ",
      "  D          D  ",
      "  D          D  ",
      "  k          k  ",
      "  jkkkkkkkkkkj  ",
      "    a  f    a   ",
      "    c  fed  c   ",
      "    aabaaabaa   ",
      "                ",
      "                "
    ],
    [
      "                ",
      "                ",
      "  jkDkkDDkkDkj  ",
      "  k          k  ",
      "  D          D  ",
      "  k          k  ",
      "  k   6  6   k  ",
      "  D          D  ",
      "  D          D  ",
      "  k          k  ",
      "  jkkkkkkkkkkj  ",
      "    a44f    a   ",
      "    c54f ed c   ",
      "    aabaaabaa   ",
      "                ",
      "                "
    ]
  ]
}