{
  "name": "multi_terraceplaza_25_floor1",
  "refpalette": "deceasedcraft:multi_terraceplaza_25/multi_terraceplaza_25_floor1_palette",
  "xsize": 16,
  "zsize": 16,
  "slices": [
    [
      "         a      ",
      "         a      ",
      "         a      ",
      "         a      ",
      "         a      ",
      "         a      ",
      "         a      ",
      "         a      ",
      "         a      ",
      "         bcccccc",
      "         adc    ",
      "         adc    ",
      "e        a c    ",
      "fg       a  cccc",
      "h        a      ",
      "         a      "
    ],
    [
      "iiiiiiiiijkkkkkk",
      "iiiiiiiiijkkllkk",
      "iiiiiiiiijkkkkkk",
      "iiiiiiiiijkkkkkk",
      "iiiiiiiiijkkkkkk",
      "iiiiiiiiijkkkkkk",
      "iiiiiiiiijkkllkk",
      "iiiiiiiiijkkkkkk",
      "iiiiiiiiijkkkkkk",
      "jjjjjjjjjbjjjjjj",
      "m        jkkkkkk",
      "e        jkkkkkk",
      "fg       jkkkkkk",
      "h        jkkkkkk",
      "         jkkkkkk",
      "         jkkkkkk"
    ],
    [
      "nnnnnnnnnopppppp",
      "nnnnnnnnnopppppp",
      "nnnnnnnnnopppppp",
      "nnnnnnnnnopppppp",
      "nnnnnnnnnopppppp",
      "nnnnnnnnnopppppp",
      "nnnnnnnnnopppppp",
      "nnnnnnnnnopppppp",
      "nnnnnnnnnopppppp",
      "qrrrrrrrrboooooo",
      "qg       oststss",
      "fg       osstsst",
      "h        ossttst",
      "         ossssst",
      "         ossssts",
      "         osstsss"
    ],
    [
      "         u   w  ",
      "         x   w  ",
      "         u   w  ",
      "         u   w  ",
      "         u   w  ",
      "         u   w  ",
      "         x   w  ",
      "         u      ",
      "         uy     ",
      "hxxxxxxxxbAAAAAB",
      "h        x      ",
      "h        x C    ",
      "         x D    ",
      "         x E    ",
      "         x      ",
      "         x      "
    ],
    [
      "         uF  I  ",
      "         xJ  K  ",
      "         uL  M  ",
      "         uN  O  ",
      "         uF  P  ",
      "         u   Q  ",
      "         xN  R  ",
      "         uJ     ",
      "         uS     ",
      "         b      ",
      "                ",
      "                ",
      "                ",
      "                ",
      "                ",
      "TTTTTTTTTT      "
    ],
    [
      "         uU     ",
      "         xU     ",
      "         uU     ",
      "         uU     ",
      "         uU     ",
      "         uU     ",
      "         xU     ",
      "         uV     ",
      "         uW     ",
      "         b      ",
      "                ",
      "                ",
      "TTTTTTTTTT      ",
      "XXXXXXXXXXYZZZZZ",
      "ppppppppppYZZZZZ",
      "0000000000YZZZZZ"
    ]
  ]
}