{
  "name": "multi_terraceplaza_25_base2",
  "refpalette": "deceasedcraft:multi_terraceplaza_25/multi_terraceplaza_25_base2_palette",
  "xsize": 16,
  "zsize": 16,
  "slices": [
    [
      "aaaaaaaaaaaaaaaa",
      "aaaaaaaaaaaaaaaa",
      "aaaaaaaaaaaaaaaa",
      "aaaaabbbbbbbbaaa",
      "aaaaabbbbbbbbaaa",
      "aaaaaaaaaaaaaaaa",
      "aaaaaaaaaaaaaaaa",
      "aaaaaaaaaaaaaaaa",
      "aaaaaaaaaaaaaaaa",
      "aaaaaaaaacaaaaaa",
      "aaaaaaaaaaaaaaaa",
      "aaaaaaaaaaaaaaaa",
      "aaaaaaaaaaaaaaaa",
      "aaaaaaaaaaaaaaaa",
      "aaaaaaaaaaaaaaaa",
      "aaaaaaaaaaaaaaaa"
    ],
    [
      "                ",
      "                ",
      "     dddddddd   ",
      "    efgfgghghi  ",
      "    jffggfgh!k  ",
      "     llllllll   ",
      "                ",
      "                ",
      "     mnnnnnno   ",
      "     pqqqcqqo   ",
      "r    pststssu   ",
      "                ",
      "                ",
      "     dddddddd   ",
      "    ewwxxwwwxi  ",
      "    jwxwwwxwwk  "
    ],
    [
      "                ",
      "                ",
      "                ",
      "                ",
      "                ",
      "                ",
      "                ",
      "                ",
      "     pyAByyAu   ",
      "     mq!qcqqu   ",
      "r    pCDCCCDo   ",
      "                ",
      "                ",
      "                ",
      "     EFIJKLIM   ",
      "     JNOFPENL   "
    ],
    [
      "                ",
      "                ",
      "                ",
      "                ",
      "                ",
      "                ",
      "                ",
      "                ",
      "     myyyAyyo   ",
      "     pQQQcQQo   ",
      "r    mtRRttRo   ",
      "                ",
      "                ",
      "                ",
      "                ",
      "                "
    ],
    [
      "                ",
      "                ",
      "                ",
      "                ",
      "                ",
      "                ",
      "                ",
      "                ",
      "      SSSSSS    ",
      "         c      ",
      "r               ",
      "                ",
      "                ",
      "                ",
      "                ",
      "                "
    ],
    [
      "                ",
      "                ",
      "                ",
      "                ",
      "                ",
      "                ",
      "                ",
      "                ",
      "         T      ",
      "         c      ",
      "r        U      ",
      "r               ",
      "r               ",
      "r               ",
      "r               ",
      "r               "
    ]
  ]
}