{
  "name": "multi_terraceplaza_25_floor2",
  "refpalette": "deceasedcraft:multi_terraceplaza_25/multi_terraceplaza_25_floor2_palette",
  "xsize": 16,
  "zsize": 16,
  "slices": [
    [
      "         a      ",
      "         b  c   ",
      "         a      ",
      "         a      ",
      "         a  c   ",
      "         a      ",
      "         b      ",
      "         a  c   ",
      "         a      ",
      "dddddddddedddddd",
      "ffffffffffgggggg",
      "hhhhhhhhhhgggggg",
      "iiiiiiiiiiiiiiii",
      "jjjjjjjjjj      ",
      "                ",
      "                "
    ],
    [
      "         k      ",
      "         k  l   ",
      "         k      ",
      "         k      ",
      "         k  l   ",
      "         k      ",
      "gggggggggkgggggg",
      "fffffffffkffffff",
      "hhhhhhhhhkhhhhhh",
      "mmmmmmmmmmmmmmmm",
      "mmmmmmmmmmmmmmmm",
      "                ",
      "                ",
      "                ",
      "                ",
      "                "
    ],
    [
      "         k      ",
      "         k  l   ",
      "         k      ",
      "gggggggggkgggggg",
      "fffffffffkffffff",
      "hhhhhhhhhhnnnnnn",
      "iiiiiiiiiiiiiiii",
      "jjjjjjjjjjjjjjjj",
      "oooooooooooooooo",
      "pppppppppppppppp",
      "                ",
      "                ",
      "                ",
      "                ",
      "                ",
      "                "
    ],
    [
      "gggggggggqgggggg",
      "fffffffffqffffff",
      "hhhhhhhhhhnnnnnn",
      "iiiiiiiiiiiiiiii",
      "jjjjjjjjjjjjjjjj",
      "                ",
      "                ",
      "                ",
      "                ",
      "                ",
      "                ",
      "                ",
      "                ",
      "                ",
      "                ",
      "                "
    ],
    [
      "iiiiiiiiiiiiiiii",
      "jjjjjjjjjjjjjjjj",
      "                ",
      "                ",
      "                ",
      "                ",
      "                ",
      "                ",
      "                ",
      "                ",
      "                ",
      "                ",
      "                ",
      "                ",
      "                ",
      "                "
    ],
    [
      "                ",
      "                ",
      "                ",
      "                ",
      "                ",
      "                ",
      "                ",
      "                ",
      "                ",
      "                ",
      "                ",
      "                ",
      "                ",
      "                ",
      "                ",
      "                "
    ]
  ]
}