{
  "name": "multi_terraceplaza_25_base1",
  "refpalette": "deceasedcraft:multi_terraceplaza_25/multi_terraceplaza_25_base1_palette",
  "xsize": 16,
  "zsize": 16,
  "slices": [
    [
      "                ",
      "                ",
      "                ",
      "                ",
      "                ",
      "                ",
      "                ",
      "                ",
      "                ",
      "         a      ",
      "b               ",
      "b               ",
      "bc              ",
      "b               ",
      "bd              ",
      "be              "
    ],
    [
      "                ",
      "                ",
      "                ",
      "                ",
      "                ",
      "                ",
      "                ",
      "                ",
      "                ",
      "         a      ",
      "b               ",
      "b               ",
      "bf              ",
      "b               ",
      "bg              ",
      "be              "
    ],
    [
      "                ",
      "                ",
      "                ",
      "                ",
      "                ",
      "                ",
      "                ",
      "                ",
      "                ",
      "         a      ",
      "b               ",
      "b               ",
      "b               ",
      "b               ",
      "b               ",
      "b               "
    ],
    [
      "hh              ",
      "hh              ",
      "hh              ",
      "hh              ",
      "hh              ",
      "hh              ",
      "hh              ",
      "hh              ",
      "hh              ",
      "hh       a      ",
      "bh              ",
      "bh              ",
      "bh              ",
      "bh              ",
      "bh              ",
      "bh              "
    ],
    [
      "ijjjjjjjjjjjjjjj",
      "ijjjjjjjjjjjjjjj",
      "ijjjjjjjjjjjjjjj",
      "ijjjjjjjjjjjjjjj",
      "ijjjjjjjjjjjjjjj",
      "ijjjjjjjjjjjjjjj",
      "ijjjjjjjjjjjjjjj",
      "ijjjjjjjjjjjjjjj",
      "ijjjjjjjjjjjjjjj",
      "ijjjjjjjjajjjjjj",
      "ijjjjjjjjjjjjjjj",
      "ijjjjjjjjjjjjjjj",
      "ijjjjjjjjjjjjjjj",
      "ijjjjjjjjjjjjjjj",
      "ijjjjjjjjjjjjjjj",
      "ijjjjjjjjjjjjjjj"
    ],
    [
      "kllllllllmllllll",
      "kllllllllmllllll",
      "kllllllllmllllll",
      "kllllllllmllllll",
      "kllllllllmllllll",
      "kllllllllmllllll",
      "kllllllllmllllll",
      "kllllllllmllllll",
      "kllllllllmllllll",
      "mmmmmmmmmammmmmm",
      "kllllllllmllllll",
      "kllllllllmllllll",
      "kllllllllmllllll",
      "kllllllllmllllll",
      "kllllllllmllllll",
      "kllllllllmllllll"
    ]
  ]
}