{
  "name": "multi_terraceplaza_25_ground",
  "refpalette": "deceasedcraft:multi_terraceplaza_25/multi_terraceplaza_25_ground_palette",
  "xsize": 16,
  "zsize": 16,
  "slices": [
    [
      "aabaaaaaacdddddd",
      "aabaaaaaacdddddd",
      "aaaaaaaaacdddddd",
      "aaaaaaaaacdddddd",
      "aaaaaaaaacdddddd",
      "aaaaaaaaacdddddd",
      "aaaaaaaaacdddddd",
      "aaaaaaaaacdddddd",
      "aaaaaaaaacdddddd",
      "aaaaaaaaaeffffff",
      "aaaaaaaaacdddddd",
      "aaaaaaaaacdddddd",
      "aaaaaaaaacdddddd",
      "aaaaaaaaacdddddd",
      "aaaaaaaaacdddddd",
      "aaaaaaaaacdddddd"
    ],
    [
      " gh      i      ",
      " jh      k  lmno",
      "  j         pqlm",
      "                ",
      "                ",
      "             rss",
      "         ktu w  ",
      "         ixy A  ",
      " B       ixC A  ",
      "DEF      effffff",
      " I       iJfK LM",
      "         iJfK   ",
      "         kifNO  ",
      "            fPQR",
      "            STU ",
      "           VWXY "
    ],
    [
      "         i      ",
      "         k  Z012",
      "            3456",
      "                ",
      "                ",
      "              78",
      "         k 9    ",
      "         i#$    ",
      "         i%^ & *",
      " (       effffff",
      "         i)f+ -[",
      "         i]f+   ",
      "         kif P{{",
      "            f}  ",
      "             |; ",
      "            )|  "
    ],
    [
      "         i      ",
      "         k      ",
      "                ",
      "                ",
      "                ",
      "                ",
      "         k      ",
      "         i:     ",
      "         i'     ",
      " <       effffff",
      "         i f  >>",
      "         i f    ",
      "         kif ,,,",
      "            f.ff",
      "                ",
      "?               "
    ],
    [
      "         i      ",
      "         k      ",
      "                ",
      "                ",
      "                ",
      "                ",
      "         k      ",
      "         i/     ",
      "         i`     ",
      " <       effffff",
      "         i f    ",
      "         i f    ",
      "         kif    ",
      "            ffff",
      "?               ",
      "\u0370\u0371              "
    ],
    [
      "         \u0372      ",
      "        \u0373\u0372\u0374     ",
      "        \u0373\u0372\u0374     ",
      "        \u0373\u0372\u0374     ",
      "        \u0373\u0372\u0374     ",
      "        \u0373\u0372\u0374     ",
      "        \u0375\u0372\u0374     ",
      "         \u0372\u0376     ",
      "         \u0372\u0376     ",
      "         effffff",
      "         \u0372 f    ",
      "         \u0372 f    ",
      "        \u0377\u0372\u0374f    ",
      "?       \u0377\u0372\u0374 ffff",
      "\u0370\u0371      \u0377\u0372\u0374     ",
      "\u037a       \u0377\u0372\u0374     "
    ]
  ]
}