{
  "name": "multi_thering_14_ground",
  "refpalette": "deceasedcraft:multi_thering_14/multi_thering_14_ground_palette",
  "xsize": 16,
  "zsize": 16,
  "slices": [
    [
      "aaaaaaaaaaaaaaba",
      "bbbbbbbbbbbbbbbb",
      "bbbbbbbbbbbbbbbb",
      "bbbbbbbbbbbbbbbb",
      "bbbbcbbbbbbcbbbb",
      "bbbbbbbbbbbbbbbb",
      "bbbbbbbbbbbbbbbb",
      "dddddddddddddddd",
      "eeeeeeeeeeeeeeee",
      "dddddddddddddddd",
      "bbbbbbbbbbbbbbbb",
      "bbbbbbbbbbbbbbbb",
      "aaaaaaaaaaaaaaaa",
      "cccccccccccccccc",
      "cccccccccccccccc",
      "cccccccccccccccc"
    ],
    [
      "f              f",
      "                ",
      "                ",
      "                ",
      "    g      g    ",
      "                ",
      "                ",
      "hhhhhhhhhhhhhhhh",
      "iiiiiiiiiiiiiiii",
      "hhhhhhhhhhhhhhhh",
      "                ",
      "                ",
      "    j kllm j    ",
      "nnnnnnnnnnnnnnnn",
      "                ",
      "                "
    ],
    [
      "f              f",
      "                ",
      "                ",
      "                ",
      "    o      o    ",
      "                ",
      "                ",
      "                ",
      "                ",
      "                ",
      "                ",
      "                ",
      "    p      p    ",
      "                ",
      "                ",
      "                "
    ],
    [
      "f              f",
      "                ",
      "                ",
      "                ",
      "    n      n    ",
      "                ",
      "                ",
      "                ",
      "                ",
      "                ",
      "                ",
      "                ",
      "                ",
      "                ",
      "                ",
      "                "
    ],
    [
      "f              f",
      "                ",
      "                ",
      "                ",
      "    n      n    ",
      "                ",
      "                ",
      "                ",
      "                ",
      "                ",
      "                ",
      "                ",
      "                ",
      "                ",
      "                ",
      "                "
    ],
    [
      "f              f",
      "                ",
      "                ",
      "                ",
      "    n      n    ",
      "                ",
      "                ",
      "                ",
      "                ",
      "                ",
      "                ",
      "                ",
      "                ",
      "                ",
      "                ",
      "                "
    ]
  ]
}