{
  "name": "multi_thering_14_floor7",
  "refpalette": "deceasedcraft:multi_thering_14/multi_thering_14_floor7_palette",
  "xsize": 16,
  "zsize": 16,
  "slices": [
    [
      "                ",
      "                ",
      "                ",
      "   aaaaaaaaaa   ",
      " aabbbbbbbbbbaa ",
      "abbbbbbbbbbbbbba",
      "cccdbbbbbbbbeccc",
      "ffccccccccccccff",
      "ffffffffffffffff",
      "ffffffffffffffff",
      "ccffffffffffffcc",
      "ggccccccccccccgg",
      "  gggggggggggg  ",
      "                ",
      "                ",
      "                "
    ],
    [
      "                ",
      "                ",
      "                ",
      "                ",
      "                ",
      "                ",
      "    hij  hij    ",
      "kk            kk",
      "lkkkkkkkkkkkkkkl",
      "mm llnllll lllmm",
      "oommmmmmmmmmmmoo",
      "  oooooooooooo  ",
      "                ",
      "                ",
      "                ",
      "                "
    ],
    [
      "                ",
      "                ",
      "                ",
      "                ",
      "                ",
      "                ",
      "                ",
      "                ",
      "                ",
      "mm            mm",
      "  mmmmmmmmmmmm  ",
      "                ",
      "                ",
      "                ",
      "                ",
      "                "
    ],
    [
      "                ",
      "                ",
      "                ",
      "                ",
      "                ",
      "                ",
      "                ",
      "                ",
      "                ",
      "                ",
      "                ",
      "                ",
      "                ",
      "                ",
      "                ",
      "                "
    ],
    [
      "                ",
      "                ",
      "                ",
      "                ",
      "                ",
      "                ",
      "                ",
      "                ",
      "                ",
      "                ",
      "                ",
      "                ",
      "                ",
      "                ",
      "                ",
      "                "
    ],
    [
      "                ",
      "                ",
      "                ",
      "                ",
      "                ",
      "                ",
      "                ",
      "                ",
      "                ",
      "                ",
      "                ",
      "                ",
      "                ",
      "                ",
      "                ",
      "                "
    ]
  ]
}