{
  "name": "multi_thering_14_floor6",
  "refpalette": "deceasedcraft:multi_thering_14/multi_thering_14_floor6_palette",
  "xsize": 16,
  "zsize": 16,
  "slices": [
    [
      "a              a",
      "                ",
      "                ",
      "                ",
      "                ",
      "                ",
      "                ",
      "                ",
      "                ",
      "                ",
      "                ",
      "                ",
      "                ",
      "                ",
      "                ",
      "                "
    ],
    [
      "a              a",
      "                ",
      "                ",
      "                ",
      "                ",
      "                ",
      "                ",
      "                ",
      "                ",
      "                ",
      "                ",
      "                ",
      "                ",
      "                ",
      "                ",
      "                "
    ],
    [
      "a              a",
      "                ",
      "                ",
      "                ",
      "                ",
      "                ",
      "                ",
      "                ",
      "                ",
      "                ",
      "                ",
      "                ",
      "                ",
      "                ",
      "                ",
      "                "
    ],
    [
      "a              a",
      "                ",
      "                ",
      "                ",
      "                ",
      "                ",
      "                ",
      "                ",
      "                ",
      "                ",
      "                ",
      "                ",
      "                ",
      "                ",
      "                ",
      "                "
    ],
    [
      "bbbbbbbbbbbbbbbb",
      "bbbbbbbbbbbbbbbb",
      "bbbbbbbbbbbbbbbb",
      "bbbbbbbbbbbbbbbb",
      "bbbbbbbbbbbbbbbb",
      "bbbbbbbbbbbbbbbb",
      "bbbbbbbbbbbbbbbb",
      "ccbbbbbbbbbbbbcc",
      "  cccccccccccc  ",
      "                ",
      "                ",
      "                ",
      "                ",
      "                ",
      "                ",
      "                "
    ],
    [
      "ddddeedddddeddde",
      "eeeedeeeeeeeeeee",
      "edeeeeeeeeeeeeee",
      "dddffffffffffddd",
      "dffffffffffffffd",
      "ffffffffffffffff",
      "bbbgffffffffgbbb",
      "bbbbbbbbbbbbbbbb",
      "bbbhbbbbbbbbhbbb",
      "ccbcbbbbbbbbcbcc",
      "  cccccccccccc  ",
      "                ",
      "                ",
      "                ",
      "                ",
      "                "
    ]
  ]
}