{
  "name": "multi_nuclearpowerplant_26_base11",
  "refpalette": "deceasedcraft:multi_nuclearpowerplant_26/multi_nuclearpowerplant_26_base11_palette",
  "xsize": 16,
  "zsize": 16,
  "slices": [
    [
      "           ab   ",
      "            cd  ",
      "                ",
      "                ",
      "                ",
      "                ",
      "e    e          ",
      "fg hhfg         ",
      "igjhkigll     m ",
      "nooopqoooooooooo",
      "rsssrrssssssssss",
      "tttttttttttttttt",
      "tttttttttttttttt",
      "tttttttttttttttt",
      "tttttttttttttttt",
      "tttttttttttttttt"
    ],
    [
      "          ab    ",
      "           cd   ",
      "                ",
      "                ",
      "                ",
      "                ",
      "                ",
      "ug huug         ",
      "ug hwugll      m",
      "xoooxxoooooooooo",
      "rsssrrssssssssss",
      "tttttttttttttttt",
      "tttttttttttttttt",
      "tttttttttttttttt",
      "tttttttttttttttt",
      "tttttttttttttttt"
    ],
    [
      "          b     ",
      "          cd    ",
      "                ",
      "                ",
      "                ",
      "                ",
      "                ",
      "                ",
      "    y  ll       ",
      "oooooooooooooooo",
      "ssssssssssssssss",
      "tttttttttttttttt",
      "tttttttttttttttt",
      "tttttttttttttttt",
      "tttttttttttttttt",
      "tttttttttttttttt"
    ],
    [
      "         b      ",
      "         cd     ",
      "                ",
      "                ",
      "                ",
      "                ",
      "                ",
      "                ",
      "    A  ll       ",
      "oooooooooooooooo",
      "ssssssssssssssss",
      "tttttttttttttttt",
      "tttttttttttttttt",
      "tttttttttttttttt",
      "tttttttttttttttt",
      "tttttttttttttttt"
    ],
    [
      "BBBBBBBBB       ",
      "cccccccccd      ",
      "                ",
      "                ",
      "                ",
      "                ",
      "                ",
      "                ",
      "AAA A  ll       ",
      "oooooooooooooooo",
      "ssssssssssssssss",
      "tttttttttttttttt",
      "tttttttttttttttt",
      "tttttttttttttttt",
      "tttttttttttttttt",
      "tttttttttttttttt"
    ],
    [
      "                ",
      "ddddddddd       ",
      "                ",
      "                ",
      "                ",
      "                ",
      "                ",
      "                ",
      "  A A  ll       ",
      "oooooooooooooooo",
      "ssssssssssssssss",
      "tttttttttttttttt",
      "tttttttttttttttt",
      "tttttttttttttttt",
      "tttttttttttttttt",
      "tttttttttttttttt"
    ]
  ]
}