{
  "name": "multi_nuclearpowerplant_26_base2",
  "refpalette": "deceasedcraft:multi_nuclearpowerplant_26/multi_nuclearpowerplant_26_base2_palette",
  "xsize": 16,
  "zsize": 16,
  "slices": [
    [
      "               a",
      "               a",
      "               a",
      "              a ",
      "              a ",
      "             a  ",
      "             a  ",
      "            a   ",
      "           a    ",
      "           a    ",
      "         ba     ",
      "         a      ",
      "        a       ",
      "       a        ",
      "      a         ",
      "     a          "
    ],
    [
      "               a",
      "               a",
      "               a",
      "              a ",
      "              a ",
      "             a  ",
      "             a  ",
      "            a   ",
      "           a    ",
      "           a    ",
      "         ba     ",
      "         a      ",
      "        a       ",
      "       a        ",
      "      a         ",
      "     a          "
    ],
    [
      "               a",
      "               a",
      "               a",
      "              a ",
      "              a ",
      "             a  ",
      "             a  ",
      "            a   ",
      "           a    ",
      "           a    ",
      "         ba     ",
      "         a      ",
      "        a       ",
      "       a        ",
      "      a         ",
      "     a          "
    ],
    [
      "               a",
      "               a",
      "               a",
      "              a ",
      "              a ",
      "             a  ",
      "             a  ",
      "            a   ",
      "           a    ",
      "           a    ",
      "         ba     ",
      "         a      ",
      "        a       ",
      "       a        ",
      "      a         ",
      "     a          "
    ],
    [
      "              cd",
      "              cd",
      "             ccd",
      "             cd ",
      "            ccd ",
      "            cd  ",
      "           ccd  ",
      "          ccd   ",
      "          cd    ",
      "         ccd    ",
      "        ccd     ",
      "       ccd      ",
      "      ccd       ",
      "     ccd        ",
      "    ccd         ",
      "   ccd          "
    ],
    [
      "          eeeecf",
      "         eeeeecf",
      "        eeeeeccf",
      "       eeeeeecff",
      "       eeeeeccff",
      "      eeeeeecfff",
      "     eeeeeeccfff",
      "    eeeeeeccffff",
      "  eeeeeeeecfffff",
      " eeeeeeeeccfffff",
      "eeeeeeeeccfffggg",
      "eeeeeeeccfffffff",
      "eeeeeeccffffffff",
      "eeeeeccfffffffff",
      "eeeeccffffffffff",
      "eeeccffffggfffgg"
    ]
  ]
}