{
  "name": "multi_nuclearpowerplant_26_base3",
  "refpalette": "deceasedcraft:multi_nuclearpowerplant_26/multi_nuclearpowerplant_26_base3_palette",
  "xsize": 16,
  "zsize": 16,
  "slices": [
    [
      "              ab",
      "              ab",
      "             aab",
      "             abc",
      "            aabc",
      "            abcc",
      "           aabcc",
      "          aabccc",
      "          abcccc",
      "         aabcccc",
      "        adbccccc",
      "       aabcccccc",
      "      aabccccccc",
      "     aabcccccccc",
      "    aabccccccccc",
      "   aabcccccccccc"
    ],
    [
      "               e",
      "               e",
      "               e",
      "              e ",
      "              e ",
      "             e  ",
      "             e  ",
      "            e   ",
      "           e    ",
      "           e    ",
      "         feg    ",
      "         e      ",
      "        e       ",
      "       e        ",
      "      e         ",
      "     e          "
    ],
    [
      "               e",
      "               e",
      "               e",
      "              e ",
      "              e ",
      "             e  ",
      "             e  ",
      "            e   ",
      "           e    ",
      "           e    ",
      "         fe     ",
      "         e      ",
      "        e       ",
      "       e        ",
      "      e         ",
      "     e          "
    ],
    [
      "               e",
      "               e",
      "               e",
      "              e ",
      "              e ",
      "             e  ",
      "             e  ",
      "            e   ",
      "           e    ",
      "           e    ",
      "         fe     ",
      "         e      ",
      "        e       ",
      "       e        ",
      "      e         ",
      "     e          "
    ],
    [
      "               e",
      "               e",
      "               e",
      "              e ",
      "              e ",
      "             e  ",
      "             e  ",
      "            e   ",
      "           e    ",
      "           e    ",
      "         fe     ",
      "         e      ",
      "        e       ",
      "       e        ",
      "      e         ",
      "     e          "
    ],
    [
      "               e",
      "               e",
      "               e",
      "              e ",
      "              e ",
      "             e  ",
      "             e  ",
      "            e   ",
      "           e    ",
      "           e    ",
      "         fe     ",
      "         e      ",
      "        e       ",
      "       e        ",
      "      e         ",
      "     e          "
    ]
  ]
}