{
  "name": "multi_nuclearpowerplant_26_base6",
  "refpalette": "deceasedcraft:multi_nuclearpowerplant_26/multi_nuclearpowerplant_26_base6_palette",
  "xsize": 16,
  "zsize": 16,
  "slices": [
    [
      "aaaaaaaaaaaaaaaa",
      "aaaaaaaaaaaaaaaa",
      "aaaaaaaaaaaaaaaa",
      "aaaaaaaaaaaaaaaa",
      "aaaaaaaaaaaaaaaa",
      "aaaaaaaaaaaaaaaa",
      "aaaaaaaaaaaaaaaa",
      "aaaaaaaaaaaaaaaa",
      "aaaaaaaaaaaaaaaa",
      "aaaaaaaaaaaaaaaa",
      "aaaaaaaaabaaaaaa",
      "aaaaaaaaaaaaaaaa",
      "aaaaaaaaaaaaaaaa",
      "aaaaaaaaaaaaaaaa",
      "aaaaaaaaaaaaaaaa",
      "aaaaaaaaaaaaaaaa"
    ],
    [
      "                ",
      "                ",
      "                ",
      "                ",
      "           ccccc",
      "          deeeee",
      "          deeeee",
      "          deeeee",
      "          deeeee",
      "          deeeee",
      "        fgdeeeee",
      "          deeeee",
      "          deeeee",
      "          deeeee",
      "          deeeee",
      "          deeeee"
    ],
    [
      "                ",
      "                ",
      "                ",
      "                ",
      "                ",
      "           h h h",
      "            i   ",
      "           h h h",
      "                ",
      "           h h h",
      "         g  i   ",
      "           h h h",
      "                ",
      "           h h h",
      "            i   ",
      "           h h h"
    ],
    [
      "                ",
      "                ",
      "                ",
      "                ",
      "                ",
      "           iii i",
      "          ji iki",
      "           iii i",
      "                ",
      "           iii i",
      "         gli imi",
      "           iii i",
      "                ",
      "           iii i",
      "          ni ioi",
      "           iii i"
    ],
    [
      "                ",
      "                ",
      "                ",
      "                ",
      "                ",
      "           iii i",
      "           i i i",
      "           iii i",
      "                ",
      "           iii i",
      "         g i i i",
      "           iii i",
      "                ",
      "           iii i",
      "           i i i",
      "           iii i"
    ],
    [
      "                ",
      "                ",
      "                ",
      "                ",
      "                ",
      "           iii i",
      "           i i i",
      "           iii i",
      "                ",
      "           iii i",
      "         g i i i",
      "           iii i",
      "                ",
      "           iii i",
      "           i i i",
      "           iii i"
    ]
  ]
}