{
  "name": "multi_nuclearpowerplant_26_ground",
  "refpalette": "deceasedcraft:multi_nuclearpowerplant_26/multi_nuclearpowerplant_26_ground_palette",
  "xsize": 16,
  "zsize": 16,
  "slices": [
    [
      "                ",
      "                ",
      "                ",
      "                ",
      "                ",
      "                ",
      "                ",
      "                ",
      "                ",
      "                ",
      "                ",
      "                ",
      "                ",
      "                ",
      "                ",
      "                "
    ],
    [
      "                ",
      "                ",
      "                ",
      "                ",
      "                ",
      "                ",
      "                ",
      "                ",
      "                ",
      "                ",
      "               a",
      "              aa",
      "            aaaa",
      "           aaaaa",
      "        aaaaaaaa",
      "     aaaaaaaaaaa"
    ],
    [
      "              aa",
      "             aaa",
      "             aaa",
      "            aaaa",
      "           aaaaa",
      "          aaaaaa",
      "         aaaaaaa",
      "        aaaaaaaa",
      "       aaaaaaaaa",
      "     aaaaaaaaaaa",
      "  aaaaaaaaaaaaaa",
      "aaaaaaaaaaaaaaaa",
      "aaaaaaaaaaaaaaaz",
      "aaaaaaaaaaaaazzz",
      "aaaaaaaaaaazzzzz",
      "aaaaaaaaazzzzzzz"
    ],
    [
      "      aaaaaaaaaz",
      "     aaaaaaaaaaz",
      "    aaaaaaaaaazz",
      "   aaaaaaaaaaazz",
      "  aaaaaaaaaaazzz",
      "aaaaaaaaaaaazzzz",
      "aaaaaaaaaaazzzzz",
      "aaaaaaaaaazzzzzz",
      "aaaaaaaaazzzzzzz",
      "aaaaaaaazzzzzzzz",
      "aaaaaazzzzzzzzzz",
      "aaazzzzzzzzzzzzz",
      "zzzzzzzbzzzzzzzz",
      "zzzzzzzzzzzzbz  ",
      "zzzzzzzzzzzz   c",
      "zzzzzzzzzc      "
    ],
    [
      "aaaaaaaazzzzzzzz",
      "aaaaaaazzzzzzzzc",
      "aaaaaazzzzzzzz  ",
      "aaaaazzzzzzzzz  ",
      "aaaazzzzzzzzzzzc",
      "aaazzzzzzzzz c c",
      "azzbzzzzzzz    c",
      "zzzzzzzzzzz     ",
      "zzzzzzzzz zc c  ",
      "zzzzzzzz    cdc ",
      "zzzzzzc  c    c ",
      "zzz ezc     c c ",
      "  e           c ",
      "   cd   c cc    ",
      "  c    cce      ",
      "    c  cc       "
    ],
    [
      "zzzzzzzz        ",
      "zzzzzzz     c   ",
      "zzzzzzc         ",
      "zzzzz  ccc e    ",
      "zzzzz cc     cc ",
      "zzzc cd         ",
      "zzc             ",
      " c    c         ",
      " c        e     ",
      "      cc        ",
      "   c            ",
      "                ",
      "                ",
      "                ",
      "                ",
      "                "
    ]
  ]
}