{
  "name": "multi_nuclearpowerplant_26_base9",
  "refpalette": "deceasedcraft:multi_nuclearpowerplant_26/multi_nuclearpowerplant_26_base9_palette",
  "xsize": 16,
  "zsize": 16,
  "slices": [
    [
      "                ",
      "                ",
      "                ",
      "                ",
      "                ",
      "                ",
      "                ",
      "                ",
      "  a a  bb       ",
      "cccccccccccccccc",
      "dddddddddddddddd",
      "eeeeeeeeeeeeeeee",
      "eeeeeeeeeeeeeeee",
      "eeeeeeeeeeeeeeee",
      "eeeeeeeeeeeeeeee",
      "eeeeeeeeeeeeeeee"
    ],
    [
      "                ",
      "                ",
      "                ",
      "                ",
      "                ",
      "                ",
      "                ",
      "                ",
      "  a a  bb       ",
      "cccccccccccccccc",
      "dddddddddddddddd",
      "eeeeeeeeeeeeeeee",
      "eeeeeeeeeeeeeeee",
      "eeeeeeeeeeeeeeee",
      "eeeeeeeeeeeeeeee",
      "eeeeeeeeeeeeeeee"
    ],
    [
      "                ",
      "                ",
      "                ",
      "                ",
      "                ",
      "                ",
      "                ",
      "                ",
      "  a a  bb       ",
      "cccccccccccccccc",
      "dddddddddddddddd",
      "eeeeeeeeeeeeeeee",
      "eeeeeeeeeeeeeeee",
      "eeeeeeeeeeeeeeee",
      "eeeeeeeeeeeeeeee",
      "eeeeeeeeeeeeeeee"
    ],
    [
      "                ",
      "                ",
      "                ",
      "                ",
      "                ",
      "                ",
      "                ",
      "       ff       ",
      "  a a  bb       ",
      "cccccccccccccccc",
      "dddddddddddddddd",
      "eeeeeeeeeeeeeeed",
      "eeeeeeeeeeeeeeed",
      "eeeeeeeeeeeeeeed",
      "eeeeeeeeeeeeeeed",
      "eeeeeeeeeeeeeeed"
    ],
    [
      "                ",
      "                ",
      "                ",
      "                ",
      "                ",
      "                ",
      "                ",
      "aaaaaaaaaaaaaaaa",
      "  a a  bb       ",
      "cccccccccccccccc",
      "dddddddddddddddd",
      "eeeeeeeeeeeeeeed",
      "eeeeeeeeeeeeeeed",
      "eeeeeeeeeeeeeeed",
      "eeeeeeeeeeeeeeed",
      "eeeeeeeeeeeeeeed"
    ],
    [
      "                ",
      "                ",
      "                ",
      "                ",
      "                ",
      "                ",
      "                ",
      "                ",
      "       bb       ",
      "cccccccccccccccc",
      "dddddddddddddddd",
      "eeeeeeeeeeeeeeed",
      "eeeeeeeeeeeeeeed",
      "eeeeeeeeeeeeeeed",
      "eeeeeeeeeeeeeeed",
      "eeeeeeeeeeeeeeed"
    ]
  ]
}