{
  "name": "multi_nuclearpowerplant_26_base7",
  "refpalette": "deceasedcraft:multi_nuclearpowerplant_26/multi_nuclearpowerplant_26_base7_palette",
  "xsize": 16,
  "zsize": 16,
  "slices": [
    [
      "                ",
      "                ",
      "                ",
      "                ",
      "                ",
      "           aaa a",
      "          ba aca",
      "           aaa a",
      "                ",
      "           aaa a",
      "         dea afa",
      "           aaa a",
      "                ",
      "           aaa a",
      "          ga aha",
      "           aaa a"
    ],
    [
      "                ",
      "                ",
      "                ",
      "                ",
      "                ",
      "           aaa a",
      "           a a a",
      "           aaa a",
      "                ",
      "           aaa a",
      "         d a a a",
      "           aaa a",
      "                ",
      "           aaa a",
      "           a a a",
      "           aaa a"
    ],
    [
      "                ",
      "                ",
      "                ",
      "                ",
      "                ",
      "           aaa a",
      "           a a a",
      "           aaa a",
      "                ",
      "           aaa a",
      "         d a a a",
      "           aaa a",
      "                ",
      "           aaa a",
      "           a a a",
      "           aaa a"
    ],
    [
      "                ",
      "                ",
      "                ",
      "                ",
      "                ",
      "           aaa a",
      "           aaa a",
      "           aaa a",
      "                ",
      "           aaa a",
      "         d aaa a",
      "           aaa a",
      "                ",
      "           aaa a",
      "           aaa a",
      "           aaa a"
    ],
    [
      "                ",
      "                ",
      "                ",
      "                ",
      "                ",
      "                ",
      "                ",
      "                ",
      "                ",
      "                ",
      "         d      ",
      "                ",
      "                ",
      "                ",
      "                ",
      "                "
    ],
    [
      "iiiiiiiiiiiiiiii",
      "iiiiiiiiiiiiiiii",
      "iiiiiiiiiiiiiiii",
      "iiiiiiiiiiiiiiii",
      "iiiiiiiiiiiiiiii",
      "iiiiiiiiiiiiiiii",
      "iiiiiiiiiiiiiiii",
      "iiiiiiiiiiiiiiii",
      "iiiiiiiiiiiiiiii",
      "iiiiiiiiiiiiiiii",
      "iiiiiiiiidiiiiii",
      "iiiiiiiiiiiiiiii",
      "iiiiiiiiiiiiiiii",
      "iiiiiiiiiiiiiiii",
      "iiiiiiiiiiiiiiii",
      "iiiiiiiiiiiiiiii"
    ]
  ]
}