{
  "name": "multi_nuclearpowerplant_26_base1",
  "refpalette": "deceasedcraft:multi_nuclearpowerplant_26/multi_nuclearpowerplant_26_base1_palette",
  "xsize": 16,
  "zsize": 16,
  "slices": [
    [
      "        aabbbbbb",
      "       aabbbbbbb",
      "      aabbbbbbbc",
      "      abbbbbbbbc",
      "     aabbbbbbbbc",
      "    aabbbbbbbbcc",
      "   aabbbbbbbbbcc",
      " aaabbbbbbbbbccc",
      "aabbbbbbbbbbbccc",
      "abbbbbbbbbbbbccc",
      "bbbbbbbbbbbbcccc",
      "bbbbbbbbbbbbcccc",
      "bbbbbbbbbbbccccc",
      "bbbbbbbbbbbccccc",
      "bbbbbbbbbbcccccc",
      "bbbbbbbbbbcccccc"
    ],
    [
      "        dd      ",
      "       dd       ",
      "      dd       e",
      "      d        e",
      "     dd        e",
      "    dd        ef",
      "   dd         eb",
      " ddd         efb",
      "dd           ebc",
      "d            ebc",
      "            ebcc",
      "            ebcc",
      "           ebccc",
      "           ebccc",
      "          ebcccc",
      "          ebcccc"
    ],
    [
      "                ",
      "                ",
      "                ",
      "                ",
      "                ",
      "                ",
      "                ",
      "                ",
      "               e",
      "               e",
      "              ef",
      "              eb",
      "             efb",
      "             ebc",
      "            ebcc",
      "            bccc"
    ],
    [
      "                ",
      "                ",
      "                ",
      "                ",
      "                ",
      "                ",
      "                ",
      "                ",
      "                ",
      "                ",
      "                ",
      "                ",
      "                ",
      "               e",
      "              eb",
      "             ebc"
    ],
    [
      "                ",
      "                ",
      "                ",
      "                ",
      "                ",
      "                ",
      "                ",
      "                ",
      "                ",
      "                ",
      "                ",
      "                ",
      "                ",
      "                ",
      "                ",
      "               e"
    ],
    [
      "                ",
      "                ",
      "                ",
      "                ",
      "                ",
      "                ",
      "                ",
      "                ",
      "                ",
      "                ",
      "                ",
      "                ",
      "                ",
      "                ",
      "                ",
      "                "
    ]
  ]
}