{
  "name": "multi_gunstore_0_base1",
  "refpalette": "deceasedcraft:multi_gunstore_0/multi_gunstore_0_base1_palette",
  "xsize": 16,
  "zsize": 16,
  "slices": [
    [
      "vvvvvvvvvvvvvvvv",
      "vaaaaaaaaaaaaaaa",
      "vabbbbbbbbbbbbbb",
      "vabbbbbbbbbbbbbb",
      "vabbbbbbbbbbbbbb",
      "vabbbbbbbbbbbbbb",
      "vabbbbbbbbbbbbbb",
      "vabbbbbbbbbbbbbb",
      "vabbbbbbbbbbbbbb",
      "vabbbbbbbbbbbbbb",
      "vabbbbbbbbbbbbbb",
      "vabbbbbbbbbbbbbb",
      "vabbbbbbbbbbbbbb",
      "vabbbbbbbbbbbbbb",
      "vaaaaaaaaaaaaaaa",
      "vvvvvvvvvvvvvvvv"
    ],
    [
      "vvvvvvvvvvvvvvvv",
      "vaaaaaaaaaaaaaaa",
      "vaccdeffgfffefgf",
      "vahi            ",
      "va              ",
      "va       j      ",
      "va    kkkkkkk   ",
      "val   kmkkkmk   ",
      "val   kmkkkmk   ",
      "va    kkkkkkk   ",
      "van       o     ",
      "va  p    q      ",
      "varrr s         ",
      "varrrrrp tuuwxxy",
      "vaaaaaaaaaaaaaaa",
      "vvvvvvvvvvvvvvvv"
    ],
    [
      "vvvvvvvvvvvvvvvv",
      "vaaaaaaaaaaaaaaa",
      "va    A BCDE FeI",
      "va              ",
      "va             J",
      "va              ",
      "va    sKL pM    ",
      "va    N  O  P   ",
      "va     Q        ",
      "va    K RSK n   ",
      "va              ",
      "va              ",
      "va s            ",
      "var rp     T    ",
      "vaaaaaaaaaaaaaaa",
      "vvvvvvvvvvvvvvvv"
    ],
    [
      "vvvvvvvvvvvvvvvv",
      "vaaaaaaaaaaaaaaa",
      "va              ",
      "va              ",
      "va              ",
      "va              ",
      "va              ",
      "va              ",
      "va              ",
      "va              ",
      "va              ",
      "va              ",
      "va              ",
      "vap             ",
      "vaaaaaaaaaaaaaaa",
      "vvvvvvvvvvvvvvvv"
    ],
    [
      "vvvvvvvvvvvvvvvv",
      "vaaaaaaaaaaaaaaa",
      "va              ",
      "va              ",
      "va              ",
      "va              ",
      "va              ",
      "va              ",
      "va              ",
      "va              ",
      "va              ",
      "va              ",
      "va              ",
      "va              ",
      "vaaaaaaaaaaaaaaa",
      "vvvvvvvvvvvvvvvv"
    ],
    [
      "vvvvvvvvvvvvvvvv",
      "vaaaaaaaaaaaaaaa",
      "vammmmmmmmmmmmmm",
      "vamUUUUUUUUUUUUU",
      "vamUUUUUUUUUUUUU",
      "vamUUUUUUUUUUUUV",
      "vamUUUWWWWWWWUUV",
      "vamUUUWWWWWWWUUV",
      "vamUUUWWWWWWWUUV",
      "vamUUUWWWWWWWUUV",
      "vamUUUUUUUUUUUUV",
      "vamUUUUUUUUUUUUU",
      "vamUUUUUUUUUUUUU",
      "vammmmmmmmmmmmmm",
      "vaaaaaaaaaaaaaaa",
      "vvvvvvvvvvvvvvvv"
    ]
  ]
}