{
  "name": "multi_gunstore_0_ground",
  "refpalette": "deceasedcraft:multi_gunstore_0/multi_gunstore_0_ground_palette",
  "xsize": 16,
  "zsize": 16,
  "slices": [
    [
      "aaaaHHHHHHHHHHHH",
      "aaaaHHHHHHHHHHHH",
      "aaaaHHHbbbbbbbbb",
      "bbbbHHbcccddcccc",
      "bbbbHHbcceffdccc",
      "bbbbHHbcgefffdcc",
      "bbbbHHbchceiffcc",
      "bbbbHHbcccefffcc",
      "bbbbHHbcgcccjfcc",
      "bbbbHHbcgcccjfcc",
      "bbbbHHbckcccjfcc",
      "bbbbHHbcccccelcc",
      "bbbbHHbccccccccc",
      "aaaaHHHbbbbbbbbb",
      "aaaaHHHHHHHHHHHH",
      "aaaaHHHHHHHHHHHH"
    ],
    [
      "   m            ",
      "   m            ",
      "mmmm            ",
      "n  o            ",
      "p  q            ",
      "n  o            ",
      "p  q            ",
      "n  o            ",
      "p  q            ",
      "n  o            ",
      "p  q            ",
      "nr o            ",
      "p  q            ",
      "mmmm            ",
      "   m            ",
      "   m            "
    ],
    [
      "                ",
      "                ",
      "        ssssssss",
      "                ",
      "                ",
      "                ",
      "                ",
      "                ",
      "                ",
      "                ",
      "                ",
      "                ",
      "                ",
      "        tttttttt",
      "                ",
      "                "
    ],
    [
      "                ",
      "                ",
      "        ssssssss",
      "                ",
      "                ",
      "                ",
      "                ",
      "                ",
      "                ",
      "                ",
      "                ",
      "                ",
      "                ",
      "        tttttttt",
      "                ",
      "                "
    ],
    [
      "                ",
      "                ",
      "        uuuuuuuu",
      "        wxxxxxxx",
      "        wxxxxxxx",
      "        wxyxxxxy",
      "        wxxxxxxx",
      "        wxxxxxxx",
      "        wxxxxxxx",
      "        wxxxxxxx",
      "        wxyxxxxy",
      "        wxxxxxxx",
      "        wxxxxxxx",
      "        AAAAAAAA",
      "                ",
      "                "
    ],
    [
      "                ",
      "                ",
      "        BBBBBBBB",
      "        BBBBBBBB",
      "        BBBBBBBB",
      "        BBBBBBBB",
      "        BBBBBBBB",
      "        BBBBBBBB",
      "        BBBBBBBB",
      "        BBBBBBBB",
      "        BBBBBBBB",
      "        BBBBBBBB",
      "        BBBBBBBB",
      "        BBBBBBBB",
      "                ",
      "                "
    ]
  ]
}