{
  "name": "multi_terraceplaza_14_floor2",
  "refpalette": "deceasedcraft:multi_terraceplaza_14/multi_terraceplaza_14_floor2_palette",
  "xsize": 16,
  "zsize": 16,
  "slices": [
    [
      "                ",
      "                ",
      "                ",
      "                ",
      "                ",
      " a            a ",
      "                ",
      "                ",
      "                ",
      "                ",
      "                ",
      "                ",
      "                ",
      "                ",
      "                ",
      "                "
    ],
    [
      "                ",
      "                ",
      "                ",
      "                ",
      "                ",
      "babbbbbbbbbbbbab",
      "cdc          cec",
      "cdc          cec",
      "cdc          cec",
      "cdc          cec",
      "cdc          cec",
      "cdc          cec",
      "cdc          cec",
      "cdc          cec",
      "cdc          cec",
      "cdc          cec"
    ],
    [
      "                ",
      "ffffffffffffffff",
      "                ",
      "                ",
      " g            g ",
      "hahhhhhhhhhhhhah",
      "cicjjjjjjjjjjcic",
      "kiklmmmmmmmmlkik",
      "kiklnnnnnnnnlkik",
      "kiklnnnnnnnnlkik",
      "kiklnnnnnnnnlkik",
      "kiklnnnnnnnnlkik",
      "kiklnnnnnnnnlkik",
      "kiklnnnnnnnnlkik",
      "kikloooooooolkik",
      "cicppppppppppcic"
    ],
    [
      "qqqqqqqqqqqqqqqq",
      "rsssrssrrssrsssr",
      "tuttttttttttttut",
      "tuttttttttttttut",
      "cwccccccccccccwc",
      "xaxxxxxxxxxxxxax",
      "yxyyyyyyyyyyyyxy",
      "yxyyyyyyyyyyyyxy",
      "yxyyyyyyyyyyyyxy",
      "yxyyyyyyyyyyyyxy",
      "yxyyyyyyyyyyyyxy",
      "yxyyyyyyyyyyyyxy",
      "yxyyyyyyyyyyyyxy",
      "yxyyyyyyyyyyyyxy",
      "yxyyyyyyyyyyyyxy",
      "yxyyyyyyyyyyyyxy"
    ],
    [
      "qqqqqqqqqqqqqqqq",
      "rsssrssrrssrsssr",
      "AAAAAAAAAAAAAAAA",
      "AAAAAAAAAAAAAAAA",
      "AAAAAAAAAAAAAAAA",
      "AaAAAAAAAAAAAAaA",
      "AAAAAAAAAAAAAAAA",
      "AAAAAAAAAAAAAAAA",
      "AAAAAAAAAAAAAAAA",
      "AAAAAAAAAAAAAAAA",
      "AAAAAAAAAAAAAAAA",
      "AAAAAAAAAAAAAAAA",
      "AAAAAAAAAAAAAAAA",
      "AAAAAAAAAAAAAAAA",
      "AAAAAAAAAAAAAAAA",
      "AAAAAAAAAAAAAAAA"
    ],
    [
      "BBqBqBqqqBBqqBqB",
      "rsssrssrrssrsssr",
      "                ",
      "                ",
      "                ",
      " a            a ",
      "      CDDE      ",
      "    F      F    ",
      "       II       ",
      "   J        K   ",
      "   L I MM I N   ",
      "   L I MM I N   ",
      "   O        P   ",
      "                ",
      "                ",
      "  QQQQQQQQQQQQ  "
    ]
  ]
}