{
  "name": "multi_terraceplaza_14_base1",
  "refpalette": "deceasedcraft:multi_terraceplaza_14/multi_terraceplaza_14_base1_palette",
  "xsize": 16,
  "zsize": 16,
  "slices": [
    [
      "vvvvvvvvvvvvvvvv",
      "aaaaaaaaaaaaaaaa",
      "bbbbbbbbbbbbbbbb",
      "bbbbbbbbbbbbbbbb",
      "HHHHHHHHHHHHHHHH",
      "HcHHHHHHHHHHHHcH",
      "HHHHHHHHHHHHHHHH",
      "HHHHHHHHHHHHHHHH",
      "HHHHHHHHHHHHHHHH",
      "HHHHHHHHHHHHHHHH",
      "HHHHHHHHHHHHHHHH",
      "HHHHHHHHHHHHHHHH",
      "HHHHHHHHHHHHHHHH",
      "HHHHHHHHHHHHHHHH",
      "HHHHHHHHHHHHHHHH",
      "HHHHHHHHHHHHHHHH"
    ],
    [
      "vvvvvvvvvvvvvvvv",
      "aaaaaaaaaaaaaaaa",
      "                ",
      "                ",
      "defg h fg h fgid",
      "dc    j       cd",
      "defg h fg h fgid",
      "d             id",
      "d              d",
      "d              d",
      "d              d",
      "d              d",
      "d kkkkkkkkkkkk d",
      "dil ml ml ml med",
      "di n  n  n  n id",
      "di            ed"
    ],
    [
      "vvvvvvvvvvvvvvvv",
      "aaaaaaaaaaaaaaaa",
      "                ",
      "                ",
      "                ",
      " c            c ",
      "                ",
      "                ",
      "                ",
      "                ",
      "                ",
      "                ",
      "                ",
      "                ",
      "                ",
      "                "
    ],
    [
      "vvvvvvvvvvvvvvvv",
      "aaaaaaaaaaaaaaaa",
      "                ",
      "                ",
      "                ",
      " c            c ",
      "                ",
      "                ",
      "                ",
      "                ",
      "                ",
      "                ",
      "                ",
      "                ",
      "                ",
      "                "
    ],
    [
      "vvvvvvvvvvvvvvvv",
      "aaaaaaaaaaaaaaaa",
      "opoooooooooooopo",
      "qqqqqqqqqqqqqqqq",
      "qqqqqqqqqqqqqqqq",
      "qcqqqqqqqqqqqqcq",
      "                ",
      "                ",
      "           r    ",
      "                ",
      "                ",
      "                ",
      "                ",
      "    r           ",
      "                ",
      "                "
    ],
    [
      "vvvvvvvvvvvvvvvv",
      "aaaaaaaaaaaaaaaa",
      "stssssssssssssts",
      "utuuuuuuuuuuuutu",
      "utuu uuuuuu uutu",
      "tcttttttttttttct",
      "stssssssssssssts",
      "stssssssssssssts",
      "stsswsssssswssts",
      "stssssssssssssts",
      "stssssssssssssts",
      "stssssssssssssts",
      "stssssssssssssts",
      "stsswsssssswssts",
      "stssssssssssssts",
      "stssssssssssssts"
    ]
  ]
}