{
  "name": "multi_terraceplaza_14_base2",
  "refpalette": "deceasedcraft:multi_terraceplaza_14/multi_terraceplaza_14_base2_palette",
  "xsize": 16,
  "zsize": 16,
  "slices": [
    [
      "vvvvvvvvvvvvvvvv",
      "aaaaaaaaaaaaaaaa",
      "bbbbbbbbbbbbbbbb",
      "bbbbbbbbbbbbbbbb",
      "HHHHHHHHHHHHHHHH",
      "HcHHHHHHHHHHHHcH",
      "HHHHHHHHHHHHHHHH",
      "HHHHHHHHHHHHHHHH",
      "HHHHHHHHHHHHHHHH",
      "HHHHHHHHHHHHHHHH",
      "HHHHHHHHHHHHHHHH",
      "HHHHHHHHHHHHHHHH",
      "HHHHHHHHHHHH HHH",
      "HHHHHHHHHHHHHHHH",
      "HHHHHHHHHHHHHHHH",
      "HHHHHHHHHHHHHHHH"
    ],
    [
      "vvvvvvvvvvvvvvvv",
      "aaaaaaaaaaaaaaaa",
      "                ",
      "                ",
      "defg h fg h fgid",
      "dc    j    k  cd",
      "defg h fg h fgid",
      "d              d",
      "d              d",
      "d              d",
      "d              d",
      "d              d",
      "d llllllllllll d",
      "dim nm nm nm ned",
      "di o  o  o  o id",
      "di            ed"
    ],
    [
      "vvvvvvvvvvvvvvvv",
      "aaaaaaaaaaaaaaaa",
      "                ",
      "                ",
      "                ",
      " c            c ",
      "                ",
      "                ",
      "                ",
      "                ",
      "                ",
      "                ",
      "                ",
      "                ",
      "                ",
      "                "
    ],
    [
      "vvvvvvvvvvvvvvvv",
      "aaaaaaaaaaaaaaaa",
      "                ",
      "                ",
      "                ",
      " c            c ",
      "                ",
      "                ",
      "                ",
      "                ",
      "                ",
      "                ",
      "                ",
      "                ",
      "                ",
      "                "
    ],
    [
      "vvvvvvvvvvvvvvvv",
      "aaaaaaaaaaaaaaaa",
      "pppppppppppppppp",
      "qqqqqqqqqqqqqqqq",
      "qqqqqqqqqqqqqqqq",
      "qcqqqqqqqqqqqqcq",
      "                ",
      "                ",
      "                ",
      "                ",
      "                ",
      "                ",
      "                ",
      "    r           ",
      "                ",
      "                "
    ],
    [
      "vvvvvvvvvvvvvvvv",
      "aaaaaaaaaaaaaaaa",
      "ssssssssssssssss",
      "ssssssssssssssss",
      "ssssssssssssssss",
      "tcttttttttttttct",
      "stssssssssssssts",
      "stssssssssssssts",
      "stssussssssussts",
      "stssssssssssssts",
      "stssssssssssssts",
      "stssssssssssssts",
      "stssssssssssssts",
      "stssussssssussts",
      "stssssssssssssts",
      "stssssssssssssts"
    ]
  ]
}