{
  "name": "multi_terraceplaza_14_floor4",
  "refpalette": "deceasedcraft:multi_terraceplaza_14/multi_terraceplaza_14_floor4_palette",
  "xsize": 16,
  "zsize": 16,
  "slices": [
    [
      "aabbaabbbbbaabbb",
      "cdddcddccddcdddc",
      "                ",
      "                ",
      "                ",
      " e            e ",
      "                ",
      "                ",
      "                ",
      "                ",
      "                ",
      "                ",
      "                ",
      "ffffffffffffffff",
      "ffffffffffffffff",
      "ffffffffffffffff"
    ],
    [
      "abbaabaabbaabaab",
      "cdddcddccddcdddc",
      "                ",
      "                ",
      "                ",
      " e            e ",
      "                ",
      "                ",
      "                ",
      "                ",
      "                ",
      "                ",
      "                ",
      "gggggggggggggggg",
      "                ",
      "                "
    ],
    [
      "bbaaaabbbbaaabbb",
      "cdddcddccddcdddc",
      "                ",
      "                ",
      "                ",
      " e            e ",
      "                ",
      "                ",
      "                ",
      "                ",
      "                ",
      "                ",
      "                ",
      "                ",
      "                ",
      "                "
    ],
    [
      "aaaaaaaaaaaaaaaa",
      "cdddcddccddcdddc",
      "                ",
      "                ",
      "                ",
      " e            e ",
      "                ",
      "                ",
      "                ",
      "                ",
      "                ",
      "                ",
      "                ",
      "                ",
      "                ",
      "      hijk      "
    ],
    [
      "aaaaaaaaaaaaaaaa",
      "cdddcddccddcdddc",
      "                ",
      "                ",
      "                ",
      " e            e ",
      "                ",
      "                ",
      "                ",
      "                ",
      "                ",
      "                ",
      "                ",
      "                ",
      "                ",
      "      lmno      "
    ],
    [
      "aaaaaaaaaaaaaaaa",
      "cdddcddccddcdddc",
      "                ",
      "                ",
      "                ",
      " e            e ",
      "                ",
      "                ",
      "                ",
      "                ",
      "                ",
      "                ",
      "                ",
      "                ",
      "                ",
      "      pqrs      "
    ]
  ]
}