{
  "name": "multi_terraceplaza_14_floor3",
  "refpalette": "deceasedcraft:multi_terraceplaza_14/multi_terraceplaza_14_floor3_palette",
  "xsize": 16,
  "zsize": 16,
  "slices": [
    [
      "aabaaabbbaababba",
      "cdddcddccddcdddc",
      "                ",
      "                ",
      "                ",
      " e            e ",
      "                ",
      "           f    ",
      "                ",
      "                ",
      "                ",
      "                ",
      "                ",
      "                ",
      "                ",
      "                "
    ],
    [
      "abbaaabbbabbaaba",
      "cdddcddccddcdddc",
      "                ",
      "                ",
      "                ",
      " e            e ",
      "                ",
      "                ",
      "                ",
      "                ",
      "                ",
      "                ",
      "                ",
      "                ",
      "                ",
      "                "
    ],
    [
      "bbbbbbbbbbbbbbbb",
      "cdddcddccddcdddc",
      "                ",
      "                ",
      "                ",
      " e            e ",
      "                ",
      "                ",
      "                ",
      "                ",
      "                ",
      "                ",
      "                ",
      "                ",
      "                ",
      "                "
    ],
    [
      "bbbbbbbbbbbbbbbb",
      "cdddcddccddcdddc",
      "                ",
      "                ",
      "                ",
      " e            e ",
      "                ",
      "                ",
      "                ",
      "                ",
      "                ",
      "                ",
      "                ",
      "                ",
      "                ",
      "                "
    ],
    [
      "gbbggbgbbbggbgbb",
      "cdddcddccddcdddc",
      "                ",
      "                ",
      "                ",
      " e            e ",
      "                ",
      "                ",
      "                ",
      "                ",
      "                ",
      "                ",
      "                ",
      "                ",
      "                ",
      "                "
    ],
    [
      "ggggbbbgbggbbbgb",
      "cdddcddccddcdddc",
      "                ",
      "                ",
      "                ",
      " e            e ",
      "                ",
      "                ",
      "                ",
      "                ",
      "                ",
      "                ",
      "                ",
      "                ",
      "                ",
      "                "
    ]
  ]
}