{
  "name": "multi_terraceplaza_14_floor5",
  "refpalette": "deceasedcraft:multi_terraceplaza_14/multi_terraceplaza_14_floor5_palette",
  "xsize": 16,
  "zsize": 16,
  "slices": [
    [
      "aaaaaaaaaaaaaaaa",
      "bcccbccbbccbcccb",
      "                ",
      "                ",
      "                ",
      " d            d ",
      "                ",
      "                ",
      "                ",
      "                ",
      "                ",
      "                ",
      "                ",
      "                ",
      "                ",
      "                "
    ],
    [
      "aaaaaaaaaaaaaaaa",
      "bcccbccbbccbcccb",
      "eeeeeeeeeeeeeeee",
      "eeeeeeeeeeeeeeee",
      "ffffffffffffffff",
      "gdggggggggggggdg",
      "hghhhhhhhhhhhhgh",
      "hghhhhhhhhhhhhgh",
      "hghhhhhhhhhhhhgh",
      "hghhhhhhhhhhhhgh",
      "hghhhhhhhhhhhhgh",
      "hghhhhhhhhhhhhgh",
      "hghhhhhhhhhhhhgh",
      "hghhhhhhhhhhhhgh",
      "hghhhhhhhhhhhhgh",
      "hghhhhhhhhhhhhgh"
    ],
    [
      "aaaaaaaaaaaaaaaa",
      "bcccbccbbccbcccb",
      "                ",
      "                ",
      "iiiiiiiiiiiiiiii",
      "iiiiiiiiiiiiiiii",
      "iiiiiiiiiiiiiiii",
      "iiiiiiiiiiiiiiii",
      "iiiiiiiiiiiiiiii",
      "iiiiiiiiiiiiiiii",
      "iiiiiiiiiiiiiiii",
      "iiiiiiiiiiiiiiii",
      "iiiiiiiiiiiiiiii",
      "iiiiiiiiiiiiiiii",
      "iiiiiiiiiiiiiiii",
      "iiiiiiiiiiiiiiii"
    ],
    [
      "aaaaaaaaaaaaaaaa",
      "bcccbccbbccbcccb",
      "                ",
      "                ",
      "                ",
      "                ",
      "                ",
      "                ",
      "                ",
      "                ",
      "                ",
      "                ",
      "                ",
      "                ",
      "                ",
      "                "
    ],
    [
      "                ",
      "                ",
      "                ",
      "                ",
      "                ",
      "                ",
      "                ",
      "                ",
      "                ",
      "                ",
      "                ",
      "                ",
      "                ",
      "                ",
      "                ",
      "                "
    ],
    [
      "                ",
      "                ",
      "                ",
      "                ",
      "                ",
      "                ",
      "                ",
      "                ",
      "                ",
      "                ",
      "                ",
      "                ",
      "                ",
      "                ",
      "                ",
      "                "
    ]
  ]
}