{
  "name": "multi_militarybase_2_ground",
  "refpalette": "deceasedcraft:multi_militarybase_2/multi_militarybase_2_ground_palette",
  "xsize": 16,
  "zsize": 16,
  "slices": [
    [
      "zzzzzzzzzzzzzzzz",
      "aaaaaaaaaaaaaaaa",
      "bbzzzzbbzbzzzbbz",
      "zbbzbbbbbzbzbbzb",
      "ccccccccbbbbbbbb",
      "dddddddcbbbbbbef",
      "dddddddcbbbbbbbb",
      "dddddddcbgbbbbbb",
      "dddddddcbbbbbbbb",
      "cccddddcbbbbbhbb",
      "cccddddcbbbbbbbb",
      "cccddddcbbbbbbbb",
      "cccidddcbbbbbbbb",
      "ccccccccbbbbhbbb",
      "bbbbgbgbbbbbbbbb",
      "bbbbbbbbbbbjbbbb"
    ],
    [
      "                ",
      "aaaaaaaaaaaaaaaa",
      "  kk k l  k     ",
      "       m   no  p",
      "qqqqqqqqr    s  ",
      "ttu    wx  y p  ",
      "       w   A  BC",
      "  Dn   w   E p p",
      " F     w    I   ",
      "JqqKLMKq NO O As",
      "  qP  QqNORNO N ",
      "  qQ  SqNNNNNOr ",
      "  qiSS!qNNONN s ",
      "  qqqqqq OO   TU",
      "  V         W   ",
      "W       s       "
    ],
    [
      "                ",
      "aaaaaaaaaaaaaaaa",
      "       l        ",
      "       m        ",
      "XXXYYYYX        ",
      "  Z    w        ",
      "       w        ",
      "       w        ",
      "       w        ",
      "0XXK12KX        ",
      "  X    Y  NN    ",
      "  Y    Y ONNO   ",
      "  Xi P3XO       ",
      "  XXXXXX        ",
      "                ",
      "                "
    ],
    [
      "                ",
      "aaaaaaaaaaaaaaaa",
      "       l        ",
      "   4444m        ",
      "XXXXXXXX        ",
      "       w        ",
      "       w        ",
      "       w        ",
      "       w        ",
      "XXXKKKKX4       ",
      "  X    X4       ",
      "  Y    X4       ",
      "  Xi  3X4       ",
      "  XXXXXX        ",
      "                ",
      "                "
    ],
    [
      "                ",
      "aaaaaaaaaaaaaaaa",
      "       l        ",
      "       m        ",
      "XXX5555X        ",
      "  666667        ",
      "      67        ",
      "      67        ",
      "66    67        ",
      "5XX6666X        ",
      "  X   65        ",
      "  X3  65        ",
      "  Xi3 6X        ",
      "  XXXXXX        ",
      "                ",
      "                "
    ],
    [
      "                ",
      "88888889#8888888",
      "$$$$$$$%$$$$$$$$",
      "       m        ",
      "qqqqqqqq        ",
      "  ^^^^^q        ",
      "^^^^^^^q        ",
      "^^^^^^^q        ",
      "^^^^^^^q        ",
      "qqq^^^^q        ",
      "  q^^^^q        ",
      "  q^^^^q        ",
      "  qi^^^q        ",
      "  q^^^^q        ",
      "  q&&&&q        ",
      "  q&&&&q        "
    ]
  ]
}