{
  "name": "multi_militarybase_2_base3",
  "refpalette": "deceasedcraft:multi_militarybase_2/multi_militarybase_2_base3_palette",
  "xsize": 16,
  "zsize": 16,
  "slices": [
    [
      "vvvvvvvvvvvvvvvv",
      "abaaaaaaaaacaca ",
      "                ",
      "                ",
      "                ",
      "                ",
      "                ",
      "                ",
      "                ",
      "                ",
      "                ",
      "def  gg hge def ",
      "                ",
      "  v    v    v   ",
      "iii iii iii iii ",
      " j  kl   m   nop"
    ],
    [
      "vvvvvvvvvvvvvvvv",
      "baaabaacbaaaaaa ",
      "                ",
      "                ",
      "                ",
      "                ",
      "                ",
      "                ",
      "                ",
      "                ",
      "                ",
      "                ",
      "                ",
      "  v    v    v   ",
      "fge qef qgf geq ",
      "                "
    ],
    [
      "vvvvvvvvvvvvvvvv",
      "acbaaaaaaaaacac ",
      "                ",
      "                ",
      "                ",
      "                ",
      "                ",
      "                ",
      "                ",
      "                ",
      "                ",
      "                ",
      "                ",
      "  v    v    v   ",
      "                ",
      "                "
    ],
    [
      "vvvvvvvvvvvvvvvv",
      "aaaaabbaaaaaaaa ",
      "                ",
      "                ",
      "                ",
      "                ",
      "                ",
      "                ",
      "                ",
      "                ",
      "                ",
      "                ",
      "                ",
      "  v    v    v   ",
      "                ",
      "                "
    ],
    [
      "vvvvvvvvvvvvvvvv",
      "                ",
      "                ",
      "                ",
      "                ",
      "                ",
      "                ",
      "                ",
      "                ",
      "                ",
      "                ",
      "                ",
      "                ",
      "rrvrrrrvrrrrvrrr",
      "                ",
      "                "
    ],
    [
      "vvvvvvvvvvvvvvvv",
      "ssssssssssssssss",
      "tttttttttttttttt",
      "uuuuuutttuuuuuuu",
      "tttttttttttttttt",
      "tttttttttttttttt",
      "tttttttttttttttt",
      "uuuuuutttuuuuuuu",
      "tttttttttttttttt",
      "tttttttttttttttt",
      "tttttttttttttttt",
      "uuuuuutttuuuuuuu",
      "tttttttttttttttt",
      "wwvwwwwvwwwwvwww",
      "                ",
      "                "
    ]
  ]
}