{
  "name": "multi_militarybase_2_base2",
  "refpalette": "deceasedcraft:multi_militarybase_2/multi_militarybase_2_base2_palette",
  "xsize": 16,
  "zsize": 16,
  "slices": [
    [
      "vvvvvvvvvvvvvvvv",
      "aaaaaaavaaaaaaaa",
      "aaaaaaabaaaaaaaa",
      "aaaaaaabaaaaaaaa",
      "aaaaaaabaaaaaaaa",
      "bbbbbbbvbbbbbbbb",
      "aaaaaaabaaaaaaaa",
      "aaaaaaabaaaaaaaa",
      "aaaaaaabaaaaaaaa",
      "cccccccvcccccccd",
      "eeeeeeebeeeeeeee",
      "eeeeeeebeeeeeeee",
      "eeeeeeebeeeeeeee",
      "bbvbbbbvbbbbvbbb",
      "  f    f    f   ",
      "                "
    ],
    [
      "vvvvvvvvvvvvvvvv",
      "gh!hijkv lmnoh h",
      " p pq rhs    p p",
      "tuwui rpxsw    y",
      " AB C rDEx FIyCJ",
      "KKLKKKKvKKKMKKKK",
      "       N        ",
      "       O        ",
      "PQ QPQR  QPP QQQ",
      "SSSSSSKvKSSSSSSS",
      "                ",
      "              T ",
      "U               ",
      "VVvVVVVvVVVVvVVV",
      "                ",
      "                "
    ],
    [
      "vvvvvvvvvvvvvvvv",
      " h     v        ",
      " p     hx       ",
      " u     px       ",
      "       DEx      ",
      "KKWKKKKvKKKXKKKK",
      "                ",
      "                ",
      "Y   Z  0  12    ",
      "SS3SS4KvK5S6!SS7",
      "                ",
      "                ",
      "                ",
      "  v    v    v   ",
      "                ",
      "                "
    ],
    [
      "vvvvvvvvvvvvvvvv",
      "       v        ",
      "       hx       ",
      "       px       ",
      "       u        ",
      "KKKKKKKvKKKKKKKK",
      "                ",
      "                ",
      "                ",
      "KKKKKKKvKKKKKKKK",
      "                ",
      "                ",
      "                ",
      "  v    v    v   ",
      "                ",
      "                "
    ],
    [
      "vvvvvvvvvvvvvvvv",
      "       v        ",
      "                ",
      "                ",
      "                ",
      "KKKKKKKvKKKKKKKK",
      "       V        ",
      "       V        ",
      "       V        ",
      "VVVVVVVvVVVVVVVV",
      "                ",
      "                ",
      "                ",
      "88v8888v8888v888",
      "                ",
      "                "
    ],
    [
      "vvvvvvvvvvvvvvvv",
      "99!9999v99999999",
      "#######b########",
      "#######b########",
      "#######b########",
      "bbbbbbbvbbbbbbbb",
      "#######b########",
      "#######b########",
      "#######b########",
      "#######v########",
      "#######b########",
      "#######b########",
      "#######b########",
      "$$v$$$$v$$$$v$$$",
      "                ",
      "                "
    ]
  ]
}