{
  "name": "multi_militarybase_2_base1",
  "refpalette": "deceasedcraft:multi_militarybase_2/multi_militarybase_2_base1_palette",
  "xsize": 16,
  "zsize": 16,
  "slices": [
    [
      "vvvvvvvvvvvvvvvv",
      "aaaaaaavaaaaaaaa",
      "aaaaaaabaaaaaaaa",
      "aaaaaaabaaaaaaaa",
      "aaaaaaabaaaaaaaa",
      "bbbbbbbvbbbbbbbb",
      "aaaaaaabaaaaaaaa",
      "aaaaaaabaaaaaaaa",
      "aaaaaaabaaaaaaaa",
      "cccccccvcccccccc",
      "dddddddbdddddddd",
      "dddddddbdddddddd",
      "dddddddbdddddddd",
      "bbvbbbbvbbbbvbbb",
      "  e    e    e   ",
      "                "
    ],
    [
      "vvvvvvvvvvvvvvvv",
      "       v        ",
      "                ",
      "                ",
      "                ",
      "       v        ",
      "                ",
      "                ",
      "                ",
      "       v        ",
      "                ",
      "                ",
      "                ",
      "ffvffffvffffvfff",
      "                ",
      "                "
    ],
    [
      "vvvvvvvvvvvvvvvv",
      "       v        ",
      "                ",
      "                ",
      "                ",
      "       v        ",
      "                ",
      "                ",
      "                ",
      "       v        ",
      "                ",
      "                ",
      "                ",
      "  v    v    v   ",
      "                ",
      "                "
    ],
    [
      "vvvvvvvvvvvvvvvv",
      "       v        ",
      "                ",
      "                ",
      "                ",
      "       v        ",
      "                ",
      "                ",
      "                ",
      "       v        ",
      "                ",
      "                ",
      "                ",
      "  v    v    v   ",
      "                ",
      "                "
    ],
    [
      "vvvvvvvvvvvvvvvv",
      "       v        ",
      "                ",
      "                ",
      "                ",
      "       v        ",
      "                ",
      "                ",
      "                ",
      "       v        ",
      "                ",
      "                ",
      "                ",
      "ggvggggvggggvggg",
      "                ",
      "                "
    ],
    [
      "vvvvvvvvvvvvvvvv",
      "hhhhhhhvhhhhhhhh",
      "iiiiiiibiiiiiiii",
      "iiiiiiibiiiiiiii",
      "iiiiiiibiiiiiiii",
      "bbbbbbbvbbbbbbbb",
      "iiiiiiibiiiiiiii",
      "iiiiiiibiiiiiiii",
      "iiiiiiibiiiiiiii",
      "iiiiiiiviiiiiiii",
      "iiiiiiibiiiiiiii",
      "iiiiiiibiiiiiiii",
      "iiiiiiibiiiiiiii",
      "bbvbbbbvbbbbvbbb",
      "jjjjjjjjjjjjjjjj",
      "jjjjjjjjjjjjjjjj"
    ]
  ]
}