{
  "name": "multi_militarybase_2_base4",
  "refpalette": "deceasedcraft:multi_militarybase_2/multi_militarybase_2_base4_palette",
  "xsize": 16,
  "zsize": 16,
  "slices": [
    [
      "vvvvvvvvvvvvvvvv",
      "aaaaaaaaaaaaaaaa",
      "aaaaaaaaaaaaaaaa",
      "aaaaaaaaaaaaaaaa",
      "aaaaaaaaaaaaaaaa",
      "bbbbbbbbbbbbbbbb",
      "aaaaaaaaaaaaaaaa",
      "aaaaaaaaaaaaaaaa",
      "aaaaaaaaaaaaaaaa",
      "aaaaaaaaaaaaaaaa",
      "aaaaaaaaaaaaaaaa",
      "aaaaaaaaaaaaaaaa",
      "aaaaaaaaaaaaaaaa",
      "bbvbbbbvbbbbvbbb",
      "cccccccccccccccc",
      "cccccccccccccccc"
    ],
    [
      "vvvvvvvvvvvvvvvv",
      "dddddddddddddddd",
      "dddddddddddddddd",
      "dddddddddddddddd",
      "dddddddddddddddd",
      "dddddddddddddddd",
      "dddddddddddddddd",
      "dddddddddddddddd",
      "ef ggggh iijjj f",
      "k    gh   i jl  ",
      "                ",
      "                ",
      "                ",
      "ddvddddvddddvddd",
      "mn mmnm nmmm mnm",
      "                "
    ],
    [
      "vvvvvvvvvvvvvvvv",
      "oo oooo oooo ooo",
      "    pq   r  st u",
      "r    r   w      ",
      "        xy   wAB",
      "ddddd!ddddddd!dd",
      "dddddddddddddddd",
      "dddddddddddddddd",
      "f  g  g    i    ",
      "                ",
      "                ",
      "                ",
      "                ",
      "ddvddddvddddvddd",
      " C   D  E     F ",
      "                "
    ],
    [
      "vvvvvvvvvvvvvvvv",
      " I I  I I I  I I",
      "                ",
      "                ",
      "                ",
      "ooo ooo ooo ooo ",
      " J   J    w     ",
      "        J K  J B",
      "dddddddddddddddd",
      "dddddddddddddddd",
      "LLLLLLLLLLLLLLLL",
      "                ",
      "MMMMMMMMMMMMMMMM",
      "ddvddddvddddvddd",
      "                ",
      "                "
    ],
    [
      "vvvvvvvvvvvvvvvv",
      "NNNNNONNNNNNOPN ",
      "                ",
      "                ",
      "                ",
      " QR SQT RQ  SQR ",
      "                ",
      "                ",
      "ooo ooo ooo ooo ",
      " J   U    V  V  ",
      "   WX      YZ  B",
      "ddddd!ddddddd!dd",
      "dddddddddddddddd",
      "ddvddddvddddvddd",
      "                ",
      "                "
    ],
    [
      "vvvvvvvvvvvvvvvv",
      "NNNONNNNOONNNOO ",
      "                ",
      "                ",
      "                ",
      "                ",
      "                ",
      "                ",
      "0Q  QQ1  RT Q 2 ",
      "                ",
      "                ",
      "ooo ooo ooo ooo ",
      "  U   U V       ",
      "  v    v!   v JB",
      "LLLLLLLLLLLLLLLL",
      "3333333333333333"
    ]
  ]
}