{
  "name": "multi_farmhouse1_8_floor1",
  "refpalette": "deceasedcraft:multi_farmhouse1_8/multi_farmhouse1_8_floor1_palette",
  "xsize": 16,
  "zsize": 16,
  "slices": [
    [
      "abbaaaabbccccbbb",
      "aaaaababccccccbb",
      "baababbcccccccbb",
      "aababbbcccccccbb",
      "baaabbbcccccccbb",
      "ababbbbcccccccbb",
      "baabbbbcccccccbb",
      "babbbbbcccccccbb",
      "aabbbbbcccccccbb",
      "ababbbbcccccccbb",
      "aabbbbbcccccccbb",
      "aabbbbbcccccccbb",
      "abbbbbbcccccccbb",
      "bbbbbbbcccccccbb",
      "bbbbbbbbbbbbbbbb",
      "bbbbbbbbbbbbbbbb"
    ],
    [
      "ddddddddddddddde",
      "ddddddddddddddde",
      "ddddddfdddddddge",
      "ddddddfhiiiiihge",
      "ddddddfdddddddge",
      "ddddddfdjkkkjdge",
      "ddddddfddkkkddgd",
      "ddddddfddkkkddge",
      "ddddddfdlkkkldge",
      "ddddddfdmkkkmdgn",
      "ddddddfdddodddge",
      "ddddddfdooooodge",
      "dddpddfdddddddge",
      "ddddddfhhhhhhhge",
      "dddqddfdddddddge",
      "dedeeeeeenedeeee"
    ],
    [
      "dddddddddddddddd",
      "dddddddddddddddd",
      "ddddddfdddddddgd",
      "ddddddfhiiiiihgd",
      "ddddddfddrdrddgd",
      "ddddddfdstutvdgd",
      "ddddddfddtttddgd",
      "ddddddfdwtttddgd",
      "ddddddfdxytyxdgd",
      "ddddddfdzytyzdgd",
      "ddddddfddAoAddgd",
      "ddddddfdddodddgd",
      "dddBddfdddddddgd",
      "ddddddfhhhhhhhgd",
      "ddddddfdddddddgd",
      "dddddddddddddddd"
    ],
    [
      "dddddddddddddddd",
      "dddddddddddddddd",
      "ddddddfdddddddgd",
      "ddddddfhiiiiihgd",
      "ddddddfdddddddgd",
      "ddddddfddCCCddgd",
      "ddddddfddtDEddgd",
      "ddddddfddFdGddgd",
      "ddddddfdsGdGvdgd",
      "ddddddfdsHIHvdgd",
      "ddddddfddAAAddgd",
      "ddddddfdddddddgd",
      "ddddddfdddddddgd",
      "ddddddfhhhhhhhgd",
      "ddddddfdddddddgd",
      "dddddddddddddddd"
    ],
    [
      "dddddddddddddddd",
      "dddddddddddddddd",
      "ddddddfgdddddfgd",
      "ddddddfhiiiiihgd",
      "ddddddfgdddddfgd",
      "ddddddfgdddddfgd",
      "ddddddfgdJJddfgd",
      "ddddddfgdKdGdfgd",
      "ddddddfgdGdGdfgd",
      "ddddddfgdGdGdfgd",
      "ddddddfgdLLLdfgd",
      "ddddddfgdddddfgd",
      "ddddddfgdddddfgd",
      "ddddddfhhhhhhhgd",
      "ddddddfgdddddfgd",
      "dddddddddddddddd"
    ],
    [
      "dddddddddddddddd",
      "dddddddddddddddd",
      "dddddddMgdddfNdd",
      "dddddddMiiiiiNdd",
      "dddddddMgdddfNdd",
      "dddddddMgdddfNdd",
      "dddddddMgdddfNdd",
      "dddddddMgOOOfNdd",
      "dddddddMgOOOfNdd",
      "dddddddMgOOOfNdd",
      "dddddddMgdddfNdd",
      "dddddddMgdddfNdd",
      "dddddddMgdddfNdd",
      "dddddddMhhihhNdd",
      "dddddddMgdddfNdd",
      "dddddddddddddddd"
    ]
  ]
}