{
  "name": "multi_farmhouse1_8_top",
  "refpalette": "deceasedcraft:multi_farmhouse1_8/multi_farmhouse1_8_top_palette",
  "xsize": 16,
  "zsize": 16,
  "slices": [
    [
      "aaaaaaaaaaaaaaaa",
      "aaaaaaaaaaaaaaaa",
      "aaaaaaaabcadeaaa",
      "aaaaaaaabfffeaaa",
      "aaaaaaaabcadeaaa",
      "aaaaaaaabcadeaaa",
      "aaaaaaaabcadeaaa",
      "aaaaaaaabcadeaaa",
      "aaaaaaaabcadeaaa",
      "aaaaaaaabcadeaaa",
      "aaaaaaaabcadeaaa",
      "aaaaaaaabcadeaaa",
      "aaaaaaaabcadeaaa",
      "aaaaaaaabfffeaaa",
      "aaaaaaaabcadeaaa",
      "aaaaaaaaaaaaaaaa"
    ],
    [
      "aaaaaaaaaaaaaaaa",
      "aaaaaaaaaaaaaaaa",
      "aaaaaaaaabgeaaaa",
      "aaaaaaaaabfeaaaa",
      "aaaaaaaaabgeaaaa",
      "aaaaaaaaabgeaaaa",
      "aaaaaaaaabgeaaaa",
      "aaaaaaaaabgeaaaa",
      "aaaaaaaaabgeaaaa",
      "aaaaaaaaabgeaaaa",
      "aaaaaaaaabgeaaaa",
      "aaaaaaaaabgeaaaa",
      "aaaaaaaaabgeaaaa",
      "aaaaaaaaabfeaaaa",
      "aaaaaaaaabgeaaaa",
      "aaaaaaaaaaaaaaaa"
    ],
    [
      "aaaaaaaaaaaaaaaa",
      "aaaaaaaaaaaaaaaa",
      "aaaaaaaaaahaaaaa",
      "aaaaaaaaaahaaaaa",
      "aaaaaaaaaahaaaaa",
      "aaaaaaaaaahaaaaa",
      "aaaaaaaaaahaaaaa",
      "aaaaaaaaaahaaaaa",
      "aaaaaaaaaahaaaaa",
      "aaaaaaaaaahaaaaa",
      "aaaaaaaaaahaaaaa",
      "aaaaaaaaaahaaaaa",
      "aaaaaaaaaahaaaaa",
      "aaaaaaaaaahaaaaa",
      "aaaaaaaaaahaaaaa",
      "aaaaaaaaaaaaaaaa"
    ],
    [
      "aaaaaaaaaaaaaaaa",
      "aaaaaaaaaaaaaaaa",
      "aaaaaaaaaaaaaaaa",
      "aaaaaaaaaaaaaaaa",
      "aaaaaaaaaaaaaaaa",
      "aaaaaaaaaaaaaaaa",
      "aaaaaaaaaaaaaaaa",
      "aaaaaaaaaaaaaaaa",
      "aaaaaaaaaaaaaaaa",
      "aaaaaaaaaaaaaaaa",
      "aaaaaaaaaaaaaaaa",
      "aaaaaaaaaaaaaaaa",
      "aaaaaaaaaaaaaaaa",
      "aaaaaaaaaaaaaaaa",
      "aaaaaaaaaaaaaaaa",
      "aaaaaaaaaaaaaaaa"
    ],
    [
      "aaaaaaaaaaaaaaaa",
      "aaaaaaaaaaaaaaaa",
      "aaaaaaaaaaaaaaaa",
      "aaaaaaaaaaaaaaaa",
      "aaaaaaaaaaaaaaaa",
      "aaaaaaaaaaaaaaaa",
      "aaaaaaaaaaaaaaaa",
      "aaaaaaaaaaaaaaaa",
      "aaaaaaaaaaaaaaaa",
      "aaaaaaaaaaaaaaaa",
      "aaaaaaaaaaaaaaaa",
      "aaaaaaaaaaaaaaaa",
      "aaaaaaaaaaaaaaaa",
      "aaaaaaaaaaaaaaaa",
      "aaaaaaaaaaaaaaaa",
      "aaaaaaaaaaaaaaaa"
    ],
    [
      "aaaaaaaaaaaaaaaa",
      "aaaaaaaaaaaaaaaa",
      "aaaaaaaaaaaaaaaa",
      "aaaaaaaaaaaaaaaa",
      "aaaaaaaaaaaaaaaa",
      "aaaaaaaaaaaaaaaa",
      "aaaaaaaaaaaaaaaa",
      "aaaaaaaaaaaaaaaa",
      "aaaaaaaaaaaaaaaa",
      "aaaaaaaaaaaaaaaa",
      "aaaaaaaaaaaaaaaa",
      "aaaaaaaaaaaaaaaa",
      "aaaaaaaaaaaaaaaa",
      "aaaaaaaaaaaaaaaa",
      "aaaaaaaaaaaaaaaa",
      "aaaaaaaaaaaaaaaa"
    ]
  ]
}