{
  "name": "multi_nuclearpowerplant_7_base4",
  "refpalette": "deceasedcraft:multi_nuclearpowerplant_7/multi_nuclearpowerplant_7_base4_palette",
  "xsize": 16,
  "zsize": 16,
  "slices": [
    [
      "vvvvvvvvvvvvvvvv",
      "aaaaaaaaaaaaaaab",
      "aaaaaaaaaaaaaaab",
      "aaaaaaaaaaaaaaab",
      "aaaaaaaaaaaaaaab",
      "aaaaaaaaaaaaaccc",
      "aaaaaaaaaaaaaaac",
      "aaaaaaaaaaaaaaac",
      "aaaaaaaaaaaaaaac",
      "aaaaaaaaaaaaaaac",
      "aaaaaaaaaaaaacc ",
      "aaaaaaaaaaaac   ",
      "aaaaaaaaaacc    ",
      "aaaaaaaaac      ",
      "aaaaaaacc       ",
      "aaaaaac         "
    ],
    [
      "vvvvvvvvvvvvvvvv",
      "aaaaaaaaaaaaaaab",
      "aaaaaaaaaaaaaaab",
      "aaaaaaaaaaaaaaab",
      "aaaaaaaaaaaaaaab",
      "aaaaaaaaaaaaaccc",
      "aaaaaaaaaaaaaaac",
      "aaaaaaaaaaaaaaac",
      "aaaaaaaaaaaaaaac",
      "aaaaaaaaaaaaaaac",
      "aaaaaaaaaaaaacc ",
      "aaaaaaaaaaaac   ",
      "aaaaaaaaaacc    ",
      "aaaaaaaaac      ",
      "aaaaaaacc       ",
      "aaaaaac         "
    ],
    [
      "vvvvvvvvvvvvvvvv",
      "aaaaaaaaaaaaaaab",
      "aaaaaaaaaaaaaaab",
      "aaaaaaaaaaaaaaab",
      "aaaaaaaaaaaaaaab",
      "aaaaaaaaaaaaaccc",
      "aaaaaaaaaaaaaaac",
      "aaaaaaaaaaaaaaac",
      "aaaaaaaaaaaaaaac",
      "aaaaaaaaaaaaaaac",
      "aaaaaaaaaaaaacc ",
      "aaaaaaaaaaaac   ",
      "aaaaaaaaaacc    ",
      "aaaaaaaaac      ",
      "aaaaaaacc       ",
      "aaaaaac         "
    ],
    [
      "vvvvvvvvvvvvvvvv",
      "aaaaaaaaaaaaaaab",
      "aaaaaaaaaaaaaaab",
      "aaaaaaaaaaaaaaab",
      "aaaaaaaaaaaaaaab",
      "aaaaaaaaaaaaaccc",
      "aaaaaaaaaaaaaaac",
      "aaaaaaaaaaaaaaac",
      "aaaaaaaaaaaaaaac",
      "aaaaaaaaaaaaaaac",
      "aaaaaaaaaaaaacc ",
      "aaaaaaaaaaaac   ",
      "aaaaaaaaaacc    ",
      "aaaaaaaaac      ",
      "aaaaaaacc       ",
      "aaaaaac         "
    ],
    [
      "vvvvvvvvvvvvvvvv",
      "aaaaaaaaaaaaaaab",
      "aaaaaaaaaaaaaaab",
      "aaaaaaaaaaaaaaab",
      "aaaaaaaaaaaaaaab",
      "aaaaaaaaaaaaaccc",
      "aaaaaaaaaaaaaaac",
      "aaaaaaaaaaaaaaac",
      "aaaaaaaaaaaaaaac",
      "aaaaaaaaaaaaaaac",
      "aaaaaaaaaaaaacc ",
      "aaaaaaaaaaaac   ",
      "aaaaaaaaaacc    ",
      "aaaaaaaaac      ",
      "aaaaaaacc       ",
      "aaaaaac         "
    ],
    [
      "vvvvvvvvvvvvvvvv",
      "aaaaaaaaaaaaaaab",
      "aaaaaaaaaaaaaaab",
      "aaaaaaaaaaaaaaab",
      "aaaaaaaaaaaaaaab",
      "aaaaaaaaaaaaaccc",
      "aaaaaaaaaaaaaaac",
      "aaaaaaaaaaaaaaac",
      "aaaaaaaaaaaaaaac",
      "aaaaaaaaaaaaaaac",
      "aaaaaaaaaaaaacc ",
      "aaaaaaaaaaaac   ",
      "aaaaaaaaaacc    ",
      "aaaaaaaaac      ",
      "aaaaaaacc       ",
      "aaaaaa~         "
    ]
  ]
}