{
  "name": "multi_nuclearpowerplant_7_base6",
  "refpalette": "deceasedcraft:multi_nuclearpowerplant_7/multi_nuclearpowerplant_7_base6_palette",
  "xsize": 16,
  "zsize": 16,
  "slices": [
    [
      "vvvvvvvvvvvvvvvv",
      "vvvvvvvvvvvvvvvv",
      "vvvvvvvvvvvvvvvv",
      "vvvvvvvvvvvvvvvv",
      "vvvvvvvvvvvvvvvv",
      "vvvvvvvvvvvvvvvv",
      "vvvvvvvvvvvvvvva",
      "vvvvvvvvvvvvvvab",
      "vvvvvvvvvvvvvabb",
      "vvvvvvvvvvvvabba",
      "vvvvvvvvvvvvaaac",
      "vvvvvvvvvvvaaccc",
      "vvvvvvvvvvaacccc",
      "vvvvvvvvvaaacccc",
      "vvvvvvvaaaaccccc",
      "vvvvvvadeacccccc"
    ],
    [
      "vvvvvvvvvvvvvvvv",
      "ffffffffffffffff",
      "ffffffffffffffff",
      "ffffffffffffffff",
      "ffffffffffffffff",
      "ffffffffffffffff",
      "ffffffffffffffff",
      "ffffffffffffffff",
      "ffffffffffffffff",
      "fffffffffffffffg",
      "fffffffffffffgg ",
      "ffffffffffffg   ",
      "ffffffffffgg    ",
      "fffffffffghh    ",
      "fffffffgghh     ",
      "ffffffg  h      "
    ],
    [
      "vvvvvvvvvvvvvvvv",
      "dddddddddddddddi",
      "dddddddddddddddi",
      "dddddddddddddddi",
      "dddddddddddddddi",
      "dddddddddddddggg",
      "dddddddddddddddg",
      "dddddddddddddddg",
      "dddddddddddddddg",
      "dddddddddddddddg",
      "dddddddddddddgg ",
      "ddddddddddddg   ",
      "ddddddddddgg    ",
      "dddddddddg      ",
      "dddddddgg       ",
      "ddddddg         "
    ],
    [
      "vvvvvvvvvvvvvvvv",
      "dddddddddddddddi",
      "dddddddddddddddi",
      "dddddddddddddddi",
      "dddddddddddddddi",
      "dddddddddddddggg",
      "dddddddddddddddg",
      "dddddddddddddddg",
      "dddddddddddddddg",
      "dddddddddddddddg",
      "dddddddddddddgg ",
      "ddddddddddddg   ",
      "ddddddddddgg    ",
      "dddddddddg      ",
      "dddddddgg       ",
      "ddddddg         "
    ],
    [
      "vvvvvvvvvvvvvvvv",
      "dddddddddddddddi",
      "dddddddddddddddi",
      "dddddddddddddddi",
      "dddddddddddddddi",
      "dddddddddddddggg",
      "dddddddddddddddg",
      "dddddddddddddddg",
      "dddddddddddddddg",
      "dddddddddddddddg",
      "dddddddddddddgg ",
      "ddddddddddddg   ",
      "ddddddddddgg    ",
      "dddddddddg      ",
      "dddddddgg       ",
      "ddddddg         "
    ],
    [
      "vvvvvvvvvvvvvvvv",
      "dddddddddddddddi",
      "dddddddddddddddi",
      "dddddddddddddddi",
      "dddddddddddddddi",
      "dddddddddddddggg",
      "dddddddddddddddg",
      "dddddddddddddddg",
      "dddddddddddddddg",
      "dddddddddddddddg",
      "dddddddddddddgg ",
      "ddddddddddddg   ",
      "ddddddddddgg    ",
      "dddddddddg      ",
      "dddddddgg       ",
      "ddddddg         "
    ]
  ]
}