{
  "name": "multi_nuclearpowerplant_7_base3",
  "refpalette": "deceasedcraft:multi_nuclearpowerplant_7/multi_nuclearpowerplant_7_base3_palette",
  "xsize": 16,
  "zsize": 16,
  "slices": [
    [
      "vvvvvvvvvvvvvvvv",
      "               a",
      "               a",
      "               a",
      "               a",
      "            bccc",
      "              cc",
      "dddddddddddddddd",
      "dddddddddddddddd",
      "              cc",
      "             cce",
      "            ceee",
      "          cceeee",
      "         ceeeeee",
      "       cceeeeeee",
      "      ceeeeeeee "
    ],
    [
      "vvvvvvvvvvvvvvvv",
      "               a",
      "               a",
      "               a",
      "               a",
      "            fggg",
      "              gg",
      "hhhhhhhhhhhhhh i",
      "jjjjjjjjjjjjjj k",
      "              gg",
      "             gg ",
      "            g   ",
      "          gg    ",
      "         gl     ",
      "       gg      m",
      "      g      mn "
    ],
    [
      "vvvvvvvvvvvvvvvv",
      "               a",
      "               a",
      "               a",
      "               a",
      "             ggg",
      "              gg",
      "               o",
      "               p",
      "              gg",
      "             gg ",
      "            g   ",
      "          gg    ",
      "         g      ",
      "       gg       ",
      "      g         "
    ],
    [
      "vvvvvvvvvvvvvvvv",
      "               a",
      "               a",
      "               a",
      "               a",
      "             ggg",
      "              gg",
      "               g",
      "               g",
      "              gg",
      "             gg ",
      "            g   ",
      "          gg    ",
      "         g      ",
      "       gg       ",
      "      g         "
    ],
    [
      "vvvvvvvvvvvvvvvv",
      "               a",
      "               a",
      "               a",
      "               a",
      "             ggg",
      "              gg",
      "              gq",
      "              gq",
      "              gg",
      "             gg ",
      "            g   ",
      "          gg    ",
      "         g      ",
      "       gg       ",
      "      g         "
    ],
    [
      "vvvvvvvvvvvvvvvv",
      "               a",
      "               a",
      "               a",
      "               a",
      "             ggg",
      "              gg",
      "              gq",
      "              gq",
      "              gg",
      "             gg ",
      "            g   ",
      "          gg    ",
      "         g      ",
      "       gg       ",
      "      g         "
    ]
  ]
}