{
  "name": "multi_nuclearpowerplant_7_base7",
  "refpalette": "deceasedcraft:multi_nuclearpowerplant_7/multi_nuclearpowerplant_7_base7_palette",
  "xsize": 16,
  "zsize": 16,
  "slices": [
    [
      "vvvvvvvvvvvvvvvv",
      "aaaaaaaaaaaaaaaa",
      "aaaaaaaaaaaaaaaa",
      "aaaaaaaaaaaaaaaa",
      "aaaaaaaaaaaaaaaa",
      "aaaaaaaaaaaaaaaa",
      "aaaaaaaaaaaaaaab",
      "aaaaaaaaaaaaaab ",
      "aaaaaaaaaaaaab  ",
      "aaaaaaaaaaaab   ",
      "aaaaaaaaaaaab   ",
      "aaaaaaaaaaab    ",
      "aaaaaaaaaab     ",
      "aaaaaaaaabb     ",
      "aaaaaaabbb      ",
      "aaaaaabccb      "
    ],
    [
      "vvvvvvvvvvvvvvvv",
      "aaaaaaaaaaaaaaaa",
      "aaaaaaaaaaaaaaaa",
      "aaaaaaaaaaaaaaaa",
      "aaaaaaaaaaaaaaaa",
      "aaaaaaaaaaaaaaaa",
      "aaaaaaaaaaaaaaab",
      "aaaaaaaaaaaaaab ",
      "aaaaaaaaaaaaab  ",
      "aaaaaaaaaaaab   ",
      "aaaaaaaaaaaab   ",
      "aaaaaaaaaaab    ",
      "aaaaaaaaaab     ",
      "aaaaaaaaabb     ",
      "aaaaaaabbb      ",
      "aaaaaabccb      "
    ],
    [
      "vvvvvvvvvvvvvvvv",
      "aaaaaaaaaaaaaaaa",
      "aaaaaaaaaaaaaaaa",
      "aaaaaaaaaaaaaaaa",
      "aaaaaaaaaaaaaaaa",
      "aaaaaaaaaaaaaaaa",
      "aaaaaaaaaaaaaaab",
      "aaaaaaaaaaaaaab ",
      "aaaaaaaaaaaaab  ",
      "aaaaaaaaaaaab   ",
      "aaaaaaaaaaaab   ",
      "aaaaaaaaaaab    ",
      "aaaaaaaaaab     ",
      "aaaaaaaaabb     ",
      "aaaaaaabbb      ",
      "aaaaaabccb      "
    ],
    [
      "vvvvvvvvvvvvvvvv",
      "aaaaaaaaaaaaaaaa",
      "aaaaaaaaaaaaaaaa",
      "aaaaaaaaaaaaaaaa",
      "aaaaaaaaaaaaaaaa",
      "aaaaaaaaaaaaaaaa",
      "aaaaaaaaaaaaaaab",
      "aaaaaaaaaaaaaab ",
      "aaaaaaaaaaaaab  ",
      "aaaaaaaaaaaab   ",
      "aaaaaaaaaaaab   ",
      "aaaaaaaaaaab    ",
      "aaaaaaaaaab     ",
      "aaaaaaaaabb     ",
      "aaaaaaabbb      ",
      "aaaaaabccb      "
    ],
    [
      "vvvvvvvvvvvvvvvv",
      "aaaaaaaaaaaaaaaa",
      "aaaaaaaaaaaaaaaa",
      "aaaaaaaaaaaaaaaa",
      "aaaaaaaaaaaaaaaa",
      "aaaaaaaaaaaaaaaa",
      "aaaaaaaaaaaaaaab",
      "aaaaaaaaaaaaaab ",
      "aaaaaaaaaaaaab  ",
      "aaaaaaaaaaaab   ",
      "aaaaaaaaaaaab   ",
      "aaaaaaaaaaab    ",
      "aaaaaaaaaab     ",
      "aaaaaaaaabb     ",
      "aaaaaaabbb      ",
      "aaaaaabccb      "
    ],
    [
      "vvvvvvvvvvvvvvvv",
      "dddddddddddddddd",
      "dddddddddddddddd",
      "dddddddddddddddd",
      "dddddddddddddddd",
      "dddddddddddddddd",
      "dddddddddddddddb",
      "ddddddddddddddbe",
      "dddddddddddddbee",
      "ddddddddddddbeee",
      "ddddddddddddbeee",
      "dddddddddddbeeee",
      "ddddddddddbeeeee",
      "dddddddddbbeeeee",
      "dddddddbbbeeeeee",
      "ddddddbccbeeeeee"
    ]
  ]
}