{
  "name": "multi_nuclearpowerplant_7_base2",
  "refpalette": "deceasedcraft:multi_nuclearpowerplant_7/multi_nuclearpowerplant_7_base2_palette",
  "xsize": 16,
  "zsize": 16,
  "slices": [
    [
      "vvvvvvvvvvvvvvvv",
      "               a",
      "               a",
      "               a",
      "               a",
      "             bbb",
      "              bb",
      "              bc",
      "              bc",
      "              bb",
      "             bb ",
      "            b   ",
      "          bb    ",
      "         b      ",
      "       bb       ",
      "      b         "
    ],
    [
      "vvvvvvvvvvvvvvvv",
      "de             a",
      "de             a",
      "de             a",
      "               a",
      "             bbb",
      "              bb",
      "              bc",
      "              bc",
      "              bb",
      "             bb ",
      "            b   ",
      "          bb    ",
      "         b      ",
      "       bb       ",
      "      b         "
    ],
    [
      "vvvvvvvvvvvvvvvv",
      " fde           a",
      " fde           a",
      "ddde           a",
      "               a",
      "             bbb",
      "              bb",
      "              bc",
      "              bc",
      "              bb",
      "             bb ",
      "            b   ",
      "          bb    ",
      "         b      ",
      "       bb       ",
      "      b         "
    ],
    [
      "vvvvvvvvvvvvvvvv",
      "g  fde         a",
      "   fde         a",
      " fddde         a",
      "               a",
      "             bbb",
      "              bb",
      "              bc",
      "              bc",
      "              bb",
      "             bb ",
      "            b   ",
      "          bb    ",
      "         b      ",
      "       bb       ",
      "      b         "
    ],
    [
      "vvvvvvvvvvvvvvvv",
      "     fde       a",
      "     fde       a",
      "   fddde       a",
      "               a",
      "             bbh",
      "              bi",
      "              bi",
      "              bi",
      "              bb",
      "             bb ",
      "            b   ",
      "          bb    ",
      "         b      ",
      "       bb       ",
      "      b         "
    ],
    [
      "vvvvvvvvvvvvvvvv",
      "       fde     a",
      "       fde     a",
      "     fddde     a",
      "               a",
      "jjjjjjjjjjjjjbbh",
      "              bk",
      "              bk",
      "              bk",
      "              bb",
      "             bbl",
      "            blll",
      "          bbllll",
      "         bllllll",
      "       bblllllll",
      "      blllllllll"
    ]
  ]
}