{
  "name": "multi_nuclearpowerplant_7_base8",
  "refpalette": "deceasedcraft:multi_nuclearpowerplant_7/multi_nuclearpowerplant_7_base8_palette",
  "xsize": 16,
  "zsize": 16,
  "slices": [
    [
      "vvvvvvvvvvvvvvvv",
      "aaaaaaaaaaaaaaaa",
      "aaaaaaaaaaaaaaaa",
      "aaaaaaaaaaaaaaaa",
      "aaaaaaaaaaaaaaaa",
      "aaaaaaaaaaaaaaaa",
      "aaaaaaaaaaaaaaab",
      "aaaaaaaaaaaaaabb",
      "aaaaaaaaaaaaabbb",
      "aaaaaaaaaaaabbbb",
      "aaaaaaaaaaaabbbb",
      "aaaaaaaaaaabbbbb",
      "aaaaaaaaaabbbbbb",
      "aaaaaaaaabbbbbbb",
      "aaaaaaabbbbbbbbb",
      "aaaaaabbbbbbbbbb"
    ],
    [
      "vvvvvvvvvvvvvvvv",
      "aaaaaaaaaaaaaaaa",
      "aaaaaaaaaaaaaaaa",
      "aaaaaaaaaaaaaaaa",
      "aaaaaaaaaaaaaaaa",
      "aaaaaaaaaaaaaaaa",
      "aaaaaaaaaaaaaaac",
      "aaaaaaaaaaaaaac=",
      "aaaaaaaaaaaaac==",
      "aaaaaaaaaaaac===",
      "aaaaaaaaaaaac===",
      "aaaaaaaaaaac====",
      "aaaaaaaaaac=====",
      "aaaaaaaaacc=====",
      "aaaaaaaccc======",
      "aaaaaacddc======"
    ],
    [
      "vvvvvvvvvvvvvvvv",
      "aaaaaaaaaaaaaaaa",
      "aaaaaaaaaaaaaaaa",
      "aaaaaaaaaaaaaaaa",
      "aaaaaaaaaaaaaaaa",
      "aaaaaaaaaaaaaaaa",
      "aaaaaaaaaaaaaaae",
      "aaaaaaaaaaaaaaea",
      "aaaaaaaaaaaaaeaa",
      "aaaaaaaaaaaaeaaa",
      "aaaaaaaaaaaaeaaa",
      "aaaaaaaaaaaeaaaa",
      "aaaaaaaaaaeaaaaa",
      "aaaaaaaaaeeaaaaa",
      "aaaaaaaeeeaaaaaa",
      "aaaaaaeffeaaaaaa"
    ],
    [
      "vvvvvvvvvvvvvvvv",
      "aaaaaaaaaaaaaaaa",
      "aaaaaaaaaaaaaaaa",
      "aaaaaaaaaaaaaaaa",
      "aaaaaaaaaaaaaaaa",
      "aaaaaaaaaaaaaaaa",
      "aaaaaaaaaaaaaaae",
      "aaaaaaaaaaaaaaea",
      "aaaaaaaaaaaaaeaa",
      "aaaaaaaaaaaaeaaa",
      "aaaaaaaaaaaaeaaa",
      "aaaaaaaaaaaeaaaa",
      "aaaaaaaaaaeaaaaa",
      "aaaaaaaaaeeaaaaa",
      "aaaaaaaeeeaaaaaa",
      "aaaaaaeffeaaaaaa"
    ],
    [
      "vvvvvvvvvvvvvvvv",
      "aaaaaaaaaaaaaaaa",
      "aaaaaaaaaaaaaaaa",
      "aaaaaaaaaaaaaaaa",
      "aaaaaaaaaaaaaaaa",
      "aaaaaaaaaaaaaaaa",
      "aaaaaaaaaaaaaaae",
      "aaaaaaaaaaaaaaec",
      "aaaaaaaaaaaaaecc",
      "aaaaaaaaaaaaeccc",
      "aaaaaaaaaaaaeccc",
      "aaaaaaaaaaaecccc",
      "aaaaaaaaaaeccccc",
      "aaaaaaaaaeeccccc",
      "aaaaaaaeeecccccc",
      "aaaaaaeffecccccc"
    ],
    [
      "vvvvvvvvvvvvvvvv",
      "aaaaaaaaaaaaaaaa",
      "aaaaaaaaaaaaaaaa",
      "aaaaaaaaaaaaaaaa",
      "aaaaaaaaaaaaaaaa",
      "aaaaaaaaaaaaaaaa",
      "aaaaaaaaaaaaaaae",
      "aaaaaaaaaaaaaae ",
      "aaaaaaaaaaaaae  ",
      "aaaaaaaaaaaae   ",
      "aaaaaaaaaaaae   ",
      "aaaaaaaaaaae    ",
      "aaaaaaaaaae     ",
      "aaaaaaaaaee     ",
      "aaaaaaaeee      ",
      "aaaaaaeffe      "
    ]
  ]
}