{
  "name": "multi_nuclearpowerplant_7_ground",
  "refpalette": "deceasedcraft:multi_nuclearpowerplant_7/multi_nuclearpowerplant_7_ground_palette",
  "xsize": 16,
  "zsize": 16,
  "slices": [
    [
      "zzzzzzzzzzazzzzz",
      "zzzzzzzzzzzzzzzz",
      "zzzzzzzzzzzzaaza",
      "zzzazzzzzazazzzz",
      "zzzzzzazazzzzzza",
      "zzzzzaazzzzaaaza",
      "zazzazzazazzazaa",
      "zzzzzaazzaaaaaaa",
      "zzzzzzaaazazaaaa",
      "zzzzaaaazaaaaaaa",
      "aazazazaaaaaaaab",
      "zzaaazaaaaaaabbb",
      "aazzaaaaaaaabbcc",
      "zazazaaaaabbbccc",
      "aaaaaaaaabbccccc",
      "zaaaaaabbbcccc  "
    ],
    [
      "      d         ",
      "        e    d d",
      "de              ",
      "     d    d   e ",
      "d d    d        ",
      "  d       d     ",
      "          e     ",
      "                ",
      " d              ",
      "   d           f",
      "             fgz",
      "            gzzz",
      "          fhzazz",
      "    d    gzzzzzc",
      "       fgzzazccc",
      "      gzzzzccccc"
    ],
    [
      "                ",
      "                ",
      "                ",
      "                ",
      "                ",
      "                ",
      "                ",
      "                ",
      "                ",
      "                ",
      "               i",
      "             iii",
      "            ii  ",
      "          iii zz",
      "         ii  zza",
      "       iii zzzzz"
    ],
    [
      "                ",
      "                ",
      "                ",
      "                ",
      "                ",
      "                ",
      "                ",
      "                ",
      "                ",
      "                ",
      "               i",
      "             iii",
      "            ii  ",
      "          iii dd",
      "         ii     ",
      "       iii      "
    ],
    [
      "                ",
      "                ",
      "                ",
      "                ",
      "                ",
      "                ",
      "                ",
      "                ",
      "                ",
      "                ",
      "               j",
      "             jj ",
      "            j   ",
      "          jj    ",
      "         j      ",
      "       jj       "
    ],
    [
      "                ",
      "                ",
      "                ",
      "                ",
      "                ",
      "                ",
      "                ",
      "                ",
      "                ",
      "                ",
      "                ",
      "                ",
      "                ",
      "                ",
      "                ",
      "                "
    ]
  ]
}