{
  "name": "multi_nuclearpowerplant_7_base1",
  "refpalette": "deceasedcraft:multi_nuclearpowerplant_7/multi_nuclearpowerplant_7_base1_palette",
  "xsize": 16,
  "zsize": 16,
  "slices": [
    [
      "vvvvvvvvvvvvvvvv",
      "         abc   d",
      "         abc   d",
      "       abbbc   d",
      "eeeeeeeeeeeeeeed",
      "vvvvvvvvvvvvvvvv",
      "ffffffffffffffff",
      "ffffffffffffffff",
      "ffffffffffffffff",
      "fffffffffffffffg",
      "fffffffffffffggz",
      "ffffffffffffgzzh",
      "ffffffffffggzhhh",
      "fffffffffgzzhhhh",
      "fffffffggzhhhhhh",
      "ffffffgzzhhhhhhh"
    ],
    [
      "vvvvvvvvvvvvvvvv",
      "           abccd",
      "           abccd",
      "         abbbccd",
      "            bccd",
      "vvvvvvvvvvvvvvvv",
      "iiiiiiiiiiiiiiii",
      "iiiiiiiiiiiiiiii",
      "iiiiiiiiiiiiiiii",
      "iiiiiiiiiiiiiiij",
      "iiiiiiiiiiiiijjk",
      "iiiiiiiiiiiijkk ",
      "iiiiiiiiiijjk   ",
      "iiiiiiiiijkk    ",
      "iiiiiiijjk      ",
      "iiiiiijkk       "
    ],
    [
      "vvvvvvvvvvvvvvvv",
      "             aad",
      "             aad",
      "           abaad",
      "            baad",
      "vvvvvvvvvvvvvvvv",
      "iiiiiiiiiiiiiiii",
      "iiiiiiiiiiiiiiii",
      "iiiiiiiiiiiiiiii",
      "iiiiiiiiiiiiiiij",
      "iiiiiiiiiiiiijj ",
      "iiiiiiiiiiiij   ",
      "iiiiiiiiiijj    ",
      "iiiiiiiiij      ",
      "iiiiiiijj       ",
      "iiiiiij         "
    ],
    [
      "vvvvvvvvvvvvvvvv",
      "               d",
      "               d",
      "               d",
      "            alld",
      "vvvvvvvvvvvvvvvv",
      "iiiiiiiiiiiiiiii",
      "iiiiiiiiiiiiiiii",
      "iiiiiiiiiiiiiiii",
      "iiiiiiiiiiiiiiij",
      "iiiiiiiiiiiiijj ",
      "iiiiiiiiiiiij   ",
      "iiiiiiiiiijj    ",
      "iiiiiiiiij      ",
      "iiiiiiijj       ",
      "iiiiiij         "
    ],
    [
      "vvvvvvvvvvvvvvvv",
      "               d",
      "               d",
      "               d",
      "            mlld",
      "vvvvvvvvvvvvvvvv",
      "iiiiiiiiiiiiiiii",
      "iiiiiiiiiiiiiiii",
      "iiiiiiiiiiiiiiii",
      "iiiiiiiiiiiiiiij",
      "iiiiiiiiiiiiijj ",
      "iiiiiiiiiiiij   ",
      "iiiiiiiiiijj    ",
      "iiiiiiiiijn     ",
      "iiiiiiijj       ",
      "iiiiiij         "
    ],
    [
      "vvvvvvvvvvvvvvvv",
      "oooooooooooooppd",
      "oooooooooooooqqd",
      "oooooooooooooqqd",
      "ooooooooooooorrd",
      "vvvvvvvvvvvvvvvv",
      "iiiiiiiiiiiiiiii",
      "iiiiiiiiiiiiiiii",
      "iiiiiiiiiiiiiiii",
      "iiiiiiiiiiiiiiij",
      "iiiiiiiiiiiiijjs",
      "iiiiiiiiiiiijsss",
      "iiiiiiiiiijjss  ",
      "iiiiiiiiijsss   ",
      "iiiiiiijjss     ",
      "iiiiiijsss      "
    ]
  ]
}