{
  "name": "multi_taigaresidence_2_floor5",
  "refpalette": "deceasedcraft:multi_taigaresidence_2/multi_taigaresidence_2_floor5_palette",
  "xsize": 16,
  "zsize": 16,
  "slices": [
    [
      "   abcccddefgggg",
      "   abcccddeeeeee",
      " hhhbddddddddccc",
      "  ijbddddddddccc",
      "  ijbddddddddccc",
      "  ijbddddddddddd",
      "  ijbddddddddddd",
      "  ijbddddddddddd",
      "  ijbddkdlmddldd",
      "  ijbdddlnompddd",
      "  ijbdddnppnmndd",
      "  ijbbbbbmnnqrrb",
      "  ijjjjj  sttaaa",
      "  iiiiiiiih     ",
      "          u     ",
      "                "
    ],
    [
      "    w  x  y     ",
      "    bABAC bbDbbb",
      " hhhbE AF AI A J",
      "   jbK AL AI M N",
      "   jbO AP AC AQA",
      "   jbR x  AF A O",
      "   jbAAA  SL MTR",
      "    bUUVWXYZ0SAA",
      "    b1l 0  23 4!",
      "    b5 3 6   768",
      "   jb9# $   6 %8",
      "   jbb^^s  s$  b",
      "   jjjjj        ",
      "                ",
      "                ",
      "                "
    ],
    [
      "     & *  (     ",
      "    bA)A+-bb[bbb",
      " hhhb  A  A] A{ ",
      "    b  A  A} |  ",
      "    b  A; A  A:A",
      "    b  *  S  A '",
      "    bAAS<    | '",
      "    b >      AAA",
      "    b        ,  ",
      "    b           ",
      "    b           ",
      "    bb         b",
      "                ",
      "                ",
      "                ",
      "                "
    ],
    [
      "     . A  ?     ",
      "    bAAA  bb/bbb",
      " hhhb  A  A  A` ",
      "    b  A\u0370 A  A  ",
      "    b  A  A  AAA",
      "    b  A  A  A  ",
      "    bAAA  S\u0370 A \u0371",
      "    b        AAA",
      "    b           ",
      "    b           ",
      "    b           ",
      "    bb         b",
      "                ",
      "                ",
      "                ",
      "                "
    ],
    [
      "    b  A  b     ",
      "    bAAA  bbbbbb",
      " hhhb  A\u0372 A \u0372A  ",
      "   \u0373b  A  A  A  ",
      "   \u0373b  A  A  AAA",
      "   \u0373b  A  A  A  ",
      "   \u0373bAAA  A  A  ",
      "   \u0373b  \u0374  A  AAA",
      "   \u0373b     A     ",
      "   \u0373b  \u0375  A  \u0375 \u0376",
      "   \u0373b     A     ",
      "   \u0373bbbbb A bbbb",
      "   \u0373\u0373\u0373\u0373\u0373\u0373\u0373h     ",
      "          h     ",
      "          \u0377     ",
      "                "
    ],
    [
      "    b\u037a\u037a\u037a\u037a\u037ab     ",
      "    b\u037a\u037a\u037a\u037a\u037abbbbbb",
      " hhhb\u037a\u037a\u037a\u037a\u037a\u037a\u037a\u037a\u037a\u037a\u037a",
      "   \u037bb\u037a\u037a\u037a\u037a\u037a\u037a\u037a\u037a\u037a\u037a\u037a",
      "   \u037bb\u037a\u037a\u037a\u037a\u037a\u037a\u037a\u037a\u037a\u037a\u037a",
      "   \u037bb\u037a\u037a\u037a\u037a\u037a\u037a\u037a\u037a\u037a\u037a\u037a",
      "   \u037bb\u037a\u037a\u037a\u037a\u037a\u037a\u037a\u037a\u037a\u037a\u037a",
      "   \u037bb\u037a\u037a\u037a\u037a\u037a\u037a\u037a\u037a\u037a\u037a\u037a",
      "   \u037bb\u037a\u037a\u037a\u037a\u037a\u037a\u037a\u037a\u037a\u037a\u037a",
      "   \u037bb\u037a\u037a\u037a\u037a\u037a\u037a\u037a\u037a\u037a\u037a\u037a",
      "   \u037bb\u037a\u037a\u037a\u037a\u037a\u037a\u037a\u037a\u037a\u037a\u037a",
      "   \u037bbbbbbbbbbbbb",
      "   \u037b\u037b\u037b\u037b\u037b\u037b\u037bh     ",
      "          h\u037c\u037c\u037c\u037c\u037c",
      "          h     ",
      "                "
    ]
  ]
}