{
  "name": "multi_taigaresidence_2_floor7",
  "refpalette": "deceasedcraft:multi_taigaresidence_2/multi_taigaresidence_2_floor7_palette",
  "xsize": 16,
  "zsize": 16,
  "slices": [
    [
      "   abccccccdeeee",
      "   abfffffffffff",
      " gggbhhhhhhhhhhh",
      "  ifbhhhhhhhhhhh",
      "  ifbhhhhhhhhhhh",
      "  ifbhhhhhhhhhhh",
      "  ifbhhhhhhhhhhh",
      "  ifbhhhhhhhhhhh",
      "  ifbhhhhhhhhhhh",
      "  ifbhhhhhhhhhhh",
      "  ifbhhhhhhhhhhh",
      "  ifjkkkkkkkkkkk",
      "  ifffffffglllll",
      "  iiiiiiiig     ",
      "          g     ",
      "                "
    ],
    [
      "    m           ",
      "    m           ",
      " ggnm           ",
      " ggom   pqp     ",
      " ggom  prrrp    ",
      " ggom prsrsrp   ",
      " ggom truuurw   ",
      " ggom prsrsrp   ",
      " ggom  prrrp    ",
      " ggom   pxp     ",
      " ggom           ",
      " ggommmmmmmmmmmm",
      " ggoooooooy     ",
      " gggggggggg     ",
      " gggggggggg     ",
      "                "
    ],
    [
      "    m           ",
      "    m           ",
      "    m           ",
      "    m           ",
      "    m           ",
      "    m           ",
      "    m    ~~     ",
      "    m           ",
      "    m           ",
      "    m           ",
      "    m           ",
      "    mmmmmmmmmmmm",
      "                ",
      "                ",
      "                ",
      "                "
    ],
    [
      "                ",
      "                ",
      "                ",
      "                ",
      "                ",
      "                ",
      "          ~     ",
      "                ",
      "                ",
      "                ",
      "                ",
      "    A           ",
      "                ",
      "                ",
      "                ",
      "                "
    ],
    [
      "                ",
      "                ",
      "                ",
      "                ",
      "                ",
      "                ",
      "          ~     ",
      "                ",
      "                ",
      "                ",
      "                ",
      "                ",
      "                ",
      "                ",
      "                ",
      "                "
    ],
    [
      "                ",
      "                ",
      "                ",
      "                ",
      "                ",
      "                ",
      "                ",
      "                ",
      "                ",
      "                ",
      "                ",
      "                ",
      "                ",
      "                ",
      "                ",
      "                "
    ]
  ]
}