{
  "name": "multi_taigaresidence_2_floor2",
  "refpalette": "deceasedcraft:multi_taigaresidence_2/multi_taigaresidence_2_floor2_palette",
  "xsize": 16,
  "zsize": 16,
  "slices": [
    [
      "   abccccccdeeee",
      "   abccccccccccc",
      " fffbgggcccccccc",
      "  hibgggcccccccc",
      "  hibgggcccccccc",
      "  hibgggcccccccc",
      "  hibgggcccccccc",
      "  hibgggcccccccc",
      "  hibgggcccccccc",
      "  hibccccccccccc",
      "  hibccccccccccc",
      "  hibbbbbbbbcccc",
      "  hiiiiiiiffffff",
      "  hhhhhhhhffffff",
      "          ffffff",
      "                "
    ],
    [
      "    j  k        ",
      "    bbbblbbb    ",
      " fffbmnb obpq rr",
      "   ib  k sb tu  ",
      "    bbbb sbpq   ",
      "    b! k sbp    ",
      "   ibbbb sb   w ",
      "   ib  k ob   r ",
      "   ibbbb bbbx y ",
      "   ib           ",
      "    bAA AA      ",
      "    bbBBBbbb    ",
      "   iii  iif     ",
      "          f     ",
      "          f     ",
      "                "
    ],
    [
      "       C        ",
      "    bbbbDbbb    ",
      " fffb  b  b E   ",
      "    bF C  bxI   ",
      "    bbbb  b E   ",
      "    bF C  bx    ",
      "    bbbb  bJ    ",
      "    bF C KbL    ",
      "    bbbb bbb  M ",
      "    b           ",
      "    b     N     ",
      "    bb   bbb    ",
      "          f     ",
      "          f     ",
      "          f     ",
      "                "
    ],
    [
      "       b        ",
      "    bbbbObbb    ",
      " fffb  b  b     ",
      "    bP b  b     ",
      "    bbbb !b     ",
      "    bP b  b     ",
      "    bbbb  b     ",
      "    bP b  b     ",
      "    bbbbQbbb    ",
      "    b           ",
      "    b           ",
      "    bb   bbb    ",
      "          f     ",
      "          f     ",
      "          f     ",
      "                "
    ],
    [
      "    b  b        ",
      "    bbbbbbbb    ",
      " fffb  b  b     ",
      "   Rb  b  b     ",
      "   Rbbbb  b     ",
      "   Rb  b  b     ",
      "   Rbbbb  b     ",
      "   Rb  b  b     ",
      "   Rbbbbbbbb    ",
      "   Rb           ",
      "   Rb           ",
      "   Rbbbbbbbbbbbb",
      "   RRRRRRRfSSSSS",
      "          f     ",
      "          f     ",
      "                "
    ],
    [
      "    bTTbUUU     ",
      "    bbbbbbbbOOOO",
      " fffbTTbTTbeeeee",
      "   VbTTbTTbeeeee",
      "   VbbbbTTbeeeee",
      "   VbTTbTTbeeeee",
      "   VbbbbTTbeeeee",
      "   VbTTbTTbeeeee",
      "   VbbbbbbbbQQQQ",
      "   Vbeeeeeeeeeee",
      "   Vbeeeeeeeeeee",
      "   Vbbbbbbbbbbbb",
      "   VVVVVVVf     ",
      "          fWWWWW",
      "          f     ",
      "                "
    ]
  ]
}