{
  "name": "multi_taigaresidence_2_floor4",
  "refpalette": "deceasedcraft:multi_taigaresidence_2/multi_taigaresidence_2_floor4_palette",
  "xsize": 16,
  "zsize": 16,
  "slices": [
    [
      "   abcccddefgggg",
      "   abcccddeeeeee",
      " hhhbcccdddddddd",
      "  ijbcccdddddddd",
      "  ijbddddddddddd",
      "  ijbddddddddddd",
      "  ijbddddddddddd",
      "  ijbddddddddddd",
      "  ijbddddddddddd",
      "  ijbddddddddddd",
      "  ijbddddddddddd",
      "  ijbbbbbbbbkkkb",
      "  ijjjjjjjhaaaaa",
      "  iiiiiiiih     ",
      "          h     ",
      "                "
    ],
    [
      "    l  m  n     ",
      "    bopq  bbbbbb",
      " hhhbr q  stuwx!",
      "   jbqyq As    B",
      "   jbC q As    B",
      "    bC m       D",
      "    bC qqqq     ",
      "    bE   Fq     ",
      "    bI  JKqL M F",
      "   jbNA JKqO M F",
      "   jbP   Fq     ",
      "   jbbQQQbbb   b",
      "      jjjjh     ",
      "          h     ",
      "          h     ",
      "                "
    ],
    [
      "       R  S     ",
      "    b  q  bbbbbb",
      " hhhbT q   U   V",
      "    bqWq       X",
      "    bC q       Y",
      "    bC R        ",
      "    bC qqqqZ   Z",
      "    b  0 !q     ",
      "    b     q    1",
      "    b2    q     ",
      "    b     q3    ",
      "    bb   bbb   b",
      "          h     ",
      "          h     ",
      "          h     ",
      "                "
    ],
    [
      "       q  4     ",
      "    b  q  bbbbbb",
      " hhhb5 q     6  ",
      "    bqqq        ",
      "    b  q        ",
      "    b  q        ",
      "    b  qqqq     ",
      "    b     q     ",
      "    b     q     ",
      "    b     q     ",
      "    b     q     ",
      "    bb   bbb   b",
      "          h     ",
      "          h     ",
      "          h     ",
      "                "
    ],
    [
      "    b  q  b     ",
      "    b  q  bbbbbb",
      " hhhb  q        ",
      "   7bqqq        ",
      "   7b  q        ",
      "   7b  q        ",
      "   7b  qqqq     ",
      "   7b     q     ",
      "   7b     q8 9  ",
      "   7b  9 #q     ",
      "   7b     q     ",
      "   7bbbbbbbbbbbb",
      "   7777777h     ",
      "          h     ",
      "          h     ",
      "                "
    ],
    [
      "    b$$$$$b     ",
      "    b$$$$$bbbbbb",
      " hhhb$$$$$$$$$$$",
      "   %b$$$$$$$$$$$",
      "   %b$$$$$$$$$$$",
      "   %b$$$$$$$$$$$",
      "   %b$$$$$$$$$$$",
      "   %b$$$$$$$$$$$",
      "   %b$$$$$$$$$$$",
      "   %b$$$$$$$$$$$",
      "   %b$$$$$$$$$$$",
      "   %bbbbbbbbbbbb",
      "   %%%%%%%h     ",
      "          h^^^^^",
      "          h     ",
      "                "
    ]
  ]
}