{
  "name": "multi_taigaresidence_2_floor3",
  "refpalette": "deceasedcraft:multi_taigaresidence_2/multi_taigaresidence_2_floor3_palette",
  "xsize": 16,
  "zsize": 16,
  "slices": [
    [
      "   abcccddefgggg",
      "   abcccddeeeeee",
      " hhhbddddddddccc",
      "  ijbddddddddccc",
      "  ijbddddddddccc",
      "  ijbddddddddddd",
      "  ijbddddddddddd",
      "  ijbddddddddddd",
      "  ijbddddddddddd",
      "  ijbddddddddddd",
      "  ijbddddddddddd",
      "  ijbbbbbbbbkkkb",
      "  ijjjjjjjhaaaaa",
      "  iiiiiiiih     ",
      "          h     ",
      "                "
    ],
    [
      "    l  m  n     ",
      "    bopoq bbrbbb",
      " hhhbs ot ou o!w",
      "   jbx oy ou A B",
      "   jbC oD oq oEo",
      "   jbF m  ot o C",
      "   jbooo  oy A F",
      "    bIIJx oD ooo",
      "    b  Jx o  IIK",
      "    b     oJ   L",
      "    bMNO  oJx  P",
      "   jbbQQQbbb   b",
      "   jjjj   h     ",
      "          h     ",
      "          h     ",
      "                "
    ],
    [
      "     R S  T     ",
      "    boUo  bbVbbb",
      " hhhb  o  o  oW ",
      "    b  o  o  X  ",
      "    b  oY oZ o0o",
      "    b  S  o  o 1",
      "    booo2 o  X 1",
      "    b 3   oY ooo",
      "    b     o2    ",
      "    b     o     ",
      "    b     o     ",
      "    bb   bbb   b",
      "          h     ",
      "          h     ",
      "          h     ",
      "                "
    ],
    [
      "     4 o  5     ",
      "    booo  bb6bbb",
      " hhhb  o  o  o7 ",
      "    b  o8 o  o  ",
      "    b  o  o  ooo",
      "    b  o  o  o 9",
      "    booo  o8 o !",
      "    b     o  ooo",
      "    b     o     ",
      "    b     o     ",
      "    b     o     ",
      "    bb   bbb   b",
      "          h     ",
      "          h     ",
      "          h     ",
      "                "
    ],
    [
      "    b  o  b     ",
      "    booo  bbbbbb",
      " hhhb  o  o  o  ",
      "   #b  o  o  o  ",
      "   #b  o  o  ooo",
      "   #b  o  o  o  ",
      "   #booo  o  o  ",
      "   #b     o  ooo",
      "   #b     o     ",
      "   #b     o     ",
      "   #b     o     ",
      "   #bbbbbbbbbbbb",
      "   #######h     ",
      "          h     ",
      "          h     ",
      "                "
    ],
    [
      "    b$$$$$b     ",
      "    b$$$$$bbbbbb",
      " hhhb$$$$$$$$$$$",
      "   %b$$$$$$$$$$$",
      "   %b$$$$$$$$$$$",
      "   %b$$$$$$$$$$$",
      "   %b$$$$$$$$$$$",
      "   %b$$$$$$$$$$$",
      "   %b$$$$$$$$$$$",
      "   %b$$$$$$$$$$$",
      "   %b$$$$$$$$$$$",
      "   %bbbbbbbbbbbb",
      "   %%%%%%%h     ",
      "          h^^^^^",
      "          h     ",
      "                "
    ]
  ]
}