{
  "name": "multi_taigaresidence_2_ground",
  "refpalette": "deceasedcraft:multi_taigaresidence_2/multi_taigaresidence_2_ground_palette",
  "xsize": 16,
  "zsize": 16,
  "slices": [
    [
      "aaabcbbbbbbbbbbb",
      "aaabcbbbbbbbbbbb",
      "adddcbbbbbbbbbbb",
      "aaabcbbbbbbbbbbb",
      "aaabcbbebbbbbbbb",
      "aaffcbbebbbbbbbb",
      "aaaacbbbbbbbbbbb",
      "aaaacbbbebbeebbb",
      "aaaacbbbbebbbbbb",
      "aaaacbbbbbbbbbbb",
      "aaaacbbbbbbbbbbb",
      "aaaacccccccbbbbb",
      "aaaacbbbbbcbbbbb",
      "aaaacccccccccccc",
      "aaaaaaaaaaaaaaaa",
      "aaaaaaaaaaaaaaaa"
    ],
    [
      "    gh     ijjk ",
      "    cblmnlb     ",
      " dddco    pqqqqq",
      "    cor  st     ",
      "    co    t     ",
      "  ffcor  ut  wxy",
      "    coA         ",
      "  B cor  C   wxy",
      "    co     s    ",
      "  B cor u D  EFI",
      "    co   JK     ",
      "  B cccccccccccc",
      "    cLLLLLcLLLLL",
      "  B cccccccccccc",
      "                ",
      "                "
    ],
    [
      "          M     ",
      "    cblNOlb     ",
      " dddc       PQRS",
      "    cR    T     ",
      "    cU          ",
      "  ffc     V  WXY",
      "          M     ",
      "  M  Z       0W1",
      "     2          ",
      "  M          W34",
      "                ",
      "  M       c     ",
      "          c     ",
      "  M             ",
      "                ",
      "                "
    ],
    [
      "                ",
      "    cbllllb     ",
      " dddc         S ",
      "    c           ",
      "    c           ",
      "  ffc           ",
      "                ",
      "  5             ",
      "                ",
      "  5           6 ",
      "                ",
      "  5       c     ",
      "          c     ",
      "  5             ",
      "                ",
      "                "
    ],
    [
      "    c           ",
      "    cbllllb     ",
      " dddc        S  ",
      "    c           ",
      "    c           ",
      "  ffc           ",
      "                ",
      "  5             ",
      "                ",
      "  5             ",
      "                ",
      "  5       c     ",
      "          c     ",
      "  5             ",
      "                ",
      "                "
    ],
    [
      "    c           ",
      "    cbllllb     ",
      " dddc       S   ",
      "    c     7     ",
      "    c           ",
      "  ffc           ",
      "          7     ",
      "  8             ",
      "                ",
      "  8       7     ",
      "                ",
      "  8       c     ",
      "          c     ",
      "  8             ",
      "                ",
      "                "
    ]
  ]
}