{
  "name": "multi_taigaresidence_2_floor1",
  "refpalette": "deceasedcraft:multi_taigaresidence_2/multi_taigaresidence_2_floor1_palette",
  "xsize": 16,
  "zsize": 16,
  "slices": [
    [
      "   abccccccccccc",
      "   abddddddddddd",
      " eeebfffffgh    ",
      "    bfffffg     ",
      "    bfffffg     ",
      "  iibfffffg     ",
      "     fffffg     ",
      "     fffffg     ",
      "     fffffg     ",
      "     fffffg     ",
      "     fffffg     ",
      "          b     ",
      "          b     ",
      "                ",
      "                ",
      "                "
    ],
    [
      "    j           ",
      "    b      kkkkk",
      " eeeb           ",
      "    bl  l m     ",
      "    bn lnlm     ",
      "  iibl  l m     ",
      "   ob     m     ",
      "   obl  l m     ",
      "   obn lnlm     ",
      "   obl  l m     ",
      "   ob     m     ",
      "   obbbbbbbbbbbb",
      "   ooooooobooooo",
      "                ",
      "                ",
      "                "
    ],
    [
      "                ",
      "    bp    p     ",
      " eeeb           ",
      "    b           ",
      "    b           ",
      "  iib           ",
      "    b           ",
      "    b           ",
      "    b           ",
      "    b           ",
      "    b qqqq      ",
      "    bbbbbbbbbbbb",
      "          b     ",
      "                ",
      "                ",
      "                "
    ],
    [
      "                ",
      "    b           ",
      " eeeb           ",
      "    b           ",
      "    b           ",
      "  iib           ",
      "  iib           ",
      "  iib           ",
      "  iib           ",
      "  iib           ",
      "  iib  ! r      ",
      "  iibbbbbbbbbbbb",
      "  iiiiiiiiiiiiii",
      "  iiiiiiiiiiiiii",
      "                ",
      "                "
    ],
    [
      "    b           ",
      "    b           ",
      " eeeb           ",
      "    b           ",
      "    b           ",
      "    b           ",
      "    b           ",
      "    b           ",
      "    b           ",
      "    b           ",
      "    b        stt",
      "    bbbbbbbbbbbb",
      "                ",
      "                ",
      "                ",
      "                "
    ],
    [
      "    b           ",
      "    bkkkkkkkkkkk",
      " eeebuuuuuuuuuuu",
      "   kbuuuuuuuuuuu",
      "   kbuuuuuuuuuuu",
      "   kbuuuuuuuuuuu",
      "   kbuuuuuuuuuuu",
      "   kbuuuuuuuuuuu",
      "   kbuuuuuuuuuuu",
      "   kbuuuuuuuuuuu",
      "   kbuuuuuuuuuuu",
      "   kbbbbbbbbbbbb",
      "   kkkkkkkkkkkkk",
      "                ",
      "                ",
      "                "
    ]
  ]
}