{
  "name": "multi_taigaresidence_2_floor6",
  "refpalette": "deceasedcraft:multi_taigaresidence_2/multi_taigaresidence_2_floor6_palette",
  "xsize": 16,
  "zsize": 16,
  "slices": [
    [
      "   abcccccdeffff",
      "   abcccccdddddd",
      " gggbhhhhhi!iiih",
      "  jkbhhhhhhhhhhh",
      "  jkbhhhhhhhhhhh",
      "  jkbhhhhhhhhhhh",
      "  jkbhhhhhhhhhhh",
      "  jkbhhhhhhhhhhh",
      "  jkbhhhhhdddddd",
      "  jkbhhhhhdddddd",
      "  jkbhhhhhdddddd",
      "  jkbbbbbbdddddd",
      "  jkkkkkkkglllll",
      "  jjjjjjjjg     ",
      "          g     ",
      "                "
    ],
    [
      "    m     bn    ",
      "    booopobbbbbb",
      " gggbq    rrrrr ",
      "   kbs          ",
      "   kbs    tuw x ",
      "   kbs    tuw y ",
      "   kbA          ",
      "   kbA        BC",
      "   kbD    bb    ",
      "   kbE FF I     ",
      "   kb!JJJKb  LL ",
      "   kbbMMMbbb    ",
      "   kkkkkkkg     ",
      "          g     ",
      "          g     ",
      "                "
    ],
    [
      "          bk    ",
      "    boooNobbbbbb",
      " gggbO P  rrrrr ",
      "    bQ          ",
      "    bR          ",
      "    b           ",
      "    bS          ",
      "    b      T    ",
      "    bU    bb    ",
      "    b     V     ",
      "    bW    bT    ",
      "    bb   bbb    ",
      "          g     ",
      "          g     ",
      "          g     ",
      "                "
    ],
    [
      "          bk    ",
      "    booooobbbbbb",
      " gggbX    r rr  ",
      "    bY          ",
      "    bY          ",
      "    bY          ",
      "    bZ          ",
      "    bZ     0    ",
      "    b1    bb    ",
      "    b1    2     ",
      "    b1    b     ",
      "    bb   bbb    ",
      "          g     ",
      "          g     ",
      "          g     ",
      "                "
    ],
    [
      "    b  3  b4    ",
      "    booooobbbbbb",
      " gggb           ",
      "   5b           ",
      "   5b           ",
      "   5b6 7   7    ",
      "   5b           ",
      "   5b           ",
      "   5b  3  bb    ",
      "   5b6    b     ",
      "   5b6    b     ",
      "   5bbbbbbbbbbbb",
      "   5555555g     ",
      "          g     ",
      "          g     ",
      "                "
    ],
    [
      "    b88888b     ",
      "    b88888bbbbbb",
      " gggb88888888888",
      "   9b88888888888",
      "   9b88888888888",
      "   9b88888888888",
      "   9b88888888888",
      "   9b88888888888",
      "   9b88888bb####",
      "   9b88888bfffff",
      "   9b88888bfffff",
      "   9bbbbbbbbbbbb",
      "   9999999g     ",
      "          g$$$$$",
      "          g     ",
      "                "
    ]
  ]
}