{
  "name": "multi_policeapartment_4_floor2",
  "refpalette": "deceasedcraft:multi_policeapartment_4/multi_policeapartment_4_floor2_palette",
  "xsize": 16,
  "zsize": 16,
  "slices": [
    [
      "                ",
      "                ",
      "aaaaaaaa        ",
      "bbacccca        ",
      "bbacccca        ",
      "bbbcccca        ",
      "bbaaaaaa        ",
      "bbbbbbba        ",
      "bbbbbbba        ",
      "bbbbbbba        ",
      "aaaadaaa        ",
      "ddddddda        ",
      "ddddddda        ",
      "aaaaaaaa        ",
      "                ",
      "                "
    ],
    [
      "                ",
      "                ",
      "aaaaaaaa        ",
      "efa ghia        ",
      "j ak   a        ",
      "l m n  a        ",
      "  aaaaaa        ",
      "  opqrsa        ",
      "       a        ",
      "tt    ua        ",
      "aaaawaaa        ",
      "      xy        ",
      "AAAAAABC        ",
      "CCCCCyCC        ",
      "                ",
      "                "
    ],
    [
      "                ",
      "                ",
      "aaaaaaaa        ",
      " DaE  ia        ",
      "  a   Fa        ",
      "  I nJ a        ",
      "  aaaaaa        ",
      "  oKL Ma        ",
      "       a        ",
      "NO     a        ",
      "PPaaQaaa        ",
      "       R        ",
      "                ",
      "     R          ",
      "                ",
      "                "
    ],
    [
      "                ",
      "                ",
      "SSRPPPaa        ",
      "  aTTTia        ",
      "  aU  Va        ",
      "  i  WXa        ",
      "  aaaaaa        ",
      "  oYZYZa        ",
      "       a        ",
      "01     a        ",
      "SSaa2aaa        ",
      "       R        ",
      "                ",
      "     R          ",
      "                ",
      "                "
    ],
    [
      "                ",
      "                ",
      "aaaaaaaa        ",
      "  a   ia        ",
      "  a   !a        ",
      "  a   3a        ",
      "  aaaaaa        ",
      "  i456 a        ",
      "       a        ",
      "       a        ",
      "aaaaaaaa        ",
      "       R        ",
      "                ",
      "     R          ",
      "                ",
      "                "
    ],
    [
      "                ",
      "                ",
      "SSSSSSSR        ",
      "7777777S        ",
      "7777777S        ",
      "7777777S        ",
      "7777777S        ",
      "7777777S        ",
      "7777777S        ",
      "7777777S        ",
      "8888888S        ",
      "       S        ",
      "       S        ",
      "SSSSSSSR        ",
      "                ",
      "                "
    ]
  ]
}