{
  "name": "multi_policeapartment_4_floor3",
  "refpalette": "deceasedcraft:multi_policeapartment_4/multi_policeapartment_4_floor3_palette",
  "xsize": 16,
  "zsize": 16,
  "slices": [
    [
      "                ",
      "                ",
      "aaaaaaaa        ",
      "bbacccca        ",
      "bbacccca        ",
      "bbbcccca        ",
      "bbaaaaaa        ",
      "bbbbbbba        ",
      "bbbbbbba        ",
      "bbbbbbba        ",
      "aaaadaaa        ",
      "ddddddda        ",
      "ddddddda        ",
      "aaaaaaaa        ",
      "                ",
      "                "
    ],
    [
      "                ",
      "                ",
      "aaaaaaaa        ",
      "efa ghia        ",
      "j ak  la        ",
      "m n o pa        ",
      "  aaaaaa        ",
      "  qrstua        ",
      "   w   a        ",
      "xx    ya        ",
      "aaaaAaaa        ",
      "      BC        ",
      "DDDDDDEF        ",
      "FFFFFCFF        ",
      "                ",
      "                "
    ],
    [
      "                ",
      "                ",
      "aaaaaaaa        ",
      " !aI  ia        ",
      "  a   Ja        ",
      "  K oLJa        ",
      "  aaaaaa        ",
      "  q   Ma        ",
      "       a        ",
      "NO     a        ",
      "PPaaQaaa        ",
      "       R        ",
      "                ",
      "     R          ",
      "                ",
      "                "
    ],
    [
      "                ",
      "                ",
      "SSRPPPaa        ",
      "  aTTTia        ",
      "  aU  Va        ",
      "  i  WXa        ",
      "  aaaaaa        ",
      "  YZ0Z0a        ",
      "       a        ",
      "12     a        ",
      "SSaa3aaa        ",
      "       R        ",
      "                ",
      "     R          ",
      "                ",
      "                "
    ],
    [
      "                ",
      "                ",
      "aaaaaaaa        ",
      "  a   ia        ",
      "  a   4a        ",
      "  a   5a        ",
      "  aaaaaa        ",
      "  i6 7 a        ",
      "       a        ",
      "       a        ",
      "aaaaaaaa        ",
      "       R        ",
      "                ",
      "     R          ",
      "                ",
      "                "
    ],
    [
      "                ",
      "                ",
      "SSSSSSSR        ",
      "8888888S        ",
      "8888888S        ",
      "8888888S        ",
      "8888888S        ",
      "8888888S        ",
      "8888888S        ",
      "8888888S        ",
      "9999999S        ",
      "       S        ",
      "       S        ",
      "SSSSSSSR        ",
      "                ",
      "                "
    ]
  ]
}