{
  "name": "multi_policeapartment_4_floor1",
  "refpalette": "deceasedcraft:multi_policeapartment_4/multi_policeapartment_4_floor1_palette",
  "xsize": 16,
  "zsize": 16,
  "slices": [
    [
      "                ",
      "                ",
      "aaaaaaaa        ",
      "       a        ",
      "       a        ",
      "       a        ",
      "       a        ",
      "       a        ",
      "       a        ",
      "       a        ",
      "       a        ",
      "       a        ",
      "bbbbbb a        ",
      "aaaaaaaa        ",
      "                ",
      "                "
    ],
    [
      "                ",
      "                ",
      "aaaaaaaa        ",
      "ccccccda        ",
      "ccccccca        ",
      "eeeeecca        ",
      "    ecca        ",
      "     cca        ",
      "     cca        ",
      "    ecca        ",
      " eeeecca        ",
      "ccccccca        ",
      "ccccccda        ",
      "aaaaaaaa        ",
      "ffffffffffffff  ",
      "gggggggggggggf  "
    ],
    [
      "                ",
      "                ",
      "aaaaaaaa        ",
      "hhhhhhia        ",
      "jjjkkkka        ",
      "jjjjjjka        ",
      "lllljjka        ",
      "lllljjka        ",
      "lllljjka        ",
      "lllljjka        ",
      "jjjjjjka        ",
      "jjjjjjka        ",
      "jjjjjjia        ",
      "aaaaaaaa        ",
      "                ",
      "                "
    ],
    [
      "                ",
      "                ",
      "aaaaaaaa        ",
      "hhhhhhha        ",
      "   k mha        ",
      "      ha        ",
      "      ha        ",
      "      ha        ",
      "      ha        ",
      "      ha        ",
      "      ha        ",
      "      ha        ",
      "kkkkkkka        ",
      "aaaaaaaa        ",
      "                ",
      "                "
    ],
    [
      "                ",
      "                ",
      "nnnnnnnn        ",
      "hhhohhpn        ",
      "   k mhn        ",
      "     mhn        ",
      "      hn        ",
      "      hn        ",
      "      hn        ",
      "      hn        ",
      "      hn        ",
      "      hn        ",
      "hhhhhhpn        ",
      "nnnnnnnn        ",
      "                ",
      "                "
    ],
    [
      "                ",
      "                ",
      "qqqqqqqr        ",
      "pppppppq        ",
      "sssssspq        ",
      "sssssspq        ",
      "sssssspq        ",
      "sssssspq        ",
      "sssssspq        ",
      "sssssspq        ",
      "sssssspq        ",
      "sssssspq        ",
      "pppppppq        ",
      "qqqqqqqr        ",
      "                ",
      "                "
    ]
  ]
}