{
  "name": "multi_policeapartment_4_top",
  "refpalette": "deceasedcraft:multi_policeapartment_4/multi_policeapartment_4_top_palette",
  "xsize": 16,
  "zsize": 16,
  "slices": [
    [
      "                ",
      "                ",
      "aaaaaaaa        ",
      "bbacccca        ",
      "bbacccca        ",
      "bbbcccca        ",
      "bbaaaaaa        ",
      "bbbbbbba        ",
      "bbbbbbba        ",
      "bbbbbbba        ",
      "aaaadaaa        ",
      "ddddddda        ",
      "ddddddda        ",
      "aaaaaaaa        ",
      "                ",
      "                "
    ],
    [
      "                ",
      "                ",
      "aaaaaaaa        ",
      "efaghija        ",
      "klamnopa        ",
      "  q  ria        ",
      "staaaaaa        ",
      "uwxyABCa        ",
      "     DEa        ",
      "FIJg  Ka        ",
      "aaaaLaaa        ",
      "      MN        ",
      "OOOOOOPQ        ",
      "QQQQQNQQ        ",
      "                ",
      "                "
    ],
    [
      "                ",
      "                ",
      "aaaaaaaa        ",
      " RaS  ja        ",
      "T a   Ua        ",
      "  V  W a        ",
      " Xaaaaaa        ",
      " YxZ0 Ea        ",
      "      1a        ",
      "II    2a        ",
      "34aa5aaa        ",
      "       6        ",
      "                ",
      "     6          ",
      "                ",
      "                "
    ],
    [
      "                ",
      "                ",
      "776444aa        ",
      "  a888ja        ",
      "  a9  #a        ",
      "  j  $%a        ",
      "  aaaaaa        ",
      "  x^&^&a        ",
      "       a        ",
      "I     *a        ",
      "67aa(aaa        ",
      "       6        ",
      "                ",
      "     6          ",
      "                ",
      "                "
    ],
    [
      "                ",
      "                ",
      "aaaaaaaa        ",
      "  a   ja        ",
      "  a   )a        ",
      "  a   +a        ",
      "  aaaaaa        ",
      "  j--  a        ",
      "       a        ",
      "       a        ",
      "aaaaaaaa        ",
      "       6        ",
      "                ",
      "     6          ",
      "                ",
      "                "
    ],
    [
      "                ",
      "                ",
      "77777776        ",
      "[[[[[[[7        ",
      "[[[[[[[7        ",
      "[[[[[[[7        ",
      "[[[[[[[7        ",
      "[[[[[[[7        ",
      "[[[[[[[7        ",
      "[[[[[[[7        ",
      "]]]]]]]7        ",
      "       7        ",
      "       7        ",
      "77777776        ",
      "                ",
      "                "
    ],
    [
      "                ",
      "                ",
      "aaaaaaaa        ",
      "ccccccca        ",
      "ccccc{ca        ",
      "ccccccca        ",
      "ccccccca        ",
      "ccccccca        ",
      "ccccc{ca        ",
      "ccccccca        ",
      "aaaaaaaa        ",
      "ddddddda        ",
      "ddddddda        ",
      "aaaaaaaa        ",
      "                ",
      "                "
    ],
    [
      "                ",
      "                ",
      "}}}}}}}}        ",
      "       }        ",
      "     | }        ",
      "     | }        ",
      "|||||| }        ",
      "     | }        ",
      "     | }        ",
      "       }        ",
      "}}}}}}}}        ",
      "                ",
      "                ",
      "                ",
      "                ",
      "                "
    ]
  ]
}