{
  "name": "multi_policeapartment_4_ground",
  "refpalette": "deceasedcraft:multi_policeapartment_4/multi_policeapartment_4_ground_palette",
  "xsize": 16,
  "zsize": 16,
  "slices": [
    [
      "aaaaaaaaaaaaaaaa",
      "aaaaaaaaaaaaaaaa",
      "bbbbbbbbaaaaaaaa",
      "cccccccbaaaaaaaa",
      "cccccccbaaaaaaaa",
      "cccccccbaaaaaaaa",
      "cccccccbaaaaaaaa",
      "cccccccbaaaaaaaa",
      "cccccccbaaaaaaaa",
      "cccccccbaaaaaaaa",
      "cccccccbaaaaaaaa",
      "cccccccbaaaaaaaa",
      "cccccccbaaaaaaaa",
      "ddddddbbaaaaaaaa",
      "eeeeeefeeeeeeeee",
      "HHHHHHHHHHHHHHHH"
    ],
    [
      "                ",
      "                ",
      "bbbbbbbb        ",
      "      gb        ",
      "      hb        ",
      "  i j hb        ",
      "  k l hb        ",
      "    m nb        ",
      "      nb        ",
      "  o pmnb        ",
      "  q r sb        ",
      "       b        ",
      "tttttt b        ",
      "     ubb        ",
      "      w         ",
      "                "
    ],
    [
      "                ",
      "                ",
      "bbbbbbbb        ",
      "       b        ",
      "      xb        ",
      "       b        ",
      "       b        ",
      "       b        ",
      "      sb        ",
      "       b        ",
      "       b        ",
      "       b        ",
      "yyyyyyAb        ",
      "     ubb        ",
      "      B         ",
      "                "
    ],
    [
      "                ",
      "                ",
      "bbbbbbbb        ",
      "       b        ",
      "       b        ",
      "       b        ",
      "       b        ",
      "       b        ",
      "       b        ",
      "       b        ",
      "       b        ",
      "       b        ",
      "yyyyyy b        ",
      "     ubb        ",
      "      C         ",
      "                "
    ],
    [
      "                ",
      "                ",
      "bbbbbbbb        ",
      "       b        ",
      "       D        ",
      "       D        ",
      "       D        ",
      "       E        ",
      "       E        ",
      "       D        ",
      "       D        ",
      "       D        ",
      "yyyyyy b        ",
      "     ubb        ",
      "      F         ",
      "                "
    ],
    [
      "                ",
      "                ",
      "bbbbbbbb        ",
      "       b        ",
      "       b        ",
      "       b        ",
      "       b        ",
      "       b        ",
      "       b        ",
      "       b        ",
      "       b        ",
      "       b        ",
      "yyyyyy b        ",
      "IIIIIJbb        ",
      "                ",
      "                "
    ]
  ]
}