{
  "name": "multi_policeapartment_4_floor4",
  "refpalette": "deceasedcraft:multi_policeapartment_4/multi_policeapartment_4_floor4_palette",
  "xsize": 16,
  "zsize": 16,
  "slices": [
    [
      "                ",
      "                ",
      "aaaaaaaa        ",
      "bbacccca        ",
      "bbacccca        ",
      "bbbcccca        ",
      "bbaaaaaa        ",
      "bbbbbbba        ",
      "bbbbbbba        ",
      "bbbbbbba        ",
      "aaaadaaa        ",
      "ddddddda        ",
      "ddddddda        ",
      "aaaaaaaa        ",
      "                ",
      "                "
    ],
    [
      "                ",
      "                ",
      "aaaaaaaa        ",
      "efaghija        ",
      "k al   a        ",
      "m n o  a        ",
      "  aaaaaa        ",
      "  pqrsta        ",
      "       a        ",
      "uu    wa        ",
      "aaaaxaaa        ",
      "      yA        ",
      "BBBBBBCD        ",
      "DDDDDADD        ",
      "                ",
      "                "
    ],
    [
      "                ",
      "                ",
      "aaaaaaaa        ",
      " Ea   ja        ",
      "  a    a        ",
      "  F oIJa        ",
      "  aaaaaa        ",
      "  pK  La        ",
      "       a        ",
      "MN     a        ",
      "OOaaPaaa        ",
      "       Q        ",
      "                ",
      "     Q          ",
      "                ",
      "                "
    ],
    [
      "                ",
      "                ",
      "RRQOOOaa        ",
      "  aSSSja        ",
      "  aT  Ua        ",
      "  j  VWa        ",
      "  aaaaaa        ",
      "  pXYXYa        ",
      "       a        ",
      "Z0     a        ",
      "RRaa1aaa        ",
      "       Q        ",
      "                ",
      "     Q          ",
      "                ",
      "                "
    ],
    [
      "                ",
      "                ",
      "aaaaaaaa        ",
      "  a   ja        ",
      "  a   2a        ",
      "  a   3a        ",
      "  aaaaaa        ",
      "  j  44a        ",
      "       a        ",
      "       a        ",
      "aaaaaaaa        ",
      "       Q        ",
      "                ",
      "     Q          ",
      "                ",
      "                "
    ],
    [
      "                ",
      "                ",
      "RRRRRRRQ        ",
      "5555555R        ",
      "5555555R        ",
      "5555555R        ",
      "5555555R        ",
      "5555555R        ",
      "5555555R        ",
      "5555555R        ",
      "6666666R        ",
      "       R        ",
      "       R        ",
      "RRRRRRRQ        ",
      "                ",
      "                "
    ]
  ]
}