{
  "name": "multi_terraceplaza_24_floor2",
  "refpalette": "deceasedcraft:multi_terraceplaza_24/multi_terraceplaza_24_floor2_palette",
  "xsize": 16,
  "zsize": 16,
  "slices": [
    [
      "         a      ",
      "         b      ",
      "         b      ",
      " c       deeeeee",
      "         b  ffff",
      "         bbbgggg",
      "         a      ",
      "                ",
      "h               ",
      "ij              ",
      "k               ",
      "         a      ",
      "         b      ",
      "         b      ",
      "         d      ",
      "         b      "
    ],
    [
      "        lmn     ",
      "         m     o",
      "         m      ",
      "         deeeeee",
      "         mppqqrq",
      "         mpppppp",
      "        smn     ",
      "h       smn     ",
      "ij      smn     ",
      "k       smn     ",
      "        tmn     ",
      "        smn     ",
      "         m      ",
      "         m      ",
      "         d  u   ",
      "         m      "
    ],
    [
      "         m  w   ",
      "         m      ",
      "         m      ",
      "         deeeeee",
      "         m     r",
      "         m      ",
      "h        m      ",
      "ij       m      ",
      "k        m      ",
      "         m      ",
      "         m      ",
      "         m      ",
      "         m      ",
      "         m      ",
      "         d  u   ",
      "         m      "
    ],
    [
      "xxxxxxxxxyAAABBB",
      "xxxxxxxxxyAAAAAA",
      "xxxxxxxxxyAAAAAA",
      "yyyyyyyyydyyyyyy",
      "C        yAAAAAA",
      "h        yAAAAAA",
      "ij       yAAAAAA",
      "k        yAAAAAA",
      "         yAAAAAA",
      "         yAAAAAA",
      "         yAAAAAA",
      "         yAAAAAA",
      "         yAAAAAA",
      "         yAAAAAA",
      "yyyyyyyyydyyyyyy",
      "         y      "
    ],
    [
      "DDDDDDDDDEFFFFFF",
      "DDDDDDDDDEFFFFFF",
      "DDDDDDDDDEFFFFFF",
      "IggggggggdEEEEEE",
      "Ij       EJKKJJK",
      "ij       EJJKKJK",
      "k        EKJKJJJ",
      "         EJJJKJJ",
      "         EJJKJJJ",
      "         EJJJJJJ",
      "         EJJJJJJ",
      "         EJJJJJJ",
      "         EJJJJJJ",
      "LLLLLLLLLEMMMMMM",
      "yyyyyyyyydyyyyyy",
      "FFFFFFFFFFFFFFFF"
    ],
    [
      "             NNN",
      "                ",
      "                ",
      "kOOOOOOOOd      ",
      "k        O      ",
      "k        O P    ",
      "         O Q    ",
      "         O R    ",
      "         O      ",
      "         O      ",
      "LLLLLLLLLOSSSTSS",
      "UUUUUUUUUU      ",
      "FFFFFFFFFFLLLLLL",
      "VVVVVVVVVVVVVVVV",
      "VVVVVVVVVVVVVVVV",
      "WWWWWWWWWWWWWWWW"
    ]
  ]
}