{
  "name": "multi_terraceplaza_24_floor3",
  "refpalette": "deceasedcraft:multi_terraceplaza_24/multi_terraceplaza_24_floor3_palette",
  "xsize": 16,
  "zsize": 16,
  "slices": [
    [
      "             a  ",
      "                ",
      "                ",
      "         b      ",
      "                ",
      "                ",
      "                ",
      "cccccccccc      ",
      "dddddddddd      ",
      "eeeeeeeeeefggggg",
      "hhhhhhhhhhfggggg",
      "iiiiiiiiiiiiiiii",
      "                ",
      "jjjjjjjjjjjjjjjj",
      "                ",
      "                "
    ],
    [
      "                ",
      "                ",
      "                ",
      "         b      ",
      "cccccccccc      ",
      "dddddddddd      ",
      "eeeeeeeeeecccccc",
      "hhhhhhhhhhfggggg",
      "iiiiiiiiiifggggg",
      "                ",
      "                ",
      "                ",
      "                ",
      "                ",
      "                ",
      "                "
    ],
    [
      "                ",
      "cccccccccccccccc",
      "dddddddddddddddd",
      "kkkkkkkkkbkkkkkk",
      "llllllllllllllll",
      "iiiiiiiiiiiiiiii",
      "                ",
      "                ",
      "                ",
      "                ",
      "                ",
      "                ",
      "                ",
      "                ",
      "                ",
      "                "
    ],
    [
      "eeeeeeeeeeeeeeee",
      "hhhhhhhhhhhhhhhh",
      "llllllllllllllll",
      "mmmmmmmmmmmmmmmm",
      "jjjjjjjjjjjjjjjj",
      "                ",
      "                ",
      "                ",
      "                ",
      "                ",
      "                ",
      "                ",
      "                ",
      "                ",
      "                ",
      "                "
    ],
    [
      "                ",
      "                ",
      "                ",
      "                ",
      "                ",
      "                ",
      "                ",
      "                ",
      "                ",
      "                ",
      "                ",
      "                ",
      "                ",
      "                ",
      "                ",
      "                "
    ],
    [
      "                ",
      "                ",
      "                ",
      "                ",
      "                ",
      "                ",
      "                ",
      "                ",
      "                ",
      "                ",
      "                ",
      "                ",
      "                ",
      "                ",
      "                ",
      "                "
    ]
  ]
}