{
  "name": "multi_terraceplaza_24_ground",
  "refpalette": "deceasedcraft:multi_terraceplaza_24/multi_terraceplaza_24_ground_palette",
  "xsize": 16,
  "zsize": 16,
  "slices": [
    [
      "aabaaaaaacdddddd",
      "aabaaaaaacdddddd",
      "aabaaaaaacdddddd",
      "aabaaaaaaeffffff",
      "aabaaaaaacgggggg",
      "aaaaaaaaacgggggg",
      "aaaaaaaaacgggggg",
      "aaaaaaaaacgggggg",
      "aaaaaaaaacgggggg",
      "aaaaaaaaacgggggg",
      "aaaaaaaaacgggggg",
      "aaaaaaaaacgggggg",
      "aaaaaaaaacgggggg",
      "aabaaaaaacgggggg",
      "aabaaaaaaeffffff",
      "aabaaaaaacgggggg"
    ],
    [
      " hi      jk     ",
      " li      m      ",
      " bi      mnnnnnn",
      "opq      effffff",
      " b       m r r r",
      " bs      m t t t",
      "         j r r r",
      "                ",
      "                ",
      "              u ",
      "           ww u ",
      "         j    u ",
      " bs      m ww u ",
      " b       m    u ",
      "opq      effffff",
      " bi      mxyABxy"
    ],
    [
      "         jk     ",
      "         m      ",
      "         mCCDCCD",
      " E       effffff",
      " F       m      ",
      " I       m J K  ",
      "         j      ",
      "                ",
      "                ",
      "              LM",
      "              N ",
      "         j    O ",
      " F       m    P ",
      " I       m    O ",
      " E       effffff",
      "         mQ!RSTU"
    ],
    [
      "         jk     ",
      "         m      ",
      "         mCDCCDC",
      " V       effffff",
      "         m      ",
      "         m      ",
      "         j      ",
      "                ",
      "                ",
      "                ",
      "                ",
      "         j      ",
      "         m      ",
      "         m      ",
      " V       effffff",
      "         mWWWWW "
    ],
    [
      "         jk     ",
      "         m      ",
      "         mXYXYXY",
      " V       effffff",
      "         m      ",
      "         m     Z",
      "         j      ",
      "                ",
      "                ",
      "                ",
      "               0",
      "         j     0",
      "         m     0",
      "         m     0",
      " V       effffff",
      "         m      "
    ],
    [
      "        012     ",
      "         1      ",
      "         1 34536",
      "         effffff",
      "         1      ",
      "         1      ",
      "        712     ",
      "        812     ",
      "        912     ",
      "        812     ",
      "        912     ",
      "        912     ",
      "         1      ",
      "         1      ",
      "         effffff",
      "         1      "
    ]
  ]
}