{
  "name": "multi_terraceplaza_24_base2",
  "refpalette": "deceasedcraft:multi_terraceplaza_24/multi_terraceplaza_24_base2_palette",
  "xsize": 16,
  "zsize": 16,
  "slices": [
    [
      "aaaaaaaaaaaaaaaa",
      "aaaaaaaaaaaaaaaa",
      "aaaaaaaaaaaaaaaa",
      "aaaaaaaaabaaaaaa",
      "aaaaaaaaaaaaaaaa",
      "aaaaaaaaaaaaaaaa",
      "aaaaaaaaaaaaaaaa",
      "aaaaaaaaaaaaaaaa",
      "aaaaaaaaaaaaaaaa",
      "aaaaaaaaaaaaaaaa",
      "aaaaaaaaaaaaaaaa",
      "aaaaaaaaaaaaaaaa",
      "aaaaaaaaaaaaaaaa",
      "aaaaaaaaaaaaaaaa",
      "aaaaaaaaabaaaaaa",
      "aaaaaaaaaaaaaaaa"
    ],
    [
      " cd ef gc cd ef ",
      "  d ef g   d ef ",
      "  d ef g   d ef ",
      "hi  ef  ibh  ef ",
      "                ",
      "                ",
      "                ",
      "     jjjjjjjj   ",
      "    kllllllllm  ",
      "    nllllllllo  ",
      "     iiiiiiii   ",
      "                ",
      "                ",
      "     pqqqqrqs   ",
      "     tuuubuuw   ",
      "     txxxxxxs   "
    ],
    [
      " yA    !y yA    ",
      "  A    A   A    ",
      "  A    A   A    ",
      "         b      ",
      "                ",
      "                ",
      "                ",
      "                ",
      "     BCDEFFFF   ",
      "     EIJKLLLL   ",
      "                ",
      "                ",
      "                ",
      "     tMNNNNOw   ",
      "     tuuubuus   ",
      "     pPQQPPQw   "
    ],
    [
      "                ",
      "                ",
      "                ",
      "         b      ",
      "                ",
      "                ",
      "                ",
      "                ",
      "                ",
      "                ",
      "                ",
      "                ",
      "                ",
      "     pRSS TRs   ",
      "     pUUUbUUs   ",
      "     tQPPPQPw   "
    ],
    [
      "                ",
      "                ",
      "                ",
      "         b      ",
      "                ",
      "                ",
      "                ",
      "                ",
      "                ",
      "                ",
      "                ",
      "                ",
      "                ",
      "                ",
      "         b      ",
      "      VVVVVV    "
    ],
    [
      "                ",
      "                ",
      "         W      ",
      "         b      ",
      "         X      ",
      "                ",
      "                ",
      "                ",
      "                ",
      "                ",
      "                ",
      "                ",
      "                ",
      "         W      ",
      "         b      ",
      "         X      "
    ]
  ]
}