{
  "name": "multi_terraceplaza_24_base1",
  "refpalette": "deceasedcraft:multi_terraceplaza_24/multi_terraceplaza_24_base1_palette",
  "xsize": 16,
  "zsize": 16,
  "slices": [
    [
      "                ",
      "                ",
      "                ",
      "         a      ",
      "                ",
      "                ",
      "                ",
      "                ",
      "                ",
      "                ",
      "                ",
      "                ",
      "                ",
      "                ",
      "         a      ",
      "                "
    ],
    [
      "                ",
      "                ",
      "                ",
      "         a      ",
      "                ",
      "                ",
      "                ",
      "                ",
      "                ",
      "                ",
      "                ",
      "                ",
      "                ",
      "                ",
      "         a      ",
      "                "
    ],
    [
      "                ",
      "                ",
      "                ",
      "         a      ",
      "                ",
      "                ",
      "                ",
      "                ",
      "                ",
      "                ",
      "                ",
      "                ",
      "                ",
      "                ",
      "         a      ",
      "                "
    ],
    [
      "bb              ",
      "bb              ",
      "bb              ",
      "bb       a      ",
      "bb              ",
      "bb              ",
      "bb              ",
      "bb              ",
      "bb              ",
      "bb              ",
      "bb              ",
      "bb              ",
      "bb              ",
      "bb              ",
      "bb       a      ",
      "bb              "
    ],
    [
      "cddddddddddddddd",
      "cddddddddddddddd",
      "cddddddddddddddd",
      "cddddddddadddddd",
      "cddddddddddddddd",
      "cddddddddddddddd",
      "cddddddddddddddd",
      "cddddddddddddddd",
      "cddddddddddddddd",
      "cddddddddddddddd",
      "cddddddddddddddd",
      "cddddddddddddddd",
      "cddddddddddddddd",
      "cddddddddddddddd",
      "cddddddddadddddd",
      "cddddddddddddddd"
    ],
    [
      "effffffffgffffff",
      "effffffffgffffff",
      "effffffffgffffff",
      "gggggggggagggggg",
      "effffffffgffffff",
      "effffffffgffffff",
      "effffffffgffffff",
      "effffffffgffffff",
      "effffffffgffffff",
      "effffffffgffffff",
      "effffffffgffffff",
      "effffffffgffffff",
      "effffffffgffffff",
      "effffffffgffffff",
      "gggggggggagggggg",
      "effffffffgffffff"
    ]
  ]
}