{
  "name": "multi_terraceplaza_24_floor1",
  "refpalette": "deceasedcraft:multi_terraceplaza_24/multi_terraceplaza_24_floor1_palette",
  "xsize": 16,
  "zsize": 16,
  "slices": [
    [
      "         a      ",
      "         a      ",
      "         a      ",
      "         bcccccc",
      "         a      ",
      "         a      ",
      "         a      ",
      "         a      ",
      "         a      ",
      "         a      ",
      "         a      ",
      "         a      ",
      "         a      ",
      "         a      ",
      "         bcccccc",
      "         a      "
    ],
    [
      "dddddddddefgffgf",
      "dddddddddeffffff",
      "dddddddddehihhih",
      "eeeeeeeeebeeeeee",
      "dddddddddeffffff",
      "dddddddddeffffff",
      "dddddddddeffjjff",
      "dddddddddeffffff",
      "dddddddddeffffff",
      "dddddddddeffffff",
      "dddddddddeffffff",
      "dddddddddeffjjff",
      "dddddddddeffffff",
      "dddddddddeffffff",
      "eeeeeeeeebeeeeee",
      "dddddddddeffffff"
    ],
    [
      "kkkkkkkkklmmmmmm",
      "kkkkkkkkklmmmmmm",
      "kknkkkkkklmmmmmm",
      "kknkkkkkkbcccccc",
      "kknkkkkkklmmmmmm",
      "kknkkkkkklmmmmmm",
      "kknkkkkkklmmmmmm",
      "kkkkkkkkklmmmmmm",
      "kkkkkkkkklmmmmmm",
      "kkkkkkkkklmmmmmm",
      "kkkkkkkkklmmmmmm",
      "kkkkkkkkklmmmmmm",
      "okkkkkkkklmmmmmm",
      "pkkkkkkkklmmmmmm",
      "pkkkkkkkkbmmmmmm",
      "kkkkkkkkklmmmmmm"
    ],
    [
      "         q rssst",
      " nu      w x    ",
      " n       wyA    ",
      "BCD      bcccccc",
      " nE      wFFI I ",
      " JE      wwwKLKL",
      " ME      q  NNN ",
      "  M             ",
      "              O ",
      "              O ",
      "              O ",
      "o        q    O ",
      "PQ       w      ",
      "R        w      ",
      "R        bS     ",
      "         wT  U  "
    ],
    [
      "         q VWXYZ",
      " 0       w      ",
      " 1       w2    3",
      " 4       bcccccc",
      "         w56I7I7",
      "         wwwK8K8",
      "         q      ",
      "                ",
      "                ",
      "                ",
      "o               ",
      "PQ       q      ",
      "R        w      ",
      "         w      ",
      "         b      ",
      "         w9  #  "
    ],
    [
      "         q      ",
      "         w      ",
      "         w2     ",
      " 2       bcccccc",
      "         w  I!I$",
      "         wwwKKKK",
      "         q      ",
      "                ",
      "                ",
      "o               ",
      "PQ              ",
      "R        q      ",
      "         w      ",
      "         w      ",
      "         b      ",
      "         w%     "
    ]
  ]
}