{
  "name": "multi_alienresearch_6_base2",
  "refpalette": "deceasedcraft:multi_alienresearch_6/multi_alienresearch_6_base2_palette",
  "xsize": 16,
  "zsize": 16,
  "slices": [
    [
      "  a b cd     cd ",
      "   a    ceeed   ",
      "  b a     b     ",
      "     aa   b   aa",
      "       aaaaaaa  ",
      "          b     ",
      "                ",
      "aa              ",
      "f aa            ",
      "fff aa          ",
      "ggfff aaaaaaaaa ",
      "ggggfffffhhhffff",
      "ggggggggghhhgggg",
      "gggggggggggggggg",
      "gggggiiiiiiiiiii",
      "gggggi         i"
    ],
    [
      "      j         ",
      "   k            ",
      "  a             ",
      " a              ",
      "b         k     ",
      "          a     ",
      "          a     ",
      "f         b     ",
      "gff             ",
      "gggff     a     ",
      "gggggffffhhhffff",
      "gggggggggggggggg",
      "gggggggggggggggg",
      "gggggggggggggggg",
      "gggggiiiiiiiiiii",
      "gggggi lmmmmmn i"
    ],
    [
      "                ",
      "                ",
      "                ",
      " k              ",
      "a               ",
      "h               ",
      "ff        k     ",
      "gfff      a     ",
      "gggffff   a   ff",
      "gggggffffhhhffff",
      "gggggggggggggggg",
      "gggggggggggggggg",
      "gggggggggggggggg",
      "gggggggggggggggg",
      "gggggiiiiiiiiiii",
      "gggggifofffffofi"
    ],
    [
      "                ",
      "                ",
      "  a             ",
      "ha              ",
      "hh              ",
      "gfff      a     ",
      "ggffff    a    f",
      "ggggfffffhhhffff",
      "gggggggffhhhffgg",
      "gggggggggggggggg",
      "gggggggggggggggg",
      "gggggggggggggggg",
      "gggggggggggggggg",
      "gggggggggggggggg",
      "gggggggggggggggg",
      "gggggggggggggggg"
    ],
    [
      "f               ",
      "ff a            ",
      "fhh             ",
      "ghhf      a     ",
      "ggffff    a    f",
      "ggggfffffhhhffff",
      "ggggggfffhhhfffg",
      "gggggggggggggggg",
      "gggggggggggggggg",
      "gggggggggggggggg",
      "gggggggggggggggg",
      "gggggggggggggggg",
      "gggggggggggggggg",
      "gggggggggggggggg",
      "gggggggggggggggg",
      "gggggggggggggggg"
    ],
    [
      "gffha   aaaaa   ",
      "gghhhf    a    f",
      "ggghfff   a   ff",
      "ggggfffffhhhffff",
      "ggggggfffhhhfffg",
      "gggggggggggggggg",
      "gggggggggggggggg",
      "gggggggggggggggg",
      "gggggggggggggggg",
      "gggggggggggggggg",
      "gggggggggggggggg",
      "gggggggggggggggg",
      "gggggggggggggggg",
      "gggggggggggggggg",
      "gggggggggggggggg",
      "gggggggggggggggg"
    ]
  ]
}