{
  "name": "multi_alienresearch_6_ground",
  "refpalette": "deceasedcraft:multi_alienresearch_6/multi_alienresearch_6_ground_palette",
  "xsize": 16,
  "zsize": 16,
  "slices": [
    [
      "aabbaacdeeeddedd",
      "aaaaaacdddeeeddd",
      "babaaaczzdzeeeze",
      "aaaaabcedeededdd",
      "aabbaafdeededdzz",
      "zbbzbbceedddeded",
      "bbabazcdezdedeee",
      "babbbacddeezeede",
      "babaabceeddddddd",
      "bbaabaczddeddedz",
      "aaabaacdedeeddde",
      "aaaaaafddeeddedd",
      "baaabacdddezeddd",
      "aaaaabcdeddddded",
      "aaaaaacdddeeedde",
      "aaaabacedededddd"
    ],
    [
      " gg  g!h   g    ",
      "g  i  hi jh     ",
      "        kh  g k ",
      "      g       g ",
      "llmncco   g    k",
      "pq   rls        ",
      "     kl  k      ",
      "     tc    k    ",
      "    s l         ",
      "   u wcp       k",
      "xywuwwc         ",
      "lcccllo         ",
      "A AABBc    p    ",
      "     Al         ",
      "    A c         ",
      "C    Dc         "
    ],
    [
      "                ",
      "                ",
      "                ",
      "                ",
      "EFIJFEo         ",
      "      F         ",
      "      E         ",
      "      E         ",
      "      E         ",
      "      F         ",
      "  D  wE         ",
      "FFEEEEo         ",
      "    ABF         ",
      "      F         ",
      "      E         ",
      "      E         "
    ],
    [
      "                ",
      "                ",
      "                ",
      "                ",
      "KFLMEFo         ",
      "      E         ",
      "      K         ",
      "      F         ",
      "      E         ",
      "      E         ",
      "      F         ",
      "EEEEEEo         ",
      "     NE         ",
      "      E         ",
      "      E         ",
      "      E         "
    ],
    [
      "                ",
      "                ",
      "                ",
      "                ",
      " KKFFEo         ",
      "     OF         ",
      "     O          ",
      "     OP         ",
      "     O          ",
      "     OP         ",
      "     OF         ",
      "EEFEEFo         ",
      "     OF         ",
      "     OP         ",
      "     OQ         ",
      "     OP         "
    ],
    [
      "                ",
      "                ",
      "                ",
      "                ",
      "ooR  Fo         ",
      "      K         ",
      "      F         ",
      "      K         ",
      "      F         ",
      "      E         ",
      "      F         ",
      "ooRKKEo         ",
      "      E         ",
      "      F         ",
      "      F         ",
      "      E         "
    ]
  ]
}