{
  "name": "multi_alienresearch_6_base6",
  "refpalette": "deceasedcraft:multi_alienresearch_6/multi_alienresearch_6_base6_palette",
  "xsize": 16,
  "zsize": 16,
  "slices": [
    [
      "  a             ",
      "   a            ",
      "    a           ",
      "     aa       aa",
      "       aaaaaaa  ",
      "                ",
      "                ",
      "                ",
      "                ",
      "                ",
      "                ",
      "                ",
      "                ",
      "                ",
      "                ",
      "                "
    ],
    [
      "                ",
      "                ",
      "                ",
      "                ",
      "                ",
      "                ",
      "                ",
      "                ",
      "                ",
      "                ",
      "                ",
      "                ",
      "                ",
      "                ",
      "                ",
      "                "
    ],
    [
      "   bccddeeeeeddc",
      "    bcdcdddddcdc",
      "     cdcccdcccdc",
      "       bbcdcbb  ",
      "                ",
      "                ",
      "                ",
      "                ",
      "                ",
      "                ",
      "                ",
      "                ",
      "                ",
      "                ",
      "                ",
      "                "
    ],
    [
      " fgh            ",
      "cgggh           ",
      " b ggfij klk jif",
      "  bgf fhhmimhhf ",
      "   c fgggfnfgggf",
      "     cb gf fg bc",
      "       bbc cbb  ",
      "                ",
      "                ",
      "                ",
      "                ",
      "                ",
      "                ",
      "                ",
      "                ",
      "                "
    ],
    [
      " f              ",
      "f               ",
      "gho  fi   p   if",
      "ggh f f   i   f ",
      "bggf f   fnf   f",
      " bbf fho f f ohf",
      "  cqfgghhf fhhgg",
      "    bbbggf fggbb",
      "       bbcqcbb  ",
      "                ",
      "                ",
      "                ",
      "                ",
      "                ",
      "                ",
      "                "
    ],
    [
      "r@              ",
      "@               ",
      "     @i       i@",
      "    @r@   i   @r",
      "g  @r@   @r@   @",
      "ghh@r@   @r@   @",
      "bghr@    @r@    ",
      "ddsthhh  @r@  hh",
      "  ddggghh@r@hhgg",
      "    ddbggtstggbd",
      "      ddddddddd ",
      "                ",
      "                ",
      "                ",
      "                ",
      "                "
    ]
  ]
}