{
  "name": "multi_alienresearch_6_base9",
  "refpalette": "deceasedcraft:multi_alienresearch_6/multi_alienresearch_6_base9_palette",
  "xsize": 16,
  "zsize": 16,
  "slices": [
    [
      "aaaabbbbbbcbbbbb",
      "aaaaaaddbbbbbdda",
      "aaaaaaaddbbbddaa",
      "aaaaaaaaaaaaaaaa",
      "aaaaaaaaaaaaaaaa",
      "aaaaaaaaaaaaaaaa",
      "aaaaaaaaaaaaaaaa",
      "aaaaaaaaaaaaaaaa",
      "aaaaaaaaaaaaaaaa",
      "aaaaaaaaaaaaaaaa",
      "aaaaaaaaaaaaaaaa",
      "aaaaaaaaaaaaaaaa",
      "aaaaaaaaaaaaaaaa",
      "aaaaaaaaaaaaaaaa",
      "aaaaaaaaaaaaaaaa",
      "aaaaaaaaaaaaaaaa"
    ],
    [
      "addbe   eeeee   ",
      "aabbbd    e    d",
      "aaabddd   e   dd",
      "aaaadddddbbbdddd",
      "aaaaaadddbbbddda",
      "aaaaaaaaaaaaaaaa",
      "aaaaaaaaaaaaaaaa",
      "aaaaaaaaaaaaaaaa",
      "aaaaaaaaaaaaaaaa",
      "aaaaaaaaaaaaaaaa",
      "aaaaaaaaaaaaaaaa",
      "aaaaaaaaaaaaaaaa",
      "aaaaaaaaaaaaaaaa",
      "aaaaaaaaaaaaaaaa",
      "aaaaaaaaaaaaaaaa",
      "aaaaaaaaaaaaaaaa"
    ],
    [
      "d               ",
      "dd e            ",
      "dbb             ",
      "abbd      e     ",
      "aadddd    e    d",
      "aaaadddddbbbdddd",
      "aaaaaadddbbbddda",
      "aaaaaaaaaaaaaaaa",
      "aaaaaaaaaaaaaaaa",
      "aaaaaaaaaaaaaaaa",
      "aaaaaaaaaaaaaaaa",
      "aaaaaaaaaaaaaaaa",
      "aaaaaaaaaaaaaaaa",
      "aaaaaaaaaaaaaaaa",
      "aaaaaaaaaaaaaaaa",
      "aaaaaaaaaaaaaaaa"
    ],
    [
      "                ",
      "                ",
      "  e             ",
      "be              ",
      "bb              ",
      "addd      e     ",
      "aadddd    e    d",
      "aaaadddddbbbdddd",
      "aaaaaaaddbbbddaa",
      "aaaaaaaaaaaaaaaa",
      "aaaaaaaaaaaaaaaa",
      "aaaaaaaaaaaaaaaa",
      "aaaaaaaaaaaaaaaa",
      "aaaaaaaaaaaaaaaa",
      "aaaaaaaaaaaaaaaa",
      "aaaaaaaaaaaaaaaa"
    ],
    [
      "                ",
      "   f            ",
      "  e             ",
      " g              ",
      "e         f     ",
      "b         e     ",
      "dd        g     ",
      "addd      e     ",
      "aaadddd   e   dd",
      "aaaaaddddbbbdddd",
      "aaaaaaaaaaaaaaaa",
      "aaaaaaaaaaaaaaaa",
      "aaaaaaaaaaaaaaaa",
      "aaaaaaaaaaaaaaaa",
      "aaaaaaaaaaaaaaaa",
      "aaaaaaaaaaaaaaaa"
    ],
    [
      "  e e   eeeee   ",
      "   e      e     ",
      "  g e     e     ",
      "     ee   e   ee",
      "      heeeeeeeh ",
      "          g     ",
      "                ",
      "d               ",
      "add             ",
      "aaadd     e     ",
      "aaaaaddddbbbdddd",
      "aaaaaaaaaaaaaaaa",
      "aaaaaaaaaaaaaaaa",
      "aaaaaaaaaaaaaaaa",
      "aaaaaaaaaaaaaaaa",
      "aaaaaaaaaaaaaaaa"
    ]
  ]
}