{
  "name": "multi_alienresearch_6_base8",
  "refpalette": "deceasedcraft:multi_alienresearch_6/multi_alienresearch_6_base8_palette",
  "xsize": 16,
  "zsize": 16,
  "slices": [
    [
      "abbbbbbcccccccbb",
      "abbbbbbbbbbbbbbb",
      "aabbbbbbbbbbbbbb",
      " adbbbbbbbbbbbbb",
      " ddddbbbbbbbbbbb",
      "dddddddbbbbbbbdd",
      "dddddddddddddddd",
      "dddddddddddddddd",
      "eddddddddddddddd",
      "eeeddddddddddddd",
      "ffeeedddddgddddd",
      "ffffeeehhhhhhhee",
      "ffffijjjjhhhjjjj",
      "ffffijjjjjjjjjjj",
      "ffffijjjjjjjjjjj",
      "ffffijjjjjjjjjjj"
    ],
    [
      "a      k lll k  ",
      "a               ",
      "aa   mnop   mqrp",
      " as    t     u  ",
      " w              ",
      "w               ",
      "                ",
      "          ~     ",
      "                ",
      "                ",
      "eexy            ",
      "ffeeABC   g   DE",
      "ffffeeeh hhh hee",
      "ffffiFIhJhghKhFF",
      "ffffi           ",
      "ffffi           "
    ],
    [
      "                ",
      "                ",
      "      L      MN ",
      "                ",
      "                ",
      "                ",
      "                ",
      "          ~     ",
      "                ",
      "                ",
      "                ",
      "ee              ",
      "ffeee     g     ",
      "ffffieehOhhhPhee",
      "ffffi     g     ",
      "ffffi           "
    ],
    [
      "                ",
      "                ",
      "                ",
      "                ",
      "                ",
      "                ",
      "                ",
      "          ~     ",
      "                ",
      "                ",
      "                ",
      "                ",
      "eee             ",
      "fffee   Q g Q   ",
      "ffffieehhhhhhhee",
      "ffffi     g     "
    ],
    [
      "                ",
      "                ",
      "                ",
      "                ",
      "                ",
      "                ",
      "                ",
      "          ~     ",
      "                ",
      "                ",
      "                ",
      "                ",
      "e               ",
      "fee             ",
      "fffeeee   g   ee",
      "ffffieeeehhheeee"
    ],
    [
      "                ",
      "                ",
      "                ",
      "                ",
      "                ",
      "                ",
      "                ",
      "          ~     ",
      "                ",
      "                ",
      "                ",
      "                ",
      "                ",
      "e               ",
      "feee      g     ",
      "ffffeeeeehhheeee"
    ]
  ]
}