{
  "name": "multi_alienresearch_6_base5",
  "refpalette": "deceasedcraft:multi_alienresearch_6/multi_alienresearch_6_base5_palette",
  "xsize": 16,
  "zsize": 16,
  "slices": [
    [
      "a  bcccccccccccc",
      "    bccccccccccc",
      "     bbcccccccbb",
      "     a bbbbbbb a",
      "a   a     a     ",
      "da  a     a     ",
      "efaa      a     ",
      "eeddaaa   a   aa",
      "geeefddaaaaaaadd",
      " ggeeeefddfddfee",
      "   gggeeeeeeeeeg",
      "      gggeeeggg ",
      "                ",
      "                ",
      "                ",
      "                "
    ],
    [
      "hhh@            ",
      "hhhi@           ",
      "jhkhhf@lmnonml@f",
      "jphhhhh@d@@@d@hh",
      "qjjhhhhhhhihhhhh",
      "qjjjjhhhhhkhhhhh",
      " qjjjjjhhhphhhjj",
      "  qqjjjjjjqjjjjj",
      "    qqqjjjqjjjqq",
      "       qqqqqqq  ",
      "          r     ",
      "                ",
      "                ",
      "                ",
      "                ",
      "                "
    ],
    [
      "   @            ",
      "   s@           ",
      "  s  @@t  u  t@@",
      "       @@@@@@@  ",
      "          s     ",
      "          s     ",
      "                ",
      "                ",
      "                ",
      "          ~     ",
      "                ",
      "                ",
      "                ",
      "                ",
      "                ",
      "                "
    ],
    [
      "   whhee     eeh",
      "   jjjhheeeeehhj",
      "    xjjjhhhhhjjj",
      "     xxjjjjjjjxx",
      "       xxxjxxx  ",
      "                ",
      "                ",
      "                ",
      "                ",
      "          ~     ",
      "                ",
      "                ",
      "                ",
      "                ",
      "                ",
      "                "
    ],
    [
      "    y   jjjjj   ",
      "                ",
      "                ",
      "                ",
      "                ",
      "                ",
      "                ",
      "                ",
      "                ",
      "          ~     ",
      "                ",
      "                ",
      "                ",
      "                ",
      "                ",
      "                "
    ],
    [
      "    A           ",
      "                ",
      "                ",
      "                ",
      "                ",
      "                ",
      "                ",
      "                ",
      "                ",
      "          ~     ",
      "                ",
      "                ",
      "                ",
      "                ",
      "                ",
      "                "
    ]
  ]
}