{
  "name": "multi_alienresearch_6_base3",
  "refpalette": "deceasedcraft:multi_alienresearch_6/multi_alienresearch_6_base3_palette",
  "xsize": 16,
  "zsize": 16,
  "slices": [
    [
      "a     b         ",
      "c               ",
      " d              ",
      " ed             ",
      "e  fg           ",
      "h    fg       fg",
      "ih     fjjjjjg  ",
      "iihh      e     ",
      "kkiihhh   e     ",
      "kkkkiiihhhihhhhh",
      "kkkkkkiiiiiiiiih",
      "kkkkkkkkkkkkkkih",
      "kkkkkkkkkkkkkkih",
      "llkkkkkkkkkkkkih",
      "mmllllkkkkkkkkil",
      "nnmmmmlllllllllm"
    ],
    [
      "      o         ",
      "                ",
      "                ",
      "                ",
      "                ",
      "                ",
      "                ",
      "pp              ",
      "  pp            ",
      "   qpp          ",
      "      rpppppppr ",
      "          stutp ",
      "            w p ",
      "m             p ",
      "nmmm x    l   p ",
      "nnnnmmmiyiiiAimm"
    ],
    [
      "      B         ",
      "                ",
      "                ",
      "                ",
      "                ",
      "                ",
      "                ",
      "pp              ",
      "  pp            ",
      "    pp          ",
      "      rpppppppr ",
      "          C  Dp ",
      "m             p ",
      "nmm           p ",
      "nnnmmmm   l   mm",
      "nnnnnEFiIiiiJiFE"
    ],
    [
      "      B         ",
      "                ",
      "                ",
      "                ",
      "                ",
      "                ",
      "                ",
      "pp              ",
      "  pp            ",
      "    pp          ",
      "      rpppppppr ",
      "              p ",
      "mmm           p ",
      "nnnmm     l   l ",
      "nnnnnmmiiiiiiimm",
      "nnnnnEFihiiihiFE"
    ],
    [
      "      B         ",
      "                ",
      "                ",
      "                ",
      "                ",
      "                ",
      "                ",
      "pp              ",
      "  pp            ",
      "    pp          ",
      "      rpppppppr ",
      "mm            p ",
      "nnmmm     l   l ",
      "nnnnnmmmmiiimmmm",
      "nnnnnEEEEEEEEEEE",
      "nnnnnE!KKKKKKK E"
    ],
    [
      "      B         ",
      "                ",
      "                ",
      "                ",
      "                ",
      "                ",
      "                ",
      "LL              ",
      "  LL            ",
      "    LL          ",
      "mm    pLLLLLLLp ",
      "nnmm      l   l ",
      "nnnnmmmmmiiimmmm",
      "nnnnnnnnnnnnnnnn",
      "nnnnnEEEEEEEEEEE",
      "nnnnnE         E"
    ]
  ]
}