{
  "name": "multi_alienresearch_6_top",
  "refpalette": "deceasedcraft:multi_alienresearch_6/multi_alienresearch_6_top_palette",
  "xsize": 16,
  "zsize": 16,
  "slices": [
    [
      "                ",
      "                ",
      "ab              ",
      "ab              ",
      "abcccdc         ",
      "a               ",
      "ab              ",
      "ab              ",
      "ab              ",
      "ab              ",
      "ab              ",
      "abcccdc         ",
      "ab              ",
      "ab              ",
      "ab              ",
      "ab              "
    ],
    [
      "      d         ",
      "      d         ",
      "  ebb d         ",
      " ffab d         ",
      "  eabcccdg      ",
      "  eab d         ",
      " fea  d         ",
      " feab d         ",
      " feab d         ",
      "  eab d         ",
      " feab d         ",
      " ffabcccd       ",
      " f ab d         ",
      " feab d         ",
      " feab d         ",
      "  eab d         "
    ],
    [
      "                ",
      "                ",
      "     ef         ",
      "     eab        ",
      "    ffabcccd    ",
      "    feab        ",
      "     fab        ",
      "    feab        ",
      "     eab        ",
      "    feab        ",
      "    f ab        ",
      "    ffabcccd    ",
      "    feab        ",
      "    feab        ",
      "     eab        ",
      "    feab        "
    ],
    [
      "             d  ",
      "             d  ",
      "             d  ",
      "        ebb  d  ",
      "        fabcccd ",
      "         hi  d  ",
      "        eab  d  ",
      "       feab  d  ",
      "       fiii  d  ",
      "       feab  d  ",
      "       feab  d  ",
      "       fiiicccd ",
      "       feab  d  ",
      "        fab  d  ",
      "       fihi  d  ",
      "       feab  d  "
    ],
    [
      "          feab  ",
      "                ",
      "                ",
      "          febb  ",
      "          feabcc",
      "           iab  ",
      "           eab  ",
      "          fea   ",
      "           iab  ",
      "          feab  ",
      "          feab  ",
      "           iabcc",
      "          feab  ",
      "          feab  ",
      "           iab  ",
      "          feab  "
    ],
    [
      "             fea",
      "              fa",
      "              eh",
      "              ea",
      "             fea",
      "             fei",
      "             fea",
      "              ea",
      "             fei",
      "             ffa",
      "             fea",
      "             ffi",
      "             fea",
      "             fea",
      "              ei",
      "             fea"
    ]
  ]
}