{
  "name": "multi_hospital_3_floor1",
  "refpalette": "deceasedcraft:multi_hospital_3/multi_hospital_3_floor1_palette",
  "xsize": 16,
  "zsize": 16,
  "slices": [
    [
      "aaaaaaaaaaaaaab ",
      "aaaaaaaaaaaaaab ",
      "cdeeeeeeeeeeeeb ",
      "fbbbbbbbbbbbbbb ",
      "fbg             ",
      "fbg             ",
      "fbg             ",
      "fbg             ",
      "fbg             ",
      "fbg             ",
      "fbg             ",
      "fbg             ",
      "fbg             ",
      "bbg             ",
      "bbg             ",
      "                "
    ],
    [
      " h    i    jke  ",
      " hlm nilm   oep ",
      "edeeeeeeeeeeeep ",
      " qp pp pp pp p  ",
      " q              ",
      "rq              ",
      "sq              ",
      " q              ",
      " q              ",
      "rq              ",
      "sq              ",
      " q              ",
      " q              ",
      "qq              ",
      "                ",
      "                "
    ],
    [
      " t    u      w  ",
      " t   !u      ep ",
      "edeweeweeweewep ",
      " qp pp pp pp p  ",
      " q              ",
      " q              ",
      " q              ",
      " q              ",
      " q              ",
      " q              ",
      " q              ",
      " q              ",
      " q              ",
      "qq              ",
      "                ",
      "                "
    ],
    [
      " t    u      w  ",
      " t    u      ep ",
      "edeweeweeweewep ",
      " qp pp pp pp p  ",
      " q              ",
      " q              ",
      " q              ",
      " q              ",
      " q              ",
      " q              ",
      " q              ",
      " q              ",
      " q              ",
      "qq              ",
      "                ",
      "                "
    ],
    [
      " t    u      w  ",
      " t    u      ep ",
      "edeweeweeweewep ",
      " qp pp pp pp p  ",
      " q              ",
      " q              ",
      " q              ",
      " q              ",
      " q              ",
      " q              ",
      " q              ",
      " q              ",
      " q              ",
      "qq              ",
      "                ",
      "                "
    ],
    [
      " exxxexxxexxxe  ",
      " exxxexxxexxxep ",
      "edeeeeeeeeeeeep ",
      " qp pp pp pp p  ",
      " q              ",
      " q              ",
      " q              ",
      " q              ",
      " q              ",
      " q              ",
      " q              ",
      " q              ",
      " q              ",
      "qq              ",
      "                ",
      "                "
    ]
  ]
}