{
  "name": "multi_hospital_3_base4",
  "refpalette": "deceasedcraft:multi_hospital_3/multi_hospital_3_base4_palette",
  "xsize": 16,
  "zsize": 16,
  "slices": [
    [
      "    a           ",
      "    a           ",
      "    a           ",
      "    a           ",
      "    a           ",
      "  bbbbbbbbb  bbb",
      "  cd       ef gh",
      " iij      kkkkgh",
      "aag  kl       gh",
      " mn   op      gh",
      " qr   os      gh",
      "tug  wxggggggggh",
      "ggbyyyyyyyyyyyyh",
      "ggbhhhhhhhhhhhhh",
      "ggghhhhhhhhhhhhh",
      "vvvvvvvvvvvvvvvv"
    ],
    [
      "    a           ",
      "    a           ",
      "    a           ",
      "    a          A",
      "    a           ",
      "  bbbbbbbbb  bbb",
      "  BC      DEFDgh",
      " iij          gh",
      "aag   kl      gh",
      " IJ    op     gh",
      " KJ    os     gh",
      " ug   wxgggggggh",
      "Lgbyyyyyyyyyyyyh",
      "Mgbhhhhhhhhhhhhh",
      "ggghhhhhhhhhhhhh",
      "vvvvvvvvvvvvvvvv"
    ],
    [
      "    a          N",
      "    a          N",
      "    a          N",
      "    a         OP",
      "    a          N",
      "  bbbbbbbbbQQbbb",
      "  Bj       RR gh",
      " iij          gh",
      "aag    kl    Ogh",
      " ug     op    gh",
      "Sug     os    gh",
      "Tug    wxggggggh",
      "Ugbyyyyyyyyyyyyh",
      " gbhhhhhhhhhhhhh",
      "ggghhhhhhhhhhhhh",
      "vvvvvvvvvvvvvvvv"
    ],
    [
      "   Vgggggggggggg",
      "   Vgggggggggggg",
      "   Vgggggggggggg",
      "   Vgggggggggggg",
      "   Vgggggggggggg",
      "  bbbbbbbbbbbbbb",
      "  BW         NNN",
      " iiW         Ngh",
      "aagW    kl   Ngh",
      " ubW     op  Ngh",
      " ubW     os  Xgh",
      "YubW    wxgggNgh",
      "ggbyyyyyyyyyyyyh",
      "ggbhhhhhhhhhhhhh",
      "ggghhhhhhhhhhhhh",
      "vvvvvvvvvvvvvvvv"
    ],
    [
      "  Z0122222111121",
      "  Z0122222111121",
      "  Z0111111111121",
      "  Z0111111111121",
      "  Z0111111111111",
      "  bbbbbbbbbxxbbb",
      "  ByW      xxxyh",
      " iiyW      xxxyh",
      "aagyW    klxxxyh",
      " ubyW     oxxxyh",
      " ubyW     oxxxyh",
      "3ubyW    wxxxxyh",
      "4gbyyyyyyyyyyyyh",
      "Mgbhhhhhhhhhhhhh",
      "ggghhhhhhhhhhhhh",
      "vvvvvvvvvvvvvvvv"
    ],
    [
      "   @ 56765    8i",
      "   @ 99999   #$i",
      "   @   % %    ^i",
      "   @ %      & ^i",
      "  Z0i*****()+(ii",
      "  bbbbbbbbb--bbb",
      "  BgyW     [  yh",
      " iigyW     [  yh",
      "aaggyW    k[  yh",
      " ubgyW        yh",
      "SubgyW        yh",
      "TubgyW    wwwwyh",
      "Ugbgyyyyyyyyyyyh",
      " gbhhhhhhhhhhhhh",
      "ggghhhhhhhhhhhhh",
      "vvvvvvvvvvvvvvvv"
    ]
  ]
}