{
  "name": "multi_hospital_3_ground",
  "refpalette": "deceasedcraft:multi_hospital_3/multi_hospital_3_ground_palette",
  "xsize": 16,
  "zsize": 16,
  "slices": [
    [
      "aaaabbbbaaaaaaaa",
      "aaaabbbbaaaaaaaa",
      "aaaaaaaaaaaaaaaa",
      "aaaaaaaaaaaaaaaa",
      "aaaaaaaaaaaaaaaa",
      "bbbccccccaaaaaaa",
      "dddbbefgaaaaaaaa",
      "dddbb hgaaaaaaaa",
      "dddbb hgaaaa i j",
      "dddbb hgaaaab   ",
      "dddbb hgaaaab   ",
      "dddbb kgaaaab   ",
      "dddbbbbbcbbbcbbb",
      "dddbbbbbbbbbbbbb",
      "llllllllllllllll",
      "llllllllllllllll"
    ],
    [
      "mn op  q        ",
      "rn os  o     tuw",
      "xxyxxxxx        ",
      "                ",
      "AB  CCCC   DEFFI",
      "JJJccccccK  L  M",
      "NNN O       P  Q",
      "    O h    RSTTU",
      "    O h    Vcccc",
      "    O h     W   ",
      "    Okh     X   ",
      "    OkYe    Z   ",
      "    OOOOc000c111",
      "        h h h h ",
      "2234432222222222",
      "   44           "
    ],
    [
      "5  o   6        ",
      "7  o 88o        ",
      "xx9xxxxx        ",
      "                ",
      "           #$%^&",
      "222cccccc*      ",
      "NNN O           ",
      "    O h    ()+)+",
      "    O h     cccc",
      "    Okh     W   ",
      "    O-h     [   ",
      "    Oe      ]   ",
      "    OOOOcOOOc111",
      "        h h h h ",
      "                ",
      "                "
    ],
    [
      "   o   {}       ",
      "   o   o        ",
      "xx0xxxxx        ",
      "                ",
      "     |;    #::::",
      "   cccccc'      ",
      "NNN O           ",
      "    O h    ())+)",
      "    Okh     cccc",
      "    O-h     W   ",
      "    O h     W   ",
      "    O      <W   ",
      "    OOOOccccc111",
      "        h h h h ",
      "                ",
      "                "
    ],
    [
      "   o   o        ",
      "   o>  o        ",
      "xxxxxxxx        ",
      "   ,   ,  .  .. ",
      "           ?////",
      "```cccccc  \u0370    ",
      "NNN O      \u0370    ",
      "    Okh    \u0371\u0372\u0373 \u0374",
      "    O-h     cccc",
      "    O h    <c   ",
      "    O h     c   ",
      "    O    <<!c   ",
      "    OOOOccccc111",
      "        h h h h ",
      "                ",
      "                "
    ],
    [
      "\u0375\u0375\u0375\u0375\u0376\u0375\u0375\u0375\u0375\u0375\u0375\u0375\u0375\u0375\u0375\u0375",
      "\u0375\u0375\u0375\u0375\u0377\u0375\u0375\u0375\u0375\u0375\u0375\u0375\u0375\u0375\u0375\u0375",
      "\u0375\u0375\u0375\u0375\u0375\u0375\u0375\u0375\u0375\u0375\u0375\u0375\u0375\u0375\u0375\u0375",
      "\u0375\u0375\u0375\u0375\u0375\u0375\u0375\u0375\u0375\u0375\u037a\u037a\u0375\u037a\u037a\u0375",
      "\u0375\u0375\u0375\u0375\u0375\u0375\u0375\u0375\u0375\u0375\u0375\u0375\u0375\u0375\u0375\u0375",
      "\u0375\u0375\u0375cccccc\u0375\u0375\u0375\u0375\u0375\u0375\u0375",
      "\u037b\u037b\u037b Okk \u037c\u0375\u0375\u0375\u0375\u0375\u0375\u0375",
      "    O-h \u037c\u0375\u0375\u0375\u0375\u0375\u0375\u0375",
      "    O h \u037c\u0375\u0375\u0375cccc",
      "    O h \u037c\u0375\u0375\u0375c   ",
      "    O h \u037c\u0375\u0375\u0375c   ",
      "2   O   \u037c\u0375\u0375\u0375c   ",
      "    OOOOccccc111",
      "        h h h h ",
      "                ",
      "                "
    ]
  ]
}