{
  "name": "multi_hospital_3_top",
  "refpalette": "deceasedcraft:multi_hospital_3/multi_hospital_3_top_palette",
  "xsize": 16,
  "zsize": 16,
  "slices": [
    [
      "aabbbbbbaaaaaaaa",
      "aabbbbbbaaaaaaaa",
      "aabaaaaaaaaaaaaa",
      "aabaaaaaaaaaaaaa",
      "aabaaaaaaaaaaaaa",
      "aabccccccaaaaaaa",
      "dddefghiaaaaaaaa",
      "    j kiaaaaaaaa",
      "    f kiaaaa l b",
      "    j kiaaaabm m",
      "    f kiaaaabmmm",
      "n   j oiaaaabmmm",
      "    fjfjcccccbbb",
      "        k k k k ",
      "                ",
      "                "
    ],
    [
      "  p qr st   uw x",
      "  uuuuuut   uuuu",
      "  y         uA B",
      "  C         u D ",
      "  y EEEE    u  F",
      "  uccccccI  J   ",
      "dddeK       uLLM",
      "    K k   N uuuu",
      "    K k    Occcc",
      "    K k     PQRQ",
      "    Kok     S   ",
      "T   KoUg    V   ",
      "    KKKKcWWWcXXX",
      "        k k k k ",
      "                ",
      "                "
    ],
    [
      "  Y Z 01    K2  ",
      "  dddddd    dddd",
      "  y         K3  ",
      "  4         K5  ",
      "  y         d   ",
      "  dcccccc6  7   ",
      "dddeK       d 8 ",
      "    K k     dddd",
      "    K k     cccc",
      "    Kok     PQQQ",
      "    K9k     #   ",
      "    Kg      $   ",
      "    KKKKcKKKcXXX",
      "        k k k k ",
      "                ",
      "                "
    ],
    [
      "  % ^ &1    K*  ",
      "  dddddd    dddd",
      "  y         K(  ",
      "  y         K)  ",
      "  y  +-     d   ",
      "  dcccccc[ ]%   ",
      "j{deK       d } ",
      "    K k     dddd",
      "    Kok     cccc",
      "    K9k     PQQQ",
      "    K k     P | ",
      "    K       P   ",
      "    KKKKcccccXXX",
      "        k k k k ",
      "                ",
      "                "
    ],
    [
      "  ;:';:'    d   ",
      "  dddddd    dddd",
      "  d         d   ",
      "  d         d   ",
      "  d  <>     d   ",
      "  dcccccc   d   ",
      "dddeK       d   ",
      "    Kok     dddd",
      "    K9k     cccc",
      "    K k     ciii",
      "    K k     ciii",
      "    K       ciii",
      "    KKKKcccccXXX",
      "        k k k k ",
      "                ",
      "                "
    ],
    [
      ",,e.???1    d   ",
      ",,dddddd    dddd",
      ",,d         d   ",
      ",,d         d   ",
      ",,d         d   ",
      ",,dcccccc   d   ",
      "dddeKoo     d   ",
      "    K9k     dddd",
      "    K k     cccc",
      "    K k     c   ",
      "    K k     c / ",
      "    K       c   ",
      "    KKKKcccccXXX",
      "        k k k k ",
      "                ",
      "                "
    ],
    [
      "````\u0370\u0370\u0370`\u0371\u0372\u0372\u0372\u0372\u0372\u0372\u0372",
      "````````\u0371\u0372\u0372\u0372\u0372\u0372\u0372\u0372",
      "````````\u0371\u0372\u0372\u0372\u0372\u0372\u0372\u0372",
      "````````\u0371\u0372\u0372\u0372\u0372\u0372\u0372\u0372",
      "````````\u0371\u0372\u0372\u0372\u0372\u0372\u0372\u0372",
      "```cccccc\u0372\u0372\u0372\u0372\u0372\u0372\u0372",
      "dddeKghi\u0372\u0372\u0372\u0372\u0372\u0372\u0372\u0372",
      "    K k\u0373\u0372\u0372\u0372\u0372\u0372\u0372\u0372\u0372",
      "    K k\u0373\u0372\u0372\u0372\u0372 l b",
      "    K k\u0373\u0372\u0372\u0372\u0372b   ",
      "    K k\u0373\u0372\u0372\u0372\u0372b / ",
      "    K  \u0373\u0372\u0372\u0372\u0372b   ",
      "    KKKKcccccbbb",
      "        k k k k ",
      "                ",
      "                "
    ],
    [
      "   \u0374\u0375!\u0375\u0376X      \u0377",
      "    \u037a\u037a\u037a X       ",
      "        \u037b      \u0377",
      "        \u037c       ",
      "        X      \u0377",
      "   cccccc       ",
      "    f          \u0377",
      "    j k\u037d        ",
      "    f k\u037d   Occcc",
      "    j k\u037d    P   ",
      "    f k\u037d    \u037e / ",
      "    j  \u037d    \u037f   ",
      "    fjfjcWWWcXXX",
      "        k k k k ",
      "                ",
      "                "
    ],
    [
      "    \u0384 \u0385 X       ",
      "        X       ",
      "        \u0386       ",
      "        \u0387       ",
      "        X       ",
      "   cccccc\u0388      ",
      "    K           ",
      "    K k         ",
      "    K k     cccc",
      "    K k     P   ",
      "    K k     \u0389 / ",
      "    K       \u038a   ",
      "    KKKKcKKKcXXX",
      "        k k k k ",
      "                ",
      "                "
    ],
    [
      "        X       ",
      "        X       ",
      "        \u038c       ",
      "        \u038c       ",
      "        X       ",
      "   cccccc       ",
      "    K           ",
      "    K k         ",
      "    K k     cccc",
      "    K k     P   ",
      "    K k     P / ",
      "    K       P   ",
      "    KKKKcccccXXX",
      "        k k k k ",
      "                ",
      "                "
    ],
    [
      "        X       ",
      "        X       ",
      "        X       ",
      "        X       ",
      "        X       ",
      "   cccccc       ",
      "    K           ",
      "    K k         ",
      "    K k     cccc",
      "    K k     c   ",
      "    K k     c / ",
      "    K       c   ",
      "    KKKKcccccccc",
      "        k k k k ",
      "                ",
      "                "
    ],
    [
      "      `\u0370\u0371\u0372\u0372\u0372\u0372\u0372\u0372\u0372",
      "      `\u0370\u0371\u0372\u0372\u0372\u0372\u0372\u0372\u0372",
      "      `\u0370\u0371\u0372\u0372\u0372\u0372\u0372\u0372\u0372",
      "      `\u0370\u0371\u0372\u0372\u0372\u0372\u0372\u0372\u0372",
      "      `\u0370\u0371\u0372\u0372\u0372\u0372\u0372\u0372\u0372",
      "   ccccc\u0371\u0372\u0372\u0372\u0372\u0372\u0372\u0372",
      "   `\u0370iii\u0371\u0372\u0372\u0372\u0372\u0372\u0372\u0372",
      "   `\u0370iii\u0371\u0372\u0372\u0372\u0372\u0372\u0372\u0372",
      "   `\u0370iii\u0371\u0372\u0372\u0372cccc",
      "   `\u0370iii\u0371\u0372\u0372\u0372c\u038e\u038f\u038e",
      "   `\u0370iii\u0371\u0372\u0372\u0372c\u038e\u0390\u038e",
      "   `\u0370iii\u0371\u0372\u0372\u0372c\u038e\u0391\u038e",
      "   `\u0370\u0370\u0370\u0370cccccccc",
      "   `\u0370\u0370\u0370\u0370\u0370\u0370\u0370\u0370\u0370\u0370\u0370\u0370",
      "   `````````````",
      "                "
    ],
    [
      "      \u0392 \u0392\u0392\u0392\u0392\u0392\u0392\u0392\u0392",
      "      \u0392 \u0392\u0392\u0392\u0392\u0392\u0392\u0392\u0392",
      "      \u0392 \u0392\u0392\u0392\u0392\u0392\u0392\u0392\u0392",
      "      \u0392 \u0392\u0392\u0392\u0392\u0392\u0392\u0392\u0392",
      "      \u0392 \u0392\u0392\u0392\u0392\u0392\u0392\u0392\u0392",
      "   ccccc\u0392\u0392\u0392\u0392\u0392\u0392\u0392\u0392",
      "   \u0392 \u0392\u0392\u0392\u0392\u0392\u0392\u0392\u0392\u0392\u0392\u0392",
      "   \u0392 \u0392\u0392\u0392\u0392\u0392\u0392\u0392\u0392\u0392\u0392\u0392",
      "   \u0392 \u0392\u0392\u0392\u0392\u0392\u0392\u0392\u0392\u0392\u0392\u0392",
      "   \u0392 \u0392\u0392\u0392\u0392\u0392\u0392\u0392\u0392\u0392\u0392\u0392",
      "   \u0392 \u0392\u0392\u0392\u0392\u0392\u0392\u0392\u0392\u0392\u0393\u0392",
      "   \u0392 \u0392\u0392\u0392\u0392\u0392\u0392\u0392\u0392\u0392\u0392\u0392",
      "   \u0392 \u0392\u0392\u0392\u0392\u0392\u0392\u0392\u0392\u0392\u0392\u0392",
      "   \u0392            ",
      "   \u0392\u0392\u0392\u0392\u0392\u0392\u0392\u0392\u0392\u0392\u0392\u0392\u0392",
      "                "
    ],
    [
      "                ",
      "                ",
      "                ",
      "                ",
      "                ",
      "   ccccc        ",
      "                ",
      "                ",
      "                ",
      "                ",
      "                ",
      "                ",
      "                ",
      "                ",
      "                ",
      "                "
    ]
  ]
}