{
  "name": "multi_hospital_3_base2",
  "refpalette": "deceasedcraft:multi_hospital_3/multi_hospital_3_base2_palette",
  "xsize": 16,
  "zsize": 16,
  "slices": [
    [
      "   a           b",
      "   a           b",
      "   a           c",
      "   @           c",
      "  decccccccccccc",
      "ffgggggggggggggg",
      "ffhiii jjjjjjjjk",
      "ccccccljjjjjjjjk",
      "mmj jjnjjjjjgggg",
      "oogjjjjjjjjjijjj",
      "oogjjjjjjjjjijjj",
      "oogjjjjjjjjjijjj",
      "jjgjjjjjjjjjgiii",
      "jjgkkkkkkkkkpiii",
      "jjjkkkkkkkkkjjjj",
      "vvvvvvvvvvvvvvvv"
    ],
    [
      "   a           q",
      "   a           q",
      "   a           c",
      "   @           c",
      "  decccccccccccc",
      "rrgggggggggggggg",
      "  st ucjjjjjjjjk",
      "cccccccjjjjjjjjk",
      "jjjnjj jjjjjgggg",
      "gggjjjjjjjjjg   ",
      "gggjjjjjjjjjg   ",
      "gggjjjjjjjjjg   ",
      "gggjjjjjjjjjg@@@",
      "gggkkkkkkkkkpwww",
      "jjjkkkkkkkkkjjjj",
      "vvvvvvvvvvvvvvvv"
    ],
    [
      "   @           c",
      "   @           c",
      "   @           c",
      "   @           c",
      "  decccccccccccc",
      " ugggggggggggggg",
      "  x  ycjjjjjjjjg",
      "cccccccjjjjjjjjg",
      " AB jjnjjjjjgggg",
      " nnjjjjjjjjjg   ",
      "jjjjjjjjjjjjg   ",
      "jjjjjjjjjjjjg   ",
      "jjjjjjjjjjjjg@@@",
      "kkkkkkkkkkkkpwww",
      "kkkkkkkkkkkkjjjj",
      "vvvvvvvvvvvvvvvv"
    ],
    [
      "  decccccccccccc",
      "  decccccccccccc",
      "  decccccccccccc",
      "  decccccccccccc",
      "  decccccccccccc",
      "  gggggggggggggg",
      "  CD ycjjjjjgiii",
      "cccccccjjjjjgiii",
      "nnnnjj jjjjjgg B",
      "nnnjjjjjjjjjg   ",
      "jjjjjjjjjjjjg   ",
      "jjjjjjjjjjjjg   ",
      "jjjjjjjjjjjjg@@@",
      "kkkkkkkkkkkkpwww",
      "kkkkkkkkkkkkjjjj",
      "vvvvvvvvvvvvvvvv"
    ],
    [
      "EEEjgggggggggggg",
      "EEEjgggggggggggg",
      "EEEjgggggggggggg",
      "EEEjgggggggggggg",
      "EEEjgggggggggggg",
      "EEgggggggggggggg",
      "EEEccycjjjjjgiii",
      "EEnnnccjjjjjgiii",
      "jjj jjFjjjjjgggg",
      "jjjnjjjjjjjjg   ",
      "jjjnjjjjjjjjg   ",
      "jjjnnnnnnjjjg   ",
      "jjjjjjjjjjjjg@@@",
      "kkkkkkkkkkkkpwww",
      "kkkkkkkkkkkkjjjj",
      "vvvvvvvvvvvvvvvv"
    ],
    [
      "iiigggggiiiiiiii",
      "iiiiiiiiiiiiiiii",
      "iiiiiiiiiiiiiiii",
      "iiiiiiiiiiiiiiii",
      "iiiiiiiiiiiiiiii",
      "iiiggggggggggggg",
      "kjnccy jjjjjgiiI",
      "kjnJ cKjjjjjgiiI",
      "kjjL  Mjjjjjgggg",
      "kjjNjjjjjjjjg   ",
      "kjj jjjjjjjjg   ",
      "kjj      jjjg   ",
      "kjjjjjjjjjjjg@@@",
      "kkkkkkkkkkkkpwww",
      "kkkkkkkkkkkkjjjj",
      "vvvvvvvvvvvvvvvv"
    ]
  ]
}