{
  "name": "multi_hospital_3_base5",
  "refpalette": "deceasedcraft:multi_hospital_3/multi_hospital_3_base5_palette",
  "xsize": 16,
  "zsize": 16,
  "slices": [
    [
      "vvvvvvvvvvvvvvvv",
      "vvvvvvvvvvvvvvvv",
      "vvvvvvvvvvvvvvvv",
      "vvvvvvvvvvvvvvvv",
      "vvvvvvvvvvvvvvvv",
      "vvvvvvvvvvvvvvvv",
      "vvvvvvvvvvvvvvvv",
      "vvvvvvvvvvvvvvvv",
      "vvvvvvvvvvvvvvvv",
      "vvvvvvvvvvvvvvvv",
      "vvvvvvvvvvvvvvvv",
      "vvvvvvvvvvvvvvvv",
      "vvvvvvvvvvvvvvvv",
      "vvvvvvvvvvvvvvvv",
      "vvvvvvvvvvvvvvvv",
      "vvvvvvvvvvvvvvvv"
    ],
    [
      "aaaaaaaaaaaaaaaa",
      "aaaaaaaaaaaaaaaa",
      "aaaaaaaaaaaaaaaa",
      "aaaaaaaaaaaaaaaa",
      "aaaaaaaaaaaaaaaa",
      "aaaaaaaaaaaaaaaa",
      "aaaaaaaaaaaaaaaa",
      "aaaaaaaaaaaaaaaa",
      "aaaaaaaaaaaaaaaa",
      "aaaaaaaaaaaaaaaa",
      "aaaaaaaaaaaaaaaa",
      "aaaaaaaaaaaaaaaa",
      "aaaaaaaaaaaaaaaa",
      "aaaaaaaaaaaaaaaa",
      "aaaaaaaaaaaaaaaa",
      "vvvvvvvvvvvvvvvv"
    ],
    [
      "aaaaaaaaaaaaaaaa",
      "aaaaaaaaaaaaaaaa",
      "aaaaaaaaaaaaaaaa",
      "aaaaaaaaaaaaaaaa",
      "aaaaaaaaaaaaaaaa",
      "aaaaaaaaaaaaaaaa",
      "aaaaaaaaaaaaaaaa",
      "aaaaaaaaaaaaaaaa",
      "aaaaaaaaaaaaaaaa",
      "aaaaaaaaaaaaaaaa",
      "aaaaaaaaaaaaaaaa",
      "aaaaaaaaaaaaaaaa",
      "aaaaaaaaaaaaaaaa",
      "aaaaaaaaaaaaaaaa",
      "aaaaaaaaaaaaaaaa",
      "vvvvvvvvvvvvvvvv"
    ],
    [
      "bbbccccccccccccc",
      "bbbccccccccccccc",
      "bbbccccccccccccc",
      "bbbccccccccccccc",
      "bbbccccccccccccc",
      "bbbddddddddddddd",
      "bbbeeeeeeeeeeeca",
      "bbbeeeeeeeeeeeca",
      "ccceeeeeeeeeeeca",
      "ddceeeeeeeeeeeca",
      "ddceeeeeeeeeeeca",
      "ddccccccccccccca",
      "dddffffffffffffa",
      "dddaaaaaaaaaaaaa",
      "cccaaaaaaaaaaaaa",
      "vvvvvvvvvvvvvvvv"
    ],
    [
      "g  hciiiiiiiiiii",
      "   hciiiiiiiiiii",
      "   hciiiiiiiiiii",
      "   hciiiiiiiiiii",
      "   hciiiiiiiiiii",
      "  dddddddddeeddd",
      "  jk    lmnnonca",
      "pppq    r     ca",
      "sscttu        ca",
      "wweeex       mca",
      "wweeey     m !ca",
      "wwceecccccccccca",
      "Acdffffffffffffa",
      "Acdaaaaaaaaaaaaa",
      "cccaaaaaaaaaaaaa",
      "vvvvvvvvvvvvvvvv"
    ],
    [
      "B   sCC CC D CCC",
      "    sCCC CC CCC ",
      "    sCCCC C CC C",
      "    s CCCC E CCC",
      "    sCC C C FCC ",
      "  dddddddddttddd",
      "   I     lJJJJca",
      " ppq     rJJJJca",
      "ssc KL        ca",
      " MN  Ox       ca",
      "PQR  Oy   STUVca",
      "Wwc Xeccccccccca",
      "Ycdffffffffffffa",
      " cdaaaaaaaaaaaaa",
      "cccaaaaaaaaaaaaa",
      "vvvvvvvvvvvvvvvv"
    ]
  ]
}