{
  "name": "multi_hospital_3_base3",
  "refpalette": "deceasedcraft:multi_hospital_3/multi_hospital_3_base3_palette",
  "xsize": 16,
  "zsize": 16,
  "slices": [
    [
      "   a bc de     f",
      "   a ghgig    jf",
      "   a          kf",
      "   @          ef",
      "  lmfnnonopqrpff",
      "  sssssssss  sss",
      "  tuuwx       wy",
      " ffuuwx       wy",
      "AAuuuwx       wy",
      " Bsuuwx       wy",
      " Bsuuwx       wy",
      "CBsuuwx       wy",
      "uusuuwwwwwwwwwwy",
      "uusyyyyyyyyyyyyy",
      "uuuyyyyyyyyyyyyy",
      "vvvvvvvvvvvvvvvv"
    ],
    [
      "   a          Df",
      "   a           f",
      "   a           f",
      "   @ EEEEE     f",
      "  lmfonnonpFFpff",
      "  sssssssssIIsss",
      "  tuuuwx      wy",
      " ffuuuwx      wy",
      "AAuuuuwx      wy",
      " Bsuuuwx      wy",
      " Bsuuuwx      wy",
      "JBsuuuwx      wy",
      "Kusuuuwwwwwwwwwy",
      "Lusyyyyyyyyyyyyy",
      "uuuyyyyyyyyyyyyy",
      "vvvvvvvvvvvvvvvv"
    ],
    [
      "   a           f",
      "   a           f",
      "   a           f",
      "   @ MNOPQ     f",
      "  lmffffffppppff",
      "  ssssssssssssss",
      "  tLuuuwx     wy",
      " ffLuuuwx     wy",
      "AAuLuuuwx     wy",
      " Bsuuuuwx     wy",
      "RBsuuuuwx     wy",
      "SBsuuuuwx     wy",
      "Tusuuuuwwwwwwwwy",
      " usyyyyyyyyyyyyy",
      "uuuyyyyyyyyyyyyy",
      "vvvvvvvvvvvvvvvv"
    ],
    [
      "   aUVVVVV     f",
      "   aUVVVVV     f",
      "   aUVVVVV     f",
      "   @UVVVVV     f",
      "  lmfWWWWWffffff",
      "  ssssssssssssss",
      "  t uuuuwx    wy",
      " ffXuuuuwx    wy",
      "AAuLuuuuwx YY wy",
      " Bsuuuuuwx    wy",
      " Bsuuuuuwx    wy",
      "ZBsuuuuuwx    wy",
      "uusuuuuuwwwwwwwy",
      "uusyyyyyyyyyyyyy",
      "uuuyyyyyyyyyyyyy",
      "vvvvvvvvvvvvvvvv"
    ],
    [
      "   a  01234    5",
      "   a   3634    5",
      "   a    7 4    f",
      "   @      4    f",
      "  lmffffffffffff",
      "  ssssssssssssss",
      "  t8uuuuuwBBBBwy",
      " ffuuuuuuwBBBBwy",
      "AAu uuuuuwBBBBwy",
      " BsuuuuuuwBBBBwy",
      " BsuuuuuuwBBBBwy",
      "JBsuuuuuuwBBBBwy",
      "Kusuuuuuuwwwwwwy",
      "Lusyyyyyyyyyyyyy",
      "uuuyyyyyyyyyyyyy",
      "vvvvvvvvvvvvvvvv"
    ],
    [
      "   a           9",
      "   a   b#      9",
      "   a           f",
      "   @           f",
      "  lmffffffffffff",
      "  ssssssssssssss",
      "  t uuLuuuuuuuuy",
      " ffuuuLuuuuuuuuy",
      "AAuLuuLuuuuussss",
      " Bsuuuuuuuuussss",
      " Bsuuuuuuuuussss",
      "SBsuuuuuuuuussss",
      "Tusuuuuuuuuussss",
      " usyyyyyyyyy$$$$",
      "uuuyyyyyyyyyuuuu",
      "vvvvvvvvvvvvvvvv"
    ]
  ]
}