{
  "name": "multi_hospital_3_base1",
  "refpalette": "deceasedcraft:multi_hospital_3/multi_hospital_3_base1_palette",
  "xsize": 16,
  "zsize": 16,
  "slices": [
    [
      "   aaaaabbbbbbbb",
      "      ccbbbbbbbb",
      "      ccbbbbbbbb",
      "      debbbbbbbb",
      "       fbbbbbbbb",
      "gggaaaaabbbbaaaa",
      "hijkklbbbbbbabm ",
      "hi   kbbbbbbbbm ",
      "hiiaikbbbbbb n a",
      "hiiaikbbbbbbb   ",
      "hiiaikbbbbbbb   ",
      "hiiaokbbbbbbb   ",
      "hiiaaaaabbbbabbb",
      "hhhhhhhhhhhhpbbb",
      "hhhhhhhhhhhhiiii",
      "vvvvvvvvvvvvvvvv"
    ],
    [
      "   aaaaa    aaaa",
      "             pqq",
      "             p r",
      "             s  ",
      "             p  ",
      "gggaaaaagtugawaa",
      "hi xykA     a   ",
      "hiiiikB     C   ",
      "hiiaikBD   Eaaaa",
      "hiiaikBF    I   ",
      "hiiaokB     J   ",
      "hiiaKkLMA   N   ",
      "hiiaaaaagggga@@@",
      "hhhhhhhhhhhhpooo",
      "hhhhhhhhhhhhiiii",
      "vvvvvvvvvvvvvvvv"
    ],
    [
      "   aaaaa    aaaa",
      "             pOP",
      "             pQ ",
      "             R  ",
      "             p  ",
      "gggaaaaagSTgawaa",
      "hijxyk  U  Ua   ",
      "hiiiikB     V   ",
      "hiiaikB     aaaa",
      "hiiaokB     I   ",
      "hiiaKWB     X   ",
      "hiiaKM      Y   ",
      "hiiaaaaagggga@@@",
      "hhhhhhhhhhhhpooo",
      "hhhhhhhhhhhhiiii",
      "vvvvvvvvvvvvvvvv"
    ],
    [
      "   aaaaa    aaaa",
      "             p  ",
      "             p  ",
      "            Z0  ",
      "             p  ",
      "gggaaaaag11gawaa",
      "hi xyk      a   ",
      "hiiiikB    23   ",
      "hiiaokB     aaaa",
      "hiiaKWB     I   ",
      "hiiaK B     I   ",
      "hiiaK       I   ",
      "hiiaaaaagggga@@@",
      "hhhhhhhhhhhhpooo",
      "hhhhhhhhhhhhiiii",
      "vvvvvvvvvvvvvvvv"
    ],
    [
      "444aaaaa    aaaa",
      "44444b       pkk",
      "44444b       pkk",
      "44444b       pkk",
      "44444b       pkk",
      "555aaaaaggggawaa",
      "hiia6k      a   ",
      "hiiaokB     a   ",
      "hiiaKWB     aaaa",
      "hiiaK B     a   ",
      "hiiaK B     a   ",
      "hiiaK       a   ",
      "hiiaaaaagggga@@@",
      "hhhhhhhhhhhhpooo",
      "hhhhhhhhhhhhiiii",
      "vvvvvvvvvvvvvvvv"
    ],
    [
      "777aaaaa7777aaaa",
      "77777b7777777777",
      "77777b7777777777",
      "77777b7777777777",
      "77777b7777777777",
      "777aaaaa7777aaaa",
      "hiiaok8 7777a777",
      "hiiaKWB 7777a777",
      "hiiaK B 7777aaaa",
      "hiiaK B 7777a   ",
      "hiiaK B 7777a   ",
      "hiiaK   7777a   ",
      "hiiaaaaa7777a@@@",
      "hhhhhhhhhhhhpooo",
      "hhhhhhhhhhhhiiii",
      "vvvvvvvvvvvvvvvv"
    ]
  ]
}