{
  "name": "multi_nuclearpowerplant_45_ground",
  "refpalette": "deceasedcraft:multi_nuclearpowerplant_45/multi_nuclearpowerplant_45_ground_palette",
  "xsize": 16,
  "zsize": 16,
  "slices": [
    [
      "aaaaaaaaaabccccc",
      "aaaaaaaaaabbcccc",
      "aaaaaaaaaaabcczc",
      "aaaaaaaaaaabcccc",
      "aaaaaaaaaaazcccc",
      "aaaaaaaaaaabcccc",
      "aaaaaaaaaaabcccc",
      "aaaaaaaaaaabcccc",
      "aaaaaaaaaaabcccc",
      "aaaaaaaaaaabcccc",
      "aaaaaaaaaaabcccc",
      "aaaaaaaaaaazcccc",
      "aaaaaaaaaaabcccc",
      "aaaaaaaaaaabcccc",
      "aaaaaaaaaabbcccc",
      "aaaaaaaaaabccccz"
    ],
    [
      "zzzzczcczzzd    ",
      "zczzzzzzzczce   ",
      "zzzczczccccce   ",
      "czczcccccccze   ",
      "ccccczccccce    ",
      "cccccccccccce   ",
      "cccccccccccc    ",
      "ccccccccccce    ",
      "cccccccccccee   ",
      "cccccccccccce   ",
      "zcccccczccce    ",
      "ccccczcczccze   ",
      "czczcccccccce   ",
      "zzzczczczccee   ",
      "zczzzzzzzczce   ",
      "zzzzzzzcczzf   g"
    ],
    [
      "g         hi    ",
      "        g       ",
      "                ",
      "                ",
      "     g          ",
      "                ",
      "                ",
      "                ",
      "                ",
      "                ",
      "                ",
      "                ",
      "                ",
      " g              ",
      "          g     ",
      "          hi    "
    ],
    [
      "          hi    ",
      "                ",
      "                ",
      "                ",
      "                ",
      "                ",
      "                ",
      "                ",
      "                ",
      "                ",
      "                ",
      "                ",
      "                ",
      "                ",
      "                ",
      "   j  j   hi    "
    ],
    [
      "          ki    ",
      "                ",
      "                ",
      "                ",
      "                ",
      "                ",
      "                ",
      "                ",
      "                ",
      "                ",
      "                ",
      "                ",
      "                ",
      "                ",
      "                ",
      "   j  j   ki    "
    ],
    [
      "                ",
      "                ",
      "                ",
      "                ",
      "                ",
      "                ",
      "                ",
      "                ",
      "                ",
      "                ",
      "                ",
      "                ",
      "                ",
      "                ",
      "                ",
      "                "
    ]
  ]
}