{
  "name": "multi_nuclearpowerplant_45_base11",
  "refpalette": "deceasedcraft:multi_nuclearpowerplant_45/multi_nuclearpowerplant_45_base11_palette",
  "xsize": 16,
  "zsize": 16,
  "slices": [
    [
      "aaab========cddv",
      "efab========cddv",
      "ghab========cddv",
      "aaab========cddv",
      "geab========cddv",
      "hfab========cddv",
      "aaab========cddv",
      "efab========cddv",
      "ghab========cddv",
      "aaab========cddv",
      "geab========cddv",
      "hfab========cddv",
      "aaab========cddv",
      "efab========cddv",
      "ghab========cddv",
      "aaab========cddv"
    ],
    [
      "aaab========cddv",
      "geab========cddv",
      "hfab========cddv",
      "aaab========cddv",
      "efab========cddv",
      "ghab========cddv",
      "aaab========cddv",
      "ieab========cddv",
      "hfab========cddv",
      "aaab========cddv",
      "efab========cddv",
      "ghab========cddv",
      "aaab========cddv",
      "geab========cddv",
      "hfab========cddv",
      "aaab========cddv"
    ],
    [
      "aaab========cddv",
      "aaab========cddv",
      "aaab========cddv",
      "aaab========cddv",
      "geab========cddv",
      "hfab========cddv",
      "aaab========cddv",
      "aaab========cddv",
      "aaab========cddv",
      "aaab========cddv",
      "aaab========cddv",
      "aaab========cddv",
      "aaab========cddv",
      "aaab========cddv",
      "aaab========cddv",
      "aaab========cddv"
    ],
    [
      "aaab========cddv",
      "aaab========cddv",
      "aaab========cddv",
      "aaab========cddv",
      "aaab========cddv",
      "aaab========cddv",
      "aaab========cddv",
      "aaab========cddv",
      "aaab========cddv",
      "aaab========cddv",
      "aaab========cddv",
      "aaab========cddv",
      "aaab========cddv",
      "aaab========cddv",
      "aaab========cddv",
      "aaab========cddv"
    ],
    [
      "aaab========cddv",
      "aaab========cddv",
      "aaab========cddv",
      "aaab========cddv",
      "aaab========cddv",
      "aaab========cddv",
      "aaab========cddv",
      "aaab========cddv",
      "aaab========cddv",
      "aaab========cddv",
      "aaab========cddv",
      "aaab========cbbv",
      "aaab========cbbv",
      "aaab========cbbv",
      "aaab========cbbv",
      "aaab========cddv"
    ],
    [
      "aaab========cddv",
      "aaab========cddv",
      "aaab========cddv",
      "aaab========cddv",
      "aaab========cddv",
      "aaab========cddv",
      "aaab========cddv",
      "aaab========cddv",
      "aaab========cddv",
      "aaab========cddv",
      "aaab========cbbv",
      "aaab========cbbv",
      "aaab========cbbv",
      "aaab========cjjv",
      "aaab========cbbv",
      "aaab========cddv"
    ]
  ]
}