{
  "name": "multi_nuclearpowerplant_45_base6",
  "refpalette": "deceasedcraft:multi_nuclearpowerplant_45/multi_nuclearpowerplant_45_base6_palette",
  "xsize": 16,
  "zsize": 16,
  "slices": [
    [
      "            abbv",
      "ccc         abbv",
      "d d        eabbv",
      "ccc         abbv",
      "            abbv",
      "       fgggghiiv",
      "       g    hiiv",
      "       g    hiiv",
      "       g    hiiv",
      "       g    hiiv",
      "       fgggghiiv",
      "            abbv",
      "ccc         abbv",
      "djd         abbv",
      "ccc         abbv",
      "        kl  abbv"
    ],
    [
      "            mbbv",
      "ccc         mbbv",
      "d d        embbv",
      "ccc         mbbv",
      "            mbbv",
      "       fggggniiv",
      "       g    niiv",
      "       g    niiv",
      "       g    niiv",
      "       g    niiv",
      "       fggggniiv",
      "            mbbv",
      "ccc         mbbv",
      "djd         mbbv",
      "ccc         mbbv",
      "            mbbv"
    ],
    [
      "            mbbv",
      "ccc         mbbv",
      "d d        embbv",
      "ccc         mbbv",
      "            mbbv",
      "       fggggniiv",
      "       g    niiv",
      "       g    niiv",
      "       g    niiv",
      "       g    niiv",
      "       fggggniiv",
      "            mbbv",
      "ccc         mbbv",
      "djd         mbbv",
      "ccc         mbbv",
      "            mbbv"
    ],
    [
      "            mbbv",
      "ccc         mbbv",
      "d d        embbv",
      "ccc         mbbv",
      "            mbbv",
      "       fggggniiv",
      "       g    niiv",
      "       g    niiv",
      "       g    niiv",
      "       g    niiv",
      "       fggggniiv",
      "            mbbv",
      "ccc         mbbv",
      "djd         mbbv",
      "ccc         mbbv",
      "            mbbv"
    ],
    [
      "            mbbv",
      "ccc         mbbv",
      "d d        embbv",
      "ccc         mbbv",
      "            mbbv",
      "       fggggniiv",
      "       g    niiv",
      "       g    niiv",
      "       g    niiv",
      "       g    niiv",
      "       fggggniiv",
      "            mbbv",
      "ccc         mbbv",
      "djd         mbbv",
      "ccc         mbbv",
      "            mbbv"
    ],
    [
      "            mbbv",
      "ccc         mbbv",
      "d d        embbv",
      "ccc         mbbv",
      "            mbbv",
      "       fggggniiv",
      "       g    niiv",
      "       g    niiv",
      "       g    niiv",
      "       g    niiv",
      "       fggggniiv",
      "            mbbv",
      "ccc         mbbv",
      "djd         mbbv",
      "ccc         mbbv",
      "            mbbv"
    ]
  ]
}