{
  "name": "multi_nuclearpowerplant_45_base1",
  "refpalette": "deceasedcraft:multi_nuclearpowerplant_45/multi_nuclearpowerplant_45_base1_palette",
  "xsize": 16,
  "zsize": 16,
  "slices": [
    [
      "       ab   cddv",
      "e     fab   cddv",
      "ghhaaaa b  icddv",
      "  aj    k   cddv",
      "  a     b   cddv",
      "  hl   maaaanoov",
      "  hp   aqrrrnoov",
      "  s   t    uwoov",
      "  x   y    uwoov",
      "  hA   aBrrrnoov",
      "  hC   maaaanoov",
      "  a        Dcddv",
      "  aj       Ecddv",
      " hhaaaa     cddv",
      "F     fa    cddv",
      "       a    cddv"
    ],
    [
      "       ab   cddv",
      "I     jab   cddv",
      " hhaaaa b  icddv",
      "  aJ   KL   cddv",
      "  a     b   cddv",
      "  h    maaaanoov",
      "  h    aqrrrnoov",
      "  M    N   unoov",
      "  M    N   unoov",
      "  h    aBrrrnoov",
      "  h    maaaanoov",
      "  a        Dcddv",
      "  aJ        cddv",
      " hhaaaa     cddv",
      "O     ja    cddv",
      "       a    cddv"
    ],
    [
      "       ab   cddv",
      "      Jab   cddv",
      "hhhaaaa b  icddv",
      "  a     b   cddv",
      "  a     b   cddv",
      "  h    maaaanoov",
      "  h    aqrrrnoov",
      "  h    a   uwoov",
      "  h    a   uwoov",
      "  h    aBrrrnoov",
      "  h    maaaanoov",
      "  a        Dcddv",
      "  a         cddv",
      "hhhaaaa     cddv",
      "      Ja    cddv",
      "       a    cddv"
    ],
    [
      "       ab  icddv",
      "       ab  icddv",
      "hhhaaaa b  icddv",
      "  a     b   cddv",
      "  a     b   cddv",
      "  a    maaaanoov",
      "  a    aPPPPnoov",
      "  a    aQQQPnoov",
      "  a    aQQQPnoov",
      "  a    aPPPPnoov",
      "  a    maaaanoov",
      "  a        Dcddv",
      "  a         cddv",
      "hhhaaaa     cddv",
      "       a    cddv",
      "       a    cddv"
    ],
    [
      "       aoooocddv",
      "    R  aoooocddv",
      "hhhaaaaSb  icddv",
      "TTaUUUU b   cddv",
      "  aUUUU b   cddv",
      "  aUUUUmaaaanoov",
      "  aUUUUa    noov",
      "  aUUUUa    noov",
      "  aUUUUa    noov",
      "  aUUUUa    noov",
      "  aUUUUmaaaanoov",
      "  aUUUU UUUDcddv",
      "VVaUUUU UUUUcddv",
      "hhhaaaaWUUUUcddv",
      "    X  aUUUUcddv",
      "       aUUUUcddv"
    ],
    [
      "YYYYYYYai Zocoov",
      "YYYYYYYai ZZcoov",
      "ZZZaaaa0iiiZcoov",
      "11Z   i2b  Zcoov",
      "11Z   i2b  Zcoov",
      "11Z   i2ZZZZnoov",
      "11Z   iZ33 4noov",
      "11Z   iZ45 6noov",
      "11Z   iZ74 8noov",
      "11Z   iZ9##$noov",
      "11Z   i2ZZZZnoov",
      "11Z   i2  Z%coov",
      "11Z   i2  ZZcoov",
      "ZZZaaaa0i ZZcoov",
      "YYYYYYYai ZZcoov",
      "YYYYYYYai Zocoov"
    ]
  ]
}