{
  "name": "multi_nuclearpowerplant_45_base9",
  "refpalette": "deceasedcraft:multi_nuclearpowerplant_45/multi_nuclearpowerplant_45_base9_palette",
  "xsize": 16,
  "zsize": 16,
  "slices": [
    [
      "    a       bccv",
      "    a       bccv",
      "    d     efbccv",
      "    a       bggv",
      "    a       bhhv",
      "    a  ijjjjbkkv",
      "    a  j    b  v",
      "    a  j    b  v",
      "    a  j    b  v",
      "    a  j    b  v",
      "    a  ijjjjb  v",
      "    a       b  v",
      "    a       b  v",
      "    fjjjjjjfb  v",
      "          l bggv",
      "            bccv"
    ],
    [
      "    a       bggv",
      "    a       bggv",
      "    d      fbggv",
      "    a       bhhv",
      "    a       bkkv",
      "    a  ijjjjb  v",
      "    a  j    b  v",
      "    a  j    b  v",
      "    a  j    b  v",
      "    a  j    b  v",
      "    a  ijjjjb  v",
      "    a       b  v",
      "    a       b  v",
      "    fjjjjjjfb  v",
      "           mbggv",
      "           mbccv"
    ],
    [
      "    a       bhhv",
      "    a       bhhv",
      "    d     nfbhhv",
      "    a       bkkv",
      "    a       b  v",
      "    a  ijjjjb  v",
      "    a  j    b  v",
      "    a  j    b  v",
      "    a  j    b  v",
      "    a  j    b  v",
      "    a  ijjjjb  v",
      "    a       b  v",
      "    a       b  v",
      "    fjjjjjjfb  v",
      "          lobggv",
      "          pqbccv"
    ],
    [
      "    a       bkkv",
      "    a       b  v",
      "rrrsd      fb  v",
      "    at      b  v",
      "    a       b  v",
      "    a  ijjjjb  v",
      "    a  j    b  v",
      "    a  j    b  v",
      "    a  j    b  v",
      "    a  j    b  v",
      "    a  ijjjjb  v",
      "    a       b  v",
      "    a       b  v",
      "rrrsfjjjjjjfb tv",
      "          l bggv",
      "            bccv"
    ],
    [
      "    f       b  v",
      "    f       b  v",
      "uuuuffffffffb  v",
      "    f!      b  v",
      "    ft      b  v",
      "    f  ijjjjb  v",
      "    f  j    b  v",
      "    f  j    b  v",
      "    f  j    b  v",
      "    f  j    b  v",
      "    f  ijjjjb  v",
      "    f       b  v",
      "    f       b  v",
      "uuuuffffffffbt v",
      "    u       bggv",
      "    u       bccv"
    ],
    [
      "    jwwwwwwwb  v",
      "    jwwwwwwwb  v",
      "   xfwwwwwwwb  v",
      "    jywwwwwwb  v",
      "    jwwwwwwwb  v",
      "    jwwwjjjjb  v",
      "    jwwj    b  v",
      "    jwwj    b  v",
      "    jwwj    b  v",
      "    jwwj    b  v",
      "    jwwwjjjjb  v",
      "    jwwwwwwwb tv",
      "    jywwwwwwb tv",
      "   xfjjjjjjfbt!v",
      "    A       bggv",
      "            bccv"
    ]
  ]
}