{
  "name": "multi_nuclearpowerplant_45_base7",
  "refpalette": "deceasedcraft:multi_nuclearpowerplant_45/multi_nuclearpowerplant_45_base7_palette",
  "xsize": 16,
  "zsize": 16,
  "slices": [
    [
      "            a  v",
      "bbb         a  v",
      "bcb         a  v",
      "bbb         a  v",
      " d          a  v",
      " e     fgggga  v",
      "       g    a  v",
      "      h     a  v",
      "      i     a  v",
      "       g    a  v",
      " e     fgggga  v",
      " j          a  v",
      "bbb         a  v",
      "bkb         a  v",
      "bbb         allv",
      " !          ammv"
    ],
    [
      " n          a  v",
      "bnb         a  v",
      "opo         a  v",
      "bnb         a  v",
      " n          a  v",
      " q     fgggga  v",
      "       g    a  v",
      "       r    a  v",
      "       r    a  v",
      "       g    a  v",
      " q     fgggga  v",
      " n          a  v",
      "bnb         a  v",
      "opo         a  v",
      "bnb         allv",
      " n          ammv"
    ],
    [
      "            a  v",
      "bbb         a  v",
      "o o         a  v",
      "bsb         a  v",
      " t          a  v",
      "       fgggga  v",
      "       g    a  v",
      "       g    a  v",
      "       g    a  v",
      "       g    a  v",
      "       fgggga  v",
      " u          a  v",
      "bwb         a  v",
      "oxo         a  v",
      "bbb         allv",
      "            ammv"
    ],
    [
      "            a  v",
      "bbb         a  v",
      "o o         a  v",
      "bbb         a  v",
      "            a  v",
      "       fgggga  v",
      "       g    a  v",
      "       g    a  v",
      "       g    a  v",
      "       g    a  v",
      "       fgggga  v",
      "            a  v",
      "bbb         a  v",
      "oxo         a  v",
      "bbb         allv",
      "          yAammv"
    ],
    [
      "           Ba  v",
      "bbb        Ba  v",
      "o o        Ba  v",
      "bbb         a  v",
      "            a  v",
      "       fgggga  v",
      "       g    a  v",
      "       g    a  v",
      "       g    a  v",
      "       g    a  v",
      "       fgggga  v",
      "        CCCCa  v",
      "bbb     CCCCa  v",
      "oxo     CCCCa  v",
      "bbb       yAallv",
      "            ammv"
    ],
    [
      "            allv",
      "bbb         allv",
      "o o        Ballv",
      "bbb         allv",
      "            allv",
      "       fggggallv",
      "       g    allv",
      "       g    allv",
      "       g    allv",
      "       g    allv",
      "       fggggallv",
      "        D   allv",
      "bbb     D  Eallv",
      "oxo     D   allv",
      "bbb     FI  allv",
      "            ammv"
    ]
  ]
}