{
  "name": "multi_nuclearpowerplant_45_base10",
  "refpalette": "deceasedcraft:multi_nuclearpowerplant_45/multi_nuclearpowerplant_45_base10_palette",
  "xsize": 16,
  "zsize": 16,
  "slices": [
    [
      "   abcccccccdeev",
      "   abcccccccdeev",
      "   abcccccccdeev",
      "   abcccccccdeev",
      "   abcccccccdeev",
      "   abcccffffdeev",
      "   abcc     deev",
      "   abccf    deev",
      "   abccf    deev",
      "   abccf    dggv",
      "   abcccffffdhhv",
      "   abcccccccdhhv",
      "   abcccccccdhhv",
      "   abcccccccdiiv",
      "   abcccccccdggv",
      "   abcccccccdeev"
    ],
    [
      "    j    k lmeev",
      "    j       meev",
      "    n      fmeev",
      "    j      omeev",
      "    j      omeev",
      "    j  pqqqqmeev",
      "    j  q    meev",
      "    j rs    meev",
      "    j ts    mggv",
      "    j  q    mhhv",
      "    j  pqqqqmuuv",
      "    j      wx  v",
      "    j      yA  v",
      "    fqqBCqqfm  v",
      "    D      Emggv",
      "    D      Emeev"
    ],
    [
      "    j       meev",
      "    j      Fmeev",
      "    n      fmeev",
      "    j      Imeev",
      "    j      Imeev",
      "    j  pqqqqmeev",
      "    j  q    meev",
      "    j J     mggv",
      "    j K     mhhv",
      "    j  q    muuv",
      "    j  pqqqqm  v",
      "    j      LM  v",
      "    j N  N OP  v",
      "    fqqQRqqfm  v",
      "          STmggv",
      "          UVmeev"
    ],
    [
      "    j       meev",
      "    j       meev",
      "    n      fmeev",
      "    j      Wmeev",
      "    j      Wmeev",
      "    j  pqqqqmeev",
      "    j  q    mggv",
      "    j  X    mhhv",
      "    j  X    muuv",
      "    j  q    m  v",
      "    j  pqqqqm  v",
      "    j       d  v",
      "    j       d  v",
      "    fqqXXqqfm  v",
      "          S mggv",
      "            meev"
    ],
    [
      "    j       meev",
      "    j       meev",
      "    n      fmeev",
      "    j       meev",
      "    j       meev",
      "    j  pqqqqmggv",
      "    j  q    mhhv",
      "    j  q    muuv",
      "    j  q    m  v",
      "    j  q    m  v",
      "    j  pqqqqm  v",
      "    j       m  v",
      "    j       m  v",
      "    fqqqqqqfm  v",
      "           Emggv",
      "           Emeev"
    ],
    [
      "    j       meev",
      "    j       meev",
      "    n      fmeev",
      "    j       meev",
      "    j       mggv",
      "    j  pqqqqmhhv",
      "    j  q    muuv",
      "    j  q    m  v",
      "    j  q    m  v",
      "    j  q    m  v",
      "    j  pqqqqm  v",
      "    j       m  v",
      "    j       m  v",
      "    fqqqqqqfm  v",
      "          STmggv",
      "          U meev"
    ]
  ]
}