{
  "name": "multi_nuclearpowerplant_45_base12",
  "refpalette": "deceasedcraft:multi_nuclearpowerplant_45/multi_nuclearpowerplant_45_base12_palette",
  "xsize": 16,
  "zsize": 16,
  "slices": [
    [
      "aaaaaaaaaaaaaaav",
      "aaaaaaaaaaaaaaav",
      "aaaaaaaaaaaaaaav",
      "aaaaaaaaaaaaaaav",
      "aaaaaaaaaaaaaaav",
      "aaaaaaaaaaaaaaav",
      "aaaaaaaaaaaaaaav",
      "aaaaaaaaaaaaaaav",
      "aaaaaaaaaaaaaaav",
      "aaaaaaaaaaaaaaav",
      "aaaaaaaaaaaaaaav",
      "aaaaaaaaaaaaaaav",
      "aaaaaaaaaaaaaaav",
      "aaaaaaaaaaaaaaav",
      "aaaaaaaaaaaaaaav",
      "aaaaaaaaaaaaaaav"
    ],
    [
      "bbbbbbbbbbbbbaav",
      "bbbbbbbbbbbbbaav",
      "bbbbbbbbbbbbbaav",
      "bbbbbbbbbbbbbaav",
      "bbbbbbbbbbbbbaav",
      "bbbbbbbbbbbbbaav",
      "bbbbbbbbbbbbbaav",
      "bbbbbbbbbbbbbaav",
      "bbbbbbbbbbbbbaav",
      "bbbbbbbbbbbbbaav",
      "bbbbbbbbbbbbbaav",
      "bbbbbbbbbbbbbaav",
      "bbbbbbbbbbbbbaav",
      "bbbbbbbbbbbbbaav",
      "bbbbbbbbbbbbbaav",
      "bbbbbbbbbbbbbaav"
    ],
    [
      "============caav",
      "============caav",
      "============caav",
      "============caav",
      "============caav",
      "============caav",
      "============caav",
      "============caav",
      "============caav",
      "============caav",
      "============caav",
      "============caav",
      "============caav",
      "============caav",
      "============caav",
      "============caav"
    ],
    [
      "dddb========eaav",
      "dddb========eaav",
      "dddb========eaav",
      "dddb========eaav",
      "dddb========eaav",
      "dddb========eaav",
      "dddb========eaav",
      "dddb========eaav",
      "dddb========eaav",
      "dddb========eaav",
      "dddb========eaav",
      "dddb========eaav",
      "dddb========eaav",
      "dddb========eaav",
      "dddb========eaav",
      "dddb========eaav"
    ],
    [
      "fffb========eaav",
      "ggfb========eaav",
      "ggfb========eaav",
      "fffb========eaav",
      "ggfb========eaav",
      "ggfb========eaav",
      "fffb========eaav",
      "ggfb========eaav",
      "ggfb========eaav",
      "fffb========eaav",
      "ggfb========eaav",
      "ggfb========eaav",
      "fffb========eaav",
      "ggfb========eaav",
      "ggfb========eaav",
      "fffb========eaav"
    ],
    [
      "fffb========eaav",
      "hifb========eaav",
      "jkfb========eaav",
      "fffb========eaav",
      "ikfb========eaav",
      "hjfb========eaav",
      "fffb========eaav",
      "hifb========eaav",
      "jkfb========eaav",
      "fffb========eaav",
      "ikfb========eaav",
      "hjfb========eaav",
      "fffb========eaav",
      "hifb========eaav",
      "jkfb========eaav",
      "fffb========eaav"
    ]
  ]
}