{
  "name": "multi_nuclearpowerplant_45_base4",
  "refpalette": "deceasedcraft:multi_nuclearpowerplant_45/multi_nuclearpowerplant_45_base4_palette",
  "xsize": 16,
  "zsize": 16,
  "slices": [
    [
      " a          bccv",
      "ddd         bccv",
      "ded        fbccv",
      "ddd         bccv",
      "            bccv",
      "       ghhhhijjv",
      "       h    ijjv",
      "       h    ijjv",
      "       h    ijjv",
      "       h    ijjv",
      "       ghhhhijjv",
      "            bccv",
      "ddd         bccv",
      "ded         bccv",
      "ddd         bccv",
      " a          bccv"
    ],
    [
      "            bccv",
      "kkk         bccv",
      "klk        fbccv",
      "kkk         bccv",
      "            bccv",
      "       ghhhhijjv",
      "       h    ijjv",
      "       h    ijjv",
      "       h    ijjv",
      "       h    ijjv",
      "       ghhhhijjv",
      "            bccv",
      "kkk         bccv",
      "klk         bccv",
      "kkk         bccv",
      "            bccv"
    ],
    [
      "            bccv",
      "            bccv",
      "           fbccv",
      "            bccv",
      "            bccv",
      "       ghhhhijjv",
      "       h    ijjv",
      "       h    ijjv",
      "       h    ijjv",
      "       h    ijjv",
      "       ghhhhijjv",
      "            bccv",
      "            bccv",
      "            bccv",
      "            bccv",
      "            bccv"
    ],
    [
      "            bccv",
      "            bccv",
      "           fbccv",
      "            bccv",
      "            bccv",
      "       ghhhhijjv",
      "       h    ijjv",
      "       h    ijjv",
      "       h    ijjv",
      "       h    ijjv",
      "       ghhhhijjv",
      "            bccv",
      "            bccv",
      "            bccv",
      "            bccv",
      "            bccv"
    ],
    [
      "mmmm        bccv",
      "            bccv",
      "           fbccv",
      "            bccv",
      "            bccv",
      "mmmm   ghhhhijjv",
      "       h    ijjv",
      "       h    ijjv",
      "       h    ijjv",
      "       h    ijjv",
      "mmmm   ghhhhijjv",
      "            bccv",
      "            bccv",
      "            bccv",
      "            bccv",
      "mmmm        bccv"
    ],
    [
      "n n         bccv",
      "            bccv",
      "           fbccv",
      "            bccv",
      "            bccv",
      "n n    ghhhhijjv",
      "       h    ijjv",
      "       h    ijjv",
      "       h    ijjv",
      "       h    ijjv",
      "n n    ghhhhijjv",
      "            bccv",
      "            bccv",
      "            bccv",
      "            bccv",
      "n n       opbccv"
    ]
  ]
}