{
  "name": "multi_nuclearpowerplant_45_base2",
  "refpalette": "deceasedcraft:multi_nuclearpowerplant_45/multi_nuclearpowerplant_45_base2_palette",
  "xsize": 16,
  "zsize": 16,
  "slices": [
    [
      "   a  a=b  cdeev",
      "fffaffa=b  cdeev",
      "======= b  cdeev",
      "        b   deev",
      "        b   deev",
      "       ghhhhijjv",
      "       h    ijjv",
      "       h    kjjv",
      "       h    kjjv",
      "       h    ijjv",
      "       ghhhhijjv",
      "            deev",
      "            deev",
      "=======     deev",
      "lllalla=    deev",
      "   a  a=    deev"
    ],
    [
      "mmma  a=b   deev",
      "fffaffa=b   deev",
      "======= b  cdeev",
      "        b   deev",
      "        b   deev",
      "       ghhhhijjv",
      "       h    ijjv",
      "       h    ijjv",
      "       h    ijjv",
      "       h    ijjv",
      "       ghhhhijjv",
      "            deev",
      "            deev",
      "=======     deev",
      "lllalla=    deev",
      "mmma  a=    deev"
    ],
    [
      "ccca  a=b   deev",
      "fffaffa=b   deev",
      "======= b  cdeev",
      "        b   deev",
      "        b   deev",
      "       ghhhhijjv",
      "       h    ijjv",
      "       h    kjjv",
      "       h    kjjv",
      "       h    ijjv",
      "       ghhhhijjv",
      "            deev",
      "            deev",
      "=======     deev",
      "lllalla=    deev",
      "ccca  a=    deev"
    ],
    [
      "aaaaaaa=jjjjdeev",
      "aaaaaaa=jjjjdeev",
      "======= b  cdeev",
      "nnnnnnn b   deev",
      "nnnnnnn b   deev",
      "nnooonnghhhhijjv",
      "nnnnnnnh    ijjv",
      "nnnnnnnh    ijjv",
      "nnnnnnnh    ijjv",
      "nnnnnnnh    ijjv",
      "nnooonnghhhhijjv",
      "nnnnnnn     deev",
      "nnnnnnn     deev",
      "=======     deev",
      "aaaaaaa=    deev",
      "aaaaaaa=  pqdeev"
    ],
    [
      "       rssssdeev",
      "rrrrrrrrssssdeev",
      "tttttttrssscdeev",
      "tttttttrssssdeev",
      "tttttttrssssdeev",
      "tttttttruuuuijjv",
      "ttttttt  wwwijjv",
      "tttttttuxxxwkjjv",
      "tttttttuxxxwkjjv",
      "tttttttuwwwwijjv",
      "tttttttruuuuijjv",
      "tttttttryyyydeev",
      "tttttttryyyydeev",
      "tttttttryyyydeev",
      "rrrrrrrr  pqdeev",
      "       r    deev"
    ],
    [
      "ttttttthb   deev",
      "ttttttthb   deev",
      "ABBhhhh b  cdeev",
      "C hD  EFI   deev",
      "  h     b   deev",
      "  BJ   ghhhhijjv",
      "  BK   hLMMMijjv",
      "  NOP QR STUijjv",
      "  VO WXRYZ0Uijjv",
      "  B1   h2MMMijjv",
      "  B3   ghhhhijjv",
      "  h     4556deev",
      "7!hD       8deev",
      "ABBhhhh 99  deev",
      "ttttttth    deev",
      "ttttttth    deev"
    ]
  ]
}