{
  "name": "multi_nuclearpowerplant_45_base5",
  "refpalette": "deceasedcraft:multi_nuclearpowerplant_45/multi_nuclearpowerplant_45_base5_palette",
  "xsize": 16,
  "zsize": 16,
  "slices": [
    [
      "            abbv",
      "ccc         abbv",
      "d d        eabbv",
      "ccc         abbv",
      "            abbv",
      "       fgggghiiv",
      "       g    hiiv",
      "       g    hiiv",
      "       g    hiiv",
      "       g    hiiv",
      "       fgggghiiv",
      "            abbv",
      "ccc         abbv",
      "djd         abbv",
      "ccc         abbv",
      "            abbv"
    ],
    [
      "            abbv",
      "ccc         abbv",
      "dkd        eabbv",
      "ccc         abbv",
      "            abbv",
      "       fgggghiiv",
      "       g    hiiv",
      "       g    hiiv",
      "       g    hiiv",
      "       g    hiiv",
      "       fgggghiiv",
      "            abbv",
      "ccc         abbv",
      "dld         abbv",
      "ccc         abbv",
      "          mnabbv"
    ],
    [
      "            abbv",
      "ccc         abbv",
      "d d        eabbv",
      "ccc         abbv",
      "            abbv",
      "       fgggghiiv",
      "       g    hiiv",
      "       g    hiiv",
      "       g    hiiv",
      "       g    hiiv",
      "       fgggghiiv",
      "        ooooabbv",
      "ccc     ooooabbv",
      "djd     ooooabbv",
      "ccc       mnabbv",
      "            abbv"
    ],
    [
      "            abbv",
      "ccc         abbv",
      "d d        eabbv",
      "ccc         abbv",
      "            abbv",
      "       fgggghiiv",
      "       g    hiiv",
      "       g    hiiv",
      "       g    hiiv",
      "       g    hiiv",
      "       fgggghiiv",
      "        pq  abbv",
      "ccc     p q!abbv",
      "djd     p  qabbv",
      "ccc     rs  abbv",
      "            abbv"
    ],
    [
      " t          abbv",
      "ccc         abbv",
      "d d        eabbv",
      "ccc         abbv",
      "            abbv",
      "       fgggghiiv",
      "       g    hiiv",
      "       g    hiiv",
      "       g    hiiv",
      "       g    hiiv",
      "       fgggghiiv",
      "            abbv",
      "ccc        qabbv",
      "djd         abbv",
      "ccc         abbv",
      " t      rs  abbv"
    ],
    [
      "u w         abbv",
      "c c         abbv",
      "dkd        eabbv",
      "ccc         abbv",
      "            abbv",
      "       fgggghiiv",
      "       g    hiiv",
      "       g    hiiv",
      "       g    hiiv",
      "       g    hiiv",
      "       fgggghiiv",
      "            abbv",
      "ccc         abbv",
      "dld         abbv",
      "cjc         abbv",
      "ujw         abbv"
    ]
  ]
}