{
  "name": "multi_nuclearpowerplant_45_base3",
  "refpalette": "deceasedcraft:multi_nuclearpowerplant_45/multi_nuclearpowerplant_45_base3_palette",
  "xsize": 16,
  "zsize": 16,
  "slices": [
    [
      "aaaaaaabccccdeev",
      "aaaaaaabccccdeev",
      "aaaaaaabcccfdeev",
      "aaaaaaabccccdeev",
      "aaaaaaabccccdeev",
      "aaaaaaabggggahhv",
      "aaaaaaa     ahhv",
      "aaaaaaag    ahhv",
      "aaaaaaag    ahhv",
      "aaaaaaag    ahhv",
      "aaaaaaabggggahhv",
      "aaaaaaabiiiideev",
      "aaaaaaabiiiideev",
      "aaaaaaabiiiideev",
      "aaaaaaab  jkdeev",
      "aaaaaaab    deev"
    ],
    [
      "lllllll=m   neev",
      "lllllll=m   neev",
      "======= m  oneev",
      "p  qp   r   neev",
      "        m   neev",
      "       sttttuhhv",
      "       t    uhhv",
      "      wx    uhhv",
      "      yx    uhhv",
      "       t    uhhv",
      "       sttttuhhv",
      "            neev",
      "A  BA      Cneev",
      "=======     neev",
      "lllllll=DE  neev",
      "lllllll=    neev"
    ],
    [
      "      l=m   neev",
      "FFFFFFl=m   neev",
      "======= m  Ineev",
      "        J   neev",
      "        m   neev",
      "       sttttuhhv",
      "       t    uhhv",
      "      K     Lhhv",
      "      M     Lhhv",
      "       t    uhhv",
      "       sttttuhhv",
      "            neev",
      "            neev",
      "=======     neev",
      "NNNNNNl=    neev",
      "      l=DE  neev"
    ],
    [
      "      l=m   neev",
      "FFFFFFl=m   neev",
      "======= m  Ineev",
      "       OP   neev",
      "        m   neev",
      "       sttttuhhv",
      "       t    uhhv",
      "       Q    uhhv",
      "       Q    uhhv",
      "       t    uhhv",
      "       sttttuhhv",
      "            neev",
      "            neev",
      "=======     neev",
      "NNNNNNl=    neev",
      "      l=    neev"
    ],
    [
      "   R  l=m   neev",
      "FFFFFFl=m   neev",
      "======= m  Ineev",
      "        m   neev",
      "        m   neev",
      "       sttttuhhv",
      "       t    uhhv",
      "       t    Lhhv",
      "       t    Lhhv",
      "       t    uhhv",
      "       sttttuhhv",
      "            neev",
      "            neev",
      "=======     neev",
      "NNNNNNl=    neev",
      "   R  l=    neev"
    ],
    [
      "   l  l=m   neev",
      "FFFlFFl=m   neev",
      "======= m  Ineev",
      "        m   neev",
      "        m   neev",
      "       sttttuhhv",
      "       t    uhhv",
      "       t    uhhv",
      "       t    uhhv",
      "       t    uhhv",
      "       sttttuhhv",
      "            neev",
      "            neev",
      "=======     neev",
      "NNNlNNl=    neev",
      "   l  l=    neev"
    ]
  ]
}