{
  "name": "multi_nuclearpowerplant_45_base8",
  "refpalette": "deceasedcraft:multi_nuclearpowerplant_45/multi_nuclearpowerplant_45_base8_palette",
  "xsize": 16,
  "zsize": 16,
  "slices": [
    [
      "    ab      c  v",
      "    ab      c  v",
      "    db      c  v",
      "    ab      c  v",
      "    ab      c  v",
      "    ab  aaaac  v",
      "    ab a    c  v",
      "    ab a    c  v",
      "    ab a    c  v",
      "    ab a    c  v",
      "    ab  aaaac  v",
      "    ab      c  v",
      "    abbbbbbbc  v",
      "    daaaaaadc ev",
      "            cffv",
      "            cggv"
    ],
    [
      "ffffffffffffh  v",
      "ffffffffffffh  v",
      "ffffffffffffh  v",
      "ffffffffffffh  v",
      "ffffffffffffh  v",
      "ffffffffaaaah  v",
      "fffffffa    h  v",
      "fffffffa    h  v",
      "fffffffa    h  v",
      "fffffffa    h  v",
      "ffffffffaaaah  v",
      "ffffffffffffh  v",
      "ffffffffffffh  v",
      "fffffffffffih  v",
      "ffffffffffffhffv",
      "ffffffffffffhggv"
    ],
    [
      "ggggggggggggc  v",
      "ggggggggggggc  v",
      "ggggggggggggc  v",
      "ggggggggggggc  v",
      "ggggggggggggc  v",
      "ggggggggaaaac  v",
      "ggggggga    c  v",
      "ggggggga    c  v",
      "ggggggga    c  v",
      "ggggggga    c  v",
      "ggggggggaaaac  v",
      "ggggggggggggc  v",
      "ggggggggggggc  v",
      "ggggggggggggc  v",
      "ggggggggggggcffv",
      "ggggggggggggcggv"
    ],
    [
      "ggggggggggggc  v",
      "ggggggggggggc  v",
      "ggggggggggggc  v",
      "ggggggggggggc  v",
      "ggggggggggggc  v",
      "ggggggggaaaac  v",
      "ggggggga    c  v",
      "ggggggga    c  v",
      "ggggggga    c  v",
      "ggggggga    c  v",
      "ggggggggaaaac  v",
      "ggggggggggggc  v",
      "ggggggggggggc  v",
      "ggggggggggggc  v",
      "ggggggggggggcffv",
      "ggggggggggggcggv"
    ],
    [
      "jjjjkhhhhhhhc  v",
      "fffjkhhhhhhhc  v",
      "fffjkhhhhhhhc  v",
      "fffjkhhhhhhhc  v",
      "jjjjkhhhhhhhc  v",
      "klkkkhhhddddc  v",
      "hhhhhhh     c  v",
      "hhhhhhhd    c  v",
      "hhhhhhhd    c  v",
      "hhhhhhhd    c  v",
      "klkkkhhhddddc  v",
      "mmmmkhhhhhhhc  v",
      "fffmkhhhhhhhc  v",
      "fffmkhhhhhhhc  v",
      "fffmkhhhhhhhcffv",
      "mmmmkhhhhhhhcggv"
    ],
    [
      "            c  v",
      "nnn         c  v",
      "n n         c  v",
      "nnn         c  v",
      "            c  v",
      "       oaaaac  v",
      "       a    c  v",
      "      pq    c  v",
      "      rq    c  v",
      "       a    c  v",
      "       oaaaac  v",
      "            c  v",
      "nnn         c  v",
      "n n         c  v",
      "nnn         cffv",
      "            cggv"
    ]
  ]
}