{
  "name": "multi_nuclearpowerplant_38_base8",
  "refpalette": "deceasedcraft:multi_nuclearpowerplant_38/multi_nuclearpowerplant_38_base8_palette",
  "xsize": 16,
  "zsize": 16,
  "slices": [
    [
      "                ",
      "           a a  ",
      "    a       b   ",
      "           a a  ",
      "                ",
      "                ",
      "                ",
      "                ",
      "                ",
      "                ",
      "                ",
      "                ",
      "           a a  ",
      "    a       b   ",
      "           a a  ",
      "                "
    ],
    [
      "cccccccccccccccc",
      "cccccccccccccccc",
      "ccccccccccccdccc",
      "cccccccccccccccc",
      "cccccccccccccccc",
      "cccccccccccccccc",
      "cccccccccccccccc",
      "cccccccccccccccc",
      "cccccccccccccccc",
      "cccccccccccccccc",
      "cccccccccccccccc",
      "cccccccccccccccc",
      "cccccccccccccccc",
      "ccccccccccccdccc",
      "cccccccccccccccc",
      "cccccccccccccccc"
    ],
    [
      "eeeeeeeeeeefgfee",
      "eeeeeeeeeeefhfee",
      "eeeeeeeeeeefifee",
      "eeeeeeeeeeefhfee",
      "eeeeeeeeeeefgfee",
      "eeeeeeeeeeefgfee",
      "eeeeeeeeeeefgfee",
      "eeeeeeeeeeefgfee",
      "eeeeeeeeeeefgfee",
      "eeeeeeeeeeefgfee",
      "eeeeeeeeeeefgfee",
      "eeeeeeeeeeefgfee",
      "eeeeeeeeeeefhfee",
      "eeeeeeeeeeefifee",
      "eeeeeeeeeeefhfee",
      "eeeeeeeeeeefgfee"
    ],
    [
      "eeeeeeeeeeeefeee",
      "eeeeeeeeeeeefeee",
      "eeeeeeeeeeeefeee",
      "eeeeeeeeeeeefeee",
      "eeeeeeeeeeeefeee",
      "eeeeeeeeeeeefeee",
      "eeeeeeeeeeeefeee",
      "eeeeeeeeeeeefeee",
      "eeeeeeeeeeeefeee",
      "eeeeeeeeeeeefeee",
      "eeeeeeeeeeeefeee",
      "eeeeeeeeeeeefeee",
      "eeeeeeeeeeeefeee",
      "eeeeeeeeeeeefeee",
      "eeeeeeeeeeeefeee",
      "eeeeeeeeeeeefeee"
    ],
    [
      "======jkllllllkm",
      "======jkllllllkm",
      "======jkllllllkm",
      "======jkllllllkm",
      "nonnnnokllllllkm",
      "kkkkkkkkllllllkk",
      "llllllllllllllll",
      "llllllllllllllll",
      "llllllllllllllll",
      "llllllllllllllll",
      "kkkkkkkkllllllkk",
      "nonnnnokllllllkp",
      "======jkllllllkp",
      "======jkllllllkp",
      "======jkllllllkp",
      "======jkllllllkp"
    ],
    [
      "      q         ",
      "   aa q         ",
      "   aa q         ",
      "      q   r     ",
      " aqqqqa         ",
      "      s         ",
      "                ",
      "                ",
      "                ",
      "                ",
      "      t         ",
      " aqqqqa         ",
      "      q   r     ",
      "   aa q         ",
      "   aa q         ",
      "      q         "
    ]
  ]
}