{
  "name": "multi_nuclearpowerplant_38_base1",
  "refpalette": "deceasedcraft:multi_nuclearpowerplant_38/multi_nuclearpowerplant_38_base1_palette",
  "xsize": 16,
  "zsize": 16,
  "slices": [
    [
      "aaaaaaabb       ",
      "aaaaaaabbc     d",
      "eeeeeeefgggggggh",
      "       i jklkm  ",
      "       i        ",
      "       i        ",
      "       i        ",
      "       i nolop  ",
      "       i jklkm  ",
      "       i        ",
      "       i        ",
      "       i        ",
      "       i poloq  ",
      "eeeeeeefggggggg ",
      "aaaaaaabbc     r",
      "aaaaaaabb       "
    ],
    [
      "aaaaaaabb       ",
      "aaaaaaabb!     s",
      "eeeeeeefggggggg ",
      "       i        ",
      "       i        ",
      "       i        ",
      "       i        ",
      "       i        ",
      "       i        ",
      "       i        ",
      "       i        ",
      "       i        ",
      "       i        ",
      "eeeeeeefggggggg ",
      "aaaaaaabbt     u",
      "aaaaaaabb       "
    ],
    [
      "aaaaaaabb       ",
      "aaaaaaabb       ",
      "eeeeeeefgggggggg",
      "       i        ",
      "       i        ",
      "       i        ",
      "       i        ",
      "       i        ",
      "       i        ",
      "       i        ",
      "       i        ",
      "       i        ",
      "       i        ",
      "eeeeeeefgggggggg",
      "aaaaaaabbw      ",
      "aaaaaaabb       "
    ],
    [
      "aaaaaaabb       ",
      "aaaaaaabb       ",
      "eeeeeeefgggggggg",
      "exy    i        ",
      "exy    i        ",
      "exy    i        ",
      "exy    i        ",
      "exy    i        ",
      "exy    i        ",
      "exy    i        ",
      "exy    i        ",
      "exy    i        ",
      "exy    i        ",
      "eeeeeeefgggggggg",
      "aaaaaaabb       ",
      "aaaaaaabb       "
    ],
    [
      "aaaaaaabb       ",
      "aaaaaaabb       ",
      "aaaeeeefgggggggg",
      "aaaexy iAAAAAAAA",
      "aaaexy i        ",
      "aaaexy i        ",
      "aaaexy i        ",
      "aaaexy i        ",
      "aaaexy i        ",
      "aaaexy i        ",
      "aaaexy i        ",
      "aaaexy i        ",
      "aaaexy iBBBBBBBB",
      "aaaeeeefgggggggg",
      "aaaaaaabb       ",
      "aaaaaaabb       "
    ],
    [
      "CDaaaaabbEEEEEEE",
      "CDaaaaabbEEEEEEE",
      "CDaaaaefffffffff",
      "CDaaaaefeeeeeeee",
      "CDaaaaefeeeeeeee",
      "CDaaaaefeeFeeeeF",
      "CDaaaaefeeFeeeeF",
      "CDaaaaefeeFeeeeF",
      "CDaaaaefeeFeeeeI",
      "CDaaaaefeeFeeeeI",
      "CDaaaaefeeFeeeeI",
      "CDaaaaefeeeeeeee",
      "CDaaaaefeeeeeeee",
      "CDaaaaefffffffff",
      "CDaaaaabbEEEEEEE",
      "CDaaaaabbEEEEEEE"
    ]
  ]
}