{
  "name": "multi_nuclearpowerplant_38_base7",
  "refpalette": "deceasedcraft:multi_nuclearpowerplant_38/multi_nuclearpowerplant_38_base7_palette",
  "xsize": 16,
  "zsize": 16,
  "slices": [
    [
      "                ",
      "    a           ",
      "   aa           ",
      "          b     ",
      " c    c         ",
      "                ",
      "                ",
      "                ",
      "                ",
      "                ",
      "                ",
      " c    c         ",
      "          b     ",
      "   aa           ",
      "   aa           ",
      "                "
    ],
    [
      "                ",
      "                ",
      "                ",
      "          b     ",
      " c    c         ",
      "                ",
      "                ",
      "                ",
      "                ",
      "                ",
      "                ",
      " c    c         ",
      "          b     ",
      "   aa           ",
      "   aa           ",
      "ddef            "
    ],
    [
      "                ",
      "                ",
      "                ",
      " g    g   b     ",
      " c    c         ",
      "                ",
      "                ",
      "                ",
      "                ",
      "                ",
      "                ",
      " c    c         ",
      " h    h   b     ",
      "                ",
      "                ",
      "                "
    ],
    [
      " c    c         ",
      " c    c         ",
      " c    c         ",
      "ccccccc   b     ",
      " c    c         ",
      "                ",
      "                ",
      "                ",
      "                ",
      "                ",
      " i              ",
      " c    c         ",
      "ccccccc   b     ",
      " c    c         ",
      " c    c         ",
      " c    c         "
    ],
    [
      "jjjjjj          ",
      "jjjjjj          ",
      "jjjjjj          ",
      "jjjjjj    b     ",
      " c    c         ",
      "                ",
      "                ",
      "                ",
      "                ",
      "                ",
      "                ",
      " c    c         ",
      "jjjjjj    b     ",
      "jjjjjj          ",
      "jjjjjj          ",
      "jjjjjj          "
    ],
    [
      " k lmn   oo     ",
      "   mmn   oo     ",
      "   lmn   oo     ",
      "nnnnnj   op     ",
      " c    c  oo     ",
      "         oo     ",
      "         oo     ",
      "         oo     ",
      "         oo     ",
      "         oo     ",
      "         oo     ",
      " c    c  oo     ",
      "nnnnnj   op     ",
      "   mmn   oo     ",
      "   mmn   oo     ",
      "qqqmmn   oo     "
    ]
  ]
}