{
  "name": "multi_nuclearpowerplant_38_base12",
  "refpalette": "deceasedcraft:multi_nuclearpowerplant_38/multi_nuclearpowerplant_38_base12_palette",
  "xsize": 16,
  "zsize": 16,
  "slices": [
    [
      "aaaaaaaaaaaaaaaa",
      "aaaaaaaaaaaaaaaa",
      "aaaaaaaaaaaaaaaa",
      "aaaaaaaaaaaaaaaa",
      "aaaaaaaaaaaaaaaa",
      "aaaaaaaaaaaaaaaa",
      "aaaaaaaaaaaaaaaa",
      "aaaaaaaaaaaaaaaa",
      "aaaaaaaaaaaaaaaa",
      "aaaaaaaaaaaaaaaa",
      "aaaaaaaaaaaaaaaa",
      "aaaaaaaaaaaaaaaa",
      "aaaaaaaaaaaaaaaa",
      "aaaaaaaaaaaaaaaa",
      "aaaaaaaaaaaaaaaa",
      "aaaaaaaaaaaaaaaa"
    ],
    [
      "bbbbbbbbbbbbbbbb",
      "bbbbbbbbbbbbbbbb",
      "bbbbbbbbbbbbbbbb",
      "bbbbbbbbbbbbbbbb",
      "bbbbbbbbbbbbbbbb",
      "bbbbbbbbbbbbbbbb",
      "bbbbbbbbbbbbbbbb",
      "bbbbbbbbbbbbbbbb",
      "bbbbbbbbbbbbbbbb",
      "bbbbbbbbbbbbbbbb",
      "bbbbbbbbbbbbbbbb",
      "bbbbbbbbbbbbbbbb",
      "bbbbbbbbbbbbbbbb",
      "bbbbbbbbbbbbbbbb",
      "bbbbbbbbbbbbbbbb",
      "bbbbbbbbbbbbbbbb"
    ],
    [
      "================",
      "================",
      "================",
      "================",
      "================",
      "================",
      "================",
      "================",
      "================",
      "================",
      "================",
      "================",
      "================",
      "================",
      "================",
      "================"
    ],
    [
      "cccccccccccccccc",
      "cccccccccccccccc",
      "cccccccccccccccc",
      "cccccccccccccccc",
      "cccccccccccccccc",
      "cccccccccccccccc",
      "cccccccccccccccc",
      "cccccccccccccccc",
      "cccccccccccccccc",
      "cccccccccccccccc",
      "cccccccccccccccc",
      "cccccccccccccccc",
      "cccccccccccccccc",
      "cccccccccccccccc",
      "cccccccccccccccc",
      "cccccccccccccccc"
    ],
    [
      "dddddddddddddddd",
      "deedeedeedeedeed",
      "deedeedeedeedeed",
      "dddddddddddddddd",
      "deedeedeedeedeed",
      "deedeedeedeedeed",
      "dddddddddddddddd",
      "deedeedeedeedeed",
      "deedeedeedeedeed",
      "dddddddddddddddd",
      "deedeedeedeedeed",
      "deedeedeedeedeed",
      "dddddddddddddddd",
      "deedeedeedeedeed",
      "deedeedeedeedeed",
      "dddddddddddddddd"
    ],
    [
      "dddddddddddddddd",
      "dfgdhfdfgdhfdfgd",
      "dhidigdhidigdhid",
      "dddddddddddddddd",
      "dhfdfgdhfdfgdhfd",
      "digdhidigdhidigd",
      "dddddddddddddddd",
      "dfgdhfdfgdhfdfgd",
      "dhidigdhidigdhid",
      "dddddddddddddddd",
      "dhfdfgdhfdfgdhfd",
      "digdhidigdhidigd",
      "dddddddddddddddd",
      "dfgdhfdfgdhfdfgd",
      "dhidigdhidigdhid",
      "dddddddddddddddd"
    ]
  ]
}