{
  "name": "multi_nuclearpowerplant_38_base11",
  "refpalette": "deceasedcraft:multi_nuclearpowerplant_38/multi_nuclearpowerplant_38_base11_palette",
  "xsize": 16,
  "zsize": 16,
  "slices": [
    [
      "aaaaaaaaaaaaaaaa",
      "abcacdabeacdabca",
      "afdabfafdabfafda",
      "aaaaaaaaaaaaaaaa",
      "acdabcacdabcacda",
      "abfafdabfafdabfa",
      "aaaaaaaaaaaaaaaa",
      "abcacdabcacdabca",
      "afdabfafdabfafda",
      "aaaaaaaaaaaaaaaa",
      "acdabcacdabcacda",
      "abfafdabfafdabfa",
      "aaaaaaaaaaaaaaaa",
      "abcacdabcacdabca",
      "afdabfafdabfafda",
      "aaaaaaaaaaaaaaaa"
    ],
    [
      "aaaaaaaaaaaaaaaa",
      "acdabcacdabcacda",
      "abfafdabeafdabfa",
      "aaaaaaaaaaaaaaaa",
      "abcacdabcacdabca",
      "afdabfafdabfafda",
      "aaaaaaaaaaaaaaaa",
      "acdabcacdabcacda",
      "abfafdabfafdabfa",
      "aaaaaaaaaaaaaaaa",
      "abcacdabcacdabca",
      "afdabfafdabfafda",
      "aaaaaaaaaaaaaaaa",
      "acdabcacdabcacda",
      "abfafdabfafdabfa",
      "aaaaaaaaaaaaaaaa"
    ],
    [
      "aaaaaaaaaaaaaaaa",
      "abcaaaaaaacdabca",
      "afdaaaaaaabfafda",
      "aaaaaaaaaaaaaaaa",
      "aaaabcaaaaaaaaaa",
      "aaaafdaaaaaaaaaa",
      "aaaaaaaaaaaaaaaa",
      "aaaaaaaaaacdaaaa",
      "aaaaaaaaaabfaaaa",
      "aaaaaaaaaaaaaaaa",
      "acdaaaaaaaaaaaaa",
      "abfaaaaaaaaaaaaa",
      "aaaaaaaaaaaaaaaa",
      "aaaaaaaaaaaaabca",
      "aaaaaaaaaaaaafda",
      "aaaaaaaaaaaaaaaa"
    ],
    [
      "aaaaaaaaaaaaaaaa",
      "aaaaaaaaaaaaaaaa",
      "aaaaaaaaaaaaaaaa",
      "aaaaaaaaaaaaaaaa",
      "aaaaaaaaaaaaaaaa",
      "aaaaaaaaaaaaaaaa",
      "aaaaaaaaaaaaaaaa",
      "aaaaaaaaaaaaaaaa",
      "aaaaaaaaaaaaaaaa",
      "aaaaaaaaaaaaaaaa",
      "aaaaaaaaaaaaaaaa",
      "aaaaaaaaaaaaaaaa",
      "aaaaaaaaaaaaaaaa",
      "aaaaaaaaaaaaaaaa",
      "aaaaaaaaaaaaaaaa",
      "aaaaaaaaaaaaaaaa"
    ],
    [
      "aaaaaaaaaaaaaaaa",
      "aaaaaaaaaaaaaaaa",
      "aaaaaaaaaaaaaaaa",
      "aaaaaaaaaaaaaaaa",
      "aaaaaaaaaaaaaaaa",
      "aaaaaaaaaaaaaaaa",
      "aaaaaaaaaaaaaaaa",
      "aaaaaaaaaaaaaaaa",
      "aaaaaaaaaaaaaaaa",
      "aaaaaaaaaaaaaaaa",
      "aaaaaaaaaaaaaaaa",
      "aaaaaaaaaaaaaaaa",
      "aaaaaaaaaaaaaaaa",
      "aaaaaaaaaaaaaaaa",
      "aaaaaaaaaaaaaaaa",
      "aaaaaaaaaaaaaaaa"
    ],
    [
      "aaaaaaaaaaaaaaaa",
      "aaaaaaaaaaaaaaaa",
      "aaaaaaaaaaaaaaaa",
      "aaaaaaaaaaaaaaaa",
      "aaaaaaaaaaaaaaaa",
      "aaaaaaaaaaaaaaaa",
      "aaaaaaaaaaaaaaaa",
      "aaaaaaaaaaaaaaaa",
      "aaaaaaaaaaaaaaaa",
      "aaaaaaaaaaaaaaaa",
      "aaaaaaaaaaaaaaaa",
      "aaaaaaaaaaaaaaaa",
      "aaaaaaaaaaaaaaaa",
      "aaaaaaaaaaaaaaaa",
      "aaaaaaaaaaaaaaaa",
      "aaaaaaaaaaaaaaaa"
    ]
  ]
}