{
  "name": "multi_nuclearpowerplant_38_base3",
  "refpalette": "deceasedcraft:multi_nuclearpowerplant_38/multi_nuclearpowerplant_38_base3_palette",
  "xsize": 16,
  "zsize": 16,
  "slices": [
    [
      "aaaaab     cdddd",
      "aaaaab     cdddd",
      "aaaaaabcccccdddd",
      "aaaaaabddddddddd",
      "aaaaaabddddddddd",
      "aaaaaabddddddddd",
      "aaaaaabddddddddd",
      "aaaaaabddddddddd",
      "aaaaaabddddddddd",
      "aaaaaabddddddddd",
      "aaaaaabddddddddd",
      "aaaaaabddddddddd",
      "aaaaaabddddddddd",
      "aaaaaabcccccdddd",
      "aaaaab     cdddd",
      "aaaaab     cdddd"
    ],
    [
      "ee   f     g  =h",
      "ijk  f     g  =h",
      "     lfggggg  l=",
      "      f        m",
      "                ",
      "n               ",
      "op              ",
      "!p              ",
      "qp              ",
      "op              ",
      "r               ",
      "      s         ",
      "      f        t",
      "     lfggggg  l=",
      "ijk  f     g  =h",
      "ee   f     g  =h"
    ],
    [
      "uu   f        =h",
      "jjk  f        =h",
      "     wf       w=",
      "      f         ",
      "                ",
      "                ",
      "x               ",
      "                ",
      "                ",
      "yA              ",
      "                ",
      "                ",
      "      f         ",
      "     wf       w=",
      "jjk  f        =h",
      "uu   f        =h"
    ],
    [
      "uu   f       B=h",
      "jjk  f        =h",
      "CC   Df       D=",
      "      f         ",
      "                ",
      "                ",
      "                ",
      "                ",
      "                ",
      "                ",
      "                ",
      "                ",
      "      f         ",
      "EE   Df       D=",
      "jjk  f        =h",
      "uu   f       B=h"
    ],
    [
      "FF   f        =h",
      "II   f        =h",
      "      f        =",
      "      f         ",
      "                ",
      "                ",
      "                ",
      "                ",
      "                ",
      "                ",
      "                ",
      "                ",
      "      f         ",
      "      f        =",
      "II   f        =h",
      "FF   f        =h"
    ],
    [
      "     f        =h",
      "     f        =h",
      "      f        =",
      "      f         ",
      "      fJ        ",
      "      fJ        ",
      "      fJ        ",
      "      fJ        ",
      "      fJ        ",
      "      fJ        ",
      "      fJ        ",
      "      fJ        ",
      "      f         ",
      "      f        =",
      "     f        =h",
      "     f        =h"
    ]
  ]
}