{
  "name": "multi_nuclearpowerplant_38_base2",
  "refpalette": "deceasedcraft:multi_nuclearpowerplant_38/multi_nuclearpowerplant_38_base2_palette",
  "xsize": 16,
  "zsize": 16,
  "slices": [
    [
      "     a        =b",
      "     a        =b",
      "      a        =",
      "      a         ",
      "      a         ",
      "     ca         ",
      "     ca         ",
      "     ca         ",
      "     ca         ",
      "     ca         ",
      "     ca         ",
      "      a         ",
      "      a         ",
      "      a        =",
      "     a        =b",
      "     a        =b"
    ],
    [
      "     a        =b",
      "     a        =b",
      "      a        =",
      "      a         ",
      "      a         ",
      "     ca         ",
      "     ca         ",
      "     ca         ",
      "     ca         ",
      "     ca         ",
      "     ca         ",
      "      a         ",
      "      a         ",
      "      a        =",
      "     a        =b",
      "     a        =b"
    ],
    [
      "     a        =b",
      "     a        =b",
      "      a        =",
      "      a         ",
      "      a         ",
      "     ca         ",
      "     ca         ",
      "     ca         ",
      "     ca         ",
      "     ca         ",
      "     ca         ",
      "      a         ",
      "      a         ",
      "      a        =",
      "     a        =b",
      "     a        =b"
    ],
    [
      "     a dddeeed=b",
      "     a  dddddd=b",
      "      a ddddddd=",
      "      a dddddddd",
      "      a dddddddd",
      "      a ddeeeddd",
      "      a dddddddd",
      "      a dddddddd",
      "      a dddddddd",
      "      a dddddddd",
      "      a ddeeeddd",
      "      a dddddddd",
      "      a dddddddd",
      "      a ddddddd=",
      "     a  dddddd=b",
      "     a dddeeed=b"
    ],
    [
      "     fg h     h ",
      "     fgghhhhhhhh",
      "      fgiiiiiiii",
      "      fgiiiiiiii",
      "      fgiiiiiiii",
      "      fgiiiiiiii",
      "      fgiiiiiiii",
      "      fgiiiiiiii",
      "      fgiiiiiiii",
      "      fgiiiiiiii",
      "      fgiiiiiiii",
      "      fgiiiiiiii",
      "      fgiiiiiiii",
      "      fgiiiiiiii",
      "     fgghhhhhhhh",
      "     fg h     h "
    ],
    [
      "jjkkkkglliiiiiii",
      "kkkkkkglliiiiiii",
      "kkkkkkkgmmmmmmmn",
      "       o pqrst u",
      "       o  w   x ",
      "       o    x   ",
      "       o y      ",
      "       o ABrCD  ",
      "       o pqrst  ",
      "       o  w yE  ",
      "       o        ",
      "       o  y x   ",
      "       o ABrCD F",
      "kkkkkkkgmmmmmmmn",
      "kkkkkkglliiiiiii",
      "jjkkkkglliiiiiii"
    ]
  ]
}