{
  "name": "multi_nuclearpowerplant_38_base6",
  "refpalette": "deceasedcraft:multi_nuclearpowerplant_38/multi_nuclearpowerplant_38_base6_palette",
  "xsize": 16,
  "zsize": 16,
  "slices": [
    [
      "a a bc de f     ",
      "   gbc de f     ",
      "   gbc de f     ",
      "ccccch de f     ",
      " i    ide f     ",
      "dddddddde f     ",
      "eeeeeeeee f     ",
      "jjjjjjjjk f     ",
      "jjjjjjjjk f     ",
      "lllllllll f     ",
      "ddddddddl f     ",
      " i    idl f     ",
      "ccccch dl f     ",
      "   bbc dl f     ",
      "   bbc dl f     ",
      "aaabbc dl f     "
    ],
    [
      "mmmmmhno        ",
      " aabbc o        ",
      " aabbc o        ",
      "ccccch o        ",
      "piq    o        ",
      "oooooooo        ",
      "                ",
      "                ",
      "                ",
      "                ",
      "oooooooo        ",
      "ris    o        ",
      "ccccch o        ",
      "aaabbc o        ",
      "aaabbc o        ",
      "mmmmmhno        "
    ],
    [
      "aa bbc t        ",
      "   gbc t        ",
      "   bbc t        ",
      "ccccch t        ",
      " i     t        ",
      "u uuuuu         ",
      "                ",
      "                ",
      "                ",
      "                ",
      "wwwwwww         ",
      " i     t        ",
      "ccccch t        ",
      "   bbc t        ",
      "   bbc t        ",
      "aaabbc t        "
    ],
    [
      " a gbc          ",
      "   gbc          ",
      "   gbc          ",
      "ccccch          ",
      " i              ",
      "                ",
      "                ",
      "                ",
      "                ",
      "                ",
      "                ",
      " i              ",
      "ccccch          ",
      "   bbc          ",
      "   bbc          ",
      "aaabbc          "
    ],
    [
      "ccccch          ",
      "ccccch          ",
      "cccxch          ",
      "hhhhhh          ",
      " i              ",
      "                ",
      "                ",
      "                ",
      "                ",
      "                ",
      "                ",
      " i              ",
      "hhhhhh          ",
      "cccxch          ",
      "ccccch          ",
      "ccccch          "
    ],
    [
      " y              ",
      " y A            ",
      " yB C           ",
      "iDEF            ",
      " i              ",
      "                ",
      "                ",
      "                ",
      "                ",
      "                ",
      "                ",
      " i              ",
      "iDIA            ",
      " yBJC           ",
      " y F            ",
      " y              "
    ]
  ]
}