{
  "name": "multi_nuclearpowerplant_38_ground",
  "refpalette": "deceasedcraft:multi_nuclearpowerplant_38/multi_nuclearpowerplant_38_ground_palette",
  "xsize": 16,
  "zsize": 16,
  "slices": [
    [
      "  abccdedddddddd",
      "  abecddeddddddd",
      "  abeccdeddddddd",
      "  abefcdeddddddd",
      "  abefcdeddddddd",
      "  abefcceddddddd",
      "  abeffceddddddd",
      "  abeffceddddddd",
      "  abeffceddddddd",
      "  abeffceddddddd",
      "  abefcceddddddd",
      "  abefcdeddddddd",
      "  abefcdeddddddd",
      "  abeccdeddddddd",
      "  abecddeddddddd",
      "  abccdedddddddd"
    ],
    [
      "    cczzzzzzzzzz",
      "     czzzzzfzzzz",
      "     cczzzzzzzzf",
      "     aczfzfzfzzz",
      "     acfzfzfzzff",
      "     accfffffffz",
      "     abczfffffff",
      "     abcffffzfff",
      "     abcffffffff",
      "     abcffffffff",
      "     accfffzffff",
      "     acfzfzfzzfz",
      "     aczzzfzfzzz",
      "     cczzzzzzzzf",
      "     czzzzzzzzzz",
      "    cczzzzzzzzzz"
    ],
    [
      "        g       ",
      "         g      ",
      "                ",
      "               h",
      "                ",
      "                ",
      "                ",
      "                ",
      "                ",
      "                ",
      "                ",
      "                ",
      "                ",
      "          g  i  ",
      "             j  ",
      "         g kkkk "
    ],
    [
      "                ",
      "                ",
      "                ",
      "                ",
      "                ",
      "                ",
      "                ",
      "                ",
      "                ",
      "                ",
      "                ",
      "                ",
      "                ",
      "                ",
      "           l  l ",
      "           mnom "
    ],
    [
      "                ",
      "                ",
      "                ",
      "                ",
      "                ",
      "                ",
      "                ",
      "                ",
      "                ",
      "                ",
      "                ",
      "                ",
      "                ",
      "                ",
      "           l  l ",
      "          pqrsmt"
    ],
    [
      "                ",
      "                ",
      "                ",
      "                ",
      "                ",
      "                ",
      "                ",
      "                ",
      "                ",
      "                ",
      "                ",
      "                ",
      "                ",
      "                ",
      "                ",
      "            uw  "
    ]
  ]
}