{
  "name": "street_highrise_office_straight_6",
  "refpalette": "deceasedcraft:streets/street_highrise_office_straight_6_palette",
  "xsize": 16,
  "zsize": 16,
  "slices": [
    [
      "aaaaaaaaaaaaaaaa",
      "vvvvvvvvvvvvvvvv",
      "vvvvvvvvvvvvvvvv",
      "aaaavvvvvvvvaaaa",
      "bbbbavvvvvvabbbb",
      "HHHHbaaaaaabHHHH",
      "HHHHHHHHHHHHHHHH",
      "HHHHHHHHHHHHHHHH",
      "HHHHHHHHHHHHHHHH",
      "HHHHHHHHHHHHHHHH",
      "HHHHbaaaaaabHHHH",
      "bbbbavvvvvvabbbb",
      "aaaavvvvvvvvaaaa",
      "vvvvvvvvvvvvvvvv",
      "vvvvvvvvvvvvvvvv",
      "aaaaaaaaaaaaaaaa"
    ],
    [
      "cccccccdcccccccc",
      "eefefeefeeeeeffe",
      "efeeeeeeeefeeeee",
      "cccceeeefeefcccc",
      "ggggceeeeeecgggg",
      "     cccccc     ",
      "       hh       ",
      " ii    hh    ii ",
      " gg    hh    gg ",
      "       hh       ",
      "     cccccc     ",
      "iiiiceefefeciiii",
      "ccccefeeeeeecccc",
      "efeeeefeeeeeefee",
      "eeefeeeeeeefeeef",
      "ccccccccdccccccc"
    ],
    [
      "       j        ",
      "                ",
      "                ",
      "                ",
      "                ",
      "                ",
      "                ",
      "                ",
      "                ",
      "                ",
      "                ",
      "                ",
      "                ",
      "                ",
      "                ",
      "        j       "
    ],
    [
      "       j        ",
      "                ",
      "                ",
      "                ",
      "                ",
      "                ",
      "                ",
      "                ",
      "                ",
      "                ",
      "                ",
      "                ",
      "                ",
      "                ",
      "                ",
      "        j       "
    ],
    [
      "       j        ",
      "                ",
      "                ",
      "                ",
      "                ",
      "                ",
      "                ",
      "                ",
      "                ",
      "                ",
      "                ",
      "                ",
      "                ",
      "                ",
      "                ",
      "        j       "
    ],
    [
      "       j        ",
      "                ",
      "       k        ",
      "                ",
      "                ",
      "                ",
      "                ",
      "                ",
      "                ",
      "                ",
      "                ",
      "                ",
      "                ",
      "        k       ",
      "                ",
      "        j       "
    ],
    [
      "       l        ",
      "       l        ",
      "       m        ",
      "                ",
      "                ",
      "                ",
      "                ",
      "                ",
      "                ",
      "                ",
      "                ",
      "                ",
      "                ",
      "        m       ",
      "        l       ",
      "        l       "
    ]
  ]
}