{
  "name": "street_highrise_office_straight_5",
  "refpalette": "deceasedcraft:streets/street_highrise_office_straight_5_palette",
  "xsize": 16,
  "zsize": 16,
  "slices": [
    [
      "aaaaaaaaaaaaaaaa",
      "vvvvvvvvvvvvvvvv",
      "vvvvvvvvvvvvvvvv",
      "aaaavvvvvvvvaaaa",
      "bbbbavvvvvvabbbb",
      "HHHHbaaaaaabHHHH",
      "HHHHHHHHHHHHHHHH",
      "HHHHHHHHHHHHHHHH",
      "HHHHHHHHHHHHHHHH",
      "HHHHHHHHHHHHHHHH",
      "HHHHbaaaaaabHHHH",
      "bbbbavvvvvvabbbb",
      "aaaavvvvvvvvaaaa",
      "vvvvvvvvvvvvvvvv",
      "vvvvvvvvvvvvvvvv",
      "aaaaaaaaaaaaaaaa"
    ],
    [
      "cccccccdcccccccc",
      "efefeeeeeeeeeeee",
      "eeefefefeeeeeffe",
      "cccceeggggefcccc",
      "hhhhceeefeechhhh",
      "     cccccc     ",
      "       ii       ",
      " jj    ii    jj ",
      " hh    ii    hh ",
      "       ii       ",
      "     cccccc     ",
      "jjjjcfefeefcjjjj",
      "cccceeggggeecccc",
      "efeeefeeeeefeeef",
      "eeeefeeeeeeefeee",
      "ccccccccdccccccc"
    ],
    [
      "       k        ",
      "                ",
      "                ",
      "                ",
      "                ",
      "                ",
      "                ",
      "                ",
      "                ",
      "                ",
      "                ",
      "                ",
      "                ",
      "                ",
      "                ",
      "        k       "
    ],
    [
      "       k        ",
      "                ",
      "                ",
      "                ",
      "                ",
      "                ",
      "                ",
      "                ",
      "                ",
      "                ",
      "                ",
      "                ",
      "                ",
      "                ",
      "                ",
      "        k       "
    ],
    [
      "       k        ",
      "                ",
      "                ",
      "                ",
      "                ",
      "                ",
      "                ",
      "                ",
      "                ",
      "                ",
      "                ",
      "                ",
      "                ",
      "                ",
      "                ",
      "        k       "
    ],
    [
      "       k        ",
      "                ",
      "       l        ",
      "                ",
      "                ",
      "                ",
      "                ",
      "                ",
      "                ",
      "                ",
      "                ",
      "                ",
      "                ",
      "        l       ",
      "                ",
      "        k       "
    ],
    [
      "       m        ",
      "       m        ",
      "       n        ",
      "                ",
      "                ",
      "                ",
      "                ",
      "                ",
      "                ",
      "                ",
      "                ",
      "                ",
      "                ",
      "        n       ",
      "        m       ",
      "        m       "
    ]
  ]
}