{
  "name": "street_highrise_office_straight",
  "refpalette": "deceasedcraft:streets/street_highrise_office_straight_palette",
  "xsize": 16,
  "zsize": 16,
  "slices": [
    [
      "aaaaaaaaaaaaaaaa",
      "vvvvvvvvvvvvvvvv",
      "vvvvvvvvvvvvvvvv",
      "aaaaaaaaaaaaaaaa",
      "bbbbbbbbbbbbbbbb",
      "HHHHHHHHHHHHHHHH",
      "HHHHHHHHHHHHHHHH",
      "HHHHHHHHHHHHHHHH",
      "HHHHHHHHHHHHHHHH",
      "HHHHHHHHHHHHHHHH",
      "HHHHHHHHHHHHHHHH",
      "bbbbbbbbbbbbbbbb",
      "aaaaaaaaaaaaaaaa",
      "vvvvvvvvvvvvvvvv",
      "vvvvvvvvvvvvvvvv",
      "aaaaaaaaaaaaaaaa"
    ],
    [
      "cccccccdcccccccc",
      "efeeefeeeeffeefe",
      "eeffeeefeeeeeefe",
      "cccccccgcccccccc",
      "hhhhhhhhhhhhhhhh",
      "                ",
      "                ",
      " ii  ii  ii  ii ",
      " hh  hh  hh  hh ",
      "                ",
      "                ",
      "iiiiiiiiiiiiiiii",
      "ccccccccjccccccc",
      "feeeffeeefeeffee",
      "eefeeeefefeeeeef",
      "ccccccccdccccccc"
    ],
    [
      "       k        ",
      "                ",
      "                ",
      "                ",
      "                ",
      "                ",
      "                ",
      "                ",
      "                ",
      "                ",
      "                ",
      "                ",
      "                ",
      "                ",
      "                ",
      "        k       "
    ],
    [
      "       k        ",
      "                ",
      "                ",
      "                ",
      "                ",
      "                ",
      "                ",
      "                ",
      "                ",
      "                ",
      "                ",
      "                ",
      "                ",
      "                ",
      "                ",
      "        k       "
    ],
    [
      "       k        ",
      "                ",
      "                ",
      "                ",
      "                ",
      "                ",
      "                ",
      "                ",
      "                ",
      "                ",
      "                ",
      "                ",
      "                ",
      "                ",
      "                ",
      "        k       "
    ],
    [
      "       k        ",
      "                ",
      "       l        ",
      "                ",
      "                ",
      "                ",
      "                ",
      "                ",
      "                ",
      "                ",
      "                ",
      "                ",
      "                ",
      "        l       ",
      "                ",
      "        k       "
    ],
    [
      "       m        ",
      "       m        ",
      "       n        ",
      "                ",
      "                ",
      "                ",
      "                ",
      "                ",
      "                ",
      "                ",
      "                ",
      "                ",
      "                ",
      "        n       ",
      "        m       ",
      "        m       "
    ]
  ]
}