{
  "name": "street_highrise_office_none",
  "refpalette": "deceasedcraft:streets/street_highrise_office_none_palette",
  "xsize": 16,
  "zsize": 16,
  "slices": [
    [
      "aaaaaaaaaaaaaaaa",
      "aavvvvvvvvvvvvaa",
      "avvvvvvvvvvvvvva",
      "avvvaaaaaaaavvva",
      "avvaabbbbbbaavva",
      "avvabbccccbbavva",
      "avvabccbbccbavva",
      "avvabcbbbbcbavva",
      "avvabcbbbbcbavva",
      "avvabccbbccbavva",
      "avvabbccccbbavva",
      "avvaabbbbbbaavva",
      "avvvaaaaaaaavvva",
      "avvvvvvvvvvvvvva",
      "aavvvvvvvvvvvvaa",
      "aaaaaaaaaaaaaaaa"
    ],
    [
      " dddddddddddddd ",
      "ddeeeeeeeeeeeedd",
      "deeeeeeeeeeeeeed",
      "deeeddddddddeeed",
      "deedaffffffadeed",
      "deedffggggffdeed",
      "deedfgg  ggfdeed",
      "deedfg    gfdeed",
      "deedfg    gfdeed",
      "deedfgg  ggfdeed",
      "deedffggggffdeed",
      "deedaffffffadeed",
      "deeeddddddddeeed",
      "deeeeeeeeeeeeeed",
      "ddeeeeeeeeeeeedd",
      " dddddddddddddd "
    ],
    [
      "                ",
      "                ",
      "                ",
      "                ",
      "    h      h    ",
      "      gggg      ",
      "     gg  gg     ",
      "     g    g     ",
      "     g    g     ",
      "     gg  gg     ",
      "      gggg      ",
      "    h      h    ",
      "                ",
      "                ",
      "                ",
      "                "
    ],
    [
      "                ",
      "                ",
      "                ",
      "                ",
      "    i      i    ",
      "                ",
      "                ",
      "                ",
      "                ",
      "                ",
      "                ",
      "    i      i    ",
      "                ",
      "                ",
      "                ",
      "                "
    ],
    [
      "                ",
      "                ",
      "                ",
      "                ",
      "    j      j    ",
      "                ",
      "                ",
      "                ",
      "                ",
      "                ",
      "                ",
      "    j      j    ",
      "                ",
      "                ",
      "                ",
      "                "
    ]
  ]
}