{
  "name": "street_highrise_office_all_3",
  "refpalette": "deceasedcraft:streets/street_highrise_office_all_3_palette",
  "xsize": 16,
  "zsize": 16,
  "slices": [
    [
      "avvabHHHHHHbavva",
      "vvvabHHHHHHbavvv",
      "vvvacddcHHHbavvv",
      "aaabHHHHHHHHbaaa",
      "bbbHeeeefeeeHcbb",
      "HHHHfeHHHHefHcHH",
      "HHHHfHeHHfHeHdHH",
      "HHHHeHHefHHeHdHH",
      "HHcHeHHeeHHeHHHH",
      "HHdHfHeHHeHeHHHH",
      "HHdHfeHHHHfeHHHH",
      "bbcHeeeffeeeHbbb",
      "aaabHHHHHHHHbaaa",
      "vvvabHHHdcdcavvv",
      "vvvabHHHHHHbavvv",
      "avvabHHHHHHbavva"
    ],
    [
      "ghhgi      jgkhg",
      "khkgi  ji  jgkhh",
      "hhkg    i  jlhkh",
      "gglmn      opggg",
      "qqqn        o qq",
      "                ",
      "                ",
      " rr           r ",
      " q           qq ",
      "                ",
      "                ",
      "rr s        trrr",
      "gggus      twlgg",
      "hhhli  j    ghhh",
      "hkhgi  ji  jgkkh",
      "ghhgi      jghkg"
    ],
    [
      "                ",
      "                ",
      "            x   ",
      "  x             ",
      "                ",
      "                ",
      "                ",
      "                ",
      "                ",
      "                ",
      "                ",
      "                ",
      "             x  ",
      "   x            ",
      "                ",
      "                "
    ],
    [
      "                ",
      "                ",
      "            x   ",
      "  x             ",
      "                ",
      "                ",
      "                ",
      "                ",
      "                ",
      "                ",
      "                ",
      "                ",
      "             x  ",
      "   x            ",
      "                ",
      "                "
    ],
    [
      "                ",
      "                ",
      "            x   ",
      "  xy        y   ",
      "                ",
      "                ",
      "                ",
      "                ",
      "                ",
      "                ",
      "                ",
      "                ",
      "   y        yx  ",
      "   x            ",
      "                ",
      "                "
    ],
    [
      "                ",
      "                ",
      "            x   ",
      "  xA        A   ",
      "                ",
      "                ",
      "                ",
      "                ",
      "                ",
      "                ",
      "                ",
      "                ",
      "   A        Bx  ",
      "   x            ",
      "                ",
      "                "
    ],
    [
      "                ",
      "                ",
      "            x   ",
      "  xC        C   ",
      "                ",
      "                ",
      "                ",
      "                ",
      "                ",
      "                ",
      "                ",
      "                ",
      "   C        Cx  ",
      "   x            ",
      "                ",
      "                "
    ]
  ]
}