{
  "name": "street_highrise_office_all_police",
  "refpalette": "deceasedcraft:streets/street_highrise_office_all_police_palette",
  "xsize": 16,
  "zsize": 16,
  "slices": [
    [
      "avvabHHHHHHbavva",
      "vvvabHHHHHHbavvv",
      "vvvvccccHHHbvvvv",
      "aavbHHHHHHHHbvaa",
      "bbbHdeeddeeeHcbb",
      "HHHHdeHHHHdeHcHH",
      "HHHHeHeHHeHeHcHH",
      "HHHHeHHeeHHeHcHH",
      "HHcHeHHdeHHdHHHH",
      "HHcHdHeHHdHdHHHH",
      "HHcHeeHHHHdeHHHH",
      "bbcHedddedddHbbb",
      "aavbHHHHHHHHbvaa",
      "vvvvbHHHccccvvvv",
      "vvvabHHHHHHbavvv",
      "avvabHHHHHHbavva"
    ],
    [
      "fggfh      ifgjf",
      "jggfh  ih  ifggj",
      "gj      h  ik gg",
      "ffklm      no ff",
      "pppm        n pp",
      "                ",
      "                ",
      " qq           q ",
      " p    r str  pp ",
      "    uwxwyyxA    ",
      "    BCDEFIJK    ",
      "qq LuwxwyyxAMqqq",
      "ff NL O PQOMRkff",
      "gg kS  i      jg",
      "gjjfhTUiU VUfggg",
      "fggfh      ifjgf"
    ],
    [
      "                ",
      "                ",
      "            W   ",
      "  W             ",
      "                ",
      "                ",
      "                ",
      "                ",
      "         t      ",
      "     XXY@yZ01   ",
      "     XYY@2w0    ",
      "     XXY@yZ03   ",
      "         Q   W  ",
      "   W            ",
      "                ",
      "                "
    ],
    [
      "                ",
      "                ",
      "            W   ",
      "  W             ",
      "                ",
      "                ",
      "                ",
      "                ",
      "                ",
      "        4       ",
      "        XXX     ",
      "        5       ",
      "             W  ",
      "   W            ",
      "                ",
      "                "
    ],
    [
      "                ",
      "                ",
      "            W   ",
      "  W6        6   ",
      "                ",
      "                ",
      "                ",
      "                ",
      "                ",
      "                ",
      "                ",
      "                ",
      "   6        6W  ",
      "   W            ",
      "                ",
      "                "
    ],
    [
      "                ",
      "                ",
      "            W   ",
      "  W7        8   ",
      "                ",
      "                ",
      "                ",
      "                ",
      "                ",
      "                ",
      "                ",
      "                ",
      "   8        8W  ",
      "   W            ",
      "                ",
      "                "
    ],
    [
      "                ",
      "                ",
      "            W   ",
      "  W9        9   ",
      "                ",
      "                ",
      "                ",
      "                ",
      "                ",
      "                ",
      "                ",
      "                ",
      "   9        9W  ",
      "   W            ",
      "                ",
      "                "
    ]
  ]
}