{
  "name": "street_highrise_hotel_straight_bus_stop",
  "refpalette": "deceasedcraft:streets/street_highrise_hotel_straight_bus_stop_palette",
  "xsize": 16,
  "zsize": 16,
  "slices": [
    [
      "aaaaaaaaaaaaaaaa",
      "abaabaabbaabaaba",
      "aaaaaaaaaaaaaaaa",
      "cccccccccccccccc",
      "dddddddddddddddd",
      "eeeeeeeeeeeeeeee",
      "HHHHHHHHHHHHHHHH",
      "HHHHHHHHHHHHHHHH",
      "HHHHHHHHHHHHHHHH",
      "HHHHHHHHHHHHHHHH",
      "eeeeHHHHHHHHeeee",
      "dddeeeeeeeeeeddd",
      "cccccaaaaaaccccc",
      "aaaaaaaaaaaaaaaa",
      "abaabaabbaabaaba",
      "aaaaaaaaaaaaaaaa"
    ],
    [
      "                ",
      "                ",
      "                ",
      "ffghhgffffghhgff",
      "iiiiiiiiiiiiiiii",
      "jjjjjjjjjjjjjjjj",
      "kkkkkkkkkkkkkkkk",
      "                ",
      "                ",
      "llllmmmmmmmmllll",
      "jjjj        jjjj",
      "iiijj      jjiii",
      "ffghno  ooonhgff",
      "   pqrrrrrrqs   ",
      "   pqqqqqqqqs   ",
      "   pqqqqqqqqs   "
    ],
    [
      "                ",
      "                ",
      "                ",
      "    t      t    ",
      "iiiiiiiiiiiiiiii",
      "                ",
      "                ",
      "                ",
      "                ",
      "                ",
      "                ",
      "ii            ii",
      "    toooooou    ",
      "   owoooooowo   ",
      "   oo  oo  oo   ",
      "   owxxooxxwo   "
    ],
    [
      "                ",
      "                ",
      "                ",
      "                ",
      "                ",
      "                ",
      "                ",
      "                ",
      "                ",
      "                ",
      "                ",
      "                ",
      "   oooooooooo   ",
      "   owoooooowo   ",
      "   oyooooooyo   ",
      "   ow      wo   "
    ],
    [
      "                ",
      "                ",
      "                ",
      "                ",
      "                ",
      "                ",
      "                ",
      "                ",
      "                ",
      "                ",
      "                ",
      "                ",
      "   oooooooooo   ",
      "   owwwwwwwwo   ",
      "   AwoooooowA   ",
      "   BCCCCCCCCB   "
    ],
    [
      "                ",
      "                ",
      "                ",
      "                ",
      "                ",
      "                ",
      "                ",
      "                ",
      "                ",
      "                ",
      "                ",
      "                ",
      "   DDDDDDDDDD   ",
      "   DEEEEEEEED   ",
      "   DEEEEEEEED   ",
      "    oooooooo    "
    ]
  ]
}