{
  "name": "street_highrise_office_all",
  "refpalette": "deceasedcraft:streets/street_highrise_office_all_palette",
  "xsize": 16,
  "zsize": 16,
  "slices": [
    [
      "avvabHHHHHHbavva",
      "vvvabHHHHHHbavvv",
      "vvvvccccccdcvvvv",
      "aavbHcHHHHcHbvaa",
      "bbcHHHcHHdHHHcbb",
      "HHdcHHHccHHHccHH",
      "HHcHcHHHHHHcHcHH",
      "HHcHHcHHHHcHHcHH",
      "HHcHHcHHHHdHHcHH",
      "HHcHcHHHHHHdHcHH",
      "HHccHHHcdHHHcdHH",
      "bbcHHHcHHcHHHcbb",
      "aavbHdHHHHdHbvaa",
      "vvvvccdcccccvvvv",
      "vvvabHHHHHHbavvv",
      "avvabHHHHHHbavva"
    ],
    [
      "efgeh      ieffe",
      "fgfeh      iegff",
      "ff            gf",
      "eej           ee",
      "kk            kk",
      "                ",
      "                ",
      "                ",
      "                ",
      "                ",
      "                ",
      "ll            ll",
      "ee           jee",
      "ff            ff",
      "gfgeh      iefgf",
      "egfeh      ieffe"
    ],
    [
      "                ",
      "                ",
      "                ",
      "  m             ",
      "                ",
      "                ",
      "                ",
      "                ",
      "                ",
      "                ",
      "                ",
      "                ",
      "             m  ",
      "                ",
      "                ",
      "                "
    ],
    [
      "                ",
      "                ",
      "                ",
      "  m             ",
      "                ",
      "                ",
      "                ",
      "                ",
      "                ",
      "                ",
      "                ",
      "                ",
      "             m  ",
      "                ",
      "                ",
      "                "
    ],
    [
      "                ",
      "                ",
      "                ",
      "  mn            ",
      "                ",
      "                ",
      "                ",
      "                ",
      "                ",
      "                ",
      "                ",
      "                ",
      "            om  ",
      "                ",
      "                ",
      "                "
    ],
    [
      "                ",
      "                ",
      "  o             ",
      "  mp            ",
      "                ",
      "                ",
      "                ",
      "                ",
      "                ",
      "                ",
      "                ",
      "                ",
      "            pm  ",
      "             n  ",
      "                ",
      "                "
    ],
    [
      "                ",
      "                ",
      "  q             ",
      "  mr            ",
      "                ",
      "                ",
      "                ",
      "                ",
      "                ",
      "                ",
      "                ",
      "                ",
      "            qm  ",
      "             r  ",
      "                ",
      "                "
    ]
  ]
}