{
  "name": "street_highrise_office_bend",
  "refpalette": "deceasedcraft:streets/street_highrise_office_bend_palette",
  "xsize": 16,
  "zsize": 16,
  "slices": [
    [
      "avvabHHHHHHbavva",
      "vvvabHHHHHHbavva",
      "vvvabHHHHHHbavva",
      "aaaabHHHHHHbavva",
      "bbbbHHHHHHHbavva",
      "HHHHHHHHHHHbavva",
      "HHHHHHHHHHHbavva",
      "HHHHHHHHHHHbavva",
      "HHHHHHHHHHHbavva",
      "HHHHHHHHHHbaavva",
      "HHHHHHHHHbaccvva",
      "bbbbbbbbbacccvva",
      "aaaaaaaaaaccvvva",
      "vvvvvvvvvvvvvvva",
      "vvvvvvvvvvvvvvaa",
      "aaaaaaaaaaaaaaaa"
    ],
    [
      "defdg      hdeed",
      "eeedg  hg  hdefd",
      "efedg  hg  hdfed",
      "dddig      hdeed",
      "jjjjk      hdefd",
      "       hg  hdeed",
      "       hl  hdeed",
      " mm  mm    hnefo",
      " jj  jp   qrdeed",
      "         qrddeed",
      "        qrd  fed",
      "mmmmmmmmrd s eed",
      "ddddddddtd  eeed",
      "eeeeeffeeeeefefd",
      "eeefeeeefeeeeedd",
      "ddddddddodddddd "
    ],
    [
      "                ",
      "                ",
      "                ",
      "                ",
      "                ",
      "                ",
      "                ",
      "               u",
      "                ",
      "                ",
      "                ",
      "           ~    ",
      "                ",
      "                ",
      "                ",
      "        u       "
    ],
    [
      "                ",
      "                ",
      "                ",
      "                ",
      "                ",
      "                ",
      "                ",
      "               u",
      "                ",
      "                ",
      "                ",
      "                ",
      "                ",
      "                ",
      "                ",
      "        u       "
    ],
    [
      "                ",
      "                ",
      "                ",
      "                ",
      "                ",
      "                ",
      "                ",
      "               u",
      "                ",
      "                ",
      "                ",
      "                ",
      "                ",
      "                ",
      "                ",
      "        u       "
    ],
    [
      "                ",
      "                ",
      "                ",
      "                ",
      "                ",
      "                ",
      "                ",
      "             w u",
      "                ",
      "                ",
      "                ",
      "                ",
      "                ",
      "        w       ",
      "                ",
      "        u       "
    ],
    [
      "                ",
      "                ",
      "                ",
      "                ",
      "                ",
      "                ",
      "                ",
      "             xyy",
      "                ",
      "                ",
      "                ",
      "                ",
      "                ",
      "        A       ",
      "        y       ",
      "        y       "
    ]
  ]
}