{
  "name": "street_retail_district_straight_display",
  "refpalette": "deceasedcraft:streets/street_retail_district_straight_display_palette",
  "xsize": 16,
  "zsize": 16,
  "slices": [
    [
      "aaaaaaaaaaaaaaaa",
      "abbaabbaabbaabba",
      "aaaaaaaaaaaaaaaa",
      "cccddccccccddccc",
      "eeeffeeeeeeffeee",
      "gggggggggggggggg",
      "HHHHHHHHHHHHHHHH",
      "HHHHHHHHHHHHHHHH",
      "HHHHHHHHHHHHHHHH",
      "HHHHHHHHHHHHHHHH",
      "gggggggggggggggg",
      "eeeffeeeeeeffeee",
      "cccddccccccddccc",
      "aaaaaaaaaaaaaaaa",
      "abbaabbaabbaabba",
      "aaaaaaaaaaaaaaaa"
    ],
    [
      "                ",
      "                ",
      "                ",
      "                ",
      "hhhiihhhhhhjjhhh",
      "kkkkkkkkkkkkkkkk",
      "llllllllllllllll",
      "                ",
      "                ",
      "mmmmmmmmmmmmmmmm",
      "kkkkkkkkkkkkkkkk",
      "hhhjjhhhhhhnnhhh",
      "                ",
      "                ",
      "                ",
      "                "
    ],
    [
      "                ",
      "                ",
      "                ",
      "           oo   ",
      "           jj   ",
      "           pp   ",
      "                ",
      "                ",
      "                ",
      "                ",
      "   oo           ",
      "   jj           ",
      "   pp           ",
      "                ",
      "                ",
      "                "
    ],
    [
      "                ",
      "                ",
      "                ",
      "           oo   ",
      "           jj   ",
      "           pp   ",
      "                ",
      "                ",
      "                ",
      "                ",
      "   oo           ",
      "   jj           ",
      "   pp           ",
      "                ",
      "                ",
      "                "
    ],
    [
      "                ",
      "                ",
      "                ",
      "           oo   ",
      "           jj   ",
      "           pp   ",
      "                ",
      "                ",
      "                ",
      "                ",
      "   oo           ",
      "   jj           ",
      "   pp           ",
      "                ",
      "                ",
      "                "
    ]
  ]
}