{
  "name": "street_highrise_office_t_shape_bus_stop",
  "refpalette": "deceasedcraft:streets/street_highrise_office_t_shape_bus_stop_palette",
  "xsize": 16,
  "zsize": 16,
  "slices": [
    [
      "avvabHHHHHHbavva",
      "vvvabHHHHHHbavvv",
      "vvvabHHHHHHbavvv",
      "aaaabHHHHHHbaaaa",
      "bbbbHHHHHHHHbbbb",
      "HHHHHHHHHHHHHHHH",
      "HHHHHHHHHHHHHHHH",
      "HHHHHHHHHHHHHHHH",
      "HHHHHHHHHHHHHHHH",
      "HHHHHHHHHHHHHHHH",
      "HHHHbaaaaaabHHHH",
      "bbbbavvvvvvabbbb",
      "aaaaavvvvvvvaaaa",
      "vvvvvvvvvvvvvvvv",
      "vvvvvvvvvvvvvvvv",
      "aaaaaaaaaaaaaaaa"
    ],
    [
      "cddce      fcddc",
      "dddce  fe  fcgdd",
      "dgdce  fe  fcgdd",
      "ccche      fhccc",
      "iiiij      kiiii",
      "                ",
      "                ",
      " ll          ll ",
      " im          ni ",
      "    ollllllp    ",
      "   oqccccccrp   ",
      "lllqcvdgdgvcrlll",
      "ccccgvvvvvvdcccc",
      "gddddvvvvvvgdgdg",
      "ddgddggddgdddddd",
      "cccccccccccccccc"
    ],
    [
      "                ",
      "                ",
      "                ",
      "                ",
      "                ",
      "                ",
      "                ",
      "                ",
      "                ",
      "                ",
      "                ",
      "     sttttst    ",
      "        t tt t  ",
      "    usw  wsxtt  ",
      "    tyyyyyy  t  ",
      "                "
    ],
    [
      "                ",
      "                ",
      "                ",
      "                ",
      "                ",
      "                ",
      "                ",
      "                ",
      "                ",
      "                ",
      "                ",
      "    tsttttsttt  ",
      "      ttt  t t  ",
      "    usAAAAsx t  ",
      "    tyyyyyy  t  ",
      "                "
    ],
    [
      "                ",
      "                ",
      "                ",
      "                ",
      "                ",
      "                ",
      "                ",
      "                ",
      "                ",
      "                ",
      "                ",
      "    tst ttsttt  ",
      "             t  ",
      "    usB  Bsx    ",
      "     yyyyyy     ",
      "                "
    ],
    [
      "                ",
      "                ",
      "                ",
      "                ",
      "                ",
      "                ",
      "                ",
      "                ",
      "                ",
      "                ",
      "                ",
      "    CCCCCCCC    ",
      "    DDDDDDDD    ",
      "    CCCCCCCC    ",
      "     t    ttt   ",
      "                "
    ]
  ]
}