{
  "name": "street_highrise_hotel_full",
  "refpalette": "deceasedcraft:streets/street_highrise_hotel_full_palette",
  "xsize": 16,
  "zsize": 16,
  "slices": [
    [
      "aabbbbbbbbbbbbaa",
      "abbbcbbccbbcbbba",
      "bbcbbbbbbbbbbcbb",
      "bbbbbaaaaaabbbbb",
      "bcbbaddddddabbcb",
      "bbbaddeeeeddabbb",
      "bbbadeeeeeedabbb",
      "bcbadeeeeeedabcb",
      "bcbadeeeeeedabcb",
      "bbbadeeeeeedabbb",
      "bbbaddeeeeddabbb",
      "bcbbaddddddabbcb",
      "bbbbbaaaaaabbbbb",
      "bbcbbbbbbbbbbcbb",
      "abbbcbbccbbcbbba",
      "aabbbbbbbbbbbbaa"
    ],
    [
      "fg            gf",
      "h              i",
      "                ",
      "     jkkkkj     ",
      "    lmmmmmml    ",
      "   jnoppppoqj   ",
      "   knppppppqk   ",
      "   knppppppqk   ",
      "   knppppppqk   ",
      "   knppppppqk   ",
      "   jnoppppoqj   ",
      "    lrrrrrrl    ",
      "     jkkkkj     ",
      "                ",
      "h              i",
      "fs            sf"
    ],
    [
      "t              t",
      "                ",
      "                ",
      "                ",
      "    u      u    ",
      "     wxy Aw     ",
      "     ABC        ",
      "          A     ",
      "       A        ",
      "      A  A      ",
      "     w  A w     ",
      "    u      u    ",
      "                ",
      "                ",
      "                ",
      "D              t"
    ],
    [
      "                ",
      "                ",
      "                ",
      "                ",
      "    E      E    ",
      "                ",
      "                ",
      "                ",
      "                ",
      "                ",
      "                ",
      "    E      E    ",
      "                ",
      "                ",
      "                ",
      "                "
    ]
  ]
}