{
  "name": "street_highrise_hotel_all",
  "refpalette": "deceasedcraft:streets/street_highrise_hotel_all_palette",
  "xsize": 16,
  "zsize": 16,
  "slices": [
    [
      "aaabcdHHHHdcbaaa",
      "aeabcdHHHHdcbaea",
      "aaaaaaHHHHaaaaaa",
      "bbaeaaHHHHaaeabb",
      "ccaaddHHHHddaacc",
      "ddaadHHHHHHdaadd",
      "HHHHHHHHHHHHHHHH",
      "HHHHHHHHHHHHHHHH",
      "HHHHHHHHHHHHHHHH",
      "HHHHHHHHHHHHHHHH",
      "ddaadHHHHHHdaadd",
      "ccaaddHHHHddaacc",
      "bbaeaaHHHHaaeabb",
      "aaaaaaHHHHaaaaaa",
      "aeabcdHHHHdcbaea",
      "aaabcdHHHHdcbaaa"
    ],
    [
      "   fghi  jhgf   ",
      "   kghl  mhgk   ",
      "      nnnn      ",
      "fk    nnnn    kf",
      "gg  hho  phh  gg",
      "hh  hqr  sth  hh",
      "uwxxyr    swAAyu",
      "  xx        AA  ",
      "  xx        AA  ",
      "BCxxDE    FCAADB",
      "hh  hIE  FJh  hh",
      "gg  hhl  mhh  gg",
      "fk    KKKK    kf",
      "      KKKK      ",
      "   kgho  phgk   ",
      "   fghi  jhgf   "
    ],
    [
      "    g      g    ",
      "   L        M   ",
      "                ",
      " M            N ",
      "g              g",
      "                ",
      "                ",
      "                ",
      "                ",
      "                ",
      "                ",
      "g              g",
      " M            L ",
      "                ",
      "   N        M   ",
      "    g      g    "
    ]
  ]
}