{
  "name": "street_highrise_office_bend_2",
  "refpalette": "deceasedcraft:streets/street_highrise_office_bend_2_palette",
  "xsize": 16,
  "zsize": 16,
  "slices": [
    [
      "avvabHHHHHHbavva",
      "vvvabHHHHHHbavva",
      "vvvabHHHHHHbavva",
      "aaaabHHHHHHbavva",
      "bbbbHHHHHHHbavva",
      "HHHHHHHHHHHbavva",
      "HHHHHHHHHHHbavva",
      "HHHHHHHHHHHbavva",
      "HHHHHHHHHHHbavva",
      "HHHHHHHHHHHbavva",
      "HHHHHHHHHHbbavva",
      "bbbbbbbbbbbaavva",
      "aaaaaaaaaaaavvva",
      "vvvvvvvvvvvvvvva",
      "vvvvvvvvvvvvvvaa",
      "aaaaaaaaaaaaaaaa"
    ],
    [
      "cdecf      gcddc",
      "dddcf  gf  gcdec",
      "dedcf  gf  gcedc",
      "ccchf      gcddc",
      "iiiij      gcdec",
      "       gf  gcddc",
      "       gk  gcddc",
      " ll  ll    gmden",
      " ii  io    gcddc",
      "           gcddc",
      "           pcedc",
      "lllllllllpqccddc",
      "ccccccccrcccdddc",
      "dddddeeddddeddec",
      "dddeddddedddddcc",
      "ccccccccncccccc "
    ],
    [
      "                ",
      "                ",
      "                ",
      "                ",
      "                ",
      "                ",
      "                ",
      "               s",
      "                ",
      "                ",
      "                ",
      "                ",
      "                ",
      "                ",
      "                ",
      "        s       "
    ],
    [
      "                ",
      "                ",
      "                ",
      "                ",
      "                ",
      "                ",
      "                ",
      "               s",
      "                ",
      "                ",
      "                ",
      "                ",
      "                ",
      "                ",
      "                ",
      "        s       "
    ],
    [
      "                ",
      "                ",
      "                ",
      "                ",
      "                ",
      "                ",
      "                ",
      "               s",
      "                ",
      "                ",
      "                ",
      "                ",
      "                ",
      "                ",
      "                ",
      "        s       "
    ],
    [
      "                ",
      "                ",
      "                ",
      "                ",
      "                ",
      "                ",
      "                ",
      "             t s",
      "                ",
      "                ",
      "                ",
      "                ",
      "                ",
      "                ",
      "                ",
      "        s       "
    ],
    [
      "                ",
      "                ",
      "                ",
      "                ",
      "                ",
      "                ",
      "                ",
      "             uww",
      "                ",
      "                ",
      "                ",
      "                ",
      "                ",
      "        u       ",
      "        w       ",
      "        w       "
    ]
  ]
}