{
  "name": "street_highrise_hotel_bend",
  "refpalette": "deceasedcraft:streets/street_highrise_hotel_bend_palette",
  "xsize": 16,
  "zsize": 16,
  "slices": [
    [
      "aaabcdHHHHdcbaaa",
      "aeabcdHHHHdcbaea",
      "aaabcdHHHHdcbaaa",
      "bbbccdHHHHdcbaaa",
      "ccccddHHHHdcbaea",
      "dddddHHHHHdcbaaa",
      "HHHHHHHHHHdcbaaa",
      "HHHHHHHHHHdcbaea",
      "HHHHHHHHHHdcbaaa",
      "HHHHHHHHHddcbaaa",
      "ddddddddddccbaea",
      "cccccccccccbbaaa",
      "bbbbbbbbbbbbaaaa",
      "aaaaaaaaaaaaaeaa",
      "aeaaeaaeaaeaaaab",
      "aaaaaaaaaaaaaabb"
    ],
    [
      "   fghi  jhgf   ",
      "   fghi  jhgf   ",
      "   kghi  jhgk   ",
      "ffklghi  jhgm   ",
      "gggghhi  jhgm   ",
      "hhhhhno  jhgk   ",
      "pppppo   jhgf   ",
      "         jhgf   ",
      "        qrhgf   ",
      "ssssssssrhhgf   ",
      "hhhhhhhhhhggk   ",
      "ggggggggggglm   ",
      "ffkttkffffkt    ",
      "                ",
      "               u",
      "              tl"
    ],
    [
      "    g      g    ",
      "    g      g    ",
      "    g      g    ",
      "   wg      g    ",
      "gggg       gx   ",
      "           g    ",
      "           g    ",
      "           g    ",
      "           g    ",
      "           g    ",
      "          gg    ",
      "gggggggggggx    ",
      "    y           ",
      "                ",
      "                ",
      "               y"
    ]
  ]
}