{
  "name": "street_highrise_hotel_all_2",
  "refpalette": "deceasedcraft:streets/street_highrise_hotel_all_2_palette",
  "xsize": 16,
  "zsize": 16,
  "slices": [
    [
      "aaabcdHHHHdcbaaa",
      "aeaccdHHHHdccaea",
      "aaacddHHHHddcaaa",
      "bccddHHHHHHddccb",
      "ccddHHHHHHHHddcc",
      "dddHHHddddHHHddd",
      "HHHHHddbbddHHHHH",
      "HHHHHdbbbbdHHHHH",
      "HHHHHdbbbbdHHHHH",
      "HHHHHddbbddHHHHH",
      "dddHHHddddHHHddd",
      "ccddHHHHHHHHddcc",
      "bccddHHHHHHddccb",
      "aaacddHHHHddcaaa",
      "aeaccdHHHHdccaea",
      "aaabcdHHHHdcbaaa"
    ],
    [
      "   fghi  jhgf   ",
      "   gghi  jhgg   ",
      "   ghhi  jhhg   ",
      "fgghklm  nlohggf",
      "gghkm      nohgg",
      "hhhi   hh   jhhh",
      "lllm  pqrp  nlll",
      "     hqsqrh     ",
      "     hqssth     ",
      "uuuw  pqrp  xuuu",
      "hhhi   hh   jhhh",
      "gghyw      xAhgg",
      "fgghyuw  xuAhggf",
      "   ghhi  jhhg   ",
      "   gghi  jhgg   ",
      "   fghi  jhgf   "
    ],
    [
      "    g      g    ",
      "   gg      gg   ",
      "   g        g   ",
      " gg          gg ",
      "gg            gg",
      "                ",
      "      Br C      ",
      "      rqr       ",
      "      qss       ",
      "      Dq B      ",
      "                ",
      "gg            gg",
      " gg          gg ",
      "   g        g   ",
      "   gg      gg   ",
      "    g      g    "
    ],
    [
      "                ",
      "                ",
      "                ",
      "                ",
      "                ",
      "                ",
      "      D         ",
      "       r        ",
      "      rEs       ",
      "       r B      ",
      "                ",
      "                ",
      "                ",
      "                ",
      "                ",
      "                "
    ],
    [
      "                ",
      "                ",
      "                ",
      "                ",
      "                ",
      "                ",
      "                ",
      "                ",
      "        F       ",
      "         C      ",
      "                ",
      "                ",
      "                ",
      "                ",
      "                ",
      "                "
    ]
  ]
}