{
  "name": "street_highrise_hotel_all_3",
  "refpalette": "deceasedcraft:streets/street_highrise_hotel_all_3_palette",
  "xsize": 16,
  "zsize": 16,
  "slices": [
    [
      "aaabcdHHHHdcbaaa",
      "aeaccdHHHHdccaea",
      "aaacddHHHHddcaaa",
      "bccddHHHHHHddccb",
      "ccddHHHHHHHHddcc",
      "dddHHHddddHHHddd",
      "HHHHHddbbddHHHHH",
      "HHHHHdbbbbdHHHHH",
      "HHHHHdbbbbdHHHHH",
      "HHHHHddbbddHHHHH",
      "dddHHHddddHHHddd",
      "ccddHHHHHHHHddcc",
      "bccddHHHHHHddccb",
      "aaacddHHHHddcaaa",
      "aeaccdHHHHdccaea",
      "aaabcdHHHHdcbaaa"
    ],
    [
      "   fghi  jhgf   ",
      "   gghi  jhgg   ",
      "   ghhi  jhhg   ",
      "fgghklm  nlohggf",
      "gghkm      nohgg",
      "hhhi        jhhh",
      "lllm   hh   nlll",
      "      hpph      ",
      "      hpph      ",
      "qqqr   hh   sqqq",
      "hhhi        jhhh",
      "gghtr      suhgg",
      "fgghtqr  squhggf",
      "   ghhi  jhhg   ",
      "   gghi  jhgg   ",
      "   fghi  jhgf   "
    ],
    [
      "    g      g    ",
      "   gg      gg   ",
      "   g        g   ",
      " gg          gg ",
      "gg            gg",
      "                ",
      "        w       ",
      "      xyyA      ",
      "       yyA      ",
      "       BB       ",
      "                ",
      "gg            gg",
      " gg          gg ",
      "   g        g   ",
      "   gg      gg   ",
      "    g      g    "
    ],
    [
      "                ",
      "                ",
      "                ",
      "                ",
      "                ",
      "                ",
      "       w        ",
      "      xyyA      ",
      "      xyyA      ",
      "       B        ",
      "                ",
      "                ",
      "                ",
      "                ",
      "                ",
      "                "
    ],
    [
      "                ",
      "                ",
      "                ",
      "                ",
      "                ",
      "                ",
      "        w       ",
      "      xyyA      ",
      "      xyy       ",
      "       BB       ",
      "                ",
      "                ",
      "                ",
      "                ",
      "                ",
      "                "
    ],
    [
      "                ",
      "                ",
      "                ",
      "                ",
      "                ",
      "                ",
      "       ww       ",
      "      xyy       ",
      "      xyyA      ",
      "        B       ",
      "                ",
      "                ",
      "                ",
      "                ",
      "                ",
      "                "
    ]
  ]
}