{
  "name": "street_highrise_hotel_straight",
  "refpalette": "deceasedcraft:streets/street_highrise_hotel_straight_palette",
  "xsize": 16,
  "zsize": 16,
  "slices": [
    [
      "aaaaaaaaaaaaaaaa",
      "abaabaabbaabaaba",
      "aaaaaaaaaaaaaaaa",
      "cccccccccccccccc",
      "dddddddddddddddd",
      "eeeeeeeeeeeeeeee",
      "HHHHHHHHHHHHHHHH",
      "HHHHHHHHHHHHHHHH",
      "HHHHHHHHHHHHHHHH",
      "HHHHHHHHHHHHHHHH",
      "eeeeeeeeeeeeeeee",
      "dddddddddddddddd",
      "cccccccccccccccc",
      "aaaaaaaaaaaaaaaa",
      "abaabaabbaabaaba",
      "aaaaaaaaaaaaaaaa"
    ],
    [
      "                ",
      "                ",
      "                ",
      "ffghhgffffghhgff",
      "iiiiiiiiiiiiiiii",
      "jjjjjjjjjjjjjjjj",
      "kkkkkkkkkkkkkkkk",
      "                ",
      "                ",
      "llllllllllllllll",
      "jjjjjjjjjjjjjjjj",
      "iiiiiiiiiiiiiiii",
      "ffgmmgffffgmmgff",
      "                ",
      "                ",
      "                "
    ],
    [
      "                ",
      "                ",
      "                ",
      "    n      n    ",
      "iiiiiiiiiiiiiiii",
      "                ",
      "                ",
      "                ",
      "                ",
      "                ",
      "                ",
      "iiiiiiiiiiiiiiii",
      "    o      o    ",
      "                ",
      "                ",
      "                "
    ]
  ]
}