{
  "name": "street_highrise_office_straight_2",
  "refpalette": "deceasedcraft:streets/street_highrise_office_straight_2_palette",
  "xsize": 16,
  "zsize": 16,
  "slices": [
    [
      "aaaaaaaaaaaaaaaa",
      "vvvvvvvvvvvvvvvv",
      "vvvvvvvvvvvvvvvv",
      "aaaaaaaaaaaaaaaa",
      "bbbbbbbbbbbbbbbb",
      "HHHHHHHHHHHHHHHH",
      "HHHHHHHHHHHHHHHH",
      "HHHHHHHHHHHHHHHH",
      "HHHHHHHHHHHHHHHH",
      "HHHHHHHHHHHHHHHH",
      "HHHHHHHHHHHHHHHH",
      "bbbbbbbbbbbbbbbb",
      "aaaaaaaaaaaaaaaa",
      "vvvvvvvvvvvvvvvv",
      "vvvvvvvvvvvvvvvv",
      "aaaaaaaaaaaaaaaa"
    ],
    [
      "cccccccdcccccccc",
      "eefeeeeeeeffeeee",
      "eeeeefeeeeeeeefe",
      "cccccccgcccccccc",
      "hhhhhhhhhhhhhhhh",
      "                ",
      "                ",
      " ii  ii  ii  ii ",
      " hh  hh  hh  hh ",
      "                ",
      "                ",
      "iiiiiiiiiiiiiiii",
      "ccccccccjccccccc",
      "eeefeeefeeefeeee",
      "feeffeeeeeeeeefe",
      "ccccccccdccccccc"
    ],
    [
      "       k        ",
      "                ",
      "                ",
      "                ",
      "                ",
      "                ",
      "                ",
      "                ",
      "                ",
      "                ",
      "                ",
      "                ",
      "                ",
      "                ",
      "                ",
      "        k       "
    ],
    [
      "       k        ",
      "                ",
      "                ",
      "                ",
      "                ",
      "                ",
      "                ",
      "                ",
      "                ",
      "                ",
      "                ",
      "                ",
      "                ",
      "                ",
      "                ",
      "        k       "
    ],
    [
      "       k        ",
      "                ",
      "                ",
      "                ",
      "                ",
      "                ",
      "                ",
      "                ",
      "                ",
      "                ",
      "                ",
      "                ",
      "                ",
      "                ",
      "                ",
      "        k       "
    ],
    [
      "       k        ",
      "                ",
      "       l        ",
      "                ",
      "                ",
      "                ",
      "                ",
      "                ",
      "                ",
      "                ",
      "                ",
      "                ",
      "                ",
      "        l       ",
      "                ",
      "        k       "
    ],
    [
      "       m        ",
      "       m        ",
      "       n        ",
      "                ",
      "                ",
      "                ",
      "                ",
      "                ",
      "                ",
      "                ",
      "                ",
      "                ",
      "                ",
      "        n       ",
      "        m       ",
      "        m       "
    ]
  ]
}