{
  "name": "street_highrise_office_straight_3",
  "refpalette": "deceasedcraft:streets/street_highrise_office_straight_3_palette",
  "xsize": 16,
  "zsize": 16,
  "slices": [
    [
      "aaaaaaaaaaaaaaaa",
      "vvvvvvvvvvvvvvvv",
      "vvvvvvvvvvvvvvvv",
      "aaaaaaaaaaaaaaaa",
      "bbbbbbbbbbbbbbbb",
      "HHHHHHHHHHHHHHHH",
      "HHHHHHHHHHHHHHHH",
      "HHHHHHHHHHHHHHHH",
      "HHHHHHHHHHHHHHHH",
      "HHHHHHHHHHHHHHHH",
      "HHHHHHHHHHHHHHHH",
      "bbbbbbbbbbbbbbbb",
      "aaaaaaaaaaaaaaaa",
      "vvvvvvvvvvvvvvvv",
      "vvvvvvvvvvvvvvvv",
      "aaaaaaaaaaaaaaaa"
    ],
    [
      "cccccccdcccccccc",
      "eefeeeeefeefeeee",
      "eeeeffeeeeeeeefe",
      "cccccccgcccccccc",
      "hhhhhhhhhhhhhhhh",
      "                ",
      "                ",
      " ii  ii  ii  ii ",
      " hh  hh  hh  hh ",
      "                ",
      "        j       ",
      "iiiiiiiiiiiiiiii",
      "cccccccckccccccc",
      "fefeeeeeffeeeefe",
      "eefefeeeeeefeeee",
      "ccccccccdccccccc"
    ],
    [
      "       l        ",
      "                ",
      "                ",
      "                ",
      "                ",
      "                ",
      "                ",
      "                ",
      "                ",
      "                ",
      "                ",
      "                ",
      "                ",
      "                ",
      "                ",
      "        l       "
    ],
    [
      "       l        ",
      "                ",
      "                ",
      "                ",
      "                ",
      "                ",
      "                ",
      "                ",
      "                ",
      "                ",
      "                ",
      "                ",
      "                ",
      "                ",
      "                ",
      "        l       "
    ],
    [
      "       l        ",
      "                ",
      "                ",
      "                ",
      "                ",
      "                ",
      "                ",
      "                ",
      "                ",
      "                ",
      "                ",
      "                ",
      "                ",
      "                ",
      "                ",
      "        l       "
    ],
    [
      "       l        ",
      "                ",
      "       m        ",
      "                ",
      "                ",
      "                ",
      "                ",
      "                ",
      "                ",
      "                ",
      "                ",
      "                ",
      "                ",
      "        m       ",
      "                ",
      "        l       "
    ],
    [
      "       n        ",
      "       n        ",
      "       o        ",
      "                ",
      "                ",
      "                ",
      "                ",
      "                ",
      "                ",
      "                ",
      "                ",
      "                ",
      "                ",
      "        o       ",
      "        n       ",
      "        n       "
    ]
  ]
}