{
  "name": "street_highrise_office_t_shape_newspaper_store",
  "refpalette": "deceasedcraft:streets/street_highrise_office_t_shape_newspaper_store_palette",
  "xsize": 16,
  "zsize": 16,
  "slices": [
    [
      "avvabHHHHHHbavva",
      "vvvabHHHHHHbavvv",
      "vvvabHHHHHHbavvv",
      "aaaabHHHHHHbaaaa",
      "bbbbHHHHHHHHbbbb",
      "HHHHHHHHHHHHHHHH",
      "HHHHHHHHHHHHHHHH",
      "HHHHHHHHHHHHHHHH",
      "HHHHHHHHHHHHHHHH",
      "HHHHHHHHHHHHHHHH",
      "HHHHbaaaaaabHHHH",
      "bbbbavvvvvvabbbb",
      "aaaaavvvvvvvaaaa",
      "vvvvvvvvvvvvvvvv",
      "vvvvvvvvvvvvvvvv",
      "aaaaaaaaaaaaaaaa"
    ],
    [
      "cddce      fcddc",
      "gdgce  fe  fcddd",
      "dddce  fe  fcgdd",
      "ccche      fhccc",
      "iiiij      kiiii",
      "                ",
      "                ",
      " ll          ll ",
      " im          ni ",
      "    ollllllp    ",
      "   oqccccccrp   ",
      "lllqcdssssdcrlll",
      "cccccdtsstdgcccc",
      "dgdggdggdddddddd",
      "gddddgdgdddgddgd",
      "cccccccccccccccc"
    ],
    [
      "                ",
      "                ",
      "                ",
      "                ",
      "                ",
      "                ",
      "                ",
      "                ",
      "                ",
      "                ",
      "                ",
      "      ssss      ",
      "      tuut      ",
      "      wwww      ",
      "                ",
      "                "
    ],
    [
      "                ",
      "                ",
      "                ",
      "                ",
      "                ",
      "                ",
      "                ",
      "                ",
      "                ",
      "                ",
      "                ",
      "      wxxw      ",
      "      y         ",
      "      w  w      ",
      "                ",
      "                "
    ],
    [
      "                ",
      "                ",
      "                ",
      "                ",
      "                ",
      "                ",
      "                ",
      "                ",
      "                ",
      "                ",
      "                ",
      "      wwww      ",
      "      wAAw      ",
      "      wwww      ",
      "                ",
      "                "
    ],
    [
      "                ",
      "                ",
      "                ",
      "                ",
      "                ",
      "                ",
      "                ",
      "                ",
      "                ",
      "                ",
      "                ",
      "      BBBB      ",
      "      BBBB      ",
      "      BBBB      ",
      "                ",
      "                "
    ]
  ]
}