{
  "name": "street_highrise_residential_all",
  "refpalette": "deceasedcraft:streets/street_highrise_residential_all_palette",
  "xsize": 16,
  "zsize": 16,
  "slices": [
    [
      "aaabcdHHHHdcbaaa",
      "aaaacdHHHHdcaaaa",
      "aaaaaaHHHHaaaaaa",
      "baaaaaHHHHaaaaab",
      "ccaaddHHHHddaacc",
      "ddaadHHHHHHdaadd",
      "HHHHHHHHHHHHHHHH",
      "HHHHHHHHHHHHHHHH",
      "HHHHHHHHHHHHHHHH",
      "HHHHHHHHHHHHHHHH",
      "ddaadHHHHHHdaadd",
      "ccaaddHHHHddaacc",
      "baaaaaHHHHaaaaab",
      "aaaaaaHHHHaaaaaa",
      "aaaacdHHHHdcaaaa",
      "aaabcdHHHHdcbaaa"
    ],
    [
      "   efgh  igfe   ",
      "    fgh  igf    ",
      "      jjjj      ",
      "e     jjjj     e",
      "ff  ggh  igg  ff",
      "gg  gkl  mng  gg",
      "ooppol    moqqoo",
      "  pp        qq  ",
      "  pp        qq  ",
      "rrpprs    trqqrr",
      "gg  gus  twg  gg",
      "ff  ggh  igg  ff",
      "e     xxxx     e",
      "      xxxx      ",
      "    fgh  igf    ",
      "   efgh  igfe   "
    ],
    [
      "   y        y   ",
      "                ",
      "                ",
      "y              y",
      "                ",
      "                ",
      "                ",
      "                ",
      "                ",
      "                ",
      "                ",
      "                ",
      "y              y",
      "                ",
      "                ",
      "   y        y   "
    ]
  ]
}