{
  "name": "street_highrise_office_all_2",
  "refpalette": "deceasedcraft:streets/street_highrise_office_all_2_palette",
  "xsize": 16,
  "zsize": 16,
  "slices": [
    [
      "avvabHHHHHHbavva",
      "vvvabHHHHHHbavvv",
      "vvvaccccHHHbavvv",
      "aaabHHHHHHHHbaaa",
      "bbbHdeddddddHfbb",
      "HHHHddHHHHedHfHH",
      "HHHHdHdHHdHdHfHH",
      "HHHHdHHdeHHdHfHH",
      "HHcHeHHedHHdHHHH",
      "HHfHdHdHHdHdHHHH",
      "HHcHddHHHHddHHHH",
      "bbfHeedddeedHbbb",
      "aaabHHHHHHHHbaaa",
      "vvvabHHHffccavvv",
      "vvvabHHHHHHbavvv",
      "avvabHHHHHHbavva"
    ],
    [
      "ghhgi      jghkg",
      "khhgi  ji  jghhk",
      "hkhg    i  jlkhh",
      "gglmn      opggg",
      "qqqn        o qq",
      "                ",
      "                ",
      " rr           r ",
      " q           qq ",
      "                ",
      "                ",
      "rr s        trrr",
      "gggus      twlgg",
      "hhhli  j    ghkh",
      "hkkgi  ji  jghhh",
      "ghhgi      jgkhg"
    ],
    [
      "                ",
      "                ",
      "            x   ",
      "  x             ",
      "                ",
      "                ",
      "                ",
      "                ",
      "                ",
      "                ",
      "                ",
      "                ",
      "             x  ",
      "   x            ",
      "                ",
      "                "
    ],
    [
      "                ",
      "                ",
      "            x   ",
      "  x             ",
      "                ",
      "                ",
      "                ",
      "                ",
      "                ",
      "                ",
      "                ",
      "                ",
      "             x  ",
      "   x            ",
      "                ",
      "                "
    ],
    [
      "                ",
      "                ",
      "            x   ",
      "  xy        A   ",
      "                ",
      "                ",
      "                ",
      "                ",
      "                ",
      "                ",
      "                ",
      "                ",
      "   A        yx  ",
      "   x            ",
      "                ",
      "                "
    ],
    [
      "                ",
      "                ",
      "            x   ",
      "  xB        B   ",
      "                ",
      "                ",
      "                ",
      "                ",
      "                ",
      "                ",
      "                ",
      "                ",
      "   B        Bx  ",
      "   x            ",
      "                ",
      "                "
    ],
    [
      "                ",
      "                ",
      "            x   ",
      "  xC        D   ",
      "                ",
      "                ",
      "                ",
      "                ",
      "                ",
      "                ",
      "                ",
      "                ",
      "   D        Cx  ",
      "   x            ",
      "                ",
      "                "
    ]
  ]
}