{
  "name": "street_highrise_office_all_4",
  "refpalette": "deceasedcraft:streets/street_highrise_office_all_4_palette",
  "xsize": 16,
  "zsize": 16,
  "slices": [
    [
      "avvabHHHHHHbavva",
      "vvvabHHHHHHbavvv",
      "vvvaccdcHHHbavvv",
      "aaabHHHHHHHHbaaa",
      "bbbHeefeefefHdbb",
      "HHHHefHHHHffHdHH",
      "HHHHfHfHHeHfHdHH",
      "HHHHfHHfeHHfHdHH",
      "HHdHfHHffHHfHHHH",
      "HHdHeHfHHfHfHHHH",
      "HHcHffHHHHefHHHH",
      "bbcHfeeffffeHbbb",
      "aaabHHHHHHHHbaaa",
      "vvvabHHHcdddavvv",
      "vvvabHHHHHHbavvv",
      "avvabHHHHHHbavva"
    ],
    [
      "ghhgi      jgkkg",
      "hhhgi  ji  jghhh",
      "hhkg    i  jlhkh",
      "gglmn      opggg",
      "qqqn        o qq",
      "                ",
      "                ",
      " rr           r ",
      " q           qq ",
      "                ",
      "                ",
      "rr s        trrr",
      "gggus      twlgg",
      "hhkli  j    ghhh",
      "hhkgi  ji  jghkk",
      "ghhgi      jghkg"
    ],
    [
      "                ",
      "                ",
      "            x   ",
      "  x             ",
      "                ",
      "                ",
      "                ",
      "                ",
      "                ",
      "                ",
      "                ",
      "                ",
      "             x  ",
      "   x            ",
      "                ",
      "                "
    ],
    [
      "                ",
      "                ",
      "            x   ",
      "  x             ",
      "                ",
      "                ",
      "                ",
      "                ",
      "                ",
      "                ",
      "                ",
      "                ",
      "             x  ",
      "   x            ",
      "                ",
      "                "
    ],
    [
      "                ",
      "                ",
      "            x   ",
      "  xy        m   ",
      "                ",
      "                ",
      "                ",
      "                ",
      "                ",
      "                ",
      "                ",
      "                ",
      "   m        mx  ",
      "   x            ",
      "                ",
      "                "
    ],
    [
      "                ",
      "                ",
      "            x   ",
      "  xA        A   ",
      "                ",
      "                ",
      "                ",
      "                ",
      "                ",
      "                ",
      "                ",
      "                ",
      "   A        Ax  ",
      "   x            ",
      "                ",
      "                "
    ],
    [
      "                ",
      "                ",
      "            x   ",
      "  xB        C   ",
      "                ",
      "                ",
      "                ",
      "                ",
      "                ",
      "                ",
      "                ",
      "                ",
      "   B        Bx  ",
      "   x            ",
      "                ",
      "                "
    ]
  ]
}