{
  "name": "street_highrise_hotel_t_shape",
  "refpalette": "deceasedcraft:streets/street_highrise_hotel_t_shape_palette",
  "xsize": 16,
  "zsize": 16,
  "slices": [
    [
      "aaabcdHHHHdcbaaa",
      "aeabcdHHHHdcbaea",
      "aaabcdHHHHdcbaaa",
      "bbbbcdHHHHdcbbbb",
      "ccccddHHHHddcccc",
      "dddddHHHHHHddddd",
      "HHHHHHHHHHHHHHHH",
      "HHHHHHHHHHHHHHHH",
      "HHHHHHHHHHHHHHHH",
      "HHHHHHHHHHHHHHHH",
      "dddddddddddddddd",
      "cccccccccccccccc",
      "bbbbbbbbbbbbbbbb",
      "aaaaaaaaaaaaaaaa",
      "aeaaeaaeeaaeaaea",
      "aaaaaaaaaaaaaaaa"
    ],
    [
      "   fghi  jhgf   ",
      "   fghi  jhgf   ",
      "   kghi  jhgk   ",
      "ffklghi  jhglkff",
      "gggghhi  jhhgggg",
      "hhhhhmn  ophhhhh",
      "qqqqqn    oqqqqq",
      "                ",
      "                ",
      "rrrrrrrrrrrrrrrr",
      "hhhhhhhhhhhhhhhh",
      "gggggggggggggggg",
      "ffksskffffksskff",
      "                ",
      "                ",
      "                "
    ],
    [
      "    g      g    ",
      "    g      g    ",
      "    g      g    ",
      "   tg      gu   ",
      "gggg        gggg",
      "                ",
      "                ",
      "                ",
      "                ",
      "                ",
      "                ",
      "gggggggggggggggg",
      "    w      w    ",
      "                ",
      "                ",
      "                "
    ]
  ]
}