{
  "name": "street_highrise_hotel_end",
  "refpalette": "deceasedcraft:streets/street_highrise_hotel_end_palette",
  "xsize": 16,
  "zsize": 16,
  "slices": [
    [
      "aaaabbbbbbbbbbbb",
      "acaaaaaaaaaaaaaa",
      "aaaaaaaaaaaaaaaa",
      "ddddbeHHHHHHHHaa",
      "bbbbbeHHHHHHHHaa",
      "eeeeeeHHHHHHHHaa",
      "HHHHHHHHHHHHHHaa",
      "HHHHHHHHHHHHHHaa",
      "HHHHHHHHHHHHHHaa",
      "HHHHHHHHHHHHHHaa",
      "eeeeeeHHHHHHHHaa",
      "bbbbbeHHHHHHHHaa",
      "ddddbeHHHHHHHHaa",
      "aaaaaaaaaaaaaaaa",
      "acaaaaaaaaaaaaaa",
      "aaaabbbbbbbbbbbb"
    ],
    [
      "    ffffffffffff",
      "                ",
      "                ",
      "gghifjklllk  m  ",
      "fffffjn   o  p  ",
      "jjjjjjn   k qm  ",
      "llllllr   o  p  ",
      "          k  m  ",
      "          o  p  ",
      "sssssst   k  m  ",
      "jjjjjjn   o  p  ",
      "fffffjn   k um  ",
      "gghifjossso  p  ",
      "                ",
      "                ",
      "    ffffffffffff"
    ],
    [
      "     ffffffffff ",
      "                ",
      "                ",
      "   w            ",
      "fffff           ",
      "                ",
      "                ",
      "                ",
      "                ",
      "                ",
      "                ",
      "fffff           ",
      "   x            ",
      "                ",
      "                ",
      "     ffffffffff "
    ]
  ]
}