{
  "name": "multi_thering_3_base2",
  "refpalette": "deceasedcraft:multi_thering_3/multi_thering_3_base2_palette",
  "xsize": 16,
  "zsize": 16,
  "slices": [
    [
      "vaaaaaaaaaaaaaab",
      "vaaaaaaaaaaaaaaa",
      "vaaaaaaaaaaaaaaa",
      "vaaaaaaaaaaaaaaa",
      "vaaaaaaaaaaaaaaa",
      "vaaaaaaaaaaaaaaa",
      "vaaaaaaaaaaaaaaa",
      "vaaaaaaaaaaaaaaa",
      "vaaaaaaaaaaaaaaa",
      "vaaaaaaaaaaaaaaa",
      "vaaaaaaaaaaaaaaa",
      "vaaaaaaaaaaaaaaa",
      "vaaaaaaaaaaaaaaa",
      "vaaaaaaaaaaaaaaa",
      "vaaaaaaaaaaaaaaa",
      "vaaaaaaaaaaaaaaa"
    ],
    [
      "vaaaaaaaaaaaaaab",
      "vaaaaaaaaaaaaaaa",
      "vaaaaaaaaaaaaaaa",
      "vaaaaaaaaaaaaaaa",
      "vaaaaaaaaaaaaaaa",
      "vaaaaaaaaaaaaaaa",
      "vaaaaaaaaaaaaaaa",
      "vaaaaaaaaaaaaaaa",
      "vaaaaaaaaaaaaaaa",
      "vaaaaaaaaaaaaaaa",
      "vaaaaaaaaaaaaaaa",
      "vaaaaaaaaaaaaaaa",
      "vaaaaaaaaaaaaaaa",
      "vaaaaaaaaaaaaaaa",
      "vaaaaaaaaaaaaaaa",
      "vaaaaaaaaaaaaaaa"
    ],
    [
      "vccccccccccccccb",
      "vccccccccccccccc",
      "vccccccccccccccc",
      "vccccccccccccccc",
      "vccccccccccccccc",
      "vccccccccccccccc",
      "vccccccccccccccc",
      "vccccccccccccccc",
      "vccccccccccccccc",
      "vccccccccccccccc",
      "vccccccccccccccc",
      "vccccccccccccccc",
      "vccccccccccccccc",
      "vccccccccccccccc",
      "vccccccccccccccc",
      "vccccccccccccccc"
    ],
    [
      "vdeeeedffffffffd",
      "vdddddddggggggdd",
      "vdhhhhhhhhhhhhff",
      "vdhhhhhhhhhhhhff",
      "vdhhhhhhhhhhhhff",
      "vdhhhhhhhhhhhhff",
      "vdhhhhhhhhhhhhff",
      "vdhhhhhhhhhhhhff",
      "vdhhhhhhhhhhhhff",
      "vdhhhhhhhhhhhhff",
      "vdhhhhhhhhhhhhff",
      "vdhhhhhhhhhhhhff",
      "vdhhhhhhhhhhhhff",
      "vdhhhhhhhhhhhhff",
      "vdhhhhhhhhhhhhff",
      "vddddddddddddddd"
    ],
    [
      "vd    d        i",
      "vdddddddjjkljjdd",
      "vd            mn",
      "vd o o  o o  pnn",
      "vdqrrr qrrr  pnn",
      "vd rsr  rtr  pnn",
      "vdqrrr qrrr  pnn",
      "vd u u  u u  pnn",
      "vd           pnn",
      "vd o o  o o  pnn",
      "vdqrrr qrrr  pnn",
      "vd r!r  rtr  pnn",
      "vdqrrr qrrr  pnn",
      "vd u u  u u  pnn",
      "vd            mn",
      "vddddddddddddddd"
    ],
    [
      "vd    d        i",
      "vdddddddjjwxjjdd",
      "vd              ",
      "vd              ",
      "vd              ",
      "vd  y    A      ",
      "vd              ",
      "vd              ",
      "vd           B  ",
      "vd              ",
      "vd              ",
      "vd  C           ",
      "vd              ",
      "vd              ",
      "vd              ",
      "vddddddddddddddd"
    ]
  ]
}