{
  "name": "multi_thering_3_ground",
  "refpalette": "deceasedcraft:multi_thering_3/multi_thering_3_ground_palette",
  "xsize": 16,
  "zsize": 16,
  "slices": [
    [
      "aHHabbbbaHHacdde",
      "aHHabbbbaHHacddc",
      "aHHaHHHHaHHacddc",
      "aHHaHHHHaHHacddc",
      "aHHaHHHHaHHacddc",
      "aHHaHHHHaHHacddc",
      "aHHaHHHHaHHacddc",
      "aHHaHHHHaHHacddc",
      "aHHaHHHHaHHacddc",
      "aHHaHHHHaHHacddc",
      "aHHaHHHHaHHacddc",
      "aHHaHHHHaHHacddc",
      "aHHaHHHHaHHacddc",
      "aHHaHHHHaHHacddc",
      "aHHabbbbaHHacddc",
      "aHHabbbbaHHacddc"
    ],
    [
      "     f         g",
      "    hhhh        ",
      "    i  j        ",
      "    k  l        ",
      "    i  j        ",
      "  m k  l        ",
      "    i  j        ",
      "    k  l        ",
      "    i  j        ",
      "    k  l        ",
      "    i  j n      ",
      "    k  l        ",
      "    i  j        ",
      "    k  l        ",
      "    hhhh        ",
      "     f          "
    ],
    [
      "     h         g",
      "                ",
      "                ",
      "                ",
      "                ",
      "                ",
      "                ",
      "                ",
      "                ",
      "                ",
      "                ",
      "                ",
      "                ",
      "                ",
      "                ",
      "     h          "
    ],
    [
      "     op        g",
      "                ",
      "                ",
      "                ",
      "                ",
      "                ",
      "                ",
      "                ",
      "                ",
      "                ",
      "                ",
      "                ",
      "                ",
      "                ",
      "                ",
      "     o          "
    ],
    [
      "    ooo        g",
      "     p          ",
      "                ",
      "                ",
      "                ",
      "                ",
      "                ",
      "                ",
      "                ",
      "                ",
      "                ",
      "                ",
      "                ",
      "                ",
      "     o          ",
      "     oo         "
    ],
    [
      "    ooo        g",
      "     o          ",
      "                ",
      "                ",
      "                ",
      "                ",
      "                ",
      "                ",
      "                ",
      "                ",
      "                ",
      "                ",
      "                ",
      "                ",
      "     p          ",
      "    ooo         "
    ]
  ]
}