{
  "name": "multi_thering_3_base1",
  "refpalette": "deceasedcraft:multi_thering_3/multi_thering_3_base1_palette",
  "xsize": 16,
  "zsize": 16,
  "slices": [
    [
      "va    a        b",
      "vaaaaaaaccccccaa",
      "va              ",
      "va              ",
      "va              ",
      "va              ",
      "va              ",
      "va              ",
      "va              ",
      "va              ",
      "va              ",
      "va              ",
      "va              ",
      "va              ",
      "va              ",
      "vaaaaaaaaaaaaaaa"
    ],
    [
      "va    a        b",
      "vaaaaaaaddddddaa",
      "va              ",
      "va             e",
      "va              ",
      "va             f",
      "va             f",
      "va             f",
      "va             f",
      "va             f",
      "va             f",
      "va             f",
      "va              ",
      "va             e",
      "va              ",
      "vaaaaaaaaaaaaaaa"
    ],
    [
      "vaghh a        b",
      "vaaaaaaaaaaaaaaa",
      "va             i",
      "va             j",
      "va             k",
      "va             f",
      "va             f",
      "va             f",
      "va             f",
      "va             f",
      "va             f",
      "va             f",
      "va             i",
      "va             j",
      "va             k",
      "vaaaaaaaaaaaaaaa"
    ],
    [
      "valmmma        b",
      "vaaaaaaaaaaaaaaa",
      "va             n",
      "va             j",
      "va             o",
      "va             f",
      "va             f",
      "va             f",
      "va             f",
      "va             f",
      "va             f",
      "va             f",
      "va             n",
      "va             j",
      "va             o",
      "vaaaaaaaaaaaaaaa"
    ],
    [
      "vap   a        b",
      "vaaaaaaaaaaaaaaa",
      "va              ",
      "va              ",
      "va              ",
      "va              ",
      "va              ",
      "va              ",
      "va    q         ",
      "va              ",
      "va              ",
      "va              ",
      "va              ",
      "va              ",
      "va              ",
      "vaaaaaaaaaaaaaaa"
    ],
    [
      "varrrrammmmmmmmb",
      "vaaaaaaaaaaaaaaa",
      "vammmmmmmmmmmmms",
      "vammmmmmmmmmmmms",
      "vammmmmmmmmmmmms",
      "vammmmmmmmmmmmms",
      "vammmmmmmmmmmmms",
      "vammmmmmmmmmmmms",
      "vammmmmmmmmmmmms",
      "vammmmmmmmmmmmms",
      "vammmmmmmmmmmmms",
      "vammmmmmmmmmmmms",
      "vammmmmmmmmmmmms",
      "vammmmmmmmmmmmms",
      "vammmmmmmmmmmmms",
      "vaaaaaaaaaaaaaaa"
    ]
  ]
}