{
  "name": "multi_thering_3_floor6",
  "refpalette": "deceasedcraft:multi_thering_3/multi_thering_3_floor6_palette",
  "xsize": 16,
  "zsize": 16,
  "slices": [
    [
      "               a",
      "                ",
      "                ",
      "                ",
      "                ",
      "                ",
      "                ",
      "                ",
      "                ",
      "                ",
      "                ",
      "                ",
      "                ",
      "                ",
      "                ",
      "                "
    ],
    [
      "               a",
      "               a",
      "               a",
      "               a",
      "               a",
      "               a",
      "               a",
      "               a",
      "               a",
      "               a",
      "               a",
      "               a",
      "               a",
      "               a",
      "               a",
      "               a"
    ],
    [
      "               a",
      "                ",
      "                ",
      "                ",
      "                ",
      "                ",
      "                ",
      "                ",
      "                ",
      "                ",
      "                ",
      "                ",
      "                ",
      "                ",
      "                ",
      "                "
    ],
    [
      "               a",
      "                ",
      "                ",
      "                ",
      "                ",
      "                ",
      "                ",
      "                ",
      "                ",
      "                ",
      "                ",
      "                ",
      "                ",
      "                ",
      "                ",
      "                "
    ],
    [
      "        bccccccc",
      "        bccccccc",
      "         bcccccc",
      "         bcccccc",
      "         bbccccc",
      "          bccccc",
      "          bccccc",
      "           bcccc",
      "           bbccc",
      "            bccc",
      "             bcc",
      "             bbc",
      "              bc",
      "               b",
      "                ",
      "                "
    ],
    [
      "      bcccdefffe",
      "      bccccfffee",
      "       bcccefffe",
      "       bcccceffe",
      "       bccccefff",
      "        bbgceeff",
      "        bcccceff",
      "         bccccee",
      "         bccccef",
      "          bcccce",
      "          bccccc",
      "           bcccc",
      "            bbgc",
      "            bbcc",
      "             bbc",
      "              bc"
    ]
  ]
}