{
  "name": "multi_thering_3_floor7",
  "refpalette": "deceasedcraft:multi_thering_3/multi_thering_3_floor7_palette",
  "xsize": 16,
  "zsize": 16,
  "slices": [
    [
      "    abcccb d    ",
      "    abcccbb     ",
      "     abcccb     ",
      "     abcccbbe   ",
      "     abccccb    ",
      "      abcccbdd  ",
      "      abcccbb   ",
      "      aabcccbbe ",
      "       abccccb  ",
      "       aabcccbbd",
      "        abccccbb",
      "         abccccb",
      "         abbcccb",
      "          abcccc",
      "           abccc",
      "           aabcc"
    ],
    [
      "     fghi  j    ",
      "     fghi       ",
      "      fgii      ",
      "      fghi  k   ",
      "      fghii     ",
      "       fghi jj  ",
      "       fg i     ",
      "        fgii  k ",
      "        fghii   ",
      "         fghi  j",
      "         fghii  ",
      "          fglii ",
      "          ffghi ",
      "           fghii",
      "            fghi",
      "             fgh"
    ],
    [
      "      g    g    ",
      "      g         ",
      "       g        ",
      "       g    j   ",
      "       g        ",
      "        g   gg  ",
      "        g       ",
      "         g    j ",
      "         g      ",
      "          g    g",
      "          g     ",
      "           g    ",
      "            g   ",
      "            g   ",
      "             g  ",
      "              g "
    ],
    [
      "           g    ",
      "                ",
      "                ",
      "            g   ",
      "                ",
      "            gg  ",
      "                ",
      "              g ",
      "                ",
      "               g",
      "                ",
      "                ",
      "                ",
      "                ",
      "                ",
      "                "
    ],
    [
      "           g    ",
      "                ",
      "                ",
      "            g   ",
      "                ",
      "            mg  ",
      "                ",
      "              g ",
      "                ",
      "               g",
      "                ",
      "                ",
      "                ",
      "                ",
      "                ",
      "                "
    ],
    [
      "           m    ",
      "                ",
      "                ",
      "            g   ",
      "                ",
      "             m  ",
      "                ",
      "              g ",
      "                ",
      "               m",
      "                ",
      "                ",
      "                ",
      "                ",
      "                ",
      "                "
    ]
  ]
}