{
  "name": "multi_flatlarge_7_floor3",
  "refpalette": "deceasedcraft:multi_flatlarge_7/multi_flatlarge_7_floor3_palette",
  "xsize": 16,
  "zsize": 16,
  "slices": [
    [
      "aaaaaaaaaaaaab  ",
      "aaaaaaaaaaaaac  ",
      "dddeddddddddde  ",
      "dddeddddddddde  ",
      "dddeddddddddde  ",
      "dddeddddddddde  ",
      "dddeddddddddde  ",
      "dddeddddddddde  ",
      "fffefffdddddde  ",
      "fffefffdddddde  ",
      "fffefffdddddde  ",
      "fffefffddddddc  ",
      "eeegeeeeeeeeg   ",
      "                ",
      "                ",
      "                "
    ],
    [
      "             h  ",
      "iiijiiiiiikiic  ",
      "  lem   en  oe  ",
      "p qer steu  wc  ",
      "p qer sten  xc  ",
      "  yeA   e   wc  ",
      "  BeC   D   Ec  ",
      "eFeeeIeee JJKc  ",
      "L MeN LO  PP c  ",
      "L QeR LS    Tc  ",
      "L UeU LV   WXe  ",
      "L  e  LY   ZXc  ",
      "0LegeL0LLLLeg   ",
      "                ",
      "                ",
      "                "
    ],
    [
      "                ",
      "iii iiiiii1iic  ",
      "   e    e   2e  ",
      "   e    e    c  ",
      "   e    e   34  ",
      "   e    e    c  ",
      "  BeC   5    c  ",
      "e6eee7eee    c  ",
      "L  e  L     34  ",
      "L  e  L     8c  ",
      "L UeU L     9e  ",
      "L #e$ L %^& 9c  ",
      "04ege40L444eg   ",
      "                ",
      "                ",
      "                "
    ],
    [
      "                ",
      "iii iiiiii*iic  ",
      "   e    e(   e  ",
      "   e    e(   c  ",
      "   e    e(  )4  ",
      "   e    e    c  ",
      "  BeC   c    c  ",
      "e*eee*eee    c  ",
      "L +e- L     )4  ",
      "L  e  L     8c  ",
      "L  e  L     9e  ",
      "L [e] L {}| 9c  ",
      "04ege40L444eg   ",
      "                ",
      "                ",
      "                "
    ],
    [
      "                ",
      "iii iiiiiiiiic  ",
      "   e    e    e  ",
      "   e    e    e  ",
      "   e    e    e  ",
      "   e    e    e  ",
      "   e    e    e  ",
      "eeeeeeeee    e  ",
      "e;;e;;e      e  ",
      "e;;e;;e     :e  ",
      "e;;e;;e      e  ",
      "e;;e;;e      c  ",
      "eeegeeeeeeeeg   ",
      "                ",
      "                ",
      "                "
    ],
    [
      "'''''''''''''<  ",
      ">>>>>>>>>>>>>c  ",
      "aaaeaaaaaaaaa,  ",
      "aaaeaaaaaaaaa,  ",
      "aaaeaaaaaaaaa,  ",
      "aaaeaaaaaaaaa,  ",
      "aaaeaaaaaaaaa,  ",
      "aaaeaaaaaaaaa,  ",
      "a  e  aaaaaaa,  ",
      "a .e. aaaaaaa,  ",
      "a  e  aaaaaaa,  ",
      "aaaeaaaaaaaaac  ",
      ",,,g,,,,,,,,g   ",
      "                ",
      "                ",
      "                "
    ]
  ]
}