{
  "name": "multi_flatlarge_7_floor1",
  "refpalette": "deceasedcraft:multi_flatlarge_7/multi_flatlarge_7_floor1_palette",
  "xsize": 16,
  "zsize": 16,
  "slices": [
    [
      "aaaaaaaaaaaaab  ",
      "aaaaaaaaaaaaac  ",
      "dddeddddddddde  ",
      "dddeddddddddde  ",
      "dddeddddddddde  ",
      "dddeddddddddde  ",
      "dddeddddddddde  ",
      "dddeddddddddde  ",
      "fffefffdddddde  ",
      "fffefffdddddde  ",
      "fffefffdddddde  ",
      "fffefffddddddc  ",
      "eeegeeeeeeeeg   ",
      "                ",
      "                ",
      "                "
    ],
    [
      "             h  ",
      "iiijiiiiiikiic  ",
      "  lem   en  oe  ",
      "p qer steu  wc  ",
      "p qer sten  xc  ",
      "  ley   e   wc  ",
      "  AeB   C   Dc  ",
      "eEeeeFeee IIJc  ",
      "K LeM KN  OO c  ",
      "K PeQ KR    Sc  ",
      "K TeT KU   VWe  ",
      "K  e  KX   YWc  ",
      "ZKegeKZKKKKeg   ",
      "                ",
      "                ",
      "                "
    ],
    [
      "                ",
      "iii iiiiii0iic  ",
      "   e    e   1e  ",
      "   e    e    c  ",
      "   e    e   23  ",
      "   e    e    c  ",
      "  AeB   4    c  ",
      "e5eee6eee    c  ",
      "K  e  K     23  ",
      "K  e  K     7c  ",
      "K TeT K     8e  ",
      "K 9e# K $%^ 8c  ",
      "Z3ege3ZK333eg   ",
      "                ",
      "                ",
      "                "
    ],
    [
      "                ",
      "iii iiiiii&iic  ",
      "   e    e*   e  ",
      "   e    e*   c  ",
      "   e    e*  (3  ",
      "   e    e    c  ",
      "  AeB   c    c  ",
      "e&eee&eee    c  ",
      "K )e+ K     (3  ",
      "K  e  K     7c  ",
      "K  e  K     8e  ",
      "K -e[ K ]{} 8c  ",
      "Z3ege3ZK333eg   ",
      "                ",
      "                ",
      "                "
    ],
    [
      "                ",
      "iii iiiiiiiiic  ",
      "   e    e    e  ",
      "   e    e    e  ",
      "   e    e    e  ",
      "   e    e    e  ",
      "   e    e    e  ",
      "eeeeeeeee    e  ",
      "e||e||e      e  ",
      "e||e||e     ;e  ",
      "e||e||e      e  ",
      "e||e||e      c  ",
      "eeegeeeeeeeeg   ",
      "                ",
      "                ",
      "                "
    ],
    [
      ":::::::::::::'  ",
      "<<<<<<<<<<<<<c  ",
      "aaaeaaaaaaaaa>  ",
      "aaaeaaaaaaaaa>  ",
      "aaaeaaaaaaaaa>  ",
      "aaaeaaaaaaaaa>  ",
      "aaaeaaaaaaaaa>  ",
      "aaaeaaaaaaaaa>  ",
      "a  e  aaaaaaa>  ",
      "a ,e, aaaaaaa>  ",
      "a  e  aaaaaaa>  ",
      "aaaeaaaaaaaaac  ",
      ">>>g>>>>>>>>g   ",
      "                ",
      "                ",
      "                "
    ]
  ]
}