{
  "name": "multi_flatlarge_7_ground",
  "refpalette": "deceasedcraft:multi_flatlarge_7/multi_flatlarge_7_ground_palette",
  "xsize": 16,
  "zsize": 16,
  "slices": [
    [
      "aaaaaaaaaaaaabHH",
      "cccaccccccccabHH",
      "ccccccccccccdbHH",
      "ccccccccccccdbHH",
      "ccccccccccccdbHH",
      "ccccccccccccdbHH",
      "ccccccccccccdbHH",
      "ccccccccccccdbHH",
      "ccccccccccccdbHH",
      "ccccccccccccdbHH",
      "ccccccccccccdbHH",
      "cccaccccccccabHH",
      "dddddddddddddbHH",
      "bbbbbbbbbbbbbHHH",
      "HHHHHHHHHHHHHHHH",
      "HHHHHHHHHHHHHHHH"
    ],
    [
      "eeffefeffefef   ",
      "ghgihghghghgi   ",
      "            j   ",
      "            j   ",
      "klk lklklklkj   ",
      "            j   ",
      "            j   ",
      "            j   ",
      "ghg hghghghgj   ",
      "            j   ",
      "            j   ",
      "klkilklklklki   ",
      "jjjjjjjjjjjjj   ",
      "                ",
      "                ",
      "                "
    ],
    [
      "                ",
      "   m        m   ",
      "                ",
      "                ",
      "                ",
      "                ",
      "                ",
      "                ",
      "                ",
      "                ",
      "                ",
      "   m        m   ",
      "                ",
      "                ",
      "                ",
      "                "
    ],
    [
      "                ",
      "   m        m   ",
      "                ",
      "                ",
      "                ",
      "                ",
      "                ",
      "                ",
      "                ",
      "                ",
      "                ",
      "   m        m   ",
      "                ",
      "                ",
      "                ",
      "                "
    ],
    [
      "                ",
      "nnnmnnnnnnnnm   ",
      "   o        p   ",
      "   o        p   ",
      "   o        p   ",
      "   o        p   ",
      "   o        p   ",
      "   o        p   ",
      "   o        p   ",
      "   o        p   ",
      "   o        p   ",
      "qqqmqqqqqqqqm   ",
      "                ",
      "                ",
      "                ",
      "                "
    ],
    [
      "oooooooooooooo  ",
      "rrrrrrrrrrrrro  ",
      "sssrssssssssro  ",
      "sssrssssssssro  ",
      "sssrssssssssro  ",
      "sssrssssssssro  ",
      "sssrssssssssro  ",
      "sssrssssssssro  ",
      "sssrssssssssro  ",
      "sssrssssssssro  ",
      "sssrssssssssro  ",
      "rrrrrrrrrrrrro  ",
      "oooooooooooooo  ",
      "                ",
      "                ",
      "                "
    ]
  ]
}