{
  "name": "multi_hospitaldamaged_3_base1",
  "refpalette": "deceasedcraft:multi_hospitaldamaged_3/multi_hospitaldamaged_3_base1_palette",
  "xsize": 16,
  "zsize": 16,
  "slices": [
    [
      "vvvvvvvvvvvvvvvv",
      "aaabaaaaaaaaaacv",
      "daaaae       acv",
      "     e       acv",
      "     f       acv",
      "     f       acv",
      "     f       acv",
      "     f       acv",
      "     f       acv",
      "     f       acv",
      "     f       acv",
      "     f       acv",
      "     f       acv",
      "     e       acv",
      "daagae       acv",
      "hhhhhe  eiiieajv"
    ],
    [
      "vvvvvvvvvvvvvvvv",
      "aaabaaaaaaaaaacv",
      "daaaae       acv",
      "     e       acv",
      "     f       acv",
      "     f       acv",
      "     f       acv",
      "     f       acv",
      "     f       acv",
      "     f       acv",
      "     f       acv",
      "     f       acv",
      "     f       acv",
      "     e       acv",
      "daakae       acv",
      "el  me  eeeeeajv"
    ],
    [
      "vvvvvvvvvvvvvvvv",
      "aaanaaaaaaaaaacv",
      "daaaae       acv",
      "     e       acv",
      "     f       acv",
      "     f       acv",
      "     f       acv",
      "     f       acv",
      "     f       acv",
      "     f       acv",
      "     f       acv",
      "     f       acv",
      "     f       acv",
      "     e       acv",
      "daakae       acv",
      "eo   e  eeeeeajv"
    ],
    [
      "vvvvvvvvvvvvvvvv",
      "aaabaaaaaaaaaacv",
      "daaaae       acv",
      "     e       acv",
      "    pe       acv",
      "    pe       acv",
      "    pe       acv",
      "    pe       acv",
      "    pe       acv",
      "    pe       acv",
      "    pe       acv",
      "    pe       acv",
      "    pe       acv",
      "     e       acv",
      "daakae       acv",
      "e   qe  eeeeeajv"
    ],
    [
      "vvvvvvvvvvvvvvvv",
      "aaaaaaaaaaaaaacv",
      "daarae       acv",
      "rrrrre       acv",
      "rrrrre       acv",
      "rrrrre       acv",
      "rrrrre       acv",
      "rrrrre       acv",
      "rrrrre       acv",
      "rrrrre       acv",
      "rrrrre       acv",
      "rrrrre       acv",
      "rrrrre       acv",
      "rrrrre       acv",
      "daarae       acv",
      "errrre  eeeeeajv"
    ],
    [
      "vvvvvvvvvvvvvvvv",
      "aaaaaaaaaaaaaacv",
      "daaaaesssssssacv",
      "sssssssssssssacv",
      "sssssssssssssacv",
      "sssssssssssssacv",
      "sssssssssssssacv",
      "sssssssssssssacv",
      "sssssssssssssacv",
      "sssssssssssssacv",
      "sssssssssssssacv",
      "sssssssssssssacv",
      "sssssssssssssacv",
      "sssssssssssssacv",
      "sssssssssssssacv",
      "essssesseeeeeajv"
    ]
  ]
}