{
  "name": "multi_hospitaldamaged_3_base2",
  "refpalette": "deceasedcraft:multi_hospitaldamaged_3/multi_hospitaldamaged_3_base2_palette",
  "xsize": 16,
  "zsize": 16,
  "slices": [
    [
      "vvvvvvvvvvvvvvvv",
      "vvvvvvvvvvvvvvvv",
      "vvvvvvvvvvvvvvvv",
      "vvvvvvvvvvvvvvvv",
      "vvvvvvvvvvvvvvvv",
      "vvvvvvvvvvvvvvvv",
      "vvvvvvvvvvvvvvvv",
      "vvvvvvvvvvvvvvvv",
      "vvvvvvvvvvvvvvvv",
      "vvvvvvvvvvvvvvvv",
      "vvvvvvvvvvvvvvvv",
      "vvvvvvvvvvvvvvvv",
      "vvvvvvvvvvvvvvvv",
      "vvvvvvvvvvvvvvvv",
      "vvvvvvvvvvvvvvvv",
      "vvvvvvvvvvvvvvvv"
    ],
    [
      "vvvvvvvvvvvvvvvv",
      "vvvvvvvvvvvvvvvv",
      "aaaaaaaaaaaaaaav",
      "aaaaaaaaaaaaaaav",
      "aaaaaaaaaaaaaaav",
      "aaaaaaaaaaaaaaav",
      "aaaaaaaaaaaaaaav",
      "aaaaaaaaaaaaaaav",
      "aaaaaaaaaaaaaaav",
      "aaaaaaaaaaaaaaav",
      "aaaaaaaaaaaaaaav",
      "aaaaaaaaaaaaaaav",
      "aaaaaaaaaaaaaaav",
      "aaaaaaaaaaaaaaav",
      "aaaaaaaaaaaaaaav",
      "aaaaaaaabbbbbcdv"
    ],
    [
      "vvvvvvvvvvvvvvvv",
      "ccccccccccccccav",
      "bbbbbbbbbbbbbcav",
      "bbbbbbbbbbbbbcav",
      "bbbbbbbbbbbbbcav",
      "bbbbbbbbbbbbbcav",
      "bbbbbbbbbbbbbcav",
      "bbbbbbbbbbbbbcav",
      "bbbbbbbbbbbbbcav",
      "bbbbbbbbbbbbbcav",
      "bbbbbbbbbbbbbcav",
      "bbbbbbbbbbbbbcav",
      "bbbbbbbbbbbbbcav",
      "bbbbbbbbbbbbbcav",
      "bbbbbbbbbbbbbcav",
      "eeeeeeeebbbbbcdv"
    ],
    [
      "vvvvvvvvvvvvvvvv",
      "ccccccccccccccav",
      "fccgcbeeeeeeecav",
      "fffhhbeeeeeeecav",
      "hhhhhieeeeeeecav",
      "hhhhhieeeeeeecav",
      "fhhhhieeeeeeecav",
      "fhhhhieeeeeeecav",
      "fhhhhieeeeeeecav",
      "fhhhhieeeeeeecav",
      "fhhhhieeeeeeecav",
      "hhhhhieeeeeeecav",
      "hhhhhieeeeeeecav",
      "fffhhbeeeeeeecav",
      "fccgcbeeeeeeecav",
      "eeeeeeeejeeebcdv"
    ],
    [
      "vvvvvvvvvvvvvvvv",
      "ccckccccccccccav",
      "fccccbllmnollcav",
      "pqq  b       cav",
      "     r   s   cav",
      "     r  tut  cav",
      "w    r xyABC cav",
      "w    rD yAB  cav",
      "w    r xyABC cav",
      "w    r  yAB Ecav",
      "w    r xyABC cav",
      "     r  tFt  cav",
      "     r D I J cav",
      "KLL  b       cav",
      "fccMcb  N    cav",
      "bbbbbbOObPQRbcdv"
    ],
    [
      "vvvvvvvvvvvvvvvv",
      "ccckccccccccccav",
      "fccccbSTUV WXcav",
      " YZ  b       cav",
      "     r       cav",
      "     r  0E1  cav",
      "2    r    J  cav",
      "3    r  4    cav",
      "2    r  5    cav",
      "2    r  4 E  cav",
      "     r  6    cav",
      "     r   7   cav",
      "     r       cav",
      " 89  b#      cav",
      "fccMcb       cav",
      "bbbbbb  bP$%bcdv"
    ]
  ]
}