{
  "name": "multi_hospitaldamaged_3_top",
  "refpalette": "deceasedcraft:multi_hospitaldamaged_3/multi_hospitaldamaged_3_top_palette",
  "xsize": 16,
  "zsize": 16,
  "slices": [
    [
      "                ",
      "                ",
      "aaaaaaab        ",
      "ccccccd         ",
      "ccccccd         ",
      "eeeeeed         ",
      "eeeeeed         ",
      "eeeeeed         ",
      "ccccccd         ",
      "ccccccd         ",
      "eeeeeed         ",
      "eeeeeed         ",
      "eeeeeed         ",
      "ccccccdffgfgf   ",
      "ccccccdhhhhhhi  ",
      "jjjjjjjkjllljm  "
    ],
    [
      "                ",
      "                ",
      "       b        ",
      "nnnnnnnb        ",
      "nnnnnnnb        ",
      "oooooonb        ",
      "oooooonb        ",
      "oooooonb        ",
      "nnnnnnnb        ",
      "nnnnnnnb        ",
      "oooooonb        ",
      "oooooonb        ",
      "oooooonp        ",
      "qqqqqqqbfffggf  ",
      "hhhhhhhhhhhhhh  ",
      "rsrtttrsjjjjjm  "
    ],
    [
      "                ",
      "                ",
      "                ",
      "                ",
      "                ",
      "                ",
      "                ",
      "                ",
      "                ",
      "                ",
      "                ",
      "                ",
      "                ",
      "fffgfgffgffggg  ",
      "hhhhhhhhhhhhhu  ",
      "whxyABChjjjjjm  "
    ],
    [
      "                ",
      "                ",
      "                ",
      "                ",
      "                ",
      "                ",
      "                ",
      "                ",
      "                ",
      "                ",
      "                ",
      "                ",
      "                ",
      "        ffgffg  ",
      "jjjDDDjjhhhhhh  ",
      " h     hjjjjjm  "
    ],
    [
      "                ",
      "                ",
      "                ",
      "                ",
      "                ",
      "                ",
      "                ",
      "                ",
      "                ",
      "                ",
      "                ",
      "                ",
      "                ",
      "gfffffffffffgf  ",
      "hhhhhhhhhhhhhh  ",
      " h     hjjjjjm  "
    ],
    [
      "                ",
      "                ",
      "                ",
      "                ",
      "                ",
      "                ",
      "                ",
      "                ",
      "                ",
      "                ",
      "                ",
      "                ",
      "                ",
      "fffffgfffffffg  ",
      "hhhhhhhhhhhhhh  ",
      " h     hjjjjjm  "
    ],
    [
      "                ",
      "                ",
      "                ",
      "                ",
      "                ",
      "                ",
      "                ",
      "                ",
      "                ",
      "                ",
      "                ",
      "                ",
      "                ",
      "ffffffffffgfff  ",
      "hhhhhhhhhhhhhu  ",
      "bbbbbbbbjllljm  "
    ],
    [
      "                ",
      "                ",
      "                ",
      "                ",
      "                ",
      "                ",
      "                ",
      "                ",
      "                ",
      "                ",
      "                ",
      "                ",
      "                ",
      "                ",
      "EEEEEEEEm m m   ",
      " FI   JKjjjjjm  "
    ],
    [
      "                ",
      "                ",
      "                ",
      "                ",
      "                ",
      "                ",
      "                ",
      "                ",
      "                ",
      "                ",
      "                ",
      "                ",
      "                ",
      "                ",
      "EEEEEEEEm m m   ",
      "        jjjjjm  "
    ],
    [
      "                ",
      "                ",
      "                ",
      "                ",
      "                ",
      "                ",
      "                ",
      "                ",
      "                ",
      "                ",
      "                ",
      "                ",
      "                ",
      "                ",
      "DDDDDDEEm m m   ",
      "        jjjjjm  "
    ],
    [
      "                ",
      "                ",
      "                ",
      "                ",
      "                ",
      "                ",
      "                ",
      "                ",
      "                ",
      "                ",
      "                ",
      "                ",
      "                ",
      "                ",
      "EEEEEEEEm m m   ",
      "        jjjjjm  "
    ],
    [
      "                ",
      "                ",
      "                ",
      "                ",
      "                ",
      "                ",
      "                ",
      "                ",
      "                ",
      "                ",
      "                ",
      "                ",
      "                ",
      "LLLLLLLLLLLLLLL ",
      "EEEEEEEEEEEEEEL ",
      "bbbbbbbbjjjjjEL "
    ],
    [
      "                ",
      "                ",
      "                ",
      "                ",
      "                ",
      "                ",
      "                ",
      "                ",
      "                ",
      "                ",
      "                ",
      "                ",
      "                ",
      "MMMMMMMMNMMMMNM ",
      "              M ",
      "MMMMMMMMMMMMM N "
    ]
  ]
}