{
  "name": "multi_hospitaldamaged_3_ground",
  "refpalette": "deceasedcraft:multi_hospitaldamaged_3/multi_hospitaldamaged_3_ground_palette",
  "xsize": 16,
  "zsize": 16,
  "slices": [
    [
      "abbbaaaabbaaabaa",
      "bbaaaaaaaaaaaaab",
      "cccccccd     eab",
      "       feeeeeeaa",
      "   g   heeeeeeaa",
      "iiiji  keeeeeeaa",
      "iiiii lkeeeeeeba",
      "iiiji  keeeeeeab",
      "   m   keeeeeeaa",
      "       keeeeeeaa",
      "       keeeeeeaa",
      "       keeeeeeaa",
      "    n  keeeeeeab",
      "       heeeeeeaa",
      "  o p  feeeeeeaa",
      "eeeeqqqqreeeqeab"
    ],
    [
      "                ",
      "   stt tstts tu ",
      "wwwwwwwd      t ",
      "       fxxxxx s ",
      "yAAAA   BC Dx t ",
      "EFIJKL M  N x s ",
      "O   P     DQx   ",
      "E RSKL    NTx   ",
      "UVVVU    W Dx s ",
      "         N  x t ",
      "       X   Yx t ",
      "          N x t ",
      "            x s ",
      "         Z  x   ",
      "       f0  Mx s ",
      "1 2nqqqqq345q6  "
    ],
    [
      "                ",
      "                ",
      "wwwwwwwd        ",
      "       f77787   ",
      "99999       7   ",
      "#  $%       7   ",
      "^   &      T8   ",
      "#*()%       7   ",
      "+++++       7   ",
      "            7   ",
      "            7   ",
      "            7   ",
      "            -   ",
      "            7   ",
      "       f    7   ",
      "11  qqqqq3[]q6  "
    ],
    [
      "                ",
      "                ",
      "111111wd        ",
      "       f7887{   ",
      "yAAAy       7   ",
      "E}  |;      7   ",
      ":''''<      1   ",
      "E>>>|;      1   ",
      "UVVVU       1   ",
      "            q   ",
      "            1   ",
      "            1   ",
      "                ",
      "            8   ",
      "       f    7   ",
      "11  qqqqq333q6  "
    ],
    [
      "                ",
      "                ",
      "111111wd        ",
      "       f,. .    ",
      "       fffff.   ",
      "?////  fdddf,   ",
      " /     fdddf,   ",
      "?////  fdddf,   ",
      "       fdddf.   ",
      "       fdddf,   ",
      "       fdddf,   ",
      "       fdddf.   ",
      "       fdddf.   ",
      "       fdddf,   ",
      "       fffff,   ",
      "11 1qqqqqqqqq6  "
    ],
    [
      "                ",
      "                ",
      "wwwwwwwd        ",
      "      `\u0370\u0370\u0370\u0371\u0370\u0370   ",
      "      `\u0370\u0370\u0370\u0370\u0370\u0371   ",
      "      `\u0370   \u0370\u0370   ",
      "      `\u0370   \u0370\u0370   ",
      "      `\u0370   \u0370\u0370   ",
      "      `\u0370   \u0370\u0370   ",
      "      `\u0370   \u0370\u0370   ",
      "      `\u0370   \u0370\u0370   ",
      "      `\u0370   \u0370\u0370   ",
      "      `\u0370   \u0370\u0371   ",
      "      `\u0370   \u0370\u0370   ",
      "      `\u0370\u0370\u0370\u0370\u0370\u0370   ",
      "qqqqqqqqqqqqq6  "
    ]
  ]
}