{
  "name": "multi_filmworkstower_7_base2",
  "refpalette": "deceasedcraft:multi_filmworkstower_7/multi_filmworkstower_7_base2_palette",
  "xsize": 16,
  "zsize": 16,
  "slices": [
    [
      "aaaaaaaaaaaaabcd",
      "aaaaaaaaaaaaabee",
      "aaaaaaaaaaaaab  ",
      "aaaaaaaaaaaaab  ",
      "aaaaaaaaaaaaab  ",
      "aaaaaaaaaaaaab f",
      "ggggggaaaaaaab  ",
      "aaaaaaaaaaaaabbb",
      "aaaaaaaaaaaaaaaa",
      "aaaaaaaaaaaaaaaa",
      "aaaaaaaaaaaaaaaa",
      "aaaaaaaaaaaaaaaa",
      "aaaaaaaaaaaaaaaa",
      "hhhhhhhhhhhhhhhh",
      "iiiiiiiiiiiiiiii",
      "vvvvvvvvvvvvvvvv"
    ],
    [
      "   j         bee",
      "k  j         b  ",
      "l  j         b  ",
      "   j         b  ",
      "   j         b  ",
      "   j         b f",
      "ggggggm    nob  ",
      "pq           bbb",
      "                ",
      "                ",
      "                ",
      "                ",
      "pq              ",
      "hhhhhhhhhhhhhhhh",
      "iiiiiiiiiiiiiiii",
      "vvvvvvvvvvvvvvvv"
    ],
    [
      "   r         b  ",
      "   r         b  ",
      "s  r         b  ",
      "   r         b  ",
      "   r         b  ",
      "   r         b f",
      "ggggggg     ob  ",
      " q           bbb",
      "                ",
      "                ",
      "                ",
      "                ",
      " q              ",
      "hhhhhhhhhhhhhhhh",
      "iiiiiiiiiiiiiiii",
      "vvvvvvvvvvvvvvvv"
    ],
    [
      "   r         b  ",
      "   r         b  ",
      "   r         b  ",
      "   r         b  ",
      "   r         b  ",
      "   r        tb f",
      "gggggggm    ob  ",
      "pq           bbb",
      "                ",
      "                ",
      "                ",
      "                ",
      "pq              ",
      "hhhhhhhhhhhhhhhh",
      "iiiiiiiiiiiiiiii",
      "vvvvvvvvvvvvvvvv"
    ],
    [
      "   r        ub  ",
      "   r        ub  ",
      "   r        ub  ",
      "   r        ub  ",
      "   r        ub  ",
      "   r        ub w",
      "gggggggg   xob  ",
      " q           bbb",
      "                ",
      "                ",
      "                ",
      "                ",
      " q              ",
      "hhhhhhhhhhhhhhhh",
      "iiiiiiiiiiiiiiii",
      "vvvvvvvvvvvvvvvv"
    ],
    [
      "   r         b  ",
      "   r         b  ",
      "   r         b  ",
      "   r         b  ",
      "   r         b  ",
      "   r         b  ",
      "ggggggggm   ob  ",
      "pq           bbb",
      "                ",
      "                ",
      "                ",
      "                ",
      "pq              ",
      "hhhhhhhhhhhhhhhh",
      "iiiiiiiiiiiiiiii",
      "vvvvvvvvvvvvvvvv"
    ]
  ]
}