{
  "name": "multi_filmworkstower_7_base3",
  "refpalette": "deceasedcraft:multi_filmworkstower_7/multi_filmworkstower_7_base3_palette",
  "xsize": 16,
  "zsize": 16,
  "slices": [
    [
      "aaaaaaaaaaaabbbb",
      "aaaaaaaaaaaabbbb",
      "aaaaaaaaaaaabbbb",
      "aaaaaaaaaaaabbbb",
      "aaaaaaaaaaaabbbb",
      "aaaaaaaaaaaabbbb",
      "abbbbbaaaaaabbbb",
      "aaaaaaaaaaaabbbb",
      "aaaaaaaaaaaabbbb",
      "aaaaaaaaaaaaaaaa",
      "aaaaaaaaaaaaaaaa",
      "aaaaaaaaaaaaaaaa",
      "aaaaaaaaaaaaaaaa",
      "aaaaaaaaaaaaaaaa",
      "aaaaaaaaaaaaaaaa",
      "vvvvvvvvvvvvvvvv"
    ],
    [
      "aaaaaaaaaaaabcde",
      "aaaaaaaaaaaabcff",
      "aaaaaaaaaaaabcff",
      "aaaaaaaaaaaabcff",
      "aaaaaaaaaaaabcfg",
      "aaaaaaaaaaaabcff",
      "abbbbbaaaaaabcff",
      "aaaaaaaaaaaabccc",
      "aaaaaaaaaaaabbbb",
      "aaaaaaaaaaaaaaaa",
      "aaaaaaaaaaaaaaaa",
      "aaaaaaaaaaaaaaaa",
      "aaaaaaaaaaaaaaaa",
      "aaaaaaaaaaaaaaaa",
      "aaaaaaaaaaaaaaaa",
      "vvvvvvvvvvvvvvvv"
    ],
    [
      "aaaaaaaaaaaabche",
      "aaaaaaaaaaaabc  ",
      "aaaaaaaaaaaabcij",
      "aaaaaaaaaaaabc k",
      "aaaaaaaaaaaabc  ",
      "aaaaaaaaaaaabc l",
      "abbbbbaaaaaabc  ",
      "aaaaaaaaaaaabccc",
      "aaaaaaaaaaaabbbb",
      "aaaaaaaaaaaaaaaa",
      "aaaaaaaaaaaaaaaa",
      "aaaaaaaaaaaaaaaa",
      "aaaaaaaaaaaaaaaa",
      "aaaaaaaaaaaaaaaa",
      "aaaaaaaaaaaaaaaa",
      "vvvvvvvvvvvvvvvv"
    ],
    [
      "aaaaaaaaaaaabche",
      "aaaaaaaaaaaabc  ",
      "aaaaaaaaaaaabc  ",
      "aaaaaaaaaaaabc  ",
      "aaaaaaaaaaaabc  ",
      "aaaaaaaaaaaabc l",
      "abbbbbaaaaaabc  ",
      "aaaaaaaaaaaabccc",
      "aaaaaaaaaaaabbbb",
      "aaaaaaaaaaaaaaaa",
      "aaaaaaaaaaaaaaaa",
      "aaaaaaaaaaaaaaaa",
      "aaaaaaaaaaaaaaaa",
      "aaaaaaaaaaaaaaaa",
      "aaaaaaaaaaaaaaaa",
      "vvvvvvvvvvvvvvvv"
    ],
    [
      "aaaaaaaaaaaabchm",
      "aaaaaaaaaaaabc  ",
      "aaaaaaaaaaaabc  ",
      "aaaaaaaaaaaabc  ",
      "aaaaaaaaaaaabc  ",
      "aaaaaaaaaaaabc n",
      "abbbbbaaaaaabc  ",
      "aaaaaaaaaaaabccc",
      "aaaaaaaaaaaabbbb",
      "aaaaaaaaaaaaaaaa",
      "aaaaaaaaaaaaaaaa",
      "aaaaaaaaaaaaaaaa",
      "aaaaaaaaaaaaaaaa",
      "aaaaaaaaaaaaaaaa",
      "aaaaaaaaaaaaaaaa",
      "vvvvvvvvvvvvvvvv"
    ],
    [
      "aaaaaaaaaaaabche",
      "aaaaaaaaaaaabc  ",
      "aaaaaaaaaaaabc  ",
      "aaaaaaaaaaaabc  ",
      "aaaaaaaaaaaabc  ",
      "aaaaaaaaaaaabc n",
      "abbbbbaaaaaabc  ",
      "aaaaaaaaaaaabccc",
      "aaaaaaaaaaaabbbb",
      "aaaaaaaaaaaaaaaa",
      "aaaaaaaaaaaaaaaa",
      "aaaaaaaaaaaaaaaa",
      "aaaaaaaaaaaaaaaa",
      "aaaaaaaaaaaaaaaa",
      "aaaaaaaaaaaaaaaa",
      "vvvvvvvvvvvvvvvv"
    ]
  ]
}