{
  "name": "multi_filmworkstower_7_base1",
  "refpalette": "deceasedcraft:multi_filmworkstower_7/multi_filmworkstower_7_base1_palette",
  "xsize": 16,
  "zsize": 16,
  "slices": [
    [
      "   a         b  ",
      "   a         b  ",
      "   a         b  ",
      "   a         b  ",
      "   a         b  ",
      "   a         b  ",
      "ccccccccc   db  ",
      " e f         bbb",
      "   f            ",
      "   f            ",
      "   f            ",
      "   f            ",
      " e f            ",
      "gggggggggggggggg",
      "hhhhhhhhhhhhhhhh",
      "vvvvvvvvvvvvvvvv"
    ],
    [
      "   a         b  ",
      "   a         b  ",
      "   a         b  ",
      "   a         b  ",
      "   a         b  ",
      "   a        ib  ",
      "cccccccccj kdb  ",
      "le a         bbb",
      "   a            ",
      "   a            ",
      "   a            ",
      "   a            ",
      "le a            ",
      "gggggggggggggggg",
      "hhhhhhhhhhhhhhhh",
      "vvvvvvvvvvvvvvvv"
    ],
    [
      "   a        mb  ",
      "   a        mb  ",
      "   a        mb  ",
      "   a        mb  ",
      "   a        mb  ",
      "   a        mb  ",
      "ccccccccccnndb  ",
      " e a         bbb",
      "   a            ",
      "   a            ",
      "   a            ",
      "   a            ",
      " e a            ",
      "gggggggggggggggg",
      "hhhhhhhhhhhhhhhh",
      "vvvvvvvvvvvvvvvv"
    ],
    [
      "   a            ",
      "   a            ",
      "   a            ",
      "   a            ",
      "   a            ",
      "   a            ",
      "ccccccccccjodp  ",
      " e a            ",
      "   a            ",
      "   a            ",
      "   a            ",
      "   a            ",
      " e a            ",
      "gggggggggggggggg",
      "hhhhhhhhhhhhhhhh",
      "vvvvvvvvvvvvvvvv"
    ],
    [
      "qqqrsssssssstsuw",
      "qqqrsssssssstsuw",
      "qqqrsssssssstsuw",
      "qqqrsssssssstsuw",
      "qqqrsssssssstsuw",
      "qqqrsssssssstsuu",
      "cccccccccccsxsss",
      "qqqrssssssssssss",
      "qqqrssssssssssss",
      "qqqrssssssssssss",
      "qqqrssssssssssss",
      "qqqrssssssssssss",
      "qqqrssssssssssss",
      "gggggggggggggggg",
      "hhhhhhhhhhhhhhhh",
      "vvvvvvvvvvvvvvvv"
    ],
    [
      "cccccccccccccccc",
      "cccccccccccccccc",
      "cccccccccccccccc",
      "cccccccccccccccc",
      "cccccccccccccccc",
      "cccccccccccccccc",
      "ccccccccccccc cc",
      "cccccccccccccccc",
      "cccccccccccccccc",
      "cccccccccccccccc",
      "cccccccccccccccc",
      "cccccccccccccccc",
      "cccccccccccccccc",
      "gggggggggggggggg",
      "hhhhhhhhhhhhhhhh",
      "vvvvvvvvvvvvvvvv"
    ]
  ]
}