{
  "name": "multi_filmworkstower_7_floor3",
  "refpalette": "deceasedcraft:multi_filmworkstower_7/multi_filmworkstower_7_floor3_palette",
  "xsize": 16,
  "zsize": 16,
  "slices": [
    [
      "     ab         ",
      "    acb         ",
      "     ab         ",
      "     ab         ",
      "    acb         ",
      "     ab         ",
      "      d         ",
      "      e         ",
      "      f         ",
      "      ffffffffff",
      "                ",
      "                ",
      "                ",
      "                ",
      "                ",
      "                "
    ],
    [
      "      agh       ",
      "     acgh       ",
      "      agh       ",
      "      agh       ",
      "     acgh       ",
      "      agh       ",
      "       dd     ij",
      "       ee       ",
      "       ff       ",
      "       fffffffff",
      "                ",
      "                ",
      "                ",
      "                ",
      "                ",
      "                "
    ],
    [
      "       kcghhhhhh",
      "      accghhhhhh",
      "       kcghhhhhh",
      "       kcghhhhhh",
      "      accghhhhhh",
      "       kcghhhhhh",
      "         dddd dd",
      "         eeeeeee",
      "         fffffff",
      "         fffffff",
      "                ",
      "                ",
      "                ",
      "                ",
      "                ",
      "                "
    ],
    [
      "         kkkkkkk",
      "       kcccccccc",
      "         kkkkkkk",
      "         kkkkkkk",
      "       kcccccccc",
      "         kkkkkkk",
      "                ",
      "                ",
      "                ",
      "                ",
      "                ",
      "                ",
      "                ",
      "                ",
      "                ",
      "                "
    ],
    [
      "                ",
      "                ",
      "                ",
      "                ",
      "                ",
      "                ",
      "                ",
      "                ",
      "                ",
      "                ",
      "                ",
      "                ",
      "                ",
      "                ",
      "                ",
      "                "
    ],
    [
      "                ",
      "                ",
      "                ",
      "                ",
      "                ",
      "                ",
      "                ",
      "                ",
      "                ",
      "                ",
      "                ",
      "                ",
      "                ",
      "                ",
      "                ",
      "                "
    ]
  ]
}