{
  "name": "multi_filmworkstower_7_ground",
  "refpalette": "deceasedcraft:multi_filmworkstower_7/multi_filmworkstower_7_ground_palette",
  "xsize": 16,
  "zsize": 16,
  "slices": [
    [
      "aaaaaaaaab    cd",
      "aaaaaaaaaeb   cd",
      "aaaaaaaaab    cd",
      "aaaaaaaaab    cd",
      "aaaaaaaaaeb   cd",
      "aaaaaaaaab    cd",
      "aaaaaaaaaffff cd",
      "aaaaaaaaafggggcd",
      "ddddddddffggggcd",
      "ffffffffffggggcd",
      "ggggggggggggggcd",
      "ggggggggggggggcd",
      "ggggggggggggggcd",
      "ggggggggggggggcd",
      "ggggggggggggggcd",
      "ggggggggggggggcd"
    ],
    [
      "         hb    i",
      "         jeb   i",
      "         ab    i",
      "         ab    i",
      "         aeb   i",
      "         ab    i",
      "         jfffk i",
      "         lb    i",
      "mmmmmmmmdenn   i",
      "oooooooooo     i",
      "               i",
      "               i",
      "               i",
      "               i",
      "               i",
      "                "
    ],
    [
      "          hb    ",
      "         jjeb   ",
      "         pjb    ",
      "         qjb    ",
      "         qjeb   ",
      "         rjb    ",
      "         jjfffk ",
      "         slb    ",
      "mmmmmmmmmdenn   ",
      "ooooooooooo     ",
      "                ",
      "                ",
      "                ",
      "                ",
      "                ",
      "                "
    ],
    [
      "           hb   ",
      "           hebt ",
      "           jb   ",
      "           ab   ",
      "           aebt ",
      "           ab   ",
      "           jfffk",
      "          slb   ",
      "m mmmmmmmmdenn  ",
      "oooooooooooo    ",
      "                ",
      "                ",
      "                ",
      "                ",
      "                ",
      "                "
    ],
    [
      "            hb  ",
      "            heb ",
      "           jjb  ",
      "           pjb  ",
      "           qjeb ",
      "           rjb  ",
      "           jjfff",
      "           slb  ",
      "  mm  mmmmmdenn ",
      "ooooooooooooo   ",
      "                ",
      "                ",
      "                ",
      "                ",
      "                ",
      "                "
    ],
    [
      "             hb ",
      "             heb",
      "             hb ",
      "             jb ",
      "             aeb",
      "             ab ",
      "             jff",
      "            slb ",
      "       m mmmdenn",
      "oooooooooooooo  ",
      "                ",
      "                ",
      "                ",
      "                ",
      "                ",
      "                "
    ]
  ]
}