{
  "name": "multi_communitycenter_2_base1",
  "refpalette": "deceasedcraft:multi_communitycenter_2/multi_communitycenter_2_base1_palette",
  "xsize": 16,
  "zsize": 16,
  "slices": [
    [
      "vHHHHHHHHHHHHHHH",
      "vHHHHHHHHHHHHHHH",
      "vHHHHHHHHHHHHHHH",
      "vHHHHHHHHHHHHHHH",
      "vHHHHHHHHHHHHHHH",
      "vHHHHHHHHHHHHHHH",
      "vHHHHHHHHHHHHHHH",
      "vHHHHHHHHHHHHHHH",
      "vHHHHHHHHHHHHHHH",
      "vHHHHHHHHHHHHHHH",
      "vHHHHHHHHHHHHHHH",
      "vHHHHHHHHHHHHHHH",
      "vHHHHHHHHHHHHHHH",
      "vHHHHHHHHHHHHHHH",
      "vHHHHHHHHHHHHHHH",
      "vvvvvvvvvvvvvvvv"
    ],
    [
      "vaaaab    b    b",
      "vaaaa cdcd      ",
      "vaaaa           ",
      "vaaaa           ",
      "vaaaa           ",
      "vaaaa           ",
      "vaaaa efef efef ",
      "vaaaab    b    b",
      "vaaaa           ",
      "vaaaa cdcd cdcd ",
      "vaaaaaaaaaaaaaaa",
      "vaaaaaaaaaaaaaaa",
      "vaaaaaaaaaaaaaaa",
      "vaaaaaaaaaaaaaaa",
      "vaaaaaaaaaaaaaaa",
      "vvvvvvvvvvvvvvvv"
    ],
    [
      "vaaaab    b    b",
      "vaaaa           ",
      "vaaaa           ",
      "vaaaa           ",
      "vaaaa           ",
      "vaaaa           ",
      "vaaaa           ",
      "vaaaab    b    b",
      "vaaaa           ",
      "vaaaa           ",
      "vaaaaaaaaaaaaaaa",
      "vaaaaaaaaaaaaaaa",
      "vaaaaaaaaaaaaaaa",
      "vaaaaaaaaaaaaaaa",
      "vaaaaaaaaaaaaaaa",
      "vvvvvvvvvvvvvvvv"
    ],
    [
      "vaaaab    b    b",
      "vaaaa           ",
      "vaaaa           ",
      "vaaaa           ",
      "vaaaa           ",
      "vaaaa           ",
      "vaaaa           ",
      "vaaaab    b    b",
      "vaaaa           ",
      "vaaaa!          ",
      "vaaaaaaaaaaaaaaa",
      "vaaaaaaaaaaaaaaa",
      "vaaaaaaaaaaaaaaa",
      "vaaaaaaaaaaaaaaa",
      "vaaaaaaaaaaaaaaa",
      "vvvvvvvvvvvvvvvv"
    ],
    [
      "vaaaabggggbggggb",
      "vaaaab    b    b",
      "vaaaab    b    b",
      "vaaaab    b    b",
      "vaaaab    b    b",
      "vaaaab    b    b",
      "vaaaab    b    b",
      "vaaaabggggbggggb",
      "vaaaab    b    b",
      "vaaaab    b    b",
      "vaaaaaaaaaaaaaaa",
      "vaaaaaaaaaaaaaaa",
      "vaaaaaaaaaaaaaaa",
      "vaaaaaaaaaaaaaaa",
      "vaaaaaaaaaaaaaaa",
      "vvvvvvvvvvvvvvvv"
    ],
    [
      "vaaaaaaaaaaaaaaa",
      "vaaaaaaaaaaaaaaa",
      "vaaaaaaaaaaaaaaa",
      "vaaaaaaaaaaaaaaa",
      "vaaaaaaaaaaaaaaa",
      "vaaaaaaaaaaaaaaa",
      "vaaaaaaaaaaaaaaa",
      "vaaaaaaaaaaaaaaa",
      "vaaaaaaaaaaaaaaa",
      "vaaaaaaaaaaaaaaa",
      "vaaaaaaaaaaaaaaa",
      "vaaaaaaaaaaaaaaa",
      "vaaaaaaaaaaaaaaa",
      "vaaaaaaaaaaaaaaa",
      "vaaaaaaaaaaaaaaa",
      "vvvvvvvvvvvvvvvv"
    ]
  ]
}