{
  "name": "multi_communitycenter_2_ground",
  "refpalette": "deceasedcraft:multi_communitycenter_2/multi_communitycenter_2_ground_palette",
  "xsize": 16,
  "zsize": 16,
  "slices": [
    [
      "aaaabbccccccdbbb",
      "aaaaabccccccdbbb",
      "aaaaabbcccccbdbb",
      "aaaaaabcccccbbdd",
      "aaaaaabbcccbeeee",
      "aafaaaabbcbeeeee",
      "aafgaaaabbeeeeee",
      "aafggaaaabbeeeee",
      "aaffggaaaabbeeee",
      "aafffffaaaabbbee",
      "aaaaaaffaaaaabbb",
      "aahhhafggaaaaaab",
      "aahhhafgfgaaaaaa",
      "aahhhafffffaaaaa",
      "aaaaaaaaaaaaaaaa",
      "aaaaaaaaaaaaaaaa"
    ],
    [
      "    iij         ",
      "     ikkk   l   ",
      "     ii m   nn  ",
      "      i     nnl ",
      " o    iikkknp   ",
      " o     ii!nqr   ",
      " o      iis r t ",
      " uw      ii   t ",
      " ux       ii  n ",
      " uyAB      iii  ",
      " uuuuu       iii",
      " ufffuw        i",
      " ufhfux         ",
      " ufffuyAB       ",
      " uuuuuuuuooo    ",
      "                "
    ],
    [
      "    CC          ",
      "     C D    l   ",
      "     ii     nn  ",
      "      C     nnl ",
      "      CCE Fn    ",
      "       CCInI    ",
      "        ii  J r ",
      "         iC   p ",
      "          CC  r ",
      "  K        CCi  ",
      " ooooo       iCC",
      " o   o         C",
      " o L o          ",
      " o   oK         ",
      " ooooo          ",
      "                "
    ],
    [
      "    CC          ",
      "     C      l   ",
      "     ii     nn  ",
      "      C     nnl ",
      "      CC   n    ",
      "       CC n     ",
      "        ii    J ",
      "         iC   J ",
      "          CC  J ",
      "           CCi  ",
      "             iCC",
      "               C",
      "   L            ",
      "                ",
      "                ",
      "                "
    ],
    [
      "    ii      M   ",
      "     i      l   ",
      "     ii     nn  ",
      "      i     nnll",
      "      ii   n    ",
      "       iiIn     ",
      "        ii      ",
      "         ii     ",
      "          ii    ",
      "           iii  ",
      "  NNN        iii",
      " NNNNN         i",
      " NNLNN          ",
      " NNNNN          ",
      "  NNN           ",
      "                "
    ],
    [
      "    iiOOOOOnnPP ",
      "     iOOOOOOnP  ",
      "     iiOOOOOnn  ",
      "      iOOOOOnnnn",
      "      iiOOOnOOOn",
      "       iiOnOOOOO",
      "        iiOOOOOO",
      "         iiOOOOO",
      "          iiOOOO",
      "           iiiOO",
      "             iii",
      "   N           i",
      "  NLN           ",
      "   N            ",
      "                ",
      "                "
    ]
  ]
}