{
  "name": "multi_sunkenmonumentpark_8_ground",
  "refpalette": "deceasedcraft:multi_sunkenmonumentpark_8/multi_sunkenmonumentpark_8_ground_palette",
  "xsize": 16,
  "zsize": 16,
  "slices": [
    [
      "aabbcccccccccccc",
      "aabbcccccccccccc",
      "aabbccdddddddddd",
      "aabbcddddddddddd",
      "eebbcfffffffffff",
      "ggccc   h hi    ",
      "  ccc hi  j  i i",
      "  ccc           ",
      "  ccc      k k  ",
      "  lccc k k      ",
      "  mmml        k ",
      "    mm          ",
      "        k     k ",
      "          n     ",
      "              n ",
      "                "
    ],
    [
      "                ",
      "               h",
      "        i h h   ",
      "    o h  j  i hj",
      "    o           ",
      "  ppo      k    ",
      "  ppc  k  q  k k",
      "  ppc           ",
      "  bbc      n n  ",
      "  bbbc n n      ",
      "  bbbc        n ",
      "  cccc          ",
      "  ccccc n     n ",
      "  ccccc   n     ",
      "mmmmccc       n ",
      "mmmmmmmm        "
    ],
    [
      "                ",
      "                ",
      "        k       ",
      "         q  k  q",
      "                ",
      "           n    ",
      "    o  n  k  n n",
      "    o           ",
      "    o      n n  ",
      "     r n n      ",
      "     o        n ",
      "  pppo          ",
      "  ppppc n     n ",
      "  ppppc   s     ",
      "ccbbbbc       s ",
      "bbbbbbbc        "
    ],
    [
      "                ",
      "                ",
      "        n       ",
      "         k  n  k",
      "                ",
      "           n    ",
      "       n  n  n n",
      "                ",
      "           n s  ",
      "       s s      ",
      "              s ",
      "                ",
      "      r s     s ",
      "tt    o         ",
      "u     o         ",
      "       r        "
    ],
    [
      "                ",
      "                ",
      "        n       ",
      "         n  n  n",
      "                ",
      "           s    ",
      "       s  n  s s",
      "                ",
      "                ",
      "                ",
      "                ",
      "                ",
      "                ",
      "                ",
      "                ",
      "                "
    ],
    [
      "                ",
      "                ",
      "        s       ",
      "         n  s  n",
      "                ",
      "                ",
      "          s     ",
      "                ",
      "                ",
      "                ",
      "                ",
      "                ",
      "                ",
      "                ",
      "                ",
      "                "
    ]
  ]
}