{
  "name": "multi_sunkenmonumentpark_8_base1",
  "refpalette": "deceasedcraft:multi_sunkenmonumentpark_8/multi_sunkenmonumentpark_8_base1_palette",
  "xsize": 16,
  "zsize": 16,
  "slices": [
    [
      "vvvvvvvvvvvvvvvv",
      "aaaaaaaaaaaaaaaa",
      "aaaaaaaaaaaaaaaa",
      "aaaaaaaaaaaaaaaa",
      "aaaaaaaaaaaaaaaa",
      "aaaaaaaaaaaaaaaa",
      "aaaaaaaaaaaaaaaa",
      "aaaaaaaaaaaaaaaa",
      "aaaaaaaaaaaaaaaa",
      "aaaaaaaaaaaaaaaa",
      "aaaaaaaaaaaaaaaa",
      "aaaaaaaaaaaaaaaa",
      "aaaaaaaaaaaaaaaa",
      "aaaaaaaaaaaaaaaa",
      "aaaaaaaaaaaaaaaa",
      "aaaaaaaaaaaaaaaa"
    ],
    [
      "vvvvvvvvvvvvvvvv",
      "aaaaaaaaaaaaaaaa",
      "aaaaaaaaaaaaaaaa",
      "aaaaaaaaaaaaaaaa",
      "aaaaaaaaaaaaaaaa",
      "aaaaaaaaaaaaaaaa",
      "aaaaaaaaaaaaaaaa",
      "aaaaaaaaaaaaaaaa",
      "aaaaaaaaaaaaaaaa",
      "aaaaaaaaaaaaaaaa",
      "aaaaaaaaaaaaaaaa",
      "aaaaaaaaaaaaaaaa",
      "aaaaaaaaaaaaaaaa",
      "aaaaaaaaaaaaaaaa",
      "aaaaaaaaaaaaaaaa",
      "aaaaaaaaaaaaaaaa"
    ],
    [
      "vvvvvvvvvvvvvvvv",
      "aaaaaaaaaaaaaaaa",
      "aaaaaaaaaaaaaaaa",
      "aaaaaaaaaaaaaaaa",
      "aaaaaaaaaaaaaaaa",
      "aaaaaaaaaaaaaaaa",
      "aaaaaaaaaaaaaaaa",
      "aaaaaaaaaaaaaaaa",
      "aaaaaaaaaaaaaaaa",
      "aaaaaaaaaaaaaaaa",
      "aaaaaaaaaaaaaaaa",
      "aaaaaaaaaaaaaaaa",
      "aaaaaaaaaaaaaaaa",
      "bbcccccccaaaaaaa",
      "bbccccccccccaaaa",
      "bbcccccccccccaaa"
    ],
    [
      "vvvvvvvvvvvvvvvv",
      "dddddaaaaaaaaaaa",
      "dddddaaaaaaaaaaa",
      "dddddaaaaaaaaaaa",
      "dddddaaaaaaaaaaa",
      "dddddaaaaaaaaaaa",
      "aaaaaaaaaaaaaaaa",
      "aaaaaaaaaaaaaaaa",
      "aaaaaaaaaaaaaaaa",
      "aaaaaaaaaaaaaaaa",
      "bbccccccccccccaa",
      "bbcccccccccccccc",
      "bbcccccccccccccc",
      "eefffffffccccccc",
      "gg       fffcccc",
      "          h fccc"
    ],
    [
      "vvvvvvvvvvvvvvvv",
      "ddddd           ",
      "ddddd           ",
      "ddddd           ",
      "ddddd           ",
      "ddddd           ",
      "bbddd           ",
      "bbcccccccccccccc",
      "bbcccccccccccccc",
      "bbcccccccccccccc",
      "eeffffffffffffcc",
      "gg    h h  h  ff",
      "   h    i     i ",
      "          j     ",
      "            h j ",
      "                "
    ],
    [
      "vvvvvvvvvvvvvvvv",
      "ddddd           ",
      "ddddd           ",
      "ddddd           ",
      "dddddccccccccccc",
      "bbdddccccccccccc",
      "bbdddccccccccccc",
      "eedddfffffffffff",
      "gg kl    h j j  ",
      "      hj j  h   ",
      "              j ",
      "                ",
      "        m     m ",
      "          n     ",
      "              n ",
      "                "
    ]
  ]
}