{
  "xsize": 16,
  "zsize": 16,
  "refpalette": "lce2:offshore",
  "slices": [
    [
      "       !!       ",
      " !AA! !!!! !AA! ",
      " B  B  !!  B  B ",
      " B  B      B  B ",
      " !AA!      !AA! ",
      "                ",
      " !            ! ",
      "!!!          !!!",
      "!!!          !!!",
      " !            ! ",
      "                ",
      " !AA!      !AA! ",
      " B  B      B  B ",
      " B  B  !!  B  B ",
      " !AA! !!!! !AA! ",
      "       !!       "
    ],
    [
      "DDDDDDDDDDDDDDDD",
      "DDDDDDDDDDDDDDDD",
      "DDDDDDDDDDDDDDDD",
      "DDDDDDDDDDDDDDDD",
      "DDDDDDDDDDDDDDDD",
      "!!!!!!!!!!!!!!!!",
      "!!!!!!!!!!!!!!!!",
      "!!!!!!!!!!!!!!!!",
      "!!!!!!!!!!!!!!!!",
      "!!!!!!!!!!!!!!!!",
      "!!!!!!!!!!!!!!!!",
      "!!!!!!!!!!!!!!!!",
      "!!!!!!!!!!!!!!!!",
      "!!!!!!!!!!!!!!!!",
      "!!!!!!!!!!!!!!!!",
      "!!!!!!!!!!!!!!!!"
    ],
    [
      "                ",
      "                ",
      "                ",
      "                ",
      "                ",
      "                ",
      "                ",
      "                ",
      "                ",
      "                ",
      "                ",
      "                ",
      "                ",
      "                ",
      "                ",
      "      &         "
    ],
    [
      "                ",
      "                ",
      "                ",
      "                ",
      "                ",
      "                ",
      "                ",
      "                ",
      "                ",
      "                ",
      "                ",
      "                ",
      "                ",
      "                ",
      "                ",
      "      &         "
    ],
    [
      "                ",
      "                ",
      "                ",
      "                ",
      "                ",
      "                ",
      "                ",
      "                ",
      "                ",
      "                ",
      "                ",
      "                ",
      "                ",
      "                ",
      "                ",
      "      &         "
    ],
    [
      "                ",
      "                ",
      "                ",
      "                ",
      "                ",
      "                ",
      "                ",
      "                ",
      "                ",
      "                ",
      "                ",
      "                ",
      "                ",
      "                ",
      "                ",
      "      !!!!!!!!!!"
    ]
  ]
}