{
  "xsize": 16,
  "zsize": 16,
  "refpalette": "lce2:offshore",
  "slices": [
    [
      "              !!",
      "              !!",
      "              !!",
      "              !!",
      "              !!",
      "              !!",
      "             !!!",
      "             !!!",
      "              !!",
      "              !!",
      "              !!",
      "              !!",
      "              !!",
      "              !!",
      "              !!",
      "             !!!"
    ],
    [
      "               #",
      "              ##",
      "              ##",
      "              ##",
      "              ##",
      "              ##",
      "              ##",
      "              ##",
      "              ##",
      "              ##",
      "              ##",
      "               #",
      "               #",
      "               #",
      "               !",
      "             !!!"
    ],
    [
      "!!!!!!!!!!     #",
      "!!!!!!!!!!    ##",
      "!!!!!!!!!!    ##",
      "!!!!!!!!!!    ##",
      "!!!!!!!!!!    ##",
      "!!!!!!!!!!    ##",
      "!!!!!!!!!!    ##",
      "!!!!!!!!!!    ##",
      "!!!!!!!!!!    ##",
      "!!!!!!!!!!    ##",
      "!!!!!!!!!!    ##",
      "!!!!!!!!!!     #",
      "!!!!!!!!!!     #",
      "!!!!!!!!!!     #",
      "!!!!!!!!!!      ",
      "!!!!!!!!!!      "
    ],
    [
      "       !!       ",
      " !AA! !!!!      ",
      " B  B  !!       ",
      " B  B           ",
      " !AA!           ",
      "                ",
      " !              ",
      "!!!             ",
      "!!!             ",
      " !              ",
      "                ",
      " !AA!           ",
      " B  B           ",
      " B  B  !!       ",
      " !AA! !!!!      ",
      "       !!       "
    ],
    [
      "                ",
      " )((*  !!       ",
      " =  =           ",
      " =  =           ",
      " +((,           ",
      "                ",
      "                ",
      " !              ",
      " !              ",
      "                ",
      "                ",
      " )((*           ",
      " =  =           ",
      " =  =           ",
      " +((,  !!       ",
      "                "
    ],
    [
      "                ",
      " )((*  !!       ",
      " =  =           ",
      " =  =           ",
      " +((,           ",
      "                ",
      "                ",
      " !              ",
      " !              ",
      "                ",
      "                ",
      " )((*           ",
      " =  =           ",
      " =  =           ",
      " +((,  !!       ",
      "                "
    ]
  ]
}