{
  "xsize": 16,
  "zsize": 16,
  "refpalette": "lce2:offshore",
  "slices": [
    [
      "                ",
      " )((** !!! )(((*",
      " == ==     ==  =",
      " == ==     ==  =",
      " +((,,     +(((,",
      "                ",
      "                ",
      " !!            !",
      " !!            !",
      "                ",
      "                ",
      " )((**     )(((*",
      "#== ==     ==  =",
      "#== ==     ==  =",
      "#+((,, !!! +(((,",
      "#               "
    ],
    [
      "       !!!      ",
      " !AA!!!!!!!!AAA!",
      " BB BB !!! BB  B",
      " BB BB     BB  B",
      " !AA!!     !AAA!",
      "                ",
      " !!            !",
      "!!!!          !!",
      "!!!!          !!",
      ".!!            !",
      "..              ",
      " !AA!!     !AAA!",
      "#BB BB     BB  B",
      "#BB BB !!! BB  B",
      "#!AA!!!!!!!!AAA!",
      "#      !!!      "
    ],
    [
      "!!!!!!!!!!!!!!!!",
      "!!!!!!!!!!!!!!!!",
      "!!!!!!!!!!!!!!!!",
      "!!!!!!!!!!!!!!!!",
      "!!!!!!!!!!!!!!!!",
      "!!!!!!!!!!!!!!!!",
      "!!!!!!!!!!!!!!!!",
      "!!!!!!!!!!!!!!!!",
      "!!!!!!!!!!!!!!!!",
      "!!!!!!!!!!!!!!!!",
      "!!!!!!!!!!!!!!!!",
      "!!!!!!!!!!!!!!!!",
      "!!!!!!!!!!!!!!!!",
      "!!!!!!!!!!!!!!!!",
      "!!!!!!!!!!!!!!!!",
      "!!!!!!!!!!!!!!!!"
    ],
    [
      "                ",
      "                ",
      "                ",
      "                ",
      "                ",
      "                ",
      "                ",
      "                ",
      "                ",
      "..              ",
      "...             ",
      " .              ",
      "                ",
      "                ",
      "        !!!!!   ",
      "        !!!!!   "
    ],
    [
      "                ",
      "                ",
      "                ",
      "                ",
      "                ",
      "                ",
      "                ",
      "                ",
      "                ",
      " .              ",
      "...             ",
      " .              ",
      "                ",
      "                ",
      "          !     ",
      "         !!!    "
    ],
    [
      "                ",
      "                ",
      "                ",
      "                ",
      "                ",
      "                ",
      "                ",
      "                ",
      "                ",
      " .              ",
      "...             ",
      " .              ",
      "                ",
      "                ",
      "          !     ",
      "         !!!    "
    ]
  ]
}