{
  "xsize": 16,
  "zsize": 16,
  "refpalette": "lce2:offshore",
  "slices": [
    [
      "                ",
      "                ",
      "                ",
      "                ",
      "                ",
      "         NOPPPPP",
      "    MMMMMMMMMMMM",
      "QQRPPPPPPPPPPPPP",
      "    MMMMMMMMMMMM",
      "         NOPPPPP",
      "                ",
      "                ",
      "                ",
      "                ",
      "                ",
      "                "
    ],
    [
      "               M",
      "              MM",
      "              MM",
      "             MMM",
      "           SPPPP",
      "      TMOOPPPPPP",
      " UPPPPPPPPPPPPPP",
      "vvPPPPPPPPPPPPPP",
      " UPPPPPPPPPPPPPP",
      "       MOOPPPPPP",
      "           SPPPP",
      "             MMM",
      "              MM",
      "              MM",
      "               M",
      "               M"
    ],
    [
      "                ",
      "                ",
      "                ",
      "                ",
      "                ",
      "                ",
      "     SSSPPSSSSS ",
      "  SSVVVVVVPPPPPP",
      "     SSSPPSSSSS ",
      "                ",
      "                ",
      "                ",
      "                ",
      "                ",
      "                ",
      "                "
    ],
    [
      "                ",
      "                ",
      "                ",
      "                ",
      "                ",
      "                ",
      "                ",
      "     WVVWX      ",
      "                ",
      "                ",
      "                ",
      "                ",
      "                ",
      "                ",
      "                ",
      "                "
    ],
    [
      "                ",
      "                ",
      "                ",
      "                ",
      "                ",
      "                ",
      "                ",
      "                ",
      "                ",
      "                ",
      "                ",
      "                ",
      "                ",
      "                ",
      "                ",
      "                "
    ],
    [
      "                ",
      "                ",
      "                ",
      "                ",
      "                ",
      "                ",
      "                ",
      "                ",
      "                ",
      "                ",
      "                ",
      "                ",
      "                ",
      "                ",
      "                ",
      "                "
    ]
  ]
}