{
  "xsize": 16,
  "zsize": 16,
  "refpalette": "lce2:offshore",
  "slices": [
    [
      "                ",
      "                ",
      "                ",
      "                ",
      "                ",
      "                ",
      "                ",
      "                ",
      "     !          ",
      "    !!!         ",
      "!!!!!!!!        ",
      "    !!!         ",
      "     !          ",
      "#    !          ",
      "!#   !          ",
      "#!#             "
    ],
    [
      "                ",
      "                ",
      "                ",
      "                ",
      "                ",
      "                ",
      "                ",
      "                ",
      "     !          ",
      "    !!!         ",
      "   !!!!!        ",
      "!!!!!!!         ",
      "!!!!!!          ",
      "#!!!!           ",
      "!#!!!           ",
      " ! !!           "
    ],
    [
      "                ",
      "                ",
      "                ",
      "                ",
      "                ",
      "                ",
      "                ",
      "                ",
      "    !!!         ",
      "   !!!!!        ",
      "   !!!!!        ",
      "!!!!!!!!        ",
      "!!!!!!!!        ",
      "#!!!!           ",
      "!#!!!           ",
      "##              "
    ],
    [
      "!!!!!!!!!!!!!!!!",
      "!!!!!!!!!!!!!!!!",
      "!!!!!!!!!!!!!!!!",
      "!!!!!!!!!!!!!!!!",
      "!!!!!!!!!!!!!!!!",
      "!!!!!!!!!!!!!!!!",
      "!!!!!!!!!!!!!!!!",
      "!!!!!!!!!!!!!!!!",
      "!!!!!!!!!!!!!!!!",
      "!!!!!!!!!!!!!!!!",
      "!!!!!!!!!!!!!!!!",
      "!!!!!!!!!!!!!!!!",
      "!!!!!!!!!!!!!!!!",
      "!!!!!!!!!!!!!!!!",
      "!!!!!!!!!!!!!!!!",
      "!!!!!!!!!!!!!!!!"
    ],
    [
      "       !!!      ",
      " !AA!!!!!!!!AA!!",
      " BB BB !!! BB BB",
      " BB BB     BB BB",
      " !AA!!     !AA!!",
      "                ",
      " !!           !!",
      "!!!!         !!!",
      "!!!! !       !!!",
      " !! !!!       !!",
      "   !!!!!        ",
      " !AA!!!    !AA!!",
      " BB BB     BB BB",
      " BB BB !!! BB BB",
      "!!AA!!!!!!!!AA!!",
      " !      !!      "
    ],
    [
      "                ",
      " )((** !!! )((**",
      " == ==     == ==",
      " == ==     == ==",
      " +((,,     +((,,",
      "                ",
      "                ",
      " !!           !!",
      " !!  !        !!",
      "    !!!         ",
      "!!!!!!!!        ",
      " )((**!    )((**",
      " == ==     == ==",
      " == ==     == ==",
      "!+((,, !!! +((,,",
      " !   !          "
    ]
  ]
}