{
  "name": "multi_filmworkstower_14_base2",
  "refpalette": "deceasedcraft:multi_filmworkstower_14/multi_filmworkstower_14_base2_palette",
  "xsize": 16,
  "zsize": 16,
  "slices": [
    [
      " abbbbbbbcccccbb",
      " abbbbbbbcccccbb",
      "dabbbbbbbcccccbb",
      "eabbbbbbbcccccbb",
      " abbbbbbbcccccbb",
      " abbbbbbbcccccbb",
      "dabbbbbbbcccccbb",
      " abbbbbbbcccccbb",
      " abbbbbbbcccccbb",
      " abbbbbbbfffffbb",
      " abbbbbbbcccccbb",
      " abbbbbbbcccccbb",
      "dabbbbbbbcccccbb",
      " abbbbbbbcccccbb",
      " abbbbbbbcccccbb",
      " abbbbbbbcccccbb"
    ],
    [
      "ga      h  i  j ",
      "ka      hlmmmnj ",
      "oa      hpppppj ",
      "oa      hpppppj ",
      " a      hqrrrsj ",
      " a      h  i  j ",
      "ta      u     j ",
      " a      h     j ",
      " a      hwxyABj ",
      " aCD    EfffffF ",
      " a      hI   wj ",
      " a      hJ   Kj ",
      "ta      hJi  Lj ",
      " a      hJ   Mj ",
      " a      hN    j ",
      " a      hO    P "
    ],
    [
      " a      h     j ",
      " a      hQ !RSj ",
      " a      hpppppj ",
      " a      hTTTTTj ",
      " a      hUV WXj ",
      "Ya      h     j ",
      "da      Z     j ",
      " a      h     j ",
      " a      h0    j ",
      " aC     fffffff ",
      " a      h1   2j ",
      " a      h3    j ",
      "da      h4    j ",
      "5a      h     j ",
      " a      h     j ",
      " a      h     6 "
    ],
    [
      " a      h     j ",
      " a      h78889j ",
      " a      hpppppj ",
      " a      hTTTTTj ",
      " a      h#$$$%j ",
      " a      h     j ",
      " a      ^     j ",
      "Ya      h     j ",
      " a&     h    *j ",
      " aC    EfffffffF",
      " a(     h) +- j ",
      "5a      h[    j ",
      " a      h[    j ",
      " a      h[    j ",
      " a      h]    j ",
      " a      h     { "
    ],
    [
      " a}     h|||||j ",
      " a}     h|||||j ",
      " a}     hpppppj ",
      " a}     hpppppj ",
      " a}     h|||||j ",
      " a}     h|||||j ",
      " a}     h|||||j ",
      " a}     h|||||j ",
      "Ya}     h|||||j ",
      ";aC:   fffffffff",
      "5a}     h|||||j ",
      " a}     h|||||j ",
      " a}     h|||||j ",
      " a}     h|||||j ",
      " a}     h|||||j ",
      " a}     h|||||j "
    ],
    [
      " a              ",
      " a              ",
      " a              ",
      " a              ",
      " a              ",
      " a              ",
      " a              ",
      " a              ",
      " a              ",
      " aC   Efff'<>fff",
      " a              ",
      " a              ",
      " a              ",
      " a              ",
      " a              ",
      " a              "
    ]
  ]
}