{
  "name": "multi_filmworkstower_14_base1",
  "refpalette": "deceasedcraft:multi_filmworkstower_14/multi_filmworkstower_14_base1_palette",
  "xsize": 16,
  "zsize": 16,
  "slices": [
    [
      " a              ",
      " a              ",
      " a              ",
      " a              ",
      " a              ",
      " a              ",
      " a              ",
      " a              ",
      " a              ",
      " ab   cccd   ecc",
      " a              ",
      " a              ",
      " a              ",
      " a              ",
      " a              ",
      " a              "
    ],
    [
      " a              ",
      " a              ",
      " a              ",
      " a              ",
      " a              ",
      " a              ",
      " a              ",
      " a              ",
      " af             ",
      " abg hccd     ec",
      " ai             ",
      " a              ",
      " a              ",
      " a              ",
      " a              ",
      " a              "
    ],
    [
      " aj             ",
      " aj             ",
      " aj             ",
      " aj             ",
      " aj             ",
      " aj             ",
      " aj             ",
      " aj             ",
      " aj             ",
      " abkkccd       e",
      " aj             ",
      " aj             ",
      " aj             ",
      " aj             ",
      " aj             ",
      " aj             "
    ],
    [
      "                ",
      "                ",
      "                ",
      "                ",
      "                ",
      "                ",
      "                ",
      "                ",
      "                ",
      " lbmhcd         ",
      "                ",
      "                ",
      "                ",
      "                ",
      "                ",
      "                "
    ],
    [
      "nopooooooooooooo",
      "nopooooooooooooo",
      "nopooooooooooooo",
      "nopooooooooooooo",
      "nopooooooooooooo",
      "nopooooooooooooo",
      "nopooooooooooooo",
      "nopooooooooooooo",
      "nopooooooooooooo",
      "noqoccoooooooooo",
      "nopooooooooooooo",
      "nopooooooooooooo",
      "nopooooooooooooo",
      "nopooooooooooooo",
      "nopooooooooooooo",
      "nopooooooooooooo"
    ],
    [
      "cccccccccccccccc",
      "cccccccccccccccc",
      "cccccccccccccccc",
      "cccccccccccccccc",
      "cccccccccccccccc",
      "cccccccccccccccc",
      "cccccccccccccccc",
      "cccccccccccccccc",
      "cccccccccccccccc",
      "c cccccccccccccc",
      "cccccccccccccccc",
      "cccccccccccccccc",
      "cccccccccccccccc",
      "cccccccccccccccc",
      "cccccccccccccccc",
      "cccccccccccccccc"
    ]
  ]
}