{
  "name": "multi_filmworkstower_14_base3",
  "refpalette": "deceasedcraft:multi_filmworkstower_14/multi_filmworkstower_14_base3_palette",
  "xsize": 16,
  "zsize": 16,
  "slices": [
    [
      "aaabbbbbbbbbbbbb",
      "aaabbbbbbbbbbbbb",
      "aaabbbbbbbbbbbbb",
      "aaabbbbbbbbbbbbb",
      "aaabbbbbbbbbbbbb",
      "aaabbbbbbbbbbbbb",
      "aaabbbbbbbbbbbbb",
      "aaabbbbbbbbbbbbb",
      "aaabbbbbbbbbbbbb",
      "aaabbbbbbaaaaabb",
      "aaabbbbbbbbbbbbb",
      "aaabbbbbbbbbbbbb",
      "aaabbbbbbbbbbbbb",
      "aaabbbbbbbbbbbbb",
      "aaabbbbbbbbbbbbb",
      "aaabbbbbbbbbbbbb"
    ],
    [
      "cdabbbbbbbbbbbbb",
      "cdabbbbbbbbbbbbb",
      "cdabbbbbbbbbbbbb",
      "edabbbbbbbbbbbbb",
      "fdabbbbbbbbbbbbb",
      "gdabbbbbbbbbbbbb",
      "cdabbbbbbbbbbbbb",
      "cdabbbbbbbbbbbbb",
      "cdabbbbbbbbbbbbb",
      "cdabbbbbbaaaaabb",
      "cdabbbbbbbbbbbbb",
      "cdabbbbbbbbbbbbb",
      "cdabbbbbbbbbbbbb",
      "gdabbbbbbbbbbbbb",
      "gdabbbbbbbbbbbbb",
      "gdabbbbbbbbbbbbb"
    ],
    [
      "cdabbbbbbbbbbbbb",
      "cdabbbbbbbbbbbbb",
      "cdabbbbbbbbbbbbb",
      " dabbbbbbbbbbbbb",
      " dabbbbbbbbbbbbb",
      " dabbbbbbbbbbbbb",
      "hdabbbbbbbbbbbbb",
      " dabbbbbbbbbbbbb",
      " dabbbbbbbbbbbbb",
      " dabbbbbbaaaaabb",
      " dabbbbbbbbbbbbb",
      " dabbbbbbbbbbbbb",
      "hdabbbbbbbbbbbbb",
      " dabbbbbbbbbbbbb",
      " dabbbbbbbbbbbbb",
      " dabbbbbbbbbbbbb"
    ],
    [
      " dabbbbbbbbbbbbb",
      " dabbbbbbbbbbbbb",
      "idabbbbbbbbbbbbb",
      " dabbbbbbbbbbbbb",
      " dabbbbbbbbbbbbb",
      " dabbbbbbbbbbbbb",
      "jcabbbbbbbbbbbbb",
      " dabbbbbbbbbbbbb",
      " dabbbbbbbbbbbbb",
      " dabbbbbbaaaaabb",
      " dabbbbbbbbbbbbb",
      " dabbbbbbbbbbbbb",
      "jcabbbbbbbbbbbbb",
      " dabbbbbbbbbbbbb",
      " dabbbbbbbbbbbbb",
      " dabbbbbbbbbbbbb"
    ],
    [
      " dabbbbbbbbbbbbb",
      " dabbbbbbbbbbbbb",
      "idabbbbbbbbbbbbb",
      " dabbbbbbbbbbbbb",
      " dabbbbbbbbbbbbb",
      " dabbbbbbbbbbbbb",
      "cdabbbbbbbbbbbbb",
      " dabbbbbbbbbbbbb",
      " dabbbbbbbbbbbbb",
      " dabbbbbbaaaaabb",
      " dabbbbbbbbbbbbb",
      " dabbbbbbbbbbbbb",
      "cdabbbbbbbbbbbbb",
      " dabbbbbbbbbbbbb",
      " dabbbbbbbbbbbbb",
      " dabbbbbbbbbbbbb"
    ],
    [
      " dabbbbbbbbbbbbb",
      " dabbbbbbbbbbbbb",
      "idabbbbbbbbbbbbb",
      " dabbbbbbbbbbbbb",
      " dabbbbbbbbbbbbb",
      " dabbbbbbbbbbbbb",
      "kdabbbbbbbbbbbbb",
      " dabbbbbbbbbbbbb",
      " dabbbbbbbbbbbbb",
      " dabbbbbbaaaaabb",
      " dabbbbbbbbbbbbb",
      " dabbbbbbbbbbbbb",
      "kdabbbbbbbbbbbbb",
      " dabbbbbbbbbbbbb",
      " dabbbbbbbbbbbbb",
      " dabbbbbbbbbbbbb"
    ]
  ]
}