{
  "name": "multi_filmworkstower_14_floor2",
  "refpalette": "deceasedcraft:multi_filmworkstower_14/multi_filmworkstower_14_floor2_palette",
  "xsize": 16,
  "zsize": 16,
  "slices": [
    [
      "                ",
      "                ",
      "                ",
      "                ",
      "                ",
      "                ",
      "aaaaaaaaaaaaaaaa",
      "bbbbbbbbbbbbbbbb",
      "cccccccccccccccc",
      "ddddddddddbebddd",
      "dddddddddddddddd",
      "dddddddddddddddd",
      "dddddddddddddddd",
      "dddddddddddddddd",
      "dddddddddddddddd",
      "dddddddddddddddd"
    ],
    [
      "                ",
      "                ",
      "                ",
      "                ",
      "                ",
      "     fffffffffff",
      "aaaaaaaaaaaaaaaa",
      "gggggggggggggggg",
      "hhhhhhhhhhhhhhhh",
      "         ibjbk  ",
      "                ",
      "                ",
      "                ",
      "                ",
      "                ",
      "llll            "
    ],
    [
      "                ",
      "                ",
      "                ",
      "                ",
      "                ",
      "     fffffffffff",
      "aaaaaaaaaaaaaaaa",
      "mmmmmmmmmmmmmmmm",
      "                ",
      "nnnn o  ip q rk ",
      "                ",
      "                ",
      "                ",
      "                ",
      "                ",
      "                "
    ],
    [
      "                ",
      "                ",
      "                ",
      "                ",
      "                ",
      "     fffffffffff",
      "aaaaaaaaaaaaaaaa",
      "mmmmmmmmmmmmmmmm",
      "                ",
      "ssss t ip  u  rk",
      "                ",
      "                ",
      "                ",
      "                ",
      "                ",
      "                "
    ],
    [
      "                ",
      "                ",
      "                ",
      "                ",
      "                ",
      "     fffffffffff",
      "aaaaaaaaaaaaaaaa",
      "m mmm mmm m mmmm",
      "                ",
      "wwww xip   u   r",
      "                ",
      "                ",
      "                ",
      "                ",
      "                ",
      "                "
    ],
    [
      "                ",
      "                ",
      "                ",
      "                ",
      "                ",
      "     fffffffffff",
      "aaaaaaaaaaaaaaaa",
      "  mm    m   mm  ",
      "                ",
      "   y ip    u    ",
      "                ",
      "                ",
      "                ",
      "                ",
      "                ",
      "                "
    ]
  ]
}