{
  "name": "multi_filmworkstower_14_floor1",
  "refpalette": "deceasedcraft:multi_filmworkstower_14/multi_filmworkstower_14_floor1_palette",
  "xsize": 16,
  "zsize": 16,
  "slices": [
    [
      "                ",
      "                ",
      "                ",
      "                ",
      "                ",
      "                ",
      "                ",
      "                ",
      "                ",
      "                ",
      "                ",
      "                ",
      "                ",
      "                ",
      "                ",
      "                "
    ],
    [
      "abaac           ",
      "abaac           ",
      "abaac           ",
      "abaac           ",
      "abaac           ",
      "abaac           ",
      "abaac           ",
      "ccccc           ",
      "                ",
      "                ",
      "                ",
      "                ",
      "                ",
      "                ",
      "                ",
      "                "
    ],
    [
      "dddd            ",
      "dddd            ",
      "dddd            ",
      "dddd            ",
      "dddd            ",
      "dddd            ",
      "dddd            ",
      "                ",
      "                ",
      "                ",
      "                ",
      "                ",
      "                ",
      "                ",
      "                ",
      "                "
    ],
    [
      "                ",
      "                ",
      "                ",
      "                ",
      "                ",
      "                ",
      "                ",
      "                ",
      "                ",
      "eeeeeeeeeeeeeeee",
      "                ",
      "                ",
      "                ",
      "                ",
      "                ",
      "                "
    ],
    [
      "                ",
      "                ",
      "                ",
      "                ",
      "                ",
      "                ",
      "                ",
      "                ",
      "                ",
      "ffffffffffffffff",
      "                ",
      "   g       g    ",
      "                ",
      "                ",
      "   g       g    ",
      "                "
    ],
    [
      "                ",
      "                ",
      "                ",
      "                ",
      "                ",
      "                ",
      "                ",
      "hhhhhhhhhhhhhhhh",
      "iiiiiiiiiiiiiiii",
      "ffffffffffffffff",
      "iiiiiiiiiiiiiiii",
      "jjjjjjjjjjjjjjjj",
      "iiiiiiiiiiiiiiii",
      "iiiiiiiiiiiiiiii",
      "jjjjjjjjjjjjjjjj",
      "iiiiiiiiiiiiiiii"
    ]
  ]
}