{
  "name": "multi_filmworkstower_14_floor3",
  "refpalette": "deceasedcraft:multi_filmworkstower_14/multi_filmworkstower_14_floor3_palette",
  "xsize": 16,
  "zsize": 16,
  "slices": [
    [
      "                ",
      "                ",
      "                ",
      "                ",
      "                ",
      "     aaaaaaaaaaa",
      "bbbbbbbbbbbbbbbb",
      "                ",
      "           c    ",
      "   def     g    ",
      "                ",
      "                ",
      "                ",
      "                ",
      "                ",
      "                "
    ],
    [
      "                ",
      "                ",
      "                ",
      "                ",
      "                ",
      "                ",
      "bbbbbbbbbbbbbbbb",
      "                ",
      "           h    ",
      "i ief      h    ",
      "                ",
      "                ",
      "                ",
      "                ",
      "                ",
      "                "
    ],
    [
      "                ",
      "                ",
      "                ",
      "                ",
      "                ",
      "                ",
      "bbbbbbbbbbbbbbbb",
      "bbbbbbbbbbbbbbbb",
      "jjjjjjjjjjjjjjjj",
      "k kkkkkkkkkkkkkk",
      "llllllllllllllll",
      "llllllllllllllll",
      "llllllllllllllll",
      "llllllllllllllll",
      "llllllllllllllll",
      "llllllllllllllll"
    ],
    [
      "                ",
      "                ",
      "                ",
      "                ",
      "                ",
      "                ",
      "                ",
      "                ",
      "                ",
      "                ",
      "mmmmmmmmmmmmmmmm",
      "nnnnnnnnnnnnnnnn",
      "mmmmmmmmmmmmmmmm",
      "mmmmmmmmmmmmmmmm",
      "nnnnnnnnnnnnnnnn",
      "mmmmmmmmmmmmmmmm"
    ],
    [
      "                ",
      "                ",
      "                ",
      "                ",
      "                ",
      "                ",
      "                ",
      "                ",
      "                ",
      "                ",
      "                ",
      "                ",
      "                ",
      "                ",
      "                ",
      "                "
    ],
    [
      "                ",
      "                ",
      "                ",
      "                ",
      "                ",
      "                ",
      "                ",
      "                ",
      "                ",
      "                ",
      "                ",
      "                ",
      "                ",
      "                ",
      "                ",
      "                "
    ]
  ]
}