{
  "name": "building_factoryb_top",
  "refpalette": "deceasedcraft:building_factoryb/building_factoryb_top_palette",
  "xsize": 16,
  "zsize": 16,
  "slices": [
    [
      "                ",
      "                ",
      "                ",
      " abbbbbbbbbbbba ",
      " cdddddddddddde ",
      " cd        f de ",
      " cdgggggghhggde ",
      " cd          de ",
      " cd          de ",
      " cd          de ",
      " cd          de ",
      " cdgghhgghhggde ",
      " cdfi        de ",
      " cdddddddddddde ",
      " ajkkjjjjjjjjja ",
      "                "
    ],
    [
      "                ",
      "                ",
      " llllllllllllll ",
      " llllllllllllll ",
      " mnoooooooooonm ",
      " mnppqqppqqppnm ",
      "  npprrpprrppn  ",
      "  npp  pp  ppn  ",
      "  n          n  ",
      "  n          n  ",
      "  n          n  ",
      "  n  ss  ss! n  ",
      "  n         fn  ",
      "  nnnnnnnnnnnn  ",
      " a kk         a ",
      "                "
    ],
    [
      "                ",
      "                ",
      "                ",
      "                ",
      "                ",
      "                ",
      " ll  tt  tt  ll ",
      " ll  tt  tt  ll ",
      " mnppqqppqqppnm ",
      " mnppqqppqqppnm ",
      "  npp  pp  ppn  ",
      "  n  ss  ss  n  ",
      "  n    ff   fn  ",
      "  nnnnnnnnnnnn  ",
      " a kk         a ",
      "                "
    ],
    [
      "                ",
      "                ",
      "                ",
      "                ",
      "                ",
      "                ",
      "                ",
      "                ",
      "                ",
      "                ",
      " ll  tt  tt  ll ",
      " llttttttttttll ",
      " mnqqqqqqqqqqnm ",
      " mnoooooooooonm ",
      " ajkkjjjjjjjjja ",
      "                "
    ],
    [
      "                ",
      "                ",
      "                ",
      "                ",
      "                ",
      "                ",
      "                ",
      "                ",
      "                ",
      "        ~       ",
      "                ",
      "                ",
      "   kk           ",
      "   kk           ",
      " llkkllllllllll ",
      " llllllllllllll "
    ],
    [
      "                ",
      "                ",
      "                ",
      "                ",
      "                ",
      "                ",
      "                ",
      "                ",
      "                ",
      "        ~       ",
      "                ",
      "                ",
      "                ",
      "   uw           ",
      "   kx           ",
      "                "
    ],
    [
      "                ",
      "                ",
      "                ",
      "                ",
      "                ",
      "                ",
      "                ",
      "                ",
      "                ",
      "        ~       ",
      "                ",
      "                ",
      "                ",
      "                ",
      "                ",
      "                "
    ],
    [
      "                ",
      "                ",
      "                ",
      "                ",
      "                ",
      "                ",
      "                ",
      "                ",
      "                ",
      "        ~       ",
      "                ",
      "                ",
      "                ",
      "                ",
      "                ",
      "                "
    ],
    [
      "                ",
      "                ",
      "                ",
      "                ",
      "                ",
      "                ",
      "                ",
      "                ",
      "                ",
      "        ~       ",
      "                ",
      "                ",
      "                ",
      "                ",
      "                ",
      "                "
    ],
    [
      "                ",
      "                ",
      "                ",
      "                ",
      "                ",
      "                ",
      "                ",
      "                ",
      "                ",
      "        ~       ",
      "                ",
      "                ",
      "                ",
      "                ",
      "                ",
      "                "
    ],
    [
      "                ",
      "                ",
      "                ",
      "                ",
      "                ",
      "                ",
      "                ",
      "                ",
      "                ",
      "        ~       ",
      "                ",
      "                ",
      "                ",
      "                ",
      "                ",
      "                "
    ]
  ]
}