{
  "name": "building_factoryb_ground",
  "refpalette": "deceasedcraft:building_factoryb/building_factoryb_ground_palette",
  "xsize": 16,
  "zsize": 16,
  "slices": [
    [
      "zzzzzzzzazazzzzz",
      "zzzzzzazzazzzzzz",
      "zzzzzzzaazzazzzz",
      "zzzzzz=aaaazzzzz",
      "zzz=b==vvvvc=zzz",
      "zzz=b==dddd==zzz",
      "zzz=b==dddd==zzz",
      "zzz=b==dddd==zzz",
      "zzz=b==dddd==zzz",
      "zzz=b==dddd==zzz",
      "zzz=b==dddd==zzz",
      "zzz=b==dddd==zzz",
      "zzz=b==dddd==zzz",
      "zzz=b=zvvvvczzzz",
      "zzzzzzzaaazazzzz",
      "zzzzzzzzaaazazzz"
    ],
    [
      "e    e      e   ",
      "e      e      ee",
      "e fghei     jfhe",
      " kfllghh   fffk ",
      "hhmmmmn    nmmh ",
      "hhmoppqrsstu!mh ",
      "ehmwxyp     umie",
      "i mA  B     Cm  ",
      " hmD EF     Imhe",
      "ehmJ        Imh ",
      " hmD        Im e",
      "eimA        Kmh ",
      "ehmALMNrsstOOmhi",
      "hhmpoPnQQQQnmmhh",
      "ekmRRmh     hhke",
      " ehkkhe      hi "
    ],
    [
      "                ",
      "                ",
      "  j             ",
      " kfg  h     jfk ",
      " hmmmmnSSSSnmm  ",
      " hTUppq    VuT  ",
      "  TW XY      T  ",
      "  TZ  0      T  ",
      "  m1  2     Imh ",
      " hm34       Im  ",
      "  T1        IT  ",
      "  T5         T  ",
      "  T67      8KTh ",
      " hmp9#n$$$$nmmh ",
      " kmRRm      hhk ",
      "  hkkh          "
    ],
    [
      "                ",
      "                ",
      "                ",
      " k            k ",
      " hmmmmn$$$$nmm  ",
      "  T9%^q      T  ",
      "  T &&*      T  ",
      "  T ***      T  ",
      "  m          m  ",
      "  m(         m  ",
      "  T          T  ",
      "  T          T  ",
      "  T o        T  ",
      "  m)o)n$$$$nmm  ",
      " kmRRm       hk ",
      "   kk           "
    ],
    [
      "                ",
      "                ",
      "                ",
      " k            k ",
      "  mmmmn$$$$nmm  ",
      "  +U pq      +  ",
      "  + -- [     +  ",
      "  +]   [     +  ",
      "  m {{{      m  ",
      "  m          m  ",
      "  +          +  ",
      "  +          +  ",
      "  + o        +  ",
      "  mmmmn$$$$nmm  ",
      " k}RR}        k ",
      "   }}           "
    ],
    [
      "                ",
      "                ",
      "                ",
      " k     ||||   k ",
      "  mmmmnnnnnnmm  ",
      "  ;o pq      ;  ",
      "  ;:''   <>  ;  ",
      "  ;:         ;  ",
      "  m:         m  ",
      "  m:         m  ",
      "  ;:         ;  ",
      "  ;: ><  >>  ;  ",
      "  ;,#        ;  ",
      "  mmmmnnnnnnmm  ",
      " k RR  ||||   k ",
      "                "
    ]
  ]
}