{
  "name": "building_factoryb_ground_180",
  "refpalette": "deceasedcraft:building_factoryb/building_factoryb_ground_palette_180",
  "xsize": 16,
  "zsize": 16,
  "slices": [
    [
      "zzzazaaazzzzzzzz",
      "zzzzazaaazzzzzzz",
      "zzzzcvvvvz=b=zzz",
      "zzz==dddd==b=zzz",
      "zzz==dddd==b=zzz",
      "zzz==dddd==b=zzz",
      "zzz==dddd==b=zzz",
      "zzz==dddd==b=zzz",
      "zzz==dddd==b=zzz",
      "zzz==dddd==b=zzz",
      "zzz==dddd==b=zzz",
      "zzz=cvvvv==b=zzz",
      "zzzzzaaaa=zzzzzz",
      "zzzzazzaazzzzzzz",
      "zzzzzzazzazzzzzz",
      "zzzzzazazzzzzzzz"
    ],
    [
      " ih      ehkkhe ",
      "ekhh     hmRRmke",
      "hhmmnQQQQnPopmhh",
      "ihmOOtssrNMLAmhe",
      " hmK        Amie",
      "e mI        Dmh ",
      " hmI        Jmhe",
      "ehmI     FE Dmh ",
      "  mC     B  Am i",
      "eimu     pyxwmhe",
      " hm!utssrqppomhh",
      " hmmn    nmmmmhh",
      " kfff   hhgllfk ",
      "ehfj     iehgf e",
      "ee      e      e",
      "   e      e    e"
    ],
    [
      "          hkkh  ",
      " khh      mRRmk ",
      " hmmn$$$$n#9pmh ",
      " hTK8      76T  ",
      "  T         5T  ",
      "  TI        1T  ",
      "  mI       43mh ",
      " hmI     2  1m  ",
      "  T      0  ZT  ",
      "  T      YX WT  ",
      "  TuV    qppUTh ",
      "  mmnSSSSnmmmmh ",
      " kfj     h  gfk ",
      "             j  ",
      "                ",
      "                "
    ],
    [
      "           kk   ",
      " kh       mRRmk ",
      "  mmn$$$$n)o)m  ",
      "  T        o T  ",
      "  T          T  ",
      "  T          T  ",
      "  m         (m  ",
      "  m          m  ",
      "  T      *** T  ",
      "  T      *&& T  ",
      "  T      q^%9T  ",
      "  mmn$$$$nmmmmh ",
      " k            k ",
      "                ",
      "                ",
      "                "
    ],
    [
      "           }}   ",
      " k        }RR}k ",
      "  mmn$$$$nmmmm  ",
      "  +        o +  ",
      "  +          +  ",
      "  +          +  ",
      "  m          m  ",
      "  m      {{{ m  ",
      "  +     [   ]+  ",
      "  +     [ -- +  ",
      "  +      qp U+  ",
      "  mmn$$$$nmmmm  ",
      " k            k ",
      "                ",
      "                ",
      "                "
    ],
    [
      "                ",
      " k   ||||  RR k ",
      "  mmnnnnnnmmmm  ",
      "  ;        #,;  ",
      "  ;  >>  <> :;  ",
      "  ;         :;  ",
      "  m         :m  ",
      "  m         :m  ",
      "  ;         :;  ",
      "  ;  ><   '':;  ",
      "  ;      qp o;  ",
      "  mmnnnnnnmmmm  ",
      " k   ||||     k ",
      "                ",
      "                ",
      "                "
    ]
  ]
}