{
  "name": "building_factoryb_ground_90",
  "refpalette": "deceasedcraft:building_factoryb/building_factoryb_ground_palette_90",
  "xsize": 16,
  "zsize": 16,
  "slices": [
    [
      "zzzzzzzzzzzzzzzz",
      "zzzzzzzzzzzzzzzz",
      "zzzzzzzzzzzzzzzz",
      "zzzz=========zza",
      "zzazc========caz",
      "azzavddddddddvza",
      "zazavddddddddvaa",
      "azaavddddddddvaa",
      "zzaavddddddddvaz",
      "zaz==========zzz",
      "zzzz==========zz",
      "zzzzbbbbbbbbbbzz",
      "zzzz==========zz",
      "zzzzzzzzzzzzzzzz",
      "zzzzzzzzzzzzzzzz",
      "zzzzzzzzzzzzzzzz"
    ],
    [
      " ee   e e e ihe ",
      " ehkhhi hh hhhki",
      "  ffmmmmmmmmmmhh",
      "e jfm!uCIIIKOmh ",
      "   fnu      On  ",
      "     t      tQ  ",
      "     s      sQ  ",
      "     s      sQ  ",
      " e h r      rQ  ",
      "  ihnqpBF   Nnhe",
      "e egmpy E   MPmh",
      "  hlmpx     LoRk",
      "  glmowADJDAApRk",
      "  ffmmmmmmmmmmmh",
      "   khhh hhhihhke",
      "eee hhei e eehe "
    ],
    [
      "                ",
      "   k    h   hhk ",
      "   fmTTTmmTTTmh ",
      "   jmu  III Kmh ",
      "    nV      8n  ",
      "    S        $  ",
      "    S        $  ",
      "    S        $  ",
      "    S        $  ",
      "   hnqY02    n  ",
      "    mpX      #mh",
      "    mp   4  79Rk",
      "   gmUWZ13156pRk",
      "  jfmTTTmmTTTmmh",
      "   khh   h   hk ",
      "                "
    ],
    [
      "                ",
      "   k          k ",
      "    mTTTmmTTTmh ",
      "    m        m  ",
      "    n        n  ",
      "    $        $  ",
      "    $        $  ",
      "    $        $  ",
      "    $        $  ",
      "    nq**     n  ",
      "    m^&*     )m ",
      "    m%&*    ooRk",
      "    m9   (   )Rk",
      "    mTTTmmTTTmm ",
      "   kh         k ",
      "                "
    ],
    [
      "                ",
      "   k          k ",
      "    m+++mm+++m  ",
      "    m        m  ",
      "    n        n  ",
      "    $        $  ",
      "    $        $  ",
      "    $        $  ",
      "    $ [[     $  ",
      "    nq  {    n  ",
      "    mp- {    m} ",
      "    m - {   omR}",
      "    mU ]     mR}",
      "    m+++mm+++m} ",
      "   k          k ",
      "                "
    ],
    [
      "                ",
      "   k          k ",
      "    m;;;mm;;;m  ",
      "    m        m  ",
      "    n        n  ",
      "   |n >    > n| ",
      "   |n <    > n| ",
      "   |n        n| ",
      "   |n        n| ",
      "    nq     < n  ",
      "    mp'    > m  ",
      "    m '     #mR ",
      "    mo::::::,mR ",
      "    m;;;mm;;;m  ",
      "   k          k ",
      "                "
    ]
  ]
}