{
  "name": "building_factoryb_top_90",
  "refpalette": "deceasedcraft:building_factoryb/building_factoryb_top_palette_90",
  "xsize": 16,
  "zsize": 16,
  "slices": [
    [
      "                ",
      "   aeeeeeeeeeea ",
      "   bddddddddddj ",
      "   bd g    g dj ",
      "   bdfg    g dj ",
      "   bd h    h dj ",
      "   bd h    h dj ",
      "   bd g    g dj ",
      "   bd g    g dj ",
      "   bd g    h dj ",
      "   bd g    h dj ",
      "   bd g    gidk ",
      "   bd g    gfdk ",
      "   bddddddddddj ",
      "   acccccccccca ",
      "                "
    ],
    [
      "                ",
      "  llmm        a ",
      "  llnnnnnnnnnn  ",
      "  lloppp    fn  ",
      "  lloppp   ! n  ",
      "  lloqr    s n  ",
      "  lloqr    s n  ",
      "  lloppp     n  ",
      "  lloppp     n  ",
      "  lloqr    s n  ",
      "  lloqr    s n  ",
      "  lloppp     nk ",
      "  lloppp     nk ",
      "  llnnnnnnnnnn  ",
      "  llmm        a ",
      "                "
    ],
    [
      "                ",
      "      llmm    a ",
      "      llnnnnnn  ",
      "        ppp fn  ",
      "        ppp  n  ",
      "      ttqq s n  ",
      "      ttqq s n  ",
      "        ppp fn  ",
      "        ppp fn  ",
      "      ttqq s n  ",
      "      ttqq s n  ",
      "        ppp  nk ",
      "        ppp  nk ",
      "      llnnnnnn  ",
      "      llmm    a ",
      "                "
    ],
    [
      "                ",
      "          llmma ",
      "          llnnj ",
      "           tqoj ",
      "           tqoj ",
      "          ttqoj ",
      "          ttqoj ",
      "           tqoj ",
      "           tqoj ",
      "          ttqoj ",
      "          ttqoj ",
      "           tqok ",
      "           tqok ",
      "          llnnj ",
      "          llmma ",
      "                "
    ],
    [
      "                ",
      "              ll",
      "              ll",
      "              ll",
      "              ll",
      "              ll",
      "              ll",
      "         ~    ll",
      "              ll",
      "              ll",
      "              ll",
      "            kkkl",
      "            kkkl",
      "              ll",
      "              ll",
      "                "
    ],
    [
      "                ",
      "                ",
      "                ",
      "                ",
      "                ",
      "                ",
      "                ",
      "         ~      ",
      "                ",
      "                ",
      "                ",
      "             wx ",
      "             uk ",
      "                ",
      "                ",
      "                "
    ],
    [
      "                ",
      "                ",
      "                ",
      "                ",
      "                ",
      "                ",
      "                ",
      "         ~      ",
      "                ",
      "                ",
      "                ",
      "                ",
      "                ",
      "                ",
      "                ",
      "                "
    ],
    [
      "                ",
      "                ",
      "                ",
      "                ",
      "                ",
      "                ",
      "                ",
      "         ~      ",
      "                ",
      "                ",
      "                ",
      "                ",
      "                ",
      "                ",
      "                ",
      "                "
    ],
    [
      "                ",
      "                ",
      "                ",
      "                ",
      "                ",
      "                ",
      "                ",
      "         ~      ",
      "                ",
      "                ",
      "                ",
      "                ",
      "                ",
      "                ",
      "                ",
      "                "
    ],
    [
      "                ",
      "                ",
      "                ",
      "                ",
      "                ",
      "                ",
      "                ",
      "         ~      ",
      "                ",
      "                ",
      "                ",
      "                ",
      "                ",
      "                ",
      "                ",
      "                "
    ],
    [
      "                ",
      "                ",
      "                ",
      "                ",
      "                ",
      "                ",
      "                ",
      "         ~      ",
      "                ",
      "                ",
      "                ",
      "                ",
      "                ",
      "                ",
      "                ",
      "                "
    ]
  ]
}