{
  "name": "building_factoryb_ground_270",
  "refpalette": "deceasedcraft:building_factoryb/building_factoryb_ground_palette_270",
  "xsize": 16,
  "zsize": 16,
  "slices": [
    [
      "zzzzzzzzzzzzzzzz",
      "zzzzzzzzzzzzzzzz",
      "zzzzzzzzzzzzzzzz",
      "zz==========zzzz",
      "zzbbbbbbbbbbzzzz",
      "zz==========zzzz",
      "zzz==========zaz",
      "zavddddddddvaazz",
      "aavddddddddvaaza",
      "aavddddddddvazaz",
      "azvddddddddvazza",
      "zac========czazz",
      "azz=========zzzz",
      "zzzzzzzzzzzzzzzz",
      "zzzzzzzzzzzzzzzz",
      "zzzzzzzzzzzzzzzz"
    ],
    [
      " ehee e iehh eee",
      "ekhhihhh hhhk   ",
      "hmmmmmmmmmmmff  ",
      "kRpAADJDAwomlg  ",
      "kRoL     xpmlh  ",
      "hmPM   E ypmge e",
      "ehnN   FBpqnhi  ",
      "  Qr      r h e ",
      "  Qs      s     ",
      "  Qs      s     ",
      "  Qt      t     ",
      "  nO      unf   ",
      " hmOKIIICu!mfj e",
      "hhmmmmmmmmmmff  ",
      "ikhhh hh ihhkhe ",
      " ehi e e e   ee "
    ],
    [
      "                ",
      " kh   h   hhk   ",
      "hmmTTTmmTTTmfj  ",
      "kRp65131ZWUmg   ",
      "kR97  4   pm    ",
      "hm#      Xpm    ",
      "  n    20Yqnh   ",
      "  $        S    ",
      "  $        S    ",
      "  $        S    ",
      "  $        S    ",
      "  n8      Vn    ",
      " hmK III  umj   ",
      " hmTTTmmTTTmf   ",
      " khh   h    k   ",
      "                "
    ],
    [
      "                ",
      " k         hk   ",
      " mmTTTmmTTTm    ",
      "kR)   (   9m    ",
      "kRoo    *&%m    ",
      " m)     *&^m    ",
      "  n     **qn    ",
      "  $        $    ",
      "  $        $    ",
      "  $        $    ",
      "  $        $    ",
      "  n        n    ",
      "  m        m    ",
      " hmTTTmmTTTm    ",
      " k          k   ",
      "                "
    ],
    [
      "                ",
      " k          k   ",
      " }m+++mm+++m    ",
      "}Rm     ] Um    ",
      "}Rmo   { - m    ",
      " }m    { -pm    ",
      "  n    {  qn    ",
      "  $     [[ $    ",
      "  $        $    ",
      "  $        $    ",
      "  $        $    ",
      "  n        n    ",
      "  m        m    ",
      "  m+++mm+++m    ",
      " k          k   ",
      "                "
    ],
    [
      "                ",
      " k          k   ",
      "  m;;;mm;;;m    ",
      " Rm,::::::om    ",
      " Rm#     ' m    ",
      "  m >    'pm    ",
      "  n <     qn    ",
      " |n        n|   ",
      " |n        n|   ",
      " |n >    < n|   ",
      " |n >    > n|   ",
      "  n        n    ",
      "  m        m    ",
      "  m;;;mm;;;m    ",
      " k          k   ",
      "                "
    ]
  ]
}