{
  "name": "building_factoryb_top_270",
  "refpalette": "deceasedcraft:building_factoryb/building_factoryb_top_palette_270",
  "xsize": 16,
  "zsize": 16,
  "slices": [
    [
      "                ",
      " acccccccccca   ",
      " jddddddddddb   ",
      " kdfg    g db   ",
      " kdig    g db   ",
      " jd h    g db   ",
      " jd h    g db   ",
      " jd g    g db   ",
      " jd g    g db   ",
      " jd h    h db   ",
      " jd h    h db   ",
      " jd g    gfdb   ",
      " jd g    g db   ",
      " jddddddddddb   ",
      " aeeeeeeeeeea   ",
      "                "
    ],
    [
      "                ",
      " a        mmll  ",
      "  nnnnnnnnnnll  ",
      " kn     pppoll  ",
      " kn     pppoll  ",
      "  n s    rqoll  ",
      "  n s    rqoll  ",
      "  n     pppoll  ",
      "  n     pppoll  ",
      "  n s    rqoll  ",
      "  n s    rqoll  ",
      "  n !   pppoll  ",
      "  nf    pppoll  ",
      "  nnnnnnnnnnll  ",
      " a        mmll  ",
      "                "
    ],
    [
      "                ",
      " a    mmll      ",
      "  nnnnnnll      ",
      " kn  ppp        ",
      " kn  ppp        ",
      "  n s qqtt      ",
      "  n s qqtt      ",
      "  nf ppp        ",
      "  nf ppp        ",
      "  n s qqtt      ",
      "  n s qqtt      ",
      "  n  ppp        ",
      "  nf ppp        ",
      "  nnnnnnll      ",
      " a    mmll      ",
      "                "
    ],
    [
      "                ",
      " ammll          ",
      " jnnll          ",
      " koqt           ",
      " koqt           ",
      " joqtt          ",
      " joqtt          ",
      " joqt           ",
      " joqt           ",
      " joqtt          ",
      " joqtt          ",
      " joqt           ",
      " joqt           ",
      " jnnll          ",
      " ammll          ",
      "                "
    ],
    [
      "                ",
      "ll              ",
      "ll              ",
      "lkkk            ",
      "lkkk            ",
      "ll              ",
      "ll              ",
      "ll              ",
      "ll    ~         ",
      "ll              ",
      "ll              ",
      "ll              ",
      "ll              ",
      "ll              ",
      "ll              ",
      "                "
    ],
    [
      "                ",
      "                ",
      "                ",
      " ku             ",
      " xw             ",
      "                ",
      "                ",
      "                ",
      "      ~         ",
      "                ",
      "                ",
      "                ",
      "                ",
      "                ",
      "                ",
      "                "
    ],
    [
      "                ",
      "                ",
      "                ",
      "                ",
      "                ",
      "                ",
      "                ",
      "                ",
      "      ~         ",
      "                ",
      "                ",
      "                ",
      "                ",
      "                ",
      "                ",
      "                "
    ],
    [
      "                ",
      "                ",
      "                ",
      "                ",
      "                ",
      "                ",
      "                ",
      "                ",
      "      ~         ",
      "                ",
      "                ",
      "                ",
      "                ",
      "                ",
      "                ",
      "                "
    ],
    [
      "                ",
      "                ",
      "                ",
      "                ",
      "                ",
      "                ",
      "                ",
      "                ",
      "      ~         ",
      "                ",
      "                ",
      "                ",
      "                ",
      "                ",
      "                ",
      "                "
    ],
    [
      "                ",
      "                ",
      "                ",
      "                ",
      "                ",
      "                ",
      "                ",
      "                ",
      "      ~         ",
      "                ",
      "                ",
      "                ",
      "                ",
      "                ",
      "                ",
      "                "
    ],
    [
      "                ",
      "                ",
      "                ",
      "                ",
      "                ",
      "                ",
      "                ",
      "                ",
      "      ~         ",
      "                ",
      "                ",
      "                ",
      "                ",
      "                ",
      "                ",
      "                "
    ]
  ]
}