{
  "name": "building_factoryb_top_180",
  "refpalette": "deceasedcraft:building_factoryb/building_factoryb_top_palette_180",
  "xsize": 16,
  "zsize": 16,
  "slices": [
    [
      "                ",
      " ajjjjjjjjjkkja ",
      " eddddddddddddc ",
      " ed        ifdc ",
      " edgghhgghhggdc ",
      " ed          dc ",
      " ed          dc ",
      " ed          dc ",
      " ed          dc ",
      " edgghhggggggdc ",
      " ed f        dc ",
      " eddddddddddddc ",
      " abbbbbbbbbbbba ",
      "                ",
      "                ",
      "                "
    ],
    [
      "                ",
      " a         kk a ",
      "  nnnnnnnnnnnn  ",
      "  nf         n  ",
      "  n !ss  ss  n  ",
      "  n          n  ",
      "  n          n  ",
      "  n          n  ",
      "  npp  pp  ppn  ",
      "  npprrpprrppn  ",
      " mnppqqppqqppnm ",
      " mnoooooooooonm ",
      " llllllllllllll ",
      " llllllllllllll ",
      "                ",
      "                "
    ],
    [
      "                ",
      " a         kk a ",
      "  nnnnnnnnnnnn  ",
      "  nf   ff    n  ",
      "  n  ss  ss  n  ",
      "  npp  pp  ppn  ",
      " mnppqqppqqppnm ",
      " mnppqqppqqppnm ",
      " ll  tt  tt  ll ",
      " ll  tt  tt  ll ",
      "                ",
      "                ",
      "                ",
      "                ",
      "                ",
      "                "
    ],
    [
      "                ",
      " ajjjjjjjjjkkja ",
      " mnoooooooooonm ",
      " mnqqqqqqqqqqnm ",
      " llttttttttttll ",
      " ll  tt  tt  ll ",
      "                ",
      "                ",
      "                ",
      "                ",
      "                ",
      "                ",
      "                ",
      "                ",
      "                ",
      "                "
    ],
    [
      " llllllllllllll ",
      " llllllllllkkll ",
      "           kk   ",
      "           kk   ",
      "                ",
      "                ",
      "       ~        ",
      "                ",
      "                ",
      "                ",
      "                ",
      "                ",
      "                ",
      "                ",
      "                ",
      "                "
    ],
    [
      "                ",
      "           xk   ",
      "           wu   ",
      "                ",
      "                ",
      "                ",
      "       ~        ",
      "                ",
      "                ",
      "                ",
      "                ",
      "                ",
      "                ",
      "                ",
      "                ",
      "                "
    ],
    [
      "                ",
      "                ",
      "                ",
      "                ",
      "                ",
      "                ",
      "       ~        ",
      "                ",
      "                ",
      "                ",
      "                ",
      "                ",
      "                ",
      "                ",
      "                ",
      "                "
    ],
    [
      "                ",
      "                ",
      "                ",
      "                ",
      "                ",
      "                ",
      "       ~        ",
      "                ",
      "                ",
      "                ",
      "                ",
      "                ",
      "                ",
      "                ",
      "                ",
      "                "
    ],
    [
      "                ",
      "                ",
      "                ",
      "                ",
      "                ",
      "                ",
      "       ~        ",
      "                ",
      "                ",
      "                ",
      "                ",
      "                ",
      "                ",
      "                ",
      "                ",
      "                "
    ],
    [
      "                ",
      "                ",
      "                ",
      "                ",
      "                ",
      "                ",
      "       ~        ",
      "                ",
      "                ",
      "                ",
      "                ",
      "                ",
      "                ",
      "                ",
      "                ",
      "                "
    ],
    [
      "                ",
      "                ",
      "                ",
      "                ",
      "                ",
      "                ",
      "       ~        ",
      "                ",
      "                ",
      "                ",
      "                ",
      "                ",
      "                ",
      "                ",
      "                ",
      "                "
    ]
  ]
}