{
  "name": "multi_militarybase_3_base2",
  "refpalette": "deceasedcraft:multi_militarybase_3/multi_militarybase_3_base2_palette",
  "xsize": 16,
  "zsize": 16,
  "slices": [
    [
      "                ",
      "  a    a    a   ",
      "bbvbbbbvbbbbvbbb",
      "cccccccbcccdcccc",
      "cccccccbcccc ecf",
      "cccccccbcccgehfc",
      "iiiiiiiviighfjii",
      "kkkkkkkbkkd!gfhk",
      "kkkkkkkbkkkfjhkk",
      "kkkkkkkbkkkkkkkk",
      "bbbbbbbvbbbbbbbb",
      "lllllllbllllllll",
      "lllllllbllllllll",
      "lllllllbllllllll",
      "lllllllvllllllll",
      "vvvvvvvvvvvvvvvv"
    ],
    [
      "                ",
      "                ",
      "mmvmmmmvmm mvmm ",
      "       n    o   ",
      "        p g   q ",
      "      r s       ",
      "ttttttuvut     t",
      "wx xxx   x     x",
      "        yn      ",
      "              AB",
      "uuCuuuuvuuuuDuuu",
      "E  FIJJKL L   L ",
      "M   N OK        ",
      "E   IJJK P P P P",
      "M Q N Ov P P P!P",
      "vvvvvvvvvvvvvvvv"
    ],
    [
      "                ",
      "                ",
      "  v    v    v   ",
      "                ",
      "                ",
      "                ",
      "tR!tStuvuT     t",
      "U               ",
      "                ",
      "                ",
      "uuVuuuuvuuuuWuuu",
      "X   IJJK        ",
      "M   Y  K        ",
      "X   IJJK P P P P",
      "M   Y  vZPZPZPZP",
      "vvvvvvvvvvvvvvvv"
    ],
    [
      "                ",
      "                ",
      "  v    v    v   ",
      "                ",
      "                ",
      "                ",
      "uuuuuuuvuuu0  0u",
      "                ",
      "                ",
      "                ",
      "uuuuuuuvuuuuuuuu",
      "M   IJJK        ",
      "M   I  K        ",
      "M   IJJK        ",
      "M 1 I  v2 2 2 2 ",
      "vvvvvvvvvvvvvvvv"
    ],
    [
      "                ",
      "                ",
      "33v3333v3333v333",
      "                ",
      "                ",
      "                ",
      "mmmmmmmvmmmmm mm",
      "       m        ",
      "       m        ",
      "       m        ",
      "uuuuuuuvuuuuuuuu",
      "4444444K44444444",
      "4444444K44444444",
      "4444444K44444444",
      "4444444v44444444",
      "vvvvvvvvvvvvvvvv"
    ],
    [
      "                ",
      "                ",
      "55v5555v5555v555",
      "6666666b66666666",
      "6666666b66666666",
      "6666666b66666666",
      "6666666v66666666",
      "6666666b66666666",
      "6666666b66666666",
      "6666666b66666666",
      "bbbbbbbvbbbbbbbb",
      "78  7 8b8 7  87 ",
      "7   7  b  7   78",
      "7   7 8b  7  878",
      "7777777v77777777",
      "vvvvvvvvvvvvvvvv"
    ]
  ]
}