{
  "name": "multi_militarybase_3_ground",
  "refpalette": "deceasedcraft:multi_militarybase_3/multi_militarybase_3_ground_palette",
  "xsize": 16,
  "zsize": 16,
  "slices": [
    [
      "aaaaaaaaaaaaaaaa",
      "aabcaaabaaaaaaaa",
      "ddddddddaaaaaaaa",
      "ddde dddaaaaaaaa",
      "ddddddddaaaaaaaa",
      "ddddddddaaaaaaaa",
      "dddffffdaaaaaaaa",
      "fffffffdaaggagga",
      "fffffffdaaggagga",
      "fffffffdaaggagga",
      "fffffffdaaaaaaaa",
      "ddddddddzaaaaaaa",
      "aaaazaaaaazzzzaz",
      "zzazzzzaazazzaaz",
      "hhhhhhhhhhhhhhhh",
      "zzzzzzzzzzzzzzzz"
    ],
    [
      "i    j  k  l  m ",
      "n       o     p ",
      "q rrrrrrsss ssss",
      "  re ttr  p    s",
      "  r   urw   xy  ",
      "  r   Arq       ",
      "BrrCDECr  FI FI ",
      "JK    Lr  g! gg ",
      "      Mr  gg gg ",
      "      Mr  gg gg ",
      "NO    !r        ",
      "rrrrrrrrssssssss",
      "       P    QR  ",
      "   S S T S S    ",
      "hhhhhhhhhhhhhhhh",
      "                "
    ],
    [
      "                ",
      "                ",
      "  UUUUUUsss ssss",
      "  Ue VVU       s",
      "  W    W        ",
      "  U    W        ",
      "XUUCYZCU  01 01 ",
      "       U  gg gg ",
      "       W  ggegge",
      "       W  22 22 ",
      " 3    4U        ",
      "UUUWWWWUssssssss",
      "       P        ",
      "       T        ",
      "hhhhhhhhhhhhhhhh",
      "                "
    ],
    [
      "                ",
      "                ",
      "  UUUUUUssssssss",
      "  Ue   U5      s",
      "  W    U5       ",
      "  U    U5       ",
      "UUUCCCCU5       ",
      "       U5 gg gg ",
      "       U5 gg gg ",
      "       U5       ",
      "      4U5       ",
      "UUUUUUUUssssssss",
      "   5555P        ",
      "       T        ",
      "hhhhhhhhhhhhhhhh",
      "                "
    ],
    [
      "                ",
      "                ",
      "  UUUUUU66666666",
      "  Ue u7U       6",
      "  Uu  78        ",
      "  U   78        ",
      "8UU7777U        ",
      "77    7U  99 99 ",
      "      78  99 99 ",
      "      78        ",
      "  77777U        ",
      "UUU8888U66666666",
      "       P        ",
      "       T        ",
      "hhhhhhhhhhhhhhhh",
      "                "
    ],
    [
      "  r####r        ",
      "  r####r        ",
      "  r$$$$r        ",
      "  re$$$r        ",
      "  r$$$$r        ",
      "  r$$$$r        ",
      "rrr$$$$r        ",
      "$$$$$$$r        ",
      "$$$$$$$r        ",
      "$$$$$$$r        ",
      "  $$$$$r        ",
      "rrrrrrrr        ",
      "       P        ",
      "%%%%%%%^%%%%%%%%",
      "&&&&&&&*(&&&&)&&",
      "                "
    ]
  ]
}