{
  "name": "multi_militarybase_3_base1",
  "refpalette": "deceasedcraft:multi_militarybase_3/multi_militarybase_3_base1_palette",
  "xsize": 16,
  "zsize": 16,
  "slices": [
    [
      "                ",
      "  a    a    a   ",
      "bbvbbbbvbbbbvbbb",
      "cccccccbcccccdcc",
      "ccccccdbcccccccc",
      "dccccccbccdccccd",
      "eeeeeeeveeeeeeee",
      "fffffffbffffffff",
      "fffffffbffffffff",
      "fffffffbffffffff",
      "bbbbbbbvbbbbbbbb",
      "gggggggbffffffff",
      "gggggggbffffffff",
      "gggggggbffffffff",
      "gggggggvffffffff",
      "vvvvvvvvvvvvvvvv"
    ],
    [
      "                ",
      "                ",
      "hhvhhhhvhhhhvhhh",
      "           i    ",
      " jk     l       ",
      "            m   ",
      "       vnnnnnnnn",
      "    o pq        ",
      " rs   tq  uu uu ",
      "w   xywq  uu uu ",
      "nnAnnnnv        ",
      "BC DEFFq        ",
      "I   J KqL L L L ",
      "B   EFFqL L L L ",
      "I M J KvL L L L ",
      "vvvvvvvvvvvvvvvv"
    ],
    [
      "                ",
      "                ",
      "  v    v    v   ",
      "                ",
      "                ",
      "                ",
      "       vnnnnnnnn",
      "       q        ",
      "       q  uu uu ",
      "       q  uu uu ",
      "nnNnnnnv        ",
      "O   EFFq        ",
      "I   P  qQ R S S ",
      "O   EFFqR Q R S ",
      "I   P  vR Q S S ",
      "vvvvvvvvvvvvvvvv"
    ],
    [
      "                ",
      "                ",
      "  v    v    v   ",
      "                ",
      "                ",
      "                ",
      "       vnnnnnnnn",
      "       q        ",
      "       q  uu uu ",
      "       q  uu uu ",
      "nnnnnnnv        ",
      "I   EFFq        ",
      "I   E  q        ",
      "I   EFFq        ",
      "I T E  v        ",
      "vvvvvvvvvvvvvvvv"
    ],
    [
      "                ",
      "                ",
      "UUvUUUUvUUUUvUUU",
      "                ",
      "                ",
      "                ",
      "       vnnnnnnnn",
      "       q        ",
      "       q  VV VV ",
      "       q  VV !V ",
      "nnnnnnnv  WW WW ",
      "XXXXXXXq        ",
      "XXXXXXXq        ",
      "XXXXXXXq        ",
      "XXXXXXXv        ",
      "vvvvvvvvvvvvvvvv"
    ],
    [
      "YYYYYYYYYYYYYYYY",
      "YYYYYYYYYYYYYYYY",
      "bbvbbbbvbbbbvbbb",
      "ZZZZZZZbZZZZZZZZ",
      "ZZZZZZZbZZZZZZZZ",
      "ZZZZZZZbZZZZZZZZ",
      "ZZZZZZZv00000000",
      "ZZZZZZZbZZ11Z11Z",
      "ZZZZZZZbZZVVZVVZ",
      "ZZZZZZZbZZVVZVVZ",
      "bbbbbbbvbbbbbbbb",
      "23  2 3bZZZZZZZZ",
      "2   2  bZZZZZZZZ",
      "23 32 3bZZZZZZZZ",
      "2222222v22222222",
      "vvvvvvvvvvvvvvvv"
    ]
  ]
}