{
  "name": "multi_militarybase_3_base3",
  "refpalette": "deceasedcraft:multi_militarybase_3/multi_militarybase_3_base3_palette",
  "xsize": 16,
  "zsize": 16,
  "slices": [
    [
      "     a       b  ",
      "cccccccccccccccc",
      "ddvddddvddddvddd",
      "eeeefeedeeegeeee",
      "eeeeegedgeheefee",
      "eeefeeedeeeefeee",
      "iiiiiiiviiiiiiii",
      "jjjjjjjdjjjjjjjj",
      "jjjjjjjdjjjjjjjj",
      "jjjjjjjdjjjjjjjj",
      "dddddddvd dddddd",
      "kkkkkkkdjjjjjjjj",
      "kkkkkkkdjjjjjjjj",
      "kkkkkkkdjjjjjjjj",
      "kkkkkkkvjjjjjjjj",
      "vvvvvvvvvvvvvvvv"
    ],
    [
      "                ",
      "  l             ",
      " mvmmmmvmmmmvm  ",
      "     n on       ",
      "  n p q  r s    ",
      "    n  tu  w oq ",
      "       v        ",
      "                ",
      "       w xyx  A ",
      "    BCDE xFx IJx",
      "KKLKKKKv        ",
      "M  NOPPQ xyxx   ",
      "R   S TQ xFxUV  ",
      "M   OPPQ     x  ",
      "R W S Tv xJx xJx",
      "vvvvvvvvvvvvvvvv"
    ],
    [
      "                ",
      "                ",
      "  v    v    v   ",
      "                ",
      "                ",
      "                ",
      "       v        ",
      "                ",
      "                ",
      "                ",
      "KKXKKKKv        ",
      "Y   OPPQ  Z     ",
      "R   0  Q        ",
      "Y   OPPQ        ",
      "R   0  v        ",
      "vvvvvvvvvvvvvvvv"
    ],
    [
      "                ",
      "                ",
      "  v    v    v   ",
      "                ",
      "                ",
      "                ",
      "       v        ",
      "                ",
      "                ",
      "                ",
      "KKKKKKKv        ",
      "R   OPPQ        ",
      "R   O  Q        ",
      "R   OPPQ        ",
      "R 1 O  v        ",
      "vvvvvvvvvvvvvvvv"
    ],
    [
      "                ",
      "                ",
      "22v2222v2222v222",
      "                ",
      "                ",
      "                ",
      "       v        ",
      "                ",
      "                ",
      "                ",
      "KKKKKKKvmmmmmmmm",
      "3333333Q        ",
      "3333333Q        ",
      "3333333Q        ",
      "3333333v        ",
      "vvvvvvvvvvvvvvvv"
    ],
    [
      "                ",
      "                ",
      "44v4444v4444v444",
      "5555555d55555555",
      "5555555d55555555",
      "5555555d55555555",
      "5555555v55555555",
      "5555555d55555555",
      "5555555d55555555",
      "5555555d55555555",
      "dddddddvdddddddd",
      "6  7!  d55555555",
      "6   6  d55555555",
      "6  76 7d55555555",
      "6666666v66666666",
      "vvvvvvvvvvvvvvvv"
    ]
  ]
}