{
  "name": "multi_alienresearch_3_ground",
  "refpalette": "deceasedcraft:multi_alienresearch_3/multi_alienresearch_3_ground_palette",
  "xsize": 16,
  "zsize": 16,
  "slices": [
    [
      "zzazaaaaaaazbvcd",
      "zzzaaaabaaazbvcd",
      "zazaaaazaaaavbce",
      "zzzazaaaazaabvcf",
      "zzzzaaaaaazbvvcz",
      "zzaaazaaaazabvcf",
      "zzzaaaaazaazbbcz",
      "zzzaazaaaaaabvcd",
      "zzazaaabaaabavcf",
      "zzzaaaaaazaabbce",
      "zzzzaaaaaaaabvcc",
      "zazzaazaaaaaavvv",
      "zzzaazaaaazbvbbb",
      "zzaaaaaabaazabaa",
      "zzzaaaaazazzazza",
      "zzzazaazzzazzazz"
    ],
    [
      "           g  hi",
      "       jklmg  hi",
      "           g  hn",
      " o         g  hp",
      "  o    jqlog  ho",
      "           g  h ",
      "           g  hr",
      "       l jkg  h ",
      " o         g  h ",
      "  o        g  hn",
      "       jq lg  hh",
      "   o       g    ",
      "          og    ",
      " o     lqm ggggg",
      "o         o   o ",
      "  o o           "
    ],
    [
      "           g  s ",
      "           g  tu",
      "           g  sn",
      "           g  t ",
      "           g  w ",
      "           g  x ",
      "           g  xr",
      "           g  s ",
      "           g  s ",
      "           g  sn",
      "           g  ts",
      "           g    ",
      "           g    ",
      "           ggggg",
      "                ",
      "                "
    ],
    [
      "           g  s ",
      "           g    ",
      "           g  sn",
      "           g  ! ",
      "           g  y ",
      "           g  x ",
      "           g   r",
      "           g  sr",
      "           g  s ",
      "           g  wn",
      "           g   s",
      "           g    ",
      "                ",
      "           ggggg",
      "                ",
      "                "
    ],
    [
      "           A  s ",
      "           A  y ",
      "           A  sn",
      "           A  y ",
      "           A  s ",
      "           A  x ",
      "           A  xr",
      "           A  y ",
      "           A  s ",
      "           A  yn",
      "           A  ws",
      "           A    ",
      "                ",
      "           AAAAA",
      "                ",
      "                "
    ],
    [
      "             BsC",
      "              yC",
      "              sn",
      "              sC",
      "             BsC",
      "             BsC",
      "             BsC",
      "             DsC",
      "              yC",
      "              sn",
      "              ss",
      "                ",
      "                ",
      "                ",
      "                ",
      "                "
    ]
  ]
}