{
  "name": "multi_alienresearch_3_base3",
  "refpalette": "deceasedcraft:multi_alienresearch_3/multi_alienresearch_3_base3_palette",
  "xsize": 16,
  "zsize": 16,
  "slices": [
    [
      "vabbaccccccccccc",
      "va  accccccccccc",
      "va  accccccccccc",
      "va  accccccccccc",
      "va  accccccccccc",
      "vdeeaccccccccccc",
      "vccccccccccccccc",
      "vccccccccccccccc",
      "vccccccccccccccc",
      "vccccccccccccccc",
      "vccccccccccccccc",
      "vccccccccccccccc",
      "vccccccccccccccc",
      "vccccccccccccccc",
      "vccccccccccccccc",
      "vvvvvvvvvvvvvvvv"
    ],
    [
      "va  accccccccccc",
      "va  accccccccccc",
      "va  accccccccccc",
      "va  accccccccccc",
      "vaeeaccccccccccc",
      "vccccccccccccccc",
      "vccccccccccccccc",
      "vccccccccccccccc",
      "vccccccccccccccc",
      "vccccccccccccccc",
      "vccccccccccccccc",
      "vccccccccccccccc",
      "vccccccccccccccc",
      "vccccccccccccccc",
      "vccccccccccccccc",
      "vvvvvvvvvvvvvvvv"
    ],
    [
      "va  accccccccccc",
      "va  accccccccccc",
      "va  accccccccccc",
      "vaeeaccccccccccc",
      "vccccccccccccccc",
      "vccccccccccccccc",
      "vccccccccccccccc",
      "vccccccccccccccc",
      "vccccccccccccccc",
      "vccccccccccccccc",
      "vccccccccccccccc",
      "vccccccccccccccc",
      "vccccccccccccccc",
      "vccccccccccccccc",
      "vccccccccccccccc",
      "vvvvvvvvvvvvvvvv"
    ],
    [
      "va  accccccccccc",
      "va  accccccccccc",
      "vaeeaccccccccccc",
      "vccccccccccccccc",
      "vccccccccccccccc",
      "vccccccccccccccc",
      "vccccccccccccccc",
      "vccccccccccccccc",
      "vccccccccccccccc",
      "vccccccccccccccc",
      "vccccccccccccccc",
      "vccccccccccccccc",
      "vccccccccccccccc",
      "vccccccccccccccc",
      "vccccccccccccccc",
      "vvvvvvvvvvvvvvvv"
    ],
    [
      "va  accccccccccc",
      "vaeeaccccccccccc",
      "vccccccccccccccc",
      "vccccccccccccccc",
      "vccccccccccccccc",
      "vccccccccccccccc",
      "vccccccccccccccc",
      "vccccccccccccccc",
      "vccccccccccccccc",
      "vccccccccccccccc",
      "vccccccccccccccc",
      "vccccccccccccccc",
      "vccccccccccccccc",
      "vccccccccccccccc",
      "vccccccccccccccc",
      "vvvvvvvvvvvvvvvv"
    ],
    [
      "vaeeaccccccccccc",
      "vccccccccccccccc",
      "vccccccccccccccc",
      "vccccccccccccccc",
      "vccccccccccccccc",
      "vccccccccccccccc",
      "vccccccccccccccc",
      "vccccccccccccccc",
      "vccccccccccccccc",
      "vccccccccccccccc",
      "vccccccccccccccc",
      "vccccccccccccccc",
      "vccccccccccccccc",
      "vccccccccccccccc",
      "vccccccccccccccc",
      "vvvvvvvvvvvvvvvv"
    ]
  ]
}