{
  "name": "multi_alienresearch_3_base5",
  "refpalette": "deceasedcraft:multi_alienresearch_3/multi_alienresearch_3_base5_palette",
  "xsize": 16,
  "zsize": 16,
  "slices": [
    [
      "vaaaaaaaaaaaaabb",
      "vaaaaaaaaaaaaaaa",
      "vaaaaaaaaaaaaaaa",
      "vaaaaaaaaaaaaaaa",
      "vaaaaaaaaaaaaaaa",
      "vaaaaaaaaaaaaaaa",
      "vaaaaaaaaaaaaaaa",
      "vaaaaaaaaaaaaaaa",
      "vaaaaaaaaaaaaaaa",
      "vaaaaaaaaaaaaaaa",
      "vaaaaaaaaaaaaaaa",
      "vaaaccccccaaaaaa",
      "vcdde    faaaaaa",
      "vcdde    faaaaaa",
      "vccccccccgaaaaaa",
      "vvvvvvvvvvvvvvvv"
    ],
    [
      "vaaaaaaaaaaaaabb",
      "vaaaaaaaaaaaaaaa",
      "vaaaaaaaaaaaaaaa",
      "vaaaaaaaaaaaaaaa",
      "vaaaaaaaaaaaaaaa",
      "vaaaaaaaaaaaaaaa",
      "vaaaaaaaaaaaaaaa",
      "vaaaaaaaaaaaaaaa",
      "vaaaaaaaaaaaaaaa",
      "vaaaaaaaaaaaaaaa",
      "vaaaaaaaaaaaaaaa",
      "vhiicccccaaaaaaa",
      "vc      faaaaaaa",
      "vc j    faaaaaaa",
      "vccgcccccaaaaaaa",
      "vvvvvvvvvvvvvvvv"
    ],
    [
      "vaaaaaaaaaaaaakk",
      "vaaaaaaaaaaaaaaa",
      "vaaaaaaaaaaaaaaa",
      "vaaaaaaaaaaaaaaa",
      "vaaaaaaaaaaaaaaa",
      "vaaaaaaaaaaaaaaa",
      "vaaaaaaaaaaaaaaa",
      "vaaaaaaaaaaaaaaa",
      "vaaaaaaaaaaaaaaa",
      "vaaaaaaaaaaaaaaa",
      "vciicaaaaaaaaaaa",
      "vg  ccccaaaaaaaa",
      "vc     faaaaaaaa",
      "vc     faaaaaaaa",
      "vccgccccaaaaaaaa",
      "vvvvvvvvvvvvvvvv"
    ],
    [
      "vaaaaaaaaaaaaakk",
      "vaaaaaaaaaaaaaaa",
      "vaaaaaaaaaaaaaaa",
      "vaaaaaaaaaaaaaaa",
      "vaaaaaaaaaaaaaaa",
      "vaaaaaaaaaaaaaaa",
      "vaaaaaaaaaaaaaaa",
      "vaaaaaaaaaaaaaaa",
      "vaaaaaaaaaaaaaaa",
      "vciicaaaaaaaaaaa",
      "vc  caaaaaaaaaaa",
      "vg  cccaaaaaaaaa",
      "vc    faaaaaaaaa",
      "vc    faaaaaaaaa",
      "vccgcccaaaaaaaaa",
      "vvvvvvvvvvvvvvvv"
    ],
    [
      "vaaaaaaaaaaaaakk",
      "vaaaaaaaaaaaaaaa",
      "vaaaaaaaaaaaaaaa",
      "vaaaaaaaaaaaaaaa",
      "vaaaaaaaaaaaaaaa",
      "vaaaaaaaaaaaaaaa",
      "vaaaaaaaaaaaaaaa",
      "vaaaaaaaaaaaaaaa",
      "vciicaaaaaaaaaaa",
      "vc  caaaaaaaaaaa",
      "vc  caaaaaaaaaaa",
      "vg  ccaaaaaaaaaa",
      "vc   faaaaaaaaaa",
      "vc   faaaaaaaaaa",
      "vccgccaaaaaaaaaa",
      "vvvvvvvvvvvvvvvv"
    ],
    [
      "vaaaaaaaaaaaaaak",
      "vaaaaaaaaaaaaaaa",
      "vaaaaaaaaaaaaaaa",
      "vaaaaaaaaaaaaaaa",
      "vaaaaaaaaaaaaaaa",
      "vaaaaaaaaaaaaaaa",
      "vaaaaaaaaaaaaaaa",
      "vciicaaaaaaaaaaa",
      "vc  caaaaaaaaaaa",
      "vc  caaaaaaaaaaa",
      "vc  caaaaaaaaaaa",
      "vg  caaaaaaaaaaa",
      "vc  faaaaaaaaaaa",
      "vc  faaaaaaaaaaa",
      "vccgcaaaaaaaaaaa",
      "vvvvvvvvvvvvvvvv"
    ]
  ]
}