{
  "name": "multi_alienresearch_3_base4",
  "refpalette": "deceasedcraft:multi_alienresearch_3/multi_alienresearch_3_base4_palette",
  "xsize": 16,
  "zsize": 16,
  "slices": [
    [
      "vaaaaaaaaaaaaaab",
      "vaaaaaaaaaaaaaaa",
      "vaaaaaaaaaaaaaaa",
      "vaaaaaaaaaaaaaaa",
      "vaaaaaaaaaaaaaaa",
      "vaaaaaaaaaaaaaaa",
      "vcddcaaaaaaaaaaa",
      "vc  caaaaaaaaaaa",
      "vc  caaaaaaaaaaa",
      "vc  caaaaaaaaaaa",
      "vc  caaaaaaaaaaa",
      "veffcaaaaaaaaaaa",
      "vcggaaaaaaaaaaaa",
      "vcggaaaaaaaaaaaa",
      "vcccaaaaaaaaaaaa",
      "vvvvvvvvvvvvvvvv"
    ],
    [
      "vaaaaaaaaaaaaaaa",
      "vaaaaaaaaaaaaaaa",
      "vaaaaaaaaaaaaaaa",
      "vaaaaaaaaaaaaaaa",
      "vaaaaaaaaaaaaaaa",
      "vhddcaaaaaaaaaaa",
      "vc  caaaaaaaaaaa",
      "vc  caaaaaaaaaaa",
      "vc  caaaaaaaaaaa",
      "vc  caaaaaaaaaaa",
      "vcffcaaaaaaaaaaa",
      "vaaaaaaaaaaaaaaa",
      "vaaaaaaaaaaaaaaa",
      "vaaaaaaaaaaaaaaa",
      "vaaaaaaaaaaaaaaa",
      "vvvvvvvvvvvvvvvv"
    ],
    [
      "vaaaaaaaaaaaaaaa",
      "vaaaaaaaaaaaaaaa",
      "vaaaaaaaaaaaaaaa",
      "vaaaaaaaaaaaaaaa",
      "vcddcaaaaaaaaaaa",
      "ve  caaaaaaaaaaa",
      "vc  caaaaaaaaaaa",
      "vc  caaaaaaaaaaa",
      "vc  caaaaaaaaaaa",
      "vcffcaaaaaaaaaaa",
      "vaaaaaaaaaaaaaaa",
      "vaaaaaaaaaaaaaaa",
      "vaaaaaaaaaaaaaaa",
      "vaaaaaaaaaaaaaaa",
      "vaaaaaaaaaaaaaaa",
      "vvvvvvvvvvvvvvvv"
    ],
    [
      "vaaaaaaaaaaaaaaa",
      "vaaaaaaaaaaaaaaa",
      "vaaaaaaaaaaaaaaa",
      "vcddcaaaaaaaaaaa",
      "vc  caaaaaaaaaaa",
      "ve  caaaaaaaaaaa",
      "vc  caaaaaaaaaaa",
      "vc  caaaaaaaaaaa",
      "vcffcaaaaaaaaaaa",
      "vaaaaaaaaaaaaaaa",
      "vaaaaaaaaaaaaaaa",
      "vaaaaaaaaaaaaaaa",
      "vaaaaaaaaaaaaaaa",
      "vaaaaaaaaaaaaaaa",
      "vaaaaaaaaaaaaaaa",
      "vvvvvvvvvvvvvvvv"
    ],
    [
      "vaaaaaaaaaaaaaaa",
      "vaaaaaaaaaaaaaaa",
      "vcddcaaaaaaaaaaa",
      "vc  caaaaaaaaaaa",
      "vc  caaaaaaaaaaa",
      "ve  caaaaaaaaaaa",
      "vc  caaaaaaaaaaa",
      "vcffcaaaaaaaaaaa",
      "vaaaaaaaaaaaaaaa",
      "vaaaaaaaaaaaaaaa",
      "vaaaaaaaaaaaaaaa",
      "vaaaaaaaaaaaaaaa",
      "vaaaaaaaaaaaaaaa",
      "vaaaaaaaaaaaaaaa",
      "vaaaaaaaaaaaaaaa",
      "vvvvvvvvvvvvvvvv"
    ],
    [
      "vaaaaaaaaaaaaaaa",
      "vcddcaaaaaaaaaaa",
      "vc  caaaaaaaaaaa",
      "vc  caaaaaaaaaaa",
      "vc  caaaaaaaaaaa",
      "ve  caaaaaaaaaaa",
      "vcffcaaaaaaaaaaa",
      "vaaaaaaaaaaaaaaa",
      "vaaaaaaaaaaaaaaa",
      "vaaaaaaaaaaaaaaa",
      "vaaaaaaaaaaaaaaa",
      "vaaaaaaaaaaaaaaa",
      "vaaaaaaaaaaaaaaa",
      "vaaaaaaaaaaaaaaa",
      "vaaaaaaaaaaaaaaa",
      "vvvvvvvvvvvvvvvv"
    ]
  ]
}