{
  "name": "multi_flatlarge_1_ground",
  "refpalette": "deceasedcraft:multi_flatlarge_1/multi_flatlarge_1_ground_palette",
  "xsize": 16,
  "zsize": 16,
  "slices": [
    [
      "HHabbbbbbbbbbbbb",
      "HHabccccccccbccc",
      "HHadcccccccccccc",
      "HHadcccccccccccc",
      "HHadcccccccccccc",
      "HHadcccccccccccc",
      "HHadcccccccccccc",
      "HHadcccccccccccc",
      "HHadcccccccccccc",
      "HHadcccccccccccc",
      "HHadcccccccccccc",
      "HHabccccccccbccc",
      "HHaddddddddddddd",
      "HHHaaaaaaaaaaaaa",
      "HHHHHHHHHHHHHHHH",
      "HHHHHHHHHHHHHHHH"
    ],
    [
      "   eeefffeefefef",
      "   g    hihighih",
      "   j            ",
      "   j            ",
      "   j    klkl klk",
      "   j            ",
      "   j            ",
      "   j            ",
      "   jhihihihi hih",
      "   j            ",
      "   j            ",
      "   gklklklklgklk",
      "   jjjjjjjjjjjjj",
      "                ",
      "                ",
      "                "
    ],
    [
      "                ",
      "   m        m   ",
      "                ",
      "                ",
      "                ",
      "                ",
      "                ",
      "                ",
      "                ",
      "                ",
      "                ",
      "   m        m   ",
      "                ",
      "                ",
      "                ",
      "                "
    ],
    [
      "                ",
      "   m        m   ",
      "                ",
      "                ",
      "                ",
      "                ",
      "                ",
      "                ",
      "                ",
      "                ",
      "                ",
      "   m        m   ",
      "                ",
      "                ",
      "                ",
      "                "
    ],
    [
      "   n            ",
      "   moooooooomooo",
      "   n        o   ",
      "   n        o   ",
      "   n        o   ",
      "   n        o   ",
      "   n        o   ",
      "   n        o   ",
      "   n        o   ",
      "   n        o   ",
      "   n        o   ",
      "   mppppppppmppp",
      "                ",
      "                ",
      "                ",
      "                "
    ],
    [
      "  oqrrrrrrrrqrrr",
      "  oqqqqqqqqqqqqq",
      "  oqrrrrrrrrqrrr",
      "  oqrrrrrrrrqrrr",
      "  oqrrrrrrrrqrrr",
      "  oqrrrrrrrrqrrr",
      "  oqrrrrrrrrqrrr",
      "  oqrrrrrrrrqrrr",
      "  oqrrrrrrrrqrrr",
      "  oqrrrrrrrrqrrr",
      "  oqrrrrrrrrqrrr",
      "  oqqqqqqqqqqqqq",
      "  oooooooooooooo",
      "                ",
      "                ",
      "                "
    ]
  ]
}