{
  "name": "multi_flatlarge_1_floor3",
  "refpalette": "deceasedcraft:multi_flatlarge_1/multi_flatlarge_1_floor3_palette",
  "xsize": 16,
  "zsize": 16,
  "slices": [
    [
      "  abbbbbbbbbbbbb",
      "  cbbbbbbbbbbbbb",
      "  deeeeeeeeedeee",
      "  deeeeeeeeedeee",
      "  deeeeeeeeedeee",
      "  deeeeeeeeedeee",
      "  deeeeeeeeedeee",
      "  deeeeeeeeedeee",
      "  deeeeeefffdfff",
      "  deeeeeefffdfff",
      "  deeeeeefffdfff",
      "  ceeeeeefffdfff",
      "   gddddddddgddd",
      "                ",
      "                ",
      "                "
    ],
    [
      "  h             ",
      "  ciijiiiiiikiii",
      "  dl  md   ndo  ",
      "  cp  qdrs tdu w",
      "  cx  mdrs tdu w",
      "  cp   d   ydA  ",
      "  cB   C   DdE  ",
      "  cFII dddJdddKd",
      "  c LL  MN OdP N",
      "  cQ    RN SdT N",
      "  dUV   WN XdX N",
      "  cUY   ZN  d  N",
      "   gdNNNN0NdgdN0",
      "                ",
      "                ",
      "                "
    ],
    [
      "                ",
      "  cii1iiiiii iii",
      "  d2   d    d   ",
      "  c    d    d   ",
      "  34   d    d   ",
      "  c    d    d   ",
      "  c    5   DdE  ",
      "  c    ddd6ddd7d",
      "  34     N  d  N",
      "  c8     N  d  N",
      "  d9     N XdX N",
      "  c9 #$% N ^d& N",
      "   gd333N03dgd30",
      "                ",
      "                ",
      "                "
    ],
    [
      "                ",
      "  cii*iiiiii iii",
      "  d   (d    d   ",
      "  c   (d    d   ",
      "  3)  (d    d   ",
      "  c    d    d   ",
      "  c    c   DdE  ",
      "  c    ddd*ddd*d",
      "  3)     N +d- N",
      "  c8     N  d  N",
      "  d9     N  d  N",
      "  c9 []{ N }d| N",
      "   gd333N03dgd30",
      "                ",
      "                ",
      "                "
    ],
    [
      "                ",
      "  ciiiiiiiii iii",
      "  d    d    d   ",
      "  d    d    d   ",
      "  d    d    d   ",
      "  d    d    d   ",
      "  d    d    d   ",
      "  d    ddddddddd",
      "  d      d;;d;;d",
      "  d:     d;;d;;d",
      "  d      d;;d;;d",
      "  c      d;;d;;d",
      "   gddddddddgddd",
      "                ",
      "                ",
      "                "
    ],
    [
      "  '<<<<<<<<<<<<<",
      "  c>>>>>>>>>>>>>",
      "  ,bbbbbbbbbdbbb",
      "  ,bbbbbbbbbdbbb",
      "  ,bbbbbbbbbdbbb",
      "  ,bbbbbbbbbdbbb",
      "  ,bbbbbbbbbdbbb",
      "  ,bbbbbbbbbdbbb",
      "  ,bbbbbbb  d  b",
      "  ,bbbbbbb .d. b",
      "  ,bbbbbbb  d  b",
      "  cbbbbbbbbbdbbb",
      "   g,,,,,,,,g,,,",
      "                ",
      "                ",
      "                "
    ]
  ]
}