{
  "name": "multi_nuclearpowerplant_29_base8",
  "refpalette": "deceasedcraft:multi_nuclearpowerplant_29/multi_nuclearpowerplant_29_base8_palette",
  "xsize": 16,
  "zsize": 16,
  "slices": [
    [
      "aaaaaaaaaaaab   ",
      "aaaaaaaaaaaab   ",
      "aaaaaaaaaaaab   ",
      "aaaaaaaaaaaabc  ",
      "aaaaaaaaaaaab   ",
      "aaaaaaaaaaaab   ",
      "ddddddddddddb   ",
      "eeeeeeeeeeeeb   ",
      "eeeeeeeeeeeeb   ",
      "eeeeeeeeeeeeb   ",
      "eeeeeeeeefffb   ",
      "eeeeeeeeefgfb   ",
      "eeeeeeeeefffb   ",
      "eeeeeeeeeh dbc  ",
      "eeeeeeeeeh db   ",
      "eeeeeeeeeh db   "
    ],
    [
      "============iaaa",
      "===========aaaaa",
      "===========aaaaa",
      "===========aajaa",
      "===========aaaaa",
      "===========aaaaa",
      "============iaaa",
      "============iaaa",
      "============iaaa",
      "============iaaa",
      "=========fffiaaa",
      "=========fgfiaaa",
      "=========fffiaaa",
      "=========fkfijaa",
      "=========fkfiaaa",
      "=========fkfiaaa"
    ],
    [
      "llllllllllllblll",
      "lllllllllllammmn",
      "lllllllllllo   p",
      "lllllllllllo   p",
      "lllllllllllo   p",
      "lllllllllllammmq",
      "llllllllllllblll",
      "llllllllllllblll",
      "llllllllllllblll",
      "llllllllllllblll",
      "lllllllllfffblll",
      "lllllllllfgfblll",
      "lllllllllfgfblll",
      "lllllllllfgfblll",
      "lllllllllfgfblll",
      "lllllllllfgfblll"
    ],
    [
      "llllllllllllblll",
      "lllllllllllaaaaa",
      "lllllllllllaaaaa",
      "lllllllllllaaaaa",
      "lllllllllllaaaaa",
      "lllllllllllaaaaa",
      "llllllllllllblll",
      "llllllllllllblll",
      "llllllllllllblll",
      "llllllllllllblll",
      "lllllllllfffblll",
      "lllllllllfffblll",
      "lllllllllfffblll",
      "lllllllllfffblll",
      "lllllllllfffblll",
      "lllllllllfffblll"
    ],
    [
      "===rs===========",
      "====rs==========",
      "=====rs=========",
      "======rs========",
      "=======rs=======",
      "========rs======",
      "=========rs=====",
      "==========rs====",
      "===========rs===",
      "===========ris==",
      "===========riis=",
      "===========riiis",
      "rrrrrrrrrrriiiii",
      "iiiiiiiiiiiiiiii",
      "iiiiiiiiiiiiiiii",
      "iiiiiiiiiiiiiiii"
    ],
    [
      " t  =jjjjjjjjjjj",
      "u    =jjjjjjjjjj",
      " t    =jjjjjjjjj",
      "       =jjjjjjjj",
      " t t t  =jjjjjjj",
      "u   u    =jjjjjj",
      " t t t    =jjjjj",
      "           =jjjj",
      " t t t t t  =jjj",
      "u   u   u    =jj",
      " t t t t t    =j",
      "               =",
      "                ",
      "                ",
      "                ",
      "                "
    ]
  ]
}