{
  "name": "multi_nuclearpowerplant_29_base3",
  "refpalette": "deceasedcraft:multi_nuclearpowerplant_29/multi_nuclearpowerplant_29_base3_palette",
  "xsize": 16,
  "zsize": 16,
  "slices": [
    [
      "aaaabcdddd      ",
      "aaaaabcdddd     ",
      "aaaaaabcdddd    ",
      "aaaaaaabcdddd   ",
      "aaaaaaaabcdddd  ",
      "aaaaaaaaabcdddd ",
      "aaaaaaaaaabcdddd",
      "aaaaaaaaaaabcddd",
      "aaaaaaaaaaab=cdd",
      "aaaaaaaaaaaab=cd",
      "aaaaaaaaaaaaab=c",
      "aaaaaaaaaaaaaab=",
      "aaaaaaaaaaaaaab ",
      "aaaaaaaaaaaaaaab",
      "aaaaaaaaaaaaaaab",
      "aaaaaaaaaaaaaaaa"
    ],
    [
      "efffgh   i      ",
      "effffgh   i     ",
      "efffffgh   i    ",
      "effffffgh   i   ",
      " effffffgh   i  ",
      " efffffffgh   i ",
      "  efffffffgh   i",
      "   efffffffgh   ",
      "    eefffffg=h  ",
      "      eeeeeeg=h ",
      "            jg=h",
      "        klkk mg=",
      "        nnnnnng ",
      "        k l k  g",
      "     o    k    g",
      "    pq          "
    ],
    [
      "   rgh          ",
      "  rstgh         ",
      "   t  gh        ",
      "    u  gh       ",
      "        gh      ",
      "   usw  xgh     ",
      "    w y sxgh    ",
      "         x gh   ",
      "           g=h  ",
      "            g=h ",
      "            Ag=h",
      "              g=",
      "         B!C  g ",
      "               g",
      "     o         g",
      "    Dq          "
    ],
    [
      "    gh          ",
      "     gh         ",
      "      gh        ",
      "       gh       ",
      "        gh      ",
      "         gh     ",
      "          gh    ",
      "           gh   ",
      "           g=h  ",
      "            g=h ",
      "            Eg=h",
      "              g=",
      "          l   g ",
      "               g",
      "     o         g",
      "    Dq          "
    ],
    [
      "    gh          ",
      "     gh         ",
      "      gh        ",
      "       gh       ",
      "        gh      ",
      "         gh     ",
      "          gh    ",
      "           gh   ",
      "           g=h  ",
      "            g=h ",
      "             g=h",
      "              g=",
      "              g ",
      "               g",
      "               g",
      "    FI          "
    ],
    [
      "    gh          ",
      "     gh         ",
      "      gh        ",
      "       gh       ",
      "        gh      ",
      "         gh     ",
      "          gh    ",
      "           gh   ",
      "           g=h  ",
      "            g=h ",
      "             g=h",
      "              g=",
      "              g ",
      "               g",
      "               g",
      "                "
    ]
  ]
}