{
  "name": "multi_nuclearpowerplant_29_base7",
  "refpalette": "deceasedcraft:multi_nuclearpowerplant_29/multi_nuclearpowerplant_29_base7_palette",
  "xsize": 16,
  "zsize": 16,
  "slices": [
    [
      "aa  =b      ccdd",
      " a   =b      ccd",
      "aa    =b      cc",
      "       =b      c",
      "aa aaa  =b      ",
      " aea a   =b     ",
      "aa aaa    =b    ",
      "           =b   ",
      "aa aaa aaa  =b  ",
      " afa a a a   =b ",
      "aa aaa aaa    =b",
      "               =",
      "                ",
      "                ",
      "                ",
      "                "
    ],
    [
      "aa  =b      ccdd",
      " a   =b      ccd",
      "aa    =b      cc",
      "       =b      c",
      "aa aaa  =b      ",
      " a a a   =b     ",
      "aa aaa    =b    ",
      "           =b   ",
      "aa aaa aaa  =b  ",
      " a a a a a   =b ",
      "aa aaa aaa    =b",
      "               =",
      "                ",
      "                ",
      "                ",
      "                "
    ],
    [
      "aa  =b      cc  ",
      " a   =b      cc ",
      "aa    =b      cc",
      "       =b      c",
      "aa aaa  =b      ",
      " a a a   =b     ",
      "aa aaa    =b    ",
      "           =b   ",
      "aa aaa aaa  =b  ",
      " a a a a a   =b ",
      "aa aaa aaa    =b",
      "               =",
      "                ",
      "                ",
      "                ",
      "                "
    ],
    [
      "aa  =b      cc  ",
      "aa   =b      cc ",
      "aa    =b      cc",
      "       =b      c",
      "aa aaa  =b      ",
      "aa aaa   =b     ",
      "aa aaa    =b    ",
      "           =b   ",
      "aa aaa aaa  =b  ",
      "aa aaa aaa   =b ",
      "aa aaa aaa    =b",
      "               =",
      "                ",
      "                ",
      "                ",
      "                "
    ],
    [
      "    =b      cc  ",
      "     =b      cc ",
      "      =b      cc",
      "       =b      c",
      "        =b      ",
      "         =b     ",
      "          =b    ",
      "           =b   ",
      "            =b  ",
      "             =b ",
      "              =b",
      "               =",
      "                ",
      "                ",
      "                ",
      "                "
    ],
    [
      "gggg=b      cc  ",
      "ggggg=b      cc ",
      "gggggg=b      cc",
      "ggggggg=b      c",
      "gggggggg=b      ",
      "ggggggggg=b     ",
      "gggggggggg=b    ",
      "ggggggggggg=b   ",
      "gggggggggggg=b  ",
      "ggggggggggggg=b ",
      "gggggggggggggg=b",
      "ggggggggggggggg=",
      "gggggggggggggggg",
      "gggggggggggggggg",
      "gggggggggggggggg",
      "gggggggggggggggg"
    ]
  ]
}