{
  "name": "multi_nuclearpowerplant_29_base1",
  "refpalette": "deceasedcraft:multi_nuclearpowerplant_29/multi_nuclearpowerplant_29_base1_palette",
  "xsize": 16,
  "zsize": 16,
  "slices": [
    [
      "aaaaaaab========",
      "aaaaaaaab=======",
      "aaaaaaaaab======",
      "aaaaaaaaaab=====",
      "aaaaaaaaaaab====",
      "aaaaaaaaaaaab===",
      "aaaaaaaaaaaaab==",
      "aaaaaaaaaaaaabc=",
      "aaaaaaaaaaaaaabc",
      "aaaaaaaaaaaaaaab",
      "aaaaaaaaaaaaaaaa",
      "aaaaaaaaaaaaaaaa",
      "aaaaaaaaaaaaaaaa",
      "aaaaaaaaaaaaaaaa",
      "aaaaaaaaaaaaaaaa",
      "aaaaaaaaaaaaaaaa"
    ],
    [
      "aaaaaaabcccccccc",
      "aaaaaaaabccccccc",
      "aaaaaaaaabcccccc",
      "aaaaaaaaaabccccc",
      "aaaaaaaaaaabcccc",
      "aaaaaaaaaaaabccc",
      "aaaaaaaaaaaaabcc",
      "aaaaaaaaaaaaabcc",
      "aaaaaaaaaaaaaabc",
      "aaaaaaaaaaaaaaab",
      "baaaaaaaaaaaaaaa",
      "baaaaaaaaaaaaaaa",
      "baaaaaaaaaaaaaaa",
      "dbaaaaaaaaaaaaaa",
      "ebaaaaaaaaaaaaaa",
      "ebaaaaaaaaaaaaaa"
    ],
    [
      "aaaaaaabcccccccc",
      "aaaaaaaabccccccc",
      "aaaaaaaaabcccccc",
      "aaaaaaaaaabccccc",
      "aaaaaaaaaaabcccc",
      "baaaaaaaaaaabccc",
      "baaaaaaaaaaaabcc",
      "dbaaaaaaaaaaabcc",
      "ebaaaaaaaaaaaabc",
      "edbaaaaaaaaaaaab",
      " ebaaaaaaaaaaaaa",
      " edbaaaaaaaaaaaa",
      " edbaaaaaaaaaaaa",
      "  ebaaaaaaaaaaaa",
      "  edbaaaaaaaaaaa",
      "  edbaaaaaaaaaaa"
    ],
    [
      "aaaaaaabcccccccc",
      "aaaaaaaabccccccc",
      "baaaaaaaabcccccf",
      "ebaaaaaaaabccccc",
      "ebaaaaaaaaabcccc",
      " ebaaaaaaaaabccc",
      " edbaaaaaaaaabcc",
      "  ebaaaaaaaaabcc",
      "  edbaaaaaaaaabc",
      "   ebaaaaaaaaaab",
      "   edbaaaaaaaaaa",
      "    ebaaaaaaaaaa",
      "    edbaaaaaaaaa",
      "    edbaaaaaaaaa",
      "     ebaaaaaaaaa",
      "     edbaaaaaaaa"
    ],
    [
      "baaaaaabcccccccf",
      "ebaaaaaabccccccc",
      " ebaaaaaabccccc ",
      "  ebaaaaaabcccfg",
      "  ebaaaaaaabccfh",
      "   ebaaaaaaabccg",
      "    ebaaaaaaabcf",
      "    ebaaaaaaabcc",
      "     ebaaaaaaabc",
      "     edbaaaaaaab",
      "      ebaaaaaaaa",
      "      edbaaaaaaa",
      "       ebaaaaaaa",
      "       edbaaaaaa",
      "       edbaaaaaa",
      "        ebaaaaaa"
    ],
    [
      " ebaaaabccccccc ",
      "  ebaaaabcccccc ",
      "   ebaaaabcccfh ",
      "    ebaaaabccc  ",
      "    edbaaaabcfh ",
      "     ebaaaaabcc ",
      "      ebaaaaabf ",
      "      edbaaaabfh",
      "       ebaaaaabc",
      "        ebaaaaab",
      "        edbaaaaa",
      "         ebaaaaa",
      "         edbaaaa",
      "          ebaaaa",
      "          edbaaa",
      "          edbaaa"
    ]
  ]
}