{
  "name": "multi_nuclearpowerplant_29_base11",
  "refpalette": "deceasedcraft:multi_nuclearpowerplant_29/multi_nuclearpowerplant_29_base11_palette",
  "xsize": 16,
  "zsize": 16,
  "slices": [
    [
      "aaaaaaaaaaaabcdd",
      "aaaaaaaaaaacbeee",
      "aaaaaaaaaaacbe f",
      "aaaaaaaaaaacbe f",
      "aaaaaaaaaaacbe f",
      "ccccccccccccbeee",
      "ggggggggggggbcdd",
      "       hh  gbcdd",
      "           gbcdd",
      "           gbcdd",
      "         i gbcdd",
      "           gbcdd",
      "         i gbcdd",
      "           gbedd",
      "           gbcdd",
      "           gbcdd"
    ],
    [
      "aaaaaaaaaaaabcdd",
      "aaaaaaaaaaacbeee",
      "aaaaaaaaaaacbe f",
      "aaaaaaaaaaacbe f",
      "aaaaaaaaaaacbe f",
      "ccccccccccccbeee",
      "ggggggggggggbcdd",
      "j      hh  gbcdd",
      "           gbcdd",
      "           gbcdd",
      "         iigbcdd",
      "         i gbcdd",
      "         iigbcdd",
      "           gbedd",
      "           gbcdd",
      "           gbcdd"
    ],
    [
      "aaaaaaaaaaaabcdd",
      "aaaaaaaaaaaceeee",
      "aaaaaaaaaaaceeek",
      "aaaaaaaaaaaceeel",
      "aaaaaaaaaaaceeem",
      "cccccccccccceeee",
      "ggggggggggggbcdd",
      "no     hh  gbcdd",
      "           gbcdd",
      "           gbcdd",
      "         iigbcdd",
      "         i gbcdd",
      "         iigbcdd",
      "           gbedd",
      "           gbcdd",
      "           gbcdd"
    ],
    [
      "aaaaaaaaaaaabcdd",
      "aaaaaaaaaaaceeee",
      "aaaaaaaaaaae   p",
      "aaaaaaaaaaae   p",
      "aaaaaaaaaaae   p",
      "cccccccccccceeee",
      "ggggggggggggbcdd",
      "  o    hh  gbcdd",
      "           gbcdd",
      "           gbcdd",
      "         qqqqrdd",
      "         qsqqrdd",
      "         qqqqrdd",
      "           gbedd",
      "           gbcdd",
      "           gbcdd"
    ],
    [
      "aaaaaaaaaaaabcdd",
      "aaaaaaaaaaacectt",
      "aaaaaaaaaaaceeee",
      "aaaaaaaaaaaceeee",
      "aaaaaaaaaaaceeee",
      "ccccccccccccecuu",
      "ggggggggggggbcdd",
      "   o   hh  gbcdd",
      "           gbcdd",
      "           gbcdd",
      "         qqqqrdd",
      "         wddddxd",
      "         qqqqrdd",
      "           gbedd",
      "           gbcdd",
      "           gbcdd"
    ],
    [
      "aaaaaaaaaaaabcdd",
      "aaaaaaaaaaacbcdd",
      "aaaaaaaaaaacbcdd",
      "aaaaaaaaaaacbedd",
      "aaaaaaaaaaacbcdd",
      "ccccccccccccbcdd",
      "ggggggggggggbcdd",
      "    o  hh  gbcdd",
      "           gbcdd",
      "           gbcdd",
      "         qqqqrdd",
      "         wdqqrdd",
      "         qqqqrdd",
      "           gbedd",
      "           gbcdd",
      "           gbcdd"
    ]
  ]
}