{
  "name": "multi_nuclearpowerplant_29_base12",
  "refpalette": "deceasedcraft:multi_nuclearpowerplant_29/multi_nuclearpowerplant_29_base12_palette",
  "xsize": 16,
  "zsize": 16,
  "slices": [
    [
      "aaaaaaaaaaaaaaaa",
      "aaaaaaaaaaaaaaaa",
      "aaaaaaaaaaaaaaaa",
      "aaaaaaaaaaaaaaaa",
      "aaaaaaaaaaaaaaaa",
      "aaaaaaaaaaaaaaaa",
      "aaaaaaaaaaaaaaaa",
      "aaaaaaaaaaaaaaaa",
      "aaaaaaaaaaaaaaaa",
      "aaaaaaaaaaaaaaaa",
      "aaaaaaaaaaaaaaaa",
      "aaaaaaaaaaaaaaaa",
      "aaaaaaaaaaaaaaaa",
      "aaaaaaaaaaaaaaaa",
      "aaaaaaaaaaaaaaaa",
      "aaaaaaaaaaaaaaaa"
    ],
    [
      "aaaaaaaaaaaabbbb",
      "aaaaaaaaaaabbbbb",
      "aaaaaaaaaaabbbbb",
      "aaaaaaaaaaabbbbb",
      "aaaaaaaaaaabbbbb",
      "bbbbbbbbbbbbbbbb",
      "bbbbbbbbbbbbbbbb",
      "bbbbbbbbbbbbbbbb",
      "bbbbbbbbbbbbbbbb",
      "bbbbbbbbbbbbbbbb",
      "bbbbbbbbbbbbbbbb",
      "bbbbbbbbbbbbbbbb",
      "bbbbbbbbbbbbbbbb",
      "bbbbbbbbbbbbbbbb",
      "bbbbbbbbbbbbbbbb",
      "bbbbbbbbbbbbbbbb"
    ],
    [
      "aaaaaaaaaaaac===",
      "aaaaaaaaaaabc===",
      "aaaaaaaaaaabc===",
      "aaaaaaaaaaabc===",
      "aaaaaaaaaaabc===",
      "bbbbbbbbbbbbc===",
      "ddddddddddddc===",
      "eeeeeeeeeeedc===",
      "eeeeeeeeeeedc===",
      "eeeeeeeeffffc===",
      "eeeeeeeeffffc===",
      "eeeeeeeeffgfc===",
      "eeeeeeeeffffc===",
      "eeeeeeeeffffc===",
      "eeeeeeeeeeedc===",
      "eeeeeeeeeeedc==="
    ],
    [
      "aaaaaaaaaaaahbii",
      "aaaaaaaaaaabhbii",
      "aaaaaaaaaaabhbjj",
      "aaaaaaaaaaabhbjj",
      "aaaaaaaaaaabhbjj",
      "bbbbbbbbbbbbhbii",
      "ddddddddddddhbii",
      "       kk  dhbii",
      "           dhbii",
      "           dhbii",
      "         l dhbii",
      "           dhbii",
      "         l dhbii",
      "           dhbii",
      "           dhbii",
      "           dhbii"
    ],
    [
      "aaaaaaaaaaaahbmm",
      "aaaaaaaaaaabhjjj",
      "aaaaaaaaaaabhj  ",
      "aaaaaaaaaaabhjno",
      "aaaaaaaaaaabhj  ",
      "bbbbbbbbbbbbhjjj",
      "ddddddddddddhbmm",
      "       kk  dhbmm",
      "           dhbmm",
      "           dhbmm",
      "         p dhbmm",
      "          qdhbmm",
      "         p dhbmm",
      "           dhjmm",
      "           dhbmm",
      "           dhbmm"
    ],
    [
      "aaaaaaaaaaaahbmm",
      "aaaaaaaaaaabhjjj",
      "aaaaaaaaaaabhj r",
      "aaaaaaaaaaabhj r",
      "aaaaaaaaaaabhj r",
      "bbbbbbbbbbbbhjjj",
      "ddddddddddddhbmm",
      "       kk  dhbmm",
      "           dhbmm",
      "           dhbmm",
      "         psdhbmm",
      "          tdhbmm",
      "         pudhbmm",
      "           dhjmm",
      "           dhbmm",
      "           dhbmm"
    ]
  ]
}