{
  "name": "multi_nuclearpowerplant_29_base5",
  "refpalette": "deceasedcraft:multi_nuclearpowerplant_29/multi_nuclearpowerplant_29_base5_palette",
  "xsize": 16,
  "zsize": 16,
  "slices": [
    [
      "aa  =b      cc  ",
      " a   =b      cc ",
      "aa    =b      cc",
      "       =b      c",
      "aa aaa  =b      ",
      " a a a   =b     ",
      "aa aaa    =b    ",
      "           =b   ",
      "aa aaa aaa  =b  ",
      " a a a a a   =b ",
      "aa aaa aaa    =b",
      "               =",
      "                ",
      "                ",
      "                ",
      "                "
    ],
    [
      "aa  =b      cc  ",
      " a   =b      cc ",
      "aa    =b      cc",
      "       =b      c",
      "aa aaa  =b      ",
      " a a a   =b     ",
      "aa aaa    =b    ",
      "           =b   ",
      "aa aaa aaa  =b  ",
      " a a a a a   =b ",
      "aa aaa aaa    =b",
      "               =",
      "                ",
      "                ",
      "                ",
      "                "
    ],
    [
      "aa  =b      cc  ",
      "aa   =b      cc ",
      "aa    =b      cc",
      "       =b      c",
      "aa aaa  =b      ",
      "aa aaa   =b     ",
      "aa aaa    =b    ",
      "           =b   ",
      "aa aaa aaa  =b  ",
      "aa aaa aaa   =b ",
      "aa aaa aaa    =b",
      "               =",
      "                ",
      "                ",
      "                ",
      "                "
    ],
    [
      "    =b      cc  ",
      "     =b      cc ",
      "      =b      cc",
      "       =b      c",
      "        =b      ",
      "         =b     ",
      "          =b    ",
      "           =b   ",
      "            =b  ",
      "             =b ",
      "              =b",
      "               =",
      "                ",
      "                ",
      "                ",
      "                "
    ],
    [
      "    =b      cc  ",
      "     =b      cc ",
      "      =b      cd",
      "       =b      c",
      "        =b      ",
      "         =b     ",
      "          =b    ",
      "           =b   ",
      "            =b  ",
      "             =b ",
      "              =b",
      "               =",
      "                ",
      "                ",
      "                ",
      "                "
    ],
    [
      "    =b      cc  ",
      "     =b      cc ",
      "      =b      cc",
      "       =b      c",
      "        =b      ",
      "         =b     ",
      "          =b    ",
      "           =b   ",
      "            =b  ",
      "             =b ",
      "              =b",
      "               =",
      "                ",
      "                ",
      "                ",
      "                "
    ]
  ]
}