{
  "name": "multi_nuclearpowerplant_29_ground",
  "refpalette": "deceasedcraft:multi_nuclearpowerplant_29/multi_nuclearpowerplant_29_ground_palette",
  "xsize": 16,
  "zsize": 16,
  "slices": [
    [
      "   abccbdddddde ",
      "    abccbdddedz ",
      "     abccbddde  ",
      "      abccbddd  ",
      "       abccbdd  ",
      "       afbccbg  ",
      "        abcccbh ",
      "         abccbe ",
      "         afbccbg",
      "          abcccb",
      "          iabccc",
      "           afbcc",
      "            abcc",
      "            afbc",
      "             abc",
      "             afb"
    ],
    [
      "ddddddddddzzhz  ",
      "dddddddddddzz   ",
      "ddddddddddddz   ",
      "dddddddddddddz  ",
      "ddddddddddddd   ",
      "dddddddddddddd  ",
      "ddddddddddddde  ",
      " ddddddddddddd  ",
      "  ddddddddddddd ",
      "   ddddddddddddd",
      "   ddddddddddddd",
      "    dddddddddddd",
      "     ddddddddddd",
      "     ddddddddddd",
      "      dddddddddd",
      "      dddddddddd"
    ],
    [
      "zzzzzzzzzz      ",
      "zzzzzzzzzzzd    ",
      "zzzzzzzzhzzz    ",
      "zzzzzzzzzzhz    ",
      "zzzzzzzzzzzzz   ",
      "dzzzzzhzzzzzz   ",
      "ddzzzzzzzzzzz   ",
      "dddzzzzzzzzzz   ",
      "ddddzzzzzzzdzz  ",
      "ddddzzzzzzzzzzz ",
      "dddddzzzzzzzzzzz",
      "ddddddzzzzzzzzz ",
      "ddddddzzzzzzzzzz",
      "dddddddzzzzzzhzz",
      "dddddddzzzzzzzzz",
      "dddddddzzzzzzzzz"
    ],
    [
      "                ",
      "                ",
      "j k             ",
      "j               ",
      "zz  j           ",
      "z          d    ",
      "zz              ",
      "zzz             ",
      "zzzz            ",
      "zzzz   k j      ",
      "zzzzz         d ",
      "zzzzzzz  j      ",
      "zzzzzz          ",
      "zzzzzzz j       ",
      "zzzzzzz         ",
      "zzzzzzz         "
    ],
    [
      "                ",
      "                ",
      "                ",
      "                ",
      "                ",
      "                ",
      "                ",
      "                ",
      "                ",
      " h              ",
      "                ",
      "                ",
      "                ",
      "                ",
      "  j             ",
      "   k            "
    ],
    [
      "                ",
      "                ",
      "                ",
      "                ",
      "                ",
      "                ",
      "                ",
      "                ",
      "                ",
      "                ",
      "                ",
      "                ",
      "                ",
      "                ",
      "                ",
      "                "
    ]
  ]
}