{
  "name": "multi_nuclearpowerplant_29_base10",
  "refpalette": "deceasedcraft:multi_nuclearpowerplant_29/multi_nuclearpowerplant_29_base10_palette",
  "xsize": 16,
  "zsize": 16,
  "slices": [
    [
      "aaaaaaaaaaaabc  ",
      "aaaaaaaaaaadbc  ",
      "aaaaaaaaaaadbc  ",
      "aaaaaaaaaaadbe  ",
      "aaaaaaaaaaadbf  ",
      "ddddddddddddbf  ",
      "ggggggggggggbf  ",
      "     hijjiigbf  ",
      "iiiiiiiiiiigbf  ",
      "iiiiiiiiiiigbf  ",
      "         kkkbf  ",
      "         lmkbf  ",
      "         knkbf  ",
      "          ogbe  ",
      "           gbf  ",
      "           gbf  "
    ],
    [
      "aaaaaaaaaaaap   ",
      "aaaaaaaaaaadp   ",
      "aaaaaaaaaaadp   ",
      "aaaaaaaaaaadpqr ",
      "aaaaaaaaaaadp   ",
      "ddddddddddddp   ",
      "ggggggggggggp   ",
      "       jj stp   ",
      "uuuuuu     tpwww",
      "xxxxxxxxx  tp   ",
      "         kkkp   ",
      "         lmkp   ",
      "         kkkp   ",
      "           gpqr ",
      "           gp   ",
      "           gp   "
    ],
    [
      "aaaaaaaaaaaap   ",
      "aaaaaaaaaaadp   ",
      "aaaaaaaaaaadp   ",
      "aaaaaaaaaaadpq  ",
      "aaaaaaaaaaadp   ",
      "ddddddddddddp   ",
      "ggggggggggggp   ",
      "       jj   p   ",
      "            yAAA",
      "            p   ",
      "         kkkp   ",
      "         lmkp   ",
      "         kkkp   ",
      "           gpq  ",
      "           gp   ",
      "           gp   "
    ],
    [
      "aaaaaaaaaaaap   ",
      "aaaaaaaaaaadp   ",
      "aaaaaaaaaaadp   ",
      "aaaaaaaaaaadpq  ",
      "aaaaaaaaaaadp   ",
      "ddddddddddddp   ",
      "ggggggggggggp   ",
      "       jj   p   ",
      "            B   ",
      "            p   ",
      "         kkkp   ",
      "         lmkp   ",
      "         kkkp   ",
      "           gpq  ",
      "           gp   ",
      "           gp   "
    ],
    [
      "aaaaaaaaaaaap   ",
      "aaaaaaaaaaadp   ",
      "aaaaaaaaaaadp   ",
      "aaaaaaaaaaadpq  ",
      "aaaaaaaaaaadp   ",
      "ddddddddddddp   ",
      "ggggggggggggp   ",
      "       jj   p   ",
      "           Cb   ",
      "            p   ",
      "         kkkp   ",
      "         lmkp   ",
      "         knkp   ",
      "          ogpq  ",
      "           gp   ",
      "           gp   "
    ],
    [
      "aaaaaaaaaaaap   ",
      "aaaaaaaaaaadp   ",
      "aaaaaaaaaaadp   ",
      "aaaaaaaaaaadpq  ",
      "aaaaaaaaaaadp   ",
      "ddddddddddddp   ",
      "ggggggggggggp   ",
      "       jj   p   ",
      "            p   ",
      "            p   ",
      "         kkkp   ",
      "         lmkp   ",
      "         kkkp   ",
      "           gpq  ",
      "           gp   ",
      "           gp   "
    ]
  ]
}