{
  "name": "multi_nuclearpowerplant_29_base9",
  "refpalette": "deceasedcraft:multi_nuclearpowerplant_29/multi_nuclearpowerplant_29_base9_palette",
  "xsize": 16,
  "zsize": 16,
  "slices": [
    [
      "aaaaaaaaaaaab   ",
      "aaaaaaaaaaacb   ",
      "aaaaaaaaaaacb   ",
      "aaaaaaaaaaacbd  ",
      "aaaaaaaaaaacb   ",
      "ccccccccccccb   ",
      "eeeeeeeeeeeeb   ",
      "       ff   b   ",
      "            b   ",
      "            b   ",
      "         gggb   ",
      "         higb   ",
      "         gggb   ",
      "           ebd  ",
      "           eb   ",
      "           eb   "
    ],
    [
      "aaaaaaaaaaaab   ",
      "aaaaaaaaaaacb   ",
      "aaaaaaaaaaacb   ",
      "aaaaaaaaaaacbd  ",
      "aaaaaaaaaaacb   ",
      "ccccccccccccb   ",
      "eeeeeeeeeeeeb   ",
      "       ff   b   ",
      "            b   ",
      "            b   ",
      "         gggb   ",
      "         higb   ",
      "         gggb   ",
      "           ebd  ",
      "           eb   ",
      "           eb   "
    ],
    [
      "aaaaaaaaaaaab   ",
      "aaaaaaaaaaacb   ",
      "aaaaaaaaaaacb   ",
      "aaaaaaaaaaacbd  ",
      "aaaaaaaaaaacb   ",
      "ccccccccccccb   ",
      "eeeeeeeeeeeeb   ",
      "       ff   b   ",
      "            b   ",
      "            b   ",
      "         gggb   ",
      "         higb   ",
      "         gggb   ",
      "           ebd  ",
      "           eb   ",
      "           eb   "
    ],
    [
      "ccaaaaaaaaaab   ",
      "ccaaaaaaaaacb   ",
      "ccaaaaaaaaacb   ",
      "ccaaaaaaaaacbd  ",
      "ccaaaaaaaaacb   ",
      "ccccccccccccb   ",
      "eeeeeeeeeeeeb   ",
      "       ff   b   ",
      "       jj   b   ",
      "            b   ",
      "         gggb   ",
      "         higb   ",
      "         gggb   ",
      "           ebdkl",
      "           eb   ",
      "           eb   "
    ],
    [
      "mcaaaaaaaaaab   ",
      "mcaaaaaaaaacb   ",
      "mcaaaaaaaaacb   ",
      "mcaaaaaaaaacbddd",
      "mcaaaaaaaaacb   ",
      "mcccccccccccb   ",
      "meeeeeeeeeeeb   ",
      "m      ff   b   ",
      "mmmmmmmmmmmmno  ",
      "            b   ",
      "         gggb   ",
      "         higb   ",
      "         gggb   ",
      "           ebddd",
      "           eb   ",
      "           eb   "
    ],
    [
      "ccaaaaaaaaaab   ",
      "ccaaaaaaaaacb   ",
      "ccaaaaaaaaacb   ",
      "ccaaaaaaaaacbdp ",
      "ccaaaaaaaaacb   ",
      "ccccccccccccb   ",
      "eeeeeeeeeeeeb   ",
      "       ff   b   ",
      "            b   ",
      "            b   ",
      "         gggb   ",
      "         gigb   ",
      "         gggb   ",
      "           ebdp ",
      "           eb   ",
      "           eb   "
    ]
  ]
}