{
  "name": "multi_nuclearpowerplant_29_base2",
  "refpalette": "deceasedcraft:multi_nuclearpowerplant_29/multi_nuclearpowerplant_29_base2_palette",
  "xsize": 16,
  "zsize": 16,
  "slices": [
    [
      "    ab          ",
      "     ab         ",
      "      ab        ",
      "       ab       ",
      "        ab      ",
      "         ab     ",
      "          ab    ",
      "           ab   ",
      "           a=b  ",
      "            a=b ",
      "             a=b",
      "              a=",
      "              a ",
      "               a",
      "               a",
      "                "
    ],
    [
      "    ab          ",
      "     ab         ",
      "      ab        ",
      "       abccccdde",
      "        ab      ",
      "         ab     ",
      "          ab    ",
      "           ab   ",
      "           a=b  ",
      "            a=b ",
      "             a=b",
      "              a=",
      "              a ",
      "               a",
      "               a",
      "                "
    ],
    [
      "    ab          ",
      "     ab         ",
      "      ab        ",
      "       abfffff  ",
      "        ab      ",
      "         ab     ",
      "          ab    ",
      "           ab   ",
      "           a=b  ",
      "            a=b ",
      "             a=b",
      "              a=",
      "              a ",
      "               a",
      "               a",
      "                "
    ],
    [
      "    abb         ",
      "     abb        ",
      "      abb       ",
      "       abb      ",
      "        abb     ",
      "         abb    ",
      "          abb   ",
      "           abb  ",
      "           a=bb ",
      "            a=bb",
      "             a=b",
      "              a=",
      "              a ",
      "               a",
      "               a",
      "                "
    ],
    [
      "    ghhbi       ",
      "     ghhbi      ",
      "      ghhbi     ",
      "       ghhbi    ",
      "        ghhbi   ",
      "         ghhbi  ",
      "          ghhbi ",
      "           gh=bi",
      "           ghh=b",
      "            ghh=",
      "             ghh",
      "              gh",
      "              gh",
      "               g",
      "               g",
      "                "
    ],
    [
      "jkkkkhh=bbbbbbbb",
      "kkkkkkhh=bbbbbbb",
      "kkkkkkkhh=bbbbbb",
      "kkkkkkkkhh=bbbbb",
      "kkkkkkkkkhh=bbbb",
      "kkkkjjjkkkhh=bbb",
      "kkkkkkkkkkkhh=bb",
      "kkkkkkkkkkkkh==b",
      "kkkkkkkkkkkkhh==",
      "kkkkkkkkkkkkkhh=",
      "kkkkkkkkkkkkkkhh",
      "kjjjkkkkjjjkkkkh",
      "kkkkkkkkkkkkkkkh",
      "kkkkkkkkkkkkkkkk",
      "kkkkkkkkkkkkkkkk",
      "kkkkkkkkkkkkkkkk"
    ]
  ]
}