{
  "name": "multi_nuclearpowerplant_29_base6",
  "refpalette": "deceasedcraft:multi_nuclearpowerplant_29/multi_nuclearpowerplant_29_base6_palette",
  "xsize": 16,
  "zsize": 16,
  "slices": [
    [
      "aaaa=b      cc  ",
      "aaaaa=b      cc ",
      "aaaaaa=b      cc",
      "aaaaaaa=b      c",
      "aaaaaaaa=b      ",
      "aaaaaaaaa=b     ",
      "aaaaaaaaaa=b    ",
      "aaaaaaaaaaa=b   ",
      "aaaaaaaaaaaa=b  ",
      "aaaaaaaaaaaaa=b ",
      "aaaaaaaaaaaaaa=b",
      "aaaaaaaaaaaaaaa=",
      "aaaaaaaaaaaaaaaa",
      "aaaaaaaaaaaaaaaa",
      "aaaaaaaaaaaaaaaa",
      "aaaaaaaaaaaaaaaa"
    ],
    [
      "dddd=b      cc  ",
      "ddddd=b      cc ",
      "dddddd=b      cc",
      "ddddddd=b      c",
      "dddddddd=b      ",
      "ddddddddd=b     ",
      "dddddddddd=b    ",
      "ddddddddddd=b   ",
      "dddddddddddd=b  ",
      "ddddddddddddd=b ",
      "dddddddddddddd=b",
      "eeeeeeeeeeeeeef=",
      "                ",
      "                ",
      "                ",
      "  g             "
    ],
    [
      " h  =b      ccii",
      "j   !=b      cc ",
      " h    =b      cc",
      "       =b      c",
      " h h h  =b      ",
      "j   j    =b     ",
      " h h h    =b    ",
      "           =b   ",
      " h h h h h  =b  ",
      "j   j   j    =b ",
      " h h h h h    =b",
      "               =",
      "                ",
      "                ",
      "                ",
      "                "
    ],
    [
      "jj  =b      cc  ",
      " j   =b      cc ",
      "jj    =b      cc",
      "       =b      c",
      "jj jjj  =b      ",
      " jkj j   =b     ",
      "jj jjj    =b    ",
      "           =b   ",
      "jj jjj jjj  =b  ",
      " jlj jmj j   =b ",
      "jj jjj jjj    =b",
      "               =",
      "                ",
      "                ",
      "                ",
      "                "
    ],
    [
      "jj  =b      cc  ",
      " j   =b      cc ",
      "jj    =b      cc",
      "       =b      c",
      "jj jjj  =b      ",
      " j j j   =b     ",
      "jj jjj    =b    ",
      "           =b   ",
      "jj jjj jjj  =b  ",
      " j j j j j   =b ",
      "jj jjj jjj    =b",
      "               =",
      "                ",
      "                ",
      "                ",
      "                "
    ],
    [
      "jj  =b      cc  ",
      " j   =b      cc ",
      "jj    =b      cc",
      "       =b      c",
      "jj jjj  =b      ",
      " j j j   =b     ",
      "jj jjj    =b    ",
      "           =b   ",
      "jj jjj jjj  =b  ",
      " j j j j j   =b ",
      "jj jjj jjj    =b",
      "               =",
      "                ",
      "                ",
      "                ",
      "                "
    ]
  ]
}