{
  "name": "building_clothstore_ground_270",
  "refpalette": "deceasedcraft:building_clothstore/building_clothstore_ground_palette_270",
  "xsize": 16,
  "zsize": 16,
  "slices": [
    [
      "aaaaaaaaaaaaaaaa",
      "aaabbbbbbbbbbbaa",
      "bbbbfbdddddccbaa",
      "iibbgbdddddccbaa",
      "iibbgbbbbbbccbaa",
      "iiabhccccccccbaa",
      "iiabeeeeeeeccbaa",
      "iibbeeeeeeeccbaa",
      "iibbeeeeeeeccbaa",
      "iiabeeeeeeeccbaa",
      "iiabfccccccccbaa",
      "iibbgbbbbbbccbaa",
      "iibbgbcccccccbaa",
      "bbbbhbcccccccbaa",
      "aaabbbbbbbbbbbaa",
      "aaaaaaaaaaaaaaaa"
    ],
    [
      "                ",
      "OOOlllllllllll  ",
      "  jlKAJIyyypnlj ",
      "   m AJ    q m  ",
      "   m AAAAAAr m  ",
      "  klLp  B! p lk ",
      "  kl       s lk ",
      "   M   EED t m  ",
      "   N   EED u m  ",
      "  kl       w lk ",
      "  klKp    Bp lk ",
      "   m AAAAAAp m  ",
      "   m AB    x m  ",
      "  jlLA  F Cpolj ",
      "OOOlllllllllll  ",
      "                "
    ],
    [
      "                ",
      "   QQQQQQQQQQQ  ",
      "  PQ9A5 0XUpkQP ",
      "   mVA6    R m  ",
      "   mWAAAAAAS m  ",
      "   Q#pWYVYVp Q  ",
      "   Q         Q  ",
      "   $    1    m  ",
      "   %   32    m  ",
      "   Q         Q  ",
      "   Q9pYWYWWp Q  ",
      "   mYAAAAAAp m  ",
      "   mWA74ZZ T m  ",
      "  PQ#A8    pkQP ",
      "   QQQQQQQQQQQ  ",
      "                "
    ],
    [
      "                ",
      "   QQQ+++++QQQ  ",
      "  ^Q{A-----p Q^ ",
      "   :}A     )*&  ",
      "   :}AAAAAA)(&  ",
      "   Q|p[[[[[p Q  ",
      "   Q         Q  ",
      "   :w       *&  ",
      "   :;       (&  ",
      "   Q         Q  ",
      "   Q{p[[[[[p Q  ",
      "   :}AAAAAAp*&  ",
      "   :}A     )(&  ",
      "  ^Q|A]]]]]p Q^ ",
      "   QQQ+++++QQQ  ",
      "                "
    ],
    [
      "                ",
      "   QQQQQQQQQQQ  ",
      "   Q'''''''''Q  ",
      "   Q'''''''''Q  ",
      "   Q'''''''''Q  ",
      "   Q'''''''''Q  ",
      "   Q''>>>><''Q  ",
      "   Q''>.,><''Q  ",
      "   Q''>.,><''Q  ",
      "   Q''>>>><''Q  ",
      "   Q'''''''''Q  ",
      "   Q'''''''''Q  ",
      "   Q'''''''''Q  ",
      "   Q'''''''''Q  ",
      "   QQQQQQQQQQQ  ",
      "                "
    ],
    [
      "                ",
      "   ???????????  ",
      "   ?/////////?  ",
      "   ?/```````/?  ",
      "   ?/```````/?  ",
      "   ?/```````/?  ",
      "   ?/```````/?  ",
      "   ?/``\u0371\u0370```/?  ",
      "   ?/``\u0371\u0370```/?  ",
      "   ?/```````/?  ",
      "   ?/```````/?  ",
      "   ?/```````/?  ",
      "   ?/```````/?  ",
      "   ?/////////?  ",
      "   ???????????  ",
      "                "
    ]
  ]
}