{
  "name": "building_clothstore_ground_90",
  "refpalette": "deceasedcraft:building_clothstore/building_clothstore_ground_palette_90",
  "xsize": 16,
  "zsize": 16,
  "slices": [
    [
      "aaaaaaaaaaaaaaaa",
      "aabbbbbbbbbbbaaa",
      "aabcccccccbhbbbb",
      "aabcccccccbgbbii",
      "aabccbbbbbbgbbii",
      "aabccccccccfbaii",
      "aabcceeeeeeebaii",
      "aabcceeeeeeebbii",
      "aabcceeeeeeebbii",
      "aabcceeeeeeebaii",
      "aabcccccccchbaii",
      "aabccbbbbbbgbbii",
      "aabccdddddbgbbii",
      "aabccdddddbfbbbb",
      "aabbbbbbbbbbbaaa",
      "aaaaaaaaaaaaaaaa"
    ],
    [
      "                ",
      "  lllllllllllOOO",
      " jlopC F  ALlj  ",
      "  m x    BA m   ",
      "  m pAAAAAA m   ",
      " kl pB    pKlk  ",
      " kl w       lk  ",
      "  m u DEE   N   ",
      "  m t DEE   M   ",
      " kl s       lk  ",
      " kl p !B  pLlk  ",
      "  m rAAAAAA m   ",
      "  m q    JA m   ",
      " jlnpyyyIJAKlj  ",
      "  lllllllllllOOO",
      "                "
    ],
    [
      "                ",
      "  QQQQQQQQQQQ   ",
      " PQkp    8A#QP  ",
      "  m T ZZ47AWm   ",
      "  m pAAAAAAYm   ",
      "  Q pWWYWYp9Q   ",
      "  Q         Q   ",
      "  m    23   %   ",
      "  m    1    $   ",
      "  Q         Q   ",
      "  Q pVYVYWp#Q   ",
      "  m SAAAAAAWm   ",
      "  m R    6AVm   ",
      " PQkpUX0 5A9QP  ",
      "  QQQQQQQQQQQ   ",
      "                "
    ],
    [
      "                ",
      "  QQQ+++++QQQ   ",
      " ^Q p]]]]]A|Q^  ",
      "  &()     A}:   ",
      "  &*pAAAAAA}:   ",
      "  Q p[[[[[p{Q   ",
      "  Q         Q   ",
      "  &(       ;:   ",
      "  &*       w:   ",
      "  Q         Q   ",
      "  Q p[[[[[p|Q   ",
      "  &()AAAAAA}:   ",
      "  &*)     A}:   ",
      " ^Q p-----A{Q^  ",
      "  QQQ+++++QQQ   ",
      "                "
    ],
    [
      "                ",
      "  QQQQQQQQQQQ   ",
      "  Q'''''''''Q   ",
      "  Q'''''''''Q   ",
      "  Q'''''''''Q   ",
      "  Q'''''''''Q   ",
      "  Q''<>>>>''Q   ",
      "  Q''<>,.>''Q   ",
      "  Q''<>,.>''Q   ",
      "  Q''<>>>>''Q   ",
      "  Q'''''''''Q   ",
      "  Q'''''''''Q   ",
      "  Q'''''''''Q   ",
      "  Q'''''''''Q   ",
      "  QQQQQQQQQQQ   ",
      "                "
    ],
    [
      "                ",
      "  ???????????   ",
      "  ?/////////?   ",
      "  ?/```````/?   ",
      "  ?/```````/?   ",
      "  ?/```````/?   ",
      "  ?/```````/?   ",
      "  ?/```\u0370\u0371``/?   ",
      "  ?/```\u0370\u0371``/?   ",
      "  ?/```````/?   ",
      "  ?/```````/?   ",
      "  ?/```````/?   ",
      "  ?/```````/?   ",
      "  ?/////////?   ",
      "  ???????????   ",
      "                "
    ]
  ]
}