{
  "name": "building_clothstore_ground",
  "refpalette": "deceasedcraft:building_clothstore/building_clothstore_ground_palette",
  "xsize": 16,
  "zsize": 16,
  "slices": [
    [
      "aaaaaaaaaaaaaaaa",
      "aaaaaaaaaaaaaaaa",
      "abbbbbbbbbbbbbba",
      "abccccccccccccba",
      "abccccccccccccba",
      "abddbceeeecbccba",
      "abddbceeeecbccba",
      "abddbceeeecbccba",
      "abddbceeeecbccba",
      "abddbceeeecbccba",
      "abbbbceeeecbbbba",
      "abfggheeeefgghba",
      "abbbbbbbbbbbbbba",
      "aabbbaabbaabbbaa",
      "aabiiiiiiiiiibaa",
      "aabiiiiiiiiiibaa"
    ],
    [
      "                ",
      "  j  kk  kk  j  ",
      " llmmllmmllmmll ",
      " ln          ol ",
      " lpqrpstuwppxpl ",
      " ly A     BA Cl ",
      " ly A! DD  A  l ",
      " ly AB EE  A Fl ",
      " lI A  EE  A  l ",
      " lJJA      AB l ",
      " lAAAp    pAAAl ",
      " lK  L    K  Ll ",
      " llmmllMNllmmll ",
      " Oj  kk  kk  jO ",
      " O            O ",
      " O            O "
    ],
    [
      "                ",
      "  P          P  ",
      " QQmmQQmmQQmmQQ ",
      " Qk          kQ ",
      " QpRSp    ppTpQ ",
      " QU AV    WA  Q ",
      " QX AY    WAZ Q ",
      " Q0 AV 12 YAZ Q ",
      " Q  AY  3 WA4 Q ",
      " Q56AW    YA78Q ",
      " QAAAp    pAAAQ ",
      " Q9VW#    9YW#Q ",
      " QQmmQQ$%QQmmQQ ",
      "  P          P  ",
      "                ",
      "                "
    ],
    [
      "                ",
      "  ^          ^  ",
      " QQ&&QQ&&QQ&&QQ ",
      " Q *(  *(  *( Q ",
      " Qp))p    pp)pQ ",
      " +- A[    [A ]+ ",
      " +- A[    [A ]+ ",
      " +- A[    [A ]+ ",
      " +- A[    [A ]+ ",
      " +- A[    [A ]+ ",
      " QAAAp    pAAAQ ",
      " Q{}}| w; {}}|Q ",
      " QQ::QQ::QQ::QQ ",
      "  ^          ^  ",
      "                ",
      "                "
    ],
    [
      "                ",
      "                ",
      " QQQQQQQQQQQQQQ ",
      " Q''''''''''''Q ",
      " Q''''''''''''Q ",
      " Q''''<<<<''''Q ",
      " Q''''>>>>''''Q ",
      " Q''''>,,>''''Q ",
      " Q''''>..>''''Q ",
      " Q''''>>>>''''Q ",
      " Q''''''''''''Q ",
      " Q''''''''''''Q ",
      " QQQQQQQQQQQQQQ ",
      "                ",
      "                ",
      "                "
    ],
    [
      "                ",
      "                ",
      " ?????????????? ",
      " ?////////////? ",
      " ?/``````````/? ",
      " ?/``````````/? ",
      " ?/``````````/? ",
      " ?/````\u0370\u0370````/? ",
      " ?/````\u0371\u0371````/? ",
      " ?/``````````/? ",
      " ?/``````````/? ",
      " ?////////////? ",
      " ?????????????? ",
      "                ",
      "                ",
      "                "
    ]
  ]
}