{
  "name": "building_clothstore_ground_180",
  "refpalette": "deceasedcraft:building_clothstore/building_clothstore_ground_palette_180",
  "xsize": 16,
  "zsize": 16,
  "slices": [
    [
      "aabiiiiiiiiiibaa",
      "aabiiiiiiiiiibaa",
      "aabbbaabbaabbbaa",
      "abbbbbbbbbbbbbba",
      "abhggfeeeehggfba",
      "abbbbceeeecbbbba",
      "abccbceeeecbddba",
      "abccbceeeecbddba",
      "abccbceeeecbddba",
      "abccbceeeecbddba",
      "abccbceeeecbddba",
      "abccccccccccccba",
      "abccccccccccccba",
      "abbbbbbbbbbbbbba",
      "aaaaaaaaaaaaaaaa",
      "aaaaaaaaaaaaaaaa"
    ],
    [
      " O            O ",
      " O            O ",
      " Oj  kk  kk  jO ",
      " llmmllNMllmmll ",
      " lL  K    L  Kl ",
      " lAAAp    pAAAl ",
      " l BA      AJJl ",
      " l  A  EE  A Il ",
      " lF A  EE BA yl ",
      " l  A  DD !A yl ",
      " lC AB     A yl ",
      " lpxppwutsprqpl ",
      " lo          nl ",
      " llmmllmmllmmll ",
      "  j  kk  kk  j  ",
      "                "
    ],
    [
      "                ",
      "                ",
      "  P          P  ",
      " QQmmQQ%$QQmmQQ ",
      " Q#WY9    #WV9Q ",
      " QAAAp    pAAAQ ",
      " Q87AY    WA65Q ",
      " Q 4AW 3  YA  Q ",
      " Q ZAY 21 VA 0Q ",
      " Q ZAW    YA XQ ",
      " Q  AW    VA UQ ",
      " QpTpp    pSRpQ ",
      " Qk          kQ ",
      " QQmmQQmmQQmmQQ ",
      "  P          P  ",
      "                "
    ],
    [
      "                ",
      "                ",
      "  ^          ^  ",
      " QQ::QQ::QQ::QQ ",
      " Q|}}{ ;w |}}{Q ",
      " QAAAp    pAAAQ ",
      " +] A[    [A -+ ",
      " +] A[    [A -+ ",
      " +] A[    [A -+ ",
      " +] A[    [A -+ ",
      " +] A[    [A -+ ",
      " Qp)pp    p))pQ ",
      " Q (*  (*  (* Q ",
      " QQ&&QQ&&QQ&&QQ ",
      "  ^          ^  ",
      "                "
    ],
    [
      "                ",
      "                ",
      "                ",
      " QQQQQQQQQQQQQQ ",
      " Q''''''''''''Q ",
      " Q''''''''''''Q ",
      " Q''''>>>>''''Q ",
      " Q''''>..>''''Q ",
      " Q''''>,,>''''Q ",
      " Q''''>>>>''''Q ",
      " Q''''<<<<''''Q ",
      " Q''''''''''''Q ",
      " Q''''''''''''Q ",
      " QQQQQQQQQQQQQQ ",
      "                ",
      "                "
    ],
    [
      "                ",
      "                ",
      "                ",
      " ?????????????? ",
      " ?////////////? ",
      " ?/``````````/? ",
      " ?/``````````/? ",
      " ?/````\u0371\u0371````/? ",
      " ?/````\u0370\u0370````/? ",
      " ?/``````````/? ",
      " ?/``````````/? ",
      " ?/``````````/? ",
      " ?////////////? ",
      " ?????????????? ",
      "                ",
      "                "
    ]
  ]
}