{
  "name": "multi_nuclearpowerplant_15_base11",
  "refpalette": "deceasedcraft:multi_nuclearpowerplant_15/multi_nuclearpowerplant_15_base11_palette",
  "xsize": 16,
  "zsize": 16,
  "slices": [
    [
      "aaaaaaaaaaaaaaaa",
      "aaaaaaaaaaaaaaaa",
      "aaaaaaaaaaaaaaaa",
      "aaaaaaaaaaaaaaaa",
      "aaaaaaaaaaaaaaaa",
      "bcccbbccccbbcccb",
      "deeefgeeeehieeef",
      "jklmnjkoompjklmn",
      "qk mmqk  mmqk mm",
      "r    r     r    ",
      "                ",
      "                ",
      "                ",
      "                ",
      "                ",
      "                "
    ],
    [
      "aaaaaaaaaaaaaaaa",
      "aaaaaaaaaaaaaaaa",
      "aaaaaaaaaaaaaaaa",
      "aaaaaaaaaaaaaaaa",
      "aaaaaaaaaaaaaaaa",
      "bcccbbccccbbcccb",
      "seeetteeeetteeet",
      "uk mwukoomwuk mx",
      "uk muuk  muuk mu",
      "                ",
      "                ",
      "                ",
      "                ",
      "                ",
      "                ",
      "                "
    ],
    [
      "aaaaaaaaaaaaaaaa",
      "aaaaaaaaaaaaaaaa",
      "aaaaaaaaaaaaaaaa",
      "aaaaaaaaaaaaaaaa",
      "aaaaaaaaaaaaaaaa",
      "cccccccccccccccc",
      "eeeeeeeeeeeeeeee",
      "    y  oo y    y",
      "                ",
      "                ",
      "                ",
      "                ",
      "                ",
      "                ",
      "                ",
      "                "
    ],
    [
      "aaaaaaaaaaaaaaaa",
      "aaaaaaaaaaaaaaaa",
      "aaaaaaaaaaaaaaaa",
      "aaaaaaaaaaaaaaaa",
      "aaaaaaaaaaaaaaaa",
      "cccccccccccccccc",
      "eeeeeeeeeeeeeeee",
      "    A  oo A    A",
      "                ",
      "                ",
      "                ",
      "                ",
      "                ",
      "                ",
      "                ",
      "                "
    ],
    [
      "aaaaaaaaaaaaaaaa",
      "aaaaaaaaaaaaaaaa",
      "aaaaaaaaaaaaaaaa",
      "aaaaaaaaaaaaaaaa",
      "aaaaaaaaaaaaaaaa",
      "cccccccccccccccc",
      "eeeeeeeeeeeeeeee",
      " AAAA  oo A    A",
      "                ",
      "                ",
      "                ",
      "                ",
      "                ",
      "                ",
      "BBBBBBBBBBBBBBBB",
      "CCCCCCCCCCCCCCCC"
    ],
    [
      "aaaaaaaaaaaaaaaa",
      "aaaaaaaaaaaaaaaa",
      "aaaaaaaaaaaaaaaa",
      "aaaaaaaaaaaaaaaa",
      "aaaaaaaaaaaaaaaa",
      "cccccccccccccccc",
      "eeeeeeeeeeeeeeee",
      " A     oo A     ",
      "                ",
      "                ",
      "                ",
      "                ",
      "                ",
      "                ",
      "                ",
      "DDDDDDDDDDDDDDDD"
    ]
  ]
}