{
  "name": "multi_nuclearpowerplant_15_base7",
  "refpalette": "deceasedcraft:multi_nuclearpowerplant_15/multi_nuclearpowerplant_15_base7_palette",
  "xsize": 16,
  "zsize": 16,
  "slices": [
    [
      "                ",
      "      a  b      ",
      "                ",
      "                ",
      "                ",
      "                ",
      "                ",
      "                ",
      "      a  b      ",
      "                ",
      "                ",
      "                ",
      "                ",
      "                ",
      "                ",
      "      a  b      "
    ],
    [
      "       cc       ",
      "      accb      ",
      "       cc       ",
      "       cc       ",
      "       cc       ",
      "       cc       ",
      "       cc       ",
      "       cc       ",
      "      accb      ",
      "       cc       ",
      "       cc       ",
      "       cc       ",
      "       cc       ",
      "       cc       ",
      "       cc       ",
      "      accb      "
    ],
    [
      "      deef      ",
      "      deef      ",
      "      deef      ",
      "      deef      ",
      "      deef      ",
      "      deef      ",
      "      deef      ",
      "      deef      ",
      "      deef      ",
      "      deef      ",
      "      deef      ",
      "      deef      ",
      "      deef      ",
      "      deef      ",
      "      deef      ",
      "      deef      "
    ],
    [
      "      deef      ",
      "      deef      ",
      "      deef      ",
      "      deef      ",
      "      deef      ",
      "      deef      ",
      "      deef      ",
      "      deef      ",
      "      deef      ",
      "      deef      ",
      "      deef      ",
      "      deef      ",
      "      deef      ",
      "      deef      ",
      "      deef      ",
      "      deef      "
    ],
    [
      "       gg       ",
      "       gg       ",
      "       gg       ",
      "       gg       ",
      "       gg       ",
      "       gg       ",
      "       gg       ",
      "       gg       ",
      "       gg       ",
      "       gg       ",
      "       gg       ",
      "       gg       ",
      "       gg       ",
      "       gg       ",
      "       gg       ",
      "       gg       "
    ],
    [
      "hhhhh      hhhhh",
      "hhhhh      hhhhh",
      "hhhhh      hhhhh",
      "hhhhh      hhhhh",
      "hhhhh      hhhhh",
      "hhhhh      hhhhh",
      "hhhhh      hhhhh",
      "hhhhh      hhhhh",
      "hhhhh      hhhhh",
      "hhhhh      hhhhh",
      "hhhhh      hhhhh",
      "hhhhh      hhhhh",
      "hhhhh      hhhhh",
      "hhhhh      hhhhh",
      "hhhhh      hhhhh",
      "hhhhh      hhhhh"
    ]
  ]
}