{
  "name": "multi_nuclearpowerplant_15_ground",
  "refpalette": "deceasedcraft:multi_nuclearpowerplant_15/multi_nuclearpowerplant_15_ground_palette",
  "xsize": 16,
  "zsize": 16,
  "slices": [
    [
      "      !ab       ",
      "      a b       ",
      "        b       ",
      "      c bc      ",
      "      d bd      ",
      "        b       ",
      "        b       ",
      "        b       ",
      "        b       ",
      "        b       ",
      "       eb       ",
      "        f       ",
      "                ",
      "                ",
      "                ",
      "                "
    ],
    [
      "gggg  a         ",
      "g               ",
      "      c  c      ",
      "      d  d      ",
      "                ",
      "                ",
      "                ",
      "                ",
      "                ",
      "                ",
      "                ",
      "                ",
      "                ",
      "                ",
      "                ",
      "                "
    ],
    [
      "gggggggggggggggg",
      "gggggggggggggggg",
      "gggggggggggggggg",
      "gggggggggggggggg",
      "ggggg         gg",
      "                ",
      "                ",
      "                ",
      "                ",
      "                ",
      "                ",
      "                ",
      "                ",
      "                ",
      "                ",
      "                "
    ],
    [
      "zzzzzzzzzzzzzzzh",
      "zzzzzzzzzzzzzzzz",
      "zhzzzzzzzzzzzzzz",
      "zzzhgggggggggggz",
      "gggggggggggggggg",
      "gggggggggggggggg",
      "gggggggggggggggg",
      "gggggggggggggggg",
      "         ggggggg",
      "             ggg",
      "                ",
      "                ",
      "                ",
      "                ",
      "                ",
      "                "
    ],
    [
      "   i j          ",
      "  j      j      ",
      "    j z  jzzj j ",
      " j  zzzzzzzzzzzz",
      "zzzzzzzzzzzzzzzz",
      "zzzzzzzzzzzzzzzz",
      "zzzzzzzzzzzzzzzz",
      "ggggggggggzzzzzz",
      "ggggggggggggggzz",
      "gggggggggggggggg",
      "gggggggggggggggg",
      "g   gggggggggggg",
      "        gggggggg",
      "          gggggg",
      "            gggg",
      "              gg"
    ],
    [
      "                ",
      "                ",
      "                ",
      "        j       ",
      "j jj jj     j   ",
      "j        i     j",
      "zj z    z      j",
      "zzzzzzzzzzz z   ",
      "zzzzzzzzzzzzzzz ",
      "zzzzzhzzzzzzzzzz",
      "gggggzzzzzzzzzzz",
      "gggggggggzzzzzzz",
      "gggggggggggzzzzz",
      "gggggggggggggzzz",
      "gggggggggggggggz",
      "   ggggggggggggg"
    ]
  ]
}