{
  "name": "multi_nuclearpowerplant_15_base1",
  "refpalette": "deceasedcraft:multi_nuclearpowerplant_15/multi_nuclearpowerplant_15_base1_palette",
  "xsize": 16,
  "zsize": 16,
  "slices": [
    [
      "aaaaaaaaaaaaaaaa",
      "aaaaaaaaaaaaaaaa",
      "aaaaaaaaaaaaaaaa",
      "aaaaaaaaaaaaaaaa",
      "aaaabbbbbbbbaaaa",
      "abbbb cccc bbbba",
      "bb    cccc    bb",
      "      cccc      ",
      "                ",
      "                ",
      "       d        ",
      "        e       ",
      "                ",
      "                ",
      "                ",
      "                "
    ],
    [
      "                ",
      "                ",
      "                ",
      "    ff    ff    ",
      "    gh    ig    ",
      " ggggh    igggg ",
      "gg   h    i   gg",
      "     hjjjji     ",
      "                ",
      "                ",
      "       d        ",
      "        e       ",
      "                ",
      "                ",
      "                ",
      "                "
    ],
    [
      "                ",
      "                ",
      "                ",
      "                ",
      "                ",
      "                ",
      "                ",
      "                ",
      "                ",
      "                ",
      "       d        ",
      "        e       ",
      "                ",
      "                ",
      "                ",
      "                "
    ],
    [
      "                ",
      "                ",
      "                ",
      "                ",
      "                ",
      "                ",
      "                ",
      "                ",
      "                ",
      "                ",
      "       d        ",
      "        e       ",
      "                ",
      "                ",
      "                ",
      "                "
    ],
    [
      "      k  k      ",
      "      k  k      ",
      "      k  k      ",
      "      k  k      ",
      "      k  k      ",
      "      k  k      ",
      "      k  k      ",
      "      k  k      ",
      "      l  l      ",
      "      l  l      ",
      "      ld l      ",
      "        e       ",
      "                ",
      "                ",
      "                ",
      "                "
    ],
    [
      "      mn m      ",
      "      m  m      ",
      "      m  m      ",
      "      m  m      ",
      "      o  o      ",
      "      p  p      ",
      "      p  p      ",
      "      p  p      ",
      "      p  p      ",
      "      p  p      ",
      "      qrsq      ",
      "        e       ",
      "                ",
      "                ",
      "                ",
      "                "
    ]
  ]
}