{
  "name": "multi_verticalschool_23_base2",
  "refpalette": "deceasedcraft:multi_verticalschool_23/multi_verticalschool_23_base2_palette",
  "xsize": 16,
  "zsize": 16,
  "slices": [
    [
      "vvvvvvvvvvvvvvvv",
      "vvvvvvvvvvvvvvvv",
      "vvvvvvvvvvvvvvvv",
      "vvvvvvvvvvvvvvvv",
      "vvvvvvvvvvvvvvvv",
      "vvvvvvvvvvvvvvvv",
      "vvvvvvvvvvvvvvvv",
      "vvvvvvvvvvvvvvvv",
      "vvvvvvvvvvvvvvvv",
      "vvvvvvvvvvvvvvvv",
      "vvvvvvvvvvvvvvvv",
      "vvvvvvvvvvvvvvvv",
      "vvvvvvvvvvvvvvvv",
      "vvvvvvvvvvvvvvvv",
      "vvvvvvvvvvvvvvvv",
      "vvvvvvvvvvvvvvvv"
    ],
    [
      "aaaaaaaaaaabbbbv",
      "aaaaaaaaaaabbbbv",
      "aaaaaaaaaaabbbbv",
      "aaaaaaaaaaabbbbv",
      "aaaaaaaaaaabbbbv",
      "aaaaaaaaaaabbbbv",
      "aaaaaaaaaaabbbbv",
      "aaaaaaaaaaabbbbv",
      "aaaaaaaaaaabbbbv",
      "aaaaaaaaaaabbbbv",
      "aaaaaaaaaaabbbbv",
      "aaaaaaaaaaabbbbv",
      "aaaaaaaaaaabbbbv",
      "aaaaaaaaaaabbbbv",
      "aaaaaaacccabbbbv",
      "aaaaaaaaaaabbbbv"
    ],
    [
      "aaaaaaaaaaabbbbv",
      "aaaaaaaaaaabbbbv",
      "aaaaaaaaaaabbbbv",
      "aaaaaaaaaaabbbbv",
      "aaaaaaaaaaabbbbv",
      "aaaaaaaaaaabbbbv",
      "aaaaaaaaaaabbbbv",
      "aaaaaaaaaaabbbbv",
      "aaaaaaaaaaabbbbv",
      "aaaaaaaaaaabbbbv",
      "aaaaaaaaaaabbbbv",
      "aaaaaaaaaaabbbbv",
      "aaaaaaaaaaabbbbv",
      "aaaaaaaaaaabbbbv",
      "aaaaaaacccabbbbv",
      "aaaaaaaaaaabbbbv"
    ],
    [
      "HHHHHHHHHdebbbbv",
      "HHHHHHHHHdebbbbv",
      "HHHHHHHHHdebbbbv",
      "HHHHHHHHHdebbbbv",
      "HHHHHHHHHdebbbbv",
      "HHHHHHHHHdebbbbv",
      "HHHHHHHHHdebbbbv",
      "HHHHHHHHHdebbbbv",
      "HHHHHHHHHdebbbbv",
      "HHHHHHHHHdebbbbv",
      "HHHHHHHHHdebbbbv",
      "HHHHHHHHHdebbbbv",
      "HHHHHHHHHdebbbbv",
      "HHHHHHHHHdebbbbv",
      "HHHHHHHcccebbbbv",
      "HHHHHHHHHdebbbbv"
    ],
    [
      "   f      ebbbbv",
      "ggghgijk  ebbbbv",
      "lllllgi   ebbbbv",
      "lllllgi   ebbbbv",
      "lllllgi   ebbbbv",
      "ggghgijm  ebbbbv",
      "   n      ebbbbv",
      "          ebbbbv",
      "       k  ebbbbv",
      "          ebbbbv",
      "o         ebbbbv",
      "          ebbbbv",
      "       m  ebbbbv",
      "          ebbbbv",
      "       cccebbbbv",
      "   f      ebbbbv"
    ],
    [
      "          pbbbbv",
      "qqrstqqu  pbbbbv",
      "wwwwwxy   pbbbbv",
      "wwwwwxy   pbbbbv",
      "wwwwwxy   pbbbbv",
      "qqrAtqqu  pbbbbv",
      "          pbbbbv",
      "          pbbbbv",
      "          pbbbbv",
      "          pbbbbv",
      "          pbbbbv",
      "          pbbbbv",
      "          pbbbbv",
      "          pbbbbv",
      "       cccpbbbbv",
      "          pbbbbv"
    ]
  ]
}