{
  "name": "multi_verticalschool_23_base1",
  "refpalette": "deceasedcraft:multi_verticalschool_23/multi_verticalschool_23_base1_palette",
  "xsize": 16,
  "zsize": 16,
  "slices": [
    [
      "aaaaaa    bccccv",
      "ddddddd   bccccv",
      "efefegdh  bccccv",
      " i j gdh  bccccv",
      "efefegdh  bccccv",
      "ddddkdd   bccccv",
      "llll l    bccccv",
      "          bccccv",
      "          bccccv",
      "          bccccv",
      "          bccccv",
      "          bccccv",
      "          bccccv",
      "          bccccv",
      "       mmmbccccv",
      "aaaaaa    bccccv"
    ],
    [
      "          bccccv",
      "nnnnnno   bccccv",
      "      p   bccccv",
      "      p   bccccv",
      "      p   bccccv",
      "nnnnqno   bccccv",
      "          bccccv",
      "          bccccv",
      "          bccccv",
      "          bccccv",
      "          bccccv",
      "          bccccv",
      "          bccccv",
      "          bccccv",
      "       mmmbccccv",
      "          bccccv"
    ],
    [
      "          bccccv",
      "rrrrrrs   bccccv",
      "ttttttu   bccccv",
      "www  tu   bccccv",
      "ttttttu   bccccv",
      "rrrrrrs   bccccv",
      "          bccccv",
      "          bccccv",
      "          bccccv",
      "          bccccv",
      "          bccccv",
      "          bccccv",
      "          bccccv",
      "          bccccv",
      "       mmmbccccv",
      "          bccccv"
    ],
    [
      "          bccccv",
      "          bccccv",
      "          bccccv",
      "   xy     bccccv",
      "          bccccv",
      "          bccccv",
      "          bccccv",
      "          bccccv",
      "          bccccv",
      "          bccccv",
      "          bccccv",
      "          bccccv",
      "          bccccv",
      "          bccccv",
      "       mmmbccccv",
      "          bccccv"
    ],
    [
      "          bccccv",
      "          bccccv",
      "          bccccv",
      "          bccccv",
      "          bccccv",
      "          bccccv",
      "          bccccv",
      "          bccccv",
      "          bccccv",
      "          bccccv",
      "          bccccv",
      "          bccccv",
      "          bccccv",
      "          bccccv",
      "       mmmbccccv",
      "          bccccv"
    ],
    [
      "AAAAAAAAAABccccv",
      "AAAAAAAAAABccccv",
      "AAAAAAAAAABccccv",
      "AAAAAAACCABccccv",
      "AAAAAAAAAABccccv",
      "AAAAAAAAAABccccv",
      "AAAAAAAAAABccccv",
      "AAAAAAAAAABccccv",
      "AAAAAAAAAABccccv",
      "AAAAAAAAAABccccv",
      "AAAAAAACCABccccv",
      "AAAAAAAAAABccccv",
      "AAAAAAAAAABccccv",
      "AAAAAAAAAABccccv",
      "AAAAAAAmmmBccccv",
      "AAAAAAAAAABccccv"
    ]
  ]
}