{
  "name": "multi_filmworkstower_17_base3",
  "refpalette": "deceasedcraft:multi_filmworkstower_17/multi_filmworkstower_17_base3_palette",
  "xsize": 16,
  "zsize": 16,
  "slices": [
    [
      "aaaabbbbbbbbbbbb",
      "aaaabbbbbbbbbbbb",
      "aaaabbbbbbbbbbbb",
      "aaaabbbbbbbbbbbb",
      "aaaabbbbbbbbbbbb",
      "aaaabbbbbbbbbbbb",
      "aaaabbbbbbbbbbbb",
      "aaaabbbbbbbbbbbb",
      "aaaabbbbbbbbbbbb",
      "aaaabbbbbbbbbbbb",
      "aaaabbbbbbbbbbbb",
      "aaaabbbbbbbbbbbb",
      "aaaabbbbbbbbbbbb",
      "aaaabbbbbbbbbbbb",
      "aaaabbbbbbbbbbbb",
      "aaaabbbbbbbbbbbb"
    ],
    [
      "aaaabcddeddddddd",
      "aaaabcdddddddddd",
      "aaaabcdddddddddd",
      "aaaabcdddddddddd",
      "aaaabcdddddddddd",
      "aaaabcdddddfdddd",
      "aaaabcdddddddddd",
      "aaaabcdddddddddd",
      "aaaabcdddddddddd",
      "aaaabcdddddddddd",
      "aaaabcdddddddddd",
      "aaaabcdddddddddd",
      "aaaabcdddddddddd",
      "aaaabcdddddddddd",
      "aaaabcdddddddddd",
      "aaaabcdddddddddd"
    ],
    [
      "aaaabcdegddddddd",
      "aaaabcddfddddddd",
      "aaaabcddedhdddid",
      "aaaabcdjkkkdkl d",
      "aaaabckkdmhhnokk",
      "aaaabcpppppqpppp",
      "aaaabcdddddeeddd",
      "aaaabcdddddddddd",
      "aaaabcdddddddddd",
      "aaaabcdddddddddd",
      "aaaabcdddfdddddd",
      "aaaabcdrdedddddd",
      "aaaabcddddeddddk",
      "aaaabcdddddk dks",
      "aaaabcdddkkttk  ",
      "aaaabcdddt tk  s"
    ],
    [
      "aaaabc      s   ",
      "aaaabcl    u    ",
      "aaaabc wx    y  ",
      "aaaabc A        ",
      "aaaabc BC       ",
      "aaaabcpBppp ppDp",
      "aaaabc BEEF  EEE",
      "aaaabcpB EEEuD  ",
      "aaaabc Bxkkkk tk",
      "aaaabckBl  k kk ",
      "aaaabckBI ktk  l",
      "aaaabcJAk     s ",
      "aaaabckB     l  ",
      "aaaabc Bll      ",
      "aaaabckB        ",
      "aaaabc B        "
    ],
    [
      "aaaabc          ",
      "aaaabc          ",
      "aaaabc          ",
      "aaaabc K        ",
      "aaaabc L        ",
      "aaaabcDLD M D   ",
      "aaaabc L        ",
      "aaaabc L        ",
      "aaaabc L        ",
      "aaaabc L        ",
      "aaaabc L        ",
      "aaaabc L        ",
      "aaaabc L        ",
      "aaaabc L        ",
      "aaaabc L        ",
      "aaaabc L        "
    ],
    [
      "aaaabc          ",
      "aaaabc          ",
      "aaaabc          ",
      "aaaabc          ",
      "aaaabc          ",
      "aaaabc          ",
      "aaaabc          ",
      "aaaabc          ",
      "aaaabc          ",
      "aaaabc          ",
      "aaaabc          ",
      "aaaabc          ",
      "aaaabc          ",
      "aaaabc          ",
      "aaaabc          ",
      "aaaabc          "
    ]
  ]
}