{
  "name": "multi_filmworkstower_17_base2",
  "refpalette": "deceasedcraft:multi_filmworkstower_17/multi_filmworkstower_17_base2_palette",
  "xsize": 16,
  "zsize": 16,
  "slices": [
    [
      "aaaaab          ",
      "aaaaab          ",
      "aaaaab          ",
      "aaaaab          ",
      "aaaaab          ",
      "aaaaab          ",
      "aaaaab          ",
      "aaaaab          ",
      "aaaaab          ",
      "aaaaab          ",
      "aaaaab          ",
      "aaaaab          ",
      "aaaaab          ",
      "aaaaab          ",
      "aaaaab          ",
      "aaaaab          "
    ],
    [
      "     b          ",
      "     b          ",
      "     b          ",
      "     b          ",
      "     b          ",
      "     b          ",
      "     b          ",
      "     b          ",
      "     b          ",
      "     b          ",
      "     b          ",
      "     b          ",
      "   cdb          ",
      "     b          ",
      "     b          ",
      "     b          "
    ],
    [
      "     b          ",
      "     b          ",
      "     b          ",
      "     b          ",
      "     b          ",
      "     b          ",
      "     b          ",
      "     b          ",
      "     b          ",
      "     b          ",
      "     b          ",
      "     b          ",
      "    db          ",
      "     b          ",
      "     b          ",
      "     b          "
    ],
    [
      "    eb          ",
      "     b          ",
      "     b          ",
      "     b          ",
      "     b          ",
      "     b          ",
      "     b          ",
      "     b          ",
      "     b          ",
      "     b          ",
      "     b          ",
      "    fb          ",
      "    db          ",
      "    eb          ",
      "     b          ",
      "     b          "
    ],
    [
      "    gb          ",
      "    gb          ",
      "    gb          ",
      "    gb          ",
      "    gb          ",
      "    gb          ",
      "    gb          ",
      "    gb          ",
      "    gb          ",
      "    gb          ",
      "    gb          ",
      "    gb          ",
      "   hdb          ",
      "    gb          ",
      "    gb          ",
      "    gb          "
    ],
    [
      "     b          ",
      "     b          ",
      "     b          ",
      "     b          ",
      "     b          ",
      "     b          ",
      "     b          ",
      "     b          ",
      "     b          ",
      "     b          ",
      "     b          ",
      "     b          ",
      "i   db          ",
      "     b          ",
      "     b          ",
      "     b          "
    ]
  ]
}