{
  "name": "multi_filmworkstower_17_ground",
  "refpalette": "deceasedcraft:multi_filmworkstower_17/multi_filmworkstower_17_ground_palette",
  "xsize": 16,
  "zsize": 16,
  "slices": [
    [
      "aaaaaaaabcHHHHHH",
      "aaaaaaaabcHHHHHH",
      "aaaaaaaabcHHHHHH",
      "aaaaaaaabcHHHHHH",
      "aaaaaaaabcHHHHHH",
      "aaaaaaaabcHHHHHH",
      "aaaaaaaabcHHHHHH",
      "aaaaaaaabcHHHHHH",
      "aaaaaaaabcHHHHHH",
      "aaaaaaaabcHHHHHH",
      "aaaaaaaabcHHHHHH",
      "aaaaaaaabcHHHHHH",
      "aaaaaaaabcHHHHHH",
      "baaaaaabbcHHHHHH",
      "bbaaaabbcHHHHHHH",
      "cbbbbbbcHHHHHHHH"
    ],
    [
      "d      de       ",
      "d      de     fg",
      "d  h   de       ",
      "d      de       ",
      "d      de       ",
      "d      de       ",
      "d      de     ij",
      "d      de       ",
      "d      de       ",
      "d   h  de     fg",
      "d      de     ij",
      "d      de       ",
      "d      de       ",
      "ed    dee     fg",
      "eeddddee        ",
      " eeeeee         "
    ],
    [
      "                ",
      "                ",
      "   k            ",
      "                ",
      "                ",
      "                ",
      "                ",
      "                ",
      "                ",
      "    k           ",
      "                ",
      "                ",
      "                ",
      "                ",
      "                ",
      "                "
    ],
    [
      "                ",
      "                ",
      "   d            ",
      "   d            ",
      "                ",
      "                ",
      "                ",
      "                ",
      "    d           ",
      "    d           ",
      "                ",
      "                ",
      "                ",
      "                ",
      "                ",
      "                "
    ],
    [
      "                ",
      "   l            ",
      "  ddd           ",
      "   d            ",
      "                ",
      "                ",
      "                ",
      "                ",
      "    d           ",
      "   dd           ",
      "    d           ",
      "                ",
      "                ",
      "                ",
      "                ",
      "                "
    ],
    [
      "                ",
      "   d            ",
      "   dd           ",
      "   l            ",
      "                ",
      "                ",
      "                ",
      "                ",
      "    l           ",
      "   ddd          ",
      "    d           ",
      "                ",
      "                ",
      "                ",
      "                ",
      "                "
    ]
  ]
}