{
  "name": "multi_filmworkstower_17_base1",
  "refpalette": "deceasedcraft:multi_filmworkstower_17/multi_filmworkstower_17_base1_palette",
  "xsize": 16,
  "zsize": 16,
  "slices": [
    [
      "     a          ",
      "     a          ",
      "     a          ",
      "     a          ",
      "     a          ",
      "     a          ",
      "     a          ",
      "     a          ",
      "     a          ",
      "     a          ",
      "     a          ",
      "     a          ",
      "b   ca          ",
      "     a          ",
      "     a          ",
      "     a          "
    ],
    [
      "    da          ",
      "     a          ",
      "     a          ",
      "     a          ",
      "     a          ",
      "     a          ",
      "     a          ",
      "     a          ",
      "     a          ",
      "     a          ",
      "     a          ",
      "    ea          ",
      "bf gca          ",
      "    da          ",
      "     a          ",
      "     a          "
    ],
    [
      "    ha          ",
      "    ha          ",
      "    ha          ",
      "    ha          ",
      "    ha          ",
      "    ha          ",
      "    ha          ",
      "    ha          ",
      "    ha          ",
      "    ha          ",
      "    ha          ",
      "    ha          ",
      "bbiica          ",
      "    ha          ",
      "    ha          ",
      "    ha          "
    ],
    [
      "                ",
      "           j   j",
      "           j   j",
      "           j   j",
      "           j   j",
      "           j   j",
      "           k   k",
      "           j   j",
      "           j   j",
      "           j   j",
      "           j   j",
      "           l   l",
      "mbfnco     j   j",
      "           j   j",
      "           j   j",
      "           j   j"
    ],
    [
      "ppppppqqqqqqqqqq",
      "ppppppqrrrrrrrrr",
      "ppppppqrstssstss",
      "ppppppqrsusssuss",
      "ppppppqrsusssuss",
      "ppppppqrsusssuss",
      "ppppppqrwxwrwxwr",
      "ppppppqrsusssuss",
      "ppppppqrsusssuss",
      "ppppppqrsusssuss",
      "ppppppqrsusssuss",
      "ppppppqrwxwrwxwr",
      "pbbpypqrsusssuss",
      "ppppppqrsusssuss",
      "ppppppqrsusssuss",
      "ppppppqrsusssuss"
    ],
    [
      "bbbbbbbbbbbbbbbb",
      "bbbbbbbbbbbbbbbb",
      "bbbbbbbbbbbbbbbb",
      "bbbbbbbbbbbbbbbb",
      "bbbbbbbbbbbbbbbb",
      "bbbbbbbbbbbbbbbb",
      "bbbbbbbbbbbbbbbb",
      "bbbbbbbbbbbbbbbb",
      "bbbbbbbbbbbbbbbb",
      "bbbbbbbbbbbbbbbb",
      "bbbbbbbbbbbbbbbb",
      "bbbbbbbbbbbbbbbb",
      "bbbbbbbbbbbbbbbb",
      "bbbbbbbbbbbbbbbb",
      "bbbbbbbbbbbbbbbb",
      "bbbbbbbbbbbbbbbb"
    ]
  ]
}