{
  "name": "multi_courtyardofficetower_1_floor13",
  "refpalette": "deceasedcraft:multi_courtyardofficetower_1/multi_courtyardofficetower_1_floor13_palette",
  "xsize": 16,
  "zsize": 16,
  "slices": [
    [
      "           abccd",
      "           abccd",
      "           ebccd",
      "        ffffbccd",
      "           ebccd",
      "           abccd",
      "           abccd",
      "          gabccd",
      "           abccd",
      "           abccd",
      "           ebccd",
      "        ffffbccd",
      "           ebccd",
      "           abccd",
      "           abccd",
      "          gabcch"
    ],
    [
      "           a   i",
      "           a   i",
      "           ej  i",
      "        ffffk  l",
      "           em  i",
      "           a   i",
      "           a   i",
      "          ga   i",
      "           a   i",
      "           a   i",
      "           ej  i",
      "        ffffk  l",
      "           em  i",
      "           a   i",
      "           a   i",
      "          ga   n"
    ],
    [
      "           a   i",
      "           a   i",
      "           e   i",
      "        ffff   l",
      "           e   i",
      "           a   i",
      "           a   i",
      "          ga   i",
      "           a   i",
      "           a   i",
      "           e   i",
      "        ffff   l",
      "           e   i",
      "           a   i",
      "           a   i",
      "          ga   o"
    ],
    [
      "           a   i",
      "           a   i",
      "           e   i",
      "        ffff   l",
      "           e   i",
      "           a   i",
      "           a   i",
      "          ga   i",
      "           a   i",
      "           a   i",
      "           e   i",
      "        ffff   l",
      "           e   i",
      "           a   i",
      "           a   i",
      "          ga   o"
    ],
    [
      "           a   i",
      "           a   i",
      "           e   i",
      "        ffff   l",
      "           e   i",
      "           a   i",
      "           a   i",
      "          ga   i",
      "           a   i",
      "           a   i",
      "           e   i",
      "        ffff   l",
      "           e   i",
      "           a   i",
      "           a   i",
      "          ga    "
    ],
    [
      "           a   i",
      "           a   i",
      "           e   i",
      "        ffff   l",
      "           e   i",
      "           a   i",
      "           a   i",
      "          ga   i",
      "           a   i",
      "           a   i",
      "           e   i",
      "        ffff   l",
      "           e   i",
      "           a   i",
      "           a   i",
      "          ga    "
    ]
  ]
}