{
  "name": "multi_courtyardofficetower_1_floor17",
  "refpalette": "deceasedcraft:multi_courtyardofficetower_1/multi_courtyardofficetower_1_floor17_palette",
  "xsize": 16,
  "zsize": 16,
  "slices": [
    [
      "           abbbc",
      "           abbbc",
      "           abbbc",
      "        ddddbbbc",
      "           abbbc",
      "           abbbc",
      "           abbbc",
      "          eabbbc",
      "           abbbc",
      "           abbbc",
      "           abbbc",
      "        ddddbbbc",
      "           abbbc",
      "           abbbc",
      "           abbbc",
      "          eabbbc"
    ],
    [
      "           f   g",
      "           f h g",
      "           ij  g",
      "        ddddk  g",
      "           ij l ",
      "           f    ",
      "           f    ",
      "          ef    ",
      "           fm   ",
      "           f    ",
      "           ij   ",
      "        ddddkh g",
      "           ij  g",
      "           fh  g",
      "           f   g",
      "          ef l  "
    ],
    [
      "           f    ",
      "           f    ",
      "           i    ",
      "        dddd    ",
      "           i    ",
      "           f    ",
      "           f    ",
      "          ef    ",
      "           f    ",
      "           f    ",
      "           i    ",
      "        dddd    ",
      "           i    ",
      "           f    ",
      "           f    ",
      "          ef    "
    ],
    [
      "           f    ",
      "           f    ",
      "           i    ",
      "        dddd    ",
      "           i    ",
      "           f    ",
      "           f    ",
      "          ef    ",
      "           f    ",
      "           f    ",
      "           i    ",
      "        dddd    ",
      "           i    ",
      "           f    ",
      "           f    ",
      "          ef    "
    ],
    [
      "           f    ",
      "           f    ",
      "           i    ",
      "        ddddn   ",
      "           i    ",
      "           f    ",
      "           f    ",
      "          ef    ",
      "           f    ",
      "           f    ",
      "           i    ",
      "        ddddn   ",
      "           i    ",
      "           f    ",
      "           f    ",
      "          ef    "
    ],
    [
      "           fooon",
      "           fopon",
      "           iooon",
      "        dddddddd",
      "           iooon",
      "           fopon",
      "           fooon",
      "          efooon",
      "           fooon",
      "           fopon",
      "           iooon",
      "        ddddooon",
      "           iooon",
      "           fopon",
      "           fooon",
      "          efooon"
    ]
  ]
}