{
  "name": "multi_courtyardofficetower_1_floor5",
  "refpalette": "deceasedcraft:multi_courtyardofficetower_1/multi_courtyardofficetower_1_floor5_palette",
  "xsize": 16,
  "zsize": 16,
  "slices": [
    [
      "           abbbc",
      "           abbbc",
      "           abbbc",
      "        ddddbbbc",
      "           abbbc",
      "           abbbc",
      "           abbbc",
      "          eabbbc",
      "           abbbc",
      "           abbbc",
      "           abbbc",
      "        ddddbbbc",
      "           abbbc",
      "           abbbc",
      "           abbbc",
      "          eabbbc"
    ],
    [
      "           f   g",
      "           f   g",
      "           hij g",
      "        ddddk lg",
      "           hi   ",
      "           f    ",
      "           fm   ",
      "          ef n  ",
      "           f    ",
      "           f m  ",
      "           hio  ",
      "        ddddk  g",
      "           hi ng",
      "           f  pg",
      "           f   g",
      "          ef    "
    ],
    [
      "           f    ",
      "           f    ",
      "           h    ",
      "        ddddq   ",
      "           h    ",
      "           f    ",
      "           f    ",
      "          ef    ",
      "           f    ",
      "           f    ",
      "           h    ",
      "        dddd    ",
      "           h    ",
      "           f    ",
      "           f    ",
      "          ef    "
    ],
    [
      "           f    ",
      "           f    ",
      "           h    ",
      "        dddd    ",
      "           h    ",
      "           f    ",
      "           f    ",
      "          ef    ",
      "           f    ",
      "           f    ",
      "           h    ",
      "        dddd    ",
      "           h    ",
      "           f    ",
      "           f    ",
      "          ef    "
    ],
    [
      "           f    ",
      "           f    ",
      "           h    ",
      "        dddd    ",
      "           h    ",
      "           f    ",
      "           f    ",
      "          ef    ",
      "           f    ",
      "           f    ",
      "           h    ",
      "        dddd    ",
      "           h    ",
      "           f    ",
      "           f    ",
      "          ef    "
    ],
    [
      "           frrrs",
      "           frtrs",
      "           hrrrs",
      "        dddddddd",
      "           hrrrs",
      "           frtrs",
      "           frrrs",
      "          efrrrs",
      "           frrrs",
      "           frtrs",
      "           hrrrs",
      "        ddddrrrs",
      "           hrrrs",
      "           frtrs",
      "           frrrs",
      "          efrrrs"
    ]
  ]
}