{
  "name": "multi_courtyardofficetower_1_floor7",
  "refpalette": "deceasedcraft:multi_courtyardofficetower_1/multi_courtyardofficetower_1_floor7_palette",
  "xsize": 16,
  "zsize": 16,
  "slices": [
    [
      "           abbbc",
      "           abbbc",
      "           abbbc",
      "        ddddbbbc",
      "           abbbc",
      "           abbbc",
      "           abbbc",
      "          eabbbc",
      "           abbbc",
      "           abbbc",
      "           abbbc",
      "        ddddbbbc",
      "           abbbc",
      "           abbbc",
      "           abbbc",
      "          eabbbc"
    ],
    [
      "           f   g",
      "           f   g",
      "           hi  g",
      "        ddddj  g",
      "           hi   ",
      "           f    ",
      "           f    ",
      "          ef    ",
      "           f    ",
      "           f    ",
      "           hi   ",
      "        ddddj  g",
      "           hi  g",
      "           f   g",
      "           f   g",
      "          ef    "
    ],
    [
      "           f    ",
      "           f    ",
      "           h    ",
      "        ddddk   ",
      "           h    ",
      "           f    ",
      "           f    ",
      "          ef    ",
      "           f    ",
      "           f    ",
      "           h    ",
      "        ddddl   ",
      "           h    ",
      "           f    ",
      "           f    ",
      "          ef    "
    ],
    [
      "           f    ",
      "           f    ",
      "           h    ",
      "        dddd    ",
      "           h    ",
      "           f    ",
      "           f    ",
      "          ef    ",
      "           f    ",
      "           f    ",
      "           h    ",
      "        dddd    ",
      "           h    ",
      "           f    ",
      "           f    ",
      "          ef    "
    ],
    [
      "           f    ",
      "           f    ",
      "           h    ",
      "        dddd    ",
      "           h    ",
      "           f    ",
      "           f    ",
      "          ef    ",
      "           f    ",
      "           f    ",
      "           h    ",
      "        dddd    ",
      "           h    ",
      "           f    ",
      "           f    ",
      "          ef    "
    ],
    [
      "           fmmmn",
      "           fmomn",
      "           hmmmn",
      "        dddddddd",
      "           hmmmn",
      "           fmomn",
      "           fmmmn",
      "          efmmmn",
      "           fmmmn",
      "           fmomn",
      "           hmmmn",
      "        ddddmmmn",
      "           hmmmn",
      "           fmomn",
      "           fmmmn",
      "          efmmmn"
    ]
  ]
}