{
  "name": "multi_courtyardofficetower_1_floor19",
  "refpalette": "deceasedcraft:multi_courtyardofficetower_1/multi_courtyardofficetower_1_floor19_palette",
  "xsize": 16,
  "zsize": 16,
  "slices": [
    [
      "           a    ",
      "           a    ",
      "           b    ",
      "        cccc    ",
      "           b    ",
      "           a    ",
      "           a    ",
      "          da    ",
      "           a    ",
      "           a    ",
      "           b    ",
      "        cccc    ",
      "           b    ",
      "           a    ",
      "           a    ",
      "          da    "
    ],
    [
      "           a    ",
      "           a    ",
      "           b    ",
      "        cccc    ",
      "           b    ",
      "           a    ",
      "           a    ",
      "          da    ",
      "           a    ",
      "           a    ",
      "           b    ",
      "        cccc    ",
      "           b    ",
      "           a    ",
      "           a    ",
      "          da    "
    ],
    [
      "           a    ",
      "           a    ",
      "           b    ",
      "        cccc    ",
      "           b    ",
      "           a    ",
      "           a    ",
      "          da    ",
      "           a    ",
      "           a    ",
      "           b    ",
      "        cccc    ",
      "           b    ",
      "           a    ",
      "           a    ",
      "          da    "
    ],
    [
      "           a    ",
      "           a    ",
      "           b    ",
      "        cccc    ",
      "           b    ",
      "           a    ",
      "           a    ",
      "          da    ",
      "           a    ",
      "           a    ",
      "           b    ",
      "        cccc    ",
      "           b    ",
      "           a    ",
      "           a    ",
      "          da    "
    ],
    [
      "           a    ",
      "           a    ",
      "           b    ",
      "        cccc    ",
      "           b    ",
      "           a    ",
      "           a    ",
      "          da    ",
      "           a    ",
      "           a    ",
      "           b    ",
      "        cccc    ",
      "           b    ",
      "           a    ",
      "           a    ",
      "          da    "
    ],
    [
      "           aeeee",
      "           aefee",
      "           beeee",
      "        cccccccc",
      "           beeee",
      "           aefee",
      "           aeeee",
      "          daeeee",
      "           aeeee",
      "           aefee",
      "           beeee",
      "        cccceeee",
      "           beeee",
      "           aefee",
      "           aeeee",
      "          daeeee"
    ]
  ]
}