{
  "name": "multi_courtyardofficetower_1_floor4",
  "refpalette": "deceasedcraft:multi_courtyardofficetower_1/multi_courtyardofficetower_1_floor4_palette",
  "xsize": 16,
  "zsize": 16,
  "slices": [
    [
      "           abbbc",
      "           abbbc",
      "           abbbc",
      "        ddddbbbc",
      "           abbbc",
      "           abbbc",
      "           abbbc",
      "          eabbbc",
      "           abbbc",
      "           abbbc",
      "           abbbc",
      "        ddddbbbc",
      "           abbbc",
      "           abbbc",
      "           abbbc",
      "          eabbbc"
    ],
    [
      "           f   g",
      "           f   g",
      "           hi  g",
      "        ddddj  g",
      "           hi   ",
      "           f    ",
      "           f    ",
      "          ef    ",
      "           f    ",
      "           f    ",
      "           hi   ",
      "        ddddj  g",
      "           hi  g",
      "           f   g",
      "           f   g",
      "          ef    "
    ],
    [
      "           f    ",
      "           f    ",
      "           h    ",
      "        dddd!   ",
      "           h    ",
      "           f    ",
      "           f    ",
      "          ef    ",
      "           f    ",
      "           f    ",
      "           h    ",
      "        dddd    ",
      "           h    ",
      "           f    ",
      "           f    ",
      "          ef    "
    ],
    [
      "           f    ",
      "           f    ",
      "           h    ",
      "        dddd    ",
      "           h    ",
      "           f    ",
      "           f    ",
      "          ef    ",
      "           f    ",
      "           f    ",
      "           h    ",
      "        dddd    ",
      "           h    ",
      "           f    ",
      "           f    ",
      "          ef    "
    ],
    [
      "           f    ",
      "           f    ",
      "           h    ",
      "        ddddk   ",
      "           h    ",
      "           f    ",
      "           f    ",
      "          ef    ",
      "           f    ",
      "           f    ",
      "           h    ",
      "        ddddk   ",
      "           h    ",
      "           f    ",
      "           f    ",
      "          ef    "
    ],
    [
      "           flllk",
      "           flmlk",
      "           hlllk",
      "        dddddddd",
      "           hlllk",
      "           flmlk",
      "           flllk",
      "          eflllk",
      "           flllk",
      "           flmlk",
      "           hlllk",
      "        ddddlllk",
      "           hlllk",
      "           flmlk",
      "           flllk",
      "          eflllk"
    ]
  ]
}