{
  "name": "multi_courtyardofficetower_1_base1",
  "refpalette": "deceasedcraft:multi_courtyardofficetower_1/multi_courtyardofficetower_1_base1_palette",
  "xsize": 16,
  "zsize": 16,
  "slices": [
    [
      "vvvvvvvvvvvvaaaa",
      "vvvvvvvvvvvvaaaa",
      "vvvvvvvvvvvvaaaa",
      "vvvvvvvvbbbbaaaa",
      "vvvvvvvvvvvvaaaa",
      "vvvvvvvvvvvvaaaa",
      "vvvvvvvvvvvvaaaa",
      "vvvvvvvvvvvvaaaa",
      "vvvvvvvvvvvvaaaa",
      "vvvvvvvvvvvvaaaa",
      "vvvvvvvvvvvvaaaa",
      "vvvvvvvvbbbbaaaa",
      "vvvvvvvvvvvvaaaa",
      "vvvvvvvvvvvvaaaa",
      "vvvvvvvvvvvvaaaa",
      "vvvvvvvvvvvvaaaa"
    ],
    [
      "vcHHHHccccccdeee",
      "vcHHHHccccccdeee",
      "vcHHHHccccccdeee",
      "vcHHHHccbbbbdeee",
      "vcHHHHccccccdeee",
      "vcHHHHccccccdeee",
      "vcHHHHccccccdeee",
      "vcHHHHccccccdeee",
      "vcHHHHccccccdeee",
      "vcHHHHccccccdeee",
      "vcHHHHccccccdeee",
      "vcHHHHccbbbbdeee",
      "vcHHHHccccccdeee",
      "vcHHHHccccccdeee",
      "vcHHHHccccccdeee",
      "vcHHHHccccccdeee"
    ],
    [
      "v      f  ghieee",
      "v          hieee",
      "v      j  khieee",
      "v       bbbbieee",
      "v      f  ghieee",
      "v        l hieee",
      "v      j  khieee",
      "v          hieee",
      "v      f  ghieee",
      "v          hieee",
      "v      j  khieee",
      "v       bbbbieee",
      "v      f  ghieee",
      "v          hieee",
      "v      j  khieee",
      "v          hieee"
    ],
    [
      "v           ieee",
      "v           ieee",
      "v           ieee",
      "v       bbbbieee",
      "v           ieee",
      "v           ieee",
      "v           ieee",
      "v           ieee",
      "v           ieee",
      "v           ieee",
      "v           ieee",
      "v       bbbbieee",
      "v           ieee",
      "v           ieee",
      "v           ieee",
      "v           ieee"
    ],
    [
      "v           ieee",
      "v           ieee",
      "v           ieee",
      "v       bbbbieee",
      "v           ieee",
      "v           ieee",
      "v           ieee",
      "v           ieee",
      "v           ieee",
      "v           ieee",
      "v           ieee",
      "v       bbbbieee",
      "v           ieee",
      "v           ieee",
      "v           ieee",
      "v           ieee"
    ],
    [
      "vmmmmmmmmmmmieee",
      "vmmmmmmmmmmmieee",
      "vmmmmmmmmmmmieee",
      "vmmmmmm!bbbbieee",
      "vmmmmmmmmmmmieee",
      "vmmmmmmmmmmmieee",
      "vmmmmmmmmmmmieee",
      "vmmmmmmmmmmmieee",
      "vmmmmmmmmmmmieee",
      "vmmmmmmmmmmmieee",
      "vmmmmmmmmmmmieee",
      "vmmmmmmnbbbbieee",
      "vmmmmmmmmmmmieee",
      "vmmmmmmmmmmmieee",
      "vmmmmmmmmmmmieee",
      "vmmmmmmmmmmmieee"
    ]
  ]
}