{
  "name": "multi_courtyardofficetower_1_floor14",
  "refpalette": "deceasedcraft:multi_courtyardofficetower_1/multi_courtyardofficetower_1_floor14_palette",
  "xsize": 16,
  "zsize": 16,
  "slices": [
    [
      "           a   b",
      "           a   b",
      "           c   b",
      "        dddd   e",
      "           c   b",
      "           a   b",
      "           a   b",
      "          fa   b",
      "           a   b",
      "           a   b",
      "           c   b",
      "        dddd   e",
      "           c   b",
      "           a   b",
      "           a   b",
      "          fa   g"
    ],
    [
      "           a   b",
      "           a   b",
      "           c   b",
      "        dddd   e",
      "           c   b",
      "           a   b",
      "           a   b",
      "          fa   b",
      "           a   b",
      "           a   b",
      "           c   b",
      "        dddd   e",
      "           c   b",
      "           a   b",
      "           a   b",
      "          fa   g"
    ],
    [
      "           a   b",
      "           a   b",
      "           c   b",
      "        dddd   e",
      "           c   b",
      "           a   b",
      "           a   b",
      "          fa   b",
      "           a   b",
      "           a   b",
      "           c   b",
      "        dddd   e",
      "           c   b",
      "           a   b",
      "           a   b",
      "          fa   g"
    ],
    [
      "           a   b",
      "           a   b",
      "           c   b",
      "        dddd   e",
      "           c   b",
      "           a   b",
      "           a   b",
      "          fa   b",
      "           a   b",
      "           a   b",
      "           c   b",
      "        dddd   e",
      "           c   b",
      "           a   b",
      "           a   b",
      "          fa   h"
    ],
    [
      "           a   b",
      "           a   b",
      "           c   b",
      "        dddd   e",
      "           c   b",
      "           a   b",
      "           a   b",
      "          fa   b",
      "           a   b",
      "           a   b",
      "           c   b",
      "        dddd   e",
      "           c   b",
      "           a   b",
      "           a   b",
      "          fa   i"
    ],
    [
      "           ajjjk",
      "           ajljk",
      "           cjjjk",
      "        dddddddd",
      "           cjjjk",
      "           ajljk",
      "           ajjjk",
      "          fajjjk",
      "           ajjjk",
      "           ajljk",
      "           cjjjk",
      "        ddddjjjk",
      "           cjjjk",
      "           ajljk",
      "           ajjjk",
      "          fajjjk"
    ]
  ]
}