{
  "name": "multi_courtyardofficetower_1_floor20",
  "refpalette": "deceasedcraft:multi_courtyardofficetower_1/multi_courtyardofficetower_1_floor20_palette",
  "xsize": 16,
  "zsize": 16,
  "slices": [
    [
      "           abccc",
      "           abccc",
      "           dbccc",
      "        eeeefccc",
      "           dbccc",
      "           abccc",
      "           abccc",
      "          gabhhh",
      "           abccc",
      "           abccc",
      "           dbccc",
      "        eeeefccc",
      "           dbccc",
      "           abccc",
      "           abccc",
      "          gabhhh"
    ],
    [
      "           gi   ",
      "           gi  j",
      "           ki lm",
      "        eeeen  o",
      "           kippp",
      "           giqrs",
      "           gittt",
      "          ggiuuu",
      "           gittt",
      "           giwxy",
      "           kiAAA",
      "        eeeen   ",
      "           kippp",
      "           giqrs",
      "           gittt",
      "          ggiuuu"
    ],
    [
      "                ",
      "                ",
      "               B",
      "        eeeeC   ",
      "                ",
      "                ",
      "                ",
      "             DED",
      "                ",
      "                ",
      "                ",
      "        eeeeC   ",
      "                ",
      "                ",
      "                ",
      "              FI"
    ],
    [
      "                ",
      "                ",
      "                ",
      "        eeeeJ   ",
      "                ",
      "                ",
      "                ",
      "                ",
      "                ",
      "                ",
      "                ",
      "        eeeeJ   ",
      "                ",
      "                ",
      "                ",
      "                "
    ],
    [
      "                ",
      "                ",
      "                ",
      "        eeeeJ   ",
      "                ",
      "                ",
      "                ",
      "                ",
      "                ",
      "                ",
      "                ",
      "        eeeeJ   ",
      "                ",
      "                ",
      "                ",
      "                "
    ],
    [
      "                ",
      "                ",
      "                ",
      "        eeeeK   ",
      "                ",
      "                ",
      "                ",
      "                ",
      "                ",
      "                ",
      "                ",
      "        eeeeK   ",
      "                ",
      "                ",
      "                ",
      "                "
    ]
  ]
}