{
  "name": "multi_courtyardofficetower_1_floor8",
  "refpalette": "deceasedcraft:multi_courtyardofficetower_1/multi_courtyardofficetower_1_floor8_palette",
  "xsize": 16,
  "zsize": 16,
  "slices": [
    [
      "           abbbc",
      "           abbbc",
      "           abbbc",
      "        ddddbbbc",
      "           abbbc",
      "           abbbc",
      "           abbbc",
      "          eabbbc",
      "           abbbc",
      "           abbbc",
      "           abbbc",
      "        ddddbbbc",
      "           abbbc",
      "           abbbc",
      "           abbbc",
      "          eabbbc"
    ],
    [
      "           f   g",
      "           f   g",
      "           hi  g",
      "        ddddj  g",
      "           hk   ",
      "           f    ",
      "           f    ",
      "          ef    ",
      "           f    ",
      "           f    ",
      "           hi   ",
      "        ddddj  g",
      "           hk  g",
      "           f   g",
      "           f   g",
      "          ef    "
    ],
    [
      "           f    ",
      "           f    ",
      "           h    ",
      "        dddd    ",
      "           h    ",
      "           f    ",
      "           f    ",
      "          ef    ",
      "           f    ",
      "           f    ",
      "           h    ",
      "        dddd    ",
      "           h    ",
      "           f    ",
      "           f    ",
      "          ef    "
    ],
    [
      "           f    ",
      "           f    ",
      "           h    ",
      "        dddd    ",
      "           h    ",
      "           f    ",
      "           f    ",
      "          ef    ",
      "           f    ",
      "           f    ",
      "           h    ",
      "        dddd    ",
      "           h    ",
      "           f    ",
      "           f    ",
      "          ef    "
    ],
    [
      "           f    ",
      "           f    ",
      "           h    ",
      "        dddd    ",
      "           h    ",
      "           f    ",
      "           f    ",
      "          ef    ",
      "           f    ",
      "           f    ",
      "           h    ",
      "        dddd    ",
      "           h    ",
      "           f    ",
      "           f    ",
      "          ef    "
    ],
    [
      "           f    ",
      "           f    ",
      "           h    ",
      "        dddd    ",
      "           h    ",
      "           f    ",
      "           f    ",
      "          ef    ",
      "           f    ",
      "           f    ",
      "           h    ",
      "        dddd    ",
      "           h    ",
      "           f    ",
      "           f    ",
      "          ef    "
    ]
  ]
}