{
  "name": "multi_courtyardofficetower_1_floor18",
  "refpalette": "deceasedcraft:multi_courtyardofficetower_1/multi_courtyardofficetower_1_floor18_palette",
  "xsize": 16,
  "zsize": 16,
  "slices": [
    [
      "           abbbc",
      "           abbbc",
      "           abbbc",
      "        ddddbbbc",
      "           abbbc",
      "           abbbc",
      "           abbbc",
      "          eabbbc",
      "           abbbc",
      "           abbbc",
      "           abbbc",
      "        ddddbbbc",
      "           abbbc",
      "           abbbc",
      "           abbbc",
      "          eabbbc"
    ],
    [
      "           fg  h",
      "           fi  h",
      "           jk  h",
      "        dddd   h",
      "           jg   ",
      "           fi   ",
      "           fk   ",
      "          ef    ",
      "           fg   ",
      "           fi   ",
      "           jk   ",
      "        dddd   h",
      "           jg  h",
      "           fi  h",
      "           fk  h",
      "          ef    "
    ],
    [
      "           f    ",
      "           fl   ",
      "           j    ",
      "        dddd    ",
      "           j    ",
      "           f    ",
      "           f    ",
      "          ef    ",
      "           f    ",
      "           fm   ",
      "           j    ",
      "        dddd    ",
      "           j    ",
      "           fn   ",
      "           f    ",
      "          ef    "
    ],
    [
      "           f    ",
      "           f    ",
      "           j    ",
      "        dddd    ",
      "           j    ",
      "           f    ",
      "           f    ",
      "          ef    ",
      "           f    ",
      "           f    ",
      "           j    ",
      "        dddd    ",
      "           j    ",
      "           f    ",
      "           f    ",
      "          ef    "
    ],
    [
      "           f    ",
      "           f    ",
      "           j    ",
      "        dddd    ",
      "           j    ",
      "           f    ",
      "           f    ",
      "          ef    ",
      "           f    ",
      "           f    ",
      "           j    ",
      "        dddd    ",
      "           j    ",
      "           f    ",
      "           f    ",
      "          ef    "
    ],
    [
      "           f    ",
      "           f    ",
      "           j    ",
      "        dddd    ",
      "           j    ",
      "           f    ",
      "           f    ",
      "          ef    ",
      "           f    ",
      "           f    ",
      "           j    ",
      "        dddd    ",
      "           j    ",
      "           f    ",
      "           f    ",
      "          ef    "
    ]
  ]
}