{
  "name": "multi_courtyardofficetower_1_floor3",
  "refpalette": "deceasedcraft:multi_courtyardofficetower_1/multi_courtyardofficetower_1_floor3_palette",
  "xsize": 16,
  "zsize": 16,
  "slices": [
    [
      "           a    ",
      "           a    ",
      "           b    ",
      "        cccc    ",
      "           b    ",
      "           a    ",
      "           a    ",
      "          da    ",
      "           a    ",
      "           a    ",
      "           b    ",
      "        cccc    ",
      "           b    ",
      "           a    ",
      "           a    ",
      "          da    "
    ],
    [
      "           a    ",
      "           a    ",
      "           b    ",
      "        cccc    ",
      "           b    ",
      "           a    ",
      "           a    ",
      "          da    ",
      "           a    ",
      "           a    ",
      "           b    ",
      "        cccc    ",
      "           b    ",
      "           a    ",
      "           a    ",
      "          da    "
    ],
    [
      "           a    ",
      "           a    ",
      "           b    ",
      "        cccc    ",
      "           b    ",
      "           a    ",
      "           a    ",
      "          da    ",
      "           a    ",
      "           a    ",
      "           b    ",
      "        cccc    ",
      "           b    ",
      "           a    ",
      "           a    ",
      "          da    "
    ],
    [
      "           a    ",
      "           a    ",
      "           b    ",
      "        cccc    ",
      "           b    ",
      "           a    ",
      "           a    ",
      "          da    ",
      "           a    ",
      "           a    ",
      "           b    ",
      "        cccc    ",
      "           b    ",
      "           a    ",
      "           a    ",
      "          da    "
    ],
    [
      "           a    ",
      "           a    ",
      "           b    ",
      "        cccc    ",
      "           b    ",
      "           a    ",
      "           a    ",
      "          da    ",
      "           a    ",
      "           a    ",
      "           b    ",
      "        cccc    ",
      "           b    ",
      "           a    ",
      "           a    ",
      "          da    "
    ],
    [
      "           aeeef",
      "           aegef",
      "           beeef",
      "        cccccccc",
      "           beeef",
      "           aegef",
      "           aeeef",
      "          daeeef",
      "           aeeef",
      "           aegef",
      "           beeef",
      "        cccceeef",
      "           beeef",
      "           aegef",
      "           aeeef",
      "          daeeef"
    ]
  ]
}