{
  "name": "multi_courtyardofficetower_1_ground",
  "refpalette": "deceasedcraft:multi_courtyardofficetower_1/multi_courtyardofficetower_1_ground_palette",
  "xsize": 16,
  "zsize": 16,
  "slices": [
    [
      "aaaaaaaaabcdeffa",
      "aaaaaaaaabcdaffa",
      "aaaaaaaaabbbgffa",
      "aaaaaaaahhhhaffa",
      "aaaaaaaaabbbafff",
      "aaaaaaaaabcdefff",
      "aaaaaaaaabcdgfff",
      "aaaaaaaaabideffa",
      "aaaaaaaaabcdeffa",
      "aaaaaaaaabcdafff",
      "aaaaaaaaabbbaffa",
      "aaaaaaaahhhhaffa",
      "aaaaaaaaabbbgfff",
      "aaaaaaaaabcdaffa",
      "aaaaaaaaabcdeffa",
      "aaaaaaaaabidgfff"
    ],
    [
      "  j  j  kd      ",
      "   l    kd     l",
      "        kddd    ",
      "j       hhhh   m",
      "  jl  j kddd    ",
      "        kd      ",
      "   j    kd      ",
      "        kd      ",
      "  l  j  kd      ",
      "    lj  kd      ",
      "        kddd    ",
      "     j  hhhh   m",
      "   j    kddd    ",
      " j      kd      ",
      "  l j j kd      ",
      "        kd      "
    ],
    [
      "                ",
      "   k           k",
      "                ",
      "        hhhh    ",
      "   k            ",
      "                ",
      "                ",
      "                ",
      "  k             ",
      "    k           ",
      "                ",
      "        hhhh    ",
      "                ",
      " j              ",
      "  k             ",
      "                "
    ],
    [
      "                ",
      "   j           j",
      "                ",
      "        hhhh    ",
      "   j            ",
      "                ",
      "                ",
      "                ",
      "  j             ",
      "    j           ",
      "                ",
      "        hhhh    ",
      "                ",
      "                ",
      "  j             ",
      "                "
    ],
    [
      "                ",
      "   j           j",
      "                ",
      "        hhhh    ",
      "   j            ",
      "                ",
      "                ",
      "                ",
      "  j             ",
      "    j           ",
      "                ",
      "        hhhh    ",
      "                ",
      "                ",
      "  j             ",
      "                "
    ],
    [
      "                ",
      "   j           n",
      "                ",
      "        hhhh    ",
      "   j            ",
      "                ",
      "                ",
      "                ",
      "  j             ",
      "    j           ",
      "                ",
      "        hhhh    ",
      "                ",
      "                ",
      "  j             ",
      "                "
    ]
  ]
}