{
  "name": "multi_courtyardofficetower_1_floor2",
  "refpalette": "deceasedcraft:multi_courtyardofficetower_1/multi_courtyardofficetower_1_floor2_palette",
  "xsize": 16,
  "zsize": 16,
  "slices": [
    [
      "           abccd",
      "           abccd",
      "           ebccd",
      "        ffffbccd",
      "           ebccd",
      "           abccd",
      "           abccd",
      "          gabccd",
      "           abccd",
      "           abccd",
      "           ebccd",
      "        ffffbccd",
      "           ebccd",
      "           abccd",
      "           abccd",
      "          gabccd"
    ],
    [
      "           ah  i",
      "           aj  i",
      "           e   i",
      "        ffff   i",
      "           e    ",
      "           a    ",
      "           ak   ",
      "          gah   ",
      "           aj   ",
      "           a    ",
      "           e    ",
      "        ffff   i",
      "           e   i",
      "           ak  i",
      "           ah  i",
      "          gaj   "
    ],
    [
      "           a    ",
      "           a    ",
      "           e    ",
      "        ffff    ",
      "           e    ",
      "           a    ",
      "           a    ",
      "          ga    ",
      "           a    ",
      "           a    ",
      "           e    ",
      "        ffff    ",
      "           e    ",
      "           a    ",
      "           a    ",
      "          ga    "
    ],
    [
      "           a    ",
      "           a    ",
      "           e    ",
      "        ffff    ",
      "           e    ",
      "           a    ",
      "           a    ",
      "          ga    ",
      "           a    ",
      "           a    ",
      "           e    ",
      "        ffff    ",
      "           e    ",
      "           a    ",
      "           a    ",
      "          ga    "
    ],
    [
      "           a    ",
      "           a    ",
      "           e    ",
      "        ffff    ",
      "           e    ",
      "           a    ",
      "           a    ",
      "          ga    ",
      "           a    ",
      "           a    ",
      "           e    ",
      "        ffff    ",
      "           e    ",
      "           a    ",
      "           a    ",
      "          ga    "
    ],
    [
      "           a    ",
      "           a    ",
      "           e    ",
      "        ffff    ",
      "           e    ",
      "           a    ",
      "           a    ",
      "          ga    ",
      "           a    ",
      "           a    ",
      "           e    ",
      "        ffff    ",
      "           e    ",
      "           a    ",
      "           a    ",
      "          ga    "
    ]
  ]
}