{
  "name": "multi_filmworkstower_19_floor1",
  "refpalette": "deceasedcraft:multi_filmworkstower_19/multi_filmworkstower_19_floor1_palette",
  "xsize": 16,
  "zsize": 16,
  "slices": [
    [
      "                ",
      "                ",
      "                ",
      "   a            ",
      "                ",
      "                ",
      "         bc     ",
      "                ",
      "                ",
      "                ",
      "    a           ",
      "                ",
      "                ",
      "                ",
      "                ",
      "                "
    ],
    [
      "                ",
      "                ",
      "                ",
      "                ",
      "                ",
      "                ",
      "          bc    ",
      "                ",
      "                ",
      "                ",
      "    d           ",
      "                ",
      "                ",
      "                ",
      "                ",
      "                "
    ],
    [
      "                ",
      "                ",
      "                ",
      "                ",
      "                ",
      "                ",
      "           bce  ",
      "                ",
      "                ",
      "                ",
      "                ",
      "                ",
      "                ",
      "                ",
      "                ",
      "                "
    ],
    [
      "                ",
      "                ",
      "                ",
      "                ",
      "                ",
      "                ",
      "eeeeeeeeeeefggge",
      "                ",
      "                ",
      "                ",
      "                ",
      "                ",
      "                ",
      "                ",
      "                ",
      "                "
    ],
    [
      "                ",
      "   h       h    ",
      "                ",
      "                ",
      "   h       h    ",
      "                ",
      "gggggggggggggggg",
      "                ",
      "                ",
      "                ",
      "                ",
      "                ",
      "                ",
      "                ",
      "                ",
      "                "
    ],
    [
      "iiiiiiiiiiiiiiii",
      "jjjjjjjjjjjjjjjj",
      "iiiiiiiiiiiiiiii",
      "iiiiiiiiiiiiiiii",
      "jjjjjjjjjjjjjjjj",
      "iiiiiiiiiiiiiiii",
      "gggggggggggggggg",
      "iiiiiiiiiiiiiiii",
      "kkkkkkkkkkkkkkkk",
      "                ",
      "                ",
      "                ",
      "                ",
      "                ",
      "                ",
      "                "
    ]
  ]
}