{
  "name": "multi_filmworkstower_19_ground",
  "refpalette": "deceasedcraft:multi_filmworkstower_19/multi_filmworkstower_19_ground_palette",
  "xsize": 16,
  "zsize": 16,
  "slices": [
    [
      "aaaaaaaabcHHHHHH",
      "ddddddddbcHHHHHH",
      "eeeeeeeebcHHHHHH",
      "eeeeeeeebcHHHHHH",
      "eeeeeeeebcHHHHHH",
      "eeeeeeeebcHHHHHH",
      "eeeef eebcHHHHHH",
      "eeeeeeeebcHHHHHH",
      "eeeeeeeebcHHHHHH",
      "eeeeeeeebcHHHHHH",
      "eeeeeeeebcHHHHHH",
      "eeeeeeeebcHHHHHH",
      "eeeeeeeebcHHHHHH",
      "eeeeeeeebcHHHHHH",
      "eeeeeeeebccccccc",
      "eeeeeeeebbbbbbbb"
    ],
    [
      "                ",
      "              gh",
      "i      ij     kl",
      "i  m   ij       ",
      "i      ij       ",
      "i      ij     gh",
      "i   no ij       ",
      "i      ij       ",
      "i      ij       ",
      "i      ij       ",
      "i   m  ij klklkl",
      "i      ij  p    ",
      "i      ij       ",
      "i      ij ghghgh",
      "i      ij       ",
      "i      ijjjjjjjj"
    ],
    [
      "                ",
      "                ",
      "                ",
      "   q            ",
      "                ",
      "                ",
      "     no         ",
      "                ",
      "                ",
      "                ",
      "    q           ",
      "                ",
      "                ",
      "                ",
      "                ",
      "                "
    ],
    [
      "                ",
      "                ",
      "                ",
      "   i            ",
      "   i            ",
      "                ",
      "      no        ",
      "                ",
      "                ",
      "                ",
      "    ii          ",
      "                ",
      "                ",
      "                ",
      "                ",
      "                "
    ],
    [
      "                ",
      "                ",
      "   i            ",
      "  rii           ",
      "   i            ",
      "                ",
      "       no       ",
      "                ",
      "                ",
      "    r           ",
      "   iii          ",
      "    i           ",
      "                ",
      "                ",
      "                ",
      "                "
    ],
    [
      "                ",
      "                ",
      "   i            ",
      "  ii            ",
      "   r            ",
      "                ",
      "        no      ",
      "                ",
      "                ",
      "    i           ",
      "   iii          ",
      "    r           ",
      "                ",
      "                ",
      "                ",
      "                "
    ]
  ]
}