{
  "name": "multi_filmworkstower_19_base2",
  "refpalette": "deceasedcraft:multi_filmworkstower_19/multi_filmworkstower_19_base2_palette",
  "xsize": 16,
  "zsize": 16,
  "slices": [
    [
      "aaaaab          ",
      "aaaaab          ",
      "aaaaab          ",
      "aaaaab          ",
      "aaaaab          ",
      "aaaaab          ",
      "aaaaab          ",
      "aaaaabbbbbbbbbbb",
      "aaaaaaaaaaaaaaaa",
      "aaaaaaaaaaaaaaaa",
      "aaaaaaaaaaaaaaaa",
      "aaaaaaaaaaaaaaaa",
      "aaaaaaaaaaaaaaaa",
      "cccccccccccccccc",
      "dddddddddddddddd",
      "vvvvvvvvvvvvvvvv"
    ],
    [
      "     b          ",
      "     b          ",
      "     b          ",
      "     b          ",
      "     b          ",
      "     b          ",
      "   efb          ",
      "     bbbbbbbbbbb",
      "                ",
      "                ",
      "                ",
      "                ",
      "                ",
      "cccccccccccccccc",
      "dddddddddddddddd",
      "vvvvvvvvvvvvvvvv"
    ],
    [
      "     b          ",
      "     b          ",
      "     b          ",
      "     b          ",
      "     b          ",
      "     b          ",
      "    fb          ",
      "     bbbbbbbbbbb",
      "                ",
      "                ",
      "                ",
      "                ",
      "                ",
      "cccccccccccccccc",
      "dddddddddddddddd",
      "vvvvvvvvvvvvvvvv"
    ],
    [
      "     b          ",
      "     b          ",
      "     b          ",
      "     b          ",
      "     b          ",
      "    gb          ",
      "    fb          ",
      "     bbbbbbbbbbb",
      "                ",
      "                ",
      "                ",
      "                ",
      "                ",
      "cccccccccccccccc",
      "dddddddddddddddd",
      "vvvvvvvvvvvvvvvv"
    ],
    [
      "    hb          ",
      "    hb          ",
      "    hb          ",
      "    hb          ",
      "    hb          ",
      "    hb          ",
      "   ifb          ",
      "     bbbbbbbbbbb",
      "                ",
      "                ",
      "                ",
      "                ",
      "                ",
      "cccccccccccccccc",
      "dddddddddddddddd",
      "vvvvvvvvvvvvvvvv"
    ],
    [
      "     b          ",
      "     b          ",
      "     b          ",
      "     b          ",
      "     b          ",
      "     b          ",
      "j   fb          ",
      "     bbbbbbbbbbb",
      "                ",
      "                ",
      "                ",
      "                ",
      "                ",
      "cccccccccccccccc",
      "dddddddddddddddd",
      "vvvvvvvvvvvvvvvv"
    ]
  ]
}