{
  "name": "multi_filmworkstower_19_base3",
  "refpalette": "deceasedcraft:multi_filmworkstower_19/multi_filmworkstower_19_base3_palette",
  "xsize": 16,
  "zsize": 16,
  "slices": [
    [
      "aaaabbbbbbbbbbbb",
      "aaaabbbbbbbbbbbb",
      "aaaabbbbbbbbbbbb",
      "aaaabbbbbbbbbbbb",
      "aaaabbbbbbbbbbbb",
      "aaaabbbbbbbbbbbb",
      "aaaabbbbbbbbbbbb",
      "aaaabbbbbbbbbbbb",
      "aaaabbbbbbbbbbbb",
      "aaaaaaaaaaaaaaaa",
      "aaaaaaaaaaaaaaaa",
      "aaaaaaaaaaaaaaaa",
      "aaaaaaaaaaaaaaaa",
      "aaaaaaaaaaaaaaaa",
      "aaaaaaaaaaaaaaaa",
      "vvvvvvvvvvvvvvvv"
    ],
    [
      "aaaabcddddddeddd",
      "aaaabcddddddeddd",
      "aaaabcddfdddeddd",
      "aaaabcdddddddddd",
      "aaaabcddddddefdd",
      "aaaabcddddddeddd",
      "aaaabcfddddddddd",
      "aaaabccccccccccc",
      "aaaabbbbbbbbbbbb",
      "aaaaaaaaaaaaaaaa",
      "aaaaaaaaaaaaaaaa",
      "aaaaaaaaaaaaaaaa",
      "aaaaaaaaaaaaaaaa",
      "aaaaaaaaaaaaaaaa",
      "aaaaaaaaaaaaaaaa",
      "vvvvvvvvvvvvvvvv"
    ],
    [
      "aaaabc   g   h  ",
      "aaaabcgg        ",
      "aaaabc          ",
      "aaaabc i        ",
      "aaaabcfj       k",
      "aaaabc          ",
      "aaaabc  f       ",
      "aaaabccccccccccc",
      "aaaabbbbbbbbbbbb",
      "aaaaaaaaaaaaaaaa",
      "aaaaaaaaaaaaaaaa",
      "aaaaaaaaaaaaaaaa",
      "aaaaaaaaaaaaaaaa",
      "aaaaaaaaaaaaaaaa",
      "aaaaaaaaaaaaaaaa",
      "vvvvvvvvvvvvvvvv"
    ],
    [
      "aaaabc l        ",
      "aaaabc l        ",
      "aaaabc l        ",
      "aaaabc m        ",
      "aaaabc j        ",
      "aaaabc          ",
      "aaaabc          ",
      "aaaabccccccccccc",
      "aaaabbbbbbbbbbbb",
      "aaaaaaaaaaaaaaaa",
      "aaaaaaaaaaaaaaaa",
      "aaaaaaaaaaaaaaaa",
      "aaaaaaaaaaaaaaaa",
      "aaaaaaaaaaaaaaaa",
      "aaaaaaaaaaaaaaaa",
      "vvvvvvvvvvvvvvvv"
    ],
    [
      "aaaabc n        ",
      "aaaabc n        ",
      "aaaabc n        ",
      "aaaabc o        ",
      "aaaabc          ",
      "aaaabc          ",
      "aaaabc          ",
      "aaaabccccccccccc",
      "aaaabbbbbbbbbbbb",
      "aaaaaaaaaaaaaaaa",
      "aaaaaaaaaaaaaaaa",
      "aaaaaaaaaaaaaaaa",
      "aaaaaaaaaaaaaaaa",
      "aaaaaaaaaaaaaaaa",
      "aaaaaaaaaaaaaaaa",
      "vvvvvvvvvvvvvvvv"
    ],
    [
      "aaaabc          ",
      "aaaabc          ",
      "aaaabc          ",
      "aaaabc          ",
      "aaaabc          ",
      "aaaabc          ",
      "aaaabc          ",
      "aaaabccccccccccc",
      "aaaabbbbbbbbbbbb",
      "aaaaaaaaaaaaaaaa",
      "aaaaaaaaaaaaaaaa",
      "aaaaaaaaaaaaaaaa",
      "aaaaaaaaaaaaaaaa",
      "aaaaaaaaaaaaaaaa",
      "aaaaaaaaaaaaaaaa",
      "vvvvvvvvvvvvvvvv"
    ]
  ]
}