{
  "name": "multi_filmworkstower_19_base1",
  "refpalette": "deceasedcraft:multi_filmworkstower_19/multi_filmworkstower_19_base1_palette",
  "xsize": 16,
  "zsize": 16,
  "slices": [
    [
      "     a          ",
      "     a          ",
      "     a          ",
      "     a          ",
      "     a          ",
      "     a          ",
      "b   ca          ",
      "     aaaaaaaaaaa",
      "                ",
      "                ",
      "                ",
      "                ",
      "                ",
      "dddddddddddddddd",
      "eeeeeeeeeeeeeeee",
      "vvvvvvvvvvvvvvvv"
    ],
    [
      "     a          ",
      "     a          ",
      "     a          ",
      "     a          ",
      "     a          ",
      "    fa          ",
      "bg hca          ",
      "     aaaaaaaaaaa",
      "                ",
      "                ",
      "                ",
      "                ",
      "                ",
      "dddddddddddddddd",
      "eeeeeeeeeeeeeeee",
      "vvvvvvvvvvvvvvvv"
    ],
    [
      "    ia          ",
      "    ia          ",
      "    ia          ",
      "    ia          ",
      "    ia          ",
      "    ia          ",
      "bbjjca          ",
      "     aaaaaaaaaaa",
      "                ",
      "                ",
      "                ",
      "                ",
      "                ",
      "dddddddddddddddd",
      "eeeeeeeeeeeeeeee",
      "vvvvvvvvvvvvvvvv"
    ],
    [
      "           k   k",
      "           k   k",
      "           k   k",
      "           k   k",
      "           k   k",
      "                ",
      "lbgmcn          ",
      "                ",
      "                ",
      "                ",
      "                ",
      "                ",
      "                ",
      "dddddddddddddddd",
      "eeeeeeeeeeeeeeee",
      "vvvvvvvvvvvvvvvv"
    ],
    [
      "oooooopqrsrrrsrr",
      "oooooopqrsrrrsrr",
      "oooooopqrsrrrsrr",
      "oooooopqrtrrrtrr",
      "oooooopqqqqqqqqq",
      "oooooopppppppppp",
      "obbocooooooooooo",
      "oooooooooooooooo",
      "oooooooooooooooo",
      "oooooooooooooooo",
      "oooooooooooooooo",
      "oooooooooooooooo",
      "oooooooooooooooo",
      "dddddddddddddddd",
      "eeeeeeeeeeeeeeee",
      "vvvvvvvvvvvvvvvv"
    ],
    [
      "bbbbbbbbbbbbbbbb",
      "bbbbbbbbbbbbbbbb",
      "bbbbbbbbbbbbbbbb",
      "bbbbbbbbbbbbbbbb",
      "bbbbbbbbbbbbbbbb",
      "bbbbbbbbbbbbbbbb",
      "bbbbb bbbbbbbbbb",
      "bbbbbbbbbbbbbbbb",
      "bbbbbbbbbbbbbbbb",
      "bbbbbbbbbbbbbbbb",
      "bbbbbbbbbbbbbbbb",
      "bbbbbbbbbbbbbbbb",
      "bbbbbbbbbbbbbbbb",
      "dddddddddddddddd",
      "eeeeeeeeeeeeeeee",
      "vvvvvvvvvvvvvvvv"
    ]
  ]
}