{
  "name": "multi_farmhouse1_0_floor1",
  "refpalette": "deceasedcraft:multi_farmhouse1_0/multi_farmhouse1_0_floor1_palette",
  "xsize": 16,
  "zsize": 16,
  "slices": [
    [
      "aaabbbbbbbbbbbbb",
      "abbbbbbbbbbbbbbb",
      "bbbbbbbbbbbbbbbb",
      "bbbbbbbbbbbbbbbb",
      "bbbbbbbbbbbbbbbb",
      "abbbbbbbbbbbbbbb",
      "cbbbbbdbbbbbbbbb",
      "bbbbbbbbbbbbbbbb",
      "bbbbbbbbbbbbbbbb",
      "bbbbbbbbbbbbbbbb",
      "bbbbbbbbbbbbbbbb",
      "bbbbbbbbbbbbbbbb",
      "bbbbbbbbbbbbbbbb",
      "bbbbbbbbbbbbbbbb",
      "bbbbbbbbbbbbbbbb",
      "bbbbbbbbbbbbbbbb"
    ],
    [
      "aaaeaaaaeaaaeaea",
      "aaaaaeaaaaeaaaaa",
      "aaeaaaeaeeeeaaae",
      "aaaeeeeeaaeaeeae",
      "aeaeeaeeaaeeaeee",
      "aaeaeeaeeeaeaeee",
      "aaeeaefeeeeeeeee",
      "aeeaeeeeeeeeeeee",
      "caeeeeeeaeeeeaee",
      "aeeeaaeeeeeeeeee",
      "geeaeeeeeeeeeeee",
      "aheeeeeeeeeeeeee",
      "eeeeaeeeeeeaeeee",
      "geaeeeeeaeeeeeee",
      "aeeeaeeeeeeeeeea",
      "eaeaeeeeeeeeeeee"
    ],
    [
      "aaaiaaaaiaaaiaia",
      "aaaaaiaaaaiaaaaa",
      "aaiaaaiaiiiiaaai",
      "aaaiiiiiaaiaiiai",
      "aiaiiaiiaaiiaiii",
      "aaiaiiaiiiaiaiii",
      "aaiiaijiiiiiiiii",
      "aiiaiiiiiiiiiiii",
      "aaiiiiiiaiiiiaii",
      "aiiiaaiiiiiiiiii",
      "aiiaiiiiiiiiiiii",
      "aaiiiiiiiiiiiiii",
      "iiiiaiiiiiiaiiii",
      "aiaiiiiiaiiiiiii",
      "aiiiaiiiiiiiiiia",
      "iaiaiiiiiiiiiiii"
    ],
    [
      "aaaaaaaaaaaaaaaa",
      "aaaaaaaaaaaaaaaa",
      "aaaaaaaaaaaaaaaa",
      "aaaaaaaaaaaaaaaa",
      "aaaaaaaaaaaaaaaa",
      "aaaaaaaaaaaaaaaa",
      "aaaaaklkaaaaaaaa",
      "aaaaaaaaaaaaaaaa",
      "aaaaaaaaaaaaaaaa",
      "aaaaaaaaaaaaaaaa",
      "aaaaaaaaaaaaaaaa",
      "aaaaaaaaaaaaaaaa",
      "aaaaaaaaaaaaaaaa",
      "aaaaaaaaaaaaaaaa",
      "aaaaaaaaaaaaaaaa",
      "aaaaaaaaaaaaaaaa"
    ],
    [
      "aaaaaaaaaaaaaaaa",
      "aaaaaaaaaaaaaaaa",
      "aaaaaaaaaaaaaaaa",
      "aaaaaaaaaaaaaaaa",
      "aaaaaaaaaaaaaaaa",
      "aaaaaaaaaaaaaaaa",
      "aaaaaamaaaaaaaaa",
      "aaaaaaaaaaaaaaaa",
      "aaaaaaaaaaaaaaaa",
      "aaaaaaaaaaaaaaaa",
      "aaaaaaaaaaaaaaaa",
      "aaaaaaaaaaaaaaaa",
      "aaaaaaaaaaaaaaaa",
      "aaaaaaaaaaaaaaaa",
      "aaaaaaaaaaaaaaaa",
      "aaaaaaaaaaaaaaaa"
    ],
    [
      "aaaaaaaaaaaaaaaa",
      "aaaaaaaaaaaaaaaa",
      "aaaaaaaaaaaaaaaa",
      "aaaaaaaaaaaaaaaa",
      "aaaaaaaaaaaaaaaa",
      "aaaaaanaaaaaaaaa",
      "aaaaanonaaaaaaaa",
      "aaaaaanaaaaaaaaa",
      "aaaaaaaaaaaaaaaa",
      "aaaaaaaaaaaaaaaa",
      "aaaaaaaaaaaaaaaa",
      "aaaaaaaaaaaaaaaa",
      "aaaaaaaaaaaaaaaa",
      "aaaaaaaaaaaaaaaa",
      "aaaaaaaaaaaaaaaa",
      "aaaaaaaaaaaaaaaa"
    ]
  ]
}