{
  "name": "multi_nuclearpowerplant_18_base8",
  "refpalette": "deceasedcraft:multi_nuclearpowerplant_18/multi_nuclearpowerplant_18_base8_palette",
  "xsize": 16,
  "zsize": 16,
  "slices": [
    [
      "a    a    a    a",
      "a    a    a    a",
      "a    a    a    a",
      "a    a    a    a",
      "bccccbccccbccccb",
      "a    a    a    a",
      "d    a    a    d",
      "=ddd a    a ddd=",
      "====dddddddd====",
      "e==============e",
      "feee========eeef",
      "gfffeeeeeeeefffg",
      "ggggffffffffgggg",
      "gggggggggggggggg",
      "gggggggggggggggg",
      "gggggggggggggggg"
    ],
    [
      "hhhhhhhhhhhhhhhh",
      "hhhhhhhhhhhhhhhh",
      "hhhhhhhhhhhhhhhh",
      "hhhhhhhhhhhhhhhh",
      "hhhhhhhhhhhhhhhh",
      "hhhhhhhhhhhhhhhh",
      "hhhhhhhhhhhhhhhh",
      "hhhhhhhhhhhhhhhh",
      "ddhhhhhhhhhhhhdd",
      "iddddhhhhhhddddi",
      "=iiiddddddddiii=",
      "====iiiiiiii====",
      "======jjjj======",
      "================",
      "================",
      "================"
    ],
    [
      "kkkkkkkkkkkkkkkk",
      "kkkkkkkkkkkkkkkk",
      "kkkkkkkkkkkkkkkk",
      "kkkkkkkkkkkkkkkk",
      "kkkkkkkkkkkkkkkk",
      "kkkkkkkkkkkkkkkk",
      "kkkkkkkkkkkkkkkk",
      "kkkkkkkkkkkkkkkk",
      "ddkkkkkkkkkkkkdd",
      "lddddkkkkkkddddl",
      "mlllddddddddlllm",
      "mmmmllllllllmmmm",
      "mmmmmmjkkjmmmmmm",
      "mmmmmmmmmmmmmmmm",
      "mmmmmmmmmmmmmmmm",
      "mmmmmmmmmmmmmmmm"
    ],
    [
      "kkkkkkkkkkkkkkkk",
      "kkkkkkkkkkkkkkkk",
      "kkkkkkkkkkkkkkkk",
      "kkkkkkkkkkkkkkkk",
      "kkkkkkkkkkkkkkkk",
      "kkkkkkkkkkkkkkkk",
      "kkkkkkkkkkkkkkkk",
      "kkkkkkkkkkkkkkkk",
      "ddkkkkkkkkkkkkdd",
      "lddddkkkkkkddddl",
      "mlllddddddddlllm",
      "mmmmllllllllmmmm",
      "mmmmmmjjjjmmmmmm",
      "mmmmmmmmmmmmmmmm",
      "mmmmmmmmmmmmmmmm",
      "mmmmmmmmmmmmmmmm"
    ],
    [
      "kkkkkkkkkkkkkkkk",
      "kkkkkkkkkkkkkkkk",
      "kkkkkkkkkkkkkkkk",
      "kkkkkkkkkkkkkkkk",
      "kkkkkkkkkkkkkkkk",
      "kkkkkkkkkkkkkkkk",
      "kkkkkkkkkkkkkkkk",
      "kkkkkkkkkkkkkkkk",
      "ddkkkkkkkkkkkkdd",
      "iddddkkkkkkddddi",
      "niiiddddddddiiin",
      "nnnniiiiiiiinnnn",
      "ooonnnnnnnnnnooo",
      "oooooooooooooooo",
      "oooooooooooooooo",
      "oooooooooooooooo"
    ],
    [
      "kkkkkkkkkkkkkkkk",
      "kkkkkkkkkkkkkkkk",
      "kkkkkkkkkkkkkkkk",
      "kkkkkkkkkkkkkkkk",
      "kkkkkkkkkkkkkkkk",
      "kkkkkkkkkkkkkkkk",
      "kkkkkkkkkkkkkkkk",
      "kkkkkkkkkkkkkkkk",
      "ddkkkkkkkkkkkkdd",
      "lddddkkkkkkddddl",
      " lllddddddddlll ",
      "    llllllll    ",
      "                ",
      "                ",
      "                ",
      "                "
    ]
  ]
}