{
  "name": "multi_nuclearpowerplant_18_top",
  "refpalette": "deceasedcraft:multi_nuclearpowerplant_18/multi_nuclearpowerplant_18_top_palette",
  "xsize": 16,
  "zsize": 16,
  "slices": [
    [
      "aa=          =aa",
      "aaa===    ===aaa",
      "bbaaaa====aaaabb",
      "  bbaaaaaaaabb  ",
      "     cccccc     ",
      "                ",
      "                ",
      "                ",
      "                ",
      "                ",
      "                ",
      "                ",
      "                ",
      "d               ",
      "dddd            ",
      "eeeddddddddddddd"
    ],
    [
      "aa=          =aa",
      "aaa===    ===aaa",
      "bbaaaa====aaaabb",
      "  bbaaaaaaaabb  ",
      "     cccccc     ",
      "                ",
      "                ",
      "                ",
      "                ",
      "                ",
      "                ",
      "                ",
      "                ",
      "d               ",
      "dddd            ",
      "zzzdddddffff    "
    ],
    [
      "aa=          =aa",
      "aaa===    ===aaa",
      " baaaa====aaaab ",
      "   baaaaaaaab   ",
      "      cccc      ",
      "                ",
      "                ",
      "                ",
      "                ",
      "                ",
      "                ",
      "                ",
      "                ",
      "f               ",
      "ffff            ",
      "   f            "
    ],
    [
      "aa=          =aa",
      "baa===    ===aab",
      " baaaa====aaaab ",
      "   bbaaaaaabb   ",
      "      cccc      ",
      "                ",
      "                ",
      "                ",
      "                ",
      "                ",
      "                ",
      "                ",
      "                ",
      "                ",
      "                ",
      "                "
    ],
    [
      "aa=          =aa",
      "baa===    ===aab",
      "  aaaa====aaaa  ",
      "    baaaaaab    ",
      "                ",
      "                ",
      "                ",
      "                ",
      "                ",
      "                ",
      "                ",
      "                ",
      "                ",
      "                ",
      "                ",
      "                "
    ],
    [
      "aa=          =aa",
      "baa===    ===aab",
      "  aaaa====aaaa  ",
      "    baaaaaab    ",
      "                ",
      "                ",
      "                ",
      "                ",
      "                ",
      "                ",
      "                ",
      "                ",
      "                ",
      "                ",
      "                ",
      "                "
    ],
    [
      "aa=          =aa",
      "baa===    ===aab",
      "  aaaa====aaaa  ",
      "    baaaaaab    ",
      "                ",
      "                ",
      "                ",
      "                ",
      "                ",
      "                ",
      "                ",
      "                ",
      "                ",
      "                ",
      "                ",
      "                "
    ],
    [
      "aa=          =aa",
      "baa===    ===aab",
      "  aaaa====aaaa  ",
      "    baaaaaab    ",
      "                ",
      "                ",
      "                ",
      "                ",
      "                ",
      "                ",
      "                ",
      "                ",
      "                ",
      "                ",
      "                ",
      "                "
    ],
    [
      "aa=          =aa",
      " aa===    ===aa ",
      "  aaaa====aaaa  ",
      "     aaaaaa     ",
      "                ",
      "                ",
      "                ",
      "                ",
      "                ",
      "                ",
      "                ",
      "                ",
      "                ",
      "                ",
      "                ",
      "                "
    ],
    [
      "aa=          =aa",
      " aa===    ===aa ",
      "  aaaa====aaaa  ",
      "     aaaaaa     ",
      "                ",
      "                ",
      "                ",
      "                ",
      "                ",
      "                ",
      "                ",
      "                ",
      "                ",
      "                ",
      "                ",
      "                "
    ],
    [
      "aa=          =aa",
      " aa===    ===aa ",
      "  aaaa====aaaa  ",
      "     aaaaaa     ",
      "                ",
      "                ",
      "                ",
      "                ",
      "                ",
      "                ",
      "                ",
      "                ",
      "                ",
      "                ",
      "                ",
      "                "
    ],
    [
      "aa=          =aa",
      " aa===    ===aa ",
      "  aaaa====aaaa  ",
      "     aaaaaa     ",
      "                ",
      "                ",
      "                ",
      "                ",
      "                ",
      "                ",
      "                ",
      "                ",
      "                ",
      "                ",
      "                ",
      "                "
    ],
    [
      "aa=          =aa",
      " aa===    ===aa ",
      "  aaaa====aaaa  ",
      "     aaaaaa     ",
      "                ",
      "                ",
      "                ",
      "                ",
      "                ",
      "                ",
      "                ",
      "                ",
      "                ",
      "                ",
      "                ",
      "                "
    ],
    [
      "aa=          =aa",
      " aa===    ===aa ",
      "  aaaa====aaaa  ",
      "     aaaaaa     ",
      "                ",
      "                ",
      "                ",
      "                ",
      "                ",
      "                ",
      "                ",
      "                ",
      "                ",
      "                ",
      "                ",
      "                "
    ],
    [
      "aa=          =aa",
      " aa===    ===aa ",
      "  aaaa====aaaa  ",
      "     aaaaaa     ",
      "                ",
      "                ",
      "                ",
      "                ",
      "                ",
      "                ",
      "                ",
      "                ",
      "                ",
      "                ",
      "                ",
      "                "
    ],
    [
      "aa=          =aa",
      "baa===    ===aab",
      "  aaaa====aaaa  ",
      "    baaaaaab    ",
      "                ",
      "                ",
      "                ",
      "                ",
      "                ",
      "                ",
      "                ",
      "                ",
      "                ",
      "                ",
      "                ",
      "                "
    ],
    [
      "aa=          =aa",
      "baa===    ===aab",
      "  aaaa====aaaa  ",
      "    baaaaaab    ",
      "                ",
      "                ",
      "                ",
      "                ",
      "                ",
      "                ",
      "                ",
      "                ",
      "                ",
      "                ",
      "                ",
      "                "
    ],
    [
      "aa=          =aa",
      "aaa===    ===aaa",
      "  aaaa====aaaa  ",
      "    aaaaaaaa    ",
      "                ",
      "                ",
      "                ",
      "                ",
      "                ",
      "                ",
      "                ",
      "                ",
      "                ",
      "                ",
      "                ",
      "                "
    ],
    [
      "aa=          =aa",
      "aaa===    ===aaa",
      " caaaa====aaaac ",
      "   caaaaaaaac   ",
      "     cccccc     ",
      "                ",
      "                ",
      "                ",
      "                ",
      "                ",
      "                ",
      "                ",
      "                ",
      "                ",
      "                ",
      "                "
    ],
    [
      "aa=          =aa",
      "aaa===    ===aaa",
      " caaaa====aaaac ",
      "   caaaaaaaac   ",
      "     cccccc     ",
      "                ",
      "                ",
      "                ",
      "                ",
      "                ",
      "                ",
      "                ",
      "                ",
      "                ",
      "                ",
      "                "
    ],
    [
      "gg            gg",
      "agg          gga",
      "aaaggg    gggaaa",
      "  aaaggggggaaa  ",
      "    aaaaaaaa    ",
      "                ",
      "                ",
      "                ",
      "                ",
      "                ",
      "                ",
      "                ",
      "                ",
      "                ",
      "                ",
      "                "
    ]
  ]
}