{
  "name": "multi_nuclearpowerplant_18_base12",
  "refpalette": "deceasedcraft:multi_nuclearpowerplant_18/multi_nuclearpowerplant_18_base12_palette",
  "xsize": 16,
  "zsize": 16,
  "slices": [
    [
      "aaaaaaaaaaaaaaaa",
      "aaaaaaaaaaaaaaaa",
      "aaaaaaaaaaaaaaaa",
      "aaaaaaaaaaaaaaaa",
      "aaaaaaaaaaaaaaaa",
      "aaaaaaaaaaaaaaaa",
      "aaaaaaaaaaaaaaaa",
      "aaaaaaaaaaaaaaaa",
      "aaaaaaaaaaaaaaaa",
      "aaaaaaaaaaaaaaaa",
      "aaaaaaaaaaaaaaaa",
      "aaaaaaaaaaaaaaaa",
      "aaaaaaaaaaaaaaaa",
      "aaaaaaaaaaaaaaaa",
      "aaaaaaaaaaaaaaaa",
      "aaaaaaaaaaaaaaaa"
    ],
    [
      "bbbbbbbbbbbbbbbb",
      "bbbbbbbbbbbbbbbb",
      "bbbbbbbbbbbbbbbb",
      "bbbbbbbbbbbbbbbb",
      "bbbbbbbbbbbbbbbb",
      "bbbbbbbbbbbbbbbb",
      "bbbbbbbbbbbbbbbb",
      "bbbbbbbbbbbbbbbb",
      "bbbbbbbbbbbbbbbb",
      "bbbbbbbbbbbbbbbb",
      "bbbbbbbbbbbbbbbb",
      "bbbbbbbbbbbbbbbb",
      "bbbbbbbbbbbbbbbb",
      "bbbbbbbbbbbbbbbb",
      "bbbbbbbbbbbbbbbb",
      "bbbbbbbbbbbbbbbb"
    ],
    [
      "cccccccccccccccc",
      "cccccccccccccccc",
      "cccccccccccccccc",
      "cccccccccccccccc",
      "cccccccccccccccc",
      "cccccccccccccccc",
      "cccccccccccccccc",
      "cccccccccccccccc",
      "cccccccccccccccc",
      "cccccccccccccccc",
      "cccccccccccccccc",
      "cccccccccccccccc",
      "cccccccccccccccc",
      "cccccccccccccccc",
      "cccccccccccccccc",
      "cccccccccccccccc"
    ],
    [
      "                ",
      "                ",
      "de    fdde    fd",
      "                ",
      "                ",
      "                ",
      "dggggggddggggggd",
      "hiiiiiiiihiiiiii",
      "hhhhhhhhhhhhhhhh",
      "iiiiiiihiiiihihi",
      "djjjjjjddjjjjjjd",
      "                ",
      "                ",
      "                ",
      "de    fdde    fd",
      "                "
    ],
    [
      "                ",
      "                ",
      "dk    lddk    ld",
      "       dd       ",
      "       dd       ",
      "       dd       ",
      "dk    lddk    ld",
      "  mn o          ",
      "  pqrp          ",
      "  msso          ",
      "dk    lddk    ld",
      "       dd       ",
      "       dd       ",
      "       dd       ",
      "d      dd      d",
      "                "
    ],
    [
      "                ",
      "tuuuuuuttuuuuuut",
      "dddddddddddddddd",
      "wuuuuuuwwuuuuuuw",
      "                ",
      "                ",
      "dddddddddddddddd",
      "  xxxx          ",
      "  xyyx          ",
      "  xxxx          ",
      "dddddddddddddddd",
      "                ",
      "                ",
      "                ",
      "d      dd      d",
      "                "
    ]
  ]
}