{
  "name": "multi_nuclearpowerplant_18_base11",
  "refpalette": "deceasedcraft:multi_nuclearpowerplant_18/multi_nuclearpowerplant_18_base11_palette",
  "xsize": 16,
  "zsize": 16,
  "slices": [
    [
      "                ",
      "aaaaaaaaaaaaaaaa",
      "aaaaaaaaaaaaaaaa",
      "aaaaaaaaaaaaaaaa",
      "                ",
      "                ",
      "  bbbc          ",
      "                ",
      "  deef          ",
      "                ",
      "  bbbc          ",
      "                ",
      "                ",
      "                ",
      "g      gg      g",
      "                "
    ],
    [
      "                ",
      "     hhhhhh   hh",
      "     hhhhhh   hh",
      "     hhhhhh   hh",
      "                ",
      "                ",
      "                ",
      "   ii           ",
      "   jj           ",
      "   kk           ",
      "                ",
      "                ",
      "                ",
      "                ",
      "gl    mggl    mg",
      "                "
    ],
    [
      "                ",
      "                ",
      "                ",
      "                ",
      "                ",
      "                ",
      "                ",
      "   ii           ",
      "   jj           ",
      "   kk           ",
      "                ",
      "                ",
      "                ",
      "                ",
      "gggggggggggggggg",
      "                "
    ],
    [
      "                ",
      "                ",
      "                ",
      "                ",
      "                ",
      "                ",
      "                ",
      "   ii           ",
      "   jj           ",
      "   kk           ",
      "                ",
      "                ",
      "                ",
      "                ",
      "g      gg      g",
      "n      nn      n"
    ],
    [
      "                ",
      "                ",
      "                ",
      "                ",
      "                ",
      "                ",
      "                ",
      "   ii           ",
      "   jj           ",
      "   kk           ",
      "                ",
      "                ",
      "                ",
      "                ",
      "goppppqggoppppqg",
      "rrrrrrrrrrrrrrrr"
    ],
    [
      "                ",
      "                ",
      "                ",
      "                ",
      "                ",
      "                ",
      "                ",
      "   ii           ",
      "   jj           ",
      "   kk           ",
      "                ",
      "                ",
      "                ",
      "                ",
      "gopppppggopppppg",
      "                "
    ]
  ]
}