{
  "name": "multi_nuclearpowerplant_18_base5",
  "refpalette": "deceasedcraft:multi_nuclearpowerplant_18/multi_nuclearpowerplant_18_base5_palette",
  "xsize": 16,
  "zsize": 16,
  "slices": [
    [
      "                ",
      "                ",
      "                ",
      "                ",
      "                ",
      "                ",
      "                ",
      "=              =",
      "   =        =   ",
      "      =  =      ",
      "                ",
      "                ",
      "                ",
      "                ",
      "                ",
      "                "
    ],
    [
      "                ",
      "                ",
      "                ",
      "                ",
      "                ",
      "                ",
      "a              b",
      "   ba      ba   ",
      "     ba  ba     ",
      "                ",
      "                ",
      "                ",
      "                ",
      "                ",
      "                ",
      "                "
    ],
    [
      "                ",
      "                ",
      "                ",
      "                ",
      "                ",
      "                ",
      "                ",
      "    =      =    ",
      "     =    =     ",
      "                ",
      "                ",
      "                ",
      "                ",
      "                ",
      "                ",
      "                "
    ],
    [
      "cccccccccccccccc",
      "cccccccccccccccc",
      "cccccccccccccccc",
      "cccccccccccccccc",
      "cccccccccccccccc",
      "ddccccccccccccdd",
      "eedddccccccdddee",
      "ffee=dddddd=eeff",
      " ffff=eeee=ffff ",
      "    ffffffff    ",
      "                ",
      "                ",
      "                ",
      "                ",
      "                ",
      "                "
    ],
    [
      "                ",
      "                ",
      "                ",
      "                ",
      "                ",
      "==            ==",
      "gg===      ===gg",
      "hgggg======ggggh",
      "  hhgggggggghh  ",
      "     hhhhhh     ",
      "                ",
      "                ",
      "                ",
      "                ",
      "                ",
      "                "
    ],
    [
      "i    j    j    i",
      "     k    k     ",
      "     k    k     ",
      "     l    l     ",
      "    m~nkko~p    ",
      "==   i    i   ==",
      "gg===      ===gg",
      " gggg======gggg ",
      "    gggggggg    ",
      "                ",
      "                ",
      "                ",
      "                ",
      "                ",
      "                ",
      "                "
    ]
  ]
}