{
  "name": "multi_nuclearpowerplant_18_ground",
  "refpalette": "deceasedcraft:multi_nuclearpowerplant_18/multi_nuclearpowerplant_18_ground_palette",
  "xsize": 16,
  "zsize": 16,
  "slices": [
    [
      "==            ==",
      "a==          ==a",
      "aaa===    ===aaa",
      "  aaa======aaa  ",
      "    aaaaaaaa    ",
      "                ",
      "                ",
      "                ",
      "                ",
      "                ",
      "                ",
      "                ",
      "                ",
      "                ",
      "                ",
      "                "
    ],
    [
      "==            ==",
      "a==          ==a",
      "aaa===    ===aaa",
      "  aaa======aaa  ",
      "    aaaaaaaa    ",
      "                ",
      "                ",
      "                ",
      "                ",
      "                ",
      "                ",
      "                ",
      "                ",
      "                ",
      "                ",
      "                "
    ],
    [
      "==            ==",
      "a==          ==a",
      "aaa===    ===aaa",
      "  aaa======aaa  ",
      "    aaaaaaaa    ",
      "                ",
      "                ",
      "                ",
      "                ",
      "                ",
      "                ",
      "                ",
      "                ",
      "                ",
      "                ",
      "                "
    ],
    [
      "==            ==",
      "a==          ==a",
      "aaa===    ===aaa",
      "  aaa======aaa  ",
      "    aaaaaaaa    ",
      "                ",
      "                ",
      "                ",
      "                ",
      "                ",
      "                ",
      "                ",
      "                ",
      "                ",
      "                ",
      "                "
    ],
    [
      "==            ==",
      "a==          ==a",
      "aaa===    ===aaa",
      "  aaa======aaa  ",
      "    aaaaaaaa    ",
      "                ",
      "                ",
      "                ",
      "                ",
      "                ",
      "                ",
      "                ",
      "                ",
      "                ",
      "                ",
      "              b "
    ],
    [
      "aa=          =aa",
      "aaa===    ===aaa",
      "ccaaaa====aaaacc",
      "  ccaaaaaaaacc  ",
      "     dddddd     ",
      "                ",
      "                ",
      "                ",
      "                ",
      "                ",
      "                ",
      "                ",
      "                ",
      "                ",
      " b              ",
      "        eeeeeeee"
    ]
  ]
}