{
  "name": "multi_nuclearpowerplant_18_base4",
  "refpalette": "deceasedcraft:multi_nuclearpowerplant_18/multi_nuclearpowerplant_18_base4_palette",
  "xsize": 16,
  "zsize": 16,
  "slices": [
    [
      "aaaabcbaabcbaaaa",
      "    dce  dce    ",
      "    dce  dce    ",
      "=   dcbffbce   =",
      "==  dcccccce  ==",
      "gg===aaaaaa===gg",
      "hgggg======ggggh",
      "  hhgggggggghh  ",
      "     hhhhhh     ",
      "                ",
      "                ",
      "                ",
      "                ",
      "                ",
      "                ",
      "                "
    ],
    [
      "                ",
      "                ",
      "                ",
      "=              =",
      "==            ==",
      "gg===      ===gg",
      "hgggg======ggggh",
      "  hhgggggggghh  ",
      "     hhhhhh     ",
      "                ",
      "                ",
      "                ",
      "                ",
      "                ",
      "                ",
      "                "
    ],
    [
      "                ",
      "                ",
      "                ",
      "=              =",
      "==            ==",
      "gg===      ===gg",
      " gggg======gggg ",
      "    gggggggg    ",
      "                ",
      "                ",
      "                ",
      "                ",
      "                ",
      "                ",
      "                ",
      "                "
    ],
    [
      "                ",
      "                ",
      "=              =",
      "g==          ==g",
      "gg===      ===gg",
      "igggg======ggggi",
      "  hhgggggggghh  ",
      "     hhhhhh     ",
      "                ",
      "                ",
      "                ",
      "                ",
      "                ",
      "                ",
      "                ",
      "                "
    ],
    [
      "                ",
      "                ",
      "=              =",
      "g==          ==g",
      "gg===      ===gg",
      "igggg======ggggi",
      "  hhgggggggghh  ",
      "     hhhhhh     ",
      "                ",
      "                ",
      "                ",
      "                ",
      "                ",
      "                ",
      "                ",
      "                "
    ],
    [
      "                ",
      "                ",
      "=              =",
      "g==          ==g",
      "gg===      ===gg",
      "igggg======ggggi",
      "  hhgggggggghh  ",
      "     hhhhhh     ",
      "                ",
      "                ",
      "                ",
      "                ",
      "                ",
      "                ",
      "                ",
      "                "
    ]
  ]
}