{
  "name": "multi_nuclearpowerplant_18_base1",
  "refpalette": "deceasedcraft:multi_nuclearpowerplant_18/multi_nuclearpowerplant_18_base1_palette",
  "xsize": 16,
  "zsize": 16,
  "slices": [
    [
      "==            ==",
      "a==          ==a",
      "aaa===    ===aaa",
      " baaa======aaab ",
      "   baaaaaaaab   ",
      "     bbbbbb     ",
      "                ",
      "                ",
      "                ",
      "                ",
      "                ",
      "                ",
      "                ",
      "                ",
      "                ",
      "                "
    ],
    [
      "==            ==",
      "a==          ==a",
      "aaa===    ===aaa",
      " baaa======aaab ",
      "   baaaaaaaab   ",
      "     bbbbbb     ",
      "                ",
      "                ",
      "                ",
      "                ",
      "                ",
      "                ",
      "                ",
      "                ",
      "                ",
      "                "
    ],
    [
      "==            ==",
      "a==          ==a",
      "aaa===    ===aaa",
      " baaa======aaab ",
      "   baaaaaaaab   ",
      "     bbbbbb     ",
      "                ",
      "                ",
      "                ",
      "                ",
      "                ",
      "                ",
      "                ",
      "                ",
      "                ",
      "                "
    ],
    [
      "==            ==",
      "a==          ==a",
      "aaa===    ===aaa",
      "  aaa======aaa  ",
      "    aaaaaaaa    ",
      "                ",
      "                ",
      "                ",
      "                ",
      "                ",
      "                ",
      "                ",
      "                ",
      "                ",
      "                ",
      "                "
    ],
    [
      "==            ==",
      "a==          ==a",
      "aaa===    ===aaa",
      "  aaa======aaa  ",
      "    aaaaaaaa    ",
      "                ",
      "                ",
      "                ",
      "                ",
      "                ",
      "                ",
      "                ",
      "                ",
      "                ",
      "                ",
      "                "
    ],
    [
      "==            ==",
      "a==          ==a",
      "aaa===    ===aaa",
      "  aaa======aaa  ",
      "    aaaaaaaa    ",
      "                ",
      "                ",
      "                ",
      "                ",
      "                ",
      "                ",
      "                ",
      "                ",
      "                ",
      "                ",
      "                "
    ]
  ]
}