{
  "name": "multi_nuclearpowerplant_18_base9",
  "refpalette": "deceasedcraft:multi_nuclearpowerplant_18/multi_nuclearpowerplant_18_base9_palette",
  "xsize": 16,
  "zsize": 16,
  "slices": [
    [
      "   aa           ",
      "   aa           ",
      "   aa           ",
      "                ",
      "                ",
      "                ",
      "                ",
      "                ",
      "                ",
      "                ",
      "                ",
      "                ",
      "                ",
      "                ",
      "                ",
      "                "
    ],
    [
      "                ",
      "                ",
      "                ",
      "                ",
      "                ",
      "                ",
      "                ",
      "                ",
      "                ",
      "                ",
      "                ",
      "                ",
      "                ",
      "                ",
      "                ",
      "                "
    ],
    [
      "                ",
      "                ",
      "                ",
      "                ",
      "                ",
      "                ",
      "                ",
      "                ",
      "                ",
      "                ",
      "                ",
      "                ",
      "                ",
      "                ",
      "                ",
      "                "
    ],
    [
      "bbbbbbbbbbbbbbbb",
      "bbbbbbbbbbbbbbbb",
      "bbbbbbbbbbbbbbbb",
      "bbbbbbbbbbbbbbbb",
      "bbbbbbbbbbbbbbbb",
      "bbbbbbbbbbbbbbbb",
      "bbbbbbbbbbbbbbbb",
      "bbbbbbbbbbbbbbbb",
      " bbbbbbbbbbbbbb ",
      "    bbbbbbbb    ",
      "                ",
      "                ",
      "                ",
      "                ",
      "                ",
      "                "
    ],
    [
      "c    c    c    c",
      "                ",
      "                ",
      "d    d    d    d",
      "ef  gef  gef  ge",
      "c    c    c    c",
      "h              h",
      "ihhh        hhhi",
      " iiihhhhhhhhiii ",
      "    iiiiiiii    ",
      "                ",
      "                ",
      "                ",
      "                ",
      "                ",
      "                "
    ],
    [
      "                ",
      "                ",
      "                ",
      "                ",
      "e    e    e    e",
      "                ",
      "h              h",
      "=hhh        hhh=",
      "i===hhhhhhhh===i",
      " iii========iii ",
      "    iiiiiiii    ",
      "                ",
      "                ",
      "                ",
      "                ",
      "                "
    ]
  ]
}