{
  "name": "multi_nuclearpowerplant_18_base7",
  "refpalette": "deceasedcraft:multi_nuclearpowerplant_18/multi_nuclearpowerplant_18_base7_palette",
  "xsize": 16,
  "zsize": 16,
  "slices": [
    [
      "aaaaaaaaaaaaaaaa",
      "aaaaaaaaaaaaaaaa",
      "aaaaaaaaaaaaaaaa",
      "aaaaaaaaaaaaaaaa",
      "aaaaaaaaaaaaaaaa",
      "aaaaaaaaaaaaaaaa",
      "aaaaaaaaaaaaaaaa",
      "aaaaaaaaaaaaaaaa",
      "bbaaaaaaaaaaaabb",
      "cbbbbaaaaaabbbbc",
      " cccbbbbbbbbccc ",
      "    cccccccc    ",
      "                ",
      "                ",
      "                ",
      "                "
    ],
    [
      "aaaaaaaaaaaaaaaa",
      "aaaaaaaaaaaaaaaa",
      "aaaaaaaaaaaaaaaa",
      "aaaaaaaaaaaaaaaa",
      "aaaaaaaaaaaaaaaa",
      "aaaaaaaaaaaaaaaa",
      "aaaaaaaaaaaaaaaa",
      "aaaaaaaaaaaaaaaa",
      "bbaaaaaaaaaaaabb",
      "cbbbbaaaaaabbbbc",
      " cccbbbbbbbbccc ",
      "    ccddddcc    ",
      "       ee       ",
      "       ee       ",
      "       ee       ",
      "       ee       "
    ],
    [
      "aaaaaaaaaaaaaaaa",
      "aaaaaaaaaaaaaaaa",
      "aaaaaaaaaaaaaaaa",
      "aaaaaaaaaaaaaaaa",
      "aaaaaaaaaaaaaaaa",
      "aaaaaaaaaaaaaaaa",
      "aaaaaaaaaaaaaaaa",
      "aaaaaaaaaaaaaaaa",
      "bbaaaaaaaaaaaabb",
      "cbbbbaaaaaabbbbc",
      " cccbbbaabbbccc ",
      "    ccdaadcc    ",
      "      faag      ",
      "      faag      ",
      "      faag      ",
      "      faag      "
    ],
    [
      "aaaaaaaaaaaaaaaa",
      "aaaaaaaaaaaaaaaa",
      "aaaaaaaaaaaaaaaa",
      "aaaaaaaaaaaaaaaa",
      "aaaaaaaaaaaaaaaa",
      "aaaaaaaaaaaaaaaa",
      "aaaaaaaaaaaaaaaa",
      "aaaaaaaaaaaaaaaa",
      "bbaaaaaaaaaaaabb",
      "cbbbbaaaaaabbbbc",
      " cccbbbaabbbccc ",
      "    ccdaadcc    ",
      "      faag      ",
      "      faag      ",
      "      faag      ",
      "      faag      "
    ],
    [
      "aaaaaaaaaaaaaaaa",
      "aaaaaaaaaaaaaaaa",
      "aaaaaaaaaaaaaaaa",
      "aaaaaaaaaaaaaaaa",
      "aaaaaaaaaaaaaaaa",
      "aaaaaaaaaaaaaaaa",
      "aaaaaaaaaaaaaaaa",
      "aahaaaaaaaaaaaaa",
      "bbaaaaaaaaaaaabb",
      "cbbbbaaaaaabbbbc",
      " cccbbbbbbbbccc ",
      "    ccddddcc    ",
      "       ii       ",
      "       ii       ",
      "       ii       ",
      "       ii       "
    ],
    [
      "                ",
      "                ",
      "                ",
      "                ",
      "                ",
      "                ",
      "                ",
      "                ",
      "bb            bb",
      " bbbb      bbbb ",
      "j   bbbbbbbb   j",
      "jjjk        kjjj",
      "llljjjjjjjjjjlll",
      "lllll      lllll",
      "lllll      lllll",
      "lllll      lllll"
    ]
  ]
}