{
  "name": "multi_nuclearpowerplant_18_base3",
  "refpalette": "deceasedcraft:multi_nuclearpowerplant_18/multi_nuclearpowerplant_18_base3_palette",
  "xsize": 16,
  "zsize": 16,
  "slices": [
    [
      "                ",
      "                ",
      "=              =",
      "a==          ==a",
      "aa===      ===aa",
      " aaaa======aaaa ",
      "    aaaaaaaa    ",
      "                ",
      "                ",
      "                ",
      "                ",
      "                ",
      "                ",
      "                ",
      "                ",
      "                "
    ],
    [
      "                ",
      "                ",
      "=              =",
      "a==          ==a",
      "aa===      ===aa",
      " aaaa======aaaa ",
      "    aaaaaaaa    ",
      "                ",
      "                ",
      "                ",
      "                ",
      "                ",
      "                ",
      "                ",
      "                ",
      "                "
    ],
    [
      "                ",
      "=              =",
      "a==          ==a",
      "aaa==      ==aaa",
      "baaaa======aaaab",
      "  ccaaaaaaaacc  ",
      "     cccccc     ",
      "                ",
      "                ",
      "                ",
      "                ",
      "                ",
      "                ",
      "                ",
      "                ",
      "                "
    ],
    [
      "                ",
      "=              =",
      "a==          ==a",
      "aaa==      ==aaa",
      "baaaa======aaaab",
      "  ccaaaaaaaacc  ",
      "     cccccc     ",
      "                ",
      "                ",
      "                ",
      "                ",
      "                ",
      "                ",
      "                ",
      "                ",
      "                "
    ],
    [
      "                ",
      "=              =",
      "a==          ==a",
      "aaa==      ==aaa",
      " aaaa======aaaa ",
      "   caaaaaaaac   ",
      "     cccccc     ",
      "                ",
      "                ",
      "                ",
      "                ",
      "                ",
      "                ",
      "                ",
      "                ",
      "                "
    ],
    [
      "                ",
      "=              =",
      "a==          ==a",
      "aaa==      ==aaa",
      " baaa======aaab ",
      "   caaaaaaaac   ",
      "     cccccc     ",
      "                ",
      "                ",
      "                ",
      "                ",
      "                ",
      "                ",
      "                ",
      "                ",
      "                "
    ]
  ]
}