{
  "name": "multi_nuclearpowerplant_18_base2",
  "refpalette": "deceasedcraft:multi_nuclearpowerplant_18/multi_nuclearpowerplant_18_base2_palette",
  "xsize": 16,
  "zsize": 16,
  "slices": [
    [
      "                ",
      "=              =",
      "a==          ==a",
      "aaa==      ==aaa",
      " baaa======aaab ",
      "   caaaaaaaac   ",
      "     cccccc     ",
      "                ",
      "                ",
      "                ",
      "                ",
      "                ",
      "                ",
      "                ",
      "                ",
      "                "
    ],
    [
      "                ",
      "=              =",
      "a==          ==a",
      "aaa==      ==aaa",
      " baaa======aaab ",
      "    aaaaaaaa    ",
      "                ",
      "                ",
      "                ",
      "                ",
      "                ",
      "                ",
      "                ",
      "                ",
      "                ",
      "                "
    ],
    [
      "                ",
      "=              =",
      "a==          ==a",
      "aaa==      ==aaa",
      "  aaa======aaa  ",
      "    aaaaaaaa    ",
      "                ",
      "                ",
      "                ",
      "                ",
      "                ",
      "                ",
      "                ",
      "                ",
      "                ",
      "                "
    ],
    [
      "                ",
      "=              =",
      "a==          ==a",
      "aaa==      ==aaa",
      "  aaa======aaa  ",
      "    aaaaaaaa    ",
      "                ",
      "                ",
      "                ",
      "                ",
      "                ",
      "                ",
      "                ",
      "                ",
      "                ",
      "                "
    ],
    [
      "==            ==",
      "a==          ==a",
      "aaa===    ===aaa",
      " caaa======aaac ",
      "   caaaaaaaac   ",
      "     cccccc     ",
      "                ",
      "                ",
      "                ",
      "                ",
      "                ",
      "                ",
      "                ",
      "                ",
      "                ",
      "                "
    ],
    [
      "==            ==",
      "a==          ==a",
      "aaa===    ===aaa",
      " caaa======aaac ",
      "   caaaaaaaac   ",
      "     cccccc     ",
      "                ",
      "                ",
      "                ",
      "                ",
      "                ",
      "                ",
      "                ",
      "                ",
      "                ",
      "                "
    ]
  ]
}