{
  "name": "multi_nuclearpowerplant_5_base7",
  "refpalette": "deceasedcraft:multi_nuclearpowerplant_5/multi_nuclearpowerplant_5_base7_palette",
  "xsize": 16,
  "zsize": 16,
  "slices": [
    [
      "vaaaaaaaabcccccc",
      "vaaaaaaaaabccccc",
      "vaaaaaaaaabccccc",
      "vaaaaaaaaaabcccc",
      "vaaaaaaaaaaabccc",
      "vaaaaaaaaaaabccc",
      "vaaaaaaaaaaaabcc",
      "vaaaaaaaaaaaaabc",
      "vaaaaaaaaaaaaabc",
      "vaaaaaaaaaaaaaab",
      "vaaaaaaaaaaaaaaa",
      "vaaaaaaaaaaaaaaa",
      "vaaaaaaaaaaaaaaa",
      "vaaaaaaaaaaaaaaa",
      "vaaaaaaaaaaaaaaa",
      "vaaaaaaaaaaaaaaa"
    ],
    [
      "vaaaaaaaabcccccc",
      "vaaaaaaaaabccccc",
      "vaaaaaaaaabccccc",
      "vaaaaaaaaaabcccc",
      "vaaaaaaaaaaabccc",
      "vaaaaaaaaaaabccc",
      "vaaaaaaaaaaaabcc",
      "vaaaaaaaaaaaaabc",
      "vaaaaaaaaaaaaabc",
      "vaaaaaaaaaaaaaab",
      "vaaaaaaaaaaaaaaa",
      "vaaaaaaaaaaaaaaa",
      "vaaaaaaaaaaaaaaa",
      "vaaaaaaaaaaaaaaa",
      "vaaaaaaaaaaaaaaa",
      "vaaaaaaaaaaaaaaa"
    ],
    [
      "vaaaaaaaabcccccc",
      "vaaaaaaaaabccccc",
      "vaaaaaaaaabccccc",
      "vaaaaaaaaaabcccc",
      "vaaaaaaaaaaabccc",
      "vaaaaaaaaaaabccc",
      "vaaaaaaaaaaaabcc",
      "vaaaaaaaaaaaaabc",
      "vaaaaaaaaaaaaabc",
      "vaaaaaaaaaaaaaab",
      "vaaaaaaaaaaaaaaa",
      "vaaaaaaaaaaaaaaa",
      "vaaaaaaaaaaaaaaa",
      "vaaaaaaaaaaaaaaa",
      "vaaaaaaaaaaaaaaa",
      "vaaaaaaaaaaaaaaa"
    ],
    [
      "vaaaaaaaabcccccc",
      "vaaaaaaaaabccccc",
      "vaaaaaaaaabccccc",
      "vaaaaaaaaaabcccc",
      "vaaaaaaaaaaabccc",
      "vaaaaaaaaaaabccc",
      "vaaaaaaaaaaaabcc",
      "vaaaaaaaaaaaaabc",
      "vaaaaaaaaaaaaabc",
      "vaaaaaaaaaaaaaab",
      "vaaaaaaaaaaaaaaa",
      "vaaaaaaaaaaaaaaa",
      "vaaaaaaaaaaaaaaa",
      "vaaaaaaaaaaaaaaa",
      "vaaaaaaaaaaaaaaa",
      "vaaaaaaaaaaaaaaa"
    ],
    [
      "vaaaaaaaabcccccc",
      "vaaaaaaaaabccccc",
      "vaaaaaaaaabccccc",
      "vaaaaaaaaaabcccc",
      "vaaaaaaaaaaabccc",
      "vaaaaaaaaaaabccc",
      "vaaaaaaaaaaaabcc",
      "vaaaaaaaaaaaaabc",
      "vaaaaaaaaaaaaabc",
      "vaaaaaaaaaaaaaab",
      "vaaaaaaaaaaaaaaa",
      "vaaaaaaaaaaaaaaa",
      "vaaaaaaaaaaaaaaa",
      "vaaaaaaaaaaaaaaa",
      "vaaaaaaaaaaaaaaa",
      "vaaaaaaaaaaaaaaa"
    ],
    [
      "vddddddddbcccccc",
      "vdddddddddbccccc",
      "vdddddddddbccccc",
      "vddddddddddbcccc",
      "vdddddddddddbccc",
      "vdddddddddddbccc",
      "vddddddddddddbcc",
      "vdddddddddddddbc",
      "vdddddddddddddbc",
      "vddddddddddddddb",
      "vddddddddddddddd",
      "vddddddddddddddd",
      "vddddddddddddddd",
      "vddddddddddddddd",
      "vddddddddddddddd",
      "vddddddddddddddd"
    ]
  ]
}