{
  "name": "multi_nuclearpowerplant_5_base11",
  "refpalette": "deceasedcraft:multi_nuclearpowerplant_5/multi_nuclearpowerplant_5_base11_palette",
  "xsize": 16,
  "zsize": 16,
  "slices": [
    [
      "vaaabcd    dc   ",
      "vaaabcd    dc   ",
      "vaaabccddddcc   ",
      "vaaabbcccccc    ",
      "vaaabbe         ",
      "vaaabbe         ",
      "vaaabbe         ",
      "vaaabbef        ",
      "vaaabbeff       ",
      "vaaabbeeeeeeeeee",
      "vaaabbbbbbbbbbbb",
      "vaaaaaaaaaaaaaaa",
      "vaaaaaaaaaaaaaaa",
      "vaaaaaaaaaaaaaaa",
      "vaaaaaaaaaaaaaaa",
      "vaaaaaaaaaaaaaaa"
    ],
    [
      "vaaabcd    dc   ",
      "vaaabcd    dc   ",
      "vaaabccddddcc   ",
      "vaaabbcccccc    ",
      "vaaabbe         ",
      "vaaabbe         ",
      "vaaabbe         ",
      "vaaabbef        ",
      "vaaabbeff       ",
      "vaaabbeeeeeeeeee",
      "vaaabbbbbbbbbbbb",
      "vaaaaaaaaaaaaaaa",
      "vaaaaaaaaaaaaaaa",
      "vaaaaaaaaaaaaaaa",
      "vaaaaaaaaaaaaaaa",
      "vaaaaaaaaaaaaaaa"
    ],
    [
      "vaaabcd    dc   ",
      "vaaabcd    dc   ",
      "vaaabccddddcc   ",
      "vaaabbcccccc    ",
      "vaaabbe         ",
      "vaaabbe         ",
      "vaaabbe         ",
      "vaaabbef        ",
      "vaaabbeff       ",
      "vaaabbeeeeeeeeee",
      "vaaabbbbbbbbbbbb",
      "vaaaaaaaaaaaaaaa",
      "vaaaaaaaaaaaaaaa",
      "vaaaaaaaaaaaaaaa",
      "vaaaaaaaaaaaaaaa",
      "vaaaaaaaaaaaaaaa"
    ],
    [
      "vaaabcd    dc   ",
      "vaaabcd    dc   ",
      "vaaabccddddcc   ",
      "vaaabbcccccc    ",
      "vaaabbe         ",
      "vaaabbe         ",
      "vaaabbe         ",
      "vaaabbef        ",
      "vaaabbeff       ",
      "vaaabbeeeeeeeeee",
      "vaaabbbbbbbbbbbb",
      "vaaaaaaaaaaaaaaa",
      "vaaaaaaaaaaaaaaa",
      "vaaaaaaaaaaaaaaa",
      "vaaaaaaaaaaaaaaa",
      "vaaaaaaaaaaaaaaa"
    ],
    [
      "vaaabcd    dc   ",
      "vaaabcd    dc   ",
      "vaaabccddddcc   ",
      "vaaabbcccccc    ",
      "vaaabbe         ",
      "vaaabbe         ",
      "vaaabbe         ",
      "vaaabbef        ",
      "vaaabbeff       ",
      "vaaabbeeeeeeeeee",
      "vaaabbbbbbbbbbbb",
      "vaaaaaaaaaaaaaaa",
      "vaaaaaaaaaaaaaaa",
      "vaaaaaaaaaaaaaaa",
      "vaaaaaaaaaaaaaaa",
      "vaaaaaaaaaaaaaaa"
    ],
    [
      "vaaabcdbbbbdc   ",
      "vaaabcdbbbbdc   ",
      "vaaabccddddcc   ",
      "vaaabbcccccc    ",
      "vaaabbe         ",
      "vaaabbe         ",
      "vaaabbe         ",
      "vaaabbef        ",
      "vaaabbeff       ",
      "vaaabbeeeeeeeeee",
      "vaaabbbbbbbbbbbb",
      "vaaaaaaaaaaaaaaa",
      "vaaaaaaaaaaaaaaa",
      "vaaaaaaaaaaaaaaa",
      "vaaaaaaaaaaaaaaa",
      "vaaaaaaaaaaaaaaa"
    ]
  ]
}