{
  "name": "multi_nuclearpowerplant_5_base1",
  "refpalette": "deceasedcraft:multi_nuclearpowerplant_5/multi_nuclearpowerplant_5_base1_palette",
  "xsize": 16,
  "zsize": 16,
  "slices": [
    [
      "vaaaaaaaabzccccc",
      "vaaaaaaaaabzcccc",
      "vaaaaaaaaabzcccc",
      "vaaaaaaaaaabzccc",
      "vaaaaaaaaaaabzcc",
      "vaaaaaaaaaaabzcc",
      "vaaaaaaaaaaaabzc",
      "vaaaaaaaaaaaaabz",
      "vaaaaaaaaaaaaabz",
      "vaaaaaaaaaaaaaab",
      "vaaaaaaaaaaaaaaa",
      "vaaaaaaaaaaaaaaa",
      "vaaaaaaaaaaaaaaa",
      "vaaaaaaaaaaaaaaa",
      "vaaaaaaaaaaaaaaa",
      "vaaaaaaaaaaaaaaa"
    ],
    [
      "vddddddddef     ",
      "vdddddddddef    ",
      "vdddddddddef    ",
      "vddddddddddef   ",
      "vdddddddddddef  ",
      "vdddddddddddef  ",
      "vddddddddddddef ",
      "vdddddddddddddef",
      "vdddddddddddddef",
      "vdddddddddddddde",
      "vddddddddddddddd",
      "vddddddddddddddd",
      "vddddddddddddddd",
      "vddddddddddddddd",
      "vddddddddddddddd",
      "vddddddddddddddd"
    ],
    [
      "vdddddddde      ",
      "vddddddddde     ",
      "vddddddddde     ",
      "vdddddddddde    ",
      "vddddddddddde   ",
      "vddddddddddde   ",
      "vdddddddddddde  ",
      "vddddddddddddde ",
      "vddddddddddddde ",
      "vdddddddddddddde",
      "vddddddddddddddd",
      "vddddddddddddddd",
      "vddddddddddddddd",
      "vddddddddddddddd",
      "vddddddddddddddd",
      "vddddddddddddddd"
    ],
    [
      "vdddddddde      ",
      "vddddddddde     ",
      "vddddddddde     ",
      "vdddddddddde    ",
      "vddddddddddde   ",
      "vddddddddddde   ",
      "vdddddddddddde  ",
      "vddddddddddddde ",
      "vddddddddddddde ",
      "vdddddddddddddde",
      "vddddddddddddddd",
      "vddddddddddddddd",
      "vddddddddddddddd",
      "vddddddddddddddd",
      "vddddddddddddddd",
      "vddddddddddddddd"
    ],
    [
      "vdddddddde      ",
      "vddddddddde     ",
      "vddddddddde     ",
      "vdddddddddde    ",
      "vdddddddddddeg  ",
      "vddddddddddde   ",
      "vdddddddddddde  ",
      "vddddddddddddde ",
      "vddddddddddddde ",
      "vdddddddddddddde",
      "vddddddddddddddd",
      "vddddddddddddddd",
      "vddddddddddddddd",
      "vddddddddddddddd",
      "vddddddddddddddd",
      "vddddddddddddddd"
    ],
    [
      "vddddddddehh    ",
      "vdddddddddeh    ",
      "vdddddddddehh   ",
      "vddddddddddehh  ",
      "vdddddddddddeh  ",
      "vdddddddddddehh ",
      "vddddddddddddehh",
      "vdddddddddddddeh",
      "vdddddddddddddeh",
      "vdddddddddddddde",
      "vddddddddddddddd",
      "vddddddddddddddd",
      "vddddddddddddddd",
      "vddddddddddddddd",
      "vddddddddddddddd",
      "vddddddddddddddd"
    ]
  ]
}