{
  "name": "multi_nuclearpowerplant_5_base2",
  "refpalette": "deceasedcraft:multi_nuclearpowerplant_5/multi_nuclearpowerplant_5_base2_palette",
  "xsize": 16,
  "zsize": 16,
  "slices": [
    [
      "v        a      ",
      "v         a     ",
      "v         a     ",
      "v          a    ",
      "v           a   ",
      "v           a   ",
      "v            a  ",
      "v             a ",
      "v             a ",
      "v              a",
      "v               ",
      "v               ",
      "v               ",
      "v               ",
      "v               ",
      "v               "
    ],
    [
      "v        a      ",
      "v         a     ",
      "v         a     ",
      "v          a    ",
      "v           a   ",
      "v           a   ",
      "v            a  ",
      "v             a ",
      "v             a ",
      "v              a",
      "v               ",
      "v               ",
      "v               ",
      "v               ",
      "v               ",
      "v               "
    ],
    [
      "v        a      ",
      "v         a     ",
      "v         a     ",
      "v          a    ",
      "v           a   ",
      "v           a   ",
      "v            a  ",
      "v             a ",
      "v             a ",
      "v              a",
      "v               ",
      "v               ",
      "v               ",
      "v               ",
      "v               ",
      "v               "
    ],
    [
      "v        a      ",
      "v         a     ",
      "v         a     ",
      "v          a    ",
      "v           a   ",
      "v           a   ",
      "v            a  ",
      "v             a ",
      "v             a ",
      "v              a",
      "v               ",
      "v               ",
      "v               ",
      "v               ",
      "v               ",
      "v               "
    ],
    [
      "v        a      ",
      "v         a     ",
      "v         a     ",
      "v          a    ",
      "v           a   ",
      "v           a   ",
      "v            a  ",
      "v             a ",
      "v             a ",
      "v              a",
      "v               ",
      "v               ",
      "v               ",
      "v               ",
      "v               ",
      "v               "
    ],
    [
      "v        abbbbbb",
      "v         abbbbb",
      "v         abbbbb",
      "v          abbbb",
      "v           abbb",
      "v           abbb",
      "v            abb",
      "v             ab",
      "v             ab",
      "v              a",
      "v               ",
      "v               ",
      "v               ",
      "v               ",
      "v               ",
      "v               "
    ]
  ]
}