{
  "name": "multi_nuclearpowerplant_5_base10",
  "refpalette": "deceasedcraft:multi_nuclearpowerplant_5/multi_nuclearpowerplant_5_base10_palette",
  "xsize": 16,
  "zsize": 16,
  "slices": [
    [
      "vaaabcbbbbbbc   ",
      "vaaabcbbbbbbc   ",
      "vaaabccbbbbcc   ",
      "vaaabbcccccc    ",
      "vaaabbd ee      ",
      "vaaabbd ee      ",
      "vaaabbd eeeeeeee",
      "vaaabbdfeeeeeeee",
      "vaaabbdff       ",
      "vaaabbdddddddddd",
      "vaaabbbbbbbbbbbb",
      "vaaaaaaaaaaaaaaa",
      "vaaaaaaaaaaaaaaa",
      "vaaaaaaaaaaaaaaa",
      "vaaaaaaaaaaaaaaa",
      "vaaaaaaaaaaaaaaa"
    ],
    [
      "vaaabc      c   ",
      "vaaabc      c   ",
      "vaaabcc    cc   ",
      "vaaabbccghcc    ",
      "vaaabbd ij      ",
      "vaaabbd ijkkkkkk",
      "vaaabbd i       ",
      "vaaabbdflkkkkkkk",
      "vaaabbdff       ",
      "vaaabbdddddddddd",
      "vaaabbbbbbbbbbbb",
      "vaaaaaaaaaaaaaaa",
      "vaaaaaaaaaaaaaaa",
      "vaaaaaaaaaaaaaaa",
      "vaaaaaaaaaaaaaaa",
      "vaaaaaaaaaaaaaaa"
    ],
    [
      "vaaabc      c   ",
      "vaaabc      c   ",
      "vaaabcc    cc   ",
      "vaaabbccmncc    ",
      "vaaabbd   o     ",
      "vaaabbd         ",
      "vaaabbd         ",
      "vaaabbdf        ",
      "vaaabbdff       ",
      "vaaabbdddddddddd",
      "vaaabbbbbbbbbbbb",
      "vaaaaaaaaaaaaaaa",
      "vaaaaaaaaaaaaaaa",
      "vaaaaaaaaaaaaaaa",
      "vaaaaaaaaaaaaaaa",
      "vaaaaaaaaaaaaaaa"
    ],
    [
      "vaaabc      c   ",
      "vaaabc      c   ",
      "vaaabcc    cc   ",
      "vaaabbccppcc    ",
      "vaaabbd         ",
      "vaaabbd         ",
      "vaaabbd         ",
      "vaaabbdf        ",
      "vaaabbdff       ",
      "vaaabbdddddddddd",
      "vaaabbbbbbbbbbbb",
      "vaaaaaaaaaaaaaaa",
      "vaaaaaaaaaaaaaaa",
      "vaaaaaaaaaaaaaaa",
      "vaaaaaaaaaaaaaaa",
      "vaaaaaaaaaaaaaaa"
    ],
    [
      "vaaabc      c   ",
      "vaaabc      c   ",
      "vaaabcc    cc   ",
      "vaaabbcccccc    ",
      "vaaabbd         ",
      "vaaabbd         ",
      "vaaabbd         ",
      "vaaabbdf        ",
      "vaaabbdff       ",
      "vaaabbdddddddddd",
      "vaaabbbbbbbbbbbb",
      "vaaaaaaaaaaaaaaa",
      "vaaaaaaaaaaaaaaa",
      "vaaaaaaaaaaaaaaa",
      "vaaaaaaaaaaaaaaa",
      "vaaaaaaaaaaaaaaa"
    ],
    [
      "vaaabc      c   ",
      "vaaabc      c   ",
      "vaaabcc    cc   ",
      "vaaabbcccccc    ",
      "vaaabbd         ",
      "vaaabbd         ",
      "vaaabbd         ",
      "vaaabbdf        ",
      "vaaabbdff       ",
      "vaaabbdddddddddd",
      "vaaabbbbbbbbbbbb",
      "vaaaaaaaaaaaaaaa",
      "vaaaaaaaaaaaaaaa",
      "vaaaaaaaaaaaaaaa",
      "vaaaaaaaaaaaaaaa",
      "vaaaaaaaaaaaaaaa"
    ]
  ]
}