{
  "name": "multi_nuclearpowerplant_5_ground",
  "refpalette": "deceasedcraft:multi_nuclearpowerplant_5/multi_nuclearpowerplant_5_ground_palette",
  "xsize": 16,
  "zsize": 16,
  "slices": [
    [
      "zzzaaazaaabbc   ",
      "zzazaaaaaaabcc  ",
      "zzzazazaaaabbcc ",
      "zzzzazaaaaaabbc ",
      "zazzzzazaaaaabcc",
      "zzzazazaaaaaabbc",
      "zzzzzazzaazaaabb",
      "zzazzzzaaaaaaaab",
      "zzzzzzaaazaaaaab",
      "zzzzzazzaaazaaaa",
      "zzzazzzzzaazaaaa",
      "zzzzzzazazaazaaa",
      "zzzzzzzzaazzazaa",
      "zzzzzzzzzzazaaaa",
      "zzzzzazzazzaaaaz",
      "zzzzzzzzzzzzazza"
    ],
    [
      "         dazccc ",
      "          ezcccc",
      "f f       dzzccc",
      "  f        ezzcc",
      "     f      ezcc",
      "  f         dzzc",
      "             ezz",
      "    g f       ha",
      " f  f         dz",
      "   ff f    f   e",
      "f               ",
      "  fff           ",
      "  f f      f    ",
      "ff  f f         ",
      " f  f           ",
      "ff  f  g  ff    "
    ],
    [
      "          iizzcc",
      "           izzcc",
      "           iizzc",
      "            iizz",
      "             iza",
      "             iiz",
      "              ii",
      "               i",
      "               i",
      "                ",
      "                ",
      "                ",
      "                ",
      "                ",
      "                ",
      "                "
    ],
    [
      "          iif zc",
      "           ig zz",
      "           ii  a",
      "            ii  ",
      "             i  ",
      "             ii ",
      "              ii",
      "               i",
      "               i",
      "                ",
      "                ",
      "                ",
      "                ",
      "                ",
      "                ",
      "                "
    ],
    [
      "          j   gz",
      "           j   f",
      "           j    ",
      "            j   ",
      "             j  ",
      "             j  ",
      "              j ",
      "               j",
      "               j",
      "                ",
      "                ",
      "                ",
      "                ",
      "                ",
      "                ",
      "                "
    ],
    [
      "                ",
      "                ",
      "                ",
      "                ",
      "                ",
      "                ",
      "                ",
      "                ",
      "                ",
      "                ",
      "                ",
      "                ",
      "                ",
      "                ",
      "                ",
      "                "
    ]
  ]
}