{
  "name": "multi_nuclearpowerplant_5_base3",
  "refpalette": "deceasedcraft:multi_nuclearpowerplant_5/multi_nuclearpowerplant_5_base3_palette",
  "xsize": 16,
  "zsize": 16,
  "slices": [
    [
      "vaa      bccccc ",
      "vaa       bccccc",
      "vaa       bccccc",
      "vaa        bcccc",
      "vaa         bccc",
      "vaa         bccc",
      "vaa          bcc",
      "vaa           bc",
      "vaa           bc",
      "vaa            b",
      "vaa             ",
      "vaa             ",
      "vaa             ",
      "vaa             ",
      "vaa             ",
      "vaa             "
    ],
    [
      "v d      e    f ",
      "v d       e    g",
      "v d       e    f",
      "v d        e    ",
      "v d         e   ",
      "v d         eh  ",
      "v d          e  ",
      "v d           e ",
      "v d           e ",
      "v d            e",
      "v d             ",
      "v d             ",
      "v d             ",
      "v d             ",
      "v d             ",
      "v d             "
    ],
    [
      "v        e      ",
      "v         e     ",
      "v         e     ",
      "v          e    ",
      "v           e   ",
      "v           e   ",
      "v            e  ",
      "v             e ",
      "v             e ",
      "v              e",
      "v               ",
      "v               ",
      "v               ",
      "v               ",
      "v               ",
      "v               "
    ],
    [
      "v        e      ",
      "v         e     ",
      "v         e     ",
      "v          e    ",
      "v           e   ",
      "v           e   ",
      "v            e  ",
      "v             e ",
      "v             e ",
      "v              e",
      "v               ",
      "v               ",
      "v               ",
      "v               ",
      "v               ",
      "v               "
    ],
    [
      "v        e      ",
      "v         e     ",
      "v         e     ",
      "v          e    ",
      "v           e   ",
      "v           e   ",
      "v            e  ",
      "v             e ",
      "v             e ",
      "v              e",
      "v               ",
      "v               ",
      "v               ",
      "v               ",
      "v               ",
      "v               "
    ],
    [
      "v        e      ",
      "v         e     ",
      "v         e     ",
      "v          e    ",
      "v           e   ",
      "v           e   ",
      "v            e  ",
      "v             e ",
      "v             e ",
      "v              e",
      "v               ",
      "v               ",
      "v               ",
      "v               ",
      "v               ",
      "v               "
    ]
  ]
}