{
  "name": "multi_nuclearpowerplant_5_base6",
  "refpalette": "deceasedcraft:multi_nuclearpowerplant_5/multi_nuclearpowerplant_5_base6_palette",
  "xsize": 16,
  "zsize": 16,
  "slices": [
    [
      "vvvvvvvvva      ",
      "vvvvvvvvvva     ",
      "vvvvvvvvvva     ",
      "vvvvvvvvvvva    ",
      "vvvvvvvvvvvva   ",
      "vvvvvvvvvvvvab  ",
      "vvvvvvvvvvvvva  ",
      "vvvvvvvvvvvvvvac",
      "vvvvvvvvvvvvvvad",
      "vvvvvvvvvvvvvvva",
      "vvvvvvvvvvvvvvvv",
      "vvvvvvvvvvvvvvvv",
      "vvvvvvvvvvvvvvvv",
      "vvvvvvvvvvvvvvvv",
      "vvvvvvvvvvvvvvvv",
      "vvvvvvvvvvvvvvvv"
    ],
    [
      "veeeeeeeef      ",
      "veeeeeeeeef     ",
      "veeeeeeeeef     ",
      "veeeeeeeeeef    ",
      "veeeeeeeeeeef   ",
      "veeeeeeeeeeef   ",
      "veeeeeeeeeeeef  ",
      "veeeeeeeeeeeeef ",
      "veeeeeeeeeeeeef ",
      "veeeeeeeeeeeeeef",
      "veeeeeeeeeeeeeee",
      "veeeeeeeeeeeeeee",
      "veeeeeeeeeeeeeee",
      "veeeeeeeeeeeeeee",
      "veeeeeeeeeeeeeee",
      "veeeeeeeeeeeeeee"
    ],
    [
      "vddddddddf      ",
      "vdddddddddf     ",
      "vdddddddddf     ",
      "vddddddddddf    ",
      "vdddddddddddf   ",
      "vdddddddddddf   ",
      "vddddddddddddf  ",
      "vdddddddddddddf ",
      "vdddddddddddddf ",
      "vddddddddddddddf",
      "vddddddddddddddd",
      "vddddddddddddddd",
      "vddddddddddddddd",
      "vddddddddddddddd",
      "vddddddddddddddd",
      "vddddddddddddddd"
    ],
    [
      "vddddddddf      ",
      "vdddddddddf     ",
      "vdddddddddf     ",
      "vddddddddddf    ",
      "vdddddddddddf   ",
      "vdddddddddddf   ",
      "vddddddddddddf  ",
      "vdddddddddddddf ",
      "vdddddddddddddf ",
      "vddddddddddddddf",
      "vddddddddddddddd",
      "vddddddddddddddd",
      "vddddddddddddddd",
      "vddddddddddddddd",
      "vddddddddddddddd",
      "vddddddddddddddd"
    ],
    [
      "vddddddddf      ",
      "vdddddddddf     ",
      "vdddddddddf     ",
      "vddddddddddf    ",
      "vdddddddddddf   ",
      "vdddddddddddf   ",
      "vddddddddddddf  ",
      "vdddddddddddddf ",
      "vdddddddddddddf ",
      "vddddddddddddddf",
      "vddddddddddddddd",
      "vddddddddddddddd",
      "vddddddddddddddd",
      "vddddddddddddddd",
      "vddddddddddddddd",
      "vddddddddddddddd"
    ],
    [
      "vddddddddf      ",
      "vdddddddddf     ",
      "vdddddddddf     ",
      "vddddddddddf    ",
      "vdddddddddddf   ",
      "vdddddddddddf   ",
      "vddddddddddddf  ",
      "vdddddddddddddf ",
      "vdddddddddddddf ",
      "vddddddddddddddf",
      "vddddddddddddddd",
      "vddddddddddddddd",
      "vddddddddddddddd",
      "vddddddddddddddd",
      "vddddddddddddddd",
      "vddddddddddddddd"
    ]
  ]
}