{
  "name": "multi_nuclearpowerplant_5_base9",
  "refpalette": "deceasedcraft:multi_nuclearpowerplant_5/multi_nuclearpowerplant_5_base9_palette",
  "xsize": 16,
  "zsize": 16,
  "slices": [
    [
      "vaaabbcdeeecf   ",
      "vaaabbceeeecf   ",
      "vaaabbcccccff   ",
      "vaaabbgfffff    ",
      "vaaabbg         ",
      "vaaabbg         ",
      "vaaabbg         ",
      "vaaabbgh        ",
      "vaaabbghh       ",
      "vaaabbgggggggggg",
      "vaaabbbbbbbbbbbb",
      "vaaaaaaaaaaaaaaa",
      "vaaaaaaaaaaaaaaa",
      "vaaaaaaaaaaaaaaa",
      "vaaaaaaaaaaaaaaa",
      "vaaaaaaaaaaaaaaa"
    ],
    [
      "vaaabbgi   f    ",
      "vaaabbg    f    ",
      "vaaabbgffff     ",
      "vaaabbg         ",
      "vaaabbg         ",
      "vaaabbg         ",
      "vaaabbg         ",
      "vaaabbgh        ",
      "vaaabbghh       ",
      "vaaabbgggggggggg",
      "vaaabbbbbbbbbbbb",
      "vaaaaaaaaaaaaaaa",
      "vaaaaaaaaaaaaaaa",
      "vaaaaaaaaaaaaaaa",
      "vaaaaaaaaaaaaaaa",
      "vaaaaaaaaaaaaaaa"
    ],
    [
      "vaaabbgi        ",
      "vaaabbg         ",
      "vaaabbg         ",
      "vaaabbg         ",
      "vaaabbg         ",
      "vaaabbg         ",
      "vaaabbg         ",
      "vaaabbgh        ",
      "vaaabbghh       ",
      "vaaabbgggggggggg",
      "vaaabbbbbbbbbbbb",
      "vaaaaaaaaaaaaaaa",
      "vaaaaaaaaaaaaaaa",
      "vaaaaaaaaaaaaaaa",
      "vaaaaaaaaaaaaaaa",
      "vaaaaaaaaaaaaaaa"
    ],
    [
      "vaaabbgi        ",
      "vaaabbg         ",
      "vaaabbg         ",
      "vaaabbg         ",
      "vaaabbg         ",
      "vaaabbg         ",
      "vaaabbg         ",
      "vaaabbghj       ",
      "vaaabbghh       ",
      "vaaabbgggggggggg",
      "vaaabbbbbbbbbbbb",
      "vaaaaaaaaaaaaaaa",
      "vaaaaaaaaaaaaaaa",
      "vaaaaaaaaaaaaaaa",
      "vaaaaaaaaaaaaaaa",
      "vaaaaaaaaaaaaaaa"
    ],
    [
      "vaaabbgii       ",
      "vaaabbg i       ",
      "vaaabbg i       ",
      "vaaabbg i       ",
      "vaaabbg i       ",
      "vaaabbg i       ",
      "vaaabbg i       ",
      "vaaabbghiiiiiiii",
      "vaaabbghh       ",
      "vaaabbgggggggggg",
      "vaaabbbbbbbbbbbb",
      "vaaaaaaaaaaaaaaa",
      "vaaaaaaaaaaaaaaa",
      "vaaaaaaaaaaaaaaa",
      "vaaaaaaaaaaaaaaa",
      "vaaaaaaaaaaaaaaa"
    ],
    [
      "vaaabbg         ",
      "vaaabbg         ",
      "vaaabbg         ",
      "vaaabbg         ",
      "vaaabbg         ",
      "vaaabbg         ",
      "vaaabbg         ",
      "vaaabbgh        ",
      "vaaabbghh       ",
      "vaaabbgggggggggg",
      "vaaabbbbbbbbbbbb",
      "vaaaaaaaaaaaaaaa",
      "vaaaaaaaaaaaaaaa",
      "vaaaaaaaaaaaaaaa",
      "vaaaaaaaaaaaaaaa",
      "vaaaaaaaaaaaaaaa"
    ]
  ]
}