{
  "name": "multi_nuclearpowerplant_5_base5",
  "refpalette": "deceasedcraft:multi_nuclearpowerplant_5/multi_nuclearpowerplant_5_base5_palette",
  "xsize": 16,
  "zsize": 16,
  "slices": [
    [
      "vaaaaaaaab      ",
      "vaaaaaaaaab     ",
      "vaaaaaaaaab     ",
      "vaaaaaaaaaab    ",
      "vaaaaaaaaaaab   ",
      "vaaaaaaaaaaab   ",
      "vaaaaaaaaaaaab  ",
      "vaaaaaaaaaaaaab ",
      "vaaaaaaaaaaaaab ",
      "vaaaaaaaaaaaaaab",
      "vaaaaaaaaaaaaaaa",
      "vaaaaaaaaaaaaaaa",
      "vaaaaaaaaaaaaaaa",
      "vaaaaaaaaaaaaaaa",
      "vaaaaaaaaaaaaaaa",
      "vaaaaaaaaaaaaaaa"
    ],
    [
      "vaaaaaaaab      ",
      "vaaaaaaaaab     ",
      "vaaaaaaaaab     ",
      "vaaaaaaaaaab    ",
      "vaaaaaaaaaaab   ",
      "vaaaaaaaaaaab   ",
      "vaaaaaaaaaaaab  ",
      "vaaaaaaaaaaaaab ",
      "vaaaaaaaaaaaaab ",
      "vaaaaaaaaaaaaaab",
      "vaaaaaaaaaaaaaaa",
      "vaaaaaaaaaaaaaaa",
      "vaaaaaaaaaaaaaaa",
      "vaaaaaaaaaaaaaaa",
      "vaaaaaaaaaaaaaaa",
      "vaaaaaaaaaaaaaaa"
    ],
    [
      "vaaaaaaaab      ",
      "vaaaaaaaaab     ",
      "vaaaaaaaaab     ",
      "vaaaaaaaaaab    ",
      "vaaaaaaaaaaab   ",
      "vaaaaaaaaaaab   ",
      "vaaaaaaaaaaaab  ",
      "vaaaaaaaaaaaaab ",
      "vaaaaaaaaaaaaab ",
      "vaaaaaaaaaaaaaab",
      "vaaaaaaaaaaaaaaa",
      "vaaaaaaaaaaaaaaa",
      "vaaaaaaaaaaaaaaa",
      "vaaaaaaaaaaaaaaa",
      "vaaaaaaaaaaaaaaa",
      "vaaaaaaaaaaaaaaa"
    ],
    [
      "vaaaaaaaab      ",
      "vaaaaaaaaab     ",
      "vaaaaaaaaab     ",
      "vaaaaaaaaaab    ",
      "vaaaaaaaaaaab   ",
      "vaaaaaaaaaaab   ",
      "vaaaaaaaaaaaab  ",
      "vaaaaaaaaaaaaab ",
      "vaaaaaaaaaaaaab ",
      "vaaaaaaaaaaaaaab",
      "vaaaaaaaaaaaaaaa",
      "vaaaaaaaaaaaaaaa",
      "vaaaaaaaaaaaaaaa",
      "vaaaaaaaaaaaaaaa",
      "vaaaaaaaaaaaaaaa",
      "vaaaaaaaaaaaaaaa"
    ],
    [
      "vaaaaaaaab      ",
      "vaaaaaaaaab     ",
      "vaaaaaaaaab     ",
      "vaaaaaaaaaab    ",
      "vaaaaaaaaaaab   ",
      "vaaaaaaaaaaab   ",
      "vaaaaaaaaaaaab  ",
      "vaaaaaaaaaaaaab ",
      "vaaaaaaaaaaaaab ",
      "vaaaaaaaaaaaaaab",
      "vaaaaaaaaaaaaaaa",
      "vaaaaaaaaaaaaaaa",
      "vaaaaaaaaaaaaaaa",
      "vaaaaaaaaaaaaaaa",
      "vaaaaaaaaaaaaaaa",
      "vaaaaaaaaaaaaaaa"
    ],
    [
      "vaaaaaaaab      ",
      "vaaaaaaaaab     ",
      "vaaaaaaaaab     ",
      "vaaaaaaaaaab    ",
      "vaaaaaaaaaaab   ",
      "vaaaaaaaaaaab   ",
      "vaaaaaaaaaaaab  ",
      "vaaaaaaaaaaaaab ",
      "vaaaaaaaaaaaaab ",
      "vaaaaaaaaaaaaaab",
      "vaaaaaaaaaaaaaaa",
      "vaaaaaaaaaaaaaaa",
      "vaaaaaaaaaaaaaaa",
      "vaaaaaaaaaaaaaaa",
      "vaaaaaaaaaaaaaaa",
      "vaaaaaaaaaaaaaaa"
    ]
  ]
}