{
  "name": "multi_nuclearpowerplant_5_base12",
  "refpalette": "deceasedcraft:multi_nuclearpowerplant_5/multi_nuclearpowerplant_5_base12_palette",
  "xsize": 16,
  "zsize": 16,
  "slices": [
    [
      "vaaaaaaaaaaaaaaa",
      "vaaaaaaaaaaaaaaa",
      "vaaaaaaaaaaaaaaa",
      "vaaaaaaaaaaaaaaa",
      "vaaaaaaaaaaaaaaa",
      "vaaaaaaaaaaaaaaa",
      "vaaaaaaaaaaaaaaa",
      "vaaaaaaaaaaaaaaa",
      "vaaaaaaaaaaaaaaa",
      "vaaaaaaaaaaaaaaa",
      "vaaaaaaaaaaaaaaa",
      "vaaaaaaaaaaaaaaa",
      "vaaaaaaaaaaaaaaa",
      "vaaaaaaaaaaaaaaa",
      "vaaaaaaaaaaaaaaa",
      "vaaaaaaaaaaaaaaa"
    ],
    [
      "vaaabbbbbbbbbbbb",
      "vaaabbbbbbbbbbbb",
      "vaaabbbbbbbbbbbb",
      "vaaabbbbbbbbbbbb",
      "vaaabbbbbbbbbbbb",
      "vaaabbbbbbbbbbbb",
      "vaaabbbbbbbbbbbb",
      "vaaabbbbbbbbbbbb",
      "vaaabbbbbbbbbbbb",
      "vaaabbbbbbbbbbbb",
      "vaaabbbbbbbbbbbb",
      "vaaaaaaaaaaaaaaa",
      "vaaaaaaaaaaaaaaa",
      "vaaaaaaaaaaaaaaa",
      "vaaaaaaaaaaaaaaa",
      "vaaaaaaaaaaaaaaa"
    ],
    [
      "vaaabc======cddd",
      "vaaabc======cddd",
      "vaaabcc====ccddd",
      "vaaabbccccccdddd",
      "vaaabbeddddddddd",
      "vaaabbeddddddddd",
      "vaaabbeddddddddd",
      "vaaabbeddddddddd",
      "vaaabbeddddddddd",
      "vaaabbeeeeeeeeee",
      "vaaabbbbbbbbbbbb",
      "vaaaaaaaaaaaaaaa",
      "vaaaaaaaaaaaaaaa",
      "vaaaaaaaaaaaaaaa",
      "vaaaaaaaaaaaaaaa",
      "vaaaaaaaaaaaaaaa"
    ],
    [
      "vaaabfbbbbbbf   ",
      "vaaabfbbbbbbf   ",
      "vaaabffbbbbff   ",
      "vaaabbffffff    ",
      "vaaabbe         ",
      "vaaabbe         ",
      "vaaabbe         ",
      "vaaabbeg        ",
      "vaaabbegg       ",
      "vaaabbeeeeeeeeee",
      "vaaabbbbbbbbbbbb",
      "vaaaaaaaaaaaaaaa",
      "vaaaaaaaaaaaaaaa",
      "vaaaaaaaaaaaaaaa",
      "vaaaaaaaaaaaaaaa",
      "vaaaaaaaaaaaaaaa"
    ],
    [
      "vaaabfhbbbbhf   ",
      "vaaabfhbbbbhf   ",
      "vaaabffhhhhff   ",
      "vaaabbffffff    ",
      "vaaabbe         ",
      "vaaabbe         ",
      "vaaabbe         ",
      "vaaabbeg        ",
      "vaaabbegg       ",
      "vaaabbeeeeeeeeee",
      "vaaabbbbbbbbbbbb",
      "vaaaaaaaaaaaaaaa",
      "vaaaaaaaaaaaaaaa",
      "vaaaaaaaaaaaaaaa",
      "vaaaaaaaaaaaaaaa",
      "vaaaaaaaaaaaaaaa"
    ],
    [
      "vaaabfh    hf   ",
      "vaaabfh    hf   ",
      "vaaabffhhhhff   ",
      "vaaabbffffff    ",
      "vaaabbe         ",
      "vaaabbe         ",
      "vaaabbe         ",
      "vaaabbeg        ",
      "vaaabbegg       ",
      "vaaabbeeeeeeeeee",
      "vaaabbbbbbbbbbbb",
      "vaaaaaaaaaaaaaaa",
      "vaaaaaaaaaaaaaaa",
      "vaaaaaaaaaaaaaaa",
      "vaaaaaaaaaaaaaaa",
      "vaaaaaaaaaaaaaaa"
    ]
  ]
}