{
  "name": "multi_nuclearpowerplant_5_base8",
  "refpalette": "deceasedcraft:multi_nuclearpowerplant_5/multi_nuclearpowerplant_5_base8_palette",
  "xsize": 16,
  "zsize": 16,
  "slices": [
    [
      "vaaabbcddddddddd",
      "vaaabbcddddddddd",
      "vaaabbcddddddddd",
      "vaaabbcddddddddd",
      "vaaabbcddddddddd",
      "vaaabbcddddddddd",
      "vaaabbcddddddddd",
      "vaaabbcddddddddd",
      "vaaabbcddddddddd",
      "vaaabbcccccccccc",
      "vaaabbbbbbbbbbbb",
      "vaaaaaaaaaaaaaaa",
      "vaaaaaaaaaaaaaaa",
      "vaaaaaaaaaaaaaaa",
      "vaaaaaaaaaaaaaaa",
      "vaaaaaaaaaaaaaaa"
    ],
    [
      "vaaabbbbbeffffff",
      "vaaabbbbbbefffff",
      "vaaabbbbbbefffff",
      "vaaabbbbbbbeffff",
      "vaaabbbbbbbbefff",
      "vaaabbbbbbbbefff",
      "vaaabbbbbbbbbeff",
      "vaaabbbbbbbbbbef",
      "vaaabbbbbbbbbbef",
      "vaaabbbbbbbbbbbe",
      "vaaabbbbbbbbbbbb",
      "vaaaaaaaaaaaaaaa",
      "vaaaaaaaaaaaaaaa",
      "vaaaaaaaaaaaaaaa",
      "vaaaaaaaaaaaaaaa",
      "vaaaaaaaaaaaaaaa"
    ],
    [
      "vaaaaaaaaghhhhhh",
      "vaaaaaaaaaghhhhh",
      "vaaaaaaaaaghhhhh",
      "vaaaaaaaaaaghhhh",
      "vaaaaaaaaaaaghhh",
      "vaaaaaaaaaaaghhh",
      "vaaaaaaaaaaaaghh",
      "vaaaaaaaaaaaaagh",
      "vaaaaaaaaaaaaagh",
      "vaaaaaaaaaaaaaag",
      "vaaaaaaaaaaaaaaa",
      "vaaaaaaaaaaaaaaa",
      "vaaaaaaaaaaaaaaa",
      "vaaaaaaaaaaaaaaa",
      "vaaaaaaaaaaaaaaa",
      "vaaaaaaaaaaaaaaa"
    ],
    [
      "vaaaaaaaaghhhhhh",
      "vaaaaaaaaaghhhhh",
      "vaaaaaaaaaghhhhh",
      "vaaaaaaaaaaghhhh",
      "vaaaaaaaaaaaghhh",
      "vaaaaaaaaaaaghhh",
      "vaaaaaaaaaaaaghh",
      "vaaaaaaaaaaaaagh",
      "vaaaaaaaaaaaaagh",
      "vaaaaaaaaaaaaaag",
      "vaaaaaaaaaaaaaaa",
      "vaaaaaaaaaaaaaaa",
      "vaaaaaaaaaaaaaaa",
      "vaaaaaaaaaaaaaaa",
      "vaaaaaaaaaaaaaaa",
      "vaaaaaaaaaaaaaaa"
    ],
    [
      "vaaaaaaaaghhhhhh",
      "vaaaaaaaaaghhhhh",
      "vaaaaaaaaaghhhhh",
      "vaaaaaaaaaaghhhh",
      "vaaaaaaaaaaaghhh",
      "vaaaaaaaaaaaghhh",
      "vaaaaaaaaaaaaghh",
      "vaaaaaaaaaaaaagh",
      "vaaaaaaaaaaaaagh",
      "vaaaaaaaaaaaaaag",
      "vaaaaaaaaaaaaaaa",
      "vaaaaaaaaaaaaaaa",
      "vaaaaaaaaaaaaaaa",
      "vaaaaaaaaaaaaaaa",
      "vaaaaaaaaaaaaaaa",
      "vaaaaaaaaaaaaaaa"
    ],
    [
      "vaaaaaaaaghhhhhh",
      "vaaaaaaaaaghhhhh",
      "vaaaaaaaaaghhhhh",
      "vaaaaaaaaaaghhhh",
      "vaaaaaaaaaaaghhh",
      "vaaaaaaaaaaaghhh",
      "vaaaaaaaaaaaaghh",
      "vaaaaaaaaaaaaagh",
      "vaaaaaaaaaaaaagh",
      "vaaaaaaaaaaaaaag",
      "vaaaaaaaaaaaaaaa",
      "vaaaaaaaaaaaaaaa",
      "vaaaaaaaaaaaaaaa",
      "vaaaaaaaaaaaaaaa",
      "vaaaaaaaaaaaaaaa",
      "vaaaaaaaaaaaaaaa"
    ]
  ]
}