{
  "name": "multi_hospital_0_base5",
  "refpalette": "deceasedcraft:multi_hospital_0/multi_hospital_0_base5_palette",
  "xsize": 16,
  "zsize": 16,
  "slices": [
    [
      "vvvvvvvvvvvvvvvv",
      "vvvvvvvvvvvvvvvv",
      "vvvvvvvvvvvvvvvv",
      "vvvvvvvvvvvvvvvv",
      "vvvvvvvvvvvvvvvv",
      "vvvvvvvvvvvvvvvv",
      "vvvvvvvvvvvvvvvv",
      "vvvvvvvvvvvvvvvv",
      "vvvvvvvvvvvvvvvv",
      "vvvvvvvvvvvvvvvv",
      "vvvvvvvvvvvvvvvv",
      "vvvvvvvvvvvvvvvv",
      "vvvvvvvvvvvvvvvv",
      "vvvvvvvvvvvvvvvv",
      "vvvvvvvvvvvvvvvv",
      "vvvvvvvvvvvvvvvv"
    ],
    [
      "vvvvvvvvvvvvvvvv",
      "vaaaaaaaaaaaaaaa",
      "vaaaaaaaaaaaaaaa",
      "vaaaaaaaaaaaaaaa",
      "vaaaaaaaaaaaaaaa",
      "vaaaaaaaaaaaaaaa",
      "vaaaaaaaaaaaaaaa",
      "vaaaaaaaaaaaaaaa",
      "vaaaaaaaaaaaaaaa",
      "vaaaaaaaaaaaaaaa",
      "vaaaaaaaaaaaaaaa",
      "vaaaaaaabbbbbaaa",
      "vaaaaaabbbbbbbaa",
      "vaaaaaabbbbbbbaa",
      "vaaaaaabbbbbbbaa",
      "vaaaaaabbbbbbbaa"
    ],
    [
      "vvvvvvvvvvvvvvvv",
      "vaaaaaaaaaaaaaaa",
      "vaaaaaaaaaaaaaaa",
      "vaaaaaaaaaaaaaaa",
      "vaaaaaaaaaaaaaaa",
      "vaaaaaaaaaaaaaaa",
      "vaaaaaaaaaaaaaaa",
      "vaaaaaaaaaaaaaaa",
      "vaaaaaaaaaaaaaaa",
      "vaaaaaaaaaaaaaaa",
      "vaaaaaaaaaaaaaaa",
      "vaaaaaaabbbbbaaa",
      "vaaaaaabcccccbaa",
      "vaaaaaabcccccbaa",
      "vaaaaaabcdcccbaa",
      "vaaaaaabcccccbaa"
    ],
    [
      "vvvvvvvvvvvvvvvv",
      "vaaaaaaaaaaaaaaa",
      "vaaaaaaaaaaaaaaa",
      "vaaaaaaaaaaaaaaa",
      "vaaaaaaaaaaaaaaa",
      "veeeeeeeeeeeeeee",
      "veeeeeeeeeeeeeee",
      "veeeeeeeeeeeeeee",
      "veeeeeeeeeeeeeee",
      "veeeeeeeeeeeeeee",
      "veeeeeeeeeeeeeee",
      "veeeeeeebbbbbeee",
      "veeeeeebfcgcdbee",
      "veeeeeebcgdhcbee",
      "veeeeeebijkiibee",
      "veeeeeebdfcdcbee"
    ],
    [
      "vvvvvvvvvvvvvvvv",
      "vaaaaaaaaaaaaaaa",
      "vaaaaaaaaaaaaaaa",
      "vaaaaaaaaaaaaaaa",
      "vaaaaaaaaaaaaaaa",
      "vlllllllllllllll",
      "vl              ",
      "vl       m m    ",
      "vl      nooon   ",
      "vl              ",
      "vl      ppqpp   ",
      "vl     bbbbbbb  ",
      "vl  r sbthghjbu ",
      "vl wx sbhhjhhbu ",
      "vl  x ybijhhibA ",
      "vl wx sbjthjhbu "
    ],
    [
      "vvvvvvvvvvvvvvvv",
      "vaaaaaaaaaaaaaaa",
      "vaaaaaaaaaaaaaaa",
      "vaaaaaaaaaaaaaaa",
      "vaaaaaaaaaaaaaaa",
      "vlllllllllllllll",
      "vl              ",
      "vl              ",
      "vl      B  CD   ",
      "vl              ",
      "vl        E     ",
      "vl     FIIIIIF  ",
      "vl  D  IthggjI  ",
      "vl  J  IihjhhI  ",
      "vl    KIijhhiIL ",
      "vl  M  IjthjiI  "
    ]
  ]
}