{
  "name": "multi_hospital_0_top",
  "refpalette": "deceasedcraft:multi_hospital_0/multi_hospital_0_top_palette",
  "xsize": 16,
  "zsize": 16,
  "slices": [
    [
      "                ",
      "                ",
      "                ",
      "                ",
      "                ",
      "                ",
      "                ",
      "                ",
      "                ",
      "                ",
      "                ",
      "   abbbbbbbbbbbb",
      "   abccccccccccc",
      "   abcdddddddddd",
      "   abcdddddddddd",
      "   abcdddddddddd"
    ],
    [
      "                ",
      "                ",
      "                ",
      "                ",
      "                ",
      "                ",
      "                ",
      "                ",
      "                ",
      "                ",
      "                ",
      "     ee ee ee ee",
      "    eccccccccccc",
      "    ecf gf gf gf",
      "     c h  h  h! ",
      "    ec          "
    ],
    [
      "                ",
      "                ",
      "                ",
      "                ",
      "                ",
      "                ",
      "                ",
      "                ",
      "                ",
      "                ",
      "                ",
      "     ee ee ee ee",
      "    eccicciccicc",
      "    ec          ",
      "     i          ",
      "    ec          "
    ],
    [
      "                ",
      "                ",
      "                ",
      "                ",
      "                ",
      "                ",
      "                ",
      "                ",
      "                ",
      "                ",
      "                ",
      "     ee ee ee ee",
      "    eccicciccicc",
      "    ec          ",
      "     i          ",
      "    ec          "
    ],
    [
      "                ",
      "                ",
      "                ",
      "                ",
      "                ",
      "                ",
      "                ",
      "                ",
      "                ",
      "                ",
      "                ",
      "     ee ee ee ee",
      "    eccicciccicc",
      "    ec          ",
      "     i          ",
      "    ec          "
    ],
    [
      "                ",
      "                ",
      "                ",
      "                ",
      "                ",
      "                ",
      "                ",
      "                ",
      "                ",
      "                ",
      "                ",
      "     ee ee ee ee",
      "    eccccccccccc",
      "    ecjjjjjjjjjj",
      "     cjkkkkkkkkk",
      "    ecjkkkkkkkkk"
    ],
    [
      "                ",
      "                ",
      "                ",
      "                ",
      "                ",
      "                ",
      "                ",
      "                ",
      "                ",
      "                ",
      "                ",
      "   abbbbbbbbbbbb",
      "   ablllllllllll",
      "   ablmmmmmmmmmm",
      "   ablmmmmmmmmmm",
      "   ablmmmmmmmmmn"
    ],
    [
      "                ",
      "                ",
      "                ",
      "                ",
      "                ",
      "                ",
      "                ",
      "                ",
      "                ",
      "                ",
      "                ",
      "                ",
      "     mmmmmmmmmmm",
      "     m    o     ",
      "     m  ppppp   ",
      "     m ppqqqppn "
    ],
    [
      "                ",
      "                ",
      "                ",
      "                ",
      "                ",
      "                ",
      "                ",
      "                ",
      "                ",
      "                ",
      "                ",
      "                ",
      "                ",
      "          r     ",
      "                ",
      "                "
    ]
  ]
}