{
  "name": "multi_hospital_0_base3",
  "refpalette": "deceasedcraft:multi_hospital_0/multi_hospital_0_base3_palette",
  "xsize": 16,
  "zsize": 16,
  "slices": [
    [
      "vvvvvvvvvvvvvvvv",
      "vaaaaaaaaaaaaaaa",
      "vaaaaaaaaaaaaaaa",
      "vaaaaaaaaaaaaaaa",
      "vaaaaaaaaaaaaaaa",
      "vbbbbbbbbbcbbbbb",
      "vb              ",
      "vb              ",
      "vb              ",
      "vbde            ",
      "vb              ",
      "vb     fgggggf  ",
      "vb     ghijiig  ",
      "vb     giihiig  ",
      "vb     gkhiikg  ",
      "vb     gilihig  "
    ],
    [
      "vvvvvvvvvvvvvvvv",
      "vaaaaaaaaaaaaaaa",
      "vaaaaaaaaaaaaaaa",
      "vaaaaaaaaaaaaaaa",
      "vaaaaaaaaaaaaaaa",
      "vbbbbbbbbbmbbbbb",
      "vb        n     ",
      "vb              ",
      "vb              ",
      "vb              ",
      "vbde            ",
      "vb     fgggggf  ",
      "vb     ghijjig  ",
      "vb     gkihiig  ",
      "vb     gkhiikg  ",
      "vb     gilihkg  "
    ],
    [
      "vvvvvvvvvvvvvvvv",
      "vaaaaaaaaaaaaaaa",
      "vaaaaaaaaaaaaaaa",
      "vaaaaaaaaaaaaaaa",
      "vaaaaaaaaaaaaaaa",
      "vbbbbbbbbbcbbbbb",
      "vb              ",
      "vb              ",
      "vb              ",
      "vb              ",
      "vb              ",
      "vbde   fgggggf  ",
      "vboo   ghiijig  ",
      "vboo   gkihiig  ",
      "vboo   gihiiig  ",
      "vboo   gilihkg  "
    ],
    [
      "vvvvvvvvvvvvvvvv",
      "vaaaaaaaaaaaaaaa",
      "vaaaaaaaaaaaaaaa",
      "vaaaaaaaaaaaaaaa",
      "vaaaaaaaaaaaaaaa",
      "vbbbbbbbbbcbbbbb",
      "vb              ",
      "vb              ",
      "vb              ",
      "vb              ",
      "vb              ",
      "vb     fgggggf  ",
      "vb p   gqiijjg  ",
      "vb p   gkihiig  ",
      "vc p   gihiiig  ",
      "vb p   gilihkg  "
    ],
    [
      "vvvvvvvvvvvvvvvv",
      "vaaaaaaaaaaaaaaa",
      "vaaaaaaaaaaaaaaa",
      "vaaaaaaaaaaaaaaa",
      "vaaaaaaaaaaaaaaa",
      "vbbbbbbbbbcbbbbb",
      "vb              ",
      "vb              ",
      "vb              ",
      "vb              ",
      "vb              ",
      "vb     fgggggf  ",
      "vb     gkiiijg  ",
      "vb     giihiig  ",
      "vc     gjhiiig  ",
      "vb     gjlihrg  "
    ],
    [
      "vvvvvvvvvvvvvvvv",
      "vaaaaaaaaaaaaaaa",
      "vaaaaaaaaaaaaaaa",
      "vaaaaaaaaaaaaaaa",
      "vaaaaaaaaaaaaaaa",
      "vbbbbbbbbbcbbbbb",
      "vb              ",
      "vb              ",
      "vb              ",
      "vb              ",
      "vb              ",
      "vb     fgggggf  ",
      "vb     gkkiijg  ",
      "vb     giihiqg  ",
      "vms    gihiiig  ",
      "vb     gjlihhg  "
    ]
  ]
}