{
  "name": "multi_hospital_0_base1",
  "refpalette": "deceasedcraft:multi_hospital_0/multi_hospital_0_base1_palette",
  "xsize": 16,
  "zsize": 16,
  "slices": [
    [
      "vvvvvvvvvvvvvvvv",
      "vaaaaabbbbbcde  ",
      "vafgggg    chii ",
      "vafj k     cd   ",
      "vafgggg    cdl  ",
      "vafj       chii ",
      "vafgggg    cd   ",
      "vafj k     cde  ",
      "vafgggg    chii ",
      "vafj! k    cd   ",
      "vafgggg    cdl  ",
      "vafj       chii ",
      "vafgggg    cd   ",
      "vafjm      cde  ",
      "vafgggg    chii ",
      "vafj k     cd   "
    ],
    [
      "vvvvvvvvvvvvvvvv",
      "vaaaaabbbbbcd   ",
      "vafgggg    chnk ",
      "vafjooo    cd   ",
      "vafgggg    cd   ",
      "vafjooo    chnk ",
      "vafgggg    cd   ",
      "vafjooo    cd   ",
      "vafgggg    chn! ",
      "vafjooo    cd   ",
      "vafgggg    cd   ",
      "vafjooo    chnk ",
      "vafgggg    cd   ",
      "vafjooo    cd   ",
      "vafgggg    chn  ",
      "vafjooo    cd   "
    ],
    [
      "vvvvvvvvvvvvvvvv",
      "vaaaaabbbbbcd   ",
      "vafgggg    ch   ",
      "vafjppp    cd   ",
      "vafgggg    cd   ",
      "vafjppp    ch   ",
      "vafgggg    cd   ",
      "vafjppp    cd   ",
      "vafgggg    ch   ",
      "vafjppp    cd   ",
      "vafgggg    cd   ",
      "vafjppp    ch   ",
      "vafgggg    cd   ",
      "vafjppp    cd   ",
      "vafgggg    ch   ",
      "vafjppp    cd   "
    ],
    [
      "vvvvvvvvvvvvvvvv",
      "vaaaaabbbbbcd   ",
      "vafgggg    ch   ",
      "vafj       cd   ",
      "vafgggg    cd   ",
      "vafjq!     ch   ",
      "vafgggg    cd   ",
      "vafj r     cd   ",
      "vafgggg    ch   ",
      "vafj       cd   ",
      "vafgggg    cd   ",
      "vafj       ch   ",
      "vafgggg    cd   ",
      "vafj       cd   ",
      "vafgggg    ch   ",
      "vafj r     cd   "
    ],
    [
      "vvvvvvvvvvvvvvvv",
      "vaaaaabbbbbchsss",
      "vafgggg    chhhh",
      "vafgggg    chsss",
      "vafgggg    chsss",
      "vafgogg    chhhh",
      "vafgggg    chsss",
      "vafgggg    chsss",
      "vafgggg    chhhh",
      "vafgggg    chsss",
      "vafgggg    chsss",
      "vafgggg    chhhh",
      "vafgggg    chsss",
      "vafgggg    chsss",
      "vafgggg    chhhh",
      "vafgggg    chsss"
    ],
    [
      "vvvvvvvvvvvvvvvv",
      "vaaaaafffffcffff",
      "vafffffffffchfff",
      "vafffffffffchfff",
      "vafffffffffchfff",
      "vafffffffffchfff",
      "vafffffffffcaaaf",
      "vafffffffffchfff",
      "vafffffffffchfff",
      "vafffffffffchfff",
      "vafffffffffchfff",
      "vafffffffffchfff",
      "vafffffffffchfff",
      "vafffffffffchfff",
      "vafffffffffchfff",
      "vafffffffffchfff"
    ]
  ]
}