{
  "name": "multi_hospital_0_base4",
  "refpalette": "deceasedcraft:multi_hospital_0/multi_hospital_0_base4_palette",
  "xsize": 16,
  "zsize": 16,
  "slices": [
    [
      "vvvvvvvvvvvvvvvv",
      "vaaaaaaaaaaaaaaa",
      "vaaaaaaaaaaaaaaa",
      "vaaaaaaaaaaaaaaa",
      "vaaaaaaaaaaaaaaa",
      "vbbbbbbbbbbbbbbb",
      "vb              ",
      "vb              ",
      "vb              ",
      "vb              ",
      "vb              ",
      "vb     cdddddc  ",
      "vb     deffghd  ",
      "vb     difhffd  ",
      "vb     dfhfffd  ",
      "vb     dhefhid  "
    ],
    [
      "vvvvvvvvvvvvvvvv",
      "vaaaaaaaaaaaaaaa",
      "vaaaaaaaaaaaaaaa",
      "vaaaaaaaaaaaaaaa",
      "vaaaaaaaaaaaaaaa",
      "vbbbbbbbbbbbbbbb",
      "vb              ",
      "vb              ",
      "vb              ",
      "vb              ",
      "vb              ",
      "vb     cdddddc  ",
      "vb     diffggd  ",
      "vb     difhffd  ",
      "vb     dfhfffd  ",
      "vb     dhefhjd  "
    ],
    [
      "vvvvvvvvvvvvvvvv",
      "vaaaaaaaaaaaaaaa",
      "vaaaaaaaaaaaaaaa",
      "vaaaaaaaaaaaaaaa",
      "vaaaaaaaaaaaaaaa",
      "vbbbbbbbbbbbbbbb",
      "vb              ",
      "vb              ",
      "vb              ",
      "vb              ",
      "vb              ",
      "vb     cdddddc  ",
      "vb     diiffgd  ",
      "vb     dffhffd  ",
      "vb     dfhfffd  ",
      "vb     dhefhfd  "
    ],
    [
      "vvvvvvvvvvvvvvvv",
      "vaaaaaaaaaaaaaaa",
      "vaaaaaaaaaaaaaaa",
      "vaaaaaaaaaaaaaaa",
      "vaaaaaaaaaaaaaaa",
      "vbbbbbbbbbbbbbbb",
      "vb              ",
      "vb              ",
      "vb              ",
      "vb              ",
      "vb              ",
      "vb     cdddddc  ",
      "vb     dijffgd  ",
      "vb     dffhfgd  ",
      "vb     dfhfffd  ",
      "vb     dhefhfd  "
    ],
    [
      "vvvvvvvvvvvvvvvv",
      "vaaaaaaaaaaaaaaa",
      "vaaaaaaaaaaaaaaa",
      "vaaaaaaaaaaaaaaa",
      "vaaaaaaaaaaaaaaa",
      "vbbbbbbbbbbbbbbb",
      "vbkkkkkkkkkkkkkk",
      "vbkkkkkkkkkkkkkk",
      "vb              ",
      "vb              ",
      "vb              ",
      "vb     cdddddc  ",
      "vb     dlifffd  ",
      "vb     dffhfgd  ",
      "vb     dfhfffd  ",
      "vb     dgefhgd  "
    ],
    [
      "vvvvvvvvvvvvvvvv",
      "vaaaaaaaaaaaaaaa",
      "vaaaaaaaaaaaaaaa",
      "vaaaaaaaaaaaaaaa",
      "vaaaaaaaaaaaaaaa",
      "vbbbbbbbbbmbbbbb",
      "vb              ",
      "vb  nnnnnnnnnnnn",
      "vbop            ",
      "vb              ",
      "vb              ",
      "vb     cdddddc  ",
      "vb     dhiiffd  ",
      "vb     dffhfjd  ",
      "vb     dghffgd  ",
      "vb     dgefhfd  "
    ]
  ]
}