{
  "name": "multi_hospital_0_base2",
  "refpalette": "deceasedcraft:multi_hospital_0/multi_hospital_0_base2_palette",
  "xsize": 16,
  "zsize": 16,
  "slices": [
    [
      "vvvvvvvvvvvvvvvv",
      "vaaaaaaaaaaaaaaa",
      "vaaaaaaaaaaaaaaa",
      "vaaaaaaaaaaaaaaa",
      "vaaaaaaaaaaaaaaa",
      "vbbbbbbbbbcbbbbb",
      "vb              ",
      "vb              ",
      "vb              ",
      "vb              ",
      "vb              ",
      "vb     deeeeed  ",
      "vb     efgffhe  ",
      "vb     effifhe  ",
      "vc     efifffe  ",
      "vb     ehjfiie  "
    ],
    [
      "vvvvvvvvvvvvvvvv",
      "vaaaaaaaaaaaaaaa",
      "vaaaaaaaaaaaaaaa",
      "vaaaaaaaaaaaaaaa",
      "vaaaaaaaaaaaaaaa",
      "vbbbbbbbbbcbbbbb",
      "vb              ",
      "vb              ",
      "vb              ",
      "vb              ",
      "vb              ",
      "vb     deeeeed  ",
      "vb     efggffe  ",
      "vb     effifhe  ",
      "vc     ehiffhe  ",
      "vb     ehjfiie  "
    ],
    [
      "vvvvvvvvvvvvvvvv",
      "vaaaaaaaaaaaaaaa",
      "vaaaaaaaaaaaaaaa",
      "vaaaaaaaaaaaaaaa",
      "vaaaaaaaaaaaaaaa",
      "vbbbbbbbbbcbbbbb",
      "vb              ",
      "vb              ",
      "vb              ",
      "vb              ",
      "vb              ",
      "vb     deeeeed  ",
      "vb     effgffe  ",
      "vb     effiffe  ",
      "vc     ehiffhe  ",
      "vb     efjfiie  "
    ],
    [
      "vvvvvvvvvvvvvvvv",
      "vaaaaaaaaaaaaaaa",
      "vaaaaaaaaaaaaaaa",
      "vaaaaaaaaaaaaaaa",
      "vaaaaaaaaaaaaaaa",
      "vbbbbbbbbbcbbbbb",
      "vb              ",
      "vb              ",
      "vb              ",
      "vb              ",
      "vb      kkkkk   ",
      "vb     lllllll  ",
      "vb    mlnoggnlp ",
      "vb    mlohnonlp ",
      "vc    mlhnqnhlp ",
      "vb    mlnonghlp "
    ],
    [
      "vvvvvvvvvvvvvvvv",
      "vrrrrrrrrrrrrrrr",
      "vrrrrrrrrrrrrrrr",
      "vrrrrrrrrrrrrrrr",
      "vrrrrrrrrrrrrrrr",
      "vrrrrrrrrrrrrrrr",
      "vrrrrrrrrrrrrrrr",
      "vrrrrrrrrrrrrrrr",
      "vrrrrrrrrrrrrrrr",
      "vrrrrrrrrrrrrrrr",
      "vrrrrrrrrrrrrrrr",
      "vrrrrrrrrrrrrrrr",
      "vrrrrrrrrrrrrrrr",
      "vrrrrrrrrrrrrrrr",
      "vrrrrrrrrrrrrrrr",
      "vrrrrrrrrrrrrrrr"
    ],
    [
      "vvvvvvvvvvvvvvvv",
      "vssssstttttuwwww",
      "vsxyyyy    uwwww",
      "vsxyyyy    uwwww",
      "vsxyyyy    uwwww",
      "vsxyyyy    uwwww",
      "vsxyyyy    uwwww",
      "vsxyyyy    uwwww",
      "vsxyyyy    uwwww",
      "vsxyyyy    uwwww",
      "vsxyyyy  A uwwww",
      "vsxyyyy    uwwww",
      "vsxyyyy    uwwww",
      "vsxyyyy    uwwww",
      "vsxyyyy    uwwww",
      "vsxyyyy    uwwww"
    ]
  ]
}