{
  "name": "multi_hospital_0_ground",
  "refpalette": "deceasedcraft:multi_hospital_0/multi_hospital_0_ground_palette",
  "xsize": 16,
  "zsize": 16,
  "slices": [
    [
      "aaaaaaaaaaaaaaaa",
      "aHHHHHHHHHHHHHHH",
      "aHHHHHHHHHHHHHHH",
      "bbbbbbbbbbbbbbbb",
      "HHHHHHHHHHHHHHHH",
      "HHHHHHHHHHHHHHHH",
      "HHHHHHHHHHHHHHHH",
      "bbbbbbbbbbbbbbbb",
      "aaaaaaaaaaaaaaaa",
      "aaaccccccccccccc",
      "aaacdddddddddddd",
      "aaacdddddddddddd",
      "aaaccccccccccccc",
      "aaeeeeeeeeeeeeee",
      "aaaffcgggggccccg",
      "aaaffcgggggccccg"
    ],
    [
      "                ",
      " h  ih  ih  ih  ",
      " j  kj  kj  kj l",
      "                ",
      "    m           ",
      "                ",
      "                ",
      "                ",
      "nnoppppppppppppp",
      "nnpqqqqqqqqqqqqq",
      "nnpq            ",
      "nnpqrrrrrrrrrrrr",
      "nnpqssssssssssss",
      "nneeeeeeeeeeeeee",
      "nnn tuwx   y  A ",
      "nnn tuw  B C  C "
    ],
    [
      "                ",
      "                ",
      "                ",
      "                ",
      "                ",
      "                ",
      "                ",
      "                ",
      "                ",
      "                ",
      "                ",
      "                ",
      "       DwEwF wIw",
      "  eeeeeeeeeeeeee",
      "    tuw    J  K ",
      "    tuw   LC  CM"
    ],
    [
      "                ",
      "                ",
      "                ",
      "                ",
      "                ",
      "                ",
      "                ",
      "                ",
      "                ",
      "                ",
      "                ",
      "                ",
      "        wEwCwwEw",
      "  eeeeeeeeeeeeee",
      "    tuw   NO  PQ",
      "    tuR    C  C "
    ],
    [
      "                ",
      "                ",
      "                ",
      "                ",
      "                ",
      "                ",
      "                ",
      "                ",
      "                ",
      "                ",
      "                ",
      "                ",
      "      S   S   S ",
      "  eeeeeeeeeeeeee",
      "    tuw  N!C  C ",
      "    tuw    C  C "
    ],
    [
      "                ",
      "                ",
      "                ",
      "                ",
      "                ",
      "                ",
      "                ",
      "                ",
      "                ",
      "                ",
      "                ",
      "    TTTTTTTTTTTT",
      "    TUUUUUUUUUUU",
      "    TUVVVVVVVVVV",
      "    TUVVVVVVVVVV",
      "    TUVVVVVVVVVV"
    ]
  ]
}