{
  "name": "multi_sunkenclub_5_ground",
  "refpalette": "deceasedcraft:multi_sunkenclub_5/multi_sunkenclub_5_ground_palette",
  "xsize": 16,
  "zsize": 16,
  "slices": [
    [
      "              aa",
      "            aaab",
      "aaaaaaaaaaaaabbb",
      "bbbbbbbbbbbbbbbb",
      "bbbbbbbbbcbbbbbc",
      "cbbccbcccbcbcbcc",
      "cbbbccbcbcccbccc",
      "bbcbbbccccbbbbbb",
      "bbbbdbcbcbbdbbbb",
      "aaaaaaaaaaaaaaaa",
      "eeeef g  g feeee",
      "eeeef g  g feeee",
      "eeeef g  g feeee",
      "eeeef g  g feeee",
      "aaaaaaaaaaaaaaaa",
      "dddddddddddddddd"
    ],
    [
      "~~~~~~~~~~~~hhhi",
      "hhhhhhhhhhhhhii~",
      "iiiijiiiiiiji~~~",
      "~~~~~~~kl~~~~~~~",
      "~~~~~~~~~~~~~~~~",
      "~~~~~~~~~~~~~~~~",
      "~~~~~~~~~~~~~~~~",
      "~~~~~~~~~~~~~~~~",
      "mn~~o~~~~~~o~~mn",
      "iiiijiippiijiiii",
      "hhhhhhiqqihhhhhh",
      "~~~~~hiqqih~~~~~",
      "~~~~~hiqqih~~~~~",
      "hhhhhhiqqihhhhhh",
      "iiiijiirriijiiii",
      "~~~~~~~~~~~~~~~~"
    ],
    [
      "~~~~~~~~~~~~~~~~",
      "~~~~~~~~~~~~~~~~",
      "~~~~s~~~~~~s~~~~",
      "~~~~~~~~~~~~~~~~",
      "~~~~~~~~~~~~~~~~",
      "~~~~~~~~~~~~~~~~",
      "~~~~~~~~~~~~~~~~",
      "~~~~~~~~~~~~~~~~",
      "~~~~~~~~~~~~~~~~",
      "~~~~~~i~~i~s~~~~",
      "~~~~~~i~~i~~~~~~",
      "~~~~~~i~~i~~~~~~",
      "~~~~~~i~~i~~~~~~",
      "~~~~~~i~~i~~~~~~",
      "~~~~s~i~~i~s~~~~",
      "~~~~~~~~~~~~~~~~"
    ],
    [
      "~~~~~~~~~~~~~~~~",
      "~~~~~~~~~~~~~~~~",
      "~~~~~~~~~~~~~~~~",
      "~~~~~~~~~~~~~~~~",
      "~~~~~~~~~~~~~~~~",
      "~~~~~~~~~~~~~~~~",
      "~~~~~~~~~~~~~~~~",
      "~~~~~~~~~~~~~~~~",
      "~~~~~~~~~~~~~~~~",
      "~~~~~~~~~~~~~~~~",
      "~~~~~~~~~~~~~~~~",
      "~~~~~~~~~~~~~~~~",
      "~~~~~~~~~~~~~~~~",
      "~~~~~~~~~~~~~~~~",
      "~~~~~~~~~~~~~~~~",
      "~~~~~~~~~~~~~~~~"
    ],
    [
      "~~~~~~~~~~~~~~~~",
      "~~~~~~~~~~~~~~~~",
      "~~~~~~~~~~~~~~~~",
      "~~~~~~~~~~~~~~~~",
      "~~~~~~~~~~~~~~~~",
      "~~~~~~~~~~~~~~~~",
      "~~~~~~~~~~~~~~~~",
      "~~~~~~~~~~~~~~~~",
      "~~~~~~~~~~~~~~~~",
      "~~~~~~~~~~~~~~~~",
      "~~~~~~~~~~~~~~~~",
      "~~~~~~~~~~~~~~~~",
      "~~~~~~~~~~~~~~~~",
      "~~~~~~~~~~~~~~~~",
      "~~~~~~~~~~~~~~~~",
      "~~~~~~~~~~~~~~~~"
    ],
    [
      "~~~~~~~~~~~~~~~~",
      "~~~~~~~~~~~~~~~~",
      "~~~~~~~~~~~~~~~~",
      "~~~~~~~~~~~~~~~~",
      "~~~~~~~~~~~~~~~~",
      "~~~~~~~~~~~~~~~~",
      "~~~~~~~~~~~~~~~~",
      "~~~~~~~~~~~~~~~~",
      "~~~~~~~~~~~~~~~~",
      "~~~~~~~~~~~~~~~~",
      "~~~~~~~~~~~~~~~~",
      "~~~~~~~~~~~~~~~~",
      "~~~~~~~~~~~~~~~~",
      "~~~~~~~~~~~~~~~~",
      "~~~~~~~~~~~~~~~~",
      "~~~~~~~~~~~~~~~~"
    ]
  ]
}