{
  "name": "multi_sunkenclub_5_base2",
  "refpalette": "deceasedcraft:multi_sunkenclub_5/multi_sunkenclub_5_base2_palette",
  "xsize": 16,
  "zsize": 16,
  "slices": [
    [
      "vvvvvvvvvvvvvvvv",
      "vvvvvvvvvvvvvvvv",
      "vvvvvvvvvvvvvvvv",
      "aaaaaaaaaaaaaaaa",
      "aaaaaaaaaaaaaaaa",
      "aaaaaaaaaaaaaaaa",
      "aaaaaaaaaaaaaaaa",
      "aaaaaaaaaaaaaaaa",
      "aaaaaaaaaaaaaaaa",
      "vvvvvvvvvvvvvvvv",
      "vvvvvvvvvvvvvvvv",
      "vvvvvvvvvvvvvvvv",
      "vvvvvvvvvvvvvvvv",
      "vvvvvvvvvvvvvvvv",
      "vvvvvvvvvvvvvvvv",
      "vvvvvvvvvvvvvvvv"
    ],
    [
      "bbbbbcbaacbbbddd",
      "bbbbcccaaccbbbbb",
      "aaaaeaaaaaaeaaaa",
      "fggfggghhgggfggg",
      "gggggfgggggggggg",
      "ggggggghhggggfgf",
      "ggggggghhggggggg",
      "gggggggggggggggg",
      "gfgfggghhfggggff",
      "aaaaeaaaaaaeaaaa",
      "bcccccbcccdccccb",
      "cccbdccccbcccdcc",
      "bbbbbbbbbbbbbbbb",
      "ddddidddddd!dddd",
      "jjjjkjjjjjjkjjjj",
      "vvvvvvvvvvvvvvvv"
    ],
    [
      "lmno  p q   onrn",
      "oooo   p    oooo",
      "    e      e    ",
      "     s tt       ",
      "  s       s   s ",
      "s      tt  s    ",
      "    s  tt       ",
      "s               ",
      "  s    tt s s   ",
      "    e      e    ",
      "               u",
      "   u     u      ",
      "rwrwwwrwxxwwrwrw",
      " n n n   nn nn n",
      "yyyykyyyyyykyyyy",
      "vvvvvvvvvvvvvvvv"
    ],
    [
      " AB          B B",
      "                ",
      "    e      e    ",
      "                ",
      "                ",
      "                ",
      "                ",
      "                ",
      "                ",
      "    e      e    ",
      "                ",
      "                ",
      "                ",
      " B B B   BB BB B",
      "yyyykyyyyyykyyyy",
      "vvvvvvvvvvvvvvvv"
    ],
    [
      "                ",
      "                ",
      "    e      e    ",
      "                ",
      "                ",
      "                ",
      "                ",
      "                ",
      "                ",
      "    e      e    ",
      "                ",
      "                ",
      "                ",
      "                ",
      "y CykCyyyyykCyyy",
      "vvvvvvvvvvvvvvvv"
    ],
    [
      "                ",
      "                ",
      "    e      e    ",
      "                ",
      "                ",
      "                ",
      "                ",
      "                ",
      "                ",
      "    e      e    ",
      "                ",
      "                ",
      "                ",
      "                ",
      "y CCkCyyyyCkCyyy",
      "vvvvvvvvvvvvvvvv"
    ]
  ]
}