{
  "name": "multi_nuclearpowerplant_39_base2",
  "refpalette": "deceasedcraft:multi_nuclearpowerplant_39/multi_nuclearpowerplant_39_base2_palette",
  "xsize": 16,
  "zsize": 16,
  "slices": [
    [
      "     a        =b",
      "     a        =b",
      "     a        =b",
      "     a        =b",
      "    a         =b",
      "    a         =b",
      "    a        ===",
      "    a       ==bb",
      "   a       =bb  ",
      "   a      =b    ",
      "  a      =b     ",
      "  a     =b      ",
      "  a    =b       ",
      " a    =b        ",
      " a   =b         ",
      "a   =b          "
    ],
    [
      "     a        =b",
      "     a        =b",
      "     a        =b",
      "     a        =b",
      "    a         =b",
      "    a         =b",
      "    a        ===",
      "    a       ==bb",
      "   a       =bb  ",
      "   a      =bc   ",
      "  a      =b c   ",
      "  a     =b  c   ",
      "  a    =b   c   ",
      " a    =b    c   ",
      " a   =b     c   ",
      "a   =b      c   "
    ],
    [
      "     a        =b",
      "     a        =b",
      "     a        =b",
      "     a        =b",
      "    a         =b",
      "    a         =b",
      "   da        ===",
      "    a       ==bb",
      "   a       =bb  ",
      "   a      =be   ",
      "  a      =b e   ",
      "  a     =b  e   ",
      "  a    =b   e   ",
      " a    =b    e   ",
      " a   =b     e   ",
      "a   =b      e   "
    ],
    [
      "     a fffffff=b",
      "     a fffffff=b",
      "     a fffffff=b",
      "     a fffffff=b",
      "    a  fffgggf=b",
      "    a ffffffff=b",
      "    a fffffff===",
      "    a ffffff===b",
      "   a  fffff==bbh",
      "   a fffff=bb   ",
      "  a  ffff=bb    ",
      "  a ffff=bb     ",
      "  a fff=bb      ",
      " a  ff=bb       ",
      " a ff=bb        ",
      "a  f=bb         "
    ],
    [
      "     ij k     k ",
      "     ij k     k ",
      "     ij k     k ",
      "     ij k     k ",
      "    ijj k     k ",
      "    ij  kl    k ",
      "    ij  klllllll",
      "    ijkkkkkkkkk=",
      "   ijj       ==b",
      "   ij      ==bbm",
      "  ijj     ==bmm ",
      "  ij     ==bm   ",
      "  ij    ==bm    ",
      " ijj   ==bm     ",
      " ij   ==bm      ",
      "ijj  ==bm       "
    ],
    [
      "nnnnnnjooppppppp",
      "nnnnnnjooppppppp",
      "nnnnnnjooppppppp",
      "nnnnnnjooppppppp",
      "nnnnnjjooppppppp",
      "nnnnnjqoorpppppp",
      "snnnnjqooppppppp",
      "nnnnnjqooooooooo",
      "nnnnjjqtttttttt=",
      "nnnnjqttttttt==b",
      "nnnjjqtttttt=bbb",
      "nnnjqtttttt=bbbb",
      "nnnjqttttt=bbbbb",
      "nnjjqtttt=bbbbbb",
      "nnjqtttt=bbbbbbb",
      "njjqttt=bbbbbbbb"
    ]
  ]
}