{
  "name": "multi_nuclearpowerplant_39_base7",
  "refpalette": "deceasedcraft:multi_nuclearpowerplant_39/multi_nuclearpowerplant_39_base7_palette",
  "xsize": 16,
  "zsize": 16,
  "slices": [
    [
      "   aa           ",
      "   aa           ",
      "                ",
      " b    b         ",
      "                ",
      "          c     ",
      "              ==",
      "            ==dd",
      "           =dde ",
      "         f=d    ",
      "         =d     ",
      "        =d      ",
      "       =de     g",
      "      =d      gg",
      "     =d      ggh",
      "    =d      gghh"
    ],
    [
      "   aa           ",
      "   aa           ",
      "                ",
      " b    b         ",
      "               i",
      "          c    j",
      "              ==",
      "            ==dd",
      "           =dd  ",
      "         f=d    ",
      "         =d     ",
      "        =d      ",
      "       =d      g",
      "      =d      gg",
      "     =d      ggh",
      "    =d      gghh"
    ],
    [
      "                ",
      "                ",
      " k    k         ",
      " b    b         ",
      "              i ",
      "          c   j ",
      "              ==",
      "            ==dd",
      "           =dd  ",
      "         f=d    ",
      "         =d     ",
      "        =d      ",
      "       =d      g",
      "      =d      gg",
      "     =d      ggl",
      "    =d      ggll"
    ],
    [
      " b    b         ",
      " b    b         ",
      "bbbbbbb         ",
      " b    b         ",
      " e           i  ",
      "          c  j  ",
      "              ==",
      "            ==dd",
      "           =dd  ",
      "         f=d    ",
      "         =d     ",
      "        =d      ",
      "       =d      g",
      "      =d      gg",
      "     =d      ggl",
      "    =d      ggll"
    ],
    [
      "mmmmmm          ",
      "mmmmmm          ",
      "mmmmmm          ",
      " b    b         ",
      "            i   ",
      "          c j   ",
      "              ==",
      "            ==dd",
      "           =dd  ",
      "         f=d    ",
      "         =d     ",
      "        =d      ",
      "       =d      g",
      "      =d      gg",
      "     =d      ggl",
      "    =d      ggll"
    ],
    [
      "   nno   pp     ",
      "   nno   pp     ",
      "ooooom   pp     ",
      " b    b  pp     ",
      "         ppi    ",
      "         pqj    ",
      "rrrrrrrrr     ==",
      "rrrrrrrrr   ==dd",
      "rrrrrrrrr  =dd  ",
      "rrrrrrrrrf=d    ",
      "rrrrrrrrr=d     ",
      "rrrrrrrr=d      ",
      "rrrrrrr=d      g",
      "rrrrrr=d      gg",
      "rrrrr=d      ggl",
      "rrrr=d      ggll"
    ]
  ]
}