{
  "name": "multi_nuclearpowerplant_39_base4",
  "refpalette": "deceasedcraft:multi_nuclearpowerplant_39/multi_nuclearpowerplant_39_base4_palette",
  "xsize": 16,
  "zsize": 16,
  "slices": [
    [
      "                ",
      "                ",
      "                ",
      "                ",
      "                ",
      "                ",
      "              ==",
      "            ==aa",
      "           =aa  ",
      "          =a    ",
      "         =a     ",
      "        =a      ",
      "       =a      b",
      "      =a      bb",
      "     =a      bbc",
      "    =a      bbcc"
    ],
    [
      "                ",
      "                ",
      "                ",
      "                ",
      "                ",
      "                ",
      "              ==",
      "            ==aa",
      "           =aa  ",
      "          =a    ",
      "         =a     ",
      "        =a      ",
      "       =a      b",
      "      =a      bb",
      "     =a      bbc",
      "    =a      bbcc"
    ],
    [
      "                ",
      "                ",
      "                ",
      "                ",
      "                ",
      "                ",
      "              ==",
      "            ==aa",
      "           =aa  ",
      "          =a    ",
      "         =a     ",
      "        =a      ",
      "       =a      b",
      "      =a      bb",
      "     =a      bbc",
      "    =a      bbcc"
    ],
    [
      "                ",
      "                ",
      "                ",
      "                ",
      "                ",
      "                ",
      "              ==",
      "            ==aa",
      "           =aa  ",
      "          =a    ",
      "         =a     ",
      "        =a      ",
      "       =a      b",
      "      =a      bb",
      "     =a      bbc",
      "    =a      bbcc"
    ],
    [
      "                ",
      "                ",
      "                ",
      "                ",
      "               d",
      "                ",
      "              ==",
      "            ==aa",
      "           =aa  ",
      "          =a    ",
      "         =a     ",
      "        =a      ",
      "       =a      b",
      "      =a      bb",
      "     =a      bb ",
      "    =a      bb  "
    ],
    [
      "                ",
      "                ",
      "                ",
      "                ",
      "                ",
      "                ",
      "              ==",
      "            ==aa",
      "           =aa  ",
      "          =a    ",
      "         =a     ",
      "        =a      ",
      "       =a      e",
      "      =a      ee",
      "     =a      ee ",
      "    =a      ee  "
    ]
  ]
}