{
  "name": "multi_nuclearpowerplant_39_base12",
  "refpalette": "deceasedcraft:multi_nuclearpowerplant_39/multi_nuclearpowerplant_39_base12_palette",
  "xsize": 16,
  "zsize": 16,
  "slices": [
    [
      "aaaaaaaaaaaaaaaa",
      "aaaaaaaaaaaaaaaa",
      "aaaaaaaaaaaaaaaa",
      "aaaaaaaaaaaaaaaa",
      "aaaaaaaaaaaaaaaa",
      "aaaaaaaaaaaaaaaa",
      "aaaaaaaaaaaaaaaa",
      "aaaaaaaaaaaaaaaa",
      "aaaaaaaaaaaaaaaa",
      "aaaaaaaaaaaaaaaa",
      "aaaaaaaaaaaaaaaa",
      "aaaaaaaaaaaaaaaa",
      "aaaaaaaaaaaaaaaa",
      "aaaaaaaaaaaaaaaa",
      "aaaaaaaaaaaaaaaa",
      "aaaaaaaaaaaaaaaa"
    ],
    [
      "bbbbbbbbbbbbbbbb",
      "bbbbbbbbbbbbbbbb",
      "bbbbbbbbbbbbbbbb",
      "bbbbbbbbbbbbbbbb",
      "bbbbbbbbbbbbbbbb",
      "bbbbbbbbbbbbbbbb",
      "bbbbbbbbbbbbbbbb",
      "bbbbbbbbbbbbbbbb",
      "bbbbbbbbbbbbbbbb",
      "bbbbbbbbbbbbbbbb",
      "bbbbbbbbbbbbbbbb",
      "bbbbbbbbbbbbbbbb",
      "bbbbbbbbbbbbbbbb",
      "bbbbbbbbbbbbbbbb",
      "bbbbbbbbbbbbbbbb",
      "bbbbbbbbbbbbbbbb"
    ],
    [
      "================",
      "================",
      "================",
      "================",
      "================",
      "================",
      "================",
      "================",
      "================",
      "================",
      "================",
      "================",
      "================",
      "================",
      "================",
      "================"
    ],
    [
      "cccccccccccccccc",
      "cccccccccccccccc",
      "cccccccccccccccc",
      "cccccccccccccccc",
      "cccccccccccccccc",
      "cccccccccccccccc",
      "cccccccccccccccc",
      "cccccccccccccccc",
      "cccccccccccccccc",
      "cccccccccccccccc",
      "cccccccccccccccc",
      "cccccccccccccccc",
      "cccccccccccccccc",
      "cccccccccccccccc",
      "cccccccccccccccc",
      "cccccccccccccccc"
    ],
    [
      "deedeedeedeedeed",
      "deedeedeedeedeed",
      "fddddddddddddddd",
      "deedeedeedeedeed",
      "deedeedeedeedeed",
      "dddddddddddddddd",
      "deedeedeedeedeed",
      "deedeedeedeedeed",
      "dddddddddddddddd",
      "deedeedeedeedeed",
      "deedeedeedeedeed",
      "dddddddddddddddd",
      "deedeedeedeedeed",
      "deedeedeedeedeed",
      "dddddddddddddddd",
      "deedeedeedeedeed"
    ],
    [
      "dghdhidghdhidghd",
      "djidgjdjidgjdjid",
      "fddddddddddddddd",
      "dhidghdhidghdhid",
      "dgjdjidgjdjidgjd",
      "dddddddddddddddd",
      "dghdhidghdhidghd",
      "djidgjdjidgjdjid",
      "dddddddddddddddd",
      "dhidghdhidghdhid",
      "dgjdjidgjdjidgjd",
      "dddddddddddddddd",
      "dghdhidghdhidghd",
      "djidgjdjidgjdjid",
      "dddddddddddddddd",
      "dhidghdhidghdhid"
    ]
  ]
}