{
  "name": "multi_nuclearpowerplant_39_ground",
  "refpalette": "deceasedcraft:multi_nuclearpowerplant_39/multi_nuclearpowerplant_39_ground_palette",
  "xsize": 16,
  "zsize": 16,
  "slices": [
    [
      " abccddedddddddd",
      " accdddedddddddd",
      " ccddddedddddddd",
      "ccdddddedddddddd",
      "cddddddedddddddd",
      "ddddddeddddddddd",
      "ddddddeddddddddd",
      "adddddeddddddddd",
      "adddddeddddddddd",
      "aedddedddddddddd",
      "bedddedddddddddd",
      "beddeddddddddddd",
      "effdeddddddddddd",
      "effdeddddddddddd",
      "effedddddddddddd",
      "fffedddddddddddd"
    ],
    [
      "   cczzzzzzzzzzz",
      "  cczzzzzzzzzzzz",
      " cczzzzzzzzzzzzz",
      "cczzzzzzzzzzzzzz",
      "czzzzzzzzzzzzzzz",
      "dzzzzzzzzzzzzzzz",
      "ddzzzzzzzzzzzzzz",
      "ddzzzzzzzzzzzzzz",
      "dddzzzzzzzzzzzzz",
      "dddzzzzzzzzzzzzz",
      "dddzzzzzzzzzzzzz",
      "ddddzzzzzzzfzzzz",
      "ddddzzzzzzzfzzzz",
      "ddddzzzzzzzzzzzz",
      "ddddzzzzzzzzzzzz",
      "ddddzzzzzzzzzzzz"
    ],
    [
      "   g   h   ijji ",
      "  gg     klmjjm ",
      " gg    h  nmjjm ",
      "ggh        mjjm ",
      "g  h  h    ijji ",
      "z h h      mmmm ",
      "zz   h   h      ",
      "zz z h hh   h  h",
      "zzz             ",
      "zzz  h          ",
      "zzzz    h h h  h",
      "zzzz    h    h  ",
      "zzzz h    h     ",
      "fzzz        h h ",
      "zfzzzh     h   n",
      "zzzz         h  "
    ],
    [
      "           op q ",
      "           rstu ",
      "          wxyyAB",
      "           uCCr ",
      "           D  E ",
      "           FIIJ ",
      "           KLLK ",
      "                ",
      " h              ",
      "h               ",
      "                ",
      "                ",
      "   h            ",
      "                ",
      "                ",
      "                "
    ],
    [
      "           M  M ",
      "           M  M ",
      "           N  O ",
      "          PQQQQR",
      "           STTB ",
      "            UV  ",
      "                ",
      "                ",
      "                ",
      "                ",
      "                ",
      "                ",
      "                ",
      "                ",
      "                ",
      "                "
    ],
    [
      "            UU  ",
      "           UurU ",
      "          WTssTX",
      "           UVUV ",
      "                ",
      "                ",
      "                ",
      "                ",
      "                ",
      "                ",
      "                ",
      "                ",
      "                ",
      "                ",
      "                ",
      "                "
    ]
  ]
}