{
  "name": "multi_nuclearpowerplant_39_base11",
  "refpalette": "deceasedcraft:multi_nuclearpowerplant_39/multi_nuclearpowerplant_39_base11_palette",
  "xsize": 16,
  "zsize": 16,
  "slices": [
    [
      "abcadbabcadbabca",
      "adeaecadeaecadea",
      "faaaaaaaaaaaaaaa",
      "adbabcadbabcadga",
      "aecadeaecadeaeca",
      "aaaaaaaaaaaaaaaa",
      "abcahhabcadbabca",
      "adeahhadeaecadea",
      "aaaaaaaaaaaaaaaa",
      "adbabcadbabcadba",
      "aecadeaecadeaeca",
      "aaaaaaaaaaaaaaaa",
      "abcadbabcadbabca",
      "adeaecadeaecadea",
      "aaaaaaaaaaaaaaaa",
      "adbabcadbabcadba"
    ],
    [
      "adbabcadbabcadba",
      "aecadeaecadeaeca",
      "faaaaaaaaaaaaaaa",
      "abcaaaabcaaaaaaa",
      "adeaaaadeaaaaaaa",
      "aaaaaaaaaaaaaaaa",
      "aaaaaiaaaaaaadba",
      "aaaaaaaaaaaaaeca",
      "aaaaaaaaaaaaaaaa",
      "aaaadbaaaaaaaaaa",
      "aaaaecaaaaaaaaaa",
      "aaaaaaaaaaaaaaaa",
      "aaaaaaadbaaaaaaa",
      "aaaaaaaecaaaaaaa",
      "aaaaaaaaaaaaaaaa",
      "aaaaaaaaaaaaaaaa"
    ],
    [
      "aaaaaaabcaaaaaaa",
      "aaaaaaadeaaaaaaa",
      "faaaaaaaaaaaaaaa",
      "aaaaaaaaaaaaaaaa",
      "aaaaaaaaaaaaaaaa",
      "aaaaaaaaaaaaaaaa",
      "aaaaaaaaaaaaaaaa",
      "aaaaaaaaaaaaaaaa",
      "aaaaaaaaaaaaaaaa",
      "aaaaaaaaaaaaaaaa",
      "aaaaaaaaaaaaaaaa",
      "aaaaaaaaaaaaaaaa",
      "aaaaaaaaaaaaaaaa",
      "aaaaaaaaaaaaaaaa",
      "aaaaaaaaaaaaaaaa",
      "aaaaaaaaaaaaaaaa"
    ],
    [
      "aaaaaaaaaaaaaaaa",
      "aaaaaaaaaaaaaaaa",
      "faaaaaaaaaaaaaaa",
      "aaaaaaaaaaaaaaaa",
      "aaaaaaaaaaaaaaaa",
      "aaaaaaaaaaaaaaaa",
      "aaaaaaaaaaaaaaaa",
      "aaaaaaaaaaaaaaaa",
      "aaaaaaaaaaaaaaaa",
      "aaaaaaaaaaaaaaaa",
      "aaaaaaaaaaaaaaaa",
      "aaaaaaaaaaaaaaaa",
      "aaaaaaaaaaaaaaaa",
      "aaaaaaaaaaaaaaaa",
      "aaaaaaaaaaaaaaaa",
      "aaaaaaaaaaaaaaaa"
    ],
    [
      "aaaaaaaaaaaaaaaa",
      "aaaaaaaaaaaaaaaa",
      "faaaaaaaaaaaaaaa",
      "aaaaaaaaaaaaaaaa",
      "aaaaaaaaaaaaaaaa",
      "aaaaaaaaaaaaaaaa",
      "aaaaaaaaaaaaaaaa",
      "aaaaaaaaaaaaaaaa",
      "aaaaaaaaaaaaaaaa",
      "aaaaaaaaaaaaaaaa",
      "aaaaaaaaaaaaaaaa",
      "aaaaaaaaaaaaaaaa",
      "aaaaaaaaaaaaaaaa",
      "aaaaaaaaaaaaaaaa",
      "aaaaaaaaaaaaaaaa",
      "aaaaaaaaaaaaaaaa"
    ],
    [
      "aaaaaaaaaaaaaaaa",
      "aaaaaaaaaaaaaaaa",
      "faaaaaaaaaaaaaaa",
      "aaaaaaaaaaaaaaaa",
      "aaaaaaaaaaaaaaaa",
      "aaaaaaaaaaaaaaaa",
      "aaaaaaaaaaaaaaaa",
      "aaaaaaaaaaaaaaaa",
      "aaaaaaaaaaaaaaaa",
      "aaaaaaaaaaaaaaaa",
      "aaaaaaaaaaaaaaaa",
      "aaaaaaaaaaaaaaaa",
      "aaaaaaaaaaaaaaaa",
      "aaaaaaaaaaaaaaaa",
      "aaaaaaaaaaaaaaaa",
      "aaaaaaaaaaaaaaaa"
    ]
  ]
}