{
  "name": "multi_nuclearpowerplant_39_base8",
  "refpalette": "deceasedcraft:multi_nuclearpowerplant_39/multi_nuclearpowerplant_39_base8_palette",
  "xsize": 16,
  "zsize": 16,
  "slices": [
    [
      "                ",
      "                ",
      "                ",
      "                ",
      "                ",
      "                ",
      "           a a  ",
      "    a       b   ",
      "           a a  ",
      "                ",
      "                ",
      "                ",
      "                ",
      "                ",
      "                ",
      "                "
    ],
    [
      "cccccccccccccccc",
      "cccccccccccccccc",
      "cccccccccccccccc",
      "cccccccccccccccc",
      "cccccccccccccccc",
      "cccccccccccccccc",
      "cccccccccccccccc",
      "ccccccccccccdccc",
      "cccccccccccccccc",
      "cccccccccccccccc",
      "cccccccccccccccc",
      "cccccccccccccccc",
      "cccccccccccccccc",
      "cccccccccccccccc",
      "cccccccccccccccc",
      "cccccccccccccccc"
    ],
    [
      "eeeeeeeeeeefgfee",
      "eeeeeeeeeeefgfee",
      "eeeeeeeeeeefgfee",
      "eeeeeeeeeeefgfee",
      "eeeeeeeeeeefgfee",
      "eeeeeeeeeeefgfee",
      "eeeeeeeeeeefhfee",
      "eeeeeeeeeeefifee",
      "eeeeeeeeeeefhfee",
      "eeeeeeeeeeefgfee",
      "eeeeeeeeeeefgfee",
      "eeeeeeeeeeefgfee",
      "eeeeeeeeeeefgfee",
      "eeeeeeeeeeefgfee",
      "eeeeeeeeeeefgfee",
      "eeeeeeeeeeefgfee"
    ],
    [
      "eeeeeeeeeeeefeee",
      "eeeeeeeeeeeefeee",
      "eeeeeeeeeeeefeee",
      "eeeeeeeeeeeefeee",
      "eeeeeeeeeeeefeee",
      "eeeeeeeeeeeefeee",
      "eeeeeeeeeeeefeee",
      "eeeeeeeeeeeefeee",
      "eeeeeeeeeeeefeee",
      "eeeeeeeeeeeefeee",
      "eeeeeeeeeeeefeee",
      "eeeeeeeeeeeefeee",
      "eeeeeeeeeeeefeee",
      "eeeeeeeeeeeefeee",
      "eeeeeeeeeeeefeee",
      "eeeeeeeeeeeefeee"
    ],
    [
      "======jkllllllkm",
      "======jkllllllkm",
      "======jkllllllkm",
      "nonnnnokllllllkm",
      "kkkkkkkkllllllkk",
      "llllllllllllllll",
      "llllllllllllllpp",
      "llllllllllllpp==",
      "lllllllllllp====",
      "llllllllllp=====",
      "lllllllllp======",
      "llllllllp=======",
      "lllllllp========",
      "llllllp=========",
      "lllllp==========",
      "llllp==========="
    ],
    [
      "   aa q         ",
      "   aa q         ",
      "      q         ",
      " aqqqqa         ",
      "      r         ",
      "          s     ",
      "              ==",
      "            ==oo",
      "           =oooo",
      "         t=ooooo",
      "         =oooooo",
      "        =ooooooo",
      "       =oooooooo",
      "      =ooooooooo",
      "     =oooooooooo",
      "    =ooooooooooo"
    ]
  ]
}