{
  "name": "multi_nuclearpowerplant_39_base6",
  "refpalette": "deceasedcraft:multi_nuclearpowerplant_39/multi_nuclearpowerplant_39_base6_palette",
  "xsize": 16,
  "zsize": 16,
  "slices": [
    [
      "   aab cd e     ",
      "   aab cd e     ",
      "bbbbbf cd e     ",
      " g    gcd e     ",
      "ccccccccd       ",
      "ddddddddd       ",
      "hhhhhhhhhij   ==",
      "hhhhhhhhhkk ==ll",
      "hhhhhhhhhkk=ll  ",
      "hhhhhhhhhm=l    ",
      "hhhhhhhhh=l     ",
      "hhhhhhhh=l      ",
      "hhhhhhh=l      n",
      "hhhhhh=l      nn",
      "hhhhh=l      nno",
      "hhhh=l      nnoo"
    ],
    [
      "pppaab q        ",
      "pppaab q        ",
      "bbbbbf q        ",
      "rgs    q        ",
      "qqqqqqqq        ",
      "                ",
      "              ==",
      "          e ==ll",
      "          t=ll  ",
      "         m=l    ",
      "         =l     ",
      "        =l      ",
      "       =l      n",
      "      =l      nn",
      "     =l      nno",
      "    =l      nnoo"
    ],
    [
      "   aab u        ",
      "   aab u        ",
      "bbbbbf u        ",
      " g w   u        ",
      "xxxwwwwwwwwwwwww",
      "                ",
      "              ==",
      "            ==ll",
      "           =ll  ",
      "         y=l    ",
      "         =l     ",
      "        =l      ",
      "       =l      n",
      "      =l      nn",
      "     =l      nnA",
      "    =l      nnoA"
    ],
    [
      "   aab          ",
      "   aab          ",
      "bbbBbf          ",
      " gCoDEEEEEEEEEEE",
      "  Cooooooooooooo",
      "   FFFFFFFFFFFFF",
      "              ==",
      "            ==ll",
      "           =ll  ",
      "          =l    ",
      "         =l     ",
      "        =l      ",
      "       =l      n",
      "      =l      nn",
      "     =l      nno",
      "    =l      nnoo"
    ],
    [
      "bbbbbf          ",
      "bbbbbf          ",
      "ffffff          ",
      " g I            ",
      "   IIIIIIIIIIIII",
      "                ",
      "              ==",
      "            ==ll",
      "           =ll  ",
      "          =l    ",
      "         =l     ",
      "        =l      ",
      "       =l      n",
      "      =l      nn",
      "     =l      nno",
      "    =l      nnoo"
    ],
    [
      " J              ",
      "KJ              ",
      "glL             ",
      " g              ",
      "                ",
      "                ",
      "              ==",
      "            ==ll",
      "           =ll  ",
      "          =l    ",
      "         =l     ",
      "        =l      ",
      "       =l      n",
      "      =l      nn",
      "     =l      nno",
      "    =l      nnoo"
    ]
  ]
}