{
  "name": "multi_nuclearpowerplant_39_base3",
  "refpalette": "deceasedcraft:multi_nuclearpowerplant_39/multi_nuclearpowerplant_39_base3_palette",
  "xsize": 16,
  "zsize": 16,
  "slices": [
    [
      "aaaaab     cdddd",
      "aaaaab     cdddd",
      "aaaaab     cdddd",
      "aaaaab     cdddd",
      "aaaab      cdddd",
      "aaaab      cdddd",
      "aaaab      cdd==",
      "aaaab      c==ee",
      "aaab       =eeff",
      "aaab      =effff",
      "aab      =efffff",
      "aab     =effff  ",
      "aab    =effff   ",
      "ab    =effff    ",
      "ab   =effff     ",
      "b   =effff      "
    ],
    [
      "g    h     i  jk",
      "lm   h     i  nk",
      "l    h     i  nk",
      "l    h     i  jk",
      "o   h      i  =k",
      "p   h      i  =k",
      "    h      i ===",
      "    h      i==kk",
      "   h       =kkq ",
      "  rh      =k    ",
      "s h      =k   tt",
      "  h     =k   u  ",
      "  h    =kq  u   ",
      " h    =k   u    ",
      " h   =k   u     ",
      "h   =k   u      "
    ],
    [
      "w    h        jk",
      "x    h         y",
      "A    h         B",
      "     h        jk",
      "C   h         =k",
      "    h         =k",
      "   Dh        ===",
      "    h       ==kk",
      "   h       =kk  ",
      "  Eh      =k    ",
      "  h      =k     ",
      "  h     =k      ",
      "  h    =k       ",
      " h    =k        ",
      " h   =k         ",
      "h   =k          "
    ],
    [
      "     h        jk",
      "     h         F",
      "     h         I",
      "     h        jk",
      "    h        J=k",
      "    h         =k",
      "    h        ===",
      "    h       ==kk",
      "   h       =kk  ",
      "  Kh      =k    ",
      "  h      =k     ",
      "  h     =k      ",
      "  h    =k       ",
      " h    =k        ",
      " h   =k         ",
      "h   =k          "
    ],
    [
      "     h        jk",
      "     h        jL",
      "     h        jL",
      "     h        jk",
      "    h         =k",
      "    h         =k",
      "    h        ===",
      "    h       ==kk",
      "   h       =kk  ",
      "   h      =k    ",
      "  h      =k     ",
      "  h     =k      ",
      "  h    =k       ",
      " h    =k        ",
      " h   =k         ",
      "h   =k          "
    ],
    [
      "     h        =k",
      "     h        =k",
      "     h        =k",
      "     h        =k",
      "    h         =k",
      "    h         =k",
      "    h        ===",
      "    h       ==kk",
      "   h       =kk  ",
      "   h      =k    ",
      "  h      =k     ",
      "  h     =k      ",
      "  h    =k       ",
      " h    =k        ",
      " h   =k         ",
      "h   =k          "
    ]
  ]
}