{
  "name": "multi_nuclearpowerplant_39_base5",
  "refpalette": "deceasedcraft:multi_nuclearpowerplant_39/multi_nuclearpowerplant_39_base5_palette",
  "xsize": 16,
  "zsize": 16,
  "slices": [
    [
      "ab              ",
      "cb              ",
      "db              ",
      " b              ",
      "                ",
      "                ",
      "              ==",
      "            ==ee",
      "           =ee  ",
      "          =e    ",
      "         =e     ",
      "        =e      ",
      "       =e      f",
      "      =e      ff",
      "     =e      ffg",
      "    =e      ffgg"
    ],
    [
      "                ",
      "h               ",
      "                ",
      "                ",
      "                ",
      "                ",
      "              ==",
      "            ==ee",
      "           =ee  ",
      "          =e    ",
      "         =e     ",
      "        =e      ",
      "       =e      f",
      "      =e      ff",
      "     =e      ffg",
      "    =e      ffgg"
    ],
    [
      "                ",
      "                ",
      "                ",
      "                ",
      "                ",
      "                ",
      "              ==",
      "            ==ee",
      "           =ee  ",
      "          =e    ",
      "         =e     ",
      "        =e      ",
      "       =e      f",
      "      =e      ff",
      "     =e      ffg",
      "    =e      ffgg"
    ],
    [
      "                ",
      "                ",
      "                ",
      "                ",
      "                ",
      "                ",
      "              ==",
      "            ==ee",
      "           =ee  ",
      "          =e    ",
      "         =e     ",
      "        =e      ",
      "       =e      f",
      "      =e      ff",
      "     =e      ffg",
      "    =e      ffgg"
    ],
    [
      "                ",
      "                ",
      "                ",
      "                ",
      "                ",
      "                ",
      "              ==",
      "            ==ee",
      "           =ee  ",
      "          =e    ",
      "         =e     ",
      "        =e      ",
      "       =e      f",
      "      =e      ff",
      "     =e      ffg",
      "    =e      ffgg"
    ],
    [
      "                ",
      "                ",
      "                ",
      "                ",
      "                ",
      "                ",
      "              ==",
      "            ==ee",
      "           =ee  ",
      "          =e    ",
      "         =e     ",
      "        =e      ",
      "       =e      f",
      "      =e      ff",
      "     =e      ffg",
      "    =e      ffgg"
    ]
  ]
}