{
  "name": "multi_nuclearpowerplant_39_base1",
  "refpalette": "deceasedcraft:multi_nuclearpowerplant_39/multi_nuclearpowerplant_39_base1_palette",
  "xsize": 16,
  "zsize": 16,
  "slices": [
    [
      "aaaaaaabb  c    ",
      "aaaaaaabb  deef ",
      "aaaaaaabb       ",
      "aaaaaaabb    g  ",
      "aaaaaaabbhhhhhhh",
      "aaaaaaibbjklkkmm",
      "aaaaaaibbnoponqr",
      "aaaaaaibbbbbbbbb",
      "aaaaaaisssssssss",
      "aaaaaisssssssss=",
      "aaaaaisssssss===",
      "aaaaisssssss====",
      "aaaaissssss=====",
      "aaaaisssss======",
      "aaaisssss=======",
      "aaaissss========"
    ],
    [
      "aaaaaaabb       ",
      "aaaaaaabbt  uwx ",
      "aaaaaaabb       ",
      "aaaaaaabby      ",
      "aaaaaaabb       ",
      "aaaaaaibb   AB C",
      "aaaaaaibbnDEDnFI",
      "aaaaaaibbbbbbbbb",
      "aaaaaaisssssssss",
      "aaaaaissssssssss",
      "aaaaaissssssssss",
      "aaaaisssssssssss",
      "aaaaisssssssssss",
      "aaaaisssssssssss",
      "aaaissssssssssss",
      "aaaissssssssssss"
    ],
    [
      "aaaaaaabb       ",
      "aaaaaaabb       ",
      "aaaaaaabb       ",
      "aaaaaaabby      ",
      "aaaaaaabb       ",
      "aaaaaaibbJ   K L",
      "aaaaaaibbnMNOnNI",
      "aaaaaaibbbbbbbbb",
      "aaaaaaisssssssss",
      "aaaaaissssssssss",
      "aaaaaissssssssss",
      "aaaaisssssssssss",
      "aaaaisssssssssss",
      "aaaaisssssssssss",
      "aaaissssssssssss",
      "aaaissssssssssss"
    ],
    [
      "aaaaaaabb       ",
      "aaaaaaabb       ",
      "aaaaaaabb       ",
      "aaaaaaabb       ",
      "aaaaaaabb       ",
      "aaaaaaibbPQPPPQP",
      "aaaaaaibbnnnnnnn",
      "aaaaaaibbbbbbbbb",
      "aaaaaaisssssssss",
      "aaaaaissssssssss",
      "aaaaaissssssssss",
      "aaaaisssssssssss",
      "aaaaisssssssssss",
      "aaaaisssssssssss",
      "aaaissssssssssss",
      "aaaissssssssssss"
    ],
    [
      "aaaaaaabb       ",
      "aaaaaaabb       ",
      "aaaaaaabb       ",
      "aaaaaaabb       ",
      "aaaaaaabb       ",
      "aaaaaaibbRRRRRRR",
      "aaaaaaibbSSSSSSS",
      "aaaaaaibbbbbbbbb",
      "aaaaaaisssssssss",
      "aaaaaissssssssss",
      "aaaaaissssssssss",
      "aaaaisssssssssss",
      "aaaaisssssssssss",
      "aaaaisssssssssss",
      "aaaissssssssssss",
      "aaaissssssssssss"
    ],
    [
      "iaaaaaabbTTUTTUT",
      "iaaaaaabbTTUTTUT",
      "iaaaaaabbTTUTTUT",
      "iaaaaaabbTTUTTUT",
      "iaaaaaabbTTTTTTT",
      "iaaaaaibbTTTTTTT",
      "aaaaaaibbVWWWWWW",
      "aaaaaaibbbbbbbbb",
      "aaaaaaisssssssss",
      "aaaaaissssssssss",
      "aaaaaissssssssss",
      "aaaaisssssssssss",
      "aaaaisssssssssss",
      "aaaaisssssssssss",
      "aaaissssssssssss",
      "aaaissssssssssss"
    ]
  ]
}