{
  "name": "multi_sunkenmonumentpark_13_base1",
  "refpalette": "deceasedcraft:multi_sunkenmonumentpark_13/multi_sunkenmonumentpark_13_base1_palette",
  "xsize": 16,
  "zsize": 16,
  "slices": [
    [
      "aaaaaaaaaaaaaaav",
      "aaaaaaaaaaaaaaav",
      "aaaaaaaaaaaaaaav",
      "aaaaaaaaaaaaaaav",
      "aaaaaaaaaaaaaaav",
      "aaaaaaaaaaaaaaav",
      "aaaaaaaaaaaaaaav",
      "aaaaaaaaaaaaaaav",
      "aaaaaaaaaaaaaaav",
      "aaaaaaaaaaaaaaav",
      "aaaaaaaaaaaaaaav",
      "aaaaaaaaaaaaaaav",
      "aaaaaaaaaaaaaaav",
      "aaaaaaaaaaaaaaav",
      "aaaaaaaaaaaaaaav",
      "aaaaaaaaaaaaaaav"
    ],
    [
      "aaaaaaaaaaaaaaav",
      "aaaaaaaaaaaaaaav",
      "aaaaaaaaaaaaaaav",
      "aaaaaaaaaaaaaaav",
      "aaaaaaaaaaaaaaav",
      "aaaaaaaaaaaaaaav",
      "aaaaaaaaaaaaaaav",
      "aaaaaaaaaaaaaaav",
      "aaaaaaaaaaaaaaav",
      "aaaaaaaaaaaaaaav",
      "aaaaaaaaaaaaaaav",
      "aaaaaaaaaaaaaaav",
      "aaaaaaaaaaaaaaav",
      "aaaaaaaaaaaaaaav",
      "aaaaaaaaaaaaaaav",
      "aaaaaaaaaaaaaaav"
    ],
    [
      "aaaaaaaaaaaaaaav",
      "aaaaaaaaaaaaaaav",
      "aaaaaaaaaaaaaaav",
      "baaaaaaaaaaaaaav",
      "bbaaaaaaaaaaaaav",
      "bbaaaaaaaaaaaaav",
      "bbaaaaaaaaaaaaav",
      "bbbaaaaaaaaaaaav",
      "bbbaaaaaaaaaaaav",
      "bbbaaaaaaaaaaaav",
      "bbbaaaaaaaaaaaav",
      "bbbaaaaaaaaaaaav",
      "bbbaaaaaaaaaaaav",
      "bbbaaaaaaaaaaaav",
      "cccaaaaaaaaaaaav",
      "cccaaaaaaaaaaaav"
    ],
    [
      "bbbbbaaaaaaaaaav",
      "bbbbbaaaaaaaaaav",
      "bbbbbbaaaaaaaaav",
      "dbbbbbaaaaaaaaav",
      " dbbbbaaaaaaaaav",
      " dbbbbaaaaaaaaav",
      " dbbbbaaaaaaaaav",
      "  dbbbaaaaaaaaav",
      " edbbbaaaaaaaaav",
      "e dbbbaaaaaaaaav",
      "  dbbbaaaaaaaaav",
      "  dbbbaaaafffffv",
      "  dbbbaaaafffffv",
      "  dbbbaaaafffffv",
      " ghcccaaaafffffv",
      " ghcccaaaafffffv"
    ],
    [
      "    dbbbb      v",
      "  i dbbbb      v",
      "     dbbb      v",
      "   j dbbb      v",
      "    edbbb      v",
      "   e dbbb      v",
      "   e dbbb      v",
      "   i dbbb      v",
      "     dbbb      v",
      "   e dbbb      v",
      "     dbbb      v",
      "     dbbbffffffv",
      "     dbbbffffffv",
      "     dbbbffffffv",
      "    ghcccffffffv",
      "    ghcccffffffv"
    ],
    [
      "      i dbbb   v",
      "  k     dbbb   v",
      "      i dbbb   v",
      "   l    dbbb   v",
      "        dbbb   v",
      "      i dbbb   v",
      "        dbbb   v",
      "   k  i dbbb   v",
      "       idbbb   v",
      "        dbbb   v",
      "       edbbb   v",
      "       mfffffffv",
      "       nfffffffv",
      "        fffffffv",
      "       ghcccfffv",
      "       ghcccfffv"
    ]
  ]
}