{
  "name": "multi_sunkenmonumentpark_13_ground",
  "refpalette": "deceasedcraft:multi_sunkenmonumentpark_13/multi_sunkenmonumentpark_13_ground_palette",
  "xsize": 16,
  "zsize": 16,
  "slices": [
    [
      "      a    bccdd",
      "  e      f bccdd",
      "      a    bccdd",
      "   a     f bccdd",
      "           bccdd",
      "      a    bccdd",
      "           bccdd",
      "   e  a  f bccdd",
      "       a   bccdd",
      "           bccdd",
      "    ghd    bcddd",
      "    ggdddddddddd",
      "     gdddddiiiii",
      "     ghddddiiiii",
      "          jkllll",
      "          jkllll"
    ],
    [
      "      e         ",
      "  e      a  fm  ",
      "      e         ",
      "   e     a  n   ",
      "             f  ",
      "      e         ",
      "            n   ",
      "   e  e  a  f   ",
      "g      e     n  ",
      "gddd            ",
      "gdddddd         ",
      "gddddiidddooo   ",
      "ggdddiiippp     ",
      "ggdddiiippp     ",
      "gg              ",
      "gg              "
    ],
    [
      "      e         ",
      "  q      e  ar  ",
      "      e         ",
      "   e     e      ",
      "             a  ",
      "      e         ",
      "                ",
      "   q  e  e  a   ",
      "d      e        ",
      "iddd            ",
      "iippoos         ",
      "iippp  ooo      ",
      "iippp           ",
      "iippp           ",
      "id              ",
      "id              "
    ],
    [
      "      e         ",
      "         e  ea  ",
      "      q         ",
      "   q     e      ",
      "             e  ",
      "      q         ",
      "                ",
      "      e  e  e   ",
      "s      q        ",
      " oos            ",
      "                ",
      "                ",
      "                ",
      "                ",
      "  t             ",
      " ut             "
    ],
    [
      "      q         ",
      "         q  ee  ",
      "                ",
      "         q      ",
      "             e  ",
      "                ",
      "                ",
      "      q     e   ",
      "                ",
      "                ",
      "                ",
      "                ",
      "                ",
      "                ",
      "                ",
      "                "
    ],
    [
      "                ",
      "             e  ",
      "                ",
      "                ",
      "             q  ",
      "                ",
      "                ",
      "            q   ",
      "                ",
      "                ",
      "                ",
      "                ",
      "                ",
      "                ",
      "                ",
      "                "
    ]
  ]
}