{
  "name": "building_residentialb_ground_270",
  "refpalette": "deceasedcraft:building_residentialb/building_residentialb_ground_palette_270",
  "xsize": 16,
  "zsize": 16,
  "slices": [
    [
      "aabaaaaaaaaaabaa",
      "abbaabbbbbbbbbba",
      "abffffffbbbbbbba",
      "abfeeeegcccccbba",
      "abfeeeegddddcbba",
      "bbfeeeegddddcbba",
      "abfeeeegddddcbba",
      "abfeeeegddddcbba",
      "abfeeeegeeeecbba",
      "abfeeeegeeeecbba",
      "abfeeeegeeeecbba",
      "abfeeeegeeeecbba",
      "bbfeeeegcccccbba",
      "bbffffffbbbbbbba",
      "abbbbbbbbbbbbbba",
      "abbbbbbbbbbbbbba"
    ],
    [
      "                ",
      "  M             ",
      "  tFBttthhhhhh  ",
      "  t     ccccch  ",
      "  t    u   ich  ",
      "  t    u   jch  ",
      "  t     r  kch  ",
      "  tIC      lch  ",
      "  t    mmmmmch  ",
      "  tJD  ws pnch  ",
      "  tEEy w   och  ",
      "  tK y   q !ch  ",
      "  tL A xccccch  ",
      "  tttttthhhhhh  ",
      "                ",
      " hhhhhhhhhhhhhh "
    ],
    [
      "                ",
      "                ",
      "  tZWtTt        ",
      "  t  U  ccccc   ",
      "  T     S  Nc   ",
      "  T     S  Oc   ",
      "  T     S   c   ",
      "  t        Pc   ",
      "  t    mmmmmc   ",
      "  t0X   w   c   ",
      "  tEEy  w  Qc   ",
      "  t  y     Rc   ",
      "  t  V  ccccc   ",
      "  tYYtTt        ",
      "                ",
      "                "
    ],
    [
      "                ",
      "                ",
      "  tTTtTt        ",
      "  t     c11cc   ",
      "  T         c   ",
      "  T         1   ",
      "  T         1   ",
      "  t         c   ",
      "  t    mmmmmc   ",
      "  t      w  1   ",
      "  tEEy   w  1   ",
      "  t  y      c   ",
      "  t  y  c11cc   ",
      "  tYYtTt        ",
      "                ",
      "                "
    ],
    [
      "                ",
      "                ",
      "  22222t222222  ",
      "  24444 ccccc2  ",
      "  24444     c2  ",
      "  24444     c2  ",
      "  24444  3  c2  ",
      "  24444     c2  ",
      "  24444mmmmmc2  ",
      "  24444   w c2  ",
      "  24444   w c2  ",
      "  24444     c2  ",
      "  24444 ccccc2  ",
      "  22222t222222  ",
      "                ",
      "                "
    ],
    [
      "                ",
      "                ",
      "  tttttttttttt  ",
      "  tm   geeeeet  ",
      "  tm   geeeeet  ",
      "  t^  wgeeeeet  ",
      "  t&  wgeeeeet  ",
      "  tm  5geeeeet  ",
      "  tm 96geeeeet  ",
      "  t^   g   wet  ",
      "  t& #7g   wet  ",
      "  tm   geeeeet  ",
      "  tm%$8geeeeet  ",
      "  tttttttttttt  ",
      "                ",
      "                "
    ]
  ]
}