{
  "name": "building_residentialb_ground_180",
  "refpalette": "deceasedcraft:building_residentialb/building_residentialb_ground_palette_180",
  "xsize": 16,
  "zsize": 16,
  "slices": [
    [
      "aabbaaaaaabaaaaa",
      "bbbbbbbbbbbbbbba",
      "bbffffffffffffbb",
      "bbfeeeeeeeeeefaa",
      "bbfeeeeeeeeeefaa",
      "bbfeeeeeeeeeefba",
      "bbfeeeeeeeeeefba",
      "bbfggggggggggfba",
      "bbbceeeeddddcbba",
      "bbbceeeeddddcbba",
      "bbbceeeeddddcbba",
      "bbbceeeeddddcbba",
      "bbbccccccccccbba",
      "bbbbbbbbbbbbbbbb",
      "bbbbbbbbbbbbbbba",
      "aaaaaaaaaaaaaaaa"
    ],
    [
      "                ",
      "h               ",
      "h ttttttttttttM ",
      "h tLKEJ I    F  ",
      "h t  ED C    B  ",
      "h tAyy       t  ",
      "h t          t  ",
      "h tx wwm  uu t  ",
      "h hc  sm r  ch  ",
      "h hcq  m    ch  ",
      "h hc  pm    ch  ",
      "h hc!onmlkjich  ",
      "h hcccccccccch  ",
      "h hhhhhhhhhhhh  ",
      "h               ",
      "                "
    ],
    [
      "                ",
      "                ",
      "  tttttttTTTtt  ",
      "  Y  E0      Z  ",
      "  Y  EX      W  ",
      "  tVyy      Ut  ",
      "  T          T  ",
      "  t    m     t  ",
      "   c wwm SSSc   ",
      "   c   m    c   ",
      "   c   m    c   ",
      "   cRQ mP ONc   ",
      "   cccccccccc   ",
      "                ",
      "                ",
      "                "
    ],
    [
      "                ",
      "                ",
      "  tttttttTTTtt  ",
      "  Y  E       T  ",
      "  Y  E       T  ",
      "  tyyy       t  ",
      "  T          T  ",
      "  t    m     t  ",
      "   c   m    c   ",
      "   1 wwm    1   ",
      "   1   m    1   ",
      "   c   m    c   ",
      "   cc11cc11cc   ",
      "                ",
      "                ",
      "                "
    ],
    [
      "                ",
      "                ",
      "  222222222222  ",
      "  244444444442  ",
      "  244444444442  ",
      "  244444444442  ",
      "  244444444442  ",
      "  t    m     t  ",
      "  2c   m    c2  ",
      "  2c   m 3  c2  ",
      "  2c wwm    c2  ",
      "  2c   m    c2  ",
      "  2cccccccccc2  ",
      "  222222222222  ",
      "                ",
      "                "
    ],
    [
      "                ",
      "                ",
      "  tttttttttttt  ",
      "  tmm&^mm&^mmt  ",
      "  t%         t  ",
      "  t$ # 9     t  ",
      "  t8 7 65ww  t  ",
      "  tggggggggggt  ",
      "  tee  eeeeeet  ",
      "  tee  eeeeeet  ",
      "  tee  eeeeeet  ",
      "  teewweeeeeet  ",
      "  teeeeeeeeeet  ",
      "  tttttttttttt  ",
      "                ",
      "                "
    ]
  ]
}