{
  "name": "building_residentialb_ground",
  "refpalette": "deceasedcraft:building_residentialb/building_residentialb_ground_palette",
  "xsize": 16,
  "zsize": 16,
  "slices": [
    [
      "aaaaaaaaaaaaaaaa",
      "abbbbbbbbbbbbbbb",
      "bbbbbbbbbbbbbbbb",
      "abbccccccccccbbb",
      "abbcddddeeeecbbb",
      "abbcddddeeeecbbb",
      "abbcddddeeeecbbb",
      "abbcddddeeeecbbb",
      "abfggggggggggfbb",
      "abfeeeeeeeeeefbb",
      "abfeeeeeeeeeefbb",
      "aafeeeeeeeeeefbb",
      "aafeeeeeeeeeefbb",
      "bbffffffffffffbb",
      "abbbbbbbbbbbbbbb",
      "aaaaabaaaaaabbaa"
    ],
    [
      "                ",
      "               h",
      "  hhhhhhhhhhhh h",
      "  hcccccccccch h",
      "  hcijklmno!ch h",
      "  hc    mp  ch h",
      "  hc    m  qch h",
      "  hc  r ms  ch h",
      "  t uu  mww xt h",
      "  t          t h",
      "  t       yyAt h",
      "  B    C DE  t h",
      "  F    I JEKLt h",
      " Mtttttttttttt h",
      "               h",
      "                "
    ],
    [
      "                ",
      "                ",
      "                ",
      "   cccccccccc   ",
      "   cNO Pm QRc   ",
      "   c    m   c   ",
      "   c    m   c   ",
      "   cSSS mww c   ",
      "  t     m    t  ",
      "  T          T  ",
      "  tU      yyVt  ",
      "  W      XE  Y  ",
      "  Z      0E  Y  ",
      "  ttTTTttttttt  ",
      "                ",
      "                "
    ],
    [
      "                ",
      "                ",
      "                ",
      "   cc11cc11cc   ",
      "   c    m   c   ",
      "   1    m   1   ",
      "   1    mww 1   ",
      "   c    m   c   ",
      "  t     m    t  ",
      "  T          T  ",
      "  t       yyyt  ",
      "  T       E  Y  ",
      "  T       E  Y  ",
      "  ttTTTttttttt  ",
      "                ",
      "                "
    ],
    [
      "                ",
      "                ",
      "  222222222222  ",
      "  2cccccccccc2  ",
      "  2c    m   c2  ",
      "  2c    mww c2  ",
      "  2c  3 m   c2  ",
      "  2c    m   c2  ",
      "  t     m    t  ",
      "  244444444442  ",
      "  244444444442  ",
      "  244444444442  ",
      "  244444444442  ",
      "  222222222222  ",
      "                ",
      "                "
    ],
    [
      "                ",
      "                ",
      "  tttttttttttt  ",
      "  teeeeeeeeeet  ",
      "  teeeeeewweet  ",
      "  teeeeee  eet  ",
      "  teeeeee  eet  ",
      "  teeeeee  eet  ",
      "  tggggggggggt  ",
      "  t  ww56 7 8t  ",
      "  t     9 # $t  ",
      "  t         %t  ",
      "  tmm^&mm^&mmt  ",
      "  tttttttttttt  ",
      "                ",
      "                "
    ]
  ]
}