{
  "name": "building_residentialb_ground_90",
  "refpalette": "deceasedcraft:building_residentialb/building_residentialb_ground_palette_90",
  "xsize": 16,
  "zsize": 16,
  "slices": [
    [
      "abbbbbbbbbbbbbba",
      "abbbbbbbbbbbbbba",
      "abbbbbbbffffffbb",
      "abbcccccgeeeefbb",
      "abbceeeegeeeefba",
      "abbceeeegeeeefba",
      "abbceeeegeeeefba",
      "abbceeeegeeeefba",
      "abbcddddgeeeefba",
      "abbcddddgeeeefba",
      "abbcddddgeeeefbb",
      "abbcddddgeeeefba",
      "abbcccccgeeeefba",
      "abbbbbbbffffffba",
      "abbbbbbbbbbaabba",
      "aabaaaaaaaaaabaa"
    ],
    [
      " hhhhhhhhhhhhhh ",
      "                ",
      "  hhhhhhtttttt  ",
      "  hcccccx A Lt  ",
      "  hc! q   y Kt  ",
      "  hco   w yEEt  ",
      "  hcnp sw  DJt  ",
      "  hcmmmmm    t  ",
      "  hcl      CIt  ",
      "  hck  r     t  ",
      "  hcj   u    t  ",
      "  hci   u    t  ",
      "  hccccc     t  ",
      "  hhhhhhtttBFt  ",
      "             M  ",
      "                "
    ],
    [
      "                ",
      "                ",
      "        tTtYYt  ",
      "   ccccc  V  t  ",
      "   cR     y  t  ",
      "   cQ  w  yEEt  ",
      "   c   w   X0t  ",
      "   cmmmmm    t  ",
      "   cP        t  ",
      "   c   S     T  ",
      "   cO  S     T  ",
      "   cN  S     T  ",
      "   ccccc  U  t  ",
      "        tTtWZt  ",
      "                ",
      "                "
    ],
    [
      "                ",
      "                ",
      "        tTtYYt  ",
      "   cc11c  y  t  ",
      "   c      y  t  ",
      "   1  w   yEEt  ",
      "   1  w      t  ",
      "   cmmmmm    t  ",
      "   c         t  ",
      "   1         T  ",
      "   1         T  ",
      "   c         T  ",
      "   cc11c     t  ",
      "        tTtTTt  ",
      "                ",
      "                "
    ],
    [
      "                ",
      "                ",
      "  222222t22222  ",
      "  2ccccc 44442  ",
      "  2c     44442  ",
      "  2c w   44442  ",
      "  2c w   44442  ",
      "  2cmmmmm44442  ",
      "  2c     44442  ",
      "  2c  3  44442  ",
      "  2c     44442  ",
      "  2c     44442  ",
      "  2ccccc 44442  ",
      "  222222t22222  ",
      "                ",
      "                "
    ],
    [
      "                ",
      "                ",
      "  tttttttttttt  ",
      "  teeeeeg8$%mt  ",
      "  teeeeeg   mt  ",
      "  tew   g7# &t  ",
      "  tew   g   ^t  ",
      "  teeeeeg69 mt  ",
      "  teeeeeg5  mt  ",
      "  teeeeegw  &t  ",
      "  teeeeegw  ^t  ",
      "  teeeeeg   mt  ",
      "  teeeeeg   mt  ",
      "  tttttttttttt  ",
      "                ",
      "                "
    ]
  ]
}