{
  "name": "building_residentialb_floor1_90",
  "refpalette": "deceasedcraft:building_residentialb/building_residentialb_floor1_palette_90",
  "xsize": 16,
  "zsize": 16,
  "slices": [
    [
      "                ",
      "                ",
      "  aaaaaaa       ",
      "  adiklmn  qr   ",
      "  a  j  n   r   ",
      "  a hhhhn       ",
      "  a ggggn       ",
      "  a     n   r   ",
      "  a     n   r   ",
      "  acccc p       ",
      "  acccc o       ",
      "  acffc n   r   ",
      "  abeeb n   r   ",
      "  aaaaaaa       ",
      "                ",
      "                "
    ],
    [
      "                ",
      "                ",
      "  astttsa       ",
      "  sdwxA n   r   ",
      "  t     n   r   ",
      "  t     n       ",
      "  t     n       ",
      "  t     n   r   ",
      "  t     n   r   ",
      "  t     C       ",
      "  t     B       ",
      "  t     n   r   ",
      "  su  y n   r   ",
      "  astttsa       ",
      "                ",
      "                "
    ],
    [
      "                ",
      "           FsIJ ",
      "  astttsa  FsIJ ",
      "  sD    n  FsIJ ",
      "  t     n  FsIJ ",
      "  t     n  FsIJ ",
      "  t     n  FsIJ ",
      "  t     n  FsIJ ",
      "  t     n  FsIJ ",
      "  t     E  FsIJ ",
      "  t     E  FsIJ ",
      "  t     n  FsIJ ",
      "  s     n  FsIJ ",
      "  astttsa  FsIJ ",
      "           FsIJ ",
      "                "
    ],
    [
      "                ",
      "        FsIJ    ",
      "  aaaaaaasIJ    ",
      "  a     ssIJ    ",
      "  a     ssIJ    ",
      "  a     ssIJ    ",
      "  a     ssIJ    ",
      "  a     ssIJ    ",
      "  a     ssIJ    ",
      "  a     ssIJ    ",
      "  a     ssIJ    ",
      "  a     ssIJ    ",
      "  a     ssIJ    ",
      "  aaaaaaasIJ    ",
      "        FsIJ    ",
      "                "
    ],
    [
      "                ",
      "     FsIJ       ",
      "  rr FsIJ       ",
      "     FsIJ       ",
      "     FsIJ       ",
      "  r LFsIJ       ",
      "  r  FsIJ       ",
      "     FsIJ       ",
      "     FsIJ       ",
      "  r  FsIJ       ",
      "  r KFsIJ       ",
      "     FsIJ       ",
      "     FsIJ       ",
      "  rr FsIJ       ",
      "     FsIJ       ",
      "                "
    ],
    [
      "                ",
      "  FsIJ          ",
      "  ssIJ          ",
      "  FsIJ          ",
      "  FsIJ          ",
      "  ssIJ          ",
      "  ssIJ          ",
      "  FsIJ          ",
      "  FsIJ ~        ",
      "  ssIJ          ",
      "  ssIJ          ",
      "  FsIJ          ",
      "  FsIJ          ",
      "  ssIJ          ",
      "  FsIJ          ",
      "                "
    ]
  ]
}