{
  "name": "building_residentialb_floor1_180",
  "refpalette": "deceasedcraft:building_residentialb/building_residentialb_floor1_palette_180",
  "xsize": 16,
  "zsize": 16,
  "slices": [
    [
      "                ",
      "                ",
      "                ",
      "   rr  rr  rr   ",
      "   q            ",
      "                ",
      "                ",
      "  annnnnnponna  ",
      "  am hg      a  ",
      "  al hg  cccba  ",
      "  akjhg  ccfea  ",
      "  ai hg  ccfea  ",
      "  ad     cccba  ",
      "  aaaaaaaaaaaa  ",
      "                ",
      "                "
    ],
    [
      "                ",
      "                ",
      "                ",
      "   rr  rr  rr   ",
      "                ",
      "                ",
      "                ",
      "  annnnnnCBnna  ",
      "  s          s  ",
      "  tA        yt  ",
      "  tx         t  ",
      "  tw         t  ",
      "  sd        us  ",
      "  asttttttttsa  ",
      "                ",
      "                "
    ],
    [
      "                ",
      " JJJJJJJJJJJJJJ ",
      " IIIIIIIIIIIIII ",
      " ssssssssssssss ",
      " FFFFFFFFFFFFFF ",
      "                ",
      "                ",
      "  annnnnnEEnna  ",
      "  s          s  ",
      "  t          t  ",
      "  t          t  ",
      "  t          t  ",
      "  sD         s  ",
      "  asttttttttsa  ",
      "                ",
      "                "
    ],
    [
      "                ",
      "                ",
      "                ",
      "                ",
      " JJJJJJJJJJJJJJ ",
      " IIIIIIIIIIIIII ",
      " ssssssssssssss ",
      " FassssssssssaF ",
      "  a          a  ",
      "  a          a  ",
      "  a          a  ",
      "  a          a  ",
      "  a          a  ",
      "  aaaaaaaaaaaa  ",
      "                ",
      "                "
    ],
    [
      "                ",
      "                ",
      "                ",
      "                ",
      "                ",
      "                ",
      "                ",
      " JJJJJJJJJJJJJJ ",
      " IIIIIIIIIIIIII ",
      " ssssssssssssss ",
      " FFFFFFFFFFFFFF ",
      "     L    K     ",
      "  r          r  ",
      "  r  rr  rr  r  ",
      "                ",
      "                "
    ],
    [
      "                ",
      "                ",
      "                ",
      "                ",
      "                ",
      "                ",
      "                ",
      "                ",
      "        ~       ",
      "                ",
      " JJJJJJJJJJJJJJ ",
      " IIIIIIIIIIIIII ",
      " ssssssssssssss ",
      " FsFFssFFssFFsF ",
      "                ",
      "                "
    ]
  ]
}