{
  "name": "building_residentialb_floor1_270",
  "refpalette": "deceasedcraft:building_residentialb/building_residentialb_floor1_palette_270",
  "xsize": 16,
  "zsize": 16,
  "slices": [
    [
      "                ",
      "                ",
      "       aaaaaaa  ",
      "   r   n beeba  ",
      "   r   n cffca  ",
      "       o cccca  ",
      "       p cccca  ",
      "   r   n     a  ",
      "   r   n     a  ",
      "       ngggg a  ",
      "       nhhhh a  ",
      "   r   n  j  a  ",
      "   rq  nmlkida  ",
      "       aaaaaaa  ",
      "                ",
      "                "
    ],
    [
      "                ",
      "                ",
      "       astttsa  ",
      "   r   n y  us  ",
      "   r   n     t  ",
      "       B     t  ",
      "       C     t  ",
      "   r   n     t  ",
      "   r   n     t  ",
      "       n     t  ",
      "       n     t  ",
      "   r   n     t  ",
      "   r   n Axwds  ",
      "       astttsa  ",
      "                ",
      "                "
    ],
    [
      "                ",
      " JIsF           ",
      " JIsF  astttsa  ",
      " JIsF  n     s  ",
      " JIsF  n     t  ",
      " JIsF  E     t  ",
      " JIsF  E     t  ",
      " JIsF  n     t  ",
      " JIsF  n     t  ",
      " JIsF  n     t  ",
      " JIsF  n     t  ",
      " JIsF  n     t  ",
      " JIsF  n    Ds  ",
      " JIsF  astttsa  ",
      " JIsF           ",
      "                "
    ],
    [
      "                ",
      "    JIsF        ",
      "    JIsaaaaaaa  ",
      "    JIss     a  ",
      "    JIss     a  ",
      "    JIss     a  ",
      "    JIss     a  ",
      "    JIss     a  ",
      "    JIss     a  ",
      "    JIss     a  ",
      "    JIss     a  ",
      "    JIss     a  ",
      "    JIss     a  ",
      "    JIsaaaaaaa  ",
      "    JIsF        ",
      "                "
    ],
    [
      "                ",
      "       JIsF     ",
      "       JIsF rr  ",
      "       JIsF     ",
      "       JIsF     ",
      "       JIsFK r  ",
      "       JIsF  r  ",
      "       JIsF     ",
      "       JIsF     ",
      "       JIsF  r  ",
      "       JIsFL r  ",
      "       JIsF     ",
      "       JIsF     ",
      "       JIsF rr  ",
      "       JIsF     ",
      "                "
    ],
    [
      "                ",
      "          JIsF  ",
      "          JIss  ",
      "          JIsF  ",
      "          JIsF  ",
      "          JIss  ",
      "          JIss  ",
      "        ~ JIsF  ",
      "          JIsF  ",
      "          JIss  ",
      "          JIss  ",
      "          JIsF  ",
      "          JIsF  ",
      "          JIss  ",
      "          JIsF  ",
      "                "
    ]
  ]
}