{
  "name": "building_residentialb_floor1",
  "refpalette": "deceasedcraft:building_residentialb/building_residentialb_floor1_palette",
  "xsize": 16,
  "zsize": 16,
  "slices": [
    [
      "                ",
      "                ",
      "  aaaaaaaaaaaa  ",
      "  abccc     da  ",
      "  aefcc  gh ia  ",
      "  aefcc  ghjka  ",
      "  abccc  gh la  ",
      "  a      gh ma  ",
      "  annopnnnnnna  ",
      "                ",
      "                ",
      "            q   ",
      "   rr  rr  rr   ",
      "                ",
      "                ",
      "                "
    ],
    [
      "                ",
      "                ",
      "  asttttttttsa  ",
      "  su        ds  ",
      "  t         wt  ",
      "  t         xt  ",
      "  ty        At  ",
      "  s          s  ",
      "  annBCnnnnnna  ",
      "                ",
      "                ",
      "                ",
      "   rr  rr  rr   ",
      "                ",
      "                ",
      "                "
    ],
    [
      "                ",
      "                ",
      "  asttttttttsa  ",
      "  s         Ds  ",
      "  t          t  ",
      "  t          t  ",
      "  t          t  ",
      "  s          s  ",
      "  annEEnnnnnna  ",
      "                ",
      "                ",
      " FFFFFFFFFFFFFF ",
      " ssssssssssssss ",
      " IIIIIIIIIIIIII ",
      " JJJJJJJJJJJJJJ ",
      "                "
    ],
    [
      "                ",
      "                ",
      "  aaaaaaaaaaaa  ",
      "  a          a  ",
      "  a          a  ",
      "  a          a  ",
      "  a          a  ",
      "  a          a  ",
      " FassssssssssaF ",
      " ssssssssssssss ",
      " IIIIIIIIIIIIII ",
      " JJJJJJJJJJJJJJ ",
      "                ",
      "                ",
      "                ",
      "                "
    ],
    [
      "                ",
      "                ",
      "  r  rr  rr  r  ",
      "  r          r  ",
      "     K    L     ",
      " FFFFFFFFFFFFFF ",
      " ssssssssssssss ",
      " IIIIIIIIIIIIII ",
      " JJJJJJJJJJJJJJ ",
      "                ",
      "                ",
      "                ",
      "                ",
      "                ",
      "                ",
      "                "
    ],
    [
      "                ",
      "                ",
      " FsFFssFFssFFsF ",
      " ssssssssssssss ",
      " IIIIIIIIIIIIII ",
      " JJJJJJJJJJJJJJ ",
      "                ",
      "       ~        ",
      "                ",
      "                ",
      "                ",
      "                ",
      "                ",
      "                ",
      "                ",
      "                "
    ]
  ]
}