{
  "name": "multi_verticalschool_12_floor9",
  "refpalette": "deceasedcraft:multi_verticalschool_12/multi_verticalschool_12_floor9_palette",
  "xsize": 16,
  "zsize": 16,
  "slices": [
    [
      "aaab c      ddde",
      "  aaaaaaab c  fe",
      "        aaaaaafe",
      "              fe",
      "              fe",
      "             gfe",
      "             hfe",
      "             ife",
      "              fe",
      "              fe",
      "           j  fe",
      "           j  fe",
      "           jklfe",
      "           j  fe",
      "           j  fe",
      "           jddde"
    ],
    [
      "aaab c      ddde",
      "  aaaaaaab c  fe",
      "        aaaaaafe",
      "              fe",
      "              fe",
      "             mfe",
      "             hfe",
      "             nfe",
      "              fe",
      "              fe",
      "           j  fe",
      "           j  fe",
      "           jopfe",
      "           j  fe",
      "           j  fe",
      "           jddde"
    ],
    [
      "aaab c      ddde",
      "  aaaaaaab c  fe",
      "        aaaaaafe",
      "              fe",
      "              fe",
      "              fe",
      "             qfe",
      "              fe",
      "              fe",
      "              fe",
      "           j  fe",
      "           j  fe",
      "           j  fe",
      "           j  fe",
      "           j  fe",
      "           jddde"
    ],
    [
      "aaab c      ddde",
      "  aaaaaaab c  fe",
      "        aaaaaafe",
      "              fe",
      "              fe",
      "              fe",
      "              fe",
      "              fe",
      "              fe",
      "              fe",
      "              fe",
      "              fe",
      "              fe",
      "              fe",
      "              fe",
      "            ddde"
    ],
    [
      "aaab c      ddde",
      "  aaaaaaab c  fe",
      "        aaaaaafe",
      "              fe",
      "              fe",
      "              fe",
      "              fe",
      "              fe",
      "              fe",
      "              fe",
      "              fe",
      "              fe",
      "              fe",
      "              fe",
      "              fe",
      "            ddde"
    ],
    [
      "aaab c     rddde",
      "  aaaaaaab c  fe",
      "        stttttfe",
      "        uuuuuufe",
      "        uuuuuufe",
      "        uuuuuufe",
      "        uuuuuufe",
      "        uuuuuufe",
      "        uuuuuufe",
      "        uuuuuufe",
      "        uuuuuufe",
      "        uuuuuufe",
      "        uuuuuufe",
      "        uuuuuufe",
      "        uuuuuufe",
      "        uuuuddde"
    ]
  ]
}