{
  "name": "multi_verticalschool_12_floor30",
  "refpalette": "deceasedcraft:multi_verticalschool_12/multi_verticalschool_12_floor30_palette",
  "xsize": 16,
  "zsize": 16,
  "slices": [
    [
      "aaaaabbbbbbbcccd",
      "aaaabeeeeeeefffd",
      "aaaabeeeeeeefffd",
      "bbbbbeeeeeebfffd",
      "ddddbeeeeeeefffd",
      "ddddbbbbbbbbfffd",
      "fffffffffffffffd",
      "fffffffffffffffd",
      "fffffffffffffffd",
      "fffffffffffffffd",
      "ddddbbbbbbbbfffd",
      "ddddbeeeeeeefffd",
      "bbbbbeeeeeebfffd",
      "aaaabeeeeeeefffd",
      "aaaabeeeeeeefffd",
      "aaaaabbbbbbbcccd"
    ],
    [
      "     bbbbbbbccc ",
      "@@@@b ghghgi    ",
      "jjjjb g g gi    ",
      "ffffbklklklb    ",
      "mnmnb      o    ",
      "    bbbbbbbb    ",
      "        pq      ",
      "                ",
      "                ",
      "                ",
      "    bbbbbbbb    ",
      "rmrrb      s    ",
      "ffffbtuwutub    ",
      "jjjjbxgyg gi    ",
      "@@@@b gAgAgi    ",
      "     bbbbbbbccc "
    ],
    [
      "BBBBBbbbbbbbccc ",
      "ffffbCg g g  D  ",
      "ffffbEg g g     ",
      "ffffbFlFlFlb    ",
      "I ! b      J    ",
      "    bbbbbbbb    ",
      "       p        ",
      "                ",
      "                ",
      "                ",
      "    bbbbbbbb    ",
      " K  b      L    ",
      "ffffbMuNuMub    ",
      "ffffb g g g     ",
      "ffffbOg g g  P  ",
      "BBBBBbbbbbbbccc "
    ],
    [
      "QQQQQbbbbbbbccc ",
      "RRRSbTg g gU    ",
      "ffffb g g gV    ",
      "ffffbllllllb    ",
      "WWWWb      X    ",
      "YYYYbbbbbbbb    ",
      "      p         ",
      "                ",
      "                ",
      "                ",
      "YYYYbbbbbbbb    ",
      "WWWWb      X    ",
      "ffffbuuuuuub    ",
      "ffffb g g gU    ",
      "ZZZ0b1g g gV    ",
      "qqqqqbbbbbbbccc "
    ],
    [
      "     bbbbbbbccc ",
      "    bffffffb    ",
      "    bffffffb    ",
      "RRRSbffffffb    ",
      "fffffffffffb    ",
      "bbbbbbbbbbbb    ",
      "    2p          ",
      "    2           ",
      "    2           ",
      "    2           ",
      "bbbbbbbbbbbb    ",
      "fffffffffffb    ",
      "ZZZ0bffffffb    ",
      "    bffffffb    ",
      "    bffffffb    ",
      "     bbbbbbbccc "
    ],
    [
      "     bbbbbbbccc ",
      "    b344443b    ",
      "    b 5    b    ",
      "    b    6 b    ",
      "     7   rrb    ",
      "bbbb bbbbbbb    ",
      "    8           ",
      "    9           ",
      "    9           ",
      "    9           ",
      "bbbb bbbbbbb    ",
      "     #   nnb    ",
      " !  b      b    ",
      "    b $ $  b    ",
      "    b3%%%%3b    ",
      "     bbbbbbbccc "
    ]
  ]
}