{
  "name": "multi_verticalschool_12_floor26",
  "refpalette": "deceasedcraft:multi_verticalschool_12/multi_verticalschool_12_floor26_palette",
  "xsize": 16,
  "zsize": 16,
  "slices": [
    [
      "aaaaaaaaaaaabbbc",
      "adddddddddddddac",
      "adddddddddddddac",
      "adddddddddddddac",
      "adddddddddddddac",
      "adddddddddddddac",
      "adddddddddddddac",
      "adddddddddddddac",
      "adddddddddddddac",
      "adddddddddddddac",
      "adddddddddddddac",
      "adddddddddddddac",
      "adddddddddddddac",
      "adddddddddddddac",
      "adddddddddddddac",
      "aaaaaaaaaaaabbbc"
    ],
    [
      "aaaaaaaaaaaabbbe",
      "a fgg!h gggifjae",
      "k             ae",
      "l             ae",
      "a   mn   mn   ae",
      "ao  pq  rpqs tae",
      "au rwxy Awx yBae",
      "aCDEwxy rwxy Fae",
      "au rwx yrwxy Iae",
      "aJ rwxy Dwxy Kae",
      "aL  MN   MN  Oae",
      "a   PQ   PQ   ae",
      "k    nnnnn    ae",
      "R   STUUUVW XYae",
      "aZ0    1   E22ae",
      "aaaaaaaaaaaabbbe"
    ],
    [
      "333333333333bbb ",
      "3  i4gi hiih  3 ",
      "5             3 ",
      "6             7 ",
      "3             7 ",
      "3   X     8   7 ",
      "7   9    #    7 ",
      "7   $E        3 ",
      "7   %    ^&   3 ",
      "7   *(    )   7 ",
      "3        +    7 ",
      "3             7 ",
      "5             7 ",
      "-     [ ]!    3 ",
      "3 {    }      3 ",
      "333333333333bbb "
    ],
    [
      "333333333333bbb ",
      "3             3 ",
      "7             3 ",
      "7             7 ",
      "3             7 ",
      "3             7 ",
      "7             7 ",
      "7             3 ",
      "7             3 ",
      "7             7 ",
      "3             7 ",
      "3             7 ",
      "7             7 ",
      "7             3 ",
      "3|            3 ",
      "333333333333bbb "
    ],
    [
      "333333333333bbb ",
      "3             3 ",
      "3             3 ",
      "3             3 ",
      "3             3 ",
      "3             3 ",
      "3             3 ",
      "3             3 ",
      "3             3 ",
      "3             3 ",
      "3             3 ",
      "3             3 ",
      "3             3 ",
      "3             3 ",
      "3;            3 ",
      "333333333333bbb "
    ],
    [
      "333333333333bbb:",
      "3'''''''''''''3:",
      "3'''''''''''''3:",
      "3''<<<'''<<<''3:",
      "3'''''''''''''3:",
      "3'''''''''''''3:",
      "3''<<<'''<><''3:",
      "3'''''''''''''3:",
      "3'''''''''''''3:",
      "3''<><'''<<<''3:",
      "3'''''''''''''3:",
      "3'''''''''''''3:",
      "3''<<<'''<<<''3:",
      "3'''''''''''''3:",
      "3'''''''''''''3:",
      "333333333333bbb:"
    ]
  ]
}