{
  "name": "multi_verticalschool_12_floor14",
  "refpalette": "deceasedcraft:multi_verticalschool_12/multi_verticalschool_12_floor14_palette",
  "xsize": 16,
  "zsize": 16,
  "slices": [
    [
      "            aaab",
      "            b c ",
      "            b   ",
      "            bd  ",
      "            be  ",
      "            be  ",
      "            bf  ",
      "            b   ",
      "            b   ",
      "            bd  ",
      "            be  ",
      "            be  ",
      "            bf  ",
      "            b   ",
      "            b c ",
      "gbbbbbbhgbbbaaab"
    ],
    [
      "            aaab",
      "            b   ",
      "            b   ",
      "            b   ",
      "            b   ",
      "            b   ",
      "            b   ",
      "            b   ",
      "            b   ",
      "            b   ",
      "            b   ",
      "            b   ",
      "            b   ",
      "            b   ",
      "            b   ",
      "bbbbbbbbbbbbaaab"
    ],
    [
      "            aaab",
      "            b   ",
      "            b   ",
      "            b   ",
      "            b   ",
      "            b   ",
      "            b   ",
      "            b   ",
      "            b   ",
      "            b   ",
      "            b   ",
      "            b   ",
      "            b   ",
      "            b   ",
      "            b   ",
      "bbbbbbbbbbbbaaab"
    ],
    [
      "            aaab",
      "            b   ",
      "            b   ",
      "            b   ",
      "            b   ",
      "            b   ",
      "            b   ",
      "            b   ",
      "            b   ",
      "            b   ",
      "            b   ",
      "            b   ",
      "            b   ",
      "            b   ",
      "            b   ",
      "bbbbbbbbbbbbaaab"
    ],
    [
      "            aaab",
      "            b ii",
      "            b ii",
      "            b ii",
      "            b ii",
      "            b ii",
      "            b ii",
      "            b ii",
      "            b ii",
      "            b ii",
      "            b ii",
      "            b ii",
      "            b ii",
      "            b ii",
      "            b ii",
      "bbbbbbbbbbbbaaab"
    ],
    [
      "            aaab",
      "            b  j",
      "            b  j",
      "            b  j",
      "            b  j",
      "            bk j",
      "            b  j",
      "            b  j",
      "            b  j",
      "            b  j",
      "            bk j",
      "            b  j",
      "            b  j",
      "            b  j",
      "            b  j",
      "bbbbbbbbbbbbaaab"
    ]
  ]
}