{
  "name": "multi_verticalschool_12_ground",
  "refpalette": "deceasedcraft:multi_verticalschool_12/multi_verticalschool_12_ground_palette",
  "xsize": 16,
  "zsize": 16,
  "slices": [
    [
      "a          bcccd",
      "a            add",
      "a            add",
      "a            add",
      "a            add",
      "a            add",
      "eefggggggggheeee",
      "eefggggggggheeee",
      "eefggggggggheeee",
      "eefggggggggheeee",
      "a            add",
      "a            add",
      "a            add",
      "a            add",
      "a            add",
      "a          bcccd"
    ],
    [
      "i           ccc ",
      "i             i ",
      "i             i ",
      "i             i ",
      "i             i ",
      "i             i ",
      "jjjjjjjjjjjjjj  ",
      "                ",
      "                ",
      "kkkkkkkkkkkkkk  ",
      "i             i ",
      "i             i ",
      "i             i ",
      "i             i ",
      "i             i ",
      "i           ccc "
    ],
    [
      "            ccc ",
      "                ",
      "                ",
      "                ",
      "                ",
      "                ",
      "                ",
      "                ",
      "                ",
      "                ",
      "                ",
      "                ",
      "                ",
      "                ",
      "                ",
      "            ccc "
    ],
    [
      "            ccc ",
      "                ",
      "                ",
      "                ",
      "                ",
      "                ",
      "                ",
      "                ",
      "                ",
      "                ",
      "                ",
      "                ",
      "                ",
      "                ",
      "                ",
      "            ccc "
    ],
    [
      "            ccc ",
      "                ",
      "                ",
      "                ",
      "                ",
      "                ",
      "                ",
      "                ",
      "                ",
      "                ",
      "                ",
      "                ",
      "                ",
      "                ",
      "                ",
      "            ccc "
    ],
    [
      "            ccc ",
      "                ",
      "                ",
      "                ",
      "                ",
      "                ",
      "                ",
      "                ",
      "                ",
      "                ",
      "                ",
      "                ",
      "                ",
      "                ",
      "                ",
      "            ccc "
    ]
  ]
}