{
  "name": "multi_verticalschool_12_floor20",
  "refpalette": "deceasedcraft:multi_verticalschool_12/multi_verticalschool_12_floor20_palette",
  "xsize": 16,
  "zsize": 16,
  "slices": [
    [
      "    aaaaaaaabbb ",
      "    acdccc ccca ",
      "    e         e ",
      "    e         e ",
      "    a         a ",
      "    e         e ",
      "    e         e ",
      "    e         e ",
      "    e         e ",
      "    e         e ",
      "    e         e ",
      "    a         a ",
      "    e         e ",
      "    e         e ",
      "    af        a ",
      "    aaaaaaaabbb "
    ],
    [
      "    aaaaaaaabbb ",
      "    a         a ",
      "    a         a ",
      "    a         a ",
      "    a         a ",
      "    a         a ",
      "    a         a ",
      "    a         a ",
      "    a         a ",
      "    a         a ",
      "    a         a ",
      "    a         a ",
      "    a         a ",
      "    a         a ",
      "    ag        a ",
      "    aaaaaaaabbb "
    ],
    [
      "    aaaaaaaabbbh",
      "    aiiiiiiiiiah",
      "    aiiiiiiiiiah",
      "    aijiijiijiah",
      "    aiiiiiiiiiah",
      "    aiiiiiiiiiah",
      "    aijiijiijiah",
      "    aiiiiiiiiiah",
      "    aiiiiiiiiiah",
      "    aijiijiijiah",
      "    aiiiiiiiiiah",
      "    aiiiiiiiiiah",
      "    aikiijiijiah",
      "    aiiiiiiiiiah",
      "    aiiiiiiiiiah",
      "    aaaaaaaabbbh"
    ],
    [
      "  lmnnnnnnnnbbbo",
      "  lmnpppppppppno",
      "  lmnpppppppppno",
      "  lmnpppppppppno",
      "  lmnpppppppppno",
      "  lmnpppppppppno",
      "lllmnpppppppppno",
      "mmmmnpppppppppno",
      "mmmmnpppppppppno",
      "lllmnpppppppppno",
      "  lmnpppppppppno",
      "  lmnpppppppppno",
      "  lmnpppppppppno",
      "  lmnpppppppppno",
      "  lmnpppppppppno",
      "  lmnnnnnnnnbbbo"
    ],
    [
      "  q nnnnnnnnbbb ",
      "  q nrrsrrrrsrn ",
      "  q t         n ",
      "  q u         n ",
      "  q nw ww ww wn ",
      "  q nx yA yA xn ",
      "BB  n         n ",
      "    nw ww ww wn ",
      "    nx yA yA xn ",
      "CC  n         n ",
      "  q nw ww ww wn ",
      "  q nx yA yA xn ",
      "  q t         n ",
      "  q u    D    n ",
      "  q nEFIIIIIJJn ",
      "  q nnnnnnnnbbb "
    ],
    [
      "    aaaaaaaabbb ",
      "    arrrrsKsrra ",
      "    L         e ",
      "    M         e ",
      "    a         a ",
      "    e  N     Ne ",
      "    e         e ",
      "    e         e ",
      "    eN     N  e ",
      "    e         e ",
      "    e         e ",
      "    a  N  N   a ",
      "    L         e ",
      "    M         e ",
      "    a O  P    a ",
      "    aaaaaaaabbb "
    ]
  ]
}