{
  "name": "multi_verticalschool_12_floor7",
  "refpalette": "deceasedcraft:multi_verticalschool_12/multi_verticalschool_12_floor7_palette",
  "xsize": 16,
  "zsize": 16,
  "slices": [
    [
      "            aaa ",
      "                ",
      "                ",
      "                ",
      "                ",
      "                ",
      "                ",
      "                ",
      "                ",
      "                ",
      "                ",
      "                ",
      "                ",
      "                ",
      "                ",
      "            aaa "
    ],
    [
      "            aaa ",
      "                ",
      "                ",
      "                ",
      "                ",
      "                ",
      "                ",
      "                ",
      "                ",
      "                ",
      "                ",
      "                ",
      "                ",
      "                ",
      "                ",
      "            aaa "
    ],
    [
      "        bbbbaaab",
      "        bbbbbbbb",
      "        bbbbbbbb",
      "        bbbbbbbb",
      "        bbbbbbbb",
      "        bbbbbbbb",
      "        bbbbbbbb",
      "        bbbbbbbb",
      "        bbbbbbbb",
      "        bbbbbbbb",
      "        bbbbbbbb",
      "        bbbbbbbb",
      "        bbbbbbbb",
      "        bbbbbbbb",
      "        bbbbbbbb",
      "        bbbbaaab"
    ],
    [
      "      bcccccaaac",
      "      bccccccccc",
      "      bccccccccc",
      "      bccccccccc",
      "      bccccccccc",
      "      bccccccccc",
      "      bccccccccc",
      "      bccccccccc",
      "      bccccccccc",
      "      bccccccccc",
      "      bccccccccc",
      "      bccccccccc",
      "      bccccccccc",
      "      bccccccccc",
      "      bccccccccc",
      "      bcccccaaac"
    ],
    [
      "    bcccccccaaac",
      "    bcdddccccccc",
      "    bcddddddddcc",
      "    bcddddddddef",
      "    bcddddddddef",
      "    bcdddddgggcc",
      "    bcddddg  gcc",
      "    bcdddghijgcc",
      "    bcdddg   gcc",
      "    bcdddg   gcc",
      "    bcdddgk  gce",
      "    bcdddghijgce",
      "    bcdddg  kgce",
      "    bcdddg l gce",
      "    bcdddgkkkgcc",
      "    bcdddghiaaac"
    ],
    [
      "  bcccc    kaaac",
      "  bcdddmmn o  ec",
      "  bcddd mmmmmmec",
      "  bcddd       p ",
      "  bcddd       q ",
      "  bcddd    gggec",
      "  bcddd  rrgggec",
      "  bcddd  gggggec",
      "  bcddd  gggggef",
      "  bcdds  gggggec",
      "  bcddt  gggggu ",
      "  bcddt  gggggu ",
      "  bcddt  ggggguw",
      "  bcdd   ggxyguA",
      "  bcdd   gggggec",
      "  bcdds  gggaaac"
    ]
  ]
}