{
  "name": "multi_verticalschool_12_floor10",
  "refpalette": "deceasedcraft:multi_verticalschool_12/multi_verticalschool_12_floor10_palette",
  "xsize": 16,
  "zsize": 16,
  "slices": [
    [
      "aaab c     cddde",
      "  fggggggb c  he",
      "  iiiiiiib c  he",
      "  iiiiiiib c  he",
      "  iiiiiiib c  he",
      "  iiiiiiib c  he",
      "  iiiiiiib c  he",
      "  iiiiiiib c  he",
      "  iiiiiiib c  he",
      "  iiiiiiib c  he",
      "  iiiiiiib c  he",
      "  iiiiiiib c  he",
      "  iiiiiiib c  he",
      "  iiiiiiib c  he",
      "  iiiiiiib c  he",
      "  iiiiiiib cddde"
    ],
    [
      "gggb cj     ddde",
      "iiib c     c  he",
      "iiib c     j  he",
      "iiib c        he",
      "iiib c        he",
      "iiib c     c  he",
      "iiib c        he",
      "iiib c        he",
      "iiib c        he",
      "iiib c     c  he",
      "iiib c        he",
      "iiib c        he",
      "iiib cj       he",
      "iiib c     ceeee",
      "iiib c     eeeee",
      "iiib c     eddde"
    ],
    [
      "j   jcjj   jddde",
      "           cj he",
      "              he",
      " j            he",
      "              he",
      "     j     c  he",
      "    jc   j    he",
      "              he",
      "           j  he",
      "           cj he",
      "           kkkhe",
      "     j    kkkkhe",
      "     cj  kkkkkhe",
      "  j     kkkceeee",
      "        kkkellle",
      "        kkkeddde"
    ],
    [
      "mmmmmmmmmmmmdddm",
      "mmmmmmmmmmmmmmmm",
      "mmmmmmmmmmmmmmmm",
      "mmmmmmmmmmmmmmmm",
      "mmmmmmmmmmmmmmmm",
      "mmmmmmmmmmmmmmmm",
      "mmmmmmmmmmmmmmmm",
      "mmmmmmmmmmmmmmmm",
      "mmmmmmmmmmmmmmmm",
      "mmmmmmmmmmmmmmmm",
      "mmmmmmmmmmmeeeee",
      "mmmmmmmmmmeennne",
      "mmmmmmmmmennnnnn",
      "mmmmmmmmeennooon",
      "mmmmmmmmennpqrst",
      "mmmmmmmmennpdddt"
    ],
    [
      "            ddd ",
      "                ",
      "                ",
      "                ",
      "    uw          ",
      "                ",
      "    ux          ",
      "                ",
      "    yw          ",
      "                ",
      "                ",
      "                ",
      "            ABAC",
      "    y      B   C",
      "          B    D",
      "    E     B dddF"
    ],
    [
      "            ddd ",
      "                ",
      "                ",
      "                ",
      "                ",
      "                ",
      "                ",
      "                ",
      "                ",
      "                ",
      "                ",
      "             CDI",
      "             CDF",
      "             CDF",
      "             JK ",
      "            ddd "
    ]
  ]
}