{
  "name": "multi_verticalschool_12_floor11",
  "refpalette": "deceasedcraft:multi_verticalschool_12/multi_verticalschool_12_floor11_palette",
  "xsize": 16,
  "zsize": 16,
  "slices": [
    [
      "            aaa ",
      "             !  ",
      "                ",
      "                ",
      "                ",
      "                ",
      "                ",
      "                ",
      "                ",
      "                ",
      "             bb ",
      "           cde c",
      "          ffde  ",
      "          ffde  ",
      "             gg ",
      "            aaa "
    ],
    [
      "            aaa ",
      "                ",
      "                ",
      "                ",
      "                ",
      "                ",
      "                ",
      "                ",
      "                ",
      "                ",
      "            bb  ",
      "          bc   c",
      "         hee    ",
      "         cee    ",
      "         dddgg  ",
      "         fffaaa "
    ],
    [
      "            aaa ",
      "             i  ",
      "                ",
      "                ",
      "                ",
      "                ",
      "                ",
      "                ",
      "                ",
      "                ",
      "                ",
      "           c   c",
      "                ",
      "         c      ",
      "        h   j   ",
      "        heeeaaa "
    ],
    [
      "            aaa ",
      "                ",
      "                ",
      "                ",
      "                ",
      "                ",
      "                ",
      "                ",
      "                ",
      "                ",
      "                ",
      "           c   c",
      "                ",
      "         c      ",
      "                ",
      "        h   aaa "
    ],
    [
      "kkkkkkkkkkkkaaak",
      "kkkkkkkkkkkkkkkk",
      "kkkkkkkkkkkkkkkk",
      "kkkkkkkkkkkkkkkk",
      "kkkkkkkkkkkkkkkk",
      "kkkllllkkkkkkkkk",
      "kkklkklkkkkkkkkk",
      "kkkllllkkkkkkkkk",
      "kkkkkkkkkkkkkkkk",
      "kkkkkkkkkkkkkkkk",
      "kkkkkkkkkkk     ",
      "kkkkkkkkkk m   m",
      "kkkkkkkkk       ",
      "kkkkkkkk m      ",
      "kkkllllk        ",
      "kkklkklk    aaa "
    ],
    [
      "nooooonnnnpnaaap",
      "noooonnnnnnpqrpq",
      "noooonnnnpnpprpp",
      "oooonnnnnnpnprpp",
      "oooonnnnnnnpprpp",
      "oooossnnnsppnrpp",
      "oootssssnnssspss",
      "ootossssssnssssn",
      "otoossssssssssss",
      "tooonnssssssnsss",
      "oooosnnnnnnuuuuu",
      "oooonnnnnuuufffu",
      "oooonnnnnufffffd",
      "oooonnnnuufffffd",
      "oooonnnnu    w d",
      "oooonnnnu   aaad"
    ]
  ]
}