{
  "name": "multi_verticalschool_12_floor22",
  "refpalette": "deceasedcraft:multi_verticalschool_12/multi_verticalschool_12_floor22_palette",
  "xsize": 16,
  "zsize": 16,
  "slices": [
    [
      "            aaab",
      "             cdb",
      "             cdb",
      "             cdb",
      "             cdb",
      "             cdb",
      "             cdb",
      "             cdb",
      "             cdb",
      "             cdb",
      "             cdb",
      "             cdb",
      "             cdb",
      "             cdb",
      "             cdb",
      "            aaab"
    ],
    [
      "            aaab",
      "             efb",
      "             efb",
      "             efb",
      "             efb",
      "             efb",
      "             efb",
      "             efb",
      "             efb",
      "             efb",
      "             efb",
      "             efb",
      "             efb",
      "             efb",
      "             efb",
      "            aaab"
    ],
    [
      "           gaaah",
      "             iii",
      "             iii",
      "             iii",
      "             iii",
      "             iii",
      "             iii",
      "             iii",
      "             iii",
      "             iii",
      "             iii",
      "             iii",
      "             iii",
      "             iii",
      "             iii",
      "           gaaah"
    ],
    [
      "            aaaj",
      "             k  ",
      "             k l",
      "             k l",
      "             k  ",
      "             k  ",
      "             k  ",
      "             k m",
      "             k m",
      "             k  ",
      "             k  ",
      "             k  ",
      "             k l",
      "             k l",
      "             k  ",
      "            aaaj"
    ],
    [
      "            aaan",
      "                ",
      "                ",
      "                ",
      "                ",
      "                ",
      "                ",
      "                ",
      "                ",
      "                ",
      "                ",
      "                ",
      "                ",
      "                ",
      "                ",
      "            aaan"
    ],
    [
      "            aaao",
      "                ",
      "                ",
      "                ",
      "                ",
      "                ",
      "                ",
      "                ",
      "                ",
      "                ",
      "                ",
      "                ",
      "                ",
      "                ",
      "                ",
      "            aaao"
    ]
  ]
}