{
  "name": "multi_verticalschool_12_floor13",
  "refpalette": "deceasedcraft:multi_verticalschool_12/multi_verticalschool_12_floor13_palette",
  "xsize": 16,
  "zsize": 16,
  "slices": [
    [
      "            aaa ",
      "                ",
      "                ",
      "                ",
      "                ",
      "                ",
      "                ",
      "                ",
      "                ",
      "                ",
      "                ",
      "                ",
      "                ",
      "                ",
      "                ",
      "            aaa "
    ],
    [
      "            aaa ",
      "                ",
      "                ",
      "                ",
      "                ",
      "                ",
      "                ",
      "                ",
      "                ",
      "                ",
      "                ",
      "                ",
      "                ",
      "                ",
      "                ",
      "            aaa "
    ],
    [
      "bbbbbbbbbbbbaaab",
      "bbbbbbbbbbbbbbbb",
      "bbbbbbbbbbbbbbbb",
      "bbbbbbbbbbbbbbbb",
      "bbbbbbbbbbbbbbbb",
      "bbbbbbbbbbbbbbbb",
      "bbbbbbbbbbbbbbbb",
      "bbbbbbbbbbbbbbbb",
      "bbbbbbbbbbbbbbbb",
      "bbbbbbbbbbbbbbbb",
      "bbbbbbbbbbbbbbbb",
      "bbbbbbbbbbbbbbbb",
      "bbbbbbbbbbbbbbbb",
      "bbbbbbbbbbbbbbbb",
      "bbbbbbbbbbbbbbbb",
      "bbbbbbbbbbbbaaab"
    ],
    [
      "ccddddccccccaaae",
      "ccddddccccccefff",
      "ccddddccccccefff",
      "ccddddccccccefff",
      "ccddddccccccefff",
      "ccddddccccccefff",
      "ccddddccccccefff",
      "ccddddccccccefff",
      "ccddddccccccefff",
      "ccddddccccccefff",
      "ccddddccccccefff",
      "ccddddccccccefff",
      "ccddddccccccefff",
      "ccddddccccccefff",
      "ccddddccccccefff",
      "eeeeeeeeeeeeaaae"
    ],
    [
      "   g g    hhaaae",
      "            eijk",
      "    g     lmei  ",
      "   n     oooep  ",
      "  n n     qrest ",
      "   n        es  ",
      "          hheu  ",
      "    w       ei  ",
      "  w  w    lmei  ",
      "    w    oooep  ",
      "          qresx ",
      "   y        es  ",
      "  y y     hheu  ",
      "            ei A",
      "   y      lmeijB",
      "CeeeeeeDCeeeaaae"
    ],
    [
      "            aaae",
      "            e E ",
      "            eF  ",
      "         EEEe   ",
      "            eI  ",
      "            eJ  ",
      "            eK  ",
      "            e   ",
      "            e   ",
      "         EEEeL  ",
      "            eI  ",
      "            e   ",
      "            e   ",
      "            e   ",
      "            e E ",
      "MeeeeeeNMeeeaaae"
    ]
  ]
}