{
  "name": "multi_verticalschool_12_floor3",
  "refpalette": "deceasedcraft:multi_verticalschool_12/multi_verticalschool_12_floor3_palette",
  "xsize": 16,
  "zsize": 16,
  "slices": [
    [
      "   abbba   accca",
      "   aaaaa   aaaaa",
      "                ",
      "                ",
      "                ",
      "                ",
      "                ",
      "                ",
      "                ",
      "                ",
      "                ",
      "                ",
      "                ",
      "                ",
      "   aaaaa   aaaaa",
      "   abb!a   accca"
    ],
    [
      "            ccc ",
      "                ",
      "                ",
      "                ",
      "                ",
      "                ",
      "                ",
      "                ",
      "                ",
      "                ",
      "                ",
      "                ",
      "                ",
      "                ",
      "                ",
      "            ccc "
    ],
    [
      "            ccc ",
      "                ",
      "                ",
      "                ",
      "                ",
      "                ",
      "                ",
      "                ",
      "                ",
      "                ",
      "                ",
      "                ",
      "                ",
      "                ",
      "                ",
      "            ccc "
    ],
    [
      "            ccc ",
      "                ",
      "                ",
      "                ",
      "                ",
      "                ",
      "                ",
      "                ",
      "                ",
      "                ",
      "                ",
      "                ",
      "                ",
      "                ",
      "                ",
      "            ccc "
    ],
    [
      "dddedddedddeccce",
      "dddddddddddddddd",
      "dddddddddddddddd",
      "dddddddddddddddd",
      "dddddddddddddddd",
      "dddedddedddeddde",
      "dddddddddddddddd",
      "dddddddddddddddd",
      "dddddddddddddddd",
      "dddddddddddddddd",
      "dddedddedddeddde",
      "dddddddddddddddd",
      "dddddddddddddddd",
      "dddddddddddddddd",
      "dddddddddddddddd",
      "dddedddedddeccce"
    ],
    [
      "fffffggggggfcccf",
      "ffffffgggggfgfff",
      "fffffgggggggffff",
      "fffffgfggggfffff",
      "hfffgfgggggffiff",
      "hfffffggggfgfffg",
      "hfffffggggggfffg",
      "hffffgggggggffff",
      "hfffffgggggfggff",
      "hfffffgggggfffgf",
      "hffffgggggggffff",
      "hffffggggggfgiff",
      "ffffgfgggggfffff",
      "ffgfggggggggffff",
      "ffffggggggffffff",
      "fffggggggggfcccf"
    ]
  ]
}