{
  "name": "multi_verticalschool_12_floor19",
  "refpalette": "deceasedcraft:multi_verticalschool_12/multi_verticalschool_12_floor19_palette",
  "xsize": 16,
  "zsize": 16,
  "slices": [
    [
      "    aaaaaaaabbb ",
      "    accccccccca ",
      "    d         d ",
      "    d         d ",
      "    a         a ",
      "    d         d ",
      "    d         d ",
      "    d         d ",
      "    d         d ",
      "    d         d ",
      "    d         d ",
      "    a         a ",
      "    d         d ",
      "    d         d ",
      "    ae      fga ",
      "    aaaaaaaabbb "
    ],
    [
      "    aaaaaaaabbb ",
      "    a         a ",
      "    a         a ",
      "    a         a ",
      "    a         a ",
      "    a         a ",
      "    a         a ",
      "    a         a ",
      "    a         a ",
      "    a         a ",
      "    a         a ",
      "    a         a ",
      "    a         a ",
      "    a         a ",
      "    ah        a ",
      "    aaaaaaaabbb "
    ],
    [
      "    aaaaaaaabbbi",
      "    ajjjjjjjjjai",
      "    ajjjjjjjjjai",
      "    ajkjjkjjkjai",
      "    ajjjjjjjjjai",
      "    ajjjjjjjjjai",
      "    ajljjljjljai",
      "    ajjjjjjjjjai",
      "    ajjjjjjjjjai",
      "    ajkjjkjjkjai",
      "    ajjjjjjjjjai",
      "    ajjjjjjjjjai",
      "    ajkjjkjjkjai",
      "    ajjjjjjjjjai",
      "    ajjjjjjjjjai",
      "    aaaaaaaabbbi"
    ],
    [
      "  mnoooooooobbbp",
      "  mnoqqqqqqqqqop",
      "  mnoqqqqqqqqqop",
      "  mnoqqqqqqqqqop",
      "  mnoqqqqqqqqqop",
      "  mnoqqqqqqqqqop",
      "mmmnoqqqqqqqqqop",
      "nnnnoqqqqqqqqqop",
      "nnnnoqqqqqqqqqop",
      "mmmnoqqqqqqqqqop",
      "  mnoqqqqqqqqqop",
      "  mnoqqqqqqqqqop",
      "  mnoqqqqqqqqqop",
      "  mnoqqqqqqqqqop",
      "  mnoqqqqqqqqqop",
      "  mnoooooooobbbp"
    ],
    [
      "  r oooooooobbb ",
      "  r ossts!ststo ",
      "  r u         o ",
      "  r w         o ",
      "  r ox xx xx xo ",
      "  r oy AB AB yo ",
      "CC  o         o ",
      "    ox xx xx xo ",
      "    oy AB AB yo ",
      "DD  o        Eo ",
      "  r ox xx xx xo ",
      "  r oy AB AB yo ",
      "  r u         o ",
      "  r w    F    o ",
      "  r oIJKKKKKLLo ",
      "  r oooooooobbb "
    ],
    [
      "    aaaaaaaabbb ",
      "    asssstssssa ",
      "    M         d ",
      "    N         d ",
      "    a         a ",
      "    dO P  Q  Rd ",
      "    d         d ",
      "    d         d ",
      "    dS R  RS  d ",
      "    d         d ",
      "    d         d ",
      "    a  QS    Ta ",
      "    M         d ",
      "    N         d ",
      "    aUV  W    a ",
      "    aaaaaaaabbb "
    ]
  ]
}