{
  "name": "multi_verticalschool_12_floor17",
  "refpalette": "deceasedcraft:multi_verticalschool_12/multi_verticalschool_12_floor17_palette",
  "xsize": 16,
  "zsize": 16,
  "slices": [
    [
      "       a    bbbc",
      "               c",
      "               c",
      "               c",
      "               c",
      "       a       c",
      "               c",
      "               c",
      "               c",
      "               c",
      "       a       c",
      "               c",
      "               c",
      "               c",
      "               c",
      "       a    bbbc"
    ],
    [
      "       a    bbbc",
      "               c",
      "               c",
      "               c",
      "               c",
      "       a       c",
      "               c",
      "               c",
      "               c",
      "               c",
      "       a       c",
      "               c",
      "               c",
      "               c",
      "               c",
      "       a    bbbc"
    ],
    [
      "    dddeddddbbbc",
      "    dddddddddddc",
      "    dddddddddddc",
      "    dddddddddddc",
      "    dddddddddddc",
      "    dddedddddddc",
      "    dddddddddddc",
      "    dddddddddddc",
      "    dddddddddddc",
      "    dddddddddddc",
      "    dddedddddddc",
      "    dddddddddddc",
      "    dddddddddddc",
      "    dddddddddddc",
      "    dddddddddddc",
      "    ddd!ddddbbbc"
    ],
    [
      "  fghhhhhhhhbbbi",
      "  fghjjjjjjjjjhi",
      "  fghjjjjjjjjjhi",
      "  fghjjjjjjjjjhi",
      "  fghjjjjjjjjjhi",
      "  fghjjjjjjjjjhi",
      "fffghjjjjjjjjjhi",
      "gggghjjjjjjjjjhi",
      "gggghjjjjjjjjjhi",
      "fffghjjjjjjjjjhi",
      "  fghjjjjjjjjjhi",
      "  fghjjjjjjjjjhi",
      "  fghjjjjjjjjjhi",
      "  fghjjjjjjjjjhi",
      "  fghjjjjjjjjjhi",
      "  fghhhhhhhhbbbi"
    ],
    [
      "  k hhhhhhhhbbb ",
      "  k hllllllmllh ",
      "  k n         h ",
      "  k o         h ",
      "  k hp pp pp ph ",
      "  k hq rs rs qh ",
      "tt  h         h ",
      "    hp pp pp ph ",
      "    hq rs rs qh ",
      "uu  h         h ",
      "  k hp pp pp ph ",
      "  k hq rs rs qh ",
      "  k n         h ",
      "  k o    w    h ",
      "  k hxyAAAAABBh ",
      "  k hhhhhhhhbbb "
    ],
    [
      "    CCCCCCCCbbb ",
      "    ClmlmlllDlC ",
      "    E         F ",
      "    I         F ",
      "    C         C ",
      "    F         F ",
      "    F         F ",
      "    F         F ",
      "    F         F ",
      "    F         F ",
      "    F         F ",
      "    C         C ",
      "    E         F ",
      "    I         F ",
      "    CJK  L    C ",
      "    CCCCCCCCbbb "
    ]
  ]
}