{
  "name": "multi_verticalschool_12_floor28",
  "refpalette": "deceasedcraft:multi_verticalschool_12/multi_verticalschool_12_floor28_palette",
  "xsize": 16,
  "zsize": 16,
  "slices": [
    [
      "aaaaaaaaaaaabbbc",
      "adddddddddddddac",
      "adddddddddddddac",
      "adddddddddddddac",
      "adddddddddddddac",
      "adddddddddddddac",
      "adddddddddddddac",
      "adddddddddddddac",
      "adddddddddddddac",
      "adddddddddddddac",
      "adddddddddddddac",
      "adddddddddddddac",
      "adddddddddddddac",
      "adddddddddddddac",
      "adddddddddddddac",
      "aaaaaaaaaaaabbbc"
    ],
    [
      "aaaaaaaaaaaabbbe",
      "afg  fhhhg ifgae",
      "j             ae",
      "k             ae",
      "a             ae",
      "a      l      ae",
      "a   lm n ml   ae",
      "a ml       lm ae",
      "a    ol lp    ae",
      "a  qlm   mlr  ae",
      "a     ol      ae",
      "a    lm ml    ae",
      "j           s ae",
      "k      t    u ae",
      "awxy A        ae",
      "aaaaaaaaaaaabbbe"
    ],
    [
      "BBBBBBBBBBBBbbb ",
      "BC   DEFIJ   KB ",
      "L             B ",
      "M             N ",
      "B             N ",
      "B             N ",
      "N    !        N ",
      "N             B ",
      "N             B ",
      "N             N ",
      "B             N ",
      "B             N ",
      "L             N ",
      "M             B ",
      "BOP Q  R  Q   B ",
      "BBBBBBBBBBBBbbb "
    ],
    [
      "BBBBBBBBBBBBbbb ",
      "B             B ",
      "N             B ",
      "N             N ",
      "B             N ",
      "B             N ",
      "N             N ",
      "N             B ",
      "N             B ",
      "N             N ",
      "B             N ",
      "B             N ",
      "N             N ",
      "N             B ",
      "BS TUV   TUV  B ",
      "BBBBBBBBBBBBbbb "
    ],
    [
      "BBBBBBBBBBBBbbb ",
      "B             B ",
      "B             B ",
      "B             B ",
      "B             B ",
      "B             B ",
      "B             B ",
      "B             B ",
      "B             B ",
      "B             B ",
      "B             B ",
      "B             B ",
      "B             B ",
      "B             B ",
      "BW XUY   XUY  B ",
      "BBBBBBBBBBBBbbb "
    ],
    [
      "BBBBBBBBBBBBbbbZ",
      "B0000000000000BZ",
      "B0000000000000BZ",
      "B0011100011100BZ",
      "B0000000000000BZ",
      "B0000000000000BZ",
      "B0011100011100BZ",
      "B0000000000000BZ",
      "B0000000000000BZ",
      "B0011100011100BZ",
      "B0000000000000BZ",
      "B0000000000000BZ",
      "B0011100011200BZ",
      "B0000000000000BZ",
      "B0000000000000BZ",
      "BBBBBBBBBBBBbbbZ"
    ]
  ]
}