{
  "name": "multi_verticalschool_12_base2",
  "refpalette": "deceasedcraft:multi_verticalschool_12/multi_verticalschool_12_base2_palette",
  "xsize": 16,
  "zsize": 16,
  "slices": [
    [
      "vvvvvvvvvvvvvvvv",
      "vvvvvvvvvvvvvvvv",
      "vvvvvvvvvvvvvvvv",
      "vvvvvvvvvvvvvvvv",
      "vvvvvvvvvvvvvvvv",
      "vvvvvvvvvvvvvvvv",
      "vvvvvvvvvvvvvvvv",
      "vvvvvvvvvvvvvvvv",
      "vvvvvvvvvvvvvvvv",
      "vvvvvvvvvvvvvvvv",
      "vvvvvvvvvvvvvvvv",
      "vvvvvvvvvvvvvvvv",
      "vvvvvvvvvvvvvvvv",
      "vvvvvvvvvvvvvvvv",
      "vvvvvvvvvvvvvvvv",
      "vvvvvvvvvvvvvvvv"
    ],
    [
      "aaaaaaaaaaaabbba",
      "aaaaaaaaaaaaaaaa",
      "aaaaaaaaaaaaaaaa",
      "aaaaaaaaaaaaaaaa",
      "aaaaaaaaaaaaaaaa",
      "aaaaaaaaaaaaaaaa",
      "aaaaaaaaaaaaaaaa",
      "aaaaaaaaaaaaaaaa",
      "aaaaaaaaaaaaaaaa",
      "aaaaaaaaaaaaaaaa",
      "aaaaaaaaaaaaaaaa",
      "aaaaaaaaaaaaaaaa",
      "aaaaaaaaaaaaaaaa",
      "aaaaaaaaaaaaaaaa",
      "aaaaaaaaaaaaaaaa",
      "aaaaaaaaaaaabbba"
    ],
    [
      "aaaaaaaaaaaabbba",
      "aaaaaaaaaaaaaaaa",
      "aaaaaaaaaaaaaaaa",
      "aaaaaaaaaaaaaaaa",
      "aaaaaaaaaaaaaaaa",
      "aaaaaaaaaaaaaaaa",
      "aaaaaaaaaaaaaaaa",
      "aaaaaaaaaaaaaaaa",
      "aaaaaaaaaaaaaaaa",
      "aaaaaaaaaaaaaaaa",
      "aaaaaaaaaaaaaaaa",
      "aaaaaaaaaaaaaaaa",
      "aaaaaaaaaaaaaaaa",
      "aaaaaaaaaaaaaaaa",
      "aaaaaaaaaaaaaaaa",
      "aaaaaaaaaaaabbba"
    ],
    [
      "bcHHHHHHHHHHbbbH",
      "bcHHHHHHHHHHHHHH",
      "bcHHHHHHHHHHHHHH",
      "bcHHHHHHHHHHHHHH",
      "bcHHHHHHHdHHHHHH",
      "befgfgfgfgfgfgfg",
      "befgfgfgfgfgfgfg",
      "befgfgfgfgfgfgfg",
      "befgfgfgfgfgfgfg",
      "befgfgfgfgfgfgfg",
      "befgfgfgfgfgfgfg",
      "bcHHHHHHHdHHHHHH",
      "bcHHHHHHHHHHHHHH",
      "bcHHHHHHHHHHHHHH",
      "bcHHHHHHHHHHHHHH",
      "bcHHHHHHHHHHbbbH"
    ],
    [
      "b        hhhiiih",
      "         j  klj ",
      "m          n l o",
      "         p  qlp ",
      "         r      ",
      "                ",
      "st              ",
      "ut              ",
      "st              ",
      "ut              ",
      "                ",
      "         w      ",
      "         j  klj ",
      "x          n l o",
      "         p  qlp ",
      "b        yyyiiiy"
    ],
    [
      "b           iii ",
      "                ",
      "A               ",
      "                ",
      "                ",
      "                ",
      "B               ",
      "C               ",
      "B               ",
      "C               ",
      "                ",
      "                ",
      "                ",
      "D               ",
      "                ",
      "b           iii "
    ]
  ]
}