{
  "name": "multi_verticalschool_12_floor31",
  "refpalette": "deceasedcraft:multi_verticalschool_12/multi_verticalschool_12_floor31_palette",
  "xsize": 16,
  "zsize": 16,
  "slices": [
    [
      "     a@@@@aabbb ",
      "    ac d efa    ",
      "    ag    ha    ",
      "    a      a    ",
      "     i     a    ",
      "aaaa aaaaaaa    ",
      "                ",
      "                ",
      "                ",
      "                ",
      "aaaa aaaaaaa    ",
      "     j   k a    ",
      "    a      a    ",
      "    ag    ha    ",
      "    alm no a    ",
      "     a@@@@aabbb "
    ],
    [
      "     a@@@@aabbb ",
      "    a      a    ",
      "    ap    qa    ",
      "    a      a    ",
      "rr  st   u a    ",
      "aaaawaaaaaaa    ",
      "                ",
      "                ",
      "                ",
      "                ",
      "aaaawaaaaaaa    ",
      "xx  sy    Aa    ",
      "    a      a    ",
      "    ap    qa    ",
      "    a      a    ",
      "     a@@@@aabbb "
    ],
    [
      "     aaaaaaabbb ",
      "    aB    Ba    ",
      "    a      a    ",
      "    a      a    ",
      "CC  a      a    ",
      "aaaaaaaaaaaa    ",
      "                ",
      "                ",
      "                ",
      "                ",
      "aaaaaaaaaaaa    ",
      "DD  a      a    ",
      "    a      a    ",
      "    a      a    ",
      "    aE    Ea    ",
      "     aaaaaaabbb "
    ],
    [
      "     aaaaaaabbb ",
      "    aF    Fa    ",
      "    a      a    ",
      "    a      a    ",
      "    a      a    ",
      "aaaaaaaaaaaa    ",
      "                ",
      "                ",
      "                ",
      "                ",
      "aaaaaaaaaaaa    ",
      "    a      a    ",
      "    a      a    ",
      "    a      a    ",
      "    aF    Fa    ",
      "     aaaaaaabbb "
    ],
    [
      "IIIIIaaaaaaabbbJ",
      "IIIIaIIIIIIaJJJJ",
      "IIIIaIIIIIIaJJJJ",
      "IIIIaIIIIIIaJJJJ",
      "IIIIaIIIIIIaJJJJ",
      "aaaaaaaaaaaaJJJJ",
      "JJJJJJJJJJJJJJJJ",
      "JJJJJJJJJJJJJJJJ",
      "JJJJJJJJJJJJJJJJ",
      "JJJJJJJJJJJJJJJJ",
      "aaaaaaaaaaaaJJJJ",
      "IIIIaIIIIIIaJJJJ",
      "IIIIaIIIIIIaJJJJ",
      "IIIIaIIIIIIaJJJJ",
      "IIIIaIIIIIIaJJJJ",
      "IIIIIaaaaaaabbbJ"
    ],
    [
      "bbbbbbbbbbbbbbbK",
      "LLLLLLLLLLLLLLbK",
      "LLLLLLLLLLLLLLbK",
      "LLLLLLLLLLLLLLbK",
      "LLLLLLLLLLLLLLbK",
      "LLLLLLLLLLLLLLbK",
      "LLLLLLLLLLLLLLbK",
      "LLLLLLLLLLLLLLbK",
      "LLLLLLLLLLLLLLbK",
      "LLLLLLLLLLLLLLbK",
      "LLLLLLLLLLLLLLbK",
      "LLLLLLLLLLLLLLbK",
      "LLLLLLLLLLLLLLbK",
      "LLLLLLLLLLLLLLbK",
      "LLLLLLLLLLLLLLbK",
      "bbbbbbbbbbbbbbbK"
    ]
  ]
}