{
  "name": "multi_verticalschool_12_floor21",
  "refpalette": "deceasedcraft:multi_verticalschool_12/multi_verticalschool_12_floor21_palette",
  "xsize": 16,
  "zsize": 16,
  "slices": [
    [
      "    aaaaaaaabbb ",
      "    ac ccc  cca ",
      "    d         d ",
      "    d         d ",
      "    a         a ",
      "    d         d ",
      "    d         d ",
      "    d         d ",
      "    d         d ",
      "    d         d ",
      "    d         d ",
      "    a         a ",
      "    d         d ",
      "    d         d ",
      "    ae        a ",
      "    aaaaaaaabbb "
    ],
    [
      "    aaaaaaaabbb ",
      "    a         a ",
      "    a         a ",
      "    a         a ",
      "    a         a ",
      "    a         a ",
      "    a         a ",
      "    a         a ",
      "    a         a ",
      "    a         a ",
      "    a         a ",
      "    a         a ",
      "    a         a ",
      "    a         a ",
      "    af        a ",
      "    aaaaaaaabbb "
    ],
    [
      "ggggaaaaaaaabbbh",
      "ggggaiiiiiiiiiah",
      "ggggaiiiiiiiiiah",
      "ggggaijiijiijiah",
      "ggggaiiiiiiiiiah",
      "ggggaiiiiiiiiiah",
      "ggggaikiijiijiah",
      "ggggaiiiiiiiiiah",
      "ggggaiiiiiiiiiah",
      "ggggaijiikiikiah",
      "ggggaiiiiiiiiiah",
      "ggggaiiiiiiiiiah",
      "ggggaikiijiijiah",
      "ggggaiiiiiiiiiah",
      "ggggaiiiiiiiiiah",
      "ggggaaaaaaaabbbh"
    ],
    [
      "llllllllllllbbbm",
      "llllllllllllllmm",
      "llllllllllllllmm",
      "llllllllllllllmm",
      "llllllllllllllmm",
      "llllllllllllllmm",
      "llllllllllllllmm",
      "llllllllllllllmm",
      "llllllllllllllmm",
      "llllllllllllllmm",
      "llllllllllllllmm",
      "llllllllllllllmm",
      "llllllllllllllmm",
      "llllllllllllllmm",
      "llllllllllllllmm",
      "llllllllllllbbbm"
    ],
    [
      "           nbbbo",
      "             pqo",
      "    r r r r  pqo",
      "    stttttu  pqo",
      "    wwwwwww  pqo",
      "    xyyyyyA  pqo",
      "    B B B B  pqo",
      "             pqo",
      "             pqo",
      "    r r r r  pqo",
      "    stttttu  pqo",
      "    wwwwwww  pqo",
      "    xyyyyyA  pqo",
      "    B B B B  pqo",
      "             pqo",
      "           nbbbo"
    ],
    [
      "            bbbo",
      "             pqo",
      "             pqo",
      "     C   DE  pqo",
      "    FFFFFFF  pqo",
      "    IJK IL   pqo",
      "             pqo",
      "             pqo",
      "             pqo",
      "             pqo",
      "    MN   OP  pqo",
      "    FFFFFFF  pqo",
      "      I J    pqo",
      "             pqo",
      "             pqo",
      "            bbbo"
    ]
  ]
}