{
  "name": "multi_verticalschool_12_floor2",
  "refpalette": "deceasedcraft:multi_verticalschool_12/multi_verticalschool_12_floor2_palette",
  "xsize": 16,
  "zsize": 16,
  "slices": [
    [
      "            aaa ",
      "                ",
      "                ",
      "                ",
      "                ",
      "                ",
      "                ",
      "                ",
      "                ",
      "                ",
      "                ",
      "                ",
      "                ",
      "                ",
      "                ",
      "            aaa "
    ],
    [
      "            aaa ",
      "                ",
      "                ",
      "                ",
      "                ",
      "                ",
      "                ",
      "                ",
      "                ",
      "                ",
      "                ",
      "                ",
      "                ",
      "                ",
      "                ",
      "            aaa "
    ],
    [
      "bbbbbbbbbbbbaaab",
      "bbbbbbbbbbbbbbbb",
      "bbbbbbbbbbbbbbbb",
      "bbbbbbbbbbbbbbbb",
      "bbbbbbbbbbbbbbbb",
      "bbbbbbbbbbbbbbbb",
      "bbbbbbbbbbbbbbbb",
      "bbbbbbbbbbbbbbbb",
      "bbbbbbbbbbbbbbbb",
      "bbbbbbbbbbbbbbbb",
      "bbbbbbbbbbbbbbbb",
      "bbbbbbbbbbbbbbbb",
      "bbbbbbbbbbbbbbbb",
      "bbbbbbbbbbbbbbbb",
      "bbbbbbbbbbbbbbbc",
      "bbbbbbbbbbbbaaac"
    ],
    [
      "ddddddddddddaaad",
      "dddddddddddddddd",
      "dddddddddddddddd",
      "dddddddddddddddd",
      "dddddddddddddddd",
      "dddddddddddddddd",
      "dddddddddddddddd",
      "dddddddddddddddd",
      "dddddddddddddddd",
      "dddddddddddddddd",
      "dddddddddddddddd",
      "dddddddddddddddd",
      "dddddddddddddddd",
      "dddddddddddddddd",
      "dddddddddddddddd",
      "ddddddddddddaaad"
    ],
    [
      "   efffg   eaaag",
      "   hfffh   hfffh",
      "    ijk     ijk ",
      "    ljm     ljm ",
      "   nljmo   nljmo",
      "    ljm     ljm ",
      "    pjq     pjq ",
      "    rrr     rrr ",
      "    sss     sss ",
      "    ijk     ijk ",
      "    ljm     ljm ",
      "   nljmo   nljmo",
      "    ljm     ljm ",
      "    pjq     pjq ",
      "   hfffh   hfffh",
      "   efffg   eaaag"
    ],
    [
      "    ! t    uaaaw",
      "   hhhhh   hhhhh",
      "    xy       y  ",
      "    AyB     CyD ",
      "    EyF     EyF ",
      "    Ay      Iy  ",
      "     y       y  ",
      "                ",
      "                ",
      "     y      Jy  ",
      "     yI      yD ",
      "    EyF     EyF ",
      "    Iyx     Dy  ",
      "     yK      yL ",
      "   hhhhh   hhhhh",
      "   Mfff     aaaN"
    ]
  ]
}