{
  "name": "multi_verticalschool_12_floor15",
  "refpalette": "deceasedcraft:multi_verticalschool_12/multi_verticalschool_12_floor15_palette",
  "xsize": 16,
  "zsize": 16,
  "slices": [
    [
      "            aaab",
      "            bc b",
      "            bd b",
      "            bc b",
      "            bc b",
      "            bc b",
      "            bc b",
      "            bc b",
      "            bc b",
      "            bc b",
      "            bc b",
      "            bc b",
      "            bc b",
      "            bd b",
      "            bc b",
      "bbbbbbbbbbbbaaab"
    ],
    [
      "            aaab",
      "            b  b",
      "            b  b",
      "            b  b",
      "            b  b",
      "            befb",
      "            b  b",
      "            b  b",
      "            b  b",
      "            b  b",
      "            befb",
      "            b  b",
      "            b  b",
      "            b  b",
      "            b  b",
      "bbbbbbbbbbbbaaab"
    ],
    [
      "ggggggggggghaaab",
      "ggggggggggghbiib",
      "ggggggggggghbiib",
      "ggggggggggghbiib",
      "ggggggggggghbiib",
      "ggggggggggghbiib",
      "ggggggggggghbiib",
      "ggggggggggghbiib",
      "ggggggggggghbiib",
      "ggggggggggghbiib",
      "ggggggggggghbiib",
      "ggggggggggghbiib",
      "ggggggggggghbiib",
      "ggggggggggghbiib",
      "hhhhhhhhhhhhbiib",
      "bbbbbbbbbbbbaaab"
    ],
    [
      "jkkkkkkkkkkkaaal",
      "jkkkkkkkkkkkkkkl",
      "jkkkkkkkkkkkkkkl",
      "jkkkkkkkkkkkkkkl",
      "jkkkkkkkkkkkkkkl",
      "kkkkkkkkkkkkkkkl",
      "kkkkkkkkkkkkkkkm",
      "kkkkkkkkkkkkkkkn",
      "kkkkkkkkkkkkkkkm",
      "kkkkkkkkkkkkkkkm",
      "kkkkkkkkkkkkkkkl",
      "jkkkkkkkkkkkkkkl",
      "jkkkkkkkkkkkkkkl",
      "jkkkkkkkkkkkkkkl",
      "jkkkkkkkkkkkkkkl",
      "jkkkkkkkkkkkaaal"
    ],
    [
      "mopqp   r   aaa ",
      "mopqp  sqt  qqqu",
      "mopqp   w   pppu",
      "mo             u",
      "mo      r   pppu",
      "x      sqt  qqqu",
      "        w   pppy",
      "                ",
      "                ",
      "        r   pppA",
      "B      sqt  qqqu",
      "mo      w   pppu",
      "mo             u",
      "mopqp   r   pppu",
      "mopqp  sqt  qqqu",
      "mopqp   w   aaa "
    ],
    [
      "C  D        aaa ",
      "E              F",
      "I  J           F",
      "K              F",
      "               F",
      "        L      F",
      "                ",
      "                ",
      "                ",
      "                ",
      "            M  F",
      "K              F",
      "C              F",
      "   N           F",
      "O  P        QR F",
      "E           aaa "
    ]
  ]
}