{
  "name": "multi_verticalschool_12_floor27",
  "refpalette": "deceasedcraft:multi_verticalschool_12/multi_verticalschool_12_floor27_palette",
  "xsize": 16,
  "zsize": 16,
  "slices": [
    [
      "abbbbbbbaaaacccd",
      "abbbbbbbbbbbbbad",
      "abbbbbbbbbbbbbad",
      "abbbbbbbbbbbbbad",
      "abbbbbbbbbbbbbad",
      "abbbbbbbbbbbbbad",
      "abbbbbbbbbbbbbad",
      "abbbbbbbbbbbbbad",
      "abbbbbbbbbbbbbad",
      "abbbbbbbbbbbbbad",
      "abbbbbbbbbbbbbad",
      "abbbbbbbbbbbbbad",
      "abbbbbbbbbbbbbad",
      "abbbbbbbbbbbbbad",
      "abbbbbbbbbbbbbad",
      "abbbbbbbaaaacccd"
    ],
    [
      "ae     faaaacccg",
      "ah     ijkllkmag",
      "an            ag",
      "an       o oo ag",
      "ap     qrrrrrrag",
      "ap     qstuutsag",
      "ap       o   oag",
      "an            ag",
      "an            ag",
      "ap       o  o ag",
      "ap     qwrxxrwag",
      "ap     qttttttag",
      "an       o o oag",
      "an            ag",
      "ay     ABCDDCEag",
      "ae     faaaacccg"
    ],
    [
      "FI     JFFFFccc ",
      "F        KLMNOF ",
      "P!            F ",
      "P             P ",
      "FQ       R RSRP ",
      "FT       U  VWP ",
      "FQ            P ",
      "P             F ",
      "P             F ",
      "FQ            P ",
      "FT          X P ",
      "FQ      VYZY YP ",
      "P             P ",
      "P             F ",
      "F       01X234F ",
      "FI     JFFFFccc "
    ],
    [
      "F5      FFFFccc ",
      "F       677778F ",
      "P             F ",
      "P             P ",
      "F             P ",
      "F9            P ",
      "F             P ",
      "P             F ",
      "P             F ",
      "F             P ",
      "F9            P ",
      "F             P ",
      "P             P ",
      "P             F ",
      "F       #$$$$%F ",
      "F5      FFFFccc "
    ],
    [
      "F^     &FFFFccc ",
      "F       *(*(*(F ",
      "F       )     F ",
      "F       )     F ",
      "F       )     F ",
      "F       )     F ",
      "F       )     F ",
      "F       )     F ",
      "F       )     F ",
      "F       )     F ",
      "F       )     F ",
      "F       )     F ",
      "F       )     F ",
      "F       )     F ",
      "F       +-!-+-F ",
      "F^     &FFFFccc "
    ],
    [
      "F[[]]][[FFFFccc{",
      "F[[[[[[[}}}}}}F{",
      "F[[[[[[[}}}}}}F{",
      "F[[]]][[}}}}}}F{",
      "F[[[[[[[}}]]}}F{",
      "F[[[[[[[}}||}}F{",
      "F[[]]][[}}]]}}F{",
      "F[[[[[[[}}||}}F{",
      "F[[[[[[[}}]]}}F{",
      "F[[]]][[}}]]}}F{",
      "F[[[[[[[}}]]}}F{",
      "F[[[[[[[}}]]}}F{",
      "F[[]]][[}}}}}}F{",
      "F[[[[[[[}}}}}}F{",
      "F[[[[[[[}}}}}}F{",
      "F[[|]][[FFFFccc{"
    ]
  ]
}