{
  "name": "multi_verticalschool_12_floor25",
  "refpalette": "deceasedcraft:multi_verticalschool_12/multi_verticalschool_12_floor25_palette",
  "xsize": 16,
  "zsize": 16,
  "slices": [
    [
      "aaaaaaaaaaaabbbc",
      "adddddddddddddac",
      "adddddddddddddac",
      "adddddddddddddac",
      "adddddddddddddac",
      "adddddddddddddac",
      "adddddddddddddac",
      "adddddddddddddac",
      "adddddddddddddac",
      "adddddddddddddac",
      "adddddddddddddac",
      "adddddddddddddac",
      "adddddddddddddac",
      "adddddddddddddac",
      "adddddddddddddac",
      "aaaaaaaaaaaabbbc"
    ],
    [
      "aaaaaaaaaaaabbbe",
      "a fgggh giggf ae",
      "j             ae",
      "k             ae",
      "a   lm   lm   ae",
      "an opq   pq  rae",
      "as  tuw xtuw yae",
      "aA xtuw xtuw Bae",
      "aC xtuw xtu wDae",
      "aE xtu  xtu  Fae",
      "aI  JKw  JKL Mae",
      "a   NO   NO   ae",
      "j    mmmmm    ae",
      "k   PQRRRST   ae",
      "aUV    L   WXXae",
      "aaaaaaaaaaaabbbe"
    ],
    [
      "YYYYYYYYYYYYbbb ",
      "Y  gZgh h0gh  Y ",
      "1             Y ",
      "2             3 ",
      "Y             3 ",
      "Y   4     5   3 ",
      "3    6   7    3 ",
      "3        8    Y ",
      "3   9#    !   Y ",
      "3   $    %    3 ",
      "Y    ^   &    3 ",
      "Y             3 ",
      "1             3 ",
      "2       *(    Y ",
      "Y )    +      Y ",
      "YYYYYYYYYYYYbbb "
    ],
    [
      "YYYYYYYYYYYYbbb ",
      "Y             Y ",
      "3             Y ",
      "3             3 ",
      "Y             3 ",
      "Y             3 ",
      "3             3 ",
      "3             Y ",
      "3             Y ",
      "3             3 ",
      "Y             3 ",
      "Y             3 ",
      "3             3 ",
      "3             Y ",
      "Y-            Y ",
      "YYYYYYYYYYYYbbb "
    ],
    [
      "YYYYYYYYYYYYbbb ",
      "Y             Y ",
      "Y             Y ",
      "Y             Y ",
      "Y             Y ",
      "Y             Y ",
      "Y             Y ",
      "Y             Y ",
      "Y             Y ",
      "Y             Y ",
      "Y             Y ",
      "Y             Y ",
      "Y             Y ",
      "Y             Y ",
      "Y[            Y ",
      "YYYYYYYYYYYYbbb "
    ],
    [
      "YYYYYYYYYYYYbbb]",
      "Y{{{{{{{{{{{{{Y]",
      "Y{{{{{{{{{{{{{Y]",
      "Y{{}}|{{{|||{{Y]",
      "Y{{{{{{{{{{{{{Y]",
      "Y{{{{{{{{{{{{{Y]",
      "Y{{|||{{{|||{{Y]",
      "Y{{{{{{{{{{{{{Y]",
      "Y{{{{{{{{{{{{{Y]",
      "Y{{|||{{{|||{{Y]",
      "Y{{{{{{{{{{{{{Y]",
      "Y{{{{{{{{{{{{{Y]",
      "Y{{||}{{{|||{{Y]",
      "Y{{{{{{{{{{{{{Y]",
      "Y{{{{{{{{{{{{{Y]",
      "YYYYYYYYYYYYbbb]"
    ]
  ]
}