{
  "name": "multi_verticalschool_12_floor29",
  "refpalette": "deceasedcraft:multi_verticalschool_12/multi_verticalschool_12_floor29_palette",
  "xsize": 16,
  "zsize": 16,
  "slices": [
    [
      "aaaaaaaaaaaabbbc",
      "adddddddddddddac",
      "adddddddddddddac",
      "adddddddddddddac",
      "adddddddddddddac",
      "adddddddddddddac",
      "adddddddddddddac",
      "adddddddddddddac",
      "adddddddddddddac",
      "adddddddddddddac",
      "adddddddddddddac",
      "adddddddddddddac",
      "adddddddddddddac",
      "adddddddddddddac",
      "adddddddddddddac",
      "aaaaaaaaaaaabbbc"
    ],
    [
      "aaaaaaaaaaaabbbe",
      "afg         fgae",
      "h             ae",
      "i            jae",
      "a            kae",
      "a            lae",
      "a            kae",
      "a            mae",
      "a            kae",
      "a     n n    oae",
      "a            kae",
      "a            pae",
      "h    qqqqq   kae",
      "i             ae",
      "arst      u rsae",
      "aaaaaaaaaaaabbbe"
    ],
    [
      "wwwwwwwwwwwwbbb ",
      "wxy ABBBBBC yDw ",
      "E             w ",
      "F             I ",
      "w             I ",
      "w             I ",
      "I             I ",
      "I             w ",
      "I             w ",
      "I             I ",
      "w             I ",
      "w             I ",
      "E    J JJ     I ",
      "F             w ",
      "w K    L    MNw ",
      "wwwwwwwwwwwwbbb "
    ],
    [
      "wwwwwwwwwwwwbbb ",
      "wOPQ       O!Qw ",
      "I             w ",
      "I             I ",
      "w             I ",
      "w             I ",
      "I             I ",
      "I             w ",
      "I             w ",
      "I             I ",
      "w             I ",
      "w             I ",
      "I             I ",
      "I             w ",
      "wR            w ",
      "wwwwwwwwwwwwbbb "
    ],
    [
      "wwwwwwwwwwwwbbb ",
      "wSPT       SUTw ",
      "w             w ",
      "w             w ",
      "w             w ",
      "w             w ",
      "w             w ",
      "w             w ",
      "w             w ",
      "w             w ",
      "w             w ",
      "w             w ",
      "w             w ",
      "w             w ",
      "wU            w ",
      "wwwwwwwwwwwwbbb "
    ],
    [
      "wwwwwwwwwwwwbbbV",
      "wWWWWWWWWWWWWWwV",
      "wWWWWWWWWWWWWWwV",
      "wWWXYYWWWXXXWWwV",
      "wWWWWWWWWWWWWWwV",
      "wWWWWWWWWWWWWWwV",
      "wWWXXXWWWXXXWWwV",
      "wWWWWWWWWWWWWWwV",
      "wWWWWWWWWWWWWWwV",
      "wWWXXXWWWXXXWWwV",
      "wWWWWWWWWWWWWWwV",
      "wWWWWWWWWWWWWWwV",
      "wWWXXXWWWXXXWWwV",
      "wWWWWWWWWWWWWWwV",
      "wWWWWWWWWWWWWWwV",
      "wwwwwwwwwwwwbbbV"
    ]
  ]
}