{
  "name": "multi_verticalschool_12_floor8",
  "refpalette": "deceasedcraft:multi_verticalschool_12/multi_verticalschool_12_floor8_palette",
  "xsize": 16,
  "zsize": 16,
  "slices": [
    [
      "abbbbc      dddb",
      "abeeeffffg c  hb",
      "abeee   ffffffhb",
      "abeeei        j ",
      "abeee         k ",
      "abeeei        hb",
      "abeee         hb",
      "abeeei        hb",
      "abeee         l ",
      "abeem         hb",
      "abeem         hn",
      "abeem         ho",
      "abee          ho",
      "abeep         hq",
      "abee          hb",
      "abeep       dddb"
    ],
    [
      "eeeg c     rdddb",
      "eeeffffffg c  hb",
      "eee     ffffffhb",
      "eeei          st",
      "eee           st",
      "eeei          hb",
      "eee           hb",
      "eeei          hb",
      "eem           u ",
      "eem           hb",
      "eem           hb",
      "eei           hb",
      "ee            hb",
      "eei           hb",
      "ee            hb",
      "eei         dddb"
    ],
    [
      "effg c      dddb",
      "e fffffffg c  hb",
      "ei      ffffffhb",
      "e             hb",
      "ei            hb",
      "e             hb",
      "ei            hb",
      "m             hb",
      "m             hb",
      "m             hb",
      "              hb",
      "i             hb",
      "              hb",
      "i             hb",
      "              hb",
      "i           dddb"
    ],
    [
      "fffg c      dddb",
      "  fffffffg c  hb",
      "        ffffffhb",
      "              hb",
      "              hb",
      "              hb",
      "              hb",
      "              hb",
      "              hb",
      "              hb",
      "           w  hb",
      "           w  hb",
      "           w  hb",
      "           w  hb",
      "           w  hb",
      "           wdddb"
    ],
    [
      "fffg c      dddb",
      "  fffffffg c  hb",
      "        ffffffhb",
      "              hb",
      "              hb",
      "              hb",
      "             xhb",
      "              hb",
      "              hb",
      "              hb",
      "           w  hb",
      "           w  hb",
      "           wyAhb",
      "           w  hb",
      "           w  hb",
      "           wdddb"
    ],
    [
      "fffg c      dddb",
      "  fffffffg c  hb",
      "        ffffffhb",
      "              hb",
      "              hb",
      "             Bhb",
      "             Chb",
      "             Dhb",
      "              hb",
      "              hb",
      "           w  hb",
      "           w  hb",
      "           wEFhb",
      "           w  hb",
      "           w  hb",
      "           wdddb"
    ]
  ]
}