{
  "name": "multi_verticalschool_12_floor18",
  "refpalette": "deceasedcraft:multi_verticalschool_12/multi_verticalschool_12_floor18_palette",
  "xsize": 16,
  "zsize": 16,
  "slices": [
    [
      "    aaaaaaaabbb ",
      "    accccccccca ",
      "    d         d ",
      "    d         d ",
      "    a         a ",
      "    d         d ",
      "    d         d ",
      "    d         d ",
      "    d         d ",
      "    d         d ",
      "    d         d ",
      "    a         a ",
      "    d         d ",
      "    d         d ",
      "    ae        a ",
      "    aaaaaaaabbb "
    ],
    [
      "    aaaaaaaabbb ",
      "    a         a ",
      "    a         a ",
      "    a         a ",
      "    a         a ",
      "    a         a ",
      "    a         a ",
      "    a         a ",
      "    a         a ",
      "    a         a ",
      "    a         a ",
      "    a         a ",
      "    a         a ",
      "    a         a ",
      "    af        a ",
      "    aaaaaaaabbb "
    ],
    [
      "    aaaaaaaabbbg",
      "    ahhhhhhhhhag",
      "    ahhhhhhhhhag",
      "    ahihhihhihag",
      "    ahhhhhhhhhag",
      "    ahhhhhhhhhag",
      "    ahihhihhihag",
      "    ahhhhhhhhhag",
      "    ahhhhhhhhhag",
      "    ahjhhihhjhag",
      "    ahhhhhhhhhag",
      "    ahhhhhhhhhag",
      "    ahjhhjhhihag",
      "    ahhhhhhhhhag",
      "    ahhhhhhhhhag",
      "    aaaaaaaabbbg"
    ],
    [
      "  klmmmmmmmmbbbn",
      "  klmooooooooomn",
      "  klmooooooooomn",
      "  klmooooooooomn",
      "  klmooooooooomn",
      "  klmooooooooomn",
      "kkklmooooooooomn",
      "llllmooooooooomn",
      "llllmooooooooomn",
      "kkklmooooooooomn",
      "  klmooooooooomn",
      "  klmooooooooomn",
      "  klmooooooooomn",
      "  klmooooooooomn",
      "  klmooooooooomn",
      "  klmmmmmmmmbbbn"
    ],
    [
      "  p mmmmmmmmbbb ",
      "  p mqrrrqrrrrm ",
      "  p s         m ",
      "  p t         m ",
      "  p mu uu uu um ",
      "  p mw xy xy wm ",
      "AA  m         m ",
      "    mu uu uu um ",
      "    mw xy xy wm ",
      "BB  m         m ",
      "  p mu uu uu um ",
      "  p mw xy xy wm ",
      "  p s         m ",
      "  p t    !    m ",
      "  p mCDEEEEEFFm ",
      "  p mmmmmmmmbbb "
    ],
    [
      "    aaaaaaaabbb ",
      "    arrrrrqrrqa ",
      "    I         d ",
      "    J         d ",
      "    a         a ",
      "    dK LM NO Od ",
      "    d         d ",
      "    d         d ",
      "    dO K  LO Nd ",
      "    d         d ",
      "    d         d ",
      "    aL OP ML  a ",
      "    I         d ",
      "    J    Q    d ",
      "    a    R    a ",
      "    aaaaaaaabbb "
    ]
  ]
}