{
  "name": "multi_verticalschool_12_floor23",
  "refpalette": "deceasedcraft:multi_verticalschool_12/multi_verticalschool_12_floor23_palette",
  "xsize": 16,
  "zsize": 16,
  "slices": [
    [
      "            aaa ",
      "                ",
      "                ",
      "                ",
      "                ",
      "                ",
      "                ",
      "                ",
      "                ",
      "                ",
      "                ",
      "                ",
      "                ",
      "                ",
      "                ",
      "            aaa "
    ],
    [
      "bbbbbbbbbbbbaaac",
      "bbbbbbbbbbbbbdcc",
      "bbbbbbbbbbbbbdcc",
      "bbbbbbbbbbbbbdcc",
      "bbbbbbbbbbbbbdcc",
      "bbbbbbbbbbbbbdcc",
      "bbbbbbbbbbbbbdcc",
      "bbbbbbbbbbbbbdcc",
      "bbbbbbbbbbbbbdcc",
      "bbbbbbbbbbbbbdcc",
      "bbbbbbbbbbbbbdcc",
      "bbbbbbbbbbbbbdcc",
      "bbbbbbbbbbbbbdcc",
      "bbbbbbbbbbbbbdcc",
      "bbbbbbbbbbbbbdcc",
      "bbbbbbbbbbbbaaac"
    ],
    [
      "eeffffffffffaaag",
      "heijjjjjjjjjjfhg",
      "heejjjjjjjjjjfhg",
      "hheiffffffffffhg",
      "kheelllllllllfhg",
      "khheifffffffffhg",
      "kkheemmmmmmmmfhg",
      "kkhheimmmmmmmfhg",
      "kkkheeffffffffhg",
      "kkkhheinnnnnnfhg",
      "kkkkheennnnnnfhg",
      "kkkkhheiffffffhg",
      "kkkkkheejjjjjfhg",
      "kkkkkhheifffffhg",
      "kkkkkkheellllfhg",
      "kkkkkkhheiffaaag"
    ],
    [
      "            aaao",
      "              po",
      "              po",
      "qr            po",
      " s            po",
      " t            po",
      "              po",
      "              po",
      "              po",
      "   qr         po",
      "    u         po",
      "    w         po",
      "              po",
      "              po",
      "              po",
      "      qr    aaao"
    ],
    [
      "            aaax",
      "               x",
      "               x",
      "yA             x",
      "               x",
      "               x",
      "               x",
      "               x",
      "               x",
      "   yB          x",
      "               x",
      "               x",
      "               x",
      "               x",
      "               x",
      "      yC    aaax"
    ],
    [
      "            aaa ",
      "                ",
      "                ",
      "D               ",
      "                ",
      "                ",
      "                ",
      "                ",
      "                ",
      "   D            ",
      "                ",
      "                ",
      "                ",
      "                ",
      "                ",
      "      D     aaa "
    ]
  ]
}