{
  "name": "multi_gallery_1_base2",
  "refpalette": "deceasedcraft:multi_gallery_1/multi_gallery_1_base2_palette",
  "xsize": 16,
  "zsize": 16,
  "slices": [
    [
      "vaaaaaaaaaaaaaaa",
      "vaaaaaaaaaaaaaaa",
      "vaaaaaaaaaaaaaaa",
      "vaaaaaaaaaaaaaaa",
      "vaaaaaaaaaaaaaaa",
      "vaaaaaaaaaaaaaaa",
      "vaaaaaaaaaaaaaaa",
      "vaaaaaaaaaaaaaaa",
      "vaaaaaaaaaaaaaaa",
      "vaaaaaaaaaaaaaaa",
      "vaaaaaaaaaaaaaaa",
      "vaaaaaaaaaaaaaaa",
      "vbbbbbbbbbbbbbbb",
      "vaaaaaaaaaaaaaaa",
      "vaaaaaaaaaaaaaaa",
      "vvvvvvvvvvvvvvvv"
    ],
    [
      "vaaaaaaaaaaaaaaa",
      "vaaaaaaaaaaaaaaa",
      "vaaaaaaaaaaaaaaa",
      "vaaaaaaaaaaaaaaa",
      "vaaaaaaaaaaaaaaa",
      "vaaaaaaaaaaaaaaa",
      "vaaaaaaaaaaaaaac",
      "vaaaaaaaaaaaaaaa",
      "vaaaaaaaaaaaaaaa",
      "vaaaaaaaaaaaaaaa",
      "vaaaaaaaaaaaaaaa",
      "vaaaaaaaaaaaaaaa",
      "vbbbbbbbbbbbbbbb",
      "vaaaaaaaaaaaaaaa",
      "vaaaaaaaaaaaaaaa",
      "vvvvvvvvvvvvvvvv"
    ],
    [
      "vdeeeeeaaaaaaaaa",
      "vdeeeeeaaaaaaaaa",
      "vdeeeeeaaaaaaaaa",
      "vdeeeeeaaaaaaaaa",
      "vdeeeeeaaaaaaaaa",
      "vdeeeeeaaaaaaaaa",
      "vdeeeeeaaaaaaaac",
      "vdeeeeeaaaaaaaaa",
      "vdeeeeeaaaaaaaaa",
      "vdeeeeeaaaaaaaaa",
      "vdeeeeeaaaaaaaaa",
      "vdeeeeeaaaaaaaaa",
      "vbbbbbbbbbbbbbbb",
      "vaaaaaaaaaaaaaaa",
      "vaaaaaaaaaaaaaaa",
      "vvvvvvvvvvvvvvvv"
    ],
    [
      "vbbbbfbghihhhddh",
      "vjk l  mhihhhddh",
      "vjnno pghihhhddh",
      "vjk q pmh!hhhddh",
      "vjnno pghihhhddh",
      "vjk l pmhhhhhhhh",
      "vjnno pghhhhhhhr",
      "vjk l pmhhhhhhhh",
      "vjnno pghhhhhhhh",
      "vst    mhhhhhhhh",
      "vruw   xhhhhhhhh",
      "vruy   xhhhhhhhh",
      "vbbbbbbbbbbAbbbb",
      "vaaaaaaaaaaaaaaa",
      "vaaaaaaaaaaaaaaa",
      "vvvvvvvvvvvvvvvv"
    ],
    [
      "vbbbbBbC D    EE",
      "vj  F  IJD    Kd",
      "vjnno  C D    Kd",
      "vj  L MIJD    Kd",
      "vjnno NC D    EE",
      "vj  F MI        ",
      "vjnno NCt       ",
      "vj  F MIO       ",
      "vjnno NCP       ",
      "vsQR  SIt       ",
      "vru             ",
      "vru             ",
      "vbbbbbbbbbbTbbbb",
      "vaaaaaaaaaaUaaaa",
      "vaaaaaaaaaaaaaaa",
      "vvvvvvvvvvvvvvvv"
    ],
    [
      "vbbbbbbg      EE",
      "vj  o  m        ",
      "vjnno Vg        ",
      "vj  o Wm        ",
      "vjnno Wg      EE",
      "vj  o Wm        ",
      "vjnno WgQ       ",
      "vj  o Wm        ",
      "vjnno Xg        ",
      "vs     mQ       ",
      "vru             ",
      "vru             ",
      "vbbbbbbbbbbbbbbb",
      "vaaaaaaaaaaaaaaa",
      "vaaaaaaaaaaaaaaa",
      "vvvvvvvvvvvvvvvv"
    ]
  ]
}