{
  "name": "multi_gallery_1_ground",
  "refpalette": "deceasedcraft:multi_gallery_1/multi_gallery_1_ground_palette",
  "xsize": 16,
  "zsize": 16,
  "slices": [
    [
      "aaaaaaabbbbac   ",
      "aaaaaaabbbaac   ",
      "aaaaaabbbbac    ",
      "aaaaaabbbaac    ",
      "aaaaabbbbac     ",
      "aaaaabbbaac     ",
      "aaaabbbbacddd   ",
      "aaaabbbaacdeeff ",
      "aaabbbbacceeegff",
      "aaabbbbacceeg   ",
      "aabbbbbccccg    ",
      "aabbbbbccccc    ",
      "abbbbbbhhhhhhhhh",
      "abbbbbbbbbbbbbbb",
      "bbbbbbbbbbbbbbbb",
      "bbbbbbbbbbbbbbbb"
    ],
    [
      "           i    ",
      "          iij   ",
      "          i     ",
      "         iik    ",
      "         ilddd  ",
      "        iiheef  ",
      "        ihgggf  ",
      "       iihg  ff ",
      "       ihh      ",
      "       ihh      ",
      "       hhhh     ",
      "       hhhhh    ",
      "       hhhhhhhhh",
      "                ",
      "                ",
      "                "
    ],
    [
      "                ",
      "            m   ",
      "           lddd ",
      "           heef ",
      "          hgggf ",
      "          h  ff ",
      "         h   f  ",
      "         h      ",
      "        hh      ",
      "        hh      ",
      "       hhhh     ",
      "       hhhhh    ",
      "       hhhhhhhhh",
      "                ",
      "                ",
      "                "
    ],
    [
      "            lddd",
      "            heef",
      "           hgggf",
      "           h  ff",
      "          h   f ",
      "          h     ",
      "         h     n",
      "         h      ",
      "        hh      ",
      "        hh      ",
      "       hhhh     ",
      "       hhhhh    ",
      "       hhhhhhhhh",
      "                ",
      "                ",
      "                "
    ],
    [
      "            hggg",
      "            h  f",
      "           h   f",
      "           h    ",
      "          h     ",
      "          h     ",
      "         h     o",
      "         h      ",
      "        hh      ",
      "        hh      ",
      "       hhhh     ",
      "       hhhhh    ",
      "       hhhhhhhhh",
      "                ",
      "                ",
      "                "
    ],
    [
      "            h   ",
      "            h   ",
      "           h    ",
      "           h    ",
      "          h     ",
      "          h     ",
      "         h     o",
      "         h      ",
      "        hh      ",
      "        hh      ",
      "       hhhh     ",
      "       hhhhh    ",
      "       hhhhhhhhh",
      "                ",
      "                ",
      "                "
    ]
  ]
}