{
  "name": "multi_gallery_1_base1",
  "refpalette": "deceasedcraft:multi_gallery_1/multi_gallery_1_base1_palette",
  "xsize": 16,
  "zsize": 16,
  "slices": [
    [
      "vaaaaaab        ",
      "vc  d  e        ",
      "vcffd  b        ",
      "vc  d  e        ",
      "vcffd  b       g",
      "vc  d  e        ",
      "vcffd  b        ",
      "vc  d  e        ",
      "vcffd  b        ",
      "vh     e        ",
      "vij             ",
      "vij             ",
      "vaaaaaaaaaaaaaaa",
      "vkkkkkkkkkkkkkkk",
      "vkkkkkkkkkkkkkkk",
      "vvvvvvvvvvvvvvvv"
    ],
    [
      "vaaaaaal        ",
      "vc  d  m        ",
      "vcffd  l        ",
      "vc  d  m        ",
      "vcffd  l        ",
      "vc  d  m        ",
      "vcffd  l        ",
      "vc  d  m        ",
      "vcffd  l        ",
      "vh     m        ",
      "vij   nj        ",
      "vij   nj        ",
      "vaaaaaaaaaaaaaaa",
      "vkkkkkkkkkkkkkkk",
      "vkkkkkkkkkkkkkkk",
      "vvvvvvvvvvvvvvvv"
    ],
    [
      "vaaaaaab        ",
      "vc op  e        ",
      "vc  p  b        ",
      "vcoop  e        ",
      "vc op  b        ",
      "vc  p  e        ",
      "vc  p  b        ",
      "vc  p  e        ",
      "vcppp  b        ",
      "vh     e        ",
      "vij   nj        ",
      "vij   nj        ",
      "vaaaaaaaaaaaaaaa",
      "vkkkkkkkkkkkkkkk",
      "vkkkkkkkkkkkkkkk",
      "vvvvvvvvvvvvvvvv"
    ],
    [
      "vaaaaaal        ",
      "vcqccccm        ",
      "vccccccl        ",
      "vc!ccccm        ",
      "vccccccl        ",
      "vcqccccm        ",
      "vccccccl        ",
      "vcqccccm        ",
      "vccccccl        ",
      "vh     m        ",
      "virssstj        ",
      "virssstj        ",
      "vaaaaaaaaaaaaaaa",
      "vkkkkkkkkkkkkkkk",
      "vkkkkkkkkkkkkkkk",
      "vvvvvvvvvvvvvvvv"
    ],
    [
      "vaaaaaub        ",
      "vcuuuuue        ",
      "vc  ooub        ",
      "vcuuuuue        ",
      "vcoo  ub        ",
      "vcuuuuue        ",
      "vco  oub        ",
      "vcuuuuue        ",
      "vcwxxxxb       g",
      "vhy    e      AB",
      "vh     j      AB",
      "vh     j     AAB",
      "vaCCCCCaaaaaaaaa",
      "vkkkkkkkkkkkkkkk",
      "vkkkkkkkkkkkkkkk",
      "vvvvvvvvvvvvvvvv"
    ],
    [
      "vaxxxxxaxxxxD   ",
      "vaxxxxxaxxxxD   ",
      "vaxxxxxaxxxD    ",
      "vaxxxxxaxxxD    ",
      "vaxxxxxaxxD     ",
      "vaxxxxxaxxD     ",
      "vaxxxxxaxD      ",
      "vaxxxxxaxD      ",
      "vaxxxxxaxD   Agg",
      "vahhhhhaxD  ABE ",
      "vahhhhhxxxDABBE ",
      "vahhhhhxxxDABEE ",
      "vaaaaaaaaaaaaaaa",
      "vkkkkkkkkkkkkkkk",
      "vkkkkkkkkkkkkkkk",
      "vvvvvvvvvvvvvvvv"
    ]
  ]
}