{
  "name": "multi_filmworkstower_9_floor8",
  "refpalette": "deceasedcraft:multi_filmworkstower_9/multi_filmworkstower_9_floor8_palette",
  "xsize": 16,
  "zsize": 16,
  "slices": [
    [
      "aaab            ",
      "aaabc           ",
      "aaab            ",
      "aaab            ",
      "aaabc           ",
      "aaab            ",
      "aaab            ",
      "aaabc           ",
      "aaab            ",
      "aaab            ",
      "aaabc           ",
      "aaab            ",
      "aaa dde         ",
      "aaab            ",
      "aaabc           ",
      "bbb             "
    ],
    [
      "   b            ",
      "   bc           ",
      "   b            ",
      "fffb            ",
      "g  bc           ",
      "hi b            ",
      "ji b            ",
      "k  bc           ",
      "lllb            ",
      "   b            ",
      "g  bc           ",
      "hi b            ",
      "ji mdde         ",
      "k  b            ",
      "   bc           ",
      "bbb             "
    ],
    [
      "   b            ",
      "   bc           ",
      "   b            ",
      "nnnb            ",
      "   bc           ",
      "   b            ",
      "o  b            ",
      "   bc           ",
      "pppb            ",
      "   b            ",
      "   bc           ",
      "q  b            ",
      "   mdde         ",
      "   b            ",
      "   bc           ",
      "bbb             "
    ],
    [
      "   b            ",
      "   bc           ",
      "   b            ",
      "   b            ",
      "   bc           ",
      "   b            ",
      "   b            ",
      "   bc           ",
      "   b            ",
      "   b            ",
      "   bc           ",
      "   b            ",
      "   mdde         ",
      "   b            ",
      "   bc           ",
      "bbb             "
    ],
    [
      "   b            ",
      "   bc           ",
      "   b            ",
      "   b            ",
      "   bc           ",
      "   b            ",
      "   b            ",
      "   bc           ",
      "   b            ",
      "   b            ",
      "   bc           ",
      "   b            ",
      "   mdde         ",
      "   b            ",
      "   bc           ",
      "bbb             "
    ],
    [
      "rrrb            ",
      "rrrbc           ",
      "rrrb            ",
      "srrb            ",
      "rrrbc           ",
      "rrrb            ",
      "rrrb            ",
      "rrrbc           ",
      "srrb            ",
      "rrrb            ",
      "rrrbc           ",
      "rrrb            ",
      "ttttdde         ",
      "srrb            ",
      "rrrbc           ",
      "bbb             "
    ]
  ]
}