{
  "name": "multi_filmworkstower_9_floor6",
  "refpalette": "deceasedcraft:multi_filmworkstower_9/multi_filmworkstower_9_floor6_palette",
  "xsize": 16,
  "zsize": 16,
  "slices": [
    [
      "aaab            ",
      "aaabc           ",
      "aaab            ",
      "aaab            ",
      "aaabc           ",
      "aaab            ",
      "aaab            ",
      "aaabc           ",
      "aaab            ",
      "aaab            ",
      "aaabc           ",
      "aaab            ",
      "aaa dde         ",
      "aaab            ",
      "aaabc           ",
      "bbb             "
    ],
    [
      "  fb            ",
      " gfbc           ",
      "  hb            ",
      " ijb            ",
      "  kbc           ",
      "  fb            ",
      "  fb            ",
      "  hbc           ",
      " ijb            ",
      "  kb            ",
      "  fbc           ",
      "  fb            ",
      "  hldde         ",
      " ijb            ",
      "  kbc           ",
      "bbb             "
    ],
    [
      "  mb            ",
      "  !bc           ",
      "  nb            ",
      "  ob            ",
      "  pbc           ",
      "  mb            ",
      "  nb            ",
      "  qbc           ",
      "  ob            ",
      "  pb            ",
      "  rbc           ",
      "  mb            ",
      "   ldde         ",
      "  ob            ",
      "  pbc           ",
      "bbb             "
    ],
    [
      "   b            ",
      "   bc           ",
      "   b            ",
      "   b            ",
      "   bc           ",
      "   b            ",
      "   b            ",
      "   bc           ",
      "   b            ",
      "   b            ",
      "   bc           ",
      "   b            ",
      "   ldde         ",
      "   b            ",
      "   bc           ",
      "bbb             "
    ],
    [
      "   b            ",
      "   bc           ",
      "   b            ",
      "   b            ",
      "   bc           ",
      "   b            ",
      "   b            ",
      "   bc           ",
      "   b            ",
      "   b            ",
      "   bc           ",
      "   b            ",
      "   ldde         ",
      "   b            ",
      "   bc           ",
      "bbb             "
    ],
    [
      "sssb            ",
      "sssbc           ",
      "sssb            ",
      "tssb            ",
      "sssbc           ",
      "sssb            ",
      "sssb            ",
      "sssbc           ",
      "tssb            ",
      "sssb            ",
      "sssbc           ",
      "sssb            ",
      "uuuudde         ",
      "tssb            ",
      "sssbc           ",
      "bbb             "
    ]
  ]
}