{
  "name": "multi_filmworkstower_9_floor11",
  "refpalette": "deceasedcraft:multi_filmworkstower_9/multi_filmworkstower_9_floor11_palette",
  "xsize": 16,
  "zsize": 16,
  "slices": [
    [
      "aaab            ",
      "aaabc           ",
      "aaab            ",
      "aaab            ",
      "aaabc           ",
      "aaab            ",
      "aaab            ",
      "aaabc           ",
      "aaab            ",
      "aaab            ",
      "aaabc           ",
      "aaab            ",
      "aaa dde         ",
      "aaab            ",
      "aaabc           ",
      "bbb             "
    ],
    [
      "f gb            ",
      "h ibc           ",
      "jjkb            ",
      "lmnb            ",
      "o pbc           ",
      "q gb            ",
      " rgb            ",
      "  ibc           ",
      "jjkb            ",
      "mmnb            ",
      "o pbc           ",
      "q gb            ",
      "f gsdde         ",
      "h ib            ",
      "jjkbc           ",
      "bbb             "
    ],
    [
      "  tb            ",
      "  ubc           ",
      "wx b            ",
      "yABb            ",
      "   bc           ",
      "  Cb            ",
      "  Db            ",
      "   bc           ",
      "wx b            ",
      "yEFb            ",
      "  Ibc           ",
      "  Cb            ",
      "  tsdde         ",
      "  Jb            ",
      "wKBbc           ",
      "bbb             "
    ],
    [
      "   b            ",
      "   bc           ",
      "   b            ",
      "   b            ",
      "   bc           ",
      "   b            ",
      "   b            ",
      "   bc           ",
      "   b            ",
      "   b            ",
      "   bc           ",
      "   b            ",
      "   sdde         ",
      "   b            ",
      "   bc           ",
      "bbb             "
    ],
    [
      "   b            ",
      "   bc           ",
      "   b            ",
      "   b            ",
      "   bc           ",
      "   b            ",
      "   b            ",
      "   bc           ",
      "   b            ",
      "   b            ",
      "   bc           ",
      "   b            ",
      "   sdde         ",
      "   b            ",
      "   bc           ",
      "bbb             "
    ],
    [
      "LLLb            ",
      "LLLbc           ",
      "LLLb            ",
      "MLLb            ",
      "LLLbc           ",
      "LLLb            ",
      "LLLb            ",
      "LLLbc           ",
      "MLLb            ",
      "LLLb            ",
      "LLLbc           ",
      "LLLb            ",
      "NNNNdde         ",
      "MLLb            ",
      "LLLbc           ",
      "bbb             "
    ]
  ]
}