{
  "name": "multi_filmworkstower_9_floor2",
  "refpalette": "deceasedcraft:multi_filmworkstower_9/multi_filmworkstower_9_floor2_palette",
  "xsize": 16,
  "zsize": 16,
  "slices": [
    [
      "aaab            ",
      "aaabc           ",
      "aaab            ",
      "aaab            ",
      "aaabc           ",
      "aaab            ",
      "aaab            ",
      "aaabc           ",
      "aaab            ",
      "aaab            ",
      "aaabc           ",
      "aaab            ",
      "aaa ddde        ",
      "fffb            ",
      "gggbc           ",
      "bbb             "
    ],
    [
      "hi b            ",
      "hj bc           ",
      "hk b            ",
      "   b            ",
      "   bc           ",
      "ll b            ",
      "   b            ",
      "mn bc           ",
      "   b            ",
      "oo b            ",
      "   bc           ",
      " p b            ",
      "   qdddr        ",
      "sssb            ",
      "   bc           ",
      "bbb             "
    ],
    [
      "h  b            ",
      "ht bc           ",
      "hu b            ",
      "   b            ",
      "   bc           ",
      "ss b            ",
      "   b            ",
      "   bc           ",
      "   b            ",
      "   b            ",
      "   bc           ",
      "   b            ",
      "   qddd         ",
      "   b            ",
      "   bc           ",
      "bbb             "
    ],
    [
      "   b            ",
      "   bc           ",
      "   b            ",
      "   b            ",
      "   bc           ",
      "   b            ",
      "   b            ",
      "   bc           ",
      "   b            ",
      "   b            ",
      "   bc           ",
      "   b            ",
      "   qddd         ",
      "   b            ",
      "   bc           ",
      "bbb             "
    ],
    [
      "   b            ",
      "   bc           ",
      "   b            ",
      "   b            ",
      "   bc           ",
      "   b            ",
      "   b            ",
      "   bc           ",
      "   b            ",
      "   b            ",
      "   bc           ",
      "   b            ",
      "   qddd         ",
      "   b            ",
      "   bc           ",
      "bbb             "
    ],
    [
      "   b            ",
      "   bc           ",
      "   b            ",
      "   b            ",
      "   bc           ",
      "   b            ",
      "   b            ",
      "   bc           ",
      "   b            ",
      "   b            ",
      "   bc           ",
      "   b            ",
      "   qddr         ",
      "   b            ",
      "   bc           ",
      "bbb             "
    ]
  ]
}