{
  "name": "multi_filmworkstower_9_ground",
  "refpalette": "deceasedcraft:multi_filmworkstower_9/multi_filmworkstower_9_ground_palette",
  "xsize": 16,
  "zsize": 16,
  "slices": [
    [
      "aabcccccccccccde",
      "aabcccccccccccde",
      "aabcccccccccccde",
      "aabccccccccccdde",
      "aabccccccccccdee",
      "aabccccccccdddee",
      "aabccccccdddeeee",
      "aabccccdddeeeeee",
      "aabccdddeeeeeeff",
      "aagdddeeeeeeffff",
      "adddeeeeeefffffh",
      "ddeeeeeefffffhhe",
      "eeeeeefffffhheee",
      "eeeefffffhheeeee",
      "eeffffffheeeeeee",
      "fffffffheeeeeiee"
    ],
    [
      "              jk",
      "              jk",
      "              jk",
      "             jjk",
      "             jkk",
      "           jjjk ",
      "         jjjkkl ",
      "       jjjkkk   ",
      "     jjjkkk     ",
      "   jjjklk       ",
      " jjjkkk         ",
      "jjkkl           ",
      "kkk             ",
      "k               ",
      "                ",
      "             mnn"
    ],
    [
      "                ",
      "                ",
      "                ",
      "                ",
      "                ",
      "                ",
      "                ",
      "                ",
      "                ",
      "                ",
      "                ",
      "                ",
      "                ",
      "                ",
      "                ",
      "             k  "
    ],
    [
      "                ",
      "                ",
      "                ",
      "                ",
      "                ",
      "                ",
      "                ",
      "                ",
      "                ",
      "                ",
      "                ",
      "                ",
      "               o",
      "                ",
      "                ",
      "             n  "
    ],
    [
      "                ",
      "                ",
      "                ",
      "                ",
      "                ",
      "                ",
      "                ",
      "                ",
      "                ",
      "                ",
      "                ",
      "                ",
      "p             oq",
      "                ",
      "                ",
      "             n  "
    ],
    [
      "                ",
      "                ",
      "                ",
      "                ",
      "                ",
      "                ",
      "                ",
      "                ",
      "                ",
      "                ",
      "                ",
      "                ",
      "rp           oq ",
      "                ",
      "                ",
      "             s  "
    ]
  ]
}